{"event_at":"2026-07-28T03:13:38.601000Z","event_fingerprint":"d170bc08d0ad93fad037b957efcc893f9f10ae749af57ca642f0cf866283ac9d","payload":{"connection_id":"a6b55582af5f430fb37ad02bf0922475","event_at":"2026-07-28T03:13:38.601000Z","event_type":"price_change","frame_hash":"ba2e5cbad44f4025e2c43eb28d0a1b0e308bb7ac5a57cbb7ae3e7973e3ab00e2","frame_index":0,"kind":"data","monotonic_ns":310401627582541,"payload":{"event_type":"price_change","market":"0x779291bef19b6709f61e9764a954aafe9ffae488d50ae674aabdcb4f248006d5","price_changes":[{"asset_id":"14965588658799411272385430903075831224615961675357217884735713260981483529984","best_ask":"0.88","best_bid":"0.87","hash":"802894f9db99af7962969a1726d97be5753a5f81","price":"0.76","side":"BUY","size":"62"},{"asset_id":"8761897749749422724209054078244794145777693856614463256546737399611489089783","best_ask":"0.13","best_bid":"0.12","hash":"3720d0c28eab93b36a95224c12c17fad8e4001fa","price":"0.24","side":"SELL","size":"62"}],"timestamp":"1785208418601"},"payload_hash":"fffdebb811121b8bda5f042688183de52e69c751aaf2b08afa5c2bc1a431aa78","raw_frame":"{\"market\":\"0x779291bef19b6709f61e9764a954aafe9ffae488d50ae674aabdcb4f248006d5\", \"price_changes\":[{\"asset_id\":\"14965588658799411272385430903075831224615961675357217884735713260981483529984\", \"price\":\"0.76\", \"size\":\"62\", \"side\":\"BUY\", \"hash\":\"802894f9db99af7962969a1726d97be5753a5f81\", \"best_bid\":\"0.87\", \"best_ask\":\"0.88\"}, {\"asset_id\":\"8761897749749422724209054078244794145777693856614463256546737399611489089783\", \"price\":\"0.24\", \"size\":\"62\", \"side\":\"SELL\", \"hash\":\"3720d0c28eab93b36a95224c12c17fad8e4001fa\", \"best_bid\":\"0.12\", \"best_ask\":\"0.13\"}], \"timestamp\":\"1785208418601\", \"event_type\":\"price_change\"}","received_at":"2026-07-28T03:13:38.592368Z","schema_version":"clob-market-ws.price_change.v1","sequence":null,"server_hash":null,"server_timestamp":"1785208418601","session_id":"3e519d9098404c15b234d96025eb1a2b","source":"clob_market_ws"},"received_at":"2026-07-28T03:13:38.592368Z","record_id":"88afce31b6e304f8a06f97b9d236311a71a5bda97883e114800b7e0b5236beba","schema_fingerprint":"4aa3821a28b0b7c2400bc59aba4bcc0a76e971dadd19610d3ad38c768e124dc7","schema_version":"edge-lab-recorder.raw.v1","sequence":null,"source":"clob_market_ws"}
{"event_at":"2026-07-28T03:13:38.601000Z","event_fingerprint":"07ae2c1c3f3a90aa2dc871246972ef4a67fcba52c33be55ba28a4e4b018aee34","payload":{"connection_id":"a6b55582af5f430fb37ad02bf0922475","event_at":"2026-07-28T03:13:38.601000Z","event_type":"price_change","frame_hash":"92bb256f2ace0ea5871bb7271570a05cbdb9a3fc954aecf00328436ae08aa7b1","frame_index":0,"kind":"data","monotonic_ns":310401629815250,"payload":{"event_type":"price_change","market":"0x779291bef19b6709f61e9764a954aafe9ffae488d50ae674aabdcb4f248006d5","price_changes":[{"asset_id":"14965588658799411272385430903075831224615961675357217884735713260981483529984","best_ask":"0.88","best_bid":"0.87","hash":"0aef998b7d3d6fa0f0adda5ce2bcf38f071b4ffe","price":"0.68","side":"BUY","size":"46"},{"asset_id":"8761897749749422724209054078244794145777693856614463256546737399611489089783","best_ask":"0.13","best_bid":"0.12","hash":"67651dd2efcb6eaf3467a3b6897441bf8957b274","price":"0.32","side":"SELL","size":"46"}],"timestamp":"1785208418601"},"payload_hash":"513a50774d67e9b653b6495252f3051467bdce9b065fda82fbc84ddf1481a9d4","raw_frame":"{\"market\":\"0x779291bef19b6709f61e9764a954aafe9ffae488d50ae674aabdcb4f248006d5\", \"price_changes\":[{\"asset_id\":\"14965588658799411272385430903075831224615961675357217884735713260981483529984\", \"price\":\"0.68\", \"size\":\"46\", \"side\":\"BUY\", \"hash\":\"0aef998b7d3d6fa0f0adda5ce2bcf38f071b4ffe\", \"best_bid\":\"0.87\", \"best_ask\":\"0.88\"}, {\"asset_id\":\"8761897749749422724209054078244794145777693856614463256546737399611489089783\", \"price\":\"0.32\", \"size\":\"46\", \"side\":\"SELL\", \"hash\":\"67651dd2efcb6eaf3467a3b6897441bf8957b274\", \"best_bid\":\"0.12\", \"best_ask\":\"0.13\"}], \"timestamp\":\"1785208418601\", \"event_type\":\"price_change\"}","received_at":"2026-07-28T03:13:38.594600Z","schema_version":"clob-market-ws.price_change.v1","sequence":null,"server_hash":null,"server_timestamp":"1785208418601","session_id":"3e519d9098404c15b234d96025eb1a2b","source":"clob_market_ws"},"received_at":"2026-07-28T03:13:38.594600Z","record_id":"d869014e9d86b643403ab855fff840fa898b75afbae97c35efd14232f7ea9455","schema_fingerprint":"4aa3821a28b0b7c2400bc59aba4bcc0a76e971dadd19610d3ad38c768e124dc7","schema_version":"edge-lab-recorder.raw.v1","sequence":null,"source":"clob_market_ws"}
{"event_at":"2026-07-28T03:13:38.603000Z","event_fingerprint":"d03e051040542788187b3dbafa43ad6a8ace24ba91499cdd4e40466827630320","payload":{"connection_id":"a6b55582af5f430fb37ad02bf0922475","event_at":"2026-07-28T03:13:38.603000Z","event_type":"best_bid_ask","frame_hash":"0506c72c6c315ad903feb35735911b93a7f6aeae51a6a35054664a80d19c5ff0","frame_index":0,"kind":"data","monotonic_ns":310401631415666,"payload":{"asset_id":"14965588658799411272385430903075831224615961675357217884735713260981483529984","best_ask":"0.88","best_bid":"0.84","event_type":"best_bid_ask","market":"0x779291bef19b6709f61e9764a954aafe9ffae488d50ae674aabdcb4f248006d5","spread":"0.04","timestamp":"1785208418603"},"payload_hash":"d6e027d101be7a141df8f4506a7123cea8d4a5ba7365de2f45c64b64972f5f44","raw_frame":"{\"market\":\"0x779291bef19b6709f61e9764a954aafe9ffae488d50ae674aabdcb4f248006d5\", \"asset_id\":\"14965588658799411272385430903075831224615961675357217884735713260981483529984\", \"best_bid\":\"0.84\", \"best_ask\":\"0.88\", \"spread\":\"0.04\", \"timestamp\":\"1785208418603\", \"event_type\":\"best_bid_ask\"}","received_at":"2026-07-28T03:13:38.596202Z","schema_version":"clob-market-ws.best_bid_ask.v1","sequence":null,"server_hash":null,"server_timestamp":"1785208418603","session_id":"3e519d9098404c15b234d96025eb1a2b","source":"clob_market_ws"},"received_at":"2026-07-28T03:13:38.596202Z","record_id":"4ed12408b9d758bc3a52ebf0a65841aacda575744ced17130113d17cf9c22b4a","schema_fingerprint":"8488399f31b0337811b13b266be932db7062827c2470b78bd8e9e99bab51d17d","schema_version":"edge-lab-recorder.raw.v1","sequence":null,"source":"clob_market_ws"}
{"event_at":"2026-07-28T03:13:38.603000Z","event_fingerprint":"271bf358f4aae3c4fe728b7511a1b4bfa7a746269e35f2913ec9dc221920afb0","payload":{"connection_id":"a6b55582af5f430fb37ad02bf0922475","event_at":"2026-07-28T03:13:38.603000Z","event_type":"best_bid_ask","frame_hash":"ae6d7142fb3397ed2957c8852a1f0aca5bc7c397a39b5b3e10eeb4c66ef3e088","frame_index":0,"kind":"data","monotonic_ns":310401632547166,"payload":{"asset_id":"8761897749749422724209054078244794145777693856614463256546737399611489089783","best_ask":"0.16","best_bid":"0.12","event_type":"best_bid_ask","market":"0x779291bef19b6709f61e9764a954aafe9ffae488d50ae674aabdcb4f248006d5","spread":"0.04","timestamp":"1785208418603"},"payload_hash":"d10826ad0a73dae1bf7bb54f2f21aca6fc64ba3626cd23392b840670c5a21e20","raw_frame":"{\"market\":\"0x779291bef19b6709f61e9764a954aafe9ffae488d50ae674aabdcb4f248006d5\", \"asset_id\":\"8761897749749422724209054078244794145777693856614463256546737399611489089783\", \"best_bid\":\"0.12\", \"best_ask\":\"0.16\", \"spread\":\"0.04\", \"timestamp\":\"1785208418603\", \"event_type\":\"best_bid_ask\"}","received_at":"2026-07-28T03:13:38.597332Z","schema_version":"clob-market-ws.best_bid_ask.v1","sequence":null,"server_hash":null,"server_timestamp":"1785208418603","session_id":"3e519d9098404c15b234d96025eb1a2b","source":"clob_market_ws"},"received_at":"2026-07-28T03:13:38.597332Z","record_id":"c4ee3e5c88736d9ac271aeb5a8080136697ee3920d693dc1614324a1276330c5","schema_fingerprint":"8488399f31b0337811b13b266be932db7062827c2470b78bd8e9e99bab51d17d","schema_version":"edge-lab-recorder.raw.v1","sequence":null,"source":"clob_market_ws"}
{"event_at":"2026-07-28T03:13:38.603000Z","event_fingerprint":"6fda8af3af0252a8950ccbbc36a6bec02ec2ab3cdfe02644ed89b39e1df3c328","payload":{"connection_id":"a6b55582af5f430fb37ad02bf0922475","event_at":"2026-07-28T03:13:38.603000Z","event_type":"price_change","frame_hash":"ff7c86ffa4f96f619d163a3b754ba71a7e612659807951356c4450b9c3b1c0f1","frame_index":0,"kind":"data","monotonic_ns":310401633675125,"payload":{"event_type":"price_change","market":"0x779291bef19b6709f61e9764a954aafe9ffae488d50ae674aabdcb4f248006d5","price_changes":[{"asset_id":"14965588658799411272385430903075831224615961675357217884735713260981483529984","best_ask":"0.88","best_bid":"0.84","hash":"39ed75143bf428e9e4129a2e4a4094cd7ffd2d42","price":"0.87","side":"BUY","size":"0"},{"asset_id":"8761897749749422724209054078244794145777693856614463256546737399611489089783","best_ask":"0.16","best_bid":"0.12","hash":"c449835b0ef67e756b4e16e07e8c011e6cca5f65","price":"0.13","side":"SELL","size":"0"}],"timestamp":"1785208418603"},"payload_hash":"d67161408c241db311d21e56587384f12f37c39b4d36898f342e59d3e4424daa","raw_frame":"{\"market\":\"0x779291bef19b6709f61e9764a954aafe9ffae488d50ae674aabdcb4f248006d5\", \"price_changes\":[{\"asset_id\":\"14965588658799411272385430903075831224615961675357217884735713260981483529984\", \"price\":\"0.87\", \"size\":\"0\", \"side\":\"BUY\", \"hash\":\"39ed75143bf428e9e4129a2e4a4094cd7ffd2d42\", \"best_bid\":\"0.84\", \"best_ask\":\"0.88\"}, {\"asset_id\":\"8761897749749422724209054078244794145777693856614463256546737399611489089783\", \"price\":\"0.13\", \"size\":\"0\", \"side\":\"SELL\", \"hash\":\"c449835b0ef67e756b4e16e07e8c011e6cca5f65\", \"best_bid\":\"0.12\", \"best_ask\":\"0.16\"}], \"timestamp\":\"1785208418603\", \"event_type\":\"price_change\"}","received_at":"2026-07-28T03:13:38.598462Z","schema_version":"clob-market-ws.price_change.v1","sequence":null,"server_hash":null,"server_timestamp":"1785208418603","session_id":"3e519d9098404c15b234d96025eb1a2b","source":"clob_market_ws"},"received_at":"2026-07-28T03:13:38.598462Z","record_id":"ee677d9b6610b735fb5c2d212aa5fe42f6c18920dab271b2d6f43b3a028c821e","schema_fingerprint":"4aa3821a28b0b7c2400bc59aba4bcc0a76e971dadd19610d3ad38c768e124dc7","schema_version":"edge-lab-recorder.raw.v1","sequence":null,"source":"clob_market_ws"}
{"event_at":"2026-07-28T03:13:38.603000Z","event_fingerprint":"eee62cde808663c0a22e2dc6cef6f29519d1a3f3b9d4bee2bf1fe39899f9d23d","payload":{"connection_id":"a6b55582af5f430fb37ad02bf0922475","event_at":"2026-07-28T03:13:38.603000Z","event_type":"price_change","frame_hash":"eae61ce1ca9bf34702051d5ee95027b59720d939b14414b2ae91ea246987a2ca","frame_index":0,"kind":"data","monotonic_ns":310401635189375,"payload":{"event_type":"price_change","market":"0x779291bef19b6709f61e9764a954aafe9ffae488d50ae674aabdcb4f248006d5","price_changes":[{"asset_id":"8761897749749422724209054078244794145777693856614463256546737399611489089783","best_ask":"0.16","best_bid":"0.12","hash":"4c30e68b801745b0c01fa25f3fef05e4fc572a27","price":"0.12","side":"BUY","size":"116.34"},{"asset_id":"14965588658799411272385430903075831224615961675357217884735713260981483529984","best_ask":"0.88","best_bid":"0.84","hash":"3fd527626d232474a7c896a7dfe138aa4581b372","price":"0.88","side":"SELL","size":"116.34"}],"timestamp":"1785208418603"},"payload_hash":"a8f34eac56324defb3181adfe2cfac4de8def327073af455c67145d258eb9055","raw_frame":"{\"market\":\"0x779291bef19b6709f61e9764a954aafe9ffae488d50ae674aabdcb4f248006d5\", \"price_changes\":[{\"asset_id\":\"8761897749749422724209054078244794145777693856614463256546737399611489089783\", \"price\":\"0.12\", \"size\":\"116.34\", \"side\":\"BUY\", \"hash\":\"4c30e68b801745b0c01fa25f3fef05e4fc572a27\", \"best_bid\":\"0.12\", \"best_ask\":\"0.16\"}, {\"asset_id\":\"14965588658799411272385430903075831224615961675357217884735713260981483529984\", \"price\":\"0.88\", \"size\":\"116.34\", \"side\":\"SELL\", \"hash\":\"3fd527626d232474a7c896a7dfe138aa4581b372\", \"best_bid\":\"0.84\", \"best_ask\":\"0.88\"}], \"timestamp\":\"1785208418603\", \"event_type\":\"price_change\"}","received_at":"2026-07-28T03:13:38.599975Z","schema_version":"clob-market-ws.price_change.v1","sequence":null,"server_hash":null,"server_timestamp":"1785208418603","session_id":"3e519d9098404c15b234d96025eb1a2b","source":"clob_market_ws"},"received_at":"2026-07-28T03:13:38.599975Z","record_id":"81fb04abf8e614d8a3f5555d543aca74810b3571cac0f6fc76a09dfc919f4693","schema_fingerprint":"4aa3821a28b0b7c2400bc59aba4bcc0a76e971dadd19610d3ad38c768e124dc7","schema_version":"edge-lab-recorder.raw.v1","sequence":null,"source":"clob_market_ws"}
{"event_at":"2026-07-28T03:13:38.603000Z","event_fingerprint":"3ceb4508e84f119de49cd06ddf9f7d3ed792f2a97e2ff2a63c719f22d83d9324","payload":{"connection_id":"a6b55582af5f430fb37ad02bf0922475","event_at":"2026-07-28T03:13:38.603000Z","event_type":"price_change","frame_hash":"b82cd053449700d8c09f875fe765dc006c1a099a8fa98cd66d626604cb4dc329","frame_index":0,"kind":"data","monotonic_ns":310401636741166,"payload":{"event_type":"price_change","market":"0x779291bef19b6709f61e9764a954aafe9ffae488d50ae674aabdcb4f248006d5","price_changes":[{"asset_id":"8761897749749422724209054078244794145777693856614463256546737399611489089783","best_ask":"0.16","best_bid":"0.12","hash":"658fd0eb41630f6917dd17f4a0b1cdcb109e21ac","price":"0.09","side":"BUY","size":"297"},{"asset_id":"14965588658799411272385430903075831224615961675357217884735713260981483529984","best_ask":"0.88","best_bid":"0.84","hash":"553e7ab9d46d347ca5d46352d0c7b09a0dba3037","price":"0.91","side":"SELL","size":"297"}],"timestamp":"1785208418603"},"payload_hash":"c7b57b27e1a52d3597d156ab5e496ce6534331379e3544ab2650d1a0b17cffb9","raw_frame":"{\"market\":\"0x779291bef19b6709f61e9764a954aafe9ffae488d50ae674aabdcb4f248006d5\", \"price_changes\":[{\"asset_id\":\"8761897749749422724209054078244794145777693856614463256546737399611489089783\", \"price\":\"0.09\", \"size\":\"297\", \"side\":\"BUY\", \"hash\":\"658fd0eb41630f6917dd17f4a0b1cdcb109e21ac\", \"best_bid\":\"0.12\", \"best_ask\":\"0.16\"}, {\"asset_id\":\"14965588658799411272385430903075831224615961675357217884735713260981483529984\", \"price\":\"0.91\", \"size\":\"297\", \"side\":\"SELL\", \"hash\":\"553e7ab9d46d347ca5d46352d0c7b09a0dba3037\", \"best_bid\":\"0.84\", \"best_ask\":\"0.88\"}], \"timestamp\":\"1785208418603\", \"event_type\":\"price_change\"}","received_at":"2026-07-28T03:13:38.601529Z","schema_version":"clob-market-ws.price_change.v1","sequence":null,"server_hash":null,"server_timestamp":"1785208418603","session_id":"3e519d9098404c15b234d96025eb1a2b","source":"clob_market_ws"},"received_at":"2026-07-28T03:13:38.601529Z","record_id":"3f1ea0492b62657fd1318dc13c7579f62d39942b4ca7f9a77733b6e44e754e91","schema_fingerprint":"4aa3821a28b0b7c2400bc59aba4bcc0a76e971dadd19610d3ad38c768e124dc7","schema_version":"edge-lab-recorder.raw.v1","sequence":null,"source":"clob_market_ws"}
{"event_at":"2026-07-28T03:13:38.604000Z","event_fingerprint":"5941b9879a1f33139d70e71f6583415ff593cbb0da00ad56d96117f66d684eb2","payload":{"connection_id":"a6b55582af5f430fb37ad02bf0922475","event_at":"2026-07-28T03:13:38.604000Z","event_type":"price_change","frame_hash":"cd1c2e0c2ce13f7656245f133c7c89ff0f3e9bd31243c0b86dced63a7e6bbf50","frame_index":0,"kind":"data","monotonic_ns":310401638209458,"payload":{"event_type":"price_change","market":"0x779291bef19b6709f61e9764a954aafe9ffae488d50ae674aabdcb4f248006d5","price_changes":[{"asset_id":"8761897749749422724209054078244794145777693856614463256546737399611489089783","best_ask":"0.16","best_bid":"0.12","hash":"daa9c1e3cfd32e3b07e9151556ff80f4aedc4f73","price":"0.11","side":"BUY","size":"40"},{"asset_id":"14965588658799411272385430903075831224615961675357217884735713260981483529984","best_ask":"0.88","best_bid":"0.84","hash":"4190f3926239bfbfc1d615290e19df4a2cc7731c","price":"0.89","side":"SELL","size":"40"}],"timestamp":"1785208418604"},"payload_hash":"f5463e26d2e48537525bab62af483bacfad6419627abbf11d0bdd954bc028dbb","raw_frame":"{\"market\":\"0x779291bef19b6709f61e9764a954aafe9ffae488d50ae674aabdcb4f248006d5\", \"price_changes\":[{\"asset_id\":\"8761897749749422724209054078244794145777693856614463256546737399611489089783\", \"price\":\"0.11\", \"size\":\"40\", \"side\":\"BUY\", \"hash\":\"daa9c1e3cfd32e3b07e9151556ff80f4aedc4f73\", \"best_bid\":\"0.12\", \"best_ask\":\"0.16\"}, {\"asset_id\":\"14965588658799411272385430903075831224615961675357217884735713260981483529984\", \"price\":\"0.89\", \"size\":\"40\", \"side\":\"SELL\", \"hash\":\"4190f3926239bfbfc1d615290e19df4a2cc7731c\", \"best_bid\":\"0.84\", \"best_ask\":\"0.88\"}], \"timestamp\":\"1785208418604\", \"event_type\":\"price_change\"}","received_at":"2026-07-28T03:13:38.602997Z","schema_version":"clob-market-ws.price_change.v1","sequence":null,"server_hash":null,"server_timestamp":"1785208418604","session_id":"3e519d9098404c15b234d96025eb1a2b","source":"clob_market_ws"},"received_at":"2026-07-28T03:13:38.602997Z","record_id":"5a0a5d0b1d7bfa6be21f1495f18c015a93047072773388bf7b89d21e9005706a","schema_fingerprint":"4aa3821a28b0b7c2400bc59aba4bcc0a76e971dadd19610d3ad38c768e124dc7","schema_version":"edge-lab-recorder.raw.v1","sequence":null,"source":"clob_market_ws"}
{"event_at":"2026-07-28T03:13:38.608000Z","event_fingerprint":"e6f24a38a02afc9fc76f20bd62f3cc4cd66e90e647613252b90f40ff7a2d24d3","payload":{"connection_id":"a6b55582af5f430fb37ad02bf0922475","event_at":"2026-07-28T03:13:38.608000Z","event_type":"best_bid_ask","frame_hash":"df086c4b5c969d30b20b09883becf2a559d00f48aff4c7da0bf40a1ee785ec5f","frame_index":0,"kind":"data","monotonic_ns":310401639758875,"payload":{"asset_id":"14965588658799411272385430903075831224615961675357217884735713260981483529984","best_ask":"0.87","best_bid":"0.84","event_type":"best_bid_ask","market":"0x779291bef19b6709f61e9764a954aafe9ffae488d50ae674aabdcb4f248006d5","spread":"0.03","timestamp":"1785208418608"},"payload_hash":"bc1ba4d86fa5f054a5fc0f0570ca46674577b0d9d70f34c41c2b07d87f6c2f87","raw_frame":"{\"market\":\"0x779291bef19b6709f61e9764a954aafe9ffae488d50ae674aabdcb4f248006d5\", \"asset_id\":\"14965588658799411272385430903075831224615961675357217884735713260981483529984\", \"best_bid\":\"0.84\", \"best_ask\":\"0.87\", \"spread\":\"0.03\", \"timestamp\":\"1785208418608\", \"event_type\":\"best_bid_ask\"}","received_at":"2026-07-28T03:13:38.604546Z","schema_version":"clob-market-ws.best_bid_ask.v1","sequence":null,"server_hash":null,"server_timestamp":"1785208418608","session_id":"3e519d9098404c15b234d96025eb1a2b","source":"clob_market_ws"},"received_at":"2026-07-28T03:13:38.604546Z","record_id":"c44c70ab507b607271c6bbc01ba9e6f8c4ff47fa81979373d0362fc9e59b30dd","schema_fingerprint":"8488399f31b0337811b13b266be932db7062827c2470b78bd8e9e99bab51d17d","schema_version":"edge-lab-recorder.raw.v1","sequence":null,"source":"clob_market_ws"}
{"event_at":"2026-07-28T03:13:38.608000Z","event_fingerprint":"ae9a453fbc31533ac0ec46984daeeaa15939ae1467ba6b29313baf10dcbdc295","payload":{"connection_id":"a6b55582af5f430fb37ad02bf0922475","event_at":"2026-07-28T03:13:38.608000Z","event_type":"best_bid_ask","frame_hash":"4073c0df1e3758cb1f4555a2ff1dbe3f8ea9cd9b283216a602fdc4de45ea716f","frame_index":0,"kind":"data","monotonic_ns":310401640901875,"payload":{"asset_id":"8761897749749422724209054078244794145777693856614463256546737399611489089783","best_ask":"0.16","best_bid":"0.13","event_type":"best_bid_ask","market":"0x779291bef19b6709f61e9764a954aafe9ffae488d50ae674aabdcb4f248006d5","spread":"0.03","timestamp":"1785208418608"},"payload_hash":"05dc2fa4935297a6a6710988756337e5a854822ebe1b87e29b183a2a0d45d44a","raw_frame":"{\"market\":\"0x779291bef19b6709f61e9764a954aafe9ffae488d50ae674aabdcb4f248006d5\", \"asset_id\":\"8761897749749422724209054078244794145777693856614463256546737399611489089783\", \"best_bid\":\"0.13\", \"best_ask\":\"0.16\", \"spread\":\"0.03\", \"timestamp\":\"1785208418608\", \"event_type\":\"best_bid_ask\"}","received_at":"2026-07-28T03:13:38.605689Z","schema_version":"clob-market-ws.best_bid_ask.v1","sequence":null,"server_hash":null,"server_timestamp":"1785208418608","session_id":"3e519d9098404c15b234d96025eb1a2b","source":"clob_market_ws"},"received_at":"2026-07-28T03:13:38.605689Z","record_id":"73599ccfcbdc825365db26ba10542bed7843ce37a8416c723bc1b9ad9d17a540","schema_fingerprint":"8488399f31b0337811b13b266be932db7062827c2470b78bd8e9e99bab51d17d","schema_version":"edge-lab-recorder.raw.v1","sequence":null,"source":"clob_market_ws"}
{"event_at":"2026-07-28T03:13:38.608000Z","event_fingerprint":"7aaf47577e7d92c2039ae18fe6291839805d03bb6b0e650ca862e64b3c14ef69","payload":{"connection_id":"a6b55582af5f430fb37ad02bf0922475","event_at":"2026-07-28T03:13:38.608000Z","event_type":"price_change","frame_hash":"8e9d6aa5e0d7d56a89322ba142863c846f4f5e883f6d298f64e98d60bb355281","frame_index":0,"kind":"data","monotonic_ns":310401641955041,"payload":{"event_type":"price_change","market":"0x779291bef19b6709f61e9764a954aafe9ffae488d50ae674aabdcb4f248006d5","price_changes":[{"asset_id":"8761897749749422724209054078244794145777693856614463256546737399611489089783","best_ask":"0.16","best_bid":"0.13","hash":"3cafce44998119b9b90169a2e70c5fcccb0e9c8f","price":"0.13","side":"BUY","size":"20"},{"asset_id":"14965588658799411272385430903075831224615961675357217884735713260981483529984","best_ask":"0.87","best_bid":"0.84","hash":"625e3d264fd603a2c88529ffd0e2c735a72b965f","price":"0.87","side":"SELL","size":"20"}],"timestamp":"1785208418608"},"payload_hash":"4cd33b676abeac79828ae4aa914e1d2ef8ed3e16efd43c026ca8eac3cd94fe08","raw_frame":"{\"market\":\"0x779291bef19b6709f61e9764a954aafe9ffae488d50ae674aabdcb4f248006d5\", \"price_changes\":[{\"asset_id\":\"8761897749749422724209054078244794145777693856614463256546737399611489089783\", \"price\":\"0.13\", \"size\":\"20\", \"side\":\"BUY\", \"hash\":\"3cafce44998119b9b90169a2e70c5fcccb0e9c8f\", \"best_bid\":\"0.13\", \"best_ask\":\"0.16\"}, {\"asset_id\":\"14965588658799411272385430903075831224615961675357217884735713260981483529984\", \"price\":\"0.87\", \"size\":\"20\", \"side\":\"SELL\", \"hash\":\"625e3d264fd603a2c88529ffd0e2c735a72b965f\", \"best_bid\":\"0.84\", \"best_ask\":\"0.87\"}], \"timestamp\":\"1785208418608\", \"event_type\":\"price_change\"}","received_at":"2026-07-28T03:13:38.606743Z","schema_version":"clob-market-ws.price_change.v1","sequence":null,"server_hash":null,"server_timestamp":"1785208418608","session_id":"3e519d9098404c15b234d96025eb1a2b","source":"clob_market_ws"},"received_at":"2026-07-28T03:13:38.606743Z","record_id":"ffdfa81320e41e32660c9f4dddc9fb7179baf06dc8158c4d58fe902f80b1f7c3","schema_fingerprint":"4aa3821a28b0b7c2400bc59aba4bcc0a76e971dadd19610d3ad38c768e124dc7","schema_version":"edge-lab-recorder.raw.v1","sequence":null,"source":"clob_market_ws"}
{"event_at":"2026-07-28T03:13:38.609000Z","event_fingerprint":"fe2257b37e355f0aa769c34ec001d65a23deb93a7860ddf5ee37ad720212a12f","payload":{"connection_id":"a6b55582af5f430fb37ad02bf0922475","event_at":"2026-07-28T03:13:38.609000Z","event_type":"best_bid_ask","frame_hash":"feafcd52df6993826cc40e6b53c3fb9feec69500d611a0ad991b5d8b2b57655f","frame_index":0,"kind":"data","monotonic_ns":310401643457125,"payload":{"asset_id":"14965588658799411272385430903075831224615961675357217884735713260981483529984","best_ask":"0.85","best_bid":"0.84","event_type":"best_bid_ask","market":"0x779291bef19b6709f61e9764a954aafe9ffae488d50ae674aabdcb4f248006d5","spread":"0.01","timestamp":"1785208418609"},"payload_hash":"31c218e852c9ce15c19b0b89ac1754b6e6112a00ebf22391385591b62cad75c3","raw_frame":"{\"market\":\"0x779291bef19b6709f61e9764a954aafe9ffae488d50ae674aabdcb4f248006d5\", \"asset_id\":\"14965588658799411272385430903075831224615961675357217884735713260981483529984\", \"best_bid\":\"0.84\", \"best_ask\":\"0.85\", \"spread\":\"0.01\", \"timestamp\":\"1785208418609\", \"event_type\":\"best_bid_ask\"}","received_at":"2026-07-28T03:13:38.608245Z","schema_version":"clob-market-ws.best_bid_ask.v1","sequence":null,"server_hash":null,"server_timestamp":"1785208418609","session_id":"3e519d9098404c15b234d96025eb1a2b","source":"clob_market_ws"},"received_at":"2026-07-28T03:13:38.608245Z","record_id":"99226bd96731aed366c54e465ce6baecd4eb95449b28faf403bfd3ca4dd81d14","schema_fingerprint":"8488399f31b0337811b13b266be932db7062827c2470b78bd8e9e99bab51d17d","schema_version":"edge-lab-recorder.raw.v1","sequence":null,"source":"clob_market_ws"}
{"event_at":"2026-07-28T03:13:38.609000Z","event_fingerprint":"46040346a1841c4b20ab84486240afbed01f5f1b1b810d690f7556111cf6884c","payload":{"connection_id":"a6b55582af5f430fb37ad02bf0922475","event_at":"2026-07-28T03:13:38.609000Z","event_type":"best_bid_ask","frame_hash":"da66ae3104ae383c5a50a94db1a120e36c25d57257eabd123d95298df723a5ca","frame_index":0,"kind":"data","monotonic_ns":310401644484416,"payload":{"asset_id":"8761897749749422724209054078244794145777693856614463256546737399611489089783","best_ask":"0.16","best_bid":"0.15","event_type":"best_bid_ask","market":"0x779291bef19b6709f61e9764a954aafe9ffae488d50ae674aabdcb4f248006d5","spread":"0.01","timestamp":"1785208418609"},"payload_hash":"f3c26c614de327b413a3dcdee0b35da4bb5924004727bdf2c476bd90d648a27e","raw_frame":"{\"market\":\"0x779291bef19b6709f61e9764a954aafe9ffae488d50ae674aabdcb4f248006d5\", \"asset_id\":\"8761897749749422724209054078244794145777693856614463256546737399611489089783\", \"best_bid\":\"0.15\", \"best_ask\":\"0.16\", \"spread\":\"0.01\", \"timestamp\":\"1785208418609\", \"event_type\":\"best_bid_ask\"}","received_at":"2026-07-28T03:13:38.609272Z","schema_version":"clob-market-ws.best_bid_ask.v1","sequence":null,"server_hash":null,"server_timestamp":"1785208418609","session_id":"3e519d9098404c15b234d96025eb1a2b","source":"clob_market_ws"},"received_at":"2026-07-28T03:13:38.609272Z","record_id":"2ebe3feb5d38f542e8282d05cce641f236c7ae55d157d2fd4a805280ba3608c1","schema_fingerprint":"8488399f31b0337811b13b266be932db7062827c2470b78bd8e9e99bab51d17d","schema_version":"edge-lab-recorder.raw.v1","sequence":null,"source":"clob_market_ws"}
{"event_at":"2026-07-28T03:13:38.609000Z","event_fingerprint":"b003ed67f22d23d81ade6459e025c54520ca1d97b4a46f65c082bb39e78b2a19","payload":{"connection_id":"a6b55582af5f430fb37ad02bf0922475","event_at":"2026-07-28T03:13:38.609000Z","event_type":"price_change","frame_hash":"9bf5e2e068939d6fc20452fefcec4c58a46e484c79c70ddc9b3de8d0f0e79b84","frame_index":0,"kind":"data","monotonic_ns":310401645537958,"payload":{"event_type":"price_change","market":"0x779291bef19b6709f61e9764a954aafe9ffae488d50ae674aabdcb4f248006d5","price_changes":[{"asset_id":"8761897749749422724209054078244794145777693856614463256546737399611489089783","best_ask":"0.16","best_bid":"0.15","hash":"b0c17c6f30657e105420c6cb8d1389eafe55acf7","price":"0.15","side":"BUY","size":"20"},{"asset_id":"14965588658799411272385430903075831224615961675357217884735713260981483529984","best_ask":"0.85","best_bid":"0.84","hash":"c2976cdfed196b30b857011038f5bca2cf2add32","price":"0.85","side":"SELL","size":"20"}],"timestamp":"1785208418609"},"payload_hash":"7d72c3adc05bf91f05e7aa44faa5696574bb9df7fa3b3015af41228b8ccb3aa7","raw_frame":"{\"market\":\"0x779291bef19b6709f61e9764a954aafe9ffae488d50ae674aabdcb4f248006d5\", \"price_changes\":[{\"asset_id\":\"8761897749749422724209054078244794145777693856614463256546737399611489089783\", \"price\":\"0.15\", \"size\":\"20\", \"side\":\"BUY\", \"hash\":\"b0c17c6f30657e105420c6cb8d1389eafe55acf7\", \"best_bid\":\"0.15\", \"best_ask\":\"0.16\"}, {\"asset_id\":\"14965588658799411272385430903075831224615961675357217884735713260981483529984\", \"price\":\"0.85\", \"size\":\"20\", \"side\":\"SELL\", \"hash\":\"c2976cdfed196b30b857011038f5bca2cf2add32\", \"best_bid\":\"0.84\", \"best_ask\":\"0.85\"}], \"timestamp\":\"1785208418609\", \"event_type\":\"price_change\"}","received_at":"2026-07-28T03:13:38.610325Z","schema_version":"clob-market-ws.price_change.v1","sequence":null,"server_hash":null,"server_timestamp":"1785208418609","session_id":"3e519d9098404c15b234d96025eb1a2b","source":"clob_market_ws"},"received_at":"2026-07-28T03:13:38.610325Z","record_id":"2f73a1ffd8e21cf63c53763fc3e8f3fed35e2cc9fc5c3a835d6c908e04b6ab0f","schema_fingerprint":"4aa3821a28b0b7c2400bc59aba4bcc0a76e971dadd19610d3ad38c768e124dc7","schema_version":"edge-lab-recorder.raw.v1","sequence":null,"source":"clob_market_ws"}
{"event_at":"2026-07-28T03:13:38.611000Z","event_fingerprint":"b0cbad44dd57e55432a7f50bb0b5d6b57ef496f1b89041e2a4cc3188ae59f535","payload":{"connection_id":"a6b55582af5f430fb37ad02bf0922475","event_at":"2026-07-28T03:13:38.611000Z","event_type":"price_change","frame_hash":"5b9f98d2f5def47dba59a98c42580605dcf04e6693aacbe2f1c792f0fec87285","frame_index":0,"kind":"data","monotonic_ns":310401647026708,"payload":{"event_type":"price_change","market":"0x779291bef19b6709f61e9764a954aafe9ffae488d50ae674aabdcb4f248006d5","price_changes":[{"asset_id":"8761897749749422724209054078244794145777693856614463256546737399611489089783","best_ask":"0.16","best_bid":"0.15","hash":"206b7974bed6990e22e2a04952b9bf1100e1b464","price":"0.14","side":"BUY","size":"20"},{"asset_id":"14965588658799411272385430903075831224615961675357217884735713260981483529984","best_ask":"0.85","best_bid":"0.84","hash":"2151debb8be432c1b06cb16478cc728fcd7203be","price":"0.86","side":"SELL","size":"20"}],"timestamp":"1785208418611"},"payload_hash":"b6c904cbb5c4f21797d32daf6369bb4fc8741b1b1c6bd63407afd02a37919a37","raw_frame":"{\"market\":\"0x779291bef19b6709f61e9764a954aafe9ffae488d50ae674aabdcb4f248006d5\", \"price_changes\":[{\"asset_id\":\"8761897749749422724209054078244794145777693856614463256546737399611489089783\", \"price\":\"0.14\", \"size\":\"20\", \"side\":\"BUY\", \"hash\":\"206b7974bed6990e22e2a04952b9bf1100e1b464\", \"best_bid\":\"0.15\", \"best_ask\":\"0.16\"}, {\"asset_id\":\"14965588658799411272385430903075831224615961675357217884735713260981483529984\", \"price\":\"0.86\", \"size\":\"20\", \"side\":\"SELL\", \"hash\":\"2151debb8be432c1b06cb16478cc728fcd7203be\", \"best_bid\":\"0.84\", \"best_ask\":\"0.85\"}], \"timestamp\":\"1785208418611\", \"event_type\":\"price_change\"}","received_at":"2026-07-28T03:13:38.611814Z","schema_version":"clob-market-ws.price_change.v1","sequence":null,"server_hash":null,"server_timestamp":"1785208418611","session_id":"3e519d9098404c15b234d96025eb1a2b","source":"clob_market_ws"},"received_at":"2026-07-28T03:13:38.611814Z","record_id":"ce82b3cebd7356a6e411e57f323ece79b32fee472224e637d68283748b82b521","schema_fingerprint":"4aa3821a28b0b7c2400bc59aba4bcc0a76e971dadd19610d3ad38c768e124dc7","schema_version":"edge-lab-recorder.raw.v1","sequence":null,"source":"clob_market_ws"}
{"event_at":"2026-07-28T03:13:38.612000Z","event_fingerprint":"c8ca6eef8bf12ff1ebf4d9f6922db9f683868182d5d167e48688253b256abc2a","payload":{"connection_id":"a6b55582af5f430fb37ad02bf0922475","event_at":"2026-07-28T03:13:38.612000Z","event_type":"price_change","frame_hash":"cb76df26ebe2dee45bce20a6157ed3895f5ec47ab3802e622ffa2cb0e9f7c6a6","frame_index":0,"kind":"data","monotonic_ns":310401648543833,"payload":{"event_type":"price_change","market":"0x779291bef19b6709f61e9764a954aafe9ffae488d50ae674aabdcb4f248006d5","price_changes":[{"asset_id":"14965588658799411272385430903075831224615961675357217884735713260981483529984","best_ask":"0.85","best_bid":"0.84","hash":"38f91918b089652d30f1114cfc92153662dfeda1","price":"0.56","side":"BUY","size":"50"},{"asset_id":"8761897749749422724209054078244794145777693856614463256546737399611489089783","best_ask":"0.16","best_bid":"0.15","hash":"8b784cb8366be452e296ae946dde8b16aa728d8a","price":"0.44","side":"SELL","size":"50"}],"timestamp":"1785208418612"},"payload_hash":"fa9083413ad55a693018a8f523240db367c44beb683a5d6eb50360bc46b80204","raw_frame":"{\"market\":\"0x779291bef19b6709f61e9764a954aafe9ffae488d50ae674aabdcb4f248006d5\", \"price_changes\":[{\"asset_id\":\"14965588658799411272385430903075831224615961675357217884735713260981483529984\", \"price\":\"0.56\", \"size\":\"50\", \"side\":\"BUY\", \"hash\":\"38f91918b089652d30f1114cfc92153662dfeda1\", \"best_bid\":\"0.84\", \"best_ask\":\"0.85\"}, {\"asset_id\":\"8761897749749422724209054078244794145777693856614463256546737399611489089783\", \"price\":\"0.44\", \"size\":\"50\", \"side\":\"SELL\", \"hash\":\"8b784cb8366be452e296ae946dde8b16aa728d8a\", \"best_bid\":\"0.15\", \"best_ask\":\"0.16\"}], \"timestamp\":\"1785208418612\", \"event_type\":\"price_change\"}","received_at":"2026-07-28T03:13:38.613331Z","schema_version":"clob-market-ws.price_change.v1","sequence":null,"server_hash":null,"server_timestamp":"1785208418612","session_id":"3e519d9098404c15b234d96025eb1a2b","source":"clob_market_ws"},"received_at":"2026-07-28T03:13:38.613331Z","record_id":"b6e64dfa61d3092258c0c4196fc808af795fa953513750922533f661aed12336","schema_fingerprint":"4aa3821a28b0b7c2400bc59aba4bcc0a76e971dadd19610d3ad38c768e124dc7","schema_version":"edge-lab-recorder.raw.v1","sequence":null,"source":"clob_market_ws"}
{"event_at":"2026-07-28T03:13:38.613000Z","event_fingerprint":"c345f13ebc76cee3a224dffec578e9fec91a5b312fe7fadfee3e0327a95d07ac","payload":{"connection_id":"a6b55582af5f430fb37ad02bf0922475","event_at":"2026-07-28T03:13:38.613000Z","event_type":"price_change","frame_hash":"b32d462c41150b47ede833fe26f93a27def231ed7e5a96174f23713f762d8b35","frame_index":0,"kind":"data","monotonic_ns":310401650015583,"payload":{"event_type":"price_change","market":"0x779291bef19b6709f61e9764a954aafe9ffae488d50ae674aabdcb4f248006d5","price_changes":[{"asset_id":"8761897749749422724209054078244794145777693856614463256546737399611489089783","best_ask":"0.16","best_bid":"0.15","hash":"a04bfea0db0bff46553f689d1354612e8aef6db8","price":"0.15","side":"BUY","size":"30"},{"asset_id":"14965588658799411272385430903075831224615961675357217884735713260981483529984","best_ask":"0.85","best_bid":"0.84","hash":"cf2dd28c7d3f88b911df5288851075ecaabb4ccc","price":"0.85","side":"SELL","size":"30"}],"timestamp":"1785208418613"},"payload_hash":"e9b15e9a08341fe4587f609d808e2c253bd952c0225de493366dbf8ece7a5997","raw_frame":"{\"market\":\"0x779291bef19b6709f61e9764a954aafe9ffae488d50ae674aabdcb4f248006d5\", \"price_changes\":[{\"asset_id\":\"8761897749749422724209054078244794145777693856614463256546737399611489089783\", \"price\":\"0.15\", \"size\":\"30\", \"side\":\"BUY\", \"hash\":\"a04bfea0db0bff46553f689d1354612e8aef6db8\", \"best_bid\":\"0.15\", \"best_ask\":\"0.16\"}, {\"asset_id\":\"14965588658799411272385430903075831224615961675357217884735713260981483529984\", \"price\":\"0.85\", \"size\":\"30\", \"side\":\"SELL\", \"hash\":\"cf2dd28c7d3f88b911df5288851075ecaabb4ccc\", \"best_bid\":\"0.84\", \"best_ask\":\"0.85\"}], \"timestamp\":\"1785208418613\", \"event_type\":\"price_change\"}","received_at":"2026-07-28T03:13:38.614802Z","schema_version":"clob-market-ws.price_change.v1","sequence":null,"server_hash":null,"server_timestamp":"1785208418613","session_id":"3e519d9098404c15b234d96025eb1a2b","source":"clob_market_ws"},"received_at":"2026-07-28T03:13:38.614802Z","record_id":"cf6fa9293e865669e1ce137322e6fe5cea38b4327458b9e6a0a9ecc5e2fc00a3","schema_fingerprint":"4aa3821a28b0b7c2400bc59aba4bcc0a76e971dadd19610d3ad38c768e124dc7","schema_version":"edge-lab-recorder.raw.v1","sequence":null,"source":"clob_market_ws"}
{"event_at":"2026-07-28T03:13:38.614000Z","event_fingerprint":"0c1b16ecb763eb66be9a46b9df76edddeba4d693e1f290ebac298fc9df173abb","payload":{"connection_id":"a6b55582af5f430fb37ad02bf0922475","event_at":"2026-07-28T03:13:38.614000Z","event_type":"best_bid_ask","frame_hash":"7b8423fdf210b773174980eeb7fdba5f5228363c26f67cdc7c2f4d58a514c783","frame_index":0,"kind":"data","monotonic_ns":310401651486500,"payload":{"asset_id":"14965588658799411272385430903075831224615961675357217884735713260981483529984","best_ask":"0.85","best_bid":"0.78","event_type":"best_bid_ask","market":"0x779291bef19b6709f61e9764a954aafe9ffae488d50ae674aabdcb4f248006d5","spread":"0.07","timestamp":"1785208418614"},"payload_hash":"d648cb2677b2e7254948f05ace6d33ecdb92a28c378e3fd24590f9d2b96deaba","raw_frame":"{\"market\":\"0x779291bef19b6709f61e9764a954aafe9ffae488d50ae674aabdcb4f248006d5\", \"asset_id\":\"14965588658799411272385430903075831224615961675357217884735713260981483529984\", \"best_bid\":\"0.78\", \"best_ask\":\"0.85\", \"spread\":\"0.07\", \"timestamp\":\"1785208418614\", \"event_type\":\"best_bid_ask\"}","received_at":"2026-07-28T03:13:38.616274Z","schema_version":"clob-market-ws.best_bid_ask.v1","sequence":null,"server_hash":null,"server_timestamp":"1785208418614","session_id":"3e519d9098404c15b234d96025eb1a2b","source":"clob_market_ws"},"received_at":"2026-07-28T03:13:38.616274Z","record_id":"601bdfde4a8da1e05c623bdc92f16748e3ca68f3db904c527732558343f24862","schema_fingerprint":"8488399f31b0337811b13b266be932db7062827c2470b78bd8e9e99bab51d17d","schema_version":"edge-lab-recorder.raw.v1","sequence":null,"source":"clob_market_ws"}
{"event_at":"2026-07-28T03:13:38.614000Z","event_fingerprint":"723b543d17718e5a26f620a248d0a7974710d34c0d23c9180dbf4077ee72854a","payload":{"connection_id":"a6b55582af5f430fb37ad02bf0922475","event_at":"2026-07-28T03:13:38.614000Z","event_type":"best_bid_ask","frame_hash":"4891ffda0758f55c0e2030c66a0d725625c20e96dcd4cb6eddb1c9dae808b5c2","frame_index":0,"kind":"data","monotonic_ns":310401652518750,"payload":{"asset_id":"8761897749749422724209054078244794145777693856614463256546737399611489089783","best_ask":"0.22","best_bid":"0.15","event_type":"best_bid_ask","market":"0x779291bef19b6709f61e9764a954aafe9ffae488d50ae674aabdcb4f248006d5","spread":"0.07","timestamp":"1785208418614"},"payload_hash":"d97be16155ddb163c844ee38d80cea9f549d106c07088c5bab65ad6466aeee6f","raw_frame":"{\"market\":\"0x779291bef19b6709f61e9764a954aafe9ffae488d50ae674aabdcb4f248006d5\", \"asset_id\":\"8761897749749422724209054078244794145777693856614463256546737399611489089783\", \"best_bid\":\"0.15\", \"best_ask\":\"0.22\", \"spread\":\"0.07\", \"timestamp\":\"1785208418614\", \"event_type\":\"best_bid_ask\"}","received_at":"2026-07-28T03:13:38.617306Z","schema_version":"clob-market-ws.best_bid_ask.v1","sequence":null,"server_hash":null,"server_timestamp":"1785208418614","session_id":"3e519d9098404c15b234d96025eb1a2b","source":"clob_market_ws"},"received_at":"2026-07-28T03:13:38.617306Z","record_id":"eb615cf6a809924f7a7cec7d37d9b8ffa6b031f61a3405e45730a6f53a128a9e","schema_fingerprint":"8488399f31b0337811b13b266be932db7062827c2470b78bd8e9e99bab51d17d","schema_version":"edge-lab-recorder.raw.v1","sequence":null,"source":"clob_market_ws"}
{"event_at":"2026-07-28T03:13:38.614000Z","event_fingerprint":"ef816b5b5cfb01d430715339c8e11a8b69c353fa43f3e3508d7026c02d6ff51f","payload":{"connection_id":"a6b55582af5f430fb37ad02bf0922475","event_at":"2026-07-28T03:13:38.614000Z","event_type":"price_change","frame_hash":"915c90e70c5b522ccbdb7d4e55159d1917003683c168410d491a5c27f9d5b9c6","frame_index":0,"kind":"data","monotonic_ns":310401653621625,"payload":{"event_type":"price_change","market":"0x779291bef19b6709f61e9764a954aafe9ffae488d50ae674aabdcb4f248006d5","price_changes":[{"asset_id":"14965588658799411272385430903075831224615961675357217884735713260981483529984","best_ask":"0.85","best_bid":"0.78","hash":"c7e8a01af99efdf08d754b447a4c44beea6c1b1a","price":"0.84","side":"BUY","size":"0"},{"asset_id":"8761897749749422724209054078244794145777693856614463256546737399611489089783","best_ask":"0.22","best_bid":"0.15","hash":"7b3dad2ede98f4f0f3594caf3706e3e29fcd5cd2","price":"0.16","side":"SELL","size":"0"}],"timestamp":"1785208418614"},"payload_hash":"3332ebc55788d48600cc0fe347f7ec460ecb4a1d49c202c52a604f0631efe43d","raw_frame":"{\"market\":\"0x779291bef19b6709f61e9764a954aafe9ffae488d50ae674aabdcb4f248006d5\", \"price_changes\":[{\"asset_id\":\"14965588658799411272385430903075831224615961675357217884735713260981483529984\", \"price\":\"0.84\", \"size\":\"0\", \"side\":\"BUY\", \"hash\":\"c7e8a01af99efdf08d754b447a4c44beea6c1b1a\", \"best_bid\":\"0.78\", \"best_ask\":\"0.85\"}, {\"asset_id\":\"8761897749749422724209054078244794145777693856614463256546737399611489089783\", \"price\":\"0.16\", \"size\":\"0\", \"side\":\"SELL\", \"hash\":\"7b3dad2ede98f4f0f3594caf3706e3e29fcd5cd2\", \"best_bid\":\"0.15\", \"best_ask\":\"0.22\"}], \"timestamp\":\"1785208418614\", \"event_type\":\"price_change\"}","received_at":"2026-07-28T03:13:38.618408Z","schema_version":"clob-market-ws.price_change.v1","sequence":null,"server_hash":null,"server_timestamp":"1785208418614","session_id":"3e519d9098404c15b234d96025eb1a2b","source":"clob_market_ws"},"received_at":"2026-07-28T03:13:38.618408Z","record_id":"0d1e1b607b756266d164230bd825e1519933274c28cd7a4f6948eaa6ba9c7b7c","schema_fingerprint":"4aa3821a28b0b7c2400bc59aba4bcc0a76e971dadd19610d3ad38c768e124dc7","schema_version":"edge-lab-recorder.raw.v1","sequence":null,"source":"clob_market_ws"}
{"event_at":"2026-07-28T03:13:38.614000Z","event_fingerprint":"018f2e6f560a1608255ac532b6df707558f10a66273477e23c34d3c0de9df7ea","payload":{"connection_id":"a6b55582af5f430fb37ad02bf0922475","event_at":"2026-07-28T03:13:38.614000Z","event_type":"price_change","frame_hash":"f020dc7a0a75d750e14e74b797068ebe56419a72abfaa74cc5cdb0337e4d2724","frame_index":0,"kind":"data","monotonic_ns":310401655131541,"payload":{"event_type":"price_change","market":"0x779291bef19b6709f61e9764a954aafe9ffae488d50ae674aabdcb4f248006d5","price_changes":[{"asset_id":"14965588658799411272385430903075831224615961675357217884735713260981483529984","best_ask":"0.85","best_bid":"0.78","hash":"c796b2c4a95174191f0c641d9f0d604387b8054d","price":"0.55","side":"BUY","size":"80"},{"asset_id":"8761897749749422724209054078244794145777693856614463256546737399611489089783","best_ask":"0.22","best_bid":"0.15","hash":"c04949084eb3a3e33cc937a1b39a80a7bf064159","price":"0.45","side":"SELL","size":"80"}],"timestamp":"1785208418614"},"payload_hash":"e14ddc91062a92cc01396005b96706c954a9b9bfaf494c9c393e97fe1a014886","raw_frame":"{\"market\":\"0x779291bef19b6709f61e9764a954aafe9ffae488d50ae674aabdcb4f248006d5\", \"price_changes\":[{\"asset_id\":\"14965588658799411272385430903075831224615961675357217884735713260981483529984\", \"price\":\"0.55\", \"size\":\"80\", \"side\":\"BUY\", \"hash\":\"c796b2c4a95174191f0c641d9f0d604387b8054d\", \"best_bid\":\"0.78\", \"best_ask\":\"0.85\"}, {\"asset_id\":\"8761897749749422724209054078244794145777693856614463256546737399611489089783\", \"price\":\"0.45\", \"size\":\"80\", \"side\":\"SELL\", \"hash\":\"c04949084eb3a3e33cc937a1b39a80a7bf064159\", \"best_bid\":\"0.15\", \"best_ask\":\"0.22\"}], \"timestamp\":\"1785208418614\", \"event_type\":\"price_change\"}","received_at":"2026-07-28T03:13:38.619919Z","schema_version":"clob-market-ws.price_change.v1","sequence":null,"server_hash":null,"server_timestamp":"1785208418614","session_id":"3e519d9098404c15b234d96025eb1a2b","source":"clob_market_ws"},"received_at":"2026-07-28T03:13:38.619919Z","record_id":"852bb6d58a45986fa6b5a858808953c1a1c2f34ec0e81ee1f674e42823668325","schema_fingerprint":"4aa3821a28b0b7c2400bc59aba4bcc0a76e971dadd19610d3ad38c768e124dc7","schema_version":"edge-lab-recorder.raw.v1","sequence":null,"source":"clob_market_ws"}
{"event_at":"2026-07-28T03:13:38.615000Z","event_fingerprint":"bb0746b5ac0dbdd3bd68fdc295b3e4a2eff52e5ff41d8e9de0002108164d4cf1","payload":{"connection_id":"a6b55582af5f430fb37ad02bf0922475","event_at":"2026-07-28T03:13:38.615000Z","event_type":"price_change","frame_hash":"31cb137188dc4f0d4467422d6920b4d1873efdd24fb265d47a56bae5850ed708","frame_index":0,"kind":"data","monotonic_ns":310401656619291,"payload":{"event_type":"price_change","market":"0x779291bef19b6709f61e9764a954aafe9ffae488d50ae674aabdcb4f248006d5","price_changes":[{"asset_id":"8761897749749422724209054078244794145777693856614463256546737399611489089783","best_ask":"0.22","best_bid":"0.15","hash":"7a7f751e8b9939db2b5947549c593d6569d14bb8","price":"0.1","side":"BUY","size":"417.98"},{"asset_id":"14965588658799411272385430903075831224615961675357217884735713260981483529984","best_ask":"0.85","best_bid":"0.78","hash":"e1cd8e4731ff9cedade0bec427adc243d035eb73","price":"0.9","side":"SELL","size":"417.98"}],"timestamp":"1785208418615"},"payload_hash":"77fc29f569b710b615b8edfc41046870b53cebbe38375fb5145a546f321378e9","raw_frame":"{\"market\":\"0x779291bef19b6709f61e9764a954aafe9ffae488d50ae674aabdcb4f248006d5\", \"price_changes\":[{\"asset_id\":\"8761897749749422724209054078244794145777693856614463256546737399611489089783\", \"price\":\"0.1\", \"size\":\"417.98\", \"side\":\"BUY\", \"hash\":\"7a7f751e8b9939db2b5947549c593d6569d14bb8\", \"best_bid\":\"0.15\", \"best_ask\":\"0.22\"}, {\"asset_id\":\"14965588658799411272385430903075831224615961675357217884735713260981483529984\", \"price\":\"0.9\", \"size\":\"417.98\", \"side\":\"SELL\", \"hash\":\"e1cd8e4731ff9cedade0bec427adc243d035eb73\", \"best_bid\":\"0.78\", \"best_ask\":\"0.85\"}], \"timestamp\":\"1785208418615\", \"event_type\":\"price_change\"}","received_at":"2026-07-28T03:13:38.621406Z","schema_version":"clob-market-ws.price_change.v1","sequence":null,"server_hash":null,"server_timestamp":"1785208418615","session_id":"3e519d9098404c15b234d96025eb1a2b","source":"clob_market_ws"},"received_at":"2026-07-28T03:13:38.621406Z","record_id":"c2f9e1c525a57890d4f6b7fde2772be3efe4b7708b7d3a6d1ecf5fc6b3805d7f","schema_fingerprint":"4aa3821a28b0b7c2400bc59aba4bcc0a76e971dadd19610d3ad38c768e124dc7","schema_version":"edge-lab-recorder.raw.v1","sequence":null,"source":"clob_market_ws"}
{"event_at":"2026-07-28T03:13:38.615000Z","event_fingerprint":"8087a01678f4caa4720cd2f082a38d7fe6d3297698e756979c248ed6c8dbf411","payload":{"connection_id":"a6b55582af5f430fb37ad02bf0922475","event_at":"2026-07-28T03:13:38.615000Z","event_type":"price_change","frame_hash":"94fc39459bf1a85d587ee20681e03cf922cfdf05566928d7a93d6abb80e7d3c6","frame_index":0,"kind":"data","monotonic_ns":310401658105375,"payload":{"event_type":"price_change","market":"0x779291bef19b6709f61e9764a954aafe9ffae488d50ae674aabdcb4f248006d5","price_changes":[{"asset_id":"8761897749749422724209054078244794145777693856614463256546737399611489089783","best_ask":"0.22","best_bid":"0.15","hash":"224bb1d38a7726b0e02d7a4ea1791d006108cb1e","price":"0.13","side":"BUY","size":"30"},{"asset_id":"14965588658799411272385430903075831224615961675357217884735713260981483529984","best_ask":"0.85","best_bid":"0.78","hash":"0f2f9dec73394702210556577b73593707e0f7e0","price":"0.87","side":"SELL","size":"30"}],"timestamp":"1785208418615"},"payload_hash":"d01e5a7da69d63226b9ee6b90039306f1051a8441880f6320a736cfb50f493e1","raw_frame":"{\"market\":\"0x779291bef19b6709f61e9764a954aafe9ffae488d50ae674aabdcb4f248006d5\", \"price_changes\":[{\"asset_id\":\"8761897749749422724209054078244794145777693856614463256546737399611489089783\", \"price\":\"0.13\", \"size\":\"30\", \"side\":\"BUY\", \"hash\":\"224bb1d38a7726b0e02d7a4ea1791d006108cb1e\", \"best_bid\":\"0.15\", \"best_ask\":\"0.22\"}, {\"asset_id\":\"14965588658799411272385430903075831224615961675357217884735713260981483529984\", \"price\":\"0.87\", \"size\":\"30\", \"side\":\"SELL\", \"hash\":\"0f2f9dec73394702210556577b73593707e0f7e0\", \"best_bid\":\"0.78\", \"best_ask\":\"0.85\"}], \"timestamp\":\"1785208418615\", \"event_type\":\"price_change\"}","received_at":"2026-07-28T03:13:38.622893Z","schema_version":"clob-market-ws.price_change.v1","sequence":null,"server_hash":null,"server_timestamp":"1785208418615","session_id":"3e519d9098404c15b234d96025eb1a2b","source":"clob_market_ws"},"received_at":"2026-07-28T03:13:38.622893Z","record_id":"9fcf1c4163ed041fa2f59a90e793577517eee62962a78adf69330baafe645510","schema_fingerprint":"4aa3821a28b0b7c2400bc59aba4bcc0a76e971dadd19610d3ad38c768e124dc7","schema_version":"edge-lab-recorder.raw.v1","sequence":null,"source":"clob_market_ws"}
{"event_at":"2026-07-28T03:13:38.616000Z","event_fingerprint":"29b1896490977ac6a8ed598860b23524b39e6f26502a16b94661b93c5c5e6c01","payload":{"connection_id":"a6b55582af5f430fb37ad02bf0922475","event_at":"2026-07-28T03:13:38.616000Z","event_type":"price_change","frame_hash":"29613ea8e0d68111f795a98643ca0f78d08102762ff4ff772dde5492d111bc7f","frame_index":0,"kind":"data","monotonic_ns":310401659600125,"payload":{"event_type":"price_change","market":"0x779291bef19b6709f61e9764a954aafe9ffae488d50ae674aabdcb4f248006d5","price_changes":[{"asset_id":"14965588658799411272385430903075831224615961675357217884735713260981483529984","best_ask":"0.85","best_bid":"0.78","hash":"39d392940e50688d886bf6823c23990710225488","price":"0.53","side":"BUY","size":"50"},{"asset_id":"8761897749749422724209054078244794145777693856614463256546737399611489089783","best_ask":"0.22","best_bid":"0.15","hash":"da93d0b346ab3eab57ac7b590a69e705f96f00b4","price":"0.47","side":"SELL","size":"50"}],"timestamp":"1785208418616"},"payload_hash":"7febec83e1e71cd9927ce6cc2e7af56f2bf9cd734f6bc83b2adef28c4b27b153","raw_frame":"{\"market\":\"0x779291bef19b6709f61e9764a954aafe9ffae488d50ae674aabdcb4f248006d5\", \"price_changes\":[{\"asset_id\":\"14965588658799411272385430903075831224615961675357217884735713260981483529984\", \"price\":\"0.53\", \"size\":\"50\", \"side\":\"BUY\", \"hash\":\"39d392940e50688d886bf6823c23990710225488\", \"best_bid\":\"0.78\", \"best_ask\":\"0.85\"}, {\"asset_id\":\"8761897749749422724209054078244794145777693856614463256546737399611489089783\", \"price\":\"0.47\", \"size\":\"50\", \"side\":\"SELL\", \"hash\":\"da93d0b346ab3eab57ac7b590a69e705f96f00b4\", \"best_bid\":\"0.15\", \"best_ask\":\"0.22\"}], \"timestamp\":\"1785208418616\", \"event_type\":\"price_change\"}","received_at":"2026-07-28T03:13:38.624387Z","schema_version":"clob-market-ws.price_change.v1","sequence":null,"server_hash":null,"server_timestamp":"1785208418616","session_id":"3e519d9098404c15b234d96025eb1a2b","source":"clob_market_ws"},"received_at":"2026-07-28T03:13:38.624387Z","record_id":"0edadc2cc100dcbebd423e07ac2fce68d2259861b39525b64f8585428f8f02c7","schema_fingerprint":"4aa3821a28b0b7c2400bc59aba4bcc0a76e971dadd19610d3ad38c768e124dc7","schema_version":"edge-lab-recorder.raw.v1","sequence":null,"source":"clob_market_ws"}
{"event_at":"2026-07-28T03:13:38.617000Z","event_fingerprint":"b5a523b79137c0896851e96b9a1f7081c1b0cc91d6117137b429cf1cc2f6d4bc","payload":{"connection_id":"a6b55582af5f430fb37ad02bf0922475","event_at":"2026-07-28T03:13:38.617000Z","event_type":"best_bid_ask","frame_hash":"7abd8d2d1d5b4d952c702f272378423f6b5d231495762febf6c7cde9feb9ccdb","frame_index":0,"kind":"data","monotonic_ns":310401661117041,"payload":{"asset_id":"14965588658799411272385430903075831224615961675357217884735713260981483529984","best_ask":"0.8","best_bid":"0.78","event_type":"best_bid_ask","market":"0x779291bef19b6709f61e9764a954aafe9ffae488d50ae674aabdcb4f248006d5","spread":"0.02","timestamp":"1785208418617"},"payload_hash":"6620b63336ab62f7f0f0dc17d53a2bd2a7245b30419d9ab2fa17c0f72b63653f","raw_frame":"{\"market\":\"0x779291bef19b6709f61e9764a954aafe9ffae488d50ae674aabdcb4f248006d5\", \"asset_id\":\"14965588658799411272385430903075831224615961675357217884735713260981483529984\", \"best_bid\":\"0.78\", \"best_ask\":\"0.8\", \"spread\":\"0.02\", \"timestamp\":\"1785208418617\", \"event_type\":\"best_bid_ask\"}","received_at":"2026-07-28T03:13:38.625904Z","schema_version":"clob-market-ws.best_bid_ask.v1","sequence":null,"server_hash":null,"server_timestamp":"1785208418617","session_id":"3e519d9098404c15b234d96025eb1a2b","source":"clob_market_ws"},"received_at":"2026-07-28T03:13:38.625904Z","record_id":"e01f52f91e3591c50fea4aff9f76c846e1dca4a900b4c999077ee0226d122985","schema_fingerprint":"8488399f31b0337811b13b266be932db7062827c2470b78bd8e9e99bab51d17d","schema_version":"edge-lab-recorder.raw.v1","sequence":null,"source":"clob_market_ws"}
{"event_at":"2026-07-28T03:13:38.617000Z","event_fingerprint":"cd3da2894ad703678a930136991f14ac546a1b9f3e5baf97d83403c0897c203a","payload":{"connection_id":"a6b55582af5f430fb37ad02bf0922475","event_at":"2026-07-28T03:13:38.617000Z","event_type":"best_bid_ask","frame_hash":"091848487a75f044663b605cd269937ad9aeda6d92fadebc7fe79460045b8bc2","frame_index":0,"kind":"data","monotonic_ns":310401662246708,"payload":{"asset_id":"8761897749749422724209054078244794145777693856614463256546737399611489089783","best_ask":"0.22","best_bid":"0.2","event_type":"best_bid_ask","market":"0x779291bef19b6709f61e9764a954aafe9ffae488d50ae674aabdcb4f248006d5","spread":"0.02","timestamp":"1785208418617"},"payload_hash":"1c2c81bdafc62dc0cca214b3b6d023cef84f69402bd4f27767abf7f02637990c","raw_frame":"{\"market\":\"0x779291bef19b6709f61e9764a954aafe9ffae488d50ae674aabdcb4f248006d5\", \"asset_id\":\"8761897749749422724209054078244794145777693856614463256546737399611489089783\", \"best_bid\":\"0.2\", \"best_ask\":\"0.22\", \"spread\":\"0.02\", \"timestamp\":\"1785208418617\", \"event_type\":\"best_bid_ask\"}","received_at":"2026-07-28T03:13:38.627033Z","schema_version":"clob-market-ws.best_bid_ask.v1","sequence":null,"server_hash":null,"server_timestamp":"1785208418617","session_id":"3e519d9098404c15b234d96025eb1a2b","source":"clob_market_ws"},"received_at":"2026-07-28T03:13:38.627033Z","record_id":"c04116b80775dd767cbb411bdd1cc9181430f97fd1ae076c9da92e9adfe31c45","schema_fingerprint":"8488399f31b0337811b13b266be932db7062827c2470b78bd8e9e99bab51d17d","schema_version":"edge-lab-recorder.raw.v1","sequence":null,"source":"clob_market_ws"}
{"event_at":"2026-07-28T03:13:38.616000Z","event_fingerprint":"6b4e551664d3499e0002b922125035c5b6f814ec3d718d6d08633f4e8175e744","payload":{"connection_id":"a6b55582af5f430fb37ad02bf0922475","event_at":"2026-07-28T03:13:38.616000Z","event_type":"price_change","frame_hash":"a09cca8f82aa904589a467ba6e3a52935f60ca9d78bc341b424e8f25445bc8ec","frame_index":0,"kind":"data","monotonic_ns":310401663306458,"payload":{"event_type":"price_change","market":"0x779291bef19b6709f61e9764a954aafe9ffae488d50ae674aabdcb4f248006d5","price_changes":[{"asset_id":"8761897749749422724209054078244794145777693856614463256546737399611489089783","best_ask":"0.22","best_bid":"0.2","hash":"db44b80e83394edcf3ae7a664e5db0e5b1cd624f","price":"0.2","side":"BUY","size":"10"},{"asset_id":"14965588658799411272385430903075831224615961675357217884735713260981483529984","best_ask":"0.8","best_bid":"0.78","hash":"8ea3d6565f95e03c413c6741fd64b1a4c6821f08","price":"0.8","side":"SELL","size":"10"}],"timestamp":"1785208418616"},"payload_hash":"005b14f292a511ded68c6079007df46cac38023bdef0cc53fdefe8bb54b52681","raw_frame":"{\"market\":\"0x779291bef19b6709f61e9764a954aafe9ffae488d50ae674aabdcb4f248006d5\", \"price_changes\":[{\"asset_id\":\"8761897749749422724209054078244794145777693856614463256546737399611489089783\", \"price\":\"0.2\", \"size\":\"10\", \"side\":\"BUY\", \"hash\":\"db44b80e83394edcf3ae7a664e5db0e5b1cd624f\", \"best_bid\":\"0.2\", \"best_ask\":\"0.22\"}, {\"asset_id\":\"14965588658799411272385430903075831224615961675357217884735713260981483529984\", \"price\":\"0.8\", \"size\":\"10\", \"side\":\"SELL\", \"hash\":\"8ea3d6565f95e03c413c6741fd64b1a4c6821f08\", \"best_bid\":\"0.78\", \"best_ask\":\"0.8\"}], \"timestamp\":\"1785208418616\", \"event_type\":\"price_change\"}","received_at":"2026-07-28T03:13:38.628094Z","schema_version":"clob-market-ws.price_change.v1","sequence":null,"server_hash":null,"server_timestamp":"1785208418616","session_id":"3e519d9098404c15b234d96025eb1a2b","source":"clob_market_ws"},"received_at":"2026-07-28T03:13:38.628094Z","record_id":"d4690d9cff9ec260426709334ff39fab1658376ed81b83f11bd79787fdc01c58","schema_fingerprint":"4aa3821a28b0b7c2400bc59aba4bcc0a76e971dadd19610d3ad38c768e124dc7","schema_version":"edge-lab-recorder.raw.v1","sequence":null,"source":"clob_market_ws"}
{"event_at":"2026-07-28T03:13:38.617000Z","event_fingerprint":"4adaf3b9df18d009f3e4bf35f2fffb183359349c5becf9d275fd4c673e05d59b","payload":{"connection_id":"a6b55582af5f430fb37ad02bf0922475","event_at":"2026-07-28T03:13:38.617000Z","event_type":"price_change","frame_hash":"6b76e4bbac25f75c67ac62f2a79366f4b694ed20779386cee2c97ac3d8b4d121","frame_index":0,"kind":"data","monotonic_ns":310401664776666,"payload":{"event_type":"price_change","market":"0x779291bef19b6709f61e9764a954aafe9ffae488d50ae674aabdcb4f248006d5","price_changes":[{"asset_id":"14965588658799411272385430903075831224615961675357217884735713260981483529984","best_ask":"0.8","best_bid":"0.78","hash":"a2796699e52de0b2962cad80a67914eb078e718c","price":"0.58","side":"BUY","size":"80"},{"asset_id":"8761897749749422724209054078244794145777693856614463256546737399611489089783","best_ask":"0.22","best_bid":"0.2","hash":"7b351f2f874dd2b18208f4d4d065dbaf7f2cc8d1","price":"0.42","side":"SELL","size":"80"}],"timestamp":"1785208418617"},"payload_hash":"60a7c45eec8359017557334d8adc2004c310e0d5068c97cdc48751406742611f","raw_frame":"{\"market\":\"0x779291bef19b6709f61e9764a954aafe9ffae488d50ae674aabdcb4f248006d5\", \"price_changes\":[{\"asset_id\":\"14965588658799411272385430903075831224615961675357217884735713260981483529984\", \"price\":\"0.58\", \"size\":\"80\", \"side\":\"BUY\", \"hash\":\"a2796699e52de0b2962cad80a67914eb078e718c\", \"best_bid\":\"0.78\", \"best_ask\":\"0.8\"}, {\"asset_id\":\"8761897749749422724209054078244794145777693856614463256546737399611489089783\", \"price\":\"0.42\", \"size\":\"80\", \"side\":\"SELL\", \"hash\":\"7b351f2f874dd2b18208f4d4d065dbaf7f2cc8d1\", \"best_bid\":\"0.2\", \"best_ask\":\"0.22\"}], \"timestamp\":\"1785208418617\", \"event_type\":\"price_change\"}","received_at":"2026-07-28T03:13:38.629563Z","schema_version":"clob-market-ws.price_change.v1","sequence":null,"server_hash":null,"server_timestamp":"1785208418617","session_id":"3e519d9098404c15b234d96025eb1a2b","source":"clob_market_ws"},"received_at":"2026-07-28T03:13:38.629563Z","record_id":"ea1a9a0156703a1984f1a8363f2a1b1c125e681832fcfb9d9ebd01b165085cf6","schema_fingerprint":"4aa3821a28b0b7c2400bc59aba4bcc0a76e971dadd19610d3ad38c768e124dc7","schema_version":"edge-lab-recorder.raw.v1","sequence":null,"source":"clob_market_ws"}
{"event_at":"2026-07-28T03:13:38.618000Z","event_fingerprint":"aa3c21a12d10f91bd083622e23ec4adddbdb3609105b3dc2d7c9c4157b72abce","payload":{"connection_id":"a6b55582af5f430fb37ad02bf0922475","event_at":"2026-07-28T03:13:38.618000Z","event_type":"price_change","frame_hash":"93b03b63579528fb266096a3aa2c9f0d48e99b517a70a2a2c9902913801a3074","frame_index":0,"kind":"data","monotonic_ns":310401666252875,"payload":{"event_type":"price_change","market":"0x779291bef19b6709f61e9764a954aafe9ffae488d50ae674aabdcb4f248006d5","price_changes":[{"asset_id":"14965588658799411272385430903075831224615961675357217884735713260981483529984","best_ask":"0.8","best_bid":"0.78","hash":"7c0e33f03ddd1bd5ae94ab615489fce37fc181bd","price":"0.88","side":"SELL","size":"96.34"},{"asset_id":"8761897749749422724209054078244794145777693856614463256546737399611489089783","best_ask":"0.22","best_bid":"0.2","hash":"f89c58753942e4a7ec80081519274e3cfae0a6e2","price":"0.12","side":"BUY","size":"96.34"}],"timestamp":"1785208418618"},"payload_hash":"df8c3e8c138909c4d92e3a965f0aab4bcf1dc2babc43e3d92adbe357ec765810","raw_frame":"{\"market\":\"0x779291bef19b6709f61e9764a954aafe9ffae488d50ae674aabdcb4f248006d5\", \"price_changes\":[{\"asset_id\":\"14965588658799411272385430903075831224615961675357217884735713260981483529984\", \"price\":\"0.88\", \"size\":\"96.34\", \"side\":\"SELL\", \"hash\":\"7c0e33f03ddd1bd5ae94ab615489fce37fc181bd\", \"best_bid\":\"0.78\", \"best_ask\":\"0.8\"}, {\"asset_id\":\"8761897749749422724209054078244794145777693856614463256546737399611489089783\", \"price\":\"0.12\", \"size\":\"96.34\", \"side\":\"BUY\", \"hash\":\"f89c58753942e4a7ec80081519274e3cfae0a6e2\", \"best_bid\":\"0.2\", \"best_ask\":\"0.22\"}], \"timestamp\":\"1785208418618\", \"event_type\":\"price_change\"}","received_at":"2026-07-28T03:13:38.631040Z","schema_version":"clob-market-ws.price_change.v1","sequence":null,"server_hash":null,"server_timestamp":"1785208418618","session_id":"3e519d9098404c15b234d96025eb1a2b","source":"clob_market_ws"},"received_at":"2026-07-28T03:13:38.631040Z","record_id":"7da372b07fab21e3ec5c49196718b94caaca976531d5b8cbd20386834fbf68f3","schema_fingerprint":"4aa3821a28b0b7c2400bc59aba4bcc0a76e971dadd19610d3ad38c768e124dc7","schema_version":"edge-lab-recorder.raw.v1","sequence":null,"source":"clob_market_ws"}
{"event_at":"2026-07-28T03:13:38.618000Z","event_fingerprint":"ab927b8bbe04f2e8138c867a72c5127824b5f7ccfeca7f2dfb1425a53fb41e23","payload":{"connection_id":"a6b55582af5f430fb37ad02bf0922475","event_at":"2026-07-28T03:13:38.618000Z","event_type":"price_change","frame_hash":"bc1a0e4d382582c99966143a216372e2cd37d467dc28f487d672250e74633014","frame_index":0,"kind":"data","monotonic_ns":310401667801541,"payload":{"event_type":"price_change","market":"0x779291bef19b6709f61e9764a954aafe9ffae488d50ae674aabdcb4f248006d5","price_changes":[{"asset_id":"8761897749749422724209054078244794145777693856614463256546737399611489089783","best_ask":"0.22","best_bid":"0.2","hash":"e8d83ab17de216ff43bc214f546b1ddba5180a69","price":"0.19","side":"BUY","size":"20"},{"asset_id":"14965588658799411272385430903075831224615961675357217884735713260981483529984","best_ask":"0.8","best_bid":"0.78","hash":"44749cd240cfdc31b4a8940e600c94532a4f1bb4","price":"0.81","side":"SELL","size":"20"}],"timestamp":"1785208418618"},"payload_hash":"2b77fd0bca2a034faad906d8ce0f15169f56095fe1e08ed624ff06e25bcf4024","raw_frame":"{\"market\":\"0x779291bef19b6709f61e9764a954aafe9ffae488d50ae674aabdcb4f248006d5\", \"price_changes\":[{\"asset_id\":\"8761897749749422724209054078244794145777693856614463256546737399611489089783\", \"price\":\"0.19\", \"size\":\"20\", \"side\":\"BUY\", \"hash\":\"e8d83ab17de216ff43bc214f546b1ddba5180a69\", \"best_bid\":\"0.2\", \"best_ask\":\"0.22\"}, {\"asset_id\":\"14965588658799411272385430903075831224615961675357217884735713260981483529984\", \"price\":\"0.81\", \"size\":\"20\", \"side\":\"SELL\", \"hash\":\"44749cd240cfdc31b4a8940e600c94532a4f1bb4\", \"best_bid\":\"0.78\", \"best_ask\":\"0.8\"}], \"timestamp\":\"1785208418618\", \"event_type\":\"price_change\"}","received_at":"2026-07-28T03:13:38.632588Z","schema_version":"clob-market-ws.price_change.v1","sequence":null,"server_hash":null,"server_timestamp":"1785208418618","session_id":"3e519d9098404c15b234d96025eb1a2b","source":"clob_market_ws"},"received_at":"2026-07-28T03:13:38.632588Z","record_id":"2949a1573199fd572149f70444d4ef9f10072da3c7b5adc691c98c2010e85550","schema_fingerprint":"4aa3821a28b0b7c2400bc59aba4bcc0a76e971dadd19610d3ad38c768e124dc7","schema_version":"edge-lab-recorder.raw.v1","sequence":null,"source":"clob_market_ws"}
{"event_at":"2026-07-28T03:13:38.620000Z","event_fingerprint":"c03358af4f940b83b4c9f6adce781e4f87565ea777015142e3b2a96d3ac6fb3b","payload":{"connection_id":"a6b55582af5f430fb37ad02bf0922475","event_at":"2026-07-28T03:13:38.620000Z","event_type":"price_change","frame_hash":"f042dfeb6ab5fb102cfb768a63737b809fe208c05ffc7db728a64a5ec8985b91","frame_index":0,"kind":"data","monotonic_ns":310401670675208,"payload":{"event_type":"price_change","market":"0x779291bef19b6709f61e9764a954aafe9ffae488d50ae674aabdcb4f248006d5","price_changes":[{"asset_id":"8761897749749422724209054078244794145777693856614463256546737399611489089783","best_ask":"0.22","best_bid":"0.2","hash":"7c2c30cc4d133a6c9f9403e78a8bf85e573302b0","price":"0.13","side":"BUY","size":"37.7"},{"asset_id":"14965588658799411272385430903075831224615961675357217884735713260981483529984","best_ask":"0.8","best_bid":"0.78","hash":"68dc358650051a825f72d577a18f76c710312ce3","price":"0.87","side":"SELL","size":"37.7"}],"timestamp":"1785208418620"},"payload_hash":"5d2ffd740f627c8900729752b9ddfe664ae29877473ddb074a5ebf35ba0f5349","raw_frame":"{\"market\":\"0x779291bef19b6709f61e9764a954aafe9ffae488d50ae674aabdcb4f248006d5\", \"price_changes\":[{\"asset_id\":\"8761897749749422724209054078244794145777693856614463256546737399611489089783\", \"price\":\"0.13\", \"size\":\"37.7\", \"side\":\"BUY\", \"hash\":\"7c2c30cc4d133a6c9f9403e78a8bf85e573302b0\", \"best_bid\":\"0.2\", \"best_ask\":\"0.22\"}, {\"asset_id\":\"14965588658799411272385430903075831224615961675357217884735713260981483529984\", \"price\":\"0.87\", \"size\":\"37.7\", \"side\":\"SELL\", \"hash\":\"68dc358650051a825f72d577a18f76c710312ce3\", \"best_bid\":\"0.78\", \"best_ask\":\"0.8\"}], \"timestamp\":\"1785208418620\", \"event_type\":\"price_change\"}","received_at":"2026-07-28T03:13:38.635462Z","schema_version":"clob-market-ws.price_change.v1","sequence":null,"server_hash":null,"server_timestamp":"1785208418620","session_id":"3e519d9098404c15b234d96025eb1a2b","source":"clob_market_ws"},"received_at":"2026-07-28T03:13:38.635462Z","record_id":"fb83b06e47a6cc9017c8ee3e330fe01b0185e4130822c94b52a440f2822511c7","schema_fingerprint":"4aa3821a28b0b7c2400bc59aba4bcc0a76e971dadd19610d3ad38c768e124dc7","schema_version":"edge-lab-recorder.raw.v1","sequence":null,"source":"clob_market_ws"}
{"event_at":"2026-07-28T03:13:38.621000Z","event_fingerprint":"9dbf026d0e09c7c29ef856526be5f342e2136fd54293b46c8c17817aa1b4d9b2","payload":{"connection_id":"a6b55582af5f430fb37ad02bf0922475","event_at":"2026-07-28T03:13:38.621000Z","event_type":"price_change","frame_hash":"54199d7ed7b26a999dfe376d69248aca4702656299450756598520f73bcd9faf","frame_index":0,"kind":"data","monotonic_ns":310401672195333,"payload":{"event_type":"price_change","market":"0x779291bef19b6709f61e9764a954aafe9ffae488d50ae674aabdcb4f248006d5","price_changes":[{"asset_id":"8761897749749422724209054078244794145777693856614463256546737399611489089783","best_ask":"0.22","best_bid":"0.2","hash":"b023856d67c162e7e5f27f11d02e4d7e21bbfc11","price":"0.12","side":"BUY","size":"76.34"},{"asset_id":"14965588658799411272385430903075831224615961675357217884735713260981483529984","best_ask":"0.8","best_bid":"0.78","hash":"fd50c5711b5fe3377a95d73067c33dc4366aa51c","price":"0.88","side":"SELL","size":"76.34"}],"timestamp":"1785208418621"},"payload_hash":"0ce70ddc23f490bb4569cb25099a899ef2461c4e3f899a43c9c81a4d973cf3eb","raw_frame":"{\"market\":\"0x779291bef19b6709f61e9764a954aafe9ffae488d50ae674aabdcb4f248006d5\", \"price_changes\":[{\"asset_id\":\"8761897749749422724209054078244794145777693856614463256546737399611489089783\", \"price\":\"0.12\", \"size\":\"76.34\", \"side\":\"BUY\", \"hash\":\"b023856d67c162e7e5f27f11d02e4d7e21bbfc11\", \"best_bid\":\"0.2\", \"best_ask\":\"0.22\"}, {\"asset_id\":\"14965588658799411272385430903075831224615961675357217884735713260981483529984\", \"price\":\"0.88\", \"size\":\"76.34\", \"side\":\"SELL\", \"hash\":\"fd50c5711b5fe3377a95d73067c33dc4366aa51c\", \"best_bid\":\"0.78\", \"best_ask\":\"0.8\"}], \"timestamp\":\"1785208418621\", \"event_type\":\"price_change\"}","received_at":"2026-07-28T03:13:38.636982Z","schema_version":"clob-market-ws.price_change.v1","sequence":null,"server_hash":null,"server_timestamp":"1785208418621","session_id":"3e519d9098404c15b234d96025eb1a2b","source":"clob_market_ws"},"received_at":"2026-07-28T03:13:38.636982Z","record_id":"314387871bc045a27900b85ffcf5e199c097087bd9f6ac230214a6c3c2b60b14","schema_fingerprint":"4aa3821a28b0b7c2400bc59aba4bcc0a76e971dadd19610d3ad38c768e124dc7","schema_version":"edge-lab-recorder.raw.v1","sequence":null,"source":"clob_market_ws"}
{"event_at":"2026-07-28T03:13:38.621000Z","event_fingerprint":"3671b8b23eea8ff86d81cc6334cc63327cea7717cddd967936cadef86e58ea40","payload":{"connection_id":"a6b55582af5f430fb37ad02bf0922475","event_at":"2026-07-28T03:13:38.621000Z","event_type":"price_change","frame_hash":"fee60e55774c1ac72f92e669165980a6df015a9fc24de0c60e070db2b838712a","frame_index":0,"kind":"data","monotonic_ns":310401673677708,"payload":{"event_type":"price_change","market":"0x779291bef19b6709f61e9764a954aafe9ffae488d50ae674aabdcb4f248006d5","price_changes":[{"asset_id":"8761897749749422724209054078244794145777693856614463256546737399611489089783","best_ask":"0.22","best_bid":"0.2","hash":"aef7f1da9049d5c604f806351c35fa0446d06ab0","price":"0.12","side":"BUY","size":"56.34"},{"asset_id":"14965588658799411272385430903075831224615961675357217884735713260981483529984","best_ask":"0.8","best_bid":"0.78","hash":"36ae465e4d4ed6e055f77d8276cf3dee8b229b51","price":"0.88","side":"SELL","size":"56.34"}],"timestamp":"1785208418621"},"payload_hash":"fc7d35dbf01fb2f86aaf9209631860c64ccc6d5811709c00e9d03ab75bb0ea36","raw_frame":"{\"market\":\"0x779291bef19b6709f61e9764a954aafe9ffae488d50ae674aabdcb4f248006d5\", \"price_changes\":[{\"asset_id\":\"8761897749749422724209054078244794145777693856614463256546737399611489089783\", \"price\":\"0.12\", \"size\":\"56.34\", \"side\":\"BUY\", \"hash\":\"aef7f1da9049d5c604f806351c35fa0446d06ab0\", \"best_bid\":\"0.2\", \"best_ask\":\"0.22\"}, {\"asset_id\":\"14965588658799411272385430903075831224615961675357217884735713260981483529984\", \"price\":\"0.88\", \"size\":\"56.34\", \"side\":\"SELL\", \"hash\":\"36ae465e4d4ed6e055f77d8276cf3dee8b229b51\", \"best_bid\":\"0.78\", \"best_ask\":\"0.8\"}], \"timestamp\":\"1785208418621\", \"event_type\":\"price_change\"}","received_at":"2026-07-28T03:13:38.638464Z","schema_version":"clob-market-ws.price_change.v1","sequence":null,"server_hash":null,"server_timestamp":"1785208418621","session_id":"3e519d9098404c15b234d96025eb1a2b","source":"clob_market_ws"},"received_at":"2026-07-28T03:13:38.638464Z","record_id":"5375ee67f823b104da7f05882223543eb081e9e2b343cb2bccfbb030301480b0","schema_fingerprint":"4aa3821a28b0b7c2400bc59aba4bcc0a76e971dadd19610d3ad38c768e124dc7","schema_version":"edge-lab-recorder.raw.v1","sequence":null,"source":"clob_market_ws"}
{"event_at":"2026-07-28T03:13:38.622000Z","event_fingerprint":"ecd0fc949fa70ad1586dfaaa81c12cd9685248b68c8ae305462b80268c8e357f","payload":{"connection_id":"a6b55582af5f430fb37ad02bf0922475","event_at":"2026-07-28T03:13:38.622000Z","event_type":"price_change","frame_hash":"11ada93d8f3e358a95668623b457679a7a1ea1a94c37d75c4860981f1a87cef8","frame_index":0,"kind":"data","monotonic_ns":310401675161208,"payload":{"event_type":"price_change","market":"0x779291bef19b6709f61e9764a954aafe9ffae488d50ae674aabdcb4f248006d5","price_changes":[{"asset_id":"8761897749749422724209054078244794145777693856614463256546737399611489089783","best_ask":"0.22","best_bid":"0.2","hash":"87efbf734b230246cd3baa3126d7e63679202896","price":"0.16","side":"BUY","size":"10"},{"asset_id":"14965588658799411272385430903075831224615961675357217884735713260981483529984","best_ask":"0.8","best_bid":"0.78","hash":"d054f253324ea37db3fbd2d88384e685655d1c61","price":"0.84","side":"SELL","size":"10"}],"timestamp":"1785208418622"},"payload_hash":"a2135bcf077507d016ed8822d493b56ab95d8308b5ec0015f97d67997e6eb5a1","raw_frame":"{\"market\":\"0x779291bef19b6709f61e9764a954aafe9ffae488d50ae674aabdcb4f248006d5\", \"price_changes\":[{\"asset_id\":\"8761897749749422724209054078244794145777693856614463256546737399611489089783\", \"price\":\"0.16\", \"size\":\"10\", \"side\":\"BUY\", \"hash\":\"87efbf734b230246cd3baa3126d7e63679202896\", \"best_bid\":\"0.2\", \"best_ask\":\"0.22\"}, {\"asset_id\":\"14965588658799411272385430903075831224615961675357217884735713260981483529984\", \"price\":\"0.84\", \"size\":\"10\", \"side\":\"SELL\", \"hash\":\"d054f253324ea37db3fbd2d88384e685655d1c61\", \"best_bid\":\"0.78\", \"best_ask\":\"0.8\"}], \"timestamp\":\"1785208418622\", \"event_type\":\"price_change\"}","received_at":"2026-07-28T03:13:38.639948Z","schema_version":"clob-market-ws.price_change.v1","sequence":null,"server_hash":null,"server_timestamp":"1785208418622","session_id":"3e519d9098404c15b234d96025eb1a2b","source":"clob_market_ws"},"received_at":"2026-07-28T03:13:38.639948Z","record_id":"e74c0202e6580bebe0033cf8f74565b9fa784d3a14b9a7e463422da4837ea523","schema_fingerprint":"4aa3821a28b0b7c2400bc59aba4bcc0a76e971dadd19610d3ad38c768e124dc7","schema_version":"edge-lab-recorder.raw.v1","sequence":null,"source":"clob_market_ws"}
{"event_at":"2026-07-28T03:13:38.623000Z","event_fingerprint":"e8c4c6ed49769416bd0c891b795c121cf2dc5160f46fbf554cea691d20aa9cd5","payload":{"connection_id":"a6b55582af5f430fb37ad02bf0922475","event_at":"2026-07-28T03:13:38.623000Z","event_type":"price_change","frame_hash":"248239258002d5940a643df60801f08e89c637e657232d906fa57eb9063f9487","frame_index":0,"kind":"data","monotonic_ns":310401676668041,"payload":{"event_type":"price_change","market":"0x779291bef19b6709f61e9764a954aafe9ffae488d50ae674aabdcb4f248006d5","price_changes":[{"asset_id":"8761897749749422724209054078244794145777693856614463256546737399611489089783","best_ask":"0.22","best_bid":"0.2","hash":"095a94a8dca935caa240b00bd2df0809a0cbfa41","price":"0.18","side":"BUY","size":"10"},{"asset_id":"14965588658799411272385430903075831224615961675357217884735713260981483529984","best_ask":"0.8","best_bid":"0.78","hash":"bb3c2dcb7f8141875befd79b67d3ae7d11e77c8a","price":"0.82","side":"SELL","size":"10"}],"timestamp":"1785208418623"},"payload_hash":"5ece3132068c82f5bf79f970aac59364e7c8cf85570bccd2b57c2bc3d999bbad","raw_frame":"{\"market\":\"0x779291bef19b6709f61e9764a954aafe9ffae488d50ae674aabdcb4f248006d5\", \"price_changes\":[{\"asset_id\":\"8761897749749422724209054078244794145777693856614463256546737399611489089783\", \"price\":\"0.18\", \"size\":\"10\", \"side\":\"BUY\", \"hash\":\"095a94a8dca935caa240b00bd2df0809a0cbfa41\", \"best_bid\":\"0.2\", \"best_ask\":\"0.22\"}, {\"asset_id\":\"14965588658799411272385430903075831224615961675357217884735713260981483529984\", \"price\":\"0.82\", \"size\":\"10\", \"side\":\"SELL\", \"hash\":\"bb3c2dcb7f8141875befd79b67d3ae7d11e77c8a\", \"best_bid\":\"0.78\", \"best_ask\":\"0.8\"}], \"timestamp\":\"1785208418623\", \"event_type\":\"price_change\"}","received_at":"2026-07-28T03:13:38.641456Z","schema_version":"clob-market-ws.price_change.v1","sequence":null,"server_hash":null,"server_timestamp":"1785208418623","session_id":"3e519d9098404c15b234d96025eb1a2b","source":"clob_market_ws"},"received_at":"2026-07-28T03:13:38.641456Z","record_id":"b91394a940b0ac5c4bc8a80afbb4d38e1551cf8aa3300dcbbc72fc2844a66e61","schema_fingerprint":"4aa3821a28b0b7c2400bc59aba4bcc0a76e971dadd19610d3ad38c768e124dc7","schema_version":"edge-lab-recorder.raw.v1","sequence":null,"source":"clob_market_ws"}
{"event_at":"2026-07-28T03:13:38.624000Z","event_fingerprint":"1961ee53bf0388ac480bfa41c0e48d3909322ca367e1902598347067e192c545","payload":{"connection_id":"a6b55582af5f430fb37ad02bf0922475","event_at":"2026-07-28T03:13:38.624000Z","event_type":"price_change","frame_hash":"c358adb89d096682e487e01b999b6c691e0734cdd8343e7f6dc21f8cd5594773","frame_index":0,"kind":"data","monotonic_ns":310401678119958,"payload":{"event_type":"price_change","market":"0x779291bef19b6709f61e9764a954aafe9ffae488d50ae674aabdcb4f248006d5","price_changes":[{"asset_id":"8761897749749422724209054078244794145777693856614463256546737399611489089783","best_ask":"0.22","best_bid":"0.2","hash":"ea62d94fe698e713a16316ce873494113c0dab2a","price":"0.16","side":"BUY","size":"30"},{"asset_id":"14965588658799411272385430903075831224615961675357217884735713260981483529984","best_ask":"0.8","best_bid":"0.78","hash":"9fe5b5cf2a4dc09bdf53d9c3d05f5a30cdbffb54","price":"0.84","side":"SELL","size":"30"}],"timestamp":"1785208418624"},"payload_hash":"63495e7d8eef3961417248bf76d61b49cfdd346c87367ae8c9a3b501627342ec","raw_frame":"{\"market\":\"0x779291bef19b6709f61e9764a954aafe9ffae488d50ae674aabdcb4f248006d5\", \"price_changes\":[{\"asset_id\":\"8761897749749422724209054078244794145777693856614463256546737399611489089783\", \"price\":\"0.16\", \"size\":\"30\", \"side\":\"BUY\", \"hash\":\"ea62d94fe698e713a16316ce873494113c0dab2a\", \"best_bid\":\"0.2\", \"best_ask\":\"0.22\"}, {\"asset_id\":\"14965588658799411272385430903075831224615961675357217884735713260981483529984\", \"price\":\"0.84\", \"size\":\"30\", \"side\":\"SELL\", \"hash\":\"9fe5b5cf2a4dc09bdf53d9c3d05f5a30cdbffb54\", \"best_bid\":\"0.78\", \"best_ask\":\"0.8\"}], \"timestamp\":\"1785208418624\", \"event_type\":\"price_change\"}","received_at":"2026-07-28T03:13:38.642907Z","schema_version":"clob-market-ws.price_change.v1","sequence":null,"server_hash":null,"server_timestamp":"1785208418624","session_id":"3e519d9098404c15b234d96025eb1a2b","source":"clob_market_ws"},"received_at":"2026-07-28T03:13:38.642907Z","record_id":"568b786755acaef007a962632bce79c9d1cd3091bad064fb458b14ed4328bb9c","schema_fingerprint":"4aa3821a28b0b7c2400bc59aba4bcc0a76e971dadd19610d3ad38c768e124dc7","schema_version":"edge-lab-recorder.raw.v1","sequence":null,"source":"clob_market_ws"}
{"event_at":"2026-07-28T03:13:38.625000Z","event_fingerprint":"83b70baf3700bc0936f39d207917626860083c016f772f1d16ca61744c9c7b2a","payload":{"connection_id":"a6b55582af5f430fb37ad02bf0922475","event_at":"2026-07-28T03:13:38.625000Z","event_type":"price_change","frame_hash":"8f51ff16fdb2576eea3832b89bf076aa804f4c604aac9204b9cdd88c73e5174e","frame_index":0,"kind":"data","monotonic_ns":310401679576250,"payload":{"event_type":"price_change","market":"0x779291bef19b6709f61e9764a954aafe9ffae488d50ae674aabdcb4f248006d5","price_changes":[{"asset_id":"8761897749749422724209054078244794145777693856614463256546737399611489089783","best_ask":"0.22","best_bid":"0.2","hash":"033f2a7aec661737caf081f76f424412008a737b","price":"0.12","side":"BUY","size":"48"},{"asset_id":"14965588658799411272385430903075831224615961675357217884735713260981483529984","best_ask":"0.8","best_bid":"0.78","hash":"27a701d5395d94341322da355278a1366f5c423f","price":"0.88","side":"SELL","size":"48"}],"timestamp":"1785208418625"},"payload_hash":"8b53f85f14d307e65d78f77d6ebbea5fcc25fbb7473c97ac096aee33afc42855","raw_frame":"{\"market\":\"0x779291bef19b6709f61e9764a954aafe9ffae488d50ae674aabdcb4f248006d5\", \"price_changes\":[{\"asset_id\":\"8761897749749422724209054078244794145777693856614463256546737399611489089783\", \"price\":\"0.12\", \"size\":\"48\", \"side\":\"BUY\", \"hash\":\"033f2a7aec661737caf081f76f424412008a737b\", \"best_bid\":\"0.2\", \"best_ask\":\"0.22\"}, {\"asset_id\":\"14965588658799411272385430903075831224615961675357217884735713260981483529984\", \"price\":\"0.88\", \"size\":\"48\", \"side\":\"SELL\", \"hash\":\"27a701d5395d94341322da355278a1366f5c423f\", \"best_bid\":\"0.78\", \"best_ask\":\"0.8\"}], \"timestamp\":\"1785208418625\", \"event_type\":\"price_change\"}","received_at":"2026-07-28T03:13:38.644363Z","schema_version":"clob-market-ws.price_change.v1","sequence":null,"server_hash":null,"server_timestamp":"1785208418625","session_id":"3e519d9098404c15b234d96025eb1a2b","source":"clob_market_ws"},"received_at":"2026-07-28T03:13:38.644363Z","record_id":"ced8d7d044a089ecde1da3ce537a8a17ad0afd1bd0643327a2b7a76ddd61d49d","schema_fingerprint":"4aa3821a28b0b7c2400bc59aba4bcc0a76e971dadd19610d3ad38c768e124dc7","schema_version":"edge-lab-recorder.raw.v1","sequence":null,"source":"clob_market_ws"}
{"event_at":"2026-07-28T03:13:38.625000Z","event_fingerprint":"6ef9e0a46e47e8c8c9b002f41797f51a5719d9ba2af3e60a0d67d2e614157c93","payload":{"connection_id":"a6b55582af5f430fb37ad02bf0922475","event_at":"2026-07-28T03:13:38.625000Z","event_type":"price_change","frame_hash":"e429a2b69d5bfe863b5a20045b54a6ec403791178d382eb029101d8a709d8541","frame_index":0,"kind":"data","monotonic_ns":310401681046208,"payload":{"event_type":"price_change","market":"0x779291bef19b6709f61e9764a954aafe9ffae488d50ae674aabdcb4f248006d5","price_changes":[{"asset_id":"8761897749749422724209054078244794145777693856614463256546737399611489089783","best_ask":"0.22","best_bid":"0.2","hash":"d8f4d5e1b9f25df36dfc5197b17e77fc85321cdd","price":"0.17","side":"BUY","size":"10"},{"asset_id":"14965588658799411272385430903075831224615961675357217884735713260981483529984","best_ask":"0.8","best_bid":"0.78","hash":"5074d7c8f51071521560a2c6f4c90ceb3d35f76c","price":"0.83","side":"SELL","size":"10"}],"timestamp":"1785208418625"},"payload_hash":"e13c74d838a8eda0a4e0f9168007eb6e8be66646203b77aa4b57d9d72027900c","raw_frame":"{\"market\":\"0x779291bef19b6709f61e9764a954aafe9ffae488d50ae674aabdcb4f248006d5\", \"price_changes\":[{\"asset_id\":\"8761897749749422724209054078244794145777693856614463256546737399611489089783\", \"price\":\"0.17\", \"size\":\"10\", \"side\":\"BUY\", \"hash\":\"d8f4d5e1b9f25df36dfc5197b17e77fc85321cdd\", \"best_bid\":\"0.2\", \"best_ask\":\"0.22\"}, {\"asset_id\":\"14965588658799411272385430903075831224615961675357217884735713260981483529984\", \"price\":\"0.83\", \"size\":\"10\", \"side\":\"SELL\", \"hash\":\"5074d7c8f51071521560a2c6f4c90ceb3d35f76c\", \"best_bid\":\"0.78\", \"best_ask\":\"0.8\"}], \"timestamp\":\"1785208418625\", \"event_type\":\"price_change\"}","received_at":"2026-07-28T03:13:38.645834Z","schema_version":"clob-market-ws.price_change.v1","sequence":null,"server_hash":null,"server_timestamp":"1785208418625","session_id":"3e519d9098404c15b234d96025eb1a2b","source":"clob_market_ws"},"received_at":"2026-07-28T03:13:38.645834Z","record_id":"f605e1618be12027f8e768a9f12b25f2a44855de39a8f8eddb25565f3876a4f1","schema_fingerprint":"4aa3821a28b0b7c2400bc59aba4bcc0a76e971dadd19610d3ad38c768e124dc7","schema_version":"edge-lab-recorder.raw.v1","sequence":null,"source":"clob_market_ws"}
{"event_at":"2026-07-28T03:13:38.626000Z","event_fingerprint":"9310090ac9066437cd462dcf0d923e563eeb44e1f359804a353875e7b38a2da7","payload":{"connection_id":"a6b55582af5f430fb37ad02bf0922475","event_at":"2026-07-28T03:13:38.626000Z","event_type":"price_change","frame_hash":"dddde2e0daeb2315bc5807ec81ff9f9d919bf925ace5171a4f2ea0406d552756","frame_index":0,"kind":"data","monotonic_ns":310401682463333,"payload":{"event_type":"price_change","market":"0x779291bef19b6709f61e9764a954aafe9ffae488d50ae674aabdcb4f248006d5","price_changes":[{"asset_id":"8761897749749422724209054078244794145777693856614463256546737399611489089783","best_ask":"0.22","best_bid":"0.2","hash":"29da4820fb9b2e2873d2136b03df2800b17dc4b8","price":"0.18","side":"BUY","size":"30"},{"asset_id":"14965588658799411272385430903075831224615961675357217884735713260981483529984","best_ask":"0.8","best_bid":"0.78","hash":"46d4392c81a4388c68ef5b5746c5c09a641f2ffe","price":"0.82","side":"SELL","size":"30"}],"timestamp":"1785208418626"},"payload_hash":"0e218c47b3e5a7e0357f9cb4de3271619b8c085ffc0a0cac825902735b8cb70c","raw_frame":"{\"market\":\"0x779291bef19b6709f61e9764a954aafe9ffae488d50ae674aabdcb4f248006d5\", \"price_changes\":[{\"asset_id\":\"8761897749749422724209054078244794145777693856614463256546737399611489089783\", \"price\":\"0.18\", \"size\":\"30\", \"side\":\"BUY\", \"hash\":\"29da4820fb9b2e2873d2136b03df2800b17dc4b8\", \"best_bid\":\"0.2\", \"best_ask\":\"0.22\"}, {\"asset_id\":\"14965588658799411272385430903075831224615961675357217884735713260981483529984\", \"price\":\"0.82\", \"size\":\"30\", \"side\":\"SELL\", \"hash\":\"46d4392c81a4388c68ef5b5746c5c09a641f2ffe\", \"best_bid\":\"0.78\", \"best_ask\":\"0.8\"}], \"timestamp\":\"1785208418626\", \"event_type\":\"price_change\"}","received_at":"2026-07-28T03:13:38.647250Z","schema_version":"clob-market-ws.price_change.v1","sequence":null,"server_hash":null,"server_timestamp":"1785208418626","session_id":"3e519d9098404c15b234d96025eb1a2b","source":"clob_market_ws"},"received_at":"2026-07-28T03:13:38.647250Z","record_id":"fed12ce7e01d37ee9f795e2abfdfc3f81a49c106de81667ecaf74a6d0f8e0eff","schema_fingerprint":"4aa3821a28b0b7c2400bc59aba4bcc0a76e971dadd19610d3ad38c768e124dc7","schema_version":"edge-lab-recorder.raw.v1","sequence":null,"source":"clob_market_ws"}
{"event_at":"2026-07-28T03:13:38.627000Z","event_fingerprint":"debac50b85cec942d1257698c2f19e15eb3a79bd8fa11e15e5fe79d267119a99","payload":{"connection_id":"a6b55582af5f430fb37ad02bf0922475","event_at":"2026-07-28T03:13:38.627000Z","event_type":"price_change","frame_hash":"56ed0a40b220eb50b8adf2b56a6cbd53e8d995295aef9e3e59ee115bef5b7f0b","frame_index":0,"kind":"data","monotonic_ns":310401683931583,"payload":{"event_type":"price_change","market":"0x779291bef19b6709f61e9764a954aafe9ffae488d50ae674aabdcb4f248006d5","price_changes":[{"asset_id":"8761897749749422724209054078244794145777693856614463256546737399611489089783","best_ask":"0.22","best_bid":"0.2","hash":"5b658324ec87921e5cdda37a6c48e62494a47a5c","price":"0.13","side":"BUY","size":"30"},{"asset_id":"14965588658799411272385430903075831224615961675357217884735713260981483529984","best_ask":"0.8","best_bid":"0.78","hash":"4dfb0083222115201130c923b7e238828c0eb94c","price":"0.87","side":"SELL","size":"30"}],"timestamp":"1785208418627"},"payload_hash":"fa9ca9af3965904541d29c033e38957f75f7db8d34f799ebf19d172659a3341c","raw_frame":"{\"market\":\"0x779291bef19b6709f61e9764a954aafe9ffae488d50ae674aabdcb4f248006d5\", \"price_changes\":[{\"asset_id\":\"8761897749749422724209054078244794145777693856614463256546737399611489089783\", \"price\":\"0.13\", \"size\":\"30\", \"side\":\"BUY\", \"hash\":\"5b658324ec87921e5cdda37a6c48e62494a47a5c\", \"best_bid\":\"0.2\", \"best_ask\":\"0.22\"}, {\"asset_id\":\"14965588658799411272385430903075831224615961675357217884735713260981483529984\", \"price\":\"0.87\", \"size\":\"30\", \"side\":\"SELL\", \"hash\":\"4dfb0083222115201130c923b7e238828c0eb94c\", \"best_bid\":\"0.78\", \"best_ask\":\"0.8\"}], \"timestamp\":\"1785208418627\", \"event_type\":\"price_change\"}","received_at":"2026-07-28T03:13:38.648719Z","schema_version":"clob-market-ws.price_change.v1","sequence":null,"server_hash":null,"server_timestamp":"1785208418627","session_id":"3e519d9098404c15b234d96025eb1a2b","source":"clob_market_ws"},"received_at":"2026-07-28T03:13:38.648719Z","record_id":"655073b806436f2c7a729bbd7b77002f248fc44ed3bf4377ffc0eb2f21ad7a13","schema_fingerprint":"4aa3821a28b0b7c2400bc59aba4bcc0a76e971dadd19610d3ad38c768e124dc7","schema_version":"edge-lab-recorder.raw.v1","sequence":null,"source":"clob_market_ws"}
{"event_at":"2026-07-28T03:13:38.627000Z","event_fingerprint":"216ad147f727e8085a8f47626a0cfb11d446d3f40adfa8ac8065cb78fe409251","payload":{"connection_id":"a6b55582af5f430fb37ad02bf0922475","event_at":"2026-07-28T03:13:38.627000Z","event_type":"price_change","frame_hash":"eda1d5156976afe78173b8b82e8d6eaf5f1755c4a10e7671706f4a43e30a56ee","frame_index":0,"kind":"data","monotonic_ns":310401685459791,"payload":{"event_type":"price_change","market":"0x779291bef19b6709f61e9764a954aafe9ffae488d50ae674aabdcb4f248006d5","price_changes":[{"asset_id":"14965588658799411272385430903075831224615961675357217884735713260981483529984","best_ask":"0.8","best_bid":"0.78","hash":"aadaad53bc72414d7ee9d75cec0a2c08be4c0a92","price":"0.88","side":"SELL","size":"30"},{"asset_id":"8761897749749422724209054078244794145777693856614463256546737399611489089783","best_ask":"0.22","best_bid":"0.2","hash":"d248ff086a91dfaf34cacae70a16f751143097fa","price":"0.12","side":"BUY","size":"30"}],"timestamp":"1785208418627"},"payload_hash":"38e40c5b23c527c7580ba6769be723ca0969c0510fab24a7633da1fac9b51b55","raw_frame":"{\"market\":\"0x779291bef19b6709f61e9764a954aafe9ffae488d50ae674aabdcb4f248006d5\", \"price_changes\":[{\"asset_id\":\"14965588658799411272385430903075831224615961675357217884735713260981483529984\", \"price\":\"0.88\", \"size\":\"30\", \"side\":\"SELL\", \"hash\":\"aadaad53bc72414d7ee9d75cec0a2c08be4c0a92\", \"best_bid\":\"0.78\", \"best_ask\":\"0.8\"}, {\"asset_id\":\"8761897749749422724209054078244794145777693856614463256546737399611489089783\", \"price\":\"0.12\", \"size\":\"30\", \"side\":\"BUY\", \"hash\":\"d248ff086a91dfaf34cacae70a16f751143097fa\", \"best_bid\":\"0.2\", \"best_ask\":\"0.22\"}], \"timestamp\":\"1785208418627\", \"event_type\":\"price_change\"}","received_at":"2026-07-28T03:13:38.650246Z","schema_version":"clob-market-ws.price_change.v1","sequence":null,"server_hash":null,"server_timestamp":"1785208418627","session_id":"3e519d9098404c15b234d96025eb1a2b","source":"clob_market_ws"},"received_at":"2026-07-28T03:13:38.650246Z","record_id":"475fcaa8f6ad3853eb647b89289518be3273fe4abfcf57c828d6a43072c6f06c","schema_fingerprint":"4aa3821a28b0b7c2400bc59aba4bcc0a76e971dadd19610d3ad38c768e124dc7","schema_version":"edge-lab-recorder.raw.v1","sequence":null,"source":"clob_market_ws"}
{"event_at":"2026-07-28T03:13:38.627000Z","event_fingerprint":"294f2d1fe039a64b1154bac6d6eeaee2955755f2ce14e0cae1bebddef8f5fdad","payload":{"connection_id":"a6b55582af5f430fb37ad02bf0922475","event_at":"2026-07-28T03:13:38.627000Z","event_type":"price_change","frame_hash":"c1fafad61367b80e14fcb1e7bd7f1c8f4966d8954440df2b701e0bc01be5eb18","frame_index":0,"kind":"data","monotonic_ns":310401686973541,"payload":{"event_type":"price_change","market":"0x779291bef19b6709f61e9764a954aafe9ffae488d50ae674aabdcb4f248006d5","price_changes":[{"asset_id":"14965588658799411272385430903075831224615961675357217884735713260981483529984","best_ask":"0.8","best_bid":"0.78","hash":"9fd85903fe89f3fc671312fbb78625d4565bf475","price":"0.01","side":"BUY","size":"5360.02"},{"asset_id":"8761897749749422724209054078244794145777693856614463256546737399611489089783","best_ask":"0.22","best_bid":"0.2","hash":"a81a07d447a1dd117bb572dc967b37d8ceb54ba8","price":"0.99","side":"SELL","size":"5360.02"}],"timestamp":"1785208418627"},"payload_hash":"1850b1235082266b6a3ae431de151693f52dbcef3bf1bb39d13b104abbe92b74","raw_frame":"{\"market\":\"0x779291bef19b6709f61e9764a954aafe9ffae488d50ae674aabdcb4f248006d5\", \"price_changes\":[{\"asset_id\":\"14965588658799411272385430903075831224615961675357217884735713260981483529984\", \"price\":\"0.01\", \"size\":\"5360.02\", \"side\":\"BUY\", \"hash\":\"9fd85903fe89f3fc671312fbb78625d4565bf475\", \"best_bid\":\"0.78\", \"best_ask\":\"0.8\"}, {\"asset_id\":\"8761897749749422724209054078244794145777693856614463256546737399611489089783\", \"price\":\"0.99\", \"size\":\"5360.02\", \"side\":\"SELL\", \"hash\":\"a81a07d447a1dd117bb572dc967b37d8ceb54ba8\", \"best_bid\":\"0.2\", \"best_ask\":\"0.22\"}], \"timestamp\":\"1785208418627\", \"event_type\":\"price_change\"}","received_at":"2026-07-28T03:13:38.651760Z","schema_version":"clob-market-ws.price_change.v1","sequence":null,"server_hash":null,"server_timestamp":"1785208418627","session_id":"3e519d9098404c15b234d96025eb1a2b","source":"clob_market_ws"},"received_at":"2026-07-28T03:13:38.651760Z","record_id":"d01347433cfde7c06ea73af020807a702ac9008fb1a5c715cc1fe621864b85d5","schema_fingerprint":"4aa3821a28b0b7c2400bc59aba4bcc0a76e971dadd19610d3ad38c768e124dc7","schema_version":"edge-lab-recorder.raw.v1","sequence":null,"source":"clob_market_ws"}
{"event_at":"2026-07-28T03:13:38.629000Z","event_fingerprint":"2d9c8d97922df1b21da88b1d065e0f02a70dc149c999a4201fc46e181be4a147","payload":{"connection_id":"a6b55582af5f430fb37ad02bf0922475","event_at":"2026-07-28T03:13:38.629000Z","event_type":"price_change","frame_hash":"b8bd79d9f6ed4c8a81cebf3b7dbf8898b99fccde7a3df1f35f680cb9fa4c84d9","frame_index":0,"kind":"data","monotonic_ns":310401688450458,"payload":{"event_type":"price_change","market":"0x779291bef19b6709f61e9764a954aafe9ffae488d50ae674aabdcb4f248006d5","price_changes":[{"asset_id":"8761897749749422724209054078244794145777693856614463256546737399611489089783","best_ask":"0.22","best_bid":"0.2","hash":"8f637d8cad095ca57add7f818b07523d52a88c10","price":"0.19","side":"BUY","size":"30"},{"asset_id":"14965588658799411272385430903075831224615961675357217884735713260981483529984","best_ask":"0.8","best_bid":"0.78","hash":"0316d38dac05ab72da539ebabca5ffd18691ccd8","price":"0.81","side":"SELL","size":"30"}],"timestamp":"1785208418629"},"payload_hash":"364f7288eb9e1abdc9d1f4b395349d4848ac3f97e36bf9c0af7608e88292b56b","raw_frame":"{\"market\":\"0x779291bef19b6709f61e9764a954aafe9ffae488d50ae674aabdcb4f248006d5\", \"price_changes\":[{\"asset_id\":\"8761897749749422724209054078244794145777693856614463256546737399611489089783\", \"price\":\"0.19\", \"size\":\"30\", \"side\":\"BUY\", \"hash\":\"8f637d8cad095ca57add7f818b07523d52a88c10\", \"best_bid\":\"0.2\", \"best_ask\":\"0.22\"}, {\"asset_id\":\"14965588658799411272385430903075831224615961675357217884735713260981483529984\", \"price\":\"0.81\", \"size\":\"30\", \"side\":\"SELL\", \"hash\":\"0316d38dac05ab72da539ebabca5ffd18691ccd8\", \"best_bid\":\"0.78\", \"best_ask\":\"0.8\"}], \"timestamp\":\"1785208418629\", \"event_type\":\"price_change\"}","received_at":"2026-07-28T03:13:38.653237Z","schema_version":"clob-market-ws.price_change.v1","sequence":null,"server_hash":null,"server_timestamp":"1785208418629","session_id":"3e519d9098404c15b234d96025eb1a2b","source":"clob_market_ws"},"received_at":"2026-07-28T03:13:38.653237Z","record_id":"773b73ca1287fe8144cb4e2aa2b8492311841f66afb9f349f08731bb33bb88f2","schema_fingerprint":"4aa3821a28b0b7c2400bc59aba4bcc0a76e971dadd19610d3ad38c768e124dc7","schema_version":"edge-lab-recorder.raw.v1","sequence":null,"source":"clob_market_ws"}
{"event_at":"2026-07-28T03:13:38.630000Z","event_fingerprint":"acd0c9e105479c625b00ecf642a4a84ad0d12abfffd1662fed90a092d094d5b2","payload":{"connection_id":"a6b55582af5f430fb37ad02bf0922475","event_at":"2026-07-28T03:13:38.630000Z","event_type":"price_change","frame_hash":"d1a983443ca4638c7a74bd63a872dd0dd5da419fb8ef2c0cd4705991881fcd35","frame_index":0,"kind":"data","monotonic_ns":310401689910041,"payload":{"event_type":"price_change","market":"0x779291bef19b6709f61e9764a954aafe9ffae488d50ae674aabdcb4f248006d5","price_changes":[{"asset_id":"8761897749749422724209054078244794145777693856614463256546737399611489089783","best_ask":"0.22","best_bid":"0.2","hash":"b0b089053935dd9d4a5022e2f9a84fff15d36432","price":"0.16","side":"BUY","size":"74"},{"asset_id":"14965588658799411272385430903075831224615961675357217884735713260981483529984","best_ask":"0.8","best_bid":"0.78","hash":"a41fd221bebbc60a3f201db7c870ebec5a863a37","price":"0.84","side":"SELL","size":"74"}],"timestamp":"1785208418630"},"payload_hash":"c2f4c6cda8940e128b25931055bc6c338765453f3a7dab675c2ae2ba75141e84","raw_frame":"{\"market\":\"0x779291bef19b6709f61e9764a954aafe9ffae488d50ae674aabdcb4f248006d5\", \"price_changes\":[{\"asset_id\":\"8761897749749422724209054078244794145777693856614463256546737399611489089783\", \"price\":\"0.16\", \"size\":\"74\", \"side\":\"BUY\", \"hash\":\"b0b089053935dd9d4a5022e2f9a84fff15d36432\", \"best_bid\":\"0.2\", \"best_ask\":\"0.22\"}, {\"asset_id\":\"14965588658799411272385430903075831224615961675357217884735713260981483529984\", \"price\":\"0.84\", \"size\":\"74\", \"side\":\"SELL\", \"hash\":\"a41fd221bebbc60a3f201db7c870ebec5a863a37\", \"best_bid\":\"0.78\", \"best_ask\":\"0.8\"}], \"timestamp\":\"1785208418630\", \"event_type\":\"price_change\"}","received_at":"2026-07-28T03:13:38.654697Z","schema_version":"clob-market-ws.price_change.v1","sequence":null,"server_hash":null,"server_timestamp":"1785208418630","session_id":"3e519d9098404c15b234d96025eb1a2b","source":"clob_market_ws"},"received_at":"2026-07-28T03:13:38.654697Z","record_id":"dd858418734b444709a188326b3491a2c3d6cf2fd335d2ab6d3a3b82a4f05d13","schema_fingerprint":"4aa3821a28b0b7c2400bc59aba4bcc0a76e971dadd19610d3ad38c768e124dc7","schema_version":"edge-lab-recorder.raw.v1","sequence":null,"source":"clob_market_ws"}
{"event_at":"2026-07-28T03:13:38.631000Z","event_fingerprint":"3b2d3c9229232723ec7d50508772d44ab035c2174c54471199363b657bda08ae","payload":{"connection_id":"a6b55582af5f430fb37ad02bf0922475","event_at":"2026-07-28T03:13:38.631000Z","event_type":"price_change","frame_hash":"e1f5ad60a86267edf43dee00a6157325ff56966e9bdceee38dfc2c5909c13e8b","frame_index":0,"kind":"data","monotonic_ns":310401691380291,"payload":{"event_type":"price_change","market":"0x779291bef19b6709f61e9764a954aafe9ffae488d50ae674aabdcb4f248006d5","price_changes":[{"asset_id":"8761897749749422724209054078244794145777693856614463256546737399611489089783","best_ask":"0.22","best_bid":"0.2","hash":"43218c22f46a0591be727aac13104d82c124a592","price":"0.14","side":"BUY","size":"30"},{"asset_id":"14965588658799411272385430903075831224615961675357217884735713260981483529984","best_ask":"0.8","best_bid":"0.78","hash":"5f56a550c5f3cbf6ebc253107c16a040ec7e619e","price":"0.86","side":"SELL","size":"30"}],"timestamp":"1785208418631"},"payload_hash":"f0fcc608741b6cdc16ade8948e5b1b9217ed019a634e57eb6801d92b7ded05db","raw_frame":"{\"market\":\"0x779291bef19b6709f61e9764a954aafe9ffae488d50ae674aabdcb4f248006d5\", \"price_changes\":[{\"asset_id\":\"8761897749749422724209054078244794145777693856614463256546737399611489089783\", \"price\":\"0.14\", \"size\":\"30\", \"side\":\"BUY\", \"hash\":\"43218c22f46a0591be727aac13104d82c124a592\", \"best_bid\":\"0.2\", \"best_ask\":\"0.22\"}, {\"asset_id\":\"14965588658799411272385430903075831224615961675357217884735713260981483529984\", \"price\":\"0.86\", \"size\":\"30\", \"side\":\"SELL\", \"hash\":\"5f56a550c5f3cbf6ebc253107c16a040ec7e619e\", \"best_bid\":\"0.78\", \"best_ask\":\"0.8\"}], \"timestamp\":\"1785208418631\", \"event_type\":\"price_change\"}","received_at":"2026-07-28T03:13:38.656167Z","schema_version":"clob-market-ws.price_change.v1","sequence":null,"server_hash":null,"server_timestamp":"1785208418631","session_id":"3e519d9098404c15b234d96025eb1a2b","source":"clob_market_ws"},"received_at":"2026-07-28T03:13:38.656167Z","record_id":"7ce4dcbcdc66ed96092a2ae1e5d957c2519b1a26407e525f2591962017301554","schema_fingerprint":"4aa3821a28b0b7c2400bc59aba4bcc0a76e971dadd19610d3ad38c768e124dc7","schema_version":"edge-lab-recorder.raw.v1","sequence":null,"source":"clob_market_ws"}
{"event_at":"2026-07-28T03:13:38.632000Z","event_fingerprint":"3f8397750e19b34fd3e1e91a7ec705c82a15d0774859c30cf8bb84cb412ef9d8","payload":{"connection_id":"a6b55582af5f430fb37ad02bf0922475","event_at":"2026-07-28T03:13:38.632000Z","event_type":"price_change","frame_hash":"8a81308316ea2cb3c0959bb836aebe0c8381fac979bc92ac424311d9a0d96372","frame_index":0,"kind":"data","monotonic_ns":310401692832375,"payload":{"event_type":"price_change","market":"0x779291bef19b6709f61e9764a954aafe9ffae488d50ae674aabdcb4f248006d5","price_changes":[{"asset_id":"8761897749749422724209054078244794145777693856614463256546737399611489089783","best_ask":"0.22","best_bid":"0.2","hash":"9e26e47c6d2321b44dddb68308046e5b8f17e01b","price":"0.17","side":"BUY","size":"30"},{"asset_id":"14965588658799411272385430903075831224615961675357217884735713260981483529984","best_ask":"0.8","best_bid":"0.78","hash":"ae8d91170dfecc173c15fa17a0b31d888a1aa222","price":"0.83","side":"SELL","size":"30"}],"timestamp":"1785208418632"},"payload_hash":"2bf4f171822420e6e2c8e30d762d2ec75bc60f9dc8f480ad37e7242bf1bc4474","raw_frame":"{\"market\":\"0x779291bef19b6709f61e9764a954aafe9ffae488d50ae674aabdcb4f248006d5\", \"price_changes\":[{\"asset_id\":\"8761897749749422724209054078244794145777693856614463256546737399611489089783\", \"price\":\"0.17\", \"size\":\"30\", \"side\":\"BUY\", \"hash\":\"9e26e47c6d2321b44dddb68308046e5b8f17e01b\", \"best_bid\":\"0.2\", \"best_ask\":\"0.22\"}, {\"asset_id\":\"14965588658799411272385430903075831224615961675357217884735713260981483529984\", \"price\":\"0.83\", \"size\":\"30\", \"side\":\"SELL\", \"hash\":\"ae8d91170dfecc173c15fa17a0b31d888a1aa222\", \"best_bid\":\"0.78\", \"best_ask\":\"0.8\"}], \"timestamp\":\"1785208418632\", \"event_type\":\"price_change\"}","received_at":"2026-07-28T03:13:38.657619Z","schema_version":"clob-market-ws.price_change.v1","sequence":null,"server_hash":null,"server_timestamp":"1785208418632","session_id":"3e519d9098404c15b234d96025eb1a2b","source":"clob_market_ws"},"received_at":"2026-07-28T03:13:38.657619Z","record_id":"584b4fbae1ffeebea99372a7ae90d9e3598348dc894e4b8ddfd05bfbf11932f4","schema_fingerprint":"4aa3821a28b0b7c2400bc59aba4bcc0a76e971dadd19610d3ad38c768e124dc7","schema_version":"edge-lab-recorder.raw.v1","sequence":null,"source":"clob_market_ws"}
{"event_at":"2026-07-28T03:13:38.635000Z","event_fingerprint":"9121acbd4849fc4ac2a9433ef308b6220ce535e1bada1089632e0c800cd25bdd","payload":{"connection_id":"a6b55582af5f430fb37ad02bf0922475","event_at":"2026-07-28T03:13:38.635000Z","event_type":"best_bid_ask","frame_hash":"75f0382e670623bb9afd224e3671e68f3ca5cc827a9a0fa2aadbe142e398d6f4","frame_index":0,"kind":"data","monotonic_ns":310401694300083,"payload":{"asset_id":"14965588658799411272385430903075831224615961675357217884735713260981483529984","best_ask":"0.81","best_bid":"0.78","event_type":"best_bid_ask","market":"0x779291bef19b6709f61e9764a954aafe9ffae488d50ae674aabdcb4f248006d5","spread":"0.03","timestamp":"1785208418635"},"payload_hash":"91dc8ed83b433397e23d6970d5791b76d92cf9ea21df3f563f717f7125a0572a","raw_frame":"{\"market\":\"0x779291bef19b6709f61e9764a954aafe9ffae488d50ae674aabdcb4f248006d5\", \"asset_id\":\"14965588658799411272385430903075831224615961675357217884735713260981483529984\", \"best_bid\":\"0.78\", \"best_ask\":\"0.81\", \"spread\":\"0.03\", \"timestamp\":\"1785208418635\", \"event_type\":\"best_bid_ask\"}","received_at":"2026-07-28T03:13:38.659087Z","schema_version":"clob-market-ws.best_bid_ask.v1","sequence":null,"server_hash":null,"server_timestamp":"1785208418635","session_id":"3e519d9098404c15b234d96025eb1a2b","source":"clob_market_ws"},"received_at":"2026-07-28T03:13:38.659087Z","record_id":"8b93c8304aadde6eafab2fe44935162d84292d1dcbfc94b579ef4d2043024d5b","schema_fingerprint":"8488399f31b0337811b13b266be932db7062827c2470b78bd8e9e99bab51d17d","schema_version":"edge-lab-recorder.raw.v1","sequence":null,"source":"clob_market_ws"}
{"event_at":"2026-07-28T03:13:38.635000Z","event_fingerprint":"ca25f3ec286190cd92d5b8f31551ee5af959384e256e66e2140a840dc6ca7458","payload":{"connection_id":"a6b55582af5f430fb37ad02bf0922475","event_at":"2026-07-28T03:13:38.635000Z","event_type":"best_bid_ask","frame_hash":"1539df9f8da13715a6d04f42fe3d30d746275cac082f74e0c6454555ffeb6f58","frame_index":0,"kind":"data","monotonic_ns":310401695316083,"payload":{"asset_id":"8761897749749422724209054078244794145777693856614463256546737399611489089783","best_ask":"0.22","best_bid":"0.19","event_type":"best_bid_ask","market":"0x779291bef19b6709f61e9764a954aafe9ffae488d50ae674aabdcb4f248006d5","spread":"0.03","timestamp":"1785208418635"},"payload_hash":"711b016f062348bbb9941ce6183c1ed1f8dfc9794b5994cc0adfd365b187a9ce","raw_frame":"{\"market\":\"0x779291bef19b6709f61e9764a954aafe9ffae488d50ae674aabdcb4f248006d5\", \"asset_id\":\"8761897749749422724209054078244794145777693856614463256546737399611489089783\", \"best_bid\":\"0.19\", \"best_ask\":\"0.22\", \"spread\":\"0.03\", \"timestamp\":\"1785208418635\", \"event_type\":\"best_bid_ask\"}","received_at":"2026-07-28T03:13:38.660103Z","schema_version":"clob-market-ws.best_bid_ask.v1","sequence":null,"server_hash":null,"server_timestamp":"1785208418635","session_id":"3e519d9098404c15b234d96025eb1a2b","source":"clob_market_ws"},"received_at":"2026-07-28T03:13:38.660103Z","record_id":"96fff4d91877fe2e4de035a5b1921386186b102d35a91ca7df6be61ffc863ea4","schema_fingerprint":"8488399f31b0337811b13b266be932db7062827c2470b78bd8e9e99bab51d17d","schema_version":"edge-lab-recorder.raw.v1","sequence":null,"source":"clob_market_ws"}
{"event_at":"2026-07-28T03:13:38.635000Z","event_fingerprint":"b7d2ff5284134983dca05f403b2c5d0e0d683b611b7474453fbc26e7959cd58a","payload":{"connection_id":"a6b55582af5f430fb37ad02bf0922475","event_at":"2026-07-28T03:13:38.635000Z","event_type":"price_change","frame_hash":"e6033d60760755b20344a6eb611c89e83130145961bdfdda0a90b9dd2c69dedb","frame_index":0,"kind":"data","monotonic_ns":310401696342541,"payload":{"event_type":"price_change","market":"0x779291bef19b6709f61e9764a954aafe9ffae488d50ae674aabdcb4f248006d5","price_changes":[{"asset_id":"8761897749749422724209054078244794145777693856614463256546737399611489089783","best_ask":"0.22","best_bid":"0.19","hash":"07fe5e9b5b17484d60bc629584009f226370a8fa","price":"0.2","side":"BUY","size":"0"},{"asset_id":"14965588658799411272385430903075831224615961675357217884735713260981483529984","best_ask":"0.81","best_bid":"0.78","hash":"a33a777931057052acd2fcb648a6ed786f8cea48","price":"0.8","side":"SELL","size":"0"}],"timestamp":"1785208418635"},"payload_hash":"4598eb39d0124012a4936cd4ac2fddf52d66a01e15020b7bc42e71275a5d330c","raw_frame":"{\"market\":\"0x779291bef19b6709f61e9764a954aafe9ffae488d50ae674aabdcb4f248006d5\", \"price_changes\":[{\"asset_id\":\"8761897749749422724209054078244794145777693856614463256546737399611489089783\", \"price\":\"0.2\", \"size\":\"0\", \"side\":\"BUY\", \"hash\":\"07fe5e9b5b17484d60bc629584009f226370a8fa\", \"best_bid\":\"0.19\", \"best_ask\":\"0.22\"}, {\"asset_id\":\"14965588658799411272385430903075831224615961675357217884735713260981483529984\", \"price\":\"0.8\", \"size\":\"0\", \"side\":\"SELL\", \"hash\":\"a33a777931057052acd2fcb648a6ed786f8cea48\", \"best_bid\":\"0.78\", \"best_ask\":\"0.81\"}], \"timestamp\":\"1785208418635\", \"event_type\":\"price_change\"}","received_at":"2026-07-28T03:13:38.661130Z","schema_version":"clob-market-ws.price_change.v1","sequence":null,"server_hash":null,"server_timestamp":"1785208418635","session_id":"3e519d9098404c15b234d96025eb1a2b","source":"clob_market_ws"},"received_at":"2026-07-28T03:13:38.661130Z","record_id":"9804e4a3b71076f2444255cc3988248c8fe042820474e52748e5bb2bb14e2197","schema_fingerprint":"4aa3821a28b0b7c2400bc59aba4bcc0a76e971dadd19610d3ad38c768e124dc7","schema_version":"edge-lab-recorder.raw.v1","sequence":null,"source":"clob_market_ws"}
{"event_at":"2026-07-28T03:13:38.639000Z","event_fingerprint":"f475588a7eff7277e34b744afdb3615ac93d08a4b75b4f046211bf6695b52ba1","payload":{"connection_id":"a6b55582af5f430fb37ad02bf0922475","event_at":"2026-07-28T03:13:38.639000Z","event_type":"price_change","frame_hash":"68def042240b3253d3040ab8350c8f3ae6e9366631c5788a8376940c49d5f252","frame_index":0,"kind":"data","monotonic_ns":310401697798708,"payload":{"event_type":"price_change","market":"0x779291bef19b6709f61e9764a954aafe9ffae488d50ae674aabdcb4f248006d5","price_changes":[{"asset_id":"8761897749749422724209054078244794145777693856614463256546737399611489089783","best_ask":"0.22","best_bid":"0.19","hash":"6a32d51dff54b18163277672a2a167ec21da37d7","price":"0.19","side":"BUY","size":"10"},{"asset_id":"14965588658799411272385430903075831224615961675357217884735713260981483529984","best_ask":"0.81","best_bid":"0.78","hash":"99573f3d00f60027a6de022a1a077c5878561216","price":"0.81","side":"SELL","size":"10"}],"timestamp":"1785208418639"},"payload_hash":"2d6f0e512f6e6223a5b252f3f79e38c179c7da99f37022b34bdc47f58bbc2267","raw_frame":"{\"market\":\"0x779291bef19b6709f61e9764a954aafe9ffae488d50ae674aabdcb4f248006d5\", \"price_changes\":[{\"asset_id\":\"8761897749749422724209054078244794145777693856614463256546737399611489089783\", \"price\":\"0.19\", \"size\":\"10\", \"side\":\"BUY\", \"hash\":\"6a32d51dff54b18163277672a2a167ec21da37d7\", \"best_bid\":\"0.19\", \"best_ask\":\"0.22\"}, {\"asset_id\":\"14965588658799411272385430903075831224615961675357217884735713260981483529984\", \"price\":\"0.81\", \"size\":\"10\", \"side\":\"SELL\", \"hash\":\"99573f3d00f60027a6de022a1a077c5878561216\", \"best_bid\":\"0.78\", \"best_ask\":\"0.81\"}], \"timestamp\":\"1785208418639\", \"event_type\":\"price_change\"}","received_at":"2026-07-28T03:13:38.662586Z","schema_version":"clob-market-ws.price_change.v1","sequence":null,"server_hash":null,"server_timestamp":"1785208418639","session_id":"3e519d9098404c15b234d96025eb1a2b","source":"clob_market_ws"},"received_at":"2026-07-28T03:13:38.662586Z","record_id":"16a6f0b95d4ae9d6a20d1d10f94d07e969d7cddb94ca2253b21cbd0c79e59b66","schema_fingerprint":"4aa3821a28b0b7c2400bc59aba4bcc0a76e971dadd19610d3ad38c768e124dc7","schema_version":"edge-lab-recorder.raw.v1","sequence":null,"source":"clob_market_ws"}
{"event_at":"2026-07-28T03:13:38.641000Z","event_fingerprint":"a86ab65fc5c7acbb727342f7943ae6fff15a926167f9aa6f55fc6c5a77f80758","payload":{"connection_id":"a6b55582af5f430fb37ad02bf0922475","event_at":"2026-07-28T03:13:38.641000Z","event_type":"best_bid_ask","frame_hash":"4482e4cb772b31e617e317afdb73ef66ca995fe17535e16073db08d6d82f0f79","frame_index":0,"kind":"data","monotonic_ns":310401699262541,"payload":{"asset_id":"14965588658799411272385430903075831224615961675357217884735713260981483529984","best_ask":"0.81","best_bid":"0.79","event_type":"best_bid_ask","market":"0x779291bef19b6709f61e9764a954aafe9ffae488d50ae674aabdcb4f248006d5","spread":"0.02","timestamp":"1785208418641"},"payload_hash":"fb0d3e7254534b9ee1ac1a4ae783f8981d403ecd9897f27ead8ed40b936cede6","raw_frame":"{\"market\":\"0x779291bef19b6709f61e9764a954aafe9ffae488d50ae674aabdcb4f248006d5\", \"asset_id\":\"14965588658799411272385430903075831224615961675357217884735713260981483529984\", \"best_bid\":\"0.79\", \"best_ask\":\"0.81\", \"spread\":\"0.02\", \"timestamp\":\"1785208418641\", \"event_type\":\"best_bid_ask\"}","received_at":"2026-07-28T03:13:38.664050Z","schema_version":"clob-market-ws.best_bid_ask.v1","sequence":null,"server_hash":null,"server_timestamp":"1785208418641","session_id":"3e519d9098404c15b234d96025eb1a2b","source":"clob_market_ws"},"received_at":"2026-07-28T03:13:38.664050Z","record_id":"ad5649f32638368bb45388a2de25c44450d6fddce2cdf9888fc6a55552fad207","schema_fingerprint":"8488399f31b0337811b13b266be932db7062827c2470b78bd8e9e99bab51d17d","schema_version":"edge-lab-recorder.raw.v1","sequence":null,"source":"clob_market_ws"}
{"event_at":"2026-07-28T03:13:38.641000Z","event_fingerprint":"b063bce4f2e8c08bf9be90c4752d60ac640ec5fda8b1d7195019448397764dfa","payload":{"connection_id":"a6b55582af5f430fb37ad02bf0922475","event_at":"2026-07-28T03:13:38.641000Z","event_type":"best_bid_ask","frame_hash":"a4c12f3c6212c19e2b7ed9077eb581f936c15c3de7d3904954d96405613a6a34","frame_index":0,"kind":"data","monotonic_ns":310401700278500,"payload":{"asset_id":"8761897749749422724209054078244794145777693856614463256546737399611489089783","best_ask":"0.21","best_bid":"0.19","event_type":"best_bid_ask","market":"0x779291bef19b6709f61e9764a954aafe9ffae488d50ae674aabdcb4f248006d5","spread":"0.02","timestamp":"1785208418641"},"payload_hash":"16ec75d40e866dd0c61ba2c114468c09531ebd8a1707f96e3a5b53d178cec86a","raw_frame":"{\"market\":\"0x779291bef19b6709f61e9764a954aafe9ffae488d50ae674aabdcb4f248006d5\", \"asset_id\":\"8761897749749422724209054078244794145777693856614463256546737399611489089783\", \"best_bid\":\"0.19\", \"best_ask\":\"0.21\", \"spread\":\"0.02\", \"timestamp\":\"1785208418641\", \"event_type\":\"best_bid_ask\"}","received_at":"2026-07-28T03:13:38.665066Z","schema_version":"clob-market-ws.best_bid_ask.v1","sequence":null,"server_hash":null,"server_timestamp":"1785208418641","session_id":"3e519d9098404c15b234d96025eb1a2b","source":"clob_market_ws"},"received_at":"2026-07-28T03:13:38.665066Z","record_id":"9855c7319d8026e78c5f951ab8ad3820e7f7c1c4a4ec6b081c597435eb164c7c","schema_fingerprint":"8488399f31b0337811b13b266be932db7062827c2470b78bd8e9e99bab51d17d","schema_version":"edge-lab-recorder.raw.v1","sequence":null,"source":"clob_market_ws"}
{"event_at":"2026-07-28T03:13:38.641000Z","event_fingerprint":"f467b555570bbc4a8d7a3bf1312eeb5bfc7a0c3ca76535277fa6b13adc689f31","payload":{"connection_id":"a6b55582af5f430fb37ad02bf0922475","event_at":"2026-07-28T03:13:38.641000Z","event_type":"price_change","frame_hash":"e4d709c08935112b1b99203b4ce15aad0278506d09c65158d408c8f6d02cc30a","frame_index":0,"kind":"data","monotonic_ns":310401701324708,"payload":{"event_type":"price_change","market":"0x779291bef19b6709f61e9764a954aafe9ffae488d50ae674aabdcb4f248006d5","price_changes":[{"asset_id":"14965588658799411272385430903075831224615961675357217884735713260981483529984","best_ask":"0.81","best_bid":"0.79","hash":"7c0302ba693252902f7648cac0af0aae4095c95e","price":"0.79","side":"BUY","size":"5"},{"asset_id":"8761897749749422724209054078244794145777693856614463256546737399611489089783","best_ask":"0.21","best_bid":"0.19","hash":"15b4b2818da9adc2a50415f8c85c55293c0de262","price":"0.21","side":"SELL","size":"5"}],"timestamp":"1785208418641"},"payload_hash":"154012854346f2e253328c4db7ffa9b41ba880d7a7dabfdc257871da28e00e89","raw_frame":"{\"market\":\"0x779291bef19b6709f61e9764a954aafe9ffae488d50ae674aabdcb4f248006d5\", \"price_changes\":[{\"asset_id\":\"14965588658799411272385430903075831224615961675357217884735713260981483529984\", \"price\":\"0.79\", \"size\":\"5\", \"side\":\"BUY\", \"hash\":\"7c0302ba693252902f7648cac0af0aae4095c95e\", \"best_bid\":\"0.79\", \"best_ask\":\"0.81\"}, {\"asset_id\":\"8761897749749422724209054078244794145777693856614463256546737399611489089783\", \"price\":\"0.21\", \"size\":\"5\", \"side\":\"SELL\", \"hash\":\"15b4b2818da9adc2a50415f8c85c55293c0de262\", \"best_bid\":\"0.19\", \"best_ask\":\"0.21\"}], \"timestamp\":\"1785208418641\", \"event_type\":\"price_change\"}","received_at":"2026-07-28T03:13:38.666112Z","schema_version":"clob-market-ws.price_change.v1","sequence":null,"server_hash":null,"server_timestamp":"1785208418641","session_id":"3e519d9098404c15b234d96025eb1a2b","source":"clob_market_ws"},"received_at":"2026-07-28T03:13:38.666112Z","record_id":"d981cd18daba8b687f1bd0bbb01919200dd4c020b8ef8e672eaf975c1fe055d0","schema_fingerprint":"4aa3821a28b0b7c2400bc59aba4bcc0a76e971dadd19610d3ad38c768e124dc7","schema_version":"edge-lab-recorder.raw.v1","sequence":null,"source":"clob_market_ws"}
{"event_at":"2026-07-28T03:13:38.641000Z","event_fingerprint":"cc9f03daa616c00014d04a85473521bd88de18c9842fa177546d7b0993bf2919","payload":{"connection_id":"a6b55582af5f430fb37ad02bf0922475","event_at":"2026-07-28T03:13:38.641000Z","event_type":"price_change","frame_hash":"0945aedfd80caeab76e7c6c63cfc9f78e94d4e1a6062c9463ec9a9e3b028c05a","frame_index":0,"kind":"data","monotonic_ns":310401702828583,"payload":{"event_type":"price_change","market":"0x779291bef19b6709f61e9764a954aafe9ffae488d50ae674aabdcb4f248006d5","price_changes":[{"asset_id":"14965588658799411272385430903075831224615961675357217884735713260981483529984","best_ask":"0.81","best_bid":"0.79","hash":"9ada4e3750edeefa9e489099e569d36210a4654a","price":"0.55","side":"BUY","size":"65"},{"asset_id":"8761897749749422724209054078244794145777693856614463256546737399611489089783","best_ask":"0.21","best_bid":"0.19","hash":"43704c539306f054cc9d1ae0aee1707de5b93dd5","price":"0.45","side":"SELL","size":"65"}],"timestamp":"1785208418641"},"payload_hash":"a0ea4fd284c5926b01ba8ba4fc1a502544776d6c90a79ed529259605d5df7090","raw_frame":"{\"market\":\"0x779291bef19b6709f61e9764a954aafe9ffae488d50ae674aabdcb4f248006d5\", \"price_changes\":[{\"asset_id\":\"14965588658799411272385430903075831224615961675357217884735713260981483529984\", \"price\":\"0.55\", \"size\":\"65\", \"side\":\"BUY\", \"hash\":\"9ada4e3750edeefa9e489099e569d36210a4654a\", \"best_bid\":\"0.79\", \"best_ask\":\"0.81\"}, {\"asset_id\":\"8761897749749422724209054078244794145777693856614463256546737399611489089783\", \"price\":\"0.45\", \"size\":\"65\", \"side\":\"SELL\", \"hash\":\"43704c539306f054cc9d1ae0aee1707de5b93dd5\", \"best_bid\":\"0.19\", \"best_ask\":\"0.21\"}], \"timestamp\":\"1785208418641\", \"event_type\":\"price_change\"}","received_at":"2026-07-28T03:13:38.667615Z","schema_version":"clob-market-ws.price_change.v1","sequence":null,"server_hash":null,"server_timestamp":"1785208418641","session_id":"3e519d9098404c15b234d96025eb1a2b","source":"clob_market_ws"},"received_at":"2026-07-28T03:13:38.667615Z","record_id":"d37ca84ac10600c17f815484f7eb6d2d47292d5f27b8f2041a1a3030f71d645c","schema_fingerprint":"4aa3821a28b0b7c2400bc59aba4bcc0a76e971dadd19610d3ad38c768e124dc7","schema_version":"edge-lab-recorder.raw.v1","sequence":null,"source":"clob_market_ws"}
{"event_at":"2026-07-28T03:13:38.641000Z","event_fingerprint":"91f5ee3b682a89a9e76e53bf35e97ba37f1c8108820bc89d098d1b888545ad2f","payload":{"connection_id":"a6b55582af5f430fb37ad02bf0922475","event_at":"2026-07-28T03:13:38.641000Z","event_type":"price_change","frame_hash":"ccbc00b6fac46cf96abf5c8d1757a17a8d8dad89b27f240c908c09e14f26be66","frame_index":0,"kind":"data","monotonic_ns":310401704355166,"payload":{"event_type":"price_change","market":"0x779291bef19b6709f61e9764a954aafe9ffae488d50ae674aabdcb4f248006d5","price_changes":[{"asset_id":"8761897749749422724209054078244794145777693856614463256546737399611489089783","best_ask":"0.21","best_bid":"0.19","hash":"3269ae510bd38c0f9757f81cfe9765ddac008959","price":"0.09","side":"BUY","size":"312.87"},{"asset_id":"14965588658799411272385430903075831224615961675357217884735713260981483529984","best_ask":"0.81","best_bid":"0.79","hash":"45da7aae24d4d5e83dcc394652452c95929946ac","price":"0.91","side":"SELL","size":"312.87"}],"timestamp":"1785208418641"},"payload_hash":"b543d08403da1d0a6ab1d6e0474bed752dfdd6842e981e2708c6efa81118d755","raw_frame":"{\"market\":\"0x779291bef19b6709f61e9764a954aafe9ffae488d50ae674aabdcb4f248006d5\", \"price_changes\":[{\"asset_id\":\"8761897749749422724209054078244794145777693856614463256546737399611489089783\", \"price\":\"0.09\", \"size\":\"312.87\", \"side\":\"BUY\", \"hash\":\"3269ae510bd38c0f9757f81cfe9765ddac008959\", \"best_bid\":\"0.19\", \"best_ask\":\"0.21\"}, {\"asset_id\":\"14965588658799411272385430903075831224615961675357217884735713260981483529984\", \"price\":\"0.91\", \"size\":\"312.87\", \"side\":\"SELL\", \"hash\":\"45da7aae24d4d5e83dcc394652452c95929946ac\", \"best_bid\":\"0.79\", \"best_ask\":\"0.81\"}], \"timestamp\":\"1785208418641\", \"event_type\":\"price_change\"}","received_at":"2026-07-28T03:13:38.669143Z","schema_version":"clob-market-ws.price_change.v1","sequence":null,"server_hash":null,"server_timestamp":"1785208418641","session_id":"3e519d9098404c15b234d96025eb1a2b","source":"clob_market_ws"},"received_at":"2026-07-28T03:13:38.669143Z","record_id":"da35ab1df53d97fc9e37204f35634089c6bfb15685a220df34ac37049bae7b37","schema_fingerprint":"4aa3821a28b0b7c2400bc59aba4bcc0a76e971dadd19610d3ad38c768e124dc7","schema_version":"edge-lab-recorder.raw.v1","sequence":null,"source":"clob_market_ws"}
{"event_at":"2026-07-28T03:13:38.644000Z","event_fingerprint":"1bf8f16c05515d3911c65d1c91600b112243b88384af422260d3e6f135a6527b","payload":{"connection_id":"a6b55582af5f430fb37ad02bf0922475","event_at":"2026-07-28T03:13:38.644000Z","event_type":"price_change","frame_hash":"a2ca0222daee552d842178178c5f2f34531a3a46add48019c34448d7a37469a9","frame_index":0,"kind":"data","monotonic_ns":310401705649791,"payload":{"event_type":"price_change","market":"0x779291bef19b6709f61e9764a954aafe9ffae488d50ae674aabdcb4f248006d5","price_changes":[{"asset_id":"8761897749749422724209054078244794145777693856614463256546737399611489089783","best_ask":"0.21","best_bid":"0.19","hash":"fb458fdbc755b112a24f614a52dcd9f611f8cf20","price":"0.18","side":"BUY","size":"10"},{"asset_id":"14965588658799411272385430903075831224615961675357217884735713260981483529984","best_ask":"0.81","best_bid":"0.79","hash":"e2d45a48390eb3cd5241025024200d77a4451d73","price":"0.82","side":"SELL","size":"10"}],"timestamp":"1785208418644"},"payload_hash":"1f1e29f575334e19c0f812f9cd5ea9a16d5ca6a326b0b407c178df0b59d98dc5","raw_frame":"{\"market\":\"0x779291bef19b6709f61e9764a954aafe9ffae488d50ae674aabdcb4f248006d5\", \"price_changes\":[{\"asset_id\":\"8761897749749422724209054078244794145777693856614463256546737399611489089783\", \"price\":\"0.18\", \"size\":\"10\", \"side\":\"BUY\", \"hash\":\"fb458fdbc755b112a24f614a52dcd9f611f8cf20\", \"best_bid\":\"0.19\", \"best_ask\":\"0.21\"}, {\"asset_id\":\"14965588658799411272385430903075831224615961675357217884735713260981483529984\", \"price\":\"0.82\", \"size\":\"10\", \"side\":\"SELL\", \"hash\":\"e2d45a48390eb3cd5241025024200d77a4451d73\", \"best_bid\":\"0.79\", \"best_ask\":\"0.81\"}], \"timestamp\":\"1785208418644\", \"event_type\":\"price_change\"}","received_at":"2026-07-28T03:13:38.670438Z","schema_version":"clob-market-ws.price_change.v1","sequence":null,"server_hash":null,"server_timestamp":"1785208418644","session_id":"3e519d9098404c15b234d96025eb1a2b","source":"clob_market_ws"},"received_at":"2026-07-28T03:13:38.670438Z","record_id":"aa060eae291a0d8f689bb56f59815c032e036b37c64342d7c051aa7ebcc77a9d","schema_fingerprint":"4aa3821a28b0b7c2400bc59aba4bcc0a76e971dadd19610d3ad38c768e124dc7","schema_version":"edge-lab-recorder.raw.v1","sequence":null,"source":"clob_market_ws"}
{"event_at":"2026-07-28T03:13:38.648000Z","event_fingerprint":"bb59ffebaa150d193c4e6304511eb88ef7ab74947069bbe5909e5fb5cdd274ab","payload":{"connection_id":"a6b55582af5f430fb37ad02bf0922475","event_at":"2026-07-28T03:13:38.648000Z","event_type":"price_change","frame_hash":"2f2d437508a2ecb2d6eafe8f1de391f549d4746f72c54eff30b0b0f3bc467a7c","frame_index":0,"kind":"data","monotonic_ns":310401706984791,"payload":{"event_type":"price_change","market":"0x779291bef19b6709f61e9764a954aafe9ffae488d50ae674aabdcb4f248006d5","price_changes":[{"asset_id":"14965588658799411272385430903075831224615961675357217884735713260981483529984","best_ask":"0.81","best_bid":"0.79","hash":"33eb304bdc79055029e56b4e1f3d3c4a363505d6","price":"0.45","side":"BUY","size":"183.14"},{"asset_id":"8761897749749422724209054078244794145777693856614463256546737399611489089783","best_ask":"0.21","best_bid":"0.19","hash":"96491c8b22baf12a1599881a28e1634c56e6c80f","price":"0.55","side":"SELL","size":"183.14"}],"timestamp":"1785208418648"},"payload_hash":"d052b766fa2d4145940dcbca3699a2f6a34e4b67249911b2ddd3d17dab1f27a6","raw_frame":"{\"market\":\"0x779291bef19b6709f61e9764a954aafe9ffae488d50ae674aabdcb4f248006d5\", \"price_changes\":[{\"asset_id\":\"14965588658799411272385430903075831224615961675357217884735713260981483529984\", \"price\":\"0.45\", \"size\":\"183.14\", \"side\":\"BUY\", \"hash\":\"33eb304bdc79055029e56b4e1f3d3c4a363505d6\", \"best_bid\":\"0.79\", \"best_ask\":\"0.81\"}, {\"asset_id\":\"8761897749749422724209054078244794145777693856614463256546737399611489089783\", \"price\":\"0.55\", \"size\":\"183.14\", \"side\":\"SELL\", \"hash\":\"96491c8b22baf12a1599881a28e1634c56e6c80f\", \"best_bid\":\"0.19\", \"best_ask\":\"0.21\"}], \"timestamp\":\"1785208418648\", \"event_type\":\"price_change\"}","received_at":"2026-07-28T03:13:38.671773Z","schema_version":"clob-market-ws.price_change.v1","sequence":null,"server_hash":null,"server_timestamp":"1785208418648","session_id":"3e519d9098404c15b234d96025eb1a2b","source":"clob_market_ws"},"received_at":"2026-07-28T03:13:38.671773Z","record_id":"5c0f5774341cd3f978035f15d2f9873f93faf0dc487f020eb785dd3acd0099ec","schema_fingerprint":"4aa3821a28b0b7c2400bc59aba4bcc0a76e971dadd19610d3ad38c768e124dc7","schema_version":"edge-lab-recorder.raw.v1","sequence":null,"source":"clob_market_ws"}
{"event_at":"2026-07-28T03:13:38.652000Z","event_fingerprint":"bcdbf479b537146166da33420b7065603d285a657e57eff0afc03739c81aa043","payload":{"connection_id":"a6b55582af5f430fb37ad02bf0922475","event_at":"2026-07-28T03:13:38.652000Z","event_type":"price_change","frame_hash":"c8c7a0962a14296ac3ba7b6ece4721147c82147c4e4f78bfa6a8d5591cc7da24","frame_index":0,"kind":"data","monotonic_ns":310401708284541,"payload":{"event_type":"price_change","market":"0x779291bef19b6709f61e9764a954aafe9ffae488d50ae674aabdcb4f248006d5","price_changes":[{"asset_id":"14965588658799411272385430903075831224615961675357217884735713260981483529984","best_ask":"0.81","best_bid":"0.79","hash":"fa3c078d92cedefa317e0414a9a967e5e9640295","price":"0.69","side":"BUY","size":"66"},{"asset_id":"8761897749749422724209054078244794145777693856614463256546737399611489089783","best_ask":"0.21","best_bid":"0.19","hash":"157b836248581039ca6455fb0ed7c121e184c9d1","price":"0.31","side":"SELL","size":"66"}],"timestamp":"1785208418652"},"payload_hash":"7380422af00da7ff60f0f719193b5703c740a963363d50edd05cd7d1608e3f54","raw_frame":"{\"market\":\"0x779291bef19b6709f61e9764a954aafe9ffae488d50ae674aabdcb4f248006d5\", \"price_changes\":[{\"asset_id\":\"14965588658799411272385430903075831224615961675357217884735713260981483529984\", \"price\":\"0.69\", \"size\":\"66\", \"side\":\"BUY\", \"hash\":\"fa3c078d92cedefa317e0414a9a967e5e9640295\", \"best_bid\":\"0.79\", \"best_ask\":\"0.81\"}, {\"asset_id\":\"8761897749749422724209054078244794145777693856614463256546737399611489089783\", \"price\":\"0.31\", \"size\":\"66\", \"side\":\"SELL\", \"hash\":\"157b836248581039ca6455fb0ed7c121e184c9d1\", \"best_bid\":\"0.19\", \"best_ask\":\"0.21\"}], \"timestamp\":\"1785208418652\", \"event_type\":\"price_change\"}","received_at":"2026-07-28T03:13:38.673072Z","schema_version":"clob-market-ws.price_change.v1","sequence":null,"server_hash":null,"server_timestamp":"1785208418652","session_id":"3e519d9098404c15b234d96025eb1a2b","source":"clob_market_ws"},"received_at":"2026-07-28T03:13:38.673072Z","record_id":"b51d54fc831f5ab5ab33dd93224f1861c7f7f5e076b5d7e89068c376cd6419fb","schema_fingerprint":"4aa3821a28b0b7c2400bc59aba4bcc0a76e971dadd19610d3ad38c768e124dc7","schema_version":"edge-lab-recorder.raw.v1","sequence":null,"source":"clob_market_ws"}
{"event_at":"2026-07-28T03:13:38.653000Z","event_fingerprint":"608aa2f962450337a98f3a27a63499eaecb0afd5e2c62c793a4177108f05a72a","payload":{"connection_id":"a6b55582af5f430fb37ad02bf0922475","event_at":"2026-07-28T03:13:38.653000Z","event_type":"best_bid_ask","frame_hash":"48e1a111976b6d9cebd1c80d7126fe4b90290c8a0678475954591f008b454ef5","frame_index":0,"kind":"data","monotonic_ns":310401709715666,"payload":{"asset_id":"14965588658799411272385430903075831224615961675357217884735713260981483529984","best_ask":"0.81","best_bid":"0.78","event_type":"best_bid_ask","market":"0x779291bef19b6709f61e9764a954aafe9ffae488d50ae674aabdcb4f248006d5","spread":"0.03","timestamp":"1785208418653"},"payload_hash":"1413d1eb3eadd03e2c695fd28925d06b8a162ae66cce399e2ea3ec74885b712e","raw_frame":"{\"market\":\"0x779291bef19b6709f61e9764a954aafe9ffae488d50ae674aabdcb4f248006d5\", \"asset_id\":\"14965588658799411272385430903075831224615961675357217884735713260981483529984\", \"best_bid\":\"0.78\", \"best_ask\":\"0.81\", \"spread\":\"0.03\", \"timestamp\":\"1785208418653\", \"event_type\":\"best_bid_ask\"}","received_at":"2026-07-28T03:13:38.674502Z","schema_version":"clob-market-ws.best_bid_ask.v1","sequence":null,"server_hash":null,"server_timestamp":"1785208418653","session_id":"3e519d9098404c15b234d96025eb1a2b","source":"clob_market_ws"},"received_at":"2026-07-28T03:13:38.674502Z","record_id":"ddee66049c7cb4fecfffe35cd1afff57bdf80470163b24b2924269a95c94e490","schema_fingerprint":"8488399f31b0337811b13b266be932db7062827c2470b78bd8e9e99bab51d17d","schema_version":"edge-lab-recorder.raw.v1","sequence":null,"source":"clob_market_ws"}
{"event_at":"2026-07-28T03:13:38.653000Z","event_fingerprint":"881dc2a060a6fce5cb153f5fc3cbeedc93806e8d26620efe1acb48c4f35ecefc","payload":{"connection_id":"a6b55582af5f430fb37ad02bf0922475","event_at":"2026-07-28T03:13:38.653000Z","event_type":"best_bid_ask","frame_hash":"0fde154cebe5cc03f1f90350efb123fdd919ece0780adbacc9eef6197f4cc693","frame_index":0,"kind":"data","monotonic_ns":310401710753083,"payload":{"asset_id":"8761897749749422724209054078244794145777693856614463256546737399611489089783","best_ask":"0.22","best_bid":"0.19","event_type":"best_bid_ask","market":"0x779291bef19b6709f61e9764a954aafe9ffae488d50ae674aabdcb4f248006d5","spread":"0.03","timestamp":"1785208418653"},"payload_hash":"4543501eacaa17826011549f68aac6335b2e2f9d72ff948e7d27f50a77fa02c7","raw_frame":"{\"market\":\"0x779291bef19b6709f61e9764a954aafe9ffae488d50ae674aabdcb4f248006d5\", \"asset_id\":\"8761897749749422724209054078244794145777693856614463256546737399611489089783\", \"best_bid\":\"0.19\", \"best_ask\":\"0.22\", \"spread\":\"0.03\", \"timestamp\":\"1785208418653\", \"event_type\":\"best_bid_ask\"}","received_at":"2026-07-28T03:13:38.675540Z","schema_version":"clob-market-ws.best_bid_ask.v1","sequence":null,"server_hash":null,"server_timestamp":"1785208418653","session_id":"3e519d9098404c15b234d96025eb1a2b","source":"clob_market_ws"},"received_at":"2026-07-28T03:13:38.675540Z","record_id":"952bf308d10f2ef7e8fbe4eb3b374ab054ce6cb6a835969c1033ad388872e109","schema_fingerprint":"8488399f31b0337811b13b266be932db7062827c2470b78bd8e9e99bab51d17d","schema_version":"edge-lab-recorder.raw.v1","sequence":null,"source":"clob_market_ws"}
{"event_at":"2026-07-28T03:13:38.653000Z","event_fingerprint":"fa8ee9709f4192ca37f387cead4648fff004320f5e5c92cfd3f6219eed7f01d5","payload":{"connection_id":"a6b55582af5f430fb37ad02bf0922475","event_at":"2026-07-28T03:13:38.653000Z","event_type":"price_change","frame_hash":"67ea093cdf21870acd0050ca0005fdbe59480f0d96047657d74d0b98dcc770db","frame_index":0,"kind":"data","monotonic_ns":310401711767583,"payload":{"event_type":"price_change","market":"0x779291bef19b6709f61e9764a954aafe9ffae488d50ae674aabdcb4f248006d5","price_changes":[{"asset_id":"14965588658799411272385430903075831224615961675357217884735713260981483529984","best_ask":"0.81","best_bid":"0.78","hash":"cce0fbbc341bde0d22d0188c1aa7c153c237f5f1","price":"0.79","side":"BUY","size":"0"},{"asset_id":"8761897749749422724209054078244794145777693856614463256546737399611489089783","best_ask":"0.22","best_bid":"0.19","hash":"8f9afbc3552a5698f565f364e6a74741571d489a","price":"0.21","side":"SELL","size":"0"}],"timestamp":"1785208418653"},"payload_hash":"741809706a6db1b71735efbea941763a94709fad56c6f2145643f808a73c85a0","raw_frame":"{\"market\":\"0x779291bef19b6709f61e9764a954aafe9ffae488d50ae674aabdcb4f248006d5\", \"price_changes\":[{\"asset_id\":\"14965588658799411272385430903075831224615961675357217884735713260981483529984\", \"price\":\"0.79\", \"size\":\"0\", \"side\":\"BUY\", \"hash\":\"cce0fbbc341bde0d22d0188c1aa7c153c237f5f1\", \"best_bid\":\"0.78\", \"best_ask\":\"0.81\"}, {\"asset_id\":\"8761897749749422724209054078244794145777693856614463256546737399611489089783\", \"price\":\"0.21\", \"size\":\"0\", \"side\":\"SELL\", \"hash\":\"8f9afbc3552a5698f565f364e6a74741571d489a\", \"best_bid\":\"0.19\", \"best_ask\":\"0.22\"}], \"timestamp\":\"1785208418653\", \"event_type\":\"price_change\"}","received_at":"2026-07-28T03:13:38.676554Z","schema_version":"clob-market-ws.price_change.v1","sequence":null,"server_hash":null,"server_timestamp":"1785208418653","session_id":"3e519d9098404c15b234d96025eb1a2b","source":"clob_market_ws"},"received_at":"2026-07-28T03:13:38.676554Z","record_id":"8d94d424014cdd458eeb76f1e642a56d5b970d543e01b9b4c7032c95c5d035d5","schema_fingerprint":"4aa3821a28b0b7c2400bc59aba4bcc0a76e971dadd19610d3ad38c768e124dc7","schema_version":"edge-lab-recorder.raw.v1","sequence":null,"source":"clob_market_ws"}
{"event_at":"2026-07-28T03:13:38.656000Z","event_fingerprint":"d1706aab0e24330672a62901e9578b120d355ebe3ccaa590ab47a0354e6ffb22","payload":{"connection_id":"a6b55582af5f430fb37ad02bf0922475","event_at":"2026-07-28T03:13:38.656000Z","event_type":"price_change","frame_hash":"6eda270ea3bca5511813b9c94800288ef58e65cd0592b783769b8396f4c76b13","frame_index":0,"kind":"data","monotonic_ns":310401713253208,"payload":{"event_type":"price_change","market":"0x779291bef19b6709f61e9764a954aafe9ffae488d50ae674aabdcb4f248006d5","price_changes":[{"asset_id":"8761897749749422724209054078244794145777693856614463256546737399611489089783","best_ask":"0.22","best_bid":"0.19","hash":"d6d7832d0c28ce95d250c42a1c2d783565f8a5a4","price":"0.22","side":"SELL","size":"270"},{"asset_id":"14965588658799411272385430903075831224615961675357217884735713260981483529984","best_ask":"0.81","best_bid":"0.78","hash":"f830ecb47590fe952996444a5d5bba7a9244822a","price":"0.78","side":"BUY","size":"270"}],"timestamp":"1785208418656"},"payload_hash":"87ee7fbd3539fc92d5a110a817c410132367b690960fddb62441f44ac51061d6","raw_frame":"{\"market\":\"0x779291bef19b6709f61e9764a954aafe9ffae488d50ae674aabdcb4f248006d5\", \"price_changes\":[{\"asset_id\":\"8761897749749422724209054078244794145777693856614463256546737399611489089783\", \"price\":\"0.22\", \"size\":\"270\", \"side\":\"SELL\", \"hash\":\"d6d7832d0c28ce95d250c42a1c2d783565f8a5a4\", \"best_bid\":\"0.19\", \"best_ask\":\"0.22\"}, {\"asset_id\":\"14965588658799411272385430903075831224615961675357217884735713260981483529984\", \"price\":\"0.78\", \"size\":\"270\", \"side\":\"BUY\", \"hash\":\"f830ecb47590fe952996444a5d5bba7a9244822a\", \"best_bid\":\"0.78\", \"best_ask\":\"0.81\"}], \"timestamp\":\"1785208418656\", \"event_type\":\"price_change\"}","received_at":"2026-07-28T03:13:38.678041Z","schema_version":"clob-market-ws.price_change.v1","sequence":null,"server_hash":null,"server_timestamp":"1785208418656","session_id":"3e519d9098404c15b234d96025eb1a2b","source":"clob_market_ws"},"received_at":"2026-07-28T03:13:38.678041Z","record_id":"fae283963d712949c68b6213ee91c2b44297eacb850eef0a2b127436e623c8fa","schema_fingerprint":"4aa3821a28b0b7c2400bc59aba4bcc0a76e971dadd19610d3ad38c768e124dc7","schema_version":"edge-lab-recorder.raw.v1","sequence":null,"source":"clob_market_ws"}
{"event_at":"2026-07-28T03:13:38.659000Z","event_fingerprint":"beccc0a86af1c9f23de62397ca6f900b7b116555d3b759a4d9be947e06f5b6c1","payload":{"connection_id":"a6b55582af5f430fb37ad02bf0922475","event_at":"2026-07-28T03:13:38.659000Z","event_type":"price_change","frame_hash":"0c2a5d698b69e65e1f92cbaca4ca23dd1344e8e2738ca2cfdd5ba0c9599e0e65","frame_index":0,"kind":"data","monotonic_ns":310401714740625,"payload":{"event_type":"price_change","market":"0x779291bef19b6709f61e9764a954aafe9ffae488d50ae674aabdcb4f248006d5","price_changes":[{"asset_id":"14965588658799411272385430903075831224615961675357217884735713260981483529984","best_ask":"0.81","best_bid":"0.78","hash":"e4927b3b4e59a1544d332d1f3de9f6f2bde03abb","price":"0.75","side":"BUY","size":"54"},{"asset_id":"8761897749749422724209054078244794145777693856614463256546737399611489089783","best_ask":"0.22","best_bid":"0.19","hash":"6b02b37d46ae719dae4129be3d8b99f6b3e9bc45","price":"0.25","side":"SELL","size":"54"}],"timestamp":"1785208418659"},"payload_hash":"50034d637ebb633438d76794c098db79368f1d469bc9d36ea839c83ab61694d3","raw_frame":"{\"market\":\"0x779291bef19b6709f61e9764a954aafe9ffae488d50ae674aabdcb4f248006d5\", \"price_changes\":[{\"asset_id\":\"14965588658799411272385430903075831224615961675357217884735713260981483529984\", \"price\":\"0.75\", \"size\":\"54\", \"side\":\"BUY\", \"hash\":\"e4927b3b4e59a1544d332d1f3de9f6f2bde03abb\", \"best_bid\":\"0.78\", \"best_ask\":\"0.81\"}, {\"asset_id\":\"8761897749749422724209054078244794145777693856614463256546737399611489089783\", \"price\":\"0.25\", \"size\":\"54\", \"side\":\"SELL\", \"hash\":\"6b02b37d46ae719dae4129be3d8b99f6b3e9bc45\", \"best_bid\":\"0.19\", \"best_ask\":\"0.22\"}], \"timestamp\":\"1785208418659\", \"event_type\":\"price_change\"}","received_at":"2026-07-28T03:13:38.679527Z","schema_version":"clob-market-ws.price_change.v1","sequence":null,"server_hash":null,"server_timestamp":"1785208418659","session_id":"3e519d9098404c15b234d96025eb1a2b","source":"clob_market_ws"},"received_at":"2026-07-28T03:13:38.679527Z","record_id":"d860b718486b05eabbe0f6777177ebaf927683200d3f52838999af9401180dab","schema_fingerprint":"4aa3821a28b0b7c2400bc59aba4bcc0a76e971dadd19610d3ad38c768e124dc7","schema_version":"edge-lab-recorder.raw.v1","sequence":null,"source":"clob_market_ws"}
{"event_at":"2026-07-28T03:13:38.660000Z","event_fingerprint":"70b696522499de929838ce5e9d53ad9822081ec71b4c7b837f169f09bda60b95","payload":{"connection_id":"a6b55582af5f430fb37ad02bf0922475","event_at":"2026-07-28T03:13:38.660000Z","event_type":"price_change","frame_hash":"f6466d45dcebeeced5685b48b78043bdd6a87ed8c5ec79edde2cc67b7fd70611","frame_index":0,"kind":"data","monotonic_ns":310401716260625,"payload":{"event_type":"price_change","market":"0x779291bef19b6709f61e9764a954aafe9ffae488d50ae674aabdcb4f248006d5","price_changes":[{"asset_id":"8761897749749422724209054078244794145777693856614463256546737399611489089783","best_ask":"0.22","best_bid":"0.19","hash":"97c981fcc1c6cddffd19de0c4960471be74f29b8","price":"0.16","side":"BUY","size":"30"},{"asset_id":"14965588658799411272385430903075831224615961675357217884735713260981483529984","best_ask":"0.81","best_bid":"0.78","hash":"cb9af5a9a6e08f157def5033856dabbe11162b91","price":"0.84","side":"SELL","size":"30"}],"timestamp":"1785208418660"},"payload_hash":"e23ca62c6293725c2c7a41c8292128b84c4aa180f9cc53f62149c3720eb88c49","raw_frame":"{\"market\":\"0x779291bef19b6709f61e9764a954aafe9ffae488d50ae674aabdcb4f248006d5\", \"price_changes\":[{\"asset_id\":\"8761897749749422724209054078244794145777693856614463256546737399611489089783\", \"price\":\"0.16\", \"size\":\"30\", \"side\":\"BUY\", \"hash\":\"97c981fcc1c6cddffd19de0c4960471be74f29b8\", \"best_bid\":\"0.19\", \"best_ask\":\"0.22\"}, {\"asset_id\":\"14965588658799411272385430903075831224615961675357217884735713260981483529984\", \"price\":\"0.84\", \"size\":\"30\", \"side\":\"SELL\", \"hash\":\"cb9af5a9a6e08f157def5033856dabbe11162b91\", \"best_bid\":\"0.78\", \"best_ask\":\"0.81\"}], \"timestamp\":\"1785208418660\", \"event_type\":\"price_change\"}","received_at":"2026-07-28T03:13:38.681047Z","schema_version":"clob-market-ws.price_change.v1","sequence":null,"server_hash":null,"server_timestamp":"1785208418660","session_id":"3e519d9098404c15b234d96025eb1a2b","source":"clob_market_ws"},"received_at":"2026-07-28T03:13:38.681047Z","record_id":"f95344c3b288adf3bff969d58ecabb1cad08f409e08133ea2fe1f33ecfee74b2","schema_fingerprint":"4aa3821a28b0b7c2400bc59aba4bcc0a76e971dadd19610d3ad38c768e124dc7","schema_version":"edge-lab-recorder.raw.v1","sequence":null,"source":"clob_market_ws"}
{"event_at":"2026-07-28T03:13:38.662000Z","event_fingerprint":"a99537132ac90f9b058a0624d436a957502f62bff0fb37057e85fb99616cfc6f","payload":{"connection_id":"a6b55582af5f430fb37ad02bf0922475","event_at":"2026-07-28T03:13:38.662000Z","event_type":"price_change","frame_hash":"93b577da5872b62786de8c6f79198cf4d409806f3feb81b3a6af41eff1c8527a","frame_index":0,"kind":"data","monotonic_ns":310401717745875,"payload":{"event_type":"price_change","market":"0x779291bef19b6709f61e9764a954aafe9ffae488d50ae674aabdcb4f248006d5","price_changes":[{"asset_id":"8761897749749422724209054078244794145777693856614463256546737399611489089783","best_ask":"0.22","best_bid":"0.19","hash":"b3566998359f5a303e8ed619a4bd52a21681da5c","price":"0.05","side":"BUY","size":"986"},{"asset_id":"14965588658799411272385430903075831224615961675357217884735713260981483529984","best_ask":"0.81","best_bid":"0.78","hash":"e428d7dd57cb320d5dbcac859cf5585014362e29","price":"0.95","side":"SELL","size":"986"}],"timestamp":"1785208418662"},"payload_hash":"87d0547c8c465f181d64fd50c20a65183122e52adb188d5e0dde8185cd7e201b","raw_frame":"{\"market\":\"0x779291bef19b6709f61e9764a954aafe9ffae488d50ae674aabdcb4f248006d5\", \"price_changes\":[{\"asset_id\":\"8761897749749422724209054078244794145777693856614463256546737399611489089783\", \"price\":\"0.05\", \"size\":\"986\", \"side\":\"BUY\", \"hash\":\"b3566998359f5a303e8ed619a4bd52a21681da5c\", \"best_bid\":\"0.19\", \"best_ask\":\"0.22\"}, {\"asset_id\":\"14965588658799411272385430903075831224615961675357217884735713260981483529984\", \"price\":\"0.95\", \"size\":\"986\", \"side\":\"SELL\", \"hash\":\"e428d7dd57cb320d5dbcac859cf5585014362e29\", \"best_bid\":\"0.78\", \"best_ask\":\"0.81\"}], \"timestamp\":\"1785208418662\", \"event_type\":\"price_change\"}","received_at":"2026-07-28T03:13:38.682533Z","schema_version":"clob-market-ws.price_change.v1","sequence":null,"server_hash":null,"server_timestamp":"1785208418662","session_id":"3e519d9098404c15b234d96025eb1a2b","source":"clob_market_ws"},"received_at":"2026-07-28T03:13:38.682533Z","record_id":"62d528f526be11aa5bba71a14827c8f48635a1dcdcd96e8e387bf4ba9da21e8e","schema_fingerprint":"4aa3821a28b0b7c2400bc59aba4bcc0a76e971dadd19610d3ad38c768e124dc7","schema_version":"edge-lab-recorder.raw.v1","sequence":null,"source":"clob_market_ws"}
{"event_at":"2026-07-28T03:13:38.663000Z","event_fingerprint":"cad4dbecf766e57054f04e9e6eb15685998d29d2a2ee1c7dd30b6e4e584a40cc","payload":{"connection_id":"a6b55582af5f430fb37ad02bf0922475","event_at":"2026-07-28T03:13:38.663000Z","event_type":"price_change","frame_hash":"09e321a84a0f59a6f9d2922408748226e5bb57c12fae4f53e17fb4eafec98700","frame_index":0,"kind":"data","monotonic_ns":310401719216208,"payload":{"event_type":"price_change","market":"0x779291bef19b6709f61e9764a954aafe9ffae488d50ae674aabdcb4f248006d5","price_changes":[{"asset_id":"14965588658799411272385430903075831224615961675357217884735713260981483529984","best_ask":"0.81","best_bid":"0.78","hash":"a5d5e832427103aecf8c41e49d449c833bfdffcf","price":"0.69","side":"BUY","size":"36"},{"asset_id":"8761897749749422724209054078244794145777693856614463256546737399611489089783","best_ask":"0.22","best_bid":"0.19","hash":"35bd8181111e2105f299730ca91595142be6d1ef","price":"0.31","side":"SELL","size":"36"}],"timestamp":"1785208418663"},"payload_hash":"15af7f969e860bc29983a7d08d5deecd592241468a2e2e59f8e834262301ea83","raw_frame":"{\"market\":\"0x779291bef19b6709f61e9764a954aafe9ffae488d50ae674aabdcb4f248006d5\", \"price_changes\":[{\"asset_id\":\"14965588658799411272385430903075831224615961675357217884735713260981483529984\", \"price\":\"0.69\", \"size\":\"36\", \"side\":\"BUY\", \"hash\":\"a5d5e832427103aecf8c41e49d449c833bfdffcf\", \"best_bid\":\"0.78\", \"best_ask\":\"0.81\"}, {\"asset_id\":\"8761897749749422724209054078244794145777693856614463256546737399611489089783\", \"price\":\"0.31\", \"size\":\"36\", \"side\":\"SELL\", \"hash\":\"35bd8181111e2105f299730ca91595142be6d1ef\", \"best_bid\":\"0.19\", \"best_ask\":\"0.22\"}], \"timestamp\":\"1785208418663\", \"event_type\":\"price_change\"}","received_at":"2026-07-28T03:13:38.684003Z","schema_version":"clob-market-ws.price_change.v1","sequence":null,"server_hash":null,"server_timestamp":"1785208418663","session_id":"3e519d9098404c15b234d96025eb1a2b","source":"clob_market_ws"},"received_at":"2026-07-28T03:13:38.684003Z","record_id":"41f74a02165953e70c1018d804247c0a242601377e497d983c1b6cbb6846dd60","schema_fingerprint":"4aa3821a28b0b7c2400bc59aba4bcc0a76e971dadd19610d3ad38c768e124dc7","schema_version":"edge-lab-recorder.raw.v1","sequence":null,"source":"clob_market_ws"}
{"event_at":"2026-07-28T03:13:38.666000Z","event_fingerprint":"5cff01310926967655dcf808a1ece06d30eea564ee0f239fa709cb250fb368c2","payload":{"connection_id":"a6b55582af5f430fb37ad02bf0922475","event_at":"2026-07-28T03:13:38.666000Z","event_type":"best_bid_ask","frame_hash":"8fb700baf47a008255f145b0487e8579b4efad19adf813c8626232c2b58873df","frame_index":0,"kind":"data","monotonic_ns":310401720748000,"payload":{"asset_id":"14965588658799411272385430903075831224615961675357217884735713260981483529984","best_ask":"0.8","best_bid":"0.78","event_type":"best_bid_ask","market":"0x779291bef19b6709f61e9764a954aafe9ffae488d50ae674aabdcb4f248006d5","spread":"0.02","timestamp":"1785208418666"},"payload_hash":"7bbda2b2b35ce24b193182ced9cb57a0e2cb59658ef87ca4e07f1db1afea6702","raw_frame":"{\"market\":\"0x779291bef19b6709f61e9764a954aafe9ffae488d50ae674aabdcb4f248006d5\", \"asset_id\":\"14965588658799411272385430903075831224615961675357217884735713260981483529984\", \"best_bid\":\"0.78\", \"best_ask\":\"0.8\", \"spread\":\"0.02\", \"timestamp\":\"1785208418666\", \"event_type\":\"best_bid_ask\"}","received_at":"2026-07-28T03:13:38.685534Z","schema_version":"clob-market-ws.best_bid_ask.v1","sequence":null,"server_hash":null,"server_timestamp":"1785208418666","session_id":"3e519d9098404c15b234d96025eb1a2b","source":"clob_market_ws"},"received_at":"2026-07-28T03:13:38.685534Z","record_id":"bf4fca46cb8bb792027b6dd2c112db03a50199eb4429effcedae8271b978ac7a","schema_fingerprint":"8488399f31b0337811b13b266be932db7062827c2470b78bd8e9e99bab51d17d","schema_version":"edge-lab-recorder.raw.v1","sequence":null,"source":"clob_market_ws"}
{"event_at":"2026-07-28T03:13:38.666000Z","event_fingerprint":"f68da5e45dff065d66508ff5c40a789a16788d29fd03fe3f77bd8f61806b66b9","payload":{"connection_id":"a6b55582af5f430fb37ad02bf0922475","event_at":"2026-07-28T03:13:38.666000Z","event_type":"best_bid_ask","frame_hash":"c90ca1d414a153aaf83f0641f2481dd7024e55c5dc2a4a5da7ad7a8760d37a5a","frame_index":0,"kind":"data","monotonic_ns":310401721810791,"payload":{"asset_id":"8761897749749422724209054078244794145777693856614463256546737399611489089783","best_ask":"0.22","best_bid":"0.2","event_type":"best_bid_ask","market":"0x779291bef19b6709f61e9764a954aafe9ffae488d50ae674aabdcb4f248006d5","spread":"0.02","timestamp":"1785208418666"},"payload_hash":"7a077fd9ce7a962d11c0c1bc173ab5eee6eaf6538d3811c5206e1d6a3f7c7058","raw_frame":"{\"market\":\"0x779291bef19b6709f61e9764a954aafe9ffae488d50ae674aabdcb4f248006d5\", \"asset_id\":\"8761897749749422724209054078244794145777693856614463256546737399611489089783\", \"best_bid\":\"0.2\", \"best_ask\":\"0.22\", \"spread\":\"0.02\", \"timestamp\":\"1785208418666\", \"event_type\":\"best_bid_ask\"}","received_at":"2026-07-28T03:13:38.686597Z","schema_version":"clob-market-ws.best_bid_ask.v1","sequence":null,"server_hash":null,"server_timestamp":"1785208418666","session_id":"3e519d9098404c15b234d96025eb1a2b","source":"clob_market_ws"},"received_at":"2026-07-28T03:13:38.686597Z","record_id":"b965d9bed6d20696a82f9336753f8d00915d984c42b715075cc02827c478e67c","schema_fingerprint":"8488399f31b0337811b13b266be932db7062827c2470b78bd8e9e99bab51d17d","schema_version":"edge-lab-recorder.raw.v1","sequence":null,"source":"clob_market_ws"}
{"event_at":"2026-07-28T03:13:38.666000Z","event_fingerprint":"47cf39dd73e5a865b4294b36324b38dbb3b9b3bbd22f63695f5dde39b57d7a4b","payload":{"connection_id":"a6b55582af5f430fb37ad02bf0922475","event_at":"2026-07-28T03:13:38.666000Z","event_type":"price_change","frame_hash":"d4588d829ae9a51479b2408928b1409c798ed3a184c2b1d34a52cb0d487f8646","frame_index":0,"kind":"data","monotonic_ns":310401722955291,"payload":{"event_type":"price_change","market":"0x779291bef19b6709f61e9764a954aafe9ffae488d50ae674aabdcb4f248006d5","price_changes":[{"asset_id":"8761897749749422724209054078244794145777693856614463256546737399611489089783","best_ask":"0.22","best_bid":"0.2","hash":"4b7f50714c6c4276f55b98399feb2a8f5f7d7fd4","price":"0.2","side":"BUY","size":"5"},{"asset_id":"14965588658799411272385430903075831224615961675357217884735713260981483529984","best_ask":"0.8","best_bid":"0.78","hash":"7ef0768bfd83b324309bbae292848f22384e67f3","price":"0.8","side":"SELL","size":"5"}],"timestamp":"1785208418666"},"payload_hash":"efed883fe524eaf17df6357525e4dc87c020a0682baacb46fc14a2dd27eab27c","raw_frame":"{\"market\":\"0x779291bef19b6709f61e9764a954aafe9ffae488d50ae674aabdcb4f248006d5\", \"price_changes\":[{\"asset_id\":\"8761897749749422724209054078244794145777693856614463256546737399611489089783\", \"price\":\"0.2\", \"size\":\"5\", \"side\":\"BUY\", \"hash\":\"4b7f50714c6c4276f55b98399feb2a8f5f7d7fd4\", \"best_bid\":\"0.2\", \"best_ask\":\"0.22\"}, {\"asset_id\":\"14965588658799411272385430903075831224615961675357217884735713260981483529984\", \"price\":\"0.8\", \"size\":\"5\", \"side\":\"SELL\", \"hash\":\"7ef0768bfd83b324309bbae292848f22384e67f3\", \"best_bid\":\"0.78\", \"best_ask\":\"0.8\"}], \"timestamp\":\"1785208418666\", \"event_type\":\"price_change\"}","received_at":"2026-07-28T03:13:38.687741Z","schema_version":"clob-market-ws.price_change.v1","sequence":null,"server_hash":null,"server_timestamp":"1785208418666","session_id":"3e519d9098404c15b234d96025eb1a2b","source":"clob_market_ws"},"received_at":"2026-07-28T03:13:38.687741Z","record_id":"404f52d0b6e813395e9011c24da6722f66eca811fbdfeffc2baf84a848f5e8e3","schema_fingerprint":"4aa3821a28b0b7c2400bc59aba4bcc0a76e971dadd19610d3ad38c768e124dc7","schema_version":"edge-lab-recorder.raw.v1","sequence":null,"source":"clob_market_ws"}
{"event_at":"2026-07-28T03:13:38.667000Z","event_fingerprint":"c20d055c9db494fb0f79a4b1e6a75bf1a00ace9df140a51e6bd9438a8ddb0dd6","payload":{"connection_id":"a6b55582af5f430fb37ad02bf0922475","event_at":"2026-07-28T03:13:38.667000Z","event_type":"price_change","frame_hash":"27e138d91d4b858fb364b710e6e0e257752bad3c5afe79d2555ffd2d9197db27","frame_index":0,"kind":"data","monotonic_ns":310401724564583,"payload":{"event_type":"price_change","market":"0x779291bef19b6709f61e9764a954aafe9ffae488d50ae674aabdcb4f248006d5","price_changes":[{"asset_id":"8761897749749422724209054078244794145777693856614463256546737399611489089783","best_ask":"0.22","best_bid":"0.2","hash":"3276bcb30a8c5f2b6f1a00e03e316d08eff9e94e","price":"0.2","side":"BUY","size":"10"},{"asset_id":"14965588658799411272385430903075831224615961675357217884735713260981483529984","best_ask":"0.8","best_bid":"0.78","hash":"c4765fbb022000c6767ceed0c5fa52370ca6ad33","price":"0.8","side":"SELL","size":"10"}],"timestamp":"1785208418667"},"payload_hash":"7f9f320a6d02a4c457cd13080ea73d813383807c8059fcfa7279916d10753ea5","raw_frame":"{\"market\":\"0x779291bef19b6709f61e9764a954aafe9ffae488d50ae674aabdcb4f248006d5\", \"price_changes\":[{\"asset_id\":\"8761897749749422724209054078244794145777693856614463256546737399611489089783\", \"price\":\"0.2\", \"size\":\"10\", \"side\":\"BUY\", \"hash\":\"3276bcb30a8c5f2b6f1a00e03e316d08eff9e94e\", \"best_bid\":\"0.2\", \"best_ask\":\"0.22\"}, {\"asset_id\":\"14965588658799411272385430903075831224615961675357217884735713260981483529984\", \"price\":\"0.8\", \"size\":\"10\", \"side\":\"SELL\", \"hash\":\"c4765fbb022000c6767ceed0c5fa52370ca6ad33\", \"best_bid\":\"0.78\", \"best_ask\":\"0.8\"}], \"timestamp\":\"1785208418667\", \"event_type\":\"price_change\"}","received_at":"2026-07-28T03:13:38.689351Z","schema_version":"clob-market-ws.price_change.v1","sequence":null,"server_hash":null,"server_timestamp":"1785208418667","session_id":"3e519d9098404c15b234d96025eb1a2b","source":"clob_market_ws"},"received_at":"2026-07-28T03:13:38.689351Z","record_id":"4ce27cae2182e67145cb04f3bed03cc274d7c94670250c4a5b346f4b1496aa52","schema_fingerprint":"4aa3821a28b0b7c2400bc59aba4bcc0a76e971dadd19610d3ad38c768e124dc7","schema_version":"edge-lab-recorder.raw.v1","sequence":null,"source":"clob_market_ws"}
{"event_at":"2026-07-28T03:13:38.667000Z","event_fingerprint":"1fd02d8b0d3029c6ef8d2e7b0a4a96e35d35e5ee8191b2ebc36c96af3bcb8697","payload":{"connection_id":"a6b55582af5f430fb37ad02bf0922475","event_at":"2026-07-28T03:13:38.667000Z","event_type":"price_change","frame_hash":"4a94daed91c12a4ec171167e5d31afcf65524b5a87674f2ee0e7c56ca2b5c268","frame_index":0,"kind":"data","monotonic_ns":310401726061083,"payload":{"event_type":"price_change","market":"0x779291bef19b6709f61e9764a954aafe9ffae488d50ae674aabdcb4f248006d5","price_changes":[{"asset_id":"8761897749749422724209054078244794145777693856614463256546737399611489089783","best_ask":"0.22","best_bid":"0.2","hash":"0fbf09a27e4db1e7444708def75725e003fa508c","price":"0.05","side":"BUY","size":"1016"},{"asset_id":"14965588658799411272385430903075831224615961675357217884735713260981483529984","best_ask":"0.8","best_bid":"0.78","hash":"dbb967cbcfe40afc00d5e63b9c5baecde46780e3","price":"0.95","side":"SELL","size":"1016"}],"timestamp":"1785208418667"},"payload_hash":"a88252ae29d0e8bc509dac9503e2d1af5448048bfe42163297f407ec4e40d97f","raw_frame":"{\"market\":\"0x779291bef19b6709f61e9764a954aafe9ffae488d50ae674aabdcb4f248006d5\", \"price_changes\":[{\"asset_id\":\"8761897749749422724209054078244794145777693856614463256546737399611489089783\", \"price\":\"0.05\", \"size\":\"1016\", \"side\":\"BUY\", \"hash\":\"0fbf09a27e4db1e7444708def75725e003fa508c\", \"best_bid\":\"0.2\", \"best_ask\":\"0.22\"}, {\"asset_id\":\"14965588658799411272385430903075831224615961675357217884735713260981483529984\", \"price\":\"0.95\", \"size\":\"1016\", \"side\":\"SELL\", \"hash\":\"dbb967cbcfe40afc00d5e63b9c5baecde46780e3\", \"best_bid\":\"0.78\", \"best_ask\":\"0.8\"}], \"timestamp\":\"1785208418667\", \"event_type\":\"price_change\"}","received_at":"2026-07-28T03:13:38.690847Z","schema_version":"clob-market-ws.price_change.v1","sequence":null,"server_hash":null,"server_timestamp":"1785208418667","session_id":"3e519d9098404c15b234d96025eb1a2b","source":"clob_market_ws"},"received_at":"2026-07-28T03:13:38.690847Z","record_id":"a30b5812d402db97819f123d814a4cbe4a710fb07b068861c0d6f96ec38e9dd9","schema_fingerprint":"4aa3821a28b0b7c2400bc59aba4bcc0a76e971dadd19610d3ad38c768e124dc7","schema_version":"edge-lab-recorder.raw.v1","sequence":null,"source":"clob_market_ws"}
{"event_at":"2026-07-28T03:13:38.669000Z","event_fingerprint":"215e16f2aed525e31cf02da1de9c91b33edaa5af64f881225614b7a013045c67","payload":{"connection_id":"a6b55582af5f430fb37ad02bf0922475","event_at":"2026-07-28T03:13:38.669000Z","event_type":"price_change","frame_hash":"36d1f327c9d87b4f5e0e850e1b773f9e6f3802240547ffeb2c4cff09dfb70df2","frame_index":0,"kind":"data","monotonic_ns":310401727549625,"payload":{"event_type":"price_change","market":"0x779291bef19b6709f61e9764a954aafe9ffae488d50ae674aabdcb4f248006d5","price_changes":[{"asset_id":"8761897749749422724209054078244794145777693856614463256546737399611489089783","best_ask":"0.22","best_bid":"0.2","hash":"ececb09d9032229641144aae2e25ad3729c37c28","price":"0.2","side":"BUY","size":"5"},{"asset_id":"14965588658799411272385430903075831224615961675357217884735713260981483529984","best_ask":"0.8","best_bid":"0.78","hash":"3991a50c349d380f486349d62c61ffaf21c2df39","price":"0.8","side":"SELL","size":"5"}],"timestamp":"1785208418669"},"payload_hash":"417e903de372b1fec762115cf2b84c59c0f9f26c683880589c4d19f921cb15a2","raw_frame":"{\"market\":\"0x779291bef19b6709f61e9764a954aafe9ffae488d50ae674aabdcb4f248006d5\", \"price_changes\":[{\"asset_id\":\"8761897749749422724209054078244794145777693856614463256546737399611489089783\", \"price\":\"0.2\", \"size\":\"5\", \"side\":\"BUY\", \"hash\":\"ececb09d9032229641144aae2e25ad3729c37c28\", \"best_bid\":\"0.2\", \"best_ask\":\"0.22\"}, {\"asset_id\":\"14965588658799411272385430903075831224615961675357217884735713260981483529984\", \"price\":\"0.8\", \"size\":\"5\", \"side\":\"SELL\", \"hash\":\"3991a50c349d380f486349d62c61ffaf21c2df39\", \"best_bid\":\"0.78\", \"best_ask\":\"0.8\"}], \"timestamp\":\"1785208418669\", \"event_type\":\"price_change\"}","received_at":"2026-07-28T03:13:38.692337Z","schema_version":"clob-market-ws.price_change.v1","sequence":null,"server_hash":null,"server_timestamp":"1785208418669","session_id":"3e519d9098404c15b234d96025eb1a2b","source":"clob_market_ws"},"received_at":"2026-07-28T03:13:38.692337Z","record_id":"07a989149e0152a047dd9861f8cb83e4cc6a94b17ad73d108cafca9211fdc556","schema_fingerprint":"4aa3821a28b0b7c2400bc59aba4bcc0a76e971dadd19610d3ad38c768e124dc7","schema_version":"edge-lab-recorder.raw.v1","sequence":null,"source":"clob_market_ws"}
{"event_at":"2026-07-28T03:13:38.681000Z","event_fingerprint":"f1469dd5fe7c19d2e1145a475dfa5f50d331c23f5201c19ce0e95993c067102f","payload":{"connection_id":"a6b55582af5f430fb37ad02bf0922475","event_at":"2026-07-28T03:13:38.681000Z","event_type":"best_bid_ask","frame_hash":"c3ecb4a566d66d6fae41d52f1584bff792a400b61721915fc44f81d172e7c885","frame_index":0,"kind":"data","monotonic_ns":310401729014750,"payload":{"asset_id":"14965588658799411272385430903075831224615961675357217884735713260981483529984","best_ask":"0.81","best_bid":"0.78","event_type":"best_bid_ask","market":"0x779291bef19b6709f61e9764a954aafe9ffae488d50ae674aabdcb4f248006d5","spread":"0.03","timestamp":"1785208418681"},"payload_hash":"9629cf9cf050ea060666a3ab5f6d9ec52c364e481fcfaff647cba37910216114","raw_frame":"{\"market\":\"0x779291bef19b6709f61e9764a954aafe9ffae488d50ae674aabdcb4f248006d5\", \"asset_id\":\"14965588658799411272385430903075831224615961675357217884735713260981483529984\", \"best_bid\":\"0.78\", \"best_ask\":\"0.81\", \"spread\":\"0.03\", \"timestamp\":\"1785208418681\", \"event_type\":\"best_bid_ask\"}","received_at":"2026-07-28T03:13:38.693801Z","schema_version":"clob-market-ws.best_bid_ask.v1","sequence":null,"server_hash":null,"server_timestamp":"1785208418681","session_id":"3e519d9098404c15b234d96025eb1a2b","source":"clob_market_ws"},"received_at":"2026-07-28T03:13:38.693801Z","record_id":"caac3ba3636480f7dae7c1c0d1ec627f2ad21c271ffd5cb2d8dd5e7b15ed261d","schema_fingerprint":"8488399f31b0337811b13b266be932db7062827c2470b78bd8e9e99bab51d17d","schema_version":"edge-lab-recorder.raw.v1","sequence":null,"source":"clob_market_ws"}
{"event_at":"2026-07-28T03:13:38.681000Z","event_fingerprint":"c791474ce78a31b0a55f4a802171af672ffedb3d88b813be3899e8e52a2bbc86","payload":{"connection_id":"a6b55582af5f430fb37ad02bf0922475","event_at":"2026-07-28T03:13:38.681000Z","event_type":"best_bid_ask","frame_hash":"c3d2cac0e8904177cc9d2d9a2963db5580481ed1cec506fcaa0a5b983fc5b700","frame_index":0,"kind":"data","monotonic_ns":310401730136166,"payload":{"asset_id":"8761897749749422724209054078244794145777693856614463256546737399611489089783","best_ask":"0.22","best_bid":"0.19","event_type":"best_bid_ask","market":"0x779291bef19b6709f61e9764a954aafe9ffae488d50ae674aabdcb4f248006d5","spread":"0.03","timestamp":"1785208418681"},"payload_hash":"858fa1abe71b6f2748b409138142a13351c2bd3d7e8b0b7fd1c4a90b401d9df1","raw_frame":"{\"market\":\"0x779291bef19b6709f61e9764a954aafe9ffae488d50ae674aabdcb4f248006d5\", \"asset_id\":\"8761897749749422724209054078244794145777693856614463256546737399611489089783\", \"best_bid\":\"0.19\", \"best_ask\":\"0.22\", \"spread\":\"0.03\", \"timestamp\":\"1785208418681\", \"event_type\":\"best_bid_ask\"}","received_at":"2026-07-28T03:13:38.694921Z","schema_version":"clob-market-ws.best_bid_ask.v1","sequence":null,"server_hash":null,"server_timestamp":"1785208418681","session_id":"3e519d9098404c15b234d96025eb1a2b","source":"clob_market_ws"},"received_at":"2026-07-28T03:13:38.694921Z","record_id":"7f87cbeafd7f8d2966d9475150d9b27f7c016b1bf52917241c05752a4ebabe9a","schema_fingerprint":"8488399f31b0337811b13b266be932db7062827c2470b78bd8e9e99bab51d17d","schema_version":"edge-lab-recorder.raw.v1","sequence":null,"source":"clob_market_ws"}
{"event_at":"2026-07-28T03:13:38.681000Z","event_fingerprint":"4cd4f3f08f1152aeece26304bfc4c397ab43bc5726e9c02e520556cfe2e0e4f9","payload":{"connection_id":"a6b55582af5f430fb37ad02bf0922475","event_at":"2026-07-28T03:13:38.681000Z","event_type":"price_change","frame_hash":"6d8f414d5faae7d198ba638e08f608f9d7f06701aeebb769c4e2d54b0ffa7f57","frame_index":0,"kind":"data","monotonic_ns":310401731214875,"payload":{"event_type":"price_change","market":"0x779291bef19b6709f61e9764a954aafe9ffae488d50ae674aabdcb4f248006d5","price_changes":[{"asset_id":"8761897749749422724209054078244794145777693856614463256546737399611489089783","best_ask":"0.22","best_bid":"0.19","hash":"7e1b6ce71e389b17d23164d418f6d38b1e6bab53","price":"0.2","side":"BUY","size":"0"},{"asset_id":"14965588658799411272385430903075831224615961675357217884735713260981483529984","best_ask":"0.81","best_bid":"0.78","hash":"f3ef8dfaa00836981e98248c680fc360a3e574c1","price":"0.8","side":"SELL","size":"0"}],"timestamp":"1785208418681"},"payload_hash":"ab8cef6bd1b0667981ca741523120ed645c2e0d94f99337b009eb234336703ab","raw_frame":"{\"market\":\"0x779291bef19b6709f61e9764a954aafe9ffae488d50ae674aabdcb4f248006d5\", \"price_changes\":[{\"asset_id\":\"8761897749749422724209054078244794145777693856614463256546737399611489089783\", \"price\":\"0.2\", \"size\":\"0\", \"side\":\"BUY\", \"hash\":\"7e1b6ce71e389b17d23164d418f6d38b1e6bab53\", \"best_bid\":\"0.19\", \"best_ask\":\"0.22\"}, {\"asset_id\":\"14965588658799411272385430903075831224615961675357217884735713260981483529984\", \"price\":\"0.8\", \"size\":\"0\", \"side\":\"SELL\", \"hash\":\"f3ef8dfaa00836981e98248c680fc360a3e574c1\", \"best_bid\":\"0.78\", \"best_ask\":\"0.81\"}], \"timestamp\":\"1785208418681\", \"event_type\":\"price_change\"}","received_at":"2026-07-28T03:13:38.696002Z","schema_version":"clob-market-ws.price_change.v1","sequence":null,"server_hash":null,"server_timestamp":"1785208418681","session_id":"3e519d9098404c15b234d96025eb1a2b","source":"clob_market_ws"},"received_at":"2026-07-28T03:13:38.696002Z","record_id":"311c732ed062affabf04c479695b050448b82872ecef15ca0f764336d72d345e","schema_fingerprint":"4aa3821a28b0b7c2400bc59aba4bcc0a76e971dadd19610d3ad38c768e124dc7","schema_version":"edge-lab-recorder.raw.v1","sequence":null,"source":"clob_market_ws"}
{"event_at":"2026-07-28T03:13:38.687000Z","event_fingerprint":"f00488e4aeaef745d8f7c80689e7e3b477fd6b23d3768cc1f23301bf8324f026","payload":{"connection_id":"a6b55582af5f430fb37ad02bf0922475","event_at":"2026-07-28T03:13:38.687000Z","event_type":"price_change","frame_hash":"3091c372fb626af0fded65a144f19d1de8f4244ebb563d6555727bc16dcf75bc","frame_index":0,"kind":"data","monotonic_ns":310401732716250,"payload":{"event_type":"price_change","market":"0x779291bef19b6709f61e9764a954aafe9ffae488d50ae674aabdcb4f248006d5","price_changes":[{"asset_id":"14965588658799411272385430903075831224615961675357217884735713260981483529984","best_ask":"0.81","best_bid":"0.78","hash":"b60c97945822f04bd54a6296e950c742c0c21eea","price":"0.73","side":"BUY","size":"72.59"},{"asset_id":"8761897749749422724209054078244794145777693856614463256546737399611489089783","best_ask":"0.22","best_bid":"0.19","hash":"23e2338c975789dbf57d5e0524a436ed318079b7","price":"0.27","side":"SELL","size":"72.59"}],"timestamp":"1785208418687"},"payload_hash":"822bcd11fd4a44ebd61d9be72abc98b0b33f4a0569755d56ec303c894a3abf8c","raw_frame":"{\"market\":\"0x779291bef19b6709f61e9764a954aafe9ffae488d50ae674aabdcb4f248006d5\", \"price_changes\":[{\"asset_id\":\"14965588658799411272385430903075831224615961675357217884735713260981483529984\", \"price\":\"0.73\", \"size\":\"72.59\", \"side\":\"BUY\", \"hash\":\"b60c97945822f04bd54a6296e950c742c0c21eea\", \"best_bid\":\"0.78\", \"best_ask\":\"0.81\"}, {\"asset_id\":\"8761897749749422724209054078244794145777693856614463256546737399611489089783\", \"price\":\"0.27\", \"size\":\"72.59\", \"side\":\"SELL\", \"hash\":\"23e2338c975789dbf57d5e0524a436ed318079b7\", \"best_bid\":\"0.19\", \"best_ask\":\"0.22\"}], \"timestamp\":\"1785208418687\", \"event_type\":\"price_change\"}","received_at":"2026-07-28T03:13:38.697503Z","schema_version":"clob-market-ws.price_change.v1","sequence":null,"server_hash":null,"server_timestamp":"1785208418687","session_id":"3e519d9098404c15b234d96025eb1a2b","source":"clob_market_ws"},"received_at":"2026-07-28T03:13:38.697503Z","record_id":"b85c265f5e5791297265c7a9f3f5b6c40d192f539ec01d4d16e98696da8b88fa","schema_fingerprint":"4aa3821a28b0b7c2400bc59aba4bcc0a76e971dadd19610d3ad38c768e124dc7","schema_version":"edge-lab-recorder.raw.v1","sequence":null,"source":"clob_market_ws"}
{"event_at":"2026-07-28T03:13:38.688000Z","event_fingerprint":"4d17cec760980599e4c71f5c50d20b300ba5a9e6a4e77ac2bb9d3036e1a1602e","payload":{"connection_id":"a6b55582af5f430fb37ad02bf0922475","event_at":"2026-07-28T03:13:38.688000Z","event_type":"price_change","frame_hash":"087ef767ee7325c67821182cf5ff356218bb2aefe99e7f1a164a5c26d1435ca0","frame_index":0,"kind":"data","monotonic_ns":310401734172416,"payload":{"event_type":"price_change","market":"0x779291bef19b6709f61e9764a954aafe9ffae488d50ae674aabdcb4f248006d5","price_changes":[{"asset_id":"8761897749749422724209054078244794145777693856614463256546737399611489089783","best_ask":"0.22","best_bid":"0.19","hash":"18cc0e820d787e86089795144e610c6579954a9d","price":"0.05","side":"BUY","size":"1046"},{"asset_id":"14965588658799411272385430903075831224615961675357217884735713260981483529984","best_ask":"0.81","best_bid":"0.78","hash":"28d5dc6d7c5b56a5bbe71fc1fa4967330c8afbfd","price":"0.95","side":"SELL","size":"1046"}],"timestamp":"1785208418688"},"payload_hash":"15f41dce7c920c14c99e1dc11cc18ae988d49f59fd8fa3a3fb97178ee11afd57","raw_frame":"{\"market\":\"0x779291bef19b6709f61e9764a954aafe9ffae488d50ae674aabdcb4f248006d5\", \"price_changes\":[{\"asset_id\":\"8761897749749422724209054078244794145777693856614463256546737399611489089783\", \"price\":\"0.05\", \"size\":\"1046\", \"side\":\"BUY\", \"hash\":\"18cc0e820d787e86089795144e610c6579954a9d\", \"best_bid\":\"0.19\", \"best_ask\":\"0.22\"}, {\"asset_id\":\"14965588658799411272385430903075831224615961675357217884735713260981483529984\", \"price\":\"0.95\", \"size\":\"1046\", \"side\":\"SELL\", \"hash\":\"28d5dc6d7c5b56a5bbe71fc1fa4967330c8afbfd\", \"best_bid\":\"0.78\", \"best_ask\":\"0.81\"}], \"timestamp\":\"1785208418688\", \"event_type\":\"price_change\"}","received_at":"2026-07-28T03:13:38.698959Z","schema_version":"clob-market-ws.price_change.v1","sequence":null,"server_hash":null,"server_timestamp":"1785208418688","session_id":"3e519d9098404c15b234d96025eb1a2b","source":"clob_market_ws"},"received_at":"2026-07-28T03:13:38.698959Z","record_id":"da447a48871db9cb42f5bd092833fc5c1876db257ea8157c0d8d2d9384f065f2","schema_fingerprint":"4aa3821a28b0b7c2400bc59aba4bcc0a76e971dadd19610d3ad38c768e124dc7","schema_version":"edge-lab-recorder.raw.v1","sequence":null,"source":"clob_market_ws"}
{"event_at":"2026-07-28T03:13:38.690000Z","event_fingerprint":"1a971198358b72f606e9059c7980e321c6452eb028d545dea506d750e3920ea5","payload":{"connection_id":"a6b55582af5f430fb37ad02bf0922475","event_at":"2026-07-28T03:13:38.690000Z","event_type":"price_change","frame_hash":"7690d49fa62351653a9f0db7c6f402c2c43b583c94d48a40817c982a8bf5a14b","frame_index":0,"kind":"data","monotonic_ns":310401735652583,"payload":{"event_type":"price_change","market":"0x779291bef19b6709f61e9764a954aafe9ffae488d50ae674aabdcb4f248006d5","price_changes":[{"asset_id":"8761897749749422724209054078244794145777693856614463256546737399611489089783","best_ask":"0.22","best_bid":"0.19","hash":"ed968b9dc370f5e89933309f48568db2b393fc99","price":"0.12","side":"BUY","size":"42"},{"asset_id":"14965588658799411272385430903075831224615961675357217884735713260981483529984","best_ask":"0.81","best_bid":"0.78","hash":"9935054a2b2ab719e9c78f33f625fcec167c7d95","price":"0.88","side":"SELL","size":"42"}],"timestamp":"1785208418690"},"payload_hash":"3cee9e511303fb66f008e316efb2927211a51b1116407bc3316650a35f308303","raw_frame":"{\"market\":\"0x779291bef19b6709f61e9764a954aafe9ffae488d50ae674aabdcb4f248006d5\", \"price_changes\":[{\"asset_id\":\"8761897749749422724209054078244794145777693856614463256546737399611489089783\", \"price\":\"0.12\", \"size\":\"42\", \"side\":\"BUY\", \"hash\":\"ed968b9dc370f5e89933309f48568db2b393fc99\", \"best_bid\":\"0.19\", \"best_ask\":\"0.22\"}, {\"asset_id\":\"14965588658799411272385430903075831224615961675357217884735713260981483529984\", \"price\":\"0.88\", \"size\":\"42\", \"side\":\"SELL\", \"hash\":\"9935054a2b2ab719e9c78f33f625fcec167c7d95\", \"best_bid\":\"0.78\", \"best_ask\":\"0.81\"}], \"timestamp\":\"1785208418690\", \"event_type\":\"price_change\"}","received_at":"2026-07-28T03:13:38.700439Z","schema_version":"clob-market-ws.price_change.v1","sequence":null,"server_hash":null,"server_timestamp":"1785208418690","session_id":"3e519d9098404c15b234d96025eb1a2b","source":"clob_market_ws"},"received_at":"2026-07-28T03:13:38.700439Z","record_id":"9efe85721e1142b062eae32dfc61b45e14059e1bc37a6789453a8c63035e2c79","schema_fingerprint":"4aa3821a28b0b7c2400bc59aba4bcc0a76e971dadd19610d3ad38c768e124dc7","schema_version":"edge-lab-recorder.raw.v1","sequence":null,"source":"clob_market_ws"}
{"event_at":"2026-07-28T03:13:38.695000Z","event_fingerprint":"65cbc4fc2a6109ee80cd11c4a60e5cc1c456e94e0fe49883765f6f197828f921","payload":{"connection_id":"a6b55582af5f430fb37ad02bf0922475","event_at":"2026-07-28T03:13:38.695000Z","event_type":"best_bid_ask","frame_hash":"788defe5e187375c37c7437808e751da40ea698340c13a73a9a6e6d9a8271ca4","frame_index":0,"kind":"data","monotonic_ns":310401737088416,"payload":{"asset_id":"14965588658799411272385430903075831224615961675357217884735713260981483529984","best_ask":"0.81","best_bid":"0.79","event_type":"best_bid_ask","market":"0x779291bef19b6709f61e9764a954aafe9ffae488d50ae674aabdcb4f248006d5","spread":"0.02","timestamp":"1785208418695"},"payload_hash":"a427f5c150b5ddbbd8e2e1c66cebe6336edb45fb7550e23e5c1735e11407bc1c","raw_frame":"{\"market\":\"0x779291bef19b6709f61e9764a954aafe9ffae488d50ae674aabdcb4f248006d5\", \"asset_id\":\"14965588658799411272385430903075831224615961675357217884735713260981483529984\", \"best_bid\":\"0.79\", \"best_ask\":\"0.81\", \"spread\":\"0.02\", \"timestamp\":\"1785208418695\", \"event_type\":\"best_bid_ask\"}","received_at":"2026-07-28T03:13:38.701875Z","schema_version":"clob-market-ws.best_bid_ask.v1","sequence":null,"server_hash":null,"server_timestamp":"1785208418695","session_id":"3e519d9098404c15b234d96025eb1a2b","source":"clob_market_ws"},"received_at":"2026-07-28T03:13:38.701875Z","record_id":"b67564a1e70f64b7450d058d2a3ed9a3a0968021dcdd1e3e6e401745ecc67ab4","schema_fingerprint":"8488399f31b0337811b13b266be932db7062827c2470b78bd8e9e99bab51d17d","schema_version":"edge-lab-recorder.raw.v1","sequence":null,"source":"clob_market_ws"}
{"event_at":"2026-07-28T03:13:38.695000Z","event_fingerprint":"743f039a6b7d50bd375cb866df78b7a7322c044002b3de3071543bf2ec2aca79","payload":{"connection_id":"a6b55582af5f430fb37ad02bf0922475","event_at":"2026-07-28T03:13:38.695000Z","event_type":"best_bid_ask","frame_hash":"fb547ffff3b65c3666625366de1366579b888c4a8d9ec5041a9e94ebb1700f8a","frame_index":0,"kind":"data","monotonic_ns":310401740439375,"payload":{"asset_id":"8761897749749422724209054078244794145777693856614463256546737399611489089783","best_ask":"0.21","best_bid":"0.19","event_type":"best_bid_ask","market":"0x779291bef19b6709f61e9764a954aafe9ffae488d50ae674aabdcb4f248006d5","spread":"0.02","timestamp":"1785208418695"},"payload_hash":"f2673ef82bf4dbc032f29e70fffd86105e678b6377d8e85a56485880acfd64f0","raw_frame":"{\"market\":\"0x779291bef19b6709f61e9764a954aafe9ffae488d50ae674aabdcb4f248006d5\", \"asset_id\":\"8761897749749422724209054078244794145777693856614463256546737399611489089783\", \"best_bid\":\"0.19\", \"best_ask\":\"0.21\", \"spread\":\"0.02\", \"timestamp\":\"1785208418695\", \"event_type\":\"best_bid_ask\"}","received_at":"2026-07-28T03:13:38.705223Z","schema_version":"clob-market-ws.best_bid_ask.v1","sequence":null,"server_hash":null,"server_timestamp":"1785208418695","session_id":"3e519d9098404c15b234d96025eb1a2b","source":"clob_market_ws"},"received_at":"2026-07-28T03:13:38.705223Z","record_id":"77254b5b1c44b8cffa585bb5bb677121bb8efd1eeb224eab83ee1f82aa38b1ec","schema_fingerprint":"8488399f31b0337811b13b266be932db7062827c2470b78bd8e9e99bab51d17d","schema_version":"edge-lab-recorder.raw.v1","sequence":null,"source":"clob_market_ws"}
{"event_at":"2026-07-28T03:13:38.695000Z","event_fingerprint":"ed9364eda6360877cc9e5286253d068293f52d966500a8d434ef0ea7f93d6727","payload":{"connection_id":"a6b55582af5f430fb37ad02bf0922475","event_at":"2026-07-28T03:13:38.695000Z","event_type":"price_change","frame_hash":"943c5afe5e23d171d365ec517405621fca6c948f20ac64532188cbaeb736a803","frame_index":0,"kind":"data","monotonic_ns":310401743155083,"payload":{"event_type":"price_change","market":"0x779291bef19b6709f61e9764a954aafe9ffae488d50ae674aabdcb4f248006d5","price_changes":[{"asset_id":"14965588658799411272385430903075831224615961675357217884735713260981483529984","best_ask":"0.81","best_bid":"0.79","hash":"b2b0a66991e7f1b283d07f78e03fb2f60c173218","price":"0.79","side":"BUY","size":"5"},{"asset_id":"8761897749749422724209054078244794145777693856614463256546737399611489089783","best_ask":"0.21","best_bid":"0.19","hash":"0e4436db795784c9511aa693d40daad24a74155c","price":"0.21","side":"SELL","size":"5"}],"timestamp":"1785208418695"},"payload_hash":"e6f55daca908d30c36bab528844966212a0dcea893ea87460024b0b5879f517f","raw_frame":"{\"market\":\"0x779291bef19b6709f61e9764a954aafe9ffae488d50ae674aabdcb4f248006d5\", \"price_changes\":[{\"asset_id\":\"14965588658799411272385430903075831224615961675357217884735713260981483529984\", \"price\":\"0.79\", \"size\":\"5\", \"side\":\"BUY\", \"hash\":\"b2b0a66991e7f1b283d07f78e03fb2f60c173218\", \"best_bid\":\"0.79\", \"best_ask\":\"0.81\"}, {\"asset_id\":\"8761897749749422724209054078244794145777693856614463256546737399611489089783\", \"price\":\"0.21\", \"size\":\"5\", \"side\":\"SELL\", \"hash\":\"0e4436db795784c9511aa693d40daad24a74155c\", \"best_bid\":\"0.19\", \"best_ask\":\"0.21\"}], \"timestamp\":\"1785208418695\", \"event_type\":\"price_change\"}","received_at":"2026-07-28T03:13:38.707941Z","schema_version":"clob-market-ws.price_change.v1","sequence":null,"server_hash":null,"server_timestamp":"1785208418695","session_id":"3e519d9098404c15b234d96025eb1a2b","source":"clob_market_ws"},"received_at":"2026-07-28T03:13:38.707941Z","record_id":"0a6bc15f73ccef0eece97f62b7bdd41ce87d34e3bfab46e3c6b741e32f90d5b0","schema_fingerprint":"4aa3821a28b0b7c2400bc59aba4bcc0a76e971dadd19610d3ad38c768e124dc7","schema_version":"edge-lab-recorder.raw.v1","sequence":null,"source":"clob_market_ws"}
{"event_at":"2026-07-28T03:13:38.702000Z","event_fingerprint":"13ae91264ce3be52049a90aa00c89a7619fef721fcec4e48a059bf266e8a9499","payload":{"connection_id":"a6b55582af5f430fb37ad02bf0922475","event_at":"2026-07-28T03:13:38.702000Z","event_type":"price_change","frame_hash":"91c0374be85c190767d0a4e7ba69eb946f2ab44671aee8af1f08852e30701a86","frame_index":0,"kind":"data","monotonic_ns":310401752647875,"payload":{"event_type":"price_change","market":"0x779291bef19b6709f61e9764a954aafe9ffae488d50ae674aabdcb4f248006d5","price_changes":[{"asset_id":"8761897749749422724209054078244794145777693856614463256546737399611489089783","best_ask":"0.21","best_bid":"0.19","hash":"44e71cb9bc83b83f3f7566cee98376dd67f984f4","price":"0.11","side":"BUY","size":"55"},{"asset_id":"14965588658799411272385430903075831224615961675357217884735713260981483529984","best_ask":"0.81","best_bid":"0.79","hash":"45014f3be5a852a44d8f8f4897841dbab1a68180","price":"0.89","side":"SELL","size":"55"}],"timestamp":"1785208418702"},"payload_hash":"3541ade4d1718354c937b83094fd2582d95e77467d455ac5fe60c1e95815b7a6","raw_frame":"{\"market\":\"0x779291bef19b6709f61e9764a954aafe9ffae488d50ae674aabdcb4f248006d5\", \"price_changes\":[{\"asset_id\":\"8761897749749422724209054078244794145777693856614463256546737399611489089783\", \"price\":\"0.11\", \"size\":\"55\", \"side\":\"BUY\", \"hash\":\"44e71cb9bc83b83f3f7566cee98376dd67f984f4\", \"best_bid\":\"0.19\", \"best_ask\":\"0.21\"}, {\"asset_id\":\"14965588658799411272385430903075831224615961675357217884735713260981483529984\", \"price\":\"0.89\", \"size\":\"55\", \"side\":\"SELL\", \"hash\":\"45014f3be5a852a44d8f8f4897841dbab1a68180\", \"best_bid\":\"0.79\", \"best_ask\":\"0.81\"}], \"timestamp\":\"1785208418702\", \"event_type\":\"price_change\"}","received_at":"2026-07-28T03:13:38.717432Z","schema_version":"clob-market-ws.price_change.v1","sequence":null,"server_hash":null,"server_timestamp":"1785208418702","session_id":"3e519d9098404c15b234d96025eb1a2b","source":"clob_market_ws"},"received_at":"2026-07-28T03:13:38.717432Z","record_id":"80f7a9ff300446e4357589e9cfbe89b444a854914233aa65e0dfc54a1179d2ad","schema_fingerprint":"4aa3821a28b0b7c2400bc59aba4bcc0a76e971dadd19610d3ad38c768e124dc7","schema_version":"edge-lab-recorder.raw.v1","sequence":null,"source":"clob_market_ws"}
{"event_at":"2026-07-28T03:13:38.703000Z","event_fingerprint":"7127dc7a8441cc33902b46e451639862af2f0f7336206474560c79a1dec8c400","payload":{"connection_id":"a6b55582af5f430fb37ad02bf0922475","event_at":"2026-07-28T03:13:38.703000Z","event_type":"price_change","frame_hash":"7e56f5a1086011a6cbcbd237c065915f31ca43096a20fe9e9e6a01451a342437","frame_index":0,"kind":"data","monotonic_ns":310401754548416,"payload":{"event_type":"price_change","market":"0x779291bef19b6709f61e9764a954aafe9ffae488d50ae674aabdcb4f248006d5","price_changes":[{"asset_id":"8761897749749422724209054078244794145777693856614463256546737399611489089783","best_ask":"0.21","best_bid":"0.19","hash":"3a6f4aebd233b51e662a49d5a9972f23b778c01c","price":"0.12","side":"BUY","size":"57"},{"asset_id":"14965588658799411272385430903075831224615961675357217884735713260981483529984","best_ask":"0.81","best_bid":"0.79","hash":"551a414d331a36cc40e66c9bd2d4447e2598bd22","price":"0.88","side":"SELL","size":"57"}],"timestamp":"1785208418703"},"payload_hash":"9fe0a18b81ce70a9d765e6f6724a07bd463cbe18d016565bd828d91a77bb7e77","raw_frame":"{\"market\":\"0x779291bef19b6709f61e9764a954aafe9ffae488d50ae674aabdcb4f248006d5\", \"price_changes\":[{\"asset_id\":\"8761897749749422724209054078244794145777693856614463256546737399611489089783\", \"price\":\"0.12\", \"size\":\"57\", \"side\":\"BUY\", \"hash\":\"3a6f4aebd233b51e662a49d5a9972f23b778c01c\", \"best_bid\":\"0.19\", \"best_ask\":\"0.21\"}, {\"asset_id\":\"14965588658799411272385430903075831224615961675357217884735713260981483529984\", \"price\":\"0.88\", \"size\":\"57\", \"side\":\"SELL\", \"hash\":\"551a414d331a36cc40e66c9bd2d4447e2598bd22\", \"best_bid\":\"0.79\", \"best_ask\":\"0.81\"}], \"timestamp\":\"1785208418703\", \"event_type\":\"price_change\"}","received_at":"2026-07-28T03:13:38.719333Z","schema_version":"clob-market-ws.price_change.v1","sequence":null,"server_hash":null,"server_timestamp":"1785208418703","session_id":"3e519d9098404c15b234d96025eb1a2b","source":"clob_market_ws"},"received_at":"2026-07-28T03:13:38.719333Z","record_id":"76a2c486e378f8c8ebe1dccf2a60a36fe7ec2a1f81a090c1588941cd574e2d7c","schema_fingerprint":"4aa3821a28b0b7c2400bc59aba4bcc0a76e971dadd19610d3ad38c768e124dc7","schema_version":"edge-lab-recorder.raw.v1","sequence":null,"source":"clob_market_ws"}
{"event_at":"2026-07-28T03:13:38.708000Z","event_fingerprint":"489bc49c9a2789c4f5bf2be4aa8d7bffb9982362145aa5e5c6413d051eadaea7","payload":{"connection_id":"a6b55582af5f430fb37ad02bf0922475","event_at":"2026-07-28T03:13:38.708000Z","event_type":"price_change","frame_hash":"fe4eae63ec8d99fe7d09858a02f825b8afa28ea5a90f85fe234c1832b634360e","frame_index":0,"kind":"data","monotonic_ns":310401756120208,"payload":{"event_type":"price_change","market":"0x779291bef19b6709f61e9764a954aafe9ffae488d50ae674aabdcb4f248006d5","price_changes":[{"asset_id":"14965588658799411272385430903075831224615961675357217884735713260981483529984","best_ask":"0.81","best_bid":"0.79","hash":"d9986591b2ff6d643c442a13af4adef8c126289f","price":"0.03","side":"BUY","size":"565"},{"asset_id":"8761897749749422724209054078244794145777693856614463256546737399611489089783","best_ask":"0.21","best_bid":"0.19","hash":"72bdb8f2d6af83165f2208b72cb8d1accf62a13a","price":"0.97","side":"SELL","size":"565"}],"timestamp":"1785208418708"},"payload_hash":"41f8c456f3484526c559f062cc52d5a28f93f2833b2bdb1d610149d5cff96788","raw_frame":"{\"market\":\"0x779291bef19b6709f61e9764a954aafe9ffae488d50ae674aabdcb4f248006d5\", \"price_changes\":[{\"asset_id\":\"14965588658799411272385430903075831224615961675357217884735713260981483529984\", \"price\":\"0.03\", \"size\":\"565\", \"side\":\"BUY\", \"hash\":\"d9986591b2ff6d643c442a13af4adef8c126289f\", \"best_bid\":\"0.79\", \"best_ask\":\"0.81\"}, {\"asset_id\":\"8761897749749422724209054078244794145777693856614463256546737399611489089783\", \"price\":\"0.97\", \"size\":\"565\", \"side\":\"SELL\", \"hash\":\"72bdb8f2d6af83165f2208b72cb8d1accf62a13a\", \"best_bid\":\"0.19\", \"best_ask\":\"0.21\"}], \"timestamp\":\"1785208418708\", \"event_type\":\"price_change\"}","received_at":"2026-07-28T03:13:38.720905Z","schema_version":"clob-market-ws.price_change.v1","sequence":null,"server_hash":null,"server_timestamp":"1785208418708","session_id":"3e519d9098404c15b234d96025eb1a2b","source":"clob_market_ws"},"received_at":"2026-07-28T03:13:38.720905Z","record_id":"e2da47de508f2413efe6c81ddd5b763848969e78e2735e34937724aacfb9cbfd","schema_fingerprint":"4aa3821a28b0b7c2400bc59aba4bcc0a76e971dadd19610d3ad38c768e124dc7","schema_version":"edge-lab-recorder.raw.v1","sequence":null,"source":"clob_market_ws"}
{"event_at":"2026-07-28T03:13:38.711000Z","event_fingerprint":"892c9e2597c1ac671802ae1b82691860b6743e00e47da70540ebbecb665c58c4","payload":{"connection_id":"a6b55582af5f430fb37ad02bf0922475","event_at":"2026-07-28T03:13:38.711000Z","event_type":"price_change","frame_hash":"c53ffa34e21a4d72d11a52cb36f132fdb28dbb1232c011e34326e6bbe66d8fff","frame_index":0,"kind":"data","monotonic_ns":310401757708041,"payload":{"event_type":"price_change","market":"0x779291bef19b6709f61e9764a954aafe9ffae488d50ae674aabdcb4f248006d5","price_changes":[{"asset_id":"8761897749749422724209054078244794145777693856614463256546737399611489089783","best_ask":"0.21","best_bid":"0.19","hash":"ea1dfd809c40a8d6daa359c48d6a301d936c1982","price":"0.1","side":"BUY","size":"402.98"},{"asset_id":"14965588658799411272385430903075831224615961675357217884735713260981483529984","best_ask":"0.81","best_bid":"0.79","hash":"4ab70b34a89e518506fe56cb2ecc13ee995c7da9","price":"0.9","side":"SELL","size":"402.98"}],"timestamp":"1785208418711"},"payload_hash":"671be471cb48de1f0bfca726ae7f6864c35dcfb9968147eeeb564e5d340dffec","raw_frame":"{\"market\":\"0x779291bef19b6709f61e9764a954aafe9ffae488d50ae674aabdcb4f248006d5\", \"price_changes\":[{\"asset_id\":\"8761897749749422724209054078244794145777693856614463256546737399611489089783\", \"price\":\"0.1\", \"size\":\"402.98\", \"side\":\"BUY\", \"hash\":\"ea1dfd809c40a8d6daa359c48d6a301d936c1982\", \"best_bid\":\"0.19\", \"best_ask\":\"0.21\"}, {\"asset_id\":\"14965588658799411272385430903075831224615961675357217884735713260981483529984\", \"price\":\"0.9\", \"size\":\"402.98\", \"side\":\"SELL\", \"hash\":\"4ab70b34a89e518506fe56cb2ecc13ee995c7da9\", \"best_bid\":\"0.79\", \"best_ask\":\"0.81\"}], \"timestamp\":\"1785208418711\", \"event_type\":\"price_change\"}","received_at":"2026-07-28T03:13:38.722494Z","schema_version":"clob-market-ws.price_change.v1","sequence":null,"server_hash":null,"server_timestamp":"1785208418711","session_id":"3e519d9098404c15b234d96025eb1a2b","source":"clob_market_ws"},"received_at":"2026-07-28T03:13:38.722494Z","record_id":"8cb7d36266d7b5ffa56bcba2922cc9323b0cf94aed70cf49d3c15b056aa736c2","schema_fingerprint":"4aa3821a28b0b7c2400bc59aba4bcc0a76e971dadd19610d3ad38c768e124dc7","schema_version":"edge-lab-recorder.raw.v1","sequence":null,"source":"clob_market_ws"}
{"event_at":"2026-07-28T03:13:38.711000Z","event_fingerprint":"5c291dadeb4656b48c617a679614f2f93f86c0cba012db65bd43e63c46316fa2","payload":{"connection_id":"a6b55582af5f430fb37ad02bf0922475","event_at":"2026-07-28T03:13:38.711000Z","event_type":"price_change","frame_hash":"df0a1d21e0f442a400e055ac4a6f36bf7e270b77f8e9147be9f93e0998e55bc2","frame_index":0,"kind":"data","monotonic_ns":310401759211041,"payload":{"event_type":"price_change","market":"0x779291bef19b6709f61e9764a954aafe9ffae488d50ae674aabdcb4f248006d5","price_changes":[{"asset_id":"8761897749749422724209054078244794145777693856614463256546737399611489089783","best_ask":"0.21","best_bid":"0.19","hash":"ea1dfd809c40a8d6daa359c48d6a301d936c1982","price":"0.09","side":"BUY","size":"297.87"},{"asset_id":"14965588658799411272385430903075831224615961675357217884735713260981483529984","best_ask":"0.81","best_bid":"0.79","hash":"4ab70b34a89e518506fe56cb2ecc13ee995c7da9","price":"0.91","side":"SELL","size":"297.87"}],"timestamp":"1785208418711"},"payload_hash":"2e615273c01044b43590e8fa5ea125c3eb53f4cba8837e21e0b4b397b0993be7","raw_frame":"{\"market\":\"0x779291bef19b6709f61e9764a954aafe9ffae488d50ae674aabdcb4f248006d5\", \"price_changes\":[{\"asset_id\":\"8761897749749422724209054078244794145777693856614463256546737399611489089783\", \"price\":\"0.09\", \"size\":\"297.87\", \"side\":\"BUY\", \"hash\":\"ea1dfd809c40a8d6daa359c48d6a301d936c1982\", \"best_bid\":\"0.19\", \"best_ask\":\"0.21\"}, {\"asset_id\":\"14965588658799411272385430903075831224615961675357217884735713260981483529984\", \"price\":\"0.91\", \"size\":\"297.87\", \"side\":\"SELL\", \"hash\":\"4ab70b34a89e518506fe56cb2ecc13ee995c7da9\", \"best_bid\":\"0.79\", \"best_ask\":\"0.81\"}], \"timestamp\":\"1785208418711\", \"event_type\":\"price_change\"}","received_at":"2026-07-28T03:13:38.723996Z","schema_version":"clob-market-ws.price_change.v1","sequence":null,"server_hash":null,"server_timestamp":"1785208418711","session_id":"3e519d9098404c15b234d96025eb1a2b","source":"clob_market_ws"},"received_at":"2026-07-28T03:13:38.723996Z","record_id":"c30ea2a5153274ff96411875e0f1782637d1a5551f02662a5d235e29f3f79290","schema_fingerprint":"4aa3821a28b0b7c2400bc59aba4bcc0a76e971dadd19610d3ad38c768e124dc7","schema_version":"edge-lab-recorder.raw.v1","sequence":null,"source":"clob_market_ws"}
{"event_at":"2026-07-28T03:13:38.711000Z","event_fingerprint":"40595ae7d71cd360879e1ddd7f46576a9daf519c69e3fe74200c6cef4749d9fd","payload":{"connection_id":"a6b55582af5f430fb37ad02bf0922475","event_at":"2026-07-28T03:13:38.711000Z","event_type":"price_change","frame_hash":"f3be5325dc38f12a5b94e1088817210296581fcb68e6a01221e1a2cda5faa25c","frame_index":0,"kind":"data","monotonic_ns":310401760707916,"payload":{"event_type":"price_change","market":"0x779291bef19b6709f61e9764a954aafe9ffae488d50ae674aabdcb4f248006d5","price_changes":[{"asset_id":"8761897749749422724209054078244794145777693856614463256546737399611489089783","best_ask":"0.21","best_bid":"0.19","hash":"ea1dfd809c40a8d6daa359c48d6a301d936c1982","price":"0.08","side":"BUY","size":"290"},{"asset_id":"14965588658799411272385430903075831224615961675357217884735713260981483529984","best_ask":"0.81","best_bid":"0.79","hash":"4ab70b34a89e518506fe56cb2ecc13ee995c7da9","price":"0.92","side":"SELL","size":"290"}],"timestamp":"1785208418711"},"payload_hash":"876217b194d2c8dfc7c002e909b4e0e8361ac1e0971c1a01ef5a47c54e0113c7","raw_frame":"{\"market\":\"0x779291bef19b6709f61e9764a954aafe9ffae488d50ae674aabdcb4f248006d5\", \"price_changes\":[{\"asset_id\":\"8761897749749422724209054078244794145777693856614463256546737399611489089783\", \"price\":\"0.08\", \"size\":\"290\", \"side\":\"BUY\", \"hash\":\"ea1dfd809c40a8d6daa359c48d6a301d936c1982\", \"best_bid\":\"0.19\", \"best_ask\":\"0.21\"}, {\"asset_id\":\"14965588658799411272385430903075831224615961675357217884735713260981483529984\", \"price\":\"0.92\", \"size\":\"290\", \"side\":\"SELL\", \"hash\":\"4ab70b34a89e518506fe56cb2ecc13ee995c7da9\", \"best_bid\":\"0.79\", \"best_ask\":\"0.81\"}], \"timestamp\":\"1785208418711\", \"event_type\":\"price_change\"}","received_at":"2026-07-28T03:13:38.725494Z","schema_version":"clob-market-ws.price_change.v1","sequence":null,"server_hash":null,"server_timestamp":"1785208418711","session_id":"3e519d9098404c15b234d96025eb1a2b","source":"clob_market_ws"},"received_at":"2026-07-28T03:13:38.725494Z","record_id":"930bed34b9d58f30cc067b37d7d2940fdab8ce5a95ce36fa588fca441d1eb21b","schema_fingerprint":"4aa3821a28b0b7c2400bc59aba4bcc0a76e971dadd19610d3ad38c768e124dc7","schema_version":"edge-lab-recorder.raw.v1","sequence":null,"source":"clob_market_ws"}
{"event_at":"2026-07-28T03:13:38.711000Z","event_fingerprint":"605cfd8a8d6d9dab89c0cd9866a75c650c266a8bb70af0e8f0535555b0ea4474","payload":{"connection_id":"a6b55582af5f430fb37ad02bf0922475","event_at":"2026-07-28T03:13:38.711000Z","event_type":"price_change","frame_hash":"122264d0ca4f295afa0053d42597ff0a597e1fb9730624bdf0d6c171a51c4c1b","frame_index":0,"kind":"data","monotonic_ns":310401762198208,"payload":{"event_type":"price_change","market":"0x779291bef19b6709f61e9764a954aafe9ffae488d50ae674aabdcb4f248006d5","price_changes":[{"asset_id":"8761897749749422724209054078244794145777693856614463256546737399611489089783","best_ask":"0.21","best_bid":"0.19","hash":"ea1dfd809c40a8d6daa359c48d6a301d936c1982","price":"0.07","side":"BUY","size":"316"},{"asset_id":"14965588658799411272385430903075831224615961675357217884735713260981483529984","best_ask":"0.81","best_bid":"0.79","hash":"4ab70b34a89e518506fe56cb2ecc13ee995c7da9","price":"0.93","side":"SELL","size":"316"}],"timestamp":"1785208418711"},"payload_hash":"3f95375c5628b01b23d3b6660756bfbb36d9e05e52b17c1b40ef088d255394e0","raw_frame":"{\"market\":\"0x779291bef19b6709f61e9764a954aafe9ffae488d50ae674aabdcb4f248006d5\", \"price_changes\":[{\"asset_id\":\"8761897749749422724209054078244794145777693856614463256546737399611489089783\", \"price\":\"0.07\", \"size\":\"316\", \"side\":\"BUY\", \"hash\":\"ea1dfd809c40a8d6daa359c48d6a301d936c1982\", \"best_bid\":\"0.19\", \"best_ask\":\"0.21\"}, {\"asset_id\":\"14965588658799411272385430903075831224615961675357217884735713260981483529984\", \"price\":\"0.93\", \"size\":\"316\", \"side\":\"SELL\", \"hash\":\"4ab70b34a89e518506fe56cb2ecc13ee995c7da9\", \"best_bid\":\"0.79\", \"best_ask\":\"0.81\"}], \"timestamp\":\"1785208418711\", \"event_type\":\"price_change\"}","received_at":"2026-07-28T03:13:38.726984Z","schema_version":"clob-market-ws.price_change.v1","sequence":null,"server_hash":null,"server_timestamp":"1785208418711","session_id":"3e519d9098404c15b234d96025eb1a2b","source":"clob_market_ws"},"received_at":"2026-07-28T03:13:38.726984Z","record_id":"d7161e477f35b46b530d20dcfc49fcfa1861d29e2ee6a4a953591eb7f9010cf4","schema_fingerprint":"4aa3821a28b0b7c2400bc59aba4bcc0a76e971dadd19610d3ad38c768e124dc7","schema_version":"edge-lab-recorder.raw.v1","sequence":null,"source":"clob_market_ws"}
{"event_at":"2026-07-28T03:13:38.713000Z","event_fingerprint":"0179aca560d876eebdb8d3c4f9e74ad18391398a4e2311752dfbc2e62cf01a4b","payload":{"connection_id":"a6b55582af5f430fb37ad02bf0922475","event_at":"2026-07-28T03:13:38.713000Z","event_type":"best_bid_ask","frame_hash":"cff29284114aa9b9539946d75f5c402491a40ed5f7bee619909336035418d4bf","frame_index":0,"kind":"data","monotonic_ns":310401763695666,"payload":{"asset_id":"14965588658799411272385430903075831224615961675357217884735713260981483529984","best_ask":"0.81","best_bid":"0.78","event_type":"best_bid_ask","market":"0x779291bef19b6709f61e9764a954aafe9ffae488d50ae674aabdcb4f248006d5","spread":"0.03","timestamp":"1785208418713"},"payload_hash":"f6b74ae0b72ad0a0b80733205998babe5ca0a50ca2e4b1e389728799358b719a","raw_frame":"{\"market\":\"0x779291bef19b6709f61e9764a954aafe9ffae488d50ae674aabdcb4f248006d5\", \"asset_id\":\"14965588658799411272385430903075831224615961675357217884735713260981483529984\", \"best_bid\":\"0.78\", \"best_ask\":\"0.81\", \"spread\":\"0.03\", \"timestamp\":\"1785208418713\", \"event_type\":\"best_bid_ask\"}","received_at":"2026-07-28T03:13:38.728482Z","schema_version":"clob-market-ws.best_bid_ask.v1","sequence":null,"server_hash":null,"server_timestamp":"1785208418713","session_id":"3e519d9098404c15b234d96025eb1a2b","source":"clob_market_ws"},"received_at":"2026-07-28T03:13:38.728482Z","record_id":"01411d264798d38b1a74245cf1378fd07ce7234aba770c138952b0489817ab06","schema_fingerprint":"8488399f31b0337811b13b266be932db7062827c2470b78bd8e9e99bab51d17d","schema_version":"edge-lab-recorder.raw.v1","sequence":null,"source":"clob_market_ws"}
{"event_at":"2026-07-28T03:13:38.713000Z","event_fingerprint":"fc24a02d43911725ff9467a40b7cee5ab5f727467a44884d3e4a1ab0df7e3a39","payload":{"connection_id":"a6b55582af5f430fb37ad02bf0922475","event_at":"2026-07-28T03:13:38.713000Z","event_type":"best_bid_ask","frame_hash":"a3f43c085125f94f163bb0baeb93c13e9481a635043923a524adc478859baa20","frame_index":0,"kind":"data","monotonic_ns":310401764732458,"payload":{"asset_id":"8761897749749422724209054078244794145777693856614463256546737399611489089783","best_ask":"0.22","best_bid":"0.19","event_type":"best_bid_ask","market":"0x779291bef19b6709f61e9764a954aafe9ffae488d50ae674aabdcb4f248006d5","spread":"0.03","timestamp":"1785208418713"},"payload_hash":"946032a754cc85d360b72bfc57cee21cad5f0d63f08ff50b37337c0d371041ba","raw_frame":"{\"market\":\"0x779291bef19b6709f61e9764a954aafe9ffae488d50ae674aabdcb4f248006d5\", \"asset_id\":\"8761897749749422724209054078244794145777693856614463256546737399611489089783\", \"best_bid\":\"0.19\", \"best_ask\":\"0.22\", \"spread\":\"0.03\", \"timestamp\":\"1785208418713\", \"event_type\":\"best_bid_ask\"}","received_at":"2026-07-28T03:13:38.729519Z","schema_version":"clob-market-ws.best_bid_ask.v1","sequence":null,"server_hash":null,"server_timestamp":"1785208418713","session_id":"3e519d9098404c15b234d96025eb1a2b","source":"clob_market_ws"},"received_at":"2026-07-28T03:13:38.729519Z","record_id":"e10dd08651f7bb36d2fc6cff221cf5f4869c29a22edb4023dfe734c861faaa10","schema_fingerprint":"8488399f31b0337811b13b266be932db7062827c2470b78bd8e9e99bab51d17d","schema_version":"edge-lab-recorder.raw.v1","sequence":null,"source":"clob_market_ws"}
{"event_at":"2026-07-28T03:13:38.713000Z","event_fingerprint":"cb9391e85f514a78ef738bb91ad64b2677b6b5560fff42602e0f37587cb4b5e5","payload":{"connection_id":"a6b55582af5f430fb37ad02bf0922475","event_at":"2026-07-28T03:13:38.713000Z","event_type":"price_change","frame_hash":"58ba36d7e90563f2ed288661aa556b523f681e15f49a0a9196aee0b7149e6228","frame_index":0,"kind":"data","monotonic_ns":310401765763333,"payload":{"event_type":"price_change","market":"0x779291bef19b6709f61e9764a954aafe9ffae488d50ae674aabdcb4f248006d5","price_changes":[{"asset_id":"14965588658799411272385430903075831224615961675357217884735713260981483529984","best_ask":"0.81","best_bid":"0.78","hash":"ae529e2f71705940c6c14331015309d3e99a9180","price":"0.79","side":"BUY","size":"0"},{"asset_id":"8761897749749422724209054078244794145777693856614463256546737399611489089783","best_ask":"0.22","best_bid":"0.19","hash":"702c5276d50040396c8afa79af73072f53c62e90","price":"0.21","side":"SELL","size":"0"}],"timestamp":"1785208418713"},"payload_hash":"4e2b9ebcaaa50098f9251e9f21249c310dc0780b12be8c64315d830828b94af7","raw_frame":"{\"market\":\"0x779291bef19b6709f61e9764a954aafe9ffae488d50ae674aabdcb4f248006d5\", \"price_changes\":[{\"asset_id\":\"14965588658799411272385430903075831224615961675357217884735713260981483529984\", \"price\":\"0.79\", \"size\":\"0\", \"side\":\"BUY\", \"hash\":\"ae529e2f71705940c6c14331015309d3e99a9180\", \"best_bid\":\"0.78\", \"best_ask\":\"0.81\"}, {\"asset_id\":\"8761897749749422724209054078244794145777693856614463256546737399611489089783\", \"price\":\"0.21\", \"size\":\"0\", \"side\":\"SELL\", \"hash\":\"702c5276d50040396c8afa79af73072f53c62e90\", \"best_bid\":\"0.19\", \"best_ask\":\"0.22\"}], \"timestamp\":\"1785208418713\", \"event_type\":\"price_change\"}","received_at":"2026-07-28T03:13:38.730550Z","schema_version":"clob-market-ws.price_change.v1","sequence":null,"server_hash":null,"server_timestamp":"1785208418713","session_id":"3e519d9098404c15b234d96025eb1a2b","source":"clob_market_ws"},"received_at":"2026-07-28T03:13:38.730550Z","record_id":"6768ad702783e0e7103b0fb4106f42e11b177332c13d744c37c26eb5de060971","schema_fingerprint":"4aa3821a28b0b7c2400bc59aba4bcc0a76e971dadd19610d3ad38c768e124dc7","schema_version":"edge-lab-recorder.raw.v1","sequence":null,"source":"clob_market_ws"}
{"event_at":"2026-07-28T03:13:38.713000Z","event_fingerprint":"54d284e4e097fd6694fcfd35ac2ab4bdf91b9a5e6c5b10b3e617e53f00eb931c","payload":{"connection_id":"a6b55582af5f430fb37ad02bf0922475","event_at":"2026-07-28T03:13:38.713000Z","event_type":"price_change","frame_hash":"b01808652017bb613bd4416f68f89fcb133f62d6c388f0c25f909c615807fee1","frame_index":0,"kind":"data","monotonic_ns":310401767238791,"payload":{"event_type":"price_change","market":"0x779291bef19b6709f61e9764a954aafe9ffae488d50ae674aabdcb4f248006d5","price_changes":[{"asset_id":"8761897749749422724209054078244794145777693856614463256546737399611489089783","best_ask":"0.22","best_bid":"0.19","hash":"f3ee08bca269f23771445191c33a56b6cabbcf9a","price":"0.11","side":"BUY","size":"105.04"},{"asset_id":"14965588658799411272385430903075831224615961675357217884735713260981483529984","best_ask":"0.81","best_bid":"0.78","hash":"e78a34f7105bb6f17f892a483ac80ffb650e43ef","price":"0.89","side":"SELL","size":"105.04"}],"timestamp":"1785208418713"},"payload_hash":"a25493ef9af3bc5d2a4157d1087e0a22d1d8dff2f41e6e200ffa2ebc9c9ce0ab","raw_frame":"{\"market\":\"0x779291bef19b6709f61e9764a954aafe9ffae488d50ae674aabdcb4f248006d5\", \"price_changes\":[{\"asset_id\":\"8761897749749422724209054078244794145777693856614463256546737399611489089783\", \"price\":\"0.11\", \"size\":\"105.04\", \"side\":\"BUY\", \"hash\":\"f3ee08bca269f23771445191c33a56b6cabbcf9a\", \"best_bid\":\"0.19\", \"best_ask\":\"0.22\"}, {\"asset_id\":\"14965588658799411272385430903075831224615961675357217884735713260981483529984\", \"price\":\"0.89\", \"size\":\"105.04\", \"side\":\"SELL\", \"hash\":\"e78a34f7105bb6f17f892a483ac80ffb650e43ef\", \"best_bid\":\"0.78\", \"best_ask\":\"0.81\"}], \"timestamp\":\"1785208418713\", \"event_type\":\"price_change\"}","received_at":"2026-07-28T03:13:38.732025Z","schema_version":"clob-market-ws.price_change.v1","sequence":null,"server_hash":null,"server_timestamp":"1785208418713","session_id":"3e519d9098404c15b234d96025eb1a2b","source":"clob_market_ws"},"received_at":"2026-07-28T03:13:38.732025Z","record_id":"a2445afef49c6bba2212718cf7c07c2edf106e3d3798a0cd7ce62e5da7adc1e3","schema_fingerprint":"4aa3821a28b0b7c2400bc59aba4bcc0a76e971dadd19610d3ad38c768e124dc7","schema_version":"edge-lab-recorder.raw.v1","sequence":null,"source":"clob_market_ws"}
{"event_at":"2026-07-28T03:13:38.717000Z","event_fingerprint":"9cd8c4251d188a1335c027a7130c0fc3ca65861d7550ea509d091a2869beb3d0","payload":{"connection_id":"a6b55582af5f430fb37ad02bf0922475","event_at":"2026-07-28T03:13:38.717000Z","event_type":"best_bid_ask","frame_hash":"728b1b4144331c2fc116c0fd757346c2cfac70e594356600dd473aebf4eeaf34","frame_index":0,"kind":"data","monotonic_ns":310401768708458,"payload":{"asset_id":"14965588658799411272385430903075831224615961675357217884735713260981483529984","best_ask":"0.8","best_bid":"0.78","event_type":"best_bid_ask","market":"0x779291bef19b6709f61e9764a954aafe9ffae488d50ae674aabdcb4f248006d5","spread":"0.02","timestamp":"1785208418717"},"payload_hash":"57c24eed77feba328ca4717a1f492cbb829e74912d848d7dcd837fbcec5a1aff","raw_frame":"{\"market\":\"0x779291bef19b6709f61e9764a954aafe9ffae488d50ae674aabdcb4f248006d5\", \"asset_id\":\"14965588658799411272385430903075831224615961675357217884735713260981483529984\", \"best_bid\":\"0.78\", \"best_ask\":\"0.8\", \"spread\":\"0.02\", \"timestamp\":\"1785208418717\", \"event_type\":\"best_bid_ask\"}","received_at":"2026-07-28T03:13:38.733495Z","schema_version":"clob-market-ws.best_bid_ask.v1","sequence":null,"server_hash":null,"server_timestamp":"1785208418717","session_id":"3e519d9098404c15b234d96025eb1a2b","source":"clob_market_ws"},"received_at":"2026-07-28T03:13:38.733495Z","record_id":"7efcdb5b3b1788b2746dd543a729c05b08a73428c27ccda7c89894e2c6661c8e","schema_fingerprint":"8488399f31b0337811b13b266be932db7062827c2470b78bd8e9e99bab51d17d","schema_version":"edge-lab-recorder.raw.v1","sequence":null,"source":"clob_market_ws"}
{"event_at":"2026-07-28T03:13:38.717000Z","event_fingerprint":"bdec05ab5b185dbcb403d8a44d24a760bbc4b409c35263c0470269c2f99f82e7","payload":{"connection_id":"a6b55582af5f430fb37ad02bf0922475","event_at":"2026-07-28T03:13:38.717000Z","event_type":"best_bid_ask","frame_hash":"99857929bc9c4e9946e9fd8d301b8d12e2fefca71ccc69c7972bf6da9f6b22d7","frame_index":0,"kind":"data","monotonic_ns":310401769741041,"payload":{"asset_id":"8761897749749422724209054078244794145777693856614463256546737399611489089783","best_ask":"0.22","best_bid":"0.2","event_type":"best_bid_ask","market":"0x779291bef19b6709f61e9764a954aafe9ffae488d50ae674aabdcb4f248006d5","spread":"0.02","timestamp":"1785208418717"},"payload_hash":"3259911031f7c1825709f606941e23852cf62b96b41689ef742cde35d00ce95e","raw_frame":"{\"market\":\"0x779291bef19b6709f61e9764a954aafe9ffae488d50ae674aabdcb4f248006d5\", \"asset_id\":\"8761897749749422724209054078244794145777693856614463256546737399611489089783\", \"best_bid\":\"0.2\", \"best_ask\":\"0.22\", \"spread\":\"0.02\", \"timestamp\":\"1785208418717\", \"event_type\":\"best_bid_ask\"}","received_at":"2026-07-28T03:13:38.734528Z","schema_version":"clob-market-ws.best_bid_ask.v1","sequence":null,"server_hash":null,"server_timestamp":"1785208418717","session_id":"3e519d9098404c15b234d96025eb1a2b","source":"clob_market_ws"},"received_at":"2026-07-28T03:13:38.734528Z","record_id":"d264a7993f2c0bfb191c6f0c0c7067b4623a8f5b9e9dcf50646401eb246ee796","schema_fingerprint":"8488399f31b0337811b13b266be932db7062827c2470b78bd8e9e99bab51d17d","schema_version":"edge-lab-recorder.raw.v1","sequence":null,"source":"clob_market_ws"}
