{"event_at":"2026-07-28T03:07:13.416000Z","event_fingerprint":"94a6a5e5d8d4a64e1c80e7872335a95f02d966d365f9648976eb415d02263fcb","payload":{"connection_id":"a6b55582af5f430fb37ad02bf0922475","event_at":"2026-07-28T03:07:13.416000Z","event_type":"best_bid_ask","frame_hash":"d84f0ad6dca11b714c611de2d6af8ba3d72d1c0316036c920b8e484304fa7ad4","frame_index":0,"kind":"data","monotonic_ns":310020403422750,"payload":{"asset_id":"8761897749749422724209054078244794145777693856614463256546737399611489089783","best_ask":"0.65","best_bid":"0.64","event_type":"best_bid_ask","market":"0x779291bef19b6709f61e9764a954aafe9ffae488d50ae674aabdcb4f248006d5","spread":"0.01","timestamp":"1785208033416"},"payload_hash":"7d98490a45555658baf66dfc6357b4402aa25ca72e520bbf99260e0fbf4675d4","raw_frame":"{\"market\":\"0x779291bef19b6709f61e9764a954aafe9ffae488d50ae674aabdcb4f248006d5\", \"asset_id\":\"8761897749749422724209054078244794145777693856614463256546737399611489089783\", \"best_bid\":\"0.64\", \"best_ask\":\"0.65\", \"spread\":\"0.01\", \"timestamp\":\"1785208033416\", \"event_type\":\"best_bid_ask\"}","received_at":"2026-07-28T03:07:17.371524Z","schema_version":"clob-market-ws.best_bid_ask.v1","sequence":null,"server_hash":null,"server_timestamp":"1785208033416","session_id":"3e519d9098404c15b234d96025eb1a2b","source":"clob_market_ws"},"received_at":"2026-07-28T03:07:17.371524Z","record_id":"2d01cbe105da679da4f43678967f28c8917303e57c1541a08b8e2d0ea56b632e","schema_fingerprint":"8488399f31b0337811b13b266be932db7062827c2470b78bd8e9e99bab51d17d","schema_version":"edge-lab-recorder.raw.v1","sequence":null,"source":"clob_market_ws"}
{"event_at":"2026-07-28T03:07:13.416000Z","event_fingerprint":"e16ed79bae2ee2aaeb241743fe5adc69c27469f34b320e7b3f26c2908de51464","payload":{"connection_id":"a6b55582af5f430fb37ad02bf0922475","event_at":"2026-07-28T03:07:13.416000Z","event_type":"price_change","frame_hash":"bfc21ea28cc0a4047500ee6eb40174cf6d267ac34425df6b70575347893c298f","frame_index":0,"kind":"data","monotonic_ns":310020409678916,"payload":{"event_type":"price_change","market":"0x779291bef19b6709f61e9764a954aafe9ffae488d50ae674aabdcb4f248006d5","price_changes":[{"asset_id":"8761897749749422724209054078244794145777693856614463256546737399611489089783","best_ask":"0.65","best_bid":"0.64","hash":"e1ba73b00fe5d3c928f2a026b44322c4e5f70009","price":"0.64","side":"BUY","size":"20.98"},{"asset_id":"14965588658799411272385430903075831224615961675357217884735713260981483529984","best_ask":"0.36","best_bid":"0.35","hash":"6b3f1643d7c22db62c79a56b0ee7aec80e7523af","price":"0.36","side":"SELL","size":"20.98"}],"timestamp":"1785208033416"},"payload_hash":"69fba2d8f4ab1917e690683014ec8ab083d3f827d953a91ccc48afd3c0ebcc9a","raw_frame":"{\"market\":\"0x779291bef19b6709f61e9764a954aafe9ffae488d50ae674aabdcb4f248006d5\", \"price_changes\":[{\"asset_id\":\"8761897749749422724209054078244794145777693856614463256546737399611489089783\", \"price\":\"0.64\", \"size\":\"20.98\", \"side\":\"BUY\", \"hash\":\"e1ba73b00fe5d3c928f2a026b44322c4e5f70009\", \"best_bid\":\"0.64\", \"best_ask\":\"0.65\"}, {\"asset_id\":\"14965588658799411272385430903075831224615961675357217884735713260981483529984\", \"price\":\"0.36\", \"size\":\"20.98\", \"side\":\"SELL\", \"hash\":\"6b3f1643d7c22db62c79a56b0ee7aec80e7523af\", \"best_bid\":\"0.35\", \"best_ask\":\"0.36\"}], \"timestamp\":\"1785208033416\", \"event_type\":\"price_change\"}","received_at":"2026-07-28T03:07:17.377781Z","schema_version":"clob-market-ws.price_change.v1","sequence":null,"server_hash":null,"server_timestamp":"1785208033416","session_id":"3e519d9098404c15b234d96025eb1a2b","source":"clob_market_ws"},"received_at":"2026-07-28T03:07:17.377781Z","record_id":"059c28edf0e0adc2bda6870291b2f4ab934d312176b74557600e180a69609deb","schema_fingerprint":"4aa3821a28b0b7c2400bc59aba4bcc0a76e971dadd19610d3ad38c768e124dc7","schema_version":"edge-lab-recorder.raw.v1","sequence":null,"source":"clob_market_ws"}
{"event_at":"2026-07-28T03:07:13.416000Z","event_fingerprint":"433d742e9ed4ba292db23fa9f4ddfe3de7637f79f03f62937f6dac663138ea60","payload":{"connection_id":"a6b55582af5f430fb37ad02bf0922475","event_at":"2026-07-28T03:07:13.416000Z","event_type":"book","frame_hash":"067c8a03697c3ae00f26eefb4fe04589ebe692bac648b2f12379ed77c88115e2","frame_index":0,"kind":"data","monotonic_ns":310020412781291,"payload":{"asks":[{"price":"0.99","size":"5608.02"},{"price":"0.98","size":"688.1"},{"price":"0.97","size":"648.1"},{"price":"0.96","size":"588.09"},{"price":"0.95","size":"653.2"},{"price":"0.94","size":"583.2"},{"price":"0.93","size":"546.1"},{"price":"0.92","size":"550.79"},{"price":"0.91","size":"566.6"},{"price":"0.9","size":"130.2"},{"price":"0.89","size":"30.6"},{"price":"0.88","size":"68.4"},{"price":"0.87","size":"26.5"},{"price":"0.86","size":"44.9"},{"price":"0.85","size":"204.5"},{"price":"0.84","size":"62.3"},{"price":"0.83","size":"51.3"},{"price":"0.82","size":"85.86"},{"price":"0.81","size":"49.5"},{"price":"0.8","size":"81.8"},{"price":"0.79","size":"78.1"},{"price":"0.78","size":"47.5"},{"price":"0.77","size":"46.89"},{"price":"0.76","size":"76.39"},{"price":"0.75","size":"75"},{"price":"0.74","size":"45.6"},{"price":"0.73","size":"81.2"},{"price":"0.72","size":"50.9"},{"price":"0.71","size":"50.6"},{"price":"0.7","size":"107.3"},{"price":"0.69","size":"50"},{"price":"0.68","size":"49.8"},{"price":"0.67","size":"79.6"},{"price":"0.66","size":"49.4"},{"price":"0.65","size":"58.2"},{"price":"0.64","size":"78"},{"price":"0.63","size":"47.9"},{"price":"0.62","size":"47.7"},{"price":"0.61","size":"77.6"},{"price":"0.6","size":"51.5"},{"price":"0.59","size":"47.4"},{"price":"0.58","size":"77.3"},{"price":"0.57","size":"47.2"},{"price":"0.56","size":"47.2"},{"price":"0.55","size":"85.1"},{"price":"0.54","size":"47.1"},{"price":"0.53","size":"47"},{"price":"0.52","size":"77"},{"price":"0.51","size":"47"},{"price":"0.5","size":"40.2"},{"price":"0.49","size":"65"},{"price":"0.48","size":"35"},{"price":"0.47","size":"35"},{"price":"0.46","size":"102"},{"price":"0.45","size":"71"},{"price":"0.44","size":"171"},{"price":"0.43","size":"205"},{"price":"0.42","size":"175"},{"price":"0.41","size":"176.5"},{"price":"0.4","size":"178"},{"price":"0.39","size":"53"},{"price":"0.38","size":"42"},{"price":"0.37","size":"49"},{"price":"0.36","size":"20.98"}],"asset_id":"14965588658799411272385430903075831224615961675357217884735713260981483529984","bids":[{"price":"0.01","size":"5758.02"},{"price":"0.02","size":"708.1"},{"price":"0.03","size":"668.1"},{"price":"0.04","size":"648.09"},{"price":"0.05","size":"689.2"},{"price":"0.06","size":"605.2"},{"price":"0.07","size":"911.1"},{"price":"0.08","size":"347.79"},{"price":"0.09","size":"303.6"},{"price":"0.1","size":"476.29"},{"price":"0.11","size":"376.6"},{"price":"0.12","size":"364.4"},{"price":"0.13","size":"366.5"},{"price":"0.14","size":"322.9"},{"price":"0.15","size":"331.5"},{"price":"0.16","size":"346.3"},{"price":"0.17","size":"297.3"},{"price":"0.18","size":"288.8"},{"price":"0.19","size":"305.76"},{"price":"0.2","size":"290.8"},{"price":"0.21","size":"265.1"},{"price":"0.22","size":"301.07"},{"price":"0.23","size":"138"},{"price":"0.24","size":"125"},{"price":"0.25","size":"160"},{"price":"0.26","size":"125"},{"price":"0.27","size":"64"},{"price":"0.28","size":"85.6"},{"price":"0.29","size":"62.6"},{"price":"0.3","size":"78.6"},{"price":"0.31","size":"60.6"},{"price":"0.32","size":"49.6"},{"price":"0.33","size":"52.6"},{"price":"0.34","size":"31.6"},{"price":"0.35","size":"41.6"}],"event_type":"book","hash":"6b3f1643d7c22db62c79a56b0ee7aec80e7523af","market":"0x779291bef19b6709f61e9764a954aafe9ffae488d50ae674aabdcb4f248006d5","timestamp":"1785208033416"},"payload_hash":"b30d45d0b9399906b679cc4767f620dbf073bee549ecb9b1d8be5d21a3639835","raw_frame":"{\"market\":\"0x779291bef19b6709f61e9764a954aafe9ffae488d50ae674aabdcb4f248006d5\", \"asset_id\":\"14965588658799411272385430903075831224615961675357217884735713260981483529984\", \"bids\":[{\"price\":\"0.01\", \"size\":\"5758.02\"}, {\"price\":\"0.02\", \"size\":\"708.1\"}, {\"price\":\"0.03\", \"size\":\"668.1\"}, {\"price\":\"0.04\", \"size\":\"648.09\"}, {\"price\":\"0.05\", \"size\":\"689.2\"}, {\"price\":\"0.06\", \"size\":\"605.2\"}, {\"price\":\"0.07\", \"size\":\"911.1\"}, {\"price\":\"0.08\", \"size\":\"347.79\"}, {\"price\":\"0.09\", \"size\":\"303.6\"}, {\"price\":\"0.1\", \"size\":\"476.29\"}, {\"price\":\"0.11\", \"size\":\"376.6\"}, {\"price\":\"0.12\", \"size\":\"364.4\"}, {\"price\":\"0.13\", \"size\":\"366.5\"}, {\"price\":\"0.14\", \"size\":\"322.9\"}, {\"price\":\"0.15\", \"size\":\"331.5\"}, {\"price\":\"0.16\", \"size\":\"346.3\"}, {\"price\":\"0.17\", \"size\":\"297.3\"}, {\"price\":\"0.18\", \"size\":\"288.8\"}, {\"price\":\"0.19\", \"size\":\"305.76\"}, {\"price\":\"0.2\", \"size\":\"290.8\"}, {\"price\":\"0.21\", \"size\":\"265.1\"}, {\"price\":\"0.22\", \"size\":\"301.07\"}, {\"price\":\"0.23\", \"size\":\"138\"}, {\"price\":\"0.24\", \"size\":\"125\"}, {\"price\":\"0.25\", \"size\":\"160\"}, {\"price\":\"0.26\", \"size\":\"125\"}, {\"price\":\"0.27\", \"size\":\"64\"}, {\"price\":\"0.28\", \"size\":\"85.6\"}, {\"price\":\"0.29\", \"size\":\"62.6\"}, {\"price\":\"0.3\", \"size\":\"78.6\"}, {\"price\":\"0.31\", \"size\":\"60.6\"}, {\"price\":\"0.32\", \"size\":\"49.6\"}, {\"price\":\"0.33\", \"size\":\"52.6\"}, {\"price\":\"0.34\", \"size\":\"31.6\"}, {\"price\":\"0.35\", \"size\":\"41.6\"}], \"asks\":[{\"price\":\"0.99\", \"size\":\"5608.02\"}, {\"price\":\"0.98\", \"size\":\"688.1\"}, {\"price\":\"0.97\", \"size\":\"648.1\"}, {\"price\":\"0.96\", \"size\":\"588.09\"}, {\"price\":\"0.95\", \"size\":\"653.2\"}, {\"price\":\"0.94\", \"size\":\"583.2\"}, {\"price\":\"0.93\", \"size\":\"546.1\"}, {\"price\":\"0.92\", \"size\":\"550.79\"}, {\"price\":\"0.91\", \"size\":\"566.6\"}, {\"price\":\"0.9\", \"size\":\"130.2\"}, {\"price\":\"0.89\", \"size\":\"30.6\"}, {\"price\":\"0.88\", \"size\":\"68.4\"}, {\"price\":\"0.87\", \"size\":\"26.5\"}, {\"price\":\"0.86\", \"size\":\"44.9\"}, {\"price\":\"0.85\", \"size\":\"204.5\"}, {\"price\":\"0.84\", \"size\":\"62.3\"}, {\"price\":\"0.83\", \"size\":\"51.3\"}, {\"price\":\"0.82\", \"size\":\"85.86\"}, {\"price\":\"0.81\", \"size\":\"49.5\"}, {\"price\":\"0.8\", \"size\":\"81.8\"}, {\"price\":\"0.79\", \"size\":\"78.1\"}, {\"price\":\"0.78\", \"size\":\"47.5\"}, {\"price\":\"0.77\", \"size\":\"46.89\"}, {\"price\":\"0.76\", \"size\":\"76.39\"}, {\"price\":\"0.75\", \"size\":\"75\"}, {\"price\":\"0.74\", \"size\":\"45.6\"}, {\"price\":\"0.73\", \"size\":\"81.2\"}, {\"price\":\"0.72\", \"size\":\"50.9\"}, {\"price\":\"0.71\", \"size\":\"50.6\"}, {\"price\":\"0.7\", \"size\":\"107.3\"}, {\"price\":\"0.69\", \"size\":\"50\"}, {\"price\":\"0.68\", \"size\":\"49.8\"}, {\"price\":\"0.67\", \"size\":\"79.6\"}, {\"price\":\"0.66\", \"size\":\"49.4\"}, {\"price\":\"0.65\", \"size\":\"58.2\"}, {\"price\":\"0.64\", \"size\":\"78\"}, {\"price\":\"0.63\", \"size\":\"47.9\"}, {\"price\":\"0.62\", \"size\":\"47.7\"}, {\"price\":\"0.61\", \"size\":\"77.6\"}, {\"price\":\"0.6\", \"size\":\"51.5\"}, {\"price\":\"0.59\", \"size\":\"47.4\"}, {\"price\":\"0.58\", \"size\":\"77.3\"}, {\"price\":\"0.57\", \"size\":\"47.2\"}, {\"price\":\"0.56\", \"size\":\"47.2\"}, {\"price\":\"0.55\", \"size\":\"85.1\"}, {\"price\":\"0.54\", \"size\":\"47.1\"}, {\"price\":\"0.53\", \"size\":\"47\"}, {\"price\":\"0.52\", \"size\":\"77\"}, {\"price\":\"0.51\", \"size\":\"47\"}, {\"price\":\"0.5\", \"size\":\"40.2\"}, {\"price\":\"0.49\", \"size\":\"65\"}, {\"price\":\"0.48\", \"size\":\"35\"}, {\"price\":\"0.47\", \"size\":\"35\"}, {\"price\":\"0.46\", \"size\":\"102\"}, {\"price\":\"0.45\", \"size\":\"71\"}, {\"price\":\"0.44\", \"size\":\"171\"}, {\"price\":\"0.43\", \"size\":\"205\"}, {\"price\":\"0.42\", \"size\":\"175\"}, {\"price\":\"0.41\", \"size\":\"176.5\"}, {\"price\":\"0.4\", \"size\":\"178\"}, {\"price\":\"0.39\", \"size\":\"53\"}, {\"price\":\"0.38\", \"size\":\"42\"}, {\"price\":\"0.37\", \"size\":\"49\"}, {\"price\":\"0.36\", \"size\":\"20.98\"}], \"hash\":\"6b3f1643d7c22db62c79a56b0ee7aec80e7523af\", \"timestamp\":\"1785208033416\", \"event_type\":\"book\"}","received_at":"2026-07-28T03:07:17.380883Z","schema_version":"clob-market-ws.book.v1","sequence":null,"server_hash":"6b3f1643d7c22db62c79a56b0ee7aec80e7523af","server_timestamp":"1785208033416","session_id":"3e519d9098404c15b234d96025eb1a2b","source":"clob_market_ws"},"received_at":"2026-07-28T03:07:17.380883Z","record_id":"1e5b530d8038d9fbb17e8a8144a43c449af12ad6a37a7c9fbfc5569312d4e63e","schema_fingerprint":"dc2caa1c89c6a7426e2e07ff925910cd4d0a8a223a515d4092d91d6d127aacb6","schema_version":"edge-lab-recorder.raw.v1","sequence":null,"source":"clob_market_ws"}
{"event_at":"2026-07-28T03:07:13.416000Z","event_fingerprint":"d668b495520bdc6413b18c9ccb690d9004643c30f8cdc89cea905308e2001a69","payload":{"connection_id":"a6b55582af5f430fb37ad02bf0922475","event_at":"2026-07-28T03:07:13.416000Z","event_type":"book","frame_hash":"e40956ae5d33235c85b9fd509aa93dd442a8c6bb56b2dd5f328dcf18b74d69c0","frame_index":0,"kind":"data","monotonic_ns":310020424682958,"payload":{"asks":[{"price":"0.99","size":"5758.02"},{"price":"0.98","size":"708.1"},{"price":"0.97","size":"668.1"},{"price":"0.96","size":"648.09"},{"price":"0.95","size":"689.2"},{"price":"0.94","size":"605.2"},{"price":"0.93","size":"911.1"},{"price":"0.92","size":"347.79"},{"price":"0.91","size":"303.6"},{"price":"0.9","size":"476.29"},{"price":"0.89","size":"376.6"},{"price":"0.88","size":"364.4"},{"price":"0.87","size":"366.5"},{"price":"0.86","size":"322.9"},{"price":"0.85","size":"331.5"},{"price":"0.84","size":"346.3"},{"price":"0.83","size":"297.3"},{"price":"0.82","size":"288.8"},{"price":"0.81","size":"305.76"},{"price":"0.8","size":"290.8"},{"price":"0.79","size":"265.1"},{"price":"0.78","size":"301.07"},{"price":"0.77","size":"138"},{"price":"0.76","size":"125"},{"price":"0.75","size":"160"},{"price":"0.74","size":"125"},{"price":"0.73","size":"64"},{"price":"0.72","size":"85.6"},{"price":"0.71","size":"62.6"},{"price":"0.7","size":"78.6"},{"price":"0.69","size":"60.6"},{"price":"0.68","size":"49.6"},{"price":"0.67","size":"52.6"},{"price":"0.66","size":"31.6"},{"price":"0.65","size":"41.6"}],"asset_id":"8761897749749422724209054078244794145777693856614463256546737399611489089783","bids":[{"price":"0.01","size":"5608.02"},{"price":"0.02","size":"688.1"},{"price":"0.03","size":"648.1"},{"price":"0.04","size":"588.09"},{"price":"0.05","size":"653.2"},{"price":"0.06","size":"583.2"},{"price":"0.07","size":"546.1"},{"price":"0.08","size":"550.79"},{"price":"0.09","size":"566.6"},{"price":"0.1","size":"130.2"},{"price":"0.11","size":"30.6"},{"price":"0.12","size":"68.4"},{"price":"0.13","size":"26.5"},{"price":"0.14","size":"44.9"},{"price":"0.15","size":"204.5"},{"price":"0.16","size":"62.3"},{"price":"0.17","size":"51.3"},{"price":"0.18","size":"85.86"},{"price":"0.19","size":"49.5"},{"price":"0.2","size":"81.8"},{"price":"0.21","size":"78.1"},{"price":"0.22","size":"47.5"},{"price":"0.23","size":"46.89"},{"price":"0.24","size":"76.39"},{"price":"0.25","size":"75"},{"price":"0.26","size":"45.6"},{"price":"0.27","size":"81.2"},{"price":"0.28","size":"50.9"},{"price":"0.29","size":"50.6"},{"price":"0.3","size":"107.3"},{"price":"0.31","size":"50"},{"price":"0.32","size":"49.8"},{"price":"0.33","size":"79.6"},{"price":"0.34","size":"49.4"},{"price":"0.35","size":"58.2"},{"price":"0.36","size":"78"},{"price":"0.37","size":"47.9"},{"price":"0.38","size":"47.7"},{"price":"0.39","size":"77.6"},{"price":"0.4","size":"51.5"},{"price":"0.41","size":"47.4"},{"price":"0.42","size":"77.3"},{"price":"0.43","size":"47.2"},{"price":"0.44","size":"47.2"},{"price":"0.45","size":"85.1"},{"price":"0.46","size":"47.1"},{"price":"0.47","size":"47"},{"price":"0.48","size":"77"},{"price":"0.49","size":"47"},{"price":"0.5","size":"40.2"},{"price":"0.51","size":"65"},{"price":"0.52","size":"35"},{"price":"0.53","size":"35"},{"price":"0.54","size":"102"},{"price":"0.55","size":"71"},{"price":"0.56","size":"171"},{"price":"0.57","size":"205"},{"price":"0.58","size":"175"},{"price":"0.59","size":"176.5"},{"price":"0.6","size":"178"},{"price":"0.61","size":"53"},{"price":"0.62","size":"42"},{"price":"0.63","size":"49"},{"price":"0.64","size":"20.98"}],"event_type":"book","hash":"e1ba73b00fe5d3c928f2a026b44322c4e5f70009","market":"0x779291bef19b6709f61e9764a954aafe9ffae488d50ae674aabdcb4f248006d5","timestamp":"1785208033416"},"payload_hash":"233e8a83f8f8b15aaad134876768582b76885e22207007895eac89f577ef6aa1","raw_frame":"{\"market\":\"0x779291bef19b6709f61e9764a954aafe9ffae488d50ae674aabdcb4f248006d5\", \"asset_id\":\"8761897749749422724209054078244794145777693856614463256546737399611489089783\", \"bids\":[{\"price\":\"0.01\", \"size\":\"5608.02\"}, {\"price\":\"0.02\", \"size\":\"688.1\"}, {\"price\":\"0.03\", \"size\":\"648.1\"}, {\"price\":\"0.04\", \"size\":\"588.09\"}, {\"price\":\"0.05\", \"size\":\"653.2\"}, {\"price\":\"0.06\", \"size\":\"583.2\"}, {\"price\":\"0.07\", \"size\":\"546.1\"}, {\"price\":\"0.08\", \"size\":\"550.79\"}, {\"price\":\"0.09\", \"size\":\"566.6\"}, {\"price\":\"0.1\", \"size\":\"130.2\"}, {\"price\":\"0.11\", \"size\":\"30.6\"}, {\"price\":\"0.12\", \"size\":\"68.4\"}, {\"price\":\"0.13\", \"size\":\"26.5\"}, {\"price\":\"0.14\", \"size\":\"44.9\"}, {\"price\":\"0.15\", \"size\":\"204.5\"}, {\"price\":\"0.16\", \"size\":\"62.3\"}, {\"price\":\"0.17\", \"size\":\"51.3\"}, {\"price\":\"0.18\", \"size\":\"85.86\"}, {\"price\":\"0.19\", \"size\":\"49.5\"}, {\"price\":\"0.2\", \"size\":\"81.8\"}, {\"price\":\"0.21\", \"size\":\"78.1\"}, {\"price\":\"0.22\", \"size\":\"47.5\"}, {\"price\":\"0.23\", \"size\":\"46.89\"}, {\"price\":\"0.24\", \"size\":\"76.39\"}, {\"price\":\"0.25\", \"size\":\"75\"}, {\"price\":\"0.26\", \"size\":\"45.6\"}, {\"price\":\"0.27\", \"size\":\"81.2\"}, {\"price\":\"0.28\", \"size\":\"50.9\"}, {\"price\":\"0.29\", \"size\":\"50.6\"}, {\"price\":\"0.3\", \"size\":\"107.3\"}, {\"price\":\"0.31\", \"size\":\"50\"}, {\"price\":\"0.32\", \"size\":\"49.8\"}, {\"price\":\"0.33\", \"size\":\"79.6\"}, {\"price\":\"0.34\", \"size\":\"49.4\"}, {\"price\":\"0.35\", \"size\":\"58.2\"}, {\"price\":\"0.36\", \"size\":\"78\"}, {\"price\":\"0.37\", \"size\":\"47.9\"}, {\"price\":\"0.38\", \"size\":\"47.7\"}, {\"price\":\"0.39\", \"size\":\"77.6\"}, {\"price\":\"0.4\", \"size\":\"51.5\"}, {\"price\":\"0.41\", \"size\":\"47.4\"}, {\"price\":\"0.42\", \"size\":\"77.3\"}, {\"price\":\"0.43\", \"size\":\"47.2\"}, {\"price\":\"0.44\", \"size\":\"47.2\"}, {\"price\":\"0.45\", \"size\":\"85.1\"}, {\"price\":\"0.46\", \"size\":\"47.1\"}, {\"price\":\"0.47\", \"size\":\"47\"}, {\"price\":\"0.48\", \"size\":\"77\"}, {\"price\":\"0.49\", \"size\":\"47\"}, {\"price\":\"0.5\", \"size\":\"40.2\"}, {\"price\":\"0.51\", \"size\":\"65\"}, {\"price\":\"0.52\", \"size\":\"35\"}, {\"price\":\"0.53\", \"size\":\"35\"}, {\"price\":\"0.54\", \"size\":\"102\"}, {\"price\":\"0.55\", \"size\":\"71\"}, {\"price\":\"0.56\", \"size\":\"171\"}, {\"price\":\"0.57\", \"size\":\"205\"}, {\"price\":\"0.58\", \"size\":\"175\"}, {\"price\":\"0.59\", \"size\":\"176.5\"}, {\"price\":\"0.6\", \"size\":\"178\"}, {\"price\":\"0.61\", \"size\":\"53\"}, {\"price\":\"0.62\", \"size\":\"42\"}, {\"price\":\"0.63\", \"size\":\"49\"}, {\"price\":\"0.64\", \"size\":\"20.98\"}], \"asks\":[{\"price\":\"0.99\", \"size\":\"5758.02\"}, {\"price\":\"0.98\", \"size\":\"708.1\"}, {\"price\":\"0.97\", \"size\":\"668.1\"}, {\"price\":\"0.96\", \"size\":\"648.09\"}, {\"price\":\"0.95\", \"size\":\"689.2\"}, {\"price\":\"0.94\", \"size\":\"605.2\"}, {\"price\":\"0.93\", \"size\":\"911.1\"}, {\"price\":\"0.92\", \"size\":\"347.79\"}, {\"price\":\"0.91\", \"size\":\"303.6\"}, {\"price\":\"0.9\", \"size\":\"476.29\"}, {\"price\":\"0.89\", \"size\":\"376.6\"}, {\"price\":\"0.88\", \"size\":\"364.4\"}, {\"price\":\"0.87\", \"size\":\"366.5\"}, {\"price\":\"0.86\", \"size\":\"322.9\"}, {\"price\":\"0.85\", \"size\":\"331.5\"}, {\"price\":\"0.84\", \"size\":\"346.3\"}, {\"price\":\"0.83\", \"size\":\"297.3\"}, {\"price\":\"0.82\", \"size\":\"288.8\"}, {\"price\":\"0.81\", \"size\":\"305.76\"}, {\"price\":\"0.8\", \"size\":\"290.8\"}, {\"price\":\"0.79\", \"size\":\"265.1\"}, {\"price\":\"0.78\", \"size\":\"301.07\"}, {\"price\":\"0.77\", \"size\":\"138\"}, {\"price\":\"0.76\", \"size\":\"125\"}, {\"price\":\"0.75\", \"size\":\"160\"}, {\"price\":\"0.74\", \"size\":\"125\"}, {\"price\":\"0.73\", \"size\":\"64\"}, {\"price\":\"0.72\", \"size\":\"85.6\"}, {\"price\":\"0.71\", \"size\":\"62.6\"}, {\"price\":\"0.7\", \"size\":\"78.6\"}, {\"price\":\"0.69\", \"size\":\"60.6\"}, {\"price\":\"0.68\", \"size\":\"49.6\"}, {\"price\":\"0.67\", \"size\":\"52.6\"}, {\"price\":\"0.66\", \"size\":\"31.6\"}, {\"price\":\"0.65\", \"size\":\"41.6\"}], \"hash\":\"e1ba73b00fe5d3c928f2a026b44322c4e5f70009\", \"timestamp\":\"1785208033416\", \"event_type\":\"book\"}","received_at":"2026-07-28T03:07:17.392782Z","schema_version":"clob-market-ws.book.v1","sequence":null,"server_hash":"e1ba73b00fe5d3c928f2a026b44322c4e5f70009","server_timestamp":"1785208033416","session_id":"3e519d9098404c15b234d96025eb1a2b","source":"clob_market_ws"},"received_at":"2026-07-28T03:07:17.392782Z","record_id":"ba8d32aacbc1d0d09e90a76696d85884fd0a74598366b9428ce83745ca28368c","schema_fingerprint":"dc2caa1c89c6a7426e2e07ff925910cd4d0a8a223a515d4092d91d6d127aacb6","schema_version":"edge-lab-recorder.raw.v1","sequence":null,"source":"clob_market_ws"}
{"event_at":"2026-07-28T03:07:13.429000Z","event_fingerprint":"63fb796f21244f1cce28550436bc4d8b7510d35573874a4ce0a2c4fb656d0a91","payload":{"connection_id":"a6b55582af5f430fb37ad02bf0922475","event_at":"2026-07-28T03:07:13.429000Z","event_type":"price_change","frame_hash":"2cd73f202dac63b940e3d93a55ed37a8426e5fa1ff3286512a29a57c5a18a739","frame_index":0,"kind":"data","monotonic_ns":310020438417791,"payload":{"event_type":"price_change","market":"0x779291bef19b6709f61e9764a954aafe9ffae488d50ae674aabdcb4f248006d5","price_changes":[{"asset_id":"14965588658799411272385430903075831224615961675357217884735713260981483529984","best_ask":"0.36","best_bid":"0.35","hash":"48e8af3e1fa4683baefc41eac4b6f47144d5c6fd","price":"0.33","side":"BUY","size":"77.6"},{"asset_id":"8761897749749422724209054078244794145777693856614463256546737399611489089783","best_ask":"0.65","best_bid":"0.64","hash":"95f6f6235ec73df718eee52e782e19d311415d48","price":"0.67","side":"SELL","size":"77.6"}],"timestamp":"1785208033429"},"payload_hash":"2a5f0b61fd7e3f92ec6ea43d80ca6c560a20497b2a8641ce403f5bb98da0f2c2","raw_frame":"{\"market\":\"0x779291bef19b6709f61e9764a954aafe9ffae488d50ae674aabdcb4f248006d5\", \"price_changes\":[{\"asset_id\":\"14965588658799411272385430903075831224615961675357217884735713260981483529984\", \"price\":\"0.33\", \"size\":\"77.6\", \"side\":\"BUY\", \"hash\":\"48e8af3e1fa4683baefc41eac4b6f47144d5c6fd\", \"best_bid\":\"0.35\", \"best_ask\":\"0.36\"}, {\"asset_id\":\"8761897749749422724209054078244794145777693856614463256546737399611489089783\", \"price\":\"0.67\", \"size\":\"77.6\", \"side\":\"SELL\", \"hash\":\"95f6f6235ec73df718eee52e782e19d311415d48\", \"best_bid\":\"0.64\", \"best_ask\":\"0.65\"}], \"timestamp\":\"1785208033429\", \"event_type\":\"price_change\"}","received_at":"2026-07-28T03:07:17.406520Z","schema_version":"clob-market-ws.price_change.v1","sequence":null,"server_hash":null,"server_timestamp":"1785208033429","session_id":"3e519d9098404c15b234d96025eb1a2b","source":"clob_market_ws"},"received_at":"2026-07-28T03:07:17.406520Z","record_id":"ac0a20dc456450cd6d84b864268b7234e573ee35d3c3694434eadde00e083c25","schema_fingerprint":"4aa3821a28b0b7c2400bc59aba4bcc0a76e971dadd19610d3ad38c768e124dc7","schema_version":"edge-lab-recorder.raw.v1","sequence":null,"source":"clob_market_ws"}
{"event_at":"2026-07-28T03:07:13.430000Z","event_fingerprint":"308a83c5752329bf69e48deb70d3d86cdb98ae2897e357ce6412c869cf8079be","payload":{"connection_id":"a6b55582af5f430fb37ad02bf0922475","event_at":"2026-07-28T03:07:13.430000Z","event_type":"price_change","frame_hash":"c319c4822d91d7f8430f9d85a2c4ddadf2f5f80aa75bdd22e3f0e105908fda5d","frame_index":0,"kind":"data","monotonic_ns":310020441552791,"payload":{"event_type":"price_change","market":"0x779291bef19b6709f61e9764a954aafe9ffae488d50ae674aabdcb4f248006d5","price_changes":[{"asset_id":"8761897749749422724209054078244794145777693856614463256546737399611489089783","best_ask":"0.65","best_bid":"0.64","hash":"042c7e1a10ed02546b86ff47ed08a0a6c001a0ee","price":"0.67","side":"SELL","size":"102.6"},{"asset_id":"14965588658799411272385430903075831224615961675357217884735713260981483529984","best_ask":"0.36","best_bid":"0.35","hash":"b9f2557d125a6d0e6238d313a91fa346db36f545","price":"0.33","side":"BUY","size":"102.6"}],"timestamp":"1785208033430"},"payload_hash":"4e8d310739156ad87f0ccd07a9d87fea74a71d217144e7fc0b19a549e79245f1","raw_frame":"{\"market\":\"0x779291bef19b6709f61e9764a954aafe9ffae488d50ae674aabdcb4f248006d5\", \"price_changes\":[{\"asset_id\":\"8761897749749422724209054078244794145777693856614463256546737399611489089783\", \"price\":\"0.67\", \"size\":\"102.6\", \"side\":\"SELL\", \"hash\":\"042c7e1a10ed02546b86ff47ed08a0a6c001a0ee\", \"best_bid\":\"0.64\", \"best_ask\":\"0.65\"}, {\"asset_id\":\"14965588658799411272385430903075831224615961675357217884735713260981483529984\", \"price\":\"0.33\", \"size\":\"102.6\", \"side\":\"BUY\", \"hash\":\"b9f2557d125a6d0e6238d313a91fa346db36f545\", \"best_bid\":\"0.35\", \"best_ask\":\"0.36\"}], \"timestamp\":\"1785208033430\", \"event_type\":\"price_change\"}","received_at":"2026-07-28T03:07:17.409651Z","schema_version":"clob-market-ws.price_change.v1","sequence":null,"server_hash":null,"server_timestamp":"1785208033430","session_id":"3e519d9098404c15b234d96025eb1a2b","source":"clob_market_ws"},"received_at":"2026-07-28T03:07:17.409651Z","record_id":"d6d987c12c7f047582892aadf3cc156d451b08fcb3e8e8aa7f68113a88f593d0","schema_fingerprint":"4aa3821a28b0b7c2400bc59aba4bcc0a76e971dadd19610d3ad38c768e124dc7","schema_version":"edge-lab-recorder.raw.v1","sequence":null,"source":"clob_market_ws"}
{"event_at":"2026-07-28T03:07:13.441000Z","event_fingerprint":"64613220ba63050799db3684f5a5a82c7c3626cbf385ec20477feccee2016d9f","payload":{"connection_id":"a6b55582af5f430fb37ad02bf0922475","event_at":"2026-07-28T03:07:13.441000Z","event_type":"price_change","frame_hash":"e675e0c504b8d8ac9312999118191a39ec79b98dac718943366f6f0c8ae8691e","frame_index":0,"kind":"data","monotonic_ns":310020444574333,"payload":{"event_type":"price_change","market":"0x779291bef19b6709f61e9764a954aafe9ffae488d50ae674aabdcb4f248006d5","price_changes":[{"asset_id":"14965588658799411272385430903075831224615961675357217884735713260981483529984","best_ask":"0.36","best_bid":"0.35","hash":"b794020442ab56424014ec9f581037af95b20f85","price":"0.2","side":"BUY","size":"308.5"},{"asset_id":"8761897749749422724209054078244794145777693856614463256546737399611489089783","best_ask":"0.65","best_bid":"0.64","hash":"bdd7c9fca0b1fd3151aa8ed9042da417df9b0ea8","price":"0.8","side":"SELL","size":"308.5"}],"timestamp":"1785208033441"},"payload_hash":"b10b216c61fe79f1e63217cba58feec3d8d166f80c41ee021094656e5f84ffd2","raw_frame":"{\"market\":\"0x779291bef19b6709f61e9764a954aafe9ffae488d50ae674aabdcb4f248006d5\", \"price_changes\":[{\"asset_id\":\"14965588658799411272385430903075831224615961675357217884735713260981483529984\", \"price\":\"0.2\", \"size\":\"308.5\", \"side\":\"BUY\", \"hash\":\"b794020442ab56424014ec9f581037af95b20f85\", \"best_bid\":\"0.35\", \"best_ask\":\"0.36\"}, {\"asset_id\":\"8761897749749422724209054078244794145777693856614463256546737399611489089783\", \"price\":\"0.8\", \"size\":\"308.5\", \"side\":\"SELL\", \"hash\":\"bdd7c9fca0b1fd3151aa8ed9042da417df9b0ea8\", \"best_bid\":\"0.64\", \"best_ask\":\"0.65\"}], \"timestamp\":\"1785208033441\", \"event_type\":\"price_change\"}","received_at":"2026-07-28T03:07:17.412675Z","schema_version":"clob-market-ws.price_change.v1","sequence":null,"server_hash":null,"server_timestamp":"1785208033441","session_id":"3e519d9098404c15b234d96025eb1a2b","source":"clob_market_ws"},"received_at":"2026-07-28T03:07:17.412675Z","record_id":"83404ce2705a17e3c0b24b4f57b43410c803974f663ce3688174acdbe3a77bc0","schema_fingerprint":"4aa3821a28b0b7c2400bc59aba4bcc0a76e971dadd19610d3ad38c768e124dc7","schema_version":"edge-lab-recorder.raw.v1","sequence":null,"source":"clob_market_ws"}
{"event_at":"2026-07-28T03:07:13.442000Z","event_fingerprint":"b011c5086312318dcf832949535ad93b95f33066849a434b463cdd8960ac66d5","payload":{"connection_id":"a6b55582af5f430fb37ad02bf0922475","event_at":"2026-07-28T03:07:13.442000Z","event_type":"price_change","frame_hash":"8184cb0d8a809b4ce087ff2a66ed692d1899a7b8e7b8f010e460e2aafb025a49","frame_index":0,"kind":"data","monotonic_ns":310020447659916,"payload":{"event_type":"price_change","market":"0x779291bef19b6709f61e9764a954aafe9ffae488d50ae674aabdcb4f248006d5","price_changes":[{"asset_id":"14965588658799411272385430903075831224615961675357217884735713260981483529984","best_ask":"0.36","best_bid":"0.35","hash":"5c79a2624e233e04005e6535c545532fd8ac9177","price":"0.21","side":"BUY","size":"282.25"},{"asset_id":"8761897749749422724209054078244794145777693856614463256546737399611489089783","best_ask":"0.65","best_bid":"0.64","hash":"02b21f9040806eaea8e9c976f0eff1d65cdb6c08","price":"0.79","side":"SELL","size":"282.25"}],"timestamp":"1785208033442"},"payload_hash":"5e97f27702396065c6d0edce5a79f283d194c199d61296b61a7f8910180c8226","raw_frame":"{\"market\":\"0x779291bef19b6709f61e9764a954aafe9ffae488d50ae674aabdcb4f248006d5\", \"price_changes\":[{\"asset_id\":\"14965588658799411272385430903075831224615961675357217884735713260981483529984\", \"price\":\"0.21\", \"size\":\"282.25\", \"side\":\"BUY\", \"hash\":\"5c79a2624e233e04005e6535c545532fd8ac9177\", \"best_bid\":\"0.35\", \"best_ask\":\"0.36\"}, {\"asset_id\":\"8761897749749422724209054078244794145777693856614463256546737399611489089783\", \"price\":\"0.79\", \"size\":\"282.25\", \"side\":\"SELL\", \"hash\":\"02b21f9040806eaea8e9c976f0eff1d65cdb6c08\", \"best_bid\":\"0.64\", \"best_ask\":\"0.65\"}], \"timestamp\":\"1785208033442\", \"event_type\":\"price_change\"}","received_at":"2026-07-28T03:07:17.415760Z","schema_version":"clob-market-ws.price_change.v1","sequence":null,"server_hash":null,"server_timestamp":"1785208033442","session_id":"3e519d9098404c15b234d96025eb1a2b","source":"clob_market_ws"},"received_at":"2026-07-28T03:07:17.415760Z","record_id":"f8548318c1f6c5b4e1fe680a974f459ee7596582d2427ec409580219f4634721","schema_fingerprint":"4aa3821a28b0b7c2400bc59aba4bcc0a76e971dadd19610d3ad38c768e124dc7","schema_version":"edge-lab-recorder.raw.v1","sequence":null,"source":"clob_market_ws"}
{"event_at":"2026-07-28T03:07:13.444000Z","event_fingerprint":"37f751509ae90c87ec6390f35b188e97a30fdbc8522c4c03a8dc01fe5b3c5a05","payload":{"connection_id":"a6b55582af5f430fb37ad02bf0922475","event_at":"2026-07-28T03:07:13.444000Z","event_type":"price_change","frame_hash":"d721f1f67c84b3645dba9e4f17c89d99b3de1c5228390c3828331f4d76791b09","frame_index":0,"kind":"data","monotonic_ns":310020450401250,"payload":{"event_type":"price_change","market":"0x779291bef19b6709f61e9764a954aafe9ffae488d50ae674aabdcb4f248006d5","price_changes":[{"asset_id":"8761897749749422724209054078244794145777693856614463256546737399611489089783","best_ask":"0.65","best_bid":"0.64","hash":"45a787739de8020ca85c98d17ec933a417cc614a","price":"0.63","side":"BUY","size":"61.65"},{"asset_id":"14965588658799411272385430903075831224615961675357217884735713260981483529984","best_ask":"0.36","best_bid":"0.35","hash":"f8c41be648b80a4c8bd5f513708acbbb12dfa2c5","price":"0.37","side":"SELL","size":"61.65"}],"timestamp":"1785208033444"},"payload_hash":"6789076334922e182a8ef049b25144062512f3d41a699013f542b15665ae1e5d","raw_frame":"{\"market\":\"0x779291bef19b6709f61e9764a954aafe9ffae488d50ae674aabdcb4f248006d5\", \"price_changes\":[{\"asset_id\":\"8761897749749422724209054078244794145777693856614463256546737399611489089783\", \"price\":\"0.63\", \"size\":\"61.65\", \"side\":\"BUY\", \"hash\":\"45a787739de8020ca85c98d17ec933a417cc614a\", \"best_bid\":\"0.64\", \"best_ask\":\"0.65\"}, {\"asset_id\":\"14965588658799411272385430903075831224615961675357217884735713260981483529984\", \"price\":\"0.37\", \"size\":\"61.65\", \"side\":\"SELL\", \"hash\":\"f8c41be648b80a4c8bd5f513708acbbb12dfa2c5\", \"best_bid\":\"0.35\", \"best_ask\":\"0.36\"}], \"timestamp\":\"1785208033444\", \"event_type\":\"price_change\"}","received_at":"2026-07-28T03:07:17.418505Z","schema_version":"clob-market-ws.price_change.v1","sequence":null,"server_hash":null,"server_timestamp":"1785208033444","session_id":"3e519d9098404c15b234d96025eb1a2b","source":"clob_market_ws"},"received_at":"2026-07-28T03:07:17.418505Z","record_id":"4fab74dd0204431be33941475515b37ed8a34dff3592db0decc26a833716c2bc","schema_fingerprint":"4aa3821a28b0b7c2400bc59aba4bcc0a76e971dadd19610d3ad38c768e124dc7","schema_version":"edge-lab-recorder.raw.v1","sequence":null,"source":"clob_market_ws"}
{"event_at":"2026-07-28T03:07:13.445000Z","event_fingerprint":"877e8100a43f610e3c22fb11d14ac13273ddc65bb08c1c8654d671d8b26534a6","payload":{"connection_id":"a6b55582af5f430fb37ad02bf0922475","event_at":"2026-07-28T03:07:13.445000Z","event_type":"price_change","frame_hash":"cbc2fad0e87ca24a69bcd9fb5b8b5fdff4e9c69f80e52e0a7e7415e52c1613e5","frame_index":0,"kind":"data","monotonic_ns":310020452145625,"payload":{"event_type":"price_change","market":"0x779291bef19b6709f61e9764a954aafe9ffae488d50ae674aabdcb4f248006d5","price_changes":[{"asset_id":"8761897749749422724209054078244794145777693856614463256546737399611489089783","best_ask":"0.65","best_bid":"0.64","hash":"6451d22c01a779584e9e2c3956815979fe5c139f","price":"0.64","side":"BUY","size":"33.74"},{"asset_id":"14965588658799411272385430903075831224615961675357217884735713260981483529984","best_ask":"0.36","best_bid":"0.35","hash":"9588c542ae48fbf9b7c0cf9db59620dc2191e27a","price":"0.36","side":"SELL","size":"33.74"}],"timestamp":"1785208033445"},"payload_hash":"18d8461f6c93cb6bec54451b6e197340a956e10747a0b4eea1ad68ff7af2ed67","raw_frame":"{\"market\":\"0x779291bef19b6709f61e9764a954aafe9ffae488d50ae674aabdcb4f248006d5\", \"price_changes\":[{\"asset_id\":\"8761897749749422724209054078244794145777693856614463256546737399611489089783\", \"price\":\"0.64\", \"size\":\"33.74\", \"side\":\"BUY\", \"hash\":\"6451d22c01a779584e9e2c3956815979fe5c139f\", \"best_bid\":\"0.64\", \"best_ask\":\"0.65\"}, {\"asset_id\":\"14965588658799411272385430903075831224615961675357217884735713260981483529984\", \"price\":\"0.36\", \"size\":\"33.74\", \"side\":\"SELL\", \"hash\":\"9588c542ae48fbf9b7c0cf9db59620dc2191e27a\", \"best_bid\":\"0.35\", \"best_ask\":\"0.36\"}], \"timestamp\":\"1785208033445\", \"event_type\":\"price_change\"}","received_at":"2026-07-28T03:07:17.420252Z","schema_version":"clob-market-ws.price_change.v1","sequence":null,"server_hash":null,"server_timestamp":"1785208033445","session_id":"3e519d9098404c15b234d96025eb1a2b","source":"clob_market_ws"},"received_at":"2026-07-28T03:07:17.420252Z","record_id":"004f7db94a2e3d9d9ed9a4bcb35c9f308db1f6602b342e95897af054936d2467","schema_fingerprint":"4aa3821a28b0b7c2400bc59aba4bcc0a76e971dadd19610d3ad38c768e124dc7","schema_version":"edge-lab-recorder.raw.v1","sequence":null,"source":"clob_market_ws"}
{"event_at":"2026-07-28T03:07:13.446000Z","event_fingerprint":"2e71d4efb893aab5299328392db54f1da94c079b365eb5bd9e67668f6b5ab1b2","payload":{"connection_id":"a6b55582af5f430fb37ad02bf0922475","event_at":"2026-07-28T03:07:13.446000Z","event_type":"price_change","frame_hash":"4fc46139fef84aa91525ab054acceb6749d2f3e66c091d02d7f3b521cacf66e5","frame_index":0,"kind":"data","monotonic_ns":310020453264458,"payload":{"event_type":"price_change","market":"0x779291bef19b6709f61e9764a954aafe9ffae488d50ae674aabdcb4f248006d5","price_changes":[{"asset_id":"8761897749749422724209054078244794145777693856614463256546737399611489089783","best_ask":"0.65","best_bid":"0.64","hash":"376b8e8474f38e8aef803d5a8bfeca7656a9a33a","price":"0.62","side":"BUY","size":"54.54"},{"asset_id":"14965588658799411272385430903075831224615961675357217884735713260981483529984","best_ask":"0.36","best_bid":"0.35","hash":"b010e04ece057b1993faed3106bbf8ad22cc9ab2","price":"0.38","side":"SELL","size":"54.54"}],"timestamp":"1785208033446"},"payload_hash":"31645d66593ef52adce9a005a303ddc018e3089a1ec57f8cc66ead0e45b119bf","raw_frame":"{\"market\":\"0x779291bef19b6709f61e9764a954aafe9ffae488d50ae674aabdcb4f248006d5\", \"price_changes\":[{\"asset_id\":\"8761897749749422724209054078244794145777693856614463256546737399611489089783\", \"price\":\"0.62\", \"size\":\"54.54\", \"side\":\"BUY\", \"hash\":\"376b8e8474f38e8aef803d5a8bfeca7656a9a33a\", \"best_bid\":\"0.64\", \"best_ask\":\"0.65\"}, {\"asset_id\":\"14965588658799411272385430903075831224615961675357217884735713260981483529984\", \"price\":\"0.38\", \"size\":\"54.54\", \"side\":\"SELL\", \"hash\":\"b010e04ece057b1993faed3106bbf8ad22cc9ab2\", \"best_bid\":\"0.35\", \"best_ask\":\"0.36\"}], \"timestamp\":\"1785208033446\", \"event_type\":\"price_change\"}","received_at":"2026-07-28T03:07:17.421371Z","schema_version":"clob-market-ws.price_change.v1","sequence":null,"server_hash":null,"server_timestamp":"1785208033446","session_id":"3e519d9098404c15b234d96025eb1a2b","source":"clob_market_ws"},"received_at":"2026-07-28T03:07:17.421371Z","record_id":"69830125b7d0d1533c235dc6a62ba1ef70582ddf0fb50eb28fd562e3ba068cf0","schema_fingerprint":"4aa3821a28b0b7c2400bc59aba4bcc0a76e971dadd19610d3ad38c768e124dc7","schema_version":"edge-lab-recorder.raw.v1","sequence":null,"source":"clob_market_ws"}
{"event_at":"2026-07-28T03:07:13.447000Z","event_fingerprint":"5a7ce0d5db283d2c243f666dbcd334dc8db9f7027f34beae240a405026021935","payload":{"connection_id":"a6b55582af5f430fb37ad02bf0922475","event_at":"2026-07-28T03:07:13.447000Z","event_type":"price_change","frame_hash":"0999b5ebd44822764021125b1bcf566a97fd016420a09893375d458b53d74ac4","frame_index":0,"kind":"data","monotonic_ns":310020454527125,"payload":{"event_type":"price_change","market":"0x779291bef19b6709f61e9764a954aafe9ffae488d50ae674aabdcb4f248006d5","price_changes":[{"asset_id":"14965588658799411272385430903075831224615961675357217884735713260981483529984","best_ask":"0.36","best_bid":"0.35","hash":"0d7e260a17686bce63ed7ea865e896489d329cde","price":"0.19","side":"BUY","size":"324.07"},{"asset_id":"8761897749749422724209054078244794145777693856614463256546737399611489089783","best_ask":"0.65","best_bid":"0.64","hash":"c9262c08c4005f3c43bef7ad7c799e713ea03f8c","price":"0.81","side":"SELL","size":"324.07"}],"timestamp":"1785208033447"},"payload_hash":"96f0956358c719e3e4641505ea12b92fa01cf91d254b4728b6c52857fa1443fa","raw_frame":"{\"market\":\"0x779291bef19b6709f61e9764a954aafe9ffae488d50ae674aabdcb4f248006d5\", \"price_changes\":[{\"asset_id\":\"14965588658799411272385430903075831224615961675357217884735713260981483529984\", \"price\":\"0.19\", \"size\":\"324.07\", \"side\":\"BUY\", \"hash\":\"0d7e260a17686bce63ed7ea865e896489d329cde\", \"best_bid\":\"0.35\", \"best_ask\":\"0.36\"}, {\"asset_id\":\"8761897749749422724209054078244794145777693856614463256546737399611489089783\", \"price\":\"0.81\", \"size\":\"324.07\", \"side\":\"SELL\", \"hash\":\"c9262c08c4005f3c43bef7ad7c799e713ea03f8c\", \"best_bid\":\"0.64\", \"best_ask\":\"0.65\"}], \"timestamp\":\"1785208033447\", \"event_type\":\"price_change\"}","received_at":"2026-07-28T03:07:17.422633Z","schema_version":"clob-market-ws.price_change.v1","sequence":null,"server_hash":null,"server_timestamp":"1785208033447","session_id":"3e519d9098404c15b234d96025eb1a2b","source":"clob_market_ws"},"received_at":"2026-07-28T03:07:17.422633Z","record_id":"136d5bc2987ad98a29dce7e9b84952bcb52ebb4eb5f4cfa60160f545879cd179","schema_fingerprint":"4aa3821a28b0b7c2400bc59aba4bcc0a76e971dadd19610d3ad38c768e124dc7","schema_version":"edge-lab-recorder.raw.v1","sequence":null,"source":"clob_market_ws"}
{"event_at":"2026-07-28T03:07:13.452000Z","event_fingerprint":"8dbb095df2a8cb7ef7d6202c45b150499783bdabade94ce8bd75d34beb0d3f87","payload":{"connection_id":"a6b55582af5f430fb37ad02bf0922475","event_at":"2026-07-28T03:07:13.452000Z","event_type":"price_change","frame_hash":"679348b5ac0146a838caa15badeff9f3b2e9a58acdacca3d23773d749e937e2e","frame_index":0,"kind":"data","monotonic_ns":310020455840583,"payload":{"event_type":"price_change","market":"0x779291bef19b6709f61e9764a954aafe9ffae488d50ae674aabdcb4f248006d5","price_changes":[{"asset_id":"14965588658799411272385430903075831224615961675357217884735713260981483529984","best_ask":"0.36","best_bid":"0.35","hash":"74b57cb4226c8ab512aef217653382b05f7ff5cc","price":"0.3","side":"BUY","size":"91.2"},{"asset_id":"8761897749749422724209054078244794145777693856614463256546737399611489089783","best_ask":"0.65","best_bid":"0.64","hash":"54eae9b27361a766ff2487b3f7879230b3020827","price":"0.7","side":"SELL","size":"91.2"}],"timestamp":"1785208033452"},"payload_hash":"4995edf870221063bf1c2d695a04e3a5a71810f3c89e5a52323889ce1398f48e","raw_frame":"{\"market\":\"0x779291bef19b6709f61e9764a954aafe9ffae488d50ae674aabdcb4f248006d5\", \"price_changes\":[{\"asset_id\":\"14965588658799411272385430903075831224615961675357217884735713260981483529984\", \"price\":\"0.3\", \"size\":\"91.2\", \"side\":\"BUY\", \"hash\":\"74b57cb4226c8ab512aef217653382b05f7ff5cc\", \"best_bid\":\"0.35\", \"best_ask\":\"0.36\"}, {\"asset_id\":\"8761897749749422724209054078244794145777693856614463256546737399611489089783\", \"price\":\"0.7\", \"size\":\"91.2\", \"side\":\"SELL\", \"hash\":\"54eae9b27361a766ff2487b3f7879230b3020827\", \"best_bid\":\"0.64\", \"best_ask\":\"0.65\"}], \"timestamp\":\"1785208033452\", \"event_type\":\"price_change\"}","received_at":"2026-07-28T03:07:17.423947Z","schema_version":"clob-market-ws.price_change.v1","sequence":null,"server_hash":null,"server_timestamp":"1785208033452","session_id":"3e519d9098404c15b234d96025eb1a2b","source":"clob_market_ws"},"received_at":"2026-07-28T03:07:17.423947Z","record_id":"7523c561d85b24e894a25cebe4ad9f3d9498da45a7b64e1f4d4b642b8728c920","schema_fingerprint":"4aa3821a28b0b7c2400bc59aba4bcc0a76e971dadd19610d3ad38c768e124dc7","schema_version":"edge-lab-recorder.raw.v1","sequence":null,"source":"clob_market_ws"}
{"event_at":"2026-07-28T03:07:13.457000Z","event_fingerprint":"242d92c4c800c0ccc104e40b723d9315da1e8763504b6609b1d7d59e53c0df4a","payload":{"connection_id":"a6b55582af5f430fb37ad02bf0922475","event_at":"2026-07-28T03:07:13.457000Z","event_type":"price_change","frame_hash":"69c9d186930a4565c5f128accd5b7bffa75a73c5ae879152236d958ae5c618f3","frame_index":0,"kind":"data","monotonic_ns":310020458111250,"payload":{"event_type":"price_change","market":"0x779291bef19b6709f61e9764a954aafe9ffae488d50ae674aabdcb4f248006d5","price_changes":[{"asset_id":"8761897749749422724209054078244794145777693856614463256546737399611489089783","best_ask":"0.65","best_bid":"0.64","hash":"5d9613c5dfd7a0d87cbb59d31797b13791b40ec0","price":"0.01","side":"BUY","size":"5613.02"},{"asset_id":"14965588658799411272385430903075831224615961675357217884735713260981483529984","best_ask":"0.36","best_bid":"0.35","hash":"dca540ca332647feae84b71a5516059d5faee827","price":"0.99","side":"SELL","size":"5613.02"}],"timestamp":"1785208033457"},"payload_hash":"09a87921a267d53a416568fd27dd2562249f219e8e94079c3d5e67fa3102ebdf","raw_frame":"{\"market\":\"0x779291bef19b6709f61e9764a954aafe9ffae488d50ae674aabdcb4f248006d5\", \"price_changes\":[{\"asset_id\":\"8761897749749422724209054078244794145777693856614463256546737399611489089783\", \"price\":\"0.01\", \"size\":\"5613.02\", \"side\":\"BUY\", \"hash\":\"5d9613c5dfd7a0d87cbb59d31797b13791b40ec0\", \"best_bid\":\"0.64\", \"best_ask\":\"0.65\"}, {\"asset_id\":\"14965588658799411272385430903075831224615961675357217884735713260981483529984\", \"price\":\"0.99\", \"size\":\"5613.02\", \"side\":\"SELL\", \"hash\":\"dca540ca332647feae84b71a5516059d5faee827\", \"best_bid\":\"0.35\", \"best_ask\":\"0.36\"}], \"timestamp\":\"1785208033457\", \"event_type\":\"price_change\"}","received_at":"2026-07-28T03:07:17.426213Z","schema_version":"clob-market-ws.price_change.v1","sequence":null,"server_hash":null,"server_timestamp":"1785208033457","session_id":"3e519d9098404c15b234d96025eb1a2b","source":"clob_market_ws"},"received_at":"2026-07-28T03:07:17.426213Z","record_id":"d264192cbca64bac18af7f0ac0a09e4d6a82d78aed70ff6e5ef4b7093ead7ff8","schema_fingerprint":"4aa3821a28b0b7c2400bc59aba4bcc0a76e971dadd19610d3ad38c768e124dc7","schema_version":"edge-lab-recorder.raw.v1","sequence":null,"source":"clob_market_ws"}
{"event_at":"2026-07-28T03:07:13.458000Z","event_fingerprint":"598085b3c56aef472d26ac9b84466b977e284a4daa5babf017bf7e104ad5cb38","payload":{"connection_id":"a6b55582af5f430fb37ad02bf0922475","event_at":"2026-07-28T03:07:13.458000Z","event_type":"price_change","frame_hash":"cda880296dc19de4785fa3792cc25d5d198c9342b2e764135fa6cb581b81f556","frame_index":0,"kind":"data","monotonic_ns":310020461241666,"payload":{"event_type":"price_change","market":"0x779291bef19b6709f61e9764a954aafe9ffae488d50ae674aabdcb4f248006d5","price_changes":[{"asset_id":"8761897749749422724209054078244794145777693856614463256546737399611489089783","best_ask":"0.65","best_bid":"0.64","hash":"ba54623c80b3de23b8e9a91282088ac5501a6010","price":"0.43","side":"BUY","size":"124.71"},{"asset_id":"14965588658799411272385430903075831224615961675357217884735713260981483529984","best_ask":"0.36","best_bid":"0.35","hash":"b79ce4e1b3906fb7b4464feb4cf291912fcd8f5c","price":"0.57","side":"SELL","size":"124.71"}],"timestamp":"1785208033458"},"payload_hash":"36e32082ab28fc8e74e3adc3d2ef5294d885a758e763a5136d2d2ab78a74f872","raw_frame":"{\"market\":\"0x779291bef19b6709f61e9764a954aafe9ffae488d50ae674aabdcb4f248006d5\", \"price_changes\":[{\"asset_id\":\"8761897749749422724209054078244794145777693856614463256546737399611489089783\", \"price\":\"0.43\", \"size\":\"124.71\", \"side\":\"BUY\", \"hash\":\"ba54623c80b3de23b8e9a91282088ac5501a6010\", \"best_bid\":\"0.64\", \"best_ask\":\"0.65\"}, {\"asset_id\":\"14965588658799411272385430903075831224615961675357217884735713260981483529984\", \"price\":\"0.57\", \"size\":\"124.71\", \"side\":\"SELL\", \"hash\":\"b79ce4e1b3906fb7b4464feb4cf291912fcd8f5c\", \"best_bid\":\"0.35\", \"best_ask\":\"0.36\"}], \"timestamp\":\"1785208033458\", \"event_type\":\"price_change\"}","received_at":"2026-07-28T03:07:17.429347Z","schema_version":"clob-market-ws.price_change.v1","sequence":null,"server_hash":null,"server_timestamp":"1785208033458","session_id":"3e519d9098404c15b234d96025eb1a2b","source":"clob_market_ws"},"received_at":"2026-07-28T03:07:17.429347Z","record_id":"bdde4220b2577ad411cbca6e100f33ec476aef5cd2ea89725fd2da2171864c8b","schema_fingerprint":"4aa3821a28b0b7c2400bc59aba4bcc0a76e971dadd19610d3ad38c768e124dc7","schema_version":"edge-lab-recorder.raw.v1","sequence":null,"source":"clob_market_ws"}
{"event_at":"2026-07-28T03:07:13.463000Z","event_fingerprint":"b6312c4317f70904b71f6cd29c51a0d14c7075596e90ed3d123eecc357f45970","payload":{"connection_id":"a6b55582af5f430fb37ad02bf0922475","event_at":"2026-07-28T03:07:13.463000Z","event_type":"price_change","frame_hash":"1ed8ab885966a24a6ca2ae1d1f6a2053e261cce61582833c6bf16d9c86a0c752","frame_index":0,"kind":"data","monotonic_ns":310020463439000,"payload":{"event_type":"price_change","market":"0x779291bef19b6709f61e9764a954aafe9ffae488d50ae674aabdcb4f248006d5","price_changes":[{"asset_id":"14965588658799411272385430903075831224615961675357217884735713260981483529984","best_ask":"0.36","best_bid":"0.35","hash":"053ad4915aaf97020a097df1c53034415ba8afe1","price":"0.13","side":"BUY","size":"561.5"},{"asset_id":"8761897749749422724209054078244794145777693856614463256546737399611489089783","best_ask":"0.65","best_bid":"0.64","hash":"a4b46b3a85c30533bd1ce3206be9ee38330d8b5e","price":"0.87","side":"SELL","size":"561.5"}],"timestamp":"1785208033463"},"payload_hash":"6b92b5b77e473f7a80d4aedd11b1b6f9a425f1c2986baf7e0be952ce85ffa422","raw_frame":"{\"market\":\"0x779291bef19b6709f61e9764a954aafe9ffae488d50ae674aabdcb4f248006d5\", \"price_changes\":[{\"asset_id\":\"14965588658799411272385430903075831224615961675357217884735713260981483529984\", \"price\":\"0.13\", \"size\":\"561.5\", \"side\":\"BUY\", \"hash\":\"053ad4915aaf97020a097df1c53034415ba8afe1\", \"best_bid\":\"0.35\", \"best_ask\":\"0.36\"}, {\"asset_id\":\"8761897749749422724209054078244794145777693856614463256546737399611489089783\", \"price\":\"0.87\", \"size\":\"561.5\", \"side\":\"SELL\", \"hash\":\"a4b46b3a85c30533bd1ce3206be9ee38330d8b5e\", \"best_bid\":\"0.64\", \"best_ask\":\"0.65\"}], \"timestamp\":\"1785208033463\", \"event_type\":\"price_change\"}","received_at":"2026-07-28T03:07:17.431541Z","schema_version":"clob-market-ws.price_change.v1","sequence":null,"server_hash":null,"server_timestamp":"1785208033463","session_id":"3e519d9098404c15b234d96025eb1a2b","source":"clob_market_ws"},"received_at":"2026-07-28T03:07:17.431541Z","record_id":"5e50b622ed9bd37f7b16524d27ffca6fbec902bd2b4afa41ccb9d6705c968844","schema_fingerprint":"4aa3821a28b0b7c2400bc59aba4bcc0a76e971dadd19610d3ad38c768e124dc7","schema_version":"edge-lab-recorder.raw.v1","sequence":null,"source":"clob_market_ws"}
{"event_at":"2026-07-28T03:07:13.473000Z","event_fingerprint":"70d37970ec4e94154b79662d6f849c31f3e6ffce03705eac6e1743b8bf3347ac","payload":{"connection_id":"a6b55582af5f430fb37ad02bf0922475","event_at":"2026-07-28T03:07:13.473000Z","event_type":"last_trade_price","frame_hash":"48cc44de72155067dfb5edc9ad81cf89ea32ab8d8da95974c458b31b15db3dfa","frame_index":0,"kind":"data","monotonic_ns":310020466389750,"payload":{"asset_id":"8761897749749422724209054078244794145777693856614463256546737399611489089783","event_type":"last_trade_price","fee_rate_bps":"0","market":"0x779291bef19b6709f61e9764a954aafe9ffae488d50ae674aabdcb4f248006d5","price":"0.64","side":"SELL","size":"0.02","timestamp":"1785208033473","transaction_hash":"0xe47b53382a51935b7288047bb2c4850dc4dc40461c1313ec27140073f48789e9"},"payload_hash":"0279c35e8f591c7f4dca58e9dab50e99ee322a9282240b1cecef6ccfd41373d0","raw_frame":"{\"market\":\"0x779291bef19b6709f61e9764a954aafe9ffae488d50ae674aabdcb4f248006d5\", \"asset_id\":\"8761897749749422724209054078244794145777693856614463256546737399611489089783\", \"price\":\"0.64\", \"size\":\"0.02\", \"fee_rate_bps\":\"0\", \"side\":\"SELL\", \"timestamp\":\"1785208033473\", \"event_type\":\"last_trade_price\", \"transaction_hash\":\"0xe47b53382a51935b7288047bb2c4850dc4dc40461c1313ec27140073f48789e9\"}","received_at":"2026-07-28T03:07:17.434492Z","schema_version":"clob-market-ws.last_trade_price.v1","sequence":null,"server_hash":null,"server_timestamp":"1785208033473","session_id":"3e519d9098404c15b234d96025eb1a2b","source":"clob_market_ws"},"received_at":"2026-07-28T03:07:17.434492Z","record_id":"7cb0771436b87be84a871720772c9cad7dca577b3744f14688f960e4a0c94abb","schema_fingerprint":"95ad9be75a4b695cd99991e12b2592bc7346f3f5388a82d0000ba65bc0d9fd0a","schema_version":"edge-lab-recorder.raw.v1","sequence":null,"source":"clob_market_ws"}
{"event_at":"2026-07-28T03:07:13.487000Z","event_fingerprint":"c2c48593c6517169669ee24d952106eb2295a3d7bdbf480732e4afe349cf70ef","payload":{"connection_id":"a6b55582af5f430fb37ad02bf0922475","event_at":"2026-07-28T03:07:13.487000Z","event_type":"price_change","frame_hash":"a7263ffd378a66510825c8848e6f3d0bb470dafdcc04d4fad49f6e9e0e0d8e17","frame_index":0,"kind":"data","monotonic_ns":310020469083958,"payload":{"event_type":"price_change","market":"0x779291bef19b6709f61e9764a954aafe9ffae488d50ae674aabdcb4f248006d5","price_changes":[{"asset_id":"14965588658799411272385430903075831224615961675357217884735713260981483529984","best_ask":"0.36","best_bid":"0.35","hash":"6b647517a776c2ed75238d89c24a1587c3f9c9af","price":"0.23","side":"BUY","size":"154.89"},{"asset_id":"8761897749749422724209054078244794145777693856614463256546737399611489089783","best_ask":"0.65","best_bid":"0.64","hash":"d6de2811e339bc2d04b12a16d1056ea5c2e32154","price":"0.77","side":"SELL","size":"154.89"}],"timestamp":"1785208033487"},"payload_hash":"bbe14d5299b9cbfb623a8f3b2af169d00b1409271dfa76cb63a18f656edef223","raw_frame":"{\"market\":\"0x779291bef19b6709f61e9764a954aafe9ffae488d50ae674aabdcb4f248006d5\", \"price_changes\":[{\"asset_id\":\"14965588658799411272385430903075831224615961675357217884735713260981483529984\", \"price\":\"0.23\", \"size\":\"154.89\", \"side\":\"BUY\", \"hash\":\"6b647517a776c2ed75238d89c24a1587c3f9c9af\", \"best_bid\":\"0.35\", \"best_ask\":\"0.36\"}, {\"asset_id\":\"8761897749749422724209054078244794145777693856614463256546737399611489089783\", \"price\":\"0.77\", \"size\":\"154.89\", \"side\":\"SELL\", \"hash\":\"d6de2811e339bc2d04b12a16d1056ea5c2e32154\", \"best_bid\":\"0.64\", \"best_ask\":\"0.65\"}], \"timestamp\":\"1785208033487\", \"event_type\":\"price_change\"}","received_at":"2026-07-28T03:07:17.437185Z","schema_version":"clob-market-ws.price_change.v1","sequence":null,"server_hash":null,"server_timestamp":"1785208033487","session_id":"3e519d9098404c15b234d96025eb1a2b","source":"clob_market_ws"},"received_at":"2026-07-28T03:07:17.437185Z","record_id":"7070f40e89a3d45c10c7cafaad896a881ae00242fe8477e5b33c07a279bb441a","schema_fingerprint":"4aa3821a28b0b7c2400bc59aba4bcc0a76e971dadd19610d3ad38c768e124dc7","schema_version":"edge-lab-recorder.raw.v1","sequence":null,"source":"clob_market_ws"}
{"event_at":"2026-07-28T03:07:13.488000Z","event_fingerprint":"d9df67a3f0cc1d1e7153ca4ad4307903e725785c7fd4ffab6c924c3a8173746c","payload":{"connection_id":"a6b55582af5f430fb37ad02bf0922475","event_at":"2026-07-28T03:07:13.488000Z","event_type":"price_change","frame_hash":"4c011a7d758ffa14ecdf6030b41b373b8561c3b2636fa1b1f43861b1a861ce3e","frame_index":0,"kind":"data","monotonic_ns":310020472043041,"payload":{"event_type":"price_change","market":"0x779291bef19b6709f61e9764a954aafe9ffae488d50ae674aabdcb4f248006d5","price_changes":[{"asset_id":"14965588658799411272385430903075831224615961675357217884735713260981483529984","best_ask":"0.36","best_bid":"0.35","hash":"deaf1ec27a0a3bffa1e95bdc1ba4ee7c3b0ba7d2","price":"0.24","side":"BUY","size":"155"},{"asset_id":"8761897749749422724209054078244794145777693856614463256546737399611489089783","best_ask":"0.65","best_bid":"0.64","hash":"561acf639298ace3fa2f15a7776e4a5b995a01fc","price":"0.76","side":"SELL","size":"155"}],"timestamp":"1785208033488"},"payload_hash":"e3e7af87d01808fedb358eb25bb34aaf2d6490d329a912e46db34ab1839b4ac4","raw_frame":"{\"market\":\"0x779291bef19b6709f61e9764a954aafe9ffae488d50ae674aabdcb4f248006d5\", \"price_changes\":[{\"asset_id\":\"14965588658799411272385430903075831224615961675357217884735713260981483529984\", \"price\":\"0.24\", \"size\":\"155\", \"side\":\"BUY\", \"hash\":\"deaf1ec27a0a3bffa1e95bdc1ba4ee7c3b0ba7d2\", \"best_bid\":\"0.35\", \"best_ask\":\"0.36\"}, {\"asset_id\":\"8761897749749422724209054078244794145777693856614463256546737399611489089783\", \"price\":\"0.76\", \"size\":\"155\", \"side\":\"SELL\", \"hash\":\"561acf639298ace3fa2f15a7776e4a5b995a01fc\", \"best_bid\":\"0.64\", \"best_ask\":\"0.65\"}], \"timestamp\":\"1785208033488\", \"event_type\":\"price_change\"}","received_at":"2026-07-28T03:07:17.440144Z","schema_version":"clob-market-ws.price_change.v1","sequence":null,"server_hash":null,"server_timestamp":"1785208033488","session_id":"3e519d9098404c15b234d96025eb1a2b","source":"clob_market_ws"},"received_at":"2026-07-28T03:07:17.440144Z","record_id":"3013092b541e194a79f3abb34f296feec69a0fee5c02e4044b24f1ae602af9d9","schema_fingerprint":"4aa3821a28b0b7c2400bc59aba4bcc0a76e971dadd19610d3ad38c768e124dc7","schema_version":"edge-lab-recorder.raw.v1","sequence":null,"source":"clob_market_ws"}
{"event_at":"2026-07-28T03:07:13.506000Z","event_fingerprint":"2337c146b8de499a920597ec9b74d85167808423834560cdb2da1629562fd0b3","payload":{"connection_id":"a6b55582af5f430fb37ad02bf0922475","event_at":"2026-07-28T03:07:13.506000Z","event_type":"price_change","frame_hash":"5762f2aab887d78517f0f2b81062e871d0e66d0402a4e0394435086078561ac8","frame_index":0,"kind":"data","monotonic_ns":310020475049875,"payload":{"event_type":"price_change","market":"0x779291bef19b6709f61e9764a954aafe9ffae488d50ae674aabdcb4f248006d5","price_changes":[{"asset_id":"14965588658799411272385430903075831224615961675357217884735713260981483529984","best_ask":"0.36","best_bid":"0.35","hash":"48711d6374c621929c649bb3e4f2009d29a86588","price":"0.28","side":"BUY","size":"73"},{"asset_id":"8761897749749422724209054078244794145777693856614463256546737399611489089783","best_ask":"0.65","best_bid":"0.64","hash":"e79c5a4db14c7074b076ae6a206c293f532f9acb","price":"0.72","side":"SELL","size":"73"}],"timestamp":"1785208033506"},"payload_hash":"641425ad22ec54d9e3909f822c5482db64c828249ac495b6f6646e93538e0d66","raw_frame":"{\"market\":\"0x779291bef19b6709f61e9764a954aafe9ffae488d50ae674aabdcb4f248006d5\", \"price_changes\":[{\"asset_id\":\"14965588658799411272385430903075831224615961675357217884735713260981483529984\", \"price\":\"0.28\", \"size\":\"73\", \"side\":\"BUY\", \"hash\":\"48711d6374c621929c649bb3e4f2009d29a86588\", \"best_bid\":\"0.35\", \"best_ask\":\"0.36\"}, {\"asset_id\":\"8761897749749422724209054078244794145777693856614463256546737399611489089783\", \"price\":\"0.72\", \"size\":\"73\", \"side\":\"SELL\", \"hash\":\"e79c5a4db14c7074b076ae6a206c293f532f9acb\", \"best_bid\":\"0.64\", \"best_ask\":\"0.65\"}], \"timestamp\":\"1785208033506\", \"event_type\":\"price_change\"}","received_at":"2026-07-28T03:07:17.443151Z","schema_version":"clob-market-ws.price_change.v1","sequence":null,"server_hash":null,"server_timestamp":"1785208033506","session_id":"3e519d9098404c15b234d96025eb1a2b","source":"clob_market_ws"},"received_at":"2026-07-28T03:07:17.443151Z","record_id":"096f6ee5b631a36941f8fd69bdd97cbe7bd359de3a8016a7ba924ce2b89c09e3","schema_fingerprint":"4aa3821a28b0b7c2400bc59aba4bcc0a76e971dadd19610d3ad38c768e124dc7","schema_version":"edge-lab-recorder.raw.v1","sequence":null,"source":"clob_market_ws"}
{"event_at":"2026-07-28T03:07:13.512000Z","event_fingerprint":"a2b042efca1b24e919c7e0604ea5c2c79151588ed7ab56bc52ae07f7cb42e583","payload":{"connection_id":"a6b55582af5f430fb37ad02bf0922475","event_at":"2026-07-28T03:07:13.512000Z","event_type":"price_change","frame_hash":"d9d56d6e696674f9c3dee8b211194b1b58e05299cb7a3f281258025c74655c54","frame_index":0,"kind":"data","monotonic_ns":310020478032625,"payload":{"event_type":"price_change","market":"0x779291bef19b6709f61e9764a954aafe9ffae488d50ae674aabdcb4f248006d5","price_changes":[{"asset_id":"8761897749749422724209054078244794145777693856614463256546737399611489089783","best_ask":"0.65","best_bid":"0.64","hash":"02f605705f60768bf9855f5e374fc52da361362a","price":"0.57","side":"BUY","size":"235"},{"asset_id":"14965588658799411272385430903075831224615961675357217884735713260981483529984","best_ask":"0.36","best_bid":"0.35","hash":"62efbdc0aea9c9edeb751166fc2cd7b7d8a6a9a8","price":"0.43","side":"SELL","size":"235"}],"timestamp":"1785208033512"},"payload_hash":"2aa4433dd6bd9a9322a06b658e38c7091fe15cfb46a31f705e64071dea62a3a3","raw_frame":"{\"market\":\"0x779291bef19b6709f61e9764a954aafe9ffae488d50ae674aabdcb4f248006d5\", \"price_changes\":[{\"asset_id\":\"8761897749749422724209054078244794145777693856614463256546737399611489089783\", \"price\":\"0.57\", \"size\":\"235\", \"side\":\"BUY\", \"hash\":\"02f605705f60768bf9855f5e374fc52da361362a\", \"best_bid\":\"0.64\", \"best_ask\":\"0.65\"}, {\"asset_id\":\"14965588658799411272385430903075831224615961675357217884735713260981483529984\", \"price\":\"0.43\", \"size\":\"235\", \"side\":\"SELL\", \"hash\":\"62efbdc0aea9c9edeb751166fc2cd7b7d8a6a9a8\", \"best_bid\":\"0.35\", \"best_ask\":\"0.36\"}], \"timestamp\":\"1785208033512\", \"event_type\":\"price_change\"}","received_at":"2026-07-28T03:07:17.446134Z","schema_version":"clob-market-ws.price_change.v1","sequence":null,"server_hash":null,"server_timestamp":"1785208033512","session_id":"3e519d9098404c15b234d96025eb1a2b","source":"clob_market_ws"},"received_at":"2026-07-28T03:07:17.446134Z","record_id":"fd414cb76509f08e5e268f772adaf3c241f96ca2f8f04619c43773f57b3ddb9c","schema_fingerprint":"4aa3821a28b0b7c2400bc59aba4bcc0a76e971dadd19610d3ad38c768e124dc7","schema_version":"edge-lab-recorder.raw.v1","sequence":null,"source":"clob_market_ws"}
{"event_at":"2026-07-28T03:07:13.513000Z","event_fingerprint":"1a960317e945da87681957977eda8a1096f093431831a917c794675f6c48f6bf","payload":{"connection_id":"a6b55582af5f430fb37ad02bf0922475","event_at":"2026-07-28T03:07:13.513000Z","event_type":"price_change","frame_hash":"f7ca3eba820d8523e26417c393ad6e38bf8ad4c75f0bc6d8f4b80eb891f105d0","frame_index":0,"kind":"data","monotonic_ns":310020481015541,"payload":{"event_type":"price_change","market":"0x779291bef19b6709f61e9764a954aafe9ffae488d50ae674aabdcb4f248006d5","price_changes":[{"asset_id":"8761897749749422724209054078244794145777693856614463256546737399611489089783","best_ask":"0.65","best_bid":"0.64","hash":"88f0d0eb52a2bac725df00542f3dd2d37ca96102","price":"0.57","side":"BUY","size":"265"},{"asset_id":"14965588658799411272385430903075831224615961675357217884735713260981483529984","best_ask":"0.36","best_bid":"0.35","hash":"aa3548b095ed661b8dc92cd2f17d0cb7ccbbee39","price":"0.43","side":"SELL","size":"265"}],"timestamp":"1785208033513"},"payload_hash":"5096c8cd870304be30942b184487a768fb7917525b5f9632fe306c8deb90494c","raw_frame":"{\"market\":\"0x779291bef19b6709f61e9764a954aafe9ffae488d50ae674aabdcb4f248006d5\", \"price_changes\":[{\"asset_id\":\"8761897749749422724209054078244794145777693856614463256546737399611489089783\", \"price\":\"0.57\", \"size\":\"265\", \"side\":\"BUY\", \"hash\":\"88f0d0eb52a2bac725df00542f3dd2d37ca96102\", \"best_bid\":\"0.64\", \"best_ask\":\"0.65\"}, {\"asset_id\":\"14965588658799411272385430903075831224615961675357217884735713260981483529984\", \"price\":\"0.43\", \"size\":\"265\", \"side\":\"SELL\", \"hash\":\"aa3548b095ed661b8dc92cd2f17d0cb7ccbbee39\", \"best_bid\":\"0.35\", \"best_ask\":\"0.36\"}], \"timestamp\":\"1785208033513\", \"event_type\":\"price_change\"}","received_at":"2026-07-28T03:07:17.449117Z","schema_version":"clob-market-ws.price_change.v1","sequence":null,"server_hash":null,"server_timestamp":"1785208033513","session_id":"3e519d9098404c15b234d96025eb1a2b","source":"clob_market_ws"},"received_at":"2026-07-28T03:07:17.449117Z","record_id":"a6236e541fce152730b5b5655da5319c0a5347e85ec4feb1e7130eef22247cbc","schema_fingerprint":"4aa3821a28b0b7c2400bc59aba4bcc0a76e971dadd19610d3ad38c768e124dc7","schema_version":"edge-lab-recorder.raw.v1","sequence":null,"source":"clob_market_ws"}
{"event_at":"2026-07-28T03:07:13.521000Z","event_fingerprint":"6e873fd7a7f6eae0b53804b123916a5fff9d29f02d81e0ba63962f33da1e2caf","payload":{"connection_id":"a6b55582af5f430fb37ad02bf0922475","event_at":"2026-07-28T03:07:13.521000Z","event_type":"price_change","frame_hash":"f19dc7dbe8c6c655cfa3e7980c034de9e1654caea6a9f1b90f40cd1d52dde1e7","frame_index":0,"kind":"data","monotonic_ns":310020484049541,"payload":{"event_type":"price_change","market":"0x779291bef19b6709f61e9764a954aafe9ffae488d50ae674aabdcb4f248006d5","price_changes":[{"asset_id":"14965588658799411272385430903075831224615961675357217884735713260981483529984","best_ask":"0.36","best_bid":"0.35","hash":"9f4ff91ff5fa8d70b54af08421c325fb6679c4a5","price":"0.34","side":"BUY","size":"44.2"},{"asset_id":"8761897749749422724209054078244794145777693856614463256546737399611489089783","best_ask":"0.65","best_bid":"0.64","hash":"990e1ca1fa805848ecf212a6b2b3b0361df66a1d","price":"0.66","side":"SELL","size":"44.2"}],"timestamp":"1785208033521"},"payload_hash":"acc45227cb43f878a4d4023cc6efa3de657840342cef7a30a4e8503501474e9f","raw_frame":"{\"market\":\"0x779291bef19b6709f61e9764a954aafe9ffae488d50ae674aabdcb4f248006d5\", \"price_changes\":[{\"asset_id\":\"14965588658799411272385430903075831224615961675357217884735713260981483529984\", \"price\":\"0.34\", \"size\":\"44.2\", \"side\":\"BUY\", \"hash\":\"9f4ff91ff5fa8d70b54af08421c325fb6679c4a5\", \"best_bid\":\"0.35\", \"best_ask\":\"0.36\"}, {\"asset_id\":\"8761897749749422724209054078244794145777693856614463256546737399611489089783\", \"price\":\"0.66\", \"size\":\"44.2\", \"side\":\"SELL\", \"hash\":\"990e1ca1fa805848ecf212a6b2b3b0361df66a1d\", \"best_bid\":\"0.64\", \"best_ask\":\"0.65\"}], \"timestamp\":\"1785208033521\", \"event_type\":\"price_change\"}","received_at":"2026-07-28T03:07:17.452150Z","schema_version":"clob-market-ws.price_change.v1","sequence":null,"server_hash":null,"server_timestamp":"1785208033521","session_id":"3e519d9098404c15b234d96025eb1a2b","source":"clob_market_ws"},"received_at":"2026-07-28T03:07:17.452150Z","record_id":"3668166e848b778d2713f93dcd8895a99cfba38d325af7052a00b0edab2c22d1","schema_fingerprint":"4aa3821a28b0b7c2400bc59aba4bcc0a76e971dadd19610d3ad38c768e124dc7","schema_version":"edge-lab-recorder.raw.v1","sequence":null,"source":"clob_market_ws"}
{"event_at":"2026-07-28T03:07:13.522000Z","event_fingerprint":"725e94bdaa18f1b55440101e0a7404695c9bf107565a99cc1caef4c58da75dac","payload":{"connection_id":"a6b55582af5f430fb37ad02bf0922475","event_at":"2026-07-28T03:07:13.522000Z","event_type":"price_change","frame_hash":"91d245f89d18b075764e0b7ee2e72fa1858819e94d146ea88992b125fe80621d","frame_index":0,"kind":"data","monotonic_ns":310020487115291,"payload":{"event_type":"price_change","market":"0x779291bef19b6709f61e9764a954aafe9ffae488d50ae674aabdcb4f248006d5","price_changes":[{"asset_id":"14965588658799411272385430903075831224615961675357217884735713260981483529984","best_ask":"0.36","best_bid":"0.35","hash":"346b584023ccd96ac655579a41e326b515b6b6dd","price":"0.33","side":"BUY","size":"77.6"},{"asset_id":"8761897749749422724209054078244794145777693856614463256546737399611489089783","best_ask":"0.65","best_bid":"0.64","hash":"1aebb34b50c21f0cf5ba78f5d9e76829406bd6d2","price":"0.67","side":"SELL","size":"77.6"}],"timestamp":"1785208033522"},"payload_hash":"e4b8a9e2308d69c3e5a45ff22b19dee1020d1142e149365f1211600db14ddb68","raw_frame":"{\"market\":\"0x779291bef19b6709f61e9764a954aafe9ffae488d50ae674aabdcb4f248006d5\", \"price_changes\":[{\"asset_id\":\"14965588658799411272385430903075831224615961675357217884735713260981483529984\", \"price\":\"0.33\", \"size\":\"77.6\", \"side\":\"BUY\", \"hash\":\"346b584023ccd96ac655579a41e326b515b6b6dd\", \"best_bid\":\"0.35\", \"best_ask\":\"0.36\"}, {\"asset_id\":\"8761897749749422724209054078244794145777693856614463256546737399611489089783\", \"price\":\"0.67\", \"size\":\"77.6\", \"side\":\"SELL\", \"hash\":\"1aebb34b50c21f0cf5ba78f5d9e76829406bd6d2\", \"best_bid\":\"0.64\", \"best_ask\":\"0.65\"}], \"timestamp\":\"1785208033522\", \"event_type\":\"price_change\"}","received_at":"2026-07-28T03:07:17.455216Z","schema_version":"clob-market-ws.price_change.v1","sequence":null,"server_hash":null,"server_timestamp":"1785208033522","session_id":"3e519d9098404c15b234d96025eb1a2b","source":"clob_market_ws"},"received_at":"2026-07-28T03:07:17.455216Z","record_id":"2414f0854fba4cab3f7b6c3c3ed7c83a973b346ce6e4ebfcb2f9a9772a131d72","schema_fingerprint":"4aa3821a28b0b7c2400bc59aba4bcc0a76e971dadd19610d3ad38c768e124dc7","schema_version":"edge-lab-recorder.raw.v1","sequence":null,"source":"clob_market_ws"}
{"event_at":"2026-07-28T03:07:13.529000Z","event_fingerprint":"5db1f83b81e4a54f2d933b9a52d235c02b4f646bb5431e8b131f1382a5fc26bb","payload":{"connection_id":"a6b55582af5f430fb37ad02bf0922475","event_at":"2026-07-28T03:07:13.529000Z","event_type":"price_change","frame_hash":"932e73101a9e332ea8f92be4cc0febb024e2a234a972649436c1b898bcd3d7aa","frame_index":0,"kind":"data","monotonic_ns":310020490291333,"payload":{"event_type":"price_change","market":"0x779291bef19b6709f61e9764a954aafe9ffae488d50ae674aabdcb4f248006d5","price_changes":[{"asset_id":"14965588658799411272385430903075831224615961675357217884735713260981483529984","best_ask":"0.36","best_bid":"0.35","hash":"eec1f22192bae0478a55b68989c517b38e5b6c58","price":"0.24","side":"BUY","size":"125"},{"asset_id":"8761897749749422724209054078244794145777693856614463256546737399611489089783","best_ask":"0.65","best_bid":"0.64","hash":"3b88aab0cfa40bd8cdc10f8304987b33bbd67347","price":"0.76","side":"SELL","size":"125"}],"timestamp":"1785208033529"},"payload_hash":"c03d1ad8d1a6663abf80c2b6e49a89416a24995400f90b6cf9c1566899ace740","raw_frame":"{\"market\":\"0x779291bef19b6709f61e9764a954aafe9ffae488d50ae674aabdcb4f248006d5\", \"price_changes\":[{\"asset_id\":\"14965588658799411272385430903075831224615961675357217884735713260981483529984\", \"price\":\"0.24\", \"size\":\"125\", \"side\":\"BUY\", \"hash\":\"eec1f22192bae0478a55b68989c517b38e5b6c58\", \"best_bid\":\"0.35\", \"best_ask\":\"0.36\"}, {\"asset_id\":\"8761897749749422724209054078244794145777693856614463256546737399611489089783\", \"price\":\"0.76\", \"size\":\"125\", \"side\":\"SELL\", \"hash\":\"3b88aab0cfa40bd8cdc10f8304987b33bbd67347\", \"best_bid\":\"0.64\", \"best_ask\":\"0.65\"}], \"timestamp\":\"1785208033529\", \"event_type\":\"price_change\"}","received_at":"2026-07-28T03:07:17.458392Z","schema_version":"clob-market-ws.price_change.v1","sequence":null,"server_hash":null,"server_timestamp":"1785208033529","session_id":"3e519d9098404c15b234d96025eb1a2b","source":"clob_market_ws"},"received_at":"2026-07-28T03:07:17.458392Z","record_id":"cb0914cb74a6a82659514df7435574ee4ec92c26362643c5c5db789b96525b78","schema_fingerprint":"4aa3821a28b0b7c2400bc59aba4bcc0a76e971dadd19610d3ad38c768e124dc7","schema_version":"edge-lab-recorder.raw.v1","sequence":null,"source":"clob_market_ws"}
{"event_at":"2026-07-28T03:07:13.529000Z","event_fingerprint":"afdae79ab0e6a23cf724ea4e20618ae4c5bc1f24e735b6e77aea348345c9c3c5","payload":{"connection_id":"a6b55582af5f430fb37ad02bf0922475","event_at":"2026-07-28T03:07:13.529000Z","event_type":"price_change","frame_hash":"c4868835910521ac5e922ab18f5eb85794698e6fdb4a9c132b9f45a9cc862dcc","frame_index":0,"kind":"data","monotonic_ns":310020493248791,"payload":{"event_type":"price_change","market":"0x779291bef19b6709f61e9764a954aafe9ffae488d50ae674aabdcb4f248006d5","price_changes":[{"asset_id":"8761897749749422724209054078244794145777693856614463256546737399611489089783","best_ask":"0.65","best_bid":"0.64","hash":"e94636dba82a8d7708a744331dc7932de2f696c2","price":"0.01","side":"BUY","size":"5608.02"},{"asset_id":"14965588658799411272385430903075831224615961675357217884735713260981483529984","best_ask":"0.36","best_bid":"0.35","hash":"fc8c9463426f953f4e11e7031fdd09dd809b6c93","price":"0.99","side":"SELL","size":"5608.02"}],"timestamp":"1785208033529"},"payload_hash":"e88323f9b68f047f821fe92113b5d6c4786817202018751309e3215ce8952c5a","raw_frame":"{\"market\":\"0x779291bef19b6709f61e9764a954aafe9ffae488d50ae674aabdcb4f248006d5\", \"price_changes\":[{\"asset_id\":\"8761897749749422724209054078244794145777693856614463256546737399611489089783\", \"price\":\"0.01\", \"size\":\"5608.02\", \"side\":\"BUY\", \"hash\":\"e94636dba82a8d7708a744331dc7932de2f696c2\", \"best_bid\":\"0.64\", \"best_ask\":\"0.65\"}, {\"asset_id\":\"14965588658799411272385430903075831224615961675357217884735713260981483529984\", \"price\":\"0.99\", \"size\":\"5608.02\", \"side\":\"SELL\", \"hash\":\"fc8c9463426f953f4e11e7031fdd09dd809b6c93\", \"best_bid\":\"0.35\", \"best_ask\":\"0.36\"}], \"timestamp\":\"1785208033529\", \"event_type\":\"price_change\"}","received_at":"2026-07-28T03:07:17.461350Z","schema_version":"clob-market-ws.price_change.v1","sequence":null,"server_hash":null,"server_timestamp":"1785208033529","session_id":"3e519d9098404c15b234d96025eb1a2b","source":"clob_market_ws"},"received_at":"2026-07-28T03:07:17.461350Z","record_id":"3005f1551026239c4dd03051b46b7e498228fb1996331a6c41486fa466fd6147","schema_fingerprint":"4aa3821a28b0b7c2400bc59aba4bcc0a76e971dadd19610d3ad38c768e124dc7","schema_version":"edge-lab-recorder.raw.v1","sequence":null,"source":"clob_market_ws"}
{"event_at":"2026-07-28T03:07:13.531000Z","event_fingerprint":"71a671a24dbbc27b67c492a9eb806c3de2c91c8aa8d8e2b526d7a3c43b858424","payload":{"connection_id":"a6b55582af5f430fb37ad02bf0922475","event_at":"2026-07-28T03:07:13.531000Z","event_type":"price_change","frame_hash":"907f4bfcb00cd866402ea456488c635d8250d6635743a766ee489dc98e4fe853","frame_index":0,"kind":"data","monotonic_ns":310020496175375,"payload":{"event_type":"price_change","market":"0x779291bef19b6709f61e9764a954aafe9ffae488d50ae674aabdcb4f248006d5","price_changes":[{"asset_id":"8761897749749422724209054078244794145777693856614463256546737399611489089783","best_ask":"0.65","best_bid":"0.64","hash":"fbe4c6fec46177918393d42364821407762600a4","price":"0.67","side":"SELL","size":"52.6"},{"asset_id":"14965588658799411272385430903075831224615961675357217884735713260981483529984","best_ask":"0.36","best_bid":"0.35","hash":"6df4b1440aa0ed85dc908a0ddd42d6ed4578e9b7","price":"0.33","side":"BUY","size":"52.6"}],"timestamp":"1785208033531"},"payload_hash":"2143d46ded5810bce981a800fcf3e260c550fc755cc6571a4f7ab5f3328857d1","raw_frame":"{\"market\":\"0x779291bef19b6709f61e9764a954aafe9ffae488d50ae674aabdcb4f248006d5\", \"price_changes\":[{\"asset_id\":\"8761897749749422724209054078244794145777693856614463256546737399611489089783\", \"price\":\"0.67\", \"size\":\"52.6\", \"side\":\"SELL\", \"hash\":\"fbe4c6fec46177918393d42364821407762600a4\", \"best_bid\":\"0.64\", \"best_ask\":\"0.65\"}, {\"asset_id\":\"14965588658799411272385430903075831224615961675357217884735713260981483529984\", \"price\":\"0.33\", \"size\":\"52.6\", \"side\":\"BUY\", \"hash\":\"6df4b1440aa0ed85dc908a0ddd42d6ed4578e9b7\", \"best_bid\":\"0.35\", \"best_ask\":\"0.36\"}], \"timestamp\":\"1785208033531\", \"event_type\":\"price_change\"}","received_at":"2026-07-28T03:07:17.464277Z","schema_version":"clob-market-ws.price_change.v1","sequence":null,"server_hash":null,"server_timestamp":"1785208033531","session_id":"3e519d9098404c15b234d96025eb1a2b","source":"clob_market_ws"},"received_at":"2026-07-28T03:07:17.464277Z","record_id":"90bab7bbbeed3edb1cd9ff7299b9d4a2fdf141bf14c9acc6c8ce853c339e6ca4","schema_fingerprint":"4aa3821a28b0b7c2400bc59aba4bcc0a76e971dadd19610d3ad38c768e124dc7","schema_version":"edge-lab-recorder.raw.v1","sequence":null,"source":"clob_market_ws"}
{"event_at":"2026-07-28T03:07:13.533000Z","event_fingerprint":"06aa252e0e4528893dee155e0d5398e32a394042d8a488efd82fd9be3a08d18f","payload":{"connection_id":"a6b55582af5f430fb37ad02bf0922475","event_at":"2026-07-28T03:07:13.533000Z","event_type":"price_change","frame_hash":"7aef21049312a4e51034b52f9cd2822d79281ef061ad21d629a05df85efee456","frame_index":0,"kind":"data","monotonic_ns":310020499191000,"payload":{"event_type":"price_change","market":"0x779291bef19b6709f61e9764a954aafe9ffae488d50ae674aabdcb4f248006d5","price_changes":[{"asset_id":"14965588658799411272385430903075831224615961675357217884735713260981483529984","best_ask":"0.36","best_bid":"0.35","hash":"63f85ac584613193242a51e0f999cd7b49ee5c63","price":"0.25","side":"BUY","size":"190"},{"asset_id":"8761897749749422724209054078244794145777693856614463256546737399611489089783","best_ask":"0.65","best_bid":"0.64","hash":"2c9b69f0bcfa39a9e67970bc834b0aa5611cb50b","price":"0.75","side":"SELL","size":"190"}],"timestamp":"1785208033533"},"payload_hash":"8409c0ad8ee9fbd623cc08bed2a2ca53762a55b7fa4aa6abd10cbf571bfd2b81","raw_frame":"{\"market\":\"0x779291bef19b6709f61e9764a954aafe9ffae488d50ae674aabdcb4f248006d5\", \"price_changes\":[{\"asset_id\":\"14965588658799411272385430903075831224615961675357217884735713260981483529984\", \"price\":\"0.25\", \"size\":\"190\", \"side\":\"BUY\", \"hash\":\"63f85ac584613193242a51e0f999cd7b49ee5c63\", \"best_bid\":\"0.35\", \"best_ask\":\"0.36\"}, {\"asset_id\":\"8761897749749422724209054078244794145777693856614463256546737399611489089783\", \"price\":\"0.75\", \"size\":\"190\", \"side\":\"SELL\", \"hash\":\"2c9b69f0bcfa39a9e67970bc834b0aa5611cb50b\", \"best_bid\":\"0.64\", \"best_ask\":\"0.65\"}], \"timestamp\":\"1785208033533\", \"event_type\":\"price_change\"}","received_at":"2026-07-28T03:07:17.467293Z","schema_version":"clob-market-ws.price_change.v1","sequence":null,"server_hash":null,"server_timestamp":"1785208033533","session_id":"3e519d9098404c15b234d96025eb1a2b","source":"clob_market_ws"},"received_at":"2026-07-28T03:07:17.467293Z","record_id":"ac51155c87ea098021c3bf7f34b9ca4168e2b214519192113bee2f34de853585","schema_fingerprint":"4aa3821a28b0b7c2400bc59aba4bcc0a76e971dadd19610d3ad38c768e124dc7","schema_version":"edge-lab-recorder.raw.v1","sequence":null,"source":"clob_market_ws"}
{"event_at":"2026-07-28T03:07:13.540000Z","event_fingerprint":"0858ba7084a1614431282cdd658289375c9574697e7bf6c32f16274db833ceff","payload":{"connection_id":"a6b55582af5f430fb37ad02bf0922475","event_at":"2026-07-28T03:07:13.540000Z","event_type":"price_change","frame_hash":"28b3467b9bb2e6cb0eeb2a22afcc7c33c90c095089bb48ee01974066ba7546e7","frame_index":0,"kind":"data","monotonic_ns":310020502141791,"payload":{"event_type":"price_change","market":"0x779291bef19b6709f61e9764a954aafe9ffae488d50ae674aabdcb4f248006d5","price_changes":[{"asset_id":"14965588658799411272385430903075831224615961675357217884735713260981483529984","best_ask":"0.36","best_bid":"0.35","hash":"e950a7430cfbca7fb19caa9378d8df224bcc4f91","price":"0.1","side":"BUY","size":"376.29"},{"asset_id":"8761897749749422724209054078244794145777693856614463256546737399611489089783","best_ask":"0.65","best_bid":"0.64","hash":"8f4020499af18ceacd0d2a55d8c23bd6500a4d64","price":"0.9","side":"SELL","size":"376.29"}],"timestamp":"1785208033540"},"payload_hash":"0addcddf113f291a36613021f08aea1f9eb2303732be67ba0388f76659053db4","raw_frame":"{\"market\":\"0x779291bef19b6709f61e9764a954aafe9ffae488d50ae674aabdcb4f248006d5\", \"price_changes\":[{\"asset_id\":\"14965588658799411272385430903075831224615961675357217884735713260981483529984\", \"price\":\"0.1\", \"size\":\"376.29\", \"side\":\"BUY\", \"hash\":\"e950a7430cfbca7fb19caa9378d8df224bcc4f91\", \"best_bid\":\"0.35\", \"best_ask\":\"0.36\"}, {\"asset_id\":\"8761897749749422724209054078244794145777693856614463256546737399611489089783\", \"price\":\"0.9\", \"size\":\"376.29\", \"side\":\"SELL\", \"hash\":\"8f4020499af18ceacd0d2a55d8c23bd6500a4d64\", \"best_bid\":\"0.64\", \"best_ask\":\"0.65\"}], \"timestamp\":\"1785208033540\", \"event_type\":\"price_change\"}","received_at":"2026-07-28T03:07:17.470243Z","schema_version":"clob-market-ws.price_change.v1","sequence":null,"server_hash":null,"server_timestamp":"1785208033540","session_id":"3e519d9098404c15b234d96025eb1a2b","source":"clob_market_ws"},"received_at":"2026-07-28T03:07:17.470243Z","record_id":"e5d0e8cf541bd447431eb0dbaf5f1ce350470e615991164d97d42156eb64e6bd","schema_fingerprint":"4aa3821a28b0b7c2400bc59aba4bcc0a76e971dadd19610d3ad38c768e124dc7","schema_version":"edge-lab-recorder.raw.v1","sequence":null,"source":"clob_market_ws"}
{"event_at":"2026-07-28T03:07:13.540000Z","event_fingerprint":"50e80555995bfe86a6fe73eed157e73a7d6429f570ba865a6ef765431ec5c3b7","payload":{"connection_id":"a6b55582af5f430fb37ad02bf0922475","event_at":"2026-07-28T03:07:13.540000Z","event_type":"price_change","frame_hash":"6349a7bdae534bec677e329a7b875a1516ee620b2269fd06d1f665d6d54d3bbb","frame_index":0,"kind":"data","monotonic_ns":310020505095208,"payload":{"event_type":"price_change","market":"0x779291bef19b6709f61e9764a954aafe9ffae488d50ae674aabdcb4f248006d5","price_changes":[{"asset_id":"14965588658799411272385430903075831224615961675357217884735713260981483529984","best_ask":"0.36","best_bid":"0.35","hash":"e950a7430cfbca7fb19caa9378d8df224bcc4f91","price":"0.14","side":"BUY","size":"222.9"},{"asset_id":"8761897749749422724209054078244794145777693856614463256546737399611489089783","best_ask":"0.65","best_bid":"0.64","hash":"8f4020499af18ceacd0d2a55d8c23bd6500a4d64","price":"0.86","side":"SELL","size":"222.9"}],"timestamp":"1785208033540"},"payload_hash":"00f3dd72a1729d7ea9b5547ad0191c12c19523d5e1d29f786ab1117d67909ca8","raw_frame":"{\"market\":\"0x779291bef19b6709f61e9764a954aafe9ffae488d50ae674aabdcb4f248006d5\", \"price_changes\":[{\"asset_id\":\"14965588658799411272385430903075831224615961675357217884735713260981483529984\", \"price\":\"0.14\", \"size\":\"222.9\", \"side\":\"BUY\", \"hash\":\"e950a7430cfbca7fb19caa9378d8df224bcc4f91\", \"best_bid\":\"0.35\", \"best_ask\":\"0.36\"}, {\"asset_id\":\"8761897749749422724209054078244794145777693856614463256546737399611489089783\", \"price\":\"0.86\", \"size\":\"222.9\", \"side\":\"SELL\", \"hash\":\"8f4020499af18ceacd0d2a55d8c23bd6500a4d64\", \"best_bid\":\"0.64\", \"best_ask\":\"0.65\"}], \"timestamp\":\"1785208033540\", \"event_type\":\"price_change\"}","received_at":"2026-07-28T03:07:17.473197Z","schema_version":"clob-market-ws.price_change.v1","sequence":null,"server_hash":null,"server_timestamp":"1785208033540","session_id":"3e519d9098404c15b234d96025eb1a2b","source":"clob_market_ws"},"received_at":"2026-07-28T03:07:17.473197Z","record_id":"6349750534214c6619e95e00afd09a7cf9957748ea40e34dbbcb1c7381691efd","schema_fingerprint":"4aa3821a28b0b7c2400bc59aba4bcc0a76e971dadd19610d3ad38c768e124dc7","schema_version":"edge-lab-recorder.raw.v1","sequence":null,"source":"clob_market_ws"}
{"event_at":"2026-07-28T03:07:13.540000Z","event_fingerprint":"92d54ed7e9437c576d4d754d5cb698c6a0d4b3da2129a5ea960d76b7c5cb4910","payload":{"connection_id":"a6b55582af5f430fb37ad02bf0922475","event_at":"2026-07-28T03:07:13.540000Z","event_type":"price_change","frame_hash":"aaf8120176cc6a1aaba79beadbb663f468e0c8dd9e794fed959be3534a0f51b5","frame_index":0,"kind":"data","monotonic_ns":310020508029833,"payload":{"event_type":"price_change","market":"0x779291bef19b6709f61e9764a954aafe9ffae488d50ae674aabdcb4f248006d5","price_changes":[{"asset_id":"14965588658799411272385430903075831224615961675357217884735713260981483529984","best_ask":"0.36","best_bid":"0.35","hash":"e950a7430cfbca7fb19caa9378d8df224bcc4f91","price":"0.13","side":"BUY","size":"461.5"},{"asset_id":"8761897749749422724209054078244794145777693856614463256546737399611489089783","best_ask":"0.65","best_bid":"0.64","hash":"8f4020499af18ceacd0d2a55d8c23bd6500a4d64","price":"0.87","side":"SELL","size":"461.5"}],"timestamp":"1785208033540"},"payload_hash":"e70d9a7ccc98c9d41ad5b78df1aacf73238a7478358b6c6f480d43239ab39e0e","raw_frame":"{\"market\":\"0x779291bef19b6709f61e9764a954aafe9ffae488d50ae674aabdcb4f248006d5\", \"price_changes\":[{\"asset_id\":\"14965588658799411272385430903075831224615961675357217884735713260981483529984\", \"price\":\"0.13\", \"size\":\"461.5\", \"side\":\"BUY\", \"hash\":\"e950a7430cfbca7fb19caa9378d8df224bcc4f91\", \"best_bid\":\"0.35\", \"best_ask\":\"0.36\"}, {\"asset_id\":\"8761897749749422724209054078244794145777693856614463256546737399611489089783\", \"price\":\"0.87\", \"size\":\"461.5\", \"side\":\"SELL\", \"hash\":\"8f4020499af18ceacd0d2a55d8c23bd6500a4d64\", \"best_bid\":\"0.64\", \"best_ask\":\"0.65\"}], \"timestamp\":\"1785208033540\", \"event_type\":\"price_change\"}","received_at":"2026-07-28T03:07:17.476132Z","schema_version":"clob-market-ws.price_change.v1","sequence":null,"server_hash":null,"server_timestamp":"1785208033540","session_id":"3e519d9098404c15b234d96025eb1a2b","source":"clob_market_ws"},"received_at":"2026-07-28T03:07:17.476132Z","record_id":"b5ea5bd71af4d074baa39f68bd5e92c7531d415c7a49ff70c7f22334a6973de9","schema_fingerprint":"4aa3821a28b0b7c2400bc59aba4bcc0a76e971dadd19610d3ad38c768e124dc7","schema_version":"edge-lab-recorder.raw.v1","sequence":null,"source":"clob_market_ws"}
{"event_at":"2026-07-28T03:07:13.540000Z","event_fingerprint":"a34a7185a474b315831c8b5fbd78a0275057381660a31826664a4cbcfdb05383","payload":{"connection_id":"a6b55582af5f430fb37ad02bf0922475","event_at":"2026-07-28T03:07:13.540000Z","event_type":"price_change","frame_hash":"5dc1af7937bd5d7ea001eb0d609b43723adc922600d991061ff58c807d60c373","frame_index":0,"kind":"data","monotonic_ns":310020510998166,"payload":{"event_type":"price_change","market":"0x779291bef19b6709f61e9764a954aafe9ffae488d50ae674aabdcb4f248006d5","price_changes":[{"asset_id":"14965588658799411272385430903075831224615961675357217884735713260981483529984","best_ask":"0.36","best_bid":"0.35","hash":"e950a7430cfbca7fb19caa9378d8df224bcc4f91","price":"0.12","side":"BUY","size":"264.4"},{"asset_id":"8761897749749422724209054078244794145777693856614463256546737399611489089783","best_ask":"0.65","best_bid":"0.64","hash":"8f4020499af18ceacd0d2a55d8c23bd6500a4d64","price":"0.88","side":"SELL","size":"264.4"}],"timestamp":"1785208033540"},"payload_hash":"14c463d5e05d015095fdeceb88966cf7eb8bb4c8f5d60ddcbd708d68d247c1a5","raw_frame":"{\"market\":\"0x779291bef19b6709f61e9764a954aafe9ffae488d50ae674aabdcb4f248006d5\", \"price_changes\":[{\"asset_id\":\"14965588658799411272385430903075831224615961675357217884735713260981483529984\", \"price\":\"0.12\", \"size\":\"264.4\", \"side\":\"BUY\", \"hash\":\"e950a7430cfbca7fb19caa9378d8df224bcc4f91\", \"best_bid\":\"0.35\", \"best_ask\":\"0.36\"}, {\"asset_id\":\"8761897749749422724209054078244794145777693856614463256546737399611489089783\", \"price\":\"0.88\", \"size\":\"264.4\", \"side\":\"SELL\", \"hash\":\"8f4020499af18ceacd0d2a55d8c23bd6500a4d64\", \"best_bid\":\"0.64\", \"best_ask\":\"0.65\"}], \"timestamp\":\"1785208033540\", \"event_type\":\"price_change\"}","received_at":"2026-07-28T03:07:17.479099Z","schema_version":"clob-market-ws.price_change.v1","sequence":null,"server_hash":null,"server_timestamp":"1785208033540","session_id":"3e519d9098404c15b234d96025eb1a2b","source":"clob_market_ws"},"received_at":"2026-07-28T03:07:17.479099Z","record_id":"2baef29186ab645c840d668bde4db65dc02355881b9f04e21a6eb4adf8aa13e3","schema_fingerprint":"4aa3821a28b0b7c2400bc59aba4bcc0a76e971dadd19610d3ad38c768e124dc7","schema_version":"edge-lab-recorder.raw.v1","sequence":null,"source":"clob_market_ws"}
{"event_at":"2026-07-28T03:07:13.540000Z","event_fingerprint":"4124f2f82f43580966769a3d7ccabc5f48c9725e9dcca02bfd03cc99cb914e19","payload":{"connection_id":"a6b55582af5f430fb37ad02bf0922475","event_at":"2026-07-28T03:07:13.540000Z","event_type":"price_change","frame_hash":"aa03eeb8e099308543ffa6ebbef96c711c653c20adb70b54dc42867a3c83a123","frame_index":0,"kind":"data","monotonic_ns":310020514931375,"payload":{"event_type":"price_change","market":"0x779291bef19b6709f61e9764a954aafe9ffae488d50ae674aabdcb4f248006d5","price_changes":[{"asset_id":"14965588658799411272385430903075831224615961675357217884735713260981483529984","best_ask":"0.36","best_bid":"0.35","hash":"e950a7430cfbca7fb19caa9378d8df224bcc4f91","price":"0.11","side":"BUY","size":"276.6"},{"asset_id":"8761897749749422724209054078244794145777693856614463256546737399611489089783","best_ask":"0.65","best_bid":"0.64","hash":"8f4020499af18ceacd0d2a55d8c23bd6500a4d64","price":"0.89","side":"SELL","size":"276.6"}],"timestamp":"1785208033540"},"payload_hash":"b4ca4ed5fd2db404025509f7138ffbb5126adc37298b972819cc6c08482b502d","raw_frame":"{\"market\":\"0x779291bef19b6709f61e9764a954aafe9ffae488d50ae674aabdcb4f248006d5\", \"price_changes\":[{\"asset_id\":\"14965588658799411272385430903075831224615961675357217884735713260981483529984\", \"price\":\"0.11\", \"size\":\"276.6\", \"side\":\"BUY\", \"hash\":\"e950a7430cfbca7fb19caa9378d8df224bcc4f91\", \"best_bid\":\"0.35\", \"best_ask\":\"0.36\"}, {\"asset_id\":\"8761897749749422724209054078244794145777693856614463256546737399611489089783\", \"price\":\"0.89\", \"size\":\"276.6\", \"side\":\"SELL\", \"hash\":\"8f4020499af18ceacd0d2a55d8c23bd6500a4d64\", \"best_bid\":\"0.64\", \"best_ask\":\"0.65\"}], \"timestamp\":\"1785208033540\", \"event_type\":\"price_change\"}","received_at":"2026-07-28T03:07:17.483033Z","schema_version":"clob-market-ws.price_change.v1","sequence":null,"server_hash":null,"server_timestamp":"1785208033540","session_id":"3e519d9098404c15b234d96025eb1a2b","source":"clob_market_ws"},"received_at":"2026-07-28T03:07:17.483033Z","record_id":"06afd5dc710c0752eca1ba1218d6213378ca8847afd19b10387e20254e112de9","schema_fingerprint":"4aa3821a28b0b7c2400bc59aba4bcc0a76e971dadd19610d3ad38c768e124dc7","schema_version":"edge-lab-recorder.raw.v1","sequence":null,"source":"clob_market_ws"}
{"event_at":"2026-07-28T03:07:13.554000Z","event_fingerprint":"d31378d527e8200fc27760e90b8e62802bc32a2f2ac59075ce076772998d3b62","payload":{"connection_id":"a6b55582af5f430fb37ad02bf0922475","event_at":"2026-07-28T03:07:13.554000Z","event_type":"price_change","frame_hash":"8081ca230f361b9dae4788bb99143df215b5dc605ef89b136ca83be74bb7fc8f","frame_index":0,"kind":"data","monotonic_ns":310020533148000,"payload":{"event_type":"price_change","market":"0x779291bef19b6709f61e9764a954aafe9ffae488d50ae674aabdcb4f248006d5","price_changes":[{"asset_id":"14965588658799411272385430903075831224615961675357217884735713260981483529984","best_ask":"0.36","best_bid":"0.35","hash":"9a44b0c12f2ef1c751875b082190ce1509b244d7","price":"0.36","side":"SELL","size":"38.74"},{"asset_id":"8761897749749422724209054078244794145777693856614463256546737399611489089783","best_ask":"0.65","best_bid":"0.64","hash":"547988da007864c2929d16f537fbc1f5e8627c63","price":"0.64","side":"BUY","size":"38.74"}],"timestamp":"1785208033554"},"payload_hash":"954608162693573ad798fbc808bf9e2b9fef350bbabd746746cb13da533674a4","raw_frame":"{\"market\":\"0x779291bef19b6709f61e9764a954aafe9ffae488d50ae674aabdcb4f248006d5\", \"price_changes\":[{\"asset_id\":\"14965588658799411272385430903075831224615961675357217884735713260981483529984\", \"price\":\"0.36\", \"size\":\"38.74\", \"side\":\"SELL\", \"hash\":\"9a44b0c12f2ef1c751875b082190ce1509b244d7\", \"best_bid\":\"0.35\", \"best_ask\":\"0.36\"}, {\"asset_id\":\"8761897749749422724209054078244794145777693856614463256546737399611489089783\", \"price\":\"0.64\", \"size\":\"38.74\", \"side\":\"BUY\", \"hash\":\"547988da007864c2929d16f537fbc1f5e8627c63\", \"best_bid\":\"0.64\", \"best_ask\":\"0.65\"}], \"timestamp\":\"1785208033554\", \"event_type\":\"price_change\"}","received_at":"2026-07-28T03:07:17.501245Z","schema_version":"clob-market-ws.price_change.v1","sequence":null,"server_hash":null,"server_timestamp":"1785208033554","session_id":"3e519d9098404c15b234d96025eb1a2b","source":"clob_market_ws"},"received_at":"2026-07-28T03:07:17.501245Z","record_id":"6d04a4fd3af1e86d8d97249cf80abde6d45e450a3782d1d1aa0398e7cc383224","schema_fingerprint":"4aa3821a28b0b7c2400bc59aba4bcc0a76e971dadd19610d3ad38c768e124dc7","schema_version":"edge-lab-recorder.raw.v1","sequence":null,"source":"clob_market_ws"}
{"event_at":"2026-07-28T03:07:13.560000Z","event_fingerprint":"0897627e02531901d6f3b6e448bd1b96c75030fdedc638307cdbfae74c3e64e1","payload":{"connection_id":"a6b55582af5f430fb37ad02bf0922475","event_at":"2026-07-28T03:07:13.560000Z","event_type":"price_change","frame_hash":"df23b957dc7f58c2ac4a281c69506edc430698b88e75a68e8718c34f38722ba2","frame_index":0,"kind":"data","monotonic_ns":310020536257583,"payload":{"event_type":"price_change","market":"0x779291bef19b6709f61e9764a954aafe9ffae488d50ae674aabdcb4f248006d5","price_changes":[{"asset_id":"14965588658799411272385430903075831224615961675357217884735713260981483529984","best_ask":"0.36","best_bid":"0.35","hash":"9f9d9abf35f1d846cb1d7f26d0ff0e4133abc0b3","price":"0.24","side":"BUY","size":"225"},{"asset_id":"8761897749749422724209054078244794145777693856614463256546737399611489089783","best_ask":"0.65","best_bid":"0.64","hash":"8bad4008411288ba44aee95a568972112e65b4f8","price":"0.76","side":"SELL","size":"225"}],"timestamp":"1785208033560"},"payload_hash":"372bf55e8c3dc37776da6430237e76e7d175d9d0d78919769428f99a99f5c93a","raw_frame":"{\"market\":\"0x779291bef19b6709f61e9764a954aafe9ffae488d50ae674aabdcb4f248006d5\", \"price_changes\":[{\"asset_id\":\"14965588658799411272385430903075831224615961675357217884735713260981483529984\", \"price\":\"0.24\", \"size\":\"225\", \"side\":\"BUY\", \"hash\":\"9f9d9abf35f1d846cb1d7f26d0ff0e4133abc0b3\", \"best_bid\":\"0.35\", \"best_ask\":\"0.36\"}, {\"asset_id\":\"8761897749749422724209054078244794145777693856614463256546737399611489089783\", \"price\":\"0.76\", \"size\":\"225\", \"side\":\"SELL\", \"hash\":\"8bad4008411288ba44aee95a568972112e65b4f8\", \"best_bid\":\"0.64\", \"best_ask\":\"0.65\"}], \"timestamp\":\"1785208033560\", \"event_type\":\"price_change\"}","received_at":"2026-07-28T03:07:17.504358Z","schema_version":"clob-market-ws.price_change.v1","sequence":null,"server_hash":null,"server_timestamp":"1785208033560","session_id":"3e519d9098404c15b234d96025eb1a2b","source":"clob_market_ws"},"received_at":"2026-07-28T03:07:17.504358Z","record_id":"23435a8e7dc08169c16fd03e31f54181e96665143979a5bbcef35c2059ae6d2e","schema_fingerprint":"4aa3821a28b0b7c2400bc59aba4bcc0a76e971dadd19610d3ad38c768e124dc7","schema_version":"edge-lab-recorder.raw.v1","sequence":null,"source":"clob_market_ws"}
{"event_at":"2026-07-28T03:07:13.602000Z","event_fingerprint":"45b3c7f1d5e023afd45dfdb895f0315296262253be896ef244cb85c9d2e3f25e","payload":{"connection_id":"a6b55582af5f430fb37ad02bf0922475","event_at":"2026-07-28T03:07:13.602000Z","event_type":"price_change","frame_hash":"3d0c269ccc09e2891218aea80d8e71dd7644a61076846960ca24e742700dcc35","frame_index":0,"kind":"data","monotonic_ns":310020539307250,"payload":{"event_type":"price_change","market":"0x779291bef19b6709f61e9764a954aafe9ffae488d50ae674aabdcb4f248006d5","price_changes":[{"asset_id":"14965588658799411272385430903075831224615961675357217884735713260981483529984","best_ask":"0.36","best_bid":"0.35","hash":"f49fe7956f80a3ba1d43f20f1a6286f87f43b1e3","price":"0.3","side":"BUY","size":"103.2"},{"asset_id":"8761897749749422724209054078244794145777693856614463256546737399611489089783","best_ask":"0.65","best_bid":"0.64","hash":"2ec424d19af6d27c7d30bbbb124397491a561fdb","price":"0.7","side":"SELL","size":"103.2"}],"timestamp":"1785208033602"},"payload_hash":"496002df1a999a36c1bdb17c81152c346cb83a981643c6a7301653cad1186b89","raw_frame":"{\"market\":\"0x779291bef19b6709f61e9764a954aafe9ffae488d50ae674aabdcb4f248006d5\", \"price_changes\":[{\"asset_id\":\"14965588658799411272385430903075831224615961675357217884735713260981483529984\", \"price\":\"0.3\", \"size\":\"103.2\", \"side\":\"BUY\", \"hash\":\"f49fe7956f80a3ba1d43f20f1a6286f87f43b1e3\", \"best_bid\":\"0.35\", \"best_ask\":\"0.36\"}, {\"asset_id\":\"8761897749749422724209054078244794145777693856614463256546737399611489089783\", \"price\":\"0.7\", \"size\":\"103.2\", \"side\":\"SELL\", \"hash\":\"2ec424d19af6d27c7d30bbbb124397491a561fdb\", \"best_bid\":\"0.64\", \"best_ask\":\"0.65\"}], \"timestamp\":\"1785208033602\", \"event_type\":\"price_change\"}","received_at":"2026-07-28T03:07:17.507408Z","schema_version":"clob-market-ws.price_change.v1","sequence":null,"server_hash":null,"server_timestamp":"1785208033602","session_id":"3e519d9098404c15b234d96025eb1a2b","source":"clob_market_ws"},"received_at":"2026-07-28T03:07:17.507408Z","record_id":"69e99d13e6dfa2b59716166340df8cfb961295a71fd35f7356719d263a0a9ea5","schema_fingerprint":"4aa3821a28b0b7c2400bc59aba4bcc0a76e971dadd19610d3ad38c768e124dc7","schema_version":"edge-lab-recorder.raw.v1","sequence":null,"source":"clob_market_ws"}
{"event_at":"2026-07-28T03:07:13.626000Z","event_fingerprint":"28b6836b9ef219cbb48461b1d8affb5c83dee389fe0f3d078a21dee4f6d0d478","payload":{"connection_id":"a6b55582af5f430fb37ad02bf0922475","event_at":"2026-07-28T03:07:13.626000Z","event_type":"price_change","frame_hash":"1b856f4991fa4cdf2ea321fa6069a1ef979caf0d13bed4e9af75c619255ab8b3","frame_index":0,"kind":"data","monotonic_ns":310020542409333,"payload":{"event_type":"price_change","market":"0x779291bef19b6709f61e9764a954aafe9ffae488d50ae674aabdcb4f248006d5","price_changes":[{"asset_id":"8761897749749422724209054078244794145777693856614463256546737399611489089783","best_ask":"0.65","best_bid":"0.64","hash":"74aff8e06a883b9b011d18184cbd8586c4887739","price":"0.43","side":"BUY","size":"202.22"},{"asset_id":"14965588658799411272385430903075831224615961675357217884735713260981483529984","best_ask":"0.36","best_bid":"0.35","hash":"582351153796bc58736af0a1ae31e4ca38b3c7f8","price":"0.57","side":"SELL","size":"202.22"}],"timestamp":"1785208033626"},"payload_hash":"abed98139541a3881a1bd6005675c0b3840fd718e34fd149fe0a19f1c90f51ab","raw_frame":"{\"market\":\"0x779291bef19b6709f61e9764a954aafe9ffae488d50ae674aabdcb4f248006d5\", \"price_changes\":[{\"asset_id\":\"8761897749749422724209054078244794145777693856614463256546737399611489089783\", \"price\":\"0.43\", \"size\":\"202.22\", \"side\":\"BUY\", \"hash\":\"74aff8e06a883b9b011d18184cbd8586c4887739\", \"best_bid\":\"0.64\", \"best_ask\":\"0.65\"}, {\"asset_id\":\"14965588658799411272385430903075831224615961675357217884735713260981483529984\", \"price\":\"0.57\", \"size\":\"202.22\", \"side\":\"SELL\", \"hash\":\"582351153796bc58736af0a1ae31e4ca38b3c7f8\", \"best_bid\":\"0.35\", \"best_ask\":\"0.36\"}], \"timestamp\":\"1785208033626\", \"event_type\":\"price_change\"}","received_at":"2026-07-28T03:07:17.510509Z","schema_version":"clob-market-ws.price_change.v1","sequence":null,"server_hash":null,"server_timestamp":"1785208033626","session_id":"3e519d9098404c15b234d96025eb1a2b","source":"clob_market_ws"},"received_at":"2026-07-28T03:07:17.510509Z","record_id":"c8a0e5e1efb9821d1d9956150d49ec222d5f440f6bd671173e28ae26f03d8237","schema_fingerprint":"4aa3821a28b0b7c2400bc59aba4bcc0a76e971dadd19610d3ad38c768e124dc7","schema_version":"edge-lab-recorder.raw.v1","sequence":null,"source":"clob_market_ws"}
{"event_at":"2026-07-28T03:07:13.626000Z","event_fingerprint":"695ae8a8280a682856b304da22c3554d93e465179b66c6247436d68895c1f2a6","payload":{"connection_id":"a6b55582af5f430fb37ad02bf0922475","event_at":"2026-07-28T03:07:13.626000Z","event_type":"price_change","frame_hash":"b802200cdf9e0dc7161aea84a21d76971b2155716414c3309b8ef489eb352885","frame_index":0,"kind":"data","monotonic_ns":310020545354750,"payload":{"event_type":"price_change","market":"0x779291bef19b6709f61e9764a954aafe9ffae488d50ae674aabdcb4f248006d5","price_changes":[{"asset_id":"14965588658799411272385430903075831224615961675357217884735713260981483529984","best_ask":"0.36","best_bid":"0.35","hash":"7d5e170debf90efd1f7d07bbc8cecd1a50151064","price":"0.34","side":"BUY","size":"38.4"},{"asset_id":"8761897749749422724209054078244794145777693856614463256546737399611489089783","best_ask":"0.65","best_bid":"0.64","hash":"c0059b1da5cdbf0ca2009cb1c6c4dd7e0892a033","price":"0.66","side":"SELL","size":"38.4"}],"timestamp":"1785208033626"},"payload_hash":"16f2087a121180c4c52a894090288741263e1fc3c0b09aad95ac7773b97a4c9b","raw_frame":"{\"market\":\"0x779291bef19b6709f61e9764a954aafe9ffae488d50ae674aabdcb4f248006d5\", \"price_changes\":[{\"asset_id\":\"14965588658799411272385430903075831224615961675357217884735713260981483529984\", \"price\":\"0.34\", \"size\":\"38.4\", \"side\":\"BUY\", \"hash\":\"7d5e170debf90efd1f7d07bbc8cecd1a50151064\", \"best_bid\":\"0.35\", \"best_ask\":\"0.36\"}, {\"asset_id\":\"8761897749749422724209054078244794145777693856614463256546737399611489089783\", \"price\":\"0.66\", \"size\":\"38.4\", \"side\":\"SELL\", \"hash\":\"c0059b1da5cdbf0ca2009cb1c6c4dd7e0892a033\", \"best_bid\":\"0.64\", \"best_ask\":\"0.65\"}], \"timestamp\":\"1785208033626\", \"event_type\":\"price_change\"}","received_at":"2026-07-28T03:07:17.513456Z","schema_version":"clob-market-ws.price_change.v1","sequence":null,"server_hash":null,"server_timestamp":"1785208033626","session_id":"3e519d9098404c15b234d96025eb1a2b","source":"clob_market_ws"},"received_at":"2026-07-28T03:07:17.513456Z","record_id":"1c93089a3c49ec2a4d4b7d9c9a45a332d00e284805964ccf12d85e662623adb1","schema_fingerprint":"4aa3821a28b0b7c2400bc59aba4bcc0a76e971dadd19610d3ad38c768e124dc7","schema_version":"edge-lab-recorder.raw.v1","sequence":null,"source":"clob_market_ws"}
{"event_at":"2026-07-28T03:07:13.626000Z","event_fingerprint":"e53721737399c618d72011d2effa35616e5b8ab19262b278425df5d0e14408e9","payload":{"connection_id":"a6b55582af5f430fb37ad02bf0922475","event_at":"2026-07-28T03:07:13.626000Z","event_type":"price_change","frame_hash":"e57674a2f2638c9303c6fe43cc8ee6e53baf347abc964da6fbf4dcae49bce205","frame_index":0,"kind":"data","monotonic_ns":310020547976458,"payload":{"event_type":"price_change","market":"0x779291bef19b6709f61e9764a954aafe9ffae488d50ae674aabdcb4f248006d5","price_changes":[{"asset_id":"14965588658799411272385430903075831224615961675357217884735713260981483529984","best_ask":"0.36","best_bid":"0.35","hash":"7d5e170debf90efd1f7d07bbc8cecd1a50151064","price":"0.35","side":"BUY","size":"35.8"},{"asset_id":"8761897749749422724209054078244794145777693856614463256546737399611489089783","best_ask":"0.65","best_bid":"0.64","hash":"c0059b1da5cdbf0ca2009cb1c6c4dd7e0892a033","price":"0.65","side":"SELL","size":"35.8"}],"timestamp":"1785208033626"},"payload_hash":"b5a091b1fa228b7bc3c31bc769b95783f04080760c91af3365b2de6b42ae918b","raw_frame":"{\"market\":\"0x779291bef19b6709f61e9764a954aafe9ffae488d50ae674aabdcb4f248006d5\", \"price_changes\":[{\"asset_id\":\"14965588658799411272385430903075831224615961675357217884735713260981483529984\", \"price\":\"0.35\", \"size\":\"35.8\", \"side\":\"BUY\", \"hash\":\"7d5e170debf90efd1f7d07bbc8cecd1a50151064\", \"best_bid\":\"0.35\", \"best_ask\":\"0.36\"}, {\"asset_id\":\"8761897749749422724209054078244794145777693856614463256546737399611489089783\", \"price\":\"0.65\", \"size\":\"35.8\", \"side\":\"SELL\", \"hash\":\"c0059b1da5cdbf0ca2009cb1c6c4dd7e0892a033\", \"best_bid\":\"0.64\", \"best_ask\":\"0.65\"}], \"timestamp\":\"1785208033626\", \"event_type\":\"price_change\"}","received_at":"2026-07-28T03:07:17.516078Z","schema_version":"clob-market-ws.price_change.v1","sequence":null,"server_hash":null,"server_timestamp":"1785208033626","session_id":"3e519d9098404c15b234d96025eb1a2b","source":"clob_market_ws"},"received_at":"2026-07-28T03:07:17.516078Z","record_id":"87eb9c90bf81caf6c01265950c7bd1e69a92e09960d638504901cd1bb3042a71","schema_fingerprint":"4aa3821a28b0b7c2400bc59aba4bcc0a76e971dadd19610d3ad38c768e124dc7","schema_version":"edge-lab-recorder.raw.v1","sequence":null,"source":"clob_market_ws"}
{"event_at":"2026-07-28T03:07:13.628000Z","event_fingerprint":"ee6ee8bb39f072711407d93f4c80e063b05bb7a5dc124f3b56a2627301b51c99","payload":{"connection_id":"a6b55582af5f430fb37ad02bf0922475","event_at":"2026-07-28T03:07:13.628000Z","event_type":"price_change","frame_hash":"802f5a8d277865192bc43439b468feb2396eb760b73156195281bc28533445db","frame_index":0,"kind":"data","monotonic_ns":310020550283583,"payload":{"event_type":"price_change","market":"0x779291bef19b6709f61e9764a954aafe9ffae488d50ae674aabdcb4f248006d5","price_changes":[{"asset_id":"8761897749749422724209054078244794145777693856614463256546737399611489089783","best_ask":"0.65","best_bid":"0.64","hash":"b54fa5fd2a385e65793082072668d701f6b715bf","price":"0.66","side":"SELL","size":"63.4"},{"asset_id":"14965588658799411272385430903075831224615961675357217884735713260981483529984","best_ask":"0.36","best_bid":"0.35","hash":"cc9a99b26077ca23b9d624d23df669ed69617465","price":"0.34","side":"BUY","size":"63.4"}],"timestamp":"1785208033628"},"payload_hash":"c259ebb4a49d63554b2bf66993ff957d9a3fc9864b270ddab4d0181f5ccc741e","raw_frame":"{\"market\":\"0x779291bef19b6709f61e9764a954aafe9ffae488d50ae674aabdcb4f248006d5\", \"price_changes\":[{\"asset_id\":\"8761897749749422724209054078244794145777693856614463256546737399611489089783\", \"price\":\"0.66\", \"size\":\"63.4\", \"side\":\"SELL\", \"hash\":\"b54fa5fd2a385e65793082072668d701f6b715bf\", \"best_bid\":\"0.64\", \"best_ask\":\"0.65\"}, {\"asset_id\":\"14965588658799411272385430903075831224615961675357217884735713260981483529984\", \"price\":\"0.34\", \"size\":\"63.4\", \"side\":\"BUY\", \"hash\":\"cc9a99b26077ca23b9d624d23df669ed69617465\", \"best_bid\":\"0.35\", \"best_ask\":\"0.36\"}], \"timestamp\":\"1785208033628\", \"event_type\":\"price_change\"}","received_at":"2026-07-28T03:07:17.518387Z","schema_version":"clob-market-ws.price_change.v1","sequence":null,"server_hash":null,"server_timestamp":"1785208033628","session_id":"3e519d9098404c15b234d96025eb1a2b","source":"clob_market_ws"},"received_at":"2026-07-28T03:07:17.518387Z","record_id":"fbb14eeeb835312e527d1d313272705a56491a5750955b80ab4e8c10f497f602","schema_fingerprint":"4aa3821a28b0b7c2400bc59aba4bcc0a76e971dadd19610d3ad38c768e124dc7","schema_version":"edge-lab-recorder.raw.v1","sequence":null,"source":"clob_market_ws"}
{"event_at":"2026-07-28T03:07:13.630000Z","event_fingerprint":"3f11f5a7a934f34234c36ac81a0b641fadb31f0fa8610d0afe70ccf38679b56a","payload":{"connection_id":"a6b55582af5f430fb37ad02bf0922475","event_at":"2026-07-28T03:07:13.630000Z","event_type":"price_change","frame_hash":"049b37c284509203afab541846581880622184a545088e5ad135c9b8712ede32","frame_index":0,"kind":"data","monotonic_ns":310020551746625,"payload":{"event_type":"price_change","market":"0x779291bef19b6709f61e9764a954aafe9ffae488d50ae674aabdcb4f248006d5","price_changes":[{"asset_id":"14965588658799411272385430903075831224615961675357217884735713260981483529984","best_ask":"0.36","best_bid":"0.35","hash":"52b3e1088a13cde1c1af6f2e2cf5d0878c86e486","price":"0.36","side":"SELL","size":"33.74"},{"asset_id":"8761897749749422724209054078244794145777693856614463256546737399611489089783","best_ask":"0.65","best_bid":"0.64","hash":"4c72376042510c12d7b973c2d78ca28224533304","price":"0.64","side":"BUY","size":"33.74"}],"timestamp":"1785208033630"},"payload_hash":"574578853157ace15fba62a0260f30bcd75a64e9e2c41ea5a5de2579b206e1a5","raw_frame":"{\"market\":\"0x779291bef19b6709f61e9764a954aafe9ffae488d50ae674aabdcb4f248006d5\", \"price_changes\":[{\"asset_id\":\"14965588658799411272385430903075831224615961675357217884735713260981483529984\", \"price\":\"0.36\", \"size\":\"33.74\", \"side\":\"SELL\", \"hash\":\"52b3e1088a13cde1c1af6f2e2cf5d0878c86e486\", \"best_bid\":\"0.35\", \"best_ask\":\"0.36\"}, {\"asset_id\":\"8761897749749422724209054078244794145777693856614463256546737399611489089783\", \"price\":\"0.64\", \"size\":\"33.74\", \"side\":\"BUY\", \"hash\":\"4c72376042510c12d7b973c2d78ca28224533304\", \"best_bid\":\"0.64\", \"best_ask\":\"0.65\"}], \"timestamp\":\"1785208033630\", \"event_type\":\"price_change\"}","received_at":"2026-07-28T03:07:17.519851Z","schema_version":"clob-market-ws.price_change.v1","sequence":null,"server_hash":null,"server_timestamp":"1785208033630","session_id":"3e519d9098404c15b234d96025eb1a2b","source":"clob_market_ws"},"received_at":"2026-07-28T03:07:17.519851Z","record_id":"4edd6b4a6f1447bfd85217e2cdbe22581c66a25bfaa48cf9946edf6fd3eba2ee","schema_fingerprint":"4aa3821a28b0b7c2400bc59aba4bcc0a76e971dadd19610d3ad38c768e124dc7","schema_version":"edge-lab-recorder.raw.v1","sequence":null,"source":"clob_market_ws"}
{"event_at":"2026-07-28T03:07:13.634000Z","event_fingerprint":"a8eb2798e69d6b2ecaef30f78b62391a59ec7d9aa896ccfccfe29bc464928c9d","payload":{"connection_id":"a6b55582af5f430fb37ad02bf0922475","event_at":"2026-07-28T03:07:13.634000Z","event_type":"price_change","frame_hash":"ce73f7ce569ef4b930a307dbaeee6b698a76794b1c36b8c62b1593ed9a3a2ab3","frame_index":0,"kind":"data","monotonic_ns":310020553729583,"payload":{"event_type":"price_change","market":"0x779291bef19b6709f61e9764a954aafe9ffae488d50ae674aabdcb4f248006d5","price_changes":[{"asset_id":"14965588658799411272385430903075831224615961675357217884735713260981483529984","best_ask":"0.36","best_bid":"0.35","hash":"47c2fa071f3f88d78da8488b168caccf7f2c804d","price":"0.34","side":"BUY","size":"88.4"},{"asset_id":"8761897749749422724209054078244794145777693856614463256546737399611489089783","best_ask":"0.65","best_bid":"0.64","hash":"e52154b50854ef98be7a70c90aaf7d7634fa7260","price":"0.66","side":"SELL","size":"88.4"}],"timestamp":"1785208033634"},"payload_hash":"0292e563682767882da2faf032877e555396fb5b16f789a286a3829b00ecc004","raw_frame":"{\"market\":\"0x779291bef19b6709f61e9764a954aafe9ffae488d50ae674aabdcb4f248006d5\", \"price_changes\":[{\"asset_id\":\"14965588658799411272385430903075831224615961675357217884735713260981483529984\", \"price\":\"0.34\", \"size\":\"88.4\", \"side\":\"BUY\", \"hash\":\"47c2fa071f3f88d78da8488b168caccf7f2c804d\", \"best_bid\":\"0.35\", \"best_ask\":\"0.36\"}, {\"asset_id\":\"8761897749749422724209054078244794145777693856614463256546737399611489089783\", \"price\":\"0.66\", \"size\":\"88.4\", \"side\":\"SELL\", \"hash\":\"e52154b50854ef98be7a70c90aaf7d7634fa7260\", \"best_bid\":\"0.64\", \"best_ask\":\"0.65\"}], \"timestamp\":\"1785208033634\", \"event_type\":\"price_change\"}","received_at":"2026-07-28T03:07:17.521833Z","schema_version":"clob-market-ws.price_change.v1","sequence":null,"server_hash":null,"server_timestamp":"1785208033634","session_id":"3e519d9098404c15b234d96025eb1a2b","source":"clob_market_ws"},"received_at":"2026-07-28T03:07:17.521833Z","record_id":"a099215a86d2b6fea1c96ceb8fcd1922450e0411635d809fb6c56b355dac6803","schema_fingerprint":"4aa3821a28b0b7c2400bc59aba4bcc0a76e971dadd19610d3ad38c768e124dc7","schema_version":"edge-lab-recorder.raw.v1","sequence":null,"source":"clob_market_ws"}
{"event_at":"2026-07-28T03:07:13.634000Z","event_fingerprint":"611020e9a4577f4c68597c59a8bc5594593977d46f031333e2622b8f98a43cdd","payload":{"connection_id":"a6b55582af5f430fb37ad02bf0922475","event_at":"2026-07-28T03:07:13.634000Z","event_type":"price_change","frame_hash":"e4c3c6bd999c3e97e191752b3fd128779af6945543c6a81d6fc6340e94cb9081","frame_index":0,"kind":"data","monotonic_ns":310020556081666,"payload":{"event_type":"price_change","market":"0x779291bef19b6709f61e9764a954aafe9ffae488d50ae674aabdcb4f248006d5","price_changes":[{"asset_id":"14965588658799411272385430903075831224615961675357217884735713260981483529984","best_ask":"0.36","best_bid":"0.35","hash":"34222386a8519092126ac8f3f0fc7b11aeedefb1","price":"0.33","side":"BUY","size":"58.58"},{"asset_id":"8761897749749422724209054078244794145777693856614463256546737399611489089783","best_ask":"0.65","best_bid":"0.64","hash":"07f639f27eca22b5d91c6e5be74b2361c44293bb","price":"0.67","side":"SELL","size":"58.58"}],"timestamp":"1785208033634"},"payload_hash":"6c4103616486fee23a1aa938cccc659b0ba4a68bc18de46a5d2e02e55af214c6","raw_frame":"{\"market\":\"0x779291bef19b6709f61e9764a954aafe9ffae488d50ae674aabdcb4f248006d5\", \"price_changes\":[{\"asset_id\":\"14965588658799411272385430903075831224615961675357217884735713260981483529984\", \"price\":\"0.33\", \"size\":\"58.58\", \"side\":\"BUY\", \"hash\":\"34222386a8519092126ac8f3f0fc7b11aeedefb1\", \"best_bid\":\"0.35\", \"best_ask\":\"0.36\"}, {\"asset_id\":\"8761897749749422724209054078244794145777693856614463256546737399611489089783\", \"price\":\"0.67\", \"size\":\"58.58\", \"side\":\"SELL\", \"hash\":\"07f639f27eca22b5d91c6e5be74b2361c44293bb\", \"best_bid\":\"0.64\", \"best_ask\":\"0.65\"}], \"timestamp\":\"1785208033634\", \"event_type\":\"price_change\"}","received_at":"2026-07-28T03:07:17.524185Z","schema_version":"clob-market-ws.price_change.v1","sequence":null,"server_hash":null,"server_timestamp":"1785208033634","session_id":"3e519d9098404c15b234d96025eb1a2b","source":"clob_market_ws"},"received_at":"2026-07-28T03:07:17.524185Z","record_id":"714ecd7c06502b4cdd9633f6a77aac20a870e168a5af118a0b14b26027722619","schema_fingerprint":"4aa3821a28b0b7c2400bc59aba4bcc0a76e971dadd19610d3ad38c768e124dc7","schema_version":"edge-lab-recorder.raw.v1","sequence":null,"source":"clob_market_ws"}
{"event_at":"2026-07-28T03:07:13.660000Z","event_fingerprint":"5fe4153afa34cf17acdaac7d162e7b6875c11ff70ea6915ddef558a9ffcd8efd","payload":{"connection_id":"a6b55582af5f430fb37ad02bf0922475","event_at":"2026-07-28T03:07:13.660000Z","event_type":"price_change","frame_hash":"3276a20305ed8c75a0b55fa27c35f8001b902c83b6730df697e604e81e292824","frame_index":0,"kind":"data","monotonic_ns":310020558012375,"payload":{"event_type":"price_change","market":"0x779291bef19b6709f61e9764a954aafe9ffae488d50ae674aabdcb4f248006d5","price_changes":[{"asset_id":"14965588658799411272385430903075831224615961675357217884735713260981483529984","best_ask":"0.36","best_bid":"0.35","hash":"a85b3901dc530e55ce54c0cf00f4b06d53e0b24a","price":"0.25","side":"BUY","size":"220"},{"asset_id":"8761897749749422724209054078244794145777693856614463256546737399611489089783","best_ask":"0.65","best_bid":"0.64","hash":"5c6d0fab2a6434b6227e1bde1d5d345e6ec969a8","price":"0.75","side":"SELL","size":"220"}],"timestamp":"1785208033660"},"payload_hash":"6e7bc9ba472555dbb84c13de570027db8c4af7fc4fa1ed10ea36dcadd605ad9f","raw_frame":"{\"market\":\"0x779291bef19b6709f61e9764a954aafe9ffae488d50ae674aabdcb4f248006d5\", \"price_changes\":[{\"asset_id\":\"14965588658799411272385430903075831224615961675357217884735713260981483529984\", \"price\":\"0.25\", \"size\":\"220\", \"side\":\"BUY\", \"hash\":\"a85b3901dc530e55ce54c0cf00f4b06d53e0b24a\", \"best_bid\":\"0.35\", \"best_ask\":\"0.36\"}, {\"asset_id\":\"8761897749749422724209054078244794145777693856614463256546737399611489089783\", \"price\":\"0.75\", \"size\":\"220\", \"side\":\"SELL\", \"hash\":\"5c6d0fab2a6434b6227e1bde1d5d345e6ec969a8\", \"best_bid\":\"0.64\", \"best_ask\":\"0.65\"}], \"timestamp\":\"1785208033660\", \"event_type\":\"price_change\"}","received_at":"2026-07-28T03:07:17.526114Z","schema_version":"clob-market-ws.price_change.v1","sequence":null,"server_hash":null,"server_timestamp":"1785208033660","session_id":"3e519d9098404c15b234d96025eb1a2b","source":"clob_market_ws"},"received_at":"2026-07-28T03:07:17.526114Z","record_id":"41d74715bc5a4b2279f8e0084cebbd61efe405e2bd817b5e138a83064a59ac7c","schema_fingerprint":"4aa3821a28b0b7c2400bc59aba4bcc0a76e971dadd19610d3ad38c768e124dc7","schema_version":"edge-lab-recorder.raw.v1","sequence":null,"source":"clob_market_ws"}
{"event_at":"2026-07-28T03:07:13.695000Z","event_fingerprint":"34821453da4ec6ed05b587bd7c66715200c5d12b54426073341c37ff6c374c0c","payload":{"connection_id":"a6b55582af5f430fb37ad02bf0922475","event_at":"2026-07-28T03:07:13.695000Z","event_type":"price_change","frame_hash":"de41dd8dd0e893cf803787bfabbc4c365ae571fe187c20ca82486be79359413f","frame_index":0,"kind":"data","monotonic_ns":310020559608375,"payload":{"event_type":"price_change","market":"0x779291bef19b6709f61e9764a954aafe9ffae488d50ae674aabdcb4f248006d5","price_changes":[{"asset_id":"14965588658799411272385430903075831224615961675357217884735713260981483529984","best_ask":"0.36","best_bid":"0.35","hash":"c0f11663ab26ab690cf50027fe43e07bb6013842","price":"0.2","side":"BUY","size":"290.8"},{"asset_id":"8761897749749422724209054078244794145777693856614463256546737399611489089783","best_ask":"0.65","best_bid":"0.64","hash":"f00b6614f16f60b30ccd64124dd495b61087a7d8","price":"0.8","side":"SELL","size":"290.8"}],"timestamp":"1785208033695"},"payload_hash":"a9c33cebf570485becc2a7edf01b6fa0153a80369d62c978f49365a73584c62f","raw_frame":"{\"market\":\"0x779291bef19b6709f61e9764a954aafe9ffae488d50ae674aabdcb4f248006d5\", \"price_changes\":[{\"asset_id\":\"14965588658799411272385430903075831224615961675357217884735713260981483529984\", \"price\":\"0.2\", \"size\":\"290.8\", \"side\":\"BUY\", \"hash\":\"c0f11663ab26ab690cf50027fe43e07bb6013842\", \"best_bid\":\"0.35\", \"best_ask\":\"0.36\"}, {\"asset_id\":\"8761897749749422724209054078244794145777693856614463256546737399611489089783\", \"price\":\"0.8\", \"size\":\"290.8\", \"side\":\"SELL\", \"hash\":\"f00b6614f16f60b30ccd64124dd495b61087a7d8\", \"best_bid\":\"0.64\", \"best_ask\":\"0.65\"}], \"timestamp\":\"1785208033695\", \"event_type\":\"price_change\"}","received_at":"2026-07-28T03:07:17.527713Z","schema_version":"clob-market-ws.price_change.v1","sequence":null,"server_hash":null,"server_timestamp":"1785208033695","session_id":"3e519d9098404c15b234d96025eb1a2b","source":"clob_market_ws"},"received_at":"2026-07-28T03:07:17.527713Z","record_id":"6a87d308a5063e123c0e7029b937bba667939fff6760cfcb892800c11542bb93","schema_fingerprint":"4aa3821a28b0b7c2400bc59aba4bcc0a76e971dadd19610d3ad38c768e124dc7","schema_version":"edge-lab-recorder.raw.v1","sequence":null,"source":"clob_market_ws"}
{"event_at":"2026-07-28T03:07:13.695000Z","event_fingerprint":"2c2ba17e88f36e0a9981c26da930d4cbc5e626bf449ea33d6678d73246fa2dc3","payload":{"connection_id":"a6b55582af5f430fb37ad02bf0922475","event_at":"2026-07-28T03:07:13.695000Z","event_type":"price_change","frame_hash":"2dfdf6f57e91a14fb9ad567f5d0e6a30e71c5d28f04b31b0b594003b7076d8e5","frame_index":0,"kind":"data","monotonic_ns":310020561230041,"payload":{"event_type":"price_change","market":"0x779291bef19b6709f61e9764a954aafe9ffae488d50ae674aabdcb4f248006d5","price_changes":[{"asset_id":"14965588658799411272385430903075831224615961675357217884735713260981483529984","best_ask":"0.36","best_bid":"0.35","hash":"c0f11663ab26ab690cf50027fe43e07bb6013842","price":"0.19","side":"BUY","size":"305.76"},{"asset_id":"8761897749749422724209054078244794145777693856614463256546737399611489089783","best_ask":"0.65","best_bid":"0.64","hash":"f00b6614f16f60b30ccd64124dd495b61087a7d8","price":"0.81","side":"SELL","size":"305.76"}],"timestamp":"1785208033695"},"payload_hash":"4a8749f0b3d7b4150d942bb5640690d8c46137d2e0f9aefcbbd84d8922a06005","raw_frame":"{\"market\":\"0x779291bef19b6709f61e9764a954aafe9ffae488d50ae674aabdcb4f248006d5\", \"price_changes\":[{\"asset_id\":\"14965588658799411272385430903075831224615961675357217884735713260981483529984\", \"price\":\"0.19\", \"size\":\"305.76\", \"side\":\"BUY\", \"hash\":\"c0f11663ab26ab690cf50027fe43e07bb6013842\", \"best_bid\":\"0.35\", \"best_ask\":\"0.36\"}, {\"asset_id\":\"8761897749749422724209054078244794145777693856614463256546737399611489089783\", \"price\":\"0.81\", \"size\":\"305.76\", \"side\":\"SELL\", \"hash\":\"f00b6614f16f60b30ccd64124dd495b61087a7d8\", \"best_bid\":\"0.64\", \"best_ask\":\"0.65\"}], \"timestamp\":\"1785208033695\", \"event_type\":\"price_change\"}","received_at":"2026-07-28T03:07:17.529334Z","schema_version":"clob-market-ws.price_change.v1","sequence":null,"server_hash":null,"server_timestamp":"1785208033695","session_id":"3e519d9098404c15b234d96025eb1a2b","source":"clob_market_ws"},"received_at":"2026-07-28T03:07:17.529334Z","record_id":"0e2c43070e7b5c92a950d5ead748e81fe45c0622011fd5b9b2f8d1484fedb506","schema_fingerprint":"4aa3821a28b0b7c2400bc59aba4bcc0a76e971dadd19610d3ad38c768e124dc7","schema_version":"edge-lab-recorder.raw.v1","sequence":null,"source":"clob_market_ws"}
{"event_at":"2026-07-28T03:07:13.695000Z","event_fingerprint":"9c806b5c7e777a7af0965fcac832778ee756e1db3531392c1fd0fdf33ff09cf5","payload":{"connection_id":"a6b55582af5f430fb37ad02bf0922475","event_at":"2026-07-28T03:07:13.695000Z","event_type":"price_change","frame_hash":"44d94de5c872df27e27470f61fb7a47ae062e35bc2e74e1060c9d4494a326b8d","frame_index":0,"kind":"data","monotonic_ns":310020562739541,"payload":{"event_type":"price_change","market":"0x779291bef19b6709f61e9764a954aafe9ffae488d50ae674aabdcb4f248006d5","price_changes":[{"asset_id":"8761897749749422724209054078244794145777693856614463256546737399611489089783","best_ask":"0.65","best_bid":"0.64","hash":"f00b6614f16f60b30ccd64124dd495b61087a7d8","price":"0.63","side":"BUY","size":"49"},{"asset_id":"14965588658799411272385430903075831224615961675357217884735713260981483529984","best_ask":"0.36","best_bid":"0.35","hash":"c0f11663ab26ab690cf50027fe43e07bb6013842","price":"0.37","side":"SELL","size":"49"}],"timestamp":"1785208033695"},"payload_hash":"5f9a55dd1e39b7061c156cbba543d079ec9de59f7b6bdc0138c97cff14000d30","raw_frame":"{\"market\":\"0x779291bef19b6709f61e9764a954aafe9ffae488d50ae674aabdcb4f248006d5\", \"price_changes\":[{\"asset_id\":\"8761897749749422724209054078244794145777693856614463256546737399611489089783\", \"price\":\"0.63\", \"size\":\"49\", \"side\":\"BUY\", \"hash\":\"f00b6614f16f60b30ccd64124dd495b61087a7d8\", \"best_bid\":\"0.64\", \"best_ask\":\"0.65\"}, {\"asset_id\":\"14965588658799411272385430903075831224615961675357217884735713260981483529984\", \"price\":\"0.37\", \"size\":\"49\", \"side\":\"SELL\", \"hash\":\"c0f11663ab26ab690cf50027fe43e07bb6013842\", \"best_bid\":\"0.35\", \"best_ask\":\"0.36\"}], \"timestamp\":\"1785208033695\", \"event_type\":\"price_change\"}","received_at":"2026-07-28T03:07:17.530844Z","schema_version":"clob-market-ws.price_change.v1","sequence":null,"server_hash":null,"server_timestamp":"1785208033695","session_id":"3e519d9098404c15b234d96025eb1a2b","source":"clob_market_ws"},"received_at":"2026-07-28T03:07:17.530844Z","record_id":"2a74ad105f7b03f15d1ea0dd1aa2e98c88ac412e5375795fc2050c866e74ae3d","schema_fingerprint":"4aa3821a28b0b7c2400bc59aba4bcc0a76e971dadd19610d3ad38c768e124dc7","schema_version":"edge-lab-recorder.raw.v1","sequence":null,"source":"clob_market_ws"}
{"event_at":"2026-07-28T03:07:13.695000Z","event_fingerprint":"0239e7520b387ed09ec786d8ed585afb982960cc86570de84ff45e269444c7c7","payload":{"connection_id":"a6b55582af5f430fb37ad02bf0922475","event_at":"2026-07-28T03:07:13.695000Z","event_type":"price_change","frame_hash":"3c7a8655f10bfbe4b5457825d27b96f9b6d95115991552909aa5f89a5009a52c","frame_index":0,"kind":"data","monotonic_ns":310020566660041,"payload":{"event_type":"price_change","market":"0x779291bef19b6709f61e9764a954aafe9ffae488d50ae674aabdcb4f248006d5","price_changes":[{"asset_id":"8761897749749422724209054078244794145777693856614463256546737399611489089783","best_ask":"0.65","best_bid":"0.64","hash":"f00b6614f16f60b30ccd64124dd495b61087a7d8","price":"0.64","side":"BUY","size":"20.98"},{"asset_id":"14965588658799411272385430903075831224615961675357217884735713260981483529984","best_ask":"0.36","best_bid":"0.35","hash":"c0f11663ab26ab690cf50027fe43e07bb6013842","price":"0.36","side":"SELL","size":"20.98"}],"timestamp":"1785208033695"},"payload_hash":"d8fcb40a9647d26f3d3deac913a5c147b5ec4cd5c8d02fd91c13285ff3d3ce39","raw_frame":"{\"market\":\"0x779291bef19b6709f61e9764a954aafe9ffae488d50ae674aabdcb4f248006d5\", \"price_changes\":[{\"asset_id\":\"8761897749749422724209054078244794145777693856614463256546737399611489089783\", \"price\":\"0.64\", \"size\":\"20.98\", \"side\":\"BUY\", \"hash\":\"f00b6614f16f60b30ccd64124dd495b61087a7d8\", \"best_bid\":\"0.64\", \"best_ask\":\"0.65\"}, {\"asset_id\":\"14965588658799411272385430903075831224615961675357217884735713260981483529984\", \"price\":\"0.36\", \"size\":\"20.98\", \"side\":\"SELL\", \"hash\":\"c0f11663ab26ab690cf50027fe43e07bb6013842\", \"best_bid\":\"0.35\", \"best_ask\":\"0.36\"}], \"timestamp\":\"1785208033695\", \"event_type\":\"price_change\"}","received_at":"2026-07-28T03:07:17.534759Z","schema_version":"clob-market-ws.price_change.v1","sequence":null,"server_hash":null,"server_timestamp":"1785208033695","session_id":"3e519d9098404c15b234d96025eb1a2b","source":"clob_market_ws"},"received_at":"2026-07-28T03:07:17.534759Z","record_id":"451d075468769b690e87106c6a34dddc553b3fac99f3449368345502af160bb8","schema_fingerprint":"4aa3821a28b0b7c2400bc59aba4bcc0a76e971dadd19610d3ad38c768e124dc7","schema_version":"edge-lab-recorder.raw.v1","sequence":null,"source":"clob_market_ws"}
{"event_at":"2026-07-28T03:07:13.703000Z","event_fingerprint":"cbe5c2c9d6990f175ef7cbff5c1f642e3b82376d5975963ee98d35d0fa70211d","payload":{"connection_id":"a6b55582af5f430fb37ad02bf0922475","event_at":"2026-07-28T03:07:13.703000Z","event_type":"price_change","frame_hash":"623e4466ff522767be49110d40a6f19c3c917c482d05e983dfafc46add9a8176","frame_index":0,"kind":"data","monotonic_ns":310020570501375,"payload":{"event_type":"price_change","market":"0x779291bef19b6709f61e9764a954aafe9ffae488d50ae674aabdcb4f248006d5","price_changes":[{"asset_id":"8761897749749422724209054078244794145777693856614463256546737399611489089783","best_ask":"0.65","best_bid":"0.64","hash":"f29cf0a25674d9c65927be898111ef51597a960f","price":"0.04","side":"BUY","size":"593.09"},{"asset_id":"14965588658799411272385430903075831224615961675357217884735713260981483529984","best_ask":"0.36","best_bid":"0.35","hash":"553a793a118aa57c4465264fe4d255d7c40e4e89","price":"0.96","side":"SELL","size":"593.09"}],"timestamp":"1785208033703"},"payload_hash":"2a2dba72ee8d8e6f378431cc53fa5715f463856680878232893932ee7f57c420","raw_frame":"{\"market\":\"0x779291bef19b6709f61e9764a954aafe9ffae488d50ae674aabdcb4f248006d5\", \"price_changes\":[{\"asset_id\":\"8761897749749422724209054078244794145777693856614463256546737399611489089783\", \"price\":\"0.04\", \"size\":\"593.09\", \"side\":\"BUY\", \"hash\":\"f29cf0a25674d9c65927be898111ef51597a960f\", \"best_bid\":\"0.64\", \"best_ask\":\"0.65\"}, {\"asset_id\":\"14965588658799411272385430903075831224615961675357217884735713260981483529984\", \"price\":\"0.96\", \"size\":\"593.09\", \"side\":\"SELL\", \"hash\":\"553a793a118aa57c4465264fe4d255d7c40e4e89\", \"best_bid\":\"0.35\", \"best_ask\":\"0.36\"}], \"timestamp\":\"1785208033703\", \"event_type\":\"price_change\"}","received_at":"2026-07-28T03:07:17.538599Z","schema_version":"clob-market-ws.price_change.v1","sequence":null,"server_hash":null,"server_timestamp":"1785208033703","session_id":"3e519d9098404c15b234d96025eb1a2b","source":"clob_market_ws"},"received_at":"2026-07-28T03:07:17.538599Z","record_id":"6b26487227ec8fe9cfc5994431c4e475726bd4552776637587c7992f0bffb9f8","schema_fingerprint":"4aa3821a28b0b7c2400bc59aba4bcc0a76e971dadd19610d3ad38c768e124dc7","schema_version":"edge-lab-recorder.raw.v1","sequence":null,"source":"clob_market_ws"}
{"event_at":"2026-07-28T03:07:13.708000Z","event_fingerprint":"cd65460d08ffab192de2630a5b9ca61cf83d261b90a50e0107179029a252d1a3","payload":{"connection_id":"a6b55582af5f430fb37ad02bf0922475","event_at":"2026-07-28T03:07:13.708000Z","event_type":"price_change","frame_hash":"44e28d68ae5b727b40c4dafbf85fe36c43d6ad9a5c06b088f88ebb75d82c6e3d","frame_index":0,"kind":"data","monotonic_ns":310020573612500,"payload":{"event_type":"price_change","market":"0x779291bef19b6709f61e9764a954aafe9ffae488d50ae674aabdcb4f248006d5","price_changes":[{"asset_id":"8761897749749422724209054078244794145777693856614463256546737399611489089783","best_ask":"0.65","best_bid":"0.64","hash":"0ec1eff1c4221324f9b5d4482fb3fb40590c5a37","price":"0.62","side":"BUY","size":"42"},{"asset_id":"14965588658799411272385430903075831224615961675357217884735713260981483529984","best_ask":"0.36","best_bid":"0.35","hash":"96d1d5f013e30d38aec9eb3097781bc17cb79f7e","price":"0.38","side":"SELL","size":"42"}],"timestamp":"1785208033708"},"payload_hash":"f4fc7c5c39f66ab3f4e5051c44f9494bbdef4774d8d01a8f844bd6507d490b14","raw_frame":"{\"market\":\"0x779291bef19b6709f61e9764a954aafe9ffae488d50ae674aabdcb4f248006d5\", \"price_changes\":[{\"asset_id\":\"8761897749749422724209054078244794145777693856614463256546737399611489089783\", \"price\":\"0.62\", \"size\":\"42\", \"side\":\"BUY\", \"hash\":\"0ec1eff1c4221324f9b5d4482fb3fb40590c5a37\", \"best_bid\":\"0.64\", \"best_ask\":\"0.65\"}, {\"asset_id\":\"14965588658799411272385430903075831224615961675357217884735713260981483529984\", \"price\":\"0.38\", \"size\":\"42\", \"side\":\"SELL\", \"hash\":\"96d1d5f013e30d38aec9eb3097781bc17cb79f7e\", \"best_bid\":\"0.35\", \"best_ask\":\"0.36\"}], \"timestamp\":\"1785208033708\", \"event_type\":\"price_change\"}","received_at":"2026-07-28T03:07:17.541712Z","schema_version":"clob-market-ws.price_change.v1","sequence":null,"server_hash":null,"server_timestamp":"1785208033708","session_id":"3e519d9098404c15b234d96025eb1a2b","source":"clob_market_ws"},"received_at":"2026-07-28T03:07:17.541712Z","record_id":"ac26a78c5223057d18b7e5f29e59977011ee248c2ccad7d47ecda605adacc346","schema_fingerprint":"4aa3821a28b0b7c2400bc59aba4bcc0a76e971dadd19610d3ad38c768e124dc7","schema_version":"edge-lab-recorder.raw.v1","sequence":null,"source":"clob_market_ws"}
{"event_at":"2026-07-28T03:07:13.721000Z","event_fingerprint":"fa1003a74a3b6c93ada83de27273279a32c1ccc2ca3138d661b46b64ad935146","payload":{"connection_id":"a6b55582af5f430fb37ad02bf0922475","event_at":"2026-07-28T03:07:13.721000Z","event_type":"price_change","frame_hash":"ec1d64a789b1a54552725774f235227e956b409bb2eb780d358ce718d3ba1d35","frame_index":0,"kind":"data","monotonic_ns":310020576631250,"payload":{"event_type":"price_change","market":"0x779291bef19b6709f61e9764a954aafe9ffae488d50ae674aabdcb4f248006d5","price_changes":[{"asset_id":"8761897749749422724209054078244794145777693856614463256546737399611489089783","best_ask":"0.65","best_bid":"0.64","hash":"612d1737fbe4c62e1b87aecbd31e0e5dc7a4a80c","price":"0.01","side":"BUY","size":"5613.02"},{"asset_id":"14965588658799411272385430903075831224615961675357217884735713260981483529984","best_ask":"0.36","best_bid":"0.35","hash":"10d838cef877afb49f31d77b605ff4b6c41df50e","price":"0.99","side":"SELL","size":"5613.02"}],"timestamp":"1785208033721"},"payload_hash":"9edebae555a537538327011806701adbbb3d5a86b5f6c2032a654773b00c9c4d","raw_frame":"{\"market\":\"0x779291bef19b6709f61e9764a954aafe9ffae488d50ae674aabdcb4f248006d5\", \"price_changes\":[{\"asset_id\":\"8761897749749422724209054078244794145777693856614463256546737399611489089783\", \"price\":\"0.01\", \"size\":\"5613.02\", \"side\":\"BUY\", \"hash\":\"612d1737fbe4c62e1b87aecbd31e0e5dc7a4a80c\", \"best_bid\":\"0.64\", \"best_ask\":\"0.65\"}, {\"asset_id\":\"14965588658799411272385430903075831224615961675357217884735713260981483529984\", \"price\":\"0.99\", \"size\":\"5613.02\", \"side\":\"SELL\", \"hash\":\"10d838cef877afb49f31d77b605ff4b6c41df50e\", \"best_bid\":\"0.35\", \"best_ask\":\"0.36\"}], \"timestamp\":\"1785208033721\", \"event_type\":\"price_change\"}","received_at":"2026-07-28T03:07:17.544733Z","schema_version":"clob-market-ws.price_change.v1","sequence":null,"server_hash":null,"server_timestamp":"1785208033721","session_id":"3e519d9098404c15b234d96025eb1a2b","source":"clob_market_ws"},"received_at":"2026-07-28T03:07:17.544733Z","record_id":"b3a8f851fb0e6e10937fbec403a5ac961dc6f49cc415df06424c91e38dc340ce","schema_fingerprint":"4aa3821a28b0b7c2400bc59aba4bcc0a76e971dadd19610d3ad38c768e124dc7","schema_version":"edge-lab-recorder.raw.v1","sequence":null,"source":"clob_market_ws"}
{"event_at":"2026-07-28T03:07:13.728000Z","event_fingerprint":"a676cab5899539a3e3a5da8052e6398f19e0d68e8d633f9aefe5e374d58e2849","payload":{"connection_id":"a6b55582af5f430fb37ad02bf0922475","event_at":"2026-07-28T03:07:13.728000Z","event_type":"price_change","frame_hash":"901b9fdb041b53d2c2f8caaeb302ba63b81e8ecd4965980a4eaa87dc9ea330f3","frame_index":0,"kind":"data","monotonic_ns":310020580715375,"payload":{"event_type":"price_change","market":"0x779291bef19b6709f61e9764a954aafe9ffae488d50ae674aabdcb4f248006d5","price_changes":[{"asset_id":"14965588658799411272385430903075831224615961675357217884735713260981483529984","best_ask":"0.36","best_bid":"0.35","hash":"2ea4efde517b81c358cf6bf1b50c47ed93cb53ad","price":"0.33","side":"BUY","size":"52.6"},{"asset_id":"8761897749749422724209054078244794145777693856614463256546737399611489089783","best_ask":"0.65","best_bid":"0.64","hash":"d3421ac7793052ec2de7c9bc54ba41b7700605cf","price":"0.67","side":"SELL","size":"52.6"}],"timestamp":"1785208033728"},"payload_hash":"29b44eccdb76bdae4d71339eebdd184fae719e5b5b4a4b40ec3f59ad264f5946","raw_frame":"{\"market\":\"0x779291bef19b6709f61e9764a954aafe9ffae488d50ae674aabdcb4f248006d5\", \"price_changes\":[{\"asset_id\":\"14965588658799411272385430903075831224615961675357217884735713260981483529984\", \"price\":\"0.33\", \"size\":\"52.6\", \"side\":\"BUY\", \"hash\":\"2ea4efde517b81c358cf6bf1b50c47ed93cb53ad\", \"best_bid\":\"0.35\", \"best_ask\":\"0.36\"}, {\"asset_id\":\"8761897749749422724209054078244794145777693856614463256546737399611489089783\", \"price\":\"0.67\", \"size\":\"52.6\", \"side\":\"SELL\", \"hash\":\"d3421ac7793052ec2de7c9bc54ba41b7700605cf\", \"best_bid\":\"0.64\", \"best_ask\":\"0.65\"}], \"timestamp\":\"1785208033728\", \"event_type\":\"price_change\"}","received_at":"2026-07-28T03:07:17.548815Z","schema_version":"clob-market-ws.price_change.v1","sequence":null,"server_hash":null,"server_timestamp":"1785208033728","session_id":"3e519d9098404c15b234d96025eb1a2b","source":"clob_market_ws"},"received_at":"2026-07-28T03:07:17.548815Z","record_id":"71875fbff99f0fb8854fcf69ea5699b122152913ee84aa65b843f5a2ccfec51b","schema_fingerprint":"4aa3821a28b0b7c2400bc59aba4bcc0a76e971dadd19610d3ad38c768e124dc7","schema_version":"edge-lab-recorder.raw.v1","sequence":null,"source":"clob_market_ws"}
{"event_at":"2026-07-28T03:07:13.732000Z","event_fingerprint":"482729260dacf191c9b640a96a86540da37dcf4b7bd0c375e69e4be6ef2b8384","payload":{"connection_id":"a6b55582af5f430fb37ad02bf0922475","event_at":"2026-07-28T03:07:13.732000Z","event_type":"price_change","frame_hash":"e68927d3869e068967bd9937e45859e9b5ac556f482a62520f7b1bdb3e56a15e","frame_index":0,"kind":"data","monotonic_ns":310020583768625,"payload":{"event_type":"price_change","market":"0x779291bef19b6709f61e9764a954aafe9ffae488d50ae674aabdcb4f248006d5","price_changes":[{"asset_id":"8761897749749422724209054078244794145777693856614463256546737399611489089783","best_ask":"0.65","best_bid":"0.64","hash":"6c7b0465ae5c1d69c4cc45ef43ba1a875df05c20","price":"0.04","side":"BUY","size":"588.09"},{"asset_id":"14965588658799411272385430903075831224615961675357217884735713260981483529984","best_ask":"0.36","best_bid":"0.35","hash":"329e262376c71ea3400ec301e735e5206d98b1ab","price":"0.96","side":"SELL","size":"588.09"}],"timestamp":"1785208033732"},"payload_hash":"e33f146f1a4a4c8ba3ddcd3a6e78da1e78faf0af547bad64216bd441126f55fb","raw_frame":"{\"market\":\"0x779291bef19b6709f61e9764a954aafe9ffae488d50ae674aabdcb4f248006d5\", \"price_changes\":[{\"asset_id\":\"8761897749749422724209054078244794145777693856614463256546737399611489089783\", \"price\":\"0.04\", \"size\":\"588.09\", \"side\":\"BUY\", \"hash\":\"6c7b0465ae5c1d69c4cc45ef43ba1a875df05c20\", \"best_bid\":\"0.64\", \"best_ask\":\"0.65\"}, {\"asset_id\":\"14965588658799411272385430903075831224615961675357217884735713260981483529984\", \"price\":\"0.96\", \"size\":\"588.09\", \"side\":\"SELL\", \"hash\":\"329e262376c71ea3400ec301e735e5206d98b1ab\", \"best_bid\":\"0.35\", \"best_ask\":\"0.36\"}], \"timestamp\":\"1785208033732\", \"event_type\":\"price_change\"}","received_at":"2026-07-28T03:07:17.551868Z","schema_version":"clob-market-ws.price_change.v1","sequence":null,"server_hash":null,"server_timestamp":"1785208033732","session_id":"3e519d9098404c15b234d96025eb1a2b","source":"clob_market_ws"},"received_at":"2026-07-28T03:07:17.551868Z","record_id":"2d57716a94579557918e49dbae9122eb7f521cbced6db80b2aa98e0aa8d9738e","schema_fingerprint":"4aa3821a28b0b7c2400bc59aba4bcc0a76e971dadd19610d3ad38c768e124dc7","schema_version":"edge-lab-recorder.raw.v1","sequence":null,"source":"clob_market_ws"}
{"event_at":"2026-07-28T03:07:13.735000Z","event_fingerprint":"6f97e6d68de5ccafeda9f664c34da00bf724ea2984cdfb7a1b2dad590080c07c","payload":{"connection_id":"a6b55582af5f430fb37ad02bf0922475","event_at":"2026-07-28T03:07:13.735000Z","event_type":"price_change","frame_hash":"9d1a53d7c1a75c7dfd63a45e0b91572240c3030d0a1307d84037f52093c5d547","frame_index":0,"kind":"data","monotonic_ns":310020586823083,"payload":{"event_type":"price_change","market":"0x779291bef19b6709f61e9764a954aafe9ffae488d50ae674aabdcb4f248006d5","price_changes":[{"asset_id":"14965588658799411272385430903075831224615961675357217884735713260981483529984","best_ask":"0.36","best_bid":"0.35","hash":"4d41d6f18198689e6d0a1e65c140e71b36c5c066","price":"0.36","side":"SELL","size":"25.98"},{"asset_id":"8761897749749422724209054078244794145777693856614463256546737399611489089783","best_ask":"0.65","best_bid":"0.64","hash":"25a7434a83f3029fe4689c70bb86a9aa538a068d","price":"0.64","side":"BUY","size":"25.98"}],"timestamp":"1785208033735"},"payload_hash":"a8d1ec43892722af13c5541e4b5d0828baa4fd0165633cf398d06a56deaf0aec","raw_frame":"{\"market\":\"0x779291bef19b6709f61e9764a954aafe9ffae488d50ae674aabdcb4f248006d5\", \"price_changes\":[{\"asset_id\":\"14965588658799411272385430903075831224615961675357217884735713260981483529984\", \"price\":\"0.36\", \"size\":\"25.98\", \"side\":\"SELL\", \"hash\":\"4d41d6f18198689e6d0a1e65c140e71b36c5c066\", \"best_bid\":\"0.35\", \"best_ask\":\"0.36\"}, {\"asset_id\":\"8761897749749422724209054078244794145777693856614463256546737399611489089783\", \"price\":\"0.64\", \"size\":\"25.98\", \"side\":\"BUY\", \"hash\":\"25a7434a83f3029fe4689c70bb86a9aa538a068d\", \"best_bid\":\"0.64\", \"best_ask\":\"0.65\"}], \"timestamp\":\"1785208033735\", \"event_type\":\"price_change\"}","received_at":"2026-07-28T03:07:17.554922Z","schema_version":"clob-market-ws.price_change.v1","sequence":null,"server_hash":null,"server_timestamp":"1785208033735","session_id":"3e519d9098404c15b234d96025eb1a2b","source":"clob_market_ws"},"received_at":"2026-07-28T03:07:17.554922Z","record_id":"b2dc4e8964ae52403cc7581131617f880af9714304e81277e53e683082e7970f","schema_fingerprint":"4aa3821a28b0b7c2400bc59aba4bcc0a76e971dadd19610d3ad38c768e124dc7","schema_version":"edge-lab-recorder.raw.v1","sequence":null,"source":"clob_market_ws"}
{"event_at":"2026-07-28T03:07:13.736000Z","event_fingerprint":"91cef7da916fda16821627dfb2bd27ea8caae786ac9f2c7198debf93ebaf8e6d","payload":{"connection_id":"a6b55582af5f430fb37ad02bf0922475","event_at":"2026-07-28T03:07:13.736000Z","event_type":"price_change","frame_hash":"1c65efb9e2e6971c7f7d24421fb110fb8c2221ad7775b8ad154a60d7a0b83223","frame_index":0,"kind":"data","monotonic_ns":310020589902166,"payload":{"event_type":"price_change","market":"0x779291bef19b6709f61e9764a954aafe9ffae488d50ae674aabdcb4f248006d5","price_changes":[{"asset_id":"14965588658799411272385430903075831224615961675357217884735713260981483529984","best_ask":"0.36","best_bid":"0.35","hash":"bbbc5cf4c07f30bdeed8cfbfd58150f1e496a516","price":"0.34","side":"BUY","size":"98.4"},{"asset_id":"8761897749749422724209054078244794145777693856614463256546737399611489089783","best_ask":"0.65","best_bid":"0.64","hash":"9413b95a7c91f4e506a0fe5fbad56de58bd0a19c","price":"0.66","side":"SELL","size":"98.4"}],"timestamp":"1785208033736"},"payload_hash":"11ca57550254c3b033a0fcd22987a28a87cb216ebc69544bca1b6577d40d80b3","raw_frame":"{\"market\":\"0x779291bef19b6709f61e9764a954aafe9ffae488d50ae674aabdcb4f248006d5\", \"price_changes\":[{\"asset_id\":\"14965588658799411272385430903075831224615961675357217884735713260981483529984\", \"price\":\"0.34\", \"size\":\"98.4\", \"side\":\"BUY\", \"hash\":\"bbbc5cf4c07f30bdeed8cfbfd58150f1e496a516\", \"best_bid\":\"0.35\", \"best_ask\":\"0.36\"}, {\"asset_id\":\"8761897749749422724209054078244794145777693856614463256546737399611489089783\", \"price\":\"0.66\", \"size\":\"98.4\", \"side\":\"SELL\", \"hash\":\"9413b95a7c91f4e506a0fe5fbad56de58bd0a19c\", \"best_bid\":\"0.64\", \"best_ask\":\"0.65\"}], \"timestamp\":\"1785208033736\", \"event_type\":\"price_change\"}","received_at":"2026-07-28T03:07:17.558001Z","schema_version":"clob-market-ws.price_change.v1","sequence":null,"server_hash":null,"server_timestamp":"1785208033736","session_id":"3e519d9098404c15b234d96025eb1a2b","source":"clob_market_ws"},"received_at":"2026-07-28T03:07:17.558001Z","record_id":"6d341230e2a71450102d469cccbe7320b5a487077c761fadea70ff06f9b75c4b","schema_fingerprint":"4aa3821a28b0b7c2400bc59aba4bcc0a76e971dadd19610d3ad38c768e124dc7","schema_version":"edge-lab-recorder.raw.v1","sequence":null,"source":"clob_market_ws"}
{"event_at":"2026-07-28T03:07:13.738000Z","event_fingerprint":"f949eef24e4fb707387adf5fef207d410602cec6f3b70a19e1746c13596eab3e","payload":{"connection_id":"a6b55582af5f430fb37ad02bf0922475","event_at":"2026-07-28T03:07:13.738000Z","event_type":"price_change","frame_hash":"20c575766cc2b18b3af01acfe5be5cbd8d656131f7adf067ae845e78cf389a17","frame_index":0,"kind":"data","monotonic_ns":310020592864875,"payload":{"event_type":"price_change","market":"0x779291bef19b6709f61e9764a954aafe9ffae488d50ae674aabdcb4f248006d5","price_changes":[{"asset_id":"14965588658799411272385430903075831224615961675357217884735713260981483529984","best_ask":"0.36","best_bid":"0.35","hash":"279a35d4e454f74973df696830bc64fb8afb3b2f","price":"0.14","side":"BUY","size":"417.9"},{"asset_id":"8761897749749422724209054078244794145777693856614463256546737399611489089783","best_ask":"0.65","best_bid":"0.64","hash":"71bfeab43b40d9efab8f60834d5ac02b86866718","price":"0.86","side":"SELL","size":"417.9"}],"timestamp":"1785208033738"},"payload_hash":"1d61737169f6b9032d267fcf2150e9d6f5e514481e187c618b4aba3fc3ba979e","raw_frame":"{\"market\":\"0x779291bef19b6709f61e9764a954aafe9ffae488d50ae674aabdcb4f248006d5\", \"price_changes\":[{\"asset_id\":\"14965588658799411272385430903075831224615961675357217884735713260981483529984\", \"price\":\"0.14\", \"size\":\"417.9\", \"side\":\"BUY\", \"hash\":\"279a35d4e454f74973df696830bc64fb8afb3b2f\", \"best_bid\":\"0.35\", \"best_ask\":\"0.36\"}, {\"asset_id\":\"8761897749749422724209054078244794145777693856614463256546737399611489089783\", \"price\":\"0.86\", \"size\":\"417.9\", \"side\":\"SELL\", \"hash\":\"71bfeab43b40d9efab8f60834d5ac02b86866718\", \"best_bid\":\"0.64\", \"best_ask\":\"0.65\"}], \"timestamp\":\"1785208033738\", \"event_type\":\"price_change\"}","received_at":"2026-07-28T03:07:17.560965Z","schema_version":"clob-market-ws.price_change.v1","sequence":null,"server_hash":null,"server_timestamp":"1785208033738","session_id":"3e519d9098404c15b234d96025eb1a2b","source":"clob_market_ws"},"received_at":"2026-07-28T03:07:17.560965Z","record_id":"a6857ebd23fa56971d706074dc9ec2bc76d58e4fecc1e28a6358b0f0b9dea497","schema_fingerprint":"4aa3821a28b0b7c2400bc59aba4bcc0a76e971dadd19610d3ad38c768e124dc7","schema_version":"edge-lab-recorder.raw.v1","sequence":null,"source":"clob_market_ws"}
{"event_at":"2026-07-28T03:07:13.744000Z","event_fingerprint":"25d0a322a7219d7f3a752e9461c460076f281bbc95584acf232d9edbfa7789cd","payload":{"connection_id":"a6b55582af5f430fb37ad02bf0922475","event_at":"2026-07-28T03:07:13.744000Z","event_type":"price_change","frame_hash":"d3355ba9342bb0c6c3f7833f882d038f88cd312eaaeb2584acba7c041205fcb9","frame_index":0,"kind":"data","monotonic_ns":310020595826250,"payload":{"event_type":"price_change","market":"0x779291bef19b6709f61e9764a954aafe9ffae488d50ae674aabdcb4f248006d5","price_changes":[{"asset_id":"8761897749749422724209054078244794145777693856614463256546737399611489089783","best_ask":"0.65","best_bid":"0.64","hash":"d25bf5e91ca3e7c1430761c6603ded768c015e59","price":"0.01","side":"BUY","size":"5608.02"},{"asset_id":"14965588658799411272385430903075831224615961675357217884735713260981483529984","best_ask":"0.36","best_bid":"0.35","hash":"16101a1d7d3bfc4eee071200bd1aff37628c3c67","price":"0.99","side":"SELL","size":"5608.02"}],"timestamp":"1785208033744"},"payload_hash":"12362dbc958146c87f874b5cfa877278c5f6d397b7c36f3ac1b445d27fa83182","raw_frame":"{\"market\":\"0x779291bef19b6709f61e9764a954aafe9ffae488d50ae674aabdcb4f248006d5\", \"price_changes\":[{\"asset_id\":\"8761897749749422724209054078244794145777693856614463256546737399611489089783\", \"price\":\"0.01\", \"size\":\"5608.02\", \"side\":\"BUY\", \"hash\":\"d25bf5e91ca3e7c1430761c6603ded768c015e59\", \"best_bid\":\"0.64\", \"best_ask\":\"0.65\"}, {\"asset_id\":\"14965588658799411272385430903075831224615961675357217884735713260981483529984\", \"price\":\"0.99\", \"size\":\"5608.02\", \"side\":\"SELL\", \"hash\":\"16101a1d7d3bfc4eee071200bd1aff37628c3c67\", \"best_bid\":\"0.35\", \"best_ask\":\"0.36\"}], \"timestamp\":\"1785208033744\", \"event_type\":\"price_change\"}","received_at":"2026-07-28T03:07:17.563926Z","schema_version":"clob-market-ws.price_change.v1","sequence":null,"server_hash":null,"server_timestamp":"1785208033744","session_id":"3e519d9098404c15b234d96025eb1a2b","source":"clob_market_ws"},"received_at":"2026-07-28T03:07:17.563926Z","record_id":"d39ac541cf4164818abf5825e15dbf9f54bd639688288f1b32ba0144f3962708","schema_fingerprint":"4aa3821a28b0b7c2400bc59aba4bcc0a76e971dadd19610d3ad38c768e124dc7","schema_version":"edge-lab-recorder.raw.v1","sequence":null,"source":"clob_market_ws"}
{"event_at":"2026-07-28T03:07:13.753000Z","event_fingerprint":"bb09ac1b789e72778d1feb45b95edcee31f1bb8efdcd9cfeee02ffaed3f9fdde","payload":{"connection_id":"a6b55582af5f430fb37ad02bf0922475","event_at":"2026-07-28T03:07:13.753000Z","event_type":"price_change","frame_hash":"e8ef5cfd393b0a53a3686cdfc4ae82dc297f368715fc0afd454e874258f1a55c","frame_index":0,"kind":"data","monotonic_ns":310020598842208,"payload":{"event_type":"price_change","market":"0x779291bef19b6709f61e9764a954aafe9ffae488d50ae674aabdcb4f248006d5","price_changes":[{"asset_id":"14965588658799411272385430903075831224615961675357217884735713260981483529984","best_ask":"0.36","best_bid":"0.35","hash":"b8a8fb7c697f001029764247809c1f6e41ce3e74","price":"0.24","side":"BUY","size":"241.39"},{"asset_id":"8761897749749422724209054078244794145777693856614463256546737399611489089783","best_ask":"0.65","best_bid":"0.64","hash":"05bd3e9f7b95e5f8d46e170270984eea5c2fd4ab","price":"0.76","side":"SELL","size":"241.39"}],"timestamp":"1785208033753"},"payload_hash":"656938b8dace099f49a6d845d6c7cac344abb7a6597b68794d20688d8dc60e4e","raw_frame":"{\"market\":\"0x779291bef19b6709f61e9764a954aafe9ffae488d50ae674aabdcb4f248006d5\", \"price_changes\":[{\"asset_id\":\"14965588658799411272385430903075831224615961675357217884735713260981483529984\", \"price\":\"0.24\", \"size\":\"241.39\", \"side\":\"BUY\", \"hash\":\"b8a8fb7c697f001029764247809c1f6e41ce3e74\", \"best_bid\":\"0.35\", \"best_ask\":\"0.36\"}, {\"asset_id\":\"8761897749749422724209054078244794145777693856614463256546737399611489089783\", \"price\":\"0.76\", \"size\":\"241.39\", \"side\":\"SELL\", \"hash\":\"05bd3e9f7b95e5f8d46e170270984eea5c2fd4ab\", \"best_bid\":\"0.64\", \"best_ask\":\"0.65\"}], \"timestamp\":\"1785208033753\", \"event_type\":\"price_change\"}","received_at":"2026-07-28T03:07:17.566942Z","schema_version":"clob-market-ws.price_change.v1","sequence":null,"server_hash":null,"server_timestamp":"1785208033753","session_id":"3e519d9098404c15b234d96025eb1a2b","source":"clob_market_ws"},"received_at":"2026-07-28T03:07:17.566942Z","record_id":"19f350bc82440eb1e879d2032d930e2332ef8535313e602bac4d03d22aebe027","schema_fingerprint":"4aa3821a28b0b7c2400bc59aba4bcc0a76e971dadd19610d3ad38c768e124dc7","schema_version":"edge-lab-recorder.raw.v1","sequence":null,"source":"clob_market_ws"}
{"event_at":"2026-07-28T03:07:13.756000Z","event_fingerprint":"2da723f2fa486e8596f1328e04e8456c2cb502dcc1dc0ba24e8e36c3cb6d36ff","payload":{"connection_id":"a6b55582af5f430fb37ad02bf0922475","event_at":"2026-07-28T03:07:13.756000Z","event_type":"price_change","frame_hash":"2fbf4a2b82599a5df58fee0143a38d2fefda2747e3a8f5cb11ae98fd898fed60","frame_index":0,"kind":"data","monotonic_ns":310020601843916,"payload":{"event_type":"price_change","market":"0x779291bef19b6709f61e9764a954aafe9ffae488d50ae674aabdcb4f248006d5","price_changes":[{"asset_id":"8761897749749422724209054078244794145777693856614463256546737399611489089783","best_ask":"0.65","best_bid":"0.64","hash":"2e458df277c76f7666edc36f5d3432c67ae7ee1f","price":"0.57","side":"BUY","size":"295"},{"asset_id":"14965588658799411272385430903075831224615961675357217884735713260981483529984","best_ask":"0.36","best_bid":"0.35","hash":"afca127909959fad72fece4b348528af5d924c3a","price":"0.43","side":"SELL","size":"295"}],"timestamp":"1785208033756"},"payload_hash":"d9b6c48e81428faa7dee12a198a9fd40d47047bdd24ce7130561602c6122d71a","raw_frame":"{\"market\":\"0x779291bef19b6709f61e9764a954aafe9ffae488d50ae674aabdcb4f248006d5\", \"price_changes\":[{\"asset_id\":\"8761897749749422724209054078244794145777693856614463256546737399611489089783\", \"price\":\"0.57\", \"size\":\"295\", \"side\":\"BUY\", \"hash\":\"2e458df277c76f7666edc36f5d3432c67ae7ee1f\", \"best_bid\":\"0.64\", \"best_ask\":\"0.65\"}, {\"asset_id\":\"14965588658799411272385430903075831224615961675357217884735713260981483529984\", \"price\":\"0.43\", \"size\":\"295\", \"side\":\"SELL\", \"hash\":\"afca127909959fad72fece4b348528af5d924c3a\", \"best_bid\":\"0.35\", \"best_ask\":\"0.36\"}], \"timestamp\":\"1785208033756\", \"event_type\":\"price_change\"}","received_at":"2026-07-28T03:07:17.569944Z","schema_version":"clob-market-ws.price_change.v1","sequence":null,"server_hash":null,"server_timestamp":"1785208033756","session_id":"3e519d9098404c15b234d96025eb1a2b","source":"clob_market_ws"},"received_at":"2026-07-28T03:07:17.569944Z","record_id":"483c8d95a8bc1d4222ab9fb765903419fc321fd4246700f6eba4aaa6fc307744","schema_fingerprint":"4aa3821a28b0b7c2400bc59aba4bcc0a76e971dadd19610d3ad38c768e124dc7","schema_version":"edge-lab-recorder.raw.v1","sequence":null,"source":"clob_market_ws"}
{"event_at":"2026-07-28T03:07:13.763000Z","event_fingerprint":"dcc8a1b1d8c63cc9ce396126606d3638d13c45f98ea661da570fb977a63724cc","payload":{"connection_id":"a6b55582af5f430fb37ad02bf0922475","event_at":"2026-07-28T03:07:13.763000Z","event_type":"price_change","frame_hash":"656923a161167489cb0ada2fc0a61a94fc00fc9f5f2034027bd3d0d46659c2b6","frame_index":0,"kind":"data","monotonic_ns":310020604898125,"payload":{"event_type":"price_change","market":"0x779291bef19b6709f61e9764a954aafe9ffae488d50ae674aabdcb4f248006d5","price_changes":[{"asset_id":"8761897749749422724209054078244794145777693856614463256546737399611489089783","best_ask":"0.65","best_bid":"0.64","hash":"0a90b903836dc0ec144a11d6118b0811bb76202d","price":"0.01","side":"BUY","size":"5613.02"},{"asset_id":"14965588658799411272385430903075831224615961675357217884735713260981483529984","best_ask":"0.36","best_bid":"0.35","hash":"c006b5d61f853546efcbe5b0b1cc7700b000c523","price":"0.99","side":"SELL","size":"5613.02"}],"timestamp":"1785208033763"},"payload_hash":"a53b9bc2816158e2e63aa67dc8396b336717fb1ebfa5363563c6b52dc5fc7c0b","raw_frame":"{\"market\":\"0x779291bef19b6709f61e9764a954aafe9ffae488d50ae674aabdcb4f248006d5\", \"price_changes\":[{\"asset_id\":\"8761897749749422724209054078244794145777693856614463256546737399611489089783\", \"price\":\"0.01\", \"size\":\"5613.02\", \"side\":\"BUY\", \"hash\":\"0a90b903836dc0ec144a11d6118b0811bb76202d\", \"best_bid\":\"0.64\", \"best_ask\":\"0.65\"}, {\"asset_id\":\"14965588658799411272385430903075831224615961675357217884735713260981483529984\", \"price\":\"0.99\", \"size\":\"5613.02\", \"side\":\"SELL\", \"hash\":\"c006b5d61f853546efcbe5b0b1cc7700b000c523\", \"best_bid\":\"0.35\", \"best_ask\":\"0.36\"}], \"timestamp\":\"1785208033763\", \"event_type\":\"price_change\"}","received_at":"2026-07-28T03:07:17.572996Z","schema_version":"clob-market-ws.price_change.v1","sequence":null,"server_hash":null,"server_timestamp":"1785208033763","session_id":"3e519d9098404c15b234d96025eb1a2b","source":"clob_market_ws"},"received_at":"2026-07-28T03:07:17.572996Z","record_id":"43de454833e83d98be6e4e500b420dc3d82554a83da76da6a11e28bdd5b80c40","schema_fingerprint":"4aa3821a28b0b7c2400bc59aba4bcc0a76e971dadd19610d3ad38c768e124dc7","schema_version":"edge-lab-recorder.raw.v1","sequence":null,"source":"clob_market_ws"}
{"event_at":"2026-07-28T03:07:13.770000Z","event_fingerprint":"a22b5ba75db4153face77fef9339ac71356016571bc02b3e1da8f709e6d2c538","payload":{"connection_id":"a6b55582af5f430fb37ad02bf0922475","event_at":"2026-07-28T03:07:13.770000Z","event_type":"price_change","frame_hash":"13fdec554f5ce3820b12d9a094fdc63af2b1c0d23f4769bc530945ff8b11de6e","frame_index":0,"kind":"data","monotonic_ns":310020607976916,"payload":{"event_type":"price_change","market":"0x779291bef19b6709f61e9764a954aafe9ffae488d50ae674aabdcb4f248006d5","price_changes":[{"asset_id":"8761897749749422724209054078244794145777693856614463256546737399611489089783","best_ask":"0.65","best_bid":"0.64","hash":"6c7ad6c6c1531599cc42dd916dc5904203aa8013","price":"0.15","side":"BUY","size":"104.5"},{"asset_id":"14965588658799411272385430903075831224615961675357217884735713260981483529984","best_ask":"0.36","best_bid":"0.35","hash":"d267a147f38830a3adcc19a838158749aa85208f","price":"0.85","side":"SELL","size":"104.5"}],"timestamp":"1785208033770"},"payload_hash":"1f9a174fb57b07caca2ac7e42492fa1a222eb47c8cc46bf53fe42f4b234fd81b","raw_frame":"{\"market\":\"0x779291bef19b6709f61e9764a954aafe9ffae488d50ae674aabdcb4f248006d5\", \"price_changes\":[{\"asset_id\":\"8761897749749422724209054078244794145777693856614463256546737399611489089783\", \"price\":\"0.15\", \"size\":\"104.5\", \"side\":\"BUY\", \"hash\":\"6c7ad6c6c1531599cc42dd916dc5904203aa8013\", \"best_bid\":\"0.64\", \"best_ask\":\"0.65\"}, {\"asset_id\":\"14965588658799411272385430903075831224615961675357217884735713260981483529984\", \"price\":\"0.85\", \"size\":\"104.5\", \"side\":\"SELL\", \"hash\":\"d267a147f38830a3adcc19a838158749aa85208f\", \"best_bid\":\"0.35\", \"best_ask\":\"0.36\"}], \"timestamp\":\"1785208033770\", \"event_type\":\"price_change\"}","received_at":"2026-07-28T03:07:17.576077Z","schema_version":"clob-market-ws.price_change.v1","sequence":null,"server_hash":null,"server_timestamp":"1785208033770","session_id":"3e519d9098404c15b234d96025eb1a2b","source":"clob_market_ws"},"received_at":"2026-07-28T03:07:17.576077Z","record_id":"9bd9e04f606d4a225d4e3fd51f96053bbc457b6d5d0834a7e16b339a28852a66","schema_fingerprint":"4aa3821a28b0b7c2400bc59aba4bcc0a76e971dadd19610d3ad38c768e124dc7","schema_version":"edge-lab-recorder.raw.v1","sequence":null,"source":"clob_market_ws"}
{"event_at":"2026-07-28T03:07:13.770000Z","event_fingerprint":"579213ada59608b28b68fa18b5f01cc150a12f265a6ad408a23734e32c59850a","payload":{"connection_id":"a6b55582af5f430fb37ad02bf0922475","event_at":"2026-07-28T03:07:13.770000Z","event_type":"price_change","frame_hash":"9593e2c12a9a6b34d020f27fde941773bae60086dc6e089bb85efe88ee8ca920","frame_index":0,"kind":"data","monotonic_ns":310020610936458,"payload":{"event_type":"price_change","market":"0x779291bef19b6709f61e9764a954aafe9ffae488d50ae674aabdcb4f248006d5","price_changes":[{"asset_id":"14965588658799411272385430903075831224615961675357217884735713260981483529984","best_ask":"0.36","best_bid":"0.35","hash":"d267a147f38830a3adcc19a838158749aa85208f","price":"0.01","side":"BUY","size":"5658.02"},{"asset_id":"8761897749749422724209054078244794145777693856614463256546737399611489089783","best_ask":"0.65","best_bid":"0.64","hash":"6c7ad6c6c1531599cc42dd916dc5904203aa8013","price":"0.99","side":"SELL","size":"5658.02"}],"timestamp":"1785208033770"},"payload_hash":"decc51599fdca7b7ece3f8ede4b2f22e796bde06098bad787a38eed876962ebd","raw_frame":"{\"market\":\"0x779291bef19b6709f61e9764a954aafe9ffae488d50ae674aabdcb4f248006d5\", \"price_changes\":[{\"asset_id\":\"14965588658799411272385430903075831224615961675357217884735713260981483529984\", \"price\":\"0.01\", \"size\":\"5658.02\", \"side\":\"BUY\", \"hash\":\"d267a147f38830a3adcc19a838158749aa85208f\", \"best_bid\":\"0.35\", \"best_ask\":\"0.36\"}, {\"asset_id\":\"8761897749749422724209054078244794145777693856614463256546737399611489089783\", \"price\":\"0.99\", \"size\":\"5658.02\", \"side\":\"SELL\", \"hash\":\"6c7ad6c6c1531599cc42dd916dc5904203aa8013\", \"best_bid\":\"0.64\", \"best_ask\":\"0.65\"}], \"timestamp\":\"1785208033770\", \"event_type\":\"price_change\"}","received_at":"2026-07-28T03:07:17.579036Z","schema_version":"clob-market-ws.price_change.v1","sequence":null,"server_hash":null,"server_timestamp":"1785208033770","session_id":"3e519d9098404c15b234d96025eb1a2b","source":"clob_market_ws"},"received_at":"2026-07-28T03:07:17.579036Z","record_id":"8b9c603b9a51ce776d81a06f7917597194083543022e4f4fb0ff0e8978122d6c","schema_fingerprint":"4aa3821a28b0b7c2400bc59aba4bcc0a76e971dadd19610d3ad38c768e124dc7","schema_version":"edge-lab-recorder.raw.v1","sequence":null,"source":"clob_market_ws"}
{"event_at":"2026-07-28T03:07:13.800000Z","event_fingerprint":"d9dcf6b88283e1931a52c6b43c795834dfd7a877f08194982729da9f29cae185","payload":{"connection_id":"a6b55582af5f430fb37ad02bf0922475","event_at":"2026-07-28T03:07:13.800000Z","event_type":"price_change","frame_hash":"4ad0afcb07383a1786eb8946eaf45fa93d27cba0c0eac8392cb0680d760bc018","frame_index":0,"kind":"data","monotonic_ns":310020613944333,"payload":{"event_type":"price_change","market":"0x779291bef19b6709f61e9764a954aafe9ffae488d50ae674aabdcb4f248006d5","price_changes":[{"asset_id":"8761897749749422724209054078244794145777693856614463256546737399611489089783","best_ask":"0.65","best_bid":"0.64","hash":"440c49941c451b3a19080824af9d0bbca0b572a8","price":"0.01","side":"BUY","size":"5608.02"},{"asset_id":"14965588658799411272385430903075831224615961675357217884735713260981483529984","best_ask":"0.36","best_bid":"0.35","hash":"ffff33b64f258c0393b60f2d818b43f697039f82","price":"0.99","side":"SELL","size":"5608.02"}],"timestamp":"1785208033800"},"payload_hash":"d8d1e485f6d3f2d6ea0d320351791c7b2c8ef59ed2cee1bdf36417abbe18a3c2","raw_frame":"{\"market\":\"0x779291bef19b6709f61e9764a954aafe9ffae488d50ae674aabdcb4f248006d5\", \"price_changes\":[{\"asset_id\":\"8761897749749422724209054078244794145777693856614463256546737399611489089783\", \"price\":\"0.01\", \"size\":\"5608.02\", \"side\":\"BUY\", \"hash\":\"440c49941c451b3a19080824af9d0bbca0b572a8\", \"best_bid\":\"0.64\", \"best_ask\":\"0.65\"}, {\"asset_id\":\"14965588658799411272385430903075831224615961675357217884735713260981483529984\", \"price\":\"0.99\", \"size\":\"5608.02\", \"side\":\"SELL\", \"hash\":\"ffff33b64f258c0393b60f2d818b43f697039f82\", \"best_bid\":\"0.35\", \"best_ask\":\"0.36\"}], \"timestamp\":\"1785208033800\", \"event_type\":\"price_change\"}","received_at":"2026-07-28T03:07:17.582044Z","schema_version":"clob-market-ws.price_change.v1","sequence":null,"server_hash":null,"server_timestamp":"1785208033800","session_id":"3e519d9098404c15b234d96025eb1a2b","source":"clob_market_ws"},"received_at":"2026-07-28T03:07:17.582044Z","record_id":"ac16c348d8e0aff47432efd9bf64dffeb0330e36ca29dd43fdfa45075d7ae8d6","schema_fingerprint":"4aa3821a28b0b7c2400bc59aba4bcc0a76e971dadd19610d3ad38c768e124dc7","schema_version":"edge-lab-recorder.raw.v1","sequence":null,"source":"clob_market_ws"}
{"event_at":"2026-07-28T03:07:13.800000Z","event_fingerprint":"b6d815940777735f0342067bb2230b250ce5560d0eca3c691ff2e28ac1ab3b7d","payload":{"connection_id":"a6b55582af5f430fb37ad02bf0922475","event_at":"2026-07-28T03:07:13.800000Z","event_type":"price_change","frame_hash":"723a53fe1e876f0565fa808f03cad7d996a95809525744ccc28ab57c331226e7","frame_index":0,"kind":"data","monotonic_ns":310020616895208,"payload":{"event_type":"price_change","market":"0x779291bef19b6709f61e9764a954aafe9ffae488d50ae674aabdcb4f248006d5","price_changes":[{"asset_id":"14965588658799411272385430903075831224615961675357217884735713260981483529984","best_ask":"0.36","best_bid":"0.35","hash":"89623878b53ade302a41208a9efed326dfdc8797","price":"0.33","side":"BUY","size":"148.6"},{"asset_id":"8761897749749422724209054078244794145777693856614463256546737399611489089783","best_ask":"0.65","best_bid":"0.64","hash":"7abe76747f5892d7be77773c90a69d79c69d63e9","price":"0.67","side":"SELL","size":"148.6"}],"timestamp":"1785208033800"},"payload_hash":"45aa319b121bff7a0f4a4142d61f5329960f96ba6baccc373a5fc2fc1b51e4a5","raw_frame":"{\"market\":\"0x779291bef19b6709f61e9764a954aafe9ffae488d50ae674aabdcb4f248006d5\", \"price_changes\":[{\"asset_id\":\"14965588658799411272385430903075831224615961675357217884735713260981483529984\", \"price\":\"0.33\", \"size\":\"148.6\", \"side\":\"BUY\", \"hash\":\"89623878b53ade302a41208a9efed326dfdc8797\", \"best_bid\":\"0.35\", \"best_ask\":\"0.36\"}, {\"asset_id\":\"8761897749749422724209054078244794145777693856614463256546737399611489089783\", \"price\":\"0.67\", \"size\":\"148.6\", \"side\":\"SELL\", \"hash\":\"7abe76747f5892d7be77773c90a69d79c69d63e9\", \"best_bid\":\"0.64\", \"best_ask\":\"0.65\"}], \"timestamp\":\"1785208033800\", \"event_type\":\"price_change\"}","received_at":"2026-07-28T03:07:17.584996Z","schema_version":"clob-market-ws.price_change.v1","sequence":null,"server_hash":null,"server_timestamp":"1785208033800","session_id":"3e519d9098404c15b234d96025eb1a2b","source":"clob_market_ws"},"received_at":"2026-07-28T03:07:17.584996Z","record_id":"66a90730407f3ca5c588cb2e76db5e833f37e4f88bae573fc8201662fc59e5e5","schema_fingerprint":"4aa3821a28b0b7c2400bc59aba4bcc0a76e971dadd19610d3ad38c768e124dc7","schema_version":"edge-lab-recorder.raw.v1","sequence":null,"source":"clob_market_ws"}
{"event_at":"2026-07-28T03:07:13.801000Z","event_fingerprint":"1498665b381d576599a4628d13643db50258f8eb563fd2f679e2ae431be891e7","payload":{"connection_id":"a6b55582af5f430fb37ad02bf0922475","event_at":"2026-07-28T03:07:13.801000Z","event_type":"price_change","frame_hash":"24633ad87c56df7f987f4d4fbcdedfe0a14271bc530d1b0a70f43b32844e424f","frame_index":0,"kind":"data","monotonic_ns":310020619851916,"payload":{"event_type":"price_change","market":"0x779291bef19b6709f61e9764a954aafe9ffae488d50ae674aabdcb4f248006d5","price_changes":[{"asset_id":"14965588658799411272385430903075831224615961675357217884735713260981483529984","best_ask":"0.36","best_bid":"0.35","hash":"543840e7b6514e5c6afd2c04d8c5664f29c8458e","price":"0.31","side":"BUY","size":"73.2"},{"asset_id":"8761897749749422724209054078244794145777693856614463256546737399611489089783","best_ask":"0.65","best_bid":"0.64","hash":"2d48517fe0f42fe088a045531dee07fe323a07da","price":"0.69","side":"SELL","size":"73.2"}],"timestamp":"1785208033801"},"payload_hash":"959906da96ffd2d655b29fc03af33789228419b90c7c7c8f8343eccd0e2e74a8","raw_frame":"{\"market\":\"0x779291bef19b6709f61e9764a954aafe9ffae488d50ae674aabdcb4f248006d5\", \"price_changes\":[{\"asset_id\":\"14965588658799411272385430903075831224615961675357217884735713260981483529984\", \"price\":\"0.31\", \"size\":\"73.2\", \"side\":\"BUY\", \"hash\":\"543840e7b6514e5c6afd2c04d8c5664f29c8458e\", \"best_bid\":\"0.35\", \"best_ask\":\"0.36\"}, {\"asset_id\":\"8761897749749422724209054078244794145777693856614463256546737399611489089783\", \"price\":\"0.69\", \"size\":\"73.2\", \"side\":\"SELL\", \"hash\":\"2d48517fe0f42fe088a045531dee07fe323a07da\", \"best_bid\":\"0.64\", \"best_ask\":\"0.65\"}], \"timestamp\":\"1785208033801\", \"event_type\":\"price_change\"}","received_at":"2026-07-28T03:07:17.587952Z","schema_version":"clob-market-ws.price_change.v1","sequence":null,"server_hash":null,"server_timestamp":"1785208033801","session_id":"3e519d9098404c15b234d96025eb1a2b","source":"clob_market_ws"},"received_at":"2026-07-28T03:07:17.587952Z","record_id":"71146bae6687f7795a5155ea188962ce6bca0191d0ecd218212363f660ba2be9","schema_fingerprint":"4aa3821a28b0b7c2400bc59aba4bcc0a76e971dadd19610d3ad38c768e124dc7","schema_version":"edge-lab-recorder.raw.v1","sequence":null,"source":"clob_market_ws"}
{"event_at":"2026-07-28T03:07:13.802000Z","event_fingerprint":"e8f679a8c25973083d0cb07ea474d7795c2807ce7faab104f01f879a48d0a258","payload":{"connection_id":"a6b55582af5f430fb37ad02bf0922475","event_at":"2026-07-28T03:07:13.802000Z","event_type":"price_change","frame_hash":"49647d20eb85234a19b88508ccc3b6b219c798cc3d75b824687008b6545ca9f3","frame_index":0,"kind":"data","monotonic_ns":310020622799083,"payload":{"event_type":"price_change","market":"0x779291bef19b6709f61e9764a954aafe9ffae488d50ae674aabdcb4f248006d5","price_changes":[{"asset_id":"8761897749749422724209054078244794145777693856614463256546737399611489089783","best_ask":"0.65","best_bid":"0.64","hash":"5283a13cd598c5867708d8984e2a49080c6d1115","price":"0.63","side":"BUY","size":"61.6"},{"asset_id":"14965588658799411272385430903075831224615961675357217884735713260981483529984","best_ask":"0.36","best_bid":"0.35","hash":"28dee1c2cfb4ddc2b10423cbf519aee8639d1ade","price":"0.37","side":"SELL","size":"61.6"}],"timestamp":"1785208033802"},"payload_hash":"c8db54b153d66a2b2b1c19b14627d04bb897a6078da44821a5d452053f979ef6","raw_frame":"{\"market\":\"0x779291bef19b6709f61e9764a954aafe9ffae488d50ae674aabdcb4f248006d5\", \"price_changes\":[{\"asset_id\":\"8761897749749422724209054078244794145777693856614463256546737399611489089783\", \"price\":\"0.63\", \"size\":\"61.6\", \"side\":\"BUY\", \"hash\":\"5283a13cd598c5867708d8984e2a49080c6d1115\", \"best_bid\":\"0.64\", \"best_ask\":\"0.65\"}, {\"asset_id\":\"14965588658799411272385430903075831224615961675357217884735713260981483529984\", \"price\":\"0.37\", \"size\":\"61.6\", \"side\":\"SELL\", \"hash\":\"28dee1c2cfb4ddc2b10423cbf519aee8639d1ade\", \"best_bid\":\"0.35\", \"best_ask\":\"0.36\"}], \"timestamp\":\"1785208033802\", \"event_type\":\"price_change\"}","received_at":"2026-07-28T03:07:17.590899Z","schema_version":"clob-market-ws.price_change.v1","sequence":null,"server_hash":null,"server_timestamp":"1785208033802","session_id":"3e519d9098404c15b234d96025eb1a2b","source":"clob_market_ws"},"received_at":"2026-07-28T03:07:17.590899Z","record_id":"78d966dcfe16858d00f4c93bb5674c5552a898d56e71fdedcffcb39c0de10a5a","schema_fingerprint":"4aa3821a28b0b7c2400bc59aba4bcc0a76e971dadd19610d3ad38c768e124dc7","schema_version":"edge-lab-recorder.raw.v1","sequence":null,"source":"clob_market_ws"}
{"event_at":"2026-07-28T03:07:13.823000Z","event_fingerprint":"1cf01edd638f68b48eaf8a4d467c00401a2a34c7cfc318b91a50688962a15779","payload":{"connection_id":"a6b55582af5f430fb37ad02bf0922475","event_at":"2026-07-28T03:07:13.823000Z","event_type":"price_change","frame_hash":"07b36c3573d3442c1259afa77ce17eb06e03bbdb30902a06bd0a8e40142f6dc9","frame_index":0,"kind":"data","monotonic_ns":310020625822416,"payload":{"event_type":"price_change","market":"0x779291bef19b6709f61e9764a954aafe9ffae488d50ae674aabdcb4f248006d5","price_changes":[{"asset_id":"8761897749749422724209054078244794145777693856614463256546737399611489089783","best_ask":"0.65","best_bid":"0.64","hash":"49e25f37741711f6c100514377b2fc92dde210df","price":"0.64","side":"BUY","size":"56.98"},{"asset_id":"14965588658799411272385430903075831224615961675357217884735713260981483529984","best_ask":"0.36","best_bid":"0.35","hash":"fbe58f9c495ede0aac102d77110bcc9131ce2d7b","price":"0.36","side":"SELL","size":"56.98"}],"timestamp":"1785208033823"},"payload_hash":"3aba1cca9734823c9d86be7a5681617bc08d8e6acad888b1a81ca4ab395a1587","raw_frame":"{\"market\":\"0x779291bef19b6709f61e9764a954aafe9ffae488d50ae674aabdcb4f248006d5\", \"price_changes\":[{\"asset_id\":\"8761897749749422724209054078244794145777693856614463256546737399611489089783\", \"price\":\"0.64\", \"size\":\"56.98\", \"side\":\"BUY\", \"hash\":\"49e25f37741711f6c100514377b2fc92dde210df\", \"best_bid\":\"0.64\", \"best_ask\":\"0.65\"}, {\"asset_id\":\"14965588658799411272385430903075831224615961675357217884735713260981483529984\", \"price\":\"0.36\", \"size\":\"56.98\", \"side\":\"SELL\", \"hash\":\"fbe58f9c495ede0aac102d77110bcc9131ce2d7b\", \"best_bid\":\"0.35\", \"best_ask\":\"0.36\"}], \"timestamp\":\"1785208033823\", \"event_type\":\"price_change\"}","received_at":"2026-07-28T03:07:17.593923Z","schema_version":"clob-market-ws.price_change.v1","sequence":null,"server_hash":null,"server_timestamp":"1785208033823","session_id":"3e519d9098404c15b234d96025eb1a2b","source":"clob_market_ws"},"received_at":"2026-07-28T03:07:17.593923Z","record_id":"c89dfebda02585a3f00a1d8e9188916c7a153c3aa8bf77f29b7e41a0b0ee28c3","schema_fingerprint":"4aa3821a28b0b7c2400bc59aba4bcc0a76e971dadd19610d3ad38c768e124dc7","schema_version":"edge-lab-recorder.raw.v1","sequence":null,"source":"clob_market_ws"}
{"event_at":"2026-07-28T03:07:13.823000Z","event_fingerprint":"0a8f69c6aec0c34d3e920620369a8395fb931959421c800634a14cc3a3e019f9","payload":{"connection_id":"a6b55582af5f430fb37ad02bf0922475","event_at":"2026-07-28T03:07:13.823000Z","event_type":"price_change","frame_hash":"881f5ae11292811210a293e5ebd2aa0cc0eb096fa0672d1e66d32cbb241de7e3","frame_index":0,"kind":"data","monotonic_ns":310020628796583,"payload":{"event_type":"price_change","market":"0x779291bef19b6709f61e9764a954aafe9ffae488d50ae674aabdcb4f248006d5","price_changes":[{"asset_id":"8761897749749422724209054078244794145777693856614463256546737399611489089783","best_ask":"0.65","best_bid":"0.64","hash":"6cabd6323296def472a03ce636a41aff6c475c02","price":"0.43","side":"BUY","size":"279.73"},{"asset_id":"14965588658799411272385430903075831224615961675357217884735713260981483529984","best_ask":"0.36","best_bid":"0.35","hash":"6668bdca1b6a6f8838e5fde4708b1f318e1ef9c8","price":"0.57","side":"SELL","size":"279.73"}],"timestamp":"1785208033823"},"payload_hash":"01050419850459744aa45c32db8e32042cdd687f1c85670ee46e0e82c7a5bb11","raw_frame":"{\"market\":\"0x779291bef19b6709f61e9764a954aafe9ffae488d50ae674aabdcb4f248006d5\", \"price_changes\":[{\"asset_id\":\"8761897749749422724209054078244794145777693856614463256546737399611489089783\", \"price\":\"0.43\", \"size\":\"279.73\", \"side\":\"BUY\", \"hash\":\"6cabd6323296def472a03ce636a41aff6c475c02\", \"best_bid\":\"0.64\", \"best_ask\":\"0.65\"}, {\"asset_id\":\"14965588658799411272385430903075831224615961675357217884735713260981483529984\", \"price\":\"0.57\", \"size\":\"279.73\", \"side\":\"SELL\", \"hash\":\"6668bdca1b6a6f8838e5fde4708b1f318e1ef9c8\", \"best_bid\":\"0.35\", \"best_ask\":\"0.36\"}], \"timestamp\":\"1785208033823\", \"event_type\":\"price_change\"}","received_at":"2026-07-28T03:07:17.596895Z","schema_version":"clob-market-ws.price_change.v1","sequence":null,"server_hash":null,"server_timestamp":"1785208033823","session_id":"3e519d9098404c15b234d96025eb1a2b","source":"clob_market_ws"},"received_at":"2026-07-28T03:07:17.596895Z","record_id":"ff17271c2bbf96cf1f81499bfdd7c41156818b2d44a011368b396c51343ee1ec","schema_fingerprint":"4aa3821a28b0b7c2400bc59aba4bcc0a76e971dadd19610d3ad38c768e124dc7","schema_version":"edge-lab-recorder.raw.v1","sequence":null,"source":"clob_market_ws"}
{"event_at":"2026-07-28T03:07:13.829000Z","event_fingerprint":"f485850c1cc144ab02a89e8801e48314bc2e743ee70ff0f876fdf0cee2d134a2","payload":{"connection_id":"a6b55582af5f430fb37ad02bf0922475","event_at":"2026-07-28T03:07:13.829000Z","event_type":"price_change","frame_hash":"4541ccf9f6cec762402ebac530723e41c518810d0231a73d75b58e439086d0f7","frame_index":0,"kind":"data","monotonic_ns":310020631733916,"payload":{"event_type":"price_change","market":"0x779291bef19b6709f61e9764a954aafe9ffae488d50ae674aabdcb4f248006d5","price_changes":[{"asset_id":"8761897749749422724209054078244794145777693856614463256546737399611489089783","best_ask":"0.65","best_bid":"0.64","hash":"c8773b4b1a108274f96efe2f325b0b057f4df6dc","price":"0.04","side":"BUY","size":"593.09"},{"asset_id":"14965588658799411272385430903075831224615961675357217884735713260981483529984","best_ask":"0.36","best_bid":"0.35","hash":"e752470958a5ce9679e9edc3c1f6f9d24ec14222","price":"0.96","side":"SELL","size":"593.09"}],"timestamp":"1785208033829"},"payload_hash":"c337e6cd852a17d0748b87fb5700f0752704991c938cb0ba838e93fb7c56b027","raw_frame":"{\"market\":\"0x779291bef19b6709f61e9764a954aafe9ffae488d50ae674aabdcb4f248006d5\", \"price_changes\":[{\"asset_id\":\"8761897749749422724209054078244794145777693856614463256546737399611489089783\", \"price\":\"0.04\", \"size\":\"593.09\", \"side\":\"BUY\", \"hash\":\"c8773b4b1a108274f96efe2f325b0b057f4df6dc\", \"best_bid\":\"0.64\", \"best_ask\":\"0.65\"}, {\"asset_id\":\"14965588658799411272385430903075831224615961675357217884735713260981483529984\", \"price\":\"0.96\", \"size\":\"593.09\", \"side\":\"SELL\", \"hash\":\"e752470958a5ce9679e9edc3c1f6f9d24ec14222\", \"best_bid\":\"0.35\", \"best_ask\":\"0.36\"}], \"timestamp\":\"1785208033829\", \"event_type\":\"price_change\"}","received_at":"2026-07-28T03:07:17.599834Z","schema_version":"clob-market-ws.price_change.v1","sequence":null,"server_hash":null,"server_timestamp":"1785208033829","session_id":"3e519d9098404c15b234d96025eb1a2b","source":"clob_market_ws"},"received_at":"2026-07-28T03:07:17.599834Z","record_id":"3fb6da9dbc1ad8f2388e500d58d31dd5ad797b60a033574d955b8e7cefe25486","schema_fingerprint":"4aa3821a28b0b7c2400bc59aba4bcc0a76e971dadd19610d3ad38c768e124dc7","schema_version":"edge-lab-recorder.raw.v1","sequence":null,"source":"clob_market_ws"}
{"event_at":"2026-07-28T03:07:13.834000Z","event_fingerprint":"19c2cd429b115ed370fc777968069038ca25440cb9050ec2e4a6cb2b3f0113e8","payload":{"connection_id":"a6b55582af5f430fb37ad02bf0922475","event_at":"2026-07-28T03:07:13.834000Z","event_type":"price_change","frame_hash":"9cf9abc22d0808edb6fc146d82cb980cb8daddddaacd8ca447956c9926200996","frame_index":0,"kind":"data","monotonic_ns":310020634671875,"payload":{"event_type":"price_change","market":"0x779291bef19b6709f61e9764a954aafe9ffae488d50ae674aabdcb4f248006d5","price_changes":[{"asset_id":"14965588658799411272385430903075831224615961675357217884735713260981483529984","best_ask":"0.36","best_bid":"0.35","hash":"16d854348b37ea86dcc8f016c422ef3c4239fd19","price":"0.36","side":"SELL","size":"41"},{"asset_id":"8761897749749422724209054078244794145777693856614463256546737399611489089783","best_ask":"0.65","best_bid":"0.64","hash":"237d6cdc7ed26cab0862c16442afd3575be22e6d","price":"0.64","side":"BUY","size":"41"}],"timestamp":"1785208033834"},"payload_hash":"87ece9624faba48d928530487934cda67d9a848cef04c378816fe635ef4e98f1","raw_frame":"{\"market\":\"0x779291bef19b6709f61e9764a954aafe9ffae488d50ae674aabdcb4f248006d5\", \"price_changes\":[{\"asset_id\":\"14965588658799411272385430903075831224615961675357217884735713260981483529984\", \"price\":\"0.36\", \"size\":\"41\", \"side\":\"SELL\", \"hash\":\"16d854348b37ea86dcc8f016c422ef3c4239fd19\", \"best_bid\":\"0.35\", \"best_ask\":\"0.36\"}, {\"asset_id\":\"8761897749749422724209054078244794145777693856614463256546737399611489089783\", \"price\":\"0.64\", \"size\":\"41\", \"side\":\"BUY\", \"hash\":\"237d6cdc7ed26cab0862c16442afd3575be22e6d\", \"best_bid\":\"0.64\", \"best_ask\":\"0.65\"}], \"timestamp\":\"1785208033834\", \"event_type\":\"price_change\"}","received_at":"2026-07-28T03:07:17.602772Z","schema_version":"clob-market-ws.price_change.v1","sequence":null,"server_hash":null,"server_timestamp":"1785208033834","session_id":"3e519d9098404c15b234d96025eb1a2b","source":"clob_market_ws"},"received_at":"2026-07-28T03:07:17.602772Z","record_id":"b6b3a5f7f2a764cdd36cf84b9ab0cf242a29a0b6976311d238235d6e9bf9e6df","schema_fingerprint":"4aa3821a28b0b7c2400bc59aba4bcc0a76e971dadd19610d3ad38c768e124dc7","schema_version":"edge-lab-recorder.raw.v1","sequence":null,"source":"clob_market_ws"}
{"event_at":"2026-07-28T03:07:13.834000Z","event_fingerprint":"fbbfc26aef525dcd61e1cd3864f013c7ce31af5d852956d3141d79ab88188c09","payload":{"connection_id":"a6b55582af5f430fb37ad02bf0922475","event_at":"2026-07-28T03:07:13.834000Z","event_type":"price_change","frame_hash":"edb55c3ee4b1e3ed11727e3d98691ab765d575179bf7dec3e7037599b9f9e1a0","frame_index":0,"kind":"data","monotonic_ns":310020637604416,"payload":{"event_type":"price_change","market":"0x779291bef19b6709f61e9764a954aafe9ffae488d50ae674aabdcb4f248006d5","price_changes":[{"asset_id":"8761897749749422724209054078244794145777693856614463256546737399611489089783","best_ask":"0.65","best_bid":"0.64","hash":"237d6cdc7ed26cab0862c16442afd3575be22e6d","price":"0.64","side":"BUY","size":"41"},{"asset_id":"14965588658799411272385430903075831224615961675357217884735713260981483529984","best_ask":"0.36","best_bid":"0.35","hash":"16d854348b37ea86dcc8f016c422ef3c4239fd19","price":"0.36","side":"SELL","size":"41"}],"timestamp":"1785208033834"},"payload_hash":"cb5cf53328cb0328377e601a569a9dff42b0b398614c272b1f46da14e50cf219","raw_frame":"{\"market\":\"0x779291bef19b6709f61e9764a954aafe9ffae488d50ae674aabdcb4f248006d5\", \"price_changes\":[{\"asset_id\":\"8761897749749422724209054078244794145777693856614463256546737399611489089783\", \"price\":\"0.64\", \"size\":\"41\", \"side\":\"BUY\", \"hash\":\"237d6cdc7ed26cab0862c16442afd3575be22e6d\", \"best_bid\":\"0.64\", \"best_ask\":\"0.65\"}, {\"asset_id\":\"14965588658799411272385430903075831224615961675357217884735713260981483529984\", \"price\":\"0.36\", \"size\":\"41\", \"side\":\"SELL\", \"hash\":\"16d854348b37ea86dcc8f016c422ef3c4239fd19\", \"best_bid\":\"0.35\", \"best_ask\":\"0.36\"}], \"timestamp\":\"1785208033834\", \"event_type\":\"price_change\"}","received_at":"2026-07-28T03:07:17.605704Z","schema_version":"clob-market-ws.price_change.v1","sequence":null,"server_hash":null,"server_timestamp":"1785208033834","session_id":"3e519d9098404c15b234d96025eb1a2b","source":"clob_market_ws"},"received_at":"2026-07-28T03:07:17.605704Z","record_id":"10a439108df9a6949fe02491ad3bcb790386b073164c71c92d3fabd336753cfb","schema_fingerprint":"4aa3821a28b0b7c2400bc59aba4bcc0a76e971dadd19610d3ad38c768e124dc7","schema_version":"edge-lab-recorder.raw.v1","sequence":null,"source":"clob_market_ws"}
{"event_at":"2026-07-28T03:07:13.839000Z","event_fingerprint":"49a012ffc664422187b139f50938b876b7a796fa0481a4030571a80ed6dc4c1c","payload":{"connection_id":"a6b55582af5f430fb37ad02bf0922475","event_at":"2026-07-28T03:07:13.839000Z","event_type":"price_change","frame_hash":"3d379b91a1ebfe706466ceb9a33052cd4672cf96565939c0e33e1dbd0f6a94e9","frame_index":0,"kind":"data","monotonic_ns":310020640551541,"payload":{"event_type":"price_change","market":"0x779291bef19b6709f61e9764a954aafe9ffae488d50ae674aabdcb4f248006d5","price_changes":[{"asset_id":"14965588658799411272385430903075831224615961675357217884735713260981483529984","best_ask":"0.36","best_bid":"0.35","hash":"f15fcf44230619752eea8fce136c47be77e1e7c7","price":"0.25","side":"BUY","size":"250"},{"asset_id":"8761897749749422724209054078244794145777693856614463256546737399611489089783","best_ask":"0.65","best_bid":"0.64","hash":"5256af35873989b2cdd45b2f9b77bec936dfe713","price":"0.75","side":"SELL","size":"250"}],"timestamp":"1785208033839"},"payload_hash":"de804e9eb3e1a8cfa655ab772888189bbeec195c7ea1e3ce5b120d71829fbf5b","raw_frame":"{\"market\":\"0x779291bef19b6709f61e9764a954aafe9ffae488d50ae674aabdcb4f248006d5\", \"price_changes\":[{\"asset_id\":\"14965588658799411272385430903075831224615961675357217884735713260981483529984\", \"price\":\"0.25\", \"size\":\"250\", \"side\":\"BUY\", \"hash\":\"f15fcf44230619752eea8fce136c47be77e1e7c7\", \"best_bid\":\"0.35\", \"best_ask\":\"0.36\"}, {\"asset_id\":\"8761897749749422724209054078244794145777693856614463256546737399611489089783\", \"price\":\"0.75\", \"size\":\"250\", \"side\":\"SELL\", \"hash\":\"5256af35873989b2cdd45b2f9b77bec936dfe713\", \"best_bid\":\"0.64\", \"best_ask\":\"0.65\"}], \"timestamp\":\"1785208033839\", \"event_type\":\"price_change\"}","received_at":"2026-07-28T03:07:17.608652Z","schema_version":"clob-market-ws.price_change.v1","sequence":null,"server_hash":null,"server_timestamp":"1785208033839","session_id":"3e519d9098404c15b234d96025eb1a2b","source":"clob_market_ws"},"received_at":"2026-07-28T03:07:17.608652Z","record_id":"e3343af198b000f8ea75b7727787db2aa15f23059808a4c2b41582a3a13ebc65","schema_fingerprint":"4aa3821a28b0b7c2400bc59aba4bcc0a76e971dadd19610d3ad38c768e124dc7","schema_version":"edge-lab-recorder.raw.v1","sequence":null,"source":"clob_market_ws"}
{"event_at":"2026-07-28T03:07:13.839000Z","event_fingerprint":"2c848210ece600e958d9b1861a7af237c2a4ee6ce548172607d2ce1ba9936ad7","payload":{"connection_id":"a6b55582af5f430fb37ad02bf0922475","event_at":"2026-07-28T03:07:13.839000Z","event_type":"price_change","frame_hash":"197671c8a8990fc43ee168fdee61da7d813bdc1d12ca0f38ac17dd269576edf8","frame_index":0,"kind":"data","monotonic_ns":310020646326666,"payload":{"event_type":"price_change","market":"0x779291bef19b6709f61e9764a954aafe9ffae488d50ae674aabdcb4f248006d5","price_changes":[{"asset_id":"14965588658799411272385430903075831224615961675357217884735713260981483529984","best_ask":"0.36","best_bid":"0.35","hash":"1c5909b8e9ee969901629d90c36177009f7c590a","price":"0.33","side":"BUY","size":"155.6"},{"asset_id":"8761897749749422724209054078244794145777693856614463256546737399611489089783","best_ask":"0.65","best_bid":"0.64","hash":"d09480de4894ac0124260feb9020bf07b89c2dd3","price":"0.67","side":"SELL","size":"155.6"}],"timestamp":"1785208033839"},"payload_hash":"3b01a4ae7e86aed2d090873d3e6cdb712f448d4dca36786a68a60ad40123fa1b","raw_frame":"{\"market\":\"0x779291bef19b6709f61e9764a954aafe9ffae488d50ae674aabdcb4f248006d5\", \"price_changes\":[{\"asset_id\":\"14965588658799411272385430903075831224615961675357217884735713260981483529984\", \"price\":\"0.33\", \"size\":\"155.6\", \"side\":\"BUY\", \"hash\":\"1c5909b8e9ee969901629d90c36177009f7c590a\", \"best_bid\":\"0.35\", \"best_ask\":\"0.36\"}, {\"asset_id\":\"8761897749749422724209054078244794145777693856614463256546737399611489089783\", \"price\":\"0.67\", \"size\":\"155.6\", \"side\":\"SELL\", \"hash\":\"d09480de4894ac0124260feb9020bf07b89c2dd3\", \"best_bid\":\"0.64\", \"best_ask\":\"0.65\"}], \"timestamp\":\"1785208033839\", \"event_type\":\"price_change\"}","received_at":"2026-07-28T03:07:17.614427Z","schema_version":"clob-market-ws.price_change.v1","sequence":null,"server_hash":null,"server_timestamp":"1785208033839","session_id":"3e519d9098404c15b234d96025eb1a2b","source":"clob_market_ws"},"received_at":"2026-07-28T03:07:17.614427Z","record_id":"00039a98bc1d8c3e4b5219c59f56205af2ec3ccaf8b8a61a3cdb966521aff279","schema_fingerprint":"4aa3821a28b0b7c2400bc59aba4bcc0a76e971dadd19610d3ad38c768e124dc7","schema_version":"edge-lab-recorder.raw.v1","sequence":null,"source":"clob_market_ws"}
{"event_at":"2026-07-28T03:07:13.846000Z","event_fingerprint":"3d466c7dc4adc54cce00ae71ee751635e98c3dac0687eea4b1dc4be000e7cc19","payload":{"connection_id":"a6b55582af5f430fb37ad02bf0922475","event_at":"2026-07-28T03:07:13.846000Z","event_type":"price_change","frame_hash":"2e8e58736c062ae2e9de8c33bd5dc585e3274cb7485c24a38d5863846e89f3ef","frame_index":0,"kind":"data","monotonic_ns":310020660840416,"payload":{"event_type":"price_change","market":"0x779291bef19b6709f61e9764a954aafe9ffae488d50ae674aabdcb4f248006d5","price_changes":[{"asset_id":"8761897749749422724209054078244794145777693856614463256546737399611489089783","best_ask":"0.65","best_bid":"0.64","hash":"1f53601b08937684410ab67dbf6015dae7a8603b","price":"0.61","side":"BUY","size":"63"},{"asset_id":"14965588658799411272385430903075831224615961675357217884735713260981483529984","best_ask":"0.36","best_bid":"0.35","hash":"bc751b1ddc2318eb17eba9a5542f5a7ea02506a4","price":"0.39","side":"SELL","size":"63"}],"timestamp":"1785208033846"},"payload_hash":"475d62a6a6507e858bc569d6990e85e3808c88bfafefab01c3bc753823b9b402","raw_frame":"{\"market\":\"0x779291bef19b6709f61e9764a954aafe9ffae488d50ae674aabdcb4f248006d5\", \"price_changes\":[{\"asset_id\":\"8761897749749422724209054078244794145777693856614463256546737399611489089783\", \"price\":\"0.61\", \"size\":\"63\", \"side\":\"BUY\", \"hash\":\"1f53601b08937684410ab67dbf6015dae7a8603b\", \"best_bid\":\"0.64\", \"best_ask\":\"0.65\"}, {\"asset_id\":\"14965588658799411272385430903075831224615961675357217884735713260981483529984\", \"price\":\"0.39\", \"size\":\"63\", \"side\":\"SELL\", \"hash\":\"bc751b1ddc2318eb17eba9a5542f5a7ea02506a4\", \"best_bid\":\"0.35\", \"best_ask\":\"0.36\"}], \"timestamp\":\"1785208033846\", \"event_type\":\"price_change\"}","received_at":"2026-07-28T03:07:17.628940Z","schema_version":"clob-market-ws.price_change.v1","sequence":null,"server_hash":null,"server_timestamp":"1785208033846","session_id":"3e519d9098404c15b234d96025eb1a2b","source":"clob_market_ws"},"received_at":"2026-07-28T03:07:17.628940Z","record_id":"36448db462686ee5562853b9e12672accba31a38166198a9f129f90b21f1b79a","schema_fingerprint":"4aa3821a28b0b7c2400bc59aba4bcc0a76e971dadd19610d3ad38c768e124dc7","schema_version":"edge-lab-recorder.raw.v1","sequence":null,"source":"clob_market_ws"}
{"event_at":"2026-07-28T03:07:13.862000Z","event_fingerprint":"f913aa86acba2f48b6b940ac64d4453d33a2e002dd94d0dcd8dac56199872cc4","payload":{"connection_id":"a6b55582af5f430fb37ad02bf0922475","event_at":"2026-07-28T03:07:13.862000Z","event_type":"price_change","frame_hash":"1b7f662221ee93cec0f7d3e837a173876b574257dee66a5dda0d3a079adde925","frame_index":0,"kind":"data","monotonic_ns":310020673981958,"payload":{"event_type":"price_change","market":"0x779291bef19b6709f61e9764a954aafe9ffae488d50ae674aabdcb4f248006d5","price_changes":[{"asset_id":"14965588658799411272385430903075831224615961675357217884735713260981483529984","best_ask":"0.36","best_bid":"0.35","hash":"082aa4259f0c1d425aa7db34a9f7697c5763414a","price":"0.22","side":"BUY","size":"318"},{"asset_id":"8761897749749422724209054078244794145777693856614463256546737399611489089783","best_ask":"0.65","best_bid":"0.64","hash":"7ee98737880497ce2f34655a3784e274f92fc7f1","price":"0.78","side":"SELL","size":"318"}],"timestamp":"1785208033862"},"payload_hash":"e03070b6770ca5916c446795cd8659a2059c4d3db4e9d886bd435815641d103b","raw_frame":"{\"market\":\"0x779291bef19b6709f61e9764a954aafe9ffae488d50ae674aabdcb4f248006d5\", \"price_changes\":[{\"asset_id\":\"14965588658799411272385430903075831224615961675357217884735713260981483529984\", \"price\":\"0.22\", \"size\":\"318\", \"side\":\"BUY\", \"hash\":\"082aa4259f0c1d425aa7db34a9f7697c5763414a\", \"best_bid\":\"0.35\", \"best_ask\":\"0.36\"}, {\"asset_id\":\"8761897749749422724209054078244794145777693856614463256546737399611489089783\", \"price\":\"0.78\", \"size\":\"318\", \"side\":\"SELL\", \"hash\":\"7ee98737880497ce2f34655a3784e274f92fc7f1\", \"best_bid\":\"0.64\", \"best_ask\":\"0.65\"}], \"timestamp\":\"1785208033862\", \"event_type\":\"price_change\"}","received_at":"2026-07-28T03:07:17.642080Z","schema_version":"clob-market-ws.price_change.v1","sequence":null,"server_hash":null,"server_timestamp":"1785208033862","session_id":"3e519d9098404c15b234d96025eb1a2b","source":"clob_market_ws"},"received_at":"2026-07-28T03:07:17.642080Z","record_id":"b6f562f7d33a2694e5bbeeac075d09d3ea2858bc9279b09e17fc9d9eaa69918e","schema_fingerprint":"4aa3821a28b0b7c2400bc59aba4bcc0a76e971dadd19610d3ad38c768e124dc7","schema_version":"edge-lab-recorder.raw.v1","sequence":null,"source":"clob_market_ws"}
{"event_at":"2026-07-28T03:07:13.875000Z","event_fingerprint":"8e2fcfe13ea2d0b2f1de0311216ebe8f7e45463c9745d91d5eb82723a4f84d2a","payload":{"connection_id":"a6b55582af5f430fb37ad02bf0922475","event_at":"2026-07-28T03:07:13.875000Z","event_type":"price_change","frame_hash":"647139c54cb755ec7db93aced48e9cf68d21c9b11c85fc4eb08f026eab1f480c","frame_index":0,"kind":"data","monotonic_ns":310020676927125,"payload":{"event_type":"price_change","market":"0x779291bef19b6709f61e9764a954aafe9ffae488d50ae674aabdcb4f248006d5","price_changes":[{"asset_id":"14965588658799411272385430903075831224615961675357217884735713260981483529984","best_ask":"0.36","best_bid":"0.35","hash":"0e70504728be60adccc2cd5bbbf6a5bab046335f","price":"0.14","side":"BUY","size":"612.9"},{"asset_id":"8761897749749422724209054078244794145777693856614463256546737399611489089783","best_ask":"0.65","best_bid":"0.64","hash":"a43f97ccb99c539ce40eea84e53736e05ba92098","price":"0.86","side":"SELL","size":"612.9"}],"timestamp":"1785208033875"},"payload_hash":"82a77d8fa8f92954e01114988a0c47266df3f179a81e8d09180b3f2f7e700b9a","raw_frame":"{\"market\":\"0x779291bef19b6709f61e9764a954aafe9ffae488d50ae674aabdcb4f248006d5\", \"price_changes\":[{\"asset_id\":\"14965588658799411272385430903075831224615961675357217884735713260981483529984\", \"price\":\"0.14\", \"size\":\"612.9\", \"side\":\"BUY\", \"hash\":\"0e70504728be60adccc2cd5bbbf6a5bab046335f\", \"best_bid\":\"0.35\", \"best_ask\":\"0.36\"}, {\"asset_id\":\"8761897749749422724209054078244794145777693856614463256546737399611489089783\", \"price\":\"0.86\", \"size\":\"612.9\", \"side\":\"SELL\", \"hash\":\"a43f97ccb99c539ce40eea84e53736e05ba92098\", \"best_bid\":\"0.64\", \"best_ask\":\"0.65\"}], \"timestamp\":\"1785208033875\", \"event_type\":\"price_change\"}","received_at":"2026-07-28T03:07:17.645025Z","schema_version":"clob-market-ws.price_change.v1","sequence":null,"server_hash":null,"server_timestamp":"1785208033875","session_id":"3e519d9098404c15b234d96025eb1a2b","source":"clob_market_ws"},"received_at":"2026-07-28T03:07:17.645025Z","record_id":"4a4eb800ee458988605ccc270e55338f7e2b5796a88aacbeafcf3e0c1330560f","schema_fingerprint":"4aa3821a28b0b7c2400bc59aba4bcc0a76e971dadd19610d3ad38c768e124dc7","schema_version":"edge-lab-recorder.raw.v1","sequence":null,"source":"clob_market_ws"}
{"event_at":"2026-07-28T03:07:13.876000Z","event_fingerprint":"62123166f0ee3fb4999cfa7815eee3c0af9a273c3f7317d923b3a82704cbf35a","payload":{"connection_id":"a6b55582af5f430fb37ad02bf0922475","event_at":"2026-07-28T03:07:13.876000Z","event_type":"price_change","frame_hash":"e498d00e3e66112a131d043b5d3476d1c0e44a8df9bb5044fe9ab81f91b1286b","frame_index":0,"kind":"data","monotonic_ns":310020679980625,"payload":{"event_type":"price_change","market":"0x779291bef19b6709f61e9764a954aafe9ffae488d50ae674aabdcb4f248006d5","price_changes":[{"asset_id":"14965588658799411272385430903075831224615961675357217884735713260981483529984","best_ask":"0.36","best_bid":"0.35","hash":"1c7fd61811eb12a25971985fb88a4f015c079e11","price":"0.32","side":"BUY","size":"55.48"},{"asset_id":"8761897749749422724209054078244794145777693856614463256546737399611489089783","best_ask":"0.65","best_bid":"0.64","hash":"b1dfca900e02fa4ae2ba702483051b10fd177405","price":"0.68","side":"SELL","size":"55.48"}],"timestamp":"1785208033876"},"payload_hash":"159a58bb29e1c8fb7a6d608a514299a17d92c6b3ed5fab5f046136c8068dc310","raw_frame":"{\"market\":\"0x779291bef19b6709f61e9764a954aafe9ffae488d50ae674aabdcb4f248006d5\", \"price_changes\":[{\"asset_id\":\"14965588658799411272385430903075831224615961675357217884735713260981483529984\", \"price\":\"0.32\", \"size\":\"55.48\", \"side\":\"BUY\", \"hash\":\"1c7fd61811eb12a25971985fb88a4f015c079e11\", \"best_bid\":\"0.35\", \"best_ask\":\"0.36\"}, {\"asset_id\":\"8761897749749422724209054078244794145777693856614463256546737399611489089783\", \"price\":\"0.68\", \"size\":\"55.48\", \"side\":\"SELL\", \"hash\":\"b1dfca900e02fa4ae2ba702483051b10fd177405\", \"best_bid\":\"0.64\", \"best_ask\":\"0.65\"}], \"timestamp\":\"1785208033876\", \"event_type\":\"price_change\"}","received_at":"2026-07-28T03:07:17.648079Z","schema_version":"clob-market-ws.price_change.v1","sequence":null,"server_hash":null,"server_timestamp":"1785208033876","session_id":"3e519d9098404c15b234d96025eb1a2b","source":"clob_market_ws"},"received_at":"2026-07-28T03:07:17.648079Z","record_id":"2e06ed4bda56289d01adbaa0fd338896475099a30c238df31d5771a82ddba3f7","schema_fingerprint":"4aa3821a28b0b7c2400bc59aba4bcc0a76e971dadd19610d3ad38c768e124dc7","schema_version":"edge-lab-recorder.raw.v1","sequence":null,"source":"clob_market_ws"}
{"event_at":"2026-07-28T03:07:13.877000Z","event_fingerprint":"738da79c0f64ed7ecfa74bf55ba20246d13d9914f56865fe277a411396e8679e","payload":{"connection_id":"a6b55582af5f430fb37ad02bf0922475","event_at":"2026-07-28T03:07:13.877000Z","event_type":"price_change","frame_hash":"60d2c3166fc2eedd2530d93fe4a823ab9c217c78fbe19e00133081c97a7cf93d","frame_index":0,"kind":"data","monotonic_ns":310020682995333,"payload":{"event_type":"price_change","market":"0x779291bef19b6709f61e9764a954aafe9ffae488d50ae674aabdcb4f248006d5","price_changes":[{"asset_id":"14965588658799411272385430903075831224615961675357217884735713260981483529984","best_ask":"0.36","best_bid":"0.35","hash":"8ce7c68ee705340c7b6e992b7f253def2f328ca6","price":"0.33","side":"BUY","size":"168.2"},{"asset_id":"8761897749749422724209054078244794145777693856614463256546737399611489089783","best_ask":"0.65","best_bid":"0.64","hash":"c44a87412f733474c6a5c651ee23a200f618192f","price":"0.67","side":"SELL","size":"168.2"}],"timestamp":"1785208033877"},"payload_hash":"7b48e9c66c32f219734f29b5282f88f149d1a5d47b2872fa75c2624217bf5bce","raw_frame":"{\"market\":\"0x779291bef19b6709f61e9764a954aafe9ffae488d50ae674aabdcb4f248006d5\", \"price_changes\":[{\"asset_id\":\"14965588658799411272385430903075831224615961675357217884735713260981483529984\", \"price\":\"0.33\", \"size\":\"168.2\", \"side\":\"BUY\", \"hash\":\"8ce7c68ee705340c7b6e992b7f253def2f328ca6\", \"best_bid\":\"0.35\", \"best_ask\":\"0.36\"}, {\"asset_id\":\"8761897749749422724209054078244794145777693856614463256546737399611489089783\", \"price\":\"0.67\", \"size\":\"168.2\", \"side\":\"SELL\", \"hash\":\"c44a87412f733474c6a5c651ee23a200f618192f\", \"best_bid\":\"0.64\", \"best_ask\":\"0.65\"}], \"timestamp\":\"1785208033877\", \"event_type\":\"price_change\"}","received_at":"2026-07-28T03:07:17.651094Z","schema_version":"clob-market-ws.price_change.v1","sequence":null,"server_hash":null,"server_timestamp":"1785208033877","session_id":"3e519d9098404c15b234d96025eb1a2b","source":"clob_market_ws"},"received_at":"2026-07-28T03:07:17.651094Z","record_id":"de048845284d4835e1d4e458942dc3b938f0b8d066cc955ebfc9b8ef5ba205e3","schema_fingerprint":"4aa3821a28b0b7c2400bc59aba4bcc0a76e971dadd19610d3ad38c768e124dc7","schema_version":"edge-lab-recorder.raw.v1","sequence":null,"source":"clob_market_ws"}
{"event_at":"2026-07-28T03:07:13.877000Z","event_fingerprint":"83b7057376a7d922e4e03c59b73340fb21056fdc80e30ecb9a63c74cac51fa87","payload":{"connection_id":"a6b55582af5f430fb37ad02bf0922475","event_at":"2026-07-28T03:07:13.877000Z","event_type":"price_change","frame_hash":"3f1d853b7a05d2e7bb5dd046d759d693ba6a0beec2b917f9e1e94494724d00c7","frame_index":0,"kind":"data","monotonic_ns":310020685996791,"payload":{"event_type":"price_change","market":"0x779291bef19b6709f61e9764a954aafe9ffae488d50ae674aabdcb4f248006d5","price_changes":[{"asset_id":"14965588658799411272385430903075831224615961675357217884735713260981483529984","best_ask":"0.36","best_bid":"0.35","hash":"f711770bcde06a9542fa3195c783950de997488b","price":"0.33","side":"BUY","size":"438.2"},{"asset_id":"8761897749749422724209054078244794145777693856614463256546737399611489089783","best_ask":"0.65","best_bid":"0.64","hash":"6c88e1c58b1f53ff2fc6a8e78f74049ff8ec68a2","price":"0.67","side":"SELL","size":"438.2"}],"timestamp":"1785208033877"},"payload_hash":"749a149c32ac127d2b3de93172358e31af0a89bb0b952e8c07e3792483ba7421","raw_frame":"{\"market\":\"0x779291bef19b6709f61e9764a954aafe9ffae488d50ae674aabdcb4f248006d5\", \"price_changes\":[{\"asset_id\":\"14965588658799411272385430903075831224615961675357217884735713260981483529984\", \"price\":\"0.33\", \"size\":\"438.2\", \"side\":\"BUY\", \"hash\":\"f711770bcde06a9542fa3195c783950de997488b\", \"best_bid\":\"0.35\", \"best_ask\":\"0.36\"}, {\"asset_id\":\"8761897749749422724209054078244794145777693856614463256546737399611489089783\", \"price\":\"0.67\", \"size\":\"438.2\", \"side\":\"SELL\", \"hash\":\"6c88e1c58b1f53ff2fc6a8e78f74049ff8ec68a2\", \"best_bid\":\"0.64\", \"best_ask\":\"0.65\"}], \"timestamp\":\"1785208033877\", \"event_type\":\"price_change\"}","received_at":"2026-07-28T03:07:17.654095Z","schema_version":"clob-market-ws.price_change.v1","sequence":null,"server_hash":null,"server_timestamp":"1785208033877","session_id":"3e519d9098404c15b234d96025eb1a2b","source":"clob_market_ws"},"received_at":"2026-07-28T03:07:17.654095Z","record_id":"4c50cecd20cc194b92ec8ce152705ce868b86b25954ee86eb980e0bfd88817c8","schema_fingerprint":"4aa3821a28b0b7c2400bc59aba4bcc0a76e971dadd19610d3ad38c768e124dc7","schema_version":"edge-lab-recorder.raw.v1","sequence":null,"source":"clob_market_ws"}
{"event_at":"2026-07-28T03:07:13.881000Z","event_fingerprint":"1621562ba0156f7dc046138db2ec5425860be4ce226918735f9a3d806f0088a4","payload":{"connection_id":"a6b55582af5f430fb37ad02bf0922475","event_at":"2026-07-28T03:07:13.881000Z","event_type":"price_change","frame_hash":"32a08dd9a3fc86a23f4f823b1b7ac1457c4ccac0025b2d05b43d07c48570200c","frame_index":0,"kind":"data","monotonic_ns":310020689010583,"payload":{"event_type":"price_change","market":"0x779291bef19b6709f61e9764a954aafe9ffae488d50ae674aabdcb4f248006d5","price_changes":[{"asset_id":"8761897749749422724209054078244794145777693856614463256546737399611489089783","best_ask":"0.65","best_bid":"0.64","hash":"ee2bfc2422ac8438cf9a2cfc677814e3c2962be8","price":"0.04","side":"BUY","size":"588.09"},{"asset_id":"14965588658799411272385430903075831224615961675357217884735713260981483529984","best_ask":"0.36","best_bid":"0.35","hash":"57e51b1a40dbfa99ce5a7be7efbbbb0bf6e68e65","price":"0.96","side":"SELL","size":"588.09"}],"timestamp":"1785208033881"},"payload_hash":"4a8c5b3c067b52196db30c5cbc83e49652c9efea0e96483d463fee1eb04bc08b","raw_frame":"{\"market\":\"0x779291bef19b6709f61e9764a954aafe9ffae488d50ae674aabdcb4f248006d5\", \"price_changes\":[{\"asset_id\":\"8761897749749422724209054078244794145777693856614463256546737399611489089783\", \"price\":\"0.04\", \"size\":\"588.09\", \"side\":\"BUY\", \"hash\":\"ee2bfc2422ac8438cf9a2cfc677814e3c2962be8\", \"best_bid\":\"0.64\", \"best_ask\":\"0.65\"}, {\"asset_id\":\"14965588658799411272385430903075831224615961675357217884735713260981483529984\", \"price\":\"0.96\", \"size\":\"588.09\", \"side\":\"SELL\", \"hash\":\"57e51b1a40dbfa99ce5a7be7efbbbb0bf6e68e65\", \"best_bid\":\"0.35\", \"best_ask\":\"0.36\"}], \"timestamp\":\"1785208033881\", \"event_type\":\"price_change\"}","received_at":"2026-07-28T03:07:17.657109Z","schema_version":"clob-market-ws.price_change.v1","sequence":null,"server_hash":null,"server_timestamp":"1785208033881","session_id":"3e519d9098404c15b234d96025eb1a2b","source":"clob_market_ws"},"received_at":"2026-07-28T03:07:17.657109Z","record_id":"e6029df3f7f9b6fdc3b10a7f373bd871f1a999064e343e7f2a256209f3fe19bf","schema_fingerprint":"4aa3821a28b0b7c2400bc59aba4bcc0a76e971dadd19610d3ad38c768e124dc7","schema_version":"edge-lab-recorder.raw.v1","sequence":null,"source":"clob_market_ws"}
