{"event_at":"2026-07-28T03:09:18.635000Z","event_fingerprint":"4a3fe401f021943c33df3ede0ac2fffe045002f743ce2b869c70a9f1552be795","payload":{"connection_id":"a6b55582af5f430fb37ad02bf0922475","event_at":"2026-07-28T03:09:18.635000Z","event_type":"price_change","frame_hash":"d24c4674ebf7e89fde405bf707ae78165a25adc2b718af056ab5ac62ea39346c","frame_index":0,"kind":"data","monotonic_ns":310141556517750,"payload":{"event_type":"price_change","market":"0x779291bef19b6709f61e9764a954aafe9ffae488d50ae674aabdcb4f248006d5","price_changes":[{"asset_id":"14965588658799411272385430903075831224615961675357217884735713260981483529984","best_ask":"0.33","best_bid":"0.32","hash":"522b8b208128d4f72a71a5198e4b050b1e1e45fe","price":"0.28","side":"BUY","size":"145"},{"asset_id":"8761897749749422724209054078244794145777693856614463256546737399611489089783","best_ask":"0.68","best_bid":"0.67","hash":"f2cc916bf92b3d3c15eeb581057d373144346571","price":"0.72","side":"SELL","size":"145"}],"timestamp":"1785208158635"},"payload_hash":"1fd085cc485474cde0ca29626a02932879143bbaa0cf812b13f7aaeeb99fb63a","raw_frame":"{\"market\":\"0x779291bef19b6709f61e9764a954aafe9ffae488d50ae674aabdcb4f248006d5\", \"price_changes\":[{\"asset_id\":\"14965588658799411272385430903075831224615961675357217884735713260981483529984\", \"price\":\"0.28\", \"size\":\"145\", \"side\":\"BUY\", \"hash\":\"522b8b208128d4f72a71a5198e4b050b1e1e45fe\", \"best_bid\":\"0.32\", \"best_ask\":\"0.33\"}, {\"asset_id\":\"8761897749749422724209054078244794145777693856614463256546737399611489089783\", \"price\":\"0.72\", \"size\":\"145\", \"side\":\"SELL\", \"hash\":\"f2cc916bf92b3d3c15eeb581057d373144346571\", \"best_bid\":\"0.67\", \"best_ask\":\"0.68\"}], \"timestamp\":\"1785208158635\", \"event_type\":\"price_change\"}","received_at":"2026-07-28T03:09:18.523563Z","schema_version":"clob-market-ws.price_change.v1","sequence":null,"server_hash":null,"server_timestamp":"1785208158635","session_id":"3e519d9098404c15b234d96025eb1a2b","source":"clob_market_ws"},"received_at":"2026-07-28T03:09:18.523563Z","record_id":"22e8cf48f9bc8759e1c9d1ccc48b7869427446c738470802f921ecadc16bad4d","schema_fingerprint":"4aa3821a28b0b7c2400bc59aba4bcc0a76e971dadd19610d3ad38c768e124dc7","schema_version":"edge-lab-recorder.raw.v1","sequence":null,"source":"clob_market_ws"}
{"event_at":"2026-07-28T03:09:18.635000Z","event_fingerprint":"cbc1728fa59b364ee09370be681fa4f5711d1ad9e41f6f45bb9e6e50d1ad0eec","payload":{"connection_id":"a6b55582af5f430fb37ad02bf0922475","event_at":"2026-07-28T03:09:18.635000Z","event_type":"price_change","frame_hash":"8b6f30d9cb43482ed44107d3104215bee298d488d8d5c0746a0f35c6b97ad85a","frame_index":0,"kind":"data","monotonic_ns":310141558721750,"payload":{"event_type":"price_change","market":"0x779291bef19b6709f61e9764a954aafe9ffae488d50ae674aabdcb4f248006d5","price_changes":[{"asset_id":"14965588658799411272385430903075831224615961675357217884735713260981483529984","best_ask":"0.33","best_bid":"0.32","hash":"81a40923e9723cedee9d11277d9b0cfdd46f065b","price":"0.33","side":"SELL","size":"96.6"},{"asset_id":"8761897749749422724209054078244794145777693856614463256546737399611489089783","best_ask":"0.68","best_bid":"0.67","hash":"c7197a2d0da300b754d32e9c20ef75da5fa1c7e0","price":"0.67","side":"BUY","size":"96.6"}],"timestamp":"1785208158635"},"payload_hash":"995dcf3c0d9e4708d5ec4bec84130514dd16aa87c037435ede34b177349f8182","raw_frame":"{\"market\":\"0x779291bef19b6709f61e9764a954aafe9ffae488d50ae674aabdcb4f248006d5\", \"price_changes\":[{\"asset_id\":\"14965588658799411272385430903075831224615961675357217884735713260981483529984\", \"price\":\"0.33\", \"size\":\"96.6\", \"side\":\"SELL\", \"hash\":\"81a40923e9723cedee9d11277d9b0cfdd46f065b\", \"best_bid\":\"0.32\", \"best_ask\":\"0.33\"}, {\"asset_id\":\"8761897749749422724209054078244794145777693856614463256546737399611489089783\", \"price\":\"0.67\", \"size\":\"96.6\", \"side\":\"BUY\", \"hash\":\"c7197a2d0da300b754d32e9c20ef75da5fa1c7e0\", \"best_bid\":\"0.67\", \"best_ask\":\"0.68\"}], \"timestamp\":\"1785208158635\", \"event_type\":\"price_change\"}","received_at":"2026-07-28T03:09:18.525768Z","schema_version":"clob-market-ws.price_change.v1","sequence":null,"server_hash":null,"server_timestamp":"1785208158635","session_id":"3e519d9098404c15b234d96025eb1a2b","source":"clob_market_ws"},"received_at":"2026-07-28T03:09:18.525768Z","record_id":"e102cf4dec59b2dd93c09d285147bc3260c7fc165b99c50686f4ed3273b918ea","schema_fingerprint":"4aa3821a28b0b7c2400bc59aba4bcc0a76e971dadd19610d3ad38c768e124dc7","schema_version":"edge-lab-recorder.raw.v1","sequence":null,"source":"clob_market_ws"}
{"event_at":"2026-07-28T03:09:18.636000Z","event_fingerprint":"354230840185202880f633670aad09c302b01d554df9bf57c3a81b3432357ee1","payload":{"connection_id":"a6b55582af5f430fb37ad02bf0922475","event_at":"2026-07-28T03:09:18.636000Z","event_type":"price_change","frame_hash":"621775c9b60f896dba5fb34632b2b594d3f0aac0e75dd66bf5b8ef3460fdbbb7","frame_index":0,"kind":"data","monotonic_ns":310141560986625,"payload":{"event_type":"price_change","market":"0x779291bef19b6709f61e9764a954aafe9ffae488d50ae674aabdcb4f248006d5","price_changes":[{"asset_id":"14965588658799411272385430903075831224615961675357217884735713260981483529984","best_ask":"0.33","best_bid":"0.32","hash":"577e09b9c6187068dd8d3c37569ea1783c5ba81e","price":"0.28","side":"BUY","size":"49"},{"asset_id":"8761897749749422724209054078244794145777693856614463256546737399611489089783","best_ask":"0.68","best_bid":"0.67","hash":"35e9745cda5d1fd1d8ea27631022030ca2e62773","price":"0.72","side":"SELL","size":"49"}],"timestamp":"1785208158636"},"payload_hash":"22260e24b9201ecd4f240743cc9741094799aba0e096c4769f0aedf58a4fb26b","raw_frame":"{\"market\":\"0x779291bef19b6709f61e9764a954aafe9ffae488d50ae674aabdcb4f248006d5\", \"price_changes\":[{\"asset_id\":\"14965588658799411272385430903075831224615961675357217884735713260981483529984\", \"price\":\"0.28\", \"size\":\"49\", \"side\":\"BUY\", \"hash\":\"577e09b9c6187068dd8d3c37569ea1783c5ba81e\", \"best_bid\":\"0.32\", \"best_ask\":\"0.33\"}, {\"asset_id\":\"8761897749749422724209054078244794145777693856614463256546737399611489089783\", \"price\":\"0.72\", \"size\":\"49\", \"side\":\"SELL\", \"hash\":\"35e9745cda5d1fd1d8ea27631022030ca2e62773\", \"best_bid\":\"0.67\", \"best_ask\":\"0.68\"}], \"timestamp\":\"1785208158636\", \"event_type\":\"price_change\"}","received_at":"2026-07-28T03:09:18.528033Z","schema_version":"clob-market-ws.price_change.v1","sequence":null,"server_hash":null,"server_timestamp":"1785208158636","session_id":"3e519d9098404c15b234d96025eb1a2b","source":"clob_market_ws"},"received_at":"2026-07-28T03:09:18.528033Z","record_id":"702f4f33cde385d46bed98ca0bde87e6ba20d95287f697a1d31c778dfe630407","schema_fingerprint":"4aa3821a28b0b7c2400bc59aba4bcc0a76e971dadd19610d3ad38c768e124dc7","schema_version":"edge-lab-recorder.raw.v1","sequence":null,"source":"clob_market_ws"}
{"event_at":"2026-07-28T03:09:18.637000Z","event_fingerprint":"6e5fab1e2d54a6125acd75c4bc4c0b96ff16c53ca395b75501e85289c9e23f60","payload":{"connection_id":"a6b55582af5f430fb37ad02bf0922475","event_at":"2026-07-28T03:09:18.637000Z","event_type":"price_change","frame_hash":"0924d49c473dcfbd77ce199fec376cd5b3c306a0502bfb6f85cd1488c01c848f","frame_index":0,"kind":"data","monotonic_ns":310141562535250,"payload":{"event_type":"price_change","market":"0x779291bef19b6709f61e9764a954aafe9ffae488d50ae674aabdcb4f248006d5","price_changes":[{"asset_id":"8761897749749422724209054078244794145777693856614463256546737399611489089783","best_ask":"0.68","best_bid":"0.67","hash":"ff78e56991eee5e5754e6dc48637f90f0d39db9d","price":"0.61","side":"BUY","size":"96.94"},{"asset_id":"14965588658799411272385430903075831224615961675357217884735713260981483529984","best_ask":"0.33","best_bid":"0.32","hash":"d4e80c8268e7aa0b277f7a896cba950079040d21","price":"0.39","side":"SELL","size":"96.94"}],"timestamp":"1785208158637"},"payload_hash":"2385f6ac67c3f0406ef633c313caba5124972bc090ed6003564e704e853f695f","raw_frame":"{\"market\":\"0x779291bef19b6709f61e9764a954aafe9ffae488d50ae674aabdcb4f248006d5\", \"price_changes\":[{\"asset_id\":\"8761897749749422724209054078244794145777693856614463256546737399611489089783\", \"price\":\"0.61\", \"size\":\"96.94\", \"side\":\"BUY\", \"hash\":\"ff78e56991eee5e5754e6dc48637f90f0d39db9d\", \"best_bid\":\"0.67\", \"best_ask\":\"0.68\"}, {\"asset_id\":\"14965588658799411272385430903075831224615961675357217884735713260981483529984\", \"price\":\"0.39\", \"size\":\"96.94\", \"side\":\"SELL\", \"hash\":\"d4e80c8268e7aa0b277f7a896cba950079040d21\", \"best_bid\":\"0.32\", \"best_ask\":\"0.33\"}], \"timestamp\":\"1785208158637\", \"event_type\":\"price_change\"}","received_at":"2026-07-28T03:09:18.529583Z","schema_version":"clob-market-ws.price_change.v1","sequence":null,"server_hash":null,"server_timestamp":"1785208158637","session_id":"3e519d9098404c15b234d96025eb1a2b","source":"clob_market_ws"},"received_at":"2026-07-28T03:09:18.529583Z","record_id":"dad0bf1815198498c6e49a0e34014a3ac3cbf4faa0c05eb1e666f2f54446c20f","schema_fingerprint":"4aa3821a28b0b7c2400bc59aba4bcc0a76e971dadd19610d3ad38c768e124dc7","schema_version":"edge-lab-recorder.raw.v1","sequence":null,"source":"clob_market_ws"}
{"event_at":"2026-07-28T03:09:18.637000Z","event_fingerprint":"5a57fffa3e4cab1acf327af2db51de8c587d47568938a67cc6b58e541eb5ba38","payload":{"connection_id":"a6b55582af5f430fb37ad02bf0922475","event_at":"2026-07-28T03:09:18.637000Z","event_type":"price_change","frame_hash":"0c115ff7af836796ead4389f0f84446a742944649ffb1f745be0c62e41fe2350","frame_index":0,"kind":"data","monotonic_ns":310141564027166,"payload":{"event_type":"price_change","market":"0x779291bef19b6709f61e9764a954aafe9ffae488d50ae674aabdcb4f248006d5","price_changes":[{"asset_id":"14965588658799411272385430903075831224615961675357217884735713260981483529984","best_ask":"0.33","best_bid":"0.32","hash":"004735a08379c4da7cd0fa8994d871e4cebe4d6f","price":"0.29","side":"BUY","size":"47"},{"asset_id":"8761897749749422724209054078244794145777693856614463256546737399611489089783","best_ask":"0.68","best_bid":"0.67","hash":"70acb63624c7b89f5467089ea69cc13e9d4eb15e","price":"0.71","side":"SELL","size":"47"}],"timestamp":"1785208158637"},"payload_hash":"41721234b3af225e6c6e0c7c39b76cbc007117602274c18980aa83a96a0b53f5","raw_frame":"{\"market\":\"0x779291bef19b6709f61e9764a954aafe9ffae488d50ae674aabdcb4f248006d5\", \"price_changes\":[{\"asset_id\":\"14965588658799411272385430903075831224615961675357217884735713260981483529984\", \"price\":\"0.29\", \"size\":\"47\", \"side\":\"BUY\", \"hash\":\"004735a08379c4da7cd0fa8994d871e4cebe4d6f\", \"best_bid\":\"0.32\", \"best_ask\":\"0.33\"}, {\"asset_id\":\"8761897749749422724209054078244794145777693856614463256546737399611489089783\", \"price\":\"0.71\", \"size\":\"47\", \"side\":\"SELL\", \"hash\":\"70acb63624c7b89f5467089ea69cc13e9d4eb15e\", \"best_bid\":\"0.67\", \"best_ask\":\"0.68\"}], \"timestamp\":\"1785208158637\", \"event_type\":\"price_change\"}","received_at":"2026-07-28T03:09:18.531073Z","schema_version":"clob-market-ws.price_change.v1","sequence":null,"server_hash":null,"server_timestamp":"1785208158637","session_id":"3e519d9098404c15b234d96025eb1a2b","source":"clob_market_ws"},"received_at":"2026-07-28T03:09:18.531073Z","record_id":"7b8e359ef646ba8d6874c6e0c34a68208025658ff97c545dd8ce4e215163a375","schema_fingerprint":"4aa3821a28b0b7c2400bc59aba4bcc0a76e971dadd19610d3ad38c768e124dc7","schema_version":"edge-lab-recorder.raw.v1","sequence":null,"source":"clob_market_ws"}
{"event_at":"2026-07-28T03:09:18.639000Z","event_fingerprint":"de11d87b84d0018e77b0a2540ae63bd2ac9e2fc6d74edcb745f1ca3391758f00","payload":{"connection_id":"a6b55582af5f430fb37ad02bf0922475","event_at":"2026-07-28T03:09:18.639000Z","event_type":"price_change","frame_hash":"a932f11491f61ce719af933eedd7d3189d31bdb0c37b2def8798a26e853eb5ef","frame_index":0,"kind":"data","monotonic_ns":310141565601125,"payload":{"event_type":"price_change","market":"0x779291bef19b6709f61e9764a954aafe9ffae488d50ae674aabdcb4f248006d5","price_changes":[{"asset_id":"14965588658799411272385430903075831224615961675357217884735713260981483529984","best_ask":"0.33","best_bid":"0.32","hash":"05797c87add56d0db1af2ef788dea1c314bc772d","price":"0.16","side":"BUY","size":"326.3"},{"asset_id":"8761897749749422724209054078244794145777693856614463256546737399611489089783","best_ask":"0.68","best_bid":"0.67","hash":"f97996bb6f64f2a7dae6352c764de6db99de9fc1","price":"0.84","side":"SELL","size":"326.3"}],"timestamp":"1785208158639"},"payload_hash":"f0f6d6d49697dd3c1cc664e790282b35cc788693aac9ab0369d2d14c4276140b","raw_frame":"{\"market\":\"0x779291bef19b6709f61e9764a954aafe9ffae488d50ae674aabdcb4f248006d5\", \"price_changes\":[{\"asset_id\":\"14965588658799411272385430903075831224615961675357217884735713260981483529984\", \"price\":\"0.16\", \"size\":\"326.3\", \"side\":\"BUY\", \"hash\":\"05797c87add56d0db1af2ef788dea1c314bc772d\", \"best_bid\":\"0.32\", \"best_ask\":\"0.33\"}, {\"asset_id\":\"8761897749749422724209054078244794145777693856614463256546737399611489089783\", \"price\":\"0.84\", \"size\":\"326.3\", \"side\":\"SELL\", \"hash\":\"f97996bb6f64f2a7dae6352c764de6db99de9fc1\", \"best_bid\":\"0.67\", \"best_ask\":\"0.68\"}], \"timestamp\":\"1785208158639\", \"event_type\":\"price_change\"}","received_at":"2026-07-28T03:09:18.532648Z","schema_version":"clob-market-ws.price_change.v1","sequence":null,"server_hash":null,"server_timestamp":"1785208158639","session_id":"3e519d9098404c15b234d96025eb1a2b","source":"clob_market_ws"},"received_at":"2026-07-28T03:09:18.532648Z","record_id":"3f772bd1e7a035ae2f3144914f48cd700ae506bf194f7a255b917602c27d104f","schema_fingerprint":"4aa3821a28b0b7c2400bc59aba4bcc0a76e971dadd19610d3ad38c768e124dc7","schema_version":"edge-lab-recorder.raw.v1","sequence":null,"source":"clob_market_ws"}
{"event_at":"2026-07-28T03:09:18.641000Z","event_fingerprint":"741f42cbfcb05d0b3f42de9d516b2b7a2f8de1c08cc0ad9013f6ef01e5b702c2","payload":{"connection_id":"a6b55582af5f430fb37ad02bf0922475","event_at":"2026-07-28T03:09:18.641000Z","event_type":"price_change","frame_hash":"3f835c4f6d28c6de685e921d872039758517b05ff3d8594d2cdc0c95dcad6029","frame_index":0,"kind":"data","monotonic_ns":310141567166166,"payload":{"event_type":"price_change","market":"0x779291bef19b6709f61e9764a954aafe9ffae488d50ae674aabdcb4f248006d5","price_changes":[{"asset_id":"8761897749749422724209054078244794145777693856614463256546737399611489089783","best_ask":"0.68","best_bid":"0.67","hash":"e44a0befb62ea7128c8d3c6093e0a3e1df964f1c","price":"0.64","side":"BUY","size":"116.54"},{"asset_id":"14965588658799411272385430903075831224615961675357217884735713260981483529984","best_ask":"0.33","best_bid":"0.32","hash":"36fe80c11338060691584c300f2643175f034531","price":"0.36","side":"SELL","size":"116.54"}],"timestamp":"1785208158641"},"payload_hash":"33046b395ed8411427fd2679e5e0f82065874a79894fd050eaddfaa8eb85eca6","raw_frame":"{\"market\":\"0x779291bef19b6709f61e9764a954aafe9ffae488d50ae674aabdcb4f248006d5\", \"price_changes\":[{\"asset_id\":\"8761897749749422724209054078244794145777693856614463256546737399611489089783\", \"price\":\"0.64\", \"size\":\"116.54\", \"side\":\"BUY\", \"hash\":\"e44a0befb62ea7128c8d3c6093e0a3e1df964f1c\", \"best_bid\":\"0.67\", \"best_ask\":\"0.68\"}, {\"asset_id\":\"14965588658799411272385430903075831224615961675357217884735713260981483529984\", \"price\":\"0.36\", \"size\":\"116.54\", \"side\":\"SELL\", \"hash\":\"36fe80c11338060691584c300f2643175f034531\", \"best_bid\":\"0.32\", \"best_ask\":\"0.33\"}], \"timestamp\":\"1785208158641\", \"event_type\":\"price_change\"}","received_at":"2026-07-28T03:09:18.534214Z","schema_version":"clob-market-ws.price_change.v1","sequence":null,"server_hash":null,"server_timestamp":"1785208158641","session_id":"3e519d9098404c15b234d96025eb1a2b","source":"clob_market_ws"},"received_at":"2026-07-28T03:09:18.534214Z","record_id":"14583cf2179afb16ddf1c3e4001d5cc281d5a338f6d98a1cb11440a94393716b","schema_fingerprint":"4aa3821a28b0b7c2400bc59aba4bcc0a76e971dadd19610d3ad38c768e124dc7","schema_version":"edge-lab-recorder.raw.v1","sequence":null,"source":"clob_market_ws"}
{"event_at":"2026-07-28T03:09:18.642000Z","event_fingerprint":"29b188558b9fb47a4d750249ad8821380701203bff12a1a6fe09f0e9bcf4b881","payload":{"connection_id":"a6b55582af5f430fb37ad02bf0922475","event_at":"2026-07-28T03:09:18.642000Z","event_type":"price_change","frame_hash":"52fa2545e6e697b3842886a0c0791f001df5e5e3836c50f220a121b73b5720e5","frame_index":0,"kind":"data","monotonic_ns":310141568652916,"payload":{"event_type":"price_change","market":"0x779291bef19b6709f61e9764a954aafe9ffae488d50ae674aabdcb4f248006d5","price_changes":[{"asset_id":"8761897749749422724209054078244794145777693856614463256546737399611489089783","best_ask":"0.68","best_bid":"0.67","hash":"5dc75d273a83ea10eb3ff0eb607dd1d3601deeea","price":"0.65","side":"BUY","size":"107.2"},{"asset_id":"14965588658799411272385430903075831224615961675357217884735713260981483529984","best_ask":"0.33","best_bid":"0.32","hash":"2c80a8fdf9851c40d37fcd84835e55a8c101a46c","price":"0.35","side":"SELL","size":"107.2"}],"timestamp":"1785208158642"},"payload_hash":"a298c88cb35e0c0cb87b9fb213d530c226660f7fa2fac683f5a5628305f1fdaa","raw_frame":"{\"market\":\"0x779291bef19b6709f61e9764a954aafe9ffae488d50ae674aabdcb4f248006d5\", \"price_changes\":[{\"asset_id\":\"8761897749749422724209054078244794145777693856614463256546737399611489089783\", \"price\":\"0.65\", \"size\":\"107.2\", \"side\":\"BUY\", \"hash\":\"5dc75d273a83ea10eb3ff0eb607dd1d3601deeea\", \"best_bid\":\"0.67\", \"best_ask\":\"0.68\"}, {\"asset_id\":\"14965588658799411272385430903075831224615961675357217884735713260981483529984\", \"price\":\"0.35\", \"size\":\"107.2\", \"side\":\"SELL\", \"hash\":\"2c80a8fdf9851c40d37fcd84835e55a8c101a46c\", \"best_bid\":\"0.32\", \"best_ask\":\"0.33\"}], \"timestamp\":\"1785208158642\", \"event_type\":\"price_change\"}","received_at":"2026-07-28T03:09:18.535701Z","schema_version":"clob-market-ws.price_change.v1","sequence":null,"server_hash":null,"server_timestamp":"1785208158642","session_id":"3e519d9098404c15b234d96025eb1a2b","source":"clob_market_ws"},"received_at":"2026-07-28T03:09:18.535701Z","record_id":"97e42b48606dfe9e29379ac01cdc7c88e1ffa58fd42f1ebb516dc4bb637cb449","schema_fingerprint":"4aa3821a28b0b7c2400bc59aba4bcc0a76e971dadd19610d3ad38c768e124dc7","schema_version":"edge-lab-recorder.raw.v1","sequence":null,"source":"clob_market_ws"}
{"event_at":"2026-07-28T03:09:18.643000Z","event_fingerprint":"070fca3ddf15e2a5d6ca80a8695471b620e3f9fe0eabc4ece135927f950d9359","payload":{"connection_id":"a6b55582af5f430fb37ad02bf0922475","event_at":"2026-07-28T03:09:18.643000Z","event_type":"price_change","frame_hash":"4423336de2e8425f53691adcfa557a3765ddcc953c781d167cb065d65c119e19","frame_index":0,"kind":"data","monotonic_ns":310141570119000,"payload":{"event_type":"price_change","market":"0x779291bef19b6709f61e9764a954aafe9ffae488d50ae674aabdcb4f248006d5","price_changes":[{"asset_id":"14965588658799411272385430903075831224615961675357217884735713260981483529984","best_ask":"0.33","best_bid":"0.32","hash":"d1a3e337300a47799cbed2fc58304dfca7aacbec","price":"0.19","side":"BUY","size":"320.92"},{"asset_id":"8761897749749422724209054078244794145777693856614463256546737399611489089783","best_ask":"0.68","best_bid":"0.67","hash":"a35e35ec5e6812b8258f8ee2d21efc5cc720847f","price":"0.81","side":"SELL","size":"320.92"}],"timestamp":"1785208158643"},"payload_hash":"c34527f29e221f04ca62f3f8ca2e35a6d9eb95d8b941306c52a5a7561a6162b3","raw_frame":"{\"market\":\"0x779291bef19b6709f61e9764a954aafe9ffae488d50ae674aabdcb4f248006d5\", \"price_changes\":[{\"asset_id\":\"14965588658799411272385430903075831224615961675357217884735713260981483529984\", \"price\":\"0.19\", \"size\":\"320.92\", \"side\":\"BUY\", \"hash\":\"d1a3e337300a47799cbed2fc58304dfca7aacbec\", \"best_bid\":\"0.32\", \"best_ask\":\"0.33\"}, {\"asset_id\":\"8761897749749422724209054078244794145777693856614463256546737399611489089783\", \"price\":\"0.81\", \"size\":\"320.92\", \"side\":\"SELL\", \"hash\":\"a35e35ec5e6812b8258f8ee2d21efc5cc720847f\", \"best_bid\":\"0.67\", \"best_ask\":\"0.68\"}], \"timestamp\":\"1785208158643\", \"event_type\":\"price_change\"}","received_at":"2026-07-28T03:09:18.537166Z","schema_version":"clob-market-ws.price_change.v1","sequence":null,"server_hash":null,"server_timestamp":"1785208158643","session_id":"3e519d9098404c15b234d96025eb1a2b","source":"clob_market_ws"},"received_at":"2026-07-28T03:09:18.537166Z","record_id":"09064aa1f557294fb1b2e81d3d8bce299cac9758a9cadab4571b95317bf1a55b","schema_fingerprint":"4aa3821a28b0b7c2400bc59aba4bcc0a76e971dadd19610d3ad38c768e124dc7","schema_version":"edge-lab-recorder.raw.v1","sequence":null,"source":"clob_market_ws"}
{"event_at":"2026-07-28T03:09:18.646000Z","event_fingerprint":"2008539848c339633d26df3bbd6233afbd51f8661699729419ceb3cca7f6d62b","payload":{"connection_id":"a6b55582af5f430fb37ad02bf0922475","event_at":"2026-07-28T03:09:18.646000Z","event_type":"price_change","frame_hash":"5f7032c16b1bcbce78651d80eb31a0ad1004516e1f03d7cac680b17dab19ce7f","frame_index":0,"kind":"data","monotonic_ns":310141571652583,"payload":{"event_type":"price_change","market":"0x779291bef19b6709f61e9764a954aafe9ffae488d50ae674aabdcb4f248006d5","price_changes":[{"asset_id":"8761897749749422724209054078244794145777693856614463256546737399611489089783","best_ask":"0.68","best_bid":"0.67","hash":"d84b3b43b5e37d44433511d7797e4d255b2398be","price":"0.6","side":"BUY","size":"298.28"},{"asset_id":"14965588658799411272385430903075831224615961675357217884735713260981483529984","best_ask":"0.33","best_bid":"0.32","hash":"7c864a2dcd261ced1acd9cacd11c81813950dba7","price":"0.4","side":"SELL","size":"298.28"}],"timestamp":"1785208158646"},"payload_hash":"e54e73b1402db45b260454c2c1eb29dd0ea17516eed06fd1b5782e7a7d601e61","raw_frame":"{\"market\":\"0x779291bef19b6709f61e9764a954aafe9ffae488d50ae674aabdcb4f248006d5\", \"price_changes\":[{\"asset_id\":\"8761897749749422724209054078244794145777693856614463256546737399611489089783\", \"price\":\"0.6\", \"size\":\"298.28\", \"side\":\"BUY\", \"hash\":\"d84b3b43b5e37d44433511d7797e4d255b2398be\", \"best_bid\":\"0.67\", \"best_ask\":\"0.68\"}, {\"asset_id\":\"14965588658799411272385430903075831224615961675357217884735713260981483529984\", \"price\":\"0.4\", \"size\":\"298.28\", \"side\":\"SELL\", \"hash\":\"7c864a2dcd261ced1acd9cacd11c81813950dba7\", \"best_bid\":\"0.32\", \"best_ask\":\"0.33\"}], \"timestamp\":\"1785208158646\", \"event_type\":\"price_change\"}","received_at":"2026-07-28T03:09:18.538699Z","schema_version":"clob-market-ws.price_change.v1","sequence":null,"server_hash":null,"server_timestamp":"1785208158646","session_id":"3e519d9098404c15b234d96025eb1a2b","source":"clob_market_ws"},"received_at":"2026-07-28T03:09:18.538699Z","record_id":"7225a665d4c7ecbb3f6f79733b3f891ba6cb074fd4410a225a8362f944e540d4","schema_fingerprint":"4aa3821a28b0b7c2400bc59aba4bcc0a76e971dadd19610d3ad38c768e124dc7","schema_version":"edge-lab-recorder.raw.v1","sequence":null,"source":"clob_market_ws"}
{"event_at":"2026-07-28T03:09:18.646000Z","event_fingerprint":"6d02ec2eaef9049a4df3a73900ff143d99f96d69f726c2189ec8774819e485f0","payload":{"connection_id":"a6b55582af5f430fb37ad02bf0922475","event_at":"2026-07-28T03:09:18.646000Z","event_type":"price_change","frame_hash":"b3297ba2f59be07f52d519de42f8cdc8b765ab2c78e1c5e36824e26a157be35d","frame_index":0,"kind":"data","monotonic_ns":310141573228000,"payload":{"event_type":"price_change","market":"0x779291bef19b6709f61e9764a954aafe9ffae488d50ae674aabdcb4f248006d5","price_changes":[{"asset_id":"14965588658799411272385430903075831224615961675357217884735713260981483529984","best_ask":"0.33","best_bid":"0.32","hash":"f521cedb91f2e3036a54041534bdec694b82479b","price":"0.26","side":"BUY","size":"157"},{"asset_id":"8761897749749422724209054078244794145777693856614463256546737399611489089783","best_ask":"0.68","best_bid":"0.67","hash":"ca38e9af6ea3001a01424eda0ab3ed72fb3faf93","price":"0.74","side":"SELL","size":"157"}],"timestamp":"1785208158646"},"payload_hash":"2e1b42f727e47e59bf0a98daa26ffc3cf644de9aa42f745e81be0821b2980f2f","raw_frame":"{\"market\":\"0x779291bef19b6709f61e9764a954aafe9ffae488d50ae674aabdcb4f248006d5\", \"price_changes\":[{\"asset_id\":\"14965588658799411272385430903075831224615961675357217884735713260981483529984\", \"price\":\"0.26\", \"size\":\"157\", \"side\":\"BUY\", \"hash\":\"f521cedb91f2e3036a54041534bdec694b82479b\", \"best_bid\":\"0.32\", \"best_ask\":\"0.33\"}, {\"asset_id\":\"8761897749749422724209054078244794145777693856614463256546737399611489089783\", \"price\":\"0.74\", \"size\":\"157\", \"side\":\"SELL\", \"hash\":\"ca38e9af6ea3001a01424eda0ab3ed72fb3faf93\", \"best_bid\":\"0.67\", \"best_ask\":\"0.68\"}], \"timestamp\":\"1785208158646\", \"event_type\":\"price_change\"}","received_at":"2026-07-28T03:09:18.540276Z","schema_version":"clob-market-ws.price_change.v1","sequence":null,"server_hash":null,"server_timestamp":"1785208158646","session_id":"3e519d9098404c15b234d96025eb1a2b","source":"clob_market_ws"},"received_at":"2026-07-28T03:09:18.540276Z","record_id":"a151981e39906fbda5a30ac0748a1a57650d5c7080bea5ef1e600c1ad5c673b4","schema_fingerprint":"4aa3821a28b0b7c2400bc59aba4bcc0a76e971dadd19610d3ad38c768e124dc7","schema_version":"edge-lab-recorder.raw.v1","sequence":null,"source":"clob_market_ws"}
{"event_at":"2026-07-28T03:09:18.648000Z","event_fingerprint":"5a9a709682861ec31e4849a4cebb9aeb5b7cbc27931e8302092d296dd4e9c6a5","payload":{"connection_id":"a6b55582af5f430fb37ad02bf0922475","event_at":"2026-07-28T03:09:18.648000Z","event_type":"price_change","frame_hash":"9adcdbe43f62181256c8dbe8af96b487a3bff6ea38700a7fafcd6252efd4f9ad","frame_index":0,"kind":"data","monotonic_ns":310141574687750,"payload":{"event_type":"price_change","market":"0x779291bef19b6709f61e9764a954aafe9ffae488d50ae674aabdcb4f248006d5","price_changes":[{"asset_id":"8761897749749422724209054078244794145777693856614463256546737399611489089783","best_ask":"0.68","best_bid":"0.67","hash":"c32d3a0a8a1ddf0a9bd4af785cf830c62657f08f","price":"0.66","side":"BUY","size":"131.05"},{"asset_id":"14965588658799411272385430903075831224615961675357217884735713260981483529984","best_ask":"0.33","best_bid":"0.32","hash":"f4e93800133ebdfe825088d8d2b8be7936aa6436","price":"0.34","side":"SELL","size":"131.05"}],"timestamp":"1785208158648"},"payload_hash":"55ed12f2760fb642cf5a539cfb36f563ae426c85719d0e9bcb166927612113f6","raw_frame":"{\"market\":\"0x779291bef19b6709f61e9764a954aafe9ffae488d50ae674aabdcb4f248006d5\", \"price_changes\":[{\"asset_id\":\"8761897749749422724209054078244794145777693856614463256546737399611489089783\", \"price\":\"0.66\", \"size\":\"131.05\", \"side\":\"BUY\", \"hash\":\"c32d3a0a8a1ddf0a9bd4af785cf830c62657f08f\", \"best_bid\":\"0.67\", \"best_ask\":\"0.68\"}, {\"asset_id\":\"14965588658799411272385430903075831224615961675357217884735713260981483529984\", \"price\":\"0.34\", \"size\":\"131.05\", \"side\":\"SELL\", \"hash\":\"f4e93800133ebdfe825088d8d2b8be7936aa6436\", \"best_bid\":\"0.32\", \"best_ask\":\"0.33\"}], \"timestamp\":\"1785208158648\", \"event_type\":\"price_change\"}","received_at":"2026-07-28T03:09:18.541736Z","schema_version":"clob-market-ws.price_change.v1","sequence":null,"server_hash":null,"server_timestamp":"1785208158648","session_id":"3e519d9098404c15b234d96025eb1a2b","source":"clob_market_ws"},"received_at":"2026-07-28T03:09:18.541736Z","record_id":"76751c5f62b833a68017d2bb7cc8a8ab03c6da5de5ecd639bca14b02f37f1983","schema_fingerprint":"4aa3821a28b0b7c2400bc59aba4bcc0a76e971dadd19610d3ad38c768e124dc7","schema_version":"edge-lab-recorder.raw.v1","sequence":null,"source":"clob_market_ws"}
{"event_at":"2026-07-28T03:09:18.648000Z","event_fingerprint":"0c76d4fe6c6e54a9c83956afd4662c233a0822f095350d1e3c9eff4c6892c26c","payload":{"connection_id":"a6b55582af5f430fb37ad02bf0922475","event_at":"2026-07-28T03:09:18.648000Z","event_type":"price_change","frame_hash":"794bc7289253af43da872add99f85dfa134739ccd87e7187e144ab6cd2188b76","frame_index":0,"kind":"data","monotonic_ns":310141576226375,"payload":{"event_type":"price_change","market":"0x779291bef19b6709f61e9764a954aafe9ffae488d50ae674aabdcb4f248006d5","price_changes":[{"asset_id":"14965588658799411272385430903075831224615961675357217884735713260981483529984","best_ask":"0.33","best_bid":"0.32","hash":"9eecf3c1f369ffed654e2a1374b2a40ccd2cc3e2","price":"0.36","side":"SELL","size":"94.6"},{"asset_id":"8761897749749422724209054078244794145777693856614463256546737399611489089783","best_ask":"0.68","best_bid":"0.67","hash":"3e1129118a01e93af624230c2d33b3ff94021deb","price":"0.64","side":"BUY","size":"94.6"}],"timestamp":"1785208158648"},"payload_hash":"393e2a876c3c94244eeca28aaf124a2d82cad54f4a452459c2ab71f45f5e7339","raw_frame":"{\"market\":\"0x779291bef19b6709f61e9764a954aafe9ffae488d50ae674aabdcb4f248006d5\", \"price_changes\":[{\"asset_id\":\"14965588658799411272385430903075831224615961675357217884735713260981483529984\", \"price\":\"0.36\", \"size\":\"94.6\", \"side\":\"SELL\", \"hash\":\"9eecf3c1f369ffed654e2a1374b2a40ccd2cc3e2\", \"best_bid\":\"0.32\", \"best_ask\":\"0.33\"}, {\"asset_id\":\"8761897749749422724209054078244794145777693856614463256546737399611489089783\", \"price\":\"0.64\", \"size\":\"94.6\", \"side\":\"BUY\", \"hash\":\"3e1129118a01e93af624230c2d33b3ff94021deb\", \"best_bid\":\"0.67\", \"best_ask\":\"0.68\"}], \"timestamp\":\"1785208158648\", \"event_type\":\"price_change\"}","received_at":"2026-07-28T03:09:18.543274Z","schema_version":"clob-market-ws.price_change.v1","sequence":null,"server_hash":null,"server_timestamp":"1785208158648","session_id":"3e519d9098404c15b234d96025eb1a2b","source":"clob_market_ws"},"received_at":"2026-07-28T03:09:18.543274Z","record_id":"312a3c9e2c6caeae7f35239d9ec1c9da263258b9b823fd9812668345d4a3e6f3","schema_fingerprint":"4aa3821a28b0b7c2400bc59aba4bcc0a76e971dadd19610d3ad38c768e124dc7","schema_version":"edge-lab-recorder.raw.v1","sequence":null,"source":"clob_market_ws"}
{"event_at":"2026-07-28T03:09:18.651000Z","event_fingerprint":"804d1b176d68578b528e0e2a54cb270887b69de00e07ef596f279a7466bd60d8","payload":{"connection_id":"a6b55582af5f430fb37ad02bf0922475","event_at":"2026-07-28T03:09:18.651000Z","event_type":"price_change","frame_hash":"eb6799fd8fc845f3180f2932c83ee7412539db5b07d19c789219a19f2a47c430","frame_index":0,"kind":"data","monotonic_ns":310141577750666,"payload":{"event_type":"price_change","market":"0x779291bef19b6709f61e9764a954aafe9ffae488d50ae674aabdcb4f248006d5","price_changes":[{"asset_id":"14965588658799411272385430903075831224615961675357217884735713260981483529984","best_ask":"0.33","best_bid":"0.32","hash":"0c3da37577366d527eda4a3fe78f6b9e96adee1e","price":"0.25","side":"BUY","size":"281"},{"asset_id":"8761897749749422724209054078244794145777693856614463256546737399611489089783","best_ask":"0.68","best_bid":"0.67","hash":"688975a67b281df4ae2748993f94238a5d282abf","price":"0.75","side":"SELL","size":"281"}],"timestamp":"1785208158651"},"payload_hash":"b25ef006523004cabba4cfabfaf7df949bc98dd9111cc5ecaff8a96d0367b610","raw_frame":"{\"market\":\"0x779291bef19b6709f61e9764a954aafe9ffae488d50ae674aabdcb4f248006d5\", \"price_changes\":[{\"asset_id\":\"14965588658799411272385430903075831224615961675357217884735713260981483529984\", \"price\":\"0.25\", \"size\":\"281\", \"side\":\"BUY\", \"hash\":\"0c3da37577366d527eda4a3fe78f6b9e96adee1e\", \"best_bid\":\"0.32\", \"best_ask\":\"0.33\"}, {\"asset_id\":\"8761897749749422724209054078244794145777693856614463256546737399611489089783\", \"price\":\"0.75\", \"size\":\"281\", \"side\":\"SELL\", \"hash\":\"688975a67b281df4ae2748993f94238a5d282abf\", \"best_bid\":\"0.67\", \"best_ask\":\"0.68\"}], \"timestamp\":\"1785208158651\", \"event_type\":\"price_change\"}","received_at":"2026-07-28T03:09:18.544799Z","schema_version":"clob-market-ws.price_change.v1","sequence":null,"server_hash":null,"server_timestamp":"1785208158651","session_id":"3e519d9098404c15b234d96025eb1a2b","source":"clob_market_ws"},"received_at":"2026-07-28T03:09:18.544799Z","record_id":"9c0e46af6c9a920d4a877f81d88f418fb3682ba1b92aab2e44f73c27c8d35eb4","schema_fingerprint":"4aa3821a28b0b7c2400bc59aba4bcc0a76e971dadd19610d3ad38c768e124dc7","schema_version":"edge-lab-recorder.raw.v1","sequence":null,"source":"clob_market_ws"}
{"event_at":"2026-07-28T03:09:18.653000Z","event_fingerprint":"251be919a38a8950c0585728c4abfb4e1e0ca8858334e2e41c025921411e304e","payload":{"connection_id":"a6b55582af5f430fb37ad02bf0922475","event_at":"2026-07-28T03:09:18.653000Z","event_type":"price_change","frame_hash":"6eaea76830e41d27530ea58a536a1a3f58f7033562210fb848f94335ba2e9b37","frame_index":0,"kind":"data","monotonic_ns":310141579194958,"payload":{"event_type":"price_change","market":"0x779291bef19b6709f61e9764a954aafe9ffae488d50ae674aabdcb4f248006d5","price_changes":[{"asset_id":"8761897749749422724209054078244794145777693856614463256546737399611489089783","best_ask":"0.68","best_bid":"0.67","hash":"f4a91e44103310f05278500849675df8df65aca7","price":"0.63","side":"BUY","size":"100.65"},{"asset_id":"14965588658799411272385430903075831224615961675357217884735713260981483529984","best_ask":"0.33","best_bid":"0.32","hash":"bd74a2f017317cc4c039e2e1280550539a272132","price":"0.37","side":"SELL","size":"100.65"}],"timestamp":"1785208158653"},"payload_hash":"cb12c27c8d396348d5bd40ca6b732ccd15387ef15cba7747f12391d214c716c7","raw_frame":"{\"market\":\"0x779291bef19b6709f61e9764a954aafe9ffae488d50ae674aabdcb4f248006d5\", \"price_changes\":[{\"asset_id\":\"8761897749749422724209054078244794145777693856614463256546737399611489089783\", \"price\":\"0.63\", \"size\":\"100.65\", \"side\":\"BUY\", \"hash\":\"f4a91e44103310f05278500849675df8df65aca7\", \"best_bid\":\"0.67\", \"best_ask\":\"0.68\"}, {\"asset_id\":\"14965588658799411272385430903075831224615961675357217884735713260981483529984\", \"price\":\"0.37\", \"size\":\"100.65\", \"side\":\"SELL\", \"hash\":\"bd74a2f017317cc4c039e2e1280550539a272132\", \"best_bid\":\"0.32\", \"best_ask\":\"0.33\"}], \"timestamp\":\"1785208158653\", \"event_type\":\"price_change\"}","received_at":"2026-07-28T03:09:18.546243Z","schema_version":"clob-market-ws.price_change.v1","sequence":null,"server_hash":null,"server_timestamp":"1785208158653","session_id":"3e519d9098404c15b234d96025eb1a2b","source":"clob_market_ws"},"received_at":"2026-07-28T03:09:18.546243Z","record_id":"fdb904faa5a1ddc41f3e9bcc907437ca6c72b28ca0500b3b12f1f2242e414d1b","schema_fingerprint":"4aa3821a28b0b7c2400bc59aba4bcc0a76e971dadd19610d3ad38c768e124dc7","schema_version":"edge-lab-recorder.raw.v1","sequence":null,"source":"clob_market_ws"}
{"event_at":"2026-07-28T03:09:18.653000Z","event_fingerprint":"54a61e51a4368e98e261de35cf6fc9a166ead8b4ed943663659533e8b214d0c7","payload":{"connection_id":"a6b55582af5f430fb37ad02bf0922475","event_at":"2026-07-28T03:09:18.653000Z","event_type":"price_change","frame_hash":"2b708fef2fb3056e7f640d15d90d1de4b9ac2b9408aae9271ca9c5a4000a9f88","frame_index":0,"kind":"data","monotonic_ns":310141580674125,"payload":{"event_type":"price_change","market":"0x779291bef19b6709f61e9764a954aafe9ffae488d50ae674aabdcb4f248006d5","price_changes":[{"asset_id":"14965588658799411272385430903075831224615961675357217884735713260981483529984","best_ask":"0.33","best_bid":"0.32","hash":"d30382acead9b54f278e8a3d3b91403a326025b1","price":"0.26","side":"BUY","size":"151"},{"asset_id":"8761897749749422724209054078244794145777693856614463256546737399611489089783","best_ask":"0.68","best_bid":"0.67","hash":"a3441de0bda47754c8fcf81cdbda3d747b5871b9","price":"0.74","side":"SELL","size":"151"}],"timestamp":"1785208158653"},"payload_hash":"8c4d159507d3a841a3b611c7aa1f5530d7c5a8ac27cfa7c8635398e7a4d1274a","raw_frame":"{\"market\":\"0x779291bef19b6709f61e9764a954aafe9ffae488d50ae674aabdcb4f248006d5\", \"price_changes\":[{\"asset_id\":\"14965588658799411272385430903075831224615961675357217884735713260981483529984\", \"price\":\"0.26\", \"size\":\"151\", \"side\":\"BUY\", \"hash\":\"d30382acead9b54f278e8a3d3b91403a326025b1\", \"best_bid\":\"0.32\", \"best_ask\":\"0.33\"}, {\"asset_id\":\"8761897749749422724209054078244794145777693856614463256546737399611489089783\", \"price\":\"0.74\", \"size\":\"151\", \"side\":\"SELL\", \"hash\":\"a3441de0bda47754c8fcf81cdbda3d747b5871b9\", \"best_bid\":\"0.67\", \"best_ask\":\"0.68\"}], \"timestamp\":\"1785208158653\", \"event_type\":\"price_change\"}","received_at":"2026-07-28T03:09:18.547723Z","schema_version":"clob-market-ws.price_change.v1","sequence":null,"server_hash":null,"server_timestamp":"1785208158653","session_id":"3e519d9098404c15b234d96025eb1a2b","source":"clob_market_ws"},"received_at":"2026-07-28T03:09:18.547723Z","record_id":"62525b1eb2f663d01ea6d3604f81e78f6beaae73453032861ad717bc6b0b1280","schema_fingerprint":"4aa3821a28b0b7c2400bc59aba4bcc0a76e971dadd19610d3ad38c768e124dc7","schema_version":"edge-lab-recorder.raw.v1","sequence":null,"source":"clob_market_ws"}
{"event_at":"2026-07-28T03:09:18.655000Z","event_fingerprint":"7cc3ef77db02e861f7d18ae5b6cc4bed8f5e513705bbfadd9b1ab2efb253ade2","payload":{"connection_id":"a6b55582af5f430fb37ad02bf0922475","event_at":"2026-07-28T03:09:18.655000Z","event_type":"price_change","frame_hash":"741dc91539e80ec977388f14c52866d9e7fe91353e453f1dd2e53e8360053d1a","frame_index":0,"kind":"data","monotonic_ns":310141582130916,"payload":{"event_type":"price_change","market":"0x779291bef19b6709f61e9764a954aafe9ffae488d50ae674aabdcb4f248006d5","price_changes":[{"asset_id":"14965588658799411272385430903075831224615961675357217884735713260981483529984","best_ask":"0.33","best_bid":"0.32","hash":"ba37231d2cd6dac313e913a546e0453b06aaa9d2","price":"0.25","side":"BUY","size":"274"},{"asset_id":"8761897749749422724209054078244794145777693856614463256546737399611489089783","best_ask":"0.68","best_bid":"0.67","hash":"6cfcf5df2798d23d2b1c036c5e4722d15acd4ab6","price":"0.75","side":"SELL","size":"274"}],"timestamp":"1785208158655"},"payload_hash":"92fff5ee213333b99a0c9cc6e32381b553b57637b0180d690fc37669a9cf6ee1","raw_frame":"{\"market\":\"0x779291bef19b6709f61e9764a954aafe9ffae488d50ae674aabdcb4f248006d5\", \"price_changes\":[{\"asset_id\":\"14965588658799411272385430903075831224615961675357217884735713260981483529984\", \"price\":\"0.25\", \"size\":\"274\", \"side\":\"BUY\", \"hash\":\"ba37231d2cd6dac313e913a546e0453b06aaa9d2\", \"best_bid\":\"0.32\", \"best_ask\":\"0.33\"}, {\"asset_id\":\"8761897749749422724209054078244794145777693856614463256546737399611489089783\", \"price\":\"0.75\", \"size\":\"274\", \"side\":\"SELL\", \"hash\":\"6cfcf5df2798d23d2b1c036c5e4722d15acd4ab6\", \"best_bid\":\"0.67\", \"best_ask\":\"0.68\"}], \"timestamp\":\"1785208158655\", \"event_type\":\"price_change\"}","received_at":"2026-07-28T03:09:18.549179Z","schema_version":"clob-market-ws.price_change.v1","sequence":null,"server_hash":null,"server_timestamp":"1785208158655","session_id":"3e519d9098404c15b234d96025eb1a2b","source":"clob_market_ws"},"received_at":"2026-07-28T03:09:18.549179Z","record_id":"1cfc5535ad47f5078145dc715dc9df70235418e66406b7db7ae52871f9cf6287","schema_fingerprint":"4aa3821a28b0b7c2400bc59aba4bcc0a76e971dadd19610d3ad38c768e124dc7","schema_version":"edge-lab-recorder.raw.v1","sequence":null,"source":"clob_market_ws"}
{"event_at":"2026-07-28T03:09:18.655000Z","event_fingerprint":"652e5ac3e049b7540d8e312fbe407964c31782ec7d1b40e171cf90e9dfa90357","payload":{"connection_id":"a6b55582af5f430fb37ad02bf0922475","event_at":"2026-07-28T03:09:18.655000Z","event_type":"price_change","frame_hash":"6d95d82ef06721f1f42424a8555e7116913c332dd3e532774f4190795e808921","frame_index":0,"kind":"data","monotonic_ns":310141583580583,"payload":{"event_type":"price_change","market":"0x779291bef19b6709f61e9764a954aafe9ffae488d50ae674aabdcb4f248006d5","price_changes":[{"asset_id":"14965588658799411272385430903075831224615961675357217884735713260981483529984","best_ask":"0.33","best_bid":"0.32","hash":"9778088543976ed93122437625ba58d9a21c87c7","price":"0.2","side":"BUY","size":"312.48"},{"asset_id":"8761897749749422724209054078244794145777693856614463256546737399611489089783","best_ask":"0.68","best_bid":"0.67","hash":"964c36aa87d628dbb0da24184dbc477e3dc53268","price":"0.8","side":"SELL","size":"312.48"}],"timestamp":"1785208158655"},"payload_hash":"17d90f6159471e2f623ab83efb7aeea93d270b3e5588397ab01a2689077d0f3b","raw_frame":"{\"market\":\"0x779291bef19b6709f61e9764a954aafe9ffae488d50ae674aabdcb4f248006d5\", \"price_changes\":[{\"asset_id\":\"14965588658799411272385430903075831224615961675357217884735713260981483529984\", \"price\":\"0.2\", \"size\":\"312.48\", \"side\":\"BUY\", \"hash\":\"9778088543976ed93122437625ba58d9a21c87c7\", \"best_bid\":\"0.32\", \"best_ask\":\"0.33\"}, {\"asset_id\":\"8761897749749422724209054078244794145777693856614463256546737399611489089783\", \"price\":\"0.8\", \"size\":\"312.48\", \"side\":\"SELL\", \"hash\":\"964c36aa87d628dbb0da24184dbc477e3dc53268\", \"best_bid\":\"0.67\", \"best_ask\":\"0.68\"}], \"timestamp\":\"1785208158655\", \"event_type\":\"price_change\"}","received_at":"2026-07-28T03:09:18.550629Z","schema_version":"clob-market-ws.price_change.v1","sequence":null,"server_hash":null,"server_timestamp":"1785208158655","session_id":"3e519d9098404c15b234d96025eb1a2b","source":"clob_market_ws"},"received_at":"2026-07-28T03:09:18.550629Z","record_id":"2adb81ac94b0271b8bdcc50fc9b787158ad97837200a7676ffd9b20017452836","schema_fingerprint":"4aa3821a28b0b7c2400bc59aba4bcc0a76e971dadd19610d3ad38c768e124dc7","schema_version":"edge-lab-recorder.raw.v1","sequence":null,"source":"clob_market_ws"}
{"event_at":"2026-07-28T03:09:18.656000Z","event_fingerprint":"b4af5bcade94070e9985d551f9ba3f2b7e8dfc3694e1b60b982f897db547b05e","payload":{"connection_id":"a6b55582af5f430fb37ad02bf0922475","event_at":"2026-07-28T03:09:18.656000Z","event_type":"price_change","frame_hash":"fd7db770c5097fb7df1ec8122eb41e69dc209d40b9904fdaf706f785bb8820ca","frame_index":0,"kind":"data","monotonic_ns":310141585035458,"payload":{"event_type":"price_change","market":"0x779291bef19b6709f61e9764a954aafe9ffae488d50ae674aabdcb4f248006d5","price_changes":[{"asset_id":"14965588658799411272385430903075831224615961675357217884735713260981483529984","best_ask":"0.33","best_bid":"0.32","hash":"69a4243b2a4b601c34e0710041f738a78e9ea1a2","price":"0.23","side":"BUY","size":"246"},{"asset_id":"8761897749749422724209054078244794145777693856614463256546737399611489089783","best_ask":"0.68","best_bid":"0.67","hash":"6f2201907ddbf78f99a433d363010aae0920c2ac","price":"0.77","side":"SELL","size":"246"}],"timestamp":"1785208158656"},"payload_hash":"636afbc9cb1854c4b759977d293a8788460cfe80a98ad2632abc7e96fcca7296","raw_frame":"{\"market\":\"0x779291bef19b6709f61e9764a954aafe9ffae488d50ae674aabdcb4f248006d5\", \"price_changes\":[{\"asset_id\":\"14965588658799411272385430903075831224615961675357217884735713260981483529984\", \"price\":\"0.23\", \"size\":\"246\", \"side\":\"BUY\", \"hash\":\"69a4243b2a4b601c34e0710041f738a78e9ea1a2\", \"best_bid\":\"0.32\", \"best_ask\":\"0.33\"}, {\"asset_id\":\"8761897749749422724209054078244794145777693856614463256546737399611489089783\", \"price\":\"0.77\", \"size\":\"246\", \"side\":\"SELL\", \"hash\":\"6f2201907ddbf78f99a433d363010aae0920c2ac\", \"best_bid\":\"0.67\", \"best_ask\":\"0.68\"}], \"timestamp\":\"1785208158656\", \"event_type\":\"price_change\"}","received_at":"2026-07-28T03:09:18.552084Z","schema_version":"clob-market-ws.price_change.v1","sequence":null,"server_hash":null,"server_timestamp":"1785208158656","session_id":"3e519d9098404c15b234d96025eb1a2b","source":"clob_market_ws"},"received_at":"2026-07-28T03:09:18.552084Z","record_id":"9583ec6d5589ce9db29e63c8558e6cdab276622c9c8baf189bc620e368455748","schema_fingerprint":"4aa3821a28b0b7c2400bc59aba4bcc0a76e971dadd19610d3ad38c768e124dc7","schema_version":"edge-lab-recorder.raw.v1","sequence":null,"source":"clob_market_ws"}
{"event_at":"2026-07-28T03:09:18.656000Z","event_fingerprint":"cd61c964172295eddd83cc144e65df52d1f3a91a6cb7cf6dfe28cbaef48479dc","payload":{"connection_id":"a6b55582af5f430fb37ad02bf0922475","event_at":"2026-07-28T03:09:18.656000Z","event_type":"price_change","frame_hash":"2030bb20ccbc1832e00db3b72860b119e96bb467f10212860935c7a359efd7ee","frame_index":0,"kind":"data","monotonic_ns":310141586484500,"payload":{"event_type":"price_change","market":"0x779291bef19b6709f61e9764a954aafe9ffae488d50ae674aabdcb4f248006d5","price_changes":[{"asset_id":"8761897749749422724209054078244794145777693856614463256546737399611489089783","best_ask":"0.68","best_bid":"0.67","hash":"e4978b81d5e9d25ed1bcfa618502546dd6f95e98","price":"0.67","side":"BUY","size":"126.6"},{"asset_id":"14965588658799411272385430903075831224615961675357217884735713260981483529984","best_ask":"0.33","best_bid":"0.32","hash":"a26481a1eb46edd2af5281cb8ccd60674fce63ed","price":"0.33","side":"SELL","size":"126.6"}],"timestamp":"1785208158656"},"payload_hash":"8d5630df693fca634014438b20622f227e0f6e44bb6742b3977eaaa88712795a","raw_frame":"{\"market\":\"0x779291bef19b6709f61e9764a954aafe9ffae488d50ae674aabdcb4f248006d5\", \"price_changes\":[{\"asset_id\":\"8761897749749422724209054078244794145777693856614463256546737399611489089783\", \"price\":\"0.67\", \"size\":\"126.6\", \"side\":\"BUY\", \"hash\":\"e4978b81d5e9d25ed1bcfa618502546dd6f95e98\", \"best_bid\":\"0.67\", \"best_ask\":\"0.68\"}, {\"asset_id\":\"14965588658799411272385430903075831224615961675357217884735713260981483529984\", \"price\":\"0.33\", \"size\":\"126.6\", \"side\":\"SELL\", \"hash\":\"a26481a1eb46edd2af5281cb8ccd60674fce63ed\", \"best_bid\":\"0.32\", \"best_ask\":\"0.33\"}], \"timestamp\":\"1785208158656\", \"event_type\":\"price_change\"}","received_at":"2026-07-28T03:09:18.553533Z","schema_version":"clob-market-ws.price_change.v1","sequence":null,"server_hash":null,"server_timestamp":"1785208158656","session_id":"3e519d9098404c15b234d96025eb1a2b","source":"clob_market_ws"},"received_at":"2026-07-28T03:09:18.553533Z","record_id":"26980141db663bbb0d4acbfe2e3bc47f9b2a189484eea46b4f587360b71088bc","schema_fingerprint":"4aa3821a28b0b7c2400bc59aba4bcc0a76e971dadd19610d3ad38c768e124dc7","schema_version":"edge-lab-recorder.raw.v1","sequence":null,"source":"clob_market_ws"}
{"event_at":"2026-07-28T03:09:18.658000Z","event_fingerprint":"c37c739ef71684a8f35486db79529ed77ad0476f73ebcd7e4e68e1f6c9ba8c16","payload":{"connection_id":"a6b55582af5f430fb37ad02bf0922475","event_at":"2026-07-28T03:09:18.658000Z","event_type":"price_change","frame_hash":"6ffedef03d81c947d97a9e330d3897aeda502164072de6d7592cc20232d3e621","frame_index":0,"kind":"data","monotonic_ns":310141587932041,"payload":{"event_type":"price_change","market":"0x779291bef19b6709f61e9764a954aafe9ffae488d50ae674aabdcb4f248006d5","price_changes":[{"asset_id":"14965588658799411272385430903075831224615961675357217884735713260981483529984","best_ask":"0.33","best_bid":"0.32","hash":"865846058361e67d429a51083fbabbd34b79ac39","price":"0.31","side":"BUY","size":"36"},{"asset_id":"8761897749749422724209054078244794145777693856614463256546737399611489089783","best_ask":"0.68","best_bid":"0.67","hash":"468b8eefe6769bbec0e690f5ba7caabd609c9ffe","price":"0.69","side":"SELL","size":"36"}],"timestamp":"1785208158658"},"payload_hash":"3f044624758271c4ba14c29622c16604d2d43ec30fe7a0bafd98fdde8c5902e6","raw_frame":"{\"market\":\"0x779291bef19b6709f61e9764a954aafe9ffae488d50ae674aabdcb4f248006d5\", \"price_changes\":[{\"asset_id\":\"14965588658799411272385430903075831224615961675357217884735713260981483529984\", \"price\":\"0.31\", \"size\":\"36\", \"side\":\"BUY\", \"hash\":\"865846058361e67d429a51083fbabbd34b79ac39\", \"best_bid\":\"0.32\", \"best_ask\":\"0.33\"}, {\"asset_id\":\"8761897749749422724209054078244794145777693856614463256546737399611489089783\", \"price\":\"0.69\", \"size\":\"36\", \"side\":\"SELL\", \"hash\":\"468b8eefe6769bbec0e690f5ba7caabd609c9ffe\", \"best_bid\":\"0.67\", \"best_ask\":\"0.68\"}], \"timestamp\":\"1785208158658\", \"event_type\":\"price_change\"}","received_at":"2026-07-28T03:09:18.554981Z","schema_version":"clob-market-ws.price_change.v1","sequence":null,"server_hash":null,"server_timestamp":"1785208158658","session_id":"3e519d9098404c15b234d96025eb1a2b","source":"clob_market_ws"},"received_at":"2026-07-28T03:09:18.554981Z","record_id":"9ff8ed8c41b3215164baec339b13a48b76d43cedcddb3ef764c66bfbb06c1f2b","schema_fingerprint":"4aa3821a28b0b7c2400bc59aba4bcc0a76e971dadd19610d3ad38c768e124dc7","schema_version":"edge-lab-recorder.raw.v1","sequence":null,"source":"clob_market_ws"}
{"event_at":"2026-07-28T03:09:18.659000Z","event_fingerprint":"709eee392cde9b638474b85253043932975dc46f684287e46fb15e0b4dc7ba34","payload":{"connection_id":"a6b55582af5f430fb37ad02bf0922475","event_at":"2026-07-28T03:09:18.659000Z","event_type":"price_change","frame_hash":"0bfba60a70fc1eb681ce214c64ad6e0f74018e395d00e421e2fc974d90fe9520","frame_index":0,"kind":"data","monotonic_ns":310141589391750,"payload":{"event_type":"price_change","market":"0x779291bef19b6709f61e9764a954aafe9ffae488d50ae674aabdcb4f248006d5","price_changes":[{"asset_id":"8761897749749422724209054078244794145777693856614463256546737399611489089783","best_ask":"0.68","best_bid":"0.67","hash":"dc5f8b85e614d14f0f43e3ee5e29829e6fed1051","price":"0.6","side":"BUY","size":"292.28"},{"asset_id":"14965588658799411272385430903075831224615961675357217884735713260981483529984","best_ask":"0.33","best_bid":"0.32","hash":"1ca7d321edde3fbe1409c622234193e101f8fed2","price":"0.4","side":"SELL","size":"292.28"}],"timestamp":"1785208158659"},"payload_hash":"9cbcbddee884e82324fc4ae58417fe55ec51ad5d23b9a4294a1f8958c0c63e63","raw_frame":"{\"market\":\"0x779291bef19b6709f61e9764a954aafe9ffae488d50ae674aabdcb4f248006d5\", \"price_changes\":[{\"asset_id\":\"8761897749749422724209054078244794145777693856614463256546737399611489089783\", \"price\":\"0.6\", \"size\":\"292.28\", \"side\":\"BUY\", \"hash\":\"dc5f8b85e614d14f0f43e3ee5e29829e6fed1051\", \"best_bid\":\"0.67\", \"best_ask\":\"0.68\"}, {\"asset_id\":\"14965588658799411272385430903075831224615961675357217884735713260981483529984\", \"price\":\"0.4\", \"size\":\"292.28\", \"side\":\"SELL\", \"hash\":\"1ca7d321edde3fbe1409c622234193e101f8fed2\", \"best_bid\":\"0.32\", \"best_ask\":\"0.33\"}], \"timestamp\":\"1785208158659\", \"event_type\":\"price_change\"}","received_at":"2026-07-28T03:09:18.556440Z","schema_version":"clob-market-ws.price_change.v1","sequence":null,"server_hash":null,"server_timestamp":"1785208158659","session_id":"3e519d9098404c15b234d96025eb1a2b","source":"clob_market_ws"},"received_at":"2026-07-28T03:09:18.556440Z","record_id":"f887634f4155f0688d587989c4eea3f38cc73300c38af59f349c2e32b905104d","schema_fingerprint":"4aa3821a28b0b7c2400bc59aba4bcc0a76e971dadd19610d3ad38c768e124dc7","schema_version":"edge-lab-recorder.raw.v1","sequence":null,"source":"clob_market_ws"}
{"event_at":"2026-07-28T03:09:18.659000Z","event_fingerprint":"15baeeb258fe5de914ae4f11fc29b1698b9ba3da9dc6c6efca07763b3604d5e1","payload":{"connection_id":"a6b55582af5f430fb37ad02bf0922475","event_at":"2026-07-28T03:09:18.659000Z","event_type":"price_change","frame_hash":"7f7bfd89a4a48785eec76ffe4fdf382552c8d48b565c9ea2429d9b1696d00647","frame_index":0,"kind":"data","monotonic_ns":310141590890541,"payload":{"event_type":"price_change","market":"0x779291bef19b6709f61e9764a954aafe9ffae488d50ae674aabdcb4f248006d5","price_changes":[{"asset_id":"14965588658799411272385430903075831224615961675357217884735713260981483529984","best_ask":"0.33","best_bid":"0.32","hash":"177761892a823ddcdd44cc8cf2f8c74d4c0b8315","price":"0.28","side":"BUY","size":"43"},{"asset_id":"8761897749749422724209054078244794145777693856614463256546737399611489089783","best_ask":"0.68","best_bid":"0.67","hash":"a6f54c2711f97d634b42619404980de9c94e8dd0","price":"0.72","side":"SELL","size":"43"}],"timestamp":"1785208158659"},"payload_hash":"e352d326e54b7fca8fa9b48e70879574014f883629602374567a2db9871bddcf","raw_frame":"{\"market\":\"0x779291bef19b6709f61e9764a954aafe9ffae488d50ae674aabdcb4f248006d5\", \"price_changes\":[{\"asset_id\":\"14965588658799411272385430903075831224615961675357217884735713260981483529984\", \"price\":\"0.28\", \"size\":\"43\", \"side\":\"BUY\", \"hash\":\"177761892a823ddcdd44cc8cf2f8c74d4c0b8315\", \"best_bid\":\"0.32\", \"best_ask\":\"0.33\"}, {\"asset_id\":\"8761897749749422724209054078244794145777693856614463256546737399611489089783\", \"price\":\"0.72\", \"size\":\"43\", \"side\":\"SELL\", \"hash\":\"a6f54c2711f97d634b42619404980de9c94e8dd0\", \"best_bid\":\"0.67\", \"best_ask\":\"0.68\"}], \"timestamp\":\"1785208158659\", \"event_type\":\"price_change\"}","received_at":"2026-07-28T03:09:18.557939Z","schema_version":"clob-market-ws.price_change.v1","sequence":null,"server_hash":null,"server_timestamp":"1785208158659","session_id":"3e519d9098404c15b234d96025eb1a2b","source":"clob_market_ws"},"received_at":"2026-07-28T03:09:18.557939Z","record_id":"2bb023d7967046327c72c18c6b1333a90a51c8c1d3a5b3b8db13bd187e7a75dc","schema_fingerprint":"4aa3821a28b0b7c2400bc59aba4bcc0a76e971dadd19610d3ad38c768e124dc7","schema_version":"edge-lab-recorder.raw.v1","sequence":null,"source":"clob_market_ws"}
{"event_at":"2026-07-28T03:09:18.660000Z","event_fingerprint":"706e7691cffdadeece0f93c608a5b9f325c3be73c0edacbdd8e831a47d399747","payload":{"connection_id":"a6b55582af5f430fb37ad02bf0922475","event_at":"2026-07-28T03:09:18.660000Z","event_type":"price_change","frame_hash":"20c16614f51766e3f1c306eb02153e8e1cce12b6ae1f03d85022dada2c9a2057","frame_index":0,"kind":"data","monotonic_ns":310141592401666,"payload":{"event_type":"price_change","market":"0x779291bef19b6709f61e9764a954aafe9ffae488d50ae674aabdcb4f248006d5","price_changes":[{"asset_id":"14965588658799411272385430903075831224615961675357217884735713260981483529984","best_ask":"0.33","best_bid":"0.32","hash":"472db8c29fcfaddf318ea43d9069ff41a34dfd2e","price":"0.25","side":"BUY","size":"194"},{"asset_id":"8761897749749422724209054078244794145777693856614463256546737399611489089783","best_ask":"0.68","best_bid":"0.67","hash":"70fcc0291df5942e5824a9c2bb8fa5729e09322e","price":"0.75","side":"SELL","size":"194"}],"timestamp":"1785208158660"},"payload_hash":"44089c3f7158327713c75c580c59be0acbe7b715e6506ab78541b2dbf62dccb9","raw_frame":"{\"market\":\"0x779291bef19b6709f61e9764a954aafe9ffae488d50ae674aabdcb4f248006d5\", \"price_changes\":[{\"asset_id\":\"14965588658799411272385430903075831224615961675357217884735713260981483529984\", \"price\":\"0.25\", \"size\":\"194\", \"side\":\"BUY\", \"hash\":\"472db8c29fcfaddf318ea43d9069ff41a34dfd2e\", \"best_bid\":\"0.32\", \"best_ask\":\"0.33\"}, {\"asset_id\":\"8761897749749422724209054078244794145777693856614463256546737399611489089783\", \"price\":\"0.75\", \"size\":\"194\", \"side\":\"SELL\", \"hash\":\"70fcc0291df5942e5824a9c2bb8fa5729e09322e\", \"best_bid\":\"0.67\", \"best_ask\":\"0.68\"}], \"timestamp\":\"1785208158660\", \"event_type\":\"price_change\"}","received_at":"2026-07-28T03:09:18.559450Z","schema_version":"clob-market-ws.price_change.v1","sequence":null,"server_hash":null,"server_timestamp":"1785208158660","session_id":"3e519d9098404c15b234d96025eb1a2b","source":"clob_market_ws"},"received_at":"2026-07-28T03:09:18.559450Z","record_id":"14338ac94cb4c7fa21edd1aa024ec76bde359bbd86d1dcee9bb96d0bbfeebbc5","schema_fingerprint":"4aa3821a28b0b7c2400bc59aba4bcc0a76e971dadd19610d3ad38c768e124dc7","schema_version":"edge-lab-recorder.raw.v1","sequence":null,"source":"clob_market_ws"}
{"event_at":"2026-07-28T03:09:18.660000Z","event_fingerprint":"76563f1e9ecd2b7fe6b26ff4def6ab704c374c2711e50ebeaf64a7748aa2558c","payload":{"connection_id":"a6b55582af5f430fb37ad02bf0922475","event_at":"2026-07-28T03:09:18.660000Z","event_type":"price_change","frame_hash":"69edf7041917427c988ada1993e40c0472404bd32a8d3b4e46af20338cdc86ea","frame_index":0,"kind":"data","monotonic_ns":310141593837125,"payload":{"event_type":"price_change","market":"0x779291bef19b6709f61e9764a954aafe9ffae488d50ae674aabdcb4f248006d5","price_changes":[{"asset_id":"8761897749749422724209054078244794145777693856614463256546737399611489089783","best_ask":"0.68","best_bid":"0.67","hash":"853c3a0e60c38509a3fb25e9543a79ba50322e14","price":"0.66","side":"BUY","size":"106.05"},{"asset_id":"14965588658799411272385430903075831224615961675357217884735713260981483529984","best_ask":"0.33","best_bid":"0.32","hash":"be893f3886373c1e711f07620f136a8ef5aba44a","price":"0.34","side":"SELL","size":"106.05"}],"timestamp":"1785208158660"},"payload_hash":"a8c1ece8db99a64acde32beccc99a7d7baad06caee7d6d9cf2852b4c79623337","raw_frame":"{\"market\":\"0x779291bef19b6709f61e9764a954aafe9ffae488d50ae674aabdcb4f248006d5\", \"price_changes\":[{\"asset_id\":\"8761897749749422724209054078244794145777693856614463256546737399611489089783\", \"price\":\"0.66\", \"size\":\"106.05\", \"side\":\"BUY\", \"hash\":\"853c3a0e60c38509a3fb25e9543a79ba50322e14\", \"best_bid\":\"0.67\", \"best_ask\":\"0.68\"}, {\"asset_id\":\"14965588658799411272385430903075831224615961675357217884735713260981483529984\", \"price\":\"0.34\", \"size\":\"106.05\", \"side\":\"SELL\", \"hash\":\"be893f3886373c1e711f07620f136a8ef5aba44a\", \"best_bid\":\"0.32\", \"best_ask\":\"0.33\"}], \"timestamp\":\"1785208158660\", \"event_type\":\"price_change\"}","received_at":"2026-07-28T03:09:18.560885Z","schema_version":"clob-market-ws.price_change.v1","sequence":null,"server_hash":null,"server_timestamp":"1785208158660","session_id":"3e519d9098404c15b234d96025eb1a2b","source":"clob_market_ws"},"received_at":"2026-07-28T03:09:18.560885Z","record_id":"182cd1ca9e2893608dabcf21d5103f888533b50b9cfc611694d6db32f086e2e7","schema_fingerprint":"4aa3821a28b0b7c2400bc59aba4bcc0a76e971dadd19610d3ad38c768e124dc7","schema_version":"edge-lab-recorder.raw.v1","sequence":null,"source":"clob_market_ws"}
{"event_at":"2026-07-28T03:09:18.660000Z","event_fingerprint":"a74a4b017fa918a8408bf5f670eeaa2ca10bf96387c921ab23854039c016d45b","payload":{"connection_id":"a6b55582af5f430fb37ad02bf0922475","event_at":"2026-07-28T03:09:18.660000Z","event_type":"price_change","frame_hash":"c87abb4c26f5f8561d7d4761d8c2acf0787215ad164db80ced171aa0336a3996","frame_index":0,"kind":"data","monotonic_ns":310141595369083,"payload":{"event_type":"price_change","market":"0x779291bef19b6709f61e9764a954aafe9ffae488d50ae674aabdcb4f248006d5","price_changes":[{"asset_id":"14965588658799411272385430903075831224615961675357217884735713260981483529984","best_ask":"0.33","best_bid":"0.32","hash":"81d6a97da2c6bcf635dff601cd5e4e1a16ddda5e","price":"0.24","side":"BUY","size":"241"},{"asset_id":"8761897749749422724209054078244794145777693856614463256546737399611489089783","best_ask":"0.68","best_bid":"0.67","hash":"be26fdf736366e4ac0b7a30d39095c12d275e298","price":"0.76","side":"SELL","size":"241"}],"timestamp":"1785208158660"},"payload_hash":"1d00440ebc37ca061ee6405aa4aaa35206d9b39a100d74e220f4793a362a48b7","raw_frame":"{\"market\":\"0x779291bef19b6709f61e9764a954aafe9ffae488d50ae674aabdcb4f248006d5\", \"price_changes\":[{\"asset_id\":\"14965588658799411272385430903075831224615961675357217884735713260981483529984\", \"price\":\"0.24\", \"size\":\"241\", \"side\":\"BUY\", \"hash\":\"81d6a97da2c6bcf635dff601cd5e4e1a16ddda5e\", \"best_bid\":\"0.32\", \"best_ask\":\"0.33\"}, {\"asset_id\":\"8761897749749422724209054078244794145777693856614463256546737399611489089783\", \"price\":\"0.76\", \"size\":\"241\", \"side\":\"SELL\", \"hash\":\"be26fdf736366e4ac0b7a30d39095c12d275e298\", \"best_bid\":\"0.67\", \"best_ask\":\"0.68\"}], \"timestamp\":\"1785208158660\", \"event_type\":\"price_change\"}","received_at":"2026-07-28T03:09:18.562416Z","schema_version":"clob-market-ws.price_change.v1","sequence":null,"server_hash":null,"server_timestamp":"1785208158660","session_id":"3e519d9098404c15b234d96025eb1a2b","source":"clob_market_ws"},"received_at":"2026-07-28T03:09:18.562416Z","record_id":"9d5cfa63aca95dbf3d1f5e2691bce552c677f535c3a0fd3aad33d47cde100465","schema_fingerprint":"4aa3821a28b0b7c2400bc59aba4bcc0a76e971dadd19610d3ad38c768e124dc7","schema_version":"edge-lab-recorder.raw.v1","sequence":null,"source":"clob_market_ws"}
{"event_at":"2026-07-28T03:09:18.662000Z","event_fingerprint":"d4edb3a48a419a9a91583aab666174c704dc82cbf7c14c0dadeaf20c8d503a62","payload":{"connection_id":"a6b55582af5f430fb37ad02bf0922475","event_at":"2026-07-28T03:09:18.662000Z","event_type":"price_change","frame_hash":"af6935903e0ac79d14773df6c585b08933939e4840be7a6d07f8f58a1c1b7454","frame_index":0,"kind":"data","monotonic_ns":310141596834916,"payload":{"event_type":"price_change","market":"0x779291bef19b6709f61e9764a954aafe9ffae488d50ae674aabdcb4f248006d5","price_changes":[{"asset_id":"8761897749749422724209054078244794145777693856614463256546737399611489089783","best_ask":"0.68","best_bid":"0.67","hash":"95845d089e65b7a5ec51ead3460173924533a363","price":"0.43","side":"BUY","size":"202.22"},{"asset_id":"14965588658799411272385430903075831224615961675357217884735713260981483529984","best_ask":"0.33","best_bid":"0.32","hash":"b8cf212fce66a4aca005d4ad99b78c3de98e96f3","price":"0.57","side":"SELL","size":"202.22"}],"timestamp":"1785208158662"},"payload_hash":"a5bb74c6aee28f14f38a73760fa77818116dd38f8178410a2b1c505e74e3bce5","raw_frame":"{\"market\":\"0x779291bef19b6709f61e9764a954aafe9ffae488d50ae674aabdcb4f248006d5\", \"price_changes\":[{\"asset_id\":\"8761897749749422724209054078244794145777693856614463256546737399611489089783\", \"price\":\"0.43\", \"size\":\"202.22\", \"side\":\"BUY\", \"hash\":\"95845d089e65b7a5ec51ead3460173924533a363\", \"best_bid\":\"0.67\", \"best_ask\":\"0.68\"}, {\"asset_id\":\"14965588658799411272385430903075831224615961675357217884735713260981483529984\", \"price\":\"0.57\", \"size\":\"202.22\", \"side\":\"SELL\", \"hash\":\"b8cf212fce66a4aca005d4ad99b78c3de98e96f3\", \"best_bid\":\"0.32\", \"best_ask\":\"0.33\"}], \"timestamp\":\"1785208158662\", \"event_type\":\"price_change\"}","received_at":"2026-07-28T03:09:18.563883Z","schema_version":"clob-market-ws.price_change.v1","sequence":null,"server_hash":null,"server_timestamp":"1785208158662","session_id":"3e519d9098404c15b234d96025eb1a2b","source":"clob_market_ws"},"received_at":"2026-07-28T03:09:18.563883Z","record_id":"ba4096e370a6beda18720a6fdc73012d7254772f136607ecb81318da85b00516","schema_fingerprint":"4aa3821a28b0b7c2400bc59aba4bcc0a76e971dadd19610d3ad38c768e124dc7","schema_version":"edge-lab-recorder.raw.v1","sequence":null,"source":"clob_market_ws"}
{"event_at":"2026-07-28T03:09:18.662000Z","event_fingerprint":"fc1e464454a8c2870fb504ef7948fc6968c25e7b086e0205e170717182d367f5","payload":{"connection_id":"a6b55582af5f430fb37ad02bf0922475","event_at":"2026-07-28T03:09:18.662000Z","event_type":"price_change","frame_hash":"88bf8a4987e84846f4ec4ecbc4687011489a50d4f9fcdf2b52dc2d9f893d8f83","frame_index":0,"kind":"data","monotonic_ns":310141598296708,"payload":{"event_type":"price_change","market":"0x779291bef19b6709f61e9764a954aafe9ffae488d50ae674aabdcb4f248006d5","price_changes":[{"asset_id":"14965588658799411272385430903075831224615961675357217884735713260981483529984","best_ask":"0.33","best_bid":"0.32","hash":"122b2fc1a5a94587f26fe16f5fc0759b65d0cd5c","price":"0.3","side":"BUY","size":"68"},{"asset_id":"8761897749749422724209054078244794145777693856614463256546737399611489089783","best_ask":"0.68","best_bid":"0.67","hash":"fbfd6f6835d3ec6ee8388e752798d174e0c0d2b4","price":"0.7","side":"SELL","size":"68"}],"timestamp":"1785208158662"},"payload_hash":"3e3f0766dcb54b2414c8b8bbc78471bd23cd62bb7529f1a8f4939e35a92893fd","raw_frame":"{\"market\":\"0x779291bef19b6709f61e9764a954aafe9ffae488d50ae674aabdcb4f248006d5\", \"price_changes\":[{\"asset_id\":\"14965588658799411272385430903075831224615961675357217884735713260981483529984\", \"price\":\"0.3\", \"size\":\"68\", \"side\":\"BUY\", \"hash\":\"122b2fc1a5a94587f26fe16f5fc0759b65d0cd5c\", \"best_bid\":\"0.32\", \"best_ask\":\"0.33\"}, {\"asset_id\":\"8761897749749422724209054078244794145777693856614463256546737399611489089783\", \"price\":\"0.7\", \"size\":\"68\", \"side\":\"SELL\", \"hash\":\"fbfd6f6835d3ec6ee8388e752798d174e0c0d2b4\", \"best_bid\":\"0.67\", \"best_ask\":\"0.68\"}], \"timestamp\":\"1785208158662\", \"event_type\":\"price_change\"}","received_at":"2026-07-28T03:09:18.565345Z","schema_version":"clob-market-ws.price_change.v1","sequence":null,"server_hash":null,"server_timestamp":"1785208158662","session_id":"3e519d9098404c15b234d96025eb1a2b","source":"clob_market_ws"},"received_at":"2026-07-28T03:09:18.565345Z","record_id":"8654d7490feaab59c23f165f9f17ebd194a79666539ab3107fdf85a3c1c9e654","schema_fingerprint":"4aa3821a28b0b7c2400bc59aba4bcc0a76e971dadd19610d3ad38c768e124dc7","schema_version":"edge-lab-recorder.raw.v1","sequence":null,"source":"clob_market_ws"}
{"event_at":"2026-07-28T03:09:18.662000Z","event_fingerprint":"bf73d4899f2bcf9e759b453aecb8fc55ea75060949125f5ceae80b8a3e4b0ddc","payload":{"connection_id":"a6b55582af5f430fb37ad02bf0922475","event_at":"2026-07-28T03:09:18.662000Z","event_type":"price_change","frame_hash":"196d226afe30dc69c0c4de8dd59b33926b2399831af610a0c73f3a562784030c","frame_index":0,"kind":"data","monotonic_ns":310141599730625,"payload":{"event_type":"price_change","market":"0x779291bef19b6709f61e9764a954aafe9ffae488d50ae674aabdcb4f248006d5","price_changes":[{"asset_id":"14965588658799411272385430903075831224615961675357217884735713260981483529984","best_ask":"0.33","best_bid":"0.32","hash":"07af664aa67e760ea1d3672949bb5f03bb663c68","price":"0.24","side":"BUY","size":"158"},{"asset_id":"8761897749749422724209054078244794145777693856614463256546737399611489089783","best_ask":"0.68","best_bid":"0.67","hash":"b504c37b4743b5e1dc4193283aa10aaaec7d287c","price":"0.76","side":"SELL","size":"158"}],"timestamp":"1785208158662"},"payload_hash":"89a1f4497f409cc536403173169540d3a58d0859ad479c44f9fb138a08835096","raw_frame":"{\"market\":\"0x779291bef19b6709f61e9764a954aafe9ffae488d50ae674aabdcb4f248006d5\", \"price_changes\":[{\"asset_id\":\"14965588658799411272385430903075831224615961675357217884735713260981483529984\", \"price\":\"0.24\", \"size\":\"158\", \"side\":\"BUY\", \"hash\":\"07af664aa67e760ea1d3672949bb5f03bb663c68\", \"best_bid\":\"0.32\", \"best_ask\":\"0.33\"}, {\"asset_id\":\"8761897749749422724209054078244794145777693856614463256546737399611489089783\", \"price\":\"0.76\", \"size\":\"158\", \"side\":\"SELL\", \"hash\":\"b504c37b4743b5e1dc4193283aa10aaaec7d287c\", \"best_bid\":\"0.67\", \"best_ask\":\"0.68\"}], \"timestamp\":\"1785208158662\", \"event_type\":\"price_change\"}","received_at":"2026-07-28T03:09:18.566779Z","schema_version":"clob-market-ws.price_change.v1","sequence":null,"server_hash":null,"server_timestamp":"1785208158662","session_id":"3e519d9098404c15b234d96025eb1a2b","source":"clob_market_ws"},"received_at":"2026-07-28T03:09:18.566779Z","record_id":"aaa408e07cda384dda5cd309bee810d662f0c0b4578584980b11506349b53f59","schema_fingerprint":"4aa3821a28b0b7c2400bc59aba4bcc0a76e971dadd19610d3ad38c768e124dc7","schema_version":"edge-lab-recorder.raw.v1","sequence":null,"source":"clob_market_ws"}
{"event_at":"2026-07-28T03:09:18.663000Z","event_fingerprint":"570ed4482ce63eafc313cf9f3ec19674b9d94da091a1267257c294307385f216","payload":{"connection_id":"a6b55582af5f430fb37ad02bf0922475","event_at":"2026-07-28T03:09:18.663000Z","event_type":"price_change","frame_hash":"dca5aac8146fb6afea3d9c9bae3d19a8820ecb530725f12503ba91f335d219b1","frame_index":0,"kind":"data","monotonic_ns":310141601188500,"payload":{"event_type":"price_change","market":"0x779291bef19b6709f61e9764a954aafe9ffae488d50ae674aabdcb4f248006d5","price_changes":[{"asset_id":"8761897749749422724209054078244794145777693856614463256546737399611489089783","best_ask":"0.68","best_bid":"0.67","hash":"e0e80a1eff14de1e76a56f96fe59db6d61436817","price":"0.7","side":"SELL","size":"43"},{"asset_id":"14965588658799411272385430903075831224615961675357217884735713260981483529984","best_ask":"0.33","best_bid":"0.32","hash":"a228b3fc0cae30273dd8bfcec77919a0410a2733","price":"0.3","side":"BUY","size":"43"}],"timestamp":"1785208158663"},"payload_hash":"03d8ebd9bd6d7878a24e90c5a079b16162d500106a1b53eedc86f37d2b1499a4","raw_frame":"{\"market\":\"0x779291bef19b6709f61e9764a954aafe9ffae488d50ae674aabdcb4f248006d5\", \"price_changes\":[{\"asset_id\":\"8761897749749422724209054078244794145777693856614463256546737399611489089783\", \"price\":\"0.7\", \"size\":\"43\", \"side\":\"SELL\", \"hash\":\"e0e80a1eff14de1e76a56f96fe59db6d61436817\", \"best_bid\":\"0.67\", \"best_ask\":\"0.68\"}, {\"asset_id\":\"14965588658799411272385430903075831224615961675357217884735713260981483529984\", \"price\":\"0.3\", \"size\":\"43\", \"side\":\"BUY\", \"hash\":\"a228b3fc0cae30273dd8bfcec77919a0410a2733\", \"best_bid\":\"0.32\", \"best_ask\":\"0.33\"}], \"timestamp\":\"1785208158663\", \"event_type\":\"price_change\"}","received_at":"2026-07-28T03:09:18.568237Z","schema_version":"clob-market-ws.price_change.v1","sequence":null,"server_hash":null,"server_timestamp":"1785208158663","session_id":"3e519d9098404c15b234d96025eb1a2b","source":"clob_market_ws"},"received_at":"2026-07-28T03:09:18.568237Z","record_id":"dd1b4ba8225e2005c0a3df78571f488106eb70a1bd45b2be4a8591f7bfa7c24f","schema_fingerprint":"4aa3821a28b0b7c2400bc59aba4bcc0a76e971dadd19610d3ad38c768e124dc7","schema_version":"edge-lab-recorder.raw.v1","sequence":null,"source":"clob_market_ws"}
{"event_at":"2026-07-28T03:09:18.663000Z","event_fingerprint":"9825b9ae486000b4a2e32675329448c44e4e285a6cf9fff6f36275dc9115d341","payload":{"connection_id":"a6b55582af5f430fb37ad02bf0922475","event_at":"2026-07-28T03:09:18.663000Z","event_type":"price_change","frame_hash":"be1f3de1817ed314461b2f4ae73a178ba385c3f670172e8bcfe72df73792730f","frame_index":0,"kind":"data","monotonic_ns":310141602631458,"payload":{"event_type":"price_change","market":"0x779291bef19b6709f61e9764a954aafe9ffae488d50ae674aabdcb4f248006d5","price_changes":[{"asset_id":"8761897749749422724209054078244794145777693856614463256546737399611489089783","best_ask":"0.68","best_bid":"0.67","hash":"f4d4efa0f294a12a9f0f41bf5540648cbff60d06","price":"0.43","side":"BUY","size":"124.71"},{"asset_id":"14965588658799411272385430903075831224615961675357217884735713260981483529984","best_ask":"0.33","best_bid":"0.32","hash":"244a3150c6ae774f545dcc6e0c5a3d658ec55113","price":"0.57","side":"SELL","size":"124.71"}],"timestamp":"1785208158663"},"payload_hash":"1b31030a74ae1ef35e2924f1bdaecf472593370926a59eae6688294d5dd70aca","raw_frame":"{\"market\":\"0x779291bef19b6709f61e9764a954aafe9ffae488d50ae674aabdcb4f248006d5\", \"price_changes\":[{\"asset_id\":\"8761897749749422724209054078244794145777693856614463256546737399611489089783\", \"price\":\"0.43\", \"size\":\"124.71\", \"side\":\"BUY\", \"hash\":\"f4d4efa0f294a12a9f0f41bf5540648cbff60d06\", \"best_bid\":\"0.67\", \"best_ask\":\"0.68\"}, {\"asset_id\":\"14965588658799411272385430903075831224615961675357217884735713260981483529984\", \"price\":\"0.57\", \"size\":\"124.71\", \"side\":\"SELL\", \"hash\":\"244a3150c6ae774f545dcc6e0c5a3d658ec55113\", \"best_bid\":\"0.32\", \"best_ask\":\"0.33\"}], \"timestamp\":\"1785208158663\", \"event_type\":\"price_change\"}","received_at":"2026-07-28T03:09:18.569680Z","schema_version":"clob-market-ws.price_change.v1","sequence":null,"server_hash":null,"server_timestamp":"1785208158663","session_id":"3e519d9098404c15b234d96025eb1a2b","source":"clob_market_ws"},"received_at":"2026-07-28T03:09:18.569680Z","record_id":"84ff9ea6c54b07ac6fc7e4b96c40a713df0be6e456eba2ebe95b367d4e974dc7","schema_fingerprint":"4aa3821a28b0b7c2400bc59aba4bcc0a76e971dadd19610d3ad38c768e124dc7","schema_version":"edge-lab-recorder.raw.v1","sequence":null,"source":"clob_market_ws"}
{"event_at":"2026-07-28T03:09:18.665000Z","event_fingerprint":"72c3acafcc40e37d8b57b4f796a3db926fc043c7cd604c073a9e07ac8e91dbfb","payload":{"connection_id":"a6b55582af5f430fb37ad02bf0922475","event_at":"2026-07-28T03:09:18.665000Z","event_type":"price_change","frame_hash":"4ca4c39ae2c424dee7f151cb4dfc81e037609af20427ab4da6738bc305b20d84","frame_index":0,"kind":"data","monotonic_ns":310141604085541,"payload":{"event_type":"price_change","market":"0x779291bef19b6709f61e9764a954aafe9ffae488d50ae674aabdcb4f248006d5","price_changes":[{"asset_id":"8761897749749422724209054078244794145777693856614463256546737399611489089783","best_ask":"0.68","best_bid":"0.67","hash":"743861fa1ccefd44fb1bd283ddb4debf4933dd2b","price":"0.43","side":"BUY","size":"47.2"},{"asset_id":"14965588658799411272385430903075831224615961675357217884735713260981483529984","best_ask":"0.33","best_bid":"0.32","hash":"9079d147c97df3e2059e2ed6c6759f84969d2b03","price":"0.57","side":"SELL","size":"47.2"}],"timestamp":"1785208158665"},"payload_hash":"3b1f315ea30fa09104aa8ba069be33328e248837bf8735e47b91da5016aa664a","raw_frame":"{\"market\":\"0x779291bef19b6709f61e9764a954aafe9ffae488d50ae674aabdcb4f248006d5\", \"price_changes\":[{\"asset_id\":\"8761897749749422724209054078244794145777693856614463256546737399611489089783\", \"price\":\"0.43\", \"size\":\"47.2\", \"side\":\"BUY\", \"hash\":\"743861fa1ccefd44fb1bd283ddb4debf4933dd2b\", \"best_bid\":\"0.67\", \"best_ask\":\"0.68\"}, {\"asset_id\":\"14965588658799411272385430903075831224615961675357217884735713260981483529984\", \"price\":\"0.57\", \"size\":\"47.2\", \"side\":\"SELL\", \"hash\":\"9079d147c97df3e2059e2ed6c6759f84969d2b03\", \"best_bid\":\"0.32\", \"best_ask\":\"0.33\"}], \"timestamp\":\"1785208158665\", \"event_type\":\"price_change\"}","received_at":"2026-07-28T03:09:18.571134Z","schema_version":"clob-market-ws.price_change.v1","sequence":null,"server_hash":null,"server_timestamp":"1785208158665","session_id":"3e519d9098404c15b234d96025eb1a2b","source":"clob_market_ws"},"received_at":"2026-07-28T03:09:18.571134Z","record_id":"f149b5b84c3010794c0102c971795d550c99e7ecb4d9bcc08774e50791eecb40","schema_fingerprint":"4aa3821a28b0b7c2400bc59aba4bcc0a76e971dadd19610d3ad38c768e124dc7","schema_version":"edge-lab-recorder.raw.v1","sequence":null,"source":"clob_market_ws"}
{"event_at":"2026-07-28T03:09:18.665000Z","event_fingerprint":"7d298086ac84ddf4d3508b8f8c5f0d3b149ec240b78e77073f702758d669e23e","payload":{"connection_id":"a6b55582af5f430fb37ad02bf0922475","event_at":"2026-07-28T03:09:18.665000Z","event_type":"price_change","frame_hash":"807775de46fabc92b8947c9ef3a9aa4824b0deba6007045126ed6eb6b489c8a6","frame_index":0,"kind":"data","monotonic_ns":310141605529291,"payload":{"event_type":"price_change","market":"0x779291bef19b6709f61e9764a954aafe9ffae488d50ae674aabdcb4f248006d5","price_changes":[{"asset_id":"14965588658799411272385430903075831224615961675357217884735713260981483529984","best_ask":"0.33","best_bid":"0.32","hash":"f3edc7656342d77a29977daab80cd817e1734992","price":"0.22","side":"BUY","size":"281.5"},{"asset_id":"8761897749749422724209054078244794145777693856614463256546737399611489089783","best_ask":"0.68","best_bid":"0.67","hash":"a9e5f7b6d0c8ffb959eb4278c1d34ffdb697d0ac","price":"0.78","side":"SELL","size":"281.5"}],"timestamp":"1785208158665"},"payload_hash":"c07f833bdd832a0834b81585f0f544b598b2444bbf6d5c3a4c2c33eff108e243","raw_frame":"{\"market\":\"0x779291bef19b6709f61e9764a954aafe9ffae488d50ae674aabdcb4f248006d5\", \"price_changes\":[{\"asset_id\":\"14965588658799411272385430903075831224615961675357217884735713260981483529984\", \"price\":\"0.22\", \"size\":\"281.5\", \"side\":\"BUY\", \"hash\":\"f3edc7656342d77a29977daab80cd817e1734992\", \"best_bid\":\"0.32\", \"best_ask\":\"0.33\"}, {\"asset_id\":\"8761897749749422724209054078244794145777693856614463256546737399611489089783\", \"price\":\"0.78\", \"size\":\"281.5\", \"side\":\"SELL\", \"hash\":\"a9e5f7b6d0c8ffb959eb4278c1d34ffdb697d0ac\", \"best_bid\":\"0.67\", \"best_ask\":\"0.68\"}], \"timestamp\":\"1785208158665\", \"event_type\":\"price_change\"}","received_at":"2026-07-28T03:09:18.572578Z","schema_version":"clob-market-ws.price_change.v1","sequence":null,"server_hash":null,"server_timestamp":"1785208158665","session_id":"3e519d9098404c15b234d96025eb1a2b","source":"clob_market_ws"},"received_at":"2026-07-28T03:09:18.572578Z","record_id":"3a7b51ea9be46ca489045e6fd383e3415e61e97d7183775db3fd03ffd5bcb1fc","schema_fingerprint":"4aa3821a28b0b7c2400bc59aba4bcc0a76e971dadd19610d3ad38c768e124dc7","schema_version":"edge-lab-recorder.raw.v1","sequence":null,"source":"clob_market_ws"}
{"event_at":"2026-07-28T03:09:18.666000Z","event_fingerprint":"ecd4fc1730a1e7e6a55a17d132a3861e3be89af9e1449d25ee71c9cd0813ee70","payload":{"connection_id":"a6b55582af5f430fb37ad02bf0922475","event_at":"2026-07-28T03:09:18.666000Z","event_type":"price_change","frame_hash":"986117489ce0c33e9dd24cedf9e58995422fe195edb50b799a3426197caaa9ff","frame_index":0,"kind":"data","monotonic_ns":310141606996625,"payload":{"event_type":"price_change","market":"0x779291bef19b6709f61e9764a954aafe9ffae488d50ae674aabdcb4f248006d5","price_changes":[{"asset_id":"8761897749749422724209054078244794145777693856614463256546737399611489089783","best_ask":"0.68","best_bid":"0.67","hash":"afa64633fd1ee9b5bffcb0103512814e1de8a6fd","price":"0.01","side":"BUY","size":"5608.02"},{"asset_id":"14965588658799411272385430903075831224615961675357217884735713260981483529984","best_ask":"0.33","best_bid":"0.32","hash":"62ac0dcab7dfee5cfc76fef2189f695f89fa0d65","price":"0.99","side":"SELL","size":"5608.02"}],"timestamp":"1785208158666"},"payload_hash":"6b50de1da659176dbd0523bd69551d0c41e2872efbbcc20160b4df0b6bd405de","raw_frame":"{\"market\":\"0x779291bef19b6709f61e9764a954aafe9ffae488d50ae674aabdcb4f248006d5\", \"price_changes\":[{\"asset_id\":\"8761897749749422724209054078244794145777693856614463256546737399611489089783\", \"price\":\"0.01\", \"size\":\"5608.02\", \"side\":\"BUY\", \"hash\":\"afa64633fd1ee9b5bffcb0103512814e1de8a6fd\", \"best_bid\":\"0.67\", \"best_ask\":\"0.68\"}, {\"asset_id\":\"14965588658799411272385430903075831224615961675357217884735713260981483529984\", \"price\":\"0.99\", \"size\":\"5608.02\", \"side\":\"SELL\", \"hash\":\"62ac0dcab7dfee5cfc76fef2189f695f89fa0d65\", \"best_bid\":\"0.32\", \"best_ask\":\"0.33\"}], \"timestamp\":\"1785208158666\", \"event_type\":\"price_change\"}","received_at":"2026-07-28T03:09:18.574044Z","schema_version":"clob-market-ws.price_change.v1","sequence":null,"server_hash":null,"server_timestamp":"1785208158666","session_id":"3e519d9098404c15b234d96025eb1a2b","source":"clob_market_ws"},"received_at":"2026-07-28T03:09:18.574044Z","record_id":"4e3560860a5a09c457dda5856d8248be408097a58d12955f6fe848e4ffc6ccd6","schema_fingerprint":"4aa3821a28b0b7c2400bc59aba4bcc0a76e971dadd19610d3ad38c768e124dc7","schema_version":"edge-lab-recorder.raw.v1","sequence":null,"source":"clob_market_ws"}
{"event_at":"2026-07-28T03:09:18.667000Z","event_fingerprint":"6620db2fa4b03344e58404bbff7ce72646dfd6664f1e6c40984f316379f43eba","payload":{"connection_id":"a6b55582af5f430fb37ad02bf0922475","event_at":"2026-07-28T03:09:18.667000Z","event_type":"price_change","frame_hash":"d7ab1621ecb7c693ca30cfd6ed08f6c823f59d0b3e04c8e68f5a4228bbab01f5","frame_index":0,"kind":"data","monotonic_ns":310141607743750,"payload":{"event_type":"price_change","market":"0x779291bef19b6709f61e9764a954aafe9ffae488d50ae674aabdcb4f248006d5","price_changes":[{"asset_id":"14965588658799411272385430903075831224615961675357217884735713260981483529984","best_ask":"0.33","best_bid":"0.32","hash":"1d4d170efe311b748f369181f55b0ceb8de47615","price":"0.27","side":"BUY","size":"319"},{"asset_id":"8761897749749422724209054078244794145777693856614463256546737399611489089783","best_ask":"0.68","best_bid":"0.67","hash":"d82d669f847deb02e4bd6588f9fb3b851f11f5c0","price":"0.73","side":"SELL","size":"319"}],"timestamp":"1785208158667"},"payload_hash":"f21e8480dcbd27d691684f79b96502e7c57aec6a8982fece72e0eaad2739b093","raw_frame":"{\"market\":\"0x779291bef19b6709f61e9764a954aafe9ffae488d50ae674aabdcb4f248006d5\", \"price_changes\":[{\"asset_id\":\"14965588658799411272385430903075831224615961675357217884735713260981483529984\", \"price\":\"0.27\", \"size\":\"319\", \"side\":\"BUY\", \"hash\":\"1d4d170efe311b748f369181f55b0ceb8de47615\", \"best_bid\":\"0.32\", \"best_ask\":\"0.33\"}, {\"asset_id\":\"8761897749749422724209054078244794145777693856614463256546737399611489089783\", \"price\":\"0.73\", \"size\":\"319\", \"side\":\"SELL\", \"hash\":\"d82d669f847deb02e4bd6588f9fb3b851f11f5c0\", \"best_bid\":\"0.67\", \"best_ask\":\"0.68\"}], \"timestamp\":\"1785208158667\", \"event_type\":\"price_change\"}","received_at":"2026-07-28T03:09:18.574797Z","schema_version":"clob-market-ws.price_change.v1","sequence":null,"server_hash":null,"server_timestamp":"1785208158667","session_id":"3e519d9098404c15b234d96025eb1a2b","source":"clob_market_ws"},"received_at":"2026-07-28T03:09:18.574797Z","record_id":"dd68ba272b7553d47e39e1295cf1b1c13f68bb2106d5f7418606fe4ba9daa2b9","schema_fingerprint":"4aa3821a28b0b7c2400bc59aba4bcc0a76e971dadd19610d3ad38c768e124dc7","schema_version":"edge-lab-recorder.raw.v1","sequence":null,"source":"clob_market_ws"}
{"event_at":"2026-07-28T03:09:18.667000Z","event_fingerprint":"ca53e32ea537a64c84414c4f98f3dc62987cf7419e81d5ecdf610f9ba51621b6","payload":{"connection_id":"a6b55582af5f430fb37ad02bf0922475","event_at":"2026-07-28T03:09:18.667000Z","event_type":"price_change","frame_hash":"5ca03de68099ba1201ac3913c32f2e97a6ef043242eb77da0a42d8d3cded43e7","frame_index":0,"kind":"data","monotonic_ns":310141608314916,"payload":{"event_type":"price_change","market":"0x779291bef19b6709f61e9764a954aafe9ffae488d50ae674aabdcb4f248006d5","price_changes":[{"asset_id":"14965588658799411272385430903075831224615961675357217884735713260981483529984","best_ask":"0.33","best_bid":"0.32","hash":"7fa8f0dd6bffa2a48dbc8554788a74317a4cd3e3","price":"0.21","side":"BUY","size":"180.13"},{"asset_id":"8761897749749422724209054078244794145777693856614463256546737399611489089783","best_ask":"0.68","best_bid":"0.67","hash":"5a55b3ac8e4da508b06b896b38d1a46d41e17e73","price":"0.79","side":"SELL","size":"180.13"}],"timestamp":"1785208158667"},"payload_hash":"4b121e1b41a1a91fff0659e34eeebbfcb384f1cd9f8610c0138f896dd845f421","raw_frame":"{\"market\":\"0x779291bef19b6709f61e9764a954aafe9ffae488d50ae674aabdcb4f248006d5\", \"price_changes\":[{\"asset_id\":\"14965588658799411272385430903075831224615961675357217884735713260981483529984\", \"price\":\"0.21\", \"size\":\"180.13\", \"side\":\"BUY\", \"hash\":\"7fa8f0dd6bffa2a48dbc8554788a74317a4cd3e3\", \"best_bid\":\"0.32\", \"best_ask\":\"0.33\"}, {\"asset_id\":\"8761897749749422724209054078244794145777693856614463256546737399611489089783\", \"price\":\"0.79\", \"size\":\"180.13\", \"side\":\"SELL\", \"hash\":\"5a55b3ac8e4da508b06b896b38d1a46d41e17e73\", \"best_bid\":\"0.67\", \"best_ask\":\"0.68\"}], \"timestamp\":\"1785208158667\", \"event_type\":\"price_change\"}","received_at":"2026-07-28T03:09:18.575363Z","schema_version":"clob-market-ws.price_change.v1","sequence":null,"server_hash":null,"server_timestamp":"1785208158667","session_id":"3e519d9098404c15b234d96025eb1a2b","source":"clob_market_ws"},"received_at":"2026-07-28T03:09:18.575363Z","record_id":"edbf1b827b0b01d419a33f1e074e989cb6e67c21908246b1590aef0fc47a9d5e","schema_fingerprint":"4aa3821a28b0b7c2400bc59aba4bcc0a76e971dadd19610d3ad38c768e124dc7","schema_version":"edge-lab-recorder.raw.v1","sequence":null,"source":"clob_market_ws"}
{"event_at":"2026-07-28T03:09:18.667000Z","event_fingerprint":"129607be3c3fc572edc21cd53fdaadb8c5ab382a1d9d86ed4d20506c9c9a71e3","payload":{"connection_id":"a6b55582af5f430fb37ad02bf0922475","event_at":"2026-07-28T03:09:18.667000Z","event_type":"price_change","frame_hash":"d267ef71f6e48d9b0083884a877989fb8aad2632d90eb2c80a5e1bf9cb74713e","frame_index":0,"kind":"data","monotonic_ns":310141609802500,"payload":{"event_type":"price_change","market":"0x779291bef19b6709f61e9764a954aafe9ffae488d50ae674aabdcb4f248006d5","price_changes":[{"asset_id":"8761897749749422724209054078244794145777693856614463256546737399611489089783","best_ask":"0.68","best_bid":"0.67","hash":"5e5c1a95685bcba0740e19f6f28990ca03766e6a","price":"0.61","side":"BUY","size":"90.94"},{"asset_id":"14965588658799411272385430903075831224615961675357217884735713260981483529984","best_ask":"0.33","best_bid":"0.32","hash":"437189dea53fdbbe3e3c82ed8d82c926b98acd4b","price":"0.39","side":"SELL","size":"90.94"}],"timestamp":"1785208158667"},"payload_hash":"d67d539017cddab10c5bd161bf9ac4ebbf4a4df78118630416b8f9198923a018","raw_frame":"{\"market\":\"0x779291bef19b6709f61e9764a954aafe9ffae488d50ae674aabdcb4f248006d5\", \"price_changes\":[{\"asset_id\":\"8761897749749422724209054078244794145777693856614463256546737399611489089783\", \"price\":\"0.61\", \"size\":\"90.94\", \"side\":\"BUY\", \"hash\":\"5e5c1a95685bcba0740e19f6f28990ca03766e6a\", \"best_bid\":\"0.67\", \"best_ask\":\"0.68\"}, {\"asset_id\":\"14965588658799411272385430903075831224615961675357217884735713260981483529984\", \"price\":\"0.39\", \"size\":\"90.94\", \"side\":\"SELL\", \"hash\":\"437189dea53fdbbe3e3c82ed8d82c926b98acd4b\", \"best_bid\":\"0.32\", \"best_ask\":\"0.33\"}], \"timestamp\":\"1785208158667\", \"event_type\":\"price_change\"}","received_at":"2026-07-28T03:09:18.576851Z","schema_version":"clob-market-ws.price_change.v1","sequence":null,"server_hash":null,"server_timestamp":"1785208158667","session_id":"3e519d9098404c15b234d96025eb1a2b","source":"clob_market_ws"},"received_at":"2026-07-28T03:09:18.576851Z","record_id":"1628588a37dc04355e7e84f8d3e09a53ce8f2121d6a86f5f84e67efe6466205d","schema_fingerprint":"4aa3821a28b0b7c2400bc59aba4bcc0a76e971dadd19610d3ad38c768e124dc7","schema_version":"edge-lab-recorder.raw.v1","sequence":null,"source":"clob_market_ws"}
{"event_at":"2026-07-28T03:09:18.667000Z","event_fingerprint":"7a383cf83d3a476b3fe0d2a06c633f07e82fde9aa813c3fc60b77e6b18391d36","payload":{"connection_id":"a6b55582af5f430fb37ad02bf0922475","event_at":"2026-07-28T03:09:18.667000Z","event_type":"price_change","frame_hash":"f746c19696c7c4e1ec48c314f720678401824e859097e699ab45a358b08323f0","frame_index":0,"kind":"data","monotonic_ns":310141611219166,"payload":{"event_type":"price_change","market":"0x779291bef19b6709f61e9764a954aafe9ffae488d50ae674aabdcb4f248006d5","price_changes":[{"asset_id":"14965588658799411272385430903075831224615961675357217884735713260981483529984","best_ask":"0.33","best_bid":"0.32","hash":"ed54394ec3fd3e027655ec43e0b1b429357160e0","price":"0.23","side":"BUY","size":"159"},{"asset_id":"8761897749749422724209054078244794145777693856614463256546737399611489089783","best_ask":"0.68","best_bid":"0.67","hash":"9d92f4b4c9c76a31e70fa996371fa1ab1e981f22","price":"0.77","side":"SELL","size":"159"}],"timestamp":"1785208158667"},"payload_hash":"7333cb0e49bef9896ed31e351ce307544542c1e6b2da58b739b4eb62ecc5b7bb","raw_frame":"{\"market\":\"0x779291bef19b6709f61e9764a954aafe9ffae488d50ae674aabdcb4f248006d5\", \"price_changes\":[{\"asset_id\":\"14965588658799411272385430903075831224615961675357217884735713260981483529984\", \"price\":\"0.23\", \"size\":\"159\", \"side\":\"BUY\", \"hash\":\"ed54394ec3fd3e027655ec43e0b1b429357160e0\", \"best_bid\":\"0.32\", \"best_ask\":\"0.33\"}, {\"asset_id\":\"8761897749749422724209054078244794145777693856614463256546737399611489089783\", \"price\":\"0.77\", \"size\":\"159\", \"side\":\"SELL\", \"hash\":\"9d92f4b4c9c76a31e70fa996371fa1ab1e981f22\", \"best_bid\":\"0.67\", \"best_ask\":\"0.68\"}], \"timestamp\":\"1785208158667\", \"event_type\":\"price_change\"}","received_at":"2026-07-28T03:09:18.578267Z","schema_version":"clob-market-ws.price_change.v1","sequence":null,"server_hash":null,"server_timestamp":"1785208158667","session_id":"3e519d9098404c15b234d96025eb1a2b","source":"clob_market_ws"},"received_at":"2026-07-28T03:09:18.578267Z","record_id":"1e60cf9bf9c0bc8128c203172e78f663da76b40f26f7ea48c855595ba3b26576","schema_fingerprint":"4aa3821a28b0b7c2400bc59aba4bcc0a76e971dadd19610d3ad38c768e124dc7","schema_version":"edge-lab-recorder.raw.v1","sequence":null,"source":"clob_market_ws"}
{"event_at":"2026-07-28T03:09:18.668000Z","event_fingerprint":"e54cd20845b683026a10dc88e142b9288332811879a4b05b133b554487c24a49","payload":{"connection_id":"a6b55582af5f430fb37ad02bf0922475","event_at":"2026-07-28T03:09:18.668000Z","event_type":"price_change","frame_hash":"c69846583f50e976f25902c04ae59fdc46083d34f7cde8de48009f40b521b4c0","frame_index":0,"kind":"data","monotonic_ns":310141612694583,"payload":{"event_type":"price_change","market":"0x779291bef19b6709f61e9764a954aafe9ffae488d50ae674aabdcb4f248006d5","price_changes":[{"asset_id":"8761897749749422724209054078244794145777693856614463256546737399611489089783","best_ask":"0.68","best_bid":"0.67","hash":"6c0efb96211617f282f8cb2557b6bab35c2fbdda","price":"0.59","side":"BUY","size":"194.26"},{"asset_id":"14965588658799411272385430903075831224615961675357217884735713260981483529984","best_ask":"0.33","best_bid":"0.32","hash":"b95270f2a7e7d8970192e7b066261b318a5b645d","price":"0.41","side":"SELL","size":"194.26"}],"timestamp":"1785208158668"},"payload_hash":"52e1b658c09b46e6e70eaffde04304da27d47319e263f8c2a5a37da5dd0a5422","raw_frame":"{\"market\":\"0x779291bef19b6709f61e9764a954aafe9ffae488d50ae674aabdcb4f248006d5\", \"price_changes\":[{\"asset_id\":\"8761897749749422724209054078244794145777693856614463256546737399611489089783\", \"price\":\"0.59\", \"size\":\"194.26\", \"side\":\"BUY\", \"hash\":\"6c0efb96211617f282f8cb2557b6bab35c2fbdda\", \"best_bid\":\"0.67\", \"best_ask\":\"0.68\"}, {\"asset_id\":\"14965588658799411272385430903075831224615961675357217884735713260981483529984\", \"price\":\"0.41\", \"size\":\"194.26\", \"side\":\"SELL\", \"hash\":\"b95270f2a7e7d8970192e7b066261b318a5b645d\", \"best_bid\":\"0.32\", \"best_ask\":\"0.33\"}], \"timestamp\":\"1785208158668\", \"event_type\":\"price_change\"}","received_at":"2026-07-28T03:09:18.579743Z","schema_version":"clob-market-ws.price_change.v1","sequence":null,"server_hash":null,"server_timestamp":"1785208158668","session_id":"3e519d9098404c15b234d96025eb1a2b","source":"clob_market_ws"},"received_at":"2026-07-28T03:09:18.579743Z","record_id":"6a6033f584db3cb1b2e3dde551ee060bb2f4e4b284f5ab3dd2ec68b49757a485","schema_fingerprint":"4aa3821a28b0b7c2400bc59aba4bcc0a76e971dadd19610d3ad38c768e124dc7","schema_version":"edge-lab-recorder.raw.v1","sequence":null,"source":"clob_market_ws"}
{"event_at":"2026-07-28T03:09:18.669000Z","event_fingerprint":"d29896dd6f61830fc80d93881177e3352771b5f0d685e07465f40e813c266a8d","payload":{"connection_id":"a6b55582af5f430fb37ad02bf0922475","event_at":"2026-07-28T03:09:18.669000Z","event_type":"price_change","frame_hash":"53af2be2fbed3dd2bfd55f54a1cea5af06e4f4ab4386e9e91dc4b95198180ad3","frame_index":0,"kind":"data","monotonic_ns":310141614162000,"payload":{"event_type":"price_change","market":"0x779291bef19b6709f61e9764a954aafe9ffae488d50ae674aabdcb4f248006d5","price_changes":[{"asset_id":"14965588658799411272385430903075831224615961675357217884735713260981483529984","best_ask":"0.33","best_bid":"0.32","hash":"b403010e8fd841fd7ff685356575c8a0a41568c3","price":"0.14","side":"BUY","size":"207.9"},{"asset_id":"8761897749749422724209054078244794145777693856614463256546737399611489089783","best_ask":"0.68","best_bid":"0.67","hash":"d8c8975d534f5cdd8228b1af40b186bbb41592d9","price":"0.86","side":"SELL","size":"207.9"}],"timestamp":"1785208158669"},"payload_hash":"6c9d1fa13116d93483793fd8c8e29ead637bd2b2bb7f8f6850bb0f134d8fb1c4","raw_frame":"{\"market\":\"0x779291bef19b6709f61e9764a954aafe9ffae488d50ae674aabdcb4f248006d5\", \"price_changes\":[{\"asset_id\":\"14965588658799411272385430903075831224615961675357217884735713260981483529984\", \"price\":\"0.14\", \"size\":\"207.9\", \"side\":\"BUY\", \"hash\":\"b403010e8fd841fd7ff685356575c8a0a41568c3\", \"best_bid\":\"0.32\", \"best_ask\":\"0.33\"}, {\"asset_id\":\"8761897749749422724209054078244794145777693856614463256546737399611489089783\", \"price\":\"0.86\", \"size\":\"207.9\", \"side\":\"SELL\", \"hash\":\"d8c8975d534f5cdd8228b1af40b186bbb41592d9\", \"best_bid\":\"0.67\", \"best_ask\":\"0.68\"}], \"timestamp\":\"1785208158669\", \"event_type\":\"price_change\"}","received_at":"2026-07-28T03:09:18.581210Z","schema_version":"clob-market-ws.price_change.v1","sequence":null,"server_hash":null,"server_timestamp":"1785208158669","session_id":"3e519d9098404c15b234d96025eb1a2b","source":"clob_market_ws"},"received_at":"2026-07-28T03:09:18.581210Z","record_id":"4829222aa035c9b32bfac0eb53ff1fd5d11863f1142eced74f62a592097c88e4","schema_fingerprint":"4aa3821a28b0b7c2400bc59aba4bcc0a76e971dadd19610d3ad38c768e124dc7","schema_version":"edge-lab-recorder.raw.v1","sequence":null,"source":"clob_market_ws"}
{"event_at":"2026-07-28T03:09:18.670000Z","event_fingerprint":"ceb33a7f9e84ea624b37271fe67675b84aefe0d4bc122f6b66e59027f3dda813","payload":{"connection_id":"a6b55582af5f430fb37ad02bf0922475","event_at":"2026-07-28T03:09:18.670000Z","event_type":"price_change","frame_hash":"ee301d463589f0fa299ff2b34693ecc0dc8ae0f01bd00166c09fbfe4cf34573d","frame_index":0,"kind":"data","monotonic_ns":310141615620208,"payload":{"event_type":"price_change","market":"0x779291bef19b6709f61e9764a954aafe9ffae488d50ae674aabdcb4f248006d5","price_changes":[{"asset_id":"14965588658799411272385430903075831224615961675357217884735713260981483529984","best_ask":"0.33","best_bid":"0.32","hash":"f5cb8a1b8e7718c59795f937ebea6f6684e59498","price":"0.15","side":"BUY","size":"142"},{"asset_id":"8761897749749422724209054078244794145777693856614463256546737399611489089783","best_ask":"0.68","best_bid":"0.67","hash":"a723a37bc5d52f17182453267647405c64ef4f60","price":"0.85","side":"SELL","size":"142"}],"timestamp":"1785208158670"},"payload_hash":"9d8f077b4a59a931310a90e2de4ae1fb3d051e23308b22397362efd1042f3459","raw_frame":"{\"market\":\"0x779291bef19b6709f61e9764a954aafe9ffae488d50ae674aabdcb4f248006d5\", \"price_changes\":[{\"asset_id\":\"14965588658799411272385430903075831224615961675357217884735713260981483529984\", \"price\":\"0.15\", \"size\":\"142\", \"side\":\"BUY\", \"hash\":\"f5cb8a1b8e7718c59795f937ebea6f6684e59498\", \"best_bid\":\"0.32\", \"best_ask\":\"0.33\"}, {\"asset_id\":\"8761897749749422724209054078244794145777693856614463256546737399611489089783\", \"price\":\"0.85\", \"size\":\"142\", \"side\":\"SELL\", \"hash\":\"a723a37bc5d52f17182453267647405c64ef4f60\", \"best_bid\":\"0.67\", \"best_ask\":\"0.68\"}], \"timestamp\":\"1785208158670\", \"event_type\":\"price_change\"}","received_at":"2026-07-28T03:09:18.582669Z","schema_version":"clob-market-ws.price_change.v1","sequence":null,"server_hash":null,"server_timestamp":"1785208158670","session_id":"3e519d9098404c15b234d96025eb1a2b","source":"clob_market_ws"},"received_at":"2026-07-28T03:09:18.582669Z","record_id":"3b8c3c24c8464cd7408ba508f4def9314aac4d36313652f5bc743523968f8fc9","schema_fingerprint":"4aa3821a28b0b7c2400bc59aba4bcc0a76e971dadd19610d3ad38c768e124dc7","schema_version":"edge-lab-recorder.raw.v1","sequence":null,"source":"clob_market_ws"}
{"event_at":"2026-07-28T03:09:18.671000Z","event_fingerprint":"faa0147d33b67015e881db793ff5fcf1c8531d110c8e3621c1163ea7187854e5","payload":{"connection_id":"a6b55582af5f430fb37ad02bf0922475","event_at":"2026-07-28T03:09:18.671000Z","event_type":"price_change","frame_hash":"25655cdcb7907ad01ec4c2da17f96964425d9a817e5f49eaca818ed702a6f4f5","frame_index":0,"kind":"data","monotonic_ns":310141617138166,"payload":{"event_type":"price_change","market":"0x779291bef19b6709f61e9764a954aafe9ffae488d50ae674aabdcb4f248006d5","price_changes":[{"asset_id":"14965588658799411272385430903075831224615961675357217884735713260981483529984","best_ask":"0.33","best_bid":"0.32","hash":"972fe4a31a03e04c9671c24f324b3eb3f89bdbec","price":"0.22","side":"BUY","size":"190.5"},{"asset_id":"8761897749749422724209054078244794145777693856614463256546737399611489089783","best_ask":"0.68","best_bid":"0.67","hash":"74f7a79cddfa686f0f714ccf6530557f7cbb2c75","price":"0.78","side":"SELL","size":"190.5"}],"timestamp":"1785208158671"},"payload_hash":"e20c269abbc33cd6190c5aa18eab4d7529ac4139f4b56194150762e5852134cc","raw_frame":"{\"market\":\"0x779291bef19b6709f61e9764a954aafe9ffae488d50ae674aabdcb4f248006d5\", \"price_changes\":[{\"asset_id\":\"14965588658799411272385430903075831224615961675357217884735713260981483529984\", \"price\":\"0.22\", \"size\":\"190.5\", \"side\":\"BUY\", \"hash\":\"972fe4a31a03e04c9671c24f324b3eb3f89bdbec\", \"best_bid\":\"0.32\", \"best_ask\":\"0.33\"}, {\"asset_id\":\"8761897749749422724209054078244794145777693856614463256546737399611489089783\", \"price\":\"0.78\", \"size\":\"190.5\", \"side\":\"SELL\", \"hash\":\"74f7a79cddfa686f0f714ccf6530557f7cbb2c75\", \"best_bid\":\"0.67\", \"best_ask\":\"0.68\"}], \"timestamp\":\"1785208158671\", \"event_type\":\"price_change\"}","received_at":"2026-07-28T03:09:18.584186Z","schema_version":"clob-market-ws.price_change.v1","sequence":null,"server_hash":null,"server_timestamp":"1785208158671","session_id":"3e519d9098404c15b234d96025eb1a2b","source":"clob_market_ws"},"received_at":"2026-07-28T03:09:18.584186Z","record_id":"0f0c3c46fd7c0f88cad81dba3d8e3162b88228a85dcb7dea45ee583d75f41192","schema_fingerprint":"4aa3821a28b0b7c2400bc59aba4bcc0a76e971dadd19610d3ad38c768e124dc7","schema_version":"edge-lab-recorder.raw.v1","sequence":null,"source":"clob_market_ws"}
{"event_at":"2026-07-28T03:09:18.671000Z","event_fingerprint":"0be0a08b2905214f642eedb491ab85539eb9e4cdb40c402494e09ccfb86d17ec","payload":{"connection_id":"a6b55582af5f430fb37ad02bf0922475","event_at":"2026-07-28T03:09:18.671000Z","event_type":"price_change","frame_hash":"bbe1bf0fa6a03812d10e2243019b12445f9c8a709bad5331fdd999370f26b654","frame_index":0,"kind":"data","monotonic_ns":310141618590750,"payload":{"event_type":"price_change","market":"0x779291bef19b6709f61e9764a954aafe9ffae488d50ae674aabdcb4f248006d5","price_changes":[{"asset_id":"8761897749749422724209054078244794145777693856614463256546737399611489089783","best_ask":"0.68","best_bid":"0.67","hash":"70715c2ffb2011f04994e8825ce7f23b18788e5c","price":"0.63","side":"BUY","size":"130.65"},{"asset_id":"14965588658799411272385430903075831224615961675357217884735713260981483529984","best_ask":"0.33","best_bid":"0.32","hash":"5222b11159f2a6d133ddf8c3a96c489b25129b70","price":"0.37","side":"SELL","size":"130.65"}],"timestamp":"1785208158671"},"payload_hash":"e92f51d2b2e9609a8ebaf6023f6f28700cd3357d6018c9683bec6884bb6704ed","raw_frame":"{\"market\":\"0x779291bef19b6709f61e9764a954aafe9ffae488d50ae674aabdcb4f248006d5\", \"price_changes\":[{\"asset_id\":\"8761897749749422724209054078244794145777693856614463256546737399611489089783\", \"price\":\"0.63\", \"size\":\"130.65\", \"side\":\"BUY\", \"hash\":\"70715c2ffb2011f04994e8825ce7f23b18788e5c\", \"best_bid\":\"0.67\", \"best_ask\":\"0.68\"}, {\"asset_id\":\"14965588658799411272385430903075831224615961675357217884735713260981483529984\", \"price\":\"0.37\", \"size\":\"130.65\", \"side\":\"SELL\", \"hash\":\"5222b11159f2a6d133ddf8c3a96c489b25129b70\", \"best_bid\":\"0.32\", \"best_ask\":\"0.33\"}], \"timestamp\":\"1785208158671\", \"event_type\":\"price_change\"}","received_at":"2026-07-28T03:09:18.585639Z","schema_version":"clob-market-ws.price_change.v1","sequence":null,"server_hash":null,"server_timestamp":"1785208158671","session_id":"3e519d9098404c15b234d96025eb1a2b","source":"clob_market_ws"},"received_at":"2026-07-28T03:09:18.585639Z","record_id":"4f39fde87220f4e42614dacebf9b6782912f0f818a9934e5f35a66ebd54a1862","schema_fingerprint":"4aa3821a28b0b7c2400bc59aba4bcc0a76e971dadd19610d3ad38c768e124dc7","schema_version":"edge-lab-recorder.raw.v1","sequence":null,"source":"clob_market_ws"}
{"event_at":"2026-07-28T03:09:18.671000Z","event_fingerprint":"52967e03bfa827afbff8561abde4bad5bee2bc026497884f2806f83fd5589526","payload":{"connection_id":"a6b55582af5f430fb37ad02bf0922475","event_at":"2026-07-28T03:09:18.671000Z","event_type":"price_change","frame_hash":"74e2d489c677cbfec426c05f76b7d84eb28443c07c91b72a6a307139d45ff921","frame_index":0,"kind":"data","monotonic_ns":310141620060791,"payload":{"event_type":"price_change","market":"0x779291bef19b6709f61e9764a954aafe9ffae488d50ae674aabdcb4f248006d5","price_changes":[{"asset_id":"14965588658799411272385430903075831224615961675357217884735713260981483529984","best_ask":"0.33","best_bid":"0.32","hash":"59c40e9875a60ac9981607aba3efb3ebf20f88d4","price":"0.21","side":"BUY","size":"163.1"},{"asset_id":"8761897749749422724209054078244794145777693856614463256546737399611489089783","best_ask":"0.68","best_bid":"0.67","hash":"a4eaccea6be59ae39a49e2cc2c1796824da76ff3","price":"0.79","side":"SELL","size":"163.1"}],"timestamp":"1785208158671"},"payload_hash":"ba62382b016a326e0da405af263a3f21d62de628a2292d4cc4c9bc6424fafce9","raw_frame":"{\"market\":\"0x779291bef19b6709f61e9764a954aafe9ffae488d50ae674aabdcb4f248006d5\", \"price_changes\":[{\"asset_id\":\"14965588658799411272385430903075831224615961675357217884735713260981483529984\", \"price\":\"0.21\", \"size\":\"163.1\", \"side\":\"BUY\", \"hash\":\"59c40e9875a60ac9981607aba3efb3ebf20f88d4\", \"best_bid\":\"0.32\", \"best_ask\":\"0.33\"}, {\"asset_id\":\"8761897749749422724209054078244794145777693856614463256546737399611489089783\", \"price\":\"0.79\", \"size\":\"163.1\", \"side\":\"SELL\", \"hash\":\"a4eaccea6be59ae39a49e2cc2c1796824da76ff3\", \"best_bid\":\"0.67\", \"best_ask\":\"0.68\"}], \"timestamp\":\"1785208158671\", \"event_type\":\"price_change\"}","received_at":"2026-07-28T03:09:18.587109Z","schema_version":"clob-market-ws.price_change.v1","sequence":null,"server_hash":null,"server_timestamp":"1785208158671","session_id":"3e519d9098404c15b234d96025eb1a2b","source":"clob_market_ws"},"received_at":"2026-07-28T03:09:18.587109Z","record_id":"602a2a888025db382da4acd278b4ad67b925ba507c95c490f15cff855f3664ec","schema_fingerprint":"4aa3821a28b0b7c2400bc59aba4bcc0a76e971dadd19610d3ad38c768e124dc7","schema_version":"edge-lab-recorder.raw.v1","sequence":null,"source":"clob_market_ws"}
{"event_at":"2026-07-28T03:09:18.671000Z","event_fingerprint":"487355600766402c8845e77f57bb267a2f1876aa66e6ef031f056d23bb11a40e","payload":{"connection_id":"a6b55582af5f430fb37ad02bf0922475","event_at":"2026-07-28T03:09:18.671000Z","event_type":"price_change","frame_hash":"4e29a83df10dce24fffafae36d8cebe912bf7798a4ace33e678dcebc1b31f609","frame_index":0,"kind":"data","monotonic_ns":310141621556500,"payload":{"event_type":"price_change","market":"0x779291bef19b6709f61e9764a954aafe9ffae488d50ae674aabdcb4f248006d5","price_changes":[{"asset_id":"14965588658799411272385430903075831224615961675357217884735713260981483529984","best_ask":"0.33","best_bid":"0.32","hash":"59c40e9875a60ac9981607aba3efb3ebf20f88d4","price":"0.2","side":"BUY","size":"294.91"},{"asset_id":"8761897749749422724209054078244794145777693856614463256546737399611489089783","best_ask":"0.68","best_bid":"0.67","hash":"a4eaccea6be59ae39a49e2cc2c1796824da76ff3","price":"0.8","side":"SELL","size":"294.91"}],"timestamp":"1785208158671"},"payload_hash":"bf325f81cdc4cc4a7d164fd26f7f6c54b4ddba42cbd0a1cc7cb0989919f7e56f","raw_frame":"{\"market\":\"0x779291bef19b6709f61e9764a954aafe9ffae488d50ae674aabdcb4f248006d5\", \"price_changes\":[{\"asset_id\":\"14965588658799411272385430903075831224615961675357217884735713260981483529984\", \"price\":\"0.2\", \"size\":\"294.91\", \"side\":\"BUY\", \"hash\":\"59c40e9875a60ac9981607aba3efb3ebf20f88d4\", \"best_bid\":\"0.32\", \"best_ask\":\"0.33\"}, {\"asset_id\":\"8761897749749422724209054078244794145777693856614463256546737399611489089783\", \"price\":\"0.8\", \"size\":\"294.91\", \"side\":\"SELL\", \"hash\":\"a4eaccea6be59ae39a49e2cc2c1796824da76ff3\", \"best_bid\":\"0.67\", \"best_ask\":\"0.68\"}], \"timestamp\":\"1785208158671\", \"event_type\":\"price_change\"}","received_at":"2026-07-28T03:09:18.588605Z","schema_version":"clob-market-ws.price_change.v1","sequence":null,"server_hash":null,"server_timestamp":"1785208158671","session_id":"3e519d9098404c15b234d96025eb1a2b","source":"clob_market_ws"},"received_at":"2026-07-28T03:09:18.588605Z","record_id":"46984b0e437047b8d9420bb8c76feba3794b8d0ba9c6590116637c0ec24ba474","schema_fingerprint":"4aa3821a28b0b7c2400bc59aba4bcc0a76e971dadd19610d3ad38c768e124dc7","schema_version":"edge-lab-recorder.raw.v1","sequence":null,"source":"clob_market_ws"}
{"event_at":"2026-07-28T03:09:18.671000Z","event_fingerprint":"68ffabe5b9830de7f5a4fb07e3179a0642387f30c0f730504149d318ac99834d","payload":{"connection_id":"a6b55582af5f430fb37ad02bf0922475","event_at":"2026-07-28T03:09:18.671000Z","event_type":"price_change","frame_hash":"c477253f3cf86c94f36e4ef01f2c455ed0dd2c07ceab66465696ce0b37b7acf5","frame_index":0,"kind":"data","monotonic_ns":310141623035375,"payload":{"event_type":"price_change","market":"0x779291bef19b6709f61e9764a954aafe9ffae488d50ae674aabdcb4f248006d5","price_changes":[{"asset_id":"14965588658799411272385430903075831224615961675357217884735713260981483529984","best_ask":"0.33","best_bid":"0.32","hash":"59c40e9875a60ac9981607aba3efb3ebf20f88d4","price":"0.19","side":"BUY","size":"302.76"},{"asset_id":"8761897749749422724209054078244794145777693856614463256546737399611489089783","best_ask":"0.68","best_bid":"0.67","hash":"a4eaccea6be59ae39a49e2cc2c1796824da76ff3","price":"0.81","side":"SELL","size":"302.76"}],"timestamp":"1785208158671"},"payload_hash":"aefb7006a815e5c3e7c644b8deaae86f54cd0ec5243f4294105a13243ec89a39","raw_frame":"{\"market\":\"0x779291bef19b6709f61e9764a954aafe9ffae488d50ae674aabdcb4f248006d5\", \"price_changes\":[{\"asset_id\":\"14965588658799411272385430903075831224615961675357217884735713260981483529984\", \"price\":\"0.19\", \"size\":\"302.76\", \"side\":\"BUY\", \"hash\":\"59c40e9875a60ac9981607aba3efb3ebf20f88d4\", \"best_bid\":\"0.32\", \"best_ask\":\"0.33\"}, {\"asset_id\":\"8761897749749422724209054078244794145777693856614463256546737399611489089783\", \"price\":\"0.81\", \"size\":\"302.76\", \"side\":\"SELL\", \"hash\":\"a4eaccea6be59ae39a49e2cc2c1796824da76ff3\", \"best_bid\":\"0.67\", \"best_ask\":\"0.68\"}], \"timestamp\":\"1785208158671\", \"event_type\":\"price_change\"}","received_at":"2026-07-28T03:09:18.590084Z","schema_version":"clob-market-ws.price_change.v1","sequence":null,"server_hash":null,"server_timestamp":"1785208158671","session_id":"3e519d9098404c15b234d96025eb1a2b","source":"clob_market_ws"},"received_at":"2026-07-28T03:09:18.590084Z","record_id":"8465e2da2fa389d6f610d2121157553d3fc928e0b04fb9ed0fcbb9c4b7ed011c","schema_fingerprint":"4aa3821a28b0b7c2400bc59aba4bcc0a76e971dadd19610d3ad38c768e124dc7","schema_version":"edge-lab-recorder.raw.v1","sequence":null,"source":"clob_market_ws"}
{"event_at":"2026-07-28T03:09:18.672000Z","event_fingerprint":"c16348ef2091f141f326490eee19bdfcbcc34b7c20c874ca941e1e090c0554a5","payload":{"connection_id":"a6b55582af5f430fb37ad02bf0922475","event_at":"2026-07-28T03:09:18.672000Z","event_type":"price_change","frame_hash":"3d9e180f63505805992891b6f1d59dcc6c773218aef3be8697f4e87d99cfe62d","frame_index":0,"kind":"data","monotonic_ns":310141624488541,"payload":{"event_type":"price_change","market":"0x779291bef19b6709f61e9764a954aafe9ffae488d50ae674aabdcb4f248006d5","price_changes":[{"asset_id":"14965588658799411272385430903075831224615961675357217884735713260981483529984","best_ask":"0.33","best_bid":"0.32","hash":"1a9740f202a2eed332fd7e4ad31e5b61acaa2ce1","price":"0.13","side":"BUY","size":"251.5"},{"asset_id":"8761897749749422724209054078244794145777693856614463256546737399611489089783","best_ask":"0.68","best_bid":"0.67","hash":"3c57fbe8018103e2dd57f2a6edf8b7676699c61c","price":"0.87","side":"SELL","size":"251.5"}],"timestamp":"1785208158672"},"payload_hash":"7ceddf3a3ae5c12c3deabc08c75c91626e273ef298583349f81235c502419b9e","raw_frame":"{\"market\":\"0x779291bef19b6709f61e9764a954aafe9ffae488d50ae674aabdcb4f248006d5\", \"price_changes\":[{\"asset_id\":\"14965588658799411272385430903075831224615961675357217884735713260981483529984\", \"price\":\"0.13\", \"size\":\"251.5\", \"side\":\"BUY\", \"hash\":\"1a9740f202a2eed332fd7e4ad31e5b61acaa2ce1\", \"best_bid\":\"0.32\", \"best_ask\":\"0.33\"}, {\"asset_id\":\"8761897749749422724209054078244794145777693856614463256546737399611489089783\", \"price\":\"0.87\", \"size\":\"251.5\", \"side\":\"SELL\", \"hash\":\"3c57fbe8018103e2dd57f2a6edf8b7676699c61c\", \"best_bid\":\"0.67\", \"best_ask\":\"0.68\"}], \"timestamp\":\"1785208158672\", \"event_type\":\"price_change\"}","received_at":"2026-07-28T03:09:18.591537Z","schema_version":"clob-market-ws.price_change.v1","sequence":null,"server_hash":null,"server_timestamp":"1785208158672","session_id":"3e519d9098404c15b234d96025eb1a2b","source":"clob_market_ws"},"received_at":"2026-07-28T03:09:18.591537Z","record_id":"870a2559c500c03bcba252273ea55ba4e3cd6c58245b599968ff02952543cc8e","schema_fingerprint":"4aa3821a28b0b7c2400bc59aba4bcc0a76e971dadd19610d3ad38c768e124dc7","schema_version":"edge-lab-recorder.raw.v1","sequence":null,"source":"clob_market_ws"}
{"event_at":"2026-07-28T03:09:18.673000Z","event_fingerprint":"32921221c8f71d81675215f06e6806b48675374581f50211b2d0beee652fdb69","payload":{"connection_id":"a6b55582af5f430fb37ad02bf0922475","event_at":"2026-07-28T03:09:18.673000Z","event_type":"price_change","frame_hash":"54f542bd1d2d621fff226e5ceecbccb63e510651bea737d8619b158b8ea81501","frame_index":0,"kind":"data","monotonic_ns":310141625930958,"payload":{"event_type":"price_change","market":"0x779291bef19b6709f61e9764a954aafe9ffae488d50ae674aabdcb4f248006d5","price_changes":[{"asset_id":"8761897749749422724209054078244794145777693856614463256546737399611489089783","best_ask":"0.68","best_bid":"0.67","hash":"2626467d34b1051f519ce9c1f3088395d30bd9e0","price":"0.54","side":"BUY","size":"117.1"},{"asset_id":"14965588658799411272385430903075831224615961675357217884735713260981483529984","best_ask":"0.33","best_bid":"0.32","hash":"b27c40a8766d12d1fdc857ed3bbe090c153300da","price":"0.46","side":"SELL","size":"117.1"}],"timestamp":"1785208158673"},"payload_hash":"48500f23af8fe14f35450dfcf9e5ffb30914c25c54d2ba8a1434814419b98430","raw_frame":"{\"market\":\"0x779291bef19b6709f61e9764a954aafe9ffae488d50ae674aabdcb4f248006d5\", \"price_changes\":[{\"asset_id\":\"8761897749749422724209054078244794145777693856614463256546737399611489089783\", \"price\":\"0.54\", \"size\":\"117.1\", \"side\":\"BUY\", \"hash\":\"2626467d34b1051f519ce9c1f3088395d30bd9e0\", \"best_bid\":\"0.67\", \"best_ask\":\"0.68\"}, {\"asset_id\":\"14965588658799411272385430903075831224615961675357217884735713260981483529984\", \"price\":\"0.46\", \"size\":\"117.1\", \"side\":\"SELL\", \"hash\":\"b27c40a8766d12d1fdc857ed3bbe090c153300da\", \"best_bid\":\"0.32\", \"best_ask\":\"0.33\"}], \"timestamp\":\"1785208158673\", \"event_type\":\"price_change\"}","received_at":"2026-07-28T03:09:18.592979Z","schema_version":"clob-market-ws.price_change.v1","sequence":null,"server_hash":null,"server_timestamp":"1785208158673","session_id":"3e519d9098404c15b234d96025eb1a2b","source":"clob_market_ws"},"received_at":"2026-07-28T03:09:18.592979Z","record_id":"c76f8a45f27d52638d96183deba6e99ae9e96c7da82fc442a2fc853114cb91d8","schema_fingerprint":"4aa3821a28b0b7c2400bc59aba4bcc0a76e971dadd19610d3ad38c768e124dc7","schema_version":"edge-lab-recorder.raw.v1","sequence":null,"source":"clob_market_ws"}
{"event_at":"2026-07-28T03:09:18.673000Z","event_fingerprint":"68130cdd382b1bde8309448ad9d13fb1994df72359ec99f3493d57f92e92e525","payload":{"connection_id":"a6b55582af5f430fb37ad02bf0922475","event_at":"2026-07-28T03:09:18.673000Z","event_type":"price_change","frame_hash":"aef9cc8f5478749c0de98ae974c466d71948b68d36b3abb57c72c38bf94852f0","frame_index":0,"kind":"data","monotonic_ns":310141627401125,"payload":{"event_type":"price_change","market":"0x779291bef19b6709f61e9764a954aafe9ffae488d50ae674aabdcb4f248006d5","price_changes":[{"asset_id":"14965588658799411272385430903075831224615961675357217884735713260981483529984","best_ask":"0.33","best_bid":"0.32","hash":"2cb6dfd64dbaf3eb95001d943aff5c567570de73","price":"0.21","side":"BUY","size":"156.1"},{"asset_id":"8761897749749422724209054078244794145777693856614463256546737399611489089783","best_ask":"0.68","best_bid":"0.67","hash":"306e4b49b99f921fba9200d572fabc7f477e65d2","price":"0.79","side":"SELL","size":"156.1"}],"timestamp":"1785208158673"},"payload_hash":"f1f5c89a4e2e695aca90dc7a36b2d96f1176a72015b5244627cd9328cb7796c0","raw_frame":"{\"market\":\"0x779291bef19b6709f61e9764a954aafe9ffae488d50ae674aabdcb4f248006d5\", \"price_changes\":[{\"asset_id\":\"14965588658799411272385430903075831224615961675357217884735713260981483529984\", \"price\":\"0.21\", \"size\":\"156.1\", \"side\":\"BUY\", \"hash\":\"2cb6dfd64dbaf3eb95001d943aff5c567570de73\", \"best_bid\":\"0.32\", \"best_ask\":\"0.33\"}, {\"asset_id\":\"8761897749749422724209054078244794145777693856614463256546737399611489089783\", \"price\":\"0.79\", \"size\":\"156.1\", \"side\":\"SELL\", \"hash\":\"306e4b49b99f921fba9200d572fabc7f477e65d2\", \"best_bid\":\"0.67\", \"best_ask\":\"0.68\"}], \"timestamp\":\"1785208158673\", \"event_type\":\"price_change\"}","received_at":"2026-07-28T03:09:18.594449Z","schema_version":"clob-market-ws.price_change.v1","sequence":null,"server_hash":null,"server_timestamp":"1785208158673","session_id":"3e519d9098404c15b234d96025eb1a2b","source":"clob_market_ws"},"received_at":"2026-07-28T03:09:18.594449Z","record_id":"3691a4ca307b1b0548930818fcd1ece0d814d5dc9f9adace3651f9a0ab10a2a1","schema_fingerprint":"4aa3821a28b0b7c2400bc59aba4bcc0a76e971dadd19610d3ad38c768e124dc7","schema_version":"edge-lab-recorder.raw.v1","sequence":null,"source":"clob_market_ws"}
{"event_at":"2026-07-28T03:09:18.674000Z","event_fingerprint":"999a5c1b22e63be84fa962a065910f2dd5ec186000b404dd6d7bba2848545a0e","payload":{"connection_id":"a6b55582af5f430fb37ad02bf0922475","event_at":"2026-07-28T03:09:18.674000Z","event_type":"price_change","frame_hash":"26d8027e981a1c343d32231d0bc00df311491939044440bc833b03d2f8c1596c","frame_index":0,"kind":"data","monotonic_ns":310141628846791,"payload":{"event_type":"price_change","market":"0x779291bef19b6709f61e9764a954aafe9ffae488d50ae674aabdcb4f248006d5","price_changes":[{"asset_id":"14965588658799411272385430903075831224615961675357217884735713260981483529984","best_ask":"0.33","best_bid":"0.32","hash":"8be5bb93dc91751bd52c49bb6dade51d84342648","price":"0.3","side":"BUY","size":"30"},{"asset_id":"8761897749749422724209054078244794145777693856614463256546737399611489089783","best_ask":"0.68","best_bid":"0.67","hash":"51692bd7dc3edd8bba4c356192674c521084dd5b","price":"0.7","side":"SELL","size":"30"}],"timestamp":"1785208158674"},"payload_hash":"d8ebc9124ed1edc831227d4c51df99e3f4c26b59a5bc622d980764fb93383f84","raw_frame":"{\"market\":\"0x779291bef19b6709f61e9764a954aafe9ffae488d50ae674aabdcb4f248006d5\", \"price_changes\":[{\"asset_id\":\"14965588658799411272385430903075831224615961675357217884735713260981483529984\", \"price\":\"0.3\", \"size\":\"30\", \"side\":\"BUY\", \"hash\":\"8be5bb93dc91751bd52c49bb6dade51d84342648\", \"best_bid\":\"0.32\", \"best_ask\":\"0.33\"}, {\"asset_id\":\"8761897749749422724209054078244794145777693856614463256546737399611489089783\", \"price\":\"0.7\", \"size\":\"30\", \"side\":\"SELL\", \"hash\":\"51692bd7dc3edd8bba4c356192674c521084dd5b\", \"best_bid\":\"0.67\", \"best_ask\":\"0.68\"}], \"timestamp\":\"1785208158674\", \"event_type\":\"price_change\"}","received_at":"2026-07-28T03:09:18.595894Z","schema_version":"clob-market-ws.price_change.v1","sequence":null,"server_hash":null,"server_timestamp":"1785208158674","session_id":"3e519d9098404c15b234d96025eb1a2b","source":"clob_market_ws"},"received_at":"2026-07-28T03:09:18.595894Z","record_id":"f78cd6483dcd24852bd4f272c7e0e07afafeea8cf3f2efaaeac2924966230105","schema_fingerprint":"4aa3821a28b0b7c2400bc59aba4bcc0a76e971dadd19610d3ad38c768e124dc7","schema_version":"edge-lab-recorder.raw.v1","sequence":null,"source":"clob_market_ws"}
{"event_at":"2026-07-28T03:09:18.674000Z","event_fingerprint":"5cd6976692d4845d55b6016059cf7e2289142114b22115cac897bf51200be21d","payload":{"connection_id":"a6b55582af5f430fb37ad02bf0922475","event_at":"2026-07-28T03:09:18.674000Z","event_type":"price_change","frame_hash":"b99b616632830ad049ec44f0d08eb7923e72aa3f10e6e118b0895aa5a54c75bf","frame_index":0,"kind":"data","monotonic_ns":310141630328875,"payload":{"event_type":"price_change","market":"0x779291bef19b6709f61e9764a954aafe9ffae488d50ae674aabdcb4f248006d5","price_changes":[{"asset_id":"14965588658799411272385430903075831224615961675357217884735713260981483529984","best_ask":"0.33","best_bid":"0.32","hash":"cdb40a42b47ab9acae58b9be65c770cee6fadcd6","price":"0.18","side":"BUY","size":"296.17"},{"asset_id":"8761897749749422724209054078244794145777693856614463256546737399611489089783","best_ask":"0.68","best_bid":"0.67","hash":"5324f623105b6da46ed6a7210f17ca7120577e50","price":"0.82","side":"SELL","size":"296.17"}],"timestamp":"1785208158674"},"payload_hash":"583889095b0c95987d5bb9e2bbb06c10580b6d28884cfaf665c90da2032f71f7","raw_frame":"{\"market\":\"0x779291bef19b6709f61e9764a954aafe9ffae488d50ae674aabdcb4f248006d5\", \"price_changes\":[{\"asset_id\":\"14965588658799411272385430903075831224615961675357217884735713260981483529984\", \"price\":\"0.18\", \"size\":\"296.17\", \"side\":\"BUY\", \"hash\":\"cdb40a42b47ab9acae58b9be65c770cee6fadcd6\", \"best_bid\":\"0.32\", \"best_ask\":\"0.33\"}, {\"asset_id\":\"8761897749749422724209054078244794145777693856614463256546737399611489089783\", \"price\":\"0.82\", \"size\":\"296.17\", \"side\":\"SELL\", \"hash\":\"5324f623105b6da46ed6a7210f17ca7120577e50\", \"best_bid\":\"0.67\", \"best_ask\":\"0.68\"}], \"timestamp\":\"1785208158674\", \"event_type\":\"price_change\"}","received_at":"2026-07-28T03:09:18.597377Z","schema_version":"clob-market-ws.price_change.v1","sequence":null,"server_hash":null,"server_timestamp":"1785208158674","session_id":"3e519d9098404c15b234d96025eb1a2b","source":"clob_market_ws"},"received_at":"2026-07-28T03:09:18.597377Z","record_id":"9042050406131b2fac2ed8a26a8bfc58ece5af3e5eafccfcff022780cab5248e","schema_fingerprint":"4aa3821a28b0b7c2400bc59aba4bcc0a76e971dadd19610d3ad38c768e124dc7","schema_version":"edge-lab-recorder.raw.v1","sequence":null,"source":"clob_market_ws"}
{"event_at":"2026-07-28T03:09:18.676000Z","event_fingerprint":"a6f4e08230164464a88372bce3ca93017038d32679ee7d7b634dda9d5afc872e","payload":{"connection_id":"a6b55582af5f430fb37ad02bf0922475","event_at":"2026-07-28T03:09:18.676000Z","event_type":"price_change","frame_hash":"225a8da978861855b2a00455a9b21b8c18603a88636777555612b53a97e68bff","frame_index":0,"kind":"data","monotonic_ns":310141631789916,"payload":{"event_type":"price_change","market":"0x779291bef19b6709f61e9764a954aafe9ffae488d50ae674aabdcb4f248006d5","price_changes":[{"asset_id":"14965588658799411272385430903075831224615961675357217884735713260981483529984","best_ask":"0.33","best_bid":"0.32","hash":"c99bcbacc6af99b8b55a9439cca516b1a5f6eec3","price":"0.15","side":"BUY","size":"275"},{"asset_id":"8761897749749422724209054078244794145777693856614463256546737399611489089783","best_ask":"0.68","best_bid":"0.67","hash":"8678b014b19547752a62a1d1ace0ce46161e93db","price":"0.85","side":"SELL","size":"275"}],"timestamp":"1785208158676"},"payload_hash":"b614d69b177edfdfe42b7ca6a02ac0360f4d78e884f7420240fa494f4e8524f3","raw_frame":"{\"market\":\"0x779291bef19b6709f61e9764a954aafe9ffae488d50ae674aabdcb4f248006d5\", \"price_changes\":[{\"asset_id\":\"14965588658799411272385430903075831224615961675357217884735713260981483529984\", \"price\":\"0.15\", \"size\":\"275\", \"side\":\"BUY\", \"hash\":\"c99bcbacc6af99b8b55a9439cca516b1a5f6eec3\", \"best_bid\":\"0.32\", \"best_ask\":\"0.33\"}, {\"asset_id\":\"8761897749749422724209054078244794145777693856614463256546737399611489089783\", \"price\":\"0.85\", \"size\":\"275\", \"side\":\"SELL\", \"hash\":\"8678b014b19547752a62a1d1ace0ce46161e93db\", \"best_bid\":\"0.67\", \"best_ask\":\"0.68\"}], \"timestamp\":\"1785208158676\", \"event_type\":\"price_change\"}","received_at":"2026-07-28T03:09:18.598838Z","schema_version":"clob-market-ws.price_change.v1","sequence":null,"server_hash":null,"server_timestamp":"1785208158676","session_id":"3e519d9098404c15b234d96025eb1a2b","source":"clob_market_ws"},"received_at":"2026-07-28T03:09:18.598838Z","record_id":"ab4229be15f29482746ad6fe646cada8110111268da3d85e079c4dcc5bf1e4c2","schema_fingerprint":"4aa3821a28b0b7c2400bc59aba4bcc0a76e971dadd19610d3ad38c768e124dc7","schema_version":"edge-lab-recorder.raw.v1","sequence":null,"source":"clob_market_ws"}
{"event_at":"2026-07-28T03:09:18.677000Z","event_fingerprint":"9ff1cd042fa2f1ebe04f2b88c69fad13854bbd6e8731781472c8b22b2b6d3dbc","payload":{"connection_id":"a6b55582af5f430fb37ad02bf0922475","event_at":"2026-07-28T03:09:18.677000Z","event_type":"price_change","frame_hash":"da16eac16953d271fe5b190438e450db1c192446196abe6c771b1ad89bdb6179","frame_index":0,"kind":"data","monotonic_ns":310141633240500,"payload":{"event_type":"price_change","market":"0x779291bef19b6709f61e9764a954aafe9ffae488d50ae674aabdcb4f248006d5","price_changes":[{"asset_id":"8761897749749422724209054078244794145777693856614463256546737399611489089783","best_ask":"0.68","best_bid":"0.67","hash":"a04536abd153604658a7ff4610653d02e1e34b85","price":"0.6","side":"BUY","size":"322.28"},{"asset_id":"14965588658799411272385430903075831224615961675357217884735713260981483529984","best_ask":"0.33","best_bid":"0.32","hash":"d2f6da2cc205fbf319a8b846b5151fbb091a4e7c","price":"0.4","side":"SELL","size":"322.28"}],"timestamp":"1785208158677"},"payload_hash":"130191c6de0e7b5654f87ac0d5c1db08486cc595f5cb68d063f39ac8e46e5636","raw_frame":"{\"market\":\"0x779291bef19b6709f61e9764a954aafe9ffae488d50ae674aabdcb4f248006d5\", \"price_changes\":[{\"asset_id\":\"8761897749749422724209054078244794145777693856614463256546737399611489089783\", \"price\":\"0.6\", \"size\":\"322.28\", \"side\":\"BUY\", \"hash\":\"a04536abd153604658a7ff4610653d02e1e34b85\", \"best_bid\":\"0.67\", \"best_ask\":\"0.68\"}, {\"asset_id\":\"14965588658799411272385430903075831224615961675357217884735713260981483529984\", \"price\":\"0.4\", \"size\":\"322.28\", \"side\":\"SELL\", \"hash\":\"d2f6da2cc205fbf319a8b846b5151fbb091a4e7c\", \"best_bid\":\"0.32\", \"best_ask\":\"0.33\"}], \"timestamp\":\"1785208158677\", \"event_type\":\"price_change\"}","received_at":"2026-07-28T03:09:18.600289Z","schema_version":"clob-market-ws.price_change.v1","sequence":null,"server_hash":null,"server_timestamp":"1785208158677","session_id":"3e519d9098404c15b234d96025eb1a2b","source":"clob_market_ws"},"received_at":"2026-07-28T03:09:18.600289Z","record_id":"3db4f44661694e176e3a38f1637a7244a6ede69f9ec655cacc3db259b3766c32","schema_fingerprint":"4aa3821a28b0b7c2400bc59aba4bcc0a76e971dadd19610d3ad38c768e124dc7","schema_version":"edge-lab-recorder.raw.v1","sequence":null,"source":"clob_market_ws"}
{"event_at":"2026-07-28T03:09:18.677000Z","event_fingerprint":"955241f6d413a8b8f858862acaef8e7152523a61bf98ac1e641a903d90043cf2","payload":{"connection_id":"a6b55582af5f430fb37ad02bf0922475","event_at":"2026-07-28T03:09:18.677000Z","event_type":"price_change","frame_hash":"2f716072eddb669c41bb4646f636e5b3d118f28b7bc1b4febbd196eef3b346b0","frame_index":0,"kind":"data","monotonic_ns":310141634700458,"payload":{"event_type":"price_change","market":"0x779291bef19b6709f61e9764a954aafe9ffae488d50ae674aabdcb4f248006d5","price_changes":[{"asset_id":"8761897749749422724209054078244794145777693856614463256546737399611489089783","best_ask":"0.68","best_bid":"0.67","hash":"12a0aa4589785bbdfc3812fa2015bfc767bd7c9d","price":"0.53","side":"BUY","size":"47"},{"asset_id":"14965588658799411272385430903075831224615961675357217884735713260981483529984","best_ask":"0.33","best_bid":"0.32","hash":"c48a5b19335d48c4d5743ae7b9f5dbb6506a1b2c","price":"0.47","side":"SELL","size":"47"}],"timestamp":"1785208158677"},"payload_hash":"e94dce74da7f57cc576e40a82ac0e46bda3a15f94c43a0bb1f0b7288d2972699","raw_frame":"{\"market\":\"0x779291bef19b6709f61e9764a954aafe9ffae488d50ae674aabdcb4f248006d5\", \"price_changes\":[{\"asset_id\":\"8761897749749422724209054078244794145777693856614463256546737399611489089783\", \"price\":\"0.53\", \"size\":\"47\", \"side\":\"BUY\", \"hash\":\"12a0aa4589785bbdfc3812fa2015bfc767bd7c9d\", \"best_bid\":\"0.67\", \"best_ask\":\"0.68\"}, {\"asset_id\":\"14965588658799411272385430903075831224615961675357217884735713260981483529984\", \"price\":\"0.47\", \"size\":\"47\", \"side\":\"SELL\", \"hash\":\"c48a5b19335d48c4d5743ae7b9f5dbb6506a1b2c\", \"best_bid\":\"0.32\", \"best_ask\":\"0.33\"}], \"timestamp\":\"1785208158677\", \"event_type\":\"price_change\"}","received_at":"2026-07-28T03:09:18.601749Z","schema_version":"clob-market-ws.price_change.v1","sequence":null,"server_hash":null,"server_timestamp":"1785208158677","session_id":"3e519d9098404c15b234d96025eb1a2b","source":"clob_market_ws"},"received_at":"2026-07-28T03:09:18.601749Z","record_id":"43c302872217dce83bd6e2f3372fddcb63ce7a805001cf19214693e4504fe32d","schema_fingerprint":"4aa3821a28b0b7c2400bc59aba4bcc0a76e971dadd19610d3ad38c768e124dc7","schema_version":"edge-lab-recorder.raw.v1","sequence":null,"source":"clob_market_ws"}
{"event_at":"2026-07-28T03:09:18.678000Z","event_fingerprint":"fa4039f782910206a83ff78f9404f04a6ba66db2128f43f62e3b27045c8de44b","payload":{"connection_id":"a6b55582af5f430fb37ad02bf0922475","event_at":"2026-07-28T03:09:18.678000Z","event_type":"price_change","frame_hash":"c13f020d91182600698b2dba7c16a0b44d14da8b235f105dcca096a19f3ca426","frame_index":0,"kind":"data","monotonic_ns":310141636139291,"payload":{"event_type":"price_change","market":"0x779291bef19b6709f61e9764a954aafe9ffae488d50ae674aabdcb4f248006d5","price_changes":[{"asset_id":"8761897749749422724209054078244794145777693856614463256546737399611489089783","best_ask":"0.68","best_bid":"0.67","hash":"73b25cff14e612ee948118ce8086e93baa6f7435","price":"0.62","side":"BUY","size":"70.05"},{"asset_id":"14965588658799411272385430903075831224615961675357217884735713260981483529984","best_ask":"0.33","best_bid":"0.32","hash":"efc7ff4cbd2123ad702db7643198dfb4158ca9e6","price":"0.38","side":"SELL","size":"70.05"}],"timestamp":"1785208158678"},"payload_hash":"d341abf9be430fbdc7ba91325bad9d4465cd355e968980b6ebcc4bd06f1d7458","raw_frame":"{\"market\":\"0x779291bef19b6709f61e9764a954aafe9ffae488d50ae674aabdcb4f248006d5\", \"price_changes\":[{\"asset_id\":\"8761897749749422724209054078244794145777693856614463256546737399611489089783\", \"price\":\"0.62\", \"size\":\"70.05\", \"side\":\"BUY\", \"hash\":\"73b25cff14e612ee948118ce8086e93baa6f7435\", \"best_bid\":\"0.67\", \"best_ask\":\"0.68\"}, {\"asset_id\":\"14965588658799411272385430903075831224615961675357217884735713260981483529984\", \"price\":\"0.38\", \"size\":\"70.05\", \"side\":\"SELL\", \"hash\":\"efc7ff4cbd2123ad702db7643198dfb4158ca9e6\", \"best_bid\":\"0.32\", \"best_ask\":\"0.33\"}], \"timestamp\":\"1785208158678\", \"event_type\":\"price_change\"}","received_at":"2026-07-28T03:09:18.603187Z","schema_version":"clob-market-ws.price_change.v1","sequence":null,"server_hash":null,"server_timestamp":"1785208158678","session_id":"3e519d9098404c15b234d96025eb1a2b","source":"clob_market_ws"},"received_at":"2026-07-28T03:09:18.603187Z","record_id":"304fd0a444e1e7fe356ec94e2352e27688625f7b44bff2e2c222d49452994bc2","schema_fingerprint":"4aa3821a28b0b7c2400bc59aba4bcc0a76e971dadd19610d3ad38c768e124dc7","schema_version":"edge-lab-recorder.raw.v1","sequence":null,"source":"clob_market_ws"}
{"event_at":"2026-07-28T03:09:18.678000Z","event_fingerprint":"2cca0968ff6d56106f99bfb3d959c073d1110a24c1d38ccb7c99a4ef59f93552","payload":{"connection_id":"a6b55582af5f430fb37ad02bf0922475","event_at":"2026-07-28T03:09:18.678000Z","event_type":"price_change","frame_hash":"7c968b0abe00e985dc9beb373562aef04518d6072db958ad79989df3c6ea1dfd","frame_index":0,"kind":"data","monotonic_ns":310141637596458,"payload":{"event_type":"price_change","market":"0x779291bef19b6709f61e9764a954aafe9ffae488d50ae674aabdcb4f248006d5","price_changes":[{"asset_id":"14965588658799411272385430903075831224615961675357217884735713260981483529984","best_ask":"0.33","best_bid":"0.32","hash":"0ffb956ed4659912bfb5fea938d8e8f38a595308","price":"0.18","side":"BUY","size":"277.3"},{"asset_id":"8761897749749422724209054078244794145777693856614463256546737399611489089783","best_ask":"0.68","best_bid":"0.67","hash":"d9ab88a71f3006f3b87a332328da8609a1c96dcb","price":"0.82","side":"SELL","size":"277.3"}],"timestamp":"1785208158678"},"payload_hash":"b8d7ce9bbe4ef1bb04a7f04168f4abaccad28466eef4f7517ba0df6ec3af6be1","raw_frame":"{\"market\":\"0x779291bef19b6709f61e9764a954aafe9ffae488d50ae674aabdcb4f248006d5\", \"price_changes\":[{\"asset_id\":\"14965588658799411272385430903075831224615961675357217884735713260981483529984\", \"price\":\"0.18\", \"size\":\"277.3\", \"side\":\"BUY\", \"hash\":\"0ffb956ed4659912bfb5fea938d8e8f38a595308\", \"best_bid\":\"0.32\", \"best_ask\":\"0.33\"}, {\"asset_id\":\"8761897749749422724209054078244794145777693856614463256546737399611489089783\", \"price\":\"0.82\", \"size\":\"277.3\", \"side\":\"SELL\", \"hash\":\"d9ab88a71f3006f3b87a332328da8609a1c96dcb\", \"best_bid\":\"0.67\", \"best_ask\":\"0.68\"}], \"timestamp\":\"1785208158678\", \"event_type\":\"price_change\"}","received_at":"2026-07-28T03:09:18.604644Z","schema_version":"clob-market-ws.price_change.v1","sequence":null,"server_hash":null,"server_timestamp":"1785208158678","session_id":"3e519d9098404c15b234d96025eb1a2b","source":"clob_market_ws"},"received_at":"2026-07-28T03:09:18.604644Z","record_id":"710f4361e5a7e82e8391808c7702c250d9822c1d68e722a31e1edec2a956125b","schema_fingerprint":"4aa3821a28b0b7c2400bc59aba4bcc0a76e971dadd19610d3ad38c768e124dc7","schema_version":"edge-lab-recorder.raw.v1","sequence":null,"source":"clob_market_ws"}
{"event_at":"2026-07-28T03:09:18.678000Z","event_fingerprint":"271284c74467436224ccc605106516765615d9722acf0e34f328ee485a03f50f","payload":{"connection_id":"a6b55582af5f430fb37ad02bf0922475","event_at":"2026-07-28T03:09:18.678000Z","event_type":"price_change","frame_hash":"ccbb49d002f27bb8aa0a535a8cba477d87e586606a97a7b9c882e6b17b12845a","frame_index":0,"kind":"data","monotonic_ns":310141639043625,"payload":{"event_type":"price_change","market":"0x779291bef19b6709f61e9764a954aafe9ffae488d50ae674aabdcb4f248006d5","price_changes":[{"asset_id":"14965588658799411272385430903075831224615961675357217884735713260981483529984","best_ask":"0.33","best_bid":"0.32","hash":"9af2a2fdb3e2591787b4fc81c73df513d3abf842","price":"0.31","side":"BUY","size":"30"},{"asset_id":"8761897749749422724209054078244794145777693856614463256546737399611489089783","best_ask":"0.68","best_bid":"0.67","hash":"2579ef8ef8c02ddfbb62252cc3e61ea61d9cf424","price":"0.69","side":"SELL","size":"30"}],"timestamp":"1785208158678"},"payload_hash":"094224ad1c9b50c61b875dbcda72063442cd7e2dd6f7a9d87a318bff6a5fb974","raw_frame":"{\"market\":\"0x779291bef19b6709f61e9764a954aafe9ffae488d50ae674aabdcb4f248006d5\", \"price_changes\":[{\"asset_id\":\"14965588658799411272385430903075831224615961675357217884735713260981483529984\", \"price\":\"0.31\", \"size\":\"30\", \"side\":\"BUY\", \"hash\":\"9af2a2fdb3e2591787b4fc81c73df513d3abf842\", \"best_bid\":\"0.32\", \"best_ask\":\"0.33\"}, {\"asset_id\":\"8761897749749422724209054078244794145777693856614463256546737399611489089783\", \"price\":\"0.69\", \"size\":\"30\", \"side\":\"SELL\", \"hash\":\"2579ef8ef8c02ddfbb62252cc3e61ea61d9cf424\", \"best_bid\":\"0.67\", \"best_ask\":\"0.68\"}], \"timestamp\":\"1785208158678\", \"event_type\":\"price_change\"}","received_at":"2026-07-28T03:09:18.606092Z","schema_version":"clob-market-ws.price_change.v1","sequence":null,"server_hash":null,"server_timestamp":"1785208158678","session_id":"3e519d9098404c15b234d96025eb1a2b","source":"clob_market_ws"},"received_at":"2026-07-28T03:09:18.606092Z","record_id":"d90bc56c45cf66d8f2b6de01ab99777ee582908817cd34db8339e4fb236a63b3","schema_fingerprint":"4aa3821a28b0b7c2400bc59aba4bcc0a76e971dadd19610d3ad38c768e124dc7","schema_version":"edge-lab-recorder.raw.v1","sequence":null,"source":"clob_market_ws"}
{"event_at":"2026-07-28T03:09:18.678000Z","event_fingerprint":"35610f55482a8eff2d637591ba177d689abca32f90fb925a77073a08a445ea17","payload":{"connection_id":"a6b55582af5f430fb37ad02bf0922475","event_at":"2026-07-28T03:09:18.678000Z","event_type":"price_change","frame_hash":"ebcf42a7f138be7097640d391eeba1f185cd491d19fd1ae129481f125f247b94","frame_index":0,"kind":"data","monotonic_ns":310141640535458,"payload":{"event_type":"price_change","market":"0x779291bef19b6709f61e9764a954aafe9ffae488d50ae674aabdcb4f248006d5","price_changes":[{"asset_id":"14965588658799411272385430903075831224615961675357217884735713260981483529984","best_ask":"0.33","best_bid":"0.32","hash":"6185eeee66c09d69f721e06e2b657d11b4e2ae96","price":"0.26","side":"BUY","size":"145"},{"asset_id":"8761897749749422724209054078244794145777693856614463256546737399611489089783","best_ask":"0.68","best_bid":"0.67","hash":"cf452a2c32a6e144f665f2e12350d5b7fe2cafd9","price":"0.74","side":"SELL","size":"145"}],"timestamp":"1785208158678"},"payload_hash":"4934954260da392d20c7f2b11aefabe215756b6768e93da370dec3b1077c652b","raw_frame":"{\"market\":\"0x779291bef19b6709f61e9764a954aafe9ffae488d50ae674aabdcb4f248006d5\", \"price_changes\":[{\"asset_id\":\"14965588658799411272385430903075831224615961675357217884735713260981483529984\", \"price\":\"0.26\", \"size\":\"145\", \"side\":\"BUY\", \"hash\":\"6185eeee66c09d69f721e06e2b657d11b4e2ae96\", \"best_bid\":\"0.32\", \"best_ask\":\"0.33\"}, {\"asset_id\":\"8761897749749422724209054078244794145777693856614463256546737399611489089783\", \"price\":\"0.74\", \"size\":\"145\", \"side\":\"SELL\", \"hash\":\"cf452a2c32a6e144f665f2e12350d5b7fe2cafd9\", \"best_bid\":\"0.67\", \"best_ask\":\"0.68\"}], \"timestamp\":\"1785208158678\", \"event_type\":\"price_change\"}","received_at":"2026-07-28T03:09:18.607581Z","schema_version":"clob-market-ws.price_change.v1","sequence":null,"server_hash":null,"server_timestamp":"1785208158678","session_id":"3e519d9098404c15b234d96025eb1a2b","source":"clob_market_ws"},"received_at":"2026-07-28T03:09:18.607581Z","record_id":"7892216ad63e02d0d65f4de741ea1a8610c43daaf71cae476d63228cda48ef86","schema_fingerprint":"4aa3821a28b0b7c2400bc59aba4bcc0a76e971dadd19610d3ad38c768e124dc7","schema_version":"edge-lab-recorder.raw.v1","sequence":null,"source":"clob_market_ws"}
{"event_at":"2026-07-28T03:09:18.679000Z","event_fingerprint":"fe71db1826bced3ce402266479679e965a74eb94fb802b10174eb339252e3d05","payload":{"connection_id":"a6b55582af5f430fb37ad02bf0922475","event_at":"2026-07-28T03:09:18.679000Z","event_type":"price_change","frame_hash":"8208a5da261c4006a2a802ff4399894cb7730272eac2f53ecff10dbf2fbd702c","frame_index":0,"kind":"data","monotonic_ns":310141642051958,"payload":{"event_type":"price_change","market":"0x779291bef19b6709f61e9764a954aafe9ffae488d50ae674aabdcb4f248006d5","price_changes":[{"asset_id":"8761897749749422724209054078244794145777693856614463256546737399611489089783","best_ask":"0.68","best_bid":"0.67","hash":"d89234c978b3c17a68c20360bd73fa0763b070f3","price":"0.66","side":"BUY","size":"116.05"},{"asset_id":"14965588658799411272385430903075831224615961675357217884735713260981483529984","best_ask":"0.33","best_bid":"0.32","hash":"f87453ee6704f59987b26a7370a704afaba0e72e","price":"0.34","side":"SELL","size":"116.05"}],"timestamp":"1785208158679"},"payload_hash":"3dd6d744f11fb9c4a686fa7c8767730d7c70165bd926b0cf3704a201d70714dd","raw_frame":"{\"market\":\"0x779291bef19b6709f61e9764a954aafe9ffae488d50ae674aabdcb4f248006d5\", \"price_changes\":[{\"asset_id\":\"8761897749749422724209054078244794145777693856614463256546737399611489089783\", \"price\":\"0.66\", \"size\":\"116.05\", \"side\":\"BUY\", \"hash\":\"d89234c978b3c17a68c20360bd73fa0763b070f3\", \"best_bid\":\"0.67\", \"best_ask\":\"0.68\"}, {\"asset_id\":\"14965588658799411272385430903075831224615961675357217884735713260981483529984\", \"price\":\"0.34\", \"size\":\"116.05\", \"side\":\"SELL\", \"hash\":\"f87453ee6704f59987b26a7370a704afaba0e72e\", \"best_bid\":\"0.32\", \"best_ask\":\"0.33\"}], \"timestamp\":\"1785208158679\", \"event_type\":\"price_change\"}","received_at":"2026-07-28T03:09:18.609099Z","schema_version":"clob-market-ws.price_change.v1","sequence":null,"server_hash":null,"server_timestamp":"1785208158679","session_id":"3e519d9098404c15b234d96025eb1a2b","source":"clob_market_ws"},"received_at":"2026-07-28T03:09:18.609099Z","record_id":"0b08d8cef6e193cddc8c7f0e2f2c8e1c808ef7205e9b0c6553f43ab8c703753d","schema_fingerprint":"4aa3821a28b0b7c2400bc59aba4bcc0a76e971dadd19610d3ad38c768e124dc7","schema_version":"edge-lab-recorder.raw.v1","sequence":null,"source":"clob_market_ws"}
{"event_at":"2026-07-28T03:09:18.680000Z","event_fingerprint":"c27c90d232314b14e18a75ce983fedd3f00b042e446f96e696c054a5d2b9db56","payload":{"connection_id":"a6b55582af5f430fb37ad02bf0922475","event_at":"2026-07-28T03:09:18.680000Z","event_type":"price_change","frame_hash":"2f6c69931d67f9a895229d10c068a195657dff15516627e8f049480bce6d3ef9","frame_index":0,"kind":"data","monotonic_ns":310141643531916,"payload":{"event_type":"price_change","market":"0x779291bef19b6709f61e9764a954aafe9ffae488d50ae674aabdcb4f248006d5","price_changes":[{"asset_id":"8761897749749422724209054078244794145777693856614463256546737399611489089783","best_ask":"0.68","best_bid":"0.67","hash":"7b248c2dcb7917470b2af727a8428b20592760d1","price":"0.62","side":"BUY","size":"77.55"},{"asset_id":"14965588658799411272385430903075831224615961675357217884735713260981483529984","best_ask":"0.33","best_bid":"0.32","hash":"05741a8e16dd6d087dc77304452e514dbfc72170","price":"0.38","side":"SELL","size":"77.55"}],"timestamp":"1785208158680"},"payload_hash":"edde73e4fd0a3f147f14d0743e285624dacbcd0ebebfcebe1d855e99bcb839bf","raw_frame":"{\"market\":\"0x779291bef19b6709f61e9764a954aafe9ffae488d50ae674aabdcb4f248006d5\", \"price_changes\":[{\"asset_id\":\"8761897749749422724209054078244794145777693856614463256546737399611489089783\", \"price\":\"0.62\", \"size\":\"77.55\", \"side\":\"BUY\", \"hash\":\"7b248c2dcb7917470b2af727a8428b20592760d1\", \"best_bid\":\"0.67\", \"best_ask\":\"0.68\"}, {\"asset_id\":\"14965588658799411272385430903075831224615961675357217884735713260981483529984\", \"price\":\"0.38\", \"size\":\"77.55\", \"side\":\"SELL\", \"hash\":\"05741a8e16dd6d087dc77304452e514dbfc72170\", \"best_bid\":\"0.32\", \"best_ask\":\"0.33\"}], \"timestamp\":\"1785208158680\", \"event_type\":\"price_change\"}","received_at":"2026-07-28T03:09:18.610579Z","schema_version":"clob-market-ws.price_change.v1","sequence":null,"server_hash":null,"server_timestamp":"1785208158680","session_id":"3e519d9098404c15b234d96025eb1a2b","source":"clob_market_ws"},"received_at":"2026-07-28T03:09:18.610579Z","record_id":"2e8cab3b4c967b5b183b4216f09459fa836d00822dd4b76aaa72573f5791f6d1","schema_fingerprint":"4aa3821a28b0b7c2400bc59aba4bcc0a76e971dadd19610d3ad38c768e124dc7","schema_version":"edge-lab-recorder.raw.v1","sequence":null,"source":"clob_market_ws"}
{"event_at":"2026-07-28T03:09:18.681000Z","event_fingerprint":"5b37abf87cd2dec0d22d311bdd44fe341aecf303de031df516448cc8bf723995","payload":{"connection_id":"a6b55582af5f430fb37ad02bf0922475","event_at":"2026-07-28T03:09:18.681000Z","event_type":"price_change","frame_hash":"803c95b22810596b0b25934214d0ef08dfa8067a83c2fb48dfc74e6913caed14","frame_index":0,"kind":"data","monotonic_ns":310141645048166,"payload":{"event_type":"price_change","market":"0x779291bef19b6709f61e9764a954aafe9ffae488d50ae674aabdcb4f248006d5","price_changes":[{"asset_id":"14965588658799411272385430903075831224615961675357217884735713260981483529984","best_ask":"0.33","best_bid":"0.32","hash":"c2ab8bf2cfc34d9b8057ba9c7da58a5ac2c2030f","price":"0.11","side":"BUY","size":"255.6"},{"asset_id":"8761897749749422724209054078244794145777693856614463256546737399611489089783","best_ask":"0.68","best_bid":"0.67","hash":"030a09cf2a4c1897d4c403450679cc5b6d0b3e89","price":"0.89","side":"SELL","size":"255.6"}],"timestamp":"1785208158681"},"payload_hash":"9422180e903738f8e119bf1ebe676160d928b2ff24b16008e233922519b4da6a","raw_frame":"{\"market\":\"0x779291bef19b6709f61e9764a954aafe9ffae488d50ae674aabdcb4f248006d5\", \"price_changes\":[{\"asset_id\":\"14965588658799411272385430903075831224615961675357217884735713260981483529984\", \"price\":\"0.11\", \"size\":\"255.6\", \"side\":\"BUY\", \"hash\":\"c2ab8bf2cfc34d9b8057ba9c7da58a5ac2c2030f\", \"best_bid\":\"0.32\", \"best_ask\":\"0.33\"}, {\"asset_id\":\"8761897749749422724209054078244794145777693856614463256546737399611489089783\", \"price\":\"0.89\", \"size\":\"255.6\", \"side\":\"SELL\", \"hash\":\"030a09cf2a4c1897d4c403450679cc5b6d0b3e89\", \"best_bid\":\"0.67\", \"best_ask\":\"0.68\"}], \"timestamp\":\"1785208158681\", \"event_type\":\"price_change\"}","received_at":"2026-07-28T03:09:18.612092Z","schema_version":"clob-market-ws.price_change.v1","sequence":null,"server_hash":null,"server_timestamp":"1785208158681","session_id":"3e519d9098404c15b234d96025eb1a2b","source":"clob_market_ws"},"received_at":"2026-07-28T03:09:18.612092Z","record_id":"152fb3c438d4e6e951e20d096712870cb9f5e7e6aa47ae2cd3c2a25103407eaa","schema_fingerprint":"4aa3821a28b0b7c2400bc59aba4bcc0a76e971dadd19610d3ad38c768e124dc7","schema_version":"edge-lab-recorder.raw.v1","sequence":null,"source":"clob_market_ws"}
{"event_at":"2026-07-28T03:09:18.681000Z","event_fingerprint":"a14881e158e4cc4da5c7ebf61ef651d4bb5049bad9ebf82ab190b2abe95da845","payload":{"connection_id":"a6b55582af5f430fb37ad02bf0922475","event_at":"2026-07-28T03:09:18.681000Z","event_type":"price_change","frame_hash":"7f4ddf347059b2f5103405c45016eb47fcddc7dd3f1e64856844dde7602caf6e","frame_index":0,"kind":"data","monotonic_ns":310141646621166,"payload":{"event_type":"price_change","market":"0x779291bef19b6709f61e9764a954aafe9ffae488d50ae674aabdcb4f248006d5","price_changes":[{"asset_id":"14965588658799411272385430903075831224615961675357217884735713260981483529984","best_ask":"0.33","best_bid":"0.32","hash":"43f28c9fe8d1c953df7e4011f8530c9f2ccc361a","price":"0.25","side":"BUY","size":"188"},{"asset_id":"8761897749749422724209054078244794145777693856614463256546737399611489089783","best_ask":"0.68","best_bid":"0.67","hash":"f6838e76a11145bf6e52625432271ec00d28a824","price":"0.75","side":"SELL","size":"188"}],"timestamp":"1785208158681"},"payload_hash":"6a74f08b6d4238ea1176db7f77c344b6a6fecc9364156e4c958aa252eac21703","raw_frame":"{\"market\":\"0x779291bef19b6709f61e9764a954aafe9ffae488d50ae674aabdcb4f248006d5\", \"price_changes\":[{\"asset_id\":\"14965588658799411272385430903075831224615961675357217884735713260981483529984\", \"price\":\"0.25\", \"size\":\"188\", \"side\":\"BUY\", \"hash\":\"43f28c9fe8d1c953df7e4011f8530c9f2ccc361a\", \"best_bid\":\"0.32\", \"best_ask\":\"0.33\"}, {\"asset_id\":\"8761897749749422724209054078244794145777693856614463256546737399611489089783\", \"price\":\"0.75\", \"size\":\"188\", \"side\":\"SELL\", \"hash\":\"f6838e76a11145bf6e52625432271ec00d28a824\", \"best_bid\":\"0.67\", \"best_ask\":\"0.68\"}], \"timestamp\":\"1785208158681\", \"event_type\":\"price_change\"}","received_at":"2026-07-28T03:09:18.613669Z","schema_version":"clob-market-ws.price_change.v1","sequence":null,"server_hash":null,"server_timestamp":"1785208158681","session_id":"3e519d9098404c15b234d96025eb1a2b","source":"clob_market_ws"},"received_at":"2026-07-28T03:09:18.613669Z","record_id":"fd36794b4359f6702000c9d4f457d0d6357a1c2886e9d913cf76c23d3c73b2dd","schema_fingerprint":"4aa3821a28b0b7c2400bc59aba4bcc0a76e971dadd19610d3ad38c768e124dc7","schema_version":"edge-lab-recorder.raw.v1","sequence":null,"source":"clob_market_ws"}
{"event_at":"2026-07-28T03:09:18.682000Z","event_fingerprint":"b97804a52b994949466364d769a7656edee2b730dadb0ed1c8ccfc6334e00c41","payload":{"connection_id":"a6b55582af5f430fb37ad02bf0922475","event_at":"2026-07-28T03:09:18.682000Z","event_type":"price_change","frame_hash":"a6e4585a261c059471568ecaf11dac0a5cd841298934c237132bd89e837f2f63","frame_index":0,"kind":"data","monotonic_ns":310141648086583,"payload":{"event_type":"price_change","market":"0x779291bef19b6709f61e9764a954aafe9ffae488d50ae674aabdcb4f248006d5","price_changes":[{"asset_id":"14965588658799411272385430903075831224615961675357217884735713260981483529984","best_ask":"0.33","best_bid":"0.32","hash":"b6a541d7ec4e06f1b7ab518cbada1be38cfbcf36","price":"0.23","side":"BUY","size":"165"},{"asset_id":"8761897749749422724209054078244794145777693856614463256546737399611489089783","best_ask":"0.68","best_bid":"0.67","hash":"2383d77128736aab4bb049523bc421d08abdf7a5","price":"0.77","side":"SELL","size":"165"}],"timestamp":"1785208158682"},"payload_hash":"4e83003e2952b5dcfe3773aeafa4983fa53c79808f1b707199dc624944c769c1","raw_frame":"{\"market\":\"0x779291bef19b6709f61e9764a954aafe9ffae488d50ae674aabdcb4f248006d5\", \"price_changes\":[{\"asset_id\":\"14965588658799411272385430903075831224615961675357217884735713260981483529984\", \"price\":\"0.23\", \"size\":\"165\", \"side\":\"BUY\", \"hash\":\"b6a541d7ec4e06f1b7ab518cbada1be38cfbcf36\", \"best_bid\":\"0.32\", \"best_ask\":\"0.33\"}, {\"asset_id\":\"8761897749749422724209054078244794145777693856614463256546737399611489089783\", \"price\":\"0.77\", \"size\":\"165\", \"side\":\"SELL\", \"hash\":\"2383d77128736aab4bb049523bc421d08abdf7a5\", \"best_bid\":\"0.67\", \"best_ask\":\"0.68\"}], \"timestamp\":\"1785208158682\", \"event_type\":\"price_change\"}","received_at":"2026-07-28T03:09:18.615134Z","schema_version":"clob-market-ws.price_change.v1","sequence":null,"server_hash":null,"server_timestamp":"1785208158682","session_id":"3e519d9098404c15b234d96025eb1a2b","source":"clob_market_ws"},"received_at":"2026-07-28T03:09:18.615134Z","record_id":"1c7f5423d9fd97257c332c26476725ff1a969d74af81b9f96386d241dde1db66","schema_fingerprint":"4aa3821a28b0b7c2400bc59aba4bcc0a76e971dadd19610d3ad38c768e124dc7","schema_version":"edge-lab-recorder.raw.v1","sequence":null,"source":"clob_market_ws"}
{"event_at":"2026-07-28T03:09:18.683000Z","event_fingerprint":"fce1b41c266f4253323a723b1612fb1e7a922fee58b19f0ec29634a1f1750c2f","payload":{"connection_id":"a6b55582af5f430fb37ad02bf0922475","event_at":"2026-07-28T03:09:18.683000Z","event_type":"price_change","frame_hash":"3f9615845a4ca355d095b93c8f3492c8c9fea0c0a3ebacaca56130c04c7705e2","frame_index":0,"kind":"data","monotonic_ns":310141649899125,"payload":{"event_type":"price_change","market":"0x779291bef19b6709f61e9764a954aafe9ffae488d50ae674aabdcb4f248006d5","price_changes":[{"asset_id":"8761897749749422724209054078244794145777693856614463256546737399611489089783","best_ask":"0.68","best_bid":"0.67","hash":"38f9b2c08ab89d48c9a0a827cecef79207c38326","price":"0.66","side":"BUY","size":"122.05"},{"asset_id":"14965588658799411272385430903075831224615961675357217884735713260981483529984","best_ask":"0.33","best_bid":"0.32","hash":"e70424b8ea213321808b906c12a38872f60be049","price":"0.34","side":"SELL","size":"122.05"}],"timestamp":"1785208158683"},"payload_hash":"00729dbe85d062f3810140d571736b580aeb4df48ce7f5afd4828a59f233631a","raw_frame":"{\"market\":\"0x779291bef19b6709f61e9764a954aafe9ffae488d50ae674aabdcb4f248006d5\", \"price_changes\":[{\"asset_id\":\"8761897749749422724209054078244794145777693856614463256546737399611489089783\", \"price\":\"0.66\", \"size\":\"122.05\", \"side\":\"BUY\", \"hash\":\"38f9b2c08ab89d48c9a0a827cecef79207c38326\", \"best_bid\":\"0.67\", \"best_ask\":\"0.68\"}, {\"asset_id\":\"14965588658799411272385430903075831224615961675357217884735713260981483529984\", \"price\":\"0.34\", \"size\":\"122.05\", \"side\":\"SELL\", \"hash\":\"e70424b8ea213321808b906c12a38872f60be049\", \"best_bid\":\"0.32\", \"best_ask\":\"0.33\"}], \"timestamp\":\"1785208158683\", \"event_type\":\"price_change\"}","received_at":"2026-07-28T03:09:18.616945Z","schema_version":"clob-market-ws.price_change.v1","sequence":null,"server_hash":null,"server_timestamp":"1785208158683","session_id":"3e519d9098404c15b234d96025eb1a2b","source":"clob_market_ws"},"received_at":"2026-07-28T03:09:18.616945Z","record_id":"a0780f9253be6ca864808d2b1f113d1fae385bafbfe8caaff93540f0dd6b38c5","schema_fingerprint":"4aa3821a28b0b7c2400bc59aba4bcc0a76e971dadd19610d3ad38c768e124dc7","schema_version":"edge-lab-recorder.raw.v1","sequence":null,"source":"clob_market_ws"}
{"event_at":"2026-07-28T03:09:18.683000Z","event_fingerprint":"6050e57932cb76bc1184816d9b20e4b1b368249d950d524cafb05540973a205f","payload":{"connection_id":"a6b55582af5f430fb37ad02bf0922475","event_at":"2026-07-28T03:09:18.683000Z","event_type":"price_change","frame_hash":"777849e4fa52f09a6d4ed620892aa3f2e501cacda2076c28826b499738fc9a83","frame_index":0,"kind":"data","monotonic_ns":310141651420958,"payload":{"event_type":"price_change","market":"0x779291bef19b6709f61e9764a954aafe9ffae488d50ae674aabdcb4f248006d5","price_changes":[{"asset_id":"14965588658799411272385430903075831224615961675357217884735713260981483529984","best_ask":"0.33","best_bid":"0.32","hash":"4561b365ae33fcac5697857ce096e62f34f02be9","price":"0.25","side":"BUY","size":"198"},{"asset_id":"8761897749749422724209054078244794145777693856614463256546737399611489089783","best_ask":"0.68","best_bid":"0.67","hash":"6e1640f33dbce0fa9b3fbf6ed31973ceeb987617","price":"0.75","side":"SELL","size":"198"}],"timestamp":"1785208158683"},"payload_hash":"69d8249aeb8c0d3a9aaa38e3f7fa7cd72ef6733df16d6318b4a725d829ba8db3","raw_frame":"{\"market\":\"0x779291bef19b6709f61e9764a954aafe9ffae488d50ae674aabdcb4f248006d5\", \"price_changes\":[{\"asset_id\":\"14965588658799411272385430903075831224615961675357217884735713260981483529984\", \"price\":\"0.25\", \"size\":\"198\", \"side\":\"BUY\", \"hash\":\"4561b365ae33fcac5697857ce096e62f34f02be9\", \"best_bid\":\"0.32\", \"best_ask\":\"0.33\"}, {\"asset_id\":\"8761897749749422724209054078244794145777693856614463256546737399611489089783\", \"price\":\"0.75\", \"size\":\"198\", \"side\":\"SELL\", \"hash\":\"6e1640f33dbce0fa9b3fbf6ed31973ceeb987617\", \"best_bid\":\"0.67\", \"best_ask\":\"0.68\"}], \"timestamp\":\"1785208158683\", \"event_type\":\"price_change\"}","received_at":"2026-07-28T03:09:18.618469Z","schema_version":"clob-market-ws.price_change.v1","sequence":null,"server_hash":null,"server_timestamp":"1785208158683","session_id":"3e519d9098404c15b234d96025eb1a2b","source":"clob_market_ws"},"received_at":"2026-07-28T03:09:18.618469Z","record_id":"c54e04bd01bd35c5008c5bdd74d2f2676103cd4dc7abad21c50e5436cb698bc1","schema_fingerprint":"4aa3821a28b0b7c2400bc59aba4bcc0a76e971dadd19610d3ad38c768e124dc7","schema_version":"edge-lab-recorder.raw.v1","sequence":null,"source":"clob_market_ws"}
{"event_at":"2026-07-28T03:09:18.685000Z","event_fingerprint":"8ccc0ff6181ddb43e0efa64a1a61361975243184dca2ce8847dc55c00cdf5e1b","payload":{"connection_id":"a6b55582af5f430fb37ad02bf0922475","event_at":"2026-07-28T03:09:18.685000Z","event_type":"price_change","frame_hash":"679ffaaa05ca919a620cf574e16abfe209fb5792c6843aa59e19cb6cbeb2c7ac","frame_index":0,"kind":"data","monotonic_ns":310141652888083,"payload":{"event_type":"price_change","market":"0x779291bef19b6709f61e9764a954aafe9ffae488d50ae674aabdcb4f248006d5","price_changes":[{"asset_id":"14965588658799411272385430903075831224615961675357217884735713260981483529984","best_ask":"0.33","best_bid":"0.32","hash":"b2de28cdc399e457c6acd228dd85c7f8d96cce2d","price":"0.2","side":"BUY","size":"276.11"},{"asset_id":"8761897749749422724209054078244794145777693856614463256546737399611489089783","best_ask":"0.68","best_bid":"0.67","hash":"98e7c5d5866021d6c4cc165a3f5f7cb72d379d97","price":"0.8","side":"SELL","size":"276.11"}],"timestamp":"1785208158685"},"payload_hash":"e3af2eae966280e5cdf4f4a4b82b008690355695070ffc715adcc16d901d7841","raw_frame":"{\"market\":\"0x779291bef19b6709f61e9764a954aafe9ffae488d50ae674aabdcb4f248006d5\", \"price_changes\":[{\"asset_id\":\"14965588658799411272385430903075831224615961675357217884735713260981483529984\", \"price\":\"0.2\", \"size\":\"276.11\", \"side\":\"BUY\", \"hash\":\"b2de28cdc399e457c6acd228dd85c7f8d96cce2d\", \"best_bid\":\"0.32\", \"best_ask\":\"0.33\"}, {\"asset_id\":\"8761897749749422724209054078244794145777693856614463256546737399611489089783\", \"price\":\"0.8\", \"size\":\"276.11\", \"side\":\"SELL\", \"hash\":\"98e7c5d5866021d6c4cc165a3f5f7cb72d379d97\", \"best_bid\":\"0.67\", \"best_ask\":\"0.68\"}], \"timestamp\":\"1785208158685\", \"event_type\":\"price_change\"}","received_at":"2026-07-28T03:09:18.619935Z","schema_version":"clob-market-ws.price_change.v1","sequence":null,"server_hash":null,"server_timestamp":"1785208158685","session_id":"3e519d9098404c15b234d96025eb1a2b","source":"clob_market_ws"},"received_at":"2026-07-28T03:09:18.619935Z","record_id":"70661ed3da5b429024f0a3172ae5f130c2974c42416f44119df77e364a513694","schema_fingerprint":"4aa3821a28b0b7c2400bc59aba4bcc0a76e971dadd19610d3ad38c768e124dc7","schema_version":"edge-lab-recorder.raw.v1","sequence":null,"source":"clob_market_ws"}
{"event_at":"2026-07-28T03:09:18.685000Z","event_fingerprint":"a8591ddfb88d286588e48755773b20d527aa83dde92994bd3d91ad247bdd23f6","payload":{"connection_id":"a6b55582af5f430fb37ad02bf0922475","event_at":"2026-07-28T03:09:18.685000Z","event_type":"price_change","frame_hash":"79293462ed7a293bed0adde2dff32d9de80e266bf2b81b6cec845c1048ba01d7","frame_index":0,"kind":"data","monotonic_ns":310141654358291,"payload":{"event_type":"price_change","market":"0x779291bef19b6709f61e9764a954aafe9ffae488d50ae674aabdcb4f248006d5","price_changes":[{"asset_id":"14965588658799411272385430903075831224615961675357217884735713260981483529984","best_ask":"0.33","best_bid":"0.32","hash":"b2de28cdc399e457c6acd228dd85c7f8d96cce2d","price":"0.21","side":"BUY","size":"138"},{"asset_id":"8761897749749422724209054078244794145777693856614463256546737399611489089783","best_ask":"0.68","best_bid":"0.67","hash":"98e7c5d5866021d6c4cc165a3f5f7cb72d379d97","price":"0.79","side":"SELL","size":"138"}],"timestamp":"1785208158685"},"payload_hash":"8cd1281cf6df46af8c82e2ba5bea4c9bcfc823842091d4d7b417c36eed5fed6e","raw_frame":"{\"market\":\"0x779291bef19b6709f61e9764a954aafe9ffae488d50ae674aabdcb4f248006d5\", \"price_changes\":[{\"asset_id\":\"14965588658799411272385430903075831224615961675357217884735713260981483529984\", \"price\":\"0.21\", \"size\":\"138\", \"side\":\"BUY\", \"hash\":\"b2de28cdc399e457c6acd228dd85c7f8d96cce2d\", \"best_bid\":\"0.32\", \"best_ask\":\"0.33\"}, {\"asset_id\":\"8761897749749422724209054078244794145777693856614463256546737399611489089783\", \"price\":\"0.79\", \"size\":\"138\", \"side\":\"SELL\", \"hash\":\"98e7c5d5866021d6c4cc165a3f5f7cb72d379d97\", \"best_bid\":\"0.67\", \"best_ask\":\"0.68\"}], \"timestamp\":\"1785208158685\", \"event_type\":\"price_change\"}","received_at":"2026-07-28T03:09:18.621406Z","schema_version":"clob-market-ws.price_change.v1","sequence":null,"server_hash":null,"server_timestamp":"1785208158685","session_id":"3e519d9098404c15b234d96025eb1a2b","source":"clob_market_ws"},"received_at":"2026-07-28T03:09:18.621406Z","record_id":"6181169d8d1d0e7779cbc95ad7ec5fb2440ccd562bbb0504976c4d1f73d236fb","schema_fingerprint":"4aa3821a28b0b7c2400bc59aba4bcc0a76e971dadd19610d3ad38c768e124dc7","schema_version":"edge-lab-recorder.raw.v1","sequence":null,"source":"clob_market_ws"}
{"event_at":"2026-07-28T03:09:18.685000Z","event_fingerprint":"7cb8b29deea6014ceaf85ca4015a8bfae5821a45180650ad91e94426707cd113","payload":{"connection_id":"a6b55582af5f430fb37ad02bf0922475","event_at":"2026-07-28T03:09:18.685000Z","event_type":"price_change","frame_hash":"43e51ec53b104720cb512b523013e057631cc428b901de96ea262c4fd39b486a","frame_index":0,"kind":"data","monotonic_ns":310141655826500,"payload":{"event_type":"price_change","market":"0x779291bef19b6709f61e9764a954aafe9ffae488d50ae674aabdcb4f248006d5","price_changes":[{"asset_id":"14965588658799411272385430903075831224615961675357217884735713260981483529984","best_ask":"0.33","best_bid":"0.32","hash":"b2de28cdc399e457c6acd228dd85c7f8d96cce2d","price":"0.22","side":"BUY","size":"173"},{"asset_id":"8761897749749422724209054078244794145777693856614463256546737399611489089783","best_ask":"0.68","best_bid":"0.67","hash":"98e7c5d5866021d6c4cc165a3f5f7cb72d379d97","price":"0.78","side":"SELL","size":"173"}],"timestamp":"1785208158685"},"payload_hash":"1a0e437ad6c0b1773ea84c8ece053c0ac532d959b8fd2d20a199372b0cb9d818","raw_frame":"{\"market\":\"0x779291bef19b6709f61e9764a954aafe9ffae488d50ae674aabdcb4f248006d5\", \"price_changes\":[{\"asset_id\":\"14965588658799411272385430903075831224615961675357217884735713260981483529984\", \"price\":\"0.22\", \"size\":\"173\", \"side\":\"BUY\", \"hash\":\"b2de28cdc399e457c6acd228dd85c7f8d96cce2d\", \"best_bid\":\"0.32\", \"best_ask\":\"0.33\"}, {\"asset_id\":\"8761897749749422724209054078244794145777693856614463256546737399611489089783\", \"price\":\"0.78\", \"size\":\"173\", \"side\":\"SELL\", \"hash\":\"98e7c5d5866021d6c4cc165a3f5f7cb72d379d97\", \"best_bid\":\"0.67\", \"best_ask\":\"0.68\"}], \"timestamp\":\"1785208158685\", \"event_type\":\"price_change\"}","received_at":"2026-07-28T03:09:18.622874Z","schema_version":"clob-market-ws.price_change.v1","sequence":null,"server_hash":null,"server_timestamp":"1785208158685","session_id":"3e519d9098404c15b234d96025eb1a2b","source":"clob_market_ws"},"received_at":"2026-07-28T03:09:18.622874Z","record_id":"b77d0d0c73d344b1f15f4bbe9d3d08ed2e8aaaa0c59e28eccaedba32771d8026","schema_fingerprint":"4aa3821a28b0b7c2400bc59aba4bcc0a76e971dadd19610d3ad38c768e124dc7","schema_version":"edge-lab-recorder.raw.v1","sequence":null,"source":"clob_market_ws"}
{"event_at":"2026-07-28T03:09:18.685000Z","event_fingerprint":"2662405664c822c14d31b12d3ce0a3d8aff3da6219adc0dbf3af706cb241c0a3","payload":{"connection_id":"a6b55582af5f430fb37ad02bf0922475","event_at":"2026-07-28T03:09:18.685000Z","event_type":"price_change","frame_hash":"2afed49a52a74271843b98be7bdce71c8857d51b9b3ce482a6f8751467648209","frame_index":0,"kind":"data","monotonic_ns":310141657304083,"payload":{"event_type":"price_change","market":"0x779291bef19b6709f61e9764a954aafe9ffae488d50ae674aabdcb4f248006d5","price_changes":[{"asset_id":"14965588658799411272385430903075831224615961675357217884735713260981483529984","best_ask":"0.33","best_bid":"0.32","hash":"afd8e64a90e48857e23b813bbaa03ba3eb5c1c3a","price":"0.12","side":"BUY","size":"832.4"},{"asset_id":"8761897749749422724209054078244794145777693856614463256546737399611489089783","best_ask":"0.68","best_bid":"0.67","hash":"29504ecaaa685bde41e7c77c2b1c429780f3d274","price":"0.88","side":"SELL","size":"832.4"}],"timestamp":"1785208158685"},"payload_hash":"120c2adcfe5f9f1339c538abb3f3bf599d09d71f1be13f0831b3bb2150b20f95","raw_frame":"{\"market\":\"0x779291bef19b6709f61e9764a954aafe9ffae488d50ae674aabdcb4f248006d5\", \"price_changes\":[{\"asset_id\":\"14965588658799411272385430903075831224615961675357217884735713260981483529984\", \"price\":\"0.12\", \"size\":\"832.4\", \"side\":\"BUY\", \"hash\":\"afd8e64a90e48857e23b813bbaa03ba3eb5c1c3a\", \"best_bid\":\"0.32\", \"best_ask\":\"0.33\"}, {\"asset_id\":\"8761897749749422724209054078244794145777693856614463256546737399611489089783\", \"price\":\"0.88\", \"size\":\"832.4\", \"side\":\"SELL\", \"hash\":\"29504ecaaa685bde41e7c77c2b1c429780f3d274\", \"best_bid\":\"0.67\", \"best_ask\":\"0.68\"}], \"timestamp\":\"1785208158685\", \"event_type\":\"price_change\"}","received_at":"2026-07-28T03:09:18.624352Z","schema_version":"clob-market-ws.price_change.v1","sequence":null,"server_hash":null,"server_timestamp":"1785208158685","session_id":"3e519d9098404c15b234d96025eb1a2b","source":"clob_market_ws"},"received_at":"2026-07-28T03:09:18.624352Z","record_id":"3a3f379e2d4056561f5b33a4a5cfd4fb4d597523aa7a0d240b90131b226e4079","schema_fingerprint":"4aa3821a28b0b7c2400bc59aba4bcc0a76e971dadd19610d3ad38c768e124dc7","schema_version":"edge-lab-recorder.raw.v1","sequence":null,"source":"clob_market_ws"}
{"event_at":"2026-07-28T03:09:18.686000Z","event_fingerprint":"19b903895c9921736dbbf640a53599225d6a384d6631e8e3e4335d534bc0ff0b","payload":{"connection_id":"a6b55582af5f430fb37ad02bf0922475","event_at":"2026-07-28T03:09:18.686000Z","event_type":"price_change","frame_hash":"7a9d6f4e854ba3db2826a3083cafaf58e414e22b349e6ee08e293e195512e3e6","frame_index":0,"kind":"data","monotonic_ns":310141658783833,"payload":{"event_type":"price_change","market":"0x779291bef19b6709f61e9764a954aafe9ffae488d50ae674aabdcb4f248006d5","price_changes":[{"asset_id":"8761897749749422724209054078244794145777693856614463256546737399611489089783","best_ask":"0.68","best_bid":"0.67","hash":"f4ddceef0710bd1015243f069294627f4297490e","price":"0.67","side":"BUY","size":"151.6"},{"asset_id":"14965588658799411272385430903075831224615961675357217884735713260981483529984","best_ask":"0.33","best_bid":"0.32","hash":"40bff187c8a457a4d40f578dbaa854583e67a522","price":"0.33","side":"SELL","size":"151.6"}],"timestamp":"1785208158686"},"payload_hash":"783acbc4673b1dd8ef113f4a81acee4b2f8e0e2247dfe4b137e9a02ae64a41f0","raw_frame":"{\"market\":\"0x779291bef19b6709f61e9764a954aafe9ffae488d50ae674aabdcb4f248006d5\", \"price_changes\":[{\"asset_id\":\"8761897749749422724209054078244794145777693856614463256546737399611489089783\", \"price\":\"0.67\", \"size\":\"151.6\", \"side\":\"BUY\", \"hash\":\"f4ddceef0710bd1015243f069294627f4297490e\", \"best_bid\":\"0.67\", \"best_ask\":\"0.68\"}, {\"asset_id\":\"14965588658799411272385430903075831224615961675357217884735713260981483529984\", \"price\":\"0.33\", \"size\":\"151.6\", \"side\":\"SELL\", \"hash\":\"40bff187c8a457a4d40f578dbaa854583e67a522\", \"best_bid\":\"0.32\", \"best_ask\":\"0.33\"}], \"timestamp\":\"1785208158686\", \"event_type\":\"price_change\"}","received_at":"2026-07-28T03:09:18.625832Z","schema_version":"clob-market-ws.price_change.v1","sequence":null,"server_hash":null,"server_timestamp":"1785208158686","session_id":"3e519d9098404c15b234d96025eb1a2b","source":"clob_market_ws"},"received_at":"2026-07-28T03:09:18.625832Z","record_id":"f51dec28be3dbc56948101540aeca1dfad1383592746e6afe5885f7897a10260","schema_fingerprint":"4aa3821a28b0b7c2400bc59aba4bcc0a76e971dadd19610d3ad38c768e124dc7","schema_version":"edge-lab-recorder.raw.v1","sequence":null,"source":"clob_market_ws"}
{"event_at":"2026-07-28T03:09:18.687000Z","event_fingerprint":"f26b772ac2906df108257f78da0ae94f79291480e1847251fc25362694369343","payload":{"connection_id":"a6b55582af5f430fb37ad02bf0922475","event_at":"2026-07-28T03:09:18.687000Z","event_type":"price_change","frame_hash":"20c740da39f53512db0afd9feeddfa93897e4ad7a60d4b0f7b05578d0ec43dcd","frame_index":0,"kind":"data","monotonic_ns":310141660256125,"payload":{"event_type":"price_change","market":"0x779291bef19b6709f61e9764a954aafe9ffae488d50ae674aabdcb4f248006d5","price_changes":[{"asset_id":"14965588658799411272385430903075831224615961675357217884735713260981483529984","best_ask":"0.33","best_bid":"0.32","hash":"dfe7faac876e1c055f7e09485de7a61196eba95f","price":"0.2","side":"BUY","size":"268"},{"asset_id":"8761897749749422724209054078244794145777693856614463256546737399611489089783","best_ask":"0.68","best_bid":"0.67","hash":"d170abe1c1bfba21030533bdd3a82b8b802940f8","price":"0.8","side":"SELL","size":"268"}],"timestamp":"1785208158687"},"payload_hash":"db23f78ea1ed80a2d68e18370cc1651e363007b2e364e17af765dc7a91dcf0d0","raw_frame":"{\"market\":\"0x779291bef19b6709f61e9764a954aafe9ffae488d50ae674aabdcb4f248006d5\", \"price_changes\":[{\"asset_id\":\"14965588658799411272385430903075831224615961675357217884735713260981483529984\", \"price\":\"0.2\", \"size\":\"268\", \"side\":\"BUY\", \"hash\":\"dfe7faac876e1c055f7e09485de7a61196eba95f\", \"best_bid\":\"0.32\", \"best_ask\":\"0.33\"}, {\"asset_id\":\"8761897749749422724209054078244794145777693856614463256546737399611489089783\", \"price\":\"0.8\", \"size\":\"268\", \"side\":\"SELL\", \"hash\":\"d170abe1c1bfba21030533bdd3a82b8b802940f8\", \"best_bid\":\"0.67\", \"best_ask\":\"0.68\"}], \"timestamp\":\"1785208158687\", \"event_type\":\"price_change\"}","received_at":"2026-07-28T03:09:18.627304Z","schema_version":"clob-market-ws.price_change.v1","sequence":null,"server_hash":null,"server_timestamp":"1785208158687","session_id":"3e519d9098404c15b234d96025eb1a2b","source":"clob_market_ws"},"received_at":"2026-07-28T03:09:18.627304Z","record_id":"271f6dd06fc9d3c5905acf122cd943e4a13e690a534259aa7c06112ad2804b88","schema_fingerprint":"4aa3821a28b0b7c2400bc59aba4bcc0a76e971dadd19610d3ad38c768e124dc7","schema_version":"edge-lab-recorder.raw.v1","sequence":null,"source":"clob_market_ws"}
{"event_at":"2026-07-28T03:09:18.687000Z","event_fingerprint":"8c48db943a4c2867ee47aa56d4812b158e5d5cc2df33f4b2671b9b8dbf3bf1de","payload":{"connection_id":"a6b55582af5f430fb37ad02bf0922475","event_at":"2026-07-28T03:09:18.687000Z","event_type":"price_change","frame_hash":"111b28973f8b71150fea59ffbcb0d67a161f4872d0c75068652bd98afc2f3555","frame_index":0,"kind":"data","monotonic_ns":310141661731541,"payload":{"event_type":"price_change","market":"0x779291bef19b6709f61e9764a954aafe9ffae488d50ae674aabdcb4f248006d5","price_changes":[{"asset_id":"14965588658799411272385430903075831224615961675357217884735713260981483529984","best_ask":"0.33","best_bid":"0.32","hash":"92e2d9f40b11b573cd5fad1eee38e0dc1439313d","price":"0.19","side":"BUY","size":"308.76"},{"asset_id":"8761897749749422724209054078244794145777693856614463256546737399611489089783","best_ask":"0.68","best_bid":"0.67","hash":"8dba05d15df3d7998e1e6826933e3023c5f133d0","price":"0.81","side":"SELL","size":"308.76"}],"timestamp":"1785208158687"},"payload_hash":"7e071ad1e69c95d4b7b21eebcebe771f228fffa3294523587a548abe330790ec","raw_frame":"{\"market\":\"0x779291bef19b6709f61e9764a954aafe9ffae488d50ae674aabdcb4f248006d5\", \"price_changes\":[{\"asset_id\":\"14965588658799411272385430903075831224615961675357217884735713260981483529984\", \"price\":\"0.19\", \"size\":\"308.76\", \"side\":\"BUY\", \"hash\":\"92e2d9f40b11b573cd5fad1eee38e0dc1439313d\", \"best_bid\":\"0.32\", \"best_ask\":\"0.33\"}, {\"asset_id\":\"8761897749749422724209054078244794145777693856614463256546737399611489089783\", \"price\":\"0.81\", \"size\":\"308.76\", \"side\":\"SELL\", \"hash\":\"8dba05d15df3d7998e1e6826933e3023c5f133d0\", \"best_bid\":\"0.67\", \"best_ask\":\"0.68\"}], \"timestamp\":\"1785208158687\", \"event_type\":\"price_change\"}","received_at":"2026-07-28T03:09:18.628779Z","schema_version":"clob-market-ws.price_change.v1","sequence":null,"server_hash":null,"server_timestamp":"1785208158687","session_id":"3e519d9098404c15b234d96025eb1a2b","source":"clob_market_ws"},"received_at":"2026-07-28T03:09:18.628779Z","record_id":"c1dcda144cf94f912f1b1c38369958ce9baf5b4c82dbf20e9a0d84842be41393","schema_fingerprint":"4aa3821a28b0b7c2400bc59aba4bcc0a76e971dadd19610d3ad38c768e124dc7","schema_version":"edge-lab-recorder.raw.v1","sequence":null,"source":"clob_market_ws"}
{"event_at":"2026-07-28T03:09:18.691000Z","event_fingerprint":"75c42cb97be9262a637fa263d14a8ca6f66725edced017b5c50e10215575f35f","payload":{"connection_id":"a6b55582af5f430fb37ad02bf0922475","event_at":"2026-07-28T03:09:18.691000Z","event_type":"price_change","frame_hash":"f3a7143dcac55ac27d27ef9ff6a6a3d67af0ccdc12e338a368e9fada430e62cc","frame_index":0,"kind":"data","monotonic_ns":310141663196125,"payload":{"event_type":"price_change","market":"0x779291bef19b6709f61e9764a954aafe9ffae488d50ae674aabdcb4f248006d5","price_changes":[{"asset_id":"8761897749749422724209054078244794145777693856614463256546737399611489089783","best_ask":"0.68","best_bid":"0.67","hash":"69b207991a1092e34c08b10ab6c0f294b4023933","price":"0.46","side":"BUY","size":"119.53"},{"asset_id":"14965588658799411272385430903075831224615961675357217884735713260981483529984","best_ask":"0.33","best_bid":"0.32","hash":"4bccfa16a34012e988e0df0e408d9c12d438acab","price":"0.54","side":"SELL","size":"119.53"}],"timestamp":"1785208158691"},"payload_hash":"cd781339f516e6084afc0d0fdcd0bba212d4c567aeec5d5dd709607c1c83aa1b","raw_frame":"{\"market\":\"0x779291bef19b6709f61e9764a954aafe9ffae488d50ae674aabdcb4f248006d5\", \"price_changes\":[{\"asset_id\":\"8761897749749422724209054078244794145777693856614463256546737399611489089783\", \"price\":\"0.46\", \"size\":\"119.53\", \"side\":\"BUY\", \"hash\":\"69b207991a1092e34c08b10ab6c0f294b4023933\", \"best_bid\":\"0.67\", \"best_ask\":\"0.68\"}, {\"asset_id\":\"14965588658799411272385430903075831224615961675357217884735713260981483529984\", \"price\":\"0.54\", \"size\":\"119.53\", \"side\":\"SELL\", \"hash\":\"4bccfa16a34012e988e0df0e408d9c12d438acab\", \"best_bid\":\"0.32\", \"best_ask\":\"0.33\"}], \"timestamp\":\"1785208158691\", \"event_type\":\"price_change\"}","received_at":"2026-07-28T03:09:18.630244Z","schema_version":"clob-market-ws.price_change.v1","sequence":null,"server_hash":null,"server_timestamp":"1785208158691","session_id":"3e519d9098404c15b234d96025eb1a2b","source":"clob_market_ws"},"received_at":"2026-07-28T03:09:18.630244Z","record_id":"3d0821ba5b9d574b3c8c853f41f8b353a6f31ca0fa78f80ae566624bea452128","schema_fingerprint":"4aa3821a28b0b7c2400bc59aba4bcc0a76e971dadd19610d3ad38c768e124dc7","schema_version":"edge-lab-recorder.raw.v1","sequence":null,"source":"clob_market_ws"}
{"event_at":"2026-07-28T03:09:18.692000Z","event_fingerprint":"06ceef0634970366c370303f14c95cf82768579adb26fe1636651d821501f438","payload":{"connection_id":"a6b55582af5f430fb37ad02bf0922475","event_at":"2026-07-28T03:09:18.692000Z","event_type":"price_change","frame_hash":"169f951c364a28fd99ef2edb0932bdf541ed0cc9e55326510aa07f3ca4fe2660","frame_index":0,"kind":"data","monotonic_ns":310141664683000,"payload":{"event_type":"price_change","market":"0x779291bef19b6709f61e9764a954aafe9ffae488d50ae674aabdcb4f248006d5","price_changes":[{"asset_id":"14965588658799411272385430903075831224615961675357217884735713260981483529984","best_ask":"0.33","best_bid":"0.32","hash":"7039db017cb58e08da1dc62ea1e191df7b5789a9","price":"0.19","side":"BUY","size":"289.26"},{"asset_id":"8761897749749422724209054078244794145777693856614463256546737399611489089783","best_ask":"0.68","best_bid":"0.67","hash":"2434bd64b906757328ec5b7d74fc81384a535ffd","price":"0.81","side":"SELL","size":"289.26"}],"timestamp":"1785208158692"},"payload_hash":"9c63409805ca7be0e5d04c8943648692912e481e706c42aab8b4f8412ba4bba8","raw_frame":"{\"market\":\"0x779291bef19b6709f61e9764a954aafe9ffae488d50ae674aabdcb4f248006d5\", \"price_changes\":[{\"asset_id\":\"14965588658799411272385430903075831224615961675357217884735713260981483529984\", \"price\":\"0.19\", \"size\":\"289.26\", \"side\":\"BUY\", \"hash\":\"7039db017cb58e08da1dc62ea1e191df7b5789a9\", \"best_bid\":\"0.32\", \"best_ask\":\"0.33\"}, {\"asset_id\":\"8761897749749422724209054078244794145777693856614463256546737399611489089783\", \"price\":\"0.81\", \"size\":\"289.26\", \"side\":\"SELL\", \"hash\":\"2434bd64b906757328ec5b7d74fc81384a535ffd\", \"best_bid\":\"0.67\", \"best_ask\":\"0.68\"}], \"timestamp\":\"1785208158692\", \"event_type\":\"price_change\"}","received_at":"2026-07-28T03:09:18.631730Z","schema_version":"clob-market-ws.price_change.v1","sequence":null,"server_hash":null,"server_timestamp":"1785208158692","session_id":"3e519d9098404c15b234d96025eb1a2b","source":"clob_market_ws"},"received_at":"2026-07-28T03:09:18.631730Z","record_id":"14f6b9da08f36e5b384f66251cd8e2f65ac1b2ec9585af9f3f660c5a5fdc83ba","schema_fingerprint":"4aa3821a28b0b7c2400bc59aba4bcc0a76e971dadd19610d3ad38c768e124dc7","schema_version":"edge-lab-recorder.raw.v1","sequence":null,"source":"clob_market_ws"}
{"event_at":"2026-07-28T03:09:18.693000Z","event_fingerprint":"9ef921824a399578b18be43bbbfebf3c74637f3af94001f49e95ba808831c044","payload":{"connection_id":"a6b55582af5f430fb37ad02bf0922475","event_at":"2026-07-28T03:09:18.693000Z","event_type":"price_change","frame_hash":"61f405fb3629accb4c7d680f1ebffa0fee2abc4de60aa651b507525b34b7593f","frame_index":0,"kind":"data","monotonic_ns":310141666144083,"payload":{"event_type":"price_change","market":"0x779291bef19b6709f61e9764a954aafe9ffae488d50ae674aabdcb4f248006d5","price_changes":[{"asset_id":"14965588658799411272385430903075831224615961675357217884735713260981483529984","best_ask":"0.33","best_bid":"0.32","hash":"fd3ef24056e9a0bbeefd422ded523275f1b50952","price":"0.27","side":"BUY","size":"314"},{"asset_id":"8761897749749422724209054078244794145777693856614463256546737399611489089783","best_ask":"0.68","best_bid":"0.67","hash":"914cea441397faf2dbf2618e96d72f4deb32508c","price":"0.73","side":"SELL","size":"314"}],"timestamp":"1785208158693"},"payload_hash":"5bdd742142b298b2316622a994026bc455786b3af058ee9514bda63f10942704","raw_frame":"{\"market\":\"0x779291bef19b6709f61e9764a954aafe9ffae488d50ae674aabdcb4f248006d5\", \"price_changes\":[{\"asset_id\":\"14965588658799411272385430903075831224615961675357217884735713260981483529984\", \"price\":\"0.27\", \"size\":\"314\", \"side\":\"BUY\", \"hash\":\"fd3ef24056e9a0bbeefd422ded523275f1b50952\", \"best_bid\":\"0.32\", \"best_ask\":\"0.33\"}, {\"asset_id\":\"8761897749749422724209054078244794145777693856614463256546737399611489089783\", \"price\":\"0.73\", \"size\":\"314\", \"side\":\"SELL\", \"hash\":\"914cea441397faf2dbf2618e96d72f4deb32508c\", \"best_bid\":\"0.67\", \"best_ask\":\"0.68\"}], \"timestamp\":\"1785208158693\", \"event_type\":\"price_change\"}","received_at":"2026-07-28T03:09:18.633192Z","schema_version":"clob-market-ws.price_change.v1","sequence":null,"server_hash":null,"server_timestamp":"1785208158693","session_id":"3e519d9098404c15b234d96025eb1a2b","source":"clob_market_ws"},"received_at":"2026-07-28T03:09:18.633192Z","record_id":"8c94c5b21342d0554c6a6006e35267a798844a1283b19e891d89485a931249cc","schema_fingerprint":"4aa3821a28b0b7c2400bc59aba4bcc0a76e971dadd19610d3ad38c768e124dc7","schema_version":"edge-lab-recorder.raw.v1","sequence":null,"source":"clob_market_ws"}
{"event_at":"2026-07-28T03:09:18.699000Z","event_fingerprint":"8340cb14d2a0f75a8120b5aaeaa1e317ebcc14ae6fb9504621b030ac3e23ceb3","payload":{"connection_id":"a6b55582af5f430fb37ad02bf0922475","event_at":"2026-07-28T03:09:18.699000Z","event_type":"price_change","frame_hash":"a9a2af8a38c57c57b012ed3ce070af212f13ce42c31ad05b410a4ca3ad87b5c8","frame_index":0,"kind":"data","monotonic_ns":310141667607625,"payload":{"event_type":"price_change","market":"0x779291bef19b6709f61e9764a954aafe9ffae488d50ae674aabdcb4f248006d5","price_changes":[{"asset_id":"14965588658799411272385430903075831224615961675357217884735713260981483529984","best_ask":"0.33","best_bid":"0.32","hash":"a154c57ac4d6ff24260d80ba2052eacd06dac45c","price":"0.28","side":"BUY","size":"30"},{"asset_id":"8761897749749422724209054078244794145777693856614463256546737399611489089783","best_ask":"0.68","best_bid":"0.67","hash":"5181dfc7bedc83696cb904cc3197d3ba33e200aa","price":"0.72","side":"SELL","size":"30"}],"timestamp":"1785208158699"},"payload_hash":"98216e014e74f89d3226374ee398c994deeb1a19302320e4c6d32c38381f8234","raw_frame":"{\"market\":\"0x779291bef19b6709f61e9764a954aafe9ffae488d50ae674aabdcb4f248006d5\", \"price_changes\":[{\"asset_id\":\"14965588658799411272385430903075831224615961675357217884735713260981483529984\", \"price\":\"0.28\", \"size\":\"30\", \"side\":\"BUY\", \"hash\":\"a154c57ac4d6ff24260d80ba2052eacd06dac45c\", \"best_bid\":\"0.32\", \"best_ask\":\"0.33\"}, {\"asset_id\":\"8761897749749422724209054078244794145777693856614463256546737399611489089783\", \"price\":\"0.72\", \"size\":\"30\", \"side\":\"SELL\", \"hash\":\"5181dfc7bedc83696cb904cc3197d3ba33e200aa\", \"best_bid\":\"0.67\", \"best_ask\":\"0.68\"}], \"timestamp\":\"1785208158699\", \"event_type\":\"price_change\"}","received_at":"2026-07-28T03:09:18.634655Z","schema_version":"clob-market-ws.price_change.v1","sequence":null,"server_hash":null,"server_timestamp":"1785208158699","session_id":"3e519d9098404c15b234d96025eb1a2b","source":"clob_market_ws"},"received_at":"2026-07-28T03:09:18.634655Z","record_id":"713b13811c19e280a11e04979d0b42bf663d6446622a287afe0517f4b8e8be6b","schema_fingerprint":"4aa3821a28b0b7c2400bc59aba4bcc0a76e971dadd19610d3ad38c768e124dc7","schema_version":"edge-lab-recorder.raw.v1","sequence":null,"source":"clob_market_ws"}
{"event_at":"2026-07-28T03:09:18.699000Z","event_fingerprint":"64a8581f047db58d2cafa3946bd1b9cb7e3dbb5c578ff7c4478caf6f7e617aba","payload":{"connection_id":"a6b55582af5f430fb37ad02bf0922475","event_at":"2026-07-28T03:09:18.699000Z","event_type":"price_change","frame_hash":"7d2debd8d65883e967476dfe2440cfe352c3b8dbd6370aaa925e588a42a19106","frame_index":0,"kind":"data","monotonic_ns":310141669083125,"payload":{"event_type":"price_change","market":"0x779291bef19b6709f61e9764a954aafe9ffae488d50ae674aabdcb4f248006d5","price_changes":[{"asset_id":"14965588658799411272385430903075831224615961675357217884735713260981483529984","best_ask":"0.33","best_bid":"0.32","hash":"a154c57ac4d6ff24260d80ba2052eacd06dac45c","price":"0.29","side":"BUY","size":"30"},{"asset_id":"8761897749749422724209054078244794145777693856614463256546737399611489089783","best_ask":"0.68","best_bid":"0.67","hash":"5181dfc7bedc83696cb904cc3197d3ba33e200aa","price":"0.71","side":"SELL","size":"30"}],"timestamp":"1785208158699"},"payload_hash":"8865e9531b077f9b7eb137fb0a152cdc5620f86891f03e16a3d1a7e5faa60a4e","raw_frame":"{\"market\":\"0x779291bef19b6709f61e9764a954aafe9ffae488d50ae674aabdcb4f248006d5\", \"price_changes\":[{\"asset_id\":\"14965588658799411272385430903075831224615961675357217884735713260981483529984\", \"price\":\"0.29\", \"size\":\"30\", \"side\":\"BUY\", \"hash\":\"a154c57ac4d6ff24260d80ba2052eacd06dac45c\", \"best_bid\":\"0.32\", \"best_ask\":\"0.33\"}, {\"asset_id\":\"8761897749749422724209054078244794145777693856614463256546737399611489089783\", \"price\":\"0.71\", \"size\":\"30\", \"side\":\"SELL\", \"hash\":\"5181dfc7bedc83696cb904cc3197d3ba33e200aa\", \"best_bid\":\"0.67\", \"best_ask\":\"0.68\"}], \"timestamp\":\"1785208158699\", \"event_type\":\"price_change\"}","received_at":"2026-07-28T03:09:18.636131Z","schema_version":"clob-market-ws.price_change.v1","sequence":null,"server_hash":null,"server_timestamp":"1785208158699","session_id":"3e519d9098404c15b234d96025eb1a2b","source":"clob_market_ws"},"received_at":"2026-07-28T03:09:18.636131Z","record_id":"0148344a29afacd924842c4ddc1a2d6b9ba1b303023b8d6292b31222759169ea","schema_fingerprint":"4aa3821a28b0b7c2400bc59aba4bcc0a76e971dadd19610d3ad38c768e124dc7","schema_version":"edge-lab-recorder.raw.v1","sequence":null,"source":"clob_market_ws"}
{"event_at":"2026-07-28T03:09:18.700000Z","event_fingerprint":"06e5282a123ab0f6da6eef303b60de91c5319e042a64b5ba08126d267102600e","payload":{"connection_id":"a6b55582af5f430fb37ad02bf0922475","event_at":"2026-07-28T03:09:18.700000Z","event_type":"price_change","frame_hash":"f104e552cfed9aa41afed7550378da5af3309937d09d52545cca5ddf46b94148","frame_index":0,"kind":"data","monotonic_ns":310141670539916,"payload":{"event_type":"price_change","market":"0x779291bef19b6709f61e9764a954aafe9ffae488d50ae674aabdcb4f248006d5","price_changes":[{"asset_id":"14965588658799411272385430903075831224615961675357217884735713260981483529984","best_ask":"0.33","best_bid":"0.32","hash":"1d4a393ad33c765b62265181c8bdfddd6cc8cbd7","price":"0.21","side":"BUY","size":"144"},{"asset_id":"8761897749749422724209054078244794145777693856614463256546737399611489089783","best_ask":"0.68","best_bid":"0.67","hash":"0da86a5dd3268a8cc1acba8b8f661c3c3133632b","price":"0.79","side":"SELL","size":"144"}],"timestamp":"1785208158700"},"payload_hash":"3b7e8d3acfd0f283db289aa1ab3adcea522a2b3b02f06d6cc593694973c64333","raw_frame":"{\"market\":\"0x779291bef19b6709f61e9764a954aafe9ffae488d50ae674aabdcb4f248006d5\", \"price_changes\":[{\"asset_id\":\"14965588658799411272385430903075831224615961675357217884735713260981483529984\", \"price\":\"0.21\", \"size\":\"144\", \"side\":\"BUY\", \"hash\":\"1d4a393ad33c765b62265181c8bdfddd6cc8cbd7\", \"best_bid\":\"0.32\", \"best_ask\":\"0.33\"}, {\"asset_id\":\"8761897749749422724209054078244794145777693856614463256546737399611489089783\", \"price\":\"0.79\", \"size\":\"144\", \"side\":\"SELL\", \"hash\":\"0da86a5dd3268a8cc1acba8b8f661c3c3133632b\", \"best_bid\":\"0.67\", \"best_ask\":\"0.68\"}], \"timestamp\":\"1785208158700\", \"event_type\":\"price_change\"}","received_at":"2026-07-28T03:09:18.637588Z","schema_version":"clob-market-ws.price_change.v1","sequence":null,"server_hash":null,"server_timestamp":"1785208158700","session_id":"3e519d9098404c15b234d96025eb1a2b","source":"clob_market_ws"},"received_at":"2026-07-28T03:09:18.637588Z","record_id":"7c2805488b90da8163452a1b04723066a73c81513446cb0ca87a4f19627d9482","schema_fingerprint":"4aa3821a28b0b7c2400bc59aba4bcc0a76e971dadd19610d3ad38c768e124dc7","schema_version":"edge-lab-recorder.raw.v1","sequence":null,"source":"clob_market_ws"}
{"event_at":"2026-07-28T03:09:18.701000Z","event_fingerprint":"541b7671cba2a5be468bc57258a3fd77d82b90a6aa2d4ab9836afede18b7a566","payload":{"connection_id":"a6b55582af5f430fb37ad02bf0922475","event_at":"2026-07-28T03:09:18.701000Z","event_type":"price_change","frame_hash":"336fbbc566065e9c176f26648ed2f02604067ba35ef006b1fb70e43fe6857274","frame_index":0,"kind":"data","monotonic_ns":310141672000125,"payload":{"event_type":"price_change","market":"0x779291bef19b6709f61e9764a954aafe9ffae488d50ae674aabdcb4f248006d5","price_changes":[{"asset_id":"8761897749749422724209054078244794145777693856614463256546737399611489089783","best_ask":"0.68","best_bid":"0.67","hash":"1307277cabd3e88a0ceeffcdf1d4e6e9e0821356","price":"0.6","side":"BUY","size":"352.28"},{"asset_id":"14965588658799411272385430903075831224615961675357217884735713260981483529984","best_ask":"0.33","best_bid":"0.32","hash":"7b6579000eaa66d147c6421ec0e361df1a684ee4","price":"0.4","side":"SELL","size":"352.28"}],"timestamp":"1785208158701"},"payload_hash":"df8d5d8a31b5a4f57224fe8278715e30a3931e49048f05cfee5d6e7fb68075d6","raw_frame":"{\"market\":\"0x779291bef19b6709f61e9764a954aafe9ffae488d50ae674aabdcb4f248006d5\", \"price_changes\":[{\"asset_id\":\"8761897749749422724209054078244794145777693856614463256546737399611489089783\", \"price\":\"0.6\", \"size\":\"352.28\", \"side\":\"BUY\", \"hash\":\"1307277cabd3e88a0ceeffcdf1d4e6e9e0821356\", \"best_bid\":\"0.67\", \"best_ask\":\"0.68\"}, {\"asset_id\":\"14965588658799411272385430903075831224615961675357217884735713260981483529984\", \"price\":\"0.4\", \"size\":\"352.28\", \"side\":\"SELL\", \"hash\":\"7b6579000eaa66d147c6421ec0e361df1a684ee4\", \"best_bid\":\"0.32\", \"best_ask\":\"0.33\"}], \"timestamp\":\"1785208158701\", \"event_type\":\"price_change\"}","received_at":"2026-07-28T03:09:18.639048Z","schema_version":"clob-market-ws.price_change.v1","sequence":null,"server_hash":null,"server_timestamp":"1785208158701","session_id":"3e519d9098404c15b234d96025eb1a2b","source":"clob_market_ws"},"received_at":"2026-07-28T03:09:18.639048Z","record_id":"ee6fc22f62e55f6121ddced54fd887f4ab41c39a16720d4ed3cf151e4d02e1bc","schema_fingerprint":"4aa3821a28b0b7c2400bc59aba4bcc0a76e971dadd19610d3ad38c768e124dc7","schema_version":"edge-lab-recorder.raw.v1","sequence":null,"source":"clob_market_ws"}
{"event_at":"2026-07-28T03:09:18.702000Z","event_fingerprint":"5ef97da9e34040e48554be66c7a82192d14b7ad9dd6f4f410f21fbf011f3d1a2","payload":{"connection_id":"a6b55582af5f430fb37ad02bf0922475","event_at":"2026-07-28T03:09:18.702000Z","event_type":"price_change","frame_hash":"429d308e6047206eeee20ca433322c22240c84534f500784905ff25c27a06406","frame_index":0,"kind":"data","monotonic_ns":310141673459500,"payload":{"event_type":"price_change","market":"0x779291bef19b6709f61e9764a954aafe9ffae488d50ae674aabdcb4f248006d5","price_changes":[{"asset_id":"14965588658799411272385430903075831224615961675357217884735713260981483529984","best_ask":"0.33","best_bid":"0.32","hash":"3df46350c776bcd616cefe7a1aa52341828f9052","price":"0.26","side":"BUY","size":"45"},{"asset_id":"8761897749749422724209054078244794145777693856614463256546737399611489089783","best_ask":"0.68","best_bid":"0.67","hash":"755b910fec77e9fe66851dd66913009a3eccd16f","price":"0.74","side":"SELL","size":"45"}],"timestamp":"1785208158702"},"payload_hash":"6b8afc80a634a5b82fca1a73ab2eb0ed104e78d7ad845980d0c9186f264c8331","raw_frame":"{\"market\":\"0x779291bef19b6709f61e9764a954aafe9ffae488d50ae674aabdcb4f248006d5\", \"price_changes\":[{\"asset_id\":\"14965588658799411272385430903075831224615961675357217884735713260981483529984\", \"price\":\"0.26\", \"size\":\"45\", \"side\":\"BUY\", \"hash\":\"3df46350c776bcd616cefe7a1aa52341828f9052\", \"best_bid\":\"0.32\", \"best_ask\":\"0.33\"}, {\"asset_id\":\"8761897749749422724209054078244794145777693856614463256546737399611489089783\", \"price\":\"0.74\", \"size\":\"45\", \"side\":\"SELL\", \"hash\":\"755b910fec77e9fe66851dd66913009a3eccd16f\", \"best_bid\":\"0.67\", \"best_ask\":\"0.68\"}], \"timestamp\":\"1785208158702\", \"event_type\":\"price_change\"}","received_at":"2026-07-28T03:09:18.640507Z","schema_version":"clob-market-ws.price_change.v1","sequence":null,"server_hash":null,"server_timestamp":"1785208158702","session_id":"3e519d9098404c15b234d96025eb1a2b","source":"clob_market_ws"},"received_at":"2026-07-28T03:09:18.640507Z","record_id":"50f1e07ad7f1007995bb2f742af9a06a87ec1f06853cdaec7e7b38f30a1cd906","schema_fingerprint":"4aa3821a28b0b7c2400bc59aba4bcc0a76e971dadd19610d3ad38c768e124dc7","schema_version":"edge-lab-recorder.raw.v1","sequence":null,"source":"clob_market_ws"}
{"event_at":"2026-07-28T03:09:18.703000Z","event_fingerprint":"7e2b862980adcc9a13d49789cd3783a1e8e891e0a473aa1cbb0785e4971ffc81","payload":{"connection_id":"a6b55582af5f430fb37ad02bf0922475","event_at":"2026-07-28T03:09:18.703000Z","event_type":"price_change","frame_hash":"ae883606465594b734fc11fa3428084e6ff241d3c9fbbe64f5c815dac1a5c007","frame_index":0,"kind":"data","monotonic_ns":310141674921875,"payload":{"event_type":"price_change","market":"0x779291bef19b6709f61e9764a954aafe9ffae488d50ae674aabdcb4f248006d5","price_changes":[{"asset_id":"14965588658799411272385430903075831224615961675357217884735713260981483529984","best_ask":"0.33","best_bid":"0.32","hash":"33af97157513a2a203de66b8c62cc036ad7a4c46","price":"0.15","side":"BUY","size":"235"},{"asset_id":"8761897749749422724209054078244794145777693856614463256546737399611489089783","best_ask":"0.68","best_bid":"0.67","hash":"ce92f9a57e7a59aabbbbf8bbb06ea53e0b6c9026","price":"0.85","side":"SELL","size":"235"}],"timestamp":"1785208158703"},"payload_hash":"2d265ce2b2795e0637c74091b51e43dfbf2a8af217977721ecbb339348171f7d","raw_frame":"{\"market\":\"0x779291bef19b6709f61e9764a954aafe9ffae488d50ae674aabdcb4f248006d5\", \"price_changes\":[{\"asset_id\":\"14965588658799411272385430903075831224615961675357217884735713260981483529984\", \"price\":\"0.15\", \"size\":\"235\", \"side\":\"BUY\", \"hash\":\"33af97157513a2a203de66b8c62cc036ad7a4c46\", \"best_bid\":\"0.32\", \"best_ask\":\"0.33\"}, {\"asset_id\":\"8761897749749422724209054078244794145777693856614463256546737399611489089783\", \"price\":\"0.85\", \"size\":\"235\", \"side\":\"SELL\", \"hash\":\"ce92f9a57e7a59aabbbbf8bbb06ea53e0b6c9026\", \"best_bid\":\"0.67\", \"best_ask\":\"0.68\"}], \"timestamp\":\"1785208158703\", \"event_type\":\"price_change\"}","received_at":"2026-07-28T03:09:18.641969Z","schema_version":"clob-market-ws.price_change.v1","sequence":null,"server_hash":null,"server_timestamp":"1785208158703","session_id":"3e519d9098404c15b234d96025eb1a2b","source":"clob_market_ws"},"received_at":"2026-07-28T03:09:18.641969Z","record_id":"215635ff11ba9abcca3da3ec716e4441f2dbc245c4f7e655bab7c8555340f0f8","schema_fingerprint":"4aa3821a28b0b7c2400bc59aba4bcc0a76e971dadd19610d3ad38c768e124dc7","schema_version":"edge-lab-recorder.raw.v1","sequence":null,"source":"clob_market_ws"}
{"event_at":"2026-07-28T03:09:18.706000Z","event_fingerprint":"ea87e46db824bf9b97567a2eacb43d208cfdf9050ded2ce2a9e418675ec89991","payload":{"connection_id":"a6b55582af5f430fb37ad02bf0922475","event_at":"2026-07-28T03:09:18.706000Z","event_type":"price_change","frame_hash":"0d1cc358a989b7be433010e8bcdba3de60a3d8289585e3f70d614fbd338fe178","frame_index":0,"kind":"data","monotonic_ns":310141676357041,"payload":{"event_type":"price_change","market":"0x779291bef19b6709f61e9764a954aafe9ffae488d50ae674aabdcb4f248006d5","price_changes":[{"asset_id":"8761897749749422724209054078244794145777693856614463256546737399611489089783","best_ask":"0.68","best_bid":"0.67","hash":"d82588ceee6bda1874b4f9e859756892ab622613","price":"0.6","side":"BUY","size":"332.28"},{"asset_id":"14965588658799411272385430903075831224615961675357217884735713260981483529984","best_ask":"0.33","best_bid":"0.32","hash":"0ba2897f7daa5254115dd5460efd4db73ffafac7","price":"0.4","side":"SELL","size":"332.28"}],"timestamp":"1785208158706"},"payload_hash":"fcea09f65c8b29c51cd4d1e5e996b75ec5e6b7ceda49af22729e09aeab63a947","raw_frame":"{\"market\":\"0x779291bef19b6709f61e9764a954aafe9ffae488d50ae674aabdcb4f248006d5\", \"price_changes\":[{\"asset_id\":\"8761897749749422724209054078244794145777693856614463256546737399611489089783\", \"price\":\"0.6\", \"size\":\"332.28\", \"side\":\"BUY\", \"hash\":\"d82588ceee6bda1874b4f9e859756892ab622613\", \"best_bid\":\"0.67\", \"best_ask\":\"0.68\"}, {\"asset_id\":\"14965588658799411272385430903075831224615961675357217884735713260981483529984\", \"price\":\"0.4\", \"size\":\"332.28\", \"side\":\"SELL\", \"hash\":\"0ba2897f7daa5254115dd5460efd4db73ffafac7\", \"best_bid\":\"0.32\", \"best_ask\":\"0.33\"}], \"timestamp\":\"1785208158706\", \"event_type\":\"price_change\"}","received_at":"2026-07-28T03:09:18.643405Z","schema_version":"clob-market-ws.price_change.v1","sequence":null,"server_hash":null,"server_timestamp":"1785208158706","session_id":"3e519d9098404c15b234d96025eb1a2b","source":"clob_market_ws"},"received_at":"2026-07-28T03:09:18.643405Z","record_id":"2ff8a3dc78166d0d62bfe330954e8c86a6f48472e2d177acebc9861c48d23b7d","schema_fingerprint":"4aa3821a28b0b7c2400bc59aba4bcc0a76e971dadd19610d3ad38c768e124dc7","schema_version":"edge-lab-recorder.raw.v1","sequence":null,"source":"clob_market_ws"}
{"event_at":"2026-07-28T03:09:18.708000Z","event_fingerprint":"d8ed969cecfa6b9ee48bbf74051461f58b26325bb3693958e1f27efa154f335f","payload":{"connection_id":"a6b55582af5f430fb37ad02bf0922475","event_at":"2026-07-28T03:09:18.708000Z","event_type":"price_change","frame_hash":"d086ba186c2b7447f94bf65ac8a5845f5c01a7a4fc8a0d3b6fb09d78595ff028","frame_index":0,"kind":"data","monotonic_ns":310141677824375,"payload":{"event_type":"price_change","market":"0x779291bef19b6709f61e9764a954aafe9ffae488d50ae674aabdcb4f248006d5","price_changes":[{"asset_id":"8761897749749422724209054078244794145777693856614463256546737399611489089783","best_ask":"0.68","best_bid":"0.67","hash":"51b74a4b000e82e9f1e93f268751dc1dd6337835","price":"0.6","side":"BUY","size":"319.94"},{"asset_id":"14965588658799411272385430903075831224615961675357217884735713260981483529984","best_ask":"0.33","best_bid":"0.32","hash":"b6ccb28125ffe58962e7474752305f8849ef69c5","price":"0.4","side":"SELL","size":"319.94"}],"timestamp":"1785208158708"},"payload_hash":"b01fea93bd3a245d3c47bb7ff2041953cfca5cb31904de868c0f63cce6b48e7c","raw_frame":"{\"market\":\"0x779291bef19b6709f61e9764a954aafe9ffae488d50ae674aabdcb4f248006d5\", \"price_changes\":[{\"asset_id\":\"8761897749749422724209054078244794145777693856614463256546737399611489089783\", \"price\":\"0.6\", \"size\":\"319.94\", \"side\":\"BUY\", \"hash\":\"51b74a4b000e82e9f1e93f268751dc1dd6337835\", \"best_bid\":\"0.67\", \"best_ask\":\"0.68\"}, {\"asset_id\":\"14965588658799411272385430903075831224615961675357217884735713260981483529984\", \"price\":\"0.4\", \"size\":\"319.94\", \"side\":\"SELL\", \"hash\":\"b6ccb28125ffe58962e7474752305f8849ef69c5\", \"best_bid\":\"0.32\", \"best_ask\":\"0.33\"}], \"timestamp\":\"1785208158708\", \"event_type\":\"price_change\"}","received_at":"2026-07-28T03:09:18.644872Z","schema_version":"clob-market-ws.price_change.v1","sequence":null,"server_hash":null,"server_timestamp":"1785208158708","session_id":"3e519d9098404c15b234d96025eb1a2b","source":"clob_market_ws"},"received_at":"2026-07-28T03:09:18.644872Z","record_id":"7cee413d78f12a3a36bb5526f13f57fddaad7e01d3f197f1ccb7c3642a7ece25","schema_fingerprint":"4aa3821a28b0b7c2400bc59aba4bcc0a76e971dadd19610d3ad38c768e124dc7","schema_version":"edge-lab-recorder.raw.v1","sequence":null,"source":"clob_market_ws"}
{"event_at":"2026-07-28T03:09:18.708000Z","event_fingerprint":"da9e41a91e6d0ec7345ac160dc723c0e5eca0cf48657f5b2998927ac8fb22dcd","payload":{"connection_id":"a6b55582af5f430fb37ad02bf0922475","event_at":"2026-07-28T03:09:18.708000Z","event_type":"price_change","frame_hash":"87b9548eca0a8c4ac756e99c76d5013efc5629357e9e1be83809a4612eaa9a8e","frame_index":0,"kind":"data","monotonic_ns":310141679360291,"payload":{"event_type":"price_change","market":"0x779291bef19b6709f61e9764a954aafe9ffae488d50ae674aabdcb4f248006d5","price_changes":[{"asset_id":"8761897749749422724209054078244794145777693856614463256546737399611489089783","best_ask":"0.68","best_bid":"0.67","hash":"51b74a4b000e82e9f1e93f268751dc1dd6337835","price":"0.59","side":"BUY","size":"181.94"},{"asset_id":"14965588658799411272385430903075831224615961675357217884735713260981483529984","best_ask":"0.33","best_bid":"0.32","hash":"b6ccb28125ffe58962e7474752305f8849ef69c5","price":"0.41","side":"SELL","size":"181.94"}],"timestamp":"1785208158708"},"payload_hash":"70d43523851db31a224b1ac4196c44aae130a9c6521d4c63d4d5171a479b7277","raw_frame":"{\"market\":\"0x779291bef19b6709f61e9764a954aafe9ffae488d50ae674aabdcb4f248006d5\", \"price_changes\":[{\"asset_id\":\"8761897749749422724209054078244794145777693856614463256546737399611489089783\", \"price\":\"0.59\", \"size\":\"181.94\", \"side\":\"BUY\", \"hash\":\"51b74a4b000e82e9f1e93f268751dc1dd6337835\", \"best_bid\":\"0.67\", \"best_ask\":\"0.68\"}, {\"asset_id\":\"14965588658799411272385430903075831224615961675357217884735713260981483529984\", \"price\":\"0.41\", \"size\":\"181.94\", \"side\":\"SELL\", \"hash\":\"b6ccb28125ffe58962e7474752305f8849ef69c5\", \"best_bid\":\"0.32\", \"best_ask\":\"0.33\"}], \"timestamp\":\"1785208158708\", \"event_type\":\"price_change\"}","received_at":"2026-07-28T03:09:18.646407Z","schema_version":"clob-market-ws.price_change.v1","sequence":null,"server_hash":null,"server_timestamp":"1785208158708","session_id":"3e519d9098404c15b234d96025eb1a2b","source":"clob_market_ws"},"received_at":"2026-07-28T03:09:18.646407Z","record_id":"077ada4d6dd80074176657c2ed5c19c3a1ebec8f119130ef869dbd507cff72ee","schema_fingerprint":"4aa3821a28b0b7c2400bc59aba4bcc0a76e971dadd19610d3ad38c768e124dc7","schema_version":"edge-lab-recorder.raw.v1","sequence":null,"source":"clob_market_ws"}
{"event_at":"2026-07-28T03:09:18.708000Z","event_fingerprint":"7faf11e73339d5378f3fe7d9267925b02d4c8b31ad1fa26f08766fce933acd1c","payload":{"connection_id":"a6b55582af5f430fb37ad02bf0922475","event_at":"2026-07-28T03:09:18.708000Z","event_type":"price_change","frame_hash":"25ca4accd6834b98fdd15cf5b72837406b17f2c543ca4e9594228086639c3988","frame_index":0,"kind":"data","monotonic_ns":310141680801625,"payload":{"event_type":"price_change","market":"0x779291bef19b6709f61e9764a954aafe9ffae488d50ae674aabdcb4f248006d5","price_changes":[{"asset_id":"8761897749749422724209054078244794145777693856614463256546737399611489089783","best_ask":"0.68","best_bid":"0.67","hash":"51b74a4b000e82e9f1e93f268751dc1dd6337835","price":"0.58","side":"BUY","size":"169"},{"asset_id":"14965588658799411272385430903075831224615961675357217884735713260981483529984","best_ask":"0.33","best_bid":"0.32","hash":"b6ccb28125ffe58962e7474752305f8849ef69c5","price":"0.42","side":"SELL","size":"169"}],"timestamp":"1785208158708"},"payload_hash":"49118d1312e8ecbbfeb48ed35cfd26435f1c13921d6ab224c185e604ccfd51b6","raw_frame":"{\"market\":\"0x779291bef19b6709f61e9764a954aafe9ffae488d50ae674aabdcb4f248006d5\", \"price_changes\":[{\"asset_id\":\"8761897749749422724209054078244794145777693856614463256546737399611489089783\", \"price\":\"0.58\", \"size\":\"169\", \"side\":\"BUY\", \"hash\":\"51b74a4b000e82e9f1e93f268751dc1dd6337835\", \"best_bid\":\"0.67\", \"best_ask\":\"0.68\"}, {\"asset_id\":\"14965588658799411272385430903075831224615961675357217884735713260981483529984\", \"price\":\"0.42\", \"size\":\"169\", \"side\":\"SELL\", \"hash\":\"b6ccb28125ffe58962e7474752305f8849ef69c5\", \"best_bid\":\"0.32\", \"best_ask\":\"0.33\"}], \"timestamp\":\"1785208158708\", \"event_type\":\"price_change\"}","received_at":"2026-07-28T03:09:18.647849Z","schema_version":"clob-market-ws.price_change.v1","sequence":null,"server_hash":null,"server_timestamp":"1785208158708","session_id":"3e519d9098404c15b234d96025eb1a2b","source":"clob_market_ws"},"received_at":"2026-07-28T03:09:18.647849Z","record_id":"3a6013f5c4ab33f53ce9620e7f24d1654babccbbddf1da9513ad0014621610a7","schema_fingerprint":"4aa3821a28b0b7c2400bc59aba4bcc0a76e971dadd19610d3ad38c768e124dc7","schema_version":"edge-lab-recorder.raw.v1","sequence":null,"source":"clob_market_ws"}
{"event_at":"2026-07-28T03:09:18.708000Z","event_fingerprint":"c8dbd6d0246d068c2b7d767c96f5468ada5595cebeb1bd95e5954a3a676ea2ea","payload":{"connection_id":"a6b55582af5f430fb37ad02bf0922475","event_at":"2026-07-28T03:09:18.708000Z","event_type":"price_change","frame_hash":"bb4dcfc5590202b910110b4ca1327ba7a9cd85be04f85b7ab4ee77ba50d8fdce","frame_index":0,"kind":"data","monotonic_ns":310141682276291,"payload":{"event_type":"price_change","market":"0x779291bef19b6709f61e9764a954aafe9ffae488d50ae674aabdcb4f248006d5","price_changes":[{"asset_id":"8761897749749422724209054078244794145777693856614463256546737399611489089783","best_ask":"0.68","best_bid":"0.67","hash":"51b74a4b000e82e9f1e93f268751dc1dd6337835","price":"0.57","side":"BUY","size":"200"},{"asset_id":"14965588658799411272385430903075831224615961675357217884735713260981483529984","best_ask":"0.33","best_bid":"0.32","hash":"b6ccb28125ffe58962e7474752305f8849ef69c5","price":"0.43","side":"SELL","size":"200"}],"timestamp":"1785208158708"},"payload_hash":"b43e53669d2c745f6b60cfbb7ef945933c7a4333ca3e964a505de4ae12ace901","raw_frame":"{\"market\":\"0x779291bef19b6709f61e9764a954aafe9ffae488d50ae674aabdcb4f248006d5\", \"price_changes\":[{\"asset_id\":\"8761897749749422724209054078244794145777693856614463256546737399611489089783\", \"price\":\"0.57\", \"size\":\"200\", \"side\":\"BUY\", \"hash\":\"51b74a4b000e82e9f1e93f268751dc1dd6337835\", \"best_bid\":\"0.67\", \"best_ask\":\"0.68\"}, {\"asset_id\":\"14965588658799411272385430903075831224615961675357217884735713260981483529984\", \"price\":\"0.43\", \"size\":\"200\", \"side\":\"SELL\", \"hash\":\"b6ccb28125ffe58962e7474752305f8849ef69c5\", \"best_bid\":\"0.32\", \"best_ask\":\"0.33\"}], \"timestamp\":\"1785208158708\", \"event_type\":\"price_change\"}","received_at":"2026-07-28T03:09:18.649324Z","schema_version":"clob-market-ws.price_change.v1","sequence":null,"server_hash":null,"server_timestamp":"1785208158708","session_id":"3e519d9098404c15b234d96025eb1a2b","source":"clob_market_ws"},"received_at":"2026-07-28T03:09:18.649324Z","record_id":"28e473074ecbe1baffb2d0a7ca3bc8f917d9f2ac11d44a943ef39ed5a79a750f","schema_fingerprint":"4aa3821a28b0b7c2400bc59aba4bcc0a76e971dadd19610d3ad38c768e124dc7","schema_version":"edge-lab-recorder.raw.v1","sequence":null,"source":"clob_market_ws"}
