{"event_at":"2026-07-28T03:10:51.049000Z","event_fingerprint":"edaaf35d93065ccab2efe5f5e32e9e93f075f2db257a61ea71c86b542df323e9","payload":{"connection_id":"a6b55582af5f430fb37ad02bf0922475","event_at":"2026-07-28T03:10:51.049000Z","event_type":"price_change","frame_hash":"449af9c33509e3a26c419dcc68d3fe61d8e1fbe8d8827cf1e9415ca31d0bc02f","frame_index":0,"kind":"data","monotonic_ns":310233957164666,"payload":{"event_type":"price_change","market":"0x779291bef19b6709f61e9764a954aafe9ffae488d50ae674aabdcb4f248006d5","price_changes":[{"asset_id":"14965588658799411272385430903075831224615961675357217884735713260981483529984","best_ask":"0.09","best_bid":"0.08","hash":"9b758e9714f1a6b65960d2467de4e7c7a3d58086","price":"0.01","side":"BUY","size":"5508.02"},{"asset_id":"8761897749749422724209054078244794145777693856614463256546737399611489089783","best_ask":"0.92","best_bid":"0.91","hash":"b95e7acc7298ce3292056e6f15eb26e5a95a6d74","price":"0.99","side":"SELL","size":"5508.02"}],"timestamp":"1785208251049"},"payload_hash":"461b7d30f64894a47eb09f167e767a1526a893816783c0aa628d7f08b8bbc5af","raw_frame":"{\"market\":\"0x779291bef19b6709f61e9764a954aafe9ffae488d50ae674aabdcb4f248006d5\", \"price_changes\":[{\"asset_id\":\"14965588658799411272385430903075831224615961675357217884735713260981483529984\", \"price\":\"0.01\", \"size\":\"5508.02\", \"side\":\"BUY\", \"hash\":\"9b758e9714f1a6b65960d2467de4e7c7a3d58086\", \"best_bid\":\"0.08\", \"best_ask\":\"0.09\"}, {\"asset_id\":\"8761897749749422724209054078244794145777693856614463256546737399611489089783\", \"price\":\"0.99\", \"size\":\"5508.02\", \"side\":\"SELL\", \"hash\":\"b95e7acc7298ce3292056e6f15eb26e5a95a6d74\", \"best_bid\":\"0.91\", \"best_ask\":\"0.92\"}], \"timestamp\":\"1785208251049\", \"event_type\":\"price_change\"}","received_at":"2026-07-28T03:10:50.923406Z","schema_version":"clob-market-ws.price_change.v1","sequence":null,"server_hash":null,"server_timestamp":"1785208251049","session_id":"3e519d9098404c15b234d96025eb1a2b","source":"clob_market_ws"},"received_at":"2026-07-28T03:10:50.923406Z","record_id":"de88bca8883af99e0c35658cec8fe7c52dcfec297a6202b17a11d8731660ed8e","schema_fingerprint":"4aa3821a28b0b7c2400bc59aba4bcc0a76e971dadd19610d3ad38c768e124dc7","schema_version":"edge-lab-recorder.raw.v1","sequence":null,"source":"clob_market_ws"}
{"event_at":"2026-07-28T03:10:51.104000Z","event_fingerprint":"e2652957cfcf55b770e047f0a27db16eaae482f696104abbe3d0d90535155778","payload":{"connection_id":"a6b55582af5f430fb37ad02bf0922475","event_at":"2026-07-28T03:10:51.104000Z","event_type":"price_change","frame_hash":"121ec8850456ac641a92a295b73443445310bfd838a1aef0df1eb9d842e3f3c3","frame_index":0,"kind":"data","monotonic_ns":310233971607041,"payload":{"event_type":"price_change","market":"0x779291bef19b6709f61e9764a954aafe9ffae488d50ae674aabdcb4f248006d5","price_changes":[{"asset_id":"8761897749749422724209054078244794145777693856614463256546737399611489089783","best_ask":"0.92","best_bid":"0.91","hash":"d7592c4342d18a23071f2a0ad7ca6ab6b85a35a3","price":"0.01","side":"BUY","size":"5603.02"},{"asset_id":"14965588658799411272385430903075831224615961675357217884735713260981483529984","best_ask":"0.09","best_bid":"0.08","hash":"aa6b6fbaa3cbfb102a7a2c382c245e09a7e2afe6","price":"0.99","side":"SELL","size":"5603.02"}],"timestamp":"1785208251104"},"payload_hash":"0c390997c628b037fcc93bce796b457b3244e6d91d00fd79acbc97ae75b93ecb","raw_frame":"{\"market\":\"0x779291bef19b6709f61e9764a954aafe9ffae488d50ae674aabdcb4f248006d5\", \"price_changes\":[{\"asset_id\":\"8761897749749422724209054078244794145777693856614463256546737399611489089783\", \"price\":\"0.01\", \"size\":\"5603.02\", \"side\":\"BUY\", \"hash\":\"d7592c4342d18a23071f2a0ad7ca6ab6b85a35a3\", \"best_bid\":\"0.91\", \"best_ask\":\"0.92\"}, {\"asset_id\":\"14965588658799411272385430903075831224615961675357217884735713260981483529984\", \"price\":\"0.99\", \"size\":\"5603.02\", \"side\":\"SELL\", \"hash\":\"aa6b6fbaa3cbfb102a7a2c382c245e09a7e2afe6\", \"best_bid\":\"0.08\", \"best_ask\":\"0.09\"}], \"timestamp\":\"1785208251104\", \"event_type\":\"price_change\"}","received_at":"2026-07-28T03:10:50.937849Z","schema_version":"clob-market-ws.price_change.v1","sequence":null,"server_hash":null,"server_timestamp":"1785208251104","session_id":"3e519d9098404c15b234d96025eb1a2b","source":"clob_market_ws"},"received_at":"2026-07-28T03:10:50.937849Z","record_id":"682a99a4683714524c79672ca5b1cb8efe5e718a79ed293d2e1e276ad9bb5f12","schema_fingerprint":"4aa3821a28b0b7c2400bc59aba4bcc0a76e971dadd19610d3ad38c768e124dc7","schema_version":"edge-lab-recorder.raw.v1","sequence":null,"source":"clob_market_ws"}
{"event_at":"2026-07-28T03:10:51.118000Z","event_fingerprint":"0d9e6885682b68eee6ed5e825243659956e1b84d291c84e1f0dbad01b5b13d4f","payload":{"connection_id":"a6b55582af5f430fb37ad02bf0922475","event_at":"2026-07-28T03:10:51.118000Z","event_type":"price_change","frame_hash":"082e94be9d244b2d3dcd95468d0ad85b8b80a5be4a2497b7c0d7ce1ade82165b","frame_index":0,"kind":"data","monotonic_ns":310233985658083,"payload":{"event_type":"price_change","market":"0x779291bef19b6709f61e9764a954aafe9ffae488d50ae674aabdcb4f248006d5","price_changes":[{"asset_id":"8761897749749422724209054078244794145777693856614463256546737399611489089783","best_ask":"0.92","best_bid":"0.91","hash":"17a17e0fc991860956dbfba5fa57314ce5ee3338","price":"0.01","side":"BUY","size":"5608.02"},{"asset_id":"14965588658799411272385430903075831224615961675357217884735713260981483529984","best_ask":"0.09","best_bid":"0.08","hash":"e5f9874d08ee2a5110746e16bc4a8f4bfa776f29","price":"0.99","side":"SELL","size":"5608.02"}],"timestamp":"1785208251118"},"payload_hash":"2fcca7bc4a7ee7f0982e0aeb19f1099ea0dc543636ddc6c4f1db0bc5fbbcebe0","raw_frame":"{\"market\":\"0x779291bef19b6709f61e9764a954aafe9ffae488d50ae674aabdcb4f248006d5\", \"price_changes\":[{\"asset_id\":\"8761897749749422724209054078244794145777693856614463256546737399611489089783\", \"price\":\"0.01\", \"size\":\"5608.02\", \"side\":\"BUY\", \"hash\":\"17a17e0fc991860956dbfba5fa57314ce5ee3338\", \"best_bid\":\"0.91\", \"best_ask\":\"0.92\"}, {\"asset_id\":\"14965588658799411272385430903075831224615961675357217884735713260981483529984\", \"price\":\"0.99\", \"size\":\"5608.02\", \"side\":\"SELL\", \"hash\":\"e5f9874d08ee2a5110746e16bc4a8f4bfa776f29\", \"best_bid\":\"0.08\", \"best_ask\":\"0.09\"}], \"timestamp\":\"1785208251118\", \"event_type\":\"price_change\"}","received_at":"2026-07-28T03:10:50.951902Z","schema_version":"clob-market-ws.price_change.v1","sequence":null,"server_hash":null,"server_timestamp":"1785208251118","session_id":"3e519d9098404c15b234d96025eb1a2b","source":"clob_market_ws"},"received_at":"2026-07-28T03:10:50.951902Z","record_id":"df5b4666160324cff893ddebbc6ac1adfe848e0fae273c9a175616227f1b7b45","schema_fingerprint":"4aa3821a28b0b7c2400bc59aba4bcc0a76e971dadd19610d3ad38c768e124dc7","schema_version":"edge-lab-recorder.raw.v1","sequence":null,"source":"clob_market_ws"}
{"event_at":"2026-07-28T03:10:51.138000Z","event_fingerprint":"df99a3565333798326655ca1251c9dba6d76bc440a67e498589ecc42bef7b602","payload":{"connection_id":"a6b55582af5f430fb37ad02bf0922475","event_at":"2026-07-28T03:10:51.138000Z","event_type":"price_change","frame_hash":"ca79d2a1f39c158336ade7bb7571f671e73f74309c564287ccec9ba372b1ac94","frame_index":0,"kind":"data","monotonic_ns":310234006218958,"payload":{"event_type":"price_change","market":"0x779291bef19b6709f61e9764a954aafe9ffae488d50ae674aabdcb4f248006d5","price_changes":[{"asset_id":"8761897749749422724209054078244794145777693856614463256546737399611489089783","best_ask":"0.92","best_bid":"0.91","hash":"bb20d9f6b85853d423e3913f05d0d985e065297d","price":"0.01","side":"BUY","size":"5603.02"},{"asset_id":"14965588658799411272385430903075831224615961675357217884735713260981483529984","best_ask":"0.09","best_bid":"0.08","hash":"c72fffd4be7ee1a5324476fc359edabad8c8b427","price":"0.99","side":"SELL","size":"5603.02"}],"timestamp":"1785208251138"},"payload_hash":"98a8f2230f38af73b9df74d7b8f33de309ba740366762c152e4c3090b46453d8","raw_frame":"{\"market\":\"0x779291bef19b6709f61e9764a954aafe9ffae488d50ae674aabdcb4f248006d5\", \"price_changes\":[{\"asset_id\":\"8761897749749422724209054078244794145777693856614463256546737399611489089783\", \"price\":\"0.01\", \"size\":\"5603.02\", \"side\":\"BUY\", \"hash\":\"bb20d9f6b85853d423e3913f05d0d985e065297d\", \"best_bid\":\"0.91\", \"best_ask\":\"0.92\"}, {\"asset_id\":\"14965588658799411272385430903075831224615961675357217884735713260981483529984\", \"price\":\"0.99\", \"size\":\"5603.02\", \"side\":\"SELL\", \"hash\":\"c72fffd4be7ee1a5324476fc359edabad8c8b427\", \"best_bid\":\"0.08\", \"best_ask\":\"0.09\"}], \"timestamp\":\"1785208251138\", \"event_type\":\"price_change\"}","received_at":"2026-07-28T03:10:50.972462Z","schema_version":"clob-market-ws.price_change.v1","sequence":null,"server_hash":null,"server_timestamp":"1785208251138","session_id":"3e519d9098404c15b234d96025eb1a2b","source":"clob_market_ws"},"received_at":"2026-07-28T03:10:50.972462Z","record_id":"5ebfb39fa37c7035607cf508378596bf144db5ed1c642bd49866c7fab8d3a595","schema_fingerprint":"4aa3821a28b0b7c2400bc59aba4bcc0a76e971dadd19610d3ad38c768e124dc7","schema_version":"edge-lab-recorder.raw.v1","sequence":null,"source":"clob_market_ws"}
{"event_at":"2026-07-28T03:10:51.142000Z","event_fingerprint":"8175efbd7d533f0e58f005e84144cb24b479d8452be0041533244620720f86d9","payload":{"connection_id":"a6b55582af5f430fb37ad02bf0922475","event_at":"2026-07-28T03:10:51.142000Z","event_type":"price_change","frame_hash":"05a569a5600d8f94a8fb3f7d3da17ea380fac090f6782a51c04a08d708d7a244","frame_index":0,"kind":"data","monotonic_ns":310234008977333,"payload":{"event_type":"price_change","market":"0x779291bef19b6709f61e9764a954aafe9ffae488d50ae674aabdcb4f248006d5","price_changes":[{"asset_id":"14965588658799411272385430903075831224615961675357217884735713260981483529984","best_ask":"0.09","best_bid":"0.08","hash":"c8323e641af6e01d8f9fb2d2126b9b2e9da02419","price":"0.01","side":"BUY","size":"5503.02"},{"asset_id":"8761897749749422724209054078244794145777693856614463256546737399611489089783","best_ask":"0.92","best_bid":"0.91","hash":"c5960b12fd3a03c43340ca9d56d890954a01e62e","price":"0.99","side":"SELL","size":"5503.02"}],"timestamp":"1785208251142"},"payload_hash":"83068799586aaf0c25e050c4d83baae648e4653b9ab0a8a03eaa976650ed2aac","raw_frame":"{\"market\":\"0x779291bef19b6709f61e9764a954aafe9ffae488d50ae674aabdcb4f248006d5\", \"price_changes\":[{\"asset_id\":\"14965588658799411272385430903075831224615961675357217884735713260981483529984\", \"price\":\"0.01\", \"size\":\"5503.02\", \"side\":\"BUY\", \"hash\":\"c8323e641af6e01d8f9fb2d2126b9b2e9da02419\", \"best_bid\":\"0.08\", \"best_ask\":\"0.09\"}, {\"asset_id\":\"8761897749749422724209054078244794145777693856614463256546737399611489089783\", \"price\":\"0.99\", \"size\":\"5503.02\", \"side\":\"SELL\", \"hash\":\"c5960b12fd3a03c43340ca9d56d890954a01e62e\", \"best_bid\":\"0.91\", \"best_ask\":\"0.92\"}], \"timestamp\":\"1785208251142\", \"event_type\":\"price_change\"}","received_at":"2026-07-28T03:10:50.975221Z","schema_version":"clob-market-ws.price_change.v1","sequence":null,"server_hash":null,"server_timestamp":"1785208251142","session_id":"3e519d9098404c15b234d96025eb1a2b","source":"clob_market_ws"},"received_at":"2026-07-28T03:10:50.975221Z","record_id":"ff2d940c68756c287553645aa91ad34f92373094b988463827c0df778b63d60e","schema_fingerprint":"4aa3821a28b0b7c2400bc59aba4bcc0a76e971dadd19610d3ad38c768e124dc7","schema_version":"edge-lab-recorder.raw.v1","sequence":null,"source":"clob_market_ws"}
{"event_at":"2026-07-28T03:10:51.144000Z","event_fingerprint":"0cb36e7f829921719e9832df5113416aceb6091625d20a34371d66ac156a2f54","payload":{"connection_id":"a6b55582af5f430fb37ad02bf0922475","event_at":"2026-07-28T03:10:51.144000Z","event_type":"price_change","frame_hash":"a21f841a181d23188b61b1b7484f04a73f88beb631b1b3ba1ea573866368a528","frame_index":0,"kind":"data","monotonic_ns":310234011800583,"payload":{"event_type":"price_change","market":"0x779291bef19b6709f61e9764a954aafe9ffae488d50ae674aabdcb4f248006d5","price_changes":[{"asset_id":"14965588658799411272385430903075831224615961675357217884735713260981483529984","best_ask":"0.09","best_bid":"0.08","hash":"2a15fefd1ab32db03d0751fb65ad75a254609eac","price":"0.06","side":"BUY","size":"501.98"},{"asset_id":"8761897749749422724209054078244794145777693856614463256546737399611489089783","best_ask":"0.92","best_bid":"0.91","hash":"38e92147a175c726de52fc35af8988bf1553e226","price":"0.94","side":"SELL","size":"501.98"}],"timestamp":"1785208251144"},"payload_hash":"791270dfbddca26dc53973ac43650aa30fceb3720dad995433714f63ef05c768","raw_frame":"{\"market\":\"0x779291bef19b6709f61e9764a954aafe9ffae488d50ae674aabdcb4f248006d5\", \"price_changes\":[{\"asset_id\":\"14965588658799411272385430903075831224615961675357217884735713260981483529984\", \"price\":\"0.06\", \"size\":\"501.98\", \"side\":\"BUY\", \"hash\":\"2a15fefd1ab32db03d0751fb65ad75a254609eac\", \"best_bid\":\"0.08\", \"best_ask\":\"0.09\"}, {\"asset_id\":\"8761897749749422724209054078244794145777693856614463256546737399611489089783\", \"price\":\"0.94\", \"size\":\"501.98\", \"side\":\"SELL\", \"hash\":\"38e92147a175c726de52fc35af8988bf1553e226\", \"best_bid\":\"0.91\", \"best_ask\":\"0.92\"}], \"timestamp\":\"1785208251144\", \"event_type\":\"price_change\"}","received_at":"2026-07-28T03:10:50.978043Z","schema_version":"clob-market-ws.price_change.v1","sequence":null,"server_hash":null,"server_timestamp":"1785208251144","session_id":"3e519d9098404c15b234d96025eb1a2b","source":"clob_market_ws"},"received_at":"2026-07-28T03:10:50.978043Z","record_id":"7dc0bd023779def8b8599ea75274049807f9ae82828547669125ac05764d621e","schema_fingerprint":"4aa3821a28b0b7c2400bc59aba4bcc0a76e971dadd19610d3ad38c768e124dc7","schema_version":"edge-lab-recorder.raw.v1","sequence":null,"source":"clob_market_ws"}
{"event_at":"2026-07-28T03:10:51.163000Z","event_fingerprint":"60e482b827b10d9b132c940d62de6c8b8fa8de2231e324588c2d390c6b48e8ca","payload":{"connection_id":"a6b55582af5f430fb37ad02bf0922475","event_at":"2026-07-28T03:10:51.163000Z","event_type":"price_change","frame_hash":"ce5010510b914a5534bf7162bfd48fffc67b5add547384b5b888d9a2a96fe3e4","frame_index":0,"kind":"data","monotonic_ns":310234031965708,"payload":{"event_type":"price_change","market":"0x779291bef19b6709f61e9764a954aafe9ffae488d50ae674aabdcb4f248006d5","price_changes":[{"asset_id":"8761897749749422724209054078244794145777693856614463256546737399611489089783","best_ask":"0.92","best_bid":"0.91","hash":"60d7e0f9a3e2c3c5f79587cbe0243be25de2794e","price":"0.91","side":"BUY","size":"206.2"},{"asset_id":"14965588658799411272385430903075831224615961675357217884735713260981483529984","best_ask":"0.09","best_bid":"0.08","hash":"2195c28ccadd82cef4db9c287a63b9bb6c4cd335","price":"0.09","side":"SELL","size":"206.2"}],"timestamp":"1785208251163"},"payload_hash":"a532c80377ae9c30bd926531c24aab08cdea0e78ff4cfcdb277659622788fc96","raw_frame":"{\"market\":\"0x779291bef19b6709f61e9764a954aafe9ffae488d50ae674aabdcb4f248006d5\", \"price_changes\":[{\"asset_id\":\"8761897749749422724209054078244794145777693856614463256546737399611489089783\", \"price\":\"0.91\", \"size\":\"206.2\", \"side\":\"BUY\", \"hash\":\"60d7e0f9a3e2c3c5f79587cbe0243be25de2794e\", \"best_bid\":\"0.91\", \"best_ask\":\"0.92\"}, {\"asset_id\":\"14965588658799411272385430903075831224615961675357217884735713260981483529984\", \"price\":\"0.09\", \"size\":\"206.2\", \"side\":\"SELL\", \"hash\":\"2195c28ccadd82cef4db9c287a63b9bb6c4cd335\", \"best_bid\":\"0.08\", \"best_ask\":\"0.09\"}], \"timestamp\":\"1785208251163\", \"event_type\":\"price_change\"}","received_at":"2026-07-28T03:10:50.998208Z","schema_version":"clob-market-ws.price_change.v1","sequence":null,"server_hash":null,"server_timestamp":"1785208251163","session_id":"3e519d9098404c15b234d96025eb1a2b","source":"clob_market_ws"},"received_at":"2026-07-28T03:10:50.998208Z","record_id":"2127c2971f578ebcc85d888fe269a89c2e1eef753c80a36e2fa685de49b849f2","schema_fingerprint":"4aa3821a28b0b7c2400bc59aba4bcc0a76e971dadd19610d3ad38c768e124dc7","schema_version":"edge-lab-recorder.raw.v1","sequence":null,"source":"clob_market_ws"}
{"event_at":"2026-07-28T03:10:51.211000Z","event_fingerprint":"767993ea97796fe98709ac635269789eaa102de5db330bc6201c594591fa91dc","payload":{"connection_id":"a6b55582af5f430fb37ad02bf0922475","event_at":"2026-07-28T03:10:51.211000Z","event_type":"price_change","frame_hash":"dc4dc8b4dfcbad436ab1d96be39608f6d559988f3459fcfd446bcbcc19668089","frame_index":0,"kind":"data","monotonic_ns":310234081242375,"payload":{"event_type":"price_change","market":"0x779291bef19b6709f61e9764a954aafe9ffae488d50ae674aabdcb4f248006d5","price_changes":[{"asset_id":"8761897749749422724209054078244794145777693856614463256546737399611489089783","best_ask":"0.92","best_bid":"0.91","hash":"dcf19ab42360a5b1ebed3f984be6034dfd691a4c","price":"0.04","side":"BUY","size":"593.09"},{"asset_id":"14965588658799411272385430903075831224615961675357217884735713260981483529984","best_ask":"0.09","best_bid":"0.08","hash":"be0b5a15860ff96543ca39259bbc62e944a7819c","price":"0.96","side":"SELL","size":"593.09"}],"timestamp":"1785208251211"},"payload_hash":"a227c3a8ae2aba3570f0be1b76fb57a250411a1aed0b96103f922834c57f6359","raw_frame":"{\"market\":\"0x779291bef19b6709f61e9764a954aafe9ffae488d50ae674aabdcb4f248006d5\", \"price_changes\":[{\"asset_id\":\"8761897749749422724209054078244794145777693856614463256546737399611489089783\", \"price\":\"0.04\", \"size\":\"593.09\", \"side\":\"BUY\", \"hash\":\"dcf19ab42360a5b1ebed3f984be6034dfd691a4c\", \"best_bid\":\"0.91\", \"best_ask\":\"0.92\"}, {\"asset_id\":\"14965588658799411272385430903075831224615961675357217884735713260981483529984\", \"price\":\"0.96\", \"size\":\"593.09\", \"side\":\"SELL\", \"hash\":\"be0b5a15860ff96543ca39259bbc62e944a7819c\", \"best_bid\":\"0.08\", \"best_ask\":\"0.09\"}], \"timestamp\":\"1785208251211\", \"event_type\":\"price_change\"}","received_at":"2026-07-28T03:10:51.047484Z","schema_version":"clob-market-ws.price_change.v1","sequence":null,"server_hash":null,"server_timestamp":"1785208251211","session_id":"3e519d9098404c15b234d96025eb1a2b","source":"clob_market_ws"},"received_at":"2026-07-28T03:10:51.047484Z","record_id":"94cf7b9b8b585b9edb5aee12856a2570266db42fca6379d4de835d36e6897b58","schema_fingerprint":"4aa3821a28b0b7c2400bc59aba4bcc0a76e971dadd19610d3ad38c768e124dc7","schema_version":"edge-lab-recorder.raw.v1","sequence":null,"source":"clob_market_ws"}
{"event_at":"2026-07-28T03:10:51.249000Z","event_fingerprint":"0a1e99d3ead665f7532032db73c06966ed923cd4f5d4a20a383d5c6787ba56b4","payload":{"connection_id":"a6b55582af5f430fb37ad02bf0922475","event_at":"2026-07-28T03:10:51.249000Z","event_type":"price_change","frame_hash":"e706bfbdf41bf833c9e1334b65ef0b6186702a3b887a79823c1d90d14b508f9b","frame_index":0,"kind":"data","monotonic_ns":310234123907875,"payload":{"event_type":"price_change","market":"0x779291bef19b6709f61e9764a954aafe9ffae488d50ae674aabdcb4f248006d5","price_changes":[{"asset_id":"8761897749749422724209054078244794145777693856614463256546737399611489089783","best_ask":"0.92","best_bid":"0.91","hash":"c875e48140148df64355e21c703376d63ff86d1e","price":"0.04","side":"BUY","size":"588.09"},{"asset_id":"14965588658799411272385430903075831224615961675357217884735713260981483529984","best_ask":"0.09","best_bid":"0.08","hash":"442d8d442f9ffbfd43a161d4c1ba367a4ce4741e","price":"0.96","side":"SELL","size":"588.09"}],"timestamp":"1785208251249"},"payload_hash":"1d2bbf33585fea98b732def8579b921ec1c5f6714241199145aa255ea8d2dd2b","raw_frame":"{\"market\":\"0x779291bef19b6709f61e9764a954aafe9ffae488d50ae674aabdcb4f248006d5\", \"price_changes\":[{\"asset_id\":\"8761897749749422724209054078244794145777693856614463256546737399611489089783\", \"price\":\"0.04\", \"size\":\"588.09\", \"side\":\"BUY\", \"hash\":\"c875e48140148df64355e21c703376d63ff86d1e\", \"best_bid\":\"0.91\", \"best_ask\":\"0.92\"}, {\"asset_id\":\"14965588658799411272385430903075831224615961675357217884735713260981483529984\", \"price\":\"0.96\", \"size\":\"588.09\", \"side\":\"SELL\", \"hash\":\"442d8d442f9ffbfd43a161d4c1ba367a4ce4741e\", \"best_bid\":\"0.08\", \"best_ask\":\"0.09\"}], \"timestamp\":\"1785208251249\", \"event_type\":\"price_change\"}","received_at":"2026-07-28T03:10:51.090149Z","schema_version":"clob-market-ws.price_change.v1","sequence":null,"server_hash":null,"server_timestamp":"1785208251249","session_id":"3e519d9098404c15b234d96025eb1a2b","source":"clob_market_ws"},"received_at":"2026-07-28T03:10:51.090149Z","record_id":"edde34f46e417d9ecc6198868882698ed5dca50594016535cf95edfeec0dc965","schema_fingerprint":"4aa3821a28b0b7c2400bc59aba4bcc0a76e971dadd19610d3ad38c768e124dc7","schema_version":"edge-lab-recorder.raw.v1","sequence":null,"source":"clob_market_ws"}
{"event_at":"2026-07-28T03:10:51.303000Z","event_fingerprint":"d296dfcc144633477a4749e7b2ac4bc4c77a46359353e551a9419d0bba4c75d8","payload":{"connection_id":"a6b55582af5f430fb37ad02bf0922475","event_at":"2026-07-28T03:10:51.303000Z","event_type":"price_change","frame_hash":"723c67932c3fc0c438033c28695421bee25118ee9352d42d697e8556ccac2cb6","frame_index":0,"kind":"data","monotonic_ns":310234173779583,"payload":{"event_type":"price_change","market":"0x779291bef19b6709f61e9764a954aafe9ffae488d50ae674aabdcb4f248006d5","price_changes":[{"asset_id":"8761897749749422724209054078244794145777693856614463256546737399611489089783","best_ask":"0.92","best_bid":"0.91","hash":"80aee4e4603704249b96ce386524f4cc0d0340fd","price":"0.91","side":"BUY","size":"193.6"},{"asset_id":"14965588658799411272385430903075831224615961675357217884735713260981483529984","best_ask":"0.09","best_bid":"0.08","hash":"420bdb54c61a8dcb80f8950cf729544aacc272a7","price":"0.09","side":"SELL","size":"193.6"}],"timestamp":"1785208251303"},"payload_hash":"fd0352a0402568c226295ed46bce6452f6d9bca2f6f631fd0345c95451552b7d","raw_frame":"{\"market\":\"0x779291bef19b6709f61e9764a954aafe9ffae488d50ae674aabdcb4f248006d5\", \"price_changes\":[{\"asset_id\":\"8761897749749422724209054078244794145777693856614463256546737399611489089783\", \"price\":\"0.91\", \"size\":\"193.6\", \"side\":\"BUY\", \"hash\":\"80aee4e4603704249b96ce386524f4cc0d0340fd\", \"best_bid\":\"0.91\", \"best_ask\":\"0.92\"}, {\"asset_id\":\"14965588658799411272385430903075831224615961675357217884735713260981483529984\", \"price\":\"0.09\", \"size\":\"193.6\", \"side\":\"SELL\", \"hash\":\"420bdb54c61a8dcb80f8950cf729544aacc272a7\", \"best_bid\":\"0.08\", \"best_ask\":\"0.09\"}], \"timestamp\":\"1785208251303\", \"event_type\":\"price_change\"}","received_at":"2026-07-28T03:10:51.140020Z","schema_version":"clob-market-ws.price_change.v1","sequence":null,"server_hash":null,"server_timestamp":"1785208251303","session_id":"3e519d9098404c15b234d96025eb1a2b","source":"clob_market_ws"},"received_at":"2026-07-28T03:10:51.140020Z","record_id":"226f9a93080ba59818ef80bfa2b8398b1c81115fd42b240a1986e492a5730aa5","schema_fingerprint":"4aa3821a28b0b7c2400bc59aba4bcc0a76e971dadd19610d3ad38c768e124dc7","schema_version":"edge-lab-recorder.raw.v1","sequence":null,"source":"clob_market_ws"}
{"event_at":"2026-07-28T03:10:51.305000Z","event_fingerprint":"2d8cb22c75f03cdc361f8cc0455999f773a9c0c1a3aab99f60d28a53ea9355d7","payload":{"connection_id":"a6b55582af5f430fb37ad02bf0922475","event_at":"2026-07-28T03:10:51.305000Z","event_type":"price_change","frame_hash":"a40a5521cf3add2a4c0af41899246f82a425c210dcbe1dc9966b94b1e3ada5d0","frame_index":0,"kind":"data","monotonic_ns":310234175358208,"payload":{"event_type":"price_change","market":"0x779291bef19b6709f61e9764a954aafe9ffae488d50ae674aabdcb4f248006d5","price_changes":[{"asset_id":"8761897749749422724209054078244794145777693856614463256546737399611489089783","best_ask":"0.92","best_bid":"0.91","hash":"69f7d381767617c2a15d62a2637e5d322d700007","price":"0.94","side":"SELL","size":"476.98"},{"asset_id":"14965588658799411272385430903075831224615961675357217884735713260981483529984","best_ask":"0.09","best_bid":"0.08","hash":"9b25f9f158a7026290d45dff16055c5740d8cdc7","price":"0.06","side":"BUY","size":"476.98"}],"timestamp":"1785208251305"},"payload_hash":"210ac2744612b62e2b4656b205717e8365a9fc21fd90db101fa280889f65d95e","raw_frame":"{\"market\":\"0x779291bef19b6709f61e9764a954aafe9ffae488d50ae674aabdcb4f248006d5\", \"price_changes\":[{\"asset_id\":\"8761897749749422724209054078244794145777693856614463256546737399611489089783\", \"price\":\"0.94\", \"size\":\"476.98\", \"side\":\"SELL\", \"hash\":\"69f7d381767617c2a15d62a2637e5d322d700007\", \"best_bid\":\"0.91\", \"best_ask\":\"0.92\"}, {\"asset_id\":\"14965588658799411272385430903075831224615961675357217884735713260981483529984\", \"price\":\"0.06\", \"size\":\"476.98\", \"side\":\"BUY\", \"hash\":\"9b25f9f158a7026290d45dff16055c5740d8cdc7\", \"best_bid\":\"0.08\", \"best_ask\":\"0.09\"}], \"timestamp\":\"1785208251305\", \"event_type\":\"price_change\"}","received_at":"2026-07-28T03:10:51.141598Z","schema_version":"clob-market-ws.price_change.v1","sequence":null,"server_hash":null,"server_timestamp":"1785208251305","session_id":"3e519d9098404c15b234d96025eb1a2b","source":"clob_market_ws"},"received_at":"2026-07-28T03:10:51.141598Z","record_id":"72cc467a08561dd13625c31e465e21e12d6338c7961f1f0ee8173a735b57895d","schema_fingerprint":"4aa3821a28b0b7c2400bc59aba4bcc0a76e971dadd19610d3ad38c768e124dc7","schema_version":"edge-lab-recorder.raw.v1","sequence":null,"source":"clob_market_ws"}
{"event_at":"2026-07-28T03:10:51.308000Z","event_fingerprint":"1a190da95a065651846893aca24909bcfe5036317ab638e70320eae70840b786","payload":{"connection_id":"a6b55582af5f430fb37ad02bf0922475","event_at":"2026-07-28T03:10:51.308000Z","event_type":"price_change","frame_hash":"a07a011c63baa4451d676e289fe565fabf36b12011f972e9e05c0a3fdb5d8d97","frame_index":0,"kind":"data","monotonic_ns":310234177112583,"payload":{"event_type":"price_change","market":"0x779291bef19b6709f61e9764a954aafe9ffae488d50ae674aabdcb4f248006d5","price_changes":[{"asset_id":"8761897749749422724209054078244794145777693856614463256546737399611489089783","best_ask":"0.92","best_bid":"0.91","hash":"0fbe73fde410c401d08a1fa9479367ab8153d80b","price":"0.91","side":"BUY","size":"181"},{"asset_id":"14965588658799411272385430903075831224615961675357217884735713260981483529984","best_ask":"0.09","best_bid":"0.08","hash":"43a973463f8b7d0504fe1f9d6f7e1e626ebacea1","price":"0.09","side":"SELL","size":"181"}],"timestamp":"1785208251308"},"payload_hash":"229bfc3960520d3f7e56a81562141169f1c8921a37be91050e4934f882961ac2","raw_frame":"{\"market\":\"0x779291bef19b6709f61e9764a954aafe9ffae488d50ae674aabdcb4f248006d5\", \"price_changes\":[{\"asset_id\":\"8761897749749422724209054078244794145777693856614463256546737399611489089783\", \"price\":\"0.91\", \"size\":\"181\", \"side\":\"BUY\", \"hash\":\"0fbe73fde410c401d08a1fa9479367ab8153d80b\", \"best_bid\":\"0.91\", \"best_ask\":\"0.92\"}, {\"asset_id\":\"14965588658799411272385430903075831224615961675357217884735713260981483529984\", \"price\":\"0.09\", \"size\":\"181\", \"side\":\"SELL\", \"hash\":\"43a973463f8b7d0504fe1f9d6f7e1e626ebacea1\", \"best_bid\":\"0.08\", \"best_ask\":\"0.09\"}], \"timestamp\":\"1785208251308\", \"event_type\":\"price_change\"}","received_at":"2026-07-28T03:10:51.143354Z","schema_version":"clob-market-ws.price_change.v1","sequence":null,"server_hash":null,"server_timestamp":"1785208251308","session_id":"3e519d9098404c15b234d96025eb1a2b","source":"clob_market_ws"},"received_at":"2026-07-28T03:10:51.143354Z","record_id":"f0ea7f3ebc1417aa4da0814a9df38b2c167117911e3665da9ea1b893ccd8a3fe","schema_fingerprint":"4aa3821a28b0b7c2400bc59aba4bcc0a76e971dadd19610d3ad38c768e124dc7","schema_version":"edge-lab-recorder.raw.v1","sequence":null,"source":"clob_market_ws"}
{"event_at":"2026-07-28T03:10:51.309000Z","event_fingerprint":"9a5b1693752470df08442803351878371e485ec87c626ff1319efffd787ea7b0","payload":{"connection_id":"a6b55582af5f430fb37ad02bf0922475","event_at":"2026-07-28T03:10:51.309000Z","event_type":"price_change","frame_hash":"13caaf7360d2af127b29ef0e0582ac37870bdf236a7e50faae54408b07051cdb","frame_index":0,"kind":"data","monotonic_ns":310234188945041,"payload":{"event_type":"price_change","market":"0x779291bef19b6709f61e9764a954aafe9ffae488d50ae674aabdcb4f248006d5","price_changes":[{"asset_id":"8761897749749422724209054078244794145777693856614463256546737399611489089783","best_ask":"0.92","best_bid":"0.91","hash":"136d678bc754c41c2509e1795fff7c277862951e","price":"0.89","side":"BUY","size":"68.64"},{"asset_id":"14965588658799411272385430903075831224615961675357217884735713260981483529984","best_ask":"0.09","best_bid":"0.08","hash":"fd60bcbacefc5cf49e9d5bea14f6ffaa63d064bb","price":"0.11","side":"SELL","size":"68.64"}],"timestamp":"1785208251309"},"payload_hash":"e80e72d434db1c9e6c8b976b426cae84377e4b1289b77b20b435d07a69f88a6c","raw_frame":"{\"market\":\"0x779291bef19b6709f61e9764a954aafe9ffae488d50ae674aabdcb4f248006d5\", \"price_changes\":[{\"asset_id\":\"8761897749749422724209054078244794145777693856614463256546737399611489089783\", \"price\":\"0.89\", \"size\":\"68.64\", \"side\":\"BUY\", \"hash\":\"136d678bc754c41c2509e1795fff7c277862951e\", \"best_bid\":\"0.91\", \"best_ask\":\"0.92\"}, {\"asset_id\":\"14965588658799411272385430903075831224615961675357217884735713260981483529984\", \"price\":\"0.11\", \"size\":\"68.64\", \"side\":\"SELL\", \"hash\":\"fd60bcbacefc5cf49e9d5bea14f6ffaa63d064bb\", \"best_bid\":\"0.08\", \"best_ask\":\"0.09\"}], \"timestamp\":\"1785208251309\", \"event_type\":\"price_change\"}","received_at":"2026-07-28T03:10:51.155185Z","schema_version":"clob-market-ws.price_change.v1","sequence":null,"server_hash":null,"server_timestamp":"1785208251309","session_id":"3e519d9098404c15b234d96025eb1a2b","source":"clob_market_ws"},"received_at":"2026-07-28T03:10:51.155185Z","record_id":"f0e92bd4514eb5bafa820e9df2691912fa06217411de96c0afe00d1d549434da","schema_fingerprint":"4aa3821a28b0b7c2400bc59aba4bcc0a76e971dadd19610d3ad38c768e124dc7","schema_version":"edge-lab-recorder.raw.v1","sequence":null,"source":"clob_market_ws"}
{"event_at":"2026-07-28T03:10:51.329000Z","event_fingerprint":"2b5651f6d70ee74344d6d257a8d7c1f07fa984003468a477491cea399115c3ae","payload":{"connection_id":"a6b55582af5f430fb37ad02bf0922475","event_at":"2026-07-28T03:10:51.329000Z","event_type":"price_change","frame_hash":"76f28b880d44834d241ccd878966fa6863f9c955bbd7c1a5bd490e0b631ba2dc","frame_index":0,"kind":"data","monotonic_ns":310234211228416,"payload":{"event_type":"price_change","market":"0x779291bef19b6709f61e9764a954aafe9ffae488d50ae674aabdcb4f248006d5","price_changes":[{"asset_id":"8761897749749422724209054078244794145777693856614463256546737399611489089783","best_ask":"0.92","best_bid":"0.91","hash":"0ac9a646f34ad50b94f94086e7671f43ae293282","price":"0.93","side":"SELL","size":"57"},{"asset_id":"14965588658799411272385430903075831224615961675357217884735713260981483529984","best_ask":"0.09","best_bid":"0.08","hash":"23e8b24c006cdd45053e46c194fe8ac5e642dfff","price":"0.07","side":"BUY","size":"57"}],"timestamp":"1785208251329"},"payload_hash":"aeba25140924ce80ea3e1308f04b975622553c01b87401a10c6b742677216a08","raw_frame":"{\"market\":\"0x779291bef19b6709f61e9764a954aafe9ffae488d50ae674aabdcb4f248006d5\", \"price_changes\":[{\"asset_id\":\"8761897749749422724209054078244794145777693856614463256546737399611489089783\", \"price\":\"0.93\", \"size\":\"57\", \"side\":\"SELL\", \"hash\":\"0ac9a646f34ad50b94f94086e7671f43ae293282\", \"best_bid\":\"0.91\", \"best_ask\":\"0.92\"}, {\"asset_id\":\"14965588658799411272385430903075831224615961675357217884735713260981483529984\", \"price\":\"0.07\", \"size\":\"57\", \"side\":\"BUY\", \"hash\":\"23e8b24c006cdd45053e46c194fe8ac5e642dfff\", \"best_bid\":\"0.08\", \"best_ask\":\"0.09\"}], \"timestamp\":\"1785208251329\", \"event_type\":\"price_change\"}","received_at":"2026-07-28T03:10:51.177467Z","schema_version":"clob-market-ws.price_change.v1","sequence":null,"server_hash":null,"server_timestamp":"1785208251329","session_id":"3e519d9098404c15b234d96025eb1a2b","source":"clob_market_ws"},"received_at":"2026-07-28T03:10:51.177467Z","record_id":"f085bf0c0e5fdf02b095327b3d2955a32add520ccfc730738e41f40e072401a1","schema_fingerprint":"4aa3821a28b0b7c2400bc59aba4bcc0a76e971dadd19610d3ad38c768e124dc7","schema_version":"edge-lab-recorder.raw.v1","sequence":null,"source":"clob_market_ws"}
{"event_at":"2026-07-28T03:10:51.335000Z","event_fingerprint":"0dfaf5f578e3e35931883e417b2ad4a39b1385c51dfd43feb376721bfdea93b6","payload":{"connection_id":"a6b55582af5f430fb37ad02bf0922475","event_at":"2026-07-28T03:10:51.335000Z","event_type":"price_change","frame_hash":"da78f0b49f1785d9f9957fc5d98a257806e9d4087e6117d69b88f40b933226c3","frame_index":0,"kind":"data","monotonic_ns":310234212992541,"payload":{"event_type":"price_change","market":"0x779291bef19b6709f61e9764a954aafe9ffae488d50ae674aabdcb4f248006d5","price_changes":[{"asset_id":"14965588658799411272385430903075831224615961675357217884735713260981483529984","best_ask":"0.09","best_bid":"0.08","hash":"a6caddff5dabe1b7bce0f72fe45ecfd837c4a104","price":"0.06","side":"BUY","size":"451.98"},{"asset_id":"8761897749749422724209054078244794145777693856614463256546737399611489089783","best_ask":"0.92","best_bid":"0.91","hash":"0d2f1a0a1ca1d25b1136d672fc1f4411012bd2bf","price":"0.94","side":"SELL","size":"451.98"}],"timestamp":"1785208251335"},"payload_hash":"93e60e9d2cd0346eb544eaf524a692f1e27179a604b47131521ab11212690500","raw_frame":"{\"market\":\"0x779291bef19b6709f61e9764a954aafe9ffae488d50ae674aabdcb4f248006d5\", \"price_changes\":[{\"asset_id\":\"14965588658799411272385430903075831224615961675357217884735713260981483529984\", \"price\":\"0.06\", \"size\":\"451.98\", \"side\":\"BUY\", \"hash\":\"a6caddff5dabe1b7bce0f72fe45ecfd837c4a104\", \"best_bid\":\"0.08\", \"best_ask\":\"0.09\"}, {\"asset_id\":\"8761897749749422724209054078244794145777693856614463256546737399611489089783\", \"price\":\"0.94\", \"size\":\"451.98\", \"side\":\"SELL\", \"hash\":\"0d2f1a0a1ca1d25b1136d672fc1f4411012bd2bf\", \"best_bid\":\"0.91\", \"best_ask\":\"0.92\"}], \"timestamp\":\"1785208251335\", \"event_type\":\"price_change\"}","received_at":"2026-07-28T03:10:51.179233Z","schema_version":"clob-market-ws.price_change.v1","sequence":null,"server_hash":null,"server_timestamp":"1785208251335","session_id":"3e519d9098404c15b234d96025eb1a2b","source":"clob_market_ws"},"received_at":"2026-07-28T03:10:51.179233Z","record_id":"fccb1ad1bfb9ab7f10750ff1db2ab5f5db30060f1688a5e2a92fa62f3863d725","schema_fingerprint":"4aa3821a28b0b7c2400bc59aba4bcc0a76e971dadd19610d3ad38c768e124dc7","schema_version":"edge-lab-recorder.raw.v1","sequence":null,"source":"clob_market_ws"}
{"event_at":"2026-07-28T03:10:51.337000Z","event_fingerprint":"5fa0bd793ad0b77433c6965ba8c210c6d798d5c297c1923ccd9d3e3bb84a708d","payload":{"connection_id":"a6b55582af5f430fb37ad02bf0922475","event_at":"2026-07-28T03:10:51.337000Z","event_type":"price_change","frame_hash":"db9b4547e74ed6cef92e9debeebafaff2921dd8f8bedd1b1dc1c85c938855db3","frame_index":0,"kind":"data","monotonic_ns":310234214613958,"payload":{"event_type":"price_change","market":"0x779291bef19b6709f61e9764a954aafe9ffae488d50ae674aabdcb4f248006d5","price_changes":[{"asset_id":"8761897749749422724209054078244794145777693856614463256546737399611489089783","best_ask":"0.92","best_bid":"0.91","hash":"e831352d5022acdc2cda284bef549673b857c16b","price":"0.85","side":"BUY","size":"186.54"},{"asset_id":"14965588658799411272385430903075831224615961675357217884735713260981483529984","best_ask":"0.09","best_bid":"0.08","hash":"00240a9d9a477b9a15444f72e9d633fac45ecb48","price":"0.15","side":"SELL","size":"186.54"}],"timestamp":"1785208251337"},"payload_hash":"0e948c2290c64e44199668551f68b3645b4a285742986f65948c07a1933824a1","raw_frame":"{\"market\":\"0x779291bef19b6709f61e9764a954aafe9ffae488d50ae674aabdcb4f248006d5\", \"price_changes\":[{\"asset_id\":\"8761897749749422724209054078244794145777693856614463256546737399611489089783\", \"price\":\"0.85\", \"size\":\"186.54\", \"side\":\"BUY\", \"hash\":\"e831352d5022acdc2cda284bef549673b857c16b\", \"best_bid\":\"0.91\", \"best_ask\":\"0.92\"}, {\"asset_id\":\"14965588658799411272385430903075831224615961675357217884735713260981483529984\", \"price\":\"0.15\", \"size\":\"186.54\", \"side\":\"SELL\", \"hash\":\"00240a9d9a477b9a15444f72e9d633fac45ecb48\", \"best_bid\":\"0.08\", \"best_ask\":\"0.09\"}], \"timestamp\":\"1785208251337\", \"event_type\":\"price_change\"}","received_at":"2026-07-28T03:10:51.180853Z","schema_version":"clob-market-ws.price_change.v1","sequence":null,"server_hash":null,"server_timestamp":"1785208251337","session_id":"3e519d9098404c15b234d96025eb1a2b","source":"clob_market_ws"},"received_at":"2026-07-28T03:10:51.180853Z","record_id":"1b29d2ed0b1e9bf07249acf53926421781304601914f7cfc6ccd8b28377b9cdc","schema_fingerprint":"4aa3821a28b0b7c2400bc59aba4bcc0a76e971dadd19610d3ad38c768e124dc7","schema_version":"edge-lab-recorder.raw.v1","sequence":null,"source":"clob_market_ws"}
{"event_at":"2026-07-28T03:10:51.351000Z","event_fingerprint":"024abbf002c8ffcadb9711f8f3c55b6ba3cedee756a52f4c0e6323759709be59","payload":{"connection_id":"a6b55582af5f430fb37ad02bf0922475","event_at":"2026-07-28T03:10:51.351000Z","event_type":"price_change","frame_hash":"cdee2215054d349eb281bf7b614b672b3d0ff5e849e47bebdd43895118d5b6f2","frame_index":0,"kind":"data","monotonic_ns":310234221061083,"payload":{"event_type":"price_change","market":"0x779291bef19b6709f61e9764a954aafe9ffae488d50ae674aabdcb4f248006d5","price_changes":[{"asset_id":"8761897749749422724209054078244794145777693856614463256546737399611489089783","best_ask":"0.92","best_bid":"0.91","hash":"d48c6bca491d47d597f78e35ac0be1f5d193e645","price":"0.81","side":"BUY","size":"210.18"},{"asset_id":"14965588658799411272385430903075831224615961675357217884735713260981483529984","best_ask":"0.09","best_bid":"0.08","hash":"6baeac47fca7c5984d3441f1421f27811b5a2caf","price":"0.19","side":"SELL","size":"210.18"}],"timestamp":"1785208251351"},"payload_hash":"5d3d14e3267d5be7826d9551e0c716a2f4544e0d8a9000d39fac98e1feb742ef","raw_frame":"{\"market\":\"0x779291bef19b6709f61e9764a954aafe9ffae488d50ae674aabdcb4f248006d5\", \"price_changes\":[{\"asset_id\":\"8761897749749422724209054078244794145777693856614463256546737399611489089783\", \"price\":\"0.81\", \"size\":\"210.18\", \"side\":\"BUY\", \"hash\":\"d48c6bca491d47d597f78e35ac0be1f5d193e645\", \"best_bid\":\"0.91\", \"best_ask\":\"0.92\"}, {\"asset_id\":\"14965588658799411272385430903075831224615961675357217884735713260981483529984\", \"price\":\"0.19\", \"size\":\"210.18\", \"side\":\"SELL\", \"hash\":\"6baeac47fca7c5984d3441f1421f27811b5a2caf\", \"best_bid\":\"0.08\", \"best_ask\":\"0.09\"}], \"timestamp\":\"1785208251351\", \"event_type\":\"price_change\"}","received_at":"2026-07-28T03:10:51.187301Z","schema_version":"clob-market-ws.price_change.v1","sequence":null,"server_hash":null,"server_timestamp":"1785208251351","session_id":"3e519d9098404c15b234d96025eb1a2b","source":"clob_market_ws"},"received_at":"2026-07-28T03:10:51.187301Z","record_id":"6b55e7cae6d5743084e6910e68df29ac63c2008a3e8df68661307344642cc4b2","schema_fingerprint":"4aa3821a28b0b7c2400bc59aba4bcc0a76e971dadd19610d3ad38c768e124dc7","schema_version":"edge-lab-recorder.raw.v1","sequence":null,"source":"clob_market_ws"}
{"event_at":"2026-07-28T03:10:51.357000Z","event_fingerprint":"7407441691babd43b54df7204ed8c2b649c7920e0edbf49ac0c4429d0f4c8df7","payload":{"connection_id":"a6b55582af5f430fb37ad02bf0922475","event_at":"2026-07-28T03:10:51.357000Z","event_type":"price_change","frame_hash":"e5f673eaa8d46325d0d3ef6164188960f3983af89bfc18c3e04bb5c68648bc8e","frame_index":0,"kind":"data","monotonic_ns":310234233404416,"payload":{"event_type":"price_change","market":"0x779291bef19b6709f61e9764a954aafe9ffae488d50ae674aabdcb4f248006d5","price_changes":[{"asset_id":"8761897749749422724209054078244794145777693856614463256546737399611489089783","best_ask":"0.92","best_bid":"0.91","hash":"92dc6e58db1548f54c0ed62662ef3655297b0b3f","price":"0.88","side":"BUY","size":"99.2"},{"asset_id":"14965588658799411272385430903075831224615961675357217884735713260981483529984","best_ask":"0.09","best_bid":"0.08","hash":"df3ef464b73c41b68bab52fffdedeb48042b6b63","price":"0.12","side":"SELL","size":"99.2"}],"timestamp":"1785208251357"},"payload_hash":"af7c29fb4864900ae961161011b76421b064215d7969ddf6e9a862b70f837ffd","raw_frame":"{\"market\":\"0x779291bef19b6709f61e9764a954aafe9ffae488d50ae674aabdcb4f248006d5\", \"price_changes\":[{\"asset_id\":\"8761897749749422724209054078244794145777693856614463256546737399611489089783\", \"price\":\"0.88\", \"size\":\"99.2\", \"side\":\"BUY\", \"hash\":\"92dc6e58db1548f54c0ed62662ef3655297b0b3f\", \"best_bid\":\"0.91\", \"best_ask\":\"0.92\"}, {\"asset_id\":\"14965588658799411272385430903075831224615961675357217884735713260981483529984\", \"price\":\"0.12\", \"size\":\"99.2\", \"side\":\"SELL\", \"hash\":\"df3ef464b73c41b68bab52fffdedeb48042b6b63\", \"best_bid\":\"0.08\", \"best_ask\":\"0.09\"}], \"timestamp\":\"1785208251357\", \"event_type\":\"price_change\"}","received_at":"2026-07-28T03:10:51.199645Z","schema_version":"clob-market-ws.price_change.v1","sequence":null,"server_hash":null,"server_timestamp":"1785208251357","session_id":"3e519d9098404c15b234d96025eb1a2b","source":"clob_market_ws"},"received_at":"2026-07-28T03:10:51.199645Z","record_id":"eecc9028d4ce34275553d86a2925dc05ba55180174a73ec5e88fe23547bc8319","schema_fingerprint":"4aa3821a28b0b7c2400bc59aba4bcc0a76e971dadd19610d3ad38c768e124dc7","schema_version":"edge-lab-recorder.raw.v1","sequence":null,"source":"clob_market_ws"}
{"event_at":"2026-07-28T03:10:51.370000Z","event_fingerprint":"ce057887df3885d4c1126ada86ba9e925da4d269a7623de7c95ef9534298633b","payload":{"connection_id":"a6b55582af5f430fb37ad02bf0922475","event_at":"2026-07-28T03:10:51.370000Z","event_type":"price_change","frame_hash":"c199e26b54605be75d8807020818acd4602b4450a883692bda173a23c44b8577","frame_index":0,"kind":"data","monotonic_ns":310234237733125,"payload":{"event_type":"price_change","market":"0x779291bef19b6709f61e9764a954aafe9ffae488d50ae674aabdcb4f248006d5","price_changes":[{"asset_id":"14965588658799411272385430903075831224615961675357217884735713260981483529984","best_ask":"0.09","best_bid":"0.08","hash":"4d1db83c5611146684b1a9194122e9782c8f4d36","price":"0.07","side":"BUY","size":"82"},{"asset_id":"8761897749749422724209054078244794145777693856614463256546737399611489089783","best_ask":"0.92","best_bid":"0.91","hash":"48ce6861fc277968ca7c820bdefd14e8674ee720","price":"0.93","side":"SELL","size":"82"}],"timestamp":"1785208251370"},"payload_hash":"bafd2649ebe4dfa1dd4a8ddf5b38baa08e8520945bfd4c511ca959ab5081afc7","raw_frame":"{\"market\":\"0x779291bef19b6709f61e9764a954aafe9ffae488d50ae674aabdcb4f248006d5\", \"price_changes\":[{\"asset_id\":\"14965588658799411272385430903075831224615961675357217884735713260981483529984\", \"price\":\"0.07\", \"size\":\"82\", \"side\":\"BUY\", \"hash\":\"4d1db83c5611146684b1a9194122e9782c8f4d36\", \"best_bid\":\"0.08\", \"best_ask\":\"0.09\"}, {\"asset_id\":\"8761897749749422724209054078244794145777693856614463256546737399611489089783\", \"price\":\"0.93\", \"size\":\"82\", \"side\":\"SELL\", \"hash\":\"48ce6861fc277968ca7c820bdefd14e8674ee720\", \"best_bid\":\"0.91\", \"best_ask\":\"0.92\"}], \"timestamp\":\"1785208251370\", \"event_type\":\"price_change\"}","received_at":"2026-07-28T03:10:51.203973Z","schema_version":"clob-market-ws.price_change.v1","sequence":null,"server_hash":null,"server_timestamp":"1785208251370","session_id":"3e519d9098404c15b234d96025eb1a2b","source":"clob_market_ws"},"received_at":"2026-07-28T03:10:51.203973Z","record_id":"9805c0a37edc3d80afb80b69fe024e9a52b14ce59f01b903ef5bb85219d84e32","schema_fingerprint":"4aa3821a28b0b7c2400bc59aba4bcc0a76e971dadd19610d3ad38c768e124dc7","schema_version":"edge-lab-recorder.raw.v1","sequence":null,"source":"clob_market_ws"}
{"event_at":"2026-07-28T03:10:51.404000Z","event_fingerprint":"e2e8db9451e2ba00049395f6105d7cde09e0404338388cb57e2ed992a339f55a","payload":{"connection_id":"a6b55582af5f430fb37ad02bf0922475","event_at":"2026-07-28T03:10:51.404000Z","event_type":"price_change","frame_hash":"f712e3de24e856074c7450cdbce3d18f996de3903293738fe95d5a6f4f2d74e3","frame_index":0,"kind":"data","monotonic_ns":310234290866166,"payload":{"event_type":"price_change","market":"0x779291bef19b6709f61e9764a954aafe9ffae488d50ae674aabdcb4f248006d5","price_changes":[{"asset_id":"8761897749749422724209054078244794145777693856614463256546737399611489089783","best_ask":"0.92","best_bid":"0.91","hash":"dcdd5d63f366f62361ff2a31d6c5588f878aec0c","price":"0.86","side":"BUY","size":"205"},{"asset_id":"14965588658799411272385430903075831224615961675357217884735713260981483529984","best_ask":"0.09","best_bid":"0.08","hash":"372c51e5c2f580ac6ffaeae60bc8b3551a49f546","price":"0.14","side":"SELL","size":"205"}],"timestamp":"1785208251404"},"payload_hash":"84158efa99eeeb88ca981d94ae8a1065ac821015a4a1e9daabc8c9f734176b2f","raw_frame":"{\"market\":\"0x779291bef19b6709f61e9764a954aafe9ffae488d50ae674aabdcb4f248006d5\", \"price_changes\":[{\"asset_id\":\"8761897749749422724209054078244794145777693856614463256546737399611489089783\", \"price\":\"0.86\", \"size\":\"205\", \"side\":\"BUY\", \"hash\":\"dcdd5d63f366f62361ff2a31d6c5588f878aec0c\", \"best_bid\":\"0.91\", \"best_ask\":\"0.92\"}, {\"asset_id\":\"14965588658799411272385430903075831224615961675357217884735713260981483529984\", \"price\":\"0.14\", \"size\":\"205\", \"side\":\"SELL\", \"hash\":\"372c51e5c2f580ac6ffaeae60bc8b3551a49f546\", \"best_bid\":\"0.08\", \"best_ask\":\"0.09\"}], \"timestamp\":\"1785208251404\", \"event_type\":\"price_change\"}","received_at":"2026-07-28T03:10:51.257105Z","schema_version":"clob-market-ws.price_change.v1","sequence":null,"server_hash":null,"server_timestamp":"1785208251404","session_id":"3e519d9098404c15b234d96025eb1a2b","source":"clob_market_ws"},"received_at":"2026-07-28T03:10:51.257105Z","record_id":"ea04c290180cbafff7b5bc35ad40d253eb15d86571dccfaffa772aff607d35be","schema_fingerprint":"4aa3821a28b0b7c2400bc59aba4bcc0a76e971dadd19610d3ad38c768e124dc7","schema_version":"edge-lab-recorder.raw.v1","sequence":null,"source":"clob_market_ws"}
