{"event_at":"2026-07-28T03:00:26.044000Z","event_fingerprint":"845618f3c8c9cf480dd4dfe55b790ad2c3914122b3a87daade883265c6347f51","payload":{"connection_id":"a6b55582af5f430fb37ad02bf0922475","event_at":"2026-07-28T03:00:26.044000Z","event_type":"price_change","frame_hash":"556dbaa28f40aa64bcc5502e97a0a3253d2350121a3cdd3bb04c4660c23c521c","frame_index":0,"kind":"data","monotonic_ns":309611933875541,"payload":{"event_type":"price_change","market":"0x779291bef19b6709f61e9764a954aafe9ffae488d50ae674aabdcb4f248006d5","price_changes":[{"asset_id":"14965588658799411272385430903075831224615961675357217884735713260981483529984","best_ask":"0.6","best_bid":"0.59","hash":"91262f0785effb3b02e6dbad65cb3e15395a645d","price":"0.45","side":"BUY","size":"273.21"},{"asset_id":"8761897749749422724209054078244794145777693856614463256546737399611489089783","best_ask":"0.41","best_bid":"0.4","hash":"336b5f862b29eca0bcc5765704de2f53a55ee2a2","price":"0.55","side":"SELL","size":"273.21"}],"timestamp":"1785207626044"},"payload_hash":"f19a1476fae1b5d85b9da6836acd778ceb7c708ff7e5c291f55a5a0ea9f0e79f","raw_frame":"{\"market\":\"0x779291bef19b6709f61e9764a954aafe9ffae488d50ae674aabdcb4f248006d5\", \"price_changes\":[{\"asset_id\":\"14965588658799411272385430903075831224615961675357217884735713260981483529984\", \"price\":\"0.45\", \"size\":\"273.21\", \"side\":\"BUY\", \"hash\":\"91262f0785effb3b02e6dbad65cb3e15395a645d\", \"best_bid\":\"0.59\", \"best_ask\":\"0.6\"}, {\"asset_id\":\"8761897749749422724209054078244794145777693856614463256546737399611489089783\", \"price\":\"0.55\", \"size\":\"273.21\", \"side\":\"SELL\", \"hash\":\"336b5f862b29eca0bcc5765704de2f53a55ee2a2\", \"best_bid\":\"0.4\", \"best_ask\":\"0.41\"}], \"timestamp\":\"1785207626044\", \"event_type\":\"price_change\"}","received_at":"2026-07-28T03:00:28.915302Z","schema_version":"clob-market-ws.price_change.v1","sequence":null,"server_hash":null,"server_timestamp":"1785207626044","session_id":"3e519d9098404c15b234d96025eb1a2b","source":"clob_market_ws"},"received_at":"2026-07-28T03:00:28.915302Z","record_id":"bcf2982574296f04ec3726295ab2521694bbbe919ee214c94c94562f0004c875","schema_fingerprint":"4aa3821a28b0b7c2400bc59aba4bcc0a76e971dadd19610d3ad38c768e124dc7","schema_version":"edge-lab-recorder.raw.v1","sequence":null,"source":"clob_market_ws"}
{"event_at":"2026-07-28T03:00:26.048000Z","event_fingerprint":"6fc56bd390bd47e38bfae76ac72ebfb010a1d04508805963346f56f8f3118ce5","payload":{"connection_id":"a6b55582af5f430fb37ad02bf0922475","event_at":"2026-07-28T03:00:26.048000Z","event_type":"price_change","frame_hash":"d982835ab2ec083dd13c534d67a8cb0aeabc47928778e27d56ee784411f4a50d","frame_index":0,"kind":"data","monotonic_ns":309611945891916,"payload":{"event_type":"price_change","market":"0x779291bef19b6709f61e9764a954aafe9ffae488d50ae674aabdcb4f248006d5","price_changes":[{"asset_id":"14965588658799411272385430903075831224615961675357217884735713260981483529984","best_ask":"0.6","best_bid":"0.59","hash":"a4c885e003a0d17431c2ffc3283622fb45e89f77","price":"0.56","side":"BUY","size":"103.32"},{"asset_id":"8761897749749422724209054078244794145777693856614463256546737399611489089783","best_ask":"0.41","best_bid":"0.4","hash":"403b3e008d0b957ff65aafbc990c5b5e5d6ef550","price":"0.44","side":"SELL","size":"103.32"}],"timestamp":"1785207626048"},"payload_hash":"9f6f13dc7dbff4a69fefd6fd8edb73de1f2445c63f7c861ee36c7bb2c9b9a987","raw_frame":"{\"market\":\"0x779291bef19b6709f61e9764a954aafe9ffae488d50ae674aabdcb4f248006d5\", \"price_changes\":[{\"asset_id\":\"14965588658799411272385430903075831224615961675357217884735713260981483529984\", \"price\":\"0.56\", \"size\":\"103.32\", \"side\":\"BUY\", \"hash\":\"a4c885e003a0d17431c2ffc3283622fb45e89f77\", \"best_bid\":\"0.59\", \"best_ask\":\"0.6\"}, {\"asset_id\":\"8761897749749422724209054078244794145777693856614463256546737399611489089783\", \"price\":\"0.44\", \"size\":\"103.32\", \"side\":\"SELL\", \"hash\":\"403b3e008d0b957ff65aafbc990c5b5e5d6ef550\", \"best_bid\":\"0.4\", \"best_ask\":\"0.41\"}], \"timestamp\":\"1785207626048\", \"event_type\":\"price_change\"}","received_at":"2026-07-28T03:00:28.927320Z","schema_version":"clob-market-ws.price_change.v1","sequence":null,"server_hash":null,"server_timestamp":"1785207626048","session_id":"3e519d9098404c15b234d96025eb1a2b","source":"clob_market_ws"},"received_at":"2026-07-28T03:00:28.927320Z","record_id":"68a84c9ac80d8ebc3cd8c6032d24071026c77b0eef247e81873b5638b37f27d3","schema_fingerprint":"4aa3821a28b0b7c2400bc59aba4bcc0a76e971dadd19610d3ad38c768e124dc7","schema_version":"edge-lab-recorder.raw.v1","sequence":null,"source":"clob_market_ws"}
{"event_at":"2026-07-28T03:00:26.050000Z","event_fingerprint":"d793de350b33fc39e6663c305b0a454b732130e5665b1422f82d5f384ab7cad8","payload":{"connection_id":"a6b55582af5f430fb37ad02bf0922475","event_at":"2026-07-28T03:00:26.050000Z","event_type":"price_change","frame_hash":"11bfeb54de95311a4639f4fa1a7d9cb406445e9d5ed47cc929c5496a47d1b7d7","frame_index":0,"kind":"data","monotonic_ns":309611950919000,"payload":{"event_type":"price_change","market":"0x779291bef19b6709f61e9764a954aafe9ffae488d50ae674aabdcb4f248006d5","price_changes":[{"asset_id":"14965588658799411272385430903075831224615961675357217884735713260981483529984","best_ask":"0.6","best_bid":"0.59","hash":"4a0794201833a0dce00231ca855c89ed7bd9811b","price":"0.54","side":"BUY","size":"180.6"},{"asset_id":"8761897749749422724209054078244794145777693856614463256546737399611489089783","best_ask":"0.41","best_bid":"0.4","hash":"295a32e781c5be2b984f08bd27172456748c686c","price":"0.46","side":"SELL","size":"180.6"}],"timestamp":"1785207626050"},"payload_hash":"8bccfc7a5c5cd595801a6ae2f464440e010f76a6de1022b57317cc9f9d6db350","raw_frame":"{\"market\":\"0x779291bef19b6709f61e9764a954aafe9ffae488d50ae674aabdcb4f248006d5\", \"price_changes\":[{\"asset_id\":\"14965588658799411272385430903075831224615961675357217884735713260981483529984\", \"price\":\"0.54\", \"size\":\"180.6\", \"side\":\"BUY\", \"hash\":\"4a0794201833a0dce00231ca855c89ed7bd9811b\", \"best_bid\":\"0.59\", \"best_ask\":\"0.6\"}, {\"asset_id\":\"8761897749749422724209054078244794145777693856614463256546737399611489089783\", \"price\":\"0.46\", \"size\":\"180.6\", \"side\":\"SELL\", \"hash\":\"295a32e781c5be2b984f08bd27172456748c686c\", \"best_bid\":\"0.4\", \"best_ask\":\"0.41\"}], \"timestamp\":\"1785207626050\", \"event_type\":\"price_change\"}","received_at":"2026-07-28T03:00:28.932346Z","schema_version":"clob-market-ws.price_change.v1","sequence":null,"server_hash":null,"server_timestamp":"1785207626050","session_id":"3e519d9098404c15b234d96025eb1a2b","source":"clob_market_ws"},"received_at":"2026-07-28T03:00:28.932346Z","record_id":"1c4bbb293904f75f3304bfb549d5d41e61495c2434da793f10b5712c909c5c38","schema_fingerprint":"4aa3821a28b0b7c2400bc59aba4bcc0a76e971dadd19610d3ad38c768e124dc7","schema_version":"edge-lab-recorder.raw.v1","sequence":null,"source":"clob_market_ws"}
{"event_at":"2026-07-28T03:00:26.053000Z","event_fingerprint":"6889595148ed009b481eed11cca0642506feb64a1dbc1a56877b94fc0661614c","payload":{"connection_id":"a6b55582af5f430fb37ad02bf0922475","event_at":"2026-07-28T03:00:26.053000Z","event_type":"price_change","frame_hash":"5729d082e3ff4b3facdd10ffd1e0af7ec013673d569e1c514fd51ce4cb0a5bc2","frame_index":0,"kind":"data","monotonic_ns":309611955381416,"payload":{"event_type":"price_change","market":"0x779291bef19b6709f61e9764a954aafe9ffae488d50ae674aabdcb4f248006d5","price_changes":[{"asset_id":"14965588658799411272385430903075831224615961675357217884735713260981483529984","best_ask":"0.6","best_bid":"0.59","hash":"b561567419b8e81ae4cd72ea785c7336113e3353","price":"0.57","side":"BUY","size":"110.5"},{"asset_id":"8761897749749422724209054078244794145777693856614463256546737399611489089783","best_ask":"0.41","best_bid":"0.4","hash":"caf0908552ed65e0281d18c1e9fee9520e0c9c13","price":"0.43","side":"SELL","size":"110.5"}],"timestamp":"1785207626053"},"payload_hash":"116aded9aff0a2608a1c9067a2111d5b2d16531fa8699964316d7df0a3a9953d","raw_frame":"{\"market\":\"0x779291bef19b6709f61e9764a954aafe9ffae488d50ae674aabdcb4f248006d5\", \"price_changes\":[{\"asset_id\":\"14965588658799411272385430903075831224615961675357217884735713260981483529984\", \"price\":\"0.57\", \"size\":\"110.5\", \"side\":\"BUY\", \"hash\":\"b561567419b8e81ae4cd72ea785c7336113e3353\", \"best_bid\":\"0.59\", \"best_ask\":\"0.6\"}, {\"asset_id\":\"8761897749749422724209054078244794145777693856614463256546737399611489089783\", \"price\":\"0.43\", \"size\":\"110.5\", \"side\":\"SELL\", \"hash\":\"caf0908552ed65e0281d18c1e9fee9520e0c9c13\", \"best_bid\":\"0.4\", \"best_ask\":\"0.41\"}], \"timestamp\":\"1785207626053\", \"event_type\":\"price_change\"}","received_at":"2026-07-28T03:00:28.936810Z","schema_version":"clob-market-ws.price_change.v1","sequence":null,"server_hash":null,"server_timestamp":"1785207626053","session_id":"3e519d9098404c15b234d96025eb1a2b","source":"clob_market_ws"},"received_at":"2026-07-28T03:00:28.936810Z","record_id":"64b99a8829e91a3572339d39e2fa0dbf21fce21b008fe3d3391f9d7fcd3f15c6","schema_fingerprint":"4aa3821a28b0b7c2400bc59aba4bcc0a76e971dadd19610d3ad38c768e124dc7","schema_version":"edge-lab-recorder.raw.v1","sequence":null,"source":"clob_market_ws"}
{"event_at":"2026-07-28T03:00:26.056000Z","event_fingerprint":"0a163fae2b4516482c39118883dd92a4d9dcf56828d40da4cc1d2fa930bc2699","payload":{"connection_id":"a6b55582af5f430fb37ad02bf0922475","event_at":"2026-07-28T03:00:26.056000Z","event_type":"price_change","frame_hash":"86aabf895f80a4549b77e1e31aaf3e477f67d48e5cde952287f5550e94aeb208","frame_index":0,"kind":"data","monotonic_ns":309611962846958,"payload":{"event_type":"price_change","market":"0x779291bef19b6709f61e9764a954aafe9ffae488d50ae674aabdcb4f248006d5","price_changes":[{"asset_id":"8761897749749422724209054078244794145777693856614463256546737399611489089783","best_ask":"0.41","best_bid":"0.4","hash":"43c344cbd7e7abae84db20a3c1f656eabe8b5b5c","price":"0.38","side":"BUY","size":"388.6"},{"asset_id":"14965588658799411272385430903075831224615961675357217884735713260981483529984","best_ask":"0.6","best_bid":"0.59","hash":"298fc3f2128b6351ef3472044f85e234b47a6a34","price":"0.62","side":"SELL","size":"388.6"}],"timestamp":"1785207626056"},"payload_hash":"05ccbf0c403ed816f11115ee8b68e2e833a97af45316290045585cca40c7a98a","raw_frame":"{\"market\":\"0x779291bef19b6709f61e9764a954aafe9ffae488d50ae674aabdcb4f248006d5\", \"price_changes\":[{\"asset_id\":\"8761897749749422724209054078244794145777693856614463256546737399611489089783\", \"price\":\"0.38\", \"size\":\"388.6\", \"side\":\"BUY\", \"hash\":\"43c344cbd7e7abae84db20a3c1f656eabe8b5b5c\", \"best_bid\":\"0.4\", \"best_ask\":\"0.41\"}, {\"asset_id\":\"14965588658799411272385430903075831224615961675357217884735713260981483529984\", \"price\":\"0.62\", \"size\":\"388.6\", \"side\":\"SELL\", \"hash\":\"298fc3f2128b6351ef3472044f85e234b47a6a34\", \"best_bid\":\"0.59\", \"best_ask\":\"0.6\"}], \"timestamp\":\"1785207626056\", \"event_type\":\"price_change\"}","received_at":"2026-07-28T03:00:28.944275Z","schema_version":"clob-market-ws.price_change.v1","sequence":null,"server_hash":null,"server_timestamp":"1785207626056","session_id":"3e519d9098404c15b234d96025eb1a2b","source":"clob_market_ws"},"received_at":"2026-07-28T03:00:28.944275Z","record_id":"17c8de7d8c380283e9300ebf4756f0f095e708e7643e455944bbddb2361e76fd","schema_fingerprint":"4aa3821a28b0b7c2400bc59aba4bcc0a76e971dadd19610d3ad38c768e124dc7","schema_version":"edge-lab-recorder.raw.v1","sequence":null,"source":"clob_market_ws"}
{"event_at":"2026-07-28T03:00:26.067000Z","event_fingerprint":"4f59e598f06269a81100dbd19164e035c25547951f7e387a9b8d2d53c0010d7f","payload":{"connection_id":"a6b55582af5f430fb37ad02bf0922475","event_at":"2026-07-28T03:00:26.067000Z","event_type":"price_change","frame_hash":"6d5ec0e0851cd0b9b6434301d6759b943dede10a7b2d02e2e17f8d420c32e99c","frame_index":0,"kind":"data","monotonic_ns":309611970914791,"payload":{"event_type":"price_change","market":"0x779291bef19b6709f61e9764a954aafe9ffae488d50ae674aabdcb4f248006d5","price_changes":[{"asset_id":"14965588658799411272385430903075831224615961675357217884735713260981483529984","best_ask":"0.6","best_bid":"0.59","hash":"d422b7da222c10d3ddf2b8e3cc222d86e0530581","price":"0.47","side":"BUY","size":"140"},{"asset_id":"8761897749749422724209054078244794145777693856614463256546737399611489089783","best_ask":"0.41","best_bid":"0.4","hash":"fd330fd79d9f21aa09cb451c9cfc8def56e83178","price":"0.53","side":"SELL","size":"140"}],"timestamp":"1785207626067"},"payload_hash":"12277930b4f9acbb6366f5b1cd2193c5e064c583b2b860d0b125bfc79742bad7","raw_frame":"{\"market\":\"0x779291bef19b6709f61e9764a954aafe9ffae488d50ae674aabdcb4f248006d5\", \"price_changes\":[{\"asset_id\":\"14965588658799411272385430903075831224615961675357217884735713260981483529984\", \"price\":\"0.47\", \"size\":\"140\", \"side\":\"BUY\", \"hash\":\"d422b7da222c10d3ddf2b8e3cc222d86e0530581\", \"best_bid\":\"0.59\", \"best_ask\":\"0.6\"}, {\"asset_id\":\"8761897749749422724209054078244794145777693856614463256546737399611489089783\", \"price\":\"0.53\", \"size\":\"140\", \"side\":\"SELL\", \"hash\":\"fd330fd79d9f21aa09cb451c9cfc8def56e83178\", \"best_bid\":\"0.4\", \"best_ask\":\"0.41\"}], \"timestamp\":\"1785207626067\", \"event_type\":\"price_change\"}","received_at":"2026-07-28T03:00:28.952343Z","schema_version":"clob-market-ws.price_change.v1","sequence":null,"server_hash":null,"server_timestamp":"1785207626067","session_id":"3e519d9098404c15b234d96025eb1a2b","source":"clob_market_ws"},"received_at":"2026-07-28T03:00:28.952343Z","record_id":"23d107e43ae26305e30073378427ce59f7e13d77912942bcee96d30e7ab8be9c","schema_fingerprint":"4aa3821a28b0b7c2400bc59aba4bcc0a76e971dadd19610d3ad38c768e124dc7","schema_version":"edge-lab-recorder.raw.v1","sequence":null,"source":"clob_market_ws"}
{"event_at":"2026-07-28T03:00:26.067000Z","event_fingerprint":"2999e5e097c4a5dff26f646604099377c146bc0984c4925c2ce03b1d811f0fc5","payload":{"connection_id":"a6b55582af5f430fb37ad02bf0922475","event_at":"2026-07-28T03:00:26.067000Z","event_type":"price_change","frame_hash":"dc1c605b0c0f71e3a82937adbfd8ec0396cdc126d233a054b2ed5cffea1bb7d6","frame_index":0,"kind":"data","monotonic_ns":309611983071791,"payload":{"event_type":"price_change","market":"0x779291bef19b6709f61e9764a954aafe9ffae488d50ae674aabdcb4f248006d5","price_changes":[{"asset_id":"8761897749749422724209054078244794145777693856614463256546737399611489089783","best_ask":"0.41","best_bid":"0.4","hash":"fd330fd79d9f21aa09cb451c9cfc8def56e83178","price":"0.3","side":"BUY","size":"127.06"},{"asset_id":"14965588658799411272385430903075831224615961675357217884735713260981483529984","best_ask":"0.6","best_bid":"0.59","hash":"d422b7da222c10d3ddf2b8e3cc222d86e0530581","price":"0.7","side":"SELL","size":"127.06"}],"timestamp":"1785207626067"},"payload_hash":"47b25a097cc12f9ae61240383fbb01ba269b2f1322aee85584b53b4584552e3b","raw_frame":"{\"market\":\"0x779291bef19b6709f61e9764a954aafe9ffae488d50ae674aabdcb4f248006d5\", \"price_changes\":[{\"asset_id\":\"8761897749749422724209054078244794145777693856614463256546737399611489089783\", \"price\":\"0.3\", \"size\":\"127.06\", \"side\":\"BUY\", \"hash\":\"fd330fd79d9f21aa09cb451c9cfc8def56e83178\", \"best_bid\":\"0.4\", \"best_ask\":\"0.41\"}, {\"asset_id\":\"14965588658799411272385430903075831224615961675357217884735713260981483529984\", \"price\":\"0.7\", \"size\":\"127.06\", \"side\":\"SELL\", \"hash\":\"d422b7da222c10d3ddf2b8e3cc222d86e0530581\", \"best_bid\":\"0.59\", \"best_ask\":\"0.6\"}], \"timestamp\":\"1785207626067\", \"event_type\":\"price_change\"}","received_at":"2026-07-28T03:00:28.964499Z","schema_version":"clob-market-ws.price_change.v1","sequence":null,"server_hash":null,"server_timestamp":"1785207626067","session_id":"3e519d9098404c15b234d96025eb1a2b","source":"clob_market_ws"},"received_at":"2026-07-28T03:00:28.964499Z","record_id":"71a6b5959e3d3acefcb5e9a2d9b110576d3d9563106565d646d6e6fd6b6d9eec","schema_fingerprint":"4aa3821a28b0b7c2400bc59aba4bcc0a76e971dadd19610d3ad38c768e124dc7","schema_version":"edge-lab-recorder.raw.v1","sequence":null,"source":"clob_market_ws"}
{"event_at":"2026-07-28T03:00:26.067000Z","event_fingerprint":"f32e6ca7a4683d63bf37167f596255da8c2fb9aee81df3631ec1978eafab8d10","payload":{"connection_id":"a6b55582af5f430fb37ad02bf0922475","event_at":"2026-07-28T03:00:26.067000Z","event_type":"price_change","frame_hash":"4625371c251cc3e257e89d12667454f7516d7e3368b5d2ae25324ea4e2028100","frame_index":0,"kind":"data","monotonic_ns":309611991876291,"payload":{"event_type":"price_change","market":"0x779291bef19b6709f61e9764a954aafe9ffae488d50ae674aabdcb4f248006d5","price_changes":[{"asset_id":"8761897749749422724209054078244794145777693856614463256546737399611489089783","best_ask":"0.41","best_bid":"0.4","hash":"40100b0f5a067db884213c97c1b07a9e767f6fd3","price":"0.15","side":"BUY","size":"229"},{"asset_id":"14965588658799411272385430903075831224615961675357217884735713260981483529984","best_ask":"0.6","best_bid":"0.59","hash":"c6e84f8ec2b0ef821f873578e12b1ad80ecaa64c","price":"0.85","side":"SELL","size":"229"}],"timestamp":"1785207626067"},"payload_hash":"14cbab700376bfa72a90a4f5b47246da48672fa545ec8c47669d84464d52746b","raw_frame":"{\"market\":\"0x779291bef19b6709f61e9764a954aafe9ffae488d50ae674aabdcb4f248006d5\", \"price_changes\":[{\"asset_id\":\"8761897749749422724209054078244794145777693856614463256546737399611489089783\", \"price\":\"0.15\", \"size\":\"229\", \"side\":\"BUY\", \"hash\":\"40100b0f5a067db884213c97c1b07a9e767f6fd3\", \"best_bid\":\"0.4\", \"best_ask\":\"0.41\"}, {\"asset_id\":\"14965588658799411272385430903075831224615961675357217884735713260981483529984\", \"price\":\"0.85\", \"size\":\"229\", \"side\":\"SELL\", \"hash\":\"c6e84f8ec2b0ef821f873578e12b1ad80ecaa64c\", \"best_bid\":\"0.59\", \"best_ask\":\"0.6\"}], \"timestamp\":\"1785207626067\", \"event_type\":\"price_change\"}","received_at":"2026-07-28T03:00:28.973304Z","schema_version":"clob-market-ws.price_change.v1","sequence":null,"server_hash":null,"server_timestamp":"1785207626067","session_id":"3e519d9098404c15b234d96025eb1a2b","source":"clob_market_ws"},"received_at":"2026-07-28T03:00:28.973304Z","record_id":"c31cf7d987ba8a4492f6647cba37cbeefd1db834a77535a67ede0fd5854cadfa","schema_fingerprint":"4aa3821a28b0b7c2400bc59aba4bcc0a76e971dadd19610d3ad38c768e124dc7","schema_version":"edge-lab-recorder.raw.v1","sequence":null,"source":"clob_market_ws"}
{"event_at":"2026-07-28T03:00:26.068000Z","event_fingerprint":"96cf68450916987e7bf7045f0feecbd5081a87d41972ebd4eaee2626554741f7","payload":{"connection_id":"a6b55582af5f430fb37ad02bf0922475","event_at":"2026-07-28T03:00:26.068000Z","event_type":"price_change","frame_hash":"b2123510cace0b03c93a502e3657333644c7246a04b3f0f2a0531f7cb49b6395","frame_index":0,"kind":"data","monotonic_ns":309612009668166,"payload":{"event_type":"price_change","market":"0x779291bef19b6709f61e9764a954aafe9ffae488d50ae674aabdcb4f248006d5","price_changes":[{"asset_id":"8761897749749422724209054078244794145777693856614463256546737399611489089783","best_ask":"0.41","best_bid":"0.4","hash":"64fb4e955fd8e8cfbb82f4c7995d96aa591e8ef6","price":"0.15","side":"BUY","size":"34"},{"asset_id":"14965588658799411272385430903075831224615961675357217884735713260981483529984","best_ask":"0.6","best_bid":"0.59","hash":"a8248b62955b7d269626e6e2377e4a1a45f6e7f7","price":"0.85","side":"SELL","size":"34"}],"timestamp":"1785207626068"},"payload_hash":"cc403f9613d876735abc32ba700d74ab692b4cbc917f42a9b89320598e93cca1","raw_frame":"{\"market\":\"0x779291bef19b6709f61e9764a954aafe9ffae488d50ae674aabdcb4f248006d5\", \"price_changes\":[{\"asset_id\":\"8761897749749422724209054078244794145777693856614463256546737399611489089783\", \"price\":\"0.15\", \"size\":\"34\", \"side\":\"BUY\", \"hash\":\"64fb4e955fd8e8cfbb82f4c7995d96aa591e8ef6\", \"best_bid\":\"0.4\", \"best_ask\":\"0.41\"}, {\"asset_id\":\"14965588658799411272385430903075831224615961675357217884735713260981483529984\", \"price\":\"0.85\", \"size\":\"34\", \"side\":\"SELL\", \"hash\":\"a8248b62955b7d269626e6e2377e4a1a45f6e7f7\", \"best_bid\":\"0.59\", \"best_ask\":\"0.6\"}], \"timestamp\":\"1785207626068\", \"event_type\":\"price_change\"}","received_at":"2026-07-28T03:00:28.991093Z","schema_version":"clob-market-ws.price_change.v1","sequence":null,"server_hash":null,"server_timestamp":"1785207626068","session_id":"3e519d9098404c15b234d96025eb1a2b","source":"clob_market_ws"},"received_at":"2026-07-28T03:00:28.991093Z","record_id":"9bd72c97773aac2ba8518b4ce71ffe3d24862561c830cdaa194cbea5c8fdc3a5","schema_fingerprint":"4aa3821a28b0b7c2400bc59aba4bcc0a76e971dadd19610d3ad38c768e124dc7","schema_version":"edge-lab-recorder.raw.v1","sequence":null,"source":"clob_market_ws"}
{"event_at":"2026-07-28T03:00:26.072000Z","event_fingerprint":"d849ace09f8462a7978db7aeb7247b21983b7d21e0d43a9884225324630a7bb7","payload":{"connection_id":"a6b55582af5f430fb37ad02bf0922475","event_at":"2026-07-28T03:00:26.072000Z","event_type":"price_change","frame_hash":"c6d3ca0e4299fe7b626ca640e8de2ad56b665f87a7b9e7c024c5d00775f27fea","frame_index":0,"kind":"data","monotonic_ns":309612017943083,"payload":{"event_type":"price_change","market":"0x779291bef19b6709f61e9764a954aafe9ffae488d50ae674aabdcb4f248006d5","price_changes":[{"asset_id":"8761897749749422724209054078244794145777693856614463256546737399611489089783","best_ask":"0.41","best_bid":"0.4","hash":"187527e908cc51a653f246b6d945434f8f6d33be","price":"0.32","side":"BUY","size":"189"},{"asset_id":"14965588658799411272385430903075831224615961675357217884735713260981483529984","best_ask":"0.6","best_bid":"0.59","hash":"36e2b3eb9728a2064acac3f20621e8d1d69da298","price":"0.68","side":"SELL","size":"189"}],"timestamp":"1785207626072"},"payload_hash":"71341402b6aef03dcc9a43891a5cdcd7c7c99a185f7d2cede44018b73d17aaeb","raw_frame":"{\"market\":\"0x779291bef19b6709f61e9764a954aafe9ffae488d50ae674aabdcb4f248006d5\", \"price_changes\":[{\"asset_id\":\"8761897749749422724209054078244794145777693856614463256546737399611489089783\", \"price\":\"0.32\", \"size\":\"189\", \"side\":\"BUY\", \"hash\":\"187527e908cc51a653f246b6d945434f8f6d33be\", \"best_bid\":\"0.4\", \"best_ask\":\"0.41\"}, {\"asset_id\":\"14965588658799411272385430903075831224615961675357217884735713260981483529984\", \"price\":\"0.68\", \"size\":\"189\", \"side\":\"SELL\", \"hash\":\"36e2b3eb9728a2064acac3f20621e8d1d69da298\", \"best_bid\":\"0.59\", \"best_ask\":\"0.6\"}], \"timestamp\":\"1785207626072\", \"event_type\":\"price_change\"}","received_at":"2026-07-28T03:00:28.999370Z","schema_version":"clob-market-ws.price_change.v1","sequence":null,"server_hash":null,"server_timestamp":"1785207626072","session_id":"3e519d9098404c15b234d96025eb1a2b","source":"clob_market_ws"},"received_at":"2026-07-28T03:00:28.999370Z","record_id":"e1ddd479a0fdcb5bd9a34fdb2012c50ba8404afbb8c1a3ba5edb469b8b47b4a3","schema_fingerprint":"4aa3821a28b0b7c2400bc59aba4bcc0a76e971dadd19610d3ad38c768e124dc7","schema_version":"edge-lab-recorder.raw.v1","sequence":null,"source":"clob_market_ws"}
{"event_at":"2026-07-28T03:00:26.073000Z","event_fingerprint":"714f94ccbf89219de374e9c19eb2e2452c8b66b4a9446cbd4a6e6df9a31187a4","payload":{"connection_id":"a6b55582af5f430fb37ad02bf0922475","event_at":"2026-07-28T03:00:26.073000Z","event_type":"price_change","frame_hash":"0950669dd833fc6e9344580c2dd64683cd88242c0def11a8b5d036bd92893eae","frame_index":0,"kind":"data","monotonic_ns":309612026587708,"payload":{"event_type":"price_change","market":"0x779291bef19b6709f61e9764a954aafe9ffae488d50ae674aabdcb4f248006d5","price_changes":[{"asset_id":"14965588658799411272385430903075831224615961675357217884735713260981483529984","best_ask":"0.6","best_bid":"0.59","hash":"456b283c59d54c067808944b571e025b43bd9328","price":"0.02","side":"BUY","size":"1625"},{"asset_id":"8761897749749422724209054078244794145777693856614463256546737399611489089783","best_ask":"0.41","best_bid":"0.4","hash":"67233475d210ee797671a47b0509b3995f224b56","price":"0.98","side":"SELL","size":"1625"}],"timestamp":"1785207626073"},"payload_hash":"eb5a5d7bb9add8a2c2f7a0721be90c57de7fc2686b4ddcb7f88e620dd8eb2725","raw_frame":"{\"market\":\"0x779291bef19b6709f61e9764a954aafe9ffae488d50ae674aabdcb4f248006d5\", \"price_changes\":[{\"asset_id\":\"14965588658799411272385430903075831224615961675357217884735713260981483529984\", \"price\":\"0.02\", \"size\":\"1625\", \"side\":\"BUY\", \"hash\":\"456b283c59d54c067808944b571e025b43bd9328\", \"best_bid\":\"0.59\", \"best_ask\":\"0.6\"}, {\"asset_id\":\"8761897749749422724209054078244794145777693856614463256546737399611489089783\", \"price\":\"0.98\", \"size\":\"1625\", \"side\":\"SELL\", \"hash\":\"67233475d210ee797671a47b0509b3995f224b56\", \"best_bid\":\"0.4\", \"best_ask\":\"0.41\"}], \"timestamp\":\"1785207626073\", \"event_type\":\"price_change\"}","received_at":"2026-07-28T03:00:29.008015Z","schema_version":"clob-market-ws.price_change.v1","sequence":null,"server_hash":null,"server_timestamp":"1785207626073","session_id":"3e519d9098404c15b234d96025eb1a2b","source":"clob_market_ws"},"received_at":"2026-07-28T03:00:29.008015Z","record_id":"495cfb3f0d30eb123a39527a98c61ecc5ce098ef0e7ad4ab77fd29ff0cdcf78a","schema_fingerprint":"4aa3821a28b0b7c2400bc59aba4bcc0a76e971dadd19610d3ad38c768e124dc7","schema_version":"edge-lab-recorder.raw.v1","sequence":null,"source":"clob_market_ws"}
{"event_at":"2026-07-28T03:00:26.074000Z","event_fingerprint":"084e60a540580a70c914399834fa1bfb6e4a7f8683d1d79d6bff729cf0a79e41","payload":{"connection_id":"a6b55582af5f430fb37ad02bf0922475","event_at":"2026-07-28T03:00:26.074000Z","event_type":"price_change","frame_hash":"a72b30a408b43ce16b5256521ea15a18b841dedc9dd42cf34be62140d2d1e247","frame_index":0,"kind":"data","monotonic_ns":309612032543625,"payload":{"event_type":"price_change","market":"0x779291bef19b6709f61e9764a954aafe9ffae488d50ae674aabdcb4f248006d5","price_changes":[{"asset_id":"8761897749749422724209054078244794145777693856614463256546737399611489089783","best_ask":"0.41","best_bid":"0.4","hash":"8c7e6301d281d1daada8283a87996fad8015a135","price":"0.01","side":"BUY","size":"7555.02"},{"asset_id":"14965588658799411272385430903075831224615961675357217884735713260981483529984","best_ask":"0.6","best_bid":"0.59","hash":"3d1b4c53fb85778db1da75c09bd349fc56e23a4e","price":"0.99","side":"SELL","size":"7555.02"}],"timestamp":"1785207626074"},"payload_hash":"06dc4d564358e824113267310063e8774191be78fa24f00758c46772b8bbfaaa","raw_frame":"{\"market\":\"0x779291bef19b6709f61e9764a954aafe9ffae488d50ae674aabdcb4f248006d5\", \"price_changes\":[{\"asset_id\":\"8761897749749422724209054078244794145777693856614463256546737399611489089783\", \"price\":\"0.01\", \"size\":\"7555.02\", \"side\":\"BUY\", \"hash\":\"8c7e6301d281d1daada8283a87996fad8015a135\", \"best_bid\":\"0.4\", \"best_ask\":\"0.41\"}, {\"asset_id\":\"14965588658799411272385430903075831224615961675357217884735713260981483529984\", \"price\":\"0.99\", \"size\":\"7555.02\", \"side\":\"SELL\", \"hash\":\"3d1b4c53fb85778db1da75c09bd349fc56e23a4e\", \"best_bid\":\"0.59\", \"best_ask\":\"0.6\"}], \"timestamp\":\"1785207626074\", \"event_type\":\"price_change\"}","received_at":"2026-07-28T03:00:29.013971Z","schema_version":"clob-market-ws.price_change.v1","sequence":null,"server_hash":null,"server_timestamp":"1785207626074","session_id":"3e519d9098404c15b234d96025eb1a2b","source":"clob_market_ws"},"received_at":"2026-07-28T03:00:29.013971Z","record_id":"e535e33121481682336d1181fe94aa65d85c01b6582751da84264bb3988fbf09","schema_fingerprint":"4aa3821a28b0b7c2400bc59aba4bcc0a76e971dadd19610d3ad38c768e124dc7","schema_version":"edge-lab-recorder.raw.v1","sequence":null,"source":"clob_market_ws"}
{"event_at":"2026-07-28T03:00:26.072000Z","event_fingerprint":"af3f98aea111091a58a5f9c5174766ad0729c608a3d0c6ef20b3930fd07fc974","payload":{"connection_id":"a6b55582af5f430fb37ad02bf0922475","event_at":"2026-07-28T03:00:26.072000Z","event_type":"last_trade_price","frame_hash":"0f5f7de23b0467a3b821bc3f276457155b0a10e7996fa1cbf720f6126a141a53","frame_index":0,"kind":"data","monotonic_ns":309612037521250,"payload":{"asset_id":"8761897749749422724209054078244794145777693856614463256546737399611489089783","event_type":"last_trade_price","fee_rate_bps":"0","market":"0x779291bef19b6709f61e9764a954aafe9ffae488d50ae674aabdcb4f248006d5","price":"0.4","side":"SELL","size":"0.02","timestamp":"1785207626072","transaction_hash":"0xb5eb62416bb5b369f7bb0599a123d427fc58ac3c541e9dc31a379de6a05f8254"},"payload_hash":"ab3fea6b8d661fe7784b926cacfab011f1144cb834a0da8545bd05f821d03452","raw_frame":"{\"market\":\"0x779291bef19b6709f61e9764a954aafe9ffae488d50ae674aabdcb4f248006d5\", \"asset_id\":\"8761897749749422724209054078244794145777693856614463256546737399611489089783\", \"price\":\"0.4\", \"size\":\"0.02\", \"fee_rate_bps\":\"0\", \"side\":\"SELL\", \"timestamp\":\"1785207626072\", \"event_type\":\"last_trade_price\", \"transaction_hash\":\"0xb5eb62416bb5b369f7bb0599a123d427fc58ac3c541e9dc31a379de6a05f8254\"}","received_at":"2026-07-28T03:00:29.018949Z","schema_version":"clob-market-ws.last_trade_price.v1","sequence":null,"server_hash":null,"server_timestamp":"1785207626072","session_id":"3e519d9098404c15b234d96025eb1a2b","source":"clob_market_ws"},"received_at":"2026-07-28T03:00:29.018949Z","record_id":"5415fef50d19ecf3200b33063da9b28e287c580b2bac64111fbdbeaa58094c27","schema_fingerprint":"95ad9be75a4b695cd99991e12b2592bc7346f3f5388a82d0000ba65bc0d9fd0a","schema_version":"edge-lab-recorder.raw.v1","sequence":null,"source":"clob_market_ws"}
{"event_at":"2026-07-28T03:00:26.077000Z","event_fingerprint":"286d2bbf2c71dc6331b1f5d0424b7613142ebd4b0b23569dd304917d9a9f8ad2","payload":{"connection_id":"a6b55582af5f430fb37ad02bf0922475","event_at":"2026-07-28T03:00:26.077000Z","event_type":"price_change","frame_hash":"b8b13d05475a123be13b3427193c348eda18da0804a27d73ba56d0cef7c67eb8","frame_index":0,"kind":"data","monotonic_ns":309612041574333,"payload":{"event_type":"price_change","market":"0x779291bef19b6709f61e9764a954aafe9ffae488d50ae674aabdcb4f248006d5","price_changes":[{"asset_id":"8761897749749422724209054078244794145777693856614463256546737399611489089783","best_ask":"0.41","best_bid":"0.4","hash":"10a89222b874d0c31120262527457e8ef2124dac","price":"0.28","side":"BUY","size":"193.62"},{"asset_id":"14965588658799411272385430903075831224615961675357217884735713260981483529984","best_ask":"0.6","best_bid":"0.59","hash":"2700345175e566285ec37f3c506d702a028c9d8e","price":"0.72","side":"SELL","size":"193.62"}],"timestamp":"1785207626077"},"payload_hash":"fc6a8d1e00a306eac7079b457d76a5a394523a6f065c7b955e5ea864664629ad","raw_frame":"{\"market\":\"0x779291bef19b6709f61e9764a954aafe9ffae488d50ae674aabdcb4f248006d5\", \"price_changes\":[{\"asset_id\":\"8761897749749422724209054078244794145777693856614463256546737399611489089783\", \"price\":\"0.28\", \"size\":\"193.62\", \"side\":\"BUY\", \"hash\":\"10a89222b874d0c31120262527457e8ef2124dac\", \"best_bid\":\"0.4\", \"best_ask\":\"0.41\"}, {\"asset_id\":\"14965588658799411272385430903075831224615961675357217884735713260981483529984\", \"price\":\"0.72\", \"size\":\"193.62\", \"side\":\"SELL\", \"hash\":\"2700345175e566285ec37f3c506d702a028c9d8e\", \"best_bid\":\"0.59\", \"best_ask\":\"0.6\"}], \"timestamp\":\"1785207626077\", \"event_type\":\"price_change\"}","received_at":"2026-07-28T03:00:29.023001Z","schema_version":"clob-market-ws.price_change.v1","sequence":null,"server_hash":null,"server_timestamp":"1785207626077","session_id":"3e519d9098404c15b234d96025eb1a2b","source":"clob_market_ws"},"received_at":"2026-07-28T03:00:29.023001Z","record_id":"1d162faa79a843b8d5939b28476981f1cb2aa3d302af5e69249ddc9ccb801e8c","schema_fingerprint":"4aa3821a28b0b7c2400bc59aba4bcc0a76e971dadd19610d3ad38c768e124dc7","schema_version":"edge-lab-recorder.raw.v1","sequence":null,"source":"clob_market_ws"}
{"event_at":"2026-07-28T03:00:26.086000Z","event_fingerprint":"d67513ad0c2fc4b0c691d802173039247969af673daa795398bce82875db5de1","payload":{"connection_id":"a6b55582af5f430fb37ad02bf0922475","event_at":"2026-07-28T03:00:26.086000Z","event_type":"price_change","frame_hash":"9bcfd4613b6fb9276681499b4ff09712ce1cf9e31aaed5fde01e1f2fc73eb8b2","frame_index":0,"kind":"data","monotonic_ns":309612047871000,"payload":{"event_type":"price_change","market":"0x779291bef19b6709f61e9764a954aafe9ffae488d50ae674aabdcb4f248006d5","price_changes":[{"asset_id":"8761897749749422724209054078244794145777693856614463256546737399611489089783","best_ask":"0.41","best_bid":"0.4","hash":"78d0dd388ab8d1d8af782ef941aa4c97cdb6ec0e","price":"0.36","side":"BUY","size":"124"},{"asset_id":"14965588658799411272385430903075831224615961675357217884735713260981483529984","best_ask":"0.6","best_bid":"0.59","hash":"9842f57cd6edad97b8957df81568edccd5f99bb6","price":"0.64","side":"SELL","size":"124"}],"timestamp":"1785207626086"},"payload_hash":"e65930b870d2b930cab387920faa754f750b237d08d6389b31a638d4d0c3bda4","raw_frame":"{\"market\":\"0x779291bef19b6709f61e9764a954aafe9ffae488d50ae674aabdcb4f248006d5\", \"price_changes\":[{\"asset_id\":\"8761897749749422724209054078244794145777693856614463256546737399611489089783\", \"price\":\"0.36\", \"size\":\"124\", \"side\":\"BUY\", \"hash\":\"78d0dd388ab8d1d8af782ef941aa4c97cdb6ec0e\", \"best_bid\":\"0.4\", \"best_ask\":\"0.41\"}, {\"asset_id\":\"14965588658799411272385430903075831224615961675357217884735713260981483529984\", \"price\":\"0.64\", \"size\":\"124\", \"side\":\"SELL\", \"hash\":\"9842f57cd6edad97b8957df81568edccd5f99bb6\", \"best_bid\":\"0.59\", \"best_ask\":\"0.6\"}], \"timestamp\":\"1785207626086\", \"event_type\":\"price_change\"}","received_at":"2026-07-28T03:00:29.029298Z","schema_version":"clob-market-ws.price_change.v1","sequence":null,"server_hash":null,"server_timestamp":"1785207626086","session_id":"3e519d9098404c15b234d96025eb1a2b","source":"clob_market_ws"},"received_at":"2026-07-28T03:00:29.029298Z","record_id":"297839ed776602e94998915abbc83839fd4caeefb05953783df82bc298c5da92","schema_fingerprint":"4aa3821a28b0b7c2400bc59aba4bcc0a76e971dadd19610d3ad38c768e124dc7","schema_version":"edge-lab-recorder.raw.v1","sequence":null,"source":"clob_market_ws"}
{"event_at":"2026-07-28T03:00:26.086000Z","event_fingerprint":"91bebfd15c31e1aa245c8669cc44bd88fc75a502edfa743645346e6f1d68ac8e","payload":{"connection_id":"a6b55582af5f430fb37ad02bf0922475","event_at":"2026-07-28T03:00:26.086000Z","event_type":"price_change","frame_hash":"edb5870b9d6fd23be84827c0d0bc0a9f67bcd63a6766595908da57958abd156d","frame_index":0,"kind":"data","monotonic_ns":309612053343916,"payload":{"event_type":"price_change","market":"0x779291bef19b6709f61e9764a954aafe9ffae488d50ae674aabdcb4f248006d5","price_changes":[{"asset_id":"14965588658799411272385430903075831224615961675357217884735713260981483529984","best_ask":"0.6","best_bid":"0.59","hash":"9842f57cd6edad97b8957df81568edccd5f99bb6","price":"0.58","side":"BUY","size":"209.59"},{"asset_id":"8761897749749422724209054078244794145777693856614463256546737399611489089783","best_ask":"0.41","best_bid":"0.4","hash":"78d0dd388ab8d1d8af782ef941aa4c97cdb6ec0e","price":"0.42","side":"SELL","size":"209.59"}],"timestamp":"1785207626086"},"payload_hash":"44716bef74c9401d350714c5871106bc7e99d855470870217536dbb4b5e8e14d","raw_frame":"{\"market\":\"0x779291bef19b6709f61e9764a954aafe9ffae488d50ae674aabdcb4f248006d5\", \"price_changes\":[{\"asset_id\":\"14965588658799411272385430903075831224615961675357217884735713260981483529984\", \"price\":\"0.58\", \"size\":\"209.59\", \"side\":\"BUY\", \"hash\":\"9842f57cd6edad97b8957df81568edccd5f99bb6\", \"best_bid\":\"0.59\", \"best_ask\":\"0.6\"}, {\"asset_id\":\"8761897749749422724209054078244794145777693856614463256546737399611489089783\", \"price\":\"0.42\", \"size\":\"209.59\", \"side\":\"SELL\", \"hash\":\"78d0dd388ab8d1d8af782ef941aa4c97cdb6ec0e\", \"best_bid\":\"0.4\", \"best_ask\":\"0.41\"}], \"timestamp\":\"1785207626086\", \"event_type\":\"price_change\"}","received_at":"2026-07-28T03:00:29.034770Z","schema_version":"clob-market-ws.price_change.v1","sequence":null,"server_hash":null,"server_timestamp":"1785207626086","session_id":"3e519d9098404c15b234d96025eb1a2b","source":"clob_market_ws"},"received_at":"2026-07-28T03:00:29.034770Z","record_id":"be74b5de6acd2850b4a125148b93276ef7d8d39ac265fabbb2bf6b5207f2b25a","schema_fingerprint":"4aa3821a28b0b7c2400bc59aba4bcc0a76e971dadd19610d3ad38c768e124dc7","schema_version":"edge-lab-recorder.raw.v1","sequence":null,"source":"clob_market_ws"}
{"event_at":"2026-07-28T03:00:26.095000Z","event_fingerprint":"9a968f53dc1be346112c715a705060c3a4320f4e7d039b9083f7ece1c189e2d1","payload":{"connection_id":"a6b55582af5f430fb37ad02bf0922475","event_at":"2026-07-28T03:00:26.095000Z","event_type":"price_change","frame_hash":"d660d2d1d30b94161946a50edccc90c122712293e5abbbafd9099ec3cc688b39","frame_index":0,"kind":"data","monotonic_ns":309612058253625,"payload":{"event_type":"price_change","market":"0x779291bef19b6709f61e9764a954aafe9ffae488d50ae674aabdcb4f248006d5","price_changes":[{"asset_id":"8761897749749422724209054078244794145777693856614463256546737399611489089783","best_ask":"0.41","best_bid":"0.4","hash":"57ebf2a2467213e9af5204065e92c789ce5c5de8","price":"0.01","side":"BUY","size":"7550.02"},{"asset_id":"14965588658799411272385430903075831224615961675357217884735713260981483529984","best_ask":"0.6","best_bid":"0.59","hash":"b0cf39f52cd6a5695e040c31bde4eecd80968e31","price":"0.99","side":"SELL","size":"7550.02"}],"timestamp":"1785207626095"},"payload_hash":"9558ceb8d91ad143845c1026d6404bfaeb31afed93646d92bb0f54356e0a8296","raw_frame":"{\"market\":\"0x779291bef19b6709f61e9764a954aafe9ffae488d50ae674aabdcb4f248006d5\", \"price_changes\":[{\"asset_id\":\"8761897749749422724209054078244794145777693856614463256546737399611489089783\", \"price\":\"0.01\", \"size\":\"7550.02\", \"side\":\"BUY\", \"hash\":\"57ebf2a2467213e9af5204065e92c789ce5c5de8\", \"best_bid\":\"0.4\", \"best_ask\":\"0.41\"}, {\"asset_id\":\"14965588658799411272385430903075831224615961675357217884735713260981483529984\", \"price\":\"0.99\", \"size\":\"7550.02\", \"side\":\"SELL\", \"hash\":\"b0cf39f52cd6a5695e040c31bde4eecd80968e31\", \"best_bid\":\"0.59\", \"best_ask\":\"0.6\"}], \"timestamp\":\"1785207626095\", \"event_type\":\"price_change\"}","received_at":"2026-07-28T03:00:29.039681Z","schema_version":"clob-market-ws.price_change.v1","sequence":null,"server_hash":null,"server_timestamp":"1785207626095","session_id":"3e519d9098404c15b234d96025eb1a2b","source":"clob_market_ws"},"received_at":"2026-07-28T03:00:29.039681Z","record_id":"1d18b79d8606dd50fc35bf1499fce779d970fc8bba8c1a6f43a9c48b986c12ab","schema_fingerprint":"4aa3821a28b0b7c2400bc59aba4bcc0a76e971dadd19610d3ad38c768e124dc7","schema_version":"edge-lab-recorder.raw.v1","sequence":null,"source":"clob_market_ws"}
{"event_at":"2026-07-28T03:00:26.096000Z","event_fingerprint":"82a0e817d1f1538e74cb7cad327499edd6b06362b01c7f39895109afc34f2abe","payload":{"connection_id":"a6b55582af5f430fb37ad02bf0922475","event_at":"2026-07-28T03:00:26.096000Z","event_type":"price_change","frame_hash":"25f9594355cf4ec5d9a2992081aa0e3c6d578596af60d4d909b4d1c7a7c9393b","frame_index":0,"kind":"data","monotonic_ns":309612064053458,"payload":{"event_type":"price_change","market":"0x779291bef19b6709f61e9764a954aafe9ffae488d50ae674aabdcb4f248006d5","price_changes":[{"asset_id":"8761897749749422724209054078244794145777693856614463256546737399611489089783","best_ask":"0.41","best_bid":"0.4","hash":"c08f3bd9e6c7814fee91695c97c91c6f5b47f6c2","price":"0.36","side":"BUY","size":"119"},{"asset_id":"14965588658799411272385430903075831224615961675357217884735713260981483529984","best_ask":"0.6","best_bid":"0.59","hash":"bdb729232d92b977042ea4cd9424d7f59e859c25","price":"0.64","side":"SELL","size":"119"}],"timestamp":"1785207626096"},"payload_hash":"65d2faafbc43cf163f80f131ce1de7980cc7fc42071ab326b7f2eac521c99f50","raw_frame":"{\"market\":\"0x779291bef19b6709f61e9764a954aafe9ffae488d50ae674aabdcb4f248006d5\", \"price_changes\":[{\"asset_id\":\"8761897749749422724209054078244794145777693856614463256546737399611489089783\", \"price\":\"0.36\", \"size\":\"119\", \"side\":\"BUY\", \"hash\":\"c08f3bd9e6c7814fee91695c97c91c6f5b47f6c2\", \"best_bid\":\"0.4\", \"best_ask\":\"0.41\"}, {\"asset_id\":\"14965588658799411272385430903075831224615961675357217884735713260981483529984\", \"price\":\"0.64\", \"size\":\"119\", \"side\":\"SELL\", \"hash\":\"bdb729232d92b977042ea4cd9424d7f59e859c25\", \"best_bid\":\"0.59\", \"best_ask\":\"0.6\"}], \"timestamp\":\"1785207626096\", \"event_type\":\"price_change\"}","received_at":"2026-07-28T03:00:29.045480Z","schema_version":"clob-market-ws.price_change.v1","sequence":null,"server_hash":null,"server_timestamp":"1785207626096","session_id":"3e519d9098404c15b234d96025eb1a2b","source":"clob_market_ws"},"received_at":"2026-07-28T03:00:29.045480Z","record_id":"29afcd0fb4abc1868ebfcd36d144ab38546fcfc9a8873b05e60f48d1e2c98528","schema_fingerprint":"4aa3821a28b0b7c2400bc59aba4bcc0a76e971dadd19610d3ad38c768e124dc7","schema_version":"edge-lab-recorder.raw.v1","sequence":null,"source":"clob_market_ws"}
{"event_at":null,"event_fingerprint":"8ff830c7c334883ef9a6e380c85443d987b15e18549cc94a54efd2d70da3b884","payload":{"connection_id":"a6b55582af5f430fb37ad02bf0922475","event_type":"heartbeat_ack","frame_hash":"95784973cc639977bff93619700168505cb8f7855e44fa643d34622a43706c87","kind":"lifecycle","monotonic_ns":309612070148500,"raw_frame":"PONG","received_at":"2026-07-28T03:00:29.051574Z","schema_version":"edge-lab-recorder.heartbeat-ack.v1","session_id":"3e519d9098404c15b234d96025eb1a2b","source":"clob_market_ws"},"received_at":"2026-07-28T03:00:29.051574Z","record_id":"7995abc76f1594612d725e0dbc782375961105228c5cc098be15e78944a067ca","schema_fingerprint":"c14ee1aab3ca674ee738e5268877b544d74c41ad3c427cedc09236467dc68ba1","schema_version":"edge-lab-recorder.raw.v1","sequence":null,"source":"clob_market_ws"}
{"event_at":"2026-07-28T03:00:26.098000Z","event_fingerprint":"b1108f3fe8f1c04de1dae583ce9c075c844bba55e8a5857178ede2877c43efd3","payload":{"connection_id":"a6b55582af5f430fb37ad02bf0922475","event_at":"2026-07-28T03:00:26.098000Z","event_type":"price_change","frame_hash":"13872e53f17b63482c07099aa3644c387ab16ceca2926e3936777649cafdd743","frame_index":0,"kind":"data","monotonic_ns":309612077036375,"payload":{"event_type":"price_change","market":"0x779291bef19b6709f61e9764a954aafe9ffae488d50ae674aabdcb4f248006d5","price_changes":[{"asset_id":"8761897749749422724209054078244794145777693856614463256546737399611489089783","best_ask":"0.41","best_bid":"0.4","hash":"cbce2db4ba3ce6686a9740bb4601a881ed05cb0f","price":"0.36","side":"BUY","size":"98"},{"asset_id":"14965588658799411272385430903075831224615961675357217884735713260981483529984","best_ask":"0.6","best_bid":"0.59","hash":"b1a477fba3d999be5fc4c2d12348e176760007da","price":"0.64","side":"SELL","size":"98"}],"timestamp":"1785207626098"},"payload_hash":"b31e60c83d8ae45c88a1ca64f855f6ecbfa791cc865b885e62a01612578d8f90","raw_frame":"{\"market\":\"0x779291bef19b6709f61e9764a954aafe9ffae488d50ae674aabdcb4f248006d5\", \"price_changes\":[{\"asset_id\":\"8761897749749422724209054078244794145777693856614463256546737399611489089783\", \"price\":\"0.36\", \"size\":\"98\", \"side\":\"BUY\", \"hash\":\"cbce2db4ba3ce6686a9740bb4601a881ed05cb0f\", \"best_bid\":\"0.4\", \"best_ask\":\"0.41\"}, {\"asset_id\":\"14965588658799411272385430903075831224615961675357217884735713260981483529984\", \"price\":\"0.64\", \"size\":\"98\", \"side\":\"SELL\", \"hash\":\"b1a477fba3d999be5fc4c2d12348e176760007da\", \"best_bid\":\"0.59\", \"best_ask\":\"0.6\"}], \"timestamp\":\"1785207626098\", \"event_type\":\"price_change\"}","received_at":"2026-07-28T03:00:29.058463Z","schema_version":"clob-market-ws.price_change.v1","sequence":null,"server_hash":null,"server_timestamp":"1785207626098","session_id":"3e519d9098404c15b234d96025eb1a2b","source":"clob_market_ws"},"received_at":"2026-07-28T03:00:29.058463Z","record_id":"7a3522712084704a1367f81c71ba0a7a8c2d086178fd3a5b6ec4b1d4eaef1fe4","schema_fingerprint":"4aa3821a28b0b7c2400bc59aba4bcc0a76e971dadd19610d3ad38c768e124dc7","schema_version":"edge-lab-recorder.raw.v1","sequence":null,"source":"clob_market_ws"}
{"event_at":"2026-07-28T03:00:26.100000Z","event_fingerprint":"616b54eb7cd84ec916d0cf09c9ded88a2d95b57dd77d7e4a44d52e577b1849ad","payload":{"connection_id":"a6b55582af5f430fb37ad02bf0922475","event_at":"2026-07-28T03:00:26.100000Z","event_type":"price_change","frame_hash":"99ccb2578da859894efd755b5048e8cdc6ca16864385c9a737de6f1054f39a8c","frame_index":0,"kind":"data","monotonic_ns":309612082106375,"payload":{"event_type":"price_change","market":"0x779291bef19b6709f61e9764a954aafe9ffae488d50ae674aabdcb4f248006d5","price_changes":[{"asset_id":"8761897749749422724209054078244794145777693856614463256546737399611489089783","best_ask":"0.41","best_bid":"0.4","hash":"b7e047ea6314f2b996e633ca66357866bcf808de","price":"0.38","side":"BUY","size":"378.6"},{"asset_id":"14965588658799411272385430903075831224615961675357217884735713260981483529984","best_ask":"0.6","best_bid":"0.59","hash":"fc05eaee17abb07db9e91acc2c967163721d160f","price":"0.62","side":"SELL","size":"378.6"}],"timestamp":"1785207626100"},"payload_hash":"48f72187cc7d3712f783803c885d0223094a35c8aaafbff10574e564032d8b33","raw_frame":"{\"market\":\"0x779291bef19b6709f61e9764a954aafe9ffae488d50ae674aabdcb4f248006d5\", \"price_changes\":[{\"asset_id\":\"8761897749749422724209054078244794145777693856614463256546737399611489089783\", \"price\":\"0.38\", \"size\":\"378.6\", \"side\":\"BUY\", \"hash\":\"b7e047ea6314f2b996e633ca66357866bcf808de\", \"best_bid\":\"0.4\", \"best_ask\":\"0.41\"}, {\"asset_id\":\"14965588658799411272385430903075831224615961675357217884735713260981483529984\", \"price\":\"0.62\", \"size\":\"378.6\", \"side\":\"SELL\", \"hash\":\"fc05eaee17abb07db9e91acc2c967163721d160f\", \"best_bid\":\"0.59\", \"best_ask\":\"0.6\"}], \"timestamp\":\"1785207626100\", \"event_type\":\"price_change\"}","received_at":"2026-07-28T03:00:29.063533Z","schema_version":"clob-market-ws.price_change.v1","sequence":null,"server_hash":null,"server_timestamp":"1785207626100","session_id":"3e519d9098404c15b234d96025eb1a2b","source":"clob_market_ws"},"received_at":"2026-07-28T03:00:29.063533Z","record_id":"2ec536a24e3d3531ab6df8d6bfdb6a9cf3a444724c3cd936a2326557f4c283b1","schema_fingerprint":"4aa3821a28b0b7c2400bc59aba4bcc0a76e971dadd19610d3ad38c768e124dc7","schema_version":"edge-lab-recorder.raw.v1","sequence":null,"source":"clob_market_ws"}
{"event_at":"2026-07-28T03:00:26.101000Z","event_fingerprint":"94a4e796e0a9333b537ee62cb18bf8b258145fde1da597a9dc11df68da609808","payload":{"connection_id":"a6b55582af5f430fb37ad02bf0922475","event_at":"2026-07-28T03:00:26.101000Z","event_type":"price_change","frame_hash":"4c3a04abfbc17e6fc5673c36cbf29309550d8d442f05870e520defc6273f66a0","frame_index":0,"kind":"data","monotonic_ns":309612087231000,"payload":{"event_type":"price_change","market":"0x779291bef19b6709f61e9764a954aafe9ffae488d50ae674aabdcb4f248006d5","price_changes":[{"asset_id":"8761897749749422724209054078244794145777693856614463256546737399611489089783","best_ask":"0.41","best_bid":"0.4","hash":"e5e25b8fce00e3d4bd85905d9c38181056aaf70e","price":"0.37","side":"BUY","size":"16"},{"asset_id":"14965588658799411272385430903075831224615961675357217884735713260981483529984","best_ask":"0.6","best_bid":"0.59","hash":"6849209bcefe02ac2477077d8fd744a3409f6df2","price":"0.63","side":"SELL","size":"16"}],"timestamp":"1785207626101"},"payload_hash":"83aabf9dbd7730176f2f7bf508f7dc950896faeb34695d0b356330f6a62c68c0","raw_frame":"{\"market\":\"0x779291bef19b6709f61e9764a954aafe9ffae488d50ae674aabdcb4f248006d5\", \"price_changes\":[{\"asset_id\":\"8761897749749422724209054078244794145777693856614463256546737399611489089783\", \"price\":\"0.37\", \"size\":\"16\", \"side\":\"BUY\", \"hash\":\"e5e25b8fce00e3d4bd85905d9c38181056aaf70e\", \"best_bid\":\"0.4\", \"best_ask\":\"0.41\"}, {\"asset_id\":\"14965588658799411272385430903075831224615961675357217884735713260981483529984\", \"price\":\"0.63\", \"size\":\"16\", \"side\":\"SELL\", \"hash\":\"6849209bcefe02ac2477077d8fd744a3409f6df2\", \"best_bid\":\"0.59\", \"best_ask\":\"0.6\"}], \"timestamp\":\"1785207626101\", \"event_type\":\"price_change\"}","received_at":"2026-07-28T03:00:29.068657Z","schema_version":"clob-market-ws.price_change.v1","sequence":null,"server_hash":null,"server_timestamp":"1785207626101","session_id":"3e519d9098404c15b234d96025eb1a2b","source":"clob_market_ws"},"received_at":"2026-07-28T03:00:29.068657Z","record_id":"7193168779b28ce445ce9b6c82254b1deb67478b225c4919a2f60d4f24b14f81","schema_fingerprint":"4aa3821a28b0b7c2400bc59aba4bcc0a76e971dadd19610d3ad38c768e124dc7","schema_version":"edge-lab-recorder.raw.v1","sequence":null,"source":"clob_market_ws"}
{"event_at":"2026-07-28T03:00:26.101000Z","event_fingerprint":"06c96957c7740301aae47186facb0f409732eff7ebf25b68f45fa11744925f28","payload":{"connection_id":"a6b55582af5f430fb37ad02bf0922475","event_at":"2026-07-28T03:00:26.101000Z","event_type":"price_change","frame_hash":"c5efda7bbdde7357faa9fa27b533d171463ea97443cb5efcf9fc268c050dc2b3","frame_index":0,"kind":"data","monotonic_ns":309612093080500,"payload":{"event_type":"price_change","market":"0x779291bef19b6709f61e9764a954aafe9ffae488d50ae674aabdcb4f248006d5","price_changes":[{"asset_id":"14965588658799411272385430903075831224615961675357217884735713260981483529984","best_ask":"0.6","best_bid":"0.59","hash":"209f5cd6a7ae7e6d4e2d346114a911897b5c936d","price":"0.58","side":"BUY","size":"214.59"},{"asset_id":"8761897749749422724209054078244794145777693856614463256546737399611489089783","best_ask":"0.41","best_bid":"0.4","hash":"15e630ee14366552121cdf6202067aa6918d56f3","price":"0.42","side":"SELL","size":"214.59"}],"timestamp":"1785207626101"},"payload_hash":"000f28b59d4bb1aa2381a254d7b5cd4231cceded4fe2b82ff71b00b8db2401cd","raw_frame":"{\"market\":\"0x779291bef19b6709f61e9764a954aafe9ffae488d50ae674aabdcb4f248006d5\", \"price_changes\":[{\"asset_id\":\"14965588658799411272385430903075831224615961675357217884735713260981483529984\", \"price\":\"0.58\", \"size\":\"214.59\", \"side\":\"BUY\", \"hash\":\"209f5cd6a7ae7e6d4e2d346114a911897b5c936d\", \"best_bid\":\"0.59\", \"best_ask\":\"0.6\"}, {\"asset_id\":\"8761897749749422724209054078244794145777693856614463256546737399611489089783\", \"price\":\"0.42\", \"size\":\"214.59\", \"side\":\"SELL\", \"hash\":\"15e630ee14366552121cdf6202067aa6918d56f3\", \"best_bid\":\"0.4\", \"best_ask\":\"0.41\"}], \"timestamp\":\"1785207626101\", \"event_type\":\"price_change\"}","received_at":"2026-07-28T03:00:29.074506Z","schema_version":"clob-market-ws.price_change.v1","sequence":null,"server_hash":null,"server_timestamp":"1785207626101","session_id":"3e519d9098404c15b234d96025eb1a2b","source":"clob_market_ws"},"received_at":"2026-07-28T03:00:29.074506Z","record_id":"9f0e36b85f0fdb3d54ac4b192dd5ca1e88fc607204e3f42f5d8e2d710f93db2c","schema_fingerprint":"4aa3821a28b0b7c2400bc59aba4bcc0a76e971dadd19610d3ad38c768e124dc7","schema_version":"edge-lab-recorder.raw.v1","sequence":null,"source":"clob_market_ws"}
{"event_at":"2026-07-28T03:00:26.103000Z","event_fingerprint":"addee706229c69de5d59a97a56fa268093e6b4bd2ec2d6a153671829676bb7ad","payload":{"connection_id":"a6b55582af5f430fb37ad02bf0922475","event_at":"2026-07-28T03:00:26.103000Z","event_type":"price_change","frame_hash":"02a5c688c93c9464d1d8271cf02b5ed5367fe7b456b5ab76f469b663b08f1a9e","frame_index":0,"kind":"data","monotonic_ns":309612099075750,"payload":{"event_type":"price_change","market":"0x779291bef19b6709f61e9764a954aafe9ffae488d50ae674aabdcb4f248006d5","price_changes":[{"asset_id":"8761897749749422724209054078244794145777693856614463256546737399611489089783","best_ask":"0.41","best_bid":"0.4","hash":"27b6f2cd3174bed55c0164e42b90674318a610c6","price":"0.35","side":"BUY","size":"232"},{"asset_id":"14965588658799411272385430903075831224615961675357217884735713260981483529984","best_ask":"0.6","best_bid":"0.59","hash":"acd801a631a1de335e8cd941cab1d482a1931540","price":"0.65","side":"SELL","size":"232"}],"timestamp":"1785207626103"},"payload_hash":"2665aa89e2d6643930cef3b3f902689eabe7efc62df02d2c1a76040152afe7b5","raw_frame":"{\"market\":\"0x779291bef19b6709f61e9764a954aafe9ffae488d50ae674aabdcb4f248006d5\", \"price_changes\":[{\"asset_id\":\"8761897749749422724209054078244794145777693856614463256546737399611489089783\", \"price\":\"0.35\", \"size\":\"232\", \"side\":\"BUY\", \"hash\":\"27b6f2cd3174bed55c0164e42b90674318a610c6\", \"best_bid\":\"0.4\", \"best_ask\":\"0.41\"}, {\"asset_id\":\"14965588658799411272385430903075831224615961675357217884735713260981483529984\", \"price\":\"0.65\", \"size\":\"232\", \"side\":\"SELL\", \"hash\":\"acd801a631a1de335e8cd941cab1d482a1931540\", \"best_bid\":\"0.59\", \"best_ask\":\"0.6\"}], \"timestamp\":\"1785207626103\", \"event_type\":\"price_change\"}","received_at":"2026-07-28T03:00:29.080506Z","schema_version":"clob-market-ws.price_change.v1","sequence":null,"server_hash":null,"server_timestamp":"1785207626103","session_id":"3e519d9098404c15b234d96025eb1a2b","source":"clob_market_ws"},"received_at":"2026-07-28T03:00:29.080506Z","record_id":"d270de3c49b40e6b8af566a21f38204ca8479ef6745e20c4d3880f2ce61e3af2","schema_fingerprint":"4aa3821a28b0b7c2400bc59aba4bcc0a76e971dadd19610d3ad38c768e124dc7","schema_version":"edge-lab-recorder.raw.v1","sequence":null,"source":"clob_market_ws"}
{"event_at":"2026-07-28T03:00:26.103000Z","event_fingerprint":"7a2069bc690c4f847bbecba662d5c2d772f0fbab76e7635805e66856984aa418","payload":{"connection_id":"a6b55582af5f430fb37ad02bf0922475","event_at":"2026-07-28T03:00:26.103000Z","event_type":"price_change","frame_hash":"44d7b447445de03344bf2446e8172a398a7a305325ae6eb324e0a6697920e23f","frame_index":0,"kind":"data","monotonic_ns":309612101488250,"payload":{"event_type":"price_change","market":"0x779291bef19b6709f61e9764a954aafe9ffae488d50ae674aabdcb4f248006d5","price_changes":[{"asset_id":"8761897749749422724209054078244794145777693856614463256546737399611489089783","best_ask":"0.41","best_bid":"0.4","hash":"e9a3f040b389b747e8b5a14f9fa0a306040dfe95","price":"0.28","side":"BUY","size":"201.12"},{"asset_id":"14965588658799411272385430903075831224615961675357217884735713260981483529984","best_ask":"0.6","best_bid":"0.59","hash":"4480152733c720758f3ac9aff5cd661f991907f8","price":"0.72","side":"SELL","size":"201.12"}],"timestamp":"1785207626103"},"payload_hash":"7700eb62ade5d83e0c3b9d4ba43af663aebc9e7e4ec6348f9c3e39c61cbe362f","raw_frame":"{\"market\":\"0x779291bef19b6709f61e9764a954aafe9ffae488d50ae674aabdcb4f248006d5\", \"price_changes\":[{\"asset_id\":\"8761897749749422724209054078244794145777693856614463256546737399611489089783\", \"price\":\"0.28\", \"size\":\"201.12\", \"side\":\"BUY\", \"hash\":\"e9a3f040b389b747e8b5a14f9fa0a306040dfe95\", \"best_bid\":\"0.4\", \"best_ask\":\"0.41\"}, {\"asset_id\":\"14965588658799411272385430903075831224615961675357217884735713260981483529984\", \"price\":\"0.72\", \"size\":\"201.12\", \"side\":\"SELL\", \"hash\":\"4480152733c720758f3ac9aff5cd661f991907f8\", \"best_bid\":\"0.59\", \"best_ask\":\"0.6\"}], \"timestamp\":\"1785207626103\", \"event_type\":\"price_change\"}","received_at":"2026-07-28T03:00:29.082920Z","schema_version":"clob-market-ws.price_change.v1","sequence":null,"server_hash":null,"server_timestamp":"1785207626103","session_id":"3e519d9098404c15b234d96025eb1a2b","source":"clob_market_ws"},"received_at":"2026-07-28T03:00:29.082920Z","record_id":"55146ba6717ce313a8b8c2f645110854ac8b2835ad7f73d5ab047090dd1bbd3b","schema_fingerprint":"4aa3821a28b0b7c2400bc59aba4bcc0a76e971dadd19610d3ad38c768e124dc7","schema_version":"edge-lab-recorder.raw.v1","sequence":null,"source":"clob_market_ws"}
{"event_at":"2026-07-28T03:00:26.104000Z","event_fingerprint":"a93093181c963945e59215c666df8962a77f6c14fc4847bab9d99b8d46a2ba87","payload":{"connection_id":"a6b55582af5f430fb37ad02bf0922475","event_at":"2026-07-28T03:00:26.104000Z","event_type":"price_change","frame_hash":"512d8d6147934360b6777be410648a155e318de0cbff6705e489b55d0733ed6c","frame_index":0,"kind":"data","monotonic_ns":309612103749166,"payload":{"event_type":"price_change","market":"0x779291bef19b6709f61e9764a954aafe9ffae488d50ae674aabdcb4f248006d5","price_changes":[{"asset_id":"8761897749749422724209054078244794145777693856614463256546737399611489089783","best_ask":"0.41","best_bid":"0.4","hash":"f4a49420edc86b711da27944c7866c001cee7a82","price":"0.33","side":"BUY","size":"109"},{"asset_id":"14965588658799411272385430903075831224615961675357217884735713260981483529984","best_ask":"0.6","best_bid":"0.59","hash":"26dd926f48ab377e789fd15f1e06716d8454a73b","price":"0.67","side":"SELL","size":"109"}],"timestamp":"1785207626104"},"payload_hash":"2315904ffcfa60156232d9241250336530563637914c9837ba28b9a5c423c845","raw_frame":"{\"market\":\"0x779291bef19b6709f61e9764a954aafe9ffae488d50ae674aabdcb4f248006d5\", \"price_changes\":[{\"asset_id\":\"8761897749749422724209054078244794145777693856614463256546737399611489089783\", \"price\":\"0.33\", \"size\":\"109\", \"side\":\"BUY\", \"hash\":\"f4a49420edc86b711da27944c7866c001cee7a82\", \"best_bid\":\"0.4\", \"best_ask\":\"0.41\"}, {\"asset_id\":\"14965588658799411272385430903075831224615961675357217884735713260981483529984\", \"price\":\"0.67\", \"size\":\"109\", \"side\":\"SELL\", \"hash\":\"26dd926f48ab377e789fd15f1e06716d8454a73b\", \"best_bid\":\"0.59\", \"best_ask\":\"0.6\"}], \"timestamp\":\"1785207626104\", \"event_type\":\"price_change\"}","received_at":"2026-07-28T03:00:29.085181Z","schema_version":"clob-market-ws.price_change.v1","sequence":null,"server_hash":null,"server_timestamp":"1785207626104","session_id":"3e519d9098404c15b234d96025eb1a2b","source":"clob_market_ws"},"received_at":"2026-07-28T03:00:29.085181Z","record_id":"6e32669bfe45cec639ae8cba1b99164ebdf71a66480d8b4865c14a4b1d00750f","schema_fingerprint":"4aa3821a28b0b7c2400bc59aba4bcc0a76e971dadd19610d3ad38c768e124dc7","schema_version":"edge-lab-recorder.raw.v1","sequence":null,"source":"clob_market_ws"}
{"event_at":"2026-07-28T03:00:26.105000Z","event_fingerprint":"f0013a9034104d2182a0d07f1b469ffab1f07f3a83c0d5e2c422a578d4f1cac3","payload":{"connection_id":"a6b55582af5f430fb37ad02bf0922475","event_at":"2026-07-28T03:00:26.105000Z","event_type":"price_change","frame_hash":"f688cc5574fa543cacde08481edf80b59ddcd0751d1c90238e300083522c6c12","frame_index":0,"kind":"data","monotonic_ns":309612107010666,"payload":{"event_type":"price_change","market":"0x779291bef19b6709f61e9764a954aafe9ffae488d50ae674aabdcb4f248006d5","price_changes":[{"asset_id":"14965588658799411272385430903075831224615961675357217884735713260981483529984","best_ask":"0.6","best_bid":"0.59","hash":"6d96c27d40e4e3b943b82dc6454d90155753647f","price":"0.49","side":"BUY","size":"188.5"},{"asset_id":"8761897749749422724209054078244794145777693856614463256546737399611489089783","best_ask":"0.41","best_bid":"0.4","hash":"c34ff77a8b50d4817241d2d5e699270cbb3f41cb","price":"0.51","side":"SELL","size":"188.5"}],"timestamp":"1785207626105"},"payload_hash":"6e3fb40b8481a54926d73fc4a2c1ff1d6c5d6f906efb9986e1b2f9100220362e","raw_frame":"{\"market\":\"0x779291bef19b6709f61e9764a954aafe9ffae488d50ae674aabdcb4f248006d5\", \"price_changes\":[{\"asset_id\":\"14965588658799411272385430903075831224615961675357217884735713260981483529984\", \"price\":\"0.49\", \"size\":\"188.5\", \"side\":\"BUY\", \"hash\":\"6d96c27d40e4e3b943b82dc6454d90155753647f\", \"best_bid\":\"0.59\", \"best_ask\":\"0.6\"}, {\"asset_id\":\"8761897749749422724209054078244794145777693856614463256546737399611489089783\", \"price\":\"0.51\", \"size\":\"188.5\", \"side\":\"SELL\", \"hash\":\"c34ff77a8b50d4817241d2d5e699270cbb3f41cb\", \"best_bid\":\"0.4\", \"best_ask\":\"0.41\"}], \"timestamp\":\"1785207626105\", \"event_type\":\"price_change\"}","received_at":"2026-07-28T03:00:29.088442Z","schema_version":"clob-market-ws.price_change.v1","sequence":null,"server_hash":null,"server_timestamp":"1785207626105","session_id":"3e519d9098404c15b234d96025eb1a2b","source":"clob_market_ws"},"received_at":"2026-07-28T03:00:29.088442Z","record_id":"c47ccbc95d5794daa4b15503d6cd2fa06f4c9005ff3654e8391b19fbc4f09b4e","schema_fingerprint":"4aa3821a28b0b7c2400bc59aba4bcc0a76e971dadd19610d3ad38c768e124dc7","schema_version":"edge-lab-recorder.raw.v1","sequence":null,"source":"clob_market_ws"}
{"event_at":"2026-07-28T03:00:26.107000Z","event_fingerprint":"d36aaa89fc80c465be5b08b90af9b5f0b190426dce46c45a2c6d017a2cb31b1c","payload":{"connection_id":"a6b55582af5f430fb37ad02bf0922475","event_at":"2026-07-28T03:00:26.107000Z","event_type":"price_change","frame_hash":"3af76ea316ba5d177f7c11e4c6a7430aaeaef053eeea84d3fff0bdc0d036b374","frame_index":0,"kind":"data","monotonic_ns":309612109971208,"payload":{"event_type":"price_change","market":"0x779291bef19b6709f61e9764a954aafe9ffae488d50ae674aabdcb4f248006d5","price_changes":[{"asset_id":"8761897749749422724209054078244794145777693856614463256546737399611489089783","best_ask":"0.41","best_bid":"0.4","hash":"7c4788285b4a9571fb2396c4e1c80d5ef7c78080","price":"0.37","side":"BUY","size":"10"},{"asset_id":"14965588658799411272385430903075831224615961675357217884735713260981483529984","best_ask":"0.6","best_bid":"0.59","hash":"ecca1621144401f9d097c1621a91d2aa26343cd7","price":"0.63","side":"SELL","size":"10"}],"timestamp":"1785207626107"},"payload_hash":"6245d3e52fed14d3871f95ca9f1ad5169998a31d954bfbee090570ec65e90599","raw_frame":"{\"market\":\"0x779291bef19b6709f61e9764a954aafe9ffae488d50ae674aabdcb4f248006d5\", \"price_changes\":[{\"asset_id\":\"8761897749749422724209054078244794145777693856614463256546737399611489089783\", \"price\":\"0.37\", \"size\":\"10\", \"side\":\"BUY\", \"hash\":\"7c4788285b4a9571fb2396c4e1c80d5ef7c78080\", \"best_bid\":\"0.4\", \"best_ask\":\"0.41\"}, {\"asset_id\":\"14965588658799411272385430903075831224615961675357217884735713260981483529984\", \"price\":\"0.63\", \"size\":\"10\", \"side\":\"SELL\", \"hash\":\"ecca1621144401f9d097c1621a91d2aa26343cd7\", \"best_bid\":\"0.59\", \"best_ask\":\"0.6\"}], \"timestamp\":\"1785207626107\", \"event_type\":\"price_change\"}","received_at":"2026-07-28T03:00:29.091403Z","schema_version":"clob-market-ws.price_change.v1","sequence":null,"server_hash":null,"server_timestamp":"1785207626107","session_id":"3e519d9098404c15b234d96025eb1a2b","source":"clob_market_ws"},"received_at":"2026-07-28T03:00:29.091403Z","record_id":"d941ebc1a3b533cbabe926027beff49c7d7d8a2d8cb4bddad39af91839eafecf","schema_fingerprint":"4aa3821a28b0b7c2400bc59aba4bcc0a76e971dadd19610d3ad38c768e124dc7","schema_version":"edge-lab-recorder.raw.v1","sequence":null,"source":"clob_market_ws"}
{"event_at":"2026-07-28T03:00:26.118000Z","event_fingerprint":"5fb7ad6e815e2e46081d6276ddf48d4c0aa77379c2d0c83fe73ca031bde42d50","payload":{"connection_id":"a6b55582af5f430fb37ad02bf0922475","event_at":"2026-07-28T03:00:26.118000Z","event_type":"price_change","frame_hash":"3efb2e620912a2ec224086dc89ba52e2d9c350167c4e333d619d11ceda7c80b3","frame_index":0,"kind":"data","monotonic_ns":309612114947083,"payload":{"event_type":"price_change","market":"0x779291bef19b6709f61e9764a954aafe9ffae488d50ae674aabdcb4f248006d5","price_changes":[{"asset_id":"14965588658799411272385430903075831224615961675357217884735713260981483529984","best_ask":"0.6","best_bid":"0.59","hash":"6889a67eb448152c96fea5bb325d46593cd0a83c","price":"0.01","side":"BUY","size":"7555.02"},{"asset_id":"8761897749749422724209054078244794145777693856614463256546737399611489089783","best_ask":"0.41","best_bid":"0.4","hash":"afa6c18deb3a9824cb8c650e9f96f41016c07878","price":"0.99","side":"SELL","size":"7555.02"}],"timestamp":"1785207626118"},"payload_hash":"70a567bccd93b524e32298688a33320bdd5e6bf18c6b280ed5a514189067d9db","raw_frame":"{\"market\":\"0x779291bef19b6709f61e9764a954aafe9ffae488d50ae674aabdcb4f248006d5\", \"price_changes\":[{\"asset_id\":\"14965588658799411272385430903075831224615961675357217884735713260981483529984\", \"price\":\"0.01\", \"size\":\"7555.02\", \"side\":\"BUY\", \"hash\":\"6889a67eb448152c96fea5bb325d46593cd0a83c\", \"best_bid\":\"0.59\", \"best_ask\":\"0.6\"}, {\"asset_id\":\"8761897749749422724209054078244794145777693856614463256546737399611489089783\", \"price\":\"0.99\", \"size\":\"7555.02\", \"side\":\"SELL\", \"hash\":\"afa6c18deb3a9824cb8c650e9f96f41016c07878\", \"best_bid\":\"0.4\", \"best_ask\":\"0.41\"}], \"timestamp\":\"1785207626118\", \"event_type\":\"price_change\"}","received_at":"2026-07-28T03:00:29.096379Z","schema_version":"clob-market-ws.price_change.v1","sequence":null,"server_hash":null,"server_timestamp":"1785207626118","session_id":"3e519d9098404c15b234d96025eb1a2b","source":"clob_market_ws"},"received_at":"2026-07-28T03:00:29.096379Z","record_id":"69abdf5500a6c425c21e070a6a9b8540ab6c10fec0f2a8bbfb37fcba53df3c72","schema_fingerprint":"4aa3821a28b0b7c2400bc59aba4bcc0a76e971dadd19610d3ad38c768e124dc7","schema_version":"edge-lab-recorder.raw.v1","sequence":null,"source":"clob_market_ws"}
{"event_at":"2026-07-28T03:00:26.121000Z","event_fingerprint":"d8e4842e4880d812ef09d21d2455e6c964850879bddfaa17a4d87eb77d0b15fb","payload":{"connection_id":"a6b55582af5f430fb37ad02bf0922475","event_at":"2026-07-28T03:00:26.121000Z","event_type":"price_change","frame_hash":"420cf33c3bea5b834c8525c1bb4ca1e73c2fbed1301260b4f093b740c70fa662","frame_index":0,"kind":"data","monotonic_ns":309612123701833,"payload":{"event_type":"price_change","market":"0x779291bef19b6709f61e9764a954aafe9ffae488d50ae674aabdcb4f248006d5","price_changes":[{"asset_id":"8761897749749422724209054078244794145777693856614463256546737399611489089783","best_ask":"0.41","best_bid":"0.4","hash":"dc91c60e07fec18f017e49d94118419a04cab659","price":"0.2","side":"BUY","size":"209.66"},{"asset_id":"14965588658799411272385430903075831224615961675357217884735713260981483529984","best_ask":"0.6","best_bid":"0.59","hash":"cab863e1a5e059ba98d7ee949e358f54a02df4af","price":"0.8","side":"SELL","size":"209.66"}],"timestamp":"1785207626121"},"payload_hash":"c9983df486d11a250dd7cfb3fc2ad0cc352ac9996c501e5c076dbd6d16bf90b7","raw_frame":"{\"market\":\"0x779291bef19b6709f61e9764a954aafe9ffae488d50ae674aabdcb4f248006d5\", \"price_changes\":[{\"asset_id\":\"8761897749749422724209054078244794145777693856614463256546737399611489089783\", \"price\":\"0.2\", \"size\":\"209.66\", \"side\":\"BUY\", \"hash\":\"dc91c60e07fec18f017e49d94118419a04cab659\", \"best_bid\":\"0.4\", \"best_ask\":\"0.41\"}, {\"asset_id\":\"14965588658799411272385430903075831224615961675357217884735713260981483529984\", \"price\":\"0.8\", \"size\":\"209.66\", \"side\":\"SELL\", \"hash\":\"cab863e1a5e059ba98d7ee949e358f54a02df4af\", \"best_bid\":\"0.59\", \"best_ask\":\"0.6\"}], \"timestamp\":\"1785207626121\", \"event_type\":\"price_change\"}","received_at":"2026-07-28T03:00:29.105126Z","schema_version":"clob-market-ws.price_change.v1","sequence":null,"server_hash":null,"server_timestamp":"1785207626121","session_id":"3e519d9098404c15b234d96025eb1a2b","source":"clob_market_ws"},"received_at":"2026-07-28T03:00:29.105126Z","record_id":"d10626a1c159228bf32490a8500b679237f109d59c71cd8ff27fd6644010e41d","schema_fingerprint":"4aa3821a28b0b7c2400bc59aba4bcc0a76e971dadd19610d3ad38c768e124dc7","schema_version":"edge-lab-recorder.raw.v1","sequence":null,"source":"clob_market_ws"}
{"event_at":"2026-07-28T03:00:26.123000Z","event_fingerprint":"1faee5cc98346115ccad0accf658527890e673fa85ffb77ebd2c46adebcbe03f","payload":{"connection_id":"a6b55582af5f430fb37ad02bf0922475","event_at":"2026-07-28T03:00:26.123000Z","event_type":"price_change","frame_hash":"587839e6d6056dfaf30ba05a3235f32cb8f40af6e4541ecaca8d7afc67730c47","frame_index":0,"kind":"data","monotonic_ns":309612128328625,"payload":{"event_type":"price_change","market":"0x779291bef19b6709f61e9764a954aafe9ffae488d50ae674aabdcb4f248006d5","price_changes":[{"asset_id":"8761897749749422724209054078244794145777693856614463256546737399611489089783","best_ask":"0.41","best_bid":"0.4","hash":"475560966e9e166cb0d87a147ff9d71bcfe2a867","price":"0.35","side":"BUY","size":"242"},{"asset_id":"14965588658799411272385430903075831224615961675357217884735713260981483529984","best_ask":"0.6","best_bid":"0.59","hash":"5998ed5ea472bb82edad023f5ce8f71b7c2f65d5","price":"0.65","side":"SELL","size":"242"}],"timestamp":"1785207626123"},"payload_hash":"b258fe4635c80f5d511204bd85ebcb294015479ed392bb79468dbae2bfeb64dc","raw_frame":"{\"market\":\"0x779291bef19b6709f61e9764a954aafe9ffae488d50ae674aabdcb4f248006d5\", \"price_changes\":[{\"asset_id\":\"8761897749749422724209054078244794145777693856614463256546737399611489089783\", \"price\":\"0.35\", \"size\":\"242\", \"side\":\"BUY\", \"hash\":\"475560966e9e166cb0d87a147ff9d71bcfe2a867\", \"best_bid\":\"0.4\", \"best_ask\":\"0.41\"}, {\"asset_id\":\"14965588658799411272385430903075831224615961675357217884735713260981483529984\", \"price\":\"0.65\", \"size\":\"242\", \"side\":\"SELL\", \"hash\":\"5998ed5ea472bb82edad023f5ce8f71b7c2f65d5\", \"best_bid\":\"0.59\", \"best_ask\":\"0.6\"}], \"timestamp\":\"1785207626123\", \"event_type\":\"price_change\"}","received_at":"2026-07-28T03:00:29.109754Z","schema_version":"clob-market-ws.price_change.v1","sequence":null,"server_hash":null,"server_timestamp":"1785207626123","session_id":"3e519d9098404c15b234d96025eb1a2b","source":"clob_market_ws"},"received_at":"2026-07-28T03:00:29.109754Z","record_id":"dae079eac1a012be5b0a75e2d28ed0387f4be4d6169ffdd29da8ee0e14ff991d","schema_fingerprint":"4aa3821a28b0b7c2400bc59aba4bcc0a76e971dadd19610d3ad38c768e124dc7","schema_version":"edge-lab-recorder.raw.v1","sequence":null,"source":"clob_market_ws"}
{"event_at":"2026-07-28T03:00:26.124000Z","event_fingerprint":"a832202f8037c0d0ed4049a44a68f039b841537fb6f727553d08297aca33ec60","payload":{"connection_id":"a6b55582af5f430fb37ad02bf0922475","event_at":"2026-07-28T03:00:26.124000Z","event_type":"price_change","frame_hash":"9856a4a94a0d70793ff8fa6fe4a2bc8c5dd491c4a2c9737150bbddafe5f47f08","frame_index":0,"kind":"data","monotonic_ns":309612131609416,"payload":{"event_type":"price_change","market":"0x779291bef19b6709f61e9764a954aafe9ffae488d50ae674aabdcb4f248006d5","price_changes":[{"asset_id":"14965588658799411272385430903075831224615961675357217884735713260981483529984","best_ask":"0.6","best_bid":"0.59","hash":"7140fed442dde0105b2c5b0fe7497347aa95d33f","price":"0.59","side":"BUY","size":"153.43"},{"asset_id":"8761897749749422724209054078244794145777693856614463256546737399611489089783","best_ask":"0.41","best_bid":"0.4","hash":"9a704ff12c647753d1c53b84368c4c3c3d00a8f2","price":"0.41","side":"SELL","size":"153.43"}],"timestamp":"1785207626124"},"payload_hash":"a78ae42940d2ff1590d5eb137bc3b1c7c7bd6d31ccda0ddfc2f6acca94ab1d7e","raw_frame":"{\"market\":\"0x779291bef19b6709f61e9764a954aafe9ffae488d50ae674aabdcb4f248006d5\", \"price_changes\":[{\"asset_id\":\"14965588658799411272385430903075831224615961675357217884735713260981483529984\", \"price\":\"0.59\", \"size\":\"153.43\", \"side\":\"BUY\", \"hash\":\"7140fed442dde0105b2c5b0fe7497347aa95d33f\", \"best_bid\":\"0.59\", \"best_ask\":\"0.6\"}, {\"asset_id\":\"8761897749749422724209054078244794145777693856614463256546737399611489089783\", \"price\":\"0.41\", \"size\":\"153.43\", \"side\":\"SELL\", \"hash\":\"9a704ff12c647753d1c53b84368c4c3c3d00a8f2\", \"best_bid\":\"0.4\", \"best_ask\":\"0.41\"}], \"timestamp\":\"1785207626124\", \"event_type\":\"price_change\"}","received_at":"2026-07-28T03:00:29.113033Z","schema_version":"clob-market-ws.price_change.v1","sequence":null,"server_hash":null,"server_timestamp":"1785207626124","session_id":"3e519d9098404c15b234d96025eb1a2b","source":"clob_market_ws"},"received_at":"2026-07-28T03:00:29.113033Z","record_id":"dfbfec5311e8e256c1fc3498bc84fa319db40a470d4c13c29592afe2883d8d90","schema_fingerprint":"4aa3821a28b0b7c2400bc59aba4bcc0a76e971dadd19610d3ad38c768e124dc7","schema_version":"edge-lab-recorder.raw.v1","sequence":null,"source":"clob_market_ws"}
{"event_at":"2026-07-28T03:00:26.127000Z","event_fingerprint":"3d1fd969de450c23c17f00c82223eac43b92763af58295070f0c7e48f8ab3b59","payload":{"connection_id":"a6b55582af5f430fb37ad02bf0922475","event_at":"2026-07-28T03:00:26.127000Z","event_type":"price_change","frame_hash":"8d7640ea92371686e4818d8a9169f5af3e8699b8ce1d66ce2c1be3dc8e85bb9c","frame_index":0,"kind":"data","monotonic_ns":309612138171583,"payload":{"event_type":"price_change","market":"0x779291bef19b6709f61e9764a954aafe9ffae488d50ae674aabdcb4f248006d5","price_changes":[{"asset_id":"8761897749749422724209054078244794145777693856614463256546737399611489089783","best_ask":"0.41","best_bid":"0.4","hash":"b998ddbeaa89030203a4ab97450accc21ba7d637","price":"0.37","side":"BUY","size":"16"},{"asset_id":"14965588658799411272385430903075831224615961675357217884735713260981483529984","best_ask":"0.6","best_bid":"0.59","hash":"769daaa13ae016409cb5bac196978be994aa2c8f","price":"0.63","side":"SELL","size":"16"}],"timestamp":"1785207626127"},"payload_hash":"62c96f3d292c87f9847368d9739f6391f7f87f4ee742b0f2dd5420e66b9c31f4","raw_frame":"{\"market\":\"0x779291bef19b6709f61e9764a954aafe9ffae488d50ae674aabdcb4f248006d5\", \"price_changes\":[{\"asset_id\":\"8761897749749422724209054078244794145777693856614463256546737399611489089783\", \"price\":\"0.37\", \"size\":\"16\", \"side\":\"BUY\", \"hash\":\"b998ddbeaa89030203a4ab97450accc21ba7d637\", \"best_bid\":\"0.4\", \"best_ask\":\"0.41\"}, {\"asset_id\":\"14965588658799411272385430903075831224615961675357217884735713260981483529984\", \"price\":\"0.63\", \"size\":\"16\", \"side\":\"SELL\", \"hash\":\"769daaa13ae016409cb5bac196978be994aa2c8f\", \"best_bid\":\"0.59\", \"best_ask\":\"0.6\"}], \"timestamp\":\"1785207626127\", \"event_type\":\"price_change\"}","received_at":"2026-07-28T03:00:29.119598Z","schema_version":"clob-market-ws.price_change.v1","sequence":null,"server_hash":null,"server_timestamp":"1785207626127","session_id":"3e519d9098404c15b234d96025eb1a2b","source":"clob_market_ws"},"received_at":"2026-07-28T03:00:29.119598Z","record_id":"94be84e8f0e3ae7695004af9f173ceb2d389c0ed21bb2e66c044b75e4d1adcbc","schema_fingerprint":"4aa3821a28b0b7c2400bc59aba4bcc0a76e971dadd19610d3ad38c768e124dc7","schema_version":"edge-lab-recorder.raw.v1","sequence":null,"source":"clob_market_ws"}
{"event_at":"2026-07-28T03:00:26.128000Z","event_fingerprint":"547b845fbb9cc177a59bad2a71b776ab5d18fc072bbf76f3745f6f6a5fb4d3c9","payload":{"connection_id":"a6b55582af5f430fb37ad02bf0922475","event_at":"2026-07-28T03:00:26.128000Z","event_type":"price_change","frame_hash":"03e8a4b14ede1bf1ba94464ac956f5ebd3a5bacc9cf9c1dbfa2cc3f2950aafc4","frame_index":0,"kind":"data","monotonic_ns":309612145944500,"payload":{"event_type":"price_change","market":"0x779291bef19b6709f61e9764a954aafe9ffae488d50ae674aabdcb4f248006d5","price_changes":[{"asset_id":"8761897749749422724209054078244794145777693856614463256546737399611489089783","best_ask":"0.41","best_bid":"0.4","hash":"800cd31bcd20aa608d1a417cadf5a213b7f48716","price":"0.3","side":"BUY","size":"133.06"},{"asset_id":"14965588658799411272385430903075831224615961675357217884735713260981483529984","best_ask":"0.6","best_bid":"0.59","hash":"e14ac470e2391b2d9184cb3a4db6c08ac97713f3","price":"0.7","side":"SELL","size":"133.06"}],"timestamp":"1785207626128"},"payload_hash":"47ceeb5a3ad453c11d3fe32497aeb0b0acd6fec6215c45fdfda38ed0078ad4a7","raw_frame":"{\"market\":\"0x779291bef19b6709f61e9764a954aafe9ffae488d50ae674aabdcb4f248006d5\", \"price_changes\":[{\"asset_id\":\"8761897749749422724209054078244794145777693856614463256546737399611489089783\", \"price\":\"0.3\", \"size\":\"133.06\", \"side\":\"BUY\", \"hash\":\"800cd31bcd20aa608d1a417cadf5a213b7f48716\", \"best_bid\":\"0.4\", \"best_ask\":\"0.41\"}, {\"asset_id\":\"14965588658799411272385430903075831224615961675357217884735713260981483529984\", \"price\":\"0.7\", \"size\":\"133.06\", \"side\":\"SELL\", \"hash\":\"e14ac470e2391b2d9184cb3a4db6c08ac97713f3\", \"best_bid\":\"0.59\", \"best_ask\":\"0.6\"}], \"timestamp\":\"1785207626128\", \"event_type\":\"price_change\"}","received_at":"2026-07-28T03:00:29.127371Z","schema_version":"clob-market-ws.price_change.v1","sequence":null,"server_hash":null,"server_timestamp":"1785207626128","session_id":"3e519d9098404c15b234d96025eb1a2b","source":"clob_market_ws"},"received_at":"2026-07-28T03:00:29.127371Z","record_id":"4cd957e7a66313a34bc0c878d2a2ba80c33973fee44f27ff7667dd66acd8d076","schema_fingerprint":"4aa3821a28b0b7c2400bc59aba4bcc0a76e971dadd19610d3ad38c768e124dc7","schema_version":"edge-lab-recorder.raw.v1","sequence":null,"source":"clob_market_ws"}
{"event_at":"2026-07-28T03:00:26.138000Z","event_fingerprint":"0381a34cb34cb5e36ec551cc11e793b1d9d441a8ee4eb83d3a8747f4cf76da76","payload":{"connection_id":"a6b55582af5f430fb37ad02bf0922475","event_at":"2026-07-28T03:00:26.138000Z","event_type":"price_change","frame_hash":"9dd96849f6b542033b95c501e841d822ceb08b8cb0e6a71cd5e76171ab3dfd60","frame_index":0,"kind":"data","monotonic_ns":309612153938916,"payload":{"event_type":"price_change","market":"0x779291bef19b6709f61e9764a954aafe9ffae488d50ae674aabdcb4f248006d5","price_changes":[{"asset_id":"8761897749749422724209054078244794145777693856614463256546737399611489089783","best_ask":"0.41","best_bid":"0.4","hash":"130e889bdd975bf5405f2064b6291c183979ba57","price":"0.3","side":"BUY","size":"145.06"},{"asset_id":"14965588658799411272385430903075831224615961675357217884735713260981483529984","best_ask":"0.6","best_bid":"0.59","hash":"8abd8da74e53d9897560c54c2078c957b5c58a50","price":"0.7","side":"SELL","size":"145.06"}],"timestamp":"1785207626138"},"payload_hash":"72dfd83ca8bec056ee9cf1a41fae1c200f6b2d946bdd7e5e4ed8fc150284212c","raw_frame":"{\"market\":\"0x779291bef19b6709f61e9764a954aafe9ffae488d50ae674aabdcb4f248006d5\", \"price_changes\":[{\"asset_id\":\"8761897749749422724209054078244794145777693856614463256546737399611489089783\", \"price\":\"0.3\", \"size\":\"145.06\", \"side\":\"BUY\", \"hash\":\"130e889bdd975bf5405f2064b6291c183979ba57\", \"best_bid\":\"0.4\", \"best_ask\":\"0.41\"}, {\"asset_id\":\"14965588658799411272385430903075831224615961675357217884735713260981483529984\", \"price\":\"0.7\", \"size\":\"145.06\", \"side\":\"SELL\", \"hash\":\"8abd8da74e53d9897560c54c2078c957b5c58a50\", \"best_bid\":\"0.59\", \"best_ask\":\"0.6\"}], \"timestamp\":\"1785207626138\", \"event_type\":\"price_change\"}","received_at":"2026-07-28T03:00:29.135365Z","schema_version":"clob-market-ws.price_change.v1","sequence":null,"server_hash":null,"server_timestamp":"1785207626138","session_id":"3e519d9098404c15b234d96025eb1a2b","source":"clob_market_ws"},"received_at":"2026-07-28T03:00:29.135365Z","record_id":"d128cd674727bd44e2c228c761fa63017fb698740f6da4422bcf4598c177c575","schema_fingerprint":"4aa3821a28b0b7c2400bc59aba4bcc0a76e971dadd19610d3ad38c768e124dc7","schema_version":"edge-lab-recorder.raw.v1","sequence":null,"source":"clob_market_ws"}
{"event_at":"2026-07-28T03:00:26.140000Z","event_fingerprint":"12cd5f06d4202145984e75750d18fe61f6ba098c3b7882b5fd764ca75f348025","payload":{"connection_id":"a6b55582af5f430fb37ad02bf0922475","event_at":"2026-07-28T03:00:26.140000Z","event_type":"price_change","frame_hash":"b9462a4d194a02eadc55a5792730f61f54c271442e3d340d22a8ab7795a6ef15","frame_index":0,"kind":"data","monotonic_ns":309612160454541,"payload":{"event_type":"price_change","market":"0x779291bef19b6709f61e9764a954aafe9ffae488d50ae674aabdcb4f248006d5","price_changes":[{"asset_id":"14965588658799411272385430903075831224615961675357217884735713260981483529984","best_ask":"0.6","best_bid":"0.59","hash":"08cf1d3bbe5711655b27b30ff009b9a735217a00","price":"0.01","side":"BUY","size":"7550.02"},{"asset_id":"8761897749749422724209054078244794145777693856614463256546737399611489089783","best_ask":"0.41","best_bid":"0.4","hash":"ef96944d59b64443ab1414d46beb22fd26a6bf9a","price":"0.99","side":"SELL","size":"7550.02"}],"timestamp":"1785207626140"},"payload_hash":"3254c61f924d75280239f35a09680a3f8400f05df8fa21a2e8036088e9aa869a","raw_frame":"{\"market\":\"0x779291bef19b6709f61e9764a954aafe9ffae488d50ae674aabdcb4f248006d5\", \"price_changes\":[{\"asset_id\":\"14965588658799411272385430903075831224615961675357217884735713260981483529984\", \"price\":\"0.01\", \"size\":\"7550.02\", \"side\":\"BUY\", \"hash\":\"08cf1d3bbe5711655b27b30ff009b9a735217a00\", \"best_bid\":\"0.59\", \"best_ask\":\"0.6\"}, {\"asset_id\":\"8761897749749422724209054078244794145777693856614463256546737399611489089783\", \"price\":\"0.99\", \"size\":\"7550.02\", \"side\":\"SELL\", \"hash\":\"ef96944d59b64443ab1414d46beb22fd26a6bf9a\", \"best_bid\":\"0.4\", \"best_ask\":\"0.41\"}], \"timestamp\":\"1785207626140\", \"event_type\":\"price_change\"}","received_at":"2026-07-28T03:00:29.141881Z","schema_version":"clob-market-ws.price_change.v1","sequence":null,"server_hash":null,"server_timestamp":"1785207626140","session_id":"3e519d9098404c15b234d96025eb1a2b","source":"clob_market_ws"},"received_at":"2026-07-28T03:00:29.141881Z","record_id":"98b032f2405605f3aee10dde59b149f11ad221981f8bb9d15808c7702b797a24","schema_fingerprint":"4aa3821a28b0b7c2400bc59aba4bcc0a76e971dadd19610d3ad38c768e124dc7","schema_version":"edge-lab-recorder.raw.v1","sequence":null,"source":"clob_market_ws"}
{"event_at":"2026-07-28T03:00:26.153000Z","event_fingerprint":"365985cfe7bab8a65973fcb79b29b55b8785c93c6df6f918fc0c109b2bb3ff2b","payload":{"connection_id":"a6b55582af5f430fb37ad02bf0922475","event_at":"2026-07-28T03:00:26.153000Z","event_type":"price_change","frame_hash":"04a987db32aa30c874520b3e0a2905ec545ba3fb10beb89361a183352d292496","frame_index":0,"kind":"data","monotonic_ns":309612165250083,"payload":{"event_type":"price_change","market":"0x779291bef19b6709f61e9764a954aafe9ffae488d50ae674aabdcb4f248006d5","price_changes":[{"asset_id":"14965588658799411272385430903075831224615961675357217884735713260981483529984","best_ask":"0.6","best_bid":"0.59","hash":"971dff465056ddc1f513864bd57e4d0e6cfdee7e","price":"0.04","side":"BUY","size":"775"},{"asset_id":"8761897749749422724209054078244794145777693856614463256546737399611489089783","best_ask":"0.41","best_bid":"0.4","hash":"2da545153988d4d4d37b37a84ba5c7b83b8f3979","price":"0.96","side":"SELL","size":"775"}],"timestamp":"1785207626153"},"payload_hash":"9d6b9b62506c246b3b979685e3d0ee7bce83d4a8e4c3ca53fa5490301cd0c30c","raw_frame":"{\"market\":\"0x779291bef19b6709f61e9764a954aafe9ffae488d50ae674aabdcb4f248006d5\", \"price_changes\":[{\"asset_id\":\"14965588658799411272385430903075831224615961675357217884735713260981483529984\", \"price\":\"0.04\", \"size\":\"775\", \"side\":\"BUY\", \"hash\":\"971dff465056ddc1f513864bd57e4d0e6cfdee7e\", \"best_bid\":\"0.59\", \"best_ask\":\"0.6\"}, {\"asset_id\":\"8761897749749422724209054078244794145777693856614463256546737399611489089783\", \"price\":\"0.96\", \"size\":\"775\", \"side\":\"SELL\", \"hash\":\"2da545153988d4d4d37b37a84ba5c7b83b8f3979\", \"best_bid\":\"0.4\", \"best_ask\":\"0.41\"}], \"timestamp\":\"1785207626153\", \"event_type\":\"price_change\"}","received_at":"2026-07-28T03:00:29.146677Z","schema_version":"clob-market-ws.price_change.v1","sequence":null,"server_hash":null,"server_timestamp":"1785207626153","session_id":"3e519d9098404c15b234d96025eb1a2b","source":"clob_market_ws"},"received_at":"2026-07-28T03:00:29.146677Z","record_id":"13e0fca9a81ac3d12e9825721ff9e7b46c06586ddb741a26ff386e692e21330c","schema_fingerprint":"4aa3821a28b0b7c2400bc59aba4bcc0a76e971dadd19610d3ad38c768e124dc7","schema_version":"edge-lab-recorder.raw.v1","sequence":null,"source":"clob_market_ws"}
{"event_at":"2026-07-28T03:00:26.157000Z","event_fingerprint":"d19975c52c25528d557e9f9b70a83ce2e51c55779cfde3474fc7fd30616df845","payload":{"connection_id":"a6b55582af5f430fb37ad02bf0922475","event_at":"2026-07-28T03:00:26.157000Z","event_type":"price_change","frame_hash":"4d45e66ecbd711d5f561514f5afa1bdec26f4f5741fb61ce5f5e046b62a95d80","frame_index":0,"kind":"data","monotonic_ns":309612169918291,"payload":{"event_type":"price_change","market":"0x779291bef19b6709f61e9764a954aafe9ffae488d50ae674aabdcb4f248006d5","price_changes":[{"asset_id":"8761897749749422724209054078244794145777693856614463256546737399611489089783","best_ask":"0.41","best_bid":"0.4","hash":"064e8bad910f063ed1ab7fd7fcdff5f43b631850","price":"0.22","side":"BUY","size":"44"},{"asset_id":"14965588658799411272385430903075831224615961675357217884735713260981483529984","best_ask":"0.6","best_bid":"0.59","hash":"70c6b24eeb88802aad4ea5108e243ca3880efa63","price":"0.78","side":"SELL","size":"44"}],"timestamp":"1785207626157"},"payload_hash":"06bac4ce1669259f627237137a62730ac3d59e24ba6c108c7ffee730aee46d7b","raw_frame":"{\"market\":\"0x779291bef19b6709f61e9764a954aafe9ffae488d50ae674aabdcb4f248006d5\", \"price_changes\":[{\"asset_id\":\"8761897749749422724209054078244794145777693856614463256546737399611489089783\", \"price\":\"0.22\", \"size\":\"44\", \"side\":\"BUY\", \"hash\":\"064e8bad910f063ed1ab7fd7fcdff5f43b631850\", \"best_bid\":\"0.4\", \"best_ask\":\"0.41\"}, {\"asset_id\":\"14965588658799411272385430903075831224615961675357217884735713260981483529984\", \"price\":\"0.78\", \"size\":\"44\", \"side\":\"SELL\", \"hash\":\"70c6b24eeb88802aad4ea5108e243ca3880efa63\", \"best_bid\":\"0.59\", \"best_ask\":\"0.6\"}], \"timestamp\":\"1785207626157\", \"event_type\":\"price_change\"}","received_at":"2026-07-28T03:00:29.151344Z","schema_version":"clob-market-ws.price_change.v1","sequence":null,"server_hash":null,"server_timestamp":"1785207626157","session_id":"3e519d9098404c15b234d96025eb1a2b","source":"clob_market_ws"},"received_at":"2026-07-28T03:00:29.151344Z","record_id":"39352ed602fb4cfa7b0d34a3271153eb83708cfd995ffe4c45244230a93fe6de","schema_fingerprint":"4aa3821a28b0b7c2400bc59aba4bcc0a76e971dadd19610d3ad38c768e124dc7","schema_version":"edge-lab-recorder.raw.v1","sequence":null,"source":"clob_market_ws"}
{"event_at":"2026-07-28T03:00:26.212000Z","event_fingerprint":"7af97fbc8708b76cbb96773063c68078d1132ba8462e3dc6a64a9f0f15921ae9","payload":{"connection_id":"a6b55582af5f430fb37ad02bf0922475","event_at":"2026-07-28T03:00:26.212000Z","event_type":"price_change","frame_hash":"d625eae83b05ba72307813683077cbd8fad0cacb6d986ec90d807b25e91494e4","frame_index":0,"kind":"data","monotonic_ns":309612175432583,"payload":{"event_type":"price_change","market":"0x779291bef19b6709f61e9764a954aafe9ffae488d50ae674aabdcb4f248006d5","price_changes":[{"asset_id":"8761897749749422724209054078244794145777693856614463256546737399611489089783","best_ask":"0.41","best_bid":"0.4","hash":"ce15d84398a12c19e114e1faffaa68d6a2e3ca20","price":"0.32","side":"BUY","size":"159"},{"asset_id":"14965588658799411272385430903075831224615961675357217884735713260981483529984","best_ask":"0.6","best_bid":"0.59","hash":"a934dbd37ac610d75f218b5ffe1af9a8b2f18d32","price":"0.68","side":"SELL","size":"159"}],"timestamp":"1785207626212"},"payload_hash":"a273bdaade9e8e34f6ca8d04e9574cf75ea9e1fd0dff8d816013dd56040c01e2","raw_frame":"{\"market\":\"0x779291bef19b6709f61e9764a954aafe9ffae488d50ae674aabdcb4f248006d5\", \"price_changes\":[{\"asset_id\":\"8761897749749422724209054078244794145777693856614463256546737399611489089783\", \"price\":\"0.32\", \"size\":\"159\", \"side\":\"BUY\", \"hash\":\"ce15d84398a12c19e114e1faffaa68d6a2e3ca20\", \"best_bid\":\"0.4\", \"best_ask\":\"0.41\"}, {\"asset_id\":\"14965588658799411272385430903075831224615961675357217884735713260981483529984\", \"price\":\"0.68\", \"size\":\"159\", \"side\":\"SELL\", \"hash\":\"a934dbd37ac610d75f218b5ffe1af9a8b2f18d32\", \"best_bid\":\"0.59\", \"best_ask\":\"0.6\"}], \"timestamp\":\"1785207626212\", \"event_type\":\"price_change\"}","received_at":"2026-07-28T03:00:29.156859Z","schema_version":"clob-market-ws.price_change.v1","sequence":null,"server_hash":null,"server_timestamp":"1785207626212","session_id":"3e519d9098404c15b234d96025eb1a2b","source":"clob_market_ws"},"received_at":"2026-07-28T03:00:29.156859Z","record_id":"20d496167d13cb2729dc0e667baebba964bdc53bda4ecb882744621710ce0f77","schema_fingerprint":"4aa3821a28b0b7c2400bc59aba4bcc0a76e971dadd19610d3ad38c768e124dc7","schema_version":"edge-lab-recorder.raw.v1","sequence":null,"source":"clob_market_ws"}
{"event_at":"2026-07-28T03:00:26.214000Z","event_fingerprint":"7aa54b0fc1fdc5fb9dc467a85655335798e8654d004d068d61ba440997977c0a","payload":{"connection_id":"a6b55582af5f430fb37ad02bf0922475","event_at":"2026-07-28T03:00:26.214000Z","event_type":"price_change","frame_hash":"93e606cdb26632339828c919de5d01edf6c3271b4d81aaf91dfae4423956a2a4","frame_index":0,"kind":"data","monotonic_ns":309612181490916,"payload":{"event_type":"price_change","market":"0x779291bef19b6709f61e9764a954aafe9ffae488d50ae674aabdcb4f248006d5","price_changes":[{"asset_id":"8761897749749422724209054078244794145777693856614463256546737399611489089783","best_ask":"0.41","best_bid":"0.4","hash":"aab0b99e6166b04271c393bcd3c8808bd2da9065","price":"0.32","side":"BUY","size":"129"},{"asset_id":"14965588658799411272385430903075831224615961675357217884735713260981483529984","best_ask":"0.6","best_bid":"0.59","hash":"a5154dd859cb8990f83e7f0c61f8cba7b06c4008","price":"0.68","side":"SELL","size":"129"}],"timestamp":"1785207626214"},"payload_hash":"1de16c301efbd59aab106ea0cdc87bfb2db3a58f4d7bfa7eab04fcce8cfe5e19","raw_frame":"{\"market\":\"0x779291bef19b6709f61e9764a954aafe9ffae488d50ae674aabdcb4f248006d5\", \"price_changes\":[{\"asset_id\":\"8761897749749422724209054078244794145777693856614463256546737399611489089783\", \"price\":\"0.32\", \"size\":\"129\", \"side\":\"BUY\", \"hash\":\"aab0b99e6166b04271c393bcd3c8808bd2da9065\", \"best_bid\":\"0.4\", \"best_ask\":\"0.41\"}, {\"asset_id\":\"14965588658799411272385430903075831224615961675357217884735713260981483529984\", \"price\":\"0.68\", \"size\":\"129\", \"side\":\"SELL\", \"hash\":\"a5154dd859cb8990f83e7f0c61f8cba7b06c4008\", \"best_bid\":\"0.59\", \"best_ask\":\"0.6\"}], \"timestamp\":\"1785207626214\", \"event_type\":\"price_change\"}","received_at":"2026-07-28T03:00:29.162907Z","schema_version":"clob-market-ws.price_change.v1","sequence":null,"server_hash":null,"server_timestamp":"1785207626214","session_id":"3e519d9098404c15b234d96025eb1a2b","source":"clob_market_ws"},"received_at":"2026-07-28T03:00:29.162907Z","record_id":"a0de04f5152b2b828d654049bd721f2215e5c1a2e6d61a5ae12f369e0b18a57f","schema_fingerprint":"4aa3821a28b0b7c2400bc59aba4bcc0a76e971dadd19610d3ad38c768e124dc7","schema_version":"edge-lab-recorder.raw.v1","sequence":null,"source":"clob_market_ws"}
{"event_at":"2026-07-28T03:00:26.215000Z","event_fingerprint":"4af7cf5fc9693074c28132dd3bc0e9986cb60c63aea51a2ea6a162febe081509","payload":{"connection_id":"a6b55582af5f430fb37ad02bf0922475","event_at":"2026-07-28T03:00:26.215000Z","event_type":"price_change","frame_hash":"5c28fb0884105fb55ac7881c304f6dcec546375b624dd886cdd5c5e643a026eb","frame_index":0,"kind":"data","monotonic_ns":309612186674750,"payload":{"event_type":"price_change","market":"0x779291bef19b6709f61e9764a954aafe9ffae488d50ae674aabdcb4f248006d5","price_changes":[{"asset_id":"8761897749749422724209054078244794145777693856614463256546737399611489089783","best_ask":"0.41","best_bid":"0.4","hash":"481edc17a4b0747ca666b38856859e03779a585e","price":"0.35","side":"BUY","size":"232"},{"asset_id":"14965588658799411272385430903075831224615961675357217884735713260981483529984","best_ask":"0.6","best_bid":"0.59","hash":"30c8c2d9cd5b8e2fa47148ad7125658693d9d69c","price":"0.65","side":"SELL","size":"232"}],"timestamp":"1785207626215"},"payload_hash":"e99be39ea3107fee1baaf893836714ee572b63d0e144c97d56ca653ae3682b4c","raw_frame":"{\"market\":\"0x779291bef19b6709f61e9764a954aafe9ffae488d50ae674aabdcb4f248006d5\", \"price_changes\":[{\"asset_id\":\"8761897749749422724209054078244794145777693856614463256546737399611489089783\", \"price\":\"0.35\", \"size\":\"232\", \"side\":\"BUY\", \"hash\":\"481edc17a4b0747ca666b38856859e03779a585e\", \"best_bid\":\"0.4\", \"best_ask\":\"0.41\"}, {\"asset_id\":\"14965588658799411272385430903075831224615961675357217884735713260981483529984\", \"price\":\"0.65\", \"size\":\"232\", \"side\":\"SELL\", \"hash\":\"30c8c2d9cd5b8e2fa47148ad7125658693d9d69c\", \"best_bid\":\"0.59\", \"best_ask\":\"0.6\"}], \"timestamp\":\"1785207626215\", \"event_type\":\"price_change\"}","received_at":"2026-07-28T03:00:29.168101Z","schema_version":"clob-market-ws.price_change.v1","sequence":null,"server_hash":null,"server_timestamp":"1785207626215","session_id":"3e519d9098404c15b234d96025eb1a2b","source":"clob_market_ws"},"received_at":"2026-07-28T03:00:29.168101Z","record_id":"ced47fc0f16225ca5c88ae255862d42c24a5ffda4b585baf9bd02d059ec11240","schema_fingerprint":"4aa3821a28b0b7c2400bc59aba4bcc0a76e971dadd19610d3ad38c768e124dc7","schema_version":"edge-lab-recorder.raw.v1","sequence":null,"source":"clob_market_ws"}
{"event_at":"2026-07-28T03:00:26.215000Z","event_fingerprint":"69b1d77b3f1d412e732e7b57dccfab14d534bea9140760a58c31092df5b75ea4","payload":{"connection_id":"a6b55582af5f430fb37ad02bf0922475","event_at":"2026-07-28T03:00:26.215000Z","event_type":"price_change","frame_hash":"cc6eb206bba8b1aa4cd68dde6d1e21979c068f66939ab096506bcc7016e1e991","frame_index":0,"kind":"data","monotonic_ns":309612193708208,"payload":{"event_type":"price_change","market":"0x779291bef19b6709f61e9764a954aafe9ffae488d50ae674aabdcb4f248006d5","price_changes":[{"asset_id":"8761897749749422724209054078244794145777693856614463256546737399611489089783","best_ask":"0.41","best_bid":"0.4","hash":"c999cb793568c1e5238292ff012943ae15ef9ed9","price":"0.32","side":"BUY","size":"99"},{"asset_id":"14965588658799411272385430903075831224615961675357217884735713260981483529984","best_ask":"0.6","best_bid":"0.59","hash":"850f5c7ebce0af2ad704f67de2311d98972a0556","price":"0.68","side":"SELL","size":"99"}],"timestamp":"1785207626215"},"payload_hash":"c34683715fe12019a11299541ce6544b0316f3bd23c0a3537b3117880f01cedc","raw_frame":"{\"market\":\"0x779291bef19b6709f61e9764a954aafe9ffae488d50ae674aabdcb4f248006d5\", \"price_changes\":[{\"asset_id\":\"8761897749749422724209054078244794145777693856614463256546737399611489089783\", \"price\":\"0.32\", \"size\":\"99\", \"side\":\"BUY\", \"hash\":\"c999cb793568c1e5238292ff012943ae15ef9ed9\", \"best_bid\":\"0.4\", \"best_ask\":\"0.41\"}, {\"asset_id\":\"14965588658799411272385430903075831224615961675357217884735713260981483529984\", \"price\":\"0.68\", \"size\":\"99\", \"side\":\"SELL\", \"hash\":\"850f5c7ebce0af2ad704f67de2311d98972a0556\", \"best_bid\":\"0.59\", \"best_ask\":\"0.6\"}], \"timestamp\":\"1785207626215\", \"event_type\":\"price_change\"}","received_at":"2026-07-28T03:00:29.175135Z","schema_version":"clob-market-ws.price_change.v1","sequence":null,"server_hash":null,"server_timestamp":"1785207626215","session_id":"3e519d9098404c15b234d96025eb1a2b","source":"clob_market_ws"},"received_at":"2026-07-28T03:00:29.175135Z","record_id":"c9af5bdb5d50a1dbd10960f6fc6fd67cd1ee6fb46c3eac8fb164465372c7e35b","schema_fingerprint":"4aa3821a28b0b7c2400bc59aba4bcc0a76e971dadd19610d3ad38c768e124dc7","schema_version":"edge-lab-recorder.raw.v1","sequence":null,"source":"clob_market_ws"}
{"event_at":"2026-07-28T03:00:26.217000Z","event_fingerprint":"b61dcc8328cd29cbf6e2d1730b807e4334843ab64c88a5be6955507ad348bcd2","payload":{"connection_id":"a6b55582af5f430fb37ad02bf0922475","event_at":"2026-07-28T03:00:26.217000Z","event_type":"price_change","frame_hash":"85c7366a03ffe7490581dac2f496376d97d192c83baf6277b8afd7b1c31c9ce8","frame_index":0,"kind":"data","monotonic_ns":309612198980333,"payload":{"event_type":"price_change","market":"0x779291bef19b6709f61e9764a954aafe9ffae488d50ae674aabdcb4f248006d5","price_changes":[{"asset_id":"8761897749749422724209054078244794145777693856614463256546737399611489089783","best_ask":"0.41","best_bid":"0.4","hash":"d9599f93c6f37851935a0c8c753ac5836b3d1065","price":"0.38","side":"BUY","size":"108.6"},{"asset_id":"14965588658799411272385430903075831224615961675357217884735713260981483529984","best_ask":"0.6","best_bid":"0.59","hash":"815afa18aaee3f8398c3ada742a70e299a8bbc52","price":"0.62","side":"SELL","size":"108.6"}],"timestamp":"1785207626217"},"payload_hash":"045d103e992f61ea45f7c7e1d1c267772602096578c553929cd0eb8ebc3c604a","raw_frame":"{\"market\":\"0x779291bef19b6709f61e9764a954aafe9ffae488d50ae674aabdcb4f248006d5\", \"price_changes\":[{\"asset_id\":\"8761897749749422724209054078244794145777693856614463256546737399611489089783\", \"price\":\"0.38\", \"size\":\"108.6\", \"side\":\"BUY\", \"hash\":\"d9599f93c6f37851935a0c8c753ac5836b3d1065\", \"best_bid\":\"0.4\", \"best_ask\":\"0.41\"}, {\"asset_id\":\"14965588658799411272385430903075831224615961675357217884735713260981483529984\", \"price\":\"0.62\", \"size\":\"108.6\", \"side\":\"SELL\", \"hash\":\"815afa18aaee3f8398c3ada742a70e299a8bbc52\", \"best_bid\":\"0.59\", \"best_ask\":\"0.6\"}], \"timestamp\":\"1785207626217\", \"event_type\":\"price_change\"}","received_at":"2026-07-28T03:00:29.180406Z","schema_version":"clob-market-ws.price_change.v1","sequence":null,"server_hash":null,"server_timestamp":"1785207626217","session_id":"3e519d9098404c15b234d96025eb1a2b","source":"clob_market_ws"},"received_at":"2026-07-28T03:00:29.180406Z","record_id":"cb28fa163d95455f8928eaf169daf044cc790be70cf95eda0a77b56987d63a10","schema_fingerprint":"4aa3821a28b0b7c2400bc59aba4bcc0a76e971dadd19610d3ad38c768e124dc7","schema_version":"edge-lab-recorder.raw.v1","sequence":null,"source":"clob_market_ws"}
{"event_at":"2026-07-28T03:00:26.218000Z","event_fingerprint":"6231ae5b5378e3a5e68af64b0d7af3ebf2ffb461dd0bfe46eae4ce14bcd8a0f8","payload":{"connection_id":"a6b55582af5f430fb37ad02bf0922475","event_at":"2026-07-28T03:00:26.218000Z","event_type":"price_change","frame_hash":"71c248f66aafb6065564e82093f1a82118a4510c6c022ac453240aca59e5fd12","frame_index":0,"kind":"data","monotonic_ns":309612204320208,"payload":{"event_type":"price_change","market":"0x779291bef19b6709f61e9764a954aafe9ffae488d50ae674aabdcb4f248006d5","price_changes":[{"asset_id":"14965588658799411272385430903075831224615961675357217884735713260981483529984","best_ask":"0.6","best_bid":"0.59","hash":"c79f1a93a7fb3ceb0225b0d853b64d1b20751e72","price":"0.59","side":"BUY","size":"423.43"},{"asset_id":"8761897749749422724209054078244794145777693856614463256546737399611489089783","best_ask":"0.41","best_bid":"0.4","hash":"3cedf6603f780ec89f64e61eef88d37175f1ec92","price":"0.41","side":"SELL","size":"423.43"}],"timestamp":"1785207626218"},"payload_hash":"434cb2c532b82ce656a400f5d18f178630e365c75abe816142876d776e4151c8","raw_frame":"{\"market\":\"0x779291bef19b6709f61e9764a954aafe9ffae488d50ae674aabdcb4f248006d5\", \"price_changes\":[{\"asset_id\":\"14965588658799411272385430903075831224615961675357217884735713260981483529984\", \"price\":\"0.59\", \"size\":\"423.43\", \"side\":\"BUY\", \"hash\":\"c79f1a93a7fb3ceb0225b0d853b64d1b20751e72\", \"best_bid\":\"0.59\", \"best_ask\":\"0.6\"}, {\"asset_id\":\"8761897749749422724209054078244794145777693856614463256546737399611489089783\", \"price\":\"0.41\", \"size\":\"423.43\", \"side\":\"SELL\", \"hash\":\"3cedf6603f780ec89f64e61eef88d37175f1ec92\", \"best_bid\":\"0.4\", \"best_ask\":\"0.41\"}], \"timestamp\":\"1785207626218\", \"event_type\":\"price_change\"}","received_at":"2026-07-28T03:00:29.185747Z","schema_version":"clob-market-ws.price_change.v1","sequence":null,"server_hash":null,"server_timestamp":"1785207626218","session_id":"3e519d9098404c15b234d96025eb1a2b","source":"clob_market_ws"},"received_at":"2026-07-28T03:00:29.185747Z","record_id":"cf87357d67825951079fd636a4dd3293e1bbaf38bf1456beae8bb13829bbbfce","schema_fingerprint":"4aa3821a28b0b7c2400bc59aba4bcc0a76e971dadd19610d3ad38c768e124dc7","schema_version":"edge-lab-recorder.raw.v1","sequence":null,"source":"clob_market_ws"}
{"event_at":"2026-07-28T03:00:26.219000Z","event_fingerprint":"4da4eda7aa503117dff4d6ab348b4d36968aabfe50592661f4bc274172392511","payload":{"connection_id":"a6b55582af5f430fb37ad02bf0922475","event_at":"2026-07-28T03:00:26.219000Z","event_type":"price_change","frame_hash":"efa81076e007e435b30c5d7ee611683d0738de8aa655b6b72c07f1b218521aa8","frame_index":0,"kind":"data","monotonic_ns":309612208852125,"payload":{"event_type":"price_change","market":"0x779291bef19b6709f61e9764a954aafe9ffae488d50ae674aabdcb4f248006d5","price_changes":[{"asset_id":"8761897749749422724209054078244794145777693856614463256546737399611489089783","best_ask":"0.41","best_bid":"0.4","hash":"325f05f9a46f5aaa4b0d88202c026b89e85f266b","price":"0.38","side":"BUY","size":"12.6"},{"asset_id":"14965588658799411272385430903075831224615961675357217884735713260981483529984","best_ask":"0.6","best_bid":"0.59","hash":"04e3094ae93e3770997d88c47af4c00ec4669a7b","price":"0.62","side":"SELL","size":"12.6"}],"timestamp":"1785207626219"},"payload_hash":"f4b18dfbcddd3455883276ca09e366803a8693465b3b9361b95b83eb0d1812da","raw_frame":"{\"market\":\"0x779291bef19b6709f61e9764a954aafe9ffae488d50ae674aabdcb4f248006d5\", \"price_changes\":[{\"asset_id\":\"8761897749749422724209054078244794145777693856614463256546737399611489089783\", \"price\":\"0.38\", \"size\":\"12.6\", \"side\":\"BUY\", \"hash\":\"325f05f9a46f5aaa4b0d88202c026b89e85f266b\", \"best_bid\":\"0.4\", \"best_ask\":\"0.41\"}, {\"asset_id\":\"14965588658799411272385430903075831224615961675357217884735713260981483529984\", \"price\":\"0.62\", \"size\":\"12.6\", \"side\":\"SELL\", \"hash\":\"04e3094ae93e3770997d88c47af4c00ec4669a7b\", \"best_bid\":\"0.59\", \"best_ask\":\"0.6\"}], \"timestamp\":\"1785207626219\", \"event_type\":\"price_change\"}","received_at":"2026-07-28T03:00:29.190279Z","schema_version":"clob-market-ws.price_change.v1","sequence":null,"server_hash":null,"server_timestamp":"1785207626219","session_id":"3e519d9098404c15b234d96025eb1a2b","source":"clob_market_ws"},"received_at":"2026-07-28T03:00:29.190279Z","record_id":"df64a9c4430b437c53dcdad46e9b9592d5ce0d8e35085385eaf8c048342efc31","schema_fingerprint":"4aa3821a28b0b7c2400bc59aba4bcc0a76e971dadd19610d3ad38c768e124dc7","schema_version":"edge-lab-recorder.raw.v1","sequence":null,"source":"clob_market_ws"}
{"event_at":"2026-07-28T03:00:26.219000Z","event_fingerprint":"9bbf34bcb7d46376646ba2eb37b23e64ea65da7a1fe0e27ea788def7663f8858","payload":{"connection_id":"a6b55582af5f430fb37ad02bf0922475","event_at":"2026-07-28T03:00:26.219000Z","event_type":"price_change","frame_hash":"5c819ed570f126a7fcf2318b359928cb4a96ff83d08bfcfe6f50309437f4f61e","frame_index":0,"kind":"data","monotonic_ns":309612213688625,"payload":{"event_type":"price_change","market":"0x779291bef19b6709f61e9764a954aafe9ffae488d50ae674aabdcb4f248006d5","price_changes":[{"asset_id":"14965588658799411272385430903075831224615961675357217884735713260981483529984","best_ask":"0.6","best_bid":"0.59","hash":"04e3094ae93e3770997d88c47af4c00ec4669a7b","price":"0.58","side":"BUY","size":"118.59"},{"asset_id":"8761897749749422724209054078244794145777693856614463256546737399611489089783","best_ask":"0.41","best_bid":"0.4","hash":"325f05f9a46f5aaa4b0d88202c026b89e85f266b","price":"0.42","side":"SELL","size":"118.59"}],"timestamp":"1785207626219"},"payload_hash":"498dd8be6e9531c2317fbcbbb1d21caa67a1b31f12d969b07443dfd00b9da966","raw_frame":"{\"market\":\"0x779291bef19b6709f61e9764a954aafe9ffae488d50ae674aabdcb4f248006d5\", \"price_changes\":[{\"asset_id\":\"14965588658799411272385430903075831224615961675357217884735713260981483529984\", \"price\":\"0.58\", \"size\":\"118.59\", \"side\":\"BUY\", \"hash\":\"04e3094ae93e3770997d88c47af4c00ec4669a7b\", \"best_bid\":\"0.59\", \"best_ask\":\"0.6\"}, {\"asset_id\":\"8761897749749422724209054078244794145777693856614463256546737399611489089783\", \"price\":\"0.42\", \"size\":\"118.59\", \"side\":\"SELL\", \"hash\":\"325f05f9a46f5aaa4b0d88202c026b89e85f266b\", \"best_bid\":\"0.4\", \"best_ask\":\"0.41\"}], \"timestamp\":\"1785207626219\", \"event_type\":\"price_change\"}","received_at":"2026-07-28T03:00:29.195115Z","schema_version":"clob-market-ws.price_change.v1","sequence":null,"server_hash":null,"server_timestamp":"1785207626219","session_id":"3e519d9098404c15b234d96025eb1a2b","source":"clob_market_ws"},"received_at":"2026-07-28T03:00:29.195115Z","record_id":"5197fbdb6cea487d151fa16cc2a18e8fec506f7327c2c7a039a0c64027f839dd","schema_fingerprint":"4aa3821a28b0b7c2400bc59aba4bcc0a76e971dadd19610d3ad38c768e124dc7","schema_version":"edge-lab-recorder.raw.v1","sequence":null,"source":"clob_market_ws"}
{"event_at":"2026-07-28T03:00:26.223000Z","event_fingerprint":"b3dcd1e0432527ec0db2d7f407395b37f18a2f06fe901d4f61d769c881326782","payload":{"connection_id":"a6b55582af5f430fb37ad02bf0922475","event_at":"2026-07-28T03:00:26.223000Z","event_type":"price_change","frame_hash":"673f306efdd2159b1faa3b00c01349d4f7f7af156643179fb93595e418a5174b","frame_index":0,"kind":"data","monotonic_ns":309612218640583,"payload":{"event_type":"price_change","market":"0x779291bef19b6709f61e9764a954aafe9ffae488d50ae674aabdcb4f248006d5","price_changes":[{"asset_id":"14965588658799411272385430903075831224615961675357217884735713260981483529984","best_ask":"0.6","best_bid":"0.59","hash":"6a403a0b1effbca98bafbbad36a4608943b003f1","price":"0.59","side":"BUY","size":"519.43"},{"asset_id":"8761897749749422724209054078244794145777693856614463256546737399611489089783","best_ask":"0.41","best_bid":"0.4","hash":"13ebe6731b26190043a34a1a61e3b2434840fead","price":"0.41","side":"SELL","size":"519.43"}],"timestamp":"1785207626223"},"payload_hash":"efa22bae22291b1a9620bf62e799735db464d064edfb20ec7a5a68a99293e43f","raw_frame":"{\"market\":\"0x779291bef19b6709f61e9764a954aafe9ffae488d50ae674aabdcb4f248006d5\", \"price_changes\":[{\"asset_id\":\"14965588658799411272385430903075831224615961675357217884735713260981483529984\", \"price\":\"0.59\", \"size\":\"519.43\", \"side\":\"BUY\", \"hash\":\"6a403a0b1effbca98bafbbad36a4608943b003f1\", \"best_bid\":\"0.59\", \"best_ask\":\"0.6\"}, {\"asset_id\":\"8761897749749422724209054078244794145777693856614463256546737399611489089783\", \"price\":\"0.41\", \"size\":\"519.43\", \"side\":\"SELL\", \"hash\":\"13ebe6731b26190043a34a1a61e3b2434840fead\", \"best_bid\":\"0.4\", \"best_ask\":\"0.41\"}], \"timestamp\":\"1785207626223\", \"event_type\":\"price_change\"}","received_at":"2026-07-28T03:00:29.200067Z","schema_version":"clob-market-ws.price_change.v1","sequence":null,"server_hash":null,"server_timestamp":"1785207626223","session_id":"3e519d9098404c15b234d96025eb1a2b","source":"clob_market_ws"},"received_at":"2026-07-28T03:00:29.200067Z","record_id":"cc59590a2710e01e7f21c2ec1ec5bb3e3c3d0c6a5b882696d1a1d3e6109d4f0c","schema_fingerprint":"4aa3821a28b0b7c2400bc59aba4bcc0a76e971dadd19610d3ad38c768e124dc7","schema_version":"edge-lab-recorder.raw.v1","sequence":null,"source":"clob_market_ws"}
{"event_at":"2026-07-28T03:00:26.224000Z","event_fingerprint":"6919016f028e73b619c4ab57b460cbb6c71b32a5829a3fb76cbe23c8e6555b70","payload":{"connection_id":"a6b55582af5f430fb37ad02bf0922475","event_at":"2026-07-28T03:00:26.224000Z","event_type":"price_change","frame_hash":"ac8e4157f996f3dcac95e0e826c83aaf49478d09d0db8008f10426ce41eb4557","frame_index":0,"kind":"data","monotonic_ns":309612231554666,"payload":{"event_type":"price_change","market":"0x779291bef19b6709f61e9764a954aafe9ffae488d50ae674aabdcb4f248006d5","price_changes":[{"asset_id":"14965588658799411272385430903075831224615961675357217884735713260981483529984","best_ask":"0.6","best_bid":"0.59","hash":"0e6c97276a4f25cea99f9c46ec1507350eb92c3d","price":"0.54","side":"BUY","size":"150.6"},{"asset_id":"8761897749749422724209054078244794145777693856614463256546737399611489089783","best_ask":"0.41","best_bid":"0.4","hash":"608dcac9cf1bd019aaf4858c17aea10df8e4d798","price":"0.46","side":"SELL","size":"150.6"}],"timestamp":"1785207626224"},"payload_hash":"7dcad02e01d9ae88733ff8fdfc6ffeb4930ad1395c221c781402585ac06f33b1","raw_frame":"{\"market\":\"0x779291bef19b6709f61e9764a954aafe9ffae488d50ae674aabdcb4f248006d5\", \"price_changes\":[{\"asset_id\":\"14965588658799411272385430903075831224615961675357217884735713260981483529984\", \"price\":\"0.54\", \"size\":\"150.6\", \"side\":\"BUY\", \"hash\":\"0e6c97276a4f25cea99f9c46ec1507350eb92c3d\", \"best_bid\":\"0.59\", \"best_ask\":\"0.6\"}, {\"asset_id\":\"8761897749749422724209054078244794145777693856614463256546737399611489089783\", \"price\":\"0.46\", \"size\":\"150.6\", \"side\":\"SELL\", \"hash\":\"608dcac9cf1bd019aaf4858c17aea10df8e4d798\", \"best_bid\":\"0.4\", \"best_ask\":\"0.41\"}], \"timestamp\":\"1785207626224\", \"event_type\":\"price_change\"}","received_at":"2026-07-28T03:00:29.212977Z","schema_version":"clob-market-ws.price_change.v1","sequence":null,"server_hash":null,"server_timestamp":"1785207626224","session_id":"3e519d9098404c15b234d96025eb1a2b","source":"clob_market_ws"},"received_at":"2026-07-28T03:00:29.212977Z","record_id":"32ea0e757de9f14c91b3dc6afed12f453b0aebbb72a22b5b1b52f09dcb272e90","schema_fingerprint":"4aa3821a28b0b7c2400bc59aba4bcc0a76e971dadd19610d3ad38c768e124dc7","schema_version":"edge-lab-recorder.raw.v1","sequence":null,"source":"clob_market_ws"}
{"event_at":"2026-07-28T03:00:26.224000Z","event_fingerprint":"a719d7c292358ad769da88337f85f1206bae7f04a4d036f4a281cac5d8c531ea","payload":{"connection_id":"a6b55582af5f430fb37ad02bf0922475","event_at":"2026-07-28T03:00:26.224000Z","event_type":"price_change","frame_hash":"d10f61a24f4d11b879926c6e4cc39e9b746f5a4cb62593ce8cc2e8061499ea39","frame_index":0,"kind":"data","monotonic_ns":309612241367041,"payload":{"event_type":"price_change","market":"0x779291bef19b6709f61e9764a954aafe9ffae488d50ae674aabdcb4f248006d5","price_changes":[{"asset_id":"8761897749749422724209054078244794145777693856614463256546737399611489089783","best_ask":"0.41","best_bid":"0.4","hash":"b2b8aeeaa64efaad539133cc33cc2165a387ff8d","price":"0.37","side":"BUY","size":"28.6"},{"asset_id":"14965588658799411272385430903075831224615961675357217884735713260981483529984","best_ask":"0.6","best_bid":"0.59","hash":"704b85b9c516bcfe1f9729b3d61dd78c527173aa","price":"0.63","side":"SELL","size":"28.6"}],"timestamp":"1785207626224"},"payload_hash":"a69616e94411a5c4557f8f1225fdaa11f2b685fbaa104983ecb54ef41831bb7d","raw_frame":"{\"market\":\"0x779291bef19b6709f61e9764a954aafe9ffae488d50ae674aabdcb4f248006d5\", \"price_changes\":[{\"asset_id\":\"8761897749749422724209054078244794145777693856614463256546737399611489089783\", \"price\":\"0.37\", \"size\":\"28.6\", \"side\":\"BUY\", \"hash\":\"b2b8aeeaa64efaad539133cc33cc2165a387ff8d\", \"best_bid\":\"0.4\", \"best_ask\":\"0.41\"}, {\"asset_id\":\"14965588658799411272385430903075831224615961675357217884735713260981483529984\", \"price\":\"0.63\", \"size\":\"28.6\", \"side\":\"SELL\", \"hash\":\"704b85b9c516bcfe1f9729b3d61dd78c527173aa\", \"best_bid\":\"0.59\", \"best_ask\":\"0.6\"}], \"timestamp\":\"1785207626224\", \"event_type\":\"price_change\"}","received_at":"2026-07-28T03:00:29.222793Z","schema_version":"clob-market-ws.price_change.v1","sequence":null,"server_hash":null,"server_timestamp":"1785207626224","session_id":"3e519d9098404c15b234d96025eb1a2b","source":"clob_market_ws"},"received_at":"2026-07-28T03:00:29.222793Z","record_id":"51e633efa0d64ed5428e611c639489f77f039cf998b1139609b05ed69a6fe03d","schema_fingerprint":"4aa3821a28b0b7c2400bc59aba4bcc0a76e971dadd19610d3ad38c768e124dc7","schema_version":"edge-lab-recorder.raw.v1","sequence":null,"source":"clob_market_ws"}
{"event_at":"2026-07-28T03:00:26.225000Z","event_fingerprint":"9d8f33aba5f7c0091fa0b5d34ccb4a17b548c196267788d9e2c12a43bf092680","payload":{"connection_id":"a6b55582af5f430fb37ad02bf0922475","event_at":"2026-07-28T03:00:26.225000Z","event_type":"price_change","frame_hash":"2b4b9c8b4901678048a0309e16ce95d3cdcc973a0fbe478aa2af103e3f5d34c8","frame_index":0,"kind":"data","monotonic_ns":309612249204125,"payload":{"event_type":"price_change","market":"0x779291bef19b6709f61e9764a954aafe9ffae488d50ae674aabdcb4f248006d5","price_changes":[{"asset_id":"8761897749749422724209054078244794145777693856614463256546737399611489089783","best_ask":"0.41","best_bid":"0.4","hash":"cd635910f8101cc5c472f4096299b633803a450c","price":"0.21","side":"BUY","size":"35"},{"asset_id":"14965588658799411272385430903075831224615961675357217884735713260981483529984","best_ask":"0.6","best_bid":"0.59","hash":"532b8f08ef95325b3931fbb43f7d7eaaad3806d7","price":"0.79","side":"SELL","size":"35"}],"timestamp":"1785207626225"},"payload_hash":"b69a6036929c2ead44a32e9f93ffa4182b4c607afe47062797c373dee69d3264","raw_frame":"{\"market\":\"0x779291bef19b6709f61e9764a954aafe9ffae488d50ae674aabdcb4f248006d5\", \"price_changes\":[{\"asset_id\":\"8761897749749422724209054078244794145777693856614463256546737399611489089783\", \"price\":\"0.21\", \"size\":\"35\", \"side\":\"BUY\", \"hash\":\"cd635910f8101cc5c472f4096299b633803a450c\", \"best_bid\":\"0.4\", \"best_ask\":\"0.41\"}, {\"asset_id\":\"14965588658799411272385430903075831224615961675357217884735713260981483529984\", \"price\":\"0.79\", \"size\":\"35\", \"side\":\"SELL\", \"hash\":\"532b8f08ef95325b3931fbb43f7d7eaaad3806d7\", \"best_bid\":\"0.59\", \"best_ask\":\"0.6\"}], \"timestamp\":\"1785207626225\", \"event_type\":\"price_change\"}","received_at":"2026-07-28T03:00:29.230630Z","schema_version":"clob-market-ws.price_change.v1","sequence":null,"server_hash":null,"server_timestamp":"1785207626225","session_id":"3e519d9098404c15b234d96025eb1a2b","source":"clob_market_ws"},"received_at":"2026-07-28T03:00:29.230630Z","record_id":"2cc36a0181a9f481ae8b0acb365ac560607ad45feef7ef3c6b126ba65226833f","schema_fingerprint":"4aa3821a28b0b7c2400bc59aba4bcc0a76e971dadd19610d3ad38c768e124dc7","schema_version":"edge-lab-recorder.raw.v1","sequence":null,"source":"clob_market_ws"}
{"event_at":"2026-07-28T03:00:26.226000Z","event_fingerprint":"0df35229245d1475347e06bff6b5f027472241d0c957b5f03da08c70403b2aac","payload":{"connection_id":"a6b55582af5f430fb37ad02bf0922475","event_at":"2026-07-28T03:00:26.226000Z","event_type":"price_change","frame_hash":"fed166bb704613b41f1976abc11f94bf10d0930c7874b8a7bc93a87ddab14666","frame_index":0,"kind":"data","monotonic_ns":309612253128166,"payload":{"event_type":"price_change","market":"0x779291bef19b6709f61e9764a954aafe9ffae488d50ae674aabdcb4f248006d5","price_changes":[{"asset_id":"8761897749749422724209054078244794145777693856614463256546737399611489089783","best_ask":"0.41","best_bid":"0.4","hash":"3086efa7be8e3c3bda27caaa6bff516fef04d8dd","price":"0.38","side":"BUY","size":"0"},{"asset_id":"14965588658799411272385430903075831224615961675357217884735713260981483529984","best_ask":"0.6","best_bid":"0.59","hash":"8aca00f1f46075eea24207b92b92c002c445a3fc","price":"0.62","side":"SELL","size":"0"}],"timestamp":"1785207626226"},"payload_hash":"864eb65d2a00d64cbf9286b1bd1d52049a8f54a89b0397f1ac6e571e108fe25a","raw_frame":"{\"market\":\"0x779291bef19b6709f61e9764a954aafe9ffae488d50ae674aabdcb4f248006d5\", \"price_changes\":[{\"asset_id\":\"8761897749749422724209054078244794145777693856614463256546737399611489089783\", \"price\":\"0.38\", \"size\":\"0\", \"side\":\"BUY\", \"hash\":\"3086efa7be8e3c3bda27caaa6bff516fef04d8dd\", \"best_bid\":\"0.4\", \"best_ask\":\"0.41\"}, {\"asset_id\":\"14965588658799411272385430903075831224615961675357217884735713260981483529984\", \"price\":\"0.62\", \"size\":\"0\", \"side\":\"SELL\", \"hash\":\"8aca00f1f46075eea24207b92b92c002c445a3fc\", \"best_bid\":\"0.59\", \"best_ask\":\"0.6\"}], \"timestamp\":\"1785207626226\", \"event_type\":\"price_change\"}","received_at":"2026-07-28T03:00:29.234559Z","schema_version":"clob-market-ws.price_change.v1","sequence":null,"server_hash":null,"server_timestamp":"1785207626226","session_id":"3e519d9098404c15b234d96025eb1a2b","source":"clob_market_ws"},"received_at":"2026-07-28T03:00:29.234559Z","record_id":"c61ab7a5b5493db5575803a1b771c6aff4c7239974a231f5496d536e5c7c73fa","schema_fingerprint":"4aa3821a28b0b7c2400bc59aba4bcc0a76e971dadd19610d3ad38c768e124dc7","schema_version":"edge-lab-recorder.raw.v1","sequence":null,"source":"clob_market_ws"}
{"event_at":"2026-07-28T03:00:26.227000Z","event_fingerprint":"2c66f90fc7de1db15b3af8645b3bbf375ee832d1dede933781e70b9279ee84fe","payload":{"connection_id":"a6b55582af5f430fb37ad02bf0922475","event_at":"2026-07-28T03:00:26.227000Z","event_type":"price_change","frame_hash":"cf70b3a39b65126cfaa3b6c74e10a20bd306e6a803d0da6816e43324336d848d","frame_index":0,"kind":"data","monotonic_ns":309612255348708,"payload":{"event_type":"price_change","market":"0x779291bef19b6709f61e9764a954aafe9ffae488d50ae674aabdcb4f248006d5","price_changes":[{"asset_id":"14965588658799411272385430903075831224615961675357217884735713260981483529984","best_ask":"0.6","best_bid":"0.59","hash":"e7d70627c9ad511bc58257628fe65b21ad83091b","price":"0.55","side":"BUY","size":"94.6"},{"asset_id":"8761897749749422724209054078244794145777693856614463256546737399611489089783","best_ask":"0.41","best_bid":"0.4","hash":"0f9a1b9d159490216d94f39427a1a31a6b64052b","price":"0.45","side":"SELL","size":"94.6"}],"timestamp":"1785207626227"},"payload_hash":"97bfd071a1bbd664fe15ee5d50fe746386881ba05bd9ddb6b3de68c9f8a0cfc1","raw_frame":"{\"market\":\"0x779291bef19b6709f61e9764a954aafe9ffae488d50ae674aabdcb4f248006d5\", \"price_changes\":[{\"asset_id\":\"14965588658799411272385430903075831224615961675357217884735713260981483529984\", \"price\":\"0.55\", \"size\":\"94.6\", \"side\":\"BUY\", \"hash\":\"e7d70627c9ad511bc58257628fe65b21ad83091b\", \"best_bid\":\"0.59\", \"best_ask\":\"0.6\"}, {\"asset_id\":\"8761897749749422724209054078244794145777693856614463256546737399611489089783\", \"price\":\"0.45\", \"size\":\"94.6\", \"side\":\"SELL\", \"hash\":\"0f9a1b9d159490216d94f39427a1a31a6b64052b\", \"best_bid\":\"0.4\", \"best_ask\":\"0.41\"}], \"timestamp\":\"1785207626227\", \"event_type\":\"price_change\"}","received_at":"2026-07-28T03:00:29.236781Z","schema_version":"clob-market-ws.price_change.v1","sequence":null,"server_hash":null,"server_timestamp":"1785207626227","session_id":"3e519d9098404c15b234d96025eb1a2b","source":"clob_market_ws"},"received_at":"2026-07-28T03:00:29.236781Z","record_id":"09edf37945d9ad837fc27967272c6e09c56c63c7defff97311bb3e10e64afe85","schema_fingerprint":"4aa3821a28b0b7c2400bc59aba4bcc0a76e971dadd19610d3ad38c768e124dc7","schema_version":"edge-lab-recorder.raw.v1","sequence":null,"source":"clob_market_ws"}
{"event_at":"2026-07-28T03:00:26.232000Z","event_fingerprint":"91a83934328fdd93aeb5e21c4440e5f1a19a8c2e9b917bdf99b19e0cc76e4cfa","payload":{"connection_id":"a6b55582af5f430fb37ad02bf0922475","event_at":"2026-07-28T03:00:26.232000Z","event_type":"price_change","frame_hash":"7595a48c2407f2a1321bbb22077af988b19c467aab65624fed3eb1c07b519196","frame_index":0,"kind":"data","monotonic_ns":309612257487083,"payload":{"event_type":"price_change","market":"0x779291bef19b6709f61e9764a954aafe9ffae488d50ae674aabdcb4f248006d5","price_changes":[{"asset_id":"14965588658799411272385430903075831224615961675357217884735713260981483529984","best_ask":"0.6","best_bid":"0.59","hash":"ceb31b541188e05c16256a9d9790de5660639257","price":"0.54","side":"BUY","size":"120.6"},{"asset_id":"8761897749749422724209054078244794145777693856614463256546737399611489089783","best_ask":"0.41","best_bid":"0.4","hash":"0f69948ff07ba3b16021290d0ab9f93d875856a7","price":"0.46","side":"SELL","size":"120.6"}],"timestamp":"1785207626232"},"payload_hash":"e6cb6cd20848aa0ad789de1c841d4b852feb27ce05368220bc61df5e98d752d4","raw_frame":"{\"market\":\"0x779291bef19b6709f61e9764a954aafe9ffae488d50ae674aabdcb4f248006d5\", \"price_changes\":[{\"asset_id\":\"14965588658799411272385430903075831224615961675357217884735713260981483529984\", \"price\":\"0.54\", \"size\":\"120.6\", \"side\":\"BUY\", \"hash\":\"ceb31b541188e05c16256a9d9790de5660639257\", \"best_bid\":\"0.59\", \"best_ask\":\"0.6\"}, {\"asset_id\":\"8761897749749422724209054078244794145777693856614463256546737399611489089783\", \"price\":\"0.46\", \"size\":\"120.6\", \"side\":\"SELL\", \"hash\":\"0f69948ff07ba3b16021290d0ab9f93d875856a7\", \"best_bid\":\"0.4\", \"best_ask\":\"0.41\"}], \"timestamp\":\"1785207626232\", \"event_type\":\"price_change\"}","received_at":"2026-07-28T03:00:29.238919Z","schema_version":"clob-market-ws.price_change.v1","sequence":null,"server_hash":null,"server_timestamp":"1785207626232","session_id":"3e519d9098404c15b234d96025eb1a2b","source":"clob_market_ws"},"received_at":"2026-07-28T03:00:29.238919Z","record_id":"83a3bfd6d62ad22f5a1e7242be6726e10272fc6e58d401bdc6e4f3b0c74e4908","schema_fingerprint":"4aa3821a28b0b7c2400bc59aba4bcc0a76e971dadd19610d3ad38c768e124dc7","schema_version":"edge-lab-recorder.raw.v1","sequence":null,"source":"clob_market_ws"}
{"event_at":"2026-07-28T03:00:26.234000Z","event_fingerprint":"ef19e64daf2908ade2b137e31a6e05f74be3b5f5061c59082b27fca661c0536e","payload":{"connection_id":"a6b55582af5f430fb37ad02bf0922475","event_at":"2026-07-28T03:00:26.234000Z","event_type":"price_change","frame_hash":"0a35ac3ca4289e8371bb352fa2bae1878a9968dd225c7c856a31e58fbe7fedce","frame_index":0,"kind":"data","monotonic_ns":309612261515375,"payload":{"event_type":"price_change","market":"0x779291bef19b6709f61e9764a954aafe9ffae488d50ae674aabdcb4f248006d5","price_changes":[{"asset_id":"14965588658799411272385430903075831224615961675357217884735713260981483529984","best_ask":"0.6","best_bid":"0.59","hash":"0595fe8eca0c978a9936f6a92b9b7325bd4edc52","price":"0.54","side":"BUY","size":"90.6"},{"asset_id":"8761897749749422724209054078244794145777693856614463256546737399611489089783","best_ask":"0.41","best_bid":"0.4","hash":"7f85af321872868908e7b8e248b9bc70fd857d53","price":"0.46","side":"SELL","size":"90.6"}],"timestamp":"1785207626234"},"payload_hash":"d921a12201c0df6072445a95b8ea8fd8b0cdc24e99e65dbe4be283debd9fa56a","raw_frame":"{\"market\":\"0x779291bef19b6709f61e9764a954aafe9ffae488d50ae674aabdcb4f248006d5\", \"price_changes\":[{\"asset_id\":\"14965588658799411272385430903075831224615961675357217884735713260981483529984\", \"price\":\"0.54\", \"size\":\"90.6\", \"side\":\"BUY\", \"hash\":\"0595fe8eca0c978a9936f6a92b9b7325bd4edc52\", \"best_bid\":\"0.59\", \"best_ask\":\"0.6\"}, {\"asset_id\":\"8761897749749422724209054078244794145777693856614463256546737399611489089783\", \"price\":\"0.46\", \"size\":\"90.6\", \"side\":\"SELL\", \"hash\":\"7f85af321872868908e7b8e248b9bc70fd857d53\", \"best_bid\":\"0.4\", \"best_ask\":\"0.41\"}], \"timestamp\":\"1785207626234\", \"event_type\":\"price_change\"}","received_at":"2026-07-28T03:00:29.242942Z","schema_version":"clob-market-ws.price_change.v1","sequence":null,"server_hash":null,"server_timestamp":"1785207626234","session_id":"3e519d9098404c15b234d96025eb1a2b","source":"clob_market_ws"},"received_at":"2026-07-28T03:00:29.242942Z","record_id":"b92f40ca3b11952063670f714db725f9eaff370f6cb256f1e5f05f7128f35771","schema_fingerprint":"4aa3821a28b0b7c2400bc59aba4bcc0a76e971dadd19610d3ad38c768e124dc7","schema_version":"edge-lab-recorder.raw.v1","sequence":null,"source":"clob_market_ws"}
{"event_at":"2026-07-28T03:00:26.237000Z","event_fingerprint":"c01efc3459a511fadcf282f4f3f7d4653fbc4f07e0b5ef9740d20246c4260052","payload":{"connection_id":"a6b55582af5f430fb37ad02bf0922475","event_at":"2026-07-28T03:00:26.237000Z","event_type":"price_change","frame_hash":"c6066c4de9a03af33a8941ed64e78924544a2eb6909d474e512479dc48aff44f","frame_index":0,"kind":"data","monotonic_ns":309612266405416,"payload":{"event_type":"price_change","market":"0x779291bef19b6709f61e9764a954aafe9ffae488d50ae674aabdcb4f248006d5","price_changes":[{"asset_id":"8761897749749422724209054078244794145777693856614463256546737399611489089783","best_ask":"0.41","best_bid":"0.4","hash":"4e3313ef8ff9183e856647eb6e6f5b51fc799509","price":"0.37","side":"BUY","size":"16"},{"asset_id":"14965588658799411272385430903075831224615961675357217884735713260981483529984","best_ask":"0.6","best_bid":"0.59","hash":"e9b339e4baf71939689d4d3a990dc5dae584d4a2","price":"0.63","side":"SELL","size":"16"}],"timestamp":"1785207626237"},"payload_hash":"0034716f25bae30317b4fb0695607e6b58b092903d5578edf3f344bedc96c0f4","raw_frame":"{\"market\":\"0x779291bef19b6709f61e9764a954aafe9ffae488d50ae674aabdcb4f248006d5\", \"price_changes\":[{\"asset_id\":\"8761897749749422724209054078244794145777693856614463256546737399611489089783\", \"price\":\"0.37\", \"size\":\"16\", \"side\":\"BUY\", \"hash\":\"4e3313ef8ff9183e856647eb6e6f5b51fc799509\", \"best_bid\":\"0.4\", \"best_ask\":\"0.41\"}, {\"asset_id\":\"14965588658799411272385430903075831224615961675357217884735713260981483529984\", \"price\":\"0.63\", \"size\":\"16\", \"side\":\"SELL\", \"hash\":\"e9b339e4baf71939689d4d3a990dc5dae584d4a2\", \"best_bid\":\"0.59\", \"best_ask\":\"0.6\"}], \"timestamp\":\"1785207626237\", \"event_type\":\"price_change\"}","received_at":"2026-07-28T03:00:29.247831Z","schema_version":"clob-market-ws.price_change.v1","sequence":null,"server_hash":null,"server_timestamp":"1785207626237","session_id":"3e519d9098404c15b234d96025eb1a2b","source":"clob_market_ws"},"received_at":"2026-07-28T03:00:29.247831Z","record_id":"76e8d007837e6cdc43280ee7668bc3d9314c729d59b67aea6634423ec2cf0c6c","schema_fingerprint":"4aa3821a28b0b7c2400bc59aba4bcc0a76e971dadd19610d3ad38c768e124dc7","schema_version":"edge-lab-recorder.raw.v1","sequence":null,"source":"clob_market_ws"}
{"event_at":"2026-07-28T03:00:26.237000Z","event_fingerprint":"fb049be2c968d55436a2060cc9293cedb8075ed2c56e31919802638d1cfed542","payload":{"connection_id":"a6b55582af5f430fb37ad02bf0922475","event_at":"2026-07-28T03:00:26.237000Z","event_type":"price_change","frame_hash":"3129cdbedc0902e96ea1e26ddd61ec2827ceb34ebb1ebabc1e9712fb784e5ad6","frame_index":0,"kind":"data","monotonic_ns":309612271375125,"payload":{"event_type":"price_change","market":"0x779291bef19b6709f61e9764a954aafe9ffae488d50ae674aabdcb4f248006d5","price_changes":[{"asset_id":"14965588658799411272385430903075831224615961675357217884735713260981483529984","best_ask":"0.6","best_bid":"0.59","hash":"ce5b2e7a5bf48e8ec77834e9b93f3d5d82568d56","price":"0.56","side":"BUY","size":"90.72"},{"asset_id":"8761897749749422724209054078244794145777693856614463256546737399611489089783","best_ask":"0.41","best_bid":"0.4","hash":"bcd4c1b4f55b5d40ffc302f80518a78cb7c81aa8","price":"0.44","side":"SELL","size":"90.72"}],"timestamp":"1785207626237"},"payload_hash":"d3a97f434f7b70d2b84d41d80d803fa9d852df814c246932ae2469157a487810","raw_frame":"{\"market\":\"0x779291bef19b6709f61e9764a954aafe9ffae488d50ae674aabdcb4f248006d5\", \"price_changes\":[{\"asset_id\":\"14965588658799411272385430903075831224615961675357217884735713260981483529984\", \"price\":\"0.56\", \"size\":\"90.72\", \"side\":\"BUY\", \"hash\":\"ce5b2e7a5bf48e8ec77834e9b93f3d5d82568d56\", \"best_bid\":\"0.59\", \"best_ask\":\"0.6\"}, {\"asset_id\":\"8761897749749422724209054078244794145777693856614463256546737399611489089783\", \"price\":\"0.44\", \"size\":\"90.72\", \"side\":\"SELL\", \"hash\":\"bcd4c1b4f55b5d40ffc302f80518a78cb7c81aa8\", \"best_bid\":\"0.4\", \"best_ask\":\"0.41\"}], \"timestamp\":\"1785207626237\", \"event_type\":\"price_change\"}","received_at":"2026-07-28T03:00:29.252801Z","schema_version":"clob-market-ws.price_change.v1","sequence":null,"server_hash":null,"server_timestamp":"1785207626237","session_id":"3e519d9098404c15b234d96025eb1a2b","source":"clob_market_ws"},"received_at":"2026-07-28T03:00:29.252801Z","record_id":"ce9b0a2306d4ef7bdd01e5809bb074f4fd5bb509c0a8ad61f7c48d7f58491211","schema_fingerprint":"4aa3821a28b0b7c2400bc59aba4bcc0a76e971dadd19610d3ad38c768e124dc7","schema_version":"edge-lab-recorder.raw.v1","sequence":null,"source":"clob_market_ws"}
{"event_at":"2026-07-28T03:00:26.242000Z","event_fingerprint":"1aa32ac6d251e748e43f0f0a587c5b0b6e93e2c6a759a056cdcc97df4df09182","payload":{"connection_id":"a6b55582af5f430fb37ad02bf0922475","event_at":"2026-07-28T03:00:26.242000Z","event_type":"price_change","frame_hash":"4e6912b819c9b47217589a2bd64e137f61a1c7ed90ea3349a3e3fbd6bd890222","frame_index":0,"kind":"data","monotonic_ns":309612277017125,"payload":{"event_type":"price_change","market":"0x779291bef19b6709f61e9764a954aafe9ffae488d50ae674aabdcb4f248006d5","price_changes":[{"asset_id":"14965588658799411272385430903075831224615961675357217884735713260981483529984","best_ask":"0.6","best_bid":"0.59","hash":"2e653fdeb9efedebb7824507503f8edd1a4997e9","price":"0.04","side":"BUY","size":"770"},{"asset_id":"8761897749749422724209054078244794145777693856614463256546737399611489089783","best_ask":"0.41","best_bid":"0.4","hash":"a7892670c35ccad694f866617aa73eeed4457d0f","price":"0.96","side":"SELL","size":"770"}],"timestamp":"1785207626242"},"payload_hash":"b40b34435f5ffd05f414fd8625ab808d2ef39b658fb789a19a46adce2f354d8a","raw_frame":"{\"market\":\"0x779291bef19b6709f61e9764a954aafe9ffae488d50ae674aabdcb4f248006d5\", \"price_changes\":[{\"asset_id\":\"14965588658799411272385430903075831224615961675357217884735713260981483529984\", \"price\":\"0.04\", \"size\":\"770\", \"side\":\"BUY\", \"hash\":\"2e653fdeb9efedebb7824507503f8edd1a4997e9\", \"best_bid\":\"0.59\", \"best_ask\":\"0.6\"}, {\"asset_id\":\"8761897749749422724209054078244794145777693856614463256546737399611489089783\", \"price\":\"0.96\", \"size\":\"770\", \"side\":\"SELL\", \"hash\":\"a7892670c35ccad694f866617aa73eeed4457d0f\", \"best_bid\":\"0.4\", \"best_ask\":\"0.41\"}], \"timestamp\":\"1785207626242\", \"event_type\":\"price_change\"}","received_at":"2026-07-28T03:00:29.258443Z","schema_version":"clob-market-ws.price_change.v1","sequence":null,"server_hash":null,"server_timestamp":"1785207626242","session_id":"3e519d9098404c15b234d96025eb1a2b","source":"clob_market_ws"},"received_at":"2026-07-28T03:00:29.258443Z","record_id":"9dabdce666aa1f79ff7856e431ad6ab638392ba81b42e1d5de96801173f10ad5","schema_fingerprint":"4aa3821a28b0b7c2400bc59aba4bcc0a76e971dadd19610d3ad38c768e124dc7","schema_version":"edge-lab-recorder.raw.v1","sequence":null,"source":"clob_market_ws"}
{"event_at":"2026-07-28T03:00:26.245000Z","event_fingerprint":"2ffd08a4c2e87e4d58cb58a3eadd580545391f9e018affcb63b455658c06a00e","payload":{"connection_id":"a6b55582af5f430fb37ad02bf0922475","event_at":"2026-07-28T03:00:26.245000Z","event_type":"price_change","frame_hash":"2263866d9322155b228135d940261fd54e803d768a4c22ced8195f8ec977fc3e","frame_index":0,"kind":"data","monotonic_ns":309612286267541,"payload":{"event_type":"price_change","market":"0x779291bef19b6709f61e9764a954aafe9ffae488d50ae674aabdcb4f248006d5","price_changes":[{"asset_id":"14965588658799411272385430903075831224615961675357217884735713260981483529984","best_ask":"0.6","best_bid":"0.59","hash":"a49f13332b01ffd11152e6f0da65a1dc9f425d5d","price":"0.57","side":"BUY","size":"103.5"},{"asset_id":"8761897749749422724209054078244794145777693856614463256546737399611489089783","best_ask":"0.41","best_bid":"0.4","hash":"bcdd50a75a0b9d2b90477d7d33e74bb9df685932","price":"0.43","side":"SELL","size":"103.5"}],"timestamp":"1785207626245"},"payload_hash":"e9c8983019a8f939f7716e31ef69444890ae358d88e9df541ecf351f777f95c9","raw_frame":"{\"market\":\"0x779291bef19b6709f61e9764a954aafe9ffae488d50ae674aabdcb4f248006d5\", \"price_changes\":[{\"asset_id\":\"14965588658799411272385430903075831224615961675357217884735713260981483529984\", \"price\":\"0.57\", \"size\":\"103.5\", \"side\":\"BUY\", \"hash\":\"a49f13332b01ffd11152e6f0da65a1dc9f425d5d\", \"best_bid\":\"0.59\", \"best_ask\":\"0.6\"}, {\"asset_id\":\"8761897749749422724209054078244794145777693856614463256546737399611489089783\", \"price\":\"0.43\", \"size\":\"103.5\", \"side\":\"SELL\", \"hash\":\"bcdd50a75a0b9d2b90477d7d33e74bb9df685932\", \"best_bid\":\"0.4\", \"best_ask\":\"0.41\"}], \"timestamp\":\"1785207626245\", \"event_type\":\"price_change\"}","received_at":"2026-07-28T03:00:29.267694Z","schema_version":"clob-market-ws.price_change.v1","sequence":null,"server_hash":null,"server_timestamp":"1785207626245","session_id":"3e519d9098404c15b234d96025eb1a2b","source":"clob_market_ws"},"received_at":"2026-07-28T03:00:29.267694Z","record_id":"d9170fca3c600c257e10631e40ba7ec5257cfd43910bf103ded70d014ce7a103","schema_fingerprint":"4aa3821a28b0b7c2400bc59aba4bcc0a76e971dadd19610d3ad38c768e124dc7","schema_version":"edge-lab-recorder.raw.v1","sequence":null,"source":"clob_market_ws"}
{"event_at":"2026-07-28T03:00:26.247000Z","event_fingerprint":"ad798a57f7fb648f72f7edfb8f528b79ae5461e6847bcaff33862f76386851bb","payload":{"connection_id":"a6b55582af5f430fb37ad02bf0922475","event_at":"2026-07-28T03:00:26.247000Z","event_type":"price_change","frame_hash":"a58fcce5cfd826e76a00a45ae8857d96bd1f353bb2507da97ea24b0710adef79","frame_index":0,"kind":"data","monotonic_ns":309612291243708,"payload":{"event_type":"price_change","market":"0x779291bef19b6709f61e9764a954aafe9ffae488d50ae674aabdcb4f248006d5","price_changes":[{"asset_id":"8761897749749422724209054078244794145777693856614463256546737399611489089783","best_ask":"0.41","best_bid":"0.4","hash":"0fdfe96d27d8291aea0b568c77bdd330161796f8","price":"0.2","side":"BUY","size":"376.32"},{"asset_id":"14965588658799411272385430903075831224615961675357217884735713260981483529984","best_ask":"0.6","best_bid":"0.59","hash":"848d890198b9ea80cac5be62c0a9b0e879226366","price":"0.8","side":"SELL","size":"376.32"}],"timestamp":"1785207626247"},"payload_hash":"1691e2964ac733e7ffe05d9e15fbb39af9113c0965b5a0d054143dc654e72daa","raw_frame":"{\"market\":\"0x779291bef19b6709f61e9764a954aafe9ffae488d50ae674aabdcb4f248006d5\", \"price_changes\":[{\"asset_id\":\"8761897749749422724209054078244794145777693856614463256546737399611489089783\", \"price\":\"0.2\", \"size\":\"376.32\", \"side\":\"BUY\", \"hash\":\"0fdfe96d27d8291aea0b568c77bdd330161796f8\", \"best_bid\":\"0.4\", \"best_ask\":\"0.41\"}, {\"asset_id\":\"14965588658799411272385430903075831224615961675357217884735713260981483529984\", \"price\":\"0.8\", \"size\":\"376.32\", \"side\":\"SELL\", \"hash\":\"848d890198b9ea80cac5be62c0a9b0e879226366\", \"best_bid\":\"0.59\", \"best_ask\":\"0.6\"}], \"timestamp\":\"1785207626247\", \"event_type\":\"price_change\"}","received_at":"2026-07-28T03:00:29.272668Z","schema_version":"clob-market-ws.price_change.v1","sequence":null,"server_hash":null,"server_timestamp":"1785207626247","session_id":"3e519d9098404c15b234d96025eb1a2b","source":"clob_market_ws"},"received_at":"2026-07-28T03:00:29.272668Z","record_id":"693418f22cd1218625f4b83bdf025539843d09718a8ab1cb53af906e8ecdb1e5","schema_fingerprint":"4aa3821a28b0b7c2400bc59aba4bcc0a76e971dadd19610d3ad38c768e124dc7","schema_version":"edge-lab-recorder.raw.v1","sequence":null,"source":"clob_market_ws"}
{"event_at":"2026-07-28T03:00:26.248000Z","event_fingerprint":"2ea73eb8a8acf0a1e7e890b8d27834fef247feab4d285ec2f2601a69abfd050a","payload":{"connection_id":"a6b55582af5f430fb37ad02bf0922475","event_at":"2026-07-28T03:00:26.248000Z","event_type":"price_change","frame_hash":"74b3d320566fddde550a5184e545d1eabc59a0a136c49bdc70877ce88221d8e9","frame_index":0,"kind":"data","monotonic_ns":309612297340250,"payload":{"event_type":"price_change","market":"0x779291bef19b6709f61e9764a954aafe9ffae488d50ae674aabdcb4f248006d5","price_changes":[{"asset_id":"8761897749749422724209054078244794145777693856614463256546737399611489089783","best_ask":"0.41","best_bid":"0.4","hash":"ddbee7456a15f6c6272e38b7dd2810080a478080","price":"0.34","side":"BUY","size":"116"},{"asset_id":"14965588658799411272385430903075831224615961675357217884735713260981483529984","best_ask":"0.6","best_bid":"0.59","hash":"d6ed5732c6bdf1d594466647358ec2bc60ffc4ad","price":"0.66","side":"SELL","size":"116"}],"timestamp":"1785207626248"},"payload_hash":"94e4e7e6930c04f2d74be696dfe2cb6b26d47f2735547b6a006680d1fca2a8a7","raw_frame":"{\"market\":\"0x779291bef19b6709f61e9764a954aafe9ffae488d50ae674aabdcb4f248006d5\", \"price_changes\":[{\"asset_id\":\"8761897749749422724209054078244794145777693856614463256546737399611489089783\", \"price\":\"0.34\", \"size\":\"116\", \"side\":\"BUY\", \"hash\":\"ddbee7456a15f6c6272e38b7dd2810080a478080\", \"best_bid\":\"0.4\", \"best_ask\":\"0.41\"}, {\"asset_id\":\"14965588658799411272385430903075831224615961675357217884735713260981483529984\", \"price\":\"0.66\", \"size\":\"116\", \"side\":\"SELL\", \"hash\":\"d6ed5732c6bdf1d594466647358ec2bc60ffc4ad\", \"best_bid\":\"0.59\", \"best_ask\":\"0.6\"}], \"timestamp\":\"1785207626248\", \"event_type\":\"price_change\"}","received_at":"2026-07-28T03:00:29.278767Z","schema_version":"clob-market-ws.price_change.v1","sequence":null,"server_hash":null,"server_timestamp":"1785207626248","session_id":"3e519d9098404c15b234d96025eb1a2b","source":"clob_market_ws"},"received_at":"2026-07-28T03:00:29.278767Z","record_id":"80d49ff0da58dd1af245b5054604571702b4174257dec1121dd0e99333762843","schema_fingerprint":"4aa3821a28b0b7c2400bc59aba4bcc0a76e971dadd19610d3ad38c768e124dc7","schema_version":"edge-lab-recorder.raw.v1","sequence":null,"source":"clob_market_ws"}
{"event_at":"2026-07-28T03:00:26.250000Z","event_fingerprint":"304dd2971db2fe0cd19b6339b4eac78ab125db94b4c25069d8ebfe3ea144ca1c","payload":{"connection_id":"a6b55582af5f430fb37ad02bf0922475","event_at":"2026-07-28T03:00:26.250000Z","event_type":"price_change","frame_hash":"f5505d1d3596d2aec5c422d99f47d7e7d5b177595da7c4c4c7517df66e8002ec","frame_index":0,"kind":"data","monotonic_ns":309612302417875,"payload":{"event_type":"price_change","market":"0x779291bef19b6709f61e9764a954aafe9ffae488d50ae674aabdcb4f248006d5","price_changes":[{"asset_id":"14965588658799411272385430903075831224615961675357217884735713260981483529984","best_ask":"0.6","best_bid":"0.59","hash":"984adf52ad946fc27cfa88902796c27cbfd88d3c","price":"0.59","side":"BUY","size":"513.63"},{"asset_id":"8761897749749422724209054078244794145777693856614463256546737399611489089783","best_ask":"0.41","best_bid":"0.4","hash":"d5d3261f7b597b1d544b5437d0e968c3dc4285cb","price":"0.41","side":"SELL","size":"513.63"}],"timestamp":"1785207626250"},"payload_hash":"1efa8ea30782ca55a0b1c7d5747d0e6a772263b17cbf3695243129b04c2360d3","raw_frame":"{\"market\":\"0x779291bef19b6709f61e9764a954aafe9ffae488d50ae674aabdcb4f248006d5\", \"price_changes\":[{\"asset_id\":\"14965588658799411272385430903075831224615961675357217884735713260981483529984\", \"price\":\"0.59\", \"size\":\"513.63\", \"side\":\"BUY\", \"hash\":\"984adf52ad946fc27cfa88902796c27cbfd88d3c\", \"best_bid\":\"0.59\", \"best_ask\":\"0.6\"}, {\"asset_id\":\"8761897749749422724209054078244794145777693856614463256546737399611489089783\", \"price\":\"0.41\", \"size\":\"513.63\", \"side\":\"SELL\", \"hash\":\"d5d3261f7b597b1d544b5437d0e968c3dc4285cb\", \"best_bid\":\"0.4\", \"best_ask\":\"0.41\"}], \"timestamp\":\"1785207626250\", \"event_type\":\"price_change\"}","received_at":"2026-07-28T03:00:29.283843Z","schema_version":"clob-market-ws.price_change.v1","sequence":null,"server_hash":null,"server_timestamp":"1785207626250","session_id":"3e519d9098404c15b234d96025eb1a2b","source":"clob_market_ws"},"received_at":"2026-07-28T03:00:29.283843Z","record_id":"5148aa41ab4be0b31bbef9eab5d9b1e98256febf83b04976527f031352bfbaff","schema_fingerprint":"4aa3821a28b0b7c2400bc59aba4bcc0a76e971dadd19610d3ad38c768e124dc7","schema_version":"edge-lab-recorder.raw.v1","sequence":null,"source":"clob_market_ws"}
{"event_at":"2026-07-28T03:00:26.251000Z","event_fingerprint":"2b649b5825fbbd9e57dc1d35671eef02c5e7f18f3d43879aefec3e498cf88845","payload":{"connection_id":"a6b55582af5f430fb37ad02bf0922475","event_at":"2026-07-28T03:00:26.251000Z","event_type":"price_change","frame_hash":"eee9eb5646f4dda4647b10a06f01c8ecf60997d93e3f8549f70dd27b155ff4d0","frame_index":0,"kind":"data","monotonic_ns":309612310393041,"payload":{"event_type":"price_change","market":"0x779291bef19b6709f61e9764a954aafe9ffae488d50ae674aabdcb4f248006d5","price_changes":[{"asset_id":"8761897749749422724209054078244794145777693856614463256546737399611489089783","best_ask":"0.41","best_bid":"0.4","hash":"484d48b9b9a6d9383f0388942ba9fd38a965d7e1","price":"0.21","side":"BUY","size":"45"},{"asset_id":"14965588658799411272385430903075831224615961675357217884735713260981483529984","best_ask":"0.6","best_bid":"0.59","hash":"28869a6eba2f2736aaea7a8a19eb0d1a25d276eb","price":"0.79","side":"SELL","size":"45"}],"timestamp":"1785207626251"},"payload_hash":"4e1514a1f9327b34bd85ae239a6d93aeb1f020b74d4d0ac9b5d5e9919046f1f3","raw_frame":"{\"market\":\"0x779291bef19b6709f61e9764a954aafe9ffae488d50ae674aabdcb4f248006d5\", \"price_changes\":[{\"asset_id\":\"8761897749749422724209054078244794145777693856614463256546737399611489089783\", \"price\":\"0.21\", \"size\":\"45\", \"side\":\"BUY\", \"hash\":\"484d48b9b9a6d9383f0388942ba9fd38a965d7e1\", \"best_bid\":\"0.4\", \"best_ask\":\"0.41\"}, {\"asset_id\":\"14965588658799411272385430903075831224615961675357217884735713260981483529984\", \"price\":\"0.79\", \"size\":\"45\", \"side\":\"SELL\", \"hash\":\"28869a6eba2f2736aaea7a8a19eb0d1a25d276eb\", \"best_bid\":\"0.59\", \"best_ask\":\"0.6\"}], \"timestamp\":\"1785207626251\", \"event_type\":\"price_change\"}","received_at":"2026-07-28T03:00:29.291817Z","schema_version":"clob-market-ws.price_change.v1","sequence":null,"server_hash":null,"server_timestamp":"1785207626251","session_id":"3e519d9098404c15b234d96025eb1a2b","source":"clob_market_ws"},"received_at":"2026-07-28T03:00:29.291817Z","record_id":"605a2ce34680174ef0c937d3454b400178754604c724ebc6f4a8384c67a5ea5f","schema_fingerprint":"4aa3821a28b0b7c2400bc59aba4bcc0a76e971dadd19610d3ad38c768e124dc7","schema_version":"edge-lab-recorder.raw.v1","sequence":null,"source":"clob_market_ws"}
{"event_at":"2026-07-28T03:00:26.252000Z","event_fingerprint":"5d61be2327047fdfd4b8e9d12216796ce5a54137d1ab3639ff1a5a0e7347cfc1","payload":{"connection_id":"a6b55582af5f430fb37ad02bf0922475","event_at":"2026-07-28T03:00:26.252000Z","event_type":"price_change","frame_hash":"e42730a15136fc6035a415dfcf05f8cfb9410d99ef76101eff673c7cb7de9074","frame_index":0,"kind":"data","monotonic_ns":309612323530666,"payload":{"event_type":"price_change","market":"0x779291bef19b6709f61e9764a954aafe9ffae488d50ae674aabdcb4f248006d5","price_changes":[{"asset_id":"14965588658799411272385430903075831224615961675357217884735713260981483529984","best_ask":"0.6","best_bid":"0.59","hash":"6f20852e8429e60f59cedf621e964e80453f2c7b","price":"0.56","side":"BUY","size":"99.72"},{"asset_id":"8761897749749422724209054078244794145777693856614463256546737399611489089783","best_ask":"0.41","best_bid":"0.4","hash":"e7486eeaa1c1edf9457c054e0e11ef0c4d7c207d","price":"0.44","side":"SELL","size":"99.72"}],"timestamp":"1785207626252"},"payload_hash":"4f53b4b079f933fc077cfb9ded86a86f89182cac74f1612d9e408903fa62c091","raw_frame":"{\"market\":\"0x779291bef19b6709f61e9764a954aafe9ffae488d50ae674aabdcb4f248006d5\", \"price_changes\":[{\"asset_id\":\"14965588658799411272385430903075831224615961675357217884735713260981483529984\", \"price\":\"0.56\", \"size\":\"99.72\", \"side\":\"BUY\", \"hash\":\"6f20852e8429e60f59cedf621e964e80453f2c7b\", \"best_bid\":\"0.59\", \"best_ask\":\"0.6\"}, {\"asset_id\":\"8761897749749422724209054078244794145777693856614463256546737399611489089783\", \"price\":\"0.44\", \"size\":\"99.72\", \"side\":\"SELL\", \"hash\":\"e7486eeaa1c1edf9457c054e0e11ef0c4d7c207d\", \"best_bid\":\"0.4\", \"best_ask\":\"0.41\"}], \"timestamp\":\"1785207626252\", \"event_type\":\"price_change\"}","received_at":"2026-07-28T03:00:29.304956Z","schema_version":"clob-market-ws.price_change.v1","sequence":null,"server_hash":null,"server_timestamp":"1785207626252","session_id":"3e519d9098404c15b234d96025eb1a2b","source":"clob_market_ws"},"received_at":"2026-07-28T03:00:29.304956Z","record_id":"97e3abc58aabb402c3583dbd7893a379356373489b6e5d2a8c01bed5e7d53d77","schema_fingerprint":"4aa3821a28b0b7c2400bc59aba4bcc0a76e971dadd19610d3ad38c768e124dc7","schema_version":"edge-lab-recorder.raw.v1","sequence":null,"source":"clob_market_ws"}
{"event_at":"2026-07-28T03:00:26.254000Z","event_fingerprint":"2b4ffd2dea46f3bc27a066564b8685aa9097237291d1066898517acf1a72d644","payload":{"connection_id":"a6b55582af5f430fb37ad02bf0922475","event_at":"2026-07-28T03:00:26.254000Z","event_type":"price_change","frame_hash":"384730863c5028ab50c7cde07064ac8e810184b380b32a96d8ccb0b7fc1075a6","frame_index":0,"kind":"data","monotonic_ns":309612327303125,"payload":{"event_type":"price_change","market":"0x779291bef19b6709f61e9764a954aafe9ffae488d50ae674aabdcb4f248006d5","price_changes":[{"asset_id":"8761897749749422724209054078244794145777693856614463256546737399611489089783","best_ask":"0.41","best_bid":"0.4","hash":"bdeaa902a8b9181b24afd2115b9efd5c9ffbf667","price":"0.36","side":"BUY","size":"42"},{"asset_id":"14965588658799411272385430903075831224615961675357217884735713260981483529984","best_ask":"0.6","best_bid":"0.59","hash":"7bc60e37746893850ae93e9d9cac78ac535c22ad","price":"0.64","side":"SELL","size":"42"}],"timestamp":"1785207626254"},"payload_hash":"3ad19ff2f8d356efb975bab88d9a7f31b6e75aa393d495722a8cf18c515cfadb","raw_frame":"{\"market\":\"0x779291bef19b6709f61e9764a954aafe9ffae488d50ae674aabdcb4f248006d5\", \"price_changes\":[{\"asset_id\":\"8761897749749422724209054078244794145777693856614463256546737399611489089783\", \"price\":\"0.36\", \"size\":\"42\", \"side\":\"BUY\", \"hash\":\"bdeaa902a8b9181b24afd2115b9efd5c9ffbf667\", \"best_bid\":\"0.4\", \"best_ask\":\"0.41\"}, {\"asset_id\":\"14965588658799411272385430903075831224615961675357217884735713260981483529984\", \"price\":\"0.64\", \"size\":\"42\", \"side\":\"SELL\", \"hash\":\"7bc60e37746893850ae93e9d9cac78ac535c22ad\", \"best_bid\":\"0.59\", \"best_ask\":\"0.6\"}], \"timestamp\":\"1785207626254\", \"event_type\":\"price_change\"}","received_at":"2026-07-28T03:00:29.308728Z","schema_version":"clob-market-ws.price_change.v1","sequence":null,"server_hash":null,"server_timestamp":"1785207626254","session_id":"3e519d9098404c15b234d96025eb1a2b","source":"clob_market_ws"},"received_at":"2026-07-28T03:00:29.308728Z","record_id":"ec0b2dc19bacc36598acb4791355074fdbde0f501435621b73cf823f172745a9","schema_fingerprint":"4aa3821a28b0b7c2400bc59aba4bcc0a76e971dadd19610d3ad38c768e124dc7","schema_version":"edge-lab-recorder.raw.v1","sequence":null,"source":"clob_market_ws"}
{"event_at":"2026-07-28T03:00:26.254000Z","event_fingerprint":"6d4bb540b50fa6388344d6e48cbfc89722af5077c932272a86c4b454bf56d363","payload":{"connection_id":"a6b55582af5f430fb37ad02bf0922475","event_at":"2026-07-28T03:00:26.254000Z","event_type":"price_change","frame_hash":"ec49118c6afd011774737c5f3c2a8e18103c3f8887d0946bf993f9b5b659756b","frame_index":0,"kind":"data","monotonic_ns":309612332507083,"payload":{"event_type":"price_change","market":"0x779291bef19b6709f61e9764a954aafe9ffae488d50ae674aabdcb4f248006d5","price_changes":[{"asset_id":"8761897749749422724209054078244794145777693856614463256546737399611489089783","best_ask":"0.41","best_bid":"0.4","hash":"aaaca9098cf9cd38dab86109a81cf2e8d16d4d83","price":"0.2","side":"BUY","size":"396.32"},{"asset_id":"14965588658799411272385430903075831224615961675357217884735713260981483529984","best_ask":"0.6","best_bid":"0.59","hash":"24141d432207ef3041555a53eef2e805a0200ddf","price":"0.8","side":"SELL","size":"396.32"}],"timestamp":"1785207626254"},"payload_hash":"45f5de8701474c5c3bc3bb5165b5e5447aa419f916c6788143c2555f2f00128a","raw_frame":"{\"market\":\"0x779291bef19b6709f61e9764a954aafe9ffae488d50ae674aabdcb4f248006d5\", \"price_changes\":[{\"asset_id\":\"8761897749749422724209054078244794145777693856614463256546737399611489089783\", \"price\":\"0.2\", \"size\":\"396.32\", \"side\":\"BUY\", \"hash\":\"aaaca9098cf9cd38dab86109a81cf2e8d16d4d83\", \"best_bid\":\"0.4\", \"best_ask\":\"0.41\"}, {\"asset_id\":\"14965588658799411272385430903075831224615961675357217884735713260981483529984\", \"price\":\"0.8\", \"size\":\"396.32\", \"side\":\"SELL\", \"hash\":\"24141d432207ef3041555a53eef2e805a0200ddf\", \"best_bid\":\"0.59\", \"best_ask\":\"0.6\"}], \"timestamp\":\"1785207626254\", \"event_type\":\"price_change\"}","received_at":"2026-07-28T03:00:29.313927Z","schema_version":"clob-market-ws.price_change.v1","sequence":null,"server_hash":null,"server_timestamp":"1785207626254","session_id":"3e519d9098404c15b234d96025eb1a2b","source":"clob_market_ws"},"received_at":"2026-07-28T03:00:29.313927Z","record_id":"f2523e70ac78baf678cf2f10b9efbb9cda865391baaf878f4729c71bd0d4b88f","schema_fingerprint":"4aa3821a28b0b7c2400bc59aba4bcc0a76e971dadd19610d3ad38c768e124dc7","schema_version":"edge-lab-recorder.raw.v1","sequence":null,"source":"clob_market_ws"}
{"event_at":"2026-07-28T03:00:26.255000Z","event_fingerprint":"68b0b5b37484a580efefd767108fcda62dd57249b24bff6ecd516a1a7c4d8785","payload":{"connection_id":"a6b55582af5f430fb37ad02bf0922475","event_at":"2026-07-28T03:00:26.255000Z","event_type":"price_change","frame_hash":"4ed138e51eb1d486dd984b537d8f97b928a32686a5aae632dc4263cf76ad5548","frame_index":0,"kind":"data","monotonic_ns":309612338408625,"payload":{"event_type":"price_change","market":"0x779291bef19b6709f61e9764a954aafe9ffae488d50ae674aabdcb4f248006d5","price_changes":[{"asset_id":"14965588658799411272385430903075831224615961675357217884735713260981483529984","best_ask":"0.6","best_bid":"0.59","hash":"6e02b8560c580ae95e0eca1d74d14d95e7a24c32","price":"0.55","side":"BUY","size":"124.6"},{"asset_id":"8761897749749422724209054078244794145777693856614463256546737399611489089783","best_ask":"0.41","best_bid":"0.4","hash":"2acc706687363c7ef43bab8b57697b802c80d4ee","price":"0.45","side":"SELL","size":"124.6"}],"timestamp":"1785207626255"},"payload_hash":"4e6a1e8ebac896c3212c7a81992c59b456db17b708bbd696b9063139148a3e3e","raw_frame":"{\"market\":\"0x779291bef19b6709f61e9764a954aafe9ffae488d50ae674aabdcb4f248006d5\", \"price_changes\":[{\"asset_id\":\"14965588658799411272385430903075831224615961675357217884735713260981483529984\", \"price\":\"0.55\", \"size\":\"124.6\", \"side\":\"BUY\", \"hash\":\"6e02b8560c580ae95e0eca1d74d14d95e7a24c32\", \"best_bid\":\"0.59\", \"best_ask\":\"0.6\"}, {\"asset_id\":\"8761897749749422724209054078244794145777693856614463256546737399611489089783\", \"price\":\"0.45\", \"size\":\"124.6\", \"side\":\"SELL\", \"hash\":\"2acc706687363c7ef43bab8b57697b802c80d4ee\", \"best_bid\":\"0.4\", \"best_ask\":\"0.41\"}], \"timestamp\":\"1785207626255\", \"event_type\":\"price_change\"}","received_at":"2026-07-28T03:00:29.319833Z","schema_version":"clob-market-ws.price_change.v1","sequence":null,"server_hash":null,"server_timestamp":"1785207626255","session_id":"3e519d9098404c15b234d96025eb1a2b","source":"clob_market_ws"},"received_at":"2026-07-28T03:00:29.319833Z","record_id":"a46762b0e835533505e2f46b77c9346ed4834507c3070a8b6a33f5b1d143268e","schema_fingerprint":"4aa3821a28b0b7c2400bc59aba4bcc0a76e971dadd19610d3ad38c768e124dc7","schema_version":"edge-lab-recorder.raw.v1","sequence":null,"source":"clob_market_ws"}
{"event_at":"2026-07-28T03:00:26.256000Z","event_fingerprint":"f12aa23017cf3cd564367938426a5aef65217f607dc8ea7351178f25df93d750","payload":{"connection_id":"a6b55582af5f430fb37ad02bf0922475","event_at":"2026-07-28T03:00:26.256000Z","event_type":"price_change","frame_hash":"82ffbb0c1aecd694f140f9c9d97fd8a3955a3751af5bb09d8d6ca2033b864882","frame_index":0,"kind":"data","monotonic_ns":309612344262833,"payload":{"event_type":"price_change","market":"0x779291bef19b6709f61e9764a954aafe9ffae488d50ae674aabdcb4f248006d5","price_changes":[{"asset_id":"8761897749749422724209054078244794145777693856614463256546737399611489089783","best_ask":"0.41","best_bid":"0.4","hash":"3ca472e68a8b25c56a6175fa9982fdeea1432646","price":"0.26","side":"BUY","size":"120"},{"asset_id":"14965588658799411272385430903075831224615961675357217884735713260981483529984","best_ask":"0.6","best_bid":"0.59","hash":"4f7f17a59720bdfa21f71935b6a8770640550df0","price":"0.74","side":"SELL","size":"120"}],"timestamp":"1785207626256"},"payload_hash":"2aaf93c8b41dfa40ffb0ecd1ea66ecafaf53eb5f5bf9b27a63e6d518a05afde1","raw_frame":"{\"market\":\"0x779291bef19b6709f61e9764a954aafe9ffae488d50ae674aabdcb4f248006d5\", \"price_changes\":[{\"asset_id\":\"8761897749749422724209054078244794145777693856614463256546737399611489089783\", \"price\":\"0.26\", \"size\":\"120\", \"side\":\"BUY\", \"hash\":\"3ca472e68a8b25c56a6175fa9982fdeea1432646\", \"best_bid\":\"0.4\", \"best_ask\":\"0.41\"}, {\"asset_id\":\"14965588658799411272385430903075831224615961675357217884735713260981483529984\", \"price\":\"0.74\", \"size\":\"120\", \"side\":\"SELL\", \"hash\":\"4f7f17a59720bdfa21f71935b6a8770640550df0\", \"best_bid\":\"0.59\", \"best_ask\":\"0.6\"}], \"timestamp\":\"1785207626256\", \"event_type\":\"price_change\"}","received_at":"2026-07-28T03:00:29.325692Z","schema_version":"clob-market-ws.price_change.v1","sequence":null,"server_hash":null,"server_timestamp":"1785207626256","session_id":"3e519d9098404c15b234d96025eb1a2b","source":"clob_market_ws"},"received_at":"2026-07-28T03:00:29.325692Z","record_id":"d61e0df4a8d9fc094fd738cf9e903cea9f9f55850dc45c497c629159812457b4","schema_fingerprint":"4aa3821a28b0b7c2400bc59aba4bcc0a76e971dadd19610d3ad38c768e124dc7","schema_version":"edge-lab-recorder.raw.v1","sequence":null,"source":"clob_market_ws"}
{"event_at":"2026-07-28T03:00:26.257000Z","event_fingerprint":"e6863df29ca0628f423004cd71b1f698622f61245421c99fc96f54bdf3ada54f","payload":{"connection_id":"a6b55582af5f430fb37ad02bf0922475","event_at":"2026-07-28T03:00:26.257000Z","event_type":"price_change","frame_hash":"c1bf617b7e8425b456ade7df51dc1dbb4f68c8b04df6396b2cc3401979b4e88d","frame_index":0,"kind":"data","monotonic_ns":309612359589041,"payload":{"event_type":"price_change","market":"0x779291bef19b6709f61e9764a954aafe9ffae488d50ae674aabdcb4f248006d5","price_changes":[{"asset_id":"8761897749749422724209054078244794145777693856614463256546737399611489089783","best_ask":"0.41","best_bid":"0.4","hash":"3849ce011c24fa891402602eaaf5db1a45f80a17","price":"0.35","side":"BUY","size":"175"},{"asset_id":"14965588658799411272385430903075831224615961675357217884735713260981483529984","best_ask":"0.6","best_bid":"0.59","hash":"b08b502b1886526928603d51c8972aa9323e1ca0","price":"0.65","side":"SELL","size":"175"}],"timestamp":"1785207626257"},"payload_hash":"1233ef362ff8376d31935366bbebea4e5cbe71330d9dee2d1233ed387704122b","raw_frame":"{\"market\":\"0x779291bef19b6709f61e9764a954aafe9ffae488d50ae674aabdcb4f248006d5\", \"price_changes\":[{\"asset_id\":\"8761897749749422724209054078244794145777693856614463256546737399611489089783\", \"price\":\"0.35\", \"size\":\"175\", \"side\":\"BUY\", \"hash\":\"3849ce011c24fa891402602eaaf5db1a45f80a17\", \"best_bid\":\"0.4\", \"best_ask\":\"0.41\"}, {\"asset_id\":\"14965588658799411272385430903075831224615961675357217884735713260981483529984\", \"price\":\"0.65\", \"size\":\"175\", \"side\":\"SELL\", \"hash\":\"b08b502b1886526928603d51c8972aa9323e1ca0\", \"best_bid\":\"0.59\", \"best_ask\":\"0.6\"}], \"timestamp\":\"1785207626257\", \"event_type\":\"price_change\"}","received_at":"2026-07-28T03:00:29.341020Z","schema_version":"clob-market-ws.price_change.v1","sequence":null,"server_hash":null,"server_timestamp":"1785207626257","session_id":"3e519d9098404c15b234d96025eb1a2b","source":"clob_market_ws"},"received_at":"2026-07-28T03:00:29.341020Z","record_id":"18612265bc96c713520fe5eb2d275fbef80253837deb78877dbd6b88601fff3e","schema_fingerprint":"4aa3821a28b0b7c2400bc59aba4bcc0a76e971dadd19610d3ad38c768e124dc7","schema_version":"edge-lab-recorder.raw.v1","sequence":null,"source":"clob_market_ws"}
{"event_at":"2026-07-28T03:00:26.257000Z","event_fingerprint":"113d0b66e6742a063e350079c1a3b233b75d49caffcd764f17d15960ced01683","payload":{"connection_id":"a6b55582af5f430fb37ad02bf0922475","event_at":"2026-07-28T03:00:26.257000Z","event_type":"price_change","frame_hash":"ee3006173315256954c85f2d3041fb7e5cf4c765b89989735dbe0a2feba7937e","frame_index":0,"kind":"data","monotonic_ns":309612362663250,"payload":{"event_type":"price_change","market":"0x779291bef19b6709f61e9764a954aafe9ffae488d50ae674aabdcb4f248006d5","price_changes":[{"asset_id":"8761897749749422724209054078244794145777693856614463256546737399611489089783","best_ask":"0.41","best_bid":"0.4","hash":"0e242ee4972d800631c84ad6eeccbdc29dab8bba","price":"0.25","side":"BUY","size":"248"},{"asset_id":"14965588658799411272385430903075831224615961675357217884735713260981483529984","best_ask":"0.6","best_bid":"0.59","hash":"841887e83304b1e108e02f00a8251382645130a3","price":"0.75","side":"SELL","size":"248"}],"timestamp":"1785207626257"},"payload_hash":"30b8cbd74adae3ab2a6f5e52d5040f0c33406fb7b2172ebeb7c47bf3e0cb30c6","raw_frame":"{\"market\":\"0x779291bef19b6709f61e9764a954aafe9ffae488d50ae674aabdcb4f248006d5\", \"price_changes\":[{\"asset_id\":\"8761897749749422724209054078244794145777693856614463256546737399611489089783\", \"price\":\"0.25\", \"size\":\"248\", \"side\":\"BUY\", \"hash\":\"0e242ee4972d800631c84ad6eeccbdc29dab8bba\", \"best_bid\":\"0.4\", \"best_ask\":\"0.41\"}, {\"asset_id\":\"14965588658799411272385430903075831224615961675357217884735713260981483529984\", \"price\":\"0.75\", \"size\":\"248\", \"side\":\"SELL\", \"hash\":\"841887e83304b1e108e02f00a8251382645130a3\", \"best_bid\":\"0.59\", \"best_ask\":\"0.6\"}], \"timestamp\":\"1785207626257\", \"event_type\":\"price_change\"}","received_at":"2026-07-28T03:00:29.344094Z","schema_version":"clob-market-ws.price_change.v1","sequence":null,"server_hash":null,"server_timestamp":"1785207626257","session_id":"3e519d9098404c15b234d96025eb1a2b","source":"clob_market_ws"},"received_at":"2026-07-28T03:00:29.344094Z","record_id":"ca679d5fc023901fcd8ca705aee7111fb2db2fca259c681a5053dc6815cf6cc4","schema_fingerprint":"4aa3821a28b0b7c2400bc59aba4bcc0a76e971dadd19610d3ad38c768e124dc7","schema_version":"edge-lab-recorder.raw.v1","sequence":null,"source":"clob_market_ws"}
{"event_at":"2026-07-28T03:00:26.258000Z","event_fingerprint":"15ea52e44865510795d1d00d654049846615ac859229dc77a7d8be473ab3bd87","payload":{"connection_id":"a6b55582af5f430fb37ad02bf0922475","event_at":"2026-07-28T03:00:26.258000Z","event_type":"price_change","frame_hash":"59dc6d78352ef8f59504443652f13331ce7e3bda27b3f10efce8096662622971","frame_index":0,"kind":"data","monotonic_ns":309612364712125,"payload":{"event_type":"price_change","market":"0x779291bef19b6709f61e9764a954aafe9ffae488d50ae674aabdcb4f248006d5","price_changes":[{"asset_id":"14965588658799411272385430903075831224615961675357217884735713260981483529984","best_ask":"0.6","best_bid":"0.59","hash":"bfb295e15a7cc7a16152b93d5bf62902c711daaa","price":"0.59","side":"BUY","size":"507.83"},{"asset_id":"8761897749749422724209054078244794145777693856614463256546737399611489089783","best_ask":"0.41","best_bid":"0.4","hash":"29cfbfa92866bec5c278161c7c15ecda45e8d874","price":"0.41","side":"SELL","size":"507.83"}],"timestamp":"1785207626258"},"payload_hash":"94dce63196d8e69f612b01b4398baf4334be92cc9102a1ff5a063d28ec895d2a","raw_frame":"{\"market\":\"0x779291bef19b6709f61e9764a954aafe9ffae488d50ae674aabdcb4f248006d5\", \"price_changes\":[{\"asset_id\":\"14965588658799411272385430903075831224615961675357217884735713260981483529984\", \"price\":\"0.59\", \"size\":\"507.83\", \"side\":\"BUY\", \"hash\":\"bfb295e15a7cc7a16152b93d5bf62902c711daaa\", \"best_bid\":\"0.59\", \"best_ask\":\"0.6\"}, {\"asset_id\":\"8761897749749422724209054078244794145777693856614463256546737399611489089783\", \"price\":\"0.41\", \"size\":\"507.83\", \"side\":\"SELL\", \"hash\":\"29cfbfa92866bec5c278161c7c15ecda45e8d874\", \"best_bid\":\"0.4\", \"best_ask\":\"0.41\"}], \"timestamp\":\"1785207626258\", \"event_type\":\"price_change\"}","received_at":"2026-07-28T03:00:29.346142Z","schema_version":"clob-market-ws.price_change.v1","sequence":null,"server_hash":null,"server_timestamp":"1785207626258","session_id":"3e519d9098404c15b234d96025eb1a2b","source":"clob_market_ws"},"received_at":"2026-07-28T03:00:29.346142Z","record_id":"e952305f516f1b096cf6aa60831b4d27e6d4594fba2d2c3772df2d6712c7481d","schema_fingerprint":"4aa3821a28b0b7c2400bc59aba4bcc0a76e971dadd19610d3ad38c768e124dc7","schema_version":"edge-lab-recorder.raw.v1","sequence":null,"source":"clob_market_ws"}
{"event_at":"2026-07-28T03:00:26.261000Z","event_fingerprint":"1611d8a067df1cc03c67ce82db2b3833fac51bcf1281db98848a4218856ca8bc","payload":{"connection_id":"a6b55582af5f430fb37ad02bf0922475","event_at":"2026-07-28T03:00:26.261000Z","event_type":"price_change","frame_hash":"e551ef7b6293df1200a312e5cf3bc55c8b33edddf77015d7cd4938422b098b76","frame_index":0,"kind":"data","monotonic_ns":309612368974000,"payload":{"event_type":"price_change","market":"0x779291bef19b6709f61e9764a954aafe9ffae488d50ae674aabdcb4f248006d5","price_changes":[{"asset_id":"14965588658799411272385430903075831224615961675357217884735713260981483529984","best_ask":"0.6","best_bid":"0.59","hash":"a04f220b9c9c9ffccb8742c08ddc2886dec5a6d5","price":"0.55","side":"BUY","size":"154.6"},{"asset_id":"8761897749749422724209054078244794145777693856614463256546737399611489089783","best_ask":"0.41","best_bid":"0.4","hash":"45659858c5225c81672776f3461ada4f0c872797","price":"0.45","side":"SELL","size":"154.6"}],"timestamp":"1785207626261"},"payload_hash":"5b451941093c87e15fe062499515cba69e46640297a1c8fdd888849dc656de9c","raw_frame":"{\"market\":\"0x779291bef19b6709f61e9764a954aafe9ffae488d50ae674aabdcb4f248006d5\", \"price_changes\":[{\"asset_id\":\"14965588658799411272385430903075831224615961675357217884735713260981483529984\", \"price\":\"0.55\", \"size\":\"154.6\", \"side\":\"BUY\", \"hash\":\"a04f220b9c9c9ffccb8742c08ddc2886dec5a6d5\", \"best_bid\":\"0.59\", \"best_ask\":\"0.6\"}, {\"asset_id\":\"8761897749749422724209054078244794145777693856614463256546737399611489089783\", \"price\":\"0.45\", \"size\":\"154.6\", \"side\":\"SELL\", \"hash\":\"45659858c5225c81672776f3461ada4f0c872797\", \"best_bid\":\"0.4\", \"best_ask\":\"0.41\"}], \"timestamp\":\"1785207626261\", \"event_type\":\"price_change\"}","received_at":"2026-07-28T03:00:29.350399Z","schema_version":"clob-market-ws.price_change.v1","sequence":null,"server_hash":null,"server_timestamp":"1785207626261","session_id":"3e519d9098404c15b234d96025eb1a2b","source":"clob_market_ws"},"received_at":"2026-07-28T03:00:29.350399Z","record_id":"58a9c0bd2e5c201ec8b7b49bb7c860335184e2e15081c2625e7c5740e10c4dec","schema_fingerprint":"4aa3821a28b0b7c2400bc59aba4bcc0a76e971dadd19610d3ad38c768e124dc7","schema_version":"edge-lab-recorder.raw.v1","sequence":null,"source":"clob_market_ws"}
{"event_at":"2026-07-28T03:00:26.262000Z","event_fingerprint":"c759e8d0e7145b93c43b3a886b232de79d30f942ac52790143c84130fbef7dd3","payload":{"connection_id":"a6b55582af5f430fb37ad02bf0922475","event_at":"2026-07-28T03:00:26.262000Z","event_type":"price_change","frame_hash":"bf3de9bf3c101e2e9a33cb172144102eb0b28358b92ee04ba8714e2c99907189","frame_index":0,"kind":"data","monotonic_ns":309612373163500,"payload":{"event_type":"price_change","market":"0x779291bef19b6709f61e9764a954aafe9ffae488d50ae674aabdcb4f248006d5","price_changes":[{"asset_id":"14965588658799411272385430903075831224615961675357217884735713260981483529984","best_ask":"0.6","best_bid":"0.59","hash":"b6d6513dd4750d60978e2cb05f35aee3d7340476","price":"0.55","side":"BUY","size":"184.6"},{"asset_id":"8761897749749422724209054078244794145777693856614463256546737399611489089783","best_ask":"0.41","best_bid":"0.4","hash":"38ac658eca15d6d4c11267c8cc3d052a64a6323f","price":"0.45","side":"SELL","size":"184.6"}],"timestamp":"1785207626262"},"payload_hash":"e781f625bd6354650c3b17bddf229d6ef294a84bf02abe582391084f1dcdf572","raw_frame":"{\"market\":\"0x779291bef19b6709f61e9764a954aafe9ffae488d50ae674aabdcb4f248006d5\", \"price_changes\":[{\"asset_id\":\"14965588658799411272385430903075831224615961675357217884735713260981483529984\", \"price\":\"0.55\", \"size\":\"184.6\", \"side\":\"BUY\", \"hash\":\"b6d6513dd4750d60978e2cb05f35aee3d7340476\", \"best_bid\":\"0.59\", \"best_ask\":\"0.6\"}, {\"asset_id\":\"8761897749749422724209054078244794145777693856614463256546737399611489089783\", \"price\":\"0.45\", \"size\":\"184.6\", \"side\":\"SELL\", \"hash\":\"38ac658eca15d6d4c11267c8cc3d052a64a6323f\", \"best_bid\":\"0.4\", \"best_ask\":\"0.41\"}], \"timestamp\":\"1785207626262\", \"event_type\":\"price_change\"}","received_at":"2026-07-28T03:00:29.354588Z","schema_version":"clob-market-ws.price_change.v1","sequence":null,"server_hash":null,"server_timestamp":"1785207626262","session_id":"3e519d9098404c15b234d96025eb1a2b","source":"clob_market_ws"},"received_at":"2026-07-28T03:00:29.354588Z","record_id":"4b6cea08ca57de1fe290d6959bc2a2cdbc068a8b6196d743e96e50bb5d5f00ce","schema_fingerprint":"4aa3821a28b0b7c2400bc59aba4bcc0a76e971dadd19610d3ad38c768e124dc7","schema_version":"edge-lab-recorder.raw.v1","sequence":null,"source":"clob_market_ws"}
{"event_at":"2026-07-28T03:00:26.264000Z","event_fingerprint":"fd57d346178a9d3ac1d6ec69f0b549d59d0f2cc21446d52f0cd658614a787f1c","payload":{"connection_id":"a6b55582af5f430fb37ad02bf0922475","event_at":"2026-07-28T03:00:26.264000Z","event_type":"price_change","frame_hash":"f41eaff1dc8ab54530a6c286e0549351dd87528ed14d1e6e6c8bee856e2ce4ff","frame_index":0,"kind":"data","monotonic_ns":309612377659791,"payload":{"event_type":"price_change","market":"0x779291bef19b6709f61e9764a954aafe9ffae488d50ae674aabdcb4f248006d5","price_changes":[{"asset_id":"14965588658799411272385430903075831224615961675357217884735713260981483529984","best_ask":"0.6","best_bid":"0.59","hash":"dcd8241042e4db2ac2477266245f0b51aa884846","price":"0.51","side":"BUY","size":"182"},{"asset_id":"8761897749749422724209054078244794145777693856614463256546737399611489089783","best_ask":"0.41","best_bid":"0.4","hash":"273525e202221250b3a9398080fceb73f559e780","price":"0.49","side":"SELL","size":"182"}],"timestamp":"1785207626264"},"payload_hash":"bee0691493cffc24eb391f10a8b54b8ff23de6ff0667bcca3a63d255209e4917","raw_frame":"{\"market\":\"0x779291bef19b6709f61e9764a954aafe9ffae488d50ae674aabdcb4f248006d5\", \"price_changes\":[{\"asset_id\":\"14965588658799411272385430903075831224615961675357217884735713260981483529984\", \"price\":\"0.51\", \"size\":\"182\", \"side\":\"BUY\", \"hash\":\"dcd8241042e4db2ac2477266245f0b51aa884846\", \"best_bid\":\"0.59\", \"best_ask\":\"0.6\"}, {\"asset_id\":\"8761897749749422724209054078244794145777693856614463256546737399611489089783\", \"price\":\"0.49\", \"size\":\"182\", \"side\":\"SELL\", \"hash\":\"273525e202221250b3a9398080fceb73f559e780\", \"best_bid\":\"0.4\", \"best_ask\":\"0.41\"}], \"timestamp\":\"1785207626264\", \"event_type\":\"price_change\"}","received_at":"2026-07-28T03:00:29.359090Z","schema_version":"clob-market-ws.price_change.v1","sequence":null,"server_hash":null,"server_timestamp":"1785207626264","session_id":"3e519d9098404c15b234d96025eb1a2b","source":"clob_market_ws"},"received_at":"2026-07-28T03:00:29.359090Z","record_id":"4021c92e55577d529e4dd76d79f41552f2d2621052472b0dd48b92409aa43e5a","schema_fingerprint":"4aa3821a28b0b7c2400bc59aba4bcc0a76e971dadd19610d3ad38c768e124dc7","schema_version":"edge-lab-recorder.raw.v1","sequence":null,"source":"clob_market_ws"}
{"event_at":"2026-07-28T03:00:26.265000Z","event_fingerprint":"9f90fa245902a9b6d103011a87f46e807b515f5be1a6c13a62f888f1fea7940f","payload":{"connection_id":"a6b55582af5f430fb37ad02bf0922475","event_at":"2026-07-28T03:00:26.265000Z","event_type":"price_change","frame_hash":"e569f1849c611b0fdbaa411650dfd5e3862ed190ccde1d30637a29009f044af6","frame_index":0,"kind":"data","monotonic_ns":309612381687791,"payload":{"event_type":"price_change","market":"0x779291bef19b6709f61e9764a954aafe9ffae488d50ae674aabdcb4f248006d5","price_changes":[{"asset_id":"8761897749749422724209054078244794145777693856614463256546737399611489089783","best_ask":"0.41","best_bid":"0.4","hash":"ab250afdd3b8085b8e6745b72df122996b45272f","price":"0.31","side":"BUY","size":"101"},{"asset_id":"14965588658799411272385430903075831224615961675357217884735713260981483529984","best_ask":"0.6","best_bid":"0.59","hash":"fa0579e06aa872bae714076bd7e8895715d17441","price":"0.69","side":"SELL","size":"101"}],"timestamp":"1785207626265"},"payload_hash":"1a2c60650eb803168bbe2ef7dc6113280368b119f33c0cd81517665194f0526e","raw_frame":"{\"market\":\"0x779291bef19b6709f61e9764a954aafe9ffae488d50ae674aabdcb4f248006d5\", \"price_changes\":[{\"asset_id\":\"8761897749749422724209054078244794145777693856614463256546737399611489089783\", \"price\":\"0.31\", \"size\":\"101\", \"side\":\"BUY\", \"hash\":\"ab250afdd3b8085b8e6745b72df122996b45272f\", \"best_bid\":\"0.4\", \"best_ask\":\"0.41\"}, {\"asset_id\":\"14965588658799411272385430903075831224615961675357217884735713260981483529984\", \"price\":\"0.69\", \"size\":\"101\", \"side\":\"SELL\", \"hash\":\"fa0579e06aa872bae714076bd7e8895715d17441\", \"best_bid\":\"0.59\", \"best_ask\":\"0.6\"}], \"timestamp\":\"1785207626265\", \"event_type\":\"price_change\"}","received_at":"2026-07-28T03:00:29.363113Z","schema_version":"clob-market-ws.price_change.v1","sequence":null,"server_hash":null,"server_timestamp":"1785207626265","session_id":"3e519d9098404c15b234d96025eb1a2b","source":"clob_market_ws"},"received_at":"2026-07-28T03:00:29.363113Z","record_id":"dd15227d0c3a51280b7bdf9864680d8d2589f5fa46b9f851705f1b34da8cdc2d","schema_fingerprint":"4aa3821a28b0b7c2400bc59aba4bcc0a76e971dadd19610d3ad38c768e124dc7","schema_version":"edge-lab-recorder.raw.v1","sequence":null,"source":"clob_market_ws"}
{"event_at":"2026-07-28T03:00:26.265000Z","event_fingerprint":"400c4075f66de62850f909563153e56419d746262b37fe71b475200fa1dc62dd","payload":{"connection_id":"a6b55582af5f430fb37ad02bf0922475","event_at":"2026-07-28T03:00:26.265000Z","event_type":"price_change","frame_hash":"a7b16cbd87e6187681c85800752b178bd45ed8c021f47e9a1df9f0ff088858d0","frame_index":0,"kind":"data","monotonic_ns":309612387896625,"payload":{"event_type":"price_change","market":"0x779291bef19b6709f61e9764a954aafe9ffae488d50ae674aabdcb4f248006d5","price_changes":[{"asset_id":"8761897749749422724209054078244794145777693856614463256546737399611489089783","best_ask":"0.41","best_bid":"0.4","hash":"ab250afdd3b8085b8e6745b72df122996b45272f","price":"0.3","side":"BUY","size":"131"},{"asset_id":"14965588658799411272385430903075831224615961675357217884735713260981483529984","best_ask":"0.6","best_bid":"0.59","hash":"fa0579e06aa872bae714076bd7e8895715d17441","price":"0.7","side":"SELL","size":"131"}],"timestamp":"1785207626265"},"payload_hash":"19407d343bd8c16fb6d706ece09d9524d87368e193d980a979673f74b243e55a","raw_frame":"{\"market\":\"0x779291bef19b6709f61e9764a954aafe9ffae488d50ae674aabdcb4f248006d5\", \"price_changes\":[{\"asset_id\":\"8761897749749422724209054078244794145777693856614463256546737399611489089783\", \"price\":\"0.3\", \"size\":\"131\", \"side\":\"BUY\", \"hash\":\"ab250afdd3b8085b8e6745b72df122996b45272f\", \"best_bid\":\"0.4\", \"best_ask\":\"0.41\"}, {\"asset_id\":\"14965588658799411272385430903075831224615961675357217884735713260981483529984\", \"price\":\"0.7\", \"size\":\"131\", \"side\":\"SELL\", \"hash\":\"fa0579e06aa872bae714076bd7e8895715d17441\", \"best_bid\":\"0.59\", \"best_ask\":\"0.6\"}], \"timestamp\":\"1785207626265\", \"event_type\":\"price_change\"}","received_at":"2026-07-28T03:00:29.369321Z","schema_version":"clob-market-ws.price_change.v1","sequence":null,"server_hash":null,"server_timestamp":"1785207626265","session_id":"3e519d9098404c15b234d96025eb1a2b","source":"clob_market_ws"},"received_at":"2026-07-28T03:00:29.369321Z","record_id":"699cfb838673dcec4b718217320d87a2b1f2bc6faaac83950079b30317b38b7c","schema_fingerprint":"4aa3821a28b0b7c2400bc59aba4bcc0a76e971dadd19610d3ad38c768e124dc7","schema_version":"edge-lab-recorder.raw.v1","sequence":null,"source":"clob_market_ws"}
{"event_at":"2026-07-28T03:00:26.265000Z","event_fingerprint":"3752805df25ec604baefc67ad4f5cc983ec9ebb0270a2e3dcd643b1c05136e9c","payload":{"connection_id":"a6b55582af5f430fb37ad02bf0922475","event_at":"2026-07-28T03:00:26.265000Z","event_type":"price_change","frame_hash":"2aac0d67350ddcd6233e9af08cdfd9479ea5be75bcef53b7829e7a18409ccb4b","frame_index":0,"kind":"data","monotonic_ns":309612399315791,"payload":{"event_type":"price_change","market":"0x779291bef19b6709f61e9764a954aafe9ffae488d50ae674aabdcb4f248006d5","price_changes":[{"asset_id":"8761897749749422724209054078244794145777693856614463256546737399611489089783","best_ask":"0.41","best_bid":"0.4","hash":"88ef1097c19e591adba2ab41e876d83856c23398","price":"0.37","side":"BUY","size":"10"},{"asset_id":"14965588658799411272385430903075831224615961675357217884735713260981483529984","best_ask":"0.6","best_bid":"0.59","hash":"e79a847e75456a357e6e643a0c801af41fd36d76","price":"0.63","side":"SELL","size":"10"}],"timestamp":"1785207626265"},"payload_hash":"404a50be7b4b35d968aeb80ad4f974925ace7f1096e9c9160f7721385d3f6eed","raw_frame":"{\"market\":\"0x779291bef19b6709f61e9764a954aafe9ffae488d50ae674aabdcb4f248006d5\", \"price_changes\":[{\"asset_id\":\"8761897749749422724209054078244794145777693856614463256546737399611489089783\", \"price\":\"0.37\", \"size\":\"10\", \"side\":\"BUY\", \"hash\":\"88ef1097c19e591adba2ab41e876d83856c23398\", \"best_bid\":\"0.4\", \"best_ask\":\"0.41\"}, {\"asset_id\":\"14965588658799411272385430903075831224615961675357217884735713260981483529984\", \"price\":\"0.63\", \"size\":\"10\", \"side\":\"SELL\", \"hash\":\"e79a847e75456a357e6e643a0c801af41fd36d76\", \"best_bid\":\"0.59\", \"best_ask\":\"0.6\"}], \"timestamp\":\"1785207626265\", \"event_type\":\"price_change\"}","received_at":"2026-07-28T03:00:29.380741Z","schema_version":"clob-market-ws.price_change.v1","sequence":null,"server_hash":null,"server_timestamp":"1785207626265","session_id":"3e519d9098404c15b234d96025eb1a2b","source":"clob_market_ws"},"received_at":"2026-07-28T03:00:29.380741Z","record_id":"5ee146fa97f771ee24a4f1e1237adab7ecb5758ddce4ce7aee8f49d43a6eda67","schema_fingerprint":"4aa3821a28b0b7c2400bc59aba4bcc0a76e971dadd19610d3ad38c768e124dc7","schema_version":"edge-lab-recorder.raw.v1","sequence":null,"source":"clob_market_ws"}
{"event_at":"2026-07-28T03:00:26.266000Z","event_fingerprint":"5677da04a2a1e9903f4273203ba60cf9630698a015a4d3700e6ba3206baf9dd5","payload":{"connection_id":"a6b55582af5f430fb37ad02bf0922475","event_at":"2026-07-28T03:00:26.266000Z","event_type":"price_change","frame_hash":"53490382f8fe864f6a4897ce7f6358d47d45d72a18273d489dc791b50c0b1989","frame_index":0,"kind":"data","monotonic_ns":309612406558041,"payload":{"event_type":"price_change","market":"0x779291bef19b6709f61e9764a954aafe9ffae488d50ae674aabdcb4f248006d5","price_changes":[{"asset_id":"8761897749749422724209054078244794145777693856614463256546737399611489089783","best_ask":"0.41","best_bid":"0.4","hash":"7d5341a675b62ec865772538aa3c8790a810ddca","price":"0.37","side":"BUY","size":"106"},{"asset_id":"14965588658799411272385430903075831224615961675357217884735713260981483529984","best_ask":"0.6","best_bid":"0.59","hash":"5deb4b1afe89360bde14c01e2d5d3b9ae4920791","price":"0.63","side":"SELL","size":"106"}],"timestamp":"1785207626266"},"payload_hash":"ce3bd4dcc8e3d94b3925e2233916c54ebc44b70d9faae8c94e68bf0299b8caa7","raw_frame":"{\"market\":\"0x779291bef19b6709f61e9764a954aafe9ffae488d50ae674aabdcb4f248006d5\", \"price_changes\":[{\"asset_id\":\"8761897749749422724209054078244794145777693856614463256546737399611489089783\", \"price\":\"0.37\", \"size\":\"106\", \"side\":\"BUY\", \"hash\":\"7d5341a675b62ec865772538aa3c8790a810ddca\", \"best_bid\":\"0.4\", \"best_ask\":\"0.41\"}, {\"asset_id\":\"14965588658799411272385430903075831224615961675357217884735713260981483529984\", \"price\":\"0.63\", \"size\":\"106\", \"side\":\"SELL\", \"hash\":\"5deb4b1afe89360bde14c01e2d5d3b9ae4920791\", \"best_bid\":\"0.59\", \"best_ask\":\"0.6\"}], \"timestamp\":\"1785207626266\", \"event_type\":\"price_change\"}","received_at":"2026-07-28T03:00:29.387983Z","schema_version":"clob-market-ws.price_change.v1","sequence":null,"server_hash":null,"server_timestamp":"1785207626266","session_id":"3e519d9098404c15b234d96025eb1a2b","source":"clob_market_ws"},"received_at":"2026-07-28T03:00:29.387983Z","record_id":"fdf1d6be95685807fa450e888fe94cedc0bb4e2b8a395d14038503683acbad33","schema_fingerprint":"4aa3821a28b0b7c2400bc59aba4bcc0a76e971dadd19610d3ad38c768e124dc7","schema_version":"edge-lab-recorder.raw.v1","sequence":null,"source":"clob_market_ws"}
{"event_at":"2026-07-28T03:00:26.267000Z","event_fingerprint":"96ee50be790c456bab266a92b06d45a521392f8d937acf095571f9d239bf29c6","payload":{"connection_id":"a6b55582af5f430fb37ad02bf0922475","event_at":"2026-07-28T03:00:26.267000Z","event_type":"price_change","frame_hash":"2208b819d380a52f685e89f86ff9a62828245f2bb01ab5a189f2e1e56e7a7bad","frame_index":0,"kind":"data","monotonic_ns":309612417770166,"payload":{"event_type":"price_change","market":"0x779291bef19b6709f61e9764a954aafe9ffae488d50ae674aabdcb4f248006d5","price_changes":[{"asset_id":"8761897749749422724209054078244794145777693856614463256546737399611489089783","best_ask":"0.41","best_bid":"0.4","hash":"066ca92255c4fff7e33c0b284f46e576125975d0","price":"0.35","side":"BUY","size":"170"},{"asset_id":"14965588658799411272385430903075831224615961675357217884735713260981483529984","best_ask":"0.6","best_bid":"0.59","hash":"7a8b25b89e3e302d38a00614756d079b4cf541de","price":"0.65","side":"SELL","size":"170"}],"timestamp":"1785207626267"},"payload_hash":"1a85b071ecf70b996d4eb4d8ffac21c86fa0d5a4d3299b60bc2c4dcd9edf4140","raw_frame":"{\"market\":\"0x779291bef19b6709f61e9764a954aafe9ffae488d50ae674aabdcb4f248006d5\", \"price_changes\":[{\"asset_id\":\"8761897749749422724209054078244794145777693856614463256546737399611489089783\", \"price\":\"0.35\", \"size\":\"170\", \"side\":\"BUY\", \"hash\":\"066ca92255c4fff7e33c0b284f46e576125975d0\", \"best_bid\":\"0.4\", \"best_ask\":\"0.41\"}, {\"asset_id\":\"14965588658799411272385430903075831224615961675357217884735713260981483529984\", \"price\":\"0.65\", \"size\":\"170\", \"side\":\"SELL\", \"hash\":\"7a8b25b89e3e302d38a00614756d079b4cf541de\", \"best_bid\":\"0.59\", \"best_ask\":\"0.6\"}], \"timestamp\":\"1785207626267\", \"event_type\":\"price_change\"}","received_at":"2026-07-28T03:00:29.399195Z","schema_version":"clob-market-ws.price_change.v1","sequence":null,"server_hash":null,"server_timestamp":"1785207626267","session_id":"3e519d9098404c15b234d96025eb1a2b","source":"clob_market_ws"},"received_at":"2026-07-28T03:00:29.399195Z","record_id":"c72aa3d601cc1cae6ebdb969771fc0c2344e9f57c517f2dfb371b3c0234b9ca4","schema_fingerprint":"4aa3821a28b0b7c2400bc59aba4bcc0a76e971dadd19610d3ad38c768e124dc7","schema_version":"edge-lab-recorder.raw.v1","sequence":null,"source":"clob_market_ws"}
{"event_at":"2026-07-28T03:00:26.272000Z","event_fingerprint":"144e464cbd1a4c7d5ea47e639768670484f8939bf76ffdfa4989bff0a170a7e1","payload":{"connection_id":"a6b55582af5f430fb37ad02bf0922475","event_at":"2026-07-28T03:00:26.272000Z","event_type":"price_change","frame_hash":"38fedbd9fdb8120433f1ca8f17da2496b91746e77e965e88c5cb950a456930b6","frame_index":0,"kind":"data","monotonic_ns":309612422958500,"payload":{"event_type":"price_change","market":"0x779291bef19b6709f61e9764a954aafe9ffae488d50ae674aabdcb4f248006d5","price_changes":[{"asset_id":"8761897749749422724209054078244794145777693856614463256546737399611489089783","best_ask":"0.41","best_bid":"0.4","hash":"2a4b99ff2be9df531f22c344cc38db580151d838","price":"0.37","side":"BUY","size":"118.6"},{"asset_id":"14965588658799411272385430903075831224615961675357217884735713260981483529984","best_ask":"0.6","best_bid":"0.59","hash":"6b13af750491f0722b6fcd6dda274d05b7ece35e","price":"0.63","side":"SELL","size":"118.6"}],"timestamp":"1785207626272"},"payload_hash":"c5e5e7cf2a7f90f6d32d7fa81c7d9aa3697c6930b443753808b52a19ffe45d06","raw_frame":"{\"market\":\"0x779291bef19b6709f61e9764a954aafe9ffae488d50ae674aabdcb4f248006d5\", \"price_changes\":[{\"asset_id\":\"8761897749749422724209054078244794145777693856614463256546737399611489089783\", \"price\":\"0.37\", \"size\":\"118.6\", \"side\":\"BUY\", \"hash\":\"2a4b99ff2be9df531f22c344cc38db580151d838\", \"best_bid\":\"0.4\", \"best_ask\":\"0.41\"}, {\"asset_id\":\"14965588658799411272385430903075831224615961675357217884735713260981483529984\", \"price\":\"0.63\", \"size\":\"118.6\", \"side\":\"SELL\", \"hash\":\"6b13af750491f0722b6fcd6dda274d05b7ece35e\", \"best_bid\":\"0.59\", \"best_ask\":\"0.6\"}], \"timestamp\":\"1785207626272\", \"event_type\":\"price_change\"}","received_at":"2026-07-28T03:00:29.404384Z","schema_version":"clob-market-ws.price_change.v1","sequence":null,"server_hash":null,"server_timestamp":"1785207626272","session_id":"3e519d9098404c15b234d96025eb1a2b","source":"clob_market_ws"},"received_at":"2026-07-28T03:00:29.404384Z","record_id":"e215c7cde9d5df23e03f712e23b053ae7270f10e5f747015d428c1ea29de0003","schema_fingerprint":"4aa3821a28b0b7c2400bc59aba4bcc0a76e971dadd19610d3ad38c768e124dc7","schema_version":"edge-lab-recorder.raw.v1","sequence":null,"source":"clob_market_ws"}
{"event_at":"2026-07-28T03:00:26.273000Z","event_fingerprint":"7fddfe05164c531003685e698a542bf28c880e86160ff2cadf2efaa4d36a69fd","payload":{"connection_id":"a6b55582af5f430fb37ad02bf0922475","event_at":"2026-07-28T03:00:26.273000Z","event_type":"price_change","frame_hash":"cafe42afdb0c8d6b193c7d1098f914e42ddca2306690f4e708277fe637e8a651","frame_index":0,"kind":"data","monotonic_ns":309612429467416,"payload":{"event_type":"price_change","market":"0x779291bef19b6709f61e9764a954aafe9ffae488d50ae674aabdcb4f248006d5","price_changes":[{"asset_id":"8761897749749422724209054078244794145777693856614463256546737399611489089783","best_ask":"0.41","best_bid":"0.4","hash":"18fef3e48238f287ae1d710001b8bf326b62e13a","price":"0.35","side":"BUY","size":"70"},{"asset_id":"14965588658799411272385430903075831224615961675357217884735713260981483529984","best_ask":"0.6","best_bid":"0.59","hash":"bab6ead79f35c9addc072726b524893a86f3dcbd","price":"0.65","side":"SELL","size":"70"}],"timestamp":"1785207626273"},"payload_hash":"d50cbb08f440cd9662224416369ba15fadf2c87e0690f59b93969eea0be336a5","raw_frame":"{\"market\":\"0x779291bef19b6709f61e9764a954aafe9ffae488d50ae674aabdcb4f248006d5\", \"price_changes\":[{\"asset_id\":\"8761897749749422724209054078244794145777693856614463256546737399611489089783\", \"price\":\"0.35\", \"size\":\"70\", \"side\":\"BUY\", \"hash\":\"18fef3e48238f287ae1d710001b8bf326b62e13a\", \"best_bid\":\"0.4\", \"best_ask\":\"0.41\"}, {\"asset_id\":\"14965588658799411272385430903075831224615961675357217884735713260981483529984\", \"price\":\"0.65\", \"size\":\"70\", \"side\":\"SELL\", \"hash\":\"bab6ead79f35c9addc072726b524893a86f3dcbd\", \"best_bid\":\"0.59\", \"best_ask\":\"0.6\"}], \"timestamp\":\"1785207626273\", \"event_type\":\"price_change\"}","received_at":"2026-07-28T03:00:29.410890Z","schema_version":"clob-market-ws.price_change.v1","sequence":null,"server_hash":null,"server_timestamp":"1785207626273","session_id":"3e519d9098404c15b234d96025eb1a2b","source":"clob_market_ws"},"received_at":"2026-07-28T03:00:29.410890Z","record_id":"b40899bb16e5295ba799673a525d4df390a8b430b371a9a7dd57571879cc3456","schema_fingerprint":"4aa3821a28b0b7c2400bc59aba4bcc0a76e971dadd19610d3ad38c768e124dc7","schema_version":"edge-lab-recorder.raw.v1","sequence":null,"source":"clob_market_ws"}
{"event_at":"2026-07-28T03:00:26.274000Z","event_fingerprint":"027ca46465517494f7cb258767ff54cff48b7192c534893facb1b14b2e2f755d","payload":{"connection_id":"a6b55582af5f430fb37ad02bf0922475","event_at":"2026-07-28T03:00:26.274000Z","event_type":"price_change","frame_hash":"1113fd614660ec731f97c23f5c1e5258c046f6c466587a586ab7c4d9e7deda1d","frame_index":0,"kind":"data","monotonic_ns":309612436482125,"payload":{"event_type":"price_change","market":"0x779291bef19b6709f61e9764a954aafe9ffae488d50ae674aabdcb4f248006d5","price_changes":[{"asset_id":"8761897749749422724209054078244794145777693856614463256546737399611489089783","best_ask":"0.41","best_bid":"0.4","hash":"1f6d78960e556fed3ef32e2343c8b4c5c8152eae","price":"0.37","side":"BUY","size":"388.6"},{"asset_id":"14965588658799411272385430903075831224615961675357217884735713260981483529984","best_ask":"0.6","best_bid":"0.59","hash":"dc55bbc5f6b61a4448446f9fc470cd6a7b98ee13","price":"0.63","side":"SELL","size":"388.6"}],"timestamp":"1785207626274"},"payload_hash":"6bb76e832a0ece5f6a8304549b41af10c6b934c771c1109dca4a3d17888c15a3","raw_frame":"{\"market\":\"0x779291bef19b6709f61e9764a954aafe9ffae488d50ae674aabdcb4f248006d5\", \"price_changes\":[{\"asset_id\":\"8761897749749422724209054078244794145777693856614463256546737399611489089783\", \"price\":\"0.37\", \"size\":\"388.6\", \"side\":\"BUY\", \"hash\":\"1f6d78960e556fed3ef32e2343c8b4c5c8152eae\", \"best_bid\":\"0.4\", \"best_ask\":\"0.41\"}, {\"asset_id\":\"14965588658799411272385430903075831224615961675357217884735713260981483529984\", \"price\":\"0.63\", \"size\":\"388.6\", \"side\":\"SELL\", \"hash\":\"dc55bbc5f6b61a4448446f9fc470cd6a7b98ee13\", \"best_bid\":\"0.59\", \"best_ask\":\"0.6\"}], \"timestamp\":\"1785207626274\", \"event_type\":\"price_change\"}","received_at":"2026-07-28T03:00:29.417906Z","schema_version":"clob-market-ws.price_change.v1","sequence":null,"server_hash":null,"server_timestamp":"1785207626274","session_id":"3e519d9098404c15b234d96025eb1a2b","source":"clob_market_ws"},"received_at":"2026-07-28T03:00:29.417906Z","record_id":"12bf9808c795c9cccdddac75b24c2f5d332150881b32980527b1f0da0bf1034b","schema_fingerprint":"4aa3821a28b0b7c2400bc59aba4bcc0a76e971dadd19610d3ad38c768e124dc7","schema_version":"edge-lab-recorder.raw.v1","sequence":null,"source":"clob_market_ws"}
{"event_at":"2026-07-28T03:00:26.275000Z","event_fingerprint":"e2ff43b89520a348714feafd88161be4efc29e74984f5cab3e0dc3761925d35f","payload":{"connection_id":"a6b55582af5f430fb37ad02bf0922475","event_at":"2026-07-28T03:00:26.275000Z","event_type":"price_change","frame_hash":"a5a270926dee80492b3d04985b08fa203205cc43d22b24d6838b13b499e917dd","frame_index":0,"kind":"data","monotonic_ns":309612444435958,"payload":{"event_type":"price_change","market":"0x779291bef19b6709f61e9764a954aafe9ffae488d50ae674aabdcb4f248006d5","price_changes":[{"asset_id":"14965588658799411272385430903075831224615961675357217884735713260981483529984","best_ask":"0.6","best_bid":"0.59","hash":"f2f051be7514f3c342a27dff9c7b138dd102cb46","price":"0.45","side":"BUY","size":"199.14"},{"asset_id":"8761897749749422724209054078244794145777693856614463256546737399611489089783","best_ask":"0.41","best_bid":"0.4","hash":"43e31067a50d16c92f5522c16d94617e9f033928","price":"0.55","side":"SELL","size":"199.14"}],"timestamp":"1785207626275"},"payload_hash":"119fe0c972bfd503fa89a58f1a3a167b5f53ff5c39c781761dc52baeea766f2c","raw_frame":"{\"market\":\"0x779291bef19b6709f61e9764a954aafe9ffae488d50ae674aabdcb4f248006d5\", \"price_changes\":[{\"asset_id\":\"14965588658799411272385430903075831224615961675357217884735713260981483529984\", \"price\":\"0.45\", \"size\":\"199.14\", \"side\":\"BUY\", \"hash\":\"f2f051be7514f3c342a27dff9c7b138dd102cb46\", \"best_bid\":\"0.59\", \"best_ask\":\"0.6\"}, {\"asset_id\":\"8761897749749422724209054078244794145777693856614463256546737399611489089783\", \"price\":\"0.55\", \"size\":\"199.14\", \"side\":\"SELL\", \"hash\":\"43e31067a50d16c92f5522c16d94617e9f033928\", \"best_bid\":\"0.4\", \"best_ask\":\"0.41\"}], \"timestamp\":\"1785207626275\", \"event_type\":\"price_change\"}","received_at":"2026-07-28T03:00:29.425861Z","schema_version":"clob-market-ws.price_change.v1","sequence":null,"server_hash":null,"server_timestamp":"1785207626275","session_id":"3e519d9098404c15b234d96025eb1a2b","source":"clob_market_ws"},"received_at":"2026-07-28T03:00:29.425861Z","record_id":"6eea5eb931628302a458980761ea8bc15ad9a9f3ab8e7541a8509d5dc1ac6870","schema_fingerprint":"4aa3821a28b0b7c2400bc59aba4bcc0a76e971dadd19610d3ad38c768e124dc7","schema_version":"edge-lab-recorder.raw.v1","sequence":null,"source":"clob_market_ws"}
{"event_at":"2026-07-28T03:00:26.282000Z","event_fingerprint":"56501e88316bc6f548c90f5f5edc78abd26e984a7274e2f4fca0059fef902439","payload":{"connection_id":"a6b55582af5f430fb37ad02bf0922475","event_at":"2026-07-28T03:00:26.282000Z","event_type":"price_change","frame_hash":"d35a29ebfda8e28e5f4cfbee4ff37f8b6239174319e86e6289fe0e995009a161","frame_index":0,"kind":"data","monotonic_ns":309612451258250,"payload":{"event_type":"price_change","market":"0x779291bef19b6709f61e9764a954aafe9ffae488d50ae674aabdcb4f248006d5","price_changes":[{"asset_id":"8761897749749422724209054078244794145777693856614463256546737399611489089783","best_ask":"0.41","best_bid":"0.4","hash":"07616c6f8b8a01ed0a110c188bbd4765e2d4d9b1","price":"0.37","side":"BUY","size":"376"},{"asset_id":"14965588658799411272385430903075831224615961675357217884735713260981483529984","best_ask":"0.6","best_bid":"0.59","hash":"d572efafe2fe5909818a8649b22a60ee86d9fd2c","price":"0.63","side":"SELL","size":"376"}],"timestamp":"1785207626282"},"payload_hash":"83dddac1e065e898a5f2214390f81861ab939877b56cfc60f57e46df56b6ec73","raw_frame":"{\"market\":\"0x779291bef19b6709f61e9764a954aafe9ffae488d50ae674aabdcb4f248006d5\", \"price_changes\":[{\"asset_id\":\"8761897749749422724209054078244794145777693856614463256546737399611489089783\", \"price\":\"0.37\", \"size\":\"376\", \"side\":\"BUY\", \"hash\":\"07616c6f8b8a01ed0a110c188bbd4765e2d4d9b1\", \"best_bid\":\"0.4\", \"best_ask\":\"0.41\"}, {\"asset_id\":\"14965588658799411272385430903075831224615961675357217884735713260981483529984\", \"price\":\"0.63\", \"size\":\"376\", \"side\":\"SELL\", \"hash\":\"d572efafe2fe5909818a8649b22a60ee86d9fd2c\", \"best_bid\":\"0.59\", \"best_ask\":\"0.6\"}], \"timestamp\":\"1785207626282\", \"event_type\":\"price_change\"}","received_at":"2026-07-28T03:00:29.432681Z","schema_version":"clob-market-ws.price_change.v1","sequence":null,"server_hash":null,"server_timestamp":"1785207626282","session_id":"3e519d9098404c15b234d96025eb1a2b","source":"clob_market_ws"},"received_at":"2026-07-28T03:00:29.432681Z","record_id":"ebad26f72234c117dcee82ca2871c963a4666956e43b0c8e8aa6fe015ac0fb9a","schema_fingerprint":"4aa3821a28b0b7c2400bc59aba4bcc0a76e971dadd19610d3ad38c768e124dc7","schema_version":"edge-lab-recorder.raw.v1","sequence":null,"source":"clob_market_ws"}
{"event_at":"2026-07-28T03:00:26.286000Z","event_fingerprint":"235c02e141b44d69bbb16e63e2e82b6aa6945083472e412f6494f22697f74188","payload":{"connection_id":"a6b55582af5f430fb37ad02bf0922475","event_at":"2026-07-28T03:00:26.286000Z","event_type":"price_change","frame_hash":"bd8bcba95266a1ad45e5fc284679a6c479d4372efae5cba6b80b17ae7add267a","frame_index":0,"kind":"data","monotonic_ns":309612460155875,"payload":{"event_type":"price_change","market":"0x779291bef19b6709f61e9764a954aafe9ffae488d50ae674aabdcb4f248006d5","price_changes":[{"asset_id":"14965588658799411272385430903075831224615961675357217884735713260981483529984","best_ask":"0.6","best_bid":"0.59","hash":"52852ad9e85725156a3f6757055500a1785178f0","price":"0.45","side":"BUY","size":"125.07"},{"asset_id":"8761897749749422724209054078244794145777693856614463256546737399611489089783","best_ask":"0.41","best_bid":"0.4","hash":"b3f0a907e84678e51b7b3dc8d3de1ae0a95c0829","price":"0.55","side":"SELL","size":"125.07"}],"timestamp":"1785207626286"},"payload_hash":"3aa0908f14fb65a775d6146ed2f0becc90623f9f10a1fbc5747bac7a7e4adc08","raw_frame":"{\"market\":\"0x779291bef19b6709f61e9764a954aafe9ffae488d50ae674aabdcb4f248006d5\", \"price_changes\":[{\"asset_id\":\"14965588658799411272385430903075831224615961675357217884735713260981483529984\", \"price\":\"0.45\", \"size\":\"125.07\", \"side\":\"BUY\", \"hash\":\"52852ad9e85725156a3f6757055500a1785178f0\", \"best_bid\":\"0.59\", \"best_ask\":\"0.6\"}, {\"asset_id\":\"8761897749749422724209054078244794145777693856614463256546737399611489089783\", \"price\":\"0.55\", \"size\":\"125.07\", \"side\":\"SELL\", \"hash\":\"b3f0a907e84678e51b7b3dc8d3de1ae0a95c0829\", \"best_bid\":\"0.4\", \"best_ask\":\"0.41\"}], \"timestamp\":\"1785207626286\", \"event_type\":\"price_change\"}","received_at":"2026-07-28T03:00:29.441580Z","schema_version":"clob-market-ws.price_change.v1","sequence":null,"server_hash":null,"server_timestamp":"1785207626286","session_id":"3e519d9098404c15b234d96025eb1a2b","source":"clob_market_ws"},"received_at":"2026-07-28T03:00:29.441580Z","record_id":"46c2589e6c8350de6b851fda44add1586cbd8eff6b5a0ee4fc8dcefd6518bfcb","schema_fingerprint":"4aa3821a28b0b7c2400bc59aba4bcc0a76e971dadd19610d3ad38c768e124dc7","schema_version":"edge-lab-recorder.raw.v1","sequence":null,"source":"clob_market_ws"}
{"event_at":"2026-07-28T03:00:26.287000Z","event_fingerprint":"10a4ab0b0629ed115585eff79744585372d38bf812781a987465311b10f9a49b","payload":{"connection_id":"a6b55582af5f430fb37ad02bf0922475","event_at":"2026-07-28T03:00:26.287000Z","event_type":"price_change","frame_hash":"639dd4de40aa608841f361f953453c8af792315956fa2421c2602871fc85db34","frame_index":0,"kind":"data","monotonic_ns":309612465262083,"payload":{"event_type":"price_change","market":"0x779291bef19b6709f61e9764a954aafe9ffae488d50ae674aabdcb4f248006d5","price_changes":[{"asset_id":"14965588658799411272385430903075831224615961675357217884735713260981483529984","best_ask":"0.6","best_bid":"0.59","hash":"2bc94881af9de3c1d03d9b37999f915fe4886ff2","price":"0.45","side":"BUY","size":"51"},{"asset_id":"8761897749749422724209054078244794145777693856614463256546737399611489089783","best_ask":"0.41","best_bid":"0.4","hash":"5286c5d059e5a684a4b348a1cf8c64a9146f5362","price":"0.55","side":"SELL","size":"51"}],"timestamp":"1785207626287"},"payload_hash":"69b3fe44079b7de1f8d5e8436f6e92781138325ce1e468bf227b56b87f1828fe","raw_frame":"{\"market\":\"0x779291bef19b6709f61e9764a954aafe9ffae488d50ae674aabdcb4f248006d5\", \"price_changes\":[{\"asset_id\":\"14965588658799411272385430903075831224615961675357217884735713260981483529984\", \"price\":\"0.45\", \"size\":\"51\", \"side\":\"BUY\", \"hash\":\"2bc94881af9de3c1d03d9b37999f915fe4886ff2\", \"best_bid\":\"0.59\", \"best_ask\":\"0.6\"}, {\"asset_id\":\"8761897749749422724209054078244794145777693856614463256546737399611489089783\", \"price\":\"0.55\", \"size\":\"51\", \"side\":\"SELL\", \"hash\":\"5286c5d059e5a684a4b348a1cf8c64a9146f5362\", \"best_bid\":\"0.4\", \"best_ask\":\"0.41\"}], \"timestamp\":\"1785207626287\", \"event_type\":\"price_change\"}","received_at":"2026-07-28T03:00:29.446686Z","schema_version":"clob-market-ws.price_change.v1","sequence":null,"server_hash":null,"server_timestamp":"1785207626287","session_id":"3e519d9098404c15b234d96025eb1a2b","source":"clob_market_ws"},"received_at":"2026-07-28T03:00:29.446686Z","record_id":"a8db5693099335840b3acfa2a1bb848d6e7070271b52a1440c92ba7243fd6c27","schema_fingerprint":"4aa3821a28b0b7c2400bc59aba4bcc0a76e971dadd19610d3ad38c768e124dc7","schema_version":"edge-lab-recorder.raw.v1","sequence":null,"source":"clob_market_ws"}
{"event_at":"2026-07-28T03:00:26.300000Z","event_fingerprint":"304ae13fbbc669bde556760458e189761a66f2bff7807a13ae0129d79f9a1117","payload":{"connection_id":"a6b55582af5f430fb37ad02bf0922475","event_at":"2026-07-28T03:00:26.300000Z","event_type":"price_change","frame_hash":"eb647a4055d67c63d367aecc8f8347b74ca4878e14826942d0e09836e2902ef3","frame_index":0,"kind":"data","monotonic_ns":309612470949166,"payload":{"event_type":"price_change","market":"0x779291bef19b6709f61e9764a954aafe9ffae488d50ae674aabdcb4f248006d5","price_changes":[{"asset_id":"8761897749749422724209054078244794145777693856614463256546737399611489089783","best_ask":"0.41","best_bid":"0.4","hash":"88a42bc5bde807608f4e304f0656e057c1a95dba","price":"0.28","side":"BUY","size":"193.62"},{"asset_id":"14965588658799411272385430903075831224615961675357217884735713260981483529984","best_ask":"0.6","best_bid":"0.59","hash":"385d2db89d19f218e7b7a8c411e609ecc0446ddb","price":"0.72","side":"SELL","size":"193.62"}],"timestamp":"1785207626300"},"payload_hash":"da9bdb3d478df8702f08854973f1d65915fae9df4157fa1cb216b1334f16ed89","raw_frame":"{\"market\":\"0x779291bef19b6709f61e9764a954aafe9ffae488d50ae674aabdcb4f248006d5\", \"price_changes\":[{\"asset_id\":\"8761897749749422724209054078244794145777693856614463256546737399611489089783\", \"price\":\"0.28\", \"size\":\"193.62\", \"side\":\"BUY\", \"hash\":\"88a42bc5bde807608f4e304f0656e057c1a95dba\", \"best_bid\":\"0.4\", \"best_ask\":\"0.41\"}, {\"asset_id\":\"14965588658799411272385430903075831224615961675357217884735713260981483529984\", \"price\":\"0.72\", \"size\":\"193.62\", \"side\":\"SELL\", \"hash\":\"385d2db89d19f218e7b7a8c411e609ecc0446ddb\", \"best_bid\":\"0.59\", \"best_ask\":\"0.6\"}], \"timestamp\":\"1785207626300\", \"event_type\":\"price_change\"}","received_at":"2026-07-28T03:00:29.452374Z","schema_version":"clob-market-ws.price_change.v1","sequence":null,"server_hash":null,"server_timestamp":"1785207626300","session_id":"3e519d9098404c15b234d96025eb1a2b","source":"clob_market_ws"},"received_at":"2026-07-28T03:00:29.452374Z","record_id":"9b71163e80dc6afba42e92b209e0c09a3f184c26fd1b5f4f8b228a80611df082","schema_fingerprint":"4aa3821a28b0b7c2400bc59aba4bcc0a76e971dadd19610d3ad38c768e124dc7","schema_version":"edge-lab-recorder.raw.v1","sequence":null,"source":"clob_market_ws"}
{"event_at":"2026-07-28T03:00:26.312000Z","event_fingerprint":"f39197d37c53dad36e27df604c7399ea1542ddabcba1f4da2a76b3211e52ac60","payload":{"connection_id":"a6b55582af5f430fb37ad02bf0922475","event_at":"2026-07-28T03:00:26.312000Z","event_type":"price_change","frame_hash":"1541dc4ef5b207f9b7d6f1b37239ee15060c8e81fe2a17b177f1092752ca3cf5","frame_index":0,"kind":"data","monotonic_ns":309612476552833,"payload":{"event_type":"price_change","market":"0x779291bef19b6709f61e9764a954aafe9ffae488d50ae674aabdcb4f248006d5","price_changes":[{"asset_id":"8761897749749422724209054078244794145777693856614463256546737399611489089783","best_ask":"0.41","best_bid":"0.4","hash":"c5c6d586a406677332fd7101b4cfd3bbcaf2708f","price":"0.37","side":"BUY","size":"366"},{"asset_id":"14965588658799411272385430903075831224615961675357217884735713260981483529984","best_ask":"0.6","best_bid":"0.59","hash":"5411005b3fe72b252a8286785f9b0a91445ce952","price":"0.63","side":"SELL","size":"366"}],"timestamp":"1785207626312"},"payload_hash":"d905dde52f4a57b6c5ad466f3e29bd30c75a846d67f2326b9eaaf04408998358","raw_frame":"{\"market\":\"0x779291bef19b6709f61e9764a954aafe9ffae488d50ae674aabdcb4f248006d5\", \"price_changes\":[{\"asset_id\":\"8761897749749422724209054078244794145777693856614463256546737399611489089783\", \"price\":\"0.37\", \"size\":\"366\", \"side\":\"BUY\", \"hash\":\"c5c6d586a406677332fd7101b4cfd3bbcaf2708f\", \"best_bid\":\"0.4\", \"best_ask\":\"0.41\"}, {\"asset_id\":\"14965588658799411272385430903075831224615961675357217884735713260981483529984\", \"price\":\"0.63\", \"size\":\"366\", \"side\":\"SELL\", \"hash\":\"5411005b3fe72b252a8286785f9b0a91445ce952\", \"best_bid\":\"0.59\", \"best_ask\":\"0.6\"}], \"timestamp\":\"1785207626312\", \"event_type\":\"price_change\"}","received_at":"2026-07-28T03:00:29.457978Z","schema_version":"clob-market-ws.price_change.v1","sequence":null,"server_hash":null,"server_timestamp":"1785207626312","session_id":"3e519d9098404c15b234d96025eb1a2b","source":"clob_market_ws"},"received_at":"2026-07-28T03:00:29.457978Z","record_id":"c1ec1191aa4e1bab1fe1271e099b74fd6e410ed500727c9f57a9ad4a2b9a3b4c","schema_fingerprint":"4aa3821a28b0b7c2400bc59aba4bcc0a76e971dadd19610d3ad38c768e124dc7","schema_version":"edge-lab-recorder.raw.v1","sequence":null,"source":"clob_market_ws"}
