{"event_at":"2026-07-28T03:12:12.942000Z","event_fingerprint":"56b92b54f700cfbd16c7fe177637f877f30cbc387c8dd9b44adcdd2181543369","payload":{"connection_id":"a6b55582af5f430fb37ad02bf0922475","event_at":"2026-07-28T03:12:12.942000Z","event_type":"price_change","frame_hash":"b0a2eb052450d723275edf15e87f03cdcf2a11f41efc1e68fa0572eefae0f64d","frame_index":0,"kind":"data","monotonic_ns":310330147975416,"payload":{"event_type":"price_change","market":"0x779291bef19b6709f61e9764a954aafe9ffae488d50ae674aabdcb4f248006d5","price_changes":[{"asset_id":"8761897749749422724209054078244794145777693856614463256546737399611489089783","best_ask":"0.68","best_bid":"0.67","hash":"c01d894ce25abee5fd68ccfcd35f922c33050bef","price":"0.01","side":"BUY","size":"5300.02"},{"asset_id":"14965588658799411272385430903075831224615961675357217884735713260981483529984","best_ask":"0.33","best_bid":"0.32","hash":"ae207dce445ba41b6c37806d93e025ff450eb992","price":"0.99","side":"SELL","size":"5300.02"}],"timestamp":"1785208332942"},"payload_hash":"13188b358dd63b159e2e53d5202212b1e4d57bd3e31fbb7e870e88e3c039aa2f","raw_frame":"{\"market\":\"0x779291bef19b6709f61e9764a954aafe9ffae488d50ae674aabdcb4f248006d5\", \"price_changes\":[{\"asset_id\":\"8761897749749422724209054078244794145777693856614463256546737399611489089783\", \"price\":\"0.01\", \"size\":\"5300.02\", \"side\":\"BUY\", \"hash\":\"c01d894ce25abee5fd68ccfcd35f922c33050bef\", \"best_bid\":\"0.67\", \"best_ask\":\"0.68\"}, {\"asset_id\":\"14965588658799411272385430903075831224615961675357217884735713260981483529984\", \"price\":\"0.99\", \"size\":\"5300.02\", \"side\":\"SELL\", \"hash\":\"ae207dce445ba41b6c37806d93e025ff450eb992\", \"best_bid\":\"0.32\", \"best_ask\":\"0.33\"}], \"timestamp\":\"1785208332942\", \"event_type\":\"price_change\"}","received_at":"2026-07-28T03:12:27.113383Z","schema_version":"clob-market-ws.price_change.v1","sequence":null,"server_hash":null,"server_timestamp":"1785208332942","session_id":"3e519d9098404c15b234d96025eb1a2b","source":"clob_market_ws"},"received_at":"2026-07-28T03:12:27.113383Z","record_id":"56781fae8a02c221a8e95581f194222c7711ba2eb6a93022cbf88d8b0a0b155c","schema_fingerprint":"4aa3821a28b0b7c2400bc59aba4bcc0a76e971dadd19610d3ad38c768e124dc7","schema_version":"edge-lab-recorder.raw.v1","sequence":null,"source":"clob_market_ws"}
{"event_at":"2026-07-28T03:12:12.998000Z","event_fingerprint":"be78a132fa5cd352293f4612b2e3b52a9f43af931303e73e4cf3ef6965554626","payload":{"connection_id":"a6b55582af5f430fb37ad02bf0922475","event_at":"2026-07-28T03:12:12.998000Z","event_type":"price_change","frame_hash":"c08cfdd4e8429fd96dc573d0ac5315af81dde602096bf0b5a3b0c16aa6802af0","frame_index":0,"kind":"data","monotonic_ns":310330150210875,"payload":{"event_type":"price_change","market":"0x779291bef19b6709f61e9764a954aafe9ffae488d50ae674aabdcb4f248006d5","price_changes":[{"asset_id":"14965588658799411272385430903075831224615961675357217884735713260981483529984","best_ask":"0.33","best_bid":"0.32","hash":"85cc012a16db646b596e8d768691895f94ef86cc","price":"0.23","side":"BUY","size":"290"},{"asset_id":"8761897749749422724209054078244794145777693856614463256546737399611489089783","best_ask":"0.68","best_bid":"0.67","hash":"5f7db0deed000119dd9e7cee7409e719a9f9f182","price":"0.77","side":"SELL","size":"290"}],"timestamp":"1785208332998"},"payload_hash":"a735a3e8f3e67d479e9f605dbbe4793a5a54c7699050f82343605b625b0810d9","raw_frame":"{\"market\":\"0x779291bef19b6709f61e9764a954aafe9ffae488d50ae674aabdcb4f248006d5\", \"price_changes\":[{\"asset_id\":\"14965588658799411272385430903075831224615961675357217884735713260981483529984\", \"price\":\"0.23\", \"size\":\"290\", \"side\":\"BUY\", \"hash\":\"85cc012a16db646b596e8d768691895f94ef86cc\", \"best_bid\":\"0.32\", \"best_ask\":\"0.33\"}, {\"asset_id\":\"8761897749749422724209054078244794145777693856614463256546737399611489089783\", \"price\":\"0.77\", \"size\":\"290\", \"side\":\"SELL\", \"hash\":\"5f7db0deed000119dd9e7cee7409e719a9f9f182\", \"best_bid\":\"0.67\", \"best_ask\":\"0.68\"}], \"timestamp\":\"1785208332998\", \"event_type\":\"price_change\"}","received_at":"2026-07-28T03:12:27.115619Z","schema_version":"clob-market-ws.price_change.v1","sequence":null,"server_hash":null,"server_timestamp":"1785208332998","session_id":"3e519d9098404c15b234d96025eb1a2b","source":"clob_market_ws"},"received_at":"2026-07-28T03:12:27.115619Z","record_id":"8149f879ab483116b41ee305ee56a160ab75e49a0951f18ba2be0473da3ce484","schema_fingerprint":"4aa3821a28b0b7c2400bc59aba4bcc0a76e971dadd19610d3ad38c768e124dc7","schema_version":"edge-lab-recorder.raw.v1","sequence":null,"source":"clob_market_ws"}
{"event_at":"2026-07-28T03:12:13.001000Z","event_fingerprint":"80093ad9ea46376158851f716ec32830277d6a64597d89a461653c99020a3a43","payload":{"connection_id":"a6b55582af5f430fb37ad02bf0922475","event_at":"2026-07-28T03:12:13.001000Z","event_type":"price_change","frame_hash":"be80f9a33e16b066acedb2a64aef043f800b2a6397652a845d88cf3fd925c866","frame_index":0,"kind":"data","monotonic_ns":310330151791208,"payload":{"event_type":"price_change","market":"0x779291bef19b6709f61e9764a954aafe9ffae488d50ae674aabdcb4f248006d5","price_changes":[{"asset_id":"8761897749749422724209054078244794145777693856614463256546737399611489089783","best_ask":"0.68","best_bid":"0.67","hash":"462f34d12228b43cde415bac18511b2174af1e90","price":"0.7","side":"SELL","size":"451.6"},{"asset_id":"14965588658799411272385430903075831224615961675357217884735713260981483529984","best_ask":"0.33","best_bid":"0.32","hash":"d3d09dc94a2dbbdaf0dd208c4ebdea55b820178d","price":"0.3","side":"BUY","size":"451.6"}],"timestamp":"1785208333001"},"payload_hash":"8bff55d004cfed6701ab592987b71f80ccf8874c4a541140c93c9974900e9dd8","raw_frame":"{\"market\":\"0x779291bef19b6709f61e9764a954aafe9ffae488d50ae674aabdcb4f248006d5\", \"price_changes\":[{\"asset_id\":\"8761897749749422724209054078244794145777693856614463256546737399611489089783\", \"price\":\"0.7\", \"size\":\"451.6\", \"side\":\"SELL\", \"hash\":\"462f34d12228b43cde415bac18511b2174af1e90\", \"best_bid\":\"0.67\", \"best_ask\":\"0.68\"}, {\"asset_id\":\"14965588658799411272385430903075831224615961675357217884735713260981483529984\", \"price\":\"0.3\", \"size\":\"451.6\", \"side\":\"BUY\", \"hash\":\"d3d09dc94a2dbbdaf0dd208c4ebdea55b820178d\", \"best_bid\":\"0.32\", \"best_ask\":\"0.33\"}], \"timestamp\":\"1785208333001\", \"event_type\":\"price_change\"}","received_at":"2026-07-28T03:12:27.117200Z","schema_version":"clob-market-ws.price_change.v1","sequence":null,"server_hash":null,"server_timestamp":"1785208333001","session_id":"3e519d9098404c15b234d96025eb1a2b","source":"clob_market_ws"},"received_at":"2026-07-28T03:12:27.117200Z","record_id":"6b0ca664103ec34ee30d302bb9db409353877872ac980c668fc8c6def25e27d5","schema_fingerprint":"4aa3821a28b0b7c2400bc59aba4bcc0a76e971dadd19610d3ad38c768e124dc7","schema_version":"edge-lab-recorder.raw.v1","sequence":null,"source":"clob_market_ws"}
{"event_at":"2026-07-28T03:12:13.013000Z","event_fingerprint":"955cd90e6fc9327948eec4f8aee5b29f2e3054a5ea0f2eb5afdd5ceb8c060a00","payload":{"connection_id":"a6b55582af5f430fb37ad02bf0922475","event_at":"2026-07-28T03:12:13.013000Z","event_type":"price_change","frame_hash":"3f2efc0af5b9af7990a70463de99a8821458cdc80ecdc6a8beee12c3308b9f48","frame_index":0,"kind":"data","monotonic_ns":310330153339000,"payload":{"event_type":"price_change","market":"0x779291bef19b6709f61e9764a954aafe9ffae488d50ae674aabdcb4f248006d5","price_changes":[{"asset_id":"8761897749749422724209054078244794145777693856614463256546737399611489089783","best_ask":"0.68","best_bid":"0.67","hash":"cef422d2465c0bfa2569bdc07c279880c0057ce4","price":"0.84","side":"SELL","size":"169"},{"asset_id":"14965588658799411272385430903075831224615961675357217884735713260981483529984","best_ask":"0.33","best_bid":"0.32","hash":"3dcaedf3dc4b3b5c69dde79fc6a4605f3349141e","price":"0.16","side":"BUY","size":"169"}],"timestamp":"1785208333013"},"payload_hash":"77b6ae63edf09b1cfa4d3255a8b64fed3eaec5dbee15f760d814e65ea1dc5426","raw_frame":"{\"market\":\"0x779291bef19b6709f61e9764a954aafe9ffae488d50ae674aabdcb4f248006d5\", \"price_changes\":[{\"asset_id\":\"8761897749749422724209054078244794145777693856614463256546737399611489089783\", \"price\":\"0.84\", \"size\":\"169\", \"side\":\"SELL\", \"hash\":\"cef422d2465c0bfa2569bdc07c279880c0057ce4\", \"best_bid\":\"0.67\", \"best_ask\":\"0.68\"}, {\"asset_id\":\"14965588658799411272385430903075831224615961675357217884735713260981483529984\", \"price\":\"0.16\", \"size\":\"169\", \"side\":\"BUY\", \"hash\":\"3dcaedf3dc4b3b5c69dde79fc6a4605f3349141e\", \"best_bid\":\"0.32\", \"best_ask\":\"0.33\"}], \"timestamp\":\"1785208333013\", \"event_type\":\"price_change\"}","received_at":"2026-07-28T03:12:27.118748Z","schema_version":"clob-market-ws.price_change.v1","sequence":null,"server_hash":null,"server_timestamp":"1785208333013","session_id":"3e519d9098404c15b234d96025eb1a2b","source":"clob_market_ws"},"received_at":"2026-07-28T03:12:27.118748Z","record_id":"e4662deb11961ed4ebf0608918980edc87fb0d42c09e7f6753ac937560acb40c","schema_fingerprint":"4aa3821a28b0b7c2400bc59aba4bcc0a76e971dadd19610d3ad38c768e124dc7","schema_version":"edge-lab-recorder.raw.v1","sequence":null,"source":"clob_market_ws"}
{"event_at":"2026-07-28T03:12:13.022000Z","event_fingerprint":"2a32afe65cb016dea407a70978fa6558d7e625d5822536d6bdb0e74e1969d40e","payload":{"connection_id":"a6b55582af5f430fb37ad02bf0922475","event_at":"2026-07-28T03:12:13.022000Z","event_type":"price_change","frame_hash":"b400e1a98093c35c76cf2ab94ebe393bd5197a0bed8facfdd7bbf1e327b294be","frame_index":0,"kind":"data","monotonic_ns":310330154885625,"payload":{"event_type":"price_change","market":"0x779291bef19b6709f61e9764a954aafe9ffae488d50ae674aabdcb4f248006d5","price_changes":[{"asset_id":"14965588658799411272385430903075831224615961675357217884735713260981483529984","best_ask":"0.33","best_bid":"0.32","hash":"9c42c76f6366f0d2b6a98280c01ab94d9bd3da8f","price":"0.01","side":"BUY","size":"5365.02"},{"asset_id":"8761897749749422724209054078244794145777693856614463256546737399611489089783","best_ask":"0.68","best_bid":"0.67","hash":"9f0df1148205dc83e36b08518725441eba3d2730","price":"0.99","side":"SELL","size":"5365.02"}],"timestamp":"1785208333022"},"payload_hash":"f26b0475b0c32765029d3197f23a7d476c361150a62d4645db321da39040117f","raw_frame":"{\"market\":\"0x779291bef19b6709f61e9764a954aafe9ffae488d50ae674aabdcb4f248006d5\", \"price_changes\":[{\"asset_id\":\"14965588658799411272385430903075831224615961675357217884735713260981483529984\", \"price\":\"0.01\", \"size\":\"5365.02\", \"side\":\"BUY\", \"hash\":\"9c42c76f6366f0d2b6a98280c01ab94d9bd3da8f\", \"best_bid\":\"0.32\", \"best_ask\":\"0.33\"}, {\"asset_id\":\"8761897749749422724209054078244794145777693856614463256546737399611489089783\", \"price\":\"0.99\", \"size\":\"5365.02\", \"side\":\"SELL\", \"hash\":\"9f0df1148205dc83e36b08518725441eba3d2730\", \"best_bid\":\"0.67\", \"best_ask\":\"0.68\"}], \"timestamp\":\"1785208333022\", \"event_type\":\"price_change\"}","received_at":"2026-07-28T03:12:27.120294Z","schema_version":"clob-market-ws.price_change.v1","sequence":null,"server_hash":null,"server_timestamp":"1785208333022","session_id":"3e519d9098404c15b234d96025eb1a2b","source":"clob_market_ws"},"received_at":"2026-07-28T03:12:27.120294Z","record_id":"76786beaef673e975e70260b01348d07abcd9af54452f303e2e15cb59dce08f1","schema_fingerprint":"4aa3821a28b0b7c2400bc59aba4bcc0a76e971dadd19610d3ad38c768e124dc7","schema_version":"edge-lab-recorder.raw.v1","sequence":null,"source":"clob_market_ws"}
{"event_at":"2026-07-28T03:12:13.023000Z","event_fingerprint":"169a8424b16094739e778a1891da7ca0537787707f4a04d5d91a12752030db94","payload":{"connection_id":"a6b55582af5f430fb37ad02bf0922475","event_at":"2026-07-28T03:12:13.023000Z","event_type":"price_change","frame_hash":"35d593c4324108d61ca4d5db936e7d8fa6f0df14fbdaab950ea3d99cc3eefc28","frame_index":0,"kind":"data","monotonic_ns":310330156408750,"payload":{"event_type":"price_change","market":"0x779291bef19b6709f61e9764a954aafe9ffae488d50ae674aabdcb4f248006d5","price_changes":[{"asset_id":"8761897749749422724209054078244794145777693856614463256546737399611489089783","best_ask":"0.68","best_bid":"0.67","hash":"1dea87080eb4728efb61fa4eb2ed69e07f550901","price":"0.01","side":"BUY","size":"5305.02"},{"asset_id":"14965588658799411272385430903075831224615961675357217884735713260981483529984","best_ask":"0.33","best_bid":"0.32","hash":"1c68c7c17a5a795d5a734078106956c0fb4673c7","price":"0.99","side":"SELL","size":"5305.02"}],"timestamp":"1785208333023"},"payload_hash":"15c94483e263eb07b1d9315a86a0a03e6c223f715082d13b4a70af29e73dd9e0","raw_frame":"{\"market\":\"0x779291bef19b6709f61e9764a954aafe9ffae488d50ae674aabdcb4f248006d5\", \"price_changes\":[{\"asset_id\":\"8761897749749422724209054078244794145777693856614463256546737399611489089783\", \"price\":\"0.01\", \"size\":\"5305.02\", \"side\":\"BUY\", \"hash\":\"1dea87080eb4728efb61fa4eb2ed69e07f550901\", \"best_bid\":\"0.67\", \"best_ask\":\"0.68\"}, {\"asset_id\":\"14965588658799411272385430903075831224615961675357217884735713260981483529984\", \"price\":\"0.99\", \"size\":\"5305.02\", \"side\":\"SELL\", \"hash\":\"1c68c7c17a5a795d5a734078106956c0fb4673c7\", \"best_bid\":\"0.32\", \"best_ask\":\"0.33\"}], \"timestamp\":\"1785208333023\", \"event_type\":\"price_change\"}","received_at":"2026-07-28T03:12:27.121818Z","schema_version":"clob-market-ws.price_change.v1","sequence":null,"server_hash":null,"server_timestamp":"1785208333023","session_id":"3e519d9098404c15b234d96025eb1a2b","source":"clob_market_ws"},"received_at":"2026-07-28T03:12:27.121818Z","record_id":"fb0b9b84b673e828e871bba52e28fc076fb39653e646d24af944e544029d8e2f","schema_fingerprint":"4aa3821a28b0b7c2400bc59aba4bcc0a76e971dadd19610d3ad38c768e124dc7","schema_version":"edge-lab-recorder.raw.v1","sequence":null,"source":"clob_market_ws"}
{"event_at":"2026-07-28T03:12:13.027000Z","event_fingerprint":"735d9ce6eca7562ce95ba7990a9c6127ec638c7b127f7e7854fe0e0ff75c1417","payload":{"connection_id":"a6b55582af5f430fb37ad02bf0922475","event_at":"2026-07-28T03:12:13.027000Z","event_type":"price_change","frame_hash":"f589734ce40a221e52613d2794401a05194be27c927266cf12b1850c2cfb1639","frame_index":0,"kind":"data","monotonic_ns":310330157900541,"payload":{"event_type":"price_change","market":"0x779291bef19b6709f61e9764a954aafe9ffae488d50ae674aabdcb4f248006d5","price_changes":[{"asset_id":"14965588658799411272385430903075831224615961675357217884735713260981483529984","best_ask":"0.33","best_bid":"0.32","hash":"1b4d0af84028d76420305c23e102fcca1127baa3","price":"0.01","side":"BUY","size":"5370.02"},{"asset_id":"8761897749749422724209054078244794145777693856614463256546737399611489089783","best_ask":"0.68","best_bid":"0.67","hash":"7d6d2609b7d29ab9c2ee6d6b816959d6f1fe0352","price":"0.99","side":"SELL","size":"5370.02"}],"timestamp":"1785208333027"},"payload_hash":"cf6bc640099774695bae2afeac6cdeca93b1a7bb595cf95691918ae080b746f3","raw_frame":"{\"market\":\"0x779291bef19b6709f61e9764a954aafe9ffae488d50ae674aabdcb4f248006d5\", \"price_changes\":[{\"asset_id\":\"14965588658799411272385430903075831224615961675357217884735713260981483529984\", \"price\":\"0.01\", \"size\":\"5370.02\", \"side\":\"BUY\", \"hash\":\"1b4d0af84028d76420305c23e102fcca1127baa3\", \"best_bid\":\"0.32\", \"best_ask\":\"0.33\"}, {\"asset_id\":\"8761897749749422724209054078244794145777693856614463256546737399611489089783\", \"price\":\"0.99\", \"size\":\"5370.02\", \"side\":\"SELL\", \"hash\":\"7d6d2609b7d29ab9c2ee6d6b816959d6f1fe0352\", \"best_bid\":\"0.67\", \"best_ask\":\"0.68\"}], \"timestamp\":\"1785208333027\", \"event_type\":\"price_change\"}","received_at":"2026-07-28T03:12:27.123310Z","schema_version":"clob-market-ws.price_change.v1","sequence":null,"server_hash":null,"server_timestamp":"1785208333027","session_id":"3e519d9098404c15b234d96025eb1a2b","source":"clob_market_ws"},"received_at":"2026-07-28T03:12:27.123310Z","record_id":"7f2ff787a276a7fe2034e8dc764ce3eed8350760399c1e702c051c176f9a57ed","schema_fingerprint":"4aa3821a28b0b7c2400bc59aba4bcc0a76e971dadd19610d3ad38c768e124dc7","schema_version":"edge-lab-recorder.raw.v1","sequence":null,"source":"clob_market_ws"}
{"event_at":"2026-07-28T03:12:13.034000Z","event_fingerprint":"ea8ffef7e097d2097d2b5ed8f44aedf0bce0eea6a5d54229ca5a8a64675455c5","payload":{"connection_id":"a6b55582af5f430fb37ad02bf0922475","event_at":"2026-07-28T03:12:13.034000Z","event_type":"price_change","frame_hash":"0348dd9adb8d694399dc4293cd675077ceb11aaf0e715fd2dad42db08122c093","frame_index":0,"kind":"data","monotonic_ns":310330159381083,"payload":{"event_type":"price_change","market":"0x779291bef19b6709f61e9764a954aafe9ffae488d50ae674aabdcb4f248006d5","price_changes":[{"asset_id":"14965588658799411272385430903075831224615961675357217884735713260981483529984","best_ask":"0.33","best_bid":"0.32","hash":"e95eb1f87506b74666c164637be4468efb99952f","price":"0.13","side":"BUY","size":"76"},{"asset_id":"8761897749749422724209054078244794145777693856614463256546737399611489089783","best_ask":"0.68","best_bid":"0.67","hash":"57ea75665b3032cb746b1f474538d2bbc5acead4","price":"0.87","side":"SELL","size":"76"}],"timestamp":"1785208333034"},"payload_hash":"d27f27d584ef8fe9a1487d2176358b8815621813ed175291d348c07ed35c9c54","raw_frame":"{\"market\":\"0x779291bef19b6709f61e9764a954aafe9ffae488d50ae674aabdcb4f248006d5\", \"price_changes\":[{\"asset_id\":\"14965588658799411272385430903075831224615961675357217884735713260981483529984\", \"price\":\"0.13\", \"size\":\"76\", \"side\":\"BUY\", \"hash\":\"e95eb1f87506b74666c164637be4468efb99952f\", \"best_bid\":\"0.32\", \"best_ask\":\"0.33\"}, {\"asset_id\":\"8761897749749422724209054078244794145777693856614463256546737399611489089783\", \"price\":\"0.87\", \"size\":\"76\", \"side\":\"SELL\", \"hash\":\"57ea75665b3032cb746b1f474538d2bbc5acead4\", \"best_bid\":\"0.67\", \"best_ask\":\"0.68\"}], \"timestamp\":\"1785208333034\", \"event_type\":\"price_change\"}","received_at":"2026-07-28T03:12:27.124790Z","schema_version":"clob-market-ws.price_change.v1","sequence":null,"server_hash":null,"server_timestamp":"1785208333034","session_id":"3e519d9098404c15b234d96025eb1a2b","source":"clob_market_ws"},"received_at":"2026-07-28T03:12:27.124790Z","record_id":"05d30ce6a7f7e43b116adbbff806d3ab822bfa331861270b127189c4f12a10eb","schema_fingerprint":"4aa3821a28b0b7c2400bc59aba4bcc0a76e971dadd19610d3ad38c768e124dc7","schema_version":"edge-lab-recorder.raw.v1","sequence":null,"source":"clob_market_ws"}
{"event_at":"2026-07-28T03:12:13.049000Z","event_fingerprint":"3976fb503777dc53b0125d126f5c0bedd159d2bf94cd4e5bb470a85917af7c78","payload":{"connection_id":"a6b55582af5f430fb37ad02bf0922475","event_at":"2026-07-28T03:12:13.049000Z","event_type":"price_change","frame_hash":"89038a992d6bc19c25547e7f4da76c1acdf5e0fb806d3236c442995909d9b6c5","frame_index":0,"kind":"data","monotonic_ns":310330160882208,"payload":{"event_type":"price_change","market":"0x779291bef19b6709f61e9764a954aafe9ffae488d50ae674aabdcb4f248006d5","price_changes":[{"asset_id":"8761897749749422724209054078244794145777693856614463256546737399611489089783","best_ask":"0.68","best_bid":"0.67","hash":"6aa0333652b9e6ab9311e02ca19dcebcc10ab59a","price":"0.84","side":"SELL","size":"175.22"},{"asset_id":"14965588658799411272385430903075831224615961675357217884735713260981483529984","best_ask":"0.33","best_bid":"0.32","hash":"a4aeaec752c36f14db83e09748bdde969b95bb5f","price":"0.16","side":"BUY","size":"175.22"}],"timestamp":"1785208333049"},"payload_hash":"e8ba78ec4aa7861b094f61b8ccb8ce44a0f2d888a42d303e185086b77cc08b5b","raw_frame":"{\"market\":\"0x779291bef19b6709f61e9764a954aafe9ffae488d50ae674aabdcb4f248006d5\", \"price_changes\":[{\"asset_id\":\"8761897749749422724209054078244794145777693856614463256546737399611489089783\", \"price\":\"0.84\", \"size\":\"175.22\", \"side\":\"SELL\", \"hash\":\"6aa0333652b9e6ab9311e02ca19dcebcc10ab59a\", \"best_bid\":\"0.67\", \"best_ask\":\"0.68\"}, {\"asset_id\":\"14965588658799411272385430903075831224615961675357217884735713260981483529984\", \"price\":\"0.16\", \"size\":\"175.22\", \"side\":\"BUY\", \"hash\":\"a4aeaec752c36f14db83e09748bdde969b95bb5f\", \"best_bid\":\"0.32\", \"best_ask\":\"0.33\"}], \"timestamp\":\"1785208333049\", \"event_type\":\"price_change\"}","received_at":"2026-07-28T03:12:27.126291Z","schema_version":"clob-market-ws.price_change.v1","sequence":null,"server_hash":null,"server_timestamp":"1785208333049","session_id":"3e519d9098404c15b234d96025eb1a2b","source":"clob_market_ws"},"received_at":"2026-07-28T03:12:27.126291Z","record_id":"66d0a18c90ef657e0502f40af41a2027b7e0e5ea83c9e8cc6df5493b5c6b70cf","schema_fingerprint":"4aa3821a28b0b7c2400bc59aba4bcc0a76e971dadd19610d3ad38c768e124dc7","schema_version":"edge-lab-recorder.raw.v1","sequence":null,"source":"clob_market_ws"}
{"event_at":"2026-07-28T03:12:13.051000Z","event_fingerprint":"881435fdf9dddb4fd07aefdd4fd685ae1fa8f0a8843996863ec822b2e776662a","payload":{"connection_id":"a6b55582af5f430fb37ad02bf0922475","event_at":"2026-07-28T03:12:13.051000Z","event_type":"price_change","frame_hash":"eee5cb3de5603013ca35b9ad9180431b4f0a48138deb51835bbf3df64246924b","frame_index":0,"kind":"data","monotonic_ns":310330162397666,"payload":{"event_type":"price_change","market":"0x779291bef19b6709f61e9764a954aafe9ffae488d50ae674aabdcb4f248006d5","price_changes":[{"asset_id":"14965588658799411272385430903075831224615961675357217884735713260981483529984","best_ask":"0.33","best_bid":"0.32","hash":"b575c7a92ec0e5bdf1280aaf461718c76364fc66","price":"0.01","side":"BUY","size":"5365.02"},{"asset_id":"8761897749749422724209054078244794145777693856614463256546737399611489089783","best_ask":"0.68","best_bid":"0.67","hash":"bc5c7f31719d1668731bdf4bb46016fd2c497b69","price":"0.99","side":"SELL","size":"5365.02"}],"timestamp":"1785208333051"},"payload_hash":"703515930393f57ccb1355eb13e191dd6386ae75bd28c85b1c0c8337aa625130","raw_frame":"{\"market\":\"0x779291bef19b6709f61e9764a954aafe9ffae488d50ae674aabdcb4f248006d5\", \"price_changes\":[{\"asset_id\":\"14965588658799411272385430903075831224615961675357217884735713260981483529984\", \"price\":\"0.01\", \"size\":\"5365.02\", \"side\":\"BUY\", \"hash\":\"b575c7a92ec0e5bdf1280aaf461718c76364fc66\", \"best_bid\":\"0.32\", \"best_ask\":\"0.33\"}, {\"asset_id\":\"8761897749749422724209054078244794145777693856614463256546737399611489089783\", \"price\":\"0.99\", \"size\":\"5365.02\", \"side\":\"SELL\", \"hash\":\"bc5c7f31719d1668731bdf4bb46016fd2c497b69\", \"best_bid\":\"0.67\", \"best_ask\":\"0.68\"}], \"timestamp\":\"1785208333051\", \"event_type\":\"price_change\"}","received_at":"2026-07-28T03:12:27.127807Z","schema_version":"clob-market-ws.price_change.v1","sequence":null,"server_hash":null,"server_timestamp":"1785208333051","session_id":"3e519d9098404c15b234d96025eb1a2b","source":"clob_market_ws"},"received_at":"2026-07-28T03:12:27.127807Z","record_id":"3b2e5e1f05e727da5340ef96dbe97447f93526907e78dbba4a5725742aaefa38","schema_fingerprint":"4aa3821a28b0b7c2400bc59aba4bcc0a76e971dadd19610d3ad38c768e124dc7","schema_version":"edge-lab-recorder.raw.v1","sequence":null,"source":"clob_market_ws"}
{"event_at":"2026-07-28T03:12:13.074000Z","event_fingerprint":"1367f8570c4b6ac6f455610cfcc20c9181f11caaf5a2f6f0589b6b83b57df143","payload":{"connection_id":"a6b55582af5f430fb37ad02bf0922475","event_at":"2026-07-28T03:12:13.074000Z","event_type":"price_change","frame_hash":"59924b3b4d370ebad6b717fdd8ada430260f3cb4764d2f162e812a937bfc68bc","frame_index":0,"kind":"data","monotonic_ns":310330163891666,"payload":{"event_type":"price_change","market":"0x779291bef19b6709f61e9764a954aafe9ffae488d50ae674aabdcb4f248006d5","price_changes":[{"asset_id":"8761897749749422724209054078244794145777693856614463256546737399611489089783","best_ask":"0.68","best_bid":"0.67","hash":"fa3999d77e0fc39e09f872937f54b326bfeb8790","price":"0.01","side":"BUY","size":"5300.02"},{"asset_id":"14965588658799411272385430903075831224615961675357217884735713260981483529984","best_ask":"0.33","best_bid":"0.32","hash":"a29509d064e91b263c61f43b8773f7e7ce3129f6","price":"0.99","side":"SELL","size":"5300.02"}],"timestamp":"1785208333074"},"payload_hash":"277522c5e83f1c020f39493a78f2bbfaec3d2e81a24c6012dff16c6b9575f7b4","raw_frame":"{\"market\":\"0x779291bef19b6709f61e9764a954aafe9ffae488d50ae674aabdcb4f248006d5\", \"price_changes\":[{\"asset_id\":\"8761897749749422724209054078244794145777693856614463256546737399611489089783\", \"price\":\"0.01\", \"size\":\"5300.02\", \"side\":\"BUY\", \"hash\":\"fa3999d77e0fc39e09f872937f54b326bfeb8790\", \"best_bid\":\"0.67\", \"best_ask\":\"0.68\"}, {\"asset_id\":\"14965588658799411272385430903075831224615961675357217884735713260981483529984\", \"price\":\"0.99\", \"size\":\"5300.02\", \"side\":\"SELL\", \"hash\":\"a29509d064e91b263c61f43b8773f7e7ce3129f6\", \"best_bid\":\"0.32\", \"best_ask\":\"0.33\"}], \"timestamp\":\"1785208333074\", \"event_type\":\"price_change\"}","received_at":"2026-07-28T03:12:27.129301Z","schema_version":"clob-market-ws.price_change.v1","sequence":null,"server_hash":null,"server_timestamp":"1785208333074","session_id":"3e519d9098404c15b234d96025eb1a2b","source":"clob_market_ws"},"received_at":"2026-07-28T03:12:27.129301Z","record_id":"6ce22709c431dbca1cdd3b0b8a6788e9d86e96ba7d34e6d7e2c614075e8d9bcc","schema_fingerprint":"4aa3821a28b0b7c2400bc59aba4bcc0a76e971dadd19610d3ad38c768e124dc7","schema_version":"edge-lab-recorder.raw.v1","sequence":null,"source":"clob_market_ws"}
{"event_at":"2026-07-28T03:12:13.101000Z","event_fingerprint":"858c19505552cb133d052534c6c0afeaf6a000cb8e929743c86a8457c4fc4097","payload":{"connection_id":"a6b55582af5f430fb37ad02bf0922475","event_at":"2026-07-28T03:12:13.101000Z","event_type":"price_change","frame_hash":"aaf10280b37cfa689344463c0a75e59e599f69bee299aa0e71af6ac6061634ca","frame_index":0,"kind":"data","monotonic_ns":310330165428750,"payload":{"event_type":"price_change","market":"0x779291bef19b6709f61e9764a954aafe9ffae488d50ae674aabdcb4f248006d5","price_changes":[{"asset_id":"14965588658799411272385430903075831224615961675357217884735713260981483529984","best_ask":"0.33","best_bid":"0.32","hash":"8773318581221c28924507d1ced2bf17e8a4de22","price":"0.01","side":"BUY","size":"5360.02"},{"asset_id":"8761897749749422724209054078244794145777693856614463256546737399611489089783","best_ask":"0.68","best_bid":"0.67","hash":"3c107e4b53495c8d68ac94a42816a3e7fc2951d7","price":"0.99","side":"SELL","size":"5360.02"}],"timestamp":"1785208333101"},"payload_hash":"f2571193a5e97218d5c0591e052c11be0d166ce8ea1b64af6ec42ab51ff98c0b","raw_frame":"{\"market\":\"0x779291bef19b6709f61e9764a954aafe9ffae488d50ae674aabdcb4f248006d5\", \"price_changes\":[{\"asset_id\":\"14965588658799411272385430903075831224615961675357217884735713260981483529984\", \"price\":\"0.01\", \"size\":\"5360.02\", \"side\":\"BUY\", \"hash\":\"8773318581221c28924507d1ced2bf17e8a4de22\", \"best_bid\":\"0.32\", \"best_ask\":\"0.33\"}, {\"asset_id\":\"8761897749749422724209054078244794145777693856614463256546737399611489089783\", \"price\":\"0.99\", \"size\":\"5360.02\", \"side\":\"SELL\", \"hash\":\"3c107e4b53495c8d68ac94a42816a3e7fc2951d7\", \"best_bid\":\"0.67\", \"best_ask\":\"0.68\"}], \"timestamp\":\"1785208333101\", \"event_type\":\"price_change\"}","received_at":"2026-07-28T03:12:27.130836Z","schema_version":"clob-market-ws.price_change.v1","sequence":null,"server_hash":null,"server_timestamp":"1785208333101","session_id":"3e519d9098404c15b234d96025eb1a2b","source":"clob_market_ws"},"received_at":"2026-07-28T03:12:27.130836Z","record_id":"370290cd87857cd5ac72548f20561b1fa43418ecd59d1f734936411b884888f8","schema_fingerprint":"4aa3821a28b0b7c2400bc59aba4bcc0a76e971dadd19610d3ad38c768e124dc7","schema_version":"edge-lab-recorder.raw.v1","sequence":null,"source":"clob_market_ws"}
{"event_at":"2026-07-28T03:12:13.119000Z","event_fingerprint":"8e247c8a8aed5c532475706952d0a9299d5bb36e2dbd226eba0222657c25a6c8","payload":{"connection_id":"a6b55582af5f430fb37ad02bf0922475","event_at":"2026-07-28T03:12:13.119000Z","event_type":"price_change","frame_hash":"8f66e8d6ab1630e635e8c71903124899a17f36962fb4290a886da373ec37694d","frame_index":0,"kind":"data","monotonic_ns":310330167002000,"payload":{"event_type":"price_change","market":"0x779291bef19b6709f61e9764a954aafe9ffae488d50ae674aabdcb4f248006d5","price_changes":[{"asset_id":"8761897749749422724209054078244794145777693856614463256546737399611489089783","best_ask":"0.68","best_bid":"0.67","hash":"cfacfb38e5d785280ec180e25281489bb41200dc","price":"0.01","side":"BUY","size":"5305.02"},{"asset_id":"14965588658799411272385430903075831224615961675357217884735713260981483529984","best_ask":"0.33","best_bid":"0.32","hash":"fcab536d3b91169f0266d0f29ecc3f8736e5bbae","price":"0.99","side":"SELL","size":"5305.02"}],"timestamp":"1785208333119"},"payload_hash":"d724dab0ebf859cb8fa98342cfef3c66bc9745092601168d8855f9f313b7b742","raw_frame":"{\"market\":\"0x779291bef19b6709f61e9764a954aafe9ffae488d50ae674aabdcb4f248006d5\", \"price_changes\":[{\"asset_id\":\"8761897749749422724209054078244794145777693856614463256546737399611489089783\", \"price\":\"0.01\", \"size\":\"5305.02\", \"side\":\"BUY\", \"hash\":\"cfacfb38e5d785280ec180e25281489bb41200dc\", \"best_bid\":\"0.67\", \"best_ask\":\"0.68\"}, {\"asset_id\":\"14965588658799411272385430903075831224615961675357217884735713260981483529984\", \"price\":\"0.99\", \"size\":\"5305.02\", \"side\":\"SELL\", \"hash\":\"fcab536d3b91169f0266d0f29ecc3f8736e5bbae\", \"best_bid\":\"0.32\", \"best_ask\":\"0.33\"}], \"timestamp\":\"1785208333119\", \"event_type\":\"price_change\"}","received_at":"2026-07-28T03:12:27.132411Z","schema_version":"clob-market-ws.price_change.v1","sequence":null,"server_hash":null,"server_timestamp":"1785208333119","session_id":"3e519d9098404c15b234d96025eb1a2b","source":"clob_market_ws"},"received_at":"2026-07-28T03:12:27.132411Z","record_id":"c58812d2ed50937639d9e9dbda6dcd4f6b6cad6ef80f6479ff1675bc19dca4af","schema_fingerprint":"4aa3821a28b0b7c2400bc59aba4bcc0a76e971dadd19610d3ad38c768e124dc7","schema_version":"edge-lab-recorder.raw.v1","sequence":null,"source":"clob_market_ws"}
{"event_at":"2026-07-28T03:12:13.138000Z","event_fingerprint":"be60c522c111164e5d9f3d25adbdd1cbf1d773b5021cb0a42f401d8365808ac3","payload":{"connection_id":"a6b55582af5f430fb37ad02bf0922475","event_at":"2026-07-28T03:12:13.138000Z","event_type":"price_change","frame_hash":"6ea11ddcf3049fde6423ffbac5cc21128a40b62e024ccb309aae855683c904d5","frame_index":0,"kind":"data","monotonic_ns":310330168495416,"payload":{"event_type":"price_change","market":"0x779291bef19b6709f61e9764a954aafe9ffae488d50ae674aabdcb4f248006d5","price_changes":[{"asset_id":"8761897749749422724209054078244794145777693856614463256546737399611489089783","best_ask":"0.68","best_bid":"0.67","hash":"684be7eb5a971f71fcfaef497e6a5ae9f8c42dbd","price":"0.01","side":"BUY","size":"5300.02"},{"asset_id":"14965588658799411272385430903075831224615961675357217884735713260981483529984","best_ask":"0.33","best_bid":"0.32","hash":"a7530e56d99129db0670277cc648c5af7a78f2da","price":"0.99","side":"SELL","size":"5300.02"}],"timestamp":"1785208333138"},"payload_hash":"c038461b2b5766efd138a7c38cc1c7d20b7acd4aaf7aeebf1dfd123a1375eb2b","raw_frame":"{\"market\":\"0x779291bef19b6709f61e9764a954aafe9ffae488d50ae674aabdcb4f248006d5\", \"price_changes\":[{\"asset_id\":\"8761897749749422724209054078244794145777693856614463256546737399611489089783\", \"price\":\"0.01\", \"size\":\"5300.02\", \"side\":\"BUY\", \"hash\":\"684be7eb5a971f71fcfaef497e6a5ae9f8c42dbd\", \"best_bid\":\"0.67\", \"best_ask\":\"0.68\"}, {\"asset_id\":\"14965588658799411272385430903075831224615961675357217884735713260981483529984\", \"price\":\"0.99\", \"size\":\"5300.02\", \"side\":\"SELL\", \"hash\":\"a7530e56d99129db0670277cc648c5af7a78f2da\", \"best_bid\":\"0.32\", \"best_ask\":\"0.33\"}], \"timestamp\":\"1785208333138\", \"event_type\":\"price_change\"}","received_at":"2026-07-28T03:12:27.133899Z","schema_version":"clob-market-ws.price_change.v1","sequence":null,"server_hash":null,"server_timestamp":"1785208333138","session_id":"3e519d9098404c15b234d96025eb1a2b","source":"clob_market_ws"},"received_at":"2026-07-28T03:12:27.133899Z","record_id":"6a318bfa2fa966db803c93e134cfa56f34a40d6f51f7ffaa53689392ea346441","schema_fingerprint":"4aa3821a28b0b7c2400bc59aba4bcc0a76e971dadd19610d3ad38c768e124dc7","schema_version":"edge-lab-recorder.raw.v1","sequence":null,"source":"clob_market_ws"}
{"event_at":"2026-07-28T03:12:13.153000Z","event_fingerprint":"2e625f22f054122ed71d36b441062eef14e23415fc99d7a530eaa6b620907797","payload":{"connection_id":"a6b55582af5f430fb37ad02bf0922475","event_at":"2026-07-28T03:12:13.153000Z","event_type":"price_change","frame_hash":"9cda9dffc34eee82d9db5391941c1c6b08d7b23932fe5feb681f3ac6a932b1ac","frame_index":0,"kind":"data","monotonic_ns":310330170007166,"payload":{"event_type":"price_change","market":"0x779291bef19b6709f61e9764a954aafe9ffae488d50ae674aabdcb4f248006d5","price_changes":[{"asset_id":"8761897749749422724209054078244794145777693856614463256546737399611489089783","best_ask":"0.68","best_bid":"0.67","hash":"3d24abc38c364f726d1de604690b95340773b07f","price":"0.7","side":"SELL","size":"439.6"},{"asset_id":"14965588658799411272385430903075831224615961675357217884735713260981483529984","best_ask":"0.33","best_bid":"0.32","hash":"f7fbc6865f6363fa9af69fd3283e341dc4aa3292","price":"0.3","side":"BUY","size":"439.6"}],"timestamp":"1785208333153"},"payload_hash":"74e1436db328be2bd41eda9567e9a277d772ac159086b3f2cc73bab38244bf5b","raw_frame":"{\"market\":\"0x779291bef19b6709f61e9764a954aafe9ffae488d50ae674aabdcb4f248006d5\", \"price_changes\":[{\"asset_id\":\"8761897749749422724209054078244794145777693856614463256546737399611489089783\", \"price\":\"0.7\", \"size\":\"439.6\", \"side\":\"SELL\", \"hash\":\"3d24abc38c364f726d1de604690b95340773b07f\", \"best_bid\":\"0.67\", \"best_ask\":\"0.68\"}, {\"asset_id\":\"14965588658799411272385430903075831224615961675357217884735713260981483529984\", \"price\":\"0.3\", \"size\":\"439.6\", \"side\":\"BUY\", \"hash\":\"f7fbc6865f6363fa9af69fd3283e341dc4aa3292\", \"best_bid\":\"0.32\", \"best_ask\":\"0.33\"}], \"timestamp\":\"1785208333153\", \"event_type\":\"price_change\"}","received_at":"2026-07-28T03:12:27.135416Z","schema_version":"clob-market-ws.price_change.v1","sequence":null,"server_hash":null,"server_timestamp":"1785208333153","session_id":"3e519d9098404c15b234d96025eb1a2b","source":"clob_market_ws"},"received_at":"2026-07-28T03:12:27.135416Z","record_id":"edd0197fa33879e54c5c5d9edb7c37b9e55b146d7ce68da1e6b5aee4432f3376","schema_fingerprint":"4aa3821a28b0b7c2400bc59aba4bcc0a76e971dadd19610d3ad38c768e124dc7","schema_version":"edge-lab-recorder.raw.v1","sequence":null,"source":"clob_market_ws"}
{"event_at":"2026-07-28T03:12:13.160000Z","event_fingerprint":"082c02c5b57c3535f30a0984dc42d27cfd9d17c01ffbbead9d418fcb6b2502a4","payload":{"connection_id":"a6b55582af5f430fb37ad02bf0922475","event_at":"2026-07-28T03:12:13.160000Z","event_type":"price_change","frame_hash":"b2dc5fbcc8b227d3148d9a017ca6933c3a53323d3aa423ae4e54b565b4602929","frame_index":0,"kind":"data","monotonic_ns":310330171512875,"payload":{"event_type":"price_change","market":"0x779291bef19b6709f61e9764a954aafe9ffae488d50ae674aabdcb4f248006d5","price_changes":[{"asset_id":"8761897749749422724209054078244794145777693856614463256546737399611489089783","best_ask":"0.68","best_bid":"0.67","hash":"8983b138f97dbafea21f2be8d269cbda9974e3c3","price":"0.04","side":"BUY","size":"515"},{"asset_id":"14965588658799411272385430903075831224615961675357217884735713260981483529984","best_ask":"0.33","best_bid":"0.32","hash":"82ae9ab7fc296947556a445708c0759c41466e80","price":"0.96","side":"SELL","size":"515"}],"timestamp":"1785208333160"},"payload_hash":"30583903e213df725906caac0baec67a3002f66c4ab9667bf1302a3207cff58c","raw_frame":"{\"market\":\"0x779291bef19b6709f61e9764a954aafe9ffae488d50ae674aabdcb4f248006d5\", \"price_changes\":[{\"asset_id\":\"8761897749749422724209054078244794145777693856614463256546737399611489089783\", \"price\":\"0.04\", \"size\":\"515\", \"side\":\"BUY\", \"hash\":\"8983b138f97dbafea21f2be8d269cbda9974e3c3\", \"best_bid\":\"0.67\", \"best_ask\":\"0.68\"}, {\"asset_id\":\"14965588658799411272385430903075831224615961675357217884735713260981483529984\", \"price\":\"0.96\", \"size\":\"515\", \"side\":\"SELL\", \"hash\":\"82ae9ab7fc296947556a445708c0759c41466e80\", \"best_bid\":\"0.32\", \"best_ask\":\"0.33\"}], \"timestamp\":\"1785208333160\", \"event_type\":\"price_change\"}","received_at":"2026-07-28T03:12:27.136922Z","schema_version":"clob-market-ws.price_change.v1","sequence":null,"server_hash":null,"server_timestamp":"1785208333160","session_id":"3e519d9098404c15b234d96025eb1a2b","source":"clob_market_ws"},"received_at":"2026-07-28T03:12:27.136922Z","record_id":"01682050a6c68a7fb9e30090a56096613222d008a8a935c1074c3684c585b6b7","schema_fingerprint":"4aa3821a28b0b7c2400bc59aba4bcc0a76e971dadd19610d3ad38c768e124dc7","schema_version":"edge-lab-recorder.raw.v1","sequence":null,"source":"clob_market_ws"}
{"event_at":"2026-07-28T03:12:13.175000Z","event_fingerprint":"28cc245eb976724e92a61cd209c53324a3cca9ee950ea6ac1c03a514903f25ea","payload":{"connection_id":"a6b55582af5f430fb37ad02bf0922475","event_at":"2026-07-28T03:12:13.175000Z","event_type":"price_change","frame_hash":"8370889b85f946ce50a32f2dcccc75520549cbe3ccaa51077ba0d3f783e9c3c7","frame_index":0,"kind":"data","monotonic_ns":310330173031041,"payload":{"event_type":"price_change","market":"0x779291bef19b6709f61e9764a954aafe9ffae488d50ae674aabdcb4f248006d5","price_changes":[{"asset_id":"8761897749749422724209054078244794145777693856614463256546737399611489089783","best_ask":"0.68","best_bid":"0.67","hash":"caf7468e673f2f30e2a33da1aef35b058c32ca11","price":"0.62","side":"BUY","size":"42"},{"asset_id":"14965588658799411272385430903075831224615961675357217884735713260981483529984","best_ask":"0.33","best_bid":"0.32","hash":"05c49bc37919515ae013529e478700d924108b6c","price":"0.38","side":"SELL","size":"42"}],"timestamp":"1785208333175"},"payload_hash":"1ecdd6cb60d1ba312669ef7fec580f60115b7bed7ef7fefd34d12c75a79e2bb9","raw_frame":"{\"market\":\"0x779291bef19b6709f61e9764a954aafe9ffae488d50ae674aabdcb4f248006d5\", \"price_changes\":[{\"asset_id\":\"8761897749749422724209054078244794145777693856614463256546737399611489089783\", \"price\":\"0.62\", \"size\":\"42\", \"side\":\"BUY\", \"hash\":\"caf7468e673f2f30e2a33da1aef35b058c32ca11\", \"best_bid\":\"0.67\", \"best_ask\":\"0.68\"}, {\"asset_id\":\"14965588658799411272385430903075831224615961675357217884735713260981483529984\", \"price\":\"0.38\", \"size\":\"42\", \"side\":\"SELL\", \"hash\":\"05c49bc37919515ae013529e478700d924108b6c\", \"best_bid\":\"0.32\", \"best_ask\":\"0.33\"}], \"timestamp\":\"1785208333175\", \"event_type\":\"price_change\"}","received_at":"2026-07-28T03:12:27.138440Z","schema_version":"clob-market-ws.price_change.v1","sequence":null,"server_hash":null,"server_timestamp":"1785208333175","session_id":"3e519d9098404c15b234d96025eb1a2b","source":"clob_market_ws"},"received_at":"2026-07-28T03:12:27.138440Z","record_id":"32c952b0e013e7e59facd34893c2421f91bfeb9dd13b865d958fdedc679ce608","schema_fingerprint":"4aa3821a28b0b7c2400bc59aba4bcc0a76e971dadd19610d3ad38c768e124dc7","schema_version":"edge-lab-recorder.raw.v1","sequence":null,"source":"clob_market_ws"}
{"event_at":"2026-07-28T03:12:13.205000Z","event_fingerprint":"3991c54f7af628111747b9371fec92cb7a7d3450f5332af84650d7e8dc2347fb","payload":{"connection_id":"a6b55582af5f430fb37ad02bf0922475","event_at":"2026-07-28T03:12:13.205000Z","event_type":"price_change","frame_hash":"578723d5c5a48e815ba8f33bb1949d439e85b18b1a6ae83529b5976b58524c02","frame_index":0,"kind":"data","monotonic_ns":310330174575333,"payload":{"event_type":"price_change","market":"0x779291bef19b6709f61e9764a954aafe9ffae488d50ae674aabdcb4f248006d5","price_changes":[{"asset_id":"8761897749749422724209054078244794145777693856614463256546737399611489089783","best_ask":"0.68","best_bid":"0.67","hash":"518ac578843f4bf79e5c41fbd255c92ffbe37ee0","price":"0.67","side":"BUY","size":"62.6"},{"asset_id":"14965588658799411272385430903075831224615961675357217884735713260981483529984","best_ask":"0.33","best_bid":"0.32","hash":"250b89d64d74444652e169992116243f4f29d54c","price":"0.33","side":"SELL","size":"62.6"}],"timestamp":"1785208333205"},"payload_hash":"8bfa00a8e6df3dc6b9b158e1f775a3ad53aa753f7f9139272675c4e04ee98806","raw_frame":"{\"market\":\"0x779291bef19b6709f61e9764a954aafe9ffae488d50ae674aabdcb4f248006d5\", \"price_changes\":[{\"asset_id\":\"8761897749749422724209054078244794145777693856614463256546737399611489089783\", \"price\":\"0.67\", \"size\":\"62.6\", \"side\":\"BUY\", \"hash\":\"518ac578843f4bf79e5c41fbd255c92ffbe37ee0\", \"best_bid\":\"0.67\", \"best_ask\":\"0.68\"}, {\"asset_id\":\"14965588658799411272385430903075831224615961675357217884735713260981483529984\", \"price\":\"0.33\", \"size\":\"62.6\", \"side\":\"SELL\", \"hash\":\"250b89d64d74444652e169992116243f4f29d54c\", \"best_bid\":\"0.32\", \"best_ask\":\"0.33\"}], \"timestamp\":\"1785208333205\", \"event_type\":\"price_change\"}","received_at":"2026-07-28T03:12:27.139981Z","schema_version":"clob-market-ws.price_change.v1","sequence":null,"server_hash":null,"server_timestamp":"1785208333205","session_id":"3e519d9098404c15b234d96025eb1a2b","source":"clob_market_ws"},"received_at":"2026-07-28T03:12:27.139981Z","record_id":"51925e8023cdb271a61c4aecfc3ec483fad4c2b055034501fc4f12babd395985","schema_fingerprint":"4aa3821a28b0b7c2400bc59aba4bcc0a76e971dadd19610d3ad38c768e124dc7","schema_version":"edge-lab-recorder.raw.v1","sequence":null,"source":"clob_market_ws"}
{"event_at":"2026-07-28T03:12:13.231000Z","event_fingerprint":"265ee0df8c93d1ed68e9eded645a8a29348f71cfa21e1f6c37db42e4c7b6e351","payload":{"connection_id":"a6b55582af5f430fb37ad02bf0922475","event_at":"2026-07-28T03:12:13.231000Z","event_type":"price_change","frame_hash":"74ce86b60e2bf9dd11e23b62b2dc322e80a571c32e7442edf0408e17b825bf84","frame_index":0,"kind":"data","monotonic_ns":310330176219750,"payload":{"event_type":"price_change","market":"0x779291bef19b6709f61e9764a954aafe9ffae488d50ae674aabdcb4f248006d5","price_changes":[{"asset_id":"8761897749749422724209054078244794145777693856614463256546737399611489089783","best_ask":"0.68","best_bid":"0.67","hash":"548f7dc45f58973aae8fdac7a7ee52c9caf196c0","price":"0.04","side":"BUY","size":"510"},{"asset_id":"14965588658799411272385430903075831224615961675357217884735713260981483529984","best_ask":"0.33","best_bid":"0.32","hash":"c4ae2f578b4d27c71171c94f1dc6f1128a5f5399","price":"0.96","side":"SELL","size":"510"}],"timestamp":"1785208333231"},"payload_hash":"154a0f0d931c4e40b5c6ea3058cfc254f77571bcab0c35d562e9110fe288e534","raw_frame":"{\"market\":\"0x779291bef19b6709f61e9764a954aafe9ffae488d50ae674aabdcb4f248006d5\", \"price_changes\":[{\"asset_id\":\"8761897749749422724209054078244794145777693856614463256546737399611489089783\", \"price\":\"0.04\", \"size\":\"510\", \"side\":\"BUY\", \"hash\":\"548f7dc45f58973aae8fdac7a7ee52c9caf196c0\", \"best_bid\":\"0.67\", \"best_ask\":\"0.68\"}, {\"asset_id\":\"14965588658799411272385430903075831224615961675357217884735713260981483529984\", \"price\":\"0.96\", \"size\":\"510\", \"side\":\"SELL\", \"hash\":\"c4ae2f578b4d27c71171c94f1dc6f1128a5f5399\", \"best_bid\":\"0.32\", \"best_ask\":\"0.33\"}], \"timestamp\":\"1785208333231\", \"event_type\":\"price_change\"}","received_at":"2026-07-28T03:12:27.141627Z","schema_version":"clob-market-ws.price_change.v1","sequence":null,"server_hash":null,"server_timestamp":"1785208333231","session_id":"3e519d9098404c15b234d96025eb1a2b","source":"clob_market_ws"},"received_at":"2026-07-28T03:12:27.141627Z","record_id":"ba2dc5ec858b797012b19f72c8f33b87156a95cf811486a72a87f5ca353fa32a","schema_fingerprint":"4aa3821a28b0b7c2400bc59aba4bcc0a76e971dadd19610d3ad38c768e124dc7","schema_version":"edge-lab-recorder.raw.v1","sequence":null,"source":"clob_market_ws"}
{"event_at":"2026-07-28T03:12:13.266000Z","event_fingerprint":"709aac71ac17008001762d6d0d6e60c99353e7bb5f34cd0d414c1732f09c80cf","payload":{"connection_id":"a6b55582af5f430fb37ad02bf0922475","event_at":"2026-07-28T03:12:13.266000Z","event_type":"price_change","frame_hash":"786102e9a4188ea89f48eb2616c5b48bbfbe4e886cb4bed777ae4b3cfdf9d5fd","frame_index":0,"kind":"data","monotonic_ns":310330177748500,"payload":{"event_type":"price_change","market":"0x779291bef19b6709f61e9764a954aafe9ffae488d50ae674aabdcb4f248006d5","price_changes":[{"asset_id":"8761897749749422724209054078244794145777693856614463256546737399611489089783","best_ask":"0.68","best_bid":"0.67","hash":"ef172ea35b1c3b850aa2913b6c53d443c84189e8","price":"0.68","side":"SELL","size":"12"},{"asset_id":"14965588658799411272385430903075831224615961675357217884735713260981483529984","best_ask":"0.33","best_bid":"0.32","hash":"216efbc29830fb1af1a4ef0072fde6b0cbcc3bba","price":"0.32","side":"BUY","size":"12"}],"timestamp":"1785208333266"},"payload_hash":"42778198c36a23d91b42571a85b6d093300763acb8265567c33fef5025d98485","raw_frame":"{\"market\":\"0x779291bef19b6709f61e9764a954aafe9ffae488d50ae674aabdcb4f248006d5\", \"price_changes\":[{\"asset_id\":\"8761897749749422724209054078244794145777693856614463256546737399611489089783\", \"price\":\"0.68\", \"size\":\"12\", \"side\":\"SELL\", \"hash\":\"ef172ea35b1c3b850aa2913b6c53d443c84189e8\", \"best_bid\":\"0.67\", \"best_ask\":\"0.68\"}, {\"asset_id\":\"14965588658799411272385430903075831224615961675357217884735713260981483529984\", \"price\":\"0.32\", \"size\":\"12\", \"side\":\"BUY\", \"hash\":\"216efbc29830fb1af1a4ef0072fde6b0cbcc3bba\", \"best_bid\":\"0.32\", \"best_ask\":\"0.33\"}], \"timestamp\":\"1785208333266\", \"event_type\":\"price_change\"}","received_at":"2026-07-28T03:12:27.143156Z","schema_version":"clob-market-ws.price_change.v1","sequence":null,"server_hash":null,"server_timestamp":"1785208333266","session_id":"3e519d9098404c15b234d96025eb1a2b","source":"clob_market_ws"},"received_at":"2026-07-28T03:12:27.143156Z","record_id":"58a3ee6953582853aca9d7bd35605218fe10ad5b9d1ea1fda91456882586931e","schema_fingerprint":"4aa3821a28b0b7c2400bc59aba4bcc0a76e971dadd19610d3ad38c768e124dc7","schema_version":"edge-lab-recorder.raw.v1","sequence":null,"source":"clob_market_ws"}
{"event_at":"2026-07-28T03:12:13.279000Z","event_fingerprint":"53d615f34d9256cc2799f32678e6394d575d253523b97726cddfd35ca210bd10","payload":{"connection_id":"a6b55582af5f430fb37ad02bf0922475","event_at":"2026-07-28T03:12:13.279000Z","event_type":"price_change","frame_hash":"d032456af5cb8faa7aec55e69834cde2c5c2a1481d20d2ec74dab2461f7d5a9b","frame_index":0,"kind":"data","monotonic_ns":310330179343500,"payload":{"event_type":"price_change","market":"0x779291bef19b6709f61e9764a954aafe9ffae488d50ae674aabdcb4f248006d5","price_changes":[{"asset_id":"14965588658799411272385430903075831224615961675357217884735713260981483529984","best_ask":"0.33","best_bid":"0.32","hash":"f2308134ecac8c06eb60cae1e9f48b1692456963","price":"0.29","side":"BUY","size":"76.15"},{"asset_id":"8761897749749422724209054078244794145777693856614463256546737399611489089783","best_ask":"0.68","best_bid":"0.67","hash":"34887b1b1f218821dd2c0f4a41564e4423f4622b","price":"0.71","side":"SELL","size":"76.15"}],"timestamp":"1785208333279"},"payload_hash":"38976aa505108b0925162a39d87d85c7fddf7bcd1857277db4e146aeed51de72","raw_frame":"{\"market\":\"0x779291bef19b6709f61e9764a954aafe9ffae488d50ae674aabdcb4f248006d5\", \"price_changes\":[{\"asset_id\":\"14965588658799411272385430903075831224615961675357217884735713260981483529984\", \"price\":\"0.29\", \"size\":\"76.15\", \"side\":\"BUY\", \"hash\":\"f2308134ecac8c06eb60cae1e9f48b1692456963\", \"best_bid\":\"0.32\", \"best_ask\":\"0.33\"}, {\"asset_id\":\"8761897749749422724209054078244794145777693856614463256546737399611489089783\", \"price\":\"0.71\", \"size\":\"76.15\", \"side\":\"SELL\", \"hash\":\"34887b1b1f218821dd2c0f4a41564e4423f4622b\", \"best_bid\":\"0.67\", \"best_ask\":\"0.68\"}], \"timestamp\":\"1785208333279\", \"event_type\":\"price_change\"}","received_at":"2026-07-28T03:12:27.144752Z","schema_version":"clob-market-ws.price_change.v1","sequence":null,"server_hash":null,"server_timestamp":"1785208333279","session_id":"3e519d9098404c15b234d96025eb1a2b","source":"clob_market_ws"},"received_at":"2026-07-28T03:12:27.144752Z","record_id":"e6d0861d176aed741bb118210b4d1b65263309606a6fc3c1bd860f5324c34e7f","schema_fingerprint":"4aa3821a28b0b7c2400bc59aba4bcc0a76e971dadd19610d3ad38c768e124dc7","schema_version":"edge-lab-recorder.raw.v1","sequence":null,"source":"clob_market_ws"}
{"event_at":"2026-07-28T03:12:13.282000Z","event_fingerprint":"191cdb0ac78f3516c20fcff2dafba398f7741ea64d7a08609c2306bcebee7eaf","payload":{"connection_id":"a6b55582af5f430fb37ad02bf0922475","event_at":"2026-07-28T03:12:13.282000Z","event_type":"price_change","frame_hash":"4d02ac3a28dbce6bfd6ddd2cfe71cc61a1d126d8771892210d03eac8e2af259c","frame_index":0,"kind":"data","monotonic_ns":310330180835875,"payload":{"event_type":"price_change","market":"0x779291bef19b6709f61e9764a954aafe9ffae488d50ae674aabdcb4f248006d5","price_changes":[{"asset_id":"14965588658799411272385430903075831224615961675357217884735713260981483529984","best_ask":"0.33","best_bid":"0.32","hash":"9b6e56b3760e0d4d13802a93b4196c46b421502d","price":"0.3","side":"BUY","size":"428.6"},{"asset_id":"8761897749749422724209054078244794145777693856614463256546737399611489089783","best_ask":"0.68","best_bid":"0.67","hash":"fa20582906441d9e7d596ab028957a8ea5580fdb","price":"0.7","side":"SELL","size":"428.6"}],"timestamp":"1785208333282"},"payload_hash":"3dfaf76674ad043f56cd64d9236f07cb0aa0e779be7742635529c39b53f09f78","raw_frame":"{\"market\":\"0x779291bef19b6709f61e9764a954aafe9ffae488d50ae674aabdcb4f248006d5\", \"price_changes\":[{\"asset_id\":\"14965588658799411272385430903075831224615961675357217884735713260981483529984\", \"price\":\"0.3\", \"size\":\"428.6\", \"side\":\"BUY\", \"hash\":\"9b6e56b3760e0d4d13802a93b4196c46b421502d\", \"best_bid\":\"0.32\", \"best_ask\":\"0.33\"}, {\"asset_id\":\"8761897749749422724209054078244794145777693856614463256546737399611489089783\", \"price\":\"0.7\", \"size\":\"428.6\", \"side\":\"SELL\", \"hash\":\"fa20582906441d9e7d596ab028957a8ea5580fdb\", \"best_bid\":\"0.67\", \"best_ask\":\"0.68\"}], \"timestamp\":\"1785208333282\", \"event_type\":\"price_change\"}","received_at":"2026-07-28T03:12:27.146245Z","schema_version":"clob-market-ws.price_change.v1","sequence":null,"server_hash":null,"server_timestamp":"1785208333282","session_id":"3e519d9098404c15b234d96025eb1a2b","source":"clob_market_ws"},"received_at":"2026-07-28T03:12:27.146245Z","record_id":"66716141f302132b08855fa9edb6742a55df3da1b589453acffa7bb73afc3bb3","schema_fingerprint":"4aa3821a28b0b7c2400bc59aba4bcc0a76e971dadd19610d3ad38c768e124dc7","schema_version":"edge-lab-recorder.raw.v1","sequence":null,"source":"clob_market_ws"}
{"event_at":"2026-07-28T03:12:13.283000Z","event_fingerprint":"394a161f9427ffef9973a57267f81cbde29fef992b0f08cbe275c124a48c22a0","payload":{"connection_id":"a6b55582af5f430fb37ad02bf0922475","event_at":"2026-07-28T03:12:13.283000Z","event_type":"price_change","frame_hash":"f60ef551d3ffaecae5e21099fd930e202d74efeb8b05cc35f4f9c25088b0199c","frame_index":0,"kind":"data","monotonic_ns":310330182337750,"payload":{"event_type":"price_change","market":"0x779291bef19b6709f61e9764a954aafe9ffae488d50ae674aabdcb4f248006d5","price_changes":[{"asset_id":"14965588658799411272385430903075831224615961675357217884735713260981483529984","best_ask":"0.33","best_bid":"0.32","hash":"12c77cb52ccfc5ad132789eb05db04c392f3ba5f","price":"0.32","side":"BUY","size":"22"},{"asset_id":"8761897749749422724209054078244794145777693856614463256546737399611489089783","best_ask":"0.68","best_bid":"0.67","hash":"e048ceaf8592fc3d2b5791a9dc6a52dcf93f54f2","price":"0.68","side":"SELL","size":"22"}],"timestamp":"1785208333283"},"payload_hash":"6edf6ba0d4db18892e6acb2fb1d76fb049acfab79ddf393f73745cd0627cb023","raw_frame":"{\"market\":\"0x779291bef19b6709f61e9764a954aafe9ffae488d50ae674aabdcb4f248006d5\", \"price_changes\":[{\"asset_id\":\"14965588658799411272385430903075831224615961675357217884735713260981483529984\", \"price\":\"0.32\", \"size\":\"22\", \"side\":\"BUY\", \"hash\":\"12c77cb52ccfc5ad132789eb05db04c392f3ba5f\", \"best_bid\":\"0.32\", \"best_ask\":\"0.33\"}, {\"asset_id\":\"8761897749749422724209054078244794145777693856614463256546737399611489089783\", \"price\":\"0.68\", \"size\":\"22\", \"side\":\"SELL\", \"hash\":\"e048ceaf8592fc3d2b5791a9dc6a52dcf93f54f2\", \"best_bid\":\"0.67\", \"best_ask\":\"0.68\"}], \"timestamp\":\"1785208333283\", \"event_type\":\"price_change\"}","received_at":"2026-07-28T03:12:27.147747Z","schema_version":"clob-market-ws.price_change.v1","sequence":null,"server_hash":null,"server_timestamp":"1785208333283","session_id":"3e519d9098404c15b234d96025eb1a2b","source":"clob_market_ws"},"received_at":"2026-07-28T03:12:27.147747Z","record_id":"3fbf1009eae3e8942305491ca8d35abf478a538a6a3753857e84879a937050d3","schema_fingerprint":"4aa3821a28b0b7c2400bc59aba4bcc0a76e971dadd19610d3ad38c768e124dc7","schema_version":"edge-lab-recorder.raw.v1","sequence":null,"source":"clob_market_ws"}
{"event_at":"2026-07-28T03:12:13.283000Z","event_fingerprint":"c82cb0c6e8fd9dcf8a608cfe51380a5e853cd9f52b7688fc353c46e69b98fb5d","payload":{"connection_id":"a6b55582af5f430fb37ad02bf0922475","event_at":"2026-07-28T03:12:13.283000Z","event_type":"price_change","frame_hash":"29c103cc40d34be99356e87a9181e08d3851e41dbb1f6371e86b8459ff37354a","frame_index":0,"kind":"data","monotonic_ns":310330183822833,"payload":{"event_type":"price_change","market":"0x779291bef19b6709f61e9764a954aafe9ffae488d50ae674aabdcb4f248006d5","price_changes":[{"asset_id":"8761897749749422724209054078244794145777693856614463256546737399611489089783","best_ask":"0.68","best_bid":"0.67","hash":"9159408a70169d1cc576af35b7c711b1a3d1e598","price":"0.7","side":"SELL","size":"441.6"},{"asset_id":"14965588658799411272385430903075831224615961675357217884735713260981483529984","best_ask":"0.33","best_bid":"0.32","hash":"223bf90b05ec3c4c7dcdbc48f1de305ba0377adf","price":"0.3","side":"BUY","size":"441.6"}],"timestamp":"1785208333283"},"payload_hash":"28499efa748765942d5ea8907ee57f65eb27b23c6e0fd737dc09e320c37e3047","raw_frame":"{\"market\":\"0x779291bef19b6709f61e9764a954aafe9ffae488d50ae674aabdcb4f248006d5\", \"price_changes\":[{\"asset_id\":\"8761897749749422724209054078244794145777693856614463256546737399611489089783\", \"price\":\"0.7\", \"size\":\"441.6\", \"side\":\"SELL\", \"hash\":\"9159408a70169d1cc576af35b7c711b1a3d1e598\", \"best_bid\":\"0.67\", \"best_ask\":\"0.68\"}, {\"asset_id\":\"14965588658799411272385430903075831224615961675357217884735713260981483529984\", \"price\":\"0.3\", \"size\":\"441.6\", \"side\":\"BUY\", \"hash\":\"223bf90b05ec3c4c7dcdbc48f1de305ba0377adf\", \"best_bid\":\"0.32\", \"best_ask\":\"0.33\"}], \"timestamp\":\"1785208333283\", \"event_type\":\"price_change\"}","received_at":"2026-07-28T03:12:27.149232Z","schema_version":"clob-market-ws.price_change.v1","sequence":null,"server_hash":null,"server_timestamp":"1785208333283","session_id":"3e519d9098404c15b234d96025eb1a2b","source":"clob_market_ws"},"received_at":"2026-07-28T03:12:27.149232Z","record_id":"34b9be1d0c651d94d3e6b4ad46ccc820cc899758cc1fc8048bb4d6686424f012","schema_fingerprint":"4aa3821a28b0b7c2400bc59aba4bcc0a76e971dadd19610d3ad38c768e124dc7","schema_version":"edge-lab-recorder.raw.v1","sequence":null,"source":"clob_market_ws"}
{"event_at":"2026-07-28T03:12:13.284000Z","event_fingerprint":"9eb8f0c0f1de6dad8dd40228cb69b1a5154e7b985637b0d770b8a1f3d8569e41","payload":{"connection_id":"a6b55582af5f430fb37ad02bf0922475","event_at":"2026-07-28T03:12:13.284000Z","event_type":"price_change","frame_hash":"1f5fb76efd088127e47b8f427f0b080b209ccb68c2d761b89376a556136eca0c","frame_index":0,"kind":"data","monotonic_ns":310330185348458,"payload":{"event_type":"price_change","market":"0x779291bef19b6709f61e9764a954aafe9ffae488d50ae674aabdcb4f248006d5","price_changes":[{"asset_id":"14965588658799411272385430903075831224615961675357217884735713260981483529984","best_ask":"0.33","best_bid":"0.32","hash":"b00144df3df6161449275a54f63f60b38fb7c1b7","price":"0.3","side":"BUY","size":"461.6"},{"asset_id":"8761897749749422724209054078244794145777693856614463256546737399611489089783","best_ask":"0.68","best_bid":"0.67","hash":"1978d042902b9424050f09e26d21dbabe9c65ea1","price":"0.7","side":"SELL","size":"461.6"}],"timestamp":"1785208333284"},"payload_hash":"3fd5ba06c5995516460f018df36ec5f195c571b9621aaba84b9aa58b04a7324f","raw_frame":"{\"market\":\"0x779291bef19b6709f61e9764a954aafe9ffae488d50ae674aabdcb4f248006d5\", \"price_changes\":[{\"asset_id\":\"14965588658799411272385430903075831224615961675357217884735713260981483529984\", \"price\":\"0.3\", \"size\":\"461.6\", \"side\":\"BUY\", \"hash\":\"b00144df3df6161449275a54f63f60b38fb7c1b7\", \"best_bid\":\"0.32\", \"best_ask\":\"0.33\"}, {\"asset_id\":\"8761897749749422724209054078244794145777693856614463256546737399611489089783\", \"price\":\"0.7\", \"size\":\"461.6\", \"side\":\"SELL\", \"hash\":\"1978d042902b9424050f09e26d21dbabe9c65ea1\", \"best_bid\":\"0.67\", \"best_ask\":\"0.68\"}], \"timestamp\":\"1785208333284\", \"event_type\":\"price_change\"}","received_at":"2026-07-28T03:12:27.150757Z","schema_version":"clob-market-ws.price_change.v1","sequence":null,"server_hash":null,"server_timestamp":"1785208333284","session_id":"3e519d9098404c15b234d96025eb1a2b","source":"clob_market_ws"},"received_at":"2026-07-28T03:12:27.150757Z","record_id":"cf2fb6bb297b6cc1ddbb21c15049421ff50620bba69074c9c8f5ed6e6bafe809","schema_fingerprint":"4aa3821a28b0b7c2400bc59aba4bcc0a76e971dadd19610d3ad38c768e124dc7","schema_version":"edge-lab-recorder.raw.v1","sequence":null,"source":"clob_market_ws"}
{"event_at":"2026-07-28T03:12:13.287000Z","event_fingerprint":"4ea3d48766c8d3380f09d28a29891e8c794684377cae27bca9ba02737f9babe0","payload":{"connection_id":"a6b55582af5f430fb37ad02bf0922475","event_at":"2026-07-28T03:12:13.287000Z","event_type":"price_change","frame_hash":"f10f8a01efa15f3109046b3a8ad92f9d4ce5bc6696f59fe81977716a6dcc754a","frame_index":0,"kind":"data","monotonic_ns":310330187033833,"payload":{"event_type":"price_change","market":"0x779291bef19b6709f61e9764a954aafe9ffae488d50ae674aabdcb4f248006d5","price_changes":[{"asset_id":"8761897749749422724209054078244794145777693856614463256546737399611489089783","best_ask":"0.68","best_bid":"0.67","hash":"60776ceb65672c7353695095fd02049d0ba56eef","price":"0.67","side":"BUY","size":"47.6"},{"asset_id":"14965588658799411272385430903075831224615961675357217884735713260981483529984","best_ask":"0.33","best_bid":"0.32","hash":"727f2525c1d3742628e77cc94afae89db915748d","price":"0.33","side":"SELL","size":"47.6"}],"timestamp":"1785208333287"},"payload_hash":"ba302a1c7a256e35c098f6a382cbcf0c6b2760558770c8694e3bd65fe1c5fbfd","raw_frame":"{\"market\":\"0x779291bef19b6709f61e9764a954aafe9ffae488d50ae674aabdcb4f248006d5\", \"price_changes\":[{\"asset_id\":\"8761897749749422724209054078244794145777693856614463256546737399611489089783\", \"price\":\"0.67\", \"size\":\"47.6\", \"side\":\"BUY\", \"hash\":\"60776ceb65672c7353695095fd02049d0ba56eef\", \"best_bid\":\"0.67\", \"best_ask\":\"0.68\"}, {\"asset_id\":\"14965588658799411272385430903075831224615961675357217884735713260981483529984\", \"price\":\"0.33\", \"size\":\"47.6\", \"side\":\"SELL\", \"hash\":\"727f2525c1d3742628e77cc94afae89db915748d\", \"best_bid\":\"0.32\", \"best_ask\":\"0.33\"}], \"timestamp\":\"1785208333287\", \"event_type\":\"price_change\"}","received_at":"2026-07-28T03:12:27.152441Z","schema_version":"clob-market-ws.price_change.v1","sequence":null,"server_hash":null,"server_timestamp":"1785208333287","session_id":"3e519d9098404c15b234d96025eb1a2b","source":"clob_market_ws"},"received_at":"2026-07-28T03:12:27.152441Z","record_id":"fe27b77d6718697a49fb8c697488973e1429ceb36edab864582542eeff9aa117","schema_fingerprint":"4aa3821a28b0b7c2400bc59aba4bcc0a76e971dadd19610d3ad38c768e124dc7","schema_version":"edge-lab-recorder.raw.v1","sequence":null,"source":"clob_market_ws"}
{"event_at":"2026-07-28T03:12:13.287000Z","event_fingerprint":"07ee4ba2cbaea5c7997dba2825bcca4e1c9414017719024b9c24f5015186d9d0","payload":{"connection_id":"a6b55582af5f430fb37ad02bf0922475","event_at":"2026-07-28T03:12:13.287000Z","event_type":"price_change","frame_hash":"38aa2a0fc4418b8cdc2aa3e6593516718ac23e3b270133e44ec648758d55ed40","frame_index":0,"kind":"data","monotonic_ns":310330188571625,"payload":{"event_type":"price_change","market":"0x779291bef19b6709f61e9764a954aafe9ffae488d50ae674aabdcb4f248006d5","price_changes":[{"asset_id":"14965588658799411272385430903075831224615961675357217884735713260981483529984","best_ask":"0.33","best_bid":"0.32","hash":"727f2525c1d3742628e77cc94afae89db915748d","price":"0.2","side":"BUY","size":"256.11"},{"asset_id":"8761897749749422724209054078244794145777693856614463256546737399611489089783","best_ask":"0.68","best_bid":"0.67","hash":"60776ceb65672c7353695095fd02049d0ba56eef","price":"0.8","side":"SELL","size":"256.11"}],"timestamp":"1785208333287"},"payload_hash":"ec6cb34446509cf3a3a912bb2dcf5520230a619ffcb2102575aad2579ff90205","raw_frame":"{\"market\":\"0x779291bef19b6709f61e9764a954aafe9ffae488d50ae674aabdcb4f248006d5\", \"price_changes\":[{\"asset_id\":\"14965588658799411272385430903075831224615961675357217884735713260981483529984\", \"price\":\"0.2\", \"size\":\"256.11\", \"side\":\"BUY\", \"hash\":\"727f2525c1d3742628e77cc94afae89db915748d\", \"best_bid\":\"0.32\", \"best_ask\":\"0.33\"}, {\"asset_id\":\"8761897749749422724209054078244794145777693856614463256546737399611489089783\", \"price\":\"0.8\", \"size\":\"256.11\", \"side\":\"SELL\", \"hash\":\"60776ceb65672c7353695095fd02049d0ba56eef\", \"best_bid\":\"0.67\", \"best_ask\":\"0.68\"}], \"timestamp\":\"1785208333287\", \"event_type\":\"price_change\"}","received_at":"2026-07-28T03:12:27.153981Z","schema_version":"clob-market-ws.price_change.v1","sequence":null,"server_hash":null,"server_timestamp":"1785208333287","session_id":"3e519d9098404c15b234d96025eb1a2b","source":"clob_market_ws"},"received_at":"2026-07-28T03:12:27.153981Z","record_id":"b13f83d84e8b60d4ac1afee819fb3722410bef5d9b5742f1be208dfd2277a4b6","schema_fingerprint":"4aa3821a28b0b7c2400bc59aba4bcc0a76e971dadd19610d3ad38c768e124dc7","schema_version":"edge-lab-recorder.raw.v1","sequence":null,"source":"clob_market_ws"}
{"event_at":"2026-07-28T03:12:13.292000Z","event_fingerprint":"afdb6c9ce6af1ec4d62b33aaf5e06f7e373b4f215349c81cda93a349c3064fc6","payload":{"connection_id":"a6b55582af5f430fb37ad02bf0922475","event_at":"2026-07-28T03:12:13.292000Z","event_type":"price_change","frame_hash":"ed9c1088bec7ec0d1e99f06efd18064472cec2787c279ca9aae4173aae7a904e","frame_index":0,"kind":"data","monotonic_ns":310330190081666,"payload":{"event_type":"price_change","market":"0x779291bef19b6709f61e9764a954aafe9ffae488d50ae674aabdcb4f248006d5","price_changes":[{"asset_id":"14965588658799411272385430903075831224615961675357217884735713260981483529984","best_ask":"0.33","best_bid":"0.32","hash":"bbfcbb0137ffcba0ba1acf860a37f0807d853153","price":"0.31","side":"BUY","size":"73"},{"asset_id":"8761897749749422724209054078244794145777693856614463256546737399611489089783","best_ask":"0.68","best_bid":"0.67","hash":"b768b5e80e99ddffc4366aa94923aef6eba4656a","price":"0.69","side":"SELL","size":"73"}],"timestamp":"1785208333292"},"payload_hash":"efaeea9d6a8cae8571766431320bd9e7c1c3e68847cac82649fd94582f59a8cc","raw_frame":"{\"market\":\"0x779291bef19b6709f61e9764a954aafe9ffae488d50ae674aabdcb4f248006d5\", \"price_changes\":[{\"asset_id\":\"14965588658799411272385430903075831224615961675357217884735713260981483529984\", \"price\":\"0.31\", \"size\":\"73\", \"side\":\"BUY\", \"hash\":\"bbfcbb0137ffcba0ba1acf860a37f0807d853153\", \"best_bid\":\"0.32\", \"best_ask\":\"0.33\"}, {\"asset_id\":\"8761897749749422724209054078244794145777693856614463256546737399611489089783\", \"price\":\"0.69\", \"size\":\"73\", \"side\":\"SELL\", \"hash\":\"b768b5e80e99ddffc4366aa94923aef6eba4656a\", \"best_bid\":\"0.67\", \"best_ask\":\"0.68\"}], \"timestamp\":\"1785208333292\", \"event_type\":\"price_change\"}","received_at":"2026-07-28T03:12:27.155490Z","schema_version":"clob-market-ws.price_change.v1","sequence":null,"server_hash":null,"server_timestamp":"1785208333292","session_id":"3e519d9098404c15b234d96025eb1a2b","source":"clob_market_ws"},"received_at":"2026-07-28T03:12:27.155490Z","record_id":"8d4449933b0174c12f979e152b90186e53733172bfbef61388096b0f0b8496df","schema_fingerprint":"4aa3821a28b0b7c2400bc59aba4bcc0a76e971dadd19610d3ad38c768e124dc7","schema_version":"edge-lab-recorder.raw.v1","sequence":null,"source":"clob_market_ws"}
{"event_at":"2026-07-28T03:12:13.293000Z","event_fingerprint":"ea0ff10269a84e8924d76e6999a01c570bf0f0965f19d4dad3a735baeb4a652f","payload":{"connection_id":"a6b55582af5f430fb37ad02bf0922475","event_at":"2026-07-28T03:12:13.293000Z","event_type":"price_change","frame_hash":"7c94517359089f9e93ac0b63d767dd882a0e777249cf435cfa4b5ab9e71a5849","frame_index":0,"kind":"data","monotonic_ns":310330191588750,"payload":{"event_type":"price_change","market":"0x779291bef19b6709f61e9764a954aafe9ffae488d50ae674aabdcb4f248006d5","price_changes":[{"asset_id":"14965588658799411272385430903075831224615961675357217884735713260981483529984","best_ask":"0.33","best_bid":"0.32","hash":"5bae9723ba89b25e2b485a1b2a1ff4fafdcbb5cb","price":"0.21","side":"BUY","size":"248"},{"asset_id":"8761897749749422724209054078244794145777693856614463256546737399611489089783","best_ask":"0.68","best_bid":"0.67","hash":"6d012a3258755cbca8e17ef56dcea3676fedb081","price":"0.79","side":"SELL","size":"248"}],"timestamp":"1785208333293"},"payload_hash":"ed1e229cc2f4170ed2557474109fc8116bd1f9a74f80fe1876bd6f98a646607a","raw_frame":"{\"market\":\"0x779291bef19b6709f61e9764a954aafe9ffae488d50ae674aabdcb4f248006d5\", \"price_changes\":[{\"asset_id\":\"14965588658799411272385430903075831224615961675357217884735713260981483529984\", \"price\":\"0.21\", \"size\":\"248\", \"side\":\"BUY\", \"hash\":\"5bae9723ba89b25e2b485a1b2a1ff4fafdcbb5cb\", \"best_bid\":\"0.32\", \"best_ask\":\"0.33\"}, {\"asset_id\":\"8761897749749422724209054078244794145777693856614463256546737399611489089783\", \"price\":\"0.79\", \"size\":\"248\", \"side\":\"SELL\", \"hash\":\"6d012a3258755cbca8e17ef56dcea3676fedb081\", \"best_bid\":\"0.67\", \"best_ask\":\"0.68\"}], \"timestamp\":\"1785208333293\", \"event_type\":\"price_change\"}","received_at":"2026-07-28T03:12:27.156998Z","schema_version":"clob-market-ws.price_change.v1","sequence":null,"server_hash":null,"server_timestamp":"1785208333293","session_id":"3e519d9098404c15b234d96025eb1a2b","source":"clob_market_ws"},"received_at":"2026-07-28T03:12:27.156998Z","record_id":"f91dabb43c871c7b6459cd60df096521422bb289a683d61103eb1c8e3c5593e3","schema_fingerprint":"4aa3821a28b0b7c2400bc59aba4bcc0a76e971dadd19610d3ad38c768e124dc7","schema_version":"edge-lab-recorder.raw.v1","sequence":null,"source":"clob_market_ws"}
{"event_at":"2026-07-28T03:12:13.305000Z","event_fingerprint":"4d52ea8ed473cbad561fcf3a0e005c9f4dfecb183978985df6e1030ef1bf96de","payload":{"connection_id":"a6b55582af5f430fb37ad02bf0922475","event_at":"2026-07-28T03:12:13.305000Z","event_type":"price_change","frame_hash":"1a2cf772742c7d4b9eb25d5a86fc7e1204139ffca4b78f66df8663ea9a247d34","frame_index":0,"kind":"data","monotonic_ns":310330193099208,"payload":{"event_type":"price_change","market":"0x779291bef19b6709f61e9764a954aafe9ffae488d50ae674aabdcb4f248006d5","price_changes":[{"asset_id":"8761897749749422724209054078244794145777693856614463256546737399611489089783","best_ask":"0.68","best_bid":"0.67","hash":"8bd0aba41d58fd32050f789da46c1f0a4e5196eb","price":"0.03","side":"BUY","size":"545"},{"asset_id":"14965588658799411272385430903075831224615961675357217884735713260981483529984","best_ask":"0.33","best_bid":"0.32","hash":"484546834886c2f1efc504e72b3a679bc61e90f5","price":"0.97","side":"SELL","size":"545"}],"timestamp":"1785208333305"},"payload_hash":"34ebd668650ad48cb692cb2a740a0184c0e4392e5f9c5afafb07f5a39f34d831","raw_frame":"{\"market\":\"0x779291bef19b6709f61e9764a954aafe9ffae488d50ae674aabdcb4f248006d5\", \"price_changes\":[{\"asset_id\":\"8761897749749422724209054078244794145777693856614463256546737399611489089783\", \"price\":\"0.03\", \"size\":\"545\", \"side\":\"BUY\", \"hash\":\"8bd0aba41d58fd32050f789da46c1f0a4e5196eb\", \"best_bid\":\"0.67\", \"best_ask\":\"0.68\"}, {\"asset_id\":\"14965588658799411272385430903075831224615961675357217884735713260981483529984\", \"price\":\"0.97\", \"size\":\"545\", \"side\":\"SELL\", \"hash\":\"484546834886c2f1efc504e72b3a679bc61e90f5\", \"best_bid\":\"0.32\", \"best_ask\":\"0.33\"}], \"timestamp\":\"1785208333305\", \"event_type\":\"price_change\"}","received_at":"2026-07-28T03:12:27.158508Z","schema_version":"clob-market-ws.price_change.v1","sequence":null,"server_hash":null,"server_timestamp":"1785208333305","session_id":"3e519d9098404c15b234d96025eb1a2b","source":"clob_market_ws"},"received_at":"2026-07-28T03:12:27.158508Z","record_id":"5438033d52d739e4b323e4f698dbe75d6c110e6c270576598580b0b38aa5e443","schema_fingerprint":"4aa3821a28b0b7c2400bc59aba4bcc0a76e971dadd19610d3ad38c768e124dc7","schema_version":"edge-lab-recorder.raw.v1","sequence":null,"source":"clob_market_ws"}
{"event_at":"2026-07-28T03:12:13.312000Z","event_fingerprint":"313a2f72e33ccc6d1dbe27e67edace1f5357da8c7fae7845ee9590d5476c3d75","payload":{"connection_id":"a6b55582af5f430fb37ad02bf0922475","event_at":"2026-07-28T03:12:13.312000Z","event_type":"price_change","frame_hash":"02bc56bd5b21b120bc8fef74f4a5c8816d04a8144a2cb8eaf69b348f5d900817","frame_index":0,"kind":"data","monotonic_ns":310330194597666,"payload":{"event_type":"price_change","market":"0x779291bef19b6709f61e9764a954aafe9ffae488d50ae674aabdcb4f248006d5","price_changes":[{"asset_id":"8761897749749422724209054078244794145777693856614463256546737399611489089783","best_ask":"0.68","best_bid":"0.67","hash":"8b66b7ce70342c850cdb4cdc2f66378a0ae7452e","price":"0.01","side":"BUY","size":"5305.02"},{"asset_id":"14965588658799411272385430903075831224615961675357217884735713260981483529984","best_ask":"0.33","best_bid":"0.32","hash":"53f938e7e91269b21e1acd6fb24133cfc4920622","price":"0.99","side":"SELL","size":"5305.02"}],"timestamp":"1785208333312"},"payload_hash":"c31473fc013c802553081d688bf3876d141f2110932e22cdcf5b5e9fbaab08fb","raw_frame":"{\"market\":\"0x779291bef19b6709f61e9764a954aafe9ffae488d50ae674aabdcb4f248006d5\", \"price_changes\":[{\"asset_id\":\"8761897749749422724209054078244794145777693856614463256546737399611489089783\", \"price\":\"0.01\", \"size\":\"5305.02\", \"side\":\"BUY\", \"hash\":\"8b66b7ce70342c850cdb4cdc2f66378a0ae7452e\", \"best_bid\":\"0.67\", \"best_ask\":\"0.68\"}, {\"asset_id\":\"14965588658799411272385430903075831224615961675357217884735713260981483529984\", \"price\":\"0.99\", \"size\":\"5305.02\", \"side\":\"SELL\", \"hash\":\"53f938e7e91269b21e1acd6fb24133cfc4920622\", \"best_bid\":\"0.32\", \"best_ask\":\"0.33\"}], \"timestamp\":\"1785208333312\", \"event_type\":\"price_change\"}","received_at":"2026-07-28T03:12:27.160006Z","schema_version":"clob-market-ws.price_change.v1","sequence":null,"server_hash":null,"server_timestamp":"1785208333312","session_id":"3e519d9098404c15b234d96025eb1a2b","source":"clob_market_ws"},"received_at":"2026-07-28T03:12:27.160006Z","record_id":"45580022ca2244ce8b536196438e11bc21e63ba41349f1ba58b87a1b1ec9f4a3","schema_fingerprint":"4aa3821a28b0b7c2400bc59aba4bcc0a76e971dadd19610d3ad38c768e124dc7","schema_version":"edge-lab-recorder.raw.v1","sequence":null,"source":"clob_market_ws"}
{"event_at":"2026-07-28T03:12:13.321000Z","event_fingerprint":"cee9bdf0d1ab2d232580bae874d68e6995e777fb7fcded59e05d2181ae4afe8f","payload":{"connection_id":"a6b55582af5f430fb37ad02bf0922475","event_at":"2026-07-28T03:12:13.321000Z","event_type":"price_change","frame_hash":"be7e82ade083548e3a7fc1f115d386fd7eda3f95e5cb7fc66dae5573018dbc45","frame_index":0,"kind":"data","monotonic_ns":310330196086458,"payload":{"event_type":"price_change","market":"0x779291bef19b6709f61e9764a954aafe9ffae488d50ae674aabdcb4f248006d5","price_changes":[{"asset_id":"8761897749749422724209054078244794145777693856614463256546737399611489089783","best_ask":"0.68","best_bid":"0.67","hash":"a186fa6c724a02f31cce725ff658b5c3b10225df","price":"0.57","side":"BUY","size":"215"},{"asset_id":"14965588658799411272385430903075831224615961675357217884735713260981483529984","best_ask":"0.33","best_bid":"0.32","hash":"4618a241bacb2f833304012025fc90036e68a1e6","price":"0.43","side":"SELL","size":"215"}],"timestamp":"1785208333321"},"payload_hash":"470dedf6d70cce2109cf41b266d9515cafc8726afa006b10d440af97abbb65d8","raw_frame":"{\"market\":\"0x779291bef19b6709f61e9764a954aafe9ffae488d50ae674aabdcb4f248006d5\", \"price_changes\":[{\"asset_id\":\"8761897749749422724209054078244794145777693856614463256546737399611489089783\", \"price\":\"0.57\", \"size\":\"215\", \"side\":\"BUY\", \"hash\":\"a186fa6c724a02f31cce725ff658b5c3b10225df\", \"best_bid\":\"0.67\", \"best_ask\":\"0.68\"}, {\"asset_id\":\"14965588658799411272385430903075831224615961675357217884735713260981483529984\", \"price\":\"0.43\", \"size\":\"215\", \"side\":\"SELL\", \"hash\":\"4618a241bacb2f833304012025fc90036e68a1e6\", \"best_bid\":\"0.32\", \"best_ask\":\"0.33\"}], \"timestamp\":\"1785208333321\", \"event_type\":\"price_change\"}","received_at":"2026-07-28T03:12:27.161495Z","schema_version":"clob-market-ws.price_change.v1","sequence":null,"server_hash":null,"server_timestamp":"1785208333321","session_id":"3e519d9098404c15b234d96025eb1a2b","source":"clob_market_ws"},"received_at":"2026-07-28T03:12:27.161495Z","record_id":"2253a987d7a52891c9ab5694bc9c8f3f2502bf6cd5abda0e40c5c5412491c562","schema_fingerprint":"4aa3821a28b0b7c2400bc59aba4bcc0a76e971dadd19610d3ad38c768e124dc7","schema_version":"edge-lab-recorder.raw.v1","sequence":null,"source":"clob_market_ws"}
{"event_at":"2026-07-28T03:12:13.321000Z","event_fingerprint":"7882411c3370d19cb65907c4c5f8c754408a8341e0647d48e9af193257c17dca","payload":{"connection_id":"a6b55582af5f430fb37ad02bf0922475","event_at":"2026-07-28T03:12:13.321000Z","event_type":"price_change","frame_hash":"739cd51f8a496c2964cb54ffdc19f341fc11ca72d669ae74dd38a2bff31c5b98","frame_index":0,"kind":"data","monotonic_ns":310330197587958,"payload":{"event_type":"price_change","market":"0x779291bef19b6709f61e9764a954aafe9ffae488d50ae674aabdcb4f248006d5","price_changes":[{"asset_id":"14965588658799411272385430903075831224615961675357217884735713260981483529984","best_ask":"0.33","best_bid":"0.32","hash":"d7344db19bbc9e14a1cf36f10d65074bec7b3b06","price":"0.23","side":"BUY","size":"305"},{"asset_id":"8761897749749422724209054078244794145777693856614463256546737399611489089783","best_ask":"0.68","best_bid":"0.67","hash":"54ac7ad281ffd3e4826e7d35a44a5046f05361b8","price":"0.77","side":"SELL","size":"305"}],"timestamp":"1785208333321"},"payload_hash":"505dd04d16d90c21c80ffcfb4f719061bca8f8d7f2ab64e4e10c756d74436363","raw_frame":"{\"market\":\"0x779291bef19b6709f61e9764a954aafe9ffae488d50ae674aabdcb4f248006d5\", \"price_changes\":[{\"asset_id\":\"14965588658799411272385430903075831224615961675357217884735713260981483529984\", \"price\":\"0.23\", \"size\":\"305\", \"side\":\"BUY\", \"hash\":\"d7344db19bbc9e14a1cf36f10d65074bec7b3b06\", \"best_bid\":\"0.32\", \"best_ask\":\"0.33\"}, {\"asset_id\":\"8761897749749422724209054078244794145777693856614463256546737399611489089783\", \"price\":\"0.77\", \"size\":\"305\", \"side\":\"SELL\", \"hash\":\"54ac7ad281ffd3e4826e7d35a44a5046f05361b8\", \"best_bid\":\"0.67\", \"best_ask\":\"0.68\"}], \"timestamp\":\"1785208333321\", \"event_type\":\"price_change\"}","received_at":"2026-07-28T03:12:27.162997Z","schema_version":"clob-market-ws.price_change.v1","sequence":null,"server_hash":null,"server_timestamp":"1785208333321","session_id":"3e519d9098404c15b234d96025eb1a2b","source":"clob_market_ws"},"received_at":"2026-07-28T03:12:27.162997Z","record_id":"c847a9396c6c060fa81414336a52b4323182c474f8b7c418d7feac3000b4d999","schema_fingerprint":"4aa3821a28b0b7c2400bc59aba4bcc0a76e971dadd19610d3ad38c768e124dc7","schema_version":"edge-lab-recorder.raw.v1","sequence":null,"source":"clob_market_ws"}
{"event_at":"2026-07-28T03:12:13.338000Z","event_fingerprint":"cd473a2cc2f490422cc8c64ef0d8253488d5b198255bd6e7c3bbd2942aaf76be","payload":{"connection_id":"a6b55582af5f430fb37ad02bf0922475","event_at":"2026-07-28T03:12:13.338000Z","event_type":"price_change","frame_hash":"b33a1db4ccded7d5a5b9b32aa5704a08092fa5744a22adca2872f659eed0fd1b","frame_index":0,"kind":"data","monotonic_ns":310330199053666,"payload":{"event_type":"price_change","market":"0x779291bef19b6709f61e9764a954aafe9ffae488d50ae674aabdcb4f248006d5","price_changes":[{"asset_id":"8761897749749422724209054078244794145777693856614463256546737399611489089783","best_ask":"0.68","best_bid":"0.67","hash":"5feb57671c8e2a10f17e612caac9c49f3dfba593","price":"0.01","side":"BUY","size":"5300.02"},{"asset_id":"14965588658799411272385430903075831224615961675357217884735713260981483529984","best_ask":"0.33","best_bid":"0.32","hash":"7734325100b26c7909a733e3bc357000cbffbfe0","price":"0.99","side":"SELL","size":"5300.02"}],"timestamp":"1785208333338"},"payload_hash":"5454e73da3f1e7499cbba69b431d3145370b38db32401af7939e80cf41d04edd","raw_frame":"{\"market\":\"0x779291bef19b6709f61e9764a954aafe9ffae488d50ae674aabdcb4f248006d5\", \"price_changes\":[{\"asset_id\":\"8761897749749422724209054078244794145777693856614463256546737399611489089783\", \"price\":\"0.01\", \"size\":\"5300.02\", \"side\":\"BUY\", \"hash\":\"5feb57671c8e2a10f17e612caac9c49f3dfba593\", \"best_bid\":\"0.67\", \"best_ask\":\"0.68\"}, {\"asset_id\":\"14965588658799411272385430903075831224615961675357217884735713260981483529984\", \"price\":\"0.99\", \"size\":\"5300.02\", \"side\":\"SELL\", \"hash\":\"7734325100b26c7909a733e3bc357000cbffbfe0\", \"best_bid\":\"0.32\", \"best_ask\":\"0.33\"}], \"timestamp\":\"1785208333338\", \"event_type\":\"price_change\"}","received_at":"2026-07-28T03:12:27.164462Z","schema_version":"clob-market-ws.price_change.v1","sequence":null,"server_hash":null,"server_timestamp":"1785208333338","session_id":"3e519d9098404c15b234d96025eb1a2b","source":"clob_market_ws"},"received_at":"2026-07-28T03:12:27.164462Z","record_id":"8e19edb1b5580c07ba7be6fe1b19fbd8dc931e9c0e8c1ed3576d7bacc2a8bef8","schema_fingerprint":"4aa3821a28b0b7c2400bc59aba4bcc0a76e971dadd19610d3ad38c768e124dc7","schema_version":"edge-lab-recorder.raw.v1","sequence":null,"source":"clob_market_ws"}
{"event_at":"2026-07-28T03:12:13.341000Z","event_fingerprint":"ad2f628374e8c72309b60bc25041a50bbfbb8f05a212afb27f7620db84eb2fc5","payload":{"connection_id":"a6b55582af5f430fb37ad02bf0922475","event_at":"2026-07-28T03:12:13.341000Z","event_type":"price_change","frame_hash":"a90fb6be800ddd88083f67036ff4b582f336de9a303406ed4ccd94502e99739c","frame_index":0,"kind":"data","monotonic_ns":310330200560208,"payload":{"event_type":"price_change","market":"0x779291bef19b6709f61e9764a954aafe9ffae488d50ae674aabdcb4f248006d5","price_changes":[{"asset_id":"8761897749749422724209054078244794145777693856614463256546737399611489089783","best_ask":"0.68","best_bid":"0.67","hash":"e94beaccf64b539109a215508556c876fd23726f","price":"0.68","side":"SELL","size":"27"},{"asset_id":"14965588658799411272385430903075831224615961675357217884735713260981483529984","best_ask":"0.33","best_bid":"0.32","hash":"28b154bf11007ef20f9d22b053ab3a9883a277d2","price":"0.32","side":"BUY","size":"27"}],"timestamp":"1785208333341"},"payload_hash":"97351c64e38bc0dafaa4e9e192209f6e7bdfcace0eee943189b98c84b43d98d2","raw_frame":"{\"market\":\"0x779291bef19b6709f61e9764a954aafe9ffae488d50ae674aabdcb4f248006d5\", \"price_changes\":[{\"asset_id\":\"8761897749749422724209054078244794145777693856614463256546737399611489089783\", \"price\":\"0.68\", \"size\":\"27\", \"side\":\"SELL\", \"hash\":\"e94beaccf64b539109a215508556c876fd23726f\", \"best_bid\":\"0.67\", \"best_ask\":\"0.68\"}, {\"asset_id\":\"14965588658799411272385430903075831224615961675357217884735713260981483529984\", \"price\":\"0.32\", \"size\":\"27\", \"side\":\"BUY\", \"hash\":\"28b154bf11007ef20f9d22b053ab3a9883a277d2\", \"best_bid\":\"0.32\", \"best_ask\":\"0.33\"}], \"timestamp\":\"1785208333341\", \"event_type\":\"price_change\"}","received_at":"2026-07-28T03:12:27.165969Z","schema_version":"clob-market-ws.price_change.v1","sequence":null,"server_hash":null,"server_timestamp":"1785208333341","session_id":"3e519d9098404c15b234d96025eb1a2b","source":"clob_market_ws"},"received_at":"2026-07-28T03:12:27.165969Z","record_id":"06cf17e6a9f3117e2aeb8a330c0f2a3b5c42b98c64c79d816ca423dd4b2b56a2","schema_fingerprint":"4aa3821a28b0b7c2400bc59aba4bcc0a76e971dadd19610d3ad38c768e124dc7","schema_version":"edge-lab-recorder.raw.v1","sequence":null,"source":"clob_market_ws"}
{"event_at":"2026-07-28T03:12:13.364000Z","event_fingerprint":"d2b4c027ef564b45263c3e5dfc86026136ff82bc65e01de325bb5cf58b793ac3","payload":{"connection_id":"a6b55582af5f430fb37ad02bf0922475","event_at":"2026-07-28T03:12:13.364000Z","event_type":"price_change","frame_hash":"fc9efe9602cbecc33b752d92867c29dd78b76b13b576589f970e8bba438938f8","frame_index":0,"kind":"data","monotonic_ns":310330202483041,"payload":{"event_type":"price_change","market":"0x779291bef19b6709f61e9764a954aafe9ffae488d50ae674aabdcb4f248006d5","price_changes":[{"asset_id":"8761897749749422724209054078244794145777693856614463256546737399611489089783","best_ask":"0.68","best_bid":"0.67","hash":"e596f7bde998dc59504a6ce263b775927dc694d4","price":"0.03","side":"BUY","size":"540"},{"asset_id":"14965588658799411272385430903075831224615961675357217884735713260981483529984","best_ask":"0.33","best_bid":"0.32","hash":"af9d8f27005835acbd14f99820dcc54c62c3369d","price":"0.97","side":"SELL","size":"540"}],"timestamp":"1785208333364"},"payload_hash":"dc8adde8eb8d93c77013c429c54180da8e8fba3309830e48947765d88e02824a","raw_frame":"{\"market\":\"0x779291bef19b6709f61e9764a954aafe9ffae488d50ae674aabdcb4f248006d5\", \"price_changes\":[{\"asset_id\":\"8761897749749422724209054078244794145777693856614463256546737399611489089783\", \"price\":\"0.03\", \"size\":\"540\", \"side\":\"BUY\", \"hash\":\"e596f7bde998dc59504a6ce263b775927dc694d4\", \"best_bid\":\"0.67\", \"best_ask\":\"0.68\"}, {\"asset_id\":\"14965588658799411272385430903075831224615961675357217884735713260981483529984\", \"price\":\"0.97\", \"size\":\"540\", \"side\":\"SELL\", \"hash\":\"af9d8f27005835acbd14f99820dcc54c62c3369d\", \"best_bid\":\"0.32\", \"best_ask\":\"0.33\"}], \"timestamp\":\"1785208333364\", \"event_type\":\"price_change\"}","received_at":"2026-07-28T03:12:27.167887Z","schema_version":"clob-market-ws.price_change.v1","sequence":null,"server_hash":null,"server_timestamp":"1785208333364","session_id":"3e519d9098404c15b234d96025eb1a2b","source":"clob_market_ws"},"received_at":"2026-07-28T03:12:27.167887Z","record_id":"cba6dc7bad2c73aafd332bdd3ef142940d9ce51e992bcdd28dff7f44f9fc372b","schema_fingerprint":"4aa3821a28b0b7c2400bc59aba4bcc0a76e971dadd19610d3ad38c768e124dc7","schema_version":"edge-lab-recorder.raw.v1","sequence":null,"source":"clob_market_ws"}
{"event_at":"2026-07-28T03:12:13.368000Z","event_fingerprint":"58d6ca3565c0299064fbd2c738162b5f59846cafe48680560abeb6d092ff02ba","payload":{"connection_id":"a6b55582af5f430fb37ad02bf0922475","event_at":"2026-07-28T03:12:13.368000Z","event_type":"price_change","frame_hash":"a7ff6652b89d5e2b8156cc2ab317c62a672f7dbbde8f4cdb45cfe653e38d1380","frame_index":0,"kind":"data","monotonic_ns":310330204346041,"payload":{"event_type":"price_change","market":"0x779291bef19b6709f61e9764a954aafe9ffae488d50ae674aabdcb4f248006d5","price_changes":[{"asset_id":"14965588658799411272385430903075831224615961675357217884735713260981483529984","best_ask":"0.33","best_bid":"0.32","hash":"dbd774c3a39c9aeb352178ee6ea4d4aad5425f58","price":"0.22","side":"BUY","size":"310.57"},{"asset_id":"8761897749749422724209054078244794145777693856614463256546737399611489089783","best_ask":"0.68","best_bid":"0.67","hash":"7fd8d99962f07bfe1e3904a61fe8c07d63906d13","price":"0.78","side":"SELL","size":"310.57"}],"timestamp":"1785208333368"},"payload_hash":"90db6e2f91cd189def29fb26a4203af8e0c3eb21aa7daa062b84bec84f6a7226","raw_frame":"{\"market\":\"0x779291bef19b6709f61e9764a954aafe9ffae488d50ae674aabdcb4f248006d5\", \"price_changes\":[{\"asset_id\":\"14965588658799411272385430903075831224615961675357217884735713260981483529984\", \"price\":\"0.22\", \"size\":\"310.57\", \"side\":\"BUY\", \"hash\":\"dbd774c3a39c9aeb352178ee6ea4d4aad5425f58\", \"best_bid\":\"0.32\", \"best_ask\":\"0.33\"}, {\"asset_id\":\"8761897749749422724209054078244794145777693856614463256546737399611489089783\", \"price\":\"0.78\", \"size\":\"310.57\", \"side\":\"SELL\", \"hash\":\"7fd8d99962f07bfe1e3904a61fe8c07d63906d13\", \"best_bid\":\"0.67\", \"best_ask\":\"0.68\"}], \"timestamp\":\"1785208333368\", \"event_type\":\"price_change\"}","received_at":"2026-07-28T03:12:27.169752Z","schema_version":"clob-market-ws.price_change.v1","sequence":null,"server_hash":null,"server_timestamp":"1785208333368","session_id":"3e519d9098404c15b234d96025eb1a2b","source":"clob_market_ws"},"received_at":"2026-07-28T03:12:27.169752Z","record_id":"044bc3c4c7ea5149bf15fad39fd1882a333a548d2d2c887c3b2e84cc8a6a80be","schema_fingerprint":"4aa3821a28b0b7c2400bc59aba4bcc0a76e971dadd19610d3ad38c768e124dc7","schema_version":"edge-lab-recorder.raw.v1","sequence":null,"source":"clob_market_ws"}
{"event_at":"2026-07-28T03:12:13.373000Z","event_fingerprint":"4a03e6f7b518363e4b4ddaf8bbae34ac125dc70c233ec078367044c2c61ea1d5","payload":{"connection_id":"a6b55582af5f430fb37ad02bf0922475","event_at":"2026-07-28T03:12:13.373000Z","event_type":"price_change","frame_hash":"c6c5dc7d7b7635c1d3dda6f0908f6e4d8b86bedbd7c495533d1d96c99fc8dc14","frame_index":0,"kind":"data","monotonic_ns":310330205900041,"payload":{"event_type":"price_change","market":"0x779291bef19b6709f61e9764a954aafe9ffae488d50ae674aabdcb4f248006d5","price_changes":[{"asset_id":"8761897749749422724209054078244794145777693856614463256546737399611489089783","best_ask":"0.68","best_bid":"0.67","hash":"3cd0375b07861efe1d7184a7d4f9390f9d2ac02d","price":"0.67","side":"BUY","size":"27.6"},{"asset_id":"14965588658799411272385430903075831224615961675357217884735713260981483529984","best_ask":"0.33","best_bid":"0.32","hash":"3d0df6e63b55be478d47c66cac6f0831aef82e7c","price":"0.33","side":"SELL","size":"27.6"}],"timestamp":"1785208333373"},"payload_hash":"467e2c11a4672e9e8b37a19c7bb4e6fe7d177f84b2ffbe7d962d69deb796e533","raw_frame":"{\"market\":\"0x779291bef19b6709f61e9764a954aafe9ffae488d50ae674aabdcb4f248006d5\", \"price_changes\":[{\"asset_id\":\"8761897749749422724209054078244794145777693856614463256546737399611489089783\", \"price\":\"0.67\", \"size\":\"27.6\", \"side\":\"BUY\", \"hash\":\"3cd0375b07861efe1d7184a7d4f9390f9d2ac02d\", \"best_bid\":\"0.67\", \"best_ask\":\"0.68\"}, {\"asset_id\":\"14965588658799411272385430903075831224615961675357217884735713260981483529984\", \"price\":\"0.33\", \"size\":\"27.6\", \"side\":\"SELL\", \"hash\":\"3d0df6e63b55be478d47c66cac6f0831aef82e7c\", \"best_bid\":\"0.32\", \"best_ask\":\"0.33\"}], \"timestamp\":\"1785208333373\", \"event_type\":\"price_change\"}","received_at":"2026-07-28T03:12:27.171307Z","schema_version":"clob-market-ws.price_change.v1","sequence":null,"server_hash":null,"server_timestamp":"1785208333373","session_id":"3e519d9098404c15b234d96025eb1a2b","source":"clob_market_ws"},"received_at":"2026-07-28T03:12:27.171307Z","record_id":"b9af67da53d84f96400d82d48b4bbb6a05cfeb9efc6667b8e047ba341d527296","schema_fingerprint":"4aa3821a28b0b7c2400bc59aba4bcc0a76e971dadd19610d3ad38c768e124dc7","schema_version":"edge-lab-recorder.raw.v1","sequence":null,"source":"clob_market_ws"}
{"event_at":"2026-07-28T03:12:13.376000Z","event_fingerprint":"dcb2fe1611b12b608487cbaf4c9705cc93f48dacab4e9f6b3788dd5bfdf623ed","payload":{"connection_id":"a6b55582af5f430fb37ad02bf0922475","event_at":"2026-07-28T03:12:13.376000Z","event_type":"price_change","frame_hash":"4067b7d813880cfdc95f2d860cc779cab9410962454817b87abec51422e38cfa","frame_index":0,"kind":"data","monotonic_ns":310330207444375,"payload":{"event_type":"price_change","market":"0x779291bef19b6709f61e9764a954aafe9ffae488d50ae674aabdcb4f248006d5","price_changes":[{"asset_id":"8761897749749422724209054078244794145777693856614463256546737399611489089783","best_ask":"0.68","best_bid":"0.67","hash":"123a95efdee3dfacbd2f908be93c7b4c2bcb3a42","price":"0.65","side":"BUY","size":"66.16"},{"asset_id":"14965588658799411272385430903075831224615961675357217884735713260981483529984","best_ask":"0.33","best_bid":"0.32","hash":"f5dd44be172e67a6716d22d238f83c130143bc1a","price":"0.35","side":"SELL","size":"66.16"}],"timestamp":"1785208333376"},"payload_hash":"1039aebaaba709b24c1eb917ef8bef8f6e93888908919c1b948f116906ae744f","raw_frame":"{\"market\":\"0x779291bef19b6709f61e9764a954aafe9ffae488d50ae674aabdcb4f248006d5\", \"price_changes\":[{\"asset_id\":\"8761897749749422724209054078244794145777693856614463256546737399611489089783\", \"price\":\"0.65\", \"size\":\"66.16\", \"side\":\"BUY\", \"hash\":\"123a95efdee3dfacbd2f908be93c7b4c2bcb3a42\", \"best_bid\":\"0.67\", \"best_ask\":\"0.68\"}, {\"asset_id\":\"14965588658799411272385430903075831224615961675357217884735713260981483529984\", \"price\":\"0.35\", \"size\":\"66.16\", \"side\":\"SELL\", \"hash\":\"f5dd44be172e67a6716d22d238f83c130143bc1a\", \"best_bid\":\"0.32\", \"best_ask\":\"0.33\"}], \"timestamp\":\"1785208333376\", \"event_type\":\"price_change\"}","received_at":"2026-07-28T03:12:27.172840Z","schema_version":"clob-market-ws.price_change.v1","sequence":null,"server_hash":null,"server_timestamp":"1785208333376","session_id":"3e519d9098404c15b234d96025eb1a2b","source":"clob_market_ws"},"received_at":"2026-07-28T03:12:27.172840Z","record_id":"6934a9aaf0f2e33cde5855ea85bd13165f913c890f18670f710065a487f59671","schema_fingerprint":"4aa3821a28b0b7c2400bc59aba4bcc0a76e971dadd19610d3ad38c768e124dc7","schema_version":"edge-lab-recorder.raw.v1","sequence":null,"source":"clob_market_ws"}
{"event_at":"2026-07-28T03:12:13.379000Z","event_fingerprint":"e0cc457d5e6b07ef126b4477a88c0f67d211ce8ccd7ccba251eb319bff1d7417","payload":{"connection_id":"a6b55582af5f430fb37ad02bf0922475","event_at":"2026-07-28T03:12:13.379000Z","event_type":"price_change","frame_hash":"a8fe8ad43358cd4a13e99d1a75a9b80afe835ae426e13f3a3678882ade4c5a08","frame_index":0,"kind":"data","monotonic_ns":310330208931708,"payload":{"event_type":"price_change","market":"0x779291bef19b6709f61e9764a954aafe9ffae488d50ae674aabdcb4f248006d5","price_changes":[{"asset_id":"8761897749749422724209054078244794145777693856614463256546737399611489089783","best_ask":"0.68","best_bid":"0.67","hash":"8d257511d25db8f2897ec55e972553a3236c744c","price":"0.66","side":"BUY","size":"413.6"},{"asset_id":"14965588658799411272385430903075831224615961675357217884735713260981483529984","best_ask":"0.33","best_bid":"0.32","hash":"d798f296b9ffd0f1ca397c254baee4a798d68ee8","price":"0.34","side":"SELL","size":"413.6"}],"timestamp":"1785208333379"},"payload_hash":"82a961b00f531cdcb0d90cb27708f48ed1320469914799e4ed33473b45cc8699","raw_frame":"{\"market\":\"0x779291bef19b6709f61e9764a954aafe9ffae488d50ae674aabdcb4f248006d5\", \"price_changes\":[{\"asset_id\":\"8761897749749422724209054078244794145777693856614463256546737399611489089783\", \"price\":\"0.66\", \"size\":\"413.6\", \"side\":\"BUY\", \"hash\":\"8d257511d25db8f2897ec55e972553a3236c744c\", \"best_bid\":\"0.67\", \"best_ask\":\"0.68\"}, {\"asset_id\":\"14965588658799411272385430903075831224615961675357217884735713260981483529984\", \"price\":\"0.34\", \"size\":\"413.6\", \"side\":\"SELL\", \"hash\":\"d798f296b9ffd0f1ca397c254baee4a798d68ee8\", \"best_bid\":\"0.32\", \"best_ask\":\"0.33\"}], \"timestamp\":\"1785208333379\", \"event_type\":\"price_change\"}","received_at":"2026-07-28T03:12:27.174334Z","schema_version":"clob-market-ws.price_change.v1","sequence":null,"server_hash":null,"server_timestamp":"1785208333379","session_id":"3e519d9098404c15b234d96025eb1a2b","source":"clob_market_ws"},"received_at":"2026-07-28T03:12:27.174334Z","record_id":"df02fdfcec07035af9199ec9c2932b8b25c9cc94a83341dd3c8a669d4a235a70","schema_fingerprint":"4aa3821a28b0b7c2400bc59aba4bcc0a76e971dadd19610d3ad38c768e124dc7","schema_version":"edge-lab-recorder.raw.v1","sequence":null,"source":"clob_market_ws"}
{"event_at":"2026-07-28T03:12:13.383000Z","event_fingerprint":"888107098720d91de6f022ef8b48473fd07fe8434eb428bb4228b870394b4be7","payload":{"connection_id":"a6b55582af5f430fb37ad02bf0922475","event_at":"2026-07-28T03:12:13.383000Z","event_type":"price_change","frame_hash":"39c1c2f4b0bbd859b6e1454037f1b8b5503e80f5fd81f12d15302b8a2a7e4e14","frame_index":0,"kind":"data","monotonic_ns":310330210417458,"payload":{"event_type":"price_change","market":"0x779291bef19b6709f61e9764a954aafe9ffae488d50ae674aabdcb4f248006d5","price_changes":[{"asset_id":"8761897749749422724209054078244794145777693856614463256546737399611489089783","best_ask":"0.68","best_bid":"0.67","hash":"18b4c11ce45305250313baf4793c45eb34490d43","price":"0.7","side":"SELL","size":"448.6"},{"asset_id":"14965588658799411272385430903075831224615961675357217884735713260981483529984","best_ask":"0.33","best_bid":"0.32","hash":"5445a8a7c39858d6dc5e23eacf9fb67660d5b839","price":"0.3","side":"BUY","size":"448.6"}],"timestamp":"1785208333383"},"payload_hash":"0ddea4ae40d5a90e6b20327dca3daa1f3cd5d19b148577fc8a31842cf50cb5a4","raw_frame":"{\"market\":\"0x779291bef19b6709f61e9764a954aafe9ffae488d50ae674aabdcb4f248006d5\", \"price_changes\":[{\"asset_id\":\"8761897749749422724209054078244794145777693856614463256546737399611489089783\", \"price\":\"0.7\", \"size\":\"448.6\", \"side\":\"SELL\", \"hash\":\"18b4c11ce45305250313baf4793c45eb34490d43\", \"best_bid\":\"0.67\", \"best_ask\":\"0.68\"}, {\"asset_id\":\"14965588658799411272385430903075831224615961675357217884735713260981483529984\", \"price\":\"0.3\", \"size\":\"448.6\", \"side\":\"BUY\", \"hash\":\"5445a8a7c39858d6dc5e23eacf9fb67660d5b839\", \"best_bid\":\"0.32\", \"best_ask\":\"0.33\"}], \"timestamp\":\"1785208333383\", \"event_type\":\"price_change\"}","received_at":"2026-07-28T03:12:27.175819Z","schema_version":"clob-market-ws.price_change.v1","sequence":null,"server_hash":null,"server_timestamp":"1785208333383","session_id":"3e519d9098404c15b234d96025eb1a2b","source":"clob_market_ws"},"received_at":"2026-07-28T03:12:27.175819Z","record_id":"02b16c762a353b2b2185d45bd3a590b115b9032aa952095c35aba13afec44985","schema_fingerprint":"4aa3821a28b0b7c2400bc59aba4bcc0a76e971dadd19610d3ad38c768e124dc7","schema_version":"edge-lab-recorder.raw.v1","sequence":null,"source":"clob_market_ws"}
{"event_at":"2026-07-28T03:12:13.390000Z","event_fingerprint":"3f13dbdbac821ec86fd0983f8a639a8db7df70b763404c8a14d128327686b9a3","payload":{"connection_id":"a6b55582af5f430fb37ad02bf0922475","event_at":"2026-07-28T03:12:13.390000Z","event_type":"price_change","frame_hash":"5eaf601f3f96c1f8e44ea14c39a286851e7b5b908dfa1faeb488affa8df63723","frame_index":0,"kind":"data","monotonic_ns":310330211921708,"payload":{"event_type":"price_change","market":"0x779291bef19b6709f61e9764a954aafe9ffae488d50ae674aabdcb4f248006d5","price_changes":[{"asset_id":"14965588658799411272385430903075831224615961675357217884735713260981483529984","best_ask":"0.33","best_bid":"0.32","hash":"05ec4d33c72d025feb2dff5d8647aa48325dcfb8","price":"0.3","side":"BUY","size":"460.6"},{"asset_id":"8761897749749422724209054078244794145777693856614463256546737399611489089783","best_ask":"0.68","best_bid":"0.67","hash":"068df20e85ecdbaca05dd6c928a861cd25c51c46","price":"0.7","side":"SELL","size":"460.6"}],"timestamp":"1785208333390"},"payload_hash":"67d4f184a1771045bd6cc02a7913b98551ef78f1b36bcb0333eeb8134a06540e","raw_frame":"{\"market\":\"0x779291bef19b6709f61e9764a954aafe9ffae488d50ae674aabdcb4f248006d5\", \"price_changes\":[{\"asset_id\":\"14965588658799411272385430903075831224615961675357217884735713260981483529984\", \"price\":\"0.3\", \"size\":\"460.6\", \"side\":\"BUY\", \"hash\":\"05ec4d33c72d025feb2dff5d8647aa48325dcfb8\", \"best_bid\":\"0.32\", \"best_ask\":\"0.33\"}, {\"asset_id\":\"8761897749749422724209054078244794145777693856614463256546737399611489089783\", \"price\":\"0.7\", \"size\":\"460.6\", \"side\":\"SELL\", \"hash\":\"068df20e85ecdbaca05dd6c928a861cd25c51c46\", \"best_bid\":\"0.67\", \"best_ask\":\"0.68\"}], \"timestamp\":\"1785208333390\", \"event_type\":\"price_change\"}","received_at":"2026-07-28T03:12:27.177330Z","schema_version":"clob-market-ws.price_change.v1","sequence":null,"server_hash":null,"server_timestamp":"1785208333390","session_id":"3e519d9098404c15b234d96025eb1a2b","source":"clob_market_ws"},"received_at":"2026-07-28T03:12:27.177330Z","record_id":"9856a152639f3f26c6ed45b74bfb860bdfc7c4d9cdffcc2fe7b3718fef0f03f7","schema_fingerprint":"4aa3821a28b0b7c2400bc59aba4bcc0a76e971dadd19610d3ad38c768e124dc7","schema_version":"edge-lab-recorder.raw.v1","sequence":null,"source":"clob_market_ws"}
{"event_at":"2026-07-28T03:12:13.440000Z","event_fingerprint":"a95e773e4b15a077b68634bc00ef34ede65af4173b4388d3546050136e46b2fb","payload":{"connection_id":"a6b55582af5f430fb37ad02bf0922475","event_at":"2026-07-28T03:12:13.440000Z","event_type":"price_change","frame_hash":"585d0a3a6deb1bfbdea6d1f955e4cb7baf210276962ec8c5be3ae6e4d6b64cf1","frame_index":0,"kind":"data","monotonic_ns":310330213393875,"payload":{"event_type":"price_change","market":"0x779291bef19b6709f61e9764a954aafe9ffae488d50ae674aabdcb4f248006d5","price_changes":[{"asset_id":"8761897749749422724209054078244794145777693856614463256546737399611489089783","best_ask":"0.68","best_bid":"0.67","hash":"4288e1a7c0e6ca09b443b24d82036cb6639c9ee5","price":"0.67","side":"BUY","size":"22.6"},{"asset_id":"14965588658799411272385430903075831224615961675357217884735713260981483529984","best_ask":"0.33","best_bid":"0.32","hash":"d6f8a70f9b91c45448b55924a6fd68f6ad45da90","price":"0.33","side":"SELL","size":"22.6"}],"timestamp":"1785208333440"},"payload_hash":"d8fb0a0a38bee70546f1a2270ccf0e2d8ec8b5f036bf4ab5b70f28f2b6f0cc31","raw_frame":"{\"market\":\"0x779291bef19b6709f61e9764a954aafe9ffae488d50ae674aabdcb4f248006d5\", \"price_changes\":[{\"asset_id\":\"8761897749749422724209054078244794145777693856614463256546737399611489089783\", \"price\":\"0.67\", \"size\":\"22.6\", \"side\":\"BUY\", \"hash\":\"4288e1a7c0e6ca09b443b24d82036cb6639c9ee5\", \"best_bid\":\"0.67\", \"best_ask\":\"0.68\"}, {\"asset_id\":\"14965588658799411272385430903075831224615961675357217884735713260981483529984\", \"price\":\"0.33\", \"size\":\"22.6\", \"side\":\"SELL\", \"hash\":\"d6f8a70f9b91c45448b55924a6fd68f6ad45da90\", \"best_bid\":\"0.32\", \"best_ask\":\"0.33\"}], \"timestamp\":\"1785208333440\", \"event_type\":\"price_change\"}","received_at":"2026-07-28T03:12:27.178802Z","schema_version":"clob-market-ws.price_change.v1","sequence":null,"server_hash":null,"server_timestamp":"1785208333440","session_id":"3e519d9098404c15b234d96025eb1a2b","source":"clob_market_ws"},"received_at":"2026-07-28T03:12:27.178802Z","record_id":"ea9916a75102f24ca056b39743d1775295cacf1b33189c40b3b4d8aecbfd7cb3","schema_fingerprint":"4aa3821a28b0b7c2400bc59aba4bcc0a76e971dadd19610d3ad38c768e124dc7","schema_version":"edge-lab-recorder.raw.v1","sequence":null,"source":"clob_market_ws"}
{"event_at":"2026-07-28T03:12:13.465000Z","event_fingerprint":"7bf951699f3ce28905f8eccf8396d1a5700605dd55d3e7d3ad459bf0f243415b","payload":{"connection_id":"a6b55582af5f430fb37ad02bf0922475","event_at":"2026-07-28T03:12:13.465000Z","event_type":"price_change","frame_hash":"6b0221cb05b6ead75909011876739b1b49a9cefd9fdaf70ee4e4351b577fe510","frame_index":0,"kind":"data","monotonic_ns":310330214895791,"payload":{"event_type":"price_change","market":"0x779291bef19b6709f61e9764a954aafe9ffae488d50ae674aabdcb4f248006d5","price_changes":[{"asset_id":"8761897749749422724209054078244794145777693856614463256546737399611489089783","best_ask":"0.68","best_bid":"0.67","hash":"3166c7f1c4762353f641d5c50157fdd03df33296","price":"0.04","side":"BUY","size":"515"},{"asset_id":"14965588658799411272385430903075831224615961675357217884735713260981483529984","best_ask":"0.33","best_bid":"0.32","hash":"cdeed2a238c9bf4899f219d172a73a56c336b995","price":"0.96","side":"SELL","size":"515"}],"timestamp":"1785208333465"},"payload_hash":"69f89e2291b75ed37d825f0ed40da8f484c9f653814ed82afecdb7f0ffc1affd","raw_frame":"{\"market\":\"0x779291bef19b6709f61e9764a954aafe9ffae488d50ae674aabdcb4f248006d5\", \"price_changes\":[{\"asset_id\":\"8761897749749422724209054078244794145777693856614463256546737399611489089783\", \"price\":\"0.04\", \"size\":\"515\", \"side\":\"BUY\", \"hash\":\"3166c7f1c4762353f641d5c50157fdd03df33296\", \"best_bid\":\"0.67\", \"best_ask\":\"0.68\"}, {\"asset_id\":\"14965588658799411272385430903075831224615961675357217884735713260981483529984\", \"price\":\"0.96\", \"size\":\"515\", \"side\":\"SELL\", \"hash\":\"cdeed2a238c9bf4899f219d172a73a56c336b995\", \"best_bid\":\"0.32\", \"best_ask\":\"0.33\"}], \"timestamp\":\"1785208333465\", \"event_type\":\"price_change\"}","received_at":"2026-07-28T03:12:27.180304Z","schema_version":"clob-market-ws.price_change.v1","sequence":null,"server_hash":null,"server_timestamp":"1785208333465","session_id":"3e519d9098404c15b234d96025eb1a2b","source":"clob_market_ws"},"received_at":"2026-07-28T03:12:27.180304Z","record_id":"bc969e86b887746e35c2dca743fe47d45c3413c9d664664e2eaaa4e68cd3e003","schema_fingerprint":"4aa3821a28b0b7c2400bc59aba4bcc0a76e971dadd19610d3ad38c768e124dc7","schema_version":"edge-lab-recorder.raw.v1","sequence":null,"source":"clob_market_ws"}
{"event_at":"2026-07-28T03:12:13.483000Z","event_fingerprint":"a07c313523ef7280dd8a4034c3fdfcd7bbbb36a03dc78e2106bbc5bfcc7fcc7a","payload":{"connection_id":"a6b55582af5f430fb37ad02bf0922475","event_at":"2026-07-28T03:12:13.483000Z","event_type":"price_change","frame_hash":"12f466d2da4e37ecd595868f0a21b3cb4e2295ed36e51e1f326098bb0474ebc8","frame_index":0,"kind":"data","monotonic_ns":310330216364750,"payload":{"event_type":"price_change","market":"0x779291bef19b6709f61e9764a954aafe9ffae488d50ae674aabdcb4f248006d5","price_changes":[{"asset_id":"14965588658799411272385430903075831224615961675357217884735713260981483529984","best_ask":"0.33","best_bid":"0.32","hash":"402f6beddb2f85e374ac6f2b3e76f703b83832fb","price":"0.3","side":"BUY","size":"448.6"},{"asset_id":"8761897749749422724209054078244794145777693856614463256546737399611489089783","best_ask":"0.68","best_bid":"0.67","hash":"1f13546475fc1e6ed3dc5a1dd8b57f52c08eaa45","price":"0.7","side":"SELL","size":"448.6"}],"timestamp":"1785208333483"},"payload_hash":"75419ba86ee876304fcbcb79c9dbdada2c85fa435d39dc152daa686e1d2793b5","raw_frame":"{\"market\":\"0x779291bef19b6709f61e9764a954aafe9ffae488d50ae674aabdcb4f248006d5\", \"price_changes\":[{\"asset_id\":\"14965588658799411272385430903075831224615961675357217884735713260981483529984\", \"price\":\"0.3\", \"size\":\"448.6\", \"side\":\"BUY\", \"hash\":\"402f6beddb2f85e374ac6f2b3e76f703b83832fb\", \"best_bid\":\"0.32\", \"best_ask\":\"0.33\"}, {\"asset_id\":\"8761897749749422724209054078244794145777693856614463256546737399611489089783\", \"price\":\"0.7\", \"size\":\"448.6\", \"side\":\"SELL\", \"hash\":\"1f13546475fc1e6ed3dc5a1dd8b57f52c08eaa45\", \"best_bid\":\"0.67\", \"best_ask\":\"0.68\"}], \"timestamp\":\"1785208333483\", \"event_type\":\"price_change\"}","received_at":"2026-07-28T03:12:27.181773Z","schema_version":"clob-market-ws.price_change.v1","sequence":null,"server_hash":null,"server_timestamp":"1785208333483","session_id":"3e519d9098404c15b234d96025eb1a2b","source":"clob_market_ws"},"received_at":"2026-07-28T03:12:27.181773Z","record_id":"0a280c296ce184a257d0e89a20c4920c87da63847c5150d91235ca0d33b07a19","schema_fingerprint":"4aa3821a28b0b7c2400bc59aba4bcc0a76e971dadd19610d3ad38c768e124dc7","schema_version":"edge-lab-recorder.raw.v1","sequence":null,"source":"clob_market_ws"}
{"event_at":"2026-07-28T03:12:13.486000Z","event_fingerprint":"003da240589308b02c8a54a469cc1825c6f2027817e7dbdc61a9d13ec4fe641a","payload":{"connection_id":"a6b55582af5f430fb37ad02bf0922475","event_at":"2026-07-28T03:12:13.486000Z","event_type":"price_change","frame_hash":"00fd65db3f551ef4b2472fc2c2f0c1099e7111aa1e260d126f03ca0bf0337476","frame_index":0,"kind":"data","monotonic_ns":310330217891375,"payload":{"event_type":"price_change","market":"0x779291bef19b6709f61e9764a954aafe9ffae488d50ae674aabdcb4f248006d5","price_changes":[{"asset_id":"8761897749749422724209054078244794145777693856614463256546737399611489089783","best_ask":"0.68","best_bid":"0.67","hash":"5524fbcb4ca7f5b04fdf08015b16b524c2669a9d","price":"0.7","side":"SELL","size":"460.6"},{"asset_id":"14965588658799411272385430903075831224615961675357217884735713260981483529984","best_ask":"0.33","best_bid":"0.32","hash":"5897bdf2ad848cc62bfca35a2e8a77e17c9e2caa","price":"0.3","side":"BUY","size":"460.6"}],"timestamp":"1785208333486"},"payload_hash":"3bfe2ef217023a8c5c771f3073da4f16540ffe2a7c5e9e0cbf407e8d589ca0e5","raw_frame":"{\"market\":\"0x779291bef19b6709f61e9764a954aafe9ffae488d50ae674aabdcb4f248006d5\", \"price_changes\":[{\"asset_id\":\"8761897749749422724209054078244794145777693856614463256546737399611489089783\", \"price\":\"0.7\", \"size\":\"460.6\", \"side\":\"SELL\", \"hash\":\"5524fbcb4ca7f5b04fdf08015b16b524c2669a9d\", \"best_bid\":\"0.67\", \"best_ask\":\"0.68\"}, {\"asset_id\":\"14965588658799411272385430903075831224615961675357217884735713260981483529984\", \"price\":\"0.3\", \"size\":\"460.6\", \"side\":\"BUY\", \"hash\":\"5897bdf2ad848cc62bfca35a2e8a77e17c9e2caa\", \"best_bid\":\"0.32\", \"best_ask\":\"0.33\"}], \"timestamp\":\"1785208333486\", \"event_type\":\"price_change\"}","received_at":"2026-07-28T03:12:27.183299Z","schema_version":"clob-market-ws.price_change.v1","sequence":null,"server_hash":null,"server_timestamp":"1785208333486","session_id":"3e519d9098404c15b234d96025eb1a2b","source":"clob_market_ws"},"received_at":"2026-07-28T03:12:27.183299Z","record_id":"f60c5316bfbae8cc7da1e0719975763529d4d49195bcfeeb860519bbb28b40be","schema_fingerprint":"4aa3821a28b0b7c2400bc59aba4bcc0a76e971dadd19610d3ad38c768e124dc7","schema_version":"edge-lab-recorder.raw.v1","sequence":null,"source":"clob_market_ws"}
{"event_at":"2026-07-28T03:12:13.496000Z","event_fingerprint":"fe29fdb8170ff2f5a864a91d52be07c73a8b7dde4d0e6fc6c0cf9c34006b32fe","payload":{"connection_id":"a6b55582af5f430fb37ad02bf0922475","event_at":"2026-07-28T03:12:13.496000Z","event_type":"price_change","frame_hash":"04d5f0ffd73e4a236a2f1f679bddc329e9d9af4d3a1511ad764814b9bcd4c8f4","frame_index":0,"kind":"data","monotonic_ns":310330219415750,"payload":{"event_type":"price_change","market":"0x779291bef19b6709f61e9764a954aafe9ffae488d50ae674aabdcb4f248006d5","price_changes":[{"asset_id":"14965588658799411272385430903075831224615961675357217884735713260981483529984","best_ask":"0.33","best_bid":"0.32","hash":"b73c180e6dfb6bdd47de464132e5e81cdf3d1787","price":"0.21","side":"BUY","size":"233"},{"asset_id":"8761897749749422724209054078244794145777693856614463256546737399611489089783","best_ask":"0.68","best_bid":"0.67","hash":"c27f5a3f55b8e89b73bbd6fc9da6d861d8239e48","price":"0.79","side":"SELL","size":"233"}],"timestamp":"1785208333496"},"payload_hash":"41c8f420b904f7eacdb5f7b012d5916f98a80fde7c5f5bf8b66ab1d46f03a079","raw_frame":"{\"market\":\"0x779291bef19b6709f61e9764a954aafe9ffae488d50ae674aabdcb4f248006d5\", \"price_changes\":[{\"asset_id\":\"14965588658799411272385430903075831224615961675357217884735713260981483529984\", \"price\":\"0.21\", \"size\":\"233\", \"side\":\"BUY\", \"hash\":\"b73c180e6dfb6bdd47de464132e5e81cdf3d1787\", \"best_bid\":\"0.32\", \"best_ask\":\"0.33\"}, {\"asset_id\":\"8761897749749422724209054078244794145777693856614463256546737399611489089783\", \"price\":\"0.79\", \"size\":\"233\", \"side\":\"SELL\", \"hash\":\"c27f5a3f55b8e89b73bbd6fc9da6d861d8239e48\", \"best_bid\":\"0.67\", \"best_ask\":\"0.68\"}], \"timestamp\":\"1785208333496\", \"event_type\":\"price_change\"}","received_at":"2026-07-28T03:12:27.184823Z","schema_version":"clob-market-ws.price_change.v1","sequence":null,"server_hash":null,"server_timestamp":"1785208333496","session_id":"3e519d9098404c15b234d96025eb1a2b","source":"clob_market_ws"},"received_at":"2026-07-28T03:12:27.184823Z","record_id":"0aeadb860ee21d4093e3e5f8d581c761ce375cb9df816fbc0b709b91cff72861","schema_fingerprint":"4aa3821a28b0b7c2400bc59aba4bcc0a76e971dadd19610d3ad38c768e124dc7","schema_version":"edge-lab-recorder.raw.v1","sequence":null,"source":"clob_market_ws"}
{"event_at":"2026-07-28T03:12:13.514000Z","event_fingerprint":"cf97d8c0f54585c940d18e1ea1a18952b57e9b2f016edbb7b23c5b26a76538a1","payload":{"connection_id":"a6b55582af5f430fb37ad02bf0922475","event_at":"2026-07-28T03:12:13.514000Z","event_type":"price_change","frame_hash":"1c229542ab546d6caf04184959f4669f0f963976d60f96608d2baa5ed3d4dbb7","frame_index":0,"kind":"data","monotonic_ns":310330220946458,"payload":{"event_type":"price_change","market":"0x779291bef19b6709f61e9764a954aafe9ffae488d50ae674aabdcb4f248006d5","price_changes":[{"asset_id":"14965588658799411272385430903075831224615961675357217884735713260981483529984","best_ask":"0.33","best_bid":"0.32","hash":"8495ad13a73d45bce94397694f78374d99d123ef","price":"0.31","side":"BUY","size":"169"},{"asset_id":"8761897749749422724209054078244794145777693856614463256546737399611489089783","best_ask":"0.68","best_bid":"0.67","hash":"1d418b3622faf8aa80f449c43bbaaaaf5060dbee","price":"0.69","side":"SELL","size":"169"}],"timestamp":"1785208333514"},"payload_hash":"cf696d7c62fec6cada6fa904f471905cdb9a38f2a405dcfeadfad970c066336d","raw_frame":"{\"market\":\"0x779291bef19b6709f61e9764a954aafe9ffae488d50ae674aabdcb4f248006d5\", \"price_changes\":[{\"asset_id\":\"14965588658799411272385430903075831224615961675357217884735713260981483529984\", \"price\":\"0.31\", \"size\":\"169\", \"side\":\"BUY\", \"hash\":\"8495ad13a73d45bce94397694f78374d99d123ef\", \"best_bid\":\"0.32\", \"best_ask\":\"0.33\"}, {\"asset_id\":\"8761897749749422724209054078244794145777693856614463256546737399611489089783\", \"price\":\"0.69\", \"size\":\"169\", \"side\":\"SELL\", \"hash\":\"1d418b3622faf8aa80f449c43bbaaaaf5060dbee\", \"best_bid\":\"0.67\", \"best_ask\":\"0.68\"}], \"timestamp\":\"1785208333514\", \"event_type\":\"price_change\"}","received_at":"2026-07-28T03:12:27.186349Z","schema_version":"clob-market-ws.price_change.v1","sequence":null,"server_hash":null,"server_timestamp":"1785208333514","session_id":"3e519d9098404c15b234d96025eb1a2b","source":"clob_market_ws"},"received_at":"2026-07-28T03:12:27.186349Z","record_id":"0f328a0e8dde289deb2502439ac5724c79111deffd17ac1d6073c66a22b9d60c","schema_fingerprint":"4aa3821a28b0b7c2400bc59aba4bcc0a76e971dadd19610d3ad38c768e124dc7","schema_version":"edge-lab-recorder.raw.v1","sequence":null,"source":"clob_market_ws"}
{"event_at":"2026-07-28T03:12:13.514000Z","event_fingerprint":"713b65b9ab6e4324d17734497e2156ea1b425cfa69c728544c57dc9c604add9d","payload":{"connection_id":"a6b55582af5f430fb37ad02bf0922475","event_at":"2026-07-28T03:12:13.514000Z","event_type":"price_change","frame_hash":"30cb8bbf55436d324c9290d0ed4a5ac94c1fed71cf1554c28aa55f847c9273ba","frame_index":0,"kind":"data","monotonic_ns":310330222440041,"payload":{"event_type":"price_change","market":"0x779291bef19b6709f61e9764a954aafe9ffae488d50ae674aabdcb4f248006d5","price_changes":[{"asset_id":"14965588658799411272385430903075831224615961675357217884735713260981483529984","best_ask":"0.33","best_bid":"0.32","hash":"e37bb5fb155e6e465b3660b773c210f3e8b5e22c","price":"0.3","side":"BUY","size":"364.6"},{"asset_id":"8761897749749422724209054078244794145777693856614463256546737399611489089783","best_ask":"0.68","best_bid":"0.67","hash":"ba6a4e626563d8fd8e2c66ccb2015d7a80503144","price":"0.7","side":"SELL","size":"364.6"}],"timestamp":"1785208333514"},"payload_hash":"7786cc04f30cb0fb0beea2fbd55491c076071efdb41fefeb600322303795fa46","raw_frame":"{\"market\":\"0x779291bef19b6709f61e9764a954aafe9ffae488d50ae674aabdcb4f248006d5\", \"price_changes\":[{\"asset_id\":\"14965588658799411272385430903075831224615961675357217884735713260981483529984\", \"price\":\"0.3\", \"size\":\"364.6\", \"side\":\"BUY\", \"hash\":\"e37bb5fb155e6e465b3660b773c210f3e8b5e22c\", \"best_bid\":\"0.32\", \"best_ask\":\"0.33\"}, {\"asset_id\":\"8761897749749422724209054078244794145777693856614463256546737399611489089783\", \"price\":\"0.7\", \"size\":\"364.6\", \"side\":\"SELL\", \"hash\":\"ba6a4e626563d8fd8e2c66ccb2015d7a80503144\", \"best_bid\":\"0.67\", \"best_ask\":\"0.68\"}], \"timestamp\":\"1785208333514\", \"event_type\":\"price_change\"}","received_at":"2026-07-28T03:12:27.187849Z","schema_version":"clob-market-ws.price_change.v1","sequence":null,"server_hash":null,"server_timestamp":"1785208333514","session_id":"3e519d9098404c15b234d96025eb1a2b","source":"clob_market_ws"},"received_at":"2026-07-28T03:12:27.187849Z","record_id":"e91cc6c96999b6d9e1e8bf1344830163d760e729e811986baec235c586fa69c6","schema_fingerprint":"4aa3821a28b0b7c2400bc59aba4bcc0a76e971dadd19610d3ad38c768e124dc7","schema_version":"edge-lab-recorder.raw.v1","sequence":null,"source":"clob_market_ws"}
{"event_at":"2026-07-28T03:12:13.514000Z","event_fingerprint":"16a44c2983d4ff5ab44e1914202d178612f7c4f53200e0a6f04d7dbb899f4555","payload":{"connection_id":"a6b55582af5f430fb37ad02bf0922475","event_at":"2026-07-28T03:12:13.514000Z","event_type":"price_change","frame_hash":"e8ca19cbd39a140a69470565fa0263168362c6b73a2d6901ef224f250b168f18","frame_index":0,"kind":"data","monotonic_ns":310330223881458,"payload":{"event_type":"price_change","market":"0x779291bef19b6709f61e9764a954aafe9ffae488d50ae674aabdcb4f248006d5","price_changes":[{"asset_id":"14965588658799411272385430903075831224615961675357217884735713260981483529984","best_ask":"0.33","best_bid":"0.32","hash":"80a6edbfc190c789f778bc2328b173249b744e4f","price":"0.3","side":"BUY","size":"94.6"},{"asset_id":"8761897749749422724209054078244794145777693856614463256546737399611489089783","best_ask":"0.68","best_bid":"0.67","hash":"bc64342f056f5e0609414200c0d35b394bef1adf","price":"0.7","side":"SELL","size":"94.6"}],"timestamp":"1785208333514"},"payload_hash":"a5c6fb8b2810b77a91c2ecc9e30d00c270a16d674e44756c66b9aa2fa6030415","raw_frame":"{\"market\":\"0x779291bef19b6709f61e9764a954aafe9ffae488d50ae674aabdcb4f248006d5\", \"price_changes\":[{\"asset_id\":\"14965588658799411272385430903075831224615961675357217884735713260981483529984\", \"price\":\"0.3\", \"size\":\"94.6\", \"side\":\"BUY\", \"hash\":\"80a6edbfc190c789f778bc2328b173249b744e4f\", \"best_bid\":\"0.32\", \"best_ask\":\"0.33\"}, {\"asset_id\":\"8761897749749422724209054078244794145777693856614463256546737399611489089783\", \"price\":\"0.7\", \"size\":\"94.6\", \"side\":\"SELL\", \"hash\":\"bc64342f056f5e0609414200c0d35b394bef1adf\", \"best_bid\":\"0.67\", \"best_ask\":\"0.68\"}], \"timestamp\":\"1785208333514\", \"event_type\":\"price_change\"}","received_at":"2026-07-28T03:12:27.189290Z","schema_version":"clob-market-ws.price_change.v1","sequence":null,"server_hash":null,"server_timestamp":"1785208333514","session_id":"3e519d9098404c15b234d96025eb1a2b","source":"clob_market_ws"},"received_at":"2026-07-28T03:12:27.189290Z","record_id":"4e50e2b81b854b0d56b2cb991eee027450e3ace556d029a8e72d7461f3bc5250","schema_fingerprint":"4aa3821a28b0b7c2400bc59aba4bcc0a76e971dadd19610d3ad38c768e124dc7","schema_version":"edge-lab-recorder.raw.v1","sequence":null,"source":"clob_market_ws"}
{"event_at":"2026-07-28T03:12:13.514000Z","event_fingerprint":"3a775b60bd4637a8d68e4807ef065eedbecc419499209be8da253a3b9aa8536c","payload":{"connection_id":"a6b55582af5f430fb37ad02bf0922475","event_at":"2026-07-28T03:12:13.514000Z","event_type":"price_change","frame_hash":"f123cc8e23b4e5a6a5a434583bd21d89585a8b9edbaecd99e54fbc6702b94003","frame_index":0,"kind":"data","monotonic_ns":310330225358041,"payload":{"event_type":"price_change","market":"0x779291bef19b6709f61e9764a954aafe9ffae488d50ae674aabdcb4f248006d5","price_changes":[{"asset_id":"8761897749749422724209054078244794145777693856614463256546737399611489089783","best_ask":"0.68","best_bid":"0.67","hash":"bc64342f056f5e0609414200c0d35b394bef1adf","price":"0.66","side":"BUY","size":"143.6"},{"asset_id":"14965588658799411272385430903075831224615961675357217884735713260981483529984","best_ask":"0.33","best_bid":"0.32","hash":"80a6edbfc190c789f778bc2328b173249b744e4f","price":"0.34","side":"SELL","size":"143.6"}],"timestamp":"1785208333514"},"payload_hash":"ee915cc1d166730c1b2cec05a73019bc0f44e7cc2718c0656fc4de8c202b3649","raw_frame":"{\"market\":\"0x779291bef19b6709f61e9764a954aafe9ffae488d50ae674aabdcb4f248006d5\", \"price_changes\":[{\"asset_id\":\"8761897749749422724209054078244794145777693856614463256546737399611489089783\", \"price\":\"0.66\", \"size\":\"143.6\", \"side\":\"BUY\", \"hash\":\"bc64342f056f5e0609414200c0d35b394bef1adf\", \"best_bid\":\"0.67\", \"best_ask\":\"0.68\"}, {\"asset_id\":\"14965588658799411272385430903075831224615961675357217884735713260981483529984\", \"price\":\"0.34\", \"size\":\"143.6\", \"side\":\"SELL\", \"hash\":\"80a6edbfc190c789f778bc2328b173249b744e4f\", \"best_bid\":\"0.32\", \"best_ask\":\"0.33\"}], \"timestamp\":\"1785208333514\", \"event_type\":\"price_change\"}","received_at":"2026-07-28T03:12:27.190767Z","schema_version":"clob-market-ws.price_change.v1","sequence":null,"server_hash":null,"server_timestamp":"1785208333514","session_id":"3e519d9098404c15b234d96025eb1a2b","source":"clob_market_ws"},"received_at":"2026-07-28T03:12:27.190767Z","record_id":"a99d058e7e48b64a567f91377e8f006f3265961a2050e34126d9158f59d7d4a2","schema_fingerprint":"4aa3821a28b0b7c2400bc59aba4bcc0a76e971dadd19610d3ad38c768e124dc7","schema_version":"edge-lab-recorder.raw.v1","sequence":null,"source":"clob_market_ws"}
{"event_at":"2026-07-28T03:12:13.516000Z","event_fingerprint":"0dd63d0a17c2f02c4b980270d4e794fbba7316bf3331de5499358a5c70e7819d","payload":{"connection_id":"a6b55582af5f430fb37ad02bf0922475","event_at":"2026-07-28T03:12:13.516000Z","event_type":"price_change","frame_hash":"6386a90553fbc5b52c127aa8d0bef961bf0a7239cd1e3f479758ead2b8456e27","frame_index":0,"kind":"data","monotonic_ns":310330226827500,"payload":{"event_type":"price_change","market":"0x779291bef19b6709f61e9764a954aafe9ffae488d50ae674aabdcb4f248006d5","price_changes":[{"asset_id":"8761897749749422724209054078244794145777693856614463256546737399611489089783","best_ask":"0.68","best_bid":"0.67","hash":"9a0080495ca57f5cbafd5b429a2b28bf89f8229a","price":"0.01","side":"BUY","size":"5305.02"},{"asset_id":"14965588658799411272385430903075831224615961675357217884735713260981483529984","best_ask":"0.33","best_bid":"0.32","hash":"6fdf70f28f885c17f991896d008dc4ee2f4c00c4","price":"0.99","side":"SELL","size":"5305.02"}],"timestamp":"1785208333516"},"payload_hash":"5b4f184441ebb6e9bb44f266062e31a024731ddeba0648944852082f04bbd926","raw_frame":"{\"market\":\"0x779291bef19b6709f61e9764a954aafe9ffae488d50ae674aabdcb4f248006d5\", \"price_changes\":[{\"asset_id\":\"8761897749749422724209054078244794145777693856614463256546737399611489089783\", \"price\":\"0.01\", \"size\":\"5305.02\", \"side\":\"BUY\", \"hash\":\"9a0080495ca57f5cbafd5b429a2b28bf89f8229a\", \"best_bid\":\"0.67\", \"best_ask\":\"0.68\"}, {\"asset_id\":\"14965588658799411272385430903075831224615961675357217884735713260981483529984\", \"price\":\"0.99\", \"size\":\"5305.02\", \"side\":\"SELL\", \"hash\":\"6fdf70f28f885c17f991896d008dc4ee2f4c00c4\", \"best_bid\":\"0.32\", \"best_ask\":\"0.33\"}], \"timestamp\":\"1785208333516\", \"event_type\":\"price_change\"}","received_at":"2026-07-28T03:12:27.192236Z","schema_version":"clob-market-ws.price_change.v1","sequence":null,"server_hash":null,"server_timestamp":"1785208333516","session_id":"3e519d9098404c15b234d96025eb1a2b","source":"clob_market_ws"},"received_at":"2026-07-28T03:12:27.192236Z","record_id":"b23ff400663d11f7c6c6b6e766349000087c64e06d431c30076f74467005f3b2","schema_fingerprint":"4aa3821a28b0b7c2400bc59aba4bcc0a76e971dadd19610d3ad38c768e124dc7","schema_version":"edge-lab-recorder.raw.v1","sequence":null,"source":"clob_market_ws"}
{"event_at":"2026-07-28T03:12:13.516000Z","event_fingerprint":"c2f3d75ee1df423a943f5a06ff0d0186905ce5c1437ad171a6bc5f30c101e3e3","payload":{"connection_id":"a6b55582af5f430fb37ad02bf0922475","event_at":"2026-07-28T03:12:13.516000Z","event_type":"price_change","frame_hash":"154bccf8bcac5d379d912fb23df6a0da759d0e1d0cf3e66c669f33abb936015b","frame_index":0,"kind":"data","monotonic_ns":310330228322666,"payload":{"event_type":"price_change","market":"0x779291bef19b6709f61e9764a954aafe9ffae488d50ae674aabdcb4f248006d5","price_changes":[{"asset_id":"8761897749749422724209054078244794145777693856614463256546737399611489089783","best_ask":"0.68","best_bid":"0.67","hash":"4f605f09b3a8d3ac54520a922631cddced3d18b1","price":"0.67","side":"BUY","size":"10"},{"asset_id":"14965588658799411272385430903075831224615961675357217884735713260981483529984","best_ask":"0.33","best_bid":"0.32","hash":"b6f42b937d1ca262ca336aecb570120aadd6f2dc","price":"0.33","side":"SELL","size":"10"}],"timestamp":"1785208333516"},"payload_hash":"6d8b5270c2ba93c76b861cc781c05861c8316df863d00b121cd128be82c55c7b","raw_frame":"{\"market\":\"0x779291bef19b6709f61e9764a954aafe9ffae488d50ae674aabdcb4f248006d5\", \"price_changes\":[{\"asset_id\":\"8761897749749422724209054078244794145777693856614463256546737399611489089783\", \"price\":\"0.67\", \"size\":\"10\", \"side\":\"BUY\", \"hash\":\"4f605f09b3a8d3ac54520a922631cddced3d18b1\", \"best_bid\":\"0.67\", \"best_ask\":\"0.68\"}, {\"asset_id\":\"14965588658799411272385430903075831224615961675357217884735713260981483529984\", \"price\":\"0.33\", \"size\":\"10\", \"side\":\"SELL\", \"hash\":\"b6f42b937d1ca262ca336aecb570120aadd6f2dc\", \"best_bid\":\"0.32\", \"best_ask\":\"0.33\"}], \"timestamp\":\"1785208333516\", \"event_type\":\"price_change\"}","received_at":"2026-07-28T03:12:27.193731Z","schema_version":"clob-market-ws.price_change.v1","sequence":null,"server_hash":null,"server_timestamp":"1785208333516","session_id":"3e519d9098404c15b234d96025eb1a2b","source":"clob_market_ws"},"received_at":"2026-07-28T03:12:27.193731Z","record_id":"1474b28908f4ce7d488ac32ce94ec4518e94f789376cb304e8f5bbb345015651","schema_fingerprint":"4aa3821a28b0b7c2400bc59aba4bcc0a76e971dadd19610d3ad38c768e124dc7","schema_version":"edge-lab-recorder.raw.v1","sequence":null,"source":"clob_market_ws"}
{"event_at":"2026-07-28T03:12:13.517000Z","event_fingerprint":"9c465c51a97e1b89991c712f8ad8b699d67534fa9683732a57f8778102e166fa","payload":{"connection_id":"a6b55582af5f430fb37ad02bf0922475","event_at":"2026-07-28T03:12:13.517000Z","event_type":"price_change","frame_hash":"97c9d6e2f5e6d8aa10970c28a8253eb415aeb9ec97f4c4b7896215ff2f2c6dff","frame_index":0,"kind":"data","monotonic_ns":310330229827625,"payload":{"event_type":"price_change","market":"0x779291bef19b6709f61e9764a954aafe9ffae488d50ae674aabdcb4f248006d5","price_changes":[{"asset_id":"14965588658799411272385430903075831224615961675357217884735713260981483529984","best_ask":"0.33","best_bid":"0.32","hash":"cb8b2641c67f814c7178ccb4a3d5f3fe015fcdfc","price":"0.31","side":"BUY","size":"439"},{"asset_id":"8761897749749422724209054078244794145777693856614463256546737399611489089783","best_ask":"0.68","best_bid":"0.67","hash":"c3b62dc16f889dccf30fb51b399d5ca829e35f8e","price":"0.69","side":"SELL","size":"439"}],"timestamp":"1785208333517"},"payload_hash":"b8a10c0525380a5dc4ffa9e5ce6ac0ffb0ab099c757555dbb30aba5e0f9b364a","raw_frame":"{\"market\":\"0x779291bef19b6709f61e9764a954aafe9ffae488d50ae674aabdcb4f248006d5\", \"price_changes\":[{\"asset_id\":\"14965588658799411272385430903075831224615961675357217884735713260981483529984\", \"price\":\"0.31\", \"size\":\"439\", \"side\":\"BUY\", \"hash\":\"cb8b2641c67f814c7178ccb4a3d5f3fe015fcdfc\", \"best_bid\":\"0.32\", \"best_ask\":\"0.33\"}, {\"asset_id\":\"8761897749749422724209054078244794145777693856614463256546737399611489089783\", \"price\":\"0.69\", \"size\":\"439\", \"side\":\"SELL\", \"hash\":\"c3b62dc16f889dccf30fb51b399d5ca829e35f8e\", \"best_bid\":\"0.67\", \"best_ask\":\"0.68\"}], \"timestamp\":\"1785208333517\", \"event_type\":\"price_change\"}","received_at":"2026-07-28T03:12:27.195235Z","schema_version":"clob-market-ws.price_change.v1","sequence":null,"server_hash":null,"server_timestamp":"1785208333517","session_id":"3e519d9098404c15b234d96025eb1a2b","source":"clob_market_ws"},"received_at":"2026-07-28T03:12:27.195235Z","record_id":"d4b99f7f86ecd7ab4e5668f8cd58a808f750cbc35e4dcc54f4e0ec4b8c0d6f8d","schema_fingerprint":"4aa3821a28b0b7c2400bc59aba4bcc0a76e971dadd19610d3ad38c768e124dc7","schema_version":"edge-lab-recorder.raw.v1","sequence":null,"source":"clob_market_ws"}
{"event_at":"2026-07-28T03:12:13.523000Z","event_fingerprint":"e63a26e3ea6f73c82084628170efa399001908ec8d3be6f2c4bf275510ca08a3","payload":{"connection_id":"a6b55582af5f430fb37ad02bf0922475","event_at":"2026-07-28T03:12:13.523000Z","event_type":"price_change","frame_hash":"f4f917f2471c6b3d7bfe9097a9b0b4709060c2b8a5b610f3d4eb17312117d9f4","frame_index":0,"kind":"data","monotonic_ns":310330231342291,"payload":{"event_type":"price_change","market":"0x779291bef19b6709f61e9764a954aafe9ffae488d50ae674aabdcb4f248006d5","price_changes":[{"asset_id":"14965588658799411272385430903075831224615961675357217884735713260981483529984","best_ask":"0.33","best_bid":"0.32","hash":"38815ebfb0372859aea9cbf0a9faf0471b1cd016","price":"0.2","side":"BUY","size":"271.11"},{"asset_id":"8761897749749422724209054078244794145777693856614463256546737399611489089783","best_ask":"0.68","best_bid":"0.67","hash":"0371c6a7f7b14959bb91f83d79e08080da3a6074","price":"0.8","side":"SELL","size":"271.11"}],"timestamp":"1785208333523"},"payload_hash":"b16dd73f25594fbffd92e661372657ac8a20c20fadcb1465ec6d3659007cfb7b","raw_frame":"{\"market\":\"0x779291bef19b6709f61e9764a954aafe9ffae488d50ae674aabdcb4f248006d5\", \"price_changes\":[{\"asset_id\":\"14965588658799411272385430903075831224615961675357217884735713260981483529984\", \"price\":\"0.2\", \"size\":\"271.11\", \"side\":\"BUY\", \"hash\":\"38815ebfb0372859aea9cbf0a9faf0471b1cd016\", \"best_bid\":\"0.32\", \"best_ask\":\"0.33\"}, {\"asset_id\":\"8761897749749422724209054078244794145777693856614463256546737399611489089783\", \"price\":\"0.8\", \"size\":\"271.11\", \"side\":\"SELL\", \"hash\":\"0371c6a7f7b14959bb91f83d79e08080da3a6074\", \"best_bid\":\"0.67\", \"best_ask\":\"0.68\"}], \"timestamp\":\"1785208333523\", \"event_type\":\"price_change\"}","received_at":"2026-07-28T03:12:27.196750Z","schema_version":"clob-market-ws.price_change.v1","sequence":null,"server_hash":null,"server_timestamp":"1785208333523","session_id":"3e519d9098404c15b234d96025eb1a2b","source":"clob_market_ws"},"received_at":"2026-07-28T03:12:27.196750Z","record_id":"943ae6fa80995fe5ef04c34d61591fb8013b9f541251e4e1a1ed79a109da699a","schema_fingerprint":"4aa3821a28b0b7c2400bc59aba4bcc0a76e971dadd19610d3ad38c768e124dc7","schema_version":"edge-lab-recorder.raw.v1","sequence":null,"source":"clob_market_ws"}
{"event_at":"2026-07-28T03:12:13.528000Z","event_fingerprint":"0542522654ce3f699e90a5ac131c70c68f35211a78a04ac22a2367a5e86c2169","payload":{"connection_id":"a6b55582af5f430fb37ad02bf0922475","event_at":"2026-07-28T03:12:13.528000Z","event_type":"price_change","frame_hash":"72c7cdfc44729ebd19a41a96e20b1e94d2f61403c4f6234a37e3a693787f4d62","frame_index":0,"kind":"data","monotonic_ns":310330232845541,"payload":{"event_type":"price_change","market":"0x779291bef19b6709f61e9764a954aafe9ffae488d50ae674aabdcb4f248006d5","price_changes":[{"asset_id":"8761897749749422724209054078244794145777693856614463256546737399611489089783","best_ask":"0.68","best_bid":"0.67","hash":"340d3e7c2cba9f56d49da44ecae50be3c1f9b1b1","price":"0.04","side":"BUY","size":"510"},{"asset_id":"14965588658799411272385430903075831224615961675357217884735713260981483529984","best_ask":"0.33","best_bid":"0.32","hash":"30cd087841e6e92f760d93654c9546763559f0aa","price":"0.96","side":"SELL","size":"510"}],"timestamp":"1785208333528"},"payload_hash":"752b392e6913d8be416dd4e30b521c70f92b7b8f883ecce9694e3e185fba35d8","raw_frame":"{\"market\":\"0x779291bef19b6709f61e9764a954aafe9ffae488d50ae674aabdcb4f248006d5\", \"price_changes\":[{\"asset_id\":\"8761897749749422724209054078244794145777693856614463256546737399611489089783\", \"price\":\"0.04\", \"size\":\"510\", \"side\":\"BUY\", \"hash\":\"340d3e7c2cba9f56d49da44ecae50be3c1f9b1b1\", \"best_bid\":\"0.67\", \"best_ask\":\"0.68\"}, {\"asset_id\":\"14965588658799411272385430903075831224615961675357217884735713260981483529984\", \"price\":\"0.96\", \"size\":\"510\", \"side\":\"SELL\", \"hash\":\"30cd087841e6e92f760d93654c9546763559f0aa\", \"best_bid\":\"0.32\", \"best_ask\":\"0.33\"}], \"timestamp\":\"1785208333528\", \"event_type\":\"price_change\"}","received_at":"2026-07-28T03:12:27.198254Z","schema_version":"clob-market-ws.price_change.v1","sequence":null,"server_hash":null,"server_timestamp":"1785208333528","session_id":"3e519d9098404c15b234d96025eb1a2b","source":"clob_market_ws"},"received_at":"2026-07-28T03:12:27.198254Z","record_id":"ac45e63ab68b32398c345719cd72380f8991e2d943eb21c5d9e45ae9474bd9cf","schema_fingerprint":"4aa3821a28b0b7c2400bc59aba4bcc0a76e971dadd19610d3ad38c768e124dc7","schema_version":"edge-lab-recorder.raw.v1","sequence":null,"source":"clob_market_ws"}
{"event_at":"2026-07-28T03:12:13.538000Z","event_fingerprint":"5894ff70bdd99eb904614821bf2f826cbccc09da1c6e7fcdf49a8d8a7f803b05","payload":{"connection_id":"a6b55582af5f430fb37ad02bf0922475","event_at":"2026-07-28T03:12:13.538000Z","event_type":"price_change","frame_hash":"02f55b30a321c7540c5af7c44e6e7481142662919a6c83f474947663dde34fae","frame_index":0,"kind":"data","monotonic_ns":310330234319875,"payload":{"event_type":"price_change","market":"0x779291bef19b6709f61e9764a954aafe9ffae488d50ae674aabdcb4f248006d5","price_changes":[{"asset_id":"8761897749749422724209054078244794145777693856614463256546737399611489089783","best_ask":"0.68","best_bid":"0.67","hash":"983f43efb570653ad478f34a542304a5d4144907","price":"0.01","side":"BUY","size":"5300.02"},{"asset_id":"14965588658799411272385430903075831224615961675357217884735713260981483529984","best_ask":"0.33","best_bid":"0.32","hash":"61652d53d89fd320f360302ac700a474ac10d2cd","price":"0.99","side":"SELL","size":"5300.02"}],"timestamp":"1785208333538"},"payload_hash":"14fcb912a578b074a31ebd7ba892000cf3826842c033314f2de38a9d48f7e53b","raw_frame":"{\"market\":\"0x779291bef19b6709f61e9764a954aafe9ffae488d50ae674aabdcb4f248006d5\", \"price_changes\":[{\"asset_id\":\"8761897749749422724209054078244794145777693856614463256546737399611489089783\", \"price\":\"0.01\", \"size\":\"5300.02\", \"side\":\"BUY\", \"hash\":\"983f43efb570653ad478f34a542304a5d4144907\", \"best_bid\":\"0.67\", \"best_ask\":\"0.68\"}, {\"asset_id\":\"14965588658799411272385430903075831224615961675357217884735713260981483529984\", \"price\":\"0.99\", \"size\":\"5300.02\", \"side\":\"SELL\", \"hash\":\"61652d53d89fd320f360302ac700a474ac10d2cd\", \"best_bid\":\"0.32\", \"best_ask\":\"0.33\"}], \"timestamp\":\"1785208333538\", \"event_type\":\"price_change\"}","received_at":"2026-07-28T03:12:27.199728Z","schema_version":"clob-market-ws.price_change.v1","sequence":null,"server_hash":null,"server_timestamp":"1785208333538","session_id":"3e519d9098404c15b234d96025eb1a2b","source":"clob_market_ws"},"received_at":"2026-07-28T03:12:27.199728Z","record_id":"6148555a1defcfc9398b340311001ebeb051967734098f9506dabdf62cdedbc4","schema_fingerprint":"4aa3821a28b0b7c2400bc59aba4bcc0a76e971dadd19610d3ad38c768e124dc7","schema_version":"edge-lab-recorder.raw.v1","sequence":null,"source":"clob_market_ws"}
{"event_at":"2026-07-28T03:12:13.586000Z","event_fingerprint":"2e1e41de9b5605e7d9b7a0433c31a86ceaaff9d5468b3751993b7c17f7e9d5b6","payload":{"connection_id":"a6b55582af5f430fb37ad02bf0922475","event_at":"2026-07-28T03:12:13.586000Z","event_type":"price_change","frame_hash":"5d360a47175459fdfaae6d703381117696c59e3fe31815c1d137cfeff132d6f9","frame_index":0,"kind":"data","monotonic_ns":310330235820041,"payload":{"event_type":"price_change","market":"0x779291bef19b6709f61e9764a954aafe9ffae488d50ae674aabdcb4f248006d5","price_changes":[{"asset_id":"8761897749749422724209054078244794145777693856614463256546737399611489089783","best_ask":"0.68","best_bid":"0.67","hash":"986b4c1487d1a8efb1f43df0863c609a44591020","price":"0.69","side":"SELL","size":"414"},{"asset_id":"14965588658799411272385430903075831224615961675357217884735713260981483529984","best_ask":"0.33","best_bid":"0.32","hash":"12dbeeb2f182a721dbd5c582f43c1b6bdcaf7818","price":"0.31","side":"BUY","size":"414"}],"timestamp":"1785208333586"},"payload_hash":"1bbccc21e5e6df7a75835394e5d6aa84bc903070f3b4e1bf32c1aed149e5ff94","raw_frame":"{\"market\":\"0x779291bef19b6709f61e9764a954aafe9ffae488d50ae674aabdcb4f248006d5\", \"price_changes\":[{\"asset_id\":\"8761897749749422724209054078244794145777693856614463256546737399611489089783\", \"price\":\"0.69\", \"size\":\"414\", \"side\":\"SELL\", \"hash\":\"986b4c1487d1a8efb1f43df0863c609a44591020\", \"best_bid\":\"0.67\", \"best_ask\":\"0.68\"}, {\"asset_id\":\"14965588658799411272385430903075831224615961675357217884735713260981483529984\", \"price\":\"0.31\", \"size\":\"414\", \"side\":\"BUY\", \"hash\":\"12dbeeb2f182a721dbd5c582f43c1b6bdcaf7818\", \"best_bid\":\"0.32\", \"best_ask\":\"0.33\"}], \"timestamp\":\"1785208333586\", \"event_type\":\"price_change\"}","received_at":"2026-07-28T03:12:27.201229Z","schema_version":"clob-market-ws.price_change.v1","sequence":null,"server_hash":null,"server_timestamp":"1785208333586","session_id":"3e519d9098404c15b234d96025eb1a2b","source":"clob_market_ws"},"received_at":"2026-07-28T03:12:27.201229Z","record_id":"c9a4999abf74dcd3d962166788c01e160cd7be6e482eb5b27361fdd629eff8cb","schema_fingerprint":"4aa3821a28b0b7c2400bc59aba4bcc0a76e971dadd19610d3ad38c768e124dc7","schema_version":"edge-lab-recorder.raw.v1","sequence":null,"source":"clob_market_ws"}
{"event_at":"2026-07-28T03:12:13.588000Z","event_fingerprint":"2cf82e1f19cb5c661973e83298a60ecf9be7e60bf28427905d9aa88e22816321","payload":{"connection_id":"a6b55582af5f430fb37ad02bf0922475","event_at":"2026-07-28T03:12:13.588000Z","event_type":"price_change","frame_hash":"c7e5b7666f4861952f4f98fd13cfc2f84c4e2f47b7bf656cdd7f7f24b3c6a10b","frame_index":0,"kind":"data","monotonic_ns":310330237291375,"payload":{"event_type":"price_change","market":"0x779291bef19b6709f61e9764a954aafe9ffae488d50ae674aabdcb4f248006d5","price_changes":[{"asset_id":"8761897749749422724209054078244794145777693856614463256546737399611489089783","best_ask":"0.68","best_bid":"0.67","hash":"1598a26a01837503f4fd6b10895b412bfda74b63","price":"0.64","side":"BUY","size":"51"},{"asset_id":"14965588658799411272385430903075831224615961675357217884735713260981483529984","best_ask":"0.33","best_bid":"0.32","hash":"5b2254b64306b3e91cba6ffcf3340a62d759e8a1","price":"0.36","side":"SELL","size":"51"}],"timestamp":"1785208333588"},"payload_hash":"d5b7bcf557f720e3f4049b375daf92e39b9d178007020a10f4c4da6305b5aad0","raw_frame":"{\"market\":\"0x779291bef19b6709f61e9764a954aafe9ffae488d50ae674aabdcb4f248006d5\", \"price_changes\":[{\"asset_id\":\"8761897749749422724209054078244794145777693856614463256546737399611489089783\", \"price\":\"0.64\", \"size\":\"51\", \"side\":\"BUY\", \"hash\":\"1598a26a01837503f4fd6b10895b412bfda74b63\", \"best_bid\":\"0.67\", \"best_ask\":\"0.68\"}, {\"asset_id\":\"14965588658799411272385430903075831224615961675357217884735713260981483529984\", \"price\":\"0.36\", \"size\":\"51\", \"side\":\"SELL\", \"hash\":\"5b2254b64306b3e91cba6ffcf3340a62d759e8a1\", \"best_bid\":\"0.32\", \"best_ask\":\"0.33\"}], \"timestamp\":\"1785208333588\", \"event_type\":\"price_change\"}","received_at":"2026-07-28T03:12:27.202699Z","schema_version":"clob-market-ws.price_change.v1","sequence":null,"server_hash":null,"server_timestamp":"1785208333588","session_id":"3e519d9098404c15b234d96025eb1a2b","source":"clob_market_ws"},"received_at":"2026-07-28T03:12:27.202699Z","record_id":"c68e123487481e63564bfa0870673596a150290a8db668614828b1f4c94f0db3","schema_fingerprint":"4aa3821a28b0b7c2400bc59aba4bcc0a76e971dadd19610d3ad38c768e124dc7","schema_version":"edge-lab-recorder.raw.v1","sequence":null,"source":"clob_market_ws"}
{"event_at":"2026-07-28T03:12:13.590000Z","event_fingerprint":"757554d04456e84fdf84c9afbe59775370c38323d6e3ffb83412112d69703ab0","payload":{"connection_id":"a6b55582af5f430fb37ad02bf0922475","event_at":"2026-07-28T03:12:13.590000Z","event_type":"price_change","frame_hash":"c0d6e66b61076c6a5118d2a5eb00ab08edf3ddefa626c42f4ed4621b49143fbf","frame_index":0,"kind":"data","monotonic_ns":310330238777375,"payload":{"event_type":"price_change","market":"0x779291bef19b6709f61e9764a954aafe9ffae488d50ae674aabdcb4f248006d5","price_changes":[{"asset_id":"14965588658799411272385430903075831224615961675357217884735713260981483529984","best_ask":"0.33","best_bid":"0.32","hash":"35bbac3528c5dc80e0dbd3e068c8801b28fb3177","price":"0.31","side":"BUY","size":"389"},{"asset_id":"8761897749749422724209054078244794145777693856614463256546737399611489089783","best_ask":"0.68","best_bid":"0.67","hash":"0d695256a604bf7861491f21eb5d2b3167c2991a","price":"0.69","side":"SELL","size":"389"}],"timestamp":"1785208333590"},"payload_hash":"43d4eaab203068d21059387b83523eab93d99a72f0dec23faa3fa039d7fbdcd0","raw_frame":"{\"market\":\"0x779291bef19b6709f61e9764a954aafe9ffae488d50ae674aabdcb4f248006d5\", \"price_changes\":[{\"asset_id\":\"14965588658799411272385430903075831224615961675357217884735713260981483529984\", \"price\":\"0.31\", \"size\":\"389\", \"side\":\"BUY\", \"hash\":\"35bbac3528c5dc80e0dbd3e068c8801b28fb3177\", \"best_bid\":\"0.32\", \"best_ask\":\"0.33\"}, {\"asset_id\":\"8761897749749422724209054078244794145777693856614463256546737399611489089783\", \"price\":\"0.69\", \"size\":\"389\", \"side\":\"SELL\", \"hash\":\"0d695256a604bf7861491f21eb5d2b3167c2991a\", \"best_bid\":\"0.67\", \"best_ask\":\"0.68\"}], \"timestamp\":\"1785208333590\", \"event_type\":\"price_change\"}","received_at":"2026-07-28T03:12:27.204186Z","schema_version":"clob-market-ws.price_change.v1","sequence":null,"server_hash":null,"server_timestamp":"1785208333590","session_id":"3e519d9098404c15b234d96025eb1a2b","source":"clob_market_ws"},"received_at":"2026-07-28T03:12:27.204186Z","record_id":"c77d18fba53f2fca51cc7032b3037228be887bbf3af381e1dc3608530beb2669","schema_fingerprint":"4aa3821a28b0b7c2400bc59aba4bcc0a76e971dadd19610d3ad38c768e124dc7","schema_version":"edge-lab-recorder.raw.v1","sequence":null,"source":"clob_market_ws"}
{"event_at":"2026-07-28T03:12:13.601000Z","event_fingerprint":"3e173c12e26ea8e6ad53d2995a628cf4ba49f936e2115fc762aca474844f9bf0","payload":{"connection_id":"a6b55582af5f430fb37ad02bf0922475","event_at":"2026-07-28T03:12:13.601000Z","event_type":"price_change","frame_hash":"d6752f7ba07693631e33745d51d24229e3c7c97f4436df5780c1c2b827602ffc","frame_index":0,"kind":"data","monotonic_ns":310330240242916,"payload":{"event_type":"price_change","market":"0x779291bef19b6709f61e9764a954aafe9ffae488d50ae674aabdcb4f248006d5","price_changes":[{"asset_id":"8761897749749422724209054078244794145777693856614463256546737399611489089783","best_ask":"0.68","best_bid":"0.67","hash":"7396cbbb27889cbe457ce1295eb8d931b33da671","price":"0.7","side":"SELL","size":"82.6"},{"asset_id":"14965588658799411272385430903075831224615961675357217884735713260981483529984","best_ask":"0.33","best_bid":"0.32","hash":"94fba907c1c21949911b75cd5de54972d2d5fd2b","price":"0.3","side":"BUY","size":"82.6"}],"timestamp":"1785208333601"},"payload_hash":"0b6cab2cf1b77883df2b64f99fcb5603c1d57701e10add1dbdf5c660bed722a9","raw_frame":"{\"market\":\"0x779291bef19b6709f61e9764a954aafe9ffae488d50ae674aabdcb4f248006d5\", \"price_changes\":[{\"asset_id\":\"8761897749749422724209054078244794145777693856614463256546737399611489089783\", \"price\":\"0.7\", \"size\":\"82.6\", \"side\":\"SELL\", \"hash\":\"7396cbbb27889cbe457ce1295eb8d931b33da671\", \"best_bid\":\"0.67\", \"best_ask\":\"0.68\"}, {\"asset_id\":\"14965588658799411272385430903075831224615961675357217884735713260981483529984\", \"price\":\"0.3\", \"size\":\"82.6\", \"side\":\"BUY\", \"hash\":\"94fba907c1c21949911b75cd5de54972d2d5fd2b\", \"best_bid\":\"0.32\", \"best_ask\":\"0.33\"}], \"timestamp\":\"1785208333601\", \"event_type\":\"price_change\"}","received_at":"2026-07-28T03:12:27.205651Z","schema_version":"clob-market-ws.price_change.v1","sequence":null,"server_hash":null,"server_timestamp":"1785208333601","session_id":"3e519d9098404c15b234d96025eb1a2b","source":"clob_market_ws"},"received_at":"2026-07-28T03:12:27.205651Z","record_id":"cc5c457d535085cd727c7136c7de6d459b82b4979b5cdbb384eab033d31f0f36","schema_fingerprint":"4aa3821a28b0b7c2400bc59aba4bcc0a76e971dadd19610d3ad38c768e124dc7","schema_version":"edge-lab-recorder.raw.v1","sequence":null,"source":"clob_market_ws"}
{"event_at":"2026-07-28T03:12:13.609000Z","event_fingerprint":"afef2c8b7ad22100e72a82261589a465310f7712118a9828bf9bace4723d1780","payload":{"connection_id":"a6b55582af5f430fb37ad02bf0922475","event_at":"2026-07-28T03:12:13.609000Z","event_type":"price_change","frame_hash":"73d5cdfa84157af9c1f2cd3e83e976d731bf36e8e2d6cc2ec2e5273570418b53","frame_index":0,"kind":"data","monotonic_ns":310330241726333,"payload":{"event_type":"price_change","market":"0x779291bef19b6709f61e9764a954aafe9ffae488d50ae674aabdcb4f248006d5","price_changes":[{"asset_id":"14965588658799411272385430903075831224615961675357217884735713260981483529984","best_ask":"0.33","best_bid":"0.32","hash":"078b492c216e8b8710bd36c916f04ae22984881a","price":"0.3","side":"BUY","size":"94.6"},{"asset_id":"8761897749749422724209054078244794145777693856614463256546737399611489089783","best_ask":"0.68","best_bid":"0.67","hash":"75e446318cd9a7532e7a804aac75f23118b7ef68","price":"0.7","side":"SELL","size":"94.6"}],"timestamp":"1785208333609"},"payload_hash":"4c53be54a2cfed416c9038f720d3274034fa8cd7d690d8192f7354636869b495","raw_frame":"{\"market\":\"0x779291bef19b6709f61e9764a954aafe9ffae488d50ae674aabdcb4f248006d5\", \"price_changes\":[{\"asset_id\":\"14965588658799411272385430903075831224615961675357217884735713260981483529984\", \"price\":\"0.3\", \"size\":\"94.6\", \"side\":\"BUY\", \"hash\":\"078b492c216e8b8710bd36c916f04ae22984881a\", \"best_bid\":\"0.32\", \"best_ask\":\"0.33\"}, {\"asset_id\":\"8761897749749422724209054078244794145777693856614463256546737399611489089783\", \"price\":\"0.7\", \"size\":\"94.6\", \"side\":\"SELL\", \"hash\":\"75e446318cd9a7532e7a804aac75f23118b7ef68\", \"best_bid\":\"0.67\", \"best_ask\":\"0.68\"}], \"timestamp\":\"1785208333609\", \"event_type\":\"price_change\"}","received_at":"2026-07-28T03:12:27.207135Z","schema_version":"clob-market-ws.price_change.v1","sequence":null,"server_hash":null,"server_timestamp":"1785208333609","session_id":"3e519d9098404c15b234d96025eb1a2b","source":"clob_market_ws"},"received_at":"2026-07-28T03:12:27.207135Z","record_id":"897744e2962218990d29b65f27a0e72c47c1c6730e499bd662d7ebbffa1b82b6","schema_fingerprint":"4aa3821a28b0b7c2400bc59aba4bcc0a76e971dadd19610d3ad38c768e124dc7","schema_version":"edge-lab-recorder.raw.v1","sequence":null,"source":"clob_market_ws"}
{"event_at":"2026-07-28T03:12:13.610000Z","event_fingerprint":"de9f402e3a8ea22ad82caf27980f218c9af609976ea63a1f42a3927cfa2a4a4d","payload":{"connection_id":"a6b55582af5f430fb37ad02bf0922475","event_at":"2026-07-28T03:12:13.610000Z","event_type":"price_change","frame_hash":"fa017313b2ee8755c8ff5516f6848c2d7fba1c8dab1577196f4ea751aa972680","frame_index":0,"kind":"data","monotonic_ns":310330243226333,"payload":{"event_type":"price_change","market":"0x779291bef19b6709f61e9764a954aafe9ffae488d50ae674aabdcb4f248006d5","price_changes":[{"asset_id":"8761897749749422724209054078244794145777693856614463256546737399611489089783","best_ask":"0.68","best_bid":"0.67","hash":"eb1045e84c56b29a5914e4c494ecce4b5903712b","price":"0.04","side":"BUY","size":"515"},{"asset_id":"14965588658799411272385430903075831224615961675357217884735713260981483529984","best_ask":"0.33","best_bid":"0.32","hash":"0612a18d4f785e3821f2babcc5c8ad9fc4b9298e","price":"0.96","side":"SELL","size":"515"}],"timestamp":"1785208333610"},"payload_hash":"341b258b713328e5578fc112b7a5024416385dbab40aedf4fbc810c62d901c9b","raw_frame":"{\"market\":\"0x779291bef19b6709f61e9764a954aafe9ffae488d50ae674aabdcb4f248006d5\", \"price_changes\":[{\"asset_id\":\"8761897749749422724209054078244794145777693856614463256546737399611489089783\", \"price\":\"0.04\", \"size\":\"515\", \"side\":\"BUY\", \"hash\":\"eb1045e84c56b29a5914e4c494ecce4b5903712b\", \"best_bid\":\"0.67\", \"best_ask\":\"0.68\"}, {\"asset_id\":\"14965588658799411272385430903075831224615961675357217884735713260981483529984\", \"price\":\"0.96\", \"size\":\"515\", \"side\":\"SELL\", \"hash\":\"0612a18d4f785e3821f2babcc5c8ad9fc4b9298e\", \"best_bid\":\"0.32\", \"best_ask\":\"0.33\"}], \"timestamp\":\"1785208333610\", \"event_type\":\"price_change\"}","received_at":"2026-07-28T03:12:27.208635Z","schema_version":"clob-market-ws.price_change.v1","sequence":null,"server_hash":null,"server_timestamp":"1785208333610","session_id":"3e519d9098404c15b234d96025eb1a2b","source":"clob_market_ws"},"received_at":"2026-07-28T03:12:27.208635Z","record_id":"8ca25946a4967264b5f1a1f82c700f52b388982565352497fbcd5f29f110f71c","schema_fingerprint":"4aa3821a28b0b7c2400bc59aba4bcc0a76e971dadd19610d3ad38c768e124dc7","schema_version":"edge-lab-recorder.raw.v1","sequence":null,"source":"clob_market_ws"}
{"event_at":"2026-07-28T03:12:13.612000Z","event_fingerprint":"5f9c667468c1388bc375c84b9e0de26831e75232dbb0f7230366d38a27892110","payload":{"connection_id":"a6b55582af5f430fb37ad02bf0922475","event_at":"2026-07-28T03:12:13.612000Z","event_type":"price_change","frame_hash":"f39644b03c82f2126e7f539a77813140f90e2c8ff81f4cc23794107347dcb926","frame_index":0,"kind":"data","monotonic_ns":310330244702416,"payload":{"event_type":"price_change","market":"0x779291bef19b6709f61e9764a954aafe9ffae488d50ae674aabdcb4f248006d5","price_changes":[{"asset_id":"8761897749749422724209054078244794145777693856614463256546737399611489089783","best_ask":"0.68","best_bid":"0.67","hash":"9b92d272942e5250eb83fc4ca6367e5e1afa2dd8","price":"0.68","side":"SELL","size":"52"},{"asset_id":"14965588658799411272385430903075831224615961675357217884735713260981483529984","best_ask":"0.33","best_bid":"0.32","hash":"6bc3b8af2e08c9afc4cbc405120d025a2c78b657","price":"0.32","side":"BUY","size":"52"}],"timestamp":"1785208333612"},"payload_hash":"9cc36c6ae21e30d41396ee5a2e2bfe4aaa5cbaf3dce1408fee3555675d30c04b","raw_frame":"{\"market\":\"0x779291bef19b6709f61e9764a954aafe9ffae488d50ae674aabdcb4f248006d5\", \"price_changes\":[{\"asset_id\":\"8761897749749422724209054078244794145777693856614463256546737399611489089783\", \"price\":\"0.68\", \"size\":\"52\", \"side\":\"SELL\", \"hash\":\"9b92d272942e5250eb83fc4ca6367e5e1afa2dd8\", \"best_bid\":\"0.67\", \"best_ask\":\"0.68\"}, {\"asset_id\":\"14965588658799411272385430903075831224615961675357217884735713260981483529984\", \"price\":\"0.32\", \"size\":\"52\", \"side\":\"BUY\", \"hash\":\"6bc3b8af2e08c9afc4cbc405120d025a2c78b657\", \"best_bid\":\"0.32\", \"best_ask\":\"0.33\"}], \"timestamp\":\"1785208333612\", \"event_type\":\"price_change\"}","received_at":"2026-07-28T03:12:27.210111Z","schema_version":"clob-market-ws.price_change.v1","sequence":null,"server_hash":null,"server_timestamp":"1785208333612","session_id":"3e519d9098404c15b234d96025eb1a2b","source":"clob_market_ws"},"received_at":"2026-07-28T03:12:27.210111Z","record_id":"81b4953e6aa3695a12a1aab794f4acf5b367888d635801d3d9b879803759633b","schema_fingerprint":"4aa3821a28b0b7c2400bc59aba4bcc0a76e971dadd19610d3ad38c768e124dc7","schema_version":"edge-lab-recorder.raw.v1","sequence":null,"source":"clob_market_ws"}
{"event_at":"2026-07-28T03:12:13.614000Z","event_fingerprint":"8df4b6e2dede0b06cd91228ae7fbf4f160ac1969648b9bd7e0c959d142e53674","payload":{"connection_id":"a6b55582af5f430fb37ad02bf0922475","event_at":"2026-07-28T03:12:13.614000Z","event_type":"price_change","frame_hash":"611cc8c0309741457a18dc413efd76d1e64c915b861a2b8d5416cd59a05f3764","frame_index":0,"kind":"data","monotonic_ns":310330246203708,"payload":{"event_type":"price_change","market":"0x779291bef19b6709f61e9764a954aafe9ffae488d50ae674aabdcb4f248006d5","price_changes":[{"asset_id":"14965588658799411272385430903075831224615961675357217884735713260981483529984","best_ask":"0.33","best_bid":"0.32","hash":"ecf99fecbba926df739e43472fab61efb065733f","price":"0.32","side":"BUY","size":"77"},{"asset_id":"8761897749749422724209054078244794145777693856614463256546737399611489089783","best_ask":"0.68","best_bid":"0.67","hash":"6c76bc2eed477ca701bc3cce4bd2006157dca008","price":"0.68","side":"SELL","size":"77"}],"timestamp":"1785208333614"},"payload_hash":"e773121645715bc5e654bfc0ec3daadf652cb2c3e0d69a87bf8c74baa4503f7c","raw_frame":"{\"market\":\"0x779291bef19b6709f61e9764a954aafe9ffae488d50ae674aabdcb4f248006d5\", \"price_changes\":[{\"asset_id\":\"14965588658799411272385430903075831224615961675357217884735713260981483529984\", \"price\":\"0.32\", \"size\":\"77\", \"side\":\"BUY\", \"hash\":\"ecf99fecbba926df739e43472fab61efb065733f\", \"best_bid\":\"0.32\", \"best_ask\":\"0.33\"}, {\"asset_id\":\"8761897749749422724209054078244794145777693856614463256546737399611489089783\", \"price\":\"0.68\", \"size\":\"77\", \"side\":\"SELL\", \"hash\":\"6c76bc2eed477ca701bc3cce4bd2006157dca008\", \"best_bid\":\"0.67\", \"best_ask\":\"0.68\"}], \"timestamp\":\"1785208333614\", \"event_type\":\"price_change\"}","received_at":"2026-07-28T03:12:27.211612Z","schema_version":"clob-market-ws.price_change.v1","sequence":null,"server_hash":null,"server_timestamp":"1785208333614","session_id":"3e519d9098404c15b234d96025eb1a2b","source":"clob_market_ws"},"received_at":"2026-07-28T03:12:27.211612Z","record_id":"f07d9144d64696b8ef77202d91c72d8fdeae41f0c70b655be5d862785100d5b6","schema_fingerprint":"4aa3821a28b0b7c2400bc59aba4bcc0a76e971dadd19610d3ad38c768e124dc7","schema_version":"edge-lab-recorder.raw.v1","sequence":null,"source":"clob_market_ws"}
{"event_at":"2026-07-28T03:12:13.617000Z","event_fingerprint":"75b3ad0478d0cfc2a6585e8598e2e9b0baa8bec7f5f7794f664833cb91446064","payload":{"connection_id":"a6b55582af5f430fb37ad02bf0922475","event_at":"2026-07-28T03:12:13.617000Z","event_type":"price_change","frame_hash":"7b978c958175f809ed94a75a58641b5c1eb670b9eb64e8eabf8eaeeeeb6c0267","frame_index":0,"kind":"data","monotonic_ns":310330247713583,"payload":{"event_type":"price_change","market":"0x779291bef19b6709f61e9764a954aafe9ffae488d50ae674aabdcb4f248006d5","price_changes":[{"asset_id":"8761897749749422724209054078244794145777693856614463256546737399611489089783","best_ask":"0.68","best_bid":"0.67","hash":"70027c6852b9fd7b96f6dc75f861e628fd8b5f70","price":"0.63","side":"BUY","size":"87"},{"asset_id":"14965588658799411272385430903075831224615961675357217884735713260981483529984","best_ask":"0.33","best_bid":"0.32","hash":"0791b99d2e410f91328c0c7f9f5724562a644a98","price":"0.37","side":"SELL","size":"87"}],"timestamp":"1785208333617"},"payload_hash":"3d5c7fea25d16dba46895cd16f07a70036262d8f7cfcbfccbaca6125b48dc0a9","raw_frame":"{\"market\":\"0x779291bef19b6709f61e9764a954aafe9ffae488d50ae674aabdcb4f248006d5\", \"price_changes\":[{\"asset_id\":\"8761897749749422724209054078244794145777693856614463256546737399611489089783\", \"price\":\"0.63\", \"size\":\"87\", \"side\":\"BUY\", \"hash\":\"70027c6852b9fd7b96f6dc75f861e628fd8b5f70\", \"best_bid\":\"0.67\", \"best_ask\":\"0.68\"}, {\"asset_id\":\"14965588658799411272385430903075831224615961675357217884735713260981483529984\", \"price\":\"0.37\", \"size\":\"87\", \"side\":\"SELL\", \"hash\":\"0791b99d2e410f91328c0c7f9f5724562a644a98\", \"best_bid\":\"0.32\", \"best_ask\":\"0.33\"}], \"timestamp\":\"1785208333617\", \"event_type\":\"price_change\"}","received_at":"2026-07-28T03:12:27.213121Z","schema_version":"clob-market-ws.price_change.v1","sequence":null,"server_hash":null,"server_timestamp":"1785208333617","session_id":"3e519d9098404c15b234d96025eb1a2b","source":"clob_market_ws"},"received_at":"2026-07-28T03:12:27.213121Z","record_id":"398c5d9d58e198421649f4325fe4b70d64bd6fec2d6ca016bfa26b74b97ae752","schema_fingerprint":"4aa3821a28b0b7c2400bc59aba4bcc0a76e971dadd19610d3ad38c768e124dc7","schema_version":"edge-lab-recorder.raw.v1","sequence":null,"source":"clob_market_ws"}
{"event_at":"2026-07-28T03:12:13.637000Z","event_fingerprint":"51fafdfdaec70099fad76f7923ec500d415bbe55e23ccf4b0e296d085da3ae98","payload":{"connection_id":"a6b55582af5f430fb37ad02bf0922475","event_at":"2026-07-28T03:12:13.637000Z","event_type":"price_change","frame_hash":"e091ddcfe0de50d7890e480927999050525ce06470dea04b3322f54d48f5f64a","frame_index":0,"kind":"data","monotonic_ns":310330249365666,"payload":{"event_type":"price_change","market":"0x779291bef19b6709f61e9764a954aafe9ffae488d50ae674aabdcb4f248006d5","price_changes":[{"asset_id":"14965588658799411272385430903075831224615961675357217884735713260981483529984","best_ask":"0.33","best_bid":"0.32","hash":"81762a08e54976abe72b23c4869a9f17b7f4cdbc","price":"0.32","side":"BUY","size":"96"},{"asset_id":"8761897749749422724209054078244794145777693856614463256546737399611489089783","best_ask":"0.68","best_bid":"0.67","hash":"216e9b77650a1bc7fa6a3deecbc69a9cf57903d9","price":"0.68","side":"SELL","size":"96"}],"timestamp":"1785208333637"},"payload_hash":"b337ca7ff660582dac8ffcd02a84ea18336bc2e98fcd1160a89866a67f4cc31e","raw_frame":"{\"market\":\"0x779291bef19b6709f61e9764a954aafe9ffae488d50ae674aabdcb4f248006d5\", \"price_changes\":[{\"asset_id\":\"14965588658799411272385430903075831224615961675357217884735713260981483529984\", \"price\":\"0.32\", \"size\":\"96\", \"side\":\"BUY\", \"hash\":\"81762a08e54976abe72b23c4869a9f17b7f4cdbc\", \"best_bid\":\"0.32\", \"best_ask\":\"0.33\"}, {\"asset_id\":\"8761897749749422724209054078244794145777693856614463256546737399611489089783\", \"price\":\"0.68\", \"size\":\"96\", \"side\":\"SELL\", \"hash\":\"216e9b77650a1bc7fa6a3deecbc69a9cf57903d9\", \"best_bid\":\"0.67\", \"best_ask\":\"0.68\"}], \"timestamp\":\"1785208333637\", \"event_type\":\"price_change\"}","received_at":"2026-07-28T03:12:27.214766Z","schema_version":"clob-market-ws.price_change.v1","sequence":null,"server_hash":null,"server_timestamp":"1785208333637","session_id":"3e519d9098404c15b234d96025eb1a2b","source":"clob_market_ws"},"received_at":"2026-07-28T03:12:27.214766Z","record_id":"7af68a64ec919dad87065aa03e58d899d9daf28c44c5ea3ef94dfe14d2306e90","schema_fingerprint":"4aa3821a28b0b7c2400bc59aba4bcc0a76e971dadd19610d3ad38c768e124dc7","schema_version":"edge-lab-recorder.raw.v1","sequence":null,"source":"clob_market_ws"}
{"event_at":"2026-07-28T03:12:13.639000Z","event_fingerprint":"ce321853c8da9ede25ae1da2593f16ec2d37b245954a37c3e3834ecb690d96ed","payload":{"connection_id":"a6b55582af5f430fb37ad02bf0922475","event_at":"2026-07-28T03:12:13.639000Z","event_type":"price_change","frame_hash":"2df039bcffe060477abe7d759349ab337a8fd70bbd3b0f6f27e1af1fe58aec7b","frame_index":0,"kind":"data","monotonic_ns":310330251141125,"payload":{"event_type":"price_change","market":"0x779291bef19b6709f61e9764a954aafe9ffae488d50ae674aabdcb4f248006d5","price_changes":[{"asset_id":"14965588658799411272385430903075831224615961675357217884735713260981483529984","best_ask":"0.33","best_bid":"0.32","hash":"5bd507948fd2cac8dad80ce7d2131d1569954eea","price":"0.32","side":"BUY","size":"116"},{"asset_id":"8761897749749422724209054078244794145777693856614463256546737399611489089783","best_ask":"0.68","best_bid":"0.67","hash":"e4566d1b34c18d272b9e8d0e7c21bfb94cbd3938","price":"0.68","side":"SELL","size":"116"}],"timestamp":"1785208333639"},"payload_hash":"80355ba628bfc100735411cf061d8fdbd7173bde9186b493ff4b64ce3638fa54","raw_frame":"{\"market\":\"0x779291bef19b6709f61e9764a954aafe9ffae488d50ae674aabdcb4f248006d5\", \"price_changes\":[{\"asset_id\":\"14965588658799411272385430903075831224615961675357217884735713260981483529984\", \"price\":\"0.32\", \"size\":\"116\", \"side\":\"BUY\", \"hash\":\"5bd507948fd2cac8dad80ce7d2131d1569954eea\", \"best_bid\":\"0.32\", \"best_ask\":\"0.33\"}, {\"asset_id\":\"8761897749749422724209054078244794145777693856614463256546737399611489089783\", \"price\":\"0.68\", \"size\":\"116\", \"side\":\"SELL\", \"hash\":\"e4566d1b34c18d272b9e8d0e7c21bfb94cbd3938\", \"best_bid\":\"0.67\", \"best_ask\":\"0.68\"}], \"timestamp\":\"1785208333639\", \"event_type\":\"price_change\"}","received_at":"2026-07-28T03:12:27.216548Z","schema_version":"clob-market-ws.price_change.v1","sequence":null,"server_hash":null,"server_timestamp":"1785208333639","session_id":"3e519d9098404c15b234d96025eb1a2b","source":"clob_market_ws"},"received_at":"2026-07-28T03:12:27.216548Z","record_id":"4e65eca5017809a9600b74641bd659788d08cbbe62fbd5e1a12f328439ba323e","schema_fingerprint":"4aa3821a28b0b7c2400bc59aba4bcc0a76e971dadd19610d3ad38c768e124dc7","schema_version":"edge-lab-recorder.raw.v1","sequence":null,"source":"clob_market_ws"}
{"event_at":"2026-07-28T03:12:13.639000Z","event_fingerprint":"435503261b378cec91c38ed7675bd83bc89923e3ea4fa8ba78bd01a500347e95","payload":{"connection_id":"a6b55582af5f430fb37ad02bf0922475","event_at":"2026-07-28T03:12:13.639000Z","event_type":"price_change","frame_hash":"2f102467b258e94e132d1d179eb1f51d869a37dfaf8c34684cc51c006e71b759","frame_index":0,"kind":"data","monotonic_ns":310330252669791,"payload":{"event_type":"price_change","market":"0x779291bef19b6709f61e9764a954aafe9ffae488d50ae674aabdcb4f248006d5","price_changes":[{"asset_id":"8761897749749422724209054078244794145777693856614463256546737399611489089783","best_ask":"0.68","best_bid":"0.67","hash":"03de8610dea03d2d3d6e9627ff25f71aef23526d","price":"0.68","side":"SELL","size":"135"},{"asset_id":"14965588658799411272385430903075831224615961675357217884735713260981483529984","best_ask":"0.33","best_bid":"0.32","hash":"99b357644b70c027e6ded38086664f602ca53dbb","price":"0.32","side":"BUY","size":"135"}],"timestamp":"1785208333639"},"payload_hash":"53611c3777f01a37f1e44745b1fb7dcebdcc05502ea54cf9a72dc92d31c699e8","raw_frame":"{\"market\":\"0x779291bef19b6709f61e9764a954aafe9ffae488d50ae674aabdcb4f248006d5\", \"price_changes\":[{\"asset_id\":\"8761897749749422724209054078244794145777693856614463256546737399611489089783\", \"price\":\"0.68\", \"size\":\"135\", \"side\":\"SELL\", \"hash\":\"03de8610dea03d2d3d6e9627ff25f71aef23526d\", \"best_bid\":\"0.67\", \"best_ask\":\"0.68\"}, {\"asset_id\":\"14965588658799411272385430903075831224615961675357217884735713260981483529984\", \"price\":\"0.32\", \"size\":\"135\", \"side\":\"BUY\", \"hash\":\"99b357644b70c027e6ded38086664f602ca53dbb\", \"best_bid\":\"0.32\", \"best_ask\":\"0.33\"}], \"timestamp\":\"1785208333639\", \"event_type\":\"price_change\"}","received_at":"2026-07-28T03:12:27.218078Z","schema_version":"clob-market-ws.price_change.v1","sequence":null,"server_hash":null,"server_timestamp":"1785208333639","session_id":"3e519d9098404c15b234d96025eb1a2b","source":"clob_market_ws"},"received_at":"2026-07-28T03:12:27.218078Z","record_id":"7c402353bca33bfe61e0f34a17af89875ac8de1b569801106684a215264c8e14","schema_fingerprint":"4aa3821a28b0b7c2400bc59aba4bcc0a76e971dadd19610d3ad38c768e124dc7","schema_version":"edge-lab-recorder.raw.v1","sequence":null,"source":"clob_market_ws"}
{"event_at":"2026-07-28T03:12:13.641000Z","event_fingerprint":"84d5bfa7b6716e25706fc8443bfc823ca06c9d59393727c13e06e0322a533d41","payload":{"connection_id":"a6b55582af5f430fb37ad02bf0922475","event_at":"2026-07-28T03:12:13.641000Z","event_type":"price_change","frame_hash":"dc5dc84d0b6fd4349402fe8949327e2526e63a15629db4c2649a57e0f75c02dd","frame_index":0,"kind":"data","monotonic_ns":310330254178208,"payload":{"event_type":"price_change","market":"0x779291bef19b6709f61e9764a954aafe9ffae488d50ae674aabdcb4f248006d5","price_changes":[{"asset_id":"14965588658799411272385430903075831224615961675357217884735713260981483529984","best_ask":"0.33","best_bid":"0.32","hash":"97a2056f7ec9ea3a6a6203016df4deb859230450","price":"0.31","side":"BUY","size":"409"},{"asset_id":"8761897749749422724209054078244794145777693856614463256546737399611489089783","best_ask":"0.68","best_bid":"0.67","hash":"33a23be4438220fc9bc4eadcc46e1f09fb4c8a10","price":"0.69","side":"SELL","size":"409"}],"timestamp":"1785208333641"},"payload_hash":"695f20ef6f59d3eec777ebf31bf9ed9daf3dd18ba7a04e7208a2e5c75cc2b112","raw_frame":"{\"market\":\"0x779291bef19b6709f61e9764a954aafe9ffae488d50ae674aabdcb4f248006d5\", \"price_changes\":[{\"asset_id\":\"14965588658799411272385430903075831224615961675357217884735713260981483529984\", \"price\":\"0.31\", \"size\":\"409\", \"side\":\"BUY\", \"hash\":\"97a2056f7ec9ea3a6a6203016df4deb859230450\", \"best_bid\":\"0.32\", \"best_ask\":\"0.33\"}, {\"asset_id\":\"8761897749749422724209054078244794145777693856614463256546737399611489089783\", \"price\":\"0.69\", \"size\":\"409\", \"side\":\"SELL\", \"hash\":\"33a23be4438220fc9bc4eadcc46e1f09fb4c8a10\", \"best_bid\":\"0.67\", \"best_ask\":\"0.68\"}], \"timestamp\":\"1785208333641\", \"event_type\":\"price_change\"}","received_at":"2026-07-28T03:12:27.219587Z","schema_version":"clob-market-ws.price_change.v1","sequence":null,"server_hash":null,"server_timestamp":"1785208333641","session_id":"3e519d9098404c15b234d96025eb1a2b","source":"clob_market_ws"},"received_at":"2026-07-28T03:12:27.219587Z","record_id":"1ebab44eb31a11e68590e66a5e3e42acce0632112b84e4fa348a4dd85c6105c6","schema_fingerprint":"4aa3821a28b0b7c2400bc59aba4bcc0a76e971dadd19610d3ad38c768e124dc7","schema_version":"edge-lab-recorder.raw.v1","sequence":null,"source":"clob_market_ws"}
{"event_at":"2026-07-28T03:12:13.641000Z","event_fingerprint":"68b0a8bdbf9ad07e703acaa7a30410bd5a213e8639c6c7223aae54966dd9f8a5","payload":{"connection_id":"a6b55582af5f430fb37ad02bf0922475","event_at":"2026-07-28T03:12:13.641000Z","event_type":"price_change","frame_hash":"7858c288c11c4d88dea9fd02797a4b084d41fac4a02eae5782912007f0daae0c","frame_index":0,"kind":"data","monotonic_ns":310330255644708,"payload":{"event_type":"price_change","market":"0x779291bef19b6709f61e9764a954aafe9ffae488d50ae674aabdcb4f248006d5","price_changes":[{"asset_id":"14965588658799411272385430903075831224615961675357217884735713260981483529984","best_ask":"0.33","best_bid":"0.32","hash":"3f8054639fd57b6674ad566213bcd82c768e925e","price":"0.32","side":"BUY","size":"405"},{"asset_id":"8761897749749422724209054078244794145777693856614463256546737399611489089783","best_ask":"0.68","best_bid":"0.67","hash":"9b05dcc3cc0aa45166fae55724299bd412581f96","price":"0.68","side":"SELL","size":"405"}],"timestamp":"1785208333641"},"payload_hash":"7e2d51c3c1b82d8ed7afbe89a6904bb4a43a55f6c476f866c34ad47396995f15","raw_frame":"{\"market\":\"0x779291bef19b6709f61e9764a954aafe9ffae488d50ae674aabdcb4f248006d5\", \"price_changes\":[{\"asset_id\":\"14965588658799411272385430903075831224615961675357217884735713260981483529984\", \"price\":\"0.32\", \"size\":\"405\", \"side\":\"BUY\", \"hash\":\"3f8054639fd57b6674ad566213bcd82c768e925e\", \"best_bid\":\"0.32\", \"best_ask\":\"0.33\"}, {\"asset_id\":\"8761897749749422724209054078244794145777693856614463256546737399611489089783\", \"price\":\"0.68\", \"size\":\"405\", \"side\":\"SELL\", \"hash\":\"9b05dcc3cc0aa45166fae55724299bd412581f96\", \"best_bid\":\"0.67\", \"best_ask\":\"0.68\"}], \"timestamp\":\"1785208333641\", \"event_type\":\"price_change\"}","received_at":"2026-07-28T03:12:27.221053Z","schema_version":"clob-market-ws.price_change.v1","sequence":null,"server_hash":null,"server_timestamp":"1785208333641","session_id":"3e519d9098404c15b234d96025eb1a2b","source":"clob_market_ws"},"received_at":"2026-07-28T03:12:27.221053Z","record_id":"8e9780de92d6699772a2a33e905565878928a6f7d2b07eb48013d7360bf3c66a","schema_fingerprint":"4aa3821a28b0b7c2400bc59aba4bcc0a76e971dadd19610d3ad38c768e124dc7","schema_version":"edge-lab-recorder.raw.v1","sequence":null,"source":"clob_market_ws"}
{"event_at":"2026-07-28T03:12:13.642000Z","event_fingerprint":"9ef620afaf3d9a2ab351806076bf457574223bb1e2a5921de88c303d7811c535","payload":{"connection_id":"a6b55582af5f430fb37ad02bf0922475","event_at":"2026-07-28T03:12:13.642000Z","event_type":"price_change","frame_hash":"924c1639cc4fa3c819baf8e7623f41e9854739d5393a3bbf6cbc71fc6669f040","frame_index":0,"kind":"data","monotonic_ns":310330257135958,"payload":{"event_type":"price_change","market":"0x779291bef19b6709f61e9764a954aafe9ffae488d50ae674aabdcb4f248006d5","price_changes":[{"asset_id":"8761897749749422724209054078244794145777693856614463256546737399611489089783","best_ask":"0.68","best_bid":"0.67","hash":"de2924929f77087c5613fca58c140066b22c2cb2","price":"0.66","side":"BUY","size":"47.6"},{"asset_id":"14965588658799411272385430903075831224615961675357217884735713260981483529984","best_ask":"0.33","best_bid":"0.32","hash":"50f8dc6f1feefd4db213ad68e0241da02c59b2ad","price":"0.34","side":"SELL","size":"47.6"}],"timestamp":"1785208333642"},"payload_hash":"28e0b17ac53c3d496581271c97eaea4e48d4f50d0acd334a9313e3b93a185412","raw_frame":"{\"market\":\"0x779291bef19b6709f61e9764a954aafe9ffae488d50ae674aabdcb4f248006d5\", \"price_changes\":[{\"asset_id\":\"8761897749749422724209054078244794145777693856614463256546737399611489089783\", \"price\":\"0.66\", \"size\":\"47.6\", \"side\":\"BUY\", \"hash\":\"de2924929f77087c5613fca58c140066b22c2cb2\", \"best_bid\":\"0.67\", \"best_ask\":\"0.68\"}, {\"asset_id\":\"14965588658799411272385430903075831224615961675357217884735713260981483529984\", \"price\":\"0.34\", \"size\":\"47.6\", \"side\":\"SELL\", \"hash\":\"50f8dc6f1feefd4db213ad68e0241da02c59b2ad\", \"best_bid\":\"0.32\", \"best_ask\":\"0.33\"}], \"timestamp\":\"1785208333642\", \"event_type\":\"price_change\"}","received_at":"2026-07-28T03:12:27.222544Z","schema_version":"clob-market-ws.price_change.v1","sequence":null,"server_hash":null,"server_timestamp":"1785208333642","session_id":"3e519d9098404c15b234d96025eb1a2b","source":"clob_market_ws"},"received_at":"2026-07-28T03:12:27.222544Z","record_id":"da0de630c480bb6f975167a2cd54046be0a837a08e1c201f8cf8ae3a6353fcd2","schema_fingerprint":"4aa3821a28b0b7c2400bc59aba4bcc0a76e971dadd19610d3ad38c768e124dc7","schema_version":"edge-lab-recorder.raw.v1","sequence":null,"source":"clob_market_ws"}
{"event_at":"2026-07-28T03:12:13.642000Z","event_fingerprint":"600ec68c68656a99c0837527ac546a62e2b40975cdc5c24d5d429061843333a8","payload":{"connection_id":"a6b55582af5f430fb37ad02bf0922475","event_at":"2026-07-28T03:12:13.642000Z","event_type":"price_change","frame_hash":"1cff7ec90b5e021203ce4948f9a4cbdf3170126ea65961af09443823baad237a","frame_index":0,"kind":"data","monotonic_ns":310330258594083,"payload":{"event_type":"price_change","market":"0x779291bef19b6709f61e9764a954aafe9ffae488d50ae674aabdcb4f248006d5","price_changes":[{"asset_id":"14965588658799411272385430903075831224615961675357217884735713260981483529984","best_ask":"0.33","best_bid":"0.32","hash":"50f8dc6f1feefd4db213ad68e0241da02c59b2ad","price":"0.31","side":"BUY","size":"313"},{"asset_id":"8761897749749422724209054078244794145777693856614463256546737399611489089783","best_ask":"0.68","best_bid":"0.67","hash":"de2924929f77087c5613fca58c140066b22c2cb2","price":"0.69","side":"SELL","size":"313"}],"timestamp":"1785208333642"},"payload_hash":"b45af2d3e2fe60d5c5b6443c7e0307637efb84a9183aa2fa2c201ab911395d4f","raw_frame":"{\"market\":\"0x779291bef19b6709f61e9764a954aafe9ffae488d50ae674aabdcb4f248006d5\", \"price_changes\":[{\"asset_id\":\"14965588658799411272385430903075831224615961675357217884735713260981483529984\", \"price\":\"0.31\", \"size\":\"313\", \"side\":\"BUY\", \"hash\":\"50f8dc6f1feefd4db213ad68e0241da02c59b2ad\", \"best_bid\":\"0.32\", \"best_ask\":\"0.33\"}, {\"asset_id\":\"8761897749749422724209054078244794145777693856614463256546737399611489089783\", \"price\":\"0.69\", \"size\":\"313\", \"side\":\"SELL\", \"hash\":\"de2924929f77087c5613fca58c140066b22c2cb2\", \"best_bid\":\"0.67\", \"best_ask\":\"0.68\"}], \"timestamp\":\"1785208333642\", \"event_type\":\"price_change\"}","received_at":"2026-07-28T03:12:27.224003Z","schema_version":"clob-market-ws.price_change.v1","sequence":null,"server_hash":null,"server_timestamp":"1785208333642","session_id":"3e519d9098404c15b234d96025eb1a2b","source":"clob_market_ws"},"received_at":"2026-07-28T03:12:27.224003Z","record_id":"18314314f61e1c19d45f39977579eb519dea7164df40348157f104a136646148","schema_fingerprint":"4aa3821a28b0b7c2400bc59aba4bcc0a76e971dadd19610d3ad38c768e124dc7","schema_version":"edge-lab-recorder.raw.v1","sequence":null,"source":"clob_market_ws"}
{"event_at":"2026-07-28T03:12:13.642000Z","event_fingerprint":"bbe564bbb0c51d88073b794239faca5af9c5aa6ca042ca00a720215f65a83768","payload":{"connection_id":"a6b55582af5f430fb37ad02bf0922475","event_at":"2026-07-28T03:12:13.642000Z","event_type":"price_change","frame_hash":"4a025af0a3c4378314516f25cb55e83df356907c0ec448478fedc5e4417d04b9","frame_index":0,"kind":"data","monotonic_ns":310330260072583,"payload":{"event_type":"price_change","market":"0x779291bef19b6709f61e9764a954aafe9ffae488d50ae674aabdcb4f248006d5","price_changes":[{"asset_id":"14965588658799411272385430903075831224615961675357217884735713260981483529984","best_ask":"0.33","best_bid":"0.32","hash":"e8a6e58fa100295318f280a280b0ac389f97cf12","price":"0.31","side":"BUY","size":"43"},{"asset_id":"8761897749749422724209054078244794145777693856614463256546737399611489089783","best_ask":"0.68","best_bid":"0.67","hash":"f19bf4744d807177653c2db8239b428f5a19ea72","price":"0.69","side":"SELL","size":"43"}],"timestamp":"1785208333642"},"payload_hash":"ea4863608ed6da8acb1ecc775070d7c99619c488b903d3c4058da8226e71b908","raw_frame":"{\"market\":\"0x779291bef19b6709f61e9764a954aafe9ffae488d50ae674aabdcb4f248006d5\", \"price_changes\":[{\"asset_id\":\"14965588658799411272385430903075831224615961675357217884735713260981483529984\", \"price\":\"0.31\", \"size\":\"43\", \"side\":\"BUY\", \"hash\":\"e8a6e58fa100295318f280a280b0ac389f97cf12\", \"best_bid\":\"0.32\", \"best_ask\":\"0.33\"}, {\"asset_id\":\"8761897749749422724209054078244794145777693856614463256546737399611489089783\", \"price\":\"0.69\", \"size\":\"43\", \"side\":\"SELL\", \"hash\":\"f19bf4744d807177653c2db8239b428f5a19ea72\", \"best_bid\":\"0.67\", \"best_ask\":\"0.68\"}], \"timestamp\":\"1785208333642\", \"event_type\":\"price_change\"}","received_at":"2026-07-28T03:12:27.225481Z","schema_version":"clob-market-ws.price_change.v1","sequence":null,"server_hash":null,"server_timestamp":"1785208333642","session_id":"3e519d9098404c15b234d96025eb1a2b","source":"clob_market_ws"},"received_at":"2026-07-28T03:12:27.225481Z","record_id":"74ef95a6b80d1eb4e0c83e6fbb4c7c12a72dbe6305ec386b4575b5dee643eee7","schema_fingerprint":"4aa3821a28b0b7c2400bc59aba4bcc0a76e971dadd19610d3ad38c768e124dc7","schema_version":"edge-lab-recorder.raw.v1","sequence":null,"source":"clob_market_ws"}
{"event_at":"2026-07-28T03:12:13.643000Z","event_fingerprint":"44867c4151623abfb5eab776fdf1d30bba5057673f662a7055bf98fc4dbac3c6","payload":{"connection_id":"a6b55582af5f430fb37ad02bf0922475","event_at":"2026-07-28T03:12:13.643000Z","event_type":"price_change","frame_hash":"966b5f71bebcb22bc7196c68449797358ffbe5821441e9f90a52ae8dc172f8b0","frame_index":0,"kind":"data","monotonic_ns":310330261531958,"payload":{"event_type":"price_change","market":"0x779291bef19b6709f61e9764a954aafe9ffae488d50ae674aabdcb4f248006d5","price_changes":[{"asset_id":"14965588658799411272385430903075831224615961675357217884735713260981483529984","best_ask":"0.33","best_bid":"0.32","hash":"c97d2196007270c0c8bd24f03f812415a4884bc2","price":"0.27","side":"BUY","size":"42"},{"asset_id":"8761897749749422724209054078244794145777693856614463256546737399611489089783","best_ask":"0.68","best_bid":"0.67","hash":"4e518876943af5f57112c577753655ba721c1344","price":"0.73","side":"SELL","size":"42"}],"timestamp":"1785208333643"},"payload_hash":"9b14986e199b55d6cbd4130960ebb389c0331f863fcc0abd5b92256ca6b50c48","raw_frame":"{\"market\":\"0x779291bef19b6709f61e9764a954aafe9ffae488d50ae674aabdcb4f248006d5\", \"price_changes\":[{\"asset_id\":\"14965588658799411272385430903075831224615961675357217884735713260981483529984\", \"price\":\"0.27\", \"size\":\"42\", \"side\":\"BUY\", \"hash\":\"c97d2196007270c0c8bd24f03f812415a4884bc2\", \"best_bid\":\"0.32\", \"best_ask\":\"0.33\"}, {\"asset_id\":\"8761897749749422724209054078244794145777693856614463256546737399611489089783\", \"price\":\"0.73\", \"size\":\"42\", \"side\":\"SELL\", \"hash\":\"4e518876943af5f57112c577753655ba721c1344\", \"best_bid\":\"0.67\", \"best_ask\":\"0.68\"}], \"timestamp\":\"1785208333643\", \"event_type\":\"price_change\"}","received_at":"2026-07-28T03:12:27.226940Z","schema_version":"clob-market-ws.price_change.v1","sequence":null,"server_hash":null,"server_timestamp":"1785208333643","session_id":"3e519d9098404c15b234d96025eb1a2b","source":"clob_market_ws"},"received_at":"2026-07-28T03:12:27.226940Z","record_id":"7e092691158e1279cf714452276c5fcd4a70e362d1d3d1e1d81c881471f09a2b","schema_fingerprint":"4aa3821a28b0b7c2400bc59aba4bcc0a76e971dadd19610d3ad38c768e124dc7","schema_version":"edge-lab-recorder.raw.v1","sequence":null,"source":"clob_market_ws"}
{"event_at":"2026-07-28T03:12:13.643000Z","event_fingerprint":"8b399b119c6a64b9a7323e73b6e90c2e94ce8600760c5d8589375462129657ef","payload":{"connection_id":"a6b55582af5f430fb37ad02bf0922475","event_at":"2026-07-28T03:12:13.643000Z","event_type":"price_change","frame_hash":"813891d29f4a86bdbf4ab1b3d87660cc1af65d4258237eb514f4b895d91d308e","frame_index":0,"kind":"data","monotonic_ns":310330263048583,"payload":{"event_type":"price_change","market":"0x779291bef19b6709f61e9764a954aafe9ffae488d50ae674aabdcb4f248006d5","price_changes":[{"asset_id":"8761897749749422724209054078244794145777693856614463256546737399611489089783","best_ask":"0.68","best_bid":"0.67","hash":"4e518876943af5f57112c577753655ba721c1344","price":"0.61","side":"BUY","size":"88.13"},{"asset_id":"14965588658799411272385430903075831224615961675357217884735713260981483529984","best_ask":"0.33","best_bid":"0.32","hash":"c97d2196007270c0c8bd24f03f812415a4884bc2","price":"0.39","side":"SELL","size":"88.13"}],"timestamp":"1785208333643"},"payload_hash":"aa6ff9279ff6c45ce889262172fb6548e9df244e21d474b3bd367ce4c9ad6e6b","raw_frame":"{\"market\":\"0x779291bef19b6709f61e9764a954aafe9ffae488d50ae674aabdcb4f248006d5\", \"price_changes\":[{\"asset_id\":\"8761897749749422724209054078244794145777693856614463256546737399611489089783\", \"price\":\"0.61\", \"size\":\"88.13\", \"side\":\"BUY\", \"hash\":\"4e518876943af5f57112c577753655ba721c1344\", \"best_bid\":\"0.67\", \"best_ask\":\"0.68\"}, {\"asset_id\":\"14965588658799411272385430903075831224615961675357217884735713260981483529984\", \"price\":\"0.39\", \"size\":\"88.13\", \"side\":\"SELL\", \"hash\":\"c97d2196007270c0c8bd24f03f812415a4884bc2\", \"best_bid\":\"0.32\", \"best_ask\":\"0.33\"}], \"timestamp\":\"1785208333643\", \"event_type\":\"price_change\"}","received_at":"2026-07-28T03:12:27.228457Z","schema_version":"clob-market-ws.price_change.v1","sequence":null,"server_hash":null,"server_timestamp":"1785208333643","session_id":"3e519d9098404c15b234d96025eb1a2b","source":"clob_market_ws"},"received_at":"2026-07-28T03:12:27.228457Z","record_id":"929b5d2a91a7e852ae29b9408f5e27ddabc9aabf7fcfa217c379f6f36e94daef","schema_fingerprint":"4aa3821a28b0b7c2400bc59aba4bcc0a76e971dadd19610d3ad38c768e124dc7","schema_version":"edge-lab-recorder.raw.v1","sequence":null,"source":"clob_market_ws"}
{"event_at":"2026-07-28T03:12:13.645000Z","event_fingerprint":"1c0fe225f0b48b2b9d6dc42fb5a6b5469e3931d409e984342646ad709ec57948","payload":{"connection_id":"a6b55582af5f430fb37ad02bf0922475","event_at":"2026-07-28T03:12:13.645000Z","event_type":"price_change","frame_hash":"b8e3203cb85ed35b9d4c169fa92311c4daf6f0207b588e64d6ce543e39d69f07","frame_index":0,"kind":"data","monotonic_ns":310330264541958,"payload":{"event_type":"price_change","market":"0x779291bef19b6709f61e9764a954aafe9ffae488d50ae674aabdcb4f248006d5","price_changes":[{"asset_id":"14965588658799411272385430903075831224615961675357217884735713260981483529984","best_ask":"0.33","best_bid":"0.32","hash":"c5fc988d671bad57e9cce8a7d3decdbc6f814cc4","price":"0.32","side":"BUY","size":"501"},{"asset_id":"8761897749749422724209054078244794145777693856614463256546737399611489089783","best_ask":"0.68","best_bid":"0.67","hash":"7d445802fc90928cfdb01acc501072a25359c683","price":"0.68","side":"SELL","size":"501"}],"timestamp":"1785208333645"},"payload_hash":"5b2fc4450e4d621e7a216eec7003ebb5988447cdfb9dfca031cff67e88993438","raw_frame":"{\"market\":\"0x779291bef19b6709f61e9764a954aafe9ffae488d50ae674aabdcb4f248006d5\", \"price_changes\":[{\"asset_id\":\"14965588658799411272385430903075831224615961675357217884735713260981483529984\", \"price\":\"0.32\", \"size\":\"501\", \"side\":\"BUY\", \"hash\":\"c5fc988d671bad57e9cce8a7d3decdbc6f814cc4\", \"best_bid\":\"0.32\", \"best_ask\":\"0.33\"}, {\"asset_id\":\"8761897749749422724209054078244794145777693856614463256546737399611489089783\", \"price\":\"0.68\", \"size\":\"501\", \"side\":\"SELL\", \"hash\":\"7d445802fc90928cfdb01acc501072a25359c683\", \"best_bid\":\"0.67\", \"best_ask\":\"0.68\"}], \"timestamp\":\"1785208333645\", \"event_type\":\"price_change\"}","received_at":"2026-07-28T03:12:27.229950Z","schema_version":"clob-market-ws.price_change.v1","sequence":null,"server_hash":null,"server_timestamp":"1785208333645","session_id":"3e519d9098404c15b234d96025eb1a2b","source":"clob_market_ws"},"received_at":"2026-07-28T03:12:27.229950Z","record_id":"bc9499637c557ac4e4c5535ff518c976cad5454844f5634f51af2d2e58fdb3cf","schema_fingerprint":"4aa3821a28b0b7c2400bc59aba4bcc0a76e971dadd19610d3ad38c768e124dc7","schema_version":"edge-lab-recorder.raw.v1","sequence":null,"source":"clob_market_ws"}
{"event_at":"2026-07-28T03:12:13.647000Z","event_fingerprint":"27b1753b81520459bc85b93de426e1e554dd3fee6f984696634c6d2f749112ee","payload":{"connection_id":"a6b55582af5f430fb37ad02bf0922475","event_at":"2026-07-28T03:12:13.647000Z","event_type":"price_change","frame_hash":"3c17674f385e11da37dbda486120f73da3c4f05d9d840b8524df6880e91bd339","frame_index":0,"kind":"data","monotonic_ns":310330266024208,"payload":{"event_type":"price_change","market":"0x779291bef19b6709f61e9764a954aafe9ffae488d50ae674aabdcb4f248006d5","price_changes":[{"asset_id":"14965588658799411272385430903075831224615961675357217884735713260981483529984","best_ask":"0.33","best_bid":"0.32","hash":"c8b661013108ef1e00138fb850c53e6ea11245d7","price":"0.32","side":"BUY","size":"513.6"},{"asset_id":"8761897749749422724209054078244794145777693856614463256546737399611489089783","best_ask":"0.68","best_bid":"0.67","hash":"ceccedd419ad3377bcf5a1ddc970808c3baff9ed","price":"0.68","side":"SELL","size":"513.6"}],"timestamp":"1785208333647"},"payload_hash":"160753f193ef0e6d63bd9e6ffc0b010498611caa2a38d0b53a43ff529be6228d","raw_frame":"{\"market\":\"0x779291bef19b6709f61e9764a954aafe9ffae488d50ae674aabdcb4f248006d5\", \"price_changes\":[{\"asset_id\":\"14965588658799411272385430903075831224615961675357217884735713260981483529984\", \"price\":\"0.32\", \"size\":\"513.6\", \"side\":\"BUY\", \"hash\":\"c8b661013108ef1e00138fb850c53e6ea11245d7\", \"best_bid\":\"0.32\", \"best_ask\":\"0.33\"}, {\"asset_id\":\"8761897749749422724209054078244794145777693856614463256546737399611489089783\", \"price\":\"0.68\", \"size\":\"513.6\", \"side\":\"SELL\", \"hash\":\"ceccedd419ad3377bcf5a1ddc970808c3baff9ed\", \"best_bid\":\"0.67\", \"best_ask\":\"0.68\"}], \"timestamp\":\"1785208333647\", \"event_type\":\"price_change\"}","received_at":"2026-07-28T03:12:27.231433Z","schema_version":"clob-market-ws.price_change.v1","sequence":null,"server_hash":null,"server_timestamp":"1785208333647","session_id":"3e519d9098404c15b234d96025eb1a2b","source":"clob_market_ws"},"received_at":"2026-07-28T03:12:27.231433Z","record_id":"e259d3888eab01a2466c1f2512317b0a6a65c4ba67253675b394e0f4c99e5e68","schema_fingerprint":"4aa3821a28b0b7c2400bc59aba4bcc0a76e971dadd19610d3ad38c768e124dc7","schema_version":"edge-lab-recorder.raw.v1","sequence":null,"source":"clob_market_ws"}
{"event_at":"2026-07-28T03:12:13.648000Z","event_fingerprint":"c90c7c7e55d98d587ab8ec5c583a10fa956cae7f294d918705ea362ee6bc94dc","payload":{"connection_id":"a6b55582af5f430fb37ad02bf0922475","event_at":"2026-07-28T03:12:13.648000Z","event_type":"price_change","frame_hash":"9a81beaedab85da5f4ed3a5a77ba97973805dd5b5c70f1cf082e71c0037dc105","frame_index":0,"kind":"data","monotonic_ns":310330267522375,"payload":{"event_type":"price_change","market":"0x779291bef19b6709f61e9764a954aafe9ffae488d50ae674aabdcb4f248006d5","price_changes":[{"asset_id":"14965588658799411272385430903075831224615961675357217884735713260981483529984","best_ask":"0.33","best_bid":"0.32","hash":"a6e817dab753120ba01676ce1f43d2df77d7baeb","price":"0.13","side":"BUY","size":"61"},{"asset_id":"8761897749749422724209054078244794145777693856614463256546737399611489089783","best_ask":"0.68","best_bid":"0.67","hash":"f73ce3766d74b0f693247f9d444b3225f06fef8b","price":"0.87","side":"SELL","size":"61"}],"timestamp":"1785208333648"},"payload_hash":"c8bea08766d1b7d942b8c1653cea8283416ad2e27fdbc1346fe249ff06bdea1f","raw_frame":"{\"market\":\"0x779291bef19b6709f61e9764a954aafe9ffae488d50ae674aabdcb4f248006d5\", \"price_changes\":[{\"asset_id\":\"14965588658799411272385430903075831224615961675357217884735713260981483529984\", \"price\":\"0.13\", \"size\":\"61\", \"side\":\"BUY\", \"hash\":\"a6e817dab753120ba01676ce1f43d2df77d7baeb\", \"best_bid\":\"0.32\", \"best_ask\":\"0.33\"}, {\"asset_id\":\"8761897749749422724209054078244794145777693856614463256546737399611489089783\", \"price\":\"0.87\", \"size\":\"61\", \"side\":\"SELL\", \"hash\":\"f73ce3766d74b0f693247f9d444b3225f06fef8b\", \"best_bid\":\"0.67\", \"best_ask\":\"0.68\"}], \"timestamp\":\"1785208333648\", \"event_type\":\"price_change\"}","received_at":"2026-07-28T03:12:27.232931Z","schema_version":"clob-market-ws.price_change.v1","sequence":null,"server_hash":null,"server_timestamp":"1785208333648","session_id":"3e519d9098404c15b234d96025eb1a2b","source":"clob_market_ws"},"received_at":"2026-07-28T03:12:27.232931Z","record_id":"2fcd788dc71993271f7d889424a671933737ea5711c932c82ef6138d7e68a7eb","schema_fingerprint":"4aa3821a28b0b7c2400bc59aba4bcc0a76e971dadd19610d3ad38c768e124dc7","schema_version":"edge-lab-recorder.raw.v1","sequence":null,"source":"clob_market_ws"}
{"event_at":"2026-07-28T03:12:13.648000Z","event_fingerprint":"0063f5cc8e31a175d6db696eb67494b56ccf60855075f27a3366dd1da7e68b61","payload":{"connection_id":"a6b55582af5f430fb37ad02bf0922475","event_at":"2026-07-28T03:12:13.648000Z","event_type":"price_change","frame_hash":"37b7d03dd04bb18e9637536bed4dbbabce2d4a616dffd8f0e2874b735598d405","frame_index":0,"kind":"data","monotonic_ns":310330268989625,"payload":{"event_type":"price_change","market":"0x779291bef19b6709f61e9764a954aafe9ffae488d50ae674aabdcb4f248006d5","price_changes":[{"asset_id":"14965588658799411272385430903075831224615961675357217884735713260981483529984","best_ask":"0.33","best_bid":"0.32","hash":"261784e2c83a3e336fbb796f7ed0a459b2cad629","price":"0.31","side":"BUY","size":"55.6"},{"asset_id":"8761897749749422724209054078244794145777693856614463256546737399611489089783","best_ask":"0.68","best_bid":"0.67","hash":"eac1cb60f0fdeb5c530401ec2064208818372a5f","price":"0.69","side":"SELL","size":"55.6"}],"timestamp":"1785208333648"},"payload_hash":"cb819c171ed48e30c2248dff9c9159755b7b26e760de72d64f4a79e41807dc31","raw_frame":"{\"market\":\"0x779291bef19b6709f61e9764a954aafe9ffae488d50ae674aabdcb4f248006d5\", \"price_changes\":[{\"asset_id\":\"14965588658799411272385430903075831224615961675357217884735713260981483529984\", \"price\":\"0.31\", \"size\":\"55.6\", \"side\":\"BUY\", \"hash\":\"261784e2c83a3e336fbb796f7ed0a459b2cad629\", \"best_bid\":\"0.32\", \"best_ask\":\"0.33\"}, {\"asset_id\":\"8761897749749422724209054078244794145777693856614463256546737399611489089783\", \"price\":\"0.69\", \"size\":\"55.6\", \"side\":\"SELL\", \"hash\":\"eac1cb60f0fdeb5c530401ec2064208818372a5f\", \"best_bid\":\"0.67\", \"best_ask\":\"0.68\"}], \"timestamp\":\"1785208333648\", \"event_type\":\"price_change\"}","received_at":"2026-07-28T03:12:27.234398Z","schema_version":"clob-market-ws.price_change.v1","sequence":null,"server_hash":null,"server_timestamp":"1785208333648","session_id":"3e519d9098404c15b234d96025eb1a2b","source":"clob_market_ws"},"received_at":"2026-07-28T03:12:27.234398Z","record_id":"57d6adfacecf344c85449fb53f63b37b6fa98d4d9be60a4377c006cb1d868b98","schema_fingerprint":"4aa3821a28b0b7c2400bc59aba4bcc0a76e971dadd19610d3ad38c768e124dc7","schema_version":"edge-lab-recorder.raw.v1","sequence":null,"source":"clob_market_ws"}
{"event_at":"2026-07-28T03:12:13.649000Z","event_fingerprint":"53c89efb59ee15f2106ea4f58cf4ef6207017415a84e86c52919da574b39d660","payload":{"connection_id":"a6b55582af5f430fb37ad02bf0922475","event_at":"2026-07-28T03:12:13.649000Z","event_type":"price_change","frame_hash":"86353f0118ea54a7a2f3a15b2d10c8c6947d7c68c9df7b6929ba229b51410a8b","frame_index":0,"kind":"data","monotonic_ns":310330270459000,"payload":{"event_type":"price_change","market":"0x779291bef19b6709f61e9764a954aafe9ffae488d50ae674aabdcb4f248006d5","price_changes":[{"asset_id":"8761897749749422724209054078244794145777693856614463256546737399611489089783","best_ask":"0.68","best_bid":"0.67","hash":"afb1fa3c53ba48ef3e210d06995436017b458b2a","price":"0.66","side":"BUY","size":"35"},{"asset_id":"14965588658799411272385430903075831224615961675357217884735713260981483529984","best_ask":"0.33","best_bid":"0.32","hash":"cf56374c476ed792edacbf40d797f79867370db0","price":"0.34","side":"SELL","size":"35"}],"timestamp":"1785208333649"},"payload_hash":"d1f1d06301b198681647b424ca70d467efc4db41e275f13b2dcb6fb9ae83a49d","raw_frame":"{\"market\":\"0x779291bef19b6709f61e9764a954aafe9ffae488d50ae674aabdcb4f248006d5\", \"price_changes\":[{\"asset_id\":\"8761897749749422724209054078244794145777693856614463256546737399611489089783\", \"price\":\"0.66\", \"size\":\"35\", \"side\":\"BUY\", \"hash\":\"afb1fa3c53ba48ef3e210d06995436017b458b2a\", \"best_bid\":\"0.67\", \"best_ask\":\"0.68\"}, {\"asset_id\":\"14965588658799411272385430903075831224615961675357217884735713260981483529984\", \"price\":\"0.34\", \"size\":\"35\", \"side\":\"SELL\", \"hash\":\"cf56374c476ed792edacbf40d797f79867370db0\", \"best_bid\":\"0.32\", \"best_ask\":\"0.33\"}], \"timestamp\":\"1785208333649\", \"event_type\":\"price_change\"}","received_at":"2026-07-28T03:12:27.235867Z","schema_version":"clob-market-ws.price_change.v1","sequence":null,"server_hash":null,"server_timestamp":"1785208333649","session_id":"3e519d9098404c15b234d96025eb1a2b","source":"clob_market_ws"},"received_at":"2026-07-28T03:12:27.235867Z","record_id":"bb9554316669bb67c18356caf528fe3a2123c9a698cb614d79232804e4d409b3","schema_fingerprint":"4aa3821a28b0b7c2400bc59aba4bcc0a76e971dadd19610d3ad38c768e124dc7","schema_version":"edge-lab-recorder.raw.v1","sequence":null,"source":"clob_market_ws"}
{"event_at":"2026-07-28T03:12:13.649000Z","event_fingerprint":"a103a8c7c603035a6051d64fa849bbcefd05d1c3805927ecd97429ed5653b9d8","payload":{"connection_id":"a6b55582af5f430fb37ad02bf0922475","event_at":"2026-07-28T03:12:13.649000Z","event_type":"price_change","frame_hash":"3ba6bc9d4f500dbedcef8994a10d128b80bba3dcc78b26120b75a6ac8db2e4f1","frame_index":0,"kind":"data","monotonic_ns":310330271929666,"payload":{"event_type":"price_change","market":"0x779291bef19b6709f61e9764a954aafe9ffae488d50ae674aabdcb4f248006d5","price_changes":[{"asset_id":"8761897749749422724209054078244794145777693856614463256546737399611489089783","best_ask":"0.68","best_bid":"0.67","hash":"b177970b30ba70fa7546edac42f7b70057df9a7b","price":"0.65","side":"BUY","size":"53.56"},{"asset_id":"14965588658799411272385430903075831224615961675357217884735713260981483529984","best_ask":"0.33","best_bid":"0.32","hash":"99369361a617d72ffb79ef9d154b7212f0bcdd8c","price":"0.35","side":"SELL","size":"53.56"}],"timestamp":"1785208333649"},"payload_hash":"86a15d6ddcd8836d68dfef8a5fc87e577c3379201a0988915384f438d9861eee","raw_frame":"{\"market\":\"0x779291bef19b6709f61e9764a954aafe9ffae488d50ae674aabdcb4f248006d5\", \"price_changes\":[{\"asset_id\":\"8761897749749422724209054078244794145777693856614463256546737399611489089783\", \"price\":\"0.65\", \"size\":\"53.56\", \"side\":\"BUY\", \"hash\":\"b177970b30ba70fa7546edac42f7b70057df9a7b\", \"best_bid\":\"0.67\", \"best_ask\":\"0.68\"}, {\"asset_id\":\"14965588658799411272385430903075831224615961675357217884735713260981483529984\", \"price\":\"0.35\", \"size\":\"53.56\", \"side\":\"SELL\", \"hash\":\"99369361a617d72ffb79ef9d154b7212f0bcdd8c\", \"best_bid\":\"0.32\", \"best_ask\":\"0.33\"}], \"timestamp\":\"1785208333649\", \"event_type\":\"price_change\"}","received_at":"2026-07-28T03:12:27.237338Z","schema_version":"clob-market-ws.price_change.v1","sequence":null,"server_hash":null,"server_timestamp":"1785208333649","session_id":"3e519d9098404c15b234d96025eb1a2b","source":"clob_market_ws"},"received_at":"2026-07-28T03:12:27.237338Z","record_id":"a1d16c709c410ca8ceb0fd8d617d0216ec9790c313de9abda049f688e9f964a6","schema_fingerprint":"4aa3821a28b0b7c2400bc59aba4bcc0a76e971dadd19610d3ad38c768e124dc7","schema_version":"edge-lab-recorder.raw.v1","sequence":null,"source":"clob_market_ws"}
{"event_at":"2026-07-28T03:12:13.650000Z","event_fingerprint":"c8e1aa8600fe1bb82cedfeb78748add777dc5b48e523defc50d365e74669507e","payload":{"connection_id":"a6b55582af5f430fb37ad02bf0922475","event_at":"2026-07-28T03:12:13.650000Z","event_type":"price_change","frame_hash":"68882c732379eeda354d046ff96317328702c6488f8fdf2a646d1e8f9d7351a9","frame_index":0,"kind":"data","monotonic_ns":310330273413916,"payload":{"event_type":"price_change","market":"0x779291bef19b6709f61e9764a954aafe9ffae488d50ae674aabdcb4f248006d5","price_changes":[{"asset_id":"14965588658799411272385430903075831224615961675357217884735713260981483529984","best_ask":"0.33","best_bid":"0.32","hash":"84f1f117bc6086474fa2222630f6ea5e3fd3f904","price":"0.32","side":"BUY","size":"501"},{"asset_id":"8761897749749422724209054078244794145777693856614463256546737399611489089783","best_ask":"0.68","best_bid":"0.67","hash":"0e2a8730cfbfa30f98ca31d73e42a423745bcb4d","price":"0.68","side":"SELL","size":"501"}],"timestamp":"1785208333650"},"payload_hash":"a36bd0adb22d4ec03c3d276c69599c2f0ff6ebf20a24039db8c789a526267c7a","raw_frame":"{\"market\":\"0x779291bef19b6709f61e9764a954aafe9ffae488d50ae674aabdcb4f248006d5\", \"price_changes\":[{\"asset_id\":\"14965588658799411272385430903075831224615961675357217884735713260981483529984\", \"price\":\"0.32\", \"size\":\"501\", \"side\":\"BUY\", \"hash\":\"84f1f117bc6086474fa2222630f6ea5e3fd3f904\", \"best_bid\":\"0.32\", \"best_ask\":\"0.33\"}, {\"asset_id\":\"8761897749749422724209054078244794145777693856614463256546737399611489089783\", \"price\":\"0.68\", \"size\":\"501\", \"side\":\"SELL\", \"hash\":\"0e2a8730cfbfa30f98ca31d73e42a423745bcb4d\", \"best_bid\":\"0.67\", \"best_ask\":\"0.68\"}], \"timestamp\":\"1785208333650\", \"event_type\":\"price_change\"}","received_at":"2026-07-28T03:12:27.238822Z","schema_version":"clob-market-ws.price_change.v1","sequence":null,"server_hash":null,"server_timestamp":"1785208333650","session_id":"3e519d9098404c15b234d96025eb1a2b","source":"clob_market_ws"},"received_at":"2026-07-28T03:12:27.238822Z","record_id":"ddbb7369192f064947cbb47b2c39a0e6dc0ee8b0d42e929274b0ac42e1653369","schema_fingerprint":"4aa3821a28b0b7c2400bc59aba4bcc0a76e971dadd19610d3ad38c768e124dc7","schema_version":"edge-lab-recorder.raw.v1","sequence":null,"source":"clob_market_ws"}
{"event_at":"2026-07-28T03:12:13.654000Z","event_fingerprint":"b42aace1401d868a83bc2fc26f3098f41ccd021fd8e83fcf33bd58fc72fb1178","payload":{"connection_id":"a6b55582af5f430fb37ad02bf0922475","event_at":"2026-07-28T03:12:13.654000Z","event_type":"price_change","frame_hash":"30f75d0d9908f25a658aa3c77a7364718824610a4cc1da0972757ab232934d06","frame_index":0,"kind":"data","monotonic_ns":310330274893125,"payload":{"event_type":"price_change","market":"0x779291bef19b6709f61e9764a954aafe9ffae488d50ae674aabdcb4f248006d5","price_changes":[{"asset_id":"8761897749749422724209054078244794145777693856614463256546737399611489089783","best_ask":"0.68","best_bid":"0.67","hash":"3d04def758374d83a8ec8fbc1e30fe42ac5d8361","price":"0.65","side":"BUY","size":"41"},{"asset_id":"14965588658799411272385430903075831224615961675357217884735713260981483529984","best_ask":"0.33","best_bid":"0.32","hash":"12bc5d22535f5d0ff679f30e9f0cb625625344f1","price":"0.35","side":"SELL","size":"41"}],"timestamp":"1785208333654"},"payload_hash":"aa73990135c53d3b3aa0e5e874a7adfbcaf614dbf4ce27a68485499daacb8178","raw_frame":"{\"market\":\"0x779291bef19b6709f61e9764a954aafe9ffae488d50ae674aabdcb4f248006d5\", \"price_changes\":[{\"asset_id\":\"8761897749749422724209054078244794145777693856614463256546737399611489089783\", \"price\":\"0.65\", \"size\":\"41\", \"side\":\"BUY\", \"hash\":\"3d04def758374d83a8ec8fbc1e30fe42ac5d8361\", \"best_bid\":\"0.67\", \"best_ask\":\"0.68\"}, {\"asset_id\":\"14965588658799411272385430903075831224615961675357217884735713260981483529984\", \"price\":\"0.35\", \"size\":\"41\", \"side\":\"SELL\", \"hash\":\"12bc5d22535f5d0ff679f30e9f0cb625625344f1\", \"best_bid\":\"0.32\", \"best_ask\":\"0.33\"}], \"timestamp\":\"1785208333654\", \"event_type\":\"price_change\"}","received_at":"2026-07-28T03:12:27.240302Z","schema_version":"clob-market-ws.price_change.v1","sequence":null,"server_hash":null,"server_timestamp":"1785208333654","session_id":"3e519d9098404c15b234d96025eb1a2b","source":"clob_market_ws"},"received_at":"2026-07-28T03:12:27.240302Z","record_id":"4c40ae4c3ede43cf5852599ec81364280932101710506774e3000bf70bfaae3d","schema_fingerprint":"4aa3821a28b0b7c2400bc59aba4bcc0a76e971dadd19610d3ad38c768e124dc7","schema_version":"edge-lab-recorder.raw.v1","sequence":null,"source":"clob_market_ws"}
{"event_at":"2026-07-28T03:12:13.656000Z","event_fingerprint":"cfe38f5a546fc91a223f7c715fe788fee0b5ae25bffaa5eaa7c1ddf38f9bc6ce","payload":{"connection_id":"a6b55582af5f430fb37ad02bf0922475","event_at":"2026-07-28T03:12:13.656000Z","event_type":"price_change","frame_hash":"7e5dd0ebf8c037f42a6e6106c6c320804a413f7bbef1891f89096979c6f25a30","frame_index":0,"kind":"data","monotonic_ns":310330276364416,"payload":{"event_type":"price_change","market":"0x779291bef19b6709f61e9764a954aafe9ffae488d50ae674aabdcb4f248006d5","price_changes":[{"asset_id":"8761897749749422724209054078244794145777693856614463256546737399611489089783","best_ask":"0.68","best_bid":"0.67","hash":"2cc49f8e3298801ca0af9552ba38d2b648472bad","price":"0.64","side":"BUY","size":"63.6"},{"asset_id":"14965588658799411272385430903075831224615961675357217884735713260981483529984","best_ask":"0.33","best_bid":"0.32","hash":"20d6f1b9d9bd5155c6e818754eef1a392b4a7db9","price":"0.36","side":"SELL","size":"63.6"}],"timestamp":"1785208333656"},"payload_hash":"5b6c861c87c58afb0b8538c991647825116d8fee896423d5171bfb76c3d44d55","raw_frame":"{\"market\":\"0x779291bef19b6709f61e9764a954aafe9ffae488d50ae674aabdcb4f248006d5\", \"price_changes\":[{\"asset_id\":\"8761897749749422724209054078244794145777693856614463256546737399611489089783\", \"price\":\"0.64\", \"size\":\"63.6\", \"side\":\"BUY\", \"hash\":\"2cc49f8e3298801ca0af9552ba38d2b648472bad\", \"best_bid\":\"0.67\", \"best_ask\":\"0.68\"}, {\"asset_id\":\"14965588658799411272385430903075831224615961675357217884735713260981483529984\", \"price\":\"0.36\", \"size\":\"63.6\", \"side\":\"SELL\", \"hash\":\"20d6f1b9d9bd5155c6e818754eef1a392b4a7db9\", \"best_bid\":\"0.32\", \"best_ask\":\"0.33\"}], \"timestamp\":\"1785208333656\", \"event_type\":\"price_change\"}","received_at":"2026-07-28T03:12:27.241772Z","schema_version":"clob-market-ws.price_change.v1","sequence":null,"server_hash":null,"server_timestamp":"1785208333656","session_id":"3e519d9098404c15b234d96025eb1a2b","source":"clob_market_ws"},"received_at":"2026-07-28T03:12:27.241772Z","record_id":"5ba22fb23fdd3e249b22d2320a0aefa8091f3b9a8db0bd57ca5930a777e4378b","schema_fingerprint":"4aa3821a28b0b7c2400bc59aba4bcc0a76e971dadd19610d3ad38c768e124dc7","schema_version":"edge-lab-recorder.raw.v1","sequence":null,"source":"clob_market_ws"}
{"event_at":"2026-07-28T03:12:13.657000Z","event_fingerprint":"0338bbc0043d84241ad003fb811cc256b2b4184d0640db411fffb43a882c8c66","payload":{"connection_id":"a6b55582af5f430fb37ad02bf0922475","event_at":"2026-07-28T03:12:13.657000Z","event_type":"price_change","frame_hash":"74a2bb49b01ea4c63a12a49d611c4e700db375b190fab7e0d29b50026026889f","frame_index":0,"kind":"data","monotonic_ns":310330277901708,"payload":{"event_type":"price_change","market":"0x779291bef19b6709f61e9764a954aafe9ffae488d50ae674aabdcb4f248006d5","price_changes":[{"asset_id":"8761897749749422724209054078244794145777693856614463256546737399611489089783","best_ask":"0.68","best_bid":"0.67","hash":"62acd3cd3c491728dd296f772aaa225d6981ac21","price":"0.66","side":"BUY","size":"20"},{"asset_id":"14965588658799411272385430903075831224615961675357217884735713260981483529984","best_ask":"0.33","best_bid":"0.32","hash":"23397214e61d32a3b2109922a23f2bfdc401ec01","price":"0.34","side":"SELL","size":"20"}],"timestamp":"1785208333657"},"payload_hash":"4c17452c3a7977caefe08fa0fe409e57b74c5a7d90c8e04370b2b49811f05573","raw_frame":"{\"market\":\"0x779291bef19b6709f61e9764a954aafe9ffae488d50ae674aabdcb4f248006d5\", \"price_changes\":[{\"asset_id\":\"8761897749749422724209054078244794145777693856614463256546737399611489089783\", \"price\":\"0.66\", \"size\":\"20\", \"side\":\"BUY\", \"hash\":\"62acd3cd3c491728dd296f772aaa225d6981ac21\", \"best_bid\":\"0.67\", \"best_ask\":\"0.68\"}, {\"asset_id\":\"14965588658799411272385430903075831224615961675357217884735713260981483529984\", \"price\":\"0.34\", \"size\":\"20\", \"side\":\"SELL\", \"hash\":\"23397214e61d32a3b2109922a23f2bfdc401ec01\", \"best_bid\":\"0.32\", \"best_ask\":\"0.33\"}], \"timestamp\":\"1785208333657\", \"event_type\":\"price_change\"}","received_at":"2026-07-28T03:12:27.243310Z","schema_version":"clob-market-ws.price_change.v1","sequence":null,"server_hash":null,"server_timestamp":"1785208333657","session_id":"3e519d9098404c15b234d96025eb1a2b","source":"clob_market_ws"},"received_at":"2026-07-28T03:12:27.243310Z","record_id":"f737b92f5f5b9ad7e0fc864b5bec24c182211f87ee6d37165497efb7f4a0a8c1","schema_fingerprint":"4aa3821a28b0b7c2400bc59aba4bcc0a76e971dadd19610d3ad38c768e124dc7","schema_version":"edge-lab-recorder.raw.v1","sequence":null,"source":"clob_market_ws"}
