{"event_at":"2026-07-28T03:12:12.839000Z","event_fingerprint":"ee955a1bc93527166c9635b102caee8afec2c0cedae72f09c55ea84618ab36ee","payload":{"connection_id":"a6b55582af5f430fb37ad02bf0922475","event_at":"2026-07-28T03:12:12.839000Z","event_type":"best_bid_ask","frame_hash":"5e8c5dd37a89d63d209b0d396c24c4116d209bb213e882e2296eaf0cb20c8827","frame_index":0,"kind":"data","monotonic_ns":310330106347875,"payload":{"asset_id":"14965588658799411272385430903075831224615961675357217884735713260981483529984","best_ask":"0.33","best_bid":"0.32","event_type":"best_bid_ask","market":"0x779291bef19b6709f61e9764a954aafe9ffae488d50ae674aabdcb4f248006d5","spread":"0.01","timestamp":"1785208332839"},"payload_hash":"022cc4f33adc7068c518016a550d549600c703d82958a01645bd1efc5e791176","raw_frame":"{\"market\":\"0x779291bef19b6709f61e9764a954aafe9ffae488d50ae674aabdcb4f248006d5\", \"asset_id\":\"14965588658799411272385430903075831224615961675357217884735713260981483529984\", \"best_bid\":\"0.32\", \"best_ask\":\"0.33\", \"spread\":\"0.01\", \"timestamp\":\"1785208332839\", \"event_type\":\"best_bid_ask\"}","received_at":"2026-07-28T03:12:27.071750Z","schema_version":"clob-market-ws.best_bid_ask.v1","sequence":null,"server_hash":null,"server_timestamp":"1785208332839","session_id":"3e519d9098404c15b234d96025eb1a2b","source":"clob_market_ws"},"received_at":"2026-07-28T03:12:27.071750Z","record_id":"e692af8f2f47e9593ae741f31b5aca24e5c82e6bf3c9dc0ee9b2beb34c2133b5","schema_fingerprint":"8488399f31b0337811b13b266be932db7062827c2470b78bd8e9e99bab51d17d","schema_version":"edge-lab-recorder.raw.v1","sequence":null,"source":"clob_market_ws"}
{"event_at":"2026-07-28T03:12:12.839000Z","event_fingerprint":"ac4964617a0ae80270d543d4b22cd59758315bd663bf553b5956d0d33f3e0d24","payload":{"connection_id":"a6b55582af5f430fb37ad02bf0922475","event_at":"2026-07-28T03:12:12.839000Z","event_type":"best_bid_ask","frame_hash":"df733a83df11397070561370ee1cf9e876aa8a69ff2221e18ff4c3095bb73bd1","frame_index":0,"kind":"data","monotonic_ns":310330108343125,"payload":{"asset_id":"8761897749749422724209054078244794145777693856614463256546737399611489089783","best_ask":"0.68","best_bid":"0.67","event_type":"best_bid_ask","market":"0x779291bef19b6709f61e9764a954aafe9ffae488d50ae674aabdcb4f248006d5","spread":"0.01","timestamp":"1785208332839"},"payload_hash":"23ce9f782f488aac4bab3eb740de70bb42d9c4585d688fe5b2382fe363ebc4ee","raw_frame":"{\"market\":\"0x779291bef19b6709f61e9764a954aafe9ffae488d50ae674aabdcb4f248006d5\", \"asset_id\":\"8761897749749422724209054078244794145777693856614463256546737399611489089783\", \"best_bid\":\"0.67\", \"best_ask\":\"0.68\", \"spread\":\"0.01\", \"timestamp\":\"1785208332839\", \"event_type\":\"best_bid_ask\"}","received_at":"2026-07-28T03:12:27.073745Z","schema_version":"clob-market-ws.best_bid_ask.v1","sequence":null,"server_hash":null,"server_timestamp":"1785208332839","session_id":"3e519d9098404c15b234d96025eb1a2b","source":"clob_market_ws"},"received_at":"2026-07-28T03:12:27.073745Z","record_id":"e63aa1557aa696c47b7bbfa64ede9936e1d67188990ddebdc98bf74be2b28ab6","schema_fingerprint":"8488399f31b0337811b13b266be932db7062827c2470b78bd8e9e99bab51d17d","schema_version":"edge-lab-recorder.raw.v1","sequence":null,"source":"clob_market_ws"}
{"event_at":"2026-07-28T03:12:12.839000Z","event_fingerprint":"5e40012e16692845d642e2435ed770410a7aa2345bf434740e647973e9d5c29e","payload":{"connection_id":"a6b55582af5f430fb37ad02bf0922475","event_at":"2026-07-28T03:12:12.839000Z","event_type":"price_change","frame_hash":"cb76ac00015cca8636c378a24d6e502af1beb4615bb4ed469ee6223e2550aa01","frame_index":0,"kind":"data","monotonic_ns":310330109675625,"payload":{"event_type":"price_change","market":"0x779291bef19b6709f61e9764a954aafe9ffae488d50ae674aabdcb4f248006d5","price_changes":[{"asset_id":"8761897749749422724209054078244794145777693856614463256546737399611489089783","best_ask":"0.68","best_bid":"0.67","hash":"b7834982112beff026f9ca4e663bacbbb5f7eaa8","price":"0.67","side":"BUY","size":"20"},{"asset_id":"14965588658799411272385430903075831224615961675357217884735713260981483529984","best_ask":"0.33","best_bid":"0.32","hash":"fdcef93f3570ff6362f07d40806980a676cf8753","price":"0.33","side":"SELL","size":"20"}],"timestamp":"1785208332839"},"payload_hash":"ad356fbbfd308f0a2edaeae70722a70d5c483c2e456243ebd0ea35ba47defca0","raw_frame":"{\"market\":\"0x779291bef19b6709f61e9764a954aafe9ffae488d50ae674aabdcb4f248006d5\", \"price_changes\":[{\"asset_id\":\"8761897749749422724209054078244794145777693856614463256546737399611489089783\", \"price\":\"0.67\", \"size\":\"20\", \"side\":\"BUY\", \"hash\":\"b7834982112beff026f9ca4e663bacbbb5f7eaa8\", \"best_bid\":\"0.67\", \"best_ask\":\"0.68\"}, {\"asset_id\":\"14965588658799411272385430903075831224615961675357217884735713260981483529984\", \"price\":\"0.33\", \"size\":\"20\", \"side\":\"SELL\", \"hash\":\"fdcef93f3570ff6362f07d40806980a676cf8753\", \"best_bid\":\"0.32\", \"best_ask\":\"0.33\"}], \"timestamp\":\"1785208332839\", \"event_type\":\"price_change\"}","received_at":"2026-07-28T03:12:27.075084Z","schema_version":"clob-market-ws.price_change.v1","sequence":null,"server_hash":null,"server_timestamp":"1785208332839","session_id":"3e519d9098404c15b234d96025eb1a2b","source":"clob_market_ws"},"received_at":"2026-07-28T03:12:27.075084Z","record_id":"c42d9abe72e7f64b24cad5ead9ce9e5bab8bbfa8c831995f7ec01c2c8beb0401","schema_fingerprint":"4aa3821a28b0b7c2400bc59aba4bcc0a76e971dadd19610d3ad38c768e124dc7","schema_version":"edge-lab-recorder.raw.v1","sequence":null,"source":"clob_market_ws"}
{"event_at":"2026-07-28T03:12:12.848000Z","event_fingerprint":"b7dabfdf487c20e59217d8d42a5d0a01008768d895dc24c150eac7c042eff4b8","payload":{"connection_id":"a6b55582af5f430fb37ad02bf0922475","event_at":"2026-07-28T03:12:12.848000Z","event_type":"price_change","frame_hash":"63fa54784a4f118f03cbf2bd404bff5d54727fd4b767941feddec4a4130f8659","frame_index":0,"kind":"data","monotonic_ns":310330111373541,"payload":{"event_type":"price_change","market":"0x779291bef19b6709f61e9764a954aafe9ffae488d50ae674aabdcb4f248006d5","price_changes":[{"asset_id":"8761897749749422724209054078244794145777693856614463256546737399611489089783","best_ask":"0.68","best_bid":"0.67","hash":"0187547ba623b8308271e8bfb2263a34c8c2de58","price":"0.66","side":"BUY","size":"438.6"},{"asset_id":"14965588658799411272385430903075831224615961675357217884735713260981483529984","best_ask":"0.33","best_bid":"0.32","hash":"4030a55582a0c2818a3ed7cfb2124a8112b54c34","price":"0.34","side":"SELL","size":"438.6"}],"timestamp":"1785208332848"},"payload_hash":"e1bc2a12efc6e8409b7a541aa34ba21e0330a70074ced20b9860e86200bdc13c","raw_frame":"{\"market\":\"0x779291bef19b6709f61e9764a954aafe9ffae488d50ae674aabdcb4f248006d5\", \"price_changes\":[{\"asset_id\":\"8761897749749422724209054078244794145777693856614463256546737399611489089783\", \"price\":\"0.66\", \"size\":\"438.6\", \"side\":\"BUY\", \"hash\":\"0187547ba623b8308271e8bfb2263a34c8c2de58\", \"best_bid\":\"0.67\", \"best_ask\":\"0.68\"}, {\"asset_id\":\"14965588658799411272385430903075831224615961675357217884735713260981483529984\", \"price\":\"0.34\", \"size\":\"438.6\", \"side\":\"SELL\", \"hash\":\"4030a55582a0c2818a3ed7cfb2124a8112b54c34\", \"best_bid\":\"0.32\", \"best_ask\":\"0.33\"}], \"timestamp\":\"1785208332848\", \"event_type\":\"price_change\"}","received_at":"2026-07-28T03:12:27.076782Z","schema_version":"clob-market-ws.price_change.v1","sequence":null,"server_hash":null,"server_timestamp":"1785208332848","session_id":"3e519d9098404c15b234d96025eb1a2b","source":"clob_market_ws"},"received_at":"2026-07-28T03:12:27.076782Z","record_id":"112fc759d8e2c8d895694a91941919a0a6d8284c324eed6e7428af9f0fcd3090","schema_fingerprint":"4aa3821a28b0b7c2400bc59aba4bcc0a76e971dadd19610d3ad38c768e124dc7","schema_version":"edge-lab-recorder.raw.v1","sequence":null,"source":"clob_market_ws"}
{"event_at":"2026-07-28T03:12:12.849000Z","event_fingerprint":"d61185d5ad74105c791db101bf0721e4c6bc28fe39de7cd0255f6f68b781c2c8","payload":{"connection_id":"a6b55582af5f430fb37ad02bf0922475","event_at":"2026-07-28T03:12:12.849000Z","event_type":"price_change","frame_hash":"f3f12ccbc0222537dd9ce4b063af4977fef646e4a3a0f88caf4dc3badea1097d","frame_index":0,"kind":"data","monotonic_ns":310330112985000,"payload":{"event_type":"price_change","market":"0x779291bef19b6709f61e9764a954aafe9ffae488d50ae674aabdcb4f248006d5","price_changes":[{"asset_id":"14965588658799411272385430903075831224615961675357217884735713260981483529984","best_ask":"0.33","best_bid":"0.32","hash":"322305bca383b8050dfab96bd2c59a2f6c72a1f8","price":"0.29","side":"BUY","size":"50.15"},{"asset_id":"8761897749749422724209054078244794145777693856614463256546737399611489089783","best_ask":"0.68","best_bid":"0.67","hash":"7f4ffe8160c3d93b34f55b87c93f9ade68361aaa","price":"0.71","side":"SELL","size":"50.15"}],"timestamp":"1785208332849"},"payload_hash":"a631da0af42928f72c8d96a1141796b0c56d3c2674b2680a4f0807e03ad3feaa","raw_frame":"{\"market\":\"0x779291bef19b6709f61e9764a954aafe9ffae488d50ae674aabdcb4f248006d5\", \"price_changes\":[{\"asset_id\":\"14965588658799411272385430903075831224615961675357217884735713260981483529984\", \"price\":\"0.29\", \"size\":\"50.15\", \"side\":\"BUY\", \"hash\":\"322305bca383b8050dfab96bd2c59a2f6c72a1f8\", \"best_bid\":\"0.32\", \"best_ask\":\"0.33\"}, {\"asset_id\":\"8761897749749422724209054078244794145777693856614463256546737399611489089783\", \"price\":\"0.71\", \"size\":\"50.15\", \"side\":\"SELL\", \"hash\":\"7f4ffe8160c3d93b34f55b87c93f9ade68361aaa\", \"best_bid\":\"0.67\", \"best_ask\":\"0.68\"}], \"timestamp\":\"1785208332849\", \"event_type\":\"price_change\"}","received_at":"2026-07-28T03:12:27.078394Z","schema_version":"clob-market-ws.price_change.v1","sequence":null,"server_hash":null,"server_timestamp":"1785208332849","session_id":"3e519d9098404c15b234d96025eb1a2b","source":"clob_market_ws"},"received_at":"2026-07-28T03:12:27.078394Z","record_id":"0dfbdd0d6dd9bad3e2af5b1f3656915aead2e66e3c3a4f938bec51c9ea873caa","schema_fingerprint":"4aa3821a28b0b7c2400bc59aba4bcc0a76e971dadd19610d3ad38c768e124dc7","schema_version":"edge-lab-recorder.raw.v1","sequence":null,"source":"clob_market_ws"}
{"event_at":"2026-07-28T03:12:12.850000Z","event_fingerprint":"cf9dcac9b51fc214cfb947287bef7fb4e0e7ba490571bcbb40335d2acde6caa1","payload":{"connection_id":"a6b55582af5f430fb37ad02bf0922475","event_at":"2026-07-28T03:12:12.850000Z","event_type":"price_change","frame_hash":"7787e122a01adef82f0f069156250e5ad259b9b688c89ca251c537f0b1d9c2e7","frame_index":0,"kind":"data","monotonic_ns":310330113941250,"payload":{"event_type":"price_change","market":"0x779291bef19b6709f61e9764a954aafe9ffae488d50ae674aabdcb4f248006d5","price_changes":[{"asset_id":"14965588658799411272385430903075831224615961675357217884735713260981483529984","best_ask":"0.33","best_bid":"0.32","hash":"ee375aa87a4156192b0ea18c9236716ed89cb556","price":"0.34","side":"SELL","size":"433.6"},{"asset_id":"8761897749749422724209054078244794145777693856614463256546737399611489089783","best_ask":"0.68","best_bid":"0.67","hash":"a59b99c4ac22dcdfa0d6236ef6ba91ec1970ddc8","price":"0.66","side":"BUY","size":"433.6"}],"timestamp":"1785208332850"},"payload_hash":"cdebaf5d8ec2866e3118304b3bad735aeee70b9d7d559927c3e47dbc7bee818e","raw_frame":"{\"market\":\"0x779291bef19b6709f61e9764a954aafe9ffae488d50ae674aabdcb4f248006d5\", \"price_changes\":[{\"asset_id\":\"14965588658799411272385430903075831224615961675357217884735713260981483529984\", \"price\":\"0.34\", \"size\":\"433.6\", \"side\":\"SELL\", \"hash\":\"ee375aa87a4156192b0ea18c9236716ed89cb556\", \"best_bid\":\"0.32\", \"best_ask\":\"0.33\"}, {\"asset_id\":\"8761897749749422724209054078244794145777693856614463256546737399611489089783\", \"price\":\"0.66\", \"size\":\"433.6\", \"side\":\"BUY\", \"hash\":\"a59b99c4ac22dcdfa0d6236ef6ba91ec1970ddc8\", \"best_bid\":\"0.67\", \"best_ask\":\"0.68\"}], \"timestamp\":\"1785208332850\", \"event_type\":\"price_change\"}","received_at":"2026-07-28T03:12:27.079355Z","schema_version":"clob-market-ws.price_change.v1","sequence":null,"server_hash":null,"server_timestamp":"1785208332850","session_id":"3e519d9098404c15b234d96025eb1a2b","source":"clob_market_ws"},"received_at":"2026-07-28T03:12:27.079355Z","record_id":"c754bbfabdcbbd3e2ccbf5659a85c8c9e74d3066d4df867b00ba6db64d4b4f33","schema_fingerprint":"4aa3821a28b0b7c2400bc59aba4bcc0a76e971dadd19610d3ad38c768e124dc7","schema_version":"edge-lab-recorder.raw.v1","sequence":null,"source":"clob_market_ws"}
{"event_at":"2026-07-28T03:12:12.850000Z","event_fingerprint":"a2e194a3529ac151fb85b70b0a82d2e9765c4e046ef7724976316e324b1d0b99","payload":{"connection_id":"a6b55582af5f430fb37ad02bf0922475","event_at":"2026-07-28T03:12:12.850000Z","event_type":"price_change","frame_hash":"dcffca0a45e609ef661063965621e00dc2e9770f43d142d8a844e7350dd1c8f3","frame_index":0,"kind":"data","monotonic_ns":310330114963916,"payload":{"event_type":"price_change","market":"0x779291bef19b6709f61e9764a954aafe9ffae488d50ae674aabdcb4f248006d5","price_changes":[{"asset_id":"8761897749749422724209054078244794145777693856614463256546737399611489089783","best_ask":"0.68","best_bid":"0.67","hash":"5106d6d62ba551494ebb382267965ea480b2a341","price":"0.7","side":"SELL","size":"439.6"},{"asset_id":"14965588658799411272385430903075831224615961675357217884735713260981483529984","best_ask":"0.33","best_bid":"0.32","hash":"a71850ebbb3c0423d3aa2526cdaea70043f7db54","price":"0.3","side":"BUY","size":"439.6"}],"timestamp":"1785208332850"},"payload_hash":"3a8e38c30ac3d5820068c056e968bb303593def5a47be70c8160fd2e1d622cf9","raw_frame":"{\"market\":\"0x779291bef19b6709f61e9764a954aafe9ffae488d50ae674aabdcb4f248006d5\", \"price_changes\":[{\"asset_id\":\"8761897749749422724209054078244794145777693856614463256546737399611489089783\", \"price\":\"0.7\", \"size\":\"439.6\", \"side\":\"SELL\", \"hash\":\"5106d6d62ba551494ebb382267965ea480b2a341\", \"best_bid\":\"0.67\", \"best_ask\":\"0.68\"}, {\"asset_id\":\"14965588658799411272385430903075831224615961675357217884735713260981483529984\", \"price\":\"0.3\", \"size\":\"439.6\", \"side\":\"BUY\", \"hash\":\"a71850ebbb3c0423d3aa2526cdaea70043f7db54\", \"best_bid\":\"0.32\", \"best_ask\":\"0.33\"}], \"timestamp\":\"1785208332850\", \"event_type\":\"price_change\"}","received_at":"2026-07-28T03:12:27.080373Z","schema_version":"clob-market-ws.price_change.v1","sequence":null,"server_hash":null,"server_timestamp":"1785208332850","session_id":"3e519d9098404c15b234d96025eb1a2b","source":"clob_market_ws"},"received_at":"2026-07-28T03:12:27.080373Z","record_id":"1e6b8866ae2b510edaf8cc7f341f26e3c8c2ceb8b98f14ddee285bb4d00336bc","schema_fingerprint":"4aa3821a28b0b7c2400bc59aba4bcc0a76e971dadd19610d3ad38c768e124dc7","schema_version":"edge-lab-recorder.raw.v1","sequence":null,"source":"clob_market_ws"}
{"event_at":"2026-07-28T03:12:12.859000Z","event_fingerprint":"19c9f1ff1513ae7727381e3dafcadabe1d4bcb46bf4754108c9069681c8f428b","payload":{"connection_id":"a6b55582af5f430fb37ad02bf0922475","event_at":"2026-07-28T03:12:12.859000Z","event_type":"price_change","frame_hash":"d4ba559990c95183017d0d23548cb528bca239856e4b365127b99b71486f3795","frame_index":0,"kind":"data","monotonic_ns":310330116487166,"payload":{"event_type":"price_change","market":"0x779291bef19b6709f61e9764a954aafe9ffae488d50ae674aabdcb4f248006d5","price_changes":[{"asset_id":"8761897749749422724209054078244794145777693856614463256546737399611489089783","best_ask":"0.68","best_bid":"0.67","hash":"a92029d18feec7644d2cc0c4b657b899d73707c7","price":"0.67","side":"BUY","size":"32.6"},{"asset_id":"14965588658799411272385430903075831224615961675357217884735713260981483529984","best_ask":"0.33","best_bid":"0.32","hash":"489d26820c57bb4f2f10ba68b3272442145e9368","price":"0.33","side":"SELL","size":"32.6"}],"timestamp":"1785208332859"},"payload_hash":"ec6dfad6dbeef86f2a29448745f7200fc5e97832a3cef826c7a07631ff328d55","raw_frame":"{\"market\":\"0x779291bef19b6709f61e9764a954aafe9ffae488d50ae674aabdcb4f248006d5\", \"price_changes\":[{\"asset_id\":\"8761897749749422724209054078244794145777693856614463256546737399611489089783\", \"price\":\"0.67\", \"size\":\"32.6\", \"side\":\"BUY\", \"hash\":\"a92029d18feec7644d2cc0c4b657b899d73707c7\", \"best_bid\":\"0.67\", \"best_ask\":\"0.68\"}, {\"asset_id\":\"14965588658799411272385430903075831224615961675357217884735713260981483529984\", \"price\":\"0.33\", \"size\":\"32.6\", \"side\":\"SELL\", \"hash\":\"489d26820c57bb4f2f10ba68b3272442145e9368\", \"best_bid\":\"0.32\", \"best_ask\":\"0.33\"}], \"timestamp\":\"1785208332859\", \"event_type\":\"price_change\"}","received_at":"2026-07-28T03:12:27.081897Z","schema_version":"clob-market-ws.price_change.v1","sequence":null,"server_hash":null,"server_timestamp":"1785208332859","session_id":"3e519d9098404c15b234d96025eb1a2b","source":"clob_market_ws"},"received_at":"2026-07-28T03:12:27.081897Z","record_id":"179214b6157ac4df996657b0ab6dbd309abd901eaf30087999572902a7bc61c6","schema_fingerprint":"4aa3821a28b0b7c2400bc59aba4bcc0a76e971dadd19610d3ad38c768e124dc7","schema_version":"edge-lab-recorder.raw.v1","sequence":null,"source":"clob_market_ws"}
{"event_at":"2026-07-28T03:12:12.860000Z","event_fingerprint":"3371e7c8fb4820e3ae24696475efc84d15c2ba1819653562fe37159feab3950e","payload":{"connection_id":"a6b55582af5f430fb37ad02bf0922475","event_at":"2026-07-28T03:12:12.860000Z","event_type":"price_change","frame_hash":"104424180e8690bf6965a5a03e2989f8810252de2cc2bed9a3f5aa9f851d008f","frame_index":0,"kind":"data","monotonic_ns":310330118082375,"payload":{"event_type":"price_change","market":"0x779291bef19b6709f61e9764a954aafe9ffae488d50ae674aabdcb4f248006d5","price_changes":[{"asset_id":"8761897749749422724209054078244794145777693856614463256546737399611489089783","best_ask":"0.68","best_bid":"0.67","hash":"ac6c9b01169d1d4dbdb8510a8d4bf1db27318eef","price":"0.67","side":"BUY","size":"37.6"},{"asset_id":"14965588658799411272385430903075831224615961675357217884735713260981483529984","best_ask":"0.33","best_bid":"0.32","hash":"a9e667c6d4987e17c97c975ad38dfe003efe9c0d","price":"0.33","side":"SELL","size":"37.6"}],"timestamp":"1785208332860"},"payload_hash":"fe8fc276e1f6df9bbac07fd368093447167f089ce4a255b446e8d2c497405d0e","raw_frame":"{\"market\":\"0x779291bef19b6709f61e9764a954aafe9ffae488d50ae674aabdcb4f248006d5\", \"price_changes\":[{\"asset_id\":\"8761897749749422724209054078244794145777693856614463256546737399611489089783\", \"price\":\"0.67\", \"size\":\"37.6\", \"side\":\"BUY\", \"hash\":\"ac6c9b01169d1d4dbdb8510a8d4bf1db27318eef\", \"best_bid\":\"0.67\", \"best_ask\":\"0.68\"}, {\"asset_id\":\"14965588658799411272385430903075831224615961675357217884735713260981483529984\", \"price\":\"0.33\", \"size\":\"37.6\", \"side\":\"SELL\", \"hash\":\"a9e667c6d4987e17c97c975ad38dfe003efe9c0d\", \"best_bid\":\"0.32\", \"best_ask\":\"0.33\"}], \"timestamp\":\"1785208332860\", \"event_type\":\"price_change\"}","received_at":"2026-07-28T03:12:27.083492Z","schema_version":"clob-market-ws.price_change.v1","sequence":null,"server_hash":null,"server_timestamp":"1785208332860","session_id":"3e519d9098404c15b234d96025eb1a2b","source":"clob_market_ws"},"received_at":"2026-07-28T03:12:27.083492Z","record_id":"f7f86975785d9bf946ee978f7edd0b56e5f6194f8f03aec2e024c631aed89969","schema_fingerprint":"4aa3821a28b0b7c2400bc59aba4bcc0a76e971dadd19610d3ad38c768e124dc7","schema_version":"edge-lab-recorder.raw.v1","sequence":null,"source":"clob_market_ws"}
{"event_at":"2026-07-28T03:12:12.863000Z","event_fingerprint":"bad06533e1609a99bfe942f3ceb1381555b2ae184f822d4a7833888e34a7e29b","payload":{"connection_id":"a6b55582af5f430fb37ad02bf0922475","event_at":"2026-07-28T03:12:12.863000Z","event_type":"price_change","frame_hash":"bf601f0c815829468f570b7c5cba1cdef88731c0119a6f8e934d2cf46a677d8d","frame_index":0,"kind":"data","monotonic_ns":310330119570333,"payload":{"event_type":"price_change","market":"0x779291bef19b6709f61e9764a954aafe9ffae488d50ae674aabdcb4f248006d5","price_changes":[{"asset_id":"14965588658799411272385430903075831224615961675357217884735713260981483529984","best_ask":"0.33","best_bid":"0.32","hash":"cf343170a3dd9889a38527efc0ca9632fc5a6650","price":"0.32","side":"BUY","size":"12"},{"asset_id":"8761897749749422724209054078244794145777693856614463256546737399611489089783","best_ask":"0.68","best_bid":"0.67","hash":"a53d49c53373fa38254628bc49386a47d2f97b96","price":"0.68","side":"SELL","size":"12"}],"timestamp":"1785208332863"},"payload_hash":"504a34e1f056ba2fd2d7bdf4b06554ff3d5479b33fbae9a92b79993b2126d346","raw_frame":"{\"market\":\"0x779291bef19b6709f61e9764a954aafe9ffae488d50ae674aabdcb4f248006d5\", \"price_changes\":[{\"asset_id\":\"14965588658799411272385430903075831224615961675357217884735713260981483529984\", \"price\":\"0.32\", \"size\":\"12\", \"side\":\"BUY\", \"hash\":\"cf343170a3dd9889a38527efc0ca9632fc5a6650\", \"best_bid\":\"0.32\", \"best_ask\":\"0.33\"}, {\"asset_id\":\"8761897749749422724209054078244794145777693856614463256546737399611489089783\", \"price\":\"0.68\", \"size\":\"12\", \"side\":\"SELL\", \"hash\":\"a53d49c53373fa38254628bc49386a47d2f97b96\", \"best_bid\":\"0.67\", \"best_ask\":\"0.68\"}], \"timestamp\":\"1785208332863\", \"event_type\":\"price_change\"}","received_at":"2026-07-28T03:12:27.084980Z","schema_version":"clob-market-ws.price_change.v1","sequence":null,"server_hash":null,"server_timestamp":"1785208332863","session_id":"3e519d9098404c15b234d96025eb1a2b","source":"clob_market_ws"},"received_at":"2026-07-28T03:12:27.084980Z","record_id":"f675863248833c24fcb3b934ea5aec0283183282512aad9bf733075f2e2ad302","schema_fingerprint":"4aa3821a28b0b7c2400bc59aba4bcc0a76e971dadd19610d3ad38c768e124dc7","schema_version":"edge-lab-recorder.raw.v1","sequence":null,"source":"clob_market_ws"}
{"event_at":"2026-07-28T03:12:12.867000Z","event_fingerprint":"361f526d2f670360469d1955277841f296c576502ecaebf224046f7feb57787e","payload":{"connection_id":"a6b55582af5f430fb37ad02bf0922475","event_at":"2026-07-28T03:12:12.867000Z","event_type":"price_change","frame_hash":"6d497f1e98461b7c9f86814c0dfc25ebc6970777e0122da589cd01961d2d2e7d","frame_index":0,"kind":"data","monotonic_ns":310330121099125,"payload":{"event_type":"price_change","market":"0x779291bef19b6709f61e9764a954aafe9ffae488d50ae674aabdcb4f248006d5","price_changes":[{"asset_id":"8761897749749422724209054078244794145777693856614463256546737399611489089783","best_ask":"0.68","best_bid":"0.67","hash":"dee245dd965c944f100fdb4bc00ab7826da42f1d","price":"0.67","side":"BUY","size":"57.6"},{"asset_id":"14965588658799411272385430903075831224615961675357217884735713260981483529984","best_ask":"0.33","best_bid":"0.32","hash":"a90906890ac1532e6aa9ffa6f3ad4729e9253960","price":"0.33","side":"SELL","size":"57.6"}],"timestamp":"1785208332867"},"payload_hash":"935418995e73b77ec74632067edb887647b4847c39b1771199ee04af2cc0c657","raw_frame":"{\"market\":\"0x779291bef19b6709f61e9764a954aafe9ffae488d50ae674aabdcb4f248006d5\", \"price_changes\":[{\"asset_id\":\"8761897749749422724209054078244794145777693856614463256546737399611489089783\", \"price\":\"0.67\", \"size\":\"57.6\", \"side\":\"BUY\", \"hash\":\"dee245dd965c944f100fdb4bc00ab7826da42f1d\", \"best_bid\":\"0.67\", \"best_ask\":\"0.68\"}, {\"asset_id\":\"14965588658799411272385430903075831224615961675357217884735713260981483529984\", \"price\":\"0.33\", \"size\":\"57.6\", \"side\":\"SELL\", \"hash\":\"a90906890ac1532e6aa9ffa6f3ad4729e9253960\", \"best_bid\":\"0.32\", \"best_ask\":\"0.33\"}], \"timestamp\":\"1785208332867\", \"event_type\":\"price_change\"}","received_at":"2026-07-28T03:12:27.086509Z","schema_version":"clob-market-ws.price_change.v1","sequence":null,"server_hash":null,"server_timestamp":"1785208332867","session_id":"3e519d9098404c15b234d96025eb1a2b","source":"clob_market_ws"},"received_at":"2026-07-28T03:12:27.086509Z","record_id":"466d2954289cb2d9667a2216a9b9d7e7822374e9253fca2872327a4d07ec74d4","schema_fingerprint":"4aa3821a28b0b7c2400bc59aba4bcc0a76e971dadd19610d3ad38c768e124dc7","schema_version":"edge-lab-recorder.raw.v1","sequence":null,"source":"clob_market_ws"}
{"event_at":"2026-07-28T03:12:12.869000Z","event_fingerprint":"8cf3fe0679cade7138fb825fe534f503e2bcdd98cf2d8da9d42f560329a0e418","payload":{"connection_id":"a6b55582af5f430fb37ad02bf0922475","event_at":"2026-07-28T03:12:12.869000Z","event_type":"price_change","frame_hash":"9f7c5fb7968af7c497cfaa3e90d0d37ffd3eafb73d783176e059b335d4e148dc","frame_index":0,"kind":"data","monotonic_ns":310330122584375,"payload":{"event_type":"price_change","market":"0x779291bef19b6709f61e9764a954aafe9ffae488d50ae674aabdcb4f248006d5","price_changes":[{"asset_id":"14965588658799411272385430903075831224615961675357217884735713260981483529984","best_ask":"0.33","best_bid":"0.32","hash":"332b7640de4a6a0e92d057e25a809e8bfb5ca48d","price":"0.29","side":"BUY","size":"56.15"},{"asset_id":"8761897749749422724209054078244794145777693856614463256546737399611489089783","best_ask":"0.68","best_bid":"0.67","hash":"4b7101ec7455353ee885f5a2b8312c03e078dbee","price":"0.71","side":"SELL","size":"56.15"}],"timestamp":"1785208332869"},"payload_hash":"fe315a7fc34673fdc7f531e04b0ada4fd60d364f722e472e8f93022375649753","raw_frame":"{\"market\":\"0x779291bef19b6709f61e9764a954aafe9ffae488d50ae674aabdcb4f248006d5\", \"price_changes\":[{\"asset_id\":\"14965588658799411272385430903075831224615961675357217884735713260981483529984\", \"price\":\"0.29\", \"size\":\"56.15\", \"side\":\"BUY\", \"hash\":\"332b7640de4a6a0e92d057e25a809e8bfb5ca48d\", \"best_bid\":\"0.32\", \"best_ask\":\"0.33\"}, {\"asset_id\":\"8761897749749422724209054078244794145777693856614463256546737399611489089783\", \"price\":\"0.71\", \"size\":\"56.15\", \"side\":\"SELL\", \"hash\":\"4b7101ec7455353ee885f5a2b8312c03e078dbee\", \"best_bid\":\"0.67\", \"best_ask\":\"0.68\"}], \"timestamp\":\"1785208332869\", \"event_type\":\"price_change\"}","received_at":"2026-07-28T03:12:27.087994Z","schema_version":"clob-market-ws.price_change.v1","sequence":null,"server_hash":null,"server_timestamp":"1785208332869","session_id":"3e519d9098404c15b234d96025eb1a2b","source":"clob_market_ws"},"received_at":"2026-07-28T03:12:27.087994Z","record_id":"9fd97f12a1dc5de2dc12ef94597cb37b4ffe6a6152eb9ad0333be8461338c6a0","schema_fingerprint":"4aa3821a28b0b7c2400bc59aba4bcc0a76e971dadd19610d3ad38c768e124dc7","schema_version":"edge-lab-recorder.raw.v1","sequence":null,"source":"clob_market_ws"}
{"event_at":"2026-07-28T03:12:12.872000Z","event_fingerprint":"a4f3fa23279cfad97a51242d0d94e0d37a31c4a8076a5c59b22cf2fd3f08d9e2","payload":{"connection_id":"a6b55582af5f430fb37ad02bf0922475","event_at":"2026-07-28T03:12:12.872000Z","event_type":"price_change","frame_hash":"f41bab2c46a8da5223f6f3f604fcf04fb62937e30c2c2fc4031843d8c8215bd0","frame_index":0,"kind":"data","monotonic_ns":310330124097833,"payload":{"event_type":"price_change","market":"0x779291bef19b6709f61e9764a954aafe9ffae488d50ae674aabdcb4f248006d5","price_changes":[{"asset_id":"8761897749749422724209054078244794145777693856614463256546737399611489089783","best_ask":"0.68","best_bid":"0.67","hash":"71b644d36c4b8ea2fb949c3374a8fb233e869d8d","price":"0.68","side":"SELL","size":"18"},{"asset_id":"14965588658799411272385430903075831224615961675357217884735713260981483529984","best_ask":"0.33","best_bid":"0.32","hash":"01d710f077b42659f23b9f22f4ad43e370e78d1c","price":"0.32","side":"BUY","size":"18"}],"timestamp":"1785208332872"},"payload_hash":"191d01015f7e81b91e36af2374fc5236bc0cd1b38d24bc821517bd121e60bf1b","raw_frame":"{\"market\":\"0x779291bef19b6709f61e9764a954aafe9ffae488d50ae674aabdcb4f248006d5\", \"price_changes\":[{\"asset_id\":\"8761897749749422724209054078244794145777693856614463256546737399611489089783\", \"price\":\"0.68\", \"size\":\"18\", \"side\":\"SELL\", \"hash\":\"71b644d36c4b8ea2fb949c3374a8fb233e869d8d\", \"best_bid\":\"0.67\", \"best_ask\":\"0.68\"}, {\"asset_id\":\"14965588658799411272385430903075831224615961675357217884735713260981483529984\", \"price\":\"0.32\", \"size\":\"18\", \"side\":\"BUY\", \"hash\":\"01d710f077b42659f23b9f22f4ad43e370e78d1c\", \"best_bid\":\"0.32\", \"best_ask\":\"0.33\"}], \"timestamp\":\"1785208332872\", \"event_type\":\"price_change\"}","received_at":"2026-07-28T03:12:27.089508Z","schema_version":"clob-market-ws.price_change.v1","sequence":null,"server_hash":null,"server_timestamp":"1785208332872","session_id":"3e519d9098404c15b234d96025eb1a2b","source":"clob_market_ws"},"received_at":"2026-07-28T03:12:27.089508Z","record_id":"ee8beaf8d9203a39e6f6f771f783979504ac99a3e9175aa0381ac673705453ca","schema_fingerprint":"4aa3821a28b0b7c2400bc59aba4bcc0a76e971dadd19610d3ad38c768e124dc7","schema_version":"edge-lab-recorder.raw.v1","sequence":null,"source":"clob_market_ws"}
{"event_at":"2026-07-28T03:12:12.877000Z","event_fingerprint":"b0d37e4f166eecfe252081496f23af46e6eb2c4031350468c55cd8be27d0e5ba","payload":{"connection_id":"a6b55582af5f430fb37ad02bf0922475","event_at":"2026-07-28T03:12:12.877000Z","event_type":"price_change","frame_hash":"8da7488d1e0a0429850a2b019633275a2ac0d66bfe1bf59ccffff82dcb6add21","frame_index":0,"kind":"data","monotonic_ns":310330125585250,"payload":{"event_type":"price_change","market":"0x779291bef19b6709f61e9764a954aafe9ffae488d50ae674aabdcb4f248006d5","price_changes":[{"asset_id":"14965588658799411272385430903075831224615961675357217884735713260981483529984","best_ask":"0.33","best_bid":"0.32","hash":"898f712e4ed155237224b569aa6aa896065b119a","price":"0.27","side":"BUY","size":"52"},{"asset_id":"8761897749749422724209054078244794145777693856614463256546737399611489089783","best_ask":"0.68","best_bid":"0.67","hash":"dc06b9bc4547ff7b5b5d1d316a34de4a25fdfae1","price":"0.73","side":"SELL","size":"52"}],"timestamp":"1785208332877"},"payload_hash":"46653da28c57c2d284838576fea90d455bea43e69aa9025d237908d2a6643666","raw_frame":"{\"market\":\"0x779291bef19b6709f61e9764a954aafe9ffae488d50ae674aabdcb4f248006d5\", \"price_changes\":[{\"asset_id\":\"14965588658799411272385430903075831224615961675357217884735713260981483529984\", \"price\":\"0.27\", \"size\":\"52\", \"side\":\"BUY\", \"hash\":\"898f712e4ed155237224b569aa6aa896065b119a\", \"best_bid\":\"0.32\", \"best_ask\":\"0.33\"}, {\"asset_id\":\"8761897749749422724209054078244794145777693856614463256546737399611489089783\", \"price\":\"0.73\", \"size\":\"52\", \"side\":\"SELL\", \"hash\":\"dc06b9bc4547ff7b5b5d1d316a34de4a25fdfae1\", \"best_bid\":\"0.67\", \"best_ask\":\"0.68\"}], \"timestamp\":\"1785208332877\", \"event_type\":\"price_change\"}","received_at":"2026-07-28T03:12:27.090995Z","schema_version":"clob-market-ws.price_change.v1","sequence":null,"server_hash":null,"server_timestamp":"1785208332877","session_id":"3e519d9098404c15b234d96025eb1a2b","source":"clob_market_ws"},"received_at":"2026-07-28T03:12:27.090995Z","record_id":"844f63e972be9f7d15df093b18ae107e0c8a25425615439fd2a24bebd1089c6a","schema_fingerprint":"4aa3821a28b0b7c2400bc59aba4bcc0a76e971dadd19610d3ad38c768e124dc7","schema_version":"edge-lab-recorder.raw.v1","sequence":null,"source":"clob_market_ws"}
{"event_at":"2026-07-28T03:12:12.883000Z","event_fingerprint":"ccff7791eb8822bab8a5886259df241cc635ba35abe0dc602f762b5f40ebf82a","payload":{"connection_id":"a6b55582af5f430fb37ad02bf0922475","event_at":"2026-07-28T03:12:12.883000Z","event_type":"price_change","frame_hash":"c66c9c9b251a09dfed3d0541aa2083ed318b83a7a9d72f452be0141d5f8a67f7","frame_index":0,"kind":"data","monotonic_ns":310330127061041,"payload":{"event_type":"price_change","market":"0x779291bef19b6709f61e9764a954aafe9ffae488d50ae674aabdcb4f248006d5","price_changes":[{"asset_id":"8761897749749422724209054078244794145777693856614463256546737399611489089783","best_ask":"0.68","best_bid":"0.67","hash":"f1c74c72f372f991dd60fd63c51004249b4506fb","price":"0.67","side":"BUY","size":"37.6"},{"asset_id":"14965588658799411272385430903075831224615961675357217884735713260981483529984","best_ask":"0.33","best_bid":"0.32","hash":"e4ba4370348c7d66516c9d5d861940a41cc30d09","price":"0.33","side":"SELL","size":"37.6"}],"timestamp":"1785208332883"},"payload_hash":"cfd68446b3721108d3dc9a53b13956f27076215e083066266b2befe12f5150bc","raw_frame":"{\"market\":\"0x779291bef19b6709f61e9764a954aafe9ffae488d50ae674aabdcb4f248006d5\", \"price_changes\":[{\"asset_id\":\"8761897749749422724209054078244794145777693856614463256546737399611489089783\", \"price\":\"0.67\", \"size\":\"37.6\", \"side\":\"BUY\", \"hash\":\"f1c74c72f372f991dd60fd63c51004249b4506fb\", \"best_bid\":\"0.67\", \"best_ask\":\"0.68\"}, {\"asset_id\":\"14965588658799411272385430903075831224615961675357217884735713260981483529984\", \"price\":\"0.33\", \"size\":\"37.6\", \"side\":\"SELL\", \"hash\":\"e4ba4370348c7d66516c9d5d861940a41cc30d09\", \"best_bid\":\"0.32\", \"best_ask\":\"0.33\"}], \"timestamp\":\"1785208332883\", \"event_type\":\"price_change\"}","received_at":"2026-07-28T03:12:27.092470Z","schema_version":"clob-market-ws.price_change.v1","sequence":null,"server_hash":null,"server_timestamp":"1785208332883","session_id":"3e519d9098404c15b234d96025eb1a2b","source":"clob_market_ws"},"received_at":"2026-07-28T03:12:27.092470Z","record_id":"b3804f325bd9a82c9eb68518be029450807f16d5042eafe3a5be7a1c48ee9978","schema_fingerprint":"4aa3821a28b0b7c2400bc59aba4bcc0a76e971dadd19610d3ad38c768e124dc7","schema_version":"edge-lab-recorder.raw.v1","sequence":null,"source":"clob_market_ws"}
{"event_at":"2026-07-28T03:12:12.884000Z","event_fingerprint":"edb7174b5f676ccaff5314b845def74428f8940839b8efbe542ddb1161d67986","payload":{"connection_id":"a6b55582af5f430fb37ad02bf0922475","event_at":"2026-07-28T03:12:12.884000Z","event_type":"price_change","frame_hash":"466884795bd49cdf623d537d01270846fd75f390a92c061ea52caeabd5c6fe25","frame_index":0,"kind":"data","monotonic_ns":310330128550000,"payload":{"event_type":"price_change","market":"0x779291bef19b6709f61e9764a954aafe9ffae488d50ae674aabdcb4f248006d5","price_changes":[{"asset_id":"8761897749749422724209054078244794145777693856614463256546737399611489089783","best_ask":"0.68","best_bid":"0.67","hash":"6ab12b6af98ff9b5d6eda78d51174378e6153729","price":"0.01","side":"BUY","size":"5305.02"},{"asset_id":"14965588658799411272385430903075831224615961675357217884735713260981483529984","best_ask":"0.33","best_bid":"0.32","hash":"5c4026ccfea2d74fd76d833ed860aae8c0dd6e60","price":"0.99","side":"SELL","size":"5305.02"}],"timestamp":"1785208332884"},"payload_hash":"f95dda49759aa4a3760021044baec08c6bad17eea80659c2076fd2217de66e06","raw_frame":"{\"market\":\"0x779291bef19b6709f61e9764a954aafe9ffae488d50ae674aabdcb4f248006d5\", \"price_changes\":[{\"asset_id\":\"8761897749749422724209054078244794145777693856614463256546737399611489089783\", \"price\":\"0.01\", \"size\":\"5305.02\", \"side\":\"BUY\", \"hash\":\"6ab12b6af98ff9b5d6eda78d51174378e6153729\", \"best_bid\":\"0.67\", \"best_ask\":\"0.68\"}, {\"asset_id\":\"14965588658799411272385430903075831224615961675357217884735713260981483529984\", \"price\":\"0.99\", \"size\":\"5305.02\", \"side\":\"SELL\", \"hash\":\"5c4026ccfea2d74fd76d833ed860aae8c0dd6e60\", \"best_bid\":\"0.32\", \"best_ask\":\"0.33\"}], \"timestamp\":\"1785208332884\", \"event_type\":\"price_change\"}","received_at":"2026-07-28T03:12:27.093958Z","schema_version":"clob-market-ws.price_change.v1","sequence":null,"server_hash":null,"server_timestamp":"1785208332884","session_id":"3e519d9098404c15b234d96025eb1a2b","source":"clob_market_ws"},"received_at":"2026-07-28T03:12:27.093958Z","record_id":"6b2e01c53aab201e40269b1c02b69e0210a76558815fc422917cdec4bba518d0","schema_fingerprint":"4aa3821a28b0b7c2400bc59aba4bcc0a76e971dadd19610d3ad38c768e124dc7","schema_version":"edge-lab-recorder.raw.v1","sequence":null,"source":"clob_market_ws"}
{"event_at":"2026-07-28T03:12:12.893000Z","event_fingerprint":"942c7523fe2b03b2746b2fcffa00ffee5537511a68d4e50940cffa407c35d438","payload":{"connection_id":"a6b55582af5f430fb37ad02bf0922475","event_at":"2026-07-28T03:12:12.893000Z","event_type":"new_market","frame_hash":"ad9f47c2a7ccb0cf8953b1d541d58eaa47f4b5a33cbe3bea518be8848b0d94a7","frame_index":0,"kind":"data","monotonic_ns":310330130045375,"payload":{"active":false,"assets_ids":["106379960194684366688656574511112072661231449433834617656537896627289303154625","65333919215206528121182234055213713449284048576459549421563788171869084511918"],"clob_token_ids":["106379960194684366688656574511112072661231449433834617656537896627289303154625","65333919215206528121182234055213713449284048576459549421563788171869084511918"],"condition_id":"0x97ef0bc5682a46bfbcf175295f8bfe83cb28e5f184a2bef2dad5da3355f33656","description":"Donald Trump is scheduled to appear on FOX & Friends on July 28 at 8:30 AM ET.\n\nThis market will resolve to \"Yes\" if Donald Trump says the listed term during his appearance at this event. Otherwise, the market will resolve to \"No.\"\n\nThis market is explicitly about the scheduled Fox & Friends interview. Speeches, events, or comments that occur outside of this event will not qualify toward this market's resolution.\n\nIf this event is definitively cancelled or otherwise is not aired by July 29, 2026, 11:59 PM ET, \"-No Qualifying Event-\" will resolve to \"Yes\" and all other brackets will resolve to \"No\".\n\nThe resolution source is the video/audio of the event.\n\nFor full rules, see: https://polymarket-upload.s3.us-east-2.amazonaws.com/market_products/Event+Mentions+Contract+DeFi.pdf","event_message":{"description":"Donald Trump is scheduled to appear on FOX & Friends on July 28 at 8:30 AM ET.\n\nThis market will resolve to \"Yes\" if Donald Trump says the listed term during his appearance at this event. Otherwise, the market will resolve to \"No.\"\n\nThis market is explicitly about the scheduled Fox & Friends interview. Speeches, events, or comments that occur outside of this event will not qualify toward this market's resolution.\n\nIf this event is definitively cancelled or otherwise is not aired by July 29, 2026, 11:59 PM ET, \"-No Qualifying Event-\" will resolve to \"Yes\" and all other brackets will resolve to \"No\".\n\nThe resolution source is the video/audio of the event.\n\nFor full rules, see: https://polymarket-upload.s3.us-east-2.amazonaws.com/market_products/Event+Mentions+Contract+DeFi.pdf","id":"759173","slug":"what-will-trump-say-on-fox-news-fox-friends-20260728022316498","ticker":"what-will-trump-say-on-fox-news-fox-friends-20260728022316498","title":"What will Trump say on Fox News: Fox & Friends?"},"event_type":"new_market","fee_schedule":{"exponent":"1","rate":"0.04","rebate_rate":"0.25","taker_only":true},"fees_enabled":true,"game_start_time":"","group_item_title":"-No Qualifying Event-","id":"3145111","line":"","market":"0x97ef0bc5682a46bfbcf175295f8bfe83cb28e5f184a2bef2dad5da3355f33656","order_price_min_tick_size":"0.01","outcomes":["Yes","No"],"question":"Will Trump’s remarks not air?","slug":"will-trumps-remarks-not-air-20260728022316515","sports_market_type":"","tags":[],"taker_base_fee":"1000","timestamp":"1785208332893"},"payload_hash":"249252b6894c30d98fe77baef524248ad9ab0f4c7403c91f5807c174957ce68a","raw_frame":"{\"id\":\"3145111\", \"question\":\"Will Trump’s remarks not air?\", \"market\":\"0x97ef0bc5682a46bfbcf175295f8bfe83cb28e5f184a2bef2dad5da3355f33656\", \"slug\":\"will-trumps-remarks-not-air-20260728022316515\", \"description\":\"Donald Trump is scheduled to appear on FOX & Friends on July 28 at 8:30 AM ET.\\n\\nThis market will resolve to \\\"Yes\\\" if Donald Trump says the listed term during his appearance at this event. Otherwise, the market will resolve to \\\"No.\\\"\\n\\nThis market is explicitly about the scheduled Fox & Friends interview. Speeches, events, or comments that occur outside of this event will not qualify toward this market's resolution.\\n\\nIf this event is definitively cancelled or otherwise is not aired by July 29, 2026, 11:59 PM ET, \\\"-No Qualifying Event-\\\" will resolve to \\\"Yes\\\" and all other brackets will resolve to \\\"No\\\".\\n\\nThe resolution source is the video/audio of the event.\\n\\nFor full rules, see: https://polymarket-upload.s3.us-east-2.amazonaws.com/market_products/Event+Mentions+Contract+DeFi.pdf\", \"assets_ids\":[\"106379960194684366688656574511112072661231449433834617656537896627289303154625\", \"65333919215206528121182234055213713449284048576459549421563788171869084511918\"], \"outcomes\":[\"Yes\", \"No\"], \"event_message\":{\"id\":\"759173\", \"ticker\":\"what-will-trump-say-on-fox-news-fox-friends-20260728022316498\", \"slug\":\"what-will-trump-say-on-fox-news-fox-friends-20260728022316498\", \"title\":\"What will Trump say on Fox News: Fox & Friends?\", \"description\":\"Donald Trump is scheduled to appear on FOX & Friends on July 28 at 8:30 AM ET.\\n\\nThis market will resolve to \\\"Yes\\\" if Donald Trump says the listed term during his appearance at this event. Otherwise, the market will resolve to \\\"No.\\\"\\n\\nThis market is explicitly about the scheduled Fox & Friends interview. Speeches, events, or comments that occur outside of this event will not qualify toward this market's resolution.\\n\\nIf this event is definitively cancelled or otherwise is not aired by July 29, 2026, 11:59 PM ET, \\\"-No Qualifying Event-\\\" will resolve to \\\"Yes\\\" and all other brackets will resolve to \\\"No\\\".\\n\\nThe resolution source is the video/audio of the event.\\n\\nFor full rules, see: https://polymarket-upload.s3.us-east-2.amazonaws.com/market_products/Event+Mentions+Contract+DeFi.pdf\"}, \"timestamp\":\"1785208332893\", \"event_type\":\"new_market\", \"tags\":[], \"condition_id\":\"0x97ef0bc5682a46bfbcf175295f8bfe83cb28e5f184a2bef2dad5da3355f33656\", \"active\":false, \"clob_token_ids\":[\"106379960194684366688656574511112072661231449433834617656537896627289303154625\", \"65333919215206528121182234055213713449284048576459549421563788171869084511918\"], \"sports_market_type\":\"\", \"line\":\"\", \"game_start_time\":\"\", \"order_price_min_tick_size\":\"0.01\", \"group_item_title\":\"-No Qualifying Event-\", \"taker_base_fee\":\"1000\", \"fees_enabled\":true, \"fee_schedule\":{\"exponent\":\"1\", \"rate\":\"0.04\", \"taker_only\":true, \"rebate_rate\":\"0.25\"}}","received_at":"2026-07-28T03:12:27.095452Z","schema_version":"clob-market-ws.new_market.v1","sequence":null,"server_hash":null,"server_timestamp":"1785208332893","session_id":"3e519d9098404c15b234d96025eb1a2b","source":"clob_market_ws"},"received_at":"2026-07-28T03:12:27.095452Z","record_id":"7640668e85cfba0cde422350d48e2589cca17a2f1861ca2ccdc385ee28f4e0d8","schema_fingerprint":"6639a822a7b79cfa4c3fc0044066e4f66ba8611f5bf361772bd6902a2319b82d","schema_version":"edge-lab-recorder.raw.v1","sequence":null,"source":"clob_market_ws"}
{"event_at":"2026-07-28T03:12:12.895000Z","event_fingerprint":"0e7c0efca48a1dc65bbe19fdb6d510250bdeff45ac0bccd0a098703cd097d035","payload":{"connection_id":"a6b55582af5f430fb37ad02bf0922475","event_at":"2026-07-28T03:12:12.895000Z","event_type":"price_change","frame_hash":"dcf8387f1a4f0a89c20f1ce797aacdec27c911ffce747d1870b56250989ccd0a","frame_index":0,"kind":"data","monotonic_ns":310330132200208,"payload":{"event_type":"price_change","market":"0x779291bef19b6709f61e9764a954aafe9ffae488d50ae674aabdcb4f248006d5","price_changes":[{"asset_id":"8761897749749422724209054078244794145777693856614463256546737399611489089783","best_ask":"0.68","best_bid":"0.67","hash":"5e1e5d4f484dd8347a1b9e6a60d3bcc0f109f356","price":"0.66","side":"BUY","size":"423.6"},{"asset_id":"14965588658799411272385430903075831224615961675357217884735713260981483529984","best_ask":"0.33","best_bid":"0.32","hash":"6f0b21f43de83f864311094708c9fb0e156b5283","price":"0.34","side":"SELL","size":"423.6"}],"timestamp":"1785208332895"},"payload_hash":"60902da8305a6d1543bb63a345f2aa282957fc8399dadf37ed3d550be9f84a09","raw_frame":"{\"market\":\"0x779291bef19b6709f61e9764a954aafe9ffae488d50ae674aabdcb4f248006d5\", \"price_changes\":[{\"asset_id\":\"8761897749749422724209054078244794145777693856614463256546737399611489089783\", \"price\":\"0.66\", \"size\":\"423.6\", \"side\":\"BUY\", \"hash\":\"5e1e5d4f484dd8347a1b9e6a60d3bcc0f109f356\", \"best_bid\":\"0.67\", \"best_ask\":\"0.68\"}, {\"asset_id\":\"14965588658799411272385430903075831224615961675357217884735713260981483529984\", \"price\":\"0.34\", \"size\":\"423.6\", \"side\":\"SELL\", \"hash\":\"6f0b21f43de83f864311094708c9fb0e156b5283\", \"best_bid\":\"0.32\", \"best_ask\":\"0.33\"}], \"timestamp\":\"1785208332895\", \"event_type\":\"price_change\"}","received_at":"2026-07-28T03:12:27.097609Z","schema_version":"clob-market-ws.price_change.v1","sequence":null,"server_hash":null,"server_timestamp":"1785208332895","session_id":"3e519d9098404c15b234d96025eb1a2b","source":"clob_market_ws"},"received_at":"2026-07-28T03:12:27.097609Z","record_id":"96c4cd0c5da286699d6a8d189e669c3e0b4a781be6c195f14cbee3674d35d603","schema_fingerprint":"4aa3821a28b0b7c2400bc59aba4bcc0a76e971dadd19610d3ad38c768e124dc7","schema_version":"edge-lab-recorder.raw.v1","sequence":null,"source":"clob_market_ws"}
{"event_at":"2026-07-28T03:12:12.899000Z","event_fingerprint":"4cc2bd5b422539789b5f6282402ad2afe042baa6f380ef17c0e618e771411e4f","payload":{"connection_id":"a6b55582af5f430fb37ad02bf0922475","event_at":"2026-07-28T03:12:12.899000Z","event_type":"price_change","frame_hash":"682e89eaf31a44eae3b11332a29e623eb7198b57f874a0ac77bf0c5995a77d3c","frame_index":0,"kind":"data","monotonic_ns":310330133788791,"payload":{"event_type":"price_change","market":"0x779291bef19b6709f61e9764a954aafe9ffae488d50ae674aabdcb4f248006d5","price_changes":[{"asset_id":"14965588658799411272385430903075831224615961675357217884735713260981483529984","best_ask":"0.33","best_bid":"0.32","hash":"149563d0d295451f39a86af1aa648b30d99f4f47","price":"0.26","side":"BUY","size":"129"},{"asset_id":"8761897749749422724209054078244794145777693856614463256546737399611489089783","best_ask":"0.68","best_bid":"0.67","hash":"3587b591205de308d51455a2252232ec9b8bb8dd","price":"0.74","side":"SELL","size":"129"}],"timestamp":"1785208332899"},"payload_hash":"c4fc6de94eb23e0efd5f85509bcbfdb432a7af0b4fc5b5e05dd756aa91eb416e","raw_frame":"{\"market\":\"0x779291bef19b6709f61e9764a954aafe9ffae488d50ae674aabdcb4f248006d5\", \"price_changes\":[{\"asset_id\":\"14965588658799411272385430903075831224615961675357217884735713260981483529984\", \"price\":\"0.26\", \"size\":\"129\", \"side\":\"BUY\", \"hash\":\"149563d0d295451f39a86af1aa648b30d99f4f47\", \"best_bid\":\"0.32\", \"best_ask\":\"0.33\"}, {\"asset_id\":\"8761897749749422724209054078244794145777693856614463256546737399611489089783\", \"price\":\"0.74\", \"size\":\"129\", \"side\":\"SELL\", \"hash\":\"3587b591205de308d51455a2252232ec9b8bb8dd\", \"best_bid\":\"0.67\", \"best_ask\":\"0.68\"}], \"timestamp\":\"1785208332899\", \"event_type\":\"price_change\"}","received_at":"2026-07-28T03:12:27.099188Z","schema_version":"clob-market-ws.price_change.v1","sequence":null,"server_hash":null,"server_timestamp":"1785208332899","session_id":"3e519d9098404c15b234d96025eb1a2b","source":"clob_market_ws"},"received_at":"2026-07-28T03:12:27.099188Z","record_id":"f4b94067ff318ce6ae60aa9872b0053cb67b0c24fd149e17a77606bbc9add652","schema_fingerprint":"4aa3821a28b0b7c2400bc59aba4bcc0a76e971dadd19610d3ad38c768e124dc7","schema_version":"edge-lab-recorder.raw.v1","sequence":null,"source":"clob_market_ws"}
{"event_at":"2026-07-28T03:12:12.918000Z","event_fingerprint":"4b51bf8f6b323d98e9b7f8d2d9726f08e2d27442c3dcb9fe436987fc0a9a29f5","payload":{"connection_id":"a6b55582af5f430fb37ad02bf0922475","event_at":"2026-07-28T03:12:12.918000Z","event_type":"price_change","frame_hash":"312050e4542eb84ce7613fb1c9ce8ea66d500f1bdaf903355e6a338fd7130466","frame_index":0,"kind":"data","monotonic_ns":310330135594458,"payload":{"event_type":"price_change","market":"0x779291bef19b6709f61e9764a954aafe9ffae488d50ae674aabdcb4f248006d5","price_changes":[{"asset_id":"8761897749749422724209054078244794145777693856614463256546737399611489089783","best_ask":"0.68","best_bid":"0.67","hash":"1bd68f22dacb1a5501dba6e27730c2073b7a8411","price":"0.67","side":"BUY","size":"47.6"},{"asset_id":"14965588658799411272385430903075831224615961675357217884735713260981483529984","best_ask":"0.33","best_bid":"0.32","hash":"0589979232e18f5da4e3237b3bd1b747b5d742fb","price":"0.33","side":"SELL","size":"47.6"}],"timestamp":"1785208332918"},"payload_hash":"26362774ccc36ed4404f1bbded9b92f18b75c744da927103ef5d348f7840c954","raw_frame":"{\"market\":\"0x779291bef19b6709f61e9764a954aafe9ffae488d50ae674aabdcb4f248006d5\", \"price_changes\":[{\"asset_id\":\"8761897749749422724209054078244794145777693856614463256546737399611489089783\", \"price\":\"0.67\", \"size\":\"47.6\", \"side\":\"BUY\", \"hash\":\"1bd68f22dacb1a5501dba6e27730c2073b7a8411\", \"best_bid\":\"0.67\", \"best_ask\":\"0.68\"}, {\"asset_id\":\"14965588658799411272385430903075831224615961675357217884735713260981483529984\", \"price\":\"0.33\", \"size\":\"47.6\", \"side\":\"SELL\", \"hash\":\"0589979232e18f5da4e3237b3bd1b747b5d742fb\", \"best_bid\":\"0.32\", \"best_ask\":\"0.33\"}], \"timestamp\":\"1785208332918\", \"event_type\":\"price_change\"}","received_at":"2026-07-28T03:12:27.101001Z","schema_version":"clob-market-ws.price_change.v1","sequence":null,"server_hash":null,"server_timestamp":"1785208332918","session_id":"3e519d9098404c15b234d96025eb1a2b","source":"clob_market_ws"},"received_at":"2026-07-28T03:12:27.101001Z","record_id":"17fa000cc7c3103c80fd290987948d24d3d27646788ca3d8677de2f36378657b","schema_fingerprint":"4aa3821a28b0b7c2400bc59aba4bcc0a76e971dadd19610d3ad38c768e124dc7","schema_version":"edge-lab-recorder.raw.v1","sequence":null,"source":"clob_market_ws"}
{"event_at":"2026-07-28T03:12:12.930000Z","event_fingerprint":"9a15826bf90ae6da50691237affb2b1495facdff3554a5320cb685da0aa2e8b8","payload":{"connection_id":"a6b55582af5f430fb37ad02bf0922475","event_at":"2026-07-28T03:12:12.930000Z","event_type":"price_change","frame_hash":"497129db3bf81aa531d7060268d586217a1c1761dbcc695723e9c221de8f0802","frame_index":0,"kind":"data","monotonic_ns":310330137186791,"payload":{"event_type":"price_change","market":"0x779291bef19b6709f61e9764a954aafe9ffae488d50ae674aabdcb4f248006d5","price_changes":[{"asset_id":"8761897749749422724209054078244794145777693856614463256546737399611489089783","best_ask":"0.68","best_bid":"0.67","hash":"fe266243837b9cb752b02d9d624db17a711c0658","price":"0.53","side":"BUY","size":"135"},{"asset_id":"14965588658799411272385430903075831224615961675357217884735713260981483529984","best_ask":"0.33","best_bid":"0.32","hash":"701a3e566b886c042253cec790f63e4f5328c07a","price":"0.47","side":"SELL","size":"135"}],"timestamp":"1785208332930"},"payload_hash":"8c9dca012161b2ebf3c3a1f365bb4938e2eea89307f88382c1c3d0d356fbc746","raw_frame":"{\"market\":\"0x779291bef19b6709f61e9764a954aafe9ffae488d50ae674aabdcb4f248006d5\", \"price_changes\":[{\"asset_id\":\"8761897749749422724209054078244794145777693856614463256546737399611489089783\", \"price\":\"0.53\", \"size\":\"135\", \"side\":\"BUY\", \"hash\":\"fe266243837b9cb752b02d9d624db17a711c0658\", \"best_bid\":\"0.67\", \"best_ask\":\"0.68\"}, {\"asset_id\":\"14965588658799411272385430903075831224615961675357217884735713260981483529984\", \"price\":\"0.47\", \"size\":\"135\", \"side\":\"SELL\", \"hash\":\"701a3e566b886c042253cec790f63e4f5328c07a\", \"best_bid\":\"0.32\", \"best_ask\":\"0.33\"}], \"timestamp\":\"1785208332930\", \"event_type\":\"price_change\"}","received_at":"2026-07-28T03:12:27.102596Z","schema_version":"clob-market-ws.price_change.v1","sequence":null,"server_hash":null,"server_timestamp":"1785208332930","session_id":"3e519d9098404c15b234d96025eb1a2b","source":"clob_market_ws"},"received_at":"2026-07-28T03:12:27.102596Z","record_id":"73e07f380dc83a1ffcbbae72a8c6d0442b2d34187935302cdcd46fd8d4d5c7e7","schema_fingerprint":"4aa3821a28b0b7c2400bc59aba4bcc0a76e971dadd19610d3ad38c768e124dc7","schema_version":"edge-lab-recorder.raw.v1","sequence":null,"source":"clob_market_ws"}
{"event_at":"2026-07-28T03:12:12.937000Z","event_fingerprint":"92f590d288ab4623e9882962da1988c9e45f066c9c1877cf17997c08b1a7ef19","payload":{"connection_id":"a6b55582af5f430fb37ad02bf0922475","event_at":"2026-07-28T03:12:12.937000Z","event_type":"price_change","frame_hash":"b22d3c3b2b64025e42052f9d0b64ca10cd024978308e71cffa4243c4f4492ee0","frame_index":0,"kind":"data","monotonic_ns":310330138703125,"payload":{"event_type":"price_change","market":"0x779291bef19b6709f61e9764a954aafe9ffae488d50ae674aabdcb4f248006d5","price_changes":[{"asset_id":"8761897749749422724209054078244794145777693856614463256546737399611489089783","best_ask":"0.68","best_bid":"0.67","hash":"5a2642864b4d3588f22401bb87428981e63d15b2","price":"0.49","side":"BUY","size":"47.01"},{"asset_id":"14965588658799411272385430903075831224615961675357217884735713260981483529984","best_ask":"0.33","best_bid":"0.32","hash":"06fc766e12c604fcc0d5281f7c311375c8ccc4ba","price":"0.51","side":"SELL","size":"47.01"}],"timestamp":"1785208332937"},"payload_hash":"46506675c21882753fa836e0db27ea5a60d2229cee457ae5c5382a5144498a33","raw_frame":"{\"market\":\"0x779291bef19b6709f61e9764a954aafe9ffae488d50ae674aabdcb4f248006d5\", \"price_changes\":[{\"asset_id\":\"8761897749749422724209054078244794145777693856614463256546737399611489089783\", \"price\":\"0.49\", \"size\":\"47.01\", \"side\":\"BUY\", \"hash\":\"5a2642864b4d3588f22401bb87428981e63d15b2\", \"best_bid\":\"0.67\", \"best_ask\":\"0.68\"}, {\"asset_id\":\"14965588658799411272385430903075831224615961675357217884735713260981483529984\", \"price\":\"0.51\", \"size\":\"47.01\", \"side\":\"SELL\", \"hash\":\"06fc766e12c604fcc0d5281f7c311375c8ccc4ba\", \"best_bid\":\"0.32\", \"best_ask\":\"0.33\"}], \"timestamp\":\"1785208332937\", \"event_type\":\"price_change\"}","received_at":"2026-07-28T03:12:27.104111Z","schema_version":"clob-market-ws.price_change.v1","sequence":null,"server_hash":null,"server_timestamp":"1785208332937","session_id":"3e519d9098404c15b234d96025eb1a2b","source":"clob_market_ws"},"received_at":"2026-07-28T03:12:27.104111Z","record_id":"a872dfea480d5dcbea2986fbbef6c334b6dd67441bf32784acbb6c3b9a507bc1","schema_fingerprint":"4aa3821a28b0b7c2400bc59aba4bcc0a76e971dadd19610d3ad38c768e124dc7","schema_version":"edge-lab-recorder.raw.v1","sequence":null,"source":"clob_market_ws"}
