{"event_at":"2026-07-28T03:00:25.627000Z","event_fingerprint":"044a19db34abfd07c81eced8681c9fee7b06d6b842eef19e982ec07ebf53a02b","payload":{"connection_id":"a6b55582af5f430fb37ad02bf0922475","event_at":"2026-07-28T03:00:25.627000Z","event_type":"price_change","frame_hash":"d194bc6c2fe863d2244dfc75bd3d2c1a67fbc0384e2bf69dd9dfc613ef126d52","frame_index":0,"kind":"data","monotonic_ns":309611133002000,"payload":{"event_type":"price_change","market":"0x779291bef19b6709f61e9764a954aafe9ffae488d50ae674aabdcb4f248006d5","price_changes":[{"asset_id":"14965588658799411272385430903075831224615961675357217884735713260981483529984","best_ask":"0.6","best_bid":"0.59","hash":"e567e63579ff42d064c577a05ca9e68020a75001","price":"0.52","side":"BUY","size":"218"},{"asset_id":"8761897749749422724209054078244794145777693856614463256546737399611489089783","best_ask":"0.41","best_bid":"0.4","hash":"39f6b5a57f545882b5a69cef2cda0a1c799edb32","price":"0.48","side":"SELL","size":"218"}],"timestamp":"1785207625627"},"payload_hash":"88c99c4373b4d73acc3b2ced76d4e486fadfc908a0c702435e460aa0252191ce","raw_frame":"{\"market\":\"0x779291bef19b6709f61e9764a954aafe9ffae488d50ae674aabdcb4f248006d5\", \"price_changes\":[{\"asset_id\":\"14965588658799411272385430903075831224615961675357217884735713260981483529984\", \"price\":\"0.52\", \"size\":\"218\", \"side\":\"BUY\", \"hash\":\"e567e63579ff42d064c577a05ca9e68020a75001\", \"best_bid\":\"0.59\", \"best_ask\":\"0.6\"}, {\"asset_id\":\"8761897749749422724209054078244794145777693856614463256546737399611489089783\", \"price\":\"0.48\", \"size\":\"218\", \"side\":\"SELL\", \"hash\":\"39f6b5a57f545882b5a69cef2cda0a1c799edb32\", \"best_bid\":\"0.4\", \"best_ask\":\"0.41\"}], \"timestamp\":\"1785207625627\", \"event_type\":\"price_change\"}","received_at":"2026-07-28T03:00:28.114430Z","schema_version":"clob-market-ws.price_change.v1","sequence":null,"server_hash":null,"server_timestamp":"1785207625627","session_id":"3e519d9098404c15b234d96025eb1a2b","source":"clob_market_ws"},"received_at":"2026-07-28T03:00:28.114430Z","record_id":"96145d55dcca9d74729907886debacce9785786133285f49b440d28d4ce7a1da","schema_fingerprint":"4aa3821a28b0b7c2400bc59aba4bcc0a76e971dadd19610d3ad38c768e124dc7","schema_version":"edge-lab-recorder.raw.v1","sequence":null,"source":"clob_market_ws"}
{"event_at":"2026-07-28T03:00:25.627000Z","event_fingerprint":"e8e2a922ab30c39be81f657e6e00e1aff6ef96a83000d0c65fc4c37ffa398951","payload":{"connection_id":"a6b55582af5f430fb37ad02bf0922475","event_at":"2026-07-28T03:00:25.627000Z","event_type":"price_change","frame_hash":"f48d6e09eea7ccaacdf81a673710a47e9532ff321b6e9a777a0108073871b68f","frame_index":0,"kind":"data","monotonic_ns":309611153142625,"payload":{"event_type":"price_change","market":"0x779291bef19b6709f61e9764a954aafe9ffae488d50ae674aabdcb4f248006d5","price_changes":[{"asset_id":"14965588658799411272385430903075831224615961675357217884735713260981483529984","best_ask":"0.6","best_bid":"0.59","hash":"f1d17bd05064f8301d7915e6ce3850a16e899d1d","price":"0.52","side":"BUY","size":"188"},{"asset_id":"8761897749749422724209054078244794145777693856614463256546737399611489089783","best_ask":"0.41","best_bid":"0.4","hash":"66e170ed563a67ec4c8c718176e3285b3cfb38f0","price":"0.48","side":"SELL","size":"188"}],"timestamp":"1785207625627"},"payload_hash":"d3a1c0e8ab8810f99b82183b1141ad7c25cc666911843c88a16fdd20f6fcde1f","raw_frame":"{\"market\":\"0x779291bef19b6709f61e9764a954aafe9ffae488d50ae674aabdcb4f248006d5\", \"price_changes\":[{\"asset_id\":\"14965588658799411272385430903075831224615961675357217884735713260981483529984\", \"price\":\"0.52\", \"size\":\"188\", \"side\":\"BUY\", \"hash\":\"f1d17bd05064f8301d7915e6ce3850a16e899d1d\", \"best_bid\":\"0.59\", \"best_ask\":\"0.6\"}, {\"asset_id\":\"8761897749749422724209054078244794145777693856614463256546737399611489089783\", \"price\":\"0.48\", \"size\":\"188\", \"side\":\"SELL\", \"hash\":\"66e170ed563a67ec4c8c718176e3285b3cfb38f0\", \"best_bid\":\"0.4\", \"best_ask\":\"0.41\"}], \"timestamp\":\"1785207625627\", \"event_type\":\"price_change\"}","received_at":"2026-07-28T03:00:28.134574Z","schema_version":"clob-market-ws.price_change.v1","sequence":null,"server_hash":null,"server_timestamp":"1785207625627","session_id":"3e519d9098404c15b234d96025eb1a2b","source":"clob_market_ws"},"received_at":"2026-07-28T03:00:28.134574Z","record_id":"e99db0537f7593caba9a166abac56948a9b758eeefc8730041da0d1bd8cbd928","schema_fingerprint":"4aa3821a28b0b7c2400bc59aba4bcc0a76e971dadd19610d3ad38c768e124dc7","schema_version":"edge-lab-recorder.raw.v1","sequence":null,"source":"clob_market_ws"}
{"event_at":"2026-07-28T03:00:25.628000Z","event_fingerprint":"b046ffc2d3fbdb8eff6bc5566d6da78a1f8572a894371bf148918145af841af4","payload":{"connection_id":"a6b55582af5f430fb37ad02bf0922475","event_at":"2026-07-28T03:00:25.628000Z","event_type":"price_change","frame_hash":"da4de9a7be29c9d97874e0a24bdef41b82dcfa0e45f77feb3f5dd1f32fccd6a0","frame_index":0,"kind":"data","monotonic_ns":309611160544083,"payload":{"event_type":"price_change","market":"0x779291bef19b6709f61e9764a954aafe9ffae488d50ae674aabdcb4f248006d5","price_changes":[{"asset_id":"8761897749749422724209054078244794145777693856614463256546737399611489089783","best_ask":"0.41","best_bid":"0.4","hash":"12c7364cfcbff0ec981d8a4ce883e1d460e2a0e5","price":"0.33","side":"BUY","size":"103"},{"asset_id":"14965588658799411272385430903075831224615961675357217884735713260981483529984","best_ask":"0.6","best_bid":"0.59","hash":"0f29a81d23e7bf7c257064589e90e195f321c07c","price":"0.67","side":"SELL","size":"103"}],"timestamp":"1785207625628"},"payload_hash":"08c798f79ac299a63d9a39f85786500f101fc1dd2630aabf1072ee32d1d351f3","raw_frame":"{\"market\":\"0x779291bef19b6709f61e9764a954aafe9ffae488d50ae674aabdcb4f248006d5\", \"price_changes\":[{\"asset_id\":\"8761897749749422724209054078244794145777693856614463256546737399611489089783\", \"price\":\"0.33\", \"size\":\"103\", \"side\":\"BUY\", \"hash\":\"12c7364cfcbff0ec981d8a4ce883e1d460e2a0e5\", \"best_bid\":\"0.4\", \"best_ask\":\"0.41\"}, {\"asset_id\":\"14965588658799411272385430903075831224615961675357217884735713260981483529984\", \"price\":\"0.67\", \"size\":\"103\", \"side\":\"SELL\", \"hash\":\"0f29a81d23e7bf7c257064589e90e195f321c07c\", \"best_bid\":\"0.59\", \"best_ask\":\"0.6\"}], \"timestamp\":\"1785207625628\", \"event_type\":\"price_change\"}","received_at":"2026-07-28T03:00:28.141977Z","schema_version":"clob-market-ws.price_change.v1","sequence":null,"server_hash":null,"server_timestamp":"1785207625628","session_id":"3e519d9098404c15b234d96025eb1a2b","source":"clob_market_ws"},"received_at":"2026-07-28T03:00:28.141977Z","record_id":"8d991de816ec62777ad26f0355ce3d47a46fe5a3cb886741804db91bffdc808d","schema_fingerprint":"4aa3821a28b0b7c2400bc59aba4bcc0a76e971dadd19610d3ad38c768e124dc7","schema_version":"edge-lab-recorder.raw.v1","sequence":null,"source":"clob_market_ws"}
{"event_at":"2026-07-28T03:00:25.632000Z","event_fingerprint":"300117fd0137f203eccdede5d2e289f9487fb49733a3f0f538783caa92f4f64d","payload":{"connection_id":"a6b55582af5f430fb37ad02bf0922475","event_at":"2026-07-28T03:00:25.632000Z","event_type":"price_change","frame_hash":"e8a3118cfed34fc44626c0b0e82477b2cabbc4cb9ccd30b8d29d479b83d495d5","frame_index":0,"kind":"data","monotonic_ns":309611172410000,"payload":{"event_type":"price_change","market":"0x779291bef19b6709f61e9764a954aafe9ffae488d50ae674aabdcb4f248006d5","price_changes":[{"asset_id":"14965588658799411272385430903075831224615961675357217884735713260981483529984","best_ask":"0.6","best_bid":"0.59","hash":"d3de8cce9076d038098500679c16348cfc670a9c","price":"0.49","side":"BUY","size":"181"},{"asset_id":"8761897749749422724209054078244794145777693856614463256546737399611489089783","best_ask":"0.41","best_bid":"0.4","hash":"7b093b0661a7bbd61ba4295582295a58b6cd124c","price":"0.51","side":"SELL","size":"181"}],"timestamp":"1785207625632"},"payload_hash":"a6ed0ed1f3bc9859237056bacbd15ebfaf4d06600dbecee2856d9ae8f9b72fbf","raw_frame":"{\"market\":\"0x779291bef19b6709f61e9764a954aafe9ffae488d50ae674aabdcb4f248006d5\", \"price_changes\":[{\"asset_id\":\"14965588658799411272385430903075831224615961675357217884735713260981483529984\", \"price\":\"0.49\", \"size\":\"181\", \"side\":\"BUY\", \"hash\":\"d3de8cce9076d038098500679c16348cfc670a9c\", \"best_bid\":\"0.59\", \"best_ask\":\"0.6\"}, {\"asset_id\":\"8761897749749422724209054078244794145777693856614463256546737399611489089783\", \"price\":\"0.51\", \"size\":\"181\", \"side\":\"SELL\", \"hash\":\"7b093b0661a7bbd61ba4295582295a58b6cd124c\", \"best_bid\":\"0.4\", \"best_ask\":\"0.41\"}], \"timestamp\":\"1785207625632\", \"event_type\":\"price_change\"}","received_at":"2026-07-28T03:00:28.153842Z","schema_version":"clob-market-ws.price_change.v1","sequence":null,"server_hash":null,"server_timestamp":"1785207625632","session_id":"3e519d9098404c15b234d96025eb1a2b","source":"clob_market_ws"},"received_at":"2026-07-28T03:00:28.153842Z","record_id":"979a2998ddc2b246f6feba7f326ed36ae2e0c9b656c54946b7adf13d1dbdc66b","schema_fingerprint":"4aa3821a28b0b7c2400bc59aba4bcc0a76e971dadd19610d3ad38c768e124dc7","schema_version":"edge-lab-recorder.raw.v1","sequence":null,"source":"clob_market_ws"}
{"event_at":"2026-07-28T03:00:25.635000Z","event_fingerprint":"acb5ea516261f1b70e8e332790a7176254c81a5994733790d53f9df2518d6ae6","payload":{"connection_id":"a6b55582af5f430fb37ad02bf0922475","event_at":"2026-07-28T03:00:25.635000Z","event_type":"price_change","frame_hash":"bf8ff8aff7a97b8ba3c30d83b9e8218fc1985b5242ffa91f010094e1616b0083","frame_index":0,"kind":"data","monotonic_ns":309611181369791,"payload":{"event_type":"price_change","market":"0x779291bef19b6709f61e9764a954aafe9ffae488d50ae674aabdcb4f248006d5","price_changes":[{"asset_id":"14965588658799411272385430903075831224615961675357217884735713260981483529984","best_ask":"0.6","best_bid":"0.59","hash":"5acd5d79c85ccd26cf990bca6fd9d8c26bf1d01d","price":"0.54","side":"BUY","size":"90.6"},{"asset_id":"8761897749749422724209054078244794145777693856614463256546737399611489089783","best_ask":"0.41","best_bid":"0.4","hash":"c08daf4a3fb3112ba34d7e62f233286737ad271f","price":"0.46","side":"SELL","size":"90.6"}],"timestamp":"1785207625635"},"payload_hash":"0450d2adcaf8a91dc39700755aeaf89fc08c2b63bf680b7a2225823351b00172","raw_frame":"{\"market\":\"0x779291bef19b6709f61e9764a954aafe9ffae488d50ae674aabdcb4f248006d5\", \"price_changes\":[{\"asset_id\":\"14965588658799411272385430903075831224615961675357217884735713260981483529984\", \"price\":\"0.54\", \"size\":\"90.6\", \"side\":\"BUY\", \"hash\":\"5acd5d79c85ccd26cf990bca6fd9d8c26bf1d01d\", \"best_bid\":\"0.59\", \"best_ask\":\"0.6\"}, {\"asset_id\":\"8761897749749422724209054078244794145777693856614463256546737399611489089783\", \"price\":\"0.46\", \"size\":\"90.6\", \"side\":\"SELL\", \"hash\":\"c08daf4a3fb3112ba34d7e62f233286737ad271f\", \"best_bid\":\"0.4\", \"best_ask\":\"0.41\"}], \"timestamp\":\"1785207625635\", \"event_type\":\"price_change\"}","received_at":"2026-07-28T03:00:28.162803Z","schema_version":"clob-market-ws.price_change.v1","sequence":null,"server_hash":null,"server_timestamp":"1785207625635","session_id":"3e519d9098404c15b234d96025eb1a2b","source":"clob_market_ws"},"received_at":"2026-07-28T03:00:28.162803Z","record_id":"234d8cd483aaf6c4ba1dd72b5819e259696abdc0f343f0e144b4b171476d8531","schema_fingerprint":"4aa3821a28b0b7c2400bc59aba4bcc0a76e971dadd19610d3ad38c768e124dc7","schema_version":"edge-lab-recorder.raw.v1","sequence":null,"source":"clob_market_ws"}
{"event_at":"2026-07-28T03:00:25.636000Z","event_fingerprint":"af508d28d972e388d428c2bd225890d2b55abe46749b0dde9dd55981b609ffc9","payload":{"connection_id":"a6b55582af5f430fb37ad02bf0922475","event_at":"2026-07-28T03:00:25.636000Z","event_type":"price_change","frame_hash":"1a4721a4188c8e9db4144e537e83045ac8565955e62bbe55bbe41691be06f81a","frame_index":0,"kind":"data","monotonic_ns":309611187482375,"payload":{"event_type":"price_change","market":"0x779291bef19b6709f61e9764a954aafe9ffae488d50ae674aabdcb4f248006d5","price_changes":[{"asset_id":"8761897749749422724209054078244794145777693856614463256546737399611489089783","best_ask":"0.41","best_bid":"0.4","hash":"917424ede635004349ad9a297d73a442445f0761","price":"0.23","side":"BUY","size":"34"},{"asset_id":"14965588658799411272385430903075831224615961675357217884735713260981483529984","best_ask":"0.6","best_bid":"0.59","hash":"61525cc2951066d1e9c27573fe37a0a190a45b01","price":"0.77","side":"SELL","size":"34"}],"timestamp":"1785207625636"},"payload_hash":"fc3970ffb23b35209a6fb62db38e5caaccb753f67659d65499e72b62e1ac405a","raw_frame":"{\"market\":\"0x779291bef19b6709f61e9764a954aafe9ffae488d50ae674aabdcb4f248006d5\", \"price_changes\":[{\"asset_id\":\"8761897749749422724209054078244794145777693856614463256546737399611489089783\", \"price\":\"0.23\", \"size\":\"34\", \"side\":\"BUY\", \"hash\":\"917424ede635004349ad9a297d73a442445f0761\", \"best_bid\":\"0.4\", \"best_ask\":\"0.41\"}, {\"asset_id\":\"14965588658799411272385430903075831224615961675357217884735713260981483529984\", \"price\":\"0.77\", \"size\":\"34\", \"side\":\"SELL\", \"hash\":\"61525cc2951066d1e9c27573fe37a0a190a45b01\", \"best_bid\":\"0.59\", \"best_ask\":\"0.6\"}], \"timestamp\":\"1785207625636\", \"event_type\":\"price_change\"}","received_at":"2026-07-28T03:00:28.168916Z","schema_version":"clob-market-ws.price_change.v1","sequence":null,"server_hash":null,"server_timestamp":"1785207625636","session_id":"3e519d9098404c15b234d96025eb1a2b","source":"clob_market_ws"},"received_at":"2026-07-28T03:00:28.168916Z","record_id":"51a5b1e8937f0dae2510ff089145dda9baa860b25283deb9b49c2c9321fd998d","schema_fingerprint":"4aa3821a28b0b7c2400bc59aba4bcc0a76e971dadd19610d3ad38c768e124dc7","schema_version":"edge-lab-recorder.raw.v1","sequence":null,"source":"clob_market_ws"}
{"event_at":"2026-07-28T03:00:25.638000Z","event_fingerprint":"493a43d96550d6e19cab3ac2fbcb5dd9879407a9c53439dd8809d036dd4b1449","payload":{"connection_id":"a6b55582af5f430fb37ad02bf0922475","event_at":"2026-07-28T03:00:25.638000Z","event_type":"price_change","frame_hash":"4bc99c240e7a1848b757684a23d00e5c26897fe630ebb6432c1a2ee92ab030b7","frame_index":0,"kind":"data","monotonic_ns":309611194006500,"payload":{"event_type":"price_change","market":"0x779291bef19b6709f61e9764a954aafe9ffae488d50ae674aabdcb4f248006d5","price_changes":[{"asset_id":"8761897749749422724209054078244794145777693856614463256546737399611489089783","best_ask":"0.41","best_bid":"0.4","hash":"cfcc8a678a2aef12cd5cb75179d240fb49a31a49","price":"0.38","side":"BUY","size":"298.6"},{"asset_id":"14965588658799411272385430903075831224615961675357217884735713260981483529984","best_ask":"0.6","best_bid":"0.59","hash":"cb1482e0707a6e2d9d1195f0c7fccf4346b161c6","price":"0.62","side":"SELL","size":"298.6"}],"timestamp":"1785207625638"},"payload_hash":"0159e0ba719ce5afc292b6ea0f8eb0e79252f0972f29e2b5df21da38276df23e","raw_frame":"{\"market\":\"0x779291bef19b6709f61e9764a954aafe9ffae488d50ae674aabdcb4f248006d5\", \"price_changes\":[{\"asset_id\":\"8761897749749422724209054078244794145777693856614463256546737399611489089783\", \"price\":\"0.38\", \"size\":\"298.6\", \"side\":\"BUY\", \"hash\":\"cfcc8a678a2aef12cd5cb75179d240fb49a31a49\", \"best_bid\":\"0.4\", \"best_ask\":\"0.41\"}, {\"asset_id\":\"14965588658799411272385430903075831224615961675357217884735713260981483529984\", \"price\":\"0.62\", \"size\":\"298.6\", \"side\":\"SELL\", \"hash\":\"cb1482e0707a6e2d9d1195f0c7fccf4346b161c6\", \"best_bid\":\"0.59\", \"best_ask\":\"0.6\"}], \"timestamp\":\"1785207625638\", \"event_type\":\"price_change\"}","received_at":"2026-07-28T03:00:28.175441Z","schema_version":"clob-market-ws.price_change.v1","sequence":null,"server_hash":null,"server_timestamp":"1785207625638","session_id":"3e519d9098404c15b234d96025eb1a2b","source":"clob_market_ws"},"received_at":"2026-07-28T03:00:28.175441Z","record_id":"c809d54ed9db4111796520396fe0da6957fdbcd8950b03266d06dbc32824e27d","schema_fingerprint":"4aa3821a28b0b7c2400bc59aba4bcc0a76e971dadd19610d3ad38c768e124dc7","schema_version":"edge-lab-recorder.raw.v1","sequence":null,"source":"clob_market_ws"}
{"event_at":"2026-07-28T03:00:25.641000Z","event_fingerprint":"df5f796162b4b1fe76e90cb4a0a0196e5068d42d63ed8a2ce31aa947a99415cc","payload":{"connection_id":"a6b55582af5f430fb37ad02bf0922475","event_at":"2026-07-28T03:00:25.641000Z","event_type":"price_change","frame_hash":"73cbdc198c1f27af4298b035ee3ca15c5df0d46b0caf35b6e8b4c0d5f5002c1a","frame_index":0,"kind":"data","monotonic_ns":309611198952791,"payload":{"event_type":"price_change","market":"0x779291bef19b6709f61e9764a954aafe9ffae488d50ae674aabdcb4f248006d5","price_changes":[{"asset_id":"8761897749749422724209054078244794145777693856614463256546737399611489089783","best_ask":"0.41","best_bid":"0.4","hash":"d5c6e0a38933d214b3a235adc5b5d317790ba106","price":"0.39","side":"BUY","size":"96"},{"asset_id":"14965588658799411272385430903075831224615961675357217884735713260981483529984","best_ask":"0.6","best_bid":"0.59","hash":"79f18988927535bd2f22fa10159f98abd16b9139","price":"0.61","side":"SELL","size":"96"}],"timestamp":"1785207625641"},"payload_hash":"e1f835bec1cd63551f13c33f530d6c4006604cc140c3ffbf34e32fa73ecbda70","raw_frame":"{\"market\":\"0x779291bef19b6709f61e9764a954aafe9ffae488d50ae674aabdcb4f248006d5\", \"price_changes\":[{\"asset_id\":\"8761897749749422724209054078244794145777693856614463256546737399611489089783\", \"price\":\"0.39\", \"size\":\"96\", \"side\":\"BUY\", \"hash\":\"d5c6e0a38933d214b3a235adc5b5d317790ba106\", \"best_bid\":\"0.4\", \"best_ask\":\"0.41\"}, {\"asset_id\":\"14965588658799411272385430903075831224615961675357217884735713260981483529984\", \"price\":\"0.61\", \"size\":\"96\", \"side\":\"SELL\", \"hash\":\"79f18988927535bd2f22fa10159f98abd16b9139\", \"best_bid\":\"0.59\", \"best_ask\":\"0.6\"}], \"timestamp\":\"1785207625641\", \"event_type\":\"price_change\"}","received_at":"2026-07-28T03:00:28.180386Z","schema_version":"clob-market-ws.price_change.v1","sequence":null,"server_hash":null,"server_timestamp":"1785207625641","session_id":"3e519d9098404c15b234d96025eb1a2b","source":"clob_market_ws"},"received_at":"2026-07-28T03:00:28.180386Z","record_id":"b3af6a34d3a46aaec0013394ac3cc047f4d849f62877ffc225ee931800586275","schema_fingerprint":"4aa3821a28b0b7c2400bc59aba4bcc0a76e971dadd19610d3ad38c768e124dc7","schema_version":"edge-lab-recorder.raw.v1","sequence":null,"source":"clob_market_ws"}
{"event_at":"2026-07-28T03:00:25.643000Z","event_fingerprint":"6efd7943907d379c243da1a42cb729f4af60bba2e30b42dc68980440fafbf4c2","payload":{"connection_id":"a6b55582af5f430fb37ad02bf0922475","event_at":"2026-07-28T03:00:25.643000Z","event_type":"price_change","frame_hash":"bb81b3bf6c17a21b94e5ce6cf1ec29f4c4d8680c03957ca92256e1f5f67507fa","frame_index":0,"kind":"data","monotonic_ns":309611210592875,"payload":{"event_type":"price_change","market":"0x779291bef19b6709f61e9764a954aafe9ffae488d50ae674aabdcb4f248006d5","price_changes":[{"asset_id":"14965588658799411272385430903075831224615961675357217884735713260981483529984","best_ask":"0.6","best_bid":"0.59","hash":"2e6e6c3df74defd3c22bee805eb18aa3ad61bd42","price":"0.04","side":"BUY","size":"770"},{"asset_id":"8761897749749422724209054078244794145777693856614463256546737399611489089783","best_ask":"0.41","best_bid":"0.4","hash":"0e67f658183b5c2157eadfe6ceaf222d307cb6ff","price":"0.96","side":"SELL","size":"770"}],"timestamp":"1785207625643"},"payload_hash":"007b987ea9f8e52be9ca486baeae833b972fd89acda93f865de9997b12b980ed","raw_frame":"{\"market\":\"0x779291bef19b6709f61e9764a954aafe9ffae488d50ae674aabdcb4f248006d5\", \"price_changes\":[{\"asset_id\":\"14965588658799411272385430903075831224615961675357217884735713260981483529984\", \"price\":\"0.04\", \"size\":\"770\", \"side\":\"BUY\", \"hash\":\"2e6e6c3df74defd3c22bee805eb18aa3ad61bd42\", \"best_bid\":\"0.59\", \"best_ask\":\"0.6\"}, {\"asset_id\":\"8761897749749422724209054078244794145777693856614463256546737399611489089783\", \"price\":\"0.96\", \"size\":\"770\", \"side\":\"SELL\", \"hash\":\"0e67f658183b5c2157eadfe6ceaf222d307cb6ff\", \"best_bid\":\"0.4\", \"best_ask\":\"0.41\"}], \"timestamp\":\"1785207625643\", \"event_type\":\"price_change\"}","received_at":"2026-07-28T03:00:28.192030Z","schema_version":"clob-market-ws.price_change.v1","sequence":null,"server_hash":null,"server_timestamp":"1785207625643","session_id":"3e519d9098404c15b234d96025eb1a2b","source":"clob_market_ws"},"received_at":"2026-07-28T03:00:28.192030Z","record_id":"796deb7ad1d6a1b70c81d10430ce4cc7580b97ae5012a78858ed7cd04fd4fcfe","schema_fingerprint":"4aa3821a28b0b7c2400bc59aba4bcc0a76e971dadd19610d3ad38c768e124dc7","schema_version":"edge-lab-recorder.raw.v1","sequence":null,"source":"clob_market_ws"}
{"event_at":"2026-07-28T03:00:25.651000Z","event_fingerprint":"ef5794be822c477d5b4de28e2935ae389056c81ee51cc718a3d2efd4b150ccc7","payload":{"connection_id":"a6b55582af5f430fb37ad02bf0922475","event_at":"2026-07-28T03:00:25.651000Z","event_type":"price_change","frame_hash":"ef6b145d22de10e9c728918c33e313f7e533bddb8974038c2a00853983fd020f","frame_index":0,"kind":"data","monotonic_ns":309611217862333,"payload":{"event_type":"price_change","market":"0x779291bef19b6709f61e9764a954aafe9ffae488d50ae674aabdcb4f248006d5","price_changes":[{"asset_id":"14965588658799411272385430903075831224615961675357217884735713260981483529984","best_ask":"0.6","best_bid":"0.59","hash":"5ade31d9a205fa7f09c462cc9812a61f7ae518be","price":"0.54","side":"BUY","size":"120.6"},{"asset_id":"8761897749749422724209054078244794145777693856614463256546737399611489089783","best_ask":"0.41","best_bid":"0.4","hash":"515388cff2f26fbfa74f8ba579081f9394823f00","price":"0.46","side":"SELL","size":"120.6"}],"timestamp":"1785207625651"},"payload_hash":"3ff740e4b0121407713415235bbde7db0e6bae42dfbea39bacea5135db08090f","raw_frame":"{\"market\":\"0x779291bef19b6709f61e9764a954aafe9ffae488d50ae674aabdcb4f248006d5\", \"price_changes\":[{\"asset_id\":\"14965588658799411272385430903075831224615961675357217884735713260981483529984\", \"price\":\"0.54\", \"size\":\"120.6\", \"side\":\"BUY\", \"hash\":\"5ade31d9a205fa7f09c462cc9812a61f7ae518be\", \"best_bid\":\"0.59\", \"best_ask\":\"0.6\"}, {\"asset_id\":\"8761897749749422724209054078244794145777693856614463256546737399611489089783\", \"price\":\"0.46\", \"size\":\"120.6\", \"side\":\"SELL\", \"hash\":\"515388cff2f26fbfa74f8ba579081f9394823f00\", \"best_bid\":\"0.4\", \"best_ask\":\"0.41\"}], \"timestamp\":\"1785207625651\", \"event_type\":\"price_change\"}","received_at":"2026-07-28T03:00:28.199302Z","schema_version":"clob-market-ws.price_change.v1","sequence":null,"server_hash":null,"server_timestamp":"1785207625651","session_id":"3e519d9098404c15b234d96025eb1a2b","source":"clob_market_ws"},"received_at":"2026-07-28T03:00:28.199302Z","record_id":"56d472ef63f944198bf7a4dfa8da0932ba0e822e0784acb88c262016bc1b7846","schema_fingerprint":"4aa3821a28b0b7c2400bc59aba4bcc0a76e971dadd19610d3ad38c768e124dc7","schema_version":"edge-lab-recorder.raw.v1","sequence":null,"source":"clob_market_ws"}
{"event_at":"2026-07-28T03:00:25.655000Z","event_fingerprint":"582f576e7fa87cdceac6795b0811337733dd6f530bbd0f6f0f0f02e75a02f825","payload":{"connection_id":"a6b55582af5f430fb37ad02bf0922475","event_at":"2026-07-28T03:00:25.655000Z","event_type":"price_change","frame_hash":"480fd1de41580986999ae20fcfdeb5142f04c0d5992ffb9e83c0505ed3f7b581","frame_index":0,"kind":"data","monotonic_ns":309611227496416,"payload":{"event_type":"price_change","market":"0x779291bef19b6709f61e9764a954aafe9ffae488d50ae674aabdcb4f248006d5","price_changes":[{"asset_id":"14965588658799411272385430903075831224615961675357217884735713260981483529984","best_ask":"0.6","best_bid":"0.59","hash":"8590fdacbc123cdc5c808a52915c0d884b9bcdec","price":"0.54","side":"BUY","size":"150.6"},{"asset_id":"8761897749749422724209054078244794145777693856614463256546737399611489089783","best_ask":"0.41","best_bid":"0.4","hash":"be828d41449f9437a5e6bb7bdfdfdf9d1aaa5343","price":"0.46","side":"SELL","size":"150.6"}],"timestamp":"1785207625655"},"payload_hash":"f75c5b78b81acef58f94a74ed63ec61fda3d7ff49cee30f6a47b58739ccf56ae","raw_frame":"{\"market\":\"0x779291bef19b6709f61e9764a954aafe9ffae488d50ae674aabdcb4f248006d5\", \"price_changes\":[{\"asset_id\":\"14965588658799411272385430903075831224615961675357217884735713260981483529984\", \"price\":\"0.54\", \"size\":\"150.6\", \"side\":\"BUY\", \"hash\":\"8590fdacbc123cdc5c808a52915c0d884b9bcdec\", \"best_bid\":\"0.59\", \"best_ask\":\"0.6\"}, {\"asset_id\":\"8761897749749422724209054078244794145777693856614463256546737399611489089783\", \"price\":\"0.46\", \"size\":\"150.6\", \"side\":\"SELL\", \"hash\":\"be828d41449f9437a5e6bb7bdfdfdf9d1aaa5343\", \"best_bid\":\"0.4\", \"best_ask\":\"0.41\"}], \"timestamp\":\"1785207625655\", \"event_type\":\"price_change\"}","received_at":"2026-07-28T03:00:28.208930Z","schema_version":"clob-market-ws.price_change.v1","sequence":null,"server_hash":null,"server_timestamp":"1785207625655","session_id":"3e519d9098404c15b234d96025eb1a2b","source":"clob_market_ws"},"received_at":"2026-07-28T03:00:28.208930Z","record_id":"681f0f2a217b17bfe60e64c17e218f936201d38b6af0b8825981df37b1f0df36","schema_fingerprint":"4aa3821a28b0b7c2400bc59aba4bcc0a76e971dadd19610d3ad38c768e124dc7","schema_version":"edge-lab-recorder.raw.v1","sequence":null,"source":"clob_market_ws"}
{"event_at":"2026-07-28T03:00:25.658000Z","event_fingerprint":"f68efd753c38c90e127838b8fb9f07083efaf84a22dee3835165ece6f3f7e10a","payload":{"connection_id":"a6b55582af5f430fb37ad02bf0922475","event_at":"2026-07-28T03:00:25.658000Z","event_type":"price_change","frame_hash":"42ee4881c6b0a67e79a8ea540d58703cf88fab48f3d915339c5312ff1dd967f4","frame_index":0,"kind":"data","monotonic_ns":309611229806208,"payload":{"event_type":"price_change","market":"0x779291bef19b6709f61e9764a954aafe9ffae488d50ae674aabdcb4f248006d5","price_changes":[{"asset_id":"14965588658799411272385430903075831224615961675357217884735713260981483529984","best_ask":"0.6","best_bid":"0.59","hash":"4cefae3b749ba3844dd389655710d74d3d71daf7","price":"0.54","side":"BUY","size":"180.6"},{"asset_id":"8761897749749422724209054078244794145777693856614463256546737399611489089783","best_ask":"0.41","best_bid":"0.4","hash":"518ea6d4666a9a9c08bc1319b4e78c9f983a6e6f","price":"0.46","side":"SELL","size":"180.6"}],"timestamp":"1785207625658"},"payload_hash":"2c7c5d7c5869013376fd014c509ae7449817e78fbcbf7427e62913abd4c69105","raw_frame":"{\"market\":\"0x779291bef19b6709f61e9764a954aafe9ffae488d50ae674aabdcb4f248006d5\", \"price_changes\":[{\"asset_id\":\"14965588658799411272385430903075831224615961675357217884735713260981483529984\", \"price\":\"0.54\", \"size\":\"180.6\", \"side\":\"BUY\", \"hash\":\"4cefae3b749ba3844dd389655710d74d3d71daf7\", \"best_bid\":\"0.59\", \"best_ask\":\"0.6\"}, {\"asset_id\":\"8761897749749422724209054078244794145777693856614463256546737399611489089783\", \"price\":\"0.46\", \"size\":\"180.6\", \"side\":\"SELL\", \"hash\":\"518ea6d4666a9a9c08bc1319b4e78c9f983a6e6f\", \"best_bid\":\"0.4\", \"best_ask\":\"0.41\"}], \"timestamp\":\"1785207625658\", \"event_type\":\"price_change\"}","received_at":"2026-07-28T03:00:28.211245Z","schema_version":"clob-market-ws.price_change.v1","sequence":null,"server_hash":null,"server_timestamp":"1785207625658","session_id":"3e519d9098404c15b234d96025eb1a2b","source":"clob_market_ws"},"received_at":"2026-07-28T03:00:28.211245Z","record_id":"fcfa06c65e100cf980cc2985d650fbb1c388e9ac4967dab7f47ac944f5d4ec30","schema_fingerprint":"4aa3821a28b0b7c2400bc59aba4bcc0a76e971dadd19610d3ad38c768e124dc7","schema_version":"edge-lab-recorder.raw.v1","sequence":null,"source":"clob_market_ws"}
{"event_at":"2026-07-28T03:00:25.662000Z","event_fingerprint":"26de3440a677fb5cd20f52ee9866a044c61ed51f7666b5d1712036f30fdbe2d6","payload":{"connection_id":"a6b55582af5f430fb37ad02bf0922475","event_at":"2026-07-28T03:00:25.662000Z","event_type":"price_change","frame_hash":"6cff244e526b4ce2e94440191f389f5765b3d46082724d87b56b331542a8daef","frame_index":0,"kind":"data","monotonic_ns":309611232561000,"payload":{"event_type":"price_change","market":"0x779291bef19b6709f61e9764a954aafe9ffae488d50ae674aabdcb4f248006d5","price_changes":[{"asset_id":"8761897749749422724209054078244794145777693856614463256546737399611489089783","best_ask":"0.41","best_bid":"0.4","hash":"1743e827fe4eed6ee42e7714930d3470dba6040a","price":"0.38","side":"BUY","size":"292.6"},{"asset_id":"14965588658799411272385430903075831224615961675357217884735713260981483529984","best_ask":"0.6","best_bid":"0.59","hash":"dc8b1c76cadb52a15bf10058aa2a0085a93ede4d","price":"0.62","side":"SELL","size":"292.6"}],"timestamp":"1785207625662"},"payload_hash":"9d18fe2e8a43a5ae2e41a4df9d7edbd017e401a35a9d2c59f8d0efbe9dafb7fe","raw_frame":"{\"market\":\"0x779291bef19b6709f61e9764a954aafe9ffae488d50ae674aabdcb4f248006d5\", \"price_changes\":[{\"asset_id\":\"8761897749749422724209054078244794145777693856614463256546737399611489089783\", \"price\":\"0.38\", \"size\":\"292.6\", \"side\":\"BUY\", \"hash\":\"1743e827fe4eed6ee42e7714930d3470dba6040a\", \"best_bid\":\"0.4\", \"best_ask\":\"0.41\"}, {\"asset_id\":\"14965588658799411272385430903075831224615961675357217884735713260981483529984\", \"price\":\"0.62\", \"size\":\"292.6\", \"side\":\"SELL\", \"hash\":\"dc8b1c76cadb52a15bf10058aa2a0085a93ede4d\", \"best_bid\":\"0.59\", \"best_ask\":\"0.6\"}], \"timestamp\":\"1785207625662\", \"event_type\":\"price_change\"}","received_at":"2026-07-28T03:00:28.214000Z","schema_version":"clob-market-ws.price_change.v1","sequence":null,"server_hash":null,"server_timestamp":"1785207625662","session_id":"3e519d9098404c15b234d96025eb1a2b","source":"clob_market_ws"},"received_at":"2026-07-28T03:00:28.214000Z","record_id":"31fbb9eca441e0775bfed8d3f6f8c0cf469c8a3a1008aae1102962c6f4ee138e","schema_fingerprint":"4aa3821a28b0b7c2400bc59aba4bcc0a76e971dadd19610d3ad38c768e124dc7","schema_version":"edge-lab-recorder.raw.v1","sequence":null,"source":"clob_market_ws"}
{"event_at":"2026-07-28T03:00:25.667000Z","event_fingerprint":"1f0438a4858360f86d2da3bc918c775551e6367a271eed28e53a583daddc3e68","payload":{"connection_id":"a6b55582af5f430fb37ad02bf0922475","event_at":"2026-07-28T03:00:25.667000Z","event_type":"price_change","frame_hash":"e34f10e185cb4c79d7555f7f1d26d9c518465a5df028ec11f2bf4175685b1ec3","frame_index":0,"kind":"data","monotonic_ns":309611235758708,"payload":{"event_type":"price_change","market":"0x779291bef19b6709f61e9764a954aafe9ffae488d50ae674aabdcb4f248006d5","price_changes":[{"asset_id":"8761897749749422724209054078244794145777693856614463256546737399611489089783","best_ask":"0.41","best_bid":"0.4","hash":"b64d0b6ea6cde5f67047076cbf0dc5fd36c9e565","price":"0.39","side":"BUY","size":"108.6"},{"asset_id":"14965588658799411272385430903075831224615961675357217884735713260981483529984","best_ask":"0.6","best_bid":"0.59","hash":"23ea2a2048cad3069b418bd2e72b743c8b539859","price":"0.61","side":"SELL","size":"108.6"}],"timestamp":"1785207625667"},"payload_hash":"cda5024a2540b6847dc6c509e8bd5c4a2bda2d6d3dd2eb0065c1f29af9bff0cf","raw_frame":"{\"market\":\"0x779291bef19b6709f61e9764a954aafe9ffae488d50ae674aabdcb4f248006d5\", \"price_changes\":[{\"asset_id\":\"8761897749749422724209054078244794145777693856614463256546737399611489089783\", \"price\":\"0.39\", \"size\":\"108.6\", \"side\":\"BUY\", \"hash\":\"b64d0b6ea6cde5f67047076cbf0dc5fd36c9e565\", \"best_bid\":\"0.4\", \"best_ask\":\"0.41\"}, {\"asset_id\":\"14965588658799411272385430903075831224615961675357217884735713260981483529984\", \"price\":\"0.61\", \"size\":\"108.6\", \"side\":\"SELL\", \"hash\":\"23ea2a2048cad3069b418bd2e72b743c8b539859\", \"best_bid\":\"0.59\", \"best_ask\":\"0.6\"}], \"timestamp\":\"1785207625667\", \"event_type\":\"price_change\"}","received_at":"2026-07-28T03:00:28.217198Z","schema_version":"clob-market-ws.price_change.v1","sequence":null,"server_hash":null,"server_timestamp":"1785207625667","session_id":"3e519d9098404c15b234d96025eb1a2b","source":"clob_market_ws"},"received_at":"2026-07-28T03:00:28.217198Z","record_id":"24e3b8a9d3cb3937a19ee8e2a06ddc996fc434824e0a63746b880c95fd633c8b","schema_fingerprint":"4aa3821a28b0b7c2400bc59aba4bcc0a76e971dadd19610d3ad38c768e124dc7","schema_version":"edge-lab-recorder.raw.v1","sequence":null,"source":"clob_market_ws"}
{"event_at":"2026-07-28T03:00:25.667000Z","event_fingerprint":"8091f07db639a2d5bed62d13b7d223c57c683b6077bd34d0a73d233ef7f6e5f1","payload":{"connection_id":"a6b55582af5f430fb37ad02bf0922475","event_at":"2026-07-28T03:00:25.667000Z","event_type":"price_change","frame_hash":"230eb0ea62bfbba07f736bce220e57838b7ed94c08db835edea6898ef58d8930","frame_index":0,"kind":"data","monotonic_ns":309611240271291,"payload":{"event_type":"price_change","market":"0x779291bef19b6709f61e9764a954aafe9ffae488d50ae674aabdcb4f248006d5","price_changes":[{"asset_id":"14965588658799411272385430903075831224615961675357217884735713260981483529984","best_ask":"0.6","best_bid":"0.59","hash":"58500b26c202d05a77c43f6862616c3913b74e3e","price":"0.43","side":"BUY","size":"267.53"},{"asset_id":"8761897749749422724209054078244794145777693856614463256546737399611489089783","best_ask":"0.41","best_bid":"0.4","hash":"f9d2cd74c407a1dbf0db1096e48e8f6599b5eaad","price":"0.57","side":"SELL","size":"267.53"}],"timestamp":"1785207625667"},"payload_hash":"0516af6c0a50369b3f8e228867f2fe38ba76c44294499390a549909cd88a8c10","raw_frame":"{\"market\":\"0x779291bef19b6709f61e9764a954aafe9ffae488d50ae674aabdcb4f248006d5\", \"price_changes\":[{\"asset_id\":\"14965588658799411272385430903075831224615961675357217884735713260981483529984\", \"price\":\"0.43\", \"size\":\"267.53\", \"side\":\"BUY\", \"hash\":\"58500b26c202d05a77c43f6862616c3913b74e3e\", \"best_bid\":\"0.59\", \"best_ask\":\"0.6\"}, {\"asset_id\":\"8761897749749422724209054078244794145777693856614463256546737399611489089783\", \"price\":\"0.57\", \"size\":\"267.53\", \"side\":\"SELL\", \"hash\":\"f9d2cd74c407a1dbf0db1096e48e8f6599b5eaad\", \"best_bid\":\"0.4\", \"best_ask\":\"0.41\"}], \"timestamp\":\"1785207625667\", \"event_type\":\"price_change\"}","received_at":"2026-07-28T03:00:28.221710Z","schema_version":"clob-market-ws.price_change.v1","sequence":null,"server_hash":null,"server_timestamp":"1785207625667","session_id":"3e519d9098404c15b234d96025eb1a2b","source":"clob_market_ws"},"received_at":"2026-07-28T03:00:28.221710Z","record_id":"29dba26c10f2a86ab55de81a047e0567b655e262be08b91b2483c8c6ecdc11af","schema_fingerprint":"4aa3821a28b0b7c2400bc59aba4bcc0a76e971dadd19610d3ad38c768e124dc7","schema_version":"edge-lab-recorder.raw.v1","sequence":null,"source":"clob_market_ws"}
{"event_at":"2026-07-28T03:00:25.667000Z","event_fingerprint":"b195998121a294a6934a6f0a14dee4f6865d3c49bd71af2b1cb3972d5dbaef36","payload":{"connection_id":"a6b55582af5f430fb37ad02bf0922475","event_at":"2026-07-28T03:00:25.667000Z","event_type":"price_change","frame_hash":"139dbb785a66ff6af8011c5b3a642eb9ffef990e9e4d78772c13e7c5de8719a3","frame_index":0,"kind":"data","monotonic_ns":309611248656875,"payload":{"event_type":"price_change","market":"0x779291bef19b6709f61e9764a954aafe9ffae488d50ae674aabdcb4f248006d5","price_changes":[{"asset_id":"8761897749749422724209054078244794145777693856614463256546737399611489089783","best_ask":"0.41","best_bid":"0.4","hash":"f9d2cd74c407a1dbf0db1096e48e8f6599b5eaad","price":"0.28","side":"BUY","size":"179.01"},{"asset_id":"14965588658799411272385430903075831224615961675357217884735713260981483529984","best_ask":"0.6","best_bid":"0.59","hash":"58500b26c202d05a77c43f6862616c3913b74e3e","price":"0.72","side":"SELL","size":"179.01"}],"timestamp":"1785207625667"},"payload_hash":"1b7eab0950c66d097716082f5cc14603b668faa57d415dc84051670a2d15e29a","raw_frame":"{\"market\":\"0x779291bef19b6709f61e9764a954aafe9ffae488d50ae674aabdcb4f248006d5\", \"price_changes\":[{\"asset_id\":\"8761897749749422724209054078244794145777693856614463256546737399611489089783\", \"price\":\"0.28\", \"size\":\"179.01\", \"side\":\"BUY\", \"hash\":\"f9d2cd74c407a1dbf0db1096e48e8f6599b5eaad\", \"best_bid\":\"0.4\", \"best_ask\":\"0.41\"}, {\"asset_id\":\"14965588658799411272385430903075831224615961675357217884735713260981483529984\", \"price\":\"0.72\", \"size\":\"179.01\", \"side\":\"SELL\", \"hash\":\"58500b26c202d05a77c43f6862616c3913b74e3e\", \"best_bid\":\"0.59\", \"best_ask\":\"0.6\"}], \"timestamp\":\"1785207625667\", \"event_type\":\"price_change\"}","received_at":"2026-07-28T03:00:28.230090Z","schema_version":"clob-market-ws.price_change.v1","sequence":null,"server_hash":null,"server_timestamp":"1785207625667","session_id":"3e519d9098404c15b234d96025eb1a2b","source":"clob_market_ws"},"received_at":"2026-07-28T03:00:28.230090Z","record_id":"d9839b1fb975dfd48aeb5c3f712cb58693e2c8671a84b5c79b023308bd136681","schema_fingerprint":"4aa3821a28b0b7c2400bc59aba4bcc0a76e971dadd19610d3ad38c768e124dc7","schema_version":"edge-lab-recorder.raw.v1","sequence":null,"source":"clob_market_ws"}
{"event_at":"2026-07-28T03:00:25.668000Z","event_fingerprint":"98dcc292c46fcd30b2c5d27edc05dbb25e72ced01d6401fee15028658b0d829d","payload":{"connection_id":"a6b55582af5f430fb37ad02bf0922475","event_at":"2026-07-28T03:00:25.668000Z","event_type":"price_change","frame_hash":"8cb8f503328df5fcd47da7b54c8eccbffb71618a6a505bd8786c88f37379b129","frame_index":0,"kind":"data","monotonic_ns":309611254428291,"payload":{"event_type":"price_change","market":"0x779291bef19b6709f61e9764a954aafe9ffae488d50ae674aabdcb4f248006d5","price_changes":[{"asset_id":"8761897749749422724209054078244794145777693856614463256546737399611489089783","best_ask":"0.41","best_bid":"0.4","hash":"df9fcf1f8abfcf1abb8039ea01096b8f293868e2","price":"0.32","side":"BUY","size":"99"},{"asset_id":"14965588658799411272385430903075831224615961675357217884735713260981483529984","best_ask":"0.6","best_bid":"0.59","hash":"38628c6bb755a54babd73b66bce5c1972864ccca","price":"0.68","side":"SELL","size":"99"}],"timestamp":"1785207625668"},"payload_hash":"40cae25993d551a242df2d7f366fc62bae94b5987c700342915353512c5772f8","raw_frame":"{\"market\":\"0x779291bef19b6709f61e9764a954aafe9ffae488d50ae674aabdcb4f248006d5\", \"price_changes\":[{\"asset_id\":\"8761897749749422724209054078244794145777693856614463256546737399611489089783\", \"price\":\"0.32\", \"size\":\"99\", \"side\":\"BUY\", \"hash\":\"df9fcf1f8abfcf1abb8039ea01096b8f293868e2\", \"best_bid\":\"0.4\", \"best_ask\":\"0.41\"}, {\"asset_id\":\"14965588658799411272385430903075831224615961675357217884735713260981483529984\", \"price\":\"0.68\", \"size\":\"99\", \"side\":\"SELL\", \"hash\":\"38628c6bb755a54babd73b66bce5c1972864ccca\", \"best_bid\":\"0.59\", \"best_ask\":\"0.6\"}], \"timestamp\":\"1785207625668\", \"event_type\":\"price_change\"}","received_at":"2026-07-28T03:00:28.235862Z","schema_version":"clob-market-ws.price_change.v1","sequence":null,"server_hash":null,"server_timestamp":"1785207625668","session_id":"3e519d9098404c15b234d96025eb1a2b","source":"clob_market_ws"},"received_at":"2026-07-28T03:00:28.235862Z","record_id":"34daa56ea5b4a90d15b20dc303a6424810a8ad4b54293bafa72ab2ef55bf38f3","schema_fingerprint":"4aa3821a28b0b7c2400bc59aba4bcc0a76e971dadd19610d3ad38c768e124dc7","schema_version":"edge-lab-recorder.raw.v1","sequence":null,"source":"clob_market_ws"}
{"event_at":"2026-07-28T03:00:25.684000Z","event_fingerprint":"75bd5545c1931c708caa4121b6f6a6dd47be0338d76186ff75f410c4871ab001","payload":{"connection_id":"a6b55582af5f430fb37ad02bf0922475","event_at":"2026-07-28T03:00:25.684000Z","event_type":"price_change","frame_hash":"31c7f2e1c294b81999d88f66b8c71070413d5b491bc34142331ee3c76cc598da","frame_index":0,"kind":"data","monotonic_ns":309611259239916,"payload":{"event_type":"price_change","market":"0x779291bef19b6709f61e9764a954aafe9ffae488d50ae674aabdcb4f248006d5","price_changes":[{"asset_id":"14965588658799411272385430903075831224615961675357217884735713260981483529984","best_ask":"0.6","best_bid":"0.59","hash":"e58b0c6620982e82300ce6f1edccf6a6b7475584","price":"0.57","side":"BUY","size":"475.5"},{"asset_id":"8761897749749422724209054078244794145777693856614463256546737399611489089783","best_ask":"0.41","best_bid":"0.4","hash":"ee61ecf50809e0840f970ccbdd17824b7bed0f8b","price":"0.43","side":"SELL","size":"475.5"}],"timestamp":"1785207625684"},"payload_hash":"d8f804bca8b1c4fa36e24e02805c5d6517320b98de57748ddb853ca5ec06b3eb","raw_frame":"{\"market\":\"0x779291bef19b6709f61e9764a954aafe9ffae488d50ae674aabdcb4f248006d5\", \"price_changes\":[{\"asset_id\":\"14965588658799411272385430903075831224615961675357217884735713260981483529984\", \"price\":\"0.57\", \"size\":\"475.5\", \"side\":\"BUY\", \"hash\":\"e58b0c6620982e82300ce6f1edccf6a6b7475584\", \"best_bid\":\"0.59\", \"best_ask\":\"0.6\"}, {\"asset_id\":\"8761897749749422724209054078244794145777693856614463256546737399611489089783\", \"price\":\"0.43\", \"size\":\"475.5\", \"side\":\"SELL\", \"hash\":\"ee61ecf50809e0840f970ccbdd17824b7bed0f8b\", \"best_bid\":\"0.4\", \"best_ask\":\"0.41\"}], \"timestamp\":\"1785207625684\", \"event_type\":\"price_change\"}","received_at":"2026-07-28T03:00:28.240673Z","schema_version":"clob-market-ws.price_change.v1","sequence":null,"server_hash":null,"server_timestamp":"1785207625684","session_id":"3e519d9098404c15b234d96025eb1a2b","source":"clob_market_ws"},"received_at":"2026-07-28T03:00:28.240673Z","record_id":"643fef104997581cd83cbc34406a6719776e48f76bc710badfed96a51be2afee","schema_fingerprint":"4aa3821a28b0b7c2400bc59aba4bcc0a76e971dadd19610d3ad38c768e124dc7","schema_version":"edge-lab-recorder.raw.v1","sequence":null,"source":"clob_market_ws"}
{"event_at":"2026-07-28T03:00:25.689000Z","event_fingerprint":"fdbbff87873023b1f8d0c0b804ab5ca9cafdd1a4a9a59d4f900b0f86a3cdaa00","payload":{"connection_id":"a6b55582af5f430fb37ad02bf0922475","event_at":"2026-07-28T03:00:25.689000Z","event_type":"price_change","frame_hash":"bf80b1883e860ede6e9fd11df4fb71f6b6f22d6ba167143c41e4383c81d39ddf","frame_index":0,"kind":"data","monotonic_ns":309611266496750,"payload":{"event_type":"price_change","market":"0x779291bef19b6709f61e9764a954aafe9ffae488d50ae674aabdcb4f248006d5","price_changes":[{"asset_id":"14965588658799411272385430903075831224615961675357217884735713260981483529984","best_ask":"0.6","best_bid":"0.59","hash":"33c45c146e03a52e3ec1aa779d342a7c7fbe9745","price":"0.56","side":"BUY","size":"103.32"},{"asset_id":"8761897749749422724209054078244794145777693856614463256546737399611489089783","best_ask":"0.41","best_bid":"0.4","hash":"3949641f3bc18aab1924972982666d86f9013a8c","price":"0.44","side":"SELL","size":"103.32"}],"timestamp":"1785207625689"},"payload_hash":"e81d7f9bdd717ef3c5c9cc85425de53b848edb16af55a7353b0d4932190cd951","raw_frame":"{\"market\":\"0x779291bef19b6709f61e9764a954aafe9ffae488d50ae674aabdcb4f248006d5\", \"price_changes\":[{\"asset_id\":\"14965588658799411272385430903075831224615961675357217884735713260981483529984\", \"price\":\"0.56\", \"size\":\"103.32\", \"side\":\"BUY\", \"hash\":\"33c45c146e03a52e3ec1aa779d342a7c7fbe9745\", \"best_bid\":\"0.59\", \"best_ask\":\"0.6\"}, {\"asset_id\":\"8761897749749422724209054078244794145777693856614463256546737399611489089783\", \"price\":\"0.44\", \"size\":\"103.32\", \"side\":\"SELL\", \"hash\":\"3949641f3bc18aab1924972982666d86f9013a8c\", \"best_bid\":\"0.4\", \"best_ask\":\"0.41\"}], \"timestamp\":\"1785207625689\", \"event_type\":\"price_change\"}","received_at":"2026-07-28T03:00:28.247929Z","schema_version":"clob-market-ws.price_change.v1","sequence":null,"server_hash":null,"server_timestamp":"1785207625689","session_id":"3e519d9098404c15b234d96025eb1a2b","source":"clob_market_ws"},"received_at":"2026-07-28T03:00:28.247929Z","record_id":"eb66ccdc5eb3535c13d227f9ad0b035f7f0417b8180d5dc4d242e638646a63e0","schema_fingerprint":"4aa3821a28b0b7c2400bc59aba4bcc0a76e971dadd19610d3ad38c768e124dc7","schema_version":"edge-lab-recorder.raw.v1","sequence":null,"source":"clob_market_ws"}
{"event_at":"2026-07-28T03:00:25.689000Z","event_fingerprint":"6091f578b1b63613ca22698b0a92a8033daf888a7c265704cc69d81e9673e580","payload":{"connection_id":"a6b55582af5f430fb37ad02bf0922475","event_at":"2026-07-28T03:00:25.689000Z","event_type":"price_change","frame_hash":"91113c8d053d6cfd2f0630936d778045c6a15f7e845421dc51950decb8efdd7a","frame_index":0,"kind":"data","monotonic_ns":309611276410291,"payload":{"event_type":"price_change","market":"0x779291bef19b6709f61e9764a954aafe9ffae488d50ae674aabdcb4f248006d5","price_changes":[{"asset_id":"8761897749749422724209054078244794145777693856614463256546737399611489089783","best_ask":"0.41","best_bid":"0.4","hash":"3949641f3bc18aab1924972982666d86f9013a8c","price":"0.38","side":"BUY","size":"22.6"},{"asset_id":"14965588658799411272385430903075831224615961675357217884735713260981483529984","best_ask":"0.6","best_bid":"0.59","hash":"33c45c146e03a52e3ec1aa779d342a7c7fbe9745","price":"0.62","side":"SELL","size":"22.6"}],"timestamp":"1785207625689"},"payload_hash":"46201abfe8951dedf966c0852efda54e245b4783233c2253c2582832f95d13fb","raw_frame":"{\"market\":\"0x779291bef19b6709f61e9764a954aafe9ffae488d50ae674aabdcb4f248006d5\", \"price_changes\":[{\"asset_id\":\"8761897749749422724209054078244794145777693856614463256546737399611489089783\", \"price\":\"0.38\", \"size\":\"22.6\", \"side\":\"BUY\", \"hash\":\"3949641f3bc18aab1924972982666d86f9013a8c\", \"best_bid\":\"0.4\", \"best_ask\":\"0.41\"}, {\"asset_id\":\"14965588658799411272385430903075831224615961675357217884735713260981483529984\", \"price\":\"0.62\", \"size\":\"22.6\", \"side\":\"SELL\", \"hash\":\"33c45c146e03a52e3ec1aa779d342a7c7fbe9745\", \"best_bid\":\"0.59\", \"best_ask\":\"0.6\"}], \"timestamp\":\"1785207625689\", \"event_type\":\"price_change\"}","received_at":"2026-07-28T03:00:28.257841Z","schema_version":"clob-market-ws.price_change.v1","sequence":null,"server_hash":null,"server_timestamp":"1785207625689","session_id":"3e519d9098404c15b234d96025eb1a2b","source":"clob_market_ws"},"received_at":"2026-07-28T03:00:28.257841Z","record_id":"3b5130a463a85b96abf263e04fc6bd24d1593e2a4b19ab949bd765bdf2cccf5d","schema_fingerprint":"4aa3821a28b0b7c2400bc59aba4bcc0a76e971dadd19610d3ad38c768e124dc7","schema_version":"edge-lab-recorder.raw.v1","sequence":null,"source":"clob_market_ws"}
{"event_at":"2026-07-28T03:00:25.700000Z","event_fingerprint":"ee1eb24aa6b6f01e372167377ad1024439f73e32b63c77eb8e2017cc9a226ae5","payload":{"connection_id":"a6b55582af5f430fb37ad02bf0922475","event_at":"2026-07-28T03:00:25.700000Z","event_type":"price_change","frame_hash":"a54b8f9a05eb715ece2425df73bf28e39155ff901c920191fa4e808e9c280b85","frame_index":0,"kind":"data","monotonic_ns":309611282592083,"payload":{"event_type":"price_change","market":"0x779291bef19b6709f61e9764a954aafe9ffae488d50ae674aabdcb4f248006d5","price_changes":[{"asset_id":"14965588658799411272385430903075831224615961675357217884735713260981483529984","best_ask":"0.6","best_bid":"0.59","hash":"a46147ab07cea8d77cf768522603522f10b3f7df","price":"0.44","side":"BUY","size":"40.27"},{"asset_id":"8761897749749422724209054078244794145777693856614463256546737399611489089783","best_ask":"0.41","best_bid":"0.4","hash":"9d3e0048bc353495d492f91f8928945bbcd68939","price":"0.56","side":"SELL","size":"40.27"}],"timestamp":"1785207625700"},"payload_hash":"78296f6e317a65dfe905322d65341d7d325e434b38ae720fb20ac763d9c820aa","raw_frame":"{\"market\":\"0x779291bef19b6709f61e9764a954aafe9ffae488d50ae674aabdcb4f248006d5\", \"price_changes\":[{\"asset_id\":\"14965588658799411272385430903075831224615961675357217884735713260981483529984\", \"price\":\"0.44\", \"size\":\"40.27\", \"side\":\"BUY\", \"hash\":\"a46147ab07cea8d77cf768522603522f10b3f7df\", \"best_bid\":\"0.59\", \"best_ask\":\"0.6\"}, {\"asset_id\":\"8761897749749422724209054078244794145777693856614463256546737399611489089783\", \"price\":\"0.56\", \"size\":\"40.27\", \"side\":\"SELL\", \"hash\":\"9d3e0048bc353495d492f91f8928945bbcd68939\", \"best_bid\":\"0.4\", \"best_ask\":\"0.41\"}], \"timestamp\":\"1785207625700\", \"event_type\":\"price_change\"}","received_at":"2026-07-28T03:00:28.264025Z","schema_version":"clob-market-ws.price_change.v1","sequence":null,"server_hash":null,"server_timestamp":"1785207625700","session_id":"3e519d9098404c15b234d96025eb1a2b","source":"clob_market_ws"},"received_at":"2026-07-28T03:00:28.264025Z","record_id":"c57991c2625f9d1cccb504eaff2fca3a7b201469bdcd8ec740ac0da9c2f33c01","schema_fingerprint":"4aa3821a28b0b7c2400bc59aba4bcc0a76e971dadd19610d3ad38c768e124dc7","schema_version":"edge-lab-recorder.raw.v1","sequence":null,"source":"clob_market_ws"}
{"event_at":"2026-07-28T03:00:25.705000Z","event_fingerprint":"f74e836f47d69b18e384afe4ac2fd09723184bdce27d6c0f4d0bb81126fd54a3","payload":{"connection_id":"a6b55582af5f430fb37ad02bf0922475","event_at":"2026-07-28T03:00:25.705000Z","event_type":"price_change","frame_hash":"76f9c144a4a6854c5be26c6929b9c6c816417b73bd513dc1274c36cf2db344a1","frame_index":0,"kind":"data","monotonic_ns":309611287141000,"payload":{"event_type":"price_change","market":"0x779291bef19b6709f61e9764a954aafe9ffae488d50ae674aabdcb4f248006d5","price_changes":[{"asset_id":"8761897749749422724209054078244794145777693856614463256546737399611489089783","best_ask":"0.41","best_bid":"0.4","hash":"408e3b0454783e3aae7457e482605ef225ff7258","price":"0.27","side":"BUY","size":"123.59"},{"asset_id":"14965588658799411272385430903075831224615961675357217884735713260981483529984","best_ask":"0.6","best_bid":"0.59","hash":"b0f5033adae27d2b0f1293992015118ca1759809","price":"0.73","side":"SELL","size":"123.59"}],"timestamp":"1785207625705"},"payload_hash":"9d382f55b7463eafd1ae34f839efe26654424321893b81d13bbf64693c87b770","raw_frame":"{\"market\":\"0x779291bef19b6709f61e9764a954aafe9ffae488d50ae674aabdcb4f248006d5\", \"price_changes\":[{\"asset_id\":\"8761897749749422724209054078244794145777693856614463256546737399611489089783\", \"price\":\"0.27\", \"size\":\"123.59\", \"side\":\"BUY\", \"hash\":\"408e3b0454783e3aae7457e482605ef225ff7258\", \"best_bid\":\"0.4\", \"best_ask\":\"0.41\"}, {\"asset_id\":\"14965588658799411272385430903075831224615961675357217884735713260981483529984\", \"price\":\"0.73\", \"size\":\"123.59\", \"side\":\"SELL\", \"hash\":\"b0f5033adae27d2b0f1293992015118ca1759809\", \"best_bid\":\"0.59\", \"best_ask\":\"0.6\"}], \"timestamp\":\"1785207625705\", \"event_type\":\"price_change\"}","received_at":"2026-07-28T03:00:28.268574Z","schema_version":"clob-market-ws.price_change.v1","sequence":null,"server_hash":null,"server_timestamp":"1785207625705","session_id":"3e519d9098404c15b234d96025eb1a2b","source":"clob_market_ws"},"received_at":"2026-07-28T03:00:28.268574Z","record_id":"bd99b407fdde032639872ea16886bed8623c19b7cfc8f22ab7b515010d806d69","schema_fingerprint":"4aa3821a28b0b7c2400bc59aba4bcc0a76e971dadd19610d3ad38c768e124dc7","schema_version":"edge-lab-recorder.raw.v1","sequence":null,"source":"clob_market_ws"}
{"event_at":"2026-07-28T03:00:25.719000Z","event_fingerprint":"cfd8131c968d286807b4b03b772917d95a4f595da7790a4eb7c4062da7eca0e4","payload":{"connection_id":"a6b55582af5f430fb37ad02bf0922475","event_at":"2026-07-28T03:00:25.719000Z","event_type":"price_change","frame_hash":"49f1703d3f4a65fa4f22d7d820514f51bbc58d81d28998f6a0f00ce79380988d","frame_index":0,"kind":"data","monotonic_ns":309611293490541,"payload":{"event_type":"price_change","market":"0x779291bef19b6709f61e9764a954aafe9ffae488d50ae674aabdcb4f248006d5","price_changes":[{"asset_id":"14965588658799411272385430903075831224615961675357217884735713260981483529984","best_ask":"0.6","best_bid":"0.59","hash":"0fd65b943b86ab15bce7fa10014f6421bcc8da98","price":"0.01","side":"BUY","size":"7555.02"},{"asset_id":"8761897749749422724209054078244794145777693856614463256546737399611489089783","best_ask":"0.41","best_bid":"0.4","hash":"6b072618e6308e524f1e0f157bd5f65b1fa826e5","price":"0.99","side":"SELL","size":"7555.02"}],"timestamp":"1785207625719"},"payload_hash":"9fddb53783f5115a6ae37caccf51eb1dd9bc22f1f5decbb3b57b8df461078659","raw_frame":"{\"market\":\"0x779291bef19b6709f61e9764a954aafe9ffae488d50ae674aabdcb4f248006d5\", \"price_changes\":[{\"asset_id\":\"14965588658799411272385430903075831224615961675357217884735713260981483529984\", \"price\":\"0.01\", \"size\":\"7555.02\", \"side\":\"BUY\", \"hash\":\"0fd65b943b86ab15bce7fa10014f6421bcc8da98\", \"best_bid\":\"0.59\", \"best_ask\":\"0.6\"}, {\"asset_id\":\"8761897749749422724209054078244794145777693856614463256546737399611489089783\", \"price\":\"0.99\", \"size\":\"7555.02\", \"side\":\"SELL\", \"hash\":\"6b072618e6308e524f1e0f157bd5f65b1fa826e5\", \"best_bid\":\"0.4\", \"best_ask\":\"0.41\"}], \"timestamp\":\"1785207625719\", \"event_type\":\"price_change\"}","received_at":"2026-07-28T03:00:28.274923Z","schema_version":"clob-market-ws.price_change.v1","sequence":null,"server_hash":null,"server_timestamp":"1785207625719","session_id":"3e519d9098404c15b234d96025eb1a2b","source":"clob_market_ws"},"received_at":"2026-07-28T03:00:28.274923Z","record_id":"cee9337c586c07238661d41e09f428dce530c19464572669451a7aa0077101e2","schema_fingerprint":"4aa3821a28b0b7c2400bc59aba4bcc0a76e971dadd19610d3ad38c768e124dc7","schema_version":"edge-lab-recorder.raw.v1","sequence":null,"source":"clob_market_ws"}
{"event_at":"2026-07-28T03:00:25.720000Z","event_fingerprint":"0b8f17020ab90df66b99a8e39f8a7059a29ede4d8fd408160185f1674d4533ac","payload":{"connection_id":"a6b55582af5f430fb37ad02bf0922475","event_at":"2026-07-28T03:00:25.720000Z","event_type":"price_change","frame_hash":"13b8f8ea7c5cc1639afa409c2ad09f549f2c3af006a2846ed8600adcffb6c51a","frame_index":0,"kind":"data","monotonic_ns":309611297061291,"payload":{"event_type":"price_change","market":"0x779291bef19b6709f61e9764a954aafe9ffae488d50ae674aabdcb4f248006d5","price_changes":[{"asset_id":"8761897749749422724209054078244794145777693856614463256546737399611489089783","best_ask":"0.41","best_bid":"0.4","hash":"365c0ab22d9df9ec4892da9dfa6ea9778cdc8a6a","price":"0.39","side":"BUY","size":"96"},{"asset_id":"14965588658799411272385430903075831224615961675357217884735713260981483529984","best_ask":"0.6","best_bid":"0.59","hash":"02f018193463d2fdf5238caf854176140e459f88","price":"0.61","side":"SELL","size":"96"}],"timestamp":"1785207625720"},"payload_hash":"a8a54d9a93946e34f44ad4490989b5198bace1b8563245d2f49243bf08d76859","raw_frame":"{\"market\":\"0x779291bef19b6709f61e9764a954aafe9ffae488d50ae674aabdcb4f248006d5\", \"price_changes\":[{\"asset_id\":\"8761897749749422724209054078244794145777693856614463256546737399611489089783\", \"price\":\"0.39\", \"size\":\"96\", \"side\":\"BUY\", \"hash\":\"365c0ab22d9df9ec4892da9dfa6ea9778cdc8a6a\", \"best_bid\":\"0.4\", \"best_ask\":\"0.41\"}, {\"asset_id\":\"14965588658799411272385430903075831224615961675357217884735713260981483529984\", \"price\":\"0.61\", \"size\":\"96\", \"side\":\"SELL\", \"hash\":\"02f018193463d2fdf5238caf854176140e459f88\", \"best_bid\":\"0.59\", \"best_ask\":\"0.6\"}], \"timestamp\":\"1785207625720\", \"event_type\":\"price_change\"}","received_at":"2026-07-28T03:00:28.278494Z","schema_version":"clob-market-ws.price_change.v1","sequence":null,"server_hash":null,"server_timestamp":"1785207625720","session_id":"3e519d9098404c15b234d96025eb1a2b","source":"clob_market_ws"},"received_at":"2026-07-28T03:00:28.278494Z","record_id":"d534bddda8376e1ba6aa1668fd4a2475c414a5f79ea08aeda307ae8e9df323db","schema_fingerprint":"4aa3821a28b0b7c2400bc59aba4bcc0a76e971dadd19610d3ad38c768e124dc7","schema_version":"edge-lab-recorder.raw.v1","sequence":null,"source":"clob_market_ws"}
{"event_at":"2026-07-28T03:00:25.721000Z","event_fingerprint":"6a238b37c8759adeeafef3ba7552b8a9355c7af103dc100a0cb90598d53f9ecd","payload":{"connection_id":"a6b55582af5f430fb37ad02bf0922475","event_at":"2026-07-28T03:00:25.721000Z","event_type":"price_change","frame_hash":"3b772ab5dfef7d7a5b2bfdd3026a2e70fb389ed5db2d9bbf363ea50593fedb66","frame_index":0,"kind":"data","monotonic_ns":309611305701416,"payload":{"event_type":"price_change","market":"0x779291bef19b6709f61e9764a954aafe9ffae488d50ae674aabdcb4f248006d5","price_changes":[{"asset_id":"14965588658799411272385430903075831224615961675357217884735713260981483529984","best_ask":"0.6","best_bid":"0.59","hash":"b22baf9c24d323b6483e082795ade26e50892c97","price":"0.55","side":"BUY","size":"102.2"},{"asset_id":"8761897749749422724209054078244794145777693856614463256546737399611489089783","best_ask":"0.41","best_bid":"0.4","hash":"fee62c08a40f2856e5217637c6d4f5ddf8d46fea","price":"0.45","side":"SELL","size":"102.2"}],"timestamp":"1785207625721"},"payload_hash":"64572c7dff95039bfc763e55f8b14ce130118262c71c6fd97eee778af82ac12e","raw_frame":"{\"market\":\"0x779291bef19b6709f61e9764a954aafe9ffae488d50ae674aabdcb4f248006d5\", \"price_changes\":[{\"asset_id\":\"14965588658799411272385430903075831224615961675357217884735713260981483529984\", \"price\":\"0.55\", \"size\":\"102.2\", \"side\":\"BUY\", \"hash\":\"b22baf9c24d323b6483e082795ade26e50892c97\", \"best_bid\":\"0.59\", \"best_ask\":\"0.6\"}, {\"asset_id\":\"8761897749749422724209054078244794145777693856614463256546737399611489089783\", \"price\":\"0.45\", \"size\":\"102.2\", \"side\":\"SELL\", \"hash\":\"fee62c08a40f2856e5217637c6d4f5ddf8d46fea\", \"best_bid\":\"0.4\", \"best_ask\":\"0.41\"}], \"timestamp\":\"1785207625721\", \"event_type\":\"price_change\"}","received_at":"2026-07-28T03:00:28.287133Z","schema_version":"clob-market-ws.price_change.v1","sequence":null,"server_hash":null,"server_timestamp":"1785207625721","session_id":"3e519d9098404c15b234d96025eb1a2b","source":"clob_market_ws"},"received_at":"2026-07-28T03:00:28.287133Z","record_id":"0488b9ec0b595cb4867ae348746da2fcec05c2018b56908c8234a1ade3253d56","schema_fingerprint":"4aa3821a28b0b7c2400bc59aba4bcc0a76e971dadd19610d3ad38c768e124dc7","schema_version":"edge-lab-recorder.raw.v1","sequence":null,"source":"clob_market_ws"}
{"event_at":"2026-07-28T03:00:25.724000Z","event_fingerprint":"f8d6946f4b143095d3a914c03c6b49ef0b2576b3b8e588435f571856e8b85555","payload":{"connection_id":"a6b55582af5f430fb37ad02bf0922475","event_at":"2026-07-28T03:00:25.724000Z","event_type":"price_change","frame_hash":"6a829ccff86616551b8e4e5f1d86b33d1935d690de17cb0a5b82367271ec9af1","frame_index":0,"kind":"data","monotonic_ns":309611312505583,"payload":{"event_type":"price_change","market":"0x779291bef19b6709f61e9764a954aafe9ffae488d50ae674aabdcb4f248006d5","price_changes":[{"asset_id":"14965588658799411272385430903075831224615961675357217884735713260981483529984","best_ask":"0.6","best_bid":"0.59","hash":"0d7a2b9b962be9aba3b7b6132df650a4fce0a765","price":"0.56","side":"BUY","size":"108.32"},{"asset_id":"8761897749749422724209054078244794145777693856614463256546737399611489089783","best_ask":"0.41","best_bid":"0.4","hash":"2f3cfc55fec0ce16d023754ca6a116b2e04ee03e","price":"0.44","side":"SELL","size":"108.32"}],"timestamp":"1785207625724"},"payload_hash":"2a60221c03abd9269e009b5a2f590690e08b0c8c35296b9f9ff3eb1553a181f6","raw_frame":"{\"market\":\"0x779291bef19b6709f61e9764a954aafe9ffae488d50ae674aabdcb4f248006d5\", \"price_changes\":[{\"asset_id\":\"14965588658799411272385430903075831224615961675357217884735713260981483529984\", \"price\":\"0.56\", \"size\":\"108.32\", \"side\":\"BUY\", \"hash\":\"0d7a2b9b962be9aba3b7b6132df650a4fce0a765\", \"best_bid\":\"0.59\", \"best_ask\":\"0.6\"}, {\"asset_id\":\"8761897749749422724209054078244794145777693856614463256546737399611489089783\", \"price\":\"0.44\", \"size\":\"108.32\", \"side\":\"SELL\", \"hash\":\"2f3cfc55fec0ce16d023754ca6a116b2e04ee03e\", \"best_bid\":\"0.4\", \"best_ask\":\"0.41\"}], \"timestamp\":\"1785207625724\", \"event_type\":\"price_change\"}","received_at":"2026-07-28T03:00:28.293932Z","schema_version":"clob-market-ws.price_change.v1","sequence":null,"server_hash":null,"server_timestamp":"1785207625724","session_id":"3e519d9098404c15b234d96025eb1a2b","source":"clob_market_ws"},"received_at":"2026-07-28T03:00:28.293932Z","record_id":"46e279abf9f677cfdd6391b622e449b6d806960209aa9a80926a850fc888c58e","schema_fingerprint":"4aa3821a28b0b7c2400bc59aba4bcc0a76e971dadd19610d3ad38c768e124dc7","schema_version":"edge-lab-recorder.raw.v1","sequence":null,"source":"clob_market_ws"}
{"event_at":"2026-07-28T03:00:25.726000Z","event_fingerprint":"3a94a818a6a5b727254860e334a87f1cdd85c0c580a21b855d22272ab7b49ad9","payload":{"connection_id":"a6b55582af5f430fb37ad02bf0922475","event_at":"2026-07-28T03:00:25.726000Z","event_type":"price_change","frame_hash":"4f46978bfb540b7e50c24968137bdacb40cd411f1d026387d413456ea311da00","frame_index":0,"kind":"data","monotonic_ns":309611320527208,"payload":{"event_type":"price_change","market":"0x779291bef19b6709f61e9764a954aafe9ffae488d50ae674aabdcb4f248006d5","price_changes":[{"asset_id":"14965588658799411272385430903075831224615961675357217884735713260981483529984","best_ask":"0.6","best_bid":"0.59","hash":"2d1209667be64d34c62e49888d1a683acfbf380c","price":"0.03","side":"BUY","size":"955"},{"asset_id":"8761897749749422724209054078244794145777693856614463256546737399611489089783","best_ask":"0.41","best_bid":"0.4","hash":"30c14b204c3fb8f8a7bed237074e0b2261bc28ec","price":"0.97","side":"SELL","size":"955"}],"timestamp":"1785207625726"},"payload_hash":"af680067c336788d85348f25acb6f796ecbcfef68ba48ed442033e0485a3cdb4","raw_frame":"{\"market\":\"0x779291bef19b6709f61e9764a954aafe9ffae488d50ae674aabdcb4f248006d5\", \"price_changes\":[{\"asset_id\":\"14965588658799411272385430903075831224615961675357217884735713260981483529984\", \"price\":\"0.03\", \"size\":\"955\", \"side\":\"BUY\", \"hash\":\"2d1209667be64d34c62e49888d1a683acfbf380c\", \"best_bid\":\"0.59\", \"best_ask\":\"0.6\"}, {\"asset_id\":\"8761897749749422724209054078244794145777693856614463256546737399611489089783\", \"price\":\"0.97\", \"size\":\"955\", \"side\":\"SELL\", \"hash\":\"30c14b204c3fb8f8a7bed237074e0b2261bc28ec\", \"best_bid\":\"0.4\", \"best_ask\":\"0.41\"}], \"timestamp\":\"1785207625726\", \"event_type\":\"price_change\"}","received_at":"2026-07-28T03:00:28.301960Z","schema_version":"clob-market-ws.price_change.v1","sequence":null,"server_hash":null,"server_timestamp":"1785207625726","session_id":"3e519d9098404c15b234d96025eb1a2b","source":"clob_market_ws"},"received_at":"2026-07-28T03:00:28.301960Z","record_id":"2e55b0ab0a67cb3fa0280474e18c9f326334c3e4fbd71409b122357cc65b4caf","schema_fingerprint":"4aa3821a28b0b7c2400bc59aba4bcc0a76e971dadd19610d3ad38c768e124dc7","schema_version":"edge-lab-recorder.raw.v1","sequence":null,"source":"clob_market_ws"}
{"event_at":"2026-07-28T03:00:25.734000Z","event_fingerprint":"1c07e5123e3aac5d7e9c866273ce2287f0a551431a9f0950fab4f2f94eb398ae","payload":{"connection_id":"a6b55582af5f430fb37ad02bf0922475","event_at":"2026-07-28T03:00:25.734000Z","event_type":"price_change","frame_hash":"f1a1abf51c81c9359e9f9e35da9919156ed8c2043f42f3fa0621ec4995f8a3f5","frame_index":0,"kind":"data","monotonic_ns":309611326783916,"payload":{"event_type":"price_change","market":"0x779291bef19b6709f61e9764a954aafe9ffae488d50ae674aabdcb4f248006d5","price_changes":[{"asset_id":"8761897749749422724209054078244794145777693856614463256546737399611489089783","best_ask":"0.41","best_bid":"0.4","hash":"ed44e5a0783fff4047045d81aecca71eed705fc1","price":"0.21","side":"BUY","size":"173.72"},{"asset_id":"14965588658799411272385430903075831224615961675357217884735713260981483529984","best_ask":"0.6","best_bid":"0.59","hash":"12da1d5c92b81cf0200f1dacf7ef254e802e8214","price":"0.79","side":"SELL","size":"173.72"}],"timestamp":"1785207625734"},"payload_hash":"7529683e0d9a7c777980187bc374fecd412dc36d6c9eba1a7191f7c0ef02347a","raw_frame":"{\"market\":\"0x779291bef19b6709f61e9764a954aafe9ffae488d50ae674aabdcb4f248006d5\", \"price_changes\":[{\"asset_id\":\"8761897749749422724209054078244794145777693856614463256546737399611489089783\", \"price\":\"0.21\", \"size\":\"173.72\", \"side\":\"BUY\", \"hash\":\"ed44e5a0783fff4047045d81aecca71eed705fc1\", \"best_bid\":\"0.4\", \"best_ask\":\"0.41\"}, {\"asset_id\":\"14965588658799411272385430903075831224615961675357217884735713260981483529984\", \"price\":\"0.79\", \"size\":\"173.72\", \"side\":\"SELL\", \"hash\":\"12da1d5c92b81cf0200f1dacf7ef254e802e8214\", \"best_bid\":\"0.59\", \"best_ask\":\"0.6\"}], \"timestamp\":\"1785207625734\", \"event_type\":\"price_change\"}","received_at":"2026-07-28T03:00:28.308217Z","schema_version":"clob-market-ws.price_change.v1","sequence":null,"server_hash":null,"server_timestamp":"1785207625734","session_id":"3e519d9098404c15b234d96025eb1a2b","source":"clob_market_ws"},"received_at":"2026-07-28T03:00:28.308217Z","record_id":"525504b1c8874e70725e2a76000bb422de73897e68342c0175dc23c13533c41f","schema_fingerprint":"4aa3821a28b0b7c2400bc59aba4bcc0a76e971dadd19610d3ad38c768e124dc7","schema_version":"edge-lab-recorder.raw.v1","sequence":null,"source":"clob_market_ws"}
{"event_at":"2026-07-28T03:00:25.736000Z","event_fingerprint":"27164f71020f454b7cfbe70fcd55733a9ed0f55461d1e9c5b48fa593c1f7b9d1","payload":{"connection_id":"a6b55582af5f430fb37ad02bf0922475","event_at":"2026-07-28T03:00:25.736000Z","event_type":"price_change","frame_hash":"6ae25c996f8b1dbbd07e9804909d9ba4b2c6536c2e8a4d23ff7fe266e71ba2c4","frame_index":0,"kind":"data","monotonic_ns":309611335820916,"payload":{"event_type":"price_change","market":"0x779291bef19b6709f61e9764a954aafe9ffae488d50ae674aabdcb4f248006d5","price_changes":[{"asset_id":"8761897749749422724209054078244794145777693856614463256546737399611489089783","best_ask":"0.41","best_bid":"0.4","hash":"bba75f9b78f4bd87e383b49fff2e013b6f6ed6cd","price":"0.32","side":"BUY","size":"129"},{"asset_id":"14965588658799411272385430903075831224615961675357217884735713260981483529984","best_ask":"0.6","best_bid":"0.59","hash":"4df81376b73b6337cc31c0b1e89d6cfa92404112","price":"0.68","side":"SELL","size":"129"}],"timestamp":"1785207625736"},"payload_hash":"ba695aa0228369a5898c01165654b47a6431c205e405a373d40ffbcdf26249cf","raw_frame":"{\"market\":\"0x779291bef19b6709f61e9764a954aafe9ffae488d50ae674aabdcb4f248006d5\", \"price_changes\":[{\"asset_id\":\"8761897749749422724209054078244794145777693856614463256546737399611489089783\", \"price\":\"0.32\", \"size\":\"129\", \"side\":\"BUY\", \"hash\":\"bba75f9b78f4bd87e383b49fff2e013b6f6ed6cd\", \"best_bid\":\"0.4\", \"best_ask\":\"0.41\"}, {\"asset_id\":\"14965588658799411272385430903075831224615961675357217884735713260981483529984\", \"price\":\"0.68\", \"size\":\"129\", \"side\":\"SELL\", \"hash\":\"4df81376b73b6337cc31c0b1e89d6cfa92404112\", \"best_bid\":\"0.59\", \"best_ask\":\"0.6\"}], \"timestamp\":\"1785207625736\", \"event_type\":\"price_change\"}","received_at":"2026-07-28T03:00:28.317253Z","schema_version":"clob-market-ws.price_change.v1","sequence":null,"server_hash":null,"server_timestamp":"1785207625736","session_id":"3e519d9098404c15b234d96025eb1a2b","source":"clob_market_ws"},"received_at":"2026-07-28T03:00:28.317253Z","record_id":"bab27bc58b8616e9c2e71ccec38f443c022d8e694c61d4c9e18b86c4675e1060","schema_fingerprint":"4aa3821a28b0b7c2400bc59aba4bcc0a76e971dadd19610d3ad38c768e124dc7","schema_version":"edge-lab-recorder.raw.v1","sequence":null,"source":"clob_market_ws"}
{"event_at":"2026-07-28T03:00:25.737000Z","event_fingerprint":"0fd9c29d3b34c728792186d10c0ccc2d8cf460695fefa16e01db18efa78f5499","payload":{"connection_id":"a6b55582af5f430fb37ad02bf0922475","event_at":"2026-07-28T03:00:25.737000Z","event_type":"price_change","frame_hash":"2a4d873e392913b3f01479baa3c1360e931424c619cd4f953acc4d5c979c0242","frame_index":0,"kind":"data","monotonic_ns":309611344733083,"payload":{"event_type":"price_change","market":"0x779291bef19b6709f61e9764a954aafe9ffae488d50ae674aabdcb4f248006d5","price_changes":[{"asset_id":"8761897749749422724209054078244794145777693856614463256546737399611489089783","best_ask":"0.41","best_bid":"0.4","hash":"139a4a7289d2d18e5c32224a7b35b60733bf1a42","price":"0.32","side":"BUY","size":"159"},{"asset_id":"14965588658799411272385430903075831224615961675357217884735713260981483529984","best_ask":"0.6","best_bid":"0.59","hash":"08bd72faa556c92a0095ea38b50d3c51125ecedd","price":"0.68","side":"SELL","size":"159"}],"timestamp":"1785207625737"},"payload_hash":"0a864d5da9566ea4def012068534f29e3440c9e63f2a16426a21e73966d67169","raw_frame":"{\"market\":\"0x779291bef19b6709f61e9764a954aafe9ffae488d50ae674aabdcb4f248006d5\", \"price_changes\":[{\"asset_id\":\"8761897749749422724209054078244794145777693856614463256546737399611489089783\", \"price\":\"0.32\", \"size\":\"159\", \"side\":\"BUY\", \"hash\":\"139a4a7289d2d18e5c32224a7b35b60733bf1a42\", \"best_bid\":\"0.4\", \"best_ask\":\"0.41\"}, {\"asset_id\":\"14965588658799411272385430903075831224615961675357217884735713260981483529984\", \"price\":\"0.68\", \"size\":\"159\", \"side\":\"SELL\", \"hash\":\"08bd72faa556c92a0095ea38b50d3c51125ecedd\", \"best_bid\":\"0.59\", \"best_ask\":\"0.6\"}], \"timestamp\":\"1785207625737\", \"event_type\":\"price_change\"}","received_at":"2026-07-28T03:00:28.326164Z","schema_version":"clob-market-ws.price_change.v1","sequence":null,"server_hash":null,"server_timestamp":"1785207625737","session_id":"3e519d9098404c15b234d96025eb1a2b","source":"clob_market_ws"},"received_at":"2026-07-28T03:00:28.326164Z","record_id":"91e97e47d2bc82fd5fb49fdeeba63ea93acfff106e3177ef48c1f470dd9a1424","schema_fingerprint":"4aa3821a28b0b7c2400bc59aba4bcc0a76e971dadd19610d3ad38c768e124dc7","schema_version":"edge-lab-recorder.raw.v1","sequence":null,"source":"clob_market_ws"}
{"event_at":"2026-07-28T03:00:25.740000Z","event_fingerprint":"f82197136c22934ae2f6c76266198c80dcdc5508424ee24b3eeaf2de7c415b83","payload":{"connection_id":"a6b55582af5f430fb37ad02bf0922475","event_at":"2026-07-28T03:00:25.740000Z","event_type":"price_change","frame_hash":"e9fb7adb89ec6c1ec2691a68ec9099eb75c3aac4d6592b055539574877157ce5","frame_index":0,"kind":"data","monotonic_ns":309611353746041,"payload":{"event_type":"price_change","market":"0x779291bef19b6709f61e9764a954aafe9ffae488d50ae674aabdcb4f248006d5","price_changes":[{"asset_id":"14965588658799411272385430903075831224615961675357217884735713260981483529984","best_ask":"0.6","best_bid":"0.59","hash":"35c7d9cb5ce40e3ca22f01570e8e409084fb4881","price":"0.01","side":"BUY","size":"7550.02"},{"asset_id":"8761897749749422724209054078244794145777693856614463256546737399611489089783","best_ask":"0.41","best_bid":"0.4","hash":"b95d241893da6a922f64f9ba4e0a4c614d25f52b","price":"0.99","side":"SELL","size":"7550.02"}],"timestamp":"1785207625740"},"payload_hash":"221410eeddba636e4f5bda240e21fb53d6ceedfb34f701cf3a09c452b4325868","raw_frame":"{\"market\":\"0x779291bef19b6709f61e9764a954aafe9ffae488d50ae674aabdcb4f248006d5\", \"price_changes\":[{\"asset_id\":\"14965588658799411272385430903075831224615961675357217884735713260981483529984\", \"price\":\"0.01\", \"size\":\"7550.02\", \"side\":\"BUY\", \"hash\":\"35c7d9cb5ce40e3ca22f01570e8e409084fb4881\", \"best_bid\":\"0.59\", \"best_ask\":\"0.6\"}, {\"asset_id\":\"8761897749749422724209054078244794145777693856614463256546737399611489089783\", \"price\":\"0.99\", \"size\":\"7550.02\", \"side\":\"SELL\", \"hash\":\"b95d241893da6a922f64f9ba4e0a4c614d25f52b\", \"best_bid\":\"0.4\", \"best_ask\":\"0.41\"}], \"timestamp\":\"1785207625740\", \"event_type\":\"price_change\"}","received_at":"2026-07-28T03:00:28.335175Z","schema_version":"clob-market-ws.price_change.v1","sequence":null,"server_hash":null,"server_timestamp":"1785207625740","session_id":"3e519d9098404c15b234d96025eb1a2b","source":"clob_market_ws"},"received_at":"2026-07-28T03:00:28.335175Z","record_id":"a87c8c7a6187828258bba1d2db18fe742015c51a47474feaaf8bd3abb55cecab","schema_fingerprint":"4aa3821a28b0b7c2400bc59aba4bcc0a76e971dadd19610d3ad38c768e124dc7","schema_version":"edge-lab-recorder.raw.v1","sequence":null,"source":"clob_market_ws"}
{"event_at":"2026-07-28T03:00:25.740000Z","event_fingerprint":"8d2eb16af18e9d1be2b8804917dafeee121f5c603deb89a1c0f9a237494f6680","payload":{"connection_id":"a6b55582af5f430fb37ad02bf0922475","event_at":"2026-07-28T03:00:25.740000Z","event_type":"price_change","frame_hash":"aff5dedac8e628e3b26aff1fbb7649689bb7743e90208294206035eef67b0600","frame_index":0,"kind":"data","monotonic_ns":309611365209125,"payload":{"event_type":"price_change","market":"0x779291bef19b6709f61e9764a954aafe9ffae488d50ae674aabdcb4f248006d5","price_changes":[{"asset_id":"8761897749749422724209054078244794145777693856614463256546737399611489089783","best_ask":"0.41","best_bid":"0.4","hash":"86e1fb42f1cbc38c1e3f6b8ef6da4aacd1df2a7e","price":"0.32","side":"BUY","size":"189"},{"asset_id":"14965588658799411272385430903075831224615961675357217884735713260981483529984","best_ask":"0.6","best_bid":"0.59","hash":"54468b767a91f1980179335f8e2ddf56a6932579","price":"0.68","side":"SELL","size":"189"}],"timestamp":"1785207625740"},"payload_hash":"3e0f5dfb1a8610780b20787d2e36ed376a442e7d41ebe41d280376edded7fe9d","raw_frame":"{\"market\":\"0x779291bef19b6709f61e9764a954aafe9ffae488d50ae674aabdcb4f248006d5\", \"price_changes\":[{\"asset_id\":\"8761897749749422724209054078244794145777693856614463256546737399611489089783\", \"price\":\"0.32\", \"size\":\"189\", \"side\":\"BUY\", \"hash\":\"86e1fb42f1cbc38c1e3f6b8ef6da4aacd1df2a7e\", \"best_bid\":\"0.4\", \"best_ask\":\"0.41\"}, {\"asset_id\":\"14965588658799411272385430903075831224615961675357217884735713260981483529984\", \"price\":\"0.68\", \"size\":\"189\", \"side\":\"SELL\", \"hash\":\"54468b767a91f1980179335f8e2ddf56a6932579\", \"best_bid\":\"0.59\", \"best_ask\":\"0.6\"}], \"timestamp\":\"1785207625740\", \"event_type\":\"price_change\"}","received_at":"2026-07-28T03:00:28.346638Z","schema_version":"clob-market-ws.price_change.v1","sequence":null,"server_hash":null,"server_timestamp":"1785207625740","session_id":"3e519d9098404c15b234d96025eb1a2b","source":"clob_market_ws"},"received_at":"2026-07-28T03:00:28.346638Z","record_id":"b13690d16fa7ed5d7c3a8bdf26752daf51d477f1c45aad6aa2f4c24835da0f4e","schema_fingerprint":"4aa3821a28b0b7c2400bc59aba4bcc0a76e971dadd19610d3ad38c768e124dc7","schema_version":"edge-lab-recorder.raw.v1","sequence":null,"source":"clob_market_ws"}
{"event_at":"2026-07-28T03:00:25.742000Z","event_fingerprint":"26f32a5c8980ebbe3cb81ccb414ef3c8c6f277fafdf3c2f37d8b039441d68deb","payload":{"connection_id":"a6b55582af5f430fb37ad02bf0922475","event_at":"2026-07-28T03:00:25.742000Z","event_type":"price_change","frame_hash":"8742b32d772accb435b5b46adcf0e297370a0d2c62f220bb35837db605a98f2f","frame_index":0,"kind":"data","monotonic_ns":309611374647875,"payload":{"event_type":"price_change","market":"0x779291bef19b6709f61e9764a954aafe9ffae488d50ae674aabdcb4f248006d5","price_changes":[{"asset_id":"14965588658799411272385430903075831224615961675357217884735713260981483529984","best_ask":"0.6","best_bid":"0.59","hash":"517e97f2904f1aeb1fba9d3202c5f8c18cd279f1","price":"0.43","side":"BUY","size":"190.02"},{"asset_id":"8761897749749422724209054078244794145777693856614463256546737399611489089783","best_ask":"0.41","best_bid":"0.4","hash":"c8491f2af12aab292836eda75336a59b55dee4a0","price":"0.57","side":"SELL","size":"190.02"}],"timestamp":"1785207625742"},"payload_hash":"6676a52a12d73017a1babc7b1e1e7f84b13de97a628cdd7517b4609c208d55bb","raw_frame":"{\"market\":\"0x779291bef19b6709f61e9764a954aafe9ffae488d50ae674aabdcb4f248006d5\", \"price_changes\":[{\"asset_id\":\"14965588658799411272385430903075831224615961675357217884735713260981483529984\", \"price\":\"0.43\", \"size\":\"190.02\", \"side\":\"BUY\", \"hash\":\"517e97f2904f1aeb1fba9d3202c5f8c18cd279f1\", \"best_bid\":\"0.59\", \"best_ask\":\"0.6\"}, {\"asset_id\":\"8761897749749422724209054078244794145777693856614463256546737399611489089783\", \"price\":\"0.57\", \"size\":\"190.02\", \"side\":\"SELL\", \"hash\":\"c8491f2af12aab292836eda75336a59b55dee4a0\", \"best_bid\":\"0.4\", \"best_ask\":\"0.41\"}], \"timestamp\":\"1785207625742\", \"event_type\":\"price_change\"}","received_at":"2026-07-28T03:00:28.356079Z","schema_version":"clob-market-ws.price_change.v1","sequence":null,"server_hash":null,"server_timestamp":"1785207625742","session_id":"3e519d9098404c15b234d96025eb1a2b","source":"clob_market_ws"},"received_at":"2026-07-28T03:00:28.356079Z","record_id":"9cf447c5e345646cec051d703fb2d810c7600573f78734e4c5756b8d0d2e2315","schema_fingerprint":"4aa3821a28b0b7c2400bc59aba4bcc0a76e971dadd19610d3ad38c768e124dc7","schema_version":"edge-lab-recorder.raw.v1","sequence":null,"source":"clob_market_ws"}
{"event_at":"2026-07-28T03:00:25.748000Z","event_fingerprint":"30b428f8ba8979892bae114670c5a69fc953828ffaee16e2b1bc2af7387c923d","payload":{"connection_id":"a6b55582af5f430fb37ad02bf0922475","event_at":"2026-07-28T03:00:25.748000Z","event_type":"price_change","frame_hash":"e8a074f5eecaf00197acb00dddf55e185f17b92193848ea4fa8d4367a9004416","frame_index":0,"kind":"data","monotonic_ns":309611380766166,"payload":{"event_type":"price_change","market":"0x779291bef19b6709f61e9764a954aafe9ffae488d50ae674aabdcb4f248006d5","price_changes":[{"asset_id":"14965588658799411272385430903075831224615961675357217884735713260981483529984","best_ask":"0.6","best_bid":"0.59","hash":"63b76bfcd7a29abaaa0f9c371acc14ca6b3ebe39","price":"0.43","side":"BUY","size":"112.51"},{"asset_id":"8761897749749422724209054078244794145777693856614463256546737399611489089783","best_ask":"0.41","best_bid":"0.4","hash":"3de2d0d4e517edfc3520efc47d4d2f9fb389e433","price":"0.57","side":"SELL","size":"112.51"}],"timestamp":"1785207625748"},"payload_hash":"6c0436f8194ef6459da8371d2e96454ffe1dee1e44815951f376457617780cf2","raw_frame":"{\"market\":\"0x779291bef19b6709f61e9764a954aafe9ffae488d50ae674aabdcb4f248006d5\", \"price_changes\":[{\"asset_id\":\"14965588658799411272385430903075831224615961675357217884735713260981483529984\", \"price\":\"0.43\", \"size\":\"112.51\", \"side\":\"BUY\", \"hash\":\"63b76bfcd7a29abaaa0f9c371acc14ca6b3ebe39\", \"best_bid\":\"0.59\", \"best_ask\":\"0.6\"}, {\"asset_id\":\"8761897749749422724209054078244794145777693856614463256546737399611489089783\", \"price\":\"0.57\", \"size\":\"112.51\", \"side\":\"SELL\", \"hash\":\"3de2d0d4e517edfc3520efc47d4d2f9fb389e433\", \"best_bid\":\"0.4\", \"best_ask\":\"0.41\"}], \"timestamp\":\"1785207625748\", \"event_type\":\"price_change\"}","received_at":"2026-07-28T03:00:28.362195Z","schema_version":"clob-market-ws.price_change.v1","sequence":null,"server_hash":null,"server_timestamp":"1785207625748","session_id":"3e519d9098404c15b234d96025eb1a2b","source":"clob_market_ws"},"received_at":"2026-07-28T03:00:28.362195Z","record_id":"d7563b66261e3ebccba3d4731fb71c4872f69d2c2089aafb32ae884cc226abb5","schema_fingerprint":"4aa3821a28b0b7c2400bc59aba4bcc0a76e971dadd19610d3ad38c768e124dc7","schema_version":"edge-lab-recorder.raw.v1","sequence":null,"source":"clob_market_ws"}
{"event_at":"2026-07-28T03:00:25.754000Z","event_fingerprint":"d58b268d294ad83c587fc40b333a914fc8a38dfccda226bfb7263180bc178e31","payload":{"connection_id":"a6b55582af5f430fb37ad02bf0922475","event_at":"2026-07-28T03:00:25.754000Z","event_type":"price_change","frame_hash":"96879f190468519f47f4692fe8c1f887ece4933609a99a4124402922b34833e5","frame_index":0,"kind":"data","monotonic_ns":309611393419000,"payload":{"event_type":"price_change","market":"0x779291bef19b6709f61e9764a954aafe9ffae488d50ae674aabdcb4f248006d5","price_changes":[{"asset_id":"8761897749749422724209054078244794145777693856614463256546737399611489089783","best_ask":"0.41","best_bid":"0.4","hash":"5960d49030bdf83a162fddadf3387c637979076e","price":"0.3","side":"BUY","size":"134.56"},{"asset_id":"14965588658799411272385430903075831224615961675357217884735713260981483529984","best_ask":"0.6","best_bid":"0.59","hash":"5edc1382f4786865527d9dfab7a1b3d00839a937","price":"0.7","side":"SELL","size":"134.56"}],"timestamp":"1785207625754"},"payload_hash":"ba9dfac72584f859e0fe1d9c95e0020f8f3030dd5fc135b34d52595c0e58faf3","raw_frame":"{\"market\":\"0x779291bef19b6709f61e9764a954aafe9ffae488d50ae674aabdcb4f248006d5\", \"price_changes\":[{\"asset_id\":\"8761897749749422724209054078244794145777693856614463256546737399611489089783\", \"price\":\"0.3\", \"size\":\"134.56\", \"side\":\"BUY\", \"hash\":\"5960d49030bdf83a162fddadf3387c637979076e\", \"best_bid\":\"0.4\", \"best_ask\":\"0.41\"}, {\"asset_id\":\"14965588658799411272385430903075831224615961675357217884735713260981483529984\", \"price\":\"0.7\", \"size\":\"134.56\", \"side\":\"SELL\", \"hash\":\"5edc1382f4786865527d9dfab7a1b3d00839a937\", \"best_bid\":\"0.59\", \"best_ask\":\"0.6\"}], \"timestamp\":\"1785207625754\", \"event_type\":\"price_change\"}","received_at":"2026-07-28T03:00:28.374850Z","schema_version":"clob-market-ws.price_change.v1","sequence":null,"server_hash":null,"server_timestamp":"1785207625754","session_id":"3e519d9098404c15b234d96025eb1a2b","source":"clob_market_ws"},"received_at":"2026-07-28T03:00:28.374850Z","record_id":"55f2e71b4728a31395dc6d4b55de4f09f796786c9a4e8a08f8bf44759785723f","schema_fingerprint":"4aa3821a28b0b7c2400bc59aba4bcc0a76e971dadd19610d3ad38c768e124dc7","schema_version":"edge-lab-recorder.raw.v1","sequence":null,"source":"clob_market_ws"}
{"event_at":"2026-07-28T03:00:25.756000Z","event_fingerprint":"8ee729bdeae23ed0cce3a8484f4f21966a55c06c762d7db820c35c4de2e44ab7","payload":{"connection_id":"a6b55582af5f430fb37ad02bf0922475","event_at":"2026-07-28T03:00:25.756000Z","event_type":"price_change","frame_hash":"2375abcbb755d62d1756d839b5b311d0f545dc8a7bbdaa407daed485f4ba8873","frame_index":0,"kind":"data","monotonic_ns":309611401604333,"payload":{"event_type":"price_change","market":"0x779291bef19b6709f61e9764a954aafe9ffae488d50ae674aabdcb4f248006d5","price_changes":[{"asset_id":"14965588658799411272385430903075831224615961675357217884735713260981483529984","best_ask":"0.6","best_bid":"0.59","hash":"e3cec27bd2325f63c8fdec7359cd89a2f97ce193","price":"0.43","side":"BUY","size":"35"},{"asset_id":"8761897749749422724209054078244794145777693856614463256546737399611489089783","best_ask":"0.41","best_bid":"0.4","hash":"a39dacb07bdde51fb2c7537e2a84f35c2e4881c8","price":"0.57","side":"SELL","size":"35"}],"timestamp":"1785207625756"},"payload_hash":"6841a22944759644a381269ccae279f57e317d7f0a03df3b60d9bbf42590e4c8","raw_frame":"{\"market\":\"0x779291bef19b6709f61e9764a954aafe9ffae488d50ae674aabdcb4f248006d5\", \"price_changes\":[{\"asset_id\":\"14965588658799411272385430903075831224615961675357217884735713260981483529984\", \"price\":\"0.43\", \"size\":\"35\", \"side\":\"BUY\", \"hash\":\"e3cec27bd2325f63c8fdec7359cd89a2f97ce193\", \"best_bid\":\"0.59\", \"best_ask\":\"0.6\"}, {\"asset_id\":\"8761897749749422724209054078244794145777693856614463256546737399611489089783\", \"price\":\"0.57\", \"size\":\"35\", \"side\":\"SELL\", \"hash\":\"a39dacb07bdde51fb2c7537e2a84f35c2e4881c8\", \"best_bid\":\"0.4\", \"best_ask\":\"0.41\"}], \"timestamp\":\"1785207625756\", \"event_type\":\"price_change\"}","received_at":"2026-07-28T03:00:28.383036Z","schema_version":"clob-market-ws.price_change.v1","sequence":null,"server_hash":null,"server_timestamp":"1785207625756","session_id":"3e519d9098404c15b234d96025eb1a2b","source":"clob_market_ws"},"received_at":"2026-07-28T03:00:28.383036Z","record_id":"3b4b1de4c80f3a63893b2db701e63f592ab9814d9258a7440af9f6494a9ada64","schema_fingerprint":"4aa3821a28b0b7c2400bc59aba4bcc0a76e971dadd19610d3ad38c768e124dc7","schema_version":"edge-lab-recorder.raw.v1","sequence":null,"source":"clob_market_ws"}
{"event_at":"2026-07-28T03:00:25.764000Z","event_fingerprint":"aa2c73da7cbdb7b89e2728af4c941fc9ad73da56e2b35e764bb21d27d78bb33f","payload":{"connection_id":"a6b55582af5f430fb37ad02bf0922475","event_at":"2026-07-28T03:00:25.764000Z","event_type":"price_change","frame_hash":"22a2f8cb3e902eca5ccd0d6263f023d046363934d1c90249edfa539c2f0a2331","frame_index":0,"kind":"data","monotonic_ns":309611414127458,"payload":{"event_type":"price_change","market":"0x779291bef19b6709f61e9764a954aafe9ffae488d50ae674aabdcb4f248006d5","price_changes":[{"asset_id":"8761897749749422724209054078244794145777693856614463256546737399611489089783","best_ask":"0.41","best_bid":"0.4","hash":"d104e57dae8ff9befa228d3e052fd4e80da8987a","price":"0.2","side":"BUY","size":"43"},{"asset_id":"14965588658799411272385430903075831224615961675357217884735713260981483529984","best_ask":"0.6","best_bid":"0.59","hash":"8f9980a1f4eb0071af77fb1ba9c70f9a2065a90c","price":"0.8","side":"SELL","size":"43"}],"timestamp":"1785207625764"},"payload_hash":"e99890048613ca713bfa8f8867538490f22a4560d8f43689230424fa335da71c","raw_frame":"{\"market\":\"0x779291bef19b6709f61e9764a954aafe9ffae488d50ae674aabdcb4f248006d5\", \"price_changes\":[{\"asset_id\":\"8761897749749422724209054078244794145777693856614463256546737399611489089783\", \"price\":\"0.2\", \"size\":\"43\", \"side\":\"BUY\", \"hash\":\"d104e57dae8ff9befa228d3e052fd4e80da8987a\", \"best_bid\":\"0.4\", \"best_ask\":\"0.41\"}, {\"asset_id\":\"14965588658799411272385430903075831224615961675357217884735713260981483529984\", \"price\":\"0.8\", \"size\":\"43\", \"side\":\"SELL\", \"hash\":\"8f9980a1f4eb0071af77fb1ba9c70f9a2065a90c\", \"best_bid\":\"0.59\", \"best_ask\":\"0.6\"}], \"timestamp\":\"1785207625764\", \"event_type\":\"price_change\"}","received_at":"2026-07-28T03:00:28.395557Z","schema_version":"clob-market-ws.price_change.v1","sequence":null,"server_hash":null,"server_timestamp":"1785207625764","session_id":"3e519d9098404c15b234d96025eb1a2b","source":"clob_market_ws"},"received_at":"2026-07-28T03:00:28.395557Z","record_id":"9d456063c618bfc69e7774b482264c8b9ac8f749f04478577904efa950c431aa","schema_fingerprint":"4aa3821a28b0b7c2400bc59aba4bcc0a76e971dadd19610d3ad38c768e124dc7","schema_version":"edge-lab-recorder.raw.v1","sequence":null,"source":"clob_market_ws"}
{"event_at":"2026-07-28T03:00:25.767000Z","event_fingerprint":"79aaff3bc5e3358904008b998a0baff27e9ae3866fa0063291bc9f4b6ce5d335","payload":{"connection_id":"a6b55582af5f430fb37ad02bf0922475","event_at":"2026-07-28T03:00:25.767000Z","event_type":"price_change","frame_hash":"f0a8cba9491b5efe7a712c2be16963d3d5c8a945a020f983e2941289d799a79c","frame_index":0,"kind":"data","monotonic_ns":309611426243833,"payload":{"event_type":"price_change","market":"0x779291bef19b6709f61e9764a954aafe9ffae488d50ae674aabdcb4f248006d5","price_changes":[{"asset_id":"8761897749749422724209054078244794145777693856614463256546737399611489089783","best_ask":"0.41","best_bid":"0.4","hash":"d7abbb4343c2b9a5da164fb35fe59741180a2d5f","price":"0.21","side":"BUY","size":"15"},{"asset_id":"14965588658799411272385430903075831224615961675357217884735713260981483529984","best_ask":"0.6","best_bid":"0.59","hash":"7c684120954c47e23e8a972fe6997e76daadd046","price":"0.79","side":"SELL","size":"15"}],"timestamp":"1785207625767"},"payload_hash":"433873b015d6336da9f9c6968d3766cc18571447b704fe6312fc7aa4d047c02b","raw_frame":"{\"market\":\"0x779291bef19b6709f61e9764a954aafe9ffae488d50ae674aabdcb4f248006d5\", \"price_changes\":[{\"asset_id\":\"8761897749749422724209054078244794145777693856614463256546737399611489089783\", \"price\":\"0.21\", \"size\":\"15\", \"side\":\"BUY\", \"hash\":\"d7abbb4343c2b9a5da164fb35fe59741180a2d5f\", \"best_bid\":\"0.4\", \"best_ask\":\"0.41\"}, {\"asset_id\":\"14965588658799411272385430903075831224615961675357217884735713260981483529984\", \"price\":\"0.79\", \"size\":\"15\", \"side\":\"SELL\", \"hash\":\"7c684120954c47e23e8a972fe6997e76daadd046\", \"best_bid\":\"0.59\", \"best_ask\":\"0.6\"}], \"timestamp\":\"1785207625767\", \"event_type\":\"price_change\"}","received_at":"2026-07-28T03:00:28.407674Z","schema_version":"clob-market-ws.price_change.v1","sequence":null,"server_hash":null,"server_timestamp":"1785207625767","session_id":"3e519d9098404c15b234d96025eb1a2b","source":"clob_market_ws"},"received_at":"2026-07-28T03:00:28.407674Z","record_id":"989bb8faf9c2bfad684ffda4ef8381e934d39354b4327b523ea71f02c2890d3b","schema_fingerprint":"4aa3821a28b0b7c2400bc59aba4bcc0a76e971dadd19610d3ad38c768e124dc7","schema_version":"edge-lab-recorder.raw.v1","sequence":null,"source":"clob_market_ws"}
{"event_at":"2026-07-28T03:00:25.774000Z","event_fingerprint":"a3bb1559abe10bfec7ab83ad67860226acc6d9668d2a946a36bd3ac82643339b","payload":{"connection_id":"a6b55582af5f430fb37ad02bf0922475","event_at":"2026-07-28T03:00:25.774000Z","event_type":"price_change","frame_hash":"6c4a43efdd1c7949dc2be8ac3bf8d5f40e95b60fa6bb77ecbf46cf33558318c7","frame_index":0,"kind":"data","monotonic_ns":309611434713291,"payload":{"event_type":"price_change","market":"0x779291bef19b6709f61e9764a954aafe9ffae488d50ae674aabdcb4f248006d5","price_changes":[{"asset_id":"14965588658799411272385430903075831224615961675357217884735713260981483529984","best_ask":"0.6","best_bid":"0.59","hash":"86a4251075996eb06b191fc3267bfba3f429d7e6","price":"0.03","side":"BUY","size":"950"},{"asset_id":"8761897749749422724209054078244794145777693856614463256546737399611489089783","best_ask":"0.41","best_bid":"0.4","hash":"8bd94e7809c1be7e996f4f9f6d24b46e11ba6486","price":"0.97","side":"SELL","size":"950"}],"timestamp":"1785207625774"},"payload_hash":"01605a0f4074570aa846659960d465814fecb2bf54485bd9904d2bce9650a0d4","raw_frame":"{\"market\":\"0x779291bef19b6709f61e9764a954aafe9ffae488d50ae674aabdcb4f248006d5\", \"price_changes\":[{\"asset_id\":\"14965588658799411272385430903075831224615961675357217884735713260981483529984\", \"price\":\"0.03\", \"size\":\"950\", \"side\":\"BUY\", \"hash\":\"86a4251075996eb06b191fc3267bfba3f429d7e6\", \"best_bid\":\"0.59\", \"best_ask\":\"0.6\"}, {\"asset_id\":\"8761897749749422724209054078244794145777693856614463256546737399611489089783\", \"price\":\"0.97\", \"size\":\"950\", \"side\":\"SELL\", \"hash\":\"8bd94e7809c1be7e996f4f9f6d24b46e11ba6486\", \"best_bid\":\"0.4\", \"best_ask\":\"0.41\"}], \"timestamp\":\"1785207625774\", \"event_type\":\"price_change\"}","received_at":"2026-07-28T03:00:28.416143Z","schema_version":"clob-market-ws.price_change.v1","sequence":null,"server_hash":null,"server_timestamp":"1785207625774","session_id":"3e519d9098404c15b234d96025eb1a2b","source":"clob_market_ws"},"received_at":"2026-07-28T03:00:28.416143Z","record_id":"bdda8ca8953e242467791bc74dc95da3f80c59501471ac5d93be90102e150a30","schema_fingerprint":"4aa3821a28b0b7c2400bc59aba4bcc0a76e971dadd19610d3ad38c768e124dc7","schema_version":"edge-lab-recorder.raw.v1","sequence":null,"source":"clob_market_ws"}
{"event_at":"2026-07-28T03:00:25.775000Z","event_fingerprint":"2044e3d8553c7224d499d8d14aa0642e099556ae576f9f7fee1e5c5cb32a5e2c","payload":{"connection_id":"a6b55582af5f430fb37ad02bf0922475","event_at":"2026-07-28T03:00:25.775000Z","event_type":"price_change","frame_hash":"bc9c68f21f333c1262a896afcc7387db2c75e840ab9f32aa87f936f72adc122c","frame_index":0,"kind":"data","monotonic_ns":309611442452833,"payload":{"event_type":"price_change","market":"0x779291bef19b6709f61e9764a954aafe9ffae488d50ae674aabdcb4f248006d5","price_changes":[{"asset_id":"14965588658799411272385430903075831224615961675357217884735713260981483529984","best_ask":"0.6","best_bid":"0.59","hash":"d09c8ff135ebd118f90e68f16c368c271d1c384c","price":"0.45","side":"BUY","size":"125.07"},{"asset_id":"8761897749749422724209054078244794145777693856614463256546737399611489089783","best_ask":"0.41","best_bid":"0.4","hash":"8f8231c7a34cb6aae3f6d465f7cafb64fec73bec","price":"0.55","side":"SELL","size":"125.07"}],"timestamp":"1785207625775"},"payload_hash":"8f38d2e6464dfddd6231150dbdff2edd3410e797868694f46442dbe08fdc7961","raw_frame":"{\"market\":\"0x779291bef19b6709f61e9764a954aafe9ffae488d50ae674aabdcb4f248006d5\", \"price_changes\":[{\"asset_id\":\"14965588658799411272385430903075831224615961675357217884735713260981483529984\", \"price\":\"0.45\", \"size\":\"125.07\", \"side\":\"BUY\", \"hash\":\"d09c8ff135ebd118f90e68f16c368c271d1c384c\", \"best_bid\":\"0.59\", \"best_ask\":\"0.6\"}, {\"asset_id\":\"8761897749749422724209054078244794145777693856614463256546737399611489089783\", \"price\":\"0.55\", \"size\":\"125.07\", \"side\":\"SELL\", \"hash\":\"8f8231c7a34cb6aae3f6d465f7cafb64fec73bec\", \"best_bid\":\"0.4\", \"best_ask\":\"0.41\"}], \"timestamp\":\"1785207625775\", \"event_type\":\"price_change\"}","received_at":"2026-07-28T03:00:28.423888Z","schema_version":"clob-market-ws.price_change.v1","sequence":null,"server_hash":null,"server_timestamp":"1785207625775","session_id":"3e519d9098404c15b234d96025eb1a2b","source":"clob_market_ws"},"received_at":"2026-07-28T03:00:28.423888Z","record_id":"d96a4f970833c0f00870a70bdfc40b7773044b69f5824d6b698eb2059b00a7eb","schema_fingerprint":"4aa3821a28b0b7c2400bc59aba4bcc0a76e971dadd19610d3ad38c768e124dc7","schema_version":"edge-lab-recorder.raw.v1","sequence":null,"source":"clob_market_ws"}
{"event_at":"2026-07-28T03:00:25.775000Z","event_fingerprint":"6d97d72dede643da5f1d9f760199f340fcb71d7077f3e1932c929c3d10b28ad7","payload":{"connection_id":"a6b55582af5f430fb37ad02bf0922475","event_at":"2026-07-28T03:00:25.775000Z","event_type":"price_change","frame_hash":"77b6eb30e2a3e680e1df00da809ed584006de09229acefc4c4230e504cee993c","frame_index":0,"kind":"data","monotonic_ns":309611460040458,"payload":{"event_type":"price_change","market":"0x779291bef19b6709f61e9764a954aafe9ffae488d50ae674aabdcb4f248006d5","price_changes":[{"asset_id":"8761897749749422724209054078244794145777693856614463256546737399611489089783","best_ask":"0.41","best_bid":"0.4","hash":"12330ef8d779eb1fa6844d4442d30472a9ffef28","price":"0.32","side":"BUY","size":"202.59"},{"asset_id":"14965588658799411272385430903075831224615961675357217884735713260981483529984","best_ask":"0.6","best_bid":"0.59","hash":"8cde8f98d13781ad4ffcc6adc55ad426e831712b","price":"0.68","side":"SELL","size":"202.59"}],"timestamp":"1785207625775"},"payload_hash":"217eec0a7c1db165edbbf37920580b6c807768df9ff2aa78c3842346333b852e","raw_frame":"{\"market\":\"0x779291bef19b6709f61e9764a954aafe9ffae488d50ae674aabdcb4f248006d5\", \"price_changes\":[{\"asset_id\":\"8761897749749422724209054078244794145777693856614463256546737399611489089783\", \"price\":\"0.32\", \"size\":\"202.59\", \"side\":\"BUY\", \"hash\":\"12330ef8d779eb1fa6844d4442d30472a9ffef28\", \"best_bid\":\"0.4\", \"best_ask\":\"0.41\"}, {\"asset_id\":\"14965588658799411272385430903075831224615961675357217884735713260981483529984\", \"price\":\"0.68\", \"size\":\"202.59\", \"side\":\"SELL\", \"hash\":\"8cde8f98d13781ad4ffcc6adc55ad426e831712b\", \"best_bid\":\"0.59\", \"best_ask\":\"0.6\"}], \"timestamp\":\"1785207625775\", \"event_type\":\"price_change\"}","received_at":"2026-07-28T03:00:28.441471Z","schema_version":"clob-market-ws.price_change.v1","sequence":null,"server_hash":null,"server_timestamp":"1785207625775","session_id":"3e519d9098404c15b234d96025eb1a2b","source":"clob_market_ws"},"received_at":"2026-07-28T03:00:28.441471Z","record_id":"8c4a7684f240318031d67ecf53d7901ed1eb9ae85ef3222b48543cd12ba952aa","schema_fingerprint":"4aa3821a28b0b7c2400bc59aba4bcc0a76e971dadd19610d3ad38c768e124dc7","schema_version":"edge-lab-recorder.raw.v1","sequence":null,"source":"clob_market_ws"}
{"event_at":"2026-07-28T03:00:25.776000Z","event_fingerprint":"c42f000fbdaedb191df6384cc4e33307c80ff57f4a9af0047eb6ca89fd2a3cef","payload":{"connection_id":"a6b55582af5f430fb37ad02bf0922475","event_at":"2026-07-28T03:00:25.776000Z","event_type":"price_change","frame_hash":"7fed833cb89efb5cba8e4753c2eb7aa72780fd1cf1312d90e71252f5d5d6432a","frame_index":0,"kind":"data","monotonic_ns":309611466047000,"payload":{"event_type":"price_change","market":"0x779291bef19b6709f61e9764a954aafe9ffae488d50ae674aabdcb4f248006d5","price_changes":[{"asset_id":"8761897749749422724209054078244794145777693856614463256546737399611489089783","best_ask":"0.41","best_bid":"0.4","hash":"654c4ec115aebc48de0cf263db628cdb1ebab6db","price":"0.29","side":"BUY","size":"126.26"},{"asset_id":"14965588658799411272385430903075831224615961675357217884735713260981483529984","best_ask":"0.6","best_bid":"0.59","hash":"5ca553575ae2dc014df75e82dc0720ef979582ec","price":"0.71","side":"SELL","size":"126.26"}],"timestamp":"1785207625776"},"payload_hash":"32766654d892e7638df4a656e5338b72f6b2e87cb51f656abec9385f7280725e","raw_frame":"{\"market\":\"0x779291bef19b6709f61e9764a954aafe9ffae488d50ae674aabdcb4f248006d5\", \"price_changes\":[{\"asset_id\":\"8761897749749422724209054078244794145777693856614463256546737399611489089783\", \"price\":\"0.29\", \"size\":\"126.26\", \"side\":\"BUY\", \"hash\":\"654c4ec115aebc48de0cf263db628cdb1ebab6db\", \"best_bid\":\"0.4\", \"best_ask\":\"0.41\"}, {\"asset_id\":\"14965588658799411272385430903075831224615961675357217884735713260981483529984\", \"price\":\"0.71\", \"size\":\"126.26\", \"side\":\"SELL\", \"hash\":\"5ca553575ae2dc014df75e82dc0720ef979582ec\", \"best_bid\":\"0.59\", \"best_ask\":\"0.6\"}], \"timestamp\":\"1785207625776\", \"event_type\":\"price_change\"}","received_at":"2026-07-28T03:00:28.447478Z","schema_version":"clob-market-ws.price_change.v1","sequence":null,"server_hash":null,"server_timestamp":"1785207625776","session_id":"3e519d9098404c15b234d96025eb1a2b","source":"clob_market_ws"},"received_at":"2026-07-28T03:00:28.447478Z","record_id":"ba2315ffeca0a1333d650c931a999c6c5bbc42c68499f9d0642e97a54f50e5c1","schema_fingerprint":"4aa3821a28b0b7c2400bc59aba4bcc0a76e971dadd19610d3ad38c768e124dc7","schema_version":"edge-lab-recorder.raw.v1","sequence":null,"source":"clob_market_ws"}
{"event_at":"2026-07-28T03:00:25.844000Z","event_fingerprint":"b7682fea3fc43ad2f5ca50c6ba611e54346a46503dea95c058b0789412eb0c1c","payload":{"connection_id":"a6b55582af5f430fb37ad02bf0922475","event_at":"2026-07-28T03:00:25.844000Z","event_type":"price_change","frame_hash":"17dd970a960b2425f7cff185c6c55ca9eca8105ad3e709cb6f63d739bd57f4f5","frame_index":0,"kind":"data","monotonic_ns":309611471371083,"payload":{"event_type":"price_change","market":"0x779291bef19b6709f61e9764a954aafe9ffae488d50ae674aabdcb4f248006d5","price_changes":[{"asset_id":"8761897749749422724209054078244794145777693856614463256546737399611489089783","best_ask":"0.41","best_bid":"0.4","hash":"2e7139dd6924bf26b91a8177baebe8546d4e39f5","price":"0.37","side":"BUY","size":"48"},{"asset_id":"14965588658799411272385430903075831224615961675357217884735713260981483529984","best_ask":"0.6","best_bid":"0.59","hash":"02388a1ab5bc6ff48af3ba51a17bee33721a7a6c","price":"0.63","side":"SELL","size":"48"}],"timestamp":"1785207625844"},"payload_hash":"92e927f68766ce2bf4cebdd0b9519996e0febb8defd43e36de7f5a942324b5a5","raw_frame":"{\"market\":\"0x779291bef19b6709f61e9764a954aafe9ffae488d50ae674aabdcb4f248006d5\", \"price_changes\":[{\"asset_id\":\"8761897749749422724209054078244794145777693856614463256546737399611489089783\", \"price\":\"0.37\", \"size\":\"48\", \"side\":\"BUY\", \"hash\":\"2e7139dd6924bf26b91a8177baebe8546d4e39f5\", \"best_bid\":\"0.4\", \"best_ask\":\"0.41\"}, {\"asset_id\":\"14965588658799411272385430903075831224615961675357217884735713260981483529984\", \"price\":\"0.63\", \"size\":\"48\", \"side\":\"SELL\", \"hash\":\"02388a1ab5bc6ff48af3ba51a17bee33721a7a6c\", \"best_bid\":\"0.59\", \"best_ask\":\"0.6\"}], \"timestamp\":\"1785207625844\", \"event_type\":\"price_change\"}","received_at":"2026-07-28T03:00:28.452801Z","schema_version":"clob-market-ws.price_change.v1","sequence":null,"server_hash":null,"server_timestamp":"1785207625844","session_id":"3e519d9098404c15b234d96025eb1a2b","source":"clob_market_ws"},"received_at":"2026-07-28T03:00:28.452801Z","record_id":"998bcd69fc5a2eabccdef02a9075ae554de87971b224c486b9c0c02211e24355","schema_fingerprint":"4aa3821a28b0b7c2400bc59aba4bcc0a76e971dadd19610d3ad38c768e124dc7","schema_version":"edge-lab-recorder.raw.v1","sequence":null,"source":"clob_market_ws"}
{"event_at":"2026-07-28T03:00:25.844000Z","event_fingerprint":"3cf1c33e198a827ef9636ed3f0185a308f3e30de807ff3f90b632ea916f04d76","payload":{"connection_id":"a6b55582af5f430fb37ad02bf0922475","event_at":"2026-07-28T03:00:25.844000Z","event_type":"price_change","frame_hash":"7c3f08e55b1c026ff925939708d1286e8b98da7d0c0abdf2682e4956c68459e5","frame_index":0,"kind":"data","monotonic_ns":309611479610416,"payload":{"event_type":"price_change","market":"0x779291bef19b6709f61e9764a954aafe9ffae488d50ae674aabdcb4f248006d5","price_changes":[{"asset_id":"8761897749749422724209054078244794145777693856614463256546737399611489089783","best_ask":"0.41","best_bid":"0.4","hash":"5d59987ce76dfd3ca17ee89f999b57142358a600","price":"0.37","side":"BUY","size":"36"},{"asset_id":"14965588658799411272385430903075831224615961675357217884735713260981483529984","best_ask":"0.6","best_bid":"0.59","hash":"3c7e7bfefe620d88b21836eeb52b302084ae3285","price":"0.63","side":"SELL","size":"36"}],"timestamp":"1785207625844"},"payload_hash":"5c2faa21428b4436044b1b16d176b5c07453babd14951c0b1ab7831c2b0367ce","raw_frame":"{\"market\":\"0x779291bef19b6709f61e9764a954aafe9ffae488d50ae674aabdcb4f248006d5\", \"price_changes\":[{\"asset_id\":\"8761897749749422724209054078244794145777693856614463256546737399611489089783\", \"price\":\"0.37\", \"size\":\"36\", \"side\":\"BUY\", \"hash\":\"5d59987ce76dfd3ca17ee89f999b57142358a600\", \"best_bid\":\"0.4\", \"best_ask\":\"0.41\"}, {\"asset_id\":\"14965588658799411272385430903075831224615961675357217884735713260981483529984\", \"price\":\"0.63\", \"size\":\"36\", \"side\":\"SELL\", \"hash\":\"3c7e7bfefe620d88b21836eeb52b302084ae3285\", \"best_bid\":\"0.59\", \"best_ask\":\"0.6\"}], \"timestamp\":\"1785207625844\", \"event_type\":\"price_change\"}","received_at":"2026-07-28T03:00:28.461040Z","schema_version":"clob-market-ws.price_change.v1","sequence":null,"server_hash":null,"server_timestamp":"1785207625844","session_id":"3e519d9098404c15b234d96025eb1a2b","source":"clob_market_ws"},"received_at":"2026-07-28T03:00:28.461040Z","record_id":"413ed10995ddb2c3119e0546e181eb6e80e3bbcc1a7bbda611c087eb2f462d09","schema_fingerprint":"4aa3821a28b0b7c2400bc59aba4bcc0a76e971dadd19610d3ad38c768e124dc7","schema_version":"edge-lab-recorder.raw.v1","sequence":null,"source":"clob_market_ws"}
{"event_at":"2026-07-28T03:00:25.853000Z","event_fingerprint":"c7176814d90022de8929699f3f925f507af9751eac56bb537a543abf751a7dad","payload":{"connection_id":"a6b55582af5f430fb37ad02bf0922475","event_at":"2026-07-28T03:00:25.853000Z","event_type":"price_change","frame_hash":"7cfa97e8afa19b673ea7d063167671b53c08f97791089f82842ccc862e5954c9","frame_index":0,"kind":"data","monotonic_ns":309611488541208,"payload":{"event_type":"price_change","market":"0x779291bef19b6709f61e9764a954aafe9ffae488d50ae674aabdcb4f248006d5","price_changes":[{"asset_id":"14965588658799411272385430903075831224615961675357217884735713260981483529984","best_ask":"0.6","best_bid":"0.59","hash":"c5e0638b63819c007e41bb57de80b741d1d0b629","price":"0.55","side":"BUY","size":"107.2"},{"asset_id":"8761897749749422724209054078244794145777693856614463256546737399611489089783","best_ask":"0.41","best_bid":"0.4","hash":"54a8b29736f7abb1f13e55b16e269f604f56f028","price":"0.45","side":"SELL","size":"107.2"}],"timestamp":"1785207625853"},"payload_hash":"07add518dcf44778725b6c9042ea669903b53d402ec6b24f6b4ce0cc407cacc5","raw_frame":"{\"market\":\"0x779291bef19b6709f61e9764a954aafe9ffae488d50ae674aabdcb4f248006d5\", \"price_changes\":[{\"asset_id\":\"14965588658799411272385430903075831224615961675357217884735713260981483529984\", \"price\":\"0.55\", \"size\":\"107.2\", \"side\":\"BUY\", \"hash\":\"c5e0638b63819c007e41bb57de80b741d1d0b629\", \"best_bid\":\"0.59\", \"best_ask\":\"0.6\"}, {\"asset_id\":\"8761897749749422724209054078244794145777693856614463256546737399611489089783\", \"price\":\"0.45\", \"size\":\"107.2\", \"side\":\"SELL\", \"hash\":\"54a8b29736f7abb1f13e55b16e269f604f56f028\", \"best_bid\":\"0.4\", \"best_ask\":\"0.41\"}], \"timestamp\":\"1785207625853\", \"event_type\":\"price_change\"}","received_at":"2026-07-28T03:00:28.469971Z","schema_version":"clob-market-ws.price_change.v1","sequence":null,"server_hash":null,"server_timestamp":"1785207625853","session_id":"3e519d9098404c15b234d96025eb1a2b","source":"clob_market_ws"},"received_at":"2026-07-28T03:00:28.469971Z","record_id":"39c7508adaee7db2952c9ab5f08fe888ad3d8a864d1adb994ec566bb8c6a36d2","schema_fingerprint":"4aa3821a28b0b7c2400bc59aba4bcc0a76e971dadd19610d3ad38c768e124dc7","schema_version":"edge-lab-recorder.raw.v1","sequence":null,"source":"clob_market_ws"}
{"event_at":"2026-07-28T03:00:25.856000Z","event_fingerprint":"f67d1c3f1ed1e54c1022d6eb43ea1df805ec016d7266dcaff547df5f0edbcb36","payload":{"connection_id":"a6b55582af5f430fb37ad02bf0922475","event_at":"2026-07-28T03:00:25.856000Z","event_type":"price_change","frame_hash":"5859f4b1c2c41986d4976e9dfb682008d8042b5b0aaf76d1a470ebf9516b55ec","frame_index":0,"kind":"data","monotonic_ns":309611496061250,"payload":{"event_type":"price_change","market":"0x779291bef19b6709f61e9764a954aafe9ffae488d50ae674aabdcb4f248006d5","price_changes":[{"asset_id":"8761897749749422724209054078244794145777693856614463256546737399611489089783","best_ask":"0.41","best_bid":"0.4","hash":"9b17021380e3d72051aeb3672b870009bc57253e","price":"0.36","side":"BUY","size":"139"},{"asset_id":"14965588658799411272385430903075831224615961675357217884735713260981483529984","best_ask":"0.6","best_bid":"0.59","hash":"79c7def76e03351f8223fc15263121990c2627f9","price":"0.64","side":"SELL","size":"139"}],"timestamp":"1785207625856"},"payload_hash":"0f517597d87d32cd47825fd537eb8408cae16025e5e12e5adf9dd7e0c370f88f","raw_frame":"{\"market\":\"0x779291bef19b6709f61e9764a954aafe9ffae488d50ae674aabdcb4f248006d5\", \"price_changes\":[{\"asset_id\":\"8761897749749422724209054078244794145777693856614463256546737399611489089783\", \"price\":\"0.36\", \"size\":\"139\", \"side\":\"BUY\", \"hash\":\"9b17021380e3d72051aeb3672b870009bc57253e\", \"best_bid\":\"0.4\", \"best_ask\":\"0.41\"}, {\"asset_id\":\"14965588658799411272385430903075831224615961675357217884735713260981483529984\", \"price\":\"0.64\", \"size\":\"139\", \"side\":\"SELL\", \"hash\":\"79c7def76e03351f8223fc15263121990c2627f9\", \"best_bid\":\"0.59\", \"best_ask\":\"0.6\"}], \"timestamp\":\"1785207625856\", \"event_type\":\"price_change\"}","received_at":"2026-07-28T03:00:28.477493Z","schema_version":"clob-market-ws.price_change.v1","sequence":null,"server_hash":null,"server_timestamp":"1785207625856","session_id":"3e519d9098404c15b234d96025eb1a2b","source":"clob_market_ws"},"received_at":"2026-07-28T03:00:28.477493Z","record_id":"25891e94a5b6cc7be9181aff41dd5dce6fb09afd322955b62765536d9298893e","schema_fingerprint":"4aa3821a28b0b7c2400bc59aba4bcc0a76e971dadd19610d3ad38c768e124dc7","schema_version":"edge-lab-recorder.raw.v1","sequence":null,"source":"clob_market_ws"}
{"event_at":"2026-07-28T03:00:25.866000Z","event_fingerprint":"343251912c97fcacaab6242421650f81d91a1c8ba6793700a838f8eaa16c0dbb","payload":{"connection_id":"a6b55582af5f430fb37ad02bf0922475","event_at":"2026-07-28T03:00:25.866000Z","event_type":"price_change","frame_hash":"d299c55c1a75e694131dcdeca62c542db330f0f6ffc517336f16bf7210052171","frame_index":0,"kind":"data","monotonic_ns":309611501183500,"payload":{"event_type":"price_change","market":"0x779291bef19b6709f61e9764a954aafe9ffae488d50ae674aabdcb4f248006d5","price_changes":[{"asset_id":"8761897749749422724209054078244794145777693856614463256546737399611489089783","best_ask":"0.41","best_bid":"0.4","hash":"93c81684a3c89910ec475a463d16a00aeef6ab1e","price":"0.15","side":"BUY","size":"229"},{"asset_id":"14965588658799411272385430903075831224615961675357217884735713260981483529984","best_ask":"0.6","best_bid":"0.59","hash":"4942f2ce4910b843ff2e7084295989c0d52abf8c","price":"0.85","side":"SELL","size":"229"}],"timestamp":"1785207625866"},"payload_hash":"f6456e5c07fa48d50dcf0e7c021e67a423a2a692eb421804bfc01976f2d41bc2","raw_frame":"{\"market\":\"0x779291bef19b6709f61e9764a954aafe9ffae488d50ae674aabdcb4f248006d5\", \"price_changes\":[{\"asset_id\":\"8761897749749422724209054078244794145777693856614463256546737399611489089783\", \"price\":\"0.15\", \"size\":\"229\", \"side\":\"BUY\", \"hash\":\"93c81684a3c89910ec475a463d16a00aeef6ab1e\", \"best_bid\":\"0.4\", \"best_ask\":\"0.41\"}, {\"asset_id\":\"14965588658799411272385430903075831224615961675357217884735713260981483529984\", \"price\":\"0.85\", \"size\":\"229\", \"side\":\"SELL\", \"hash\":\"4942f2ce4910b843ff2e7084295989c0d52abf8c\", \"best_bid\":\"0.59\", \"best_ask\":\"0.6\"}], \"timestamp\":\"1785207625866\", \"event_type\":\"price_change\"}","received_at":"2026-07-28T03:00:28.482619Z","schema_version":"clob-market-ws.price_change.v1","sequence":null,"server_hash":null,"server_timestamp":"1785207625866","session_id":"3e519d9098404c15b234d96025eb1a2b","source":"clob_market_ws"},"received_at":"2026-07-28T03:00:28.482619Z","record_id":"8a9071ba0106d9d6d93664a7b0f78d5f9f37c48f9f749489426c972223392bc1","schema_fingerprint":"4aa3821a28b0b7c2400bc59aba4bcc0a76e971dadd19610d3ad38c768e124dc7","schema_version":"edge-lab-recorder.raw.v1","sequence":null,"source":"clob_market_ws"}
{"event_at":"2026-07-28T03:00:25.869000Z","event_fingerprint":"2b9e42d842856dca73a58ae4cb9a9d10b8834355bf547241683d981b2412ba29","payload":{"connection_id":"a6b55582af5f430fb37ad02bf0922475","event_at":"2026-07-28T03:00:25.869000Z","event_type":"price_change","frame_hash":"2ff8136cb1f955f34f5778675a157f620fe7be9f8795ddb3955085021a0193e2","frame_index":0,"kind":"data","monotonic_ns":309611504734041,"payload":{"event_type":"price_change","market":"0x779291bef19b6709f61e9764a954aafe9ffae488d50ae674aabdcb4f248006d5","price_changes":[{"asset_id":"14965588658799411272385430903075831224615961675357217884735713260981483529984","best_ask":"0.6","best_bid":"0.59","hash":"b8d5fceea35ba34cbbdfb1c84dd4df679b1e426f","price":"0.02","side":"BUY","size":"1630"},{"asset_id":"8761897749749422724209054078244794145777693856614463256546737399611489089783","best_ask":"0.41","best_bid":"0.4","hash":"a3e32fdf53dd82f9145e289afd9b6b1f57b05a15","price":"0.98","side":"SELL","size":"1630"}],"timestamp":"1785207625869"},"payload_hash":"2d2b24006f52780765cb2165ccf7222f8d100a9f5b21358753266782ac8d154d","raw_frame":"{\"market\":\"0x779291bef19b6709f61e9764a954aafe9ffae488d50ae674aabdcb4f248006d5\", \"price_changes\":[{\"asset_id\":\"14965588658799411272385430903075831224615961675357217884735713260981483529984\", \"price\":\"0.02\", \"size\":\"1630\", \"side\":\"BUY\", \"hash\":\"b8d5fceea35ba34cbbdfb1c84dd4df679b1e426f\", \"best_bid\":\"0.59\", \"best_ask\":\"0.6\"}, {\"asset_id\":\"8761897749749422724209054078244794145777693856614463256546737399611489089783\", \"price\":\"0.98\", \"size\":\"1630\", \"side\":\"SELL\", \"hash\":\"a3e32fdf53dd82f9145e289afd9b6b1f57b05a15\", \"best_bid\":\"0.4\", \"best_ask\":\"0.41\"}], \"timestamp\":\"1785207625869\", \"event_type\":\"price_change\"}","received_at":"2026-07-28T03:00:28.486167Z","schema_version":"clob-market-ws.price_change.v1","sequence":null,"server_hash":null,"server_timestamp":"1785207625869","session_id":"3e519d9098404c15b234d96025eb1a2b","source":"clob_market_ws"},"received_at":"2026-07-28T03:00:28.486167Z","record_id":"1f8f3bb6ded3898f145fde7a2de20ecf074ba9ef9c99bee050bb4d87c0c2a416","schema_fingerprint":"4aa3821a28b0b7c2400bc59aba4bcc0a76e971dadd19610d3ad38c768e124dc7","schema_version":"edge-lab-recorder.raw.v1","sequence":null,"source":"clob_market_ws"}
{"event_at":"2026-07-28T03:00:25.889000Z","event_fingerprint":"8db906430daf1f8b984ba3cbbd2649241786fe52c6113577784dcebb80ec80b8","payload":{"connection_id":"a6b55582af5f430fb37ad02bf0922475","event_at":"2026-07-28T03:00:25.889000Z","event_type":"best_bid_ask","frame_hash":"e38ec0bb5f61111ca4ec92c15e15b3addacdd5e9ee88e805f45b0d22ff0e9739","frame_index":0,"kind":"data","monotonic_ns":309611511574291,"payload":{"asset_id":"14965588658799411272385430903075831224615961675357217884735713260981483529984","best_ask":"0.6","best_bid":"0.59","event_type":"best_bid_ask","market":"0x779291bef19b6709f61e9764a954aafe9ffae488d50ae674aabdcb4f248006d5","spread":"0.01","timestamp":"1785207625889"},"payload_hash":"a7bd77c86ed98fa5ca336673c49d84107835022fad14792cd643861a1e276b5d","raw_frame":"{\"market\":\"0x779291bef19b6709f61e9764a954aafe9ffae488d50ae674aabdcb4f248006d5\", \"asset_id\":\"14965588658799411272385430903075831224615961675357217884735713260981483529984\", \"best_bid\":\"0.59\", \"best_ask\":\"0.6\", \"spread\":\"0.01\", \"timestamp\":\"1785207625889\", \"event_type\":\"best_bid_ask\"}","received_at":"2026-07-28T03:00:28.493004Z","schema_version":"clob-market-ws.best_bid_ask.v1","sequence":null,"server_hash":null,"server_timestamp":"1785207625889","session_id":"3e519d9098404c15b234d96025eb1a2b","source":"clob_market_ws"},"received_at":"2026-07-28T03:00:28.493004Z","record_id":"eec1f7688d25a4e314ec82597752558c940ef287e26164a5d326b9b1244160d5","schema_fingerprint":"8488399f31b0337811b13b266be932db7062827c2470b78bd8e9e99bab51d17d","schema_version":"edge-lab-recorder.raw.v1","sequence":null,"source":"clob_market_ws"}
{"event_at":"2026-07-28T03:00:25.889000Z","event_fingerprint":"be2eff132246510b04592235a1efc9552c6c6496d1c7fce003924eacb3fe6d8e","payload":{"connection_id":"a6b55582af5f430fb37ad02bf0922475","event_at":"2026-07-28T03:00:25.889000Z","event_type":"best_bid_ask","frame_hash":"769d8dc1a84ec2feef3cf14a0e1a8197a4d27fe75fca09fca760db82747dd7a5","frame_index":0,"kind":"data","monotonic_ns":309611518850083,"payload":{"asset_id":"8761897749749422724209054078244794145777693856614463256546737399611489089783","best_ask":"0.41","best_bid":"0.4","event_type":"best_bid_ask","market":"0x779291bef19b6709f61e9764a954aafe9ffae488d50ae674aabdcb4f248006d5","spread":"0.01","timestamp":"1785207625889"},"payload_hash":"902bd593b204b6cc1a2184cbbeb9d34b8d9dea6ae630fa66da025be8675cea51","raw_frame":"{\"market\":\"0x779291bef19b6709f61e9764a954aafe9ffae488d50ae674aabdcb4f248006d5\", \"asset_id\":\"8761897749749422724209054078244794145777693856614463256546737399611489089783\", \"best_bid\":\"0.4\", \"best_ask\":\"0.41\", \"spread\":\"0.01\", \"timestamp\":\"1785207625889\", \"event_type\":\"best_bid_ask\"}","received_at":"2026-07-28T03:00:28.500276Z","schema_version":"clob-market-ws.best_bid_ask.v1","sequence":null,"server_hash":null,"server_timestamp":"1785207625889","session_id":"3e519d9098404c15b234d96025eb1a2b","source":"clob_market_ws"},"received_at":"2026-07-28T03:00:28.500276Z","record_id":"5316d572c335063a460eead0b669334ac77cc1004065bc5af065107b046026db","schema_fingerprint":"8488399f31b0337811b13b266be932db7062827c2470b78bd8e9e99bab51d17d","schema_version":"edge-lab-recorder.raw.v1","sequence":null,"source":"clob_market_ws"}
{"event_at":"2026-07-28T03:00:25.889000Z","event_fingerprint":"9740bae8334357167ade3a0874650d610f55bbca1e4b29e0f105814055ce6a31","payload":{"connection_id":"a6b55582af5f430fb37ad02bf0922475","event_at":"2026-07-28T03:00:25.889000Z","event_type":"price_change","frame_hash":"6e08a6a9ab23336790bbf35642fdad50875e7c490cbce32f90ce1cd92d5cfe03","frame_index":0,"kind":"data","monotonic_ns":309611534023583,"payload":{"event_type":"price_change","market":"0x779291bef19b6709f61e9764a954aafe9ffae488d50ae674aabdcb4f248006d5","price_changes":[{"asset_id":"8761897749749422724209054078244794145777693856614463256546737399611489089783","best_ask":"0.41","best_bid":"0.4","hash":"e941327c39aed55b67282c8b6d0fc3d811555f41","price":"0.4","side":"BUY","size":"4.98"},{"asset_id":"14965588658799411272385430903075831224615961675357217884735713260981483529984","best_ask":"0.6","best_bid":"0.59","hash":"85bd406f12fef58abd280794cf3ce16ec8aa9e48","price":"0.6","side":"SELL","size":"4.98"}],"timestamp":"1785207625889"},"payload_hash":"3df6af6d7b8ce14c88042c12af0e227726bfce2e1dae4809702862f8d712ab02","raw_frame":"{\"market\":\"0x779291bef19b6709f61e9764a954aafe9ffae488d50ae674aabdcb4f248006d5\", \"price_changes\":[{\"asset_id\":\"8761897749749422724209054078244794145777693856614463256546737399611489089783\", \"price\":\"0.4\", \"size\":\"4.98\", \"side\":\"BUY\", \"hash\":\"e941327c39aed55b67282c8b6d0fc3d811555f41\", \"best_bid\":\"0.4\", \"best_ask\":\"0.41\"}, {\"asset_id\":\"14965588658799411272385430903075831224615961675357217884735713260981483529984\", \"price\":\"0.6\", \"size\":\"4.98\", \"side\":\"SELL\", \"hash\":\"85bd406f12fef58abd280794cf3ce16ec8aa9e48\", \"best_bid\":\"0.59\", \"best_ask\":\"0.6\"}], \"timestamp\":\"1785207625889\", \"event_type\":\"price_change\"}","received_at":"2026-07-28T03:00:28.515450Z","schema_version":"clob-market-ws.price_change.v1","sequence":null,"server_hash":null,"server_timestamp":"1785207625889","session_id":"3e519d9098404c15b234d96025eb1a2b","source":"clob_market_ws"},"received_at":"2026-07-28T03:00:28.515450Z","record_id":"0521cbc9ea023e3bbc5ac352bd88df163f362e78fb7b8118e3bc96aa8bc17332","schema_fingerprint":"4aa3821a28b0b7c2400bc59aba4bcc0a76e971dadd19610d3ad38c768e124dc7","schema_version":"edge-lab-recorder.raw.v1","sequence":null,"source":"clob_market_ws"}
{"event_at":"2026-07-28T03:00:25.889000Z","event_fingerprint":"8a3f0d908dad544c13e34030b6539ea648a014d661aa89dc3826059894435539","payload":{"connection_id":"a6b55582af5f430fb37ad02bf0922475","event_at":"2026-07-28T03:00:25.889000Z","event_type":"book","frame_hash":"331ac36802864117872e7bf25f40a160cf6983bf85a93c1f4848603c406c966b","frame_index":0,"kind":"data","monotonic_ns":309611546073541,"payload":{"asks":[{"price":"0.99","size":"7550.02"},{"price":"0.98","size":"1620"},{"price":"0.97","size":"1063.33"},{"price":"0.96","size":"770"},{"price":"0.95","size":"640"},{"price":"0.94","size":"689"},{"price":"0.93","size":"500"},{"price":"0.92","size":"601"},{"price":"0.91","size":"500"},{"price":"0.9","size":"176"},{"price":"0.88","size":"22"},{"price":"0.87","size":"11"},{"price":"0.86","size":"10"},{"price":"0.85","size":"229"},{"price":"0.84","size":"19"},{"price":"0.83","size":"9"},{"price":"0.82","size":"8"},{"price":"0.81","size":"8"},{"price":"0.8","size":"43"},{"price":"0.79","size":"15"},{"price":"0.78","size":"14"},{"price":"0.77","size":"34"},{"price":"0.76","size":"44"},{"price":"0.75","size":"168"},{"price":"0.74","size":"43"},{"price":"0.73","size":"123.59"},{"price":"0.72","size":"179.01"},{"price":"0.71","size":"126.26"},{"price":"0.7","size":"134.56"},{"price":"0.69","size":"114.74"},{"price":"0.68","size":"202.59"},{"price":"0.67","size":"103"},{"price":"0.66","size":"106"},{"price":"0.65","size":"217"},{"price":"0.64","size":"139"},{"price":"0.63","size":"36"},{"price":"0.62","size":"22.6"},{"price":"0.61","size":"96"},{"price":"0.6","size":"4.98"}],"asset_id":"14965588658799411272385430903075831224615961675357217884735713260981483529984","bids":[{"price":"0.01","size":"7550.02"},{"price":"0.02","size":"1630"},{"price":"0.03","size":"950"},{"price":"0.04","size":"770"},{"price":"0.05","size":"740"},{"price":"0.06","size":"689"},{"price":"0.07","size":"500"},{"price":"0.08","size":"601"},{"price":"0.09","size":"500"},{"price":"0.1","size":"186"},{"price":"0.12","size":"10"},{"price":"0.15","size":"31"},{"price":"0.16","size":"10"},{"price":"0.2","size":"40"},{"price":"0.21","size":"7"},{"price":"0.22","size":"7"},{"price":"0.23","size":"7"},{"price":"0.24","size":"7"},{"price":"0.25","size":"33"},{"price":"0.26","size":"13"},{"price":"0.27","size":"13"},{"price":"0.28","size":"13"},{"price":"0.29","size":"13"},{"price":"0.3","size":"23"},{"price":"0.31","size":"16"},{"price":"0.32","size":"6"},{"price":"0.33","size":"6"},{"price":"0.34","size":"6"},{"price":"0.35","size":"97.01"},{"price":"0.36","size":"35"},{"price":"0.37","size":"35"},{"price":"0.38","size":"35"},{"price":"0.39","size":"35"},{"price":"0.4","size":"54"},{"price":"0.41","size":"35"},{"price":"0.42","size":"35"},{"price":"0.43","size":"35"},{"price":"0.44","size":"40.27"},{"price":"0.45","size":"125.07"},{"price":"0.46","size":"144"},{"price":"0.47","size":"147.5"},{"price":"0.48","size":"154"},{"price":"0.49","size":"181"},{"price":"0.5","size":"186"},{"price":"0.51","size":"188"},{"price":"0.52","size":"188"},{"price":"0.53","size":"192"},{"price":"0.54","size":"180.6"},{"price":"0.55","size":"107.2"},{"price":"0.56","size":"108.32"},{"price":"0.57","size":"475.5"},{"price":"0.58","size":"123.59"},{"price":"0.59","size":"143.43"}],"event_type":"book","hash":"85bd406f12fef58abd280794cf3ce16ec8aa9e48","market":"0x779291bef19b6709f61e9764a954aafe9ffae488d50ae674aabdcb4f248006d5","timestamp":"1785207625889"},"payload_hash":"acd35465211a93fa4e35fd51bdaa1542ba12779b8c932e6aa7399f1a6ea04de9","raw_frame":"{\"market\":\"0x779291bef19b6709f61e9764a954aafe9ffae488d50ae674aabdcb4f248006d5\", \"asset_id\":\"14965588658799411272385430903075831224615961675357217884735713260981483529984\", \"bids\":[{\"price\":\"0.01\", \"size\":\"7550.02\"}, {\"price\":\"0.02\", \"size\":\"1630\"}, {\"price\":\"0.03\", \"size\":\"950\"}, {\"price\":\"0.04\", \"size\":\"770\"}, {\"price\":\"0.05\", \"size\":\"740\"}, {\"price\":\"0.06\", \"size\":\"689\"}, {\"price\":\"0.07\", \"size\":\"500\"}, {\"price\":\"0.08\", \"size\":\"601\"}, {\"price\":\"0.09\", \"size\":\"500\"}, {\"price\":\"0.1\", \"size\":\"186\"}, {\"price\":\"0.12\", \"size\":\"10\"}, {\"price\":\"0.15\", \"size\":\"31\"}, {\"price\":\"0.16\", \"size\":\"10\"}, {\"price\":\"0.2\", \"size\":\"40\"}, {\"price\":\"0.21\", \"size\":\"7\"}, {\"price\":\"0.22\", \"size\":\"7\"}, {\"price\":\"0.23\", \"size\":\"7\"}, {\"price\":\"0.24\", \"size\":\"7\"}, {\"price\":\"0.25\", \"size\":\"33\"}, {\"price\":\"0.26\", \"size\":\"13\"}, {\"price\":\"0.27\", \"size\":\"13\"}, {\"price\":\"0.28\", \"size\":\"13\"}, {\"price\":\"0.29\", \"size\":\"13\"}, {\"price\":\"0.3\", \"size\":\"23\"}, {\"price\":\"0.31\", \"size\":\"16\"}, {\"price\":\"0.32\", \"size\":\"6\"}, {\"price\":\"0.33\", \"size\":\"6\"}, {\"price\":\"0.34\", \"size\":\"6\"}, {\"price\":\"0.35\", \"size\":\"97.01\"}, {\"price\":\"0.36\", \"size\":\"35\"}, {\"price\":\"0.37\", \"size\":\"35\"}, {\"price\":\"0.38\", \"size\":\"35\"}, {\"price\":\"0.39\", \"size\":\"35\"}, {\"price\":\"0.4\", \"size\":\"54\"}, {\"price\":\"0.41\", \"size\":\"35\"}, {\"price\":\"0.42\", \"size\":\"35\"}, {\"price\":\"0.43\", \"size\":\"35\"}, {\"price\":\"0.44\", \"size\":\"40.27\"}, {\"price\":\"0.45\", \"size\":\"125.07\"}, {\"price\":\"0.46\", \"size\":\"144\"}, {\"price\":\"0.47\", \"size\":\"147.5\"}, {\"price\":\"0.48\", \"size\":\"154\"}, {\"price\":\"0.49\", \"size\":\"181\"}, {\"price\":\"0.5\", \"size\":\"186\"}, {\"price\":\"0.51\", \"size\":\"188\"}, {\"price\":\"0.52\", \"size\":\"188\"}, {\"price\":\"0.53\", \"size\":\"192\"}, {\"price\":\"0.54\", \"size\":\"180.6\"}, {\"price\":\"0.55\", \"size\":\"107.2\"}, {\"price\":\"0.56\", \"size\":\"108.32\"}, {\"price\":\"0.57\", \"size\":\"475.5\"}, {\"price\":\"0.58\", \"size\":\"123.59\"}, {\"price\":\"0.59\", \"size\":\"143.43\"}], \"asks\":[{\"price\":\"0.99\", \"size\":\"7550.02\"}, {\"price\":\"0.98\", \"size\":\"1620\"}, {\"price\":\"0.97\", \"size\":\"1063.33\"}, {\"price\":\"0.96\", \"size\":\"770\"}, {\"price\":\"0.95\", \"size\":\"640\"}, {\"price\":\"0.94\", \"size\":\"689\"}, {\"price\":\"0.93\", \"size\":\"500\"}, {\"price\":\"0.92\", \"size\":\"601\"}, {\"price\":\"0.91\", \"size\":\"500\"}, {\"price\":\"0.9\", \"size\":\"176\"}, {\"price\":\"0.88\", \"size\":\"22\"}, {\"price\":\"0.87\", \"size\":\"11\"}, {\"price\":\"0.86\", \"size\":\"10\"}, {\"price\":\"0.85\", \"size\":\"229\"}, {\"price\":\"0.84\", \"size\":\"19\"}, {\"price\":\"0.83\", \"size\":\"9\"}, {\"price\":\"0.82\", \"size\":\"8\"}, {\"price\":\"0.81\", \"size\":\"8\"}, {\"price\":\"0.8\", \"size\":\"43\"}, {\"price\":\"0.79\", \"size\":\"15\"}, {\"price\":\"0.78\", \"size\":\"14\"}, {\"price\":\"0.77\", \"size\":\"34\"}, {\"price\":\"0.76\", \"size\":\"44\"}, {\"price\":\"0.75\", \"size\":\"168\"}, {\"price\":\"0.74\", \"size\":\"43\"}, {\"price\":\"0.73\", \"size\":\"123.59\"}, {\"price\":\"0.72\", \"size\":\"179.01\"}, {\"price\":\"0.71\", \"size\":\"126.26\"}, {\"price\":\"0.7\", \"size\":\"134.56\"}, {\"price\":\"0.69\", \"size\":\"114.74\"}, {\"price\":\"0.68\", \"size\":\"202.59\"}, {\"price\":\"0.67\", \"size\":\"103\"}, {\"price\":\"0.66\", \"size\":\"106\"}, {\"price\":\"0.65\", \"size\":\"217\"}, {\"price\":\"0.64\", \"size\":\"139\"}, {\"price\":\"0.63\", \"size\":\"36\"}, {\"price\":\"0.62\", \"size\":\"22.6\"}, {\"price\":\"0.61\", \"size\":\"96\"}, {\"price\":\"0.6\", \"size\":\"4.98\"}], \"hash\":\"85bd406f12fef58abd280794cf3ce16ec8aa9e48\", \"timestamp\":\"1785207625889\", \"event_type\":\"book\"}","received_at":"2026-07-28T03:00:28.527504Z","schema_version":"clob-market-ws.book.v1","sequence":null,"server_hash":"85bd406f12fef58abd280794cf3ce16ec8aa9e48","server_timestamp":"1785207625889","session_id":"3e519d9098404c15b234d96025eb1a2b","source":"clob_market_ws"},"received_at":"2026-07-28T03:00:28.527504Z","record_id":"855138c2220b0fbb35d04f16c94d46dfcfb384987a2c802f641b23a985e49b47","schema_fingerprint":"dc2caa1c89c6a7426e2e07ff925910cd4d0a8a223a515d4092d91d6d127aacb6","schema_version":"edge-lab-recorder.raw.v1","sequence":null,"source":"clob_market_ws"}
{"event_at":"2026-07-28T03:00:25.889000Z","event_fingerprint":"738760a4b1a39186cd0283ab41055ceb196a1fd789ae6ab4026905bdc77ac03a","payload":{"connection_id":"a6b55582af5f430fb37ad02bf0922475","event_at":"2026-07-28T03:00:25.889000Z","event_type":"book","frame_hash":"17b3ed273cf79aa900a934cfaaf47244919879f4bd774824bef201d180557337","frame_index":0,"kind":"data","monotonic_ns":309611570215750,"payload":{"asks":[{"price":"0.99","size":"7550.02"},{"price":"0.98","size":"1630"},{"price":"0.97","size":"950"},{"price":"0.96","size":"770"},{"price":"0.95","size":"740"},{"price":"0.94","size":"689"},{"price":"0.93","size":"500"},{"price":"0.92","size":"601"},{"price":"0.91","size":"500"},{"price":"0.9","size":"186"},{"price":"0.88","size":"10"},{"price":"0.85","size":"31"},{"price":"0.84","size":"10"},{"price":"0.8","size":"40"},{"price":"0.79","size":"7"},{"price":"0.78","size":"7"},{"price":"0.77","size":"7"},{"price":"0.76","size":"7"},{"price":"0.75","size":"33"},{"price":"0.74","size":"13"},{"price":"0.73","size":"13"},{"price":"0.72","size":"13"},{"price":"0.71","size":"13"},{"price":"0.7","size":"23"},{"price":"0.69","size":"16"},{"price":"0.68","size":"6"},{"price":"0.67","size":"6"},{"price":"0.66","size":"6"},{"price":"0.65","size":"97.01"},{"price":"0.64","size":"35"},{"price":"0.63","size":"35"},{"price":"0.62","size":"35"},{"price":"0.61","size":"35"},{"price":"0.6","size":"54"},{"price":"0.59","size":"35"},{"price":"0.58","size":"35"},{"price":"0.57","size":"35"},{"price":"0.56","size":"40.27"},{"price":"0.55","size":"125.07"},{"price":"0.54","size":"144"},{"price":"0.53","size":"147.5"},{"price":"0.52","size":"154"},{"price":"0.51","size":"181"},{"price":"0.5","size":"186"},{"price":"0.49","size":"188"},{"price":"0.48","size":"188"},{"price":"0.47","size":"192"},{"price":"0.46","size":"180.6"},{"price":"0.45","size":"107.2"},{"price":"0.44","size":"108.32"},{"price":"0.43","size":"475.5"},{"price":"0.42","size":"123.59"},{"price":"0.41","size":"143.43"}],"asset_id":"8761897749749422724209054078244794145777693856614463256546737399611489089783","bids":[{"price":"0.01","size":"7550.02"},{"price":"0.02","size":"1620"},{"price":"0.03","size":"1063.33"},{"price":"0.04","size":"770"},{"price":"0.05","size":"640"},{"price":"0.06","size":"689"},{"price":"0.07","size":"500"},{"price":"0.08","size":"601"},{"price":"0.09","size":"500"},{"price":"0.1","size":"176"},{"price":"0.12","size":"22"},{"price":"0.13","size":"11"},{"price":"0.14","size":"10"},{"price":"0.15","size":"229"},{"price":"0.16","size":"19"},{"price":"0.17","size":"9"},{"price":"0.18","size":"8"},{"price":"0.19","size":"8"},{"price":"0.2","size":"43"},{"price":"0.21","size":"15"},{"price":"0.22","size":"14"},{"price":"0.23","size":"34"},{"price":"0.24","size":"44"},{"price":"0.25","size":"168"},{"price":"0.26","size":"43"},{"price":"0.27","size":"123.59"},{"price":"0.28","size":"179.01"},{"price":"0.29","size":"126.26"},{"price":"0.3","size":"134.56"},{"price":"0.31","size":"114.74"},{"price":"0.32","size":"202.59"},{"price":"0.33","size":"103"},{"price":"0.34","size":"106"},{"price":"0.35","size":"217"},{"price":"0.36","size":"139"},{"price":"0.37","size":"36"},{"price":"0.38","size":"22.6"},{"price":"0.39","size":"96"},{"price":"0.4","size":"4.98"}],"event_type":"book","hash":"e941327c39aed55b67282c8b6d0fc3d811555f41","market":"0x779291bef19b6709f61e9764a954aafe9ffae488d50ae674aabdcb4f248006d5","timestamp":"1785207625889"},"payload_hash":"959c42c3730ff8a937cbfad05ca4a45c88015ee2e838f3b93aa3d9c978089a8e","raw_frame":"{\"market\":\"0x779291bef19b6709f61e9764a954aafe9ffae488d50ae674aabdcb4f248006d5\", \"asset_id\":\"8761897749749422724209054078244794145777693856614463256546737399611489089783\", \"bids\":[{\"price\":\"0.01\", \"size\":\"7550.02\"}, {\"price\":\"0.02\", \"size\":\"1620\"}, {\"price\":\"0.03\", \"size\":\"1063.33\"}, {\"price\":\"0.04\", \"size\":\"770\"}, {\"price\":\"0.05\", \"size\":\"640\"}, {\"price\":\"0.06\", \"size\":\"689\"}, {\"price\":\"0.07\", \"size\":\"500\"}, {\"price\":\"0.08\", \"size\":\"601\"}, {\"price\":\"0.09\", \"size\":\"500\"}, {\"price\":\"0.1\", \"size\":\"176\"}, {\"price\":\"0.12\", \"size\":\"22\"}, {\"price\":\"0.13\", \"size\":\"11\"}, {\"price\":\"0.14\", \"size\":\"10\"}, {\"price\":\"0.15\", \"size\":\"229\"}, {\"price\":\"0.16\", \"size\":\"19\"}, {\"price\":\"0.17\", \"size\":\"9\"}, {\"price\":\"0.18\", \"size\":\"8\"}, {\"price\":\"0.19\", \"size\":\"8\"}, {\"price\":\"0.2\", \"size\":\"43\"}, {\"price\":\"0.21\", \"size\":\"15\"}, {\"price\":\"0.22\", \"size\":\"14\"}, {\"price\":\"0.23\", \"size\":\"34\"}, {\"price\":\"0.24\", \"size\":\"44\"}, {\"price\":\"0.25\", \"size\":\"168\"}, {\"price\":\"0.26\", \"size\":\"43\"}, {\"price\":\"0.27\", \"size\":\"123.59\"}, {\"price\":\"0.28\", \"size\":\"179.01\"}, {\"price\":\"0.29\", \"size\":\"126.26\"}, {\"price\":\"0.3\", \"size\":\"134.56\"}, {\"price\":\"0.31\", \"size\":\"114.74\"}, {\"price\":\"0.32\", \"size\":\"202.59\"}, {\"price\":\"0.33\", \"size\":\"103\"}, {\"price\":\"0.34\", \"size\":\"106\"}, {\"price\":\"0.35\", \"size\":\"217\"}, {\"price\":\"0.36\", \"size\":\"139\"}, {\"price\":\"0.37\", \"size\":\"36\"}, {\"price\":\"0.38\", \"size\":\"22.6\"}, {\"price\":\"0.39\", \"size\":\"96\"}, {\"price\":\"0.4\", \"size\":\"4.98\"}], \"asks\":[{\"price\":\"0.99\", \"size\":\"7550.02\"}, {\"price\":\"0.98\", \"size\":\"1630\"}, {\"price\":\"0.97\", \"size\":\"950\"}, {\"price\":\"0.96\", \"size\":\"770\"}, {\"price\":\"0.95\", \"size\":\"740\"}, {\"price\":\"0.94\", \"size\":\"689\"}, {\"price\":\"0.93\", \"size\":\"500\"}, {\"price\":\"0.92\", \"size\":\"601\"}, {\"price\":\"0.91\", \"size\":\"500\"}, {\"price\":\"0.9\", \"size\":\"186\"}, {\"price\":\"0.88\", \"size\":\"10\"}, {\"price\":\"0.85\", \"size\":\"31\"}, {\"price\":\"0.84\", \"size\":\"10\"}, {\"price\":\"0.8\", \"size\":\"40\"}, {\"price\":\"0.79\", \"size\":\"7\"}, {\"price\":\"0.78\", \"size\":\"7\"}, {\"price\":\"0.77\", \"size\":\"7\"}, {\"price\":\"0.76\", \"size\":\"7\"}, {\"price\":\"0.75\", \"size\":\"33\"}, {\"price\":\"0.74\", \"size\":\"13\"}, {\"price\":\"0.73\", \"size\":\"13\"}, {\"price\":\"0.72\", \"size\":\"13\"}, {\"price\":\"0.71\", \"size\":\"13\"}, {\"price\":\"0.7\", \"size\":\"23\"}, {\"price\":\"0.69\", \"size\":\"16\"}, {\"price\":\"0.68\", \"size\":\"6\"}, {\"price\":\"0.67\", \"size\":\"6\"}, {\"price\":\"0.66\", \"size\":\"6\"}, {\"price\":\"0.65\", \"size\":\"97.01\"}, {\"price\":\"0.64\", \"size\":\"35\"}, {\"price\":\"0.63\", \"size\":\"35\"}, {\"price\":\"0.62\", \"size\":\"35\"}, {\"price\":\"0.61\", \"size\":\"35\"}, {\"price\":\"0.6\", \"size\":\"54\"}, {\"price\":\"0.59\", \"size\":\"35\"}, {\"price\":\"0.58\", \"size\":\"35\"}, {\"price\":\"0.57\", \"size\":\"35\"}, {\"price\":\"0.56\", \"size\":\"40.27\"}, {\"price\":\"0.55\", \"size\":\"125.07\"}, {\"price\":\"0.54\", \"size\":\"144\"}, {\"price\":\"0.53\", \"size\":\"147.5\"}, {\"price\":\"0.52\", \"size\":\"154\"}, {\"price\":\"0.51\", \"size\":\"181\"}, {\"price\":\"0.5\", \"size\":\"186\"}, {\"price\":\"0.49\", \"size\":\"188\"}, {\"price\":\"0.48\", \"size\":\"188\"}, {\"price\":\"0.47\", \"size\":\"192\"}, {\"price\":\"0.46\", \"size\":\"180.6\"}, {\"price\":\"0.45\", \"size\":\"107.2\"}, {\"price\":\"0.44\", \"size\":\"108.32\"}, {\"price\":\"0.43\", \"size\":\"475.5\"}, {\"price\":\"0.42\", \"size\":\"123.59\"}, {\"price\":\"0.41\", \"size\":\"143.43\"}], \"hash\":\"e941327c39aed55b67282c8b6d0fc3d811555f41\", \"timestamp\":\"1785207625889\", \"event_type\":\"book\"}","received_at":"2026-07-28T03:00:28.551644Z","schema_version":"clob-market-ws.book.v1","sequence":null,"server_hash":"e941327c39aed55b67282c8b6d0fc3d811555f41","server_timestamp":"1785207625889","session_id":"3e519d9098404c15b234d96025eb1a2b","source":"clob_market_ws"},"received_at":"2026-07-28T03:00:28.551644Z","record_id":"5dd11f0607ba24088670794697c2a70d382518b2edc05bc66dc103c44bf5d199","schema_fingerprint":"dc2caa1c89c6a7426e2e07ff925910cd4d0a8a223a515d4092d91d6d127aacb6","schema_version":"edge-lab-recorder.raw.v1","sequence":null,"source":"clob_market_ws"}
{"event_at":"2026-07-28T03:00:25.900000Z","event_fingerprint":"4e375ebe06865a9226116b7a6f34b1fe309b58afab4f07e353f007b9834e5135","payload":{"connection_id":"a6b55582af5f430fb37ad02bf0922475","event_at":"2026-07-28T03:00:25.900000Z","event_type":"best_bid_ask","frame_hash":"544953508d966753ff70d21e40ef19198580ad52cb0e24e23cc65666684716d7","frame_index":0,"kind":"data","monotonic_ns":309611601390416,"payload":{"asset_id":"14965588658799411272385430903075831224615961675357217884735713260981483529984","best_ask":"0.6","best_bid":"0.59","event_type":"best_bid_ask","market":"0x779291bef19b6709f61e9764a954aafe9ffae488d50ae674aabdcb4f248006d5","spread":"0.01","timestamp":"1785207625900"},"payload_hash":"65c659870ba327d24cbe325d7feb5b167d49bea6b4c2bcc87af6127bf63e8d61","raw_frame":"{\"market\":\"0x779291bef19b6709f61e9764a954aafe9ffae488d50ae674aabdcb4f248006d5\", \"asset_id\":\"14965588658799411272385430903075831224615961675357217884735713260981483529984\", \"best_bid\":\"0.59\", \"best_ask\":\"0.6\", \"spread\":\"0.01\", \"timestamp\":\"1785207625900\", \"event_type\":\"best_bid_ask\"}","received_at":"2026-07-28T03:00:28.582820Z","schema_version":"clob-market-ws.best_bid_ask.v1","sequence":null,"server_hash":null,"server_timestamp":"1785207625900","session_id":"3e519d9098404c15b234d96025eb1a2b","source":"clob_market_ws"},"received_at":"2026-07-28T03:00:28.582820Z","record_id":"a7fc1c51e6e142633fcea522d642b964528341f9cd5e8d89fa1d6438b7e49e2f","schema_fingerprint":"8488399f31b0337811b13b266be932db7062827c2470b78bd8e9e99bab51d17d","schema_version":"edge-lab-recorder.raw.v1","sequence":null,"source":"clob_market_ws"}
{"event_at":"2026-07-28T03:00:25.900000Z","event_fingerprint":"168830d4ce734c587b56bd54b3ee5f38280e1094f28c4e780f5b48f70c8d8270","payload":{"connection_id":"a6b55582af5f430fb37ad02bf0922475","event_at":"2026-07-28T03:00:25.900000Z","event_type":"best_bid_ask","frame_hash":"ed7b549df198a367195bccb6bdf0a46a89bf7b401605569c4244fc2c4bd1ec2e","frame_index":0,"kind":"data","monotonic_ns":309611607204375,"payload":{"asset_id":"8761897749749422724209054078244794145777693856614463256546737399611489089783","best_ask":"0.41","best_bid":"0.4","event_type":"best_bid_ask","market":"0x779291bef19b6709f61e9764a954aafe9ffae488d50ae674aabdcb4f248006d5","spread":"0.01","timestamp":"1785207625900"},"payload_hash":"ed25945e9bbb36b21cba724422bcf04da2a20942234aea87fce754046acb0687","raw_frame":"{\"market\":\"0x779291bef19b6709f61e9764a954aafe9ffae488d50ae674aabdcb4f248006d5\", \"asset_id\":\"8761897749749422724209054078244794145777693856614463256546737399611489089783\", \"best_bid\":\"0.4\", \"best_ask\":\"0.41\", \"spread\":\"0.01\", \"timestamp\":\"1785207625900\", \"event_type\":\"best_bid_ask\"}","received_at":"2026-07-28T03:00:28.588635Z","schema_version":"clob-market-ws.best_bid_ask.v1","sequence":null,"server_hash":null,"server_timestamp":"1785207625900","session_id":"3e519d9098404c15b234d96025eb1a2b","source":"clob_market_ws"},"received_at":"2026-07-28T03:00:28.588635Z","record_id":"f18eca1c9bcad94c2ad82659faefc85d87a375a82ee3000bd509ee9aaf672b46","schema_fingerprint":"8488399f31b0337811b13b266be932db7062827c2470b78bd8e9e99bab51d17d","schema_version":"edge-lab-recorder.raw.v1","sequence":null,"source":"clob_market_ws"}
{"event_at":"2026-07-28T03:00:25.899000Z","event_fingerprint":"bedf726a02ab6fc9cfbfdc7a0a82cec87d780b70275392d25f68b2595ec6faa1","payload":{"connection_id":"a6b55582af5f430fb37ad02bf0922475","event_at":"2026-07-28T03:00:25.899000Z","event_type":"price_change","frame_hash":"87c2f002d4856e12d11fd0dc4171c1386147514c7ac1c12197ddd1ea0e355792","frame_index":0,"kind":"data","monotonic_ns":309611611817166,"payload":{"event_type":"price_change","market":"0x779291bef19b6709f61e9764a954aafe9ffae488d50ae674aabdcb4f248006d5","price_changes":[{"asset_id":"8761897749749422724209054078244794145777693856614463256546737399611489089783","best_ask":"0.41","best_bid":"0.4","hash":"b5b96482ac6cc8aeec29ac4b8de41b1d31af0b46","price":"0.4","side":"BUY","size":"2.98"},{"asset_id":"14965588658799411272385430903075831224615961675357217884735713260981483529984","best_ask":"0.6","best_bid":"0.59","hash":"50db41d785cf17ecdc15d01e77bdfb01bd63ddb1","price":"0.6","side":"SELL","size":"2.98"}],"timestamp":"1785207625899"},"payload_hash":"c0819cc7e2d7b789169c41aee6946df1699036fd3206c6924e20b71a26ad83a0","raw_frame":"{\"market\":\"0x779291bef19b6709f61e9764a954aafe9ffae488d50ae674aabdcb4f248006d5\", \"price_changes\":[{\"asset_id\":\"8761897749749422724209054078244794145777693856614463256546737399611489089783\", \"price\":\"0.4\", \"size\":\"2.98\", \"side\":\"BUY\", \"hash\":\"b5b96482ac6cc8aeec29ac4b8de41b1d31af0b46\", \"best_bid\":\"0.4\", \"best_ask\":\"0.41\"}, {\"asset_id\":\"14965588658799411272385430903075831224615961675357217884735713260981483529984\", \"price\":\"0.6\", \"size\":\"2.98\", \"side\":\"SELL\", \"hash\":\"50db41d785cf17ecdc15d01e77bdfb01bd63ddb1\", \"best_bid\":\"0.59\", \"best_ask\":\"0.6\"}], \"timestamp\":\"1785207625899\", \"event_type\":\"price_change\"}","received_at":"2026-07-28T03:00:28.593248Z","schema_version":"clob-market-ws.price_change.v1","sequence":null,"server_hash":null,"server_timestamp":"1785207625899","session_id":"3e519d9098404c15b234d96025eb1a2b","source":"clob_market_ws"},"received_at":"2026-07-28T03:00:28.593248Z","record_id":"cc148bca1ddbdc8abbcbef63ec435b2e1d62e293bdd064fd1520bc26a234d79a","schema_fingerprint":"4aa3821a28b0b7c2400bc59aba4bcc0a76e971dadd19610d3ad38c768e124dc7","schema_version":"edge-lab-recorder.raw.v1","sequence":null,"source":"clob_market_ws"}
{"event_at":null,"event_fingerprint":"0b9cdddf686d81d2b34911581a38afb31b6bac9c3e0a54f9c691e44483ef1a0b","payload":{"connection_id":"a6b55582af5f430fb37ad02bf0922475","detail":{"current_server_timestamp":"1785207625899","entity":"clob_market_ws:14965588658799411272385430903075831224615961675357217884735713260981483529984","previous_server_timestamp":"1785207625900"},"event_type":"anomaly.time_regression","kind":"diagnostic","monotonic_ns":309611623304500,"received_at":"2026-07-28T03:00:28.604735Z","schema_version":"edge-lab-recorder.anomaly.v1","session_id":"3e519d9098404c15b234d96025eb1a2b","source":"clob_market_ws","trigger_frame_hash":"90a973d0f2418fc34f21bde36a57c623c065d595a9aead8bdcef1f01865501df","trigger_server_hash":"50db41d785cf17ecdc15d01e77bdfb01bd63ddb1"},"received_at":"2026-07-28T03:00:28.604735Z","record_id":"1da73aeb614d27be2acd4a934b1ff9f09d99fa5feb1f539d19eada4bed322e2c","schema_fingerprint":"cb1780324c96914017c24d4692a681315845f9745a5a4a3a289c5a43388b35c3","schema_version":"edge-lab-recorder.raw.v1","sequence":null,"source":"clob_market_ws"}
{"event_at":"2026-07-28T03:00:25.899000Z","event_fingerprint":"68a958e9b344d63e568e702e605ffba4a71c9acf395e4df33130105890c239da","payload":{"connection_id":"a6b55582af5f430fb37ad02bf0922475","event_at":"2026-07-28T03:00:25.899000Z","event_type":"book","frame_hash":"90a973d0f2418fc34f21bde36a57c623c065d595a9aead8bdcef1f01865501df","frame_index":0,"kind":"data","monotonic_ns":309611622947166,"payload":{"asks":[{"price":"0.99","size":"7550.02"},{"price":"0.98","size":"1620"},{"price":"0.97","size":"1063.33"},{"price":"0.96","size":"770"},{"price":"0.95","size":"640"},{"price":"0.94","size":"689"},{"price":"0.93","size":"500"},{"price":"0.92","size":"601"},{"price":"0.91","size":"500"},{"price":"0.9","size":"176"},{"price":"0.88","size":"22"},{"price":"0.87","size":"11"},{"price":"0.86","size":"10"},{"price":"0.85","size":"229"},{"price":"0.84","size":"19"},{"price":"0.83","size":"9"},{"price":"0.82","size":"8"},{"price":"0.81","size":"8"},{"price":"0.8","size":"43"},{"price":"0.79","size":"15"},{"price":"0.78","size":"14"},{"price":"0.77","size":"34"},{"price":"0.76","size":"44"},{"price":"0.75","size":"168"},{"price":"0.74","size":"43"},{"price":"0.73","size":"123.59"},{"price":"0.72","size":"179.01"},{"price":"0.71","size":"126.26"},{"price":"0.7","size":"134.56"},{"price":"0.69","size":"114.74"},{"price":"0.68","size":"202.59"},{"price":"0.67","size":"103"},{"price":"0.66","size":"106"},{"price":"0.65","size":"217"},{"price":"0.64","size":"139"},{"price":"0.63","size":"36"},{"price":"0.62","size":"22.6"},{"price":"0.61","size":"96"},{"price":"0.6","size":"2.98"}],"asset_id":"14965588658799411272385430903075831224615961675357217884735713260981483529984","bids":[{"price":"0.01","size":"7550.02"},{"price":"0.02","size":"1630"},{"price":"0.03","size":"950"},{"price":"0.04","size":"770"},{"price":"0.05","size":"740"},{"price":"0.06","size":"689"},{"price":"0.07","size":"500"},{"price":"0.08","size":"601"},{"price":"0.09","size":"500"},{"price":"0.1","size":"186"},{"price":"0.12","size":"10"},{"price":"0.15","size":"31"},{"price":"0.16","size":"10"},{"price":"0.2","size":"40"},{"price":"0.21","size":"7"},{"price":"0.22","size":"7"},{"price":"0.23","size":"7"},{"price":"0.24","size":"7"},{"price":"0.25","size":"33"},{"price":"0.26","size":"13"},{"price":"0.27","size":"13"},{"price":"0.28","size":"13"},{"price":"0.29","size":"13"},{"price":"0.3","size":"23"},{"price":"0.31","size":"16"},{"price":"0.32","size":"6"},{"price":"0.33","size":"6"},{"price":"0.34","size":"6"},{"price":"0.35","size":"97.01"},{"price":"0.36","size":"35"},{"price":"0.37","size":"35"},{"price":"0.38","size":"35"},{"price":"0.39","size":"35"},{"price":"0.4","size":"54"},{"price":"0.41","size":"35"},{"price":"0.42","size":"35"},{"price":"0.43","size":"35"},{"price":"0.44","size":"40.27"},{"price":"0.45","size":"125.07"},{"price":"0.46","size":"144"},{"price":"0.47","size":"147.5"},{"price":"0.48","size":"154"},{"price":"0.49","size":"181"},{"price":"0.5","size":"186"},{"price":"0.51","size":"188"},{"price":"0.52","size":"188"},{"price":"0.53","size":"192"},{"price":"0.54","size":"180.6"},{"price":"0.55","size":"107.2"},{"price":"0.56","size":"108.32"},{"price":"0.57","size":"475.5"},{"price":"0.58","size":"123.59"},{"price":"0.59","size":"143.43"}],"event_type":"book","hash":"50db41d785cf17ecdc15d01e77bdfb01bd63ddb1","market":"0x779291bef19b6709f61e9764a954aafe9ffae488d50ae674aabdcb4f248006d5","timestamp":"1785207625899"},"payload_hash":"c70060107d0df454065ba9d2c54877487a17a44c108972b654d7ec8a55fc7c88","raw_frame":"{\"market\":\"0x779291bef19b6709f61e9764a954aafe9ffae488d50ae674aabdcb4f248006d5\", \"asset_id\":\"14965588658799411272385430903075831224615961675357217884735713260981483529984\", \"bids\":[{\"price\":\"0.01\", \"size\":\"7550.02\"}, {\"price\":\"0.02\", \"size\":\"1630\"}, {\"price\":\"0.03\", \"size\":\"950\"}, {\"price\":\"0.04\", \"size\":\"770\"}, {\"price\":\"0.05\", \"size\":\"740\"}, {\"price\":\"0.06\", \"size\":\"689\"}, {\"price\":\"0.07\", \"size\":\"500\"}, {\"price\":\"0.08\", \"size\":\"601\"}, {\"price\":\"0.09\", \"size\":\"500\"}, {\"price\":\"0.1\", \"size\":\"186\"}, {\"price\":\"0.12\", \"size\":\"10\"}, {\"price\":\"0.15\", \"size\":\"31\"}, {\"price\":\"0.16\", \"size\":\"10\"}, {\"price\":\"0.2\", \"size\":\"40\"}, {\"price\":\"0.21\", \"size\":\"7\"}, {\"price\":\"0.22\", \"size\":\"7\"}, {\"price\":\"0.23\", \"size\":\"7\"}, {\"price\":\"0.24\", \"size\":\"7\"}, {\"price\":\"0.25\", \"size\":\"33\"}, {\"price\":\"0.26\", \"size\":\"13\"}, {\"price\":\"0.27\", \"size\":\"13\"}, {\"price\":\"0.28\", \"size\":\"13\"}, {\"price\":\"0.29\", \"size\":\"13\"}, {\"price\":\"0.3\", \"size\":\"23\"}, {\"price\":\"0.31\", \"size\":\"16\"}, {\"price\":\"0.32\", \"size\":\"6\"}, {\"price\":\"0.33\", \"size\":\"6\"}, {\"price\":\"0.34\", \"size\":\"6\"}, {\"price\":\"0.35\", \"size\":\"97.01\"}, {\"price\":\"0.36\", \"size\":\"35\"}, {\"price\":\"0.37\", \"size\":\"35\"}, {\"price\":\"0.38\", \"size\":\"35\"}, {\"price\":\"0.39\", \"size\":\"35\"}, {\"price\":\"0.4\", \"size\":\"54\"}, {\"price\":\"0.41\", \"size\":\"35\"}, {\"price\":\"0.42\", \"size\":\"35\"}, {\"price\":\"0.43\", \"size\":\"35\"}, {\"price\":\"0.44\", \"size\":\"40.27\"}, {\"price\":\"0.45\", \"size\":\"125.07\"}, {\"price\":\"0.46\", \"size\":\"144\"}, {\"price\":\"0.47\", \"size\":\"147.5\"}, {\"price\":\"0.48\", \"size\":\"154\"}, {\"price\":\"0.49\", \"size\":\"181\"}, {\"price\":\"0.5\", \"size\":\"186\"}, {\"price\":\"0.51\", \"size\":\"188\"}, {\"price\":\"0.52\", \"size\":\"188\"}, {\"price\":\"0.53\", \"size\":\"192\"}, {\"price\":\"0.54\", \"size\":\"180.6\"}, {\"price\":\"0.55\", \"size\":\"107.2\"}, {\"price\":\"0.56\", \"size\":\"108.32\"}, {\"price\":\"0.57\", \"size\":\"475.5\"}, {\"price\":\"0.58\", \"size\":\"123.59\"}, {\"price\":\"0.59\", \"size\":\"143.43\"}], \"asks\":[{\"price\":\"0.99\", \"size\":\"7550.02\"}, {\"price\":\"0.98\", \"size\":\"1620\"}, {\"price\":\"0.97\", \"size\":\"1063.33\"}, {\"price\":\"0.96\", \"size\":\"770\"}, {\"price\":\"0.95\", \"size\":\"640\"}, {\"price\":\"0.94\", \"size\":\"689\"}, {\"price\":\"0.93\", \"size\":\"500\"}, {\"price\":\"0.92\", \"size\":\"601\"}, {\"price\":\"0.91\", \"size\":\"500\"}, {\"price\":\"0.9\", \"size\":\"176\"}, {\"price\":\"0.88\", \"size\":\"22\"}, {\"price\":\"0.87\", \"size\":\"11\"}, {\"price\":\"0.86\", \"size\":\"10\"}, {\"price\":\"0.85\", \"size\":\"229\"}, {\"price\":\"0.84\", \"size\":\"19\"}, {\"price\":\"0.83\", \"size\":\"9\"}, {\"price\":\"0.82\", \"size\":\"8\"}, {\"price\":\"0.81\", \"size\":\"8\"}, {\"price\":\"0.8\", \"size\":\"43\"}, {\"price\":\"0.79\", \"size\":\"15\"}, {\"price\":\"0.78\", \"size\":\"14\"}, {\"price\":\"0.77\", \"size\":\"34\"}, {\"price\":\"0.76\", \"size\":\"44\"}, {\"price\":\"0.75\", \"size\":\"168\"}, {\"price\":\"0.74\", \"size\":\"43\"}, {\"price\":\"0.73\", \"size\":\"123.59\"}, {\"price\":\"0.72\", \"size\":\"179.01\"}, {\"price\":\"0.71\", \"size\":\"126.26\"}, {\"price\":\"0.7\", \"size\":\"134.56\"}, {\"price\":\"0.69\", \"size\":\"114.74\"}, {\"price\":\"0.68\", \"size\":\"202.59\"}, {\"price\":\"0.67\", \"size\":\"103\"}, {\"price\":\"0.66\", \"size\":\"106\"}, {\"price\":\"0.65\", \"size\":\"217\"}, {\"price\":\"0.64\", \"size\":\"139\"}, {\"price\":\"0.63\", \"size\":\"36\"}, {\"price\":\"0.62\", \"size\":\"22.6\"}, {\"price\":\"0.61\", \"size\":\"96\"}, {\"price\":\"0.6\", \"size\":\"2.98\"}], \"hash\":\"50db41d785cf17ecdc15d01e77bdfb01bd63ddb1\", \"timestamp\":\"1785207625899\", \"event_type\":\"book\"}","received_at":"2026-07-28T03:00:28.604378Z","schema_version":"clob-market-ws.book.v1","sequence":null,"server_hash":"50db41d785cf17ecdc15d01e77bdfb01bd63ddb1","server_timestamp":"1785207625899","session_id":"3e519d9098404c15b234d96025eb1a2b","source":"clob_market_ws"},"received_at":"2026-07-28T03:00:28.604378Z","record_id":"402af8611bfb64704040c4fe106a25d76a3af2763d9dd27e9254c5c32612f4a8","schema_fingerprint":"dc2caa1c89c6a7426e2e07ff925910cd4d0a8a223a515d4092d91d6d127aacb6","schema_version":"edge-lab-recorder.raw.v1","sequence":null,"source":"clob_market_ws"}
{"event_at":null,"event_fingerprint":"f9d612a86e71001fa61402ae9e70bd25e30e1077b0bf536fbfdcb562d998bf5b","payload":{"connection_id":"a6b55582af5f430fb37ad02bf0922475","detail":{"current_server_timestamp":"1785207625899","entity":"clob_market_ws:8761897749749422724209054078244794145777693856614463256546737399611489089783","previous_server_timestamp":"1785207625900"},"event_type":"anomaly.time_regression","kind":"diagnostic","monotonic_ns":309611664441833,"received_at":"2026-07-28T03:00:28.645872Z","schema_version":"edge-lab-recorder.anomaly.v1","session_id":"3e519d9098404c15b234d96025eb1a2b","source":"clob_market_ws","trigger_frame_hash":"57059fd245b87cfd2d8946f93eebfbaac14cee85d0f2fb1af9e3b42c7ebb2835","trigger_server_hash":"b5b96482ac6cc8aeec29ac4b8de41b1d31af0b46"},"received_at":"2026-07-28T03:00:28.645872Z","record_id":"a8d64120265ee39ec910b6e2d8ea57246b64122c5aefc5096cb6f3eb752ce116","schema_fingerprint":"cb1780324c96914017c24d4692a681315845f9745a5a4a3a289c5a43388b35c3","schema_version":"edge-lab-recorder.raw.v1","sequence":null,"source":"clob_market_ws"}
{"event_at":"2026-07-28T03:00:25.899000Z","event_fingerprint":"27f1aab2cad2168775fa5a01506fea0f084176c3597752d2c882a47128deb3fc","payload":{"connection_id":"a6b55582af5f430fb37ad02bf0922475","event_at":"2026-07-28T03:00:25.899000Z","event_type":"book","frame_hash":"57059fd245b87cfd2d8946f93eebfbaac14cee85d0f2fb1af9e3b42c7ebb2835","frame_index":0,"kind":"data","monotonic_ns":309611664062375,"payload":{"asks":[{"price":"0.99","size":"7550.02"},{"price":"0.98","size":"1630"},{"price":"0.97","size":"950"},{"price":"0.96","size":"770"},{"price":"0.95","size":"740"},{"price":"0.94","size":"689"},{"price":"0.93","size":"500"},{"price":"0.92","size":"601"},{"price":"0.91","size":"500"},{"price":"0.9","size":"186"},{"price":"0.88","size":"10"},{"price":"0.85","size":"31"},{"price":"0.84","size":"10"},{"price":"0.8","size":"40"},{"price":"0.79","size":"7"},{"price":"0.78","size":"7"},{"price":"0.77","size":"7"},{"price":"0.76","size":"7"},{"price":"0.75","size":"33"},{"price":"0.74","size":"13"},{"price":"0.73","size":"13"},{"price":"0.72","size":"13"},{"price":"0.71","size":"13"},{"price":"0.7","size":"23"},{"price":"0.69","size":"16"},{"price":"0.68","size":"6"},{"price":"0.67","size":"6"},{"price":"0.66","size":"6"},{"price":"0.65","size":"97.01"},{"price":"0.64","size":"35"},{"price":"0.63","size":"35"},{"price":"0.62","size":"35"},{"price":"0.61","size":"35"},{"price":"0.6","size":"54"},{"price":"0.59","size":"35"},{"price":"0.58","size":"35"},{"price":"0.57","size":"35"},{"price":"0.56","size":"40.27"},{"price":"0.55","size":"125.07"},{"price":"0.54","size":"144"},{"price":"0.53","size":"147.5"},{"price":"0.52","size":"154"},{"price":"0.51","size":"181"},{"price":"0.5","size":"186"},{"price":"0.49","size":"188"},{"price":"0.48","size":"188"},{"price":"0.47","size":"192"},{"price":"0.46","size":"180.6"},{"price":"0.45","size":"107.2"},{"price":"0.44","size":"108.32"},{"price":"0.43","size":"475.5"},{"price":"0.42","size":"123.59"},{"price":"0.41","size":"143.43"}],"asset_id":"8761897749749422724209054078244794145777693856614463256546737399611489089783","bids":[{"price":"0.01","size":"7550.02"},{"price":"0.02","size":"1620"},{"price":"0.03","size":"1063.33"},{"price":"0.04","size":"770"},{"price":"0.05","size":"640"},{"price":"0.06","size":"689"},{"price":"0.07","size":"500"},{"price":"0.08","size":"601"},{"price":"0.09","size":"500"},{"price":"0.1","size":"176"},{"price":"0.12","size":"22"},{"price":"0.13","size":"11"},{"price":"0.14","size":"10"},{"price":"0.15","size":"229"},{"price":"0.16","size":"19"},{"price":"0.17","size":"9"},{"price":"0.18","size":"8"},{"price":"0.19","size":"8"},{"price":"0.2","size":"43"},{"price":"0.21","size":"15"},{"price":"0.22","size":"14"},{"price":"0.23","size":"34"},{"price":"0.24","size":"44"},{"price":"0.25","size":"168"},{"price":"0.26","size":"43"},{"price":"0.27","size":"123.59"},{"price":"0.28","size":"179.01"},{"price":"0.29","size":"126.26"},{"price":"0.3","size":"134.56"},{"price":"0.31","size":"114.74"},{"price":"0.32","size":"202.59"},{"price":"0.33","size":"103"},{"price":"0.34","size":"106"},{"price":"0.35","size":"217"},{"price":"0.36","size":"139"},{"price":"0.37","size":"36"},{"price":"0.38","size":"22.6"},{"price":"0.39","size":"96"},{"price":"0.4","size":"2.98"}],"event_type":"book","hash":"b5b96482ac6cc8aeec29ac4b8de41b1d31af0b46","market":"0x779291bef19b6709f61e9764a954aafe9ffae488d50ae674aabdcb4f248006d5","timestamp":"1785207625899"},"payload_hash":"ea843150a18dedfbdacb97be185144f17d71fa936835bff689287dcc6d96d578","raw_frame":"{\"market\":\"0x779291bef19b6709f61e9764a954aafe9ffae488d50ae674aabdcb4f248006d5\", \"asset_id\":\"8761897749749422724209054078244794145777693856614463256546737399611489089783\", \"bids\":[{\"price\":\"0.01\", \"size\":\"7550.02\"}, {\"price\":\"0.02\", \"size\":\"1620\"}, {\"price\":\"0.03\", \"size\":\"1063.33\"}, {\"price\":\"0.04\", \"size\":\"770\"}, {\"price\":\"0.05\", \"size\":\"640\"}, {\"price\":\"0.06\", \"size\":\"689\"}, {\"price\":\"0.07\", \"size\":\"500\"}, {\"price\":\"0.08\", \"size\":\"601\"}, {\"price\":\"0.09\", \"size\":\"500\"}, {\"price\":\"0.1\", \"size\":\"176\"}, {\"price\":\"0.12\", \"size\":\"22\"}, {\"price\":\"0.13\", \"size\":\"11\"}, {\"price\":\"0.14\", \"size\":\"10\"}, {\"price\":\"0.15\", \"size\":\"229\"}, {\"price\":\"0.16\", \"size\":\"19\"}, {\"price\":\"0.17\", \"size\":\"9\"}, {\"price\":\"0.18\", \"size\":\"8\"}, {\"price\":\"0.19\", \"size\":\"8\"}, {\"price\":\"0.2\", \"size\":\"43\"}, {\"price\":\"0.21\", \"size\":\"15\"}, {\"price\":\"0.22\", \"size\":\"14\"}, {\"price\":\"0.23\", \"size\":\"34\"}, {\"price\":\"0.24\", \"size\":\"44\"}, {\"price\":\"0.25\", \"size\":\"168\"}, {\"price\":\"0.26\", \"size\":\"43\"}, {\"price\":\"0.27\", \"size\":\"123.59\"}, {\"price\":\"0.28\", \"size\":\"179.01\"}, {\"price\":\"0.29\", \"size\":\"126.26\"}, {\"price\":\"0.3\", \"size\":\"134.56\"}, {\"price\":\"0.31\", \"size\":\"114.74\"}, {\"price\":\"0.32\", \"size\":\"202.59\"}, {\"price\":\"0.33\", \"size\":\"103\"}, {\"price\":\"0.34\", \"size\":\"106\"}, {\"price\":\"0.35\", \"size\":\"217\"}, {\"price\":\"0.36\", \"size\":\"139\"}, {\"price\":\"0.37\", \"size\":\"36\"}, {\"price\":\"0.38\", \"size\":\"22.6\"}, {\"price\":\"0.39\", \"size\":\"96\"}, {\"price\":\"0.4\", \"size\":\"2.98\"}], \"asks\":[{\"price\":\"0.99\", \"size\":\"7550.02\"}, {\"price\":\"0.98\", \"size\":\"1630\"}, {\"price\":\"0.97\", \"size\":\"950\"}, {\"price\":\"0.96\", \"size\":\"770\"}, {\"price\":\"0.95\", \"size\":\"740\"}, {\"price\":\"0.94\", \"size\":\"689\"}, {\"price\":\"0.93\", \"size\":\"500\"}, {\"price\":\"0.92\", \"size\":\"601\"}, {\"price\":\"0.91\", \"size\":\"500\"}, {\"price\":\"0.9\", \"size\":\"186\"}, {\"price\":\"0.88\", \"size\":\"10\"}, {\"price\":\"0.85\", \"size\":\"31\"}, {\"price\":\"0.84\", \"size\":\"10\"}, {\"price\":\"0.8\", \"size\":\"40\"}, {\"price\":\"0.79\", \"size\":\"7\"}, {\"price\":\"0.78\", \"size\":\"7\"}, {\"price\":\"0.77\", \"size\":\"7\"}, {\"price\":\"0.76\", \"size\":\"7\"}, {\"price\":\"0.75\", \"size\":\"33\"}, {\"price\":\"0.74\", \"size\":\"13\"}, {\"price\":\"0.73\", \"size\":\"13\"}, {\"price\":\"0.72\", \"size\":\"13\"}, {\"price\":\"0.71\", \"size\":\"13\"}, {\"price\":\"0.7\", \"size\":\"23\"}, {\"price\":\"0.69\", \"size\":\"16\"}, {\"price\":\"0.68\", \"size\":\"6\"}, {\"price\":\"0.67\", \"size\":\"6\"}, {\"price\":\"0.66\", \"size\":\"6\"}, {\"price\":\"0.65\", \"size\":\"97.01\"}, {\"price\":\"0.64\", \"size\":\"35\"}, {\"price\":\"0.63\", \"size\":\"35\"}, {\"price\":\"0.62\", \"size\":\"35\"}, {\"price\":\"0.61\", \"size\":\"35\"}, {\"price\":\"0.6\", \"size\":\"54\"}, {\"price\":\"0.59\", \"size\":\"35\"}, {\"price\":\"0.58\", \"size\":\"35\"}, {\"price\":\"0.57\", \"size\":\"35\"}, {\"price\":\"0.56\", \"size\":\"40.27\"}, {\"price\":\"0.55\", \"size\":\"125.07\"}, {\"price\":\"0.54\", \"size\":\"144\"}, {\"price\":\"0.53\", \"size\":\"147.5\"}, {\"price\":\"0.52\", \"size\":\"154\"}, {\"price\":\"0.51\", \"size\":\"181\"}, {\"price\":\"0.5\", \"size\":\"186\"}, {\"price\":\"0.49\", \"size\":\"188\"}, {\"price\":\"0.48\", \"size\":\"188\"}, {\"price\":\"0.47\", \"size\":\"192\"}, {\"price\":\"0.46\", \"size\":\"180.6\"}, {\"price\":\"0.45\", \"size\":\"107.2\"}, {\"price\":\"0.44\", \"size\":\"108.32\"}, {\"price\":\"0.43\", \"size\":\"475.5\"}, {\"price\":\"0.42\", \"size\":\"123.59\"}, {\"price\":\"0.41\", \"size\":\"143.43\"}], \"hash\":\"b5b96482ac6cc8aeec29ac4b8de41b1d31af0b46\", \"timestamp\":\"1785207625899\", \"event_type\":\"book\"}","received_at":"2026-07-28T03:00:28.645490Z","schema_version":"clob-market-ws.book.v1","sequence":null,"server_hash":"b5b96482ac6cc8aeec29ac4b8de41b1d31af0b46","server_timestamp":"1785207625899","session_id":"3e519d9098404c15b234d96025eb1a2b","source":"clob_market_ws"},"received_at":"2026-07-28T03:00:28.645490Z","record_id":"9a8fd8db02df26b9568c1f09bb31646e296a615a21a3006d319d80830f04d125","schema_fingerprint":"dc2caa1c89c6a7426e2e07ff925910cd4d0a8a223a515d4092d91d6d127aacb6","schema_version":"edge-lab-recorder.raw.v1","sequence":null,"source":"clob_market_ws"}
{"event_at":"2026-07-28T03:00:25.904000Z","event_fingerprint":"083872155d50c3ef28cb2d1ec19e597387a80dfde0be1172b766c8a67120da58","payload":{"connection_id":"a6b55582af5f430fb37ad02bf0922475","event_at":"2026-07-28T03:00:25.904000Z","event_type":"price_change","frame_hash":"ecc66c272fca29cd79028d9b9680f1af6b841698c6cb2dff3a70c4486bc6ff5c","frame_index":0,"kind":"data","monotonic_ns":309611686663291,"payload":{"event_type":"price_change","market":"0x779291bef19b6709f61e9764a954aafe9ffae488d50ae674aabdcb4f248006d5","price_changes":[{"asset_id":"14965588658799411272385430903075831224615961675357217884735713260981483529984","best_ask":"0.6","best_bid":"0.59","hash":"8ec2160b087ea58d8c54aa725162eb4f1f26d35c","price":"0.45","side":"BUY","size":"199.14"},{"asset_id":"8761897749749422724209054078244794145777693856614463256546737399611489089783","best_ask":"0.41","best_bid":"0.4","hash":"ee2b1a356b717ba7cd5aece15c6b3e4ddd1f12aa","price":"0.55","side":"SELL","size":"199.14"}],"timestamp":"1785207625904"},"payload_hash":"cb30bb7f8241104ee4ce858df3925e025b8eeb3a18c4d823546d6874ee3956f3","raw_frame":"{\"market\":\"0x779291bef19b6709f61e9764a954aafe9ffae488d50ae674aabdcb4f248006d5\", \"price_changes\":[{\"asset_id\":\"14965588658799411272385430903075831224615961675357217884735713260981483529984\", \"price\":\"0.45\", \"size\":\"199.14\", \"side\":\"BUY\", \"hash\":\"8ec2160b087ea58d8c54aa725162eb4f1f26d35c\", \"best_bid\":\"0.59\", \"best_ask\":\"0.6\"}, {\"asset_id\":\"8761897749749422724209054078244794145777693856614463256546737399611489089783\", \"price\":\"0.55\", \"size\":\"199.14\", \"side\":\"SELL\", \"hash\":\"ee2b1a356b717ba7cd5aece15c6b3e4ddd1f12aa\", \"best_bid\":\"0.4\", \"best_ask\":\"0.41\"}], \"timestamp\":\"1785207625904\", \"event_type\":\"price_change\"}","received_at":"2026-07-28T03:00:28.668092Z","schema_version":"clob-market-ws.price_change.v1","sequence":null,"server_hash":null,"server_timestamp":"1785207625904","session_id":"3e519d9098404c15b234d96025eb1a2b","source":"clob_market_ws"},"received_at":"2026-07-28T03:00:28.668092Z","record_id":"2a64fdbaa68f8c474a3557a788559e3dd4bf9a81b1fae2b39d9fcda9c25c45d4","schema_fingerprint":"4aa3821a28b0b7c2400bc59aba4bcc0a76e971dadd19610d3ad38c768e124dc7","schema_version":"edge-lab-recorder.raw.v1","sequence":null,"source":"clob_market_ws"}
{"event_at":"2026-07-28T03:00:25.908000Z","event_fingerprint":"a772787ee7a95c9a345e1f0399f9cff55b8a46f2e526a0c0d6bbc80cd0399daf","payload":{"connection_id":"a6b55582af5f430fb37ad02bf0922475","event_at":"2026-07-28T03:00:25.908000Z","event_type":"price_change","frame_hash":"aa22b9cf68fba5686ac89ed85642b4a6b9cdac2485e7987d19da018c91b13f5b","frame_index":0,"kind":"data","monotonic_ns":309611693940833,"payload":{"event_type":"price_change","market":"0x779291bef19b6709f61e9764a954aafe9ffae488d50ae674aabdcb4f248006d5","price_changes":[{"asset_id":"14965588658799411272385430903075831224615961675357217884735713260981483529984","best_ask":"0.6","best_bid":"0.59","hash":"d2236a7c78968f74d9a793365e3d9e1f1852c053","price":"0.01","side":"BUY","size":"7555.02"},{"asset_id":"8761897749749422724209054078244794145777693856614463256546737399611489089783","best_ask":"0.41","best_bid":"0.4","hash":"d3727c02c8a70747dcb2a0ce4331022feb641c3f","price":"0.99","side":"SELL","size":"7555.02"}],"timestamp":"1785207625908"},"payload_hash":"482225a4c3635272e4d77e890c8c14e6f136d8e7175feccd56908b9a2cb99260","raw_frame":"{\"market\":\"0x779291bef19b6709f61e9764a954aafe9ffae488d50ae674aabdcb4f248006d5\", \"price_changes\":[{\"asset_id\":\"14965588658799411272385430903075831224615961675357217884735713260981483529984\", \"price\":\"0.01\", \"size\":\"7555.02\", \"side\":\"BUY\", \"hash\":\"d2236a7c78968f74d9a793365e3d9e1f1852c053\", \"best_bid\":\"0.59\", \"best_ask\":\"0.6\"}, {\"asset_id\":\"8761897749749422724209054078244794145777693856614463256546737399611489089783\", \"price\":\"0.99\", \"size\":\"7555.02\", \"side\":\"SELL\", \"hash\":\"d3727c02c8a70747dcb2a0ce4331022feb641c3f\", \"best_bid\":\"0.4\", \"best_ask\":\"0.41\"}], \"timestamp\":\"1785207625908\", \"event_type\":\"price_change\"}","received_at":"2026-07-28T03:00:28.675370Z","schema_version":"clob-market-ws.price_change.v1","sequence":null,"server_hash":null,"server_timestamp":"1785207625908","session_id":"3e519d9098404c15b234d96025eb1a2b","source":"clob_market_ws"},"received_at":"2026-07-28T03:00:28.675370Z","record_id":"299adc7079d1a451c5a09f666b890a48f82d5e847baca0f56b5e7f386702c197","schema_fingerprint":"4aa3821a28b0b7c2400bc59aba4bcc0a76e971dadd19610d3ad38c768e124dc7","schema_version":"edge-lab-recorder.raw.v1","sequence":null,"source":"clob_market_ws"}
{"event_at":"2026-07-28T03:00:25.927000Z","event_fingerprint":"20daf06fac1489f42f9b739af5408bf7673972e8f61e653de41b370477a2abfc","payload":{"connection_id":"a6b55582af5f430fb37ad02bf0922475","event_at":"2026-07-28T03:00:25.927000Z","event_type":"price_change","frame_hash":"73fa92cfe4393740eb8006564127270ca2c34d9d9a7a8a3de94520b6160593b9","frame_index":0,"kind":"data","monotonic_ns":309611703374166,"payload":{"event_type":"price_change","market":"0x779291bef19b6709f61e9764a954aafe9ffae488d50ae674aabdcb4f248006d5","price_changes":[{"asset_id":"14965588658799411272385430903075831224615961675357217884735713260981483529984","best_ask":"0.6","best_bid":"0.59","hash":"39b15e81df545ed9cb2a1a3ab25a05b2181818b2","price":"0.02","side":"BUY","size":"1625"},{"asset_id":"8761897749749422724209054078244794145777693856614463256546737399611489089783","best_ask":"0.41","best_bid":"0.4","hash":"e0f57e9bccf039ab507a5658b3c44f0472dd4ef0","price":"0.98","side":"SELL","size":"1625"}],"timestamp":"1785207625927"},"payload_hash":"578ab504fbf76e18983e65c8a4561964af94998e9ffda0522d5c501652587aa8","raw_frame":"{\"market\":\"0x779291bef19b6709f61e9764a954aafe9ffae488d50ae674aabdcb4f248006d5\", \"price_changes\":[{\"asset_id\":\"14965588658799411272385430903075831224615961675357217884735713260981483529984\", \"price\":\"0.02\", \"size\":\"1625\", \"side\":\"BUY\", \"hash\":\"39b15e81df545ed9cb2a1a3ab25a05b2181818b2\", \"best_bid\":\"0.59\", \"best_ask\":\"0.6\"}, {\"asset_id\":\"8761897749749422724209054078244794145777693856614463256546737399611489089783\", \"price\":\"0.98\", \"size\":\"1625\", \"side\":\"SELL\", \"hash\":\"e0f57e9bccf039ab507a5658b3c44f0472dd4ef0\", \"best_bid\":\"0.4\", \"best_ask\":\"0.41\"}], \"timestamp\":\"1785207625927\", \"event_type\":\"price_change\"}","received_at":"2026-07-28T03:00:28.684804Z","schema_version":"clob-market-ws.price_change.v1","sequence":null,"server_hash":null,"server_timestamp":"1785207625927","session_id":"3e519d9098404c15b234d96025eb1a2b","source":"clob_market_ws"},"received_at":"2026-07-28T03:00:28.684804Z","record_id":"6d4aa41e3d1d56ea69d41e9e93e584d92d2f038ce3039fb0560f497313146655","schema_fingerprint":"4aa3821a28b0b7c2400bc59aba4bcc0a76e971dadd19610d3ad38c768e124dc7","schema_version":"edge-lab-recorder.raw.v1","sequence":null,"source":"clob_market_ws"}
{"event_at":"2026-07-28T03:00:25.937000Z","event_fingerprint":"2793d428009a4b0707d5228164009eb6f3cd647e980125db8d8bca530cba72e5","payload":{"connection_id":"a6b55582af5f430fb37ad02bf0922475","event_at":"2026-07-28T03:00:25.937000Z","event_type":"price_change","frame_hash":"5cac36fc580c296cc8d8128b64a855741b4cf04513c46672ed0fdd23fcc1246b","frame_index":0,"kind":"data","monotonic_ns":309611709726166,"payload":{"event_type":"price_change","market":"0x779291bef19b6709f61e9764a954aafe9ffae488d50ae674aabdcb4f248006d5","price_changes":[{"asset_id":"14965588658799411272385430903075831224615961675357217884735713260981483529984","best_ask":"0.6","best_bid":"0.59","hash":"ab04c6b97907b009c3f9acf1cfa837fd0d2dc3ea","price":"0.01","side":"BUY","size":"7550.02"},{"asset_id":"8761897749749422724209054078244794145777693856614463256546737399611489089783","best_ask":"0.41","best_bid":"0.4","hash":"1419f2986adb13f8af408edc745ce969c5b618f0","price":"0.99","side":"SELL","size":"7550.02"}],"timestamp":"1785207625937"},"payload_hash":"c70e40c2936512568d2b26e6fd9a64c99d8b61fe20a4a4d50447e09aa3bb007e","raw_frame":"{\"market\":\"0x779291bef19b6709f61e9764a954aafe9ffae488d50ae674aabdcb4f248006d5\", \"price_changes\":[{\"asset_id\":\"14965588658799411272385430903075831224615961675357217884735713260981483529984\", \"price\":\"0.01\", \"size\":\"7550.02\", \"side\":\"BUY\", \"hash\":\"ab04c6b97907b009c3f9acf1cfa837fd0d2dc3ea\", \"best_bid\":\"0.59\", \"best_ask\":\"0.6\"}, {\"asset_id\":\"8761897749749422724209054078244794145777693856614463256546737399611489089783\", \"price\":\"0.99\", \"size\":\"7550.02\", \"side\":\"SELL\", \"hash\":\"1419f2986adb13f8af408edc745ce969c5b618f0\", \"best_bid\":\"0.4\", \"best_ask\":\"0.41\"}], \"timestamp\":\"1785207625937\", \"event_type\":\"price_change\"}","received_at":"2026-07-28T03:00:28.691155Z","schema_version":"clob-market-ws.price_change.v1","sequence":null,"server_hash":null,"server_timestamp":"1785207625937","session_id":"3e519d9098404c15b234d96025eb1a2b","source":"clob_market_ws"},"received_at":"2026-07-28T03:00:28.691155Z","record_id":"58814fa558cfba431709e37f97b11b2f6145f352a97d60c74f97f06bbfe77f4d","schema_fingerprint":"4aa3821a28b0b7c2400bc59aba4bcc0a76e971dadd19610d3ad38c768e124dc7","schema_version":"edge-lab-recorder.raw.v1","sequence":null,"source":"clob_market_ws"}
{"event_at":"2026-07-28T03:00:25.938000Z","event_fingerprint":"ac2e7cca9038a815b9e394b2509cc06486a573f3d6ac5f3a58b8939a1951dcfc","payload":{"connection_id":"a6b55582af5f430fb37ad02bf0922475","event_at":"2026-07-28T03:00:25.938000Z","event_type":"last_trade_price","frame_hash":"8e66e34446d98ebbd58552bcfc860b0d965b926aacd0734c527b8f9c2392633c","frame_index":0,"kind":"data","monotonic_ns":309611716096916,"payload":{"asset_id":"14965588658799411272385430903075831224615961675357217884735713260981483529984","event_type":"last_trade_price","fee_rate_bps":"0","market":"0x779291bef19b6709f61e9764a954aafe9ffae488d50ae674aabdcb4f248006d5","price":"0.6","side":"BUY","size":"2","timestamp":"1785207625938","transaction_hash":"0x1c08b8c07012cc0f24233b4ca3110fc06433ba6828f0d376851067bef2821228"},"payload_hash":"6f51c3c86bb4bebd9bd0b81cba17f9c50fca7d5a5bd9e56472fce50c0971e8a6","raw_frame":"{\"market\":\"0x779291bef19b6709f61e9764a954aafe9ffae488d50ae674aabdcb4f248006d5\", \"asset_id\":\"14965588658799411272385430903075831224615961675357217884735713260981483529984\", \"price\":\"0.6\", \"size\":\"2\", \"fee_rate_bps\":\"0\", \"side\":\"BUY\", \"timestamp\":\"1785207625938\", \"event_type\":\"last_trade_price\", \"transaction_hash\":\"0x1c08b8c07012cc0f24233b4ca3110fc06433ba6828f0d376851067bef2821228\"}","received_at":"2026-07-28T03:00:28.697526Z","schema_version":"clob-market-ws.last_trade_price.v1","sequence":null,"server_hash":null,"server_timestamp":"1785207625938","session_id":"3e519d9098404c15b234d96025eb1a2b","source":"clob_market_ws"},"received_at":"2026-07-28T03:00:28.697526Z","record_id":"f8c810a6cf3e66a448624902c0971f85e7d7e8a4d1041442cb19095739c8ec43","schema_fingerprint":"95ad9be75a4b695cd99991e12b2592bc7346f3f5388a82d0000ba65bc0d9fd0a","schema_version":"edge-lab-recorder.raw.v1","sequence":null,"source":"clob_market_ws"}
{"event_at":"2026-07-28T03:00:25.994000Z","event_fingerprint":"6b2852b69018b4357e1e817e023f900398251d721797d9dfdbb441a6fc04193a","payload":{"connection_id":"a6b55582af5f430fb37ad02bf0922475","event_at":"2026-07-28T03:00:25.994000Z","event_type":"price_change","frame_hash":"1774715f85a0920374ea4a8ef96164b22bdeb96e591a8319122266c2fb1d0aee","frame_index":0,"kind":"data","monotonic_ns":309611721952541,"payload":{"event_type":"price_change","market":"0x779291bef19b6709f61e9764a954aafe9ffae488d50ae674aabdcb4f248006d5","price_changes":[{"asset_id":"8761897749749422724209054078244794145777693856614463256546737399611489089783","best_ask":"0.41","best_bid":"0.4","hash":"c8cde7b45b7b7adbb75088bf9021d35ce6eab382","price":"0.15","side":"BUY","size":"424"},{"asset_id":"14965588658799411272385430903075831224615961675357217884735713260981483529984","best_ask":"0.6","best_bid":"0.59","hash":"f451492f0c4b76b34326069d85af0ae55ed6b623","price":"0.85","side":"SELL","size":"424"}],"timestamp":"1785207625994"},"payload_hash":"810d34a8cd771e6e309d0f577252d2737104a57281954593f654e3c3b1281e4b","raw_frame":"{\"market\":\"0x779291bef19b6709f61e9764a954aafe9ffae488d50ae674aabdcb4f248006d5\", \"price_changes\":[{\"asset_id\":\"8761897749749422724209054078244794145777693856614463256546737399611489089783\", \"price\":\"0.15\", \"size\":\"424\", \"side\":\"BUY\", \"hash\":\"c8cde7b45b7b7adbb75088bf9021d35ce6eab382\", \"best_bid\":\"0.4\", \"best_ask\":\"0.41\"}, {\"asset_id\":\"14965588658799411272385430903075831224615961675357217884735713260981483529984\", \"price\":\"0.85\", \"size\":\"424\", \"side\":\"SELL\", \"hash\":\"f451492f0c4b76b34326069d85af0ae55ed6b623\", \"best_bid\":\"0.59\", \"best_ask\":\"0.6\"}], \"timestamp\":\"1785207625994\", \"event_type\":\"price_change\"}","received_at":"2026-07-28T03:00:28.703382Z","schema_version":"clob-market-ws.price_change.v1","sequence":null,"server_hash":null,"server_timestamp":"1785207625994","session_id":"3e519d9098404c15b234d96025eb1a2b","source":"clob_market_ws"},"received_at":"2026-07-28T03:00:28.703382Z","record_id":"dbbc5af20b116effa7b250ec1405087588a07d9b51674722a218ef564f439399","schema_fingerprint":"4aa3821a28b0b7c2400bc59aba4bcc0a76e971dadd19610d3ad38c768e124dc7","schema_version":"edge-lab-recorder.raw.v1","sequence":null,"source":"clob_market_ws"}
{"event_at":"2026-07-28T03:00:26.006000Z","event_fingerprint":"f534c57fa52303158c417475f1b02f9ea0bfd5b112328a54a9613268f87467a3","payload":{"connection_id":"a6b55582af5f430fb37ad02bf0922475","event_at":"2026-07-28T03:00:26.006000Z","event_type":"price_change","frame_hash":"312e9e00a67ab66838242f567c8f4da725127a22b4949b8d3436450aee5dce1d","frame_index":0,"kind":"data","monotonic_ns":309611729500125,"payload":{"event_type":"price_change","market":"0x779291bef19b6709f61e9764a954aafe9ffae488d50ae674aabdcb4f248006d5","price_changes":[{"asset_id":"14965588658799411272385430903075831224615961675357217884735713260981483529984","best_ask":"0.6","best_bid":"0.59","hash":"791be9f52028cb733576c6ba34c1dcf3a9520080","price":"0.57","side":"BUY","size":"379.5"},{"asset_id":"8761897749749422724209054078244794145777693856614463256546737399611489089783","best_ask":"0.41","best_bid":"0.4","hash":"1c6e0b06c1cf3de40b734eb789c281d8a2613423","price":"0.43","side":"SELL","size":"379.5"}],"timestamp":"1785207626006"},"payload_hash":"f05231133a5e6c2407af5ca482c439fd25c7f2112488c4cebaf167cd39c6c2c0","raw_frame":"{\"market\":\"0x779291bef19b6709f61e9764a954aafe9ffae488d50ae674aabdcb4f248006d5\", \"price_changes\":[{\"asset_id\":\"14965588658799411272385430903075831224615961675357217884735713260981483529984\", \"price\":\"0.57\", \"size\":\"379.5\", \"side\":\"BUY\", \"hash\":\"791be9f52028cb733576c6ba34c1dcf3a9520080\", \"best_bid\":\"0.59\", \"best_ask\":\"0.6\"}, {\"asset_id\":\"8761897749749422724209054078244794145777693856614463256546737399611489089783\", \"price\":\"0.43\", \"size\":\"379.5\", \"side\":\"SELL\", \"hash\":\"1c6e0b06c1cf3de40b734eb789c281d8a2613423\", \"best_bid\":\"0.4\", \"best_ask\":\"0.41\"}], \"timestamp\":\"1785207626006\", \"event_type\":\"price_change\"}","received_at":"2026-07-28T03:00:28.710930Z","schema_version":"clob-market-ws.price_change.v1","sequence":null,"server_hash":null,"server_timestamp":"1785207626006","session_id":"3e519d9098404c15b234d96025eb1a2b","source":"clob_market_ws"},"received_at":"2026-07-28T03:00:28.710930Z","record_id":"d1f780697b29b0b2312e428c38df99e1436746ce132bd8f112521caa15f8e7be","schema_fingerprint":"4aa3821a28b0b7c2400bc59aba4bcc0a76e971dadd19610d3ad38c768e124dc7","schema_version":"edge-lab-recorder.raw.v1","sequence":null,"source":"clob_market_ws"}
{"event_at":"2026-07-28T03:00:26.010000Z","event_fingerprint":"341bdf583877759b1dc94b34f1c288aef88bdb938ef0c37719c4936c22ac404f","payload":{"connection_id":"a6b55582af5f430fb37ad02bf0922475","event_at":"2026-07-28T03:00:26.010000Z","event_type":"price_change","frame_hash":"35701488c72910574ec9d80ffe5054fd0c2b896ceddbaa261e02dd3c3f009b67","frame_index":0,"kind":"data","monotonic_ns":309611735159250,"payload":{"event_type":"price_change","market":"0x779291bef19b6709f61e9764a954aafe9ffae488d50ae674aabdcb4f248006d5","price_changes":[{"asset_id":"14965588658799411272385430903075831224615961675357217884735713260981483529984","best_ask":"0.6","best_bid":"0.59","hash":"3abe92ff573b7390788ec3587af4b7a297208442","price":"0.58","side":"BUY","size":"219.59"},{"asset_id":"8761897749749422724209054078244794145777693856614463256546737399611489089783","best_ask":"0.41","best_bid":"0.4","hash":"29af8d6fbb0f3896fdc6d51b6e0104ecf02c731b","price":"0.42","side":"SELL","size":"219.59"}],"timestamp":"1785207626010"},"payload_hash":"d5ab9273d8294524f999dbdd1574654d88565d3ce5f9423909fc840c7e6de7d1","raw_frame":"{\"market\":\"0x779291bef19b6709f61e9764a954aafe9ffae488d50ae674aabdcb4f248006d5\", \"price_changes\":[{\"asset_id\":\"14965588658799411272385430903075831224615961675357217884735713260981483529984\", \"price\":\"0.58\", \"size\":\"219.59\", \"side\":\"BUY\", \"hash\":\"3abe92ff573b7390788ec3587af4b7a297208442\", \"best_bid\":\"0.59\", \"best_ask\":\"0.6\"}, {\"asset_id\":\"8761897749749422724209054078244794145777693856614463256546737399611489089783\", \"price\":\"0.42\", \"size\":\"219.59\", \"side\":\"SELL\", \"hash\":\"29af8d6fbb0f3896fdc6d51b6e0104ecf02c731b\", \"best_bid\":\"0.4\", \"best_ask\":\"0.41\"}], \"timestamp\":\"1785207626010\", \"event_type\":\"price_change\"}","received_at":"2026-07-28T03:00:28.716589Z","schema_version":"clob-market-ws.price_change.v1","sequence":null,"server_hash":null,"server_timestamp":"1785207626010","session_id":"3e519d9098404c15b234d96025eb1a2b","source":"clob_market_ws"},"received_at":"2026-07-28T03:00:28.716589Z","record_id":"a3c647cd33adb260d2b65a58e9482b01a800d5b22628b51141ad7b951a6dbb69","schema_fingerprint":"4aa3821a28b0b7c2400bc59aba4bcc0a76e971dadd19610d3ad38c768e124dc7","schema_version":"edge-lab-recorder.raw.v1","sequence":null,"source":"clob_market_ws"}
{"event_at":"2026-07-28T03:00:26.011000Z","event_fingerprint":"467fca09788e8be64189266d76b458dbe6294770024d4ac3013e3d6aa8a402e5","payload":{"connection_id":"a6b55582af5f430fb37ad02bf0922475","event_at":"2026-07-28T03:00:26.011000Z","event_type":"price_change","frame_hash":"6fa9e20c69489a0d0ceee61544d3958ca55067ba0598e09381ea0703c5f7e0cc","frame_index":0,"kind":"data","monotonic_ns":309611739017833,"payload":{"event_type":"price_change","market":"0x779291bef19b6709f61e9764a954aafe9ffae488d50ae674aabdcb4f248006d5","price_changes":[{"asset_id":"8761897749749422724209054078244794145777693856614463256546737399611489089783","best_ask":"0.41","best_bid":"0.4","hash":"df3fa88bf8ebf905d00065676a5a8b3155f5f2c9","price":"0.22","side":"BUY","size":"34"},{"asset_id":"14965588658799411272385430903075831224615961675357217884735713260981483529984","best_ask":"0.6","best_bid":"0.59","hash":"c5335030b5e15a3ce7bf6ee5972f6d0a6a46326e","price":"0.78","side":"SELL","size":"34"}],"timestamp":"1785207626011"},"payload_hash":"216f98b74fa3e20812a54fd88e0abcf8d67dc8ac94c3148f785b15a1576fabc6","raw_frame":"{\"market\":\"0x779291bef19b6709f61e9764a954aafe9ffae488d50ae674aabdcb4f248006d5\", \"price_changes\":[{\"asset_id\":\"8761897749749422724209054078244794145777693856614463256546737399611489089783\", \"price\":\"0.22\", \"size\":\"34\", \"side\":\"BUY\", \"hash\":\"df3fa88bf8ebf905d00065676a5a8b3155f5f2c9\", \"best_bid\":\"0.4\", \"best_ask\":\"0.41\"}, {\"asset_id\":\"14965588658799411272385430903075831224615961675357217884735713260981483529984\", \"price\":\"0.78\", \"size\":\"34\", \"side\":\"SELL\", \"hash\":\"c5335030b5e15a3ce7bf6ee5972f6d0a6a46326e\", \"best_bid\":\"0.59\", \"best_ask\":\"0.6\"}], \"timestamp\":\"1785207626011\", \"event_type\":\"price_change\"}","received_at":"2026-07-28T03:00:28.720447Z","schema_version":"clob-market-ws.price_change.v1","sequence":null,"server_hash":null,"server_timestamp":"1785207626011","session_id":"3e519d9098404c15b234d96025eb1a2b","source":"clob_market_ws"},"received_at":"2026-07-28T03:00:28.720447Z","record_id":"e1a85180843d423d7795687f3ee07308543eb60a1c27da7a59262edb654548e8","schema_fingerprint":"4aa3821a28b0b7c2400bc59aba4bcc0a76e971dadd19610d3ad38c768e124dc7","schema_version":"edge-lab-recorder.raw.v1","sequence":null,"source":"clob_market_ws"}
{"event_at":"2026-07-28T03:00:26.012000Z","event_fingerprint":"cf335350dfcb3b76880965ec42985b3bf973e2407c8c262bba7d001a13e159b7","payload":{"connection_id":"a6b55582af5f430fb37ad02bf0922475","event_at":"2026-07-28T03:00:26.012000Z","event_type":"price_change","frame_hash":"037b7c628dc94304f2bb61c7b0a4e9c393a16bd2d1375bd4042a8823fa6f610e","frame_index":0,"kind":"data","monotonic_ns":309611744949625,"payload":{"event_type":"price_change","market":"0x779291bef19b6709f61e9764a954aafe9ffae488d50ae674aabdcb4f248006d5","price_changes":[{"asset_id":"8761897749749422724209054078244794145777693856614463256546737399611489089783","best_ask":"0.41","best_bid":"0.4","hash":"fe9badc32d88fa7dc1a1712d8c003c855c01a4de","price":"0.23","side":"BUY","size":"44"},{"asset_id":"14965588658799411272385430903075831224615961675357217884735713260981483529984","best_ask":"0.6","best_bid":"0.59","hash":"ad7021f11001b5f45c90f2b3ac4d52e75c86423d","price":"0.77","side":"SELL","size":"44"}],"timestamp":"1785207626012"},"payload_hash":"de5b4d2dbccd9df116c1fe6939d995bb24bcc5b706a02b6df89e6ee6985c2cf7","raw_frame":"{\"market\":\"0x779291bef19b6709f61e9764a954aafe9ffae488d50ae674aabdcb4f248006d5\", \"price_changes\":[{\"asset_id\":\"8761897749749422724209054078244794145777693856614463256546737399611489089783\", \"price\":\"0.23\", \"size\":\"44\", \"side\":\"BUY\", \"hash\":\"fe9badc32d88fa7dc1a1712d8c003c855c01a4de\", \"best_bid\":\"0.4\", \"best_ask\":\"0.41\"}, {\"asset_id\":\"14965588658799411272385430903075831224615961675357217884735713260981483529984\", \"price\":\"0.77\", \"size\":\"44\", \"side\":\"SELL\", \"hash\":\"ad7021f11001b5f45c90f2b3ac4d52e75c86423d\", \"best_bid\":\"0.59\", \"best_ask\":\"0.6\"}], \"timestamp\":\"1785207626012\", \"event_type\":\"price_change\"}","received_at":"2026-07-28T03:00:28.726382Z","schema_version":"clob-market-ws.price_change.v1","sequence":null,"server_hash":null,"server_timestamp":"1785207626012","session_id":"3e519d9098404c15b234d96025eb1a2b","source":"clob_market_ws"},"received_at":"2026-07-28T03:00:28.726382Z","record_id":"4044cc4c305d7bf0c1d256e18a98133147f201989a6c07a79d07b12539909358","schema_fingerprint":"4aa3821a28b0b7c2400bc59aba4bcc0a76e971dadd19610d3ad38c768e124dc7","schema_version":"edge-lab-recorder.raw.v1","sequence":null,"source":"clob_market_ws"}
{"event_at":"2026-07-28T03:00:26.012000Z","event_fingerprint":"05a8ed33b7cf0b8afe01365a24827b0169dd94bb5057d089d07c8358d0577155","payload":{"connection_id":"a6b55582af5f430fb37ad02bf0922475","event_at":"2026-07-28T03:00:26.012000Z","event_type":"price_change","frame_hash":"1d1d4145818f12482c96e18a72a46781ceedfdbff3e1c8e4d10698af84c35301","frame_index":0,"kind":"data","monotonic_ns":309611749380541,"payload":{"event_type":"price_change","market":"0x779291bef19b6709f61e9764a954aafe9ffae488d50ae674aabdcb4f248006d5","price_changes":[{"asset_id":"8761897749749422724209054078244794145777693856614463256546737399611489089783","best_ask":"0.41","best_bid":"0.4","hash":"4c0ac2caf462d05edc8b023e11decc5b3060242c","price":"0.39","side":"BUY","size":"0"},{"asset_id":"14965588658799411272385430903075831224615961675357217884735713260981483529984","best_ask":"0.6","best_bid":"0.59","hash":"6c0a6040b851ecd164f70abd023b2eb0984ad08f","price":"0.61","side":"SELL","size":"0"}],"timestamp":"1785207626012"},"payload_hash":"1210586fb113f47cf6033e22823b2a4104151d7e5e0fbc2c7f60fd7937fc8d9b","raw_frame":"{\"market\":\"0x779291bef19b6709f61e9764a954aafe9ffae488d50ae674aabdcb4f248006d5\", \"price_changes\":[{\"asset_id\":\"8761897749749422724209054078244794145777693856614463256546737399611489089783\", \"price\":\"0.39\", \"size\":\"0\", \"side\":\"BUY\", \"hash\":\"4c0ac2caf462d05edc8b023e11decc5b3060242c\", \"best_bid\":\"0.4\", \"best_ask\":\"0.41\"}, {\"asset_id\":\"14965588658799411272385430903075831224615961675357217884735713260981483529984\", \"price\":\"0.61\", \"size\":\"0\", \"side\":\"SELL\", \"hash\":\"6c0a6040b851ecd164f70abd023b2eb0984ad08f\", \"best_bid\":\"0.59\", \"best_ask\":\"0.6\"}], \"timestamp\":\"1785207626012\", \"event_type\":\"price_change\"}","received_at":"2026-07-28T03:00:28.730806Z","schema_version":"clob-market-ws.price_change.v1","sequence":null,"server_hash":null,"server_timestamp":"1785207626012","session_id":"3e519d9098404c15b234d96025eb1a2b","source":"clob_market_ws"},"received_at":"2026-07-28T03:00:28.730806Z","record_id":"45a39fae4453a9d0097f88e92672ab7e5e7e1993c082f1b06bef239a1af1f411","schema_fingerprint":"4aa3821a28b0b7c2400bc59aba4bcc0a76e971dadd19610d3ad38c768e124dc7","schema_version":"edge-lab-recorder.raw.v1","sequence":null,"source":"clob_market_ws"}
{"event_at":"2026-07-28T03:00:26.012000Z","event_fingerprint":"f8af3b0084e68ad1c3a7a939fc4bf276e65c2531fdaaafcf353d28557330d8bc","payload":{"connection_id":"a6b55582af5f430fb37ad02bf0922475","event_at":"2026-07-28T03:00:26.012000Z","event_type":"price_change","frame_hash":"b1e8f0732247751015406222520c2d5d3495a07ee8e308d2c0f9ded0aafd1c2b","frame_index":0,"kind":"data","monotonic_ns":309611765068083,"payload":{"event_type":"price_change","market":"0x779291bef19b6709f61e9764a954aafe9ffae488d50ae674aabdcb4f248006d5","price_changes":[{"asset_id":"14965588658799411272385430903075831224615961675357217884735713260981483529984","best_ask":"0.6","best_bid":"0.59","hash":"76b45d515a89a14149796285b7d257c75ef9065b","price":"0.57","side":"BUY","size":"109.5"},{"asset_id":"8761897749749422724209054078244794145777693856614463256546737399611489089783","best_ask":"0.41","best_bid":"0.4","hash":"0780a2f735641cc8ba4122ac54df2b97ed1558f4","price":"0.43","side":"SELL","size":"109.5"}],"timestamp":"1785207626012"},"payload_hash":"015c6130f9ed5818791626d0ee4165f5c2534e8a562ba11c7a1c2529bdb212f3","raw_frame":"{\"market\":\"0x779291bef19b6709f61e9764a954aafe9ffae488d50ae674aabdcb4f248006d5\", \"price_changes\":[{\"asset_id\":\"14965588658799411272385430903075831224615961675357217884735713260981483529984\", \"price\":\"0.57\", \"size\":\"109.5\", \"side\":\"BUY\", \"hash\":\"76b45d515a89a14149796285b7d257c75ef9065b\", \"best_bid\":\"0.59\", \"best_ask\":\"0.6\"}, {\"asset_id\":\"8761897749749422724209054078244794145777693856614463256546737399611489089783\", \"price\":\"0.43\", \"size\":\"109.5\", \"side\":\"SELL\", \"hash\":\"0780a2f735641cc8ba4122ac54df2b97ed1558f4\", \"best_bid\":\"0.4\", \"best_ask\":\"0.41\"}], \"timestamp\":\"1785207626012\", \"event_type\":\"price_change\"}","received_at":"2026-07-28T03:00:28.746497Z","schema_version":"clob-market-ws.price_change.v1","sequence":null,"server_hash":null,"server_timestamp":"1785207626012","session_id":"3e519d9098404c15b234d96025eb1a2b","source":"clob_market_ws"},"received_at":"2026-07-28T03:00:28.746497Z","record_id":"005b3a1daba91010a1c94f0d5c8c74cd003bd8a179c0ff4bd5f06ba0d280e6b6","schema_fingerprint":"4aa3821a28b0b7c2400bc59aba4bcc0a76e971dadd19610d3ad38c768e124dc7","schema_version":"edge-lab-recorder.raw.v1","sequence":null,"source":"clob_market_ws"}
{"event_at":"2026-07-28T03:00:26.013000Z","event_fingerprint":"401ee9e66378375ef2b5260ed159d679b917618836f15dc7b55a5a4d9208ac3c","payload":{"connection_id":"a6b55582af5f430fb37ad02bf0922475","event_at":"2026-07-28T03:00:26.013000Z","event_type":"price_change","frame_hash":"c1df3b5b9d59947cc4d4f84b88b85d947f6eabcc5d4f74c8cb473432158be0f7","frame_index":0,"kind":"data","monotonic_ns":309611773348625,"payload":{"event_type":"price_change","market":"0x779291bef19b6709f61e9764a954aafe9ffae488d50ae674aabdcb4f248006d5","price_changes":[{"asset_id":"14965588658799411272385430903075831224615961675357217884735713260981483529984","best_ask":"0.6","best_bid":"0.59","hash":"c37035a48cf56bffc8653d50d65c1b927a986d19","price":"0.54","side":"BUY","size":"175.6"},{"asset_id":"8761897749749422724209054078244794145777693856614463256546737399611489089783","best_ask":"0.41","best_bid":"0.4","hash":"131c11f84e9e1ece0e23daf73d46a424f1b65f26","price":"0.46","side":"SELL","size":"175.6"}],"timestamp":"1785207626013"},"payload_hash":"3d89da65e35d8ae49287250a01ce98c26c9b2a793aa89937eca03344e7008d33","raw_frame":"{\"market\":\"0x779291bef19b6709f61e9764a954aafe9ffae488d50ae674aabdcb4f248006d5\", \"price_changes\":[{\"asset_id\":\"14965588658799411272385430903075831224615961675357217884735713260981483529984\", \"price\":\"0.54\", \"size\":\"175.6\", \"side\":\"BUY\", \"hash\":\"c37035a48cf56bffc8653d50d65c1b927a986d19\", \"best_bid\":\"0.59\", \"best_ask\":\"0.6\"}, {\"asset_id\":\"8761897749749422724209054078244794145777693856614463256546737399611489089783\", \"price\":\"0.46\", \"size\":\"175.6\", \"side\":\"SELL\", \"hash\":\"131c11f84e9e1ece0e23daf73d46a424f1b65f26\", \"best_bid\":\"0.4\", \"best_ask\":\"0.41\"}], \"timestamp\":\"1785207626013\", \"event_type\":\"price_change\"}","received_at":"2026-07-28T03:00:28.754778Z","schema_version":"clob-market-ws.price_change.v1","sequence":null,"server_hash":null,"server_timestamp":"1785207626013","session_id":"3e519d9098404c15b234d96025eb1a2b","source":"clob_market_ws"},"received_at":"2026-07-28T03:00:28.754778Z","record_id":"e6cbd28a950fd6d50c2682f4f9944ad0b77871e4e59dc410a2b34a130f833e57","schema_fingerprint":"4aa3821a28b0b7c2400bc59aba4bcc0a76e971dadd19610d3ad38c768e124dc7","schema_version":"edge-lab-recorder.raw.v1","sequence":null,"source":"clob_market_ws"}
{"event_at":"2026-07-28T03:00:26.013000Z","event_fingerprint":"25fc198a0b784505cd6cb3414250df9b6950206c458f2109c7f6dd35bb0cc093","payload":{"connection_id":"a6b55582af5f430fb37ad02bf0922475","event_at":"2026-07-28T03:00:26.013000Z","event_type":"price_change","frame_hash":"d6fac019e4fe1565cffb8950ffc2e04376c8b79a147e6c23a70e7affb13ecd0e","frame_index":0,"kind":"data","monotonic_ns":309611780012541,"payload":{"event_type":"price_change","market":"0x779291bef19b6709f61e9764a954aafe9ffae488d50ae674aabdcb4f248006d5","price_changes":[{"asset_id":"8761897749749422724209054078244794145777693856614463256546737399611489089783","best_ask":"0.41","best_bid":"0.4","hash":"0dd7658214aa04da19d40a173ca91224b6a722a7","price":"0.38","side":"BUY","size":"292.6"},{"asset_id":"14965588658799411272385430903075831224615961675357217884735713260981483529984","best_ask":"0.6","best_bid":"0.59","hash":"5e0939b7b0c127f483386a952550f96a86c05905","price":"0.62","side":"SELL","size":"292.6"}],"timestamp":"1785207626013"},"payload_hash":"0b19ddc02b4dd1e8953085b848ea9301ab9ac34290a8c0723833e056d8050b2c","raw_frame":"{\"market\":\"0x779291bef19b6709f61e9764a954aafe9ffae488d50ae674aabdcb4f248006d5\", \"price_changes\":[{\"asset_id\":\"8761897749749422724209054078244794145777693856614463256546737399611489089783\", \"price\":\"0.38\", \"size\":\"292.6\", \"side\":\"BUY\", \"hash\":\"0dd7658214aa04da19d40a173ca91224b6a722a7\", \"best_bid\":\"0.4\", \"best_ask\":\"0.41\"}, {\"asset_id\":\"14965588658799411272385430903075831224615961675357217884735713260981483529984\", \"price\":\"0.62\", \"size\":\"292.6\", \"side\":\"SELL\", \"hash\":\"5e0939b7b0c127f483386a952550f96a86c05905\", \"best_bid\":\"0.59\", \"best_ask\":\"0.6\"}], \"timestamp\":\"1785207626013\", \"event_type\":\"price_change\"}","received_at":"2026-07-28T03:00:28.761442Z","schema_version":"clob-market-ws.price_change.v1","sequence":null,"server_hash":null,"server_timestamp":"1785207626013","session_id":"3e519d9098404c15b234d96025eb1a2b","source":"clob_market_ws"},"received_at":"2026-07-28T03:00:28.761442Z","record_id":"2bc9c8700f50ec5a1ffd4221afa43bda71aab50aa26af9a09c88300d3a41e708","schema_fingerprint":"4aa3821a28b0b7c2400bc59aba4bcc0a76e971dadd19610d3ad38c768e124dc7","schema_version":"edge-lab-recorder.raw.v1","sequence":null,"source":"clob_market_ws"}
{"event_at":"2026-07-28T03:00:26.015000Z","event_fingerprint":"c0ed55f295ed9e9b21f5836e7214ce161c1d3508d4b4b76950002d2e6a253b55","payload":{"connection_id":"a6b55582af5f430fb37ad02bf0922475","event_at":"2026-07-28T03:00:26.015000Z","event_type":"price_change","frame_hash":"3061ea1a0837a341e73a72f2a06a1abfc366d8dbe09ca4e473115f0b3fbc457e","frame_index":0,"kind":"data","monotonic_ns":309611793940625,"payload":{"event_type":"price_change","market":"0x779291bef19b6709f61e9764a954aafe9ffae488d50ae674aabdcb4f248006d5","price_changes":[{"asset_id":"8761897749749422724209054078244794145777693856614463256546737399611489089783","best_ask":"0.41","best_bid":"0.4","hash":"c8b9f22c73e81ebc3f888b6beed654e112e4296b","price":"0.36","side":"BUY","size":"134"},{"asset_id":"14965588658799411272385430903075831224615961675357217884735713260981483529984","best_ask":"0.6","best_bid":"0.59","hash":"f340317b06c54e18cd9c09460fa7afdfb8f56ba8","price":"0.64","side":"SELL","size":"134"}],"timestamp":"1785207626015"},"payload_hash":"ddf9086bdeb6e8bf1e0f71506c940c5a31e5ebdc2fcf318f2c9e1cc514ca3c4b","raw_frame":"{\"market\":\"0x779291bef19b6709f61e9764a954aafe9ffae488d50ae674aabdcb4f248006d5\", \"price_changes\":[{\"asset_id\":\"8761897749749422724209054078244794145777693856614463256546737399611489089783\", \"price\":\"0.36\", \"size\":\"134\", \"side\":\"BUY\", \"hash\":\"c8b9f22c73e81ebc3f888b6beed654e112e4296b\", \"best_bid\":\"0.4\", \"best_ask\":\"0.41\"}, {\"asset_id\":\"14965588658799411272385430903075831224615961675357217884735713260981483529984\", \"price\":\"0.64\", \"size\":\"134\", \"side\":\"SELL\", \"hash\":\"f340317b06c54e18cd9c09460fa7afdfb8f56ba8\", \"best_bid\":\"0.59\", \"best_ask\":\"0.6\"}], \"timestamp\":\"1785207626015\", \"event_type\":\"price_change\"}","received_at":"2026-07-28T03:00:28.775367Z","schema_version":"clob-market-ws.price_change.v1","sequence":null,"server_hash":null,"server_timestamp":"1785207626015","session_id":"3e519d9098404c15b234d96025eb1a2b","source":"clob_market_ws"},"received_at":"2026-07-28T03:00:28.775367Z","record_id":"d096ec7d75076d39cfcd99b50543cc194b0c065e3d39df7845350cdb145a0504","schema_fingerprint":"4aa3821a28b0b7c2400bc59aba4bcc0a76e971dadd19610d3ad38c768e124dc7","schema_version":"edge-lab-recorder.raw.v1","sequence":null,"source":"clob_market_ws"}
{"event_at":"2026-07-28T03:00:26.015000Z","event_fingerprint":"c647b04585068c1f1021401d07007ab9d373043ed0080ad8a7c99c2d4651e985","payload":{"connection_id":"a6b55582af5f430fb37ad02bf0922475","event_at":"2026-07-28T03:00:26.015000Z","event_type":"price_change","frame_hash":"097423d6bffa65ee51aeabdbf12ae022794f13501960211db2d67b5025cc5eb9","frame_index":0,"kind":"data","monotonic_ns":309611809563291,"payload":{"event_type":"price_change","market":"0x779291bef19b6709f61e9764a954aafe9ffae488d50ae674aabdcb4f248006d5","price_changes":[{"asset_id":"14965588658799411272385430903075831224615961675357217884735713260981483529984","best_ask":"0.6","best_bid":"0.59","hash":"b8c8df68857304f4bf9551513b74f98b3c1cafd8","price":"0.5","side":"BUY","size":"180"},{"asset_id":"8761897749749422724209054078244794145777693856614463256546737399611489089783","best_ask":"0.41","best_bid":"0.4","hash":"a4bfad407caa6048c7caa9906f9bd68c74a13bcb","price":"0.5","side":"SELL","size":"180"}],"timestamp":"1785207626015"},"payload_hash":"7e089f129669e4e20ecb5a2fd6820201fdbe75360143737d52d35ffea85f3aaf","raw_frame":"{\"market\":\"0x779291bef19b6709f61e9764a954aafe9ffae488d50ae674aabdcb4f248006d5\", \"price_changes\":[{\"asset_id\":\"14965588658799411272385430903075831224615961675357217884735713260981483529984\", \"price\":\"0.5\", \"size\":\"180\", \"side\":\"BUY\", \"hash\":\"b8c8df68857304f4bf9551513b74f98b3c1cafd8\", \"best_bid\":\"0.59\", \"best_ask\":\"0.6\"}, {\"asset_id\":\"8761897749749422724209054078244794145777693856614463256546737399611489089783\", \"price\":\"0.5\", \"size\":\"180\", \"side\":\"SELL\", \"hash\":\"a4bfad407caa6048c7caa9906f9bd68c74a13bcb\", \"best_bid\":\"0.4\", \"best_ask\":\"0.41\"}], \"timestamp\":\"1785207626015\", \"event_type\":\"price_change\"}","received_at":"2026-07-28T03:00:28.790989Z","schema_version":"clob-market-ws.price_change.v1","sequence":null,"server_hash":null,"server_timestamp":"1785207626015","session_id":"3e519d9098404c15b234d96025eb1a2b","source":"clob_market_ws"},"received_at":"2026-07-28T03:00:28.790989Z","record_id":"0a3514cd07dd8ae4de08fe2e93875d1fc6a6514cb677cf6b5c3f236364b0afb3","schema_fingerprint":"4aa3821a28b0b7c2400bc59aba4bcc0a76e971dadd19610d3ad38c768e124dc7","schema_version":"edge-lab-recorder.raw.v1","sequence":null,"source":"clob_market_ws"}
{"event_at":"2026-07-28T03:00:26.016000Z","event_fingerprint":"1c6243d7d097ce141d68e634ede24795965169daf3c9c45a018619b384bd0759","payload":{"connection_id":"a6b55582af5f430fb37ad02bf0922475","event_at":"2026-07-28T03:00:26.016000Z","event_type":"price_change","frame_hash":"1af60d312c42a1a01527386a652b51ff00fdeddc66d82ccaa0d17015bb2ff32a","frame_index":0,"kind":"data","monotonic_ns":309611822666750,"payload":{"event_type":"price_change","market":"0x779291bef19b6709f61e9764a954aafe9ffae488d50ae674aabdcb4f248006d5","price_changes":[{"asset_id":"14965588658799411272385430903075831224615961675357217884735713260981483529984","best_ask":"0.6","best_bid":"0.59","hash":"2590e0849c7f7ee7e2b0e7405158a66ef70979b2","price":"0.57","side":"BUY","size":"103.5"},{"asset_id":"8761897749749422724209054078244794145777693856614463256546737399611489089783","best_ask":"0.41","best_bid":"0.4","hash":"d28e5c84bd5cd4ab6be7c1e93f710f849d7d7c6b","price":"0.43","side":"SELL","size":"103.5"}],"timestamp":"1785207626016"},"payload_hash":"e9858625f2410f3d8b965abb51ac3f0ef1688c9eec13e0a4f485c708bd32d1b1","raw_frame":"{\"market\":\"0x779291bef19b6709f61e9764a954aafe9ffae488d50ae674aabdcb4f248006d5\", \"price_changes\":[{\"asset_id\":\"14965588658799411272385430903075831224615961675357217884735713260981483529984\", \"price\":\"0.57\", \"size\":\"103.5\", \"side\":\"BUY\", \"hash\":\"2590e0849c7f7ee7e2b0e7405158a66ef70979b2\", \"best_bid\":\"0.59\", \"best_ask\":\"0.6\"}, {\"asset_id\":\"8761897749749422724209054078244794145777693856614463256546737399611489089783\", \"price\":\"0.43\", \"size\":\"103.5\", \"side\":\"SELL\", \"hash\":\"d28e5c84bd5cd4ab6be7c1e93f710f849d7d7c6b\", \"best_bid\":\"0.4\", \"best_ask\":\"0.41\"}], \"timestamp\":\"1785207626016\", \"event_type\":\"price_change\"}","received_at":"2026-07-28T03:00:28.804095Z","schema_version":"clob-market-ws.price_change.v1","sequence":null,"server_hash":null,"server_timestamp":"1785207626016","session_id":"3e519d9098404c15b234d96025eb1a2b","source":"clob_market_ws"},"received_at":"2026-07-28T03:00:28.804095Z","record_id":"f188079bfb5f89d761c70d38ebdd50d0c954c2d82b62c3982a5d8356203a3721","schema_fingerprint":"4aa3821a28b0b7c2400bc59aba4bcc0a76e971dadd19610d3ad38c768e124dc7","schema_version":"edge-lab-recorder.raw.v1","sequence":null,"source":"clob_market_ws"}
{"event_at":"2026-07-28T03:00:26.023000Z","event_fingerprint":"1041feaa765a1320f36d799bb64e553e8a166d213797a8f658473a33fff45a98","payload":{"connection_id":"a6b55582af5f430fb37ad02bf0922475","event_at":"2026-07-28T03:00:26.023000Z","event_type":"price_change","frame_hash":"f76b86c56847e95d216b0a6abf39a8ada8e908c9e9d57dbd34a54b4e86c94ba0","frame_index":0,"kind":"data","monotonic_ns":309611828778666,"payload":{"event_type":"price_change","market":"0x779291bef19b6709f61e9764a954aafe9ffae488d50ae674aabdcb4f248006d5","price_changes":[{"asset_id":"8761897749749422724209054078244794145777693856614463256546737399611489089783","best_ask":"0.41","best_bid":"0.4","hash":"fc24974288884ed86ba81aee834fe5a71eeb6c3e","price":"0.08","side":"BUY","size":"618"},{"asset_id":"14965588658799411272385430903075831224615961675357217884735713260981483529984","best_ask":"0.6","best_bid":"0.59","hash":"9bf7a79edbb89dec183a901ac08021477165e6fd","price":"0.92","side":"SELL","size":"618"}],"timestamp":"1785207626023"},"payload_hash":"a149a94fc4b15a62569a8de1e0a1d474b189b8e243359c6bd79a57cb34c869f2","raw_frame":"{\"market\":\"0x779291bef19b6709f61e9764a954aafe9ffae488d50ae674aabdcb4f248006d5\", \"price_changes\":[{\"asset_id\":\"8761897749749422724209054078244794145777693856614463256546737399611489089783\", \"price\":\"0.08\", \"size\":\"618\", \"side\":\"BUY\", \"hash\":\"fc24974288884ed86ba81aee834fe5a71eeb6c3e\", \"best_bid\":\"0.4\", \"best_ask\":\"0.41\"}, {\"asset_id\":\"14965588658799411272385430903075831224615961675357217884735713260981483529984\", \"price\":\"0.92\", \"size\":\"618\", \"side\":\"SELL\", \"hash\":\"9bf7a79edbb89dec183a901ac08021477165e6fd\", \"best_bid\":\"0.59\", \"best_ask\":\"0.6\"}], \"timestamp\":\"1785207626023\", \"event_type\":\"price_change\"}","received_at":"2026-07-28T03:00:28.810207Z","schema_version":"clob-market-ws.price_change.v1","sequence":null,"server_hash":null,"server_timestamp":"1785207626023","session_id":"3e519d9098404c15b234d96025eb1a2b","source":"clob_market_ws"},"received_at":"2026-07-28T03:00:28.810207Z","record_id":"7c8e9e536d3769ce66be767468bfb056e50b8cf4b5fb2dc54d5680ac6b1f7c32","schema_fingerprint":"4aa3821a28b0b7c2400bc59aba4bcc0a76e971dadd19610d3ad38c768e124dc7","schema_version":"edge-lab-recorder.raw.v1","sequence":null,"source":"clob_market_ws"}
