{"event_at":"2026-07-28T03:08:07.378000Z","event_fingerprint":"6a08dddd2d8e67610aa582c6879c0114a2a6310bdb99cf7357d9399200e746fb","payload":{"connection_id":"a6b55582af5f430fb37ad02bf0922475","event_at":"2026-07-28T03:08:07.378000Z","event_type":"price_change","frame_hash":"49356b5ccb6d8d173cc01505af5609629e25973b490b09ef14fa59d67506e9de","frame_index":0,"kind":"data","monotonic_ns":310070409067166,"payload":{"event_type":"price_change","market":"0x779291bef19b6709f61e9764a954aafe9ffae488d50ae674aabdcb4f248006d5","price_changes":[{"asset_id":"8761897749749422724209054078244794145777693856614463256546737399611489089783","best_ask":"0.59","best_bid":"0.58","hash":"81329186823f6e3d90b3e377f3abad996f8e9c9a","price":"0.27","side":"BUY","size":"204.65"},{"asset_id":"14965588658799411272385430903075831224615961675357217884735713260981483529984","best_ask":"0.42","best_bid":"0.41","hash":"d27d02946565ea71ecf74dc63f145f214932fbd2","price":"0.73","side":"SELL","size":"204.65"}],"timestamp":"1785208087378"},"payload_hash":"86826d6fca9ad288c101f2cdc20a17365630d352155e433573fb956a083daba1","raw_frame":"{\"market\":\"0x779291bef19b6709f61e9764a954aafe9ffae488d50ae674aabdcb4f248006d5\", \"price_changes\":[{\"asset_id\":\"8761897749749422724209054078244794145777693856614463256546737399611489089783\", \"price\":\"0.27\", \"size\":\"204.65\", \"side\":\"BUY\", \"hash\":\"81329186823f6e3d90b3e377f3abad996f8e9c9a\", \"best_bid\":\"0.58\", \"best_ask\":\"0.59\"}, {\"asset_id\":\"14965588658799411272385430903075831224615961675357217884735713260981483529984\", \"price\":\"0.73\", \"size\":\"204.65\", \"side\":\"SELL\", \"hash\":\"d27d02946565ea71ecf74dc63f145f214932fbd2\", \"best_bid\":\"0.41\", \"best_ask\":\"0.42\"}], \"timestamp\":\"1785208087378\", \"event_type\":\"price_change\"}","received_at":"2026-07-28T03:08:07.376732Z","schema_version":"clob-market-ws.price_change.v1","sequence":null,"server_hash":null,"server_timestamp":"1785208087378","session_id":"3e519d9098404c15b234d96025eb1a2b","source":"clob_market_ws"},"received_at":"2026-07-28T03:08:07.376732Z","record_id":"19a3432178b0b6031e59aedab5d1b49b3a08f59c5855b134087e43b4839d030f","schema_fingerprint":"4aa3821a28b0b7c2400bc59aba4bcc0a76e971dadd19610d3ad38c768e124dc7","schema_version":"edge-lab-recorder.raw.v1","sequence":null,"source":"clob_market_ws"}
{"event_at":"2026-07-28T03:08:07.379000Z","event_fingerprint":"42cecba2684e12ca82f503af835b1d646309800abce82dcbf36cca0971e2077f","payload":{"connection_id":"a6b55582af5f430fb37ad02bf0922475","event_at":"2026-07-28T03:08:07.379000Z","event_type":"price_change","frame_hash":"c10534813d33c37aece58a5c7296d179cbc9875acf871bc8e4e6b604620306ee","frame_index":0,"kind":"data","monotonic_ns":310070411477958,"payload":{"event_type":"price_change","market":"0x779291bef19b6709f61e9764a954aafe9ffae488d50ae674aabdcb4f248006d5","price_changes":[{"asset_id":"14965588658799411272385430903075831224615961675357217884735713260981483529984","best_ask":"0.42","best_bid":"0.41","hash":"bd358ffdadca8250a5991795dc100644582f6f9c","price":"0.24","side":"BUY","size":"375.27"},{"asset_id":"8761897749749422724209054078244794145777693856614463256546737399611489089783","best_ask":"0.59","best_bid":"0.58","hash":"807386cc2a6e12fa33ea5847b5802a6d31499c25","price":"0.76","side":"SELL","size":"375.27"}],"timestamp":"1785208087379"},"payload_hash":"20d58343d855f5ec69aa154e800641454d916fa8bf84af72e00af904c3904403","raw_frame":"{\"market\":\"0x779291bef19b6709f61e9764a954aafe9ffae488d50ae674aabdcb4f248006d5\", \"price_changes\":[{\"asset_id\":\"14965588658799411272385430903075831224615961675357217884735713260981483529984\", \"price\":\"0.24\", \"size\":\"375.27\", \"side\":\"BUY\", \"hash\":\"bd358ffdadca8250a5991795dc100644582f6f9c\", \"best_bid\":\"0.41\", \"best_ask\":\"0.42\"}, {\"asset_id\":\"8761897749749422724209054078244794145777693856614463256546737399611489089783\", \"price\":\"0.76\", \"size\":\"375.27\", \"side\":\"SELL\", \"hash\":\"807386cc2a6e12fa33ea5847b5802a6d31499c25\", \"best_bid\":\"0.58\", \"best_ask\":\"0.59\"}], \"timestamp\":\"1785208087379\", \"event_type\":\"price_change\"}","received_at":"2026-07-28T03:08:07.379144Z","schema_version":"clob-market-ws.price_change.v1","sequence":null,"server_hash":null,"server_timestamp":"1785208087379","session_id":"3e519d9098404c15b234d96025eb1a2b","source":"clob_market_ws"},"received_at":"2026-07-28T03:08:07.379144Z","record_id":"0e82202980274d1f9d37dafe3f5e2210dd233a3bdfc2a2d4d543703fe3bf5515","schema_fingerprint":"4aa3821a28b0b7c2400bc59aba4bcc0a76e971dadd19610d3ad38c768e124dc7","schema_version":"edge-lab-recorder.raw.v1","sequence":null,"source":"clob_market_ws"}
{"event_at":"2026-07-28T03:08:07.380000Z","event_fingerprint":"07deb0c16bb8105d5962ed7c85774e13406d9607360a810bd9848925eb9c48cd","payload":{"connection_id":"a6b55582af5f430fb37ad02bf0922475","event_at":"2026-07-28T03:08:07.380000Z","event_type":"price_change","frame_hash":"be02554526176eeaab82a6e80a74e29a9e4ec492b0293441f935a02e96213e85","frame_index":0,"kind":"data","monotonic_ns":310070413156375,"payload":{"event_type":"price_change","market":"0x779291bef19b6709f61e9764a954aafe9ffae488d50ae674aabdcb4f248006d5","price_changes":[{"asset_id":"8761897749749422724209054078244794145777693856614463256546737399611489089783","best_ask":"0.59","best_bid":"0.58","hash":"9bfd45b94ae1410ef38b974079b12603c30c7358","price":"0.02","side":"BUY","size":"693.1"},{"asset_id":"14965588658799411272385430903075831224615961675357217884735713260981483529984","best_ask":"0.42","best_bid":"0.41","hash":"eee923619d2b3047f0a61103501a83f90ee143f2","price":"0.98","side":"SELL","size":"693.1"}],"timestamp":"1785208087380"},"payload_hash":"c8f752894fdcd6e92a9940bee7ab43154da96ec171e0fb6416f6ad2c5379e702","raw_frame":"{\"market\":\"0x779291bef19b6709f61e9764a954aafe9ffae488d50ae674aabdcb4f248006d5\", \"price_changes\":[{\"asset_id\":\"8761897749749422724209054078244794145777693856614463256546737399611489089783\", \"price\":\"0.02\", \"size\":\"693.1\", \"side\":\"BUY\", \"hash\":\"9bfd45b94ae1410ef38b974079b12603c30c7358\", \"best_bid\":\"0.58\", \"best_ask\":\"0.59\"}, {\"asset_id\":\"14965588658799411272385430903075831224615961675357217884735713260981483529984\", \"price\":\"0.98\", \"size\":\"693.1\", \"side\":\"SELL\", \"hash\":\"eee923619d2b3047f0a61103501a83f90ee143f2\", \"best_bid\":\"0.41\", \"best_ask\":\"0.42\"}], \"timestamp\":\"1785208087380\", \"event_type\":\"price_change\"}","received_at":"2026-07-28T03:08:07.380822Z","schema_version":"clob-market-ws.price_change.v1","sequence":null,"server_hash":null,"server_timestamp":"1785208087380","session_id":"3e519d9098404c15b234d96025eb1a2b","source":"clob_market_ws"},"received_at":"2026-07-28T03:08:07.380822Z","record_id":"c5e455ce7a9543641edf66adbd592da9bfa4154a772d17859c53097ebe22acea","schema_fingerprint":"4aa3821a28b0b7c2400bc59aba4bcc0a76e971dadd19610d3ad38c768e124dc7","schema_version":"edge-lab-recorder.raw.v1","sequence":null,"source":"clob_market_ws"}
{"event_at":"2026-07-28T03:08:07.381000Z","event_fingerprint":"a12e8af155fa32e6c196b97393a8bd95c70a02ad6b8431fcb9cda26bcebbeb7a","payload":{"connection_id":"a6b55582af5f430fb37ad02bf0922475","event_at":"2026-07-28T03:08:07.381000Z","event_type":"price_change","frame_hash":"a4184402f3d6c56eef9f10e352ed0580a575ff19d00894579e111e58ec1bb3a7","frame_index":0,"kind":"data","monotonic_ns":310070414712458,"payload":{"event_type":"price_change","market":"0x779291bef19b6709f61e9764a954aafe9ffae488d50ae674aabdcb4f248006d5","price_changes":[{"asset_id":"8761897749749422724209054078244794145777693856614463256546737399611489089783","best_ask":"0.59","best_bid":"0.58","hash":"517945a3151a6273d5ce753454ba6878f6fd846f","price":"0.53","side":"BUY","size":"62"},{"asset_id":"14965588658799411272385430903075831224615961675357217884735713260981483529984","best_ask":"0.42","best_bid":"0.41","hash":"cb9a980a0d2dbb9af096750d0a8fefeef20423a9","price":"0.47","side":"SELL","size":"62"}],"timestamp":"1785208087381"},"payload_hash":"855dd66213dce0f7d1613eaf197b9be8681820a924c61b380352961f4f966221","raw_frame":"{\"market\":\"0x779291bef19b6709f61e9764a954aafe9ffae488d50ae674aabdcb4f248006d5\", \"price_changes\":[{\"asset_id\":\"8761897749749422724209054078244794145777693856614463256546737399611489089783\", \"price\":\"0.53\", \"size\":\"62\", \"side\":\"BUY\", \"hash\":\"517945a3151a6273d5ce753454ba6878f6fd846f\", \"best_bid\":\"0.58\", \"best_ask\":\"0.59\"}, {\"asset_id\":\"14965588658799411272385430903075831224615961675357217884735713260981483529984\", \"price\":\"0.47\", \"size\":\"62\", \"side\":\"SELL\", \"hash\":\"cb9a980a0d2dbb9af096750d0a8fefeef20423a9\", \"best_bid\":\"0.41\", \"best_ask\":\"0.42\"}], \"timestamp\":\"1785208087381\", \"event_type\":\"price_change\"}","received_at":"2026-07-28T03:08:07.382379Z","schema_version":"clob-market-ws.price_change.v1","sequence":null,"server_hash":null,"server_timestamp":"1785208087381","session_id":"3e519d9098404c15b234d96025eb1a2b","source":"clob_market_ws"},"received_at":"2026-07-28T03:08:07.382379Z","record_id":"7980bf16ec41c6b541f776e9ec72b6d2c8b9caec15ac94e26f7e95d0d22d1d3f","schema_fingerprint":"4aa3821a28b0b7c2400bc59aba4bcc0a76e971dadd19610d3ad38c768e124dc7","schema_version":"edge-lab-recorder.raw.v1","sequence":null,"source":"clob_market_ws"}
{"event_at":"2026-07-28T03:08:07.381000Z","event_fingerprint":"4082baf217435a7a56d5d4c2858c8ff6eed6505403d646342f6a062e73dc659f","payload":{"connection_id":"a6b55582af5f430fb37ad02bf0922475","event_at":"2026-07-28T03:08:07.381000Z","event_type":"price_change","frame_hash":"09810ccf81b07f129028a770cb646b0f6ec9c541588976ab90533ea1eb3d053f","frame_index":0,"kind":"data","monotonic_ns":310070416258458,"payload":{"event_type":"price_change","market":"0x779291bef19b6709f61e9764a954aafe9ffae488d50ae674aabdcb4f248006d5","price_changes":[{"asset_id":"8761897749749422724209054078244794145777693856614463256546737399611489089783","best_ask":"0.59","best_bid":"0.58","hash":"f939250589a0400f38dc89701c182eabc04242b1","price":"0.53","side":"BUY","size":"42"},{"asset_id":"14965588658799411272385430903075831224615961675357217884735713260981483529984","best_ask":"0.42","best_bid":"0.41","hash":"fc9ed97fb85be97b995553450a2c47fb9d31ec7f","price":"0.47","side":"SELL","size":"42"}],"timestamp":"1785208087381"},"payload_hash":"27538a02f2103d22527045ab321e94da30920c57cd585c4813b06ce67b29a50a","raw_frame":"{\"market\":\"0x779291bef19b6709f61e9764a954aafe9ffae488d50ae674aabdcb4f248006d5\", \"price_changes\":[{\"asset_id\":\"8761897749749422724209054078244794145777693856614463256546737399611489089783\", \"price\":\"0.53\", \"size\":\"42\", \"side\":\"BUY\", \"hash\":\"f939250589a0400f38dc89701c182eabc04242b1\", \"best_bid\":\"0.58\", \"best_ask\":\"0.59\"}, {\"asset_id\":\"14965588658799411272385430903075831224615961675357217884735713260981483529984\", \"price\":\"0.47\", \"size\":\"42\", \"side\":\"SELL\", \"hash\":\"fc9ed97fb85be97b995553450a2c47fb9d31ec7f\", \"best_bid\":\"0.41\", \"best_ask\":\"0.42\"}], \"timestamp\":\"1785208087381\", \"event_type\":\"price_change\"}","received_at":"2026-07-28T03:08:07.383926Z","schema_version":"clob-market-ws.price_change.v1","sequence":null,"server_hash":null,"server_timestamp":"1785208087381","session_id":"3e519d9098404c15b234d96025eb1a2b","source":"clob_market_ws"},"received_at":"2026-07-28T03:08:07.383926Z","record_id":"59b713c2d935c5325343e56ca3b7468f7030e715d53e9161d065d1c827eb7f36","schema_fingerprint":"4aa3821a28b0b7c2400bc59aba4bcc0a76e971dadd19610d3ad38c768e124dc7","schema_version":"edge-lab-recorder.raw.v1","sequence":null,"source":"clob_market_ws"}
{"event_at":"2026-07-28T03:08:07.386000Z","event_fingerprint":"d3d74940cc1708239d21d2011233e9d5a86ce54451a890c8bf86f4103517359b","payload":{"connection_id":"a6b55582af5f430fb37ad02bf0922475","event_at":"2026-07-28T03:08:07.386000Z","event_type":"price_change","frame_hash":"f1f4cfcc08cfbd3da04fa1c711ef6884e8035a0404e564a6bffbfe13605a004b","frame_index":0,"kind":"data","monotonic_ns":310070417776875,"payload":{"event_type":"price_change","market":"0x779291bef19b6709f61e9764a954aafe9ffae488d50ae674aabdcb4f248006d5","price_changes":[{"asset_id":"14965588658799411272385430903075831224615961675357217884735713260981483529984","best_ask":"0.42","best_bid":"0.41","hash":"cfd8cc522d73bf891000a9175d5d059dbf79e01a","price":"0.31","side":"BUY","size":"164.71"},{"asset_id":"8761897749749422724209054078244794145777693856614463256546737399611489089783","best_ask":"0.59","best_bid":"0.58","hash":"5818c2fea28a81e3ba50c819194aeac6fa43a557","price":"0.69","side":"SELL","size":"164.71"}],"timestamp":"1785208087386"},"payload_hash":"2a0df614d9c94b0a883974ce7a175d926a17f9bf065867e7e2cf04dca1b1ae01","raw_frame":"{\"market\":\"0x779291bef19b6709f61e9764a954aafe9ffae488d50ae674aabdcb4f248006d5\", \"price_changes\":[{\"asset_id\":\"14965588658799411272385430903075831224615961675357217884735713260981483529984\", \"price\":\"0.31\", \"size\":\"164.71\", \"side\":\"BUY\", \"hash\":\"cfd8cc522d73bf891000a9175d5d059dbf79e01a\", \"best_bid\":\"0.41\", \"best_ask\":\"0.42\"}, {\"asset_id\":\"8761897749749422724209054078244794145777693856614463256546737399611489089783\", \"price\":\"0.69\", \"size\":\"164.71\", \"side\":\"SELL\", \"hash\":\"5818c2fea28a81e3ba50c819194aeac6fa43a557\", \"best_bid\":\"0.58\", \"best_ask\":\"0.59\"}], \"timestamp\":\"1785208087386\", \"event_type\":\"price_change\"}","received_at":"2026-07-28T03:08:07.385443Z","schema_version":"clob-market-ws.price_change.v1","sequence":null,"server_hash":null,"server_timestamp":"1785208087386","session_id":"3e519d9098404c15b234d96025eb1a2b","source":"clob_market_ws"},"received_at":"2026-07-28T03:08:07.385443Z","record_id":"d8d457123901e2e44377004e3c69ddad982a3a385abcec1433bc019a8be1bb02","schema_fingerprint":"4aa3821a28b0b7c2400bc59aba4bcc0a76e971dadd19610d3ad38c768e124dc7","schema_version":"edge-lab-recorder.raw.v1","sequence":null,"source":"clob_market_ws"}
{"event_at":"2026-07-28T03:08:07.387000Z","event_fingerprint":"c015592fb51572b844e61f4fe1eab2f8af4899b67577ec0ba505ed91e8ee3b36","payload":{"connection_id":"a6b55582af5f430fb37ad02bf0922475","event_at":"2026-07-28T03:08:07.387000Z","event_type":"price_change","frame_hash":"efb54349256c1cb6cfb6e53ebf6cdeec372a7fd98d766205820344cd82b64eb9","frame_index":0,"kind":"data","monotonic_ns":310070419302291,"payload":{"event_type":"price_change","market":"0x779291bef19b6709f61e9764a954aafe9ffae488d50ae674aabdcb4f248006d5","price_changes":[{"asset_id":"14965588658799411272385430903075831224615961675357217884735713260981483529984","best_ask":"0.42","best_bid":"0.41","hash":"013aff76789cb11ccedcebb3c794ba41f3ce744b","price":"0.3","side":"BUY","size":"209.23"},{"asset_id":"8761897749749422724209054078244794145777693856614463256546737399611489089783","best_ask":"0.59","best_bid":"0.58","hash":"58d8cd558d251bf1bc4941a286015670c4166732","price":"0.7","side":"SELL","size":"209.23"}],"timestamp":"1785208087387"},"payload_hash":"a24de352d3dc439037ba86e37558e1d077221c0beabd1376cb23a82931fcc92b","raw_frame":"{\"market\":\"0x779291bef19b6709f61e9764a954aafe9ffae488d50ae674aabdcb4f248006d5\", \"price_changes\":[{\"asset_id\":\"14965588658799411272385430903075831224615961675357217884735713260981483529984\", \"price\":\"0.3\", \"size\":\"209.23\", \"side\":\"BUY\", \"hash\":\"013aff76789cb11ccedcebb3c794ba41f3ce744b\", \"best_bid\":\"0.41\", \"best_ask\":\"0.42\"}, {\"asset_id\":\"8761897749749422724209054078244794145777693856614463256546737399611489089783\", \"price\":\"0.7\", \"size\":\"209.23\", \"side\":\"SELL\", \"hash\":\"58d8cd558d251bf1bc4941a286015670c4166732\", \"best_bid\":\"0.58\", \"best_ask\":\"0.59\"}], \"timestamp\":\"1785208087387\", \"event_type\":\"price_change\"}","received_at":"2026-07-28T03:08:07.386970Z","schema_version":"clob-market-ws.price_change.v1","sequence":null,"server_hash":null,"server_timestamp":"1785208087387","session_id":"3e519d9098404c15b234d96025eb1a2b","source":"clob_market_ws"},"received_at":"2026-07-28T03:08:07.386970Z","record_id":"1d27894f587799671b4f7d594c2ec252771b8ca5f0f4f205cc1ef3831f7e14f5","schema_fingerprint":"4aa3821a28b0b7c2400bc59aba4bcc0a76e971dadd19610d3ad38c768e124dc7","schema_version":"edge-lab-recorder.raw.v1","sequence":null,"source":"clob_market_ws"}
{"event_at":"2026-07-28T03:08:07.388000Z","event_fingerprint":"a444f6eb05e474839389997a1036c5891f469127e2b8faff87795a39a810686d","payload":{"connection_id":"a6b55582af5f430fb37ad02bf0922475","event_at":"2026-07-28T03:08:07.388000Z","event_type":"price_change","frame_hash":"289422e370d6c8f4c858e340f64c191cc993c64ea6c9822a77af7c571a4d8222","frame_index":0,"kind":"data","monotonic_ns":310070420866083,"payload":{"event_type":"price_change","market":"0x779291bef19b6709f61e9764a954aafe9ffae488d50ae674aabdcb4f248006d5","price_changes":[{"asset_id":"14965588658799411272385430903075831224615961675357217884735713260981483529984","best_ask":"0.42","best_bid":"0.41","hash":"67159078f3d1418fa0d76dd09bda157fbe22fe38","price":"0.41","side":"BUY","size":"531.2"},{"asset_id":"8761897749749422724209054078244794145777693856614463256546737399611489089783","best_ask":"0.59","best_bid":"0.58","hash":"1a5d2d4e87c777eaf621235515fca617eb9bb563","price":"0.59","side":"SELL","size":"531.2"}],"timestamp":"1785208087388"},"payload_hash":"26f3035535577f1fc1efef50e07c4113b7b1f54bedbffc2f82a857cc48e2bcd1","raw_frame":"{\"market\":\"0x779291bef19b6709f61e9764a954aafe9ffae488d50ae674aabdcb4f248006d5\", \"price_changes\":[{\"asset_id\":\"14965588658799411272385430903075831224615961675357217884735713260981483529984\", \"price\":\"0.41\", \"size\":\"531.2\", \"side\":\"BUY\", \"hash\":\"67159078f3d1418fa0d76dd09bda157fbe22fe38\", \"best_bid\":\"0.41\", \"best_ask\":\"0.42\"}, {\"asset_id\":\"8761897749749422724209054078244794145777693856614463256546737399611489089783\", \"price\":\"0.59\", \"size\":\"531.2\", \"side\":\"SELL\", \"hash\":\"1a5d2d4e87c777eaf621235515fca617eb9bb563\", \"best_bid\":\"0.58\", \"best_ask\":\"0.59\"}], \"timestamp\":\"1785208087388\", \"event_type\":\"price_change\"}","received_at":"2026-07-28T03:08:07.388532Z","schema_version":"clob-market-ws.price_change.v1","sequence":null,"server_hash":null,"server_timestamp":"1785208087388","session_id":"3e519d9098404c15b234d96025eb1a2b","source":"clob_market_ws"},"received_at":"2026-07-28T03:08:07.388532Z","record_id":"16e3f25e1dd50a6f7c17511e75105d25efde789a8907b700ca4ea649ec02acff","schema_fingerprint":"4aa3821a28b0b7c2400bc59aba4bcc0a76e971dadd19610d3ad38c768e124dc7","schema_version":"edge-lab-recorder.raw.v1","sequence":null,"source":"clob_market_ws"}
{"event_at":"2026-07-28T03:08:07.389000Z","event_fingerprint":"df4403b95857dbbea51f7d14e6af8ff37368445981fbcadc1083594af0214038","payload":{"connection_id":"a6b55582af5f430fb37ad02bf0922475","event_at":"2026-07-28T03:08:07.389000Z","event_type":"price_change","frame_hash":"dbb1240604720bab49b3bdb21408c5fd67e588096b6d5e6e7f8158356b39a777","frame_index":0,"kind":"data","monotonic_ns":310070422400708,"payload":{"event_type":"price_change","market":"0x779291bef19b6709f61e9764a954aafe9ffae488d50ae674aabdcb4f248006d5","price_changes":[{"asset_id":"14965588658799411272385430903075831224615961675357217884735713260981483529984","best_ask":"0.42","best_bid":"0.41","hash":"6208ca9a14b243b9ef608227928d54a196db5b00","price":"0.33","side":"BUY","size":"124.07"},{"asset_id":"8761897749749422724209054078244794145777693856614463256546737399611489089783","best_ask":"0.59","best_bid":"0.58","hash":"5313371fd468bbf9ed32c1866f251a5e51bf36fc","price":"0.67","side":"SELL","size":"124.07"}],"timestamp":"1785208087389"},"payload_hash":"e9bb8779877a2db215a5268e8c764da9d093045d476a507117735e97a5d14e10","raw_frame":"{\"market\":\"0x779291bef19b6709f61e9764a954aafe9ffae488d50ae674aabdcb4f248006d5\", \"price_changes\":[{\"asset_id\":\"14965588658799411272385430903075831224615961675357217884735713260981483529984\", \"price\":\"0.33\", \"size\":\"124.07\", \"side\":\"BUY\", \"hash\":\"6208ca9a14b243b9ef608227928d54a196db5b00\", \"best_bid\":\"0.41\", \"best_ask\":\"0.42\"}, {\"asset_id\":\"8761897749749422724209054078244794145777693856614463256546737399611489089783\", \"price\":\"0.67\", \"size\":\"124.07\", \"side\":\"SELL\", \"hash\":\"5313371fd468bbf9ed32c1866f251a5e51bf36fc\", \"best_bid\":\"0.58\", \"best_ask\":\"0.59\"}], \"timestamp\":\"1785208087389\", \"event_type\":\"price_change\"}","received_at":"2026-07-28T03:08:07.390067Z","schema_version":"clob-market-ws.price_change.v1","sequence":null,"server_hash":null,"server_timestamp":"1785208087389","session_id":"3e519d9098404c15b234d96025eb1a2b","source":"clob_market_ws"},"received_at":"2026-07-28T03:08:07.390067Z","record_id":"5455bac5bc5b404c972468c9ef78c458b3221c6a6b91da90505af6c4afe85429","schema_fingerprint":"4aa3821a28b0b7c2400bc59aba4bcc0a76e971dadd19610d3ad38c768e124dc7","schema_version":"edge-lab-recorder.raw.v1","sequence":null,"source":"clob_market_ws"}
{"event_at":"2026-07-28T03:08:07.390000Z","event_fingerprint":"97178fc80bd458dff296dee2dee357d81e8ec46f1d20d89cd6a6d86995b19422","payload":{"connection_id":"a6b55582af5f430fb37ad02bf0922475","event_at":"2026-07-28T03:08:07.390000Z","event_type":"price_change","frame_hash":"43680bdb4bb747a42583d391b559694c958bae8c62b235af272ddae43fb55769","frame_index":0,"kind":"data","monotonic_ns":310070423885833,"payload":{"event_type":"price_change","market":"0x779291bef19b6709f61e9764a954aafe9ffae488d50ae674aabdcb4f248006d5","price_changes":[{"asset_id":"8761897749749422724209054078244794145777693856614463256546737399611489089783","best_ask":"0.59","best_bid":"0.58","hash":"69c7cda69dba512a37ef8e527b24619f96228521","price":"0.52","side":"BUY","size":"41"},{"asset_id":"14965588658799411272385430903075831224615961675357217884735713260981483529984","best_ask":"0.42","best_bid":"0.41","hash":"5b394ef56fa05b1f2b2d4d6394354a83f66f4350","price":"0.48","side":"SELL","size":"41"}],"timestamp":"1785208087390"},"payload_hash":"db7e9ea791ff82f8b8d60306bab0e94dd03c211b91ce4b253838c8bb29b57d77","raw_frame":"{\"market\":\"0x779291bef19b6709f61e9764a954aafe9ffae488d50ae674aabdcb4f248006d5\", \"price_changes\":[{\"asset_id\":\"8761897749749422724209054078244794145777693856614463256546737399611489089783\", \"price\":\"0.52\", \"size\":\"41\", \"side\":\"BUY\", \"hash\":\"69c7cda69dba512a37ef8e527b24619f96228521\", \"best_bid\":\"0.58\", \"best_ask\":\"0.59\"}, {\"asset_id\":\"14965588658799411272385430903075831224615961675357217884735713260981483529984\", \"price\":\"0.48\", \"size\":\"41\", \"side\":\"SELL\", \"hash\":\"5b394ef56fa05b1f2b2d4d6394354a83f66f4350\", \"best_bid\":\"0.41\", \"best_ask\":\"0.42\"}], \"timestamp\":\"1785208087390\", \"event_type\":\"price_change\"}","received_at":"2026-07-28T03:08:07.391552Z","schema_version":"clob-market-ws.price_change.v1","sequence":null,"server_hash":null,"server_timestamp":"1785208087390","session_id":"3e519d9098404c15b234d96025eb1a2b","source":"clob_market_ws"},"received_at":"2026-07-28T03:08:07.391552Z","record_id":"dedff7de0a314b6ae0f60899c44012c2160ff88e657c7462f31d6bab3d59a6df","schema_fingerprint":"4aa3821a28b0b7c2400bc59aba4bcc0a76e971dadd19610d3ad38c768e124dc7","schema_version":"edge-lab-recorder.raw.v1","sequence":null,"source":"clob_market_ws"}
{"event_at":"2026-07-28T03:08:07.390000Z","event_fingerprint":"c9e21dcd27d5a47dfef51543649df4e90346e0f0232e872b996031d5b61ba209","payload":{"connection_id":"a6b55582af5f430fb37ad02bf0922475","event_at":"2026-07-28T03:08:07.390000Z","event_type":"price_change","frame_hash":"7ef2cbca55e77c7a312a0ab5cc8b5e89fe7e15582f5a68258ae0a0690669d68f","frame_index":0,"kind":"data","monotonic_ns":310070425427625,"payload":{"event_type":"price_change","market":"0x779291bef19b6709f61e9764a954aafe9ffae488d50ae674aabdcb4f248006d5","price_changes":[{"asset_id":"14965588658799411272385430903075831224615961675357217884735713260981483529984","best_ask":"0.42","best_bid":"0.41","hash":"a089b7d0312e99952863804ead8817e56bb38b48","price":"0.29","side":"BUY","size":"156.6"},{"asset_id":"8761897749749422724209054078244794145777693856614463256546737399611489089783","best_ask":"0.59","best_bid":"0.58","hash":"8a36ac723e08f3c3cdef37bcf2ea7185d01dafc6","price":"0.71","side":"SELL","size":"156.6"}],"timestamp":"1785208087390"},"payload_hash":"7af6ceec67d97799bf641c54d396e1674c60c0b583b4b5fdb13fb4bd2bc8fc28","raw_frame":"{\"market\":\"0x779291bef19b6709f61e9764a954aafe9ffae488d50ae674aabdcb4f248006d5\", \"price_changes\":[{\"asset_id\":\"14965588658799411272385430903075831224615961675357217884735713260981483529984\", \"price\":\"0.29\", \"size\":\"156.6\", \"side\":\"BUY\", \"hash\":\"a089b7d0312e99952863804ead8817e56bb38b48\", \"best_bid\":\"0.41\", \"best_ask\":\"0.42\"}, {\"asset_id\":\"8761897749749422724209054078244794145777693856614463256546737399611489089783\", \"price\":\"0.71\", \"size\":\"156.6\", \"side\":\"SELL\", \"hash\":\"8a36ac723e08f3c3cdef37bcf2ea7185d01dafc6\", \"best_bid\":\"0.58\", \"best_ask\":\"0.59\"}], \"timestamp\":\"1785208087390\", \"event_type\":\"price_change\"}","received_at":"2026-07-28T03:08:07.393094Z","schema_version":"clob-market-ws.price_change.v1","sequence":null,"server_hash":null,"server_timestamp":"1785208087390","session_id":"3e519d9098404c15b234d96025eb1a2b","source":"clob_market_ws"},"received_at":"2026-07-28T03:08:07.393094Z","record_id":"28c4760a1825ee2c5d225047da06c8f00bcca0e4fc80c541552e0dd15713960b","schema_fingerprint":"4aa3821a28b0b7c2400bc59aba4bcc0a76e971dadd19610d3ad38c768e124dc7","schema_version":"edge-lab-recorder.raw.v1","sequence":null,"source":"clob_market_ws"}
{"event_at":"2026-07-28T03:08:07.391000Z","event_fingerprint":"c20aa724404f975594f24fbe6c583947ccfbbfaa6d6a846e4e8e503020d3bcc5","payload":{"connection_id":"a6b55582af5f430fb37ad02bf0922475","event_at":"2026-07-28T03:08:07.391000Z","event_type":"price_change","frame_hash":"e582b475a91cb74ce5230cd6acae818e745d8cf1a24973fabca55050fa8fafb2","frame_index":0,"kind":"data","monotonic_ns":310070426893291,"payload":{"event_type":"price_change","market":"0x779291bef19b6709f61e9764a954aafe9ffae488d50ae674aabdcb4f248006d5","price_changes":[{"asset_id":"8761897749749422724209054078244794145777693856614463256546737399611489089783","best_ask":"0.59","best_bid":"0.58","hash":"9dadd938273538639deea0b6573847a37152dee8","price":"0.49","side":"BUY","size":"194.5"},{"asset_id":"14965588658799411272385430903075831224615961675357217884735713260981483529984","best_ask":"0.42","best_bid":"0.41","hash":"9cb37c5a00a5b9c1fce0260adf50b00b65c91ac5","price":"0.51","side":"SELL","size":"194.5"}],"timestamp":"1785208087391"},"payload_hash":"e778930562af0123a7b7d61fb08849b92c6399b89760bbcced3395f5d79e42f6","raw_frame":"{\"market\":\"0x779291bef19b6709f61e9764a954aafe9ffae488d50ae674aabdcb4f248006d5\", \"price_changes\":[{\"asset_id\":\"8761897749749422724209054078244794145777693856614463256546737399611489089783\", \"price\":\"0.49\", \"size\":\"194.5\", \"side\":\"BUY\", \"hash\":\"9dadd938273538639deea0b6573847a37152dee8\", \"best_bid\":\"0.58\", \"best_ask\":\"0.59\"}, {\"asset_id\":\"14965588658799411272385430903075831224615961675357217884735713260981483529984\", \"price\":\"0.51\", \"size\":\"194.5\", \"side\":\"SELL\", \"hash\":\"9cb37c5a00a5b9c1fce0260adf50b00b65c91ac5\", \"best_bid\":\"0.41\", \"best_ask\":\"0.42\"}], \"timestamp\":\"1785208087391\", \"event_type\":\"price_change\"}","received_at":"2026-07-28T03:08:07.394561Z","schema_version":"clob-market-ws.price_change.v1","sequence":null,"server_hash":null,"server_timestamp":"1785208087391","session_id":"3e519d9098404c15b234d96025eb1a2b","source":"clob_market_ws"},"received_at":"2026-07-28T03:08:07.394561Z","record_id":"c22e04063d2abe09b76c345c34a91f9ce21931bdf234f58d96e6d923519ac1ac","schema_fingerprint":"4aa3821a28b0b7c2400bc59aba4bcc0a76e971dadd19610d3ad38c768e124dc7","schema_version":"edge-lab-recorder.raw.v1","sequence":null,"source":"clob_market_ws"}
{"event_at":"2026-07-28T03:08:07.391000Z","event_fingerprint":"520cb48ed3d79c3ca583d4642c17ca898fc203fc2b5f4d59c1cb4d4e46f09873","payload":{"connection_id":"a6b55582af5f430fb37ad02bf0922475","event_at":"2026-07-28T03:08:07.391000Z","event_type":"price_change","frame_hash":"1a711b6a86074dd035565bf6b0b287436783f0da04d1d341d03e26a4990ca968","frame_index":0,"kind":"data","monotonic_ns":310070428360166,"payload":{"event_type":"price_change","market":"0x779291bef19b6709f61e9764a954aafe9ffae488d50ae674aabdcb4f248006d5","price_changes":[{"asset_id":"8761897749749422724209054078244794145777693856614463256546737399611489089783","best_ask":"0.59","best_bid":"0.58","hash":"76a6d115a9c3257e79f8ca80f630b5282dd12728","price":"0.52","side":"BUY","size":"31"},{"asset_id":"14965588658799411272385430903075831224615961675357217884735713260981483529984","best_ask":"0.42","best_bid":"0.41","hash":"b1d323a82738cb079c1f7eac504e2b59c8c839f7","price":"0.48","side":"SELL","size":"31"}],"timestamp":"1785208087391"},"payload_hash":"9397cacc641015216e2ee7fd1626e6268a94d6f0e540494307418ea403bacbe9","raw_frame":"{\"market\":\"0x779291bef19b6709f61e9764a954aafe9ffae488d50ae674aabdcb4f248006d5\", \"price_changes\":[{\"asset_id\":\"8761897749749422724209054078244794145777693856614463256546737399611489089783\", \"price\":\"0.52\", \"size\":\"31\", \"side\":\"BUY\", \"hash\":\"76a6d115a9c3257e79f8ca80f630b5282dd12728\", \"best_bid\":\"0.58\", \"best_ask\":\"0.59\"}, {\"asset_id\":\"14965588658799411272385430903075831224615961675357217884735713260981483529984\", \"price\":\"0.48\", \"size\":\"31\", \"side\":\"SELL\", \"hash\":\"b1d323a82738cb079c1f7eac504e2b59c8c839f7\", \"best_bid\":\"0.41\", \"best_ask\":\"0.42\"}], \"timestamp\":\"1785208087391\", \"event_type\":\"price_change\"}","received_at":"2026-07-28T03:08:07.396028Z","schema_version":"clob-market-ws.price_change.v1","sequence":null,"server_hash":null,"server_timestamp":"1785208087391","session_id":"3e519d9098404c15b234d96025eb1a2b","source":"clob_market_ws"},"received_at":"2026-07-28T03:08:07.396028Z","record_id":"ec58929577f534c1a57a9dd2f5d4ead7c0bf9be1f8fdd57485efaedb3e22dda9","schema_fingerprint":"4aa3821a28b0b7c2400bc59aba4bcc0a76e971dadd19610d3ad38c768e124dc7","schema_version":"edge-lab-recorder.raw.v1","sequence":null,"source":"clob_market_ws"}
{"event_at":"2026-07-28T03:08:07.391000Z","event_fingerprint":"b2d5f9a41e2fbae191b77706d3893ae07332716aa556b3121ef18957ff1d4efc","payload":{"connection_id":"a6b55582af5f430fb37ad02bf0922475","event_at":"2026-07-28T03:08:07.391000Z","event_type":"price_change","frame_hash":"bd1ace7aebccb2f07f6e6449066600f59625a3c82a00d4a7a8d53ee55f336a94","frame_index":0,"kind":"data","monotonic_ns":310070429895791,"payload":{"event_type":"price_change","market":"0x779291bef19b6709f61e9764a954aafe9ffae488d50ae674aabdcb4f248006d5","price_changes":[{"asset_id":"14965588658799411272385430903075831224615961675357217884735713260981483529984","best_ask":"0.42","best_bid":"0.41","hash":"c3010a676835ee81b1e414cccd7d66b53dfa08c1","price":"0.3","side":"BUY","size":"179.23"},{"asset_id":"8761897749749422724209054078244794145777693856614463256546737399611489089783","best_ask":"0.59","best_bid":"0.58","hash":"0ceebbc5702b2adad2eb53a30790cb945283aba0","price":"0.7","side":"SELL","size":"179.23"}],"timestamp":"1785208087391"},"payload_hash":"954cf403c7b822c38bd1de9c2ad27c9f1a6497718954e16ea558b1269bde5860","raw_frame":"{\"market\":\"0x779291bef19b6709f61e9764a954aafe9ffae488d50ae674aabdcb4f248006d5\", \"price_changes\":[{\"asset_id\":\"14965588658799411272385430903075831224615961675357217884735713260981483529984\", \"price\":\"0.3\", \"size\":\"179.23\", \"side\":\"BUY\", \"hash\":\"c3010a676835ee81b1e414cccd7d66b53dfa08c1\", \"best_bid\":\"0.41\", \"best_ask\":\"0.42\"}, {\"asset_id\":\"8761897749749422724209054078244794145777693856614463256546737399611489089783\", \"price\":\"0.7\", \"size\":\"179.23\", \"side\":\"SELL\", \"hash\":\"0ceebbc5702b2adad2eb53a30790cb945283aba0\", \"best_bid\":\"0.58\", \"best_ask\":\"0.59\"}], \"timestamp\":\"1785208087391\", \"event_type\":\"price_change\"}","received_at":"2026-07-28T03:08:07.397563Z","schema_version":"clob-market-ws.price_change.v1","sequence":null,"server_hash":null,"server_timestamp":"1785208087391","session_id":"3e519d9098404c15b234d96025eb1a2b","source":"clob_market_ws"},"received_at":"2026-07-28T03:08:07.397563Z","record_id":"99a0ec015c4d50f1179d4cc48a7d4ba833675dc0ea33b8399157287fc5a3b534","schema_fingerprint":"4aa3821a28b0b7c2400bc59aba4bcc0a76e971dadd19610d3ad38c768e124dc7","schema_version":"edge-lab-recorder.raw.v1","sequence":null,"source":"clob_market_ws"}
{"event_at":"2026-07-28T03:08:07.392000Z","event_fingerprint":"82d3946725259d79037d617332e1438b72b36acc119136479980853509a244e4","payload":{"connection_id":"a6b55582af5f430fb37ad02bf0922475","event_at":"2026-07-28T03:08:07.392000Z","event_type":"price_change","frame_hash":"f89d0a021957dd20d53baa56467e6d0d2ff7058b780f1915eae2b70224f1cac2","frame_index":0,"kind":"data","monotonic_ns":310070431709458,"payload":{"event_type":"price_change","market":"0x779291bef19b6709f61e9764a954aafe9ffae488d50ae674aabdcb4f248006d5","price_changes":[{"asset_id":"14965588658799411272385430903075831224615961675357217884735713260981483529984","best_ask":"0.42","best_bid":"0.41","hash":"fea0e518fe1f884cba56dd49f33778a1aa3059c5","price":"0.29","side":"BUY","size":"126.6"},{"asset_id":"8761897749749422724209054078244794145777693856614463256546737399611489089783","best_ask":"0.59","best_bid":"0.58","hash":"76e491d9df34cc6528c5274989610b1fce194161","price":"0.71","side":"SELL","size":"126.6"}],"timestamp":"1785208087392"},"payload_hash":"32c8cfe2c310d287dc4ca6ddc7a4a453061e3f3562ec1b04bdeeaf67588ad266","raw_frame":"{\"market\":\"0x779291bef19b6709f61e9764a954aafe9ffae488d50ae674aabdcb4f248006d5\", \"price_changes\":[{\"asset_id\":\"14965588658799411272385430903075831224615961675357217884735713260981483529984\", \"price\":\"0.29\", \"size\":\"126.6\", \"side\":\"BUY\", \"hash\":\"fea0e518fe1f884cba56dd49f33778a1aa3059c5\", \"best_bid\":\"0.41\", \"best_ask\":\"0.42\"}, {\"asset_id\":\"8761897749749422724209054078244794145777693856614463256546737399611489089783\", \"price\":\"0.71\", \"size\":\"126.6\", \"side\":\"SELL\", \"hash\":\"76e491d9df34cc6528c5274989610b1fce194161\", \"best_bid\":\"0.58\", \"best_ask\":\"0.59\"}], \"timestamp\":\"1785208087392\", \"event_type\":\"price_change\"}","received_at":"2026-07-28T03:08:07.399375Z","schema_version":"clob-market-ws.price_change.v1","sequence":null,"server_hash":null,"server_timestamp":"1785208087392","session_id":"3e519d9098404c15b234d96025eb1a2b","source":"clob_market_ws"},"received_at":"2026-07-28T03:08:07.399375Z","record_id":"680441274f81db44d40305deac80579c5618fd5154792a8e910d80580afb71e8","schema_fingerprint":"4aa3821a28b0b7c2400bc59aba4bcc0a76e971dadd19610d3ad38c768e124dc7","schema_version":"edge-lab-recorder.raw.v1","sequence":null,"source":"clob_market_ws"}
{"event_at":"2026-07-28T03:08:07.395000Z","event_fingerprint":"a2055c44f8338614983da9f9c973360ba3b0ee9cff58e9f2b96c4a6eeb658d7a","payload":{"connection_id":"a6b55582af5f430fb37ad02bf0922475","event_at":"2026-07-28T03:08:07.395000Z","event_type":"price_change","frame_hash":"776f16fa7c6934fd600f8aef47c19a16e85c204b13dfc2ba962b17ed3bc10302","frame_index":0,"kind":"data","monotonic_ns":310070433266208,"payload":{"event_type":"price_change","market":"0x779291bef19b6709f61e9764a954aafe9ffae488d50ae674aabdcb4f248006d5","price_changes":[{"asset_id":"8761897749749422724209054078244794145777693856614463256546737399611489089783","best_ask":"0.59","best_bid":"0.58","hash":"2cf797a3d3cf494e583563bfb4603b8e019d1bd1","price":"0.44","side":"BUY","size":"85"},{"asset_id":"14965588658799411272385430903075831224615961675357217884735713260981483529984","best_ask":"0.42","best_bid":"0.41","hash":"62e066d5b1e001aee45228f21d99cb922bfbe266","price":"0.56","side":"SELL","size":"85"}],"timestamp":"1785208087395"},"payload_hash":"2e8c9173401ec4396ed95b9bb838e6a92c8cf07b1f0714e51f44780f113b3ccf","raw_frame":"{\"market\":\"0x779291bef19b6709f61e9764a954aafe9ffae488d50ae674aabdcb4f248006d5\", \"price_changes\":[{\"asset_id\":\"8761897749749422724209054078244794145777693856614463256546737399611489089783\", \"price\":\"0.44\", \"size\":\"85\", \"side\":\"BUY\", \"hash\":\"2cf797a3d3cf494e583563bfb4603b8e019d1bd1\", \"best_bid\":\"0.58\", \"best_ask\":\"0.59\"}, {\"asset_id\":\"14965588658799411272385430903075831224615961675357217884735713260981483529984\", \"price\":\"0.56\", \"size\":\"85\", \"side\":\"SELL\", \"hash\":\"62e066d5b1e001aee45228f21d99cb922bfbe266\", \"best_bid\":\"0.41\", \"best_ask\":\"0.42\"}], \"timestamp\":\"1785208087395\", \"event_type\":\"price_change\"}","received_at":"2026-07-28T03:08:07.400932Z","schema_version":"clob-market-ws.price_change.v1","sequence":null,"server_hash":null,"server_timestamp":"1785208087395","session_id":"3e519d9098404c15b234d96025eb1a2b","source":"clob_market_ws"},"received_at":"2026-07-28T03:08:07.400932Z","record_id":"2b8b686083a24def19e698854e0a228366d6e0c63ab67069c9faa78e9334b9ff","schema_fingerprint":"4aa3821a28b0b7c2400bc59aba4bcc0a76e971dadd19610d3ad38c768e124dc7","schema_version":"edge-lab-recorder.raw.v1","sequence":null,"source":"clob_market_ws"}
{"event_at":"2026-07-28T03:08:07.396000Z","event_fingerprint":"b66654b513c020244a1868c5c58b49fb74a699c647f0c499cd3e64d28b0c685d","payload":{"connection_id":"a6b55582af5f430fb37ad02bf0922475","event_at":"2026-07-28T03:08:07.396000Z","event_type":"price_change","frame_hash":"ecc472d92df658ba685c0e5ef0bd6b4ae83ddfffcaf03d1104e1aeba793ef5c7","frame_index":0,"kind":"data","monotonic_ns":310070434812666,"payload":{"event_type":"price_change","market":"0x779291bef19b6709f61e9764a954aafe9ffae488d50ae674aabdcb4f248006d5","price_changes":[{"asset_id":"8761897749749422724209054078244794145777693856614463256546737399611489089783","best_ask":"0.59","best_bid":"0.58","hash":"a5ffd52a0930080e1d179d0ca41612ae8d9a5c67","price":"0.51","side":"BUY","size":"47"},{"asset_id":"14965588658799411272385430903075831224615961675357217884735713260981483529984","best_ask":"0.42","best_bid":"0.41","hash":"20c0d6681ac5e2bf7794f857ed6f3a5089a031d5","price":"0.49","side":"SELL","size":"47"}],"timestamp":"1785208087396"},"payload_hash":"88a7dacad94da3505052a17e06cb2176704b319b863297840e4279709819bad7","raw_frame":"{\"market\":\"0x779291bef19b6709f61e9764a954aafe9ffae488d50ae674aabdcb4f248006d5\", \"price_changes\":[{\"asset_id\":\"8761897749749422724209054078244794145777693856614463256546737399611489089783\", \"price\":\"0.51\", \"size\":\"47\", \"side\":\"BUY\", \"hash\":\"a5ffd52a0930080e1d179d0ca41612ae8d9a5c67\", \"best_bid\":\"0.58\", \"best_ask\":\"0.59\"}, {\"asset_id\":\"14965588658799411272385430903075831224615961675357217884735713260981483529984\", \"price\":\"0.49\", \"size\":\"47\", \"side\":\"SELL\", \"hash\":\"20c0d6681ac5e2bf7794f857ed6f3a5089a031d5\", \"best_bid\":\"0.41\", \"best_ask\":\"0.42\"}], \"timestamp\":\"1785208087396\", \"event_type\":\"price_change\"}","received_at":"2026-07-28T03:08:07.402478Z","schema_version":"clob-market-ws.price_change.v1","sequence":null,"server_hash":null,"server_timestamp":"1785208087396","session_id":"3e519d9098404c15b234d96025eb1a2b","source":"clob_market_ws"},"received_at":"2026-07-28T03:08:07.402478Z","record_id":"cee6be4299e57530f2425e716c87f5b46ca1e351f4706e7c410a9df8b20d31b2","schema_fingerprint":"4aa3821a28b0b7c2400bc59aba4bcc0a76e971dadd19610d3ad38c768e124dc7","schema_version":"edge-lab-recorder.raw.v1","sequence":null,"source":"clob_market_ws"}
{"event_at":"2026-07-28T03:08:07.397000Z","event_fingerprint":"096a1115d4b7f0b779eba5f9eefc614cb210080666e9d737aff19b61b1b6e8d8","payload":{"connection_id":"a6b55582af5f430fb37ad02bf0922475","event_at":"2026-07-28T03:08:07.397000Z","event_type":"price_change","frame_hash":"6d241d6e7b348abe8d48f6c6f993a98d0d0d1a7cda787544fe28f082d50534fe","frame_index":0,"kind":"data","monotonic_ns":310070436298875,"payload":{"event_type":"price_change","market":"0x779291bef19b6709f61e9764a954aafe9ffae488d50ae674aabdcb4f248006d5","price_changes":[{"asset_id":"8761897749749422724209054078244794145777693856614463256546737399611489089783","best_ask":"0.59","best_bid":"0.58","hash":"8bb2891e8b5517528cf95515b059668f59ab7b66","price":"0.46","side":"BUY","size":"82.98"},{"asset_id":"14965588658799411272385430903075831224615961675357217884735713260981483529984","best_ask":"0.42","best_bid":"0.41","hash":"bd766358eb444cf4ecd1d726eb43902eb7928248","price":"0.54","side":"SELL","size":"82.98"}],"timestamp":"1785208087397"},"payload_hash":"b42e437abdb06a2ab7bb79460182cb1eb8ab74f2400e562afe343c7b1656ff4e","raw_frame":"{\"market\":\"0x779291bef19b6709f61e9764a954aafe9ffae488d50ae674aabdcb4f248006d5\", \"price_changes\":[{\"asset_id\":\"8761897749749422724209054078244794145777693856614463256546737399611489089783\", \"price\":\"0.46\", \"size\":\"82.98\", \"side\":\"BUY\", \"hash\":\"8bb2891e8b5517528cf95515b059668f59ab7b66\", \"best_bid\":\"0.58\", \"best_ask\":\"0.59\"}, {\"asset_id\":\"14965588658799411272385430903075831224615961675357217884735713260981483529984\", \"price\":\"0.54\", \"size\":\"82.98\", \"side\":\"SELL\", \"hash\":\"bd766358eb444cf4ecd1d726eb43902eb7928248\", \"best_bid\":\"0.41\", \"best_ask\":\"0.42\"}], \"timestamp\":\"1785208087397\", \"event_type\":\"price_change\"}","received_at":"2026-07-28T03:08:07.403966Z","schema_version":"clob-market-ws.price_change.v1","sequence":null,"server_hash":null,"server_timestamp":"1785208087397","session_id":"3e519d9098404c15b234d96025eb1a2b","source":"clob_market_ws"},"received_at":"2026-07-28T03:08:07.403966Z","record_id":"da736f0a85698eb8c72e642a42b7268dee61ef9bdae39a8b7f0551ac95a25333","schema_fingerprint":"4aa3821a28b0b7c2400bc59aba4bcc0a76e971dadd19610d3ad38c768e124dc7","schema_version":"edge-lab-recorder.raw.v1","sequence":null,"source":"clob_market_ws"}
{"event_at":"2026-07-28T03:08:07.398000Z","event_fingerprint":"757a511eb04f6039eaf965c37c7e4c7035fd47cd31dad033c3d840ae1aad00dd","payload":{"connection_id":"a6b55582af5f430fb37ad02bf0922475","event_at":"2026-07-28T03:08:07.398000Z","event_type":"price_change","frame_hash":"ba4c494f5a50b9b681db3803882e18c78f0f1b0e8174a98d6a60b8ae92923e7b","frame_index":0,"kind":"data","monotonic_ns":310070437792000,"payload":{"event_type":"price_change","market":"0x779291bef19b6709f61e9764a954aafe9ffae488d50ae674aabdcb4f248006d5","price_changes":[{"asset_id":"14965588658799411272385430903075831224615961675357217884735713260981483529984","best_ask":"0.42","best_bid":"0.41","hash":"3ce29a65175fde84067bbe7a991fd11e1d7b7e42","price":"0.3","side":"BUY","size":"149.23"},{"asset_id":"8761897749749422724209054078244794145777693856614463256546737399611489089783","best_ask":"0.59","best_bid":"0.58","hash":"ea89cbe547ba871c88633a14a299993d733fbd58","price":"0.7","side":"SELL","size":"149.23"}],"timestamp":"1785208087398"},"payload_hash":"ee470d220d7d4bf21b92196c600faf3f3e42f86694ce09e09e9c00a3ee457566","raw_frame":"{\"market\":\"0x779291bef19b6709f61e9764a954aafe9ffae488d50ae674aabdcb4f248006d5\", \"price_changes\":[{\"asset_id\":\"14965588658799411272385430903075831224615961675357217884735713260981483529984\", \"price\":\"0.3\", \"size\":\"149.23\", \"side\":\"BUY\", \"hash\":\"3ce29a65175fde84067bbe7a991fd11e1d7b7e42\", \"best_bid\":\"0.41\", \"best_ask\":\"0.42\"}, {\"asset_id\":\"8761897749749422724209054078244794145777693856614463256546737399611489089783\", \"price\":\"0.7\", \"size\":\"149.23\", \"side\":\"SELL\", \"hash\":\"ea89cbe547ba871c88633a14a299993d733fbd58\", \"best_bid\":\"0.58\", \"best_ask\":\"0.59\"}], \"timestamp\":\"1785208087398\", \"event_type\":\"price_change\"}","received_at":"2026-07-28T03:08:07.405459Z","schema_version":"clob-market-ws.price_change.v1","sequence":null,"server_hash":null,"server_timestamp":"1785208087398","session_id":"3e519d9098404c15b234d96025eb1a2b","source":"clob_market_ws"},"received_at":"2026-07-28T03:08:07.405459Z","record_id":"ca0ad68e105ff1a07cec250937bbaf01b9f104dbbae1fbff3389622a70e18ccd","schema_fingerprint":"4aa3821a28b0b7c2400bc59aba4bcc0a76e971dadd19610d3ad38c768e124dc7","schema_version":"edge-lab-recorder.raw.v1","sequence":null,"source":"clob_market_ws"}
{"event_at":"2026-07-28T03:08:07.399000Z","event_fingerprint":"9f99b36aadc5fd04a25698bc7c2b6e34164905b840095ddffb8c6d3ed2bea60e","payload":{"connection_id":"a6b55582af5f430fb37ad02bf0922475","event_at":"2026-07-28T03:08:07.399000Z","event_type":"price_change","frame_hash":"89fc3b3d624f2bcac6378fa2d709795201855bf00164908901cf1fe7cf83f763","frame_index":0,"kind":"data","monotonic_ns":310070439261166,"payload":{"event_type":"price_change","market":"0x779291bef19b6709f61e9764a954aafe9ffae488d50ae674aabdcb4f248006d5","price_changes":[{"asset_id":"8761897749749422724209054078244794145777693856614463256546737399611489089783","best_ask":"0.59","best_bid":"0.58","hash":"42cbbf602515d49cee4cec86325d73fce44292a4","price":"0.45","side":"BUY","size":"122"},{"asset_id":"14965588658799411272385430903075831224615961675357217884735713260981483529984","best_ask":"0.42","best_bid":"0.41","hash":"3ac9063ed27a352b3b1c17f9ff006ee83cc2e261","price":"0.55","side":"SELL","size":"122"}],"timestamp":"1785208087399"},"payload_hash":"c2a73914d47deaf0dacdb3a6b14668dc6b2891f4cf7c576d7c280ce653718a5f","raw_frame":"{\"market\":\"0x779291bef19b6709f61e9764a954aafe9ffae488d50ae674aabdcb4f248006d5\", \"price_changes\":[{\"asset_id\":\"8761897749749422724209054078244794145777693856614463256546737399611489089783\", \"price\":\"0.45\", \"size\":\"122\", \"side\":\"BUY\", \"hash\":\"42cbbf602515d49cee4cec86325d73fce44292a4\", \"best_bid\":\"0.58\", \"best_ask\":\"0.59\"}, {\"asset_id\":\"14965588658799411272385430903075831224615961675357217884735713260981483529984\", \"price\":\"0.55\", \"size\":\"122\", \"side\":\"SELL\", \"hash\":\"3ac9063ed27a352b3b1c17f9ff006ee83cc2e261\", \"best_bid\":\"0.41\", \"best_ask\":\"0.42\"}], \"timestamp\":\"1785208087399\", \"event_type\":\"price_change\"}","received_at":"2026-07-28T03:08:07.406928Z","schema_version":"clob-market-ws.price_change.v1","sequence":null,"server_hash":null,"server_timestamp":"1785208087399","session_id":"3e519d9098404c15b234d96025eb1a2b","source":"clob_market_ws"},"received_at":"2026-07-28T03:08:07.406928Z","record_id":"dac129f4117e5d1e11414f91f240ff2c19bcb3dd1d7335d1c8b170bf795d0e1a","schema_fingerprint":"4aa3821a28b0b7c2400bc59aba4bcc0a76e971dadd19610d3ad38c768e124dc7","schema_version":"edge-lab-recorder.raw.v1","sequence":null,"source":"clob_market_ws"}
{"event_at":"2026-07-28T03:08:07.407000Z","event_fingerprint":"3abb6e83ec94af6a03e4231742d980d3620836f0633288c69a6da48a01069bcd","payload":{"connection_id":"a6b55582af5f430fb37ad02bf0922475","event_at":"2026-07-28T03:08:07.407000Z","event_type":"price_change","frame_hash":"687c226b966204685fa07f84de1d3266cd91f029b1f6d5fae9cf191962919017","frame_index":0,"kind":"data","monotonic_ns":310070440726625,"payload":{"event_type":"price_change","market":"0x779291bef19b6709f61e9764a954aafe9ffae488d50ae674aabdcb4f248006d5","price_changes":[{"asset_id":"14965588658799411272385430903075831224615961675357217884735713260981483529984","best_ask":"0.42","best_bid":"0.41","hash":"7e07482861649809cf93a0caf6195363a2607360","price":"0.35","side":"BUY","size":"138"},{"asset_id":"8761897749749422724209054078244794145777693856614463256546737399611489089783","best_ask":"0.59","best_bid":"0.58","hash":"cf8bac850ec6588899831a02828729321548a4e8","price":"0.65","side":"SELL","size":"138"}],"timestamp":"1785208087407"},"payload_hash":"01773df7a62d593efcf3fda95d03173ba7fd8cc27d6d850f05aea230c0b1989a","raw_frame":"{\"market\":\"0x779291bef19b6709f61e9764a954aafe9ffae488d50ae674aabdcb4f248006d5\", \"price_changes\":[{\"asset_id\":\"14965588658799411272385430903075831224615961675357217884735713260981483529984\", \"price\":\"0.35\", \"size\":\"138\", \"side\":\"BUY\", \"hash\":\"7e07482861649809cf93a0caf6195363a2607360\", \"best_bid\":\"0.41\", \"best_ask\":\"0.42\"}, {\"asset_id\":\"8761897749749422724209054078244794145777693856614463256546737399611489089783\", \"price\":\"0.65\", \"size\":\"138\", \"side\":\"SELL\", \"hash\":\"cf8bac850ec6588899831a02828729321548a4e8\", \"best_bid\":\"0.58\", \"best_ask\":\"0.59\"}], \"timestamp\":\"1785208087407\", \"event_type\":\"price_change\"}","received_at":"2026-07-28T03:08:07.408393Z","schema_version":"clob-market-ws.price_change.v1","sequence":null,"server_hash":null,"server_timestamp":"1785208087407","session_id":"3e519d9098404c15b234d96025eb1a2b","source":"clob_market_ws"},"received_at":"2026-07-28T03:08:07.408393Z","record_id":"02667382bb3fb6d016a76630345cd4f3f43a522a28f536d343ceed97f83a6081","schema_fingerprint":"4aa3821a28b0b7c2400bc59aba4bcc0a76e971dadd19610d3ad38c768e124dc7","schema_version":"edge-lab-recorder.raw.v1","sequence":null,"source":"clob_market_ws"}
{"event_at":"2026-07-28T03:08:07.408000Z","event_fingerprint":"0ab7f0ae40370812c25d90acd5a9dd11cf6abea0930a761ab074f8e469a96a1f","payload":{"connection_id":"a6b55582af5f430fb37ad02bf0922475","event_at":"2026-07-28T03:08:07.408000Z","event_type":"price_change","frame_hash":"ee1eb5f2346b38e8bdf4c11474d6a73120c9e9063fff3604d8fe208f1ef06b51","frame_index":0,"kind":"data","monotonic_ns":310070442292541,"payload":{"event_type":"price_change","market":"0x779291bef19b6709f61e9764a954aafe9ffae488d50ae674aabdcb4f248006d5","price_changes":[{"asset_id":"8761897749749422724209054078244794145777693856614463256546737399611489089783","best_ask":"0.59","best_bid":"0.58","hash":"a155c32780dc28899ea1de01a178fee6211987ab","price":"0.52","side":"BUY","size":"46"},{"asset_id":"14965588658799411272385430903075831224615961675357217884735713260981483529984","best_ask":"0.42","best_bid":"0.41","hash":"f54e3a2dfc2a8ce6b9e9221c5fe11b4354db19e6","price":"0.48","side":"SELL","size":"46"}],"timestamp":"1785208087408"},"payload_hash":"2a5a0f582ce858ba9869278749fa94c598aa8eb826a21e67bdfa7a44e18ccc94","raw_frame":"{\"market\":\"0x779291bef19b6709f61e9764a954aafe9ffae488d50ae674aabdcb4f248006d5\", \"price_changes\":[{\"asset_id\":\"8761897749749422724209054078244794145777693856614463256546737399611489089783\", \"price\":\"0.52\", \"size\":\"46\", \"side\":\"BUY\", \"hash\":\"a155c32780dc28899ea1de01a178fee6211987ab\", \"best_bid\":\"0.58\", \"best_ask\":\"0.59\"}, {\"asset_id\":\"14965588658799411272385430903075831224615961675357217884735713260981483529984\", \"price\":\"0.48\", \"size\":\"46\", \"side\":\"SELL\", \"hash\":\"f54e3a2dfc2a8ce6b9e9221c5fe11b4354db19e6\", \"best_bid\":\"0.41\", \"best_ask\":\"0.42\"}], \"timestamp\":\"1785208087408\", \"event_type\":\"price_change\"}","received_at":"2026-07-28T03:08:07.409956Z","schema_version":"clob-market-ws.price_change.v1","sequence":null,"server_hash":null,"server_timestamp":"1785208087408","session_id":"3e519d9098404c15b234d96025eb1a2b","source":"clob_market_ws"},"received_at":"2026-07-28T03:08:07.409956Z","record_id":"39b0b41ca6f39f8dc6a4ab9a2892bcda506281e4e54763c70429643594a34870","schema_fingerprint":"4aa3821a28b0b7c2400bc59aba4bcc0a76e971dadd19610d3ad38c768e124dc7","schema_version":"edge-lab-recorder.raw.v1","sequence":null,"source":"clob_market_ws"}
{"event_at":"2026-07-28T03:08:07.409000Z","event_fingerprint":"734606f58039d56d4d68bb157fbab9a8d69b68a0f918370b1ff6abee16ca2592","payload":{"connection_id":"a6b55582af5f430fb37ad02bf0922475","event_at":"2026-07-28T03:08:07.409000Z","event_type":"price_change","frame_hash":"604b73d5465b308e84e0c95b997576856ebf685fd45bf5e4d70d57a4a2ecef81","frame_index":0,"kind":"data","monotonic_ns":310070443917708,"payload":{"event_type":"price_change","market":"0x779291bef19b6709f61e9764a954aafe9ffae488d50ae674aabdcb4f248006d5","price_changes":[{"asset_id":"14965588658799411272385430903075831224615961675357217884735713260981483529984","best_ask":"0.42","best_bid":"0.41","hash":"d97aee15a9cec34de7d1190d39d2983425211dc0","price":"0.25","side":"BUY","size":"277"},{"asset_id":"8761897749749422724209054078244794145777693856614463256546737399611489089783","best_ask":"0.59","best_bid":"0.58","hash":"bcd5e9cc2da002a0108a532e083ed08a74d78e90","price":"0.75","side":"SELL","size":"277"}],"timestamp":"1785208087409"},"payload_hash":"eaf20613315c21bf9edb20c6900df631ee36fd4affeb2e4e7fcb3fe4ff9961f5","raw_frame":"{\"market\":\"0x779291bef19b6709f61e9764a954aafe9ffae488d50ae674aabdcb4f248006d5\", \"price_changes\":[{\"asset_id\":\"14965588658799411272385430903075831224615961675357217884735713260981483529984\", \"price\":\"0.25\", \"size\":\"277\", \"side\":\"BUY\", \"hash\":\"d97aee15a9cec34de7d1190d39d2983425211dc0\", \"best_bid\":\"0.41\", \"best_ask\":\"0.42\"}, {\"asset_id\":\"8761897749749422724209054078244794145777693856614463256546737399611489089783\", \"price\":\"0.75\", \"size\":\"277\", \"side\":\"SELL\", \"hash\":\"bcd5e9cc2da002a0108a532e083ed08a74d78e90\", \"best_bid\":\"0.58\", \"best_ask\":\"0.59\"}], \"timestamp\":\"1785208087409\", \"event_type\":\"price_change\"}","received_at":"2026-07-28T03:08:07.411584Z","schema_version":"clob-market-ws.price_change.v1","sequence":null,"server_hash":null,"server_timestamp":"1785208087409","session_id":"3e519d9098404c15b234d96025eb1a2b","source":"clob_market_ws"},"received_at":"2026-07-28T03:08:07.411584Z","record_id":"8845b67307158b33584fa7146999dd02eae8eba16bda119926424af16bc880c4","schema_fingerprint":"4aa3821a28b0b7c2400bc59aba4bcc0a76e971dadd19610d3ad38c768e124dc7","schema_version":"edge-lab-recorder.raw.v1","sequence":null,"source":"clob_market_ws"}
{"event_at":"2026-07-28T03:08:07.410000Z","event_fingerprint":"af7b453570223f9b95d4fe4b2f277c9b241770233257b249ce63294d211977d9","payload":{"connection_id":"a6b55582af5f430fb37ad02bf0922475","event_at":"2026-07-28T03:08:07.410000Z","event_type":"price_change","frame_hash":"91f4af0a53b11e522baa75ed624ffaa2763d8a9b0c82fa2b3a50004a3415cfd5","frame_index":0,"kind":"data","monotonic_ns":310070445437916,"payload":{"event_type":"price_change","market":"0x779291bef19b6709f61e9764a954aafe9ffae488d50ae674aabdcb4f248006d5","price_changes":[{"asset_id":"8761897749749422724209054078244794145777693856614463256546737399611489089783","best_ask":"0.59","best_bid":"0.58","hash":"5a6dd85e957bbb4ad09d9e5b1c0ad43c640556d8","price":"0.53","side":"BUY","size":"57"},{"asset_id":"14965588658799411272385430903075831224615961675357217884735713260981483529984","best_ask":"0.42","best_bid":"0.41","hash":"4ef1c393a2b217b11980f4122615f52e254db7a0","price":"0.47","side":"SELL","size":"57"}],"timestamp":"1785208087410"},"payload_hash":"4de0510ca316cc7106a384e39e84d5bdde8a00155a0a47d80019920dc7599366","raw_frame":"{\"market\":\"0x779291bef19b6709f61e9764a954aafe9ffae488d50ae674aabdcb4f248006d5\", \"price_changes\":[{\"asset_id\":\"8761897749749422724209054078244794145777693856614463256546737399611489089783\", \"price\":\"0.53\", \"size\":\"57\", \"side\":\"BUY\", \"hash\":\"5a6dd85e957bbb4ad09d9e5b1c0ad43c640556d8\", \"best_bid\":\"0.58\", \"best_ask\":\"0.59\"}, {\"asset_id\":\"14965588658799411272385430903075831224615961675357217884735713260981483529984\", \"price\":\"0.47\", \"size\":\"57\", \"side\":\"SELL\", \"hash\":\"4ef1c393a2b217b11980f4122615f52e254db7a0\", \"best_bid\":\"0.41\", \"best_ask\":\"0.42\"}], \"timestamp\":\"1785208087410\", \"event_type\":\"price_change\"}","received_at":"2026-07-28T03:08:07.413103Z","schema_version":"clob-market-ws.price_change.v1","sequence":null,"server_hash":null,"server_timestamp":"1785208087410","session_id":"3e519d9098404c15b234d96025eb1a2b","source":"clob_market_ws"},"received_at":"2026-07-28T03:08:07.413103Z","record_id":"dc28d5fb5bd200a7322f8e32a5d48b44fd3f07204ed0f08ace03e5a81c50be2e","schema_fingerprint":"4aa3821a28b0b7c2400bc59aba4bcc0a76e971dadd19610d3ad38c768e124dc7","schema_version":"edge-lab-recorder.raw.v1","sequence":null,"source":"clob_market_ws"}
{"event_at":"2026-07-28T03:08:07.412000Z","event_fingerprint":"583b69acc1010852b16274c0d8f6e7b68506e5e0f96bf7dedbee6e10f034e23c","payload":{"connection_id":"a6b55582af5f430fb37ad02bf0922475","event_at":"2026-07-28T03:08:07.412000Z","event_type":"price_change","frame_hash":"6696edea6127e4376f3f298b844e663f276cdf8a0658815460e2d2c411fad954","frame_index":0,"kind":"data","monotonic_ns":310070446942416,"payload":{"event_type":"price_change","market":"0x779291bef19b6709f61e9764a954aafe9ffae488d50ae674aabdcb4f248006d5","price_changes":[{"asset_id":"14965588658799411272385430903075831224615961675357217884735713260981483529984","best_ask":"0.42","best_bid":"0.41","hash":"0000e8118f08a789cc53a5715b0d5e9dc84dba43","price":"0.3","side":"BUY","size":"155.42"},{"asset_id":"8761897749749422724209054078244794145777693856614463256546737399611489089783","best_ask":"0.59","best_bid":"0.58","hash":"5bdc1368b327c5ae245c387735be43e10de9b215","price":"0.7","side":"SELL","size":"155.42"}],"timestamp":"1785208087412"},"payload_hash":"c395363810d80a0630ef7a72a1e2c651b47c6e7613e771721e2f3ef0f4a309c1","raw_frame":"{\"market\":\"0x779291bef19b6709f61e9764a954aafe9ffae488d50ae674aabdcb4f248006d5\", \"price_changes\":[{\"asset_id\":\"14965588658799411272385430903075831224615961675357217884735713260981483529984\", \"price\":\"0.3\", \"size\":\"155.42\", \"side\":\"BUY\", \"hash\":\"0000e8118f08a789cc53a5715b0d5e9dc84dba43\", \"best_bid\":\"0.41\", \"best_ask\":\"0.42\"}, {\"asset_id\":\"8761897749749422724209054078244794145777693856614463256546737399611489089783\", \"price\":\"0.7\", \"size\":\"155.42\", \"side\":\"SELL\", \"hash\":\"5bdc1368b327c5ae245c387735be43e10de9b215\", \"best_bid\":\"0.58\", \"best_ask\":\"0.59\"}], \"timestamp\":\"1785208087412\", \"event_type\":\"price_change\"}","received_at":"2026-07-28T03:08:07.414609Z","schema_version":"clob-market-ws.price_change.v1","sequence":null,"server_hash":null,"server_timestamp":"1785208087412","session_id":"3e519d9098404c15b234d96025eb1a2b","source":"clob_market_ws"},"received_at":"2026-07-28T03:08:07.414609Z","record_id":"e7d5da351162804f40b0957eb862280a2aa20af6c32e4e58c81f96ed3452774a","schema_fingerprint":"4aa3821a28b0b7c2400bc59aba4bcc0a76e971dadd19610d3ad38c768e124dc7","schema_version":"edge-lab-recorder.raw.v1","sequence":null,"source":"clob_market_ws"}
{"event_at":"2026-07-28T03:08:07.413000Z","event_fingerprint":"a8a1b395ea9dd97cf8ed0629112cd09794990c209379e9bc8620cd460adab14b","payload":{"connection_id":"a6b55582af5f430fb37ad02bf0922475","event_at":"2026-07-28T03:08:07.413000Z","event_type":"price_change","frame_hash":"96a9f2e066364f1e540257fa03e5c3b48effd8bd0c85dc291a947b16b0303f8a","frame_index":0,"kind":"data","monotonic_ns":310070448426625,"payload":{"event_type":"price_change","market":"0x779291bef19b6709f61e9764a954aafe9ffae488d50ae674aabdcb4f248006d5","price_changes":[{"asset_id":"8761897749749422724209054078244794145777693856614463256546737399611489089783","best_ask":"0.59","best_bid":"0.58","hash":"e2abbcb20ad5fa892a2c8f0bcbdc149a27b890d2","price":"0.49","side":"BUY","size":"209.5"},{"asset_id":"14965588658799411272385430903075831224615961675357217884735713260981483529984","best_ask":"0.42","best_bid":"0.41","hash":"40815940dea2ee902cc92802d7247da1577aaac7","price":"0.51","side":"SELL","size":"209.5"}],"timestamp":"1785208087413"},"payload_hash":"9feca6b1dec8b4025120e64dc82058ef495ce1e7d4c0a22e2d40e2c0803f3c68","raw_frame":"{\"market\":\"0x779291bef19b6709f61e9764a954aafe9ffae488d50ae674aabdcb4f248006d5\", \"price_changes\":[{\"asset_id\":\"8761897749749422724209054078244794145777693856614463256546737399611489089783\", \"price\":\"0.49\", \"size\":\"209.5\", \"side\":\"BUY\", \"hash\":\"e2abbcb20ad5fa892a2c8f0bcbdc149a27b890d2\", \"best_bid\":\"0.58\", \"best_ask\":\"0.59\"}, {\"asset_id\":\"14965588658799411272385430903075831224615961675357217884735713260981483529984\", \"price\":\"0.51\", \"size\":\"209.5\", \"side\":\"SELL\", \"hash\":\"40815940dea2ee902cc92802d7247da1577aaac7\", \"best_bid\":\"0.41\", \"best_ask\":\"0.42\"}], \"timestamp\":\"1785208087413\", \"event_type\":\"price_change\"}","received_at":"2026-07-28T03:08:07.416092Z","schema_version":"clob-market-ws.price_change.v1","sequence":null,"server_hash":null,"server_timestamp":"1785208087413","session_id":"3e519d9098404c15b234d96025eb1a2b","source":"clob_market_ws"},"received_at":"2026-07-28T03:08:07.416092Z","record_id":"72d207d79a4be654b0362355711ac31c0f66326f24f396ad0208b5290918accd","schema_fingerprint":"4aa3821a28b0b7c2400bc59aba4bcc0a76e971dadd19610d3ad38c768e124dc7","schema_version":"edge-lab-recorder.raw.v1","sequence":null,"source":"clob_market_ws"}
{"event_at":"2026-07-28T03:08:07.417000Z","event_fingerprint":"d625f6da79eebf8a79cae5887f122a0292daa470077445443694214684cdc442","payload":{"connection_id":"a6b55582af5f430fb37ad02bf0922475","event_at":"2026-07-28T03:08:07.417000Z","event_type":"price_change","frame_hash":"842eeba7eec313d1a2a1ffa7f693ba172eaa2948744ad481a784412def01d662","frame_index":0,"kind":"data","monotonic_ns":310070449943541,"payload":{"event_type":"price_change","market":"0x779291bef19b6709f61e9764a954aafe9ffae488d50ae674aabdcb4f248006d5","price_changes":[{"asset_id":"14965588658799411272385430903075831224615961675357217884735713260981483529984","best_ask":"0.42","best_bid":"0.41","hash":"5718207885a4568e8c25ceefcdf5b55108f9d8fc","price":"0.36","side":"BUY","size":"139.6"},{"asset_id":"8761897749749422724209054078244794145777693856614463256546737399611489089783","best_ask":"0.59","best_bid":"0.58","hash":"0acaf4b7bb93020ea7248ff5eecf98ca5e2bd3ab","price":"0.64","side":"SELL","size":"139.6"}],"timestamp":"1785208087417"},"payload_hash":"dbf35beb60af8405ebae4a08b4207392b4c1264759e96dc52acf78465b88830c","raw_frame":"{\"market\":\"0x779291bef19b6709f61e9764a954aafe9ffae488d50ae674aabdcb4f248006d5\", \"price_changes\":[{\"asset_id\":\"14965588658799411272385430903075831224615961675357217884735713260981483529984\", \"price\":\"0.36\", \"size\":\"139.6\", \"side\":\"BUY\", \"hash\":\"5718207885a4568e8c25ceefcdf5b55108f9d8fc\", \"best_bid\":\"0.41\", \"best_ask\":\"0.42\"}, {\"asset_id\":\"8761897749749422724209054078244794145777693856614463256546737399611489089783\", \"price\":\"0.64\", \"size\":\"139.6\", \"side\":\"SELL\", \"hash\":\"0acaf4b7bb93020ea7248ff5eecf98ca5e2bd3ab\", \"best_bid\":\"0.58\", \"best_ask\":\"0.59\"}], \"timestamp\":\"1785208087417\", \"event_type\":\"price_change\"}","received_at":"2026-07-28T03:08:07.417608Z","schema_version":"clob-market-ws.price_change.v1","sequence":null,"server_hash":null,"server_timestamp":"1785208087417","session_id":"3e519d9098404c15b234d96025eb1a2b","source":"clob_market_ws"},"received_at":"2026-07-28T03:08:07.417608Z","record_id":"ca49491257fc5a2be3c119a08d78db3312fddcbcbbc6e48f010bbe7025dad156","schema_fingerprint":"4aa3821a28b0b7c2400bc59aba4bcc0a76e971dadd19610d3ad38c768e124dc7","schema_version":"edge-lab-recorder.raw.v1","sequence":null,"source":"clob_market_ws"}
{"event_at":"2026-07-28T03:08:07.419000Z","event_fingerprint":"c0fa6a9f2c74ef52565582891171b0cafdaada52f390d18e28f79918044d45ca","payload":{"connection_id":"a6b55582af5f430fb37ad02bf0922475","event_at":"2026-07-28T03:08:07.419000Z","event_type":"price_change","frame_hash":"cff486d432b78305613850af910513bc2ff53d410710ef61368f556a3e410845","frame_index":0,"kind":"data","monotonic_ns":310070451481916,"payload":{"event_type":"price_change","market":"0x779291bef19b6709f61e9764a954aafe9ffae488d50ae674aabdcb4f248006d5","price_changes":[{"asset_id":"8761897749749422724209054078244794145777693856614463256546737399611489089783","best_ask":"0.59","best_bid":"0.58","hash":"4ab0be1283d9d593fcba497013f21d71a51b6a4c","price":"0.49","side":"BUY","size":"204.5"},{"asset_id":"14965588658799411272385430903075831224615961675357217884735713260981483529984","best_ask":"0.42","best_bid":"0.41","hash":"ba926f5fcfe8cf48807d5245db82b8a6e2ed918e","price":"0.51","side":"SELL","size":"204.5"}],"timestamp":"1785208087419"},"payload_hash":"c954b50fe0774e1d61522958514f3683ff49f46479e4d64b29ff4ea12aba10ba","raw_frame":"{\"market\":\"0x779291bef19b6709f61e9764a954aafe9ffae488d50ae674aabdcb4f248006d5\", \"price_changes\":[{\"asset_id\":\"8761897749749422724209054078244794145777693856614463256546737399611489089783\", \"price\":\"0.49\", \"size\":\"204.5\", \"side\":\"BUY\", \"hash\":\"4ab0be1283d9d593fcba497013f21d71a51b6a4c\", \"best_bid\":\"0.58\", \"best_ask\":\"0.59\"}, {\"asset_id\":\"14965588658799411272385430903075831224615961675357217884735713260981483529984\", \"price\":\"0.51\", \"size\":\"204.5\", \"side\":\"SELL\", \"hash\":\"ba926f5fcfe8cf48807d5245db82b8a6e2ed918e\", \"best_bid\":\"0.41\", \"best_ask\":\"0.42\"}], \"timestamp\":\"1785208087419\", \"event_type\":\"price_change\"}","received_at":"2026-07-28T03:08:07.419147Z","schema_version":"clob-market-ws.price_change.v1","sequence":null,"server_hash":null,"server_timestamp":"1785208087419","session_id":"3e519d9098404c15b234d96025eb1a2b","source":"clob_market_ws"},"received_at":"2026-07-28T03:08:07.419147Z","record_id":"95eb07d034871f32f623c7ec5c49d4dfa517b4ffacd7bf8c62f49a09871d3ac9","schema_fingerprint":"4aa3821a28b0b7c2400bc59aba4bcc0a76e971dadd19610d3ad38c768e124dc7","schema_version":"edge-lab-recorder.raw.v1","sequence":null,"source":"clob_market_ws"}
{"event_at":"2026-07-28T03:08:07.421000Z","event_fingerprint":"c72087a98d7316574924673581d234c15aad76dc982af52a166a81bdb25f50f5","payload":{"connection_id":"a6b55582af5f430fb37ad02bf0922475","event_at":"2026-07-28T03:08:07.421000Z","event_type":"price_change","frame_hash":"be7857790ba0130a865b124988a3effb4a0e71c0c189160b222babb7dd1dffd1","frame_index":0,"kind":"data","monotonic_ns":310070453065208,"payload":{"event_type":"price_change","market":"0x779291bef19b6709f61e9764a954aafe9ffae488d50ae674aabdcb4f248006d5","price_changes":[{"asset_id":"8761897749749422724209054078244794145777693856614463256546737399611489089783","best_ask":"0.59","best_bid":"0.58","hash":"5db8d68b59bdd85817105b55c2ecb2b58c567d7e","price":"0.46","side":"BUY","size":"87.98"},{"asset_id":"14965588658799411272385430903075831224615961675357217884735713260981483529984","best_ask":"0.42","best_bid":"0.41","hash":"a778ce7c5dedeffd9d66300a91e509180800d386","price":"0.54","side":"SELL","size":"87.98"}],"timestamp":"1785208087421"},"payload_hash":"cadff839bad86ab58b395388679e13d6ef04152cdfbd5522d0130dcf1e481f05","raw_frame":"{\"market\":\"0x779291bef19b6709f61e9764a954aafe9ffae488d50ae674aabdcb4f248006d5\", \"price_changes\":[{\"asset_id\":\"8761897749749422724209054078244794145777693856614463256546737399611489089783\", \"price\":\"0.46\", \"size\":\"87.98\", \"side\":\"BUY\", \"hash\":\"5db8d68b59bdd85817105b55c2ecb2b58c567d7e\", \"best_bid\":\"0.58\", \"best_ask\":\"0.59\"}, {\"asset_id\":\"14965588658799411272385430903075831224615961675357217884735713260981483529984\", \"price\":\"0.54\", \"size\":\"87.98\", \"side\":\"SELL\", \"hash\":\"a778ce7c5dedeffd9d66300a91e509180800d386\", \"best_bid\":\"0.41\", \"best_ask\":\"0.42\"}], \"timestamp\":\"1785208087421\", \"event_type\":\"price_change\"}","received_at":"2026-07-28T03:08:07.420728Z","schema_version":"clob-market-ws.price_change.v1","sequence":null,"server_hash":null,"server_timestamp":"1785208087421","session_id":"3e519d9098404c15b234d96025eb1a2b","source":"clob_market_ws"},"received_at":"2026-07-28T03:08:07.420728Z","record_id":"353246a602ddcb26b0b937a75b27f58441e4ec974f41d15e95eb275febef7e3c","schema_fingerprint":"4aa3821a28b0b7c2400bc59aba4bcc0a76e971dadd19610d3ad38c768e124dc7","schema_version":"edge-lab-recorder.raw.v1","sequence":null,"source":"clob_market_ws"}
{"event_at":"2026-07-28T03:08:07.422000Z","event_fingerprint":"6b8b38eaedbc3d5a19eb97177750b230c6b728bbc40c5f44243668a11d13f1e8","payload":{"connection_id":"a6b55582af5f430fb37ad02bf0922475","event_at":"2026-07-28T03:08:07.422000Z","event_type":"price_change","frame_hash":"2ec2e86e4af24900fc927d992ff16a7920c942f8c7c92435a26521899732c7d5","frame_index":0,"kind":"data","monotonic_ns":310070454711291,"payload":{"event_type":"price_change","market":"0x779291bef19b6709f61e9764a954aafe9ffae488d50ae674aabdcb4f248006d5","price_changes":[{"asset_id":"8761897749749422724209054078244794145777693856614463256546737399611489089783","best_ask":"0.59","best_bid":"0.58","hash":"bfc7a40d5f6a9a70fb65611bc8e65b33e6d98b7f","price":"0.44","side":"BUY","size":"90"},{"asset_id":"14965588658799411272385430903075831224615961675357217884735713260981483529984","best_ask":"0.42","best_bid":"0.41","hash":"3a44656302ea30ab5183a1fed6b3cccf9f187edf","price":"0.56","side":"SELL","size":"90"}],"timestamp":"1785208087422"},"payload_hash":"b9c13bd1b20900fa57bb15ad9ac5a1646b5a3ed1995ef40efe0f57f8cc3737b9","raw_frame":"{\"market\":\"0x779291bef19b6709f61e9764a954aafe9ffae488d50ae674aabdcb4f248006d5\", \"price_changes\":[{\"asset_id\":\"8761897749749422724209054078244794145777693856614463256546737399611489089783\", \"price\":\"0.44\", \"size\":\"90\", \"side\":\"BUY\", \"hash\":\"bfc7a40d5f6a9a70fb65611bc8e65b33e6d98b7f\", \"best_bid\":\"0.58\", \"best_ask\":\"0.59\"}, {\"asset_id\":\"14965588658799411272385430903075831224615961675357217884735713260981483529984\", \"price\":\"0.56\", \"size\":\"90\", \"side\":\"SELL\", \"hash\":\"3a44656302ea30ab5183a1fed6b3cccf9f187edf\", \"best_bid\":\"0.41\", \"best_ask\":\"0.42\"}], \"timestamp\":\"1785208087422\", \"event_type\":\"price_change\"}","received_at":"2026-07-28T03:08:07.422377Z","schema_version":"clob-market-ws.price_change.v1","sequence":null,"server_hash":null,"server_timestamp":"1785208087422","session_id":"3e519d9098404c15b234d96025eb1a2b","source":"clob_market_ws"},"received_at":"2026-07-28T03:08:07.422377Z","record_id":"9ed99d2c7fc009a78c4ccfcdd12b3e4742b1e9399e529fdb34ad4d62f80373e9","schema_fingerprint":"4aa3821a28b0b7c2400bc59aba4bcc0a76e971dadd19610d3ad38c768e124dc7","schema_version":"edge-lab-recorder.raw.v1","sequence":null,"source":"clob_market_ws"}
{"event_at":"2026-07-28T03:08:07.423000Z","event_fingerprint":"8d4552d800168d1e1216432ab5b9be2ea3d99e0e4d327789c5c5e7cafeb040bb","payload":{"connection_id":"a6b55582af5f430fb37ad02bf0922475","event_at":"2026-07-28T03:08:07.423000Z","event_type":"price_change","frame_hash":"41b6fd5078c00de9e665cd34204a23d17eb25bd9275577a140c8bf6f5bcf759e","frame_index":0,"kind":"data","monotonic_ns":310070456225583,"payload":{"event_type":"price_change","market":"0x779291bef19b6709f61e9764a954aafe9ffae488d50ae674aabdcb4f248006d5","price_changes":[{"asset_id":"14965588658799411272385430903075831224615961675357217884735713260981483529984","best_ask":"0.42","best_bid":"0.41","hash":"a6e2a8ba07092064166fee4156cb3888b8f9fd53","price":"0.36","side":"BUY","size":"169.6"},{"asset_id":"8761897749749422724209054078244794145777693856614463256546737399611489089783","best_ask":"0.59","best_bid":"0.58","hash":"7cda9a7ede287f25e83366845522599ec54677b0","price":"0.64","side":"SELL","size":"169.6"}],"timestamp":"1785208087423"},"payload_hash":"c9984b42eebccfe43cb4f803356a025fd85ac9a9727c4985966dbd378115d57d","raw_frame":"{\"market\":\"0x779291bef19b6709f61e9764a954aafe9ffae488d50ae674aabdcb4f248006d5\", \"price_changes\":[{\"asset_id\":\"14965588658799411272385430903075831224615961675357217884735713260981483529984\", \"price\":\"0.36\", \"size\":\"169.6\", \"side\":\"BUY\", \"hash\":\"a6e2a8ba07092064166fee4156cb3888b8f9fd53\", \"best_bid\":\"0.41\", \"best_ask\":\"0.42\"}, {\"asset_id\":\"8761897749749422724209054078244794145777693856614463256546737399611489089783\", \"price\":\"0.64\", \"size\":\"169.6\", \"side\":\"SELL\", \"hash\":\"7cda9a7ede287f25e83366845522599ec54677b0\", \"best_bid\":\"0.58\", \"best_ask\":\"0.59\"}], \"timestamp\":\"1785208087423\", \"event_type\":\"price_change\"}","received_at":"2026-07-28T03:08:07.423890Z","schema_version":"clob-market-ws.price_change.v1","sequence":null,"server_hash":null,"server_timestamp":"1785208087423","session_id":"3e519d9098404c15b234d96025eb1a2b","source":"clob_market_ws"},"received_at":"2026-07-28T03:08:07.423890Z","record_id":"a6fbedc5298fd32969c3c426525b7084e0e956a8575d1f469bf65b7524af0a11","schema_fingerprint":"4aa3821a28b0b7c2400bc59aba4bcc0a76e971dadd19610d3ad38c768e124dc7","schema_version":"edge-lab-recorder.raw.v1","sequence":null,"source":"clob_market_ws"}
{"event_at":"2026-07-28T03:08:07.425000Z","event_fingerprint":"5881629b650c78a94f67d6bf3aaef003af3bc2223bc07e6b17c1bb3b25c93b7c","payload":{"connection_id":"a6b55582af5f430fb37ad02bf0922475","event_at":"2026-07-28T03:08:07.425000Z","event_type":"price_change","frame_hash":"2afd17a19e2569a62cf12a542ff32d39ed19cd78d98b206b1f0fa050dd5fc3d2","frame_index":0,"kind":"data","monotonic_ns":310070457715000,"payload":{"event_type":"price_change","market":"0x779291bef19b6709f61e9764a954aafe9ffae488d50ae674aabdcb4f248006d5","price_changes":[{"asset_id":"8761897749749422724209054078244794145777693856614463256546737399611489089783","best_ask":"0.59","best_bid":"0.58","hash":"4259cbf67edcd50b54b8e659a1712a7fd5104484","price":"0.45","side":"BUY","size":"127"},{"asset_id":"14965588658799411272385430903075831224615961675357217884735713260981483529984","best_ask":"0.42","best_bid":"0.41","hash":"7ad3fdb88c1252886dbde02ff2e5855c66092438","price":"0.55","side":"SELL","size":"127"}],"timestamp":"1785208087425"},"payload_hash":"e24f1c6ba7494897dce857e74b0938e2e27810fe9f47b317f06c9b97d388b154","raw_frame":"{\"market\":\"0x779291bef19b6709f61e9764a954aafe9ffae488d50ae674aabdcb4f248006d5\", \"price_changes\":[{\"asset_id\":\"8761897749749422724209054078244794145777693856614463256546737399611489089783\", \"price\":\"0.45\", \"size\":\"127\", \"side\":\"BUY\", \"hash\":\"4259cbf67edcd50b54b8e659a1712a7fd5104484\", \"best_bid\":\"0.58\", \"best_ask\":\"0.59\"}, {\"asset_id\":\"14965588658799411272385430903075831224615961675357217884735713260981483529984\", \"price\":\"0.55\", \"size\":\"127\", \"side\":\"SELL\", \"hash\":\"7ad3fdb88c1252886dbde02ff2e5855c66092438\", \"best_bid\":\"0.41\", \"best_ask\":\"0.42\"}], \"timestamp\":\"1785208087425\", \"event_type\":\"price_change\"}","received_at":"2026-07-28T03:08:07.425382Z","schema_version":"clob-market-ws.price_change.v1","sequence":null,"server_hash":null,"server_timestamp":"1785208087425","session_id":"3e519d9098404c15b234d96025eb1a2b","source":"clob_market_ws"},"received_at":"2026-07-28T03:08:07.425382Z","record_id":"0b823ec84accd0143aae542da5f9b33d8d6ef80796f60f56b088d36355f1a44b","schema_fingerprint":"4aa3821a28b0b7c2400bc59aba4bcc0a76e971dadd19610d3ad38c768e124dc7","schema_version":"edge-lab-recorder.raw.v1","sequence":null,"source":"clob_market_ws"}
{"event_at":"2026-07-28T03:08:07.426000Z","event_fingerprint":"a951b4e52ea05a2d89d6be0bda0af77686feaa12b27ffd3b4b9b17769216a4ba","payload":{"connection_id":"a6b55582af5f430fb37ad02bf0922475","event_at":"2026-07-28T03:08:07.426000Z","event_type":"price_change","frame_hash":"e07cc0e547df7e1edc6d5c28d02e06a08a48244f0a58222be8d12ec39820afb7","frame_index":0,"kind":"data","monotonic_ns":310070459232750,"payload":{"event_type":"price_change","market":"0x779291bef19b6709f61e9764a954aafe9ffae488d50ae674aabdcb4f248006d5","price_changes":[{"asset_id":"14965588658799411272385430903075831224615961675357217884735713260981483529984","best_ask":"0.42","best_bid":"0.41","hash":"c1cecdfec2f393e70abdf40f96b8faa8dbf13e09","price":"0.31","side":"BUY","size":"204.71"},{"asset_id":"8761897749749422724209054078244794145777693856614463256546737399611489089783","best_ask":"0.59","best_bid":"0.58","hash":"061b522eaa972c740dff5d945edf845c129565d1","price":"0.69","side":"SELL","size":"204.71"}],"timestamp":"1785208087426"},"payload_hash":"4e9355983452b2fcaa751e8cc87c1ecc2e1b7740b3ae82edead774662ba7f031","raw_frame":"{\"market\":\"0x779291bef19b6709f61e9764a954aafe9ffae488d50ae674aabdcb4f248006d5\", \"price_changes\":[{\"asset_id\":\"14965588658799411272385430903075831224615961675357217884735713260981483529984\", \"price\":\"0.31\", \"size\":\"204.71\", \"side\":\"BUY\", \"hash\":\"c1cecdfec2f393e70abdf40f96b8faa8dbf13e09\", \"best_bid\":\"0.41\", \"best_ask\":\"0.42\"}, {\"asset_id\":\"8761897749749422724209054078244794145777693856614463256546737399611489089783\", \"price\":\"0.69\", \"size\":\"204.71\", \"side\":\"SELL\", \"hash\":\"061b522eaa972c740dff5d945edf845c129565d1\", \"best_bid\":\"0.58\", \"best_ask\":\"0.59\"}], \"timestamp\":\"1785208087426\", \"event_type\":\"price_change\"}","received_at":"2026-07-28T03:08:07.426900Z","schema_version":"clob-market-ws.price_change.v1","sequence":null,"server_hash":null,"server_timestamp":"1785208087426","session_id":"3e519d9098404c15b234d96025eb1a2b","source":"clob_market_ws"},"received_at":"2026-07-28T03:08:07.426900Z","record_id":"a18dd078159abf046f3fcfb40f1ebe15f2fc9acebafdd490ff7f77280d983b64","schema_fingerprint":"4aa3821a28b0b7c2400bc59aba4bcc0a76e971dadd19610d3ad38c768e124dc7","schema_version":"edge-lab-recorder.raw.v1","sequence":null,"source":"clob_market_ws"}
{"event_at":"2026-07-28T03:08:07.428000Z","event_fingerprint":"f59f5689f99fe23d8b990f097e0bb927803e125daf902c594530cb6409a82190","payload":{"connection_id":"a6b55582af5f430fb37ad02bf0922475","event_at":"2026-07-28T03:08:07.428000Z","event_type":"price_change","frame_hash":"c5fac24cbeaee986b9a82e8ccbb2dee5c47770b754b087fd621384e7ecd611bb","frame_index":0,"kind":"data","monotonic_ns":310070461054625,"payload":{"event_type":"price_change","market":"0x779291bef19b6709f61e9764a954aafe9ffae488d50ae674aabdcb4f248006d5","price_changes":[{"asset_id":"14965588658799411272385430903075831224615961675357217884735713260981483529984","best_ask":"0.42","best_bid":"0.41","hash":"6aba0a5f362bf8673ec1023beb7ae9abc9b3b7f7","price":"0.36","side":"BUY","size":"199.6"},{"asset_id":"8761897749749422724209054078244794145777693856614463256546737399611489089783","best_ask":"0.59","best_bid":"0.58","hash":"9c411b1b356c759e99c44c13e492297261f412bf","price":"0.64","side":"SELL","size":"199.6"}],"timestamp":"1785208087428"},"payload_hash":"068a7ae342f0a7df2bad48dbbfb1f3878c5bb2383b6f93a6d55d8c968f5b5b4d","raw_frame":"{\"market\":\"0x779291bef19b6709f61e9764a954aafe9ffae488d50ae674aabdcb4f248006d5\", \"price_changes\":[{\"asset_id\":\"14965588658799411272385430903075831224615961675357217884735713260981483529984\", \"price\":\"0.36\", \"size\":\"199.6\", \"side\":\"BUY\", \"hash\":\"6aba0a5f362bf8673ec1023beb7ae9abc9b3b7f7\", \"best_bid\":\"0.41\", \"best_ask\":\"0.42\"}, {\"asset_id\":\"8761897749749422724209054078244794145777693856614463256546737399611489089783\", \"price\":\"0.64\", \"size\":\"199.6\", \"side\":\"SELL\", \"hash\":\"9c411b1b356c759e99c44c13e492297261f412bf\", \"best_bid\":\"0.58\", \"best_ask\":\"0.59\"}], \"timestamp\":\"1785208087428\", \"event_type\":\"price_change\"}","received_at":"2026-07-28T03:08:07.428721Z","schema_version":"clob-market-ws.price_change.v1","sequence":null,"server_hash":null,"server_timestamp":"1785208087428","session_id":"3e519d9098404c15b234d96025eb1a2b","source":"clob_market_ws"},"received_at":"2026-07-28T03:08:07.428721Z","record_id":"bf20a18f286ffdb4b9271db44d29f9d55b261e5ab5d76e460187da498f28bae2","schema_fingerprint":"4aa3821a28b0b7c2400bc59aba4bcc0a76e971dadd19610d3ad38c768e124dc7","schema_version":"edge-lab-recorder.raw.v1","sequence":null,"source":"clob_market_ws"}
{"event_at":"2026-07-28T03:08:07.429000Z","event_fingerprint":"c17ccbc02138c44f7004ed31836811f064583e52a5508a8bc9b178024357c398","payload":{"connection_id":"a6b55582af5f430fb37ad02bf0922475","event_at":"2026-07-28T03:08:07.429000Z","event_type":"price_change","frame_hash":"102689512bf077214fbe6699fb5a3dc72a6b7abe2afb0503750aa6ad22e0fd25","frame_index":0,"kind":"data","monotonic_ns":310070462571416,"payload":{"event_type":"price_change","market":"0x779291bef19b6709f61e9764a954aafe9ffae488d50ae674aabdcb4f248006d5","price_changes":[{"asset_id":"8761897749749422724209054078244794145777693856614463256546737399611489089783","best_ask":"0.59","best_bid":"0.58","hash":"22828f872c2c7c0cb6d5d3750cbf65252fbb8111","price":"0.4","side":"BUY","size":"44.41"},{"asset_id":"14965588658799411272385430903075831224615961675357217884735713260981483529984","best_ask":"0.42","best_bid":"0.41","hash":"b7135d06e8a5388e03a33bf39376984b4d6e8bf7","price":"0.6","side":"SELL","size":"44.41"}],"timestamp":"1785208087429"},"payload_hash":"7a59fb28790ead6ad824c64a3c402a74f9d72894be0ed97782068c1cd831caa8","raw_frame":"{\"market\":\"0x779291bef19b6709f61e9764a954aafe9ffae488d50ae674aabdcb4f248006d5\", \"price_changes\":[{\"asset_id\":\"8761897749749422724209054078244794145777693856614463256546737399611489089783\", \"price\":\"0.4\", \"size\":\"44.41\", \"side\":\"BUY\", \"hash\":\"22828f872c2c7c0cb6d5d3750cbf65252fbb8111\", \"best_bid\":\"0.58\", \"best_ask\":\"0.59\"}, {\"asset_id\":\"14965588658799411272385430903075831224615961675357217884735713260981483529984\", \"price\":\"0.6\", \"size\":\"44.41\", \"side\":\"SELL\", \"hash\":\"b7135d06e8a5388e03a33bf39376984b4d6e8bf7\", \"best_bid\":\"0.41\", \"best_ask\":\"0.42\"}], \"timestamp\":\"1785208087429\", \"event_type\":\"price_change\"}","received_at":"2026-07-28T03:08:07.430238Z","schema_version":"clob-market-ws.price_change.v1","sequence":null,"server_hash":null,"server_timestamp":"1785208087429","session_id":"3e519d9098404c15b234d96025eb1a2b","source":"clob_market_ws"},"received_at":"2026-07-28T03:08:07.430238Z","record_id":"b25b8f2d62d8fe852fab682953080f886f85e1348d4e159952b039a5ed6a3f1b","schema_fingerprint":"4aa3821a28b0b7c2400bc59aba4bcc0a76e971dadd19610d3ad38c768e124dc7","schema_version":"edge-lab-recorder.raw.v1","sequence":null,"source":"clob_market_ws"}
{"event_at":"2026-07-28T03:08:07.433000Z","event_fingerprint":"a8820dbe5bd26816e65047a1e25829bd123aaf1f730e5e06209e9e486b1e1f5a","payload":{"connection_id":"a6b55582af5f430fb37ad02bf0922475","event_at":"2026-07-28T03:08:07.433000Z","event_type":"price_change","frame_hash":"972030b82def3961e151bd6506a515e26ff747fb6267adb61396ae6799b63b8c","frame_index":0,"kind":"data","monotonic_ns":310070464198166,"payload":{"event_type":"price_change","market":"0x779291bef19b6709f61e9764a954aafe9ffae488d50ae674aabdcb4f248006d5","price_changes":[{"asset_id":"8761897749749422724209054078244794145777693856614463256546737399611489089783","best_ask":"0.59","best_bid":"0.58","hash":"ef8c818e98b6aabb1b4b4750484df0ac4a71c433","price":"0.53","side":"BUY","size":"38"},{"asset_id":"14965588658799411272385430903075831224615961675357217884735713260981483529984","best_ask":"0.42","best_bid":"0.41","hash":"e02eb6aca0afcccf957e8c6585b5519554e75610","price":"0.47","side":"SELL","size":"38"}],"timestamp":"1785208087433"},"payload_hash":"de7c9e110267a78fb6aa7b5a24f65a6fc02a24fe9e94e4935faf76bca4a8f837","raw_frame":"{\"market\":\"0x779291bef19b6709f61e9764a954aafe9ffae488d50ae674aabdcb4f248006d5\", \"price_changes\":[{\"asset_id\":\"8761897749749422724209054078244794145777693856614463256546737399611489089783\", \"price\":\"0.53\", \"size\":\"38\", \"side\":\"BUY\", \"hash\":\"ef8c818e98b6aabb1b4b4750484df0ac4a71c433\", \"best_bid\":\"0.58\", \"best_ask\":\"0.59\"}, {\"asset_id\":\"14965588658799411272385430903075831224615961675357217884735713260981483529984\", \"price\":\"0.47\", \"size\":\"38\", \"side\":\"SELL\", \"hash\":\"e02eb6aca0afcccf957e8c6585b5519554e75610\", \"best_bid\":\"0.41\", \"best_ask\":\"0.42\"}], \"timestamp\":\"1785208087433\", \"event_type\":\"price_change\"}","received_at":"2026-07-28T03:08:07.431864Z","schema_version":"clob-market-ws.price_change.v1","sequence":null,"server_hash":null,"server_timestamp":"1785208087433","session_id":"3e519d9098404c15b234d96025eb1a2b","source":"clob_market_ws"},"received_at":"2026-07-28T03:08:07.431864Z","record_id":"e4b148bcae63cfece13c7fbe57df8ddbe5af1838866109de7d0c57d65505031e","schema_fingerprint":"4aa3821a28b0b7c2400bc59aba4bcc0a76e971dadd19610d3ad38c768e124dc7","schema_version":"edge-lab-recorder.raw.v1","sequence":null,"source":"clob_market_ws"}
{"event_at":"2026-07-28T03:08:07.436000Z","event_fingerprint":"46badfc586af1bff2ae4aa955c0c1de739a38653b979e4087c428e23a31e8a76","payload":{"connection_id":"a6b55582af5f430fb37ad02bf0922475","event_at":"2026-07-28T03:08:07.436000Z","event_type":"price_change","frame_hash":"de2cb12e8681d9f66b9474ac277b5d4753c359aa6bb7b5d8a50f82e54e1962d1","frame_index":0,"kind":"data","monotonic_ns":310070465709000,"payload":{"event_type":"price_change","market":"0x779291bef19b6709f61e9764a954aafe9ffae488d50ae674aabdcb4f248006d5","price_changes":[{"asset_id":"8761897749749422724209054078244794145777693856614463256546737399611489089783","best_ask":"0.59","best_bid":"0.58","hash":"583a3794bc94f6911c8cf50a8256f20a77eac76c","price":"0.02","side":"BUY","size":"688.1"},{"asset_id":"14965588658799411272385430903075831224615961675357217884735713260981483529984","best_ask":"0.42","best_bid":"0.41","hash":"ebde89613f18d6e031483bd2e6066c13bad0fcd6","price":"0.98","side":"SELL","size":"688.1"}],"timestamp":"1785208087436"},"payload_hash":"1a5a10d004d46cfd6c5bcfa27c8604c07fb8849302fe19cfcbd1546066b99372","raw_frame":"{\"market\":\"0x779291bef19b6709f61e9764a954aafe9ffae488d50ae674aabdcb4f248006d5\", \"price_changes\":[{\"asset_id\":\"8761897749749422724209054078244794145777693856614463256546737399611489089783\", \"price\":\"0.02\", \"size\":\"688.1\", \"side\":\"BUY\", \"hash\":\"583a3794bc94f6911c8cf50a8256f20a77eac76c\", \"best_bid\":\"0.58\", \"best_ask\":\"0.59\"}, {\"asset_id\":\"14965588658799411272385430903075831224615961675357217884735713260981483529984\", \"price\":\"0.98\", \"size\":\"688.1\", \"side\":\"SELL\", \"hash\":\"ebde89613f18d6e031483bd2e6066c13bad0fcd6\", \"best_bid\":\"0.41\", \"best_ask\":\"0.42\"}], \"timestamp\":\"1785208087436\", \"event_type\":\"price_change\"}","received_at":"2026-07-28T03:08:07.433374Z","schema_version":"clob-market-ws.price_change.v1","sequence":null,"server_hash":null,"server_timestamp":"1785208087436","session_id":"3e519d9098404c15b234d96025eb1a2b","source":"clob_market_ws"},"received_at":"2026-07-28T03:08:07.433374Z","record_id":"45722b6189dcd44e79da5492093e8a6b922cf7a569f44185a3a6e1b12143666b","schema_fingerprint":"4aa3821a28b0b7c2400bc59aba4bcc0a76e971dadd19610d3ad38c768e124dc7","schema_version":"edge-lab-recorder.raw.v1","sequence":null,"source":"clob_market_ws"}
{"event_at":"2026-07-28T03:08:07.440000Z","event_fingerprint":"ca3a629722a5c9fbbbc2f83442ef58e21b83d3ef18f4d1cd47a2297e5f65ab3d","payload":{"connection_id":"a6b55582af5f430fb37ad02bf0922475","event_at":"2026-07-28T03:08:07.440000Z","event_type":"price_change","frame_hash":"d2a79d0283dbe6e157631bbccb05a3c213ebd3015aa3e782b437b0b470b7a348","frame_index":0,"kind":"data","monotonic_ns":310070467293000,"payload":{"event_type":"price_change","market":"0x779291bef19b6709f61e9764a954aafe9ffae488d50ae674aabdcb4f248006d5","price_changes":[{"asset_id":"14965588658799411272385430903075831224615961675357217884735713260981483529984","best_ask":"0.42","best_bid":"0.41","hash":"9292120fb483515210161acc653519d144b69e5a","price":"0.47","side":"SELL","size":"53.06"},{"asset_id":"8761897749749422724209054078244794145777693856614463256546737399611489089783","best_ask":"0.59","best_bid":"0.58","hash":"8bf9ba348a814b82b85449f4e2daa0e668fabf47","price":"0.53","side":"BUY","size":"53.06"}],"timestamp":"1785208087440"},"payload_hash":"118a755bbf01933b398bda5e2bf245877b4687b0d63eecbd3ec5e32bf1d1a52a","raw_frame":"{\"market\":\"0x779291bef19b6709f61e9764a954aafe9ffae488d50ae674aabdcb4f248006d5\", \"price_changes\":[{\"asset_id\":\"14965588658799411272385430903075831224615961675357217884735713260981483529984\", \"price\":\"0.47\", \"size\":\"53.06\", \"side\":\"SELL\", \"hash\":\"9292120fb483515210161acc653519d144b69e5a\", \"best_bid\":\"0.41\", \"best_ask\":\"0.42\"}, {\"asset_id\":\"8761897749749422724209054078244794145777693856614463256546737399611489089783\", \"price\":\"0.53\", \"size\":\"53.06\", \"side\":\"BUY\", \"hash\":\"8bf9ba348a814b82b85449f4e2daa0e668fabf47\", \"best_bid\":\"0.58\", \"best_ask\":\"0.59\"}], \"timestamp\":\"1785208087440\", \"event_type\":\"price_change\"}","received_at":"2026-07-28T03:08:07.434959Z","schema_version":"clob-market-ws.price_change.v1","sequence":null,"server_hash":null,"server_timestamp":"1785208087440","session_id":"3e519d9098404c15b234d96025eb1a2b","source":"clob_market_ws"},"received_at":"2026-07-28T03:08:07.434959Z","record_id":"1eeca190718d08265ea17d0569dcc0f26526a9ad28a9d22c1d7d3badb67b72a5","schema_fingerprint":"4aa3821a28b0b7c2400bc59aba4bcc0a76e971dadd19610d3ad38c768e124dc7","schema_version":"edge-lab-recorder.raw.v1","sequence":null,"source":"clob_market_ws"}
{"event_at":"2026-07-28T03:08:07.441000Z","event_fingerprint":"bd29d2ade874a2d1a4ce5a883837ebc33be320111d41791763f64614216cc539","payload":{"connection_id":"a6b55582af5f430fb37ad02bf0922475","event_at":"2026-07-28T03:08:07.441000Z","event_type":"price_change","frame_hash":"08771ce3afe17f1508efba78a055a2c918016a23115de7bf5913ec5981b4787b","frame_index":0,"kind":"data","monotonic_ns":310070468824208,"payload":{"event_type":"price_change","market":"0x779291bef19b6709f61e9764a954aafe9ffae488d50ae674aabdcb4f248006d5","price_changes":[{"asset_id":"14965588658799411272385430903075831224615961675357217884735713260981483529984","best_ask":"0.42","best_bid":"0.41","hash":"b233d82f4f90a22b81a3935a76a91a14f664e2ec","price":"0.28","side":"BUY","size":"159.4"},{"asset_id":"8761897749749422724209054078244794145777693856614463256546737399611489089783","best_ask":"0.59","best_bid":"0.58","hash":"1978c8427d5b7cfea4162cfb6825baa1485da83c","price":"0.72","side":"SELL","size":"159.4"}],"timestamp":"1785208087441"},"payload_hash":"138c05ad19bfaa2a8bf221edefb2e917c937a8668a6f9d0e526d3fd2c837a54d","raw_frame":"{\"market\":\"0x779291bef19b6709f61e9764a954aafe9ffae488d50ae674aabdcb4f248006d5\", \"price_changes\":[{\"asset_id\":\"14965588658799411272385430903075831224615961675357217884735713260981483529984\", \"price\":\"0.28\", \"size\":\"159.4\", \"side\":\"BUY\", \"hash\":\"b233d82f4f90a22b81a3935a76a91a14f664e2ec\", \"best_bid\":\"0.41\", \"best_ask\":\"0.42\"}, {\"asset_id\":\"8761897749749422724209054078244794145777693856614463256546737399611489089783\", \"price\":\"0.72\", \"size\":\"159.4\", \"side\":\"SELL\", \"hash\":\"1978c8427d5b7cfea4162cfb6825baa1485da83c\", \"best_bid\":\"0.58\", \"best_ask\":\"0.59\"}], \"timestamp\":\"1785208087441\", \"event_type\":\"price_change\"}","received_at":"2026-07-28T03:08:07.436491Z","schema_version":"clob-market-ws.price_change.v1","sequence":null,"server_hash":null,"server_timestamp":"1785208087441","session_id":"3e519d9098404c15b234d96025eb1a2b","source":"clob_market_ws"},"received_at":"2026-07-28T03:08:07.436491Z","record_id":"7e9ea7da033cc7899ed3749e5966bf4358b4c4011c257f2e0f5cb0f219117e9b","schema_fingerprint":"4aa3821a28b0b7c2400bc59aba4bcc0a76e971dadd19610d3ad38c768e124dc7","schema_version":"edge-lab-recorder.raw.v1","sequence":null,"source":"clob_market_ws"}
{"event_at":"2026-07-28T03:08:07.456000Z","event_fingerprint":"5e55a09110326bb15a596fbea8d3d1c8b57cfd0ea8de6d746fb958cf18989e53","payload":{"connection_id":"a6b55582af5f430fb37ad02bf0922475","event_at":"2026-07-28T03:08:07.456000Z","event_type":"price_change","frame_hash":"2f0c5ca5d92ceade472cf2dfc8f0f9198d89ce19b3e8c3970c5ca41100834892","frame_index":0,"kind":"data","monotonic_ns":310070470356458,"payload":{"event_type":"price_change","market":"0x779291bef19b6709f61e9764a954aafe9ffae488d50ae674aabdcb4f248006d5","price_changes":[{"asset_id":"8761897749749422724209054078244794145777693856614463256546737399611489089783","best_ask":"0.59","best_bid":"0.58","hash":"34122d027f6e402b2c6ffedb31deba497605564c","price":"0.49","side":"BUY","size":"104.5"},{"asset_id":"14965588658799411272385430903075831224615961675357217884735713260981483529984","best_ask":"0.42","best_bid":"0.41","hash":"71ab3ae4c6dc02e259d32721bb65e9f7db30b858","price":"0.51","side":"SELL","size":"104.5"}],"timestamp":"1785208087456"},"payload_hash":"78f22ec76e5315c9f6f7d1a1643f8bb0fef096544c7cb331757a065717d880d3","raw_frame":"{\"market\":\"0x779291bef19b6709f61e9764a954aafe9ffae488d50ae674aabdcb4f248006d5\", \"price_changes\":[{\"asset_id\":\"8761897749749422724209054078244794145777693856614463256546737399611489089783\", \"price\":\"0.49\", \"size\":\"104.5\", \"side\":\"BUY\", \"hash\":\"34122d027f6e402b2c6ffedb31deba497605564c\", \"best_bid\":\"0.58\", \"best_ask\":\"0.59\"}, {\"asset_id\":\"14965588658799411272385430903075831224615961675357217884735713260981483529984\", \"price\":\"0.51\", \"size\":\"104.5\", \"side\":\"SELL\", \"hash\":\"71ab3ae4c6dc02e259d32721bb65e9f7db30b858\", \"best_bid\":\"0.41\", \"best_ask\":\"0.42\"}], \"timestamp\":\"1785208087456\", \"event_type\":\"price_change\"}","received_at":"2026-07-28T03:08:07.438023Z","schema_version":"clob-market-ws.price_change.v1","sequence":null,"server_hash":null,"server_timestamp":"1785208087456","session_id":"3e519d9098404c15b234d96025eb1a2b","source":"clob_market_ws"},"received_at":"2026-07-28T03:08:07.438023Z","record_id":"76379b3a9b05d7a79162a13fea167fcea05f85395952fbbedd52ce6b5ff58481","schema_fingerprint":"4aa3821a28b0b7c2400bc59aba4bcc0a76e971dadd19610d3ad38c768e124dc7","schema_version":"edge-lab-recorder.raw.v1","sequence":null,"source":"clob_market_ws"}
{"event_at":"2026-07-28T03:08:07.456000Z","event_fingerprint":"3d1a345b6a3f7cf987683d7a9e812bfb7db600b438a97f28b5c93471fde67eff","payload":{"connection_id":"a6b55582af5f430fb37ad02bf0922475","event_at":"2026-07-28T03:08:07.456000Z","event_type":"price_change","frame_hash":"dd5394d88a0312c3a53a5f13d9fb1c2dddcfb660cdfc8e3c14494c08413c1bd3","frame_index":0,"kind":"data","monotonic_ns":310070471837666,"payload":{"event_type":"price_change","market":"0x779291bef19b6709f61e9764a954aafe9ffae488d50ae674aabdcb4f248006d5","price_changes":[{"asset_id":"8761897749749422724209054078244794145777693856614463256546737399611489089783","best_ask":"0.59","best_bid":"0.58","hash":"34122d027f6e402b2c6ffedb31deba497605564c","price":"0.48","side":"BUY","size":"107"},{"asset_id":"14965588658799411272385430903075831224615961675357217884735713260981483529984","best_ask":"0.42","best_bid":"0.41","hash":"71ab3ae4c6dc02e259d32721bb65e9f7db30b858","price":"0.52","side":"SELL","size":"107"}],"timestamp":"1785208087456"},"payload_hash":"040b1b5e09620e35951d119635475c017f5c67e6b3b66a54db57b049cb3e9f59","raw_frame":"{\"market\":\"0x779291bef19b6709f61e9764a954aafe9ffae488d50ae674aabdcb4f248006d5\", \"price_changes\":[{\"asset_id\":\"8761897749749422724209054078244794145777693856614463256546737399611489089783\", \"price\":\"0.48\", \"size\":\"107\", \"side\":\"BUY\", \"hash\":\"34122d027f6e402b2c6ffedb31deba497605564c\", \"best_bid\":\"0.58\", \"best_ask\":\"0.59\"}, {\"asset_id\":\"14965588658799411272385430903075831224615961675357217884735713260981483529984\", \"price\":\"0.52\", \"size\":\"107\", \"side\":\"SELL\", \"hash\":\"71ab3ae4c6dc02e259d32721bb65e9f7db30b858\", \"best_bid\":\"0.41\", \"best_ask\":\"0.42\"}], \"timestamp\":\"1785208087456\", \"event_type\":\"price_change\"}","received_at":"2026-07-28T03:08:07.439504Z","schema_version":"clob-market-ws.price_change.v1","sequence":null,"server_hash":null,"server_timestamp":"1785208087456","session_id":"3e519d9098404c15b234d96025eb1a2b","source":"clob_market_ws"},"received_at":"2026-07-28T03:08:07.439504Z","record_id":"a6eb1783883fb001a5df312f667b7b904c7b5e051d748ebcb6fe9a60e25cdea5","schema_fingerprint":"4aa3821a28b0b7c2400bc59aba4bcc0a76e971dadd19610d3ad38c768e124dc7","schema_version":"edge-lab-recorder.raw.v1","sequence":null,"source":"clob_market_ws"}
{"event_at":"2026-07-28T03:08:07.457000Z","event_fingerprint":"1fe42a8b3dbfa29c03976c5c4c4a4a66d1e607438bd0106d94c91fa125ac00dd","payload":{"connection_id":"a6b55582af5f430fb37ad02bf0922475","event_at":"2026-07-28T03:08:07.457000Z","event_type":"price_change","frame_hash":"66eaa2f3078248c69a928be30c342ff93ee32f15e12585a001c5243914180857","frame_index":0,"kind":"data","monotonic_ns":310070473348625,"payload":{"event_type":"price_change","market":"0x779291bef19b6709f61e9764a954aafe9ffae488d50ae674aabdcb4f248006d5","price_changes":[{"asset_id":"14965588658799411272385430903075831224615961675357217884735713260981483529984","best_ask":"0.42","best_bid":"0.41","hash":"c0552b5d5022d3fcf996337a0f15233ab74eb79a","price":"0.33","side":"BUY","size":"118.07"},{"asset_id":"8761897749749422724209054078244794145777693856614463256546737399611489089783","best_ask":"0.59","best_bid":"0.58","hash":"2bd85f7a16b318ebe34ffeaa1bef113c7088c7ec","price":"0.67","side":"SELL","size":"118.07"}],"timestamp":"1785208087457"},"payload_hash":"a122ea32b1957bd34787b580e185e8a0bf8a84ac6b5420f2e656365cb543c268","raw_frame":"{\"market\":\"0x779291bef19b6709f61e9764a954aafe9ffae488d50ae674aabdcb4f248006d5\", \"price_changes\":[{\"asset_id\":\"14965588658799411272385430903075831224615961675357217884735713260981483529984\", \"price\":\"0.33\", \"size\":\"118.07\", \"side\":\"BUY\", \"hash\":\"c0552b5d5022d3fcf996337a0f15233ab74eb79a\", \"best_bid\":\"0.41\", \"best_ask\":\"0.42\"}, {\"asset_id\":\"8761897749749422724209054078244794145777693856614463256546737399611489089783\", \"price\":\"0.67\", \"size\":\"118.07\", \"side\":\"SELL\", \"hash\":\"2bd85f7a16b318ebe34ffeaa1bef113c7088c7ec\", \"best_bid\":\"0.58\", \"best_ask\":\"0.59\"}], \"timestamp\":\"1785208087457\", \"event_type\":\"price_change\"}","received_at":"2026-07-28T03:08:07.441015Z","schema_version":"clob-market-ws.price_change.v1","sequence":null,"server_hash":null,"server_timestamp":"1785208087457","session_id":"3e519d9098404c15b234d96025eb1a2b","source":"clob_market_ws"},"received_at":"2026-07-28T03:08:07.441015Z","record_id":"cd9792ae92cdb7f5f622ed4fe190c1c37388f6936ce64a363d01a57b60ec703d","schema_fingerprint":"4aa3821a28b0b7c2400bc59aba4bcc0a76e971dadd19610d3ad38c768e124dc7","schema_version":"edge-lab-recorder.raw.v1","sequence":null,"source":"clob_market_ws"}
{"event_at":null,"event_fingerprint":"e937667bb131d52e2484c6de384b084d0f9272946f9dae8fcfd0b8ead17a4f4b","payload":{"connection_id":"a6b55582af5f430fb37ad02bf0922475","detail":{"interval_seconds":10.0,"message":"PING"},"event_type":"heartbeat","kind":"lifecycle","monotonic_ns":310070475031708,"received_at":"2026-07-28T03:08:07.442696Z","schema_version":"edge-lab-recorder.lifecycle.v1","session_id":"3e519d9098404c15b234d96025eb1a2b","source":"clob_market_ws"},"received_at":"2026-07-28T03:08:07.442696Z","record_id":"d814dfe03d19da3e68217fa1fa981015dc42d25bd5e891da5db6d4b9d9378c42","schema_fingerprint":"cb8aa3aa4cb168a4b724fd9077bee6ecfb9bc586c57cfdf0ab89f00d82045e3c","schema_version":"edge-lab-recorder.raw.v1","sequence":null,"source":"clob_market_ws"}
{"event_at":"2026-07-28T03:08:07.458000Z","event_fingerprint":"d6b2816c0b4d50fe454fd9c394bf01928655903c0ba8cd064ae13b2ced5975ec","payload":{"connection_id":"a6b55582af5f430fb37ad02bf0922475","event_at":"2026-07-28T03:08:07.458000Z","event_type":"price_change","frame_hash":"1078e4c82b3fb7c5d4bf28156c7966e5c08fe262090e2267b8e4930e480a3a72","frame_index":0,"kind":"data","monotonic_ns":310070475115958,"payload":{"event_type":"price_change","market":"0x779291bef19b6709f61e9764a954aafe9ffae488d50ae674aabdcb4f248006d5","price_changes":[{"asset_id":"8761897749749422724209054078244794145777693856614463256546737399611489089783","best_ask":"0.59","best_bid":"0.58","hash":"bc1735cebc7561e30aa1e957fc2c48e8fc5fcf61","price":"0.54","side":"BUY","size":"5"},{"asset_id":"14965588658799411272385430903075831224615961675357217884735713260981483529984","best_ask":"0.42","best_bid":"0.41","hash":"a56e8258a1d59ed08244d8ad70ca560823b67406","price":"0.46","side":"SELL","size":"5"}],"timestamp":"1785208087458"},"payload_hash":"35ae0e4a65847de040e0336d63e35ccf0b0cda9bdb4791fddbc71473c1edb39d","raw_frame":"{\"market\":\"0x779291bef19b6709f61e9764a954aafe9ffae488d50ae674aabdcb4f248006d5\", \"price_changes\":[{\"asset_id\":\"8761897749749422724209054078244794145777693856614463256546737399611489089783\", \"price\":\"0.54\", \"size\":\"5\", \"side\":\"BUY\", \"hash\":\"bc1735cebc7561e30aa1e957fc2c48e8fc5fcf61\", \"best_bid\":\"0.58\", \"best_ask\":\"0.59\"}, {\"asset_id\":\"14965588658799411272385430903075831224615961675357217884735713260981483529984\", \"price\":\"0.46\", \"size\":\"5\", \"side\":\"SELL\", \"hash\":\"a56e8258a1d59ed08244d8ad70ca560823b67406\", \"best_bid\":\"0.41\", \"best_ask\":\"0.42\"}], \"timestamp\":\"1785208087458\", \"event_type\":\"price_change\"}","received_at":"2026-07-28T03:08:07.442783Z","schema_version":"clob-market-ws.price_change.v1","sequence":null,"server_hash":null,"server_timestamp":"1785208087458","session_id":"3e519d9098404c15b234d96025eb1a2b","source":"clob_market_ws"},"received_at":"2026-07-28T03:08:07.442783Z","record_id":"65add2414c1a8165fea133f6e59c1d49c1c7d1eaceef144a303aa5482d0bd56d","schema_fingerprint":"4aa3821a28b0b7c2400bc59aba4bcc0a76e971dadd19610d3ad38c768e124dc7","schema_version":"edge-lab-recorder.raw.v1","sequence":null,"source":"clob_market_ws"}
{"event_at":"2026-07-28T03:08:07.458000Z","event_fingerprint":"a4811ff26ec9b74f220e718b6b6d703e27516878bf2566708a48beaa1849511e","payload":{"connection_id":"a6b55582af5f430fb37ad02bf0922475","event_at":"2026-07-28T03:08:07.458000Z","event_type":"price_change","frame_hash":"9b34139b40f5c0df5ca83f763b6c1f2b35b1c5f657e17a991298595ecbe1e67d","frame_index":0,"kind":"data","monotonic_ns":310070477574166,"payload":{"event_type":"price_change","market":"0x779291bef19b6709f61e9764a954aafe9ffae488d50ae674aabdcb4f248006d5","price_changes":[{"asset_id":"14965588658799411272385430903075831224615961675357217884735713260981483529984","best_ask":"0.42","best_bid":"0.41","hash":"f192e76529752148f791441a74c707e68010befd","price":"0.34","side":"BUY","size":"124"},{"asset_id":"8761897749749422724209054078244794145777693856614463256546737399611489089783","best_ask":"0.59","best_bid":"0.58","hash":"a3eaae4ee74d337ff60881a24223ac8b46fc00fa","price":"0.66","side":"SELL","size":"124"}],"timestamp":"1785208087458"},"payload_hash":"4a05449eadf98655b1ad59ada9ce7a08de0bc62b1f788e6980d78b63fa066c5e","raw_frame":"{\"market\":\"0x779291bef19b6709f61e9764a954aafe9ffae488d50ae674aabdcb4f248006d5\", \"price_changes\":[{\"asset_id\":\"14965588658799411272385430903075831224615961675357217884735713260981483529984\", \"price\":\"0.34\", \"size\":\"124\", \"side\":\"BUY\", \"hash\":\"f192e76529752148f791441a74c707e68010befd\", \"best_bid\":\"0.41\", \"best_ask\":\"0.42\"}, {\"asset_id\":\"8761897749749422724209054078244794145777693856614463256546737399611489089783\", \"price\":\"0.66\", \"size\":\"124\", \"side\":\"SELL\", \"hash\":\"a3eaae4ee74d337ff60881a24223ac8b46fc00fa\", \"best_bid\":\"0.58\", \"best_ask\":\"0.59\"}], \"timestamp\":\"1785208087458\", \"event_type\":\"price_change\"}","received_at":"2026-07-28T03:08:07.445240Z","schema_version":"clob-market-ws.price_change.v1","sequence":null,"server_hash":null,"server_timestamp":"1785208087458","session_id":"3e519d9098404c15b234d96025eb1a2b","source":"clob_market_ws"},"received_at":"2026-07-28T03:08:07.445240Z","record_id":"f8de85eeb8023276304265de701b53b4c6847f3f9b4eb64d66ebfb9bb27047c3","schema_fingerprint":"4aa3821a28b0b7c2400bc59aba4bcc0a76e971dadd19610d3ad38c768e124dc7","schema_version":"edge-lab-recorder.raw.v1","sequence":null,"source":"clob_market_ws"}
{"event_at":"2026-07-28T03:08:07.460000Z","event_fingerprint":"865a9269c9166802c6040fb96c8404e012f48c71186a01d8d6b6bf12383f97da","payload":{"connection_id":"a6b55582af5f430fb37ad02bf0922475","event_at":"2026-07-28T03:08:07.460000Z","event_type":"price_change","frame_hash":"c56be84764a104cdf41afada095546ec5cb495725d70ff23850875d40e3bd4de","frame_index":0,"kind":"data","monotonic_ns":310070479075958,"payload":{"event_type":"price_change","market":"0x779291bef19b6709f61e9764a954aafe9ffae488d50ae674aabdcb4f248006d5","price_changes":[{"asset_id":"14965588658799411272385430903075831224615961675357217884735713260981483529984","best_ask":"0.42","best_bid":"0.41","hash":"5f418cfabb3b48dadedd0f168bfbbaa5dc005024","price":"0.47","side":"SELL","size":"38"},{"asset_id":"8761897749749422724209054078244794145777693856614463256546737399611489089783","best_ask":"0.59","best_bid":"0.58","hash":"891e31a816454876140b1a37b73f39f9322a756e","price":"0.53","side":"BUY","size":"38"}],"timestamp":"1785208087460"},"payload_hash":"4df47e817309fa70a088a3013c4d4e1d6e42fb6373d90b823f1c0e3267053edc","raw_frame":"{\"market\":\"0x779291bef19b6709f61e9764a954aafe9ffae488d50ae674aabdcb4f248006d5\", \"price_changes\":[{\"asset_id\":\"14965588658799411272385430903075831224615961675357217884735713260981483529984\", \"price\":\"0.47\", \"size\":\"38\", \"side\":\"SELL\", \"hash\":\"5f418cfabb3b48dadedd0f168bfbbaa5dc005024\", \"best_bid\":\"0.41\", \"best_ask\":\"0.42\"}, {\"asset_id\":\"8761897749749422724209054078244794145777693856614463256546737399611489089783\", \"price\":\"0.53\", \"size\":\"38\", \"side\":\"BUY\", \"hash\":\"891e31a816454876140b1a37b73f39f9322a756e\", \"best_bid\":\"0.58\", \"best_ask\":\"0.59\"}], \"timestamp\":\"1785208087460\", \"event_type\":\"price_change\"}","received_at":"2026-07-28T03:08:07.446742Z","schema_version":"clob-market-ws.price_change.v1","sequence":null,"server_hash":null,"server_timestamp":"1785208087460","session_id":"3e519d9098404c15b234d96025eb1a2b","source":"clob_market_ws"},"received_at":"2026-07-28T03:08:07.446742Z","record_id":"60a20bcfef25407ab45716fa6a0a3a401aee08210313864028c497f6c1c1f7f4","schema_fingerprint":"4aa3821a28b0b7c2400bc59aba4bcc0a76e971dadd19610d3ad38c768e124dc7","schema_version":"edge-lab-recorder.raw.v1","sequence":null,"source":"clob_market_ws"}
{"event_at":"2026-07-28T03:08:07.460000Z","event_fingerprint":"fd1712978d9603133128cd9980d265a09e877df960d871a7eb769a958e5f3de3","payload":{"connection_id":"a6b55582af5f430fb37ad02bf0922475","event_at":"2026-07-28T03:08:07.460000Z","event_type":"price_change","frame_hash":"c9864af6de8d9a7085113e66d283bbe26c18af6905f42438c36bc4250289d030","frame_index":0,"kind":"data","monotonic_ns":310070480555875,"payload":{"event_type":"price_change","market":"0x779291bef19b6709f61e9764a954aafe9ffae488d50ae674aabdcb4f248006d5","price_changes":[{"asset_id":"8761897749749422724209054078244794145777693856614463256546737399611489089783","best_ask":"0.59","best_bid":"0.58","hash":"663e478babaae6ceddb3c7a07960181cab79ce72","price":"0.52","side":"BUY","size":"36"},{"asset_id":"14965588658799411272385430903075831224615961675357217884735713260981483529984","best_ask":"0.42","best_bid":"0.41","hash":"04522d64e49489bf045127df901e9e041bfd2e55","price":"0.48","side":"SELL","size":"36"}],"timestamp":"1785208087460"},"payload_hash":"1e5954b37fb5467953c94e88a7f9eb1995465712a7c779c0c3bcb6f1dc53a270","raw_frame":"{\"market\":\"0x779291bef19b6709f61e9764a954aafe9ffae488d50ae674aabdcb4f248006d5\", \"price_changes\":[{\"asset_id\":\"8761897749749422724209054078244794145777693856614463256546737399611489089783\", \"price\":\"0.52\", \"size\":\"36\", \"side\":\"BUY\", \"hash\":\"663e478babaae6ceddb3c7a07960181cab79ce72\", \"best_bid\":\"0.58\", \"best_ask\":\"0.59\"}, {\"asset_id\":\"14965588658799411272385430903075831224615961675357217884735713260981483529984\", \"price\":\"0.48\", \"size\":\"36\", \"side\":\"SELL\", \"hash\":\"04522d64e49489bf045127df901e9e041bfd2e55\", \"best_bid\":\"0.41\", \"best_ask\":\"0.42\"}], \"timestamp\":\"1785208087460\", \"event_type\":\"price_change\"}","received_at":"2026-07-28T03:08:07.448222Z","schema_version":"clob-market-ws.price_change.v1","sequence":null,"server_hash":null,"server_timestamp":"1785208087460","session_id":"3e519d9098404c15b234d96025eb1a2b","source":"clob_market_ws"},"received_at":"2026-07-28T03:08:07.448222Z","record_id":"e1421aac40fb5e78b5dba1383f1a18a1f812feb5f55dc99d275342a8e0242eba","schema_fingerprint":"4aa3821a28b0b7c2400bc59aba4bcc0a76e971dadd19610d3ad38c768e124dc7","schema_version":"edge-lab-recorder.raw.v1","sequence":null,"source":"clob_market_ws"}
{"event_at":"2026-07-28T03:08:07.461000Z","event_fingerprint":"b3322d64c7f40d3f9cc4ba7f75318645eddfd8fc96db178ce78bd2f90c9eec63","payload":{"connection_id":"a6b55582af5f430fb37ad02bf0922475","event_at":"2026-07-28T03:08:07.461000Z","event_type":"price_change","frame_hash":"592ddb4bd5b5fff758ee987d85ad9674212a757f2353d2fb24c0aa2cd6038739","frame_index":0,"kind":"data","monotonic_ns":310070482032708,"payload":{"event_type":"price_change","market":"0x779291bef19b6709f61e9764a954aafe9ffae488d50ae674aabdcb4f248006d5","price_changes":[{"asset_id":"8761897749749422724209054078244794145777693856614463256546737399611489089783","best_ask":"0.59","best_bid":"0.58","hash":"af11ae4af9ab9866b49c3f3e1d2a7033751d5e64","price":"0.53","side":"BUY","size":"26"},{"asset_id":"14965588658799411272385430903075831224615961675357217884735713260981483529984","best_ask":"0.42","best_bid":"0.41","hash":"f7e5497f67db52a874057ac74e209c059141b575","price":"0.47","side":"SELL","size":"26"}],"timestamp":"1785208087461"},"payload_hash":"0c9d248c42d228bde2a91572de185a53c05d28d8c8f5cd22a85e685642e06c15","raw_frame":"{\"market\":\"0x779291bef19b6709f61e9764a954aafe9ffae488d50ae674aabdcb4f248006d5\", \"price_changes\":[{\"asset_id\":\"8761897749749422724209054078244794145777693856614463256546737399611489089783\", \"price\":\"0.53\", \"size\":\"26\", \"side\":\"BUY\", \"hash\":\"af11ae4af9ab9866b49c3f3e1d2a7033751d5e64\", \"best_bid\":\"0.58\", \"best_ask\":\"0.59\"}, {\"asset_id\":\"14965588658799411272385430903075831224615961675357217884735713260981483529984\", \"price\":\"0.47\", \"size\":\"26\", \"side\":\"SELL\", \"hash\":\"f7e5497f67db52a874057ac74e209c059141b575\", \"best_bid\":\"0.41\", \"best_ask\":\"0.42\"}], \"timestamp\":\"1785208087461\", \"event_type\":\"price_change\"}","received_at":"2026-07-28T03:08:07.449699Z","schema_version":"clob-market-ws.price_change.v1","sequence":null,"server_hash":null,"server_timestamp":"1785208087461","session_id":"3e519d9098404c15b234d96025eb1a2b","source":"clob_market_ws"},"received_at":"2026-07-28T03:08:07.449699Z","record_id":"ee23c47983adddd2dbe9040c5244da3850943b9296b8f417de1c9c556ce61983","schema_fingerprint":"4aa3821a28b0b7c2400bc59aba4bcc0a76e971dadd19610d3ad38c768e124dc7","schema_version":"edge-lab-recorder.raw.v1","sequence":null,"source":"clob_market_ws"}
{"event_at":"2026-07-28T03:08:07.463000Z","event_fingerprint":"e9ce2de3a1e07c54a7d95d4fd3b79e84c39508a773540acca29802ab4b42f9a5","payload":{"connection_id":"a6b55582af5f430fb37ad02bf0922475","event_at":"2026-07-28T03:08:07.463000Z","event_type":"price_change","frame_hash":"c9d99369a23057e48e022896cc39b1452ea528bef586e898043ec634ea38315c","frame_index":0,"kind":"data","monotonic_ns":310070483510708,"payload":{"event_type":"price_change","market":"0x779291bef19b6709f61e9764a954aafe9ffae488d50ae674aabdcb4f248006d5","price_changes":[{"asset_id":"8761897749749422724209054078244794145777693856614463256546737399611489089783","best_ask":"0.59","best_bid":"0.58","hash":"47b321a475b6f04d16baf4d07cd2e80b906cede3","price":"0.53","side":"BUY","size":"11"},{"asset_id":"14965588658799411272385430903075831224615961675357217884735713260981483529984","best_ask":"0.42","best_bid":"0.41","hash":"110e3233af1879266803150f5d0e4e42e757b5aa","price":"0.47","side":"SELL","size":"11"}],"timestamp":"1785208087463"},"payload_hash":"13587da9cbd0ba93898f3d55a516a8171028d9cd2d393ae008c322cbdd195676","raw_frame":"{\"market\":\"0x779291bef19b6709f61e9764a954aafe9ffae488d50ae674aabdcb4f248006d5\", \"price_changes\":[{\"asset_id\":\"8761897749749422724209054078244794145777693856614463256546737399611489089783\", \"price\":\"0.53\", \"size\":\"11\", \"side\":\"BUY\", \"hash\":\"47b321a475b6f04d16baf4d07cd2e80b906cede3\", \"best_bid\":\"0.58\", \"best_ask\":\"0.59\"}, {\"asset_id\":\"14965588658799411272385430903075831224615961675357217884735713260981483529984\", \"price\":\"0.47\", \"size\":\"11\", \"side\":\"SELL\", \"hash\":\"110e3233af1879266803150f5d0e4e42e757b5aa\", \"best_bid\":\"0.41\", \"best_ask\":\"0.42\"}], \"timestamp\":\"1785208087463\", \"event_type\":\"price_change\"}","received_at":"2026-07-28T03:08:07.451177Z","schema_version":"clob-market-ws.price_change.v1","sequence":null,"server_hash":null,"server_timestamp":"1785208087463","session_id":"3e519d9098404c15b234d96025eb1a2b","source":"clob_market_ws"},"received_at":"2026-07-28T03:08:07.451177Z","record_id":"c7b6b6863f08a3b61d10fc50f1703603cef2bb3f8deb912e207587985e4e8cab","schema_fingerprint":"4aa3821a28b0b7c2400bc59aba4bcc0a76e971dadd19610d3ad38c768e124dc7","schema_version":"edge-lab-recorder.raw.v1","sequence":null,"source":"clob_market_ws"}
{"event_at":"2026-07-28T03:08:07.465000Z","event_fingerprint":"597df4da457abd49d7306c725742d8ed1b82d89170fed7b15e881d0784237369","payload":{"connection_id":"a6b55582af5f430fb37ad02bf0922475","event_at":"2026-07-28T03:08:07.465000Z","event_type":"price_change","frame_hash":"497a8366114342a4dff7483887629470f6d8293406490110e4c361c74bbddf01","frame_index":0,"kind":"data","monotonic_ns":310070484986083,"payload":{"event_type":"price_change","market":"0x779291bef19b6709f61e9764a954aafe9ffae488d50ae674aabdcb4f248006d5","price_changes":[{"asset_id":"8761897749749422724209054078244794145777693856614463256546737399611489089783","best_ask":"0.59","best_bid":"0.58","hash":"4bb27e59f090ea5228ae105e46e341d4eae95596","price":"0.51","side":"BUY","size":"66"},{"asset_id":"14965588658799411272385430903075831224615961675357217884735713260981483529984","best_ask":"0.42","best_bid":"0.41","hash":"7e6871e994303e55a93b2c8d1cfe32dd7aaf20ab","price":"0.49","side":"SELL","size":"66"}],"timestamp":"1785208087465"},"payload_hash":"bcdc4237016a306db9c4d047557fbc972661801090c0cbef25b7dd4f10400480","raw_frame":"{\"market\":\"0x779291bef19b6709f61e9764a954aafe9ffae488d50ae674aabdcb4f248006d5\", \"price_changes\":[{\"asset_id\":\"8761897749749422724209054078244794145777693856614463256546737399611489089783\", \"price\":\"0.51\", \"size\":\"66\", \"side\":\"BUY\", \"hash\":\"4bb27e59f090ea5228ae105e46e341d4eae95596\", \"best_bid\":\"0.58\", \"best_ask\":\"0.59\"}, {\"asset_id\":\"14965588658799411272385430903075831224615961675357217884735713260981483529984\", \"price\":\"0.49\", \"size\":\"66\", \"side\":\"SELL\", \"hash\":\"7e6871e994303e55a93b2c8d1cfe32dd7aaf20ab\", \"best_bid\":\"0.41\", \"best_ask\":\"0.42\"}], \"timestamp\":\"1785208087465\", \"event_type\":\"price_change\"}","received_at":"2026-07-28T03:08:07.452653Z","schema_version":"clob-market-ws.price_change.v1","sequence":null,"server_hash":null,"server_timestamp":"1785208087465","session_id":"3e519d9098404c15b234d96025eb1a2b","source":"clob_market_ws"},"received_at":"2026-07-28T03:08:07.452653Z","record_id":"c087aa36d8a3d9d154a8b840b6e9869d71c08896b5b91872e94f65e57e01e3dd","schema_fingerprint":"4aa3821a28b0b7c2400bc59aba4bcc0a76e971dadd19610d3ad38c768e124dc7","schema_version":"edge-lab-recorder.raw.v1","sequence":null,"source":"clob_market_ws"}
{"event_at":"2026-07-28T03:08:07.466000Z","event_fingerprint":"2016b7878528d51fa10bc3ec665d46c5141accdb460eff2e710d854cbd6aee74","payload":{"connection_id":"a6b55582af5f430fb37ad02bf0922475","event_at":"2026-07-28T03:08:07.466000Z","event_type":"price_change","frame_hash":"ebac42564464406adab653769ead6c52c2643aa1ca347332ebf1f6e83917dee3","frame_index":0,"kind":"data","monotonic_ns":310070486442166,"payload":{"event_type":"price_change","market":"0x779291bef19b6709f61e9764a954aafe9ffae488d50ae674aabdcb4f248006d5","price_changes":[{"asset_id":"8761897749749422724209054078244794145777693856614463256546737399611489089783","best_ask":"0.59","best_bid":"0.58","hash":"fccb6cd51cf6fa9fc79837b760da189596c9dfce","price":"0.5","side":"BUY","size":"108"},{"asset_id":"14965588658799411272385430903075831224615961675357217884735713260981483529984","best_ask":"0.42","best_bid":"0.41","hash":"7ac6a0d62ecca116487fd9bad7e46576d2865c90","price":"0.5","side":"SELL","size":"108"}],"timestamp":"1785208087466"},"payload_hash":"9140da29417fdbb65617a6ddeb66641bf614cc3155f2baa190deb3eb8c5c2c3a","raw_frame":"{\"market\":\"0x779291bef19b6709f61e9764a954aafe9ffae488d50ae674aabdcb4f248006d5\", \"price_changes\":[{\"asset_id\":\"8761897749749422724209054078244794145777693856614463256546737399611489089783\", \"price\":\"0.5\", \"size\":\"108\", \"side\":\"BUY\", \"hash\":\"fccb6cd51cf6fa9fc79837b760da189596c9dfce\", \"best_bid\":\"0.58\", \"best_ask\":\"0.59\"}, {\"asset_id\":\"14965588658799411272385430903075831224615961675357217884735713260981483529984\", \"price\":\"0.5\", \"size\":\"108\", \"side\":\"SELL\", \"hash\":\"7ac6a0d62ecca116487fd9bad7e46576d2865c90\", \"best_bid\":\"0.41\", \"best_ask\":\"0.42\"}], \"timestamp\":\"1785208087466\", \"event_type\":\"price_change\"}","received_at":"2026-07-28T03:08:07.454108Z","schema_version":"clob-market-ws.price_change.v1","sequence":null,"server_hash":null,"server_timestamp":"1785208087466","session_id":"3e519d9098404c15b234d96025eb1a2b","source":"clob_market_ws"},"received_at":"2026-07-28T03:08:07.454108Z","record_id":"aeb98029ba476c8ade1d810c9678f1085d6ce8bbf642ec55b94ad2c03d1912c6","schema_fingerprint":"4aa3821a28b0b7c2400bc59aba4bcc0a76e971dadd19610d3ad38c768e124dc7","schema_version":"edge-lab-recorder.raw.v1","sequence":null,"source":"clob_market_ws"}
{"event_at":"2026-07-28T03:08:07.467000Z","event_fingerprint":"3d5c321e38be97fe607a285f88774b8cc81b5c4c1623b1973561903dcb519468","payload":{"connection_id":"a6b55582af5f430fb37ad02bf0922475","event_at":"2026-07-28T03:08:07.467000Z","event_type":"price_change","frame_hash":"670109b88847b995839d6cece693fff35b82b158c67db9914e58fb5cd60dced7","frame_index":0,"kind":"data","monotonic_ns":310070487955333,"payload":{"event_type":"price_change","market":"0x779291bef19b6709f61e9764a954aafe9ffae488d50ae674aabdcb4f248006d5","price_changes":[{"asset_id":"8761897749749422724209054078244794145777693856614463256546737399611489089783","best_ask":"0.59","best_bid":"0.58","hash":"ce758e9fc14600bc2a5f12600288966b2e579138","price":"0.49","side":"BUY","size":"115.5"},{"asset_id":"14965588658799411272385430903075831224615961675357217884735713260981483529984","best_ask":"0.42","best_bid":"0.41","hash":"1a87e73ddfaf2ccf9ca14dd00d9341b4ad125114","price":"0.51","side":"SELL","size":"115.5"}],"timestamp":"1785208087467"},"payload_hash":"b567ab348041ff672dc3316a483443a1d67f5b6b027b819a314a256aae7d9a85","raw_frame":"{\"market\":\"0x779291bef19b6709f61e9764a954aafe9ffae488d50ae674aabdcb4f248006d5\", \"price_changes\":[{\"asset_id\":\"8761897749749422724209054078244794145777693856614463256546737399611489089783\", \"price\":\"0.49\", \"size\":\"115.5\", \"side\":\"BUY\", \"hash\":\"ce758e9fc14600bc2a5f12600288966b2e579138\", \"best_bid\":\"0.58\", \"best_ask\":\"0.59\"}, {\"asset_id\":\"14965588658799411272385430903075831224615961675357217884735713260981483529984\", \"price\":\"0.51\", \"size\":\"115.5\", \"side\":\"SELL\", \"hash\":\"1a87e73ddfaf2ccf9ca14dd00d9341b4ad125114\", \"best_bid\":\"0.41\", \"best_ask\":\"0.42\"}], \"timestamp\":\"1785208087467\", \"event_type\":\"price_change\"}","received_at":"2026-07-28T03:08:07.455622Z","schema_version":"clob-market-ws.price_change.v1","sequence":null,"server_hash":null,"server_timestamp":"1785208087467","session_id":"3e519d9098404c15b234d96025eb1a2b","source":"clob_market_ws"},"received_at":"2026-07-28T03:08:07.455622Z","record_id":"21e4895b4c842c51b328a5bf31dc8af7ff0f6b72aa6d734e44d57193ee550f69","schema_fingerprint":"4aa3821a28b0b7c2400bc59aba4bcc0a76e971dadd19610d3ad38c768e124dc7","schema_version":"edge-lab-recorder.raw.v1","sequence":null,"source":"clob_market_ws"}
{"event_at":"2026-07-28T03:08:07.468000Z","event_fingerprint":"5ec1b34abc8c2703e6de6a9beb3ab865c88b03aeb66e0a3efd09483edc3b46d7","payload":{"connection_id":"a6b55582af5f430fb37ad02bf0922475","event_at":"2026-07-28T03:08:07.468000Z","event_type":"price_change","frame_hash":"bf0ed7bc7b8674750c5ef4425f9f33a0bb4c2715269d1980bb90daf6751511b3","frame_index":0,"kind":"data","monotonic_ns":310070489420333,"payload":{"event_type":"price_change","market":"0x779291bef19b6709f61e9764a954aafe9ffae488d50ae674aabdcb4f248006d5","price_changes":[{"asset_id":"14965588658799411272385430903075831224615961675357217884735713260981483529984","best_ask":"0.42","best_bid":"0.41","hash":"8ba4bcf16f7e3234b5d392b5462b87fd3f6bca6d","price":"0.41","side":"BUY","size":"552.2"},{"asset_id":"8761897749749422724209054078244794145777693856614463256546737399611489089783","best_ask":"0.59","best_bid":"0.58","hash":"f2c8efb45fb7e7242c6af9769615027e1a7f7cb6","price":"0.59","side":"SELL","size":"552.2"}],"timestamp":"1785208087468"},"payload_hash":"ff94b8ff7d81b15daa30432b64c952ee0d47db9d9c0be4185a9d5cee8d5748c7","raw_frame":"{\"market\":\"0x779291bef19b6709f61e9764a954aafe9ffae488d50ae674aabdcb4f248006d5\", \"price_changes\":[{\"asset_id\":\"14965588658799411272385430903075831224615961675357217884735713260981483529984\", \"price\":\"0.41\", \"size\":\"552.2\", \"side\":\"BUY\", \"hash\":\"8ba4bcf16f7e3234b5d392b5462b87fd3f6bca6d\", \"best_bid\":\"0.41\", \"best_ask\":\"0.42\"}, {\"asset_id\":\"8761897749749422724209054078244794145777693856614463256546737399611489089783\", \"price\":\"0.59\", \"size\":\"552.2\", \"side\":\"SELL\", \"hash\":\"f2c8efb45fb7e7242c6af9769615027e1a7f7cb6\", \"best_bid\":\"0.58\", \"best_ask\":\"0.59\"}], \"timestamp\":\"1785208087468\", \"event_type\":\"price_change\"}","received_at":"2026-07-28T03:08:07.457086Z","schema_version":"clob-market-ws.price_change.v1","sequence":null,"server_hash":null,"server_timestamp":"1785208087468","session_id":"3e519d9098404c15b234d96025eb1a2b","source":"clob_market_ws"},"received_at":"2026-07-28T03:08:07.457086Z","record_id":"d7e34b0b924afbe56fcab016d6eabc00ffdd2ffefb00d11a6154395bff441757","schema_fingerprint":"4aa3821a28b0b7c2400bc59aba4bcc0a76e971dadd19610d3ad38c768e124dc7","schema_version":"edge-lab-recorder.raw.v1","sequence":null,"source":"clob_market_ws"}
{"event_at":"2026-07-28T03:08:07.486000Z","event_fingerprint":"7706151f2349b811d70f6e692eb56339ace914a73c3bb687cc5a026d71a1805c","payload":{"connection_id":"a6b55582af5f430fb37ad02bf0922475","event_at":"2026-07-28T03:08:07.486000Z","event_type":"price_change","frame_hash":"e80e721098962ed1f0e03d33731e9af33afb43a6b9bfccace203d53b99ec81c3","frame_index":0,"kind":"data","monotonic_ns":310070490922458,"payload":{"event_type":"price_change","market":"0x779291bef19b6709f61e9764a954aafe9ffae488d50ae674aabdcb4f248006d5","price_changes":[{"asset_id":"8761897749749422724209054078244794145777693856614463256546737399611489089783","best_ask":"0.59","best_bid":"0.58","hash":"cb4035a1492948ba1fdc1019c0eb9e1cf4fd7785","price":"0.51","side":"BUY","size":"162"},{"asset_id":"14965588658799411272385430903075831224615961675357217884735713260981483529984","best_ask":"0.42","best_bid":"0.41","hash":"f8d8e3fa5887bb0c3f982ff031b6ef509edb160c","price":"0.49","side":"SELL","size":"162"}],"timestamp":"1785208087486"},"payload_hash":"4712c232af163940e2fd6745d8b044650b41413eeda9a49bfd61e2d93b615b5f","raw_frame":"{\"market\":\"0x779291bef19b6709f61e9764a954aafe9ffae488d50ae674aabdcb4f248006d5\", \"price_changes\":[{\"asset_id\":\"8761897749749422724209054078244794145777693856614463256546737399611489089783\", \"price\":\"0.51\", \"size\":\"162\", \"side\":\"BUY\", \"hash\":\"cb4035a1492948ba1fdc1019c0eb9e1cf4fd7785\", \"best_bid\":\"0.58\", \"best_ask\":\"0.59\"}, {\"asset_id\":\"14965588658799411272385430903075831224615961675357217884735713260981483529984\", \"price\":\"0.49\", \"size\":\"162\", \"side\":\"SELL\", \"hash\":\"f8d8e3fa5887bb0c3f982ff031b6ef509edb160c\", \"best_bid\":\"0.41\", \"best_ask\":\"0.42\"}], \"timestamp\":\"1785208087486\", \"event_type\":\"price_change\"}","received_at":"2026-07-28T03:08:07.458589Z","schema_version":"clob-market-ws.price_change.v1","sequence":null,"server_hash":null,"server_timestamp":"1785208087486","session_id":"3e519d9098404c15b234d96025eb1a2b","source":"clob_market_ws"},"received_at":"2026-07-28T03:08:07.458589Z","record_id":"0186a71ccaa1d2971346247e8c962d3cc65279b16d41d343cb2b455643d302fb","schema_fingerprint":"4aa3821a28b0b7c2400bc59aba4bcc0a76e971dadd19610d3ad38c768e124dc7","schema_version":"edge-lab-recorder.raw.v1","sequence":null,"source":"clob_market_ws"}
{"event_at":"2026-07-28T03:08:07.493000Z","event_fingerprint":"f0d22609c596bc7c4a7d44c8d72bbf183cd5b53a3a6ea3d70285c7906a6e2645","payload":{"connection_id":"a6b55582af5f430fb37ad02bf0922475","event_at":"2026-07-28T03:08:07.493000Z","event_type":"price_change","frame_hash":"e00ff99fd387d9db3022baf943524f2838bdd804642d7f2250c6ff78fbd90dd4","frame_index":0,"kind":"data","monotonic_ns":310070492501375,"payload":{"event_type":"price_change","market":"0x779291bef19b6709f61e9764a954aafe9ffae488d50ae674aabdcb4f248006d5","price_changes":[{"asset_id":"14965588658799411272385430903075831224615961675357217884735713260981483529984","best_ask":"0.42","best_bid":"0.41","hash":"46dead962f209f0b7f14b50bcbdb95d449c09775","price":"0.41","side":"BUY","size":"601.2"},{"asset_id":"8761897749749422724209054078244794145777693856614463256546737399611489089783","best_ask":"0.59","best_bid":"0.58","hash":"3a2af34c6e169cac82befd7c9a72b95d8786d41d","price":"0.59","side":"SELL","size":"601.2"}],"timestamp":"1785208087493"},"payload_hash":"5e1e315c236bd5dd650f869d4fa7bb0c60952f7996a6468d06e41845048d64cf","raw_frame":"{\"market\":\"0x779291bef19b6709f61e9764a954aafe9ffae488d50ae674aabdcb4f248006d5\", \"price_changes\":[{\"asset_id\":\"14965588658799411272385430903075831224615961675357217884735713260981483529984\", \"price\":\"0.41\", \"size\":\"601.2\", \"side\":\"BUY\", \"hash\":\"46dead962f209f0b7f14b50bcbdb95d449c09775\", \"best_bid\":\"0.41\", \"best_ask\":\"0.42\"}, {\"asset_id\":\"8761897749749422724209054078244794145777693856614463256546737399611489089783\", \"price\":\"0.59\", \"size\":\"601.2\", \"side\":\"SELL\", \"hash\":\"3a2af34c6e169cac82befd7c9a72b95d8786d41d\", \"best_bid\":\"0.58\", \"best_ask\":\"0.59\"}], \"timestamp\":\"1785208087493\", \"event_type\":\"price_change\"}","received_at":"2026-07-28T03:08:07.460166Z","schema_version":"clob-market-ws.price_change.v1","sequence":null,"server_hash":null,"server_timestamp":"1785208087493","session_id":"3e519d9098404c15b234d96025eb1a2b","source":"clob_market_ws"},"received_at":"2026-07-28T03:08:07.460166Z","record_id":"41d8949c6714b34f8355ff1b6c7fb4d3863d755e396494db7eda971bb3a56421","schema_fingerprint":"4aa3821a28b0b7c2400bc59aba4bcc0a76e971dadd19610d3ad38c768e124dc7","schema_version":"edge-lab-recorder.raw.v1","sequence":null,"source":"clob_market_ws"}
{"event_at":"2026-07-28T03:08:07.494000Z","event_fingerprint":"99a17cfc943ec9ae110f2165d13e4a886018276d80ac9a7fc68bcd5cfed476bb","payload":{"connection_id":"a6b55582af5f430fb37ad02bf0922475","event_at":"2026-07-28T03:08:07.494000Z","event_type":"price_change","frame_hash":"312d632cd95e620ee2b83c932af1802117388c0a3ec2c6d0b270c5a4a43e1176","frame_index":0,"kind":"data","monotonic_ns":310070494365750,"payload":{"event_type":"price_change","market":"0x779291bef19b6709f61e9764a954aafe9ffae488d50ae674aabdcb4f248006d5","price_changes":[{"asset_id":"8761897749749422724209054078244794145777693856614463256546737399611489089783","best_ask":"0.59","best_bid":"0.58","hash":"c0137fd17a4fc8284e0b869145f32df495bb728a","price":"0.52","side":"BUY","size":"21"},{"asset_id":"14965588658799411272385430903075831224615961675357217884735713260981483529984","best_ask":"0.42","best_bid":"0.41","hash":"f2c91fe68b2ec416afae6eec2f72cc7dbc752279","price":"0.48","side":"SELL","size":"21"}],"timestamp":"1785208087494"},"payload_hash":"6a9fccffe8f5adf965438b41958a05dc290cb6ecd143a30c395c9f55de766572","raw_frame":"{\"market\":\"0x779291bef19b6709f61e9764a954aafe9ffae488d50ae674aabdcb4f248006d5\", \"price_changes\":[{\"asset_id\":\"8761897749749422724209054078244794145777693856614463256546737399611489089783\", \"price\":\"0.52\", \"size\":\"21\", \"side\":\"BUY\", \"hash\":\"c0137fd17a4fc8284e0b869145f32df495bb728a\", \"best_bid\":\"0.58\", \"best_ask\":\"0.59\"}, {\"asset_id\":\"14965588658799411272385430903075831224615961675357217884735713260981483529984\", \"price\":\"0.48\", \"size\":\"21\", \"side\":\"SELL\", \"hash\":\"f2c91fe68b2ec416afae6eec2f72cc7dbc752279\", \"best_bid\":\"0.41\", \"best_ask\":\"0.42\"}], \"timestamp\":\"1785208087494\", \"event_type\":\"price_change\"}","received_at":"2026-07-28T03:08:07.462032Z","schema_version":"clob-market-ws.price_change.v1","sequence":null,"server_hash":null,"server_timestamp":"1785208087494","session_id":"3e519d9098404c15b234d96025eb1a2b","source":"clob_market_ws"},"received_at":"2026-07-28T03:08:07.462032Z","record_id":"e071637458cfad9fb02c427812a55e8ac21f1646f633869b50d468b92fc2d0ee","schema_fingerprint":"4aa3821a28b0b7c2400bc59aba4bcc0a76e971dadd19610d3ad38c768e124dc7","schema_version":"edge-lab-recorder.raw.v1","sequence":null,"source":"clob_market_ws"}
{"event_at":"2026-07-28T03:08:07.497000Z","event_fingerprint":"d746981963a2fd2257b285b57074037d877ccfb515d272f0d6cc63771b4623d6","payload":{"connection_id":"a6b55582af5f430fb37ad02bf0922475","event_at":"2026-07-28T03:08:07.497000Z","event_type":"price_change","frame_hash":"f8011aec7a6955a442b9a9e6d026503ab39fbbb2932cf45908fbd259f45de867","frame_index":0,"kind":"data","monotonic_ns":310070495860791,"payload":{"event_type":"price_change","market":"0x779291bef19b6709f61e9764a954aafe9ffae488d50ae674aabdcb4f248006d5","price_changes":[{"asset_id":"8761897749749422724209054078244794145777693856614463256546737399611489089783","best_ask":"0.59","best_bid":"0.58","hash":"4c8ee4ec5dfb7f9df1e3416be5b5ca8c32eced65","price":"0.51","side":"BUY","size":"143"},{"asset_id":"14965588658799411272385430903075831224615961675357217884735713260981483529984","best_ask":"0.42","best_bid":"0.41","hash":"b3140c9f799b9c52457181d33fd55331af1e8e50","price":"0.49","side":"SELL","size":"143"}],"timestamp":"1785208087497"},"payload_hash":"49a003889b1917d95347b88dbe0d66f8477e6d17c6a6c971a04ffed45eebec19","raw_frame":"{\"market\":\"0x779291bef19b6709f61e9764a954aafe9ffae488d50ae674aabdcb4f248006d5\", \"price_changes\":[{\"asset_id\":\"8761897749749422724209054078244794145777693856614463256546737399611489089783\", \"price\":\"0.51\", \"size\":\"143\", \"side\":\"BUY\", \"hash\":\"4c8ee4ec5dfb7f9df1e3416be5b5ca8c32eced65\", \"best_bid\":\"0.58\", \"best_ask\":\"0.59\"}, {\"asset_id\":\"14965588658799411272385430903075831224615961675357217884735713260981483529984\", \"price\":\"0.49\", \"size\":\"143\", \"side\":\"SELL\", \"hash\":\"b3140c9f799b9c52457181d33fd55331af1e8e50\", \"best_bid\":\"0.41\", \"best_ask\":\"0.42\"}], \"timestamp\":\"1785208087497\", \"event_type\":\"price_change\"}","received_at":"2026-07-28T03:08:07.463526Z","schema_version":"clob-market-ws.price_change.v1","sequence":null,"server_hash":null,"server_timestamp":"1785208087497","session_id":"3e519d9098404c15b234d96025eb1a2b","source":"clob_market_ws"},"received_at":"2026-07-28T03:08:07.463526Z","record_id":"6313ea992c7a2d36449fb69b3230c637166bda9b4457133774560682118c7460","schema_fingerprint":"4aa3821a28b0b7c2400bc59aba4bcc0a76e971dadd19610d3ad38c768e124dc7","schema_version":"edge-lab-recorder.raw.v1","sequence":null,"source":"clob_market_ws"}
{"event_at":"2026-07-28T03:08:07.497000Z","event_fingerprint":"8f8f5b1fb79aa2e5a1117f75e00b18dffaddd52b0d346ceed0d9fdcb659607be","payload":{"connection_id":"a6b55582af5f430fb37ad02bf0922475","event_at":"2026-07-28T03:08:07.497000Z","event_type":"price_change","frame_hash":"e26a9dbaf12e67c987acbbe4ea11c846d8d22f61e008777da8590748a2b17976","frame_index":0,"kind":"data","monotonic_ns":310070497383083,"payload":{"event_type":"price_change","market":"0x779291bef19b6709f61e9764a954aafe9ffae488d50ae674aabdcb4f248006d5","price_changes":[{"asset_id":"8761897749749422724209054078244794145777693856614463256546737399611489089783","best_ask":"0.59","best_bid":"0.58","hash":"e124b7812bdd9184b6d2c194e38825b02ceae725","price":"0.45","side":"BUY","size":"157"},{"asset_id":"14965588658799411272385430903075831224615961675357217884735713260981483529984","best_ask":"0.42","best_bid":"0.41","hash":"de86e395519b15911fd7143ca2c6fa872b413933","price":"0.55","side":"SELL","size":"157"}],"timestamp":"1785208087497"},"payload_hash":"43ea873350b5d9fcc7f6254d88df5781ca31c50832cfa25183cc0832c545ec17","raw_frame":"{\"market\":\"0x779291bef19b6709f61e9764a954aafe9ffae488d50ae674aabdcb4f248006d5\", \"price_changes\":[{\"asset_id\":\"8761897749749422724209054078244794145777693856614463256546737399611489089783\", \"price\":\"0.45\", \"size\":\"157\", \"side\":\"BUY\", \"hash\":\"e124b7812bdd9184b6d2c194e38825b02ceae725\", \"best_bid\":\"0.58\", \"best_ask\":\"0.59\"}, {\"asset_id\":\"14965588658799411272385430903075831224615961675357217884735713260981483529984\", \"price\":\"0.55\", \"size\":\"157\", \"side\":\"SELL\", \"hash\":\"de86e395519b15911fd7143ca2c6fa872b413933\", \"best_bid\":\"0.41\", \"best_ask\":\"0.42\"}], \"timestamp\":\"1785208087497\", \"event_type\":\"price_change\"}","received_at":"2026-07-28T03:08:07.465049Z","schema_version":"clob-market-ws.price_change.v1","sequence":null,"server_hash":null,"server_timestamp":"1785208087497","session_id":"3e519d9098404c15b234d96025eb1a2b","source":"clob_market_ws"},"received_at":"2026-07-28T03:08:07.465049Z","record_id":"e8f9073353fe7bbd68553792375e1f9fb5a934ba9bd3f31225ee2807e8176148","schema_fingerprint":"4aa3821a28b0b7c2400bc59aba4bcc0a76e971dadd19610d3ad38c768e124dc7","schema_version":"edge-lab-recorder.raw.v1","sequence":null,"source":"clob_market_ws"}
{"event_at":"2026-07-28T03:08:07.499000Z","event_fingerprint":"e229b09851e73e615f05311d782f6ba22016d10a68858d8db8398ca759b0b969","payload":{"connection_id":"a6b55582af5f430fb37ad02bf0922475","event_at":"2026-07-28T03:08:07.499000Z","event_type":"price_change","frame_hash":"e9110d93f175a4cf62a258dc7c1bcc0e0e791752719cc533af1ded34c2d34182","frame_index":0,"kind":"data","monotonic_ns":310070498889625,"payload":{"event_type":"price_change","market":"0x779291bef19b6709f61e9764a954aafe9ffae488d50ae674aabdcb4f248006d5","price_changes":[{"asset_id":"8761897749749422724209054078244794145777693856614463256546737399611489089783","best_ask":"0.59","best_bid":"0.58","hash":"daa78df4dd9e79ab36b4a87e807748ae99d7e877","price":"0.51","side":"BUY","size":"413"},{"asset_id":"14965588658799411272385430903075831224615961675357217884735713260981483529984","best_ask":"0.42","best_bid":"0.41","hash":"78301ca24097a838a28f7c5bf5139f29119155bf","price":"0.49","side":"SELL","size":"413"}],"timestamp":"1785208087499"},"payload_hash":"ead3e82d114ecb6000934bffaf4165b552ec1bbdce455ced50a782bc0a293a87","raw_frame":"{\"market\":\"0x779291bef19b6709f61e9764a954aafe9ffae488d50ae674aabdcb4f248006d5\", \"price_changes\":[{\"asset_id\":\"8761897749749422724209054078244794145777693856614463256546737399611489089783\", \"price\":\"0.51\", \"size\":\"413\", \"side\":\"BUY\", \"hash\":\"daa78df4dd9e79ab36b4a87e807748ae99d7e877\", \"best_bid\":\"0.58\", \"best_ask\":\"0.59\"}, {\"asset_id\":\"14965588658799411272385430903075831224615961675357217884735713260981483529984\", \"price\":\"0.49\", \"size\":\"413\", \"side\":\"SELL\", \"hash\":\"78301ca24097a838a28f7c5bf5139f29119155bf\", \"best_bid\":\"0.41\", \"best_ask\":\"0.42\"}], \"timestamp\":\"1785208087499\", \"event_type\":\"price_change\"}","received_at":"2026-07-28T03:08:07.466556Z","schema_version":"clob-market-ws.price_change.v1","sequence":null,"server_hash":null,"server_timestamp":"1785208087499","session_id":"3e519d9098404c15b234d96025eb1a2b","source":"clob_market_ws"},"received_at":"2026-07-28T03:08:07.466556Z","record_id":"36278d46715b7afc0b4c115eeae2d3f804ab653e86ca4511968ea4ae9772e5d9","schema_fingerprint":"4aa3821a28b0b7c2400bc59aba4bcc0a76e971dadd19610d3ad38c768e124dc7","schema_version":"edge-lab-recorder.raw.v1","sequence":null,"source":"clob_market_ws"}
{"event_at":"2026-07-28T03:08:07.501000Z","event_fingerprint":"5f4759243ddb62d53fd9a69f160ac97af87688719c170e2b6db8f67594a38190","payload":{"connection_id":"a6b55582af5f430fb37ad02bf0922475","event_at":"2026-07-28T03:08:07.501000Z","event_type":"price_change","frame_hash":"6beeb29f274daa200fe33f11b6c726e553f1d1ae2090a57e4b5d31702ee937f7","frame_index":0,"kind":"data","monotonic_ns":310070500385625,"payload":{"event_type":"price_change","market":"0x779291bef19b6709f61e9764a954aafe9ffae488d50ae674aabdcb4f248006d5","price_changes":[{"asset_id":"14965588658799411272385430903075831224615961675357217884735713260981483529984","best_ask":"0.42","best_bid":"0.41","hash":"badafe822d2c23171e4f7d839266fe42f418b1fd","price":"0.49","side":"SELL","size":"428.06"},{"asset_id":"8761897749749422724209054078244794145777693856614463256546737399611489089783","best_ask":"0.59","best_bid":"0.58","hash":"393062513e80cdb887dbbe7dc08fe510e3a03333","price":"0.51","side":"BUY","size":"428.06"}],"timestamp":"1785208087501"},"payload_hash":"f738185801c6b716f62088d8afa19aa6b6bd970371735d20828c8ace62ec1e11","raw_frame":"{\"market\":\"0x779291bef19b6709f61e9764a954aafe9ffae488d50ae674aabdcb4f248006d5\", \"price_changes\":[{\"asset_id\":\"14965588658799411272385430903075831224615961675357217884735713260981483529984\", \"price\":\"0.49\", \"size\":\"428.06\", \"side\":\"SELL\", \"hash\":\"badafe822d2c23171e4f7d839266fe42f418b1fd\", \"best_bid\":\"0.41\", \"best_ask\":\"0.42\"}, {\"asset_id\":\"8761897749749422724209054078244794145777693856614463256546737399611489089783\", \"price\":\"0.51\", \"size\":\"428.06\", \"side\":\"BUY\", \"hash\":\"393062513e80cdb887dbbe7dc08fe510e3a03333\", \"best_bid\":\"0.58\", \"best_ask\":\"0.59\"}], \"timestamp\":\"1785208087501\", \"event_type\":\"price_change\"}","received_at":"2026-07-28T03:08:07.468052Z","schema_version":"clob-market-ws.price_change.v1","sequence":null,"server_hash":null,"server_timestamp":"1785208087501","session_id":"3e519d9098404c15b234d96025eb1a2b","source":"clob_market_ws"},"received_at":"2026-07-28T03:08:07.468052Z","record_id":"9346d61aa71489fb3b154464556b9bdea113683342c8c7aadfb95758ca509f09","schema_fingerprint":"4aa3821a28b0b7c2400bc59aba4bcc0a76e971dadd19610d3ad38c768e124dc7","schema_version":"edge-lab-recorder.raw.v1","sequence":null,"source":"clob_market_ws"}
{"event_at":"2026-07-28T03:08:07.502000Z","event_fingerprint":"db9ff86b79fe7e89ec9f6d486d32d6c3459e0862ff9322d9085601558a2acdce","payload":{"connection_id":"a6b55582af5f430fb37ad02bf0922475","event_at":"2026-07-28T03:08:07.502000Z","event_type":"price_change","frame_hash":"c78ed80b9f4861847541df0ec20b33e2887cf334d8d2935d3109b66a3358d864","frame_index":0,"kind":"data","monotonic_ns":310070501860583,"payload":{"event_type":"price_change","market":"0x779291bef19b6709f61e9764a954aafe9ffae488d50ae674aabdcb4f248006d5","price_changes":[{"asset_id":"8761897749749422724209054078244794145777693856614463256546737399611489089783","best_ask":"0.59","best_bid":"0.58","hash":"38afb82eddcf4e8ac4030a72cfb4ef606a02f971","price":"0.27","side":"BUY","size":"328.1"},{"asset_id":"14965588658799411272385430903075831224615961675357217884735713260981483529984","best_ask":"0.42","best_bid":"0.41","hash":"37625763d7a2048468b7b52767d39c11573b5908","price":"0.73","side":"SELL","size":"328.1"}],"timestamp":"1785208087502"},"payload_hash":"cc2d86d657f845c621bbe3cfddbf15b36b106ac301bf79816e1c44df0524548f","raw_frame":"{\"market\":\"0x779291bef19b6709f61e9764a954aafe9ffae488d50ae674aabdcb4f248006d5\", \"price_changes\":[{\"asset_id\":\"8761897749749422724209054078244794145777693856614463256546737399611489089783\", \"price\":\"0.27\", \"size\":\"328.1\", \"side\":\"BUY\", \"hash\":\"38afb82eddcf4e8ac4030a72cfb4ef606a02f971\", \"best_bid\":\"0.58\", \"best_ask\":\"0.59\"}, {\"asset_id\":\"14965588658799411272385430903075831224615961675357217884735713260981483529984\", \"price\":\"0.73\", \"size\":\"328.1\", \"side\":\"SELL\", \"hash\":\"37625763d7a2048468b7b52767d39c11573b5908\", \"best_bid\":\"0.41\", \"best_ask\":\"0.42\"}], \"timestamp\":\"1785208087502\", \"event_type\":\"price_change\"}","received_at":"2026-07-28T03:08:07.469527Z","schema_version":"clob-market-ws.price_change.v1","sequence":null,"server_hash":null,"server_timestamp":"1785208087502","session_id":"3e519d9098404c15b234d96025eb1a2b","source":"clob_market_ws"},"received_at":"2026-07-28T03:08:07.469527Z","record_id":"d775c408d001e5b783b472ba694ec06af19c039edd5e3b0f4db59b2b416da827","schema_fingerprint":"4aa3821a28b0b7c2400bc59aba4bcc0a76e971dadd19610d3ad38c768e124dc7","schema_version":"edge-lab-recorder.raw.v1","sequence":null,"source":"clob_market_ws"}
{"event_at":"2026-07-28T03:08:07.503000Z","event_fingerprint":"1a742928a336157fc214136b42c2018ea151e77b3d1a2774a84429b628668567","payload":{"connection_id":"a6b55582af5f430fb37ad02bf0922475","event_at":"2026-07-28T03:08:07.503000Z","event_type":"price_change","frame_hash":"9a153780b779d4b55582b35ae6d4f21d76b8027156abc99fb6fbccdd2ef3f12a","frame_index":0,"kind":"data","monotonic_ns":310070503345166,"payload":{"event_type":"price_change","market":"0x779291bef19b6709f61e9764a954aafe9ffae488d50ae674aabdcb4f248006d5","price_changes":[{"asset_id":"14965588658799411272385430903075831224615961675357217884735713260981483529984","best_ask":"0.42","best_bid":"0.41","hash":"1e5152d65f33cc9437c7ddf5774e90db06a1893c","price":"0.29","side":"BUY","size":"119.6"},{"asset_id":"8761897749749422724209054078244794145777693856614463256546737399611489089783","best_ask":"0.59","best_bid":"0.58","hash":"97c18a41314250a5a6bd8473f03d05d1df2d1c2f","price":"0.71","side":"SELL","size":"119.6"}],"timestamp":"1785208087503"},"payload_hash":"4bfa03bb9206e755f73effabc1bbb3e5ef4dd82bfa9f68def39e45b0cd8f2f29","raw_frame":"{\"market\":\"0x779291bef19b6709f61e9764a954aafe9ffae488d50ae674aabdcb4f248006d5\", \"price_changes\":[{\"asset_id\":\"14965588658799411272385430903075831224615961675357217884735713260981483529984\", \"price\":\"0.29\", \"size\":\"119.6\", \"side\":\"BUY\", \"hash\":\"1e5152d65f33cc9437c7ddf5774e90db06a1893c\", \"best_bid\":\"0.41\", \"best_ask\":\"0.42\"}, {\"asset_id\":\"8761897749749422724209054078244794145777693856614463256546737399611489089783\", \"price\":\"0.71\", \"size\":\"119.6\", \"side\":\"SELL\", \"hash\":\"97c18a41314250a5a6bd8473f03d05d1df2d1c2f\", \"best_bid\":\"0.58\", \"best_ask\":\"0.59\"}], \"timestamp\":\"1785208087503\", \"event_type\":\"price_change\"}","received_at":"2026-07-28T03:08:07.471012Z","schema_version":"clob-market-ws.price_change.v1","sequence":null,"server_hash":null,"server_timestamp":"1785208087503","session_id":"3e519d9098404c15b234d96025eb1a2b","source":"clob_market_ws"},"received_at":"2026-07-28T03:08:07.471012Z","record_id":"23808982ad895cc664bd3cabf78bf28e43303c1e510481a73dc5db291d21d3bd","schema_fingerprint":"4aa3821a28b0b7c2400bc59aba4bcc0a76e971dadd19610d3ad38c768e124dc7","schema_version":"edge-lab-recorder.raw.v1","sequence":null,"source":"clob_market_ws"}
{"event_at":"2026-07-28T03:08:07.504000Z","event_fingerprint":"c21eb0bfcf204419b4a9a3943998c1b2dc45190d42cff29f4907a3db65ce364f","payload":{"connection_id":"a6b55582af5f430fb37ad02bf0922475","event_at":"2026-07-28T03:08:07.504000Z","event_type":"price_change","frame_hash":"933d814324e94fae76b4f7f15320668a70e89369b4e668739d173580a587ec35","frame_index":0,"kind":"data","monotonic_ns":310070504842333,"payload":{"event_type":"price_change","market":"0x779291bef19b6709f61e9764a954aafe9ffae488d50ae674aabdcb4f248006d5","price_changes":[{"asset_id":"8761897749749422724209054078244794145777693856614463256546737399611489089783","best_ask":"0.59","best_bid":"0.58","hash":"70574440c78799fe919d252d7239d1ea0c69db60","price":"0.51","side":"BUY","size":"467.06"},{"asset_id":"14965588658799411272385430903075831224615961675357217884735713260981483529984","best_ask":"0.42","best_bid":"0.41","hash":"6192add08c70e66509239cac0a5492eac333e14a","price":"0.49","side":"SELL","size":"467.06"}],"timestamp":"1785208087504"},"payload_hash":"c826b6e0621e57ab13cbdccb569a44eb4eac7e365e0dd4537f701dd6f2cb4152","raw_frame":"{\"market\":\"0x779291bef19b6709f61e9764a954aafe9ffae488d50ae674aabdcb4f248006d5\", \"price_changes\":[{\"asset_id\":\"8761897749749422724209054078244794145777693856614463256546737399611489089783\", \"price\":\"0.51\", \"size\":\"467.06\", \"side\":\"BUY\", \"hash\":\"70574440c78799fe919d252d7239d1ea0c69db60\", \"best_bid\":\"0.58\", \"best_ask\":\"0.59\"}, {\"asset_id\":\"14965588658799411272385430903075831224615961675357217884735713260981483529984\", \"price\":\"0.49\", \"size\":\"467.06\", \"side\":\"SELL\", \"hash\":\"6192add08c70e66509239cac0a5492eac333e14a\", \"best_bid\":\"0.41\", \"best_ask\":\"0.42\"}], \"timestamp\":\"1785208087504\", \"event_type\":\"price_change\"}","received_at":"2026-07-28T03:08:07.472509Z","schema_version":"clob-market-ws.price_change.v1","sequence":null,"server_hash":null,"server_timestamp":"1785208087504","session_id":"3e519d9098404c15b234d96025eb1a2b","source":"clob_market_ws"},"received_at":"2026-07-28T03:08:07.472509Z","record_id":"c0cf68054125446a362d732aba8926c22ddf86f47ee282ee2ec48ebb8b943fd1","schema_fingerprint":"4aa3821a28b0b7c2400bc59aba4bcc0a76e971dadd19610d3ad38c768e124dc7","schema_version":"edge-lab-recorder.raw.v1","sequence":null,"source":"clob_market_ws"}
{"event_at":"2026-07-28T03:08:07.505000Z","event_fingerprint":"272132d9eab1f26815da209e0cf853a30b0cebe41cecb720aafb34037036a6a8","payload":{"connection_id":"a6b55582af5f430fb37ad02bf0922475","event_at":"2026-07-28T03:08:07.505000Z","event_type":"price_change","frame_hash":"71c0bcb9922ad400a5015dc93a9eee0463b6437d2153110a048ed5381e7b552e","frame_index":0,"kind":"data","monotonic_ns":310070506309791,"payload":{"event_type":"price_change","market":"0x779291bef19b6709f61e9764a954aafe9ffae488d50ae674aabdcb4f248006d5","price_changes":[{"asset_id":"8761897749749422724209054078244794145777693856614463256546737399611489089783","best_ask":"0.59","best_bid":"0.58","hash":"59e277f18b9e7d4894270de7504236a21f4a15de","price":"0.45","side":"BUY","size":"187"},{"asset_id":"14965588658799411272385430903075831224615961675357217884735713260981483529984","best_ask":"0.42","best_bid":"0.41","hash":"4ab6b41bdace2f84bc0e28e6d0cfeb6c8872cf4c","price":"0.55","side":"SELL","size":"187"}],"timestamp":"1785208087505"},"payload_hash":"50bb26d89884d752595c22361739949b2e96890285d2920b042995c223a03e28","raw_frame":"{\"market\":\"0x779291bef19b6709f61e9764a954aafe9ffae488d50ae674aabdcb4f248006d5\", \"price_changes\":[{\"asset_id\":\"8761897749749422724209054078244794145777693856614463256546737399611489089783\", \"price\":\"0.45\", \"size\":\"187\", \"side\":\"BUY\", \"hash\":\"59e277f18b9e7d4894270de7504236a21f4a15de\", \"best_bid\":\"0.58\", \"best_ask\":\"0.59\"}, {\"asset_id\":\"14965588658799411272385430903075831224615961675357217884735713260981483529984\", \"price\":\"0.55\", \"size\":\"187\", \"side\":\"SELL\", \"hash\":\"4ab6b41bdace2f84bc0e28e6d0cfeb6c8872cf4c\", \"best_bid\":\"0.41\", \"best_ask\":\"0.42\"}], \"timestamp\":\"1785208087505\", \"event_type\":\"price_change\"}","received_at":"2026-07-28T03:08:07.473976Z","schema_version":"clob-market-ws.price_change.v1","sequence":null,"server_hash":null,"server_timestamp":"1785208087505","session_id":"3e519d9098404c15b234d96025eb1a2b","source":"clob_market_ws"},"received_at":"2026-07-28T03:08:07.473976Z","record_id":"a8211ce7579ccbaaedb734745e09005be812a95da56b99f611efb3aa00a62e7e","schema_fingerprint":"4aa3821a28b0b7c2400bc59aba4bcc0a76e971dadd19610d3ad38c768e124dc7","schema_version":"edge-lab-recorder.raw.v1","sequence":null,"source":"clob_market_ws"}
{"event_at":"2026-07-28T03:08:07.506000Z","event_fingerprint":"58319c14effb3ef87967708bd81e95f8562ff8756ced8e77b979b9c3d758a85f","payload":{"connection_id":"a6b55582af5f430fb37ad02bf0922475","event_at":"2026-07-28T03:08:07.506000Z","event_type":"price_change","frame_hash":"098847ea9a70d6a778457adad41101a6d151b934a138982db647855964baa258","frame_index":0,"kind":"data","monotonic_ns":310070507785708,"payload":{"event_type":"price_change","market":"0x779291bef19b6709f61e9764a954aafe9ffae488d50ae674aabdcb4f248006d5","price_changes":[{"asset_id":"8761897749749422724209054078244794145777693856614463256546737399611489089783","best_ask":"0.59","best_bid":"0.58","hash":"238fcd2a2b29ea59f6736b5d03029d101fd2676f","price":"0.45","side":"BUY","size":"217"},{"asset_id":"14965588658799411272385430903075831224615961675357217884735713260981483529984","best_ask":"0.42","best_bid":"0.41","hash":"e36168a93f38f5afb12d8883700a8b3060bb5c8e","price":"0.55","side":"SELL","size":"217"}],"timestamp":"1785208087506"},"payload_hash":"7445a418bffb8bd6a5e5510caa91872ecd28eb17a865ec3a5541f74b0122770a","raw_frame":"{\"market\":\"0x779291bef19b6709f61e9764a954aafe9ffae488d50ae674aabdcb4f248006d5\", \"price_changes\":[{\"asset_id\":\"8761897749749422724209054078244794145777693856614463256546737399611489089783\", \"price\":\"0.45\", \"size\":\"217\", \"side\":\"BUY\", \"hash\":\"238fcd2a2b29ea59f6736b5d03029d101fd2676f\", \"best_bid\":\"0.58\", \"best_ask\":\"0.59\"}, {\"asset_id\":\"14965588658799411272385430903075831224615961675357217884735713260981483529984\", \"price\":\"0.55\", \"size\":\"217\", \"side\":\"SELL\", \"hash\":\"e36168a93f38f5afb12d8883700a8b3060bb5c8e\", \"best_bid\":\"0.41\", \"best_ask\":\"0.42\"}], \"timestamp\":\"1785208087506\", \"event_type\":\"price_change\"}","received_at":"2026-07-28T03:08:07.475452Z","schema_version":"clob-market-ws.price_change.v1","sequence":null,"server_hash":null,"server_timestamp":"1785208087506","session_id":"3e519d9098404c15b234d96025eb1a2b","source":"clob_market_ws"},"received_at":"2026-07-28T03:08:07.475452Z","record_id":"b30025c1338b5983e50820d2ea2a16ed26c34fe825a290c7b3116bb564cce61a","schema_fingerprint":"4aa3821a28b0b7c2400bc59aba4bcc0a76e971dadd19610d3ad38c768e124dc7","schema_version":"edge-lab-recorder.raw.v1","sequence":null,"source":"clob_market_ws"}
{"event_at":"2026-07-28T03:08:07.508000Z","event_fingerprint":"d2e14c290612d3c374caabaf936654a3a9efb78f584c017ae5a7973b8534451c","payload":{"connection_id":"a6b55582af5f430fb37ad02bf0922475","event_at":"2026-07-28T03:08:07.508000Z","event_type":"price_change","frame_hash":"46e4ac6612fc65a15e22f65a9ed5b615afe40ad53580ca6f75162f665c8d044a","frame_index":0,"kind":"data","monotonic_ns":310070509256375,"payload":{"event_type":"price_change","market":"0x779291bef19b6709f61e9764a954aafe9ffae488d50ae674aabdcb4f248006d5","price_changes":[{"asset_id":"14965588658799411272385430903075831224615961675357217884735713260981483529984","best_ask":"0.42","best_bid":"0.41","hash":"108ab92459d60eecb23352d66adadc5ba4983852","price":"0.24","side":"BUY","size":"514.15"},{"asset_id":"8761897749749422724209054078244794145777693856614463256546737399611489089783","best_ask":"0.59","best_bid":"0.58","hash":"48974d0df78eb400f543dbd08e33f9b916bf77dc","price":"0.76","side":"SELL","size":"514.15"}],"timestamp":"1785208087508"},"payload_hash":"4cbb972ffb970327e1c572daa6fcbad94aa4fc412c2a5245edf58056ec51954c","raw_frame":"{\"market\":\"0x779291bef19b6709f61e9764a954aafe9ffae488d50ae674aabdcb4f248006d5\", \"price_changes\":[{\"asset_id\":\"14965588658799411272385430903075831224615961675357217884735713260981483529984\", \"price\":\"0.24\", \"size\":\"514.15\", \"side\":\"BUY\", \"hash\":\"108ab92459d60eecb23352d66adadc5ba4983852\", \"best_bid\":\"0.41\", \"best_ask\":\"0.42\"}, {\"asset_id\":\"8761897749749422724209054078244794145777693856614463256546737399611489089783\", \"price\":\"0.76\", \"size\":\"514.15\", \"side\":\"SELL\", \"hash\":\"48974d0df78eb400f543dbd08e33f9b916bf77dc\", \"best_bid\":\"0.58\", \"best_ask\":\"0.59\"}], \"timestamp\":\"1785208087508\", \"event_type\":\"price_change\"}","received_at":"2026-07-28T03:08:07.476922Z","schema_version":"clob-market-ws.price_change.v1","sequence":null,"server_hash":null,"server_timestamp":"1785208087508","session_id":"3e519d9098404c15b234d96025eb1a2b","source":"clob_market_ws"},"received_at":"2026-07-28T03:08:07.476922Z","record_id":"ed267a62b4a68fce0a2c6513f22296fe6cc49f72f8b7534c15c284313259fa4e","schema_fingerprint":"4aa3821a28b0b7c2400bc59aba4bcc0a76e971dadd19610d3ad38c768e124dc7","schema_version":"edge-lab-recorder.raw.v1","sequence":null,"source":"clob_market_ws"}
{"event_at":"2026-07-28T03:08:07.509000Z","event_fingerprint":"745c30c0c6fd46ca107b0bd2f1f16d670819d81cf4c190a5e4c35454e2f30e09","payload":{"connection_id":"a6b55582af5f430fb37ad02bf0922475","event_at":"2026-07-28T03:08:07.509000Z","event_type":"price_change","frame_hash":"05d5a13b65916849e12f70d933743b42cd206b8b58a3032ab4e04d32ecad7346","frame_index":0,"kind":"data","monotonic_ns":310070510750125,"payload":{"event_type":"price_change","market":"0x779291bef19b6709f61e9764a954aafe9ffae488d50ae674aabdcb4f248006d5","price_changes":[{"asset_id":"14965588658799411272385430903075831224615961675357217884735713260981483529984","best_ask":"0.42","best_bid":"0.41","hash":"781ce57acec48ed23672dbd91dcb7e02744ccbfd","price":"0.32","side":"BUY","size":"131.6"},{"asset_id":"8761897749749422724209054078244794145777693856614463256546737399611489089783","best_ask":"0.59","best_bid":"0.58","hash":"32ed6de67a305d62dc4dc60c16ab28a0ef2dd1a5","price":"0.68","side":"SELL","size":"131.6"}],"timestamp":"1785208087509"},"payload_hash":"eb0faa04e6136d76cbebe8f2bb40307a7a2a59cd6e37ad0eae6adb858535f7ec","raw_frame":"{\"market\":\"0x779291bef19b6709f61e9764a954aafe9ffae488d50ae674aabdcb4f248006d5\", \"price_changes\":[{\"asset_id\":\"14965588658799411272385430903075831224615961675357217884735713260981483529984\", \"price\":\"0.32\", \"size\":\"131.6\", \"side\":\"BUY\", \"hash\":\"781ce57acec48ed23672dbd91dcb7e02744ccbfd\", \"best_bid\":\"0.41\", \"best_ask\":\"0.42\"}, {\"asset_id\":\"8761897749749422724209054078244794145777693856614463256546737399611489089783\", \"price\":\"0.68\", \"size\":\"131.6\", \"side\":\"SELL\", \"hash\":\"32ed6de67a305d62dc4dc60c16ab28a0ef2dd1a5\", \"best_bid\":\"0.58\", \"best_ask\":\"0.59\"}], \"timestamp\":\"1785208087509\", \"event_type\":\"price_change\"}","received_at":"2026-07-28T03:08:07.478417Z","schema_version":"clob-market-ws.price_change.v1","sequence":null,"server_hash":null,"server_timestamp":"1785208087509","session_id":"3e519d9098404c15b234d96025eb1a2b","source":"clob_market_ws"},"received_at":"2026-07-28T03:08:07.478417Z","record_id":"a3128481fa6c6ec5a018c24eb072ffd343347a9a5fd035ae041d12a32e2c57d6","schema_fingerprint":"4aa3821a28b0b7c2400bc59aba4bcc0a76e971dadd19610d3ad38c768e124dc7","schema_version":"edge-lab-recorder.raw.v1","sequence":null,"source":"clob_market_ws"}
{"event_at":"2026-07-28T03:08:07.523000Z","event_fingerprint":"3892ee31589c84be1f2616f24231e14fe4e73ae49f3e03c0a587bc5ada264c75","payload":{"connection_id":"a6b55582af5f430fb37ad02bf0922475","event_at":"2026-07-28T03:08:07.523000Z","event_type":"price_change","frame_hash":"44b1732c53f9d9789c31ad20f825aeae69b6b6b9e4c8b0fce08111ef169e000c","frame_index":0,"kind":"data","monotonic_ns":310070512197416,"payload":{"event_type":"price_change","market":"0x779291bef19b6709f61e9764a954aafe9ffae488d50ae674aabdcb4f248006d5","price_changes":[{"asset_id":"8761897749749422724209054078244794145777693856614463256546737399611489089783","best_ask":"0.59","best_bid":"0.58","hash":"f80028d963e83e313e7c5042f3962864c788b6fe","price":"0.51","side":"BUY","size":"477.06"},{"asset_id":"14965588658799411272385430903075831224615961675357217884735713260981483529984","best_ask":"0.42","best_bid":"0.41","hash":"da76cdc109bc073a62a30ca9616b4d2bea74a430","price":"0.49","side":"SELL","size":"477.06"}],"timestamp":"1785208087523"},"payload_hash":"634b2d2e50bfb0a344a82205227e62094473f353d66822636c59fb7af1057421","raw_frame":"{\"market\":\"0x779291bef19b6709f61e9764a954aafe9ffae488d50ae674aabdcb4f248006d5\", \"price_changes\":[{\"asset_id\":\"8761897749749422724209054078244794145777693856614463256546737399611489089783\", \"price\":\"0.51\", \"size\":\"477.06\", \"side\":\"BUY\", \"hash\":\"f80028d963e83e313e7c5042f3962864c788b6fe\", \"best_bid\":\"0.58\", \"best_ask\":\"0.59\"}, {\"asset_id\":\"14965588658799411272385430903075831224615961675357217884735713260981483529984\", \"price\":\"0.49\", \"size\":\"477.06\", \"side\":\"SELL\", \"hash\":\"da76cdc109bc073a62a30ca9616b4d2bea74a430\", \"best_bid\":\"0.41\", \"best_ask\":\"0.42\"}], \"timestamp\":\"1785208087523\", \"event_type\":\"price_change\"}","received_at":"2026-07-28T03:08:07.479864Z","schema_version":"clob-market-ws.price_change.v1","sequence":null,"server_hash":null,"server_timestamp":"1785208087523","session_id":"3e519d9098404c15b234d96025eb1a2b","source":"clob_market_ws"},"received_at":"2026-07-28T03:08:07.479864Z","record_id":"d586777cb2cb252b238926225456f279444e6aec956068229181d99cf47ea108","schema_fingerprint":"4aa3821a28b0b7c2400bc59aba4bcc0a76e971dadd19610d3ad38c768e124dc7","schema_version":"edge-lab-recorder.raw.v1","sequence":null,"source":"clob_market_ws"}
{"event_at":"2026-07-28T03:08:07.524000Z","event_fingerprint":"b814ff8d47760a375816a280a4bac06fc0b3e1fb121ec6facb556a9c665ea976","payload":{"connection_id":"a6b55582af5f430fb37ad02bf0922475","event_at":"2026-07-28T03:08:07.524000Z","event_type":"price_change","frame_hash":"b81b3aa372674c62d2d2adb16274f489394687391e7d29728c54d3e452a71a51","frame_index":0,"kind":"data","monotonic_ns":310070513731250,"payload":{"event_type":"price_change","market":"0x779291bef19b6709f61e9764a954aafe9ffae488d50ae674aabdcb4f248006d5","price_changes":[{"asset_id":"8761897749749422724209054078244794145777693856614463256546737399611489089783","best_ask":"0.59","best_bid":"0.58","hash":"ac13991b2092128f09b67ca920c3a90b523eb881","price":"0.03","side":"BUY","size":"653.1"},{"asset_id":"14965588658799411272385430903075831224615961675357217884735713260981483529984","best_ask":"0.42","best_bid":"0.41","hash":"14d87c96178e2e82cd62d16ec9b625a7efc2fe00","price":"0.97","side":"SELL","size":"653.1"}],"timestamp":"1785208087524"},"payload_hash":"b656e3aa0180e4e5a5b56e770379dfe8a8121627484754402b3274f1f4ec6fa6","raw_frame":"{\"market\":\"0x779291bef19b6709f61e9764a954aafe9ffae488d50ae674aabdcb4f248006d5\", \"price_changes\":[{\"asset_id\":\"8761897749749422724209054078244794145777693856614463256546737399611489089783\", \"price\":\"0.03\", \"size\":\"653.1\", \"side\":\"BUY\", \"hash\":\"ac13991b2092128f09b67ca920c3a90b523eb881\", \"best_bid\":\"0.58\", \"best_ask\":\"0.59\"}, {\"asset_id\":\"14965588658799411272385430903075831224615961675357217884735713260981483529984\", \"price\":\"0.97\", \"size\":\"653.1\", \"side\":\"SELL\", \"hash\":\"14d87c96178e2e82cd62d16ec9b625a7efc2fe00\", \"best_bid\":\"0.41\", \"best_ask\":\"0.42\"}], \"timestamp\":\"1785208087524\", \"event_type\":\"price_change\"}","received_at":"2026-07-28T03:08:07.481394Z","schema_version":"clob-market-ws.price_change.v1","sequence":null,"server_hash":null,"server_timestamp":"1785208087524","session_id":"3e519d9098404c15b234d96025eb1a2b","source":"clob_market_ws"},"received_at":"2026-07-28T03:08:07.481394Z","record_id":"5832f9a31de6027cc5693a39eacd8f54ea9f147018e99ddefbc80652f375862a","schema_fingerprint":"4aa3821a28b0b7c2400bc59aba4bcc0a76e971dadd19610d3ad38c768e124dc7","schema_version":"edge-lab-recorder.raw.v1","sequence":null,"source":"clob_market_ws"}
{"event_at":"2026-07-28T03:08:07.532000Z","event_fingerprint":"fed9e840f4852d3a35aa31825261378d79114eb867e559669ace07f507d2352c","payload":{"connection_id":"a6b55582af5f430fb37ad02bf0922475","event_at":"2026-07-28T03:08:07.532000Z","event_type":"price_change","frame_hash":"7d5d0594eaddc4d6e886001f34bd23eb8f725283eaf880f9ac34d403fd841c5d","frame_index":0,"kind":"data","monotonic_ns":310070515314333,"payload":{"event_type":"price_change","market":"0x779291bef19b6709f61e9764a954aafe9ffae488d50ae674aabdcb4f248006d5","price_changes":[{"asset_id":"14965588658799411272385430903075831224615961675357217884735713260981483529984","best_ask":"0.42","best_bid":"0.41","hash":"1b08324f66db63cc85f47b15bb63d62e70d4b38f","price":"0.32","side":"BUY","size":"117.8"},{"asset_id":"8761897749749422724209054078244794145777693856614463256546737399611489089783","best_ask":"0.59","best_bid":"0.58","hash":"fdc026dfe916f7725c21e6fb51db49e71f98bf0a","price":"0.68","side":"SELL","size":"117.8"}],"timestamp":"1785208087532"},"payload_hash":"592975bc5955e2db0477eca992a014d2d44ab63e8bbef832326b7a907fb979b9","raw_frame":"{\"market\":\"0x779291bef19b6709f61e9764a954aafe9ffae488d50ae674aabdcb4f248006d5\", \"price_changes\":[{\"asset_id\":\"14965588658799411272385430903075831224615961675357217884735713260981483529984\", \"price\":\"0.32\", \"size\":\"117.8\", \"side\":\"BUY\", \"hash\":\"1b08324f66db63cc85f47b15bb63d62e70d4b38f\", \"best_bid\":\"0.41\", \"best_ask\":\"0.42\"}, {\"asset_id\":\"8761897749749422724209054078244794145777693856614463256546737399611489089783\", \"price\":\"0.68\", \"size\":\"117.8\", \"side\":\"SELL\", \"hash\":\"fdc026dfe916f7725c21e6fb51db49e71f98bf0a\", \"best_bid\":\"0.58\", \"best_ask\":\"0.59\"}], \"timestamp\":\"1785208087532\", \"event_type\":\"price_change\"}","received_at":"2026-07-28T03:08:07.482981Z","schema_version":"clob-market-ws.price_change.v1","sequence":null,"server_hash":null,"server_timestamp":"1785208087532","session_id":"3e519d9098404c15b234d96025eb1a2b","source":"clob_market_ws"},"received_at":"2026-07-28T03:08:07.482981Z","record_id":"9a06db7f52088c83eed6896dae257796274cc53dbd7fb7e13f6b785cd94f4398","schema_fingerprint":"4aa3821a28b0b7c2400bc59aba4bcc0a76e971dadd19610d3ad38c768e124dc7","schema_version":"edge-lab-recorder.raw.v1","sequence":null,"source":"clob_market_ws"}
{"event_at":"2026-07-28T03:08:07.532000Z","event_fingerprint":"b86f6f879eb594d243332cf100f166b9c06978fa692dde6903432772fb2c0e16","payload":{"connection_id":"a6b55582af5f430fb37ad02bf0922475","event_at":"2026-07-28T03:08:07.532000Z","event_type":"price_change","frame_hash":"037082b334b18e3c3c5be60493fcc2728c3e3b36c1ca03ff871388616888ffec","frame_index":0,"kind":"data","monotonic_ns":310070516810875,"payload":{"event_type":"price_change","market":"0x779291bef19b6709f61e9764a954aafe9ffae488d50ae674aabdcb4f248006d5","price_changes":[{"asset_id":"14965588658799411272385430903075831224615961675357217884735713260981483529984","best_ask":"0.42","best_bid":"0.41","hash":"1b08324f66db63cc85f47b15bb63d62e70d4b38f","price":"0.31","side":"BUY","size":"191"},{"asset_id":"8761897749749422724209054078244794145777693856614463256546737399611489089783","best_ask":"0.59","best_bid":"0.58","hash":"fdc026dfe916f7725c21e6fb51db49e71f98bf0a","price":"0.69","side":"SELL","size":"191"}],"timestamp":"1785208087532"},"payload_hash":"fc3c5afffe44daf662ba9f31931bad465279ea1af7605d251dd8e74f3167a2a5","raw_frame":"{\"market\":\"0x779291bef19b6709f61e9764a954aafe9ffae488d50ae674aabdcb4f248006d5\", \"price_changes\":[{\"asset_id\":\"14965588658799411272385430903075831224615961675357217884735713260981483529984\", \"price\":\"0.31\", \"size\":\"191\", \"side\":\"BUY\", \"hash\":\"1b08324f66db63cc85f47b15bb63d62e70d4b38f\", \"best_bid\":\"0.41\", \"best_ask\":\"0.42\"}, {\"asset_id\":\"8761897749749422724209054078244794145777693856614463256546737399611489089783\", \"price\":\"0.69\", \"size\":\"191\", \"side\":\"SELL\", \"hash\":\"fdc026dfe916f7725c21e6fb51db49e71f98bf0a\", \"best_bid\":\"0.58\", \"best_ask\":\"0.59\"}], \"timestamp\":\"1785208087532\", \"event_type\":\"price_change\"}","received_at":"2026-07-28T03:08:07.484477Z","schema_version":"clob-market-ws.price_change.v1","sequence":null,"server_hash":null,"server_timestamp":"1785208087532","session_id":"3e519d9098404c15b234d96025eb1a2b","source":"clob_market_ws"},"received_at":"2026-07-28T03:08:07.484477Z","record_id":"69ee9a5e4ec8f99aa30cc78de53775a3d77c2276032530bd2c95a8c8327ed104","schema_fingerprint":"4aa3821a28b0b7c2400bc59aba4bcc0a76e971dadd19610d3ad38c768e124dc7","schema_version":"edge-lab-recorder.raw.v1","sequence":null,"source":"clob_market_ws"}
{"event_at":"2026-07-28T03:08:07.532000Z","event_fingerprint":"96939ceee10f6e76aa5f422975e50965c4923331444ab2c4b8f2a2f255b1b1f8","payload":{"connection_id":"a6b55582af5f430fb37ad02bf0922475","event_at":"2026-07-28T03:08:07.532000Z","event_type":"price_change","frame_hash":"a1665ab182983df559cd9710adc759fcab623a832096d4c88ad476040710c28e","frame_index":0,"kind":"data","monotonic_ns":310070518293583,"payload":{"event_type":"price_change","market":"0x779291bef19b6709f61e9764a954aafe9ffae488d50ae674aabdcb4f248006d5","price_changes":[{"asset_id":"14965588658799411272385430903075831224615961675357217884735713260981483529984","best_ask":"0.42","best_bid":"0.41","hash":"1b08324f66db63cc85f47b15bb63d62e70d4b38f","price":"0.3","side":"BUY","size":"141.49"},{"asset_id":"8761897749749422724209054078244794145777693856614463256546737399611489089783","best_ask":"0.59","best_bid":"0.58","hash":"fdc026dfe916f7725c21e6fb51db49e71f98bf0a","price":"0.7","side":"SELL","size":"141.49"}],"timestamp":"1785208087532"},"payload_hash":"58ecb1e28f6d4c1e8b3a4876b49549b36b188cb71759f6c9b0c280189698a5e1","raw_frame":"{\"market\":\"0x779291bef19b6709f61e9764a954aafe9ffae488d50ae674aabdcb4f248006d5\", \"price_changes\":[{\"asset_id\":\"14965588658799411272385430903075831224615961675357217884735713260981483529984\", \"price\":\"0.3\", \"size\":\"141.49\", \"side\":\"BUY\", \"hash\":\"1b08324f66db63cc85f47b15bb63d62e70d4b38f\", \"best_bid\":\"0.41\", \"best_ask\":\"0.42\"}, {\"asset_id\":\"8761897749749422724209054078244794145777693856614463256546737399611489089783\", \"price\":\"0.7\", \"size\":\"141.49\", \"side\":\"SELL\", \"hash\":\"fdc026dfe916f7725c21e6fb51db49e71f98bf0a\", \"best_bid\":\"0.58\", \"best_ask\":\"0.59\"}], \"timestamp\":\"1785208087532\", \"event_type\":\"price_change\"}","received_at":"2026-07-28T03:08:07.485958Z","schema_version":"clob-market-ws.price_change.v1","sequence":null,"server_hash":null,"server_timestamp":"1785208087532","session_id":"3e519d9098404c15b234d96025eb1a2b","source":"clob_market_ws"},"received_at":"2026-07-28T03:08:07.485958Z","record_id":"a2623f9eb3e3048fb3f0249a9866700ed93d6ec64e782f500a588b25c685630f","schema_fingerprint":"4aa3821a28b0b7c2400bc59aba4bcc0a76e971dadd19610d3ad38c768e124dc7","schema_version":"edge-lab-recorder.raw.v1","sequence":null,"source":"clob_market_ws"}
{"event_at":"2026-07-28T03:08:07.536000Z","event_fingerprint":"ff4d91d71447fd6ff8511efec695ffda5d5b818b2cc0262bc22f98523a8d7140","payload":{"connection_id":"a6b55582af5f430fb37ad02bf0922475","event_at":"2026-07-28T03:08:07.536000Z","event_type":"price_change","frame_hash":"c5b2e78efcc2b6ba006d2a49da0fa58c27ae6eb58b7df1f685077876d85915bc","frame_index":0,"kind":"data","monotonic_ns":310070520047833,"payload":{"event_type":"price_change","market":"0x779291bef19b6709f61e9764a954aafe9ffae488d50ae674aabdcb4f248006d5","price_changes":[{"asset_id":"8761897749749422724209054078244794145777693856614463256546737399611489089783","best_ask":"0.59","best_bid":"0.58","hash":"eb6f7aa21c4f4a25d954f7a55aa1c3d750607c9d","price":"0.27","side":"BUY","size":"204.65"},{"asset_id":"14965588658799411272385430903075831224615961675357217884735713260981483529984","best_ask":"0.42","best_bid":"0.41","hash":"d0656252f08e4cfd082b80b84f193eb941277663","price":"0.73","side":"SELL","size":"204.65"}],"timestamp":"1785208087536"},"payload_hash":"eb49766c5e067b4fa8774b9a0e893a886c1d3c8796a1ae6b74e09eecd57434ac","raw_frame":"{\"market\":\"0x779291bef19b6709f61e9764a954aafe9ffae488d50ae674aabdcb4f248006d5\", \"price_changes\":[{\"asset_id\":\"8761897749749422724209054078244794145777693856614463256546737399611489089783\", \"price\":\"0.27\", \"size\":\"204.65\", \"side\":\"BUY\", \"hash\":\"eb6f7aa21c4f4a25d954f7a55aa1c3d750607c9d\", \"best_bid\":\"0.58\", \"best_ask\":\"0.59\"}, {\"asset_id\":\"14965588658799411272385430903075831224615961675357217884735713260981483529984\", \"price\":\"0.73\", \"size\":\"204.65\", \"side\":\"SELL\", \"hash\":\"d0656252f08e4cfd082b80b84f193eb941277663\", \"best_bid\":\"0.41\", \"best_ask\":\"0.42\"}], \"timestamp\":\"1785208087536\", \"event_type\":\"price_change\"}","received_at":"2026-07-28T03:08:07.487713Z","schema_version":"clob-market-ws.price_change.v1","sequence":null,"server_hash":null,"server_timestamp":"1785208087536","session_id":"3e519d9098404c15b234d96025eb1a2b","source":"clob_market_ws"},"received_at":"2026-07-28T03:08:07.487713Z","record_id":"408907222b87ec95a797c81155657d99d928fa37d20a41c5614d751e86e7dc8c","schema_fingerprint":"4aa3821a28b0b7c2400bc59aba4bcc0a76e971dadd19610d3ad38c768e124dc7","schema_version":"edge-lab-recorder.raw.v1","sequence":null,"source":"clob_market_ws"}
{"event_at":"2026-07-28T03:08:07.538000Z","event_fingerprint":"b2a0a295671de84b9cd5b094e64be273396f0fbbb74832fdf525089270cb3721","payload":{"connection_id":"a6b55582af5f430fb37ad02bf0922475","event_at":"2026-07-28T03:08:07.538000Z","event_type":"price_change","frame_hash":"07d52a0ef0591f114931afaad27a3fe1ffa5d8c12aa8241995d56fce9428f112","frame_index":0,"kind":"data","monotonic_ns":310070521582416,"payload":{"event_type":"price_change","market":"0x779291bef19b6709f61e9764a954aafe9ffae488d50ae674aabdcb4f248006d5","price_changes":[{"asset_id":"14965588658799411272385430903075831224615961675357217884735713260981483529984","best_ask":"0.42","best_bid":"0.41","hash":"024f9ddce749ca828ceed8091344d97d7b1d0823","price":"0.28","side":"BUY","size":"151.9"},{"asset_id":"8761897749749422724209054078244794145777693856614463256546737399611489089783","best_ask":"0.59","best_bid":"0.58","hash":"409584b5a2d7fd8aa5ba3e33e5b1a1ac7e2db963","price":"0.72","side":"SELL","size":"151.9"}],"timestamp":"1785208087538"},"payload_hash":"ac2c137cb383fea0e5c9f967cfd18bf43cd1c09837754e03d69ee5487a0a6d82","raw_frame":"{\"market\":\"0x779291bef19b6709f61e9764a954aafe9ffae488d50ae674aabdcb4f248006d5\", \"price_changes\":[{\"asset_id\":\"14965588658799411272385430903075831224615961675357217884735713260981483529984\", \"price\":\"0.28\", \"size\":\"151.9\", \"side\":\"BUY\", \"hash\":\"024f9ddce749ca828ceed8091344d97d7b1d0823\", \"best_bid\":\"0.41\", \"best_ask\":\"0.42\"}, {\"asset_id\":\"8761897749749422724209054078244794145777693856614463256546737399611489089783\", \"price\":\"0.72\", \"size\":\"151.9\", \"side\":\"SELL\", \"hash\":\"409584b5a2d7fd8aa5ba3e33e5b1a1ac7e2db963\", \"best_bid\":\"0.58\", \"best_ask\":\"0.59\"}], \"timestamp\":\"1785208087538\", \"event_type\":\"price_change\"}","received_at":"2026-07-28T03:08:07.489245Z","schema_version":"clob-market-ws.price_change.v1","sequence":null,"server_hash":null,"server_timestamp":"1785208087538","session_id":"3e519d9098404c15b234d96025eb1a2b","source":"clob_market_ws"},"received_at":"2026-07-28T03:08:07.489245Z","record_id":"c59af57dabd053941a004009111f24df0115b17cbc9db90cc831f3adda2981bc","schema_fingerprint":"4aa3821a28b0b7c2400bc59aba4bcc0a76e971dadd19610d3ad38c768e124dc7","schema_version":"edge-lab-recorder.raw.v1","sequence":null,"source":"clob_market_ws"}
{"event_at":"2026-07-28T03:08:07.538000Z","event_fingerprint":"536293082c172f51374513ab88d43d888e286b2e9a8b7b6a6d32363a0170d718","payload":{"connection_id":"a6b55582af5f430fb37ad02bf0922475","event_at":"2026-07-28T03:08:07.538000Z","event_type":"price_change","frame_hash":"dceb0a2ecccf5d739030f0a0215a68c4db8a1c76ffa675c45186241cbf084124","frame_index":0,"kind":"data","monotonic_ns":310070523187041,"payload":{"event_type":"price_change","market":"0x779291bef19b6709f61e9764a954aafe9ffae488d50ae674aabdcb4f248006d5","price_changes":[{"asset_id":"8761897749749422724209054078244794145777693856614463256546737399611489089783","best_ask":"0.59","best_bid":"0.58","hash":"409584b5a2d7fd8aa5ba3e33e5b1a1ac7e2db963","price":"0.49","side":"BUY","size":"108"},{"asset_id":"14965588658799411272385430903075831224615961675357217884735713260981483529984","best_ask":"0.42","best_bid":"0.41","hash":"024f9ddce749ca828ceed8091344d97d7b1d0823","price":"0.51","side":"SELL","size":"108"}],"timestamp":"1785208087538"},"payload_hash":"896264c7ae26bb010181e674c2ebb7d168068568929015ec4d96ad218d5a351f","raw_frame":"{\"market\":\"0x779291bef19b6709f61e9764a954aafe9ffae488d50ae674aabdcb4f248006d5\", \"price_changes\":[{\"asset_id\":\"8761897749749422724209054078244794145777693856614463256546737399611489089783\", \"price\":\"0.49\", \"size\":\"108\", \"side\":\"BUY\", \"hash\":\"409584b5a2d7fd8aa5ba3e33e5b1a1ac7e2db963\", \"best_bid\":\"0.58\", \"best_ask\":\"0.59\"}, {\"asset_id\":\"14965588658799411272385430903075831224615961675357217884735713260981483529984\", \"price\":\"0.51\", \"size\":\"108\", \"side\":\"SELL\", \"hash\":\"024f9ddce749ca828ceed8091344d97d7b1d0823\", \"best_bid\":\"0.41\", \"best_ask\":\"0.42\"}], \"timestamp\":\"1785208087538\", \"event_type\":\"price_change\"}","received_at":"2026-07-28T03:08:07.490852Z","schema_version":"clob-market-ws.price_change.v1","sequence":null,"server_hash":null,"server_timestamp":"1785208087538","session_id":"3e519d9098404c15b234d96025eb1a2b","source":"clob_market_ws"},"received_at":"2026-07-28T03:08:07.490852Z","record_id":"7d72ffd71d302740ef92473bdc7895d6adc99e38a486978770b0203c0f45eb3a","schema_fingerprint":"4aa3821a28b0b7c2400bc59aba4bcc0a76e971dadd19610d3ad38c768e124dc7","schema_version":"edge-lab-recorder.raw.v1","sequence":null,"source":"clob_market_ws"}
{"event_at":"2026-07-28T03:08:07.547000Z","event_fingerprint":"eddf3a25edfdd7fd2d58c2fc6b32df03902ba2f88730b2dbfcc20d0a9ae75e40","payload":{"connection_id":"a6b55582af5f430fb37ad02bf0922475","event_at":"2026-07-28T03:08:07.547000Z","event_type":"price_change","frame_hash":"48318e8294c5c783b10f7fe775f9762eabbfbb8a164be53d4d69b1a19e5f1992","frame_index":0,"kind":"data","monotonic_ns":310070524777333,"payload":{"event_type":"price_change","market":"0x779291bef19b6709f61e9764a954aafe9ffae488d50ae674aabdcb4f248006d5","price_changes":[{"asset_id":"8761897749749422724209054078244794145777693856614463256546737399611489089783","best_ask":"0.59","best_bid":"0.58","hash":"71a0ebe20153c81952c5739ade7356b2934ad0e7","price":"0.48","side":"BUY","size":"119.02"},{"asset_id":"14965588658799411272385430903075831224615961675357217884735713260981483529984","best_ask":"0.42","best_bid":"0.41","hash":"25ba90afa9f19ccfb22fb81cadbe581d4a955b96","price":"0.52","side":"SELL","size":"119.02"}],"timestamp":"1785208087547"},"payload_hash":"ced9c26dcd44bfd752635c7dc66ff98d5d48c101170ac2ba9b99cb8bb51f0db0","raw_frame":"{\"market\":\"0x779291bef19b6709f61e9764a954aafe9ffae488d50ae674aabdcb4f248006d5\", \"price_changes\":[{\"asset_id\":\"8761897749749422724209054078244794145777693856614463256546737399611489089783\", \"price\":\"0.48\", \"size\":\"119.02\", \"side\":\"BUY\", \"hash\":\"71a0ebe20153c81952c5739ade7356b2934ad0e7\", \"best_bid\":\"0.58\", \"best_ask\":\"0.59\"}, {\"asset_id\":\"14965588658799411272385430903075831224615961675357217884735713260981483529984\", \"price\":\"0.52\", \"size\":\"119.02\", \"side\":\"SELL\", \"hash\":\"25ba90afa9f19ccfb22fb81cadbe581d4a955b96\", \"best_bid\":\"0.41\", \"best_ask\":\"0.42\"}], \"timestamp\":\"1785208087547\", \"event_type\":\"price_change\"}","received_at":"2026-07-28T03:08:07.492444Z","schema_version":"clob-market-ws.price_change.v1","sequence":null,"server_hash":null,"server_timestamp":"1785208087547","session_id":"3e519d9098404c15b234d96025eb1a2b","source":"clob_market_ws"},"received_at":"2026-07-28T03:08:07.492444Z","record_id":"52bff34e9e5738edaaaba140ea21a749bbfbd1f4484826c471d53e6689ada595","schema_fingerprint":"4aa3821a28b0b7c2400bc59aba4bcc0a76e971dadd19610d3ad38c768e124dc7","schema_version":"edge-lab-recorder.raw.v1","sequence":null,"source":"clob_market_ws"}
{"event_at":"2026-07-28T03:08:07.548000Z","event_fingerprint":"7f10022d48148c62853a411552dc3988d0604d24f5a8cb5c4eed88427bbf551d","payload":{"connection_id":"a6b55582af5f430fb37ad02bf0922475","event_at":"2026-07-28T03:08:07.548000Z","event_type":"price_change","frame_hash":"48d2e59b3716e79622806dc1d3fcba89b1411d98d13ba387b22e9a6dbdaa998f","frame_index":0,"kind":"data","monotonic_ns":310070526272458,"payload":{"event_type":"price_change","market":"0x779291bef19b6709f61e9764a954aafe9ffae488d50ae674aabdcb4f248006d5","price_changes":[{"asset_id":"8761897749749422724209054078244794145777693856614463256546737399611489089783","best_ask":"0.59","best_bid":"0.58","hash":"556454db7804f9d4264326e4ea50936f6bf92bdf","price":"0.5","side":"BUY","size":"120"},{"asset_id":"14965588658799411272385430903075831224615961675357217884735713260981483529984","best_ask":"0.42","best_bid":"0.41","hash":"1147f97d3b3fc1627d0b4976e74b4a770b2bb176","price":"0.5","side":"SELL","size":"120"}],"timestamp":"1785208087548"},"payload_hash":"391ad53f08c254103ac10621bb5d55c9f61a9d5b938ee52d9b3f7cb3451d2c71","raw_frame":"{\"market\":\"0x779291bef19b6709f61e9764a954aafe9ffae488d50ae674aabdcb4f248006d5\", \"price_changes\":[{\"asset_id\":\"8761897749749422724209054078244794145777693856614463256546737399611489089783\", \"price\":\"0.5\", \"size\":\"120\", \"side\":\"BUY\", \"hash\":\"556454db7804f9d4264326e4ea50936f6bf92bdf\", \"best_bid\":\"0.58\", \"best_ask\":\"0.59\"}, {\"asset_id\":\"14965588658799411272385430903075831224615961675357217884735713260981483529984\", \"price\":\"0.5\", \"size\":\"120\", \"side\":\"SELL\", \"hash\":\"1147f97d3b3fc1627d0b4976e74b4a770b2bb176\", \"best_bid\":\"0.41\", \"best_ask\":\"0.42\"}], \"timestamp\":\"1785208087548\", \"event_type\":\"price_change\"}","received_at":"2026-07-28T03:08:07.493939Z","schema_version":"clob-market-ws.price_change.v1","sequence":null,"server_hash":null,"server_timestamp":"1785208087548","session_id":"3e519d9098404c15b234d96025eb1a2b","source":"clob_market_ws"},"received_at":"2026-07-28T03:08:07.493939Z","record_id":"8e89e2b66b36a2d232fabbb71e414ae6c24e1329fc3a87cdda7a6a27f6d6f95a","schema_fingerprint":"4aa3821a28b0b7c2400bc59aba4bcc0a76e971dadd19610d3ad38c768e124dc7","schema_version":"edge-lab-recorder.raw.v1","sequence":null,"source":"clob_market_ws"}
{"event_at":"2026-07-28T03:08:07.549000Z","event_fingerprint":"2c80a632b4ee129bf18f1a0e55c33d30ada6b3e2ae25842096b0ec7f19684104","payload":{"connection_id":"a6b55582af5f430fb37ad02bf0922475","event_at":"2026-07-28T03:08:07.549000Z","event_type":"best_bid_ask","frame_hash":"b7aa47ffd6708bb62615a741dd6b7bc966ae7945527b6b49fb64d076d11bbe74","frame_index":0,"kind":"data","monotonic_ns":310070527776833,"payload":{"asset_id":"14965588658799411272385430903075831224615961675357217884735713260981483529984","best_ask":"0.44","best_bid":"0.41","event_type":"best_bid_ask","market":"0x779291bef19b6709f61e9764a954aafe9ffae488d50ae674aabdcb4f248006d5","spread":"0.03","timestamp":"1785208087549"},"payload_hash":"e376249872920884b1fa68b4513540b96f3bf2766ad5b36ee35ee9ba640726cf","raw_frame":"{\"market\":\"0x779291bef19b6709f61e9764a954aafe9ffae488d50ae674aabdcb4f248006d5\", \"asset_id\":\"14965588658799411272385430903075831224615961675357217884735713260981483529984\", \"best_bid\":\"0.41\", \"best_ask\":\"0.44\", \"spread\":\"0.03\", \"timestamp\":\"1785208087549\", \"event_type\":\"best_bid_ask\"}","received_at":"2026-07-28T03:08:07.495443Z","schema_version":"clob-market-ws.best_bid_ask.v1","sequence":null,"server_hash":null,"server_timestamp":"1785208087549","session_id":"3e519d9098404c15b234d96025eb1a2b","source":"clob_market_ws"},"received_at":"2026-07-28T03:08:07.495443Z","record_id":"99fc7f06b7aa9135fdb2c2ae58851558c8e8a3c66d6f67e67979286353df711f","schema_fingerprint":"8488399f31b0337811b13b266be932db7062827c2470b78bd8e9e99bab51d17d","schema_version":"edge-lab-recorder.raw.v1","sequence":null,"source":"clob_market_ws"}
{"event_at":"2026-07-28T03:08:07.549000Z","event_fingerprint":"78f5d164ac9130da08bb96bd79e9241c57c6de61a15ead7f766e4ff0acd16245","payload":{"connection_id":"a6b55582af5f430fb37ad02bf0922475","event_at":"2026-07-28T03:08:07.549000Z","event_type":"best_bid_ask","frame_hash":"8b257cf21faf70a2f9bbf248c765b89ff14f3e45f6840187787efaff5f740ebf","frame_index":0,"kind":"data","monotonic_ns":310070528858000,"payload":{"asset_id":"8761897749749422724209054078244794145777693856614463256546737399611489089783","best_ask":"0.59","best_bid":"0.56","event_type":"best_bid_ask","market":"0x779291bef19b6709f61e9764a954aafe9ffae488d50ae674aabdcb4f248006d5","spread":"0.03","timestamp":"1785208087549"},"payload_hash":"d9383cac8eeaa33acdb92743e37624e47df8fccadd934b80f09969f90b70cc7f","raw_frame":"{\"market\":\"0x779291bef19b6709f61e9764a954aafe9ffae488d50ae674aabdcb4f248006d5\", \"asset_id\":\"8761897749749422724209054078244794145777693856614463256546737399611489089783\", \"best_bid\":\"0.56\", \"best_ask\":\"0.59\", \"spread\":\"0.03\", \"timestamp\":\"1785208087549\", \"event_type\":\"best_bid_ask\"}","received_at":"2026-07-28T03:08:07.496523Z","schema_version":"clob-market-ws.best_bid_ask.v1","sequence":null,"server_hash":null,"server_timestamp":"1785208087549","session_id":"3e519d9098404c15b234d96025eb1a2b","source":"clob_market_ws"},"received_at":"2026-07-28T03:08:07.496523Z","record_id":"4952ba800e42523033fb0eb890a76a95ef5a352fbaafd2729b0e4bcac9fe03ee","schema_fingerprint":"8488399f31b0337811b13b266be932db7062827c2470b78bd8e9e99bab51d17d","schema_version":"edge-lab-recorder.raw.v1","sequence":null,"source":"clob_market_ws"}
{"event_at":"2026-07-28T03:08:07.549000Z","event_fingerprint":"00bec9b87fe4dff568e51fa14a86248e7e2a7d5901acf2fc91e31c1596fcf3b1","payload":{"connection_id":"a6b55582af5f430fb37ad02bf0922475","event_at":"2026-07-28T03:08:07.549000Z","event_type":"price_change","frame_hash":"d349ba5b3a1568da2c31844ae420f80429289cd7dde5e6ccd58a8398fb71911d","frame_index":0,"kind":"data","monotonic_ns":310070530212083,"payload":{"event_type":"price_change","market":"0x779291bef19b6709f61e9764a954aafe9ffae488d50ae674aabdcb4f248006d5","price_changes":[{"asset_id":"8761897749749422724209054078244794145777693856614463256546737399611489089783","best_ask":"0.59","best_bid":"0.56","hash":"a634aa85540160e01e2c0b480c83098517119af6","price":"0.58","side":"BUY","size":"0"},{"asset_id":"14965588658799411272385430903075831224615961675357217884735713260981483529984","best_ask":"0.44","best_bid":"0.41","hash":"9e12683d822205b0eef1c38c6d6a20b5919a9fcb","price":"0.42","side":"SELL","size":"0"}],"timestamp":"1785208087549"},"payload_hash":"beb5b25d3ee5e62f37dfb0d5a5eca19d1de40ff58583c7f1fc48eab21bd113dd","raw_frame":"{\"market\":\"0x779291bef19b6709f61e9764a954aafe9ffae488d50ae674aabdcb4f248006d5\", \"price_changes\":[{\"asset_id\":\"8761897749749422724209054078244794145777693856614463256546737399611489089783\", \"price\":\"0.58\", \"size\":\"0\", \"side\":\"BUY\", \"hash\":\"a634aa85540160e01e2c0b480c83098517119af6\", \"best_bid\":\"0.56\", \"best_ask\":\"0.59\"}, {\"asset_id\":\"14965588658799411272385430903075831224615961675357217884735713260981483529984\", \"price\":\"0.42\", \"size\":\"0\", \"side\":\"SELL\", \"hash\":\"9e12683d822205b0eef1c38c6d6a20b5919a9fcb\", \"best_bid\":\"0.41\", \"best_ask\":\"0.44\"}], \"timestamp\":\"1785208087549\", \"event_type\":\"price_change\"}","received_at":"2026-07-28T03:08:07.497876Z","schema_version":"clob-market-ws.price_change.v1","sequence":null,"server_hash":null,"server_timestamp":"1785208087549","session_id":"3e519d9098404c15b234d96025eb1a2b","source":"clob_market_ws"},"received_at":"2026-07-28T03:08:07.497876Z","record_id":"d21c86af43379497a6e25ec5f1ec85c1df18673056be25647fdf2371ba2c9590","schema_fingerprint":"4aa3821a28b0b7c2400bc59aba4bcc0a76e971dadd19610d3ad38c768e124dc7","schema_version":"edge-lab-recorder.raw.v1","sequence":null,"source":"clob_market_ws"}
