{"event_at":"2026-07-28T03:06:35.905000Z","event_fingerprint":"95f192b5caf66ff355b4c532b4b3377a6ff7771c60ec92a685c959879b3c12d8","payload":{"connection_id":"a6b55582af5f430fb37ad02bf0922475","event_at":"2026-07-28T03:06:35.905000Z","event_type":"price_change","frame_hash":"d00694f952ee3286ae9bb867de15ec000d9dd5abdce5e41309063a744e952ffc","frame_index":0,"kind":"data","monotonic_ns":309978832829875,"payload":{"event_type":"price_change","market":"0x779291bef19b6709f61e9764a954aafe9ffae488d50ae674aabdcb4f248006d5","price_changes":[{"asset_id":"14965588658799411272385430903075831224615961675357217884735713260981483529984","best_ask":"0.23","best_bid":"0.22","hash":"18e0be74d82c742424f66e7b09abec5347bec8a6","price":"0.25","side":"SELL","size":"452.19"},{"asset_id":"8761897749749422724209054078244794145777693856614463256546737399611489089783","best_ask":"0.78","best_bid":"0.77","hash":"969899647ca61e4b7d3167a84ef3e94c5ced3737","price":"0.75","side":"BUY","size":"452.19"}],"timestamp":"1785207995905"},"payload_hash":"d4fde13754059122427bf0cf17b555780c7b52fe83f28195ba4b98f54885538c","raw_frame":"{\"market\":\"0x779291bef19b6709f61e9764a954aafe9ffae488d50ae674aabdcb4f248006d5\", \"price_changes\":[{\"asset_id\":\"14965588658799411272385430903075831224615961675357217884735713260981483529984\", \"price\":\"0.25\", \"size\":\"452.19\", \"side\":\"SELL\", \"hash\":\"18e0be74d82c742424f66e7b09abec5347bec8a6\", \"best_bid\":\"0.22\", \"best_ask\":\"0.23\"}, {\"asset_id\":\"8761897749749422724209054078244794145777693856614463256546737399611489089783\", \"price\":\"0.75\", \"size\":\"452.19\", \"side\":\"BUY\", \"hash\":\"969899647ca61e4b7d3167a84ef3e94c5ced3737\", \"best_bid\":\"0.77\", \"best_ask\":\"0.78\"}], \"timestamp\":\"1785207995905\", \"event_type\":\"price_change\"}","received_at":"2026-07-28T03:06:35.801293Z","schema_version":"clob-market-ws.price_change.v1","sequence":null,"server_hash":null,"server_timestamp":"1785207995905","session_id":"3e519d9098404c15b234d96025eb1a2b","source":"clob_market_ws"},"received_at":"2026-07-28T03:06:35.801293Z","record_id":"5b99d7b928db90524190b4f7569a426db6a2bbc16ecff3c5fb35eadc7661cf2b","schema_fingerprint":"4aa3821a28b0b7c2400bc59aba4bcc0a76e971dadd19610d3ad38c768e124dc7","schema_version":"edge-lab-recorder.raw.v1","sequence":null,"source":"clob_market_ws"}
{"event_at":"2026-07-28T03:06:35.911000Z","event_fingerprint":"2250b2696f5d2a62eac522d4679cfcc118de5d0ef9e12aae4f021dae19d28a08","payload":{"connection_id":"a6b55582af5f430fb37ad02bf0922475","event_at":"2026-07-28T03:06:35.911000Z","event_type":"price_change","frame_hash":"5dafa59f54f59bbeb52a008d767986ea81712c5a083a5ab3effa57e63c9e1686","frame_index":0,"kind":"data","monotonic_ns":309978838794291,"payload":{"event_type":"price_change","market":"0x779291bef19b6709f61e9764a954aafe9ffae488d50ae674aabdcb4f248006d5","price_changes":[{"asset_id":"14965588658799411272385430903075831224615961675357217884735713260981483529984","best_ask":"0.23","best_bid":"0.22","hash":"b042d468126baf77428c283140a8da44ba6d438f","price":"0.21","side":"BUY","size":"0"},{"asset_id":"8761897749749422724209054078244794145777693856614463256546737399611489089783","best_ask":"0.78","best_bid":"0.77","hash":"5fb75396ed89b0f5d6de5f13f38ae57f2fe4d8cc","price":"0.79","side":"SELL","size":"0"}],"timestamp":"1785207995911"},"payload_hash":"a2693cfbaafb305627ab834ea9e739c48b8e78ca861e7c7ab51fdbb5e9589e76","raw_frame":"{\"market\":\"0x779291bef19b6709f61e9764a954aafe9ffae488d50ae674aabdcb4f248006d5\", \"price_changes\":[{\"asset_id\":\"14965588658799411272385430903075831224615961675357217884735713260981483529984\", \"price\":\"0.21\", \"size\":\"0\", \"side\":\"BUY\", \"hash\":\"b042d468126baf77428c283140a8da44ba6d438f\", \"best_bid\":\"0.22\", \"best_ask\":\"0.23\"}, {\"asset_id\":\"8761897749749422724209054078244794145777693856614463256546737399611489089783\", \"price\":\"0.79\", \"size\":\"0\", \"side\":\"SELL\", \"hash\":\"5fb75396ed89b0f5d6de5f13f38ae57f2fe4d8cc\", \"best_bid\":\"0.77\", \"best_ask\":\"0.78\"}], \"timestamp\":\"1785207995911\", \"event_type\":\"price_change\"}","received_at":"2026-07-28T03:06:35.807258Z","schema_version":"clob-market-ws.price_change.v1","sequence":null,"server_hash":null,"server_timestamp":"1785207995911","session_id":"3e519d9098404c15b234d96025eb1a2b","source":"clob_market_ws"},"received_at":"2026-07-28T03:06:35.807258Z","record_id":"22c81290c18b9c97127cf4f236f2a4642cce4b4f188d2d0424926c43692a4ac6","schema_fingerprint":"4aa3821a28b0b7c2400bc59aba4bcc0a76e971dadd19610d3ad38c768e124dc7","schema_version":"edge-lab-recorder.raw.v1","sequence":null,"source":"clob_market_ws"}
{"event_at":"2026-07-28T03:06:35.911000Z","event_fingerprint":"8adf8637a5b20a2c0412de2d61f244fd955645c122f7c51d3193e18659b14bf8","payload":{"connection_id":"a6b55582af5f430fb37ad02bf0922475","event_at":"2026-07-28T03:06:35.911000Z","event_type":"price_change","frame_hash":"6194aadedd8a974291a1b7f1b254230a9bec36218b5e11e7ed270b501c79c21e","frame_index":0,"kind":"data","monotonic_ns":309978842553500,"payload":{"event_type":"price_change","market":"0x779291bef19b6709f61e9764a954aafe9ffae488d50ae674aabdcb4f248006d5","price_changes":[{"asset_id":"14965588658799411272385430903075831224615961675357217884735713260981483529984","best_ask":"0.23","best_bid":"0.22","hash":"b042d468126baf77428c283140a8da44ba6d438f","price":"0.22","side":"BUY","size":"416"},{"asset_id":"8761897749749422724209054078244794145777693856614463256546737399611489089783","best_ask":"0.78","best_bid":"0.77","hash":"5fb75396ed89b0f5d6de5f13f38ae57f2fe4d8cc","price":"0.78","side":"SELL","size":"416"}],"timestamp":"1785207995911"},"payload_hash":"4278aad30d6e468b32a294c34bca5d49c981d588097c3164d893c3666f261f98","raw_frame":"{\"market\":\"0x779291bef19b6709f61e9764a954aafe9ffae488d50ae674aabdcb4f248006d5\", \"price_changes\":[{\"asset_id\":\"14965588658799411272385430903075831224615961675357217884735713260981483529984\", \"price\":\"0.22\", \"size\":\"416\", \"side\":\"BUY\", \"hash\":\"b042d468126baf77428c283140a8da44ba6d438f\", \"best_bid\":\"0.22\", \"best_ask\":\"0.23\"}, {\"asset_id\":\"8761897749749422724209054078244794145777693856614463256546737399611489089783\", \"price\":\"0.78\", \"size\":\"416\", \"side\":\"SELL\", \"hash\":\"5fb75396ed89b0f5d6de5f13f38ae57f2fe4d8cc\", \"best_bid\":\"0.77\", \"best_ask\":\"0.78\"}], \"timestamp\":\"1785207995911\", \"event_type\":\"price_change\"}","received_at":"2026-07-28T03:06:35.811017Z","schema_version":"clob-market-ws.price_change.v1","sequence":null,"server_hash":null,"server_timestamp":"1785207995911","session_id":"3e519d9098404c15b234d96025eb1a2b","source":"clob_market_ws"},"received_at":"2026-07-28T03:06:35.811017Z","record_id":"e6f75eb66dbee11dc0d9e1cdced63b1ec68d0dcadf77d0ed7ef17b98ffc69174","schema_fingerprint":"4aa3821a28b0b7c2400bc59aba4bcc0a76e971dadd19610d3ad38c768e124dc7","schema_version":"edge-lab-recorder.raw.v1","sequence":null,"source":"clob_market_ws"}
{"event_at":"2026-07-28T03:06:35.912000Z","event_fingerprint":"b793874d3f5a5965ad72458abc23a9fa420f5e3231db5764a4d3cb704e993eac","payload":{"connection_id":"a6b55582af5f430fb37ad02bf0922475","event_at":"2026-07-28T03:06:35.912000Z","event_type":"price_change","frame_hash":"b95fcb2eaa44a4c224528f16b4e5935245302408a056aeebdfd5786bca89cf65","frame_index":0,"kind":"data","monotonic_ns":309978845622791,"payload":{"event_type":"price_change","market":"0x779291bef19b6709f61e9764a954aafe9ffae488d50ae674aabdcb4f248006d5","price_changes":[{"asset_id":"14965588658799411272385430903075831224615961675357217884735713260981483529984","best_ask":"0.23","best_bid":"0.22","hash":"692a957427d128f614570ccd9d797adec317f5ef","price":"0.2","side":"BUY","size":"68.2"},{"asset_id":"8761897749749422724209054078244794145777693856614463256546737399611489089783","best_ask":"0.78","best_bid":"0.77","hash":"845d8e586893884a102892cc9b3cb0379ee991d2","price":"0.8","side":"SELL","size":"68.2"}],"timestamp":"1785207995912"},"payload_hash":"591251dc485884a2044ab3f2eea68b5bba2067edd7baff7d738ec861441ea729","raw_frame":"{\"market\":\"0x779291bef19b6709f61e9764a954aafe9ffae488d50ae674aabdcb4f248006d5\", \"price_changes\":[{\"asset_id\":\"14965588658799411272385430903075831224615961675357217884735713260981483529984\", \"price\":\"0.2\", \"size\":\"68.2\", \"side\":\"BUY\", \"hash\":\"692a957427d128f614570ccd9d797adec317f5ef\", \"best_bid\":\"0.22\", \"best_ask\":\"0.23\"}, {\"asset_id\":\"8761897749749422724209054078244794145777693856614463256546737399611489089783\", \"price\":\"0.8\", \"size\":\"68.2\", \"side\":\"SELL\", \"hash\":\"845d8e586893884a102892cc9b3cb0379ee991d2\", \"best_bid\":\"0.77\", \"best_ask\":\"0.78\"}], \"timestamp\":\"1785207995912\", \"event_type\":\"price_change\"}","received_at":"2026-07-28T03:06:35.814087Z","schema_version":"clob-market-ws.price_change.v1","sequence":null,"server_hash":null,"server_timestamp":"1785207995912","session_id":"3e519d9098404c15b234d96025eb1a2b","source":"clob_market_ws"},"received_at":"2026-07-28T03:06:35.814087Z","record_id":"0da93f46b1469c1e36e201c65e08cf8b48d062e118023cbd92f10f5944b5a80a","schema_fingerprint":"4aa3821a28b0b7c2400bc59aba4bcc0a76e971dadd19610d3ad38c768e124dc7","schema_version":"edge-lab-recorder.raw.v1","sequence":null,"source":"clob_market_ws"}
{"event_at":"2026-07-28T03:06:35.912000Z","event_fingerprint":"12f5f9cb84a82b7159ffeae5fb182877e4e84406c10fb64fcf782efefadbf2ad","payload":{"connection_id":"a6b55582af5f430fb37ad02bf0922475","event_at":"2026-07-28T03:06:35.912000Z","event_type":"price_change","frame_hash":"74999b845826f87c73cffbda54749f23407ab69489bcde0a191af1768d8e4418","frame_index":0,"kind":"data","monotonic_ns":309978848576625,"payload":{"event_type":"price_change","market":"0x779291bef19b6709f61e9764a954aafe9ffae488d50ae674aabdcb4f248006d5","price_changes":[{"asset_id":"8761897749749422724209054078244794145777693856614463256546737399611489089783","best_ask":"0.78","best_bid":"0.77","hash":"44988b0b5068df77218e040eb7af5eb0bd716d4a","price":"0.78","side":"SELL","size":"391"},{"asset_id":"14965588658799411272385430903075831224615961675357217884735713260981483529984","best_ask":"0.23","best_bid":"0.22","hash":"c9bc988dcd27f9e4d6075c4a9643aed607cb2bf6","price":"0.22","side":"BUY","size":"391"}],"timestamp":"1785207995912"},"payload_hash":"7fd858481cca13f6548ca57eb9762d75505a44c3ff4792bbf6132f129a0b323c","raw_frame":"{\"market\":\"0x779291bef19b6709f61e9764a954aafe9ffae488d50ae674aabdcb4f248006d5\", \"price_changes\":[{\"asset_id\":\"8761897749749422724209054078244794145777693856614463256546737399611489089783\", \"price\":\"0.78\", \"size\":\"391\", \"side\":\"SELL\", \"hash\":\"44988b0b5068df77218e040eb7af5eb0bd716d4a\", \"best_bid\":\"0.77\", \"best_ask\":\"0.78\"}, {\"asset_id\":\"14965588658799411272385430903075831224615961675357217884735713260981483529984\", \"price\":\"0.22\", \"size\":\"391\", \"side\":\"BUY\", \"hash\":\"c9bc988dcd27f9e4d6075c4a9643aed607cb2bf6\", \"best_bid\":\"0.22\", \"best_ask\":\"0.23\"}], \"timestamp\":\"1785207995912\", \"event_type\":\"price_change\"}","received_at":"2026-07-28T03:06:35.817041Z","schema_version":"clob-market-ws.price_change.v1","sequence":null,"server_hash":null,"server_timestamp":"1785207995912","session_id":"3e519d9098404c15b234d96025eb1a2b","source":"clob_market_ws"},"received_at":"2026-07-28T03:06:35.817041Z","record_id":"dbe6b7f0eb882b1d745fcd17e13e68e6329385255bb2811088a64cfe97834634","schema_fingerprint":"4aa3821a28b0b7c2400bc59aba4bcc0a76e971dadd19610d3ad38c768e124dc7","schema_version":"edge-lab-recorder.raw.v1","sequence":null,"source":"clob_market_ws"}
{"event_at":"2026-07-28T03:06:35.913000Z","event_fingerprint":"8ea6ae24f42ad5a705b7fd5333eb06dab5ee9dbcdead6b036f1179e2186bc749","payload":{"connection_id":"a6b55582af5f430fb37ad02bf0922475","event_at":"2026-07-28T03:06:35.913000Z","event_type":"price_change","frame_hash":"6c63ca7b6ce48352b34b9bc8f5df928cadc1d3532adb77770701b4d502d0644c","frame_index":0,"kind":"data","monotonic_ns":309978851536000,"payload":{"event_type":"price_change","market":"0x779291bef19b6709f61e9764a954aafe9ffae488d50ae674aabdcb4f248006d5","price_changes":[{"asset_id":"8761897749749422724209054078244794145777693856614463256546737399611489089783","best_ask":"0.78","best_bid":"0.77","hash":"4ea5b2063c1fc5fa55b1baf4178a06c983b0d921","price":"0.75","side":"BUY","size":"427.19"},{"asset_id":"14965588658799411272385430903075831224615961675357217884735713260981483529984","best_ask":"0.23","best_bid":"0.22","hash":"c3b4d87d83c3dfd4b9c864a58ebb41c36fbe022d","price":"0.25","side":"SELL","size":"427.19"}],"timestamp":"1785207995913"},"payload_hash":"0ed4d4e2e4244c2834c26ec7765546b5c8efb50ec788f44bfa70e5a7e205a688","raw_frame":"{\"market\":\"0x779291bef19b6709f61e9764a954aafe9ffae488d50ae674aabdcb4f248006d5\", \"price_changes\":[{\"asset_id\":\"8761897749749422724209054078244794145777693856614463256546737399611489089783\", \"price\":\"0.75\", \"size\":\"427.19\", \"side\":\"BUY\", \"hash\":\"4ea5b2063c1fc5fa55b1baf4178a06c983b0d921\", \"best_bid\":\"0.77\", \"best_ask\":\"0.78\"}, {\"asset_id\":\"14965588658799411272385430903075831224615961675357217884735713260981483529984\", \"price\":\"0.25\", \"size\":\"427.19\", \"side\":\"SELL\", \"hash\":\"c3b4d87d83c3dfd4b9c864a58ebb41c36fbe022d\", \"best_bid\":\"0.22\", \"best_ask\":\"0.23\"}], \"timestamp\":\"1785207995913\", \"event_type\":\"price_change\"}","received_at":"2026-07-28T03:06:35.820000Z","schema_version":"clob-market-ws.price_change.v1","sequence":null,"server_hash":null,"server_timestamp":"1785207995913","session_id":"3e519d9098404c15b234d96025eb1a2b","source":"clob_market_ws"},"received_at":"2026-07-28T03:06:35.820000Z","record_id":"284faf2bd0d45045d48add3f5a43357b8970fae34ea73b196bb7d46c9ab7d95b","schema_fingerprint":"4aa3821a28b0b7c2400bc59aba4bcc0a76e971dadd19610d3ad38c768e124dc7","schema_version":"edge-lab-recorder.raw.v1","sequence":null,"source":"clob_market_ws"}
{"event_at":"2026-07-28T03:06:35.918000Z","event_fingerprint":"ebc0f36be3f10849522605510faf66e79f5902f5694d5f095f759c4235573d00","payload":{"connection_id":"a6b55582af5f430fb37ad02bf0922475","event_at":"2026-07-28T03:06:35.918000Z","event_type":"price_change","frame_hash":"b2f5f3d4ecd05ea7f24eb3535dab408f590849202f941914e621efeb2a0a1008","frame_index":0,"kind":"data","monotonic_ns":309978854602916,"payload":{"event_type":"price_change","market":"0x779291bef19b6709f61e9764a954aafe9ffae488d50ae674aabdcb4f248006d5","price_changes":[{"asset_id":"14965588658799411272385430903075831224615961675357217884735713260981483529984","best_ask":"0.23","best_bid":"0.22","hash":"4fb4fb4148266d611b83b5e0223a7ab61c72a8c2","price":"0.22","side":"BUY","size":"366"},{"asset_id":"8761897749749422724209054078244794145777693856614463256546737399611489089783","best_ask":"0.78","best_bid":"0.77","hash":"759e9079e0454fd70123340123ff333122e8f43e","price":"0.78","side":"SELL","size":"366"}],"timestamp":"1785207995918"},"payload_hash":"c342c42745d789b74051730f675c2642372b402e5add439a792811aeb578bbd1","raw_frame":"{\"market\":\"0x779291bef19b6709f61e9764a954aafe9ffae488d50ae674aabdcb4f248006d5\", \"price_changes\":[{\"asset_id\":\"14965588658799411272385430903075831224615961675357217884735713260981483529984\", \"price\":\"0.22\", \"size\":\"366\", \"side\":\"BUY\", \"hash\":\"4fb4fb4148266d611b83b5e0223a7ab61c72a8c2\", \"best_bid\":\"0.22\", \"best_ask\":\"0.23\"}, {\"asset_id\":\"8761897749749422724209054078244794145777693856614463256546737399611489089783\", \"price\":\"0.78\", \"size\":\"366\", \"side\":\"SELL\", \"hash\":\"759e9079e0454fd70123340123ff333122e8f43e\", \"best_bid\":\"0.77\", \"best_ask\":\"0.78\"}], \"timestamp\":\"1785207995918\", \"event_type\":\"price_change\"}","received_at":"2026-07-28T03:06:35.823066Z","schema_version":"clob-market-ws.price_change.v1","sequence":null,"server_hash":null,"server_timestamp":"1785207995918","session_id":"3e519d9098404c15b234d96025eb1a2b","source":"clob_market_ws"},"received_at":"2026-07-28T03:06:35.823066Z","record_id":"817433381d52e7e8f827c789217337aa527cbf8ad560a3782c10616ad853371a","schema_fingerprint":"4aa3821a28b0b7c2400bc59aba4bcc0a76e971dadd19610d3ad38c768e124dc7","schema_version":"edge-lab-recorder.raw.v1","sequence":null,"source":"clob_market_ws"}
{"event_at":"2026-07-28T03:06:35.919000Z","event_fingerprint":"785cedc9836bfc4f3fe09af95112c7a15c137801b69eaf3e8d8052feabf11c18","payload":{"connection_id":"a6b55582af5f430fb37ad02bf0922475","event_at":"2026-07-28T03:06:35.919000Z","event_type":"price_change","frame_hash":"ce7b74833ed9b445f40fa263b48b91af738a1940846b0ffca9584170bdebccaa","frame_index":0,"kind":"data","monotonic_ns":309978857552708,"payload":{"event_type":"price_change","market":"0x779291bef19b6709f61e9764a954aafe9ffae488d50ae674aabdcb4f248006d5","price_changes":[{"asset_id":"14965588658799411272385430903075831224615961675357217884735713260981483529984","best_ask":"0.23","best_bid":"0.22","hash":"4dd69e2f01787efc42592df12b771fc679c4c84e","price":"0.22","side":"BUY","size":"270"},{"asset_id":"8761897749749422724209054078244794145777693856614463256546737399611489089783","best_ask":"0.78","best_bid":"0.77","hash":"ad3b23bada92af4a2f3a0396381a5d288ea41da0","price":"0.78","side":"SELL","size":"270"}],"timestamp":"1785207995919"},"payload_hash":"de9b8c19fc892ebc0359fb83c40459815b27f48cd16af8df4c845d486e7f1094","raw_frame":"{\"market\":\"0x779291bef19b6709f61e9764a954aafe9ffae488d50ae674aabdcb4f248006d5\", \"price_changes\":[{\"asset_id\":\"14965588658799411272385430903075831224615961675357217884735713260981483529984\", \"price\":\"0.22\", \"size\":\"270\", \"side\":\"BUY\", \"hash\":\"4dd69e2f01787efc42592df12b771fc679c4c84e\", \"best_bid\":\"0.22\", \"best_ask\":\"0.23\"}, {\"asset_id\":\"8761897749749422724209054078244794145777693856614463256546737399611489089783\", \"price\":\"0.78\", \"size\":\"270\", \"side\":\"SELL\", \"hash\":\"ad3b23bada92af4a2f3a0396381a5d288ea41da0\", \"best_bid\":\"0.77\", \"best_ask\":\"0.78\"}], \"timestamp\":\"1785207995919\", \"event_type\":\"price_change\"}","received_at":"2026-07-28T03:06:35.826017Z","schema_version":"clob-market-ws.price_change.v1","sequence":null,"server_hash":null,"server_timestamp":"1785207995919","session_id":"3e519d9098404c15b234d96025eb1a2b","source":"clob_market_ws"},"received_at":"2026-07-28T03:06:35.826017Z","record_id":"1dc36cada0f7147c6a605dadf36fa3ec5d9e5517ce97e10408c847044268acbe","schema_fingerprint":"4aa3821a28b0b7c2400bc59aba4bcc0a76e971dadd19610d3ad38c768e124dc7","schema_version":"edge-lab-recorder.raw.v1","sequence":null,"source":"clob_market_ws"}
{"event_at":"2026-07-28T03:06:35.921000Z","event_fingerprint":"40da969e8866f3b231f84d48e2d1f29c54cb6c1a56eacb318831230dda19b27e","payload":{"connection_id":"a6b55582af5f430fb37ad02bf0922475","event_at":"2026-07-28T03:06:35.921000Z","event_type":"best_bid_ask","frame_hash":"c0eda4adb6a9f72d68a2a83ee4bbfbbddb048edec407bdf1bdaebeefd9adbd10","frame_index":0,"kind":"data","monotonic_ns":309978860494583,"payload":{"asset_id":"14965588658799411272385430903075831224615961675357217884735713260981483529984","best_ask":"0.23","best_bid":"0.2","event_type":"best_bid_ask","market":"0x779291bef19b6709f61e9764a954aafe9ffae488d50ae674aabdcb4f248006d5","spread":"0.03","timestamp":"1785207995921"},"payload_hash":"dbb5e24277ec248f4dbb144258ecf8723acf62bea5622ebdffc01d93cb5b5e1b","raw_frame":"{\"market\":\"0x779291bef19b6709f61e9764a954aafe9ffae488d50ae674aabdcb4f248006d5\", \"asset_id\":\"14965588658799411272385430903075831224615961675357217884735713260981483529984\", \"best_bid\":\"0.2\", \"best_ask\":\"0.23\", \"spread\":\"0.03\", \"timestamp\":\"1785207995921\", \"event_type\":\"best_bid_ask\"}","received_at":"2026-07-28T03:06:35.828959Z","schema_version":"clob-market-ws.best_bid_ask.v1","sequence":null,"server_hash":null,"server_timestamp":"1785207995921","session_id":"3e519d9098404c15b234d96025eb1a2b","source":"clob_market_ws"},"received_at":"2026-07-28T03:06:35.828959Z","record_id":"76c5178d14ed049a716b1e34c8a5ca7f9d14dbdddcc27220e85988dca02b997c","schema_fingerprint":"8488399f31b0337811b13b266be932db7062827c2470b78bd8e9e99bab51d17d","schema_version":"edge-lab-recorder.raw.v1","sequence":null,"source":"clob_market_ws"}
{"event_at":"2026-07-28T03:06:35.921000Z","event_fingerprint":"d4dc2c4b9988581827fec058b5b8d466357fe5b912e57dfd178cde80e39112f7","payload":{"connection_id":"a6b55582af5f430fb37ad02bf0922475","event_at":"2026-07-28T03:06:35.921000Z","event_type":"best_bid_ask","frame_hash":"4c65541e84d08170bcbd9bf74065537f1e8333061f2438c652052209cc1eac35","frame_index":0,"kind":"data","monotonic_ns":309978863117083,"payload":{"asset_id":"8761897749749422724209054078244794145777693856614463256546737399611489089783","best_ask":"0.8","best_bid":"0.77","event_type":"best_bid_ask","market":"0x779291bef19b6709f61e9764a954aafe9ffae488d50ae674aabdcb4f248006d5","spread":"0.03","timestamp":"1785207995921"},"payload_hash":"f4104e29b7b1db24a801a47ece4f99758e2094aba20991811cb7122d80fcaa38","raw_frame":"{\"market\":\"0x779291bef19b6709f61e9764a954aafe9ffae488d50ae674aabdcb4f248006d5\", \"asset_id\":\"8761897749749422724209054078244794145777693856614463256546737399611489089783\", \"best_bid\":\"0.77\", \"best_ask\":\"0.8\", \"spread\":\"0.03\", \"timestamp\":\"1785207995921\", \"event_type\":\"best_bid_ask\"}","received_at":"2026-07-28T03:06:35.831580Z","schema_version":"clob-market-ws.best_bid_ask.v1","sequence":null,"server_hash":null,"server_timestamp":"1785207995921","session_id":"3e519d9098404c15b234d96025eb1a2b","source":"clob_market_ws"},"received_at":"2026-07-28T03:06:35.831580Z","record_id":"281b1ec964064b7faa2de185b2967e07e44524c16aec2aa45a5df1204e052d01","schema_fingerprint":"8488399f31b0337811b13b266be932db7062827c2470b78bd8e9e99bab51d17d","schema_version":"edge-lab-recorder.raw.v1","sequence":null,"source":"clob_market_ws"}
{"event_at":"2026-07-28T03:06:35.921000Z","event_fingerprint":"43a4944056ed39b40aaae5a2eb04cbacd789716b75eb06c36e65098bfca87cf1","payload":{"connection_id":"a6b55582af5f430fb37ad02bf0922475","event_at":"2026-07-28T03:06:35.921000Z","event_type":"price_change","frame_hash":"cb13b728c4f9b7a8f3a625b7b1471249b92f8666d97dd0690b220c6fc72380c8","frame_index":0,"kind":"data","monotonic_ns":309978865834875,"payload":{"event_type":"price_change","market":"0x779291bef19b6709f61e9764a954aafe9ffae488d50ae674aabdcb4f248006d5","price_changes":[{"asset_id":"14965588658799411272385430903075831224615961675357217884735713260981483529984","best_ask":"0.23","best_bid":"0.2","hash":"491717b1e674561644a94d76f5d8843e2a78d32a","price":"0.22","side":"BUY","size":"0"},{"asset_id":"8761897749749422724209054078244794145777693856614463256546737399611489089783","best_ask":"0.8","best_bid":"0.77","hash":"34bfb9b159e7c1cda288afdfa58215eae4e76202","price":"0.78","side":"SELL","size":"0"}],"timestamp":"1785207995921"},"payload_hash":"d0bc6d0caf832756e6ab3ed7bc96d0007e339d257b956757677dbc853f2393f2","raw_frame":"{\"market\":\"0x779291bef19b6709f61e9764a954aafe9ffae488d50ae674aabdcb4f248006d5\", \"price_changes\":[{\"asset_id\":\"14965588658799411272385430903075831224615961675357217884735713260981483529984\", \"price\":\"0.22\", \"size\":\"0\", \"side\":\"BUY\", \"hash\":\"491717b1e674561644a94d76f5d8843e2a78d32a\", \"best_bid\":\"0.2\", \"best_ask\":\"0.23\"}, {\"asset_id\":\"8761897749749422724209054078244794145777693856614463256546737399611489089783\", \"price\":\"0.78\", \"size\":\"0\", \"side\":\"SELL\", \"hash\":\"34bfb9b159e7c1cda288afdfa58215eae4e76202\", \"best_bid\":\"0.77\", \"best_ask\":\"0.8\"}], \"timestamp\":\"1785207995921\", \"event_type\":\"price_change\"}","received_at":"2026-07-28T03:06:35.834298Z","schema_version":"clob-market-ws.price_change.v1","sequence":null,"server_hash":null,"server_timestamp":"1785207995921","session_id":"3e519d9098404c15b234d96025eb1a2b","source":"clob_market_ws"},"received_at":"2026-07-28T03:06:35.834298Z","record_id":"0a3d52f27f8a150f9895a33290aa09122f41d47854eaaf254fb8ae4d591b3bc0","schema_fingerprint":"4aa3821a28b0b7c2400bc59aba4bcc0a76e971dadd19610d3ad38c768e124dc7","schema_version":"edge-lab-recorder.raw.v1","sequence":null,"source":"clob_market_ws"}
{"event_at":"2026-07-28T03:06:35.926000Z","event_fingerprint":"fe323993a0eeeb405e87c33983ebbda9360efeb67ccb0a465b6c2c9c77e06f70","payload":{"connection_id":"a6b55582af5f430fb37ad02bf0922475","event_at":"2026-07-28T03:06:35.926000Z","event_type":"price_change","frame_hash":"84e9839ffed27cabc9cdfae0bbc47bbbeb78939c97acc031f292c64481b6c51a","frame_index":0,"kind":"data","monotonic_ns":309978869140291,"payload":{"event_type":"price_change","market":"0x779291bef19b6709f61e9764a954aafe9ffae488d50ae674aabdcb4f248006d5","price_changes":[{"asset_id":"14965588658799411272385430903075831224615961675357217884735713260981483529984","best_ask":"0.23","best_bid":"0.2","hash":"9b4cbcd4190e5869edd69fcee28384ca94615407","price":"0.17","side":"BUY","size":"80.2"},{"asset_id":"8761897749749422724209054078244794145777693856614463256546737399611489089783","best_ask":"0.8","best_bid":"0.77","hash":"2022e3a9f2742eef67c58fb8d31f54f495711b15","price":"0.83","side":"SELL","size":"80.2"}],"timestamp":"1785207995926"},"payload_hash":"d8b375095ba3e45886900f0f48aa32eadcf064032444198d8f5a432d6a620756","raw_frame":"{\"market\":\"0x779291bef19b6709f61e9764a954aafe9ffae488d50ae674aabdcb4f248006d5\", \"price_changes\":[{\"asset_id\":\"14965588658799411272385430903075831224615961675357217884735713260981483529984\", \"price\":\"0.17\", \"size\":\"80.2\", \"side\":\"BUY\", \"hash\":\"9b4cbcd4190e5869edd69fcee28384ca94615407\", \"best_bid\":\"0.2\", \"best_ask\":\"0.23\"}, {\"asset_id\":\"8761897749749422724209054078244794145777693856614463256546737399611489089783\", \"price\":\"0.83\", \"size\":\"80.2\", \"side\":\"SELL\", \"hash\":\"2022e3a9f2742eef67c58fb8d31f54f495711b15\", \"best_bid\":\"0.77\", \"best_ask\":\"0.8\"}], \"timestamp\":\"1785207995926\", \"event_type\":\"price_change\"}","received_at":"2026-07-28T03:06:35.837604Z","schema_version":"clob-market-ws.price_change.v1","sequence":null,"server_hash":null,"server_timestamp":"1785207995926","session_id":"3e519d9098404c15b234d96025eb1a2b","source":"clob_market_ws"},"received_at":"2026-07-28T03:06:35.837604Z","record_id":"07222a7236556887621b997f7222b3cfe497830281352e063c256e76cab1d342","schema_fingerprint":"4aa3821a28b0b7c2400bc59aba4bcc0a76e971dadd19610d3ad38c768e124dc7","schema_version":"edge-lab-recorder.raw.v1","sequence":null,"source":"clob_market_ws"}
{"event_at":"2026-07-28T03:06:35.926000Z","event_fingerprint":"6c7fd17c3cff47e15f734692f43cb919d515d06387a9e8a72b6751b26d9ff631","payload":{"connection_id":"a6b55582af5f430fb37ad02bf0922475","event_at":"2026-07-28T03:06:35.926000Z","event_type":"price_change","frame_hash":"57bbfc839daa8d298e625f367b478df919e21d8abc3ceefc128e6e8afc6a22b4","frame_index":0,"kind":"data","monotonic_ns":309978872063208,"payload":{"event_type":"price_change","market":"0x779291bef19b6709f61e9764a954aafe9ffae488d50ae674aabdcb4f248006d5","price_changes":[{"asset_id":"14965588658799411272385430903075831224615961675357217884735713260981483529984","best_ask":"0.23","best_bid":"0.2","hash":"a6a1328870327747dc14c438b141ce28be25b365","price":"0.18","side":"BUY","size":"69.6"},{"asset_id":"8761897749749422724209054078244794145777693856614463256546737399611489089783","best_ask":"0.8","best_bid":"0.77","hash":"e524db16448f2839ca66e1cacc8cc8a8700fab7a","price":"0.82","side":"SELL","size":"69.6"}],"timestamp":"1785207995926"},"payload_hash":"32727e804bac10c2eaa61d4a4edaa8ddd421bece25255d30a1d988ea684f593d","raw_frame":"{\"market\":\"0x779291bef19b6709f61e9764a954aafe9ffae488d50ae674aabdcb4f248006d5\", \"price_changes\":[{\"asset_id\":\"14965588658799411272385430903075831224615961675357217884735713260981483529984\", \"price\":\"0.18\", \"size\":\"69.6\", \"side\":\"BUY\", \"hash\":\"a6a1328870327747dc14c438b141ce28be25b365\", \"best_bid\":\"0.2\", \"best_ask\":\"0.23\"}, {\"asset_id\":\"8761897749749422724209054078244794145777693856614463256546737399611489089783\", \"price\":\"0.82\", \"size\":\"69.6\", \"side\":\"SELL\", \"hash\":\"e524db16448f2839ca66e1cacc8cc8a8700fab7a\", \"best_bid\":\"0.77\", \"best_ask\":\"0.8\"}], \"timestamp\":\"1785207995926\", \"event_type\":\"price_change\"}","received_at":"2026-07-28T03:06:35.840527Z","schema_version":"clob-market-ws.price_change.v1","sequence":null,"server_hash":null,"server_timestamp":"1785207995926","session_id":"3e519d9098404c15b234d96025eb1a2b","source":"clob_market_ws"},"received_at":"2026-07-28T03:06:35.840527Z","record_id":"5983ba04b5300019ad26e52b14d130bf851c4b224077929117860ccc4b4f9789","schema_fingerprint":"4aa3821a28b0b7c2400bc59aba4bcc0a76e971dadd19610d3ad38c768e124dc7","schema_version":"edge-lab-recorder.raw.v1","sequence":null,"source":"clob_market_ws"}
{"event_at":"2026-07-28T03:06:35.931000Z","event_fingerprint":"2315c9de645999f14c6d5d5f4a6bdde188db4dd2ba9783ed9dcd69a7424f28e2","payload":{"connection_id":"a6b55582af5f430fb37ad02bf0922475","event_at":"2026-07-28T03:06:35.931000Z","event_type":"price_change","frame_hash":"3c3d939903472f5977188d17e7b58dc0d1a48fbf7d52bd1b5856b318288bc4cc","frame_index":0,"kind":"data","monotonic_ns":309978874982375,"payload":{"event_type":"price_change","market":"0x779291bef19b6709f61e9764a954aafe9ffae488d50ae674aabdcb4f248006d5","price_changes":[{"asset_id":"8761897749749422724209054078244794145777693856614463256546737399611489089783","best_ask":"0.8","best_bid":"0.77","hash":"0c47e03f7f0ec5b197c8deba8316acc6e522d1a1","price":"0.76","side":"BUY","size":"107.17"},{"asset_id":"14965588658799411272385430903075831224615961675357217884735713260981483529984","best_ask":"0.23","best_bid":"0.2","hash":"53145c983780289288e8e58847d7b58523d236f1","price":"0.24","side":"SELL","size":"107.17"}],"timestamp":"1785207995931"},"payload_hash":"6a7675a8253ca38b8bdb5d684a287fd85b66cd99755aedaf20a9aa98749703cc","raw_frame":"{\"market\":\"0x779291bef19b6709f61e9764a954aafe9ffae488d50ae674aabdcb4f248006d5\", \"price_changes\":[{\"asset_id\":\"8761897749749422724209054078244794145777693856614463256546737399611489089783\", \"price\":\"0.76\", \"size\":\"107.17\", \"side\":\"BUY\", \"hash\":\"0c47e03f7f0ec5b197c8deba8316acc6e522d1a1\", \"best_bid\":\"0.77\", \"best_ask\":\"0.8\"}, {\"asset_id\":\"14965588658799411272385430903075831224615961675357217884735713260981483529984\", \"price\":\"0.24\", \"size\":\"107.17\", \"side\":\"SELL\", \"hash\":\"53145c983780289288e8e58847d7b58523d236f1\", \"best_bid\":\"0.2\", \"best_ask\":\"0.23\"}], \"timestamp\":\"1785207995931\", \"event_type\":\"price_change\"}","received_at":"2026-07-28T03:06:35.843446Z","schema_version":"clob-market-ws.price_change.v1","sequence":null,"server_hash":null,"server_timestamp":"1785207995931","session_id":"3e519d9098404c15b234d96025eb1a2b","source":"clob_market_ws"},"received_at":"2026-07-28T03:06:35.843446Z","record_id":"c37338f3c632c21f62ca6666fa5091e30aaf39028ff93e2744d0470536f2c579","schema_fingerprint":"4aa3821a28b0b7c2400bc59aba4bcc0a76e971dadd19610d3ad38c768e124dc7","schema_version":"edge-lab-recorder.raw.v1","sequence":null,"source":"clob_market_ws"}
{"event_at":"2026-07-28T03:06:35.934000Z","event_fingerprint":"e10ea2330dc574c7ff1ac67b21b4fed7208b990a0a1bf5816a67fd410ede70b3","payload":{"connection_id":"a6b55582af5f430fb37ad02bf0922475","event_at":"2026-07-28T03:06:35.934000Z","event_type":"price_change","frame_hash":"1cc10b343f63a3a9db39716276605573601bc0e3744e05ab2176c0000b02cbfb","frame_index":0,"kind":"data","monotonic_ns":309978877901166,"payload":{"event_type":"price_change","market":"0x779291bef19b6709f61e9764a954aafe9ffae488d50ae674aabdcb4f248006d5","price_changes":[{"asset_id":"8761897749749422724209054078244794145777693856614463256546737399611489089783","best_ask":"0.8","best_bid":"0.77","hash":"ee341b28469e1f23e7ffdf5376175e5e9a780716","price":"0.77","side":"BUY","size":"106.98"},{"asset_id":"14965588658799411272385430903075831224615961675357217884735713260981483529984","best_ask":"0.23","best_bid":"0.2","hash":"73a7d0311e86929089f0666b3ff77ea65a112d3e","price":"0.23","side":"SELL","size":"106.98"}],"timestamp":"1785207995934"},"payload_hash":"eb2dded3198fe2133d2721335be7f4490578b14d7c6c881c3ee61e6613892af1","raw_frame":"{\"market\":\"0x779291bef19b6709f61e9764a954aafe9ffae488d50ae674aabdcb4f248006d5\", \"price_changes\":[{\"asset_id\":\"8761897749749422724209054078244794145777693856614463256546737399611489089783\", \"price\":\"0.77\", \"size\":\"106.98\", \"side\":\"BUY\", \"hash\":\"ee341b28469e1f23e7ffdf5376175e5e9a780716\", \"best_bid\":\"0.77\", \"best_ask\":\"0.8\"}, {\"asset_id\":\"14965588658799411272385430903075831224615961675357217884735713260981483529984\", \"price\":\"0.23\", \"size\":\"106.98\", \"side\":\"SELL\", \"hash\":\"73a7d0311e86929089f0666b3ff77ea65a112d3e\", \"best_bid\":\"0.2\", \"best_ask\":\"0.23\"}], \"timestamp\":\"1785207995934\", \"event_type\":\"price_change\"}","received_at":"2026-07-28T03:06:35.846366Z","schema_version":"clob-market-ws.price_change.v1","sequence":null,"server_hash":null,"server_timestamp":"1785207995934","session_id":"3e519d9098404c15b234d96025eb1a2b","source":"clob_market_ws"},"received_at":"2026-07-28T03:06:35.846366Z","record_id":"32484c0a60c733b6902528fd2bd08aa24d0db0e497c170be0970426cdbb17137","schema_fingerprint":"4aa3821a28b0b7c2400bc59aba4bcc0a76e971dadd19610d3ad38c768e124dc7","schema_version":"edge-lab-recorder.raw.v1","sequence":null,"source":"clob_market_ws"}
{"event_at":"2026-07-28T03:06:35.936000Z","event_fingerprint":"20360bd6760e5ed3b94cb6e423b4c7d6b0da3a8f0ce55046f38be7caa1abb842","payload":{"connection_id":"a6b55582af5f430fb37ad02bf0922475","event_at":"2026-07-28T03:06:35.936000Z","event_type":"best_bid_ask","frame_hash":"f9de8be9c56ba11458d25ec55ab56c5e0643b40c2bb8d30103bc1226eef5ec42","frame_index":0,"kind":"data","monotonic_ns":309978880821916,"payload":{"asset_id":"14965588658799411272385430903075831224615961675357217884735713260981483529984","best_ask":"0.22","best_bid":"0.2","event_type":"best_bid_ask","market":"0x779291bef19b6709f61e9764a954aafe9ffae488d50ae674aabdcb4f248006d5","spread":"0.02","timestamp":"1785207995936"},"payload_hash":"e73771199d12a88799d31e6505489d5c53227c2cb2f4b8108fa9628b201d3253","raw_frame":"{\"market\":\"0x779291bef19b6709f61e9764a954aafe9ffae488d50ae674aabdcb4f248006d5\", \"asset_id\":\"14965588658799411272385430903075831224615961675357217884735713260981483529984\", \"best_bid\":\"0.2\", \"best_ask\":\"0.22\", \"spread\":\"0.02\", \"timestamp\":\"1785207995936\", \"event_type\":\"best_bid_ask\"}","received_at":"2026-07-28T03:06:35.849286Z","schema_version":"clob-market-ws.best_bid_ask.v1","sequence":null,"server_hash":null,"server_timestamp":"1785207995936","session_id":"3e519d9098404c15b234d96025eb1a2b","source":"clob_market_ws"},"received_at":"2026-07-28T03:06:35.849286Z","record_id":"f77237f060dc37bebf884e47eb8ab8a38581ac81837b6c1ea0f1b0d8e1cc42d8","schema_fingerprint":"8488399f31b0337811b13b266be932db7062827c2470b78bd8e9e99bab51d17d","schema_version":"edge-lab-recorder.raw.v1","sequence":null,"source":"clob_market_ws"}
{"event_at":"2026-07-28T03:06:35.936000Z","event_fingerprint":"f4b9ab377dadf29d062655c3104d7783b9dc8cb9a0f0cbe7ee3ede76ae155c62","payload":{"connection_id":"a6b55582af5f430fb37ad02bf0922475","event_at":"2026-07-28T03:06:35.936000Z","event_type":"best_bid_ask","frame_hash":"451b769ffd14ae1933e0ec304edf6bb051daa63093abb129a98e99d9c831a02c","frame_index":0,"kind":"data","monotonic_ns":309978883298250,"payload":{"asset_id":"8761897749749422724209054078244794145777693856614463256546737399611489089783","best_ask":"0.8","best_bid":"0.78","event_type":"best_bid_ask","market":"0x779291bef19b6709f61e9764a954aafe9ffae488d50ae674aabdcb4f248006d5","spread":"0.02","timestamp":"1785207995936"},"payload_hash":"ae22410acf49dcb239383c0a53c77981194077d11cc7a5e6cfef47895ceb7d74","raw_frame":"{\"market\":\"0x779291bef19b6709f61e9764a954aafe9ffae488d50ae674aabdcb4f248006d5\", \"asset_id\":\"8761897749749422724209054078244794145777693856614463256546737399611489089783\", \"best_bid\":\"0.78\", \"best_ask\":\"0.8\", \"spread\":\"0.02\", \"timestamp\":\"1785207995936\", \"event_type\":\"best_bid_ask\"}","received_at":"2026-07-28T03:06:35.851763Z","schema_version":"clob-market-ws.best_bid_ask.v1","sequence":null,"server_hash":null,"server_timestamp":"1785207995936","session_id":"3e519d9098404c15b234d96025eb1a2b","source":"clob_market_ws"},"received_at":"2026-07-28T03:06:35.851763Z","record_id":"5a1883e88e12be5d5d73211367fa749fc2b590b2ac9f08df19083bb920957585","schema_fingerprint":"8488399f31b0337811b13b266be932db7062827c2470b78bd8e9e99bab51d17d","schema_version":"edge-lab-recorder.raw.v1","sequence":null,"source":"clob_market_ws"}
{"event_at":"2026-07-28T03:06:35.935000Z","event_fingerprint":"d7a1ad64fd7bd8d67f0f502b3aa0e58c51f24648e9c08f335002179553f065b6","payload":{"connection_id":"a6b55582af5f430fb37ad02bf0922475","event_at":"2026-07-28T03:06:35.935000Z","event_type":"price_change","frame_hash":"5b10776aecf7996324ea827f14be739d593ffd6c8e406606c82598613c125315","frame_index":0,"kind":"data","monotonic_ns":309978885794208,"payload":{"event_type":"price_change","market":"0x779291bef19b6709f61e9764a954aafe9ffae488d50ae674aabdcb4f248006d5","price_changes":[{"asset_id":"8761897749749422724209054078244794145777693856614463256546737399611489089783","best_ask":"0.8","best_bid":"0.78","hash":"97096394cd88bade68527d4ab98e674ea31c221c","price":"0.78","side":"BUY","size":"26"},{"asset_id":"14965588658799411272385430903075831224615961675357217884735713260981483529984","best_ask":"0.22","best_bid":"0.2","hash":"2737afc3dcfcd70bfd686515c1c8091960d69a13","price":"0.22","side":"SELL","size":"26"}],"timestamp":"1785207995935"},"payload_hash":"9d66dc2afab477738fe18dfc2e1b68791f3fe10e106f81085223a6de432b575e","raw_frame":"{\"market\":\"0x779291bef19b6709f61e9764a954aafe9ffae488d50ae674aabdcb4f248006d5\", \"price_changes\":[{\"asset_id\":\"8761897749749422724209054078244794145777693856614463256546737399611489089783\", \"price\":\"0.78\", \"size\":\"26\", \"side\":\"BUY\", \"hash\":\"97096394cd88bade68527d4ab98e674ea31c221c\", \"best_bid\":\"0.78\", \"best_ask\":\"0.8\"}, {\"asset_id\":\"14965588658799411272385430903075831224615961675357217884735713260981483529984\", \"price\":\"0.22\", \"size\":\"26\", \"side\":\"SELL\", \"hash\":\"2737afc3dcfcd70bfd686515c1c8091960d69a13\", \"best_bid\":\"0.2\", \"best_ask\":\"0.22\"}], \"timestamp\":\"1785207995935\", \"event_type\":\"price_change\"}","received_at":"2026-07-28T03:06:35.854258Z","schema_version":"clob-market-ws.price_change.v1","sequence":null,"server_hash":null,"server_timestamp":"1785207995935","session_id":"3e519d9098404c15b234d96025eb1a2b","source":"clob_market_ws"},"received_at":"2026-07-28T03:06:35.854258Z","record_id":"4252b9a41620d10b4363973e04e447d6862f8edf686baa95ab452d90f1b271db","schema_fingerprint":"4aa3821a28b0b7c2400bc59aba4bcc0a76e971dadd19610d3ad38c768e124dc7","schema_version":"edge-lab-recorder.raw.v1","sequence":null,"source":"clob_market_ws"}
{"event_at":"2026-07-28T03:06:35.936000Z","event_fingerprint":"790a0a886beddcf65a37297dd8b10621af96afc07b60bdb431876c8bd6d51870","payload":{"connection_id":"a6b55582af5f430fb37ad02bf0922475","event_at":"2026-07-28T03:06:35.936000Z","event_type":"price_change","frame_hash":"417767168c6a92364cc290489e154cde5585afe2962793d6c6c78c736edaa3a9","frame_index":0,"kind":"data","monotonic_ns":309978889214500,"payload":{"event_type":"price_change","market":"0x779291bef19b6709f61e9764a954aafe9ffae488d50ae674aabdcb4f248006d5","price_changes":[{"asset_id":"14965588658799411272385430903075831224615961675357217884735713260981483529984","best_ask":"0.22","best_bid":"0.2","hash":"3dc8bb78e67e8a0d5aca6c3b8885e24668146f83","price":"0.25","side":"SELL","size":"422.19"},{"asset_id":"8761897749749422724209054078244794145777693856614463256546737399611489089783","best_ask":"0.8","best_bid":"0.78","hash":"c5be3ebf9f872c2585cf0487fd7a555ea5886eac","price":"0.75","side":"BUY","size":"422.19"}],"timestamp":"1785207995936"},"payload_hash":"642b6adc42acb9c9c03b2f2fb4e82779b087d2ad133889891b233dc4de2358b8","raw_frame":"{\"market\":\"0x779291bef19b6709f61e9764a954aafe9ffae488d50ae674aabdcb4f248006d5\", \"price_changes\":[{\"asset_id\":\"14965588658799411272385430903075831224615961675357217884735713260981483529984\", \"price\":\"0.25\", \"size\":\"422.19\", \"side\":\"SELL\", \"hash\":\"3dc8bb78e67e8a0d5aca6c3b8885e24668146f83\", \"best_bid\":\"0.2\", \"best_ask\":\"0.22\"}, {\"asset_id\":\"8761897749749422724209054078244794145777693856614463256546737399611489089783\", \"price\":\"0.75\", \"size\":\"422.19\", \"side\":\"BUY\", \"hash\":\"c5be3ebf9f872c2585cf0487fd7a555ea5886eac\", \"best_bid\":\"0.78\", \"best_ask\":\"0.8\"}], \"timestamp\":\"1785207995936\", \"event_type\":\"price_change\"}","received_at":"2026-07-28T03:06:35.857679Z","schema_version":"clob-market-ws.price_change.v1","sequence":null,"server_hash":null,"server_timestamp":"1785207995936","session_id":"3e519d9098404c15b234d96025eb1a2b","source":"clob_market_ws"},"received_at":"2026-07-28T03:06:35.857679Z","record_id":"727e5e28c13b65db0173dc612a36bc85111efb6664917f62e7982776de9a59c3","schema_fingerprint":"4aa3821a28b0b7c2400bc59aba4bcc0a76e971dadd19610d3ad38c768e124dc7","schema_version":"edge-lab-recorder.raw.v1","sequence":null,"source":"clob_market_ws"}
{"event_at":"2026-07-28T03:06:35.937000Z","event_fingerprint":"d17bee8c9d22b99cd4e7c4e68ceaeb2472da0cbe90bf27798c40a3a85722e57c","payload":{"connection_id":"a6b55582af5f430fb37ad02bf0922475","event_at":"2026-07-28T03:06:35.937000Z","event_type":"price_change","frame_hash":"d6cc9ded7213f89804bb3c3969fad5b56f8734f64d581f862295b01983a7deae","frame_index":0,"kind":"data","monotonic_ns":309978892244000,"payload":{"event_type":"price_change","market":"0x779291bef19b6709f61e9764a954aafe9ffae488d50ae674aabdcb4f248006d5","price_changes":[{"asset_id":"8761897749749422724209054078244794145777693856614463256546737399611489089783","best_ask":"0.8","best_bid":"0.78","hash":"1aa95322c08f95c0ab5802b907546a09394d8ffa","price":"0.8","side":"SELL","size":"93.2"},{"asset_id":"14965588658799411272385430903075831224615961675357217884735713260981483529984","best_ask":"0.22","best_bid":"0.2","hash":"3e62b11367a6d68c9174836be56e43636d115cc2","price":"0.2","side":"BUY","size":"93.2"}],"timestamp":"1785207995937"},"payload_hash":"e75cedbe78bda3814a52447aded358111a6d0161a6b102f129965c68a6b61c3e","raw_frame":"{\"market\":\"0x779291bef19b6709f61e9764a954aafe9ffae488d50ae674aabdcb4f248006d5\", \"price_changes\":[{\"asset_id\":\"8761897749749422724209054078244794145777693856614463256546737399611489089783\", \"price\":\"0.8\", \"size\":\"93.2\", \"side\":\"SELL\", \"hash\":\"1aa95322c08f95c0ab5802b907546a09394d8ffa\", \"best_bid\":\"0.78\", \"best_ask\":\"0.8\"}, {\"asset_id\":\"14965588658799411272385430903075831224615961675357217884735713260981483529984\", \"price\":\"0.2\", \"size\":\"93.2\", \"side\":\"BUY\", \"hash\":\"3e62b11367a6d68c9174836be56e43636d115cc2\", \"best_bid\":\"0.2\", \"best_ask\":\"0.22\"}], \"timestamp\":\"1785207995937\", \"event_type\":\"price_change\"}","received_at":"2026-07-28T03:06:35.860708Z","schema_version":"clob-market-ws.price_change.v1","sequence":null,"server_hash":null,"server_timestamp":"1785207995937","session_id":"3e519d9098404c15b234d96025eb1a2b","source":"clob_market_ws"},"received_at":"2026-07-28T03:06:35.860708Z","record_id":"4c2f50f6524969e7c67033f53f9e6eb1cf5e925a20ba0ee4749bf7f935a103a7","schema_fingerprint":"4aa3821a28b0b7c2400bc59aba4bcc0a76e971dadd19610d3ad38c768e124dc7","schema_version":"edge-lab-recorder.raw.v1","sequence":null,"source":"clob_market_ws"}
{"event_at":"2026-07-28T03:06:35.938000Z","event_fingerprint":"f3d03b4c8c4ccff14f88d35fa1702d0eb63a9342a9aa404ed464c97ead050db9","payload":{"connection_id":"a6b55582af5f430fb37ad02bf0922475","event_at":"2026-07-28T03:06:35.938000Z","event_type":"price_change","frame_hash":"04eee89f8066a173dfd9f8c2e9fcab5dd9b19adc9d529610a5d7c05918d57974","frame_index":0,"kind":"data","monotonic_ns":309978895211458,"payload":{"event_type":"price_change","market":"0x779291bef19b6709f61e9764a954aafe9ffae488d50ae674aabdcb4f248006d5","price_changes":[{"asset_id":"14965588658799411272385430903075831224615961675357217884735713260981483529984","best_ask":"0.22","best_bid":"0.2","hash":"2ea5166873d32d101d293129383e18b69842c474","price":"0.18","side":"BUY","size":"63.6"},{"asset_id":"8761897749749422724209054078244794145777693856614463256546737399611489089783","best_ask":"0.8","best_bid":"0.78","hash":"8c10fa5529d9c9eb20e3ab98cbb06ed9b0bc2316","price":"0.82","side":"SELL","size":"63.6"}],"timestamp":"1785207995938"},"payload_hash":"4ebcecaa2d7ba8d765fe97c12be702c852a8f3c388a9bfa40767b9e157d963f8","raw_frame":"{\"market\":\"0x779291bef19b6709f61e9764a954aafe9ffae488d50ae674aabdcb4f248006d5\", \"price_changes\":[{\"asset_id\":\"14965588658799411272385430903075831224615961675357217884735713260981483529984\", \"price\":\"0.18\", \"size\":\"63.6\", \"side\":\"BUY\", \"hash\":\"2ea5166873d32d101d293129383e18b69842c474\", \"best_bid\":\"0.2\", \"best_ask\":\"0.22\"}, {\"asset_id\":\"8761897749749422724209054078244794145777693856614463256546737399611489089783\", \"price\":\"0.82\", \"size\":\"63.6\", \"side\":\"SELL\", \"hash\":\"8c10fa5529d9c9eb20e3ab98cbb06ed9b0bc2316\", \"best_bid\":\"0.78\", \"best_ask\":\"0.8\"}], \"timestamp\":\"1785207995938\", \"event_type\":\"price_change\"}","received_at":"2026-07-28T03:06:35.863675Z","schema_version":"clob-market-ws.price_change.v1","sequence":null,"server_hash":null,"server_timestamp":"1785207995938","session_id":"3e519d9098404c15b234d96025eb1a2b","source":"clob_market_ws"},"received_at":"2026-07-28T03:06:35.863675Z","record_id":"c373f05e9e707c5615c1237bcf6596155cde977435fe7402a3968d0c4acb8e92","schema_fingerprint":"4aa3821a28b0b7c2400bc59aba4bcc0a76e971dadd19610d3ad38c768e124dc7","schema_version":"edge-lab-recorder.raw.v1","sequence":null,"source":"clob_market_ws"}
{"event_at":"2026-07-28T03:06:35.939000Z","event_fingerprint":"0edbf393d41fcb2e45e5822553ed8239d6bcd2e4f7c433c0193a6f822627eb57","payload":{"connection_id":"a6b55582af5f430fb37ad02bf0922475","event_at":"2026-07-28T03:06:35.939000Z","event_type":"price_change","frame_hash":"97ea473959e51bb5bbec3b3f310f87153e964d24b8adf88f4448aff18fa604e8","frame_index":0,"kind":"data","monotonic_ns":309978898285041,"payload":{"event_type":"price_change","market":"0x779291bef19b6709f61e9764a954aafe9ffae488d50ae674aabdcb4f248006d5","price_changes":[{"asset_id":"8761897749749422724209054078244794145777693856614463256546737399611489089783","best_ask":"0.8","best_bid":"0.78","hash":"bc380e9391e257684abc0e1650112aa102091b88","price":"0.77","side":"BUY","size":"116.98"},{"asset_id":"14965588658799411272385430903075831224615961675357217884735713260981483529984","best_ask":"0.22","best_bid":"0.2","hash":"62d690d02487bff342c7c7143618a85df092f030","price":"0.23","side":"SELL","size":"116.98"}],"timestamp":"1785207995939"},"payload_hash":"7f1045571214dd92e2f268e5899c43cbd23c72f2eec942fe07700e85b2218ce0","raw_frame":"{\"market\":\"0x779291bef19b6709f61e9764a954aafe9ffae488d50ae674aabdcb4f248006d5\", \"price_changes\":[{\"asset_id\":\"8761897749749422724209054078244794145777693856614463256546737399611489089783\", \"price\":\"0.77\", \"size\":\"116.98\", \"side\":\"BUY\", \"hash\":\"bc380e9391e257684abc0e1650112aa102091b88\", \"best_bid\":\"0.78\", \"best_ask\":\"0.8\"}, {\"asset_id\":\"14965588658799411272385430903075831224615961675357217884735713260981483529984\", \"price\":\"0.23\", \"size\":\"116.98\", \"side\":\"SELL\", \"hash\":\"62d690d02487bff342c7c7143618a85df092f030\", \"best_bid\":\"0.2\", \"best_ask\":\"0.22\"}], \"timestamp\":\"1785207995939\", \"event_type\":\"price_change\"}","received_at":"2026-07-28T03:06:35.866747Z","schema_version":"clob-market-ws.price_change.v1","sequence":null,"server_hash":null,"server_timestamp":"1785207995939","session_id":"3e519d9098404c15b234d96025eb1a2b","source":"clob_market_ws"},"received_at":"2026-07-28T03:06:35.866747Z","record_id":"46577bc6d256fe0a77af0c7954d1961de4d79e54155bdfa9a0e8b20ad4580584","schema_fingerprint":"4aa3821a28b0b7c2400bc59aba4bcc0a76e971dadd19610d3ad38c768e124dc7","schema_version":"edge-lab-recorder.raw.v1","sequence":null,"source":"clob_market_ws"}
{"event_at":"2026-07-28T03:06:35.940000Z","event_fingerprint":"7bc56eaf7853c130f4d3a15f3e9d36449902013789d2a7c59ced49f56e008cf8","payload":{"connection_id":"a6b55582af5f430fb37ad02bf0922475","event_at":"2026-07-28T03:06:35.940000Z","event_type":"price_change","frame_hash":"66f0e4aac416f9a105b740156293ae8cd9c186ef2cd3eb33f57590f01b69b430","frame_index":0,"kind":"data","monotonic_ns":309978902718500,"payload":{"event_type":"price_change","market":"0x779291bef19b6709f61e9764a954aafe9ffae488d50ae674aabdcb4f248006d5","price_changes":[{"asset_id":"14965588658799411272385430903075831224615961675357217884735713260981483529984","best_ask":"0.22","best_bid":"0.2","hash":"46f2ea3e104bf291985c4eec9ac5d52f35bd4e56","price":"0.2","side":"BUY","size":"118.2"},{"asset_id":"8761897749749422724209054078244794145777693856614463256546737399611489089783","best_ask":"0.8","best_bid":"0.78","hash":"dc439252c92cc1c9366d8e694965c463427b71a4","price":"0.8","side":"SELL","size":"118.2"}],"timestamp":"1785207995940"},"payload_hash":"98bb11f1c92c686d437c4ed79f1643db7f01204ff35a7081161e5dfc020c9ea2","raw_frame":"{\"market\":\"0x779291bef19b6709f61e9764a954aafe9ffae488d50ae674aabdcb4f248006d5\", \"price_changes\":[{\"asset_id\":\"14965588658799411272385430903075831224615961675357217884735713260981483529984\", \"price\":\"0.2\", \"size\":\"118.2\", \"side\":\"BUY\", \"hash\":\"46f2ea3e104bf291985c4eec9ac5d52f35bd4e56\", \"best_bid\":\"0.2\", \"best_ask\":\"0.22\"}, {\"asset_id\":\"8761897749749422724209054078244794145777693856614463256546737399611489089783\", \"price\":\"0.8\", \"size\":\"118.2\", \"side\":\"SELL\", \"hash\":\"dc439252c92cc1c9366d8e694965c463427b71a4\", \"best_bid\":\"0.78\", \"best_ask\":\"0.8\"}], \"timestamp\":\"1785207995940\", \"event_type\":\"price_change\"}","received_at":"2026-07-28T03:06:35.871182Z","schema_version":"clob-market-ws.price_change.v1","sequence":null,"server_hash":null,"server_timestamp":"1785207995940","session_id":"3e519d9098404c15b234d96025eb1a2b","source":"clob_market_ws"},"received_at":"2026-07-28T03:06:35.871182Z","record_id":"c2fcb0019130e4e01e8c47dd9d2be4565fb81573cceb78a3f3a7bfa5c5d6db6b","schema_fingerprint":"4aa3821a28b0b7c2400bc59aba4bcc0a76e971dadd19610d3ad38c768e124dc7","schema_version":"edge-lab-recorder.raw.v1","sequence":null,"source":"clob_market_ws"}
{"event_at":"2026-07-28T03:06:35.941000Z","event_fingerprint":"41d1c797214b6ff2c2dd77ee58d23436b764124dff4c1838f547f38801d2569b","payload":{"connection_id":"a6b55582af5f430fb37ad02bf0922475","event_at":"2026-07-28T03:06:35.941000Z","event_type":"best_bid_ask","frame_hash":"1101fd6c8e0a1fb69e7e063b53c945863e46cc541ceb01207d8e0da0b61d8a21","frame_index":0,"kind":"data","monotonic_ns":309978905256625,"payload":{"asset_id":"14965588658799411272385430903075831224615961675357217884735713260981483529984","best_ask":"0.21","best_bid":"0.2","event_type":"best_bid_ask","market":"0x779291bef19b6709f61e9764a954aafe9ffae488d50ae674aabdcb4f248006d5","spread":"0.01","timestamp":"1785207995941"},"payload_hash":"5e6560aea445c6f324a2f633ec68d1709025819d769cedea88e72ce22991b310","raw_frame":"{\"market\":\"0x779291bef19b6709f61e9764a954aafe9ffae488d50ae674aabdcb4f248006d5\", \"asset_id\":\"14965588658799411272385430903075831224615961675357217884735713260981483529984\", \"best_bid\":\"0.2\", \"best_ask\":\"0.21\", \"spread\":\"0.01\", \"timestamp\":\"1785207995941\", \"event_type\":\"best_bid_ask\"}","received_at":"2026-07-28T03:06:35.873720Z","schema_version":"clob-market-ws.best_bid_ask.v1","sequence":null,"server_hash":null,"server_timestamp":"1785207995941","session_id":"3e519d9098404c15b234d96025eb1a2b","source":"clob_market_ws"},"received_at":"2026-07-28T03:06:35.873720Z","record_id":"8ffae5ee3f0cc7dcca667137635e5a9b177e172ad5d593f5c79706e512d194f0","schema_fingerprint":"8488399f31b0337811b13b266be932db7062827c2470b78bd8e9e99bab51d17d","schema_version":"edge-lab-recorder.raw.v1","sequence":null,"source":"clob_market_ws"}
{"event_at":"2026-07-28T03:06:35.941000Z","event_fingerprint":"3d40c0e5a60f11a53d73fa6b402f4c31440ba7e379a6f0912226ba36ab7cbd3d","payload":{"connection_id":"a6b55582af5f430fb37ad02bf0922475","event_at":"2026-07-28T03:06:35.941000Z","event_type":"best_bid_ask","frame_hash":"8d06fd38b7c6e23cbecdb19d28d0c76788a9d1427c186b172247e464c993a0a3","frame_index":0,"kind":"data","monotonic_ns":309978907372875,"payload":{"asset_id":"8761897749749422724209054078244794145777693856614463256546737399611489089783","best_ask":"0.8","best_bid":"0.79","event_type":"best_bid_ask","market":"0x779291bef19b6709f61e9764a954aafe9ffae488d50ae674aabdcb4f248006d5","spread":"0.01","timestamp":"1785207995941"},"payload_hash":"e02cb9847ff2960d1ab967a986c00c322e206e44cc0839d63f0b63b6470a7cfa","raw_frame":"{\"market\":\"0x779291bef19b6709f61e9764a954aafe9ffae488d50ae674aabdcb4f248006d5\", \"asset_id\":\"8761897749749422724209054078244794145777693856614463256546737399611489089783\", \"best_bid\":\"0.79\", \"best_ask\":\"0.8\", \"spread\":\"0.01\", \"timestamp\":\"1785207995941\", \"event_type\":\"best_bid_ask\"}","received_at":"2026-07-28T03:06:35.875837Z","schema_version":"clob-market-ws.best_bid_ask.v1","sequence":null,"server_hash":null,"server_timestamp":"1785207995941","session_id":"3e519d9098404c15b234d96025eb1a2b","source":"clob_market_ws"},"received_at":"2026-07-28T03:06:35.875837Z","record_id":"fea8325be5374a65fa25214cedff82d0fa19fa435c05dd8dcd41c0bd4ef8ffaf","schema_fingerprint":"8488399f31b0337811b13b266be932db7062827c2470b78bd8e9e99bab51d17d","schema_version":"edge-lab-recorder.raw.v1","sequence":null,"source":"clob_market_ws"}
{"event_at":"2026-07-28T03:06:35.941000Z","event_fingerprint":"0a21337c43a8b7feb6485393097dbcc2c7a2d9e44a2fa0500aa58a5dfeb180c5","payload":{"connection_id":"a6b55582af5f430fb37ad02bf0922475","event_at":"2026-07-28T03:06:35.941000Z","event_type":"price_change","frame_hash":"2f528b008e27060ad4f73942b28a77986278fc4659b7d989593207fb3e145fa8","frame_index":0,"kind":"data","monotonic_ns":309978909984375,"payload":{"event_type":"price_change","market":"0x779291bef19b6709f61e9764a954aafe9ffae488d50ae674aabdcb4f248006d5","price_changes":[{"asset_id":"8761897749749422724209054078244794145777693856614463256546737399611489089783","best_ask":"0.8","best_bid":"0.79","hash":"4ce7066f90f2aa77d691ed1a79f4b3b029be78c3","price":"0.79","side":"BUY","size":"20"},{"asset_id":"14965588658799411272385430903075831224615961675357217884735713260981483529984","best_ask":"0.21","best_bid":"0.2","hash":"e652768262fcb8f0a80694a1099f89fecc3bdddb","price":"0.21","side":"SELL","size":"20"}],"timestamp":"1785207995941"},"payload_hash":"50373ddd300c9b018b4727ffdce28cc009b4cba9f796bf870285bddc2669fdcf","raw_frame":"{\"market\":\"0x779291bef19b6709f61e9764a954aafe9ffae488d50ae674aabdcb4f248006d5\", \"price_changes\":[{\"asset_id\":\"8761897749749422724209054078244794145777693856614463256546737399611489089783\", \"price\":\"0.79\", \"size\":\"20\", \"side\":\"BUY\", \"hash\":\"4ce7066f90f2aa77d691ed1a79f4b3b029be78c3\", \"best_bid\":\"0.79\", \"best_ask\":\"0.8\"}, {\"asset_id\":\"14965588658799411272385430903075831224615961675357217884735713260981483529984\", \"price\":\"0.21\", \"size\":\"20\", \"side\":\"SELL\", \"hash\":\"e652768262fcb8f0a80694a1099f89fecc3bdddb\", \"best_bid\":\"0.2\", \"best_ask\":\"0.21\"}], \"timestamp\":\"1785207995941\", \"event_type\":\"price_change\"}","received_at":"2026-07-28T03:06:35.878449Z","schema_version":"clob-market-ws.price_change.v1","sequence":null,"server_hash":null,"server_timestamp":"1785207995941","session_id":"3e519d9098404c15b234d96025eb1a2b","source":"clob_market_ws"},"received_at":"2026-07-28T03:06:35.878449Z","record_id":"124448ddef53c571c01731f10d6d311d3c802ff99019180f07011550c24471f9","schema_fingerprint":"4aa3821a28b0b7c2400bc59aba4bcc0a76e971dadd19610d3ad38c768e124dc7","schema_version":"edge-lab-recorder.raw.v1","sequence":null,"source":"clob_market_ws"}
{"event_at":"2026-07-28T03:06:35.942000Z","event_fingerprint":"5ed9ab3d7f1e22732afaf083421519be2040a4f9e17967c58feed213dcff66ff","payload":{"connection_id":"a6b55582af5f430fb37ad02bf0922475","event_at":"2026-07-28T03:06:35.942000Z","event_type":"price_change","frame_hash":"d8a3169fecc2c6987d798828d76cee427782f5c9998ad02a30eea851f2830709","frame_index":0,"kind":"data","monotonic_ns":309978912531541,"payload":{"event_type":"price_change","market":"0x779291bef19b6709f61e9764a954aafe9ffae488d50ae674aabdcb4f248006d5","price_changes":[{"asset_id":"8761897749749422724209054078244794145777693856614463256546737399611489089783","best_ask":"0.8","best_bid":"0.79","hash":"39c5ce9d850d9e0bf556081ccd62c2ec505421e2","price":"0.78","side":"BUY","size":"48"},{"asset_id":"14965588658799411272385430903075831224615961675357217884735713260981483529984","best_ask":"0.21","best_bid":"0.2","hash":"d0f81f198efd14fe12dbd0725034d0c1babf8344","price":"0.22","side":"SELL","size":"48"}],"timestamp":"1785207995942"},"payload_hash":"5918bb7459d72f1e46c7c10c09d01eaf12595c08d06f62f55946f0ca6884a511","raw_frame":"{\"market\":\"0x779291bef19b6709f61e9764a954aafe9ffae488d50ae674aabdcb4f248006d5\", \"price_changes\":[{\"asset_id\":\"8761897749749422724209054078244794145777693856614463256546737399611489089783\", \"price\":\"0.78\", \"size\":\"48\", \"side\":\"BUY\", \"hash\":\"39c5ce9d850d9e0bf556081ccd62c2ec505421e2\", \"best_bid\":\"0.79\", \"best_ask\":\"0.8\"}, {\"asset_id\":\"14965588658799411272385430903075831224615961675357217884735713260981483529984\", \"price\":\"0.22\", \"size\":\"48\", \"side\":\"SELL\", \"hash\":\"d0f81f198efd14fe12dbd0725034d0c1babf8344\", \"best_bid\":\"0.2\", \"best_ask\":\"0.21\"}], \"timestamp\":\"1785207995942\", \"event_type\":\"price_change\"}","received_at":"2026-07-28T03:06:35.880996Z","schema_version":"clob-market-ws.price_change.v1","sequence":null,"server_hash":null,"server_timestamp":"1785207995942","session_id":"3e519d9098404c15b234d96025eb1a2b","source":"clob_market_ws"},"received_at":"2026-07-28T03:06:35.880996Z","record_id":"663fba44cb333f0cfddd536b6cb36b2728e35209652d13aad62ca94b24aef44d","schema_fingerprint":"4aa3821a28b0b7c2400bc59aba4bcc0a76e971dadd19610d3ad38c768e124dc7","schema_version":"edge-lab-recorder.raw.v1","sequence":null,"source":"clob_market_ws"}
{"event_at":"2026-07-28T03:06:35.942000Z","event_fingerprint":"94b811e29e8abb5b1fef48dbf71b2215cfe85fb48a3897091c8669e7f5105621","payload":{"connection_id":"a6b55582af5f430fb37ad02bf0922475","event_at":"2026-07-28T03:06:35.942000Z","event_type":"price_change","frame_hash":"e92d4533efece4b9d4f3a43a85fc9009ed9f881ba11504534fc747c4653753c9","frame_index":0,"kind":"data","monotonic_ns":309978919283750,"payload":{"event_type":"price_change","market":"0x779291bef19b6709f61e9764a954aafe9ffae488d50ae674aabdcb4f248006d5","price_changes":[{"asset_id":"8761897749749422724209054078244794145777693856614463256546737399611489089783","best_ask":"0.8","best_bid":"0.79","hash":"40ac1239ee3c0c1671cee69fa9a63faf4e7246c6","price":"0.01","side":"BUY","size":"5608.02"},{"asset_id":"14965588658799411272385430903075831224615961675357217884735713260981483529984","best_ask":"0.21","best_bid":"0.2","hash":"941c664b42d68d03bed38fc6e643233b2331347d","price":"0.99","side":"SELL","size":"5608.02"}],"timestamp":"1785207995942"},"payload_hash":"077136b66606c5fc2af58454ae1dabe27561ccc1f05a345293b5e75806c2b664","raw_frame":"{\"market\":\"0x779291bef19b6709f61e9764a954aafe9ffae488d50ae674aabdcb4f248006d5\", \"price_changes\":[{\"asset_id\":\"8761897749749422724209054078244794145777693856614463256546737399611489089783\", \"price\":\"0.01\", \"size\":\"5608.02\", \"side\":\"BUY\", \"hash\":\"40ac1239ee3c0c1671cee69fa9a63faf4e7246c6\", \"best_bid\":\"0.79\", \"best_ask\":\"0.8\"}, {\"asset_id\":\"14965588658799411272385430903075831224615961675357217884735713260981483529984\", \"price\":\"0.99\", \"size\":\"5608.02\", \"side\":\"SELL\", \"hash\":\"941c664b42d68d03bed38fc6e643233b2331347d\", \"best_bid\":\"0.2\", \"best_ask\":\"0.21\"}], \"timestamp\":\"1785207995942\", \"event_type\":\"price_change\"}","received_at":"2026-07-28T03:06:35.887748Z","schema_version":"clob-market-ws.price_change.v1","sequence":null,"server_hash":null,"server_timestamp":"1785207995942","session_id":"3e519d9098404c15b234d96025eb1a2b","source":"clob_market_ws"},"received_at":"2026-07-28T03:06:35.887748Z","record_id":"1b3f3aab9a8e9a6d896085c74c1a72240f094b9971ca53621e9dd44d49dfcd8e","schema_fingerprint":"4aa3821a28b0b7c2400bc59aba4bcc0a76e971dadd19610d3ad38c768e124dc7","schema_version":"edge-lab-recorder.raw.v1","sequence":null,"source":"clob_market_ws"}
{"event_at":"2026-07-28T03:06:35.943000Z","event_fingerprint":"632f2fb5f0c967de5c0a0ebaeae3bb83ab031b2a31b761f91f145fa4f579d8d1","payload":{"connection_id":"a6b55582af5f430fb37ad02bf0922475","event_at":"2026-07-28T03:06:35.943000Z","event_type":"price_change","frame_hash":"7157295175996fdd7520b31f076ffd13df8251b40df90f1858334f32bcc57d7f","frame_index":0,"kind":"data","monotonic_ns":309978923658750,"payload":{"event_type":"price_change","market":"0x779291bef19b6709f61e9764a954aafe9ffae488d50ae674aabdcb4f248006d5","price_changes":[{"asset_id":"8761897749749422724209054078244794145777693856614463256546737399611489089783","best_ask":"0.8","best_bid":"0.79","hash":"a6a99d613f50eb52a0cf3f6072d8e859e5b53c03","price":"0.78","side":"BUY","size":"58"},{"asset_id":"14965588658799411272385430903075831224615961675357217884735713260981483529984","best_ask":"0.21","best_bid":"0.2","hash":"ea8d926572206ec61a651ffc32ecd9f2f5c08456","price":"0.22","side":"SELL","size":"58"}],"timestamp":"1785207995943"},"payload_hash":"96ac2a65892a8c4c91d840c67927be219b4ea389030669a74eedee86d4606bc3","raw_frame":"{\"market\":\"0x779291bef19b6709f61e9764a954aafe9ffae488d50ae674aabdcb4f248006d5\", \"price_changes\":[{\"asset_id\":\"8761897749749422724209054078244794145777693856614463256546737399611489089783\", \"price\":\"0.78\", \"size\":\"58\", \"side\":\"BUY\", \"hash\":\"a6a99d613f50eb52a0cf3f6072d8e859e5b53c03\", \"best_bid\":\"0.79\", \"best_ask\":\"0.8\"}, {\"asset_id\":\"14965588658799411272385430903075831224615961675357217884735713260981483529984\", \"price\":\"0.22\", \"size\":\"58\", \"side\":\"SELL\", \"hash\":\"ea8d926572206ec61a651ffc32ecd9f2f5c08456\", \"best_bid\":\"0.2\", \"best_ask\":\"0.21\"}], \"timestamp\":\"1785207995943\", \"event_type\":\"price_change\"}","received_at":"2026-07-28T03:06:35.892122Z","schema_version":"clob-market-ws.price_change.v1","sequence":null,"server_hash":null,"server_timestamp":"1785207995943","session_id":"3e519d9098404c15b234d96025eb1a2b","source":"clob_market_ws"},"received_at":"2026-07-28T03:06:35.892122Z","record_id":"00ceb37fd424897864b31bf0318d6fc302bc9906c45f4314400a26747ffac158","schema_fingerprint":"4aa3821a28b0b7c2400bc59aba4bcc0a76e971dadd19610d3ad38c768e124dc7","schema_version":"edge-lab-recorder.raw.v1","sequence":null,"source":"clob_market_ws"}
{"event_at":"2026-07-28T03:06:35.943000Z","event_fingerprint":"6b5ad41db1e359523987ce0b17051cf1cb4e1f7d57905f93036e7718d0ac867e","payload":{"connection_id":"a6b55582af5f430fb37ad02bf0922475","event_at":"2026-07-28T03:06:35.943000Z","event_type":"price_change","frame_hash":"b00868d20e6456abc6317e8c840142ce04c789f48ccca8bfce77a91a27f314cb","frame_index":0,"kind":"data","monotonic_ns":309978926191250,"payload":{"event_type":"price_change","market":"0x779291bef19b6709f61e9764a954aafe9ffae488d50ae674aabdcb4f248006d5","price_changes":[{"asset_id":"8761897749749422724209054078244794145777693856614463256546737399611489089783","best_ask":"0.8","best_bid":"0.79","hash":"3ab2eb995f4560be603d5b81fc25002ee28dee86","price":"0.78","side":"BUY","size":"78"},{"asset_id":"14965588658799411272385430903075831224615961675357217884735713260981483529984","best_ask":"0.21","best_bid":"0.2","hash":"a59f5019f0c76eb50c111219e718179bc2bd8bbd","price":"0.22","side":"SELL","size":"78"}],"timestamp":"1785207995943"},"payload_hash":"6143128840f92bd19fef612c5a7fa2485bb3b42f8eaa7bba420667fe9eab58e1","raw_frame":"{\"market\":\"0x779291bef19b6709f61e9764a954aafe9ffae488d50ae674aabdcb4f248006d5\", \"price_changes\":[{\"asset_id\":\"8761897749749422724209054078244794145777693856614463256546737399611489089783\", \"price\":\"0.78\", \"size\":\"78\", \"side\":\"BUY\", \"hash\":\"3ab2eb995f4560be603d5b81fc25002ee28dee86\", \"best_bid\":\"0.79\", \"best_ask\":\"0.8\"}, {\"asset_id\":\"14965588658799411272385430903075831224615961675357217884735713260981483529984\", \"price\":\"0.22\", \"size\":\"78\", \"side\":\"SELL\", \"hash\":\"a59f5019f0c76eb50c111219e718179bc2bd8bbd\", \"best_bid\":\"0.2\", \"best_ask\":\"0.21\"}], \"timestamp\":\"1785207995943\", \"event_type\":\"price_change\"}","received_at":"2026-07-28T03:06:35.894655Z","schema_version":"clob-market-ws.price_change.v1","sequence":null,"server_hash":null,"server_timestamp":"1785207995943","session_id":"3e519d9098404c15b234d96025eb1a2b","source":"clob_market_ws"},"received_at":"2026-07-28T03:06:35.894655Z","record_id":"d8d40daad81fcd99ebf945d7cba6af274a6074f60c0e0d30dc6b48ba83c6346a","schema_fingerprint":"4aa3821a28b0b7c2400bc59aba4bcc0a76e971dadd19610d3ad38c768e124dc7","schema_version":"edge-lab-recorder.raw.v1","sequence":null,"source":"clob_market_ws"}
{"event_at":"2026-07-28T03:06:35.945000Z","event_fingerprint":"d29ae8f565d71aa6c31b096ae3336a4ec2ddba18273ac1af3818290defc235e0","payload":{"connection_id":"a6b55582af5f430fb37ad02bf0922475","event_at":"2026-07-28T03:06:35.945000Z","event_type":"price_change","frame_hash":"438dd96a4f45d8b57bc6f1dc712703f714cfd9521ae4a9985d1f11f23b11244f","frame_index":0,"kind":"data","monotonic_ns":309978932214833,"payload":{"event_type":"price_change","market":"0x779291bef19b6709f61e9764a954aafe9ffae488d50ae674aabdcb4f248006d5","price_changes":[{"asset_id":"8761897749749422724209054078244794145777693856614463256546737399611489089783","best_ask":"0.8","best_bid":"0.79","hash":"9ed55747501020ae27704ef6c1a0e0ad74e13c6d","price":"0.79","side":"BUY","size":"30"},{"asset_id":"14965588658799411272385430903075831224615961675357217884735713260981483529984","best_ask":"0.21","best_bid":"0.2","hash":"f18aec48bfa84c47911b87fdc6d387993a71477e","price":"0.21","side":"SELL","size":"30"}],"timestamp":"1785207995945"},"payload_hash":"b06ddab480d37ba7c6a5c3e249e790f697e031678b0e5a1247a40ed45685bb6b","raw_frame":"{\"market\":\"0x779291bef19b6709f61e9764a954aafe9ffae488d50ae674aabdcb4f248006d5\", \"price_changes\":[{\"asset_id\":\"8761897749749422724209054078244794145777693856614463256546737399611489089783\", \"price\":\"0.79\", \"size\":\"30\", \"side\":\"BUY\", \"hash\":\"9ed55747501020ae27704ef6c1a0e0ad74e13c6d\", \"best_bid\":\"0.79\", \"best_ask\":\"0.8\"}, {\"asset_id\":\"14965588658799411272385430903075831224615961675357217884735713260981483529984\", \"price\":\"0.21\", \"size\":\"30\", \"side\":\"SELL\", \"hash\":\"f18aec48bfa84c47911b87fdc6d387993a71477e\", \"best_bid\":\"0.2\", \"best_ask\":\"0.21\"}], \"timestamp\":\"1785207995945\", \"event_type\":\"price_change\"}","received_at":"2026-07-28T03:06:35.900679Z","schema_version":"clob-market-ws.price_change.v1","sequence":null,"server_hash":null,"server_timestamp":"1785207995945","session_id":"3e519d9098404c15b234d96025eb1a2b","source":"clob_market_ws"},"received_at":"2026-07-28T03:06:35.900679Z","record_id":"e09fa4d91aa9a2beac84bd2ca20785ad769c4d3b78aad95464eeecfd21fb125f","schema_fingerprint":"4aa3821a28b0b7c2400bc59aba4bcc0a76e971dadd19610d3ad38c768e124dc7","schema_version":"edge-lab-recorder.raw.v1","sequence":null,"source":"clob_market_ws"}
{"event_at":"2026-07-28T03:06:35.946000Z","event_fingerprint":"68fc1032b0a0375b7140b386faa4cfb7d3ce0a912fd832ff31bfdfca4f6ba76e","payload":{"connection_id":"a6b55582af5f430fb37ad02bf0922475","event_at":"2026-07-28T03:06:35.946000Z","event_type":"price_change","frame_hash":"02d9c3026993b8e1252cab3e96430d7c102b32f2074601d7cdc9749c1d7337b1","frame_index":0,"kind":"data","monotonic_ns":309978937645291,"payload":{"event_type":"price_change","market":"0x779291bef19b6709f61e9764a954aafe9ffae488d50ae674aabdcb4f248006d5","price_changes":[{"asset_id":"14965588658799411272385430903075831224615961675357217884735713260981483529984","best_ask":"0.21","best_bid":"0.2","hash":"e10cbc0313c0f3013da82a1b7e244d1857a91640","price":"0.14","side":"BUY","size":"263.9"},{"asset_id":"8761897749749422724209054078244794145777693856614463256546737399611489089783","best_ask":"0.8","best_bid":"0.79","hash":"bac51dd5218c66e121116987e81f567717ef9316","price":"0.86","side":"SELL","size":"263.9"}],"timestamp":"1785207995946"},"payload_hash":"77d608504de9b977bf56886278ec05c700148901f8b12517110d584f1dc742ed","raw_frame":"{\"market\":\"0x779291bef19b6709f61e9764a954aafe9ffae488d50ae674aabdcb4f248006d5\", \"price_changes\":[{\"asset_id\":\"14965588658799411272385430903075831224615961675357217884735713260981483529984\", \"price\":\"0.14\", \"size\":\"263.9\", \"side\":\"BUY\", \"hash\":\"e10cbc0313c0f3013da82a1b7e244d1857a91640\", \"best_bid\":\"0.2\", \"best_ask\":\"0.21\"}, {\"asset_id\":\"8761897749749422724209054078244794145777693856614463256546737399611489089783\", \"price\":\"0.86\", \"size\":\"263.9\", \"side\":\"SELL\", \"hash\":\"bac51dd5218c66e121116987e81f567717ef9316\", \"best_bid\":\"0.79\", \"best_ask\":\"0.8\"}], \"timestamp\":\"1785207995946\", \"event_type\":\"price_change\"}","received_at":"2026-07-28T03:06:35.906106Z","schema_version":"clob-market-ws.price_change.v1","sequence":null,"server_hash":null,"server_timestamp":"1785207995946","session_id":"3e519d9098404c15b234d96025eb1a2b","source":"clob_market_ws"},"received_at":"2026-07-28T03:06:35.906106Z","record_id":"cafd0283306c7dfcfc321932fd70cced4a17bc97a77573ce6f8a3f8c9291b496","schema_fingerprint":"4aa3821a28b0b7c2400bc59aba4bcc0a76e971dadd19610d3ad38c768e124dc7","schema_version":"edge-lab-recorder.raw.v1","sequence":null,"source":"clob_market_ws"}
{"event_at":"2026-07-28T03:06:35.946000Z","event_fingerprint":"e5255bfa91b00d93934de72e71fe802463c65331b61b82f3347bf871778d354c","payload":{"connection_id":"a6b55582af5f430fb37ad02bf0922475","event_at":"2026-07-28T03:06:35.946000Z","event_type":"price_change","frame_hash":"7618a7bb7bff4807943e8baa059e5813a2581fd82998a4d6b5f02e9366f2516b","frame_index":0,"kind":"data","monotonic_ns":309978940823166,"payload":{"event_type":"price_change","market":"0x779291bef19b6709f61e9764a954aafe9ffae488d50ae674aabdcb4f248006d5","price_changes":[{"asset_id":"14965588658799411272385430903075831224615961675357217884735713260981483529984","best_ask":"0.21","best_bid":"0.2","hash":"efa4c3cb7732810371d84c1fda743f6ac5e0f2a9","price":"0.14","side":"BUY","size":"233.9"},{"asset_id":"8761897749749422724209054078244794145777693856614463256546737399611489089783","best_ask":"0.8","best_bid":"0.79","hash":"f0e5ecd5236898a23f20c9cf1b174cd619b703e9","price":"0.86","side":"SELL","size":"233.9"}],"timestamp":"1785207995946"},"payload_hash":"ff4500afb70dd280777c7ef06f77248628b98fc1e2067663959c9efe092b9c25","raw_frame":"{\"market\":\"0x779291bef19b6709f61e9764a954aafe9ffae488d50ae674aabdcb4f248006d5\", \"price_changes\":[{\"asset_id\":\"14965588658799411272385430903075831224615961675357217884735713260981483529984\", \"price\":\"0.14\", \"size\":\"233.9\", \"side\":\"BUY\", \"hash\":\"efa4c3cb7732810371d84c1fda743f6ac5e0f2a9\", \"best_bid\":\"0.2\", \"best_ask\":\"0.21\"}, {\"asset_id\":\"8761897749749422724209054078244794145777693856614463256546737399611489089783\", \"price\":\"0.86\", \"size\":\"233.9\", \"side\":\"SELL\", \"hash\":\"f0e5ecd5236898a23f20c9cf1b174cd619b703e9\", \"best_bid\":\"0.79\", \"best_ask\":\"0.8\"}], \"timestamp\":\"1785207995946\", \"event_type\":\"price_change\"}","received_at":"2026-07-28T03:06:35.909285Z","schema_version":"clob-market-ws.price_change.v1","sequence":null,"server_hash":null,"server_timestamp":"1785207995946","session_id":"3e519d9098404c15b234d96025eb1a2b","source":"clob_market_ws"},"received_at":"2026-07-28T03:06:35.909285Z","record_id":"4277735006dd56a850f63e70b97b1f3093016950ddb42748bbe8ca3d1ef0314f","schema_fingerprint":"4aa3821a28b0b7c2400bc59aba4bcc0a76e971dadd19610d3ad38c768e124dc7","schema_version":"edge-lab-recorder.raw.v1","sequence":null,"source":"clob_market_ws"}
{"event_at":"2026-07-28T03:06:35.946000Z","event_fingerprint":"98d59355add9214ec6b68a58433d5e09f54f3314d6f3c694031de0596d954826","payload":{"connection_id":"a6b55582af5f430fb37ad02bf0922475","event_at":"2026-07-28T03:06:35.946000Z","event_type":"price_change","frame_hash":"c93de5a5d6fefc0c5523a1c3aa8e2761b957fa177dbf9f2f70b8b100c371bb9b","frame_index":0,"kind":"data","monotonic_ns":309978943868750,"payload":{"event_type":"price_change","market":"0x779291bef19b6709f61e9764a954aafe9ffae488d50ae674aabdcb4f248006d5","price_changes":[{"asset_id":"8761897749749422724209054078244794145777693856614463256546737399611489089783","best_ask":"0.8","best_bid":"0.79","hash":"5b1267ae3d03d9fd9ccab39a7b0441ba7f358a78","price":"0.75","side":"BUY","size":"152.19"},{"asset_id":"14965588658799411272385430903075831224615961675357217884735713260981483529984","best_ask":"0.21","best_bid":"0.2","hash":"be5e4da041f9060dc6b2708176bd00de1aca4f10","price":"0.25","side":"SELL","size":"152.19"}],"timestamp":"1785207995946"},"payload_hash":"32ab5c558acb2757867df841cde73fdcfd5bb8ea6ef07ae97de80ed1ad381668","raw_frame":"{\"market\":\"0x779291bef19b6709f61e9764a954aafe9ffae488d50ae674aabdcb4f248006d5\", \"price_changes\":[{\"asset_id\":\"8761897749749422724209054078244794145777693856614463256546737399611489089783\", \"price\":\"0.75\", \"size\":\"152.19\", \"side\":\"BUY\", \"hash\":\"5b1267ae3d03d9fd9ccab39a7b0441ba7f358a78\", \"best_bid\":\"0.79\", \"best_ask\":\"0.8\"}, {\"asset_id\":\"14965588658799411272385430903075831224615961675357217884735713260981483529984\", \"price\":\"0.25\", \"size\":\"152.19\", \"side\":\"SELL\", \"hash\":\"be5e4da041f9060dc6b2708176bd00de1aca4f10\", \"best_bid\":\"0.2\", \"best_ask\":\"0.21\"}], \"timestamp\":\"1785207995946\", \"event_type\":\"price_change\"}","received_at":"2026-07-28T03:06:35.912332Z","schema_version":"clob-market-ws.price_change.v1","sequence":null,"server_hash":null,"server_timestamp":"1785207995946","session_id":"3e519d9098404c15b234d96025eb1a2b","source":"clob_market_ws"},"received_at":"2026-07-28T03:06:35.912332Z","record_id":"6184a14b24e8fdd7bb1cc7ca242464a58ff67afc2cc57b12312b7af0d3a9f86d","schema_fingerprint":"4aa3821a28b0b7c2400bc59aba4bcc0a76e971dadd19610d3ad38c768e124dc7","schema_version":"edge-lab-recorder.raw.v1","sequence":null,"source":"clob_market_ws"}
{"event_at":"2026-07-28T03:06:35.947000Z","event_fingerprint":"eaa7e93c6bf8c1d5eb6388e465977253ae38a1a6977af3496eb211fb56ac22fe","payload":{"connection_id":"a6b55582af5f430fb37ad02bf0922475","event_at":"2026-07-28T03:06:35.947000Z","event_type":"price_change","frame_hash":"6049b28da1cc24b35354093dbebfd44338929898c81484f77f48a5adf2d39465","frame_index":0,"kind":"data","monotonic_ns":309978946879875,"payload":{"event_type":"price_change","market":"0x779291bef19b6709f61e9764a954aafe9ffae488d50ae674aabdcb4f248006d5","price_changes":[{"asset_id":"14965588658799411272385430903075831224615961675357217884735713260981483529984","best_ask":"0.21","best_bid":"0.2","hash":"98afbf9f761e6132654701f99958368c0db8dc57","price":"0.2","side":"BUY","size":"105.6"},{"asset_id":"8761897749749422724209054078244794145777693856614463256546737399611489089783","best_ask":"0.8","best_bid":"0.79","hash":"154e6b678f33f151b19f30b0d1aa7fb6de40d9fe","price":"0.8","side":"SELL","size":"105.6"}],"timestamp":"1785207995947"},"payload_hash":"320bf9d0228e2b1dc2a7b0d8d58c5f27c67ec013e7485aee1f13ecc096cc92c9","raw_frame":"{\"market\":\"0x779291bef19b6709f61e9764a954aafe9ffae488d50ae674aabdcb4f248006d5\", \"price_changes\":[{\"asset_id\":\"14965588658799411272385430903075831224615961675357217884735713260981483529984\", \"price\":\"0.2\", \"size\":\"105.6\", \"side\":\"BUY\", \"hash\":\"98afbf9f761e6132654701f99958368c0db8dc57\", \"best_bid\":\"0.2\", \"best_ask\":\"0.21\"}, {\"asset_id\":\"8761897749749422724209054078244794145777693856614463256546737399611489089783\", \"price\":\"0.8\", \"size\":\"105.6\", \"side\":\"SELL\", \"hash\":\"154e6b678f33f151b19f30b0d1aa7fb6de40d9fe\", \"best_bid\":\"0.79\", \"best_ask\":\"0.8\"}], \"timestamp\":\"1785207995947\", \"event_type\":\"price_change\"}","received_at":"2026-07-28T03:06:35.915343Z","schema_version":"clob-market-ws.price_change.v1","sequence":null,"server_hash":null,"server_timestamp":"1785207995947","session_id":"3e519d9098404c15b234d96025eb1a2b","source":"clob_market_ws"},"received_at":"2026-07-28T03:06:35.915343Z","record_id":"169fe2206defc37275e73e5cf551c3364d6f263dce9ba8c5270f2d1ca1a25361","schema_fingerprint":"4aa3821a28b0b7c2400bc59aba4bcc0a76e971dadd19610d3ad38c768e124dc7","schema_version":"edge-lab-recorder.raw.v1","sequence":null,"source":"clob_market_ws"}
{"event_at":"2026-07-28T03:06:35.948000Z","event_fingerprint":"2c4844435c62f6395009618b2d8027465739eb84cb7debf0e4b2231f9f753624","payload":{"connection_id":"a6b55582af5f430fb37ad02bf0922475","event_at":"2026-07-28T03:06:35.948000Z","event_type":"price_change","frame_hash":"9147f10de376f8beb7ddbb9baca66aa422fb981dd6dba6fd1e3f31986fdadf30","frame_index":0,"kind":"data","monotonic_ns":309978949918208,"payload":{"event_type":"price_change","market":"0x779291bef19b6709f61e9764a954aafe9ffae488d50ae674aabdcb4f248006d5","price_changes":[{"asset_id":"8761897749749422724209054078244794145777693856614463256546737399611489089783","best_ask":"0.8","best_bid":"0.79","hash":"521f74b72a5649f92760a6136f7a78b84efe6c5c","price":"0.77","side":"BUY","size":"131.98"},{"asset_id":"14965588658799411272385430903075831224615961675357217884735713260981483529984","best_ask":"0.21","best_bid":"0.2","hash":"2d190ecc3eabbb15c9c6ff82fd4697e89ef13899","price":"0.23","side":"SELL","size":"131.98"}],"timestamp":"1785207995948"},"payload_hash":"401e4751c1e13bb6af62449305f1aafda295f220e6822b7ebb21a078dad876cb","raw_frame":"{\"market\":\"0x779291bef19b6709f61e9764a954aafe9ffae488d50ae674aabdcb4f248006d5\", \"price_changes\":[{\"asset_id\":\"8761897749749422724209054078244794145777693856614463256546737399611489089783\", \"price\":\"0.77\", \"size\":\"131.98\", \"side\":\"BUY\", \"hash\":\"521f74b72a5649f92760a6136f7a78b84efe6c5c\", \"best_bid\":\"0.79\", \"best_ask\":\"0.8\"}, {\"asset_id\":\"14965588658799411272385430903075831224615961675357217884735713260981483529984\", \"price\":\"0.23\", \"size\":\"131.98\", \"side\":\"SELL\", \"hash\":\"2d190ecc3eabbb15c9c6ff82fd4697e89ef13899\", \"best_bid\":\"0.2\", \"best_ask\":\"0.21\"}], \"timestamp\":\"1785207995948\", \"event_type\":\"price_change\"}","received_at":"2026-07-28T03:06:35.918382Z","schema_version":"clob-market-ws.price_change.v1","sequence":null,"server_hash":null,"server_timestamp":"1785207995948","session_id":"3e519d9098404c15b234d96025eb1a2b","source":"clob_market_ws"},"received_at":"2026-07-28T03:06:35.918382Z","record_id":"401d3ca1606f16ca4d084fdb435113036f1bdb6bff3b945d6c42b1569a68b185","schema_fingerprint":"4aa3821a28b0b7c2400bc59aba4bcc0a76e971dadd19610d3ad38c768e124dc7","schema_version":"edge-lab-recorder.raw.v1","sequence":null,"source":"clob_market_ws"}
{"event_at":"2026-07-28T03:06:35.949000Z","event_fingerprint":"75b9e39d3beaba0cb3abe3a77d15587850736a0635b517423ea2ed411eac10f5","payload":{"connection_id":"a6b55582af5f430fb37ad02bf0922475","event_at":"2026-07-28T03:06:35.949000Z","event_type":"price_change","frame_hash":"159958b078e7a760fbf2f5704c9ea45e7d2904f4c1388762fe5f9f0e10359e60","frame_index":0,"kind":"data","monotonic_ns":309978952987833,"payload":{"event_type":"price_change","market":"0x779291bef19b6709f61e9764a954aafe9ffae488d50ae674aabdcb4f248006d5","price_changes":[{"asset_id":"14965588658799411272385430903075831224615961675357217884735713260981483529984","best_ask":"0.21","best_bid":"0.2","hash":"a8f62869d5d30b2aef471d656dc4cd95c00be0a3","price":"0.2","side":"BUY","size":"93"},{"asset_id":"8761897749749422724209054078244794145777693856614463256546737399611489089783","best_ask":"0.8","best_bid":"0.79","hash":"a1d6d87ea9c9a4e8ff79a6d79a5154b71d01f800","price":"0.8","side":"SELL","size":"93"}],"timestamp":"1785207995949"},"payload_hash":"84b09a0a445b7fe4c1194326ded9eaa897a35ebec6b2c59fdca92900150e5978","raw_frame":"{\"market\":\"0x779291bef19b6709f61e9764a954aafe9ffae488d50ae674aabdcb4f248006d5\", \"price_changes\":[{\"asset_id\":\"14965588658799411272385430903075831224615961675357217884735713260981483529984\", \"price\":\"0.2\", \"size\":\"93\", \"side\":\"BUY\", \"hash\":\"a8f62869d5d30b2aef471d656dc4cd95c00be0a3\", \"best_bid\":\"0.2\", \"best_ask\":\"0.21\"}, {\"asset_id\":\"8761897749749422724209054078244794145777693856614463256546737399611489089783\", \"price\":\"0.8\", \"size\":\"93\", \"side\":\"SELL\", \"hash\":\"a1d6d87ea9c9a4e8ff79a6d79a5154b71d01f800\", \"best_bid\":\"0.79\", \"best_ask\":\"0.8\"}], \"timestamp\":\"1785207995949\", \"event_type\":\"price_change\"}","received_at":"2026-07-28T03:06:35.921451Z","schema_version":"clob-market-ws.price_change.v1","sequence":null,"server_hash":null,"server_timestamp":"1785207995949","session_id":"3e519d9098404c15b234d96025eb1a2b","source":"clob_market_ws"},"received_at":"2026-07-28T03:06:35.921451Z","record_id":"d550dde8f23feb436b5e14363efce2f8d6825425af151f9929497c92fa4b9e5e","schema_fingerprint":"4aa3821a28b0b7c2400bc59aba4bcc0a76e971dadd19610d3ad38c768e124dc7","schema_version":"edge-lab-recorder.raw.v1","sequence":null,"source":"clob_market_ws"}
{"event_at":"2026-07-28T03:06:35.950000Z","event_fingerprint":"f19140c53268dd977c368c8d4c5c2e4c499d6cfb3b8ffd1c59d4a1b4997b645c","payload":{"connection_id":"a6b55582af5f430fb37ad02bf0922475","event_at":"2026-07-28T03:06:35.950000Z","event_type":"price_change","frame_hash":"e0e70bf3b1ac1c8153f66e67446656ec0457dbee78ff6644658b26bc751a1b43","frame_index":0,"kind":"data","monotonic_ns":309978955928875,"payload":{"event_type":"price_change","market":"0x779291bef19b6709f61e9764a954aafe9ffae488d50ae674aabdcb4f248006d5","price_changes":[{"asset_id":"14965588658799411272385430903075831224615961675357217884735713260981483529984","best_ask":"0.21","best_bid":"0.2","hash":"6326a40a1cec8b5dbb06733196de2af81a3cae38","price":"0.12","side":"BUY","size":"379.4"},{"asset_id":"8761897749749422724209054078244794145777693856614463256546737399611489089783","best_ask":"0.8","best_bid":"0.79","hash":"6354652788fdaf7fd963ab45d9c7688695705d1a","price":"0.88","side":"SELL","size":"379.4"}],"timestamp":"1785207995950"},"payload_hash":"ada3c0a4202f8f9ce6510b9ad70df95997096fec23d0017dcfdf481771c35afe","raw_frame":"{\"market\":\"0x779291bef19b6709f61e9764a954aafe9ffae488d50ae674aabdcb4f248006d5\", \"price_changes\":[{\"asset_id\":\"14965588658799411272385430903075831224615961675357217884735713260981483529984\", \"price\":\"0.12\", \"size\":\"379.4\", \"side\":\"BUY\", \"hash\":\"6326a40a1cec8b5dbb06733196de2af81a3cae38\", \"best_bid\":\"0.2\", \"best_ask\":\"0.21\"}, {\"asset_id\":\"8761897749749422724209054078244794145777693856614463256546737399611489089783\", \"price\":\"0.88\", \"size\":\"379.4\", \"side\":\"SELL\", \"hash\":\"6354652788fdaf7fd963ab45d9c7688695705d1a\", \"best_bid\":\"0.79\", \"best_ask\":\"0.8\"}], \"timestamp\":\"1785207995950\", \"event_type\":\"price_change\"}","received_at":"2026-07-28T03:06:35.924393Z","schema_version":"clob-market-ws.price_change.v1","sequence":null,"server_hash":null,"server_timestamp":"1785207995950","session_id":"3e519d9098404c15b234d96025eb1a2b","source":"clob_market_ws"},"received_at":"2026-07-28T03:06:35.924393Z","record_id":"fd3f8469a2bdef51e222a1f8cf8fe6234645e33e5323b2c846450a6ef669b597","schema_fingerprint":"4aa3821a28b0b7c2400bc59aba4bcc0a76e971dadd19610d3ad38c768e124dc7","schema_version":"edge-lab-recorder.raw.v1","sequence":null,"source":"clob_market_ws"}
{"event_at":"2026-07-28T03:06:35.951000Z","event_fingerprint":"8f5eac4afde89a0947c9a50a4e8415ce754ef3eef14491603fdc0a161e068848","payload":{"connection_id":"a6b55582af5f430fb37ad02bf0922475","event_at":"2026-07-28T03:06:35.951000Z","event_type":"price_change","frame_hash":"1eb9866e78d7dee142d651cd6ee6120d63392b91d4d612d5bdb3074c70a1446e","frame_index":0,"kind":"data","monotonic_ns":309978958422416,"payload":{"event_type":"price_change","market":"0x779291bef19b6709f61e9764a954aafe9ffae488d50ae674aabdcb4f248006d5","price_changes":[{"asset_id":"8761897749749422724209054078244794145777693856614463256546737399611489089783","best_ask":"0.8","best_bid":"0.79","hash":"f557175fa5c6e679ec6f18b1b9900a1edf7e01d9","price":"0.78","side":"BUY","size":"83"},{"asset_id":"14965588658799411272385430903075831224615961675357217884735713260981483529984","best_ask":"0.21","best_bid":"0.2","hash":"4e30feee2d3f84ee8262295fe3e443956a0d57c8","price":"0.22","side":"SELL","size":"83"}],"timestamp":"1785207995951"},"payload_hash":"7eb0926583707211d05b5dd493a8a7ac89f8200fa0848bf24d860752f6bd49ac","raw_frame":"{\"market\":\"0x779291bef19b6709f61e9764a954aafe9ffae488d50ae674aabdcb4f248006d5\", \"price_changes\":[{\"asset_id\":\"8761897749749422724209054078244794145777693856614463256546737399611489089783\", \"price\":\"0.78\", \"size\":\"83\", \"side\":\"BUY\", \"hash\":\"f557175fa5c6e679ec6f18b1b9900a1edf7e01d9\", \"best_bid\":\"0.79\", \"best_ask\":\"0.8\"}, {\"asset_id\":\"14965588658799411272385430903075831224615961675357217884735713260981483529984\", \"price\":\"0.22\", \"size\":\"83\", \"side\":\"SELL\", \"hash\":\"4e30feee2d3f84ee8262295fe3e443956a0d57c8\", \"best_bid\":\"0.2\", \"best_ask\":\"0.21\"}], \"timestamp\":\"1785207995951\", \"event_type\":\"price_change\"}","received_at":"2026-07-28T03:06:35.926886Z","schema_version":"clob-market-ws.price_change.v1","sequence":null,"server_hash":null,"server_timestamp":"1785207995951","session_id":"3e519d9098404c15b234d96025eb1a2b","source":"clob_market_ws"},"received_at":"2026-07-28T03:06:35.926886Z","record_id":"c3cf71e639924742e74ee1bae4d2de7009b4e46de730f127291febc84e24e5a5","schema_fingerprint":"4aa3821a28b0b7c2400bc59aba4bcc0a76e971dadd19610d3ad38c768e124dc7","schema_version":"edge-lab-recorder.raw.v1","sequence":null,"source":"clob_market_ws"}
{"event_at":"2026-07-28T03:06:35.952000Z","event_fingerprint":"b16db7731addb1649a097446cf30a65b6696345d445bdf8f27c0d8e6d0aeb499","payload":{"connection_id":"a6b55582af5f430fb37ad02bf0922475","event_at":"2026-07-28T03:06:35.952000Z","event_type":"price_change","frame_hash":"1a5580113b68f84a4827f3438c47d5f3bb5245060e02196d2da59d1beb2d1f6b","frame_index":0,"kind":"data","monotonic_ns":309978960989458,"payload":{"event_type":"price_change","market":"0x779291bef19b6709f61e9764a954aafe9ffae488d50ae674aabdcb4f248006d5","price_changes":[{"asset_id":"14965588658799411272385430903075831224615961675357217884735713260981483529984","best_ask":"0.21","best_bid":"0.2","hash":"ed9f4f43cef0bbac4bdacae19be5aa76c91fddfd","price":"0.19","side":"BUY","size":"61.6"},{"asset_id":"8761897749749422724209054078244794145777693856614463256546737399611489089783","best_ask":"0.8","best_bid":"0.79","hash":"b1c65f734dc2cc4bdf51aee5bfef356c07a1d00a","price":"0.81","side":"SELL","size":"61.6"}],"timestamp":"1785207995952"},"payload_hash":"d1ab41a2768d5747d4f439e013a13fbd73399825592d9de8cdfae0e912f2b8d7","raw_frame":"{\"market\":\"0x779291bef19b6709f61e9764a954aafe9ffae488d50ae674aabdcb4f248006d5\", \"price_changes\":[{\"asset_id\":\"14965588658799411272385430903075831224615961675357217884735713260981483529984\", \"price\":\"0.19\", \"size\":\"61.6\", \"side\":\"BUY\", \"hash\":\"ed9f4f43cef0bbac4bdacae19be5aa76c91fddfd\", \"best_bid\":\"0.2\", \"best_ask\":\"0.21\"}, {\"asset_id\":\"8761897749749422724209054078244794145777693856614463256546737399611489089783\", \"price\":\"0.81\", \"size\":\"61.6\", \"side\":\"SELL\", \"hash\":\"b1c65f734dc2cc4bdf51aee5bfef356c07a1d00a\", \"best_bid\":\"0.79\", \"best_ask\":\"0.8\"}], \"timestamp\":\"1785207995952\", \"event_type\":\"price_change\"}","received_at":"2026-07-28T03:06:35.929453Z","schema_version":"clob-market-ws.price_change.v1","sequence":null,"server_hash":null,"server_timestamp":"1785207995952","session_id":"3e519d9098404c15b234d96025eb1a2b","source":"clob_market_ws"},"received_at":"2026-07-28T03:06:35.929453Z","record_id":"db12f83bf2a332dcb282d6630554e6bb3d0b776d80a8cefcfe70c2c1c5734ae4","schema_fingerprint":"4aa3821a28b0b7c2400bc59aba4bcc0a76e971dadd19610d3ad38c768e124dc7","schema_version":"edge-lab-recorder.raw.v1","sequence":null,"source":"clob_market_ws"}
{"event_at":"2026-07-28T03:06:35.952000Z","event_fingerprint":"6c6e3c9623b803ddb6322ca5dd3f8fde23d7253e8ee8e2a0c83d3816f6a06ecf","payload":{"connection_id":"a6b55582af5f430fb37ad02bf0922475","event_at":"2026-07-28T03:06:35.952000Z","event_type":"price_change","frame_hash":"065a248cf6a886150800a7dcd55dcc44d6b5a601c4805c763cc6e0cf2a88c269","frame_index":0,"kind":"data","monotonic_ns":309978963877041,"payload":{"event_type":"price_change","market":"0x779291bef19b6709f61e9764a954aafe9ffae488d50ae674aabdcb4f248006d5","price_changes":[{"asset_id":"14965588658799411272385430903075831224615961675357217884735713260981483529984","best_ask":"0.21","best_bid":"0.2","hash":"5d8e188736a81fc58acbab7b3e462a4d67782d4e","price":"0.16","side":"BUY","size":"143.3"},{"asset_id":"8761897749749422724209054078244794145777693856614463256546737399611489089783","best_ask":"0.8","best_bid":"0.79","hash":"d68fcde76192455201425527137b80373982623d","price":"0.84","side":"SELL","size":"143.3"}],"timestamp":"1785207995952"},"payload_hash":"cd3a35a0b14e2306cacbe51aa88fc36ced6e293abfceeecd3551c2892090416d","raw_frame":"{\"market\":\"0x779291bef19b6709f61e9764a954aafe9ffae488d50ae674aabdcb4f248006d5\", \"price_changes\":[{\"asset_id\":\"14965588658799411272385430903075831224615961675357217884735713260981483529984\", \"price\":\"0.16\", \"size\":\"143.3\", \"side\":\"BUY\", \"hash\":\"5d8e188736a81fc58acbab7b3e462a4d67782d4e\", \"best_bid\":\"0.2\", \"best_ask\":\"0.21\"}, {\"asset_id\":\"8761897749749422724209054078244794145777693856614463256546737399611489089783\", \"price\":\"0.84\", \"size\":\"143.3\", \"side\":\"SELL\", \"hash\":\"d68fcde76192455201425527137b80373982623d\", \"best_bid\":\"0.79\", \"best_ask\":\"0.8\"}], \"timestamp\":\"1785207995952\", \"event_type\":\"price_change\"}","received_at":"2026-07-28T03:06:35.932341Z","schema_version":"clob-market-ws.price_change.v1","sequence":null,"server_hash":null,"server_timestamp":"1785207995952","session_id":"3e519d9098404c15b234d96025eb1a2b","source":"clob_market_ws"},"received_at":"2026-07-28T03:06:35.932341Z","record_id":"00217a3bc7b7df634c963a16370e454f267d7cd98a99067d50d85eec92f0f6a4","schema_fingerprint":"4aa3821a28b0b7c2400bc59aba4bcc0a76e971dadd19610d3ad38c768e124dc7","schema_version":"edge-lab-recorder.raw.v1","sequence":null,"source":"clob_market_ws"}
{"event_at":"2026-07-28T03:06:35.953000Z","event_fingerprint":"6814add352268a769f02be9460089ca8bd2d079538ef726e0a99b172f84bf80d","payload":{"connection_id":"a6b55582af5f430fb37ad02bf0922475","event_at":"2026-07-28T03:06:35.953000Z","event_type":"price_change","frame_hash":"6760053d41af5f275e8043bee11cfa604214114dfbaa3c63dbff982aad1044dd","frame_index":0,"kind":"data","monotonic_ns":309978966362416,"payload":{"event_type":"price_change","market":"0x779291bef19b6709f61e9764a954aafe9ffae488d50ae674aabdcb4f248006d5","price_changes":[{"asset_id":"8761897749749422724209054078244794145777693856614463256546737399611489089783","best_ask":"0.8","best_bid":"0.79","hash":"9b06d70e00c2e0341ac7543d82c604b56e99ed0a","price":"0.78","side":"BUY","size":"95.6"},{"asset_id":"14965588658799411272385430903075831224615961675357217884735713260981483529984","best_ask":"0.21","best_bid":"0.2","hash":"14139e204ea3d7ad11ec6916ed483b5f73206d66","price":"0.22","side":"SELL","size":"95.6"}],"timestamp":"1785207995953"},"payload_hash":"a0ae495f7bfe979d681f842210b8580f4c0333865633bf2142b803f332402822","raw_frame":"{\"market\":\"0x779291bef19b6709f61e9764a954aafe9ffae488d50ae674aabdcb4f248006d5\", \"price_changes\":[{\"asset_id\":\"8761897749749422724209054078244794145777693856614463256546737399611489089783\", \"price\":\"0.78\", \"size\":\"95.6\", \"side\":\"BUY\", \"hash\":\"9b06d70e00c2e0341ac7543d82c604b56e99ed0a\", \"best_bid\":\"0.79\", \"best_ask\":\"0.8\"}, {\"asset_id\":\"14965588658799411272385430903075831224615961675357217884735713260981483529984\", \"price\":\"0.22\", \"size\":\"95.6\", \"side\":\"SELL\", \"hash\":\"14139e204ea3d7ad11ec6916ed483b5f73206d66\", \"best_bid\":\"0.2\", \"best_ask\":\"0.21\"}], \"timestamp\":\"1785207995953\", \"event_type\":\"price_change\"}","received_at":"2026-07-28T03:06:35.934826Z","schema_version":"clob-market-ws.price_change.v1","sequence":null,"server_hash":null,"server_timestamp":"1785207995953","session_id":"3e519d9098404c15b234d96025eb1a2b","source":"clob_market_ws"},"received_at":"2026-07-28T03:06:35.934826Z","record_id":"bb9019a131d15c2d520604ebe6bc2838f31b326c0d8c4e1229aeec4ac6b39dc9","schema_fingerprint":"4aa3821a28b0b7c2400bc59aba4bcc0a76e971dadd19610d3ad38c768e124dc7","schema_version":"edge-lab-recorder.raw.v1","sequence":null,"source":"clob_market_ws"}
{"event_at":"2026-07-28T03:06:35.954000Z","event_fingerprint":"6daea6717f713a66a6ff9a9201a3da31b072137c131fe5bba1a620b726b75012","payload":{"connection_id":"a6b55582af5f430fb37ad02bf0922475","event_at":"2026-07-28T03:06:35.954000Z","event_type":"price_change","frame_hash":"56e4175dac0a851ba7cacacff559bc84647583a10be2fe5fbbd5f6407a1e8dd8","frame_index":0,"kind":"data","monotonic_ns":309978973215083,"payload":{"event_type":"price_change","market":"0x779291bef19b6709f61e9764a954aafe9ffae488d50ae674aabdcb4f248006d5","price_changes":[{"asset_id":"14965588658799411272385430903075831224615961675357217884735713260981483529984","best_ask":"0.21","best_bid":"0.2","hash":"638379bebb3db68b9e74c864dee16398e243ffc8","price":"0.15","side":"BUY","size":"89.17"},{"asset_id":"8761897749749422724209054078244794145777693856614463256546737399611489089783","best_ask":"0.8","best_bid":"0.79","hash":"38a8b808265ef0839f29b980d0576799363f7f22","price":"0.85","side":"SELL","size":"89.17"}],"timestamp":"1785207995954"},"payload_hash":"4a9873861a10cb1a6dff79ef70a5caedc76d9efc85939240ff7d99aa9a2bbc61","raw_frame":"{\"market\":\"0x779291bef19b6709f61e9764a954aafe9ffae488d50ae674aabdcb4f248006d5\", \"price_changes\":[{\"asset_id\":\"14965588658799411272385430903075831224615961675357217884735713260981483529984\", \"price\":\"0.15\", \"size\":\"89.17\", \"side\":\"BUY\", \"hash\":\"638379bebb3db68b9e74c864dee16398e243ffc8\", \"best_bid\":\"0.2\", \"best_ask\":\"0.21\"}, {\"asset_id\":\"8761897749749422724209054078244794145777693856614463256546737399611489089783\", \"price\":\"0.85\", \"size\":\"89.17\", \"side\":\"SELL\", \"hash\":\"38a8b808265ef0839f29b980d0576799363f7f22\", \"best_bid\":\"0.79\", \"best_ask\":\"0.8\"}], \"timestamp\":\"1785207995954\", \"event_type\":\"price_change\"}","received_at":"2026-07-28T03:06:35.941677Z","schema_version":"clob-market-ws.price_change.v1","sequence":null,"server_hash":null,"server_timestamp":"1785207995954","session_id":"3e519d9098404c15b234d96025eb1a2b","source":"clob_market_ws"},"received_at":"2026-07-28T03:06:35.941677Z","record_id":"ef280e54068d6d31b5e67dee25dd75894abc4a8781bbec36732ae6c26fccda2a","schema_fingerprint":"4aa3821a28b0b7c2400bc59aba4bcc0a76e971dadd19610d3ad38c768e124dc7","schema_version":"edge-lab-recorder.raw.v1","sequence":null,"source":"clob_market_ws"}
{"event_at":"2026-07-28T03:06:35.955000Z","event_fingerprint":"97afc4f1e1af5db0e7d7b71a868b5afeae904dccf95a42defd91586fadfd94fb","payload":{"connection_id":"a6b55582af5f430fb37ad02bf0922475","event_at":"2026-07-28T03:06:35.955000Z","event_type":"price_change","frame_hash":"241386569c2818974935550511b404d07bb558ee923708d9830ede2b05492c53","frame_index":0,"kind":"data","monotonic_ns":309978978605916,"payload":{"event_type":"price_change","market":"0x779291bef19b6709f61e9764a954aafe9ffae488d50ae674aabdcb4f248006d5","price_changes":[{"asset_id":"14965588658799411272385430903075831224615961675357217884735713260981483529984","best_ask":"0.21","best_bid":"0.2","hash":"5f14021ad4c83167b3d666c05688b95df8b02127","price":"0.17","side":"BUY","size":"74.2"},{"asset_id":"8761897749749422724209054078244794145777693856614463256546737399611489089783","best_ask":"0.8","best_bid":"0.79","hash":"b7348d95cccb8d6e0d2724e57dcde029f7fbd41e","price":"0.83","side":"SELL","size":"74.2"}],"timestamp":"1785207995955"},"payload_hash":"410d51bd9c67ddd38d1c251fd38e398dd7fa6162e4020e34bcb46431979eef91","raw_frame":"{\"market\":\"0x779291bef19b6709f61e9764a954aafe9ffae488d50ae674aabdcb4f248006d5\", \"price_changes\":[{\"asset_id\":\"14965588658799411272385430903075831224615961675357217884735713260981483529984\", \"price\":\"0.17\", \"size\":\"74.2\", \"side\":\"BUY\", \"hash\":\"5f14021ad4c83167b3d666c05688b95df8b02127\", \"best_bid\":\"0.2\", \"best_ask\":\"0.21\"}, {\"asset_id\":\"8761897749749422724209054078244794145777693856614463256546737399611489089783\", \"price\":\"0.83\", \"size\":\"74.2\", \"side\":\"SELL\", \"hash\":\"b7348d95cccb8d6e0d2724e57dcde029f7fbd41e\", \"best_bid\":\"0.79\", \"best_ask\":\"0.8\"}], \"timestamp\":\"1785207995955\", \"event_type\":\"price_change\"}","received_at":"2026-07-28T03:06:35.947067Z","schema_version":"clob-market-ws.price_change.v1","sequence":null,"server_hash":null,"server_timestamp":"1785207995955","session_id":"3e519d9098404c15b234d96025eb1a2b","source":"clob_market_ws"},"received_at":"2026-07-28T03:06:35.947067Z","record_id":"777ac7b9ff8ed74aa70a90d4379909d4f6d5e69407cc5ef80df434ad48ffa93c","schema_fingerprint":"4aa3821a28b0b7c2400bc59aba4bcc0a76e971dadd19610d3ad38c768e124dc7","schema_version":"edge-lab-recorder.raw.v1","sequence":null,"source":"clob_market_ws"}
{"event_at":"2026-07-28T03:06:35.956000Z","event_fingerprint":"ea5e60aaf5fb6e62ec2093223e7bbdfd56cbfde1820010214753202b1e3116c9","payload":{"connection_id":"a6b55582af5f430fb37ad02bf0922475","event_at":"2026-07-28T03:06:35.956000Z","event_type":"price_change","frame_hash":"9e2f2d17cff76a727d959950d8ab06f46e21371a81339a1bb0998efbde1f77b7","frame_index":0,"kind":"data","monotonic_ns":309978981349666,"payload":{"event_type":"price_change","market":"0x779291bef19b6709f61e9764a954aafe9ffae488d50ae674aabdcb4f248006d5","price_changes":[{"asset_id":"14965588658799411272385430903075831224615961675357217884735713260981483529984","best_ask":"0.21","best_bid":"0.2","hash":"a87c0d6a83685407ff92b52d8009b27a43d8410f","price":"0.18","side":"BUY","size":"78.6"},{"asset_id":"8761897749749422724209054078244794145777693856614463256546737399611489089783","best_ask":"0.8","best_bid":"0.79","hash":"f768e261578c7b5807e72b4abdf59776e6218f2e","price":"0.82","side":"SELL","size":"78.6"}],"timestamp":"1785207995956"},"payload_hash":"54858c6584ebdc572f0eb8e3ad04a0175727a1739b205aacc64e42ce1c18937e","raw_frame":"{\"market\":\"0x779291bef19b6709f61e9764a954aafe9ffae488d50ae674aabdcb4f248006d5\", \"price_changes\":[{\"asset_id\":\"14965588658799411272385430903075831224615961675357217884735713260981483529984\", \"price\":\"0.18\", \"size\":\"78.6\", \"side\":\"BUY\", \"hash\":\"a87c0d6a83685407ff92b52d8009b27a43d8410f\", \"best_bid\":\"0.2\", \"best_ask\":\"0.21\"}, {\"asset_id\":\"8761897749749422724209054078244794145777693856614463256546737399611489089783\", \"price\":\"0.82\", \"size\":\"78.6\", \"side\":\"SELL\", \"hash\":\"f768e261578c7b5807e72b4abdf59776e6218f2e\", \"best_bid\":\"0.79\", \"best_ask\":\"0.8\"}], \"timestamp\":\"1785207995956\", \"event_type\":\"price_change\"}","received_at":"2026-07-28T03:06:35.949812Z","schema_version":"clob-market-ws.price_change.v1","sequence":null,"server_hash":null,"server_timestamp":"1785207995956","session_id":"3e519d9098404c15b234d96025eb1a2b","source":"clob_market_ws"},"received_at":"2026-07-28T03:06:35.949812Z","record_id":"646464042fafc978a40615d177c25f9cb418013cd483e1550dce4f6141be0735","schema_fingerprint":"4aa3821a28b0b7c2400bc59aba4bcc0a76e971dadd19610d3ad38c768e124dc7","schema_version":"edge-lab-recorder.raw.v1","sequence":null,"source":"clob_market_ws"}
{"event_at":"2026-07-28T03:06:35.967000Z","event_fingerprint":"05e957453db12b76aaaa451854dfbcdb86bb98d89975f81b20dede67e7b78c43","payload":{"connection_id":"a6b55582af5f430fb37ad02bf0922475","event_at":"2026-07-28T03:06:35.967000Z","event_type":"price_change","frame_hash":"08fe682f5b9c20cf73fa322f4bda3b902efe2d96ee4ffd20a45afd1341f14917","frame_index":0,"kind":"data","monotonic_ns":309978988163625,"payload":{"event_type":"price_change","market":"0x779291bef19b6709f61e9764a954aafe9ffae488d50ae674aabdcb4f248006d5","price_changes":[{"asset_id":"14965588658799411272385430903075831224615961675357217884735713260981483529984","best_ask":"0.21","best_bid":"0.2","hash":"25e7a1b23ea0ac12c0e7f69a58eadd6e2287d5ed","price":"0.19","side":"BUY","size":"49"},{"asset_id":"8761897749749422724209054078244794145777693856614463256546737399611489089783","best_ask":"0.8","best_bid":"0.79","hash":"1cc5773b25c5c8e4516c20ba2370b594525e185d","price":"0.81","side":"SELL","size":"49"}],"timestamp":"1785207995967"},"payload_hash":"aefa71d32daeeca8177dc66b4eae75fbd472a8cdb20cff772e15babcd8a46e1c","raw_frame":"{\"market\":\"0x779291bef19b6709f61e9764a954aafe9ffae488d50ae674aabdcb4f248006d5\", \"price_changes\":[{\"asset_id\":\"14965588658799411272385430903075831224615961675357217884735713260981483529984\", \"price\":\"0.19\", \"size\":\"49\", \"side\":\"BUY\", \"hash\":\"25e7a1b23ea0ac12c0e7f69a58eadd6e2287d5ed\", \"best_bid\":\"0.2\", \"best_ask\":\"0.21\"}, {\"asset_id\":\"8761897749749422724209054078244794145777693856614463256546737399611489089783\", \"price\":\"0.81\", \"size\":\"49\", \"side\":\"SELL\", \"hash\":\"1cc5773b25c5c8e4516c20ba2370b594525e185d\", \"best_bid\":\"0.79\", \"best_ask\":\"0.8\"}], \"timestamp\":\"1785207995967\", \"event_type\":\"price_change\"}","received_at":"2026-07-28T03:06:35.956626Z","schema_version":"clob-market-ws.price_change.v1","sequence":null,"server_hash":null,"server_timestamp":"1785207995967","session_id":"3e519d9098404c15b234d96025eb1a2b","source":"clob_market_ws"},"received_at":"2026-07-28T03:06:35.956626Z","record_id":"904ac6b9d3cf86dfce40b56cb59f5896cfed126b8f027bc50bf36c5816b1c5e7","schema_fingerprint":"4aa3821a28b0b7c2400bc59aba4bcc0a76e971dadd19610d3ad38c768e124dc7","schema_version":"edge-lab-recorder.raw.v1","sequence":null,"source":"clob_market_ws"}
{"event_at":"2026-07-28T03:06:35.967000Z","event_fingerprint":"c2cdc05b33a5a770218beba27e65a4391f72fe3fbe88eaa9f3376596f020561a","payload":{"connection_id":"a6b55582af5f430fb37ad02bf0922475","event_at":"2026-07-28T03:06:35.967000Z","event_type":"price_change","frame_hash":"65876e72d4b524f567863d3cd73788a06e9e96f8de0bf6ead8537178e172e28d","frame_index":0,"kind":"data","monotonic_ns":309978992550875,"payload":{"event_type":"price_change","market":"0x779291bef19b6709f61e9764a954aafe9ffae488d50ae674aabdcb4f248006d5","price_changes":[{"asset_id":"14965588658799411272385430903075831224615961675357217884735713260981483529984","best_ask":"0.21","best_bid":"0.2","hash":"8f0394e96e22b500fbc0b49180b0707a6aeb6218","price":"0.14","side":"BUY","size":"203.9"},{"asset_id":"8761897749749422724209054078244794145777693856614463256546737399611489089783","best_ask":"0.8","best_bid":"0.79","hash":"b088c417a7e06dd0cffa3a6b6d5c991bc5b1b23c","price":"0.86","side":"SELL","size":"203.9"}],"timestamp":"1785207995967"},"payload_hash":"5284f643ba96918e91af6d4a71ba3d932da63f3f56cd463aba2e7a35666c802f","raw_frame":"{\"market\":\"0x779291bef19b6709f61e9764a954aafe9ffae488d50ae674aabdcb4f248006d5\", \"price_changes\":[{\"asset_id\":\"14965588658799411272385430903075831224615961675357217884735713260981483529984\", \"price\":\"0.14\", \"size\":\"203.9\", \"side\":\"BUY\", \"hash\":\"8f0394e96e22b500fbc0b49180b0707a6aeb6218\", \"best_bid\":\"0.2\", \"best_ask\":\"0.21\"}, {\"asset_id\":\"8761897749749422724209054078244794145777693856614463256546737399611489089783\", \"price\":\"0.86\", \"size\":\"203.9\", \"side\":\"SELL\", \"hash\":\"b088c417a7e06dd0cffa3a6b6d5c991bc5b1b23c\", \"best_bid\":\"0.79\", \"best_ask\":\"0.8\"}], \"timestamp\":\"1785207995967\", \"event_type\":\"price_change\"}","received_at":"2026-07-28T03:06:35.961014Z","schema_version":"clob-market-ws.price_change.v1","sequence":null,"server_hash":null,"server_timestamp":"1785207995967","session_id":"3e519d9098404c15b234d96025eb1a2b","source":"clob_market_ws"},"received_at":"2026-07-28T03:06:35.961014Z","record_id":"66e90f846963acf9ac58e3ec01b8437d998df731bc3796d390609237cc652d33","schema_fingerprint":"4aa3821a28b0b7c2400bc59aba4bcc0a76e971dadd19610d3ad38c768e124dc7","schema_version":"edge-lab-recorder.raw.v1","sequence":null,"source":"clob_market_ws"}
{"event_at":"2026-07-28T03:06:35.967000Z","event_fingerprint":"f66de58e1239797765f7a607db1a56b6e16c886b3bba018424849fa079382191","payload":{"connection_id":"a6b55582af5f430fb37ad02bf0922475","event_at":"2026-07-28T03:06:35.967000Z","event_type":"price_change","frame_hash":"7d70bcda7dd9d07b51a33add3c038146a90932de93a620c4eb4a677c5ea4d195","frame_index":0,"kind":"data","monotonic_ns":309978995119750,"payload":{"event_type":"price_change","market":"0x779291bef19b6709f61e9764a954aafe9ffae488d50ae674aabdcb4f248006d5","price_changes":[{"asset_id":"8761897749749422724209054078244794145777693856614463256546737399611489089783","best_ask":"0.8","best_bid":"0.79","hash":"e67c5a31f0414ace56d3bbce603b8f27c4f652de","price":"0.77","side":"BUY","size":"137.98"},{"asset_id":"14965588658799411272385430903075831224615961675357217884735713260981483529984","best_ask":"0.21","best_bid":"0.2","hash":"004dd07ddce5311c8eb67c331b71092e19f59463","price":"0.23","side":"SELL","size":"137.98"}],"timestamp":"1785207995967"},"payload_hash":"6d60ca055dd8dae4cd24d9c5f037bfa3437122d4e21f95585d5a93a03af0a284","raw_frame":"{\"market\":\"0x779291bef19b6709f61e9764a954aafe9ffae488d50ae674aabdcb4f248006d5\", \"price_changes\":[{\"asset_id\":\"8761897749749422724209054078244794145777693856614463256546737399611489089783\", \"price\":\"0.77\", \"size\":\"137.98\", \"side\":\"BUY\", \"hash\":\"e67c5a31f0414ace56d3bbce603b8f27c4f652de\", \"best_bid\":\"0.79\", \"best_ask\":\"0.8\"}, {\"asset_id\":\"14965588658799411272385430903075831224615961675357217884735713260981483529984\", \"price\":\"0.23\", \"size\":\"137.98\", \"side\":\"SELL\", \"hash\":\"004dd07ddce5311c8eb67c331b71092e19f59463\", \"best_bid\":\"0.2\", \"best_ask\":\"0.21\"}], \"timestamp\":\"1785207995967\", \"event_type\":\"price_change\"}","received_at":"2026-07-28T03:06:35.963583Z","schema_version":"clob-market-ws.price_change.v1","sequence":null,"server_hash":null,"server_timestamp":"1785207995967","session_id":"3e519d9098404c15b234d96025eb1a2b","source":"clob_market_ws"},"received_at":"2026-07-28T03:06:35.963583Z","record_id":"b25172ccc5f82fd0b8e370cf8e83248b44bf8f4c6f8f171db5b3b4fa85ce767e","schema_fingerprint":"4aa3821a28b0b7c2400bc59aba4bcc0a76e971dadd19610d3ad38c768e124dc7","schema_version":"edge-lab-recorder.raw.v1","sequence":null,"source":"clob_market_ws"}
{"event_at":"2026-07-28T03:06:35.974000Z","event_fingerprint":"eef71ec7847e99d62bd3486ff5dd34f69f5efe09faf55241cccfe1c92767752f","payload":{"connection_id":"a6b55582af5f430fb37ad02bf0922475","event_at":"2026-07-28T03:06:35.974000Z","event_type":"price_change","frame_hash":"85ebbc19d3ea2a8252feb0ecdaa82a23acabdb4ebf1b0f8661a6340f69b71e26","frame_index":0,"kind":"data","monotonic_ns":309978997623208,"payload":{"event_type":"price_change","market":"0x779291bef19b6709f61e9764a954aafe9ffae488d50ae674aabdcb4f248006d5","price_changes":[{"asset_id":"8761897749749422724209054078244794145777693856614463256546737399611489089783","best_ask":"0.8","best_bid":"0.79","hash":"ffbbb07e820a43783a42ec13ad45a0fcdf606332","price":"0.75","side":"BUY","size":"142.19"},{"asset_id":"14965588658799411272385430903075831224615961675357217884735713260981483529984","best_ask":"0.21","best_bid":"0.2","hash":"8ed618cecc6ac532596460f25f23c331da3454f8","price":"0.25","side":"SELL","size":"142.19"}],"timestamp":"1785207995974"},"payload_hash":"b0cd5306da8cefa22376850d512914b92c86748a773101fb1e070de0597ddb20","raw_frame":"{\"market\":\"0x779291bef19b6709f61e9764a954aafe9ffae488d50ae674aabdcb4f248006d5\", \"price_changes\":[{\"asset_id\":\"8761897749749422724209054078244794145777693856614463256546737399611489089783\", \"price\":\"0.75\", \"size\":\"142.19\", \"side\":\"BUY\", \"hash\":\"ffbbb07e820a43783a42ec13ad45a0fcdf606332\", \"best_bid\":\"0.79\", \"best_ask\":\"0.8\"}, {\"asset_id\":\"14965588658799411272385430903075831224615961675357217884735713260981483529984\", \"price\":\"0.25\", \"size\":\"142.19\", \"side\":\"SELL\", \"hash\":\"8ed618cecc6ac532596460f25f23c331da3454f8\", \"best_bid\":\"0.2\", \"best_ask\":\"0.21\"}], \"timestamp\":\"1785207995974\", \"event_type\":\"price_change\"}","received_at":"2026-07-28T03:06:35.966087Z","schema_version":"clob-market-ws.price_change.v1","sequence":null,"server_hash":null,"server_timestamp":"1785207995974","session_id":"3e519d9098404c15b234d96025eb1a2b","source":"clob_market_ws"},"received_at":"2026-07-28T03:06:35.966087Z","record_id":"096af1ec96f12a61486c3ed78ca1fdf26c80e310786e91f20de96e936af03417","schema_fingerprint":"4aa3821a28b0b7c2400bc59aba4bcc0a76e971dadd19610d3ad38c768e124dc7","schema_version":"edge-lab-recorder.raw.v1","sequence":null,"source":"clob_market_ws"}
{"event_at":"2026-07-28T03:06:35.974000Z","event_fingerprint":"2b0ad7963447d86f51f11534c3214bbe9408c18ed74a9998d78c255b368aadd3","payload":{"connection_id":"a6b55582af5f430fb37ad02bf0922475","event_at":"2026-07-28T03:06:35.974000Z","event_type":"price_change","frame_hash":"6f6e00ba9bd09927807c5847fcf0c67c5d606545e3c725b96aec9fd5f0b9d903","frame_index":0,"kind":"data","monotonic_ns":309979000640083,"payload":{"event_type":"price_change","market":"0x779291bef19b6709f61e9764a954aafe9ffae488d50ae674aabdcb4f248006d5","price_changes":[{"asset_id":"8761897749749422724209054078244794145777693856614463256546737399611489089783","best_ask":"0.8","best_bid":"0.79","hash":"7b4959aeb08bf2c4a3f8b03d3a651cdfb54a57b5","price":"0.78","side":"BUY","size":"119.6"},{"asset_id":"14965588658799411272385430903075831224615961675357217884735713260981483529984","best_ask":"0.21","best_bid":"0.2","hash":"324fdd5c5418dcb09b04490c5bd1dada3101840a","price":"0.22","side":"SELL","size":"119.6"}],"timestamp":"1785207995974"},"payload_hash":"d61b55ccd4e33193cd6019dc9eacae8c067b72657a5df8111a1d6b2c5da05a66","raw_frame":"{\"market\":\"0x779291bef19b6709f61e9764a954aafe9ffae488d50ae674aabdcb4f248006d5\", \"price_changes\":[{\"asset_id\":\"8761897749749422724209054078244794145777693856614463256546737399611489089783\", \"price\":\"0.78\", \"size\":\"119.6\", \"side\":\"BUY\", \"hash\":\"7b4959aeb08bf2c4a3f8b03d3a651cdfb54a57b5\", \"best_bid\":\"0.79\", \"best_ask\":\"0.8\"}, {\"asset_id\":\"14965588658799411272385430903075831224615961675357217884735713260981483529984\", \"price\":\"0.22\", \"size\":\"119.6\", \"side\":\"SELL\", \"hash\":\"324fdd5c5418dcb09b04490c5bd1dada3101840a\", \"best_bid\":\"0.2\", \"best_ask\":\"0.21\"}], \"timestamp\":\"1785207995974\", \"event_type\":\"price_change\"}","received_at":"2026-07-28T03:06:35.969102Z","schema_version":"clob-market-ws.price_change.v1","sequence":null,"server_hash":null,"server_timestamp":"1785207995974","session_id":"3e519d9098404c15b234d96025eb1a2b","source":"clob_market_ws"},"received_at":"2026-07-28T03:06:35.969102Z","record_id":"1afa8a6ee72bf875b36744fb8582c727ad7d6d0e9b778ad0c22f5d83fbf583af","schema_fingerprint":"4aa3821a28b0b7c2400bc59aba4bcc0a76e971dadd19610d3ad38c768e124dc7","schema_version":"edge-lab-recorder.raw.v1","sequence":null,"source":"clob_market_ws"}
{"event_at":"2026-07-28T03:06:35.975000Z","event_fingerprint":"cdff9681b6155f9aa37f4e3290040cada7acf7c37a6c2dd707f1be42957f37cb","payload":{"connection_id":"a6b55582af5f430fb37ad02bf0922475","event_at":"2026-07-28T03:06:35.975000Z","event_type":"price_change","frame_hash":"54904b73a3c8a2f3681375a0e1ca61554395b5438bc1b47412cb2bcfd759cf0d","frame_index":0,"kind":"data","monotonic_ns":309979008230416,"payload":{"event_type":"price_change","market":"0x779291bef19b6709f61e9764a954aafe9ffae488d50ae674aabdcb4f248006d5","price_changes":[{"asset_id":"8761897749749422724209054078244794145777693856614463256546737399611489089783","best_ask":"0.8","best_bid":"0.79","hash":"e8f88725ad42aec04e8161103c420c94085caf44","price":"0.78","side":"BUY","size":"132.2"},{"asset_id":"14965588658799411272385430903075831224615961675357217884735713260981483529984","best_ask":"0.21","best_bid":"0.2","hash":"77b59d4cca46bcb943fe40bbc5a3dd5a93084d73","price":"0.22","side":"SELL","size":"132.2"}],"timestamp":"1785207995975"},"payload_hash":"8e2135519deae5dee7a5cd898bb7ef46f7f5da84a14c587af47e78d8601f601a","raw_frame":"{\"market\":\"0x779291bef19b6709f61e9764a954aafe9ffae488d50ae674aabdcb4f248006d5\", \"price_changes\":[{\"asset_id\":\"8761897749749422724209054078244794145777693856614463256546737399611489089783\", \"price\":\"0.78\", \"size\":\"132.2\", \"side\":\"BUY\", \"hash\":\"e8f88725ad42aec04e8161103c420c94085caf44\", \"best_bid\":\"0.79\", \"best_ask\":\"0.8\"}, {\"asset_id\":\"14965588658799411272385430903075831224615961675357217884735713260981483529984\", \"price\":\"0.22\", \"size\":\"132.2\", \"side\":\"SELL\", \"hash\":\"77b59d4cca46bcb943fe40bbc5a3dd5a93084d73\", \"best_bid\":\"0.2\", \"best_ask\":\"0.21\"}], \"timestamp\":\"1785207995975\", \"event_type\":\"price_change\"}","received_at":"2026-07-28T03:06:35.976692Z","schema_version":"clob-market-ws.price_change.v1","sequence":null,"server_hash":null,"server_timestamp":"1785207995975","session_id":"3e519d9098404c15b234d96025eb1a2b","source":"clob_market_ws"},"received_at":"2026-07-28T03:06:35.976692Z","record_id":"3d9751f605fb921844bef16401ba04aabf6e32827d7495670464034df63f760a","schema_fingerprint":"4aa3821a28b0b7c2400bc59aba4bcc0a76e971dadd19610d3ad38c768e124dc7","schema_version":"edge-lab-recorder.raw.v1","sequence":null,"source":"clob_market_ws"}
{"event_at":"2026-07-28T03:06:35.976000Z","event_fingerprint":"b8318a396a5eea3e63ac1cf8b0f5b55fce5e10a75a6e9a64baec16cd5df1295e","payload":{"connection_id":"a6b55582af5f430fb37ad02bf0922475","event_at":"2026-07-28T03:06:35.976000Z","event_type":"price_change","frame_hash":"68ee6fd7ce7202c8d3ef3279f36df9598b90d7ab0f8fcda77eb593421b903414","frame_index":0,"kind":"data","monotonic_ns":309979012765750,"payload":{"event_type":"price_change","market":"0x779291bef19b6709f61e9764a954aafe9ffae488d50ae674aabdcb4f248006d5","price_changes":[{"asset_id":"8761897749749422724209054078244794145777693856614463256546737399611489089783","best_ask":"0.8","best_bid":"0.79","hash":"dd96cb63bbaca2bc14959a0c0153090b77726a2b","price":"0.79","side":"BUY","size":"42.6"},{"asset_id":"14965588658799411272385430903075831224615961675357217884735713260981483529984","best_ask":"0.21","best_bid":"0.2","hash":"94577cba52c68e074c1476c21a4e15b5cf939104","price":"0.21","side":"SELL","size":"42.6"}],"timestamp":"1785207995976"},"payload_hash":"52a010e16b2cd9690ba662708e45135a3dd30e557122e7eecda06af874f3689f","raw_frame":"{\"market\":\"0x779291bef19b6709f61e9764a954aafe9ffae488d50ae674aabdcb4f248006d5\", \"price_changes\":[{\"asset_id\":\"8761897749749422724209054078244794145777693856614463256546737399611489089783\", \"price\":\"0.79\", \"size\":\"42.6\", \"side\":\"BUY\", \"hash\":\"dd96cb63bbaca2bc14959a0c0153090b77726a2b\", \"best_bid\":\"0.79\", \"best_ask\":\"0.8\"}, {\"asset_id\":\"14965588658799411272385430903075831224615961675357217884735713260981483529984\", \"price\":\"0.21\", \"size\":\"42.6\", \"side\":\"SELL\", \"hash\":\"94577cba52c68e074c1476c21a4e15b5cf939104\", \"best_bid\":\"0.2\", \"best_ask\":\"0.21\"}], \"timestamp\":\"1785207995976\", \"event_type\":\"price_change\"}","received_at":"2026-07-28T03:06:35.981226Z","schema_version":"clob-market-ws.price_change.v1","sequence":null,"server_hash":null,"server_timestamp":"1785207995976","session_id":"3e519d9098404c15b234d96025eb1a2b","source":"clob_market_ws"},"received_at":"2026-07-28T03:06:35.981226Z","record_id":"c70def164294f7d8e17cb800335fe016cbcbf3ad83dddc11e2727651f8fe4b9e","schema_fingerprint":"4aa3821a28b0b7c2400bc59aba4bcc0a76e971dadd19610d3ad38c768e124dc7","schema_version":"edge-lab-recorder.raw.v1","sequence":null,"source":"clob_market_ws"}
{"event_at":"2026-07-28T03:06:35.977000Z","event_fingerprint":"5c289748d55d457cbe312b711212c45851ce618a2c2de6d1e1a5231793e990ed","payload":{"connection_id":"a6b55582af5f430fb37ad02bf0922475","event_at":"2026-07-28T03:06:35.977000Z","event_type":"price_change","frame_hash":"39238ae6d6dcc482e7995ddb1452892bd5f210cec2c63f6f0db0ce674524596f","frame_index":0,"kind":"data","monotonic_ns":309979020167000,"payload":{"event_type":"price_change","market":"0x779291bef19b6709f61e9764a954aafe9ffae488d50ae674aabdcb4f248006d5","price_changes":[{"asset_id":"8761897749749422724209054078244794145777693856614463256546737399611489089783","best_ask":"0.8","best_bid":"0.79","hash":"98e46d45f21927a940cf7142381a02d1a6ea91a9","price":"0.71","side":"BUY","size":"186"},{"asset_id":"14965588658799411272385430903075831224615961675357217884735713260981483529984","best_ask":"0.21","best_bid":"0.2","hash":"f2e5f9aab5d287651f191e1a9bc1382aacac5cd0","price":"0.29","side":"SELL","size":"186"}],"timestamp":"1785207995977"},"payload_hash":"0ebc340e2eaf48b77fadfecc209b6c7af3e837cb499bc81b898e12d20f406072","raw_frame":"{\"market\":\"0x779291bef19b6709f61e9764a954aafe9ffae488d50ae674aabdcb4f248006d5\", \"price_changes\":[{\"asset_id\":\"8761897749749422724209054078244794145777693856614463256546737399611489089783\", \"price\":\"0.71\", \"size\":\"186\", \"side\":\"BUY\", \"hash\":\"98e46d45f21927a940cf7142381a02d1a6ea91a9\", \"best_bid\":\"0.79\", \"best_ask\":\"0.8\"}, {\"asset_id\":\"14965588658799411272385430903075831224615961675357217884735713260981483529984\", \"price\":\"0.29\", \"size\":\"186\", \"side\":\"SELL\", \"hash\":\"f2e5f9aab5d287651f191e1a9bc1382aacac5cd0\", \"best_bid\":\"0.2\", \"best_ask\":\"0.21\"}], \"timestamp\":\"1785207995977\", \"event_type\":\"price_change\"}","received_at":"2026-07-28T03:06:35.988629Z","schema_version":"clob-market-ws.price_change.v1","sequence":null,"server_hash":null,"server_timestamp":"1785207995977","session_id":"3e519d9098404c15b234d96025eb1a2b","source":"clob_market_ws"},"received_at":"2026-07-28T03:06:35.988629Z","record_id":"cedb48d1a8f0347a2ef7bd8c4044171e6ec2d237e33f291e452497a3c2b545dc","schema_fingerprint":"4aa3821a28b0b7c2400bc59aba4bcc0a76e971dadd19610d3ad38c768e124dc7","schema_version":"edge-lab-recorder.raw.v1","sequence":null,"source":"clob_market_ws"}
{"event_at":"2026-07-28T03:06:35.978000Z","event_fingerprint":"11d9513bb9fb877c9e5086fd7c66b5812c27257078017bb22fe50167c13fc578","payload":{"connection_id":"a6b55582af5f430fb37ad02bf0922475","event_at":"2026-07-28T03:06:35.978000Z","event_type":"price_change","frame_hash":"221ccee831335f1a90b459de612fd5ba7a48192fa379af93979d96dd5173bb10","frame_index":0,"kind":"data","monotonic_ns":309979024617791,"payload":{"event_type":"price_change","market":"0x779291bef19b6709f61e9764a954aafe9ffae488d50ae674aabdcb4f248006d5","price_changes":[{"asset_id":"14965588658799411272385430903075831224615961675357217884735713260981483529984","best_ask":"0.21","best_bid":"0.2","hash":"bb3901d973b1f16a2ef104139bc2cbf2f9e7405c","price":"0.16","side":"BUY","size":"152.3"},{"asset_id":"8761897749749422724209054078244794145777693856614463256546737399611489089783","best_ask":"0.8","best_bid":"0.79","hash":"5636cf59f5f6e600a0a5ae9b3ef73e6a397794f0","price":"0.84","side":"SELL","size":"152.3"}],"timestamp":"1785207995978"},"payload_hash":"c922bfac52f03fb36f73555b6f4f5b3adf4589f8d4b8c41354998221b2faceb1","raw_frame":"{\"market\":\"0x779291bef19b6709f61e9764a954aafe9ffae488d50ae674aabdcb4f248006d5\", \"price_changes\":[{\"asset_id\":\"14965588658799411272385430903075831224615961675357217884735713260981483529984\", \"price\":\"0.16\", \"size\":\"152.3\", \"side\":\"BUY\", \"hash\":\"bb3901d973b1f16a2ef104139bc2cbf2f9e7405c\", \"best_bid\":\"0.2\", \"best_ask\":\"0.21\"}, {\"asset_id\":\"8761897749749422724209054078244794145777693856614463256546737399611489089783\", \"price\":\"0.84\", \"size\":\"152.3\", \"side\":\"SELL\", \"hash\":\"5636cf59f5f6e600a0a5ae9b3ef73e6a397794f0\", \"best_bid\":\"0.79\", \"best_ask\":\"0.8\"}], \"timestamp\":\"1785207995978\", \"event_type\":\"price_change\"}","received_at":"2026-07-28T03:06:35.993080Z","schema_version":"clob-market-ws.price_change.v1","sequence":null,"server_hash":null,"server_timestamp":"1785207995978","session_id":"3e519d9098404c15b234d96025eb1a2b","source":"clob_market_ws"},"received_at":"2026-07-28T03:06:35.993080Z","record_id":"b8f4831346eeb37a49986547c146c9913c65e2ab4a3466b9ca1d1562ca84b6aa","schema_fingerprint":"4aa3821a28b0b7c2400bc59aba4bcc0a76e971dadd19610d3ad38c768e124dc7","schema_version":"edge-lab-recorder.raw.v1","sequence":null,"source":"clob_market_ws"}
{"event_at":"2026-07-28T03:06:35.978000Z","event_fingerprint":"42c661dd236e040d6ce9991efcd8229e31ad047df7c07b4a242086d3196bbcff","payload":{"connection_id":"a6b55582af5f430fb37ad02bf0922475","event_at":"2026-07-28T03:06:35.978000Z","event_type":"price_change","frame_hash":"070048b38c3fde2561c34bbc77142ac82db4319a2aa76a1ee4181ca9c466e03c","frame_index":0,"kind":"data","monotonic_ns":309979027902666,"payload":{"event_type":"price_change","market":"0x779291bef19b6709f61e9764a954aafe9ffae488d50ae674aabdcb4f248006d5","price_changes":[{"asset_id":"8761897749749422724209054078244794145777693856614463256546737399611489089783","best_ask":"0.8","best_bid":"0.79","hash":"da500b7bb810bdd5109377517fd6f6b0f994f0cb","price":"0.78","side":"BUY","size":"110.2"},{"asset_id":"14965588658799411272385430903075831224615961675357217884735713260981483529984","best_ask":"0.21","best_bid":"0.2","hash":"0b866b091c3db419fd66fd9404f7178f669421bb","price":"0.22","side":"SELL","size":"110.2"}],"timestamp":"1785207995978"},"payload_hash":"0c7847707941da0515b95da9f110349779dbb1db66dcc853f5929867d6672cd3","raw_frame":"{\"market\":\"0x779291bef19b6709f61e9764a954aafe9ffae488d50ae674aabdcb4f248006d5\", \"price_changes\":[{\"asset_id\":\"8761897749749422724209054078244794145777693856614463256546737399611489089783\", \"price\":\"0.78\", \"size\":\"110.2\", \"side\":\"BUY\", \"hash\":\"da500b7bb810bdd5109377517fd6f6b0f994f0cb\", \"best_bid\":\"0.79\", \"best_ask\":\"0.8\"}, {\"asset_id\":\"14965588658799411272385430903075831224615961675357217884735713260981483529984\", \"price\":\"0.22\", \"size\":\"110.2\", \"side\":\"SELL\", \"hash\":\"0b866b091c3db419fd66fd9404f7178f669421bb\", \"best_bid\":\"0.2\", \"best_ask\":\"0.21\"}], \"timestamp\":\"1785207995978\", \"event_type\":\"price_change\"}","received_at":"2026-07-28T03:06:35.996361Z","schema_version":"clob-market-ws.price_change.v1","sequence":null,"server_hash":null,"server_timestamp":"1785207995978","session_id":"3e519d9098404c15b234d96025eb1a2b","source":"clob_market_ws"},"received_at":"2026-07-28T03:06:35.996361Z","record_id":"889987f195fbf236ce2083e293d31147216d951de37dacc19011f6b6189cd269","schema_fingerprint":"4aa3821a28b0b7c2400bc59aba4bcc0a76e971dadd19610d3ad38c768e124dc7","schema_version":"edge-lab-recorder.raw.v1","sequence":null,"source":"clob_market_ws"}
{"event_at":"2026-07-28T03:06:35.979000Z","event_fingerprint":"a80c1d20106e4ee68c9d803c73f1937121928bcb0d4ca7c25672d304caa4b783","payload":{"connection_id":"a6b55582af5f430fb37ad02bf0922475","event_at":"2026-07-28T03:06:35.979000Z","event_type":"price_change","frame_hash":"25a62565b9a2a2d2a51a045de760706e9f6ad741db1d80acd9f2901d40453fcd","frame_index":0,"kind":"data","monotonic_ns":309979032231541,"payload":{"event_type":"price_change","market":"0x779291bef19b6709f61e9764a954aafe9ffae488d50ae674aabdcb4f248006d5","price_changes":[{"asset_id":"14965588658799411272385430903075831224615961675357217884735713260981483529984","best_ask":"0.21","best_bid":"0.2","hash":"6cf459e1ea8152cbbd5ed079e9ffa186a5838bbf","price":"0.19","side":"BUY","size":"42"},{"asset_id":"8761897749749422724209054078244794145777693856614463256546737399611489089783","best_ask":"0.8","best_bid":"0.79","hash":"80181259db7c0b84aca13e2ecf572d3f325e7748","price":"0.81","side":"SELL","size":"42"}],"timestamp":"1785207995979"},"payload_hash":"60a968e0dc787f5f213d04082e6b896ae3a8f7fab953b80f4a19dab5f4175e83","raw_frame":"{\"market\":\"0x779291bef19b6709f61e9764a954aafe9ffae488d50ae674aabdcb4f248006d5\", \"price_changes\":[{\"asset_id\":\"14965588658799411272385430903075831224615961675357217884735713260981483529984\", \"price\":\"0.19\", \"size\":\"42\", \"side\":\"BUY\", \"hash\":\"6cf459e1ea8152cbbd5ed079e9ffa186a5838bbf\", \"best_bid\":\"0.2\", \"best_ask\":\"0.21\"}, {\"asset_id\":\"8761897749749422724209054078244794145777693856614463256546737399611489089783\", \"price\":\"0.81\", \"size\":\"42\", \"side\":\"SELL\", \"hash\":\"80181259db7c0b84aca13e2ecf572d3f325e7748\", \"best_bid\":\"0.79\", \"best_ask\":\"0.8\"}], \"timestamp\":\"1785207995979\", \"event_type\":\"price_change\"}","received_at":"2026-07-28T03:06:36.000694Z","schema_version":"clob-market-ws.price_change.v1","sequence":null,"server_hash":null,"server_timestamp":"1785207995979","session_id":"3e519d9098404c15b234d96025eb1a2b","source":"clob_market_ws"},"received_at":"2026-07-28T03:06:36.000694Z","record_id":"d6d656284f11d9378c892742b723a20078e935f4a34d3081ee2a46d6442eff7c","schema_fingerprint":"4aa3821a28b0b7c2400bc59aba4bcc0a76e971dadd19610d3ad38c768e124dc7","schema_version":"edge-lab-recorder.raw.v1","sequence":null,"source":"clob_market_ws"}
{"event_at":"2026-07-28T03:06:35.979000Z","event_fingerprint":"af77518e5be8daced14674db1b66b439b92d6f06088bd490bcb33fe40fc420d9","payload":{"connection_id":"a6b55582af5f430fb37ad02bf0922475","event_at":"2026-07-28T03:06:35.979000Z","event_type":"price_change","frame_hash":"80a29186ee69d251b7f06e51cf0ab2d313859b48525121574f8fdce01b9ba251","frame_index":0,"kind":"data","monotonic_ns":309979035356166,"payload":{"event_type":"price_change","market":"0x779291bef19b6709f61e9764a954aafe9ffae488d50ae674aabdcb4f248006d5","price_changes":[{"asset_id":"14965588658799411272385430903075831224615961675357217884735713260981483529984","best_ask":"0.21","best_bid":"0.2","hash":"ad06eeba8a3f6a50095ed58b4e47a97d1f160ded","price":"0.09","side":"BUY","size":"403.6"},{"asset_id":"8761897749749422724209054078244794145777693856614463256546737399611489089783","best_ask":"0.8","best_bid":"0.79","hash":"fa66f061f5b4080a64dcb6a3482b2e4be4cb57e9","price":"0.91","side":"SELL","size":"403.6"}],"timestamp":"1785207995979"},"payload_hash":"bfb878651cd1947af000962bf6d61ebeb2bb18421f9afe08acfcd5f6a5259086","raw_frame":"{\"market\":\"0x779291bef19b6709f61e9764a954aafe9ffae488d50ae674aabdcb4f248006d5\", \"price_changes\":[{\"asset_id\":\"14965588658799411272385430903075831224615961675357217884735713260981483529984\", \"price\":\"0.09\", \"size\":\"403.6\", \"side\":\"BUY\", \"hash\":\"ad06eeba8a3f6a50095ed58b4e47a97d1f160ded\", \"best_bid\":\"0.2\", \"best_ask\":\"0.21\"}, {\"asset_id\":\"8761897749749422724209054078244794145777693856614463256546737399611489089783\", \"price\":\"0.91\", \"size\":\"403.6\", \"side\":\"SELL\", \"hash\":\"fa66f061f5b4080a64dcb6a3482b2e4be4cb57e9\", \"best_bid\":\"0.79\", \"best_ask\":\"0.8\"}], \"timestamp\":\"1785207995979\", \"event_type\":\"price_change\"}","received_at":"2026-07-28T03:06:36.003819Z","schema_version":"clob-market-ws.price_change.v1","sequence":null,"server_hash":null,"server_timestamp":"1785207995979","session_id":"3e519d9098404c15b234d96025eb1a2b","source":"clob_market_ws"},"received_at":"2026-07-28T03:06:36.003819Z","record_id":"0c880de512cd36031238da26e7662e8fbed55f3b806925109be0c27acd4c7be6","schema_fingerprint":"4aa3821a28b0b7c2400bc59aba4bcc0a76e971dadd19610d3ad38c768e124dc7","schema_version":"edge-lab-recorder.raw.v1","sequence":null,"source":"clob_market_ws"}
{"event_at":"2026-07-28T03:06:35.979000Z","event_fingerprint":"1aa63cf81ae0a3f11c11a592e7ff0d2955ecab77cc7c532ee0075174ec4bfda7","payload":{"connection_id":"a6b55582af5f430fb37ad02bf0922475","event_at":"2026-07-28T03:06:35.979000Z","event_type":"price_change","frame_hash":"2729b7afb7e1603c10c40bd7a9b85d3fd1b4b4bdf5d2778505917bc61208ad3d","frame_index":0,"kind":"data","monotonic_ns":309979038434416,"payload":{"event_type":"price_change","market":"0x779291bef19b6709f61e9764a954aafe9ffae488d50ae674aabdcb4f248006d5","price_changes":[{"asset_id":"8761897749749422724209054078244794145777693856614463256546737399611489089783","best_ask":"0.8","best_bid":"0.79","hash":"fa66f061f5b4080a64dcb6a3482b2e4be4cb57e9","price":"0.75","side":"BUY","size":"127"},{"asset_id":"14965588658799411272385430903075831224615961675357217884735713260981483529984","best_ask":"0.21","best_bid":"0.2","hash":"ad06eeba8a3f6a50095ed58b4e47a97d1f160ded","price":"0.25","side":"SELL","size":"127"}],"timestamp":"1785207995979"},"payload_hash":"5ca1fd33f2a06aac8399980c9313b7341c903d60aa3c0b750788a23fa53de681","raw_frame":"{\"market\":\"0x779291bef19b6709f61e9764a954aafe9ffae488d50ae674aabdcb4f248006d5\", \"price_changes\":[{\"asset_id\":\"8761897749749422724209054078244794145777693856614463256546737399611489089783\", \"price\":\"0.75\", \"size\":\"127\", \"side\":\"BUY\", \"hash\":\"fa66f061f5b4080a64dcb6a3482b2e4be4cb57e9\", \"best_bid\":\"0.79\", \"best_ask\":\"0.8\"}, {\"asset_id\":\"14965588658799411272385430903075831224615961675357217884735713260981483529984\", \"price\":\"0.25\", \"size\":\"127\", \"side\":\"SELL\", \"hash\":\"ad06eeba8a3f6a50095ed58b4e47a97d1f160ded\", \"best_bid\":\"0.2\", \"best_ask\":\"0.21\"}], \"timestamp\":\"1785207995979\", \"event_type\":\"price_change\"}","received_at":"2026-07-28T03:06:36.006897Z","schema_version":"clob-market-ws.price_change.v1","sequence":null,"server_hash":null,"server_timestamp":"1785207995979","session_id":"3e519d9098404c15b234d96025eb1a2b","source":"clob_market_ws"},"received_at":"2026-07-28T03:06:36.006897Z","record_id":"9e475001195da95ff91efacc57d8f8bf91324ab42ea96030ee3f8960ed55cb45","schema_fingerprint":"4aa3821a28b0b7c2400bc59aba4bcc0a76e971dadd19610d3ad38c768e124dc7","schema_version":"edge-lab-recorder.raw.v1","sequence":null,"source":"clob_market_ws"}
{"event_at":"2026-07-28T03:06:35.979000Z","event_fingerprint":"1c6378d0a62846eaa22797db99b49b4bb8961cbb80c18336f2c7977011d2a9c2","payload":{"connection_id":"a6b55582af5f430fb37ad02bf0922475","event_at":"2026-07-28T03:06:35.979000Z","event_type":"price_change","frame_hash":"7c0b18bc778d479a51722dd5d79a319998e612814b36357295e8fa00dc11cf22","frame_index":0,"kind":"data","monotonic_ns":309979041479333,"payload":{"event_type":"price_change","market":"0x779291bef19b6709f61e9764a954aafe9ffae488d50ae674aabdcb4f248006d5","price_changes":[{"asset_id":"8761897749749422724209054078244794145777693856614463256546737399611489089783","best_ask":"0.8","best_bid":"0.79","hash":"fa66f061f5b4080a64dcb6a3482b2e4be4cb57e9","price":"0.74","side":"BUY","size":"83.46"},{"asset_id":"14965588658799411272385430903075831224615961675357217884735713260981483529984","best_ask":"0.21","best_bid":"0.2","hash":"ad06eeba8a3f6a50095ed58b4e47a97d1f160ded","price":"0.26","side":"SELL","size":"83.46"}],"timestamp":"1785207995979"},"payload_hash":"ae4df6d755e646582c7ccd55209f4b9b697f190601b7f9aabf765de4b18d9ef6","raw_frame":"{\"market\":\"0x779291bef19b6709f61e9764a954aafe9ffae488d50ae674aabdcb4f248006d5\", \"price_changes\":[{\"asset_id\":\"8761897749749422724209054078244794145777693856614463256546737399611489089783\", \"price\":\"0.74\", \"size\":\"83.46\", \"side\":\"BUY\", \"hash\":\"fa66f061f5b4080a64dcb6a3482b2e4be4cb57e9\", \"best_bid\":\"0.79\", \"best_ask\":\"0.8\"}, {\"asset_id\":\"14965588658799411272385430903075831224615961675357217884735713260981483529984\", \"price\":\"0.26\", \"size\":\"83.46\", \"side\":\"SELL\", \"hash\":\"ad06eeba8a3f6a50095ed58b4e47a97d1f160ded\", \"best_bid\":\"0.2\", \"best_ask\":\"0.21\"}], \"timestamp\":\"1785207995979\", \"event_type\":\"price_change\"}","received_at":"2026-07-28T03:06:36.009940Z","schema_version":"clob-market-ws.price_change.v1","sequence":null,"server_hash":null,"server_timestamp":"1785207995979","session_id":"3e519d9098404c15b234d96025eb1a2b","source":"clob_market_ws"},"received_at":"2026-07-28T03:06:36.009940Z","record_id":"b7d2fa96485b6cfc5dedb2411de359b36c060dbdc947bcaf071185865ff8f163","schema_fingerprint":"4aa3821a28b0b7c2400bc59aba4bcc0a76e971dadd19610d3ad38c768e124dc7","schema_version":"edge-lab-recorder.raw.v1","sequence":null,"source":"clob_market_ws"}
{"event_at":"2026-07-28T03:06:35.979000Z","event_fingerprint":"24ad97d5d999ac943da746a24e408ca020f3d560c9b9c3194c33d1490d2fb326","payload":{"connection_id":"a6b55582af5f430fb37ad02bf0922475","event_at":"2026-07-28T03:06:35.979000Z","event_type":"price_change","frame_hash":"bcd1f863046a110666c73152ca77c3a0f32010f54f78f80573efd33f26693cf4","frame_index":0,"kind":"data","monotonic_ns":309979044440875,"payload":{"event_type":"price_change","market":"0x779291bef19b6709f61e9764a954aafe9ffae488d50ae674aabdcb4f248006d5","price_changes":[{"asset_id":"8761897749749422724209054078244794145777693856614463256546737399611489089783","best_ask":"0.8","best_bid":"0.79","hash":"fa66f061f5b4080a64dcb6a3482b2e4be4cb57e9","price":"0.73","side":"BUY","size":"181"},{"asset_id":"14965588658799411272385430903075831224615961675357217884735713260981483529984","best_ask":"0.21","best_bid":"0.2","hash":"ad06eeba8a3f6a50095ed58b4e47a97d1f160ded","price":"0.27","side":"SELL","size":"181"}],"timestamp":"1785207995979"},"payload_hash":"cb8406da97490b747764aa2b797c7055c1ba2f7b265f19d2413d3df4f71f9952","raw_frame":"{\"market\":\"0x779291bef19b6709f61e9764a954aafe9ffae488d50ae674aabdcb4f248006d5\", \"price_changes\":[{\"asset_id\":\"8761897749749422724209054078244794145777693856614463256546737399611489089783\", \"price\":\"0.73\", \"size\":\"181\", \"side\":\"BUY\", \"hash\":\"fa66f061f5b4080a64dcb6a3482b2e4be4cb57e9\", \"best_bid\":\"0.79\", \"best_ask\":\"0.8\"}, {\"asset_id\":\"14965588658799411272385430903075831224615961675357217884735713260981483529984\", \"price\":\"0.27\", \"size\":\"181\", \"side\":\"SELL\", \"hash\":\"ad06eeba8a3f6a50095ed58b4e47a97d1f160ded\", \"best_bid\":\"0.2\", \"best_ask\":\"0.21\"}], \"timestamp\":\"1785207995979\", \"event_type\":\"price_change\"}","received_at":"2026-07-28T03:06:36.012903Z","schema_version":"clob-market-ws.price_change.v1","sequence":null,"server_hash":null,"server_timestamp":"1785207995979","session_id":"3e519d9098404c15b234d96025eb1a2b","source":"clob_market_ws"},"received_at":"2026-07-28T03:06:36.012903Z","record_id":"fc9213d1a42305c0654098a714c2661363cb291df8f851b9b2ccdd89953dc9b1","schema_fingerprint":"4aa3821a28b0b7c2400bc59aba4bcc0a76e971dadd19610d3ad38c768e124dc7","schema_version":"edge-lab-recorder.raw.v1","sequence":null,"source":"clob_market_ws"}
{"event_at":"2026-07-28T03:06:35.979000Z","event_fingerprint":"328e13657455afc952745dfeaba8740370851e4682de90e24b9dcfa370920b14","payload":{"connection_id":"a6b55582af5f430fb37ad02bf0922475","event_at":"2026-07-28T03:06:35.979000Z","event_type":"price_change","frame_hash":"7cf468c3b4b5b6aacfa7a10c887c1296e39badf3adc491fc95e5b1c69d0ffb61","frame_index":0,"kind":"data","monotonic_ns":309979047461208,"payload":{"event_type":"price_change","market":"0x779291bef19b6709f61e9764a954aafe9ffae488d50ae674aabdcb4f248006d5","price_changes":[{"asset_id":"8761897749749422724209054078244794145777693856614463256546737399611489089783","best_ask":"0.8","best_bid":"0.79","hash":"f1755f60451a1c47f21caa064e7d097dcc21a570","price":"0.79","side":"BUY","size":"55.2"},{"asset_id":"14965588658799411272385430903075831224615961675357217884735713260981483529984","best_ask":"0.21","best_bid":"0.2","hash":"c8e45f9b4fa8799427deb20d9f96e71484075676","price":"0.21","side":"SELL","size":"55.2"}],"timestamp":"1785207995979"},"payload_hash":"c26e2354c39c413caa7bb2d0e9f8016f5c7d52eb257be83a7f59a683d0d3c09e","raw_frame":"{\"market\":\"0x779291bef19b6709f61e9764a954aafe9ffae488d50ae674aabdcb4f248006d5\", \"price_changes\":[{\"asset_id\":\"8761897749749422724209054078244794145777693856614463256546737399611489089783\", \"price\":\"0.79\", \"size\":\"55.2\", \"side\":\"BUY\", \"hash\":\"f1755f60451a1c47f21caa064e7d097dcc21a570\", \"best_bid\":\"0.79\", \"best_ask\":\"0.8\"}, {\"asset_id\":\"14965588658799411272385430903075831224615961675357217884735713260981483529984\", \"price\":\"0.21\", \"size\":\"55.2\", \"side\":\"SELL\", \"hash\":\"c8e45f9b4fa8799427deb20d9f96e71484075676\", \"best_bid\":\"0.2\", \"best_ask\":\"0.21\"}], \"timestamp\":\"1785207995979\", \"event_type\":\"price_change\"}","received_at":"2026-07-28T03:06:36.015924Z","schema_version":"clob-market-ws.price_change.v1","sequence":null,"server_hash":null,"server_timestamp":"1785207995979","session_id":"3e519d9098404c15b234d96025eb1a2b","source":"clob_market_ws"},"received_at":"2026-07-28T03:06:36.015924Z","record_id":"32d1705de500da697220a488c271d930dfd48ae6d9744591684423165ab33bec","schema_fingerprint":"4aa3821a28b0b7c2400bc59aba4bcc0a76e971dadd19610d3ad38c768e124dc7","schema_version":"edge-lab-recorder.raw.v1","sequence":null,"source":"clob_market_ws"}
{"event_at":"2026-07-28T03:06:35.980000Z","event_fingerprint":"29d0bbbfab033e354ce0c1bd674b8f562c3681b5673fef99b4d01f52ef038d2c","payload":{"connection_id":"a6b55582af5f430fb37ad02bf0922475","event_at":"2026-07-28T03:06:35.980000Z","event_type":"price_change","frame_hash":"eab528183162d7ef8ab9f71bbf01c243bcc18e669ecd3deeb30710ad7c1afd1b","frame_index":0,"kind":"data","monotonic_ns":309979050437291,"payload":{"event_type":"price_change","market":"0x779291bef19b6709f61e9764a954aafe9ffae488d50ae674aabdcb4f248006d5","price_changes":[{"asset_id":"14965588658799411272385430903075831224615961675357217884735713260981483529984","best_ask":"0.21","best_bid":"0.2","hash":"b6b36c2928bfdcb569cbf827eb1b475663479293","price":"0.08","side":"BUY","size":"955.29"},{"asset_id":"8761897749749422724209054078244794145777693856614463256546737399611489089783","best_ask":"0.8","best_bid":"0.79","hash":"0cc8c0850802c4b934071a69904ed7e528f25b76","price":"0.92","side":"SELL","size":"955.29"}],"timestamp":"1785207995980"},"payload_hash":"9d24d900c0ce970b4a6e99a41967b1789bf59e24209c27285696a6a5d48bbe6f","raw_frame":"{\"market\":\"0x779291bef19b6709f61e9764a954aafe9ffae488d50ae674aabdcb4f248006d5\", \"price_changes\":[{\"asset_id\":\"14965588658799411272385430903075831224615961675357217884735713260981483529984\", \"price\":\"0.08\", \"size\":\"955.29\", \"side\":\"BUY\", \"hash\":\"b6b36c2928bfdcb569cbf827eb1b475663479293\", \"best_bid\":\"0.2\", \"best_ask\":\"0.21\"}, {\"asset_id\":\"8761897749749422724209054078244794145777693856614463256546737399611489089783\", \"price\":\"0.92\", \"size\":\"955.29\", \"side\":\"SELL\", \"hash\":\"0cc8c0850802c4b934071a69904ed7e528f25b76\", \"best_bid\":\"0.79\", \"best_ask\":\"0.8\"}], \"timestamp\":\"1785207995980\", \"event_type\":\"price_change\"}","received_at":"2026-07-28T03:06:36.018900Z","schema_version":"clob-market-ws.price_change.v1","sequence":null,"server_hash":null,"server_timestamp":"1785207995980","session_id":"3e519d9098404c15b234d96025eb1a2b","source":"clob_market_ws"},"received_at":"2026-07-28T03:06:36.018900Z","record_id":"84b38376b5219a1e3d9f12a7ce3ecf2d48b6ea176bed172461328448907ad2d0","schema_fingerprint":"4aa3821a28b0b7c2400bc59aba4bcc0a76e971dadd19610d3ad38c768e124dc7","schema_version":"edge-lab-recorder.raw.v1","sequence":null,"source":"clob_market_ws"}
{"event_at":"2026-07-28T03:06:35.980000Z","event_fingerprint":"0fc5fc71de9c2775ab9917f73f89376a491844e3b4e32ef34a8697f6c79edfe6","payload":{"connection_id":"a6b55582af5f430fb37ad02bf0922475","event_at":"2026-07-28T03:06:35.980000Z","event_type":"price_change","frame_hash":"067beb56d7d096a29d7054b149bf11069f4ea49f25c09b81c08c87996bcd5df1","frame_index":0,"kind":"data","monotonic_ns":309979053419375,"payload":{"event_type":"price_change","market":"0x779291bef19b6709f61e9764a954aafe9ffae488d50ae674aabdcb4f248006d5","price_changes":[{"asset_id":"8761897749749422724209054078244794145777693856614463256546737399611489089783","best_ask":"0.8","best_bid":"0.79","hash":"a776448afd8bc6de1c49ee8109528b097a3df620","price":"0.78","side":"BUY","size":"105.2"},{"asset_id":"14965588658799411272385430903075831224615961675357217884735713260981483529984","best_ask":"0.21","best_bid":"0.2","hash":"68fd8e0c49184122e92e5d4d3b22704cf095ba90","price":"0.22","side":"SELL","size":"105.2"}],"timestamp":"1785207995980"},"payload_hash":"e3b3b21d72abd217640abc3c1a93d1ec485ecbfe3476fb11efb723f9f1aef6d0","raw_frame":"{\"market\":\"0x779291bef19b6709f61e9764a954aafe9ffae488d50ae674aabdcb4f248006d5\", \"price_changes\":[{\"asset_id\":\"8761897749749422724209054078244794145777693856614463256546737399611489089783\", \"price\":\"0.78\", \"size\":\"105.2\", \"side\":\"BUY\", \"hash\":\"a776448afd8bc6de1c49ee8109528b097a3df620\", \"best_bid\":\"0.79\", \"best_ask\":\"0.8\"}, {\"asset_id\":\"14965588658799411272385430903075831224615961675357217884735713260981483529984\", \"price\":\"0.22\", \"size\":\"105.2\", \"side\":\"SELL\", \"hash\":\"68fd8e0c49184122e92e5d4d3b22704cf095ba90\", \"best_bid\":\"0.2\", \"best_ask\":\"0.21\"}], \"timestamp\":\"1785207995980\", \"event_type\":\"price_change\"}","received_at":"2026-07-28T03:06:36.021882Z","schema_version":"clob-market-ws.price_change.v1","sequence":null,"server_hash":null,"server_timestamp":"1785207995980","session_id":"3e519d9098404c15b234d96025eb1a2b","source":"clob_market_ws"},"received_at":"2026-07-28T03:06:36.021882Z","record_id":"264175eabff7a31cddf3951f8a113f062819982699081928cb62547af2f365d1","schema_fingerprint":"4aa3821a28b0b7c2400bc59aba4bcc0a76e971dadd19610d3ad38c768e124dc7","schema_version":"edge-lab-recorder.raw.v1","sequence":null,"source":"clob_market_ws"}
{"event_at":"2026-07-28T03:06:35.980000Z","event_fingerprint":"d914299820ea05c948c898b80f98eb8c84b13b5fb322dabb73f19590495b971f","payload":{"connection_id":"a6b55582af5f430fb37ad02bf0922475","event_at":"2026-07-28T03:06:35.980000Z","event_type":"price_change","frame_hash":"e52178619e55769668d8481e3fbdc7f00a9a11f4c89bc15e3e96ce00037436d8","frame_index":0,"kind":"data","monotonic_ns":309979056360166,"payload":{"event_type":"price_change","market":"0x779291bef19b6709f61e9764a954aafe9ffae488d50ae674aabdcb4f248006d5","price_changes":[{"asset_id":"8761897749749422724209054078244794145777693856614463256546737399611489089783","best_ask":"0.8","best_bid":"0.79","hash":"01dbd7531519d0bf6c0520da8f03a87099287980","price":"0.73","side":"BUY","size":"166"},{"asset_id":"14965588658799411272385430903075831224615961675357217884735713260981483529984","best_ask":"0.21","best_bid":"0.2","hash":"a50e0427b27ba6b832cfbbc6c45e37b42d15b9b0","price":"0.27","side":"SELL","size":"166"}],"timestamp":"1785207995980"},"payload_hash":"dbbe322b456d2cd97d9dc9de4c7baf262ba42078c5727e52e9dbf4d9e1aed5d9","raw_frame":"{\"market\":\"0x779291bef19b6709f61e9764a954aafe9ffae488d50ae674aabdcb4f248006d5\", \"price_changes\":[{\"asset_id\":\"8761897749749422724209054078244794145777693856614463256546737399611489089783\", \"price\":\"0.73\", \"size\":\"166\", \"side\":\"BUY\", \"hash\":\"01dbd7531519d0bf6c0520da8f03a87099287980\", \"best_bid\":\"0.79\", \"best_ask\":\"0.8\"}, {\"asset_id\":\"14965588658799411272385430903075831224615961675357217884735713260981483529984\", \"price\":\"0.27\", \"size\":\"166\", \"side\":\"SELL\", \"hash\":\"a50e0427b27ba6b832cfbbc6c45e37b42d15b9b0\", \"best_bid\":\"0.2\", \"best_ask\":\"0.21\"}], \"timestamp\":\"1785207995980\", \"event_type\":\"price_change\"}","received_at":"2026-07-28T03:06:36.024823Z","schema_version":"clob-market-ws.price_change.v1","sequence":null,"server_hash":null,"server_timestamp":"1785207995980","session_id":"3e519d9098404c15b234d96025eb1a2b","source":"clob_market_ws"},"received_at":"2026-07-28T03:06:36.024823Z","record_id":"ec1d163506c3e839ef3a9735fc85284b2e86333c2686b07f45166df3cf6fc37c","schema_fingerprint":"4aa3821a28b0b7c2400bc59aba4bcc0a76e971dadd19610d3ad38c768e124dc7","schema_version":"edge-lab-recorder.raw.v1","sequence":null,"source":"clob_market_ws"}
{"event_at":"2026-07-28T03:06:35.980000Z","event_fingerprint":"2134e17cea67bcf758effd2529777c8b2d5e237bda1b414ea3407e395b95f667","payload":{"connection_id":"a6b55582af5f430fb37ad02bf0922475","event_at":"2026-07-28T03:06:35.980000Z","event_type":"price_change","frame_hash":"4fbb32d8aeeea051db3cef57466fb0e2d5419faccf5bcbb3a9fb485b0ed78dad","frame_index":0,"kind":"data","monotonic_ns":309979059293541,"payload":{"event_type":"price_change","market":"0x779291bef19b6709f61e9764a954aafe9ffae488d50ae674aabdcb4f248006d5","price_changes":[{"asset_id":"8761897749749422724209054078244794145777693856614463256546737399611489089783","best_ask":"0.8","best_bid":"0.79","hash":"01dbd7531519d0bf6c0520da8f03a87099287980","price":"0.69","side":"BUY","size":"209.5"},{"asset_id":"14965588658799411272385430903075831224615961675357217884735713260981483529984","best_ask":"0.21","best_bid":"0.2","hash":"a50e0427b27ba6b832cfbbc6c45e37b42d15b9b0","price":"0.31","side":"SELL","size":"209.5"}],"timestamp":"1785207995980"},"payload_hash":"ec8b6adcf9dfe963d5f1480ce84494a29000d8ca4a99e77dabb42a848c1ec66e","raw_frame":"{\"market\":\"0x779291bef19b6709f61e9764a954aafe9ffae488d50ae674aabdcb4f248006d5\", \"price_changes\":[{\"asset_id\":\"8761897749749422724209054078244794145777693856614463256546737399611489089783\", \"price\":\"0.69\", \"size\":\"209.5\", \"side\":\"BUY\", \"hash\":\"01dbd7531519d0bf6c0520da8f03a87099287980\", \"best_bid\":\"0.79\", \"best_ask\":\"0.8\"}, {\"asset_id\":\"14965588658799411272385430903075831224615961675357217884735713260981483529984\", \"price\":\"0.31\", \"size\":\"209.5\", \"side\":\"SELL\", \"hash\":\"a50e0427b27ba6b832cfbbc6c45e37b42d15b9b0\", \"best_bid\":\"0.2\", \"best_ask\":\"0.21\"}], \"timestamp\":\"1785207995980\", \"event_type\":\"price_change\"}","received_at":"2026-07-28T03:06:36.027756Z","schema_version":"clob-market-ws.price_change.v1","sequence":null,"server_hash":null,"server_timestamp":"1785207995980","session_id":"3e519d9098404c15b234d96025eb1a2b","source":"clob_market_ws"},"received_at":"2026-07-28T03:06:36.027756Z","record_id":"0d172b30c8c0624610aadb5465cc722381e6082ee1ceb00dca32d239afef098f","schema_fingerprint":"4aa3821a28b0b7c2400bc59aba4bcc0a76e971dadd19610d3ad38c768e124dc7","schema_version":"edge-lab-recorder.raw.v1","sequence":null,"source":"clob_market_ws"}
{"event_at":"2026-07-28T03:06:35.982000Z","event_fingerprint":"f482203362d28b133b78fb313e7ba91d52b93fccb0e2b99eb7beafda9e6b37ec","payload":{"connection_id":"a6b55582af5f430fb37ad02bf0922475","event_at":"2026-07-28T03:06:35.982000Z","event_type":"price_change","frame_hash":"c6fe93566825e8ac0d4a20e294fe0c004ae6bfa68d3219b3ab777f261d2a9503","frame_index":0,"kind":"data","monotonic_ns":309979062269083,"payload":{"event_type":"price_change","market":"0x779291bef19b6709f61e9764a954aafe9ffae488d50ae674aabdcb4f248006d5","price_changes":[{"asset_id":"14965588658799411272385430903075831224615961675357217884735713260981483529984","best_ask":"0.21","best_bid":"0.2","hash":"cf6844afe81896dd34cedb2ab724024055686ed2","price":"0.2","side":"BUY","size":"80"},{"asset_id":"8761897749749422724209054078244794145777693856614463256546737399611489089783","best_ask":"0.8","best_bid":"0.79","hash":"f0aff0de79bc81cbcf3934be1fb9a470ccc85fcf","price":"0.8","side":"SELL","size":"80"}],"timestamp":"1785207995982"},"payload_hash":"d03b7dd64261a2ca8c109f01ebc80890743e51e1e58d6a30523231d021adb85a","raw_frame":"{\"market\":\"0x779291bef19b6709f61e9764a954aafe9ffae488d50ae674aabdcb4f248006d5\", \"price_changes\":[{\"asset_id\":\"14965588658799411272385430903075831224615961675357217884735713260981483529984\", \"price\":\"0.2\", \"size\":\"80\", \"side\":\"BUY\", \"hash\":\"cf6844afe81896dd34cedb2ab724024055686ed2\", \"best_bid\":\"0.2\", \"best_ask\":\"0.21\"}, {\"asset_id\":\"8761897749749422724209054078244794145777693856614463256546737399611489089783\", \"price\":\"0.8\", \"size\":\"80\", \"side\":\"SELL\", \"hash\":\"f0aff0de79bc81cbcf3934be1fb9a470ccc85fcf\", \"best_bid\":\"0.79\", \"best_ask\":\"0.8\"}], \"timestamp\":\"1785207995982\", \"event_type\":\"price_change\"}","received_at":"2026-07-28T03:06:36.030731Z","schema_version":"clob-market-ws.price_change.v1","sequence":null,"server_hash":null,"server_timestamp":"1785207995982","session_id":"3e519d9098404c15b234d96025eb1a2b","source":"clob_market_ws"},"received_at":"2026-07-28T03:06:36.030731Z","record_id":"2b78ef399642b6bca872fd277e1bc3b9f2f7d9498e2b81e9bc06ff7c2e03d509","schema_fingerprint":"4aa3821a28b0b7c2400bc59aba4bcc0a76e971dadd19610d3ad38c768e124dc7","schema_version":"edge-lab-recorder.raw.v1","sequence":null,"source":"clob_market_ws"}
{"event_at":"2026-07-28T03:06:35.983000Z","event_fingerprint":"b7ef4984064373349d40969b63bd68505b43e400e8f32130b708d57456807d27","payload":{"connection_id":"a6b55582af5f430fb37ad02bf0922475","event_at":"2026-07-28T03:06:35.983000Z","event_type":"price_change","frame_hash":"766e1f4138ab5b2160c9b05c86cf8c392408fb845a9b17e37108e8f63414a808","frame_index":0,"kind":"data","monotonic_ns":309979065205041,"payload":{"event_type":"price_change","market":"0x779291bef19b6709f61e9764a954aafe9ffae488d50ae674aabdcb4f248006d5","price_changes":[{"asset_id":"14965588658799411272385430903075831224615961675357217884735713260981483529984","best_ask":"0.21","best_bid":"0.2","hash":"454feef193a6a11aba3399dac093b4cafa1f2b24","price":"0.23","side":"SELL","size":"142.98"},{"asset_id":"8761897749749422724209054078244794145777693856614463256546737399611489089783","best_ask":"0.8","best_bid":"0.79","hash":"34a1dbf79977d6ab8df4b9ac993f3d15d1394d43","price":"0.77","side":"BUY","size":"142.98"}],"timestamp":"1785207995983"},"payload_hash":"b5e31b89c3b69113daeba3bc08fda5e6efe0ab5d178d625f5d6905370dc82e75","raw_frame":"{\"market\":\"0x779291bef19b6709f61e9764a954aafe9ffae488d50ae674aabdcb4f248006d5\", \"price_changes\":[{\"asset_id\":\"14965588658799411272385430903075831224615961675357217884735713260981483529984\", \"price\":\"0.23\", \"size\":\"142.98\", \"side\":\"SELL\", \"hash\":\"454feef193a6a11aba3399dac093b4cafa1f2b24\", \"best_bid\":\"0.2\", \"best_ask\":\"0.21\"}, {\"asset_id\":\"8761897749749422724209054078244794145777693856614463256546737399611489089783\", \"price\":\"0.77\", \"size\":\"142.98\", \"side\":\"BUY\", \"hash\":\"34a1dbf79977d6ab8df4b9ac993f3d15d1394d43\", \"best_bid\":\"0.79\", \"best_ask\":\"0.8\"}], \"timestamp\":\"1785207995983\", \"event_type\":\"price_change\"}","received_at":"2026-07-28T03:06:36.033668Z","schema_version":"clob-market-ws.price_change.v1","sequence":null,"server_hash":null,"server_timestamp":"1785207995983","session_id":"3e519d9098404c15b234d96025eb1a2b","source":"clob_market_ws"},"received_at":"2026-07-28T03:06:36.033668Z","record_id":"2ab71eef27dac0306a2512affbb09629a9291ff772110e071832917efad7dbe4","schema_fingerprint":"4aa3821a28b0b7c2400bc59aba4bcc0a76e971dadd19610d3ad38c768e124dc7","schema_version":"edge-lab-recorder.raw.v1","sequence":null,"source":"clob_market_ws"}
{"event_at":"2026-07-28T03:06:35.984000Z","event_fingerprint":"01ec260872280ea39b25c46c45d8edf6aacab480ea9968cef67f438d524d8ad7","payload":{"connection_id":"a6b55582af5f430fb37ad02bf0922475","event_at":"2026-07-28T03:06:35.984000Z","event_type":"price_change","frame_hash":"10d9de4e81ae6d1f80889e514b2840d23bf417791658fc6ecb95f8f0c8a02aa9","frame_index":0,"kind":"data","monotonic_ns":309979068151583,"payload":{"event_type":"price_change","market":"0x779291bef19b6709f61e9764a954aafe9ffae488d50ae674aabdcb4f248006d5","price_changes":[{"asset_id":"8761897749749422724209054078244794145777693856614463256546737399611489089783","best_ask":"0.8","best_bid":"0.79","hash":"9982449d51606290c33396d74449e4811e1a6721","price":"0.77","side":"BUY","size":"149.98"},{"asset_id":"14965588658799411272385430903075831224615961675357217884735713260981483529984","best_ask":"0.21","best_bid":"0.2","hash":"5a54b7113ae0e91db2a35851f796038a6f699b27","price":"0.23","side":"SELL","size":"149.98"}],"timestamp":"1785207995984"},"payload_hash":"e270465fc266c8e427024c6193c069d4ba0884dfa4a81505b43ec165ff8d730f","raw_frame":"{\"market\":\"0x779291bef19b6709f61e9764a954aafe9ffae488d50ae674aabdcb4f248006d5\", \"price_changes\":[{\"asset_id\":\"8761897749749422724209054078244794145777693856614463256546737399611489089783\", \"price\":\"0.77\", \"size\":\"149.98\", \"side\":\"BUY\", \"hash\":\"9982449d51606290c33396d74449e4811e1a6721\", \"best_bid\":\"0.79\", \"best_ask\":\"0.8\"}, {\"asset_id\":\"14965588658799411272385430903075831224615961675357217884735713260981483529984\", \"price\":\"0.23\", \"size\":\"149.98\", \"side\":\"SELL\", \"hash\":\"5a54b7113ae0e91db2a35851f796038a6f699b27\", \"best_bid\":\"0.2\", \"best_ask\":\"0.21\"}], \"timestamp\":\"1785207995984\", \"event_type\":\"price_change\"}","received_at":"2026-07-28T03:06:36.036614Z","schema_version":"clob-market-ws.price_change.v1","sequence":null,"server_hash":null,"server_timestamp":"1785207995984","session_id":"3e519d9098404c15b234d96025eb1a2b","source":"clob_market_ws"},"received_at":"2026-07-28T03:06:36.036614Z","record_id":"d787ab2705bf532595ed1c96c1a8179962fb1a371dc734e4db34ff9924928bd0","schema_fingerprint":"4aa3821a28b0b7c2400bc59aba4bcc0a76e971dadd19610d3ad38c768e124dc7","schema_version":"edge-lab-recorder.raw.v1","sequence":null,"source":"clob_market_ws"}
{"event_at":"2026-07-28T03:06:35.986000Z","event_fingerprint":"dd51c9f3da07d68b644d56d2b8239c20e95b19be8c05ac4e59d473ab4bd4fa9a","payload":{"connection_id":"a6b55582af5f430fb37ad02bf0922475","event_at":"2026-07-28T03:06:35.986000Z","event_type":"price_change","frame_hash":"6824ac449e12bebb451364a5c1fd1bd8001ec4ca7396d53c226f931d91fdc6f9","frame_index":0,"kind":"data","monotonic_ns":309979071099541,"payload":{"event_type":"price_change","market":"0x779291bef19b6709f61e9764a954aafe9ffae488d50ae674aabdcb4f248006d5","price_changes":[{"asset_id":"14965588658799411272385430903075831224615961675357217884735713260981483529984","best_ask":"0.21","best_bid":"0.2","hash":"a37f5b2ce7f84da6bef99e81780f1afad0bf2a99","price":"0.16","side":"BUY","size":"137.3"},{"asset_id":"8761897749749422724209054078244794145777693856614463256546737399611489089783","best_ask":"0.8","best_bid":"0.79","hash":"62971f1130efd25db8c51aaaac018dfde0e43adb","price":"0.84","side":"SELL","size":"137.3"}],"timestamp":"1785207995986"},"payload_hash":"787f93d487ac2d0ee734987d355683557a4a743b1591cda409c6e4a6900c2b48","raw_frame":"{\"market\":\"0x779291bef19b6709f61e9764a954aafe9ffae488d50ae674aabdcb4f248006d5\", \"price_changes\":[{\"asset_id\":\"14965588658799411272385430903075831224615961675357217884735713260981483529984\", \"price\":\"0.16\", \"size\":\"137.3\", \"side\":\"BUY\", \"hash\":\"a37f5b2ce7f84da6bef99e81780f1afad0bf2a99\", \"best_bid\":\"0.2\", \"best_ask\":\"0.21\"}, {\"asset_id\":\"8761897749749422724209054078244794145777693856614463256546737399611489089783\", \"price\":\"0.84\", \"size\":\"137.3\", \"side\":\"SELL\", \"hash\":\"62971f1130efd25db8c51aaaac018dfde0e43adb\", \"best_bid\":\"0.79\", \"best_ask\":\"0.8\"}], \"timestamp\":\"1785207995986\", \"event_type\":\"price_change\"}","received_at":"2026-07-28T03:06:36.039562Z","schema_version":"clob-market-ws.price_change.v1","sequence":null,"server_hash":null,"server_timestamp":"1785207995986","session_id":"3e519d9098404c15b234d96025eb1a2b","source":"clob_market_ws"},"received_at":"2026-07-28T03:06:36.039562Z","record_id":"40a2a16d595c3b9a42aeaa08f716ec640b9e21e346166b7fa74cd42723ac1df2","schema_fingerprint":"4aa3821a28b0b7c2400bc59aba4bcc0a76e971dadd19610d3ad38c768e124dc7","schema_version":"edge-lab-recorder.raw.v1","sequence":null,"source":"clob_market_ws"}
{"event_at":"2026-07-28T03:06:35.988000Z","event_fingerprint":"a417d4e4321abe258444051425f25b366900831445ff4c275fe161aa58f57993","payload":{"connection_id":"a6b55582af5f430fb37ad02bf0922475","event_at":"2026-07-28T03:06:35.988000Z","event_type":"price_change","frame_hash":"01a90dcc991d98e70483ec02e0b0efeda4bdbe4228da76bafafe0c6e791e7c7c","frame_index":0,"kind":"data","monotonic_ns":309979074019833,"payload":{"event_type":"price_change","market":"0x779291bef19b6709f61e9764a954aafe9ffae488d50ae674aabdcb4f248006d5","price_changes":[{"asset_id":"14965588658799411272385430903075831224615961675357217884735713260981483529984","best_ask":"0.21","best_bid":"0.2","hash":"9c7b41359412b22d318188123a32a49ffb572d1d","price":"0.13","side":"BUY","size":"234.99"},{"asset_id":"8761897749749422724209054078244794145777693856614463256546737399611489089783","best_ask":"0.8","best_bid":"0.79","hash":"5c992987a96ba29b8dc4c493a8a0b8d4a9f7dc32","price":"0.87","side":"SELL","size":"234.99"}],"timestamp":"1785207995988"},"payload_hash":"cead4ad44733780ee883b49f8b416f25db595af39335c1c786573c2ec2931538","raw_frame":"{\"market\":\"0x779291bef19b6709f61e9764a954aafe9ffae488d50ae674aabdcb4f248006d5\", \"price_changes\":[{\"asset_id\":\"14965588658799411272385430903075831224615961675357217884735713260981483529984\", \"price\":\"0.13\", \"size\":\"234.99\", \"side\":\"BUY\", \"hash\":\"9c7b41359412b22d318188123a32a49ffb572d1d\", \"best_bid\":\"0.2\", \"best_ask\":\"0.21\"}, {\"asset_id\":\"8761897749749422724209054078244794145777693856614463256546737399611489089783\", \"price\":\"0.87\", \"size\":\"234.99\", \"side\":\"SELL\", \"hash\":\"5c992987a96ba29b8dc4c493a8a0b8d4a9f7dc32\", \"best_bid\":\"0.79\", \"best_ask\":\"0.8\"}], \"timestamp\":\"1785207995988\", \"event_type\":\"price_change\"}","received_at":"2026-07-28T03:06:36.042482Z","schema_version":"clob-market-ws.price_change.v1","sequence":null,"server_hash":null,"server_timestamp":"1785207995988","session_id":"3e519d9098404c15b234d96025eb1a2b","source":"clob_market_ws"},"received_at":"2026-07-28T03:06:36.042482Z","record_id":"e2ad81a9ebed12fbbea0b643152b4a4c9ae2e4187634877ee39b0a37c4bb8c37","schema_fingerprint":"4aa3821a28b0b7c2400bc59aba4bcc0a76e971dadd19610d3ad38c768e124dc7","schema_version":"edge-lab-recorder.raw.v1","sequence":null,"source":"clob_market_ws"}
{"event_at":"2026-07-28T03:06:35.990000Z","event_fingerprint":"51ab3a22c25f592cf3a27497d4c608bcff6d48e153a941458a97d1cdeba7fbec","payload":{"connection_id":"a6b55582af5f430fb37ad02bf0922475","event_at":"2026-07-28T03:06:35.990000Z","event_type":"price_change","frame_hash":"d728180a118264c7485e45327a32220044eded8cfb7a5c3a3589d76d5d5c7810","frame_index":0,"kind":"data","monotonic_ns":309979077129125,"payload":{"event_type":"price_change","market":"0x779291bef19b6709f61e9764a954aafe9ffae488d50ae674aabdcb4f248006d5","price_changes":[{"asset_id":"14965588658799411272385430903075831224615961675357217884735713260981483529984","best_ask":"0.21","best_bid":"0.2","hash":"ef5dd60b5cbb006d79b03c3845bf611bb9018b10","price":"0.08","side":"BUY","size":"947.79"},{"asset_id":"8761897749749422724209054078244794145777693856614463256546737399611489089783","best_ask":"0.8","best_bid":"0.79","hash":"0d6437e135e127f9ea681b54479efb431dc0299e","price":"0.92","side":"SELL","size":"947.79"}],"timestamp":"1785207995990"},"payload_hash":"e4900584f2e8c69facbc8e9b18db7deb1295fb2fdbee63608cb877114c9dd9e9","raw_frame":"{\"market\":\"0x779291bef19b6709f61e9764a954aafe9ffae488d50ae674aabdcb4f248006d5\", \"price_changes\":[{\"asset_id\":\"14965588658799411272385430903075831224615961675357217884735713260981483529984\", \"price\":\"0.08\", \"size\":\"947.79\", \"side\":\"BUY\", \"hash\":\"ef5dd60b5cbb006d79b03c3845bf611bb9018b10\", \"best_bid\":\"0.2\", \"best_ask\":\"0.21\"}, {\"asset_id\":\"8761897749749422724209054078244794145777693856614463256546737399611489089783\", \"price\":\"0.92\", \"size\":\"947.79\", \"side\":\"SELL\", \"hash\":\"0d6437e135e127f9ea681b54479efb431dc0299e\", \"best_bid\":\"0.79\", \"best_ask\":\"0.8\"}], \"timestamp\":\"1785207995990\", \"event_type\":\"price_change\"}","received_at":"2026-07-28T03:06:36.045590Z","schema_version":"clob-market-ws.price_change.v1","sequence":null,"server_hash":null,"server_timestamp":"1785207995990","session_id":"3e519d9098404c15b234d96025eb1a2b","source":"clob_market_ws"},"received_at":"2026-07-28T03:06:36.045590Z","record_id":"f229005ecb0fc712762b5956dfec150e9efd71a82cbddb2b4414fe36c247a4fb","schema_fingerprint":"4aa3821a28b0b7c2400bc59aba4bcc0a76e971dadd19610d3ad38c768e124dc7","schema_version":"edge-lab-recorder.raw.v1","sequence":null,"source":"clob_market_ws"}
{"event_at":"2026-07-28T03:06:35.996000Z","event_fingerprint":"679e6f10f856666fe37773e8860e94b08627bea8cdc0aedd6e7bf26999d36e77","payload":{"connection_id":"a6b55582af5f430fb37ad02bf0922475","event_at":"2026-07-28T03:06:35.996000Z","event_type":"price_change","frame_hash":"1e99af0b33c6dc03e83a1f5099d05e582536383746061680a987ca2d6060b08e","frame_index":0,"kind":"data","monotonic_ns":309979080186166,"payload":{"event_type":"price_change","market":"0x779291bef19b6709f61e9764a954aafe9ffae488d50ae674aabdcb4f248006d5","price_changes":[{"asset_id":"8761897749749422724209054078244794145777693856614463256546737399611489089783","best_ask":"0.8","best_bid":"0.79","hash":"c44baf7c0994ce07a5831196cbb7ea5188dc226e","price":"0.78","side":"BUY","size":"121.69"},{"asset_id":"14965588658799411272385430903075831224615961675357217884735713260981483529984","best_ask":"0.21","best_bid":"0.2","hash":"f17219a5e586a9e9bcaae01054247c072a598e9a","price":"0.22","side":"SELL","size":"121.69"}],"timestamp":"1785207995996"},"payload_hash":"8615cb0bc756a5d7e1a19c1778fb827806d7371dfc1a9e041d8dc238462a1cc1","raw_frame":"{\"market\":\"0x779291bef19b6709f61e9764a954aafe9ffae488d50ae674aabdcb4f248006d5\", \"price_changes\":[{\"asset_id\":\"8761897749749422724209054078244794145777693856614463256546737399611489089783\", \"price\":\"0.78\", \"size\":\"121.69\", \"side\":\"BUY\", \"hash\":\"c44baf7c0994ce07a5831196cbb7ea5188dc226e\", \"best_bid\":\"0.79\", \"best_ask\":\"0.8\"}, {\"asset_id\":\"14965588658799411272385430903075831224615961675357217884735713260981483529984\", \"price\":\"0.22\", \"size\":\"121.69\", \"side\":\"SELL\", \"hash\":\"f17219a5e586a9e9bcaae01054247c072a598e9a\", \"best_bid\":\"0.2\", \"best_ask\":\"0.21\"}], \"timestamp\":\"1785207995996\", \"event_type\":\"price_change\"}","received_at":"2026-07-28T03:06:36.048648Z","schema_version":"clob-market-ws.price_change.v1","sequence":null,"server_hash":null,"server_timestamp":"1785207995996","session_id":"3e519d9098404c15b234d96025eb1a2b","source":"clob_market_ws"},"received_at":"2026-07-28T03:06:36.048648Z","record_id":"3b9b96793ab97234a7d2a517840a3b9dc13c9be9928c55d4ed8813113a7dd5ed","schema_fingerprint":"4aa3821a28b0b7c2400bc59aba4bcc0a76e971dadd19610d3ad38c768e124dc7","schema_version":"edge-lab-recorder.raw.v1","sequence":null,"source":"clob_market_ws"}
{"event_at":"2026-07-28T03:06:35.997000Z","event_fingerprint":"c69e84b8aa60ffcdb77b68c8170403ef3e7dbcf98081559010100e4e12798751","payload":{"connection_id":"a6b55582af5f430fb37ad02bf0922475","event_at":"2026-07-28T03:06:35.997000Z","event_type":"price_change","frame_hash":"8305825e80131e077ca6fae89892f35d70e23e61e55c902ab01f7ae452f33461","frame_index":0,"kind":"data","monotonic_ns":309979083128541,"payload":{"event_type":"price_change","market":"0x779291bef19b6709f61e9764a954aafe9ffae488d50ae674aabdcb4f248006d5","price_changes":[{"asset_id":"14965588658799411272385430903075831224615961675357217884735713260981483529984","best_ask":"0.21","best_bid":"0.2","hash":"12bf21332f7262757f870fc7ce50c2fa0d686437","price":"0.07","side":"BUY","size":"1089.48"},{"asset_id":"8761897749749422724209054078244794145777693856614463256546737399611489089783","best_ask":"0.8","best_bid":"0.79","hash":"5d63401e8cc595fbbd2bb115ee131cdb002eb5c7","price":"0.93","side":"SELL","size":"1089.48"}],"timestamp":"1785207995997"},"payload_hash":"b096339e96ec56fb7784a2f7ebcb679405d464a5923bd38a32c19cf6f0d78031","raw_frame":"{\"market\":\"0x779291bef19b6709f61e9764a954aafe9ffae488d50ae674aabdcb4f248006d5\", \"price_changes\":[{\"asset_id\":\"14965588658799411272385430903075831224615961675357217884735713260981483529984\", \"price\":\"0.07\", \"size\":\"1089.48\", \"side\":\"BUY\", \"hash\":\"12bf21332f7262757f870fc7ce50c2fa0d686437\", \"best_bid\":\"0.2\", \"best_ask\":\"0.21\"}, {\"asset_id\":\"8761897749749422724209054078244794145777693856614463256546737399611489089783\", \"price\":\"0.93\", \"size\":\"1089.48\", \"side\":\"SELL\", \"hash\":\"5d63401e8cc595fbbd2bb115ee131cdb002eb5c7\", \"best_bid\":\"0.79\", \"best_ask\":\"0.8\"}], \"timestamp\":\"1785207995997\", \"event_type\":\"price_change\"}","received_at":"2026-07-28T03:06:36.051590Z","schema_version":"clob-market-ws.price_change.v1","sequence":null,"server_hash":null,"server_timestamp":"1785207995997","session_id":"3e519d9098404c15b234d96025eb1a2b","source":"clob_market_ws"},"received_at":"2026-07-28T03:06:36.051590Z","record_id":"1f51378411909c5a1464282964919f6fe469d07e79828ab7f680db42b1a796c4","schema_fingerprint":"4aa3821a28b0b7c2400bc59aba4bcc0a76e971dadd19610d3ad38c768e124dc7","schema_version":"edge-lab-recorder.raw.v1","sequence":null,"source":"clob_market_ws"}
{"event_at":"2026-07-28T03:06:35.997000Z","event_fingerprint":"cc3e47b98e92c1ff709a69155836840543769ff0a53d0133ac2b30ed2f9242ac","payload":{"connection_id":"a6b55582af5f430fb37ad02bf0922475","event_at":"2026-07-28T03:06:35.997000Z","event_type":"price_change","frame_hash":"6ba4a469547eb2778507eb2fb95766ac20ba0802661485ef0d2558f80f2c3921","frame_index":0,"kind":"data","monotonic_ns":309979086590541,"payload":{"event_type":"price_change","market":"0x779291bef19b6709f61e9764a954aafe9ffae488d50ae674aabdcb4f248006d5","price_changes":[{"asset_id":"8761897749749422724209054078244794145777693856614463256546737399611489089783","best_ask":"0.8","best_bid":"0.79","hash":"0505e824d9686739f270741679b1d5daa7f8626d","price":"0.79","side":"BUY","size":"72.16"},{"asset_id":"14965588658799411272385430903075831224615961675357217884735713260981483529984","best_ask":"0.21","best_bid":"0.2","hash":"01a45c0f0141a9aa524d0b34665dc12e75b44cf8","price":"0.21","side":"SELL","size":"72.16"}],"timestamp":"1785207995997"},"payload_hash":"1f672d37671897d4881875cd8701f0eb4b0d7ead1f927cc7c7e56d6dc86142cd","raw_frame":"{\"market\":\"0x779291bef19b6709f61e9764a954aafe9ffae488d50ae674aabdcb4f248006d5\", \"price_changes\":[{\"asset_id\":\"8761897749749422724209054078244794145777693856614463256546737399611489089783\", \"price\":\"0.79\", \"size\":\"72.16\", \"side\":\"BUY\", \"hash\":\"0505e824d9686739f270741679b1d5daa7f8626d\", \"best_bid\":\"0.79\", \"best_ask\":\"0.8\"}, {\"asset_id\":\"14965588658799411272385430903075831224615961675357217884735713260981483529984\", \"price\":\"0.21\", \"size\":\"72.16\", \"side\":\"SELL\", \"hash\":\"01a45c0f0141a9aa524d0b34665dc12e75b44cf8\", \"best_bid\":\"0.2\", \"best_ask\":\"0.21\"}], \"timestamp\":\"1785207995997\", \"event_type\":\"price_change\"}","received_at":"2026-07-28T03:06:36.055053Z","schema_version":"clob-market-ws.price_change.v1","sequence":null,"server_hash":null,"server_timestamp":"1785207995997","session_id":"3e519d9098404c15b234d96025eb1a2b","source":"clob_market_ws"},"received_at":"2026-07-28T03:06:36.055053Z","record_id":"51c317ca09a95709a2fa302c97a92d98872b6aa484b9c7f94517f0eb5d0264d9","schema_fingerprint":"4aa3821a28b0b7c2400bc59aba4bcc0a76e971dadd19610d3ad38c768e124dc7","schema_version":"edge-lab-recorder.raw.v1","sequence":null,"source":"clob_market_ws"}
{"event_at":"2026-07-28T03:06:35.998000Z","event_fingerprint":"e936cb6b478f78707b41e67d9adf6cacf6d840278ece637e9e0fb482e0841164","payload":{"connection_id":"a6b55582af5f430fb37ad02bf0922475","event_at":"2026-07-28T03:06:35.998000Z","event_type":"price_change","frame_hash":"d5aaf9bf43d8e34b052db70acdf47d4998ba8c56669a41277088c9e05afa0905","frame_index":0,"kind":"data","monotonic_ns":309979089600583,"payload":{"event_type":"price_change","market":"0x779291bef19b6709f61e9764a954aafe9ffae488d50ae674aabdcb4f248006d5","price_changes":[{"asset_id":"8761897749749422724209054078244794145777693856614463256546737399611489089783","best_ask":"0.8","best_bid":"0.79","hash":"bdeeb83aa1c1081f429c89bab83652eb9d886e97","price":"0.77","side":"BUY","size":"166.03"},{"asset_id":"14965588658799411272385430903075831224615961675357217884735713260981483529984","best_ask":"0.21","best_bid":"0.2","hash":"6e7c30374f54d641eee25b9282f73b792adfb10f","price":"0.23","side":"SELL","size":"166.03"}],"timestamp":"1785207995998"},"payload_hash":"f083db5b971270b64c4fb2a95040d41a8166d523f7eb2b30d7e0f8657befa80e","raw_frame":"{\"market\":\"0x779291bef19b6709f61e9764a954aafe9ffae488d50ae674aabdcb4f248006d5\", \"price_changes\":[{\"asset_id\":\"8761897749749422724209054078244794145777693856614463256546737399611489089783\", \"price\":\"0.77\", \"size\":\"166.03\", \"side\":\"BUY\", \"hash\":\"bdeeb83aa1c1081f429c89bab83652eb9d886e97\", \"best_bid\":\"0.79\", \"best_ask\":\"0.8\"}, {\"asset_id\":\"14965588658799411272385430903075831224615961675357217884735713260981483529984\", \"price\":\"0.23\", \"size\":\"166.03\", \"side\":\"SELL\", \"hash\":\"6e7c30374f54d641eee25b9282f73b792adfb10f\", \"best_bid\":\"0.2\", \"best_ask\":\"0.21\"}], \"timestamp\":\"1785207995998\", \"event_type\":\"price_change\"}","received_at":"2026-07-28T03:06:36.058062Z","schema_version":"clob-market-ws.price_change.v1","sequence":null,"server_hash":null,"server_timestamp":"1785207995998","session_id":"3e519d9098404c15b234d96025eb1a2b","source":"clob_market_ws"},"received_at":"2026-07-28T03:06:36.058062Z","record_id":"4e5cce9ef3f177aaa4531bee708747bfccfe7cffaa84fedbb99b5feb34d4e732","schema_fingerprint":"4aa3821a28b0b7c2400bc59aba4bcc0a76e971dadd19610d3ad38c768e124dc7","schema_version":"edge-lab-recorder.raw.v1","sequence":null,"source":"clob_market_ws"}
{"event_at":"2026-07-28T03:06:35.999000Z","event_fingerprint":"9847f36e7f5e559660841e6a9a0e07c05ca92a288f16fae9e7702529bcffee08","payload":{"connection_id":"a6b55582af5f430fb37ad02bf0922475","event_at":"2026-07-28T03:06:35.999000Z","event_type":"price_change","frame_hash":"fdd73d488456bfcf7427fb3a30175dd259ad9751bab1b7f22df5ae3eeb3d3912","frame_index":0,"kind":"data","monotonic_ns":309979092658125,"payload":{"event_type":"price_change","market":"0x779291bef19b6709f61e9764a954aafe9ffae488d50ae674aabdcb4f248006d5","price_changes":[{"asset_id":"14965588658799411272385430903075831224615961675357217884735713260981483529984","best_ask":"0.21","best_bid":"0.2","hash":"9b54846c12bf5b912545f55f5f266045d4a787fa","price":"0.05","side":"BUY","size":"1239.8"},{"asset_id":"8761897749749422724209054078244794145777693856614463256546737399611489089783","best_ask":"0.8","best_bid":"0.79","hash":"b73a3634b8aff4fcf13bf07cccf17014a3b76591","price":"0.95","side":"SELL","size":"1239.8"}],"timestamp":"1785207995999"},"payload_hash":"3c37ad08b7a87797c68eba99a282f4a0545a83a95d2b170ce8565caba10781e4","raw_frame":"{\"market\":\"0x779291bef19b6709f61e9764a954aafe9ffae488d50ae674aabdcb4f248006d5\", \"price_changes\":[{\"asset_id\":\"14965588658799411272385430903075831224615961675357217884735713260981483529984\", \"price\":\"0.05\", \"size\":\"1239.8\", \"side\":\"BUY\", \"hash\":\"9b54846c12bf5b912545f55f5f266045d4a787fa\", \"best_bid\":\"0.2\", \"best_ask\":\"0.21\"}, {\"asset_id\":\"8761897749749422724209054078244794145777693856614463256546737399611489089783\", \"price\":\"0.95\", \"size\":\"1239.8\", \"side\":\"SELL\", \"hash\":\"b73a3634b8aff4fcf13bf07cccf17014a3b76591\", \"best_bid\":\"0.79\", \"best_ask\":\"0.8\"}], \"timestamp\":\"1785207995999\", \"event_type\":\"price_change\"}","received_at":"2026-07-28T03:06:36.061117Z","schema_version":"clob-market-ws.price_change.v1","sequence":null,"server_hash":null,"server_timestamp":"1785207995999","session_id":"3e519d9098404c15b234d96025eb1a2b","source":"clob_market_ws"},"received_at":"2026-07-28T03:06:36.061117Z","record_id":"a27d95c510f234e510da56875c68307e22eac1ee5d4c30d4bd55a79ea30b1b51","schema_fingerprint":"4aa3821a28b0b7c2400bc59aba4bcc0a76e971dadd19610d3ad38c768e124dc7","schema_version":"edge-lab-recorder.raw.v1","sequence":null,"source":"clob_market_ws"}
{"event_at":"2026-07-28T03:06:36.000000Z","event_fingerprint":"dceac5d0cdf1e6aca46fb5d1b13c8432af4305286fe021244049f5744626567a","payload":{"connection_id":"a6b55582af5f430fb37ad02bf0922475","event_at":"2026-07-28T03:06:36.000000Z","event_type":"price_change","frame_hash":"73ebbc90413514be7d1be657b6168c39f742d1c6e5edb97bd96b02a54879ba6b","frame_index":0,"kind":"data","monotonic_ns":309979095704125,"payload":{"event_type":"price_change","market":"0x779291bef19b6709f61e9764a954aafe9ffae488d50ae674aabdcb4f248006d5","price_changes":[{"asset_id":"14965588658799411272385430903075831224615961675357217884735713260981483529984","best_ask":"0.21","best_bid":"0.2","hash":"af4ace2c9c80648799e4fff1c984cbd8e7c9b27f","price":"0.06","side":"BUY","size":"1891.71"},{"asset_id":"8761897749749422724209054078244794145777693856614463256546737399611489089783","best_ask":"0.8","best_bid":"0.79","hash":"4b71c2d44076cdbc928286a39928dc0171bd65d2","price":"0.94","side":"SELL","size":"1891.71"}],"timestamp":"1785207996000"},"payload_hash":"98f65640fb439339c9ec47211717c2848c65d26f217980c18b0f40759e57ec24","raw_frame":"{\"market\":\"0x779291bef19b6709f61e9764a954aafe9ffae488d50ae674aabdcb4f248006d5\", \"price_changes\":[{\"asset_id\":\"14965588658799411272385430903075831224615961675357217884735713260981483529984\", \"price\":\"0.06\", \"size\":\"1891.71\", \"side\":\"BUY\", \"hash\":\"af4ace2c9c80648799e4fff1c984cbd8e7c9b27f\", \"best_bid\":\"0.2\", \"best_ask\":\"0.21\"}, {\"asset_id\":\"8761897749749422724209054078244794145777693856614463256546737399611489089783\", \"price\":\"0.94\", \"size\":\"1891.71\", \"side\":\"SELL\", \"hash\":\"4b71c2d44076cdbc928286a39928dc0171bd65d2\", \"best_bid\":\"0.79\", \"best_ask\":\"0.8\"}], \"timestamp\":\"1785207996000\", \"event_type\":\"price_change\"}","received_at":"2026-07-28T03:06:36.064165Z","schema_version":"clob-market-ws.price_change.v1","sequence":null,"server_hash":null,"server_timestamp":"1785207996000","session_id":"3e519d9098404c15b234d96025eb1a2b","source":"clob_market_ws"},"received_at":"2026-07-28T03:06:36.064165Z","record_id":"d107968286731c02c731a3c947f17bbfde570778be75ec824f1e0a1e7e203337","schema_fingerprint":"4aa3821a28b0b7c2400bc59aba4bcc0a76e971dadd19610d3ad38c768e124dc7","schema_version":"edge-lab-recorder.raw.v1","sequence":null,"source":"clob_market_ws"}
{"event_at":"2026-07-28T03:06:36.006000Z","event_fingerprint":"01c37975af548ceb8450e97e7d4db075174b6b8065d0807cd083e0ffb5431087","payload":{"connection_id":"a6b55582af5f430fb37ad02bf0922475","event_at":"2026-07-28T03:06:36.006000Z","event_type":"price_change","frame_hash":"ccdc15dd878ddc1559f0a81237f8749dddd6dc14d7ab7b17f0ee7d67f4204250","frame_index":0,"kind":"data","monotonic_ns":309979098686500,"payload":{"event_type":"price_change","market":"0x779291bef19b6709f61e9764a954aafe9ffae488d50ae674aabdcb4f248006d5","price_changes":[{"asset_id":"8761897749749422724209054078244794145777693856614463256546737399611489089783","best_ask":"0.8","best_bid":"0.79","hash":"32470dcee4607d045fe341c17542f8d07ca0bcd4","price":"0.65","side":"BUY","size":"148.2"},{"asset_id":"14965588658799411272385430903075831224615961675357217884735713260981483529984","best_ask":"0.21","best_bid":"0.2","hash":"518764ba8185631cbbb8d2dc5815a3fe05b2dfe3","price":"0.35","side":"SELL","size":"148.2"}],"timestamp":"1785207996006"},"payload_hash":"7db3810ca4a321812454c59cf1fbcf4393be73a95039be9c25fab3f3017b987f","raw_frame":"{\"market\":\"0x779291bef19b6709f61e9764a954aafe9ffae488d50ae674aabdcb4f248006d5\", \"price_changes\":[{\"asset_id\":\"8761897749749422724209054078244794145777693856614463256546737399611489089783\", \"price\":\"0.65\", \"size\":\"148.2\", \"side\":\"BUY\", \"hash\":\"32470dcee4607d045fe341c17542f8d07ca0bcd4\", \"best_bid\":\"0.79\", \"best_ask\":\"0.8\"}, {\"asset_id\":\"14965588658799411272385430903075831224615961675357217884735713260981483529984\", \"price\":\"0.35\", \"size\":\"148.2\", \"side\":\"SELL\", \"hash\":\"518764ba8185631cbbb8d2dc5815a3fe05b2dfe3\", \"best_bid\":\"0.2\", \"best_ask\":\"0.21\"}], \"timestamp\":\"1785207996006\", \"event_type\":\"price_change\"}","received_at":"2026-07-28T03:06:36.067148Z","schema_version":"clob-market-ws.price_change.v1","sequence":null,"server_hash":null,"server_timestamp":"1785207996006","session_id":"3e519d9098404c15b234d96025eb1a2b","source":"clob_market_ws"},"received_at":"2026-07-28T03:06:36.067148Z","record_id":"d8e1851b286b7aea82afe9021d7a6b55921822dd3f066f76518ae5d3c9380544","schema_fingerprint":"4aa3821a28b0b7c2400bc59aba4bcc0a76e971dadd19610d3ad38c768e124dc7","schema_version":"edge-lab-recorder.raw.v1","sequence":null,"source":"clob_market_ws"}
{"event_at":"2026-07-28T03:06:36.009000Z","event_fingerprint":"2d907e24e4d52b74bcf0e5b5dd7a3297dc516dd67e59effc5795d460f69c069f","payload":{"connection_id":"a6b55582af5f430fb37ad02bf0922475","event_at":"2026-07-28T03:06:36.009000Z","event_type":"price_change","frame_hash":"4ab53e891210378e44e01f73aeda366b5b56162b165e1139ad4c8ab5564a4b97","frame_index":0,"kind":"data","monotonic_ns":309979101701541,"payload":{"event_type":"price_change","market":"0x779291bef19b6709f61e9764a954aafe9ffae488d50ae674aabdcb4f248006d5","price_changes":[{"asset_id":"8761897749749422724209054078244794145777693856614463256546737399611489089783","best_ask":"0.8","best_bid":"0.79","hash":"61f1e3feed6f2c9e0bcdaaeedb2c33f4b8bd5eb4","price":"0.78","side":"BUY","size":"97.69"},{"asset_id":"14965588658799411272385430903075831224615961675357217884735713260981483529984","best_ask":"0.21","best_bid":"0.2","hash":"af5db5ab319b259fadc226e1201be02ef779fe9b","price":"0.22","side":"SELL","size":"97.69"}],"timestamp":"1785207996009"},"payload_hash":"0b0111d377cf0dab6a140e3b5d653f0ee177fccb2b9821fc1ad5ec11f0e05d55","raw_frame":"{\"market\":\"0x779291bef19b6709f61e9764a954aafe9ffae488d50ae674aabdcb4f248006d5\", \"price_changes\":[{\"asset_id\":\"8761897749749422724209054078244794145777693856614463256546737399611489089783\", \"price\":\"0.78\", \"size\":\"97.69\", \"side\":\"BUY\", \"hash\":\"61f1e3feed6f2c9e0bcdaaeedb2c33f4b8bd5eb4\", \"best_bid\":\"0.79\", \"best_ask\":\"0.8\"}, {\"asset_id\":\"14965588658799411272385430903075831224615961675357217884735713260981483529984\", \"price\":\"0.22\", \"size\":\"97.69\", \"side\":\"SELL\", \"hash\":\"af5db5ab319b259fadc226e1201be02ef779fe9b\", \"best_bid\":\"0.2\", \"best_ask\":\"0.21\"}], \"timestamp\":\"1785207996009\", \"event_type\":\"price_change\"}","received_at":"2026-07-28T03:06:36.070162Z","schema_version":"clob-market-ws.price_change.v1","sequence":null,"server_hash":null,"server_timestamp":"1785207996009","session_id":"3e519d9098404c15b234d96025eb1a2b","source":"clob_market_ws"},"received_at":"2026-07-28T03:06:36.070162Z","record_id":"f20bc7628b71da7b6885f043088992a070ae7f4f4a27291d0dda21db8999c960","schema_fingerprint":"4aa3821a28b0b7c2400bc59aba4bcc0a76e971dadd19610d3ad38c768e124dc7","schema_version":"edge-lab-recorder.raw.v1","sequence":null,"source":"clob_market_ws"}
{"event_at":"2026-07-28T03:06:36.009000Z","event_fingerprint":"5d8f394287ca5de71dcaf7f9d916fb404848c937191cc17f9a35e2ad68eb26f7","payload":{"connection_id":"a6b55582af5f430fb37ad02bf0922475","event_at":"2026-07-28T03:06:36.009000Z","event_type":"price_change","frame_hash":"366820212e9140fdbbe1b991c489f18f12e798471b40c67bd5670f01d18d4238","frame_index":0,"kind":"data","monotonic_ns":309979104730458,"payload":{"event_type":"price_change","market":"0x779291bef19b6709f61e9764a954aafe9ffae488d50ae674aabdcb4f248006d5","price_changes":[{"asset_id":"14965588658799411272385430903075831224615961675357217884735713260981483529984","best_ask":"0.21","best_bid":"0.2","hash":"1c5ea93ede624671eee80360dd7886522b1d53de","price":"0.14","side":"BUY","size":"188.9"},{"asset_id":"8761897749749422724209054078244794145777693856614463256546737399611489089783","best_ask":"0.8","best_bid":"0.79","hash":"328726eca5732e47ae9d509ae1b56a51400e9487","price":"0.86","side":"SELL","size":"188.9"}],"timestamp":"1785207996009"},"payload_hash":"b05807e9278798c2f818570bbf904fef1ff78a6f5ec8800f890089c040aa4618","raw_frame":"{\"market\":\"0x779291bef19b6709f61e9764a954aafe9ffae488d50ae674aabdcb4f248006d5\", \"price_changes\":[{\"asset_id\":\"14965588658799411272385430903075831224615961675357217884735713260981483529984\", \"price\":\"0.14\", \"size\":\"188.9\", \"side\":\"BUY\", \"hash\":\"1c5ea93ede624671eee80360dd7886522b1d53de\", \"best_bid\":\"0.2\", \"best_ask\":\"0.21\"}, {\"asset_id\":\"8761897749749422724209054078244794145777693856614463256546737399611489089783\", \"price\":\"0.86\", \"size\":\"188.9\", \"side\":\"SELL\", \"hash\":\"328726eca5732e47ae9d509ae1b56a51400e9487\", \"best_bid\":\"0.79\", \"best_ask\":\"0.8\"}], \"timestamp\":\"1785207996009\", \"event_type\":\"price_change\"}","received_at":"2026-07-28T03:06:36.073192Z","schema_version":"clob-market-ws.price_change.v1","sequence":null,"server_hash":null,"server_timestamp":"1785207996009","session_id":"3e519d9098404c15b234d96025eb1a2b","source":"clob_market_ws"},"received_at":"2026-07-28T03:06:36.073192Z","record_id":"5df72540ea48e0ccfe6673b8289cbbe70ea176d7c8af1b03c701eeefad00e8f3","schema_fingerprint":"4aa3821a28b0b7c2400bc59aba4bcc0a76e971dadd19610d3ad38c768e124dc7","schema_version":"edge-lab-recorder.raw.v1","sequence":null,"source":"clob_market_ws"}
{"event_at":"2026-07-28T03:06:36.010000Z","event_fingerprint":"751b9108becb245a045e9d30fbf04f4face36124ad6093a55615167ea2b05b5f","payload":{"connection_id":"a6b55582af5f430fb37ad02bf0922475","event_at":"2026-07-28T03:06:36.010000Z","event_type":"price_change","frame_hash":"1d662629d07c8c670c7c376cf6f0c5685f046e6a40be6015dac416b115692a03","frame_index":0,"kind":"data","monotonic_ns":309979107686500,"payload":{"event_type":"price_change","market":"0x779291bef19b6709f61e9764a954aafe9ffae488d50ae674aabdcb4f248006d5","price_changes":[{"asset_id":"14965588658799411272385430903075831224615961675357217884735713260981483529984","best_ask":"0.21","best_bid":"0.2","hash":"c85795bb665e843a4404d0796b3e436e27890074","price":"0.18","side":"BUY","size":"63.6"},{"asset_id":"8761897749749422724209054078244794145777693856614463256546737399611489089783","best_ask":"0.8","best_bid":"0.79","hash":"fae82c43dfe16f846a038bafc327f0febbbd1c7d","price":"0.82","side":"SELL","size":"63.6"}],"timestamp":"1785207996010"},"payload_hash":"e80456ab369014afb61f7de9343c6e35578f1c6c25f7cf6f80db122dd316efb3","raw_frame":"{\"market\":\"0x779291bef19b6709f61e9764a954aafe9ffae488d50ae674aabdcb4f248006d5\", \"price_changes\":[{\"asset_id\":\"14965588658799411272385430903075831224615961675357217884735713260981483529984\", \"price\":\"0.18\", \"size\":\"63.6\", \"side\":\"BUY\", \"hash\":\"c85795bb665e843a4404d0796b3e436e27890074\", \"best_bid\":\"0.2\", \"best_ask\":\"0.21\"}, {\"asset_id\":\"8761897749749422724209054078244794145777693856614463256546737399611489089783\", \"price\":\"0.82\", \"size\":\"63.6\", \"side\":\"SELL\", \"hash\":\"fae82c43dfe16f846a038bafc327f0febbbd1c7d\", \"best_bid\":\"0.79\", \"best_ask\":\"0.8\"}], \"timestamp\":\"1785207996010\", \"event_type\":\"price_change\"}","received_at":"2026-07-28T03:06:36.076148Z","schema_version":"clob-market-ws.price_change.v1","sequence":null,"server_hash":null,"server_timestamp":"1785207996010","session_id":"3e519d9098404c15b234d96025eb1a2b","source":"clob_market_ws"},"received_at":"2026-07-28T03:06:36.076148Z","record_id":"995bfc561c51e0f0e8290c29d1d024fd26d2b6b5b5e4f5c9b36cdb53b8151c66","schema_fingerprint":"4aa3821a28b0b7c2400bc59aba4bcc0a76e971dadd19610d3ad38c768e124dc7","schema_version":"edge-lab-recorder.raw.v1","sequence":null,"source":"clob_market_ws"}
{"event_at":"2026-07-28T03:06:36.011000Z","event_fingerprint":"b604152405ad1064d18a76214e5b38c526ebc47e5ee285cc0db3a43768d69975","payload":{"connection_id":"a6b55582af5f430fb37ad02bf0922475","event_at":"2026-07-28T03:06:36.011000Z","event_type":"price_change","frame_hash":"c33b0801bd80bdfdc80baea1017e78450c9b7728d6b4a16ddb451f7ba51d85da","frame_index":0,"kind":"data","monotonic_ns":309979110638291,"payload":{"event_type":"price_change","market":"0x779291bef19b6709f61e9764a954aafe9ffae488d50ae674aabdcb4f248006d5","price_changes":[{"asset_id":"14965588658799411272385430903075831224615961675357217884735713260981483529984","best_ask":"0.21","best_bid":"0.2","hash":"028ada260c6e8868c1b0055eccdb603b990a347f","price":"0.23","side":"SELL","size":"161.03"},{"asset_id":"8761897749749422724209054078244794145777693856614463256546737399611489089783","best_ask":"0.8","best_bid":"0.79","hash":"bfa387bffd6b25e02afcb118d5533cb18c78d6cc","price":"0.77","side":"BUY","size":"161.03"}],"timestamp":"1785207996011"},"payload_hash":"b2d540c51085292cd6742cca9b7ef91109733f8779e83b1eca26572ddf6de54c","raw_frame":"{\"market\":\"0x779291bef19b6709f61e9764a954aafe9ffae488d50ae674aabdcb4f248006d5\", \"price_changes\":[{\"asset_id\":\"14965588658799411272385430903075831224615961675357217884735713260981483529984\", \"price\":\"0.23\", \"size\":\"161.03\", \"side\":\"SELL\", \"hash\":\"028ada260c6e8868c1b0055eccdb603b990a347f\", \"best_bid\":\"0.2\", \"best_ask\":\"0.21\"}, {\"asset_id\":\"8761897749749422724209054078244794145777693856614463256546737399611489089783\", \"price\":\"0.77\", \"size\":\"161.03\", \"side\":\"BUY\", \"hash\":\"bfa387bffd6b25e02afcb118d5533cb18c78d6cc\", \"best_bid\":\"0.79\", \"best_ask\":\"0.8\"}], \"timestamp\":\"1785207996011\", \"event_type\":\"price_change\"}","received_at":"2026-07-28T03:06:36.079101Z","schema_version":"clob-market-ws.price_change.v1","sequence":null,"server_hash":null,"server_timestamp":"1785207996011","session_id":"3e519d9098404c15b234d96025eb1a2b","source":"clob_market_ws"},"received_at":"2026-07-28T03:06:36.079101Z","record_id":"16eb005aaf0a2686cfd6dd164d404432455a302a2fd39db8b32fb42c5496c9e3","schema_fingerprint":"4aa3821a28b0b7c2400bc59aba4bcc0a76e971dadd19610d3ad38c768e124dc7","schema_version":"edge-lab-recorder.raw.v1","sequence":null,"source":"clob_market_ws"}
{"event_at":"2026-07-28T03:06:36.011000Z","event_fingerprint":"93032692bd7ad10d002d3531196d64e3f8629d013b30bd5275a1631cbf177589","payload":{"connection_id":"a6b55582af5f430fb37ad02bf0922475","event_at":"2026-07-28T03:06:36.011000Z","event_type":"price_change","frame_hash":"8bb01728fc18d03e23f31708946f210dddb138a04bf1f2c13dba6a83e66a75e4","frame_index":0,"kind":"data","monotonic_ns":309979113295625,"payload":{"event_type":"price_change","market":"0x779291bef19b6709f61e9764a954aafe9ffae488d50ae674aabdcb4f248006d5","price_changes":[{"asset_id":"8761897749749422724209054078244794145777693856614463256546737399611489089783","best_ask":"0.8","best_bid":"0.79","hash":"3e32e3a740b891ab63bd2eae43ebcfc1b38cf4f8","price":"0.77","side":"BUY","size":"136.03"},{"asset_id":"14965588658799411272385430903075831224615961675357217884735713260981483529984","best_ask":"0.21","best_bid":"0.2","hash":"08dab6cee4f0ba4bba3950c4889b274b5688e0c9","price":"0.23","side":"SELL","size":"136.03"}],"timestamp":"1785207996011"},"payload_hash":"9f942c644ea16c153eff90945867b17050bceed7f9836913197f15c0ee6448d5","raw_frame":"{\"market\":\"0x779291bef19b6709f61e9764a954aafe9ffae488d50ae674aabdcb4f248006d5\", \"price_changes\":[{\"asset_id\":\"8761897749749422724209054078244794145777693856614463256546737399611489089783\", \"price\":\"0.77\", \"size\":\"136.03\", \"side\":\"BUY\", \"hash\":\"3e32e3a740b891ab63bd2eae43ebcfc1b38cf4f8\", \"best_bid\":\"0.79\", \"best_ask\":\"0.8\"}, {\"asset_id\":\"14965588658799411272385430903075831224615961675357217884735713260981483529984\", \"price\":\"0.23\", \"size\":\"136.03\", \"side\":\"SELL\", \"hash\":\"08dab6cee4f0ba4bba3950c4889b274b5688e0c9\", \"best_bid\":\"0.2\", \"best_ask\":\"0.21\"}], \"timestamp\":\"1785207996011\", \"event_type\":\"price_change\"}","received_at":"2026-07-28T03:06:36.081757Z","schema_version":"clob-market-ws.price_change.v1","sequence":null,"server_hash":null,"server_timestamp":"1785207996011","session_id":"3e519d9098404c15b234d96025eb1a2b","source":"clob_market_ws"},"received_at":"2026-07-28T03:06:36.081757Z","record_id":"6401f667a7ae67c4d3b2840a48871ba42fbb7f1fc0d96dde17e2c78329e22b92","schema_fingerprint":"4aa3821a28b0b7c2400bc59aba4bcc0a76e971dadd19610d3ad38c768e124dc7","schema_version":"edge-lab-recorder.raw.v1","sequence":null,"source":"clob_market_ws"}
{"event_at":"2026-07-28T03:06:36.011000Z","event_fingerprint":"a75f145291ebe9a4171a18794d3876dc7bb8711e975fcd2f8fc44cce793f91ff","payload":{"connection_id":"a6b55582af5f430fb37ad02bf0922475","event_at":"2026-07-28T03:06:36.011000Z","event_type":"price_change","frame_hash":"c0e434612c7296bb4c95a954340881a9761126ffe0fffa71a68a82e26693f9db","frame_index":0,"kind":"data","monotonic_ns":309979116397583,"payload":{"event_type":"price_change","market":"0x779291bef19b6709f61e9764a954aafe9ffae488d50ae674aabdcb4f248006d5","price_changes":[{"asset_id":"14965588658799411272385430903075831224615961675357217884735713260981483529984","best_ask":"0.21","best_bid":"0.2","hash":"1092e7a48f1ae6333ea81c445d92d81ec30b8070","price":"0.18","side":"BUY","size":"55.6"},{"asset_id":"8761897749749422724209054078244794145777693856614463256546737399611489089783","best_ask":"0.8","best_bid":"0.79","hash":"9794122e31e10f1293ab28cf9d6d72c306f86a70","price":"0.82","side":"SELL","size":"55.6"}],"timestamp":"1785207996011"},"payload_hash":"34d8ffc223b8ce6348eb21b243548273afe02860ba2b131a5c2e7104b8b29f44","raw_frame":"{\"market\":\"0x779291bef19b6709f61e9764a954aafe9ffae488d50ae674aabdcb4f248006d5\", \"price_changes\":[{\"asset_id\":\"14965588658799411272385430903075831224615961675357217884735713260981483529984\", \"price\":\"0.18\", \"size\":\"55.6\", \"side\":\"BUY\", \"hash\":\"1092e7a48f1ae6333ea81c445d92d81ec30b8070\", \"best_bid\":\"0.2\", \"best_ask\":\"0.21\"}, {\"asset_id\":\"8761897749749422724209054078244794145777693856614463256546737399611489089783\", \"price\":\"0.82\", \"size\":\"55.6\", \"side\":\"SELL\", \"hash\":\"9794122e31e10f1293ab28cf9d6d72c306f86a70\", \"best_bid\":\"0.79\", \"best_ask\":\"0.8\"}], \"timestamp\":\"1785207996011\", \"event_type\":\"price_change\"}","received_at":"2026-07-28T03:06:36.084859Z","schema_version":"clob-market-ws.price_change.v1","sequence":null,"server_hash":null,"server_timestamp":"1785207996011","session_id":"3e519d9098404c15b234d96025eb1a2b","source":"clob_market_ws"},"received_at":"2026-07-28T03:06:36.084859Z","record_id":"ee8a813123af85d52d293d5033e6dadff29cf260131a08a260a3da8316338ee4","schema_fingerprint":"4aa3821a28b0b7c2400bc59aba4bcc0a76e971dadd19610d3ad38c768e124dc7","schema_version":"edge-lab-recorder.raw.v1","sequence":null,"source":"clob_market_ws"}
{"event_at":"2026-07-28T03:06:36.011000Z","event_fingerprint":"ef4e29ad2f92a340be01f370f7711ea97b71ca60b6eff0a99380852fcfe0baa3","payload":{"connection_id":"a6b55582af5f430fb37ad02bf0922475","event_at":"2026-07-28T03:06:36.011000Z","event_type":"price_change","frame_hash":"f89bf065a368a96478817b8cc99d2d3acb257cb261252c054e42701f916629ee","frame_index":0,"kind":"data","monotonic_ns":309979119373000,"payload":{"event_type":"price_change","market":"0x779291bef19b6709f61e9764a954aafe9ffae488d50ae674aabdcb4f248006d5","price_changes":[{"asset_id":"14965588658799411272385430903075831224615961675357217884735713260981483529984","best_ask":"0.21","best_bid":"0.2","hash":"0eb3bb4463c7a439d3e66a0aa1c78d324c2f6a51","price":"0.16","side":"BUY","size":"122.3"},{"asset_id":"8761897749749422724209054078244794145777693856614463256546737399611489089783","best_ask":"0.8","best_bid":"0.79","hash":"58f4e6e1dc6b9e2b80cd8d6648b27d7a0ffda420","price":"0.84","side":"SELL","size":"122.3"}],"timestamp":"1785207996011"},"payload_hash":"31f31bf56ef016558f585038b0e1d4448a3ddb2e5c4ebe348a755ff603ae0e85","raw_frame":"{\"market\":\"0x779291bef19b6709f61e9764a954aafe9ffae488d50ae674aabdcb4f248006d5\", \"price_changes\":[{\"asset_id\":\"14965588658799411272385430903075831224615961675357217884735713260981483529984\", \"price\":\"0.16\", \"size\":\"122.3\", \"side\":\"BUY\", \"hash\":\"0eb3bb4463c7a439d3e66a0aa1c78d324c2f6a51\", \"best_bid\":\"0.2\", \"best_ask\":\"0.21\"}, {\"asset_id\":\"8761897749749422724209054078244794145777693856614463256546737399611489089783\", \"price\":\"0.84\", \"size\":\"122.3\", \"side\":\"SELL\", \"hash\":\"58f4e6e1dc6b9e2b80cd8d6648b27d7a0ffda420\", \"best_bid\":\"0.79\", \"best_ask\":\"0.8\"}], \"timestamp\":\"1785207996011\", \"event_type\":\"price_change\"}","received_at":"2026-07-28T03:06:36.087835Z","schema_version":"clob-market-ws.price_change.v1","sequence":null,"server_hash":null,"server_timestamp":"1785207996011","session_id":"3e519d9098404c15b234d96025eb1a2b","source":"clob_market_ws"},"received_at":"2026-07-28T03:06:36.087835Z","record_id":"e238e4018f0236d91eaa6015b0104ae853f81a44f4aff27c806cd068777f66ea","schema_fingerprint":"4aa3821a28b0b7c2400bc59aba4bcc0a76e971dadd19610d3ad38c768e124dc7","schema_version":"edge-lab-recorder.raw.v1","sequence":null,"source":"clob_market_ws"}
{"event_at":"2026-07-28T03:06:36.012000Z","event_fingerprint":"5e29a2260acbcfdef4e6ca1f7140c74f1a9d5a978c94c5e47e037e170a15ada5","payload":{"connection_id":"a6b55582af5f430fb37ad02bf0922475","event_at":"2026-07-28T03:06:36.012000Z","event_type":"price_change","frame_hash":"d0f2cf910c613cc8f9cc0f101f5d1d0927c49e0a262177c61e16502b1272c4b7","frame_index":0,"kind":"data","monotonic_ns":309979122333125,"payload":{"event_type":"price_change","market":"0x779291bef19b6709f61e9764a954aafe9ffae488d50ae674aabdcb4f248006d5","price_changes":[{"asset_id":"14965588658799411272385430903075831224615961675357217884735713260981483529984","best_ask":"0.21","best_bid":"0.2","hash":"83a4b456323b84eef01607c62e780276fa60eeac","price":"0.2","side":"BUY","size":"55"},{"asset_id":"8761897749749422724209054078244794145777693856614463256546737399611489089783","best_ask":"0.8","best_bid":"0.79","hash":"cff8741367cc80582e7ce73c28ea52c7235a5b41","price":"0.8","side":"SELL","size":"55"}],"timestamp":"1785207996012"},"payload_hash":"09608e0ffdfcc80ce217c1f176e831468ee5f5f137a2df8ef2d5b997b3f1580a","raw_frame":"{\"market\":\"0x779291bef19b6709f61e9764a954aafe9ffae488d50ae674aabdcb4f248006d5\", \"price_changes\":[{\"asset_id\":\"14965588658799411272385430903075831224615961675357217884735713260981483529984\", \"price\":\"0.2\", \"size\":\"55\", \"side\":\"BUY\", \"hash\":\"83a4b456323b84eef01607c62e780276fa60eeac\", \"best_bid\":\"0.2\", \"best_ask\":\"0.21\"}, {\"asset_id\":\"8761897749749422724209054078244794145777693856614463256546737399611489089783\", \"price\":\"0.8\", \"size\":\"55\", \"side\":\"SELL\", \"hash\":\"cff8741367cc80582e7ce73c28ea52c7235a5b41\", \"best_bid\":\"0.79\", \"best_ask\":\"0.8\"}], \"timestamp\":\"1785207996012\", \"event_type\":\"price_change\"}","received_at":"2026-07-28T03:06:36.090796Z","schema_version":"clob-market-ws.price_change.v1","sequence":null,"server_hash":null,"server_timestamp":"1785207996012","session_id":"3e519d9098404c15b234d96025eb1a2b","source":"clob_market_ws"},"received_at":"2026-07-28T03:06:36.090796Z","record_id":"6af55426b3f3757db0d311d88c9e879499a1625aa079115066526997917ce98e","schema_fingerprint":"4aa3821a28b0b7c2400bc59aba4bcc0a76e971dadd19610d3ad38c768e124dc7","schema_version":"edge-lab-recorder.raw.v1","sequence":null,"source":"clob_market_ws"}
{"event_at":"2026-07-28T03:06:36.013000Z","event_fingerprint":"d6b3d488dccc4b6bd7f8f46cf6e1733d933dfad34b447fdfdf30b8ca3d9a2ecf","payload":{"connection_id":"a6b55582af5f430fb37ad02bf0922475","event_at":"2026-07-28T03:06:36.013000Z","event_type":"price_change","frame_hash":"776ad780d6e9c5dce7615f2343ca94fdc8e68bb0e7992061b206dfeeee4f5f83","frame_index":0,"kind":"data","monotonic_ns":309979125263500,"payload":{"event_type":"price_change","market":"0x779291bef19b6709f61e9764a954aafe9ffae488d50ae674aabdcb4f248006d5","price_changes":[{"asset_id":"8761897749749422724209054078244794145777693856614463256546737399611489089783","best_ask":"0.8","best_bid":"0.79","hash":"a7a7dea4570765556604be5387aefff1859546f4","price":"0.73","side":"BUY","size":"136"},{"asset_id":"14965588658799411272385430903075831224615961675357217884735713260981483529984","best_ask":"0.21","best_bid":"0.2","hash":"f4fc6fa895fac156c481547a9a301a54b9aa53ea","price":"0.27","side":"SELL","size":"136"}],"timestamp":"1785207996013"},"payload_hash":"4f43684a566192fc38a2e81608f0046e3d555574248f83a51445ca3e13fddcd5","raw_frame":"{\"market\":\"0x779291bef19b6709f61e9764a954aafe9ffae488d50ae674aabdcb4f248006d5\", \"price_changes\":[{\"asset_id\":\"8761897749749422724209054078244794145777693856614463256546737399611489089783\", \"price\":\"0.73\", \"size\":\"136\", \"side\":\"BUY\", \"hash\":\"a7a7dea4570765556604be5387aefff1859546f4\", \"best_bid\":\"0.79\", \"best_ask\":\"0.8\"}, {\"asset_id\":\"14965588658799411272385430903075831224615961675357217884735713260981483529984\", \"price\":\"0.27\", \"size\":\"136\", \"side\":\"SELL\", \"hash\":\"f4fc6fa895fac156c481547a9a301a54b9aa53ea\", \"best_bid\":\"0.2\", \"best_ask\":\"0.21\"}], \"timestamp\":\"1785207996013\", \"event_type\":\"price_change\"}","received_at":"2026-07-28T03:06:36.093726Z","schema_version":"clob-market-ws.price_change.v1","sequence":null,"server_hash":null,"server_timestamp":"1785207996013","session_id":"3e519d9098404c15b234d96025eb1a2b","source":"clob_market_ws"},"received_at":"2026-07-28T03:06:36.093726Z","record_id":"1f8b17308ef442e70879332fbc26f449f71d5d25b22eb2988932a12b3c907f6a","schema_fingerprint":"4aa3821a28b0b7c2400bc59aba4bcc0a76e971dadd19610d3ad38c768e124dc7","schema_version":"edge-lab-recorder.raw.v1","sequence":null,"source":"clob_market_ws"}
