{"event_at":"2026-07-28T03:03:47.049000Z","event_fingerprint":"7369b18120516f2984f0a88bb6b2d33450280cdcd284ac4248ae4d0a2a576fd4","payload":{"connection_id":"a6b55582af5f430fb37ad02bf0922475","event_at":"2026-07-28T03:03:47.049000Z","event_type":"price_change","frame_hash":"421918947f270aa6041c58a0d1864330779ac20e452e881638b8bfb3c3963939","frame_index":0,"kind":"data","monotonic_ns":309809919995791,"payload":{"event_type":"price_change","market":"0x779291bef19b6709f61e9764a954aafe9ffae488d50ae674aabdcb4f248006d5","price_changes":[{"asset_id":"14965588658799411272385430903075831224615961675357217884735713260981483529984","best_ask":"0.63","best_bid":"0.62","hash":"d53a28608c36cb6ac6083aae7e7d6e533b745b7a","price":"0.04","side":"BUY","size":"668.09"},{"asset_id":"8761897749749422724209054078244794145777693856614463256546737399611489089783","best_ask":"0.38","best_bid":"0.37","hash":"d92d7624580d91fd29170fe0da82047bf30f52a2","price":"0.96","side":"SELL","size":"668.09"}],"timestamp":"1785207827049"},"payload_hash":"13965c7ef97871fc54d3db8cf1c4c30c9cec819b9eec12ff6a5a972adcb65aba","raw_frame":"{\"market\":\"0x779291bef19b6709f61e9764a954aafe9ffae488d50ae674aabdcb4f248006d5\", \"price_changes\":[{\"asset_id\":\"14965588658799411272385430903075831224615961675357217884735713260981483529984\", \"price\":\"0.04\", \"size\":\"668.09\", \"side\":\"BUY\", \"hash\":\"d53a28608c36cb6ac6083aae7e7d6e533b745b7a\", \"best_bid\":\"0.62\", \"best_ask\":\"0.63\"}, {\"asset_id\":\"8761897749749422724209054078244794145777693856614463256546737399611489089783\", \"price\":\"0.96\", \"size\":\"668.09\", \"side\":\"SELL\", \"hash\":\"d92d7624580d91fd29170fe0da82047bf30f52a2\", \"best_bid\":\"0.37\", \"best_ask\":\"0.38\"}], \"timestamp\":\"1785207827049\", \"event_type\":\"price_change\"}","received_at":"2026-07-28T03:03:46.899993Z","schema_version":"clob-market-ws.price_change.v1","sequence":null,"server_hash":null,"server_timestamp":"1785207827049","session_id":"3e519d9098404c15b234d96025eb1a2b","source":"clob_market_ws"},"received_at":"2026-07-28T03:03:46.899993Z","record_id":"505811c1d80afcd2f29a72ae40e162f341d27dcc7e2e8812ef26d9ff8711de4d","schema_fingerprint":"4aa3821a28b0b7c2400bc59aba4bcc0a76e971dadd19610d3ad38c768e124dc7","schema_version":"edge-lab-recorder.raw.v1","sequence":null,"source":"clob_market_ws"}
{"event_at":"2026-07-28T03:03:47.051000Z","event_fingerprint":"bed09ab31fb3755ca19f461b1f1ff03fbb92ad8bde0a0defa39e8b8a9c22414e","payload":{"connection_id":"a6b55582af5f430fb37ad02bf0922475","event_at":"2026-07-28T03:03:47.051000Z","event_type":"price_change","frame_hash":"cfc8f320d000b0844fc2162ebfe08ce69e9e22be6d0baee535f24b15b86e05ea","frame_index":0,"kind":"data","monotonic_ns":309809922375500,"payload":{"event_type":"price_change","market":"0x779291bef19b6709f61e9764a954aafe9ffae488d50ae674aabdcb4f248006d5","price_changes":[{"asset_id":"14965588658799411272385430903075831224615961675357217884735713260981483529984","best_ask":"0.63","best_bid":"0.62","hash":"171ee3a4f48b2f0dd7012567d3899f2a11dc4602","price":"0.57","side":"BUY","size":"104.15"},{"asset_id":"8761897749749422724209054078244794145777693856614463256546737399611489089783","best_ask":"0.38","best_bid":"0.37","hash":"d977a447b1a4703683a277ef5a410c77d80ae9ec","price":"0.43","side":"SELL","size":"104.15"}],"timestamp":"1785207827051"},"payload_hash":"9f6d0791b7aa3567cc4be0ca018448cea8d881b79182739d59af250b78977f38","raw_frame":"{\"market\":\"0x779291bef19b6709f61e9764a954aafe9ffae488d50ae674aabdcb4f248006d5\", \"price_changes\":[{\"asset_id\":\"14965588658799411272385430903075831224615961675357217884735713260981483529984\", \"price\":\"0.57\", \"size\":\"104.15\", \"side\":\"BUY\", \"hash\":\"171ee3a4f48b2f0dd7012567d3899f2a11dc4602\", \"best_bid\":\"0.62\", \"best_ask\":\"0.63\"}, {\"asset_id\":\"8761897749749422724209054078244794145777693856614463256546737399611489089783\", \"price\":\"0.43\", \"size\":\"104.15\", \"side\":\"SELL\", \"hash\":\"d977a447b1a4703683a277ef5a410c77d80ae9ec\", \"best_bid\":\"0.37\", \"best_ask\":\"0.38\"}], \"timestamp\":\"1785207827051\", \"event_type\":\"price_change\"}","received_at":"2026-07-28T03:03:46.902371Z","schema_version":"clob-market-ws.price_change.v1","sequence":null,"server_hash":null,"server_timestamp":"1785207827051","session_id":"3e519d9098404c15b234d96025eb1a2b","source":"clob_market_ws"},"received_at":"2026-07-28T03:03:46.902371Z","record_id":"6d425c4f4c668bfecb85ccb555978c31b22a09440b2f718fd1ffddb8d7b741a2","schema_fingerprint":"4aa3821a28b0b7c2400bc59aba4bcc0a76e971dadd19610d3ad38c768e124dc7","schema_version":"edge-lab-recorder.raw.v1","sequence":null,"source":"clob_market_ws"}
{"event_at":"2026-07-28T03:03:47.051000Z","event_fingerprint":"f0ed7ddf4729be264eefaa79af42fdbadc01783566c35e90d4b777eb6ddf8cc4","payload":{"connection_id":"a6b55582af5f430fb37ad02bf0922475","event_at":"2026-07-28T03:03:47.051000Z","event_type":"price_change","frame_hash":"7bb31501aeb340f914660d48f5883ea8b1e2cb4322c74bf30f7a3ded6d70a7c4","frame_index":0,"kind":"data","monotonic_ns":309809923909125,"payload":{"event_type":"price_change","market":"0x779291bef19b6709f61e9764a954aafe9ffae488d50ae674aabdcb4f248006d5","price_changes":[{"asset_id":"8761897749749422724209054078244794145777693856614463256546737399611489089783","best_ask":"0.38","best_bid":"0.37","hash":"d977a447b1a4703683a277ef5a410c77d80ae9ec","price":"0.34","side":"BUY","size":"102.23"},{"asset_id":"14965588658799411272385430903075831224615961675357217884735713260981483529984","best_ask":"0.63","best_bid":"0.62","hash":"171ee3a4f48b2f0dd7012567d3899f2a11dc4602","price":"0.66","side":"SELL","size":"102.23"}],"timestamp":"1785207827051"},"payload_hash":"46be6b72f8e437eb703daee44a51a9f69f15f37ec9b59edc931b5c62c3214915","raw_frame":"{\"market\":\"0x779291bef19b6709f61e9764a954aafe9ffae488d50ae674aabdcb4f248006d5\", \"price_changes\":[{\"asset_id\":\"8761897749749422724209054078244794145777693856614463256546737399611489089783\", \"price\":\"0.34\", \"size\":\"102.23\", \"side\":\"BUY\", \"hash\":\"d977a447b1a4703683a277ef5a410c77d80ae9ec\", \"best_bid\":\"0.37\", \"best_ask\":\"0.38\"}, {\"asset_id\":\"14965588658799411272385430903075831224615961675357217884735713260981483529984\", \"price\":\"0.66\", \"size\":\"102.23\", \"side\":\"SELL\", \"hash\":\"171ee3a4f48b2f0dd7012567d3899f2a11dc4602\", \"best_bid\":\"0.62\", \"best_ask\":\"0.63\"}], \"timestamp\":\"1785207827051\", \"event_type\":\"price_change\"}","received_at":"2026-07-28T03:03:46.903906Z","schema_version":"clob-market-ws.price_change.v1","sequence":null,"server_hash":null,"server_timestamp":"1785207827051","session_id":"3e519d9098404c15b234d96025eb1a2b","source":"clob_market_ws"},"received_at":"2026-07-28T03:03:46.903906Z","record_id":"a52077f18996123657e5342e87c3f765428f78726d7080d0a03c086406586bad","schema_fingerprint":"4aa3821a28b0b7c2400bc59aba4bcc0a76e971dadd19610d3ad38c768e124dc7","schema_version":"edge-lab-recorder.raw.v1","sequence":null,"source":"clob_market_ws"}
{"event_at":"2026-07-28T03:03:47.053000Z","event_fingerprint":"082ce5d67e7898b8bf1da4023cdaf6de4ba8ec2331c11faf45f3023d7d21237a","payload":{"connection_id":"a6b55582af5f430fb37ad02bf0922475","event_at":"2026-07-28T03:03:47.053000Z","event_type":"price_change","frame_hash":"c0f36cb8961aced72da57df658e491eef4847527cee4a9a833d22af03a098482","frame_index":0,"kind":"data","monotonic_ns":309809925621666,"payload":{"event_type":"price_change","market":"0x779291bef19b6709f61e9764a954aafe9ffae488d50ae674aabdcb4f248006d5","price_changes":[{"asset_id":"14965588658799411272385430903075831224615961675357217884735713260981483529984","best_ask":"0.63","best_bid":"0.62","hash":"92c2ce8add70bb8c398098b61ba22fbdbaad756b","price":"0.54","side":"BUY","size":"206"},{"asset_id":"8761897749749422724209054078244794145777693856614463256546737399611489089783","best_ask":"0.38","best_bid":"0.37","hash":"c03bc910618d0c850bda03e05afd36b162a10fff","price":"0.46","side":"SELL","size":"206"}],"timestamp":"1785207827053"},"payload_hash":"cd0fd19b0df7a78568c5df863a98717177b3ded7e8287b620e23827adcbb8baa","raw_frame":"{\"market\":\"0x779291bef19b6709f61e9764a954aafe9ffae488d50ae674aabdcb4f248006d5\", \"price_changes\":[{\"asset_id\":\"14965588658799411272385430903075831224615961675357217884735713260981483529984\", \"price\":\"0.54\", \"size\":\"206\", \"side\":\"BUY\", \"hash\":\"92c2ce8add70bb8c398098b61ba22fbdbaad756b\", \"best_bid\":\"0.62\", \"best_ask\":\"0.63\"}, {\"asset_id\":\"8761897749749422724209054078244794145777693856614463256546737399611489089783\", \"price\":\"0.46\", \"size\":\"206\", \"side\":\"SELL\", \"hash\":\"c03bc910618d0c850bda03e05afd36b162a10fff\", \"best_bid\":\"0.37\", \"best_ask\":\"0.38\"}], \"timestamp\":\"1785207827053\", \"event_type\":\"price_change\"}","received_at":"2026-07-28T03:03:46.905620Z","schema_version":"clob-market-ws.price_change.v1","sequence":null,"server_hash":null,"server_timestamp":"1785207827053","session_id":"3e519d9098404c15b234d96025eb1a2b","source":"clob_market_ws"},"received_at":"2026-07-28T03:03:46.905620Z","record_id":"78da4fccfaa5e8fe4c2fbb60512f52fe52d64eccf4c1a5d8eaca12c263fda164","schema_fingerprint":"4aa3821a28b0b7c2400bc59aba4bcc0a76e971dadd19610d3ad38c768e124dc7","schema_version":"edge-lab-recorder.raw.v1","sequence":null,"source":"clob_market_ws"}
{"event_at":"2026-07-28T03:03:47.054000Z","event_fingerprint":"7a9d08db89b24325af5ef1c0c937e8b9f55a4f3411667bafd3c35c78bcc08368","payload":{"connection_id":"a6b55582af5f430fb37ad02bf0922475","event_at":"2026-07-28T03:03:47.054000Z","event_type":"price_change","frame_hash":"37728fec2695be5c097469c9ffa41169106b9d451b0668ad51ae13c3f8a5d5c4","frame_index":0,"kind":"data","monotonic_ns":309809927145958,"payload":{"event_type":"price_change","market":"0x779291bef19b6709f61e9764a954aafe9ffae488d50ae674aabdcb4f248006d5","price_changes":[{"asset_id":"14965588658799411272385430903075831224615961675357217884735713260981483529984","best_ask":"0.63","best_bid":"0.62","hash":"7786cf761257a80a8a8341a5078bd2c22a013584","price":"0.57","side":"BUY","size":"84.15"},{"asset_id":"8761897749749422724209054078244794145777693856614463256546737399611489089783","best_ask":"0.38","best_bid":"0.37","hash":"945b551292afc6b7e3791bc4702bd2669148f604","price":"0.43","side":"SELL","size":"84.15"}],"timestamp":"1785207827054"},"payload_hash":"2c1a9f11cbbc37b9d62c21cfda83a1defe71525390883b0625f5575cad38c2e0","raw_frame":"{\"market\":\"0x779291bef19b6709f61e9764a954aafe9ffae488d50ae674aabdcb4f248006d5\", \"price_changes\":[{\"asset_id\":\"14965588658799411272385430903075831224615961675357217884735713260981483529984\", \"price\":\"0.57\", \"size\":\"84.15\", \"side\":\"BUY\", \"hash\":\"7786cf761257a80a8a8341a5078bd2c22a013584\", \"best_bid\":\"0.62\", \"best_ask\":\"0.63\"}, {\"asset_id\":\"8761897749749422724209054078244794145777693856614463256546737399611489089783\", \"price\":\"0.43\", \"size\":\"84.15\", \"side\":\"SELL\", \"hash\":\"945b551292afc6b7e3791bc4702bd2669148f604\", \"best_bid\":\"0.37\", \"best_ask\":\"0.38\"}], \"timestamp\":\"1785207827054\", \"event_type\":\"price_change\"}","received_at":"2026-07-28T03:03:46.907144Z","schema_version":"clob-market-ws.price_change.v1","sequence":null,"server_hash":null,"server_timestamp":"1785207827054","session_id":"3e519d9098404c15b234d96025eb1a2b","source":"clob_market_ws"},"received_at":"2026-07-28T03:03:46.907144Z","record_id":"4c72a2ff9f9cfa9416622d7682e47ff23ad450c6bf6855b89744453a8994a73d","schema_fingerprint":"4aa3821a28b0b7c2400bc59aba4bcc0a76e971dadd19610d3ad38c768e124dc7","schema_version":"edge-lab-recorder.raw.v1","sequence":null,"source":"clob_market_ws"}
{"event_at":"2026-07-28T03:03:47.054000Z","event_fingerprint":"1e978c68f2492c7d216523098aa7f5c4a0ef8c80694420f61d76dbd6f5ebe9a3","payload":{"connection_id":"a6b55582af5f430fb37ad02bf0922475","event_at":"2026-07-28T03:03:47.054000Z","event_type":"price_change","frame_hash":"aa695b820a50911a5d65b5a5171eafe6173bcd3f883941b6dd1b751b35b81356","frame_index":0,"kind":"data","monotonic_ns":309809928784000,"payload":{"event_type":"price_change","market":"0x779291bef19b6709f61e9764a954aafe9ffae488d50ae674aabdcb4f248006d5","price_changes":[{"asset_id":"8761897749749422724209054078244794145777693856614463256546737399611489089783","best_ask":"0.38","best_bid":"0.37","hash":"945b551292afc6b7e3791bc4702bd2669148f604","price":"0.34","side":"BUY","size":"82.23"},{"asset_id":"14965588658799411272385430903075831224615961675357217884735713260981483529984","best_ask":"0.63","best_bid":"0.62","hash":"7786cf761257a80a8a8341a5078bd2c22a013584","price":"0.66","side":"SELL","size":"82.23"}],"timestamp":"1785207827054"},"payload_hash":"7e4430fce39269b9d07581d0982b44e31b05087a6ffd1154ee21cf56a01f35af","raw_frame":"{\"market\":\"0x779291bef19b6709f61e9764a954aafe9ffae488d50ae674aabdcb4f248006d5\", \"price_changes\":[{\"asset_id\":\"8761897749749422724209054078244794145777693856614463256546737399611489089783\", \"price\":\"0.34\", \"size\":\"82.23\", \"side\":\"BUY\", \"hash\":\"945b551292afc6b7e3791bc4702bd2669148f604\", \"best_bid\":\"0.37\", \"best_ask\":\"0.38\"}, {\"asset_id\":\"14965588658799411272385430903075831224615961675357217884735713260981483529984\", \"price\":\"0.66\", \"size\":\"82.23\", \"side\":\"SELL\", \"hash\":\"7786cf761257a80a8a8341a5078bd2c22a013584\", \"best_bid\":\"0.62\", \"best_ask\":\"0.63\"}], \"timestamp\":\"1785207827054\", \"event_type\":\"price_change\"}","received_at":"2026-07-28T03:03:46.908783Z","schema_version":"clob-market-ws.price_change.v1","sequence":null,"server_hash":null,"server_timestamp":"1785207827054","session_id":"3e519d9098404c15b234d96025eb1a2b","source":"clob_market_ws"},"received_at":"2026-07-28T03:03:46.908783Z","record_id":"8e787922eec955b2f5427ec9b456a56c30d0defbc0ca4e453df35725dae35c6e","schema_fingerprint":"4aa3821a28b0b7c2400bc59aba4bcc0a76e971dadd19610d3ad38c768e124dc7","schema_version":"edge-lab-recorder.raw.v1","sequence":null,"source":"clob_market_ws"}
{"event_at":"2026-07-28T03:03:47.057000Z","event_fingerprint":"2d975c3a53cdb49c5c0042af3c8b07c7b0c009d9d9d5f3a2d17b9e29826b956d","payload":{"connection_id":"a6b55582af5f430fb37ad02bf0922475","event_at":"2026-07-28T03:03:47.057000Z","event_type":"price_change","frame_hash":"8dfdf9374f99a91a72ea3e9232a521976624297caf7029708fed45cdb28a1865","frame_index":0,"kind":"data","monotonic_ns":309809930052291,"payload":{"event_type":"price_change","market":"0x779291bef19b6709f61e9764a954aafe9ffae488d50ae674aabdcb4f248006d5","price_changes":[{"asset_id":"14965588658799411272385430903075831224615961675357217884735713260981483529984","best_ask":"0.63","best_bid":"0.62","hash":"0b8bebff3684af340ffe5f9ecfa2e08bcd70c3f7","price":"0.01","side":"BUY","size":"7883.02"},{"asset_id":"8761897749749422724209054078244794145777693856614463256546737399611489089783","best_ask":"0.38","best_bid":"0.37","hash":"700b4a7a9ae06c6fdef02a8b8b310dc752963b1c","price":"0.99","side":"SELL","size":"7883.02"}],"timestamp":"1785207827057"},"payload_hash":"e543e957eba08f158c74f407b219a851ff013fbc588a5c7a4a0ab776067cb2b1","raw_frame":"{\"market\":\"0x779291bef19b6709f61e9764a954aafe9ffae488d50ae674aabdcb4f248006d5\", \"price_changes\":[{\"asset_id\":\"14965588658799411272385430903075831224615961675357217884735713260981483529984\", \"price\":\"0.01\", \"size\":\"7883.02\", \"side\":\"BUY\", \"hash\":\"0b8bebff3684af340ffe5f9ecfa2e08bcd70c3f7\", \"best_bid\":\"0.62\", \"best_ask\":\"0.63\"}, {\"asset_id\":\"8761897749749422724209054078244794145777693856614463256546737399611489089783\", \"price\":\"0.99\", \"size\":\"7883.02\", \"side\":\"SELL\", \"hash\":\"700b4a7a9ae06c6fdef02a8b8b310dc752963b1c\", \"best_bid\":\"0.37\", \"best_ask\":\"0.38\"}], \"timestamp\":\"1785207827057\", \"event_type\":\"price_change\"}","received_at":"2026-07-28T03:03:46.910050Z","schema_version":"clob-market-ws.price_change.v1","sequence":null,"server_hash":null,"server_timestamp":"1785207827057","session_id":"3e519d9098404c15b234d96025eb1a2b","source":"clob_market_ws"},"received_at":"2026-07-28T03:03:46.910050Z","record_id":"1e317c1d3f2a343f739e6b171d100a3c50f803d6681992f21517ff2800117359","schema_fingerprint":"4aa3821a28b0b7c2400bc59aba4bcc0a76e971dadd19610d3ad38c768e124dc7","schema_version":"edge-lab-recorder.raw.v1","sequence":null,"source":"clob_market_ws"}
{"event_at":"2026-07-28T03:03:47.077000Z","event_fingerprint":"fe6622a97c1c8afdbfedafa659cf75b77b46e373d121f1784c43248d42e4f06a","payload":{"connection_id":"a6b55582af5f430fb37ad02bf0922475","event_at":"2026-07-28T03:03:47.077000Z","event_type":"price_change","frame_hash":"90eb51f73f081e809f778b6f3609ccd5f0cabfcf620e4fff3c62727b6a113824","frame_index":0,"kind":"data","monotonic_ns":309809947967166,"payload":{"event_type":"price_change","market":"0x779291bef19b6709f61e9764a954aafe9ffae488d50ae674aabdcb4f248006d5","price_changes":[{"asset_id":"8761897749749422724209054078244794145777693856614463256546737399611489089783","best_ask":"0.38","best_bid":"0.37","hash":"eacf14702a320b11d0c9f7d9231a8f2da44ce846","price":"0.35","side":"BUY","size":"94.01"},{"asset_id":"14965588658799411272385430903075831224615961675357217884735713260981483529984","best_ask":"0.63","best_bid":"0.62","hash":"e2e3be8d26e5e5812012d51cf4752e2b0de3e177","price":"0.65","side":"SELL","size":"94.01"}],"timestamp":"1785207827077"},"payload_hash":"1bc417a19bed1dfe3995a543a785cb8fefce8a0c52932eece398853a0df6d6d0","raw_frame":"{\"market\":\"0x779291bef19b6709f61e9764a954aafe9ffae488d50ae674aabdcb4f248006d5\", \"price_changes\":[{\"asset_id\":\"8761897749749422724209054078244794145777693856614463256546737399611489089783\", \"price\":\"0.35\", \"size\":\"94.01\", \"side\":\"BUY\", \"hash\":\"eacf14702a320b11d0c9f7d9231a8f2da44ce846\", \"best_bid\":\"0.37\", \"best_ask\":\"0.38\"}, {\"asset_id\":\"14965588658799411272385430903075831224615961675357217884735713260981483529984\", \"price\":\"0.65\", \"size\":\"94.01\", \"side\":\"SELL\", \"hash\":\"e2e3be8d26e5e5812012d51cf4752e2b0de3e177\", \"best_bid\":\"0.62\", \"best_ask\":\"0.63\"}], \"timestamp\":\"1785207827077\", \"event_type\":\"price_change\"}","received_at":"2026-07-28T03:03:46.927964Z","schema_version":"clob-market-ws.price_change.v1","sequence":null,"server_hash":null,"server_timestamp":"1785207827077","session_id":"3e519d9098404c15b234d96025eb1a2b","source":"clob_market_ws"},"received_at":"2026-07-28T03:03:46.927964Z","record_id":"6e64a4db2b6d6c512d7daf573a10759bcc17c70abbf921c1095c5b2f611e615e","schema_fingerprint":"4aa3821a28b0b7c2400bc59aba4bcc0a76e971dadd19610d3ad38c768e124dc7","schema_version":"edge-lab-recorder.raw.v1","sequence":null,"source":"clob_market_ws"}
{"event_at":"2026-07-28T03:03:47.086000Z","event_fingerprint":"ef855c685c46af3974de51dbf641bfd092623777ef8a0ab34242ff98c15d4be4","payload":{"connection_id":"a6b55582af5f430fb37ad02bf0922475","event_at":"2026-07-28T03:03:47.086000Z","event_type":"price_change","frame_hash":"f9e41e53c23b6868f26d3de7da232eee1f9f4cef4a9a444775bb851d2e5bfa24","frame_index":0,"kind":"data","monotonic_ns":309809957246916,"payload":{"event_type":"price_change","market":"0x779291bef19b6709f61e9764a954aafe9ffae488d50ae674aabdcb4f248006d5","price_changes":[{"asset_id":"8761897749749422724209054078244794145777693856614463256546737399611489089783","best_ask":"0.38","best_bid":"0.37","hash":"bd8515735e203fdb3d382001ff02771f4deae18b","price":"0.34","side":"BUY","size":"103.23"},{"asset_id":"14965588658799411272385430903075831224615961675357217884735713260981483529984","best_ask":"0.63","best_bid":"0.62","hash":"d3e66bf49838b43793750d1beef8b1f7106353be","price":"0.66","side":"SELL","size":"103.23"}],"timestamp":"1785207827086"},"payload_hash":"8fc3a541f12171b21d26a44c270a0da9e8530c5d19022c98358f95c7d433ff4a","raw_frame":"{\"market\":\"0x779291bef19b6709f61e9764a954aafe9ffae488d50ae674aabdcb4f248006d5\", \"price_changes\":[{\"asset_id\":\"8761897749749422724209054078244794145777693856614463256546737399611489089783\", \"price\":\"0.34\", \"size\":\"103.23\", \"side\":\"BUY\", \"hash\":\"bd8515735e203fdb3d382001ff02771f4deae18b\", \"best_bid\":\"0.37\", \"best_ask\":\"0.38\"}, {\"asset_id\":\"14965588658799411272385430903075831224615961675357217884735713260981483529984\", \"price\":\"0.66\", \"size\":\"103.23\", \"side\":\"SELL\", \"hash\":\"d3e66bf49838b43793750d1beef8b1f7106353be\", \"best_bid\":\"0.62\", \"best_ask\":\"0.63\"}], \"timestamp\":\"1785207827086\", \"event_type\":\"price_change\"}","received_at":"2026-07-28T03:03:46.937244Z","schema_version":"clob-market-ws.price_change.v1","sequence":null,"server_hash":null,"server_timestamp":"1785207827086","session_id":"3e519d9098404c15b234d96025eb1a2b","source":"clob_market_ws"},"received_at":"2026-07-28T03:03:46.937244Z","record_id":"65348351391c1b2f82997bbe02e1d7d9944a5898bceb619d9521cbdf99f3d8de","schema_fingerprint":"4aa3821a28b0b7c2400bc59aba4bcc0a76e971dadd19610d3ad38c768e124dc7","schema_version":"edge-lab-recorder.raw.v1","sequence":null,"source":"clob_market_ws"}
{"event_at":"2026-07-28T03:03:47.146000Z","event_fingerprint":"4c4b3299f6a3c180119beee2701d73ed0676024a4335ea09fd8ab321b127e55f","payload":{"connection_id":"a6b55582af5f430fb37ad02bf0922475","event_at":"2026-07-28T03:03:47.146000Z","event_type":"price_change","frame_hash":"aec9a32d716ed678df2dd2d752845bff9634a5cbbc315e653aac86a8542a44e2","frame_index":0,"kind":"data","monotonic_ns":309810016952375,"payload":{"event_type":"price_change","market":"0x779291bef19b6709f61e9764a954aafe9ffae488d50ae674aabdcb4f248006d5","price_changes":[{"asset_id":"8761897749749422724209054078244794145777693856614463256546737399611489089783","best_ask":"0.38","best_bid":"0.37","hash":"2f34d4bd6dc93caa20e17367e6a05f2396c85213","price":"0.01","side":"BUY","size":"7853.02"},{"asset_id":"14965588658799411272385430903075831224615961675357217884735713260981483529984","best_ask":"0.63","best_bid":"0.62","hash":"69c94a33ecbdf3427d0c5ad0daeb85b574023906","price":"0.99","side":"SELL","size":"7853.02"}],"timestamp":"1785207827146"},"payload_hash":"dc8cfcd09afee9d19ff7365acfbff8e3a82b58cf3e0335cdc92240520cb8ca7f","raw_frame":"{\"market\":\"0x779291bef19b6709f61e9764a954aafe9ffae488d50ae674aabdcb4f248006d5\", \"price_changes\":[{\"asset_id\":\"8761897749749422724209054078244794145777693856614463256546737399611489089783\", \"price\":\"0.01\", \"size\":\"7853.02\", \"side\":\"BUY\", \"hash\":\"2f34d4bd6dc93caa20e17367e6a05f2396c85213\", \"best_bid\":\"0.37\", \"best_ask\":\"0.38\"}, {\"asset_id\":\"14965588658799411272385430903075831224615961675357217884735713260981483529984\", \"price\":\"0.99\", \"size\":\"7853.02\", \"side\":\"SELL\", \"hash\":\"69c94a33ecbdf3427d0c5ad0daeb85b574023906\", \"best_bid\":\"0.62\", \"best_ask\":\"0.63\"}], \"timestamp\":\"1785207827146\", \"event_type\":\"price_change\"}","received_at":"2026-07-28T03:03:46.996948Z","schema_version":"clob-market-ws.price_change.v1","sequence":null,"server_hash":null,"server_timestamp":"1785207827146","session_id":"3e519d9098404c15b234d96025eb1a2b","source":"clob_market_ws"},"received_at":"2026-07-28T03:03:46.996948Z","record_id":"270f48f4410090267bd0b021c59598c88e57064f8ec33f08dd2c9c3a933e5c81","schema_fingerprint":"4aa3821a28b0b7c2400bc59aba4bcc0a76e971dadd19610d3ad38c768e124dc7","schema_version":"edge-lab-recorder.raw.v1","sequence":null,"source":"clob_market_ws"}
{"event_at":"2026-07-28T03:03:47.171000Z","event_fingerprint":"b255d1bc789c539c9913dd0875a5df5c495d1c44369758907dde9a5f5cddc37e","payload":{"connection_id":"a6b55582af5f430fb37ad02bf0922475","event_at":"2026-07-28T03:03:47.171000Z","event_type":"price_change","frame_hash":"780d1696b3860cee6bf6e64d3cae68e071143e1c93e1aa37172d6d219a6621f2","frame_index":0,"kind":"data","monotonic_ns":309810042629791,"payload":{"event_type":"price_change","market":"0x779291bef19b6709f61e9764a954aafe9ffae488d50ae674aabdcb4f248006d5","price_changes":[{"asset_id":"14965588658799411272385430903075831224615961675357217884735713260981483529984","best_ask":"0.63","best_bid":"0.62","hash":"a7a7287deacb2ef53b6435eca9eddc0376948af2","price":"0.04","side":"BUY","size":"673.09"},{"asset_id":"8761897749749422724209054078244794145777693856614463256546737399611489089783","best_ask":"0.38","best_bid":"0.37","hash":"f64bc9219a65cd158b96ab5aed4d8f33cc8d2e4a","price":"0.96","side":"SELL","size":"673.09"}],"timestamp":"1785207827171"},"payload_hash":"83317914ab8dc52ceb2f41c888099789611591c3180f021e802e136e4da29a24","raw_frame":"{\"market\":\"0x779291bef19b6709f61e9764a954aafe9ffae488d50ae674aabdcb4f248006d5\", \"price_changes\":[{\"asset_id\":\"14965588658799411272385430903075831224615961675357217884735713260981483529984\", \"price\":\"0.04\", \"size\":\"673.09\", \"side\":\"BUY\", \"hash\":\"a7a7287deacb2ef53b6435eca9eddc0376948af2\", \"best_bid\":\"0.62\", \"best_ask\":\"0.63\"}, {\"asset_id\":\"8761897749749422724209054078244794145777693856614463256546737399611489089783\", \"price\":\"0.96\", \"size\":\"673.09\", \"side\":\"SELL\", \"hash\":\"f64bc9219a65cd158b96ab5aed4d8f33cc8d2e4a\", \"best_bid\":\"0.37\", \"best_ask\":\"0.38\"}], \"timestamp\":\"1785207827171\", \"event_type\":\"price_change\"}","received_at":"2026-07-28T03:03:47.022620Z","schema_version":"clob-market-ws.price_change.v1","sequence":null,"server_hash":null,"server_timestamp":"1785207827171","session_id":"3e519d9098404c15b234d96025eb1a2b","source":"clob_market_ws"},"received_at":"2026-07-28T03:03:47.022620Z","record_id":"97a7c93335688a049c1e20f5d731163ad37c0345ce50485e3c047497e40a5569","schema_fingerprint":"4aa3821a28b0b7c2400bc59aba4bcc0a76e971dadd19610d3ad38c768e124dc7","schema_version":"edge-lab-recorder.raw.v1","sequence":null,"source":"clob_market_ws"}
{"event_at":"2026-07-28T03:03:47.275000Z","event_fingerprint":"25a15846df752ee533bd4cdade44aeca9aa7e76fc252bfeb216ea6e3a2f9a10b","payload":{"connection_id":"a6b55582af5f430fb37ad02bf0922475","event_at":"2026-07-28T03:03:47.275000Z","event_type":"price_change","frame_hash":"fa8b91b74cbfcbd80798dc476afdb49d8b351b041ba464064063cf1d855002c8","frame_index":0,"kind":"data","monotonic_ns":309810148812000,"payload":{"event_type":"price_change","market":"0x779291bef19b6709f61e9764a954aafe9ffae488d50ae674aabdcb4f248006d5","price_changes":[{"asset_id":"8761897749749422724209054078244794145777693856614463256546737399611489089783","best_ask":"0.38","best_bid":"0.37","hash":"06ed7554b0fbb15c3ecf35b6f74840a0c6c04b7f","price":"0.21","side":"BUY","size":"344.82"},{"asset_id":"14965588658799411272385430903075831224615961675357217884735713260981483529984","best_ask":"0.63","best_bid":"0.62","hash":"1868b57d061e7b4fa39b2793c8b5da9c2b610afc","price":"0.79","side":"SELL","size":"344.82"}],"timestamp":"1785207827275"},"payload_hash":"017783dd7c7f1019e36b64250988936cc6555309c4ba58cd88a1dd838ff73023","raw_frame":"{\"market\":\"0x779291bef19b6709f61e9764a954aafe9ffae488d50ae674aabdcb4f248006d5\", \"price_changes\":[{\"asset_id\":\"8761897749749422724209054078244794145777693856614463256546737399611489089783\", \"price\":\"0.21\", \"size\":\"344.82\", \"side\":\"BUY\", \"hash\":\"06ed7554b0fbb15c3ecf35b6f74840a0c6c04b7f\", \"best_bid\":\"0.37\", \"best_ask\":\"0.38\"}, {\"asset_id\":\"14965588658799411272385430903075831224615961675357217884735713260981483529984\", \"price\":\"0.79\", \"size\":\"344.82\", \"side\":\"SELL\", \"hash\":\"1868b57d061e7b4fa39b2793c8b5da9c2b610afc\", \"best_bid\":\"0.62\", \"best_ask\":\"0.63\"}], \"timestamp\":\"1785207827275\", \"event_type\":\"price_change\"}","received_at":"2026-07-28T03:03:47.128805Z","schema_version":"clob-market-ws.price_change.v1","sequence":null,"server_hash":null,"server_timestamp":"1785207827275","session_id":"3e519d9098404c15b234d96025eb1a2b","source":"clob_market_ws"},"received_at":"2026-07-28T03:03:47.128805Z","record_id":"df1468f1ae489c11f0810b037fa2132737e4fad67e377e014c5f708c513732ae","schema_fingerprint":"4aa3821a28b0b7c2400bc59aba4bcc0a76e971dadd19610d3ad38c768e124dc7","schema_version":"edge-lab-recorder.raw.v1","sequence":null,"source":"clob_market_ws"}
{"event_at":"2026-07-28T03:03:47.278000Z","event_fingerprint":"2f2c3a3add35ac8069dd112b4e124bf95dd55f0cfe57bff5b872a389dca765a6","payload":{"connection_id":"a6b55582af5f430fb37ad02bf0922475","event_at":"2026-07-28T03:03:47.278000Z","event_type":"price_change","frame_hash":"070862f64bca94067556ec654584b1dc9a00ae761de024519eb152e4a9cd15db","frame_index":0,"kind":"data","monotonic_ns":309810150408583,"payload":{"event_type":"price_change","market":"0x779291bef19b6709f61e9764a954aafe9ffae488d50ae674aabdcb4f248006d5","price_changes":[{"asset_id":"14965588658799411272385430903075831224615961675357217884735713260981483529984","best_ask":"0.63","best_bid":"0.62","hash":"6a61cc02508bf90a153bcdd0a9ab804478ce0e53","price":"0.42","side":"BUY","size":"206.02"},{"asset_id":"8761897749749422724209054078244794145777693856614463256546737399611489089783","best_ask":"0.38","best_bid":"0.37","hash":"4a40e1ec8d5fb3e0d4fb3fa1d850f164212de1df","price":"0.58","side":"SELL","size":"206.02"}],"timestamp":"1785207827278"},"payload_hash":"d9eeaf5236d793c13a36efc24bcd90c25b5f167a36e4767d66b16f6b64143896","raw_frame":"{\"market\":\"0x779291bef19b6709f61e9764a954aafe9ffae488d50ae674aabdcb4f248006d5\", \"price_changes\":[{\"asset_id\":\"14965588658799411272385430903075831224615961675357217884735713260981483529984\", \"price\":\"0.42\", \"size\":\"206.02\", \"side\":\"BUY\", \"hash\":\"6a61cc02508bf90a153bcdd0a9ab804478ce0e53\", \"best_bid\":\"0.62\", \"best_ask\":\"0.63\"}, {\"asset_id\":\"8761897749749422724209054078244794145777693856614463256546737399611489089783\", \"price\":\"0.58\", \"size\":\"206.02\", \"side\":\"SELL\", \"hash\":\"4a40e1ec8d5fb3e0d4fb3fa1d850f164212de1df\", \"best_bid\":\"0.37\", \"best_ask\":\"0.38\"}], \"timestamp\":\"1785207827278\", \"event_type\":\"price_change\"}","received_at":"2026-07-28T03:03:47.130402Z","schema_version":"clob-market-ws.price_change.v1","sequence":null,"server_hash":null,"server_timestamp":"1785207827278","session_id":"3e519d9098404c15b234d96025eb1a2b","source":"clob_market_ws"},"received_at":"2026-07-28T03:03:47.130402Z","record_id":"79728372a8359ea2bfa97cf8635b87773dd435ef8cf9bcf8a23f158c59851f09","schema_fingerprint":"4aa3821a28b0b7c2400bc59aba4bcc0a76e971dadd19610d3ad38c768e124dc7","schema_version":"edge-lab-recorder.raw.v1","sequence":null,"source":"clob_market_ws"}
{"event_at":"2026-07-28T03:03:47.281000Z","event_fingerprint":"19ab9bc5d977d7b97ad49162013d8a81f5c8ba3958af608ba980a17761cd2970","payload":{"connection_id":"a6b55582af5f430fb37ad02bf0922475","event_at":"2026-07-28T03:03:47.281000Z","event_type":"price_change","frame_hash":"69258d5efc08a4452ee13a2882f36c8258be0555b08a1cc324da10905e93e952","frame_index":0,"kind":"data","monotonic_ns":309810156179333,"payload":{"event_type":"price_change","market":"0x779291bef19b6709f61e9764a954aafe9ffae488d50ae674aabdcb4f248006d5","price_changes":[{"asset_id":"14965588658799411272385430903075831224615961675357217884735713260981483529984","best_ask":"0.63","best_bid":"0.62","hash":"79819542fdd0f6edf797881b34f538d8150685df","price":"0.42","side":"BUY","size":"126.66"},{"asset_id":"8761897749749422724209054078244794145777693856614463256546737399611489089783","best_ask":"0.38","best_bid":"0.37","hash":"f7fd5b071f6c9ad426f0acd49ea6b87ccf91c9f6","price":"0.58","side":"SELL","size":"126.66"}],"timestamp":"1785207827281"},"payload_hash":"006616d10c7d46343f2bce4d029b039e89408b559f33cf0efbed87929732f64d","raw_frame":"{\"market\":\"0x779291bef19b6709f61e9764a954aafe9ffae488d50ae674aabdcb4f248006d5\", \"price_changes\":[{\"asset_id\":\"14965588658799411272385430903075831224615961675357217884735713260981483529984\", \"price\":\"0.42\", \"size\":\"126.66\", \"side\":\"BUY\", \"hash\":\"79819542fdd0f6edf797881b34f538d8150685df\", \"best_bid\":\"0.62\", \"best_ask\":\"0.63\"}, {\"asset_id\":\"8761897749749422724209054078244794145777693856614463256546737399611489089783\", \"price\":\"0.58\", \"size\":\"126.66\", \"side\":\"SELL\", \"hash\":\"f7fd5b071f6c9ad426f0acd49ea6b87ccf91c9f6\", \"best_bid\":\"0.37\", \"best_ask\":\"0.38\"}], \"timestamp\":\"1785207827281\", \"event_type\":\"price_change\"}","received_at":"2026-07-28T03:03:47.136173Z","schema_version":"clob-market-ws.price_change.v1","sequence":null,"server_hash":null,"server_timestamp":"1785207827281","session_id":"3e519d9098404c15b234d96025eb1a2b","source":"clob_market_ws"},"received_at":"2026-07-28T03:03:47.136173Z","record_id":"9806711c158791b831cfc194f057e95b72dbf6cd89beb96b9f79a519c3f93f7a","schema_fingerprint":"4aa3821a28b0b7c2400bc59aba4bcc0a76e971dadd19610d3ad38c768e124dc7","schema_version":"edge-lab-recorder.raw.v1","sequence":null,"source":"clob_market_ws"}
{"event_at":"2026-07-28T03:03:47.284000Z","event_fingerprint":"4767cd2ebec3586d707629e6ddedbfd4761d1495b7119708dba6a86a7b096ee8","payload":{"connection_id":"a6b55582af5f430fb37ad02bf0922475","event_at":"2026-07-28T03:03:47.284000Z","event_type":"price_change","frame_hash":"cfd71f62ad516dedd7a412ed19515b1fd6a4afe195b9170c62511496e421d161","frame_index":0,"kind":"data","monotonic_ns":309810157745500,"payload":{"event_type":"price_change","market":"0x779291bef19b6709f61e9764a954aafe9ffae488d50ae674aabdcb4f248006d5","price_changes":[{"asset_id":"8761897749749422724209054078244794145777693856614463256546737399611489089783","best_ask":"0.38","best_bid":"0.37","hash":"3884943cbbc2da56f8bd0dc074629ab7bae78d8b","price":"0.2","side":"BUY","size":"184.8"},{"asset_id":"14965588658799411272385430903075831224615961675357217884735713260981483529984","best_ask":"0.63","best_bid":"0.62","hash":"7326556affb76a018ce35601f00c2ec5ad23a239","price":"0.8","side":"SELL","size":"184.8"}],"timestamp":"1785207827284"},"payload_hash":"27ae92128ff219075a2e851523244a5a64a6cfea792127737537b80dc292f4b8","raw_frame":"{\"market\":\"0x779291bef19b6709f61e9764a954aafe9ffae488d50ae674aabdcb4f248006d5\", \"price_changes\":[{\"asset_id\":\"8761897749749422724209054078244794145777693856614463256546737399611489089783\", \"price\":\"0.2\", \"size\":\"184.8\", \"side\":\"BUY\", \"hash\":\"3884943cbbc2da56f8bd0dc074629ab7bae78d8b\", \"best_bid\":\"0.37\", \"best_ask\":\"0.38\"}, {\"asset_id\":\"14965588658799411272385430903075831224615961675357217884735713260981483529984\", \"price\":\"0.8\", \"size\":\"184.8\", \"side\":\"SELL\", \"hash\":\"7326556affb76a018ce35601f00c2ec5ad23a239\", \"best_bid\":\"0.62\", \"best_ask\":\"0.63\"}], \"timestamp\":\"1785207827284\", \"event_type\":\"price_change\"}","received_at":"2026-07-28T03:03:47.137741Z","schema_version":"clob-market-ws.price_change.v1","sequence":null,"server_hash":null,"server_timestamp":"1785207827284","session_id":"3e519d9098404c15b234d96025eb1a2b","source":"clob_market_ws"},"received_at":"2026-07-28T03:03:47.137741Z","record_id":"9f14963547013a1764e52aafaf1b17672a587da464b1c08edfe9a5bb7752f110","schema_fingerprint":"4aa3821a28b0b7c2400bc59aba4bcc0a76e971dadd19610d3ad38c768e124dc7","schema_version":"edge-lab-recorder.raw.v1","sequence":null,"source":"clob_market_ws"}
{"event_at":"2026-07-28T03:03:47.285000Z","event_fingerprint":"0bd3ac7f4c647dc16c6038fa7e613c2a11e7be9e305ac86d426dc9dc263136ed","payload":{"connection_id":"a6b55582af5f430fb37ad02bf0922475","event_at":"2026-07-28T03:03:47.285000Z","event_type":"price_change","frame_hash":"f8aa21c73c5ef7d8b291c07350a77b1ccfbdfc2d0198b5e5dcf4e6aaca63f91b","frame_index":0,"kind":"data","monotonic_ns":309810159261500,"payload":{"event_type":"price_change","market":"0x779291bef19b6709f61e9764a954aafe9ffae488d50ae674aabdcb4f248006d5","price_changes":[{"asset_id":"14965588658799411272385430903075831224615961675357217884735713260981483529984","best_ask":"0.63","best_bid":"0.62","hash":"0b26f26eb1dbb93d7af66f0d0c3ec8c374f213cb","price":"0.42","side":"BUY","size":"47.3"},{"asset_id":"8761897749749422724209054078244794145777693856614463256546737399611489089783","best_ask":"0.38","best_bid":"0.37","hash":"257d8d02dd689727cda2c1d9cbf87b4dcf7199c7","price":"0.58","side":"SELL","size":"47.3"}],"timestamp":"1785207827285"},"payload_hash":"4a288799c6ff43c220236e8de2a393cea76b6f6f7071269afb9c40aded52721d","raw_frame":"{\"market\":\"0x779291bef19b6709f61e9764a954aafe9ffae488d50ae674aabdcb4f248006d5\", \"price_changes\":[{\"asset_id\":\"14965588658799411272385430903075831224615961675357217884735713260981483529984\", \"price\":\"0.42\", \"size\":\"47.3\", \"side\":\"BUY\", \"hash\":\"0b26f26eb1dbb93d7af66f0d0c3ec8c374f213cb\", \"best_bid\":\"0.62\", \"best_ask\":\"0.63\"}, {\"asset_id\":\"8761897749749422724209054078244794145777693856614463256546737399611489089783\", \"price\":\"0.58\", \"size\":\"47.3\", \"side\":\"SELL\", \"hash\":\"257d8d02dd689727cda2c1d9cbf87b4dcf7199c7\", \"best_bid\":\"0.37\", \"best_ask\":\"0.38\"}], \"timestamp\":\"1785207827285\", \"event_type\":\"price_change\"}","received_at":"2026-07-28T03:03:47.139255Z","schema_version":"clob-market-ws.price_change.v1","sequence":null,"server_hash":null,"server_timestamp":"1785207827285","session_id":"3e519d9098404c15b234d96025eb1a2b","source":"clob_market_ws"},"received_at":"2026-07-28T03:03:47.139255Z","record_id":"4d5966ea7e0c91ecc5719f04b3c65307e6ccb5cd7f37a542e262f58d4244b145","schema_fingerprint":"4aa3821a28b0b7c2400bc59aba4bcc0a76e971dadd19610d3ad38c768e124dc7","schema_version":"edge-lab-recorder.raw.v1","sequence":null,"source":"clob_market_ws"}
{"event_at":"2026-07-28T03:03:47.286000Z","event_fingerprint":"5d4de257eabd92fbedbf4ac0f936b52ed4c88e07916b7dda871031fe00ed80e5","payload":{"connection_id":"a6b55582af5f430fb37ad02bf0922475","event_at":"2026-07-28T03:03:47.286000Z","event_type":"price_change","frame_hash":"ce5f55aaa5d553072b919a8460611580a16dbe61416bd9fd969a2fd3fea9c6ff","frame_index":0,"kind":"data","monotonic_ns":309810160906166,"payload":{"event_type":"price_change","market":"0x779291bef19b6709f61e9764a954aafe9ffae488d50ae674aabdcb4f248006d5","price_changes":[{"asset_id":"8761897749749422724209054078244794145777693856614463256546737399611489089783","best_ask":"0.38","best_bid":"0.37","hash":"460cc3f6f171d4efddd15491b06a5b2491544e2c","price":"0.21","side":"BUY","size":"186.1"},{"asset_id":"14965588658799411272385430903075831224615961675357217884735713260981483529984","best_ask":"0.63","best_bid":"0.62","hash":"c9a1326bd9f5724553e815331e8884e16337f600","price":"0.79","side":"SELL","size":"186.1"}],"timestamp":"1785207827286"},"payload_hash":"d93191290f59deea6c341377678de49b7f1fa0a50148a4ae1c5db44387316f82","raw_frame":"{\"market\":\"0x779291bef19b6709f61e9764a954aafe9ffae488d50ae674aabdcb4f248006d5\", \"price_changes\":[{\"asset_id\":\"8761897749749422724209054078244794145777693856614463256546737399611489089783\", \"price\":\"0.21\", \"size\":\"186.1\", \"side\":\"BUY\", \"hash\":\"460cc3f6f171d4efddd15491b06a5b2491544e2c\", \"best_bid\":\"0.37\", \"best_ask\":\"0.38\"}, {\"asset_id\":\"14965588658799411272385430903075831224615961675357217884735713260981483529984\", \"price\":\"0.79\", \"size\":\"186.1\", \"side\":\"SELL\", \"hash\":\"c9a1326bd9f5724553e815331e8884e16337f600\", \"best_bid\":\"0.62\", \"best_ask\":\"0.63\"}], \"timestamp\":\"1785207827286\", \"event_type\":\"price_change\"}","received_at":"2026-07-28T03:03:47.140901Z","schema_version":"clob-market-ws.price_change.v1","sequence":null,"server_hash":null,"server_timestamp":"1785207827286","session_id":"3e519d9098404c15b234d96025eb1a2b","source":"clob_market_ws"},"received_at":"2026-07-28T03:03:47.140901Z","record_id":"e7984e84e25c53519645caf5c2543962c9f5b096d1f984bc5db9f3bcbaae7265","schema_fingerprint":"4aa3821a28b0b7c2400bc59aba4bcc0a76e971dadd19610d3ad38c768e124dc7","schema_version":"edge-lab-recorder.raw.v1","sequence":null,"source":"clob_market_ws"}
{"event_at":"2026-07-28T03:03:47.298000Z","event_fingerprint":"11360d8fa93e8e5d6ecca07cfe36160bc39f40f8f96cbea3c286d08b6b71cd8f","payload":{"connection_id":"a6b55582af5f430fb37ad02bf0922475","event_at":"2026-07-28T03:03:47.298000Z","event_type":"price_change","frame_hash":"02fc288ed9339c0b30d52ba7b5f387bc7ae489faa094b76a8657fc7b2fd40da5","frame_index":0,"kind":"data","monotonic_ns":309810171445416,"payload":{"event_type":"price_change","market":"0x779291bef19b6709f61e9764a954aafe9ffae488d50ae674aabdcb4f248006d5","price_changes":[{"asset_id":"14965588658799411272385430903075831224615961675357217884735713260981483529984","best_ask":"0.63","best_bid":"0.62","hash":"04dea2d591c71150e7267e63c97f4ba94ef1bf35","price":"0.04","side":"BUY","size":"668.09"},{"asset_id":"8761897749749422724209054078244794145777693856614463256546737399611489089783","best_ask":"0.38","best_bid":"0.37","hash":"0c8574460f07009b19af1bd10a13e42f272072c6","price":"0.96","side":"SELL","size":"668.09"}],"timestamp":"1785207827298"},"payload_hash":"3bc26d8c9e18a2514c1d4cada086a4ffc2f409567f8a23f13c334fe914baf757","raw_frame":"{\"market\":\"0x779291bef19b6709f61e9764a954aafe9ffae488d50ae674aabdcb4f248006d5\", \"price_changes\":[{\"asset_id\":\"14965588658799411272385430903075831224615961675357217884735713260981483529984\", \"price\":\"0.04\", \"size\":\"668.09\", \"side\":\"BUY\", \"hash\":\"04dea2d591c71150e7267e63c97f4ba94ef1bf35\", \"best_bid\":\"0.62\", \"best_ask\":\"0.63\"}, {\"asset_id\":\"8761897749749422724209054078244794145777693856614463256546737399611489089783\", \"price\":\"0.96\", \"size\":\"668.09\", \"side\":\"SELL\", \"hash\":\"0c8574460f07009b19af1bd10a13e42f272072c6\", \"best_bid\":\"0.37\", \"best_ask\":\"0.38\"}], \"timestamp\":\"1785207827298\", \"event_type\":\"price_change\"}","received_at":"2026-07-28T03:03:47.151434Z","schema_version":"clob-market-ws.price_change.v1","sequence":null,"server_hash":null,"server_timestamp":"1785207827298","session_id":"3e519d9098404c15b234d96025eb1a2b","source":"clob_market_ws"},"received_at":"2026-07-28T03:03:47.151434Z","record_id":"01e352a4a50b2001eb3883c6d0e611478f5ee6e0ca26972515cd2fdf0c4b928d","schema_fingerprint":"4aa3821a28b0b7c2400bc59aba4bcc0a76e971dadd19610d3ad38c768e124dc7","schema_version":"edge-lab-recorder.raw.v1","sequence":null,"source":"clob_market_ws"}
{"event_at":"2026-07-28T03:03:47.322000Z","event_fingerprint":"a9900953de75097301c1e65cc82bb02cf4f2af6887d68bde6511eda7904c8614","payload":{"connection_id":"a6b55582af5f430fb37ad02bf0922475","event_at":"2026-07-28T03:03:47.322000Z","event_type":"price_change","frame_hash":"0478ce39b95ab4289145c21dd62070b81f59ca2581739857126fc3f7936a5502","frame_index":0,"kind":"data","monotonic_ns":309810193315416,"payload":{"event_type":"price_change","market":"0x779291bef19b6709f61e9764a954aafe9ffae488d50ae674aabdcb4f248006d5","price_changes":[{"asset_id":"14965588658799411272385430903075831224615961675357217884735713260981483529984","best_ask":"0.63","best_bid":"0.62","hash":"0f7f3f08ed9d169ef4f2f121efbebc7cd681c282","price":"0.01","side":"BUY","size":"7888.02"},{"asset_id":"8761897749749422724209054078244794145777693856614463256546737399611489089783","best_ask":"0.38","best_bid":"0.37","hash":"85ddae970ee2518611ae3a1f3327110a1581efb6","price":"0.99","side":"SELL","size":"7888.02"}],"timestamp":"1785207827322"},"payload_hash":"d13f79a48545949fe499a002ce78a9b5bee6c3928a79c26aa4830c9febf521bc","raw_frame":"{\"market\":\"0x779291bef19b6709f61e9764a954aafe9ffae488d50ae674aabdcb4f248006d5\", \"price_changes\":[{\"asset_id\":\"14965588658799411272385430903075831224615961675357217884735713260981483529984\", \"price\":\"0.01\", \"size\":\"7888.02\", \"side\":\"BUY\", \"hash\":\"0f7f3f08ed9d169ef4f2f121efbebc7cd681c282\", \"best_bid\":\"0.62\", \"best_ask\":\"0.63\"}, {\"asset_id\":\"8761897749749422724209054078244794145777693856614463256546737399611489089783\", \"price\":\"0.99\", \"size\":\"7888.02\", \"side\":\"SELL\", \"hash\":\"85ddae970ee2518611ae3a1f3327110a1581efb6\", \"best_bid\":\"0.37\", \"best_ask\":\"0.38\"}], \"timestamp\":\"1785207827322\", \"event_type\":\"price_change\"}","received_at":"2026-07-28T03:03:47.173308Z","schema_version":"clob-market-ws.price_change.v1","sequence":null,"server_hash":null,"server_timestamp":"1785207827322","session_id":"3e519d9098404c15b234d96025eb1a2b","source":"clob_market_ws"},"received_at":"2026-07-28T03:03:47.173308Z","record_id":"7d8c351de4aecba17731649a359283fd4ba47d8051e3975009870d8c361fca8b","schema_fingerprint":"4aa3821a28b0b7c2400bc59aba4bcc0a76e971dadd19610d3ad38c768e124dc7","schema_version":"edge-lab-recorder.raw.v1","sequence":null,"source":"clob_market_ws"}
{"event_at":"2026-07-28T03:03:47.341000Z","event_fingerprint":"a188b84fae19f3dadab78506e9c3a895580d77299da92b38b8e940a3769e889c","payload":{"connection_id":"a6b55582af5f430fb37ad02bf0922475","event_at":"2026-07-28T03:03:47.341000Z","event_type":"price_change","frame_hash":"d0a4429a486a8d237609db9690eb44a03b87e622cbcedcb798996c491be842b4","frame_index":0,"kind":"data","monotonic_ns":309810218237208,"payload":{"event_type":"price_change","market":"0x779291bef19b6709f61e9764a954aafe9ffae488d50ae674aabdcb4f248006d5","price_changes":[{"asset_id":"14965588658799411272385430903075831224615961675357217884735713260981483529984","best_ask":"0.63","best_bid":"0.62","hash":"a07593419ef4e3ec5af2ff1f240a15cd642aded6","price":"0.01","side":"BUY","size":"7883.02"},{"asset_id":"8761897749749422724209054078244794145777693856614463256546737399611489089783","best_ask":"0.38","best_bid":"0.37","hash":"9f2fe9835248dfbdf6c6ce555de31689a8df438f","price":"0.99","side":"SELL","size":"7883.02"}],"timestamp":"1785207827341"},"payload_hash":"7707cdff40bfb0df16d305642e430e107d7650535dfe900ff7b1b219b67d0aed","raw_frame":"{\"market\":\"0x779291bef19b6709f61e9764a954aafe9ffae488d50ae674aabdcb4f248006d5\", \"price_changes\":[{\"asset_id\":\"14965588658799411272385430903075831224615961675357217884735713260981483529984\", \"price\":\"0.01\", \"size\":\"7883.02\", \"side\":\"BUY\", \"hash\":\"a07593419ef4e3ec5af2ff1f240a15cd642aded6\", \"best_bid\":\"0.62\", \"best_ask\":\"0.63\"}, {\"asset_id\":\"8761897749749422724209054078244794145777693856614463256546737399611489089783\", \"price\":\"0.99\", \"size\":\"7883.02\", \"side\":\"SELL\", \"hash\":\"9f2fe9835248dfbdf6c6ce555de31689a8df438f\", \"best_bid\":\"0.37\", \"best_ask\":\"0.38\"}], \"timestamp\":\"1785207827341\", \"event_type\":\"price_change\"}","received_at":"2026-07-28T03:03:47.198228Z","schema_version":"clob-market-ws.price_change.v1","sequence":null,"server_hash":null,"server_timestamp":"1785207827341","session_id":"3e519d9098404c15b234d96025eb1a2b","source":"clob_market_ws"},"received_at":"2026-07-28T03:03:47.198228Z","record_id":"aca9e59d52b27f2257a99fffae5b665ba5b29e66d9f18f62361dd066749ee598","schema_fingerprint":"4aa3821a28b0b7c2400bc59aba4bcc0a76e971dadd19610d3ad38c768e124dc7","schema_version":"edge-lab-recorder.raw.v1","sequence":null,"source":"clob_market_ws"}
{"event_at":"2026-07-28T03:03:47.398000Z","event_fingerprint":"115205f43957da6bffc6857433222b71a1695705bb000ec8b84d0d10bb368863","payload":{"connection_id":"a6b55582af5f430fb37ad02bf0922475","event_at":"2026-07-28T03:03:47.398000Z","event_type":"price_change","frame_hash":"b9b19965d1b2fed9513212cbb487a7add920f208612e8b2ea6c4cd5b513c64e2","frame_index":0,"kind":"data","monotonic_ns":309810270390625,"payload":{"event_type":"price_change","market":"0x779291bef19b6709f61e9764a954aafe9ffae488d50ae674aabdcb4f248006d5","price_changes":[{"asset_id":"14965588658799411272385430903075831224615961675357217884735713260981483529984","best_ask":"0.63","best_bid":"0.62","hash":"0173129698afbb0f5061479d20cda77f4c126201","price":"0.04","side":"BUY","size":"673.09"},{"asset_id":"8761897749749422724209054078244794145777693856614463256546737399611489089783","best_ask":"0.38","best_bid":"0.37","hash":"f3f00ec8e65f977c1977569763b6672ea764aa33","price":"0.96","side":"SELL","size":"673.09"}],"timestamp":"1785207827398"},"payload_hash":"433de3619d932a315cb6bfb1a779d620f4132746603216a415d8b709bef3776d","raw_frame":"{\"market\":\"0x779291bef19b6709f61e9764a954aafe9ffae488d50ae674aabdcb4f248006d5\", \"price_changes\":[{\"asset_id\":\"14965588658799411272385430903075831224615961675357217884735713260981483529984\", \"price\":\"0.04\", \"size\":\"673.09\", \"side\":\"BUY\", \"hash\":\"0173129698afbb0f5061479d20cda77f4c126201\", \"best_bid\":\"0.62\", \"best_ask\":\"0.63\"}, {\"asset_id\":\"8761897749749422724209054078244794145777693856614463256546737399611489089783\", \"price\":\"0.96\", \"size\":\"673.09\", \"side\":\"SELL\", \"hash\":\"f3f00ec8e65f977c1977569763b6672ea764aa33\", \"best_bid\":\"0.37\", \"best_ask\":\"0.38\"}], \"timestamp\":\"1785207827398\", \"event_type\":\"price_change\"}","received_at":"2026-07-28T03:03:47.250382Z","schema_version":"clob-market-ws.price_change.v1","sequence":null,"server_hash":null,"server_timestamp":"1785207827398","session_id":"3e519d9098404c15b234d96025eb1a2b","source":"clob_market_ws"},"received_at":"2026-07-28T03:03:47.250382Z","record_id":"cf44374558568eb18cc2e049599c173ab40d1b10155452afb127246a7b16403c","schema_fingerprint":"4aa3821a28b0b7c2400bc59aba4bcc0a76e971dadd19610d3ad38c768e124dc7","schema_version":"edge-lab-recorder.raw.v1","sequence":null,"source":"clob_market_ws"}
{"event_at":"2026-07-28T03:03:47.408000Z","event_fingerprint":"e8c8890165cf288d9932f75d53e1b79ea8a509447bf29c4ee43974f1b5041620","payload":{"connection_id":"a6b55582af5f430fb37ad02bf0922475","event_at":"2026-07-28T03:03:47.408000Z","event_type":"price_change","frame_hash":"86b528938ed706f08680e313748ecdc71d01a58dfac00cb06845ff6a85d5d559","frame_index":0,"kind":"data","monotonic_ns":309810283776791,"payload":{"event_type":"price_change","market":"0x779291bef19b6709f61e9764a954aafe9ffae488d50ae674aabdcb4f248006d5","price_changes":[{"asset_id":"14965588658799411272385430903075831224615961675357217884735713260981483529984","best_ask":"0.63","best_bid":"0.62","hash":"86fec50844aa1441568e9a7d1dd8e676f0171910","price":"0.57","side":"BUY","size":"69.15"},{"asset_id":"8761897749749422724209054078244794145777693856614463256546737399611489089783","best_ask":"0.38","best_bid":"0.37","hash":"51e1c0add574a41b92a482a0e16e9bf616f2052c","price":"0.43","side":"SELL","size":"69.15"}],"timestamp":"1785207827408"},"payload_hash":"4ceca1f021c31d44960eeeb62f9f3bb8237333454d811f0a92a1e61ad2a3c2c4","raw_frame":"{\"market\":\"0x779291bef19b6709f61e9764a954aafe9ffae488d50ae674aabdcb4f248006d5\", \"price_changes\":[{\"asset_id\":\"14965588658799411272385430903075831224615961675357217884735713260981483529984\", \"price\":\"0.57\", \"size\":\"69.15\", \"side\":\"BUY\", \"hash\":\"86fec50844aa1441568e9a7d1dd8e676f0171910\", \"best_bid\":\"0.62\", \"best_ask\":\"0.63\"}, {\"asset_id\":\"8761897749749422724209054078244794145777693856614463256546737399611489089783\", \"price\":\"0.43\", \"size\":\"69.15\", \"side\":\"SELL\", \"hash\":\"51e1c0add574a41b92a482a0e16e9bf616f2052c\", \"best_bid\":\"0.37\", \"best_ask\":\"0.38\"}], \"timestamp\":\"1785207827408\", \"event_type\":\"price_change\"}","received_at":"2026-07-28T03:03:47.263769Z","schema_version":"clob-market-ws.price_change.v1","sequence":null,"server_hash":null,"server_timestamp":"1785207827408","session_id":"3e519d9098404c15b234d96025eb1a2b","source":"clob_market_ws"},"received_at":"2026-07-28T03:03:47.263769Z","record_id":"8ddb4058bad5f570264c50d0a2a01682db8395cc5b3de15b64b44a4edb923ca9","schema_fingerprint":"4aa3821a28b0b7c2400bc59aba4bcc0a76e971dadd19610d3ad38c768e124dc7","schema_version":"edge-lab-recorder.raw.v1","sequence":null,"source":"clob_market_ws"}
{"event_at":"2026-07-28T03:03:47.423000Z","event_fingerprint":"a36684c6175fa80b3989b9f7b8c388a01d672fce76803c668877008f24277b30","payload":{"connection_id":"a6b55582af5f430fb37ad02bf0922475","event_at":"2026-07-28T03:03:47.423000Z","event_type":"price_change","frame_hash":"4cb227b203265171c5f67b1b8d6d27f0377bc028b33bf7c07882daf886d2c5e1","frame_index":0,"kind":"data","monotonic_ns":309810298653875,"payload":{"event_type":"price_change","market":"0x779291bef19b6709f61e9764a954aafe9ffae488d50ae674aabdcb4f248006d5","price_changes":[{"asset_id":"8761897749749422724209054078244794145777693856614463256546737399611489089783","best_ask":"0.38","best_bid":"0.37","hash":"cbbf18553ba3344ea32c974c528b9a7edcb67880","price":"0.36","side":"BUY","size":"124.6"},{"asset_id":"14965588658799411272385430903075831224615961675357217884735713260981483529984","best_ask":"0.63","best_bid":"0.62","hash":"d9563c38e11673333cfa8b434f51aa86ec6a5f88","price":"0.64","side":"SELL","size":"124.6"}],"timestamp":"1785207827423"},"payload_hash":"bc51ae89e58bb97429a6db103b884366d7fdf37d793bf9e8f3c4eb243321fc06","raw_frame":"{\"market\":\"0x779291bef19b6709f61e9764a954aafe9ffae488d50ae674aabdcb4f248006d5\", \"price_changes\":[{\"asset_id\":\"8761897749749422724209054078244794145777693856614463256546737399611489089783\", \"price\":\"0.36\", \"size\":\"124.6\", \"side\":\"BUY\", \"hash\":\"cbbf18553ba3344ea32c974c528b9a7edcb67880\", \"best_bid\":\"0.37\", \"best_ask\":\"0.38\"}, {\"asset_id\":\"14965588658799411272385430903075831224615961675357217884735713260981483529984\", \"price\":\"0.64\", \"size\":\"124.6\", \"side\":\"SELL\", \"hash\":\"d9563c38e11673333cfa8b434f51aa86ec6a5f88\", \"best_bid\":\"0.62\", \"best_ask\":\"0.63\"}], \"timestamp\":\"1785207827423\", \"event_type\":\"price_change\"}","received_at":"2026-07-28T03:03:47.278645Z","schema_version":"clob-market-ws.price_change.v1","sequence":null,"server_hash":null,"server_timestamp":"1785207827423","session_id":"3e519d9098404c15b234d96025eb1a2b","source":"clob_market_ws"},"received_at":"2026-07-28T03:03:47.278645Z","record_id":"1d5c339d9bb37655cc42d7ee8b818133052e4fce0ed34b1613759bf53224dbc2","schema_fingerprint":"4aa3821a28b0b7c2400bc59aba4bcc0a76e971dadd19610d3ad38c768e124dc7","schema_version":"edge-lab-recorder.raw.v1","sequence":null,"source":"clob_market_ws"}
{"event_at":"2026-07-28T03:03:47.445000Z","event_fingerprint":"7cee5c50f11438cc234c49338c9d0fda9422f51e4d6a8d8d870bdb49482f6181","payload":{"connection_id":"a6b55582af5f430fb37ad02bf0922475","event_at":"2026-07-28T03:03:47.445000Z","event_type":"price_change","frame_hash":"a0ce361d182f6e50e9b1527bfeaa068c4d1e45f09e43cd3226b601e435d3d753","frame_index":0,"kind":"data","monotonic_ns":309810336406708,"payload":{"event_type":"price_change","market":"0x779291bef19b6709f61e9764a954aafe9ffae488d50ae674aabdcb4f248006d5","price_changes":[{"asset_id":"14965588658799411272385430903075831224615961675357217884735713260981483529984","best_ask":"0.63","best_bid":"0.62","hash":"d942546b875d5e3da3c79e6e6cc237bf6ca8f2dc","price":"0.53","side":"BUY","size":"186"},{"asset_id":"8761897749749422724209054078244794145777693856614463256546737399611489089783","best_ask":"0.38","best_bid":"0.37","hash":"e5e8257aeb2a2195a1fbcab804698c2fd6adb377","price":"0.47","side":"SELL","size":"186"}],"timestamp":"1785207827445"},"payload_hash":"9aca903b1f9c46eee4b071653210f35b1d2b932bfebc129c8b6ef81cd87c7437","raw_frame":"{\"market\":\"0x779291bef19b6709f61e9764a954aafe9ffae488d50ae674aabdcb4f248006d5\", \"price_changes\":[{\"asset_id\":\"14965588658799411272385430903075831224615961675357217884735713260981483529984\", \"price\":\"0.53\", \"size\":\"186\", \"side\":\"BUY\", \"hash\":\"d942546b875d5e3da3c79e6e6cc237bf6ca8f2dc\", \"best_bid\":\"0.62\", \"best_ask\":\"0.63\"}, {\"asset_id\":\"8761897749749422724209054078244794145777693856614463256546737399611489089783\", \"price\":\"0.47\", \"size\":\"186\", \"side\":\"SELL\", \"hash\":\"e5e8257aeb2a2195a1fbcab804698c2fd6adb377\", \"best_bid\":\"0.37\", \"best_ask\":\"0.38\"}], \"timestamp\":\"1785207827445\", \"event_type\":\"price_change\"}","received_at":"2026-07-28T03:03:47.316399Z","schema_version":"clob-market-ws.price_change.v1","sequence":null,"server_hash":null,"server_timestamp":"1785207827445","session_id":"3e519d9098404c15b234d96025eb1a2b","source":"clob_market_ws"},"received_at":"2026-07-28T03:03:47.316399Z","record_id":"0c26a5b81635f0bfb783db294e0cf104906d61969218e408758f7a89eecd6d0c","schema_fingerprint":"4aa3821a28b0b7c2400bc59aba4bcc0a76e971dadd19610d3ad38c768e124dc7","schema_version":"edge-lab-recorder.raw.v1","sequence":null,"source":"clob_market_ws"}
{"event_at":"2026-07-28T03:03:47.448000Z","event_fingerprint":"1e022064f68f7eed2b900c3aba4595499c6898d9cd629e59ece8e399531b652f","payload":{"connection_id":"a6b55582af5f430fb37ad02bf0922475","event_at":"2026-07-28T03:03:47.448000Z","event_type":"price_change","frame_hash":"b88f7cecc99cc58128c16dfe90d8db1d602fe46671f667f9a922c759635cc511","frame_index":0,"kind":"data","monotonic_ns":309810338022416,"payload":{"event_type":"price_change","market":"0x779291bef19b6709f61e9764a954aafe9ffae488d50ae674aabdcb4f248006d5","price_changes":[{"asset_id":"14965588658799411272385430903075831224615961675357217884735713260981483529984","best_ask":"0.63","best_bid":"0.62","hash":"8b531acabdfa2b0343744306c6ac0aac5bbb3f52","price":"0.04","side":"BUY","size":"668.09"},{"asset_id":"8761897749749422724209054078244794145777693856614463256546737399611489089783","best_ask":"0.38","best_bid":"0.37","hash":"4aa17847198bd00497a3508d6226024b0c9a5daa","price":"0.96","side":"SELL","size":"668.09"}],"timestamp":"1785207827448"},"payload_hash":"82948f446a9fb2b220f448f2e50eccc701481185734175539a5468608df8428f","raw_frame":"{\"market\":\"0x779291bef19b6709f61e9764a954aafe9ffae488d50ae674aabdcb4f248006d5\", \"price_changes\":[{\"asset_id\":\"14965588658799411272385430903075831224615961675357217884735713260981483529984\", \"price\":\"0.04\", \"size\":\"668.09\", \"side\":\"BUY\", \"hash\":\"8b531acabdfa2b0343744306c6ac0aac5bbb3f52\", \"best_bid\":\"0.62\", \"best_ask\":\"0.63\"}, {\"asset_id\":\"8761897749749422724209054078244794145777693856614463256546737399611489089783\", \"price\":\"0.96\", \"size\":\"668.09\", \"side\":\"SELL\", \"hash\":\"4aa17847198bd00497a3508d6226024b0c9a5daa\", \"best_bid\":\"0.37\", \"best_ask\":\"0.38\"}], \"timestamp\":\"1785207827448\", \"event_type\":\"price_change\"}","received_at":"2026-07-28T03:03:47.318015Z","schema_version":"clob-market-ws.price_change.v1","sequence":null,"server_hash":null,"server_timestamp":"1785207827448","session_id":"3e519d9098404c15b234d96025eb1a2b","source":"clob_market_ws"},"received_at":"2026-07-28T03:03:47.318015Z","record_id":"521513679f2b49b14804892652fe559a392dd9b335ed29e52aabd30f57322639","schema_fingerprint":"4aa3821a28b0b7c2400bc59aba4bcc0a76e971dadd19610d3ad38c768e124dc7","schema_version":"edge-lab-recorder.raw.v1","sequence":null,"source":"clob_market_ws"}
{"event_at":"2026-07-28T03:03:47.451000Z","event_fingerprint":"affb676b75c93ec370f06f1e607e793a2efb9a492e0341b995efa4fa305bb9d4","payload":{"connection_id":"a6b55582af5f430fb37ad02bf0922475","event_at":"2026-07-28T03:03:47.451000Z","event_type":"price_change","frame_hash":"f2de58cddc332ce97083f5f6ff66829ea45e4fadf671ba1e07c7b9ae36ad6f32","frame_index":0,"kind":"data","monotonic_ns":309810339592875,"payload":{"event_type":"price_change","market":"0x779291bef19b6709f61e9764a954aafe9ffae488d50ae674aabdcb4f248006d5","price_changes":[{"asset_id":"8761897749749422724209054078244794145777693856614463256546737399611489089783","best_ask":"0.38","best_bid":"0.37","hash":"b15bbcffaaabd7359e3c40b031e7aa6f60f21626","price":"0.37","side":"BUY","size":"305.2"},{"asset_id":"14965588658799411272385430903075831224615961675357217884735713260981483529984","best_ask":"0.63","best_bid":"0.62","hash":"0ccda91dcac9757c01a0a9debd7584e6b18c15bd","price":"0.63","side":"SELL","size":"305.2"}],"timestamp":"1785207827451"},"payload_hash":"ce31255ae0bd09dac733472177706035fd3d61b293174e84a59d007fd28fe650","raw_frame":"{\"market\":\"0x779291bef19b6709f61e9764a954aafe9ffae488d50ae674aabdcb4f248006d5\", \"price_changes\":[{\"asset_id\":\"8761897749749422724209054078244794145777693856614463256546737399611489089783\", \"price\":\"0.37\", \"size\":\"305.2\", \"side\":\"BUY\", \"hash\":\"b15bbcffaaabd7359e3c40b031e7aa6f60f21626\", \"best_bid\":\"0.37\", \"best_ask\":\"0.38\"}, {\"asset_id\":\"14965588658799411272385430903075831224615961675357217884735713260981483529984\", \"price\":\"0.63\", \"size\":\"305.2\", \"side\":\"SELL\", \"hash\":\"0ccda91dcac9757c01a0a9debd7584e6b18c15bd\", \"best_bid\":\"0.62\", \"best_ask\":\"0.63\"}], \"timestamp\":\"1785207827451\", \"event_type\":\"price_change\"}","received_at":"2026-07-28T03:03:47.319587Z","schema_version":"clob-market-ws.price_change.v1","sequence":null,"server_hash":null,"server_timestamp":"1785207827451","session_id":"3e519d9098404c15b234d96025eb1a2b","source":"clob_market_ws"},"received_at":"2026-07-28T03:03:47.319587Z","record_id":"cd2868d66e8b1d5a11f8bd80c8c046fdfe5d0cd8af37696279d96b96c8e53e7a","schema_fingerprint":"4aa3821a28b0b7c2400bc59aba4bcc0a76e971dadd19610d3ad38c768e124dc7","schema_version":"edge-lab-recorder.raw.v1","sequence":null,"source":"clob_market_ws"}
{"event_at":"2026-07-28T03:03:47.547000Z","event_fingerprint":"93c40eb277e3994486d0611d4266e4098788bada2a4d06700db34678db019f98","payload":{"connection_id":"a6b55582af5f430fb37ad02bf0922475","event_at":"2026-07-28T03:03:47.547000Z","event_type":"price_change","frame_hash":"a252ef8675e91c9d978ea94bb4045fdea50717a14aac67105f7a2f307ebad648","frame_index":0,"kind":"data","monotonic_ns":309810418094458,"payload":{"event_type":"price_change","market":"0x779291bef19b6709f61e9764a954aafe9ffae488d50ae674aabdcb4f248006d5","price_changes":[{"asset_id":"14965588658799411272385430903075831224615961675357217884735713260981483529984","best_ask":"0.63","best_bid":"0.62","hash":"5b15ead190d118dfd9f18906ff40ff3cabca1fce","price":"0.01","side":"BUY","size":"7888.02"},{"asset_id":"8761897749749422724209054078244794145777693856614463256546737399611489089783","best_ask":"0.38","best_bid":"0.37","hash":"8366bfdcd56cd18cc660237a715f0c2340bb4c8d","price":"0.99","side":"SELL","size":"7888.02"}],"timestamp":"1785207827547"},"payload_hash":"6a10a4e95b9f014932c170b3ab24d6231f46837b4b679c0f7580591a06caecbc","raw_frame":"{\"market\":\"0x779291bef19b6709f61e9764a954aafe9ffae488d50ae674aabdcb4f248006d5\", \"price_changes\":[{\"asset_id\":\"14965588658799411272385430903075831224615961675357217884735713260981483529984\", \"price\":\"0.01\", \"size\":\"7888.02\", \"side\":\"BUY\", \"hash\":\"5b15ead190d118dfd9f18906ff40ff3cabca1fce\", \"best_bid\":\"0.62\", \"best_ask\":\"0.63\"}, {\"asset_id\":\"8761897749749422724209054078244794145777693856614463256546737399611489089783\", \"price\":\"0.99\", \"size\":\"7888.02\", \"side\":\"SELL\", \"hash\":\"8366bfdcd56cd18cc660237a715f0c2340bb4c8d\", \"best_bid\":\"0.37\", \"best_ask\":\"0.38\"}], \"timestamp\":\"1785207827547\", \"event_type\":\"price_change\"}","received_at":"2026-07-28T03:03:47.398079Z","schema_version":"clob-market-ws.price_change.v1","sequence":null,"server_hash":null,"server_timestamp":"1785207827547","session_id":"3e519d9098404c15b234d96025eb1a2b","source":"clob_market_ws"},"received_at":"2026-07-28T03:03:47.398079Z","record_id":"dd6c5b7ec4a151a9a8aba8d8d1d50597cb43a8b8d226daf12251e449a4978e59","schema_fingerprint":"4aa3821a28b0b7c2400bc59aba4bcc0a76e971dadd19610d3ad38c768e124dc7","schema_version":"edge-lab-recorder.raw.v1","sequence":null,"source":"clob_market_ws"}
{"event_at":"2026-07-28T03:03:47.584000Z","event_fingerprint":"d2ed1872f3d13861a124cfda2b3b5b66616f349a11b485b0e4c433081562765f","payload":{"connection_id":"a6b55582af5f430fb37ad02bf0922475","event_at":"2026-07-28T03:03:47.584000Z","event_type":"price_change","frame_hash":"eac465864499ddd20f312568ddf489e95dfacd1a00eb8b638b5a96aa3392bb9b","frame_index":0,"kind":"data","monotonic_ns":309810459087958,"payload":{"event_type":"price_change","market":"0x779291bef19b6709f61e9764a954aafe9ffae488d50ae674aabdcb4f248006d5","price_changes":[{"asset_id":"14965588658799411272385430903075831224615961675357217884735713260981483529984","best_ask":"0.63","best_bid":"0.62","hash":"b142f35efa8a77e8ac3e670f535dea13ee0c5226","price":"0.03","side":"BUY","size":"638.1"},{"asset_id":"8761897749749422724209054078244794145777693856614463256546737399611489089783","best_ask":"0.38","best_bid":"0.37","hash":"e02510b75026dd387f7f012ec289f9ffa19e96cc","price":"0.97","side":"SELL","size":"638.1"}],"timestamp":"1785207827584"},"payload_hash":"75092e43326b5a9505d79a2ffbf3187c3fe98fe7ec908509320bc4d39318b1e6","raw_frame":"{\"market\":\"0x779291bef19b6709f61e9764a954aafe9ffae488d50ae674aabdcb4f248006d5\", \"price_changes\":[{\"asset_id\":\"14965588658799411272385430903075831224615961675357217884735713260981483529984\", \"price\":\"0.03\", \"size\":\"638.1\", \"side\":\"BUY\", \"hash\":\"b142f35efa8a77e8ac3e670f535dea13ee0c5226\", \"best_bid\":\"0.62\", \"best_ask\":\"0.63\"}, {\"asset_id\":\"8761897749749422724209054078244794145777693856614463256546737399611489089783\", \"price\":\"0.97\", \"size\":\"638.1\", \"side\":\"SELL\", \"hash\":\"e02510b75026dd387f7f012ec289f9ffa19e96cc\", \"best_bid\":\"0.37\", \"best_ask\":\"0.38\"}], \"timestamp\":\"1785207827584\", \"event_type\":\"price_change\"}","received_at":"2026-07-28T03:03:47.439078Z","schema_version":"clob-market-ws.price_change.v1","sequence":null,"server_hash":null,"server_timestamp":"1785207827584","session_id":"3e519d9098404c15b234d96025eb1a2b","source":"clob_market_ws"},"received_at":"2026-07-28T03:03:47.439078Z","record_id":"30de4ac7f0567a21e3fff50e4c20f739c40c80eadeaadbb8751b03bc9e334f00","schema_fingerprint":"4aa3821a28b0b7c2400bc59aba4bcc0a76e971dadd19610d3ad38c768e124dc7","schema_version":"edge-lab-recorder.raw.v1","sequence":null,"source":"clob_market_ws"}
{"event_at":"2026-07-28T03:03:47.585000Z","event_fingerprint":"dbdae3b4d4ccefdd92638095c25b9be4b1f26dd29307765579e36c8bbbc63d63","payload":{"connection_id":"a6b55582af5f430fb37ad02bf0922475","event_at":"2026-07-28T03:03:47.585000Z","event_type":"price_change","frame_hash":"8bed0887cb17a5c2d53cb2eb0756f1e4ff98386db5992a7b607f796b2d71ca03","frame_index":0,"kind":"data","monotonic_ns":309810460689625,"payload":{"event_type":"price_change","market":"0x779291bef19b6709f61e9764a954aafe9ffae488d50ae674aabdcb4f248006d5","price_changes":[{"asset_id":"14965588658799411272385430903075831224615961675357217884735713260981483529984","best_ask":"0.63","best_bid":"0.62","hash":"bf25ef408f94d5326e945c80ebff379bbce724d4","price":"0.01","side":"BUY","size":"7883.02"},{"asset_id":"8761897749749422724209054078244794145777693856614463256546737399611489089783","best_ask":"0.38","best_bid":"0.37","hash":"0b64ec72e55fefb4d7c415ff4fa0e3681a4ba1cb","price":"0.99","side":"SELL","size":"7883.02"}],"timestamp":"1785207827585"},"payload_hash":"884b3e37766903e27937dc6fb9128353648f418aeffeaacdc3146c56611c24a9","raw_frame":"{\"market\":\"0x779291bef19b6709f61e9764a954aafe9ffae488d50ae674aabdcb4f248006d5\", \"price_changes\":[{\"asset_id\":\"14965588658799411272385430903075831224615961675357217884735713260981483529984\", \"price\":\"0.01\", \"size\":\"7883.02\", \"side\":\"BUY\", \"hash\":\"bf25ef408f94d5326e945c80ebff379bbce724d4\", \"best_bid\":\"0.62\", \"best_ask\":\"0.63\"}, {\"asset_id\":\"8761897749749422724209054078244794145777693856614463256546737399611489089783\", \"price\":\"0.99\", \"size\":\"7883.02\", \"side\":\"SELL\", \"hash\":\"0b64ec72e55fefb4d7c415ff4fa0e3681a4ba1cb\", \"best_bid\":\"0.37\", \"best_ask\":\"0.38\"}], \"timestamp\":\"1785207827585\", \"event_type\":\"price_change\"}","received_at":"2026-07-28T03:03:47.440679Z","schema_version":"clob-market-ws.price_change.v1","sequence":null,"server_hash":null,"server_timestamp":"1785207827585","session_id":"3e519d9098404c15b234d96025eb1a2b","source":"clob_market_ws"},"received_at":"2026-07-28T03:03:47.440679Z","record_id":"6b3d4b760bbf272fa85e6ae6a8ddacdf75a97a52267953f67e9ee9f7a21ef7b7","schema_fingerprint":"4aa3821a28b0b7c2400bc59aba4bcc0a76e971dadd19610d3ad38c768e124dc7","schema_version":"edge-lab-recorder.raw.v1","sequence":null,"source":"clob_market_ws"}
{"event_at":"2026-07-28T03:03:47.714000Z","event_fingerprint":"0460668b2e8431bf41fc8c48e9fcc85215846d4c08dd9798ec2bbb1c3bd4b0b2","payload":{"connection_id":"a6b55582af5f430fb37ad02bf0922475","event_at":"2026-07-28T03:03:47.714000Z","event_type":"price_change","frame_hash":"70d7bbec66f8145cb3ab9341653020ad9182362837f509c2442269a128c08c3d","frame_index":0,"kind":"data","monotonic_ns":309810594001833,"payload":{"event_type":"price_change","market":"0x779291bef19b6709f61e9764a954aafe9ffae488d50ae674aabdcb4f248006d5","price_changes":[{"asset_id":"14965588658799411272385430903075831224615961675357217884735713260981483529984","best_ask":"0.63","best_bid":"0.62","hash":"f208e179d366a9bd2a96a0d90c2b05c67261e809","price":"0.03","side":"BUY","size":"633.1"},{"asset_id":"8761897749749422724209054078244794145777693856614463256546737399611489089783","best_ask":"0.38","best_bid":"0.37","hash":"ded3f23b16d1d9852a2957bfcf02116db64fc955","price":"0.97","side":"SELL","size":"633.1"}],"timestamp":"1785207827714"},"payload_hash":"0d892dc085418f0df147b4b73913a2781cd953a8c7a3e8dd81e5ba35b6e91e39","raw_frame":"{\"market\":\"0x779291bef19b6709f61e9764a954aafe9ffae488d50ae674aabdcb4f248006d5\", \"price_changes\":[{\"asset_id\":\"14965588658799411272385430903075831224615961675357217884735713260981483529984\", \"price\":\"0.03\", \"size\":\"633.1\", \"side\":\"BUY\", \"hash\":\"f208e179d366a9bd2a96a0d90c2b05c67261e809\", \"best_bid\":\"0.62\", \"best_ask\":\"0.63\"}, {\"asset_id\":\"8761897749749422724209054078244794145777693856614463256546737399611489089783\", \"price\":\"0.97\", \"size\":\"633.1\", \"side\":\"SELL\", \"hash\":\"ded3f23b16d1d9852a2957bfcf02116db64fc955\", \"best_bid\":\"0.37\", \"best_ask\":\"0.38\"}], \"timestamp\":\"1785207827714\", \"event_type\":\"price_change\"}","received_at":"2026-07-28T03:03:47.573987Z","schema_version":"clob-market-ws.price_change.v1","sequence":null,"server_hash":null,"server_timestamp":"1785207827714","session_id":"3e519d9098404c15b234d96025eb1a2b","source":"clob_market_ws"},"received_at":"2026-07-28T03:03:47.573987Z","record_id":"d21ee407789654c4509de3cead5b5922cf7605225768eea3bf0ddc43f04edc7d","schema_fingerprint":"4aa3821a28b0b7c2400bc59aba4bcc0a76e971dadd19610d3ad38c768e124dc7","schema_version":"edge-lab-recorder.raw.v1","sequence":null,"source":"clob_market_ws"}
{"event_at":"2026-07-28T03:03:47.717000Z","event_fingerprint":"a82602176d6be35449251584a8401f4af9aba1360b29be3aaf18a1565bc1805a","payload":{"connection_id":"a6b55582af5f430fb37ad02bf0922475","event_at":"2026-07-28T03:03:47.717000Z","event_type":"price_change","frame_hash":"52430301925b86a276d081fe95ede121f2d93fd7bc0fd1103e5091ecbbc4e0fe","frame_index":0,"kind":"data","monotonic_ns":309810595751708,"payload":{"event_type":"price_change","market":"0x779291bef19b6709f61e9764a954aafe9ffae488d50ae674aabdcb4f248006d5","price_changes":[{"asset_id":"14965588658799411272385430903075831224615961675357217884735713260981483529984","best_ask":"0.63","best_bid":"0.62","hash":"0e85a07904b9823516b384197271dd5211744501","price":"0.01","side":"BUY","size":"7888.02"},{"asset_id":"8761897749749422724209054078244794145777693856614463256546737399611489089783","best_ask":"0.38","best_bid":"0.37","hash":"f7386e01d9762ce2e5733fc350d2260d86971545","price":"0.99","side":"SELL","size":"7888.02"}],"timestamp":"1785207827717"},"payload_hash":"24e4dee59997011e30dcb5440c11c592162e5ab8a8deaec2e17756d48d8f9f55","raw_frame":"{\"market\":\"0x779291bef19b6709f61e9764a954aafe9ffae488d50ae674aabdcb4f248006d5\", \"price_changes\":[{\"asset_id\":\"14965588658799411272385430903075831224615961675357217884735713260981483529984\", \"price\":\"0.01\", \"size\":\"7888.02\", \"side\":\"BUY\", \"hash\":\"0e85a07904b9823516b384197271dd5211744501\", \"best_bid\":\"0.62\", \"best_ask\":\"0.63\"}, {\"asset_id\":\"8761897749749422724209054078244794145777693856614463256546737399611489089783\", \"price\":\"0.99\", \"size\":\"7888.02\", \"side\":\"SELL\", \"hash\":\"f7386e01d9762ce2e5733fc350d2260d86971545\", \"best_bid\":\"0.37\", \"best_ask\":\"0.38\"}], \"timestamp\":\"1785207827717\", \"event_type\":\"price_change\"}","received_at":"2026-07-28T03:03:47.575740Z","schema_version":"clob-market-ws.price_change.v1","sequence":null,"server_hash":null,"server_timestamp":"1785207827717","session_id":"3e519d9098404c15b234d96025eb1a2b","source":"clob_market_ws"},"received_at":"2026-07-28T03:03:47.575740Z","record_id":"4ed8dfc4c1d61494bd5f0c8e1b0e283bf8780f2ce325957203f35507d7936c66","schema_fingerprint":"4aa3821a28b0b7c2400bc59aba4bcc0a76e971dadd19610d3ad38c768e124dc7","schema_version":"edge-lab-recorder.raw.v1","sequence":null,"source":"clob_market_ws"}
{"event_at":"2026-07-28T03:03:47.741000Z","event_fingerprint":"0b4c9947fd7ec9579f96b6dec7617382a9b3105558f5b3591d8a41412aedf939","payload":{"connection_id":"a6b55582af5f430fb37ad02bf0922475","event_at":"2026-07-28T03:03:47.741000Z","event_type":"price_change","frame_hash":"f5e5d4c7e594c589284ca57cf712a482b6feb86e5496192d0cf2bdaeb3bed5a4","frame_index":0,"kind":"data","monotonic_ns":309810612038000,"payload":{"event_type":"price_change","market":"0x779291bef19b6709f61e9764a954aafe9ffae488d50ae674aabdcb4f248006d5","price_changes":[{"asset_id":"14965588658799411272385430903075831224615961675357217884735713260981483529984","best_ask":"0.63","best_bid":"0.62","hash":"58b69df3a949feeb109b83b8ceae1358520ccb17","price":"0.01","side":"BUY","size":"7883.02"},{"asset_id":"8761897749749422724209054078244794145777693856614463256546737399611489089783","best_ask":"0.38","best_bid":"0.37","hash":"81d41a2b0d3721cf9c2fd42ec43deff3bc5702b6","price":"0.99","side":"SELL","size":"7883.02"}],"timestamp":"1785207827741"},"payload_hash":"0f5540eae1898999496c2ea4c29c18dd40b1582ee07f67c43649f4717101b7d2","raw_frame":"{\"market\":\"0x779291bef19b6709f61e9764a954aafe9ffae488d50ae674aabdcb4f248006d5\", \"price_changes\":[{\"asset_id\":\"14965588658799411272385430903075831224615961675357217884735713260981483529984\", \"price\":\"0.01\", \"size\":\"7883.02\", \"side\":\"BUY\", \"hash\":\"58b69df3a949feeb109b83b8ceae1358520ccb17\", \"best_bid\":\"0.62\", \"best_ask\":\"0.63\"}, {\"asset_id\":\"8761897749749422724209054078244794145777693856614463256546737399611489089783\", \"price\":\"0.99\", \"size\":\"7883.02\", \"side\":\"SELL\", \"hash\":\"81d41a2b0d3721cf9c2fd42ec43deff3bc5702b6\", \"best_bid\":\"0.37\", \"best_ask\":\"0.38\"}], \"timestamp\":\"1785207827741\", \"event_type\":\"price_change\"}","received_at":"2026-07-28T03:03:47.592029Z","schema_version":"clob-market-ws.price_change.v1","sequence":null,"server_hash":null,"server_timestamp":"1785207827741","session_id":"3e519d9098404c15b234d96025eb1a2b","source":"clob_market_ws"},"received_at":"2026-07-28T03:03:47.592029Z","record_id":"18ef7241d834a992096472f9531b1a74b71134fc2ef4b490926ce60e91501dbf","schema_fingerprint":"4aa3821a28b0b7c2400bc59aba4bcc0a76e971dadd19610d3ad38c768e124dc7","schema_version":"edge-lab-recorder.raw.v1","sequence":null,"source":"clob_market_ws"}
{"event_at":"2026-07-28T03:03:47.799000Z","event_fingerprint":"0fcb27c6c35441a3f0b2460516e15404582bf80c57e2abbaf5554d26d6f8b241","payload":{"connection_id":"a6b55582af5f430fb37ad02bf0922475","event_at":"2026-07-28T03:03:47.799000Z","event_type":"price_change","frame_hash":"3efa49cc847052c0692491eaaf214555b7906d6d69e8aa780024bf0c698babb7","frame_index":0,"kind":"data","monotonic_ns":309810669761208,"payload":{"event_type":"price_change","market":"0x779291bef19b6709f61e9764a954aafe9ffae488d50ae674aabdcb4f248006d5","price_changes":[{"asset_id":"14965588658799411272385430903075831224615961675357217884735713260981483529984","best_ask":"0.63","best_bid":"0.62","hash":"090daa2e9e5ea41effcc20550dd4c12b87db5cda","price":"0.04","side":"BUY","size":"673.09"},{"asset_id":"8761897749749422724209054078244794145777693856614463256546737399611489089783","best_ask":"0.38","best_bid":"0.37","hash":"b32ac18c2f416a2c6bba8e18b510745675ffdadc","price":"0.96","side":"SELL","size":"673.09"}],"timestamp":"1785207827799"},"payload_hash":"ccb7211553437c4d56099bd93101595a2185a20d269bf479a0f8c84269070023","raw_frame":"{\"market\":\"0x779291bef19b6709f61e9764a954aafe9ffae488d50ae674aabdcb4f248006d5\", \"price_changes\":[{\"asset_id\":\"14965588658799411272385430903075831224615961675357217884735713260981483529984\", \"price\":\"0.04\", \"size\":\"673.09\", \"side\":\"BUY\", \"hash\":\"090daa2e9e5ea41effcc20550dd4c12b87db5cda\", \"best_bid\":\"0.62\", \"best_ask\":\"0.63\"}, {\"asset_id\":\"8761897749749422724209054078244794145777693856614463256546737399611489089783\", \"price\":\"0.96\", \"size\":\"673.09\", \"side\":\"SELL\", \"hash\":\"b32ac18c2f416a2c6bba8e18b510745675ffdadc\", \"best_bid\":\"0.37\", \"best_ask\":\"0.38\"}], \"timestamp\":\"1785207827799\", \"event_type\":\"price_change\"}","received_at":"2026-07-28T03:03:47.649752Z","schema_version":"clob-market-ws.price_change.v1","sequence":null,"server_hash":null,"server_timestamp":"1785207827799","session_id":"3e519d9098404c15b234d96025eb1a2b","source":"clob_market_ws"},"received_at":"2026-07-28T03:03:47.649752Z","record_id":"535d89791b5391f702d5423976125534c3f5d6c22bdbc19a0811486f1e723dd8","schema_fingerprint":"4aa3821a28b0b7c2400bc59aba4bcc0a76e971dadd19610d3ad38c768e124dc7","schema_version":"edge-lab-recorder.raw.v1","sequence":null,"source":"clob_market_ws"}
{"event_at":"2026-07-28T03:03:47.900000Z","event_fingerprint":"4334693e1d5564027c6803c9ac2430324b3f68f7b6b793955e8cb7e3ac172da6","payload":{"connection_id":"a6b55582af5f430fb37ad02bf0922475","event_at":"2026-07-28T03:03:47.900000Z","event_type":"price_change","frame_hash":"467ede43366bce735db835344982580aaa8e45e71410f67b685fb3cc05b61c46","frame_index":0,"kind":"data","monotonic_ns":309810786011791,"payload":{"event_type":"price_change","market":"0x779291bef19b6709f61e9764a954aafe9ffae488d50ae674aabdcb4f248006d5","price_changes":[{"asset_id":"14965588658799411272385430903075831224615961675357217884735713260981483529984","best_ask":"0.63","best_bid":"0.62","hash":"54f86cd963b9efe0e22da53e1c824e7c543a7b34","price":"0.04","side":"BUY","size":"668.09"},{"asset_id":"8761897749749422724209054078244794145777693856614463256546737399611489089783","best_ask":"0.38","best_bid":"0.37","hash":"8b2209e4b4eb0a0d1fb1d7738f724b60069f0680","price":"0.96","side":"SELL","size":"668.09"}],"timestamp":"1785207827900"},"payload_hash":"958e2d94b8dcfa02f527d7466ca6f0950874fa011dee6a0feb46ae3e6af80e4b","raw_frame":"{\"market\":\"0x779291bef19b6709f61e9764a954aafe9ffae488d50ae674aabdcb4f248006d5\", \"price_changes\":[{\"asset_id\":\"14965588658799411272385430903075831224615961675357217884735713260981483529984\", \"price\":\"0.04\", \"size\":\"668.09\", \"side\":\"BUY\", \"hash\":\"54f86cd963b9efe0e22da53e1c824e7c543a7b34\", \"best_bid\":\"0.62\", \"best_ask\":\"0.63\"}, {\"asset_id\":\"8761897749749422724209054078244794145777693856614463256546737399611489089783\", \"price\":\"0.96\", \"size\":\"668.09\", \"side\":\"SELL\", \"hash\":\"8b2209e4b4eb0a0d1fb1d7738f724b60069f0680\", \"best_bid\":\"0.37\", \"best_ask\":\"0.38\"}], \"timestamp\":\"1785207827900\", \"event_type\":\"price_change\"}","received_at":"2026-07-28T03:03:47.765997Z","schema_version":"clob-market-ws.price_change.v1","sequence":null,"server_hash":null,"server_timestamp":"1785207827900","session_id":"3e519d9098404c15b234d96025eb1a2b","source":"clob_market_ws"},"received_at":"2026-07-28T03:03:47.765997Z","record_id":"25e7d796f8408fde9030b0b32e1dd77a702e2d0dac91d787144c51921edb9fbf","schema_fingerprint":"4aa3821a28b0b7c2400bc59aba4bcc0a76e971dadd19610d3ad38c768e124dc7","schema_version":"edge-lab-recorder.raw.v1","sequence":null,"source":"clob_market_ws"}
{"event_at":"2026-07-28T03:03:47.996000Z","event_fingerprint":"a5c12e1557a4cc2529de3a31e7b52747b1d4f9a7029aa54332c3204fea981a4b","payload":{"connection_id":"a6b55582af5f430fb37ad02bf0922475","event_at":"2026-07-28T03:03:47.996000Z","event_type":"price_change","frame_hash":"42a75668b756410bcd39b1f3babb0b8d89d85a515a22c1dfab00d83a961379de","frame_index":0,"kind":"data","monotonic_ns":309810867559166,"payload":{"event_type":"price_change","market":"0x779291bef19b6709f61e9764a954aafe9ffae488d50ae674aabdcb4f248006d5","price_changes":[{"asset_id":"14965588658799411272385430903075831224615961675357217884735713260981483529984","best_ask":"0.63","best_bid":"0.62","hash":"93e3d3c60e516461251720ddfdcff6d27c55f2f3","price":"0.04","side":"BUY","size":"673.09"},{"asset_id":"8761897749749422724209054078244794145777693856614463256546737399611489089783","best_ask":"0.38","best_bid":"0.37","hash":"43e063d659d4573753df5e0171b39fe3d8678159","price":"0.96","side":"SELL","size":"673.09"}],"timestamp":"1785207827996"},"payload_hash":"3127f3c8263ba4342fcb110eff9228b854b6b76f7449fd636d4910690174ed7f","raw_frame":"{\"market\":\"0x779291bef19b6709f61e9764a954aafe9ffae488d50ae674aabdcb4f248006d5\", \"price_changes\":[{\"asset_id\":\"14965588658799411272385430903075831224615961675357217884735713260981483529984\", \"price\":\"0.04\", \"size\":\"673.09\", \"side\":\"BUY\", \"hash\":\"93e3d3c60e516461251720ddfdcff6d27c55f2f3\", \"best_bid\":\"0.62\", \"best_ask\":\"0.63\"}, {\"asset_id\":\"8761897749749422724209054078244794145777693856614463256546737399611489089783\", \"price\":\"0.96\", \"size\":\"673.09\", \"side\":\"SELL\", \"hash\":\"43e063d659d4573753df5e0171b39fe3d8678159\", \"best_bid\":\"0.37\", \"best_ask\":\"0.38\"}], \"timestamp\":\"1785207827996\", \"event_type\":\"price_change\"}","received_at":"2026-07-28T03:03:47.847548Z","schema_version":"clob-market-ws.price_change.v1","sequence":null,"server_hash":null,"server_timestamp":"1785207827996","session_id":"3e519d9098404c15b234d96025eb1a2b","source":"clob_market_ws"},"received_at":"2026-07-28T03:03:47.847548Z","record_id":"5bb5fdf9b8bdcd8456fca94392e61680f74bf175a46bd9093f2bb2cd5ca3305a","schema_fingerprint":"4aa3821a28b0b7c2400bc59aba4bcc0a76e971dadd19610d3ad38c768e124dc7","schema_version":"edge-lab-recorder.raw.v1","sequence":null,"source":"clob_market_ws"}
{"event_at":"2026-07-28T03:03:48.017000Z","event_fingerprint":"d3247c72721efd9f6364d34cfaabcafeefecf847c7e6a7eb0962c98b54da8340","payload":{"connection_id":"a6b55582af5f430fb37ad02bf0922475","event_at":"2026-07-28T03:03:48.017000Z","event_type":"price_change","frame_hash":"66e3b131ef49bee1fa10a1e737d51764be16255d2196387d3ab665b820900ea7","frame_index":0,"kind":"data","monotonic_ns":309810889255541,"payload":{"event_type":"price_change","market":"0x779291bef19b6709f61e9764a954aafe9ffae488d50ae674aabdcb4f248006d5","price_changes":[{"asset_id":"8761897749749422724209054078244794145777693856614463256546737399611489089783","best_ask":"0.38","best_bid":"0.37","hash":"ab53f3d0dceb8b1601a14dc5362f43503db94307","price":"0.01","side":"BUY","size":"7858.02"},{"asset_id":"14965588658799411272385430903075831224615961675357217884735713260981483529984","best_ask":"0.63","best_bid":"0.62","hash":"10c17cd14fe23007bb4aba4c72e5a155fe30d766","price":"0.99","side":"SELL","size":"7858.02"}],"timestamp":"1785207828017"},"payload_hash":"4f5e7d8b2c56b659cea46e0f03e8aecefe75b179a3f5eaa27fc3682474a4fc58","raw_frame":"{\"market\":\"0x779291bef19b6709f61e9764a954aafe9ffae488d50ae674aabdcb4f248006d5\", \"price_changes\":[{\"asset_id\":\"8761897749749422724209054078244794145777693856614463256546737399611489089783\", \"price\":\"0.01\", \"size\":\"7858.02\", \"side\":\"BUY\", \"hash\":\"ab53f3d0dceb8b1601a14dc5362f43503db94307\", \"best_bid\":\"0.37\", \"best_ask\":\"0.38\"}, {\"asset_id\":\"14965588658799411272385430903075831224615961675357217884735713260981483529984\", \"price\":\"0.99\", \"size\":\"7858.02\", \"side\":\"SELL\", \"hash\":\"10c17cd14fe23007bb4aba4c72e5a155fe30d766\", \"best_bid\":\"0.62\", \"best_ask\":\"0.63\"}], \"timestamp\":\"1785207828017\", \"event_type\":\"price_change\"}","received_at":"2026-07-28T03:03:47.869244Z","schema_version":"clob-market-ws.price_change.v1","sequence":null,"server_hash":null,"server_timestamp":"1785207828017","session_id":"3e519d9098404c15b234d96025eb1a2b","source":"clob_market_ws"},"received_at":"2026-07-28T03:03:47.869244Z","record_id":"c305e228c9fb30ed8791ac7ede4051912c19614460f68efd0270f7410b2f64e7","schema_fingerprint":"4aa3821a28b0b7c2400bc59aba4bcc0a76e971dadd19610d3ad38c768e124dc7","schema_version":"edge-lab-recorder.raw.v1","sequence":null,"source":"clob_market_ws"}
{"event_at":"2026-07-28T03:03:48.019000Z","event_fingerprint":"c0e95920ecc6a0e2aaac7a05e6dc225207808496c6dc7de98c4e2f0d2b223a05","payload":{"connection_id":"a6b55582af5f430fb37ad02bf0922475","event_at":"2026-07-28T03:03:48.019000Z","event_type":"price_change","frame_hash":"567d8fc7b1bccf4dfda3430a7e840fa1e902ec0ff0a97ecfd1bf2f8a08e3a3e6","frame_index":0,"kind":"data","monotonic_ns":309810891503291,"payload":{"event_type":"price_change","market":"0x779291bef19b6709f61e9764a954aafe9ffae488d50ae674aabdcb4f248006d5","price_changes":[{"asset_id":"14965588658799411272385430903075831224615961675357217884735713260981483529984","best_ask":"0.63","best_bid":"0.62","hash":"19652f450b9fe68d406479f03ab9312edb33c53a","price":"0.01","side":"BUY","size":"7888.02"},{"asset_id":"8761897749749422724209054078244794145777693856614463256546737399611489089783","best_ask":"0.38","best_bid":"0.37","hash":"e2c5257ac76a07e4d80c0d0acdb44179f4c006ff","price":"0.99","side":"SELL","size":"7888.02"}],"timestamp":"1785207828019"},"payload_hash":"cec1ffd53e815719df806ccdeb5d62f8954a1da32cf1ac0b7994a9e6da5373bd","raw_frame":"{\"market\":\"0x779291bef19b6709f61e9764a954aafe9ffae488d50ae674aabdcb4f248006d5\", \"price_changes\":[{\"asset_id\":\"14965588658799411272385430903075831224615961675357217884735713260981483529984\", \"price\":\"0.01\", \"size\":\"7888.02\", \"side\":\"BUY\", \"hash\":\"19652f450b9fe68d406479f03ab9312edb33c53a\", \"best_bid\":\"0.62\", \"best_ask\":\"0.63\"}, {\"asset_id\":\"8761897749749422724209054078244794145777693856614463256546737399611489089783\", \"price\":\"0.99\", \"size\":\"7888.02\", \"side\":\"SELL\", \"hash\":\"e2c5257ac76a07e4d80c0d0acdb44179f4c006ff\", \"best_bid\":\"0.37\", \"best_ask\":\"0.38\"}], \"timestamp\":\"1785207828019\", \"event_type\":\"price_change\"}","received_at":"2026-07-28T03:03:47.871489Z","schema_version":"clob-market-ws.price_change.v1","sequence":null,"server_hash":null,"server_timestamp":"1785207828019","session_id":"3e519d9098404c15b234d96025eb1a2b","source":"clob_market_ws"},"received_at":"2026-07-28T03:03:47.871489Z","record_id":"c1c2bb1726e039f318ce45445b3ad0d9c409af81aae3dcd6b54bdeb199739c12","schema_fingerprint":"4aa3821a28b0b7c2400bc59aba4bcc0a76e971dadd19610d3ad38c768e124dc7","schema_version":"edge-lab-recorder.raw.v1","sequence":null,"source":"clob_market_ws"}
{"event_at":"2026-07-28T03:03:48.024000Z","event_fingerprint":"438ae07a0a450786775948d1d7a0d93e04591a29011ff92f65356c39bee3e800","payload":{"connection_id":"a6b55582af5f430fb37ad02bf0922475","event_at":"2026-07-28T03:03:48.024000Z","event_type":"price_change","frame_hash":"e5571095c98e14685df93a6171560382af0b0737f0db2b93d345d8638ab35841","frame_index":0,"kind":"data","monotonic_ns":309810896420416,"payload":{"event_type":"price_change","market":"0x779291bef19b6709f61e9764a954aafe9ffae488d50ae674aabdcb4f248006d5","price_changes":[{"asset_id":"8761897749749422724209054078244794145777693856614463256546737399611489089783","best_ask":"0.38","best_bid":"0.37","hash":"f636cf53d6591823b3020ae7476a217f34d972da","price":"0.01","side":"BUY","size":"7863.02"},{"asset_id":"14965588658799411272385430903075831224615961675357217884735713260981483529984","best_ask":"0.63","best_bid":"0.62","hash":"74f95c44ccf53a866dbe1c6dd5b474d8aa04c478","price":"0.99","side":"SELL","size":"7863.02"}],"timestamp":"1785207828024"},"payload_hash":"1cdd98ae8be6e5582e33d8d9ffb5be88c9ab04ad8ee97c4daae0dfe884f7eb15","raw_frame":"{\"market\":\"0x779291bef19b6709f61e9764a954aafe9ffae488d50ae674aabdcb4f248006d5\", \"price_changes\":[{\"asset_id\":\"8761897749749422724209054078244794145777693856614463256546737399611489089783\", \"price\":\"0.01\", \"size\":\"7863.02\", \"side\":\"BUY\", \"hash\":\"f636cf53d6591823b3020ae7476a217f34d972da\", \"best_bid\":\"0.37\", \"best_ask\":\"0.38\"}, {\"asset_id\":\"14965588658799411272385430903075831224615961675357217884735713260981483529984\", \"price\":\"0.99\", \"size\":\"7863.02\", \"side\":\"SELL\", \"hash\":\"74f95c44ccf53a866dbe1c6dd5b474d8aa04c478\", \"best_bid\":\"0.62\", \"best_ask\":\"0.63\"}], \"timestamp\":\"1785207828024\", \"event_type\":\"price_change\"}","received_at":"2026-07-28T03:03:47.876410Z","schema_version":"clob-market-ws.price_change.v1","sequence":null,"server_hash":null,"server_timestamp":"1785207828024","session_id":"3e519d9098404c15b234d96025eb1a2b","source":"clob_market_ws"},"received_at":"2026-07-28T03:03:47.876410Z","record_id":"f56e5b1f955f9972db019979250d28b094b927ea8615cd23a41f8118db3de1b8","schema_fingerprint":"4aa3821a28b0b7c2400bc59aba4bcc0a76e971dadd19610d3ad38c768e124dc7","schema_version":"edge-lab-recorder.raw.v1","sequence":null,"source":"clob_market_ws"}
{"event_at":"2026-07-28T03:03:48.041000Z","event_fingerprint":"a5327771548810c778c51699bda0ef4c5db234833eb816f91196bb99a98ac0f1","payload":{"connection_id":"a6b55582af5f430fb37ad02bf0922475","event_at":"2026-07-28T03:03:48.041000Z","event_type":"price_change","frame_hash":"4a8c03ae3e4921c608fb205702bd113f7024a042628b4468ea504106af4c2093","frame_index":0,"kind":"data","monotonic_ns":309810914375500,"payload":{"event_type":"price_change","market":"0x779291bef19b6709f61e9764a954aafe9ffae488d50ae674aabdcb4f248006d5","price_changes":[{"asset_id":"14965588658799411272385430903075831224615961675357217884735713260981483529984","best_ask":"0.63","best_bid":"0.62","hash":"36fcc0470afa77450fb8d8c6a36dc05db5712d9d","price":"0.01","side":"BUY","size":"7883.02"},{"asset_id":"8761897749749422724209054078244794145777693856614463256546737399611489089783","best_ask":"0.38","best_bid":"0.37","hash":"056c5050f250f47ea0399164f6ff1877a66ae588","price":"0.99","side":"SELL","size":"7883.02"}],"timestamp":"1785207828041"},"payload_hash":"821d63f33e2534dbb014d518acd27df516fac6fef2455df6e400367f49d30e39","raw_frame":"{\"market\":\"0x779291bef19b6709f61e9764a954aafe9ffae488d50ae674aabdcb4f248006d5\", \"price_changes\":[{\"asset_id\":\"14965588658799411272385430903075831224615961675357217884735713260981483529984\", \"price\":\"0.01\", \"size\":\"7883.02\", \"side\":\"BUY\", \"hash\":\"36fcc0470afa77450fb8d8c6a36dc05db5712d9d\", \"best_bid\":\"0.62\", \"best_ask\":\"0.63\"}, {\"asset_id\":\"8761897749749422724209054078244794145777693856614463256546737399611489089783\", \"price\":\"0.99\", \"size\":\"7883.02\", \"side\":\"SELL\", \"hash\":\"056c5050f250f47ea0399164f6ff1877a66ae588\", \"best_bid\":\"0.37\", \"best_ask\":\"0.38\"}], \"timestamp\":\"1785207828041\", \"event_type\":\"price_change\"}","received_at":"2026-07-28T03:03:47.894365Z","schema_version":"clob-market-ws.price_change.v1","sequence":null,"server_hash":null,"server_timestamp":"1785207828041","session_id":"3e519d9098404c15b234d96025eb1a2b","source":"clob_market_ws"},"received_at":"2026-07-28T03:03:47.894365Z","record_id":"fa5924d7b8fe532a9f81bcd9e6fd27e8f82ed2ab440b1fe1a09e96d36520934d","schema_fingerprint":"4aa3821a28b0b7c2400bc59aba4bcc0a76e971dadd19610d3ad38c768e124dc7","schema_version":"edge-lab-recorder.raw.v1","sequence":null,"source":"clob_market_ws"}
{"event_at":"2026-07-28T03:03:48.042000Z","event_fingerprint":"7708421c03242292a672764c306a6a25b7fda76fda4c10d62eb9c1cd69200f6f","payload":{"connection_id":"a6b55582af5f430fb37ad02bf0922475","event_at":"2026-07-28T03:03:48.042000Z","event_type":"price_change","frame_hash":"cc25805e5d32768db695db9a716d77608679ce3c0d5617dacd2851d0dd9e94dd","frame_index":0,"kind":"data","monotonic_ns":309810915903541,"payload":{"event_type":"price_change","market":"0x779291bef19b6709f61e9764a954aafe9ffae488d50ae674aabdcb4f248006d5","price_changes":[{"asset_id":"8761897749749422724209054078244794145777693856614463256546737399611489089783","best_ask":"0.38","best_bid":"0.37","hash":"96ede07483315078ddda1f60291d7f353e65dccc","price":"0.01","side":"BUY","size":"7858.02"},{"asset_id":"14965588658799411272385430903075831224615961675357217884735713260981483529984","best_ask":"0.63","best_bid":"0.62","hash":"03dff038df7c07994ac4cf65d1da74bdfca69360","price":"0.99","side":"SELL","size":"7858.02"}],"timestamp":"1785207828042"},"payload_hash":"58438902522c9585eb7d10f5e94012c165c6068e0b79aa25c83d7b2e4e41537a","raw_frame":"{\"market\":\"0x779291bef19b6709f61e9764a954aafe9ffae488d50ae674aabdcb4f248006d5\", \"price_changes\":[{\"asset_id\":\"8761897749749422724209054078244794145777693856614463256546737399611489089783\", \"price\":\"0.01\", \"size\":\"7858.02\", \"side\":\"BUY\", \"hash\":\"96ede07483315078ddda1f60291d7f353e65dccc\", \"best_bid\":\"0.37\", \"best_ask\":\"0.38\"}, {\"asset_id\":\"14965588658799411272385430903075831224615961675357217884735713260981483529984\", \"price\":\"0.99\", \"size\":\"7858.02\", \"side\":\"SELL\", \"hash\":\"03dff038df7c07994ac4cf65d1da74bdfca69360\", \"best_bid\":\"0.62\", \"best_ask\":\"0.63\"}], \"timestamp\":\"1785207828042\", \"event_type\":\"price_change\"}","received_at":"2026-07-28T03:03:47.895892Z","schema_version":"clob-market-ws.price_change.v1","sequence":null,"server_hash":null,"server_timestamp":"1785207828042","session_id":"3e519d9098404c15b234d96025eb1a2b","source":"clob_market_ws"},"received_at":"2026-07-28T03:03:47.895892Z","record_id":"a74c90193437c9c0bf3f476ded179b668a39f120fd7ec32583219e666550a756","schema_fingerprint":"4aa3821a28b0b7c2400bc59aba4bcc0a76e971dadd19610d3ad38c768e124dc7","schema_version":"edge-lab-recorder.raw.v1","sequence":null,"source":"clob_market_ws"}
{"event_at":"2026-07-28T03:03:48.051000Z","event_fingerprint":"696f358f3ed57f333a97d4a417054ffcd20a0a3872bb3cde93e94f0b80343184","payload":{"connection_id":"a6b55582af5f430fb37ad02bf0922475","event_at":"2026-07-28T03:03:48.051000Z","event_type":"price_change","frame_hash":"b02d679197f2ae215532956375fdee75f0f290b2f44dbac4fc89920488777544","frame_index":0,"kind":"data","monotonic_ns":309810922741041,"payload":{"event_type":"price_change","market":"0x779291bef19b6709f61e9764a954aafe9ffae488d50ae674aabdcb4f248006d5","price_changes":[{"asset_id":"14965588658799411272385430903075831224615961675357217884735713260981483529984","best_ask":"0.63","best_bid":"0.62","hash":"1dfbff5600103a9ac07e521c22f55dc08898cabf","price":"0.04","side":"BUY","size":"668.09"},{"asset_id":"8761897749749422724209054078244794145777693856614463256546737399611489089783","best_ask":"0.38","best_bid":"0.37","hash":"cb52559f0cadd0f1c102d1dc384a9f8965f58e34","price":"0.96","side":"SELL","size":"668.09"}],"timestamp":"1785207828051"},"payload_hash":"83dbdcab9a206036f626b923426f1a7acb6ba7791847aec15f98013055cbda76","raw_frame":"{\"market\":\"0x779291bef19b6709f61e9764a954aafe9ffae488d50ae674aabdcb4f248006d5\", \"price_changes\":[{\"asset_id\":\"14965588658799411272385430903075831224615961675357217884735713260981483529984\", \"price\":\"0.04\", \"size\":\"668.09\", \"side\":\"BUY\", \"hash\":\"1dfbff5600103a9ac07e521c22f55dc08898cabf\", \"best_bid\":\"0.62\", \"best_ask\":\"0.63\"}, {\"asset_id\":\"8761897749749422724209054078244794145777693856614463256546737399611489089783\", \"price\":\"0.96\", \"size\":\"668.09\", \"side\":\"SELL\", \"hash\":\"cb52559f0cadd0f1c102d1dc384a9f8965f58e34\", \"best_bid\":\"0.37\", \"best_ask\":\"0.38\"}], \"timestamp\":\"1785207828051\", \"event_type\":\"price_change\"}","received_at":"2026-07-28T03:03:47.902730Z","schema_version":"clob-market-ws.price_change.v1","sequence":null,"server_hash":null,"server_timestamp":"1785207828051","session_id":"3e519d9098404c15b234d96025eb1a2b","source":"clob_market_ws"},"received_at":"2026-07-28T03:03:47.902730Z","record_id":"08a79532d8dccde0f8cb224f65d410b4a7e628a8d91f8556c90669c847dfcc0f","schema_fingerprint":"4aa3821a28b0b7c2400bc59aba4bcc0a76e971dadd19610d3ad38c768e124dc7","schema_version":"edge-lab-recorder.raw.v1","sequence":null,"source":"clob_market_ws"}
{"event_at":"2026-07-28T03:03:48.053000Z","event_fingerprint":"6a5c3f73a9268342525ef537e840b0d066f84792f424fa31272a2778d7431598","payload":{"connection_id":"a6b55582af5f430fb37ad02bf0922475","event_at":"2026-07-28T03:03:48.053000Z","event_type":"price_change","frame_hash":"14c8390f00b6df1aa398542f0b822282623b04d1a51ad4ce8bf739d1d917dfe8","frame_index":0,"kind":"data","monotonic_ns":309810924986041,"payload":{"event_type":"price_change","market":"0x779291bef19b6709f61e9764a954aafe9ffae488d50ae674aabdcb4f248006d5","price_changes":[{"asset_id":"8761897749749422724209054078244794145777693856614463256546737399611489089783","best_ask":"0.38","best_bid":"0.37","hash":"124651f373cbf0689edf32f29ef2c78641d56f09","price":"0.01","side":"BUY","size":"7853.02"},{"asset_id":"14965588658799411272385430903075831224615961675357217884735713260981483529984","best_ask":"0.63","best_bid":"0.62","hash":"7ddd00425ef32e00d90d3c12592d70eec7ce4d8a","price":"0.99","side":"SELL","size":"7853.02"}],"timestamp":"1785207828053"},"payload_hash":"d2bd880d2a93ff7e6f8cf5d09106108ffe03405638011a5bb3a824ef5fb2d8dd","raw_frame":"{\"market\":\"0x779291bef19b6709f61e9764a954aafe9ffae488d50ae674aabdcb4f248006d5\", \"price_changes\":[{\"asset_id\":\"8761897749749422724209054078244794145777693856614463256546737399611489089783\", \"price\":\"0.01\", \"size\":\"7853.02\", \"side\":\"BUY\", \"hash\":\"124651f373cbf0689edf32f29ef2c78641d56f09\", \"best_bid\":\"0.37\", \"best_ask\":\"0.38\"}, {\"asset_id\":\"14965588658799411272385430903075831224615961675357217884735713260981483529984\", \"price\":\"0.99\", \"size\":\"7853.02\", \"side\":\"SELL\", \"hash\":\"7ddd00425ef32e00d90d3c12592d70eec7ce4d8a\", \"best_bid\":\"0.62\", \"best_ask\":\"0.63\"}], \"timestamp\":\"1785207828053\", \"event_type\":\"price_change\"}","received_at":"2026-07-28T03:03:47.904974Z","schema_version":"clob-market-ws.price_change.v1","sequence":null,"server_hash":null,"server_timestamp":"1785207828053","session_id":"3e519d9098404c15b234d96025eb1a2b","source":"clob_market_ws"},"received_at":"2026-07-28T03:03:47.904974Z","record_id":"d8c7b5fe486197b95f3010a96da5e695033c539ca2bee58b1101b896d4101dfc","schema_fingerprint":"4aa3821a28b0b7c2400bc59aba4bcc0a76e971dadd19610d3ad38c768e124dc7","schema_version":"edge-lab-recorder.raw.v1","sequence":null,"source":"clob_market_ws"}
{"event_at":"2026-07-28T03:03:48.115000Z","event_fingerprint":"f8d82208bfa54a4830837ed60a3ecd404fc2a778c00d29f10ab18e9bfa281bf8","payload":{"connection_id":"a6b55582af5f430fb37ad02bf0922475","event_at":"2026-07-28T03:03:48.115000Z","event_type":"price_change","frame_hash":"eb3feba7c604728162aac1eeeea11f61651fe94c8d9d03f8504ede561d889952","frame_index":0,"kind":"data","monotonic_ns":309810995263833,"payload":{"event_type":"price_change","market":"0x779291bef19b6709f61e9764a954aafe9ffae488d50ae674aabdcb4f248006d5","price_changes":[{"asset_id":"14965588658799411272385430903075831224615961675357217884735713260981483529984","best_ask":"0.63","best_bid":"0.62","hash":"408fd1a3553128c5d2dfd4af30c59df7656c366c","price":"0.01","side":"BUY","size":"7888.02"},{"asset_id":"8761897749749422724209054078244794145777693856614463256546737399611489089783","best_ask":"0.38","best_bid":"0.37","hash":"5c60737253cd5daca8a0b90dc46d7bb90aea1c16","price":"0.99","side":"SELL","size":"7888.02"}],"timestamp":"1785207828115"},"payload_hash":"4350d3790b6ea3e4ef10e73cd5fec9909306060d04a3266afd42d0313c6106fc","raw_frame":"{\"market\":\"0x779291bef19b6709f61e9764a954aafe9ffae488d50ae674aabdcb4f248006d5\", \"price_changes\":[{\"asset_id\":\"14965588658799411272385430903075831224615961675357217884735713260981483529984\", \"price\":\"0.01\", \"size\":\"7888.02\", \"side\":\"BUY\", \"hash\":\"408fd1a3553128c5d2dfd4af30c59df7656c366c\", \"best_bid\":\"0.62\", \"best_ask\":\"0.63\"}, {\"asset_id\":\"8761897749749422724209054078244794145777693856614463256546737399611489089783\", \"price\":\"0.99\", \"size\":\"7888.02\", \"side\":\"SELL\", \"hash\":\"5c60737253cd5daca8a0b90dc46d7bb90aea1c16\", \"best_bid\":\"0.37\", \"best_ask\":\"0.38\"}], \"timestamp\":\"1785207828115\", \"event_type\":\"price_change\"}","received_at":"2026-07-28T03:03:47.975254Z","schema_version":"clob-market-ws.price_change.v1","sequence":null,"server_hash":null,"server_timestamp":"1785207828115","session_id":"3e519d9098404c15b234d96025eb1a2b","source":"clob_market_ws"},"received_at":"2026-07-28T03:03:47.975254Z","record_id":"22fc1e5c1e07a8411fc0f7cf306a65a878ab5895350289e47494259f92804c6b","schema_fingerprint":"4aa3821a28b0b7c2400bc59aba4bcc0a76e971dadd19610d3ad38c768e124dc7","schema_version":"edge-lab-recorder.raw.v1","sequence":null,"source":"clob_market_ws"}
{"event_at":"2026-07-28T03:03:48.137000Z","event_fingerprint":"ab9698f01a2fa423da95c577d1153bee27fecaf0aa6c256114067a3b0ddc54fa","payload":{"connection_id":"a6b55582af5f430fb37ad02bf0922475","event_at":"2026-07-28T03:03:48.137000Z","event_type":"price_change","frame_hash":"8884bfb5f6c7f889d36bf5ea20c5ffb91fcba49e395199ebe89fe9c04caa70b9","frame_index":0,"kind":"data","monotonic_ns":309811015256916,"payload":{"event_type":"price_change","market":"0x779291bef19b6709f61e9764a954aafe9ffae488d50ae674aabdcb4f248006d5","price_changes":[{"asset_id":"14965588658799411272385430903075831224615961675357217884735713260981483529984","best_ask":"0.63","best_bid":"0.62","hash":"f04d73208491fbe13bf0863e0c8e94822b0d8b6e","price":"0.02","side":"BUY","size":"738.1"},{"asset_id":"8761897749749422724209054078244794145777693856614463256546737399611489089783","best_ask":"0.38","best_bid":"0.37","hash":"cc59aed89b46869a9c98c2728e1613c136660267","price":"0.98","side":"SELL","size":"738.1"}],"timestamp":"1785207828137"},"payload_hash":"6da7f07a8d89e55be0d617f97e802c06afd225793d114cf855b013ed572ed537","raw_frame":"{\"market\":\"0x779291bef19b6709f61e9764a954aafe9ffae488d50ae674aabdcb4f248006d5\", \"price_changes\":[{\"asset_id\":\"14965588658799411272385430903075831224615961675357217884735713260981483529984\", \"price\":\"0.02\", \"size\":\"738.1\", \"side\":\"BUY\", \"hash\":\"f04d73208491fbe13bf0863e0c8e94822b0d8b6e\", \"best_bid\":\"0.62\", \"best_ask\":\"0.63\"}, {\"asset_id\":\"8761897749749422724209054078244794145777693856614463256546737399611489089783\", \"price\":\"0.98\", \"size\":\"738.1\", \"side\":\"SELL\", \"hash\":\"cc59aed89b46869a9c98c2728e1613c136660267\", \"best_bid\":\"0.37\", \"best_ask\":\"0.38\"}], \"timestamp\":\"1785207828137\", \"event_type\":\"price_change\"}","received_at":"2026-07-28T03:03:47.995247Z","schema_version":"clob-market-ws.price_change.v1","sequence":null,"server_hash":null,"server_timestamp":"1785207828137","session_id":"3e519d9098404c15b234d96025eb1a2b","source":"clob_market_ws"},"received_at":"2026-07-28T03:03:47.995247Z","record_id":"9c2e54bf723c4b63a7723412d7a9e7b1c10b2d77047e8be9c6285afd57bdc0f4","schema_fingerprint":"4aa3821a28b0b7c2400bc59aba4bcc0a76e971dadd19610d3ad38c768e124dc7","schema_version":"edge-lab-recorder.raw.v1","sequence":null,"source":"clob_market_ws"}
{"event_at":"2026-07-28T03:03:48.141000Z","event_fingerprint":"6d444d2573aa327967320790b25c97af808de06787c5ee20ed6f084a106be818","payload":{"connection_id":"a6b55582af5f430fb37ad02bf0922475","event_at":"2026-07-28T03:03:48.141000Z","event_type":"price_change","frame_hash":"7ba5c72ed746d5581fe69bd137cb8757ac69434e803c8239c08d8fc753dfd7f8","frame_index":0,"kind":"data","monotonic_ns":309811018131583,"payload":{"event_type":"price_change","market":"0x779291bef19b6709f61e9764a954aafe9ffae488d50ae674aabdcb4f248006d5","price_changes":[{"asset_id":"14965588658799411272385430903075831224615961675357217884735713260981483529984","best_ask":"0.63","best_bid":"0.62","hash":"cfec1c699d3e3630315c4569718620825dbd508c","price":"0.01","side":"BUY","size":"7883.02"},{"asset_id":"8761897749749422724209054078244794145777693856614463256546737399611489089783","best_ask":"0.38","best_bid":"0.37","hash":"056a4df78d39f1088f32b03b2b1bd3fff3904c04","price":"0.99","side":"SELL","size":"7883.02"}],"timestamp":"1785207828141"},"payload_hash":"dd8cbf9e7d26a338ccd7a809797a2e5ebc1050a048a1996baed8dba01e1d11c3","raw_frame":"{\"market\":\"0x779291bef19b6709f61e9764a954aafe9ffae488d50ae674aabdcb4f248006d5\", \"price_changes\":[{\"asset_id\":\"14965588658799411272385430903075831224615961675357217884735713260981483529984\", \"price\":\"0.01\", \"size\":\"7883.02\", \"side\":\"BUY\", \"hash\":\"cfec1c699d3e3630315c4569718620825dbd508c\", \"best_bid\":\"0.62\", \"best_ask\":\"0.63\"}, {\"asset_id\":\"8761897749749422724209054078244794145777693856614463256546737399611489089783\", \"price\":\"0.99\", \"size\":\"7883.02\", \"side\":\"SELL\", \"hash\":\"056a4df78d39f1088f32b03b2b1bd3fff3904c04\", \"best_bid\":\"0.37\", \"best_ask\":\"0.38\"}], \"timestamp\":\"1785207828141\", \"event_type\":\"price_change\"}","received_at":"2026-07-28T03:03:47.998121Z","schema_version":"clob-market-ws.price_change.v1","sequence":null,"server_hash":null,"server_timestamp":"1785207828141","session_id":"3e519d9098404c15b234d96025eb1a2b","source":"clob_market_ws"},"received_at":"2026-07-28T03:03:47.998121Z","record_id":"41d14bc8bf0ac2d16480764166a5af25b5c87fd0b938dbe294b5ff71724d9635","schema_fingerprint":"4aa3821a28b0b7c2400bc59aba4bcc0a76e971dadd19610d3ad38c768e124dc7","schema_version":"edge-lab-recorder.raw.v1","sequence":null,"source":"clob_market_ws"}
{"event_at":"2026-07-28T03:03:48.199000Z","event_fingerprint":"b3f470e50dc2ba0298c7b7407f6969ae67ac9eae777c168c87476710e2df346e","payload":{"connection_id":"a6b55582af5f430fb37ad02bf0922475","event_at":"2026-07-28T03:03:48.199000Z","event_type":"price_change","frame_hash":"4ebf732bef65a981b97d92cffc66c4e40cfbf4459e729d38fcf59bd981984e0b","frame_index":0,"kind":"data","monotonic_ns":309811070723208,"payload":{"event_type":"price_change","market":"0x779291bef19b6709f61e9764a954aafe9ffae488d50ae674aabdcb4f248006d5","price_changes":[{"asset_id":"14965588658799411272385430903075831224615961675357217884735713260981483529984","best_ask":"0.63","best_bid":"0.62","hash":"47d583b7fda2af04a1ac03f9639d5eedc6a8f3b5","price":"0.02","side":"BUY","size":"733.1"},{"asset_id":"8761897749749422724209054078244794145777693856614463256546737399611489089783","best_ask":"0.38","best_bid":"0.37","hash":"06545728c3061efabbbca723002373f3e21a3372","price":"0.98","side":"SELL","size":"733.1"}],"timestamp":"1785207828199"},"payload_hash":"9d8772fbc1b88ecf695403fe9939968f9e72f7745912dccde9d2a6baffc400f0","raw_frame":"{\"market\":\"0x779291bef19b6709f61e9764a954aafe9ffae488d50ae674aabdcb4f248006d5\", \"price_changes\":[{\"asset_id\":\"14965588658799411272385430903075831224615961675357217884735713260981483529984\", \"price\":\"0.02\", \"size\":\"733.1\", \"side\":\"BUY\", \"hash\":\"47d583b7fda2af04a1ac03f9639d5eedc6a8f3b5\", \"best_bid\":\"0.62\", \"best_ask\":\"0.63\"}, {\"asset_id\":\"8761897749749422724209054078244794145777693856614463256546737399611489089783\", \"price\":\"0.98\", \"size\":\"733.1\", \"side\":\"SELL\", \"hash\":\"06545728c3061efabbbca723002373f3e21a3372\", \"best_bid\":\"0.37\", \"best_ask\":\"0.38\"}], \"timestamp\":\"1785207828199\", \"event_type\":\"price_change\"}","received_at":"2026-07-28T03:03:48.050711Z","schema_version":"clob-market-ws.price_change.v1","sequence":null,"server_hash":null,"server_timestamp":"1785207828199","session_id":"3e519d9098404c15b234d96025eb1a2b","source":"clob_market_ws"},"received_at":"2026-07-28T03:03:48.050711Z","record_id":"e4599b3ce316759b4d866d6b4b65cfe9bba2d7131b2d59ca810f88fe6f0cc5e4","schema_fingerprint":"4aa3821a28b0b7c2400bc59aba4bcc0a76e971dadd19610d3ad38c768e124dc7","schema_version":"edge-lab-recorder.raw.v1","sequence":null,"source":"clob_market_ws"}
{"event_at":"2026-07-28T03:03:48.216000Z","event_fingerprint":"5effebfb25b792340c46336a4cae712d328803e8a3f34330a52f7bc53ed1f59b","payload":{"connection_id":"a6b55582af5f430fb37ad02bf0922475","event_at":"2026-07-28T03:03:48.216000Z","event_type":"price_change","frame_hash":"45fbf724d0711414c5e70e981b8142c927a0eaff783fb8d8858017ab1558e9d1","frame_index":0,"kind":"data","monotonic_ns":309811088208625,"payload":{"event_type":"price_change","market":"0x779291bef19b6709f61e9764a954aafe9ffae488d50ae674aabdcb4f248006d5","price_changes":[{"asset_id":"8761897749749422724209054078244794145777693856614463256546737399611489089783","best_ask":"0.38","best_bid":"0.37","hash":"0a6ca3c6f2ba8fcbdb076c54146b8f28cd5db994","price":"0.37","side":"BUY","size":"295.2"},{"asset_id":"14965588658799411272385430903075831224615961675357217884735713260981483529984","best_ask":"0.63","best_bid":"0.62","hash":"0c7806d1c64616a36a6c7dc7bbfef6ffabde328e","price":"0.63","side":"SELL","size":"295.2"}],"timestamp":"1785207828216"},"payload_hash":"1eac038d9677c83bf1d46dde92a4736167e817f422194280869b818121101a61","raw_frame":"{\"market\":\"0x779291bef19b6709f61e9764a954aafe9ffae488d50ae674aabdcb4f248006d5\", \"price_changes\":[{\"asset_id\":\"8761897749749422724209054078244794145777693856614463256546737399611489089783\", \"price\":\"0.37\", \"size\":\"295.2\", \"side\":\"BUY\", \"hash\":\"0a6ca3c6f2ba8fcbdb076c54146b8f28cd5db994\", \"best_bid\":\"0.37\", \"best_ask\":\"0.38\"}, {\"asset_id\":\"14965588658799411272385430903075831224615961675357217884735713260981483529984\", \"price\":\"0.63\", \"size\":\"295.2\", \"side\":\"SELL\", \"hash\":\"0c7806d1c64616a36a6c7dc7bbfef6ffabde328e\", \"best_bid\":\"0.62\", \"best_ask\":\"0.63\"}], \"timestamp\":\"1785207828216\", \"event_type\":\"price_change\"}","received_at":"2026-07-28T03:03:48.068197Z","schema_version":"clob-market-ws.price_change.v1","sequence":null,"server_hash":null,"server_timestamp":"1785207828216","session_id":"3e519d9098404c15b234d96025eb1a2b","source":"clob_market_ws"},"received_at":"2026-07-28T03:03:48.068197Z","record_id":"6e41e231d0109da1982d08161fb0a4f6f06d8bb850d9d0255184df7e6ade42a4","schema_fingerprint":"4aa3821a28b0b7c2400bc59aba4bcc0a76e971dadd19610d3ad38c768e124dc7","schema_version":"edge-lab-recorder.raw.v1","sequence":null,"source":"clob_market_ws"}
{"event_at":"2026-07-28T03:03:48.246000Z","event_fingerprint":"b9eed7f2af019e36a3e74eb788a3ba4a338951be7a354747f9696ee8449e3e69","payload":{"connection_id":"a6b55582af5f430fb37ad02bf0922475","event_at":"2026-07-28T03:03:48.246000Z","event_type":"price_change","frame_hash":"8253107d02d0a79c50fc852ef5a26a118857680ea427016e2797fbe634a1f0c9","frame_index":0,"kind":"data","monotonic_ns":309811136562666,"payload":{"event_type":"price_change","market":"0x779291bef19b6709f61e9764a954aafe9ffae488d50ae674aabdcb4f248006d5","price_changes":[{"asset_id":"8761897749749422724209054078244794145777693856614463256546737399611489089783","best_ask":"0.38","best_bid":"0.37","hash":"5690f9fe3377c3ccf2e9e7d5afc3fe6d25aa7d9d","price":"0.36","side":"BUY","size":"134.6"},{"asset_id":"14965588658799411272385430903075831224615961675357217884735713260981483529984","best_ask":"0.63","best_bid":"0.62","hash":"caf4a383cbc58b23cb2da4c06ccc557495a449fd","price":"0.64","side":"SELL","size":"134.6"}],"timestamp":"1785207828246"},"payload_hash":"0de6bdd317f04a27541c3ec56b0865642d5fe45b5db1ec08f7c9dd98d9492fbf","raw_frame":"{\"market\":\"0x779291bef19b6709f61e9764a954aafe9ffae488d50ae674aabdcb4f248006d5\", \"price_changes\":[{\"asset_id\":\"8761897749749422724209054078244794145777693856614463256546737399611489089783\", \"price\":\"0.36\", \"size\":\"134.6\", \"side\":\"BUY\", \"hash\":\"5690f9fe3377c3ccf2e9e7d5afc3fe6d25aa7d9d\", \"best_bid\":\"0.37\", \"best_ask\":\"0.38\"}, {\"asset_id\":\"14965588658799411272385430903075831224615961675357217884735713260981483529984\", \"price\":\"0.64\", \"size\":\"134.6\", \"side\":\"SELL\", \"hash\":\"caf4a383cbc58b23cb2da4c06ccc557495a449fd\", \"best_bid\":\"0.62\", \"best_ask\":\"0.63\"}], \"timestamp\":\"1785207828246\", \"event_type\":\"price_change\"}","received_at":"2026-07-28T03:03:48.116549Z","schema_version":"clob-market-ws.price_change.v1","sequence":null,"server_hash":null,"server_timestamp":"1785207828246","session_id":"3e519d9098404c15b234d96025eb1a2b","source":"clob_market_ws"},"received_at":"2026-07-28T03:03:48.116549Z","record_id":"eb404a3c387fc712b7c6f628203531b769892025d4a313868f8c6be19c778c73","schema_fingerprint":"4aa3821a28b0b7c2400bc59aba4bcc0a76e971dadd19610d3ad38c768e124dc7","schema_version":"edge-lab-recorder.raw.v1","sequence":null,"source":"clob_market_ws"}
{"event_at":"2026-07-28T03:03:48.299000Z","event_fingerprint":"08e028d754dcfbef57a4be5656b23a65b7d4216c802895385eb5b00957fc4809","payload":{"connection_id":"a6b55582af5f430fb37ad02bf0922475","event_at":"2026-07-28T03:03:48.299000Z","event_type":"price_change","frame_hash":"5254be2cd4181dae2c324c3a7601d4930401c705acf1e5aeea4bc7f3739a15bc","frame_index":0,"kind":"data","monotonic_ns":309811186403583,"payload":{"event_type":"price_change","market":"0x779291bef19b6709f61e9764a954aafe9ffae488d50ae674aabdcb4f248006d5","price_changes":[{"asset_id":"14965588658799411272385430903075831224615961675357217884735713260981483529984","best_ask":"0.63","best_bid":"0.62","hash":"8bea657542751108f9427f684157cb3e8ab28e29","price":"0.03","side":"BUY","size":"638.1"},{"asset_id":"8761897749749422724209054078244794145777693856614463256546737399611489089783","best_ask":"0.38","best_bid":"0.37","hash":"825cbb36bb35bcefbbf4d12e468cd48a4cfde9fc","price":"0.97","side":"SELL","size":"638.1"}],"timestamp":"1785207828299"},"payload_hash":"6ac8664cf73771e78d4dc0ccd0af964f21b61441c59aa2b6c74ee63f15114d4b","raw_frame":"{\"market\":\"0x779291bef19b6709f61e9764a954aafe9ffae488d50ae674aabdcb4f248006d5\", \"price_changes\":[{\"asset_id\":\"14965588658799411272385430903075831224615961675357217884735713260981483529984\", \"price\":\"0.03\", \"size\":\"638.1\", \"side\":\"BUY\", \"hash\":\"8bea657542751108f9427f684157cb3e8ab28e29\", \"best_bid\":\"0.62\", \"best_ask\":\"0.63\"}, {\"asset_id\":\"8761897749749422724209054078244794145777693856614463256546737399611489089783\", \"price\":\"0.97\", \"size\":\"638.1\", \"side\":\"SELL\", \"hash\":\"825cbb36bb35bcefbbf4d12e468cd48a4cfde9fc\", \"best_bid\":\"0.37\", \"best_ask\":\"0.38\"}], \"timestamp\":\"1785207828299\", \"event_type\":\"price_change\"}","received_at":"2026-07-28T03:03:48.166390Z","schema_version":"clob-market-ws.price_change.v1","sequence":null,"server_hash":null,"server_timestamp":"1785207828299","session_id":"3e519d9098404c15b234d96025eb1a2b","source":"clob_market_ws"},"received_at":"2026-07-28T03:03:48.166390Z","record_id":"a6b336ea2d516ec83f1e87586e9b2dc8cd1c6c586891fec782d5c57d2b90e95e","schema_fingerprint":"4aa3821a28b0b7c2400bc59aba4bcc0a76e971dadd19610d3ad38c768e124dc7","schema_version":"edge-lab-recorder.raw.v1","sequence":null,"source":"clob_market_ws"}
{"event_at":"2026-07-28T03:03:48.397000Z","event_fingerprint":"b4398b930262bfbcfcb312eb64a5027b716a595813e400f3dbf24c872edd4a75","payload":{"connection_id":"a6b55582af5f430fb37ad02bf0922475","event_at":"2026-07-28T03:03:48.397000Z","event_type":"price_change","frame_hash":"fd8700fe8a6acd4f1a994e303162c04e45d81e6bcae34af70080dd4ec6eb46fb","frame_index":0,"kind":"data","monotonic_ns":309811268611125,"payload":{"event_type":"price_change","market":"0x779291bef19b6709f61e9764a954aafe9ffae488d50ae674aabdcb4f248006d5","price_changes":[{"asset_id":"14965588658799411272385430903075831224615961675357217884735713260981483529984","best_ask":"0.63","best_bid":"0.62","hash":"3cd38d7bc88f090a77bf498b1465dd3d822d1073","price":"0.03","side":"BUY","size":"633.1"},{"asset_id":"8761897749749422724209054078244794145777693856614463256546737399611489089783","best_ask":"0.38","best_bid":"0.37","hash":"8f2b3a356c7257173ec2155647b701fbc0ecc0b8","price":"0.97","side":"SELL","size":"633.1"}],"timestamp":"1785207828397"},"payload_hash":"720af0761595a6e5399905824993eae5a5b53a3b7168848943f5536ff5b49ff6","raw_frame":"{\"market\":\"0x779291bef19b6709f61e9764a954aafe9ffae488d50ae674aabdcb4f248006d5\", \"price_changes\":[{\"asset_id\":\"14965588658799411272385430903075831224615961675357217884735713260981483529984\", \"price\":\"0.03\", \"size\":\"633.1\", \"side\":\"BUY\", \"hash\":\"3cd38d7bc88f090a77bf498b1465dd3d822d1073\", \"best_bid\":\"0.62\", \"best_ask\":\"0.63\"}, {\"asset_id\":\"8761897749749422724209054078244794145777693856614463256546737399611489089783\", \"price\":\"0.97\", \"size\":\"633.1\", \"side\":\"SELL\", \"hash\":\"8f2b3a356c7257173ec2155647b701fbc0ecc0b8\", \"best_bid\":\"0.37\", \"best_ask\":\"0.38\"}], \"timestamp\":\"1785207828397\", \"event_type\":\"price_change\"}","received_at":"2026-07-28T03:03:48.248595Z","schema_version":"clob-market-ws.price_change.v1","sequence":null,"server_hash":null,"server_timestamp":"1785207828397","session_id":"3e519d9098404c15b234d96025eb1a2b","source":"clob_market_ws"},"received_at":"2026-07-28T03:03:48.248595Z","record_id":"2639a7c8f9f467c9928ae1363f634b1d7fea1aa1387eda2151da6e6a8aa52dd8","schema_fingerprint":"4aa3821a28b0b7c2400bc59aba4bcc0a76e971dadd19610d3ad38c768e124dc7","schema_version":"edge-lab-recorder.raw.v1","sequence":null,"source":"clob_market_ws"}
{"event_at":"2026-07-28T03:03:48.497000Z","event_fingerprint":"dd57c98cab2603502c6e066484742589e10b03147725c9723e1bcde8087680c0","payload":{"connection_id":"a6b55582af5f430fb37ad02bf0922475","event_at":"2026-07-28T03:03:48.497000Z","event_type":"price_change","frame_hash":"ec93a571592500c1cca179635788c08e619b5ce26daff364df8bca4874a1b1c3","frame_index":0,"kind":"data","monotonic_ns":309811366492500,"payload":{"event_type":"price_change","market":"0x779291bef19b6709f61e9764a954aafe9ffae488d50ae674aabdcb4f248006d5","price_changes":[{"asset_id":"14965588658799411272385430903075831224615961675357217884735713260981483529984","best_ask":"0.63","best_bid":"0.62","hash":"c5eb997625916531d321e8a7e4b607e8286a3f4f","price":"0.01","side":"BUY","size":"7888.02"},{"asset_id":"8761897749749422724209054078244794145777693856614463256546737399611489089783","best_ask":"0.38","best_bid":"0.37","hash":"1ca6272d682f3e4d6c4336a99f1994b5901681df","price":"0.99","side":"SELL","size":"7888.02"}],"timestamp":"1785207828497"},"payload_hash":"53c6993929200079009b07a61f03632e63f9fbbeba7278fbd3355a0c6adb5709","raw_frame":"{\"market\":\"0x779291bef19b6709f61e9764a954aafe9ffae488d50ae674aabdcb4f248006d5\", \"price_changes\":[{\"asset_id\":\"14965588658799411272385430903075831224615961675357217884735713260981483529984\", \"price\":\"0.01\", \"size\":\"7888.02\", \"side\":\"BUY\", \"hash\":\"c5eb997625916531d321e8a7e4b607e8286a3f4f\", \"best_bid\":\"0.62\", \"best_ask\":\"0.63\"}, {\"asset_id\":\"8761897749749422724209054078244794145777693856614463256546737399611489089783\", \"price\":\"0.99\", \"size\":\"7888.02\", \"side\":\"SELL\", \"hash\":\"1ca6272d682f3e4d6c4336a99f1994b5901681df\", \"best_bid\":\"0.37\", \"best_ask\":\"0.38\"}], \"timestamp\":\"1785207828497\", \"event_type\":\"price_change\"}","received_at":"2026-07-28T03:03:48.346477Z","schema_version":"clob-market-ws.price_change.v1","sequence":null,"server_hash":null,"server_timestamp":"1785207828497","session_id":"3e519d9098404c15b234d96025eb1a2b","source":"clob_market_ws"},"received_at":"2026-07-28T03:03:48.346477Z","record_id":"15691697b47bcb5745a731c4ab73667b6958b524e0e025ea20fefc29574df02b","schema_fingerprint":"4aa3821a28b0b7c2400bc59aba4bcc0a76e971dadd19610d3ad38c768e124dc7","schema_version":"edge-lab-recorder.raw.v1","sequence":null,"source":"clob_market_ws"}
{"event_at":"2026-07-28T03:03:48.518000Z","event_fingerprint":"2851c27707fbf50636144e59cc35dee83b03efbf26ec4fa3515e3b76d89dfbad","payload":{"connection_id":"a6b55582af5f430fb37ad02bf0922475","event_at":"2026-07-28T03:03:48.518000Z","event_type":"price_change","frame_hash":"37b4ce29a8f082abe3bd626086599891ffbf34ad57f1e1250d03ead7194a833f","frame_index":0,"kind":"data","monotonic_ns":309811396343916,"payload":{"event_type":"price_change","market":"0x779291bef19b6709f61e9764a954aafe9ffae488d50ae674aabdcb4f248006d5","price_changes":[{"asset_id":"14965588658799411272385430903075831224615961675357217884735713260981483529984","best_ask":"0.63","best_bid":"0.62","hash":"f9d5712bf03a448ef61cc88296d78f88721b4266","price":"0.01","side":"BUY","size":"7893.02"},{"asset_id":"8761897749749422724209054078244794145777693856614463256546737399611489089783","best_ask":"0.38","best_bid":"0.37","hash":"a55fc69d8161528bff31b08580e19d25685fe19c","price":"0.99","side":"SELL","size":"7893.02"}],"timestamp":"1785207828518"},"payload_hash":"e01666927fbc5916de2a251ef9efad84b56192b80addabd137be0fd820bdfe80","raw_frame":"{\"market\":\"0x779291bef19b6709f61e9764a954aafe9ffae488d50ae674aabdcb4f248006d5\", \"price_changes\":[{\"asset_id\":\"14965588658799411272385430903075831224615961675357217884735713260981483529984\", \"price\":\"0.01\", \"size\":\"7893.02\", \"side\":\"BUY\", \"hash\":\"f9d5712bf03a448ef61cc88296d78f88721b4266\", \"best_bid\":\"0.62\", \"best_ask\":\"0.63\"}, {\"asset_id\":\"8761897749749422724209054078244794145777693856614463256546737399611489089783\", \"price\":\"0.99\", \"size\":\"7893.02\", \"side\":\"SELL\", \"hash\":\"a55fc69d8161528bff31b08580e19d25685fe19c\", \"best_bid\":\"0.37\", \"best_ask\":\"0.38\"}], \"timestamp\":\"1785207828518\", \"event_type\":\"price_change\"}","received_at":"2026-07-28T03:03:48.376318Z","schema_version":"clob-market-ws.price_change.v1","sequence":null,"server_hash":null,"server_timestamp":"1785207828518","session_id":"3e519d9098404c15b234d96025eb1a2b","source":"clob_market_ws"},"received_at":"2026-07-28T03:03:48.376318Z","record_id":"799eebb3cbb987100efe514c820de9ff0c8c7235011a5028b95d2eef5894d9fe","schema_fingerprint":"4aa3821a28b0b7c2400bc59aba4bcc0a76e971dadd19610d3ad38c768e124dc7","schema_version":"edge-lab-recorder.raw.v1","sequence":null,"source":"clob_market_ws"}
{"event_at":"2026-07-28T03:03:48.523000Z","event_fingerprint":"8fd7acb70caaf425f898d3cdfc2193dac36399f99ca33ead04cccfcbf15e00e8","payload":{"connection_id":"a6b55582af5f430fb37ad02bf0922475","event_at":"2026-07-28T03:03:48.523000Z","event_type":"price_change","frame_hash":"7ac10af9529d01eec0c29ccbf97fcf3ec6b779d5ee37e5d076fceed4cf7e86aa","frame_index":0,"kind":"data","monotonic_ns":309811397935041,"payload":{"event_type":"price_change","market":"0x779291bef19b6709f61e9764a954aafe9ffae488d50ae674aabdcb4f248006d5","price_changes":[{"asset_id":"14965588658799411272385430903075831224615961675357217884735713260981483529984","best_ask":"0.63","best_bid":"0.62","hash":"023fd385be6f9e4b050da5ca86a69e4f9d1b615a","price":"0.01","side":"BUY","size":"7898.02"},{"asset_id":"8761897749749422724209054078244794145777693856614463256546737399611489089783","best_ask":"0.38","best_bid":"0.37","hash":"cbf4188ee871fe512482035284b78af0832710b9","price":"0.99","side":"SELL","size":"7898.02"}],"timestamp":"1785207828523"},"payload_hash":"4199b811317ac85975850179fb59594aca5704ab8713e6b855f12622bdc6df06","raw_frame":"{\"market\":\"0x779291bef19b6709f61e9764a954aafe9ffae488d50ae674aabdcb4f248006d5\", \"price_changes\":[{\"asset_id\":\"14965588658799411272385430903075831224615961675357217884735713260981483529984\", \"price\":\"0.01\", \"size\":\"7898.02\", \"side\":\"BUY\", \"hash\":\"023fd385be6f9e4b050da5ca86a69e4f9d1b615a\", \"best_bid\":\"0.62\", \"best_ask\":\"0.63\"}, {\"asset_id\":\"8761897749749422724209054078244794145777693856614463256546737399611489089783\", \"price\":\"0.99\", \"size\":\"7898.02\", \"side\":\"SELL\", \"hash\":\"cbf4188ee871fe512482035284b78af0832710b9\", \"best_bid\":\"0.37\", \"best_ask\":\"0.38\"}], \"timestamp\":\"1785207828523\", \"event_type\":\"price_change\"}","received_at":"2026-07-28T03:03:48.377921Z","schema_version":"clob-market-ws.price_change.v1","sequence":null,"server_hash":null,"server_timestamp":"1785207828523","session_id":"3e519d9098404c15b234d96025eb1a2b","source":"clob_market_ws"},"received_at":"2026-07-28T03:03:48.377921Z","record_id":"d29d1321a84121f40cdebb3e2ace49eade467b858dcb5cded759b96487427e84","schema_fingerprint":"4aa3821a28b0b7c2400bc59aba4bcc0a76e971dadd19610d3ad38c768e124dc7","schema_version":"edge-lab-recorder.raw.v1","sequence":null,"source":"clob_market_ws"}
{"event_at":"2026-07-28T03:03:48.536000Z","event_fingerprint":"b4395ae8ded8bc36d860513f33aad99d3230a2354864067ab3c8957965ca9f45","payload":{"connection_id":"a6b55582af5f430fb37ad02bf0922475","event_at":"2026-07-28T03:03:48.536000Z","event_type":"price_change","frame_hash":"2b81d1b38decf75c2a665b9c863e7b7899ae48b27b4ab2450f6e6d925a1332bb","frame_index":0,"kind":"data","monotonic_ns":309811406551541,"payload":{"event_type":"price_change","market":"0x779291bef19b6709f61e9764a954aafe9ffae488d50ae674aabdcb4f248006d5","price_changes":[{"asset_id":"14965588658799411272385430903075831224615961675357217884735713260981483529984","best_ask":"0.63","best_bid":"0.62","hash":"1ad2a701292ad3a05abb0d8f6433ff1ad072be14","price":"0.01","side":"BUY","size":"7893.02"},{"asset_id":"8761897749749422724209054078244794145777693856614463256546737399611489089783","best_ask":"0.38","best_bid":"0.37","hash":"cf8ff4c7b374a629b9d8e499c5dbfea0780b7461","price":"0.99","side":"SELL","size":"7893.02"}],"timestamp":"1785207828536"},"payload_hash":"6882e47eeb4e0cf7d44d06385ad24cc668c9015d54a7425e7def1840c744e1b3","raw_frame":"{\"market\":\"0x779291bef19b6709f61e9764a954aafe9ffae488d50ae674aabdcb4f248006d5\", \"price_changes\":[{\"asset_id\":\"14965588658799411272385430903075831224615961675357217884735713260981483529984\", \"price\":\"0.01\", \"size\":\"7893.02\", \"side\":\"BUY\", \"hash\":\"1ad2a701292ad3a05abb0d8f6433ff1ad072be14\", \"best_bid\":\"0.62\", \"best_ask\":\"0.63\"}, {\"asset_id\":\"8761897749749422724209054078244794145777693856614463256546737399611489089783\", \"price\":\"0.99\", \"size\":\"7893.02\", \"side\":\"SELL\", \"hash\":\"cf8ff4c7b374a629b9d8e499c5dbfea0780b7461\", \"best_bid\":\"0.37\", \"best_ask\":\"0.38\"}], \"timestamp\":\"1785207828536\", \"event_type\":\"price_change\"}","received_at":"2026-07-28T03:03:48.386530Z","schema_version":"clob-market-ws.price_change.v1","sequence":null,"server_hash":null,"server_timestamp":"1785207828536","session_id":"3e519d9098404c15b234d96025eb1a2b","source":"clob_market_ws"},"received_at":"2026-07-28T03:03:48.386530Z","record_id":"2de45f25afe163cba4f523b25bfe7d0a2cbd3686cefe5d272f0b62befc04a136","schema_fingerprint":"4aa3821a28b0b7c2400bc59aba4bcc0a76e971dadd19610d3ad38c768e124dc7","schema_version":"edge-lab-recorder.raw.v1","sequence":null,"source":"clob_market_ws"}
{"event_at":"2026-07-28T03:03:48.549000Z","event_fingerprint":"f270ffa518ee44e7287239c46494e20dd9c2f764fa369b1aab2f3299fafa5faf","payload":{"connection_id":"a6b55582af5f430fb37ad02bf0922475","event_at":"2026-07-28T03:03:48.549000Z","event_type":"price_change","frame_hash":"4abf73bcce273b14e32b4dc35d6ea3b40f3b809bce9885c5cc217f7d9d91c7dc","frame_index":0,"kind":"data","monotonic_ns":309811426066875,"payload":{"event_type":"price_change","market":"0x779291bef19b6709f61e9764a954aafe9ffae488d50ae674aabdcb4f248006d5","price_changes":[{"asset_id":"14965588658799411272385430903075831224615961675357217884735713260981483529984","best_ask":"0.63","best_bid":"0.62","hash":"098aea6ba58fd8d0e03baa8a04eaef744a187076","price":"0.01","side":"BUY","size":"7888.02"},{"asset_id":"8761897749749422724209054078244794145777693856614463256546737399611489089783","best_ask":"0.38","best_bid":"0.37","hash":"d0c87ea80c1c4194c6208db4948c238c9de6762f","price":"0.99","side":"SELL","size":"7888.02"}],"timestamp":"1785207828549"},"payload_hash":"1567691351e40972ece1615c23cd3fcdec2463a2ae5566b6924d5dae623a5e48","raw_frame":"{\"market\":\"0x779291bef19b6709f61e9764a954aafe9ffae488d50ae674aabdcb4f248006d5\", \"price_changes\":[{\"asset_id\":\"14965588658799411272385430903075831224615961675357217884735713260981483529984\", \"price\":\"0.01\", \"size\":\"7888.02\", \"side\":\"BUY\", \"hash\":\"098aea6ba58fd8d0e03baa8a04eaef744a187076\", \"best_bid\":\"0.62\", \"best_ask\":\"0.63\"}, {\"asset_id\":\"8761897749749422724209054078244794145777693856614463256546737399611489089783\", \"price\":\"0.99\", \"size\":\"7888.02\", \"side\":\"SELL\", \"hash\":\"d0c87ea80c1c4194c6208db4948c238c9de6762f\", \"best_bid\":\"0.37\", \"best_ask\":\"0.38\"}], \"timestamp\":\"1785207828549\", \"event_type\":\"price_change\"}","received_at":"2026-07-28T03:03:48.406051Z","schema_version":"clob-market-ws.price_change.v1","sequence":null,"server_hash":null,"server_timestamp":"1785207828549","session_id":"3e519d9098404c15b234d96025eb1a2b","source":"clob_market_ws"},"received_at":"2026-07-28T03:03:48.406051Z","record_id":"af4f6c478157e4d7c5482855584eef19699f09c9a5ca140012c0eb002507f93e","schema_fingerprint":"4aa3821a28b0b7c2400bc59aba4bcc0a76e971dadd19610d3ad38c768e124dc7","schema_version":"edge-lab-recorder.raw.v1","sequence":null,"source":"clob_market_ws"}
{"event_at":"2026-07-28T03:03:48.550000Z","event_fingerprint":"699f558b87533c70c57da71ee5c11c147de690771fffe01d1c5137e1a9c5d192","payload":{"connection_id":"a6b55582af5f430fb37ad02bf0922475","event_at":"2026-07-28T03:03:48.550000Z","event_type":"price_change","frame_hash":"29bfe26c398c906e8167c349decbd9e7ffe9fd4306458218cb8bfe083f4036aa","frame_index":0,"kind":"data","monotonic_ns":309811427616416,"payload":{"event_type":"price_change","market":"0x779291bef19b6709f61e9764a954aafe9ffae488d50ae674aabdcb4f248006d5","price_changes":[{"asset_id":"14965588658799411272385430903075831224615961675357217884735713260981483529984","best_ask":"0.63","best_bid":"0.62","hash":"314ca22cc67316a87f39d9b5e1ac0f5c709653be","price":"0.01","side":"BUY","size":"7883.02"},{"asset_id":"8761897749749422724209054078244794145777693856614463256546737399611489089783","best_ask":"0.38","best_bid":"0.37","hash":"f41a2c8abcab6d682c09c1d32101ce726a1a1bd3","price":"0.99","side":"SELL","size":"7883.02"}],"timestamp":"1785207828550"},"payload_hash":"495a47fc0fe98110551ce441f847d809002a1fb2dbe4cde2cc837abc24cefd17","raw_frame":"{\"market\":\"0x779291bef19b6709f61e9764a954aafe9ffae488d50ae674aabdcb4f248006d5\", \"price_changes\":[{\"asset_id\":\"14965588658799411272385430903075831224615961675357217884735713260981483529984\", \"price\":\"0.01\", \"size\":\"7883.02\", \"side\":\"BUY\", \"hash\":\"314ca22cc67316a87f39d9b5e1ac0f5c709653be\", \"best_bid\":\"0.62\", \"best_ask\":\"0.63\"}, {\"asset_id\":\"8761897749749422724209054078244794145777693856614463256546737399611489089783\", \"price\":\"0.99\", \"size\":\"7883.02\", \"side\":\"SELL\", \"hash\":\"f41a2c8abcab6d682c09c1d32101ce726a1a1bd3\", \"best_bid\":\"0.37\", \"best_ask\":\"0.38\"}], \"timestamp\":\"1785207828550\", \"event_type\":\"price_change\"}","received_at":"2026-07-28T03:03:48.407601Z","schema_version":"clob-market-ws.price_change.v1","sequence":null,"server_hash":null,"server_timestamp":"1785207828550","session_id":"3e519d9098404c15b234d96025eb1a2b","source":"clob_market_ws"},"received_at":"2026-07-28T03:03:48.407601Z","record_id":"269f10feb3ad812dfbde25ebc941b43b889b430aaf2cc0752e65f77dcc2de609","schema_fingerprint":"4aa3821a28b0b7c2400bc59aba4bcc0a76e971dadd19610d3ad38c768e124dc7","schema_version":"edge-lab-recorder.raw.v1","sequence":null,"source":"clob_market_ws"}
{"event_at":"2026-07-28T03:03:48.658000Z","event_fingerprint":"7fdf68a954ed9973f264304d5e982c00453073750c450d8ca571524bcb9b4c37","payload":{"connection_id":"a6b55582af5f430fb37ad02bf0922475","event_at":"2026-07-28T03:03:48.658000Z","event_type":"price_change","frame_hash":"a42cc6098c250350a61477d33187b22b219d282681a764fb02308a7613dd48b3","frame_index":0,"kind":"data","monotonic_ns":309811537674250,"payload":{"event_type":"price_change","market":"0x779291bef19b6709f61e9764a954aafe9ffae488d50ae674aabdcb4f248006d5","price_changes":[{"asset_id":"8761897749749422724209054078244794145777693856614463256546737399611489089783","best_ask":"0.38","best_bid":"0.37","hash":"2d2e93529a6324f88439415fee17b3f5a74f1731","price":"0.19","side":"BUY","size":"232.93"},{"asset_id":"14965588658799411272385430903075831224615961675357217884735713260981483529984","best_ask":"0.63","best_bid":"0.62","hash":"bbebcfc372383f5d3a741f8257008924f9946849","price":"0.81","side":"SELL","size":"232.93"}],"timestamp":"1785207828658"},"payload_hash":"5e182d90467b4a3ac668d66dc47153fb4bd79dc43254f41f538a16575de3a1f8","raw_frame":"{\"market\":\"0x779291bef19b6709f61e9764a954aafe9ffae488d50ae674aabdcb4f248006d5\", \"price_changes\":[{\"asset_id\":\"8761897749749422724209054078244794145777693856614463256546737399611489089783\", \"price\":\"0.19\", \"size\":\"232.93\", \"side\":\"BUY\", \"hash\":\"2d2e93529a6324f88439415fee17b3f5a74f1731\", \"best_bid\":\"0.37\", \"best_ask\":\"0.38\"}, {\"asset_id\":\"14965588658799411272385430903075831224615961675357217884735713260981483529984\", \"price\":\"0.81\", \"size\":\"232.93\", \"side\":\"SELL\", \"hash\":\"bbebcfc372383f5d3a741f8257008924f9946849\", \"best_bid\":\"0.62\", \"best_ask\":\"0.63\"}], \"timestamp\":\"1785207828658\", \"event_type\":\"price_change\"}","received_at":"2026-07-28T03:03:48.517657Z","schema_version":"clob-market-ws.price_change.v1","sequence":null,"server_hash":null,"server_timestamp":"1785207828658","session_id":"3e519d9098404c15b234d96025eb1a2b","source":"clob_market_ws"},"received_at":"2026-07-28T03:03:48.517657Z","record_id":"e13ca341fcd4160b8e04d443af4291243015b1b5423ba9a9f66bb367b19b2ae2","schema_fingerprint":"4aa3821a28b0b7c2400bc59aba4bcc0a76e971dadd19610d3ad38c768e124dc7","schema_version":"edge-lab-recorder.raw.v1","sequence":null,"source":"clob_market_ws"}
{"event_at":"2026-07-28T03:03:48.659000Z","event_fingerprint":"b3a4c88d7bc3b0acb86b11d870011488d8728f2ea03be9c48eb1553a1f53e261","payload":{"connection_id":"a6b55582af5f430fb37ad02bf0922475","event_at":"2026-07-28T03:03:48.659000Z","event_type":"price_change","frame_hash":"6b21784702513f5c49d2bf4049a1149b557560fec680e74b8594ea108d5a5483","frame_index":0,"kind":"data","monotonic_ns":309811539325291,"payload":{"event_type":"price_change","market":"0x779291bef19b6709f61e9764a954aafe9ffae488d50ae674aabdcb4f248006d5","price_changes":[{"asset_id":"14965588658799411272385430903075831224615961675357217884735713260981483529984","best_ask":"0.63","best_bid":"0.62","hash":"0bf704af0e4b1d14ebe3bca6c38b60aa28e04d1b","price":"0.43","side":"BUY","size":"160.01"},{"asset_id":"8761897749749422724209054078244794145777693856614463256546737399611489089783","best_ask":"0.38","best_bid":"0.37","hash":"f97e8261f9afce2cde7be9f8e77cf258e8311106","price":"0.57","side":"SELL","size":"160.01"}],"timestamp":"1785207828659"},"payload_hash":"77f280d9d3d124b67ca5150c1be77cf46bb22698038f80fbc6bec945615f86ca","raw_frame":"{\"market\":\"0x779291bef19b6709f61e9764a954aafe9ffae488d50ae674aabdcb4f248006d5\", \"price_changes\":[{\"asset_id\":\"14965588658799411272385430903075831224615961675357217884735713260981483529984\", \"price\":\"0.43\", \"size\":\"160.01\", \"side\":\"BUY\", \"hash\":\"0bf704af0e4b1d14ebe3bca6c38b60aa28e04d1b\", \"best_bid\":\"0.62\", \"best_ask\":\"0.63\"}, {\"asset_id\":\"8761897749749422724209054078244794145777693856614463256546737399611489089783\", \"price\":\"0.57\", \"size\":\"160.01\", \"side\":\"SELL\", \"hash\":\"f97e8261f9afce2cde7be9f8e77cf258e8311106\", \"best_bid\":\"0.37\", \"best_ask\":\"0.38\"}], \"timestamp\":\"1785207828659\", \"event_type\":\"price_change\"}","received_at":"2026-07-28T03:03:48.519310Z","schema_version":"clob-market-ws.price_change.v1","sequence":null,"server_hash":null,"server_timestamp":"1785207828659","session_id":"3e519d9098404c15b234d96025eb1a2b","source":"clob_market_ws"},"received_at":"2026-07-28T03:03:48.519310Z","record_id":"5ac82b3db57ad289f5e6513042f436f1b76013e8d9a38543e586c9e3899b81d9","schema_fingerprint":"4aa3821a28b0b7c2400bc59aba4bcc0a76e971dadd19610d3ad38c768e124dc7","schema_version":"edge-lab-recorder.raw.v1","sequence":null,"source":"clob_market_ws"}
{"event_at":"2026-07-28T03:03:48.681000Z","event_fingerprint":"3512f2284e56eb4053d90e7f39bb6c3ce754d293e62fdcf2cfa84634c0b57b2e","payload":{"connection_id":"a6b55582af5f430fb37ad02bf0922475","event_at":"2026-07-28T03:03:48.681000Z","event_type":"price_change","frame_hash":"e46912dddf28972f391b8795423d86e5eb4e1158706daaf5a8e1643742fa5f74","frame_index":0,"kind":"data","monotonic_ns":309811551074375,"payload":{"event_type":"price_change","market":"0x779291bef19b6709f61e9764a954aafe9ffae488d50ae674aabdcb4f248006d5","price_changes":[{"asset_id":"14965588658799411272385430903075831224615961675357217884735713260981483529984","best_ask":"0.63","best_bid":"0.62","hash":"ff50d45a9f845137d2f7e777e304616362c933d0","price":"0.04","side":"BUY","size":"673.09"},{"asset_id":"8761897749749422724209054078244794145777693856614463256546737399611489089783","best_ask":"0.38","best_bid":"0.37","hash":"c8c86e46a2e2d68d9a90a5e27c056742bcaf01a6","price":"0.96","side":"SELL","size":"673.09"}],"timestamp":"1785207828681"},"payload_hash":"68422bc04cfa930dd266c4b9948c6e39eb16f7bc4dcdd428c09224ba4585df16","raw_frame":"{\"market\":\"0x779291bef19b6709f61e9764a954aafe9ffae488d50ae674aabdcb4f248006d5\", \"price_changes\":[{\"asset_id\":\"14965588658799411272385430903075831224615961675357217884735713260981483529984\", \"price\":\"0.04\", \"size\":\"673.09\", \"side\":\"BUY\", \"hash\":\"ff50d45a9f845137d2f7e777e304616362c933d0\", \"best_bid\":\"0.62\", \"best_ask\":\"0.63\"}, {\"asset_id\":\"8761897749749422724209054078244794145777693856614463256546737399611489089783\", \"price\":\"0.96\", \"size\":\"673.09\", \"side\":\"SELL\", \"hash\":\"c8c86e46a2e2d68d9a90a5e27c056742bcaf01a6\", \"best_bid\":\"0.37\", \"best_ask\":\"0.38\"}], \"timestamp\":\"1785207828681\", \"event_type\":\"price_change\"}","received_at":"2026-07-28T03:03:48.531059Z","schema_version":"clob-market-ws.price_change.v1","sequence":null,"server_hash":null,"server_timestamp":"1785207828681","session_id":"3e519d9098404c15b234d96025eb1a2b","source":"clob_market_ws"},"received_at":"2026-07-28T03:03:48.531059Z","record_id":"80c57291b564b51e3067ed2cde4625dc89386f5280da08ffab5e24d439a9c17a","schema_fingerprint":"4aa3821a28b0b7c2400bc59aba4bcc0a76e971dadd19610d3ad38c768e124dc7","schema_version":"edge-lab-recorder.raw.v1","sequence":null,"source":"clob_market_ws"}
{"event_at":"2026-07-28T03:03:48.724000Z","event_fingerprint":"7b0a3d6634ebe57e8f3255e74fe020ddb030031f103abc8f09700164e173e742","payload":{"connection_id":"a6b55582af5f430fb37ad02bf0922475","event_at":"2026-07-28T03:03:48.724000Z","event_type":"price_change","frame_hash":"bfb6dcaa9c89f95ee8b5e6c80954ae91b3ac1ed38e574820a0321d8f4828c5cf","frame_index":0,"kind":"data","monotonic_ns":309811612290333,"payload":{"event_type":"price_change","market":"0x779291bef19b6709f61e9764a954aafe9ffae488d50ae674aabdcb4f248006d5","price_changes":[{"asset_id":"8761897749749422724209054078244794145777693856614463256546737399611489089783","best_ask":"0.38","best_bid":"0.37","hash":"1558b89843fb7d55c545aca7359a0a73d727a08d","price":"0.36","side":"BUY","size":"139.6"},{"asset_id":"14965588658799411272385430903075831224615961675357217884735713260981483529984","best_ask":"0.63","best_bid":"0.62","hash":"862a24e5883f102cf81854820c262050012cab84","price":"0.64","side":"SELL","size":"139.6"}],"timestamp":"1785207828724"},"payload_hash":"73b77cfee8f808851632b3c47d8cb14f64e8d712662b51381f63f6ae3dff825a","raw_frame":"{\"market\":\"0x779291bef19b6709f61e9764a954aafe9ffae488d50ae674aabdcb4f248006d5\", \"price_changes\":[{\"asset_id\":\"8761897749749422724209054078244794145777693856614463256546737399611489089783\", \"price\":\"0.36\", \"size\":\"139.6\", \"side\":\"BUY\", \"hash\":\"1558b89843fb7d55c545aca7359a0a73d727a08d\", \"best_bid\":\"0.37\", \"best_ask\":\"0.38\"}, {\"asset_id\":\"14965588658799411272385430903075831224615961675357217884735713260981483529984\", \"price\":\"0.64\", \"size\":\"139.6\", \"side\":\"SELL\", \"hash\":\"862a24e5883f102cf81854820c262050012cab84\", \"best_bid\":\"0.62\", \"best_ask\":\"0.63\"}], \"timestamp\":\"1785207828724\", \"event_type\":\"price_change\"}","received_at":"2026-07-28T03:03:48.592274Z","schema_version":"clob-market-ws.price_change.v1","sequence":null,"server_hash":null,"server_timestamp":"1785207828724","session_id":"3e519d9098404c15b234d96025eb1a2b","source":"clob_market_ws"},"received_at":"2026-07-28T03:03:48.592274Z","record_id":"97ed6744cc5c633dee845f08c726d255cad8a03d11841933d5ae0abd554d7aac","schema_fingerprint":"4aa3821a28b0b7c2400bc59aba4bcc0a76e971dadd19610d3ad38c768e124dc7","schema_version":"edge-lab-recorder.raw.v1","sequence":null,"source":"clob_market_ws"}
{"event_at":"2026-07-28T03:03:48.725000Z","event_fingerprint":"f4aff34a51ceb2fa039843c4ca16e27875e590ce8e601a35b1f4bfa194791c61","payload":{"connection_id":"a6b55582af5f430fb37ad02bf0922475","event_at":"2026-07-28T03:03:48.725000Z","event_type":"price_change","frame_hash":"81b85150ad7e4c394879838b7b1b3017c5d5c92240a3bdbd9b36cad10ae35994","frame_index":0,"kind":"data","monotonic_ns":309811613875250,"payload":{"event_type":"price_change","market":"0x779291bef19b6709f61e9764a954aafe9ffae488d50ae674aabdcb4f248006d5","price_changes":[{"asset_id":"8761897749749422724209054078244794145777693856614463256546737399611489089783","best_ask":"0.38","best_bid":"0.37","hash":"c3bb0e8578e48b6dd38e94f19bce354c0cd34070","price":"0.34","side":"BUY","size":"123.23"},{"asset_id":"14965588658799411272385430903075831224615961675357217884735713260981483529984","best_ask":"0.63","best_bid":"0.62","hash":"8c665730a3f9f86538d8bc131b780192e79e0c58","price":"0.66","side":"SELL","size":"123.23"}],"timestamp":"1785207828725"},"payload_hash":"be0dfe79dd8112eb27383fdf3eb859e3ee15602f1dcb2b4b7e3d409b2b35c8c9","raw_frame":"{\"market\":\"0x779291bef19b6709f61e9764a954aafe9ffae488d50ae674aabdcb4f248006d5\", \"price_changes\":[{\"asset_id\":\"8761897749749422724209054078244794145777693856614463256546737399611489089783\", \"price\":\"0.34\", \"size\":\"123.23\", \"side\":\"BUY\", \"hash\":\"c3bb0e8578e48b6dd38e94f19bce354c0cd34070\", \"best_bid\":\"0.37\", \"best_ask\":\"0.38\"}, {\"asset_id\":\"14965588658799411272385430903075831224615961675357217884735713260981483529984\", \"price\":\"0.66\", \"size\":\"123.23\", \"side\":\"SELL\", \"hash\":\"8c665730a3f9f86538d8bc131b780192e79e0c58\", \"best_bid\":\"0.62\", \"best_ask\":\"0.63\"}], \"timestamp\":\"1785207828725\", \"event_type\":\"price_change\"}","received_at":"2026-07-28T03:03:48.593859Z","schema_version":"clob-market-ws.price_change.v1","sequence":null,"server_hash":null,"server_timestamp":"1785207828725","session_id":"3e519d9098404c15b234d96025eb1a2b","source":"clob_market_ws"},"received_at":"2026-07-28T03:03:48.593859Z","record_id":"f38f307d5ffb0962aaf8b156c166ace279362f864f647b4b44f4a425140e6d95","schema_fingerprint":"4aa3821a28b0b7c2400bc59aba4bcc0a76e971dadd19610d3ad38c768e124dc7","schema_version":"edge-lab-recorder.raw.v1","sequence":null,"source":"clob_market_ws"}
{"event_at":"2026-07-28T03:03:48.726000Z","event_fingerprint":"739e90e16d09992ac65f5578265436b1abb2ae724e559ebfef19eda34b61fcd0","payload":{"connection_id":"a6b55582af5f430fb37ad02bf0922475","event_at":"2026-07-28T03:03:48.726000Z","event_type":"price_change","frame_hash":"3c484d6e5a2f71985038102e7f5cbdb5ccc995eb2edd37a3f23b1f5e7f062564","frame_index":0,"kind":"data","monotonic_ns":309811615437666,"payload":{"event_type":"price_change","market":"0x779291bef19b6709f61e9764a954aafe9ffae488d50ae674aabdcb4f248006d5","price_changes":[{"asset_id":"14965588658799411272385430903075831224615961675357217884735713260981483529984","best_ask":"0.63","best_bid":"0.62","hash":"9261b7ed8c3f620b087e5b111e3828a3171f143c","price":"0.57","side":"BUY","size":"89.15"},{"asset_id":"8761897749749422724209054078244794145777693856614463256546737399611489089783","best_ask":"0.38","best_bid":"0.37","hash":"d28bae3ac7eba0d0e762557070f1ec1b00b6f00b","price":"0.43","side":"SELL","size":"89.15"}],"timestamp":"1785207828726"},"payload_hash":"1d482bbd9167d50c0483196e32a6e5fee2f654b353b153909cf2218a0a84d467","raw_frame":"{\"market\":\"0x779291bef19b6709f61e9764a954aafe9ffae488d50ae674aabdcb4f248006d5\", \"price_changes\":[{\"asset_id\":\"14965588658799411272385430903075831224615961675357217884735713260981483529984\", \"price\":\"0.57\", \"size\":\"89.15\", \"side\":\"BUY\", \"hash\":\"9261b7ed8c3f620b087e5b111e3828a3171f143c\", \"best_bid\":\"0.62\", \"best_ask\":\"0.63\"}, {\"asset_id\":\"8761897749749422724209054078244794145777693856614463256546737399611489089783\", \"price\":\"0.43\", \"size\":\"89.15\", \"side\":\"SELL\", \"hash\":\"d28bae3ac7eba0d0e762557070f1ec1b00b6f00b\", \"best_bid\":\"0.37\", \"best_ask\":\"0.38\"}], \"timestamp\":\"1785207828726\", \"event_type\":\"price_change\"}","received_at":"2026-07-28T03:03:48.595423Z","schema_version":"clob-market-ws.price_change.v1","sequence":null,"server_hash":null,"server_timestamp":"1785207828726","session_id":"3e519d9098404c15b234d96025eb1a2b","source":"clob_market_ws"},"received_at":"2026-07-28T03:03:48.595423Z","record_id":"ee134a1c25086e157f2717352f59b4ee9c89712f66a71a49aaddcd4f03a542cb","schema_fingerprint":"4aa3821a28b0b7c2400bc59aba4bcc0a76e971dadd19610d3ad38c768e124dc7","schema_version":"edge-lab-recorder.raw.v1","sequence":null,"source":"clob_market_ws"}
{"event_at":"2026-07-28T03:03:48.750000Z","event_fingerprint":"b1df003e161e60ac36d68af6b0b62aed57a6bd4a9c671e8d17d90708c3aa6000","payload":{"connection_id":"a6b55582af5f430fb37ad02bf0922475","event_at":"2026-07-28T03:03:48.750000Z","event_type":"price_change","frame_hash":"61ba7ff4d8a87a2bde81b538a8cb78db97fa43fc34c02f9239e942b717f3cfdb","frame_index":0,"kind":"data","monotonic_ns":309811637798000,"payload":{"event_type":"price_change","market":"0x779291bef19b6709f61e9764a954aafe9ffae488d50ae674aabdcb4f248006d5","price_changes":[{"asset_id":"14965588658799411272385430903075831224615961675357217884735713260981483529984","best_ask":"0.63","best_bid":"0.62","hash":"34eda7146d85d16a4abfda368dbfd7cac1def82c","price":"0.04","side":"BUY","size":"668.09"},{"asset_id":"8761897749749422724209054078244794145777693856614463256546737399611489089783","best_ask":"0.38","best_bid":"0.37","hash":"be790e431e1acf454a1e04bdf0a61e22f52996f0","price":"0.96","side":"SELL","size":"668.09"}],"timestamp":"1785207828750"},"payload_hash":"27307ad8cf3c3168c1ffb4d77b11d40e1c6bcf6e48eca92a32db9fa2075d6757","raw_frame":"{\"market\":\"0x779291bef19b6709f61e9764a954aafe9ffae488d50ae674aabdcb4f248006d5\", \"price_changes\":[{\"asset_id\":\"14965588658799411272385430903075831224615961675357217884735713260981483529984\", \"price\":\"0.04\", \"size\":\"668.09\", \"side\":\"BUY\", \"hash\":\"34eda7146d85d16a4abfda368dbfd7cac1def82c\", \"best_bid\":\"0.62\", \"best_ask\":\"0.63\"}, {\"asset_id\":\"8761897749749422724209054078244794145777693856614463256546737399611489089783\", \"price\":\"0.96\", \"size\":\"668.09\", \"side\":\"SELL\", \"hash\":\"be790e431e1acf454a1e04bdf0a61e22f52996f0\", \"best_bid\":\"0.37\", \"best_ask\":\"0.38\"}], \"timestamp\":\"1785207828750\", \"event_type\":\"price_change\"}","received_at":"2026-07-28T03:03:48.617781Z","schema_version":"clob-market-ws.price_change.v1","sequence":null,"server_hash":null,"server_timestamp":"1785207828750","session_id":"3e519d9098404c15b234d96025eb1a2b","source":"clob_market_ws"},"received_at":"2026-07-28T03:03:48.617781Z","record_id":"af361a5d46782ddfdfff956660523e0cf132f095ffc4b4fdd7619d11212c2ee8","schema_fingerprint":"4aa3821a28b0b7c2400bc59aba4bcc0a76e971dadd19610d3ad38c768e124dc7","schema_version":"edge-lab-recorder.raw.v1","sequence":null,"source":"clob_market_ws"}
{"event_at":"2026-07-28T03:03:48.782000Z","event_fingerprint":"b70f58fe5fd9b7f93d83aa995be517c0de79c3a0221ca350cd34aadc77325c23","payload":{"connection_id":"a6b55582af5f430fb37ad02bf0922475","event_at":"2026-07-28T03:03:48.782000Z","event_type":"price_change","frame_hash":"e08386e90a0d549fa7919c603eae042e62fdb0514c5f322656b330ce8d4132d6","frame_index":0,"kind":"data","monotonic_ns":309811656790958,"payload":{"event_type":"price_change","market":"0x779291bef19b6709f61e9764a954aafe9ffae488d50ae674aabdcb4f248006d5","price_changes":[{"asset_id":"8761897749749422724209054078244794145777693856614463256546737399611489089783","best_ask":"0.38","best_bid":"0.37","hash":"d488c51195596dd1167da756b1cf3cee542bb623","price":"0.19","side":"BUY","size":"408.36"},{"asset_id":"14965588658799411272385430903075831224615961675357217884735713260981483529984","best_ask":"0.63","best_bid":"0.62","hash":"629501b07662d8713d99b71b9900a4651d9f7df1","price":"0.81","side":"SELL","size":"408.36"}],"timestamp":"1785207828782"},"payload_hash":"6b596a68d77a7f1aa2fbc69b8a32d913e3f8ca7ae6e2bdbe9a3247271f62c2a6","raw_frame":"{\"market\":\"0x779291bef19b6709f61e9764a954aafe9ffae488d50ae674aabdcb4f248006d5\", \"price_changes\":[{\"asset_id\":\"8761897749749422724209054078244794145777693856614463256546737399611489089783\", \"price\":\"0.19\", \"size\":\"408.36\", \"side\":\"BUY\", \"hash\":\"d488c51195596dd1167da756b1cf3cee542bb623\", \"best_bid\":\"0.37\", \"best_ask\":\"0.38\"}, {\"asset_id\":\"14965588658799411272385430903075831224615961675357217884735713260981483529984\", \"price\":\"0.81\", \"size\":\"408.36\", \"side\":\"SELL\", \"hash\":\"629501b07662d8713d99b71b9900a4651d9f7df1\", \"best_bid\":\"0.62\", \"best_ask\":\"0.63\"}], \"timestamp\":\"1785207828782\", \"event_type\":\"price_change\"}","received_at":"2026-07-28T03:03:48.636775Z","schema_version":"clob-market-ws.price_change.v1","sequence":null,"server_hash":null,"server_timestamp":"1785207828782","session_id":"3e519d9098404c15b234d96025eb1a2b","source":"clob_market_ws"},"received_at":"2026-07-28T03:03:48.636775Z","record_id":"d2a37391fbfbfe672411d26b27c9c76833e840e2f98a51c48b8636572ac4709e","schema_fingerprint":"4aa3821a28b0b7c2400bc59aba4bcc0a76e971dadd19610d3ad38c768e124dc7","schema_version":"edge-lab-recorder.raw.v1","sequence":null,"source":"clob_market_ws"}
{"event_at":"2026-07-28T03:03:48.806000Z","event_fingerprint":"4cf409755b48ad7251d08c25e5c64494f3d01f99fa27f34c7c032cd9c4e3166b","payload":{"connection_id":"a6b55582af5f430fb37ad02bf0922475","event_at":"2026-07-28T03:03:48.806000Z","event_type":"price_change","frame_hash":"4e99bd8db32c49ee9b5224037fadfdf2c1a7a25ff0f4cc796110c95be066cc1e","frame_index":0,"kind":"data","monotonic_ns":309811676955875,"payload":{"event_type":"price_change","market":"0x779291bef19b6709f61e9764a954aafe9ffae488d50ae674aabdcb4f248006d5","price_changes":[{"asset_id":"14965588658799411272385430903075831224615961675357217884735713260981483529984","best_ask":"0.63","best_bid":"0.62","hash":"bb134073099c8e161072c707f5e40b6f4d160ea8","price":"0.43","side":"BUY","size":"237.52"},{"asset_id":"8761897749749422724209054078244794145777693856614463256546737399611489089783","best_ask":"0.38","best_bid":"0.37","hash":"9a5b2c6065fa3f3133e37629c1a31a2616ed01fb","price":"0.57","side":"SELL","size":"237.52"}],"timestamp":"1785207828806"},"payload_hash":"bd0d86e0db4dab8a12b0bbcbac79c14553950efd6e84aca41a44d573c5b585e4","raw_frame":"{\"market\":\"0x779291bef19b6709f61e9764a954aafe9ffae488d50ae674aabdcb4f248006d5\", \"price_changes\":[{\"asset_id\":\"14965588658799411272385430903075831224615961675357217884735713260981483529984\", \"price\":\"0.43\", \"size\":\"237.52\", \"side\":\"BUY\", \"hash\":\"bb134073099c8e161072c707f5e40b6f4d160ea8\", \"best_bid\":\"0.62\", \"best_ask\":\"0.63\"}, {\"asset_id\":\"8761897749749422724209054078244794145777693856614463256546737399611489089783\", \"price\":\"0.57\", \"size\":\"237.52\", \"side\":\"SELL\", \"hash\":\"9a5b2c6065fa3f3133e37629c1a31a2616ed01fb\", \"best_bid\":\"0.37\", \"best_ask\":\"0.38\"}], \"timestamp\":\"1785207828806\", \"event_type\":\"price_change\"}","received_at":"2026-07-28T03:03:48.656940Z","schema_version":"clob-market-ws.price_change.v1","sequence":null,"server_hash":null,"server_timestamp":"1785207828806","session_id":"3e519d9098404c15b234d96025eb1a2b","source":"clob_market_ws"},"received_at":"2026-07-28T03:03:48.656940Z","record_id":"48756cc30c0b5f30e559b48ef8126c0dcc03cf6968d39268f9910d5fb07d732e","schema_fingerprint":"4aa3821a28b0b7c2400bc59aba4bcc0a76e971dadd19610d3ad38c768e124dc7","schema_version":"edge-lab-recorder.raw.v1","sequence":null,"source":"clob_market_ws"}
{"event_at":"2026-07-28T03:03:48.832000Z","event_fingerprint":"844898acd815bb2b467b7e4a99731a4d7fbe3f2f61aee4c1c82d3ef910088a0d","payload":{"connection_id":"a6b55582af5f430fb37ad02bf0922475","event_at":"2026-07-28T03:03:48.832000Z","event_type":"price_change","frame_hash":"0c810aa92d1350a82afd8807e77992c87204bea4ab95a7d85ed32085fae95a8e","frame_index":0,"kind":"data","monotonic_ns":309811707688666,"payload":{"event_type":"price_change","market":"0x779291bef19b6709f61e9764a954aafe9ffae488d50ae674aabdcb4f248006d5","price_changes":[{"asset_id":"14965588658799411272385430903075831224615961675357217884735713260981483529984","best_ask":"0.63","best_bid":"0.62","hash":"f609bd1ba910c76e2e20727a0c10e58fe37ac974","price":"0.04","side":"BUY","size":"673.09"},{"asset_id":"8761897749749422724209054078244794145777693856614463256546737399611489089783","best_ask":"0.38","best_bid":"0.37","hash":"3fa2070265cb44e68a7aed289fff3cb22691c077","price":"0.96","side":"SELL","size":"673.09"}],"timestamp":"1785207828832"},"payload_hash":"40ccc0c54c612386aad4647dc06d255592b45cb5618e1cc82039575332ddff73","raw_frame":"{\"market\":\"0x779291bef19b6709f61e9764a954aafe9ffae488d50ae674aabdcb4f248006d5\", \"price_changes\":[{\"asset_id\":\"14965588658799411272385430903075831224615961675357217884735713260981483529984\", \"price\":\"0.04\", \"size\":\"673.09\", \"side\":\"BUY\", \"hash\":\"f609bd1ba910c76e2e20727a0c10e58fe37ac974\", \"best_bid\":\"0.62\", \"best_ask\":\"0.63\"}, {\"asset_id\":\"8761897749749422724209054078244794145777693856614463256546737399611489089783\", \"price\":\"0.96\", \"size\":\"673.09\", \"side\":\"SELL\", \"hash\":\"3fa2070265cb44e68a7aed289fff3cb22691c077\", \"best_bid\":\"0.37\", \"best_ask\":\"0.38\"}], \"timestamp\":\"1785207828832\", \"event_type\":\"price_change\"}","received_at":"2026-07-28T03:03:48.687671Z","schema_version":"clob-market-ws.price_change.v1","sequence":null,"server_hash":null,"server_timestamp":"1785207828832","session_id":"3e519d9098404c15b234d96025eb1a2b","source":"clob_market_ws"},"received_at":"2026-07-28T03:03:48.687671Z","record_id":"a50c1124ff6c38e952d5505a4fab9a63ab4500da52a74b75263773b6d150ba07","schema_fingerprint":"4aa3821a28b0b7c2400bc59aba4bcc0a76e971dadd19610d3ad38c768e124dc7","schema_version":"edge-lab-recorder.raw.v1","sequence":null,"source":"clob_market_ws"}
{"event_at":"2026-07-28T03:03:48.900000Z","event_fingerprint":"6eefbac1c0bd60b8ce45f208984fc88c1ad904834e12f4e46ffc41fc3cf5d284","payload":{"connection_id":"a6b55582af5f430fb37ad02bf0922475","event_at":"2026-07-28T03:03:48.900000Z","event_type":"price_change","frame_hash":"ce9652d88c396b8ba5b6c5e7640f961ee3828afac0216fed93b97968c3e47230","frame_index":0,"kind":"data","monotonic_ns":309811771786416,"payload":{"event_type":"price_change","market":"0x779291bef19b6709f61e9764a954aafe9ffae488d50ae674aabdcb4f248006d5","price_changes":[{"asset_id":"14965588658799411272385430903075831224615961675357217884735713260981483529984","best_ask":"0.63","best_bid":"0.62","hash":"02a2cea975c4cf5fc1ff2ab68d225ab75dc1e389","price":"0.04","side":"BUY","size":"668.09"},{"asset_id":"8761897749749422724209054078244794145777693856614463256546737399611489089783","best_ask":"0.38","best_bid":"0.37","hash":"da97e35d8d298da525ef0f5c78ddd237d0776b0e","price":"0.96","side":"SELL","size":"668.09"}],"timestamp":"1785207828900"},"payload_hash":"ad19f044fba992ce50fe54014c959458138fcffcb1e298f8716df959c3c98c70","raw_frame":"{\"market\":\"0x779291bef19b6709f61e9764a954aafe9ffae488d50ae674aabdcb4f248006d5\", \"price_changes\":[{\"asset_id\":\"14965588658799411272385430903075831224615961675357217884735713260981483529984\", \"price\":\"0.04\", \"size\":\"668.09\", \"side\":\"BUY\", \"hash\":\"02a2cea975c4cf5fc1ff2ab68d225ab75dc1e389\", \"best_bid\":\"0.62\", \"best_ask\":\"0.63\"}, {\"asset_id\":\"8761897749749422724209054078244794145777693856614463256546737399611489089783\", \"price\":\"0.96\", \"size\":\"668.09\", \"side\":\"SELL\", \"hash\":\"da97e35d8d298da525ef0f5c78ddd237d0776b0e\", \"best_bid\":\"0.37\", \"best_ask\":\"0.38\"}], \"timestamp\":\"1785207828900\", \"event_type\":\"price_change\"}","received_at":"2026-07-28T03:03:48.751768Z","schema_version":"clob-market-ws.price_change.v1","sequence":null,"server_hash":null,"server_timestamp":"1785207828900","session_id":"3e519d9098404c15b234d96025eb1a2b","source":"clob_market_ws"},"received_at":"2026-07-28T03:03:48.751768Z","record_id":"667eb88b8853304d114443a07721aa54df6d83bd185c25a6040d66228ccb7f61","schema_fingerprint":"4aa3821a28b0b7c2400bc59aba4bcc0a76e971dadd19610d3ad38c768e124dc7","schema_version":"edge-lab-recorder.raw.v1","sequence":null,"source":"clob_market_ws"}
{"event_at":"2026-07-28T03:03:48.908000Z","event_fingerprint":"2d3bde2ce5dea8033bfb07333f2760342eec1d801ad3e2a587005a6bb1fb7293","payload":{"connection_id":"a6b55582af5f430fb37ad02bf0922475","event_at":"2026-07-28T03:03:48.908000Z","event_type":"price_change","frame_hash":"a981883ca02e240dd6202af0d7a4f60dd3111f656588e976cc6d617aca64605c","frame_index":0,"kind":"data","monotonic_ns":309811777893833,"payload":{"event_type":"price_change","market":"0x779291bef19b6709f61e9764a954aafe9ffae488d50ae674aabdcb4f248006d5","price_changes":[{"asset_id":"8761897749749422724209054078244794145777693856614463256546737399611489089783","best_ask":"0.38","best_bid":"0.37","hash":"64ee24aca5ee423a657e3225e42110c65f5aea53","price":"0.19","side":"BUY","size":"583.79"},{"asset_id":"14965588658799411272385430903075831224615961675357217884735713260981483529984","best_ask":"0.63","best_bid":"0.62","hash":"d6860b2bfe3a4598243337918780fa6f1a7be24a","price":"0.81","side":"SELL","size":"583.79"}],"timestamp":"1785207828908"},"payload_hash":"09c6adfcc16e0dce6ba25350ea88ea86c9e3a948d3fc6f6387f500f61b1f79c4","raw_frame":"{\"market\":\"0x779291bef19b6709f61e9764a954aafe9ffae488d50ae674aabdcb4f248006d5\", \"price_changes\":[{\"asset_id\":\"8761897749749422724209054078244794145777693856614463256546737399611489089783\", \"price\":\"0.19\", \"size\":\"583.79\", \"side\":\"BUY\", \"hash\":\"64ee24aca5ee423a657e3225e42110c65f5aea53\", \"best_bid\":\"0.37\", \"best_ask\":\"0.38\"}, {\"asset_id\":\"14965588658799411272385430903075831224615961675357217884735713260981483529984\", \"price\":\"0.81\", \"size\":\"583.79\", \"side\":\"SELL\", \"hash\":\"d6860b2bfe3a4598243337918780fa6f1a7be24a\", \"best_bid\":\"0.62\", \"best_ask\":\"0.63\"}], \"timestamp\":\"1785207828908\", \"event_type\":\"price_change\"}","received_at":"2026-07-28T03:03:48.757877Z","schema_version":"clob-market-ws.price_change.v1","sequence":null,"server_hash":null,"server_timestamp":"1785207828908","session_id":"3e519d9098404c15b234d96025eb1a2b","source":"clob_market_ws"},"received_at":"2026-07-28T03:03:48.757877Z","record_id":"f79bc4614ee5b31a97899d214bb4f22ad730f5db7c2198cd7cf3311142087a60","schema_fingerprint":"4aa3821a28b0b7c2400bc59aba4bcc0a76e971dadd19610d3ad38c768e124dc7","schema_version":"edge-lab-recorder.raw.v1","sequence":null,"source":"clob_market_ws"}
{"event_at":"2026-07-28T03:03:48.919000Z","event_fingerprint":"af714b57ea546f0136ba3c62427dbcf612fcd3252c7123228e8f3cbae6288847","payload":{"connection_id":"a6b55582af5f430fb37ad02bf0922475","event_at":"2026-07-28T03:03:48.919000Z","event_type":"price_change","frame_hash":"41c3de96e94f7cec5956e85e2dbb2851a21689c42e9a688cfd212dfcbdbf65f8","frame_index":0,"kind":"data","monotonic_ns":309811791554875,"payload":{"event_type":"price_change","market":"0x779291bef19b6709f61e9764a954aafe9ffae488d50ae674aabdcb4f248006d5","price_changes":[{"asset_id":"14965588658799411272385430903075831224615961675357217884735713260981483529984","best_ask":"0.63","best_bid":"0.62","hash":"2c018d1829bf1faaac37efad085ad91581b47fdb","price":"0.01","side":"BUY","size":"7888.02"},{"asset_id":"8761897749749422724209054078244794145777693856614463256546737399611489089783","best_ask":"0.38","best_bid":"0.37","hash":"b51359b542a3bede377b499fdf1233cd53182c7b","price":"0.99","side":"SELL","size":"7888.02"}],"timestamp":"1785207828919"},"payload_hash":"132163e26ddfff017d5cc27c403484a6384bcb9a5a853397f38af70337cb4288","raw_frame":"{\"market\":\"0x779291bef19b6709f61e9764a954aafe9ffae488d50ae674aabdcb4f248006d5\", \"price_changes\":[{\"asset_id\":\"14965588658799411272385430903075831224615961675357217884735713260981483529984\", \"price\":\"0.01\", \"size\":\"7888.02\", \"side\":\"BUY\", \"hash\":\"2c018d1829bf1faaac37efad085ad91581b47fdb\", \"best_bid\":\"0.62\", \"best_ask\":\"0.63\"}, {\"asset_id\":\"8761897749749422724209054078244794145777693856614463256546737399611489089783\", \"price\":\"0.99\", \"size\":\"7888.02\", \"side\":\"SELL\", \"hash\":\"b51359b542a3bede377b499fdf1233cd53182c7b\", \"best_bid\":\"0.37\", \"best_ask\":\"0.38\"}], \"timestamp\":\"1785207828919\", \"event_type\":\"price_change\"}","received_at":"2026-07-28T03:03:48.771535Z","schema_version":"clob-market-ws.price_change.v1","sequence":null,"server_hash":null,"server_timestamp":"1785207828919","session_id":"3e519d9098404c15b234d96025eb1a2b","source":"clob_market_ws"},"received_at":"2026-07-28T03:03:48.771535Z","record_id":"83543f2bb481b844fc4f075db4c1115d3edabcd68e20b5f3904934e4a0d64814","schema_fingerprint":"4aa3821a28b0b7c2400bc59aba4bcc0a76e971dadd19610d3ad38c768e124dc7","schema_version":"edge-lab-recorder.raw.v1","sequence":null,"source":"clob_market_ws"}
{"event_at":"2026-07-28T03:03:48.933000Z","event_fingerprint":"e991afbfe32b884d6c5501922f27815ccb54b4a6e546854591b072383abcaf2c","payload":{"connection_id":"a6b55582af5f430fb37ad02bf0922475","event_at":"2026-07-28T03:03:48.933000Z","event_type":"price_change","frame_hash":"ecafdbae0d796a2d035ac3175a71abda147149ea5d17a5e67c792a255546dc43","frame_index":0,"kind":"data","monotonic_ns":309811803105333,"payload":{"event_type":"price_change","market":"0x779291bef19b6709f61e9764a954aafe9ffae488d50ae674aabdcb4f248006d5","price_changes":[{"asset_id":"14965588658799411272385430903075831224615961675357217884735713260981483529984","best_ask":"0.63","best_bid":"0.62","hash":"9462bf824c7591b61c0c49bbe920af58bd70a5d3","price":"0.43","side":"BUY","size":"315.03"},{"asset_id":"8761897749749422724209054078244794145777693856614463256546737399611489089783","best_ask":"0.38","best_bid":"0.37","hash":"a776ad6861810404924aeee1d9e96f01bc87d54a","price":"0.57","side":"SELL","size":"315.03"}],"timestamp":"1785207828933"},"payload_hash":"ddba2a2b1025970a8d72f82e519b25be24ff24b00e79b9dbe05419316b8d517f","raw_frame":"{\"market\":\"0x779291bef19b6709f61e9764a954aafe9ffae488d50ae674aabdcb4f248006d5\", \"price_changes\":[{\"asset_id\":\"14965588658799411272385430903075831224615961675357217884735713260981483529984\", \"price\":\"0.43\", \"size\":\"315.03\", \"side\":\"BUY\", \"hash\":\"9462bf824c7591b61c0c49bbe920af58bd70a5d3\", \"best_bid\":\"0.62\", \"best_ask\":\"0.63\"}, {\"asset_id\":\"8761897749749422724209054078244794145777693856614463256546737399611489089783\", \"price\":\"0.57\", \"size\":\"315.03\", \"side\":\"SELL\", \"hash\":\"a776ad6861810404924aeee1d9e96f01bc87d54a\", \"best_bid\":\"0.37\", \"best_ask\":\"0.38\"}], \"timestamp\":\"1785207828933\", \"event_type\":\"price_change\"}","received_at":"2026-07-28T03:03:48.783088Z","schema_version":"clob-market-ws.price_change.v1","sequence":null,"server_hash":null,"server_timestamp":"1785207828933","session_id":"3e519d9098404c15b234d96025eb1a2b","source":"clob_market_ws"},"received_at":"2026-07-28T03:03:48.783088Z","record_id":"c0e2058923dd0d85f8f2baa63f337f738683c7ba292f98c0dca150d91fee817f","schema_fingerprint":"4aa3821a28b0b7c2400bc59aba4bcc0a76e971dadd19610d3ad38c768e124dc7","schema_version":"edge-lab-recorder.raw.v1","sequence":null,"source":"clob_market_ws"}
{"event_at":"2026-07-28T03:03:48.939000Z","event_fingerprint":"c281212e4d5a60798bd8f348946fe05c0c2c02ebecc98eb6f04f4951637a60e1","payload":{"connection_id":"a6b55582af5f430fb37ad02bf0922475","event_at":"2026-07-28T03:03:48.939000Z","event_type":"price_change","frame_hash":"76abeb65741b50388e2f019ce3b6cea34de7d96a34e260a61a8259f8c6a83a3a","frame_index":0,"kind":"data","monotonic_ns":309811808815458,"payload":{"event_type":"price_change","market":"0x779291bef19b6709f61e9764a954aafe9ffae488d50ae674aabdcb4f248006d5","price_changes":[{"asset_id":"14965588658799411272385430903075831224615961675357217884735713260981483529984","best_ask":"0.63","best_bid":"0.62","hash":"3b99e063e4ffd7da00d29642f34d9d653da8be22","price":"0.01","side":"BUY","size":"7883.02"},{"asset_id":"8761897749749422724209054078244794145777693856614463256546737399611489089783","best_ask":"0.38","best_bid":"0.37","hash":"e6ee62d53b7dbd25072514712b97fc77c3b87d59","price":"0.99","side":"SELL","size":"7883.02"}],"timestamp":"1785207828939"},"payload_hash":"eae396e41a9559f14c1246939da4b6522602b7ad765e1528d077dee2cab067dc","raw_frame":"{\"market\":\"0x779291bef19b6709f61e9764a954aafe9ffae488d50ae674aabdcb4f248006d5\", \"price_changes\":[{\"asset_id\":\"14965588658799411272385430903075831224615961675357217884735713260981483529984\", \"price\":\"0.01\", \"size\":\"7883.02\", \"side\":\"BUY\", \"hash\":\"3b99e063e4ffd7da00d29642f34d9d653da8be22\", \"best_bid\":\"0.62\", \"best_ask\":\"0.63\"}, {\"asset_id\":\"8761897749749422724209054078244794145777693856614463256546737399611489089783\", \"price\":\"0.99\", \"size\":\"7883.02\", \"side\":\"SELL\", \"hash\":\"e6ee62d53b7dbd25072514712b97fc77c3b87d59\", \"best_bid\":\"0.37\", \"best_ask\":\"0.38\"}], \"timestamp\":\"1785207828939\", \"event_type\":\"price_change\"}","received_at":"2026-07-28T03:03:48.788796Z","schema_version":"clob-market-ws.price_change.v1","sequence":null,"server_hash":null,"server_timestamp":"1785207828939","session_id":"3e519d9098404c15b234d96025eb1a2b","source":"clob_market_ws"},"received_at":"2026-07-28T03:03:48.788796Z","record_id":"2ca235611896f83ee5046b350c2e2da9521d9d9b1e4ee91fbd0ab7dd58015e17","schema_fingerprint":"4aa3821a28b0b7c2400bc59aba4bcc0a76e971dadd19610d3ad38c768e124dc7","schema_version":"edge-lab-recorder.raw.v1","sequence":null,"source":"clob_market_ws"}
{"event_at":"2026-07-28T03:03:48.997000Z","event_fingerprint":"d543d62048d58ff9bdb837d09edb4107f8909b486d8453b3df2725614d9f3b7b","payload":{"connection_id":"a6b55582af5f430fb37ad02bf0922475","event_at":"2026-07-28T03:03:48.997000Z","event_type":"price_change","frame_hash":"ad858fa925f34167d328aa8395c8a287ae5f0f7354c2f68501ee17f3f99d853f","frame_index":0,"kind":"data","monotonic_ns":309811869067291,"payload":{"event_type":"price_change","market":"0x779291bef19b6709f61e9764a954aafe9ffae488d50ae674aabdcb4f248006d5","price_changes":[{"asset_id":"14965588658799411272385430903075831224615961675357217884735713260981483529984","best_ask":"0.63","best_bid":"0.62","hash":"de00dc8e507e6a8e528d71413e0fd8248b8bb53c","price":"0.01","side":"BUY","size":"7888.02"},{"asset_id":"8761897749749422724209054078244794145777693856614463256546737399611489089783","best_ask":"0.38","best_bid":"0.37","hash":"514b94d93e1e1145323484e7d9eb0e8661e0ba6a","price":"0.99","side":"SELL","size":"7888.02"}],"timestamp":"1785207828997"},"payload_hash":"1fb1a60ed1f66f75d64d29acf5673bc88b9ee088d835d45f085c155bac286cab","raw_frame":"{\"market\":\"0x779291bef19b6709f61e9764a954aafe9ffae488d50ae674aabdcb4f248006d5\", \"price_changes\":[{\"asset_id\":\"14965588658799411272385430903075831224615961675357217884735713260981483529984\", \"price\":\"0.01\", \"size\":\"7888.02\", \"side\":\"BUY\", \"hash\":\"de00dc8e507e6a8e528d71413e0fd8248b8bb53c\", \"best_bid\":\"0.62\", \"best_ask\":\"0.63\"}, {\"asset_id\":\"8761897749749422724209054078244794145777693856614463256546737399611489089783\", \"price\":\"0.99\", \"size\":\"7888.02\", \"side\":\"SELL\", \"hash\":\"514b94d93e1e1145323484e7d9eb0e8661e0ba6a\", \"best_bid\":\"0.37\", \"best_ask\":\"0.38\"}], \"timestamp\":\"1785207828997\", \"event_type\":\"price_change\"}","received_at":"2026-07-28T03:03:48.849050Z","schema_version":"clob-market-ws.price_change.v1","sequence":null,"server_hash":null,"server_timestamp":"1785207828997","session_id":"3e519d9098404c15b234d96025eb1a2b","source":"clob_market_ws"},"received_at":"2026-07-28T03:03:48.849050Z","record_id":"b98a2fbd931fb1caa68cce652da7b7114cfff4d519f36f88ba3665a4b7161a84","schema_fingerprint":"4aa3821a28b0b7c2400bc59aba4bcc0a76e971dadd19610d3ad38c768e124dc7","schema_version":"edge-lab-recorder.raw.v1","sequence":null,"source":"clob_market_ws"}
{"event_at":"2026-07-28T03:03:49.016000Z","event_fingerprint":"85b63ca93cedccf7c44002bdd60630ef0cf877ea6432bdd2c5bf42ec4a13f62a","payload":{"connection_id":"a6b55582af5f430fb37ad02bf0922475","event_at":"2026-07-28T03:03:49.016000Z","event_type":"price_change","frame_hash":"160324f3ff0338e07bb0116d648b938af48aeeb2918c850fae732a7fc0a1236f","frame_index":0,"kind":"data","monotonic_ns":309811886730625,"payload":{"event_type":"price_change","market":"0x779291bef19b6709f61e9764a954aafe9ffae488d50ae674aabdcb4f248006d5","price_changes":[{"asset_id":"14965588658799411272385430903075831224615961675357217884735713260981483529984","best_ask":"0.63","best_bid":"0.62","hash":"aab38c2c80c04b1a105583970e46d0ea97d45cd2","price":"0.01","side":"BUY","size":"7893.02"},{"asset_id":"8761897749749422724209054078244794145777693856614463256546737399611489089783","best_ask":"0.38","best_bid":"0.37","hash":"e2f3edc6e7f3b40435e06c11b9669a177a68ff3c","price":"0.99","side":"SELL","size":"7893.02"}],"timestamp":"1785207829016"},"payload_hash":"407c09ec438659d07ee24aa4567bf922aaaec6fd4060cf9e645f90ec5afb118a","raw_frame":"{\"market\":\"0x779291bef19b6709f61e9764a954aafe9ffae488d50ae674aabdcb4f248006d5\", \"price_changes\":[{\"asset_id\":\"14965588658799411272385430903075831224615961675357217884735713260981483529984\", \"price\":\"0.01\", \"size\":\"7893.02\", \"side\":\"BUY\", \"hash\":\"aab38c2c80c04b1a105583970e46d0ea97d45cd2\", \"best_bid\":\"0.62\", \"best_ask\":\"0.63\"}, {\"asset_id\":\"8761897749749422724209054078244794145777693856614463256546737399611489089783\", \"price\":\"0.99\", \"size\":\"7893.02\", \"side\":\"SELL\", \"hash\":\"e2f3edc6e7f3b40435e06c11b9669a177a68ff3c\", \"best_bid\":\"0.37\", \"best_ask\":\"0.38\"}], \"timestamp\":\"1785207829016\", \"event_type\":\"price_change\"}","received_at":"2026-07-28T03:03:48.866714Z","schema_version":"clob-market-ws.price_change.v1","sequence":null,"server_hash":null,"server_timestamp":"1785207829016","session_id":"3e519d9098404c15b234d96025eb1a2b","source":"clob_market_ws"},"received_at":"2026-07-28T03:03:48.866714Z","record_id":"2f756147b72f62b2e76cc97a11581c529539e3c9ae43b2cc079d53cfc649875f","schema_fingerprint":"4aa3821a28b0b7c2400bc59aba4bcc0a76e971dadd19610d3ad38c768e124dc7","schema_version":"edge-lab-recorder.raw.v1","sequence":null,"source":"clob_market_ws"}
{"event_at":"2026-07-28T03:03:49.019000Z","event_fingerprint":"2d738a7a6832a455854535bb28cb451625416a912cdcd86d0a5af2dc66b2424f","payload":{"connection_id":"a6b55582af5f430fb37ad02bf0922475","event_at":"2026-07-28T03:03:49.019000Z","event_type":"price_change","frame_hash":"c231eee83173337f47a40564a74122006b1e16d038e717efd5e61f68ba5971d9","frame_index":0,"kind":"data","monotonic_ns":309811889742125,"payload":{"event_type":"price_change","market":"0x779291bef19b6709f61e9764a954aafe9ffae488d50ae674aabdcb4f248006d5","price_changes":[{"asset_id":"8761897749749422724209054078244794145777693856614463256546737399611489089783","best_ask":"0.38","best_bid":"0.37","hash":"76eca8d0ac623b69018c25a43678cf0931675edb","price":"0.01","side":"BUY","size":"7858.02"},{"asset_id":"14965588658799411272385430903075831224615961675357217884735713260981483529984","best_ask":"0.63","best_bid":"0.62","hash":"bc48ad5da52f179e9b6e900cf71dc980f5b032c6","price":"0.99","side":"SELL","size":"7858.02"}],"timestamp":"1785207829019"},"payload_hash":"9d4dce768e57ee7326b354743e5de31610c0eeea5392084ad7e68b58b21aaedb","raw_frame":"{\"market\":\"0x779291bef19b6709f61e9764a954aafe9ffae488d50ae674aabdcb4f248006d5\", \"price_changes\":[{\"asset_id\":\"8761897749749422724209054078244794145777693856614463256546737399611489089783\", \"price\":\"0.01\", \"size\":\"7858.02\", \"side\":\"BUY\", \"hash\":\"76eca8d0ac623b69018c25a43678cf0931675edb\", \"best_bid\":\"0.37\", \"best_ask\":\"0.38\"}, {\"asset_id\":\"14965588658799411272385430903075831224615961675357217884735713260981483529984\", \"price\":\"0.99\", \"size\":\"7858.02\", \"side\":\"SELL\", \"hash\":\"bc48ad5da52f179e9b6e900cf71dc980f5b032c6\", \"best_bid\":\"0.62\", \"best_ask\":\"0.63\"}], \"timestamp\":\"1785207829019\", \"event_type\":\"price_change\"}","received_at":"2026-07-28T03:03:48.869726Z","schema_version":"clob-market-ws.price_change.v1","sequence":null,"server_hash":null,"server_timestamp":"1785207829019","session_id":"3e519d9098404c15b234d96025eb1a2b","source":"clob_market_ws"},"received_at":"2026-07-28T03:03:48.869726Z","record_id":"b98ae23a6b6b1ec08dd8d49d8bbd7eb6f1b935cc89dbb1800ef88eec4ea1d163","schema_fingerprint":"4aa3821a28b0b7c2400bc59aba4bcc0a76e971dadd19610d3ad38c768e124dc7","schema_version":"edge-lab-recorder.raw.v1","sequence":null,"source":"clob_market_ws"}
{"event_at":"2026-07-28T03:03:49.030000Z","event_fingerprint":"ce08dc6cfb542790e6220a1c3664ffe779de96fdc23141669228bdc76166c1ec","payload":{"connection_id":"a6b55582af5f430fb37ad02bf0922475","event_at":"2026-07-28T03:03:49.030000Z","event_type":"price_change","frame_hash":"8a67202145b76648d4b1c7f482411c26e7ceaeb20e4eea76acd17cd0a9de51e7","frame_index":0,"kind":"data","monotonic_ns":309811900750166,"payload":{"event_type":"price_change","market":"0x779291bef19b6709f61e9764a954aafe9ffae488d50ae674aabdcb4f248006d5","price_changes":[{"asset_id":"8761897749749422724209054078244794145777693856614463256546737399611489089783","best_ask":"0.38","best_bid":"0.37","hash":"cfe990db5ceaa081a2d42b851e4610ada0ce6914","price":"0.3","side":"BUY","size":"206"},{"asset_id":"14965588658799411272385430903075831224615961675357217884735713260981483529984","best_ask":"0.63","best_bid":"0.62","hash":"59774b0a3f54d74688394c6957cbf1c10caaf0a9","price":"0.7","side":"SELL","size":"206"}],"timestamp":"1785207829030"},"payload_hash":"4da98cec7499140a2bdbb943d9e4e51177c4dabb2a3991cdc6e5b9cc8d834bcf","raw_frame":"{\"market\":\"0x779291bef19b6709f61e9764a954aafe9ffae488d50ae674aabdcb4f248006d5\", \"price_changes\":[{\"asset_id\":\"8761897749749422724209054078244794145777693856614463256546737399611489089783\", \"price\":\"0.3\", \"size\":\"206\", \"side\":\"BUY\", \"hash\":\"cfe990db5ceaa081a2d42b851e4610ada0ce6914\", \"best_bid\":\"0.37\", \"best_ask\":\"0.38\"}, {\"asset_id\":\"14965588658799411272385430903075831224615961675357217884735713260981483529984\", \"price\":\"0.7\", \"size\":\"206\", \"side\":\"SELL\", \"hash\":\"59774b0a3f54d74688394c6957cbf1c10caaf0a9\", \"best_bid\":\"0.62\", \"best_ask\":\"0.63\"}], \"timestamp\":\"1785207829030\", \"event_type\":\"price_change\"}","received_at":"2026-07-28T03:03:48.880731Z","schema_version":"clob-market-ws.price_change.v1","sequence":null,"server_hash":null,"server_timestamp":"1785207829030","session_id":"3e519d9098404c15b234d96025eb1a2b","source":"clob_market_ws"},"received_at":"2026-07-28T03:03:48.880731Z","record_id":"3db5d745aeb02c868bab137a1a52912b159b456be4b1c2729f0186ce5e5be26a","schema_fingerprint":"4aa3821a28b0b7c2400bc59aba4bcc0a76e971dadd19610d3ad38c768e124dc7","schema_version":"edge-lab-recorder.raw.v1","sequence":null,"source":"clob_market_ws"}
{"event_at":"2026-07-28T03:03:49.033000Z","event_fingerprint":"bad6f74e9c35efba03cb2e6e9f56de7dcb79775df5dc1530c14753b9896115ef","payload":{"connection_id":"a6b55582af5f430fb37ad02bf0922475","event_at":"2026-07-28T03:03:49.033000Z","event_type":"price_change","frame_hash":"01207c2c0d1b69d9d2dfc32c3dacbd1387b9c19c0875d4673a9e18fdb0223bba","frame_index":0,"kind":"data","monotonic_ns":309811902836416,"payload":{"event_type":"price_change","market":"0x779291bef19b6709f61e9764a954aafe9ffae488d50ae674aabdcb4f248006d5","price_changes":[{"asset_id":"8761897749749422724209054078244794145777693856614463256546737399611489089783","best_ask":"0.38","best_bid":"0.37","hash":"b6dcbee87fcf023cd3c11913b401efe24b9d9902","price":"0.01","side":"BUY","size":"7863.02"},{"asset_id":"14965588658799411272385430903075831224615961675357217884735713260981483529984","best_ask":"0.63","best_bid":"0.62","hash":"a28d4862e7c6396163aeb8010e252a901dd90545","price":"0.99","side":"SELL","size":"7863.02"}],"timestamp":"1785207829033"},"payload_hash":"306c6e1c2c8bd4591d8bcd5b39642bdc0fcb86493b4f1c12f0a5017653cc7da9","raw_frame":"{\"market\":\"0x779291bef19b6709f61e9764a954aafe9ffae488d50ae674aabdcb4f248006d5\", \"price_changes\":[{\"asset_id\":\"8761897749749422724209054078244794145777693856614463256546737399611489089783\", \"price\":\"0.01\", \"size\":\"7863.02\", \"side\":\"BUY\", \"hash\":\"b6dcbee87fcf023cd3c11913b401efe24b9d9902\", \"best_bid\":\"0.37\", \"best_ask\":\"0.38\"}, {\"asset_id\":\"14965588658799411272385430903075831224615961675357217884735713260981483529984\", \"price\":\"0.99\", \"size\":\"7863.02\", \"side\":\"SELL\", \"hash\":\"a28d4862e7c6396163aeb8010e252a901dd90545\", \"best_bid\":\"0.62\", \"best_ask\":\"0.63\"}], \"timestamp\":\"1785207829033\", \"event_type\":\"price_change\"}","received_at":"2026-07-28T03:03:48.882819Z","schema_version":"clob-market-ws.price_change.v1","sequence":null,"server_hash":null,"server_timestamp":"1785207829033","session_id":"3e519d9098404c15b234d96025eb1a2b","source":"clob_market_ws"},"received_at":"2026-07-28T03:03:48.882819Z","record_id":"c0bf28e8431bf462f479f10e45bedea17bdecdb6c123d7ccb8290dbaaf2ae40a","schema_fingerprint":"4aa3821a28b0b7c2400bc59aba4bcc0a76e971dadd19610d3ad38c768e124dc7","schema_version":"edge-lab-recorder.raw.v1","sequence":null,"source":"clob_market_ws"}
{"event_at":"2026-07-28T03:03:49.045000Z","event_fingerprint":"e73b177c3fbad47315b0cdf5b30407403178aa205e4afbfff0826eae4ebcbd49","payload":{"connection_id":"a6b55582af5f430fb37ad02bf0922475","event_at":"2026-07-28T03:03:49.045000Z","event_type":"price_change","frame_hash":"00c597a74fbe959e5682180681efecd2377ecd57ed92d6e8dba59688be1441bb","frame_index":0,"kind":"data","monotonic_ns":309811914700458,"payload":{"event_type":"price_change","market":"0x779291bef19b6709f61e9764a954aafe9ffae488d50ae674aabdcb4f248006d5","price_changes":[{"asset_id":"14965588658799411272385430903075831224615961675357217884735713260981483529984","best_ask":"0.63","best_bid":"0.62","hash":"ae9b68e1abc3d13d4c0265ef4b3cf12c127ea4d7","price":"0.01","side":"BUY","size":"7888.02"},{"asset_id":"8761897749749422724209054078244794145777693856614463256546737399611489089783","best_ask":"0.38","best_bid":"0.37","hash":"59846a4032ddddb72cc422aedf987660b0e495fb","price":"0.99","side":"SELL","size":"7888.02"}],"timestamp":"1785207829045"},"payload_hash":"fa90e4fd9b08d5ae821d3870b6ddd63c616d79c5a9502fff53bcae7a10113777","raw_frame":"{\"market\":\"0x779291bef19b6709f61e9764a954aafe9ffae488d50ae674aabdcb4f248006d5\", \"price_changes\":[{\"asset_id\":\"14965588658799411272385430903075831224615961675357217884735713260981483529984\", \"price\":\"0.01\", \"size\":\"7888.02\", \"side\":\"BUY\", \"hash\":\"ae9b68e1abc3d13d4c0265ef4b3cf12c127ea4d7\", \"best_bid\":\"0.62\", \"best_ask\":\"0.63\"}, {\"asset_id\":\"8761897749749422724209054078244794145777693856614463256546737399611489089783\", \"price\":\"0.99\", \"size\":\"7888.02\", \"side\":\"SELL\", \"hash\":\"59846a4032ddddb72cc422aedf987660b0e495fb\", \"best_bid\":\"0.37\", \"best_ask\":\"0.38\"}], \"timestamp\":\"1785207829045\", \"event_type\":\"price_change\"}","received_at":"2026-07-28T03:03:48.894683Z","schema_version":"clob-market-ws.price_change.v1","sequence":null,"server_hash":null,"server_timestamp":"1785207829045","session_id":"3e519d9098404c15b234d96025eb1a2b","source":"clob_market_ws"},"received_at":"2026-07-28T03:03:48.894683Z","record_id":"6f6713a5b03af0cf9abf2b985ba985cb73b37e2bbf5f5ca33a07fe8b64ad7ead","schema_fingerprint":"4aa3821a28b0b7c2400bc59aba4bcc0a76e971dadd19610d3ad38c768e124dc7","schema_version":"edge-lab-recorder.raw.v1","sequence":null,"source":"clob_market_ws"}
{"event_at":"2026-07-28T03:03:49.053000Z","event_fingerprint":"8953251b213fef7d3fdb95a9eff80fb916843585625d0091116183c4e1927fca","payload":{"connection_id":"a6b55582af5f430fb37ad02bf0922475","event_at":"2026-07-28T03:03:49.053000Z","event_type":"price_change","frame_hash":"01f50cf4642abda58a4140be659a10c0d372890ae21639ade0329e9c70174eb0","frame_index":0,"kind":"data","monotonic_ns":309811925015750,"payload":{"event_type":"price_change","market":"0x779291bef19b6709f61e9764a954aafe9ffae488d50ae674aabdcb4f248006d5","price_changes":[{"asset_id":"8761897749749422724209054078244794145777693856614463256546737399611489089783","best_ask":"0.38","best_bid":"0.37","hash":"c046ca3e46ef28ac3dd055134d05ea158933acef","price":"0.01","side":"BUY","size":"7858.02"},{"asset_id":"14965588658799411272385430903075831224615961675357217884735713260981483529984","best_ask":"0.63","best_bid":"0.62","hash":"aa9c2606d6b613745bf6326c0598cd8fa15d8e28","price":"0.99","side":"SELL","size":"7858.02"}],"timestamp":"1785207829053"},"payload_hash":"33a60d8f0ec72822176e27bd1e9fee4dd257b33f7153d5d152d3b4124eb44596","raw_frame":"{\"market\":\"0x779291bef19b6709f61e9764a954aafe9ffae488d50ae674aabdcb4f248006d5\", \"price_changes\":[{\"asset_id\":\"8761897749749422724209054078244794145777693856614463256546737399611489089783\", \"price\":\"0.01\", \"size\":\"7858.02\", \"side\":\"BUY\", \"hash\":\"c046ca3e46ef28ac3dd055134d05ea158933acef\", \"best_bid\":\"0.37\", \"best_ask\":\"0.38\"}, {\"asset_id\":\"14965588658799411272385430903075831224615961675357217884735713260981483529984\", \"price\":\"0.99\", \"size\":\"7858.02\", \"side\":\"SELL\", \"hash\":\"aa9c2606d6b613745bf6326c0598cd8fa15d8e28\", \"best_bid\":\"0.62\", \"best_ask\":\"0.63\"}], \"timestamp\":\"1785207829053\", \"event_type\":\"price_change\"}","received_at":"2026-07-28T03:03:48.904998Z","schema_version":"clob-market-ws.price_change.v1","sequence":null,"server_hash":null,"server_timestamp":"1785207829053","session_id":"3e519d9098404c15b234d96025eb1a2b","source":"clob_market_ws"},"received_at":"2026-07-28T03:03:48.904998Z","record_id":"fd0e4cbd023a7e3947427ac784e94cae5537b4537a3bc7b6f01d197a871dab3a","schema_fingerprint":"4aa3821a28b0b7c2400bc59aba4bcc0a76e971dadd19610d3ad38c768e124dc7","schema_version":"edge-lab-recorder.raw.v1","sequence":null,"source":"clob_market_ws"}
{"event_at":"2026-07-28T03:03:49.055000Z","event_fingerprint":"6245aa759d4f093f7cc86a1df6891af99f2d78b6adfc9cde55800a7b7312c28b","payload":{"connection_id":"a6b55582af5f430fb37ad02bf0922475","event_at":"2026-07-28T03:03:49.055000Z","event_type":"price_change","frame_hash":"7853dde76e1d8395e2945d609c86cf85ddcc9034e557f9ff8d72044591b5b34b","frame_index":0,"kind":"data","monotonic_ns":309811934023500,"payload":{"event_type":"price_change","market":"0x779291bef19b6709f61e9764a954aafe9ffae488d50ae674aabdcb4f248006d5","price_changes":[{"asset_id":"14965588658799411272385430903075831224615961675357217884735713260981483529984","best_ask":"0.63","best_bid":"0.62","hash":"5ce885b25103ec2a24057777d5ac4ac0e05a9052","price":"0.01","side":"BUY","size":"7883.02"},{"asset_id":"8761897749749422724209054078244794145777693856614463256546737399611489089783","best_ask":"0.38","best_bid":"0.37","hash":"79e46ebee4056e8b294f912aa57abcbecccecd6d","price":"0.99","side":"SELL","size":"7883.02"}],"timestamp":"1785207829055"},"payload_hash":"821d4a9e82039d2ed4c759ec3845536c9b787ca0753afe6d4a33e51f8a9adc74","raw_frame":"{\"market\":\"0x779291bef19b6709f61e9764a954aafe9ffae488d50ae674aabdcb4f248006d5\", \"price_changes\":[{\"asset_id\":\"14965588658799411272385430903075831224615961675357217884735713260981483529984\", \"price\":\"0.01\", \"size\":\"7883.02\", \"side\":\"BUY\", \"hash\":\"5ce885b25103ec2a24057777d5ac4ac0e05a9052\", \"best_bid\":\"0.62\", \"best_ask\":\"0.63\"}, {\"asset_id\":\"8761897749749422724209054078244794145777693856614463256546737399611489089783\", \"price\":\"0.99\", \"size\":\"7883.02\", \"side\":\"SELL\", \"hash\":\"79e46ebee4056e8b294f912aa57abcbecccecd6d\", \"best_bid\":\"0.37\", \"best_ask\":\"0.38\"}], \"timestamp\":\"1785207829055\", \"event_type\":\"price_change\"}","received_at":"2026-07-28T03:03:48.914005Z","schema_version":"clob-market-ws.price_change.v1","sequence":null,"server_hash":null,"server_timestamp":"1785207829055","session_id":"3e519d9098404c15b234d96025eb1a2b","source":"clob_market_ws"},"received_at":"2026-07-28T03:03:48.914005Z","record_id":"e17884e86d028ad93b890be6baf0475084eacb9d7485bb7436dc24611512303e","schema_fingerprint":"4aa3821a28b0b7c2400bc59aba4bcc0a76e971dadd19610d3ad38c768e124dc7","schema_version":"edge-lab-recorder.raw.v1","sequence":null,"source":"clob_market_ws"}
{"event_at":"2026-07-28T03:03:49.064000Z","event_fingerprint":"506c6067e2242bc7d044e0e273de6311af2fd62ee84a99d65efd512fa4cd1ac2","payload":{"connection_id":"a6b55582af5f430fb37ad02bf0922475","event_at":"2026-07-28T03:03:49.064000Z","event_type":"price_change","frame_hash":"f9d153e1150c09fdfcbd928718ca12958906da53c761187b5000b7f6806ea8d9","frame_index":0,"kind":"data","monotonic_ns":309811935670000,"payload":{"event_type":"price_change","market":"0x779291bef19b6709f61e9764a954aafe9ffae488d50ae674aabdcb4f248006d5","price_changes":[{"asset_id":"8761897749749422724209054078244794145777693856614463256546737399611489089783","best_ask":"0.38","best_bid":"0.37","hash":"a3f99e61bde3c51b09c049e7ec3a843828262aea","price":"0.29","side":"BUY","size":"172.5"},{"asset_id":"14965588658799411272385430903075831224615961675357217884735713260981483529984","best_ask":"0.63","best_bid":"0.62","hash":"6a99d7218643b254ca72d38cc764ad2cb14e8cc1","price":"0.71","side":"SELL","size":"172.5"}],"timestamp":"1785207829064"},"payload_hash":"c28d07bd4595f3baae4f329df3f24a2e2c3d9a1404783ad2026fc0d623314d6f","raw_frame":"{\"market\":\"0x779291bef19b6709f61e9764a954aafe9ffae488d50ae674aabdcb4f248006d5\", \"price_changes\":[{\"asset_id\":\"8761897749749422724209054078244794145777693856614463256546737399611489089783\", \"price\":\"0.29\", \"size\":\"172.5\", \"side\":\"BUY\", \"hash\":\"a3f99e61bde3c51b09c049e7ec3a843828262aea\", \"best_bid\":\"0.37\", \"best_ask\":\"0.38\"}, {\"asset_id\":\"14965588658799411272385430903075831224615961675357217884735713260981483529984\", \"price\":\"0.71\", \"size\":\"172.5\", \"side\":\"SELL\", \"hash\":\"6a99d7218643b254ca72d38cc764ad2cb14e8cc1\", \"best_bid\":\"0.62\", \"best_ask\":\"0.63\"}], \"timestamp\":\"1785207829064\", \"event_type\":\"price_change\"}","received_at":"2026-07-28T03:03:48.915654Z","schema_version":"clob-market-ws.price_change.v1","sequence":null,"server_hash":null,"server_timestamp":"1785207829064","session_id":"3e519d9098404c15b234d96025eb1a2b","source":"clob_market_ws"},"received_at":"2026-07-28T03:03:48.915654Z","record_id":"954c1e3d072bdaa6565d4a2b7feb3512f2dc7acbfd7f17f08f47c8bef2c5ea32","schema_fingerprint":"4aa3821a28b0b7c2400bc59aba4bcc0a76e971dadd19610d3ad38c768e124dc7","schema_version":"edge-lab-recorder.raw.v1","sequence":null,"source":"clob_market_ws"}
{"event_at":"2026-07-28T03:03:49.089000Z","event_fingerprint":"dcbf7f87835e6c46117b1f762bb496fbf7e6f3e155305febb11aa03a9c46b4e7","payload":{"connection_id":"a6b55582af5f430fb37ad02bf0922475","event_at":"2026-07-28T03:03:49.089000Z","event_type":"price_change","frame_hash":"5eb827aa048b30c99071a87ec6441af3bf25017a822253a7b8563ab1254c0562","frame_index":0,"kind":"data","monotonic_ns":309811959106666,"payload":{"event_type":"price_change","market":"0x779291bef19b6709f61e9764a954aafe9ffae488d50ae674aabdcb4f248006d5","price_changes":[{"asset_id":"8761897749749422724209054078244794145777693856614463256546737399611489089783","best_ask":"0.38","best_bid":"0.37","hash":"3e8d907b0023b111bc41d1cadfc983b4c9159a36","price":"0.01","side":"BUY","size":"7853.02"},{"asset_id":"14965588658799411272385430903075831224615961675357217884735713260981483529984","best_ask":"0.63","best_bid":"0.62","hash":"9aa4ff611514a988807758e85adaf7ece0b44f33","price":"0.99","side":"SELL","size":"7853.02"}],"timestamp":"1785207829089"},"payload_hash":"c23b9163bb27a64d3db7026c47f7bfdf243f572b5c07bc0b6a994c9f0b591501","raw_frame":"{\"market\":\"0x779291bef19b6709f61e9764a954aafe9ffae488d50ae674aabdcb4f248006d5\", \"price_changes\":[{\"asset_id\":\"8761897749749422724209054078244794145777693856614463256546737399611489089783\", \"price\":\"0.01\", \"size\":\"7853.02\", \"side\":\"BUY\", \"hash\":\"3e8d907b0023b111bc41d1cadfc983b4c9159a36\", \"best_bid\":\"0.37\", \"best_ask\":\"0.38\"}, {\"asset_id\":\"14965588658799411272385430903075831224615961675357217884735713260981483529984\", \"price\":\"0.99\", \"size\":\"7853.02\", \"side\":\"SELL\", \"hash\":\"9aa4ff611514a988807758e85adaf7ece0b44f33\", \"best_bid\":\"0.62\", \"best_ask\":\"0.63\"}], \"timestamp\":\"1785207829089\", \"event_type\":\"price_change\"}","received_at":"2026-07-28T03:03:48.939089Z","schema_version":"clob-market-ws.price_change.v1","sequence":null,"server_hash":null,"server_timestamp":"1785207829089","session_id":"3e519d9098404c15b234d96025eb1a2b","source":"clob_market_ws"},"received_at":"2026-07-28T03:03:48.939089Z","record_id":"a04d9e5ddfb69da65a21bd11ce7b84eb3ad960ee821b1943fcf9598ba142f609","schema_fingerprint":"4aa3821a28b0b7c2400bc59aba4bcc0a76e971dadd19610d3ad38c768e124dc7","schema_version":"edge-lab-recorder.raw.v1","sequence":null,"source":"clob_market_ws"}
{"event_at":"2026-07-28T03:03:49.165000Z","event_fingerprint":"857f6e88a2ce0d76b069d2758f1ded7cf4473c65a54650b6bd4e105bba994373","payload":{"connection_id":"a6b55582af5f430fb37ad02bf0922475","event_at":"2026-07-28T03:03:49.165000Z","event_type":"price_change","frame_hash":"f7edec6ba6161bf3becea319b2d9deaa3d99c9af75fff21453b6b1d0fcf11d7e","frame_index":0,"kind":"data","monotonic_ns":309812036654375,"payload":{"event_type":"price_change","market":"0x779291bef19b6709f61e9764a954aafe9ffae488d50ae674aabdcb4f248006d5","price_changes":[{"asset_id":"14965588658799411272385430903075831224615961675357217884735713260981483529984","best_ask":"0.63","best_bid":"0.62","hash":"2d41222a8b6b5edbf12f61072c1345db12d96ff6","price":"0.57","side":"BUY","size":"79.15"},{"asset_id":"8761897749749422724209054078244794145777693856614463256546737399611489089783","best_ask":"0.38","best_bid":"0.37","hash":"ea67040439e7cc4609139d51f58b2008d891395d","price":"0.43","side":"SELL","size":"79.15"}],"timestamp":"1785207829165"},"payload_hash":"9ac03ce199742a625e54b9e5ab2dd9a4f818e4283eb7458eb1bcc4268a3f0996","raw_frame":"{\"market\":\"0x779291bef19b6709f61e9764a954aafe9ffae488d50ae674aabdcb4f248006d5\", \"price_changes\":[{\"asset_id\":\"14965588658799411272385430903075831224615961675357217884735713260981483529984\", \"price\":\"0.57\", \"size\":\"79.15\", \"side\":\"BUY\", \"hash\":\"2d41222a8b6b5edbf12f61072c1345db12d96ff6\", \"best_bid\":\"0.62\", \"best_ask\":\"0.63\"}, {\"asset_id\":\"8761897749749422724209054078244794145777693856614463256546737399611489089783\", \"price\":\"0.43\", \"size\":\"79.15\", \"side\":\"SELL\", \"hash\":\"ea67040439e7cc4609139d51f58b2008d891395d\", \"best_bid\":\"0.37\", \"best_ask\":\"0.38\"}], \"timestamp\":\"1785207829165\", \"event_type\":\"price_change\"}","received_at":"2026-07-28T03:03:49.016634Z","schema_version":"clob-market-ws.price_change.v1","sequence":null,"server_hash":null,"server_timestamp":"1785207829165","session_id":"3e519d9098404c15b234d96025eb1a2b","source":"clob_market_ws"},"received_at":"2026-07-28T03:03:49.016634Z","record_id":"d0cea3a7998f60781abed0d7d9caaea9eb5e8b4bd376e0548ebe8fbb2fe9a226","schema_fingerprint":"4aa3821a28b0b7c2400bc59aba4bcc0a76e971dadd19610d3ad38c768e124dc7","schema_version":"edge-lab-recorder.raw.v1","sequence":null,"source":"clob_market_ws"}
{"event_at":"2026-07-28T03:03:49.192000Z","event_fingerprint":"8b594095bdc9c29e8a874d9cafb7157dc2aff2d0c0eb024c39dfc8f560ce3e07","payload":{"connection_id":"a6b55582af5f430fb37ad02bf0922475","event_at":"2026-07-28T03:03:49.192000Z","event_type":"price_change","frame_hash":"b109f2d28cd2e9058d7551e6ee0747348d2e97baedfad147c11e00c45e18388a","frame_index":0,"kind":"data","monotonic_ns":309812061740541,"payload":{"event_type":"price_change","market":"0x779291bef19b6709f61e9764a954aafe9ffae488d50ae674aabdcb4f248006d5","price_changes":[{"asset_id":"14965588658799411272385430903075831224615961675357217884735713260981483529984","best_ask":"0.63","best_bid":"0.62","hash":"c0962744b641eb232ff111b1af09a6736cc4ab70","price":"0.03","side":"BUY","size":"638.1"},{"asset_id":"8761897749749422724209054078244794145777693856614463256546737399611489089783","best_ask":"0.38","best_bid":"0.37","hash":"240251b369d24b36804ea6ce2435f069e7cfeb36","price":"0.97","side":"SELL","size":"638.1"}],"timestamp":"1785207829192"},"payload_hash":"debcbcc5dee6f2d1417cc2ea3a6102733532b7e4ec2d681f57252fd4fc880368","raw_frame":"{\"market\":\"0x779291bef19b6709f61e9764a954aafe9ffae488d50ae674aabdcb4f248006d5\", \"price_changes\":[{\"asset_id\":\"14965588658799411272385430903075831224615961675357217884735713260981483529984\", \"price\":\"0.03\", \"size\":\"638.1\", \"side\":\"BUY\", \"hash\":\"c0962744b641eb232ff111b1af09a6736cc4ab70\", \"best_bid\":\"0.62\", \"best_ask\":\"0.63\"}, {\"asset_id\":\"8761897749749422724209054078244794145777693856614463256546737399611489089783\", \"price\":\"0.97\", \"size\":\"638.1\", \"side\":\"SELL\", \"hash\":\"240251b369d24b36804ea6ce2435f069e7cfeb36\", \"best_bid\":\"0.37\", \"best_ask\":\"0.38\"}], \"timestamp\":\"1785207829192\", \"event_type\":\"price_change\"}","received_at":"2026-07-28T03:03:49.041720Z","schema_version":"clob-market-ws.price_change.v1","sequence":null,"server_hash":null,"server_timestamp":"1785207829192","session_id":"3e519d9098404c15b234d96025eb1a2b","source":"clob_market_ws"},"received_at":"2026-07-28T03:03:49.041720Z","record_id":"83bf9233fe24b5dd7d97981aa065c69749751d72be9c0d154a49c6870b499768","schema_fingerprint":"4aa3821a28b0b7c2400bc59aba4bcc0a76e971dadd19610d3ad38c768e124dc7","schema_version":"edge-lab-recorder.raw.v1","sequence":null,"source":"clob_market_ws"}
{"event_at":"2026-07-28T03:03:49.193000Z","event_fingerprint":"d9ba0c1a5786900b07eb68064285dc9211a0f2ce392583e7bf068e25d8a9bd1b","payload":{"connection_id":"a6b55582af5f430fb37ad02bf0922475","event_at":"2026-07-28T03:03:49.193000Z","event_type":"price_change","frame_hash":"82ef6360ff70c3fe9709650cd2bf6dec24fe4476733c43a33128140c8d0a825e","frame_index":0,"kind":"data","monotonic_ns":309812064109250,"payload":{"event_type":"price_change","market":"0x779291bef19b6709f61e9764a954aafe9ffae488d50ae674aabdcb4f248006d5","price_changes":[{"asset_id":"14965588658799411272385430903075831224615961675357217884735713260981483529984","best_ask":"0.63","best_bid":"0.62","hash":"c7f926ac24dfb892c2b81140a4c5c5cef5b45be5","price":"0.58","side":"BUY","size":"90.85"},{"asset_id":"8761897749749422724209054078244794145777693856614463256546737399611489089783","best_ask":"0.38","best_bid":"0.37","hash":"2fe187696c9765a64108ba534e9fcfad2d0be9a0","price":"0.42","side":"SELL","size":"90.85"}],"timestamp":"1785207829193"},"payload_hash":"e62c7ab64fe7620d56853ea7effa9c25e8a45dd936d21aa232cce57606840090","raw_frame":"{\"market\":\"0x779291bef19b6709f61e9764a954aafe9ffae488d50ae674aabdcb4f248006d5\", \"price_changes\":[{\"asset_id\":\"14965588658799411272385430903075831224615961675357217884735713260981483529984\", \"price\":\"0.58\", \"size\":\"90.85\", \"side\":\"BUY\", \"hash\":\"c7f926ac24dfb892c2b81140a4c5c5cef5b45be5\", \"best_bid\":\"0.62\", \"best_ask\":\"0.63\"}, {\"asset_id\":\"8761897749749422724209054078244794145777693856614463256546737399611489089783\", \"price\":\"0.42\", \"size\":\"90.85\", \"side\":\"SELL\", \"hash\":\"2fe187696c9765a64108ba534e9fcfad2d0be9a0\", \"best_bid\":\"0.37\", \"best_ask\":\"0.38\"}], \"timestamp\":\"1785207829193\", \"event_type\":\"price_change\"}","received_at":"2026-07-28T03:03:49.044087Z","schema_version":"clob-market-ws.price_change.v1","sequence":null,"server_hash":null,"server_timestamp":"1785207829193","session_id":"3e519d9098404c15b234d96025eb1a2b","source":"clob_market_ws"},"received_at":"2026-07-28T03:03:49.044087Z","record_id":"72ad4f3adac5c717dd241a6348a309d4c87f767a620dceed3b64828a84ec7a9d","schema_fingerprint":"4aa3821a28b0b7c2400bc59aba4bcc0a76e971dadd19610d3ad38c768e124dc7","schema_version":"edge-lab-recorder.raw.v1","sequence":null,"source":"clob_market_ws"}
{"event_at":"2026-07-28T03:03:49.297000Z","event_fingerprint":"9219ffe2cba93577c9ed202c015007340376f4471c987faad8732e008aacc72d","payload":{"connection_id":"a6b55582af5f430fb37ad02bf0922475","event_at":"2026-07-28T03:03:49.297000Z","event_type":"price_change","frame_hash":"4d02531f40b54dd486e3b310bb4c1d22e07241235edce1c25fea759b0354b4a7","frame_index":0,"kind":"data","monotonic_ns":309812168762083,"payload":{"event_type":"price_change","market":"0x779291bef19b6709f61e9764a954aafe9ffae488d50ae674aabdcb4f248006d5","price_changes":[{"asset_id":"14965588658799411272385430903075831224615961675357217884735713260981483529984","best_ask":"0.63","best_bid":"0.62","hash":"26232e65239b3563c0ffd48ff8ab64e5d5b61a0d","price":"0.03","side":"BUY","size":"633.1"},{"asset_id":"8761897749749422724209054078244794145777693856614463256546737399611489089783","best_ask":"0.38","best_bid":"0.37","hash":"41dcb2ad0dbd4477c6259620de2c935e7e57881c","price":"0.97","side":"SELL","size":"633.1"}],"timestamp":"1785207829297"},"payload_hash":"774d45234cc93ce77f4b7bc63dfc57cacfb57f76f653bed9f347d6e46e5d7aa2","raw_frame":"{\"market\":\"0x779291bef19b6709f61e9764a954aafe9ffae488d50ae674aabdcb4f248006d5\", \"price_changes\":[{\"asset_id\":\"14965588658799411272385430903075831224615961675357217884735713260981483529984\", \"price\":\"0.03\", \"size\":\"633.1\", \"side\":\"BUY\", \"hash\":\"26232e65239b3563c0ffd48ff8ab64e5d5b61a0d\", \"best_bid\":\"0.62\", \"best_ask\":\"0.63\"}, {\"asset_id\":\"8761897749749422724209054078244794145777693856614463256546737399611489089783\", \"price\":\"0.97\", \"size\":\"633.1\", \"side\":\"SELL\", \"hash\":\"41dcb2ad0dbd4477c6259620de2c935e7e57881c\", \"best_bid\":\"0.37\", \"best_ask\":\"0.38\"}], \"timestamp\":\"1785207829297\", \"event_type\":\"price_change\"}","received_at":"2026-07-28T03:03:49.148739Z","schema_version":"clob-market-ws.price_change.v1","sequence":null,"server_hash":null,"server_timestamp":"1785207829297","session_id":"3e519d9098404c15b234d96025eb1a2b","source":"clob_market_ws"},"received_at":"2026-07-28T03:03:49.148739Z","record_id":"ac303e5101c29f4519bd40b6e58b41a2a2659c55cbbacb4c14f4342ebcf0c471","schema_fingerprint":"4aa3821a28b0b7c2400bc59aba4bcc0a76e971dadd19610d3ad38c768e124dc7","schema_version":"edge-lab-recorder.raw.v1","sequence":null,"source":"clob_market_ws"}
