{"event_at":null,"event_fingerprint":"33ce4d9ece294aa18e7dc48e7ab1e90b787651df3cd63103a99fa3f1172d020d","payload":{"connection_id":"a6b55582af5f430fb37ad02bf0922475","detail":{"interval_seconds":10.0,"message":"PING"},"event_type":"heartbeat","kind":"lifecycle","monotonic_ns":309293912862291,"received_at":"2026-07-28T02:55:10.896584Z","schema_version":"edge-lab-recorder.lifecycle.v1","session_id":"3e519d9098404c15b234d96025eb1a2b","source":"clob_market_ws"},"received_at":"2026-07-28T02:55:10.896584Z","record_id":"87c81eba2aa43d69a82b41d18f694f3c068f51fdec30d6668a29fa23d941a0e2","schema_fingerprint":"cb8aa3aa4cb168a4b724fd9077bee6ecfb9bc586c57cfdf0ab89f00d82045e3c","schema_version":"edge-lab-recorder.raw.v1","sequence":null,"source":"clob_market_ws"}
{"event_at":null,"event_fingerprint":"68716b48adf419ea9930aeda6eb83f244232596d9e3d736d4a455a347c52351f","payload":{"connection_id":"a6b55582af5f430fb37ad02bf0922475","event_type":"heartbeat_ack","frame_hash":"95784973cc639977bff93619700168505cb8f7855e44fa643d34622a43706c87","kind":"lifecycle","monotonic_ns":309294122176166,"raw_frame":"PONG","received_at":"2026-07-28T02:55:11.105897Z","schema_version":"edge-lab-recorder.heartbeat-ack.v1","session_id":"3e519d9098404c15b234d96025eb1a2b","source":"clob_market_ws"},"received_at":"2026-07-28T02:55:11.105897Z","record_id":"74b0230ba236170479e7b03bd87b6066abc4860a8aee01ea70c55f06868f8ada","schema_fingerprint":"c14ee1aab3ca674ee738e5268877b544d74c41ad3c427cedc09236467dc68ba1","schema_version":"edge-lab-recorder.raw.v1","sequence":null,"source":"clob_market_ws"}
{"event_at":"2026-07-28T02:55:15.255000Z","event_fingerprint":"b6d390892673228bd3a7a9abe8e4241373c82adfbffbe5fa001eb8df0739843b","payload":{"connection_id":"a6b55582af5f430fb37ad02bf0922475","event_at":"2026-07-28T02:55:15.255000Z","event_type":"price_change","frame_hash":"e111ff00caedf7451d2cbf91d8ae710058e40e86b9d88f0fbe0054698de70202","frame_index":0,"kind":"data","monotonic_ns":309299937313791,"payload":{"event_type":"price_change","market":"0x779291bef19b6709f61e9764a954aafe9ffae488d50ae674aabdcb4f248006d5","price_changes":[{"asset_id":"8761897749749422724209054078244794145777693856614463256546737399611489089783","best_ask":"0.5","best_bid":"0.48","hash":"c46a937df2b214b369f411c56190672b909fbe65","price":"0.47","side":"BUY","size":"224.67"},{"asset_id":"14965588658799411272385430903075831224615961675357217884735713260981483529984","best_ask":"0.52","best_bid":"0.5","hash":"19c8e906efab6fb50dd4a0cce0bd48e9602ad647","price":"0.53","side":"SELL","size":"224.67"}],"timestamp":"1785207315255"},"payload_hash":"09061c8cb845747700fbc94530e275e4fe2a5c9a61ee2da602dd558bef092f92","raw_frame":"{\"market\":\"0x779291bef19b6709f61e9764a954aafe9ffae488d50ae674aabdcb4f248006d5\", \"price_changes\":[{\"asset_id\":\"8761897749749422724209054078244794145777693856614463256546737399611489089783\", \"price\":\"0.47\", \"size\":\"224.67\", \"side\":\"BUY\", \"hash\":\"c46a937df2b214b369f411c56190672b909fbe65\", \"best_bid\":\"0.48\", \"best_ask\":\"0.5\"}, {\"asset_id\":\"14965588658799411272385430903075831224615961675357217884735713260981483529984\", \"price\":\"0.53\", \"size\":\"224.67\", \"side\":\"SELL\", \"hash\":\"19c8e906efab6fb50dd4a0cce0bd48e9602ad647\", \"best_bid\":\"0.5\", \"best_ask\":\"0.52\"}], \"timestamp\":\"1785207315255\", \"event_type\":\"price_change\"}","received_at":"2026-07-28T02:55:16.920994Z","schema_version":"clob-market-ws.price_change.v1","sequence":null,"server_hash":null,"server_timestamp":"1785207315255","session_id":"3e519d9098404c15b234d96025eb1a2b","source":"clob_market_ws"},"received_at":"2026-07-28T02:55:16.920994Z","record_id":"3c2fa983986ba94ab2bcb2ea589ad29d6c2fcfb285835588147d0a761c10120e","schema_fingerprint":"4aa3821a28b0b7c2400bc59aba4bcc0a76e971dadd19610d3ad38c768e124dc7","schema_version":"edge-lab-recorder.raw.v1","sequence":null,"source":"clob_market_ws"}
{"event_at":"2026-07-28T02:55:15.255000Z","event_fingerprint":"a84af53acb26df84c01de3676ca3c4f38c4f4440533127853b249daef1eab7e7","payload":{"connection_id":"a6b55582af5f430fb37ad02bf0922475","event_at":"2026-07-28T02:55:15.255000Z","event_type":"price_change","frame_hash":"a271da4c8198de0693fd9166bf4dbb9add9185bdafb76c5c4973bc36863feb0e","frame_index":0,"kind":"data","monotonic_ns":309299945099250,"payload":{"event_type":"price_change","market":"0x779291bef19b6709f61e9764a954aafe9ffae488d50ae674aabdcb4f248006d5","price_changes":[{"asset_id":"8761897749749422724209054078244794145777693856614463256546737399611489089783","best_ask":"0.5","best_bid":"0.48","hash":"c46a937df2b214b369f411c56190672b909fbe65","price":"0.46","side":"BUY","size":"245"},{"asset_id":"14965588658799411272385430903075831224615961675357217884735713260981483529984","best_ask":"0.52","best_bid":"0.5","hash":"19c8e906efab6fb50dd4a0cce0bd48e9602ad647","price":"0.54","side":"SELL","size":"245"}],"timestamp":"1785207315255"},"payload_hash":"b06d663cc922495be1495da037c6602ea5201db48ab77861f07642ac3f435605","raw_frame":"{\"market\":\"0x779291bef19b6709f61e9764a954aafe9ffae488d50ae674aabdcb4f248006d5\", \"price_changes\":[{\"asset_id\":\"8761897749749422724209054078244794145777693856614463256546737399611489089783\", \"price\":\"0.46\", \"size\":\"245\", \"side\":\"BUY\", \"hash\":\"c46a937df2b214b369f411c56190672b909fbe65\", \"best_bid\":\"0.48\", \"best_ask\":\"0.5\"}, {\"asset_id\":\"14965588658799411272385430903075831224615961675357217884735713260981483529984\", \"price\":\"0.54\", \"size\":\"245\", \"side\":\"SELL\", \"hash\":\"19c8e906efab6fb50dd4a0cce0bd48e9602ad647\", \"best_bid\":\"0.5\", \"best_ask\":\"0.52\"}], \"timestamp\":\"1785207315255\", \"event_type\":\"price_change\"}","received_at":"2026-07-28T02:55:16.928779Z","schema_version":"clob-market-ws.price_change.v1","sequence":null,"server_hash":null,"server_timestamp":"1785207315255","session_id":"3e519d9098404c15b234d96025eb1a2b","source":"clob_market_ws"},"received_at":"2026-07-28T02:55:16.928779Z","record_id":"a8b6e223b04a9d743f518578e8a56cb05d3afcd0a01a78c7a0dedfa292bc14b2","schema_fingerprint":"4aa3821a28b0b7c2400bc59aba4bcc0a76e971dadd19610d3ad38c768e124dc7","schema_version":"edge-lab-recorder.raw.v1","sequence":null,"source":"clob_market_ws"}
{"event_at":"2026-07-28T02:55:15.255000Z","event_fingerprint":"c328d24e9716e04cfb157540a24e898d849ae297c02c00cb455da6f0826dc577","payload":{"connection_id":"a6b55582af5f430fb37ad02bf0922475","event_at":"2026-07-28T02:55:15.255000Z","event_type":"price_change","frame_hash":"64db90704a030b2d0f4d84e280aa0cbee2ae1983cf9a7d1083705a505527815e","frame_index":0,"kind":"data","monotonic_ns":309299953575875,"payload":{"event_type":"price_change","market":"0x779291bef19b6709f61e9764a954aafe9ffae488d50ae674aabdcb4f248006d5","price_changes":[{"asset_id":"14965588658799411272385430903075831224615961675357217884735713260981483529984","best_ask":"0.52","best_bid":"0.5","hash":"19c8e906efab6fb50dd4a0cce0bd48e9602ad647","price":"0.48","side":"BUY","size":"275"},{"asset_id":"8761897749749422724209054078244794145777693856614463256546737399611489089783","best_ask":"0.5","best_bid":"0.48","hash":"c46a937df2b214b369f411c56190672b909fbe65","price":"0.52","side":"SELL","size":"275"}],"timestamp":"1785207315255"},"payload_hash":"4792ceb2dc0f840b29fd72ee80c2ead5a25b25edb36001912fb7dd774b175cb6","raw_frame":"{\"market\":\"0x779291bef19b6709f61e9764a954aafe9ffae488d50ae674aabdcb4f248006d5\", \"price_changes\":[{\"asset_id\":\"14965588658799411272385430903075831224615961675357217884735713260981483529984\", \"price\":\"0.48\", \"size\":\"275\", \"side\":\"BUY\", \"hash\":\"19c8e906efab6fb50dd4a0cce0bd48e9602ad647\", \"best_bid\":\"0.5\", \"best_ask\":\"0.52\"}, {\"asset_id\":\"8761897749749422724209054078244794145777693856614463256546737399611489089783\", \"price\":\"0.52\", \"size\":\"275\", \"side\":\"SELL\", \"hash\":\"c46a937df2b214b369f411c56190672b909fbe65\", \"best_bid\":\"0.48\", \"best_ask\":\"0.5\"}], \"timestamp\":\"1785207315255\", \"event_type\":\"price_change\"}","received_at":"2026-07-28T02:55:16.937255Z","schema_version":"clob-market-ws.price_change.v1","sequence":null,"server_hash":null,"server_timestamp":"1785207315255","session_id":"3e519d9098404c15b234d96025eb1a2b","source":"clob_market_ws"},"received_at":"2026-07-28T02:55:16.937255Z","record_id":"c67bef22855a34861ea906d48cfe8b4ecbd9cbce9593e254ead8a77aaac753fe","schema_fingerprint":"4aa3821a28b0b7c2400bc59aba4bcc0a76e971dadd19610d3ad38c768e124dc7","schema_version":"edge-lab-recorder.raw.v1","sequence":null,"source":"clob_market_ws"}
{"event_at":"2026-07-28T02:55:15.255000Z","event_fingerprint":"7df3405a32b1687963e27d68904361bcb9017845fe4b964d4fdd4fbf4c319fe3","payload":{"connection_id":"a6b55582af5f430fb37ad02bf0922475","event_at":"2026-07-28T02:55:15.255000Z","event_type":"price_change","frame_hash":"65e328de346ea0ed4e1e7d70b7f0ea02b187d40f49f0b8abf820b3bcdf918ffb","frame_index":0,"kind":"data","monotonic_ns":309299963758416,"payload":{"event_type":"price_change","market":"0x779291bef19b6709f61e9764a954aafe9ffae488d50ae674aabdcb4f248006d5","price_changes":[{"asset_id":"14965588658799411272385430903075831224615961675357217884735713260981483529984","best_ask":"0.52","best_bid":"0.5","hash":"19c8e906efab6fb50dd4a0cce0bd48e9602ad647","price":"0.49","side":"BUY","size":"265"},{"asset_id":"8761897749749422724209054078244794145777693856614463256546737399611489089783","best_ask":"0.5","best_bid":"0.48","hash":"c46a937df2b214b369f411c56190672b909fbe65","price":"0.51","side":"SELL","size":"265"}],"timestamp":"1785207315255"},"payload_hash":"b9d4dcbe48f47a5cbad78664a66b4fc82c68dfbf20937167ae8a7338096293f8","raw_frame":"{\"market\":\"0x779291bef19b6709f61e9764a954aafe9ffae488d50ae674aabdcb4f248006d5\", \"price_changes\":[{\"asset_id\":\"14965588658799411272385430903075831224615961675357217884735713260981483529984\", \"price\":\"0.49\", \"size\":\"265\", \"side\":\"BUY\", \"hash\":\"19c8e906efab6fb50dd4a0cce0bd48e9602ad647\", \"best_bid\":\"0.5\", \"best_ask\":\"0.52\"}, {\"asset_id\":\"8761897749749422724209054078244794145777693856614463256546737399611489089783\", \"price\":\"0.51\", \"size\":\"265\", \"side\":\"SELL\", \"hash\":\"c46a937df2b214b369f411c56190672b909fbe65\", \"best_bid\":\"0.48\", \"best_ask\":\"0.5\"}], \"timestamp\":\"1785207315255\", \"event_type\":\"price_change\"}","received_at":"2026-07-28T02:55:16.947440Z","schema_version":"clob-market-ws.price_change.v1","sequence":null,"server_hash":null,"server_timestamp":"1785207315255","session_id":"3e519d9098404c15b234d96025eb1a2b","source":"clob_market_ws"},"received_at":"2026-07-28T02:55:16.947440Z","record_id":"b5a4e5a9d2eea1e65ee190a0de2483465e1224db4a3ef2f1b7f9932d24eb2640","schema_fingerprint":"4aa3821a28b0b7c2400bc59aba4bcc0a76e971dadd19610d3ad38c768e124dc7","schema_version":"edge-lab-recorder.raw.v1","sequence":null,"source":"clob_market_ws"}
{"event_at":"2026-07-28T02:55:15.703000Z","event_fingerprint":"928b2f7003d7adf6f56c8003d361790c762ed5c386c53e4ff5afda86b98ee93a","payload":{"connection_id":"a6b55582af5f430fb37ad02bf0922475","event_at":"2026-07-28T02:55:15.703000Z","event_type":"price_change","frame_hash":"1ee0b32d91181770b0f4f56b52220aa97c89ed09304e873bc1e102a8d58db348","frame_index":0,"kind":"data","monotonic_ns":309299968526708,"payload":{"event_type":"price_change","market":"0x779291bef19b6709f61e9764a954aafe9ffae488d50ae674aabdcb4f248006d5","price_changes":[{"asset_id":"14965588658799411272385430903075831224615961675357217884735713260981483529984","best_ask":"0.52","best_bid":"0.5","hash":"bcfbb0d3441d2b4d4a23f8d8c77d7e198f5a4ed1","price":"0.48","side":"BUY","size":"280"},{"asset_id":"8761897749749422724209054078244794145777693856614463256546737399611489089783","best_ask":"0.5","best_bid":"0.48","hash":"46149c56b331fad73e62e8b2a6771f9e54d44958","price":"0.52","side":"SELL","size":"280"}],"timestamp":"1785207315703"},"payload_hash":"c848ee8de485495d4e1753e33489699a97051e8dcc66d7186fe76508cce990d8","raw_frame":"{\"market\":\"0x779291bef19b6709f61e9764a954aafe9ffae488d50ae674aabdcb4f248006d5\", \"price_changes\":[{\"asset_id\":\"14965588658799411272385430903075831224615961675357217884735713260981483529984\", \"price\":\"0.48\", \"size\":\"280\", \"side\":\"BUY\", \"hash\":\"bcfbb0d3441d2b4d4a23f8d8c77d7e198f5a4ed1\", \"best_bid\":\"0.5\", \"best_ask\":\"0.52\"}, {\"asset_id\":\"8761897749749422724209054078244794145777693856614463256546737399611489089783\", \"price\":\"0.52\", \"size\":\"280\", \"side\":\"SELL\", \"hash\":\"46149c56b331fad73e62e8b2a6771f9e54d44958\", \"best_bid\":\"0.48\", \"best_ask\":\"0.5\"}], \"timestamp\":\"1785207315703\", \"event_type\":\"price_change\"}","received_at":"2026-07-28T02:55:16.952208Z","schema_version":"clob-market-ws.price_change.v1","sequence":null,"server_hash":null,"server_timestamp":"1785207315703","session_id":"3e519d9098404c15b234d96025eb1a2b","source":"clob_market_ws"},"received_at":"2026-07-28T02:55:16.952208Z","record_id":"eaa7885558e8641058ab7743988a2bc34515b9d2319bc59d4f183f04b6eb3bb2","schema_fingerprint":"4aa3821a28b0b7c2400bc59aba4bcc0a76e971dadd19610d3ad38c768e124dc7","schema_version":"edge-lab-recorder.raw.v1","sequence":null,"source":"clob_market_ws"}
{"event_at":"2026-07-28T02:55:15.704000Z","event_fingerprint":"c8057a11834bff13d091e9955cf1eecc596fbf811f51297cf3f0f675fff6a402","payload":{"connection_id":"a6b55582af5f430fb37ad02bf0922475","event_at":"2026-07-28T02:55:15.704000Z","event_type":"price_change","frame_hash":"5e61930faebded42a35f2a6af389100875da836bd8e0272a50a85681234a18dd","frame_index":0,"kind":"data","monotonic_ns":309299973744250,"payload":{"event_type":"price_change","market":"0x779291bef19b6709f61e9764a954aafe9ffae488d50ae674aabdcb4f248006d5","price_changes":[{"asset_id":"8761897749749422724209054078244794145777693856614463256546737399611489089783","best_ask":"0.5","best_bid":"0.48","hash":"49d13ec53c40c8bfe1d95f06b3dc7c29bfc513ac","price":"0.46","side":"BUY","size":"250"},{"asset_id":"14965588658799411272385430903075831224615961675357217884735713260981483529984","best_ask":"0.52","best_bid":"0.5","hash":"c06c4debc1bead3e2a48c957b0ac77579e0eec58","price":"0.54","side":"SELL","size":"250"}],"timestamp":"1785207315704"},"payload_hash":"c141e2a8ac9d4f7e36cc486cc9e6d3b3ec416fa85055327c078ced859f036298","raw_frame":"{\"market\":\"0x779291bef19b6709f61e9764a954aafe9ffae488d50ae674aabdcb4f248006d5\", \"price_changes\":[{\"asset_id\":\"8761897749749422724209054078244794145777693856614463256546737399611489089783\", \"price\":\"0.46\", \"size\":\"250\", \"side\":\"BUY\", \"hash\":\"49d13ec53c40c8bfe1d95f06b3dc7c29bfc513ac\", \"best_bid\":\"0.48\", \"best_ask\":\"0.5\"}, {\"asset_id\":\"14965588658799411272385430903075831224615961675357217884735713260981483529984\", \"price\":\"0.54\", \"size\":\"250\", \"side\":\"SELL\", \"hash\":\"c06c4debc1bead3e2a48c957b0ac77579e0eec58\", \"best_bid\":\"0.5\", \"best_ask\":\"0.52\"}], \"timestamp\":\"1785207315704\", \"event_type\":\"price_change\"}","received_at":"2026-07-28T02:55:16.957419Z","schema_version":"clob-market-ws.price_change.v1","sequence":null,"server_hash":null,"server_timestamp":"1785207315704","session_id":"3e519d9098404c15b234d96025eb1a2b","source":"clob_market_ws"},"received_at":"2026-07-28T02:55:16.957419Z","record_id":"e675baa5994f6912df7b1f781552f4127b15ad834c3be4d105abfe0c5d1c065f","schema_fingerprint":"4aa3821a28b0b7c2400bc59aba4bcc0a76e971dadd19610d3ad38c768e124dc7","schema_version":"edge-lab-recorder.raw.v1","sequence":null,"source":"clob_market_ws"}
{"event_at":"2026-07-28T02:55:15.705000Z","event_fingerprint":"40b743f579721f8fea52f50dfbe674489179798093e84fb6c8bc08965061d27b","payload":{"connection_id":"a6b55582af5f430fb37ad02bf0922475","event_at":"2026-07-28T02:55:15.705000Z","event_type":"price_change","frame_hash":"207e1750323ca8b4011532bcfebb09481b0321c07502467f60feac88573f67b4","frame_index":0,"kind":"data","monotonic_ns":309299979750125,"payload":{"event_type":"price_change","market":"0x779291bef19b6709f61e9764a954aafe9ffae488d50ae674aabdcb4f248006d5","price_changes":[{"asset_id":"14965588658799411272385430903075831224615961675357217884735713260981483529984","best_ask":"0.52","best_bid":"0.5","hash":"baac2755141eb25a60479c61e85329efcf7e7a6c","price":"0.48","side":"BUY","size":"285"},{"asset_id":"8761897749749422724209054078244794145777693856614463256546737399611489089783","best_ask":"0.5","best_bid":"0.48","hash":"ec3ee27fe7f9bcefbecf69f02e0aabee4a8671a5","price":"0.52","side":"SELL","size":"285"}],"timestamp":"1785207315705"},"payload_hash":"e63073141b57d9de39b5f357af3950c6c1a87f4617dbd2eb82bf9b0f3c948ed2","raw_frame":"{\"market\":\"0x779291bef19b6709f61e9764a954aafe9ffae488d50ae674aabdcb4f248006d5\", \"price_changes\":[{\"asset_id\":\"14965588658799411272385430903075831224615961675357217884735713260981483529984\", \"price\":\"0.48\", \"size\":\"285\", \"side\":\"BUY\", \"hash\":\"baac2755141eb25a60479c61e85329efcf7e7a6c\", \"best_bid\":\"0.5\", \"best_ask\":\"0.52\"}, {\"asset_id\":\"8761897749749422724209054078244794145777693856614463256546737399611489089783\", \"price\":\"0.52\", \"size\":\"285\", \"side\":\"SELL\", \"hash\":\"ec3ee27fe7f9bcefbecf69f02e0aabee4a8671a5\", \"best_bid\":\"0.48\", \"best_ask\":\"0.5\"}], \"timestamp\":\"1785207315705\", \"event_type\":\"price_change\"}","received_at":"2026-07-28T02:55:16.963428Z","schema_version":"clob-market-ws.price_change.v1","sequence":null,"server_hash":null,"server_timestamp":"1785207315705","session_id":"3e519d9098404c15b234d96025eb1a2b","source":"clob_market_ws"},"received_at":"2026-07-28T02:55:16.963428Z","record_id":"21d68d813d96ce4910d2fcafa8da79cffa074a30d538be13690f835ee38e4428","schema_fingerprint":"4aa3821a28b0b7c2400bc59aba4bcc0a76e971dadd19610d3ad38c768e124dc7","schema_version":"edge-lab-recorder.raw.v1","sequence":null,"source":"clob_market_ws"}
{"event_at":"2026-07-28T02:55:15.706000Z","event_fingerprint":"9e296b35ace5265220f879f6b21426f0e84d1f80ea1d76b6d75dd199c638286f","payload":{"connection_id":"a6b55582af5f430fb37ad02bf0922475","event_at":"2026-07-28T02:55:15.706000Z","event_type":"price_change","frame_hash":"02e6aeb34f5a1cdd8a55f5d3c5a3d853a732dd8b9f5b6cd6d565d8f383e19ad6","frame_index":0,"kind":"data","monotonic_ns":309299987659125,"payload":{"event_type":"price_change","market":"0x779291bef19b6709f61e9764a954aafe9ffae488d50ae674aabdcb4f248006d5","price_changes":[{"asset_id":"8761897749749422724209054078244794145777693856614463256546737399611489089783","best_ask":"0.5","best_bid":"0.48","hash":"f27e0a3a780a21a110f74d98a3b9764838fb09ba","price":"0.47","side":"BUY","size":"229.67"},{"asset_id":"14965588658799411272385430903075831224615961675357217884735713260981483529984","best_ask":"0.52","best_bid":"0.5","hash":"ceb6954709a3f676bdef1f37e88ab65688814dbb","price":"0.53","side":"SELL","size":"229.67"}],"timestamp":"1785207315706"},"payload_hash":"5ba7a52f70a1b197454b5687c8dfc40c39828f439cd34a0ba106d3976253e96c","raw_frame":"{\"market\":\"0x779291bef19b6709f61e9764a954aafe9ffae488d50ae674aabdcb4f248006d5\", \"price_changes\":[{\"asset_id\":\"8761897749749422724209054078244794145777693856614463256546737399611489089783\", \"price\":\"0.47\", \"size\":\"229.67\", \"side\":\"BUY\", \"hash\":\"f27e0a3a780a21a110f74d98a3b9764838fb09ba\", \"best_bid\":\"0.48\", \"best_ask\":\"0.5\"}, {\"asset_id\":\"14965588658799411272385430903075831224615961675357217884735713260981483529984\", \"price\":\"0.53\", \"size\":\"229.67\", \"side\":\"SELL\", \"hash\":\"ceb6954709a3f676bdef1f37e88ab65688814dbb\", \"best_bid\":\"0.5\", \"best_ask\":\"0.52\"}], \"timestamp\":\"1785207315706\", \"event_type\":\"price_change\"}","received_at":"2026-07-28T02:55:16.971339Z","schema_version":"clob-market-ws.price_change.v1","sequence":null,"server_hash":null,"server_timestamp":"1785207315706","session_id":"3e519d9098404c15b234d96025eb1a2b","source":"clob_market_ws"},"received_at":"2026-07-28T02:55:16.971339Z","record_id":"cd05227f886cabeca8de6f01e336653fc5cf0dcdd56d90b095d351fb90bb0859","schema_fingerprint":"4aa3821a28b0b7c2400bc59aba4bcc0a76e971dadd19610d3ad38c768e124dc7","schema_version":"edge-lab-recorder.raw.v1","sequence":null,"source":"clob_market_ws"}
{"event_at":"2026-07-28T02:55:15.707000Z","event_fingerprint":"8696aba8357a03921ee055f21ffc933216413efa697949b3404627a8bff22040","payload":{"connection_id":"a6b55582af5f430fb37ad02bf0922475","event_at":"2026-07-28T02:55:15.707000Z","event_type":"price_change","frame_hash":"b1d2fb6f94511af828a1dc8e9e4eff6b294c47c29cb986429d3e854180f3aaf4","frame_index":0,"kind":"data","monotonic_ns":309299993071000,"payload":{"event_type":"price_change","market":"0x779291bef19b6709f61e9764a954aafe9ffae488d50ae674aabdcb4f248006d5","price_changes":[{"asset_id":"8761897749749422724209054078244794145777693856614463256546737399611489089783","best_ask":"0.5","best_bid":"0.48","hash":"484df09b99679007ca24c37666b3e37bb3e562a3","price":"0.48","side":"BUY","size":"210"},{"asset_id":"14965588658799411272385430903075831224615961675357217884735713260981483529984","best_ask":"0.52","best_bid":"0.5","hash":"4a5b2828caa8389b20d7208944b7938f710f46fe","price":"0.52","side":"SELL","size":"210"}],"timestamp":"1785207315707"},"payload_hash":"2bcd4d92fef33971d5cb46162e0ae642553d673a9691d85274ef9e40cab33168","raw_frame":"{\"market\":\"0x779291bef19b6709f61e9764a954aafe9ffae488d50ae674aabdcb4f248006d5\", \"price_changes\":[{\"asset_id\":\"8761897749749422724209054078244794145777693856614463256546737399611489089783\", \"price\":\"0.48\", \"size\":\"210\", \"side\":\"BUY\", \"hash\":\"484df09b99679007ca24c37666b3e37bb3e562a3\", \"best_bid\":\"0.48\", \"best_ask\":\"0.5\"}, {\"asset_id\":\"14965588658799411272385430903075831224615961675357217884735713260981483529984\", \"price\":\"0.52\", \"size\":\"210\", \"side\":\"SELL\", \"hash\":\"4a5b2828caa8389b20d7208944b7938f710f46fe\", \"best_bid\":\"0.5\", \"best_ask\":\"0.52\"}], \"timestamp\":\"1785207315707\", \"event_type\":\"price_change\"}","received_at":"2026-07-28T02:55:16.976750Z","schema_version":"clob-market-ws.price_change.v1","sequence":null,"server_hash":null,"server_timestamp":"1785207315707","session_id":"3e519d9098404c15b234d96025eb1a2b","source":"clob_market_ws"},"received_at":"2026-07-28T02:55:16.976750Z","record_id":"5db90e2cff99dc726dbca87e683bbc0ea0961ce446a21ada9c4ad991d6129ddd","schema_fingerprint":"4aa3821a28b0b7c2400bc59aba4bcc0a76e971dadd19610d3ad38c768e124dc7","schema_version":"edge-lab-recorder.raw.v1","sequence":null,"source":"clob_market_ws"}
{"event_at":"2026-07-28T02:55:15.708000Z","event_fingerprint":"a16fa3ffd99c2aee79eea790210b2aa9fe9458c9953c0b721b3996091eaf6a70","payload":{"connection_id":"a6b55582af5f430fb37ad02bf0922475","event_at":"2026-07-28T02:55:15.708000Z","event_type":"price_change","frame_hash":"e3731920563d4b9669e5e9896186bcf7a0a59a180b165c358545423968bdf13f","frame_index":0,"kind":"data","monotonic_ns":309299999229208,"payload":{"event_type":"price_change","market":"0x779291bef19b6709f61e9764a954aafe9ffae488d50ae674aabdcb4f248006d5","price_changes":[{"asset_id":"14965588658799411272385430903075831224615961675357217884735713260981483529984","best_ask":"0.52","best_bid":"0.5","hash":"c0b70b14ad045af563692b53d411a636e9be215d","price":"0.49","side":"BUY","size":"270"},{"asset_id":"8761897749749422724209054078244794145777693856614463256546737399611489089783","best_ask":"0.5","best_bid":"0.48","hash":"a558c572491fe33b525074a299710e763348b791","price":"0.51","side":"SELL","size":"270"}],"timestamp":"1785207315708"},"payload_hash":"92174ef240c42a24dfa9130e5c1fd5c55f82a667621398592ccd5960c5a24b47","raw_frame":"{\"market\":\"0x779291bef19b6709f61e9764a954aafe9ffae488d50ae674aabdcb4f248006d5\", \"price_changes\":[{\"asset_id\":\"14965588658799411272385430903075831224615961675357217884735713260981483529984\", \"price\":\"0.49\", \"size\":\"270\", \"side\":\"BUY\", \"hash\":\"c0b70b14ad045af563692b53d411a636e9be215d\", \"best_bid\":\"0.5\", \"best_ask\":\"0.52\"}, {\"asset_id\":\"8761897749749422724209054078244794145777693856614463256546737399611489089783\", \"price\":\"0.51\", \"size\":\"270\", \"side\":\"SELL\", \"hash\":\"a558c572491fe33b525074a299710e763348b791\", \"best_bid\":\"0.48\", \"best_ask\":\"0.5\"}], \"timestamp\":\"1785207315708\", \"event_type\":\"price_change\"}","received_at":"2026-07-28T02:55:16.982910Z","schema_version":"clob-market-ws.price_change.v1","sequence":null,"server_hash":null,"server_timestamp":"1785207315708","session_id":"3e519d9098404c15b234d96025eb1a2b","source":"clob_market_ws"},"received_at":"2026-07-28T02:55:16.982910Z","record_id":"b06d227697ac69355943b71956369b4ca09ca0222b589d950e45477efd69b1b3","schema_fingerprint":"4aa3821a28b0b7c2400bc59aba4bcc0a76e971dadd19610d3ad38c768e124dc7","schema_version":"edge-lab-recorder.raw.v1","sequence":null,"source":"clob_market_ws"}
{"event_at":"2026-07-28T02:55:15.709000Z","event_fingerprint":"388f66fff2a6e872485a7f2bbbba88c8487fe0e0ad09825b3d96276d8e8f1e20","payload":{"connection_id":"a6b55582af5f430fb37ad02bf0922475","event_at":"2026-07-28T02:55:15.709000Z","event_type":"price_change","frame_hash":"f038af10ef82b57b5ae741c61ec90a45434c362df3ab751c36914c46223e7728","frame_index":0,"kind":"data","monotonic_ns":309300004919000,"payload":{"event_type":"price_change","market":"0x779291bef19b6709f61e9764a954aafe9ffae488d50ae674aabdcb4f248006d5","price_changes":[{"asset_id":"14965588658799411272385430903075831224615961675357217884735713260981483529984","best_ask":"0.52","best_bid":"0.5","hash":"3fb21c1c7e346c3bcadf9e24a381d6939f50d16e","price":"0.5","side":"BUY","size":"210"},{"asset_id":"8761897749749422724209054078244794145777693856614463256546737399611489089783","best_ask":"0.5","best_bid":"0.48","hash":"77ea9c24e2bdc1c9cfceb5f3096d1884c1a1cc15","price":"0.5","side":"SELL","size":"210"}],"timestamp":"1785207315709"},"payload_hash":"cc8f17dc93a3846208f5f8fd891656cb50c4b2122963b806ebfd273a97f6cab1","raw_frame":"{\"market\":\"0x779291bef19b6709f61e9764a954aafe9ffae488d50ae674aabdcb4f248006d5\", \"price_changes\":[{\"asset_id\":\"14965588658799411272385430903075831224615961675357217884735713260981483529984\", \"price\":\"0.5\", \"size\":\"210\", \"side\":\"BUY\", \"hash\":\"3fb21c1c7e346c3bcadf9e24a381d6939f50d16e\", \"best_bid\":\"0.5\", \"best_ask\":\"0.52\"}, {\"asset_id\":\"8761897749749422724209054078244794145777693856614463256546737399611489089783\", \"price\":\"0.5\", \"size\":\"210\", \"side\":\"SELL\", \"hash\":\"77ea9c24e2bdc1c9cfceb5f3096d1884c1a1cc15\", \"best_bid\":\"0.48\", \"best_ask\":\"0.5\"}], \"timestamp\":\"1785207315709\", \"event_type\":\"price_change\"}","received_at":"2026-07-28T02:55:16.988599Z","schema_version":"clob-market-ws.price_change.v1","sequence":null,"server_hash":null,"server_timestamp":"1785207315709","session_id":"3e519d9098404c15b234d96025eb1a2b","source":"clob_market_ws"},"received_at":"2026-07-28T02:55:16.988599Z","record_id":"e12faf3268e5a8b62ddbf074f6812f4fe194671d463dd70965abd2904f251e35","schema_fingerprint":"4aa3821a28b0b7c2400bc59aba4bcc0a76e971dadd19610d3ad38c768e124dc7","schema_version":"edge-lab-recorder.raw.v1","sequence":null,"source":"clob_market_ws"}
{"event_at":"2026-07-28T02:55:15.710000Z","event_fingerprint":"16e7f50bd524c0c8cee616a7159f07941f9074e935e30600ca1a4aa5bca7aacc","payload":{"connection_id":"a6b55582af5f430fb37ad02bf0922475","event_at":"2026-07-28T02:55:15.710000Z","event_type":"price_change","frame_hash":"7ab795d51a238d080e699f95da0c05d46f3541629144b735342de18a6af14163","frame_index":0,"kind":"data","monotonic_ns":309300010924833,"payload":{"event_type":"price_change","market":"0x779291bef19b6709f61e9764a954aafe9ffae488d50ae674aabdcb4f248006d5","price_changes":[{"asset_id":"8761897749749422724209054078244794145777693856614463256546737399611489089783","best_ask":"0.5","best_bid":"0.48","hash":"18720e5113c65ad4ec442b97d75d91e6a6584ef7","price":"0.46","side":"BUY","size":"255"},{"asset_id":"14965588658799411272385430903075831224615961675357217884735713260981483529984","best_ask":"0.52","best_bid":"0.5","hash":"89e4a448f222c198d11e5e3aca01d3aac2bee426","price":"0.54","side":"SELL","size":"255"}],"timestamp":"1785207315710"},"payload_hash":"cf8108a69787bb7f60bfea4056b63e1691aef5a00f6eaf98941de03304fdd4ce","raw_frame":"{\"market\":\"0x779291bef19b6709f61e9764a954aafe9ffae488d50ae674aabdcb4f248006d5\", \"price_changes\":[{\"asset_id\":\"8761897749749422724209054078244794145777693856614463256546737399611489089783\", \"price\":\"0.46\", \"size\":\"255\", \"side\":\"BUY\", \"hash\":\"18720e5113c65ad4ec442b97d75d91e6a6584ef7\", \"best_bid\":\"0.48\", \"best_ask\":\"0.5\"}, {\"asset_id\":\"14965588658799411272385430903075831224615961675357217884735713260981483529984\", \"price\":\"0.54\", \"size\":\"255\", \"side\":\"SELL\", \"hash\":\"89e4a448f222c198d11e5e3aca01d3aac2bee426\", \"best_bid\":\"0.5\", \"best_ask\":\"0.52\"}], \"timestamp\":\"1785207315710\", \"event_type\":\"price_change\"}","received_at":"2026-07-28T02:55:16.994604Z","schema_version":"clob-market-ws.price_change.v1","sequence":null,"server_hash":null,"server_timestamp":"1785207315710","session_id":"3e519d9098404c15b234d96025eb1a2b","source":"clob_market_ws"},"received_at":"2026-07-28T02:55:16.994604Z","record_id":"441618100e80b03b6b27de0940f9e65df8f8dcde59ac0f03f1063ec081a90944","schema_fingerprint":"4aa3821a28b0b7c2400bc59aba4bcc0a76e971dadd19610d3ad38c768e124dc7","schema_version":"edge-lab-recorder.raw.v1","sequence":null,"source":"clob_market_ws"}
{"event_at":"2026-07-28T02:55:17.100000Z","event_fingerprint":"1adac87614dd32dc7a0675b6efba70dc01b6d6aa2593fc728ae7c3e999eb830d","payload":{"connection_id":"a6b55582af5f430fb37ad02bf0922475","event_at":"2026-07-28T02:55:17.100000Z","event_type":"new_market","frame_hash":"7eb4e65d5021d249d57545e0a56762d52c251778cb40619f54c7d0bf85c51f25","frame_index":0,"kind":"data","monotonic_ns":309300241556041,"payload":{"active":true,"assets_ids":["30864167918427370384246922625043123718874675750904565377786716246018369015283","78901112789060652283344637205255503079079285010158052827515608846943732314768"],"clob_token_ids":["30864167918427370384246922625043123718874675750904565377786716246018369015283","78901112789060652283344637205255503079079285010158052827515608846943732314768"],"condition_id":"0x5bdcdd3eef662efd679ebd90a96c7841eefb25b64ac525d909baca6ac3e446be","description":"In the upcoming MLB game between the Boston Red Sox and Athletics, scheduled for July 27 at 9:40 PM ET:\n\nThis market will resolve to \"Over\" if the Boston Red Sox and Athletics combine to score 5 or more runs in this game.\n\nIf the combined total is less than 5, this market will resolve to \"Under\".\n\nIf the game is postponed, this market will remain open until the game has been completed. If the game is canceled entirely, with no make-up game, this market will resolve 50-50.\n\nTo know when a postponed game will be played, please check the home team's schedule on MLB.com for the listed team and look for the game described as a makeup game.\n\nThe primary resolution source for this market is the official final statistics of the event as recognized by the governing body or event organizers. However, if the governing body or event organizers have not published final match statistics within 24 hours after the event's conclusion, a consensus of credible reporting may be used instead.","event_message":{"description":"In the upcoming MLB game between the Boston Red Sox and Athletics, scheduled for July 27 at 9:40PM ET:\n\nThis market will resolve to \"Boston Red Sox\" if the Boston Red Sox win the game.\n\nThis market will resolve to \"Athletics\" if the Athletics win the game.\n\nIf the game is postponed, this market will remain open until the game has been completed. If the game is canceled entirely, with no make-up game, or ends in a tie, this market will resolve 50-50.\n\nThe primary resolution source for this market is the official final statistics of the event as recognized by the governing body or event organizers. However, if the governing body or event organizers have not published final match statistics within 24 hours after the event's conclusion, a consensus of credible reporting may be used instead.","id":"729211","slug":"mlb-bos-oak-2026-07-27","ticker":"mlb-bos-oak-2026-07-27","title":"Boston Red Sox vs. Athletics"},"event_type":"new_market","fee_schedule":{"exponent":"1","rate":"0.05","rebate_rate":"0.15","taker_only":true},"fees_enabled":true,"game_start_time":"2026-07-28 01:40:00+00","group_item_title":"O/U 4.5","id":"3144995","line":"4.5","market":"0x5bdcdd3eef662efd679ebd90a96c7841eefb25b64ac525d909baca6ac3e446be","order_price_min_tick_size":"0.01","outcomes":["Over","Under"],"question":"Boston Red Sox vs. Athletics: O/U 4.5","slug":"mlb-bos-oak-2026-07-27-total-4pt5","sports_market_type":"totals","tags":[],"taker_base_fee":"1000","timestamp":"1785207317100"},"payload_hash":"9595459dd096237e60333e9b174e695f14c23be3a28fb0897be3b8889b91dc53","raw_frame":"{\"id\":\"3144995\", \"question\":\"Boston Red Sox vs. Athletics: O/U 4.5\", \"market\":\"0x5bdcdd3eef662efd679ebd90a96c7841eefb25b64ac525d909baca6ac3e446be\", \"slug\":\"mlb-bos-oak-2026-07-27-total-4pt5\", \"description\":\"In the upcoming MLB game between the Boston Red Sox and Athletics, scheduled for July 27 at 9:40 PM ET:\\n\\nThis market will resolve to \\\"Over\\\" if the Boston Red Sox and Athletics combine to score 5 or more runs in this game.\\n\\nIf the combined total is less than 5, this market will resolve to \\\"Under\\\".\\n\\nIf the game is postponed, this market will remain open until the game has been completed. If the game is canceled entirely, with no make-up game, this market will resolve 50-50.\\n\\nTo know when a postponed game will be played, please check the home team's schedule on MLB.com for the listed team and look for the game described as a makeup game.\\n\\nThe primary resolution source for this market is the official final statistics of the event as recognized by the governing body or event organizers. However, if the governing body or event organizers have not published final match statistics within 24 hours after the event's conclusion, a consensus of credible reporting may be used instead.\", \"assets_ids\":[\"30864167918427370384246922625043123718874675750904565377786716246018369015283\", \"78901112789060652283344637205255503079079285010158052827515608846943732314768\"], \"outcomes\":[\"Over\", \"Under\"], \"event_message\":{\"id\":\"729211\", \"ticker\":\"mlb-bos-oak-2026-07-27\", \"slug\":\"mlb-bos-oak-2026-07-27\", \"title\":\"Boston Red Sox vs. Athletics\", \"description\":\"In the upcoming MLB game between the Boston Red Sox and Athletics, scheduled for July 27 at 9:40PM ET:\\n\\nThis market will resolve to \\\"Boston Red Sox\\\" if the Boston Red Sox win the game.\\n\\nThis market will resolve to \\\"Athletics\\\" if the Athletics win the game.\\n\\nIf the game is postponed, this market will remain open until the game has been completed. If the game is canceled entirely, with no make-up game, or ends in a tie, this market will resolve 50-50.\\n\\nThe primary resolution source for this market is the official final statistics of the event as recognized by the governing body or event organizers. However, if the governing body or event organizers have not published final match statistics within 24 hours after the event's conclusion, a consensus of credible reporting may be used instead.\"}, \"timestamp\":\"1785207317100\", \"event_type\":\"new_market\", \"tags\":[], \"condition_id\":\"0x5bdcdd3eef662efd679ebd90a96c7841eefb25b64ac525d909baca6ac3e446be\", \"active\":true, \"clob_token_ids\":[\"30864167918427370384246922625043123718874675750904565377786716246018369015283\", \"78901112789060652283344637205255503079079285010158052827515608846943732314768\"], \"sports_market_type\":\"totals\", \"line\":\"4.5\", \"game_start_time\":\"2026-07-28 01:40:00+00\", \"order_price_min_tick_size\":\"0.01\", \"group_item_title\":\"O/U 4.5\", \"taker_base_fee\":\"1000\", \"fees_enabled\":true, \"fee_schedule\":{\"exponent\":\"1\", \"rate\":\"0.05\", \"taker_only\":true, \"rebate_rate\":\"0.15\"}}","received_at":"2026-07-28T02:55:17.225232Z","schema_version":"clob-market-ws.new_market.v1","sequence":null,"server_hash":null,"server_timestamp":"1785207317100","session_id":"3e519d9098404c15b234d96025eb1a2b","source":"clob_market_ws"},"received_at":"2026-07-28T02:55:17.225232Z","record_id":"eb5eca976f168a5ca877a74bcab960521fb0096f0c2ffa9d85b34c0291fe55da","schema_fingerprint":"6639a822a7b79cfa4c3fc0044066e4f66ba8611f5bf361772bd6902a2319b82d","schema_version":"edge-lab-recorder.raw.v1","sequence":null,"source":"clob_market_ws"}
{"event_at":null,"event_fingerprint":"470c358466fb96f811ba3c885d461549937e6ce3eeee67bda17eb910c222738d","payload":{"connection_id":"a6b55582af5f430fb37ad02bf0922475","detail":{"interval_seconds":10.0,"message":"PING"},"event_type":"heartbeat","kind":"lifecycle","monotonic_ns":309303918130291,"received_at":"2026-07-28T02:55:20.901780Z","schema_version":"edge-lab-recorder.lifecycle.v1","session_id":"3e519d9098404c15b234d96025eb1a2b","source":"clob_market_ws"},"received_at":"2026-07-28T02:55:20.901780Z","record_id":"ebefad017d4992c06915c864d40be077799c487be9c7842299bb245514aea2e8","schema_fingerprint":"cb8aa3aa4cb168a4b724fd9077bee6ecfb9bc586c57cfdf0ab89f00d82045e3c","schema_version":"edge-lab-recorder.raw.v1","sequence":null,"source":"clob_market_ws"}
{"event_at":null,"event_fingerprint":"83db3985a9a071603d25e801b7795ec802429d77cc0f2235554b2bb61cf0c035","payload":{"connection_id":"a6b55582af5f430fb37ad02bf0922475","event_type":"heartbeat_ack","frame_hash":"95784973cc639977bff93619700168505cb8f7855e44fa643d34622a43706c87","kind":"lifecycle","monotonic_ns":309304125328833,"raw_frame":"PONG","received_at":"2026-07-28T02:55:21.108978Z","schema_version":"edge-lab-recorder.heartbeat-ack.v1","session_id":"3e519d9098404c15b234d96025eb1a2b","source":"clob_market_ws"},"received_at":"2026-07-28T02:55:21.108978Z","record_id":"470f3b7a561f0e24ff368d6cd5a53e8c67213bcc967ba71eb10dad2a85207a94","schema_fingerprint":"c14ee1aab3ca674ee738e5268877b544d74c41ad3c427cedc09236467dc68ba1","schema_version":"edge-lab-recorder.raw.v1","sequence":null,"source":"clob_market_ws"}
{"event_at":"2026-07-28T02:55:26.174000Z","event_fingerprint":"952b867da56ea7495d157b1f1da443d451f7ac3b6e0b29f6be7957bbe0b6ee80","payload":{"connection_id":"a6b55582af5f430fb37ad02bf0922475","event_at":"2026-07-28T02:55:26.174000Z","event_type":"price_change","frame_hash":"d8d2a8eff4ab9c94b180f1ff3dfaaf48162a692bb60d0dde76174b652edac7f6","frame_index":0,"kind":"data","monotonic_ns":309309052466000,"payload":{"event_type":"price_change","market":"0x779291bef19b6709f61e9764a954aafe9ffae488d50ae674aabdcb4f248006d5","price_changes":[{"asset_id":"14965588658799411272385430903075831224615961675357217884735713260981483529984","best_ask":"0.52","best_bid":"0.5","hash":"81942ca2cc7f3b9ea4da66d48b6dddaa40a2bc8c","price":"0.43","side":"BUY","size":"130"},{"asset_id":"8761897749749422724209054078244794145777693856614463256546737399611489089783","best_ask":"0.5","best_bid":"0.48","hash":"45d72ab0feea785f8add3721128bd99b91e0a417","price":"0.57","side":"SELL","size":"130"}],"timestamp":"1785207326174"},"payload_hash":"3b247953ed01f9169027825dad7479b6a222445524419cbf4bc9ec877c0ab00d","raw_frame":"{\"market\":\"0x779291bef19b6709f61e9764a954aafe9ffae488d50ae674aabdcb4f248006d5\", \"price_changes\":[{\"asset_id\":\"14965588658799411272385430903075831224615961675357217884735713260981483529984\", \"price\":\"0.43\", \"size\":\"130\", \"side\":\"BUY\", \"hash\":\"81942ca2cc7f3b9ea4da66d48b6dddaa40a2bc8c\", \"best_bid\":\"0.5\", \"best_ask\":\"0.52\"}, {\"asset_id\":\"8761897749749422724209054078244794145777693856614463256546737399611489089783\", \"price\":\"0.57\", \"size\":\"130\", \"side\":\"SELL\", \"hash\":\"45d72ab0feea785f8add3721128bd99b91e0a417\", \"best_bid\":\"0.48\", \"best_ask\":\"0.5\"}], \"timestamp\":\"1785207326174\", \"event_type\":\"price_change\"}","received_at":"2026-07-28T02:55:26.036079Z","schema_version":"clob-market-ws.price_change.v1","sequence":null,"server_hash":null,"server_timestamp":"1785207326174","session_id":"3e519d9098404c15b234d96025eb1a2b","source":"clob_market_ws"},"received_at":"2026-07-28T02:55:26.036079Z","record_id":"907bba1cbbfbb50e61952290d1979aacb4620a2515212e307aeb658267e14248","schema_fingerprint":"4aa3821a28b0b7c2400bc59aba4bcc0a76e971dadd19610d3ad38c768e124dc7","schema_version":"edge-lab-recorder.raw.v1","sequence":null,"source":"clob_market_ws"}
{"event_at":"2026-07-28T02:55:26.174000Z","event_fingerprint":"80e3f7ef361356dc7604f66157fcf09a8b99866185ab2b1bac59c5bb4136e47a","payload":{"connection_id":"a6b55582af5f430fb37ad02bf0922475","event_at":"2026-07-28T02:55:26.174000Z","event_type":"price_change","frame_hash":"1c6022859e8e8d4bfeaad6506dd163e6d0d62b4fe5a1bd563748ac696edd7f99","frame_index":0,"kind":"data","monotonic_ns":309309055438500,"payload":{"event_type":"price_change","market":"0x779291bef19b6709f61e9764a954aafe9ffae488d50ae674aabdcb4f248006d5","price_changes":[{"asset_id":"8761897749749422724209054078244794145777693856614463256546737399611489089783","best_ask":"0.5","best_bid":"0.48","hash":"45d72ab0feea785f8add3721128bd99b91e0a417","price":"0.45","side":"BUY","size":"15.33"},{"asset_id":"14965588658799411272385430903075831224615961675357217884735713260981483529984","best_ask":"0.52","best_bid":"0.5","hash":"81942ca2cc7f3b9ea4da66d48b6dddaa40a2bc8c","price":"0.55","side":"SELL","size":"15.33"}],"timestamp":"1785207326174"},"payload_hash":"712ca314a8e5dba633d35772676da492b13b1f7d426cb2730703ad361fbc4204","raw_frame":"{\"market\":\"0x779291bef19b6709f61e9764a954aafe9ffae488d50ae674aabdcb4f248006d5\", \"price_changes\":[{\"asset_id\":\"8761897749749422724209054078244794145777693856614463256546737399611489089783\", \"price\":\"0.45\", \"size\":\"15.33\", \"side\":\"BUY\", \"hash\":\"45d72ab0feea785f8add3721128bd99b91e0a417\", \"best_bid\":\"0.48\", \"best_ask\":\"0.5\"}, {\"asset_id\":\"14965588658799411272385430903075831224615961675357217884735713260981483529984\", \"price\":\"0.55\", \"size\":\"15.33\", \"side\":\"SELL\", \"hash\":\"81942ca2cc7f3b9ea4da66d48b6dddaa40a2bc8c\", \"best_bid\":\"0.5\", \"best_ask\":\"0.52\"}], \"timestamp\":\"1785207326174\", \"event_type\":\"price_change\"}","received_at":"2026-07-28T02:55:26.039053Z","schema_version":"clob-market-ws.price_change.v1","sequence":null,"server_hash":null,"server_timestamp":"1785207326174","session_id":"3e519d9098404c15b234d96025eb1a2b","source":"clob_market_ws"},"received_at":"2026-07-28T02:55:26.039053Z","record_id":"6104745b4ae467e8bd35054c282f59727c40429a80d985a222913303e6fd6134","schema_fingerprint":"4aa3821a28b0b7c2400bc59aba4bcc0a76e971dadd19610d3ad38c768e124dc7","schema_version":"edge-lab-recorder.raw.v1","sequence":null,"source":"clob_market_ws"}
{"event_at":"2026-07-28T02:55:26.217000Z","event_fingerprint":"218bc5b676099bbce7bc545e9a730bb20d815afb324555ad5cf448df11561cd0","payload":{"connection_id":"a6b55582af5f430fb37ad02bf0922475","event_at":"2026-07-28T02:55:26.217000Z","event_type":"price_change","frame_hash":"6de6e3157a310c3f1b2b7bdf50af6aa22c2394ce541f367ec0d419f20ee49b35","frame_index":0,"kind":"data","monotonic_ns":309309097442375,"payload":{"event_type":"price_change","market":"0x779291bef19b6709f61e9764a954aafe9ffae488d50ae674aabdcb4f248006d5","price_changes":[{"asset_id":"14965588658799411272385430903075831224615961675357217884735713260981483529984","best_ask":"0.52","best_bid":"0.5","hash":"5ca5b0c6dbd01aba91d9d6f89587198503787357","price":"0.48","side":"BUY","size":"335"},{"asset_id":"8761897749749422724209054078244794145777693856614463256546737399611489089783","best_ask":"0.5","best_bid":"0.48","hash":"13ae1bd2f1f395370c977b74b4d5fea380e59ba8","price":"0.52","side":"SELL","size":"335"}],"timestamp":"1785207326217"},"payload_hash":"e6b493b39b4f1e69e7c7acccee8427c13a6923ff45e6a718c937d5d4f396132e","raw_frame":"{\"market\":\"0x779291bef19b6709f61e9764a954aafe9ffae488d50ae674aabdcb4f248006d5\", \"price_changes\":[{\"asset_id\":\"14965588658799411272385430903075831224615961675357217884735713260981483529984\", \"price\":\"0.48\", \"size\":\"335\", \"side\":\"BUY\", \"hash\":\"5ca5b0c6dbd01aba91d9d6f89587198503787357\", \"best_bid\":\"0.5\", \"best_ask\":\"0.52\"}, {\"asset_id\":\"8761897749749422724209054078244794145777693856614463256546737399611489089783\", \"price\":\"0.52\", \"size\":\"335\", \"side\":\"SELL\", \"hash\":\"13ae1bd2f1f395370c977b74b4d5fea380e59ba8\", \"best_bid\":\"0.48\", \"best_ask\":\"0.5\"}], \"timestamp\":\"1785207326217\", \"event_type\":\"price_change\"}","received_at":"2026-07-28T02:55:26.081056Z","schema_version":"clob-market-ws.price_change.v1","sequence":null,"server_hash":null,"server_timestamp":"1785207326217","session_id":"3e519d9098404c15b234d96025eb1a2b","source":"clob_market_ws"},"received_at":"2026-07-28T02:55:26.081056Z","record_id":"16802c5dfb554374d7088c92da732ee521f34c705a213bbc9503d05122241a7c","schema_fingerprint":"4aa3821a28b0b7c2400bc59aba4bcc0a76e971dadd19610d3ad38c768e124dc7","schema_version":"edge-lab-recorder.raw.v1","sequence":null,"source":"clob_market_ws"}
{"event_at":"2026-07-28T02:55:26.218000Z","event_fingerprint":"59e0b182e24bdce75453af66feab321b06fd76575e6beb143955ccb702c0b106","payload":{"connection_id":"a6b55582af5f430fb37ad02bf0922475","event_at":"2026-07-28T02:55:26.218000Z","event_type":"price_change","frame_hash":"b260e9d0035c5ece7cabcfde3d72c54b4bb05fd8949309c320394a42f1481727","frame_index":0,"kind":"data","monotonic_ns":309309103744166,"payload":{"event_type":"price_change","market":"0x779291bef19b6709f61e9764a954aafe9ffae488d50ae674aabdcb4f248006d5","price_changes":[{"asset_id":"8761897749749422724209054078244794145777693856614463256546737399611489089783","best_ask":"0.5","best_bid":"0.48","hash":"53fe53dc93fc973fa18d3ffe71dd01f1e89465bc","price":"0.38","side":"BUY","size":"209"},{"asset_id":"14965588658799411272385430903075831224615961675357217884735713260981483529984","best_ask":"0.52","best_bid":"0.5","hash":"409e2df1ac50526a27b7e4454b2a560d19e92688","price":"0.62","side":"SELL","size":"209"}],"timestamp":"1785207326218"},"payload_hash":"a8268511b9a6d80e71163a2b8a4702ab99cb1c7207f04d69d80a2548c99528d7","raw_frame":"{\"market\":\"0x779291bef19b6709f61e9764a954aafe9ffae488d50ae674aabdcb4f248006d5\", \"price_changes\":[{\"asset_id\":\"8761897749749422724209054078244794145777693856614463256546737399611489089783\", \"price\":\"0.38\", \"size\":\"209\", \"side\":\"BUY\", \"hash\":\"53fe53dc93fc973fa18d3ffe71dd01f1e89465bc\", \"best_bid\":\"0.48\", \"best_ask\":\"0.5\"}, {\"asset_id\":\"14965588658799411272385430903075831224615961675357217884735713260981483529984\", \"price\":\"0.62\", \"size\":\"209\", \"side\":\"SELL\", \"hash\":\"409e2df1ac50526a27b7e4454b2a560d19e92688\", \"best_bid\":\"0.5\", \"best_ask\":\"0.52\"}], \"timestamp\":\"1785207326218\", \"event_type\":\"price_change\"}","received_at":"2026-07-28T02:55:26.087359Z","schema_version":"clob-market-ws.price_change.v1","sequence":null,"server_hash":null,"server_timestamp":"1785207326218","session_id":"3e519d9098404c15b234d96025eb1a2b","source":"clob_market_ws"},"received_at":"2026-07-28T02:55:26.087359Z","record_id":"29daf2217a6b1fd770c4e0fe3712fab409f65fd99c0f89ffb476d27ebb73b558","schema_fingerprint":"4aa3821a28b0b7c2400bc59aba4bcc0a76e971dadd19610d3ad38c768e124dc7","schema_version":"edge-lab-recorder.raw.v1","sequence":null,"source":"clob_market_ws"}
{"event_at":"2026-07-28T02:55:26.219000Z","event_fingerprint":"c21f6740e2c645bccb14a371990e9d2fc5c764f202ded5e4d7e57ade9a1930ff","payload":{"connection_id":"a6b55582af5f430fb37ad02bf0922475","event_at":"2026-07-28T02:55:26.219000Z","event_type":"price_change","frame_hash":"668354d0a791b085aeb475e8ffee6e726e0bfbb6bee78e0acdbdb56a7b8d3a29","frame_index":0,"kind":"data","monotonic_ns":309309108989500,"payload":{"event_type":"price_change","market":"0x779291bef19b6709f61e9764a954aafe9ffae488d50ae674aabdcb4f248006d5","price_changes":[{"asset_id":"14965588658799411272385430903075831224615961675357217884735713260981483529984","best_ask":"0.52","best_bid":"0.5","hash":"775e73ed4612d61ef4284afcbd50acd457f18859","price":"0.5","side":"BUY","size":"260"},{"asset_id":"8761897749749422724209054078244794145777693856614463256546737399611489089783","best_ask":"0.5","best_bid":"0.48","hash":"84d787e8741ed9f61c8e92f48ac1ed0508da2396","price":"0.5","side":"SELL","size":"260"}],"timestamp":"1785207326219"},"payload_hash":"88c8070c581a53a1e9e9f9625a65414f30f09278f5e3b869e6f2775a26c95a29","raw_frame":"{\"market\":\"0x779291bef19b6709f61e9764a954aafe9ffae488d50ae674aabdcb4f248006d5\", \"price_changes\":[{\"asset_id\":\"14965588658799411272385430903075831224615961675357217884735713260981483529984\", \"price\":\"0.5\", \"size\":\"260\", \"side\":\"BUY\", \"hash\":\"775e73ed4612d61ef4284afcbd50acd457f18859\", \"best_bid\":\"0.5\", \"best_ask\":\"0.52\"}, {\"asset_id\":\"8761897749749422724209054078244794145777693856614463256546737399611489089783\", \"price\":\"0.5\", \"size\":\"260\", \"side\":\"SELL\", \"hash\":\"84d787e8741ed9f61c8e92f48ac1ed0508da2396\", \"best_bid\":\"0.48\", \"best_ask\":\"0.5\"}], \"timestamp\":\"1785207326219\", \"event_type\":\"price_change\"}","received_at":"2026-07-28T02:55:26.092603Z","schema_version":"clob-market-ws.price_change.v1","sequence":null,"server_hash":null,"server_timestamp":"1785207326219","session_id":"3e519d9098404c15b234d96025eb1a2b","source":"clob_market_ws"},"received_at":"2026-07-28T02:55:26.092603Z","record_id":"caf5ff638b99229adc2287ddacc3a0d9f86a98064719259a3a0cda4966b204d1","schema_fingerprint":"4aa3821a28b0b7c2400bc59aba4bcc0a76e971dadd19610d3ad38c768e124dc7","schema_version":"edge-lab-recorder.raw.v1","sequence":null,"source":"clob_market_ws"}
{"event_at":"2026-07-28T02:55:31.001000Z","event_fingerprint":"07762c6050ffef0ed25659417e68f5004588e444d443da18da7658e25c593d64","payload":{"connection_id":"a6b55582af5f430fb37ad02bf0922475","event_at":"2026-07-28T02:55:31.001000Z","event_type":"price_change","frame_hash":"1c1416a7a4d509307084b68b9777571d6cde47110659afaf2a15ebcff5f7ff1d","frame_index":0,"kind":"data","monotonic_ns":309313879109583,"payload":{"event_type":"price_change","market":"0x779291bef19b6709f61e9764a954aafe9ffae488d50ae674aabdcb4f248006d5","price_changes":[{"asset_id":"8761897749749422724209054078244794145777693856614463256546737399611489089783","best_ask":"0.5","best_bid":"0.48","hash":"ff0bdf524b40eead873b3a0fc03a3b3d60bee47a","price":"0.35","side":"BUY","size":"15"},{"asset_id":"14965588658799411272385430903075831224615961675357217884735713260981483529984","best_ask":"0.52","best_bid":"0.5","hash":"3ccbec032332f074b5cc96ad693b678d222820da","price":"0.65","side":"SELL","size":"15"}],"timestamp":"1785207331001"},"payload_hash":"c989f8f9b0c23e93f4ecdbd099eac6798ffa7a0eb7a355001f5616abf2a9c3b1","raw_frame":"{\"market\":\"0x779291bef19b6709f61e9764a954aafe9ffae488d50ae674aabdcb4f248006d5\", \"price_changes\":[{\"asset_id\":\"8761897749749422724209054078244794145777693856614463256546737399611489089783\", \"price\":\"0.35\", \"size\":\"15\", \"side\":\"BUY\", \"hash\":\"ff0bdf524b40eead873b3a0fc03a3b3d60bee47a\", \"best_bid\":\"0.48\", \"best_ask\":\"0.5\"}, {\"asset_id\":\"14965588658799411272385430903075831224615961675357217884735713260981483529984\", \"price\":\"0.65\", \"size\":\"15\", \"side\":\"SELL\", \"hash\":\"3ccbec032332f074b5cc96ad693b678d222820da\", \"best_bid\":\"0.5\", \"best_ask\":\"0.52\"}], \"timestamp\":\"1785207331001\", \"event_type\":\"price_change\"}","received_at":"2026-07-28T02:55:30.862690Z","schema_version":"clob-market-ws.price_change.v1","sequence":null,"server_hash":null,"server_timestamp":"1785207331001","session_id":"3e519d9098404c15b234d96025eb1a2b","source":"clob_market_ws"},"received_at":"2026-07-28T02:55:30.862690Z","record_id":"78a1c871d21794c763da5e4c75e37953fcce8fd245da6b73f795d5acbec6858a","schema_fingerprint":"4aa3821a28b0b7c2400bc59aba4bcc0a76e971dadd19610d3ad38c768e124dc7","schema_version":"edge-lab-recorder.raw.v1","sequence":null,"source":"clob_market_ws"}
{"event_at":"2026-07-28T02:55:31.002000Z","event_fingerprint":"2fadf82eb30050377fd6cddae62de1c48aad6ed04f7b39b2c979a14543185898","payload":{"connection_id":"a6b55582af5f430fb37ad02bf0922475","event_at":"2026-07-28T02:55:31.002000Z","event_type":"price_change","frame_hash":"8f0e1027b92db111e5e89e3103630a14cbf5e154be5bd2eef6677da2c43d6ec5","frame_index":0,"kind":"data","monotonic_ns":309313884190291,"payload":{"event_type":"price_change","market":"0x779291bef19b6709f61e9764a954aafe9ffae488d50ae674aabdcb4f248006d5","price_changes":[{"asset_id":"8761897749749422724209054078244794145777693856614463256546737399611489089783","best_ask":"0.5","best_bid":"0.48","hash":"1fc1438b15ecfaa75bcde81f20e18280f330af04","price":"0.35","side":"BUY","size":"15"},{"asset_id":"14965588658799411272385430903075831224615961675357217884735713260981483529984","best_ask":"0.52","best_bid":"0.5","hash":"9f800724084c10b54dc94d91bba714a5796a9222","price":"0.65","side":"SELL","size":"15"}],"timestamp":"1785207331002"},"payload_hash":"3ae5d7817fb6ed95a00787784e5c24f8073c875fd7e9e809614af604321f68d3","raw_frame":"{\"market\":\"0x779291bef19b6709f61e9764a954aafe9ffae488d50ae674aabdcb4f248006d5\", \"price_changes\":[{\"asset_id\":\"8761897749749422724209054078244794145777693856614463256546737399611489089783\", \"price\":\"0.35\", \"size\":\"15\", \"side\":\"BUY\", \"hash\":\"1fc1438b15ecfaa75bcde81f20e18280f330af04\", \"best_bid\":\"0.48\", \"best_ask\":\"0.5\"}, {\"asset_id\":\"14965588658799411272385430903075831224615961675357217884735713260981483529984\", \"price\":\"0.65\", \"size\":\"15\", \"side\":\"SELL\", \"hash\":\"9f800724084c10b54dc94d91bba714a5796a9222\", \"best_bid\":\"0.5\", \"best_ask\":\"0.52\"}], \"timestamp\":\"1785207331002\", \"event_type\":\"price_change\"}","received_at":"2026-07-28T02:55:30.867771Z","schema_version":"clob-market-ws.price_change.v1","sequence":null,"server_hash":null,"server_timestamp":"1785207331002","session_id":"3e519d9098404c15b234d96025eb1a2b","source":"clob_market_ws"},"received_at":"2026-07-28T02:55:30.867771Z","record_id":"c88f01d76e1b17bd521687c8e9f6a0cc7f90c97f29dd92a4372981311e025798","schema_fingerprint":"4aa3821a28b0b7c2400bc59aba4bcc0a76e971dadd19610d3ad38c768e124dc7","schema_version":"edge-lab-recorder.raw.v1","sequence":null,"source":"clob_market_ws"}
{"event_at":null,"event_fingerprint":"bc239e77ddba2def719086ab8c3011b3ff1c90f3fe313000c3ce6070d81536f6","payload":{"connection_id":"a6b55582af5f430fb37ad02bf0922475","detail":{"interval_seconds":10.0,"message":"PING"},"event_type":"heartbeat","kind":"lifecycle","monotonic_ns":309313924071708,"received_at":"2026-07-28T02:55:30.907648Z","schema_version":"edge-lab-recorder.lifecycle.v1","session_id":"3e519d9098404c15b234d96025eb1a2b","source":"clob_market_ws"},"received_at":"2026-07-28T02:55:30.907648Z","record_id":"fa36df6ab5da82f150f577da55f0781f1b1e3e67bdbe355e147586cf0f3c053e","schema_fingerprint":"cb8aa3aa4cb168a4b724fd9077bee6ecfb9bc586c57cfdf0ab89f00d82045e3c","schema_version":"edge-lab-recorder.raw.v1","sequence":null,"source":"clob_market_ws"}
{"event_at":null,"event_fingerprint":"342e92058230686bcaf32d02242d3b5c7b26d180c58a564380c8db7d569c3257","payload":{"connection_id":"a6b55582af5f430fb37ad02bf0922475","event_type":"heartbeat_ack","frame_hash":"95784973cc639977bff93619700168505cb8f7855e44fa643d34622a43706c87","kind":"lifecycle","monotonic_ns":309314140476291,"raw_frame":"PONG","received_at":"2026-07-28T02:55:31.124054Z","schema_version":"edge-lab-recorder.heartbeat-ack.v1","session_id":"3e519d9098404c15b234d96025eb1a2b","source":"clob_market_ws"},"received_at":"2026-07-28T02:55:31.124054Z","record_id":"64fff4781a79fa5cbd3772229739928ca8546dbb7ef2bea6669f4b8de1547404","schema_fingerprint":"c14ee1aab3ca674ee738e5268877b544d74c41ad3c427cedc09236467dc68ba1","schema_version":"edge-lab-recorder.raw.v1","sequence":null,"source":"clob_market_ws"}
{"event_at":"2026-07-28T02:55:32.000000Z","event_fingerprint":"83472e60bffbdb0fe4fc3721fcb6999546fb80d2b079243d41e81ab0b47bbbd0","payload":{"connection_id":"a6b55582af5f430fb37ad02bf0922475","event_at":"2026-07-28T02:55:32.000000Z","event_type":"price_change","frame_hash":"492359097ef8d94a22e6d813b965ff3dc623db5007dd0deb7192676f19ac04fd","frame_index":0,"kind":"data","monotonic_ns":309314877642791,"payload":{"event_type":"price_change","market":"0x779291bef19b6709f61e9764a954aafe9ffae488d50ae674aabdcb4f248006d5","price_changes":[{"asset_id":"14965588658799411272385430903075831224615961675357217884735713260981483529984","best_ask":"0.52","best_bid":"0.5","hash":"f0a17de72ba6c1a46c4a666e5b16f1996fae6621","price":"0.35","side":"BUY","size":"15"},{"asset_id":"8761897749749422724209054078244794145777693856614463256546737399611489089783","best_ask":"0.5","best_bid":"0.48","hash":"fe028d1f3a521b87bf1b52aa5881a4ebd11c90b0","price":"0.65","side":"SELL","size":"15"}],"timestamp":"1785207332000"},"payload_hash":"8c737af120e511f2c8dce5d8cf0afaff24be96b165a01fdcbff0232600d52741","raw_frame":"{\"market\":\"0x779291bef19b6709f61e9764a954aafe9ffae488d50ae674aabdcb4f248006d5\", \"price_changes\":[{\"asset_id\":\"14965588658799411272385430903075831224615961675357217884735713260981483529984\", \"price\":\"0.35\", \"size\":\"15\", \"side\":\"BUY\", \"hash\":\"f0a17de72ba6c1a46c4a666e5b16f1996fae6621\", \"best_bid\":\"0.5\", \"best_ask\":\"0.52\"}, {\"asset_id\":\"8761897749749422724209054078244794145777693856614463256546737399611489089783\", \"price\":\"0.65\", \"size\":\"15\", \"side\":\"SELL\", \"hash\":\"fe028d1f3a521b87bf1b52aa5881a4ebd11c90b0\", \"best_bid\":\"0.48\", \"best_ask\":\"0.5\"}], \"timestamp\":\"1785207332000\", \"event_type\":\"price_change\"}","received_at":"2026-07-28T02:55:31.861215Z","schema_version":"clob-market-ws.price_change.v1","sequence":null,"server_hash":null,"server_timestamp":"1785207332000","session_id":"3e519d9098404c15b234d96025eb1a2b","source":"clob_market_ws"},"received_at":"2026-07-28T02:55:31.861215Z","record_id":"1cca77c1105978cf2d371843301a2362cdcf1d90aefc26272bedd9cc6305899b","schema_fingerprint":"4aa3821a28b0b7c2400bc59aba4bcc0a76e971dadd19610d3ad38c768e124dc7","schema_version":"edge-lab-recorder.raw.v1","sequence":null,"source":"clob_market_ws"}
{"event_at":"2026-07-28T02:55:32.003000Z","event_fingerprint":"61b61c56a881d514cd040a3e52fd461ad338d06f203167eca0769bc0934fe7a3","payload":{"connection_id":"a6b55582af5f430fb37ad02bf0922475","event_at":"2026-07-28T02:55:32.003000Z","event_type":"price_change","frame_hash":"79ff35342324f41b34ccd080287a88cfb8218e3f4033dd6298dff84ed7788250","frame_index":0,"kind":"data","monotonic_ns":309314968486416,"payload":{"event_type":"price_change","market":"0x779291bef19b6709f61e9764a954aafe9ffae488d50ae674aabdcb4f248006d5","price_changes":[{"asset_id":"14965588658799411272385430903075831224615961675357217884735713260981483529984","best_ask":"0.52","best_bid":"0.5","hash":"ed51f29564356daa77080c931e5dedaa7c2217ac","price":"0.35","side":"BUY","size":"15"},{"asset_id":"8761897749749422724209054078244794145777693856614463256546737399611489089783","best_ask":"0.5","best_bid":"0.48","hash":"a1dc1c122748cb14ec28e50157b04539513c08fa","price":"0.65","side":"SELL","size":"15"}],"timestamp":"1785207332003"},"payload_hash":"1f4cda27d1af935d01ad36d3389643e515ad4db451b0ad2e67e44db3875b834d","raw_frame":"{\"market\":\"0x779291bef19b6709f61e9764a954aafe9ffae488d50ae674aabdcb4f248006d5\", \"price_changes\":[{\"asset_id\":\"14965588658799411272385430903075831224615961675357217884735713260981483529984\", \"price\":\"0.35\", \"size\":\"15\", \"side\":\"BUY\", \"hash\":\"ed51f29564356daa77080c931e5dedaa7c2217ac\", \"best_bid\":\"0.5\", \"best_ask\":\"0.52\"}, {\"asset_id\":\"8761897749749422724209054078244794145777693856614463256546737399611489089783\", \"price\":\"0.65\", \"size\":\"15\", \"side\":\"SELL\", \"hash\":\"a1dc1c122748cb14ec28e50157b04539513c08fa\", \"best_bid\":\"0.48\", \"best_ask\":\"0.5\"}], \"timestamp\":\"1785207332003\", \"event_type\":\"price_change\"}","received_at":"2026-07-28T02:55:31.952054Z","schema_version":"clob-market-ws.price_change.v1","sequence":null,"server_hash":null,"server_timestamp":"1785207332003","session_id":"3e519d9098404c15b234d96025eb1a2b","source":"clob_market_ws"},"received_at":"2026-07-28T02:55:31.952054Z","record_id":"0679c89f4a9c3f70c7054509641159c655f71ce1b3176ec055964a9e6a692ff9","schema_fingerprint":"4aa3821a28b0b7c2400bc59aba4bcc0a76e971dadd19610d3ad38c768e124dc7","schema_version":"edge-lab-recorder.raw.v1","sequence":null,"source":"clob_market_ws"}
{"event_at":"2026-07-28T02:55:39.841000Z","event_fingerprint":"bf0f0a3aa01ac05cf5c5c0d6eac5f5fd1bbd5022ef32289b602e727f7da76d20","payload":{"connection_id":"a6b55582af5f430fb37ad02bf0922475","event_at":"2026-07-28T02:55:39.841000Z","event_type":"price_change","frame_hash":"c4920dd3bedf2d8c1a3e6373daa7cc5559c4e12035a9bcdbe6cb5fcd77f8c359","frame_index":0,"kind":"data","monotonic_ns":309322721534291,"payload":{"event_type":"price_change","market":"0x779291bef19b6709f61e9764a954aafe9ffae488d50ae674aabdcb4f248006d5","price_changes":[{"asset_id":"8761897749749422724209054078244794145777693856614463256546737399611489089783","best_ask":"0.5","best_bid":"0.48","hash":"4eb6b5583723514da311510d493f935a2ddbc367","price":"0.46","side":"BUY","size":"155"},{"asset_id":"14965588658799411272385430903075831224615961675357217884735713260981483529984","best_ask":"0.52","best_bid":"0.5","hash":"0c435b952cac65aead14a9acb4d3a54abae006ed","price":"0.54","side":"SELL","size":"155"}],"timestamp":"1785207339841"},"payload_hash":"e2231ec04a137848037ea4b98164d4c16a789a1393d560abdc9ba0abec34029a","raw_frame":"{\"market\":\"0x779291bef19b6709f61e9764a954aafe9ffae488d50ae674aabdcb4f248006d5\", \"price_changes\":[{\"asset_id\":\"8761897749749422724209054078244794145777693856614463256546737399611489089783\", \"price\":\"0.46\", \"size\":\"155\", \"side\":\"BUY\", \"hash\":\"4eb6b5583723514da311510d493f935a2ddbc367\", \"best_bid\":\"0.48\", \"best_ask\":\"0.5\"}, {\"asset_id\":\"14965588658799411272385430903075831224615961675357217884735713260981483529984\", \"price\":\"0.54\", \"size\":\"155\", \"side\":\"SELL\", \"hash\":\"0c435b952cac65aead14a9acb4d3a54abae006ed\", \"best_bid\":\"0.5\", \"best_ask\":\"0.52\"}], \"timestamp\":\"1785207339841\", \"event_type\":\"price_change\"}","received_at":"2026-07-28T02:55:39.705044Z","schema_version":"clob-market-ws.price_change.v1","sequence":null,"server_hash":null,"server_timestamp":"1785207339841","session_id":"3e519d9098404c15b234d96025eb1a2b","source":"clob_market_ws"},"received_at":"2026-07-28T02:55:39.705044Z","record_id":"807b0ea7acc61357b38a93a8dc5f0374524d809da25a2a36dcb02c89d6d5117a","schema_fingerprint":"4aa3821a28b0b7c2400bc59aba4bcc0a76e971dadd19610d3ad38c768e124dc7","schema_version":"edge-lab-recorder.raw.v1","sequence":null,"source":"clob_market_ws"}
{"event_at":"2026-07-28T02:55:39.841000Z","event_fingerprint":"f0aa396b28d9e57df3c11192c7d5ee8bd63efb98f9d5e2ec2ca24137319e913a","payload":{"connection_id":"a6b55582af5f430fb37ad02bf0922475","event_at":"2026-07-28T02:55:39.841000Z","event_type":"price_change","frame_hash":"2a3b58780c53f7e14d3f3552b16228bb0f63913158d0553eae70b1176232da47","frame_index":0,"kind":"data","monotonic_ns":309322727278375,"payload":{"event_type":"price_change","market":"0x779291bef19b6709f61e9764a954aafe9ffae488d50ae674aabdcb4f248006d5","price_changes":[{"asset_id":"14965588658799411272385430903075831224615961675357217884735713260981483529984","best_ask":"0.52","best_bid":"0.5","hash":"0c435b952cac65aead14a9acb4d3a54abae006ed","price":"0.5","side":"BUY","size":"160"},{"asset_id":"8761897749749422724209054078244794145777693856614463256546737399611489089783","best_ask":"0.5","best_bid":"0.48","hash":"4eb6b5583723514da311510d493f935a2ddbc367","price":"0.5","side":"SELL","size":"160"}],"timestamp":"1785207339841"},"payload_hash":"02f56ca28c1b41b04c5b12b955023c35689b1fe8d5c2a622259f96a7ec86b654","raw_frame":"{\"market\":\"0x779291bef19b6709f61e9764a954aafe9ffae488d50ae674aabdcb4f248006d5\", \"price_changes\":[{\"asset_id\":\"14965588658799411272385430903075831224615961675357217884735713260981483529984\", \"price\":\"0.5\", \"size\":\"160\", \"side\":\"BUY\", \"hash\":\"0c435b952cac65aead14a9acb4d3a54abae006ed\", \"best_bid\":\"0.5\", \"best_ask\":\"0.52\"}, {\"asset_id\":\"8761897749749422724209054078244794145777693856614463256546737399611489089783\", \"price\":\"0.5\", \"size\":\"160\", \"side\":\"SELL\", \"hash\":\"4eb6b5583723514da311510d493f935a2ddbc367\", \"best_bid\":\"0.48\", \"best_ask\":\"0.5\"}], \"timestamp\":\"1785207339841\", \"event_type\":\"price_change\"}","received_at":"2026-07-28T02:55:39.710794Z","schema_version":"clob-market-ws.price_change.v1","sequence":null,"server_hash":null,"server_timestamp":"1785207339841","session_id":"3e519d9098404c15b234d96025eb1a2b","source":"clob_market_ws"},"received_at":"2026-07-28T02:55:39.710794Z","record_id":"2c44b17d0b7d4273854f2f3d5c8a9abbf08175af09835a8dcbb932e30dac1715","schema_fingerprint":"4aa3821a28b0b7c2400bc59aba4bcc0a76e971dadd19610d3ad38c768e124dc7","schema_version":"edge-lab-recorder.raw.v1","sequence":null,"source":"clob_market_ws"}
{"event_at":"2026-07-28T02:55:39.842000Z","event_fingerprint":"6d510135374c443bccfc3848bf7a5e82e5cb2b217ee1b94084ed6e0ced4f8069","payload":{"connection_id":"a6b55582af5f430fb37ad02bf0922475","event_at":"2026-07-28T02:55:39.842000Z","event_type":"price_change","frame_hash":"a3125a033442f0c42c017458cf9a8f9db3b14276abe950c31484d6cfa576bcb1","frame_index":0,"kind":"data","monotonic_ns":309322732363958,"payload":{"event_type":"price_change","market":"0x779291bef19b6709f61e9764a954aafe9ffae488d50ae674aabdcb4f248006d5","price_changes":[{"asset_id":"8761897749749422724209054078244794145777693856614463256546737399611489089783","best_ask":"0.5","best_bid":"0.48","hash":"94c34b974503c032cc9373dafdeb16d1b6b55309","price":"0.46","side":"BUY","size":"55"},{"asset_id":"14965588658799411272385430903075831224615961675357217884735713260981483529984","best_ask":"0.52","best_bid":"0.5","hash":"32b5b03bb9cda830327e2e74cbc26f478e5346de","price":"0.54","side":"SELL","size":"55"}],"timestamp":"1785207339842"},"payload_hash":"82e3154adbe3c178c3a11203440acd5291f0f00452ad99205ebbbf56ad348347","raw_frame":"{\"market\":\"0x779291bef19b6709f61e9764a954aafe9ffae488d50ae674aabdcb4f248006d5\", \"price_changes\":[{\"asset_id\":\"8761897749749422724209054078244794145777693856614463256546737399611489089783\", \"price\":\"0.46\", \"size\":\"55\", \"side\":\"BUY\", \"hash\":\"94c34b974503c032cc9373dafdeb16d1b6b55309\", \"best_bid\":\"0.48\", \"best_ask\":\"0.5\"}, {\"asset_id\":\"14965588658799411272385430903075831224615961675357217884735713260981483529984\", \"price\":\"0.54\", \"size\":\"55\", \"side\":\"SELL\", \"hash\":\"32b5b03bb9cda830327e2e74cbc26f478e5346de\", \"best_bid\":\"0.5\", \"best_ask\":\"0.52\"}], \"timestamp\":\"1785207339842\", \"event_type\":\"price_change\"}","received_at":"2026-07-28T02:55:39.715881Z","schema_version":"clob-market-ws.price_change.v1","sequence":null,"server_hash":null,"server_timestamp":"1785207339842","session_id":"3e519d9098404c15b234d96025eb1a2b","source":"clob_market_ws"},"received_at":"2026-07-28T02:55:39.715881Z","record_id":"2e77c1947297a2c76ccb8afebc53cc1892d4d15748a022316737fcc422bcf582","schema_fingerprint":"4aa3821a28b0b7c2400bc59aba4bcc0a76e971dadd19610d3ad38c768e124dc7","schema_version":"edge-lab-recorder.raw.v1","sequence":null,"source":"clob_market_ws"}
{"event_at":"2026-07-28T02:55:39.842000Z","event_fingerprint":"873ffa2cb66fc761a2f516719c9aab012976de62f31cb8b7fb02fa6f879d7fc5","payload":{"connection_id":"a6b55582af5f430fb37ad02bf0922475","event_at":"2026-07-28T02:55:39.842000Z","event_type":"price_change","frame_hash":"b54b8ddfad67862d3ca0070fbf1c8b2f9b943a901d99636d025f5e41cfb4e2a1","frame_index":0,"kind":"data","monotonic_ns":309322739083750,"payload":{"event_type":"price_change","market":"0x779291bef19b6709f61e9764a954aafe9ffae488d50ae674aabdcb4f248006d5","price_changes":[{"asset_id":"14965588658799411272385430903075831224615961675357217884735713260981483529984","best_ask":"0.52","best_bid":"0.5","hash":"32b5b03bb9cda830327e2e74cbc26f478e5346de","price":"0.5","side":"BUY","size":"60"},{"asset_id":"8761897749749422724209054078244794145777693856614463256546737399611489089783","best_ask":"0.5","best_bid":"0.48","hash":"94c34b974503c032cc9373dafdeb16d1b6b55309","price":"0.5","side":"SELL","size":"60"}],"timestamp":"1785207339842"},"payload_hash":"88ee4c67ea9473e93424b01db525a7c261b759ed1ccee803e0093b04f2c9e1a0","raw_frame":"{\"market\":\"0x779291bef19b6709f61e9764a954aafe9ffae488d50ae674aabdcb4f248006d5\", \"price_changes\":[{\"asset_id\":\"14965588658799411272385430903075831224615961675357217884735713260981483529984\", \"price\":\"0.5\", \"size\":\"60\", \"side\":\"BUY\", \"hash\":\"32b5b03bb9cda830327e2e74cbc26f478e5346de\", \"best_bid\":\"0.5\", \"best_ask\":\"0.52\"}, {\"asset_id\":\"8761897749749422724209054078244794145777693856614463256546737399611489089783\", \"price\":\"0.5\", \"size\":\"60\", \"side\":\"SELL\", \"hash\":\"94c34b974503c032cc9373dafdeb16d1b6b55309\", \"best_bid\":\"0.48\", \"best_ask\":\"0.5\"}], \"timestamp\":\"1785207339842\", \"event_type\":\"price_change\"}","received_at":"2026-07-28T02:55:39.722600Z","schema_version":"clob-market-ws.price_change.v1","sequence":null,"server_hash":null,"server_timestamp":"1785207339842","session_id":"3e519d9098404c15b234d96025eb1a2b","source":"clob_market_ws"},"received_at":"2026-07-28T02:55:39.722600Z","record_id":"a5d5131b30d081c8159467bda6caebbe6149f227a441b6967a2a2964ec7f5ebc","schema_fingerprint":"4aa3821a28b0b7c2400bc59aba4bcc0a76e971dadd19610d3ad38c768e124dc7","schema_version":"edge-lab-recorder.raw.v1","sequence":null,"source":"clob_market_ws"}
{"event_at":"2026-07-28T02:55:39.885000Z","event_fingerprint":"74e379cc194ead674b21ff972148576c8c3dbda8170c7db81f23e9b089fed2be","payload":{"connection_id":"a6b55582af5f430fb37ad02bf0922475","event_at":"2026-07-28T02:55:39.885000Z","event_type":"best_bid_ask","frame_hash":"47a327384a0087a5bebf6550bab373ee2f7f5d60a86ea3a9434cf91de4818dde","frame_index":0,"kind":"data","monotonic_ns":309322774779833,"payload":{"asset_id":"14965588658799411272385430903075831224615961675357217884735713260981483529984","best_ask":"0.51","best_bid":"0.5","event_type":"best_bid_ask","market":"0x779291bef19b6709f61e9764a954aafe9ffae488d50ae674aabdcb4f248006d5","spread":"0.01","timestamp":"1785207339885"},"payload_hash":"ac78ff0644aa1cfa86e7d4830c20dff914b58f6cb9898c2d4604e4f417bd7bbe","raw_frame":"{\"market\":\"0x779291bef19b6709f61e9764a954aafe9ffae488d50ae674aabdcb4f248006d5\", \"asset_id\":\"14965588658799411272385430903075831224615961675357217884735713260981483529984\", \"best_bid\":\"0.5\", \"best_ask\":\"0.51\", \"spread\":\"0.01\", \"timestamp\":\"1785207339885\", \"event_type\":\"best_bid_ask\"}","received_at":"2026-07-28T02:55:39.758297Z","schema_version":"clob-market-ws.best_bid_ask.v1","sequence":null,"server_hash":null,"server_timestamp":"1785207339885","session_id":"3e519d9098404c15b234d96025eb1a2b","source":"clob_market_ws"},"received_at":"2026-07-28T02:55:39.758297Z","record_id":"09f42c6efcbf82cd3870ac8775d267d0df802e9583251cd0f61a281380800204","schema_fingerprint":"8488399f31b0337811b13b266be932db7062827c2470b78bd8e9e99bab51d17d","schema_version":"edge-lab-recorder.raw.v1","sequence":null,"source":"clob_market_ws"}
{"event_at":"2026-07-28T02:55:39.885000Z","event_fingerprint":"57bd14b6d59d5bef4f49f6dbec4054d97afbd53c1320dc82ad26a490ed9e8d6e","payload":{"connection_id":"a6b55582af5f430fb37ad02bf0922475","event_at":"2026-07-28T02:55:39.885000Z","event_type":"best_bid_ask","frame_hash":"7c0c43357690abb3e0af0265f50400aa973da50a32a83e805b907a3e2df753bd","frame_index":0,"kind":"data","monotonic_ns":309322779789916,"payload":{"asset_id":"8761897749749422724209054078244794145777693856614463256546737399611489089783","best_ask":"0.5","best_bid":"0.49","event_type":"best_bid_ask","market":"0x779291bef19b6709f61e9764a954aafe9ffae488d50ae674aabdcb4f248006d5","spread":"0.01","timestamp":"1785207339885"},"payload_hash":"f790402178ec24fd65317dcbf4c10ba40da70025b7b277c0c21df55d116a6019","raw_frame":"{\"market\":\"0x779291bef19b6709f61e9764a954aafe9ffae488d50ae674aabdcb4f248006d5\", \"asset_id\":\"8761897749749422724209054078244794145777693856614463256546737399611489089783\", \"best_bid\":\"0.49\", \"best_ask\":\"0.5\", \"spread\":\"0.01\", \"timestamp\":\"1785207339885\", \"event_type\":\"best_bid_ask\"}","received_at":"2026-07-28T02:55:39.763305Z","schema_version":"clob-market-ws.best_bid_ask.v1","sequence":null,"server_hash":null,"server_timestamp":"1785207339885","session_id":"3e519d9098404c15b234d96025eb1a2b","source":"clob_market_ws"},"received_at":"2026-07-28T02:55:39.763305Z","record_id":"097aef02006171c44d155c227edbcf753a1c9679c62e99ccef19d87979b077bb","schema_fingerprint":"8488399f31b0337811b13b266be932db7062827c2470b78bd8e9e99bab51d17d","schema_version":"edge-lab-recorder.raw.v1","sequence":null,"source":"clob_market_ws"}
{"event_at":"2026-07-28T02:55:39.885000Z","event_fingerprint":"f31337e5add6d452aaf67d0095f4c4bf2a2d206d9e6c469bc2a11a6d7d751211","payload":{"connection_id":"a6b55582af5f430fb37ad02bf0922475","event_at":"2026-07-28T02:55:39.885000Z","event_type":"price_change","frame_hash":"5e76713ac5d6ec8b9df42d31ef13ee6399394fa3cc58dcea382a71b9a45cf916","frame_index":0,"kind":"data","monotonic_ns":309322783459458,"payload":{"event_type":"price_change","market":"0x779291bef19b6709f61e9764a954aafe9ffae488d50ae674aabdcb4f248006d5","price_changes":[{"asset_id":"8761897749749422724209054078244794145777693856614463256546737399611489089783","best_ask":"0.5","best_bid":"0.49","hash":"dd77321f6d25696529d71c06ca94a2d9a035a92d","price":"0.49","side":"BUY","size":"5"},{"asset_id":"14965588658799411272385430903075831224615961675357217884735713260981483529984","best_ask":"0.51","best_bid":"0.5","hash":"e0ff639970a1990a0995d9c013afbaf740c70260","price":"0.51","side":"SELL","size":"5"}],"timestamp":"1785207339885"},"payload_hash":"9a04da4fc6b8bad479217613d6bf649e930dae0efb69b90f5b5a4baaf9ca89ba","raw_frame":"{\"market\":\"0x779291bef19b6709f61e9764a954aafe9ffae488d50ae674aabdcb4f248006d5\", \"price_changes\":[{\"asset_id\":\"8761897749749422724209054078244794145777693856614463256546737399611489089783\", \"price\":\"0.49\", \"size\":\"5\", \"side\":\"BUY\", \"hash\":\"dd77321f6d25696529d71c06ca94a2d9a035a92d\", \"best_bid\":\"0.49\", \"best_ask\":\"0.5\"}, {\"asset_id\":\"14965588658799411272385430903075831224615961675357217884735713260981483529984\", \"price\":\"0.51\", \"size\":\"5\", \"side\":\"SELL\", \"hash\":\"e0ff639970a1990a0995d9c013afbaf740c70260\", \"best_bid\":\"0.5\", \"best_ask\":\"0.51\"}], \"timestamp\":\"1785207339885\", \"event_type\":\"price_change\"}","received_at":"2026-07-28T02:55:39.766975Z","schema_version":"clob-market-ws.price_change.v1","sequence":null,"server_hash":null,"server_timestamp":"1785207339885","session_id":"3e519d9098404c15b234d96025eb1a2b","source":"clob_market_ws"},"received_at":"2026-07-28T02:55:39.766975Z","record_id":"19f40fc294950af64445fad78f49234c6ddca38e6cc80f03171e3c5878f3a2f1","schema_fingerprint":"4aa3821a28b0b7c2400bc59aba4bcc0a76e971dadd19610d3ad38c768e124dc7","schema_version":"edge-lab-recorder.raw.v1","sequence":null,"source":"clob_market_ws"}
{"event_at":"2026-07-28T02:55:39.886000Z","event_fingerprint":"91f0dd531fb9c362849858e78538c0362f0d0f682a4917035fcd3c40d31cd8f1","payload":{"connection_id":"a6b55582af5f430fb37ad02bf0922475","event_at":"2026-07-28T02:55:39.886000Z","event_type":"price_change","frame_hash":"bc100cbc5a1e975816f78d98829d0100a23a1ff22e9793509c4734d2044fd2bc","frame_index":0,"kind":"data","monotonic_ns":309322787413666,"payload":{"event_type":"price_change","market":"0x779291bef19b6709f61e9764a954aafe9ffae488d50ae674aabdcb4f248006d5","price_changes":[{"asset_id":"8761897749749422724209054078244794145777693856614463256546737399611489089783","best_ask":"0.5","best_bid":"0.49","hash":"4e5a216138174eba0f5ab14d57498f32b6847508","price":"0.49","side":"BUY","size":"10"},{"asset_id":"14965588658799411272385430903075831224615961675357217884735713260981483529984","best_ask":"0.51","best_bid":"0.5","hash":"a5e2fb2efe5cdb506421158b030ab10a634650db","price":"0.51","side":"SELL","size":"10"}],"timestamp":"1785207339886"},"payload_hash":"c2415e6b5756d23f33150639644ca1c549382b6279c2c81b66d704745a79fa80","raw_frame":"{\"market\":\"0x779291bef19b6709f61e9764a954aafe9ffae488d50ae674aabdcb4f248006d5\", \"price_changes\":[{\"asset_id\":\"8761897749749422724209054078244794145777693856614463256546737399611489089783\", \"price\":\"0.49\", \"size\":\"10\", \"side\":\"BUY\", \"hash\":\"4e5a216138174eba0f5ab14d57498f32b6847508\", \"best_bid\":\"0.49\", \"best_ask\":\"0.5\"}, {\"asset_id\":\"14965588658799411272385430903075831224615961675357217884735713260981483529984\", \"price\":\"0.51\", \"size\":\"10\", \"side\":\"SELL\", \"hash\":\"a5e2fb2efe5cdb506421158b030ab10a634650db\", \"best_bid\":\"0.5\", \"best_ask\":\"0.51\"}], \"timestamp\":\"1785207339886\", \"event_type\":\"price_change\"}","received_at":"2026-07-28T02:55:39.770929Z","schema_version":"clob-market-ws.price_change.v1","sequence":null,"server_hash":null,"server_timestamp":"1785207339886","session_id":"3e519d9098404c15b234d96025eb1a2b","source":"clob_market_ws"},"received_at":"2026-07-28T02:55:39.770929Z","record_id":"aeb87aec8cd78837057ef3606a86d73f1db263641de73f64e026e47eaf272b6e","schema_fingerprint":"4aa3821a28b0b7c2400bc59aba4bcc0a76e971dadd19610d3ad38c768e124dc7","schema_version":"edge-lab-recorder.raw.v1","sequence":null,"source":"clob_market_ws"}
{"event_at":"2026-07-28T02:55:39.887000Z","event_fingerprint":"71caa9dfc048e3629b74da4a9760db318e314383671e06db11459a6bd40a8ef8","payload":{"connection_id":"a6b55582af5f430fb37ad02bf0922475","event_at":"2026-07-28T02:55:39.887000Z","event_type":"price_change","frame_hash":"3cf27eb39c173ed7acb656bdb42a690518991829bb9f6e67ca1a2529451f3801","frame_index":0,"kind":"data","monotonic_ns":309322791265416,"payload":{"event_type":"price_change","market":"0x779291bef19b6709f61e9764a954aafe9ffae488d50ae674aabdcb4f248006d5","price_changes":[{"asset_id":"8761897749749422724209054078244794145777693856614463256546737399611489089783","best_ask":"0.5","best_bid":"0.49","hash":"3421398d0548332d619589553c4cba09e5db5a56","price":"0.49","side":"BUY","size":"15"},{"asset_id":"14965588658799411272385430903075831224615961675357217884735713260981483529984","best_ask":"0.51","best_bid":"0.5","hash":"1b0048f346e07ba1e5874843381c82fd566ccd23","price":"0.51","side":"SELL","size":"15"}],"timestamp":"1785207339887"},"payload_hash":"55f3d3671c51c1089aabd0907367538b4031e1b5e579a80cee17cf9e2d8e439a","raw_frame":"{\"market\":\"0x779291bef19b6709f61e9764a954aafe9ffae488d50ae674aabdcb4f248006d5\", \"price_changes\":[{\"asset_id\":\"8761897749749422724209054078244794145777693856614463256546737399611489089783\", \"price\":\"0.49\", \"size\":\"15\", \"side\":\"BUY\", \"hash\":\"3421398d0548332d619589553c4cba09e5db5a56\", \"best_bid\":\"0.49\", \"best_ask\":\"0.5\"}, {\"asset_id\":\"14965588658799411272385430903075831224615961675357217884735713260981483529984\", \"price\":\"0.51\", \"size\":\"15\", \"side\":\"SELL\", \"hash\":\"1b0048f346e07ba1e5874843381c82fd566ccd23\", \"best_bid\":\"0.5\", \"best_ask\":\"0.51\"}], \"timestamp\":\"1785207339887\", \"event_type\":\"price_change\"}","received_at":"2026-07-28T02:55:39.774781Z","schema_version":"clob-market-ws.price_change.v1","sequence":null,"server_hash":null,"server_timestamp":"1785207339887","session_id":"3e519d9098404c15b234d96025eb1a2b","source":"clob_market_ws"},"received_at":"2026-07-28T02:55:39.774781Z","record_id":"8bfae8511c98064a35be555c15589acb95801744b2f2ba7195fe028613a83f70","schema_fingerprint":"4aa3821a28b0b7c2400bc59aba4bcc0a76e971dadd19610d3ad38c768e124dc7","schema_version":"edge-lab-recorder.raw.v1","sequence":null,"source":"clob_market_ws"}
{"event_at":"2026-07-28T02:55:39.887000Z","event_fingerprint":"ed2dfee6094572e6bdf804a468e7f5a311160aa9336b1fce258c7c395fbf1788","payload":{"connection_id":"a6b55582af5f430fb37ad02bf0922475","event_at":"2026-07-28T02:55:39.887000Z","event_type":"price_change","frame_hash":"4fb5fe22c0365d2b1ec0a9b95ed99eef955832e8b3dd26ac29cbe7214b704478","frame_index":0,"kind":"data","monotonic_ns":309322913601458,"payload":{"event_type":"price_change","market":"0x779291bef19b6709f61e9764a954aafe9ffae488d50ae674aabdcb4f248006d5","price_changes":[{"asset_id":"8761897749749422724209054078244794145777693856614463256546737399611489089783","best_ask":"0.5","best_bid":"0.49","hash":"1b90de7e42743b705117764d051d25e46123c49f","price":"0.49","side":"BUY","size":"20"},{"asset_id":"14965588658799411272385430903075831224615961675357217884735713260981483529984","best_ask":"0.51","best_bid":"0.5","hash":"b64cf50e2376bc78700ff7c2fdf27e68c6d72fff","price":"0.51","side":"SELL","size":"20"}],"timestamp":"1785207339887"},"payload_hash":"79dcb9fe564bc9597e1d7a83b66edc930df9b0c8b098bf510584e4c11528e7c7","raw_frame":"{\"market\":\"0x779291bef19b6709f61e9764a954aafe9ffae488d50ae674aabdcb4f248006d5\", \"price_changes\":[{\"asset_id\":\"8761897749749422724209054078244794145777693856614463256546737399611489089783\", \"price\":\"0.49\", \"size\":\"20\", \"side\":\"BUY\", \"hash\":\"1b90de7e42743b705117764d051d25e46123c49f\", \"best_bid\":\"0.49\", \"best_ask\":\"0.5\"}, {\"asset_id\":\"14965588658799411272385430903075831224615961675357217884735713260981483529984\", \"price\":\"0.51\", \"size\":\"20\", \"side\":\"SELL\", \"hash\":\"b64cf50e2376bc78700ff7c2fdf27e68c6d72fff\", \"best_bid\":\"0.5\", \"best_ask\":\"0.51\"}], \"timestamp\":\"1785207339887\", \"event_type\":\"price_change\"}","received_at":"2026-07-28T02:55:39.897117Z","schema_version":"clob-market-ws.price_change.v1","sequence":null,"server_hash":null,"server_timestamp":"1785207339887","session_id":"3e519d9098404c15b234d96025eb1a2b","source":"clob_market_ws"},"received_at":"2026-07-28T02:55:39.897117Z","record_id":"710e01dd4e5a68f23710c3350b83603f513d84b3c257b6dc0131026068a9512c","schema_fingerprint":"4aa3821a28b0b7c2400bc59aba4bcc0a76e971dadd19610d3ad38c768e124dc7","schema_version":"edge-lab-recorder.raw.v1","sequence":null,"source":"clob_market_ws"}
{"event_at":"2026-07-28T02:55:39.888000Z","event_fingerprint":"450efc18f0436cfe182c1d7c08e7e3935eba00454f1649527a85546db83afbdc","payload":{"connection_id":"a6b55582af5f430fb37ad02bf0922475","event_at":"2026-07-28T02:55:39.888000Z","event_type":"price_change","frame_hash":"07781b91ade835a6dfd34eb377f95ec7fea9b1220576ac87df201eee63bdd07a","frame_index":0,"kind":"data","monotonic_ns":309322920638833,"payload":{"event_type":"price_change","market":"0x779291bef19b6709f61e9764a954aafe9ffae488d50ae674aabdcb4f248006d5","price_changes":[{"asset_id":"8761897749749422724209054078244794145777693856614463256546737399611489089783","best_ask":"0.5","best_bid":"0.49","hash":"bfbe511085191cd5072383eee885bf36eb6ce0b0","price":"0.49","side":"BUY","size":"25"},{"asset_id":"14965588658799411272385430903075831224615961675357217884735713260981483529984","best_ask":"0.51","best_bid":"0.5","hash":"e20cf4a63f3255dce098c91ad3e49b1ea8cf586e","price":"0.51","side":"SELL","size":"25"}],"timestamp":"1785207339888"},"payload_hash":"1f5bac2cd61d3047754a8003c73eecaa77e9e82eeb8ff038573ba03ac60b473b","raw_frame":"{\"market\":\"0x779291bef19b6709f61e9764a954aafe9ffae488d50ae674aabdcb4f248006d5\", \"price_changes\":[{\"asset_id\":\"8761897749749422724209054078244794145777693856614463256546737399611489089783\", \"price\":\"0.49\", \"size\":\"25\", \"side\":\"BUY\", \"hash\":\"bfbe511085191cd5072383eee885bf36eb6ce0b0\", \"best_bid\":\"0.49\", \"best_ask\":\"0.5\"}, {\"asset_id\":\"14965588658799411272385430903075831224615961675357217884735713260981483529984\", \"price\":\"0.51\", \"size\":\"25\", \"side\":\"SELL\", \"hash\":\"e20cf4a63f3255dce098c91ad3e49b1ea8cf586e\", \"best_bid\":\"0.5\", \"best_ask\":\"0.51\"}], \"timestamp\":\"1785207339888\", \"event_type\":\"price_change\"}","received_at":"2026-07-28T02:55:39.904152Z","schema_version":"clob-market-ws.price_change.v1","sequence":null,"server_hash":null,"server_timestamp":"1785207339888","session_id":"3e519d9098404c15b234d96025eb1a2b","source":"clob_market_ws"},"received_at":"2026-07-28T02:55:39.904152Z","record_id":"2bad55ac7121a2c6c07a323b7bea1e467ab30de1b33e29d7ac695bc76d15ff92","schema_fingerprint":"4aa3821a28b0b7c2400bc59aba4bcc0a76e971dadd19610d3ad38c768e124dc7","schema_version":"edge-lab-recorder.raw.v1","sequence":null,"source":"clob_market_ws"}
{"event_at":"2026-07-28T02:55:39.889000Z","event_fingerprint":"d800efad75a9d5a12a70aeb099397cef561201ce8360f59856ac2f350bf11aad","payload":{"connection_id":"a6b55582af5f430fb37ad02bf0922475","event_at":"2026-07-28T02:55:39.889000Z","event_type":"price_change","frame_hash":"865a66182819d0da24e3762d15bbad0d2d21f775577ed804e01b8a8c7d130a15","frame_index":0,"kind":"data","monotonic_ns":309322925475166,"payload":{"event_type":"price_change","market":"0x779291bef19b6709f61e9764a954aafe9ffae488d50ae674aabdcb4f248006d5","price_changes":[{"asset_id":"8761897749749422724209054078244794145777693856614463256546737399611489089783","best_ask":"0.5","best_bid":"0.49","hash":"8182ebe42b1145c9f19e5f4edd43ac9c34c6aa60","price":"0.49","side":"BUY","size":"30"},{"asset_id":"14965588658799411272385430903075831224615961675357217884735713260981483529984","best_ask":"0.51","best_bid":"0.5","hash":"b15aec2d74917929bffdf15674ef00e24f31e80a","price":"0.51","side":"SELL","size":"30"}],"timestamp":"1785207339889"},"payload_hash":"93b4e162bc25b54a23bc8a1051c7345d61579493d3adc5aaf9ebb922e3eb9078","raw_frame":"{\"market\":\"0x779291bef19b6709f61e9764a954aafe9ffae488d50ae674aabdcb4f248006d5\", \"price_changes\":[{\"asset_id\":\"8761897749749422724209054078244794145777693856614463256546737399611489089783\", \"price\":\"0.49\", \"size\":\"30\", \"side\":\"BUY\", \"hash\":\"8182ebe42b1145c9f19e5f4edd43ac9c34c6aa60\", \"best_bid\":\"0.49\", \"best_ask\":\"0.5\"}, {\"asset_id\":\"14965588658799411272385430903075831224615961675357217884735713260981483529984\", \"price\":\"0.51\", \"size\":\"30\", \"side\":\"SELL\", \"hash\":\"b15aec2d74917929bffdf15674ef00e24f31e80a\", \"best_bid\":\"0.5\", \"best_ask\":\"0.51\"}], \"timestamp\":\"1785207339889\", \"event_type\":\"price_change\"}","received_at":"2026-07-28T02:55:39.908991Z","schema_version":"clob-market-ws.price_change.v1","sequence":null,"server_hash":null,"server_timestamp":"1785207339889","session_id":"3e519d9098404c15b234d96025eb1a2b","source":"clob_market_ws"},"received_at":"2026-07-28T02:55:39.908991Z","record_id":"f9828a08df8d6c9d35f52b80d4ec63e88d550587fb82cc7ae8a7888b3359aa5b","schema_fingerprint":"4aa3821a28b0b7c2400bc59aba4bcc0a76e971dadd19610d3ad38c768e124dc7","schema_version":"edge-lab-recorder.raw.v1","sequence":null,"source":"clob_market_ws"}
{"event_at":"2026-07-28T02:55:39.891000Z","event_fingerprint":"8861edee2d11ae22dc089f93b983c4c4e0b4b4b13803b772c04097fbf69ec7d7","payload":{"connection_id":"a6b55582af5f430fb37ad02bf0922475","event_at":"2026-07-28T02:55:39.891000Z","event_type":"price_change","frame_hash":"416950427afe30bf3541c482b902bbb4ef34de6059ca73e76bce80c503262c17","frame_index":0,"kind":"data","monotonic_ns":309322929788333,"payload":{"event_type":"price_change","market":"0x779291bef19b6709f61e9764a954aafe9ffae488d50ae674aabdcb4f248006d5","price_changes":[{"asset_id":"8761897749749422724209054078244794145777693856614463256546737399611489089783","best_ask":"0.5","best_bid":"0.49","hash":"0bff07042db41486ef7e66acd7451cb06d8a944f","price":"0.49","side":"BUY","size":"35"},{"asset_id":"14965588658799411272385430903075831224615961675357217884735713260981483529984","best_ask":"0.51","best_bid":"0.5","hash":"e2ea1204db095cb0df63308540bcc478658ff71c","price":"0.51","side":"SELL","size":"35"}],"timestamp":"1785207339891"},"payload_hash":"dd09074bcbcee788f0d5c95d55fa79764f270637dca1f2f0e1fcf5946df37661","raw_frame":"{\"market\":\"0x779291bef19b6709f61e9764a954aafe9ffae488d50ae674aabdcb4f248006d5\", \"price_changes\":[{\"asset_id\":\"8761897749749422724209054078244794145777693856614463256546737399611489089783\", \"price\":\"0.49\", \"size\":\"35\", \"side\":\"BUY\", \"hash\":\"0bff07042db41486ef7e66acd7451cb06d8a944f\", \"best_bid\":\"0.49\", \"best_ask\":\"0.5\"}, {\"asset_id\":\"14965588658799411272385430903075831224615961675357217884735713260981483529984\", \"price\":\"0.51\", \"size\":\"35\", \"side\":\"SELL\", \"hash\":\"e2ea1204db095cb0df63308540bcc478658ff71c\", \"best_bid\":\"0.5\", \"best_ask\":\"0.51\"}], \"timestamp\":\"1785207339891\", \"event_type\":\"price_change\"}","received_at":"2026-07-28T02:55:39.913303Z","schema_version":"clob-market-ws.price_change.v1","sequence":null,"server_hash":null,"server_timestamp":"1785207339891","session_id":"3e519d9098404c15b234d96025eb1a2b","source":"clob_market_ws"},"received_at":"2026-07-28T02:55:39.913303Z","record_id":"b629b58a8517d7956c4123344798caa15bbe6b7725e04f23b4dda674cb75ddef","schema_fingerprint":"4aa3821a28b0b7c2400bc59aba4bcc0a76e971dadd19610d3ad38c768e124dc7","schema_version":"edge-lab-recorder.raw.v1","sequence":null,"source":"clob_market_ws"}
{"event_at":"2026-07-28T02:55:39.892000Z","event_fingerprint":"f36b0f7a4e57fb9f9d750ef6ed8f6b8298de6a0a59b4099f597899c8175a247f","payload":{"connection_id":"a6b55582af5f430fb37ad02bf0922475","event_at":"2026-07-28T02:55:39.892000Z","event_type":"price_change","frame_hash":"800247e2576329d41e130b3caa9425f0b51512870dca6e4eefb2d92fef2ecf24","frame_index":0,"kind":"data","monotonic_ns":309322934341625,"payload":{"event_type":"price_change","market":"0x779291bef19b6709f61e9764a954aafe9ffae488d50ae674aabdcb4f248006d5","price_changes":[{"asset_id":"8761897749749422724209054078244794145777693856614463256546737399611489089783","best_ask":"0.5","best_bid":"0.49","hash":"bc3dc383b0473622b5c30955e3d61120b8f46be8","price":"0.49","side":"BUY","size":"40"},{"asset_id":"14965588658799411272385430903075831224615961675357217884735713260981483529984","best_ask":"0.51","best_bid":"0.5","hash":"c20d3533dd10c312101f1b14e1149a91c1f26bcb","price":"0.51","side":"SELL","size":"40"}],"timestamp":"1785207339892"},"payload_hash":"e01658245d2875d7092b6a6102ceb38a91f56baab11d03df56fd69cd999b1466","raw_frame":"{\"market\":\"0x779291bef19b6709f61e9764a954aafe9ffae488d50ae674aabdcb4f248006d5\", \"price_changes\":[{\"asset_id\":\"8761897749749422724209054078244794145777693856614463256546737399611489089783\", \"price\":\"0.49\", \"size\":\"40\", \"side\":\"BUY\", \"hash\":\"bc3dc383b0473622b5c30955e3d61120b8f46be8\", \"best_bid\":\"0.49\", \"best_ask\":\"0.5\"}, {\"asset_id\":\"14965588658799411272385430903075831224615961675357217884735713260981483529984\", \"price\":\"0.51\", \"size\":\"40\", \"side\":\"SELL\", \"hash\":\"c20d3533dd10c312101f1b14e1149a91c1f26bcb\", \"best_bid\":\"0.5\", \"best_ask\":\"0.51\"}], \"timestamp\":\"1785207339892\", \"event_type\":\"price_change\"}","received_at":"2026-07-28T02:55:39.917857Z","schema_version":"clob-market-ws.price_change.v1","sequence":null,"server_hash":null,"server_timestamp":"1785207339892","session_id":"3e519d9098404c15b234d96025eb1a2b","source":"clob_market_ws"},"received_at":"2026-07-28T02:55:39.917857Z","record_id":"8d3863e0c8d7627029f6aecc23f09004d207dd6092d1e406cc556356e66c8d11","schema_fingerprint":"4aa3821a28b0b7c2400bc59aba4bcc0a76e971dadd19610d3ad38c768e124dc7","schema_version":"edge-lab-recorder.raw.v1","sequence":null,"source":"clob_market_ws"}
{"event_at":"2026-07-28T02:55:39.892000Z","event_fingerprint":"137b5e29926a9d1845540d2cb812f5216185a31022e73d5199c1b5c4a971b0b6","payload":{"connection_id":"a6b55582af5f430fb37ad02bf0922475","event_at":"2026-07-28T02:55:39.892000Z","event_type":"price_change","frame_hash":"64f498a9918b354b109acd1664f1d7ecec9b38397b9d43b9d338a57e39694cc2","frame_index":0,"kind":"data","monotonic_ns":309322938864250,"payload":{"event_type":"price_change","market":"0x779291bef19b6709f61e9764a954aafe9ffae488d50ae674aabdcb4f248006d5","price_changes":[{"asset_id":"8761897749749422724209054078244794145777693856614463256546737399611489089783","best_ask":"0.5","best_bid":"0.49","hash":"85b9b99da0ac0fceda8659e711a47d4f7bdec405","price":"0.49","side":"BUY","size":"45"},{"asset_id":"14965588658799411272385430903075831224615961675357217884735713260981483529984","best_ask":"0.51","best_bid":"0.5","hash":"736ecbe218f075e12f29fecbc73aecaf95643ade","price":"0.51","side":"SELL","size":"45"}],"timestamp":"1785207339892"},"payload_hash":"c2ac3a45d58427a14018e828ed2ea5899cd9fc5087b2118373066110a08b1051","raw_frame":"{\"market\":\"0x779291bef19b6709f61e9764a954aafe9ffae488d50ae674aabdcb4f248006d5\", \"price_changes\":[{\"asset_id\":\"8761897749749422724209054078244794145777693856614463256546737399611489089783\", \"price\":\"0.49\", \"size\":\"45\", \"side\":\"BUY\", \"hash\":\"85b9b99da0ac0fceda8659e711a47d4f7bdec405\", \"best_bid\":\"0.49\", \"best_ask\":\"0.5\"}, {\"asset_id\":\"14965588658799411272385430903075831224615961675357217884735713260981483529984\", \"price\":\"0.51\", \"size\":\"45\", \"side\":\"SELL\", \"hash\":\"736ecbe218f075e12f29fecbc73aecaf95643ade\", \"best_bid\":\"0.5\", \"best_ask\":\"0.51\"}], \"timestamp\":\"1785207339892\", \"event_type\":\"price_change\"}","received_at":"2026-07-28T02:55:39.922377Z","schema_version":"clob-market-ws.price_change.v1","sequence":null,"server_hash":null,"server_timestamp":"1785207339892","session_id":"3e519d9098404c15b234d96025eb1a2b","source":"clob_market_ws"},"received_at":"2026-07-28T02:55:39.922377Z","record_id":"6d738bdafaf8b6c3c4170fe42e08dc5647667811cd9d04761e2cc12dc69c6c25","schema_fingerprint":"4aa3821a28b0b7c2400bc59aba4bcc0a76e971dadd19610d3ad38c768e124dc7","schema_version":"edge-lab-recorder.raw.v1","sequence":null,"source":"clob_market_ws"}
{"event_at":"2026-07-28T02:55:39.893000Z","event_fingerprint":"ce0db370a3cabc6a2e8dbdae7230ec53936561309c2f54f05d808a6d54d64b94","payload":{"connection_id":"a6b55582af5f430fb37ad02bf0922475","event_at":"2026-07-28T02:55:39.893000Z","event_type":"price_change","frame_hash":"e31b2e2a379c5514a008f90a2f89f6a8cb3bd00c28ac4b20b70f22c509720a42","frame_index":0,"kind":"data","monotonic_ns":309322943564416,"payload":{"event_type":"price_change","market":"0x779291bef19b6709f61e9764a954aafe9ffae488d50ae674aabdcb4f248006d5","price_changes":[{"asset_id":"14965588658799411272385430903075831224615961675357217884735713260981483529984","best_ask":"0.51","best_bid":"0.5","hash":"f42bedf2e7f432b32d23e61ce35401af28811e51","price":"0.47","side":"BUY","size":"119.67"},{"asset_id":"8761897749749422724209054078244794145777693856614463256546737399611489089783","best_ask":"0.5","best_bid":"0.49","hash":"74c7aaf02d548d01fbaa9b8b844abecda38cf23b","price":"0.53","side":"SELL","size":"119.67"}],"timestamp":"1785207339893"},"payload_hash":"62a7b6533a812911f078c01684c52f3f55ab890dccfef5c829a9764141193656","raw_frame":"{\"market\":\"0x779291bef19b6709f61e9764a954aafe9ffae488d50ae674aabdcb4f248006d5\", \"price_changes\":[{\"asset_id\":\"14965588658799411272385430903075831224615961675357217884735713260981483529984\", \"price\":\"0.47\", \"size\":\"119.67\", \"side\":\"BUY\", \"hash\":\"f42bedf2e7f432b32d23e61ce35401af28811e51\", \"best_bid\":\"0.5\", \"best_ask\":\"0.51\"}, {\"asset_id\":\"8761897749749422724209054078244794145777693856614463256546737399611489089783\", \"price\":\"0.53\", \"size\":\"119.67\", \"side\":\"SELL\", \"hash\":\"74c7aaf02d548d01fbaa9b8b844abecda38cf23b\", \"best_bid\":\"0.49\", \"best_ask\":\"0.5\"}], \"timestamp\":\"1785207339893\", \"event_type\":\"price_change\"}","received_at":"2026-07-28T02:55:39.927080Z","schema_version":"clob-market-ws.price_change.v1","sequence":null,"server_hash":null,"server_timestamp":"1785207339893","session_id":"3e519d9098404c15b234d96025eb1a2b","source":"clob_market_ws"},"received_at":"2026-07-28T02:55:39.927080Z","record_id":"20e615ed6dabd4a5d454632887ed66f25a7d265b132e7e4086b7f9fe645f096c","schema_fingerprint":"4aa3821a28b0b7c2400bc59aba4bcc0a76e971dadd19610d3ad38c768e124dc7","schema_version":"edge-lab-recorder.raw.v1","sequence":null,"source":"clob_market_ws"}
{"event_at":"2026-07-28T02:55:39.894000Z","event_fingerprint":"6eb66dee367f88a4fab4508106cfbd733763c7d459e740dd48ef83f3cac0c9a4","payload":{"connection_id":"a6b55582af5f430fb37ad02bf0922475","event_at":"2026-07-28T02:55:39.894000Z","event_type":"price_change","frame_hash":"659541fee14b6d678f21cb6019549577e6067be2190281bc7af0f1df41bf0aad","frame_index":0,"kind":"data","monotonic_ns":309322959172958,"payload":{"event_type":"price_change","market":"0x779291bef19b6709f61e9764a954aafe9ffae488d50ae674aabdcb4f248006d5","price_changes":[{"asset_id":"8761897749749422724209054078244794145777693856614463256546737399611489089783","best_ask":"0.5","best_bid":"0.49","hash":"fbb4bf5e0d24d0b5511df492f27d17acf7b7eb5c","price":"0.49","side":"BUY","size":"50"},{"asset_id":"14965588658799411272385430903075831224615961675357217884735713260981483529984","best_ask":"0.51","best_bid":"0.5","hash":"3061e6b750630e7e7ee8af7fb6d23726b72999fb","price":"0.51","side":"SELL","size":"50"}],"timestamp":"1785207339894"},"payload_hash":"0d5ee85f3881f07cb61c222956fa9b654e71f6a3d3e5cd14771a754bb3144eca","raw_frame":"{\"market\":\"0x779291bef19b6709f61e9764a954aafe9ffae488d50ae674aabdcb4f248006d5\", \"price_changes\":[{\"asset_id\":\"8761897749749422724209054078244794145777693856614463256546737399611489089783\", \"price\":\"0.49\", \"size\":\"50\", \"side\":\"BUY\", \"hash\":\"fbb4bf5e0d24d0b5511df492f27d17acf7b7eb5c\", \"best_bid\":\"0.49\", \"best_ask\":\"0.5\"}, {\"asset_id\":\"14965588658799411272385430903075831224615961675357217884735713260981483529984\", \"price\":\"0.51\", \"size\":\"50\", \"side\":\"SELL\", \"hash\":\"3061e6b750630e7e7ee8af7fb6d23726b72999fb\", \"best_bid\":\"0.5\", \"best_ask\":\"0.51\"}], \"timestamp\":\"1785207339894\", \"event_type\":\"price_change\"}","received_at":"2026-07-28T02:55:39.942684Z","schema_version":"clob-market-ws.price_change.v1","sequence":null,"server_hash":null,"server_timestamp":"1785207339894","session_id":"3e519d9098404c15b234d96025eb1a2b","source":"clob_market_ws"},"received_at":"2026-07-28T02:55:39.942684Z","record_id":"0fa3cb8b0bfc6dee673c5dd0da2b9c7a61f9ca51f252ea6b8cefc05aa0b65b6c","schema_fingerprint":"4aa3821a28b0b7c2400bc59aba4bcc0a76e971dadd19610d3ad38c768e124dc7","schema_version":"edge-lab-recorder.raw.v1","sequence":null,"source":"clob_market_ws"}
{"event_at":"2026-07-28T02:55:39.895000Z","event_fingerprint":"35c5a22feffe489404c34566763bcc9ba544996f97eba9a6036fe3cba679cee6","payload":{"connection_id":"a6b55582af5f430fb37ad02bf0922475","event_at":"2026-07-28T02:55:39.895000Z","event_type":"price_change","frame_hash":"e7e46864d43a7efe9ec73367bf152cb0fa1ebafe618475ea2ccc1e4894ce6083","frame_index":0,"kind":"data","monotonic_ns":309322963650875,"payload":{"event_type":"price_change","market":"0x779291bef19b6709f61e9764a954aafe9ffae488d50ae674aabdcb4f248006d5","price_changes":[{"asset_id":"14965588658799411272385430903075831224615961675357217884735713260981483529984","best_ask":"0.51","best_bid":"0.5","hash":"1f0c07762709d7ca7aced1279d08949d37adde59","price":"0.47","side":"BUY","size":"124.67"},{"asset_id":"8761897749749422724209054078244794145777693856614463256546737399611489089783","best_ask":"0.5","best_bid":"0.49","hash":"f53b4eab2e3d56ee4f160a375bb0daac00f452da","price":"0.53","side":"SELL","size":"124.67"}],"timestamp":"1785207339895"},"payload_hash":"49525d50bfbbffa6054612daf47a5cee83ef1e7a1e5494c8ec73523bc5f3bb07","raw_frame":"{\"market\":\"0x779291bef19b6709f61e9764a954aafe9ffae488d50ae674aabdcb4f248006d5\", \"price_changes\":[{\"asset_id\":\"14965588658799411272385430903075831224615961675357217884735713260981483529984\", \"price\":\"0.47\", \"size\":\"124.67\", \"side\":\"BUY\", \"hash\":\"1f0c07762709d7ca7aced1279d08949d37adde59\", \"best_bid\":\"0.5\", \"best_ask\":\"0.51\"}, {\"asset_id\":\"8761897749749422724209054078244794145777693856614463256546737399611489089783\", \"price\":\"0.53\", \"size\":\"124.67\", \"side\":\"SELL\", \"hash\":\"f53b4eab2e3d56ee4f160a375bb0daac00f452da\", \"best_bid\":\"0.49\", \"best_ask\":\"0.5\"}], \"timestamp\":\"1785207339895\", \"event_type\":\"price_change\"}","received_at":"2026-07-28T02:55:39.947165Z","schema_version":"clob-market-ws.price_change.v1","sequence":null,"server_hash":null,"server_timestamp":"1785207339895","session_id":"3e519d9098404c15b234d96025eb1a2b","source":"clob_market_ws"},"received_at":"2026-07-28T02:55:39.947165Z","record_id":"11ac338575e3182317b112a25790624e65255f4d34ff37b5d76671725b368fc7","schema_fingerprint":"4aa3821a28b0b7c2400bc59aba4bcc0a76e971dadd19610d3ad38c768e124dc7","schema_version":"edge-lab-recorder.raw.v1","sequence":null,"source":"clob_market_ws"}
{"event_at":"2026-07-28T02:55:39.896000Z","event_fingerprint":"1ed6421cc0299a8900f2528a49176cfa85517863bb1100d9fbc167e8af13133d","payload":{"connection_id":"a6b55582af5f430fb37ad02bf0922475","event_at":"2026-07-28T02:55:39.896000Z","event_type":"price_change","frame_hash":"f8654fee074696d1dadbeb3b638736ba0882b89565f9f6f0f3fa50716f0e6629","frame_index":0,"kind":"data","monotonic_ns":309322969795541,"payload":{"event_type":"price_change","market":"0x779291bef19b6709f61e9764a954aafe9ffae488d50ae674aabdcb4f248006d5","price_changes":[{"asset_id":"14965588658799411272385430903075831224615961675357217884735713260981483529984","best_ask":"0.51","best_bid":"0.5","hash":"6f9f234a3b4adabad0198ca3ebe7e6504da72a2e","price":"0.47","side":"BUY","size":"129.67"},{"asset_id":"8761897749749422724209054078244794145777693856614463256546737399611489089783","best_ask":"0.5","best_bid":"0.49","hash":"3a37eb8878d7c2e452224dde506b8d1b99325784","price":"0.53","side":"SELL","size":"129.67"}],"timestamp":"1785207339896"},"payload_hash":"d11aa91bd3453866de0c5623489cc9f68f8a3462f3b8905f64dad28398f27638","raw_frame":"{\"market\":\"0x779291bef19b6709f61e9764a954aafe9ffae488d50ae674aabdcb4f248006d5\", \"price_changes\":[{\"asset_id\":\"14965588658799411272385430903075831224615961675357217884735713260981483529984\", \"price\":\"0.47\", \"size\":\"129.67\", \"side\":\"BUY\", \"hash\":\"6f9f234a3b4adabad0198ca3ebe7e6504da72a2e\", \"best_bid\":\"0.5\", \"best_ask\":\"0.51\"}, {\"asset_id\":\"8761897749749422724209054078244794145777693856614463256546737399611489089783\", \"price\":\"0.53\", \"size\":\"129.67\", \"side\":\"SELL\", \"hash\":\"3a37eb8878d7c2e452224dde506b8d1b99325784\", \"best_bid\":\"0.49\", \"best_ask\":\"0.5\"}], \"timestamp\":\"1785207339896\", \"event_type\":\"price_change\"}","received_at":"2026-07-28T02:55:39.953310Z","schema_version":"clob-market-ws.price_change.v1","sequence":null,"server_hash":null,"server_timestamp":"1785207339896","session_id":"3e519d9098404c15b234d96025eb1a2b","source":"clob_market_ws"},"received_at":"2026-07-28T02:55:39.953310Z","record_id":"fb754038a0aa2ad21596ae52e3b27287614cb2dd0f4e39a49b3f1dc52dadd0b2","schema_fingerprint":"4aa3821a28b0b7c2400bc59aba4bcc0a76e971dadd19610d3ad38c768e124dc7","schema_version":"edge-lab-recorder.raw.v1","sequence":null,"source":"clob_market_ws"}
{"event_at":"2026-07-28T02:55:39.897000Z","event_fingerprint":"f48ae4642ec0b5c443865b1ff4969320f0ca8cb6fa72dfb25ad682646a28dc8c","payload":{"connection_id":"a6b55582af5f430fb37ad02bf0922475","event_at":"2026-07-28T02:55:39.897000Z","event_type":"price_change","frame_hash":"f03e89b8cdce57c7215bc4f975fe7e7a608e8e1a278375d8df7f0af498b714b0","frame_index":0,"kind":"data","monotonic_ns":309322973306625,"payload":{"event_type":"price_change","market":"0x779291bef19b6709f61e9764a954aafe9ffae488d50ae674aabdcb4f248006d5","price_changes":[{"asset_id":"14965588658799411272385430903075831224615961675357217884735713260981483529984","best_ask":"0.51","best_bid":"0.5","hash":"3acf8d4037e2a65c99429b6d65fa499c5a835d1c","price":"0.47","side":"BUY","size":"134.67"},{"asset_id":"8761897749749422724209054078244794145777693856614463256546737399611489089783","best_ask":"0.5","best_bid":"0.49","hash":"b44e2f0b496a41f2fd65510258a0a9ae16f135dd","price":"0.53","side":"SELL","size":"134.67"}],"timestamp":"1785207339897"},"payload_hash":"5c7a8fb35618f8149ca00fb03ac2f3917af2839495c4695fc88f31ba5e6f8ac1","raw_frame":"{\"market\":\"0x779291bef19b6709f61e9764a954aafe9ffae488d50ae674aabdcb4f248006d5\", \"price_changes\":[{\"asset_id\":\"14965588658799411272385430903075831224615961675357217884735713260981483529984\", \"price\":\"0.47\", \"size\":\"134.67\", \"side\":\"BUY\", \"hash\":\"3acf8d4037e2a65c99429b6d65fa499c5a835d1c\", \"best_bid\":\"0.5\", \"best_ask\":\"0.51\"}, {\"asset_id\":\"8761897749749422724209054078244794145777693856614463256546737399611489089783\", \"price\":\"0.53\", \"size\":\"134.67\", \"side\":\"SELL\", \"hash\":\"b44e2f0b496a41f2fd65510258a0a9ae16f135dd\", \"best_bid\":\"0.49\", \"best_ask\":\"0.5\"}], \"timestamp\":\"1785207339897\", \"event_type\":\"price_change\"}","received_at":"2026-07-28T02:55:39.956827Z","schema_version":"clob-market-ws.price_change.v1","sequence":null,"server_hash":null,"server_timestamp":"1785207339897","session_id":"3e519d9098404c15b234d96025eb1a2b","source":"clob_market_ws"},"received_at":"2026-07-28T02:55:39.956827Z","record_id":"8235d57cdb513a730598a6b778917c96810a81110b55783f87c05c29682a6453","schema_fingerprint":"4aa3821a28b0b7c2400bc59aba4bcc0a76e971dadd19610d3ad38c768e124dc7","schema_version":"edge-lab-recorder.raw.v1","sequence":null,"source":"clob_market_ws"}
{"event_at":"2026-07-28T02:55:39.898000Z","event_fingerprint":"395bfbeea63eb72fe5ce8553538437caca46bc58bc980404e4501401289c46e0","payload":{"connection_id":"a6b55582af5f430fb37ad02bf0922475","event_at":"2026-07-28T02:55:39.898000Z","event_type":"price_change","frame_hash":"1517b6f91a7ead8393850c33753bb872568f582ded5fc79e790fd0df0fdf7f32","frame_index":0,"kind":"data","monotonic_ns":309322976813500,"payload":{"event_type":"price_change","market":"0x779291bef19b6709f61e9764a954aafe9ffae488d50ae674aabdcb4f248006d5","price_changes":[{"asset_id":"14965588658799411272385430903075831224615961675357217884735713260981483529984","best_ask":"0.51","best_bid":"0.5","hash":"1db2d7b12812dfc7935a5bf38a5fc661f2970bbb","price":"0.47","side":"BUY","size":"139.67"},{"asset_id":"8761897749749422724209054078244794145777693856614463256546737399611489089783","best_ask":"0.5","best_bid":"0.49","hash":"c0b4079befde49fa5018dcc043d0bb938e5b5fed","price":"0.53","side":"SELL","size":"139.67"}],"timestamp":"1785207339898"},"payload_hash":"c6f5bac8c12f8b9dc4f851591319f6bf7548d80d192c01c9e1d3f113f0bfae6e","raw_frame":"{\"market\":\"0x779291bef19b6709f61e9764a954aafe9ffae488d50ae674aabdcb4f248006d5\", \"price_changes\":[{\"asset_id\":\"14965588658799411272385430903075831224615961675357217884735713260981483529984\", \"price\":\"0.47\", \"size\":\"139.67\", \"side\":\"BUY\", \"hash\":\"1db2d7b12812dfc7935a5bf38a5fc661f2970bbb\", \"best_bid\":\"0.5\", \"best_ask\":\"0.51\"}, {\"asset_id\":\"8761897749749422724209054078244794145777693856614463256546737399611489089783\", \"price\":\"0.53\", \"size\":\"139.67\", \"side\":\"SELL\", \"hash\":\"c0b4079befde49fa5018dcc043d0bb938e5b5fed\", \"best_bid\":\"0.49\", \"best_ask\":\"0.5\"}], \"timestamp\":\"1785207339898\", \"event_type\":\"price_change\"}","received_at":"2026-07-28T02:55:39.960328Z","schema_version":"clob-market-ws.price_change.v1","sequence":null,"server_hash":null,"server_timestamp":"1785207339898","session_id":"3e519d9098404c15b234d96025eb1a2b","source":"clob_market_ws"},"received_at":"2026-07-28T02:55:39.960328Z","record_id":"d443dfed6a4907d8a29d0c7b635da3fabc0b1d793dd1dd073efc55ce348eb384","schema_fingerprint":"4aa3821a28b0b7c2400bc59aba4bcc0a76e971dadd19610d3ad38c768e124dc7","schema_version":"edge-lab-recorder.raw.v1","sequence":null,"source":"clob_market_ws"}
{"event_at":"2026-07-28T02:55:39.898000Z","event_fingerprint":"bf541a7ad2616e0676e93168605e9a1faf3e18f2a8598597e51da44492500ffc","payload":{"connection_id":"a6b55582af5f430fb37ad02bf0922475","event_at":"2026-07-28T02:55:39.898000Z","event_type":"price_change","frame_hash":"fadd5e0739b8e695403b82e9bdd63f32fc0db624964c314dafa01061cd97d698","frame_index":0,"kind":"data","monotonic_ns":309322981384125,"payload":{"event_type":"price_change","market":"0x779291bef19b6709f61e9764a954aafe9ffae488d50ae674aabdcb4f248006d5","price_changes":[{"asset_id":"14965588658799411272385430903075831224615961675357217884735713260981483529984","best_ask":"0.51","best_bid":"0.5","hash":"631c12fbf95b34f267320a2ada49ffa2a4694e94","price":"0.47","side":"BUY","size":"144.67"},{"asset_id":"8761897749749422724209054078244794145777693856614463256546737399611489089783","best_ask":"0.5","best_bid":"0.49","hash":"ba6e905317b1cf6a6df6a94115465ee102ede44d","price":"0.53","side":"SELL","size":"144.67"}],"timestamp":"1785207339898"},"payload_hash":"a46f77efcbe5c81d002bd1c8d00cb9d589d7b60f5a35026dc18b52bed75dc967","raw_frame":"{\"market\":\"0x779291bef19b6709f61e9764a954aafe9ffae488d50ae674aabdcb4f248006d5\", \"price_changes\":[{\"asset_id\":\"14965588658799411272385430903075831224615961675357217884735713260981483529984\", \"price\":\"0.47\", \"size\":\"144.67\", \"side\":\"BUY\", \"hash\":\"631c12fbf95b34f267320a2ada49ffa2a4694e94\", \"best_bid\":\"0.5\", \"best_ask\":\"0.51\"}, {\"asset_id\":\"8761897749749422724209054078244794145777693856614463256546737399611489089783\", \"price\":\"0.53\", \"size\":\"144.67\", \"side\":\"SELL\", \"hash\":\"ba6e905317b1cf6a6df6a94115465ee102ede44d\", \"best_bid\":\"0.49\", \"best_ask\":\"0.5\"}], \"timestamp\":\"1785207339898\", \"event_type\":\"price_change\"}","received_at":"2026-07-28T02:55:39.964899Z","schema_version":"clob-market-ws.price_change.v1","sequence":null,"server_hash":null,"server_timestamp":"1785207339898","session_id":"3e519d9098404c15b234d96025eb1a2b","source":"clob_market_ws"},"received_at":"2026-07-28T02:55:39.964899Z","record_id":"4e5088cc998b1baeadd1b89eb02ba2f592cd753a5d6c8af0213329db5cee52b5","schema_fingerprint":"4aa3821a28b0b7c2400bc59aba4bcc0a76e971dadd19610d3ad38c768e124dc7","schema_version":"edge-lab-recorder.raw.v1","sequence":null,"source":"clob_market_ws"}
{"event_at":"2026-07-28T02:55:39.899000Z","event_fingerprint":"cd5113995e4e0deb11f256153f44d344eb95efa84f0e3510a659cb77bb2dc262","payload":{"connection_id":"a6b55582af5f430fb37ad02bf0922475","event_at":"2026-07-28T02:55:39.899000Z","event_type":"price_change","frame_hash":"ad27d44ea3c9799455899ebb74141b6620bec95c8a47987e7755473dceff4d3f","frame_index":0,"kind":"data","monotonic_ns":309322986599791,"payload":{"event_type":"price_change","market":"0x779291bef19b6709f61e9764a954aafe9ffae488d50ae674aabdcb4f248006d5","price_changes":[{"asset_id":"14965588658799411272385430903075831224615961675357217884735713260981483529984","best_ask":"0.51","best_bid":"0.5","hash":"7dce878b78e3f37b23f01acb9c1e2ce80a447071","price":"0.47","side":"BUY","size":"149.67"},{"asset_id":"8761897749749422724209054078244794145777693856614463256546737399611489089783","best_ask":"0.5","best_bid":"0.49","hash":"b8935ddc1887c234aab502fbeaf43a5b00432517","price":"0.53","side":"SELL","size":"149.67"}],"timestamp":"1785207339899"},"payload_hash":"184a242b181552fe4d567a0375c32c7cc7046acac9121b46022f3136fd9c037c","raw_frame":"{\"market\":\"0x779291bef19b6709f61e9764a954aafe9ffae488d50ae674aabdcb4f248006d5\", \"price_changes\":[{\"asset_id\":\"14965588658799411272385430903075831224615961675357217884735713260981483529984\", \"price\":\"0.47\", \"size\":\"149.67\", \"side\":\"BUY\", \"hash\":\"7dce878b78e3f37b23f01acb9c1e2ce80a447071\", \"best_bid\":\"0.5\", \"best_ask\":\"0.51\"}, {\"asset_id\":\"8761897749749422724209054078244794145777693856614463256546737399611489089783\", \"price\":\"0.53\", \"size\":\"149.67\", \"side\":\"SELL\", \"hash\":\"b8935ddc1887c234aab502fbeaf43a5b00432517\", \"best_bid\":\"0.49\", \"best_ask\":\"0.5\"}], \"timestamp\":\"1785207339899\", \"event_type\":\"price_change\"}","received_at":"2026-07-28T02:55:39.970115Z","schema_version":"clob-market-ws.price_change.v1","sequence":null,"server_hash":null,"server_timestamp":"1785207339899","session_id":"3e519d9098404c15b234d96025eb1a2b","source":"clob_market_ws"},"received_at":"2026-07-28T02:55:39.970115Z","record_id":"64cf8381b2c2d8533ae93b135cde1169807911b944e3811bef52a0886bbb32c2","schema_fingerprint":"4aa3821a28b0b7c2400bc59aba4bcc0a76e971dadd19610d3ad38c768e124dc7","schema_version":"edge-lab-recorder.raw.v1","sequence":null,"source":"clob_market_ws"}
{"event_at":"2026-07-28T02:55:39.900000Z","event_fingerprint":"ed206d81dc03747e045cf7aec0febaee901ccaf23edb159fa20b0a0234b95afe","payload":{"connection_id":"a6b55582af5f430fb37ad02bf0922475","event_at":"2026-07-28T02:55:39.900000Z","event_type":"price_change","frame_hash":"4a058c28ac74d33e77fd018c272fd9719dcf5f40ed1313cc82da29b33a3c3aa6","frame_index":0,"kind":"data","monotonic_ns":309322991229833,"payload":{"event_type":"price_change","market":"0x779291bef19b6709f61e9764a954aafe9ffae488d50ae674aabdcb4f248006d5","price_changes":[{"asset_id":"14965588658799411272385430903075831224615961675357217884735713260981483529984","best_ask":"0.51","best_bid":"0.5","hash":"1e26635657458bacbac3d478fc606e7d1680336a","price":"0.47","side":"BUY","size":"154.67"},{"asset_id":"8761897749749422724209054078244794145777693856614463256546737399611489089783","best_ask":"0.5","best_bid":"0.49","hash":"86ed0f25745d6aa1a361127233a4c177e63eb053","price":"0.53","side":"SELL","size":"154.67"}],"timestamp":"1785207339900"},"payload_hash":"f22ba0cfe8e786fc1ae788e1975b770cd8450e7dbebcf6a1a5dde47926da31d0","raw_frame":"{\"market\":\"0x779291bef19b6709f61e9764a954aafe9ffae488d50ae674aabdcb4f248006d5\", \"price_changes\":[{\"asset_id\":\"14965588658799411272385430903075831224615961675357217884735713260981483529984\", \"price\":\"0.47\", \"size\":\"154.67\", \"side\":\"BUY\", \"hash\":\"1e26635657458bacbac3d478fc606e7d1680336a\", \"best_bid\":\"0.5\", \"best_ask\":\"0.51\"}, {\"asset_id\":\"8761897749749422724209054078244794145777693856614463256546737399611489089783\", \"price\":\"0.53\", \"size\":\"154.67\", \"side\":\"SELL\", \"hash\":\"86ed0f25745d6aa1a361127233a4c177e63eb053\", \"best_bid\":\"0.49\", \"best_ask\":\"0.5\"}], \"timestamp\":\"1785207339900\", \"event_type\":\"price_change\"}","received_at":"2026-07-28T02:55:39.974744Z","schema_version":"clob-market-ws.price_change.v1","sequence":null,"server_hash":null,"server_timestamp":"1785207339900","session_id":"3e519d9098404c15b234d96025eb1a2b","source":"clob_market_ws"},"received_at":"2026-07-28T02:55:39.974744Z","record_id":"7953f019658c6d236f716c2fa6eab6db50b39478daafa009e8aab37621378a1c","schema_fingerprint":"4aa3821a28b0b7c2400bc59aba4bcc0a76e971dadd19610d3ad38c768e124dc7","schema_version":"edge-lab-recorder.raw.v1","sequence":null,"source":"clob_market_ws"}
{"event_at":"2026-07-28T02:55:39.901000Z","event_fingerprint":"9ff697a1c2e35c7cea62f67e40fa69f69276cb1ac6cc11d5e265c5175f749711","payload":{"connection_id":"a6b55582af5f430fb37ad02bf0922475","event_at":"2026-07-28T02:55:39.901000Z","event_type":"price_change","frame_hash":"57f11f6e270c62aab4c2c1dd989a1366af93d385ae1c1768a2bcf197d558d4bf","frame_index":0,"kind":"data","monotonic_ns":309322995824875,"payload":{"event_type":"price_change","market":"0x779291bef19b6709f61e9764a954aafe9ffae488d50ae674aabdcb4f248006d5","price_changes":[{"asset_id":"14965588658799411272385430903075831224615961675357217884735713260981483529984","best_ask":"0.51","best_bid":"0.5","hash":"bac4b8d055e3a1831f30bbf45309bca2694240be","price":"0.47","side":"BUY","size":"159.67"},{"asset_id":"8761897749749422724209054078244794145777693856614463256546737399611489089783","best_ask":"0.5","best_bid":"0.49","hash":"35c5ad82ca242e49f7f40104b84b2a45de67e2d0","price":"0.53","side":"SELL","size":"159.67"}],"timestamp":"1785207339901"},"payload_hash":"c5888a5a57dc59299615d246fb7f8590c83a2883a51a2e5393d26fff97e65e8c","raw_frame":"{\"market\":\"0x779291bef19b6709f61e9764a954aafe9ffae488d50ae674aabdcb4f248006d5\", \"price_changes\":[{\"asset_id\":\"14965588658799411272385430903075831224615961675357217884735713260981483529984\", \"price\":\"0.47\", \"size\":\"159.67\", \"side\":\"BUY\", \"hash\":\"bac4b8d055e3a1831f30bbf45309bca2694240be\", \"best_bid\":\"0.5\", \"best_ask\":\"0.51\"}, {\"asset_id\":\"8761897749749422724209054078244794145777693856614463256546737399611489089783\", \"price\":\"0.53\", \"size\":\"159.67\", \"side\":\"SELL\", \"hash\":\"35c5ad82ca242e49f7f40104b84b2a45de67e2d0\", \"best_bid\":\"0.49\", \"best_ask\":\"0.5\"}], \"timestamp\":\"1785207339901\", \"event_type\":\"price_change\"}","received_at":"2026-07-28T02:55:39.979340Z","schema_version":"clob-market-ws.price_change.v1","sequence":null,"server_hash":null,"server_timestamp":"1785207339901","session_id":"3e519d9098404c15b234d96025eb1a2b","source":"clob_market_ws"},"received_at":"2026-07-28T02:55:39.979340Z","record_id":"fe18633f91c6413f6c9df74959726fe01ab173038b41cc7f3003729c0de56267","schema_fingerprint":"4aa3821a28b0b7c2400bc59aba4bcc0a76e971dadd19610d3ad38c768e124dc7","schema_version":"edge-lab-recorder.raw.v1","sequence":null,"source":"clob_market_ws"}
{"event_at":"2026-07-28T02:55:39.901000Z","event_fingerprint":"6a816f6b6412017f8b9999c157b53c12f317a76c9bea2d07d4875c54b26b1405","payload":{"connection_id":"a6b55582af5f430fb37ad02bf0922475","event_at":"2026-07-28T02:55:39.901000Z","event_type":"price_change","frame_hash":"2569bf7d881aac86988389bfee4fb1fe08f34358f73385960cb0921f9c5386ec","frame_index":0,"kind":"data","monotonic_ns":309323002446000,"payload":{"event_type":"price_change","market":"0x779291bef19b6709f61e9764a954aafe9ffae488d50ae674aabdcb4f248006d5","price_changes":[{"asset_id":"14965588658799411272385430903075831224615961675357217884735713260981483529984","best_ask":"0.51","best_bid":"0.5","hash":"da30d468da1a20e4cc901360b408c6cf98b175e1","price":"0.47","side":"BUY","size":"164.67"},{"asset_id":"8761897749749422724209054078244794145777693856614463256546737399611489089783","best_ask":"0.5","best_bid":"0.49","hash":"4f9550a8127a691986ad54f48e8048aaef8bd346","price":"0.53","side":"SELL","size":"164.67"}],"timestamp":"1785207339901"},"payload_hash":"f4f96a5b1c50dceccb6e27cf1a69691a0117e889034ae00c8fb6ba19f1a1e994","raw_frame":"{\"market\":\"0x779291bef19b6709f61e9764a954aafe9ffae488d50ae674aabdcb4f248006d5\", \"price_changes\":[{\"asset_id\":\"14965588658799411272385430903075831224615961675357217884735713260981483529984\", \"price\":\"0.47\", \"size\":\"164.67\", \"side\":\"BUY\", \"hash\":\"da30d468da1a20e4cc901360b408c6cf98b175e1\", \"best_bid\":\"0.5\", \"best_ask\":\"0.51\"}, {\"asset_id\":\"8761897749749422724209054078244794145777693856614463256546737399611489089783\", \"price\":\"0.53\", \"size\":\"164.67\", \"side\":\"SELL\", \"hash\":\"4f9550a8127a691986ad54f48e8048aaef8bd346\", \"best_bid\":\"0.49\", \"best_ask\":\"0.5\"}], \"timestamp\":\"1785207339901\", \"event_type\":\"price_change\"}","received_at":"2026-07-28T02:55:39.985959Z","schema_version":"clob-market-ws.price_change.v1","sequence":null,"server_hash":null,"server_timestamp":"1785207339901","session_id":"3e519d9098404c15b234d96025eb1a2b","source":"clob_market_ws"},"received_at":"2026-07-28T02:55:39.985959Z","record_id":"7707ff7ccbc65eba84952708ed1883ad75dee6a1262821ce15ad1ada01a6a4ba","schema_fingerprint":"4aa3821a28b0b7c2400bc59aba4bcc0a76e971dadd19610d3ad38c768e124dc7","schema_version":"edge-lab-recorder.raw.v1","sequence":null,"source":"clob_market_ws"}
{"event_at":"2026-07-28T02:55:39.911000Z","event_fingerprint":"59b7cb8d14b8e98fb63d6fce17c8cbd7cbb16d03eedbaa30b7200229bc4bf3af","payload":{"connection_id":"a6b55582af5f430fb37ad02bf0922475","event_at":"2026-07-28T02:55:39.911000Z","event_type":"price_change","frame_hash":"5df6833327683fdffa2770dbc655f97de891be979f7ce583bc92d831a5d6b129","frame_index":0,"kind":"data","monotonic_ns":309323012803958,"payload":{"event_type":"price_change","market":"0x779291bef19b6709f61e9764a954aafe9ffae488d50ae674aabdcb4f248006d5","price_changes":[{"asset_id":"14965588658799411272385430903075831224615961675357217884735713260981483529984","best_ask":"0.51","best_bid":"0.5","hash":"3667be7a653a17cb40561f62ea0790e213ab2f1a","price":"0.47","side":"BUY","size":"169.67"},{"asset_id":"8761897749749422724209054078244794145777693856614463256546737399611489089783","best_ask":"0.5","best_bid":"0.49","hash":"7e86d5288b65bbb5f5b63d62a5331a0f32677890","price":"0.53","side":"SELL","size":"169.67"}],"timestamp":"1785207339911"},"payload_hash":"ef3c70d4b063f06cf7697d131e65340517471091619e4126976f22cb103dcee0","raw_frame":"{\"market\":\"0x779291bef19b6709f61e9764a954aafe9ffae488d50ae674aabdcb4f248006d5\", \"price_changes\":[{\"asset_id\":\"14965588658799411272385430903075831224615961675357217884735713260981483529984\", \"price\":\"0.47\", \"size\":\"169.67\", \"side\":\"BUY\", \"hash\":\"3667be7a653a17cb40561f62ea0790e213ab2f1a\", \"best_bid\":\"0.5\", \"best_ask\":\"0.51\"}, {\"asset_id\":\"8761897749749422724209054078244794145777693856614463256546737399611489089783\", \"price\":\"0.53\", \"size\":\"169.67\", \"side\":\"SELL\", \"hash\":\"7e86d5288b65bbb5f5b63d62a5331a0f32677890\", \"best_bid\":\"0.49\", \"best_ask\":\"0.5\"}], \"timestamp\":\"1785207339911\", \"event_type\":\"price_change\"}","received_at":"2026-07-28T02:55:39.996319Z","schema_version":"clob-market-ws.price_change.v1","sequence":null,"server_hash":null,"server_timestamp":"1785207339911","session_id":"3e519d9098404c15b234d96025eb1a2b","source":"clob_market_ws"},"received_at":"2026-07-28T02:55:39.996319Z","record_id":"b483d56068a94b2cc211a5ca16594f4894f98fce3e1e2608b32ac29055efe9bc","schema_fingerprint":"4aa3821a28b0b7c2400bc59aba4bcc0a76e971dadd19610d3ad38c768e124dc7","schema_version":"edge-lab-recorder.raw.v1","sequence":null,"source":"clob_market_ws"}
{"event_at":"2026-07-28T02:55:39.912000Z","event_fingerprint":"8c82c57af82f98c34bf7fd5c4be6252a1c7b1c31f2e8ad30c9ac9496ecf4cee0","payload":{"connection_id":"a6b55582af5f430fb37ad02bf0922475","event_at":"2026-07-28T02:55:39.912000Z","event_type":"price_change","frame_hash":"3a1b6d175d0a6eaa81ac61efd8774c77b6e6a1e73d8a37d8d5e79a91d420ebde","frame_index":0,"kind":"data","monotonic_ns":309323123060875,"payload":{"event_type":"price_change","market":"0x779291bef19b6709f61e9764a954aafe9ffae488d50ae674aabdcb4f248006d5","price_changes":[{"asset_id":"14965588658799411272385430903075831224615961675357217884735713260981483529984","best_ask":"0.51","best_bid":"0.5","hash":"8693e466b68fc676b4789c7ccf2d689e82427259","price":"0.47","side":"BUY","size":"174.67"},{"asset_id":"8761897749749422724209054078244794145777693856614463256546737399611489089783","best_ask":"0.5","best_bid":"0.49","hash":"a9d00cf3f838a9d8c62c51c72b3c80124145d834","price":"0.53","side":"SELL","size":"174.67"}],"timestamp":"1785207339912"},"payload_hash":"48d914be890731d97aebb823a9513de383c6936c200b2c51aa9523f14c24bce5","raw_frame":"{\"market\":\"0x779291bef19b6709f61e9764a954aafe9ffae488d50ae674aabdcb4f248006d5\", \"price_changes\":[{\"asset_id\":\"14965588658799411272385430903075831224615961675357217884735713260981483529984\", \"price\":\"0.47\", \"size\":\"174.67\", \"side\":\"BUY\", \"hash\":\"8693e466b68fc676b4789c7ccf2d689e82427259\", \"best_bid\":\"0.5\", \"best_ask\":\"0.51\"}, {\"asset_id\":\"8761897749749422724209054078244794145777693856614463256546737399611489089783\", \"price\":\"0.53\", \"size\":\"174.67\", \"side\":\"SELL\", \"hash\":\"a9d00cf3f838a9d8c62c51c72b3c80124145d834\", \"best_bid\":\"0.49\", \"best_ask\":\"0.5\"}], \"timestamp\":\"1785207339912\", \"event_type\":\"price_change\"}","received_at":"2026-07-28T02:55:40.106573Z","schema_version":"clob-market-ws.price_change.v1","sequence":null,"server_hash":null,"server_timestamp":"1785207339912","session_id":"3e519d9098404c15b234d96025eb1a2b","source":"clob_market_ws"},"received_at":"2026-07-28T02:55:40.106573Z","record_id":"8f778ad4eb7c87dfa1e4048dbc9ed55838b62bf6fd8558660c4dcd7c70c4bd61","schema_fingerprint":"4aa3821a28b0b7c2400bc59aba4bcc0a76e971dadd19610d3ad38c768e124dc7","schema_version":"edge-lab-recorder.raw.v1","sequence":null,"source":"clob_market_ws"}
{"event_at":"2026-07-28T02:55:39.913000Z","event_fingerprint":"dbe618576d53566d96fbcc546ed44aa93dacbc976ce13a79be687509e3075775","payload":{"connection_id":"a6b55582af5f430fb37ad02bf0922475","event_at":"2026-07-28T02:55:39.913000Z","event_type":"price_change","frame_hash":"2abc271dbbf9fbd90f27c05610738e49af50c3570eb77052ff198dba13f96e9f","frame_index":0,"kind":"data","monotonic_ns":309323127657333,"payload":{"event_type":"price_change","market":"0x779291bef19b6709f61e9764a954aafe9ffae488d50ae674aabdcb4f248006d5","price_changes":[{"asset_id":"14965588658799411272385430903075831224615961675357217884735713260981483529984","best_ask":"0.51","best_bid":"0.5","hash":"9af25054c4f2fbfb65edd91cd75e9af7ea654ec0","price":"0.47","side":"BUY","size":"179.67"},{"asset_id":"8761897749749422724209054078244794145777693856614463256546737399611489089783","best_ask":"0.5","best_bid":"0.49","hash":"8263ef8c66a083e447c93aad935ef2f2c83bffff","price":"0.53","side":"SELL","size":"179.67"}],"timestamp":"1785207339913"},"payload_hash":"dfb4ca22a962551844f7553fea3c53530be2fc26ee2a11f005a31f4e1e22f1a1","raw_frame":"{\"market\":\"0x779291bef19b6709f61e9764a954aafe9ffae488d50ae674aabdcb4f248006d5\", \"price_changes\":[{\"asset_id\":\"14965588658799411272385430903075831224615961675357217884735713260981483529984\", \"price\":\"0.47\", \"size\":\"179.67\", \"side\":\"BUY\", \"hash\":\"9af25054c4f2fbfb65edd91cd75e9af7ea654ec0\", \"best_bid\":\"0.5\", \"best_ask\":\"0.51\"}, {\"asset_id\":\"8761897749749422724209054078244794145777693856614463256546737399611489089783\", \"price\":\"0.53\", \"size\":\"179.67\", \"side\":\"SELL\", \"hash\":\"8263ef8c66a083e447c93aad935ef2f2c83bffff\", \"best_bid\":\"0.49\", \"best_ask\":\"0.5\"}], \"timestamp\":\"1785207339913\", \"event_type\":\"price_change\"}","received_at":"2026-07-28T02:55:40.111169Z","schema_version":"clob-market-ws.price_change.v1","sequence":null,"server_hash":null,"server_timestamp":"1785207339913","session_id":"3e519d9098404c15b234d96025eb1a2b","source":"clob_market_ws"},"received_at":"2026-07-28T02:55:40.111169Z","record_id":"bdb8cabfe2b12d903a83c61f1e34a5d7bb34353894a8d4bcf45a77b686adbbb4","schema_fingerprint":"4aa3821a28b0b7c2400bc59aba4bcc0a76e971dadd19610d3ad38c768e124dc7","schema_version":"edge-lab-recorder.raw.v1","sequence":null,"source":"clob_market_ws"}
{"event_at":"2026-07-28T02:55:39.915000Z","event_fingerprint":"ca37e62ff0cf968953945d8157aa2c4a7b93a366fbf3b2a72366d7108c534e7d","payload":{"connection_id":"a6b55582af5f430fb37ad02bf0922475","event_at":"2026-07-28T02:55:39.915000Z","event_type":"price_change","frame_hash":"862636c86da718a283fd92f4476bf581932c50a151d117f34ce290e1798ecbae","frame_index":0,"kind":"data","monotonic_ns":309323132006958,"payload":{"event_type":"price_change","market":"0x779291bef19b6709f61e9764a954aafe9ffae488d50ae674aabdcb4f248006d5","price_changes":[{"asset_id":"14965588658799411272385430903075831224615961675357217884735713260981483529984","best_ask":"0.51","best_bid":"0.5","hash":"c31cbb526da2869613632e9df331d798fc638aad","price":"0.47","side":"BUY","size":"184.67"},{"asset_id":"8761897749749422724209054078244794145777693856614463256546737399611489089783","best_ask":"0.5","best_bid":"0.49","hash":"9b8ad79646990db265088f6561eb1ea15688161c","price":"0.53","side":"SELL","size":"184.67"}],"timestamp":"1785207339915"},"payload_hash":"e0907154c6940d982f2a48a6e2bc63477a18df68ccb8a468464098d6a8d4a3ab","raw_frame":"{\"market\":\"0x779291bef19b6709f61e9764a954aafe9ffae488d50ae674aabdcb4f248006d5\", \"price_changes\":[{\"asset_id\":\"14965588658799411272385430903075831224615961675357217884735713260981483529984\", \"price\":\"0.47\", \"size\":\"184.67\", \"side\":\"BUY\", \"hash\":\"c31cbb526da2869613632e9df331d798fc638aad\", \"best_bid\":\"0.5\", \"best_ask\":\"0.51\"}, {\"asset_id\":\"8761897749749422724209054078244794145777693856614463256546737399611489089783\", \"price\":\"0.53\", \"size\":\"184.67\", \"side\":\"SELL\", \"hash\":\"9b8ad79646990db265088f6561eb1ea15688161c\", \"best_bid\":\"0.49\", \"best_ask\":\"0.5\"}], \"timestamp\":\"1785207339915\", \"event_type\":\"price_change\"}","received_at":"2026-07-28T02:55:40.115520Z","schema_version":"clob-market-ws.price_change.v1","sequence":null,"server_hash":null,"server_timestamp":"1785207339915","session_id":"3e519d9098404c15b234d96025eb1a2b","source":"clob_market_ws"},"received_at":"2026-07-28T02:55:40.115520Z","record_id":"c18cba00295d1a68802d75639da3d56aaa5ec35f36dcd3cdf243b86cbc92d128","schema_fingerprint":"4aa3821a28b0b7c2400bc59aba4bcc0a76e971dadd19610d3ad38c768e124dc7","schema_version":"edge-lab-recorder.raw.v1","sequence":null,"source":"clob_market_ws"}
{"event_at":"2026-07-28T02:55:39.915000Z","event_fingerprint":"0ba4051661f25b3665398c1ea06877b9bf06e926db7e1a2c1a8b0558a40c41bc","payload":{"connection_id":"a6b55582af5f430fb37ad02bf0922475","event_at":"2026-07-28T02:55:39.915000Z","event_type":"price_change","frame_hash":"61cbb08afc6af36633880964b4d11e428af2dd69644690ac1b871349c8e43c2c","frame_index":0,"kind":"data","monotonic_ns":309323136231416,"payload":{"event_type":"price_change","market":"0x779291bef19b6709f61e9764a954aafe9ffae488d50ae674aabdcb4f248006d5","price_changes":[{"asset_id":"14965588658799411272385430903075831224615961675357217884735713260981483529984","best_ask":"0.51","best_bid":"0.5","hash":"d9c724db5d5fd39e6ed37915f243b039323b16e3","price":"0.47","side":"BUY","size":"189.67"},{"asset_id":"8761897749749422724209054078244794145777693856614463256546737399611489089783","best_ask":"0.5","best_bid":"0.49","hash":"3503e3a21bddf4315ce984541e5a9727666d7411","price":"0.53","side":"SELL","size":"189.67"}],"timestamp":"1785207339915"},"payload_hash":"814920798f70eaf8ace4156ad357e4a18ac3063541c55175d34cbc81c59a934c","raw_frame":"{\"market\":\"0x779291bef19b6709f61e9764a954aafe9ffae488d50ae674aabdcb4f248006d5\", \"price_changes\":[{\"asset_id\":\"14965588658799411272385430903075831224615961675357217884735713260981483529984\", \"price\":\"0.47\", \"size\":\"189.67\", \"side\":\"BUY\", \"hash\":\"d9c724db5d5fd39e6ed37915f243b039323b16e3\", \"best_bid\":\"0.5\", \"best_ask\":\"0.51\"}, {\"asset_id\":\"8761897749749422724209054078244794145777693856614463256546737399611489089783\", \"price\":\"0.53\", \"size\":\"189.67\", \"side\":\"SELL\", \"hash\":\"3503e3a21bddf4315ce984541e5a9727666d7411\", \"best_bid\":\"0.49\", \"best_ask\":\"0.5\"}], \"timestamp\":\"1785207339915\", \"event_type\":\"price_change\"}","received_at":"2026-07-28T02:55:40.119746Z","schema_version":"clob-market-ws.price_change.v1","sequence":null,"server_hash":null,"server_timestamp":"1785207339915","session_id":"3e519d9098404c15b234d96025eb1a2b","source":"clob_market_ws"},"received_at":"2026-07-28T02:55:40.119746Z","record_id":"00d8e87246ca90aefb66c363f4c97b001b1141fc95bb7d839389e16ebf94a98d","schema_fingerprint":"4aa3821a28b0b7c2400bc59aba4bcc0a76e971dadd19610d3ad38c768e124dc7","schema_version":"edge-lab-recorder.raw.v1","sequence":null,"source":"clob_market_ws"}
{"event_at":"2026-07-28T02:55:39.916000Z","event_fingerprint":"d42603f3adf2c56291552eea064d280a2b683acc73bbfdd93452c1d26428c131","payload":{"connection_id":"a6b55582af5f430fb37ad02bf0922475","event_at":"2026-07-28T02:55:39.916000Z","event_type":"price_change","frame_hash":"fdd8323a39eb76a44b0e16b5fa769de1301b20268c5983fd613fc5d3cdb4b710","frame_index":0,"kind":"data","monotonic_ns":309323140579500,"payload":{"event_type":"price_change","market":"0x779291bef19b6709f61e9764a954aafe9ffae488d50ae674aabdcb4f248006d5","price_changes":[{"asset_id":"14965588658799411272385430903075831224615961675357217884735713260981483529984","best_ask":"0.51","best_bid":"0.5","hash":"13c87882dab37ac3fcf099b2400f0e9f23337df4","price":"0.47","side":"BUY","size":"194.67"},{"asset_id":"8761897749749422724209054078244794145777693856614463256546737399611489089783","best_ask":"0.5","best_bid":"0.49","hash":"ed80da31c7ff8821fc62ed42cfb58e796caa3fba","price":"0.53","side":"SELL","size":"194.67"}],"timestamp":"1785207339916"},"payload_hash":"01b6c78dbe29b33b7b1d3a7f78ab0c4a15b42a8d4019ed7e01fbfc557ee597ed","raw_frame":"{\"market\":\"0x779291bef19b6709f61e9764a954aafe9ffae488d50ae674aabdcb4f248006d5\", \"price_changes\":[{\"asset_id\":\"14965588658799411272385430903075831224615961675357217884735713260981483529984\", \"price\":\"0.47\", \"size\":\"194.67\", \"side\":\"BUY\", \"hash\":\"13c87882dab37ac3fcf099b2400f0e9f23337df4\", \"best_bid\":\"0.5\", \"best_ask\":\"0.51\"}, {\"asset_id\":\"8761897749749422724209054078244794145777693856614463256546737399611489089783\", \"price\":\"0.53\", \"size\":\"194.67\", \"side\":\"SELL\", \"hash\":\"ed80da31c7ff8821fc62ed42cfb58e796caa3fba\", \"best_bid\":\"0.49\", \"best_ask\":\"0.5\"}], \"timestamp\":\"1785207339916\", \"event_type\":\"price_change\"}","received_at":"2026-07-28T02:55:40.124093Z","schema_version":"clob-market-ws.price_change.v1","sequence":null,"server_hash":null,"server_timestamp":"1785207339916","session_id":"3e519d9098404c15b234d96025eb1a2b","source":"clob_market_ws"},"received_at":"2026-07-28T02:55:40.124093Z","record_id":"680d373b58f456ae32c19005e19dbe47ce0085b0af35c7c416703418beb75c1a","schema_fingerprint":"4aa3821a28b0b7c2400bc59aba4bcc0a76e971dadd19610d3ad38c768e124dc7","schema_version":"edge-lab-recorder.raw.v1","sequence":null,"source":"clob_market_ws"}
{"event_at":"2026-07-28T02:55:39.917000Z","event_fingerprint":"0b43991e71219c8d9b5c7810aada549b8ea311d00655587086efcdb5664ac201","payload":{"connection_id":"a6b55582af5f430fb37ad02bf0922475","event_at":"2026-07-28T02:55:39.917000Z","event_type":"price_change","frame_hash":"debfb9edad08950633d28cf5075593eda65a0cda1ecdc501de843da2d036506b","frame_index":0,"kind":"data","monotonic_ns":309323144883000,"payload":{"event_type":"price_change","market":"0x779291bef19b6709f61e9764a954aafe9ffae488d50ae674aabdcb4f248006d5","price_changes":[{"asset_id":"14965588658799411272385430903075831224615961675357217884735713260981483529984","best_ask":"0.51","best_bid":"0.5","hash":"38b39727006ce6f06daea24be307730e0f07cfee","price":"0.47","side":"BUY","size":"199.67"},{"asset_id":"8761897749749422724209054078244794145777693856614463256546737399611489089783","best_ask":"0.5","best_bid":"0.49","hash":"ba06411480539f3edf9ff16cc3ae2d2e0f2a1ca2","price":"0.53","side":"SELL","size":"199.67"}],"timestamp":"1785207339917"},"payload_hash":"bfb3baac0afab024f4a7511d917972603ad95ba50e714fb0d8a0965ff0729573","raw_frame":"{\"market\":\"0x779291bef19b6709f61e9764a954aafe9ffae488d50ae674aabdcb4f248006d5\", \"price_changes\":[{\"asset_id\":\"14965588658799411272385430903075831224615961675357217884735713260981483529984\", \"price\":\"0.47\", \"size\":\"199.67\", \"side\":\"BUY\", \"hash\":\"38b39727006ce6f06daea24be307730e0f07cfee\", \"best_bid\":\"0.5\", \"best_ask\":\"0.51\"}, {\"asset_id\":\"8761897749749422724209054078244794145777693856614463256546737399611489089783\", \"price\":\"0.53\", \"size\":\"199.67\", \"side\":\"SELL\", \"hash\":\"ba06411480539f3edf9ff16cc3ae2d2e0f2a1ca2\", \"best_bid\":\"0.49\", \"best_ask\":\"0.5\"}], \"timestamp\":\"1785207339917\", \"event_type\":\"price_change\"}","received_at":"2026-07-28T02:55:40.128397Z","schema_version":"clob-market-ws.price_change.v1","sequence":null,"server_hash":null,"server_timestamp":"1785207339917","session_id":"3e519d9098404c15b234d96025eb1a2b","source":"clob_market_ws"},"received_at":"2026-07-28T02:55:40.128397Z","record_id":"81df8203a126a91e516ac811dc700e9fb300361386e63aa7d565d97eeb00c0c3","schema_fingerprint":"4aa3821a28b0b7c2400bc59aba4bcc0a76e971dadd19610d3ad38c768e124dc7","schema_version":"edge-lab-recorder.raw.v1","sequence":null,"source":"clob_market_ws"}
{"event_at":"2026-07-28T02:55:39.918000Z","event_fingerprint":"51d2c0ca66ae3d06f4087baf10960dfb20950bf69f46cd82f14123be05fe1636","payload":{"connection_id":"a6b55582af5f430fb37ad02bf0922475","event_at":"2026-07-28T02:55:39.918000Z","event_type":"price_change","frame_hash":"fc77157c2cfacb15bb226eff0bf56fc720df5be50d017d91f394ba497a9718c5","frame_index":0,"kind":"data","monotonic_ns":309323149167333,"payload":{"event_type":"price_change","market":"0x779291bef19b6709f61e9764a954aafe9ffae488d50ae674aabdcb4f248006d5","price_changes":[{"asset_id":"14965588658799411272385430903075831224615961675357217884735713260981483529984","best_ask":"0.51","best_bid":"0.5","hash":"453a0775b1da9b4e2fa1842ff558252d8096201a","price":"0.47","side":"BUY","size":"204.67"},{"asset_id":"8761897749749422724209054078244794145777693856614463256546737399611489089783","best_ask":"0.5","best_bid":"0.49","hash":"3847d982725d9586bac94fe3c903a0e7f88a55eb","price":"0.53","side":"SELL","size":"204.67"}],"timestamp":"1785207339918"},"payload_hash":"115cc090bcc7bec3fe28e8fa74d824dcfc8d584e6627b4955d7b38abf96b7da9","raw_frame":"{\"market\":\"0x779291bef19b6709f61e9764a954aafe9ffae488d50ae674aabdcb4f248006d5\", \"price_changes\":[{\"asset_id\":\"14965588658799411272385430903075831224615961675357217884735713260981483529984\", \"price\":\"0.47\", \"size\":\"204.67\", \"side\":\"BUY\", \"hash\":\"453a0775b1da9b4e2fa1842ff558252d8096201a\", \"best_bid\":\"0.5\", \"best_ask\":\"0.51\"}, {\"asset_id\":\"8761897749749422724209054078244794145777693856614463256546737399611489089783\", \"price\":\"0.53\", \"size\":\"204.67\", \"side\":\"SELL\", \"hash\":\"3847d982725d9586bac94fe3c903a0e7f88a55eb\", \"best_bid\":\"0.49\", \"best_ask\":\"0.5\"}], \"timestamp\":\"1785207339918\", \"event_type\":\"price_change\"}","received_at":"2026-07-28T02:55:40.132681Z","schema_version":"clob-market-ws.price_change.v1","sequence":null,"server_hash":null,"server_timestamp":"1785207339918","session_id":"3e519d9098404c15b234d96025eb1a2b","source":"clob_market_ws"},"received_at":"2026-07-28T02:55:40.132681Z","record_id":"f4a724a01727b1ddb6656109a952a3365a62fc4daa8dc02cd16f59487a48f520","schema_fingerprint":"4aa3821a28b0b7c2400bc59aba4bcc0a76e971dadd19610d3ad38c768e124dc7","schema_version":"edge-lab-recorder.raw.v1","sequence":null,"source":"clob_market_ws"}
{"event_at":"2026-07-28T02:55:39.919000Z","event_fingerprint":"279fc63d32693e7f3a02473d5399cd2700fad766175452404be403c71079d556","payload":{"connection_id":"a6b55582af5f430fb37ad02bf0922475","event_at":"2026-07-28T02:55:39.919000Z","event_type":"price_change","frame_hash":"35d6e6f3136f61454b7e4e01d8d41a743f13f4332d8f7dbbb87188bac927a9a7","frame_index":0,"kind":"data","monotonic_ns":309323162658625,"payload":{"event_type":"price_change","market":"0x779291bef19b6709f61e9764a954aafe9ffae488d50ae674aabdcb4f248006d5","price_changes":[{"asset_id":"14965588658799411272385430903075831224615961675357217884735713260981483529984","best_ask":"0.51","best_bid":"0.5","hash":"580df536b9e1f113606a9a4a802b899be85439f5","price":"0.47","side":"BUY","size":"209.67"},{"asset_id":"8761897749749422724209054078244794145777693856614463256546737399611489089783","best_ask":"0.5","best_bid":"0.49","hash":"e7929063aada32f31da32eca6d532481b1c4852a","price":"0.53","side":"SELL","size":"209.67"}],"timestamp":"1785207339919"},"payload_hash":"155033c986d4e119c84626cb2aad507b11eb275afac471d030440531faa9c12f","raw_frame":"{\"market\":\"0x779291bef19b6709f61e9764a954aafe9ffae488d50ae674aabdcb4f248006d5\", \"price_changes\":[{\"asset_id\":\"14965588658799411272385430903075831224615961675357217884735713260981483529984\", \"price\":\"0.47\", \"size\":\"209.67\", \"side\":\"BUY\", \"hash\":\"580df536b9e1f113606a9a4a802b899be85439f5\", \"best_bid\":\"0.5\", \"best_ask\":\"0.51\"}, {\"asset_id\":\"8761897749749422724209054078244794145777693856614463256546737399611489089783\", \"price\":\"0.53\", \"size\":\"209.67\", \"side\":\"SELL\", \"hash\":\"e7929063aada32f31da32eca6d532481b1c4852a\", \"best_bid\":\"0.49\", \"best_ask\":\"0.5\"}], \"timestamp\":\"1785207339919\", \"event_type\":\"price_change\"}","received_at":"2026-07-28T02:55:40.146171Z","schema_version":"clob-market-ws.price_change.v1","sequence":null,"server_hash":null,"server_timestamp":"1785207339919","session_id":"3e519d9098404c15b234d96025eb1a2b","source":"clob_market_ws"},"received_at":"2026-07-28T02:55:40.146171Z","record_id":"7f0b2f586e8796fde6d1550de9e02c870bcc7c9031e2146632bd5383e7ff7b0f","schema_fingerprint":"4aa3821a28b0b7c2400bc59aba4bcc0a76e971dadd19610d3ad38c768e124dc7","schema_version":"edge-lab-recorder.raw.v1","sequence":null,"source":"clob_market_ws"}
{"event_at":"2026-07-28T02:55:39.920000Z","event_fingerprint":"f334e0873afe28fc1d717c7ff469a84139978bc8dc11a352ab945cb12aaa2d58","payload":{"connection_id":"a6b55582af5f430fb37ad02bf0922475","event_at":"2026-07-28T02:55:39.920000Z","event_type":"price_change","frame_hash":"ac80c5f44b8d88b1ccbdbbdd62e0e27ee5fa9f27e78d460fbfe9698a99230f61","frame_index":0,"kind":"data","monotonic_ns":309323167055041,"payload":{"event_type":"price_change","market":"0x779291bef19b6709f61e9764a954aafe9ffae488d50ae674aabdcb4f248006d5","price_changes":[{"asset_id":"14965588658799411272385430903075831224615961675357217884735713260981483529984","best_ask":"0.51","best_bid":"0.5","hash":"8296a173eb06107e35ef56e3f7b189ab07c2af82","price":"0.47","side":"BUY","size":"214.67"},{"asset_id":"8761897749749422724209054078244794145777693856614463256546737399611489089783","best_ask":"0.5","best_bid":"0.49","hash":"b223f5f2848d8c4a37a776794baaa541bd7cd387","price":"0.53","side":"SELL","size":"214.67"}],"timestamp":"1785207339920"},"payload_hash":"29dafb7e2325540285e516a932740d2c24f8cc11fbae736a058e4c05b4ee4b02","raw_frame":"{\"market\":\"0x779291bef19b6709f61e9764a954aafe9ffae488d50ae674aabdcb4f248006d5\", \"price_changes\":[{\"asset_id\":\"14965588658799411272385430903075831224615961675357217884735713260981483529984\", \"price\":\"0.47\", \"size\":\"214.67\", \"side\":\"BUY\", \"hash\":\"8296a173eb06107e35ef56e3f7b189ab07c2af82\", \"best_bid\":\"0.5\", \"best_ask\":\"0.51\"}, {\"asset_id\":\"8761897749749422724209054078244794145777693856614463256546737399611489089783\", \"price\":\"0.53\", \"size\":\"214.67\", \"side\":\"SELL\", \"hash\":\"b223f5f2848d8c4a37a776794baaa541bd7cd387\", \"best_bid\":\"0.49\", \"best_ask\":\"0.5\"}], \"timestamp\":\"1785207339920\", \"event_type\":\"price_change\"}","received_at":"2026-07-28T02:55:40.150568Z","schema_version":"clob-market-ws.price_change.v1","sequence":null,"server_hash":null,"server_timestamp":"1785207339920","session_id":"3e519d9098404c15b234d96025eb1a2b","source":"clob_market_ws"},"received_at":"2026-07-28T02:55:40.150568Z","record_id":"d7a6c3c4857816272638d676d4d45d415ba84f513f0af35c9a99f28c55487ac9","schema_fingerprint":"4aa3821a28b0b7c2400bc59aba4bcc0a76e971dadd19610d3ad38c768e124dc7","schema_version":"edge-lab-recorder.raw.v1","sequence":null,"source":"clob_market_ws"}
{"event_at":"2026-07-28T02:55:39.922000Z","event_fingerprint":"880c0cec9c060aa60bc20a72cd6b7e4d8f562d41e01c9b3e6c2983d715c3434b","payload":{"connection_id":"a6b55582af5f430fb37ad02bf0922475","event_at":"2026-07-28T02:55:39.922000Z","event_type":"price_change","frame_hash":"6052732c3671696b4b36a41ae31ea041a228b5d240e689da385a9ef160368c8e","frame_index":0,"kind":"data","monotonic_ns":309323171317541,"payload":{"event_type":"price_change","market":"0x779291bef19b6709f61e9764a954aafe9ffae488d50ae674aabdcb4f248006d5","price_changes":[{"asset_id":"14965588658799411272385430903075831224615961675357217884735713260981483529984","best_ask":"0.51","best_bid":"0.5","hash":"570bd5b6d6ba892d763c4f0d6e7260392db6325d","price":"0.47","side":"BUY","size":"219.67"},{"asset_id":"8761897749749422724209054078244794145777693856614463256546737399611489089783","best_ask":"0.5","best_bid":"0.49","hash":"680651d488aaea5aad7e68424721440cc0288166","price":"0.53","side":"SELL","size":"219.67"}],"timestamp":"1785207339922"},"payload_hash":"d28c15971f5974ff38405f9a2320af122276e141e068ef1d88937df496901b88","raw_frame":"{\"market\":\"0x779291bef19b6709f61e9764a954aafe9ffae488d50ae674aabdcb4f248006d5\", \"price_changes\":[{\"asset_id\":\"14965588658799411272385430903075831224615961675357217884735713260981483529984\", \"price\":\"0.47\", \"size\":\"219.67\", \"side\":\"BUY\", \"hash\":\"570bd5b6d6ba892d763c4f0d6e7260392db6325d\", \"best_bid\":\"0.5\", \"best_ask\":\"0.51\"}, {\"asset_id\":\"8761897749749422724209054078244794145777693856614463256546737399611489089783\", \"price\":\"0.53\", \"size\":\"219.67\", \"side\":\"SELL\", \"hash\":\"680651d488aaea5aad7e68424721440cc0288166\", \"best_bid\":\"0.49\", \"best_ask\":\"0.5\"}], \"timestamp\":\"1785207339922\", \"event_type\":\"price_change\"}","received_at":"2026-07-28T02:55:40.154831Z","schema_version":"clob-market-ws.price_change.v1","sequence":null,"server_hash":null,"server_timestamp":"1785207339922","session_id":"3e519d9098404c15b234d96025eb1a2b","source":"clob_market_ws"},"received_at":"2026-07-28T02:55:40.154831Z","record_id":"5fcae36293c77006d76f1d62bdf5c131064f01883acb28486aaafa57116690aa","schema_fingerprint":"4aa3821a28b0b7c2400bc59aba4bcc0a76e971dadd19610d3ad38c768e124dc7","schema_version":"edge-lab-recorder.raw.v1","sequence":null,"source":"clob_market_ws"}
{"event_at":"2026-07-28T02:55:39.923000Z","event_fingerprint":"4b0e801d4d95b32a96958bffe9decac9f87dac18b8e7cf6a6a9a0da8dadb9a62","payload":{"connection_id":"a6b55582af5f430fb37ad02bf0922475","event_at":"2026-07-28T02:55:39.923000Z","event_type":"price_change","frame_hash":"385e664025daaa98567a57c61ae014baa9edc2a1dc76c34a931e1165be0283ae","frame_index":0,"kind":"data","monotonic_ns":309323175247000,"payload":{"event_type":"price_change","market":"0x779291bef19b6709f61e9764a954aafe9ffae488d50ae674aabdcb4f248006d5","price_changes":[{"asset_id":"14965588658799411272385430903075831224615961675357217884735713260981483529984","best_ask":"0.51","best_bid":"0.5","hash":"26f295dbc5a0c0233ec686fdd6bcc28ed2699efd","price":"0.47","side":"BUY","size":"224.67"},{"asset_id":"8761897749749422724209054078244794145777693856614463256546737399611489089783","best_ask":"0.5","best_bid":"0.49","hash":"f15a40f6dd2a183b014f09b0a586779b3147bc89","price":"0.53","side":"SELL","size":"224.67"}],"timestamp":"1785207339923"},"payload_hash":"a54a5a97b38c0f59be8b3145f02e2840b3183a6ed21d75a059f0fa8fbfeabad6","raw_frame":"{\"market\":\"0x779291bef19b6709f61e9764a954aafe9ffae488d50ae674aabdcb4f248006d5\", \"price_changes\":[{\"asset_id\":\"14965588658799411272385430903075831224615961675357217884735713260981483529984\", \"price\":\"0.47\", \"size\":\"224.67\", \"side\":\"BUY\", \"hash\":\"26f295dbc5a0c0233ec686fdd6bcc28ed2699efd\", \"best_bid\":\"0.5\", \"best_ask\":\"0.51\"}, {\"asset_id\":\"8761897749749422724209054078244794145777693856614463256546737399611489089783\", \"price\":\"0.53\", \"size\":\"224.67\", \"side\":\"SELL\", \"hash\":\"f15a40f6dd2a183b014f09b0a586779b3147bc89\", \"best_bid\":\"0.49\", \"best_ask\":\"0.5\"}], \"timestamp\":\"1785207339923\", \"event_type\":\"price_change\"}","received_at":"2026-07-28T02:55:40.158761Z","schema_version":"clob-market-ws.price_change.v1","sequence":null,"server_hash":null,"server_timestamp":"1785207339923","session_id":"3e519d9098404c15b234d96025eb1a2b","source":"clob_market_ws"},"received_at":"2026-07-28T02:55:40.158761Z","record_id":"43a6ac30d70af200749ba50a773e436874873b888572105a75c5b47873aca1c3","schema_fingerprint":"4aa3821a28b0b7c2400bc59aba4bcc0a76e971dadd19610d3ad38c768e124dc7","schema_version":"edge-lab-recorder.raw.v1","sequence":null,"source":"clob_market_ws"}
{"event_at":"2026-07-28T02:55:39.924000Z","event_fingerprint":"873f38b1dc10e5e1c2048dcf1caa9c5c459a57d6b5e08d271eba60261524c3d5","payload":{"connection_id":"a6b55582af5f430fb37ad02bf0922475","event_at":"2026-07-28T02:55:39.924000Z","event_type":"price_change","frame_hash":"b73784fa724115f65b7267e0ed3bba7a344667dda00b5ab1accbe067145dfb88","frame_index":0,"kind":"data","monotonic_ns":309323179641083,"payload":{"event_type":"price_change","market":"0x779291bef19b6709f61e9764a954aafe9ffae488d50ae674aabdcb4f248006d5","price_changes":[{"asset_id":"14965588658799411272385430903075831224615961675357217884735713260981483529984","best_ask":"0.51","best_bid":"0.5","hash":"c20613d9d03ecf095948db1506e4b58f1d939f17","price":"0.47","side":"BUY","size":"229.67"},{"asset_id":"8761897749749422724209054078244794145777693856614463256546737399611489089783","best_ask":"0.5","best_bid":"0.49","hash":"c3a2eac4ca3c9c3ed66033f71c4cac5adf6669af","price":"0.53","side":"SELL","size":"229.67"}],"timestamp":"1785207339924"},"payload_hash":"c5fdcd8086f5df0aa9d5d213d545fe6b808fa83aa84d05c1d03deb411d8818ae","raw_frame":"{\"market\":\"0x779291bef19b6709f61e9764a954aafe9ffae488d50ae674aabdcb4f248006d5\", \"price_changes\":[{\"asset_id\":\"14965588658799411272385430903075831224615961675357217884735713260981483529984\", \"price\":\"0.47\", \"size\":\"229.67\", \"side\":\"BUY\", \"hash\":\"c20613d9d03ecf095948db1506e4b58f1d939f17\", \"best_bid\":\"0.5\", \"best_ask\":\"0.51\"}, {\"asset_id\":\"8761897749749422724209054078244794145777693856614463256546737399611489089783\", \"price\":\"0.53\", \"size\":\"229.67\", \"side\":\"SELL\", \"hash\":\"c3a2eac4ca3c9c3ed66033f71c4cac5adf6669af\", \"best_bid\":\"0.49\", \"best_ask\":\"0.5\"}], \"timestamp\":\"1785207339924\", \"event_type\":\"price_change\"}","received_at":"2026-07-28T02:55:40.163154Z","schema_version":"clob-market-ws.price_change.v1","sequence":null,"server_hash":null,"server_timestamp":"1785207339924","session_id":"3e519d9098404c15b234d96025eb1a2b","source":"clob_market_ws"},"received_at":"2026-07-28T02:55:40.163154Z","record_id":"64085b5330499b4883368cac05e9a849aa1fae62168652b7b246ac419630ac9d","schema_fingerprint":"4aa3821a28b0b7c2400bc59aba4bcc0a76e971dadd19610d3ad38c768e124dc7","schema_version":"edge-lab-recorder.raw.v1","sequence":null,"source":"clob_market_ws"}
{"event_at":"2026-07-28T02:55:39.925000Z","event_fingerprint":"cce8c126e01eedf48bfa0671577ab568123bdc23c179dec639aeb0cca6ef0625","payload":{"connection_id":"a6b55582af5f430fb37ad02bf0922475","event_at":"2026-07-28T02:55:39.925000Z","event_type":"price_change","frame_hash":"2e2abfa27ca844fb7c4d0333a3848b9d259c93e792ae4a1bb43e437928169c66","frame_index":0,"kind":"data","monotonic_ns":309323183995375,"payload":{"event_type":"price_change","market":"0x779291bef19b6709f61e9764a954aafe9ffae488d50ae674aabdcb4f248006d5","price_changes":[{"asset_id":"14965588658799411272385430903075831224615961675357217884735713260981483529984","best_ask":"0.51","best_bid":"0.5","hash":"e581f28e6d494f15a9610aadecb9c57cafe5a3e0","price":"0.47","side":"BUY","size":"234.67"},{"asset_id":"8761897749749422724209054078244794145777693856614463256546737399611489089783","best_ask":"0.5","best_bid":"0.49","hash":"b6d09f177d5dabe41adeae52105a46764ae32de6","price":"0.53","side":"SELL","size":"234.67"}],"timestamp":"1785207339925"},"payload_hash":"8c773e68335a42bd72cdb24c5ed0d19e8c2a155cddaf9c31743775132df3a85b","raw_frame":"{\"market\":\"0x779291bef19b6709f61e9764a954aafe9ffae488d50ae674aabdcb4f248006d5\", \"price_changes\":[{\"asset_id\":\"14965588658799411272385430903075831224615961675357217884735713260981483529984\", \"price\":\"0.47\", \"size\":\"234.67\", \"side\":\"BUY\", \"hash\":\"e581f28e6d494f15a9610aadecb9c57cafe5a3e0\", \"best_bid\":\"0.5\", \"best_ask\":\"0.51\"}, {\"asset_id\":\"8761897749749422724209054078244794145777693856614463256546737399611489089783\", \"price\":\"0.53\", \"size\":\"234.67\", \"side\":\"SELL\", \"hash\":\"b6d09f177d5dabe41adeae52105a46764ae32de6\", \"best_bid\":\"0.49\", \"best_ask\":\"0.5\"}], \"timestamp\":\"1785207339925\", \"event_type\":\"price_change\"}","received_at":"2026-07-28T02:55:40.167509Z","schema_version":"clob-market-ws.price_change.v1","sequence":null,"server_hash":null,"server_timestamp":"1785207339925","session_id":"3e519d9098404c15b234d96025eb1a2b","source":"clob_market_ws"},"received_at":"2026-07-28T02:55:40.167509Z","record_id":"f881581a03e33106a4dcf9621f48eb81d33cd7ab67c76bd57243d12a0cf1e87f","schema_fingerprint":"4aa3821a28b0b7c2400bc59aba4bcc0a76e971dadd19610d3ad38c768e124dc7","schema_version":"edge-lab-recorder.raw.v1","sequence":null,"source":"clob_market_ws"}
{"event_at":"2026-07-28T02:55:39.926000Z","event_fingerprint":"cff951071613f2fdee67f52432a4ccfacb0c9ebb201e5d62f06c2ade15e05200","payload":{"connection_id":"a6b55582af5f430fb37ad02bf0922475","event_at":"2026-07-28T02:55:39.926000Z","event_type":"price_change","frame_hash":"b4917ee502723e119086a735077dc1abf13132b98328f654b9abeee3d2937802","frame_index":0,"kind":"data","monotonic_ns":309323187651000,"payload":{"event_type":"price_change","market":"0x779291bef19b6709f61e9764a954aafe9ffae488d50ae674aabdcb4f248006d5","price_changes":[{"asset_id":"14965588658799411272385430903075831224615961675357217884735713260981483529984","best_ask":"0.51","best_bid":"0.5","hash":"cc9b0637c6b74898c3e9e2fe70357647918c3ad8","price":"0.47","side":"BUY","size":"239.67"},{"asset_id":"8761897749749422724209054078244794145777693856614463256546737399611489089783","best_ask":"0.5","best_bid":"0.49","hash":"21f4988c1de551a5297f6814a30d8fe6ad0c2980","price":"0.53","side":"SELL","size":"239.67"}],"timestamp":"1785207339926"},"payload_hash":"7f33c097dd3b398a156aed5a0346e148d33acc58062a0ecf098a3ab4db42a962","raw_frame":"{\"market\":\"0x779291bef19b6709f61e9764a954aafe9ffae488d50ae674aabdcb4f248006d5\", \"price_changes\":[{\"asset_id\":\"14965588658799411272385430903075831224615961675357217884735713260981483529984\", \"price\":\"0.47\", \"size\":\"239.67\", \"side\":\"BUY\", \"hash\":\"cc9b0637c6b74898c3e9e2fe70357647918c3ad8\", \"best_bid\":\"0.5\", \"best_ask\":\"0.51\"}, {\"asset_id\":\"8761897749749422724209054078244794145777693856614463256546737399611489089783\", \"price\":\"0.53\", \"size\":\"239.67\", \"side\":\"SELL\", \"hash\":\"21f4988c1de551a5297f6814a30d8fe6ad0c2980\", \"best_bid\":\"0.49\", \"best_ask\":\"0.5\"}], \"timestamp\":\"1785207339926\", \"event_type\":\"price_change\"}","received_at":"2026-07-28T02:55:40.171164Z","schema_version":"clob-market-ws.price_change.v1","sequence":null,"server_hash":null,"server_timestamp":"1785207339926","session_id":"3e519d9098404c15b234d96025eb1a2b","source":"clob_market_ws"},"received_at":"2026-07-28T02:55:40.171164Z","record_id":"fa642fc2160fb09f7fb9ab71575cd319c0c244fa154adc41d9f51a3081f56455","schema_fingerprint":"4aa3821a28b0b7c2400bc59aba4bcc0a76e971dadd19610d3ad38c768e124dc7","schema_version":"edge-lab-recorder.raw.v1","sequence":null,"source":"clob_market_ws"}
{"event_at":"2026-07-28T02:55:39.927000Z","event_fingerprint":"9cbbff9408724393c22d39a7cefb49196d1e22c0f86a4802b3603f067ba8e6de","payload":{"connection_id":"a6b55582af5f430fb37ad02bf0922475","event_at":"2026-07-28T02:55:39.927000Z","event_type":"price_change","frame_hash":"4cab7c39d2b15fd4b13f26438fff08dd62e64b6cc75cf9b8adb796afbeede5d3","frame_index":0,"kind":"data","monotonic_ns":309323191802500,"payload":{"event_type":"price_change","market":"0x779291bef19b6709f61e9764a954aafe9ffae488d50ae674aabdcb4f248006d5","price_changes":[{"asset_id":"14965588658799411272385430903075831224615961675357217884735713260981483529984","best_ask":"0.51","best_bid":"0.5","hash":"6235f0c721de51ad5ed7cdf583ad0d0669fabff2","price":"0.47","side":"BUY","size":"244.67"},{"asset_id":"8761897749749422724209054078244794145777693856614463256546737399611489089783","best_ask":"0.5","best_bid":"0.49","hash":"e07dbdf1c7e3b71cb0f7a0f510780a14ccaf93e4","price":"0.53","side":"SELL","size":"244.67"}],"timestamp":"1785207339927"},"payload_hash":"e8119dada23d4ea31945f8e0bada3a53a853ad5beba629d4c664dcd9e6cf10fb","raw_frame":"{\"market\":\"0x779291bef19b6709f61e9764a954aafe9ffae488d50ae674aabdcb4f248006d5\", \"price_changes\":[{\"asset_id\":\"14965588658799411272385430903075831224615961675357217884735713260981483529984\", \"price\":\"0.47\", \"size\":\"244.67\", \"side\":\"BUY\", \"hash\":\"6235f0c721de51ad5ed7cdf583ad0d0669fabff2\", \"best_bid\":\"0.5\", \"best_ask\":\"0.51\"}, {\"asset_id\":\"8761897749749422724209054078244794145777693856614463256546737399611489089783\", \"price\":\"0.53\", \"size\":\"244.67\", \"side\":\"SELL\", \"hash\":\"e07dbdf1c7e3b71cb0f7a0f510780a14ccaf93e4\", \"best_bid\":\"0.49\", \"best_ask\":\"0.5\"}], \"timestamp\":\"1785207339927\", \"event_type\":\"price_change\"}","received_at":"2026-07-28T02:55:40.175316Z","schema_version":"clob-market-ws.price_change.v1","sequence":null,"server_hash":null,"server_timestamp":"1785207339927","session_id":"3e519d9098404c15b234d96025eb1a2b","source":"clob_market_ws"},"received_at":"2026-07-28T02:55:40.175316Z","record_id":"5c405302490d6df9eaafbc9310bac9f170932675202483592e8f014b2b975bc9","schema_fingerprint":"4aa3821a28b0b7c2400bc59aba4bcc0a76e971dadd19610d3ad38c768e124dc7","schema_version":"edge-lab-recorder.raw.v1","sequence":null,"source":"clob_market_ws"}
{"event_at":"2026-07-28T02:55:39.928000Z","event_fingerprint":"42759f352bb7aee7681436ab18eb8c74c2ad196e949b14517811854a98ad99bf","payload":{"connection_id":"a6b55582af5f430fb37ad02bf0922475","event_at":"2026-07-28T02:55:39.928000Z","event_type":"price_change","frame_hash":"3ce2de6a2871e135c93961c0718935de487122a868db4f99936e8c3a4c0486f4","frame_index":0,"kind":"data","monotonic_ns":309323196992916,"payload":{"event_type":"price_change","market":"0x779291bef19b6709f61e9764a954aafe9ffae488d50ae674aabdcb4f248006d5","price_changes":[{"asset_id":"14965588658799411272385430903075831224615961675357217884735713260981483529984","best_ask":"0.51","best_bid":"0.5","hash":"45a349898ded4eeebb98caea914c4d6162d9c53a","price":"0.47","side":"BUY","size":"249.67"},{"asset_id":"8761897749749422724209054078244794145777693856614463256546737399611489089783","best_ask":"0.5","best_bid":"0.49","hash":"8d3754eabe205396c35dcd344eb0dfaa8ceb9ca1","price":"0.53","side":"SELL","size":"249.67"}],"timestamp":"1785207339928"},"payload_hash":"2017be25eac7fe892d68ada5c08a01634a82071c3281e17b4e4110193478fdf2","raw_frame":"{\"market\":\"0x779291bef19b6709f61e9764a954aafe9ffae488d50ae674aabdcb4f248006d5\", \"price_changes\":[{\"asset_id\":\"14965588658799411272385430903075831224615961675357217884735713260981483529984\", \"price\":\"0.47\", \"size\":\"249.67\", \"side\":\"BUY\", \"hash\":\"45a349898ded4eeebb98caea914c4d6162d9c53a\", \"best_bid\":\"0.5\", \"best_ask\":\"0.51\"}, {\"asset_id\":\"8761897749749422724209054078244794145777693856614463256546737399611489089783\", \"price\":\"0.53\", \"size\":\"249.67\", \"side\":\"SELL\", \"hash\":\"8d3754eabe205396c35dcd344eb0dfaa8ceb9ca1\", \"best_bid\":\"0.49\", \"best_ask\":\"0.5\"}], \"timestamp\":\"1785207339928\", \"event_type\":\"price_change\"}","received_at":"2026-07-28T02:55:40.180506Z","schema_version":"clob-market-ws.price_change.v1","sequence":null,"server_hash":null,"server_timestamp":"1785207339928","session_id":"3e519d9098404c15b234d96025eb1a2b","source":"clob_market_ws"},"received_at":"2026-07-28T02:55:40.180506Z","record_id":"3b856f2d8488ff3ad1bf4a0bd94cd1185824d6da32820445f8480e52eb3103bd","schema_fingerprint":"4aa3821a28b0b7c2400bc59aba4bcc0a76e971dadd19610d3ad38c768e124dc7","schema_version":"edge-lab-recorder.raw.v1","sequence":null,"source":"clob_market_ws"}
{"event_at":"2026-07-28T02:55:39.929000Z","event_fingerprint":"4f527695e08745d58740caf07ae143c98521243a9f3c4dea9f366eff54fe8119","payload":{"connection_id":"a6b55582af5f430fb37ad02bf0922475","event_at":"2026-07-28T02:55:39.929000Z","event_type":"price_change","frame_hash":"6fa6206e849ce27e20851b33f77528e10a9b4f1524661073fe1034d1a0f0b046","frame_index":0,"kind":"data","monotonic_ns":309323202029708,"payload":{"event_type":"price_change","market":"0x779291bef19b6709f61e9764a954aafe9ffae488d50ae674aabdcb4f248006d5","price_changes":[{"asset_id":"14965588658799411272385430903075831224615961675357217884735713260981483529984","best_ask":"0.51","best_bid":"0.5","hash":"88f92d8e163ba6d64108ae86c154aa8ad791f9d1","price":"0.47","side":"BUY","size":"254.67"},{"asset_id":"8761897749749422724209054078244794145777693856614463256546737399611489089783","best_ask":"0.5","best_bid":"0.49","hash":"1bef3687e809af9e85e071252fbe9d37d0e0fea6","price":"0.53","side":"SELL","size":"254.67"}],"timestamp":"1785207339929"},"payload_hash":"b563156d9cbc573858827c79e23c8f274234cc9cffaff47146a5340537e2b1c0","raw_frame":"{\"market\":\"0x779291bef19b6709f61e9764a954aafe9ffae488d50ae674aabdcb4f248006d5\", \"price_changes\":[{\"asset_id\":\"14965588658799411272385430903075831224615961675357217884735713260981483529984\", \"price\":\"0.47\", \"size\":\"254.67\", \"side\":\"BUY\", \"hash\":\"88f92d8e163ba6d64108ae86c154aa8ad791f9d1\", \"best_bid\":\"0.5\", \"best_ask\":\"0.51\"}, {\"asset_id\":\"8761897749749422724209054078244794145777693856614463256546737399611489089783\", \"price\":\"0.53\", \"size\":\"254.67\", \"side\":\"SELL\", \"hash\":\"1bef3687e809af9e85e071252fbe9d37d0e0fea6\", \"best_bid\":\"0.49\", \"best_ask\":\"0.5\"}], \"timestamp\":\"1785207339929\", \"event_type\":\"price_change\"}","received_at":"2026-07-28T02:55:40.185543Z","schema_version":"clob-market-ws.price_change.v1","sequence":null,"server_hash":null,"server_timestamp":"1785207339929","session_id":"3e519d9098404c15b234d96025eb1a2b","source":"clob_market_ws"},"received_at":"2026-07-28T02:55:40.185543Z","record_id":"2c72e570beed0f96c00b222117e5e684d85b785f82d9ac0f40e34b199efb617e","schema_fingerprint":"4aa3821a28b0b7c2400bc59aba4bcc0a76e971dadd19610d3ad38c768e124dc7","schema_version":"edge-lab-recorder.raw.v1","sequence":null,"source":"clob_market_ws"}
{"event_at":"2026-07-28T02:55:39.930000Z","event_fingerprint":"edd84c4c23a5519cb93ed4fbc8eb7eb2f83daba8dc924dccd84e8a51f4c17a81","payload":{"connection_id":"a6b55582af5f430fb37ad02bf0922475","event_at":"2026-07-28T02:55:39.930000Z","event_type":"price_change","frame_hash":"27b6268935c508d28e0a2052d009cb742d3b91d334a4755d85509c2a7c0da5b2","frame_index":0,"kind":"data","monotonic_ns":309323205594791,"payload":{"event_type":"price_change","market":"0x779291bef19b6709f61e9764a954aafe9ffae488d50ae674aabdcb4f248006d5","price_changes":[{"asset_id":"14965588658799411272385430903075831224615961675357217884735713260981483529984","best_ask":"0.51","best_bid":"0.5","hash":"b0d94fa10f48e7575ecb05698aa8dcc597c1003b","price":"0.47","side":"BUY","size":"259.67"},{"asset_id":"8761897749749422724209054078244794145777693856614463256546737399611489089783","best_ask":"0.5","best_bid":"0.49","hash":"d75f978344a66c8f1da5d2a0a6d97061a7fddbd0","price":"0.53","side":"SELL","size":"259.67"}],"timestamp":"1785207339930"},"payload_hash":"a897033c10fde4cc356787c5757081cd9e0a7b127217ad64d353e3dd0e79a0af","raw_frame":"{\"market\":\"0x779291bef19b6709f61e9764a954aafe9ffae488d50ae674aabdcb4f248006d5\", \"price_changes\":[{\"asset_id\":\"14965588658799411272385430903075831224615961675357217884735713260981483529984\", \"price\":\"0.47\", \"size\":\"259.67\", \"side\":\"BUY\", \"hash\":\"b0d94fa10f48e7575ecb05698aa8dcc597c1003b\", \"best_bid\":\"0.5\", \"best_ask\":\"0.51\"}, {\"asset_id\":\"8761897749749422724209054078244794145777693856614463256546737399611489089783\", \"price\":\"0.53\", \"size\":\"259.67\", \"side\":\"SELL\", \"hash\":\"d75f978344a66c8f1da5d2a0a6d97061a7fddbd0\", \"best_bid\":\"0.49\", \"best_ask\":\"0.5\"}], \"timestamp\":\"1785207339930\", \"event_type\":\"price_change\"}","received_at":"2026-07-28T02:55:40.189108Z","schema_version":"clob-market-ws.price_change.v1","sequence":null,"server_hash":null,"server_timestamp":"1785207339930","session_id":"3e519d9098404c15b234d96025eb1a2b","source":"clob_market_ws"},"received_at":"2026-07-28T02:55:40.189108Z","record_id":"4ea15686d37a0e5fa0e5bca42695177fafd44774b456759ea066e08a5372e84a","schema_fingerprint":"4aa3821a28b0b7c2400bc59aba4bcc0a76e971dadd19610d3ad38c768e124dc7","schema_version":"edge-lab-recorder.raw.v1","sequence":null,"source":"clob_market_ws"}
{"event_at":"2026-07-28T02:55:39.931000Z","event_fingerprint":"26353b1a971a29186fa8d4bdffd2b59f7e98ddcbe7afe884c416100e85593701","payload":{"connection_id":"a6b55582af5f430fb37ad02bf0922475","event_at":"2026-07-28T02:55:39.931000Z","event_type":"price_change","frame_hash":"db21069fcc1cd6f4d6af817dd1fbbcc9e628252e7d64cf0a75c4434662318250","frame_index":0,"kind":"data","monotonic_ns":309323209308208,"payload":{"event_type":"price_change","market":"0x779291bef19b6709f61e9764a954aafe9ffae488d50ae674aabdcb4f248006d5","price_changes":[{"asset_id":"14965588658799411272385430903075831224615961675357217884735713260981483529984","best_ask":"0.51","best_bid":"0.5","hash":"a571df446d5a7a59fc2569c861cdd863b33fa502","price":"0.47","side":"BUY","size":"264.67"},{"asset_id":"8761897749749422724209054078244794145777693856614463256546737399611489089783","best_ask":"0.5","best_bid":"0.49","hash":"c591cf9ec18dc37710ad92f442892d0029c96871","price":"0.53","side":"SELL","size":"264.67"}],"timestamp":"1785207339931"},"payload_hash":"19eeb0e3707f6fc95ec57aa6a47c707cfc849658dd8c216a6f6e9edd031b978e","raw_frame":"{\"market\":\"0x779291bef19b6709f61e9764a954aafe9ffae488d50ae674aabdcb4f248006d5\", \"price_changes\":[{\"asset_id\":\"14965588658799411272385430903075831224615961675357217884735713260981483529984\", \"price\":\"0.47\", \"size\":\"264.67\", \"side\":\"BUY\", \"hash\":\"a571df446d5a7a59fc2569c861cdd863b33fa502\", \"best_bid\":\"0.5\", \"best_ask\":\"0.51\"}, {\"asset_id\":\"8761897749749422724209054078244794145777693856614463256546737399611489089783\", \"price\":\"0.53\", \"size\":\"264.67\", \"side\":\"SELL\", \"hash\":\"c591cf9ec18dc37710ad92f442892d0029c96871\", \"best_bid\":\"0.49\", \"best_ask\":\"0.5\"}], \"timestamp\":\"1785207339931\", \"event_type\":\"price_change\"}","received_at":"2026-07-28T02:55:40.192821Z","schema_version":"clob-market-ws.price_change.v1","sequence":null,"server_hash":null,"server_timestamp":"1785207339931","session_id":"3e519d9098404c15b234d96025eb1a2b","source":"clob_market_ws"},"received_at":"2026-07-28T02:55:40.192821Z","record_id":"4969c435f6e5a6fc795a4b042ef94b02cd9e79d60fc4d62313f53db85c930e27","schema_fingerprint":"4aa3821a28b0b7c2400bc59aba4bcc0a76e971dadd19610d3ad38c768e124dc7","schema_version":"edge-lab-recorder.raw.v1","sequence":null,"source":"clob_market_ws"}
{"event_at":"2026-07-28T02:55:39.932000Z","event_fingerprint":"d195e0c8ea90222dc47bdbf511429948d5bc4b49eb8bbf4c4d6d9501ad257118","payload":{"connection_id":"a6b55582af5f430fb37ad02bf0922475","event_at":"2026-07-28T02:55:39.932000Z","event_type":"price_change","frame_hash":"f189d02f3fd9a4a5307e22fb6949206e12fa8a136e6e3725a46d2e0120cab1fa","frame_index":0,"kind":"data","monotonic_ns":309323212975625,"payload":{"event_type":"price_change","market":"0x779291bef19b6709f61e9764a954aafe9ffae488d50ae674aabdcb4f248006d5","price_changes":[{"asset_id":"14965588658799411272385430903075831224615961675357217884735713260981483529984","best_ask":"0.51","best_bid":"0.5","hash":"d6b505b61bd33e57eb058f1146d12cf60dbdb6e7","price":"0.47","side":"BUY","size":"269.67"},{"asset_id":"8761897749749422724209054078244794145777693856614463256546737399611489089783","best_ask":"0.5","best_bid":"0.49","hash":"14ce1ac4df16a2c1f29b9adf4d0c7bf01848796e","price":"0.53","side":"SELL","size":"269.67"}],"timestamp":"1785207339932"},"payload_hash":"0e89677ce3008bf4f37ece81b955b54a9a3589ccdbeb69d8df1eebbfaf84aacd","raw_frame":"{\"market\":\"0x779291bef19b6709f61e9764a954aafe9ffae488d50ae674aabdcb4f248006d5\", \"price_changes\":[{\"asset_id\":\"14965588658799411272385430903075831224615961675357217884735713260981483529984\", \"price\":\"0.47\", \"size\":\"269.67\", \"side\":\"BUY\", \"hash\":\"d6b505b61bd33e57eb058f1146d12cf60dbdb6e7\", \"best_bid\":\"0.5\", \"best_ask\":\"0.51\"}, {\"asset_id\":\"8761897749749422724209054078244794145777693856614463256546737399611489089783\", \"price\":\"0.53\", \"size\":\"269.67\", \"side\":\"SELL\", \"hash\":\"14ce1ac4df16a2c1f29b9adf4d0c7bf01848796e\", \"best_bid\":\"0.49\", \"best_ask\":\"0.5\"}], \"timestamp\":\"1785207339932\", \"event_type\":\"price_change\"}","received_at":"2026-07-28T02:55:40.196489Z","schema_version":"clob-market-ws.price_change.v1","sequence":null,"server_hash":null,"server_timestamp":"1785207339932","session_id":"3e519d9098404c15b234d96025eb1a2b","source":"clob_market_ws"},"received_at":"2026-07-28T02:55:40.196489Z","record_id":"9a3aee834855207a4a5fa18551af3b0f22956093086e4094fb4d0946aadcb7df","schema_fingerprint":"4aa3821a28b0b7c2400bc59aba4bcc0a76e971dadd19610d3ad38c768e124dc7","schema_version":"edge-lab-recorder.raw.v1","sequence":null,"source":"clob_market_ws"}
{"event_at":"2026-07-28T02:55:39.933000Z","event_fingerprint":"e0ecb265ddbe59a308c1767700820e598bf3c80759a4db9554cf9056f49bfc8b","payload":{"connection_id":"a6b55582af5f430fb37ad02bf0922475","event_at":"2026-07-28T02:55:39.933000Z","event_type":"price_change","frame_hash":"6e36164b01438b65f39a3dec631fa18f1988a5d5c16cc82550e8fc826ecd605d","frame_index":0,"kind":"data","monotonic_ns":309323217858875,"payload":{"event_type":"price_change","market":"0x779291bef19b6709f61e9764a954aafe9ffae488d50ae674aabdcb4f248006d5","price_changes":[{"asset_id":"14965588658799411272385430903075831224615961675357217884735713260981483529984","best_ask":"0.51","best_bid":"0.5","hash":"baddd943eb8453dceef45e247921a624a2c278fd","price":"0.47","side":"BUY","size":"274.67"},{"asset_id":"8761897749749422724209054078244794145777693856614463256546737399611489089783","best_ask":"0.5","best_bid":"0.49","hash":"1867b3feefd7a901b4988170870c58350314c485","price":"0.53","side":"SELL","size":"274.67"}],"timestamp":"1785207339933"},"payload_hash":"a460406082d70842cbc3cd3d6bbd4d95992cc711fe3521de59b78fae4b3b042f","raw_frame":"{\"market\":\"0x779291bef19b6709f61e9764a954aafe9ffae488d50ae674aabdcb4f248006d5\", \"price_changes\":[{\"asset_id\":\"14965588658799411272385430903075831224615961675357217884735713260981483529984\", \"price\":\"0.47\", \"size\":\"274.67\", \"side\":\"BUY\", \"hash\":\"baddd943eb8453dceef45e247921a624a2c278fd\", \"best_bid\":\"0.5\", \"best_ask\":\"0.51\"}, {\"asset_id\":\"8761897749749422724209054078244794145777693856614463256546737399611489089783\", \"price\":\"0.53\", \"size\":\"274.67\", \"side\":\"SELL\", \"hash\":\"1867b3feefd7a901b4988170870c58350314c485\", \"best_bid\":\"0.49\", \"best_ask\":\"0.5\"}], \"timestamp\":\"1785207339933\", \"event_type\":\"price_change\"}","received_at":"2026-07-28T02:55:40.201372Z","schema_version":"clob-market-ws.price_change.v1","sequence":null,"server_hash":null,"server_timestamp":"1785207339933","session_id":"3e519d9098404c15b234d96025eb1a2b","source":"clob_market_ws"},"received_at":"2026-07-28T02:55:40.201372Z","record_id":"c2ce10a4ef304910f108d7c3ef65a16e644f0d0122e37126e1963f7c75555d4b","schema_fingerprint":"4aa3821a28b0b7c2400bc59aba4bcc0a76e971dadd19610d3ad38c768e124dc7","schema_version":"edge-lab-recorder.raw.v1","sequence":null,"source":"clob_market_ws"}
{"event_at":"2026-07-28T02:55:39.934000Z","event_fingerprint":"54c1c6d828d2d2000383506421665edb4d01723800a3703730b76f13a60b5eaa","payload":{"connection_id":"a6b55582af5f430fb37ad02bf0922475","event_at":"2026-07-28T02:55:39.934000Z","event_type":"price_change","frame_hash":"3cda6f7ea557b915d52d4d852c00a3656607934dce9f753f918e1cd27302d94a","frame_index":0,"kind":"data","monotonic_ns":309323365927250,"payload":{"event_type":"price_change","market":"0x779291bef19b6709f61e9764a954aafe9ffae488d50ae674aabdcb4f248006d5","price_changes":[{"asset_id":"14965588658799411272385430903075831224615961675357217884735713260981483529984","best_ask":"0.51","best_bid":"0.5","hash":"a0ec65520a37f06f30dc49658b92916e67945b14","price":"0.47","side":"BUY","size":"279.67"},{"asset_id":"8761897749749422724209054078244794145777693856614463256546737399611489089783","best_ask":"0.5","best_bid":"0.49","hash":"6d66c4b46abccd8d112f5951232909b8bd118ad3","price":"0.53","side":"SELL","size":"279.67"}],"timestamp":"1785207339934"},"payload_hash":"f9704492ecab7703f41f440720f973144273f28ecbe2429a3220432dcd9be165","raw_frame":"{\"market\":\"0x779291bef19b6709f61e9764a954aafe9ffae488d50ae674aabdcb4f248006d5\", \"price_changes\":[{\"asset_id\":\"14965588658799411272385430903075831224615961675357217884735713260981483529984\", \"price\":\"0.47\", \"size\":\"279.67\", \"side\":\"BUY\", \"hash\":\"a0ec65520a37f06f30dc49658b92916e67945b14\", \"best_bid\":\"0.5\", \"best_ask\":\"0.51\"}, {\"asset_id\":\"8761897749749422724209054078244794145777693856614463256546737399611489089783\", \"price\":\"0.53\", \"size\":\"279.67\", \"side\":\"SELL\", \"hash\":\"6d66c4b46abccd8d112f5951232909b8bd118ad3\", \"best_bid\":\"0.49\", \"best_ask\":\"0.5\"}], \"timestamp\":\"1785207339934\", \"event_type\":\"price_change\"}","received_at":"2026-07-28T02:55:40.349440Z","schema_version":"clob-market-ws.price_change.v1","sequence":null,"server_hash":null,"server_timestamp":"1785207339934","session_id":"3e519d9098404c15b234d96025eb1a2b","source":"clob_market_ws"},"received_at":"2026-07-28T02:55:40.349440Z","record_id":"7dc27a07afdba67260d11b0d23c61863469dcd5a7f7a6ed4e90a8450b91b7f05","schema_fingerprint":"4aa3821a28b0b7c2400bc59aba4bcc0a76e971dadd19610d3ad38c768e124dc7","schema_version":"edge-lab-recorder.raw.v1","sequence":null,"source":"clob_market_ws"}
{"event_at":"2026-07-28T02:55:39.935000Z","event_fingerprint":"cbf89b5092617faf34b1b938fbd0d5771697d4b4b781b2cf213159fcead4debc","payload":{"connection_id":"a6b55582af5f430fb37ad02bf0922475","event_at":"2026-07-28T02:55:39.935000Z","event_type":"price_change","frame_hash":"b652fb6a4093b27e2b295ddd6b59fdbe68d93e25883b96498f2d744521563e64","frame_index":0,"kind":"data","monotonic_ns":309323370050916,"payload":{"event_type":"price_change","market":"0x779291bef19b6709f61e9764a954aafe9ffae488d50ae674aabdcb4f248006d5","price_changes":[{"asset_id":"14965588658799411272385430903075831224615961675357217884735713260981483529984","best_ask":"0.51","best_bid":"0.5","hash":"4a87747e0486f17187f197a77f1b6c0e07c7d8da","price":"0.47","side":"BUY","size":"284.67"},{"asset_id":"8761897749749422724209054078244794145777693856614463256546737399611489089783","best_ask":"0.5","best_bid":"0.49","hash":"5efc54876c4b9ef5750c313a7e49eb8669f3473f","price":"0.53","side":"SELL","size":"284.67"}],"timestamp":"1785207339935"},"payload_hash":"473d0d5f68c9777968e72ee2d956388a396ee0465e227aad4a5f47cf93a264cd","raw_frame":"{\"market\":\"0x779291bef19b6709f61e9764a954aafe9ffae488d50ae674aabdcb4f248006d5\", \"price_changes\":[{\"asset_id\":\"14965588658799411272385430903075831224615961675357217884735713260981483529984\", \"price\":\"0.47\", \"size\":\"284.67\", \"side\":\"BUY\", \"hash\":\"4a87747e0486f17187f197a77f1b6c0e07c7d8da\", \"best_bid\":\"0.5\", \"best_ask\":\"0.51\"}, {\"asset_id\":\"8761897749749422724209054078244794145777693856614463256546737399611489089783\", \"price\":\"0.53\", \"size\":\"284.67\", \"side\":\"SELL\", \"hash\":\"5efc54876c4b9ef5750c313a7e49eb8669f3473f\", \"best_bid\":\"0.49\", \"best_ask\":\"0.5\"}], \"timestamp\":\"1785207339935\", \"event_type\":\"price_change\"}","received_at":"2026-07-28T02:55:40.353563Z","schema_version":"clob-market-ws.price_change.v1","sequence":null,"server_hash":null,"server_timestamp":"1785207339935","session_id":"3e519d9098404c15b234d96025eb1a2b","source":"clob_market_ws"},"received_at":"2026-07-28T02:55:40.353563Z","record_id":"f5649b9f6dec94ec84003a3ab8310243f0d745757a0d2c8009f20d46ff3e2e1a","schema_fingerprint":"4aa3821a28b0b7c2400bc59aba4bcc0a76e971dadd19610d3ad38c768e124dc7","schema_version":"edge-lab-recorder.raw.v1","sequence":null,"source":"clob_market_ws"}
{"event_at":"2026-07-28T02:55:39.936000Z","event_fingerprint":"e84b982d19c71b1b3145b24100470f7ab4b564aa02ef33f9e942acdeb836aae5","payload":{"connection_id":"a6b55582af5f430fb37ad02bf0922475","event_at":"2026-07-28T02:55:39.936000Z","event_type":"price_change","frame_hash":"3d62ab7e6792a24a613542f93ab78d754eb52f0c06f7b6ec0c313a4198308d4b","frame_index":0,"kind":"data","monotonic_ns":309323373884666,"payload":{"event_type":"price_change","market":"0x779291bef19b6709f61e9764a954aafe9ffae488d50ae674aabdcb4f248006d5","price_changes":[{"asset_id":"14965588658799411272385430903075831224615961675357217884735713260981483529984","best_ask":"0.51","best_bid":"0.5","hash":"5494bc8f2916ef1321f159ce09c6c822f1e4dc55","price":"0.47","side":"BUY","size":"289.67"},{"asset_id":"8761897749749422724209054078244794145777693856614463256546737399611489089783","best_ask":"0.5","best_bid":"0.49","hash":"005051b7d4c18772f6d6cf60e70e631bc3a469fa","price":"0.53","side":"SELL","size":"289.67"}],"timestamp":"1785207339936"},"payload_hash":"5a04b63a35eefc92d5e52b0ff88ced30d9b6261a78988455e83314d2a45ede6d","raw_frame":"{\"market\":\"0x779291bef19b6709f61e9764a954aafe9ffae488d50ae674aabdcb4f248006d5\", \"price_changes\":[{\"asset_id\":\"14965588658799411272385430903075831224615961675357217884735713260981483529984\", \"price\":\"0.47\", \"size\":\"289.67\", \"side\":\"BUY\", \"hash\":\"5494bc8f2916ef1321f159ce09c6c822f1e4dc55\", \"best_bid\":\"0.5\", \"best_ask\":\"0.51\"}, {\"asset_id\":\"8761897749749422724209054078244794145777693856614463256546737399611489089783\", \"price\":\"0.53\", \"size\":\"289.67\", \"side\":\"SELL\", \"hash\":\"005051b7d4c18772f6d6cf60e70e631bc3a469fa\", \"best_bid\":\"0.49\", \"best_ask\":\"0.5\"}], \"timestamp\":\"1785207339936\", \"event_type\":\"price_change\"}","received_at":"2026-07-28T02:55:40.357396Z","schema_version":"clob-market-ws.price_change.v1","sequence":null,"server_hash":null,"server_timestamp":"1785207339936","session_id":"3e519d9098404c15b234d96025eb1a2b","source":"clob_market_ws"},"received_at":"2026-07-28T02:55:40.357396Z","record_id":"7d67723622efb9182af77d45970a1b11b98ccdce8c9fb716b34d07a2dfb16ef9","schema_fingerprint":"4aa3821a28b0b7c2400bc59aba4bcc0a76e971dadd19610d3ad38c768e124dc7","schema_version":"edge-lab-recorder.raw.v1","sequence":null,"source":"clob_market_ws"}
{"event_at":"2026-07-28T02:55:39.936000Z","event_fingerprint":"43e488eda1c4135734a0292548859540a6e7b6cc198c2c24a2793db45d9159b8","payload":{"connection_id":"a6b55582af5f430fb37ad02bf0922475","event_at":"2026-07-28T02:55:39.936000Z","event_type":"price_change","frame_hash":"18a1f1ec88d9b8167c153e04e22c05b2d447eb3f64f1880bc70f6e78393c08e4","frame_index":0,"kind":"data","monotonic_ns":309323379294333,"payload":{"event_type":"price_change","market":"0x779291bef19b6709f61e9764a954aafe9ffae488d50ae674aabdcb4f248006d5","price_changes":[{"asset_id":"14965588658799411272385430903075831224615961675357217884735713260981483529984","best_ask":"0.51","best_bid":"0.5","hash":"02626ce1d6dfbc7a085e5128a476485edb2314ce","price":"0.47","side":"BUY","size":"294.67"},{"asset_id":"8761897749749422724209054078244794145777693856614463256546737399611489089783","best_ask":"0.5","best_bid":"0.49","hash":"4c8b189bcadaa0f6c78d611282b2ca3844491e12","price":"0.53","side":"SELL","size":"294.67"}],"timestamp":"1785207339936"},"payload_hash":"63cefd3ef08e83f51d0f20c8ffb8fdc7d2e1ae0922b18c74457cce123fb32800","raw_frame":"{\"market\":\"0x779291bef19b6709f61e9764a954aafe9ffae488d50ae674aabdcb4f248006d5\", \"price_changes\":[{\"asset_id\":\"14965588658799411272385430903075831224615961675357217884735713260981483529984\", \"price\":\"0.47\", \"size\":\"294.67\", \"side\":\"BUY\", \"hash\":\"02626ce1d6dfbc7a085e5128a476485edb2314ce\", \"best_bid\":\"0.5\", \"best_ask\":\"0.51\"}, {\"asset_id\":\"8761897749749422724209054078244794145777693856614463256546737399611489089783\", \"price\":\"0.53\", \"size\":\"294.67\", \"side\":\"SELL\", \"hash\":\"4c8b189bcadaa0f6c78d611282b2ca3844491e12\", \"best_bid\":\"0.49\", \"best_ask\":\"0.5\"}], \"timestamp\":\"1785207339936\", \"event_type\":\"price_change\"}","received_at":"2026-07-28T02:55:40.362803Z","schema_version":"clob-market-ws.price_change.v1","sequence":null,"server_hash":null,"server_timestamp":"1785207339936","session_id":"3e519d9098404c15b234d96025eb1a2b","source":"clob_market_ws"},"received_at":"2026-07-28T02:55:40.362803Z","record_id":"8de8fd99c44266f80ec3ac09bff6fee766cee133f39c92c648e21b660edd2670","schema_fingerprint":"4aa3821a28b0b7c2400bc59aba4bcc0a76e971dadd19610d3ad38c768e124dc7","schema_version":"edge-lab-recorder.raw.v1","sequence":null,"source":"clob_market_ws"}
{"event_at":"2026-07-28T02:55:39.937000Z","event_fingerprint":"a923d1fe773b5f9b80591c49ef12ec65de85f30f6e5cd0063a814b7d41b5af0c","payload":{"connection_id":"a6b55582af5f430fb37ad02bf0922475","event_at":"2026-07-28T02:55:39.937000Z","event_type":"price_change","frame_hash":"3a9964d1c255ddcbe85539ef1cc3ffeb5bfe08df7cf3c12a3762346a82e8595d","frame_index":0,"kind":"data","monotonic_ns":309323389436666,"payload":{"event_type":"price_change","market":"0x779291bef19b6709f61e9764a954aafe9ffae488d50ae674aabdcb4f248006d5","price_changes":[{"asset_id":"14965588658799411272385430903075831224615961675357217884735713260981483529984","best_ask":"0.51","best_bid":"0.5","hash":"bb0ad2eb6f2239b9934eb7d78d7cce7abaad962f","price":"0.47","side":"BUY","size":"299.67"},{"asset_id":"8761897749749422724209054078244794145777693856614463256546737399611489089783","best_ask":"0.5","best_bid":"0.49","hash":"1ba6c0d229d634601eabe430d6c4e54e26db3f9b","price":"0.53","side":"SELL","size":"299.67"}],"timestamp":"1785207339937"},"payload_hash":"5e701556d00fe06e35a00fbb3bad335361db018d9fcf20da581ce451d9c0727b","raw_frame":"{\"market\":\"0x779291bef19b6709f61e9764a954aafe9ffae488d50ae674aabdcb4f248006d5\", \"price_changes\":[{\"asset_id\":\"14965588658799411272385430903075831224615961675357217884735713260981483529984\", \"price\":\"0.47\", \"size\":\"299.67\", \"side\":\"BUY\", \"hash\":\"bb0ad2eb6f2239b9934eb7d78d7cce7abaad962f\", \"best_bid\":\"0.5\", \"best_ask\":\"0.51\"}, {\"asset_id\":\"8761897749749422724209054078244794145777693856614463256546737399611489089783\", \"price\":\"0.53\", \"size\":\"299.67\", \"side\":\"SELL\", \"hash\":\"1ba6c0d229d634601eabe430d6c4e54e26db3f9b\", \"best_bid\":\"0.49\", \"best_ask\":\"0.5\"}], \"timestamp\":\"1785207339937\", \"event_type\":\"price_change\"}","received_at":"2026-07-28T02:55:40.372947Z","schema_version":"clob-market-ws.price_change.v1","sequence":null,"server_hash":null,"server_timestamp":"1785207339937","session_id":"3e519d9098404c15b234d96025eb1a2b","source":"clob_market_ws"},"received_at":"2026-07-28T02:55:40.372947Z","record_id":"c6132f218ec46422fc5249e23541e253c4bd7af12f11cb6aee261278948411e0","schema_fingerprint":"4aa3821a28b0b7c2400bc59aba4bcc0a76e971dadd19610d3ad38c768e124dc7","schema_version":"edge-lab-recorder.raw.v1","sequence":null,"source":"clob_market_ws"}
{"event_at":"2026-07-28T02:55:39.938000Z","event_fingerprint":"5f0dd0faf786f0a7fa29fbbe406e9b3ee446a59be45795b51cc71259663aa24a","payload":{"connection_id":"a6b55582af5f430fb37ad02bf0922475","event_at":"2026-07-28T02:55:39.938000Z","event_type":"price_change","frame_hash":"eee256a8891647e16f750e691fcc07a1ea65d4ef7b4ca86a7398f03fb3bd8c82","frame_index":0,"kind":"data","monotonic_ns":309323393984708,"payload":{"event_type":"price_change","market":"0x779291bef19b6709f61e9764a954aafe9ffae488d50ae674aabdcb4f248006d5","price_changes":[{"asset_id":"8761897749749422724209054078244794145777693856614463256546737399611489089783","best_ask":"0.5","best_bid":"0.49","hash":"a1ef5f14e939db282fbca57cb4c83b0470aaf96f","price":"0.49","side":"BUY","size":"55"},{"asset_id":"14965588658799411272385430903075831224615961675357217884735713260981483529984","best_ask":"0.51","best_bid":"0.5","hash":"79409d127663c129be3d55044a0a24ba18c7dcbf","price":"0.51","side":"SELL","size":"55"}],"timestamp":"1785207339938"},"payload_hash":"167a660b750d928bd4621db1c0590a2294a50c20900b40532f09e6980975296c","raw_frame":"{\"market\":\"0x779291bef19b6709f61e9764a954aafe9ffae488d50ae674aabdcb4f248006d5\", \"price_changes\":[{\"asset_id\":\"8761897749749422724209054078244794145777693856614463256546737399611489089783\", \"price\":\"0.49\", \"size\":\"55\", \"side\":\"BUY\", \"hash\":\"a1ef5f14e939db282fbca57cb4c83b0470aaf96f\", \"best_bid\":\"0.49\", \"best_ask\":\"0.5\"}, {\"asset_id\":\"14965588658799411272385430903075831224615961675357217884735713260981483529984\", \"price\":\"0.51\", \"size\":\"55\", \"side\":\"SELL\", \"hash\":\"79409d127663c129be3d55044a0a24ba18c7dcbf\", \"best_bid\":\"0.5\", \"best_ask\":\"0.51\"}], \"timestamp\":\"1785207339938\", \"event_type\":\"price_change\"}","received_at":"2026-07-28T02:55:40.377496Z","schema_version":"clob-market-ws.price_change.v1","sequence":null,"server_hash":null,"server_timestamp":"1785207339938","session_id":"3e519d9098404c15b234d96025eb1a2b","source":"clob_market_ws"},"received_at":"2026-07-28T02:55:40.377496Z","record_id":"092ba55e1a78ce8a7416e02ea38406ae7764759585b571d664aee325194f13cb","schema_fingerprint":"4aa3821a28b0b7c2400bc59aba4bcc0a76e971dadd19610d3ad38c768e124dc7","schema_version":"edge-lab-recorder.raw.v1","sequence":null,"source":"clob_market_ws"}
{"event_at":"2026-07-28T02:55:39.940000Z","event_fingerprint":"56cc9e4a30307d69953c53340a1ec3589282b2de706a6e245f9a13d0b6c000b0","payload":{"connection_id":"a6b55582af5f430fb37ad02bf0922475","event_at":"2026-07-28T02:55:39.940000Z","event_type":"price_change","frame_hash":"ce25632775cbef51c7379819c76990faa14ac5fb229ebd80cb96f2060fe360ab","frame_index":0,"kind":"data","monotonic_ns":309323398801083,"payload":{"event_type":"price_change","market":"0x779291bef19b6709f61e9764a954aafe9ffae488d50ae674aabdcb4f248006d5","price_changes":[{"asset_id":"14965588658799411272385430903075831224615961675357217884735713260981483529984","best_ask":"0.51","best_bid":"0.5","hash":"2b2a09fd688744029db35b1ac7fd4c95ce90f389","price":"0.47","side":"BUY","size":"304.67"},{"asset_id":"8761897749749422724209054078244794145777693856614463256546737399611489089783","best_ask":"0.5","best_bid":"0.49","hash":"6b0337c9274ceb0f2692083911c2411c9e66c339","price":"0.53","side":"SELL","size":"304.67"}],"timestamp":"1785207339940"},"payload_hash":"8f44a4e935dd3bc75771fdac1aa0496b69d1a8f0f74a439232cda8a488575607","raw_frame":"{\"market\":\"0x779291bef19b6709f61e9764a954aafe9ffae488d50ae674aabdcb4f248006d5\", \"price_changes\":[{\"asset_id\":\"14965588658799411272385430903075831224615961675357217884735713260981483529984\", \"price\":\"0.47\", \"size\":\"304.67\", \"side\":\"BUY\", \"hash\":\"2b2a09fd688744029db35b1ac7fd4c95ce90f389\", \"best_bid\":\"0.5\", \"best_ask\":\"0.51\"}, {\"asset_id\":\"8761897749749422724209054078244794145777693856614463256546737399611489089783\", \"price\":\"0.53\", \"size\":\"304.67\", \"side\":\"SELL\", \"hash\":\"6b0337c9274ceb0f2692083911c2411c9e66c339\", \"best_bid\":\"0.49\", \"best_ask\":\"0.5\"}], \"timestamp\":\"1785207339940\", \"event_type\":\"price_change\"}","received_at":"2026-07-28T02:55:40.382312Z","schema_version":"clob-market-ws.price_change.v1","sequence":null,"server_hash":null,"server_timestamp":"1785207339940","session_id":"3e519d9098404c15b234d96025eb1a2b","source":"clob_market_ws"},"received_at":"2026-07-28T02:55:40.382312Z","record_id":"20de200da772f834e648814e090fb91b93a15161fc212da78fd98b0ab47dc9e4","schema_fingerprint":"4aa3821a28b0b7c2400bc59aba4bcc0a76e971dadd19610d3ad38c768e124dc7","schema_version":"edge-lab-recorder.raw.v1","sequence":null,"source":"clob_market_ws"}
{"event_at":"2026-07-28T02:55:39.940000Z","event_fingerprint":"a73e4117559da621311c8320c7126b85ab40f4a871a9b56243bea9e420945659","payload":{"connection_id":"a6b55582af5f430fb37ad02bf0922475","event_at":"2026-07-28T02:55:39.940000Z","event_type":"price_change","frame_hash":"8620656c434f5e3c1f2320525bd1f98e4757b4e70fd56c828ba4317282767e49","frame_index":0,"kind":"data","monotonic_ns":309323404062750,"payload":{"event_type":"price_change","market":"0x779291bef19b6709f61e9764a954aafe9ffae488d50ae674aabdcb4f248006d5","price_changes":[{"asset_id":"8761897749749422724209054078244794145777693856614463256546737399611489089783","best_ask":"0.5","best_bid":"0.49","hash":"05e16cd10affe6dd1fa0529813c38f07be26f2c6","price":"0.49","side":"BUY","size":"60"},{"asset_id":"14965588658799411272385430903075831224615961675357217884735713260981483529984","best_ask":"0.51","best_bid":"0.5","hash":"fe6a5d7f68b3139cd419271c8e93d6f20bcf06d9","price":"0.51","side":"SELL","size":"60"}],"timestamp":"1785207339940"},"payload_hash":"7c633f83a570f46593ca91b7a5a11bc5ccbb98fc5f199140f57a2d657d7665c1","raw_frame":"{\"market\":\"0x779291bef19b6709f61e9764a954aafe9ffae488d50ae674aabdcb4f248006d5\", \"price_changes\":[{\"asset_id\":\"8761897749749422724209054078244794145777693856614463256546737399611489089783\", \"price\":\"0.49\", \"size\":\"60\", \"side\":\"BUY\", \"hash\":\"05e16cd10affe6dd1fa0529813c38f07be26f2c6\", \"best_bid\":\"0.49\", \"best_ask\":\"0.5\"}, {\"asset_id\":\"14965588658799411272385430903075831224615961675357217884735713260981483529984\", \"price\":\"0.51\", \"size\":\"60\", \"side\":\"SELL\", \"hash\":\"fe6a5d7f68b3139cd419271c8e93d6f20bcf06d9\", \"best_bid\":\"0.5\", \"best_ask\":\"0.51\"}], \"timestamp\":\"1785207339940\", \"event_type\":\"price_change\"}","received_at":"2026-07-28T02:55:40.387569Z","schema_version":"clob-market-ws.price_change.v1","sequence":null,"server_hash":null,"server_timestamp":"1785207339940","session_id":"3e519d9098404c15b234d96025eb1a2b","source":"clob_market_ws"},"received_at":"2026-07-28T02:55:40.387569Z","record_id":"816c60fd7f59e0a21b5f891fbe4c5228a9152040deb1369740ed046fb2a51096","schema_fingerprint":"4aa3821a28b0b7c2400bc59aba4bcc0a76e971dadd19610d3ad38c768e124dc7","schema_version":"edge-lab-recorder.raw.v1","sequence":null,"source":"clob_market_ws"}
{"event_at":"2026-07-28T02:55:39.941000Z","event_fingerprint":"29fc13ab59d7f18d1e64315d3c579619a253ffcf445da3ba03f1c828066f0799","payload":{"connection_id":"a6b55582af5f430fb37ad02bf0922475","event_at":"2026-07-28T02:55:39.941000Z","event_type":"price_change","frame_hash":"f08afcd1a6bcb6f6e343a1eefcd7b1fa000c3b5214dbae325d35e98952095efe","frame_index":0,"kind":"data","monotonic_ns":309323409547000,"payload":{"event_type":"price_change","market":"0x779291bef19b6709f61e9764a954aafe9ffae488d50ae674aabdcb4f248006d5","price_changes":[{"asset_id":"14965588658799411272385430903075831224615961675357217884735713260981483529984","best_ask":"0.51","best_bid":"0.5","hash":"1fdbf36442bab8db7b0e4b98c54ddba86df202cd","price":"0.47","side":"BUY","size":"309.67"},{"asset_id":"8761897749749422724209054078244794145777693856614463256546737399611489089783","best_ask":"0.5","best_bid":"0.49","hash":"5b2d35dbf5c3252c86ba7f7a1c2db5131cdeb030","price":"0.53","side":"SELL","size":"309.67"}],"timestamp":"1785207339941"},"payload_hash":"1abf7afc253dc0b2eccd2f92a8820e17fa543fd995c2032bc240d69f7fae239c","raw_frame":"{\"market\":\"0x779291bef19b6709f61e9764a954aafe9ffae488d50ae674aabdcb4f248006d5\", \"price_changes\":[{\"asset_id\":\"14965588658799411272385430903075831224615961675357217884735713260981483529984\", \"price\":\"0.47\", \"size\":\"309.67\", \"side\":\"BUY\", \"hash\":\"1fdbf36442bab8db7b0e4b98c54ddba86df202cd\", \"best_bid\":\"0.5\", \"best_ask\":\"0.51\"}, {\"asset_id\":\"8761897749749422724209054078244794145777693856614463256546737399611489089783\", \"price\":\"0.53\", \"size\":\"309.67\", \"side\":\"SELL\", \"hash\":\"5b2d35dbf5c3252c86ba7f7a1c2db5131cdeb030\", \"best_bid\":\"0.49\", \"best_ask\":\"0.5\"}], \"timestamp\":\"1785207339941\", \"event_type\":\"price_change\"}","received_at":"2026-07-28T02:55:40.393059Z","schema_version":"clob-market-ws.price_change.v1","sequence":null,"server_hash":null,"server_timestamp":"1785207339941","session_id":"3e519d9098404c15b234d96025eb1a2b","source":"clob_market_ws"},"received_at":"2026-07-28T02:55:40.393059Z","record_id":"e845ec0f62be1eb548890a5339b39363fb5cd16b81474b7c90e5211740e45c0b","schema_fingerprint":"4aa3821a28b0b7c2400bc59aba4bcc0a76e971dadd19610d3ad38c768e124dc7","schema_version":"edge-lab-recorder.raw.v1","sequence":null,"source":"clob_market_ws"}
{"event_at":"2026-07-28T02:55:39.942000Z","event_fingerprint":"a8314b6010628bcf7df782868301e86e82880df8dbb5428d0e64288cc5764992","payload":{"connection_id":"a6b55582af5f430fb37ad02bf0922475","event_at":"2026-07-28T02:55:39.942000Z","event_type":"price_change","frame_hash":"5b76f66ce64c7e167790be28417acb5fbe98cfcca27e485cddbed60cf9839056","frame_index":0,"kind":"data","monotonic_ns":309323414091875,"payload":{"event_type":"price_change","market":"0x779291bef19b6709f61e9764a954aafe9ffae488d50ae674aabdcb4f248006d5","price_changes":[{"asset_id":"8761897749749422724209054078244794145777693856614463256546737399611489089783","best_ask":"0.5","best_bid":"0.49","hash":"e436dcaa1e3fdc425b7c4e2b7f8ac80c32e5ff2a","price":"0.49","side":"BUY","size":"65"},{"asset_id":"14965588658799411272385430903075831224615961675357217884735713260981483529984","best_ask":"0.51","best_bid":"0.5","hash":"289c1b69ecb673e626e1597a5ecef20303233866","price":"0.51","side":"SELL","size":"65"}],"timestamp":"1785207339942"},"payload_hash":"169b1db930ad4ca820220cd94d50638e2ab5b8341710e807c647efc02928c636","raw_frame":"{\"market\":\"0x779291bef19b6709f61e9764a954aafe9ffae488d50ae674aabdcb4f248006d5\", \"price_changes\":[{\"asset_id\":\"8761897749749422724209054078244794145777693856614463256546737399611489089783\", \"price\":\"0.49\", \"size\":\"65\", \"side\":\"BUY\", \"hash\":\"e436dcaa1e3fdc425b7c4e2b7f8ac80c32e5ff2a\", \"best_bid\":\"0.49\", \"best_ask\":\"0.5\"}, {\"asset_id\":\"14965588658799411272385430903075831224615961675357217884735713260981483529984\", \"price\":\"0.51\", \"size\":\"65\", \"side\":\"SELL\", \"hash\":\"289c1b69ecb673e626e1597a5ecef20303233866\", \"best_bid\":\"0.5\", \"best_ask\":\"0.51\"}], \"timestamp\":\"1785207339942\", \"event_type\":\"price_change\"}","received_at":"2026-07-28T02:55:40.397597Z","schema_version":"clob-market-ws.price_change.v1","sequence":null,"server_hash":null,"server_timestamp":"1785207339942","session_id":"3e519d9098404c15b234d96025eb1a2b","source":"clob_market_ws"},"received_at":"2026-07-28T02:55:40.397597Z","record_id":"1d4310a6ad872d96c183f14993de20856d7b3ac83d219cbfe43e4ffa36a86e55","schema_fingerprint":"4aa3821a28b0b7c2400bc59aba4bcc0a76e971dadd19610d3ad38c768e124dc7","schema_version":"edge-lab-recorder.raw.v1","sequence":null,"source":"clob_market_ws"}
{"event_at":"2026-07-28T02:55:39.943000Z","event_fingerprint":"80822d7e32c65c32c421fd654c9c64be1868eaa764dc8b8c21b2bce2e8ac2ed8","payload":{"connection_id":"a6b55582af5f430fb37ad02bf0922475","event_at":"2026-07-28T02:55:39.943000Z","event_type":"price_change","frame_hash":"9db7fb558b7eb526169f693696ca7973695ae361fadc715448444bc53cd3e54a","frame_index":0,"kind":"data","monotonic_ns":309323418679625,"payload":{"event_type":"price_change","market":"0x779291bef19b6709f61e9764a954aafe9ffae488d50ae674aabdcb4f248006d5","price_changes":[{"asset_id":"14965588658799411272385430903075831224615961675357217884735713260981483529984","best_ask":"0.51","best_bid":"0.5","hash":"f5ded4aa5c13bff51c8247ba89c20f13e7f94749","price":"0.47","side":"BUY","size":"314.67"},{"asset_id":"8761897749749422724209054078244794145777693856614463256546737399611489089783","best_ask":"0.5","best_bid":"0.49","hash":"5b8398c9c8a087cbf422b378e6429fd3cca9e17f","price":"0.53","side":"SELL","size":"314.67"}],"timestamp":"1785207339943"},"payload_hash":"7c1036531c9750112b40b29dd32bb334ebb90ae814b3044e73f6829f2974865a","raw_frame":"{\"market\":\"0x779291bef19b6709f61e9764a954aafe9ffae488d50ae674aabdcb4f248006d5\", \"price_changes\":[{\"asset_id\":\"14965588658799411272385430903075831224615961675357217884735713260981483529984\", \"price\":\"0.47\", \"size\":\"314.67\", \"side\":\"BUY\", \"hash\":\"f5ded4aa5c13bff51c8247ba89c20f13e7f94749\", \"best_bid\":\"0.5\", \"best_ask\":\"0.51\"}, {\"asset_id\":\"8761897749749422724209054078244794145777693856614463256546737399611489089783\", \"price\":\"0.53\", \"size\":\"314.67\", \"side\":\"SELL\", \"hash\":\"5b8398c9c8a087cbf422b378e6429fd3cca9e17f\", \"best_bid\":\"0.49\", \"best_ask\":\"0.5\"}], \"timestamp\":\"1785207339943\", \"event_type\":\"price_change\"}","received_at":"2026-07-28T02:55:40.402191Z","schema_version":"clob-market-ws.price_change.v1","sequence":null,"server_hash":null,"server_timestamp":"1785207339943","session_id":"3e519d9098404c15b234d96025eb1a2b","source":"clob_market_ws"},"received_at":"2026-07-28T02:55:40.402191Z","record_id":"b49e2d0319a3e6c53baf59c2064a6b3af599040d9744bae3f1d7dcb76a406034","schema_fingerprint":"4aa3821a28b0b7c2400bc59aba4bcc0a76e971dadd19610d3ad38c768e124dc7","schema_version":"edge-lab-recorder.raw.v1","sequence":null,"source":"clob_market_ws"}
{"event_at":"2026-07-28T02:55:39.944000Z","event_fingerprint":"8a073cd79199fc2fd710f4dcf0ebe0b67d65952ac71a1a864ab7c428ac9250b2","payload":{"connection_id":"a6b55582af5f430fb37ad02bf0922475","event_at":"2026-07-28T02:55:39.944000Z","event_type":"price_change","frame_hash":"b1c9fc7631e63ccea4746bbdfd2ceb918aa776d3ec2b9163fbf30c98d13517f3","frame_index":0,"kind":"data","monotonic_ns":309323423214000,"payload":{"event_type":"price_change","market":"0x779291bef19b6709f61e9764a954aafe9ffae488d50ae674aabdcb4f248006d5","price_changes":[{"asset_id":"8761897749749422724209054078244794145777693856614463256546737399611489089783","best_ask":"0.5","best_bid":"0.49","hash":"5e4f00f9706293136e9b0c4c77147fb0d4906f1a","price":"0.49","side":"BUY","size":"70"},{"asset_id":"14965588658799411272385430903075831224615961675357217884735713260981483529984","best_ask":"0.51","best_bid":"0.5","hash":"59dc7aea459f24231c430415f65af464d7c5c315","price":"0.51","side":"SELL","size":"70"}],"timestamp":"1785207339944"},"payload_hash":"82c92f58606839920d42a8e8cb54b8d0748ff6777e1dfcb2b3a1483e7aea8b13","raw_frame":"{\"market\":\"0x779291bef19b6709f61e9764a954aafe9ffae488d50ae674aabdcb4f248006d5\", \"price_changes\":[{\"asset_id\":\"8761897749749422724209054078244794145777693856614463256546737399611489089783\", \"price\":\"0.49\", \"size\":\"70\", \"side\":\"BUY\", \"hash\":\"5e4f00f9706293136e9b0c4c77147fb0d4906f1a\", \"best_bid\":\"0.49\", \"best_ask\":\"0.5\"}, {\"asset_id\":\"14965588658799411272385430903075831224615961675357217884735713260981483529984\", \"price\":\"0.51\", \"size\":\"70\", \"side\":\"SELL\", \"hash\":\"59dc7aea459f24231c430415f65af464d7c5c315\", \"best_bid\":\"0.5\", \"best_ask\":\"0.51\"}], \"timestamp\":\"1785207339944\", \"event_type\":\"price_change\"}","received_at":"2026-07-28T02:55:40.406726Z","schema_version":"clob-market-ws.price_change.v1","sequence":null,"server_hash":null,"server_timestamp":"1785207339944","session_id":"3e519d9098404c15b234d96025eb1a2b","source":"clob_market_ws"},"received_at":"2026-07-28T02:55:40.406726Z","record_id":"5b4bb4762ff2e90d8d0fabd91f0c4bcc785223eb30a08a8c49adc3e2426c4dc3","schema_fingerprint":"4aa3821a28b0b7c2400bc59aba4bcc0a76e971dadd19610d3ad38c768e124dc7","schema_version":"edge-lab-recorder.raw.v1","sequence":null,"source":"clob_market_ws"}
