{"event_at":"2026-07-28T03:02:30.974000Z","event_fingerprint":"743973bfae5cfa282a9f5074d4cbbb5300cc4efc2c84ae249439fb8c338cc47a","payload":{"connection_id":"a6b55582af5f430fb37ad02bf0922475","event_at":"2026-07-28T03:02:30.974000Z","event_type":"price_change","frame_hash":"8b476cca76b1edcab8d6788459fb9ce3fbbdcd42a65dc5ebbd1715fabd043eb8","frame_index":0,"kind":"data","monotonic_ns":309733846005000,"payload":{"event_type":"price_change","market":"0x779291bef19b6709f61e9764a954aafe9ffae488d50ae674aabdcb4f248006d5","price_changes":[{"asset_id":"8761897749749422724209054078244794145777693856614463256546737399611489089783","best_ask":"0.51","best_bid":"0.5","hash":"20ad717d6741cd88e0a363ce18344f83f33f347d","price":"0.5","side":"BUY","size":"71.18"},{"asset_id":"14965588658799411272385430903075831224615961675357217884735713260981483529984","best_ask":"0.5","best_bid":"0.49","hash":"c8269d3bd11c8d92603f8d9a440367452bccb44e","price":"0.5","side":"SELL","size":"71.18"}],"timestamp":"1785207750974"},"payload_hash":"8c50e0bda3ba708421cb952f5b82dfe4cbe4f23ebb65dde1fa82839587ed6952","raw_frame":"{\"market\":\"0x779291bef19b6709f61e9764a954aafe9ffae488d50ae674aabdcb4f248006d5\", \"price_changes\":[{\"asset_id\":\"8761897749749422724209054078244794145777693856614463256546737399611489089783\", \"price\":\"0.5\", \"size\":\"71.18\", \"side\":\"BUY\", \"hash\":\"20ad717d6741cd88e0a363ce18344f83f33f347d\", \"best_bid\":\"0.5\", \"best_ask\":\"0.51\"}, {\"asset_id\":\"14965588658799411272385430903075831224615961675357217884735713260981483529984\", \"price\":\"0.5\", \"size\":\"71.18\", \"side\":\"SELL\", \"hash\":\"c8269d3bd11c8d92603f8d9a440367452bccb44e\", \"best_bid\":\"0.49\", \"best_ask\":\"0.5\"}], \"timestamp\":\"1785207750974\", \"event_type\":\"price_change\"}","received_at":"2026-07-28T03:02:30.826549Z","schema_version":"clob-market-ws.price_change.v1","sequence":null,"server_hash":null,"server_timestamp":"1785207750974","session_id":"3e519d9098404c15b234d96025eb1a2b","source":"clob_market_ws"},"received_at":"2026-07-28T03:02:30.826549Z","record_id":"0a14ef55c43045ecbd16fcd00e3deb5a182a445226b10bf4a7195d7db37ec80c","schema_fingerprint":"4aa3821a28b0b7c2400bc59aba4bcc0a76e971dadd19610d3ad38c768e124dc7","schema_version":"edge-lab-recorder.raw.v1","sequence":null,"source":"clob_market_ws"}
{"event_at":"2026-07-28T03:02:30.979000Z","event_fingerprint":"19b792254d5f6761e436dcda70939eaf247dfa6d6b59a18ad19b19377c386132","payload":{"connection_id":"a6b55582af5f430fb37ad02bf0922475","event_at":"2026-07-28T03:02:30.979000Z","event_type":"price_change","frame_hash":"711867446639edf4f1a48dc3e424e7e7ab02912f04180b4f1125cfeecceb5a84","frame_index":0,"kind":"data","monotonic_ns":309733851238208,"payload":{"event_type":"price_change","market":"0x779291bef19b6709f61e9764a954aafe9ffae488d50ae674aabdcb4f248006d5","price_changes":[{"asset_id":"14965588658799411272385430903075831224615961675357217884735713260981483529984","best_ask":"0.5","best_bid":"0.49","hash":"6979fd755898045073b6e972f09253b73d6a9557","price":"0.01","side":"BUY","size":"7888.02"},{"asset_id":"8761897749749422724209054078244794145777693856614463256546737399611489089783","best_ask":"0.51","best_bid":"0.5","hash":"d520f3cdbea6200c4dfad2e5d5ef4933a6f41cff","price":"0.99","side":"SELL","size":"7888.02"}],"timestamp":"1785207750979"},"payload_hash":"c8b4ec289da64ee8f783715b6284cb08f3d41ef63b7f2e5de5d8ec9aab89fe46","raw_frame":"{\"market\":\"0x779291bef19b6709f61e9764a954aafe9ffae488d50ae674aabdcb4f248006d5\", \"price_changes\":[{\"asset_id\":\"14965588658799411272385430903075831224615961675357217884735713260981483529984\", \"price\":\"0.01\", \"size\":\"7888.02\", \"side\":\"BUY\", \"hash\":\"6979fd755898045073b6e972f09253b73d6a9557\", \"best_bid\":\"0.49\", \"best_ask\":\"0.5\"}, {\"asset_id\":\"8761897749749422724209054078244794145777693856614463256546737399611489089783\", \"price\":\"0.99\", \"size\":\"7888.02\", \"side\":\"SELL\", \"hash\":\"d520f3cdbea6200c4dfad2e5d5ef4933a6f41cff\", \"best_bid\":\"0.5\", \"best_ask\":\"0.51\"}], \"timestamp\":\"1785207750979\", \"event_type\":\"price_change\"}","received_at":"2026-07-28T03:02:30.831782Z","schema_version":"clob-market-ws.price_change.v1","sequence":null,"server_hash":null,"server_timestamp":"1785207750979","session_id":"3e519d9098404c15b234d96025eb1a2b","source":"clob_market_ws"},"received_at":"2026-07-28T03:02:30.831782Z","record_id":"c90165845df91e88b4abc51f08818e93e2bd617ccb79c1c0d09a6e552ab1ebbe","schema_fingerprint":"4aa3821a28b0b7c2400bc59aba4bcc0a76e971dadd19610d3ad38c768e124dc7","schema_version":"edge-lab-recorder.raw.v1","sequence":null,"source":"clob_market_ws"}
{"event_at":"2026-07-28T03:02:30.989000Z","event_fingerprint":"9b0a7ba4efa50a889e1a95fe4f0323bc8cb2d7ba96672eba60d14eb38dfd620c","payload":{"connection_id":"a6b55582af5f430fb37ad02bf0922475","event_at":"2026-07-28T03:02:30.989000Z","event_type":"price_change","frame_hash":"6ba3a53a3294dd30b6375f6cf1062a1b56a8cc38b3f0924a5dfcda3b842119e5","frame_index":0,"kind":"data","monotonic_ns":309733860878000,"payload":{"event_type":"price_change","market":"0x779291bef19b6709f61e9764a954aafe9ffae488d50ae674aabdcb4f248006d5","price_changes":[{"asset_id":"8761897749749422724209054078244794145777693856614463256546737399611489089783","best_ask":"0.51","best_bid":"0.5","hash":"679dd987390589736f013898acae8fc4a46e1673","price":"0.01","side":"BUY","size":"7858.02"},{"asset_id":"14965588658799411272385430903075831224615961675357217884735713260981483529984","best_ask":"0.5","best_bid":"0.49","hash":"a4cc2c82ce1a228d8c9965a0389dd1cd2883d9ff","price":"0.99","side":"SELL","size":"7858.02"}],"timestamp":"1785207750989"},"payload_hash":"2942c8caa17ab473367a3b28c5561f13a1799464babf8734168ea730cbd319a2","raw_frame":"{\"market\":\"0x779291bef19b6709f61e9764a954aafe9ffae488d50ae674aabdcb4f248006d5\", \"price_changes\":[{\"asset_id\":\"8761897749749422724209054078244794145777693856614463256546737399611489089783\", \"price\":\"0.01\", \"size\":\"7858.02\", \"side\":\"BUY\", \"hash\":\"679dd987390589736f013898acae8fc4a46e1673\", \"best_bid\":\"0.5\", \"best_ask\":\"0.51\"}, {\"asset_id\":\"14965588658799411272385430903075831224615961675357217884735713260981483529984\", \"price\":\"0.99\", \"size\":\"7858.02\", \"side\":\"SELL\", \"hash\":\"a4cc2c82ce1a228d8c9965a0389dd1cd2883d9ff\", \"best_bid\":\"0.49\", \"best_ask\":\"0.5\"}], \"timestamp\":\"1785207750989\", \"event_type\":\"price_change\"}","received_at":"2026-07-28T03:02:30.841419Z","schema_version":"clob-market-ws.price_change.v1","sequence":null,"server_hash":null,"server_timestamp":"1785207750989","session_id":"3e519d9098404c15b234d96025eb1a2b","source":"clob_market_ws"},"received_at":"2026-07-28T03:02:30.841419Z","record_id":"25ed65fb80f9b4931f06fbf405a4ee0796184b838146990c4840e72bc3bc99a4","schema_fingerprint":"4aa3821a28b0b7c2400bc59aba4bcc0a76e971dadd19610d3ad38c768e124dc7","schema_version":"edge-lab-recorder.raw.v1","sequence":null,"source":"clob_market_ws"}
{"event_at":"2026-07-28T03:02:31.009000Z","event_fingerprint":"92ecfc58183d9b81b23b6c62b2a17898666a4d9dd77e04a4296bceb3b3025da3","payload":{"connection_id":"a6b55582af5f430fb37ad02bf0922475","event_at":"2026-07-28T03:02:31.009000Z","event_type":"price_change","frame_hash":"02722136e3ae01ac370afca49e258e0f01264af8fe61f9c99be90f994c61c7b7","frame_index":0,"kind":"data","monotonic_ns":309733880335458,"payload":{"event_type":"price_change","market":"0x779291bef19b6709f61e9764a954aafe9ffae488d50ae674aabdcb4f248006d5","price_changes":[{"asset_id":"14965588658799411272385430903075831224615961675357217884735713260981483529984","best_ask":"0.5","best_bid":"0.49","hash":"29932a6b2868bb6ddea8bdf28d26fbea8a0cc9b9","price":"0.38","side":"BUY","size":"206.7"},{"asset_id":"8761897749749422724209054078244794145777693856614463256546737399611489089783","best_ask":"0.51","best_bid":"0.5","hash":"f15547d6c476a80166891e735645e694a1833b9c","price":"0.62","side":"SELL","size":"206.7"}],"timestamp":"1785207751009"},"payload_hash":"444d21b97ffedf52eef29e08b733e53a1a92a6821e18961947fb0571a041b67b","raw_frame":"{\"market\":\"0x779291bef19b6709f61e9764a954aafe9ffae488d50ae674aabdcb4f248006d5\", \"price_changes\":[{\"asset_id\":\"14965588658799411272385430903075831224615961675357217884735713260981483529984\", \"price\":\"0.38\", \"size\":\"206.7\", \"side\":\"BUY\", \"hash\":\"29932a6b2868bb6ddea8bdf28d26fbea8a0cc9b9\", \"best_bid\":\"0.49\", \"best_ask\":\"0.5\"}, {\"asset_id\":\"8761897749749422724209054078244794145777693856614463256546737399611489089783\", \"price\":\"0.62\", \"size\":\"206.7\", \"side\":\"SELL\", \"hash\":\"f15547d6c476a80166891e735645e694a1833b9c\", \"best_bid\":\"0.5\", \"best_ask\":\"0.51\"}], \"timestamp\":\"1785207751009\", \"event_type\":\"price_change\"}","received_at":"2026-07-28T03:02:30.860880Z","schema_version":"clob-market-ws.price_change.v1","sequence":null,"server_hash":null,"server_timestamp":"1785207751009","session_id":"3e519d9098404c15b234d96025eb1a2b","source":"clob_market_ws"},"received_at":"2026-07-28T03:02:30.860880Z","record_id":"f0fe8fb3597fe5a19fb80f0fea5f4be5becff751181cde4fe0891906ce5497f0","schema_fingerprint":"4aa3821a28b0b7c2400bc59aba4bcc0a76e971dadd19610d3ad38c768e124dc7","schema_version":"edge-lab-recorder.raw.v1","sequence":null,"source":"clob_market_ws"}
{"event_at":"2026-07-28T03:02:31.009000Z","event_fingerprint":"9b276105957728796956ac75eeb637a551cc8483d8b51e18410478061bb983de","payload":{"connection_id":"a6b55582af5f430fb37ad02bf0922475","event_at":"2026-07-28T03:02:31.009000Z","event_type":"price_change","frame_hash":"19f081f06adfd0a3c1a2ebb0bad233cfe8c46bc4693ae33e50b5bfb9da0f6b46","frame_index":0,"kind":"data","monotonic_ns":309733881960791,"payload":{"event_type":"price_change","market":"0x779291bef19b6709f61e9764a954aafe9ffae488d50ae674aabdcb4f248006d5","price_changes":[{"asset_id":"8761897749749422724209054078244794145777693856614463256546737399611489089783","best_ask":"0.51","best_bid":"0.5","hash":"f15547d6c476a80166891e735645e694a1833b9c","price":"0.48","side":"BUY","size":"384"},{"asset_id":"14965588658799411272385430903075831224615961675357217884735713260981483529984","best_ask":"0.5","best_bid":"0.49","hash":"29932a6b2868bb6ddea8bdf28d26fbea8a0cc9b9","price":"0.52","side":"SELL","size":"384"}],"timestamp":"1785207751009"},"payload_hash":"7c8d3822abae692439530754d48407b191af8f84f96ab63616e59a3b5418c079","raw_frame":"{\"market\":\"0x779291bef19b6709f61e9764a954aafe9ffae488d50ae674aabdcb4f248006d5\", \"price_changes\":[{\"asset_id\":\"8761897749749422724209054078244794145777693856614463256546737399611489089783\", \"price\":\"0.48\", \"size\":\"384\", \"side\":\"BUY\", \"hash\":\"f15547d6c476a80166891e735645e694a1833b9c\", \"best_bid\":\"0.5\", \"best_ask\":\"0.51\"}, {\"asset_id\":\"14965588658799411272385430903075831224615961675357217884735713260981483529984\", \"price\":\"0.52\", \"size\":\"384\", \"side\":\"SELL\", \"hash\":\"29932a6b2868bb6ddea8bdf28d26fbea8a0cc9b9\", \"best_bid\":\"0.49\", \"best_ask\":\"0.5\"}], \"timestamp\":\"1785207751009\", \"event_type\":\"price_change\"}","received_at":"2026-07-28T03:02:30.862504Z","schema_version":"clob-market-ws.price_change.v1","sequence":null,"server_hash":null,"server_timestamp":"1785207751009","session_id":"3e519d9098404c15b234d96025eb1a2b","source":"clob_market_ws"},"received_at":"2026-07-28T03:02:30.862504Z","record_id":"23a1e20a96c38de1456bda8acc0af89a9672d9042af3cdc411eeeb868adab82d","schema_fingerprint":"4aa3821a28b0b7c2400bc59aba4bcc0a76e971dadd19610d3ad38c768e124dc7","schema_version":"edge-lab-recorder.raw.v1","sequence":null,"source":"clob_market_ws"}
{"event_at":"2026-07-28T03:02:31.015000Z","event_fingerprint":"3cdf5b6d6d2da278132c67cd3d073232fe086532cbe14d7d98746e942c762ba5","payload":{"connection_id":"a6b55582af5f430fb37ad02bf0922475","event_at":"2026-07-28T03:02:31.015000Z","event_type":"price_change","frame_hash":"3dbe1af2f58c0b4804cb94dd786015ec1d78127ac7222a098248853efcd02a6b","frame_index":0,"kind":"data","monotonic_ns":309733886422625,"payload":{"event_type":"price_change","market":"0x779291bef19b6709f61e9764a954aafe9ffae488d50ae674aabdcb4f248006d5","price_changes":[{"asset_id":"14965588658799411272385430903075831224615961675357217884735713260981483529984","best_ask":"0.5","best_bid":"0.49","hash":"da9839e03a3f21d8e267dde7046b1c19472ff18e","price":"0.01","side":"BUY","size":"7883.02"},{"asset_id":"8761897749749422724209054078244794145777693856614463256546737399611489089783","best_ask":"0.51","best_bid":"0.5","hash":"3b78a51532809c4f52d860e4f95261457604046d","price":"0.99","side":"SELL","size":"7883.02"}],"timestamp":"1785207751015"},"payload_hash":"c40e3b5c769af3610d2dde7ce928e662cf83bc2d2da0f6e2bcfd067151a81382","raw_frame":"{\"market\":\"0x779291bef19b6709f61e9764a954aafe9ffae488d50ae674aabdcb4f248006d5\", \"price_changes\":[{\"asset_id\":\"14965588658799411272385430903075831224615961675357217884735713260981483529984\", \"price\":\"0.01\", \"size\":\"7883.02\", \"side\":\"BUY\", \"hash\":\"da9839e03a3f21d8e267dde7046b1c19472ff18e\", \"best_bid\":\"0.49\", \"best_ask\":\"0.5\"}, {\"asset_id\":\"8761897749749422724209054078244794145777693856614463256546737399611489089783\", \"price\":\"0.99\", \"size\":\"7883.02\", \"side\":\"SELL\", \"hash\":\"3b78a51532809c4f52d860e4f95261457604046d\", \"best_bid\":\"0.5\", \"best_ask\":\"0.51\"}], \"timestamp\":\"1785207751015\", \"event_type\":\"price_change\"}","received_at":"2026-07-28T03:02:30.866967Z","schema_version":"clob-market-ws.price_change.v1","sequence":null,"server_hash":null,"server_timestamp":"1785207751015","session_id":"3e519d9098404c15b234d96025eb1a2b","source":"clob_market_ws"},"received_at":"2026-07-28T03:02:30.866967Z","record_id":"0a54eade02a6adb2772820810310b36e79bf42b67f57d80f0b87c87c3aff4144","schema_fingerprint":"4aa3821a28b0b7c2400bc59aba4bcc0a76e971dadd19610d3ad38c768e124dc7","schema_version":"edge-lab-recorder.raw.v1","sequence":null,"source":"clob_market_ws"}
{"event_at":"2026-07-28T03:02:31.015000Z","event_fingerprint":"64f3b18bc536d183a55c0a3f0e0ccba6c1dcc2f1e604f80898d050eefd9d578f","payload":{"connection_id":"a6b55582af5f430fb37ad02bf0922475","event_at":"2026-07-28T03:02:31.015000Z","event_type":"price_change","frame_hash":"7b069f83ac91ee44eab6bd0eedce3396832d87677a3623ebc36306e06629b9d0","frame_index":0,"kind":"data","monotonic_ns":309733888025208,"payload":{"event_type":"price_change","market":"0x779291bef19b6709f61e9764a954aafe9ffae488d50ae674aabdcb4f248006d5","price_changes":[{"asset_id":"8761897749749422724209054078244794145777693856614463256546737399611489089783","best_ask":"0.51","best_bid":"0.5","hash":"a37b421c3cdb4337be7cfcf7bd966c0c4b7b94c4","price":"0.04","side":"BUY","size":"643.09"},{"asset_id":"14965588658799411272385430903075831224615961675357217884735713260981483529984","best_ask":"0.5","best_bid":"0.49","hash":"6c22ceb53078aefd8a9f8f90e3d513ff1858745f","price":"0.96","side":"SELL","size":"643.09"}],"timestamp":"1785207751015"},"payload_hash":"8961479b4efb13e48cf03b0a574e1dda5147ce270c82f287e6a1f10ba8c77ae6","raw_frame":"{\"market\":\"0x779291bef19b6709f61e9764a954aafe9ffae488d50ae674aabdcb4f248006d5\", \"price_changes\":[{\"asset_id\":\"8761897749749422724209054078244794145777693856614463256546737399611489089783\", \"price\":\"0.04\", \"size\":\"643.09\", \"side\":\"BUY\", \"hash\":\"a37b421c3cdb4337be7cfcf7bd966c0c4b7b94c4\", \"best_bid\":\"0.5\", \"best_ask\":\"0.51\"}, {\"asset_id\":\"14965588658799411272385430903075831224615961675357217884735713260981483529984\", \"price\":\"0.96\", \"size\":\"643.09\", \"side\":\"SELL\", \"hash\":\"6c22ceb53078aefd8a9f8f90e3d513ff1858745f\", \"best_bid\":\"0.49\", \"best_ask\":\"0.5\"}], \"timestamp\":\"1785207751015\", \"event_type\":\"price_change\"}","received_at":"2026-07-28T03:02:30.868568Z","schema_version":"clob-market-ws.price_change.v1","sequence":null,"server_hash":null,"server_timestamp":"1785207751015","session_id":"3e519d9098404c15b234d96025eb1a2b","source":"clob_market_ws"},"received_at":"2026-07-28T03:02:30.868568Z","record_id":"b0f47eac80cbdecbf57d841c71298b5e69fae6017931b0f02c71402b10a638a5","schema_fingerprint":"4aa3821a28b0b7c2400bc59aba4bcc0a76e971dadd19610d3ad38c768e124dc7","schema_version":"edge-lab-recorder.raw.v1","sequence":null,"source":"clob_market_ws"}
{"event_at":"2026-07-28T03:02:31.027000Z","event_fingerprint":"89dd3ddb1fdfc8159a2c2bb43c91cfadeb1ce74f37367ce887bd3e421b0ea9d6","payload":{"connection_id":"a6b55582af5f430fb37ad02bf0922475","event_at":"2026-07-28T03:02:31.027000Z","event_type":"price_change","frame_hash":"2b88889116252ed94314a7e749c625e864fb06efa809f572ea802430f1649fb2","frame_index":0,"kind":"data","monotonic_ns":309733900186041,"payload":{"event_type":"price_change","market":"0x779291bef19b6709f61e9764a954aafe9ffae488d50ae674aabdcb4f248006d5","price_changes":[{"asset_id":"14965588658799411272385430903075831224615961675357217884735713260981483529984","best_ask":"0.5","best_bid":"0.49","hash":"bd0ea35f04d31f2bd8595ae00ae8ac55f007bd37","price":"0.01","side":"BUY","size":"7888.02"},{"asset_id":"8761897749749422724209054078244794145777693856614463256546737399611489089783","best_ask":"0.51","best_bid":"0.5","hash":"f8330dc9e819214d98698c52b6731d42bb636035","price":"0.99","side":"SELL","size":"7888.02"}],"timestamp":"1785207751027"},"payload_hash":"6858c026b63aaca84e3f3c02313fb58d33ec44e61883566d68561cfe52c216cd","raw_frame":"{\"market\":\"0x779291bef19b6709f61e9764a954aafe9ffae488d50ae674aabdcb4f248006d5\", \"price_changes\":[{\"asset_id\":\"14965588658799411272385430903075831224615961675357217884735713260981483529984\", \"price\":\"0.01\", \"size\":\"7888.02\", \"side\":\"BUY\", \"hash\":\"bd0ea35f04d31f2bd8595ae00ae8ac55f007bd37\", \"best_bid\":\"0.49\", \"best_ask\":\"0.5\"}, {\"asset_id\":\"8761897749749422724209054078244794145777693856614463256546737399611489089783\", \"price\":\"0.99\", \"size\":\"7888.02\", \"side\":\"SELL\", \"hash\":\"f8330dc9e819214d98698c52b6731d42bb636035\", \"best_bid\":\"0.5\", \"best_ask\":\"0.51\"}], \"timestamp\":\"1785207751027\", \"event_type\":\"price_change\"}","received_at":"2026-07-28T03:02:30.880732Z","schema_version":"clob-market-ws.price_change.v1","sequence":null,"server_hash":null,"server_timestamp":"1785207751027","session_id":"3e519d9098404c15b234d96025eb1a2b","source":"clob_market_ws"},"received_at":"2026-07-28T03:02:30.880732Z","record_id":"1c60116d1cf21721e929370b5c0ba949f269c097fc8a69afa19f0c379eff8541","schema_fingerprint":"4aa3821a28b0b7c2400bc59aba4bcc0a76e971dadd19610d3ad38c768e124dc7","schema_version":"edge-lab-recorder.raw.v1","sequence":null,"source":"clob_market_ws"}
{"event_at":"2026-07-28T03:02:31.049000Z","event_fingerprint":"c6bfba839d2ebf46544ac43cd1b9bc6858672aa50e15c212748f15ebe63f7ec7","payload":{"connection_id":"a6b55582af5f430fb37ad02bf0922475","event_at":"2026-07-28T03:02:31.049000Z","event_type":"price_change","frame_hash":"b72336e60eab7fcbfa2210c227947dddd43aa5bb9b3cc5573ee062999e607fc1","frame_index":0,"kind":"data","monotonic_ns":309733920805916,"payload":{"event_type":"price_change","market":"0x779291bef19b6709f61e9764a954aafe9ffae488d50ae674aabdcb4f248006d5","price_changes":[{"asset_id":"14965588658799411272385430903075831224615961675357217884735713260981483529984","best_ask":"0.5","best_bid":"0.49","hash":"71d32208a35dfeb84bee08b28ba8173739b6e77f","price":"0.42","side":"BUY","size":"203.32"},{"asset_id":"8761897749749422724209054078244794145777693856614463256546737399611489089783","best_ask":"0.51","best_bid":"0.5","hash":"8cd45b02913f315de91a3f33c3af1d29e32bf5bd","price":"0.58","side":"SELL","size":"203.32"}],"timestamp":"1785207751049"},"payload_hash":"0cb1d60a9841d87c1effe6258e694b7a89887e3bb2ec1cd1642ca0bdfefe26f1","raw_frame":"{\"market\":\"0x779291bef19b6709f61e9764a954aafe9ffae488d50ae674aabdcb4f248006d5\", \"price_changes\":[{\"asset_id\":\"14965588658799411272385430903075831224615961675357217884735713260981483529984\", \"price\":\"0.42\", \"size\":\"203.32\", \"side\":\"BUY\", \"hash\":\"71d32208a35dfeb84bee08b28ba8173739b6e77f\", \"best_bid\":\"0.49\", \"best_ask\":\"0.5\"}, {\"asset_id\":\"8761897749749422724209054078244794145777693856614463256546737399611489089783\", \"price\":\"0.58\", \"size\":\"203.32\", \"side\":\"SELL\", \"hash\":\"8cd45b02913f315de91a3f33c3af1d29e32bf5bd\", \"best_bid\":\"0.5\", \"best_ask\":\"0.51\"}], \"timestamp\":\"1785207751049\", \"event_type\":\"price_change\"}","received_at":"2026-07-28T03:02:30.901351Z","schema_version":"clob-market-ws.price_change.v1","sequence":null,"server_hash":null,"server_timestamp":"1785207751049","session_id":"3e519d9098404c15b234d96025eb1a2b","source":"clob_market_ws"},"received_at":"2026-07-28T03:02:30.901351Z","record_id":"4e577e16b261e49c19e529ce6004b4287cc73acbe1037bafe78fbdb48638a317","schema_fingerprint":"4aa3821a28b0b7c2400bc59aba4bcc0a76e971dadd19610d3ad38c768e124dc7","schema_version":"edge-lab-recorder.raw.v1","sequence":null,"source":"clob_market_ws"}
{"event_at":"2026-07-28T03:02:31.050000Z","event_fingerprint":"55b0ff2bb8bc1d5ce82d4a5439f14c609eccd698c89fd9527eb35a2b2b67bc56","payload":{"connection_id":"a6b55582af5f430fb37ad02bf0922475","event_at":"2026-07-28T03:02:31.050000Z","event_type":"price_change","frame_hash":"ba90ae1049e2d62a0bdc6dac74341cb2d7d3189ef17419a3316dde3bbae62d02","frame_index":0,"kind":"data","monotonic_ns":309733923065083,"payload":{"event_type":"price_change","market":"0x779291bef19b6709f61e9764a954aafe9ffae488d50ae674aabdcb4f248006d5","price_changes":[{"asset_id":"8761897749749422724209054078244794145777693856614463256546737399611489089783","best_ask":"0.51","best_bid":"0.5","hash":"d1bc2f15321420b312686cea9f2d0cc90c66ff2d","price":"0.44","side":"BUY","size":"308.15"},{"asset_id":"14965588658799411272385430903075831224615961675357217884735713260981483529984","best_ask":"0.5","best_bid":"0.49","hash":"1e946e04467613025ca6d4533170d6bfbec0a57d","price":"0.56","side":"SELL","size":"308.15"}],"timestamp":"1785207751050"},"payload_hash":"7a19d23762f74dd4087dc4e4347824c33b7b7e7e6a617620da561dc854688980","raw_frame":"{\"market\":\"0x779291bef19b6709f61e9764a954aafe9ffae488d50ae674aabdcb4f248006d5\", \"price_changes\":[{\"asset_id\":\"8761897749749422724209054078244794145777693856614463256546737399611489089783\", \"price\":\"0.44\", \"size\":\"308.15\", \"side\":\"BUY\", \"hash\":\"d1bc2f15321420b312686cea9f2d0cc90c66ff2d\", \"best_bid\":\"0.5\", \"best_ask\":\"0.51\"}, {\"asset_id\":\"14965588658799411272385430903075831224615961675357217884735713260981483529984\", \"price\":\"0.56\", \"size\":\"308.15\", \"side\":\"SELL\", \"hash\":\"1e946e04467613025ca6d4533170d6bfbec0a57d\", \"best_bid\":\"0.49\", \"best_ask\":\"0.5\"}], \"timestamp\":\"1785207751050\", \"event_type\":\"price_change\"}","received_at":"2026-07-28T03:02:30.903609Z","schema_version":"clob-market-ws.price_change.v1","sequence":null,"server_hash":null,"server_timestamp":"1785207751050","session_id":"3e519d9098404c15b234d96025eb1a2b","source":"clob_market_ws"},"received_at":"2026-07-28T03:02:30.903609Z","record_id":"39e1ed70d46817e822980126662e759efdd0ea5e951f42dab94f6462ccc8b477","schema_fingerprint":"4aa3821a28b0b7c2400bc59aba4bcc0a76e971dadd19610d3ad38c768e124dc7","schema_version":"edge-lab-recorder.raw.v1","sequence":null,"source":"clob_market_ws"}
{"event_at":"2026-07-28T03:02:31.066000Z","event_fingerprint":"065ac3d24f4f60e4ab200e49504f71d1b35ddea418ffef9ee6879c70b20d873f","payload":{"connection_id":"a6b55582af5f430fb37ad02bf0922475","event_at":"2026-07-28T03:02:31.066000Z","event_type":"price_change","frame_hash":"ddcbd21328858c4a94e76db70b572c68dcf3dd150d45abbb0aab9cc1af96d7f2","frame_index":0,"kind":"data","monotonic_ns":309733937141291,"payload":{"event_type":"price_change","market":"0x779291bef19b6709f61e9764a954aafe9ffae488d50ae674aabdcb4f248006d5","price_changes":[{"asset_id":"14965588658799411272385430903075831224615961675357217884735713260981483529984","best_ask":"0.5","best_bid":"0.49","hash":"6fcfbba798d7b9933fb1401daadb6fe92db91909","price":"0.01","side":"BUY","size":"7883.02"},{"asset_id":"8761897749749422724209054078244794145777693856614463256546737399611489089783","best_ask":"0.51","best_bid":"0.5","hash":"f7c6b5bdecafdbe24221ee0b1f0b81befe94a198","price":"0.99","side":"SELL","size":"7883.02"}],"timestamp":"1785207751066"},"payload_hash":"f371b4911d8f06cb5f021cbdd829fbc19ec86cb2a44227141377be13d1a83e76","raw_frame":"{\"market\":\"0x779291bef19b6709f61e9764a954aafe9ffae488d50ae674aabdcb4f248006d5\", \"price_changes\":[{\"asset_id\":\"14965588658799411272385430903075831224615961675357217884735713260981483529984\", \"price\":\"0.01\", \"size\":\"7883.02\", \"side\":\"BUY\", \"hash\":\"6fcfbba798d7b9933fb1401daadb6fe92db91909\", \"best_bid\":\"0.49\", \"best_ask\":\"0.5\"}, {\"asset_id\":\"8761897749749422724209054078244794145777693856614463256546737399611489089783\", \"price\":\"0.99\", \"size\":\"7883.02\", \"side\":\"SELL\", \"hash\":\"f7c6b5bdecafdbe24221ee0b1f0b81befe94a198\", \"best_bid\":\"0.5\", \"best_ask\":\"0.51\"}], \"timestamp\":\"1785207751066\", \"event_type\":\"price_change\"}","received_at":"2026-07-28T03:02:30.917685Z","schema_version":"clob-market-ws.price_change.v1","sequence":null,"server_hash":null,"server_timestamp":"1785207751066","session_id":"3e519d9098404c15b234d96025eb1a2b","source":"clob_market_ws"},"received_at":"2026-07-28T03:02:30.917685Z","record_id":"e4757a205cd137ea93c123c3cac22e1e421121bd13db1d89b0dab8c0c9f70510","schema_fingerprint":"4aa3821a28b0b7c2400bc59aba4bcc0a76e971dadd19610d3ad38c768e124dc7","schema_version":"edge-lab-recorder.raw.v1","sequence":null,"source":"clob_market_ws"}
{"event_at":"2026-07-28T03:02:31.081000Z","event_fingerprint":"06b8c08f31c5b25d7dd1c1cfb4f53cf35c920f9ee75f729a320d190584db5e9f","payload":{"connection_id":"a6b55582af5f430fb37ad02bf0922475","event_at":"2026-07-28T03:02:31.081000Z","event_type":"price_change","frame_hash":"db90ece8a7c4f0967e9f8ec630c1080cb3389cf66a6c51891902529493a92d36","frame_index":0,"kind":"data","monotonic_ns":309733952947791,"payload":{"event_type":"price_change","market":"0x779291bef19b6709f61e9764a954aafe9ffae488d50ae674aabdcb4f248006d5","price_changes":[{"asset_id":"14965588658799411272385430903075831224615961675357217884735713260981483529984","best_ask":"0.5","best_bid":"0.49","hash":"22a4b1afc6c39f749e7499272b3aa73235a61aa5","price":"0.01","side":"BUY","size":"7888.02"},{"asset_id":"8761897749749422724209054078244794145777693856614463256546737399611489089783","best_ask":"0.51","best_bid":"0.5","hash":"4716173204f0e43c393183264b834e5364c3e152","price":"0.99","side":"SELL","size":"7888.02"}],"timestamp":"1785207751081"},"payload_hash":"b8d9c4474e4d79085f1c71288b3f0f87db2bc9ddafd1adea9a5b29b3edc56759","raw_frame":"{\"market\":\"0x779291bef19b6709f61e9764a954aafe9ffae488d50ae674aabdcb4f248006d5\", \"price_changes\":[{\"asset_id\":\"14965588658799411272385430903075831224615961675357217884735713260981483529984\", \"price\":\"0.01\", \"size\":\"7888.02\", \"side\":\"BUY\", \"hash\":\"22a4b1afc6c39f749e7499272b3aa73235a61aa5\", \"best_bid\":\"0.49\", \"best_ask\":\"0.5\"}, {\"asset_id\":\"8761897749749422724209054078244794145777693856614463256546737399611489089783\", \"price\":\"0.99\", \"size\":\"7888.02\", \"side\":\"SELL\", \"hash\":\"4716173204f0e43c393183264b834e5364c3e152\", \"best_bid\":\"0.5\", \"best_ask\":\"0.51\"}], \"timestamp\":\"1785207751081\", \"event_type\":\"price_change\"}","received_at":"2026-07-28T03:02:30.933492Z","schema_version":"clob-market-ws.price_change.v1","sequence":null,"server_hash":null,"server_timestamp":"1785207751081","session_id":"3e519d9098404c15b234d96025eb1a2b","source":"clob_market_ws"},"received_at":"2026-07-28T03:02:30.933492Z","record_id":"25ba25b84f213a29bded7259eac2cb2a76892f215a18d3155892b6812ffdfb69","schema_fingerprint":"4aa3821a28b0b7c2400bc59aba4bcc0a76e971dadd19610d3ad38c768e124dc7","schema_version":"edge-lab-recorder.raw.v1","sequence":null,"source":"clob_market_ws"}
{"event_at":"2026-07-28T03:02:31.082000Z","event_fingerprint":"75fa51f37111634a08dd09defd966ceaa369535f9d0143df02a989d79576cf5d","payload":{"connection_id":"a6b55582af5f430fb37ad02bf0922475","event_at":"2026-07-28T03:02:31.082000Z","event_type":"price_change","frame_hash":"d7abb8d9bf9619faabebc6e50632f0fe47ffb562eecb93dbc0a4d3779ed7488a","frame_index":0,"kind":"data","monotonic_ns":309733954535458,"payload":{"event_type":"price_change","market":"0x779291bef19b6709f61e9764a954aafe9ffae488d50ae674aabdcb4f248006d5","price_changes":[{"asset_id":"8761897749749422724209054078244794145777693856614463256546737399611489089783","best_ask":"0.51","best_bid":"0.5","hash":"54ae28a7d2be18d16f6f05355badde672d9dfc06","price":"0.01","side":"BUY","size":"7853.02"},{"asset_id":"14965588658799411272385430903075831224615961675357217884735713260981483529984","best_ask":"0.5","best_bid":"0.49","hash":"04e309387761d77adcf000873ba87d5844d3dcf3","price":"0.99","side":"SELL","size":"7853.02"}],"timestamp":"1785207751082"},"payload_hash":"c39423e5cda85e5e65add5a81674ef0ed31dd8d1b41e6a25c0a0332023900eed","raw_frame":"{\"market\":\"0x779291bef19b6709f61e9764a954aafe9ffae488d50ae674aabdcb4f248006d5\", \"price_changes\":[{\"asset_id\":\"8761897749749422724209054078244794145777693856614463256546737399611489089783\", \"price\":\"0.01\", \"size\":\"7853.02\", \"side\":\"BUY\", \"hash\":\"54ae28a7d2be18d16f6f05355badde672d9dfc06\", \"best_bid\":\"0.5\", \"best_ask\":\"0.51\"}, {\"asset_id\":\"14965588658799411272385430903075831224615961675357217884735713260981483529984\", \"price\":\"0.99\", \"size\":\"7853.02\", \"side\":\"SELL\", \"hash\":\"04e309387761d77adcf000873ba87d5844d3dcf3\", \"best_bid\":\"0.49\", \"best_ask\":\"0.5\"}], \"timestamp\":\"1785207751082\", \"event_type\":\"price_change\"}","received_at":"2026-07-28T03:02:30.935081Z","schema_version":"clob-market-ws.price_change.v1","sequence":null,"server_hash":null,"server_timestamp":"1785207751082","session_id":"3e519d9098404c15b234d96025eb1a2b","source":"clob_market_ws"},"received_at":"2026-07-28T03:02:30.935081Z","record_id":"0114e05c0f21fc43fa15dadbfd296c20e0e827a70ec5e02c267b46df4931b35b","schema_fingerprint":"4aa3821a28b0b7c2400bc59aba4bcc0a76e971dadd19610d3ad38c768e124dc7","schema_version":"edge-lab-recorder.raw.v1","sequence":null,"source":"clob_market_ws"}
{"event_at":"2026-07-28T03:02:31.100000Z","event_fingerprint":"a6ccaf8c352bde4b506bfc75ba234495e03bdd596cc864c5f10682c96decf692","payload":{"connection_id":"a6b55582af5f430fb37ad02bf0922475","event_at":"2026-07-28T03:02:31.100000Z","event_type":"price_change","frame_hash":"05e6ee89b2e1a4afa592808761e3a6a043981ee80431acbbce53ae3089f93992","frame_index":0,"kind":"data","monotonic_ns":309733971962791,"payload":{"event_type":"price_change","market":"0x779291bef19b6709f61e9764a954aafe9ffae488d50ae674aabdcb4f248006d5","price_changes":[{"asset_id":"8761897749749422724209054078244794145777693856614463256546737399611489089783","best_ask":"0.51","best_bid":"0.5","hash":"83c8f04286d1061b1e3d7c65af22b14528242b18","price":"0.04","side":"BUY","size":"638.09"},{"asset_id":"14965588658799411272385430903075831224615961675357217884735713260981483529984","best_ask":"0.5","best_bid":"0.49","hash":"112b35af8757b56f0147b4eba7204c70e8f0583e","price":"0.96","side":"SELL","size":"638.09"}],"timestamp":"1785207751100"},"payload_hash":"97af3040aa80883e56142d05bc6860e3716527ae507d02c7831965e9ead452fd","raw_frame":"{\"market\":\"0x779291bef19b6709f61e9764a954aafe9ffae488d50ae674aabdcb4f248006d5\", \"price_changes\":[{\"asset_id\":\"8761897749749422724209054078244794145777693856614463256546737399611489089783\", \"price\":\"0.04\", \"size\":\"638.09\", \"side\":\"BUY\", \"hash\":\"83c8f04286d1061b1e3d7c65af22b14528242b18\", \"best_bid\":\"0.5\", \"best_ask\":\"0.51\"}, {\"asset_id\":\"14965588658799411272385430903075831224615961675357217884735713260981483529984\", \"price\":\"0.96\", \"size\":\"638.09\", \"side\":\"SELL\", \"hash\":\"112b35af8757b56f0147b4eba7204c70e8f0583e\", \"best_bid\":\"0.49\", \"best_ask\":\"0.5\"}], \"timestamp\":\"1785207751100\", \"event_type\":\"price_change\"}","received_at":"2026-07-28T03:02:30.952507Z","schema_version":"clob-market-ws.price_change.v1","sequence":null,"server_hash":null,"server_timestamp":"1785207751100","session_id":"3e519d9098404c15b234d96025eb1a2b","source":"clob_market_ws"},"received_at":"2026-07-28T03:02:30.952507Z","record_id":"4efeca71fdb501d50fd1d3f120fb8c5bbdf402af6c00ee399b9c4117f56190ee","schema_fingerprint":"4aa3821a28b0b7c2400bc59aba4bcc0a76e971dadd19610d3ad38c768e124dc7","schema_version":"edge-lab-recorder.raw.v1","sequence":null,"source":"clob_market_ws"}
{"event_at":"2026-07-28T03:02:31.109000Z","event_fingerprint":"fb15f997276be4846dc746b4139bbc784535da63ecf564685f264f11d24803f4","payload":{"connection_id":"a6b55582af5f430fb37ad02bf0922475","event_at":"2026-07-28T03:02:31.109000Z","event_type":"price_change","frame_hash":"b5b500b41474274860048371ed6b4abc94b78d04f2811b36c95aa66bb7093bba","frame_index":0,"kind":"data","monotonic_ns":309733981220791,"payload":{"event_type":"price_change","market":"0x779291bef19b6709f61e9764a954aafe9ffae488d50ae674aabdcb4f248006d5","price_changes":[{"asset_id":"14965588658799411272385430903075831224615961675357217884735713260981483529984","best_ask":"0.5","best_bid":"0.49","hash":"edc51532f16130d20853bfe8f8b76321196b57c7","price":"0.01","side":"BUY","size":"7883.02"},{"asset_id":"8761897749749422724209054078244794145777693856614463256546737399611489089783","best_ask":"0.51","best_bid":"0.5","hash":"54322046ade557ab1df3852db488b99fb00dd97b","price":"0.99","side":"SELL","size":"7883.02"}],"timestamp":"1785207751109"},"payload_hash":"dd3e334bef29ae943fb7a4e917c3e6cdad65acb4b5fe52b24a75ce8c51df2721","raw_frame":"{\"market\":\"0x779291bef19b6709f61e9764a954aafe9ffae488d50ae674aabdcb4f248006d5\", \"price_changes\":[{\"asset_id\":\"14965588658799411272385430903075831224615961675357217884735713260981483529984\", \"price\":\"0.01\", \"size\":\"7883.02\", \"side\":\"BUY\", \"hash\":\"edc51532f16130d20853bfe8f8b76321196b57c7\", \"best_bid\":\"0.49\", \"best_ask\":\"0.5\"}, {\"asset_id\":\"8761897749749422724209054078244794145777693856614463256546737399611489089783\", \"price\":\"0.99\", \"size\":\"7883.02\", \"side\":\"SELL\", \"hash\":\"54322046ade557ab1df3852db488b99fb00dd97b\", \"best_bid\":\"0.5\", \"best_ask\":\"0.51\"}], \"timestamp\":\"1785207751109\", \"event_type\":\"price_change\"}","received_at":"2026-07-28T03:02:30.961766Z","schema_version":"clob-market-ws.price_change.v1","sequence":null,"server_hash":null,"server_timestamp":"1785207751109","session_id":"3e519d9098404c15b234d96025eb1a2b","source":"clob_market_ws"},"received_at":"2026-07-28T03:02:30.961766Z","record_id":"24f60f0bb8427cf706e3deef6f0e3db3fc96e71b5ebd1e4480535accc43704ce","schema_fingerprint":"4aa3821a28b0b7c2400bc59aba4bcc0a76e971dadd19610d3ad38c768e124dc7","schema_version":"edge-lab-recorder.raw.v1","sequence":null,"source":"clob_market_ws"}
{"event_at":"2026-07-28T03:02:31.112000Z","event_fingerprint":"af57b80349dd2f65d0fe4656faa33cc321a199e89e96f165fca282eafac363fb","payload":{"connection_id":"a6b55582af5f430fb37ad02bf0922475","event_at":"2026-07-28T03:02:31.112000Z","event_type":"price_change","frame_hash":"9ce9850c87f63b0b36ca791827d5f0e4a223150d379fcf3400cf8e2b742d9442","frame_index":0,"kind":"data","monotonic_ns":309733984476458,"payload":{"event_type":"price_change","market":"0x779291bef19b6709f61e9764a954aafe9ffae488d50ae674aabdcb4f248006d5","price_changes":[{"asset_id":"14965588658799411272385430903075831224615961675357217884735713260981483529984","best_ask":"0.5","best_bid":"0.49","hash":"a04303112e1a18eb15d2c329d3e59e96d282dd4a","price":"0.45","side":"BUY","size":"112.6"},{"asset_id":"8761897749749422724209054078244794145777693856614463256546737399611489089783","best_ask":"0.51","best_bid":"0.5","hash":"0727c477dc54d40c1507493efef99d12c8e41f0e","price":"0.55","side":"SELL","size":"112.6"}],"timestamp":"1785207751112"},"payload_hash":"ff8865e27ad06cfbc802c3a11c76cdb59b52b06aeb2253410df808c80c710392","raw_frame":"{\"market\":\"0x779291bef19b6709f61e9764a954aafe9ffae488d50ae674aabdcb4f248006d5\", \"price_changes\":[{\"asset_id\":\"14965588658799411272385430903075831224615961675357217884735713260981483529984\", \"price\":\"0.45\", \"size\":\"112.6\", \"side\":\"BUY\", \"hash\":\"a04303112e1a18eb15d2c329d3e59e96d282dd4a\", \"best_bid\":\"0.49\", \"best_ask\":\"0.5\"}, {\"asset_id\":\"8761897749749422724209054078244794145777693856614463256546737399611489089783\", \"price\":\"0.55\", \"size\":\"112.6\", \"side\":\"SELL\", \"hash\":\"0727c477dc54d40c1507493efef99d12c8e41f0e\", \"best_bid\":\"0.5\", \"best_ask\":\"0.51\"}], \"timestamp\":\"1785207751112\", \"event_type\":\"price_change\"}","received_at":"2026-07-28T03:02:30.965022Z","schema_version":"clob-market-ws.price_change.v1","sequence":null,"server_hash":null,"server_timestamp":"1785207751112","session_id":"3e519d9098404c15b234d96025eb1a2b","source":"clob_market_ws"},"received_at":"2026-07-28T03:02:30.965022Z","record_id":"70e97cdbd74c8f0f249a7be228ad3b9b56e59875dfc2c7ba49e3173d4bb66daf","schema_fingerprint":"4aa3821a28b0b7c2400bc59aba4bcc0a76e971dadd19610d3ad38c768e124dc7","schema_version":"edge-lab-recorder.raw.v1","sequence":null,"source":"clob_market_ws"}
{"event_at":"2026-07-28T03:02:31.138000Z","event_fingerprint":"a3913dc655578dea28f47174567568d952d7328dc72bb2dcda2a1e751f50a943","payload":{"connection_id":"a6b55582af5f430fb37ad02bf0922475","event_at":"2026-07-28T03:02:31.138000Z","event_type":"price_change","frame_hash":"29c7267f18eb766c0c3dfd3ca1b79ed9f339488bb7bc6f99f8648d3d781777e7","frame_index":0,"kind":"data","monotonic_ns":309734013186375,"payload":{"event_type":"price_change","market":"0x779291bef19b6709f61e9764a954aafe9ffae488d50ae674aabdcb4f248006d5","price_changes":[{"asset_id":"14965588658799411272385430903075831224615961675357217884735713260981483529984","best_ask":"0.5","best_bid":"0.49","hash":"b85bb3f2a9879d4912c8bf931de824bb6640456d","price":"0.49","side":"BUY","size":"111.6"},{"asset_id":"8761897749749422724209054078244794145777693856614463256546737399611489089783","best_ask":"0.51","best_bid":"0.5","hash":"ad0bd14adf76995b35535553d710bfd161cc03c9","price":"0.51","side":"SELL","size":"111.6"}],"timestamp":"1785207751138"},"payload_hash":"43b3c33c89a1b7c520cce5f2d29f9814bf511392a8a7a5faedc1d6216cd10311","raw_frame":"{\"market\":\"0x779291bef19b6709f61e9764a954aafe9ffae488d50ae674aabdcb4f248006d5\", \"price_changes\":[{\"asset_id\":\"14965588658799411272385430903075831224615961675357217884735713260981483529984\", \"price\":\"0.49\", \"size\":\"111.6\", \"side\":\"BUY\", \"hash\":\"b85bb3f2a9879d4912c8bf931de824bb6640456d\", \"best_bid\":\"0.49\", \"best_ask\":\"0.5\"}, {\"asset_id\":\"8761897749749422724209054078244794145777693856614463256546737399611489089783\", \"price\":\"0.51\", \"size\":\"111.6\", \"side\":\"SELL\", \"hash\":\"ad0bd14adf76995b35535553d710bfd161cc03c9\", \"best_bid\":\"0.5\", \"best_ask\":\"0.51\"}], \"timestamp\":\"1785207751138\", \"event_type\":\"price_change\"}","received_at":"2026-07-28T03:02:30.993731Z","schema_version":"clob-market-ws.price_change.v1","sequence":null,"server_hash":null,"server_timestamp":"1785207751138","session_id":"3e519d9098404c15b234d96025eb1a2b","source":"clob_market_ws"},"received_at":"2026-07-28T03:02:30.993731Z","record_id":"04d479858f3ccf2ae3ad6b515e98ff4c23aac898f0ccbf575d9de0116b9e6434","schema_fingerprint":"4aa3821a28b0b7c2400bc59aba4bcc0a76e971dadd19610d3ad38c768e124dc7","schema_version":"edge-lab-recorder.raw.v1","sequence":null,"source":"clob_market_ws"}
{"event_at":"2026-07-28T03:02:31.155000Z","event_fingerprint":"b8f146627578ac93391ab37586cdc71106b61576a0faac59eb2b196d58670469","payload":{"connection_id":"a6b55582af5f430fb37ad02bf0922475","event_at":"2026-07-28T03:02:31.155000Z","event_type":"price_change","frame_hash":"ad3e38a531ff89badfd6adcaa8a7d5d427b27feaf3c2256fcb0c1026f5da2f4b","frame_index":0,"kind":"data","monotonic_ns":309734026776291,"payload":{"event_type":"price_change","market":"0x779291bef19b6709f61e9764a954aafe9ffae488d50ae674aabdcb4f248006d5","price_changes":[{"asset_id":"8761897749749422724209054078244794145777693856614463256546737399611489089783","best_ask":"0.51","best_bid":"0.5","hash":"8042652d235499e8e04ffa0a199272f88b64e626","price":"0.48","side":"BUY","size":"342"},{"asset_id":"14965588658799411272385430903075831224615961675357217884735713260981483529984","best_ask":"0.5","best_bid":"0.49","hash":"d559ab8721805d6f56ef69f20f4e826d0928db19","price":"0.52","side":"SELL","size":"342"}],"timestamp":"1785207751155"},"payload_hash":"2a93f9cfa04d1eb2c25e1ba1470290a8e67ecc1590945c5faaa5a3dbcd258694","raw_frame":"{\"market\":\"0x779291bef19b6709f61e9764a954aafe9ffae488d50ae674aabdcb4f248006d5\", \"price_changes\":[{\"asset_id\":\"8761897749749422724209054078244794145777693856614463256546737399611489089783\", \"price\":\"0.48\", \"size\":\"342\", \"side\":\"BUY\", \"hash\":\"8042652d235499e8e04ffa0a199272f88b64e626\", \"best_bid\":\"0.5\", \"best_ask\":\"0.51\"}, {\"asset_id\":\"14965588658799411272385430903075831224615961675357217884735713260981483529984\", \"price\":\"0.52\", \"size\":\"342\", \"side\":\"SELL\", \"hash\":\"d559ab8721805d6f56ef69f20f4e826d0928db19\", \"best_bid\":\"0.49\", \"best_ask\":\"0.5\"}], \"timestamp\":\"1785207751155\", \"event_type\":\"price_change\"}","received_at":"2026-07-28T03:02:31.007321Z","schema_version":"clob-market-ws.price_change.v1","sequence":null,"server_hash":null,"server_timestamp":"1785207751155","session_id":"3e519d9098404c15b234d96025eb1a2b","source":"clob_market_ws"},"received_at":"2026-07-28T03:02:31.007321Z","record_id":"2edf34e8779948be9c08bde870fc549311bc76ddb7bb4228287a9bd62d3d4edb","schema_fingerprint":"4aa3821a28b0b7c2400bc59aba4bcc0a76e971dadd19610d3ad38c768e124dc7","schema_version":"edge-lab-recorder.raw.v1","sequence":null,"source":"clob_market_ws"}
{"event_at":"2026-07-28T03:02:31.161000Z","event_fingerprint":"32ecdfb9f3f1c431178b2016cfdd95bd082625036076b09ea8670f974381de64","payload":{"connection_id":"a6b55582af5f430fb37ad02bf0922475","event_at":"2026-07-28T03:02:31.161000Z","event_type":"price_change","frame_hash":"f26581059834aca826353bb3871ee8f4cf7da189635d11b996cac4bd055f9d14","frame_index":0,"kind":"data","monotonic_ns":309734032942250,"payload":{"event_type":"price_change","market":"0x779291bef19b6709f61e9764a954aafe9ffae488d50ae674aabdcb4f248006d5","price_changes":[{"asset_id":"8761897749749422724209054078244794145777693856614463256546737399611489089783","best_ask":"0.51","best_bid":"0.5","hash":"d3a251a5a1e5bfe9c0ba3783fc40bca27b4aec1e","price":"0.37","side":"BUY","size":"194.57"},{"asset_id":"14965588658799411272385430903075831224615961675357217884735713260981483529984","best_ask":"0.5","best_bid":"0.49","hash":"7ff28ee46a1cf70a8e1d131f0f3562b49a21bb61","price":"0.63","side":"SELL","size":"194.57"}],"timestamp":"1785207751161"},"payload_hash":"15081fd150f089d629c062183844135e4b61d16b68b75f130054cf4f15c20b11","raw_frame":"{\"market\":\"0x779291bef19b6709f61e9764a954aafe9ffae488d50ae674aabdcb4f248006d5\", \"price_changes\":[{\"asset_id\":\"8761897749749422724209054078244794145777693856614463256546737399611489089783\", \"price\":\"0.37\", \"size\":\"194.57\", \"side\":\"BUY\", \"hash\":\"d3a251a5a1e5bfe9c0ba3783fc40bca27b4aec1e\", \"best_bid\":\"0.5\", \"best_ask\":\"0.51\"}, {\"asset_id\":\"14965588658799411272385430903075831224615961675357217884735713260981483529984\", \"price\":\"0.63\", \"size\":\"194.57\", \"side\":\"SELL\", \"hash\":\"7ff28ee46a1cf70a8e1d131f0f3562b49a21bb61\", \"best_bid\":\"0.49\", \"best_ask\":\"0.5\"}], \"timestamp\":\"1785207751161\", \"event_type\":\"price_change\"}","received_at":"2026-07-28T03:02:31.013487Z","schema_version":"clob-market-ws.price_change.v1","sequence":null,"server_hash":null,"server_timestamp":"1785207751161","session_id":"3e519d9098404c15b234d96025eb1a2b","source":"clob_market_ws"},"received_at":"2026-07-28T03:02:31.013487Z","record_id":"05a52cc8d8671bfecc79a09c0ade0ad0bb8d5f4ded723fbf7dd37956cdd8194b","schema_fingerprint":"4aa3821a28b0b7c2400bc59aba4bcc0a76e971dadd19610d3ad38c768e124dc7","schema_version":"edge-lab-recorder.raw.v1","sequence":null,"source":"clob_market_ws"}
{"event_at":"2026-07-28T03:02:31.162000Z","event_fingerprint":"f5c1d43616ce28bb97ad4e01a2fe0461aceb2f02153cda86cf1fa1da498166bc","payload":{"connection_id":"a6b55582af5f430fb37ad02bf0922475","event_at":"2026-07-28T03:02:31.162000Z","event_type":"price_change","frame_hash":"8adfa3564400d6da77f7f588716f80f6a1fe61a73faea46b43c1bcb961af3dca","frame_index":0,"kind":"data","monotonic_ns":309734034463833,"payload":{"event_type":"price_change","market":"0x779291bef19b6709f61e9764a954aafe9ffae488d50ae674aabdcb4f248006d5","price_changes":[{"asset_id":"8761897749749422724209054078244794145777693856614463256546737399611489089783","best_ask":"0.51","best_bid":"0.5","hash":"cbf94c2a1b27ab3e903ee3d0ee94aacd1336c5f3","price":"0.49","side":"BUY","size":"12"},{"asset_id":"14965588658799411272385430903075831224615961675357217884735713260981483529984","best_ask":"0.5","best_bid":"0.49","hash":"c04166cb626b73f318c14fb1b9b6e5b58d4b347f","price":"0.51","side":"SELL","size":"12"}],"timestamp":"1785207751162"},"payload_hash":"cf7c78ab4a92e6382b2355322ef253b9a4b4064447c813f882c2a7f0fe8fcaa0","raw_frame":"{\"market\":\"0x779291bef19b6709f61e9764a954aafe9ffae488d50ae674aabdcb4f248006d5\", \"price_changes\":[{\"asset_id\":\"8761897749749422724209054078244794145777693856614463256546737399611489089783\", \"price\":\"0.49\", \"size\":\"12\", \"side\":\"BUY\", \"hash\":\"cbf94c2a1b27ab3e903ee3d0ee94aacd1336c5f3\", \"best_bid\":\"0.5\", \"best_ask\":\"0.51\"}, {\"asset_id\":\"14965588658799411272385430903075831224615961675357217884735713260981483529984\", \"price\":\"0.51\", \"size\":\"12\", \"side\":\"SELL\", \"hash\":\"c04166cb626b73f318c14fb1b9b6e5b58d4b347f\", \"best_bid\":\"0.49\", \"best_ask\":\"0.5\"}], \"timestamp\":\"1785207751162\", \"event_type\":\"price_change\"}","received_at":"2026-07-28T03:02:31.015008Z","schema_version":"clob-market-ws.price_change.v1","sequence":null,"server_hash":null,"server_timestamp":"1785207751162","session_id":"3e519d9098404c15b234d96025eb1a2b","source":"clob_market_ws"},"received_at":"2026-07-28T03:02:31.015008Z","record_id":"55a91ffdc9e4eeda001652fbcd2b5b3870bd123bc8415fea0e46a773218d2642","schema_fingerprint":"4aa3821a28b0b7c2400bc59aba4bcc0a76e971dadd19610d3ad38c768e124dc7","schema_version":"edge-lab-recorder.raw.v1","sequence":null,"source":"clob_market_ws"}
{"event_at":"2026-07-28T03:02:31.163000Z","event_fingerprint":"1b3d8ca6119aff12edebc65f6f6b3a75e44b07a98092e2e019c78516f5861bce","payload":{"connection_id":"a6b55582af5f430fb37ad02bf0922475","event_at":"2026-07-28T03:02:31.163000Z","event_type":"price_change","frame_hash":"87f1ad7537724e3d4e9977b41c9080759d39ab8b39febb91d2b378724aa6f22d","frame_index":0,"kind":"data","monotonic_ns":309734036103750,"payload":{"event_type":"price_change","market":"0x779291bef19b6709f61e9764a954aafe9ffae488d50ae674aabdcb4f248006d5","price_changes":[{"asset_id":"8761897749749422724209054078244794145777693856614463256546737399611489089783","best_ask":"0.51","best_bid":"0.5","hash":"0bbe8a4d2fa6fba05a408b8dd72281678e59e54f","price":"0.48","side":"BUY","size":"384"},{"asset_id":"14965588658799411272385430903075831224615961675357217884735713260981483529984","best_ask":"0.5","best_bid":"0.49","hash":"0a1227c96132a98972fd20b52d6603e87aae0eed","price":"0.52","side":"SELL","size":"384"}],"timestamp":"1785207751163"},"payload_hash":"86f8e49932224fd89abea58b706a4dfc6d970b161595d24cfe146e1eb472fabe","raw_frame":"{\"market\":\"0x779291bef19b6709f61e9764a954aafe9ffae488d50ae674aabdcb4f248006d5\", \"price_changes\":[{\"asset_id\":\"8761897749749422724209054078244794145777693856614463256546737399611489089783\", \"price\":\"0.48\", \"size\":\"384\", \"side\":\"BUY\", \"hash\":\"0bbe8a4d2fa6fba05a408b8dd72281678e59e54f\", \"best_bid\":\"0.5\", \"best_ask\":\"0.51\"}, {\"asset_id\":\"14965588658799411272385430903075831224615961675357217884735713260981483529984\", \"price\":\"0.52\", \"size\":\"384\", \"side\":\"SELL\", \"hash\":\"0a1227c96132a98972fd20b52d6603e87aae0eed\", \"best_bid\":\"0.49\", \"best_ask\":\"0.5\"}], \"timestamp\":\"1785207751163\", \"event_type\":\"price_change\"}","received_at":"2026-07-28T03:02:31.016649Z","schema_version":"clob-market-ws.price_change.v1","sequence":null,"server_hash":null,"server_timestamp":"1785207751163","session_id":"3e519d9098404c15b234d96025eb1a2b","source":"clob_market_ws"},"received_at":"2026-07-28T03:02:31.016649Z","record_id":"4d3638d4795df8eace307ab9c3e1744a2f8fa9aee027192347164af26fdd87c7","schema_fingerprint":"4aa3821a28b0b7c2400bc59aba4bcc0a76e971dadd19610d3ad38c768e124dc7","schema_version":"edge-lab-recorder.raw.v1","sequence":null,"source":"clob_market_ws"}
{"event_at":"2026-07-28T03:02:31.170000Z","event_fingerprint":"412251726512383b0dc4ebfa8d8432f18c6df331d1ec705265b4c8e5ed33a05e","payload":{"connection_id":"a6b55582af5f430fb37ad02bf0922475","event_at":"2026-07-28T03:02:31.170000Z","event_type":"price_change","frame_hash":"cedc4f5eb52909071c8243bc3f76ce9a855f684dc6357ce4b6c2e9006ebe61cc","frame_index":0,"kind":"data","monotonic_ns":309734042556750,"payload":{"event_type":"price_change","market":"0x779291bef19b6709f61e9764a954aafe9ffae488d50ae674aabdcb4f248006d5","price_changes":[{"asset_id":"8761897749749422724209054078244794145777693856614463256546737399611489089783","best_ask":"0.51","best_bid":"0.5","hash":"32fc232ce51d21bef7a8abebf38d622bc40fdc84","price":"0.39","side":"BUY","size":"241"},{"asset_id":"14965588658799411272385430903075831224615961675357217884735713260981483529984","best_ask":"0.5","best_bid":"0.49","hash":"e5f0dcb933c42d0586c6c5200580a6d027523de2","price":"0.61","side":"SELL","size":"241"}],"timestamp":"1785207751170"},"payload_hash":"e5e5656fea77acc91654359e18006ffaae023aa9600b09642781b5215aa613b3","raw_frame":"{\"market\":\"0x779291bef19b6709f61e9764a954aafe9ffae488d50ae674aabdcb4f248006d5\", \"price_changes\":[{\"asset_id\":\"8761897749749422724209054078244794145777693856614463256546737399611489089783\", \"price\":\"0.39\", \"size\":\"241\", \"side\":\"BUY\", \"hash\":\"32fc232ce51d21bef7a8abebf38d622bc40fdc84\", \"best_bid\":\"0.5\", \"best_ask\":\"0.51\"}, {\"asset_id\":\"14965588658799411272385430903075831224615961675357217884735713260981483529984\", \"price\":\"0.61\", \"size\":\"241\", \"side\":\"SELL\", \"hash\":\"e5f0dcb933c42d0586c6c5200580a6d027523de2\", \"best_bid\":\"0.49\", \"best_ask\":\"0.5\"}], \"timestamp\":\"1785207751170\", \"event_type\":\"price_change\"}","received_at":"2026-07-28T03:02:31.023101Z","schema_version":"clob-market-ws.price_change.v1","sequence":null,"server_hash":null,"server_timestamp":"1785207751170","session_id":"3e519d9098404c15b234d96025eb1a2b","source":"clob_market_ws"},"received_at":"2026-07-28T03:02:31.023101Z","record_id":"ffd79051b4aa3934a5dae5fd351af34fd9fb6055aedcbf26791c0487647194f1","schema_fingerprint":"4aa3821a28b0b7c2400bc59aba4bcc0a76e971dadd19610d3ad38c768e124dc7","schema_version":"edge-lab-recorder.raw.v1","sequence":null,"source":"clob_market_ws"}
{"event_at":"2026-07-28T03:02:31.187000Z","event_fingerprint":"b74e65f076bd5d79665726f9fec0e246bfa469469fc66911baebc6b0c95ae032","payload":{"connection_id":"a6b55582af5f430fb37ad02bf0922475","event_at":"2026-07-28T03:02:31.187000Z","event_type":"price_change","frame_hash":"c645b29644c27b9bbbc00d7108a88f3327b5b04e0b4e9070d91801d11e21800b","frame_index":0,"kind":"data","monotonic_ns":309734058588583,"payload":{"event_type":"price_change","market":"0x779291bef19b6709f61e9764a954aafe9ffae488d50ae674aabdcb4f248006d5","price_changes":[{"asset_id":"14965588658799411272385430903075831224615961675357217884735713260981483529984","best_ask":"0.5","best_bid":"0.49","hash":"5c96c20fa9fd883c89c1398f4fa4ed8d79186d11","price":"0.39","side":"BUY","size":"224.18"},{"asset_id":"8761897749749422724209054078244794145777693856614463256546737399611489089783","best_ask":"0.51","best_bid":"0.5","hash":"f1b115f606acfde349c70ed9d872d87526e60958","price":"0.61","side":"SELL","size":"224.18"}],"timestamp":"1785207751187"},"payload_hash":"debcb65518fb7dadf7fe98a1f5ae3fbb49942694fccb8d6844a70ba71474e86f","raw_frame":"{\"market\":\"0x779291bef19b6709f61e9764a954aafe9ffae488d50ae674aabdcb4f248006d5\", \"price_changes\":[{\"asset_id\":\"14965588658799411272385430903075831224615961675357217884735713260981483529984\", \"price\":\"0.39\", \"size\":\"224.18\", \"side\":\"BUY\", \"hash\":\"5c96c20fa9fd883c89c1398f4fa4ed8d79186d11\", \"best_bid\":\"0.49\", \"best_ask\":\"0.5\"}, {\"asset_id\":\"8761897749749422724209054078244794145777693856614463256546737399611489089783\", \"price\":\"0.61\", \"size\":\"224.18\", \"side\":\"SELL\", \"hash\":\"f1b115f606acfde349c70ed9d872d87526e60958\", \"best_bid\":\"0.5\", \"best_ask\":\"0.51\"}], \"timestamp\":\"1785207751187\", \"event_type\":\"price_change\"}","received_at":"2026-07-28T03:02:31.039133Z","schema_version":"clob-market-ws.price_change.v1","sequence":null,"server_hash":null,"server_timestamp":"1785207751187","session_id":"3e519d9098404c15b234d96025eb1a2b","source":"clob_market_ws"},"received_at":"2026-07-28T03:02:31.039133Z","record_id":"7240a813627ced1a9221e59e122feefee58fbdbfe5feddca21b79bc1aa394c9b","schema_fingerprint":"4aa3821a28b0b7c2400bc59aba4bcc0a76e971dadd19610d3ad38c768e124dc7","schema_version":"edge-lab-recorder.raw.v1","sequence":null,"source":"clob_market_ws"}
{"event_at":"2026-07-28T03:02:31.197000Z","event_fingerprint":"dc8c509ac331fd051e71202476d4f02404f66bc354cd295e67e924d58b420191","payload":{"connection_id":"a6b55582af5f430fb37ad02bf0922475","event_at":"2026-07-28T03:02:31.197000Z","event_type":"price_change","frame_hash":"899e4b92632f691605d31a069ade6971e488c5d04621dec71ce91bd8f517cfe8","frame_index":0,"kind":"data","monotonic_ns":309734068914125,"payload":{"event_type":"price_change","market":"0x779291bef19b6709f61e9764a954aafe9ffae488d50ae674aabdcb4f248006d5","price_changes":[{"asset_id":"14965588658799411272385430903075831224615961675357217884735713260981483529984","best_ask":"0.5","best_bid":"0.49","hash":"b4f2df66eb807a79d62f9555119225d122c355e7","price":"0.47","side":"BUY","size":"106.6"},{"asset_id":"8761897749749422724209054078244794145777693856614463256546737399611489089783","best_ask":"0.51","best_bid":"0.5","hash":"177bce1e6bf2c3bb56a684a7591f03afbace6378","price":"0.53","side":"SELL","size":"106.6"}],"timestamp":"1785207751197"},"payload_hash":"0a1a08572a6bf9ce06b75fce66a1c38310cc3e303676b1d60b2384aa824f9720","raw_frame":"{\"market\":\"0x779291bef19b6709f61e9764a954aafe9ffae488d50ae674aabdcb4f248006d5\", \"price_changes\":[{\"asset_id\":\"14965588658799411272385430903075831224615961675357217884735713260981483529984\", \"price\":\"0.47\", \"size\":\"106.6\", \"side\":\"BUY\", \"hash\":\"b4f2df66eb807a79d62f9555119225d122c355e7\", \"best_bid\":\"0.49\", \"best_ask\":\"0.5\"}, {\"asset_id\":\"8761897749749422724209054078244794145777693856614463256546737399611489089783\", \"price\":\"0.53\", \"size\":\"106.6\", \"side\":\"SELL\", \"hash\":\"177bce1e6bf2c3bb56a684a7591f03afbace6378\", \"best_bid\":\"0.5\", \"best_ask\":\"0.51\"}], \"timestamp\":\"1785207751197\", \"event_type\":\"price_change\"}","received_at":"2026-07-28T03:02:31.049457Z","schema_version":"clob-market-ws.price_change.v1","sequence":null,"server_hash":null,"server_timestamp":"1785207751197","session_id":"3e519d9098404c15b234d96025eb1a2b","source":"clob_market_ws"},"received_at":"2026-07-28T03:02:31.049457Z","record_id":"739c57bec288585d3da0da15c27d6c094ef91d091094b6f933928e2c875b5245","schema_fingerprint":"4aa3821a28b0b7c2400bc59aba4bcc0a76e971dadd19610d3ad38c768e124dc7","schema_version":"edge-lab-recorder.raw.v1","sequence":null,"source":"clob_market_ws"}
{"event_at":"2026-07-28T03:02:31.202000Z","event_fingerprint":"0a125764485847c498ae782926c2206980746287a00957bd6d83dd69441fb778","payload":{"connection_id":"a6b55582af5f430fb37ad02bf0922475","event_at":"2026-07-28T03:02:31.202000Z","event_type":"price_change","frame_hash":"e50da230c777e39960f73b0823cf2374b9d04925625c8f8879cea429c59553a7","frame_index":0,"kind":"data","monotonic_ns":309734074423041,"payload":{"event_type":"price_change","market":"0x779291bef19b6709f61e9764a954aafe9ffae488d50ae674aabdcb4f248006d5","price_changes":[{"asset_id":"8761897749749422724209054078244794145777693856614463256546737399611489089783","best_ask":"0.51","best_bid":"0.5","hash":"ee7e28e4488d3c87bc4a1f518e8ad32b7330c3a3","price":"0.5","side":"BUY","size":"31.18"},{"asset_id":"14965588658799411272385430903075831224615961675357217884735713260981483529984","best_ask":"0.5","best_bid":"0.49","hash":"a29b2b0446bb89ed84057ad8925eada6dae6c113","price":"0.5","side":"SELL","size":"31.18"}],"timestamp":"1785207751202"},"payload_hash":"1114eaf0cec0858a8e0db34bab6c989ddc6dd20281a1db89b2c60b7082c5dd1e","raw_frame":"{\"market\":\"0x779291bef19b6709f61e9764a954aafe9ffae488d50ae674aabdcb4f248006d5\", \"price_changes\":[{\"asset_id\":\"8761897749749422724209054078244794145777693856614463256546737399611489089783\", \"price\":\"0.5\", \"size\":\"31.18\", \"side\":\"BUY\", \"hash\":\"ee7e28e4488d3c87bc4a1f518e8ad32b7330c3a3\", \"best_bid\":\"0.5\", \"best_ask\":\"0.51\"}, {\"asset_id\":\"14965588658799411272385430903075831224615961675357217884735713260981483529984\", \"price\":\"0.5\", \"size\":\"31.18\", \"side\":\"SELL\", \"hash\":\"a29b2b0446bb89ed84057ad8925eada6dae6c113\", \"best_bid\":\"0.49\", \"best_ask\":\"0.5\"}], \"timestamp\":\"1785207751202\", \"event_type\":\"price_change\"}","received_at":"2026-07-28T03:02:31.054966Z","schema_version":"clob-market-ws.price_change.v1","sequence":null,"server_hash":null,"server_timestamp":"1785207751202","session_id":"3e519d9098404c15b234d96025eb1a2b","source":"clob_market_ws"},"received_at":"2026-07-28T03:02:31.054966Z","record_id":"19627d61337f313eebf7ae93a0368f7c5679cd6f0cbfd8f91723fb55588e1a3c","schema_fingerprint":"4aa3821a28b0b7c2400bc59aba4bcc0a76e971dadd19610d3ad38c768e124dc7","schema_version":"edge-lab-recorder.raw.v1","sequence":null,"source":"clob_market_ws"}
{"event_at":"2026-07-28T03:02:31.203000Z","event_fingerprint":"30abc081162b8e875f4d5fa6e003f07697c632a29ac4374316bcee912b043fce","payload":{"connection_id":"a6b55582af5f430fb37ad02bf0922475","event_at":"2026-07-28T03:02:31.203000Z","event_type":"price_change","frame_hash":"6b5fcb4bf0c4def0001960926868f4ac218befd7c3cbde42f4630c55d1a9f503","frame_index":0,"kind":"data","monotonic_ns":309734075966041,"payload":{"event_type":"price_change","market":"0x779291bef19b6709f61e9764a954aafe9ffae488d50ae674aabdcb4f248006d5","price_changes":[{"asset_id":"8761897749749422724209054078244794145777693856614463256546737399611489089783","best_ask":"0.51","best_bid":"0.5","hash":"525902c8da9113c26ca621a3d80110fd31d64a6f","price":"0.47","side":"BUY","size":"93.06"},{"asset_id":"14965588658799411272385430903075831224615961675357217884735713260981483529984","best_ask":"0.5","best_bid":"0.49","hash":"bffa199c2f95518766ae3951215e1b12f3f598fb","price":"0.53","side":"SELL","size":"93.06"}],"timestamp":"1785207751203"},"payload_hash":"681486c6f2e753ac8213f15c00f29da70a05eba415455875a80c408435fab1a2","raw_frame":"{\"market\":\"0x779291bef19b6709f61e9764a954aafe9ffae488d50ae674aabdcb4f248006d5\", \"price_changes\":[{\"asset_id\":\"8761897749749422724209054078244794145777693856614463256546737399611489089783\", \"price\":\"0.47\", \"size\":\"93.06\", \"side\":\"BUY\", \"hash\":\"525902c8da9113c26ca621a3d80110fd31d64a6f\", \"best_bid\":\"0.5\", \"best_ask\":\"0.51\"}, {\"asset_id\":\"14965588658799411272385430903075831224615961675357217884735713260981483529984\", \"price\":\"0.53\", \"size\":\"93.06\", \"side\":\"SELL\", \"hash\":\"bffa199c2f95518766ae3951215e1b12f3f598fb\", \"best_bid\":\"0.49\", \"best_ask\":\"0.5\"}], \"timestamp\":\"1785207751203\", \"event_type\":\"price_change\"}","received_at":"2026-07-28T03:02:31.056509Z","schema_version":"clob-market-ws.price_change.v1","sequence":null,"server_hash":null,"server_timestamp":"1785207751203","session_id":"3e519d9098404c15b234d96025eb1a2b","source":"clob_market_ws"},"received_at":"2026-07-28T03:02:31.056509Z","record_id":"102d2a6d65adba7819e0004534af77b93d6a9ba8a2b8c4217d26f8b00a3d751d","schema_fingerprint":"4aa3821a28b0b7c2400bc59aba4bcc0a76e971dadd19610d3ad38c768e124dc7","schema_version":"edge-lab-recorder.raw.v1","sequence":null,"source":"clob_market_ws"}
{"event_at":"2026-07-28T03:02:31.203000Z","event_fingerprint":"e9e937e25cebbb9fe02f1d6cfb734e51e0db47fbb115c425bc38731a85aa625b","payload":{"connection_id":"a6b55582af5f430fb37ad02bf0922475","event_at":"2026-07-28T03:02:31.203000Z","event_type":"price_change","frame_hash":"ecdb9b8cafb03c80c0b9c7c659ae5b54a45473b890811b25009809392664ec66","frame_index":0,"kind":"data","monotonic_ns":309734077450125,"payload":{"event_type":"price_change","market":"0x779291bef19b6709f61e9764a954aafe9ffae488d50ae674aabdcb4f248006d5","price_changes":[{"asset_id":"8761897749749422724209054078244794145777693856614463256546737399611489089783","best_ask":"0.51","best_bid":"0.5","hash":"eea19fedaba74eaddc455ebb36b4f49f797ac909","price":"0.38","side":"BUY","size":"193"},{"asset_id":"14965588658799411272385430903075831224615961675357217884735713260981483529984","best_ask":"0.5","best_bid":"0.49","hash":"3fbde36fe950899ef7acf2c9a35784993a9f0d4d","price":"0.62","side":"SELL","size":"193"}],"timestamp":"1785207751203"},"payload_hash":"6306f9c1325cd9bf0882d8adf06a1697373e740a9e745806c395aafe211142b1","raw_frame":"{\"market\":\"0x779291bef19b6709f61e9764a954aafe9ffae488d50ae674aabdcb4f248006d5\", \"price_changes\":[{\"asset_id\":\"8761897749749422724209054078244794145777693856614463256546737399611489089783\", \"price\":\"0.38\", \"size\":\"193\", \"side\":\"BUY\", \"hash\":\"eea19fedaba74eaddc455ebb36b4f49f797ac909\", \"best_bid\":\"0.5\", \"best_ask\":\"0.51\"}, {\"asset_id\":\"14965588658799411272385430903075831224615961675357217884735713260981483529984\", \"price\":\"0.62\", \"size\":\"193\", \"side\":\"SELL\", \"hash\":\"3fbde36fe950899ef7acf2c9a35784993a9f0d4d\", \"best_bid\":\"0.49\", \"best_ask\":\"0.5\"}], \"timestamp\":\"1785207751203\", \"event_type\":\"price_change\"}","received_at":"2026-07-28T03:02:31.057994Z","schema_version":"clob-market-ws.price_change.v1","sequence":null,"server_hash":null,"server_timestamp":"1785207751203","session_id":"3e519d9098404c15b234d96025eb1a2b","source":"clob_market_ws"},"received_at":"2026-07-28T03:02:31.057994Z","record_id":"6ddac987bc9784ce60331604e77321fa956f208da829d0d43bbdb45b435c72a4","schema_fingerprint":"4aa3821a28b0b7c2400bc59aba4bcc0a76e971dadd19610d3ad38c768e124dc7","schema_version":"edge-lab-recorder.raw.v1","sequence":null,"source":"clob_market_ws"}
{"event_at":"2026-07-28T03:02:31.204000Z","event_fingerprint":"14947aa13c27a7893f7f6dd5f58f3e0fe8d875e29ac0c2dafb8f167ada979f2a","payload":{"connection_id":"a6b55582af5f430fb37ad02bf0922475","event_at":"2026-07-28T03:02:31.204000Z","event_type":"price_change","frame_hash":"1d06677271512c49d9e19c8516a80340aa14837ca20c9d2913f4e7c06a33b511","frame_index":0,"kind":"data","monotonic_ns":309734078821250,"payload":{"event_type":"price_change","market":"0x779291bef19b6709f61e9764a954aafe9ffae488d50ae674aabdcb4f248006d5","price_changes":[{"asset_id":"8761897749749422724209054078244794145777693856614463256546737399611489089783","best_ask":"0.51","best_bid":"0.5","hash":"4a0258cee73fa39be2f31fdfa4238b25fc509717","price":"0.47","side":"BUY","size":"136.06"},{"asset_id":"14965588658799411272385430903075831224615961675357217884735713260981483529984","best_ask":"0.5","best_bid":"0.49","hash":"68f30a2c2ef4c1a804867e7476cb73bef8a5f1fe","price":"0.53","side":"SELL","size":"136.06"}],"timestamp":"1785207751204"},"payload_hash":"195da347f3b12f769733c406a7fdda142e630ce584984d9ff02d609b00df6e90","raw_frame":"{\"market\":\"0x779291bef19b6709f61e9764a954aafe9ffae488d50ae674aabdcb4f248006d5\", \"price_changes\":[{\"asset_id\":\"8761897749749422724209054078244794145777693856614463256546737399611489089783\", \"price\":\"0.47\", \"size\":\"136.06\", \"side\":\"BUY\", \"hash\":\"4a0258cee73fa39be2f31fdfa4238b25fc509717\", \"best_bid\":\"0.5\", \"best_ask\":\"0.51\"}, {\"asset_id\":\"14965588658799411272385430903075831224615961675357217884735713260981483529984\", \"price\":\"0.53\", \"size\":\"136.06\", \"side\":\"SELL\", \"hash\":\"68f30a2c2ef4c1a804867e7476cb73bef8a5f1fe\", \"best_bid\":\"0.49\", \"best_ask\":\"0.5\"}], \"timestamp\":\"1785207751204\", \"event_type\":\"price_change\"}","received_at":"2026-07-28T03:02:31.059364Z","schema_version":"clob-market-ws.price_change.v1","sequence":null,"server_hash":null,"server_timestamp":"1785207751204","session_id":"3e519d9098404c15b234d96025eb1a2b","source":"clob_market_ws"},"received_at":"2026-07-28T03:02:31.059364Z","record_id":"978ce60e0bcbd6e9379a6cd6c6d12258960101c2257dc417a313712f9eeb024a","schema_fingerprint":"4aa3821a28b0b7c2400bc59aba4bcc0a76e971dadd19610d3ad38c768e124dc7","schema_version":"edge-lab-recorder.raw.v1","sequence":null,"source":"clob_market_ws"}
{"event_at":"2026-07-28T03:02:31.217000Z","event_fingerprint":"09ca68ef91b95d0574925332cb997f3b03ab0c8cef39e4660abdaa343a61b8d6","payload":{"connection_id":"a6b55582af5f430fb37ad02bf0922475","event_at":"2026-07-28T03:02:31.217000Z","event_type":"new_market","frame_hash":"9c797b086b92be7d35dfae0ab34be9ba14ff84a255d55e0b5d7deaacfa22bff4","frame_index":0,"kind":"data","monotonic_ns":309734095142208,"payload":{"active":false,"assets_ids":["82360224809492993156064238868296002117312652360668019221726645952469977840953","14483710465231359114311234413968514551668270496413170098655964787844884428930"],"clob_token_ids":["82360224809492993156064238868296002117312652360668019221726645952469977840953","14483710465231359114311234413968514551668270496413170098655964787844884428930"],"condition_id":"0x6c8c5e9ed6ed2dc6af8ff58049e9b63438231321375090d823a44c8f864dfd6c","description":"This market will resolve to \"Up\" if the Bitcoin price at the end of the time range specified in the title is greater than or equal to the price at the beginning of that range. Otherwise, it will resolve to \"Down\".\nThe resolution source for this market is information from Chainlink, specifically the BTC/USD data stream available at https://data.chain.link/streams/btc-usd.\nPlease note that this market is about the price according to Chainlink data stream BTC/USD, not according to other sources or spot markets.","event_message":{"description":"This market will resolve to \"Up\" if the Bitcoin price at the end of the time range specified in the title is greater than or equal to the price at the beginning of that range. Otherwise, it will resolve to \"Down\".\nThe resolution source for this market is information from Chainlink, specifically the BTC/USD data stream available at https://data.chain.link/streams/btc-usd.\nPlease note that this market is about the price according to Chainlink data stream BTC/USD, not according to other sources or spot markets.","id":"759156","slug":"btc-updown-5m-1785293700","ticker":"btc-updown-5m-1785293700","title":"Bitcoin Up or Down - July 28, 10:55PM-11:00PM ET"},"event_type":"new_market","fee_schedule":{"exponent":"1","rate":"0.07","rebate_rate":"0.2","taker_only":true},"fees_enabled":true,"game_start_time":"","group_item_title":"","id":"3145040","line":"","market":"0x6c8c5e9ed6ed2dc6af8ff58049e9b63438231321375090d823a44c8f864dfd6c","order_price_min_tick_size":"0.01","outcomes":["Up","Down"],"question":"Bitcoin Up or Down - July 28, 10:55PM-11:00PM ET","slug":"btc-updown-5m-1785293700","sports_market_type":"","tags":[],"taker_base_fee":"1000","timestamp":"1785207751217"},"payload_hash":"d2abe23bbf3877761c4c0e3c4578f24ecae7578d12ef1c740793cc23efde49c8","raw_frame":"{\"id\":\"3145040\", \"question\":\"Bitcoin Up or Down - July 28, 10:55PM-11:00PM ET\", \"market\":\"0x6c8c5e9ed6ed2dc6af8ff58049e9b63438231321375090d823a44c8f864dfd6c\", \"slug\":\"btc-updown-5m-1785293700\", \"description\":\"This market will resolve to \\\"Up\\\" if the Bitcoin price at the end of the time range specified in the title is greater than or equal to the price at the beginning of that range. Otherwise, it will resolve to \\\"Down\\\".\\nThe resolution source for this market is information from Chainlink, specifically the BTC/USD data stream available at https://data.chain.link/streams/btc-usd.\\nPlease note that this market is about the price according to Chainlink data stream BTC/USD, not according to other sources or spot markets.\", \"assets_ids\":[\"82360224809492993156064238868296002117312652360668019221726645952469977840953\", \"14483710465231359114311234413968514551668270496413170098655964787844884428930\"], \"outcomes\":[\"Up\", \"Down\"], \"event_message\":{\"id\":\"759156\", \"ticker\":\"btc-updown-5m-1785293700\", \"slug\":\"btc-updown-5m-1785293700\", \"title\":\"Bitcoin Up or Down - July 28, 10:55PM-11:00PM ET\", \"description\":\"This market will resolve to \\\"Up\\\" if the Bitcoin price at the end of the time range specified in the title is greater than or equal to the price at the beginning of that range. Otherwise, it will resolve to \\\"Down\\\".\\nThe resolution source for this market is information from Chainlink, specifically the BTC/USD data stream available at https://data.chain.link/streams/btc-usd.\\nPlease note that this market is about the price according to Chainlink data stream BTC/USD, not according to other sources or spot markets.\"}, \"timestamp\":\"1785207751217\", \"event_type\":\"new_market\", \"tags\":[], \"condition_id\":\"0x6c8c5e9ed6ed2dc6af8ff58049e9b63438231321375090d823a44c8f864dfd6c\", \"active\":false, \"clob_token_ids\":[\"82360224809492993156064238868296002117312652360668019221726645952469977840953\", \"14483710465231359114311234413968514551668270496413170098655964787844884428930\"], \"sports_market_type\":\"\", \"line\":\"\", \"game_start_time\":\"\", \"order_price_min_tick_size\":\"0.01\", \"group_item_title\":\"\", \"taker_base_fee\":\"1000\", \"fees_enabled\":true, \"fee_schedule\":{\"exponent\":\"1\", \"rate\":\"0.07\", \"taker_only\":true, \"rebate_rate\":\"0.2\"}}","received_at":"2026-07-28T03:02:31.075688Z","schema_version":"clob-market-ws.new_market.v1","sequence":null,"server_hash":null,"server_timestamp":"1785207751217","session_id":"3e519d9098404c15b234d96025eb1a2b","source":"clob_market_ws"},"received_at":"2026-07-28T03:02:31.075688Z","record_id":"e8be641bc9e6960806dba71a334963bb573208d95931807ab80af02f997f8c27","schema_fingerprint":"6639a822a7b79cfa4c3fc0044066e4f66ba8611f5bf361772bd6902a2319b82d","schema_version":"edge-lab-recorder.raw.v1","sequence":null,"source":"clob_market_ws"}
{"event_at":"2026-07-28T03:02:31.234000Z","event_fingerprint":"19a835719fc65267eea97fe4316a0004516edd7afc75ac9aa20988ad6cee6504","payload":{"connection_id":"a6b55582af5f430fb37ad02bf0922475","event_at":"2026-07-28T03:02:31.234000Z","event_type":"price_change","frame_hash":"9c7777ac70fcb67f8ba74e1c6128fb8e0165fff64f345a381dd66d5c012ae664","frame_index":0,"kind":"data","monotonic_ns":309734105949000,"payload":{"event_type":"price_change","market":"0x779291bef19b6709f61e9764a954aafe9ffae488d50ae674aabdcb4f248006d5","price_changes":[{"asset_id":"8761897749749422724209054078244794145777693856614463256546737399611489089783","best_ask":"0.51","best_bid":"0.5","hash":"3a7a2f06c6d446458850aa235f61ac70a3de9104","price":"0.02","side":"BUY","size":"738.1"},{"asset_id":"14965588658799411272385430903075831224615961675357217884735713260981483529984","best_ask":"0.5","best_bid":"0.49","hash":"4ab9d452e2fa00f09f50db06fb3373d0bb46fa73","price":"0.98","side":"SELL","size":"738.1"}],"timestamp":"1785207751234"},"payload_hash":"2dfa374535a32ae0507a21d0a5ab154b84be79e890591cdaa9f777ee54603263","raw_frame":"{\"market\":\"0x779291bef19b6709f61e9764a954aafe9ffae488d50ae674aabdcb4f248006d5\", \"price_changes\":[{\"asset_id\":\"8761897749749422724209054078244794145777693856614463256546737399611489089783\", \"price\":\"0.02\", \"size\":\"738.1\", \"side\":\"BUY\", \"hash\":\"3a7a2f06c6d446458850aa235f61ac70a3de9104\", \"best_bid\":\"0.5\", \"best_ask\":\"0.51\"}, {\"asset_id\":\"14965588658799411272385430903075831224615961675357217884735713260981483529984\", \"price\":\"0.98\", \"size\":\"738.1\", \"side\":\"SELL\", \"hash\":\"4ab9d452e2fa00f09f50db06fb3373d0bb46fa73\", \"best_bid\":\"0.49\", \"best_ask\":\"0.5\"}], \"timestamp\":\"1785207751234\", \"event_type\":\"price_change\"}","received_at":"2026-07-28T03:02:31.086491Z","schema_version":"clob-market-ws.price_change.v1","sequence":null,"server_hash":null,"server_timestamp":"1785207751234","session_id":"3e519d9098404c15b234d96025eb1a2b","source":"clob_market_ws"},"received_at":"2026-07-28T03:02:31.086491Z","record_id":"e6ea421299d6acd946ea224d40b4a2ebe371aeaae6c5dc49df786c6008b4a3ae","schema_fingerprint":"4aa3821a28b0b7c2400bc59aba4bcc0a76e971dadd19610d3ad38c768e124dc7","schema_version":"edge-lab-recorder.raw.v1","sequence":null,"source":"clob_market_ws"}
{"event_at":"2026-07-28T03:02:31.241000Z","event_fingerprint":"a597ddb05995bd90b2ae1a5f65672c790f34e76f25ae45133e50c853f7a892de","payload":{"connection_id":"a6b55582af5f430fb37ad02bf0922475","event_at":"2026-07-28T03:02:31.241000Z","event_type":"price_change","frame_hash":"34431b6efb3eec42da68182bd7cbee22d7d821120e6dcde45ebe2bb11778b7c1","frame_index":0,"kind":"data","monotonic_ns":309734114099875,"payload":{"event_type":"price_change","market":"0x779291bef19b6709f61e9764a954aafe9ffae488d50ae674aabdcb4f248006d5","price_changes":[{"asset_id":"14965588658799411272385430903075831224615961675357217884735713260981483529984","best_ask":"0.5","best_bid":"0.49","hash":"68296b24edfdd3c6dd3364fbfe119f77f58cb42e","price":"0.49","side":"BUY","size":"117.6"},{"asset_id":"8761897749749422724209054078244794145777693856614463256546737399611489089783","best_ask":"0.51","best_bid":"0.5","hash":"45efb8cdcd58b5353b90d6301cdffb17d1ecf623","price":"0.51","side":"SELL","size":"117.6"}],"timestamp":"1785207751241"},"payload_hash":"a4e798eb0619de072589134eb45aae73d620ac735e68242ec5607ee79978105b","raw_frame":"{\"market\":\"0x779291bef19b6709f61e9764a954aafe9ffae488d50ae674aabdcb4f248006d5\", \"price_changes\":[{\"asset_id\":\"14965588658799411272385430903075831224615961675357217884735713260981483529984\", \"price\":\"0.49\", \"size\":\"117.6\", \"side\":\"BUY\", \"hash\":\"68296b24edfdd3c6dd3364fbfe119f77f58cb42e\", \"best_bid\":\"0.49\", \"best_ask\":\"0.5\"}, {\"asset_id\":\"8761897749749422724209054078244794145777693856614463256546737399611489089783\", \"price\":\"0.51\", \"size\":\"117.6\", \"side\":\"SELL\", \"hash\":\"45efb8cdcd58b5353b90d6301cdffb17d1ecf623\", \"best_bid\":\"0.5\", \"best_ask\":\"0.51\"}], \"timestamp\":\"1785207751241\", \"event_type\":\"price_change\"}","received_at":"2026-07-28T03:02:31.094645Z","schema_version":"clob-market-ws.price_change.v1","sequence":null,"server_hash":null,"server_timestamp":"1785207751241","session_id":"3e519d9098404c15b234d96025eb1a2b","source":"clob_market_ws"},"received_at":"2026-07-28T03:02:31.094645Z","record_id":"3e05f95e33ca7aecd04e8e67dbbae5c945c60ec56fc8a10cf6456ae1f757e95f","schema_fingerprint":"4aa3821a28b0b7c2400bc59aba4bcc0a76e971dadd19610d3ad38c768e124dc7","schema_version":"edge-lab-recorder.raw.v1","sequence":null,"source":"clob_market_ws"}
{"event_at":"2026-07-28T03:02:31.251000Z","event_fingerprint":"13cf697cc07d12a0655841d223064b64c99cf94e9d820f60d7c171f086c03d4a","payload":{"connection_id":"a6b55582af5f430fb37ad02bf0922475","event_at":"2026-07-28T03:02:31.251000Z","event_type":"price_change","frame_hash":"7abc3fb161385e59e174075aae2369bca1f02fed0957d7bf3059053c43d09380","frame_index":0,"kind":"data","monotonic_ns":309734123589416,"payload":{"event_type":"price_change","market":"0x779291bef19b6709f61e9764a954aafe9ffae488d50ae674aabdcb4f248006d5","price_changes":[{"asset_id":"14965588658799411272385430903075831224615961675357217884735713260981483529984","best_ask":"0.5","best_bid":"0.49","hash":"063aadc16578477f63c97bcd9ee60982dba17dbc","price":"0.45","side":"BUY","size":"117.6"},{"asset_id":"8761897749749422724209054078244794145777693856614463256546737399611489089783","best_ask":"0.51","best_bid":"0.5","hash":"e7cf7f9af6bb0dfb3a343228bafa71d25dfb2c69","price":"0.55","side":"SELL","size":"117.6"}],"timestamp":"1785207751251"},"payload_hash":"7dc927ef517947d6613652a8b139dcc9eb7bfcac6372c92e1c6472c57c705185","raw_frame":"{\"market\":\"0x779291bef19b6709f61e9764a954aafe9ffae488d50ae674aabdcb4f248006d5\", \"price_changes\":[{\"asset_id\":\"14965588658799411272385430903075831224615961675357217884735713260981483529984\", \"price\":\"0.45\", \"size\":\"117.6\", \"side\":\"BUY\", \"hash\":\"063aadc16578477f63c97bcd9ee60982dba17dbc\", \"best_bid\":\"0.49\", \"best_ask\":\"0.5\"}, {\"asset_id\":\"8761897749749422724209054078244794145777693856614463256546737399611489089783\", \"price\":\"0.55\", \"size\":\"117.6\", \"side\":\"SELL\", \"hash\":\"e7cf7f9af6bb0dfb3a343228bafa71d25dfb2c69\", \"best_bid\":\"0.5\", \"best_ask\":\"0.51\"}], \"timestamp\":\"1785207751251\", \"event_type\":\"price_change\"}","received_at":"2026-07-28T03:02:31.104137Z","schema_version":"clob-market-ws.price_change.v1","sequence":null,"server_hash":null,"server_timestamp":"1785207751251","session_id":"3e519d9098404c15b234d96025eb1a2b","source":"clob_market_ws"},"received_at":"2026-07-28T03:02:31.104137Z","record_id":"45fbc855bcfba0f245cae76fb40bbe18ee1ab6ce23d8074eff6069c59b427d05","schema_fingerprint":"4aa3821a28b0b7c2400bc59aba4bcc0a76e971dadd19610d3ad38c768e124dc7","schema_version":"edge-lab-recorder.raw.v1","sequence":null,"source":"clob_market_ws"}
{"event_at":"2026-07-28T03:02:31.256000Z","event_fingerprint":"c3c9673e8c6ec3d4bec2e116cbe315449b3776f94e6f8b20510c5bde85359530","payload":{"connection_id":"a6b55582af5f430fb37ad02bf0922475","event_at":"2026-07-28T03:02:31.256000Z","event_type":"price_change","frame_hash":"f99bcf581d779ae39fd0a5d76e2571203000b2401abe952947b75f2c1073326c","frame_index":0,"kind":"data","monotonic_ns":309734127981208,"payload":{"event_type":"price_change","market":"0x779291bef19b6709f61e9764a954aafe9ffae488d50ae674aabdcb4f248006d5","price_changes":[{"asset_id":"8761897749749422724209054078244794145777693856614463256546737399611489089783","best_ask":"0.51","best_bid":"0.5","hash":"c46b5c976b8df0d2e6745382da26c50a9417ff08","price":"0.48","side":"BUY","size":"342"},{"asset_id":"14965588658799411272385430903075831224615961675357217884735713260981483529984","best_ask":"0.5","best_bid":"0.49","hash":"8d67b1116d4e74c22dab66d4328600042368066a","price":"0.52","side":"SELL","size":"342"}],"timestamp":"1785207751256"},"payload_hash":"6192f654a348011925ef34b1ee78c9745a5010f1fee70bf7a5dd80873dda15f0","raw_frame":"{\"market\":\"0x779291bef19b6709f61e9764a954aafe9ffae488d50ae674aabdcb4f248006d5\", \"price_changes\":[{\"asset_id\":\"8761897749749422724209054078244794145777693856614463256546737399611489089783\", \"price\":\"0.48\", \"size\":\"342\", \"side\":\"BUY\", \"hash\":\"c46b5c976b8df0d2e6745382da26c50a9417ff08\", \"best_bid\":\"0.5\", \"best_ask\":\"0.51\"}, {\"asset_id\":\"14965588658799411272385430903075831224615961675357217884735713260981483529984\", \"price\":\"0.52\", \"size\":\"342\", \"side\":\"SELL\", \"hash\":\"8d67b1116d4e74c22dab66d4328600042368066a\", \"best_bid\":\"0.49\", \"best_ask\":\"0.5\"}], \"timestamp\":\"1785207751256\", \"event_type\":\"price_change\"}","received_at":"2026-07-28T03:02:31.108529Z","schema_version":"clob-market-ws.price_change.v1","sequence":null,"server_hash":null,"server_timestamp":"1785207751256","session_id":"3e519d9098404c15b234d96025eb1a2b","source":"clob_market_ws"},"received_at":"2026-07-28T03:02:31.108529Z","record_id":"694f8798bede99512c227a8253267f6166ffbe5c946452267cfa7dca7fe9eba0","schema_fingerprint":"4aa3821a28b0b7c2400bc59aba4bcc0a76e971dadd19610d3ad38c768e124dc7","schema_version":"edge-lab-recorder.raw.v1","sequence":null,"source":"clob_market_ws"}
{"event_at":"2026-07-28T03:02:31.274000Z","event_fingerprint":"134176ed384ed206e6aeb81afbb381e55301fc19c5797684e24cb8d6fd711846","payload":{"connection_id":"a6b55582af5f430fb37ad02bf0922475","event_at":"2026-07-28T03:02:31.274000Z","event_type":"price_change","frame_hash":"628cd66dff11b4af669e14aedc95fabccd1428a7a74128a9e6da2d6a1abc1c42","frame_index":0,"kind":"data","monotonic_ns":309734145431625,"payload":{"event_type":"price_change","market":"0x779291bef19b6709f61e9764a954aafe9ffae488d50ae674aabdcb4f248006d5","price_changes":[{"asset_id":"8761897749749422724209054078244794145777693856614463256546737399611489089783","best_ask":"0.51","best_bid":"0.5","hash":"5b17f96ca00013e6b7ea4874a05cbb271ea518c5","price":"0.48","side":"BUY","size":"384"},{"asset_id":"14965588658799411272385430903075831224615961675357217884735713260981483529984","best_ask":"0.5","best_bid":"0.49","hash":"80f8219f4d5423a0896e038891e4c99736704465","price":"0.52","side":"SELL","size":"384"}],"timestamp":"1785207751274"},"payload_hash":"86a77822e9ec131ef82c3cb91b52566694fc5123394567be79572c82be23ffe8","raw_frame":"{\"market\":\"0x779291bef19b6709f61e9764a954aafe9ffae488d50ae674aabdcb4f248006d5\", \"price_changes\":[{\"asset_id\":\"8761897749749422724209054078244794145777693856614463256546737399611489089783\", \"price\":\"0.48\", \"size\":\"384\", \"side\":\"BUY\", \"hash\":\"5b17f96ca00013e6b7ea4874a05cbb271ea518c5\", \"best_bid\":\"0.5\", \"best_ask\":\"0.51\"}, {\"asset_id\":\"14965588658799411272385430903075831224615961675357217884735713260981483529984\", \"price\":\"0.52\", \"size\":\"384\", \"side\":\"SELL\", \"hash\":\"80f8219f4d5423a0896e038891e4c99736704465\", \"best_bid\":\"0.49\", \"best_ask\":\"0.5\"}], \"timestamp\":\"1785207751274\", \"event_type\":\"price_change\"}","received_at":"2026-07-28T03:02:31.125979Z","schema_version":"clob-market-ws.price_change.v1","sequence":null,"server_hash":null,"server_timestamp":"1785207751274","session_id":"3e519d9098404c15b234d96025eb1a2b","source":"clob_market_ws"},"received_at":"2026-07-28T03:02:31.125979Z","record_id":"a2f1b4cfffc8a2445628bb56186658ba02df937fc877ec413e32850d457609b6","schema_fingerprint":"4aa3821a28b0b7c2400bc59aba4bcc0a76e971dadd19610d3ad38c768e124dc7","schema_version":"edge-lab-recorder.raw.v1","sequence":null,"source":"clob_market_ws"}
{"event_at":"2026-07-28T03:02:31.299000Z","event_fingerprint":"a8f9245c11014721818339b84e390fe46a342a63ad7fdaa88689ea5675a5911a","payload":{"connection_id":"a6b55582af5f430fb37ad02bf0922475","event_at":"2026-07-28T03:02:31.299000Z","event_type":"price_change","frame_hash":"8aae6f2119da23e53a1312a789cb0bdf9b391a7a1c65585887023fb401d6437f","frame_index":0,"kind":"data","monotonic_ns":309734171525500,"payload":{"event_type":"price_change","market":"0x779291bef19b6709f61e9764a954aafe9ffae488d50ae674aabdcb4f248006d5","price_changes":[{"asset_id":"8761897749749422724209054078244794145777693856614463256546737399611489089783","best_ask":"0.51","best_bid":"0.5","hash":"feafd67c0bf696aa69e6242bc0d8beb70c2e946e","price":"0.02","side":"BUY","size":"733.1"},{"asset_id":"14965588658799411272385430903075831224615961675357217884735713260981483529984","best_ask":"0.5","best_bid":"0.49","hash":"d73c719a9f4a752d33e427f78b668a75e2340ffa","price":"0.98","side":"SELL","size":"733.1"}],"timestamp":"1785207751299"},"payload_hash":"e0930cdd698869affc432cf8c9f4deeae24a6b9510b1ff6cb523a1979fb7c31d","raw_frame":"{\"market\":\"0x779291bef19b6709f61e9764a954aafe9ffae488d50ae674aabdcb4f248006d5\", \"price_changes\":[{\"asset_id\":\"8761897749749422724209054078244794145777693856614463256546737399611489089783\", \"price\":\"0.02\", \"size\":\"733.1\", \"side\":\"BUY\", \"hash\":\"feafd67c0bf696aa69e6242bc0d8beb70c2e946e\", \"best_bid\":\"0.5\", \"best_ask\":\"0.51\"}, {\"asset_id\":\"14965588658799411272385430903075831224615961675357217884735713260981483529984\", \"price\":\"0.98\", \"size\":\"733.1\", \"side\":\"SELL\", \"hash\":\"d73c719a9f4a752d33e427f78b668a75e2340ffa\", \"best_bid\":\"0.49\", \"best_ask\":\"0.5\"}], \"timestamp\":\"1785207751299\", \"event_type\":\"price_change\"}","received_at":"2026-07-28T03:02:31.152067Z","schema_version":"clob-market-ws.price_change.v1","sequence":null,"server_hash":null,"server_timestamp":"1785207751299","session_id":"3e519d9098404c15b234d96025eb1a2b","source":"clob_market_ws"},"received_at":"2026-07-28T03:02:31.152067Z","record_id":"732e2b5bfb84ed098397515a467777784dfba76ba8263d35b9bc9ce0af160f9f","schema_fingerprint":"4aa3821a28b0b7c2400bc59aba4bcc0a76e971dadd19610d3ad38c768e124dc7","schema_version":"edge-lab-recorder.raw.v1","sequence":null,"source":"clob_market_ws"}
{"event_at":"2026-07-28T03:02:31.338000Z","event_fingerprint":"a160119eabfff7a7b04cb83c028925441cb957952e784677697f76e1a94a5d33","payload":{"connection_id":"a6b55582af5f430fb37ad02bf0922475","event_at":"2026-07-28T03:02:31.338000Z","event_type":"price_change","frame_hash":"0447442149b58db537614d929b15a55927978b5f8f81a845b9502cb777ee8366","frame_index":0,"kind":"data","monotonic_ns":309734214090791,"payload":{"event_type":"price_change","market":"0x779291bef19b6709f61e9764a954aafe9ffae488d50ae674aabdcb4f248006d5","price_changes":[{"asset_id":"8761897749749422724209054078244794145777693856614463256546737399611489089783","best_ask":"0.51","best_bid":"0.5","hash":"58b2363f9ac72b05d1f8393c1f66f4ea3ef4d57d","price":"0.48","side":"BUY","size":"396.03"},{"asset_id":"14965588658799411272385430903075831224615961675357217884735713260981483529984","best_ask":"0.5","best_bid":"0.49","hash":"dd71b4e699c7c1614ad7728cfa3570b8d07486c9","price":"0.52","side":"SELL","size":"396.03"}],"timestamp":"1785207751338"},"payload_hash":"f36140c589bbf407b3ab5189945943f6784e68a32ecebf573f765f57efcd90d0","raw_frame":"{\"market\":\"0x779291bef19b6709f61e9764a954aafe9ffae488d50ae674aabdcb4f248006d5\", \"price_changes\":[{\"asset_id\":\"8761897749749422724209054078244794145777693856614463256546737399611489089783\", \"price\":\"0.48\", \"size\":\"396.03\", \"side\":\"BUY\", \"hash\":\"58b2363f9ac72b05d1f8393c1f66f4ea3ef4d57d\", \"best_bid\":\"0.5\", \"best_ask\":\"0.51\"}, {\"asset_id\":\"14965588658799411272385430903075831224615961675357217884735713260981483529984\", \"price\":\"0.52\", \"size\":\"396.03\", \"side\":\"SELL\", \"hash\":\"dd71b4e699c7c1614ad7728cfa3570b8d07486c9\", \"best_bid\":\"0.49\", \"best_ask\":\"0.5\"}], \"timestamp\":\"1785207751338\", \"event_type\":\"price_change\"}","received_at":"2026-07-28T03:02:31.194629Z","schema_version":"clob-market-ws.price_change.v1","sequence":null,"server_hash":null,"server_timestamp":"1785207751338","session_id":"3e519d9098404c15b234d96025eb1a2b","source":"clob_market_ws"},"received_at":"2026-07-28T03:02:31.194629Z","record_id":"01820180785c4811bc814461419f5abf0d8aaab6743db339b19a62fbc4c0d2fb","schema_fingerprint":"4aa3821a28b0b7c2400bc59aba4bcc0a76e971dadd19610d3ad38c768e124dc7","schema_version":"edge-lab-recorder.raw.v1","sequence":null,"source":"clob_market_ws"}
{"event_at":"2026-07-28T03:02:31.339000Z","event_fingerprint":"cf3ba13d1a1c761667b5fc00c53f600776e6685a9c7893b9661ea88060abed4a","payload":{"connection_id":"a6b55582af5f430fb37ad02bf0922475","event_at":"2026-07-28T03:02:31.339000Z","event_type":"price_change","frame_hash":"b416d703c39875d4dd9758fa3fce7cc66b6c3fc79123e8fe279e38a3aaa2dea5","frame_index":0,"kind":"data","monotonic_ns":309734215883958,"payload":{"event_type":"price_change","market":"0x779291bef19b6709f61e9764a954aafe9ffae488d50ae674aabdcb4f248006d5","price_changes":[{"asset_id":"14965588658799411272385430903075831224615961675357217884735713260981483529984","best_ask":"0.5","best_bid":"0.49","hash":"2ca2a357cff778702bd6028769940ec13c899ee0","price":"0.38","side":"BUY","size":"219.34"},{"asset_id":"8761897749749422724209054078244794145777693856614463256546737399611489089783","best_ask":"0.51","best_bid":"0.5","hash":"f77fb089e3ee27382b3adeefd8dae87139596423","price":"0.62","side":"SELL","size":"219.34"}],"timestamp":"1785207751339"},"payload_hash":"241a37508b0565f849f63e2aeca53ff0236a7fa9f0021f95a46f1cb9ccb60c98","raw_frame":"{\"market\":\"0x779291bef19b6709f61e9764a954aafe9ffae488d50ae674aabdcb4f248006d5\", \"price_changes\":[{\"asset_id\":\"14965588658799411272385430903075831224615961675357217884735713260981483529984\", \"price\":\"0.38\", \"size\":\"219.34\", \"side\":\"BUY\", \"hash\":\"2ca2a357cff778702bd6028769940ec13c899ee0\", \"best_bid\":\"0.49\", \"best_ask\":\"0.5\"}, {\"asset_id\":\"8761897749749422724209054078244794145777693856614463256546737399611489089783\", \"price\":\"0.62\", \"size\":\"219.34\", \"side\":\"SELL\", \"hash\":\"f77fb089e3ee27382b3adeefd8dae87139596423\", \"best_bid\":\"0.5\", \"best_ask\":\"0.51\"}], \"timestamp\":\"1785207751339\", \"event_type\":\"price_change\"}","received_at":"2026-07-28T03:02:31.196423Z","schema_version":"clob-market-ws.price_change.v1","sequence":null,"server_hash":null,"server_timestamp":"1785207751339","session_id":"3e519d9098404c15b234d96025eb1a2b","source":"clob_market_ws"},"received_at":"2026-07-28T03:02:31.196423Z","record_id":"55ed69eefa887ce6399762badca568ce3d8d77f202040c1bae5bf981bd8ef7ff","schema_fingerprint":"4aa3821a28b0b7c2400bc59aba4bcc0a76e971dadd19610d3ad38c768e124dc7","schema_version":"edge-lab-recorder.raw.v1","sequence":null,"source":"clob_market_ws"}
{"event_at":"2026-07-28T03:02:31.344000Z","event_fingerprint":"2e4242114bab5993e25ad09397f6d7698135392a5cd4f5bc3a16a0cb3cd7a516","payload":{"connection_id":"a6b55582af5f430fb37ad02bf0922475","event_at":"2026-07-28T03:02:31.344000Z","event_type":"price_change","frame_hash":"4b44d7cd447932169026501c7934e82837fcefdecd08025a1b99bc3bbaab0eed","frame_index":0,"kind":"data","monotonic_ns":309734217822125,"payload":{"event_type":"price_change","market":"0x779291bef19b6709f61e9764a954aafe9ffae488d50ae674aabdcb4f248006d5","price_changes":[{"asset_id":"14965588658799411272385430903075831224615961675357217884735713260981483529984","best_ask":"0.5","best_bid":"0.49","hash":"d23961c27080b254a4ca835cb8d2872e9cb32f90","price":"0.42","side":"BUY","size":"191"},{"asset_id":"8761897749749422724209054078244794145777693856614463256546737399611489089783","best_ask":"0.51","best_bid":"0.5","hash":"496ab2605fd7825f1f5bd03fa0d298db5d08562a","price":"0.58","side":"SELL","size":"191"}],"timestamp":"1785207751344"},"payload_hash":"eb26abd03fd83d5bacdefdac3a911d1790c23fe33666dcacc971d90d6679de5c","raw_frame":"{\"market\":\"0x779291bef19b6709f61e9764a954aafe9ffae488d50ae674aabdcb4f248006d5\", \"price_changes\":[{\"asset_id\":\"14965588658799411272385430903075831224615961675357217884735713260981483529984\", \"price\":\"0.42\", \"size\":\"191\", \"side\":\"BUY\", \"hash\":\"d23961c27080b254a4ca835cb8d2872e9cb32f90\", \"best_bid\":\"0.49\", \"best_ask\":\"0.5\"}, {\"asset_id\":\"8761897749749422724209054078244794145777693856614463256546737399611489089783\", \"price\":\"0.58\", \"size\":\"191\", \"side\":\"SELL\", \"hash\":\"496ab2605fd7825f1f5bd03fa0d298db5d08562a\", \"best_bid\":\"0.5\", \"best_ask\":\"0.51\"}], \"timestamp\":\"1785207751344\", \"event_type\":\"price_change\"}","received_at":"2026-07-28T03:02:31.198365Z","schema_version":"clob-market-ws.price_change.v1","sequence":null,"server_hash":null,"server_timestamp":"1785207751344","session_id":"3e519d9098404c15b234d96025eb1a2b","source":"clob_market_ws"},"received_at":"2026-07-28T03:02:31.198365Z","record_id":"d1450beb3a635346ec7d8e54fdfc4a7122a4407c5c58b56825297344cfa318c2","schema_fingerprint":"4aa3821a28b0b7c2400bc59aba4bcc0a76e971dadd19610d3ad38c768e124dc7","schema_version":"edge-lab-recorder.raw.v1","sequence":null,"source":"clob_market_ws"}
{"event_at":"2026-07-28T03:02:31.344000Z","event_fingerprint":"a34a570c50b34dba674e7d87fd1ed11a00b1fa8fb59709b9930c6c88edcfab64","payload":{"connection_id":"a6b55582af5f430fb37ad02bf0922475","event_at":"2026-07-28T03:02:31.344000Z","event_type":"price_change","frame_hash":"827ad1f93188ebbaedec2d701f61c354483195f2872500656448c79a1f7a2623","frame_index":0,"kind":"data","monotonic_ns":309734219503375,"payload":{"event_type":"price_change","market":"0x779291bef19b6709f61e9764a954aafe9ffae488d50ae674aabdcb4f248006d5","price_changes":[{"asset_id":"8761897749749422724209054078244794145777693856614463256546737399611489089783","best_ask":"0.51","best_bid":"0.5","hash":"496ab2605fd7825f1f5bd03fa0d298db5d08562a","price":"0.44","side":"BUY","size":"296"},{"asset_id":"14965588658799411272385430903075831224615961675357217884735713260981483529984","best_ask":"0.5","best_bid":"0.49","hash":"d23961c27080b254a4ca835cb8d2872e9cb32f90","price":"0.56","side":"SELL","size":"296"}],"timestamp":"1785207751344"},"payload_hash":"42ae0dc776e5090093b68e8c1061a2f559b88ec12e3e83e5e0b0d70fe318a0c0","raw_frame":"{\"market\":\"0x779291bef19b6709f61e9764a954aafe9ffae488d50ae674aabdcb4f248006d5\", \"price_changes\":[{\"asset_id\":\"8761897749749422724209054078244794145777693856614463256546737399611489089783\", \"price\":\"0.44\", \"size\":\"296\", \"side\":\"BUY\", \"hash\":\"496ab2605fd7825f1f5bd03fa0d298db5d08562a\", \"best_bid\":\"0.5\", \"best_ask\":\"0.51\"}, {\"asset_id\":\"14965588658799411272385430903075831224615961675357217884735713260981483529984\", \"price\":\"0.56\", \"size\":\"296\", \"side\":\"SELL\", \"hash\":\"d23961c27080b254a4ca835cb8d2872e9cb32f90\", \"best_bid\":\"0.49\", \"best_ask\":\"0.5\"}], \"timestamp\":\"1785207751344\", \"event_type\":\"price_change\"}","received_at":"2026-07-28T03:02:31.200046Z","schema_version":"clob-market-ws.price_change.v1","sequence":null,"server_hash":null,"server_timestamp":"1785207751344","session_id":"3e519d9098404c15b234d96025eb1a2b","source":"clob_market_ws"},"received_at":"2026-07-28T03:02:31.200046Z","record_id":"c55b360aa1c45eff4b76373e1858de656a3d5f5acc4f036e45e957868e38353c","schema_fingerprint":"4aa3821a28b0b7c2400bc59aba4bcc0a76e971dadd19610d3ad38c768e124dc7","schema_version":"edge-lab-recorder.raw.v1","sequence":null,"source":"clob_market_ws"}
{"event_at":"2026-07-28T03:02:31.353000Z","event_fingerprint":"913c3ea478cbea8891e1a152cf68d2fdecec4a6bb566ea61931e85d06270cac9","payload":{"connection_id":"a6b55582af5f430fb37ad02bf0922475","event_at":"2026-07-28T03:02:31.353000Z","event_type":"price_change","frame_hash":"98cf66a9b26873de740be5c89e3cfba1cdf36ce410e737aca5103e2725a861d3","frame_index":0,"kind":"data","monotonic_ns":309734225396416,"payload":{"event_type":"price_change","market":"0x779291bef19b6709f61e9764a954aafe9ffae488d50ae674aabdcb4f248006d5","price_changes":[{"asset_id":"8761897749749422724209054078244794145777693856614463256546737399611489089783","best_ask":"0.51","best_bid":"0.5","hash":"0135dc39c2b74ac2b5d1b0c66dec4040445ba22e","price":"0.5","side":"BUY","size":"25.18"},{"asset_id":"14965588658799411272385430903075831224615961675357217884735713260981483529984","best_ask":"0.5","best_bid":"0.49","hash":"c3fb14404ffffb43238a8d97fa4a131ad6eca278","price":"0.5","side":"SELL","size":"25.18"}],"timestamp":"1785207751353"},"payload_hash":"9d1b6c2d963f3840b79c30748ffe229b5b046af99c97579d4611d5db86e82794","raw_frame":"{\"market\":\"0x779291bef19b6709f61e9764a954aafe9ffae488d50ae674aabdcb4f248006d5\", \"price_changes\":[{\"asset_id\":\"8761897749749422724209054078244794145777693856614463256546737399611489089783\", \"price\":\"0.5\", \"size\":\"25.18\", \"side\":\"BUY\", \"hash\":\"0135dc39c2b74ac2b5d1b0c66dec4040445ba22e\", \"best_bid\":\"0.5\", \"best_ask\":\"0.51\"}, {\"asset_id\":\"14965588658799411272385430903075831224615961675357217884735713260981483529984\", \"price\":\"0.5\", \"size\":\"25.18\", \"side\":\"SELL\", \"hash\":\"c3fb14404ffffb43238a8d97fa4a131ad6eca278\", \"best_bid\":\"0.49\", \"best_ask\":\"0.5\"}], \"timestamp\":\"1785207751353\", \"event_type\":\"price_change\"}","received_at":"2026-07-28T03:02:31.205938Z","schema_version":"clob-market-ws.price_change.v1","sequence":null,"server_hash":null,"server_timestamp":"1785207751353","session_id":"3e519d9098404c15b234d96025eb1a2b","source":"clob_market_ws"},"received_at":"2026-07-28T03:02:31.205938Z","record_id":"0f10c36a2d289b12d97e3efa65fd449b35dcd9ce63f44ce41816f59367029a08","schema_fingerprint":"4aa3821a28b0b7c2400bc59aba4bcc0a76e971dadd19610d3ad38c768e124dc7","schema_version":"edge-lab-recorder.raw.v1","sequence":null,"source":"clob_market_ws"}
{"event_at":"2026-07-28T03:02:31.354000Z","event_fingerprint":"313c1af4e0b7a5bf3bb1609480d6cdfd5e1e455ed2431d56dbba21f34867aefc","payload":{"connection_id":"a6b55582af5f430fb37ad02bf0922475","event_at":"2026-07-28T03:02:31.354000Z","event_type":"price_change","frame_hash":"c9ad3a79356e954e3b12bde444ea9569bd3fdc00723e08f21f14452bc41b32ad","frame_index":0,"kind":"data","monotonic_ns":309734227005000,"payload":{"event_type":"price_change","market":"0x779291bef19b6709f61e9764a954aafe9ffae488d50ae674aabdcb4f248006d5","price_changes":[{"asset_id":"8761897749749422724209054078244794145777693856614463256546737399611489089783","best_ask":"0.51","best_bid":"0.5","hash":"8cf47393d050ca68193554b5f40d7bce005928c8","price":"0.49","side":"BUY","size":"6"},{"asset_id":"14965588658799411272385430903075831224615961675357217884735713260981483529984","best_ask":"0.5","best_bid":"0.49","hash":"3ce10a21f223d246efd6297a8b955b0f0f8a7c84","price":"0.51","side":"SELL","size":"6"}],"timestamp":"1785207751354"},"payload_hash":"464cba6c138d6fde77582f3625f9bbd2220a78c14bb2a3ea1331766c9c67257a","raw_frame":"{\"market\":\"0x779291bef19b6709f61e9764a954aafe9ffae488d50ae674aabdcb4f248006d5\", \"price_changes\":[{\"asset_id\":\"8761897749749422724209054078244794145777693856614463256546737399611489089783\", \"price\":\"0.49\", \"size\":\"6\", \"side\":\"BUY\", \"hash\":\"8cf47393d050ca68193554b5f40d7bce005928c8\", \"best_bid\":\"0.5\", \"best_ask\":\"0.51\"}, {\"asset_id\":\"14965588658799411272385430903075831224615961675357217884735713260981483529984\", \"price\":\"0.51\", \"size\":\"6\", \"side\":\"SELL\", \"hash\":\"3ce10a21f223d246efd6297a8b955b0f0f8a7c84\", \"best_bid\":\"0.49\", \"best_ask\":\"0.5\"}], \"timestamp\":\"1785207751354\", \"event_type\":\"price_change\"}","received_at":"2026-07-28T03:02:31.207549Z","schema_version":"clob-market-ws.price_change.v1","sequence":null,"server_hash":null,"server_timestamp":"1785207751354","session_id":"3e519d9098404c15b234d96025eb1a2b","source":"clob_market_ws"},"received_at":"2026-07-28T03:02:31.207549Z","record_id":"18706e140d44037719a0a9d6db958db9d6c5b8fda06f04b89263765cfc321c87","schema_fingerprint":"4aa3821a28b0b7c2400bc59aba4bcc0a76e971dadd19610d3ad38c768e124dc7","schema_version":"edge-lab-recorder.raw.v1","sequence":null,"source":"clob_market_ws"}
{"event_at":"2026-07-28T03:02:31.371000Z","event_fingerprint":"a759bd517decfdca674d6188e13fccf9478a8c71ceb26164542ee80f8b278d88","payload":{"connection_id":"a6b55582af5f430fb37ad02bf0922475","event_at":"2026-07-28T03:02:31.371000Z","event_type":"price_change","frame_hash":"be397a50910a18f2420e8314422fddf0388ce1879ed950a4642659ac27df9e7a","frame_index":0,"kind":"data","monotonic_ns":309734253959958,"payload":{"event_type":"price_change","market":"0x779291bef19b6709f61e9764a954aafe9ffae488d50ae674aabdcb4f248006d5","price_changes":[{"asset_id":"8761897749749422724209054078244794145777693856614463256546737399611489089783","best_ask":"0.51","best_bid":"0.5","hash":"3f4cd2a62dbffbd01116c4332783843b881200a7","price":"0.48","side":"BUY","size":"391.03"},{"asset_id":"14965588658799411272385430903075831224615961675357217884735713260981483529984","best_ask":"0.5","best_bid":"0.49","hash":"34a082ecbc34720e28ad829d455dc35cc349f4dc","price":"0.52","side":"SELL","size":"391.03"}],"timestamp":"1785207751371"},"payload_hash":"63a7e72c522aa4d486566797b9807fcfd6e2d482dfbed8b52bb5eb2133026001","raw_frame":"{\"market\":\"0x779291bef19b6709f61e9764a954aafe9ffae488d50ae674aabdcb4f248006d5\", \"price_changes\":[{\"asset_id\":\"8761897749749422724209054078244794145777693856614463256546737399611489089783\", \"price\":\"0.48\", \"size\":\"391.03\", \"side\":\"BUY\", \"hash\":\"3f4cd2a62dbffbd01116c4332783843b881200a7\", \"best_bid\":\"0.5\", \"best_ask\":\"0.51\"}, {\"asset_id\":\"14965588658799411272385430903075831224615961675357217884735713260981483529984\", \"price\":\"0.52\", \"size\":\"391.03\", \"side\":\"SELL\", \"hash\":\"34a082ecbc34720e28ad829d455dc35cc349f4dc\", \"best_bid\":\"0.49\", \"best_ask\":\"0.5\"}], \"timestamp\":\"1785207751371\", \"event_type\":\"price_change\"}","received_at":"2026-07-28T03:02:31.234503Z","schema_version":"clob-market-ws.price_change.v1","sequence":null,"server_hash":null,"server_timestamp":"1785207751371","session_id":"3e519d9098404c15b234d96025eb1a2b","source":"clob_market_ws"},"received_at":"2026-07-28T03:02:31.234503Z","record_id":"6027a86c5726cd4186778536e8245ef744de45adbdb86d86c44e0287ad4812df","schema_fingerprint":"4aa3821a28b0b7c2400bc59aba4bcc0a76e971dadd19610d3ad38c768e124dc7","schema_version":"edge-lab-recorder.raw.v1","sequence":null,"source":"clob_market_ws"}
{"event_at":"2026-07-28T03:02:31.380000Z","event_fingerprint":"32955c3020f15d9300f6407a88e3c3a75837e83094410ff0e116e3716c57aa63","payload":{"connection_id":"a6b55582af5f430fb37ad02bf0922475","event_at":"2026-07-28T03:02:31.380000Z","event_type":"price_change","frame_hash":"d6e9fcc7e72d0fd10d187dd83e1c37c59c9c2c1a0b62f6196558272e3e2ab5f3","frame_index":0,"kind":"data","monotonic_ns":309734255512041,"payload":{"event_type":"price_change","market":"0x779291bef19b6709f61e9764a954aafe9ffae488d50ae674aabdcb4f248006d5","price_changes":[{"asset_id":"8761897749749422724209054078244794145777693856614463256546737399611489089783","best_ask":"0.51","best_bid":"0.5","hash":"39928134d7b184d71af713721f2b256d237d84cc","price":"0.47","side":"BUY","size":"131.06"},{"asset_id":"14965588658799411272385430903075831224615961675357217884735713260981483529984","best_ask":"0.5","best_bid":"0.49","hash":"2e6b355b6acb7d026e64ed91d355522668f9ef9f","price":"0.53","side":"SELL","size":"131.06"}],"timestamp":"1785207751380"},"payload_hash":"d2c0da5e35fd360395c2365b169230bbdb97303ab665e899902d047c6cf6b05a","raw_frame":"{\"market\":\"0x779291bef19b6709f61e9764a954aafe9ffae488d50ae674aabdcb4f248006d5\", \"price_changes\":[{\"asset_id\":\"8761897749749422724209054078244794145777693856614463256546737399611489089783\", \"price\":\"0.47\", \"size\":\"131.06\", \"side\":\"BUY\", \"hash\":\"39928134d7b184d71af713721f2b256d237d84cc\", \"best_bid\":\"0.5\", \"best_ask\":\"0.51\"}, {\"asset_id\":\"14965588658799411272385430903075831224615961675357217884735713260981483529984\", \"price\":\"0.53\", \"size\":\"131.06\", \"side\":\"SELL\", \"hash\":\"2e6b355b6acb7d026e64ed91d355522668f9ef9f\", \"best_bid\":\"0.49\", \"best_ask\":\"0.5\"}], \"timestamp\":\"1785207751380\", \"event_type\":\"price_change\"}","received_at":"2026-07-28T03:02:31.236055Z","schema_version":"clob-market-ws.price_change.v1","sequence":null,"server_hash":null,"server_timestamp":"1785207751380","session_id":"3e519d9098404c15b234d96025eb1a2b","source":"clob_market_ws"},"received_at":"2026-07-28T03:02:31.236055Z","record_id":"0737ef0ad1ccd53eae321f720cab7bc1d1c6340e123b1a272f33eefa24b9d242","schema_fingerprint":"4aa3821a28b0b7c2400bc59aba4bcc0a76e971dadd19610d3ad38c768e124dc7","schema_version":"edge-lab-recorder.raw.v1","sequence":null,"source":"clob_market_ws"}
{"event_at":"2026-07-28T03:02:31.381000Z","event_fingerprint":"0f5dce6a0713ec865b2a8f36f517b2501a142cfe0c96ff38f9df17deaa69b7f4","payload":{"connection_id":"a6b55582af5f430fb37ad02bf0922475","event_at":"2026-07-28T03:02:31.381000Z","event_type":"price_change","frame_hash":"9a7d26926fc2040fd6281fd9f11fe988b62103a64147a063388502cc70ffb6c0","frame_index":0,"kind":"data","monotonic_ns":309734257098041,"payload":{"event_type":"price_change","market":"0x779291bef19b6709f61e9764a954aafe9ffae488d50ae674aabdcb4f248006d5","price_changes":[{"asset_id":"14965588658799411272385430903075831224615961675357217884735713260981483529984","best_ask":"0.5","best_bid":"0.49","hash":"200c14606bbf118f112c12561ea278839899ce36","price":"0.48","side":"BUY","size":"412"},{"asset_id":"8761897749749422724209054078244794145777693856614463256546737399611489089783","best_ask":"0.51","best_bid":"0.5","hash":"882ff3deafe2713d435d3ce4efb7d282ae3ee116","price":"0.52","side":"SELL","size":"412"}],"timestamp":"1785207751381"},"payload_hash":"27e26e63ce46c2d96432a3b2ced4a5e28c5f86d0ca035f74cc468901c2ff1d3c","raw_frame":"{\"market\":\"0x779291bef19b6709f61e9764a954aafe9ffae488d50ae674aabdcb4f248006d5\", \"price_changes\":[{\"asset_id\":\"14965588658799411272385430903075831224615961675357217884735713260981483529984\", \"price\":\"0.48\", \"size\":\"412\", \"side\":\"BUY\", \"hash\":\"200c14606bbf118f112c12561ea278839899ce36\", \"best_bid\":\"0.49\", \"best_ask\":\"0.5\"}, {\"asset_id\":\"8761897749749422724209054078244794145777693856614463256546737399611489089783\", \"price\":\"0.52\", \"size\":\"412\", \"side\":\"SELL\", \"hash\":\"882ff3deafe2713d435d3ce4efb7d282ae3ee116\", \"best_bid\":\"0.5\", \"best_ask\":\"0.51\"}], \"timestamp\":\"1785207751381\", \"event_type\":\"price_change\"}","received_at":"2026-07-28T03:02:31.237640Z","schema_version":"clob-market-ws.price_change.v1","sequence":null,"server_hash":null,"server_timestamp":"1785207751381","session_id":"3e519d9098404c15b234d96025eb1a2b","source":"clob_market_ws"},"received_at":"2026-07-28T03:02:31.237640Z","record_id":"70fdbd720e82412464082c7ca4b9a57b97e283294564705faf54a125e0e484bb","schema_fingerprint":"4aa3821a28b0b7c2400bc59aba4bcc0a76e971dadd19610d3ad38c768e124dc7","schema_version":"edge-lab-recorder.raw.v1","sequence":null,"source":"clob_market_ws"}
{"event_at":"2026-07-28T03:02:31.381000Z","event_fingerprint":"ea52688c80708cfe7ca94c6fa0b0ff1f57293654d49f71186f53889e4d3be2f4","payload":{"connection_id":"a6b55582af5f430fb37ad02bf0922475","event_at":"2026-07-28T03:02:31.381000Z","event_type":"price_change","frame_hash":"7ca55d813496e0d7ea679d28063fdafcd71c0a9a1c906d4dde7104bf38a06cb9","frame_index":0,"kind":"data","monotonic_ns":309734258705166,"payload":{"event_type":"price_change","market":"0x779291bef19b6709f61e9764a954aafe9ffae488d50ae674aabdcb4f248006d5","price_changes":[{"asset_id":"14965588658799411272385430903075831224615961675357217884735713260981483529984","best_ask":"0.5","best_bid":"0.49","hash":"59c7207b815715ce368bb653cb7af172107c0837","price":"0.39","side":"BUY","size":"218.18"},{"asset_id":"8761897749749422724209054078244794145777693856614463256546737399611489089783","best_ask":"0.51","best_bid":"0.5","hash":"9d350fa01479861755e36b871461006e4621307d","price":"0.61","side":"SELL","size":"218.18"}],"timestamp":"1785207751381"},"payload_hash":"60aed4d48d3acc914302f197ae84ab7ccebdadfef62a9ac75efbccd91f5116e4","raw_frame":"{\"market\":\"0x779291bef19b6709f61e9764a954aafe9ffae488d50ae674aabdcb4f248006d5\", \"price_changes\":[{\"asset_id\":\"14965588658799411272385430903075831224615961675357217884735713260981483529984\", \"price\":\"0.39\", \"size\":\"218.18\", \"side\":\"BUY\", \"hash\":\"59c7207b815715ce368bb653cb7af172107c0837\", \"best_bid\":\"0.49\", \"best_ask\":\"0.5\"}, {\"asset_id\":\"8761897749749422724209054078244794145777693856614463256546737399611489089783\", \"price\":\"0.61\", \"size\":\"218.18\", \"side\":\"SELL\", \"hash\":\"9d350fa01479861755e36b871461006e4621307d\", \"best_bid\":\"0.5\", \"best_ask\":\"0.51\"}], \"timestamp\":\"1785207751381\", \"event_type\":\"price_change\"}","received_at":"2026-07-28T03:02:31.239250Z","schema_version":"clob-market-ws.price_change.v1","sequence":null,"server_hash":null,"server_timestamp":"1785207751381","session_id":"3e519d9098404c15b234d96025eb1a2b","source":"clob_market_ws"},"received_at":"2026-07-28T03:02:31.239250Z","record_id":"598b8e68b89d37065973de1c9697a8490988f5d6b5f758efc0a80292a2ecb0d2","schema_fingerprint":"4aa3821a28b0b7c2400bc59aba4bcc0a76e971dadd19610d3ad38c768e124dc7","schema_version":"edge-lab-recorder.raw.v1","sequence":null,"source":"clob_market_ws"}
{"event_at":"2026-07-28T03:02:31.386000Z","event_fingerprint":"40432c3bf4a9703e616624be5c2cf26e0fdb1e0a044efd16ccaa8b8fc3f52aea","payload":{"connection_id":"a6b55582af5f430fb37ad02bf0922475","event_at":"2026-07-28T03:02:31.386000Z","event_type":"price_change","frame_hash":"b177cd1da12f9e42c08d24a8bdca04a48f6801cfd95708f4284feb73e5d3bc8d","frame_index":0,"kind":"data","monotonic_ns":309734261520500,"payload":{"event_type":"price_change","market":"0x779291bef19b6709f61e9764a954aafe9ffae488d50ae674aabdcb4f248006d5","price_changes":[{"asset_id":"8761897749749422724209054078244794145777693856614463256546737399611489089783","best_ask":"0.51","best_bid":"0.5","hash":"a37a68e1e15a6d6f0c027c70b2d50d5d9cd6e5ac","price":"0.5","side":"BUY","size":"12.58"},{"asset_id":"14965588658799411272385430903075831224615961675357217884735713260981483529984","best_ask":"0.5","best_bid":"0.49","hash":"29994e7af12ab2c77f1a9e160e1f89caefcdd1ed","price":"0.5","side":"SELL","size":"12.58"}],"timestamp":"1785207751386"},"payload_hash":"0d342be0d4d05a5da95f622b460bdd7340f1dadd489493227b9a39b3e08b4a08","raw_frame":"{\"market\":\"0x779291bef19b6709f61e9764a954aafe9ffae488d50ae674aabdcb4f248006d5\", \"price_changes\":[{\"asset_id\":\"8761897749749422724209054078244794145777693856614463256546737399611489089783\", \"price\":\"0.5\", \"size\":\"12.58\", \"side\":\"BUY\", \"hash\":\"a37a68e1e15a6d6f0c027c70b2d50d5d9cd6e5ac\", \"best_bid\":\"0.5\", \"best_ask\":\"0.51\"}, {\"asset_id\":\"14965588658799411272385430903075831224615961675357217884735713260981483529984\", \"price\":\"0.5\", \"size\":\"12.58\", \"side\":\"SELL\", \"hash\":\"29994e7af12ab2c77f1a9e160e1f89caefcdd1ed\", \"best_bid\":\"0.49\", \"best_ask\":\"0.5\"}], \"timestamp\":\"1785207751386\", \"event_type\":\"price_change\"}","received_at":"2026-07-28T03:02:31.242062Z","schema_version":"clob-market-ws.price_change.v1","sequence":null,"server_hash":null,"server_timestamp":"1785207751386","session_id":"3e519d9098404c15b234d96025eb1a2b","source":"clob_market_ws"},"received_at":"2026-07-28T03:02:31.242062Z","record_id":"bdf6286037d28259136d5b1b11c581f4ce3d0293256dc853a06cdbb614ea6f7c","schema_fingerprint":"4aa3821a28b0b7c2400bc59aba4bcc0a76e971dadd19610d3ad38c768e124dc7","schema_version":"edge-lab-recorder.raw.v1","sequence":null,"source":"clob_market_ws"}
{"event_at":"2026-07-28T03:02:31.386000Z","event_fingerprint":"26e7f845a30123bcabe1b4e2c55fc6aba6f32b65e908b12458072fb6459feb87","payload":{"connection_id":"a6b55582af5f430fb37ad02bf0922475","event_at":"2026-07-28T03:02:31.386000Z","event_type":"price_change","frame_hash":"8a7479eccf26cd842974e6e70c5126ffd394ad46431779964491bd72238ed473","frame_index":0,"kind":"data","monotonic_ns":309734263699583,"payload":{"event_type":"price_change","market":"0x779291bef19b6709f61e9764a954aafe9ffae488d50ae674aabdcb4f248006d5","price_changes":[{"asset_id":"8761897749749422724209054078244794145777693856614463256546737399611489089783","best_ask":"0.51","best_bid":"0.5","hash":"fc9ea4348402360a6431b38bf9d61d55bcfa13de","price":"0.44","side":"BUY","size":"266"},{"asset_id":"14965588658799411272385430903075831224615961675357217884735713260981483529984","best_ask":"0.5","best_bid":"0.49","hash":"08a707ab8fc8045a1d3fbe64634517c1a3ae1458","price":"0.56","side":"SELL","size":"266"}],"timestamp":"1785207751386"},"payload_hash":"2dbaf560598b172b9213b10b24b8ddca3f61461e566c8ce51c1de81d6c2c5aa8","raw_frame":"{\"market\":\"0x779291bef19b6709f61e9764a954aafe9ffae488d50ae674aabdcb4f248006d5\", \"price_changes\":[{\"asset_id\":\"8761897749749422724209054078244794145777693856614463256546737399611489089783\", \"price\":\"0.44\", \"size\":\"266\", \"side\":\"BUY\", \"hash\":\"fc9ea4348402360a6431b38bf9d61d55bcfa13de\", \"best_bid\":\"0.5\", \"best_ask\":\"0.51\"}, {\"asset_id\":\"14965588658799411272385430903075831224615961675357217884735713260981483529984\", \"price\":\"0.56\", \"size\":\"266\", \"side\":\"SELL\", \"hash\":\"08a707ab8fc8045a1d3fbe64634517c1a3ae1458\", \"best_bid\":\"0.49\", \"best_ask\":\"0.5\"}], \"timestamp\":\"1785207751386\", \"event_type\":\"price_change\"}","received_at":"2026-07-28T03:02:31.244234Z","schema_version":"clob-market-ws.price_change.v1","sequence":null,"server_hash":null,"server_timestamp":"1785207751386","session_id":"3e519d9098404c15b234d96025eb1a2b","source":"clob_market_ws"},"received_at":"2026-07-28T03:02:31.244234Z","record_id":"02405cb37dc48c3f32dfddb7be0a28c93e9d17dfa55649f3f016a241843f3f86","schema_fingerprint":"4aa3821a28b0b7c2400bc59aba4bcc0a76e971dadd19610d3ad38c768e124dc7","schema_version":"edge-lab-recorder.raw.v1","sequence":null,"source":"clob_market_ws"}
{"event_at":"2026-07-28T03:02:31.387000Z","event_fingerprint":"46f2841d4dde65f62a4c4db71833ec53475193cfb4a80812b37a5c6f27bca9ff","payload":{"connection_id":"a6b55582af5f430fb37ad02bf0922475","event_at":"2026-07-28T03:02:31.387000Z","event_type":"price_change","frame_hash":"92f932e41b18f227eb2404a1d3747c924c4e70c94ce92bbd4ea0610d4187be40","frame_index":0,"kind":"data","monotonic_ns":309734265243458,"payload":{"event_type":"price_change","market":"0x779291bef19b6709f61e9764a954aafe9ffae488d50ae674aabdcb4f248006d5","price_changes":[{"asset_id":"14965588658799411272385430903075831224615961675357217884735713260981483529984","best_ask":"0.5","best_bid":"0.49","hash":"c3c31e0b662225aa7e66eecbc442daa2594851a1","price":"0.01","side":"BUY","size":"7888.02"},{"asset_id":"8761897749749422724209054078244794145777693856614463256546737399611489089783","best_ask":"0.51","best_bid":"0.5","hash":"aaa24fc2b7123223505ffa73b05cb18b7b10083f","price":"0.99","side":"SELL","size":"7888.02"}],"timestamp":"1785207751387"},"payload_hash":"09d41d0bba022f1a6f570e1af909fdcf09321cae1eabda1c7c4d204f2a53e4d6","raw_frame":"{\"market\":\"0x779291bef19b6709f61e9764a954aafe9ffae488d50ae674aabdcb4f248006d5\", \"price_changes\":[{\"asset_id\":\"14965588658799411272385430903075831224615961675357217884735713260981483529984\", \"price\":\"0.01\", \"size\":\"7888.02\", \"side\":\"BUY\", \"hash\":\"c3c31e0b662225aa7e66eecbc442daa2594851a1\", \"best_bid\":\"0.49\", \"best_ask\":\"0.5\"}, {\"asset_id\":\"8761897749749422724209054078244794145777693856614463256546737399611489089783\", \"price\":\"0.99\", \"size\":\"7888.02\", \"side\":\"SELL\", \"hash\":\"aaa24fc2b7123223505ffa73b05cb18b7b10083f\", \"best_bid\":\"0.5\", \"best_ask\":\"0.51\"}], \"timestamp\":\"1785207751387\", \"event_type\":\"price_change\"}","received_at":"2026-07-28T03:02:31.245787Z","schema_version":"clob-market-ws.price_change.v1","sequence":null,"server_hash":null,"server_timestamp":"1785207751387","session_id":"3e519d9098404c15b234d96025eb1a2b","source":"clob_market_ws"},"received_at":"2026-07-28T03:02:31.245787Z","record_id":"fbd9b3c9f280bd41cd37b28f59408451b00b6fbd620ff6d5499001b1b7b9d083","schema_fingerprint":"4aa3821a28b0b7c2400bc59aba4bcc0a76e971dadd19610d3ad38c768e124dc7","schema_version":"edge-lab-recorder.raw.v1","sequence":null,"source":"clob_market_ws"}
{"event_at":"2026-07-28T03:02:31.388000Z","event_fingerprint":"abc9f94354f2f0de54e73a0b2bd50229143cee1df751c9de221241c4d8cb05f0","payload":{"connection_id":"a6b55582af5f430fb37ad02bf0922475","event_at":"2026-07-28T03:02:31.388000Z","event_type":"best_bid_ask","frame_hash":"f8d200d7b9381186d8259e58e56bba06d4edd096d2e5763c018d22dd1616ca70","frame_index":0,"kind":"data","monotonic_ns":309734266768041,"payload":{"asset_id":"14965588658799411272385430903075831224615961675357217884735713260981483529984","best_ask":"0.51","best_bid":"0.49","event_type":"best_bid_ask","market":"0x779291bef19b6709f61e9764a954aafe9ffae488d50ae674aabdcb4f248006d5","spread":"0.02","timestamp":"1785207751388"},"payload_hash":"81c5099ce9b0ce7abcb1c3ab731f08987d5e8080259e442f9fd4ad2418ebf2af","raw_frame":"{\"market\":\"0x779291bef19b6709f61e9764a954aafe9ffae488d50ae674aabdcb4f248006d5\", \"asset_id\":\"14965588658799411272385430903075831224615961675357217884735713260981483529984\", \"best_bid\":\"0.49\", \"best_ask\":\"0.51\", \"spread\":\"0.02\", \"timestamp\":\"1785207751388\", \"event_type\":\"best_bid_ask\"}","received_at":"2026-07-28T03:02:31.247312Z","schema_version":"clob-market-ws.best_bid_ask.v1","sequence":null,"server_hash":null,"server_timestamp":"1785207751388","session_id":"3e519d9098404c15b234d96025eb1a2b","source":"clob_market_ws"},"received_at":"2026-07-28T03:02:31.247312Z","record_id":"b1f44b0bb7e85d993cfdb4abd8ac3d5990f2cd3becefbd6b77a41ccd5c0c1378","schema_fingerprint":"8488399f31b0337811b13b266be932db7062827c2470b78bd8e9e99bab51d17d","schema_version":"edge-lab-recorder.raw.v1","sequence":null,"source":"clob_market_ws"}
{"event_at":"2026-07-28T03:02:31.388000Z","event_fingerprint":"ceebddf7f48c548f4c4bae512d0e049022f681b0f75bba8b0f260c7458a1e301","payload":{"connection_id":"a6b55582af5f430fb37ad02bf0922475","event_at":"2026-07-28T03:02:31.388000Z","event_type":"best_bid_ask","frame_hash":"7b928528dd6067f11a0a643a812bc9ad3ea9fa0965a0eef5e63ff697972a535d","frame_index":0,"kind":"data","monotonic_ns":309734267862333,"payload":{"asset_id":"8761897749749422724209054078244794145777693856614463256546737399611489089783","best_ask":"0.51","best_bid":"0.49","event_type":"best_bid_ask","market":"0x779291bef19b6709f61e9764a954aafe9ffae488d50ae674aabdcb4f248006d5","spread":"0.02","timestamp":"1785207751388"},"payload_hash":"9b00ad3e409ae9044a5fa4296c848beb0aba0c12d28ca327a6fb303dcb47c815","raw_frame":"{\"market\":\"0x779291bef19b6709f61e9764a954aafe9ffae488d50ae674aabdcb4f248006d5\", \"asset_id\":\"8761897749749422724209054078244794145777693856614463256546737399611489089783\", \"best_bid\":\"0.49\", \"best_ask\":\"0.51\", \"spread\":\"0.02\", \"timestamp\":\"1785207751388\", \"event_type\":\"best_bid_ask\"}","received_at":"2026-07-28T03:02:31.248407Z","schema_version":"clob-market-ws.best_bid_ask.v1","sequence":null,"server_hash":null,"server_timestamp":"1785207751388","session_id":"3e519d9098404c15b234d96025eb1a2b","source":"clob_market_ws"},"received_at":"2026-07-28T03:02:31.248407Z","record_id":"46719b285f67a038a930bc53a622daa6e6bc5186811edd87556ad438dff251b4","schema_fingerprint":"8488399f31b0337811b13b266be932db7062827c2470b78bd8e9e99bab51d17d","schema_version":"edge-lab-recorder.raw.v1","sequence":null,"source":"clob_market_ws"}
{"event_at":"2026-07-28T03:02:31.388000Z","event_fingerprint":"603cbeca8ddb601c9f15903c6ea6d12b2b9423cb992df9e7e93582b103a051bb","payload":{"connection_id":"a6b55582af5f430fb37ad02bf0922475","event_at":"2026-07-28T03:02:31.388000Z","event_type":"price_change","frame_hash":"769b43922c5dc9cdc03d0da3f22c94c594190feb6679284a81d9ea33d4bbaf7f","frame_index":0,"kind":"data","monotonic_ns":309734268905958,"payload":{"event_type":"price_change","market":"0x779291bef19b6709f61e9764a954aafe9ffae488d50ae674aabdcb4f248006d5","price_changes":[{"asset_id":"8761897749749422724209054078244794145777693856614463256546737399611489089783","best_ask":"0.51","best_bid":"0.49","hash":"4fead98f9f59977726b585bc4c3e15abb4a8af43","price":"0.5","side":"BUY","size":"0"},{"asset_id":"14965588658799411272385430903075831224615961675357217884735713260981483529984","best_ask":"0.51","best_bid":"0.49","hash":"560661037806577e523874b31df6c861402561ab","price":"0.5","side":"SELL","size":"0"}],"timestamp":"1785207751388"},"payload_hash":"d9874e6da5b962cd430c57f5300c94436b8951256a8484499d50c146792870aa","raw_frame":"{\"market\":\"0x779291bef19b6709f61e9764a954aafe9ffae488d50ae674aabdcb4f248006d5\", \"price_changes\":[{\"asset_id\":\"8761897749749422724209054078244794145777693856614463256546737399611489089783\", \"price\":\"0.5\", \"size\":\"0\", \"side\":\"BUY\", \"hash\":\"4fead98f9f59977726b585bc4c3e15abb4a8af43\", \"best_bid\":\"0.49\", \"best_ask\":\"0.51\"}, {\"asset_id\":\"14965588658799411272385430903075831224615961675357217884735713260981483529984\", \"price\":\"0.5\", \"size\":\"0\", \"side\":\"SELL\", \"hash\":\"560661037806577e523874b31df6c861402561ab\", \"best_bid\":\"0.49\", \"best_ask\":\"0.51\"}], \"timestamp\":\"1785207751388\", \"event_type\":\"price_change\"}","received_at":"2026-07-28T03:02:31.249451Z","schema_version":"clob-market-ws.price_change.v1","sequence":null,"server_hash":null,"server_timestamp":"1785207751388","session_id":"3e519d9098404c15b234d96025eb1a2b","source":"clob_market_ws"},"received_at":"2026-07-28T03:02:31.249451Z","record_id":"3b1bc40d8e59b1034dc0f193a09429317290bf8da28a7094901b4de182f7bb40","schema_fingerprint":"4aa3821a28b0b7c2400bc59aba4bcc0a76e971dadd19610d3ad38c768e124dc7","schema_version":"edge-lab-recorder.raw.v1","sequence":null,"source":"clob_market_ws"}
{"event_at":"2026-07-28T03:02:31.388000Z","event_fingerprint":"e5d254060defb0195eaa940f775990ef5611ae5c0878d564c9cf1dad91a03d9c","payload":{"connection_id":"a6b55582af5f430fb37ad02bf0922475","event_at":"2026-07-28T03:02:31.388000Z","event_type":"price_change","frame_hash":"fd4ee878ec3954df891e68b3894aeb27b29d848cfb7aab9f2159448f3df53e89","frame_index":0,"kind":"data","monotonic_ns":309734280058291,"payload":{"event_type":"price_change","market":"0x779291bef19b6709f61e9764a954aafe9ffae488d50ae674aabdcb4f248006d5","price_changes":[{"asset_id":"8761897749749422724209054078244794145777693856614463256546737399611489089783","best_ask":"0.51","best_bid":"0.49","hash":"1e91c0512d7a62341a9d14693487b4fa0af5111e","price":"0.44","side":"BUY","size":"236"},{"asset_id":"14965588658799411272385430903075831224615961675357217884735713260981483529984","best_ask":"0.51","best_bid":"0.49","hash":"98b9b447cc4b22ada45a6df5b9e3ba88b39e8662","price":"0.56","side":"SELL","size":"236"}],"timestamp":"1785207751388"},"payload_hash":"2201366721b4d42fbc2ce90d548a8b6d12cb823336ed8bc7c0206090f62ab235","raw_frame":"{\"market\":\"0x779291bef19b6709f61e9764a954aafe9ffae488d50ae674aabdcb4f248006d5\", \"price_changes\":[{\"asset_id\":\"8761897749749422724209054078244794145777693856614463256546737399611489089783\", \"price\":\"0.44\", \"size\":\"236\", \"side\":\"BUY\", \"hash\":\"1e91c0512d7a62341a9d14693487b4fa0af5111e\", \"best_bid\":\"0.49\", \"best_ask\":\"0.51\"}, {\"asset_id\":\"14965588658799411272385430903075831224615961675357217884735713260981483529984\", \"price\":\"0.56\", \"size\":\"236\", \"side\":\"SELL\", \"hash\":\"98b9b447cc4b22ada45a6df5b9e3ba88b39e8662\", \"best_bid\":\"0.49\", \"best_ask\":\"0.51\"}], \"timestamp\":\"1785207751388\", \"event_type\":\"price_change\"}","received_at":"2026-07-28T03:02:31.260599Z","schema_version":"clob-market-ws.price_change.v1","sequence":null,"server_hash":null,"server_timestamp":"1785207751388","session_id":"3e519d9098404c15b234d96025eb1a2b","source":"clob_market_ws"},"received_at":"2026-07-28T03:02:31.260599Z","record_id":"b79fddbeb7fcaa137450bbcd8b62762c46d5a290d78a157e6a924b86b748297b","schema_fingerprint":"4aa3821a28b0b7c2400bc59aba4bcc0a76e971dadd19610d3ad38c768e124dc7","schema_version":"edge-lab-recorder.raw.v1","sequence":null,"source":"clob_market_ws"}
{"event_at":"2026-07-28T03:02:31.393000Z","event_fingerprint":"7827ff532c90e02d2c1fb77d1a717ec5dcdf9d6a2047f81d96add73b77122d75","payload":{"connection_id":"a6b55582af5f430fb37ad02bf0922475","event_at":"2026-07-28T03:02:31.393000Z","event_type":"price_change","frame_hash":"24ce1474c18b36d30b53d2b7bfdace097045e0c9584f4bb512bd11e2a97a6376","frame_index":0,"kind":"data","monotonic_ns":309734281674958,"payload":{"event_type":"price_change","market":"0x779291bef19b6709f61e9764a954aafe9ffae488d50ae674aabdcb4f248006d5","price_changes":[{"asset_id":"8761897749749422724209054078244794145777693856614463256546737399611489089783","best_ask":"0.51","best_bid":"0.49","hash":"b319b347cbf1744d170570b724d9f56995246305","price":"0.44","side":"BUY","size":"206"},{"asset_id":"14965588658799411272385430903075831224615961675357217884735713260981483529984","best_ask":"0.51","best_bid":"0.49","hash":"5f3d1bbc87769b27f5a808a8a43913da20facbd2","price":"0.56","side":"SELL","size":"206"}],"timestamp":"1785207751393"},"payload_hash":"ac7418df78d9e1509faafd1c3305c63e1469535d048c99969cf09beb29a206c3","raw_frame":"{\"market\":\"0x779291bef19b6709f61e9764a954aafe9ffae488d50ae674aabdcb4f248006d5\", \"price_changes\":[{\"asset_id\":\"8761897749749422724209054078244794145777693856614463256546737399611489089783\", \"price\":\"0.44\", \"size\":\"206\", \"side\":\"BUY\", \"hash\":\"b319b347cbf1744d170570b724d9f56995246305\", \"best_bid\":\"0.49\", \"best_ask\":\"0.51\"}, {\"asset_id\":\"14965588658799411272385430903075831224615961675357217884735713260981483529984\", \"price\":\"0.56\", \"size\":\"206\", \"side\":\"SELL\", \"hash\":\"5f3d1bbc87769b27f5a808a8a43913da20facbd2\", \"best_bid\":\"0.49\", \"best_ask\":\"0.51\"}], \"timestamp\":\"1785207751393\", \"event_type\":\"price_change\"}","received_at":"2026-07-28T03:02:31.262219Z","schema_version":"clob-market-ws.price_change.v1","sequence":null,"server_hash":null,"server_timestamp":"1785207751393","session_id":"3e519d9098404c15b234d96025eb1a2b","source":"clob_market_ws"},"received_at":"2026-07-28T03:02:31.262219Z","record_id":"585f0c15f403effb3b996c839502cd2bccb5809d3d306abcdd069718ddd7d7f4","schema_fingerprint":"4aa3821a28b0b7c2400bc59aba4bcc0a76e971dadd19610d3ad38c768e124dc7","schema_version":"edge-lab-recorder.raw.v1","sequence":null,"source":"clob_market_ws"}
{"event_at":"2026-07-28T03:02:31.394000Z","event_fingerprint":"ca89c8a3391bec4a4103692676e01e540668752fdba01816d7b95033ab72d098","payload":{"connection_id":"a6b55582af5f430fb37ad02bf0922475","event_at":"2026-07-28T03:02:31.394000Z","event_type":"price_change","frame_hash":"9b8a9c2d0f29c28d42557a4cbc6bbe004686ded5907fc37496f6276b57c2d16e","frame_index":0,"kind":"data","monotonic_ns":309734283440875,"payload":{"event_type":"price_change","market":"0x779291bef19b6709f61e9764a954aafe9ffae488d50ae674aabdcb4f248006d5","price_changes":[{"asset_id":"14965588658799411272385430903075831224615961675357217884735713260981483529984","best_ask":"0.51","best_bid":"0.49","hash":"1f60d89673e99657dff0ce68393498e31c6bc2b2","price":"0.49","side":"BUY","size":"213.6"},{"asset_id":"8761897749749422724209054078244794145777693856614463256546737399611489089783","best_ask":"0.51","best_bid":"0.49","hash":"84f3a873713ebd5987cfc49efb577771cd2d634a","price":"0.51","side":"SELL","size":"213.6"}],"timestamp":"1785207751394"},"payload_hash":"79231274a637776effaa2f1c597edf7f82f3abde6caec544f46405b90716d4e1","raw_frame":"{\"market\":\"0x779291bef19b6709f61e9764a954aafe9ffae488d50ae674aabdcb4f248006d5\", \"price_changes\":[{\"asset_id\":\"14965588658799411272385430903075831224615961675357217884735713260981483529984\", \"price\":\"0.49\", \"size\":\"213.6\", \"side\":\"BUY\", \"hash\":\"1f60d89673e99657dff0ce68393498e31c6bc2b2\", \"best_bid\":\"0.49\", \"best_ask\":\"0.51\"}, {\"asset_id\":\"8761897749749422724209054078244794145777693856614463256546737399611489089783\", \"price\":\"0.51\", \"size\":\"213.6\", \"side\":\"SELL\", \"hash\":\"84f3a873713ebd5987cfc49efb577771cd2d634a\", \"best_bid\":\"0.49\", \"best_ask\":\"0.51\"}], \"timestamp\":\"1785207751394\", \"event_type\":\"price_change\"}","received_at":"2026-07-28T03:02:31.263984Z","schema_version":"clob-market-ws.price_change.v1","sequence":null,"server_hash":null,"server_timestamp":"1785207751394","session_id":"3e519d9098404c15b234d96025eb1a2b","source":"clob_market_ws"},"received_at":"2026-07-28T03:02:31.263984Z","record_id":"7bb3d4be177adf85138a7c3e178ae24bf525993a007fb2a7cebd95f475a9ac3e","schema_fingerprint":"4aa3821a28b0b7c2400bc59aba4bcc0a76e971dadd19610d3ad38c768e124dc7","schema_version":"edge-lab-recorder.raw.v1","sequence":null,"source":"clob_market_ws"}
{"event_at":"2026-07-28T03:02:31.397000Z","event_fingerprint":"1a609d8990ce88cb225513f6d17d9b94fb092cd67817d736ea80c1673f7f964c","payload":{"connection_id":"a6b55582af5f430fb37ad02bf0922475","event_at":"2026-07-28T03:02:31.397000Z","event_type":"price_change","frame_hash":"9ef482625fb286049fd8fac454347ed5d717bd85799315a95965adb7318fe0f8","frame_index":0,"kind":"data","monotonic_ns":309734284962958,"payload":{"event_type":"price_change","market":"0x779291bef19b6709f61e9764a954aafe9ffae488d50ae674aabdcb4f248006d5","price_changes":[{"asset_id":"8761897749749422724209054078244794145777693856614463256546737399611489089783","best_ask":"0.51","best_bid":"0.49","hash":"4cae9e956d6d80a644e03af085c49616d80f7053","price":"0.44","side":"BUY","size":"191"},{"asset_id":"14965588658799411272385430903075831224615961675357217884735713260981483529984","best_ask":"0.51","best_bid":"0.49","hash":"e67521f7c7d91cce0e195fb3f7d1f55953323ed4","price":"0.56","side":"SELL","size":"191"}],"timestamp":"1785207751397"},"payload_hash":"624cb781585e2f1600d0fcfd996b007d1e3353fcdc480d22cb57c64ddc31dbf6","raw_frame":"{\"market\":\"0x779291bef19b6709f61e9764a954aafe9ffae488d50ae674aabdcb4f248006d5\", \"price_changes\":[{\"asset_id\":\"8761897749749422724209054078244794145777693856614463256546737399611489089783\", \"price\":\"0.44\", \"size\":\"191\", \"side\":\"BUY\", \"hash\":\"4cae9e956d6d80a644e03af085c49616d80f7053\", \"best_bid\":\"0.49\", \"best_ask\":\"0.51\"}, {\"asset_id\":\"14965588658799411272385430903075831224615961675357217884735713260981483529984\", \"price\":\"0.56\", \"size\":\"191\", \"side\":\"SELL\", \"hash\":\"e67521f7c7d91cce0e195fb3f7d1f55953323ed4\", \"best_bid\":\"0.49\", \"best_ask\":\"0.51\"}], \"timestamp\":\"1785207751397\", \"event_type\":\"price_change\"}","received_at":"2026-07-28T03:02:31.265507Z","schema_version":"clob-market-ws.price_change.v1","sequence":null,"server_hash":null,"server_timestamp":"1785207751397","session_id":"3e519d9098404c15b234d96025eb1a2b","source":"clob_market_ws"},"received_at":"2026-07-28T03:02:31.265507Z","record_id":"c90816fb6aa1c2cb3847c4e5f0b9c0fbb39dda3df3e4bcebd432c4a538b9746e","schema_fingerprint":"4aa3821a28b0b7c2400bc59aba4bcc0a76e971dadd19610d3ad38c768e124dc7","schema_version":"edge-lab-recorder.raw.v1","sequence":null,"source":"clob_market_ws"}
{"event_at":"2026-07-28T03:02:31.398000Z","event_fingerprint":"91c93abfd3a2039fec81d7007a48eb1980fd5a17b57f444bddbe4e32a5dff26f","payload":{"connection_id":"a6b55582af5f430fb37ad02bf0922475","event_at":"2026-07-28T03:02:31.398000Z","event_type":"price_change","frame_hash":"775bc123e684115e09851db7b9d7c5c594d584cd5fff8aba3fd80fa18fce38f6","frame_index":0,"kind":"data","monotonic_ns":309734286523750,"payload":{"event_type":"price_change","market":"0x779291bef19b6709f61e9764a954aafe9ffae488d50ae674aabdcb4f248006d5","price_changes":[{"asset_id":"14965588658799411272385430903075831224615961675357217884735713260981483529984","best_ask":"0.51","best_bid":"0.49","hash":"449ebe07378be02594d1f822f751c8db49954cad","price":"0.49","side":"BUY","size":"226.2"},{"asset_id":"8761897749749422724209054078244794145777693856614463256546737399611489089783","best_ask":"0.51","best_bid":"0.49","hash":"7ced41febf414e6140d5306b18a162ceab38dcee","price":"0.51","side":"SELL","size":"226.2"}],"timestamp":"1785207751398"},"payload_hash":"f188ab258425476d1f6c4d0e44269018018fc7ab054e60eb481cd2e2790e15c5","raw_frame":"{\"market\":\"0x779291bef19b6709f61e9764a954aafe9ffae488d50ae674aabdcb4f248006d5\", \"price_changes\":[{\"asset_id\":\"14965588658799411272385430903075831224615961675357217884735713260981483529984\", \"price\":\"0.49\", \"size\":\"226.2\", \"side\":\"BUY\", \"hash\":\"449ebe07378be02594d1f822f751c8db49954cad\", \"best_bid\":\"0.49\", \"best_ask\":\"0.51\"}, {\"asset_id\":\"8761897749749422724209054078244794145777693856614463256546737399611489089783\", \"price\":\"0.51\", \"size\":\"226.2\", \"side\":\"SELL\", \"hash\":\"7ced41febf414e6140d5306b18a162ceab38dcee\", \"best_bid\":\"0.49\", \"best_ask\":\"0.51\"}], \"timestamp\":\"1785207751398\", \"event_type\":\"price_change\"}","received_at":"2026-07-28T03:02:31.267066Z","schema_version":"clob-market-ws.price_change.v1","sequence":null,"server_hash":null,"server_timestamp":"1785207751398","session_id":"3e519d9098404c15b234d96025eb1a2b","source":"clob_market_ws"},"received_at":"2026-07-28T03:02:31.267066Z","record_id":"946c356dbcae93ef2ace4ac9c1a12bac62e33ac68e3eb7d83bf74d1e15c5cc1a","schema_fingerprint":"4aa3821a28b0b7c2400bc59aba4bcc0a76e971dadd19610d3ad38c768e124dc7","schema_version":"edge-lab-recorder.raw.v1","sequence":null,"source":"clob_market_ws"}
{"event_at":"2026-07-28T03:02:31.398000Z","event_fingerprint":"3ec6898261138bb2c6c636a5151f8d7fc25193faaf5ff7e3cb6259550eda1bdc","payload":{"connection_id":"a6b55582af5f430fb37ad02bf0922475","event_at":"2026-07-28T03:02:31.398000Z","event_type":"price_change","frame_hash":"3065c686f7b6564209fa066c76693d8ed241f5fe61240d29bc8746a43dc39d88","frame_index":0,"kind":"data","monotonic_ns":309734288138416,"payload":{"event_type":"price_change","market":"0x779291bef19b6709f61e9764a954aafe9ffae488d50ae674aabdcb4f248006d5","price_changes":[{"asset_id":"8761897749749422724209054078244794145777693856614463256546737399611489089783","best_ask":"0.51","best_bid":"0.49","hash":"baf80fe8b9e525fa122ce2a45a5042bd04454111","price":"0.45","side":"BUY","size":"232.14"},{"asset_id":"14965588658799411272385430903075831224615961675357217884735713260981483529984","best_ask":"0.51","best_bid":"0.49","hash":"9434e2d6908f0bd6dd0b526f0efd055513a592d4","price":"0.55","side":"SELL","size":"232.14"}],"timestamp":"1785207751398"},"payload_hash":"7f6e5913aec4fdce32fa7e79d9a3b00b2bab41050108bcfd18109f81b8df00dd","raw_frame":"{\"market\":\"0x779291bef19b6709f61e9764a954aafe9ffae488d50ae674aabdcb4f248006d5\", \"price_changes\":[{\"asset_id\":\"8761897749749422724209054078244794145777693856614463256546737399611489089783\", \"price\":\"0.45\", \"size\":\"232.14\", \"side\":\"BUY\", \"hash\":\"baf80fe8b9e525fa122ce2a45a5042bd04454111\", \"best_bid\":\"0.49\", \"best_ask\":\"0.51\"}, {\"asset_id\":\"14965588658799411272385430903075831224615961675357217884735713260981483529984\", \"price\":\"0.55\", \"size\":\"232.14\", \"side\":\"SELL\", \"hash\":\"9434e2d6908f0bd6dd0b526f0efd055513a592d4\", \"best_bid\":\"0.49\", \"best_ask\":\"0.51\"}], \"timestamp\":\"1785207751398\", \"event_type\":\"price_change\"}","received_at":"2026-07-28T03:02:31.268682Z","schema_version":"clob-market-ws.price_change.v1","sequence":null,"server_hash":null,"server_timestamp":"1785207751398","session_id":"3e519d9098404c15b234d96025eb1a2b","source":"clob_market_ws"},"received_at":"2026-07-28T03:02:31.268682Z","record_id":"067149520c2fa91c687a62ddd23d42d070e49b7904330b13497f1744317986ba","schema_fingerprint":"4aa3821a28b0b7c2400bc59aba4bcc0a76e971dadd19610d3ad38c768e124dc7","schema_version":"edge-lab-recorder.raw.v1","sequence":null,"source":"clob_market_ws"}
{"event_at":"2026-07-28T03:02:31.398000Z","event_fingerprint":"b22aba44c6d8f919efd0e955ad1ea538c28b7c59c8ce367ca9374b9cc61d0712","payload":{"connection_id":"a6b55582af5f430fb37ad02bf0922475","event_at":"2026-07-28T03:02:31.398000Z","event_type":"price_change","frame_hash":"bf44d723d6b113aa71e03d66e91ee1065b89fb0daaa2edd060472dbcff7a4f0f","frame_index":0,"kind":"data","monotonic_ns":309734289648416,"payload":{"event_type":"price_change","market":"0x779291bef19b6709f61e9764a954aafe9ffae488d50ae674aabdcb4f248006d5","price_changes":[{"asset_id":"14965588658799411272385430903075831224615961675357217884735713260981483529984","best_ask":"0.51","best_bid":"0.49","hash":"8d12c895336cc9d922bfaab52a2ad17a6c597690","price":"0.43","side":"BUY","size":"138"},{"asset_id":"8761897749749422724209054078244794145777693856614463256546737399611489089783","best_ask":"0.51","best_bid":"0.49","hash":"88878f33cbf594f3e50c8e6dfd4639537217a9e6","price":"0.57","side":"SELL","size":"138"}],"timestamp":"1785207751398"},"payload_hash":"a9a15a46154f8d35ecbd1b40be54a805da8b14d0f0b06969dc83be1f3e950a88","raw_frame":"{\"market\":\"0x779291bef19b6709f61e9764a954aafe9ffae488d50ae674aabdcb4f248006d5\", \"price_changes\":[{\"asset_id\":\"14965588658799411272385430903075831224615961675357217884735713260981483529984\", \"price\":\"0.43\", \"size\":\"138\", \"side\":\"BUY\", \"hash\":\"8d12c895336cc9d922bfaab52a2ad17a6c597690\", \"best_bid\":\"0.49\", \"best_ask\":\"0.51\"}, {\"asset_id\":\"8761897749749422724209054078244794145777693856614463256546737399611489089783\", \"price\":\"0.57\", \"size\":\"138\", \"side\":\"SELL\", \"hash\":\"88878f33cbf594f3e50c8e6dfd4639537217a9e6\", \"best_bid\":\"0.49\", \"best_ask\":\"0.51\"}], \"timestamp\":\"1785207751398\", \"event_type\":\"price_change\"}","received_at":"2026-07-28T03:02:31.270193Z","schema_version":"clob-market-ws.price_change.v1","sequence":null,"server_hash":null,"server_timestamp":"1785207751398","session_id":"3e519d9098404c15b234d96025eb1a2b","source":"clob_market_ws"},"received_at":"2026-07-28T03:02:31.270193Z","record_id":"2cd57a5de473ace25932afa5fcef48a20fd17cff81ef6575bb8a4dd6d09f35e0","schema_fingerprint":"4aa3821a28b0b7c2400bc59aba4bcc0a76e971dadd19610d3ad38c768e124dc7","schema_version":"edge-lab-recorder.raw.v1","sequence":null,"source":"clob_market_ws"}
{"event_at":"2026-07-28T03:02:31.398000Z","event_fingerprint":"50b5d2a1b05a5c8567c28daaf59e138fce0cf3db48092304fb76dfaaad008c09","payload":{"connection_id":"a6b55582af5f430fb37ad02bf0922475","event_at":"2026-07-28T03:02:31.398000Z","event_type":"price_change","frame_hash":"fec7dd9b0bd8475f11b3f5104d310af6d8396dc71840be262d99526f3dd36ddb","frame_index":0,"kind":"data","monotonic_ns":309734291151375,"payload":{"event_type":"price_change","market":"0x779291bef19b6709f61e9764a954aafe9ffae488d50ae674aabdcb4f248006d5","price_changes":[{"asset_id":"8761897749749422724209054078244794145777693856614463256546737399611489089783","best_ask":"0.51","best_bid":"0.49","hash":"dc26f6a048fdef7a8a9d7ea057001a449e0e66bd","price":"0.36","side":"BUY","size":"165"},{"asset_id":"14965588658799411272385430903075831224615961675357217884735713260981483529984","best_ask":"0.51","best_bid":"0.49","hash":"3e34f0151bd887dba7624581305f0e0b89bb7623","price":"0.64","side":"SELL","size":"165"}],"timestamp":"1785207751398"},"payload_hash":"91c5ea78c6ace2504d2ec0ba3723791377d5d31b997ff01ce75b88240218ea03","raw_frame":"{\"market\":\"0x779291bef19b6709f61e9764a954aafe9ffae488d50ae674aabdcb4f248006d5\", \"price_changes\":[{\"asset_id\":\"8761897749749422724209054078244794145777693856614463256546737399611489089783\", \"price\":\"0.36\", \"size\":\"165\", \"side\":\"BUY\", \"hash\":\"dc26f6a048fdef7a8a9d7ea057001a449e0e66bd\", \"best_bid\":\"0.49\", \"best_ask\":\"0.51\"}, {\"asset_id\":\"14965588658799411272385430903075831224615961675357217884735713260981483529984\", \"price\":\"0.64\", \"size\":\"165\", \"side\":\"SELL\", \"hash\":\"3e34f0151bd887dba7624581305f0e0b89bb7623\", \"best_bid\":\"0.49\", \"best_ask\":\"0.51\"}], \"timestamp\":\"1785207751398\", \"event_type\":\"price_change\"}","received_at":"2026-07-28T03:02:31.271696Z","schema_version":"clob-market-ws.price_change.v1","sequence":null,"server_hash":null,"server_timestamp":"1785207751398","session_id":"3e519d9098404c15b234d96025eb1a2b","source":"clob_market_ws"},"received_at":"2026-07-28T03:02:31.271696Z","record_id":"8397d8bbdf356dfdd54ea46210255a9e065cb54b37b4e25ab3eea6dcbbcbc9ad","schema_fingerprint":"4aa3821a28b0b7c2400bc59aba4bcc0a76e971dadd19610d3ad38c768e124dc7","schema_version":"edge-lab-recorder.raw.v1","sequence":null,"source":"clob_market_ws"}
{"event_at":"2026-07-28T03:02:31.399000Z","event_fingerprint":"1df4a9e28a7f866bf6afb372fcb34a3820cf69141af204277afb4a6c3a648a2b","payload":{"connection_id":"a6b55582af5f430fb37ad02bf0922475","event_at":"2026-07-28T03:02:31.399000Z","event_type":"price_change","frame_hash":"4b47f2aabae65056b4adc1b9a3a70cfdb07c15f257cddd515f3c90468736c7e8","frame_index":0,"kind":"data","monotonic_ns":309734292639958,"payload":{"event_type":"price_change","market":"0x779291bef19b6709f61e9764a954aafe9ffae488d50ae674aabdcb4f248006d5","price_changes":[{"asset_id":"8761897749749422724209054078244794145777693856614463256546737399611489089783","best_ask":"0.51","best_bid":"0.49","hash":"ac6fe625caeef29c7c03a4f4ac7a8dbdca9bfd66","price":"0.48","side":"BUY","size":"349.03"},{"asset_id":"14965588658799411272385430903075831224615961675357217884735713260981483529984","best_ask":"0.51","best_bid":"0.49","hash":"12048479b01c8ec1d44fcd1e1ab89d4bdea2bac5","price":"0.52","side":"SELL","size":"349.03"}],"timestamp":"1785207751399"},"payload_hash":"d3f75de16c46699ae12acc130e46a31b0f41dbfcc07df029da81af2fd00ed54c","raw_frame":"{\"market\":\"0x779291bef19b6709f61e9764a954aafe9ffae488d50ae674aabdcb4f248006d5\", \"price_changes\":[{\"asset_id\":\"8761897749749422724209054078244794145777693856614463256546737399611489089783\", \"price\":\"0.48\", \"size\":\"349.03\", \"side\":\"BUY\", \"hash\":\"ac6fe625caeef29c7c03a4f4ac7a8dbdca9bfd66\", \"best_bid\":\"0.49\", \"best_ask\":\"0.51\"}, {\"asset_id\":\"14965588658799411272385430903075831224615961675357217884735713260981483529984\", \"price\":\"0.52\", \"size\":\"349.03\", \"side\":\"SELL\", \"hash\":\"12048479b01c8ec1d44fcd1e1ab89d4bdea2bac5\", \"best_bid\":\"0.49\", \"best_ask\":\"0.51\"}], \"timestamp\":\"1785207751399\", \"event_type\":\"price_change\"}","received_at":"2026-07-28T03:02:31.273177Z","schema_version":"clob-market-ws.price_change.v1","sequence":null,"server_hash":null,"server_timestamp":"1785207751399","session_id":"3e519d9098404c15b234d96025eb1a2b","source":"clob_market_ws"},"received_at":"2026-07-28T03:02:31.273177Z","record_id":"c8027811eb52d40d9368786f6fcf7a5873277a72685bf783638e462e34c8ed85","schema_fingerprint":"4aa3821a28b0b7c2400bc59aba4bcc0a76e971dadd19610d3ad38c768e124dc7","schema_version":"edge-lab-recorder.raw.v1","sequence":null,"source":"clob_market_ws"}
{"event_at":"2026-07-28T03:02:31.399000Z","event_fingerprint":"ad8329325722d91e526a445044c5eb1b9e7cbd095e81842a4ebbb6fef9314356","payload":{"connection_id":"a6b55582af5f430fb37ad02bf0922475","event_at":"2026-07-28T03:02:31.399000Z","event_type":"price_change","frame_hash":"68118c4016458c0e042a80664e1aaa82cec8ca6d1f3515a48208a5bb12791fa2","frame_index":0,"kind":"data","monotonic_ns":309734294137958,"payload":{"event_type":"price_change","market":"0x779291bef19b6709f61e9764a954aafe9ffae488d50ae674aabdcb4f248006d5","price_changes":[{"asset_id":"8761897749749422724209054078244794145777693856614463256546737399611489089783","best_ask":"0.51","best_bid":"0.49","hash":"a3b0637c2bcff1e7dd5a28c691dc90572436c54b","price":"0.47","side":"BUY","size":"119"},{"asset_id":"14965588658799411272385430903075831224615961675357217884735713260981483529984","best_ask":"0.51","best_bid":"0.49","hash":"3650806069b0a62550c792d193ee87d8eed517ce","price":"0.53","side":"SELL","size":"119"}],"timestamp":"1785207751399"},"payload_hash":"567a22e0e029d8cfd73069db6bbbca8795d533857fbd557ada4a074877c26096","raw_frame":"{\"market\":\"0x779291bef19b6709f61e9764a954aafe9ffae488d50ae674aabdcb4f248006d5\", \"price_changes\":[{\"asset_id\":\"8761897749749422724209054078244794145777693856614463256546737399611489089783\", \"price\":\"0.47\", \"size\":\"119\", \"side\":\"BUY\", \"hash\":\"a3b0637c2bcff1e7dd5a28c691dc90572436c54b\", \"best_bid\":\"0.49\", \"best_ask\":\"0.51\"}, {\"asset_id\":\"14965588658799411272385430903075831224615961675357217884735713260981483529984\", \"price\":\"0.53\", \"size\":\"119\", \"side\":\"SELL\", \"hash\":\"3650806069b0a62550c792d193ee87d8eed517ce\", \"best_bid\":\"0.49\", \"best_ask\":\"0.51\"}], \"timestamp\":\"1785207751399\", \"event_type\":\"price_change\"}","received_at":"2026-07-28T03:02:31.274682Z","schema_version":"clob-market-ws.price_change.v1","sequence":null,"server_hash":null,"server_timestamp":"1785207751399","session_id":"3e519d9098404c15b234d96025eb1a2b","source":"clob_market_ws"},"received_at":"2026-07-28T03:02:31.274682Z","record_id":"794f24330fa655223cfbb5279862afcbdd46a6fe026925baa92f5de932d84a6f","schema_fingerprint":"4aa3821a28b0b7c2400bc59aba4bcc0a76e971dadd19610d3ad38c768e124dc7","schema_version":"edge-lab-recorder.raw.v1","sequence":null,"source":"clob_market_ws"}
{"event_at":"2026-07-28T03:02:31.399000Z","event_fingerprint":"12937f1f19fd560a92284c746bb974a2b11e63e0010c86ac6ea224e354693cca","payload":{"connection_id":"a6b55582af5f430fb37ad02bf0922475","event_at":"2026-07-28T03:02:31.399000Z","event_type":"price_change","frame_hash":"81db66d2e15a55909881d65c94ac41717a3d010d6cc2f7072ad35b99d26f9e7e","frame_index":0,"kind":"data","monotonic_ns":309734295650416,"payload":{"event_type":"price_change","market":"0x779291bef19b6709f61e9764a954aafe9ffae488d50ae674aabdcb4f248006d5","price_changes":[{"asset_id":"8761897749749422724209054078244794145777693856614463256546737399611489089783","best_ask":"0.51","best_bid":"0.49","hash":"a3b0637c2bcff1e7dd5a28c691dc90572436c54b","price":"0.48","side":"BUY","size":"337"},{"asset_id":"14965588658799411272385430903075831224615961675357217884735713260981483529984","best_ask":"0.51","best_bid":"0.49","hash":"3650806069b0a62550c792d193ee87d8eed517ce","price":"0.52","side":"SELL","size":"337"}],"timestamp":"1785207751399"},"payload_hash":"57a05342026f83079de0a293c6b7787e131faf9681dac2a2dccbc5243f7779af","raw_frame":"{\"market\":\"0x779291bef19b6709f61e9764a954aafe9ffae488d50ae674aabdcb4f248006d5\", \"price_changes\":[{\"asset_id\":\"8761897749749422724209054078244794145777693856614463256546737399611489089783\", \"price\":\"0.48\", \"size\":\"337\", \"side\":\"BUY\", \"hash\":\"a3b0637c2bcff1e7dd5a28c691dc90572436c54b\", \"best_bid\":\"0.49\", \"best_ask\":\"0.51\"}, {\"asset_id\":\"14965588658799411272385430903075831224615961675357217884735713260981483529984\", \"price\":\"0.52\", \"size\":\"337\", \"side\":\"SELL\", \"hash\":\"3650806069b0a62550c792d193ee87d8eed517ce\", \"best_bid\":\"0.49\", \"best_ask\":\"0.51\"}], \"timestamp\":\"1785207751399\", \"event_type\":\"price_change\"}","received_at":"2026-07-28T03:02:31.276195Z","schema_version":"clob-market-ws.price_change.v1","sequence":null,"server_hash":null,"server_timestamp":"1785207751399","session_id":"3e519d9098404c15b234d96025eb1a2b","source":"clob_market_ws"},"received_at":"2026-07-28T03:02:31.276195Z","record_id":"f1a24e6e12f50a67e0d1e5c44bd2f2f6db40c15a488402068e7de97865b51612","schema_fingerprint":"4aa3821a28b0b7c2400bc59aba4bcc0a76e971dadd19610d3ad38c768e124dc7","schema_version":"edge-lab-recorder.raw.v1","sequence":null,"source":"clob_market_ws"}
{"event_at":"2026-07-28T03:02:31.400000Z","event_fingerprint":"7b34259fec5d5699faf7a671906577b12868873bb98d157185a64486dbe3d850","payload":{"connection_id":"a6b55582af5f430fb37ad02bf0922475","event_at":"2026-07-28T03:02:31.400000Z","event_type":"price_change","frame_hash":"715dcfa4e46c0eb25ab4c085863ea5df70182949086e32d67b134007996cef27","frame_index":0,"kind":"data","monotonic_ns":309734297124458,"payload":{"event_type":"price_change","market":"0x779291bef19b6709f61e9764a954aafe9ffae488d50ae674aabdcb4f248006d5","price_changes":[{"asset_id":"14965588658799411272385430903075831224615961675357217884735713260981483529984","best_ask":"0.51","best_bid":"0.49","hash":"9f5b96b17f6a36958b742903645bbee5aa3a18c6","price":"0.4","side":"BUY","size":"323.51"},{"asset_id":"8761897749749422724209054078244794145777693856614463256546737399611489089783","best_ask":"0.51","best_bid":"0.49","hash":"46d7da7162fd9ac45990933b8d42fb5608b70fc6","price":"0.6","side":"SELL","size":"323.51"}],"timestamp":"1785207751400"},"payload_hash":"1925d313b6dc1da406fdd63266911c2fe0cf12340e6d379cdea109506b30b0e8","raw_frame":"{\"market\":\"0x779291bef19b6709f61e9764a954aafe9ffae488d50ae674aabdcb4f248006d5\", \"price_changes\":[{\"asset_id\":\"14965588658799411272385430903075831224615961675357217884735713260981483529984\", \"price\":\"0.4\", \"size\":\"323.51\", \"side\":\"BUY\", \"hash\":\"9f5b96b17f6a36958b742903645bbee5aa3a18c6\", \"best_bid\":\"0.49\", \"best_ask\":\"0.51\"}, {\"asset_id\":\"8761897749749422724209054078244794145777693856614463256546737399611489089783\", \"price\":\"0.6\", \"size\":\"323.51\", \"side\":\"SELL\", \"hash\":\"46d7da7162fd9ac45990933b8d42fb5608b70fc6\", \"best_bid\":\"0.49\", \"best_ask\":\"0.51\"}], \"timestamp\":\"1785207751400\", \"event_type\":\"price_change\"}","received_at":"2026-07-28T03:02:31.277669Z","schema_version":"clob-market-ws.price_change.v1","sequence":null,"server_hash":null,"server_timestamp":"1785207751400","session_id":"3e519d9098404c15b234d96025eb1a2b","source":"clob_market_ws"},"received_at":"2026-07-28T03:02:31.277669Z","record_id":"8410ddf8547c54264b11c1c823d9787bbb24511c8e6ca98b368d2da1d47fde04","schema_fingerprint":"4aa3821a28b0b7c2400bc59aba4bcc0a76e971dadd19610d3ad38c768e124dc7","schema_version":"edge-lab-recorder.raw.v1","sequence":null,"source":"clob_market_ws"}
{"event_at":"2026-07-28T03:02:31.403000Z","event_fingerprint":"cea505748cec98c12835398e6077d3ae127681bef28cf4418fd29f36c66bb9c7","payload":{"connection_id":"a6b55582af5f430fb37ad02bf0922475","event_at":"2026-07-28T03:02:31.403000Z","event_type":"price_change","frame_hash":"4e94390b1c175696fcce3d1269cfaf95d43eafa0f777af51df4362ca529cd9ad","frame_index":0,"kind":"data","monotonic_ns":309734298629791,"payload":{"event_type":"price_change","market":"0x779291bef19b6709f61e9764a954aafe9ffae488d50ae674aabdcb4f248006d5","price_changes":[{"asset_id":"8761897749749422724209054078244794145777693856614463256546737399611489089783","best_ask":"0.51","best_bid":"0.49","hash":"edd63d43e288090c082d61a79eec6c7617d4ba9d","price":"0.48","side":"BUY","size":"67"},{"asset_id":"14965588658799411272385430903075831224615961675357217884735713260981483529984","best_ask":"0.51","best_bid":"0.49","hash":"044cca6b458a6555fb3584644e0744b794657502","price":"0.52","side":"SELL","size":"67"}],"timestamp":"1785207751403"},"payload_hash":"08c4c62af7cc0a6fcb3c4043802016f24a86abc48a96cdc267af185fd8744b1b","raw_frame":"{\"market\":\"0x779291bef19b6709f61e9764a954aafe9ffae488d50ae674aabdcb4f248006d5\", \"price_changes\":[{\"asset_id\":\"8761897749749422724209054078244794145777693856614463256546737399611489089783\", \"price\":\"0.48\", \"size\":\"67\", \"side\":\"BUY\", \"hash\":\"edd63d43e288090c082d61a79eec6c7617d4ba9d\", \"best_bid\":\"0.49\", \"best_ask\":\"0.51\"}, {\"asset_id\":\"14965588658799411272385430903075831224615961675357217884735713260981483529984\", \"price\":\"0.52\", \"size\":\"67\", \"side\":\"SELL\", \"hash\":\"044cca6b458a6555fb3584644e0744b794657502\", \"best_bid\":\"0.49\", \"best_ask\":\"0.51\"}], \"timestamp\":\"1785207751403\", \"event_type\":\"price_change\"}","received_at":"2026-07-28T03:02:31.279174Z","schema_version":"clob-market-ws.price_change.v1","sequence":null,"server_hash":null,"server_timestamp":"1785207751403","session_id":"3e519d9098404c15b234d96025eb1a2b","source":"clob_market_ws"},"received_at":"2026-07-28T03:02:31.279174Z","record_id":"d7af8fe13f646fbdbc2bf346b8c29399f59bd40217f92bb4b8d2efebe5288939","schema_fingerprint":"4aa3821a28b0b7c2400bc59aba4bcc0a76e971dadd19610d3ad38c768e124dc7","schema_version":"edge-lab-recorder.raw.v1","sequence":null,"source":"clob_market_ws"}
{"event_at":"2026-07-28T03:02:31.404000Z","event_fingerprint":"3c64e2ea6da8a54c08b4dec5f3504688f5a66b92b1a34d99d4c0872d9e006ba2","payload":{"connection_id":"a6b55582af5f430fb37ad02bf0922475","event_at":"2026-07-28T03:02:31.404000Z","event_type":"price_change","frame_hash":"bb5083ea99fc062821213899faff652185bd8e3d27751333134731696c32ba72","frame_index":0,"kind":"data","monotonic_ns":309734300098125,"payload":{"event_type":"price_change","market":"0x779291bef19b6709f61e9764a954aafe9ffae488d50ae674aabdcb4f248006d5","price_changes":[{"asset_id":"8761897749749422724209054078244794145777693856614463256546737399611489089783","best_ask":"0.51","best_bid":"0.49","hash":"52fa7402b3d1a0cedac5f25795f96ec4581e908d","price":"0.31","side":"BUY","size":"50"},{"asset_id":"14965588658799411272385430903075831224615961675357217884735713260981483529984","best_ask":"0.51","best_bid":"0.49","hash":"8f1addc5a1ed49d8060e371aecb697ff409fab25","price":"0.69","side":"SELL","size":"50"}],"timestamp":"1785207751404"},"payload_hash":"458004b963cc468c54f7514bcfe53e0be93b72917ce5c6d8f276278548a12727","raw_frame":"{\"market\":\"0x779291bef19b6709f61e9764a954aafe9ffae488d50ae674aabdcb4f248006d5\", \"price_changes\":[{\"asset_id\":\"8761897749749422724209054078244794145777693856614463256546737399611489089783\", \"price\":\"0.31\", \"size\":\"50\", \"side\":\"BUY\", \"hash\":\"52fa7402b3d1a0cedac5f25795f96ec4581e908d\", \"best_bid\":\"0.49\", \"best_ask\":\"0.51\"}, {\"asset_id\":\"14965588658799411272385430903075831224615961675357217884735713260981483529984\", \"price\":\"0.69\", \"size\":\"50\", \"side\":\"SELL\", \"hash\":\"8f1addc5a1ed49d8060e371aecb697ff409fab25\", \"best_bid\":\"0.49\", \"best_ask\":\"0.51\"}], \"timestamp\":\"1785207751404\", \"event_type\":\"price_change\"}","received_at":"2026-07-28T03:02:31.280643Z","schema_version":"clob-market-ws.price_change.v1","sequence":null,"server_hash":null,"server_timestamp":"1785207751404","session_id":"3e519d9098404c15b234d96025eb1a2b","source":"clob_market_ws"},"received_at":"2026-07-28T03:02:31.280643Z","record_id":"8b0f1bb7986ada92707f4f5bc0ea68367023b735a8bf013f72850571efc5aebc","schema_fingerprint":"4aa3821a28b0b7c2400bc59aba4bcc0a76e971dadd19610d3ad38c768e124dc7","schema_version":"edge-lab-recorder.raw.v1","sequence":null,"source":"clob_market_ws"}
{"event_at":"2026-07-28T03:02:31.404000Z","event_fingerprint":"af9b7ee49dbcf86aa849ef3c7e336bb2caeadb44e34bb3eb8bd96c4f8cb518e2","payload":{"connection_id":"a6b55582af5f430fb37ad02bf0922475","event_at":"2026-07-28T03:02:31.404000Z","event_type":"price_change","frame_hash":"a136a8ffeb57ff28eb53b96ab2cdd831d5b058f3f39851428117bfe7e3bad296","frame_index":0,"kind":"data","monotonic_ns":309734301582083,"payload":{"event_type":"price_change","market":"0x779291bef19b6709f61e9764a954aafe9ffae488d50ae674aabdcb4f248006d5","price_changes":[{"asset_id":"8761897749749422724209054078244794145777693856614463256546737399611489089783","best_ask":"0.51","best_bid":"0.49","hash":"b61ac4ffd39b525d56384a138d26ba1218ae8ffa","price":"0.3","side":"BUY","size":"213.41"},{"asset_id":"14965588658799411272385430903075831224615961675357217884735713260981483529984","best_ask":"0.51","best_bid":"0.49","hash":"5d9c3cfb648a92b58399a3130ed5d9b306bd8fe6","price":"0.7","side":"SELL","size":"213.41"}],"timestamp":"1785207751404"},"payload_hash":"b45e4b1f8be12faa13dbaf76cde26e120cbb62f33ce5b0485677abdcd89edbcd","raw_frame":"{\"market\":\"0x779291bef19b6709f61e9764a954aafe9ffae488d50ae674aabdcb4f248006d5\", \"price_changes\":[{\"asset_id\":\"8761897749749422724209054078244794145777693856614463256546737399611489089783\", \"price\":\"0.3\", \"size\":\"213.41\", \"side\":\"BUY\", \"hash\":\"b61ac4ffd39b525d56384a138d26ba1218ae8ffa\", \"best_bid\":\"0.49\", \"best_ask\":\"0.51\"}, {\"asset_id\":\"14965588658799411272385430903075831224615961675357217884735713260981483529984\", \"price\":\"0.7\", \"size\":\"213.41\", \"side\":\"SELL\", \"hash\":\"5d9c3cfb648a92b58399a3130ed5d9b306bd8fe6\", \"best_bid\":\"0.49\", \"best_ask\":\"0.51\"}], \"timestamp\":\"1785207751404\", \"event_type\":\"price_change\"}","received_at":"2026-07-28T03:02:31.282127Z","schema_version":"clob-market-ws.price_change.v1","sequence":null,"server_hash":null,"server_timestamp":"1785207751404","session_id":"3e519d9098404c15b234d96025eb1a2b","source":"clob_market_ws"},"received_at":"2026-07-28T03:02:31.282127Z","record_id":"7003299fb3438760256984df79817ec9cbb5765f47e38b4ed76e6304c48d00d6","schema_fingerprint":"4aa3821a28b0b7c2400bc59aba4bcc0a76e971dadd19610d3ad38c768e124dc7","schema_version":"edge-lab-recorder.raw.v1","sequence":null,"source":"clob_market_ws"}
{"event_at":"2026-07-28T03:02:31.404000Z","event_fingerprint":"4e58606bbb81c3b95baf7cd4802ec0a12d2a4547faf47fcb02a47e70e3d15d72","payload":{"connection_id":"a6b55582af5f430fb37ad02bf0922475","event_at":"2026-07-28T03:02:31.404000Z","event_type":"price_change","frame_hash":"edf825981a4b67b8193b8f0875d237a5cad8a03b3cc5f9e0e8f4d60f8f023183","frame_index":0,"kind":"data","monotonic_ns":309734303064791,"payload":{"event_type":"price_change","market":"0x779291bef19b6709f61e9764a954aafe9ffae488d50ae674aabdcb4f248006d5","price_changes":[{"asset_id":"8761897749749422724209054078244794145777693856614463256546737399611489089783","best_ask":"0.51","best_bid":"0.49","hash":"249de49321567934e378e0dbf33b372a00b9acb0","price":"0.03","side":"BUY","size":"648.1"},{"asset_id":"14965588658799411272385430903075831224615961675357217884735713260981483529984","best_ask":"0.51","best_bid":"0.49","hash":"95a8cabacaebbe01be5eb1e8c913d42263890ac2","price":"0.97","side":"SELL","size":"648.1"}],"timestamp":"1785207751404"},"payload_hash":"74c84684b03ad6dc471b3b29a3dd7ab8eaa6d77278386aa26a520747898f466a","raw_frame":"{\"market\":\"0x779291bef19b6709f61e9764a954aafe9ffae488d50ae674aabdcb4f248006d5\", \"price_changes\":[{\"asset_id\":\"8761897749749422724209054078244794145777693856614463256546737399611489089783\", \"price\":\"0.03\", \"size\":\"648.1\", \"side\":\"BUY\", \"hash\":\"249de49321567934e378e0dbf33b372a00b9acb0\", \"best_bid\":\"0.49\", \"best_ask\":\"0.51\"}, {\"asset_id\":\"14965588658799411272385430903075831224615961675357217884735713260981483529984\", \"price\":\"0.97\", \"size\":\"648.1\", \"side\":\"SELL\", \"hash\":\"95a8cabacaebbe01be5eb1e8c913d42263890ac2\", \"best_bid\":\"0.49\", \"best_ask\":\"0.51\"}], \"timestamp\":\"1785207751404\", \"event_type\":\"price_change\"}","received_at":"2026-07-28T03:02:31.283609Z","schema_version":"clob-market-ws.price_change.v1","sequence":null,"server_hash":null,"server_timestamp":"1785207751404","session_id":"3e519d9098404c15b234d96025eb1a2b","source":"clob_market_ws"},"received_at":"2026-07-28T03:02:31.283609Z","record_id":"354a1848e43d6bc536d639f419e6b41328d350b2a95fe276b4e44b7e81d80405","schema_fingerprint":"4aa3821a28b0b7c2400bc59aba4bcc0a76e971dadd19610d3ad38c768e124dc7","schema_version":"edge-lab-recorder.raw.v1","sequence":null,"source":"clob_market_ws"}
{"event_at":"2026-07-28T03:02:31.406000Z","event_fingerprint":"acbdf7fc2a68e272ff5dbe37488ae8d30c0dba98b2310edfa5e4f13b22fa4768","payload":{"connection_id":"a6b55582af5f430fb37ad02bf0922475","event_at":"2026-07-28T03:02:31.406000Z","event_type":"best_bid_ask","frame_hash":"b8b36b9620faeaf5ebfc321950363f1a5f7f20cb940d3a9e2392314423fbc0df","frame_index":0,"kind":"data","monotonic_ns":309734306834250,"payload":{"asset_id":"14965588658799411272385430903075831224615961675357217884735713260981483529984","best_ask":"0.51","best_bid":"0.5","event_type":"best_bid_ask","market":"0x779291bef19b6709f61e9764a954aafe9ffae488d50ae674aabdcb4f248006d5","spread":"0.01","timestamp":"1785207751406"},"payload_hash":"df2962a985cc9fa2d6bc71c4087a765f9a408342fe10db23128edf376f8af64f","raw_frame":"{\"market\":\"0x779291bef19b6709f61e9764a954aafe9ffae488d50ae674aabdcb4f248006d5\", \"asset_id\":\"14965588658799411272385430903075831224615961675357217884735713260981483529984\", \"best_bid\":\"0.5\", \"best_ask\":\"0.51\", \"spread\":\"0.01\", \"timestamp\":\"1785207751406\", \"event_type\":\"best_bid_ask\"}","received_at":"2026-07-28T03:02:31.287376Z","schema_version":"clob-market-ws.best_bid_ask.v1","sequence":null,"server_hash":null,"server_timestamp":"1785207751406","session_id":"3e519d9098404c15b234d96025eb1a2b","source":"clob_market_ws"},"received_at":"2026-07-28T03:02:31.287376Z","record_id":"ecf91e54e83cc4cd27bb09b552337e301059d9b2783f17b2cd375b114e99620b","schema_fingerprint":"8488399f31b0337811b13b266be932db7062827c2470b78bd8e9e99bab51d17d","schema_version":"edge-lab-recorder.raw.v1","sequence":null,"source":"clob_market_ws"}
{"event_at":"2026-07-28T03:02:31.406000Z","event_fingerprint":"425c28fa21f3bcee070101c8b6ccbf454f4f642fec4ead6b85af967fdc4c7674","payload":{"connection_id":"a6b55582af5f430fb37ad02bf0922475","event_at":"2026-07-28T03:02:31.406000Z","event_type":"best_bid_ask","frame_hash":"6859b8328e18bdbdc72fbde8b9ee912eb3d4facc0d03fb8ce10e8ca1143761db","frame_index":0,"kind":"data","monotonic_ns":309734307961375,"payload":{"asset_id":"8761897749749422724209054078244794145777693856614463256546737399611489089783","best_ask":"0.5","best_bid":"0.49","event_type":"best_bid_ask","market":"0x779291bef19b6709f61e9764a954aafe9ffae488d50ae674aabdcb4f248006d5","spread":"0.01","timestamp":"1785207751406"},"payload_hash":"befda923236f7f47b7cd56890d05067e38e6ad93c2b0b420cdc7c39c464cef22","raw_frame":"{\"market\":\"0x779291bef19b6709f61e9764a954aafe9ffae488d50ae674aabdcb4f248006d5\", \"asset_id\":\"8761897749749422724209054078244794145777693856614463256546737399611489089783\", \"best_bid\":\"0.49\", \"best_ask\":\"0.5\", \"spread\":\"0.01\", \"timestamp\":\"1785207751406\", \"event_type\":\"best_bid_ask\"}","received_at":"2026-07-28T03:02:31.288505Z","schema_version":"clob-market-ws.best_bid_ask.v1","sequence":null,"server_hash":null,"server_timestamp":"1785207751406","session_id":"3e519d9098404c15b234d96025eb1a2b","source":"clob_market_ws"},"received_at":"2026-07-28T03:02:31.288505Z","record_id":"25c17e8eafac5b5f9390eeae92b41318871dd2a48607cd8e7aa79146424e2709","schema_fingerprint":"8488399f31b0337811b13b266be932db7062827c2470b78bd8e9e99bab51d17d","schema_version":"edge-lab-recorder.raw.v1","sequence":null,"source":"clob_market_ws"}
{"event_at":"2026-07-28T03:02:31.406000Z","event_fingerprint":"5fff3b6de25b6d2cc3f0aa9a2d6c341a49cd5170a90fe4596f70e526f806e800","payload":{"connection_id":"a6b55582af5f430fb37ad02bf0922475","event_at":"2026-07-28T03:02:31.406000Z","event_type":"price_change","frame_hash":"e15bae062a2ac1f691fd51f7c6a36757903aa0b7dfb09e9869328f1654bcc462","frame_index":0,"kind":"data","monotonic_ns":309734308919083,"payload":{"event_type":"price_change","market":"0x779291bef19b6709f61e9764a954aafe9ffae488d50ae674aabdcb4f248006d5","price_changes":[{"asset_id":"14965588658799411272385430903075831224615961675357217884735713260981483529984","best_ask":"0.51","best_bid":"0.5","hash":"535fb44001f528ca89771612b0a94a94867f318c","price":"0.5","side":"BUY","size":"34"},{"asset_id":"8761897749749422724209054078244794145777693856614463256546737399611489089783","best_ask":"0.5","best_bid":"0.49","hash":"60aa0f30d110692c7e846f8e52fa48b283ebbf3f","price":"0.5","side":"SELL","size":"34"}],"timestamp":"1785207751406"},"payload_hash":"5a9f4ae30bd2c3b7fe593f35b8fceb97639cb07c6ed73b9ccca7f9447cc1fb2f","raw_frame":"{\"market\":\"0x779291bef19b6709f61e9764a954aafe9ffae488d50ae674aabdcb4f248006d5\", \"price_changes\":[{\"asset_id\":\"14965588658799411272385430903075831224615961675357217884735713260981483529984\", \"price\":\"0.5\", \"size\":\"34\", \"side\":\"BUY\", \"hash\":\"535fb44001f528ca89771612b0a94a94867f318c\", \"best_bid\":\"0.5\", \"best_ask\":\"0.51\"}, {\"asset_id\":\"8761897749749422724209054078244794145777693856614463256546737399611489089783\", \"price\":\"0.5\", \"size\":\"34\", \"side\":\"SELL\", \"hash\":\"60aa0f30d110692c7e846f8e52fa48b283ebbf3f\", \"best_bid\":\"0.49\", \"best_ask\":\"0.5\"}], \"timestamp\":\"1785207751406\", \"event_type\":\"price_change\"}","received_at":"2026-07-28T03:02:31.289464Z","schema_version":"clob-market-ws.price_change.v1","sequence":null,"server_hash":null,"server_timestamp":"1785207751406","session_id":"3e519d9098404c15b234d96025eb1a2b","source":"clob_market_ws"},"received_at":"2026-07-28T03:02:31.289464Z","record_id":"6a3ef2a425c22f457967baad5bcb002886b5c76063dcc0117a69c9689c6c96c7","schema_fingerprint":"4aa3821a28b0b7c2400bc59aba4bcc0a76e971dadd19610d3ad38c768e124dc7","schema_version":"edge-lab-recorder.raw.v1","sequence":null,"source":"clob_market_ws"}
{"event_at":"2026-07-28T03:02:31.407000Z","event_fingerprint":"bd41ffde4912f0881eab47d929b4dc2e5d670dd8ec945c4fda42b7ec59b1c4ef","payload":{"connection_id":"a6b55582af5f430fb37ad02bf0922475","event_at":"2026-07-28T03:02:31.407000Z","event_type":"price_change","frame_hash":"8ee0517dc6e7e1ad42d50ff9d7a5180f9ab3bdc792dc3c64c0b6b08214487adf","frame_index":0,"kind":"data","monotonic_ns":309734310326583,"payload":{"event_type":"price_change","market":"0x779291bef19b6709f61e9764a954aafe9ffae488d50ae674aabdcb4f248006d5","price_changes":[{"asset_id":"14965588658799411272385430903075831224615961675357217884735713260981483529984","best_ask":"0.51","best_bid":"0.5","hash":"2bcd092c46ed9a33835f325130e0ac8819f30430","price":"0.43","side":"BUY","size":"133"},{"asset_id":"8761897749749422724209054078244794145777693856614463256546737399611489089783","best_ask":"0.5","best_bid":"0.49","hash":"0f7a203180408348e792f0f23e6556db7fb7bec9","price":"0.57","side":"SELL","size":"133"}],"timestamp":"1785207751407"},"payload_hash":"0be74fa4ea5b2590e788b75842dc0f00da1a0d8e70674441755b60dcac74646a","raw_frame":"{\"market\":\"0x779291bef19b6709f61e9764a954aafe9ffae488d50ae674aabdcb4f248006d5\", \"price_changes\":[{\"asset_id\":\"14965588658799411272385430903075831224615961675357217884735713260981483529984\", \"price\":\"0.43\", \"size\":\"133\", \"side\":\"BUY\", \"hash\":\"2bcd092c46ed9a33835f325130e0ac8819f30430\", \"best_bid\":\"0.5\", \"best_ask\":\"0.51\"}, {\"asset_id\":\"8761897749749422724209054078244794145777693856614463256546737399611489089783\", \"price\":\"0.57\", \"size\":\"133\", \"side\":\"SELL\", \"hash\":\"0f7a203180408348e792f0f23e6556db7fb7bec9\", \"best_bid\":\"0.49\", \"best_ask\":\"0.5\"}], \"timestamp\":\"1785207751407\", \"event_type\":\"price_change\"}","received_at":"2026-07-28T03:02:31.290871Z","schema_version":"clob-market-ws.price_change.v1","sequence":null,"server_hash":null,"server_timestamp":"1785207751407","session_id":"3e519d9098404c15b234d96025eb1a2b","source":"clob_market_ws"},"received_at":"2026-07-28T03:02:31.290871Z","record_id":"69f231a8fed20185ff097333e8558e373cfc3423bc7461cdaaabf8a86eb2ba77","schema_fingerprint":"4aa3821a28b0b7c2400bc59aba4bcc0a76e971dadd19610d3ad38c768e124dc7","schema_version":"edge-lab-recorder.raw.v1","sequence":null,"source":"clob_market_ws"}
{"event_at":"2026-07-28T03:02:31.407000Z","event_fingerprint":"d4b6d1239681520575234e6371e4a1f59d87fa178570cda0d90fbd45aca5371b","payload":{"connection_id":"a6b55582af5f430fb37ad02bf0922475","event_at":"2026-07-28T03:02:31.407000Z","event_type":"price_change","frame_hash":"038cbe37ad53edd180c22cce53c9e508e8225d2e8151e8a819d84909e6fc865f","frame_index":0,"kind":"data","monotonic_ns":309734311809541,"payload":{"event_type":"price_change","market":"0x779291bef19b6709f61e9764a954aafe9ffae488d50ae674aabdcb4f248006d5","price_changes":[{"asset_id":"14965588658799411272385430903075831224615961675357217884735713260981483529984","best_ask":"0.51","best_bid":"0.5","hash":"a51c40cbb06a5e421746bf649f934673dc0f7f3d","price":"0.48","side":"BUY","size":"136"},{"asset_id":"8761897749749422724209054078244794145777693856614463256546737399611489089783","best_ask":"0.5","best_bid":"0.49","hash":"c81c1d4ce9162b558e723226124d3d23882d354e","price":"0.52","side":"SELL","size":"136"}],"timestamp":"1785207751407"},"payload_hash":"6db51ce280fb7ed694eaffcf6679b3d83604076ff154abe657263e609955481b","raw_frame":"{\"market\":\"0x779291bef19b6709f61e9764a954aafe9ffae488d50ae674aabdcb4f248006d5\", \"price_changes\":[{\"asset_id\":\"14965588658799411272385430903075831224615961675357217884735713260981483529984\", \"price\":\"0.48\", \"size\":\"136\", \"side\":\"BUY\", \"hash\":\"a51c40cbb06a5e421746bf649f934673dc0f7f3d\", \"best_bid\":\"0.5\", \"best_ask\":\"0.51\"}, {\"asset_id\":\"8761897749749422724209054078244794145777693856614463256546737399611489089783\", \"price\":\"0.52\", \"size\":\"136\", \"side\":\"SELL\", \"hash\":\"c81c1d4ce9162b558e723226124d3d23882d354e\", \"best_bid\":\"0.49\", \"best_ask\":\"0.5\"}], \"timestamp\":\"1785207751407\", \"event_type\":\"price_change\"}","received_at":"2026-07-28T03:02:31.292353Z","schema_version":"clob-market-ws.price_change.v1","sequence":null,"server_hash":null,"server_timestamp":"1785207751407","session_id":"3e519d9098404c15b234d96025eb1a2b","source":"clob_market_ws"},"received_at":"2026-07-28T03:02:31.292353Z","record_id":"d56e886cdd7ca02fb25a2893594fcea5cf3e23fc4c90e5d1b66a7632d32a85a3","schema_fingerprint":"4aa3821a28b0b7c2400bc59aba4bcc0a76e971dadd19610d3ad38c768e124dc7","schema_version":"edge-lab-recorder.raw.v1","sequence":null,"source":"clob_market_ws"}
{"event_at":"2026-07-28T03:02:31.409000Z","event_fingerprint":"854e70507fe99a44f5aba8fbc7ab13041aa4726b7560ae020ce6f928f820d9de","payload":{"connection_id":"a6b55582af5f430fb37ad02bf0922475","event_at":"2026-07-28T03:02:31.409000Z","event_type":"best_bid_ask","frame_hash":"5dfb51d38e9910dee9dc896b590894dc140bceb32c9c784b6c36780971fe67e2","frame_index":0,"kind":"data","monotonic_ns":309734313276708,"payload":{"asset_id":"14965588658799411272385430903075831224615961675357217884735713260981483529984","best_ask":"0.52","best_bid":"0.5","event_type":"best_bid_ask","market":"0x779291bef19b6709f61e9764a954aafe9ffae488d50ae674aabdcb4f248006d5","spread":"0.02","timestamp":"1785207751409"},"payload_hash":"417f4ce25eca5ee135e8bb91d93c3a286f43f29f9685a4543aee38a7657f86b6","raw_frame":"{\"market\":\"0x779291bef19b6709f61e9764a954aafe9ffae488d50ae674aabdcb4f248006d5\", \"asset_id\":\"14965588658799411272385430903075831224615961675357217884735713260981483529984\", \"best_bid\":\"0.5\", \"best_ask\":\"0.52\", \"spread\":\"0.02\", \"timestamp\":\"1785207751409\", \"event_type\":\"best_bid_ask\"}","received_at":"2026-07-28T03:02:31.293821Z","schema_version":"clob-market-ws.best_bid_ask.v1","sequence":null,"server_hash":null,"server_timestamp":"1785207751409","session_id":"3e519d9098404c15b234d96025eb1a2b","source":"clob_market_ws"},"received_at":"2026-07-28T03:02:31.293821Z","record_id":"1ad19e6e7b907c821bd869d4bbcc6fdc1b738d23623d7de0f1e571707a74c9fd","schema_fingerprint":"8488399f31b0337811b13b266be932db7062827c2470b78bd8e9e99bab51d17d","schema_version":"edge-lab-recorder.raw.v1","sequence":null,"source":"clob_market_ws"}
{"event_at":"2026-07-28T03:02:31.409000Z","event_fingerprint":"3846c7275f24e81824dda473ce60d2106c2d1b781af9481e53554a97ddb9c06b","payload":{"connection_id":"a6b55582af5f430fb37ad02bf0922475","event_at":"2026-07-28T03:02:31.409000Z","event_type":"best_bid_ask","frame_hash":"178662c5147cbda8547d76854f89ea8158237841ae22d20d64f66ef41d29c5f5","frame_index":0,"kind":"data","monotonic_ns":309734314357375,"payload":{"asset_id":"8761897749749422724209054078244794145777693856614463256546737399611489089783","best_ask":"0.5","best_bid":"0.48","event_type":"best_bid_ask","market":"0x779291bef19b6709f61e9764a954aafe9ffae488d50ae674aabdcb4f248006d5","spread":"0.02","timestamp":"1785207751409"},"payload_hash":"57c3b7e87e3f1c9ab2fde1fd4cb279ebfeb27c539cc7ba418d16eda7885db375","raw_frame":"{\"market\":\"0x779291bef19b6709f61e9764a954aafe9ffae488d50ae674aabdcb4f248006d5\", \"asset_id\":\"8761897749749422724209054078244794145777693856614463256546737399611489089783\", \"best_bid\":\"0.48\", \"best_ask\":\"0.5\", \"spread\":\"0.02\", \"timestamp\":\"1785207751409\", \"event_type\":\"best_bid_ask\"}","received_at":"2026-07-28T03:02:31.294901Z","schema_version":"clob-market-ws.best_bid_ask.v1","sequence":null,"server_hash":null,"server_timestamp":"1785207751409","session_id":"3e519d9098404c15b234d96025eb1a2b","source":"clob_market_ws"},"received_at":"2026-07-28T03:02:31.294901Z","record_id":"d3a1674bcabb973717014a953a936da79043a69768cc41ab34c3bff62de654b6","schema_fingerprint":"8488399f31b0337811b13b266be932db7062827c2470b78bd8e9e99bab51d17d","schema_version":"edge-lab-recorder.raw.v1","sequence":null,"source":"clob_market_ws"}
{"event_at":"2026-07-28T03:02:31.407000Z","event_fingerprint":"df62aa463aa4174b34dcecef3ffbebb27103b7d3ad34cd2623954469c2ad511b","payload":{"connection_id":"a6b55582af5f430fb37ad02bf0922475","event_at":"2026-07-28T03:02:31.407000Z","event_type":"price_change","frame_hash":"7bc6279f0191713769dd85d76872933f25f0c48dc4c179f0c081b6f25859cf87","frame_index":0,"kind":"data","monotonic_ns":309734315428000,"payload":{"event_type":"price_change","market":"0x779291bef19b6709f61e9764a954aafe9ffae488d50ae674aabdcb4f248006d5","price_changes":[{"asset_id":"8761897749749422724209054078244794145777693856614463256546737399611489089783","best_ask":"0.5","best_bid":"0.48","hash":"b2e4a0bb1066463ddce203f03eadfd899409cf15","price":"0.49","side":"BUY","size":"0"},{"asset_id":"14965588658799411272385430903075831224615961675357217884735713260981483529984","best_ask":"0.52","best_bid":"0.5","hash":"886e1967c1767af712426bdbc196cfb95be7aefc","price":"0.51","side":"SELL","size":"0"}],"timestamp":"1785207751407"},"payload_hash":"76e6d33c61984b8f2045383e3bbbe94180bb39f723f2d281c5ec15affed99bee","raw_frame":"{\"market\":\"0x779291bef19b6709f61e9764a954aafe9ffae488d50ae674aabdcb4f248006d5\", \"price_changes\":[{\"asset_id\":\"8761897749749422724209054078244794145777693856614463256546737399611489089783\", \"price\":\"0.49\", \"size\":\"0\", \"side\":\"BUY\", \"hash\":\"b2e4a0bb1066463ddce203f03eadfd899409cf15\", \"best_bid\":\"0.48\", \"best_ask\":\"0.5\"}, {\"asset_id\":\"14965588658799411272385430903075831224615961675357217884735713260981483529984\", \"price\":\"0.51\", \"size\":\"0\", \"side\":\"SELL\", \"hash\":\"886e1967c1767af712426bdbc196cfb95be7aefc\", \"best_bid\":\"0.5\", \"best_ask\":\"0.52\"}], \"timestamp\":\"1785207751407\", \"event_type\":\"price_change\"}","received_at":"2026-07-28T03:02:31.295972Z","schema_version":"clob-market-ws.price_change.v1","sequence":null,"server_hash":null,"server_timestamp":"1785207751407","session_id":"3e519d9098404c15b234d96025eb1a2b","source":"clob_market_ws"},"received_at":"2026-07-28T03:02:31.295972Z","record_id":"c06b92f0dd977b29b972e10cb74344cda333a3b0f2d3a799b1ccbd74ad9e5a0d","schema_fingerprint":"4aa3821a28b0b7c2400bc59aba4bcc0a76e971dadd19610d3ad38c768e124dc7","schema_version":"edge-lab-recorder.raw.v1","sequence":null,"source":"clob_market_ws"}
{"event_at":"2026-07-28T03:02:31.409000Z","event_fingerprint":"b0be2ec95c03c022a9fdf0c6833ef9884b57429aa55e1e6799df6ac04f0aafd4","payload":{"connection_id":"a6b55582af5f430fb37ad02bf0922475","event_at":"2026-07-28T03:02:31.409000Z","event_type":"price_change","frame_hash":"73ef579ed6c6f6b7bbde6f1d8240a6ec4bd820be3f45fc3bb1b86f68383ee5ae","frame_index":0,"kind":"data","monotonic_ns":309734316936666,"payload":{"event_type":"price_change","market":"0x779291bef19b6709f61e9764a954aafe9ffae488d50ae674aabdcb4f248006d5","price_changes":[{"asset_id":"8761897749749422724209054078244794145777693856614463256546737399611489089783","best_ask":"0.5","best_bid":"0.48","hash":"b29b7a4755dca38046b29e0f14af6f16336261f0","price":"0.48","side":"BUY","size":"61"},{"asset_id":"14965588658799411272385430903075831224615961675357217884735713260981483529984","best_ask":"0.52","best_bid":"0.5","hash":"4cafaff9c129809b9802859d2cb4962d486c12a5","price":"0.52","side":"SELL","size":"61"}],"timestamp":"1785207751409"},"payload_hash":"5e77bec80e37befbd41f111ed465275fef7848ab71dcb0f1d15df00e567f78ff","raw_frame":"{\"market\":\"0x779291bef19b6709f61e9764a954aafe9ffae488d50ae674aabdcb4f248006d5\", \"price_changes\":[{\"asset_id\":\"8761897749749422724209054078244794145777693856614463256546737399611489089783\", \"price\":\"0.48\", \"size\":\"61\", \"side\":\"BUY\", \"hash\":\"b29b7a4755dca38046b29e0f14af6f16336261f0\", \"best_bid\":\"0.48\", \"best_ask\":\"0.5\"}, {\"asset_id\":\"14965588658799411272385430903075831224615961675357217884735713260981483529984\", \"price\":\"0.52\", \"size\":\"61\", \"side\":\"SELL\", \"hash\":\"4cafaff9c129809b9802859d2cb4962d486c12a5\", \"best_bid\":\"0.5\", \"best_ask\":\"0.52\"}], \"timestamp\":\"1785207751409\", \"event_type\":\"price_change\"}","received_at":"2026-07-28T03:02:31.297481Z","schema_version":"clob-market-ws.price_change.v1","sequence":null,"server_hash":null,"server_timestamp":"1785207751409","session_id":"3e519d9098404c15b234d96025eb1a2b","source":"clob_market_ws"},"received_at":"2026-07-28T03:02:31.297481Z","record_id":"5b2ae215c50933140589bfb4d0798fca2f24bd8a5db3edc7d51de6422d423403","schema_fingerprint":"4aa3821a28b0b7c2400bc59aba4bcc0a76e971dadd19610d3ad38c768e124dc7","schema_version":"edge-lab-recorder.raw.v1","sequence":null,"source":"clob_market_ws"}
{"event_at":"2026-07-28T03:02:31.409000Z","event_fingerprint":"6ee110ee59508c180acb562549075d50834c0f73a8a23681f620c41852b454c0","payload":{"connection_id":"a6b55582af5f430fb37ad02bf0922475","event_at":"2026-07-28T03:02:31.409000Z","event_type":"price_change","frame_hash":"9dbcabfe5214b6253950a8148dae4bb8ebfd87ad5b6e5753cfea142b0dddbb77","frame_index":0,"kind":"data","monotonic_ns":309734318543083,"payload":{"event_type":"price_change","market":"0x779291bef19b6709f61e9764a954aafe9ffae488d50ae674aabdcb4f248006d5","price_changes":[{"asset_id":"14965588658799411272385430903075831224615961675357217884735713260981483529984","best_ask":"0.52","best_bid":"0.5","hash":"07ef563c9f39e07c848bc8edd31e0eb536887977","price":"0.4","side":"BUY","size":"293.51"},{"asset_id":"8761897749749422724209054078244794145777693856614463256546737399611489089783","best_ask":"0.5","best_bid":"0.48","hash":"ad2738e2b9a2ba7f496f44cb001ccae0be17d571","price":"0.6","side":"SELL","size":"293.51"}],"timestamp":"1785207751409"},"payload_hash":"973d79d4e6caf88a97c4c4e96cfc4e88b2ca48934d68862f63de2068aa1683b0","raw_frame":"{\"market\":\"0x779291bef19b6709f61e9764a954aafe9ffae488d50ae674aabdcb4f248006d5\", \"price_changes\":[{\"asset_id\":\"14965588658799411272385430903075831224615961675357217884735713260981483529984\", \"price\":\"0.4\", \"size\":\"293.51\", \"side\":\"BUY\", \"hash\":\"07ef563c9f39e07c848bc8edd31e0eb536887977\", \"best_bid\":\"0.5\", \"best_ask\":\"0.52\"}, {\"asset_id\":\"8761897749749422724209054078244794145777693856614463256546737399611489089783\", \"price\":\"0.6\", \"size\":\"293.51\", \"side\":\"SELL\", \"hash\":\"ad2738e2b9a2ba7f496f44cb001ccae0be17d571\", \"best_bid\":\"0.48\", \"best_ask\":\"0.5\"}], \"timestamp\":\"1785207751409\", \"event_type\":\"price_change\"}","received_at":"2026-07-28T03:02:31.299087Z","schema_version":"clob-market-ws.price_change.v1","sequence":null,"server_hash":null,"server_timestamp":"1785207751409","session_id":"3e519d9098404c15b234d96025eb1a2b","source":"clob_market_ws"},"received_at":"2026-07-28T03:02:31.299087Z","record_id":"cba70bb1a6242c210f35b00546e8c1720e9b4e9459a7fb798662a65c0f381766","schema_fingerprint":"4aa3821a28b0b7c2400bc59aba4bcc0a76e971dadd19610d3ad38c768e124dc7","schema_version":"edge-lab-recorder.raw.v1","sequence":null,"source":"clob_market_ws"}
{"event_at":"2026-07-28T03:02:31.410000Z","event_fingerprint":"f79ed2182ea5110db66ce990ceb85718d2c040a953c93275fe6d848383f73dfe","payload":{"connection_id":"a6b55582af5f430fb37ad02bf0922475","event_at":"2026-07-28T03:02:31.410000Z","event_type":"price_change","frame_hash":"9d141bc6ae604cdeb4632b3bed17a5d7ea317269f6b149b7c4a4837cb0f32b2d","frame_index":0,"kind":"data","monotonic_ns":309734320034041,"payload":{"event_type":"price_change","market":"0x779291bef19b6709f61e9764a954aafe9ffae488d50ae674aabdcb4f248006d5","price_changes":[{"asset_id":"14965588658799411272385430903075831224615961675357217884735713260981483529984","best_ask":"0.52","best_bid":"0.5","hash":"ee9c2c2e9031b60c76b17e2409c4735e92f0f4b9","price":"0.46","side":"BUY","size":"105.6"},{"asset_id":"8761897749749422724209054078244794145777693856614463256546737399611489089783","best_ask":"0.5","best_bid":"0.48","hash":"58e6beb695134e370a3e5c2e2bb8881157064956","price":"0.54","side":"SELL","size":"105.6"}],"timestamp":"1785207751410"},"payload_hash":"3908ae52baf9ecf4d7c20197d97d4f069d11c88555375c2f6e92799aecc587f2","raw_frame":"{\"market\":\"0x779291bef19b6709f61e9764a954aafe9ffae488d50ae674aabdcb4f248006d5\", \"price_changes\":[{\"asset_id\":\"14965588658799411272385430903075831224615961675357217884735713260981483529984\", \"price\":\"0.46\", \"size\":\"105.6\", \"side\":\"BUY\", \"hash\":\"ee9c2c2e9031b60c76b17e2409c4735e92f0f4b9\", \"best_bid\":\"0.5\", \"best_ask\":\"0.52\"}, {\"asset_id\":\"8761897749749422724209054078244794145777693856614463256546737399611489089783\", \"price\":\"0.54\", \"size\":\"105.6\", \"side\":\"SELL\", \"hash\":\"58e6beb695134e370a3e5c2e2bb8881157064956\", \"best_bid\":\"0.48\", \"best_ask\":\"0.5\"}], \"timestamp\":\"1785207751410\", \"event_type\":\"price_change\"}","received_at":"2026-07-28T03:02:31.300578Z","schema_version":"clob-market-ws.price_change.v1","sequence":null,"server_hash":null,"server_timestamp":"1785207751410","session_id":"3e519d9098404c15b234d96025eb1a2b","source":"clob_market_ws"},"received_at":"2026-07-28T03:02:31.300578Z","record_id":"11c97f655e9a8dc7fdf1ca4dd52ccd02d6d9a137f3662c03e9b0f8242c8fc76e","schema_fingerprint":"4aa3821a28b0b7c2400bc59aba4bcc0a76e971dadd19610d3ad38c768e124dc7","schema_version":"edge-lab-recorder.raw.v1","sequence":null,"source":"clob_market_ws"}
{"event_at":"2026-07-28T03:02:31.411000Z","event_fingerprint":"4e2345e5a67bc4b137adda0440118c0405ad1f4af3f830a66e136fff5c0aab1f","payload":{"connection_id":"a6b55582af5f430fb37ad02bf0922475","event_at":"2026-07-28T03:02:31.411000Z","event_type":"price_change","frame_hash":"74ce90c644c72b5eb357f360f648d2fe8984d835ef074a8b655dbf428125dfa1","frame_index":0,"kind":"data","monotonic_ns":309734321521208,"payload":{"event_type":"price_change","market":"0x779291bef19b6709f61e9764a954aafe9ffae488d50ae674aabdcb4f248006d5","price_changes":[{"asset_id":"14965588658799411272385430903075831224615961675357217884735713260981483529984","best_ask":"0.52","best_bid":"0.5","hash":"e8b2d8bfe6ea11ad542f729ada426d482060bc56","price":"0.5","side":"BUY","size":"40"},{"asset_id":"8761897749749422724209054078244794145777693856614463256546737399611489089783","best_ask":"0.5","best_bid":"0.48","hash":"a2a853549a14304292215c71aa12f9bdfbea623c","price":"0.5","side":"SELL","size":"40"}],"timestamp":"1785207751411"},"payload_hash":"d6a5311dad12829f043d36abb44003989bcf4ccaa224ab4beb59b63cb92c252b","raw_frame":"{\"market\":\"0x779291bef19b6709f61e9764a954aafe9ffae488d50ae674aabdcb4f248006d5\", \"price_changes\":[{\"asset_id\":\"14965588658799411272385430903075831224615961675357217884735713260981483529984\", \"price\":\"0.5\", \"size\":\"40\", \"side\":\"BUY\", \"hash\":\"e8b2d8bfe6ea11ad542f729ada426d482060bc56\", \"best_bid\":\"0.5\", \"best_ask\":\"0.52\"}, {\"asset_id\":\"8761897749749422724209054078244794145777693856614463256546737399611489089783\", \"price\":\"0.5\", \"size\":\"40\", \"side\":\"SELL\", \"hash\":\"a2a853549a14304292215c71aa12f9bdfbea623c\", \"best_bid\":\"0.48\", \"best_ask\":\"0.5\"}], \"timestamp\":\"1785207751411\", \"event_type\":\"price_change\"}","received_at":"2026-07-28T03:02:31.302065Z","schema_version":"clob-market-ws.price_change.v1","sequence":null,"server_hash":null,"server_timestamp":"1785207751411","session_id":"3e519d9098404c15b234d96025eb1a2b","source":"clob_market_ws"},"received_at":"2026-07-28T03:02:31.302065Z","record_id":"b2f2dc93676c3f841f3a62d71e4b56a408c42c7950ae7cfb6b3ff5dd3eb5fd3f","schema_fingerprint":"4aa3821a28b0b7c2400bc59aba4bcc0a76e971dadd19610d3ad38c768e124dc7","schema_version":"edge-lab-recorder.raw.v1","sequence":null,"source":"clob_market_ws"}
{"event_at":"2026-07-28T03:02:31.412000Z","event_fingerprint":"fe9bae594c91a1a059e2b62a6e9cf2431079b273eff624daaa35cd64e6e71f6a","payload":{"connection_id":"a6b55582af5f430fb37ad02bf0922475","event_at":"2026-07-28T03:02:31.412000Z","event_type":"price_change","frame_hash":"e27a3890db946d1466a874af76bc1758ac691a21451eae29802306e23b1bb944","frame_index":0,"kind":"data","monotonic_ns":309734323494375,"payload":{"event_type":"price_change","market":"0x779291bef19b6709f61e9764a954aafe9ffae488d50ae674aabdcb4f248006d5","price_changes":[{"asset_id":"14965588658799411272385430903075831224615961675357217884735713260981483529984","best_ask":"0.52","best_bid":"0.5","hash":"1d8af0e9256a215af02f91d3e4fadddcd1d19ace","price":"0.01","side":"BUY","size":"7883.02"},{"asset_id":"8761897749749422724209054078244794145777693856614463256546737399611489089783","best_ask":"0.5","best_bid":"0.48","hash":"10a68c70da7382a9f9c5dace47470d2251a7eb19","price":"0.99","side":"SELL","size":"7883.02"}],"timestamp":"1785207751412"},"payload_hash":"e70fe49d1b741cb51ae8462c824dea5c0ff31d39682d23cbe747e2d2c84a11cc","raw_frame":"{\"market\":\"0x779291bef19b6709f61e9764a954aafe9ffae488d50ae674aabdcb4f248006d5\", \"price_changes\":[{\"asset_id\":\"14965588658799411272385430903075831224615961675357217884735713260981483529984\", \"price\":\"0.01\", \"size\":\"7883.02\", \"side\":\"BUY\", \"hash\":\"1d8af0e9256a215af02f91d3e4fadddcd1d19ace\", \"best_bid\":\"0.5\", \"best_ask\":\"0.52\"}, {\"asset_id\":\"8761897749749422724209054078244794145777693856614463256546737399611489089783\", \"price\":\"0.99\", \"size\":\"7883.02\", \"side\":\"SELL\", \"hash\":\"10a68c70da7382a9f9c5dace47470d2251a7eb19\", \"best_bid\":\"0.48\", \"best_ask\":\"0.5\"}], \"timestamp\":\"1785207751412\", \"event_type\":\"price_change\"}","received_at":"2026-07-28T03:02:31.304038Z","schema_version":"clob-market-ws.price_change.v1","sequence":null,"server_hash":null,"server_timestamp":"1785207751412","session_id":"3e519d9098404c15b234d96025eb1a2b","source":"clob_market_ws"},"received_at":"2026-07-28T03:02:31.304038Z","record_id":"c8e05196f921a16fb32bf6408470fa20de75c598474df018a33164b6d993b937","schema_fingerprint":"4aa3821a28b0b7c2400bc59aba4bcc0a76e971dadd19610d3ad38c768e124dc7","schema_version":"edge-lab-recorder.raw.v1","sequence":null,"source":"clob_market_ws"}
{"event_at":"2026-07-28T03:02:31.417000Z","event_fingerprint":"f63ba43c4a83774576c26b76356a75da3b00cf01308bc7bf5fcddb3f47429287","payload":{"connection_id":"a6b55582af5f430fb37ad02bf0922475","event_at":"2026-07-28T03:02:31.417000Z","event_type":"price_change","frame_hash":"2e11de8808bc19a075bafc6b55147c0593025783fdd21824b16af720f6c56f96","frame_index":0,"kind":"data","monotonic_ns":309734324992083,"payload":{"event_type":"price_change","market":"0x779291bef19b6709f61e9764a954aafe9ffae488d50ae674aabdcb4f248006d5","price_changes":[{"asset_id":"14965588658799411272385430903075831224615961675357217884735713260981483529984","best_ask":"0.52","best_bid":"0.5","hash":"127d9862d44baca0a0a7554b5a43a7d4aec4191b","price":"0.49","side":"BUY","size":"238.8"},{"asset_id":"8761897749749422724209054078244794145777693856614463256546737399611489089783","best_ask":"0.5","best_bid":"0.48","hash":"7a17d901aebd3a367b1e93cf75e881dec41d7340","price":"0.51","side":"SELL","size":"238.8"}],"timestamp":"1785207751417"},"payload_hash":"61e7d43faf391a443b4129289f4a671ec6aeaf4f60b43dc949cdd3db374b4168","raw_frame":"{\"market\":\"0x779291bef19b6709f61e9764a954aafe9ffae488d50ae674aabdcb4f248006d5\", \"price_changes\":[{\"asset_id\":\"14965588658799411272385430903075831224615961675357217884735713260981483529984\", \"price\":\"0.49\", \"size\":\"238.8\", \"side\":\"BUY\", \"hash\":\"127d9862d44baca0a0a7554b5a43a7d4aec4191b\", \"best_bid\":\"0.5\", \"best_ask\":\"0.52\"}, {\"asset_id\":\"8761897749749422724209054078244794145777693856614463256546737399611489089783\", \"price\":\"0.51\", \"size\":\"238.8\", \"side\":\"SELL\", \"hash\":\"7a17d901aebd3a367b1e93cf75e881dec41d7340\", \"best_bid\":\"0.48\", \"best_ask\":\"0.5\"}], \"timestamp\":\"1785207751417\", \"event_type\":\"price_change\"}","received_at":"2026-07-28T03:02:31.305536Z","schema_version":"clob-market-ws.price_change.v1","sequence":null,"server_hash":null,"server_timestamp":"1785207751417","session_id":"3e519d9098404c15b234d96025eb1a2b","source":"clob_market_ws"},"received_at":"2026-07-28T03:02:31.305536Z","record_id":"8a06d5dcd4dcd786fcf045f4932a16d91c8ceb0b5c238e3d485f1a4705be083f","schema_fingerprint":"4aa3821a28b0b7c2400bc59aba4bcc0a76e971dadd19610d3ad38c768e124dc7","schema_version":"edge-lab-recorder.raw.v1","sequence":null,"source":"clob_market_ws"}
{"event_at":"2026-07-28T03:02:31.418000Z","event_fingerprint":"600dfd5acff179fb99f12afa3d68f7ed25c37b6217d5f615b6c853d3843b17ca","payload":{"connection_id":"a6b55582af5f430fb37ad02bf0922475","event_at":"2026-07-28T03:02:31.418000Z","event_type":"price_change","frame_hash":"1f495f9f951f432f1979f8cab5482e4075117657d72f3e5502fb5723038a93b0","frame_index":0,"kind":"data","monotonic_ns":309734326455708,"payload":{"event_type":"price_change","market":"0x779291bef19b6709f61e9764a954aafe9ffae488d50ae674aabdcb4f248006d5","price_changes":[{"asset_id":"14965588658799411272385430903075831224615961675357217884735713260981483529984","best_ask":"0.52","best_bid":"0.5","hash":"b4a1bcf0692b175a272b73d11c305eefa397e042","price":"0.33","side":"BUY","size":"161.6"},{"asset_id":"8761897749749422724209054078244794145777693856614463256546737399611489089783","best_ask":"0.5","best_bid":"0.48","hash":"f4631c934bcaa414a8b1c8abde89750314ba7bb3","price":"0.67","side":"SELL","size":"161.6"}],"timestamp":"1785207751418"},"payload_hash":"478443e533811c82d9df5df3e5fd5dd67d14a26b20928586cb1f2d035bd91051","raw_frame":"{\"market\":\"0x779291bef19b6709f61e9764a954aafe9ffae488d50ae674aabdcb4f248006d5\", \"price_changes\":[{\"asset_id\":\"14965588658799411272385430903075831224615961675357217884735713260981483529984\", \"price\":\"0.33\", \"size\":\"161.6\", \"side\":\"BUY\", \"hash\":\"b4a1bcf0692b175a272b73d11c305eefa397e042\", \"best_bid\":\"0.5\", \"best_ask\":\"0.52\"}, {\"asset_id\":\"8761897749749422724209054078244794145777693856614463256546737399611489089783\", \"price\":\"0.67\", \"size\":\"161.6\", \"side\":\"SELL\", \"hash\":\"f4631c934bcaa414a8b1c8abde89750314ba7bb3\", \"best_bid\":\"0.48\", \"best_ask\":\"0.5\"}], \"timestamp\":\"1785207751418\", \"event_type\":\"price_change\"}","received_at":"2026-07-28T03:02:31.307000Z","schema_version":"clob-market-ws.price_change.v1","sequence":null,"server_hash":null,"server_timestamp":"1785207751418","session_id":"3e519d9098404c15b234d96025eb1a2b","source":"clob_market_ws"},"received_at":"2026-07-28T03:02:31.307000Z","record_id":"3f84d0fddba198ff10a7b9aeaac1ec97dea949d8c9ce98643d07441e869e91ec","schema_fingerprint":"4aa3821a28b0b7c2400bc59aba4bcc0a76e971dadd19610d3ad38c768e124dc7","schema_version":"edge-lab-recorder.raw.v1","sequence":null,"source":"clob_market_ws"}
{"event_at":"2026-07-28T03:02:31.418000Z","event_fingerprint":"88194f1476f25fcd7ec2605b8734cd41ebe9a34d8893778084f974a927e9cdd6","payload":{"connection_id":"a6b55582af5f430fb37ad02bf0922475","event_at":"2026-07-28T03:02:31.418000Z","event_type":"price_change","frame_hash":"037faff0f90ec9e11b18f2d2d175dcbe8887ab83c1ac34b55bfae59289e66725","frame_index":0,"kind":"data","monotonic_ns":309734327993166,"payload":{"event_type":"price_change","market":"0x779291bef19b6709f61e9764a954aafe9ffae488d50ae674aabdcb4f248006d5","price_changes":[{"asset_id":"8761897749749422724209054078244794145777693856614463256546737399611489089783","best_ask":"0.5","best_bid":"0.48","hash":"f4631c934bcaa414a8b1c8abde89750314ba7bb3","price":"0.37","side":"BUY","size":"189"},{"asset_id":"14965588658799411272385430903075831224615961675357217884735713260981483529984","best_ask":"0.52","best_bid":"0.5","hash":"b4a1bcf0692b175a272b73d11c305eefa397e042","price":"0.63","side":"SELL","size":"189"}],"timestamp":"1785207751418"},"payload_hash":"d0fb9426011700f215f2f88fe54c3aca99175fb71aaf404438da24a49ee85f46","raw_frame":"{\"market\":\"0x779291bef19b6709f61e9764a954aafe9ffae488d50ae674aabdcb4f248006d5\", \"price_changes\":[{\"asset_id\":\"8761897749749422724209054078244794145777693856614463256546737399611489089783\", \"price\":\"0.37\", \"size\":\"189\", \"side\":\"BUY\", \"hash\":\"f4631c934bcaa414a8b1c8abde89750314ba7bb3\", \"best_bid\":\"0.48\", \"best_ask\":\"0.5\"}, {\"asset_id\":\"14965588658799411272385430903075831224615961675357217884735713260981483529984\", \"price\":\"0.63\", \"size\":\"189\", \"side\":\"SELL\", \"hash\":\"b4a1bcf0692b175a272b73d11c305eefa397e042\", \"best_bid\":\"0.5\", \"best_ask\":\"0.52\"}], \"timestamp\":\"1785207751418\", \"event_type\":\"price_change\"}","received_at":"2026-07-28T03:02:31.308535Z","schema_version":"clob-market-ws.price_change.v1","sequence":null,"server_hash":null,"server_timestamp":"1785207751418","session_id":"3e519d9098404c15b234d96025eb1a2b","source":"clob_market_ws"},"received_at":"2026-07-28T03:02:31.308535Z","record_id":"cf6e4a06bcead3e720c9fe0437f20f6d4210743072c19b19625b1561a9ecc963","schema_fingerprint":"4aa3821a28b0b7c2400bc59aba4bcc0a76e971dadd19610d3ad38c768e124dc7","schema_version":"edge-lab-recorder.raw.v1","sequence":null,"source":"clob_market_ws"}
{"event_at":"2026-07-28T03:02:31.419000Z","event_fingerprint":"bb5b92ee98f90d0311a794aa812e213fa56202ce9cfa3988b725efbb3bfd55c9","payload":{"connection_id":"a6b55582af5f430fb37ad02bf0922475","event_at":"2026-07-28T03:02:31.419000Z","event_type":"price_change","frame_hash":"aa53be979cf679edc884c9f96f08110dddcf511d680ef12d34678ce1621c9c53","frame_index":0,"kind":"data","monotonic_ns":309734329583125,"payload":{"event_type":"price_change","market":"0x779291bef19b6709f61e9764a954aafe9ffae488d50ae674aabdcb4f248006d5","price_changes":[{"asset_id":"14965588658799411272385430903075831224615961675357217884735713260981483529984","best_ask":"0.52","best_bid":"0.5","hash":"47e9c1707bca0d3204885c7e5e2bf9571e4816b3","price":"0.5","side":"BUY","size":"59"},{"asset_id":"8761897749749422724209054078244794145777693856614463256546737399611489089783","best_ask":"0.5","best_bid":"0.48","hash":"c14f7aa93bd1a6f41b7c39819bffab9f98773b3a","price":"0.5","side":"SELL","size":"59"}],"timestamp":"1785207751419"},"payload_hash":"8ed7995b48de3ab15b20826ef2689dfb5f74471c3806926dab4627f5011376f2","raw_frame":"{\"market\":\"0x779291bef19b6709f61e9764a954aafe9ffae488d50ae674aabdcb4f248006d5\", \"price_changes\":[{\"asset_id\":\"14965588658799411272385430903075831224615961675357217884735713260981483529984\", \"price\":\"0.5\", \"size\":\"59\", \"side\":\"BUY\", \"hash\":\"47e9c1707bca0d3204885c7e5e2bf9571e4816b3\", \"best_bid\":\"0.5\", \"best_ask\":\"0.52\"}, {\"asset_id\":\"8761897749749422724209054078244794145777693856614463256546737399611489089783\", \"price\":\"0.5\", \"size\":\"59\", \"side\":\"SELL\", \"hash\":\"c14f7aa93bd1a6f41b7c39819bffab9f98773b3a\", \"best_bid\":\"0.48\", \"best_ask\":\"0.5\"}], \"timestamp\":\"1785207751419\", \"event_type\":\"price_change\"}","received_at":"2026-07-28T03:02:31.310126Z","schema_version":"clob-market-ws.price_change.v1","sequence":null,"server_hash":null,"server_timestamp":"1785207751419","session_id":"3e519d9098404c15b234d96025eb1a2b","source":"clob_market_ws"},"received_at":"2026-07-28T03:02:31.310126Z","record_id":"d1a208ba29303f37db9e2280238e9147affec715931ba37a63e98916d54de0c1","schema_fingerprint":"4aa3821a28b0b7c2400bc59aba4bcc0a76e971dadd19610d3ad38c768e124dc7","schema_version":"edge-lab-recorder.raw.v1","sequence":null,"source":"clob_market_ws"}
{"event_at":"2026-07-28T03:02:31.421000Z","event_fingerprint":"4f273ddf2ff11bcdbd2cef2742d7ba9842edf49041a0f7abd41eabdb86dcd334","payload":{"connection_id":"a6b55582af5f430fb37ad02bf0922475","event_at":"2026-07-28T03:02:31.421000Z","event_type":"best_bid_ask","frame_hash":"033f4c9bcc7951b55a0b07b13ae1687c79c4e4030b81f470d2e87d74d51b1250","frame_index":0,"kind":"data","monotonic_ns":309734331161291,"payload":{"asset_id":"14965588658799411272385430903075831224615961675357217884735713260981483529984","best_ask":"0.51","best_bid":"0.5","event_type":"best_bid_ask","market":"0x779291bef19b6709f61e9764a954aafe9ffae488d50ae674aabdcb4f248006d5","spread":"0.01","timestamp":"1785207751421"},"payload_hash":"96f168747e1f152d58427490677748773ebb10e7cd349e30d4d59ad88399f44b","raw_frame":"{\"market\":\"0x779291bef19b6709f61e9764a954aafe9ffae488d50ae674aabdcb4f248006d5\", \"asset_id\":\"14965588658799411272385430903075831224615961675357217884735713260981483529984\", \"best_bid\":\"0.5\", \"best_ask\":\"0.51\", \"spread\":\"0.01\", \"timestamp\":\"1785207751421\", \"event_type\":\"best_bid_ask\"}","received_at":"2026-07-28T03:02:31.311704Z","schema_version":"clob-market-ws.best_bid_ask.v1","sequence":null,"server_hash":null,"server_timestamp":"1785207751421","session_id":"3e519d9098404c15b234d96025eb1a2b","source":"clob_market_ws"},"received_at":"2026-07-28T03:02:31.311704Z","record_id":"7e00dd9dac1e8292cbca6080705a4004bb46e661be48d900c3fc74bc02de68f4","schema_fingerprint":"8488399f31b0337811b13b266be932db7062827c2470b78bd8e9e99bab51d17d","schema_version":"edge-lab-recorder.raw.v1","sequence":null,"source":"clob_market_ws"}
{"event_at":"2026-07-28T03:02:31.421000Z","event_fingerprint":"de0f623cbc195bcdf7cd4a50a350d8f0c800f6b20c711a53399a7720c55218fa","payload":{"connection_id":"a6b55582af5f430fb37ad02bf0922475","event_at":"2026-07-28T03:02:31.421000Z","event_type":"best_bid_ask","frame_hash":"fa5910bff8a187a23295469ea726c9c04c16beb2866626de7ece0189f13e9fc0","frame_index":0,"kind":"data","monotonic_ns":309734332239583,"payload":{"asset_id":"8761897749749422724209054078244794145777693856614463256546737399611489089783","best_ask":"0.5","best_bid":"0.49","event_type":"best_bid_ask","market":"0x779291bef19b6709f61e9764a954aafe9ffae488d50ae674aabdcb4f248006d5","spread":"0.01","timestamp":"1785207751421"},"payload_hash":"8ac8d3cc1cda28c6691b016bec2bfb187c8df0b22ec64f86c663aec505462c79","raw_frame":"{\"market\":\"0x779291bef19b6709f61e9764a954aafe9ffae488d50ae674aabdcb4f248006d5\", \"asset_id\":\"8761897749749422724209054078244794145777693856614463256546737399611489089783\", \"best_bid\":\"0.49\", \"best_ask\":\"0.5\", \"spread\":\"0.01\", \"timestamp\":\"1785207751421\", \"event_type\":\"best_bid_ask\"}","received_at":"2026-07-28T03:02:31.312782Z","schema_version":"clob-market-ws.best_bid_ask.v1","sequence":null,"server_hash":null,"server_timestamp":"1785207751421","session_id":"3e519d9098404c15b234d96025eb1a2b","source":"clob_market_ws"},"received_at":"2026-07-28T03:02:31.312782Z","record_id":"d21a242240c79f8d6d71a7b7a72afc907aac454e6fc99934acc3c08563a6c5aa","schema_fingerprint":"8488399f31b0337811b13b266be932db7062827c2470b78bd8e9e99bab51d17d","schema_version":"edge-lab-recorder.raw.v1","sequence":null,"source":"clob_market_ws"}
{"event_at":"2026-07-28T03:02:31.420000Z","event_fingerprint":"fe4d8e01a28a6c75513560fe16156018f18a3905d4aad2d08ee6e3e7043fc149","payload":{"connection_id":"a6b55582af5f430fb37ad02bf0922475","event_at":"2026-07-28T03:02:31.420000Z","event_type":"price_change","frame_hash":"4e80eb293aa2c591c54ce9a8631df841036d8d7d9e7a8d13e05d9cd967f75a9f","frame_index":0,"kind":"data","monotonic_ns":309734333391250,"payload":{"event_type":"price_change","market":"0x779291bef19b6709f61e9764a954aafe9ffae488d50ae674aabdcb4f248006d5","price_changes":[{"asset_id":"8761897749749422724209054078244794145777693856614463256546737399611489089783","best_ask":"0.5","best_bid":"0.49","hash":"baa8c270e79721472fdd543d77583bf1e768d43d","price":"0.49","side":"BUY","size":"12.6"},{"asset_id":"14965588658799411272385430903075831224615961675357217884735713260981483529984","best_ask":"0.51","best_bid":"0.5","hash":"5e89588b422fbe130fed7f16eae254f6d78cb408","price":"0.51","side":"SELL","size":"12.6"}],"timestamp":"1785207751420"},"payload_hash":"cbf5fb2e5cd8503783e91dbcf48d4b6d0ce91c0bb4a01f805a0033a7a5407fb3","raw_frame":"{\"market\":\"0x779291bef19b6709f61e9764a954aafe9ffae488d50ae674aabdcb4f248006d5\", \"price_changes\":[{\"asset_id\":\"8761897749749422724209054078244794145777693856614463256546737399611489089783\", \"price\":\"0.49\", \"size\":\"12.6\", \"side\":\"BUY\", \"hash\":\"baa8c270e79721472fdd543d77583bf1e768d43d\", \"best_bid\":\"0.49\", \"best_ask\":\"0.5\"}, {\"asset_id\":\"14965588658799411272385430903075831224615961675357217884735713260981483529984\", \"price\":\"0.51\", \"size\":\"12.6\", \"side\":\"SELL\", \"hash\":\"5e89588b422fbe130fed7f16eae254f6d78cb408\", \"best_bid\":\"0.5\", \"best_ask\":\"0.51\"}], \"timestamp\":\"1785207751420\", \"event_type\":\"price_change\"}","received_at":"2026-07-28T03:02:31.313934Z","schema_version":"clob-market-ws.price_change.v1","sequence":null,"server_hash":null,"server_timestamp":"1785207751420","session_id":"3e519d9098404c15b234d96025eb1a2b","source":"clob_market_ws"},"received_at":"2026-07-28T03:02:31.313934Z","record_id":"96d430e95cf43b029cf76d3a2709584a701f027ff5eecab48d0977d2be9df8da","schema_fingerprint":"4aa3821a28b0b7c2400bc59aba4bcc0a76e971dadd19610d3ad38c768e124dc7","schema_version":"edge-lab-recorder.raw.v1","sequence":null,"source":"clob_market_ws"}
