{"event_at":"2026-07-28T03:13:09.643000Z","event_fingerprint":"9984c9f3df654d77b1e7619f624668c1d1ddee66a248a287d755782e902cdc0f","payload":{"connection_id":"a6b55582af5f430fb37ad02bf0922475","event_at":"2026-07-28T03:13:09.643000Z","event_type":"price_change","frame_hash":"c46ebbc5fb0bd00c85305bd9c7f9615a04b8b6fd38a043b0214567a8752a0f51","frame_index":0,"kind":"data","monotonic_ns":310372965033791,"payload":{"event_type":"price_change","market":"0x779291bef19b6709f61e9764a954aafe9ffae488d50ae674aabdcb4f248006d5","price_changes":[{"asset_id":"14965588658799411272385430903075831224615961675357217884735713260981483529984","best_ask":"0.55","best_bid":"0.54","hash":"1b2dde598c4bc14d6f2b7e319ffb0729ce12ef7e","price":"0.45","side":"BUY","size":"93.36"},{"asset_id":"8761897749749422724209054078244794145777693856614463256546737399611489089783","best_ask":"0.46","best_bid":"0.45","hash":"a0feb108d6c551423ae72d51dca272cebbd205b7","price":"0.55","side":"SELL","size":"93.36"}],"timestamp":"1785208389643"},"payload_hash":"9e0bcaa1864a24661672c1949da0d44546b87681dbbaf491cdb5bc21abe8aa34","raw_frame":"{\"market\":\"0x779291bef19b6709f61e9764a954aafe9ffae488d50ae674aabdcb4f248006d5\", \"price_changes\":[{\"asset_id\":\"14965588658799411272385430903075831224615961675357217884735713260981483529984\", \"price\":\"0.45\", \"size\":\"93.36\", \"side\":\"BUY\", \"hash\":\"1b2dde598c4bc14d6f2b7e319ffb0729ce12ef7e\", \"best_bid\":\"0.54\", \"best_ask\":\"0.55\"}, {\"asset_id\":\"8761897749749422724209054078244794145777693856614463256546737399611489089783\", \"price\":\"0.55\", \"size\":\"93.36\", \"side\":\"SELL\", \"hash\":\"a0feb108d6c551423ae72d51dca272cebbd205b7\", \"best_bid\":\"0.45\", \"best_ask\":\"0.46\"}], \"timestamp\":\"1785208389643\", \"event_type\":\"price_change\"}","received_at":"2026-07-28T03:13:09.930067Z","schema_version":"clob-market-ws.price_change.v1","sequence":null,"server_hash":null,"server_timestamp":"1785208389643","session_id":"3e519d9098404c15b234d96025eb1a2b","source":"clob_market_ws"},"received_at":"2026-07-28T03:13:09.930067Z","record_id":"ddfcf65d3fb4eb9b0f58f786b63ddfdf201aa5caad17db70f4857b21cc230fbf","schema_fingerprint":"4aa3821a28b0b7c2400bc59aba4bcc0a76e971dadd19610d3ad38c768e124dc7","schema_version":"edge-lab-recorder.raw.v1","sequence":null,"source":"clob_market_ws"}
{"event_at":"2026-07-28T03:13:09.644000Z","event_fingerprint":"898d411e709dc7d7b73dbe3fc1b445949fb5eb1c7a6d985f7b88ff399641a76c","payload":{"connection_id":"a6b55582af5f430fb37ad02bf0922475","event_at":"2026-07-28T03:13:09.644000Z","event_type":"price_change","frame_hash":"023c4227d88def9b3beb1a598903d97f00e02fa1175e203b196d09500853eef3","frame_index":0,"kind":"data","monotonic_ns":310372967374708,"payload":{"event_type":"price_change","market":"0x779291bef19b6709f61e9764a954aafe9ffae488d50ae674aabdcb4f248006d5","price_changes":[{"asset_id":"8761897749749422724209054078244794145777693856614463256546737399611489089783","best_ask":"0.46","best_bid":"0.45","hash":"5468b1d6061db32f0fdb7394f69e179ca831d6a4","price":"0.18","side":"BUY","size":"258.74"},{"asset_id":"14965588658799411272385430903075831224615961675357217884735713260981483529984","best_ask":"0.55","best_bid":"0.54","hash":"7c7fca74957c7798df8bd044e23d10fdde6beff4","price":"0.82","side":"SELL","size":"258.74"}],"timestamp":"1785208389644"},"payload_hash":"fa6e6346778ee4e5644af6f56b063bd2b6c90b9ccf4e486290394b31e03b7c9d","raw_frame":"{\"market\":\"0x779291bef19b6709f61e9764a954aafe9ffae488d50ae674aabdcb4f248006d5\", \"price_changes\":[{\"asset_id\":\"8761897749749422724209054078244794145777693856614463256546737399611489089783\", \"price\":\"0.18\", \"size\":\"258.74\", \"side\":\"BUY\", \"hash\":\"5468b1d6061db32f0fdb7394f69e179ca831d6a4\", \"best_bid\":\"0.45\", \"best_ask\":\"0.46\"}, {\"asset_id\":\"14965588658799411272385430903075831224615961675357217884735713260981483529984\", \"price\":\"0.82\", \"size\":\"258.74\", \"side\":\"SELL\", \"hash\":\"7c7fca74957c7798df8bd044e23d10fdde6beff4\", \"best_bid\":\"0.54\", \"best_ask\":\"0.55\"}], \"timestamp\":\"1785208389644\", \"event_type\":\"price_change\"}","received_at":"2026-07-28T03:13:09.932411Z","schema_version":"clob-market-ws.price_change.v1","sequence":null,"server_hash":null,"server_timestamp":"1785208389644","session_id":"3e519d9098404c15b234d96025eb1a2b","source":"clob_market_ws"},"received_at":"2026-07-28T03:13:09.932411Z","record_id":"804da4d394b551b42cb421ea459ada3e7b575d9cb49a4cca59253d0fd31dff70","schema_fingerprint":"4aa3821a28b0b7c2400bc59aba4bcc0a76e971dadd19610d3ad38c768e124dc7","schema_version":"edge-lab-recorder.raw.v1","sequence":null,"source":"clob_market_ws"}
{"event_at":"2026-07-28T03:13:09.644000Z","event_fingerprint":"56eb0c61e9fb6b99d1dff59848bf50045d0ff5eadecacb104fc695eed1fd920f","payload":{"connection_id":"a6b55582af5f430fb37ad02bf0922475","event_at":"2026-07-28T03:13:09.644000Z","event_type":"price_change","frame_hash":"8c74a059cace77de3cd9fe243f3d3d9d72e57c6d56b8ebc76186907dee0651ce","frame_index":0,"kind":"data","monotonic_ns":310372968940833,"payload":{"event_type":"price_change","market":"0x779291bef19b6709f61e9764a954aafe9ffae488d50ae674aabdcb4f248006d5","price_changes":[{"asset_id":"14965588658799411272385430903075831224615961675357217884735713260981483529984","best_ask":"0.55","best_bid":"0.54","hash":"b34da5df7c72846fd8828a2fce61403a0c892010","price":"0.46","side":"BUY","size":"88"},{"asset_id":"8761897749749422724209054078244794145777693856614463256546737399611489089783","best_ask":"0.46","best_bid":"0.45","hash":"1536b9251cb9922005b1402026e0442112d3a953","price":"0.54","side":"SELL","size":"88"}],"timestamp":"1785208389644"},"payload_hash":"5a84927a90fa39ab933f94b4b10b01926bda921081809ba536866d0ec530aceb","raw_frame":"{\"market\":\"0x779291bef19b6709f61e9764a954aafe9ffae488d50ae674aabdcb4f248006d5\", \"price_changes\":[{\"asset_id\":\"14965588658799411272385430903075831224615961675357217884735713260981483529984\", \"price\":\"0.46\", \"size\":\"88\", \"side\":\"BUY\", \"hash\":\"b34da5df7c72846fd8828a2fce61403a0c892010\", \"best_bid\":\"0.54\", \"best_ask\":\"0.55\"}, {\"asset_id\":\"8761897749749422724209054078244794145777693856614463256546737399611489089783\", \"price\":\"0.54\", \"size\":\"88\", \"side\":\"SELL\", \"hash\":\"1536b9251cb9922005b1402026e0442112d3a953\", \"best_bid\":\"0.45\", \"best_ask\":\"0.46\"}], \"timestamp\":\"1785208389644\", \"event_type\":\"price_change\"}","received_at":"2026-07-28T03:13:09.933976Z","schema_version":"clob-market-ws.price_change.v1","sequence":null,"server_hash":null,"server_timestamp":"1785208389644","session_id":"3e519d9098404c15b234d96025eb1a2b","source":"clob_market_ws"},"received_at":"2026-07-28T03:13:09.933976Z","record_id":"61aec0924c41cc1c971e17d92760cbde895f2e9b45bbcb4f0b5b800d84527956","schema_fingerprint":"4aa3821a28b0b7c2400bc59aba4bcc0a76e971dadd19610d3ad38c768e124dc7","schema_version":"edge-lab-recorder.raw.v1","sequence":null,"source":"clob_market_ws"}
{"event_at":"2026-07-28T03:13:09.645000Z","event_fingerprint":"962c9e15e63e134c159a0dfafc1fec39b4eb5ec6d2c7ca51dc4deebe1558cc51","payload":{"connection_id":"a6b55582af5f430fb37ad02bf0922475","event_at":"2026-07-28T03:13:09.645000Z","event_type":"price_change","frame_hash":"77c437fb89f4d5841fe11faf18fe0c0208765c85c78e3d3b103961ceff94d58e","frame_index":0,"kind":"data","monotonic_ns":310372970515541,"payload":{"event_type":"price_change","market":"0x779291bef19b6709f61e9764a954aafe9ffae488d50ae674aabdcb4f248006d5","price_changes":[{"asset_id":"14965588658799411272385430903075831224615961675357217884735713260981483529984","best_ask":"0.55","best_bid":"0.54","hash":"e7313b578fed71c55fed477f332a0ecf4ce47792","price":"0.39","side":"BUY","size":"86"},{"asset_id":"8761897749749422724209054078244794145777693856614463256546737399611489089783","best_ask":"0.46","best_bid":"0.45","hash":"28db50eadba650330c9137ed55a34412f61a6263","price":"0.61","side":"SELL","size":"86"}],"timestamp":"1785208389645"},"payload_hash":"d317ccc18f3a08de480960e9b07466e04c68e42b6d92ecddf867edc6ae13ce5c","raw_frame":"{\"market\":\"0x779291bef19b6709f61e9764a954aafe9ffae488d50ae674aabdcb4f248006d5\", \"price_changes\":[{\"asset_id\":\"14965588658799411272385430903075831224615961675357217884735713260981483529984\", \"price\":\"0.39\", \"size\":\"86\", \"side\":\"BUY\", \"hash\":\"e7313b578fed71c55fed477f332a0ecf4ce47792\", \"best_bid\":\"0.54\", \"best_ask\":\"0.55\"}, {\"asset_id\":\"8761897749749422724209054078244794145777693856614463256546737399611489089783\", \"price\":\"0.61\", \"size\":\"86\", \"side\":\"SELL\", \"hash\":\"28db50eadba650330c9137ed55a34412f61a6263\", \"best_bid\":\"0.45\", \"best_ask\":\"0.46\"}], \"timestamp\":\"1785208389645\", \"event_type\":\"price_change\"}","received_at":"2026-07-28T03:13:09.935552Z","schema_version":"clob-market-ws.price_change.v1","sequence":null,"server_hash":null,"server_timestamp":"1785208389645","session_id":"3e519d9098404c15b234d96025eb1a2b","source":"clob_market_ws"},"received_at":"2026-07-28T03:13:09.935552Z","record_id":"ebdd07e2354cbc447fe45b7b50304c6e1bcdbc330a07b8088c090778762acbd8","schema_fingerprint":"4aa3821a28b0b7c2400bc59aba4bcc0a76e971dadd19610d3ad38c768e124dc7","schema_version":"edge-lab-recorder.raw.v1","sequence":null,"source":"clob_market_ws"}
{"event_at":"2026-07-28T03:13:09.646000Z","event_fingerprint":"be0b84327c92e379ca7863ba13debd73588ba2a77186280fce1b564082bf3122","payload":{"connection_id":"a6b55582af5f430fb37ad02bf0922475","event_at":"2026-07-28T03:13:09.646000Z","event_type":"price_change","frame_hash":"9fc8b6c4d625c86fc09d4b1eb305f36bbfd5cd6808574b3a51820f483ccffdea","frame_index":0,"kind":"data","monotonic_ns":310372972053375,"payload":{"event_type":"price_change","market":"0x779291bef19b6709f61e9764a954aafe9ffae488d50ae674aabdcb4f248006d5","price_changes":[{"asset_id":"14965588658799411272385430903075831224615961675357217884735713260981483529984","best_ask":"0.55","best_bid":"0.54","hash":"9eed970212cb492739feb953a1549dbba90fa263","price":"0.54","side":"BUY","size":"53.4"},{"asset_id":"8761897749749422724209054078244794145777693856614463256546737399611489089783","best_ask":"0.46","best_bid":"0.45","hash":"6bb643550d44002da1222f4d513b4d9401911340","price":"0.46","side":"SELL","size":"53.4"}],"timestamp":"1785208389646"},"payload_hash":"72410baccea075675a8c38768d33584491cd26ff29099211f9619a5911a3c441","raw_frame":"{\"market\":\"0x779291bef19b6709f61e9764a954aafe9ffae488d50ae674aabdcb4f248006d5\", \"price_changes\":[{\"asset_id\":\"14965588658799411272385430903075831224615961675357217884735713260981483529984\", \"price\":\"0.54\", \"size\":\"53.4\", \"side\":\"BUY\", \"hash\":\"9eed970212cb492739feb953a1549dbba90fa263\", \"best_bid\":\"0.54\", \"best_ask\":\"0.55\"}, {\"asset_id\":\"8761897749749422724209054078244794145777693856614463256546737399611489089783\", \"price\":\"0.46\", \"size\":\"53.4\", \"side\":\"SELL\", \"hash\":\"6bb643550d44002da1222f4d513b4d9401911340\", \"best_bid\":\"0.45\", \"best_ask\":\"0.46\"}], \"timestamp\":\"1785208389646\", \"event_type\":\"price_change\"}","received_at":"2026-07-28T03:13:09.937090Z","schema_version":"clob-market-ws.price_change.v1","sequence":null,"server_hash":null,"server_timestamp":"1785208389646","session_id":"3e519d9098404c15b234d96025eb1a2b","source":"clob_market_ws"},"received_at":"2026-07-28T03:13:09.937090Z","record_id":"d437e1d83de844d4b18457c6777b990251a8d80ecaeeb7119843183e3d05cf49","schema_fingerprint":"4aa3821a28b0b7c2400bc59aba4bcc0a76e971dadd19610d3ad38c768e124dc7","schema_version":"edge-lab-recorder.raw.v1","sequence":null,"source":"clob_market_ws"}
{"event_at":"2026-07-28T03:13:09.647000Z","event_fingerprint":"2da81d8b8360d3f92148972853e781561acb58b3bc6c7cbf371119ef6281298a","payload":{"connection_id":"a6b55582af5f430fb37ad02bf0922475","event_at":"2026-07-28T03:13:09.647000Z","event_type":"price_change","frame_hash":"5b47ae828e568a9fc1c704f1282489f63600e518a94ed3c9dcbe4f14cac77f6d","frame_index":0,"kind":"data","monotonic_ns":310372973569500,"payload":{"event_type":"price_change","market":"0x779291bef19b6709f61e9764a954aafe9ffae488d50ae674aabdcb4f248006d5","price_changes":[{"asset_id":"14965588658799411272385430903075831224615961675357217884735713260981483529984","best_ask":"0.55","best_bid":"0.54","hash":"4e7a76c88bfc3cf9aa264a01a2d1d0fb9b065133","price":"0.52","side":"BUY","size":"59"},{"asset_id":"8761897749749422724209054078244794145777693856614463256546737399611489089783","best_ask":"0.46","best_bid":"0.45","hash":"937e4a27aa6848000a12a38357476655ce1b5c82","price":"0.48","side":"SELL","size":"59"}],"timestamp":"1785208389647"},"payload_hash":"4254ca9cca189c683e24bb53e822bde72216af9bca9ff3fda7c44c159a9f7dcd","raw_frame":"{\"market\":\"0x779291bef19b6709f61e9764a954aafe9ffae488d50ae674aabdcb4f248006d5\", \"price_changes\":[{\"asset_id\":\"14965588658799411272385430903075831224615961675357217884735713260981483529984\", \"price\":\"0.52\", \"size\":\"59\", \"side\":\"BUY\", \"hash\":\"4e7a76c88bfc3cf9aa264a01a2d1d0fb9b065133\", \"best_bid\":\"0.54\", \"best_ask\":\"0.55\"}, {\"asset_id\":\"8761897749749422724209054078244794145777693856614463256546737399611489089783\", \"price\":\"0.48\", \"size\":\"59\", \"side\":\"SELL\", \"hash\":\"937e4a27aa6848000a12a38357476655ce1b5c82\", \"best_bid\":\"0.45\", \"best_ask\":\"0.46\"}], \"timestamp\":\"1785208389647\", \"event_type\":\"price_change\"}","received_at":"2026-07-28T03:13:09.938606Z","schema_version":"clob-market-ws.price_change.v1","sequence":null,"server_hash":null,"server_timestamp":"1785208389647","session_id":"3e519d9098404c15b234d96025eb1a2b","source":"clob_market_ws"},"received_at":"2026-07-28T03:13:09.938606Z","record_id":"f08279770e9a5ed3cba1f7a5b79a5472c02fc7f4ab164e06e674db48dabb4918","schema_fingerprint":"4aa3821a28b0b7c2400bc59aba4bcc0a76e971dadd19610d3ad38c768e124dc7","schema_version":"edge-lab-recorder.raw.v1","sequence":null,"source":"clob_market_ws"}
{"event_at":"2026-07-28T03:13:09.648000Z","event_fingerprint":"93e4979d5d51debc7273fd5c6d3f0430858447fcd290b054b46efdd64ab88d35","payload":{"connection_id":"a6b55582af5f430fb37ad02bf0922475","event_at":"2026-07-28T03:13:09.648000Z","event_type":"price_change","frame_hash":"e8ae7c347b8ddeee3637cc547327bf80634fc98e756fc486823f7df0a6e6e676","frame_index":0,"kind":"data","monotonic_ns":310372976218041,"payload":{"event_type":"price_change","market":"0x779291bef19b6709f61e9764a954aafe9ffae488d50ae674aabdcb4f248006d5","price_changes":[{"asset_id":"8761897749749422724209054078244794145777693856614463256546737399611489089783","best_ask":"0.46","best_bid":"0.45","hash":"8486afe7f8468164a21f61e31fabb84fd4efdfe2","price":"0.35","side":"BUY","size":"97"},{"asset_id":"14965588658799411272385430903075831224615961675357217884735713260981483529984","best_ask":"0.55","best_bid":"0.54","hash":"fa4bfdbd69e32c14e6a8c8eec6ec0abc2fa718e8","price":"0.65","side":"SELL","size":"97"}],"timestamp":"1785208389648"},"payload_hash":"59c4895c48721b66319c7c740c552b57b15a5bf9d8f580ccea968841cd6a677a","raw_frame":"{\"market\":\"0x779291bef19b6709f61e9764a954aafe9ffae488d50ae674aabdcb4f248006d5\", \"price_changes\":[{\"asset_id\":\"8761897749749422724209054078244794145777693856614463256546737399611489089783\", \"price\":\"0.35\", \"size\":\"97\", \"side\":\"BUY\", \"hash\":\"8486afe7f8468164a21f61e31fabb84fd4efdfe2\", \"best_bid\":\"0.45\", \"best_ask\":\"0.46\"}, {\"asset_id\":\"14965588658799411272385430903075831224615961675357217884735713260981483529984\", \"price\":\"0.65\", \"size\":\"97\", \"side\":\"SELL\", \"hash\":\"fa4bfdbd69e32c14e6a8c8eec6ec0abc2fa718e8\", \"best_bid\":\"0.54\", \"best_ask\":\"0.55\"}], \"timestamp\":\"1785208389648\", \"event_type\":\"price_change\"}","received_at":"2026-07-28T03:13:09.941253Z","schema_version":"clob-market-ws.price_change.v1","sequence":null,"server_hash":null,"server_timestamp":"1785208389648","session_id":"3e519d9098404c15b234d96025eb1a2b","source":"clob_market_ws"},"received_at":"2026-07-28T03:13:09.941253Z","record_id":"3d3c2f193938b8414194d5c2c89ead915c186fd046bf1d2c927cb6b058d3d53c","schema_fingerprint":"4aa3821a28b0b7c2400bc59aba4bcc0a76e971dadd19610d3ad38c768e124dc7","schema_version":"edge-lab-recorder.raw.v1","sequence":null,"source":"clob_market_ws"}
{"event_at":"2026-07-28T03:13:09.648000Z","event_fingerprint":"224e95bf702af52305bf7e0d02d491e15f924641a4af539cb8a3b70de4af8e7d","payload":{"connection_id":"a6b55582af5f430fb37ad02bf0922475","event_at":"2026-07-28T03:13:09.648000Z","event_type":"price_change","frame_hash":"85469909502133efc15df68d37de8ceb81336c59de5bbb484575af68d24e4e62","frame_index":0,"kind":"data","monotonic_ns":310372977828291,"payload":{"event_type":"price_change","market":"0x779291bef19b6709f61e9764a954aafe9ffae488d50ae674aabdcb4f248006d5","price_changes":[{"asset_id":"8761897749749422724209054078244794145777693856614463256546737399611489089783","best_ask":"0.46","best_bid":"0.45","hash":"e5b417b05352b15eea80715c6e9af4db98b2420e","price":"0.53","side":"SELL","size":"78"},{"asset_id":"14965588658799411272385430903075831224615961675357217884735713260981483529984","best_ask":"0.55","best_bid":"0.54","hash":"db5133797a008c853e0de954214042ce12d00aef","price":"0.47","side":"BUY","size":"78"}],"timestamp":"1785208389648"},"payload_hash":"3bb0a350c4185c632cec340d4abd03380d1b0725fa9ff75519c12319256cf539","raw_frame":"{\"market\":\"0x779291bef19b6709f61e9764a954aafe9ffae488d50ae674aabdcb4f248006d5\", \"price_changes\":[{\"asset_id\":\"8761897749749422724209054078244794145777693856614463256546737399611489089783\", \"price\":\"0.53\", \"size\":\"78\", \"side\":\"SELL\", \"hash\":\"e5b417b05352b15eea80715c6e9af4db98b2420e\", \"best_bid\":\"0.45\", \"best_ask\":\"0.46\"}, {\"asset_id\":\"14965588658799411272385430903075831224615961675357217884735713260981483529984\", \"price\":\"0.47\", \"size\":\"78\", \"side\":\"BUY\", \"hash\":\"db5133797a008c853e0de954214042ce12d00aef\", \"best_bid\":\"0.54\", \"best_ask\":\"0.55\"}], \"timestamp\":\"1785208389648\", \"event_type\":\"price_change\"}","received_at":"2026-07-28T03:13:09.942864Z","schema_version":"clob-market-ws.price_change.v1","sequence":null,"server_hash":null,"server_timestamp":"1785208389648","session_id":"3e519d9098404c15b234d96025eb1a2b","source":"clob_market_ws"},"received_at":"2026-07-28T03:13:09.942864Z","record_id":"344ac6e45bceb326eec88fabec85aad266fedb843a365c587f1753456b522a30","schema_fingerprint":"4aa3821a28b0b7c2400bc59aba4bcc0a76e971dadd19610d3ad38c768e124dc7","schema_version":"edge-lab-recorder.raw.v1","sequence":null,"source":"clob_market_ws"}
{"event_at":"2026-07-28T03:13:09.649000Z","event_fingerprint":"56a4d63eaed87ec7944e102862fb6043d0578cd314ca951be6ac46048d02eb9a","payload":{"connection_id":"a6b55582af5f430fb37ad02bf0922475","event_at":"2026-07-28T03:13:09.649000Z","event_type":"price_change","frame_hash":"d9333e1a7f4c89f17736c2868e5aa3a004b0789298c03984b441c63712be92e6","frame_index":0,"kind":"data","monotonic_ns":310372979416625,"payload":{"event_type":"price_change","market":"0x779291bef19b6709f61e9764a954aafe9ffae488d50ae674aabdcb4f248006d5","price_changes":[{"asset_id":"14965588658799411272385430903075831224615961675357217884735713260981483529984","best_ask":"0.55","best_bid":"0.54","hash":"8cb6284aa7c4ea60c01bac8fed7ea46c17cc47e2","price":"0.55","side":"SELL","size":"35"},{"asset_id":"8761897749749422724209054078244794145777693856614463256546737399611489089783","best_ask":"0.46","best_bid":"0.45","hash":"bdfcbb9e1ed0bf66d4be86d08d0ef96ca72ae818","price":"0.45","side":"BUY","size":"35"}],"timestamp":"1785208389649"},"payload_hash":"6ecd618825f5f8b22db7ba0617c6f48f7ed237d235b338250f63a30f50f6f093","raw_frame":"{\"market\":\"0x779291bef19b6709f61e9764a954aafe9ffae488d50ae674aabdcb4f248006d5\", \"price_changes\":[{\"asset_id\":\"14965588658799411272385430903075831224615961675357217884735713260981483529984\", \"price\":\"0.55\", \"size\":\"35\", \"side\":\"SELL\", \"hash\":\"8cb6284aa7c4ea60c01bac8fed7ea46c17cc47e2\", \"best_bid\":\"0.54\", \"best_ask\":\"0.55\"}, {\"asset_id\":\"8761897749749422724209054078244794145777693856614463256546737399611489089783\", \"price\":\"0.45\", \"size\":\"35\", \"side\":\"BUY\", \"hash\":\"bdfcbb9e1ed0bf66d4be86d08d0ef96ca72ae818\", \"best_bid\":\"0.45\", \"best_ask\":\"0.46\"}], \"timestamp\":\"1785208389649\", \"event_type\":\"price_change\"}","received_at":"2026-07-28T03:13:09.944452Z","schema_version":"clob-market-ws.price_change.v1","sequence":null,"server_hash":null,"server_timestamp":"1785208389649","session_id":"3e519d9098404c15b234d96025eb1a2b","source":"clob_market_ws"},"received_at":"2026-07-28T03:13:09.944452Z","record_id":"6b39684572b33ab99b3d142b13d9e9c9fc5239abb90668e54c599f6bedfc60d6","schema_fingerprint":"4aa3821a28b0b7c2400bc59aba4bcc0a76e971dadd19610d3ad38c768e124dc7","schema_version":"edge-lab-recorder.raw.v1","sequence":null,"source":"clob_market_ws"}
{"event_at":"2026-07-28T03:13:09.650000Z","event_fingerprint":"37b7ba3c4e7d54113d2d40ca770573d5083eb72164693f86ef06da05c885e0d1","payload":{"connection_id":"a6b55582af5f430fb37ad02bf0922475","event_at":"2026-07-28T03:13:09.650000Z","event_type":"price_change","frame_hash":"e1fd82d2be1041a0096af1628f739f905c58b3047beb9a0f4fc7b2ffb7e3c943","frame_index":0,"kind":"data","monotonic_ns":310372980998958,"payload":{"event_type":"price_change","market":"0x779291bef19b6709f61e9764a954aafe9ffae488d50ae674aabdcb4f248006d5","price_changes":[{"asset_id":"8761897749749422724209054078244794145777693856614463256546737399611489089783","best_ask":"0.46","best_bid":"0.45","hash":"6e830fbc6e5b7dcb778ef2016b093623b389f4e8","price":"0.18","side":"BUY","size":"73.56"},{"asset_id":"14965588658799411272385430903075831224615961675357217884735713260981483529984","best_ask":"0.55","best_bid":"0.54","hash":"2adf9d0875d502d5bc2dbc791cea6fb7ec80068c","price":"0.82","side":"SELL","size":"73.56"}],"timestamp":"1785208389650"},"payload_hash":"78a52c03a43451a562da45548b98a6d40ef30679e32ab192f826cc59a218602c","raw_frame":"{\"market\":\"0x779291bef19b6709f61e9764a954aafe9ffae488d50ae674aabdcb4f248006d5\", \"price_changes\":[{\"asset_id\":\"8761897749749422724209054078244794145777693856614463256546737399611489089783\", \"price\":\"0.18\", \"size\":\"73.56\", \"side\":\"BUY\", \"hash\":\"6e830fbc6e5b7dcb778ef2016b093623b389f4e8\", \"best_bid\":\"0.45\", \"best_ask\":\"0.46\"}, {\"asset_id\":\"14965588658799411272385430903075831224615961675357217884735713260981483529984\", \"price\":\"0.82\", \"size\":\"73.56\", \"side\":\"SELL\", \"hash\":\"2adf9d0875d502d5bc2dbc791cea6fb7ec80068c\", \"best_bid\":\"0.54\", \"best_ask\":\"0.55\"}], \"timestamp\":\"1785208389650\", \"event_type\":\"price_change\"}","received_at":"2026-07-28T03:13:09.946036Z","schema_version":"clob-market-ws.price_change.v1","sequence":null,"server_hash":null,"server_timestamp":"1785208389650","session_id":"3e519d9098404c15b234d96025eb1a2b","source":"clob_market_ws"},"received_at":"2026-07-28T03:13:09.946036Z","record_id":"fd538f5539f66aed3675c22d841c8d0279a10790342923bf89331e7dc3c187d1","schema_fingerprint":"4aa3821a28b0b7c2400bc59aba4bcc0a76e971dadd19610d3ad38c768e124dc7","schema_version":"edge-lab-recorder.raw.v1","sequence":null,"source":"clob_market_ws"}
{"event_at":"2026-07-28T03:13:09.650000Z","event_fingerprint":"1ed7a45aac160d00e68ba4b19d2a52e0047b8d3972194689005e0cf3e627e6e5","payload":{"connection_id":"a6b55582af5f430fb37ad02bf0922475","event_at":"2026-07-28T03:13:09.650000Z","event_type":"price_change","frame_hash":"f277a4945e2a5c867c45d36966663ebb8ed63ff72597eac99d77ab084e2b09d1","frame_index":0,"kind":"data","monotonic_ns":310372982526291,"payload":{"event_type":"price_change","market":"0x779291bef19b6709f61e9764a954aafe9ffae488d50ae674aabdcb4f248006d5","price_changes":[{"asset_id":"8761897749749422724209054078244794145777693856614463256546737399611489089783","best_ask":"0.46","best_bid":"0.45","hash":"3094f16c1e5a049848582b6b2d88662785271607","price":"0.76","side":"SELL","size":"37"},{"asset_id":"14965588658799411272385430903075831224615961675357217884735713260981483529984","best_ask":"0.55","best_bid":"0.54","hash":"626bce89a2e1498cb484021c6741948e0f6c7095","price":"0.24","side":"BUY","size":"37"}],"timestamp":"1785208389650"},"payload_hash":"a00eeac23f7d6008020f95c4d9060a7db487277651b7cd89efb0e7e3f0581e32","raw_frame":"{\"market\":\"0x779291bef19b6709f61e9764a954aafe9ffae488d50ae674aabdcb4f248006d5\", \"price_changes\":[{\"asset_id\":\"8761897749749422724209054078244794145777693856614463256546737399611489089783\", \"price\":\"0.76\", \"size\":\"37\", \"side\":\"SELL\", \"hash\":\"3094f16c1e5a049848582b6b2d88662785271607\", \"best_bid\":\"0.45\", \"best_ask\":\"0.46\"}, {\"asset_id\":\"14965588658799411272385430903075831224615961675357217884735713260981483529984\", \"price\":\"0.24\", \"size\":\"37\", \"side\":\"BUY\", \"hash\":\"626bce89a2e1498cb484021c6741948e0f6c7095\", \"best_bid\":\"0.54\", \"best_ask\":\"0.55\"}], \"timestamp\":\"1785208389650\", \"event_type\":\"price_change\"}","received_at":"2026-07-28T03:13:09.947563Z","schema_version":"clob-market-ws.price_change.v1","sequence":null,"server_hash":null,"server_timestamp":"1785208389650","session_id":"3e519d9098404c15b234d96025eb1a2b","source":"clob_market_ws"},"received_at":"2026-07-28T03:13:09.947563Z","record_id":"f820a741f105bd6da614f520d2bc38c45ee9f251b6f7a2316a4bd496a0b076b8","schema_fingerprint":"4aa3821a28b0b7c2400bc59aba4bcc0a76e971dadd19610d3ad38c768e124dc7","schema_version":"edge-lab-recorder.raw.v1","sequence":null,"source":"clob_market_ws"}
{"event_at":"2026-07-28T03:13:09.650000Z","event_fingerprint":"3f14323fc297cfdc6c098b047b1c5378ca5760e34aa4010ef4f8c40547a9b532","payload":{"connection_id":"a6b55582af5f430fb37ad02bf0922475","event_at":"2026-07-28T03:13:09.650000Z","event_type":"price_change","frame_hash":"ec82ed89e6468027d51de1e27a6f1cee14bc31ca5287c5f51253ae839c171fdd","frame_index":0,"kind":"data","monotonic_ns":310372984068083,"payload":{"event_type":"price_change","market":"0x779291bef19b6709f61e9764a954aafe9ffae488d50ae674aabdcb4f248006d5","price_changes":[{"asset_id":"8761897749749422724209054078244794145777693856614463256546737399611489089783","best_ask":"0.46","best_bid":"0.45","hash":"c04cbeeaeca168c59456a44366b18e3ecf79fd69","price":"0.45","side":"BUY","size":"79"},{"asset_id":"14965588658799411272385430903075831224615961675357217884735713260981483529984","best_ask":"0.55","best_bid":"0.54","hash":"e200994c73f4207ea7b332be9c780598ce82abc0","price":"0.55","side":"SELL","size":"79"}],"timestamp":"1785208389650"},"payload_hash":"ed4156156dc8b774ff0276d853dde367367b0903ce850401e8b27edd6cadbd0d","raw_frame":"{\"market\":\"0x779291bef19b6709f61e9764a954aafe9ffae488d50ae674aabdcb4f248006d5\", \"price_changes\":[{\"asset_id\":\"8761897749749422724209054078244794145777693856614463256546737399611489089783\", \"price\":\"0.45\", \"size\":\"79\", \"side\":\"BUY\", \"hash\":\"c04cbeeaeca168c59456a44366b18e3ecf79fd69\", \"best_bid\":\"0.45\", \"best_ask\":\"0.46\"}, {\"asset_id\":\"14965588658799411272385430903075831224615961675357217884735713260981483529984\", \"price\":\"0.55\", \"size\":\"79\", \"side\":\"SELL\", \"hash\":\"e200994c73f4207ea7b332be9c780598ce82abc0\", \"best_bid\":\"0.54\", \"best_ask\":\"0.55\"}], \"timestamp\":\"1785208389650\", \"event_type\":\"price_change\"}","received_at":"2026-07-28T03:13:09.949105Z","schema_version":"clob-market-ws.price_change.v1","sequence":null,"server_hash":null,"server_timestamp":"1785208389650","session_id":"3e519d9098404c15b234d96025eb1a2b","source":"clob_market_ws"},"received_at":"2026-07-28T03:13:09.949105Z","record_id":"af2f2f5d7498ce50d7b4f4e5386500683b83bd0718cf0d0eb2de6c4ffd80499a","schema_fingerprint":"4aa3821a28b0b7c2400bc59aba4bcc0a76e971dadd19610d3ad38c768e124dc7","schema_version":"edge-lab-recorder.raw.v1","sequence":null,"source":"clob_market_ws"}
{"event_at":"2026-07-28T03:13:09.651000Z","event_fingerprint":"28ad6f93caf7a0916115c8695b26172306b5857f6897e6e22fa01a32c44c6367","payload":{"connection_id":"a6b55582af5f430fb37ad02bf0922475","event_at":"2026-07-28T03:13:09.651000Z","event_type":"price_change","frame_hash":"75e73861f62daf5ca0736263d9fce4e22fed163c1a5ebd1bcee290322029ce5e","frame_index":0,"kind":"data","monotonic_ns":310372985637125,"payload":{"event_type":"price_change","market":"0x779291bef19b6709f61e9764a954aafe9ffae488d50ae674aabdcb4f248006d5","price_changes":[{"asset_id":"8761897749749422724209054078244794145777693856614463256546737399611489089783","best_ask":"0.46","best_bid":"0.45","hash":"065f88e14e2989593d3a84b2cfcff875de20b05b","price":"0.41","side":"BUY","size":"89"},{"asset_id":"14965588658799411272385430903075831224615961675357217884735713260981483529984","best_ask":"0.55","best_bid":"0.54","hash":"970c7f1f8e2a94ac55739f25b3511fe3a67e6e40","price":"0.59","side":"SELL","size":"89"}],"timestamp":"1785208389651"},"payload_hash":"38aa81ca5d17fdca55d42909f98d89b6cc588df3682f32a3213af2bb3146ed44","raw_frame":"{\"market\":\"0x779291bef19b6709f61e9764a954aafe9ffae488d50ae674aabdcb4f248006d5\", \"price_changes\":[{\"asset_id\":\"8761897749749422724209054078244794145777693856614463256546737399611489089783\", \"price\":\"0.41\", \"size\":\"89\", \"side\":\"BUY\", \"hash\":\"065f88e14e2989593d3a84b2cfcff875de20b05b\", \"best_bid\":\"0.45\", \"best_ask\":\"0.46\"}, {\"asset_id\":\"14965588658799411272385430903075831224615961675357217884735713260981483529984\", \"price\":\"0.59\", \"size\":\"89\", \"side\":\"SELL\", \"hash\":\"970c7f1f8e2a94ac55739f25b3511fe3a67e6e40\", \"best_bid\":\"0.54\", \"best_ask\":\"0.55\"}], \"timestamp\":\"1785208389651\", \"event_type\":\"price_change\"}","received_at":"2026-07-28T03:13:09.950667Z","schema_version":"clob-market-ws.price_change.v1","sequence":null,"server_hash":null,"server_timestamp":"1785208389651","session_id":"3e519d9098404c15b234d96025eb1a2b","source":"clob_market_ws"},"received_at":"2026-07-28T03:13:09.950667Z","record_id":"b07e24e4957b37ec5be06f0e53319221760901142f179e10761119b4e91d493c","schema_fingerprint":"4aa3821a28b0b7c2400bc59aba4bcc0a76e971dadd19610d3ad38c768e124dc7","schema_version":"edge-lab-recorder.raw.v1","sequence":null,"source":"clob_market_ws"}
{"event_at":"2026-07-28T03:13:09.652000Z","event_fingerprint":"edab06db093d93139eeb7cd42e75ac3c1af973e1e5c98bc36eb596e3efb7f216","payload":{"connection_id":"a6b55582af5f430fb37ad02bf0922475","event_at":"2026-07-28T03:13:09.652000Z","event_type":"price_change","frame_hash":"38c5699126b3dec35699e01e369c81f55057adaa46701880d7859d8d623d0672","frame_index":0,"kind":"data","monotonic_ns":310372987356708,"payload":{"event_type":"price_change","market":"0x779291bef19b6709f61e9764a954aafe9ffae488d50ae674aabdcb4f248006d5","price_changes":[{"asset_id":"14965588658799411272385430903075831224615961675357217884735713260981483529984","best_ask":"0.55","best_bid":"0.54","hash":"925d1282f4bcca647d93b15c7bcca2e610c5356e","price":"0.36","side":"BUY","size":"102"},{"asset_id":"8761897749749422724209054078244794145777693856614463256546737399611489089783","best_ask":"0.46","best_bid":"0.45","hash":"3928b1f77b799e483a60b7d6be722f253ee45e11","price":"0.64","side":"SELL","size":"102"}],"timestamp":"1785208389652"},"payload_hash":"fb63147693437875d8244450a85377c4382dc7444ffa06c750c5a2753ce16c39","raw_frame":"{\"market\":\"0x779291bef19b6709f61e9764a954aafe9ffae488d50ae674aabdcb4f248006d5\", \"price_changes\":[{\"asset_id\":\"14965588658799411272385430903075831224615961675357217884735713260981483529984\", \"price\":\"0.36\", \"size\":\"102\", \"side\":\"BUY\", \"hash\":\"925d1282f4bcca647d93b15c7bcca2e610c5356e\", \"best_bid\":\"0.54\", \"best_ask\":\"0.55\"}, {\"asset_id\":\"8761897749749422724209054078244794145777693856614463256546737399611489089783\", \"price\":\"0.64\", \"size\":\"102\", \"side\":\"SELL\", \"hash\":\"3928b1f77b799e483a60b7d6be722f253ee45e11\", \"best_bid\":\"0.45\", \"best_ask\":\"0.46\"}], \"timestamp\":\"1785208389652\", \"event_type\":\"price_change\"}","received_at":"2026-07-28T03:13:09.952393Z","schema_version":"clob-market-ws.price_change.v1","sequence":null,"server_hash":null,"server_timestamp":"1785208389652","session_id":"3e519d9098404c15b234d96025eb1a2b","source":"clob_market_ws"},"received_at":"2026-07-28T03:13:09.952393Z","record_id":"90ad861278d2248c0a244564c138c65fffecec9b85d8074a3f7297d6898b5283","schema_fingerprint":"4aa3821a28b0b7c2400bc59aba4bcc0a76e971dadd19610d3ad38c768e124dc7","schema_version":"edge-lab-recorder.raw.v1","sequence":null,"source":"clob_market_ws"}
{"event_at":"2026-07-28T03:13:09.652000Z","event_fingerprint":"0376e95cd04b8770b6d2785a96a66b24a0ea8cfddd1184735dfd010fc9e274e3","payload":{"connection_id":"a6b55582af5f430fb37ad02bf0922475","event_at":"2026-07-28T03:13:09.652000Z","event_type":"price_change","frame_hash":"4a897fa7c38c35e5f77d4791541e99f1cef0d0d8530010edce04025abb7a7d12","frame_index":0,"kind":"data","monotonic_ns":310372988962291,"payload":{"event_type":"price_change","market":"0x779291bef19b6709f61e9764a954aafe9ffae488d50ae674aabdcb4f248006d5","price_changes":[{"asset_id":"8761897749749422724209054078244794145777693856614463256546737399611489089783","best_ask":"0.46","best_bid":"0.45","hash":"937042ab32dad3f17eee41480d51f378f569d773","price":"0.16","side":"BUY","size":"49"},{"asset_id":"14965588658799411272385430903075831224615961675357217884735713260981483529984","best_ask":"0.55","best_bid":"0.54","hash":"1b4b0702952b847d7b2e2ece59fd64fc12f98374","price":"0.84","side":"SELL","size":"49"}],"timestamp":"1785208389652"},"payload_hash":"4250309fe9a49ed142acbead6012c4bafd7e751536c0ab2ed8f13294a2c55598","raw_frame":"{\"market\":\"0x779291bef19b6709f61e9764a954aafe9ffae488d50ae674aabdcb4f248006d5\", \"price_changes\":[{\"asset_id\":\"8761897749749422724209054078244794145777693856614463256546737399611489089783\", \"price\":\"0.16\", \"size\":\"49\", \"side\":\"BUY\", \"hash\":\"937042ab32dad3f17eee41480d51f378f569d773\", \"best_bid\":\"0.45\", \"best_ask\":\"0.46\"}, {\"asset_id\":\"14965588658799411272385430903075831224615961675357217884735713260981483529984\", \"price\":\"0.84\", \"size\":\"49\", \"side\":\"SELL\", \"hash\":\"1b4b0702952b847d7b2e2ece59fd64fc12f98374\", \"best_bid\":\"0.54\", \"best_ask\":\"0.55\"}], \"timestamp\":\"1785208389652\", \"event_type\":\"price_change\"}","received_at":"2026-07-28T03:13:09.953991Z","schema_version":"clob-market-ws.price_change.v1","sequence":null,"server_hash":null,"server_timestamp":"1785208389652","session_id":"3e519d9098404c15b234d96025eb1a2b","source":"clob_market_ws"},"received_at":"2026-07-28T03:13:09.953991Z","record_id":"b233cdf84053c1d24051fb45aaa570bc3287e43542f70a4dc5957f2ac02d9adb","schema_fingerprint":"4aa3821a28b0b7c2400bc59aba4bcc0a76e971dadd19610d3ad38c768e124dc7","schema_version":"edge-lab-recorder.raw.v1","sequence":null,"source":"clob_market_ws"}
{"event_at":"2026-07-28T03:13:09.652000Z","event_fingerprint":"387e5e5503f366a07e8771b5d175f58f56b6ccecb53a07c912db4fccf29520af","payload":{"connection_id":"a6b55582af5f430fb37ad02bf0922475","event_at":"2026-07-28T03:13:09.652000Z","event_type":"price_change","frame_hash":"ad92e833ccd32fdf6fce0d1cab26450707bf258befded1ed3c95f40b7d901f88","frame_index":0,"kind":"data","monotonic_ns":310372990564500,"payload":{"event_type":"price_change","market":"0x779291bef19b6709f61e9764a954aafe9ffae488d50ae674aabdcb4f248006d5","price_changes":[{"asset_id":"14965588658799411272385430903075831224615961675357217884735713260981483529984","best_ask":"0.55","best_bid":"0.54","hash":"69b450e415d5dc2be7cd5272186874ea488bccc9","price":"0.54","side":"BUY","size":"59.2"},{"asset_id":"8761897749749422724209054078244794145777693856614463256546737399611489089783","best_ask":"0.46","best_bid":"0.45","hash":"191f078ae7d02f106d59895c4f67a8f7108a4d66","price":"0.46","side":"SELL","size":"59.2"}],"timestamp":"1785208389652"},"payload_hash":"4b649c6ac4c6c48e4a55ebebdfb813ff17e5b7f7dfa88b2c3f938964272c1d38","raw_frame":"{\"market\":\"0x779291bef19b6709f61e9764a954aafe9ffae488d50ae674aabdcb4f248006d5\", \"price_changes\":[{\"asset_id\":\"14965588658799411272385430903075831224615961675357217884735713260981483529984\", \"price\":\"0.54\", \"size\":\"59.2\", \"side\":\"BUY\", \"hash\":\"69b450e415d5dc2be7cd5272186874ea488bccc9\", \"best_bid\":\"0.54\", \"best_ask\":\"0.55\"}, {\"asset_id\":\"8761897749749422724209054078244794145777693856614463256546737399611489089783\", \"price\":\"0.46\", \"size\":\"59.2\", \"side\":\"SELL\", \"hash\":\"191f078ae7d02f106d59895c4f67a8f7108a4d66\", \"best_bid\":\"0.45\", \"best_ask\":\"0.46\"}], \"timestamp\":\"1785208389652\", \"event_type\":\"price_change\"}","received_at":"2026-07-28T03:13:09.955601Z","schema_version":"clob-market-ws.price_change.v1","sequence":null,"server_hash":null,"server_timestamp":"1785208389652","session_id":"3e519d9098404c15b234d96025eb1a2b","source":"clob_market_ws"},"received_at":"2026-07-28T03:13:09.955601Z","record_id":"1f0c62e9c4fe57ffdafe84ce9db42f75fb65855cbacf4575b8670397b04513e5","schema_fingerprint":"4aa3821a28b0b7c2400bc59aba4bcc0a76e971dadd19610d3ad38c768e124dc7","schema_version":"edge-lab-recorder.raw.v1","sequence":null,"source":"clob_market_ws"}
{"event_at":"2026-07-28T03:13:09.653000Z","event_fingerprint":"d49356a5cee7fd4bf7ffb9f447272c550346758e84675dd43569f9682f50a9e1","payload":{"connection_id":"a6b55582af5f430fb37ad02bf0922475","event_at":"2026-07-28T03:13:09.653000Z","event_type":"price_change","frame_hash":"3fe3c04ac8f03f48c076789b29e7c0cb3b31a480dfb328d7e42462d144d023e7","frame_index":0,"kind":"data","monotonic_ns":310372994248458,"payload":{"event_type":"price_change","market":"0x779291bef19b6709f61e9764a954aafe9ffae488d50ae674aabdcb4f248006d5","price_changes":[{"asset_id":"8761897749749422724209054078244794145777693856614463256546737399611489089783","best_ask":"0.46","best_bid":"0.45","hash":"eb4d9ff93a2a9c6c9411cb197be8ac0666d06534","price":"0.54","side":"SELL","size":"97"},{"asset_id":"14965588658799411272385430903075831224615961675357217884735713260981483529984","best_ask":"0.55","best_bid":"0.54","hash":"9e0451e203b03802ae7e101e99b5daeba581dc2b","price":"0.46","side":"BUY","size":"97"}],"timestamp":"1785208389653"},"payload_hash":"356ad8b5de0b9eb86feb8161fd0b2f3e09d8cfbc5f95b4725ab1a169925c6914","raw_frame":"{\"market\":\"0x779291bef19b6709f61e9764a954aafe9ffae488d50ae674aabdcb4f248006d5\", \"price_changes\":[{\"asset_id\":\"8761897749749422724209054078244794145777693856614463256546737399611489089783\", \"price\":\"0.54\", \"size\":\"97\", \"side\":\"SELL\", \"hash\":\"eb4d9ff93a2a9c6c9411cb197be8ac0666d06534\", \"best_bid\":\"0.45\", \"best_ask\":\"0.46\"}, {\"asset_id\":\"14965588658799411272385430903075831224615961675357217884735713260981483529984\", \"price\":\"0.46\", \"size\":\"97\", \"side\":\"BUY\", \"hash\":\"9e0451e203b03802ae7e101e99b5daeba581dc2b\", \"best_bid\":\"0.54\", \"best_ask\":\"0.55\"}], \"timestamp\":\"1785208389653\", \"event_type\":\"price_change\"}","received_at":"2026-07-28T03:13:09.959285Z","schema_version":"clob-market-ws.price_change.v1","sequence":null,"server_hash":null,"server_timestamp":"1785208389653","session_id":"3e519d9098404c15b234d96025eb1a2b","source":"clob_market_ws"},"received_at":"2026-07-28T03:13:09.959285Z","record_id":"a80e721714a16767de07c667ae4cb7dd7047f0fd7d2a906ea78fb2764126fe2e","schema_fingerprint":"4aa3821a28b0b7c2400bc59aba4bcc0a76e971dadd19610d3ad38c768e124dc7","schema_version":"edge-lab-recorder.raw.v1","sequence":null,"source":"clob_market_ws"}
{"event_at":"2026-07-28T03:13:09.654000Z","event_fingerprint":"ed3ed68150e08bb3bef11b65a8ccfac101f62f769a84df2ab84e995842672080","payload":{"connection_id":"a6b55582af5f430fb37ad02bf0922475","event_at":"2026-07-28T03:13:09.654000Z","event_type":"price_change","frame_hash":"52a0456afbb267327649ea6deba0e1c785229f6626e3f2351658d894bac6ed76","frame_index":0,"kind":"data","monotonic_ns":310372995809583,"payload":{"event_type":"price_change","market":"0x779291bef19b6709f61e9764a954aafe9ffae488d50ae674aabdcb4f248006d5","price_changes":[{"asset_id":"14965588658799411272385430903075831224615961675357217884735713260981483529984","best_ask":"0.55","best_bid":"0.54","hash":"9d7d75a1621c7107cb8c2f17611a7341b3ee10eb","price":"0.46","side":"BUY","size":"92"},{"asset_id":"8761897749749422724209054078244794145777693856614463256546737399611489089783","best_ask":"0.46","best_bid":"0.45","hash":"db090110b032c3c7bde0181e1799395684fc1e4e","price":"0.54","side":"SELL","size":"92"}],"timestamp":"1785208389654"},"payload_hash":"0d59eb35302d34fbfd93a3a6bef4ffd9f5cbf000e4ff92c9bbd38bd940339802","raw_frame":"{\"market\":\"0x779291bef19b6709f61e9764a954aafe9ffae488d50ae674aabdcb4f248006d5\", \"price_changes\":[{\"asset_id\":\"14965588658799411272385430903075831224615961675357217884735713260981483529984\", \"price\":\"0.46\", \"size\":\"92\", \"side\":\"BUY\", \"hash\":\"9d7d75a1621c7107cb8c2f17611a7341b3ee10eb\", \"best_bid\":\"0.54\", \"best_ask\":\"0.55\"}, {\"asset_id\":\"8761897749749422724209054078244794145777693856614463256546737399611489089783\", \"price\":\"0.54\", \"size\":\"92\", \"side\":\"SELL\", \"hash\":\"db090110b032c3c7bde0181e1799395684fc1e4e\", \"best_bid\":\"0.45\", \"best_ask\":\"0.46\"}], \"timestamp\":\"1785208389654\", \"event_type\":\"price_change\"}","received_at":"2026-07-28T03:13:09.960845Z","schema_version":"clob-market-ws.price_change.v1","sequence":null,"server_hash":null,"server_timestamp":"1785208389654","session_id":"3e519d9098404c15b234d96025eb1a2b","source":"clob_market_ws"},"received_at":"2026-07-28T03:13:09.960845Z","record_id":"d13e67d00c7a059d1aeacffe071329506e1fdbb4c77381d03ed7564f3b747b86","schema_fingerprint":"4aa3821a28b0b7c2400bc59aba4bcc0a76e971dadd19610d3ad38c768e124dc7","schema_version":"edge-lab-recorder.raw.v1","sequence":null,"source":"clob_market_ws"}
{"event_at":"2026-07-28T03:13:09.654000Z","event_fingerprint":"1b7fe723f8071cea5b87429bb3826b62005e168b4f5faa7c6fe4f00da7474deb","payload":{"connection_id":"a6b55582af5f430fb37ad02bf0922475","event_at":"2026-07-28T03:13:09.654000Z","event_type":"price_change","frame_hash":"f619102f05b5a4301982e2804c3c981d910f1e7621c019503ff1497a17299a86","frame_index":0,"kind":"data","monotonic_ns":310372998818083,"payload":{"event_type":"price_change","market":"0x779291bef19b6709f61e9764a954aafe9ffae488d50ae674aabdcb4f248006d5","price_changes":[{"asset_id":"14965588658799411272385430903075831224615961675357217884735713260981483529984","best_ask":"0.55","best_bid":"0.54","hash":"e5f00b5e526b73b321881c6c508505edfd44b5e3","price":"0.35","side":"BUY","size":"101.36"},{"asset_id":"8761897749749422724209054078244794145777693856614463256546737399611489089783","best_ask":"0.46","best_bid":"0.45","hash":"9d97988355fca7ae74b101896ad3a02cb41787e0","price":"0.65","side":"SELL","size":"101.36"}],"timestamp":"1785208389654"},"payload_hash":"a0f444d5a1f2c52405b4870405b7d88f49d1106235e08c49d8be2b53ac483dbc","raw_frame":"{\"market\":\"0x779291bef19b6709f61e9764a954aafe9ffae488d50ae674aabdcb4f248006d5\", \"price_changes\":[{\"asset_id\":\"14965588658799411272385430903075831224615961675357217884735713260981483529984\", \"price\":\"0.35\", \"size\":\"101.36\", \"side\":\"BUY\", \"hash\":\"e5f00b5e526b73b321881c6c508505edfd44b5e3\", \"best_bid\":\"0.54\", \"best_ask\":\"0.55\"}, {\"asset_id\":\"8761897749749422724209054078244794145777693856614463256546737399611489089783\", \"price\":\"0.65\", \"size\":\"101.36\", \"side\":\"SELL\", \"hash\":\"9d97988355fca7ae74b101896ad3a02cb41787e0\", \"best_bid\":\"0.45\", \"best_ask\":\"0.46\"}], \"timestamp\":\"1785208389654\", \"event_type\":\"price_change\"}","received_at":"2026-07-28T03:13:09.963852Z","schema_version":"clob-market-ws.price_change.v1","sequence":null,"server_hash":null,"server_timestamp":"1785208389654","session_id":"3e519d9098404c15b234d96025eb1a2b","source":"clob_market_ws"},"received_at":"2026-07-28T03:13:09.963852Z","record_id":"828d861c4bf62d98f84dd8fac2be8f0436a4e0827b0775c5f65f594df7a00acb","schema_fingerprint":"4aa3821a28b0b7c2400bc59aba4bcc0a76e971dadd19610d3ad38c768e124dc7","schema_version":"edge-lab-recorder.raw.v1","sequence":null,"source":"clob_market_ws"}
{"event_at":"2026-07-28T03:13:09.654000Z","event_fingerprint":"1a0461d600fd025a24399f3722b12fc84e8aed07596b2541daabb3b17a57f4e6","payload":{"connection_id":"a6b55582af5f430fb37ad02bf0922475","event_at":"2026-07-28T03:13:09.654000Z","event_type":"price_change","frame_hash":"6c3ce1d92dbb5cdd11901a6a9ead5879521c0d2cfc09bc75caf9d6c369fe896f","frame_index":0,"kind":"data","monotonic_ns":310373003069500,"payload":{"event_type":"price_change","market":"0x779291bef19b6709f61e9764a954aafe9ffae488d50ae674aabdcb4f248006d5","price_changes":[{"asset_id":"14965588658799411272385430903075831224615961675357217884735713260981483529984","best_ask":"0.55","best_bid":"0.54","hash":"fbd6c4a63e708f1ee5a8c0becfbec68e816031a6","price":"0.26","side":"BUY","size":"51"},{"asset_id":"8761897749749422724209054078244794145777693856614463256546737399611489089783","best_ask":"0.46","best_bid":"0.45","hash":"bbf34ba4cdf26f2e132a1cf0c0e7dc6daef61ecf","price":"0.74","side":"SELL","size":"51"}],"timestamp":"1785208389654"},"payload_hash":"d6525780477289381ba25adc995810d938b27f53a6b98a6a9d6214f205c0f358","raw_frame":"{\"market\":\"0x779291bef19b6709f61e9764a954aafe9ffae488d50ae674aabdcb4f248006d5\", \"price_changes\":[{\"asset_id\":\"14965588658799411272385430903075831224615961675357217884735713260981483529984\", \"price\":\"0.26\", \"size\":\"51\", \"side\":\"BUY\", \"hash\":\"fbd6c4a63e708f1ee5a8c0becfbec68e816031a6\", \"best_bid\":\"0.54\", \"best_ask\":\"0.55\"}, {\"asset_id\":\"8761897749749422724209054078244794145777693856614463256546737399611489089783\", \"price\":\"0.74\", \"size\":\"51\", \"side\":\"SELL\", \"hash\":\"bbf34ba4cdf26f2e132a1cf0c0e7dc6daef61ecf\", \"best_bid\":\"0.45\", \"best_ask\":\"0.46\"}], \"timestamp\":\"1785208389654\", \"event_type\":\"price_change\"}","received_at":"2026-07-28T03:13:09.968105Z","schema_version":"clob-market-ws.price_change.v1","sequence":null,"server_hash":null,"server_timestamp":"1785208389654","session_id":"3e519d9098404c15b234d96025eb1a2b","source":"clob_market_ws"},"received_at":"2026-07-28T03:13:09.968105Z","record_id":"6946a44bd9a34809e15d98252804f115832967cd6d78e46817094ebf96751b62","schema_fingerprint":"4aa3821a28b0b7c2400bc59aba4bcc0a76e971dadd19610d3ad38c768e124dc7","schema_version":"edge-lab-recorder.raw.v1","sequence":null,"source":"clob_market_ws"}
{"event_at":"2026-07-28T03:13:09.655000Z","event_fingerprint":"1f075d69d21d114af03c3ec827c32fac851d23dc166ca64a01796d8a0e908c3e","payload":{"connection_id":"a6b55582af5f430fb37ad02bf0922475","event_at":"2026-07-28T03:13:09.655000Z","event_type":"price_change","frame_hash":"c382d0c30912efdf65a462344d21e0f8a4425e539818db62c5ea2821d42b0ba2","frame_index":0,"kind":"data","monotonic_ns":310378410683125,"payload":{"event_type":"price_change","market":"0x779291bef19b6709f61e9764a954aafe9ffae488d50ae674aabdcb4f248006d5","price_changes":[{"asset_id":"8761897749749422724209054078244794145777693856614463256546737399611489089783","best_ask":"0.46","best_bid":"0.45","hash":"1254eadf812ada7936c48668c889fa0b666589a9","price":"0.43","side":"BUY","size":"77"},{"asset_id":"14965588658799411272385430903075831224615961675357217884735713260981483529984","best_ask":"0.55","best_bid":"0.54","hash":"8bb4fe9ffb1f74b8668e3ae27df1409d59f69119","price":"0.57","side":"SELL","size":"77"}],"timestamp":"1785208389655"},"payload_hash":"b8fba7758f4353f748847868f92bb6a97e4339ffdd76d58be58704b15039cc4f","raw_frame":"{\"market\":\"0x779291bef19b6709f61e9764a954aafe9ffae488d50ae674aabdcb4f248006d5\", \"price_changes\":[{\"asset_id\":\"8761897749749422724209054078244794145777693856614463256546737399611489089783\", \"price\":\"0.43\", \"size\":\"77\", \"side\":\"BUY\", \"hash\":\"1254eadf812ada7936c48668c889fa0b666589a9\", \"best_bid\":\"0.45\", \"best_ask\":\"0.46\"}, {\"asset_id\":\"14965588658799411272385430903075831224615961675357217884735713260981483529984\", \"price\":\"0.57\", \"size\":\"77\", \"side\":\"SELL\", \"hash\":\"8bb4fe9ffb1f74b8668e3ae27df1409d59f69119\", \"best_bid\":\"0.54\", \"best_ask\":\"0.55\"}], \"timestamp\":\"1785208389655\", \"event_type\":\"price_change\"}","received_at":"2026-07-28T03:13:15.375663Z","schema_version":"clob-market-ws.price_change.v1","sequence":null,"server_hash":null,"server_timestamp":"1785208389655","session_id":"3e519d9098404c15b234d96025eb1a2b","source":"clob_market_ws"},"received_at":"2026-07-28T03:13:15.375663Z","record_id":"a34e93f0971540708e8d768bae2e61b4ab969c3156d3fe0e62aac43001393f6a","schema_fingerprint":"4aa3821a28b0b7c2400bc59aba4bcc0a76e971dadd19610d3ad38c768e124dc7","schema_version":"edge-lab-recorder.raw.v1","sequence":null,"source":"clob_market_ws"}
{"event_at":"2026-07-28T03:13:09.656000Z","event_fingerprint":"b781a5a8eec79324d2c0b508ec46b35ecb10dfaefc22cec0958ed9c709c039a8","payload":{"connection_id":"a6b55582af5f430fb37ad02bf0922475","event_at":"2026-07-28T03:13:09.656000Z","event_type":"price_change","frame_hash":"0272c6f170c4330b1e67e42bebc85f6980e2ad129979933634fc4f70b2c3936f","frame_index":0,"kind":"data","monotonic_ns":310378414178625,"payload":{"event_type":"price_change","market":"0x779291bef19b6709f61e9764a954aafe9ffae488d50ae674aabdcb4f248006d5","price_changes":[{"asset_id":"14965588658799411272385430903075831224615961675357217884735713260981483529984","best_ask":"0.55","best_bid":"0.54","hash":"9533101942d125e76f0f9245ac3e30ca7d78889e","price":"0.33","side":"BUY","size":"108"},{"asset_id":"8761897749749422724209054078244794145777693856614463256546737399611489089783","best_ask":"0.46","best_bid":"0.45","hash":"0ea99c2dd3848801595bd53da36736c671554e46","price":"0.67","side":"SELL","size":"108"}],"timestamp":"1785208389656"},"payload_hash":"47476ef6bb73f59de27a8999f5a88c3fbc21fe9585770425e803f55e7c8b0499","raw_frame":"{\"market\":\"0x779291bef19b6709f61e9764a954aafe9ffae488d50ae674aabdcb4f248006d5\", \"price_changes\":[{\"asset_id\":\"14965588658799411272385430903075831224615961675357217884735713260981483529984\", \"price\":\"0.33\", \"size\":\"108\", \"side\":\"BUY\", \"hash\":\"9533101942d125e76f0f9245ac3e30ca7d78889e\", \"best_bid\":\"0.54\", \"best_ask\":\"0.55\"}, {\"asset_id\":\"8761897749749422724209054078244794145777693856614463256546737399611489089783\", \"price\":\"0.67\", \"size\":\"108\", \"side\":\"SELL\", \"hash\":\"0ea99c2dd3848801595bd53da36736c671554e46\", \"best_bid\":\"0.45\", \"best_ask\":\"0.46\"}], \"timestamp\":\"1785208389656\", \"event_type\":\"price_change\"}","received_at":"2026-07-28T03:13:15.379160Z","schema_version":"clob-market-ws.price_change.v1","sequence":null,"server_hash":null,"server_timestamp":"1785208389656","session_id":"3e519d9098404c15b234d96025eb1a2b","source":"clob_market_ws"},"received_at":"2026-07-28T03:13:15.379160Z","record_id":"4fae076f3879bb8e243e96e4de4162e295a464d3378ffadfa8cdd50a58069ec0","schema_fingerprint":"4aa3821a28b0b7c2400bc59aba4bcc0a76e971dadd19610d3ad38c768e124dc7","schema_version":"edge-lab-recorder.raw.v1","sequence":null,"source":"clob_market_ws"}
{"event_at":null,"event_fingerprint":"97ce1c11b74c433a51b8e7b3a043e81369baff3b91766c8ef6c26d96dcf098aa","payload":{"connection_id":"a6b55582af5f430fb37ad02bf0922475","detail":{"interval_seconds":10.0,"message":"PING"},"event_type":"heartbeat","kind":"lifecycle","monotonic_ns":310378415825375,"received_at":"2026-07-28T03:13:15.380811Z","schema_version":"edge-lab-recorder.lifecycle.v1","session_id":"3e519d9098404c15b234d96025eb1a2b","source":"clob_market_ws"},"received_at":"2026-07-28T03:13:15.380811Z","record_id":"1b382a9459f2f33c0bad54729755e400e2f1f6c36c84897e41898dba905317e9","schema_fingerprint":"cb8aa3aa4cb168a4b724fd9077bee6ecfb9bc586c57cfdf0ab89f00d82045e3c","schema_version":"edge-lab-recorder.raw.v1","sequence":null,"source":"clob_market_ws"}
{"event_at":"2026-07-28T03:13:09.656000Z","event_fingerprint":"e7373cceb6d45e291a343fb491169385ee85fd84d20a641cbb080ab98f735b9a","payload":{"connection_id":"a6b55582af5f430fb37ad02bf0922475","event_at":"2026-07-28T03:13:09.656000Z","event_type":"price_change","frame_hash":"ae83442ce4bdfdb4e6fa5e1f148bd70d30642c24e992dd00721cc3fbe047200a","frame_index":0,"kind":"data","monotonic_ns":310378416120833,"payload":{"event_type":"price_change","market":"0x779291bef19b6709f61e9764a954aafe9ffae488d50ae674aabdcb4f248006d5","price_changes":[{"asset_id":"8761897749749422724209054078244794145777693856614463256546737399611489089783","best_ask":"0.46","best_bid":"0.45","hash":"0ea99c2dd3848801595bd53da36736c671554e46","price":"0.37","side":"BUY","size":"89"},{"asset_id":"14965588658799411272385430903075831224615961675357217884735713260981483529984","best_ask":"0.55","best_bid":"0.54","hash":"9533101942d125e76f0f9245ac3e30ca7d78889e","price":"0.63","side":"SELL","size":"89"}],"timestamp":"1785208389656"},"payload_hash":"0a1da2ec094c99f3a0486e9a1ff9627d4d038ea20889bbe868fe8653ebf7044e","raw_frame":"{\"market\":\"0x779291bef19b6709f61e9764a954aafe9ffae488d50ae674aabdcb4f248006d5\", \"price_changes\":[{\"asset_id\":\"8761897749749422724209054078244794145777693856614463256546737399611489089783\", \"price\":\"0.37\", \"size\":\"89\", \"side\":\"BUY\", \"hash\":\"0ea99c2dd3848801595bd53da36736c671554e46\", \"best_bid\":\"0.45\", \"best_ask\":\"0.46\"}, {\"asset_id\":\"14965588658799411272385430903075831224615961675357217884735713260981483529984\", \"price\":\"0.63\", \"size\":\"89\", \"side\":\"SELL\", \"hash\":\"9533101942d125e76f0f9245ac3e30ca7d78889e\", \"best_bid\":\"0.54\", \"best_ask\":\"0.55\"}], \"timestamp\":\"1785208389656\", \"event_type\":\"price_change\"}","received_at":"2026-07-28T03:13:15.381109Z","schema_version":"clob-market-ws.price_change.v1","sequence":null,"server_hash":null,"server_timestamp":"1785208389656","session_id":"3e519d9098404c15b234d96025eb1a2b","source":"clob_market_ws"},"received_at":"2026-07-28T03:13:15.381109Z","record_id":"5f0eefe297ef68a7a7b1652effec3a05ad2e3ee4004a505d8b7809c059a17fe7","schema_fingerprint":"4aa3821a28b0b7c2400bc59aba4bcc0a76e971dadd19610d3ad38c768e124dc7","schema_version":"edge-lab-recorder.raw.v1","sequence":null,"source":"clob_market_ws"}
{"event_at":"2026-07-28T03:13:09.656000Z","event_fingerprint":"6c576af99d892c7d0bd91609ccfadfa90019105e6bc3274e64fd4d342c72c7d6","payload":{"connection_id":"a6b55582af5f430fb37ad02bf0922475","event_at":"2026-07-28T03:13:09.656000Z","event_type":"price_change","frame_hash":"4149c9699aed72acb7073b7179797b126f947c1374da7f9f1c189974033b6044","frame_index":0,"kind":"data","monotonic_ns":310378418743583,"payload":{"event_type":"price_change","market":"0x779291bef19b6709f61e9764a954aafe9ffae488d50ae674aabdcb4f248006d5","price_changes":[{"asset_id":"8761897749749422724209054078244794145777693856614463256546737399611489089783","best_ask":"0.46","best_bid":"0.45","hash":"ae192ea5a387c4467c59b4a6d0b46431d32b660c","price":"0.4","side":"BUY","size":"90"},{"asset_id":"14965588658799411272385430903075831224615961675357217884735713260981483529984","best_ask":"0.55","best_bid":"0.54","hash":"baa313888684fd86408fe594eb885b62c97c4b4f","price":"0.6","side":"SELL","size":"90"}],"timestamp":"1785208389656"},"payload_hash":"e9305a53afd15fe03ce24d8ec17509bf715d0557c4d8f63de7037e33ccd7d31a","raw_frame":"{\"market\":\"0x779291bef19b6709f61e9764a954aafe9ffae488d50ae674aabdcb4f248006d5\", \"price_changes\":[{\"asset_id\":\"8761897749749422724209054078244794145777693856614463256546737399611489089783\", \"price\":\"0.4\", \"size\":\"90\", \"side\":\"BUY\", \"hash\":\"ae192ea5a387c4467c59b4a6d0b46431d32b660c\", \"best_bid\":\"0.45\", \"best_ask\":\"0.46\"}, {\"asset_id\":\"14965588658799411272385430903075831224615961675357217884735713260981483529984\", \"price\":\"0.6\", \"size\":\"90\", \"side\":\"SELL\", \"hash\":\"baa313888684fd86408fe594eb885b62c97c4b4f\", \"best_bid\":\"0.54\", \"best_ask\":\"0.55\"}], \"timestamp\":\"1785208389656\", \"event_type\":\"price_change\"}","received_at":"2026-07-28T03:13:15.383731Z","schema_version":"clob-market-ws.price_change.v1","sequence":null,"server_hash":null,"server_timestamp":"1785208389656","session_id":"3e519d9098404c15b234d96025eb1a2b","source":"clob_market_ws"},"received_at":"2026-07-28T03:13:15.383731Z","record_id":"d86a3ff6463ee3a3259b49132d537c88a172ef83b076a9368593c369cb4e6af5","schema_fingerprint":"4aa3821a28b0b7c2400bc59aba4bcc0a76e971dadd19610d3ad38c768e124dc7","schema_version":"edge-lab-recorder.raw.v1","sequence":null,"source":"clob_market_ws"}
{"event_at":"2026-07-28T03:13:09.657000Z","event_fingerprint":"005634c569170a40875d3831b380160a6d2d96cab04caf1feed3f16309ae44d3","payload":{"connection_id":"a6b55582af5f430fb37ad02bf0922475","event_at":"2026-07-28T03:13:09.657000Z","event_type":"price_change","frame_hash":"4ae475243904ec4e0ccf38a9244803924a66766577c5221a8638af5b504cc1f5","frame_index":0,"kind":"data","monotonic_ns":310378420448875,"payload":{"event_type":"price_change","market":"0x779291bef19b6709f61e9764a954aafe9ffae488d50ae674aabdcb4f248006d5","price_changes":[{"asset_id":"14965588658799411272385430903075831224615961675357217884735713260981483529984","best_ask":"0.55","best_bid":"0.54","hash":"c1891a292737f8be78044ef98a5660afbc32b523","price":"0.5","side":"BUY","size":"93.2"},{"asset_id":"8761897749749422724209054078244794145777693856614463256546737399611489089783","best_ask":"0.46","best_bid":"0.45","hash":"820b2bc7438300b6dddad732fbb69aa4654e400c","price":"0.5","side":"SELL","size":"93.2"}],"timestamp":"1785208389657"},"payload_hash":"ed88fc03e52b4514873169496e2d21898554193a03570005ede655c498a32012","raw_frame":"{\"market\":\"0x779291bef19b6709f61e9764a954aafe9ffae488d50ae674aabdcb4f248006d5\", \"price_changes\":[{\"asset_id\":\"14965588658799411272385430903075831224615961675357217884735713260981483529984\", \"price\":\"0.5\", \"size\":\"93.2\", \"side\":\"BUY\", \"hash\":\"c1891a292737f8be78044ef98a5660afbc32b523\", \"best_bid\":\"0.54\", \"best_ask\":\"0.55\"}, {\"asset_id\":\"8761897749749422724209054078244794145777693856614463256546737399611489089783\", \"price\":\"0.5\", \"size\":\"93.2\", \"side\":\"SELL\", \"hash\":\"820b2bc7438300b6dddad732fbb69aa4654e400c\", \"best_bid\":\"0.45\", \"best_ask\":\"0.46\"}], \"timestamp\":\"1785208389657\", \"event_type\":\"price_change\"}","received_at":"2026-07-28T03:13:15.385437Z","schema_version":"clob-market-ws.price_change.v1","sequence":null,"server_hash":null,"server_timestamp":"1785208389657","session_id":"3e519d9098404c15b234d96025eb1a2b","source":"clob_market_ws"},"received_at":"2026-07-28T03:13:15.385437Z","record_id":"b89b0736d65d9b2fd571ec025584e5de750fde1ef8bc3e38d7cccfe181a3b0e5","schema_fingerprint":"4aa3821a28b0b7c2400bc59aba4bcc0a76e971dadd19610d3ad38c768e124dc7","schema_version":"edge-lab-recorder.raw.v1","sequence":null,"source":"clob_market_ws"}
{"event_at":"2026-07-28T03:13:09.657000Z","event_fingerprint":"e0dfc51e2bdd115b2d1f49c7acd4983697d2cb6a0def65c8455c17ee8c6a95d7","payload":{"connection_id":"a6b55582af5f430fb37ad02bf0922475","event_at":"2026-07-28T03:13:09.657000Z","event_type":"price_change","frame_hash":"289e50134ce1fa64ac967d858f3772433484b062db41da716f34236e64305e84","frame_index":0,"kind":"data","monotonic_ns":310378422097083,"payload":{"event_type":"price_change","market":"0x779291bef19b6709f61e9764a954aafe9ffae488d50ae674aabdcb4f248006d5","price_changes":[{"asset_id":"8761897749749422724209054078244794145777693856614463256546737399611489089783","best_ask":"0.46","best_bid":"0.45","hash":"78c4cccea78f92b6a14fe7de0f1b817da82ca65c","price":"0.39","side":"BUY","size":"86"},{"asset_id":"14965588658799411272385430903075831224615961675357217884735713260981483529984","best_ask":"0.55","best_bid":"0.54","hash":"0e6c80eb0ccb1fc9e4654e73a3b447b8d1bebb87","price":"0.61","side":"SELL","size":"86"}],"timestamp":"1785208389657"},"payload_hash":"105607d51dd84f7d222032228147f5495271642669903cf803b0d28b13145e4b","raw_frame":"{\"market\":\"0x779291bef19b6709f61e9764a954aafe9ffae488d50ae674aabdcb4f248006d5\", \"price_changes\":[{\"asset_id\":\"8761897749749422724209054078244794145777693856614463256546737399611489089783\", \"price\":\"0.39\", \"size\":\"86\", \"side\":\"BUY\", \"hash\":\"78c4cccea78f92b6a14fe7de0f1b817da82ca65c\", \"best_bid\":\"0.45\", \"best_ask\":\"0.46\"}, {\"asset_id\":\"14965588658799411272385430903075831224615961675357217884735713260981483529984\", \"price\":\"0.61\", \"size\":\"86\", \"side\":\"SELL\", \"hash\":\"0e6c80eb0ccb1fc9e4654e73a3b447b8d1bebb87\", \"best_bid\":\"0.54\", \"best_ask\":\"0.55\"}], \"timestamp\":\"1785208389657\", \"event_type\":\"price_change\"}","received_at":"2026-07-28T03:13:15.387085Z","schema_version":"clob-market-ws.price_change.v1","sequence":null,"server_hash":null,"server_timestamp":"1785208389657","session_id":"3e519d9098404c15b234d96025eb1a2b","source":"clob_market_ws"},"received_at":"2026-07-28T03:13:15.387085Z","record_id":"70b381f5e7f1442c5d06c29c03cac544ae1ee7c89533d4c266d954ea99161c74","schema_fingerprint":"4aa3821a28b0b7c2400bc59aba4bcc0a76e971dadd19610d3ad38c768e124dc7","schema_version":"edge-lab-recorder.raw.v1","sequence":null,"source":"clob_market_ws"}
{"event_at":"2026-07-28T03:13:09.657000Z","event_fingerprint":"245e81160e6b09d31553bebcfa4d00e0c8662baff5288941ff18cdd26f7ebfff","payload":{"connection_id":"a6b55582af5f430fb37ad02bf0922475","event_at":"2026-07-28T03:13:09.657000Z","event_type":"price_change","frame_hash":"3aaf631ec5b45fb46a77d6ee11adc8a589e3a6db4836159930832d32c07fb9ab","frame_index":0,"kind":"data","monotonic_ns":310378423710916,"payload":{"event_type":"price_change","market":"0x779291bef19b6709f61e9764a954aafe9ffae488d50ae674aabdcb4f248006d5","price_changes":[{"asset_id":"14965588658799411272385430903075831224615961675357217884735713260981483529984","best_ask":"0.55","best_bid":"0.54","hash":"fef039b57565a82e0f43079bf398a297102bddd8","price":"0.46","side":"BUY","size":"97"},{"asset_id":"8761897749749422724209054078244794145777693856614463256546737399611489089783","best_ask":"0.46","best_bid":"0.45","hash":"583b1c6c8edc7e60aa657f25510b63eb2fe45309","price":"0.54","side":"SELL","size":"97"}],"timestamp":"1785208389657"},"payload_hash":"cf5acdeee1e3d3bced67cf529a4160c51006f5cca145f9e0b706a5bf60e19345","raw_frame":"{\"market\":\"0x779291bef19b6709f61e9764a954aafe9ffae488d50ae674aabdcb4f248006d5\", \"price_changes\":[{\"asset_id\":\"14965588658799411272385430903075831224615961675357217884735713260981483529984\", \"price\":\"0.46\", \"size\":\"97\", \"side\":\"BUY\", \"hash\":\"fef039b57565a82e0f43079bf398a297102bddd8\", \"best_bid\":\"0.54\", \"best_ask\":\"0.55\"}, {\"asset_id\":\"8761897749749422724209054078244794145777693856614463256546737399611489089783\", \"price\":\"0.54\", \"size\":\"97\", \"side\":\"SELL\", \"hash\":\"583b1c6c8edc7e60aa657f25510b63eb2fe45309\", \"best_bid\":\"0.45\", \"best_ask\":\"0.46\"}], \"timestamp\":\"1785208389657\", \"event_type\":\"price_change\"}","received_at":"2026-07-28T03:13:15.388700Z","schema_version":"clob-market-ws.price_change.v1","sequence":null,"server_hash":null,"server_timestamp":"1785208389657","session_id":"3e519d9098404c15b234d96025eb1a2b","source":"clob_market_ws"},"received_at":"2026-07-28T03:13:15.388700Z","record_id":"2b70a18d9b849ec47ab63f6269c19231bd3e201198b92d9a3b5c8db4c8c77267","schema_fingerprint":"4aa3821a28b0b7c2400bc59aba4bcc0a76e971dadd19610d3ad38c768e124dc7","schema_version":"edge-lab-recorder.raw.v1","sequence":null,"source":"clob_market_ws"}
{"event_at":"2026-07-28T03:13:09.658000Z","event_fingerprint":"ecb046be5cc3d84c0330976c146e83b8302941a4d8aa973f3331051731d942f6","payload":{"connection_id":"a6b55582af5f430fb37ad02bf0922475","event_at":"2026-07-28T03:13:09.658000Z","event_type":"price_change","frame_hash":"64b5b7d299becd6f658b3b3ccfd29170132681efb0c39ad3acfbb5423da3de94","frame_index":0,"kind":"data","monotonic_ns":310378425312500,"payload":{"event_type":"price_change","market":"0x779291bef19b6709f61e9764a954aafe9ffae488d50ae674aabdcb4f248006d5","price_changes":[{"asset_id":"8761897749749422724209054078244794145777693856614463256546737399611489089783","best_ask":"0.46","best_bid":"0.45","hash":"c0c814db58ecc33c2824f25a345b34ee6db66be4","price":"0.55","side":"SELL","size":"82.36"},{"asset_id":"14965588658799411272385430903075831224615961675357217884735713260981483529984","best_ask":"0.55","best_bid":"0.54","hash":"d80bc2fb950112793c6054095938c15e03d90753","price":"0.45","side":"BUY","size":"82.36"}],"timestamp":"1785208389658"},"payload_hash":"415465004d9b27a2844a9b961a85ec234c6588f034d59c798b22096dda3513f3","raw_frame":"{\"market\":\"0x779291bef19b6709f61e9764a954aafe9ffae488d50ae674aabdcb4f248006d5\", \"price_changes\":[{\"asset_id\":\"8761897749749422724209054078244794145777693856614463256546737399611489089783\", \"price\":\"0.55\", \"size\":\"82.36\", \"side\":\"SELL\", \"hash\":\"c0c814db58ecc33c2824f25a345b34ee6db66be4\", \"best_bid\":\"0.45\", \"best_ask\":\"0.46\"}, {\"asset_id\":\"14965588658799411272385430903075831224615961675357217884735713260981483529984\", \"price\":\"0.45\", \"size\":\"82.36\", \"side\":\"BUY\", \"hash\":\"d80bc2fb950112793c6054095938c15e03d90753\", \"best_bid\":\"0.54\", \"best_ask\":\"0.55\"}], \"timestamp\":\"1785208389658\", \"event_type\":\"price_change\"}","received_at":"2026-07-28T03:13:15.390302Z","schema_version":"clob-market-ws.price_change.v1","sequence":null,"server_hash":null,"server_timestamp":"1785208389658","session_id":"3e519d9098404c15b234d96025eb1a2b","source":"clob_market_ws"},"received_at":"2026-07-28T03:13:15.390302Z","record_id":"f5b749527531cbcb2d262b31dd9aa345d3e6786775298abe5af19419c7531110","schema_fingerprint":"4aa3821a28b0b7c2400bc59aba4bcc0a76e971dadd19610d3ad38c768e124dc7","schema_version":"edge-lab-recorder.raw.v1","sequence":null,"source":"clob_market_ws"}
{"event_at":"2026-07-28T03:13:09.659000Z","event_fingerprint":"440237a88b63d84db4968449466317799424785648bb6437f5d3aa448d7ec209","payload":{"connection_id":"a6b55582af5f430fb37ad02bf0922475","event_at":"2026-07-28T03:13:09.659000Z","event_type":"price_change","frame_hash":"104a4ea5855d253135258e214d55f018db32c2ab92459c83ac10661de1971e92","frame_index":0,"kind":"data","monotonic_ns":310378426893291,"payload":{"event_type":"price_change","market":"0x779291bef19b6709f61e9764a954aafe9ffae488d50ae674aabdcb4f248006d5","price_changes":[{"asset_id":"8761897749749422724209054078244794145777693856614463256546737399611489089783","best_ask":"0.46","best_bid":"0.45","hash":"a457770d4017615da0491e5f3882deccc5771e57","price":"0.44","side":"BUY","size":"75"},{"asset_id":"14965588658799411272385430903075831224615961675357217884735713260981483529984","best_ask":"0.55","best_bid":"0.54","hash":"4200375dd6255a93df2fe7aa958ddf00055b0f9a","price":"0.56","side":"SELL","size":"75"}],"timestamp":"1785208389659"},"payload_hash":"44217bb672fb3fa4d0778fc938004231f47dc98784203b4b41ca7526ed1f1b87","raw_frame":"{\"market\":\"0x779291bef19b6709f61e9764a954aafe9ffae488d50ae674aabdcb4f248006d5\", \"price_changes\":[{\"asset_id\":\"8761897749749422724209054078244794145777693856614463256546737399611489089783\", \"price\":\"0.44\", \"size\":\"75\", \"side\":\"BUY\", \"hash\":\"a457770d4017615da0491e5f3882deccc5771e57\", \"best_bid\":\"0.45\", \"best_ask\":\"0.46\"}, {\"asset_id\":\"14965588658799411272385430903075831224615961675357217884735713260981483529984\", \"price\":\"0.56\", \"size\":\"75\", \"side\":\"SELL\", \"hash\":\"4200375dd6255a93df2fe7aa958ddf00055b0f9a\", \"best_bid\":\"0.54\", \"best_ask\":\"0.55\"}], \"timestamp\":\"1785208389659\", \"event_type\":\"price_change\"}","received_at":"2026-07-28T03:13:15.391883Z","schema_version":"clob-market-ws.price_change.v1","sequence":null,"server_hash":null,"server_timestamp":"1785208389659","session_id":"3e519d9098404c15b234d96025eb1a2b","source":"clob_market_ws"},"received_at":"2026-07-28T03:13:15.391883Z","record_id":"a3ce09e603977397d9a7600d7d0d07b27fdb57df1ef430c419a63bf2977eec2c","schema_fingerprint":"4aa3821a28b0b7c2400bc59aba4bcc0a76e971dadd19610d3ad38c768e124dc7","schema_version":"edge-lab-recorder.raw.v1","sequence":null,"source":"clob_market_ws"}
{"event_at":"2026-07-28T03:13:09.660000Z","event_fingerprint":"25be244fb238b2ed9f53d632c246a3e2e1807e98c08c08952835a005caf9a358","payload":{"connection_id":"a6b55582af5f430fb37ad02bf0922475","event_at":"2026-07-28T03:13:09.660000Z","event_type":"price_change","frame_hash":"5c8804c2a66131c528776873cfbb16ecf975c40ad9d491f7f8d17778dc96eb39","frame_index":0,"kind":"data","monotonic_ns":310378428528750,"payload":{"event_type":"price_change","market":"0x779291bef19b6709f61e9764a954aafe9ffae488d50ae674aabdcb4f248006d5","price_changes":[{"asset_id":"14965588658799411272385430903075831224615961675357217884735713260981483529984","best_ask":"0.55","best_bid":"0.54","hash":"1d84fc118ce058db17d67ef05a9a269571d03eb8","price":"0.31","side":"BUY","size":"79.75"},{"asset_id":"8761897749749422724209054078244794145777693856614463256546737399611489089783","best_ask":"0.46","best_bid":"0.45","hash":"129e2346edb4dbe36926ebcff9ff79484ba4bcc5","price":"0.69","side":"SELL","size":"79.75"}],"timestamp":"1785208389660"},"payload_hash":"0a7d9339fc856d28506048ed346f25596d4962b073a9cbd9c5a5697517790180","raw_frame":"{\"market\":\"0x779291bef19b6709f61e9764a954aafe9ffae488d50ae674aabdcb4f248006d5\", \"price_changes\":[{\"asset_id\":\"14965588658799411272385430903075831224615961675357217884735713260981483529984\", \"price\":\"0.31\", \"size\":\"79.75\", \"side\":\"BUY\", \"hash\":\"1d84fc118ce058db17d67ef05a9a269571d03eb8\", \"best_bid\":\"0.54\", \"best_ask\":\"0.55\"}, {\"asset_id\":\"8761897749749422724209054078244794145777693856614463256546737399611489089783\", \"price\":\"0.69\", \"size\":\"79.75\", \"side\":\"SELL\", \"hash\":\"129e2346edb4dbe36926ebcff9ff79484ba4bcc5\", \"best_bid\":\"0.45\", \"best_ask\":\"0.46\"}], \"timestamp\":\"1785208389660\", \"event_type\":\"price_change\"}","received_at":"2026-07-28T03:13:15.393511Z","schema_version":"clob-market-ws.price_change.v1","sequence":null,"server_hash":null,"server_timestamp":"1785208389660","session_id":"3e519d9098404c15b234d96025eb1a2b","source":"clob_market_ws"},"received_at":"2026-07-28T03:13:15.393511Z","record_id":"faf7019a24105a30d6ea85c73c986c95f539f15ae785faf2ae8811460cf8f6b6","schema_fingerprint":"4aa3821a28b0b7c2400bc59aba4bcc0a76e971dadd19610d3ad38c768e124dc7","schema_version":"edge-lab-recorder.raw.v1","sequence":null,"source":"clob_market_ws"}
{"event_at":"2026-07-28T03:13:09.660000Z","event_fingerprint":"3e74484440c90dbb477bdd2dd6008b088a8cf7e3584f9ec7e0c18250e5fd9cfa","payload":{"connection_id":"a6b55582af5f430fb37ad02bf0922475","event_at":"2026-07-28T03:13:09.660000Z","event_type":"price_change","frame_hash":"12db330905990be448300d4b4ce62e71f59c13c7319ccf806bbfa80d9044a6b1","frame_index":0,"kind":"data","monotonic_ns":310378430380208,"payload":{"event_type":"price_change","market":"0x779291bef19b6709f61e9764a954aafe9ffae488d50ae674aabdcb4f248006d5","price_changes":[{"asset_id":"14965588658799411272385430903075831224615961675357217884735713260981483529984","best_ask":"0.55","best_bid":"0.54","hash":"47be9310a76f8a939b00b2908bed56507b9d6f73","price":"0.3","side":"BUY","size":"50.12"},{"asset_id":"8761897749749422724209054078244794145777693856614463256546737399611489089783","best_ask":"0.46","best_bid":"0.45","hash":"77dd1cb95c0fc6b1d4ebb6738da849cbfc4de003","price":"0.7","side":"SELL","size":"50.12"}],"timestamp":"1785208389660"},"payload_hash":"525f0cf953a2cda7e590eb11855cd2ed2bf9cd593f9cdeaa63067dd70d24d531","raw_frame":"{\"market\":\"0x779291bef19b6709f61e9764a954aafe9ffae488d50ae674aabdcb4f248006d5\", \"price_changes\":[{\"asset_id\":\"14965588658799411272385430903075831224615961675357217884735713260981483529984\", \"price\":\"0.3\", \"size\":\"50.12\", \"side\":\"BUY\", \"hash\":\"47be9310a76f8a939b00b2908bed56507b9d6f73\", \"best_bid\":\"0.54\", \"best_ask\":\"0.55\"}, {\"asset_id\":\"8761897749749422724209054078244794145777693856614463256546737399611489089783\", \"price\":\"0.7\", \"size\":\"50.12\", \"side\":\"SELL\", \"hash\":\"77dd1cb95c0fc6b1d4ebb6738da849cbfc4de003\", \"best_bid\":\"0.45\", \"best_ask\":\"0.46\"}], \"timestamp\":\"1785208389660\", \"event_type\":\"price_change\"}","received_at":"2026-07-28T03:13:15.395363Z","schema_version":"clob-market-ws.price_change.v1","sequence":null,"server_hash":null,"server_timestamp":"1785208389660","session_id":"3e519d9098404c15b234d96025eb1a2b","source":"clob_market_ws"},"received_at":"2026-07-28T03:13:15.395363Z","record_id":"5ee0bc42e2c1aea92d103e50c7eb72e0384d08d8fe4df94e45db9163c8a1894c","schema_fingerprint":"4aa3821a28b0b7c2400bc59aba4bcc0a76e971dadd19610d3ad38c768e124dc7","schema_version":"edge-lab-recorder.raw.v1","sequence":null,"source":"clob_market_ws"}
{"event_at":"2026-07-28T03:13:09.660000Z","event_fingerprint":"4da19f2950f932e3f7aedf43b5188282fab9bb7c07cb1b928fdd229657e815c0","payload":{"connection_id":"a6b55582af5f430fb37ad02bf0922475","event_at":"2026-07-28T03:13:09.660000Z","event_type":"price_change","frame_hash":"797703682d9f78f8bf9c5976efd7e74ba402db3a03408a2e06cb757e4bfb2dac","frame_index":0,"kind":"data","monotonic_ns":310378431525083,"payload":{"event_type":"price_change","market":"0x779291bef19b6709f61e9764a954aafe9ffae488d50ae674aabdcb4f248006d5","price_changes":[{"asset_id":"14965588658799411272385430903075831224615961675357217884735713260981483529984","best_ask":"0.55","best_bid":"0.54","hash":"c41ae9feddc11dc51d81479df90492fa3a6d65b2","price":"0.39","side":"BUY","size":"116"},{"asset_id":"8761897749749422724209054078244794145777693856614463256546737399611489089783","best_ask":"0.46","best_bid":"0.45","hash":"5047822fe92ea99c6e96336387e7ef61fd7413b4","price":"0.61","side":"SELL","size":"116"}],"timestamp":"1785208389660"},"payload_hash":"dd9485b5161197360ddd55376703f0f646590504e92b1bbd208a4ffe2e392276","raw_frame":"{\"market\":\"0x779291bef19b6709f61e9764a954aafe9ffae488d50ae674aabdcb4f248006d5\", \"price_changes\":[{\"asset_id\":\"14965588658799411272385430903075831224615961675357217884735713260981483529984\", \"price\":\"0.39\", \"size\":\"116\", \"side\":\"BUY\", \"hash\":\"c41ae9feddc11dc51d81479df90492fa3a6d65b2\", \"best_bid\":\"0.54\", \"best_ask\":\"0.55\"}, {\"asset_id\":\"8761897749749422724209054078244794145777693856614463256546737399611489089783\", \"price\":\"0.61\", \"size\":\"116\", \"side\":\"SELL\", \"hash\":\"5047822fe92ea99c6e96336387e7ef61fd7413b4\", \"best_bid\":\"0.45\", \"best_ask\":\"0.46\"}], \"timestamp\":\"1785208389660\", \"event_type\":\"price_change\"}","received_at":"2026-07-28T03:13:15.396520Z","schema_version":"clob-market-ws.price_change.v1","sequence":null,"server_hash":null,"server_timestamp":"1785208389660","session_id":"3e519d9098404c15b234d96025eb1a2b","source":"clob_market_ws"},"received_at":"2026-07-28T03:13:15.396520Z","record_id":"2df42e1a51a623d0f0bbaa013003b2dcc4334a7d982b9eaa93ff991558036089","schema_fingerprint":"4aa3821a28b0b7c2400bc59aba4bcc0a76e971dadd19610d3ad38c768e124dc7","schema_version":"edge-lab-recorder.raw.v1","sequence":null,"source":"clob_market_ws"}
{"event_at":"2026-07-28T03:13:09.661000Z","event_fingerprint":"8bab5b0d17ad1901ee6752595d24005870d5ae27b386e0f0ce5343e13fa5f38a","payload":{"connection_id":"a6b55582af5f430fb37ad02bf0922475","event_at":"2026-07-28T03:13:09.661000Z","event_type":"price_change","frame_hash":"3e5fdb6030068b633aada4794da3d6a754c0bca14000a96e5fb89cdd7aad25f8","frame_index":0,"kind":"data","monotonic_ns":310378432145916,"payload":{"event_type":"price_change","market":"0x779291bef19b6709f61e9764a954aafe9ffae488d50ae674aabdcb4f248006d5","price_changes":[{"asset_id":"14965588658799411272385430903075831224615961675357217884735713260981483529984","best_ask":"0.55","best_bid":"0.54","hash":"bc4fd66c173f2956fb7972a7610a103f0ce0ea04","price":"0.52","side":"BUY","size":"54"},{"asset_id":"8761897749749422724209054078244794145777693856614463256546737399611489089783","best_ask":"0.46","best_bid":"0.45","hash":"33b40dbf0b6a5514408205ef7890c77ef2877f20","price":"0.48","side":"SELL","size":"54"}],"timestamp":"1785208389661"},"payload_hash":"cddf69df8a588ff522ef11d1204fe8011c49ac5760efc1471f6a8868ca64603f","raw_frame":"{\"market\":\"0x779291bef19b6709f61e9764a954aafe9ffae488d50ae674aabdcb4f248006d5\", \"price_changes\":[{\"asset_id\":\"14965588658799411272385430903075831224615961675357217884735713260981483529984\", \"price\":\"0.52\", \"size\":\"54\", \"side\":\"BUY\", \"hash\":\"bc4fd66c173f2956fb7972a7610a103f0ce0ea04\", \"best_bid\":\"0.54\", \"best_ask\":\"0.55\"}, {\"asset_id\":\"8761897749749422724209054078244794145777693856614463256546737399611489089783\", \"price\":\"0.48\", \"size\":\"54\", \"side\":\"SELL\", \"hash\":\"33b40dbf0b6a5514408205ef7890c77ef2877f20\", \"best_bid\":\"0.45\", \"best_ask\":\"0.46\"}], \"timestamp\":\"1785208389661\", \"event_type\":\"price_change\"}","received_at":"2026-07-28T03:13:15.397134Z","schema_version":"clob-market-ws.price_change.v1","sequence":null,"server_hash":null,"server_timestamp":"1785208389661","session_id":"3e519d9098404c15b234d96025eb1a2b","source":"clob_market_ws"},"received_at":"2026-07-28T03:13:15.397134Z","record_id":"bd56e2020bcab4207571ea536887759b83e3ba87bde7efa01d1fcf3a2df169ab","schema_fingerprint":"4aa3821a28b0b7c2400bc59aba4bcc0a76e971dadd19610d3ad38c768e124dc7","schema_version":"edge-lab-recorder.raw.v1","sequence":null,"source":"clob_market_ws"}
{"event_at":"2026-07-28T03:13:09.662000Z","event_fingerprint":"592953203e036d12c519464133fbf555c4c221ce084ce778f955e2da5063129a","payload":{"connection_id":"a6b55582af5f430fb37ad02bf0922475","event_at":"2026-07-28T03:13:09.662000Z","event_type":"price_change","frame_hash":"d2962d78c863f5428438b6649fa4025d280eef0e4dfd02abb668491cf317d452","frame_index":0,"kind":"data","monotonic_ns":310378433753291,"payload":{"event_type":"price_change","market":"0x779291bef19b6709f61e9764a954aafe9ffae488d50ae674aabdcb4f248006d5","price_changes":[{"asset_id":"14965588658799411272385430903075831224615961675357217884735713260981483529984","best_ask":"0.55","best_bid":"0.54","hash":"ff09c5b598bf2193a1ef3be36b9234c9a52e7678","price":"0.49","side":"BUY","size":"437"},{"asset_id":"8761897749749422724209054078244794145777693856614463256546737399611489089783","best_ask":"0.46","best_bid":"0.45","hash":"354f21cee81705cc3812eeca7602f5a161fedd87","price":"0.51","side":"SELL","size":"437"}],"timestamp":"1785208389662"},"payload_hash":"5860a789a6d78c97119d32b184f07b337bd4bc2d9e003c01c1a3ee4cd13754ee","raw_frame":"{\"market\":\"0x779291bef19b6709f61e9764a954aafe9ffae488d50ae674aabdcb4f248006d5\", \"price_changes\":[{\"asset_id\":\"14965588658799411272385430903075831224615961675357217884735713260981483529984\", \"price\":\"0.49\", \"size\":\"437\", \"side\":\"BUY\", \"hash\":\"ff09c5b598bf2193a1ef3be36b9234c9a52e7678\", \"best_bid\":\"0.54\", \"best_ask\":\"0.55\"}, {\"asset_id\":\"8761897749749422724209054078244794145777693856614463256546737399611489089783\", \"price\":\"0.51\", \"size\":\"437\", \"side\":\"SELL\", \"hash\":\"354f21cee81705cc3812eeca7602f5a161fedd87\", \"best_bid\":\"0.45\", \"best_ask\":\"0.46\"}], \"timestamp\":\"1785208389662\", \"event_type\":\"price_change\"}","received_at":"2026-07-28T03:13:15.398742Z","schema_version":"clob-market-ws.price_change.v1","sequence":null,"server_hash":null,"server_timestamp":"1785208389662","session_id":"3e519d9098404c15b234d96025eb1a2b","source":"clob_market_ws"},"received_at":"2026-07-28T03:13:15.398742Z","record_id":"88c579cbacae631313a64f4364b032569aa3c227281a9b8ed33ef8ba4ff23ca3","schema_fingerprint":"4aa3821a28b0b7c2400bc59aba4bcc0a76e971dadd19610d3ad38c768e124dc7","schema_version":"edge-lab-recorder.raw.v1","sequence":null,"source":"clob_market_ws"}
{"event_at":"2026-07-28T03:13:09.663000Z","event_fingerprint":"3e58ccdfceb37cffcadb4b45b6c79f390ea2553b9ae9d535fd9d0c9d7ac97b79","payload":{"connection_id":"a6b55582af5f430fb37ad02bf0922475","event_at":"2026-07-28T03:13:09.663000Z","event_type":"price_change","frame_hash":"101a1580974d8c0ba4d9bf232322e223ab04ae2f146955a9e7bdad7679551d89","frame_index":0,"kind":"data","monotonic_ns":310378435314250,"payload":{"event_type":"price_change","market":"0x779291bef19b6709f61e9764a954aafe9ffae488d50ae674aabdcb4f248006d5","price_changes":[{"asset_id":"14965588658799411272385430903075831224615961675357217884735713260981483529984","best_ask":"0.55","best_bid":"0.54","hash":"c7442e6efb0d0c368706f7fee1fb7cda8ac422df","price":"0.55","side":"SELL","size":"74"},{"asset_id":"8761897749749422724209054078244794145777693856614463256546737399611489089783","best_ask":"0.46","best_bid":"0.45","hash":"8e32cefbb916fe396ba84ae42403eccf0ff42912","price":"0.45","side":"BUY","size":"74"}],"timestamp":"1785208389663"},"payload_hash":"51891181184c61e5ea5916eaec6316f0b6b762dc1c5f54e8200272a33aaf491d","raw_frame":"{\"market\":\"0x779291bef19b6709f61e9764a954aafe9ffae488d50ae674aabdcb4f248006d5\", \"price_changes\":[{\"asset_id\":\"14965588658799411272385430903075831224615961675357217884735713260981483529984\", \"price\":\"0.55\", \"size\":\"74\", \"side\":\"SELL\", \"hash\":\"c7442e6efb0d0c368706f7fee1fb7cda8ac422df\", \"best_bid\":\"0.54\", \"best_ask\":\"0.55\"}, {\"asset_id\":\"8761897749749422724209054078244794145777693856614463256546737399611489089783\", \"price\":\"0.45\", \"size\":\"74\", \"side\":\"BUY\", \"hash\":\"8e32cefbb916fe396ba84ae42403eccf0ff42912\", \"best_bid\":\"0.45\", \"best_ask\":\"0.46\"}], \"timestamp\":\"1785208389663\", \"event_type\":\"price_change\"}","received_at":"2026-07-28T03:13:15.400303Z","schema_version":"clob-market-ws.price_change.v1","sequence":null,"server_hash":null,"server_timestamp":"1785208389663","session_id":"3e519d9098404c15b234d96025eb1a2b","source":"clob_market_ws"},"received_at":"2026-07-28T03:13:15.400303Z","record_id":"312909ce3e7648475b28deab1f57ca434e009b8f5422ad07027eab7f62d87cc0","schema_fingerprint":"4aa3821a28b0b7c2400bc59aba4bcc0a76e971dadd19610d3ad38c768e124dc7","schema_version":"edge-lab-recorder.raw.v1","sequence":null,"source":"clob_market_ws"}
{"event_at":"2026-07-28T03:13:09.663000Z","event_fingerprint":"29fa13d4c79634f8f98c1f0a6e30d7108bc7605dfedc77d82c143a21d73bb46f","payload":{"connection_id":"a6b55582af5f430fb37ad02bf0922475","event_at":"2026-07-28T03:13:09.663000Z","event_type":"price_change","frame_hash":"70c2df14052cc4382e515ece338456070f3435d2e2b7f1e8c4c91f637774f3d3","frame_index":0,"kind":"data","monotonic_ns":310378436893291,"payload":{"event_type":"price_change","market":"0x779291bef19b6709f61e9764a954aafe9ffae488d50ae674aabdcb4f248006d5","price_changes":[{"asset_id":"14965588658799411272385430903075831224615961675357217884735713260981483529984","best_ask":"0.55","best_bid":"0.54","hash":"176f8f17441be1f3f84331441d594c18747fffae","price":"0.48","side":"BUY","size":"81"},{"asset_id":"8761897749749422724209054078244794145777693856614463256546737399611489089783","best_ask":"0.46","best_bid":"0.45","hash":"437ad4a5f3aa90f61dd8fe0d59768db00b5118d1","price":"0.52","side":"SELL","size":"81"}],"timestamp":"1785208389663"},"payload_hash":"7def5faa46d2dd33d966b6653227855b51de960cdfe04f5f4aaf3c59d2c52662","raw_frame":"{\"market\":\"0x779291bef19b6709f61e9764a954aafe9ffae488d50ae674aabdcb4f248006d5\", \"price_changes\":[{\"asset_id\":\"14965588658799411272385430903075831224615961675357217884735713260981483529984\", \"price\":\"0.48\", \"size\":\"81\", \"side\":\"BUY\", \"hash\":\"176f8f17441be1f3f84331441d594c18747fffae\", \"best_bid\":\"0.54\", \"best_ask\":\"0.55\"}, {\"asset_id\":\"8761897749749422724209054078244794145777693856614463256546737399611489089783\", \"price\":\"0.52\", \"size\":\"81\", \"side\":\"SELL\", \"hash\":\"437ad4a5f3aa90f61dd8fe0d59768db00b5118d1\", \"best_bid\":\"0.45\", \"best_ask\":\"0.46\"}], \"timestamp\":\"1785208389663\", \"event_type\":\"price_change\"}","received_at":"2026-07-28T03:13:15.401882Z","schema_version":"clob-market-ws.price_change.v1","sequence":null,"server_hash":null,"server_timestamp":"1785208389663","session_id":"3e519d9098404c15b234d96025eb1a2b","source":"clob_market_ws"},"received_at":"2026-07-28T03:13:15.401882Z","record_id":"dac88f762ff3c2e8ae4fac90dc82ced62eb4162e12e8cfb02f188ba5fe637efc","schema_fingerprint":"4aa3821a28b0b7c2400bc59aba4bcc0a76e971dadd19610d3ad38c768e124dc7","schema_version":"edge-lab-recorder.raw.v1","sequence":null,"source":"clob_market_ws"}
{"event_at":"2026-07-28T03:13:09.664000Z","event_fingerprint":"c4ae161d080aad2632f3f3fa61a6d6b342fe08210399b1e25de864471a52c527","payload":{"connection_id":"a6b55582af5f430fb37ad02bf0922475","event_at":"2026-07-28T03:13:09.664000Z","event_type":"price_change","frame_hash":"cd1d590941a9a200388ed79282081b2eb272b30e1cd6da35b37545b1999235dc","frame_index":0,"kind":"data","monotonic_ns":310378438413583,"payload":{"event_type":"price_change","market":"0x779291bef19b6709f61e9764a954aafe9ffae488d50ae674aabdcb4f248006d5","price_changes":[{"asset_id":"14965588658799411272385430903075831224615961675357217884735713260981483529984","best_ask":"0.55","best_bid":"0.54","hash":"24e27fe6cdac117fe8a016be788bcc6371b96fab","price":"0.46","side":"BUY","size":"87"},{"asset_id":"8761897749749422724209054078244794145777693856614463256546737399611489089783","best_ask":"0.46","best_bid":"0.45","hash":"12313de9a8bb0a7f824fce122d69db3bd44b678e","price":"0.54","side":"SELL","size":"87"}],"timestamp":"1785208389664"},"payload_hash":"36e90107efc3d95770f652bdc5ad2e1f2d6f0ca5f580d6d5f13636123c4caaf6","raw_frame":"{\"market\":\"0x779291bef19b6709f61e9764a954aafe9ffae488d50ae674aabdcb4f248006d5\", \"price_changes\":[{\"asset_id\":\"14965588658799411272385430903075831224615961675357217884735713260981483529984\", \"price\":\"0.46\", \"size\":\"87\", \"side\":\"BUY\", \"hash\":\"24e27fe6cdac117fe8a016be788bcc6371b96fab\", \"best_bid\":\"0.54\", \"best_ask\":\"0.55\"}, {\"asset_id\":\"8761897749749422724209054078244794145777693856614463256546737399611489089783\", \"price\":\"0.54\", \"size\":\"87\", \"side\":\"SELL\", \"hash\":\"12313de9a8bb0a7f824fce122d69db3bd44b678e\", \"best_bid\":\"0.45\", \"best_ask\":\"0.46\"}], \"timestamp\":\"1785208389664\", \"event_type\":\"price_change\"}","received_at":"2026-07-28T03:13:15.403403Z","schema_version":"clob-market-ws.price_change.v1","sequence":null,"server_hash":null,"server_timestamp":"1785208389664","session_id":"3e519d9098404c15b234d96025eb1a2b","source":"clob_market_ws"},"received_at":"2026-07-28T03:13:15.403403Z","record_id":"2a727b8c4b1366232626cbe77178e8132e07bb47ef24e75e0499facf1d65a52a","schema_fingerprint":"4aa3821a28b0b7c2400bc59aba4bcc0a76e971dadd19610d3ad38c768e124dc7","schema_version":"edge-lab-recorder.raw.v1","sequence":null,"source":"clob_market_ws"}
{"event_at":"2026-07-28T03:13:09.664000Z","event_fingerprint":"ea4b2e1c1e8f7289749567f2ccbba7f542831d0252a654446f13e1371e906c1a","payload":{"connection_id":"a6b55582af5f430fb37ad02bf0922475","event_at":"2026-07-28T03:13:09.664000Z","event_type":"price_change","frame_hash":"d87bae786032e429dd0798a5b4ba8797ebb96d4a9c3c3ec0cd03a6a2bf840d9b","frame_index":0,"kind":"data","monotonic_ns":310378439932166,"payload":{"event_type":"price_change","market":"0x779291bef19b6709f61e9764a954aafe9ffae488d50ae674aabdcb4f248006d5","price_changes":[{"asset_id":"8761897749749422724209054078244794145777693856614463256546737399611489089783","best_ask":"0.46","best_bid":"0.45","hash":"12313de9a8bb0a7f824fce122d69db3bd44b678e","price":"0.41","side":"BUY","size":"79"},{"asset_id":"14965588658799411272385430903075831224615961675357217884735713260981483529984","best_ask":"0.55","best_bid":"0.54","hash":"24e27fe6cdac117fe8a016be788bcc6371b96fab","price":"0.59","side":"SELL","size":"79"}],"timestamp":"1785208389664"},"payload_hash":"646336b4830efa09d40bb863e3244ea2b33f9a67bfb11121b94051f26fff48df","raw_frame":"{\"market\":\"0x779291bef19b6709f61e9764a954aafe9ffae488d50ae674aabdcb4f248006d5\", \"price_changes\":[{\"asset_id\":\"8761897749749422724209054078244794145777693856614463256546737399611489089783\", \"price\":\"0.41\", \"size\":\"79\", \"side\":\"BUY\", \"hash\":\"12313de9a8bb0a7f824fce122d69db3bd44b678e\", \"best_bid\":\"0.45\", \"best_ask\":\"0.46\"}, {\"asset_id\":\"14965588658799411272385430903075831224615961675357217884735713260981483529984\", \"price\":\"0.59\", \"size\":\"79\", \"side\":\"SELL\", \"hash\":\"24e27fe6cdac117fe8a016be788bcc6371b96fab\", \"best_bid\":\"0.54\", \"best_ask\":\"0.55\"}], \"timestamp\":\"1785208389664\", \"event_type\":\"price_change\"}","received_at":"2026-07-28T03:13:15.404921Z","schema_version":"clob-market-ws.price_change.v1","sequence":null,"server_hash":null,"server_timestamp":"1785208389664","session_id":"3e519d9098404c15b234d96025eb1a2b","source":"clob_market_ws"},"received_at":"2026-07-28T03:13:15.404921Z","record_id":"54bb26628a45e258565049942860b7ddce9a58fc1ab3ed8e6aee1a37aa35e477","schema_fingerprint":"4aa3821a28b0b7c2400bc59aba4bcc0a76e971dadd19610d3ad38c768e124dc7","schema_version":"edge-lab-recorder.raw.v1","sequence":null,"source":"clob_market_ws"}
{"event_at":"2026-07-28T03:13:09.664000Z","event_fingerprint":"17fc94118f8a27a89fefa3782787b0904d0fc0062e3b2648860e2adcb2758e1d","payload":{"connection_id":"a6b55582af5f430fb37ad02bf0922475","event_at":"2026-07-28T03:13:09.664000Z","event_type":"price_change","frame_hash":"bcbb821bb4a7607ffdcbe2c881e14a6d6786d2a6c3601abb192fed1d8df4f47b","frame_index":0,"kind":"data","monotonic_ns":310378441460000,"payload":{"event_type":"price_change","market":"0x779291bef19b6709f61e9764a954aafe9ffae488d50ae674aabdcb4f248006d5","price_changes":[{"asset_id":"8761897749749422724209054078244794145777693856614463256546737399611489089783","best_ask":"0.46","best_bid":"0.45","hash":"3c52c9b85b7403c9e28b7eec65be62303965b2c7","price":"0.28","side":"BUY","size":"36"},{"asset_id":"14965588658799411272385430903075831224615961675357217884735713260981483529984","best_ask":"0.55","best_bid":"0.54","hash":"f70d4b7bc0e300c1142ea4f926c38d716f1df51b","price":"0.72","side":"SELL","size":"36"}],"timestamp":"1785208389664"},"payload_hash":"85909109f3acb877a4dc1840d3b51499ed98db15d5212aa0b7761a96add5ac51","raw_frame":"{\"market\":\"0x779291bef19b6709f61e9764a954aafe9ffae488d50ae674aabdcb4f248006d5\", \"price_changes\":[{\"asset_id\":\"8761897749749422724209054078244794145777693856614463256546737399611489089783\", \"price\":\"0.28\", \"size\":\"36\", \"side\":\"BUY\", \"hash\":\"3c52c9b85b7403c9e28b7eec65be62303965b2c7\", \"best_bid\":\"0.45\", \"best_ask\":\"0.46\"}, {\"asset_id\":\"14965588658799411272385430903075831224615961675357217884735713260981483529984\", \"price\":\"0.72\", \"size\":\"36\", \"side\":\"SELL\", \"hash\":\"f70d4b7bc0e300c1142ea4f926c38d716f1df51b\", \"best_bid\":\"0.54\", \"best_ask\":\"0.55\"}], \"timestamp\":\"1785208389664\", \"event_type\":\"price_change\"}","received_at":"2026-07-28T03:13:15.406449Z","schema_version":"clob-market-ws.price_change.v1","sequence":null,"server_hash":null,"server_timestamp":"1785208389664","session_id":"3e519d9098404c15b234d96025eb1a2b","source":"clob_market_ws"},"received_at":"2026-07-28T03:13:15.406449Z","record_id":"064150116cd37425bbdafa6b88c72ca80f4626d322db1b5c9c14610b6a3d65c5","schema_fingerprint":"4aa3821a28b0b7c2400bc59aba4bcc0a76e971dadd19610d3ad38c768e124dc7","schema_version":"edge-lab-recorder.raw.v1","sequence":null,"source":"clob_market_ws"}
{"event_at":"2026-07-28T03:13:09.664000Z","event_fingerprint":"155621200261cdd19b89cb7ab3de7df6b258bb2ee72533f6152cb7e925b5facc","payload":{"connection_id":"a6b55582af5f430fb37ad02bf0922475","event_at":"2026-07-28T03:13:09.664000Z","event_type":"price_change","frame_hash":"30edb845a684d367920264d1037f5acc7eeed0d01da18ea80c303d8ee8683ff6","frame_index":0,"kind":"data","monotonic_ns":310378442956708,"payload":{"event_type":"price_change","market":"0x779291bef19b6709f61e9764a954aafe9ffae488d50ae674aabdcb4f248006d5","price_changes":[{"asset_id":"14965588658799411272385430903075831224615961675357217884735713260981483529984","best_ask":"0.55","best_bid":"0.54","hash":"93cb1c46925b4cb91412a41b7af91c1fd6537dfb","price":"0.5","side":"BUY","size":"87.4"},{"asset_id":"8761897749749422724209054078244794145777693856614463256546737399611489089783","best_ask":"0.46","best_bid":"0.45","hash":"50b61f18368499bb5a93933648cc4442ffe1cee7","price":"0.5","side":"SELL","size":"87.4"}],"timestamp":"1785208389664"},"payload_hash":"10b6860e63225a91302013fb5b7f859afa586ecade3591865700e9abb49a2a1e","raw_frame":"{\"market\":\"0x779291bef19b6709f61e9764a954aafe9ffae488d50ae674aabdcb4f248006d5\", \"price_changes\":[{\"asset_id\":\"14965588658799411272385430903075831224615961675357217884735713260981483529984\", \"price\":\"0.5\", \"size\":\"87.4\", \"side\":\"BUY\", \"hash\":\"93cb1c46925b4cb91412a41b7af91c1fd6537dfb\", \"best_bid\":\"0.54\", \"best_ask\":\"0.55\"}, {\"asset_id\":\"8761897749749422724209054078244794145777693856614463256546737399611489089783\", \"price\":\"0.5\", \"size\":\"87.4\", \"side\":\"SELL\", \"hash\":\"50b61f18368499bb5a93933648cc4442ffe1cee7\", \"best_bid\":\"0.45\", \"best_ask\":\"0.46\"}], \"timestamp\":\"1785208389664\", \"event_type\":\"price_change\"}","received_at":"2026-07-28T03:13:15.407946Z","schema_version":"clob-market-ws.price_change.v1","sequence":null,"server_hash":null,"server_timestamp":"1785208389664","session_id":"3e519d9098404c15b234d96025eb1a2b","source":"clob_market_ws"},"received_at":"2026-07-28T03:13:15.407946Z","record_id":"6117e802fade37d8f1d5c1abaee0745588ffcf0eb055622eaeeb8bb8ff304c6b","schema_fingerprint":"4aa3821a28b0b7c2400bc59aba4bcc0a76e971dadd19610d3ad38c768e124dc7","schema_version":"edge-lab-recorder.raw.v1","sequence":null,"source":"clob_market_ws"}
{"event_at":"2026-07-28T03:13:09.665000Z","event_fingerprint":"03acc31b512f717e8c8250d7e9ce88bf4c2642b0aabec7345a1268afc7641fea","payload":{"connection_id":"a6b55582af5f430fb37ad02bf0922475","event_at":"2026-07-28T03:13:09.665000Z","event_type":"price_change","frame_hash":"33e511810f1fc8a5fa32a14f64871d79ca6a8c3b661b68335ef535cc40ac7c71","frame_index":0,"kind":"data","monotonic_ns":310378444474041,"payload":{"event_type":"price_change","market":"0x779291bef19b6709f61e9764a954aafe9ffae488d50ae674aabdcb4f248006d5","price_changes":[{"asset_id":"14965588658799411272385430903075831224615961675357217884735713260981483529984","best_ask":"0.55","best_bid":"0.54","hash":"a4a3036e1e842caaf78aab95338bbf77474f7edc","price":"0.47","side":"BUY","size":"87"},{"asset_id":"8761897749749422724209054078244794145777693856614463256546737399611489089783","best_ask":"0.46","best_bid":"0.45","hash":"22f2791d20b1f371094a14dae47421f2d78e4ed9","price":"0.53","side":"SELL","size":"87"}],"timestamp":"1785208389665"},"payload_hash":"d6abd977cf565f30b0cad1468723bd0c3dccd5c6a9675a4326fef8791f97c410","raw_frame":"{\"market\":\"0x779291bef19b6709f61e9764a954aafe9ffae488d50ae674aabdcb4f248006d5\", \"price_changes\":[{\"asset_id\":\"14965588658799411272385430903075831224615961675357217884735713260981483529984\", \"price\":\"0.47\", \"size\":\"87\", \"side\":\"BUY\", \"hash\":\"a4a3036e1e842caaf78aab95338bbf77474f7edc\", \"best_bid\":\"0.54\", \"best_ask\":\"0.55\"}, {\"asset_id\":\"8761897749749422724209054078244794145777693856614463256546737399611489089783\", \"price\":\"0.53\", \"size\":\"87\", \"side\":\"SELL\", \"hash\":\"22f2791d20b1f371094a14dae47421f2d78e4ed9\", \"best_bid\":\"0.45\", \"best_ask\":\"0.46\"}], \"timestamp\":\"1785208389665\", \"event_type\":\"price_change\"}","received_at":"2026-07-28T03:13:15.409463Z","schema_version":"clob-market-ws.price_change.v1","sequence":null,"server_hash":null,"server_timestamp":"1785208389665","session_id":"3e519d9098404c15b234d96025eb1a2b","source":"clob_market_ws"},"received_at":"2026-07-28T03:13:15.409463Z","record_id":"0e44f51d7c9caefa4d2fc43b76a6e1bf706559444ad32df56828403b380255f5","schema_fingerprint":"4aa3821a28b0b7c2400bc59aba4bcc0a76e971dadd19610d3ad38c768e124dc7","schema_version":"edge-lab-recorder.raw.v1","sequence":null,"source":"clob_market_ws"}
{"event_at":"2026-07-28T03:13:09.668000Z","event_fingerprint":"b9b630faec0c5c666fe22822f87b28abaa59d714fbce77b7813838c8c085254f","payload":{"connection_id":"a6b55582af5f430fb37ad02bf0922475","event_at":"2026-07-28T03:13:09.668000Z","event_type":"price_change","frame_hash":"d6fbac8759b0b3e43b9a4402be7c20cc249836190a5b775c17d979ad7f61bc7c","frame_index":0,"kind":"data","monotonic_ns":310378445980625,"payload":{"event_type":"price_change","market":"0x779291bef19b6709f61e9764a954aafe9ffae488d50ae674aabdcb4f248006d5","price_changes":[{"asset_id":"14965588658799411272385430903075831224615961675357217884735713260981483529984","best_ask":"0.55","best_bid":"0.54","hash":"d8b65e389f56d87e51569e95e0100b09921a16e8","price":"0.5","side":"BUY","size":"81.6"},{"asset_id":"8761897749749422724209054078244794145777693856614463256546737399611489089783","best_ask":"0.46","best_bid":"0.45","hash":"57787bd2aacb058e438c5ebf619b732e7db03f2a","price":"0.5","side":"SELL","size":"81.6"}],"timestamp":"1785208389668"},"payload_hash":"8cb361e2c248b562c5b37c63985429c96032d939e2441b0131c05ee68de02e24","raw_frame":"{\"market\":\"0x779291bef19b6709f61e9764a954aafe9ffae488d50ae674aabdcb4f248006d5\", \"price_changes\":[{\"asset_id\":\"14965588658799411272385430903075831224615961675357217884735713260981483529984\", \"price\":\"0.5\", \"size\":\"81.6\", \"side\":\"BUY\", \"hash\":\"d8b65e389f56d87e51569e95e0100b09921a16e8\", \"best_bid\":\"0.54\", \"best_ask\":\"0.55\"}, {\"asset_id\":\"8761897749749422724209054078244794145777693856614463256546737399611489089783\", \"price\":\"0.5\", \"size\":\"81.6\", \"side\":\"SELL\", \"hash\":\"57787bd2aacb058e438c5ebf619b732e7db03f2a\", \"best_bid\":\"0.45\", \"best_ask\":\"0.46\"}], \"timestamp\":\"1785208389668\", \"event_type\":\"price_change\"}","received_at":"2026-07-28T03:13:15.410970Z","schema_version":"clob-market-ws.price_change.v1","sequence":null,"server_hash":null,"server_timestamp":"1785208389668","session_id":"3e519d9098404c15b234d96025eb1a2b","source":"clob_market_ws"},"received_at":"2026-07-28T03:13:15.410970Z","record_id":"975d72bea5114460d885b86150ae8856c0bd7c11a0b867e1ccf49336610bef5e","schema_fingerprint":"4aa3821a28b0b7c2400bc59aba4bcc0a76e971dadd19610d3ad38c768e124dc7","schema_version":"edge-lab-recorder.raw.v1","sequence":null,"source":"clob_market_ws"}
{"event_at":"2026-07-28T03:13:09.672000Z","event_fingerprint":"23658b0ea32a0d82b137b2752cf6dffd75a90fbf795c47ef15c8dcbdc1880e29","payload":{"connection_id":"a6b55582af5f430fb37ad02bf0922475","event_at":"2026-07-28T03:13:09.672000Z","event_type":"price_change","frame_hash":"4e8b288739f78b29325ceda635da3b06d34ff7e0f7b9c058fe0b18305319e192","frame_index":0,"kind":"data","monotonic_ns":310378447538541,"payload":{"event_type":"price_change","market":"0x779291bef19b6709f61e9764a954aafe9ffae488d50ae674aabdcb4f248006d5","price_changes":[{"asset_id":"14965588658799411272385430903075831224615961675357217884735713260981483529984","best_ask":"0.55","best_bid":"0.54","hash":"55f72b52e2a6f93fbd15eb324767524a8f8278e8","price":"0.52","side":"BUY","size":"30"},{"asset_id":"8761897749749422724209054078244794145777693856614463256546737399611489089783","best_ask":"0.46","best_bid":"0.45","hash":"8dc824cc52de6bc880788e376d910be3f512cd27","price":"0.48","side":"SELL","size":"30"}],"timestamp":"1785208389672"},"payload_hash":"5c9f9d8e44ddbd542114eab66e080da3224a9b88ccf0c020d69fc181b3e9214f","raw_frame":"{\"market\":\"0x779291bef19b6709f61e9764a954aafe9ffae488d50ae674aabdcb4f248006d5\", \"price_changes\":[{\"asset_id\":\"14965588658799411272385430903075831224615961675357217884735713260981483529984\", \"price\":\"0.52\", \"size\":\"30\", \"side\":\"BUY\", \"hash\":\"55f72b52e2a6f93fbd15eb324767524a8f8278e8\", \"best_bid\":\"0.54\", \"best_ask\":\"0.55\"}, {\"asset_id\":\"8761897749749422724209054078244794145777693856614463256546737399611489089783\", \"price\":\"0.48\", \"size\":\"30\", \"side\":\"SELL\", \"hash\":\"8dc824cc52de6bc880788e376d910be3f512cd27\", \"best_bid\":\"0.45\", \"best_ask\":\"0.46\"}], \"timestamp\":\"1785208389672\", \"event_type\":\"price_change\"}","received_at":"2026-07-28T03:13:15.412525Z","schema_version":"clob-market-ws.price_change.v1","sequence":null,"server_hash":null,"server_timestamp":"1785208389672","session_id":"3e519d9098404c15b234d96025eb1a2b","source":"clob_market_ws"},"received_at":"2026-07-28T03:13:15.412525Z","record_id":"fd3ea1e248903f639e792de09a59d8e0e86beb125c5966d4439fe2cf1a0be875","schema_fingerprint":"4aa3821a28b0b7c2400bc59aba4bcc0a76e971dadd19610d3ad38c768e124dc7","schema_version":"edge-lab-recorder.raw.v1","sequence":null,"source":"clob_market_ws"}
{"event_at":"2026-07-28T03:13:09.672000Z","event_fingerprint":"ff1caa1300bc5d55fd98609efcddcc358f265df94fd36631531efd30fa0d34de","payload":{"connection_id":"a6b55582af5f430fb37ad02bf0922475","event_at":"2026-07-28T03:13:09.672000Z","event_type":"price_change","frame_hash":"e2924bf56aedd2f8efd52a9b30a440a014fdb26f15bb21ea53eafcaa44df367a","frame_index":0,"kind":"data","monotonic_ns":310378449217750,"payload":{"event_type":"price_change","market":"0x779291bef19b6709f61e9764a954aafe9ffae488d50ae674aabdcb4f248006d5","price_changes":[{"asset_id":"8761897749749422724209054078244794145777693856614463256546737399611489089783","best_ask":"0.46","best_bid":"0.45","hash":"19caf7c9f9ba378b461063f847f905075e25414e","price":"0.12","side":"BUY","size":"247"},{"asset_id":"14965588658799411272385430903075831224615961675357217884735713260981483529984","best_ask":"0.55","best_bid":"0.54","hash":"fd5739c3b76445ff5e56765e92364d3c85bb0a47","price":"0.88","side":"SELL","size":"247"}],"timestamp":"1785208389672"},"payload_hash":"56ce9aff6d66ab22561812faa9c93bf029378a014b29d2d896fc440b7cd34455","raw_frame":"{\"market\":\"0x779291bef19b6709f61e9764a954aafe9ffae488d50ae674aabdcb4f248006d5\", \"price_changes\":[{\"asset_id\":\"8761897749749422724209054078244794145777693856614463256546737399611489089783\", \"price\":\"0.12\", \"size\":\"247\", \"side\":\"BUY\", \"hash\":\"19caf7c9f9ba378b461063f847f905075e25414e\", \"best_bid\":\"0.45\", \"best_ask\":\"0.46\"}, {\"asset_id\":\"14965588658799411272385430903075831224615961675357217884735713260981483529984\", \"price\":\"0.88\", \"size\":\"247\", \"side\":\"SELL\", \"hash\":\"fd5739c3b76445ff5e56765e92364d3c85bb0a47\", \"best_bid\":\"0.54\", \"best_ask\":\"0.55\"}], \"timestamp\":\"1785208389672\", \"event_type\":\"price_change\"}","received_at":"2026-07-28T03:13:15.414203Z","schema_version":"clob-market-ws.price_change.v1","sequence":null,"server_hash":null,"server_timestamp":"1785208389672","session_id":"3e519d9098404c15b234d96025eb1a2b","source":"clob_market_ws"},"received_at":"2026-07-28T03:13:15.414203Z","record_id":"11a30e127b3d8e8e4418c965c608c77fc34014e62e2903f2f3de593119583ede","schema_fingerprint":"4aa3821a28b0b7c2400bc59aba4bcc0a76e971dadd19610d3ad38c768e124dc7","schema_version":"edge-lab-recorder.raw.v1","sequence":null,"source":"clob_market_ws"}
{"event_at":"2026-07-28T03:13:09.674000Z","event_fingerprint":"5a64f66e266c8924a4a740cfe149e8b5fafcd413424c3e313d277b50823835e1","payload":{"connection_id":"a6b55582af5f430fb37ad02bf0922475","event_at":"2026-07-28T03:13:09.674000Z","event_type":"price_change","frame_hash":"a5392d9dffaf088ac20d06c5c60db0906d1a26a288b8e0a353f58cc613ca9a84","frame_index":0,"kind":"data","monotonic_ns":310378450826291,"payload":{"event_type":"price_change","market":"0x779291bef19b6709f61e9764a954aafe9ffae488d50ae674aabdcb4f248006d5","price_changes":[{"asset_id":"14965588658799411272385430903075831224615961675357217884735713260981483529984","best_ask":"0.55","best_bid":"0.54","hash":"8b90f312815ebf89c73cb4cb5ed595daef6b37e5","price":"0.26","side":"BUY","size":"36"},{"asset_id":"8761897749749422724209054078244794145777693856614463256546737399611489089783","best_ask":"0.46","best_bid":"0.45","hash":"ac203496c6180da8066e45bf76e643f99fb08c6d","price":"0.74","side":"SELL","size":"36"}],"timestamp":"1785208389674"},"payload_hash":"37bc90fab349d72c13b56c6814ff772c0338ac44d884c9897673a1409e342f90","raw_frame":"{\"market\":\"0x779291bef19b6709f61e9764a954aafe9ffae488d50ae674aabdcb4f248006d5\", \"price_changes\":[{\"asset_id\":\"14965588658799411272385430903075831224615961675357217884735713260981483529984\", \"price\":\"0.26\", \"size\":\"36\", \"side\":\"BUY\", \"hash\":\"8b90f312815ebf89c73cb4cb5ed595daef6b37e5\", \"best_bid\":\"0.54\", \"best_ask\":\"0.55\"}, {\"asset_id\":\"8761897749749422724209054078244794145777693856614463256546737399611489089783\", \"price\":\"0.74\", \"size\":\"36\", \"side\":\"SELL\", \"hash\":\"ac203496c6180da8066e45bf76e643f99fb08c6d\", \"best_bid\":\"0.45\", \"best_ask\":\"0.46\"}], \"timestamp\":\"1785208389674\", \"event_type\":\"price_change\"}","received_at":"2026-07-28T03:13:15.415814Z","schema_version":"clob-market-ws.price_change.v1","sequence":null,"server_hash":null,"server_timestamp":"1785208389674","session_id":"3e519d9098404c15b234d96025eb1a2b","source":"clob_market_ws"},"received_at":"2026-07-28T03:13:15.415814Z","record_id":"b06db74a75a68fe0c6f48fe2dc5f1d0a1aaf4bac9bad1c99933abdbfd290b52c","schema_fingerprint":"4aa3821a28b0b7c2400bc59aba4bcc0a76e971dadd19610d3ad38c768e124dc7","schema_version":"edge-lab-recorder.raw.v1","sequence":null,"source":"clob_market_ws"}
{"event_at":"2026-07-28T03:13:09.675000Z","event_fingerprint":"4344c42f99398f08cf7d50e8c9eac4ec11eeb262a344bb9c1eda7feebfa1ff4b","payload":{"connection_id":"a6b55582af5f430fb37ad02bf0922475","event_at":"2026-07-28T03:13:09.675000Z","event_type":"price_change","frame_hash":"443e1cbb48ce0fb6280e4b6f5136500123c038b3ad27e35775be6253b1ee4145","frame_index":0,"kind":"data","monotonic_ns":310378452445583,"payload":{"event_type":"price_change","market":"0x779291bef19b6709f61e9764a954aafe9ffae488d50ae674aabdcb4f248006d5","price_changes":[{"asset_id":"8761897749749422724209054078244794145777693856614463256546737399611489089783","best_ask":"0.46","best_bid":"0.45","hash":"d1541e2fdfffb8ab6eb59fa27416fb2c11df13df","price":"0.43","side":"BUY","size":"30"},{"asset_id":"14965588658799411272385430903075831224615961675357217884735713260981483529984","best_ask":"0.55","best_bid":"0.54","hash":"6bc0c0fbb947bba1335c895563c9ec3481132b4f","price":"0.57","side":"SELL","size":"30"}],"timestamp":"1785208389675"},"payload_hash":"953c7fa605356963bd7b55823813fea5d2f981d6d37310d9e17e31e439a56a12","raw_frame":"{\"market\":\"0x779291bef19b6709f61e9764a954aafe9ffae488d50ae674aabdcb4f248006d5\", \"price_changes\":[{\"asset_id\":\"8761897749749422724209054078244794145777693856614463256546737399611489089783\", \"price\":\"0.43\", \"size\":\"30\", \"side\":\"BUY\", \"hash\":\"d1541e2fdfffb8ab6eb59fa27416fb2c11df13df\", \"best_bid\":\"0.45\", \"best_ask\":\"0.46\"}, {\"asset_id\":\"14965588658799411272385430903075831224615961675357217884735713260981483529984\", \"price\":\"0.57\", \"size\":\"30\", \"side\":\"SELL\", \"hash\":\"6bc0c0fbb947bba1335c895563c9ec3481132b4f\", \"best_bid\":\"0.54\", \"best_ask\":\"0.55\"}], \"timestamp\":\"1785208389675\", \"event_type\":\"price_change\"}","received_at":"2026-07-28T03:13:15.417434Z","schema_version":"clob-market-ws.price_change.v1","sequence":null,"server_hash":null,"server_timestamp":"1785208389675","session_id":"3e519d9098404c15b234d96025eb1a2b","source":"clob_market_ws"},"received_at":"2026-07-28T03:13:15.417434Z","record_id":"a004c8cac338017d3bb88790e3369e7be54c3c76522c4fc7e20658b8983ef194","schema_fingerprint":"4aa3821a28b0b7c2400bc59aba4bcc0a76e971dadd19610d3ad38c768e124dc7","schema_version":"edge-lab-recorder.raw.v1","sequence":null,"source":"clob_market_ws"}
{"event_at":"2026-07-28T03:13:09.677000Z","event_fingerprint":"d18cb327b36cdbf70e5afaa8c412e5583333c9037bd185e0b8e268f55d47274f","payload":{"connection_id":"a6b55582af5f430fb37ad02bf0922475","event_at":"2026-07-28T03:13:09.677000Z","event_type":"price_change","frame_hash":"c3ca2a56a043460b0b5d417468dd4a4fea394fc6fd2886631d4de36e2c27b9db","frame_index":0,"kind":"data","monotonic_ns":310378453995500,"payload":{"event_type":"price_change","market":"0x779291bef19b6709f61e9764a954aafe9ffae488d50ae674aabdcb4f248006d5","price_changes":[{"asset_id":"8761897749749422724209054078244794145777693856614463256546737399611489089783","best_ask":"0.46","best_bid":"0.45","hash":"ab3a6dcb29d28f4c58d4644a68af32e7287ef489","price":"0.45","side":"BUY","size":"30"},{"asset_id":"14965588658799411272385430903075831224615961675357217884735713260981483529984","best_ask":"0.55","best_bid":"0.54","hash":"88b92bbb0a891e9caf886997ac00a9506137df0f","price":"0.55","side":"SELL","size":"30"}],"timestamp":"1785208389677"},"payload_hash":"25950580d80d5959ab51ddd47461044183f1bfd44d9fb77814676b5d7ccf43bb","raw_frame":"{\"market\":\"0x779291bef19b6709f61e9764a954aafe9ffae488d50ae674aabdcb4f248006d5\", \"price_changes\":[{\"asset_id\":\"8761897749749422724209054078244794145777693856614463256546737399611489089783\", \"price\":\"0.45\", \"size\":\"30\", \"side\":\"BUY\", \"hash\":\"ab3a6dcb29d28f4c58d4644a68af32e7287ef489\", \"best_bid\":\"0.45\", \"best_ask\":\"0.46\"}, {\"asset_id\":\"14965588658799411272385430903075831224615961675357217884735713260981483529984\", \"price\":\"0.55\", \"size\":\"30\", \"side\":\"SELL\", \"hash\":\"88b92bbb0a891e9caf886997ac00a9506137df0f\", \"best_bid\":\"0.54\", \"best_ask\":\"0.55\"}], \"timestamp\":\"1785208389677\", \"event_type\":\"price_change\"}","received_at":"2026-07-28T03:13:15.418983Z","schema_version":"clob-market-ws.price_change.v1","sequence":null,"server_hash":null,"server_timestamp":"1785208389677","session_id":"3e519d9098404c15b234d96025eb1a2b","source":"clob_market_ws"},"received_at":"2026-07-28T03:13:15.418983Z","record_id":"6c630d9ad2ba0240d6306df7361d16bfc92a2e57b753dba3c410e1e52ab40a03","schema_fingerprint":"4aa3821a28b0b7c2400bc59aba4bcc0a76e971dadd19610d3ad38c768e124dc7","schema_version":"edge-lab-recorder.raw.v1","sequence":null,"source":"clob_market_ws"}
{"event_at":"2026-07-28T03:13:09.677000Z","event_fingerprint":"5a4acbf5c920e102df12533b5d97d4e2d1b4a40a06e0191d69fe79e6ce69f77f","payload":{"connection_id":"a6b55582af5f430fb37ad02bf0922475","event_at":"2026-07-28T03:13:09.677000Z","event_type":"price_change","frame_hash":"265f24eec62ca72d81a0d0a1e4344c6281f0fb37c6c79a0c6743191ffefb026b","frame_index":0,"kind":"data","monotonic_ns":310378455571958,"payload":{"event_type":"price_change","market":"0x779291bef19b6709f61e9764a954aafe9ffae488d50ae674aabdcb4f248006d5","price_changes":[{"asset_id":"14965588658799411272385430903075831224615961675357217884735713260981483529984","best_ask":"0.55","best_bid":"0.54","hash":"86e87099d3b97f27bc0711f5371b0feb64ca2328","price":"0.5","side":"BUY","size":"75.8"},{"asset_id":"8761897749749422724209054078244794145777693856614463256546737399611489089783","best_ask":"0.46","best_bid":"0.45","hash":"105e7b63e2c8d0197314f6c1286d4897ddb091e8","price":"0.5","side":"SELL","size":"75.8"}],"timestamp":"1785208389677"},"payload_hash":"3d3f35f31fc729ef5ed7ab2e90855ed46ad2a64b142a39112bb6616574fdeb14","raw_frame":"{\"market\":\"0x779291bef19b6709f61e9764a954aafe9ffae488d50ae674aabdcb4f248006d5\", \"price_changes\":[{\"asset_id\":\"14965588658799411272385430903075831224615961675357217884735713260981483529984\", \"price\":\"0.5\", \"size\":\"75.8\", \"side\":\"BUY\", \"hash\":\"86e87099d3b97f27bc0711f5371b0feb64ca2328\", \"best_bid\":\"0.54\", \"best_ask\":\"0.55\"}, {\"asset_id\":\"8761897749749422724209054078244794145777693856614463256546737399611489089783\", \"price\":\"0.5\", \"size\":\"75.8\", \"side\":\"SELL\", \"hash\":\"105e7b63e2c8d0197314f6c1286d4897ddb091e8\", \"best_bid\":\"0.45\", \"best_ask\":\"0.46\"}], \"timestamp\":\"1785208389677\", \"event_type\":\"price_change\"}","received_at":"2026-07-28T03:13:15.420560Z","schema_version":"clob-market-ws.price_change.v1","sequence":null,"server_hash":null,"server_timestamp":"1785208389677","session_id":"3e519d9098404c15b234d96025eb1a2b","source":"clob_market_ws"},"received_at":"2026-07-28T03:13:15.420560Z","record_id":"4738ef0dd1b19a67d84e955bcfb5a30faf6e29ecf2b99a196b6db0e063d73562","schema_fingerprint":"4aa3821a28b0b7c2400bc59aba4bcc0a76e971dadd19610d3ad38c768e124dc7","schema_version":"edge-lab-recorder.raw.v1","sequence":null,"source":"clob_market_ws"}
{"event_at":"2026-07-28T03:13:09.678000Z","event_fingerprint":"a769582d272cd8c0dc49e9f56dc0a12a9ebb4dc6da3c639f58a6282be7d96f76","payload":{"connection_id":"a6b55582af5f430fb37ad02bf0922475","event_at":"2026-07-28T03:13:09.678000Z","event_type":"price_change","frame_hash":"4f906921ac83f24ab532146623788df2faa112f27a1b8b05cb31fc3b43e73366","frame_index":0,"kind":"data","monotonic_ns":310378457123958,"payload":{"event_type":"price_change","market":"0x779291bef19b6709f61e9764a954aafe9ffae488d50ae674aabdcb4f248006d5","price_changes":[{"asset_id":"14965588658799411272385430903075831224615961675357217884735713260981483529984","best_ask":"0.55","best_bid":"0.54","hash":"7deca3e99d69f05af9077b0f71bff4b64514a4b9","price":"0.39","side":"BUY","size":"146"},{"asset_id":"8761897749749422724209054078244794145777693856614463256546737399611489089783","best_ask":"0.46","best_bid":"0.45","hash":"afb3261be2bba767e990bca28dbc66ecd5360dba","price":"0.61","side":"SELL","size":"146"}],"timestamp":"1785208389678"},"payload_hash":"f810946d6a12e9234a0ec53ca5479d8e7eb8bdfa13859ee7d2c5914f0be52951","raw_frame":"{\"market\":\"0x779291bef19b6709f61e9764a954aafe9ffae488d50ae674aabdcb4f248006d5\", \"price_changes\":[{\"asset_id\":\"14965588658799411272385430903075831224615961675357217884735713260981483529984\", \"price\":\"0.39\", \"size\":\"146\", \"side\":\"BUY\", \"hash\":\"7deca3e99d69f05af9077b0f71bff4b64514a4b9\", \"best_bid\":\"0.54\", \"best_ask\":\"0.55\"}, {\"asset_id\":\"8761897749749422724209054078244794145777693856614463256546737399611489089783\", \"price\":\"0.61\", \"size\":\"146\", \"side\":\"SELL\", \"hash\":\"afb3261be2bba767e990bca28dbc66ecd5360dba\", \"best_bid\":\"0.45\", \"best_ask\":\"0.46\"}], \"timestamp\":\"1785208389678\", \"event_type\":\"price_change\"}","received_at":"2026-07-28T03:13:15.422112Z","schema_version":"clob-market-ws.price_change.v1","sequence":null,"server_hash":null,"server_timestamp":"1785208389678","session_id":"3e519d9098404c15b234d96025eb1a2b","source":"clob_market_ws"},"received_at":"2026-07-28T03:13:15.422112Z","record_id":"99de70e8b3e62290cb3f61b18edf3c285ec3bd2cc5faee111fe67b4f7d5ec3c5","schema_fingerprint":"4aa3821a28b0b7c2400bc59aba4bcc0a76e971dadd19610d3ad38c768e124dc7","schema_version":"edge-lab-recorder.raw.v1","sequence":null,"source":"clob_market_ws"}
{"event_at":"2026-07-28T03:13:09.679000Z","event_fingerprint":"c8b29855ea86d5d36569326a108cd4ffdf0a2ff1b750fe3462b56acafc036bf2","payload":{"connection_id":"a6b55582af5f430fb37ad02bf0922475","event_at":"2026-07-28T03:13:09.679000Z","event_type":"price_change","frame_hash":"ddc0bd5984aa4cb69d9463c3dcb7e7b7c61aa9729df47ebd96b909649856821f","frame_index":0,"kind":"data","monotonic_ns":310378458630291,"payload":{"event_type":"price_change","market":"0x779291bef19b6709f61e9764a954aafe9ffae488d50ae674aabdcb4f248006d5","price_changes":[{"asset_id":"14965588658799411272385430903075831224615961675357217884735713260981483529984","best_ask":"0.55","best_bid":"0.54","hash":"4173d2cf0b3443e454e95243bba3f8e14b1415b6","price":"0.38","side":"BUY","size":"118"},{"asset_id":"8761897749749422724209054078244794145777693856614463256546737399611489089783","best_ask":"0.46","best_bid":"0.45","hash":"f8c0c178053c121dbf8a7fb478da3a4d20592649","price":"0.62","side":"SELL","size":"118"}],"timestamp":"1785208389679"},"payload_hash":"4ce4f0506243773f56c2e4806d998c399fa5696cc44503800898c31377b1d95b","raw_frame":"{\"market\":\"0x779291bef19b6709f61e9764a954aafe9ffae488d50ae674aabdcb4f248006d5\", \"price_changes\":[{\"asset_id\":\"14965588658799411272385430903075831224615961675357217884735713260981483529984\", \"price\":\"0.38\", \"size\":\"118\", \"side\":\"BUY\", \"hash\":\"4173d2cf0b3443e454e95243bba3f8e14b1415b6\", \"best_bid\":\"0.54\", \"best_ask\":\"0.55\"}, {\"asset_id\":\"8761897749749422724209054078244794145777693856614463256546737399611489089783\", \"price\":\"0.62\", \"size\":\"118\", \"side\":\"SELL\", \"hash\":\"f8c0c178053c121dbf8a7fb478da3a4d20592649\", \"best_bid\":\"0.45\", \"best_ask\":\"0.46\"}], \"timestamp\":\"1785208389679\", \"event_type\":\"price_change\"}","received_at":"2026-07-28T03:13:15.423620Z","schema_version":"clob-market-ws.price_change.v1","sequence":null,"server_hash":null,"server_timestamp":"1785208389679","session_id":"3e519d9098404c15b234d96025eb1a2b","source":"clob_market_ws"},"received_at":"2026-07-28T03:13:15.423620Z","record_id":"9afe95877ee3dfe03bb4e6cf8a2d69e4200080b0a9bc029085f2129cc33ab33c","schema_fingerprint":"4aa3821a28b0b7c2400bc59aba4bcc0a76e971dadd19610d3ad38c768e124dc7","schema_version":"edge-lab-recorder.raw.v1","sequence":null,"source":"clob_market_ws"}
{"event_at":"2026-07-28T03:13:09.679000Z","event_fingerprint":"00c9aa32ca1cfdb58abb67e30420e914fec5563036b44a317bd024008b119c70","payload":{"connection_id":"a6b55582af5f430fb37ad02bf0922475","event_at":"2026-07-28T03:13:09.679000Z","event_type":"price_change","frame_hash":"ddbcf2e7c9838f016df9a76df5a66871cb185b2c39453ac3c971881c39a32507","frame_index":0,"kind":"data","monotonic_ns":310378460129625,"payload":{"event_type":"price_change","market":"0x779291bef19b6709f61e9764a954aafe9ffae488d50ae674aabdcb4f248006d5","price_changes":[{"asset_id":"14965588658799411272385430903075831224615961675357217884735713260981483529984","best_ask":"0.55","best_bid":"0.54","hash":"64936787b120337d1297b7146dd5ca2c0073ac96","price":"0.5","side":"BUY","size":"70"},{"asset_id":"8761897749749422724209054078244794145777693856614463256546737399611489089783","best_ask":"0.46","best_bid":"0.45","hash":"a494a6b091b05e52bcb2ea3bf2135c65f28547e2","price":"0.5","side":"SELL","size":"70"}],"timestamp":"1785208389679"},"payload_hash":"ec73d049ed507ff83331732b916ed62f32eda1f6adf83ab5dd094aa0bfca985a","raw_frame":"{\"market\":\"0x779291bef19b6709f61e9764a954aafe9ffae488d50ae674aabdcb4f248006d5\", \"price_changes\":[{\"asset_id\":\"14965588658799411272385430903075831224615961675357217884735713260981483529984\", \"price\":\"0.5\", \"size\":\"70\", \"side\":\"BUY\", \"hash\":\"64936787b120337d1297b7146dd5ca2c0073ac96\", \"best_bid\":\"0.54\", \"best_ask\":\"0.55\"}, {\"asset_id\":\"8761897749749422724209054078244794145777693856614463256546737399611489089783\", \"price\":\"0.5\", \"size\":\"70\", \"side\":\"SELL\", \"hash\":\"a494a6b091b05e52bcb2ea3bf2135c65f28547e2\", \"best_bid\":\"0.45\", \"best_ask\":\"0.46\"}], \"timestamp\":\"1785208389679\", \"event_type\":\"price_change\"}","received_at":"2026-07-28T03:13:15.425119Z","schema_version":"clob-market-ws.price_change.v1","sequence":null,"server_hash":null,"server_timestamp":"1785208389679","session_id":"3e519d9098404c15b234d96025eb1a2b","source":"clob_market_ws"},"received_at":"2026-07-28T03:13:15.425119Z","record_id":"8ca49c9ed4a1c1c4ca90cf18b22d8b5513ddbd8902e36a11911413993351225c","schema_fingerprint":"4aa3821a28b0b7c2400bc59aba4bcc0a76e971dadd19610d3ad38c768e124dc7","schema_version":"edge-lab-recorder.raw.v1","sequence":null,"source":"clob_market_ws"}
{"event_at":"2026-07-28T03:13:09.679000Z","event_fingerprint":"fac239df5cb4df495cfa9a70537529290d40ea259f90a9bc078dd94bbf4d4a4a","payload":{"connection_id":"a6b55582af5f430fb37ad02bf0922475","event_at":"2026-07-28T03:13:09.679000Z","event_type":"price_change","frame_hash":"3757cd3dbb7d75d0066ac8e9307acd35deac70086e70adf3d08067a4e71da24e","frame_index":0,"kind":"data","monotonic_ns":310378461636083,"payload":{"event_type":"price_change","market":"0x779291bef19b6709f61e9764a954aafe9ffae488d50ae674aabdcb4f248006d5","price_changes":[{"asset_id":"14965588658799411272385430903075831224615961675357217884735713260981483529984","best_ask":"0.55","best_bid":"0.54","hash":"17866f627e26838f59d338abf6ada25b1c6f0790","price":"0.27","side":"BUY","size":"36"},{"asset_id":"8761897749749422724209054078244794145777693856614463256546737399611489089783","best_ask":"0.46","best_bid":"0.45","hash":"686c0941bb0cadb842cc09c73d36e207be0b1738","price":"0.73","side":"SELL","size":"36"}],"timestamp":"1785208389679"},"payload_hash":"a3b6cb88ccea13306b9e2f518ba4e78d4231390d0f28b4d8e5da0d883b8a454f","raw_frame":"{\"market\":\"0x779291bef19b6709f61e9764a954aafe9ffae488d50ae674aabdcb4f248006d5\", \"price_changes\":[{\"asset_id\":\"14965588658799411272385430903075831224615961675357217884735713260981483529984\", \"price\":\"0.27\", \"size\":\"36\", \"side\":\"BUY\", \"hash\":\"17866f627e26838f59d338abf6ada25b1c6f0790\", \"best_bid\":\"0.54\", \"best_ask\":\"0.55\"}, {\"asset_id\":\"8761897749749422724209054078244794145777693856614463256546737399611489089783\", \"price\":\"0.73\", \"size\":\"36\", \"side\":\"SELL\", \"hash\":\"686c0941bb0cadb842cc09c73d36e207be0b1738\", \"best_bid\":\"0.45\", \"best_ask\":\"0.46\"}], \"timestamp\":\"1785208389679\", \"event_type\":\"price_change\"}","received_at":"2026-07-28T03:13:15.426625Z","schema_version":"clob-market-ws.price_change.v1","sequence":null,"server_hash":null,"server_timestamp":"1785208389679","session_id":"3e519d9098404c15b234d96025eb1a2b","source":"clob_market_ws"},"received_at":"2026-07-28T03:13:15.426625Z","record_id":"d9a73786081563ac0cc83b77819d3f908dfdcbc3aa8a02247a336bc5fd19fa26","schema_fingerprint":"4aa3821a28b0b7c2400bc59aba4bcc0a76e971dadd19610d3ad38c768e124dc7","schema_version":"edge-lab-recorder.raw.v1","sequence":null,"source":"clob_market_ws"}
{"event_at":"2026-07-28T03:13:09.681000Z","event_fingerprint":"4b7787ba9c1e1b116d34d10cc65225ba2b231ac24f0434a36570057029388ca5","payload":{"connection_id":"a6b55582af5f430fb37ad02bf0922475","event_at":"2026-07-28T03:13:09.681000Z","event_type":"price_change","frame_hash":"42127ed00657a726dd1fc9336fbc0c61e4d6a9a1d1562470363b4f636367a121","frame_index":0,"kind":"data","monotonic_ns":310378463125750,"payload":{"event_type":"price_change","market":"0x779291bef19b6709f61e9764a954aafe9ffae488d50ae674aabdcb4f248006d5","price_changes":[{"asset_id":"8761897749749422724209054078244794145777693856614463256546737399611489089783","best_ask":"0.46","best_bid":"0.45","hash":"22f8e2058fd665db71b2bd542f0a6b1645ebe57c","price":"0.68","side":"SELL","size":"64.21"},{"asset_id":"14965588658799411272385430903075831224615961675357217884735713260981483529984","best_ask":"0.55","best_bid":"0.54","hash":"a871b561aa5a71bea23aff0dd3a07fe31d063f39","price":"0.32","side":"BUY","size":"64.21"}],"timestamp":"1785208389681"},"payload_hash":"da5038c480554d98c7552974f63556ca24bbad44ee4c7a37d462f2a89085c4ca","raw_frame":"{\"market\":\"0x779291bef19b6709f61e9764a954aafe9ffae488d50ae674aabdcb4f248006d5\", \"price_changes\":[{\"asset_id\":\"8761897749749422724209054078244794145777693856614463256546737399611489089783\", \"price\":\"0.68\", \"size\":\"64.21\", \"side\":\"SELL\", \"hash\":\"22f8e2058fd665db71b2bd542f0a6b1645ebe57c\", \"best_bid\":\"0.45\", \"best_ask\":\"0.46\"}, {\"asset_id\":\"14965588658799411272385430903075831224615961675357217884735713260981483529984\", \"price\":\"0.32\", \"size\":\"64.21\", \"side\":\"BUY\", \"hash\":\"a871b561aa5a71bea23aff0dd3a07fe31d063f39\", \"best_bid\":\"0.54\", \"best_ask\":\"0.55\"}], \"timestamp\":\"1785208389681\", \"event_type\":\"price_change\"}","received_at":"2026-07-28T03:13:15.428115Z","schema_version":"clob-market-ws.price_change.v1","sequence":null,"server_hash":null,"server_timestamp":"1785208389681","session_id":"3e519d9098404c15b234d96025eb1a2b","source":"clob_market_ws"},"received_at":"2026-07-28T03:13:15.428115Z","record_id":"2d23b301e51333c1751188b34ad6048ec35f118a77aa35408e7d0c6bfd71ae63","schema_fingerprint":"4aa3821a28b0b7c2400bc59aba4bcc0a76e971dadd19610d3ad38c768e124dc7","schema_version":"edge-lab-recorder.raw.v1","sequence":null,"source":"clob_market_ws"}
{"event_at":"2026-07-28T03:13:09.683000Z","event_fingerprint":"7e47bec897be2235a2746558d8f24b9c31b28407985f06e82bca5c0b77a0dfeb","payload":{"connection_id":"a6b55582af5f430fb37ad02bf0922475","event_at":"2026-07-28T03:13:09.683000Z","event_type":"price_change","frame_hash":"cbdb704cc2af41054a1b4a833a0321d0a3f0aaf187fb7d96e0ea567047a1402d","frame_index":0,"kind":"data","monotonic_ns":310378464629250,"payload":{"event_type":"price_change","market":"0x779291bef19b6709f61e9764a954aafe9ffae488d50ae674aabdcb4f248006d5","price_changes":[{"asset_id":"8761897749749422724209054078244794145777693856614463256546737399611489089783","best_ask":"0.46","best_bid":"0.45","hash":"b12eecdea4b1bbe9f30d98a2e632b1e12054dae5","price":"0.44","side":"BUY","size":"30"},{"asset_id":"14965588658799411272385430903075831224615961675357217884735713260981483529984","best_ask":"0.55","best_bid":"0.54","hash":"1f32ab5f2fdef8336229d7b17fdcc9b74eabc6a8","price":"0.56","side":"SELL","size":"30"}],"timestamp":"1785208389683"},"payload_hash":"deb570daed3f81a6cfb732cd7c3108caf52de139de23c95382e986a01a786dc6","raw_frame":"{\"market\":\"0x779291bef19b6709f61e9764a954aafe9ffae488d50ae674aabdcb4f248006d5\", \"price_changes\":[{\"asset_id\":\"8761897749749422724209054078244794145777693856614463256546737399611489089783\", \"price\":\"0.44\", \"size\":\"30\", \"side\":\"BUY\", \"hash\":\"b12eecdea4b1bbe9f30d98a2e632b1e12054dae5\", \"best_bid\":\"0.45\", \"best_ask\":\"0.46\"}, {\"asset_id\":\"14965588658799411272385430903075831224615961675357217884735713260981483529984\", \"price\":\"0.56\", \"size\":\"30\", \"side\":\"SELL\", \"hash\":\"1f32ab5f2fdef8336229d7b17fdcc9b74eabc6a8\", \"best_bid\":\"0.54\", \"best_ask\":\"0.55\"}], \"timestamp\":\"1785208389683\", \"event_type\":\"price_change\"}","received_at":"2026-07-28T03:13:15.429619Z","schema_version":"clob-market-ws.price_change.v1","sequence":null,"server_hash":null,"server_timestamp":"1785208389683","session_id":"3e519d9098404c15b234d96025eb1a2b","source":"clob_market_ws"},"received_at":"2026-07-28T03:13:15.429619Z","record_id":"2617e5214e1a9eace54b84a52c7c6f2a1dbc7c1b5abb120fa960eced5dc0b7f5","schema_fingerprint":"4aa3821a28b0b7c2400bc59aba4bcc0a76e971dadd19610d3ad38c768e124dc7","schema_version":"edge-lab-recorder.raw.v1","sequence":null,"source":"clob_market_ws"}
{"event_at":"2026-07-28T03:13:09.689000Z","event_fingerprint":"6d3e78f73a97b0fa0ae47037b785f524565b90fa2518ffd71243b8535a7dd4c1","payload":{"connection_id":"a6b55582af5f430fb37ad02bf0922475","event_at":"2026-07-28T03:13:09.689000Z","event_type":"price_change","frame_hash":"2c6db6e0f53b55583ec43862a08cfb895e17242f0e51fe8892a59f85543bd12b","frame_index":0,"kind":"data","monotonic_ns":310378466135166,"payload":{"event_type":"price_change","market":"0x779291bef19b6709f61e9764a954aafe9ffae488d50ae674aabdcb4f248006d5","price_changes":[{"asset_id":"8761897749749422724209054078244794145777693856614463256546737399611489089783","best_ask":"0.46","best_bid":"0.45","hash":"ced7b33909d098df2366e716f6ab09147d6750bf","price":"0.27","side":"BUY","size":"66"},{"asset_id":"14965588658799411272385430903075831224615961675357217884735713260981483529984","best_ask":"0.55","best_bid":"0.54","hash":"a9ee293752bc35d0c5afcfab8cd5da24c52fce6c","price":"0.73","side":"SELL","size":"66"}],"timestamp":"1785208389689"},"payload_hash":"cac1d9ca6cad4d0cdf0c8478256714a661784276cb891b8d2fb7e04359ec3ad3","raw_frame":"{\"market\":\"0x779291bef19b6709f61e9764a954aafe9ffae488d50ae674aabdcb4f248006d5\", \"price_changes\":[{\"asset_id\":\"8761897749749422724209054078244794145777693856614463256546737399611489089783\", \"price\":\"0.27\", \"size\":\"66\", \"side\":\"BUY\", \"hash\":\"ced7b33909d098df2366e716f6ab09147d6750bf\", \"best_bid\":\"0.45\", \"best_ask\":\"0.46\"}, {\"asset_id\":\"14965588658799411272385430903075831224615961675357217884735713260981483529984\", \"price\":\"0.73\", \"size\":\"66\", \"side\":\"SELL\", \"hash\":\"a9ee293752bc35d0c5afcfab8cd5da24c52fce6c\", \"best_bid\":\"0.54\", \"best_ask\":\"0.55\"}], \"timestamp\":\"1785208389689\", \"event_type\":\"price_change\"}","received_at":"2026-07-28T03:13:15.431124Z","schema_version":"clob-market-ws.price_change.v1","sequence":null,"server_hash":null,"server_timestamp":"1785208389689","session_id":"3e519d9098404c15b234d96025eb1a2b","source":"clob_market_ws"},"received_at":"2026-07-28T03:13:15.431124Z","record_id":"01624bc5394f69b2cd6fef60e4ee33f856b9c285973ee2cb2456361f86d1b4db","schema_fingerprint":"4aa3821a28b0b7c2400bc59aba4bcc0a76e971dadd19610d3ad38c768e124dc7","schema_version":"edge-lab-recorder.raw.v1","sequence":null,"source":"clob_market_ws"}
{"event_at":"2026-07-28T03:13:09.690000Z","event_fingerprint":"c6945d3ddf783a8f331c3ddf562b32e3c2b76bc69f0faec2cf1551eb30cc1308","payload":{"connection_id":"a6b55582af5f430fb37ad02bf0922475","event_at":"2026-07-28T03:13:09.690000Z","event_type":"price_change","frame_hash":"4396da0940ccc45290a6918177ae64852065a2679fd4d5b125fb1317c087e161","frame_index":0,"kind":"data","monotonic_ns":310378467624250,"payload":{"event_type":"price_change","market":"0x779291bef19b6709f61e9764a954aafe9ffae488d50ae674aabdcb4f248006d5","price_changes":[{"asset_id":"14965588658799411272385430903075831224615961675357217884735713260981483529984","best_ask":"0.55","best_bid":"0.54","hash":"768ed4fe1e621e0bf25003c76ef663a6166e9f32","price":"0.46","side":"BUY","size":"117"},{"asset_id":"8761897749749422724209054078244794145777693856614463256546737399611489089783","best_ask":"0.46","best_bid":"0.45","hash":"81ff2a886b9347c975f9d38f48433a7e3f9c6182","price":"0.54","side":"SELL","size":"117"}],"timestamp":"1785208389690"},"payload_hash":"27bdbed8b280da1e53e7e066f380275ba13aca0b2781d4adbb9c8b974cd96a36","raw_frame":"{\"market\":\"0x779291bef19b6709f61e9764a954aafe9ffae488d50ae674aabdcb4f248006d5\", \"price_changes\":[{\"asset_id\":\"14965588658799411272385430903075831224615961675357217884735713260981483529984\", \"price\":\"0.46\", \"size\":\"117\", \"side\":\"BUY\", \"hash\":\"768ed4fe1e621e0bf25003c76ef663a6166e9f32\", \"best_bid\":\"0.54\", \"best_ask\":\"0.55\"}, {\"asset_id\":\"8761897749749422724209054078244794145777693856614463256546737399611489089783\", \"price\":\"0.54\", \"size\":\"117\", \"side\":\"SELL\", \"hash\":\"81ff2a886b9347c975f9d38f48433a7e3f9c6182\", \"best_bid\":\"0.45\", \"best_ask\":\"0.46\"}], \"timestamp\":\"1785208389690\", \"event_type\":\"price_change\"}","received_at":"2026-07-28T03:13:15.432613Z","schema_version":"clob-market-ws.price_change.v1","sequence":null,"server_hash":null,"server_timestamp":"1785208389690","session_id":"3e519d9098404c15b234d96025eb1a2b","source":"clob_market_ws"},"received_at":"2026-07-28T03:13:15.432613Z","record_id":"f85c1ee5d366c46856bdd38b1b3a248edcc44c243383d24aa81ea3a60222f6c8","schema_fingerprint":"4aa3821a28b0b7c2400bc59aba4bcc0a76e971dadd19610d3ad38c768e124dc7","schema_version":"edge-lab-recorder.raw.v1","sequence":null,"source":"clob_market_ws"}
{"event_at":"2026-07-28T03:13:09.690000Z","event_fingerprint":"ff2a86ae030590493db0ac2b21bb7a5146a376068ef32fb0726456024edbcaee","payload":{"connection_id":"a6b55582af5f430fb37ad02bf0922475","event_at":"2026-07-28T03:13:09.690000Z","event_type":"price_change","frame_hash":"7bcab47992120f967015d2ad5a963989791667105c00c56331fc3da6136fcb87","frame_index":0,"kind":"data","monotonic_ns":310378469103541,"payload":{"event_type":"price_change","market":"0x779291bef19b6709f61e9764a954aafe9ffae488d50ae674aabdcb4f248006d5","price_changes":[{"asset_id":"14965588658799411272385430903075831224615961675357217884735713260981483529984","best_ask":"0.55","best_bid":"0.54","hash":"afdbddc44725ce318580ffc273940fb2340ff551","price":"0.53","side":"BUY","size":"68"},{"asset_id":"8761897749749422724209054078244794145777693856614463256546737399611489089783","best_ask":"0.46","best_bid":"0.45","hash":"bccf8e15ff6a29f1506be4660830c786ef571d6f","price":"0.47","side":"SELL","size":"68"}],"timestamp":"1785208389690"},"payload_hash":"29f6a3bb3ff6bdcba5f14e4ce4f590313ef15b675c0f0cc49265b5248b01c92c","raw_frame":"{\"market\":\"0x779291bef19b6709f61e9764a954aafe9ffae488d50ae674aabdcb4f248006d5\", \"price_changes\":[{\"asset_id\":\"14965588658799411272385430903075831224615961675357217884735713260981483529984\", \"price\":\"0.53\", \"size\":\"68\", \"side\":\"BUY\", \"hash\":\"afdbddc44725ce318580ffc273940fb2340ff551\", \"best_bid\":\"0.54\", \"best_ask\":\"0.55\"}, {\"asset_id\":\"8761897749749422724209054078244794145777693856614463256546737399611489089783\", \"price\":\"0.47\", \"size\":\"68\", \"side\":\"SELL\", \"hash\":\"bccf8e15ff6a29f1506be4660830c786ef571d6f\", \"best_bid\":\"0.45\", \"best_ask\":\"0.46\"}], \"timestamp\":\"1785208389690\", \"event_type\":\"price_change\"}","received_at":"2026-07-28T03:13:15.434093Z","schema_version":"clob-market-ws.price_change.v1","sequence":null,"server_hash":null,"server_timestamp":"1785208389690","session_id":"3e519d9098404c15b234d96025eb1a2b","source":"clob_market_ws"},"received_at":"2026-07-28T03:13:15.434093Z","record_id":"c93ab9aa4f0eda82ab351fd167c9773f430301fee5870e523e2cd659048b2235","schema_fingerprint":"4aa3821a28b0b7c2400bc59aba4bcc0a76e971dadd19610d3ad38c768e124dc7","schema_version":"edge-lab-recorder.raw.v1","sequence":null,"source":"clob_market_ws"}
{"event_at":"2026-07-28T03:13:09.691000Z","event_fingerprint":"d31f171bf4f2d67861dc040ef7e4657d4c01919042e4f0a94c2a57c84897c4cb","payload":{"connection_id":"a6b55582af5f430fb37ad02bf0922475","event_at":"2026-07-28T03:13:09.691000Z","event_type":"price_change","frame_hash":"6979274156c4d20e617bedf7663d6a9e0f32652785e0f3f084bc58dc8cc852a0","frame_index":0,"kind":"data","monotonic_ns":310378470588541,"payload":{"event_type":"price_change","market":"0x779291bef19b6709f61e9764a954aafe9ffae488d50ae674aabdcb4f248006d5","price_changes":[{"asset_id":"8761897749749422724209054078244794145777693856614463256546737399611489089783","best_ask":"0.46","best_bid":"0.45","hash":"880e828d99fa0099a0d2c53658a14838643d0e91","price":"0.39","side":"BUY","size":"96"},{"asset_id":"14965588658799411272385430903075831224615961675357217884735713260981483529984","best_ask":"0.55","best_bid":"0.54","hash":"2b71218ed78e3d3e8a8b2dc9c5b54ce5f43f1d56","price":"0.61","side":"SELL","size":"96"}],"timestamp":"1785208389691"},"payload_hash":"109bdbea1ebb84d2c1b429f8ca438de4bf7655e0070634e465d22dd5135de19e","raw_frame":"{\"market\":\"0x779291bef19b6709f61e9764a954aafe9ffae488d50ae674aabdcb4f248006d5\", \"price_changes\":[{\"asset_id\":\"8761897749749422724209054078244794145777693856614463256546737399611489089783\", \"price\":\"0.39\", \"size\":\"96\", \"side\":\"BUY\", \"hash\":\"880e828d99fa0099a0d2c53658a14838643d0e91\", \"best_bid\":\"0.45\", \"best_ask\":\"0.46\"}, {\"asset_id\":\"14965588658799411272385430903075831224615961675357217884735713260981483529984\", \"price\":\"0.61\", \"size\":\"96\", \"side\":\"SELL\", \"hash\":\"2b71218ed78e3d3e8a8b2dc9c5b54ce5f43f1d56\", \"best_bid\":\"0.54\", \"best_ask\":\"0.55\"}], \"timestamp\":\"1785208389691\", \"event_type\":\"price_change\"}","received_at":"2026-07-28T03:13:15.435577Z","schema_version":"clob-market-ws.price_change.v1","sequence":null,"server_hash":null,"server_timestamp":"1785208389691","session_id":"3e519d9098404c15b234d96025eb1a2b","source":"clob_market_ws"},"received_at":"2026-07-28T03:13:15.435577Z","record_id":"312ed08d6e58d0103a7742f5683dd9278d94fca37f8d65e72200a3d6ae52a370","schema_fingerprint":"4aa3821a28b0b7c2400bc59aba4bcc0a76e971dadd19610d3ad38c768e124dc7","schema_version":"edge-lab-recorder.raw.v1","sequence":null,"source":"clob_market_ws"}
{"event_at":"2026-07-28T03:13:09.692000Z","event_fingerprint":"f71ec5fbd6495f18c9de7a74dd82be887e71bf72cdf856bd11036f57fd47a908","payload":{"connection_id":"a6b55582af5f430fb37ad02bf0922475","event_at":"2026-07-28T03:13:09.692000Z","event_type":"price_change","frame_hash":"aac973aa1d92857f2914a82ac96f99bd680a89c9adfe980e1d2e4bed07d5a3e1","frame_index":0,"kind":"data","monotonic_ns":310378472092083,"payload":{"event_type":"price_change","market":"0x779291bef19b6709f61e9764a954aafe9ffae488d50ae674aabdcb4f248006d5","price_changes":[{"asset_id":"14965588658799411272385430903075831224615961675357217884735713260981483529984","best_ask":"0.55","best_bid":"0.54","hash":"742543201e0d22ffa4c356a944143c5d879dcd18","price":"0.51","side":"BUY","size":"133.2"},{"asset_id":"8761897749749422724209054078244794145777693856614463256546737399611489089783","best_ask":"0.46","best_bid":"0.45","hash":"f07389855560180ac3f26a73b8d4c29d18e75df7","price":"0.49","side":"SELL","size":"133.2"}],"timestamp":"1785208389692"},"payload_hash":"5166706ff68323c64ecfee27c25a30bf20e1e1f7c31c925f5c4907b9c6a93b27","raw_frame":"{\"market\":\"0x779291bef19b6709f61e9764a954aafe9ffae488d50ae674aabdcb4f248006d5\", \"price_changes\":[{\"asset_id\":\"14965588658799411272385430903075831224615961675357217884735713260981483529984\", \"price\":\"0.51\", \"size\":\"133.2\", \"side\":\"BUY\", \"hash\":\"742543201e0d22ffa4c356a944143c5d879dcd18\", \"best_bid\":\"0.54\", \"best_ask\":\"0.55\"}, {\"asset_id\":\"8761897749749422724209054078244794145777693856614463256546737399611489089783\", \"price\":\"0.49\", \"size\":\"133.2\", \"side\":\"SELL\", \"hash\":\"f07389855560180ac3f26a73b8d4c29d18e75df7\", \"best_bid\":\"0.45\", \"best_ask\":\"0.46\"}], \"timestamp\":\"1785208389692\", \"event_type\":\"price_change\"}","received_at":"2026-07-28T03:13:15.437080Z","schema_version":"clob-market-ws.price_change.v1","sequence":null,"server_hash":null,"server_timestamp":"1785208389692","session_id":"3e519d9098404c15b234d96025eb1a2b","source":"clob_market_ws"},"received_at":"2026-07-28T03:13:15.437080Z","record_id":"9d304da21da953ffbd522d740ee204bb607382c5f082a87d48d3be76a67947e4","schema_fingerprint":"4aa3821a28b0b7c2400bc59aba4bcc0a76e971dadd19610d3ad38c768e124dc7","schema_version":"edge-lab-recorder.raw.v1","sequence":null,"source":"clob_market_ws"}
{"event_at":"2026-07-28T03:13:09.693000Z","event_fingerprint":"6c8e6c942dc66cd11894d9c2f2be3e08751085f369b527d7d73fa47f47814fad","payload":{"connection_id":"a6b55582af5f430fb37ad02bf0922475","event_at":"2026-07-28T03:13:09.693000Z","event_type":"price_change","frame_hash":"6cde3b8e364bfb72050aa285f4b4029c47a1e36a29075715f28a7758dc1262da","frame_index":0,"kind":"data","monotonic_ns":310378473673416,"payload":{"event_type":"price_change","market":"0x779291bef19b6709f61e9764a954aafe9ffae488d50ae674aabdcb4f248006d5","price_changes":[{"asset_id":"14965588658799411272385430903075831224615961675357217884735713260981483529984","best_ask":"0.55","best_bid":"0.54","hash":"c0bddffe1e6355659558f6eceb5ec1d2a4f97473","price":"0.48","side":"BUY","size":"91"},{"asset_id":"8761897749749422724209054078244794145777693856614463256546737399611489089783","best_ask":"0.46","best_bid":"0.45","hash":"db00b9baa667339ce077d7247f465d2454dc1cc8","price":"0.52","side":"SELL","size":"91"}],"timestamp":"1785208389693"},"payload_hash":"0b7e64ee8b14f65ff98e433678bb549c0c52a11de31301712960c62f860a0f54","raw_frame":"{\"market\":\"0x779291bef19b6709f61e9764a954aafe9ffae488d50ae674aabdcb4f248006d5\", \"price_changes\":[{\"asset_id\":\"14965588658799411272385430903075831224615961675357217884735713260981483529984\", \"price\":\"0.48\", \"size\":\"91\", \"side\":\"BUY\", \"hash\":\"c0bddffe1e6355659558f6eceb5ec1d2a4f97473\", \"best_bid\":\"0.54\", \"best_ask\":\"0.55\"}, {\"asset_id\":\"8761897749749422724209054078244794145777693856614463256546737399611489089783\", \"price\":\"0.52\", \"size\":\"91\", \"side\":\"SELL\", \"hash\":\"db00b9baa667339ce077d7247f465d2454dc1cc8\", \"best_bid\":\"0.45\", \"best_ask\":\"0.46\"}], \"timestamp\":\"1785208389693\", \"event_type\":\"price_change\"}","received_at":"2026-07-28T03:13:15.438662Z","schema_version":"clob-market-ws.price_change.v1","sequence":null,"server_hash":null,"server_timestamp":"1785208389693","session_id":"3e519d9098404c15b234d96025eb1a2b","source":"clob_market_ws"},"received_at":"2026-07-28T03:13:15.438662Z","record_id":"575c2907927deaf88ad27a0376b3105ba5f3d1450fbb8f97448aad5002c08680","schema_fingerprint":"4aa3821a28b0b7c2400bc59aba4bcc0a76e971dadd19610d3ad38c768e124dc7","schema_version":"edge-lab-recorder.raw.v1","sequence":null,"source":"clob_market_ws"}
{"event_at":"2026-07-28T03:13:09.694000Z","event_fingerprint":"522ecf64efea6b92efae937511734a2a5e20757ee4a6749cf3df6920d1dd726a","payload":{"connection_id":"a6b55582af5f430fb37ad02bf0922475","event_at":"2026-07-28T03:13:09.694000Z","event_type":"price_change","frame_hash":"1d3501dc3470496dc0816b7a05e9f4475fa9399f630c6b835c3e260826b30705","frame_index":0,"kind":"data","monotonic_ns":310378475187750,"payload":{"event_type":"price_change","market":"0x779291bef19b6709f61e9764a954aafe9ffae488d50ae674aabdcb4f248006d5","price_changes":[{"asset_id":"8761897749749422724209054078244794145777693856614463256546737399611489089783","best_ask":"0.46","best_bid":"0.45","hash":"043c002fa667e6e86b3c71c1e8f2652bcdf57665","price":"0.45","side":"BUY","size":"10"},{"asset_id":"14965588658799411272385430903075831224615961675357217884735713260981483529984","best_ask":"0.55","best_bid":"0.54","hash":"f9cd4f5006957f9191a5d6296cae0fc72cf60583","price":"0.55","side":"SELL","size":"10"}],"timestamp":"1785208389694"},"payload_hash":"7b91a3956a38efbd16a4cb16ad8fa9582a12bed5fc9927afe1e0273696f4b43e","raw_frame":"{\"market\":\"0x779291bef19b6709f61e9764a954aafe9ffae488d50ae674aabdcb4f248006d5\", \"price_changes\":[{\"asset_id\":\"8761897749749422724209054078244794145777693856614463256546737399611489089783\", \"price\":\"0.45\", \"size\":\"10\", \"side\":\"BUY\", \"hash\":\"043c002fa667e6e86b3c71c1e8f2652bcdf57665\", \"best_bid\":\"0.45\", \"best_ask\":\"0.46\"}, {\"asset_id\":\"14965588658799411272385430903075831224615961675357217884735713260981483529984\", \"price\":\"0.55\", \"size\":\"10\", \"side\":\"SELL\", \"hash\":\"f9cd4f5006957f9191a5d6296cae0fc72cf60583\", \"best_bid\":\"0.54\", \"best_ask\":\"0.55\"}], \"timestamp\":\"1785208389694\", \"event_type\":\"price_change\"}","received_at":"2026-07-28T03:13:15.440175Z","schema_version":"clob-market-ws.price_change.v1","sequence":null,"server_hash":null,"server_timestamp":"1785208389694","session_id":"3e519d9098404c15b234d96025eb1a2b","source":"clob_market_ws"},"received_at":"2026-07-28T03:13:15.440175Z","record_id":"6c6e6e4f72673fefedff11dfc03c85d8ab54894913e90d9262d12e600eba671e","schema_fingerprint":"4aa3821a28b0b7c2400bc59aba4bcc0a76e971dadd19610d3ad38c768e124dc7","schema_version":"edge-lab-recorder.raw.v1","sequence":null,"source":"clob_market_ws"}
{"event_at":"2026-07-28T03:13:09.694000Z","event_fingerprint":"3b90d73acf94c00047dcf4caf5638d6f50e1fda0539820bda685e3b535067756","payload":{"connection_id":"a6b55582af5f430fb37ad02bf0922475","event_at":"2026-07-28T03:13:09.694000Z","event_type":"price_change","frame_hash":"989fb600370945ed26537f2fce17f75f5a2287df0dd2765752c8c6a307a3bc55","frame_index":0,"kind":"data","monotonic_ns":310378476730791,"payload":{"event_type":"price_change","market":"0x779291bef19b6709f61e9764a954aafe9ffae488d50ae674aabdcb4f248006d5","price_changes":[{"asset_id":"14965588658799411272385430903075831224615961675357217884735713260981483529984","best_ask":"0.55","best_bid":"0.54","hash":"668a5f2c8a87eab7831cb761abd9321a28d4ddcc","price":"0.52","side":"BUY","size":"68"},{"asset_id":"8761897749749422724209054078244794145777693856614463256546737399611489089783","best_ask":"0.46","best_bid":"0.45","hash":"ecee50790b004e62c2bb8eec2146aee8df6da819","price":"0.48","side":"SELL","size":"68"}],"timestamp":"1785208389694"},"payload_hash":"5a89a825289bbadce4bf2d03d798dc61fc4635b28ce92a285e0c3c5ca2c159af","raw_frame":"{\"market\":\"0x779291bef19b6709f61e9764a954aafe9ffae488d50ae674aabdcb4f248006d5\", \"price_changes\":[{\"asset_id\":\"14965588658799411272385430903075831224615961675357217884735713260981483529984\", \"price\":\"0.52\", \"size\":\"68\", \"side\":\"BUY\", \"hash\":\"668a5f2c8a87eab7831cb761abd9321a28d4ddcc\", \"best_bid\":\"0.54\", \"best_ask\":\"0.55\"}, {\"asset_id\":\"8761897749749422724209054078244794145777693856614463256546737399611489089783\", \"price\":\"0.48\", \"size\":\"68\", \"side\":\"SELL\", \"hash\":\"ecee50790b004e62c2bb8eec2146aee8df6da819\", \"best_bid\":\"0.45\", \"best_ask\":\"0.46\"}], \"timestamp\":\"1785208389694\", \"event_type\":\"price_change\"}","received_at":"2026-07-28T03:13:15.441720Z","schema_version":"clob-market-ws.price_change.v1","sequence":null,"server_hash":null,"server_timestamp":"1785208389694","session_id":"3e519d9098404c15b234d96025eb1a2b","source":"clob_market_ws"},"received_at":"2026-07-28T03:13:15.441720Z","record_id":"7dab42efe2b47db680a62d5ff2fd969274ebf439d6c1fabd16be4e7fe5f8517d","schema_fingerprint":"4aa3821a28b0b7c2400bc59aba4bcc0a76e971dadd19610d3ad38c768e124dc7","schema_version":"edge-lab-recorder.raw.v1","sequence":null,"source":"clob_market_ws"}
{"event_at":"2026-07-28T03:13:09.695000Z","event_fingerprint":"337d93ababcdfddcaf4deb055fd1e04bb8692120ded866946acd508b29602de6","payload":{"connection_id":"a6b55582af5f430fb37ad02bf0922475","event_at":"2026-07-28T03:13:09.695000Z","event_type":"price_change","frame_hash":"e47dfdc5bdfc122ecff4ea251d04e7d62d55d51302519447c1b57b4da9741dce","frame_index":0,"kind":"data","monotonic_ns":310378478235833,"payload":{"event_type":"price_change","market":"0x779291bef19b6709f61e9764a954aafe9ffae488d50ae674aabdcb4f248006d5","price_changes":[{"asset_id":"8761897749749422724209054078244794145777693856614463256546737399611489089783","best_ask":"0.46","best_bid":"0.45","hash":"ce625f1e854d41c252cd9b688a171674caa8763a","price":"0.44","side":"BUY","size":"10"},{"asset_id":"14965588658799411272385430903075831224615961675357217884735713260981483529984","best_ask":"0.55","best_bid":"0.54","hash":"2488ab7128bde47ec92679bbf42cf9140e165ad9","price":"0.56","side":"SELL","size":"10"}],"timestamp":"1785208389695"},"payload_hash":"0cf01748d594a6d83327eef5ac7e63abe4d40e74ba9a26f8119efe8fe1ac4780","raw_frame":"{\"market\":\"0x779291bef19b6709f61e9764a954aafe9ffae488d50ae674aabdcb4f248006d5\", \"price_changes\":[{\"asset_id\":\"8761897749749422724209054078244794145777693856614463256546737399611489089783\", \"price\":\"0.44\", \"size\":\"10\", \"side\":\"BUY\", \"hash\":\"ce625f1e854d41c252cd9b688a171674caa8763a\", \"best_bid\":\"0.45\", \"best_ask\":\"0.46\"}, {\"asset_id\":\"14965588658799411272385430903075831224615961675357217884735713260981483529984\", \"price\":\"0.56\", \"size\":\"10\", \"side\":\"SELL\", \"hash\":\"2488ab7128bde47ec92679bbf42cf9140e165ad9\", \"best_bid\":\"0.54\", \"best_ask\":\"0.55\"}], \"timestamp\":\"1785208389695\", \"event_type\":\"price_change\"}","received_at":"2026-07-28T03:13:15.443225Z","schema_version":"clob-market-ws.price_change.v1","sequence":null,"server_hash":null,"server_timestamp":"1785208389695","session_id":"3e519d9098404c15b234d96025eb1a2b","source":"clob_market_ws"},"received_at":"2026-07-28T03:13:15.443225Z","record_id":"ea570d0cb380e4180c06a88704365200131c5b07984ef0da7d3073cb0048ffc3","schema_fingerprint":"4aa3821a28b0b7c2400bc59aba4bcc0a76e971dadd19610d3ad38c768e124dc7","schema_version":"edge-lab-recorder.raw.v1","sequence":null,"source":"clob_market_ws"}
{"event_at":"2026-07-28T03:13:09.696000Z","event_fingerprint":"c7e25636580432d9b6d4448cf67e9297a269767187948eaf83687ef38d6b7d99","payload":{"connection_id":"a6b55582af5f430fb37ad02bf0922475","event_at":"2026-07-28T03:13:09.696000Z","event_type":"price_change","frame_hash":"3205b3ac892854a23b2c785ab647fff70d486f63ec0ae4346a01c3cf40e543d3","frame_index":0,"kind":"data","monotonic_ns":310378479750833,"payload":{"event_type":"price_change","market":"0x779291bef19b6709f61e9764a954aafe9ffae488d50ae674aabdcb4f248006d5","price_changes":[{"asset_id":"8761897749749422724209054078244794145777693856614463256546737399611489089783","best_ask":"0.46","best_bid":"0.45","hash":"38c2dbc957a4bd8aae6cc7420e20659c919966fa","price":"0.43","side":"BUY","size":"10"},{"asset_id":"14965588658799411272385430903075831224615961675357217884735713260981483529984","best_ask":"0.55","best_bid":"0.54","hash":"3edde9bfad339f043d2b614e8e3f89bffe7e7633","price":"0.57","side":"SELL","size":"10"}],"timestamp":"1785208389696"},"payload_hash":"627b6590c3684ad3fdadeb5038bd767690a46c061c7d0e4a8065b2b3aa4c14e1","raw_frame":"{\"market\":\"0x779291bef19b6709f61e9764a954aafe9ffae488d50ae674aabdcb4f248006d5\", \"price_changes\":[{\"asset_id\":\"8761897749749422724209054078244794145777693856614463256546737399611489089783\", \"price\":\"0.43\", \"size\":\"10\", \"side\":\"BUY\", \"hash\":\"38c2dbc957a4bd8aae6cc7420e20659c919966fa\", \"best_bid\":\"0.45\", \"best_ask\":\"0.46\"}, {\"asset_id\":\"14965588658799411272385430903075831224615961675357217884735713260981483529984\", \"price\":\"0.57\", \"size\":\"10\", \"side\":\"SELL\", \"hash\":\"3edde9bfad339f043d2b614e8e3f89bffe7e7633\", \"best_bid\":\"0.54\", \"best_ask\":\"0.55\"}], \"timestamp\":\"1785208389696\", \"event_type\":\"price_change\"}","received_at":"2026-07-28T03:13:15.444740Z","schema_version":"clob-market-ws.price_change.v1","sequence":null,"server_hash":null,"server_timestamp":"1785208389696","session_id":"3e519d9098404c15b234d96025eb1a2b","source":"clob_market_ws"},"received_at":"2026-07-28T03:13:15.444740Z","record_id":"1bac88aa04893c732b4b569a996a10d8e7743d49d894ac8e1c30fc8620bf16b5","schema_fingerprint":"4aa3821a28b0b7c2400bc59aba4bcc0a76e971dadd19610d3ad38c768e124dc7","schema_version":"edge-lab-recorder.raw.v1","sequence":null,"source":"clob_market_ws"}
{"event_at":"2026-07-28T03:13:09.696000Z","event_fingerprint":"c6911a38c06f0dfdcc868a807a0eef50a6e900d12ab8b3309c3b27f1e1fab5ef","payload":{"connection_id":"a6b55582af5f430fb37ad02bf0922475","event_at":"2026-07-28T03:13:09.696000Z","event_type":"price_change","frame_hash":"b7076741ee7420510323a874af5e9399bef6d31dc8a276c676878423971c2008","frame_index":0,"kind":"data","monotonic_ns":310378481276875,"payload":{"event_type":"price_change","market":"0x779291bef19b6709f61e9764a954aafe9ffae488d50ae674aabdcb4f248006d5","price_changes":[{"asset_id":"8761897749749422724209054078244794145777693856614463256546737399611489089783","best_ask":"0.46","best_bid":"0.45","hash":"c4ccc8f50afdf16dd2a75cb2309e85ab874b79e0","price":"0.44","side":"BUY","size":"0"},{"asset_id":"14965588658799411272385430903075831224615961675357217884735713260981483529984","best_ask":"0.55","best_bid":"0.54","hash":"2509b6f443a214299d36591d17f806759d797099","price":"0.56","side":"SELL","size":"0"}],"timestamp":"1785208389696"},"payload_hash":"689dd1e3579e9c520709d874b92c42c4103ccdaa387bb0867f7b0ac421c7d993","raw_frame":"{\"market\":\"0x779291bef19b6709f61e9764a954aafe9ffae488d50ae674aabdcb4f248006d5\", \"price_changes\":[{\"asset_id\":\"8761897749749422724209054078244794145777693856614463256546737399611489089783\", \"price\":\"0.44\", \"size\":\"0\", \"side\":\"BUY\", \"hash\":\"c4ccc8f50afdf16dd2a75cb2309e85ab874b79e0\", \"best_bid\":\"0.45\", \"best_ask\":\"0.46\"}, {\"asset_id\":\"14965588658799411272385430903075831224615961675357217884735713260981483529984\", \"price\":\"0.56\", \"size\":\"0\", \"side\":\"SELL\", \"hash\":\"2509b6f443a214299d36591d17f806759d797099\", \"best_bid\":\"0.54\", \"best_ask\":\"0.55\"}], \"timestamp\":\"1785208389696\", \"event_type\":\"price_change\"}","received_at":"2026-07-28T03:13:15.446265Z","schema_version":"clob-market-ws.price_change.v1","sequence":null,"server_hash":null,"server_timestamp":"1785208389696","session_id":"3e519d9098404c15b234d96025eb1a2b","source":"clob_market_ws"},"received_at":"2026-07-28T03:13:15.446265Z","record_id":"d11e5699daa7f7bccc3b494ecee914892039cdbd662e4ac18b4f90ad7c6a1e01","schema_fingerprint":"4aa3821a28b0b7c2400bc59aba4bcc0a76e971dadd19610d3ad38c768e124dc7","schema_version":"edge-lab-recorder.raw.v1","sequence":null,"source":"clob_market_ws"}
{"event_at":"2026-07-28T03:13:09.696000Z","event_fingerprint":"f81caa879d8a1be29520d3b5d8c70f3ee817547e9b2d1bde276cc7f69509cf68","payload":{"connection_id":"a6b55582af5f430fb37ad02bf0922475","event_at":"2026-07-28T03:13:09.696000Z","event_type":"best_bid_ask","frame_hash":"ba1000a0f52e0d9a627e2583606e26d67700e0078331829b4c8a2a278fdba88c","frame_index":0,"kind":"data","monotonic_ns":310378482813333,"payload":{"asset_id":"14965588658799411272385430903075831224615961675357217884735713260981483529984","best_ask":"0.57","best_bid":"0.54","event_type":"best_bid_ask","market":"0x779291bef19b6709f61e9764a954aafe9ffae488d50ae674aabdcb4f248006d5","spread":"0.03","timestamp":"1785208389696"},"payload_hash":"106cef62204ee23a2a403123d9ac408403f57b7a3d9d5be67c138920f4df2fcd","raw_frame":"{\"market\":\"0x779291bef19b6709f61e9764a954aafe9ffae488d50ae674aabdcb4f248006d5\", \"asset_id\":\"14965588658799411272385430903075831224615961675357217884735713260981483529984\", \"best_bid\":\"0.54\", \"best_ask\":\"0.57\", \"spread\":\"0.03\", \"timestamp\":\"1785208389696\", \"event_type\":\"best_bid_ask\"}","received_at":"2026-07-28T03:13:15.447802Z","schema_version":"clob-market-ws.best_bid_ask.v1","sequence":null,"server_hash":null,"server_timestamp":"1785208389696","session_id":"3e519d9098404c15b234d96025eb1a2b","source":"clob_market_ws"},"received_at":"2026-07-28T03:13:15.447802Z","record_id":"6044b4147f61454b80e950db05d4436ca4045718dfa1d9bca3babaef46ff2200","schema_fingerprint":"8488399f31b0337811b13b266be932db7062827c2470b78bd8e9e99bab51d17d","schema_version":"edge-lab-recorder.raw.v1","sequence":null,"source":"clob_market_ws"}
{"event_at":"2026-07-28T03:13:09.696000Z","event_fingerprint":"93b272f64719c2a4cf2775f4d50c8a87b3d6a7eb218ecd9c85b292ac581e7016","payload":{"connection_id":"a6b55582af5f430fb37ad02bf0922475","event_at":"2026-07-28T03:13:09.696000Z","event_type":"best_bid_ask","frame_hash":"66e9c6b8832b9ef1febd76820e67f3155e01d906de243e2f3f774ffedec9f084","frame_index":0,"kind":"data","monotonic_ns":310378483876666,"payload":{"asset_id":"8761897749749422724209054078244794145777693856614463256546737399611489089783","best_ask":"0.46","best_bid":"0.43","event_type":"best_bid_ask","market":"0x779291bef19b6709f61e9764a954aafe9ffae488d50ae674aabdcb4f248006d5","spread":"0.03","timestamp":"1785208389696"},"payload_hash":"79439b18188c9cebd9251854d95d8e581a6bd474262f0a118569af6cb9afc484","raw_frame":"{\"market\":\"0x779291bef19b6709f61e9764a954aafe9ffae488d50ae674aabdcb4f248006d5\", \"asset_id\":\"8761897749749422724209054078244794145777693856614463256546737399611489089783\", \"best_bid\":\"0.43\", \"best_ask\":\"0.46\", \"spread\":\"0.03\", \"timestamp\":\"1785208389696\", \"event_type\":\"best_bid_ask\"}","received_at":"2026-07-28T03:13:15.448866Z","schema_version":"clob-market-ws.best_bid_ask.v1","sequence":null,"server_hash":null,"server_timestamp":"1785208389696","session_id":"3e519d9098404c15b234d96025eb1a2b","source":"clob_market_ws"},"received_at":"2026-07-28T03:13:15.448866Z","record_id":"53868c4081e36bb77748b237a8a31ec5beafb05ecf0e02effa9d07ff732f753b","schema_fingerprint":"8488399f31b0337811b13b266be932db7062827c2470b78bd8e9e99bab51d17d","schema_version":"edge-lab-recorder.raw.v1","sequence":null,"source":"clob_market_ws"}
{"event_at":"2026-07-28T03:13:09.696000Z","event_fingerprint":"325f1c7d79e342cb3b3fd6e5e2c254f327393926540d40fa86ee06a54faef62c","payload":{"connection_id":"a6b55582af5f430fb37ad02bf0922475","event_at":"2026-07-28T03:13:09.696000Z","event_type":"price_change","frame_hash":"3ba973b32db1d9a11d417940a0bdb3239abae5895e70e5251f16ec52b3d6de0c","frame_index":0,"kind":"data","monotonic_ns":310378484962625,"payload":{"event_type":"price_change","market":"0x779291bef19b6709f61e9764a954aafe9ffae488d50ae674aabdcb4f248006d5","price_changes":[{"asset_id":"8761897749749422724209054078244794145777693856614463256546737399611489089783","best_ask":"0.46","best_bid":"0.43","hash":"49a794c654b9797dd96fede73765d0f952be1116","price":"0.45","side":"BUY","size":"0"},{"asset_id":"14965588658799411272385430903075831224615961675357217884735713260981483529984","best_ask":"0.57","best_bid":"0.54","hash":"9f06e52c773e7dc05f57f9e322380993f42d34b0","price":"0.55","side":"SELL","size":"0"}],"timestamp":"1785208389696"},"payload_hash":"3bf885a1d8424b972fee640589531e5f2307994cd9958dbdf514641f7c593952","raw_frame":"{\"market\":\"0x779291bef19b6709f61e9764a954aafe9ffae488d50ae674aabdcb4f248006d5\", \"price_changes\":[{\"asset_id\":\"8761897749749422724209054078244794145777693856614463256546737399611489089783\", \"price\":\"0.45\", \"size\":\"0\", \"side\":\"BUY\", \"hash\":\"49a794c654b9797dd96fede73765d0f952be1116\", \"best_bid\":\"0.43\", \"best_ask\":\"0.46\"}, {\"asset_id\":\"14965588658799411272385430903075831224615961675357217884735713260981483529984\", \"price\":\"0.55\", \"size\":\"0\", \"side\":\"SELL\", \"hash\":\"9f06e52c773e7dc05f57f9e322380993f42d34b0\", \"best_bid\":\"0.54\", \"best_ask\":\"0.57\"}], \"timestamp\":\"1785208389696\", \"event_type\":\"price_change\"}","received_at":"2026-07-28T03:13:15.449952Z","schema_version":"clob-market-ws.price_change.v1","sequence":null,"server_hash":null,"server_timestamp":"1785208389696","session_id":"3e519d9098404c15b234d96025eb1a2b","source":"clob_market_ws"},"received_at":"2026-07-28T03:13:15.449952Z","record_id":"a0ba46e63ee5968716e1dad6364f4b129769241ad523c8be3b6ff588cb55a649","schema_fingerprint":"4aa3821a28b0b7c2400bc59aba4bcc0a76e971dadd19610d3ad38c768e124dc7","schema_version":"edge-lab-recorder.raw.v1","sequence":null,"source":"clob_market_ws"}
{"event_at":"2026-07-28T03:13:09.699000Z","event_fingerprint":"9d9d0f0d8368769f13ecaafaa0fb7bec7abe0ca29e80949f1b29864a19680592","payload":{"connection_id":"a6b55582af5f430fb37ad02bf0922475","event_at":"2026-07-28T03:13:09.699000Z","event_type":"best_bid_ask","frame_hash":"af0b347c331beef637bdb78ab9c31d072862a5471317a97c2e6569c7229bef71","frame_index":0,"kind":"data","monotonic_ns":310378486618625,"payload":{"asset_id":"14965588658799411272385430903075831224615961675357217884735713260981483529984","best_ask":"0.57","best_bid":"0.55","event_type":"best_bid_ask","market":"0x779291bef19b6709f61e9764a954aafe9ffae488d50ae674aabdcb4f248006d5","spread":"0.02","timestamp":"1785208389699"},"payload_hash":"8c73903937edb2296d814ade0e7be3a5eea903d2fe845f4409839f27ad62d3c8","raw_frame":"{\"market\":\"0x779291bef19b6709f61e9764a954aafe9ffae488d50ae674aabdcb4f248006d5\", \"asset_id\":\"14965588658799411272385430903075831224615961675357217884735713260981483529984\", \"best_bid\":\"0.55\", \"best_ask\":\"0.57\", \"spread\":\"0.02\", \"timestamp\":\"1785208389699\", \"event_type\":\"best_bid_ask\"}","received_at":"2026-07-28T03:13:15.451607Z","schema_version":"clob-market-ws.best_bid_ask.v1","sequence":null,"server_hash":null,"server_timestamp":"1785208389699","session_id":"3e519d9098404c15b234d96025eb1a2b","source":"clob_market_ws"},"received_at":"2026-07-28T03:13:15.451607Z","record_id":"d39c1a07aa79cb6bbf0727f0f895695be71033b52fd58cc2e019df8af2050d55","schema_fingerprint":"8488399f31b0337811b13b266be932db7062827c2470b78bd8e9e99bab51d17d","schema_version":"edge-lab-recorder.raw.v1","sequence":null,"source":"clob_market_ws"}
{"event_at":"2026-07-28T03:13:09.699000Z","event_fingerprint":"da32d848e7dc6702724edd84edcd4d4b4fa664427774917b80e03435c421d01e","payload":{"connection_id":"a6b55582af5f430fb37ad02bf0922475","event_at":"2026-07-28T03:13:09.699000Z","event_type":"best_bid_ask","frame_hash":"194f356b582a69fed53528696845113c05f2e65b337b0096e85392c19e98f37b","frame_index":0,"kind":"data","monotonic_ns":310378487682125,"payload":{"asset_id":"8761897749749422724209054078244794145777693856614463256546737399611489089783","best_ask":"0.45","best_bid":"0.43","event_type":"best_bid_ask","market":"0x779291bef19b6709f61e9764a954aafe9ffae488d50ae674aabdcb4f248006d5","spread":"0.02","timestamp":"1785208389699"},"payload_hash":"c6e03dad9535553838496f882e86f6a2c6d8c8f50d3477bbc450e2093446cb77","raw_frame":"{\"market\":\"0x779291bef19b6709f61e9764a954aafe9ffae488d50ae674aabdcb4f248006d5\", \"asset_id\":\"8761897749749422724209054078244794145777693856614463256546737399611489089783\", \"best_bid\":\"0.43\", \"best_ask\":\"0.45\", \"spread\":\"0.02\", \"timestamp\":\"1785208389699\", \"event_type\":\"best_bid_ask\"}","received_at":"2026-07-28T03:13:15.452671Z","schema_version":"clob-market-ws.best_bid_ask.v1","sequence":null,"server_hash":null,"server_timestamp":"1785208389699","session_id":"3e519d9098404c15b234d96025eb1a2b","source":"clob_market_ws"},"received_at":"2026-07-28T03:13:15.452671Z","record_id":"8d26bd9152988299b0ac758b106e49b4079f7beba49551d0593b5727ade6b6a8","schema_fingerprint":"8488399f31b0337811b13b266be932db7062827c2470b78bd8e9e99bab51d17d","schema_version":"edge-lab-recorder.raw.v1","sequence":null,"source":"clob_market_ws"}
{"event_at":"2026-07-28T03:13:09.699000Z","event_fingerprint":"c444c76c3422757784285f2b682bd2602e4c69e5281b39b8f947bdabfff84c5b","payload":{"connection_id":"a6b55582af5f430fb37ad02bf0922475","event_at":"2026-07-28T03:13:09.699000Z","event_type":"price_change","frame_hash":"83525578109ce302ecdcf0d06921414093641bb8eb7b583aa388c73e735bc4d9","frame_index":0,"kind":"data","monotonic_ns":310378488740500,"payload":{"event_type":"price_change","market":"0x779291bef19b6709f61e9764a954aafe9ffae488d50ae674aabdcb4f248006d5","price_changes":[{"asset_id":"14965588658799411272385430903075831224615961675357217884735713260981483529984","best_ask":"0.57","best_bid":"0.55","hash":"960df7eb06aafbb289d074834fdebd3dbaf9310d","price":"0.55","side":"BUY","size":"40"},{"asset_id":"8761897749749422724209054078244794145777693856614463256546737399611489089783","best_ask":"0.45","best_bid":"0.43","hash":"a2c5129a6aedebfa0acb2c9f642dafa38079aefa","price":"0.45","side":"SELL","size":"40"}],"timestamp":"1785208389699"},"payload_hash":"8cd2d9e3f9ecce47ea59ed58a391f4d1466d26402dc04937853df10a93a718f5","raw_frame":"{\"market\":\"0x779291bef19b6709f61e9764a954aafe9ffae488d50ae674aabdcb4f248006d5\", \"price_changes\":[{\"asset_id\":\"14965588658799411272385430903075831224615961675357217884735713260981483529984\", \"price\":\"0.55\", \"size\":\"40\", \"side\":\"BUY\", \"hash\":\"960df7eb06aafbb289d074834fdebd3dbaf9310d\", \"best_bid\":\"0.55\", \"best_ask\":\"0.57\"}, {\"asset_id\":\"8761897749749422724209054078244794145777693856614463256546737399611489089783\", \"price\":\"0.45\", \"size\":\"40\", \"side\":\"SELL\", \"hash\":\"a2c5129a6aedebfa0acb2c9f642dafa38079aefa\", \"best_bid\":\"0.43\", \"best_ask\":\"0.45\"}], \"timestamp\":\"1785208389699\", \"event_type\":\"price_change\"}","received_at":"2026-07-28T03:13:15.453730Z","schema_version":"clob-market-ws.price_change.v1","sequence":null,"server_hash":null,"server_timestamp":"1785208389699","session_id":"3e519d9098404c15b234d96025eb1a2b","source":"clob_market_ws"},"received_at":"2026-07-28T03:13:15.453730Z","record_id":"648dba1feafe7a0b4cac932b9ee487b56471101d557509f00bc3ed7fefa0c7c1","schema_fingerprint":"4aa3821a28b0b7c2400bc59aba4bcc0a76e971dadd19610d3ad38c768e124dc7","schema_version":"edge-lab-recorder.raw.v1","sequence":null,"source":"clob_market_ws"}
{"event_at":"2026-07-28T03:13:09.700000Z","event_fingerprint":"4f36fdf809851048acde25d35d26b8a0eb34327f3a8498e99d9ce7221a52d457","payload":{"connection_id":"a6b55582af5f430fb37ad02bf0922475","event_at":"2026-07-28T03:13:09.700000Z","event_type":"price_change","frame_hash":"fd530fc29b2b26ef77aeffb286fbf3b2510dcba10d208fa03164573963478ff5","frame_index":0,"kind":"data","monotonic_ns":310378490249375,"payload":{"event_type":"price_change","market":"0x779291bef19b6709f61e9764a954aafe9ffae488d50ae674aabdcb4f248006d5","price_changes":[{"asset_id":"8761897749749422724209054078244794145777693856614463256546737399611489089783","best_ask":"0.45","best_bid":"0.43","hash":"39070ae8774b2c88bbb6d8d75be8f02205bf406c","price":"0.42","side":"BUY","size":"58"},{"asset_id":"14965588658799411272385430903075831224615961675357217884735713260981483529984","best_ask":"0.57","best_bid":"0.55","hash":"512fe612d3bf7790f219ffe97855a7364e2fe8db","price":"0.58","side":"SELL","size":"58"}],"timestamp":"1785208389700"},"payload_hash":"085c6531fcd3e504781cb760eaac03fd5c0cbf60856c52b524a117e54ee57fdd","raw_frame":"{\"market\":\"0x779291bef19b6709f61e9764a954aafe9ffae488d50ae674aabdcb4f248006d5\", \"price_changes\":[{\"asset_id\":\"8761897749749422724209054078244794145777693856614463256546737399611489089783\", \"price\":\"0.42\", \"size\":\"58\", \"side\":\"BUY\", \"hash\":\"39070ae8774b2c88bbb6d8d75be8f02205bf406c\", \"best_bid\":\"0.43\", \"best_ask\":\"0.45\"}, {\"asset_id\":\"14965588658799411272385430903075831224615961675357217884735713260981483529984\", \"price\":\"0.58\", \"size\":\"58\", \"side\":\"SELL\", \"hash\":\"512fe612d3bf7790f219ffe97855a7364e2fe8db\", \"best_bid\":\"0.55\", \"best_ask\":\"0.57\"}], \"timestamp\":\"1785208389700\", \"event_type\":\"price_change\"}","received_at":"2026-07-28T03:13:15.455238Z","schema_version":"clob-market-ws.price_change.v1","sequence":null,"server_hash":null,"server_timestamp":"1785208389700","session_id":"3e519d9098404c15b234d96025eb1a2b","source":"clob_market_ws"},"received_at":"2026-07-28T03:13:15.455238Z","record_id":"3fc0aa637a1e2ecba5b294f793f6be2698b2e14bc5093d42b617e3f821ba2044","schema_fingerprint":"4aa3821a28b0b7c2400bc59aba4bcc0a76e971dadd19610d3ad38c768e124dc7","schema_version":"edge-lab-recorder.raw.v1","sequence":null,"source":"clob_market_ws"}
{"event_at":"2026-07-28T03:13:09.700000Z","event_fingerprint":"6208e9ef63fcdf4e601060596fcb48ddd808ec26c7684b5dcd497acabe713eb5","payload":{"connection_id":"a6b55582af5f430fb37ad02bf0922475","event_at":"2026-07-28T03:13:09.700000Z","event_type":"price_change","frame_hash":"d66f7f22d2998a4a647dfe0c175c69f154d6e4cdee2f729b377cab1e7671acfd","frame_index":0,"kind":"data","monotonic_ns":310378491770583,"payload":{"event_type":"price_change","market":"0x779291bef19b6709f61e9764a954aafe9ffae488d50ae674aabdcb4f248006d5","price_changes":[{"asset_id":"14965588658799411272385430903075831224615961675357217884735713260981483529984","best_ask":"0.57","best_bid":"0.55","hash":"e5c3520d6765099984d38582c5171fc747a0704e","price":"0.55","side":"BUY","size":"64"},{"asset_id":"8761897749749422724209054078244794145777693856614463256546737399611489089783","best_ask":"0.45","best_bid":"0.43","hash":"82e817b8799b03c9b7cc06353ebd9e3616c6caeb","price":"0.45","side":"SELL","size":"64"}],"timestamp":"1785208389700"},"payload_hash":"c07008bdbfdb712215226614f0d18d646fee69108192a9ab31a88866137e17b6","raw_frame":"{\"market\":\"0x779291bef19b6709f61e9764a954aafe9ffae488d50ae674aabdcb4f248006d5\", \"price_changes\":[{\"asset_id\":\"14965588658799411272385430903075831224615961675357217884735713260981483529984\", \"price\":\"0.55\", \"size\":\"64\", \"side\":\"BUY\", \"hash\":\"e5c3520d6765099984d38582c5171fc747a0704e\", \"best_bid\":\"0.55\", \"best_ask\":\"0.57\"}, {\"asset_id\":\"8761897749749422724209054078244794145777693856614463256546737399611489089783\", \"price\":\"0.45\", \"size\":\"64\", \"side\":\"SELL\", \"hash\":\"82e817b8799b03c9b7cc06353ebd9e3616c6caeb\", \"best_bid\":\"0.43\", \"best_ask\":\"0.45\"}], \"timestamp\":\"1785208389700\", \"event_type\":\"price_change\"}","received_at":"2026-07-28T03:13:15.456759Z","schema_version":"clob-market-ws.price_change.v1","sequence":null,"server_hash":null,"server_timestamp":"1785208389700","session_id":"3e519d9098404c15b234d96025eb1a2b","source":"clob_market_ws"},"received_at":"2026-07-28T03:13:15.456759Z","record_id":"53f473e93b04a8c750e2f9ae7e36d529359947d087f7ebc3f87074b2e3585b87","schema_fingerprint":"4aa3821a28b0b7c2400bc59aba4bcc0a76e971dadd19610d3ad38c768e124dc7","schema_version":"edge-lab-recorder.raw.v1","sequence":null,"source":"clob_market_ws"}
{"event_at":"2026-07-28T03:13:09.701000Z","event_fingerprint":"f2cd35e9e328ff380e7f92f06b8f0f9590dddb9127e4f641da725e41435fca97","payload":{"connection_id":"a6b55582af5f430fb37ad02bf0922475","event_at":"2026-07-28T03:13:09.701000Z","event_type":"best_bid_ask","frame_hash":"4ec1fb012f30c2fde272315aefc3e2251bb6dd2001b20f3a0ac68a9bb849abc2","frame_index":0,"kind":"data","monotonic_ns":310378493271916,"payload":{"asset_id":"14965588658799411272385430903075831224615961675357217884735713260981483529984","best_ask":"0.58","best_bid":"0.55","event_type":"best_bid_ask","market":"0x779291bef19b6709f61e9764a954aafe9ffae488d50ae674aabdcb4f248006d5","spread":"0.03","timestamp":"1785208389701"},"payload_hash":"18dce5cbfebcd59b6302d0d1bf02f9d132ebe75d3efe0167dbea641b7693f761","raw_frame":"{\"market\":\"0x779291bef19b6709f61e9764a954aafe9ffae488d50ae674aabdcb4f248006d5\", \"asset_id\":\"14965588658799411272385430903075831224615961675357217884735713260981483529984\", \"best_bid\":\"0.55\", \"best_ask\":\"0.58\", \"spread\":\"0.03\", \"timestamp\":\"1785208389701\", \"event_type\":\"best_bid_ask\"}","received_at":"2026-07-28T03:13:15.458261Z","schema_version":"clob-market-ws.best_bid_ask.v1","sequence":null,"server_hash":null,"server_timestamp":"1785208389701","session_id":"3e519d9098404c15b234d96025eb1a2b","source":"clob_market_ws"},"received_at":"2026-07-28T03:13:15.458261Z","record_id":"d220f12f80ca5caa8622477a1b09da9800af329a5b1b2b7c0bcad24df2406de5","schema_fingerprint":"8488399f31b0337811b13b266be932db7062827c2470b78bd8e9e99bab51d17d","schema_version":"edge-lab-recorder.raw.v1","sequence":null,"source":"clob_market_ws"}
{"event_at":"2026-07-28T03:13:09.701000Z","event_fingerprint":"86a91dc2bb2a474eb165d8fc117406d6255ecb6ae7713a367d3d30f8f12df969","payload":{"connection_id":"a6b55582af5f430fb37ad02bf0922475","event_at":"2026-07-28T03:13:09.701000Z","event_type":"best_bid_ask","frame_hash":"c620a82f03f690a8fce669aa3ceeb13032aaad31ebe097ae37730d2295c0c439","frame_index":0,"kind":"data","monotonic_ns":310378494309208,"payload":{"asset_id":"8761897749749422724209054078244794145777693856614463256546737399611489089783","best_ask":"0.45","best_bid":"0.42","event_type":"best_bid_ask","market":"0x779291bef19b6709f61e9764a954aafe9ffae488d50ae674aabdcb4f248006d5","spread":"0.03","timestamp":"1785208389701"},"payload_hash":"3e3e506c71dbac68235c9108f2946133e30b7488678ea04c54b6863dd9a75dd1","raw_frame":"{\"market\":\"0x779291bef19b6709f61e9764a954aafe9ffae488d50ae674aabdcb4f248006d5\", \"asset_id\":\"8761897749749422724209054078244794145777693856614463256546737399611489089783\", \"best_bid\":\"0.42\", \"best_ask\":\"0.45\", \"spread\":\"0.03\", \"timestamp\":\"1785208389701\", \"event_type\":\"best_bid_ask\"}","received_at":"2026-07-28T03:13:15.459298Z","schema_version":"clob-market-ws.best_bid_ask.v1","sequence":null,"server_hash":null,"server_timestamp":"1785208389701","session_id":"3e519d9098404c15b234d96025eb1a2b","source":"clob_market_ws"},"received_at":"2026-07-28T03:13:15.459298Z","record_id":"c3fe0a92efe4a65b652d740e61ceb4c0b7521f12bc63f482e52a299d4c876770","schema_fingerprint":"8488399f31b0337811b13b266be932db7062827c2470b78bd8e9e99bab51d17d","schema_version":"edge-lab-recorder.raw.v1","sequence":null,"source":"clob_market_ws"}
{"event_at":"2026-07-28T03:13:09.701000Z","event_fingerprint":"1b030e340e634b41f49c38dcb41bd61e6a9e2a63e9bd38272874c27a48dc60b7","payload":{"connection_id":"a6b55582af5f430fb37ad02bf0922475","event_at":"2026-07-28T03:13:09.701000Z","event_type":"price_change","frame_hash":"f4aec3f08b25e44a57899c5e3450174dad519a08d1ebdd6f57f865e973d05184","frame_index":0,"kind":"data","monotonic_ns":310378495362791,"payload":{"event_type":"price_change","market":"0x779291bef19b6709f61e9764a954aafe9ffae488d50ae674aabdcb4f248006d5","price_changes":[{"asset_id":"8761897749749422724209054078244794145777693856614463256546737399611489089783","best_ask":"0.45","best_bid":"0.42","hash":"c3f377b66ece52b59ba13638b8bb7a28a255ce20","price":"0.43","side":"BUY","size":"0"},{"asset_id":"14965588658799411272385430903075831224615961675357217884735713260981483529984","best_ask":"0.58","best_bid":"0.55","hash":"5302f50cd43dbebe94a123804e0c017cf9d33412","price":"0.57","side":"SELL","size":"0"}],"timestamp":"1785208389701"},"payload_hash":"675bed856c60ef924252b2d88d674b5491c2c5667c35831a9f2b40058122e8c2","raw_frame":"{\"market\":\"0x779291bef19b6709f61e9764a954aafe9ffae488d50ae674aabdcb4f248006d5\", \"price_changes\":[{\"asset_id\":\"8761897749749422724209054078244794145777693856614463256546737399611489089783\", \"price\":\"0.43\", \"size\":\"0\", \"side\":\"BUY\", \"hash\":\"c3f377b66ece52b59ba13638b8bb7a28a255ce20\", \"best_bid\":\"0.42\", \"best_ask\":\"0.45\"}, {\"asset_id\":\"14965588658799411272385430903075831224615961675357217884735713260981483529984\", \"price\":\"0.57\", \"size\":\"0\", \"side\":\"SELL\", \"hash\":\"5302f50cd43dbebe94a123804e0c017cf9d33412\", \"best_bid\":\"0.55\", \"best_ask\":\"0.58\"}], \"timestamp\":\"1785208389701\", \"event_type\":\"price_change\"}","received_at":"2026-07-28T03:13:15.460352Z","schema_version":"clob-market-ws.price_change.v1","sequence":null,"server_hash":null,"server_timestamp":"1785208389701","session_id":"3e519d9098404c15b234d96025eb1a2b","source":"clob_market_ws"},"received_at":"2026-07-28T03:13:15.460352Z","record_id":"f6b2d3da92d4f2fc4fa95431f627dfcc5b680513aa233ef6673c689d6a41df13","schema_fingerprint":"4aa3821a28b0b7c2400bc59aba4bcc0a76e971dadd19610d3ad38c768e124dc7","schema_version":"edge-lab-recorder.raw.v1","sequence":null,"source":"clob_market_ws"}
{"event_at":"2026-07-28T03:13:09.703000Z","event_fingerprint":"01b91fc68d3cbf6b221e72a3fb7700dd978eed147d1bb78464e1d561c4c9f78d","payload":{"connection_id":"a6b55582af5f430fb37ad02bf0922475","event_at":"2026-07-28T03:13:09.703000Z","event_type":"price_change","frame_hash":"70c6ed64e9a52d5ecf70c01ad8bc208c1236d38ec2ed0c05218e098d85e1467b","frame_index":0,"kind":"data","monotonic_ns":310378496882458,"payload":{"event_type":"price_change","market":"0x779291bef19b6709f61e9764a954aafe9ffae488d50ae674aabdcb4f248006d5","price_changes":[{"asset_id":"14965588658799411272385430903075831224615961675357217884735713260981483529984","best_ask":"0.58","best_bid":"0.55","hash":"3c943e17ae6420e2523ae3ae235da83965ce334e","price":"0.55","side":"BUY","size":"86"},{"asset_id":"8761897749749422724209054078244794145777693856614463256546737399611489089783","best_ask":"0.45","best_bid":"0.42","hash":"f4fc9d0b1346d0f211dc1d9e0704dcda5b138e79","price":"0.45","side":"SELL","size":"86"}],"timestamp":"1785208389703"},"payload_hash":"7d70e88a4dda280cd6da733517d4326cc07cb6e21211af2cf34c73e8ab48958d","raw_frame":"{\"market\":\"0x779291bef19b6709f61e9764a954aafe9ffae488d50ae674aabdcb4f248006d5\", \"price_changes\":[{\"asset_id\":\"14965588658799411272385430903075831224615961675357217884735713260981483529984\", \"price\":\"0.55\", \"size\":\"86\", \"side\":\"BUY\", \"hash\":\"3c943e17ae6420e2523ae3ae235da83965ce334e\", \"best_bid\":\"0.55\", \"best_ask\":\"0.58\"}, {\"asset_id\":\"8761897749749422724209054078244794145777693856614463256546737399611489089783\", \"price\":\"0.45\", \"size\":\"86\", \"side\":\"SELL\", \"hash\":\"f4fc9d0b1346d0f211dc1d9e0704dcda5b138e79\", \"best_bid\":\"0.42\", \"best_ask\":\"0.45\"}], \"timestamp\":\"1785208389703\", \"event_type\":\"price_change\"}","received_at":"2026-07-28T03:13:15.461872Z","schema_version":"clob-market-ws.price_change.v1","sequence":null,"server_hash":null,"server_timestamp":"1785208389703","session_id":"3e519d9098404c15b234d96025eb1a2b","source":"clob_market_ws"},"received_at":"2026-07-28T03:13:15.461872Z","record_id":"dc4623b66735de22440f3f77e1b80f5a98240600335406d5225082bbaf468da5","schema_fingerprint":"4aa3821a28b0b7c2400bc59aba4bcc0a76e971dadd19610d3ad38c768e124dc7","schema_version":"edge-lab-recorder.raw.v1","sequence":null,"source":"clob_market_ws"}
{"event_at":"2026-07-28T03:13:09.704000Z","event_fingerprint":"1abf534e627eac43909b956a9a96b2577d02872de4d769ff4118f9496ef4ef44","payload":{"connection_id":"a6b55582af5f430fb37ad02bf0922475","event_at":"2026-07-28T03:13:09.704000Z","event_type":"price_change","frame_hash":"a7f29ecd679b6c76d22ec23df5a8b18d20c303ac3a9ee7d4664c319030682079","frame_index":0,"kind":"data","monotonic_ns":310378498394833,"payload":{"event_type":"price_change","market":"0x779291bef19b6709f61e9764a954aafe9ffae488d50ae674aabdcb4f248006d5","price_changes":[{"asset_id":"14965588658799411272385430903075831224615961675357217884735713260981483529984","best_ask":"0.58","best_bid":"0.55","hash":"8f47521ef207496b3f4a4a08ab2dd73f0bbd8558","price":"0.04","side":"BUY","size":"575"},{"asset_id":"8761897749749422724209054078244794145777693856614463256546737399611489089783","best_ask":"0.45","best_bid":"0.42","hash":"fe5f0d39816527d76d119b073af748f242ddc2f1","price":"0.96","side":"SELL","size":"575"}],"timestamp":"1785208389704"},"payload_hash":"447b1da91265b6f3b5c2336ea959fd581a51fe025e91a488e4df9786e1646302","raw_frame":"{\"market\":\"0x779291bef19b6709f61e9764a954aafe9ffae488d50ae674aabdcb4f248006d5\", \"price_changes\":[{\"asset_id\":\"14965588658799411272385430903075831224615961675357217884735713260981483529984\", \"price\":\"0.04\", \"size\":\"575\", \"side\":\"BUY\", \"hash\":\"8f47521ef207496b3f4a4a08ab2dd73f0bbd8558\", \"best_bid\":\"0.55\", \"best_ask\":\"0.58\"}, {\"asset_id\":\"8761897749749422724209054078244794145777693856614463256546737399611489089783\", \"price\":\"0.96\", \"size\":\"575\", \"side\":\"SELL\", \"hash\":\"fe5f0d39816527d76d119b073af748f242ddc2f1\", \"best_bid\":\"0.42\", \"best_ask\":\"0.45\"}], \"timestamp\":\"1785208389704\", \"event_type\":\"price_change\"}","received_at":"2026-07-28T03:13:15.463383Z","schema_version":"clob-market-ws.price_change.v1","sequence":null,"server_hash":null,"server_timestamp":"1785208389704","session_id":"3e519d9098404c15b234d96025eb1a2b","source":"clob_market_ws"},"received_at":"2026-07-28T03:13:15.463383Z","record_id":"597538e163827e63f600b875f2a708420bf61d646849b6cf2c6cf8f38742dee1","schema_fingerprint":"4aa3821a28b0b7c2400bc59aba4bcc0a76e971dadd19610d3ad38c768e124dc7","schema_version":"edge-lab-recorder.raw.v1","sequence":null,"source":"clob_market_ws"}
{"event_at":"2026-07-28T03:13:09.705000Z","event_fingerprint":"e9946dd7e47a0908fff6b6e59d28ebebd681b509d1e59b7c40e2d9fec19b120a","payload":{"connection_id":"a6b55582af5f430fb37ad02bf0922475","event_at":"2026-07-28T03:13:09.705000Z","event_type":"price_change","frame_hash":"e8dac09f5f538db1973a0bbe28478d8077312df9b9aeed96bb45b922ca1a3862","frame_index":0,"kind":"data","monotonic_ns":310378502346208,"payload":{"event_type":"price_change","market":"0x779291bef19b6709f61e9764a954aafe9ffae488d50ae674aabdcb4f248006d5","price_changes":[{"asset_id":"14965588658799411272385430903075831224615961675357217884735713260981483529984","best_ask":"0.58","best_bid":"0.55","hash":"4d299067fb4e29f85ecdbf55d6fb742be154a154","price":"0.3","side":"BUY","size":"90.12"},{"asset_id":"8761897749749422724209054078244794145777693856614463256546737399611489089783","best_ask":"0.45","best_bid":"0.42","hash":"3cd07b8cb44a52f19685ba58f01aacc11aa6ee04","price":"0.7","side":"SELL","size":"90.12"}],"timestamp":"1785208389705"},"payload_hash":"0de6ef545abcb80028c399952c7bde9805db8dd569b55d4bf1cd0ef1945b0e4a","raw_frame":"{\"market\":\"0x779291bef19b6709f61e9764a954aafe9ffae488d50ae674aabdcb4f248006d5\", \"price_changes\":[{\"asset_id\":\"14965588658799411272385430903075831224615961675357217884735713260981483529984\", \"price\":\"0.3\", \"size\":\"90.12\", \"side\":\"BUY\", \"hash\":\"4d299067fb4e29f85ecdbf55d6fb742be154a154\", \"best_bid\":\"0.55\", \"best_ask\":\"0.58\"}, {\"asset_id\":\"8761897749749422724209054078244794145777693856614463256546737399611489089783\", \"price\":\"0.7\", \"size\":\"90.12\", \"side\":\"SELL\", \"hash\":\"3cd07b8cb44a52f19685ba58f01aacc11aa6ee04\", \"best_bid\":\"0.42\", \"best_ask\":\"0.45\"}], \"timestamp\":\"1785208389705\", \"event_type\":\"price_change\"}","received_at":"2026-07-28T03:13:15.467334Z","schema_version":"clob-market-ws.price_change.v1","sequence":null,"server_hash":null,"server_timestamp":"1785208389705","session_id":"3e519d9098404c15b234d96025eb1a2b","source":"clob_market_ws"},"received_at":"2026-07-28T03:13:15.467334Z","record_id":"24d7629ab2df55fee746f1498245a2d2d3b8e05f4b9eb6ce6af1175f21cbae1e","schema_fingerprint":"4aa3821a28b0b7c2400bc59aba4bcc0a76e971dadd19610d3ad38c768e124dc7","schema_version":"edge-lab-recorder.raw.v1","sequence":null,"source":"clob_market_ws"}
{"event_at":"2026-07-28T03:13:09.705000Z","event_fingerprint":"1a37c404a3c62bd3326b3272dcbe70f830445bee6d59c54c84b0f0769707fda7","payload":{"connection_id":"a6b55582af5f430fb37ad02bf0922475","event_at":"2026-07-28T03:13:09.705000Z","event_type":"price_change","frame_hash":"f2bce4f6cb8915eb40f0362ac45c32c0df38fe4e24b76ee457145111c86530ef","frame_index":0,"kind":"data","monotonic_ns":310378505592791,"payload":{"event_type":"price_change","market":"0x779291bef19b6709f61e9764a954aafe9ffae488d50ae674aabdcb4f248006d5","price_changes":[{"asset_id":"14965588658799411272385430903075831224615961675357217884735713260981483529984","best_ask":"0.58","best_bid":"0.55","hash":"7b50a4270fe88af61ef5bbc629796a347480bdc5","price":"0.51","side":"BUY","size":"108.2"},{"asset_id":"8761897749749422724209054078244794145777693856614463256546737399611489089783","best_ask":"0.45","best_bid":"0.42","hash":"48f620021f27489b5cef0440cdd0cc08cbd66775","price":"0.49","side":"SELL","size":"108.2"}],"timestamp":"1785208389705"},"payload_hash":"d4fdee9e5baebc4b2bc40808f931509b86659621e402276503586f526664fdf0","raw_frame":"{\"market\":\"0x779291bef19b6709f61e9764a954aafe9ffae488d50ae674aabdcb4f248006d5\", \"price_changes\":[{\"asset_id\":\"14965588658799411272385430903075831224615961675357217884735713260981483529984\", \"price\":\"0.51\", \"size\":\"108.2\", \"side\":\"BUY\", \"hash\":\"7b50a4270fe88af61ef5bbc629796a347480bdc5\", \"best_bid\":\"0.55\", \"best_ask\":\"0.58\"}, {\"asset_id\":\"8761897749749422724209054078244794145777693856614463256546737399611489089783\", \"price\":\"0.49\", \"size\":\"108.2\", \"side\":\"SELL\", \"hash\":\"48f620021f27489b5cef0440cdd0cc08cbd66775\", \"best_bid\":\"0.42\", \"best_ask\":\"0.45\"}], \"timestamp\":\"1785208389705\", \"event_type\":\"price_change\"}","received_at":"2026-07-28T03:13:15.470581Z","schema_version":"clob-market-ws.price_change.v1","sequence":null,"server_hash":null,"server_timestamp":"1785208389705","session_id":"3e519d9098404c15b234d96025eb1a2b","source":"clob_market_ws"},"received_at":"2026-07-28T03:13:15.470581Z","record_id":"ef1116644a39e3ba7d8c46c195852e387acc7c84cb9ee976b4a8218051bb3a0d","schema_fingerprint":"4aa3821a28b0b7c2400bc59aba4bcc0a76e971dadd19610d3ad38c768e124dc7","schema_version":"edge-lab-recorder.raw.v1","sequence":null,"source":"clob_market_ws"}
{"event_at":"2026-07-28T03:13:09.706000Z","event_fingerprint":"a751f616f1213c586a4ce4874a1334835c41695de1d75178607aefb992a2a450","payload":{"connection_id":"a6b55582af5f430fb37ad02bf0922475","event_at":"2026-07-28T03:13:09.706000Z","event_type":"best_bid_ask","frame_hash":"9742c2054d4aa1cb0b8f31c88d83dee1ebdab0077e6bb1c198af398b80f4dd45","frame_index":0,"kind":"data","monotonic_ns":310378507156041,"payload":{"asset_id":"14965588658799411272385430903075831224615961675357217884735713260981483529984","best_ask":"0.58","best_bid":"0.56","event_type":"best_bid_ask","market":"0x779291bef19b6709f61e9764a954aafe9ffae488d50ae674aabdcb4f248006d5","spread":"0.02","timestamp":"1785208389706"},"payload_hash":"5af2d70d54d536660c50e0dcaae1cf187095d4c01e1114f8f6085a6d9c5d411b","raw_frame":"{\"market\":\"0x779291bef19b6709f61e9764a954aafe9ffae488d50ae674aabdcb4f248006d5\", \"asset_id\":\"14965588658799411272385430903075831224615961675357217884735713260981483529984\", \"best_bid\":\"0.56\", \"best_ask\":\"0.58\", \"spread\":\"0.02\", \"timestamp\":\"1785208389706\", \"event_type\":\"best_bid_ask\"}","received_at":"2026-07-28T03:13:15.472144Z","schema_version":"clob-market-ws.best_bid_ask.v1","sequence":null,"server_hash":null,"server_timestamp":"1785208389706","session_id":"3e519d9098404c15b234d96025eb1a2b","source":"clob_market_ws"},"received_at":"2026-07-28T03:13:15.472144Z","record_id":"0e47b51fff8b8551a77810275fe8010196e6f1de63569df1290b2668a0770739","schema_fingerprint":"8488399f31b0337811b13b266be932db7062827c2470b78bd8e9e99bab51d17d","schema_version":"edge-lab-recorder.raw.v1","sequence":null,"source":"clob_market_ws"}
{"event_at":"2026-07-28T03:13:09.706000Z","event_fingerprint":"11034e2c9a634286d013b692c038b54906edf79c0fdd143f7c161d205cf9c412","payload":{"connection_id":"a6b55582af5f430fb37ad02bf0922475","event_at":"2026-07-28T03:13:09.706000Z","event_type":"best_bid_ask","frame_hash":"e7e7f0371c76dcc59d0269c9b47d707beeb3ba5a483318ed41a31c40a2aa1c4d","frame_index":0,"kind":"data","monotonic_ns":310378508264750,"payload":{"asset_id":"8761897749749422724209054078244794145777693856614463256546737399611489089783","best_ask":"0.44","best_bid":"0.42","event_type":"best_bid_ask","market":"0x779291bef19b6709f61e9764a954aafe9ffae488d50ae674aabdcb4f248006d5","spread":"0.02","timestamp":"1785208389706"},"payload_hash":"407c95207bed19f362db73edcaef8e8d8a499f9d142574d8c5b7415dcf08d657","raw_frame":"{\"market\":\"0x779291bef19b6709f61e9764a954aafe9ffae488d50ae674aabdcb4f248006d5\", \"asset_id\":\"8761897749749422724209054078244794145777693856614463256546737399611489089783\", \"best_bid\":\"0.42\", \"best_ask\":\"0.44\", \"spread\":\"0.02\", \"timestamp\":\"1785208389706\", \"event_type\":\"best_bid_ask\"}","received_at":"2026-07-28T03:13:15.473252Z","schema_version":"clob-market-ws.best_bid_ask.v1","sequence":null,"server_hash":null,"server_timestamp":"1785208389706","session_id":"3e519d9098404c15b234d96025eb1a2b","source":"clob_market_ws"},"received_at":"2026-07-28T03:13:15.473252Z","record_id":"9c31e818d44d4b39dbf33299886db02c2d29e917fd0073a88ee7b916b09f0c99","schema_fingerprint":"8488399f31b0337811b13b266be932db7062827c2470b78bd8e9e99bab51d17d","schema_version":"edge-lab-recorder.raw.v1","sequence":null,"source":"clob_market_ws"}
{"event_at":"2026-07-28T03:13:09.706000Z","event_fingerprint":"e205780ebbd309f11ba1c26100a6a7f8c17dd7c7e7382ba5b42d4d9757150d0f","payload":{"connection_id":"a6b55582af5f430fb37ad02bf0922475","event_at":"2026-07-28T03:13:09.706000Z","event_type":"price_change","frame_hash":"04f2153aeecc0f96f14d24366ce8c34689bc0f0623e570e5cd745d5f05ec688a","frame_index":0,"kind":"data","monotonic_ns":310378509328250,"payload":{"event_type":"price_change","market":"0x779291bef19b6709f61e9764a954aafe9ffae488d50ae674aabdcb4f248006d5","price_changes":[{"asset_id":"14965588658799411272385430903075831224615961675357217884735713260981483529984","best_ask":"0.58","best_bid":"0.56","hash":"3275c709844f958513260f7da90a603314440585","price":"0.56","side":"BUY","size":"20"},{"asset_id":"8761897749749422724209054078244794145777693856614463256546737399611489089783","best_ask":"0.44","best_bid":"0.42","hash":"3369aa3a821a10adc723803ddb4942ddba5982ec","price":"0.44","side":"SELL","size":"20"}],"timestamp":"1785208389706"},"payload_hash":"9a30ae09267caf00c0fb2b84e39c53c05980c563232109771a8235641226e798","raw_frame":"{\"market\":\"0x779291bef19b6709f61e9764a954aafe9ffae488d50ae674aabdcb4f248006d5\", \"price_changes\":[{\"asset_id\":\"14965588658799411272385430903075831224615961675357217884735713260981483529984\", \"price\":\"0.56\", \"size\":\"20\", \"side\":\"BUY\", \"hash\":\"3275c709844f958513260f7da90a603314440585\", \"best_bid\":\"0.56\", \"best_ask\":\"0.58\"}, {\"asset_id\":\"8761897749749422724209054078244794145777693856614463256546737399611489089783\", \"price\":\"0.44\", \"size\":\"20\", \"side\":\"SELL\", \"hash\":\"3369aa3a821a10adc723803ddb4942ddba5982ec\", \"best_bid\":\"0.42\", \"best_ask\":\"0.44\"}], \"timestamp\":\"1785208389706\", \"event_type\":\"price_change\"}","received_at":"2026-07-28T03:13:15.474317Z","schema_version":"clob-market-ws.price_change.v1","sequence":null,"server_hash":null,"server_timestamp":"1785208389706","session_id":"3e519d9098404c15b234d96025eb1a2b","source":"clob_market_ws"},"received_at":"2026-07-28T03:13:15.474317Z","record_id":"14e174e53ceeb130fd73571e21955dcc5e81241632607321cf38ca6125f581a0","schema_fingerprint":"4aa3821a28b0b7c2400bc59aba4bcc0a76e971dadd19610d3ad38c768e124dc7","schema_version":"edge-lab-recorder.raw.v1","sequence":null,"source":"clob_market_ws"}
{"event_at":"2026-07-28T03:13:09.706000Z","event_fingerprint":"885c4ef9932fb4b47a70a70e8ff21f0aec7f6e449937e4adf6224b1608db9889","payload":{"connection_id":"a6b55582af5f430fb37ad02bf0922475","event_at":"2026-07-28T03:13:09.706000Z","event_type":"price_change","frame_hash":"b8ff45d4d10e716935d369afcee3f5582b858eb53dcf30ef9407f25023711e93","frame_index":0,"kind":"data","monotonic_ns":310378510881041,"payload":{"event_type":"price_change","market":"0x779291bef19b6709f61e9764a954aafe9ffae488d50ae674aabdcb4f248006d5","price_changes":[{"asset_id":"8761897749749422724209054078244794145777693856614463256546737399611489089783","best_ask":"0.44","best_bid":"0.42","hash":"214554475f98e3a023a78a7796cd9ae62c5955a1","price":"0.49","side":"SELL","size":"92.2"},{"asset_id":"14965588658799411272385430903075831224615961675357217884735713260981483529984","best_ask":"0.58","best_bid":"0.56","hash":"e7175641683cceac73bb72a72590cd037da9de47","price":"0.51","side":"BUY","size":"92.2"}],"timestamp":"1785208389706"},"payload_hash":"b346c37bc8147c8c28720623bf9535e590ceebaa54574861f60e2b3bfa7c4c26","raw_frame":"{\"market\":\"0x779291bef19b6709f61e9764a954aafe9ffae488d50ae674aabdcb4f248006d5\", \"price_changes\":[{\"asset_id\":\"8761897749749422724209054078244794145777693856614463256546737399611489089783\", \"price\":\"0.49\", \"size\":\"92.2\", \"side\":\"SELL\", \"hash\":\"214554475f98e3a023a78a7796cd9ae62c5955a1\", \"best_bid\":\"0.42\", \"best_ask\":\"0.44\"}, {\"asset_id\":\"14965588658799411272385430903075831224615961675357217884735713260981483529984\", \"price\":\"0.51\", \"size\":\"92.2\", \"side\":\"BUY\", \"hash\":\"e7175641683cceac73bb72a72590cd037da9de47\", \"best_bid\":\"0.56\", \"best_ask\":\"0.58\"}], \"timestamp\":\"1785208389706\", \"event_type\":\"price_change\"}","received_at":"2026-07-28T03:13:15.475869Z","schema_version":"clob-market-ws.price_change.v1","sequence":null,"server_hash":null,"server_timestamp":"1785208389706","session_id":"3e519d9098404c15b234d96025eb1a2b","source":"clob_market_ws"},"received_at":"2026-07-28T03:13:15.475869Z","record_id":"e6ead5e58de757fb72bd2c5c4490e1e75705058fe45abd7d87caad84887dfa9b","schema_fingerprint":"4aa3821a28b0b7c2400bc59aba4bcc0a76e971dadd19610d3ad38c768e124dc7","schema_version":"edge-lab-recorder.raw.v1","sequence":null,"source":"clob_market_ws"}
{"event_at":"2026-07-28T03:13:09.710000Z","event_fingerprint":"b6e9e94f9fe91634552016fc225f85661077106a97f9ac8ff21630858d674890","payload":{"connection_id":"a6b55582af5f430fb37ad02bf0922475","event_at":"2026-07-28T03:13:09.710000Z","event_type":"price_change","frame_hash":"2b12ecfb5433e980c2cb87dff06f5baac5333dea94fc3fe6cb97bc9b3839f22e","frame_index":0,"kind":"data","monotonic_ns":310378520477125,"payload":{"event_type":"price_change","market":"0x779291bef19b6709f61e9764a954aafe9ffae488d50ae674aabdcb4f248006d5","price_changes":[{"asset_id":"14965588658799411272385430903075831224615961675357217884735713260981483529984","best_ask":"0.58","best_bid":"0.56","hash":"082dd6ae03379ceedf9250749c1dfd756365a473","price":"0.55","side":"BUY","size":"106"},{"asset_id":"8761897749749422724209054078244794145777693856614463256546737399611489089783","best_ask":"0.44","best_bid":"0.42","hash":"7bb3860757e757a3d1a68fcc946396341e07b14a","price":"0.45","side":"SELL","size":"106"}],"timestamp":"1785208389710"},"payload_hash":"e798bfa8df164d524733b23afd455e65f8e377bd9dc7b13fe9562a9687cefa22","raw_frame":"{\"market\":\"0x779291bef19b6709f61e9764a954aafe9ffae488d50ae674aabdcb4f248006d5\", \"price_changes\":[{\"asset_id\":\"14965588658799411272385430903075831224615961675357217884735713260981483529984\", \"price\":\"0.55\", \"size\":\"106\", \"side\":\"BUY\", \"hash\":\"082dd6ae03379ceedf9250749c1dfd756365a473\", \"best_bid\":\"0.56\", \"best_ask\":\"0.58\"}, {\"asset_id\":\"8761897749749422724209054078244794145777693856614463256546737399611489089783\", \"price\":\"0.45\", \"size\":\"106\", \"side\":\"SELL\", \"hash\":\"7bb3860757e757a3d1a68fcc946396341e07b14a\", \"best_bid\":\"0.42\", \"best_ask\":\"0.44\"}], \"timestamp\":\"1785208389710\", \"event_type\":\"price_change\"}","received_at":"2026-07-28T03:13:15.485464Z","schema_version":"clob-market-ws.price_change.v1","sequence":null,"server_hash":null,"server_timestamp":"1785208389710","session_id":"3e519d9098404c15b234d96025eb1a2b","source":"clob_market_ws"},"received_at":"2026-07-28T03:13:15.485464Z","record_id":"515603610d7cb943ee6b9c0db55cf4842baf5e771b6d8a2727fd6410298243d0","schema_fingerprint":"4aa3821a28b0b7c2400bc59aba4bcc0a76e971dadd19610d3ad38c768e124dc7","schema_version":"edge-lab-recorder.raw.v1","sequence":null,"source":"clob_market_ws"}
{"event_at":"2026-07-28T03:13:09.711000Z","event_fingerprint":"d50c147d08a3670771ce4c81fdc4fce1914ad1cee348b12d8b669664026615f6","payload":{"connection_id":"a6b55582af5f430fb37ad02bf0922475","event_at":"2026-07-28T03:13:09.711000Z","event_type":"price_change","frame_hash":"3418e738c2c88f411c30293141be19de6061b09919f9c5dd82ee75c0ad7a49df","frame_index":0,"kind":"data","monotonic_ns":310378522496916,"payload":{"event_type":"price_change","market":"0x779291bef19b6709f61e9764a954aafe9ffae488d50ae674aabdcb4f248006d5","price_changes":[{"asset_id":"14965588658799411272385430903075831224615961675357217884735713260981483529984","best_ask":"0.58","best_bid":"0.56","hash":"f86242d920fc1c002f6cb2b234c7aa6d9124ff5e","price":"0.55","side":"BUY","size":"128"},{"asset_id":"8761897749749422724209054078244794145777693856614463256546737399611489089783","best_ask":"0.44","best_bid":"0.42","hash":"b24eeea8b8877e41850a8a58f3610b80212beac9","price":"0.45","side":"SELL","size":"128"}],"timestamp":"1785208389711"},"payload_hash":"385c8715d934305764d2a3e3bcefdf1748084c8d7e381588c4beb4612901f057","raw_frame":"{\"market\":\"0x779291bef19b6709f61e9764a954aafe9ffae488d50ae674aabdcb4f248006d5\", \"price_changes\":[{\"asset_id\":\"14965588658799411272385430903075831224615961675357217884735713260981483529984\", \"price\":\"0.55\", \"size\":\"128\", \"side\":\"BUY\", \"hash\":\"f86242d920fc1c002f6cb2b234c7aa6d9124ff5e\", \"best_bid\":\"0.56\", \"best_ask\":\"0.58\"}, {\"asset_id\":\"8761897749749422724209054078244794145777693856614463256546737399611489089783\", \"price\":\"0.45\", \"size\":\"128\", \"side\":\"SELL\", \"hash\":\"b24eeea8b8877e41850a8a58f3610b80212beac9\", \"best_bid\":\"0.42\", \"best_ask\":\"0.44\"}], \"timestamp\":\"1785208389711\", \"event_type\":\"price_change\"}","received_at":"2026-07-28T03:13:15.487484Z","schema_version":"clob-market-ws.price_change.v1","sequence":null,"server_hash":null,"server_timestamp":"1785208389711","session_id":"3e519d9098404c15b234d96025eb1a2b","source":"clob_market_ws"},"received_at":"2026-07-28T03:13:15.487484Z","record_id":"c1049caf8c942017213648d96e98d6730c54db8ae909ab389990d7a9b01f61d6","schema_fingerprint":"4aa3821a28b0b7c2400bc59aba4bcc0a76e971dadd19610d3ad38c768e124dc7","schema_version":"edge-lab-recorder.raw.v1","sequence":null,"source":"clob_market_ws"}
{"event_at":"2026-07-28T03:13:09.712000Z","event_fingerprint":"bd8dc6a906ac9ce9e3c259242de8fd91a2fb450c33099051fc352b7b58af81ad","payload":{"connection_id":"a6b55582af5f430fb37ad02bf0922475","event_at":"2026-07-28T03:13:09.712000Z","event_type":"price_change","frame_hash":"7b65ceb7e8e8d68304b03c5e76f9117e049568f140e18df99291a12d129b643b","frame_index":0,"kind":"data","monotonic_ns":310378524091291,"payload":{"event_type":"price_change","market":"0x779291bef19b6709f61e9764a954aafe9ffae488d50ae674aabdcb4f248006d5","price_changes":[{"asset_id":"14965588658799411272385430903075831224615961675357217884735713260981483529984","best_ask":"0.58","best_bid":"0.56","hash":"719e4b40ac32e7d9ab7e67ab6f048f46a1ac34b4","price":"0.55","side":"BUY","size":"168"},{"asset_id":"8761897749749422724209054078244794145777693856614463256546737399611489089783","best_ask":"0.44","best_bid":"0.42","hash":"d34db42c557fb270f62c42bc545ba9c267fad1dc","price":"0.45","side":"SELL","size":"168"}],"timestamp":"1785208389712"},"payload_hash":"579139bf6a9ca654c962dcfc670045d258716d1d4f37381e38dc5e66cbcd6097","raw_frame":"{\"market\":\"0x779291bef19b6709f61e9764a954aafe9ffae488d50ae674aabdcb4f248006d5\", \"price_changes\":[{\"asset_id\":\"14965588658799411272385430903075831224615961675357217884735713260981483529984\", \"price\":\"0.55\", \"size\":\"168\", \"side\":\"BUY\", \"hash\":\"719e4b40ac32e7d9ab7e67ab6f048f46a1ac34b4\", \"best_bid\":\"0.56\", \"best_ask\":\"0.58\"}, {\"asset_id\":\"8761897749749422724209054078244794145777693856614463256546737399611489089783\", \"price\":\"0.45\", \"size\":\"168\", \"side\":\"SELL\", \"hash\":\"d34db42c557fb270f62c42bc545ba9c267fad1dc\", \"best_bid\":\"0.42\", \"best_ask\":\"0.44\"}], \"timestamp\":\"1785208389712\", \"event_type\":\"price_change\"}","received_at":"2026-07-28T03:13:15.489079Z","schema_version":"clob-market-ws.price_change.v1","sequence":null,"server_hash":null,"server_timestamp":"1785208389712","session_id":"3e519d9098404c15b234d96025eb1a2b","source":"clob_market_ws"},"received_at":"2026-07-28T03:13:15.489079Z","record_id":"c400ce96d95830aa448efc3059006612dc401be1860fd164529a60308415ff26","schema_fingerprint":"4aa3821a28b0b7c2400bc59aba4bcc0a76e971dadd19610d3ad38c768e124dc7","schema_version":"edge-lab-recorder.raw.v1","sequence":null,"source":"clob_market_ws"}
{"event_at":"2026-07-28T03:13:09.715000Z","event_fingerprint":"81302314ee745cb84f27b935b905fc9ca13ff9d70877c7e7492d6cd3c8035921","payload":{"connection_id":"a6b55582af5f430fb37ad02bf0922475","event_at":"2026-07-28T03:13:09.715000Z","event_type":"price_change","frame_hash":"41dbaa06e25f9d0300b76e802cc806f54d00302e44df731a4d6d31f62abdf496","frame_index":0,"kind":"data","monotonic_ns":310378525647500,"payload":{"event_type":"price_change","market":"0x779291bef19b6709f61e9764a954aafe9ffae488d50ae674aabdcb4f248006d5","price_changes":[{"asset_id":"14965588658799411272385430903075831224615961675357217884735713260981483529984","best_ask":"0.58","best_bid":"0.56","hash":"d28fc7fc378b187db9330669bb04faa11180be60","price":"0.55","side":"BUY","size":"174"},{"asset_id":"8761897749749422724209054078244794145777693856614463256546737399611489089783","best_ask":"0.44","best_bid":"0.42","hash":"6ed43938647da04f33de75f4fbf34fd8cd27cad8","price":"0.45","side":"SELL","size":"174"}],"timestamp":"1785208389715"},"payload_hash":"c9f582689ea5d10cac05b1e8f9a69cf7b9c34514c76659c5f9efc48a19246bbc","raw_frame":"{\"market\":\"0x779291bef19b6709f61e9764a954aafe9ffae488d50ae674aabdcb4f248006d5\", \"price_changes\":[{\"asset_id\":\"14965588658799411272385430903075831224615961675357217884735713260981483529984\", \"price\":\"0.55\", \"size\":\"174\", \"side\":\"BUY\", \"hash\":\"d28fc7fc378b187db9330669bb04faa11180be60\", \"best_bid\":\"0.56\", \"best_ask\":\"0.58\"}, {\"asset_id\":\"8761897749749422724209054078244794145777693856614463256546737399611489089783\", \"price\":\"0.45\", \"size\":\"174\", \"side\":\"SELL\", \"hash\":\"6ed43938647da04f33de75f4fbf34fd8cd27cad8\", \"best_bid\":\"0.42\", \"best_ask\":\"0.44\"}], \"timestamp\":\"1785208389715\", \"event_type\":\"price_change\"}","received_at":"2026-07-28T03:13:15.490635Z","schema_version":"clob-market-ws.price_change.v1","sequence":null,"server_hash":null,"server_timestamp":"1785208389715","session_id":"3e519d9098404c15b234d96025eb1a2b","source":"clob_market_ws"},"received_at":"2026-07-28T03:13:15.490635Z","record_id":"db9d8b652f4897fb028766b9cdc9233f95685284b93b1cc99b2d0b142e2945bb","schema_fingerprint":"4aa3821a28b0b7c2400bc59aba4bcc0a76e971dadd19610d3ad38c768e124dc7","schema_version":"edge-lab-recorder.raw.v1","sequence":null,"source":"clob_market_ws"}
