{"event_at":"2026-07-28T03:03:46.799000Z","event_fingerprint":"086ea6e13504ad76bd7d21a38059b394c573a3d980d889f47fc8fb91b00b9c60","payload":{"connection_id":"a6b55582af5f430fb37ad02bf0922475","event_at":"2026-07-28T03:03:46.799000Z","event_type":"price_change","frame_hash":"6ed6b56aba6c2c41eaa24b2d75d48e9459e37ddea17f82fdb0b8e53ac6fe4552","frame_index":0,"kind":"data","monotonic_ns":309809681585583,"payload":{"event_type":"price_change","market":"0x779291bef19b6709f61e9764a954aafe9ffae488d50ae674aabdcb4f248006d5","price_changes":[{"asset_id":"14965588658799411272385430903075831224615961675357217884735713260981483529984","best_ask":"0.63","best_bid":"0.62","hash":"64cdf05304e6a142c36aafceeb88236d1eee11d8","price":"0.01","side":"BUY","size":"7888.02"},{"asset_id":"8761897749749422724209054078244794145777693856614463256546737399611489089783","best_ask":"0.38","best_bid":"0.37","hash":"fdae1c1ef95c3a8f4998b28744aad227a243ed7c","price":"0.99","side":"SELL","size":"7888.02"}],"timestamp":"1785207826799"},"payload_hash":"a1ca155fbbbd8eafc077430fcd3526f0a65bec87712b930cd06c0eccebddacd1","raw_frame":"{\"market\":\"0x779291bef19b6709f61e9764a954aafe9ffae488d50ae674aabdcb4f248006d5\", \"price_changes\":[{\"asset_id\":\"14965588658799411272385430903075831224615961675357217884735713260981483529984\", \"price\":\"0.01\", \"size\":\"7888.02\", \"side\":\"BUY\", \"hash\":\"64cdf05304e6a142c36aafceeb88236d1eee11d8\", \"best_bid\":\"0.62\", \"best_ask\":\"0.63\"}, {\"asset_id\":\"8761897749749422724209054078244794145777693856614463256546737399611489089783\", \"price\":\"0.99\", \"size\":\"7888.02\", \"side\":\"SELL\", \"hash\":\"fdae1c1ef95c3a8f4998b28744aad227a243ed7c\", \"best_bid\":\"0.37\", \"best_ask\":\"0.38\"}], \"timestamp\":\"1785207826799\", \"event_type\":\"price_change\"}","received_at":"2026-07-28T03:03:46.661582Z","schema_version":"clob-market-ws.price_change.v1","sequence":null,"server_hash":null,"server_timestamp":"1785207826799","session_id":"3e519d9098404c15b234d96025eb1a2b","source":"clob_market_ws"},"received_at":"2026-07-28T03:03:46.661582Z","record_id":"2a60f8f052d20affd33a26cc6480aca0b92263efa39ee034bca7622021eb0ede","schema_fingerprint":"4aa3821a28b0b7c2400bc59aba4bcc0a76e971dadd19610d3ad38c768e124dc7","schema_version":"edge-lab-recorder.raw.v1","sequence":null,"source":"clob_market_ws"}
{"event_at":"2026-07-28T03:03:46.878000Z","event_fingerprint":"5d6a5a87c29c2ed98d7851bfcee116f6e67927670ec82e58cd5aac391df03c02","payload":{"connection_id":"a6b55582af5f430fb37ad02bf0922475","event_at":"2026-07-28T03:03:46.878000Z","event_type":"price_change","frame_hash":"f5dd46021a0a6d4fa8d18c221a24be41c828813901d3d9c5bb10a64941fe804e","frame_index":0,"kind":"data","monotonic_ns":309809748513125,"payload":{"event_type":"price_change","market":"0x779291bef19b6709f61e9764a954aafe9ffae488d50ae674aabdcb4f248006d5","price_changes":[{"asset_id":"8761897749749422724209054078244794145777693856614463256546737399611489089783","best_ask":"0.38","best_bid":"0.37","hash":"0847647317c8cbdf387466c0248ac37bd4047a3e","price":"0.34","side":"BUY","size":"122.23"},{"asset_id":"14965588658799411272385430903075831224615961675357217884735713260981483529984","best_ask":"0.63","best_bid":"0.62","hash":"c7c1d1d75109d67f5b2895072191926723b765c1","price":"0.66","side":"SELL","size":"122.23"}],"timestamp":"1785207826878"},"payload_hash":"4c5168bc49d1e248712624f8510ecc49f72172f08d561006018530e61d32de1a","raw_frame":"{\"market\":\"0x779291bef19b6709f61e9764a954aafe9ffae488d50ae674aabdcb4f248006d5\", \"price_changes\":[{\"asset_id\":\"8761897749749422724209054078244794145777693856614463256546737399611489089783\", \"price\":\"0.34\", \"size\":\"122.23\", \"side\":\"BUY\", \"hash\":\"0847647317c8cbdf387466c0248ac37bd4047a3e\", \"best_bid\":\"0.37\", \"best_ask\":\"0.38\"}, {\"asset_id\":\"14965588658799411272385430903075831224615961675357217884735713260981483529984\", \"price\":\"0.66\", \"size\":\"122.23\", \"side\":\"SELL\", \"hash\":\"c7c1d1d75109d67f5b2895072191926723b765c1\", \"best_bid\":\"0.62\", \"best_ask\":\"0.63\"}], \"timestamp\":\"1785207826878\", \"event_type\":\"price_change\"}","received_at":"2026-07-28T03:03:46.728509Z","schema_version":"clob-market-ws.price_change.v1","sequence":null,"server_hash":null,"server_timestamp":"1785207826878","session_id":"3e519d9098404c15b234d96025eb1a2b","source":"clob_market_ws"},"received_at":"2026-07-28T03:03:46.728509Z","record_id":"d8caf7efc4a078c12e6388a3999d29aecd87f7b5eb174d83bf51c72980650256","schema_fingerprint":"4aa3821a28b0b7c2400bc59aba4bcc0a76e971dadd19610d3ad38c768e124dc7","schema_version":"edge-lab-recorder.raw.v1","sequence":null,"source":"clob_market_ws"}
{"event_at":"2026-07-28T03:03:46.885000Z","event_fingerprint":"c4321f44e1942363e7615634968a82c89630f00d1299a9aa174dafad2b7bbe44","payload":{"connection_id":"a6b55582af5f430fb37ad02bf0922475","event_at":"2026-07-28T03:03:46.885000Z","event_type":"price_change","frame_hash":"c573cc88845347cbe1af818a0794e12bf95da09ccb367647cd6060a639aebdc1","frame_index":0,"kind":"data","monotonic_ns":309809755993875,"payload":{"event_type":"price_change","market":"0x779291bef19b6709f61e9764a954aafe9ffae488d50ae674aabdcb4f248006d5","price_changes":[{"asset_id":"8761897749749422724209054078244794145777693856614463256546737399611489089783","best_ask":"0.38","best_bid":"0.37","hash":"39175f38d337e0d18ac5aad07db4477b2fc625a6","price":"0.35","side":"BUY","size":"116.01"},{"asset_id":"14965588658799411272385430903075831224615961675357217884735713260981483529984","best_ask":"0.63","best_bid":"0.62","hash":"9fe7c41a8c3db5f99cd4bf956785511795a78443","price":"0.65","side":"SELL","size":"116.01"}],"timestamp":"1785207826885"},"payload_hash":"e636bc5e8ae6894347db5e575a4fbb9d6e73fb94dd918e0325a524758dc3b8ff","raw_frame":"{\"market\":\"0x779291bef19b6709f61e9764a954aafe9ffae488d50ae674aabdcb4f248006d5\", \"price_changes\":[{\"asset_id\":\"8761897749749422724209054078244794145777693856614463256546737399611489089783\", \"price\":\"0.35\", \"size\":\"116.01\", \"side\":\"BUY\", \"hash\":\"39175f38d337e0d18ac5aad07db4477b2fc625a6\", \"best_bid\":\"0.37\", \"best_ask\":\"0.38\"}, {\"asset_id\":\"14965588658799411272385430903075831224615961675357217884735713260981483529984\", \"price\":\"0.65\", \"size\":\"116.01\", \"side\":\"SELL\", \"hash\":\"9fe7c41a8c3db5f99cd4bf956785511795a78443\", \"best_bid\":\"0.62\", \"best_ask\":\"0.63\"}], \"timestamp\":\"1785207826885\", \"event_type\":\"price_change\"}","received_at":"2026-07-28T03:03:46.735991Z","schema_version":"clob-market-ws.price_change.v1","sequence":null,"server_hash":null,"server_timestamp":"1785207826885","session_id":"3e519d9098404c15b234d96025eb1a2b","source":"clob_market_ws"},"received_at":"2026-07-28T03:03:46.735991Z","record_id":"fec177f55c32e223c21d22fa867ae6e5b11b2425664560ae289b19c62f72bb64","schema_fingerprint":"4aa3821a28b0b7c2400bc59aba4bcc0a76e971dadd19610d3ad38c768e124dc7","schema_version":"edge-lab-recorder.raw.v1","sequence":null,"source":"clob_market_ws"}
{"event_at":"2026-07-28T03:03:46.899000Z","event_fingerprint":"a63c589e344b372912cb125c932138fc93fdda5fa8ef468459074d39ddbbf799","payload":{"connection_id":"a6b55582af5f430fb37ad02bf0922475","event_at":"2026-07-28T03:03:46.899000Z","event_type":"price_change","frame_hash":"c290366291b6c0e708fbbf5c7ba0e9d5c1f431bf826b319e44ff1761031345cc","frame_index":0,"kind":"data","monotonic_ns":309809770858666,"payload":{"event_type":"price_change","market":"0x779291bef19b6709f61e9764a954aafe9ffae488d50ae674aabdcb4f248006d5","price_changes":[{"asset_id":"14965588658799411272385430903075831224615961675357217884735713260981483529984","best_ask":"0.63","best_bid":"0.62","hash":"91e7a7fe1e0ea6acc57b6eaddba1b7e45ffb2e5d","price":"0.01","side":"BUY","size":"7883.02"},{"asset_id":"8761897749749422724209054078244794145777693856614463256546737399611489089783","best_ask":"0.38","best_bid":"0.37","hash":"8eb7dfba4ae8e7b94d2c8a6c31bbadd305746369","price":"0.99","side":"SELL","size":"7883.02"}],"timestamp":"1785207826899"},"payload_hash":"c5a046e75ab0f15810ac82d250a41d37625d3718357647311baaf97271b79efc","raw_frame":"{\"market\":\"0x779291bef19b6709f61e9764a954aafe9ffae488d50ae674aabdcb4f248006d5\", \"price_changes\":[{\"asset_id\":\"14965588658799411272385430903075831224615961675357217884735713260981483529984\", \"price\":\"0.01\", \"size\":\"7883.02\", \"side\":\"BUY\", \"hash\":\"91e7a7fe1e0ea6acc57b6eaddba1b7e45ffb2e5d\", \"best_bid\":\"0.62\", \"best_ask\":\"0.63\"}, {\"asset_id\":\"8761897749749422724209054078244794145777693856614463256546737399611489089783\", \"price\":\"0.99\", \"size\":\"7883.02\", \"side\":\"SELL\", \"hash\":\"8eb7dfba4ae8e7b94d2c8a6c31bbadd305746369\", \"best_bid\":\"0.37\", \"best_ask\":\"0.38\"}], \"timestamp\":\"1785207826899\", \"event_type\":\"price_change\"}","received_at":"2026-07-28T03:03:46.750855Z","schema_version":"clob-market-ws.price_change.v1","sequence":null,"server_hash":null,"server_timestamp":"1785207826899","session_id":"3e519d9098404c15b234d96025eb1a2b","source":"clob_market_ws"},"received_at":"2026-07-28T03:03:46.750855Z","record_id":"1d2bad260e8954c2126571c216c949f94d26cacd624bd4f1625b71eaef640edf","schema_fingerprint":"4aa3821a28b0b7c2400bc59aba4bcc0a76e971dadd19610d3ad38c768e124dc7","schema_version":"edge-lab-recorder.raw.v1","sequence":null,"source":"clob_market_ws"}
{"event_at":"2026-07-28T03:03:46.918000Z","event_fingerprint":"505588178dea342e4b6f535929869a2e673050811513c5da2f94a7d77fb4f6d3","payload":{"connection_id":"a6b55582af5f430fb37ad02bf0922475","event_at":"2026-07-28T03:03:46.918000Z","event_type":"price_change","frame_hash":"2969eee987dbb2fa5778de67ca08de4179de312684964f5f32b89fc22c4143a6","frame_index":0,"kind":"data","monotonic_ns":309809788929291,"payload":{"event_type":"price_change","market":"0x779291bef19b6709f61e9764a954aafe9ffae488d50ae674aabdcb4f248006d5","price_changes":[{"asset_id":"14965588658799411272385430903075831224615961675357217884735713260981483529984","best_ask":"0.63","best_bid":"0.62","hash":"2ca434cbac3f96a1a71880f06ae24506306e1d97","price":"0.01","side":"BUY","size":"7888.02"},{"asset_id":"8761897749749422724209054078244794145777693856614463256546737399611489089783","best_ask":"0.38","best_bid":"0.37","hash":"c66488aa09db35540ef2b333544869ad17f6b845","price":"0.99","side":"SELL","size":"7888.02"}],"timestamp":"1785207826918"},"payload_hash":"691b9f77be3e8a9a7763a03efd0db47ef86206794f113682c64b0c06d64b7cb7","raw_frame":"{\"market\":\"0x779291bef19b6709f61e9764a954aafe9ffae488d50ae674aabdcb4f248006d5\", \"price_changes\":[{\"asset_id\":\"14965588658799411272385430903075831224615961675357217884735713260981483529984\", \"price\":\"0.01\", \"size\":\"7888.02\", \"side\":\"BUY\", \"hash\":\"2ca434cbac3f96a1a71880f06ae24506306e1d97\", \"best_bid\":\"0.62\", \"best_ask\":\"0.63\"}, {\"asset_id\":\"8761897749749422724209054078244794145777693856614463256546737399611489089783\", \"price\":\"0.99\", \"size\":\"7888.02\", \"side\":\"SELL\", \"hash\":\"c66488aa09db35540ef2b333544869ad17f6b845\", \"best_bid\":\"0.37\", \"best_ask\":\"0.38\"}], \"timestamp\":\"1785207826918\", \"event_type\":\"price_change\"}","received_at":"2026-07-28T03:03:46.768925Z","schema_version":"clob-market-ws.price_change.v1","sequence":null,"server_hash":null,"server_timestamp":"1785207826918","session_id":"3e519d9098404c15b234d96025eb1a2b","source":"clob_market_ws"},"received_at":"2026-07-28T03:03:46.768925Z","record_id":"96b55ce5378dd171f546f70eb3d12fd571c2d24ee7d8d396e7c7cf26854933c0","schema_fingerprint":"4aa3821a28b0b7c2400bc59aba4bcc0a76e971dadd19610d3ad38c768e124dc7","schema_version":"edge-lab-recorder.raw.v1","sequence":null,"source":"clob_market_ws"}
{"event_at":"2026-07-28T03:03:46.941000Z","event_fingerprint":"cfc5a8b467154535b4faa29ae273d6d3c947efd5ecdfd012499f388dad9421aa","payload":{"connection_id":"a6b55582af5f430fb37ad02bf0922475","event_at":"2026-07-28T03:03:46.941000Z","event_type":"price_change","frame_hash":"b4b4196c78fd7299b1bc533ebac6b307801118211b67548ea7b88ac6941c7c17","frame_index":0,"kind":"data","monotonic_ns":309809816427750,"payload":{"event_type":"price_change","market":"0x779291bef19b6709f61e9764a954aafe9ffae488d50ae674aabdcb4f248006d5","price_changes":[{"asset_id":"14965588658799411272385430903075831224615961675357217884735713260981483529984","best_ask":"0.63","best_bid":"0.62","hash":"ff75eb558ed38ce0dc1a6dead419d91109d65d08","price":"0.01","side":"BUY","size":"7883.02"},{"asset_id":"8761897749749422724209054078244794145777693856614463256546737399611489089783","best_ask":"0.38","best_bid":"0.37","hash":"a2ed045e4741f7d9dbea9c5fa040b3cb9df5344c","price":"0.99","side":"SELL","size":"7883.02"}],"timestamp":"1785207826941"},"payload_hash":"031a21e4c20bc48efe3268acf569503a0a8f1f5d540d94956d5325d3674bc621","raw_frame":"{\"market\":\"0x779291bef19b6709f61e9764a954aafe9ffae488d50ae674aabdcb4f248006d5\", \"price_changes\":[{\"asset_id\":\"14965588658799411272385430903075831224615961675357217884735713260981483529984\", \"price\":\"0.01\", \"size\":\"7883.02\", \"side\":\"BUY\", \"hash\":\"ff75eb558ed38ce0dc1a6dead419d91109d65d08\", \"best_bid\":\"0.62\", \"best_ask\":\"0.63\"}, {\"asset_id\":\"8761897749749422724209054078244794145777693856614463256546737399611489089783\", \"price\":\"0.99\", \"size\":\"7883.02\", \"side\":\"SELL\", \"hash\":\"a2ed045e4741f7d9dbea9c5fa040b3cb9df5344c\", \"best_bid\":\"0.37\", \"best_ask\":\"0.38\"}], \"timestamp\":\"1785207826941\", \"event_type\":\"price_change\"}","received_at":"2026-07-28T03:03:46.796423Z","schema_version":"clob-market-ws.price_change.v1","sequence":null,"server_hash":null,"server_timestamp":"1785207826941","session_id":"3e519d9098404c15b234d96025eb1a2b","source":"clob_market_ws"},"received_at":"2026-07-28T03:03:46.796423Z","record_id":"d3850aa042944a6612c77b67e6ba75036052fb9722c6499f78bfe19848b4eaee","schema_fingerprint":"4aa3821a28b0b7c2400bc59aba4bcc0a76e971dadd19610d3ad38c768e124dc7","schema_version":"edge-lab-recorder.raw.v1","sequence":null,"source":"clob_market_ws"}
{"event_at":"2026-07-28T03:03:47.010000Z","event_fingerprint":"9454ce62b59fdb1466d09cdac9de663242e1d52c109163ee81c0340698b9e4b4","payload":{"connection_id":"a6b55582af5f430fb37ad02bf0922475","event_at":"2026-07-28T03:03:47.010000Z","event_type":"price_change","frame_hash":"80e74188a7664dd47a91e89ed6bd7242084900effd499302bdfe417a47241ced","frame_index":0,"kind":"data","monotonic_ns":309809881947000,"payload":{"event_type":"price_change","market":"0x779291bef19b6709f61e9764a954aafe9ffae488d50ae674aabdcb4f248006d5","price_changes":[{"asset_id":"14965588658799411272385430903075831224615961675357217884735713260981483529984","best_ask":"0.63","best_bid":"0.62","hash":"3f09bfa4e12ac0945b04a01aec6ca4e08cf684e7","price":"0.04","side":"BUY","size":"673.09"},{"asset_id":"8761897749749422724209054078244794145777693856614463256546737399611489089783","best_ask":"0.38","best_bid":"0.37","hash":"0513535a94d24ef19b6deb19e5cf50815975c489","price":"0.96","side":"SELL","size":"673.09"}],"timestamp":"1785207827010"},"payload_hash":"f29e00ee80d5c311ef2ca5e24b2fe87e92f90feb15c66ce425ce470507f6b5df","raw_frame":"{\"market\":\"0x779291bef19b6709f61e9764a954aafe9ffae488d50ae674aabdcb4f248006d5\", \"price_changes\":[{\"asset_id\":\"14965588658799411272385430903075831224615961675357217884735713260981483529984\", \"price\":\"0.04\", \"size\":\"673.09\", \"side\":\"BUY\", \"hash\":\"3f09bfa4e12ac0945b04a01aec6ca4e08cf684e7\", \"best_bid\":\"0.62\", \"best_ask\":\"0.63\"}, {\"asset_id\":\"8761897749749422724209054078244794145777693856614463256546737399611489089783\", \"price\":\"0.96\", \"size\":\"673.09\", \"side\":\"SELL\", \"hash\":\"0513535a94d24ef19b6deb19e5cf50815975c489\", \"best_bid\":\"0.37\", \"best_ask\":\"0.38\"}], \"timestamp\":\"1785207827010\", \"event_type\":\"price_change\"}","received_at":"2026-07-28T03:03:46.861945Z","schema_version":"clob-market-ws.price_change.v1","sequence":null,"server_hash":null,"server_timestamp":"1785207827010","session_id":"3e519d9098404c15b234d96025eb1a2b","source":"clob_market_ws"},"received_at":"2026-07-28T03:03:46.861945Z","record_id":"0163d1d12209bdff2b5c9d2fc6a788fe38f397872161675ff925a7b1b7264e0c","schema_fingerprint":"4aa3821a28b0b7c2400bc59aba4bcc0a76e971dadd19610d3ad38c768e124dc7","schema_version":"edge-lab-recorder.raw.v1","sequence":null,"source":"clob_market_ws"}
{"event_at":"2026-07-28T03:03:47.021000Z","event_fingerprint":"8f7620bc09958ff2ddb244cff62a05d971a358ce940d75f5c4b10a865ca43a2f","payload":{"connection_id":"a6b55582af5f430fb37ad02bf0922475","event_at":"2026-07-28T03:03:47.021000Z","event_type":"price_change","frame_hash":"dc369cccd31bcf1e357b3a1f00935f62ae939e1cd262890b0703912e1d39181b","frame_index":0,"kind":"data","monotonic_ns":309809892438541,"payload":{"event_type":"price_change","market":"0x779291bef19b6709f61e9764a954aafe9ffae488d50ae674aabdcb4f248006d5","price_changes":[{"asset_id":"8761897749749422724209054078244794145777693856614463256546737399611489089783","best_ask":"0.38","best_bid":"0.37","hash":"a673803938aa0ae16e6d56b3995a122c4502ed7a","price":"0.01","side":"BUY","size":"7858.02"},{"asset_id":"14965588658799411272385430903075831224615961675357217884735713260981483529984","best_ask":"0.63","best_bid":"0.62","hash":"4bbda49fbb97a39f1a55226789b536a91aad52bf","price":"0.99","side":"SELL","size":"7858.02"}],"timestamp":"1785207827021"},"payload_hash":"3f000fd65c041a23458d0f02b3d6f399fede0fecbfc079131590e998d5565e3a","raw_frame":"{\"market\":\"0x779291bef19b6709f61e9764a954aafe9ffae488d50ae674aabdcb4f248006d5\", \"price_changes\":[{\"asset_id\":\"8761897749749422724209054078244794145777693856614463256546737399611489089783\", \"price\":\"0.01\", \"size\":\"7858.02\", \"side\":\"BUY\", \"hash\":\"a673803938aa0ae16e6d56b3995a122c4502ed7a\", \"best_bid\":\"0.37\", \"best_ask\":\"0.38\"}, {\"asset_id\":\"14965588658799411272385430903075831224615961675357217884735713260981483529984\", \"price\":\"0.99\", \"size\":\"7858.02\", \"side\":\"SELL\", \"hash\":\"4bbda49fbb97a39f1a55226789b536a91aad52bf\", \"best_bid\":\"0.62\", \"best_ask\":\"0.63\"}], \"timestamp\":\"1785207827021\", \"event_type\":\"price_change\"}","received_at":"2026-07-28T03:03:46.872435Z","schema_version":"clob-market-ws.price_change.v1","sequence":null,"server_hash":null,"server_timestamp":"1785207827021","session_id":"3e519d9098404c15b234d96025eb1a2b","source":"clob_market_ws"},"received_at":"2026-07-28T03:03:46.872435Z","record_id":"3e02411914a787f13a1b33be38f2fa1509e75fb34fcef542503aa04099c17f07","schema_fingerprint":"4aa3821a28b0b7c2400bc59aba4bcc0a76e971dadd19610d3ad38c768e124dc7","schema_version":"edge-lab-recorder.raw.v1","sequence":null,"source":"clob_market_ws"}
{"event_at":"2026-07-28T03:03:47.022000Z","event_fingerprint":"f4e3bb9df1b8c750aafbc86d3733324fb9590b320af9c35199d12bd9dad9c90e","payload":{"connection_id":"a6b55582af5f430fb37ad02bf0922475","event_at":"2026-07-28T03:03:47.022000Z","event_type":"price_change","frame_hash":"5ef6fbf2ced567f3598791f1030701f31c85b6152e039975a5a0cce3b345312b","frame_index":0,"kind":"data","monotonic_ns":309809893983750,"payload":{"event_type":"price_change","market":"0x779291bef19b6709f61e9764a954aafe9ffae488d50ae674aabdcb4f248006d5","price_changes":[{"asset_id":"8761897749749422724209054078244794145777693856614463256546737399611489089783","best_ask":"0.38","best_bid":"0.37","hash":"e91127954c12f2542e6f0445de71c0ba2d836aca","price":"0.01","side":"BUY","size":"7863.02"},{"asset_id":"14965588658799411272385430903075831224615961675357217884735713260981483529984","best_ask":"0.63","best_bid":"0.62","hash":"f386d28425cac2708e55824c731a1f628d6d79dc","price":"0.99","side":"SELL","size":"7863.02"}],"timestamp":"1785207827022"},"payload_hash":"a5d7201bd759ecd9c521879d264508adbe36e47fde10290a195be8791b0d082d","raw_frame":"{\"market\":\"0x779291bef19b6709f61e9764a954aafe9ffae488d50ae674aabdcb4f248006d5\", \"price_changes\":[{\"asset_id\":\"8761897749749422724209054078244794145777693856614463256546737399611489089783\", \"price\":\"0.01\", \"size\":\"7863.02\", \"side\":\"BUY\", \"hash\":\"e91127954c12f2542e6f0445de71c0ba2d836aca\", \"best_bid\":\"0.37\", \"best_ask\":\"0.38\"}, {\"asset_id\":\"14965588658799411272385430903075831224615961675357217884735713260981483529984\", \"price\":\"0.99\", \"size\":\"7863.02\", \"side\":\"SELL\", \"hash\":\"f386d28425cac2708e55824c731a1f628d6d79dc\", \"best_bid\":\"0.62\", \"best_ask\":\"0.63\"}], \"timestamp\":\"1785207827022\", \"event_type\":\"price_change\"}","received_at":"2026-07-28T03:03:46.873982Z","schema_version":"clob-market-ws.price_change.v1","sequence":null,"server_hash":null,"server_timestamp":"1785207827022","session_id":"3e519d9098404c15b234d96025eb1a2b","source":"clob_market_ws"},"received_at":"2026-07-28T03:03:46.873982Z","record_id":"79f8a6fccdcdff59e876d29164b60534394b7b9628cb446e2db2170a7dca52fd","schema_fingerprint":"4aa3821a28b0b7c2400bc59aba4bcc0a76e971dadd19610d3ad38c768e124dc7","schema_version":"edge-lab-recorder.raw.v1","sequence":null,"source":"clob_market_ws"}
{"event_at":"2026-07-28T03:03:47.025000Z","event_fingerprint":"5141df1a13cfd4eccfcf23993b2c4aabdabc8299bc1701b40b3f84463bde28ef","payload":{"connection_id":"a6b55582af5f430fb37ad02bf0922475","event_at":"2026-07-28T03:03:47.025000Z","event_type":"price_change","frame_hash":"95845d257a9b12ac936fcbe5bbf5c9788c1d4b61315510415b49b16b388e71b1","frame_index":0,"kind":"data","monotonic_ns":309809896553375,"payload":{"event_type":"price_change","market":"0x779291bef19b6709f61e9764a954aafe9ffae488d50ae674aabdcb4f248006d5","price_changes":[{"asset_id":"14965588658799411272385430903075831224615961675357217884735713260981483529984","best_ask":"0.63","best_bid":"0.62","hash":"6a7187eba5904cdea9bbc0a0489579bcbceef868","price":"0.01","side":"BUY","size":"7888.02"},{"asset_id":"8761897749749422724209054078244794145777693856614463256546737399611489089783","best_ask":"0.38","best_bid":"0.37","hash":"7ec21c937c5bb4d02df29f47f4386bc1073bd5c9","price":"0.99","side":"SELL","size":"7888.02"}],"timestamp":"1785207827025"},"payload_hash":"deaefb7f052c61e2cd67213d5efe52a36687291fffd0247fe567990e19559e8a","raw_frame":"{\"market\":\"0x779291bef19b6709f61e9764a954aafe9ffae488d50ae674aabdcb4f248006d5\", \"price_changes\":[{\"asset_id\":\"14965588658799411272385430903075831224615961675357217884735713260981483529984\", \"price\":\"0.01\", \"size\":\"7888.02\", \"side\":\"BUY\", \"hash\":\"6a7187eba5904cdea9bbc0a0489579bcbceef868\", \"best_bid\":\"0.62\", \"best_ask\":\"0.63\"}, {\"asset_id\":\"8761897749749422724209054078244794145777693856614463256546737399611489089783\", \"price\":\"0.99\", \"size\":\"7888.02\", \"side\":\"SELL\", \"hash\":\"7ec21c937c5bb4d02df29f47f4386bc1073bd5c9\", \"best_bid\":\"0.37\", \"best_ask\":\"0.38\"}], \"timestamp\":\"1785207827025\", \"event_type\":\"price_change\"}","received_at":"2026-07-28T03:03:46.876551Z","schema_version":"clob-market-ws.price_change.v1","sequence":null,"server_hash":null,"server_timestamp":"1785207827025","session_id":"3e519d9098404c15b234d96025eb1a2b","source":"clob_market_ws"},"received_at":"2026-07-28T03:03:46.876551Z","record_id":"73493862f545e47eb22bae297e95403ed282264213bb46a0f36a0d6523980b37","schema_fingerprint":"4aa3821a28b0b7c2400bc59aba4bcc0a76e971dadd19610d3ad38c768e124dc7","schema_version":"edge-lab-recorder.raw.v1","sequence":null,"source":"clob_market_ws"}
{"event_at":"2026-07-28T03:03:47.027000Z","event_fingerprint":"ac0da845791335de5ea70ef7e64598b6e908b73da7a93b8dfbf2aeb318c72b69","payload":{"connection_id":"a6b55582af5f430fb37ad02bf0922475","event_at":"2026-07-28T03:03:47.027000Z","event_type":"price_change","frame_hash":"47d872ead9eca49001e4756e8ded27c47814febbe9be80441b3484ef5cddaf9c","frame_index":0,"kind":"data","monotonic_ns":309809898765375,"payload":{"event_type":"price_change","market":"0x779291bef19b6709f61e9764a954aafe9ffae488d50ae674aabdcb4f248006d5","price_changes":[{"asset_id":"14965588658799411272385430903075831224615961675357217884735713260981483529984","best_ask":"0.63","best_bid":"0.62","hash":"8b029a2f2445ba64e93c9fb32ea91f9392e0d856","price":"0.53","side":"BUY","size":"171"},{"asset_id":"8761897749749422724209054078244794145777693856614463256546737399611489089783","best_ask":"0.38","best_bid":"0.37","hash":"27948f421c178b11594d12dd40c26093a50024e5","price":"0.47","side":"SELL","size":"171"}],"timestamp":"1785207827027"},"payload_hash":"5db879b768ae25445ba4d4c502155df5d57e5c6672b68ea248600de14c94fbc9","raw_frame":"{\"market\":\"0x779291bef19b6709f61e9764a954aafe9ffae488d50ae674aabdcb4f248006d5\", \"price_changes\":[{\"asset_id\":\"14965588658799411272385430903075831224615961675357217884735713260981483529984\", \"price\":\"0.53\", \"size\":\"171\", \"side\":\"BUY\", \"hash\":\"8b029a2f2445ba64e93c9fb32ea91f9392e0d856\", \"best_bid\":\"0.62\", \"best_ask\":\"0.63\"}, {\"asset_id\":\"8761897749749422724209054078244794145777693856614463256546737399611489089783\", \"price\":\"0.47\", \"size\":\"171\", \"side\":\"SELL\", \"hash\":\"27948f421c178b11594d12dd40c26093a50024e5\", \"best_bid\":\"0.37\", \"best_ask\":\"0.38\"}], \"timestamp\":\"1785207827027\", \"event_type\":\"price_change\"}","received_at":"2026-07-28T03:03:46.878763Z","schema_version":"clob-market-ws.price_change.v1","sequence":null,"server_hash":null,"server_timestamp":"1785207827027","session_id":"3e519d9098404c15b234d96025eb1a2b","source":"clob_market_ws"},"received_at":"2026-07-28T03:03:46.878763Z","record_id":"3a02818f2f75a45f5591a2b4845cd7eeec2f640ff88eccb350a7a3fd8df37380","schema_fingerprint":"4aa3821a28b0b7c2400bc59aba4bcc0a76e971dadd19610d3ad38c768e124dc7","schema_version":"edge-lab-recorder.raw.v1","sequence":null,"source":"clob_market_ws"}
{"event_at":"2026-07-28T03:03:47.041000Z","event_fingerprint":"672ecb03193421e8d0454dfdd5cd0d14f2860885dca2263645ec35157e8d667c","payload":{"connection_id":"a6b55582af5f430fb37ad02bf0922475","event_at":"2026-07-28T03:03:47.041000Z","event_type":"price_change","frame_hash":"10d4018caf67ca601a0a927e3ce980d020dd86c122895347d8969383bad308ef","frame_index":0,"kind":"data","monotonic_ns":309809912432708,"payload":{"event_type":"price_change","market":"0x779291bef19b6709f61e9764a954aafe9ffae488d50ae674aabdcb4f248006d5","price_changes":[{"asset_id":"8761897749749422724209054078244794145777693856614463256546737399611489089783","best_ask":"0.38","best_bid":"0.37","hash":"82a785b56655f78aba599ae38e17317b302db973","price":"0.01","side":"BUY","size":"7858.02"},{"asset_id":"14965588658799411272385430903075831224615961675357217884735713260981483529984","best_ask":"0.63","best_bid":"0.62","hash":"f24eb7d6e311f9292edb91175b0ca3d077c72abd","price":"0.99","side":"SELL","size":"7858.02"}],"timestamp":"1785207827041"},"payload_hash":"086c356c1d60a6d7c125dff576a498318b19ff2f5dc69a802d9869d44c0eff7e","raw_frame":"{\"market\":\"0x779291bef19b6709f61e9764a954aafe9ffae488d50ae674aabdcb4f248006d5\", \"price_changes\":[{\"asset_id\":\"8761897749749422724209054078244794145777693856614463256546737399611489089783\", \"price\":\"0.01\", \"size\":\"7858.02\", \"side\":\"BUY\", \"hash\":\"82a785b56655f78aba599ae38e17317b302db973\", \"best_bid\":\"0.37\", \"best_ask\":\"0.38\"}, {\"asset_id\":\"14965588658799411272385430903075831224615961675357217884735713260981483529984\", \"price\":\"0.99\", \"size\":\"7858.02\", \"side\":\"SELL\", \"hash\":\"f24eb7d6e311f9292edb91175b0ca3d077c72abd\", \"best_bid\":\"0.62\", \"best_ask\":\"0.63\"}], \"timestamp\":\"1785207827041\", \"event_type\":\"price_change\"}","received_at":"2026-07-28T03:03:46.892430Z","schema_version":"clob-market-ws.price_change.v1","sequence":null,"server_hash":null,"server_timestamp":"1785207827041","session_id":"3e519d9098404c15b234d96025eb1a2b","source":"clob_market_ws"},"received_at":"2026-07-28T03:03:46.892430Z","record_id":"3ad4260ce56b2f595cbe0a0f5b5110e0370feb354524fa4684731118e4671e22","schema_fingerprint":"4aa3821a28b0b7c2400bc59aba4bcc0a76e971dadd19610d3ad38c768e124dc7","schema_version":"edge-lab-recorder.raw.v1","sequence":null,"source":"clob_market_ws"}
