{"event_at":"2026-07-28T03:14:42.117000Z","event_fingerprint":"ac7695999d39a8f6901b9910d619da4be4c0bbcdac061239ab34823fe826a304","payload":{"connection_id":"a6b55582af5f430fb37ad02bf0922475","event_at":"2026-07-28T03:14:42.117000Z","event_type":"price_change","frame_hash":"2cc267c9719f53e0b8ea8974812ea61e46784618629da04bb9c6202cf92a44c5","frame_index":0,"kind":"data","monotonic_ns":310464984537625,"payload":{"event_type":"price_change","market":"0x779291bef19b6709f61e9764a954aafe9ffae488d50ae674aabdcb4f248006d5","price_changes":[{"asset_id":"14965588658799411272385430903075831224615961675357217884735713260981483529984","best_ask":"1","best_bid":"0.99","hash":"b9e069f589191d705b5c9cd867958a8c800457f8","price":"0.77","side":"BUY","size":"43.29"},{"asset_id":"8761897749749422724209054078244794145777693856614463256546737399611489089783","best_ask":"0.01","best_bid":"0","hash":"20e11286e48af4a8feaedf49fdd3b191b2e1f4e1","price":"0.23","side":"SELL","size":"43.29"}],"timestamp":"1785208482117"},"payload_hash":"f2f529a4fb75b6f53d07c3d7c58e36004a52440a2e857003a977e92015a3c875","raw_frame":"{\"market\":\"0x779291bef19b6709f61e9764a954aafe9ffae488d50ae674aabdcb4f248006d5\", \"price_changes\":[{\"asset_id\":\"14965588658799411272385430903075831224615961675357217884735713260981483529984\", \"price\":\"0.77\", \"size\":\"43.29\", \"side\":\"BUY\", \"hash\":\"b9e069f589191d705b5c9cd867958a8c800457f8\", \"best_bid\":\"0.99\", \"best_ask\":\"1\"}, {\"asset_id\":\"8761897749749422724209054078244794145777693856614463256546737399611489089783\", \"price\":\"0.23\", \"size\":\"43.29\", \"side\":\"SELL\", \"hash\":\"20e11286e48af4a8feaedf49fdd3b191b2e1f4e1\", \"best_bid\":\"0\", \"best_ask\":\"0.01\"}], \"timestamp\":\"1785208482117\", \"event_type\":\"price_change\"}","received_at":"2026-07-28T03:14:41.948772Z","schema_version":"clob-market-ws.price_change.v1","sequence":null,"server_hash":null,"server_timestamp":"1785208482117","session_id":"3e519d9098404c15b234d96025eb1a2b","source":"clob_market_ws"},"received_at":"2026-07-28T03:14:41.948772Z","record_id":"f2581a56bad69f6fb08174943e88519c35420a85c075c1a5761ddd25fe8e1297","schema_fingerprint":"4aa3821a28b0b7c2400bc59aba4bcc0a76e971dadd19610d3ad38c768e124dc7","schema_version":"edge-lab-recorder.raw.v1","sequence":null,"source":"clob_market_ws"}
{"event_at":"2026-07-28T03:14:42.123000Z","event_fingerprint":"e4dc8649a3732b8107739be2726638af9b95e5ffd78ce38e91afdf5b26c8a3e2","payload":{"connection_id":"a6b55582af5f430fb37ad02bf0922475","event_at":"2026-07-28T03:14:42.123000Z","event_type":"price_change","frame_hash":"6ac0c6d8211495723cbc03db6cfa872674d0d6dcf437b45f8f799c7ac093fe08","frame_index":0,"kind":"data","monotonic_ns":310464990460125,"payload":{"event_type":"price_change","market":"0x779291bef19b6709f61e9764a954aafe9ffae488d50ae674aabdcb4f248006d5","price_changes":[{"asset_id":"14965588658799411272385430903075831224615961675357217884735713260981483529984","best_ask":"1","best_bid":"0.99","hash":"02001b178656e347d2c204ef7c409935a8db3822","price":"0.01","side":"BUY","size":"5520"},{"asset_id":"8761897749749422724209054078244794145777693856614463256546737399611489089783","best_ask":"0.01","best_bid":"0","hash":"e7de900dba3ee631bbf75755b64a013399784585","price":"0.99","side":"SELL","size":"5520"}],"timestamp":"1785208482123"},"payload_hash":"7815ad7572c054786751ae8137e8d5c7b95335bbee15587142a05e6ba01672be","raw_frame":"{\"market\":\"0x779291bef19b6709f61e9764a954aafe9ffae488d50ae674aabdcb4f248006d5\", \"price_changes\":[{\"asset_id\":\"14965588658799411272385430903075831224615961675357217884735713260981483529984\", \"price\":\"0.01\", \"size\":\"5520\", \"side\":\"BUY\", \"hash\":\"02001b178656e347d2c204ef7c409935a8db3822\", \"best_bid\":\"0.99\", \"best_ask\":\"1\"}, {\"asset_id\":\"8761897749749422724209054078244794145777693856614463256546737399611489089783\", \"price\":\"0.99\", \"size\":\"5520\", \"side\":\"SELL\", \"hash\":\"e7de900dba3ee631bbf75755b64a013399784585\", \"best_bid\":\"0\", \"best_ask\":\"0.01\"}], \"timestamp\":\"1785208482123\", \"event_type\":\"price_change\"}","received_at":"2026-07-28T03:14:41.954694Z","schema_version":"clob-market-ws.price_change.v1","sequence":null,"server_hash":null,"server_timestamp":"1785208482123","session_id":"3e519d9098404c15b234d96025eb1a2b","source":"clob_market_ws"},"received_at":"2026-07-28T03:14:41.954694Z","record_id":"341128a0e0f587676306348a604864538f720fb831c2a9912e7a9cc0f0d54e7c","schema_fingerprint":"4aa3821a28b0b7c2400bc59aba4bcc0a76e971dadd19610d3ad38c768e124dc7","schema_version":"edge-lab-recorder.raw.v1","sequence":null,"source":"clob_market_ws"}
{"event_at":"2026-07-28T03:14:42.145000Z","event_fingerprint":"019c8d31a6e8c7c3d4c043648597a7944880b063e1b0e60f374b446923f772f8","payload":{"connection_id":"a6b55582af5f430fb37ad02bf0922475","event_at":"2026-07-28T03:14:42.145000Z","event_type":"price_change","frame_hash":"b8df573e7ffc2f2e8dfb76e4608a33c8afd73351224287af86f64b5651438fe8","frame_index":0,"kind":"data","monotonic_ns":310465011728083,"payload":{"event_type":"price_change","market":"0x779291bef19b6709f61e9764a954aafe9ffae488d50ae674aabdcb4f248006d5","price_changes":[{"asset_id":"14965588658799411272385430903075831224615961675357217884735713260981483529984","best_ask":"1","best_bid":"0.99","hash":"2e7cf872a88f29523a0accae40e21333cd5b3179","price":"0.01","side":"BUY","size":"5515"},{"asset_id":"8761897749749422724209054078244794145777693856614463256546737399611489089783","best_ask":"0.01","best_bid":"0","hash":"3ff1420aff101f8a891dabf66217c84d6c16c9d1","price":"0.99","side":"SELL","size":"5515"}],"timestamp":"1785208482145"},"payload_hash":"53f39cbbdff4feeef06094fbdeadeae3216439a3ea06a9c5f0aaf4f6bee3d367","raw_frame":"{\"market\":\"0x779291bef19b6709f61e9764a954aafe9ffae488d50ae674aabdcb4f248006d5\", \"price_changes\":[{\"asset_id\":\"14965588658799411272385430903075831224615961675357217884735713260981483529984\", \"price\":\"0.01\", \"size\":\"5515\", \"side\":\"BUY\", \"hash\":\"2e7cf872a88f29523a0accae40e21333cd5b3179\", \"best_bid\":\"0.99\", \"best_ask\":\"1\"}, {\"asset_id\":\"8761897749749422724209054078244794145777693856614463256546737399611489089783\", \"price\":\"0.99\", \"size\":\"5515\", \"side\":\"SELL\", \"hash\":\"3ff1420aff101f8a891dabf66217c84d6c16c9d1\", \"best_bid\":\"0\", \"best_ask\":\"0.01\"}], \"timestamp\":\"1785208482145\", \"event_type\":\"price_change\"}","received_at":"2026-07-28T03:14:41.975958Z","schema_version":"clob-market-ws.price_change.v1","sequence":null,"server_hash":null,"server_timestamp":"1785208482145","session_id":"3e519d9098404c15b234d96025eb1a2b","source":"clob_market_ws"},"received_at":"2026-07-28T03:14:41.975958Z","record_id":"ff6dd5e445383e8a4a7ed98cf627435e8229f9f4ee67e4685540f6fbb802ce2d","schema_fingerprint":"4aa3821a28b0b7c2400bc59aba4bcc0a76e971dadd19610d3ad38c768e124dc7","schema_version":"edge-lab-recorder.raw.v1","sequence":null,"source":"clob_market_ws"}
{"event_at":"2026-07-28T03:14:42.183000Z","event_fingerprint":"fa2ddee7abd4fe9f452d559dfa02340ed8eb2c4edd2504d619f14d269e5cf214","payload":{"connection_id":"a6b55582af5f430fb37ad02bf0922475","event_at":"2026-07-28T03:14:42.183000Z","event_type":"price_change","frame_hash":"7fd21d23fceeb1c3c6ca662d0f9fbac716d5625c261687b7f7ed040f70bf9d93","frame_index":0,"kind":"data","monotonic_ns":310465049256041,"payload":{"event_type":"price_change","market":"0x779291bef19b6709f61e9764a954aafe9ffae488d50ae674aabdcb4f248006d5","price_changes":[{"asset_id":"14965588658799411272385430903075831224615961675357217884735713260981483529984","best_ask":"1","best_bid":"0.99","hash":"ffa32f7365913bba034138078f673693e3b7ecfa","price":"0.99","side":"BUY","size":"106"},{"asset_id":"8761897749749422724209054078244794145777693856614463256546737399611489089783","best_ask":"0.01","best_bid":"0","hash":"bf2fd03bc2dd6093cce8d1fda2f4485391140410","price":"0.01","side":"SELL","size":"106"}],"timestamp":"1785208482183"},"payload_hash":"5906917f197cfefe5decaf7c84de9cad3da4873c993a630d1d76462cef558ee2","raw_frame":"{\"market\":\"0x779291bef19b6709f61e9764a954aafe9ffae488d50ae674aabdcb4f248006d5\", \"price_changes\":[{\"asset_id\":\"14965588658799411272385430903075831224615961675357217884735713260981483529984\", \"price\":\"0.99\", \"size\":\"106\", \"side\":\"BUY\", \"hash\":\"ffa32f7365913bba034138078f673693e3b7ecfa\", \"best_bid\":\"0.99\", \"best_ask\":\"1\"}, {\"asset_id\":\"8761897749749422724209054078244794145777693856614463256546737399611489089783\", \"price\":\"0.01\", \"size\":\"106\", \"side\":\"SELL\", \"hash\":\"bf2fd03bc2dd6093cce8d1fda2f4485391140410\", \"best_bid\":\"0\", \"best_ask\":\"0.01\"}], \"timestamp\":\"1785208482183\", \"event_type\":\"price_change\"}","received_at":"2026-07-28T03:14:42.013486Z","schema_version":"clob-market-ws.price_change.v1","sequence":null,"server_hash":null,"server_timestamp":"1785208482183","session_id":"3e519d9098404c15b234d96025eb1a2b","source":"clob_market_ws"},"received_at":"2026-07-28T03:14:42.013486Z","record_id":"76ad5f5e47933351f49d6402c9559a4ba76117d48e4823577e152f62e175dc66","schema_fingerprint":"4aa3821a28b0b7c2400bc59aba4bcc0a76e971dadd19610d3ad38c768e124dc7","schema_version":"edge-lab-recorder.raw.v1","sequence":null,"source":"clob_market_ws"}
{"event_at":"2026-07-28T03:14:42.189000Z","event_fingerprint":"e751ae742380982ded15f83a2bda9ea879b1e0f6cca3c2fd2ea994b5a8c14c02","payload":{"connection_id":"a6b55582af5f430fb37ad02bf0922475","event_at":"2026-07-28T03:14:42.189000Z","event_type":"price_change","frame_hash":"4fd49cc8949dd862f184871133692e1291eb0d43c3fe10a518fe5c2c41b19c37","frame_index":0,"kind":"data","monotonic_ns":310465054870291,"payload":{"event_type":"price_change","market":"0x779291bef19b6709f61e9764a954aafe9ffae488d50ae674aabdcb4f248006d5","price_changes":[{"asset_id":"8761897749749422724209054078244794145777693856614463256546737399611489089783","best_ask":"0.01","best_bid":"0","hash":"1549cdcdeefd77bd3a0fa8fedca14268d91a1eae","price":"0.01","side":"SELL","size":"137"},{"asset_id":"14965588658799411272385430903075831224615961675357217884735713260981483529984","best_ask":"1","best_bid":"0.99","hash":"16ee8de3cc5c7d14b1c60aad75a3ba952cbbdeec","price":"0.99","side":"BUY","size":"137"}],"timestamp":"1785208482189"},"payload_hash":"6979a862e5f54cf57f2353f31afa05771b1b410922aa20392d15ab45f8d39aa5","raw_frame":"{\"market\":\"0x779291bef19b6709f61e9764a954aafe9ffae488d50ae674aabdcb4f248006d5\", \"price_changes\":[{\"asset_id\":\"8761897749749422724209054078244794145777693856614463256546737399611489089783\", \"price\":\"0.01\", \"size\":\"137\", \"side\":\"SELL\", \"hash\":\"1549cdcdeefd77bd3a0fa8fedca14268d91a1eae\", \"best_bid\":\"0\", \"best_ask\":\"0.01\"}, {\"asset_id\":\"14965588658799411272385430903075831224615961675357217884735713260981483529984\", \"price\":\"0.99\", \"size\":\"137\", \"side\":\"BUY\", \"hash\":\"16ee8de3cc5c7d14b1c60aad75a3ba952cbbdeec\", \"best_bid\":\"0.99\", \"best_ask\":\"1\"}], \"timestamp\":\"1785208482189\", \"event_type\":\"price_change\"}","received_at":"2026-07-28T03:14:42.019102Z","schema_version":"clob-market-ws.price_change.v1","sequence":null,"server_hash":null,"server_timestamp":"1785208482189","session_id":"3e519d9098404c15b234d96025eb1a2b","source":"clob_market_ws"},"received_at":"2026-07-28T03:14:42.019102Z","record_id":"3ca3192fb53f2bd0ca525554952c1b76ce58a560fa9063c855e50235fb120501","schema_fingerprint":"4aa3821a28b0b7c2400bc59aba4bcc0a76e971dadd19610d3ad38c768e124dc7","schema_version":"edge-lab-recorder.raw.v1","sequence":null,"source":"clob_market_ws"}
{"event_at":"2026-07-28T03:14:42.190000Z","event_fingerprint":"5b2bdb49ec1dbb7f9a243b95ee73746d0b5383ae517a8dd5c6849bf4411cce52","payload":{"connection_id":"a6b55582af5f430fb37ad02bf0922475","event_at":"2026-07-28T03:14:42.190000Z","event_type":"price_change","frame_hash":"8eec0c43b7843b9408cb3adde6b7d367bd0ec523717a39d1d33fe469e44f35d5","frame_index":0,"kind":"data","monotonic_ns":310465057044750,"payload":{"event_type":"price_change","market":"0x779291bef19b6709f61e9764a954aafe9ffae488d50ae674aabdcb4f248006d5","price_changes":[{"asset_id":"14965588658799411272385430903075831224615961675357217884735713260981483529984","best_ask":"1","best_bid":"0.99","hash":"88b94631c95104c9d9013e099211db0d6fde5b3c","price":"0.01","side":"BUY","size":"5521.24"},{"asset_id":"8761897749749422724209054078244794145777693856614463256546737399611489089783","best_ask":"0.01","best_bid":"0","hash":"56e1ca2001ca642ef6f23e2b1b4805fee5479f2f","price":"0.99","side":"SELL","size":"5521.24"}],"timestamp":"1785208482190"},"payload_hash":"e96c900918663edcdb45ce2ffd9a2eee6ca33fff347ea967b301af6e98d83334","raw_frame":"{\"market\":\"0x779291bef19b6709f61e9764a954aafe9ffae488d50ae674aabdcb4f248006d5\", \"price_changes\":[{\"asset_id\":\"14965588658799411272385430903075831224615961675357217884735713260981483529984\", \"price\":\"0.01\", \"size\":\"5521.24\", \"side\":\"BUY\", \"hash\":\"88b94631c95104c9d9013e099211db0d6fde5b3c\", \"best_bid\":\"0.99\", \"best_ask\":\"1\"}, {\"asset_id\":\"8761897749749422724209054078244794145777693856614463256546737399611489089783\", \"price\":\"0.99\", \"size\":\"5521.24\", \"side\":\"SELL\", \"hash\":\"56e1ca2001ca642ef6f23e2b1b4805fee5479f2f\", \"best_bid\":\"0\", \"best_ask\":\"0.01\"}], \"timestamp\":\"1785208482190\", \"event_type\":\"price_change\"}","received_at":"2026-07-28T03:14:42.021278Z","schema_version":"clob-market-ws.price_change.v1","sequence":null,"server_hash":null,"server_timestamp":"1785208482190","session_id":"3e519d9098404c15b234d96025eb1a2b","source":"clob_market_ws"},"received_at":"2026-07-28T03:14:42.021278Z","record_id":"ddb8627e0a2bb7808309dbe4d9ab3aacf4c2e61d03a4da32c8e5f256b2658c5b","schema_fingerprint":"4aa3821a28b0b7c2400bc59aba4bcc0a76e971dadd19610d3ad38c768e124dc7","schema_version":"edge-lab-recorder.raw.v1","sequence":null,"source":"clob_market_ws"}
{"event_at":"2026-07-28T03:14:42.191000Z","event_fingerprint":"ffab426f888bf509ef8ab5366ba279b1e2b8dcc08ffa07cf17ce36c917cecade","payload":{"connection_id":"a6b55582af5f430fb37ad02bf0922475","event_at":"2026-07-28T03:14:42.191000Z","event_type":"price_change","frame_hash":"b8fb0539c56087f26e31611b750df5fbe0aba746bf4f873beed531bb289f8aae","frame_index":0,"kind":"data","monotonic_ns":310465058634791,"payload":{"event_type":"price_change","market":"0x779291bef19b6709f61e9764a954aafe9ffae488d50ae674aabdcb4f248006d5","price_changes":[{"asset_id":"8761897749749422724209054078244794145777693856614463256546737399611489089783","best_ask":"0.01","best_bid":"0","hash":"ec8757acfaa216c3e66feba24412a3125badd56c","price":"0.02","side":"SELL","size":"77.22"},{"asset_id":"14965588658799411272385430903075831224615961675357217884735713260981483529984","best_ask":"1","best_bid":"0.99","hash":"a2d1d10b1889f8798ed0aba1aa9c70e6490e54cd","price":"0.98","side":"BUY","size":"77.22"}],"timestamp":"1785208482191"},"payload_hash":"da47a8eda183a8164a6af53a9a2b274d23bcf555e90f0cb303db8ff8ad1dae7c","raw_frame":"{\"market\":\"0x779291bef19b6709f61e9764a954aafe9ffae488d50ae674aabdcb4f248006d5\", \"price_changes\":[{\"asset_id\":\"8761897749749422724209054078244794145777693856614463256546737399611489089783\", \"price\":\"0.02\", \"size\":\"77.22\", \"side\":\"SELL\", \"hash\":\"ec8757acfaa216c3e66feba24412a3125badd56c\", \"best_bid\":\"0\", \"best_ask\":\"0.01\"}, {\"asset_id\":\"14965588658799411272385430903075831224615961675357217884735713260981483529984\", \"price\":\"0.98\", \"size\":\"77.22\", \"side\":\"BUY\", \"hash\":\"a2d1d10b1889f8798ed0aba1aa9c70e6490e54cd\", \"best_bid\":\"0.99\", \"best_ask\":\"1\"}], \"timestamp\":\"1785208482191\", \"event_type\":\"price_change\"}","received_at":"2026-07-28T03:14:42.022867Z","schema_version":"clob-market-ws.price_change.v1","sequence":null,"server_hash":null,"server_timestamp":"1785208482191","session_id":"3e519d9098404c15b234d96025eb1a2b","source":"clob_market_ws"},"received_at":"2026-07-28T03:14:42.022867Z","record_id":"ce722863d01df076daf3b7277e09863a594e4a728a36afb2eaea9ce490b6018b","schema_fingerprint":"4aa3821a28b0b7c2400bc59aba4bcc0a76e971dadd19610d3ad38c768e124dc7","schema_version":"edge-lab-recorder.raw.v1","sequence":null,"source":"clob_market_ws"}
{"event_at":"2026-07-28T03:14:42.192000Z","event_fingerprint":"b1cd6cef4d7de0554e99804f4b449ac772394d3e33cd60c1d3d500645bfeaca0","payload":{"connection_id":"a6b55582af5f430fb37ad02bf0922475","event_at":"2026-07-28T03:14:42.192000Z","event_type":"price_change","frame_hash":"529506e5c7fe3c8594a166566e7135aad13030e1bcf5d30a8fd900fa989a4d58","frame_index":0,"kind":"data","monotonic_ns":310465060351333,"payload":{"event_type":"price_change","market":"0x779291bef19b6709f61e9764a954aafe9ffae488d50ae674aabdcb4f248006d5","price_changes":[{"asset_id":"14965588658799411272385430903075831224615961675357217884735713260981483529984","best_ask":"1","best_bid":"0.99","hash":"27e6cb50a287f483ef54bc91232cc01857abf7b3","price":"0.98","side":"BUY","size":"104.6"},{"asset_id":"8761897749749422724209054078244794145777693856614463256546737399611489089783","best_ask":"0.01","best_bid":"0","hash":"b799ecc67badbcc781f26166bcca6ec5de597de4","price":"0.02","side":"SELL","size":"104.6"}],"timestamp":"1785208482192"},"payload_hash":"71632ea0ae2edceae22a68e4a3409fdcad7f5e2a60926f63a20221eb7ed74384","raw_frame":"{\"market\":\"0x779291bef19b6709f61e9764a954aafe9ffae488d50ae674aabdcb4f248006d5\", \"price_changes\":[{\"asset_id\":\"14965588658799411272385430903075831224615961675357217884735713260981483529984\", \"price\":\"0.98\", \"size\":\"104.6\", \"side\":\"BUY\", \"hash\":\"27e6cb50a287f483ef54bc91232cc01857abf7b3\", \"best_bid\":\"0.99\", \"best_ask\":\"1\"}, {\"asset_id\":\"8761897749749422724209054078244794145777693856614463256546737399611489089783\", \"price\":\"0.02\", \"size\":\"104.6\", \"side\":\"SELL\", \"hash\":\"b799ecc67badbcc781f26166bcca6ec5de597de4\", \"best_bid\":\"0\", \"best_ask\":\"0.01\"}], \"timestamp\":\"1785208482192\", \"event_type\":\"price_change\"}","received_at":"2026-07-28T03:14:42.024586Z","schema_version":"clob-market-ws.price_change.v1","sequence":null,"server_hash":null,"server_timestamp":"1785208482192","session_id":"3e519d9098404c15b234d96025eb1a2b","source":"clob_market_ws"},"received_at":"2026-07-28T03:14:42.024586Z","record_id":"9381aaf0cab7bea72a267739a08965761e3ae05fca0c67aaceace8de8437995e","schema_fingerprint":"4aa3821a28b0b7c2400bc59aba4bcc0a76e971dadd19610d3ad38c768e124dc7","schema_version":"edge-lab-recorder.raw.v1","sequence":null,"source":"clob_market_ws"}
{"event_at":"2026-07-28T03:14:42.198000Z","event_fingerprint":"bf0781e241f9deac05da189e089bf8a74c87195ec11069326886f6a29169dad7","payload":{"connection_id":"a6b55582af5f430fb37ad02bf0922475","event_at":"2026-07-28T03:14:42.198000Z","event_type":"price_change","frame_hash":"e71745c53d577aefa3a134522a8c1ff32509172d387d3e63ffc03a8fbc353892","frame_index":0,"kind":"data","monotonic_ns":310465065715375,"payload":{"event_type":"price_change","market":"0x779291bef19b6709f61e9764a954aafe9ffae488d50ae674aabdcb4f248006d5","price_changes":[{"asset_id":"14965588658799411272385430903075831224615961675357217884735713260981483529984","best_ask":"1","best_bid":"0.99","hash":"f0985a6590e976cd42e35dbd9357727986ca8b0c","price":"0.01","side":"BUY","size":"5526.24"},{"asset_id":"8761897749749422724209054078244794145777693856614463256546737399611489089783","best_ask":"0.01","best_bid":"0","hash":"6bfe791106ed0a2cfc5308b853ce39ea4889a545","price":"0.99","side":"SELL","size":"5526.24"}],"timestamp":"1785208482198"},"payload_hash":"6a74233a3a4ea38aaea9cc83449d8f7d878f5b78171e03cb34cd4b95c58f218c","raw_frame":"{\"market\":\"0x779291bef19b6709f61e9764a954aafe9ffae488d50ae674aabdcb4f248006d5\", \"price_changes\":[{\"asset_id\":\"14965588658799411272385430903075831224615961675357217884735713260981483529984\", \"price\":\"0.01\", \"size\":\"5526.24\", \"side\":\"BUY\", \"hash\":\"f0985a6590e976cd42e35dbd9357727986ca8b0c\", \"best_bid\":\"0.99\", \"best_ask\":\"1\"}, {\"asset_id\":\"8761897749749422724209054078244794145777693856614463256546737399611489089783\", \"price\":\"0.99\", \"size\":\"5526.24\", \"side\":\"SELL\", \"hash\":\"6bfe791106ed0a2cfc5308b853ce39ea4889a545\", \"best_bid\":\"0\", \"best_ask\":\"0.01\"}], \"timestamp\":\"1785208482198\", \"event_type\":\"price_change\"}","received_at":"2026-07-28T03:14:42.029950Z","schema_version":"clob-market-ws.price_change.v1","sequence":null,"server_hash":null,"server_timestamp":"1785208482198","session_id":"3e519d9098404c15b234d96025eb1a2b","source":"clob_market_ws"},"received_at":"2026-07-28T03:14:42.029950Z","record_id":"c5a7ab4a1ebd4c80c4742a5d2278a6e4b359184eac86ad7745f5e84f8d7816da","schema_fingerprint":"4aa3821a28b0b7c2400bc59aba4bcc0a76e971dadd19610d3ad38c768e124dc7","schema_version":"edge-lab-recorder.raw.v1","sequence":null,"source":"clob_market_ws"}
{"event_at":"2026-07-28T03:14:42.247000Z","event_fingerprint":"7ebb351066063a2f66e3d103874f6fc8284157de2f1d20f0a97380df446e4349","payload":{"connection_id":"a6b55582af5f430fb37ad02bf0922475","event_at":"2026-07-28T03:14:42.247000Z","event_type":"price_change","frame_hash":"77dd4968a2b690934ea499b51234c5b239e7416d00fd42ca8062a61eaad91e71","frame_index":0,"kind":"data","monotonic_ns":310465113193750,"payload":{"event_type":"price_change","market":"0x779291bef19b6709f61e9764a954aafe9ffae488d50ae674aabdcb4f248006d5","price_changes":[{"asset_id":"14965588658799411272385430903075831224615961675357217884735713260981483529984","best_ask":"1","best_bid":"0.99","hash":"5a21744b93805d5f83f7d76467b34ff1e83163ac","price":"0.77","side":"BUY","size":"86.58"},{"asset_id":"8761897749749422724209054078244794145777693856614463256546737399611489089783","best_ask":"0.01","best_bid":"0","hash":"90a7a0be9e893bb0250307678ee4859a5d85b6d1","price":"0.23","side":"SELL","size":"86.58"}],"timestamp":"1785208482247"},"payload_hash":"b4993b73f086785d2fb42a82ccae855fe57078208876609abbcd8ba0a54d3e3f","raw_frame":"{\"market\":\"0x779291bef19b6709f61e9764a954aafe9ffae488d50ae674aabdcb4f248006d5\", \"price_changes\":[{\"asset_id\":\"14965588658799411272385430903075831224615961675357217884735713260981483529984\", \"price\":\"0.77\", \"size\":\"86.58\", \"side\":\"BUY\", \"hash\":\"5a21744b93805d5f83f7d76467b34ff1e83163ac\", \"best_bid\":\"0.99\", \"best_ask\":\"1\"}, {\"asset_id\":\"8761897749749422724209054078244794145777693856614463256546737399611489089783\", \"price\":\"0.23\", \"size\":\"86.58\", \"side\":\"SELL\", \"hash\":\"90a7a0be9e893bb0250307678ee4859a5d85b6d1\", \"best_bid\":\"0\", \"best_ask\":\"0.01\"}], \"timestamp\":\"1785208482247\", \"event_type\":\"price_change\"}","received_at":"2026-07-28T03:14:42.077424Z","schema_version":"clob-market-ws.price_change.v1","sequence":null,"server_hash":null,"server_timestamp":"1785208482247","session_id":"3e519d9098404c15b234d96025eb1a2b","source":"clob_market_ws"},"received_at":"2026-07-28T03:14:42.077424Z","record_id":"149b107448cf95c3281a0f002a79bbdaaed16d377d5f9da47c8222f8efca088e","schema_fingerprint":"4aa3821a28b0b7c2400bc59aba4bcc0a76e971dadd19610d3ad38c768e124dc7","schema_version":"edge-lab-recorder.raw.v1","sequence":null,"source":"clob_market_ws"}
{"event_at":"2026-07-28T03:14:42.271000Z","event_fingerprint":"24756d86a1e8fd92bcb249f02e7ea0dfb134798c431b4de50ccfdaa07578b187","payload":{"connection_id":"a6b55582af5f430fb37ad02bf0922475","event_at":"2026-07-28T03:14:42.271000Z","event_type":"price_change","frame_hash":"530511c2245ffd5a8af67276fc7ef61d83c01c9e620d839cb924d79b769e7a38","frame_index":0,"kind":"data","monotonic_ns":310465137053750,"payload":{"event_type":"price_change","market":"0x779291bef19b6709f61e9764a954aafe9ffae488d50ae674aabdcb4f248006d5","price_changes":[{"asset_id":"14965588658799411272385430903075831224615961675357217884735713260981483529984","best_ask":"1","best_bid":"0.99","hash":"64ee23107dd2c111367f90a840b48a36193d08d3","price":"0.01","side":"BUY","size":"5521.24"},{"asset_id":"8761897749749422724209054078244794145777693856614463256546737399611489089783","best_ask":"0.01","best_bid":"0","hash":"85ccc1243414f0c3abb1396e5b81682f7fc5f3ca","price":"0.99","side":"SELL","size":"5521.24"}],"timestamp":"1785208482271"},"payload_hash":"ba8bfec688a084b3389b8e289f03ff7766067835c6f19bdfc535ef714ad34ca5","raw_frame":"{\"market\":\"0x779291bef19b6709f61e9764a954aafe9ffae488d50ae674aabdcb4f248006d5\", \"price_changes\":[{\"asset_id\":\"14965588658799411272385430903075831224615961675357217884735713260981483529984\", \"price\":\"0.01\", \"size\":\"5521.24\", \"side\":\"BUY\", \"hash\":\"64ee23107dd2c111367f90a840b48a36193d08d3\", \"best_bid\":\"0.99\", \"best_ask\":\"1\"}, {\"asset_id\":\"8761897749749422724209054078244794145777693856614463256546737399611489089783\", \"price\":\"0.99\", \"size\":\"5521.24\", \"side\":\"SELL\", \"hash\":\"85ccc1243414f0c3abb1396e5b81682f7fc5f3ca\", \"best_bid\":\"0\", \"best_ask\":\"0.01\"}], \"timestamp\":\"1785208482271\", \"event_type\":\"price_change\"}","received_at":"2026-07-28T03:14:42.101286Z","schema_version":"clob-market-ws.price_change.v1","sequence":null,"server_hash":null,"server_timestamp":"1785208482271","session_id":"3e519d9098404c15b234d96025eb1a2b","source":"clob_market_ws"},"received_at":"2026-07-28T03:14:42.101286Z","record_id":"bb12646b71bea148162f6f9d7a0e4595ed6615293841539ef2a2e54252fdbff4","schema_fingerprint":"4aa3821a28b0b7c2400bc59aba4bcc0a76e971dadd19610d3ad38c768e124dc7","schema_version":"edge-lab-recorder.raw.v1","sequence":null,"source":"clob_market_ws"}
{"event_at":"2026-07-28T03:14:42.285000Z","event_fingerprint":"b73007e1803bd41e1452d72e23b954637887c3d354f26bd00b8a40870917f4e8","payload":{"connection_id":"a6b55582af5f430fb37ad02bf0922475","event_at":"2026-07-28T03:14:42.285000Z","event_type":"price_change","frame_hash":"a2b6b0265d0c63395ee04e54150e2af1ca50fae573050e3e377bc63259dce3bf","frame_index":0,"kind":"data","monotonic_ns":310465151482250,"payload":{"event_type":"price_change","market":"0x779291bef19b6709f61e9764a954aafe9ffae488d50ae674aabdcb4f248006d5","price_changes":[{"asset_id":"14965588658799411272385430903075831224615961675357217884735713260981483529984","best_ask":"1","best_bid":"0.99","hash":"486207b067706795d920af67e9131981283e116a","price":"0.01","side":"BUY","size":"5515"},{"asset_id":"8761897749749422724209054078244794145777693856614463256546737399611489089783","best_ask":"0.01","best_bid":"0","hash":"16acec785a51f8d7a8d4db4a260eadbcb0c79f28","price":"0.99","side":"SELL","size":"5515"}],"timestamp":"1785208482285"},"payload_hash":"5c5d8d9553eaa4083330d0073f98a6b48f0aede528980a309588c2f59f525302","raw_frame":"{\"market\":\"0x779291bef19b6709f61e9764a954aafe9ffae488d50ae674aabdcb4f248006d5\", \"price_changes\":[{\"asset_id\":\"14965588658799411272385430903075831224615961675357217884735713260981483529984\", \"price\":\"0.01\", \"size\":\"5515\", \"side\":\"BUY\", \"hash\":\"486207b067706795d920af67e9131981283e116a\", \"best_bid\":\"0.99\", \"best_ask\":\"1\"}, {\"asset_id\":\"8761897749749422724209054078244794145777693856614463256546737399611489089783\", \"price\":\"0.99\", \"size\":\"5515\", \"side\":\"SELL\", \"hash\":\"16acec785a51f8d7a8d4db4a260eadbcb0c79f28\", \"best_bid\":\"0\", \"best_ask\":\"0.01\"}], \"timestamp\":\"1785208482285\", \"event_type\":\"price_change\"}","received_at":"2026-07-28T03:14:42.115714Z","schema_version":"clob-market-ws.price_change.v1","sequence":null,"server_hash":null,"server_timestamp":"1785208482285","session_id":"3e519d9098404c15b234d96025eb1a2b","source":"clob_market_ws"},"received_at":"2026-07-28T03:14:42.115714Z","record_id":"7b1a7278fb4d4f132f9da5cceb7d49cc73e893a3aa3f3518275f7e51dee426d6","schema_fingerprint":"4aa3821a28b0b7c2400bc59aba4bcc0a76e971dadd19610d3ad38c768e124dc7","schema_version":"edge-lab-recorder.raw.v1","sequence":null,"source":"clob_market_ws"}
{"event_at":"2026-07-28T03:14:42.285000Z","event_fingerprint":"b3e888fb3467298846e69c1187a341a9afbcfecccd3f1b2812b22d2c25dd2bff","payload":{"connection_id":"a6b55582af5f430fb37ad02bf0922475","event_at":"2026-07-28T03:14:42.285000Z","event_type":"price_change","frame_hash":"9fa084592b97522247fc098cb1c565dc037bc9b37f870d6b7e24883876dcd5ac","frame_index":0,"kind":"data","monotonic_ns":310465153046750,"payload":{"event_type":"price_change","market":"0x779291bef19b6709f61e9764a954aafe9ffae488d50ae674aabdcb4f248006d5","price_changes":[{"asset_id":"14965588658799411272385430903075831224615961675357217884735713260981483529984","best_ask":"1","best_bid":"0.99","hash":"486207b067706795d920af67e9131981283e116a","price":"0.98","side":"BUY","size":"60.61"},{"asset_id":"8761897749749422724209054078244794145777693856614463256546737399611489089783","best_ask":"0.01","best_bid":"0","hash":"16acec785a51f8d7a8d4db4a260eadbcb0c79f28","price":"0.02","side":"SELL","size":"60.61"}],"timestamp":"1785208482285"},"payload_hash":"03abc556618a2648c5dc062dffb382ee841fd963e6c74fb42db9401996e34424","raw_frame":"{\"market\":\"0x779291bef19b6709f61e9764a954aafe9ffae488d50ae674aabdcb4f248006d5\", \"price_changes\":[{\"asset_id\":\"14965588658799411272385430903075831224615961675357217884735713260981483529984\", \"price\":\"0.98\", \"size\":\"60.61\", \"side\":\"BUY\", \"hash\":\"486207b067706795d920af67e9131981283e116a\", \"best_bid\":\"0.99\", \"best_ask\":\"1\"}, {\"asset_id\":\"8761897749749422724209054078244794145777693856614463256546737399611489089783\", \"price\":\"0.02\", \"size\":\"60.61\", \"side\":\"SELL\", \"hash\":\"16acec785a51f8d7a8d4db4a260eadbcb0c79f28\", \"best_bid\":\"0\", \"best_ask\":\"0.01\"}], \"timestamp\":\"1785208482285\", \"event_type\":\"price_change\"}","received_at":"2026-07-28T03:14:42.117280Z","schema_version":"clob-market-ws.price_change.v1","sequence":null,"server_hash":null,"server_timestamp":"1785208482285","session_id":"3e519d9098404c15b234d96025eb1a2b","source":"clob_market_ws"},"received_at":"2026-07-28T03:14:42.117280Z","record_id":"21d21263ff97c2a26aae027e37da6fd16eab66bea559074d024e01c9aa3e3699","schema_fingerprint":"4aa3821a28b0b7c2400bc59aba4bcc0a76e971dadd19610d3ad38c768e124dc7","schema_version":"edge-lab-recorder.raw.v1","sequence":null,"source":"clob_market_ws"}
{"event_at":"2026-07-28T03:14:42.285000Z","event_fingerprint":"0a4be6dab2e22290339441817e8c75f82c96ca61b4760e64398d4260673c4f07","payload":{"connection_id":"a6b55582af5f430fb37ad02bf0922475","event_at":"2026-07-28T03:14:42.285000Z","event_type":"price_change","frame_hash":"4a9eb41aa078b7abfb1f7eecc194be314d3f0696a907a762182e8afd3e88081c","frame_index":0,"kind":"data","monotonic_ns":310465154677166,"payload":{"event_type":"price_change","market":"0x779291bef19b6709f61e9764a954aafe9ffae488d50ae674aabdcb4f248006d5","price_changes":[{"asset_id":"8761897749749422724209054078244794145777693856614463256546737399611489089783","best_ask":"0.01","best_bid":"0","hash":"16acec785a51f8d7a8d4db4a260eadbcb0c79f28","price":"0.02","side":"SELL","size":"60.61"},{"asset_id":"14965588658799411272385430903075831224615961675357217884735713260981483529984","best_ask":"1","best_bid":"0.99","hash":"486207b067706795d920af67e9131981283e116a","price":"0.98","side":"BUY","size":"60.61"}],"timestamp":"1785208482285"},"payload_hash":"187c464dc1dbf5916bdbf4f2569ff72126dd3621337f82b039fc14c45b4d65d6","raw_frame":"{\"market\":\"0x779291bef19b6709f61e9764a954aafe9ffae488d50ae674aabdcb4f248006d5\", \"price_changes\":[{\"asset_id\":\"8761897749749422724209054078244794145777693856614463256546737399611489089783\", \"price\":\"0.02\", \"size\":\"60.61\", \"side\":\"SELL\", \"hash\":\"16acec785a51f8d7a8d4db4a260eadbcb0c79f28\", \"best_bid\":\"0\", \"best_ask\":\"0.01\"}, {\"asset_id\":\"14965588658799411272385430903075831224615961675357217884735713260981483529984\", \"price\":\"0.98\", \"size\":\"60.61\", \"side\":\"BUY\", \"hash\":\"486207b067706795d920af67e9131981283e116a\", \"best_bid\":\"0.99\", \"best_ask\":\"1\"}], \"timestamp\":\"1785208482285\", \"event_type\":\"price_change\"}","received_at":"2026-07-28T03:14:42.118912Z","schema_version":"clob-market-ws.price_change.v1","sequence":null,"server_hash":null,"server_timestamp":"1785208482285","session_id":"3e519d9098404c15b234d96025eb1a2b","source":"clob_market_ws"},"received_at":"2026-07-28T03:14:42.118912Z","record_id":"81971a5d24ba773ecb18cebdfc81a31a8515c545e0df5229b7200c9404482a9d","schema_fingerprint":"4aa3821a28b0b7c2400bc59aba4bcc0a76e971dadd19610d3ad38c768e124dc7","schema_version":"edge-lab-recorder.raw.v1","sequence":null,"source":"clob_market_ws"}
{"event_at":"2026-07-28T03:14:42.296000Z","event_fingerprint":"cf562208b0defecde2ec0a38754cd31591affcfc3f9756007d66f6ca37841b1f","payload":{"connection_id":"a6b55582af5f430fb37ad02bf0922475","event_at":"2026-07-28T03:14:42.296000Z","event_type":"price_change","frame_hash":"e541f46c1616c6440ec597532aca9aa15f46bb2657869454e1dffa12cbac1738","frame_index":0,"kind":"data","monotonic_ns":310465161242958,"payload":{"event_type":"price_change","market":"0x779291bef19b6709f61e9764a954aafe9ffae488d50ae674aabdcb4f248006d5","price_changes":[{"asset_id":"14965588658799411272385430903075831224615961675357217884735713260981483529984","best_ask":"1","best_bid":"0.99","hash":"39df8a3723eeefdc1675790a3846e2a39b4f0c08","price":"0.99","side":"BUY","size":"133.16"},{"asset_id":"8761897749749422724209054078244794145777693856614463256546737399611489089783","best_ask":"0.01","best_bid":"0","hash":"842588fbf9e03633113feb8d5cc89ca1b34e1716","price":"0.01","side":"SELL","size":"133.16"}],"timestamp":"1785208482296"},"payload_hash":"5bd346fc9d053627e92f9fb9af8ebadfcbf567960f7711469c17a69309b1417c","raw_frame":"{\"market\":\"0x779291bef19b6709f61e9764a954aafe9ffae488d50ae674aabdcb4f248006d5\", \"price_changes\":[{\"asset_id\":\"14965588658799411272385430903075831224615961675357217884735713260981483529984\", \"price\":\"0.99\", \"size\":\"133.16\", \"side\":\"BUY\", \"hash\":\"39df8a3723eeefdc1675790a3846e2a39b4f0c08\", \"best_bid\":\"0.99\", \"best_ask\":\"1\"}, {\"asset_id\":\"8761897749749422724209054078244794145777693856614463256546737399611489089783\", \"price\":\"0.01\", \"size\":\"133.16\", \"side\":\"SELL\", \"hash\":\"842588fbf9e03633113feb8d5cc89ca1b34e1716\", \"best_bid\":\"0\", \"best_ask\":\"0.01\"}], \"timestamp\":\"1785208482296\", \"event_type\":\"price_change\"}","received_at":"2026-07-28T03:14:42.125475Z","schema_version":"clob-market-ws.price_change.v1","sequence":null,"server_hash":null,"server_timestamp":"1785208482296","session_id":"3e519d9098404c15b234d96025eb1a2b","source":"clob_market_ws"},"received_at":"2026-07-28T03:14:42.125475Z","record_id":"6e8b46348eede3f1fb10afe5e10542b2c0c7e56ce2287e5733836af4b0a4dd1c","schema_fingerprint":"4aa3821a28b0b7c2400bc59aba4bcc0a76e971dadd19610d3ad38c768e124dc7","schema_version":"edge-lab-recorder.raw.v1","sequence":null,"source":"clob_market_ws"}
{"event_at":"2026-07-28T03:14:42.350000Z","event_fingerprint":"4db329a1742972ed83fc0ce80461e62e6f30adcb13b30e7308b8fb552ab75385","payload":{"connection_id":"a6b55582af5f430fb37ad02bf0922475","event_at":"2026-07-28T03:14:42.350000Z","event_type":"price_change","frame_hash":"51a26fa597438278047c8806052305dd31c999187962e67783ea58402e606492","frame_index":0,"kind":"data","monotonic_ns":310465216483625,"payload":{"event_type":"price_change","market":"0x779291bef19b6709f61e9764a954aafe9ffae488d50ae674aabdcb4f248006d5","price_changes":[{"asset_id":"14965588658799411272385430903075831224615961675357217884735713260981483529984","best_ask":"1","best_bid":"0.99","hash":"8f782d4e7e57ee513f53fe1fa2a9bf77389a3582","price":"0.01","side":"BUY","size":"5520"},{"asset_id":"8761897749749422724209054078244794145777693856614463256546737399611489089783","best_ask":"0.01","best_bid":"0","hash":"775152f7b349789596b8fd402322419172f59dab","price":"0.99","side":"SELL","size":"5520"}],"timestamp":"1785208482350"},"payload_hash":"4740b7a7b41ccc0c2d5e76b00d5eb6c8a21788f1cc221df08630f19bbe1acc1f","raw_frame":"{\"market\":\"0x779291bef19b6709f61e9764a954aafe9ffae488d50ae674aabdcb4f248006d5\", \"price_changes\":[{\"asset_id\":\"14965588658799411272385430903075831224615961675357217884735713260981483529984\", \"price\":\"0.01\", \"size\":\"5520\", \"side\":\"BUY\", \"hash\":\"8f782d4e7e57ee513f53fe1fa2a9bf77389a3582\", \"best_bid\":\"0.99\", \"best_ask\":\"1\"}, {\"asset_id\":\"8761897749749422724209054078244794145777693856614463256546737399611489089783\", \"price\":\"0.99\", \"size\":\"5520\", \"side\":\"SELL\", \"hash\":\"775152f7b349789596b8fd402322419172f59dab\", \"best_bid\":\"0\", \"best_ask\":\"0.01\"}], \"timestamp\":\"1785208482350\", \"event_type\":\"price_change\"}","received_at":"2026-07-28T03:14:42.180716Z","schema_version":"clob-market-ws.price_change.v1","sequence":null,"server_hash":null,"server_timestamp":"1785208482350","session_id":"3e519d9098404c15b234d96025eb1a2b","source":"clob_market_ws"},"received_at":"2026-07-28T03:14:42.180716Z","record_id":"48c11437d8072caa3a43151610396d54ed8d2c2d2484d526f23e762f9592ca19","schema_fingerprint":"4aa3821a28b0b7c2400bc59aba4bcc0a76e971dadd19610d3ad38c768e124dc7","schema_version":"edge-lab-recorder.raw.v1","sequence":null,"source":"clob_market_ws"}
{"event_at":"2026-07-28T03:14:42.377000Z","event_fingerprint":"97abeb323c979a8c7fc60cee59832d47b3ce839886ffb7d662608336e70d5bf5","payload":{"connection_id":"a6b55582af5f430fb37ad02bf0922475","event_at":"2026-07-28T03:14:42.377000Z","event_type":"price_change","frame_hash":"71bff9080e14946d4f79bb8b6903b46fbf1af5f4e675fda977adefc053b3cf50","frame_index":0,"kind":"data","monotonic_ns":310465243336750,"payload":{"event_type":"price_change","market":"0x779291bef19b6709f61e9764a954aafe9ffae488d50ae674aabdcb4f248006d5","price_changes":[{"asset_id":"14965588658799411272385430903075831224615961675357217884735713260981483529984","best_ask":"1","best_bid":"0.99","hash":"45341b42c3e816b51fc50533e594e6730f721b21","price":"0.03","side":"BUY","size":"535"},{"asset_id":"8761897749749422724209054078244794145777693856614463256546737399611489089783","best_ask":"0.01","best_bid":"0","hash":"ce5f5e7b992b943b7e4d68aef336d45bf61740e3","price":"0.97","side":"SELL","size":"535"}],"timestamp":"1785208482377"},"payload_hash":"6172f95a47dcffd4eea1ab5dd70656b30d276917e49d16f172acefb045191e4d","raw_frame":"{\"market\":\"0x779291bef19b6709f61e9764a954aafe9ffae488d50ae674aabdcb4f248006d5\", \"price_changes\":[{\"asset_id\":\"14965588658799411272385430903075831224615961675357217884735713260981483529984\", \"price\":\"0.03\", \"size\":\"535\", \"side\":\"BUY\", \"hash\":\"45341b42c3e816b51fc50533e594e6730f721b21\", \"best_bid\":\"0.99\", \"best_ask\":\"1\"}, {\"asset_id\":\"8761897749749422724209054078244794145777693856614463256546737399611489089783\", \"price\":\"0.97\", \"size\":\"535\", \"side\":\"SELL\", \"hash\":\"ce5f5e7b992b943b7e4d68aef336d45bf61740e3\", \"best_bid\":\"0\", \"best_ask\":\"0.01\"}], \"timestamp\":\"1785208482377\", \"event_type\":\"price_change\"}","received_at":"2026-07-28T03:14:42.207566Z","schema_version":"clob-market-ws.price_change.v1","sequence":null,"server_hash":null,"server_timestamp":"1785208482377","session_id":"3e519d9098404c15b234d96025eb1a2b","source":"clob_market_ws"},"received_at":"2026-07-28T03:14:42.207566Z","record_id":"2d313a0a165b14028e5586aa78d21fcc4d7c292b225815a2edffb6eb758418f0","schema_fingerprint":"4aa3821a28b0b7c2400bc59aba4bcc0a76e971dadd19610d3ad38c768e124dc7","schema_version":"edge-lab-recorder.raw.v1","sequence":null,"source":"clob_market_ws"}
{"event_at":"2026-07-28T03:14:42.378000Z","event_fingerprint":"611560af00fbe735622b6d07e8443403307c8dbbc19a6e9a31b51e608059102b","payload":{"connection_id":"a6b55582af5f430fb37ad02bf0922475","event_at":"2026-07-28T03:14:42.378000Z","event_type":"price_change","frame_hash":"dccb1bd11ed530624499691a597f51fa6b4c496efdbe8730884e6d1db53a9a6b","frame_index":0,"kind":"data","monotonic_ns":310465245454791,"payload":{"event_type":"price_change","market":"0x779291bef19b6709f61e9764a954aafe9ffae488d50ae674aabdcb4f248006d5","price_changes":[{"asset_id":"14965588658799411272385430903075831224615961675357217884735713260981483529984","best_ask":"1","best_bid":"0.99","hash":"3b6eacbde125982d8fc0ff4b27f9302841eac45b","price":"0.01","side":"BUY","size":"5515"},{"asset_id":"8761897749749422724209054078244794145777693856614463256546737399611489089783","best_ask":"0.01","best_bid":"0","hash":"3ce5d1e486e4e3120cbe178e4c7b76982ed0e658","price":"0.99","side":"SELL","size":"5515"}],"timestamp":"1785208482378"},"payload_hash":"008768027539ec6a5a51504cbe892844f41f8680a164ab7014329945e2447656","raw_frame":"{\"market\":\"0x779291bef19b6709f61e9764a954aafe9ffae488d50ae674aabdcb4f248006d5\", \"price_changes\":[{\"asset_id\":\"14965588658799411272385430903075831224615961675357217884735713260981483529984\", \"price\":\"0.01\", \"size\":\"5515\", \"side\":\"BUY\", \"hash\":\"3b6eacbde125982d8fc0ff4b27f9302841eac45b\", \"best_bid\":\"0.99\", \"best_ask\":\"1\"}, {\"asset_id\":\"8761897749749422724209054078244794145777693856614463256546737399611489089783\", \"price\":\"0.99\", \"size\":\"5515\", \"side\":\"SELL\", \"hash\":\"3ce5d1e486e4e3120cbe178e4c7b76982ed0e658\", \"best_bid\":\"0\", \"best_ask\":\"0.01\"}], \"timestamp\":\"1785208482378\", \"event_type\":\"price_change\"}","received_at":"2026-07-28T03:14:42.209687Z","schema_version":"clob-market-ws.price_change.v1","sequence":null,"server_hash":null,"server_timestamp":"1785208482378","session_id":"3e519d9098404c15b234d96025eb1a2b","source":"clob_market_ws"},"received_at":"2026-07-28T03:14:42.209687Z","record_id":"15c51886bb5a4242bbe7701a633ad462895fe08285ba4ba82d95ef7989f7befe","schema_fingerprint":"4aa3821a28b0b7c2400bc59aba4bcc0a76e971dadd19610d3ad38c768e124dc7","schema_version":"edge-lab-recorder.raw.v1","sequence":null,"source":"clob_market_ws"}
{"event_at":"2026-07-28T03:14:42.477000Z","event_fingerprint":"6161ee8683beacceb5617593179310eae17036aca67d26b6b7a963a807498726","payload":{"connection_id":"a6b55582af5f430fb37ad02bf0922475","event_at":"2026-07-28T03:14:42.477000Z","event_type":"price_change","frame_hash":"9aea89cbf1ff9c4cbae92c4d16a6a0bec6004362f9c8b419bda6e30bf1242d59","frame_index":0,"kind":"data","monotonic_ns":310465343053000,"payload":{"event_type":"price_change","market":"0x779291bef19b6709f61e9764a954aafe9ffae488d50ae674aabdcb4f248006d5","price_changes":[{"asset_id":"14965588658799411272385430903075831224615961675357217884735713260981483529984","best_ask":"1","best_bid":"0.99","hash":"c7e214a8308abb33ee11e362aa86b16953f8e30b","price":"0.99","side":"BUY","size":"106"},{"asset_id":"8761897749749422724209054078244794145777693856614463256546737399611489089783","best_ask":"0.01","best_bid":"0","hash":"fbdc05c71affc6dcef7d916b83670f9905cd4bf0","price":"0.01","side":"SELL","size":"106"}],"timestamp":"1785208482477"},"payload_hash":"1dc1e5193bb459ec4775b884ca815296a1bb55ffeb457974982fa542b123b9dd","raw_frame":"{\"market\":\"0x779291bef19b6709f61e9764a954aafe9ffae488d50ae674aabdcb4f248006d5\", \"price_changes\":[{\"asset_id\":\"14965588658799411272385430903075831224615961675357217884735713260981483529984\", \"price\":\"0.99\", \"size\":\"106\", \"side\":\"BUY\", \"hash\":\"c7e214a8308abb33ee11e362aa86b16953f8e30b\", \"best_bid\":\"0.99\", \"best_ask\":\"1\"}, {\"asset_id\":\"8761897749749422724209054078244794145777693856614463256546737399611489089783\", \"price\":\"0.01\", \"size\":\"106\", \"side\":\"SELL\", \"hash\":\"fbdc05c71affc6dcef7d916b83670f9905cd4bf0\", \"best_bid\":\"0\", \"best_ask\":\"0.01\"}], \"timestamp\":\"1785208482477\", \"event_type\":\"price_change\"}","received_at":"2026-07-28T03:14:42.307284Z","schema_version":"clob-market-ws.price_change.v1","sequence":null,"server_hash":null,"server_timestamp":"1785208482477","session_id":"3e519d9098404c15b234d96025eb1a2b","source":"clob_market_ws"},"received_at":"2026-07-28T03:14:42.307284Z","record_id":"4923b83f272d2c8de4bf157e4301d2fd5e03b84be4e28e9a1871a7f7b4f6f552","schema_fingerprint":"4aa3821a28b0b7c2400bc59aba4bcc0a76e971dadd19610d3ad38c768e124dc7","schema_version":"edge-lab-recorder.raw.v1","sequence":null,"source":"clob_market_ws"}
{"event_at":"2026-07-28T03:14:42.482000Z","event_fingerprint":"cdb24166469fb6ed456101ea9bc0aff51e127ff4c5a85663735719e0cd6ab3a2","payload":{"connection_id":"a6b55582af5f430fb37ad02bf0922475","event_at":"2026-07-28T03:14:42.482000Z","event_type":"price_change","frame_hash":"51e5e03a1692d88b999948296545b6c8b5944fa20a51906f4e08b0089ac2755d","frame_index":0,"kind":"data","monotonic_ns":310465348487458,"payload":{"event_type":"price_change","market":"0x779291bef19b6709f61e9764a954aafe9ffae488d50ae674aabdcb4f248006d5","price_changes":[{"asset_id":"14965588658799411272385430903075831224615961675357217884735713260981483529984","best_ask":"1","best_bid":"0.99","hash":"25f7e8b4e6e32f76a32dfad8582cebf108f5e0eb","price":"0.01","side":"BUY","size":"5521.24"},{"asset_id":"8761897749749422724209054078244794145777693856614463256546737399611489089783","best_ask":"0.01","best_bid":"0","hash":"95878a0e20c46a2daeb1c9aa3c7d63e0eceadd96","price":"0.99","side":"SELL","size":"5521.24"}],"timestamp":"1785208482482"},"payload_hash":"87004c92002bc4ed97c65e8c9de23de52c451c7d2f2c172a37a363e56063640c","raw_frame":"{\"market\":\"0x779291bef19b6709f61e9764a954aafe9ffae488d50ae674aabdcb4f248006d5\", \"price_changes\":[{\"asset_id\":\"14965588658799411272385430903075831224615961675357217884735713260981483529984\", \"price\":\"0.01\", \"size\":\"5521.24\", \"side\":\"BUY\", \"hash\":\"25f7e8b4e6e32f76a32dfad8582cebf108f5e0eb\", \"best_bid\":\"0.99\", \"best_ask\":\"1\"}, {\"asset_id\":\"8761897749749422724209054078244794145777693856614463256546737399611489089783\", \"price\":\"0.99\", \"size\":\"5521.24\", \"side\":\"SELL\", \"hash\":\"95878a0e20c46a2daeb1c9aa3c7d63e0eceadd96\", \"best_bid\":\"0\", \"best_ask\":\"0.01\"}], \"timestamp\":\"1785208482482\", \"event_type\":\"price_change\"}","received_at":"2026-07-28T03:14:42.312718Z","schema_version":"clob-market-ws.price_change.v1","sequence":null,"server_hash":null,"server_timestamp":"1785208482482","session_id":"3e519d9098404c15b234d96025eb1a2b","source":"clob_market_ws"},"received_at":"2026-07-28T03:14:42.312718Z","record_id":"d3178a5a2592255ffcc0899f217424b5722522414ddc0e346ef2b1facd43f788","schema_fingerprint":"4aa3821a28b0b7c2400bc59aba4bcc0a76e971dadd19610d3ad38c768e124dc7","schema_version":"edge-lab-recorder.raw.v1","sequence":null,"source":"clob_market_ws"}
{"event_at":"2026-07-28T03:14:42.482000Z","event_fingerprint":"756f877f99bb3c18e495a65469b344ac14761f7aeb59163cf79a63b9f229755d","payload":{"connection_id":"a6b55582af5f430fb37ad02bf0922475","event_at":"2026-07-28T03:14:42.482000Z","event_type":"price_change","frame_hash":"bf0b5674006eb7d19430787f25e49b61893e794c993bc3f8167c1bd9c426638e","frame_index":0,"kind":"data","monotonic_ns":310465350043000,"payload":{"event_type":"price_change","market":"0x779291bef19b6709f61e9764a954aafe9ffae488d50ae674aabdcb4f248006d5","price_changes":[{"asset_id":"8761897749749422724209054078244794145777693856614463256546737399611489089783","best_ask":"0.01","best_bid":"0","hash":"20a47f13171dae5bb1efb9246ca7633aced5c994","price":"0.02","side":"SELL","size":"74.22"},{"asset_id":"14965588658799411272385430903075831224615961675357217884735713260981483529984","best_ask":"1","best_bid":"0.99","hash":"8106cd3969578df0390768ab3e0df22f093855bc","price":"0.98","side":"BUY","size":"74.22"}],"timestamp":"1785208482482"},"payload_hash":"b94e0fe2f4cfa92733b55705e344e679b05a8f447e67370e1d1ff21913b0017a","raw_frame":"{\"market\":\"0x779291bef19b6709f61e9764a954aafe9ffae488d50ae674aabdcb4f248006d5\", \"price_changes\":[{\"asset_id\":\"8761897749749422724209054078244794145777693856614463256546737399611489089783\", \"price\":\"0.02\", \"size\":\"74.22\", \"side\":\"SELL\", \"hash\":\"20a47f13171dae5bb1efb9246ca7633aced5c994\", \"best_bid\":\"0\", \"best_ask\":\"0.01\"}, {\"asset_id\":\"14965588658799411272385430903075831224615961675357217884735713260981483529984\", \"price\":\"0.98\", \"size\":\"74.22\", \"side\":\"BUY\", \"hash\":\"8106cd3969578df0390768ab3e0df22f093855bc\", \"best_bid\":\"0.99\", \"best_ask\":\"1\"}], \"timestamp\":\"1785208482482\", \"event_type\":\"price_change\"}","received_at":"2026-07-28T03:14:42.314275Z","schema_version":"clob-market-ws.price_change.v1","sequence":null,"server_hash":null,"server_timestamp":"1785208482482","session_id":"3e519d9098404c15b234d96025eb1a2b","source":"clob_market_ws"},"received_at":"2026-07-28T03:14:42.314275Z","record_id":"fa076308c6df49df5054b275193a29dfc762237c7cf24a71982df50d69e5761e","schema_fingerprint":"4aa3821a28b0b7c2400bc59aba4bcc0a76e971dadd19610d3ad38c768e124dc7","schema_version":"edge-lab-recorder.raw.v1","sequence":null,"source":"clob_market_ws"}
{"event_at":"2026-07-28T03:14:42.483000Z","event_fingerprint":"5a1c574334673129545517489087c9aaff774eeeeda546829f9a1b0eddabb60d","payload":{"connection_id":"a6b55582af5f430fb37ad02bf0922475","event_at":"2026-07-28T03:14:42.483000Z","event_type":"price_change","frame_hash":"c019f7ac20466e9ffef737d104383b63233f03cda5888c7d2b0b88789b58321c","frame_index":0,"kind":"data","monotonic_ns":310465351776291,"payload":{"event_type":"price_change","market":"0x779291bef19b6709f61e9764a954aafe9ffae488d50ae674aabdcb4f248006d5","price_changes":[{"asset_id":"14965588658799411272385430903075831224615961675357217884735713260981483529984","best_ask":"1","best_bid":"0.99","hash":"a278f0d9d2e93b32b6a2ba3a8e5b6b69ba881d2d","price":"0.98","side":"BUY","size":"101.6"},{"asset_id":"8761897749749422724209054078244794145777693856614463256546737399611489089783","best_ask":"0.01","best_bid":"0","hash":"b18ba71c4befbdd8eddfccd10d9a723ab11cd00c","price":"0.02","side":"SELL","size":"101.6"}],"timestamp":"1785208482483"},"payload_hash":"ed5a6bdf513f196803bd74d8bf7ac9a6a9a32da665f391af50dc7425add47b17","raw_frame":"{\"market\":\"0x779291bef19b6709f61e9764a954aafe9ffae488d50ae674aabdcb4f248006d5\", \"price_changes\":[{\"asset_id\":\"14965588658799411272385430903075831224615961675357217884735713260981483529984\", \"price\":\"0.98\", \"size\":\"101.6\", \"side\":\"BUY\", \"hash\":\"a278f0d9d2e93b32b6a2ba3a8e5b6b69ba881d2d\", \"best_bid\":\"0.99\", \"best_ask\":\"1\"}, {\"asset_id\":\"8761897749749422724209054078244794145777693856614463256546737399611489089783\", \"price\":\"0.02\", \"size\":\"101.6\", \"side\":\"SELL\", \"hash\":\"b18ba71c4befbdd8eddfccd10d9a723ab11cd00c\", \"best_bid\":\"0\", \"best_ask\":\"0.01\"}], \"timestamp\":\"1785208482483\", \"event_type\":\"price_change\"}","received_at":"2026-07-28T03:14:42.316005Z","schema_version":"clob-market-ws.price_change.v1","sequence":null,"server_hash":null,"server_timestamp":"1785208482483","session_id":"3e519d9098404c15b234d96025eb1a2b","source":"clob_market_ws"},"received_at":"2026-07-28T03:14:42.316005Z","record_id":"54994a795493a39fcf04fb20f82034ffd625e4c4def3c6478d984e223594c920","schema_fingerprint":"4aa3821a28b0b7c2400bc59aba4bcc0a76e971dadd19610d3ad38c768e124dc7","schema_version":"edge-lab-recorder.raw.v1","sequence":null,"source":"clob_market_ws"}
{"event_at":"2026-07-28T03:14:42.484000Z","event_fingerprint":"80270e6d423db6d3b2fc3749f4fe050b14b0f71766bd1caa32e521949b23e5b2","payload":{"connection_id":"a6b55582af5f430fb37ad02bf0922475","event_at":"2026-07-28T03:14:42.484000Z","event_type":"price_change","frame_hash":"e756c4f1db022b7917359880ffaf2af452eb4eacfbeec42787f911f4440fbb90","frame_index":0,"kind":"data","monotonic_ns":310465353481125,"payload":{"event_type":"price_change","market":"0x779291bef19b6709f61e9764a954aafe9ffae488d50ae674aabdcb4f248006d5","price_changes":[{"asset_id":"8761897749749422724209054078244794145777693856614463256546737399611489089783","best_ask":"0.01","best_bid":"0","hash":"83d5ede09c2a79daccecbb8d78f6c9dca42cd4be","price":"0.01","side":"SELL","size":"140"},{"asset_id":"14965588658799411272385430903075831224615961675357217884735713260981483529984","best_ask":"1","best_bid":"0.99","hash":"2c0b206750460968ef5510770231bdb3a9694504","price":"0.99","side":"BUY","size":"140"}],"timestamp":"1785208482484"},"payload_hash":"99937bd223d6084b82462a8a6a4714858b59e874d96ef459b4c863b6a1898f5c","raw_frame":"{\"market\":\"0x779291bef19b6709f61e9764a954aafe9ffae488d50ae674aabdcb4f248006d5\", \"price_changes\":[{\"asset_id\":\"8761897749749422724209054078244794145777693856614463256546737399611489089783\", \"price\":\"0.01\", \"size\":\"140\", \"side\":\"SELL\", \"hash\":\"83d5ede09c2a79daccecbb8d78f6c9dca42cd4be\", \"best_bid\":\"0\", \"best_ask\":\"0.01\"}, {\"asset_id\":\"14965588658799411272385430903075831224615961675357217884735713260981483529984\", \"price\":\"0.99\", \"size\":\"140\", \"side\":\"BUY\", \"hash\":\"2c0b206750460968ef5510770231bdb3a9694504\", \"best_bid\":\"0.99\", \"best_ask\":\"1\"}], \"timestamp\":\"1785208482484\", \"event_type\":\"price_change\"}","received_at":"2026-07-28T03:14:42.317713Z","schema_version":"clob-market-ws.price_change.v1","sequence":null,"server_hash":null,"server_timestamp":"1785208482484","session_id":"3e519d9098404c15b234d96025eb1a2b","source":"clob_market_ws"},"received_at":"2026-07-28T03:14:42.317713Z","record_id":"0c0f7e01320f35cddceb194eae9263a51e4e9ff45e79c10bf16138d4f7857523","schema_fingerprint":"4aa3821a28b0b7c2400bc59aba4bcc0a76e971dadd19610d3ad38c768e124dc7","schema_version":"edge-lab-recorder.raw.v1","sequence":null,"source":"clob_market_ws"}
{"event_at":"2026-07-28T03:14:42.499000Z","event_fingerprint":"a47f6ed693d034193c96168ffd7cb92a42811a81973d627ce679470be531cdf6","payload":{"connection_id":"a6b55582af5f430fb37ad02bf0922475","event_at":"2026-07-28T03:14:42.499000Z","event_type":"price_change","frame_hash":"49d74ce88554a39b6b1f1653c36f77e8e63500f0f25135ca5e79ba888cb4f896","frame_index":0,"kind":"data","monotonic_ns":310465371497291,"payload":{"event_type":"price_change","market":"0x779291bef19b6709f61e9764a954aafe9ffae488d50ae674aabdcb4f248006d5","price_changes":[{"asset_id":"14965588658799411272385430903075831224615961675357217884735713260981483529984","best_ask":"1","best_bid":"0.99","hash":"0fd8691f5070eca3bc2993888b2945644fb9b259","price":"0.03","side":"BUY","size":"530"},{"asset_id":"8761897749749422724209054078244794145777693856614463256546737399611489089783","best_ask":"0.01","best_bid":"0","hash":"9dc6ace711d826049ae0b839e02839afee680246","price":"0.97","side":"SELL","size":"530"}],"timestamp":"1785208482499"},"payload_hash":"53c9316cebbc7b907414d67fb147ea733a74f602f16821f81b304d89a9f52411","raw_frame":"{\"market\":\"0x779291bef19b6709f61e9764a954aafe9ffae488d50ae674aabdcb4f248006d5\", \"price_changes\":[{\"asset_id\":\"14965588658799411272385430903075831224615961675357217884735713260981483529984\", \"price\":\"0.03\", \"size\":\"530\", \"side\":\"BUY\", \"hash\":\"0fd8691f5070eca3bc2993888b2945644fb9b259\", \"best_bid\":\"0.99\", \"best_ask\":\"1\"}, {\"asset_id\":\"8761897749749422724209054078244794145777693856614463256546737399611489089783\", \"price\":\"0.97\", \"size\":\"530\", \"side\":\"SELL\", \"hash\":\"9dc6ace711d826049ae0b839e02839afee680246\", \"best_bid\":\"0\", \"best_ask\":\"0.01\"}], \"timestamp\":\"1785208482499\", \"event_type\":\"price_change\"}","received_at":"2026-07-28T03:14:42.335728Z","schema_version":"clob-market-ws.price_change.v1","sequence":null,"server_hash":null,"server_timestamp":"1785208482499","session_id":"3e519d9098404c15b234d96025eb1a2b","source":"clob_market_ws"},"received_at":"2026-07-28T03:14:42.335728Z","record_id":"8cca61b1adddcfbf4d6b04e12f71e4b1ea26d121b512ca45f37183d0510b4a14","schema_fingerprint":"4aa3821a28b0b7c2400bc59aba4bcc0a76e971dadd19610d3ad38c768e124dc7","schema_version":"edge-lab-recorder.raw.v1","sequence":null,"source":"clob_market_ws"}
{"event_at":"2026-07-28T03:14:42.513000Z","event_fingerprint":"f492f2a2eb4961b103c988927b450d8f13dd75f4202429129a2a0fc89be0a3c6","payload":{"connection_id":"a6b55582af5f430fb37ad02bf0922475","event_at":"2026-07-28T03:14:42.513000Z","event_type":"price_change","frame_hash":"0e0ccb76deca6916f518f8eac692cf77cce1cdc48b7b57f3d5c59b493d76668d","frame_index":0,"kind":"data","monotonic_ns":310465379506416,"payload":{"event_type":"price_change","market":"0x779291bef19b6709f61e9764a954aafe9ffae488d50ae674aabdcb4f248006d5","price_changes":[{"asset_id":"14965588658799411272385430903075831224615961675357217884735713260981483529984","best_ask":"1","best_bid":"0.99","hash":"405add75cad5d9f5858a5fdf7316511103c67fea","price":"0.01","side":"BUY","size":"5526.24"},{"asset_id":"8761897749749422724209054078244794145777693856614463256546737399611489089783","best_ask":"0.01","best_bid":"0","hash":"725023728880c49f3bbf4b6c67c92053ed5c310d","price":"0.99","side":"SELL","size":"5526.24"}],"timestamp":"1785208482513"},"payload_hash":"f3e1c07340b0ff5513a8244935718fc5011d2399915485adc341909d2640e58f","raw_frame":"{\"market\":\"0x779291bef19b6709f61e9764a954aafe9ffae488d50ae674aabdcb4f248006d5\", \"price_changes\":[{\"asset_id\":\"14965588658799411272385430903075831224615961675357217884735713260981483529984\", \"price\":\"0.01\", \"size\":\"5526.24\", \"side\":\"BUY\", \"hash\":\"405add75cad5d9f5858a5fdf7316511103c67fea\", \"best_bid\":\"0.99\", \"best_ask\":\"1\"}, {\"asset_id\":\"8761897749749422724209054078244794145777693856614463256546737399611489089783\", \"price\":\"0.99\", \"size\":\"5526.24\", \"side\":\"SELL\", \"hash\":\"725023728880c49f3bbf4b6c67c92053ed5c310d\", \"best_bid\":\"0\", \"best_ask\":\"0.01\"}], \"timestamp\":\"1785208482513\", \"event_type\":\"price_change\"}","received_at":"2026-07-28T03:14:42.343738Z","schema_version":"clob-market-ws.price_change.v1","sequence":null,"server_hash":null,"server_timestamp":"1785208482513","session_id":"3e519d9098404c15b234d96025eb1a2b","source":"clob_market_ws"},"received_at":"2026-07-28T03:14:42.343738Z","record_id":"79be3c0672d9701d5e2575e908d9284117a80eed5638cf7e606c627057c0664c","schema_fingerprint":"4aa3821a28b0b7c2400bc59aba4bcc0a76e971dadd19610d3ad38c768e124dc7","schema_version":"edge-lab-recorder.raw.v1","sequence":null,"source":"clob_market_ws"}
{"event_at":"2026-07-28T03:14:42.535000Z","event_fingerprint":"0b36b9915f8d99d520d557d614146922e99bfd8c980771875a359f3c1882f6e3","payload":{"connection_id":"a6b55582af5f430fb37ad02bf0922475","event_at":"2026-07-28T03:14:42.535000Z","event_type":"price_change","frame_hash":"d4a06482822a3b89958dabf6d9225b12b0cf441fed25944203b3c792dd370a5a","frame_index":0,"kind":"data","monotonic_ns":310465400015750,"payload":{"event_type":"price_change","market":"0x779291bef19b6709f61e9764a954aafe9ffae488d50ae674aabdcb4f248006d5","price_changes":[{"asset_id":"14965588658799411272385430903075831224615961675357217884735713260981483529984","best_ask":"1","best_bid":"0.99","hash":"0fa07da6cc18dae88b3533331e2bc945f28f34d2","price":"0.01","side":"BUY","size":"5521.24"},{"asset_id":"8761897749749422724209054078244794145777693856614463256546737399611489089783","best_ask":"0.01","best_bid":"0","hash":"b5d72a980f92590f95cd7f85a448a389ee682afd","price":"0.99","side":"SELL","size":"5521.24"}],"timestamp":"1785208482535"},"payload_hash":"ded9016332dfe6c0bf1ef6d7b968cf1537e1e39f59c0ad2a7c4322f03b46a777","raw_frame":"{\"market\":\"0x779291bef19b6709f61e9764a954aafe9ffae488d50ae674aabdcb4f248006d5\", \"price_changes\":[{\"asset_id\":\"14965588658799411272385430903075831224615961675357217884735713260981483529984\", \"price\":\"0.01\", \"size\":\"5521.24\", \"side\":\"BUY\", \"hash\":\"0fa07da6cc18dae88b3533331e2bc945f28f34d2\", \"best_bid\":\"0.99\", \"best_ask\":\"1\"}, {\"asset_id\":\"8761897749749422724209054078244794145777693856614463256546737399611489089783\", \"price\":\"0.99\", \"size\":\"5521.24\", \"side\":\"SELL\", \"hash\":\"b5d72a980f92590f95cd7f85a448a389ee682afd\", \"best_bid\":\"0\", \"best_ask\":\"0.01\"}], \"timestamp\":\"1785208482535\", \"event_type\":\"price_change\"}","received_at":"2026-07-28T03:14:42.364248Z","schema_version":"clob-market-ws.price_change.v1","sequence":null,"server_hash":null,"server_timestamp":"1785208482535","session_id":"3e519d9098404c15b234d96025eb1a2b","source":"clob_market_ws"},"received_at":"2026-07-28T03:14:42.364248Z","record_id":"d74a4d6657c6f24451be868a66ace4f22d0ea2859c7d0c0c4371035873487170","schema_fingerprint":"4aa3821a28b0b7c2400bc59aba4bcc0a76e971dadd19610d3ad38c768e124dc7","schema_version":"edge-lab-recorder.raw.v1","sequence":null,"source":"clob_market_ws"}
{"event_at":"2026-07-28T03:14:42.584000Z","event_fingerprint":"30b195fe37f9b771d7df5dc941aacdb7fbffdaed1d6af89c76ec78202f3ad566","payload":{"connection_id":"a6b55582af5f430fb37ad02bf0922475","event_at":"2026-07-28T03:14:42.584000Z","event_type":"price_change","frame_hash":"50358295db0a6044e18f1a19ff1b8e3be20ec50f867b02fe15d3495f1fc261bc","frame_index":0,"kind":"data","monotonic_ns":310465450418375,"payload":{"event_type":"price_change","market":"0x779291bef19b6709f61e9764a954aafe9ffae488d50ae674aabdcb4f248006d5","price_changes":[{"asset_id":"14965588658799411272385430903075831224615961675357217884735713260981483529984","best_ask":"1","best_bid":"0.99","hash":"640f9c25f67c2e5bcf2c5e44cf3c9963da113246","price":"0.01","side":"BUY","size":"5515"},{"asset_id":"8761897749749422724209054078244794145777693856614463256546737399611489089783","best_ask":"0.01","best_bid":"0","hash":"927211f301e5e8e85f8d1bc437fdd2df1406f281","price":"0.99","side":"SELL","size":"5515"}],"timestamp":"1785208482584"},"payload_hash":"e97803b052d7412fc67c3bd5902c4baaa73ffa02eeaae808531804c167800408","raw_frame":"{\"market\":\"0x779291bef19b6709f61e9764a954aafe9ffae488d50ae674aabdcb4f248006d5\", \"price_changes\":[{\"asset_id\":\"14965588658799411272385430903075831224615961675357217884735713260981483529984\", \"price\":\"0.01\", \"size\":\"5515\", \"side\":\"BUY\", \"hash\":\"640f9c25f67c2e5bcf2c5e44cf3c9963da113246\", \"best_bid\":\"0.99\", \"best_ask\":\"1\"}, {\"asset_id\":\"8761897749749422724209054078244794145777693856614463256546737399611489089783\", \"price\":\"0.99\", \"size\":\"5515\", \"side\":\"SELL\", \"hash\":\"927211f301e5e8e85f8d1bc437fdd2df1406f281\", \"best_bid\":\"0\", \"best_ask\":\"0.01\"}], \"timestamp\":\"1785208482584\", \"event_type\":\"price_change\"}","received_at":"2026-07-28T03:14:42.414650Z","schema_version":"clob-market-ws.price_change.v1","sequence":null,"server_hash":null,"server_timestamp":"1785208482584","session_id":"3e519d9098404c15b234d96025eb1a2b","source":"clob_market_ws"},"received_at":"2026-07-28T03:14:42.414650Z","record_id":"908c8392fa598820c4e46858f52ced526532ebebe93829c8dc8178cec824fa8e","schema_fingerprint":"4aa3821a28b0b7c2400bc59aba4bcc0a76e971dadd19610d3ad38c768e124dc7","schema_version":"edge-lab-recorder.raw.v1","sequence":null,"source":"clob_market_ws"}
{"event_at":"2026-07-28T03:14:42.584000Z","event_fingerprint":"d3e3566491c70e6bd23717b8ffa2da4ab6c778d797978450a18867fcce0b2f5c","payload":{"connection_id":"a6b55582af5f430fb37ad02bf0922475","event_at":"2026-07-28T03:14:42.584000Z","event_type":"price_change","frame_hash":"d271658955cca035007d0d39efe167c11ad43f3b9c01decdb16a56a311e5adc6","frame_index":0,"kind":"data","monotonic_ns":310465451996458,"payload":{"event_type":"price_change","market":"0x779291bef19b6709f61e9764a954aafe9ffae488d50ae674aabdcb4f248006d5","price_changes":[{"asset_id":"14965588658799411272385430903075831224615961675357217884735713260981483529984","best_ask":"1","best_bid":"0.99","hash":"640f9c25f67c2e5bcf2c5e44cf3c9963da113246","price":"0.98","side":"BUY","size":"60.61"},{"asset_id":"8761897749749422724209054078244794145777693856614463256546737399611489089783","best_ask":"0.01","best_bid":"0","hash":"927211f301e5e8e85f8d1bc437fdd2df1406f281","price":"0.02","side":"SELL","size":"60.61"}],"timestamp":"1785208482584"},"payload_hash":"bc2459fda44d9652a47a3302e09261e7a377b440c7c739359bebad7fceb84bc3","raw_frame":"{\"market\":\"0x779291bef19b6709f61e9764a954aafe9ffae488d50ae674aabdcb4f248006d5\", \"price_changes\":[{\"asset_id\":\"14965588658799411272385430903075831224615961675357217884735713260981483529984\", \"price\":\"0.98\", \"size\":\"60.61\", \"side\":\"BUY\", \"hash\":\"640f9c25f67c2e5bcf2c5e44cf3c9963da113246\", \"best_bid\":\"0.99\", \"best_ask\":\"1\"}, {\"asset_id\":\"8761897749749422724209054078244794145777693856614463256546737399611489089783\", \"price\":\"0.02\", \"size\":\"60.61\", \"side\":\"SELL\", \"hash\":\"927211f301e5e8e85f8d1bc437fdd2df1406f281\", \"best_bid\":\"0\", \"best_ask\":\"0.01\"}], \"timestamp\":\"1785208482584\", \"event_type\":\"price_change\"}","received_at":"2026-07-28T03:14:42.416225Z","schema_version":"clob-market-ws.price_change.v1","sequence":null,"server_hash":null,"server_timestamp":"1785208482584","session_id":"3e519d9098404c15b234d96025eb1a2b","source":"clob_market_ws"},"received_at":"2026-07-28T03:14:42.416225Z","record_id":"fbfe337adb56d9f01368aed3c2abd37ea50ebf1b92b3e72c7d1181fcb6c38ec6","schema_fingerprint":"4aa3821a28b0b7c2400bc59aba4bcc0a76e971dadd19610d3ad38c768e124dc7","schema_version":"edge-lab-recorder.raw.v1","sequence":null,"source":"clob_market_ws"}
{"event_at":"2026-07-28T03:14:42.584000Z","event_fingerprint":"e0d06977a67e68196c291a3501d4fd142eb2e0e76614bcea189c6f71ddbec7f3","payload":{"connection_id":"a6b55582af5f430fb37ad02bf0922475","event_at":"2026-07-28T03:14:42.584000Z","event_type":"price_change","frame_hash":"f2d2e815b1d79e067cc2431fbef820a69120a4bb561be94e72b76f0c30fdb1d0","frame_index":0,"kind":"data","monotonic_ns":310465453603541,"payload":{"event_type":"price_change","market":"0x779291bef19b6709f61e9764a954aafe9ffae488d50ae674aabdcb4f248006d5","price_changes":[{"asset_id":"8761897749749422724209054078244794145777693856614463256546737399611489089783","best_ask":"0.01","best_bid":"0","hash":"927211f301e5e8e85f8d1bc437fdd2df1406f281","price":"0.02","side":"SELL","size":"60.61"},{"asset_id":"14965588658799411272385430903075831224615961675357217884735713260981483529984","best_ask":"1","best_bid":"0.99","hash":"640f9c25f67c2e5bcf2c5e44cf3c9963da113246","price":"0.98","side":"BUY","size":"60.61"}],"timestamp":"1785208482584"},"payload_hash":"fe484997dd90ee1361c28e579026c93af101eda45b56cb902404bf8696788a57","raw_frame":"{\"market\":\"0x779291bef19b6709f61e9764a954aafe9ffae488d50ae674aabdcb4f248006d5\", \"price_changes\":[{\"asset_id\":\"8761897749749422724209054078244794145777693856614463256546737399611489089783\", \"price\":\"0.02\", \"size\":\"60.61\", \"side\":\"SELL\", \"hash\":\"927211f301e5e8e85f8d1bc437fdd2df1406f281\", \"best_bid\":\"0\", \"best_ask\":\"0.01\"}, {\"asset_id\":\"14965588658799411272385430903075831224615961675357217884735713260981483529984\", \"price\":\"0.98\", \"size\":\"60.61\", \"side\":\"BUY\", \"hash\":\"640f9c25f67c2e5bcf2c5e44cf3c9963da113246\", \"best_bid\":\"0.99\", \"best_ask\":\"1\"}], \"timestamp\":\"1785208482584\", \"event_type\":\"price_change\"}","received_at":"2026-07-28T03:14:42.417835Z","schema_version":"clob-market-ws.price_change.v1","sequence":null,"server_hash":null,"server_timestamp":"1785208482584","session_id":"3e519d9098404c15b234d96025eb1a2b","source":"clob_market_ws"},"received_at":"2026-07-28T03:14:42.417835Z","record_id":"f78f013c0dde47890b33d586af6053f643c1c4e3312fe0f41dd908382668c64a","schema_fingerprint":"4aa3821a28b0b7c2400bc59aba4bcc0a76e971dadd19610d3ad38c768e124dc7","schema_version":"edge-lab-recorder.raw.v1","sequence":null,"source":"clob_market_ws"}
{"event_at":"2026-07-28T03:14:42.590000Z","event_fingerprint":"e74434c9a880f014f68666861bbe241d71685f950b678b0850397473dbc4545e","payload":{"connection_id":"a6b55582af5f430fb37ad02bf0922475","event_at":"2026-07-28T03:14:42.590000Z","event_type":"price_change","frame_hash":"c841b5188363dc9e0bfc96b574a8dca454e60d583a1567fc104ce73047290cfb","frame_index":0,"kind":"data","monotonic_ns":310465456508916,"payload":{"event_type":"price_change","market":"0x779291bef19b6709f61e9764a954aafe9ffae488d50ae674aabdcb4f248006d5","price_changes":[{"asset_id":"14965588658799411272385430903075831224615961675357217884735713260981483529984","best_ask":"1","best_bid":"0.99","hash":"e06bcd30cb25734cbad9b1aa6d426493a5c67849","price":"0.99","side":"BUY","size":"133.16"},{"asset_id":"8761897749749422724209054078244794145777693856614463256546737399611489089783","best_ask":"0.01","best_bid":"0","hash":"91a273c94d8ff344ae491f2491a3d50417abc7e7","price":"0.01","side":"SELL","size":"133.16"}],"timestamp":"1785208482590"},"payload_hash":"22a420d7fcd3388cc87fa01214ae1c3cddb57b377dc8c4c53ed3bd89291df54e","raw_frame":"{\"market\":\"0x779291bef19b6709f61e9764a954aafe9ffae488d50ae674aabdcb4f248006d5\", \"price_changes\":[{\"asset_id\":\"14965588658799411272385430903075831224615961675357217884735713260981483529984\", \"price\":\"0.99\", \"size\":\"133.16\", \"side\":\"BUY\", \"hash\":\"e06bcd30cb25734cbad9b1aa6d426493a5c67849\", \"best_bid\":\"0.99\", \"best_ask\":\"1\"}, {\"asset_id\":\"8761897749749422724209054078244794145777693856614463256546737399611489089783\", \"price\":\"0.01\", \"size\":\"133.16\", \"side\":\"SELL\", \"hash\":\"91a273c94d8ff344ae491f2491a3d50417abc7e7\", \"best_bid\":\"0\", \"best_ask\":\"0.01\"}], \"timestamp\":\"1785208482590\", \"event_type\":\"price_change\"}","received_at":"2026-07-28T03:14:42.420739Z","schema_version":"clob-market-ws.price_change.v1","sequence":null,"server_hash":null,"server_timestamp":"1785208482590","session_id":"3e519d9098404c15b234d96025eb1a2b","source":"clob_market_ws"},"received_at":"2026-07-28T03:14:42.420739Z","record_id":"800eea9b1c67481c2dc7516bcc3564069f9d331344e5614d68f29a32d5d0f099","schema_fingerprint":"4aa3821a28b0b7c2400bc59aba4bcc0a76e971dadd19610d3ad38c768e124dc7","schema_version":"edge-lab-recorder.raw.v1","sequence":null,"source":"clob_market_ws"}
{"event_at":"2026-07-28T03:14:42.599000Z","event_fingerprint":"a50f8b4310044a07e1217cb4a4802c5aea1eee7e9aefa9e48f01747673e40441","payload":{"connection_id":"a6b55582af5f430fb37ad02bf0922475","event_at":"2026-07-28T03:14:42.599000Z","event_type":"price_change","frame_hash":"2f5988ccc4b162a0d5b860c586108a555d9017051226fcd40bc52fecf148d6a0","frame_index":0,"kind":"data","monotonic_ns":310465471954916,"payload":{"event_type":"price_change","market":"0x779291bef19b6709f61e9764a954aafe9ffae488d50ae674aabdcb4f248006d5","price_changes":[{"asset_id":"14965588658799411272385430903075831224615961675357217884735713260981483529984","best_ask":"1","best_bid":"0.99","hash":"859fc56201272165139c2cc9782c1b1ab8c996d5","price":"0.01","side":"BUY","size":"5520"},{"asset_id":"8761897749749422724209054078244794145777693856614463256546737399611489089783","best_ask":"0.01","best_bid":"0","hash":"055f16136a31361349088ed36685d2e56945fe8b","price":"0.99","side":"SELL","size":"5520"}],"timestamp":"1785208482599"},"payload_hash":"8f7a0c30cebd8adfb8d08876646782e41b99e6e7d8f4d9d4df7423ace8999cd9","raw_frame":"{\"market\":\"0x779291bef19b6709f61e9764a954aafe9ffae488d50ae674aabdcb4f248006d5\", \"price_changes\":[{\"asset_id\":\"14965588658799411272385430903075831224615961675357217884735713260981483529984\", \"price\":\"0.01\", \"size\":\"5520\", \"side\":\"BUY\", \"hash\":\"859fc56201272165139c2cc9782c1b1ab8c996d5\", \"best_bid\":\"0.99\", \"best_ask\":\"1\"}, {\"asset_id\":\"8761897749749422724209054078244794145777693856614463256546737399611489089783\", \"price\":\"0.99\", \"size\":\"5520\", \"side\":\"SELL\", \"hash\":\"055f16136a31361349088ed36685d2e56945fe8b\", \"best_bid\":\"0\", \"best_ask\":\"0.01\"}], \"timestamp\":\"1785208482599\", \"event_type\":\"price_change\"}","received_at":"2026-07-28T03:14:42.436185Z","schema_version":"clob-market-ws.price_change.v1","sequence":null,"server_hash":null,"server_timestamp":"1785208482599","session_id":"3e519d9098404c15b234d96025eb1a2b","source":"clob_market_ws"},"received_at":"2026-07-28T03:14:42.436185Z","record_id":"7ef3fc3271e11e8be7b8383c42e0b1ddf86602064669b9b7ddd92906bd760d44","schema_fingerprint":"4aa3821a28b0b7c2400bc59aba4bcc0a76e971dadd19610d3ad38c768e124dc7","schema_version":"edge-lab-recorder.raw.v1","sequence":null,"source":"clob_market_ws"}
{"event_at":"2026-07-28T03:14:42.628000Z","event_fingerprint":"f4a7529f372d5e166d97c6d5035674791406b1e8775fddd60c775bc13fbf4f17","payload":{"connection_id":"a6b55582af5f430fb37ad02bf0922475","event_at":"2026-07-28T03:14:42.628000Z","event_type":"price_change","frame_hash":"e02b966308d7c0c00e0d09270f7f43fe641a186de0b7bf4ab885e631e9a011b5","frame_index":0,"kind":"data","monotonic_ns":310465496381250,"payload":{"event_type":"price_change","market":"0x779291bef19b6709f61e9764a954aafe9ffae488d50ae674aabdcb4f248006d5","price_changes":[{"asset_id":"14965588658799411272385430903075831224615961675357217884735713260981483529984","best_ask":"1","best_bid":"0.99","hash":"c5ec6944c9828fcc38f8a30afe6559e6901e5dcb","price":"0.98","side":"BUY","size":"55.61"},{"asset_id":"8761897749749422724209054078244794145777693856614463256546737399611489089783","best_ask":"0.01","best_bid":"0","hash":"3eb5ed102a25b15427152c7b0ddae32dd0620cd0","price":"0.02","side":"SELL","size":"55.61"}],"timestamp":"1785208482628"},"payload_hash":"9ae7743a2335f40a1b928234f7a4f4ba18af6a04e695fffe5ec9a056b6137a88","raw_frame":"{\"market\":\"0x779291bef19b6709f61e9764a954aafe9ffae488d50ae674aabdcb4f248006d5\", \"price_changes\":[{\"asset_id\":\"14965588658799411272385430903075831224615961675357217884735713260981483529984\", \"price\":\"0.98\", \"size\":\"55.61\", \"side\":\"BUY\", \"hash\":\"c5ec6944c9828fcc38f8a30afe6559e6901e5dcb\", \"best_bid\":\"0.99\", \"best_ask\":\"1\"}, {\"asset_id\":\"8761897749749422724209054078244794145777693856614463256546737399611489089783\", \"price\":\"0.02\", \"size\":\"55.61\", \"side\":\"SELL\", \"hash\":\"3eb5ed102a25b15427152c7b0ddae32dd0620cd0\", \"best_bid\":\"0\", \"best_ask\":\"0.01\"}], \"timestamp\":\"1785208482628\", \"event_type\":\"price_change\"}","received_at":"2026-07-28T03:14:42.460610Z","schema_version":"clob-market-ws.price_change.v1","sequence":null,"server_hash":null,"server_timestamp":"1785208482628","session_id":"3e519d9098404c15b234d96025eb1a2b","source":"clob_market_ws"},"received_at":"2026-07-28T03:14:42.460610Z","record_id":"0848cc24ca31018dd62d8acbaa8d92a8b012310f5392444073cfcf98e245ebd2","schema_fingerprint":"4aa3821a28b0b7c2400bc59aba4bcc0a76e971dadd19610d3ad38c768e124dc7","schema_version":"edge-lab-recorder.raw.v1","sequence":null,"source":"clob_market_ws"}
{"event_at":"2026-07-28T03:14:42.652000Z","event_fingerprint":"f16c89037b424e3eead701acece343acd83f7d4524a933bb4102138b375f518a","payload":{"connection_id":"a6b55582af5f430fb37ad02bf0922475","event_at":"2026-07-28T03:14:42.652000Z","event_type":"price_change","frame_hash":"d725658a93e3787f63bc69e9351134a67626c9f6fadf6e6f4c36d1917bf1467a","frame_index":0,"kind":"data","monotonic_ns":310465518019500,"payload":{"event_type":"price_change","market":"0x779291bef19b6709f61e9764a954aafe9ffae488d50ae674aabdcb4f248006d5","price_changes":[{"asset_id":"14965588658799411272385430903075831224615961675357217884735713260981483529984","best_ask":"1","best_bid":"0.99","hash":"97362b64a962d018471444ac799e3a56ddc7b573","price":"0.01","side":"BUY","size":"5515"},{"asset_id":"8761897749749422724209054078244794145777693856614463256546737399611489089783","best_ask":"0.01","best_bid":"0","hash":"9fbbe92bc20dc3eb80b08a9832ad925abd8aeb60","price":"0.99","side":"SELL","size":"5515"}],"timestamp":"1785208482652"},"payload_hash":"86759572333b25ed9e8d40ba74b166432edf92027eee1fa6293fe8b7ef0b348e","raw_frame":"{\"market\":\"0x779291bef19b6709f61e9764a954aafe9ffae488d50ae674aabdcb4f248006d5\", \"price_changes\":[{\"asset_id\":\"14965588658799411272385430903075831224615961675357217884735713260981483529984\", \"price\":\"0.01\", \"size\":\"5515\", \"side\":\"BUY\", \"hash\":\"97362b64a962d018471444ac799e3a56ddc7b573\", \"best_bid\":\"0.99\", \"best_ask\":\"1\"}, {\"asset_id\":\"8761897749749422724209054078244794145777693856614463256546737399611489089783\", \"price\":\"0.99\", \"size\":\"5515\", \"side\":\"SELL\", \"hash\":\"9fbbe92bc20dc3eb80b08a9832ad925abd8aeb60\", \"best_bid\":\"0\", \"best_ask\":\"0.01\"}], \"timestamp\":\"1785208482652\", \"event_type\":\"price_change\"}","received_at":"2026-07-28T03:14:42.482250Z","schema_version":"clob-market-ws.price_change.v1","sequence":null,"server_hash":null,"server_timestamp":"1785208482652","session_id":"3e519d9098404c15b234d96025eb1a2b","source":"clob_market_ws"},"received_at":"2026-07-28T03:14:42.482250Z","record_id":"5a60d57598f8d144dc61a30c301195f9f2be49c231215d1d0761cfc19d71681b","schema_fingerprint":"4aa3821a28b0b7c2400bc59aba4bcc0a76e971dadd19610d3ad38c768e124dc7","schema_version":"edge-lab-recorder.raw.v1","sequence":null,"source":"clob_market_ws"}
{"event_at":"2026-07-28T03:14:42.675000Z","event_fingerprint":"d2aac80042a6d2b83b20c70608fa017cac0135da5324656d1ed49301c03d3abc","payload":{"connection_id":"a6b55582af5f430fb37ad02bf0922475","event_at":"2026-07-28T03:14:42.675000Z","event_type":"price_change","frame_hash":"779686115670e879f44a220bccdc30406e69f93bbe1c47d407e31b0b62b7c1d1","frame_index":0,"kind":"data","monotonic_ns":310465540750083,"payload":{"event_type":"price_change","market":"0x779291bef19b6709f61e9764a954aafe9ffae488d50ae674aabdcb4f248006d5","price_changes":[{"asset_id":"14965588658799411272385430903075831224615961675357217884735713260981483529984","best_ask":"1","best_bid":"0.99","hash":"69c3f397129dc57ae4f86879a0915b95835813d4","price":"0.99","side":"BUY","size":"138.16"},{"asset_id":"8761897749749422724209054078244794145777693856614463256546737399611489089783","best_ask":"0.01","best_bid":"0","hash":"c1d527ddb438823d86ab7593e187b186013b083f","price":"0.01","side":"SELL","size":"138.16"}],"timestamp":"1785208482675"},"payload_hash":"e17512fb37607e4571829d00955e87b289c7f1b8d38832544c54832e8976444e","raw_frame":"{\"market\":\"0x779291bef19b6709f61e9764a954aafe9ffae488d50ae674aabdcb4f248006d5\", \"price_changes\":[{\"asset_id\":\"14965588658799411272385430903075831224615961675357217884735713260981483529984\", \"price\":\"0.99\", \"size\":\"138.16\", \"side\":\"BUY\", \"hash\":\"69c3f397129dc57ae4f86879a0915b95835813d4\", \"best_bid\":\"0.99\", \"best_ask\":\"1\"}, {\"asset_id\":\"8761897749749422724209054078244794145777693856614463256546737399611489089783\", \"price\":\"0.01\", \"size\":\"138.16\", \"side\":\"SELL\", \"hash\":\"c1d527ddb438823d86ab7593e187b186013b083f\", \"best_bid\":\"0\", \"best_ask\":\"0.01\"}], \"timestamp\":\"1785208482675\", \"event_type\":\"price_change\"}","received_at":"2026-07-28T03:14:42.504977Z","schema_version":"clob-market-ws.price_change.v1","sequence":null,"server_hash":null,"server_timestamp":"1785208482675","session_id":"3e519d9098404c15b234d96025eb1a2b","source":"clob_market_ws"},"received_at":"2026-07-28T03:14:42.504977Z","record_id":"376a24061e8c56151f0475809e63cbe6d1f21e20917bc10a06ed8687b3d987ae","schema_fingerprint":"4aa3821a28b0b7c2400bc59aba4bcc0a76e971dadd19610d3ad38c768e124dc7","schema_version":"edge-lab-recorder.raw.v1","sequence":null,"source":"clob_market_ws"}
{"event_at":"2026-07-28T03:14:42.723000Z","event_fingerprint":"2ef14fbaf3d7eb02a0e545b5ef10fed8ec906d002c96872f20f9a989ff18b159","payload":{"connection_id":"a6b55582af5f430fb37ad02bf0922475","event_at":"2026-07-28T03:14:42.723000Z","event_type":"price_change","frame_hash":"026eee5f4c46697eb33f331fb1a3892b731bd5a00cd7010acebe9c13d66eff06","frame_index":0,"kind":"data","monotonic_ns":310465589044083,"payload":{"event_type":"price_change","market":"0x779291bef19b6709f61e9764a954aafe9ffae488d50ae674aabdcb4f248006d5","price_changes":[{"asset_id":"14965588658799411272385430903075831224615961675357217884735713260981483529984","best_ask":"1","best_bid":"0.99","hash":"bd23f6cb1119809196356409b4c058ea8bf9fad5","price":"0.99","side":"BUY","size":"111"},{"asset_id":"8761897749749422724209054078244794145777693856614463256546737399611489089783","best_ask":"0.01","best_bid":"0","hash":"63c2e1ff79ce3a1effbf71e54633ebb857641d39","price":"0.01","side":"SELL","size":"111"}],"timestamp":"1785208482723"},"payload_hash":"0180fa5c4c80637877800bfb14fd47f8ea507d1023c0698f0f1d8e56a068a333","raw_frame":"{\"market\":\"0x779291bef19b6709f61e9764a954aafe9ffae488d50ae674aabdcb4f248006d5\", \"price_changes\":[{\"asset_id\":\"14965588658799411272385430903075831224615961675357217884735713260981483529984\", \"price\":\"0.99\", \"size\":\"111\", \"side\":\"BUY\", \"hash\":\"bd23f6cb1119809196356409b4c058ea8bf9fad5\", \"best_bid\":\"0.99\", \"best_ask\":\"1\"}, {\"asset_id\":\"8761897749749422724209054078244794145777693856614463256546737399611489089783\", \"price\":\"0.01\", \"size\":\"111\", \"side\":\"SELL\", \"hash\":\"63c2e1ff79ce3a1effbf71e54633ebb857641d39\", \"best_bid\":\"0\", \"best_ask\":\"0.01\"}], \"timestamp\":\"1785208482723\", \"event_type\":\"price_change\"}","received_at":"2026-07-28T03:14:42.553265Z","schema_version":"clob-market-ws.price_change.v1","sequence":null,"server_hash":null,"server_timestamp":"1785208482723","session_id":"3e519d9098404c15b234d96025eb1a2b","source":"clob_market_ws"},"received_at":"2026-07-28T03:14:42.553265Z","record_id":"6db1d17cb275c04fd181e5caac551d1942b0a0c4d7e1a9d8ba171e2bba240541","schema_fingerprint":"4aa3821a28b0b7c2400bc59aba4bcc0a76e971dadd19610d3ad38c768e124dc7","schema_version":"edge-lab-recorder.raw.v1","sequence":null,"source":"clob_market_ws"}
{"event_at":"2026-07-28T03:14:42.727000Z","event_fingerprint":"67cbd066c90091f305c1f8e11d98c0ee17afed110dc2cba8d579d1395c03e2c0","payload":{"connection_id":"a6b55582af5f430fb37ad02bf0922475","event_at":"2026-07-28T03:14:42.727000Z","event_type":"price_change","frame_hash":"274202a7e80d12614060af08385cd64f8dee11ed926c88dc2baaa5875cbbbf1c","frame_index":0,"kind":"data","monotonic_ns":310465594186916,"payload":{"event_type":"price_change","market":"0x779291bef19b6709f61e9764a954aafe9ffae488d50ae674aabdcb4f248006d5","price_changes":[{"asset_id":"14965588658799411272385430903075831224615961675357217884735713260981483529984","best_ask":"1","best_bid":"0.99","hash":"8a43776a46ac9b4e18e287bb657924e1370a452a","price":"0.01","side":"BUY","size":"5521.24"},{"asset_id":"8761897749749422724209054078244794145777693856614463256546737399611489089783","best_ask":"0.01","best_bid":"0","hash":"73789ae49c3f8d2a72a29fa7f7af6a9a12d6f103","price":"0.99","side":"SELL","size":"5521.24"}],"timestamp":"1785208482727"},"payload_hash":"9f4a577e5c648ba236ed78a5dff2cec7f099bfecb35e2e05402aeb42dbce536e","raw_frame":"{\"market\":\"0x779291bef19b6709f61e9764a954aafe9ffae488d50ae674aabdcb4f248006d5\", \"price_changes\":[{\"asset_id\":\"14965588658799411272385430903075831224615961675357217884735713260981483529984\", \"price\":\"0.01\", \"size\":\"5521.24\", \"side\":\"BUY\", \"hash\":\"8a43776a46ac9b4e18e287bb657924e1370a452a\", \"best_bid\":\"0.99\", \"best_ask\":\"1\"}, {\"asset_id\":\"8761897749749422724209054078244794145777693856614463256546737399611489089783\", \"price\":\"0.99\", \"size\":\"5521.24\", \"side\":\"SELL\", \"hash\":\"73789ae49c3f8d2a72a29fa7f7af6a9a12d6f103\", \"best_bid\":\"0\", \"best_ask\":\"0.01\"}], \"timestamp\":\"1785208482727\", \"event_type\":\"price_change\"}","received_at":"2026-07-28T03:14:42.558414Z","schema_version":"clob-market-ws.price_change.v1","sequence":null,"server_hash":null,"server_timestamp":"1785208482727","session_id":"3e519d9098404c15b234d96025eb1a2b","source":"clob_market_ws"},"received_at":"2026-07-28T03:14:42.558414Z","record_id":"bcbe8dc4f039da3d4055719dc1eedf01117cf929bef0fcfe4a306fd8646c8e04","schema_fingerprint":"4aa3821a28b0b7c2400bc59aba4bcc0a76e971dadd19610d3ad38c768e124dc7","schema_version":"edge-lab-recorder.raw.v1","sequence":null,"source":"clob_market_ws"}
{"event_at":"2026-07-28T03:14:42.727000Z","event_fingerprint":"7fea147e6038b8e163db1b6d7a38ae45deb49b70a889817403470221b7e97bd4","payload":{"connection_id":"a6b55582af5f430fb37ad02bf0922475","event_at":"2026-07-28T03:14:42.727000Z","event_type":"price_change","frame_hash":"3b12025e46954e5fed2da494962c4f4346aacdc84b845718a1ce24dc6cf2894a","frame_index":0,"kind":"data","monotonic_ns":310465595826791,"payload":{"event_type":"price_change","market":"0x779291bef19b6709f61e9764a954aafe9ffae488d50ae674aabdcb4f248006d5","price_changes":[{"asset_id":"8761897749749422724209054078244794145777693856614463256546737399611489089783","best_ask":"0.01","best_bid":"0","hash":"e23290fcf25621f3b7d34fbae38305f413459594","price":"0.02","side":"SELL","size":"66.22"},{"asset_id":"14965588658799411272385430903075831224615961675357217884735713260981483529984","best_ask":"1","best_bid":"0.99","hash":"2b49cf25d8c006b919c52e4bc3f0d0793704a8e6","price":"0.98","side":"BUY","size":"66.22"}],"timestamp":"1785208482727"},"payload_hash":"b4a95846a51acf2eb1ebc2e147e79700aa9f35596b3927081f9c33b1176a459c","raw_frame":"{\"market\":\"0x779291bef19b6709f61e9764a954aafe9ffae488d50ae674aabdcb4f248006d5\", \"price_changes\":[{\"asset_id\":\"8761897749749422724209054078244794145777693856614463256546737399611489089783\", \"price\":\"0.02\", \"size\":\"66.22\", \"side\":\"SELL\", \"hash\":\"e23290fcf25621f3b7d34fbae38305f413459594\", \"best_bid\":\"0\", \"best_ask\":\"0.01\"}, {\"asset_id\":\"14965588658799411272385430903075831224615961675357217884735713260981483529984\", \"price\":\"0.98\", \"size\":\"66.22\", \"side\":\"BUY\", \"hash\":\"2b49cf25d8c006b919c52e4bc3f0d0793704a8e6\", \"best_bid\":\"0.99\", \"best_ask\":\"1\"}], \"timestamp\":\"1785208482727\", \"event_type\":\"price_change\"}","received_at":"2026-07-28T03:14:42.560054Z","schema_version":"clob-market-ws.price_change.v1","sequence":null,"server_hash":null,"server_timestamp":"1785208482727","session_id":"3e519d9098404c15b234d96025eb1a2b","source":"clob_market_ws"},"received_at":"2026-07-28T03:14:42.560054Z","record_id":"63b7aeb97ad7bd4a8b54391d873d229af793882b49d1d0c8cd06ac6e6b93f040","schema_fingerprint":"4aa3821a28b0b7c2400bc59aba4bcc0a76e971dadd19610d3ad38c768e124dc7","schema_version":"edge-lab-recorder.raw.v1","sequence":null,"source":"clob_market_ws"}
{"event_at":"2026-07-28T03:14:42.728000Z","event_fingerprint":"6681027f2e687bca6b162e1ec2304e2690ea550e3b36fc3135a10cfcc20457d1","payload":{"connection_id":"a6b55582af5f430fb37ad02bf0922475","event_at":"2026-07-28T03:14:42.728000Z","event_type":"price_change","frame_hash":"cccfb6ab56e8239d69a7f92222d6c2fe0da8443bd65887e8db2886d2888f53d9","frame_index":0,"kind":"data","monotonic_ns":310465597510833,"payload":{"event_type":"price_change","market":"0x779291bef19b6709f61e9764a954aafe9ffae488d50ae674aabdcb4f248006d5","price_changes":[{"asset_id":"14965588658799411272385430903075831224615961675357217884735713260981483529984","best_ask":"1","best_bid":"0.99","hash":"cd05df9b6dececc4c473ece42650225c1af6baae","price":"0.98","side":"BUY","size":"93.6"},{"asset_id":"8761897749749422724209054078244794145777693856614463256546737399611489089783","best_ask":"0.01","best_bid":"0","hash":"b0e5f67bfdba9a281ffd9efa5b9623f051385ed9","price":"0.02","side":"SELL","size":"93.6"}],"timestamp":"1785208482728"},"payload_hash":"e2fcaddf227cc044ef2c3c0302c5fdc7dc8a04214e6b2c9af527c636c3f2a235","raw_frame":"{\"market\":\"0x779291bef19b6709f61e9764a954aafe9ffae488d50ae674aabdcb4f248006d5\", \"price_changes\":[{\"asset_id\":\"14965588658799411272385430903075831224615961675357217884735713260981483529984\", \"price\":\"0.98\", \"size\":\"93.6\", \"side\":\"BUY\", \"hash\":\"cd05df9b6dececc4c473ece42650225c1af6baae\", \"best_bid\":\"0.99\", \"best_ask\":\"1\"}, {\"asset_id\":\"8761897749749422724209054078244794145777693856614463256546737399611489089783\", \"price\":\"0.02\", \"size\":\"93.6\", \"side\":\"SELL\", \"hash\":\"b0e5f67bfdba9a281ffd9efa5b9623f051385ed9\", \"best_bid\":\"0\", \"best_ask\":\"0.01\"}], \"timestamp\":\"1785208482728\", \"event_type\":\"price_change\"}","received_at":"2026-07-28T03:14:42.561738Z","schema_version":"clob-market-ws.price_change.v1","sequence":null,"server_hash":null,"server_timestamp":"1785208482728","session_id":"3e519d9098404c15b234d96025eb1a2b","source":"clob_market_ws"},"received_at":"2026-07-28T03:14:42.561738Z","record_id":"4f531feb116a3f7b23feeebc021e0b128070d0d1102725e60e4bcffb78431db7","schema_fingerprint":"4aa3821a28b0b7c2400bc59aba4bcc0a76e971dadd19610d3ad38c768e124dc7","schema_version":"edge-lab-recorder.raw.v1","sequence":null,"source":"clob_market_ws"}
{"event_at":"2026-07-28T03:14:42.728000Z","event_fingerprint":"0058ff9d4e462066acc193a897d1cc4c202a9b3720fc31dd35775ecf3a15a078","payload":{"connection_id":"a6b55582af5f430fb37ad02bf0922475","event_at":"2026-07-28T03:14:42.728000Z","event_type":"price_change","frame_hash":"8d89d9bf15db124053bb53a2804f9b8de3cf04cbba4c522ec9cf5a04197a7020","frame_index":0,"kind":"data","monotonic_ns":310465599159166,"payload":{"event_type":"price_change","market":"0x779291bef19b6709f61e9764a954aafe9ffae488d50ae674aabdcb4f248006d5","price_changes":[{"asset_id":"8761897749749422724209054078244794145777693856614463256546737399611489089783","best_ask":"0.01","best_bid":"0","hash":"8b36f4257587538576e48b9756ddc55a5c1293b0","price":"0.01","side":"SELL","size":"148"},{"asset_id":"14965588658799411272385430903075831224615961675357217884735713260981483529984","best_ask":"1","best_bid":"0.99","hash":"4c9c638f72f6be0b6447af214df6303faa201c6c","price":"0.99","side":"BUY","size":"148"}],"timestamp":"1785208482728"},"payload_hash":"ca89026d9857f8fc97965be52a175c5c2f936a65d1bf0ad3d34bacc561823dff","raw_frame":"{\"market\":\"0x779291bef19b6709f61e9764a954aafe9ffae488d50ae674aabdcb4f248006d5\", \"price_changes\":[{\"asset_id\":\"8761897749749422724209054078244794145777693856614463256546737399611489089783\", \"price\":\"0.01\", \"size\":\"148\", \"side\":\"SELL\", \"hash\":\"8b36f4257587538576e48b9756ddc55a5c1293b0\", \"best_bid\":\"0\", \"best_ask\":\"0.01\"}, {\"asset_id\":\"14965588658799411272385430903075831224615961675357217884735713260981483529984\", \"price\":\"0.99\", \"size\":\"148\", \"side\":\"BUY\", \"hash\":\"4c9c638f72f6be0b6447af214df6303faa201c6c\", \"best_bid\":\"0.99\", \"best_ask\":\"1\"}], \"timestamp\":\"1785208482728\", \"event_type\":\"price_change\"}","received_at":"2026-07-28T03:14:42.563390Z","schema_version":"clob-market-ws.price_change.v1","sequence":null,"server_hash":null,"server_timestamp":"1785208482728","session_id":"3e519d9098404c15b234d96025eb1a2b","source":"clob_market_ws"},"received_at":"2026-07-28T03:14:42.563390Z","record_id":"141ef662d15a75c506c41fcdc8b682f1176d705811077ac537ced5cdf5edc865","schema_fingerprint":"4aa3821a28b0b7c2400bc59aba4bcc0a76e971dadd19610d3ad38c768e124dc7","schema_version":"edge-lab-recorder.raw.v1","sequence":null,"source":"clob_market_ws"}
{"event_at":"2026-07-28T03:14:42.747000Z","event_fingerprint":"d00613b3315ed60e9de7099878be4acff249123dafada18b2e4338069500ea50","payload":{"connection_id":"a6b55582af5f430fb37ad02bf0922475","event_at":"2026-07-28T03:14:42.747000Z","event_type":"price_change","frame_hash":"f5d6a32bcc8430b457c54be9e2fdc081ed645d92885eaa3f8b8b038302b9ae4a","frame_index":0,"kind":"data","monotonic_ns":310465614950458,"payload":{"event_type":"price_change","market":"0x779291bef19b6709f61e9764a954aafe9ffae488d50ae674aabdcb4f248006d5","price_changes":[{"asset_id":"14965588658799411272385430903075831224615961675357217884735713260981483529984","best_ask":"1","best_bid":"0.99","hash":"3df3f6949984ea933578425093963aef11097b8f","price":"0.02","side":"BUY","size":"530"},{"asset_id":"8761897749749422724209054078244794145777693856614463256546737399611489089783","best_ask":"0.01","best_bid":"0","hash":"38f72181af218ae08363e2f8bed439a854a62df5","price":"0.98","side":"SELL","size":"530"}],"timestamp":"1785208482747"},"payload_hash":"e6f2f72507294ed989ea8f9ab5ba6b93cd4ae79d5454c40be0af06a2dce6602e","raw_frame":"{\"market\":\"0x779291bef19b6709f61e9764a954aafe9ffae488d50ae674aabdcb4f248006d5\", \"price_changes\":[{\"asset_id\":\"14965588658799411272385430903075831224615961675357217884735713260981483529984\", \"price\":\"0.02\", \"size\":\"530\", \"side\":\"BUY\", \"hash\":\"3df3f6949984ea933578425093963aef11097b8f\", \"best_bid\":\"0.99\", \"best_ask\":\"1\"}, {\"asset_id\":\"8761897749749422724209054078244794145777693856614463256546737399611489089783\", \"price\":\"0.98\", \"size\":\"530\", \"side\":\"SELL\", \"hash\":\"38f72181af218ae08363e2f8bed439a854a62df5\", \"best_bid\":\"0\", \"best_ask\":\"0.01\"}], \"timestamp\":\"1785208482747\", \"event_type\":\"price_change\"}","received_at":"2026-07-28T03:14:42.579179Z","schema_version":"clob-market-ws.price_change.v1","sequence":null,"server_hash":null,"server_timestamp":"1785208482747","session_id":"3e519d9098404c15b234d96025eb1a2b","source":"clob_market_ws"},"received_at":"2026-07-28T03:14:42.579179Z","record_id":"3665511670784e23009962b84389c072b82a457f32a15b829d59549c932f8e08","schema_fingerprint":"4aa3821a28b0b7c2400bc59aba4bcc0a76e971dadd19610d3ad38c768e124dc7","schema_version":"edge-lab-recorder.raw.v1","sequence":null,"source":"clob_market_ws"}
{"event_at":"2026-07-28T03:14:42.755000Z","event_fingerprint":"2c21d295ccfee61ecff0ff8b7c055f8482780be487c1838f1d558b8c620544bd","payload":{"connection_id":"a6b55582af5f430fb37ad02bf0922475","event_at":"2026-07-28T03:14:42.755000Z","event_type":"price_change","frame_hash":"8bac1e91d3b20369a29d8add4ec102ee3dbe1cbb0939f69adf4c923a730c5024","frame_index":0,"kind":"data","monotonic_ns":310465620433000,"payload":{"event_type":"price_change","market":"0x779291bef19b6709f61e9764a954aafe9ffae488d50ae674aabdcb4f248006d5","price_changes":[{"asset_id":"14965588658799411272385430903075831224615961675357217884735713260981483529984","best_ask":"1","best_bid":"0.99","hash":"d9d1dbd3861e0f01833bff4abd2ae125b1de05e2","price":"0.95","side":"BUY","size":"125"},{"asset_id":"8761897749749422724209054078244794145777693856614463256546737399611489089783","best_ask":"0.01","best_bid":"0","hash":"e657a6c1ffafde3cc3db35fd08c1826974ecc82e","price":"0.05","side":"SELL","size":"125"}],"timestamp":"1785208482755"},"payload_hash":"3e031b0de3e34e3b12ab118c6cdaf419d49037e1c4666ac0f1b19ce2d96c927f","raw_frame":"{\"market\":\"0x779291bef19b6709f61e9764a954aafe9ffae488d50ae674aabdcb4f248006d5\", \"price_changes\":[{\"asset_id\":\"14965588658799411272385430903075831224615961675357217884735713260981483529984\", \"price\":\"0.95\", \"size\":\"125\", \"side\":\"BUY\", \"hash\":\"d9d1dbd3861e0f01833bff4abd2ae125b1de05e2\", \"best_bid\":\"0.99\", \"best_ask\":\"1\"}, {\"asset_id\":\"8761897749749422724209054078244794145777693856614463256546737399611489089783\", \"price\":\"0.05\", \"size\":\"125\", \"side\":\"SELL\", \"hash\":\"e657a6c1ffafde3cc3db35fd08c1826974ecc82e\", \"best_bid\":\"0\", \"best_ask\":\"0.01\"}], \"timestamp\":\"1785208482755\", \"event_type\":\"price_change\"}","received_at":"2026-07-28T03:14:42.584661Z","schema_version":"clob-market-ws.price_change.v1","sequence":null,"server_hash":null,"server_timestamp":"1785208482755","session_id":"3e519d9098404c15b234d96025eb1a2b","source":"clob_market_ws"},"received_at":"2026-07-28T03:14:42.584661Z","record_id":"e20083f7b54d347e9d181571a2786791cd364fe433a6d09f1ff20ca1b2dee83e","schema_fingerprint":"4aa3821a28b0b7c2400bc59aba4bcc0a76e971dadd19610d3ad38c768e124dc7","schema_version":"edge-lab-recorder.raw.v1","sequence":null,"source":"clob_market_ws"}
{"event_at":"2026-07-28T03:14:42.755000Z","event_fingerprint":"f41501f18b448bb19b099c0e73a6a7bc769348a0bd798ce35f50c7d21dc61f32","payload":{"connection_id":"a6b55582af5f430fb37ad02bf0922475","event_at":"2026-07-28T03:14:42.755000Z","event_type":"price_change","frame_hash":"d44c6a73aede0d50114c28cb12184650065efdee67d9e2057ac90b5cea186a6c","frame_index":0,"kind":"data","monotonic_ns":310465622024458,"payload":{"event_type":"price_change","market":"0x779291bef19b6709f61e9764a954aafe9ffae488d50ae674aabdcb4f248006d5","price_changes":[{"asset_id":"14965588658799411272385430903075831224615961675357217884735713260981483529984","best_ask":"1","best_bid":"0.99","hash":"1040616809a070e5c7948e4d079febb44247aaf0","price":"0.95","side":"BUY","size":"105"},{"asset_id":"8761897749749422724209054078244794145777693856614463256546737399611489089783","best_ask":"0.01","best_bid":"0","hash":"d2275765732b47dd584b6f7a3630eba13cb9a79f","price":"0.05","side":"SELL","size":"105"}],"timestamp":"1785208482755"},"payload_hash":"f33914dd6139ccb4c97153622678588c48afa375ce625079e08bb7f56dc5e8b8","raw_frame":"{\"market\":\"0x779291bef19b6709f61e9764a954aafe9ffae488d50ae674aabdcb4f248006d5\", \"price_changes\":[{\"asset_id\":\"14965588658799411272385430903075831224615961675357217884735713260981483529984\", \"price\":\"0.95\", \"size\":\"105\", \"side\":\"BUY\", \"hash\":\"1040616809a070e5c7948e4d079febb44247aaf0\", \"best_bid\":\"0.99\", \"best_ask\":\"1\"}, {\"asset_id\":\"8761897749749422724209054078244794145777693856614463256546737399611489089783\", \"price\":\"0.05\", \"size\":\"105\", \"side\":\"SELL\", \"hash\":\"d2275765732b47dd584b6f7a3630eba13cb9a79f\", \"best_bid\":\"0\", \"best_ask\":\"0.01\"}], \"timestamp\":\"1785208482755\", \"event_type\":\"price_change\"}","received_at":"2026-07-28T03:14:42.586254Z","schema_version":"clob-market-ws.price_change.v1","sequence":null,"server_hash":null,"server_timestamp":"1785208482755","session_id":"3e519d9098404c15b234d96025eb1a2b","source":"clob_market_ws"},"received_at":"2026-07-28T03:14:42.586254Z","record_id":"1292526dc1618a729e4e7667b6be5f72ac8aaeb15f2fbd9d7dfd3b314a4efbc5","schema_fingerprint":"4aa3821a28b0b7c2400bc59aba4bcc0a76e971dadd19610d3ad38c768e124dc7","schema_version":"edge-lab-recorder.raw.v1","sequence":null,"source":"clob_market_ws"}
{"event_at":"2026-07-28T03:14:42.855000Z","event_fingerprint":"97be67bc003fd35bf28cd2a040031983fc2d87359d8678c5e8f4f812a35412b0","payload":{"connection_id":"a6b55582af5f430fb37ad02bf0922475","event_at":"2026-07-28T03:14:42.855000Z","event_type":"price_change","frame_hash":"220f80e7316aa82dc753f499aefd5991945cb8e039620bb7624dfed995345c3b","frame_index":0,"kind":"data","monotonic_ns":310465722786333,"payload":{"event_type":"price_change","market":"0x779291bef19b6709f61e9764a954aafe9ffae488d50ae674aabdcb4f248006d5","price_changes":[{"asset_id":"14965588658799411272385430903075831224615961675357217884735713260981483529984","best_ask":"1","best_bid":"0.99","hash":"0f678a2d0d951e285300bf4bb1e4907d58295f56","price":"0.01","side":"BUY","size":"5526.24"},{"asset_id":"8761897749749422724209054078244794145777693856614463256546737399611489089783","best_ask":"0.01","best_bid":"0","hash":"44090f55624d00051d2dfd470b2eee0ce4ac1bfc","price":"0.99","side":"SELL","size":"5526.24"}],"timestamp":"1785208482855"},"payload_hash":"8ca454fdf98f6e740b28da8671f98f9e10087d701f99f4b05ae47a021e9f8d7b","raw_frame":"{\"market\":\"0x779291bef19b6709f61e9764a954aafe9ffae488d50ae674aabdcb4f248006d5\", \"price_changes\":[{\"asset_id\":\"14965588658799411272385430903075831224615961675357217884735713260981483529984\", \"price\":\"0.01\", \"size\":\"5526.24\", \"side\":\"BUY\", \"hash\":\"0f678a2d0d951e285300bf4bb1e4907d58295f56\", \"best_bid\":\"0.99\", \"best_ask\":\"1\"}, {\"asset_id\":\"8761897749749422724209054078244794145777693856614463256546737399611489089783\", \"price\":\"0.99\", \"size\":\"5526.24\", \"side\":\"SELL\", \"hash\":\"44090f55624d00051d2dfd470b2eee0ce4ac1bfc\", \"best_bid\":\"0\", \"best_ask\":\"0.01\"}], \"timestamp\":\"1785208482855\", \"event_type\":\"price_change\"}","received_at":"2026-07-28T03:14:42.687004Z","schema_version":"clob-market-ws.price_change.v1","sequence":null,"server_hash":null,"server_timestamp":"1785208482855","session_id":"3e519d9098404c15b234d96025eb1a2b","source":"clob_market_ws"},"received_at":"2026-07-28T03:14:42.687004Z","record_id":"38e7022e71ea57d2b7ae781f70398f51d87e0e99068e0c090e753866717ce028","schema_fingerprint":"4aa3821a28b0b7c2400bc59aba4bcc0a76e971dadd19610d3ad38c768e124dc7","schema_version":"edge-lab-recorder.raw.v1","sequence":null,"source":"clob_market_ws"}
{"event_at":"2026-07-28T03:14:42.874000Z","event_fingerprint":"d33520924469c4d8f2ff6c2bc85ad5786428550018987aa5f13bb547b5c184a5","payload":{"connection_id":"a6b55582af5f430fb37ad02bf0922475","event_at":"2026-07-28T03:14:42.874000Z","event_type":"price_change","frame_hash":"cf1e6410e169ff34b401d9b64884f5ff6ad6e3b51373544ec0aa643f978cd074","frame_index":0,"kind":"data","monotonic_ns":310465739802458,"payload":{"event_type":"price_change","market":"0x779291bef19b6709f61e9764a954aafe9ffae488d50ae674aabdcb4f248006d5","price_changes":[{"asset_id":"14965588658799411272385430903075831224615961675357217884735713260981483529984","best_ask":"1","best_bid":"0.99","hash":"ba1aea8b41c194742b5578da94a7dacede4fa865","price":"0.01","side":"BUY","size":"5521.24"},{"asset_id":"8761897749749422724209054078244794145777693856614463256546737399611489089783","best_ask":"0.01","best_bid":"0","hash":"737a3faae33778df942ada31e6f29683457568bd","price":"0.99","side":"SELL","size":"5521.24"}],"timestamp":"1785208482874"},"payload_hash":"fc6cd4c81876942f40dc595ec01f76da8efc21f2b21fd2e516ba764f07b8158f","raw_frame":"{\"market\":\"0x779291bef19b6709f61e9764a954aafe9ffae488d50ae674aabdcb4f248006d5\", \"price_changes\":[{\"asset_id\":\"14965588658799411272385430903075831224615961675357217884735713260981483529984\", \"price\":\"0.01\", \"size\":\"5521.24\", \"side\":\"BUY\", \"hash\":\"ba1aea8b41c194742b5578da94a7dacede4fa865\", \"best_bid\":\"0.99\", \"best_ask\":\"1\"}, {\"asset_id\":\"8761897749749422724209054078244794145777693856614463256546737399611489089783\", \"price\":\"0.99\", \"size\":\"5521.24\", \"side\":\"SELL\", \"hash\":\"737a3faae33778df942ada31e6f29683457568bd\", \"best_bid\":\"0\", \"best_ask\":\"0.01\"}], \"timestamp\":\"1785208482874\", \"event_type\":\"price_change\"}","received_at":"2026-07-28T03:14:42.704029Z","schema_version":"clob-market-ws.price_change.v1","sequence":null,"server_hash":null,"server_timestamp":"1785208482874","session_id":"3e519d9098404c15b234d96025eb1a2b","source":"clob_market_ws"},"received_at":"2026-07-28T03:14:42.704029Z","record_id":"32157d3dd306acdf975203e592d6944428067059d9dfef0f7a198580987e7b6b","schema_fingerprint":"4aa3821a28b0b7c2400bc59aba4bcc0a76e971dadd19610d3ad38c768e124dc7","schema_version":"edge-lab-recorder.raw.v1","sequence":null,"source":"clob_market_ws"}
{"event_at":"2026-07-28T03:14:42.878000Z","event_fingerprint":"591af7fcba01b94fc92533304b45eadaf3861e19e1916f8853358169e453a82d","payload":{"connection_id":"a6b55582af5f430fb37ad02bf0922475","event_at":"2026-07-28T03:14:42.878000Z","event_type":"price_change","frame_hash":"526179ac4eb4aa1374cabc26d0b9f23e94001877c3533ade1fb49cc60582f293","frame_index":0,"kind":"data","monotonic_ns":310465745600333,"payload":{"event_type":"price_change","market":"0x779291bef19b6709f61e9764a954aafe9ffae488d50ae674aabdcb4f248006d5","price_changes":[{"asset_id":"14965588658799411272385430903075831224615961675357217884735713260981483529984","best_ask":"1","best_bid":"0.99","hash":"7dbe001ad4d3c32ac00b074ff5a46f3d22ad26ab","price":"0.01","side":"BUY","size":"5515"},{"asset_id":"8761897749749422724209054078244794145777693856614463256546737399611489089783","best_ask":"0.01","best_bid":"0","hash":"5df32faf994aa5099a3dbb30b4a9a3ada770efaa","price":"0.99","side":"SELL","size":"5515"}],"timestamp":"1785208482878"},"payload_hash":"994da7a0da7b0b283082f19efa8f0d4d9806fc0355682450b3a0b9ba8a101c8e","raw_frame":"{\"market\":\"0x779291bef19b6709f61e9764a954aafe9ffae488d50ae674aabdcb4f248006d5\", \"price_changes\":[{\"asset_id\":\"14965588658799411272385430903075831224615961675357217884735713260981483529984\", \"price\":\"0.01\", \"size\":\"5515\", \"side\":\"BUY\", \"hash\":\"7dbe001ad4d3c32ac00b074ff5a46f3d22ad26ab\", \"best_bid\":\"0.99\", \"best_ask\":\"1\"}, {\"asset_id\":\"8761897749749422724209054078244794145777693856614463256546737399611489089783\", \"price\":\"0.99\", \"size\":\"5515\", \"side\":\"SELL\", \"hash\":\"5df32faf994aa5099a3dbb30b4a9a3ada770efaa\", \"best_bid\":\"0\", \"best_ask\":\"0.01\"}], \"timestamp\":\"1785208482878\", \"event_type\":\"price_change\"}","received_at":"2026-07-28T03:14:42.709828Z","schema_version":"clob-market-ws.price_change.v1","sequence":null,"server_hash":null,"server_timestamp":"1785208482878","session_id":"3e519d9098404c15b234d96025eb1a2b","source":"clob_market_ws"},"received_at":"2026-07-28T03:14:42.709828Z","record_id":"07cb30fe897d195b0dacd5b4d9f9f4e2ce5fead9de76aee5d9ade539d4d6729f","schema_fingerprint":"4aa3821a28b0b7c2400bc59aba4bcc0a76e971dadd19610d3ad38c768e124dc7","schema_version":"edge-lab-recorder.raw.v1","sequence":null,"source":"clob_market_ws"}
{"event_at":"2026-07-28T03:14:42.878000Z","event_fingerprint":"bb7e2e42fd6e328d6e257c830a7121e4b3a7ff1bd63ce0d35f94aedbfb93d194","payload":{"connection_id":"a6b55582af5f430fb37ad02bf0922475","event_at":"2026-07-28T03:14:42.878000Z","event_type":"price_change","frame_hash":"8698472f941e8a84d28aa011b5791929cbae8c0c6ceb9a9b9ce64ca56b26f287","frame_index":0,"kind":"data","monotonic_ns":310465747200000,"payload":{"event_type":"price_change","market":"0x779291bef19b6709f61e9764a954aafe9ffae488d50ae674aabdcb4f248006d5","price_changes":[{"asset_id":"8761897749749422724209054078244794145777693856614463256546737399611489089783","best_ask":"0.01","best_bid":"0","hash":"5df32faf994aa5099a3dbb30b4a9a3ada770efaa","price":"0.02","side":"SELL","size":"55.61"},{"asset_id":"14965588658799411272385430903075831224615961675357217884735713260981483529984","best_ask":"1","best_bid":"0.99","hash":"7dbe001ad4d3c32ac00b074ff5a46f3d22ad26ab","price":"0.98","side":"BUY","size":"55.61"}],"timestamp":"1785208482878"},"payload_hash":"f4f74d9e21a5a7bdae98eb785adb56de47e3fb78c270191fbbda6cfa1563ccd8","raw_frame":"{\"market\":\"0x779291bef19b6709f61e9764a954aafe9ffae488d50ae674aabdcb4f248006d5\", \"price_changes\":[{\"asset_id\":\"8761897749749422724209054078244794145777693856614463256546737399611489089783\", \"price\":\"0.02\", \"size\":\"55.61\", \"side\":\"SELL\", \"hash\":\"5df32faf994aa5099a3dbb30b4a9a3ada770efaa\", \"best_bid\":\"0\", \"best_ask\":\"0.01\"}, {\"asset_id\":\"14965588658799411272385430903075831224615961675357217884735713260981483529984\", \"price\":\"0.98\", \"size\":\"55.61\", \"side\":\"BUY\", \"hash\":\"7dbe001ad4d3c32ac00b074ff5a46f3d22ad26ab\", \"best_bid\":\"0.99\", \"best_ask\":\"1\"}], \"timestamp\":\"1785208482878\", \"event_type\":\"price_change\"}","received_at":"2026-07-28T03:14:42.711417Z","schema_version":"clob-market-ws.price_change.v1","sequence":null,"server_hash":null,"server_timestamp":"1785208482878","session_id":"3e519d9098404c15b234d96025eb1a2b","source":"clob_market_ws"},"received_at":"2026-07-28T03:14:42.711417Z","record_id":"a9b023d398d2a3a1f881f8076c002875888eb04e1f7a29a84ce3f5ba0d27f90e","schema_fingerprint":"4aa3821a28b0b7c2400bc59aba4bcc0a76e971dadd19610d3ad38c768e124dc7","schema_version":"edge-lab-recorder.raw.v1","sequence":null,"source":"clob_market_ws"}
{"event_at":"2026-07-28T03:14:42.878000Z","event_fingerprint":"881fe8bda689367ba5c0bc39640f5e9dba84027635fd67f453756d0967304021","payload":{"connection_id":"a6b55582af5f430fb37ad02bf0922475","event_at":"2026-07-28T03:14:42.878000Z","event_type":"price_change","frame_hash":"c25804bfbd250d130c5dba6fe909988cbb9fabc5762990d4fb8b94cd08ea8036","frame_index":0,"kind":"data","monotonic_ns":310465748949291,"payload":{"event_type":"price_change","market":"0x779291bef19b6709f61e9764a954aafe9ffae488d50ae674aabdcb4f248006d5","price_changes":[{"asset_id":"14965588658799411272385430903075831224615961675357217884735713260981483529984","best_ask":"1","best_bid":"0.99","hash":"7dbe001ad4d3c32ac00b074ff5a46f3d22ad26ab","price":"0.98","side":"BUY","size":"55.61"},{"asset_id":"8761897749749422724209054078244794145777693856614463256546737399611489089783","best_ask":"0.01","best_bid":"0","hash":"5df32faf994aa5099a3dbb30b4a9a3ada770efaa","price":"0.02","side":"SELL","size":"55.61"}],"timestamp":"1785208482878"},"payload_hash":"2292e02a1c46b35bcf14a25a42adbf08493e3d65b2e6174fee275cd3673ab890","raw_frame":"{\"market\":\"0x779291bef19b6709f61e9764a954aafe9ffae488d50ae674aabdcb4f248006d5\", \"price_changes\":[{\"asset_id\":\"14965588658799411272385430903075831224615961675357217884735713260981483529984\", \"price\":\"0.98\", \"size\":\"55.61\", \"side\":\"BUY\", \"hash\":\"7dbe001ad4d3c32ac00b074ff5a46f3d22ad26ab\", \"best_bid\":\"0.99\", \"best_ask\":\"1\"}, {\"asset_id\":\"8761897749749422724209054078244794145777693856614463256546737399611489089783\", \"price\":\"0.02\", \"size\":\"55.61\", \"side\":\"SELL\", \"hash\":\"5df32faf994aa5099a3dbb30b4a9a3ada770efaa\", \"best_bid\":\"0\", \"best_ask\":\"0.01\"}], \"timestamp\":\"1785208482878\", \"event_type\":\"price_change\"}","received_at":"2026-07-28T03:14:42.713177Z","schema_version":"clob-market-ws.price_change.v1","sequence":null,"server_hash":null,"server_timestamp":"1785208482878","session_id":"3e519d9098404c15b234d96025eb1a2b","source":"clob_market_ws"},"received_at":"2026-07-28T03:14:42.713177Z","record_id":"70c437bc48017c07a0c64453ff9a1e797eb813be4a35d74b251c2ec199157902","schema_fingerprint":"4aa3821a28b0b7c2400bc59aba4bcc0a76e971dadd19610d3ad38c768e124dc7","schema_version":"edge-lab-recorder.raw.v1","sequence":null,"source":"clob_market_ws"}
{"event_at":"2026-07-28T03:14:42.881000Z","event_fingerprint":"0bbc0f304ee690024c21e5ba85aaa7d2c11e7b2fc5c26fa9db5d2ebf7cc3868e","payload":{"connection_id":"a6b55582af5f430fb37ad02bf0922475","event_at":"2026-07-28T03:14:42.881000Z","event_type":"price_change","frame_hash":"ea5b20142b6b63cffe5e639c8d99966a027b642aaa7567d2984ea39a9716af6d","frame_index":0,"kind":"data","monotonic_ns":310465750598208,"payload":{"event_type":"price_change","market":"0x779291bef19b6709f61e9764a954aafe9ffae488d50ae674aabdcb4f248006d5","price_changes":[{"asset_id":"14965588658799411272385430903075831224615961675357217884735713260981483529984","best_ask":"1","best_bid":"0.99","hash":"0f00d9ef36e469ca72eaf0ea342013cdb5811878","price":"0.99","side":"BUY","size":"138.16"},{"asset_id":"8761897749749422724209054078244794145777693856614463256546737399611489089783","best_ask":"0.01","best_bid":"0","hash":"559f781ddfeeef774c0fd45c588afdf29016e876","price":"0.01","side":"SELL","size":"138.16"}],"timestamp":"1785208482881"},"payload_hash":"ebaf14ceba3b7ce0c0b4162dba5b478b06e7181b6908364dc7c38696054bf360","raw_frame":"{\"market\":\"0x779291bef19b6709f61e9764a954aafe9ffae488d50ae674aabdcb4f248006d5\", \"price_changes\":[{\"asset_id\":\"14965588658799411272385430903075831224615961675357217884735713260981483529984\", \"price\":\"0.99\", \"size\":\"138.16\", \"side\":\"BUY\", \"hash\":\"0f00d9ef36e469ca72eaf0ea342013cdb5811878\", \"best_bid\":\"0.99\", \"best_ask\":\"1\"}, {\"asset_id\":\"8761897749749422724209054078244794145777693856614463256546737399611489089783\", \"price\":\"0.01\", \"size\":\"138.16\", \"side\":\"SELL\", \"hash\":\"559f781ddfeeef774c0fd45c588afdf29016e876\", \"best_bid\":\"0\", \"best_ask\":\"0.01\"}], \"timestamp\":\"1785208482881\", \"event_type\":\"price_change\"}","received_at":"2026-07-28T03:14:42.714826Z","schema_version":"clob-market-ws.price_change.v1","sequence":null,"server_hash":null,"server_timestamp":"1785208482881","session_id":"3e519d9098404c15b234d96025eb1a2b","source":"clob_market_ws"},"received_at":"2026-07-28T03:14:42.714826Z","record_id":"efed1e3f53e21a896f63ddc1bf3375b7d2830182e994e06f220fc32fce74c9dd","schema_fingerprint":"4aa3821a28b0b7c2400bc59aba4bcc0a76e971dadd19610d3ad38c768e124dc7","schema_version":"edge-lab-recorder.raw.v1","sequence":null,"source":"clob_market_ws"}
{"event_at":"2026-07-28T03:14:42.883000Z","event_fingerprint":"7525bf016066664cda50bad71c54808163a623a40b2f212abd7c3b573140e8a1","payload":{"connection_id":"a6b55582af5f430fb37ad02bf0922475","event_at":"2026-07-28T03:14:42.883000Z","event_type":"price_change","frame_hash":"2e842ef7c12e9d4c14e4009bcf2a5a1710525e0675111f71ae19e62c1ea5e26c","frame_index":0,"kind":"data","monotonic_ns":310465753018125,"payload":{"event_type":"price_change","market":"0x779291bef19b6709f61e9764a954aafe9ffae488d50ae674aabdcb4f248006d5","price_changes":[{"asset_id":"14965588658799411272385430903075831224615961675357217884735713260981483529984","best_ask":"1","best_bid":"0.99","hash":"87485f2fbeeb16d54ca31b7038cd68096549729f","price":"0.02","side":"BUY","size":"525"},{"asset_id":"8761897749749422724209054078244794145777693856614463256546737399611489089783","best_ask":"0.01","best_bid":"0","hash":"d36f385e0fbd3f9b7290c27bb8ac08311d0a7b8f","price":"0.98","side":"SELL","size":"525"}],"timestamp":"1785208482883"},"payload_hash":"a867b9122ba336d6181e4e7c14f423ea367a67ccaf1cb2c50a7cb6cdb89b9e6f","raw_frame":"{\"market\":\"0x779291bef19b6709f61e9764a954aafe9ffae488d50ae674aabdcb4f248006d5\", \"price_changes\":[{\"asset_id\":\"14965588658799411272385430903075831224615961675357217884735713260981483529984\", \"price\":\"0.02\", \"size\":\"525\", \"side\":\"BUY\", \"hash\":\"87485f2fbeeb16d54ca31b7038cd68096549729f\", \"best_bid\":\"0.99\", \"best_ask\":\"1\"}, {\"asset_id\":\"8761897749749422724209054078244794145777693856614463256546737399611489089783\", \"price\":\"0.98\", \"size\":\"525\", \"side\":\"SELL\", \"hash\":\"d36f385e0fbd3f9b7290c27bb8ac08311d0a7b8f\", \"best_bid\":\"0\", \"best_ask\":\"0.01\"}], \"timestamp\":\"1785208482883\", \"event_type\":\"price_change\"}","received_at":"2026-07-28T03:14:42.717243Z","schema_version":"clob-market-ws.price_change.v1","sequence":null,"server_hash":null,"server_timestamp":"1785208482883","session_id":"3e519d9098404c15b234d96025eb1a2b","source":"clob_market_ws"},"received_at":"2026-07-28T03:14:42.717243Z","record_id":"90bc072b3e6c406e1b5f1c127bcadc4444845112e45704b6f71935766b8aa001","schema_fingerprint":"4aa3821a28b0b7c2400bc59aba4bcc0a76e971dadd19610d3ad38c768e124dc7","schema_version":"edge-lab-recorder.raw.v1","sequence":null,"source":"clob_market_ws"}
{"event_at":"2026-07-28T03:14:42.916000Z","event_fingerprint":"34c503d60d63ef87d9c1b61e8b0547eeb1522309524a8f765c537bd33e203672","payload":{"connection_id":"a6b55582af5f430fb37ad02bf0922475","event_at":"2026-07-28T03:14:42.916000Z","event_type":"price_change","frame_hash":"7219ab7bf044bb8ec6a28835916750bdfbafb489107eaa30fa4a767994be5948","frame_index":0,"kind":"data","monotonic_ns":310465791279125,"payload":{"event_type":"price_change","market":"0x779291bef19b6709f61e9764a954aafe9ffae488d50ae674aabdcb4f248006d5","price_changes":[{"asset_id":"14965588658799411272385430903075831224615961675357217884735713260981483529984","best_ask":"1","best_bid":"0.99","hash":"3995318ad2171e12cc718e338c00e867f5df257d","price":"0.01","side":"BUY","size":"5520"},{"asset_id":"8761897749749422724209054078244794145777693856614463256546737399611489089783","best_ask":"0.01","best_bid":"0","hash":"9b6ccbd57de2f21258b064d0994ffb3c62b6f9dc","price":"0.99","side":"SELL","size":"5520"}],"timestamp":"1785208482916"},"payload_hash":"5701a6747ce6b656fc7e7411e26246112c45b1dc5189fd97d2e1bc8b62035319","raw_frame":"{\"market\":\"0x779291bef19b6709f61e9764a954aafe9ffae488d50ae674aabdcb4f248006d5\", \"price_changes\":[{\"asset_id\":\"14965588658799411272385430903075831224615961675357217884735713260981483529984\", \"price\":\"0.01\", \"size\":\"5520\", \"side\":\"BUY\", \"hash\":\"3995318ad2171e12cc718e338c00e867f5df257d\", \"best_bid\":\"0.99\", \"best_ask\":\"1\"}, {\"asset_id\":\"8761897749749422724209054078244794145777693856614463256546737399611489089783\", \"price\":\"0.99\", \"size\":\"5520\", \"side\":\"SELL\", \"hash\":\"9b6ccbd57de2f21258b064d0994ffb3c62b6f9dc\", \"best_bid\":\"0\", \"best_ask\":\"0.01\"}], \"timestamp\":\"1785208482916\", \"event_type\":\"price_change\"}","received_at":"2026-07-28T03:14:42.755505Z","schema_version":"clob-market-ws.price_change.v1","sequence":null,"server_hash":null,"server_timestamp":"1785208482916","session_id":"3e519d9098404c15b234d96025eb1a2b","source":"clob_market_ws"},"received_at":"2026-07-28T03:14:42.755505Z","record_id":"76d4f18cff2447b84338eef513d7121a787f7295c6c73fb6cae8fd6fa1e4b555","schema_fingerprint":"4aa3821a28b0b7c2400bc59aba4bcc0a76e971dadd19610d3ad38c768e124dc7","schema_version":"edge-lab-recorder.raw.v1","sequence":null,"source":"clob_market_ws"}
{"event_at":"2026-07-28T03:14:42.937000Z","event_fingerprint":"f3082faefe1ac494551399d7e37e170a1c2d1315f9e6775013178c718672d969","payload":{"connection_id":"a6b55582af5f430fb37ad02bf0922475","event_at":"2026-07-28T03:14:42.937000Z","event_type":"price_change","frame_hash":"32160dda1894f4e97642c973320fb9bc2951305a821122831f5b18954c49332f","frame_index":0,"kind":"data","monotonic_ns":310465808285708,"payload":{"event_type":"price_change","market":"0x779291bef19b6709f61e9764a954aafe9ffae488d50ae674aabdcb4f248006d5","price_changes":[{"asset_id":"14965588658799411272385430903075831224615961675357217884735713260981483529984","best_ask":"1","best_bid":"0.99","hash":"7ad615dc87191274b0f6eabc607cbaa0c14e2655","price":"0.01","side":"BUY","size":"5515"},{"asset_id":"8761897749749422724209054078244794145777693856614463256546737399611489089783","best_ask":"0.01","best_bid":"0","hash":"004f6bdfe8c1bce4fd89b3c1473af23466e7412b","price":"0.99","side":"SELL","size":"5515"}],"timestamp":"1785208482937"},"payload_hash":"974c5e91c42ce5c9684eeed21115d79031c4c269a2a9f9e07c94d200a3aecd65","raw_frame":"{\"market\":\"0x779291bef19b6709f61e9764a954aafe9ffae488d50ae674aabdcb4f248006d5\", \"price_changes\":[{\"asset_id\":\"14965588658799411272385430903075831224615961675357217884735713260981483529984\", \"price\":\"0.01\", \"size\":\"5515\", \"side\":\"BUY\", \"hash\":\"7ad615dc87191274b0f6eabc607cbaa0c14e2655\", \"best_bid\":\"0.99\", \"best_ask\":\"1\"}, {\"asset_id\":\"8761897749749422724209054078244794145777693856614463256546737399611489089783\", \"price\":\"0.99\", \"size\":\"5515\", \"side\":\"SELL\", \"hash\":\"004f6bdfe8c1bce4fd89b3c1473af23466e7412b\", \"best_bid\":\"0\", \"best_ask\":\"0.01\"}], \"timestamp\":\"1785208482937\", \"event_type\":\"price_change\"}","received_at":"2026-07-28T03:14:42.772511Z","schema_version":"clob-market-ws.price_change.v1","sequence":null,"server_hash":null,"server_timestamp":"1785208482937","session_id":"3e519d9098404c15b234d96025eb1a2b","source":"clob_market_ws"},"received_at":"2026-07-28T03:14:42.772511Z","record_id":"28672a3d264e383dc5abf432d7f367989740ebee5cc764a11278bebf415f737d","schema_fingerprint":"4aa3821a28b0b7c2400bc59aba4bcc0a76e971dadd19610d3ad38c768e124dc7","schema_version":"edge-lab-recorder.raw.v1","sequence":null,"source":"clob_market_ws"}
{"event_at":"2026-07-28T03:14:42.960000Z","event_fingerprint":"16854190347d26a9f40a67b4ff6a143dba9b3ca671b1db12bee22678c6ce0cfe","payload":{"connection_id":"a6b55582af5f430fb37ad02bf0922475","event_at":"2026-07-28T03:14:42.960000Z","event_type":"price_change","frame_hash":"7d748ea576cb6526e0c807d3180bd0054b7a81eb7f301e32be581ac5e3578229","frame_index":0,"kind":"data","monotonic_ns":310465827661416,"payload":{"event_type":"price_change","market":"0x779291bef19b6709f61e9764a954aafe9ffae488d50ae674aabdcb4f248006d5","price_changes":[{"asset_id":"14965588658799411272385430903075831224615961675357217884735713260981483529984","best_ask":"1","best_bid":"0.99","hash":"21c897aea4e086966d4e1803c2c53f9cabd97cf7","price":"0.02","side":"BUY","size":"530"},{"asset_id":"8761897749749422724209054078244794145777693856614463256546737399611489089783","best_ask":"0.01","best_bid":"0","hash":"cf7c820d3638d9c53b9fe4d609a392ee3bf19ed2","price":"0.98","side":"SELL","size":"530"}],"timestamp":"1785208482960"},"payload_hash":"f4644d6681ebaea722402d991ae108d9c5e4b673f54b84b4464a6c281de3fd1c","raw_frame":"{\"market\":\"0x779291bef19b6709f61e9764a954aafe9ffae488d50ae674aabdcb4f248006d5\", \"price_changes\":[{\"asset_id\":\"14965588658799411272385430903075831224615961675357217884735713260981483529984\", \"price\":\"0.02\", \"size\":\"530\", \"side\":\"BUY\", \"hash\":\"21c897aea4e086966d4e1803c2c53f9cabd97cf7\", \"best_bid\":\"0.99\", \"best_ask\":\"1\"}, {\"asset_id\":\"8761897749749422724209054078244794145777693856614463256546737399611489089783\", \"price\":\"0.98\", \"size\":\"530\", \"side\":\"SELL\", \"hash\":\"cf7c820d3638d9c53b9fe4d609a392ee3bf19ed2\", \"best_bid\":\"0\", \"best_ask\":\"0.01\"}], \"timestamp\":\"1785208482960\", \"event_type\":\"price_change\"}","received_at":"2026-07-28T03:14:42.791886Z","schema_version":"clob-market-ws.price_change.v1","sequence":null,"server_hash":null,"server_timestamp":"1785208482960","session_id":"3e519d9098404c15b234d96025eb1a2b","source":"clob_market_ws"},"received_at":"2026-07-28T03:14:42.791886Z","record_id":"a6697018be15a7eac62c9ff51cc493638a26acf1cec2cda78944025e53b204cf","schema_fingerprint":"4aa3821a28b0b7c2400bc59aba4bcc0a76e971dadd19610d3ad38c768e124dc7","schema_version":"edge-lab-recorder.raw.v1","sequence":null,"source":"clob_market_ws"}
{"event_at":"2026-07-28T03:14:42.971000Z","event_fingerprint":"8b60b8e90c76ceafe49759c9241bb07d1f684c58554039ee2102e7b7e5d43498","payload":{"connection_id":"a6b55582af5f430fb37ad02bf0922475","event_at":"2026-07-28T03:14:42.971000Z","event_type":"price_change","frame_hash":"47075cf99b51cd92e975b7ebd1ccf3382cb101ed0ec21a6e7a2feb238fc948df","frame_index":0,"kind":"data","monotonic_ns":310465838094833,"payload":{"event_type":"price_change","market":"0x779291bef19b6709f61e9764a954aafe9ffae488d50ae674aabdcb4f248006d5","price_changes":[{"asset_id":"14965588658799411272385430903075831224615961675357217884735713260981483529984","best_ask":"1","best_bid":"0.99","hash":"81e1aefc4674f5f24ebbf1ba1b798c768d8d8b1e","price":"0.99","side":"BUY","size":"168.16"},{"asset_id":"8761897749749422724209054078244794145777693856614463256546737399611489089783","best_ask":"0.01","best_bid":"0","hash":"6a8f2e67d395774b7f5cb1732450100eb867fe71","price":"0.01","side":"SELL","size":"168.16"}],"timestamp":"1785208482971"},"payload_hash":"586bc1d110c60b7e42088fdc1943b34e7740a96f7c87d398318bc22863471f5a","raw_frame":"{\"market\":\"0x779291bef19b6709f61e9764a954aafe9ffae488d50ae674aabdcb4f248006d5\", \"price_changes\":[{\"asset_id\":\"14965588658799411272385430903075831224615961675357217884735713260981483529984\", \"price\":\"0.99\", \"size\":\"168.16\", \"side\":\"BUY\", \"hash\":\"81e1aefc4674f5f24ebbf1ba1b798c768d8d8b1e\", \"best_bid\":\"0.99\", \"best_ask\":\"1\"}, {\"asset_id\":\"8761897749749422724209054078244794145777693856614463256546737399611489089783\", \"price\":\"0.01\", \"size\":\"168.16\", \"side\":\"SELL\", \"hash\":\"6a8f2e67d395774b7f5cb1732450100eb867fe71\", \"best_bid\":\"0\", \"best_ask\":\"0.01\"}], \"timestamp\":\"1785208482971\", \"event_type\":\"price_change\"}","received_at":"2026-07-28T03:14:42.802321Z","schema_version":"clob-market-ws.price_change.v1","sequence":null,"server_hash":null,"server_timestamp":"1785208482971","session_id":"3e519d9098404c15b234d96025eb1a2b","source":"clob_market_ws"},"received_at":"2026-07-28T03:14:42.802321Z","record_id":"8ac96da07f2df65cd3852b8abacdd01c124225bac408554c102f116c46eced9a","schema_fingerprint":"4aa3821a28b0b7c2400bc59aba4bcc0a76e971dadd19610d3ad38c768e124dc7","schema_version":"edge-lab-recorder.raw.v1","sequence":null,"source":"clob_market_ws"}
{"event_at":"2026-07-28T03:14:43.078000Z","event_fingerprint":"e8e8d1c494c0950d4a5183216c1fc3fa56f4b1b335924b51eea903aa36a6a589","payload":{"connection_id":"a6b55582af5f430fb37ad02bf0922475","event_at":"2026-07-28T03:14:43.078000Z","event_type":"price_change","frame_hash":"cc0b8d5018336d6c00bb6dbc001f57871d39c7c94aa1839145d5fa4d34a2862b","frame_index":0,"kind":"data","monotonic_ns":310465943703291,"payload":{"event_type":"price_change","market":"0x779291bef19b6709f61e9764a954aafe9ffae488d50ae674aabdcb4f248006d5","price_changes":[{"asset_id":"14965588658799411272385430903075831224615961675357217884735713260981483529984","best_ask":"1","best_bid":"0.99","hash":"fa64953d92779a699162bcbbbedf5649423353d9","price":"0.99","side":"BUY","size":"141"},{"asset_id":"8761897749749422724209054078244794145777693856614463256546737399611489089783","best_ask":"0.01","best_bid":"0","hash":"0fe954ab28d25eb9322beedfe503bab4ed68b644","price":"0.01","side":"SELL","size":"141"}],"timestamp":"1785208483078"},"payload_hash":"2a97cddc2a31bd593caef068c58b51b91850e724e9b4bb76527e9926a7b218d2","raw_frame":"{\"market\":\"0x779291bef19b6709f61e9764a954aafe9ffae488d50ae674aabdcb4f248006d5\", \"price_changes\":[{\"asset_id\":\"14965588658799411272385430903075831224615961675357217884735713260981483529984\", \"price\":\"0.99\", \"size\":\"141\", \"side\":\"BUY\", \"hash\":\"fa64953d92779a699162bcbbbedf5649423353d9\", \"best_bid\":\"0.99\", \"best_ask\":\"1\"}, {\"asset_id\":\"8761897749749422724209054078244794145777693856614463256546737399611489089783\", \"price\":\"0.01\", \"size\":\"141\", \"side\":\"SELL\", \"hash\":\"0fe954ab28d25eb9322beedfe503bab4ed68b644\", \"best_bid\":\"0\", \"best_ask\":\"0.01\"}], \"timestamp\":\"1785208483078\", \"event_type\":\"price_change\"}","received_at":"2026-07-28T03:14:42.907923Z","schema_version":"clob-market-ws.price_change.v1","sequence":null,"server_hash":null,"server_timestamp":"1785208483078","session_id":"3e519d9098404c15b234d96025eb1a2b","source":"clob_market_ws"},"received_at":"2026-07-28T03:14:42.907923Z","record_id":"750eb0d66ec4d350d66631955f9e5a2a3959ad6b29bf530f67362beda205c168","schema_fingerprint":"4aa3821a28b0b7c2400bc59aba4bcc0a76e971dadd19610d3ad38c768e124dc7","schema_version":"edge-lab-recorder.raw.v1","sequence":null,"source":"clob_market_ws"}
{"event_at":"2026-07-28T03:14:43.086000Z","event_fingerprint":"8c6361577a85871406b6a6f07fcef74a44d8c3aa774f24c61193ecc9b438fcef","payload":{"connection_id":"a6b55582af5f430fb37ad02bf0922475","event_at":"2026-07-28T03:14:43.086000Z","event_type":"price_change","frame_hash":"369a0fb566e3a3f000c46c9ae92695413002bf828b315d1a7783f1b650ddeb4b","frame_index":0,"kind":"data","monotonic_ns":310465954055833,"payload":{"event_type":"price_change","market":"0x779291bef19b6709f61e9764a954aafe9ffae488d50ae674aabdcb4f248006d5","price_changes":[{"asset_id":"8761897749749422724209054078244794145777693856614463256546737399611489089783","best_ask":"0.01","best_bid":"0","hash":"f6a2be0db09b15ec3e02e11b5179fea5b683dd77","price":"0.01","side":"SELL","size":"183"},{"asset_id":"14965588658799411272385430903075831224615961675357217884735713260981483529984","best_ask":"1","best_bid":"0.99","hash":"2b9cde63f547acd758f669cf185c4b87b7e810ac","price":"0.99","side":"BUY","size":"183"}],"timestamp":"1785208483086"},"payload_hash":"4bdc337cb26a52b6b7639ce44a2ab46b5419404657423b47e577c69e2d940ae3","raw_frame":"{\"market\":\"0x779291bef19b6709f61e9764a954aafe9ffae488d50ae674aabdcb4f248006d5\", \"price_changes\":[{\"asset_id\":\"8761897749749422724209054078244794145777693856614463256546737399611489089783\", \"price\":\"0.01\", \"size\":\"183\", \"side\":\"SELL\", \"hash\":\"f6a2be0db09b15ec3e02e11b5179fea5b683dd77\", \"best_bid\":\"0\", \"best_ask\":\"0.01\"}, {\"asset_id\":\"14965588658799411272385430903075831224615961675357217884735713260981483529984\", \"price\":\"0.99\", \"size\":\"183\", \"side\":\"BUY\", \"hash\":\"2b9cde63f547acd758f669cf185c4b87b7e810ac\", \"best_bid\":\"0.99\", \"best_ask\":\"1\"}], \"timestamp\":\"1785208483086\", \"event_type\":\"price_change\"}","received_at":"2026-07-28T03:14:42.918278Z","schema_version":"clob-market-ws.price_change.v1","sequence":null,"server_hash":null,"server_timestamp":"1785208483086","session_id":"3e519d9098404c15b234d96025eb1a2b","source":"clob_market_ws"},"received_at":"2026-07-28T03:14:42.918278Z","record_id":"49338417d70aa3a639d72d83d24920db06026db0e9c1a2bbc95e030f5fb764d8","schema_fingerprint":"4aa3821a28b0b7c2400bc59aba4bcc0a76e971dadd19610d3ad38c768e124dc7","schema_version":"edge-lab-recorder.raw.v1","sequence":null,"source":"clob_market_ws"}
{"event_at":"2026-07-28T03:14:43.087000Z","event_fingerprint":"3198fc089a088496be4c66792d5d2b124efa1c555427726eac4ff70e03d51549","payload":{"connection_id":"a6b55582af5f430fb37ad02bf0922475","event_at":"2026-07-28T03:14:43.087000Z","event_type":"price_change","frame_hash":"8dba1a09ded8c98f403b22c86ef878df6361e74ba691a8b286791eaf5a956026","frame_index":0,"kind":"data","monotonic_ns":310465955741708,"payload":{"event_type":"price_change","market":"0x779291bef19b6709f61e9764a954aafe9ffae488d50ae674aabdcb4f248006d5","price_changes":[{"asset_id":"14965588658799411272385430903075831224615961675357217884735713260981483529984","best_ask":"1","best_bid":"0.99","hash":"6898fa09df66c7c8b46bdcc3d4700a760bad49f7","price":"0.01","side":"BUY","size":"5521.24"},{"asset_id":"8761897749749422724209054078244794145777693856614463256546737399611489089783","best_ask":"0.01","best_bid":"0","hash":"8a65f08b148199b2eae8f08e7efc14ad943fedc4","price":"0.99","side":"SELL","size":"5521.24"}],"timestamp":"1785208483087"},"payload_hash":"ed461b42d4df6ba5e1a5ff333270f3a7a7a4cba0e18c8679923e8604fd1668ec","raw_frame":"{\"market\":\"0x779291bef19b6709f61e9764a954aafe9ffae488d50ae674aabdcb4f248006d5\", \"price_changes\":[{\"asset_id\":\"14965588658799411272385430903075831224615961675357217884735713260981483529984\", \"price\":\"0.01\", \"size\":\"5521.24\", \"side\":\"BUY\", \"hash\":\"6898fa09df66c7c8b46bdcc3d4700a760bad49f7\", \"best_bid\":\"0.99\", \"best_ask\":\"1\"}, {\"asset_id\":\"8761897749749422724209054078244794145777693856614463256546737399611489089783\", \"price\":\"0.99\", \"size\":\"5521.24\", \"side\":\"SELL\", \"hash\":\"8a65f08b148199b2eae8f08e7efc14ad943fedc4\", \"best_bid\":\"0\", \"best_ask\":\"0.01\"}], \"timestamp\":\"1785208483087\", \"event_type\":\"price_change\"}","received_at":"2026-07-28T03:14:42.919966Z","schema_version":"clob-market-ws.price_change.v1","sequence":null,"server_hash":null,"server_timestamp":"1785208483087","session_id":"3e519d9098404c15b234d96025eb1a2b","source":"clob_market_ws"},"received_at":"2026-07-28T03:14:42.919966Z","record_id":"b21d5fa1d8c12944b6642ba17f507521e186470480c0c5b02fd3ebf10cd8d5b7","schema_fingerprint":"4aa3821a28b0b7c2400bc59aba4bcc0a76e971dadd19610d3ad38c768e124dc7","schema_version":"edge-lab-recorder.raw.v1","sequence":null,"source":"clob_market_ws"}
{"event_at":"2026-07-28T03:14:43.087000Z","event_fingerprint":"10109344c9c922204fc87e63d26411448746f90b20edb8f762f652fb3b57fd5a","payload":{"connection_id":"a6b55582af5f430fb37ad02bf0922475","event_at":"2026-07-28T03:14:43.087000Z","event_type":"price_change","frame_hash":"369a18ddaddbaa398add6c518125ff0f815c201cc614c84e67381e0983c672c2","frame_index":0,"kind":"data","monotonic_ns":310465957445500,"payload":{"event_type":"price_change","market":"0x779291bef19b6709f61e9764a954aafe9ffae488d50ae674aabdcb4f248006d5","price_changes":[{"asset_id":"8761897749749422724209054078244794145777693856614463256546737399611489089783","best_ask":"0.01","best_bid":"0","hash":"387f5f869ce9a445b6d955c49fa71ac86f13ffc7","price":"0.02","side":"SELL","size":"61.22"},{"asset_id":"14965588658799411272385430903075831224615961675357217884735713260981483529984","best_ask":"1","best_bid":"0.99","hash":"c267b062b6636f98ed901524c8099705d8bbb00c","price":"0.98","side":"BUY","size":"61.22"}],"timestamp":"1785208483087"},"payload_hash":"3d1c8f985d5c91f052e88111e2e553853c60117d63005b29d0d1c097361c0e03","raw_frame":"{\"market\":\"0x779291bef19b6709f61e9764a954aafe9ffae488d50ae674aabdcb4f248006d5\", \"price_changes\":[{\"asset_id\":\"8761897749749422724209054078244794145777693856614463256546737399611489089783\", \"price\":\"0.02\", \"size\":\"61.22\", \"side\":\"SELL\", \"hash\":\"387f5f869ce9a445b6d955c49fa71ac86f13ffc7\", \"best_bid\":\"0\", \"best_ask\":\"0.01\"}, {\"asset_id\":\"14965588658799411272385430903075831224615961675357217884735713260981483529984\", \"price\":\"0.98\", \"size\":\"61.22\", \"side\":\"BUY\", \"hash\":\"c267b062b6636f98ed901524c8099705d8bbb00c\", \"best_bid\":\"0.99\", \"best_ask\":\"1\"}], \"timestamp\":\"1785208483087\", \"event_type\":\"price_change\"}","received_at":"2026-07-28T03:14:42.921672Z","schema_version":"clob-market-ws.price_change.v1","sequence":null,"server_hash":null,"server_timestamp":"1785208483087","session_id":"3e519d9098404c15b234d96025eb1a2b","source":"clob_market_ws"},"received_at":"2026-07-28T03:14:42.921672Z","record_id":"5142cb0274b2df911954b88dcec0aff76454292666e9199b34b0c4597ffffc22","schema_fingerprint":"4aa3821a28b0b7c2400bc59aba4bcc0a76e971dadd19610d3ad38c768e124dc7","schema_version":"edge-lab-recorder.raw.v1","sequence":null,"source":"clob_market_ws"}
{"event_at":"2026-07-28T03:14:43.088000Z","event_fingerprint":"87c34a4bb4ffd52d1bdb215871f4c17bea09e52394d08b600eda8d199d859b74","payload":{"connection_id":"a6b55582af5f430fb37ad02bf0922475","event_at":"2026-07-28T03:14:43.088000Z","event_type":"price_change","frame_hash":"d8504591d90a160a27e0f7b56c8eebe368e0263ae83a24f22b6b9a13e6670e9f","frame_index":0,"kind":"data","monotonic_ns":310465959079750,"payload":{"event_type":"price_change","market":"0x779291bef19b6709f61e9764a954aafe9ffae488d50ae674aabdcb4f248006d5","price_changes":[{"asset_id":"14965588658799411272385430903075831224615961675357217884735713260981483529984","best_ask":"1","best_bid":"0.99","hash":"a1b075fdd13cb00f48d30512ec07261a6650aabd","price":"0.98","side":"BUY","size":"88.6"},{"asset_id":"8761897749749422724209054078244794145777693856614463256546737399611489089783","best_ask":"0.01","best_bid":"0","hash":"95c1ab01dd004145fbeb3cc608bebae4e270d174","price":"0.02","side":"SELL","size":"88.6"}],"timestamp":"1785208483088"},"payload_hash":"69e4ca1e4f5b0bc9bb4553289a7f3dc18002013b7dac3669249425a0ae81ae84","raw_frame":"{\"market\":\"0x779291bef19b6709f61e9764a954aafe9ffae488d50ae674aabdcb4f248006d5\", \"price_changes\":[{\"asset_id\":\"14965588658799411272385430903075831224615961675357217884735713260981483529984\", \"price\":\"0.98\", \"size\":\"88.6\", \"side\":\"BUY\", \"hash\":\"a1b075fdd13cb00f48d30512ec07261a6650aabd\", \"best_bid\":\"0.99\", \"best_ask\":\"1\"}, {\"asset_id\":\"8761897749749422724209054078244794145777693856614463256546737399611489089783\", \"price\":\"0.02\", \"size\":\"88.6\", \"side\":\"SELL\", \"hash\":\"95c1ab01dd004145fbeb3cc608bebae4e270d174\", \"best_bid\":\"0\", \"best_ask\":\"0.01\"}], \"timestamp\":\"1785208483088\", \"event_type\":\"price_change\"}","received_at":"2026-07-28T03:14:42.923306Z","schema_version":"clob-market-ws.price_change.v1","sequence":null,"server_hash":null,"server_timestamp":"1785208483088","session_id":"3e519d9098404c15b234d96025eb1a2b","source":"clob_market_ws"},"received_at":"2026-07-28T03:14:42.923306Z","record_id":"57b79b6ae31efddfccb48109b05c4c80fc55e32125de29641e64ea688d4be0c3","schema_fingerprint":"4aa3821a28b0b7c2400bc59aba4bcc0a76e971dadd19610d3ad38c768e124dc7","schema_version":"edge-lab-recorder.raw.v1","sequence":null,"source":"clob_market_ws"}
{"event_at":"2026-07-28T03:14:43.098000Z","event_fingerprint":"eb513bcfc536b8d012d7c7ccd6ddde68dfb5ccdfcebf996852aeb164e61a1d90","payload":{"connection_id":"a6b55582af5f430fb37ad02bf0922475","event_at":"2026-07-28T03:14:43.098000Z","event_type":"price_change","frame_hash":"face20005dbd5ad48483768ea4386f8085d73b5f748a8694870ba5239aeed220","frame_index":0,"kind":"data","monotonic_ns":310465965296375,"payload":{"event_type":"price_change","market":"0x779291bef19b6709f61e9764a954aafe9ffae488d50ae674aabdcb4f248006d5","price_changes":[{"asset_id":"14965588658799411272385430903075831224615961675357217884735713260981483529984","best_ask":"1","best_bid":"0.99","hash":"33adda24cec9c2cf6c1999701ab28fa5ee3e6428","price":"0.02","side":"BUY","size":"525"},{"asset_id":"8761897749749422724209054078244794145777693856614463256546737399611489089783","best_ask":"0.01","best_bid":"0","hash":"4eae6993b47dfe3738120b8340d951141c9da730","price":"0.98","side":"SELL","size":"525"}],"timestamp":"1785208483098"},"payload_hash":"aba4f9dafb34e500e23b769d17981c28d66929e0d36d825173e90a0a0d910bc3","raw_frame":"{\"market\":\"0x779291bef19b6709f61e9764a954aafe9ffae488d50ae674aabdcb4f248006d5\", \"price_changes\":[{\"asset_id\":\"14965588658799411272385430903075831224615961675357217884735713260981483529984\", \"price\":\"0.02\", \"size\":\"525\", \"side\":\"BUY\", \"hash\":\"33adda24cec9c2cf6c1999701ab28fa5ee3e6428\", \"best_bid\":\"0.99\", \"best_ask\":\"1\"}, {\"asset_id\":\"8761897749749422724209054078244794145777693856614463256546737399611489089783\", \"price\":\"0.98\", \"size\":\"525\", \"side\":\"SELL\", \"hash\":\"4eae6993b47dfe3738120b8340d951141c9da730\", \"best_bid\":\"0\", \"best_ask\":\"0.01\"}], \"timestamp\":\"1785208483098\", \"event_type\":\"price_change\"}","received_at":"2026-07-28T03:14:42.929518Z","schema_version":"clob-market-ws.price_change.v1","sequence":null,"server_hash":null,"server_timestamp":"1785208483098","session_id":"3e519d9098404c15b234d96025eb1a2b","source":"clob_market_ws"},"received_at":"2026-07-28T03:14:42.929518Z","record_id":"300f42c189cf3220c28fb90464dfb85513fdb6d9ec011dd91a33571a9d8447d3","schema_fingerprint":"4aa3821a28b0b7c2400bc59aba4bcc0a76e971dadd19610d3ad38c768e124dc7","schema_version":"edge-lab-recorder.raw.v1","sequence":null,"source":"clob_market_ws"}
{"event_at":"2026-07-28T03:14:43.122000Z","event_fingerprint":"4329963f7e9736536e48011c07d9dc6646dafbba7c0bae5ebca8679392c7d6ab","payload":{"connection_id":"a6b55582af5f430fb37ad02bf0922475","event_at":"2026-07-28T03:14:43.122000Z","event_type":"price_change","frame_hash":"42818bf7bd3a82bd3d87e085179aa8291a2ca810a6d481e65ca5e8b8698e5147","frame_index":0,"kind":"data","monotonic_ns":310465989226916,"payload":{"event_type":"price_change","market":"0x779291bef19b6709f61e9764a954aafe9ffae488d50ae674aabdcb4f248006d5","price_changes":[{"asset_id":"14965588658799411272385430903075831224615961675357217884735713260981483529984","best_ask":"1","best_bid":"0.99","hash":"663e12dae1b3a4b544aa024e6521e797abc27110","price":"0.99","side":"BUY","size":"433"},{"asset_id":"8761897749749422724209054078244794145777693856614463256546737399611489089783","best_ask":"0.01","best_bid":"0","hash":"b866c376dc84f36b475d1a3d9f2a52d6654662d5","price":"0.01","side":"SELL","size":"433"}],"timestamp":"1785208483122"},"payload_hash":"708be67bc8f122a8059f9898821a4014b7dd507549edf7e0fc38a826cfbb9bbb","raw_frame":"{\"market\":\"0x779291bef19b6709f61e9764a954aafe9ffae488d50ae674aabdcb4f248006d5\", \"price_changes\":[{\"asset_id\":\"14965588658799411272385430903075831224615961675357217884735713260981483529984\", \"price\":\"0.99\", \"size\":\"433\", \"side\":\"BUY\", \"hash\":\"663e12dae1b3a4b544aa024e6521e797abc27110\", \"best_bid\":\"0.99\", \"best_ask\":\"1\"}, {\"asset_id\":\"8761897749749422724209054078244794145777693856614463256546737399611489089783\", \"price\":\"0.01\", \"size\":\"433\", \"side\":\"SELL\", \"hash\":\"b866c376dc84f36b475d1a3d9f2a52d6654662d5\", \"best_bid\":\"0\", \"best_ask\":\"0.01\"}], \"timestamp\":\"1785208483122\", \"event_type\":\"price_change\"}","received_at":"2026-07-28T03:14:42.953452Z","schema_version":"clob-market-ws.price_change.v1","sequence":null,"server_hash":null,"server_timestamp":"1785208483122","session_id":"3e519d9098404c15b234d96025eb1a2b","source":"clob_market_ws"},"received_at":"2026-07-28T03:14:42.953452Z","record_id":"6296f1f7de7fe270009dd2b4792f6ba097a8c6f3aec1f65821fa6e7c4b27c2db","schema_fingerprint":"4aa3821a28b0b7c2400bc59aba4bcc0a76e971dadd19610d3ad38c768e124dc7","schema_version":"edge-lab-recorder.raw.v1","sequence":null,"source":"clob_market_ws"}
{"event_at":"2026-07-28T03:14:43.178000Z","event_fingerprint":"17189a79b97dbaa80e9d487c47511f9902198163ab03270c85b64a2c76764f4d","payload":{"connection_id":"a6b55582af5f430fb37ad02bf0922475","event_at":"2026-07-28T03:14:43.178000Z","event_type":"price_change","frame_hash":"af8b9d6d85445b6b89e11a1bc0441e6882180f720f8e5bcd3c0755f614775b2e","frame_index":0,"kind":"data","monotonic_ns":310466045481375,"payload":{"event_type":"price_change","market":"0x779291bef19b6709f61e9764a954aafe9ffae488d50ae674aabdcb4f248006d5","price_changes":[{"asset_id":"8761897749749422724209054078244794145777693856614463256546737399611489089783","best_ask":"0.01","best_bid":"0","hash":"0ccdb9dbbfd8b07b5447a87fcf27075dbd7d8f72","price":"0.02","side":"SELL","size":"55.61"},{"asset_id":"14965588658799411272385430903075831224615961675357217884735713260981483529984","best_ask":"1","best_bid":"0.99","hash":"1e9addca585995655f65eb6d135cfbfdd011f163","price":"0.98","side":"BUY","size":"55.61"}],"timestamp":"1785208483178"},"payload_hash":"5a187ddddbd2fbb546c4d2723449dac09d69a2a2c2b4ab31f1bc9363618aa1d3","raw_frame":"{\"market\":\"0x779291bef19b6709f61e9764a954aafe9ffae488d50ae674aabdcb4f248006d5\", \"price_changes\":[{\"asset_id\":\"8761897749749422724209054078244794145777693856614463256546737399611489089783\", \"price\":\"0.02\", \"size\":\"55.61\", \"side\":\"SELL\", \"hash\":\"0ccdb9dbbfd8b07b5447a87fcf27075dbd7d8f72\", \"best_bid\":\"0\", \"best_ask\":\"0.01\"}, {\"asset_id\":\"14965588658799411272385430903075831224615961675357217884735713260981483529984\", \"price\":\"0.98\", \"size\":\"55.61\", \"side\":\"BUY\", \"hash\":\"1e9addca585995655f65eb6d135cfbfdd011f163\", \"best_bid\":\"0.99\", \"best_ask\":\"1\"}], \"timestamp\":\"1785208483178\", \"event_type\":\"price_change\"}","received_at":"2026-07-28T03:14:43.009703Z","schema_version":"clob-market-ws.price_change.v1","sequence":null,"server_hash":null,"server_timestamp":"1785208483178","session_id":"3e519d9098404c15b234d96025eb1a2b","source":"clob_market_ws"},"received_at":"2026-07-28T03:14:43.009703Z","record_id":"a8262dc2e17dd77375b0f35be48339d166e7dfb6e2ae2e4283e5410b1f30eb9a","schema_fingerprint":"4aa3821a28b0b7c2400bc59aba4bcc0a76e971dadd19610d3ad38c768e124dc7","schema_version":"edge-lab-recorder.raw.v1","sequence":null,"source":"clob_market_ws"}
{"event_at":"2026-07-28T03:14:43.178000Z","event_fingerprint":"b55a7165f18bf18d6b59d029b50e811e23202475e09ec9fd23ff8ee1c2907419","payload":{"connection_id":"a6b55582af5f430fb37ad02bf0922475","event_at":"2026-07-28T03:14:43.178000Z","event_type":"price_change","frame_hash":"610e3de6d0d577f70bb09f865aa1d5b92b2bb0dfeb4e165c0050e05abb19a43f","frame_index":0,"kind":"data","monotonic_ns":310466047230416,"payload":{"event_type":"price_change","market":"0x779291bef19b6709f61e9764a954aafe9ffae488d50ae674aabdcb4f248006d5","price_changes":[{"asset_id":"14965588658799411272385430903075831224615961675357217884735713260981483529984","best_ask":"1","best_bid":"0.99","hash":"1e9addca585995655f65eb6d135cfbfdd011f163","price":"0.98","side":"BUY","size":"55.61"},{"asset_id":"8761897749749422724209054078244794145777693856614463256546737399611489089783","best_ask":"0.01","best_bid":"0","hash":"0ccdb9dbbfd8b07b5447a87fcf27075dbd7d8f72","price":"0.02","side":"SELL","size":"55.61"}],"timestamp":"1785208483178"},"payload_hash":"d8a036478862eff1c05c26e08354becf3c9c024af23ed6d89db5fe46bc395414","raw_frame":"{\"market\":\"0x779291bef19b6709f61e9764a954aafe9ffae488d50ae674aabdcb4f248006d5\", \"price_changes\":[{\"asset_id\":\"14965588658799411272385430903075831224615961675357217884735713260981483529984\", \"price\":\"0.98\", \"size\":\"55.61\", \"side\":\"BUY\", \"hash\":\"1e9addca585995655f65eb6d135cfbfdd011f163\", \"best_bid\":\"0.99\", \"best_ask\":\"1\"}, {\"asset_id\":\"8761897749749422724209054078244794145777693856614463256546737399611489089783\", \"price\":\"0.02\", \"size\":\"55.61\", \"side\":\"SELL\", \"hash\":\"0ccdb9dbbfd8b07b5447a87fcf27075dbd7d8f72\", \"best_bid\":\"0\", \"best_ask\":\"0.01\"}], \"timestamp\":\"1785208483178\", \"event_type\":\"price_change\"}","received_at":"2026-07-28T03:14:43.011455Z","schema_version":"clob-market-ws.price_change.v1","sequence":null,"server_hash":null,"server_timestamp":"1785208483178","session_id":"3e519d9098404c15b234d96025eb1a2b","source":"clob_market_ws"},"received_at":"2026-07-28T03:14:43.011455Z","record_id":"cb43bfe6d29d041464c8294acafa640c5ab5f1f4b3a726470504677d33866473","schema_fingerprint":"4aa3821a28b0b7c2400bc59aba4bcc0a76e971dadd19610d3ad38c768e124dc7","schema_version":"edge-lab-recorder.raw.v1","sequence":null,"source":"clob_market_ws"}
{"event_at":"2026-07-28T03:14:43.178000Z","event_fingerprint":"12f8172846201bfe78c9718693d5b6b1e090592c6129cbc95d7865a6d5c87c45","payload":{"connection_id":"a6b55582af5f430fb37ad02bf0922475","event_at":"2026-07-28T03:14:43.178000Z","event_type":"price_change","frame_hash":"e3f2c8ce5b07eb2d05cf07126f35ea14ab6f7f1042465f5a8f1e2f553dc422c7","frame_index":0,"kind":"data","monotonic_ns":310466048835458,"payload":{"event_type":"price_change","market":"0x779291bef19b6709f61e9764a954aafe9ffae488d50ae674aabdcb4f248006d5","price_changes":[{"asset_id":"14965588658799411272385430903075831224615961675357217884735713260981483529984","best_ask":"1","best_bid":"0.99","hash":"1e9addca585995655f65eb6d135cfbfdd011f163","price":"0.01","side":"BUY","size":"5515"},{"asset_id":"8761897749749422724209054078244794145777693856614463256546737399611489089783","best_ask":"0.01","best_bid":"0","hash":"0ccdb9dbbfd8b07b5447a87fcf27075dbd7d8f72","price":"0.99","side":"SELL","size":"5515"}],"timestamp":"1785208483178"},"payload_hash":"95d5478b757b9c9351f7ecc9a5eb6ff5abdee76f050cd7ac4d2adf67a0aef5ec","raw_frame":"{\"market\":\"0x779291bef19b6709f61e9764a954aafe9ffae488d50ae674aabdcb4f248006d5\", \"price_changes\":[{\"asset_id\":\"14965588658799411272385430903075831224615961675357217884735713260981483529984\", \"price\":\"0.01\", \"size\":\"5515\", \"side\":\"BUY\", \"hash\":\"1e9addca585995655f65eb6d135cfbfdd011f163\", \"best_bid\":\"0.99\", \"best_ask\":\"1\"}, {\"asset_id\":\"8761897749749422724209054078244794145777693856614463256546737399611489089783\", \"price\":\"0.99\", \"size\":\"5515\", \"side\":\"SELL\", \"hash\":\"0ccdb9dbbfd8b07b5447a87fcf27075dbd7d8f72\", \"best_bid\":\"0\", \"best_ask\":\"0.01\"}], \"timestamp\":\"1785208483178\", \"event_type\":\"price_change\"}","received_at":"2026-07-28T03:14:43.013061Z","schema_version":"clob-market-ws.price_change.v1","sequence":null,"server_hash":null,"server_timestamp":"1785208483178","session_id":"3e519d9098404c15b234d96025eb1a2b","source":"clob_market_ws"},"received_at":"2026-07-28T03:14:43.013061Z","record_id":"edc36a12b8e096b7f72819246b2f67c6fd9df85199c36282bc9706da23100c17","schema_fingerprint":"4aa3821a28b0b7c2400bc59aba4bcc0a76e971dadd19610d3ad38c768e124dc7","schema_version":"edge-lab-recorder.raw.v1","sequence":null,"source":"clob_market_ws"}
{"event_at":"2026-07-28T03:14:43.181000Z","event_fingerprint":"aad03c3698de785941141a49bb64ca251458b047c75eeb0a3efbbf9bc78177f6","payload":{"connection_id":"a6b55582af5f430fb37ad02bf0922475","event_at":"2026-07-28T03:14:43.181000Z","event_type":"price_change","frame_hash":"85a052aaa55b6764d7780ea2ef5192de78b598618bb3c6ca9a6171994a6cff5d","frame_index":0,"kind":"data","monotonic_ns":310466050515125,"payload":{"event_type":"price_change","market":"0x779291bef19b6709f61e9764a954aafe9ffae488d50ae674aabdcb4f248006d5","price_changes":[{"asset_id":"14965588658799411272385430903075831224615961675357217884735713260981483529984","best_ask":"1","best_bid":"0.99","hash":"7fec5a8baa35d5d80541a63066c6fe07b7276c6b","price":"0.99","side":"BUY","size":"418.16"},{"asset_id":"8761897749749422724209054078244794145777693856614463256546737399611489089783","best_ask":"0.01","best_bid":"0","hash":"3ea6a4b576acc0d27a1649c6e632e0a3e4ae4421","price":"0.01","side":"SELL","size":"418.16"}],"timestamp":"1785208483181"},"payload_hash":"10e32e0100c3782cf4f8b9afbcb9857e2c39487234ba2378d71a05563dcc8ab2","raw_frame":"{\"market\":\"0x779291bef19b6709f61e9764a954aafe9ffae488d50ae674aabdcb4f248006d5\", \"price_changes\":[{\"asset_id\":\"14965588658799411272385430903075831224615961675357217884735713260981483529984\", \"price\":\"0.99\", \"size\":\"418.16\", \"side\":\"BUY\", \"hash\":\"7fec5a8baa35d5d80541a63066c6fe07b7276c6b\", \"best_bid\":\"0.99\", \"best_ask\":\"1\"}, {\"asset_id\":\"8761897749749422724209054078244794145777693856614463256546737399611489089783\", \"price\":\"0.01\", \"size\":\"418.16\", \"side\":\"SELL\", \"hash\":\"3ea6a4b576acc0d27a1649c6e632e0a3e4ae4421\", \"best_bid\":\"0\", \"best_ask\":\"0.01\"}], \"timestamp\":\"1785208483181\", \"event_type\":\"price_change\"}","received_at":"2026-07-28T03:14:43.014741Z","schema_version":"clob-market-ws.price_change.v1","sequence":null,"server_hash":null,"server_timestamp":"1785208483181","session_id":"3e519d9098404c15b234d96025eb1a2b","source":"clob_market_ws"},"received_at":"2026-07-28T03:14:43.014741Z","record_id":"67fa09782da76459def6f9bb96df9d59435d7c42a2b6ab1196f184ca1678a082","schema_fingerprint":"4aa3821a28b0b7c2400bc59aba4bcc0a76e971dadd19610d3ad38c768e124dc7","schema_version":"edge-lab-recorder.raw.v1","sequence":null,"source":"clob_market_ws"}
{"event_at":"2026-07-28T03:14:43.197000Z","event_fingerprint":"509af512a857d66feb78771115e90e90de40975336933fe274eef788f5bba064","payload":{"connection_id":"a6b55582af5f430fb37ad02bf0922475","event_at":"2026-07-28T03:14:43.197000Z","event_type":"price_change","frame_hash":"72484386bf88a0cf691990f74ce00194d2ad07f0f32bbfabe3cb2715ab4388de","frame_index":0,"kind":"data","monotonic_ns":310466067725958,"payload":{"event_type":"price_change","market":"0x779291bef19b6709f61e9764a954aafe9ffae488d50ae674aabdcb4f248006d5","price_changes":[{"asset_id":"14965588658799411272385430903075831224615961675357217884735713260981483529984","best_ask":"1","best_bid":"0.99","hash":"a4865bf6833c84ff3f9e51ca87af6e5e9773b876","price":"0.01","side":"BUY","size":"5520"},{"asset_id":"8761897749749422724209054078244794145777693856614463256546737399611489089783","best_ask":"0.01","best_bid":"0","hash":"3d2b7b38e01d779a2a68ed9541fe09db9a4d7a40","price":"0.99","side":"SELL","size":"5520"}],"timestamp":"1785208483197"},"payload_hash":"7da03df709a60df708f9f0ba97c67ac146614007e71115fb59949e48a8ec2793","raw_frame":"{\"market\":\"0x779291bef19b6709f61e9764a954aafe9ffae488d50ae674aabdcb4f248006d5\", \"price_changes\":[{\"asset_id\":\"14965588658799411272385430903075831224615961675357217884735713260981483529984\", \"price\":\"0.01\", \"size\":\"5520\", \"side\":\"BUY\", \"hash\":\"a4865bf6833c84ff3f9e51ca87af6e5e9773b876\", \"best_bid\":\"0.99\", \"best_ask\":\"1\"}, {\"asset_id\":\"8761897749749422724209054078244794145777693856614463256546737399611489089783\", \"price\":\"0.99\", \"size\":\"5520\", \"side\":\"SELL\", \"hash\":\"3d2b7b38e01d779a2a68ed9541fe09db9a4d7a40\", \"best_bid\":\"0\", \"best_ask\":\"0.01\"}], \"timestamp\":\"1785208483197\", \"event_type\":\"price_change\"}","received_at":"2026-07-28T03:14:43.031950Z","schema_version":"clob-market-ws.price_change.v1","sequence":null,"server_hash":null,"server_timestamp":"1785208483197","session_id":"3e519d9098404c15b234d96025eb1a2b","source":"clob_market_ws"},"received_at":"2026-07-28T03:14:43.031950Z","record_id":"e91ddd65566bdc7ddccb6b502981921dbcf20ff320176cb9cb970966bc736201","schema_fingerprint":"4aa3821a28b0b7c2400bc59aba4bcc0a76e971dadd19610d3ad38c768e124dc7","schema_version":"edge-lab-recorder.raw.v1","sequence":null,"source":"clob_market_ws"}
{"event_at":"2026-07-28T03:14:43.301000Z","event_fingerprint":"0e67502b8cf4dceaa1bbe50c928fa3ed70c30a8123d499430600fa7f5a77f35d","payload":{"connection_id":"a6b55582af5f430fb37ad02bf0922475","event_at":"2026-07-28T03:14:43.301000Z","event_type":"price_change","frame_hash":"7e0baf1801c8b788a81c2967cc1663e05ed768a4d09680fc7cc96b6adc4a773f","frame_index":0,"kind":"data","monotonic_ns":310466166652916,"payload":{"event_type":"price_change","market":"0x779291bef19b6709f61e9764a954aafe9ffae488d50ae674aabdcb4f248006d5","price_changes":[{"asset_id":"14965588658799411272385430903075831224615961675357217884735713260981483529984","best_ask":"1","best_bid":"0.99","hash":"d2a9567d426415afb5f33ffebb6b0b958cd2caf3","price":"0.01","side":"BUY","size":"5515"},{"asset_id":"8761897749749422724209054078244794145777693856614463256546737399611489089783","best_ask":"0.01","best_bid":"0","hash":"edba6f8d24f9ff7e99b0cd03df4cfa971fcd0aac","price":"0.99","side":"SELL","size":"5515"}],"timestamp":"1785208483301"},"payload_hash":"5a48efefc971cc87e36ac30e5af654b29dafbc33c35d6589e5d20cbae6468a36","raw_frame":"{\"market\":\"0x779291bef19b6709f61e9764a954aafe9ffae488d50ae674aabdcb4f248006d5\", \"price_changes\":[{\"asset_id\":\"14965588658799411272385430903075831224615961675357217884735713260981483529984\", \"price\":\"0.01\", \"size\":\"5515\", \"side\":\"BUY\", \"hash\":\"d2a9567d426415afb5f33ffebb6b0b958cd2caf3\", \"best_bid\":\"0.99\", \"best_ask\":\"1\"}, {\"asset_id\":\"8761897749749422724209054078244794145777693856614463256546737399611489089783\", \"price\":\"0.99\", \"size\":\"5515\", \"side\":\"SELL\", \"hash\":\"edba6f8d24f9ff7e99b0cd03df4cfa971fcd0aac\", \"best_bid\":\"0\", \"best_ask\":\"0.01\"}], \"timestamp\":\"1785208483301\", \"event_type\":\"price_change\"}","received_at":"2026-07-28T03:14:43.130874Z","schema_version":"clob-market-ws.price_change.v1","sequence":null,"server_hash":null,"server_timestamp":"1785208483301","session_id":"3e519d9098404c15b234d96025eb1a2b","source":"clob_market_ws"},"received_at":"2026-07-28T03:14:43.130874Z","record_id":"3ecf3e0dc21668d6b200a994d68a3d29750a9ab12158682028e7eb22eacef213","schema_fingerprint":"4aa3821a28b0b7c2400bc59aba4bcc0a76e971dadd19610d3ad38c768e124dc7","schema_version":"edge-lab-recorder.raw.v1","sequence":null,"source":"clob_market_ws"}
{"event_at":"2026-07-28T03:14:43.303000Z","event_fingerprint":"578dea9785867a807f03a2e4f7e09ba15802769b3e8dfa33e1040c8b80b8bf89","payload":{"connection_id":"a6b55582af5f430fb37ad02bf0922475","event_at":"2026-07-28T03:14:43.303000Z","event_type":"price_change","frame_hash":"a2f78cbcdb5d59132d3289a3183f5b8332143a75c8cb0080b67ec700f45aeffb","frame_index":0,"kind":"data","monotonic_ns":310466170520458,"payload":{"event_type":"price_change","market":"0x779291bef19b6709f61e9764a954aafe9ffae488d50ae674aabdcb4f248006d5","price_changes":[{"asset_id":"14965588658799411272385430903075831224615961675357217884735713260981483529984","best_ask":"1","best_bid":"0.99","hash":"12ff054626d3b8f9b4fc27b50456afd1eaab6e6d","price":"0.99","side":"BUY","size":"391"},{"asset_id":"8761897749749422724209054078244794145777693856614463256546737399611489089783","best_ask":"0.01","best_bid":"0","hash":"75a9a0eac61bed93f6936c1a555f91b2d605d8c9","price":"0.01","side":"SELL","size":"391"}],"timestamp":"1785208483303"},"payload_hash":"47933ab7600adbcae54ed5245835533e4a6592b09f7802c8c3d891cc8a534861","raw_frame":"{\"market\":\"0x779291bef19b6709f61e9764a954aafe9ffae488d50ae674aabdcb4f248006d5\", \"price_changes\":[{\"asset_id\":\"14965588658799411272385430903075831224615961675357217884735713260981483529984\", \"price\":\"0.99\", \"size\":\"391\", \"side\":\"BUY\", \"hash\":\"12ff054626d3b8f9b4fc27b50456afd1eaab6e6d\", \"best_bid\":\"0.99\", \"best_ask\":\"1\"}, {\"asset_id\":\"8761897749749422724209054078244794145777693856614463256546737399611489089783\", \"price\":\"0.01\", \"size\":\"391\", \"side\":\"SELL\", \"hash\":\"75a9a0eac61bed93f6936c1a555f91b2d605d8c9\", \"best_bid\":\"0\", \"best_ask\":\"0.01\"}], \"timestamp\":\"1785208483303\", \"event_type\":\"price_change\"}","received_at":"2026-07-28T03:14:43.134742Z","schema_version":"clob-market-ws.price_change.v1","sequence":null,"server_hash":null,"server_timestamp":"1785208483303","session_id":"3e519d9098404c15b234d96025eb1a2b","source":"clob_market_ws"},"received_at":"2026-07-28T03:14:43.134742Z","record_id":"741bfc2747ee79ac6bcc95395e33763a68a1c3b6500d35f428a19a22d2737ad2","schema_fingerprint":"4aa3821a28b0b7c2400bc59aba4bcc0a76e971dadd19610d3ad38c768e124dc7","schema_version":"edge-lab-recorder.raw.v1","sequence":null,"source":"clob_market_ws"}
{"event_at":"2026-07-28T03:14:43.307000Z","event_fingerprint":"769d0032320f9dcf544e718d7d42d16ea8f92f5a2ae4392ed02df3449b02238e","payload":{"connection_id":"a6b55582af5f430fb37ad02bf0922475","event_at":"2026-07-28T03:14:43.307000Z","event_type":"price_change","frame_hash":"38880be4fd98bd9f5e2eb520ebc48e89710b8d6b30c35001129eb677e1dbc266","frame_index":0,"kind":"data","monotonic_ns":310466172637958,"payload":{"event_type":"price_change","market":"0x779291bef19b6709f61e9764a954aafe9ffae488d50ae674aabdcb4f248006d5","price_changes":[{"asset_id":"14965588658799411272385430903075831224615961675357217884735713260981483529984","best_ask":"1","best_bid":"0.99","hash":"3b444227576a35eee6426f637cbf29595d4c78f7","price":"0.98","side":"BUY","size":"82.99"},{"asset_id":"8761897749749422724209054078244794145777693856614463256546737399611489089783","best_ask":"0.01","best_bid":"0","hash":"5124d884928b8e9ff217efea488b746a2d650484","price":"0.02","side":"SELL","size":"82.99"}],"timestamp":"1785208483307"},"payload_hash":"214b08e92fa07b6ded48b5c39b1f17927bb668f31236dd56fd5f5786e5fd1b44","raw_frame":"{\"market\":\"0x779291bef19b6709f61e9764a954aafe9ffae488d50ae674aabdcb4f248006d5\", \"price_changes\":[{\"asset_id\":\"14965588658799411272385430903075831224615961675357217884735713260981483529984\", \"price\":\"0.98\", \"size\":\"82.99\", \"side\":\"BUY\", \"hash\":\"3b444227576a35eee6426f637cbf29595d4c78f7\", \"best_bid\":\"0.99\", \"best_ask\":\"1\"}, {\"asset_id\":\"8761897749749422724209054078244794145777693856614463256546737399611489089783\", \"price\":\"0.02\", \"size\":\"82.99\", \"side\":\"SELL\", \"hash\":\"5124d884928b8e9ff217efea488b746a2d650484\", \"best_bid\":\"0\", \"best_ask\":\"0.01\"}], \"timestamp\":\"1785208483307\", \"event_type\":\"price_change\"}","received_at":"2026-07-28T03:14:43.136860Z","schema_version":"clob-market-ws.price_change.v1","sequence":null,"server_hash":null,"server_timestamp":"1785208483307","session_id":"3e519d9098404c15b234d96025eb1a2b","source":"clob_market_ws"},"received_at":"2026-07-28T03:14:43.136860Z","record_id":"08642968b1f2b8d47ee28d323e34c9e178689762f21c93b99aec4c14586d5433","schema_fingerprint":"4aa3821a28b0b7c2400bc59aba4bcc0a76e971dadd19610d3ad38c768e124dc7","schema_version":"edge-lab-recorder.raw.v1","sequence":null,"source":"clob_market_ws"}
{"event_at":"2026-07-28T03:14:43.308000Z","event_fingerprint":"a36205d9139756324e12721d0a70d806a6bd874760212c84873c155088abd96f","payload":{"connection_id":"a6b55582af5f430fb37ad02bf0922475","event_at":"2026-07-28T03:14:43.308000Z","event_type":"price_change","frame_hash":"e5b45db61d64dce95ffdbef4b74a5a7278f683583b46728b7217ef8305edbba9","frame_index":0,"kind":"data","monotonic_ns":310466174832416,"payload":{"event_type":"price_change","market":"0x779291bef19b6709f61e9764a954aafe9ffae488d50ae674aabdcb4f248006d5","price_changes":[{"asset_id":"14965588658799411272385430903075831224615961675357217884735713260981483529984","best_ask":"1","best_bid":"0.99","hash":"2372eecebd9bc79182491b4ffb6e1198e2e8e595","price":"0.01","side":"BUY","size":"5521.24"},{"asset_id":"8761897749749422724209054078244794145777693856614463256546737399611489089783","best_ask":"0.01","best_bid":"0","hash":"a946399ae0937f15cc7b638a3ab4085d69712b90","price":"0.99","side":"SELL","size":"5521.24"}],"timestamp":"1785208483308"},"payload_hash":"30b93b24f921902b25cca4a740baf19aa11f17f0062af91c78de68e36431f0d2","raw_frame":"{\"market\":\"0x779291bef19b6709f61e9764a954aafe9ffae488d50ae674aabdcb4f248006d5\", \"price_changes\":[{\"asset_id\":\"14965588658799411272385430903075831224615961675357217884735713260981483529984\", \"price\":\"0.01\", \"size\":\"5521.24\", \"side\":\"BUY\", \"hash\":\"2372eecebd9bc79182491b4ffb6e1198e2e8e595\", \"best_bid\":\"0.99\", \"best_ask\":\"1\"}, {\"asset_id\":\"8761897749749422724209054078244794145777693856614463256546737399611489089783\", \"price\":\"0.99\", \"size\":\"5521.24\", \"side\":\"SELL\", \"hash\":\"a946399ae0937f15cc7b638a3ab4085d69712b90\", \"best_bid\":\"0\", \"best_ask\":\"0.01\"}], \"timestamp\":\"1785208483308\", \"event_type\":\"price_change\"}","received_at":"2026-07-28T03:14:43.139056Z","schema_version":"clob-market-ws.price_change.v1","sequence":null,"server_hash":null,"server_timestamp":"1785208483308","session_id":"3e519d9098404c15b234d96025eb1a2b","source":"clob_market_ws"},"received_at":"2026-07-28T03:14:43.139056Z","record_id":"7e38a666c692be322f42c1b8177685baaae1c9677bf438c3a62fc33731875986","schema_fingerprint":"4aa3821a28b0b7c2400bc59aba4bcc0a76e971dadd19610d3ad38c768e124dc7","schema_version":"edge-lab-recorder.raw.v1","sequence":null,"source":"clob_market_ws"}
{"event_at":"2026-07-28T03:14:43.309000Z","event_fingerprint":"9e5a78a30bf683d7a26349da2338e0adb66da7137d0f97b597003b5c892fd8f2","payload":{"connection_id":"a6b55582af5f430fb37ad02bf0922475","event_at":"2026-07-28T03:14:43.309000Z","event_type":"price_change","frame_hash":"4c6143cdf510ba43715198af24bd5e7a5bbff2da99eeb3f7918a385641a996d7","frame_index":0,"kind":"data","monotonic_ns":310466176388458,"payload":{"event_type":"price_change","market":"0x779291bef19b6709f61e9764a954aafe9ffae488d50ae674aabdcb4f248006d5","price_changes":[{"asset_id":"8761897749749422724209054078244794145777693856614463256546737399611489089783","best_ask":"0.01","best_bid":"0","hash":"8e50f9efecffef598baf9d7f2c098ce399cb4578","price":"0.01","side":"SELL","size":"435"},{"asset_id":"14965588658799411272385430903075831224615961675357217884735713260981483529984","best_ask":"1","best_bid":"0.99","hash":"bcf8d8aa202fcfc904820d010fe346024066a130","price":"0.99","side":"BUY","size":"435"}],"timestamp":"1785208483309"},"payload_hash":"b74e1daf1c4980a150f7e8fae6d66e146e6ae5ac877e203512757c6d61b90b7e","raw_frame":"{\"market\":\"0x779291bef19b6709f61e9764a954aafe9ffae488d50ae674aabdcb4f248006d5\", \"price_changes\":[{\"asset_id\":\"8761897749749422724209054078244794145777693856614463256546737399611489089783\", \"price\":\"0.01\", \"size\":\"435\", \"side\":\"SELL\", \"hash\":\"8e50f9efecffef598baf9d7f2c098ce399cb4578\", \"best_bid\":\"0\", \"best_ask\":\"0.01\"}, {\"asset_id\":\"14965588658799411272385430903075831224615961675357217884735713260981483529984\", \"price\":\"0.99\", \"size\":\"435\", \"side\":\"BUY\", \"hash\":\"bcf8d8aa202fcfc904820d010fe346024066a130\", \"best_bid\":\"0.99\", \"best_ask\":\"1\"}], \"timestamp\":\"1785208483309\", \"event_type\":\"price_change\"}","received_at":"2026-07-28T03:14:43.140610Z","schema_version":"clob-market-ws.price_change.v1","sequence":null,"server_hash":null,"server_timestamp":"1785208483309","session_id":"3e519d9098404c15b234d96025eb1a2b","source":"clob_market_ws"},"received_at":"2026-07-28T03:14:43.140610Z","record_id":"9025a5228c7607cb3c5abf1f826801052d1b7ff9a4805b95e48a0ec9a816e640","schema_fingerprint":"4aa3821a28b0b7c2400bc59aba4bcc0a76e971dadd19610d3ad38c768e124dc7","schema_version":"edge-lab-recorder.raw.v1","sequence":null,"source":"clob_market_ws"}
{"event_at":"2026-07-28T03:14:43.316000Z","event_fingerprint":"5f52623bd139cffc95e297a336af304232437100a7b96612faae31dc47096743","payload":{"connection_id":"a6b55582af5f430fb37ad02bf0922475","event_at":"2026-07-28T03:14:43.316000Z","event_type":"price_change","frame_hash":"ec01159e8c69b5973bff57f3af9cd7d5f32e7a803e2de6c4872ec93e98d9cc47","frame_index":0,"kind":"data","monotonic_ns":310466182146208,"payload":{"event_type":"price_change","market":"0x779291bef19b6709f61e9764a954aafe9ffae488d50ae674aabdcb4f248006d5","price_changes":[{"asset_id":"14965588658799411272385430903075831224615961675357217884735713260981483529984","best_ask":"1","best_bid":"0.99","hash":"30adafb57da5cde45fc6d0233c22e5fd029b234f","price":"0.01","side":"BUY","size":"5526.24"},{"asset_id":"8761897749749422724209054078244794145777693856614463256546737399611489089783","best_ask":"0.01","best_bid":"0","hash":"eed7bb78f92dcbf4cf5e589f52e513c99f3aa67e","price":"0.99","side":"SELL","size":"5526.24"}],"timestamp":"1785208483316"},"payload_hash":"a12e2cc1532594d2e4d6ca2d4de01f4421dc5a48b19f42d5c8f7272dc582f212","raw_frame":"{\"market\":\"0x779291bef19b6709f61e9764a954aafe9ffae488d50ae674aabdcb4f248006d5\", \"price_changes\":[{\"asset_id\":\"14965588658799411272385430903075831224615961675357217884735713260981483529984\", \"price\":\"0.01\", \"size\":\"5526.24\", \"side\":\"BUY\", \"hash\":\"30adafb57da5cde45fc6d0233c22e5fd029b234f\", \"best_bid\":\"0.99\", \"best_ask\":\"1\"}, {\"asset_id\":\"8761897749749422724209054078244794145777693856614463256546737399611489089783\", \"price\":\"0.99\", \"size\":\"5526.24\", \"side\":\"SELL\", \"hash\":\"eed7bb78f92dcbf4cf5e589f52e513c99f3aa67e\", \"best_bid\":\"0\", \"best_ask\":\"0.01\"}], \"timestamp\":\"1785208483316\", \"event_type\":\"price_change\"}","received_at":"2026-07-28T03:14:43.146371Z","schema_version":"clob-market-ws.price_change.v1","sequence":null,"server_hash":null,"server_timestamp":"1785208483316","session_id":"3e519d9098404c15b234d96025eb1a2b","source":"clob_market_ws"},"received_at":"2026-07-28T03:14:43.146371Z","record_id":"f65e6c82bc5b67eda407f10dd600aa028a85533d6d1468222aa0e85bd15f7cef","schema_fingerprint":"4aa3821a28b0b7c2400bc59aba4bcc0a76e971dadd19610d3ad38c768e124dc7","schema_version":"edge-lab-recorder.raw.v1","sequence":null,"source":"clob_market_ws"}
{"event_at":"2026-07-28T03:14:43.338000Z","event_fingerprint":"a39119c90bce56aa655c516c9f9e30575b8393cf4c2fd4c7badca43cf1df881c","payload":{"connection_id":"a6b55582af5f430fb37ad02bf0922475","event_at":"2026-07-28T03:14:43.338000Z","event_type":"price_change","frame_hash":"c371115fab652f1ce292917582e14958e01818ca8ba2e4a90ac3e792dcb9f87c","frame_index":0,"kind":"data","monotonic_ns":310466204500041,"payload":{"event_type":"price_change","market":"0x779291bef19b6709f61e9764a954aafe9ffae488d50ae674aabdcb4f248006d5","price_changes":[{"asset_id":"14965588658799411272385430903075831224615961675357217884735713260981483529984","best_ask":"1","best_bid":"0.99","hash":"56bb5d87299d072e856d1d20cfeea47815f2d2ae","price":"0.01","side":"BUY","size":"5521.24"},{"asset_id":"8761897749749422724209054078244794145777693856614463256546737399611489089783","best_ask":"0.01","best_bid":"0","hash":"eb2d17080f68f6947282471143f824b04d68a0e0","price":"0.99","side":"SELL","size":"5521.24"}],"timestamp":"1785208483338"},"payload_hash":"5e63bb0cc2866e23ddee09fedde1cab54fd9234168d6b562ce983824f864cbd6","raw_frame":"{\"market\":\"0x779291bef19b6709f61e9764a954aafe9ffae488d50ae674aabdcb4f248006d5\", \"price_changes\":[{\"asset_id\":\"14965588658799411272385430903075831224615961675357217884735713260981483529984\", \"price\":\"0.01\", \"size\":\"5521.24\", \"side\":\"BUY\", \"hash\":\"56bb5d87299d072e856d1d20cfeea47815f2d2ae\", \"best_bid\":\"0.99\", \"best_ask\":\"1\"}, {\"asset_id\":\"8761897749749422724209054078244794145777693856614463256546737399611489089783\", \"price\":\"0.99\", \"size\":\"5521.24\", \"side\":\"SELL\", \"hash\":\"eb2d17080f68f6947282471143f824b04d68a0e0\", \"best_bid\":\"0\", \"best_ask\":\"0.01\"}], \"timestamp\":\"1785208483338\", \"event_type\":\"price_change\"}","received_at":"2026-07-28T03:14:43.168724Z","schema_version":"clob-market-ws.price_change.v1","sequence":null,"server_hash":null,"server_timestamp":"1785208483338","session_id":"3e519d9098404c15b234d96025eb1a2b","source":"clob_market_ws"},"received_at":"2026-07-28T03:14:43.168724Z","record_id":"f0fc2591130825154d1b7b2e0f1d368dc6fd9bf72f30738de47bd773fe71b8d2","schema_fingerprint":"4aa3821a28b0b7c2400bc59aba4bcc0a76e971dadd19610d3ad38c768e124dc7","schema_version":"edge-lab-recorder.raw.v1","sequence":null,"source":"clob_market_ws"}
{"event_at":"2026-07-28T03:14:43.354000Z","event_fingerprint":"a0ea370bcb93dcbf6df4fc1ec43a4a4a0a1a96db6bb96a5937bb9239882fc1c3","payload":{"connection_id":"a6b55582af5f430fb37ad02bf0922475","event_at":"2026-07-28T03:14:43.354000Z","event_type":"price_change","frame_hash":"15ad86f15fa06f57c09ff30db6897facb8345c8f249b1fa67c9ac769b404f020","frame_index":0,"kind":"data","monotonic_ns":310466219947666,"payload":{"event_type":"price_change","market":"0x779291bef19b6709f61e9764a954aafe9ffae488d50ae674aabdcb4f248006d5","price_changes":[{"asset_id":"14965588658799411272385430903075831224615961675357217884735713260981483529984","best_ask":"1","best_bid":"0.99","hash":"b4f65621e5d9c3e89dc99825abb72427e1cba62d","price":"0.01","side":"BUY","size":"5526.24"},{"asset_id":"8761897749749422724209054078244794145777693856614463256546737399611489089783","best_ask":"0.01","best_bid":"0","hash":"6bdc75823bb7aac48c5633f460669dce7ebe201a","price":"0.99","side":"SELL","size":"5526.24"}],"timestamp":"1785208483354"},"payload_hash":"60752420250219a626c5917a12bf806be55fcca67af4d49b52f0db3dad02598e","raw_frame":"{\"market\":\"0x779291bef19b6709f61e9764a954aafe9ffae488d50ae674aabdcb4f248006d5\", \"price_changes\":[{\"asset_id\":\"14965588658799411272385430903075831224615961675357217884735713260981483529984\", \"price\":\"0.01\", \"size\":\"5526.24\", \"side\":\"BUY\", \"hash\":\"b4f65621e5d9c3e89dc99825abb72427e1cba62d\", \"best_bid\":\"0.99\", \"best_ask\":\"1\"}, {\"asset_id\":\"8761897749749422724209054078244794145777693856614463256546737399611489089783\", \"price\":\"0.99\", \"size\":\"5526.24\", \"side\":\"SELL\", \"hash\":\"6bdc75823bb7aac48c5633f460669dce7ebe201a\", \"best_bid\":\"0\", \"best_ask\":\"0.01\"}], \"timestamp\":\"1785208483354\", \"event_type\":\"price_change\"}","received_at":"2026-07-28T03:14:43.184171Z","schema_version":"clob-market-ws.price_change.v1","sequence":null,"server_hash":null,"server_timestamp":"1785208483354","session_id":"3e519d9098404c15b234d96025eb1a2b","source":"clob_market_ws"},"received_at":"2026-07-28T03:14:43.184171Z","record_id":"2023e0f3a342949eb74a77e2f80b1b9ac360b81cfecd0db0207e9929714785bc","schema_fingerprint":"4aa3821a28b0b7c2400bc59aba4bcc0a76e971dadd19610d3ad38c768e124dc7","schema_version":"edge-lab-recorder.raw.v1","sequence":null,"source":"clob_market_ws"}
{"event_at":"2026-07-28T03:14:43.378000Z","event_fingerprint":"49e861f98605df3f9fc38b9f675f7cf8b629c3fbfc04a72f10df3faf0e6b45f7","payload":{"connection_id":"a6b55582af5f430fb37ad02bf0922475","event_at":"2026-07-28T03:14:43.378000Z","event_type":"price_change","frame_hash":"f6eaa2fe52751249967d3dd0b014f28f75e070b63a8f0b7e3612ea55ab5fdd94","frame_index":0,"kind":"data","monotonic_ns":310466243801166,"payload":{"event_type":"price_change","market":"0x779291bef19b6709f61e9764a954aafe9ffae488d50ae674aabdcb4f248006d5","price_changes":[{"asset_id":"14965588658799411272385430903075831224615961675357217884735713260981483529984","best_ask":"1","best_bid":"0.99","hash":"dbb95f9a293cf31beca0dec6aa9dc714167bc253","price":"0.04","side":"BUY","size":"535"},{"asset_id":"8761897749749422724209054078244794145777693856614463256546737399611489089783","best_ask":"0.01","best_bid":"0","hash":"c5f71496cfe857428673600065512c73131acd9e","price":"0.96","side":"SELL","size":"535"}],"timestamp":"1785208483378"},"payload_hash":"95405ad9c4feafca7200fd222d4efc28205c47148cbf7b06c87dbbd68598e5f2","raw_frame":"{\"market\":\"0x779291bef19b6709f61e9764a954aafe9ffae488d50ae674aabdcb4f248006d5\", \"price_changes\":[{\"asset_id\":\"14965588658799411272385430903075831224615961675357217884735713260981483529984\", \"price\":\"0.04\", \"size\":\"535\", \"side\":\"BUY\", \"hash\":\"dbb95f9a293cf31beca0dec6aa9dc714167bc253\", \"best_bid\":\"0.99\", \"best_ask\":\"1\"}, {\"asset_id\":\"8761897749749422724209054078244794145777693856614463256546737399611489089783\", \"price\":\"0.96\", \"size\":\"535\", \"side\":\"SELL\", \"hash\":\"c5f71496cfe857428673600065512c73131acd9e\", \"best_bid\":\"0\", \"best_ask\":\"0.01\"}], \"timestamp\":\"1785208483378\", \"event_type\":\"price_change\"}","received_at":"2026-07-28T03:14:43.208022Z","schema_version":"clob-market-ws.price_change.v1","sequence":null,"server_hash":null,"server_timestamp":"1785208483378","session_id":"3e519d9098404c15b234d96025eb1a2b","source":"clob_market_ws"},"received_at":"2026-07-28T03:14:43.208022Z","record_id":"bac1ea7f8dc713a1308c73c298b5f3cf32b98172678727f2e2eea38e88d2a05b","schema_fingerprint":"4aa3821a28b0b7c2400bc59aba4bcc0a76e971dadd19610d3ad38c768e124dc7","schema_version":"edge-lab-recorder.raw.v1","sequence":null,"source":"clob_market_ws"}
{"event_at":"2026-07-28T03:14:43.379000Z","event_fingerprint":"88d2e728311156a615aa6d73823c07ecaf31e4dced308818b38d6fb81748657b","payload":{"connection_id":"a6b55582af5f430fb37ad02bf0922475","event_at":"2026-07-28T03:14:43.379000Z","event_type":"price_change","frame_hash":"459d244243b298714a41731dd0b375a8b1d6325462d23e9711c00f568a91554d","frame_index":0,"kind":"data","monotonic_ns":310466246003083,"payload":{"event_type":"price_change","market":"0x779291bef19b6709f61e9764a954aafe9ffae488d50ae674aabdcb4f248006d5","price_changes":[{"asset_id":"14965588658799411272385430903075831224615961675357217884735713260981483529984","best_ask":"1","best_bid":"0.99","hash":"873668d603f32e42d33c0734f7ab64d1fac1185f","price":"0.01","side":"BUY","size":"5521.24"},{"asset_id":"8761897749749422724209054078244794145777693856614463256546737399611489089783","best_ask":"0.01","best_bid":"0","hash":"5337b93c06b8c3c511ba21ff4338af6297505e3e","price":"0.99","side":"SELL","size":"5521.24"}],"timestamp":"1785208483379"},"payload_hash":"a0dcc66189a1c920ba4cb638423593ecde32793a19673d6d778f3c337622e1cd","raw_frame":"{\"market\":\"0x779291bef19b6709f61e9764a954aafe9ffae488d50ae674aabdcb4f248006d5\", \"price_changes\":[{\"asset_id\":\"14965588658799411272385430903075831224615961675357217884735713260981483529984\", \"price\":\"0.01\", \"size\":\"5521.24\", \"side\":\"BUY\", \"hash\":\"873668d603f32e42d33c0734f7ab64d1fac1185f\", \"best_bid\":\"0.99\", \"best_ask\":\"1\"}, {\"asset_id\":\"8761897749749422724209054078244794145777693856614463256546737399611489089783\", \"price\":\"0.99\", \"size\":\"5521.24\", \"side\":\"SELL\", \"hash\":\"5337b93c06b8c3c511ba21ff4338af6297505e3e\", \"best_bid\":\"0\", \"best_ask\":\"0.01\"}], \"timestamp\":\"1785208483379\", \"event_type\":\"price_change\"}","received_at":"2026-07-28T03:14:43.210227Z","schema_version":"clob-market-ws.price_change.v1","sequence":null,"server_hash":null,"server_timestamp":"1785208483379","session_id":"3e519d9098404c15b234d96025eb1a2b","source":"clob_market_ws"},"received_at":"2026-07-28T03:14:43.210227Z","record_id":"16124bde4e5d53a39b3d01c6e9cc33852ab47deab267ab1be810996c227146ab","schema_fingerprint":"4aa3821a28b0b7c2400bc59aba4bcc0a76e971dadd19610d3ad38c768e124dc7","schema_version":"edge-lab-recorder.raw.v1","sequence":null,"source":"clob_market_ws"}
{"event_at":"2026-07-28T03:14:43.403000Z","event_fingerprint":"ae601bd3f4d85a06ba888b7bb4cda458b334a16357d48cb6ad69483e782afec8","payload":{"connection_id":"a6b55582af5f430fb37ad02bf0922475","event_at":"2026-07-28T03:14:43.403000Z","event_type":"price_change","frame_hash":"f306da7653be4996eac9d9947188a5709a7f210b8b74a2ad9508ce6e4029c6eb","frame_index":0,"kind":"data","monotonic_ns":310466276166250,"payload":{"event_type":"price_change","market":"0x779291bef19b6709f61e9764a954aafe9ffae488d50ae674aabdcb4f248006d5","price_changes":[{"asset_id":"14965588658799411272385430903075831224615961675357217884735713260981483529984","best_ask":"1","best_bid":"0.99","hash":"50ab3b60ce6496da764d9e950368319e5387a152","price":"0.01","side":"BUY","size":"5515"},{"asset_id":"8761897749749422724209054078244794145777693856614463256546737399611489089783","best_ask":"0.01","best_bid":"0","hash":"3d2303e17247325699159975f92d08a36c8a7c70","price":"0.99","side":"SELL","size":"5515"}],"timestamp":"1785208483403"},"payload_hash":"0e183c481210e6afe1e22c671d68cae73f1a98ac215e367591b71ef4ef8cbee2","raw_frame":"{\"market\":\"0x779291bef19b6709f61e9764a954aafe9ffae488d50ae674aabdcb4f248006d5\", \"price_changes\":[{\"asset_id\":\"14965588658799411272385430903075831224615961675357217884735713260981483529984\", \"price\":\"0.01\", \"size\":\"5515\", \"side\":\"BUY\", \"hash\":\"50ab3b60ce6496da764d9e950368319e5387a152\", \"best_bid\":\"0.99\", \"best_ask\":\"1\"}, {\"asset_id\":\"8761897749749422724209054078244794145777693856614463256546737399611489089783\", \"price\":\"0.99\", \"size\":\"5515\", \"side\":\"SELL\", \"hash\":\"3d2303e17247325699159975f92d08a36c8a7c70\", \"best_bid\":\"0\", \"best_ask\":\"0.01\"}], \"timestamp\":\"1785208483403\", \"event_type\":\"price_change\"}","received_at":"2026-07-28T03:14:43.240386Z","schema_version":"clob-market-ws.price_change.v1","sequence":null,"server_hash":null,"server_timestamp":"1785208483403","session_id":"3e519d9098404c15b234d96025eb1a2b","source":"clob_market_ws"},"received_at":"2026-07-28T03:14:43.240386Z","record_id":"0bf085afa16f1df4a3d00e54c4bc74914f0f3c847a2bab344dec7047b752e012","schema_fingerprint":"4aa3821a28b0b7c2400bc59aba4bcc0a76e971dadd19610d3ad38c768e124dc7","schema_version":"edge-lab-recorder.raw.v1","sequence":null,"source":"clob_market_ws"}
{"event_at":"2026-07-28T03:14:43.404000Z","event_fingerprint":"8458a4bf190726ff584354706375ab454bb019375e1267c68dec1a02cb0bde13","payload":{"connection_id":"a6b55582af5f430fb37ad02bf0922475","event_at":"2026-07-28T03:14:43.404000Z","event_type":"price_change","frame_hash":"9f4a5f678807191b7fb78690bde7427b9d1abb563daa9f1eb7aa0633be8ad187","frame_index":0,"kind":"data","monotonic_ns":310466277902166,"payload":{"event_type":"price_change","market":"0x779291bef19b6709f61e9764a954aafe9ffae488d50ae674aabdcb4f248006d5","price_changes":[{"asset_id":"8761897749749422724209054078244794145777693856614463256546737399611489089783","best_ask":"0.01","best_bid":"0","hash":"119015bdcb3914945ef560910e81631051b6479e","price":"0.01","side":"SELL","size":"391"},{"asset_id":"14965588658799411272385430903075831224615961675357217884735713260981483529984","best_ask":"1","best_bid":"0.99","hash":"cbb5c0961eea2a6ae246ed6074bfbd93c75419d1","price":"0.99","side":"BUY","size":"391"}],"timestamp":"1785208483404"},"payload_hash":"12a5e1a4db40607d951542b1ac7aa863b91848fc9f706ca2ad3ca447aa8b4e8d","raw_frame":"{\"market\":\"0x779291bef19b6709f61e9764a954aafe9ffae488d50ae674aabdcb4f248006d5\", \"price_changes\":[{\"asset_id\":\"8761897749749422724209054078244794145777693856614463256546737399611489089783\", \"price\":\"0.01\", \"size\":\"391\", \"side\":\"SELL\", \"hash\":\"119015bdcb3914945ef560910e81631051b6479e\", \"best_bid\":\"0\", \"best_ask\":\"0.01\"}, {\"asset_id\":\"14965588658799411272385430903075831224615961675357217884735713260981483529984\", \"price\":\"0.99\", \"size\":\"391\", \"side\":\"BUY\", \"hash\":\"cbb5c0961eea2a6ae246ed6074bfbd93c75419d1\", \"best_bid\":\"0.99\", \"best_ask\":\"1\"}], \"timestamp\":\"1785208483404\", \"event_type\":\"price_change\"}","received_at":"2026-07-28T03:14:43.242126Z","schema_version":"clob-market-ws.price_change.v1","sequence":null,"server_hash":null,"server_timestamp":"1785208483404","session_id":"3e519d9098404c15b234d96025eb1a2b","source":"clob_market_ws"},"received_at":"2026-07-28T03:14:43.242126Z","record_id":"bbc9ea906b783e435e14d8a447f47f978428304dc933b8c1bc9c1a261b492320","schema_fingerprint":"4aa3821a28b0b7c2400bc59aba4bcc0a76e971dadd19610d3ad38c768e124dc7","schema_version":"edge-lab-recorder.raw.v1","sequence":null,"source":"clob_market_ws"}
{"event_at":"2026-07-28T03:14:43.405000Z","event_fingerprint":"d4703f4473c7cbc5a8171cf6386a7130c1c7780555ed80c5002a8854019ec225","payload":{"connection_id":"a6b55582af5f430fb37ad02bf0922475","event_at":"2026-07-28T03:14:43.405000Z","event_type":"price_change","frame_hash":"74bf103f801d0e6e21869c6164d8096d2efe30038f52153796cc09cb228dc84d","frame_index":0,"kind":"data","monotonic_ns":310466279467500,"payload":{"event_type":"price_change","market":"0x779291bef19b6709f61e9764a954aafe9ffae488d50ae674aabdcb4f248006d5","price_changes":[{"asset_id":"14965588658799411272385430903075831224615961675357217884735713260981483529984","best_ask":"1","best_bid":"0.99","hash":"e452755bc8986dbc88fb654883054ceadf34d923","price":"0.98","side":"BUY","size":"55.61"},{"asset_id":"8761897749749422724209054078244794145777693856614463256546737399611489089783","best_ask":"0.01","best_bid":"0","hash":"541a85ba3e8e0ec966ff687753c9058034bdc111","price":"0.02","side":"SELL","size":"55.61"}],"timestamp":"1785208483405"},"payload_hash":"54edd2bff7e71da4103bcc77a586378ef683226987da1401a318328d42c09278","raw_frame":"{\"market\":\"0x779291bef19b6709f61e9764a954aafe9ffae488d50ae674aabdcb4f248006d5\", \"price_changes\":[{\"asset_id\":\"14965588658799411272385430903075831224615961675357217884735713260981483529984\", \"price\":\"0.98\", \"size\":\"55.61\", \"side\":\"BUY\", \"hash\":\"e452755bc8986dbc88fb654883054ceadf34d923\", \"best_bid\":\"0.99\", \"best_ask\":\"1\"}, {\"asset_id\":\"8761897749749422724209054078244794145777693856614463256546737399611489089783\", \"price\":\"0.02\", \"size\":\"55.61\", \"side\":\"SELL\", \"hash\":\"541a85ba3e8e0ec966ff687753c9058034bdc111\", \"best_bid\":\"0\", \"best_ask\":\"0.01\"}], \"timestamp\":\"1785208483405\", \"event_type\":\"price_change\"}","received_at":"2026-07-28T03:14:43.243691Z","schema_version":"clob-market-ws.price_change.v1","sequence":null,"server_hash":null,"server_timestamp":"1785208483405","session_id":"3e519d9098404c15b234d96025eb1a2b","source":"clob_market_ws"},"received_at":"2026-07-28T03:14:43.243691Z","record_id":"791d20788a2819663eb8f71b98e8a6268b0ebef037f216445fc45e0b1d8f149f","schema_fingerprint":"4aa3821a28b0b7c2400bc59aba4bcc0a76e971dadd19610d3ad38c768e124dc7","schema_version":"edge-lab-recorder.raw.v1","sequence":null,"source":"clob_market_ws"}
{"event_at":"2026-07-28T03:14:43.406000Z","event_fingerprint":"3858b82ca609426723e2b107308e49adecc08f115c7b464fc2fe5dcb47806697","payload":{"connection_id":"a6b55582af5f430fb37ad02bf0922475","event_at":"2026-07-28T03:14:43.406000Z","event_type":"price_change","frame_hash":"e0678fb7d997aa07c157940b258d70a1ea4c579e97413a2ff5f667c1c4f5eed2","frame_index":0,"kind":"data","monotonic_ns":310466281016500,"payload":{"event_type":"price_change","market":"0x779291bef19b6709f61e9764a954aafe9ffae488d50ae674aabdcb4f248006d5","price_changes":[{"asset_id":"14965588658799411272385430903075831224615961675357217884735713260981483529984","best_ask":"1","best_bid":"0.99","hash":"2eca8b0185e08539ec3d28d148dfd326a4a49706","price":"0.99","side":"BUY","size":"418.16"},{"asset_id":"8761897749749422724209054078244794145777693856614463256546737399611489089783","best_ask":"0.01","best_bid":"0","hash":"023106bc183e2bb6597414fe3bc7a52929f0cffd","price":"0.01","side":"SELL","size":"418.16"}],"timestamp":"1785208483406"},"payload_hash":"9a13362f421d1376e6f25726f90d0b191af1dc0ebc4a8b5af56d28a06bdba0f9","raw_frame":"{\"market\":\"0x779291bef19b6709f61e9764a954aafe9ffae488d50ae674aabdcb4f248006d5\", \"price_changes\":[{\"asset_id\":\"14965588658799411272385430903075831224615961675357217884735713260981483529984\", \"price\":\"0.99\", \"size\":\"418.16\", \"side\":\"BUY\", \"hash\":\"2eca8b0185e08539ec3d28d148dfd326a4a49706\", \"best_bid\":\"0.99\", \"best_ask\":\"1\"}, {\"asset_id\":\"8761897749749422724209054078244794145777693856614463256546737399611489089783\", \"price\":\"0.01\", \"size\":\"418.16\", \"side\":\"SELL\", \"hash\":\"023106bc183e2bb6597414fe3bc7a52929f0cffd\", \"best_bid\":\"0\", \"best_ask\":\"0.01\"}], \"timestamp\":\"1785208483406\", \"event_type\":\"price_change\"}","received_at":"2026-07-28T03:14:43.245241Z","schema_version":"clob-market-ws.price_change.v1","sequence":null,"server_hash":null,"server_timestamp":"1785208483406","session_id":"3e519d9098404c15b234d96025eb1a2b","source":"clob_market_ws"},"received_at":"2026-07-28T03:14:43.245241Z","record_id":"dbc29c2f2ba489e4823e026e4e365ba5ac0a0b3647bf081e67cca9d6ad42194d","schema_fingerprint":"4aa3821a28b0b7c2400bc59aba4bcc0a76e971dadd19610d3ad38c768e124dc7","schema_version":"edge-lab-recorder.raw.v1","sequence":null,"source":"clob_market_ws"}
{"event_at":"2026-07-28T03:14:43.433000Z","event_fingerprint":"43026057304a9bb904bbae394381ba452d95f8b73538ab7c94ca8238a3a144ae","payload":{"connection_id":"a6b55582af5f430fb37ad02bf0922475","event_at":"2026-07-28T03:14:43.433000Z","event_type":"price_change","frame_hash":"5a8353681d9bd886dc311d3d8a0bc5fb95119620e96503b8c56ddee726e2980c","frame_index":0,"kind":"data","monotonic_ns":310466298841666,"payload":{"event_type":"price_change","market":"0x779291bef19b6709f61e9764a954aafe9ffae488d50ae674aabdcb4f248006d5","price_changes":[{"asset_id":"14965588658799411272385430903075831224615961675357217884735713260981483529984","best_ask":"1","best_bid":"0.99","hash":"e7e43a22ba255f09a66fc21695b701087c3d87fb","price":"0.04","side":"BUY","size":"530"},{"asset_id":"8761897749749422724209054078244794145777693856614463256546737399611489089783","best_ask":"0.01","best_bid":"0","hash":"5a16586ca78e765451e9f9bd94e98d326a798b0f","price":"0.96","side":"SELL","size":"530"}],"timestamp":"1785208483433"},"payload_hash":"be3c7c08f257a271045b1e39c45d6fccdf1e20cd199fdbb2924b00ab478b7bdd","raw_frame":"{\"market\":\"0x779291bef19b6709f61e9764a954aafe9ffae488d50ae674aabdcb4f248006d5\", \"price_changes\":[{\"asset_id\":\"14965588658799411272385430903075831224615961675357217884735713260981483529984\", \"price\":\"0.04\", \"size\":\"530\", \"side\":\"BUY\", \"hash\":\"e7e43a22ba255f09a66fc21695b701087c3d87fb\", \"best_bid\":\"0.99\", \"best_ask\":\"1\"}, {\"asset_id\":\"8761897749749422724209054078244794145777693856614463256546737399611489089783\", \"price\":\"0.96\", \"size\":\"530\", \"side\":\"SELL\", \"hash\":\"5a16586ca78e765451e9f9bd94e98d326a798b0f\", \"best_bid\":\"0\", \"best_ask\":\"0.01\"}], \"timestamp\":\"1785208483433\", \"event_type\":\"price_change\"}","received_at":"2026-07-28T03:14:43.263065Z","schema_version":"clob-market-ws.price_change.v1","sequence":null,"server_hash":null,"server_timestamp":"1785208483433","session_id":"3e519d9098404c15b234d96025eb1a2b","source":"clob_market_ws"},"received_at":"2026-07-28T03:14:43.263065Z","record_id":"2c42d87028276c75feb68e7311b34f941448df839368df97c3725b78414f4af8","schema_fingerprint":"4aa3821a28b0b7c2400bc59aba4bcc0a76e971dadd19610d3ad38c768e124dc7","schema_version":"edge-lab-recorder.raw.v1","sequence":null,"source":"clob_market_ws"}
{"event_at":"2026-07-28T03:14:43.513000Z","event_fingerprint":"e2d5ae238c00e455360089c93b7b26df8b002ba693e6535e448da45ad90009be","payload":{"connection_id":"a6b55582af5f430fb37ad02bf0922475","event_at":"2026-07-28T03:14:43.513000Z","event_type":"price_change","frame_hash":"0c4f9ac053f157cd54cfb394292b4f1712ff7546f8e10b5e10f08a95d045a678","frame_index":0,"kind":"data","monotonic_ns":310466380988458,"payload":{"event_type":"price_change","market":"0x779291bef19b6709f61e9764a954aafe9ffae488d50ae674aabdcb4f248006d5","price_changes":[{"asset_id":"14965588658799411272385430903075831224615961675357217884735713260981483529984","best_ask":"1","best_bid":"0.99","hash":"9d7bc662d0708dc7040fbd88f32ae0ee60977e5c","price":"0.99","side":"BUY","size":"391"},{"asset_id":"8761897749749422724209054078244794145777693856614463256546737399611489089783","best_ask":"0.01","best_bid":"0","hash":"5b4a865b99de1fca570b9a0a70fe22e5fd3341ee","price":"0.01","side":"SELL","size":"391"}],"timestamp":"1785208483513"},"payload_hash":"1b0e228dfa3a0ae9fc09c9fbb0453c022223c79c20c12b0d399ea04cfd514365","raw_frame":"{\"market\":\"0x779291bef19b6709f61e9764a954aafe9ffae488d50ae674aabdcb4f248006d5\", \"price_changes\":[{\"asset_id\":\"14965588658799411272385430903075831224615961675357217884735713260981483529984\", \"price\":\"0.99\", \"size\":\"391\", \"side\":\"BUY\", \"hash\":\"9d7bc662d0708dc7040fbd88f32ae0ee60977e5c\", \"best_bid\":\"0.99\", \"best_ask\":\"1\"}, {\"asset_id\":\"8761897749749422724209054078244794145777693856614463256546737399611489089783\", \"price\":\"0.01\", \"size\":\"391\", \"side\":\"SELL\", \"hash\":\"5b4a865b99de1fca570b9a0a70fe22e5fd3341ee\", \"best_bid\":\"0\", \"best_ask\":\"0.01\"}], \"timestamp\":\"1785208483513\", \"event_type\":\"price_change\"}","received_at":"2026-07-28T03:14:43.345207Z","schema_version":"clob-market-ws.price_change.v1","sequence":null,"server_hash":null,"server_timestamp":"1785208483513","session_id":"3e519d9098404c15b234d96025eb1a2b","source":"clob_market_ws"},"received_at":"2026-07-28T03:14:43.345207Z","record_id":"cce290dcc089e9b9aa5b287e7ef65672771ff17bb893ed766c7ec9e4d8ab8134","schema_fingerprint":"4aa3821a28b0b7c2400bc59aba4bcc0a76e971dadd19610d3ad38c768e124dc7","schema_version":"edge-lab-recorder.raw.v1","sequence":null,"source":"clob_market_ws"}
{"event_at":"2026-07-28T03:14:43.518000Z","event_fingerprint":"70b39cb74ad52a635982000fa94fb315295bf15ed90da7f4cb7f2a3672665fa3","payload":{"connection_id":"a6b55582af5f430fb37ad02bf0922475","event_at":"2026-07-28T03:14:43.518000Z","event_type":"price_change","frame_hash":"ec8a5a5b1d2df7334be85b514db47c7e6e9741be67727912ad3ce486f0acfaac","frame_index":0,"kind":"data","monotonic_ns":310466383398458,"payload":{"event_type":"price_change","market":"0x779291bef19b6709f61e9764a954aafe9ffae488d50ae674aabdcb4f248006d5","price_changes":[{"asset_id":"14965588658799411272385430903075831224615961675357217884735713260981483529984","best_ask":"1","best_bid":"0.99","hash":"bb6b17ee8ec60699bd79848dca745c4cff56fb30","price":"0.99","side":"BUY","size":"398.38"},{"asset_id":"8761897749749422724209054078244794145777693856614463256546737399611489089783","best_ask":"0.01","best_bid":"0","hash":"62d3e7ff28d0c5c24b32869cb90b8f6e71cb8671","price":"0.01","side":"SELL","size":"398.38"}],"timestamp":"1785208483518"},"payload_hash":"6180d7111648177b16e7f70ef901b687d4a31288e25560de1855f507dfc0fe82","raw_frame":"{\"market\":\"0x779291bef19b6709f61e9764a954aafe9ffae488d50ae674aabdcb4f248006d5\", \"price_changes\":[{\"asset_id\":\"14965588658799411272385430903075831224615961675357217884735713260981483529984\", \"price\":\"0.99\", \"size\":\"398.38\", \"side\":\"BUY\", \"hash\":\"bb6b17ee8ec60699bd79848dca745c4cff56fb30\", \"best_bid\":\"0.99\", \"best_ask\":\"1\"}, {\"asset_id\":\"8761897749749422724209054078244794145777693856614463256546737399611489089783\", \"price\":\"0.01\", \"size\":\"398.38\", \"side\":\"SELL\", \"hash\":\"62d3e7ff28d0c5c24b32869cb90b8f6e71cb8671\", \"best_bid\":\"0\", \"best_ask\":\"0.01\"}], \"timestamp\":\"1785208483518\", \"event_type\":\"price_change\"}","received_at":"2026-07-28T03:14:43.347621Z","schema_version":"clob-market-ws.price_change.v1","sequence":null,"server_hash":null,"server_timestamp":"1785208483518","session_id":"3e519d9098404c15b234d96025eb1a2b","source":"clob_market_ws"},"received_at":"2026-07-28T03:14:43.347621Z","record_id":"8871fd187fd24e5ca564de47ce7241a5ca4d5845d7253be50d433cf4895051a6","schema_fingerprint":"4aa3821a28b0b7c2400bc59aba4bcc0a76e971dadd19610d3ad38c768e124dc7","schema_version":"edge-lab-recorder.raw.v1","sequence":null,"source":"clob_market_ws"}
{"event_at":"2026-07-28T03:14:43.518000Z","event_fingerprint":"d171f96907cb7da1061a6d0a791818ebb31ac91f37ca74a3f9905102f6dcaeb6","payload":{"connection_id":"a6b55582af5f430fb37ad02bf0922475","event_at":"2026-07-28T03:14:43.518000Z","event_type":"price_change","frame_hash":"32457ff49a85a31f35be8eeacf2308ee1ff8f300909b860496c5748600858488","frame_index":0,"kind":"data","monotonic_ns":310466385762166,"payload":{"event_type":"price_change","market":"0x779291bef19b6709f61e9764a954aafe9ffae488d50ae674aabdcb4f248006d5","price_changes":[{"asset_id":"8761897749749422724209054078244794145777693856614463256546737399611489089783","best_ask":"0.01","best_bid":"0","hash":"c6d07f0cfff6c1748fe4e521d10c6f598db04523","price":"0.01","side":"SELL","size":"445.99"},{"asset_id":"14965588658799411272385430903075831224615961675357217884735713260981483529984","best_ask":"1","best_bid":"0.99","hash":"107f39cd2e3c246e949a39db7ef888b7edd4e22f","price":"0.99","side":"BUY","size":"445.99"}],"timestamp":"1785208483518"},"payload_hash":"24d95ffc98de682f35bab41fe6fb496ca9627db5ba650d78744eca066d27876f","raw_frame":"{\"market\":\"0x779291bef19b6709f61e9764a954aafe9ffae488d50ae674aabdcb4f248006d5\", \"price_changes\":[{\"asset_id\":\"8761897749749422724209054078244794145777693856614463256546737399611489089783\", \"price\":\"0.01\", \"size\":\"445.99\", \"side\":\"SELL\", \"hash\":\"c6d07f0cfff6c1748fe4e521d10c6f598db04523\", \"best_bid\":\"0\", \"best_ask\":\"0.01\"}, {\"asset_id\":\"14965588658799411272385430903075831224615961675357217884735713260981483529984\", \"price\":\"0.99\", \"size\":\"445.99\", \"side\":\"BUY\", \"hash\":\"107f39cd2e3c246e949a39db7ef888b7edd4e22f\", \"best_bid\":\"0.99\", \"best_ask\":\"1\"}], \"timestamp\":\"1785208483518\", \"event_type\":\"price_change\"}","received_at":"2026-07-28T03:14:43.349982Z","schema_version":"clob-market-ws.price_change.v1","sequence":null,"server_hash":null,"server_timestamp":"1785208483518","session_id":"3e519d9098404c15b234d96025eb1a2b","source":"clob_market_ws"},"received_at":"2026-07-28T03:14:43.349982Z","record_id":"661e06c11df7763a0b8712c265d6a7c1d8f558cbf33a1dc6aae99a393946b190","schema_fingerprint":"4aa3821a28b0b7c2400bc59aba4bcc0a76e971dadd19610d3ad38c768e124dc7","schema_version":"edge-lab-recorder.raw.v1","sequence":null,"source":"clob_market_ws"}
{"event_at":"2026-07-28T03:14:43.519000Z","event_fingerprint":"4961a0ace9c8b211b0b86d8e101dd61ccf92ea92a87ab6c547cea3b2bc0141de","payload":{"connection_id":"a6b55582af5f430fb37ad02bf0922475","event_at":"2026-07-28T03:14:43.519000Z","event_type":"price_change","frame_hash":"dcfe24d17d86ff718ad582b4795a59b87adafca4e4ce28dc4aeb6027e916aa02","frame_index":0,"kind":"data","monotonic_ns":310466387341541,"payload":{"event_type":"price_change","market":"0x779291bef19b6709f61e9764a954aafe9ffae488d50ae674aabdcb4f248006d5","price_changes":[{"asset_id":"14965588658799411272385430903075831224615961675357217884735713260981483529984","best_ask":"1","best_bid":"0.99","hash":"9f8c353e82273dbbc1d3d30b6ecdb67a6caa1883","price":"0.19","side":"BUY","size":"35"},{"asset_id":"8761897749749422724209054078244794145777693856614463256546737399611489089783","best_ask":"0.01","best_bid":"0","hash":"0c1866d901c282051348829f00ad069a2d0af91f","price":"0.81","side":"SELL","size":"35"}],"timestamp":"1785208483519"},"payload_hash":"9892461a5e849b2c6080b080b49441de3ad9053c669e77dacba073115de0741d","raw_frame":"{\"market\":\"0x779291bef19b6709f61e9764a954aafe9ffae488d50ae674aabdcb4f248006d5\", \"price_changes\":[{\"asset_id\":\"14965588658799411272385430903075831224615961675357217884735713260981483529984\", \"price\":\"0.19\", \"size\":\"35\", \"side\":\"BUY\", \"hash\":\"9f8c353e82273dbbc1d3d30b6ecdb67a6caa1883\", \"best_bid\":\"0.99\", \"best_ask\":\"1\"}, {\"asset_id\":\"8761897749749422724209054078244794145777693856614463256546737399611489089783\", \"price\":\"0.81\", \"size\":\"35\", \"side\":\"SELL\", \"hash\":\"0c1866d901c282051348829f00ad069a2d0af91f\", \"best_bid\":\"0\", \"best_ask\":\"0.01\"}], \"timestamp\":\"1785208483519\", \"event_type\":\"price_change\"}","received_at":"2026-07-28T03:14:43.351565Z","schema_version":"clob-market-ws.price_change.v1","sequence":null,"server_hash":null,"server_timestamp":"1785208483519","session_id":"3e519d9098404c15b234d96025eb1a2b","source":"clob_market_ws"},"received_at":"2026-07-28T03:14:43.351565Z","record_id":"b1f3a4a18c32250465d9aa7e4a4381975ef776fc4e3064decbbca70a49b276af","schema_fingerprint":"4aa3821a28b0b7c2400bc59aba4bcc0a76e971dadd19610d3ad38c768e124dc7","schema_version":"edge-lab-recorder.raw.v1","sequence":null,"source":"clob_market_ws"}
{"event_at":"2026-07-28T03:14:43.520000Z","event_fingerprint":"89bfdb20be2ccc85fecace93f84413f02e8b2f121010dc8d0d33f32465d22d7e","payload":{"connection_id":"a6b55582af5f430fb37ad02bf0922475","event_at":"2026-07-28T03:14:43.520000Z","event_type":"price_change","frame_hash":"e563085a300b650ae22dff1d6853d5657bcc3cd9034f9a1cff501bc860f06953","frame_index":0,"kind":"data","monotonic_ns":310466388786208,"payload":{"event_type":"price_change","market":"0x779291bef19b6709f61e9764a954aafe9ffae488d50ae674aabdcb4f248006d5","price_changes":[{"asset_id":"14965588658799411272385430903075831224615961675357217884735713260981483529984","best_ask":"1","best_bid":"0.99","hash":"c20ec011b1f3ac9029eb17c06bd82f3db1ed39ca","price":"0.98","side":"BUY","size":"74.61"},{"asset_id":"8761897749749422724209054078244794145777693856614463256546737399611489089783","best_ask":"0.01","best_bid":"0","hash":"9d676bfaab6ef72941697ec7de4d6d296b2c593e","price":"0.02","side":"SELL","size":"74.61"}],"timestamp":"1785208483520"},"payload_hash":"09f56533baa9dfc98f92ddf4d8d83d1c271fac6c9dbe059c564b448cb7152385","raw_frame":"{\"market\":\"0x779291bef19b6709f61e9764a954aafe9ffae488d50ae674aabdcb4f248006d5\", \"price_changes\":[{\"asset_id\":\"14965588658799411272385430903075831224615961675357217884735713260981483529984\", \"price\":\"0.98\", \"size\":\"74.61\", \"side\":\"BUY\", \"hash\":\"c20ec011b1f3ac9029eb17c06bd82f3db1ed39ca\", \"best_bid\":\"0.99\", \"best_ask\":\"1\"}, {\"asset_id\":\"8761897749749422724209054078244794145777693856614463256546737399611489089783\", \"price\":\"0.02\", \"size\":\"74.61\", \"side\":\"SELL\", \"hash\":\"9d676bfaab6ef72941697ec7de4d6d296b2c593e\", \"best_bid\":\"0\", \"best_ask\":\"0.01\"}], \"timestamp\":\"1785208483520\", \"event_type\":\"price_change\"}","received_at":"2026-07-28T03:14:43.353012Z","schema_version":"clob-market-ws.price_change.v1","sequence":null,"server_hash":null,"server_timestamp":"1785208483520","session_id":"3e519d9098404c15b234d96025eb1a2b","source":"clob_market_ws"},"received_at":"2026-07-28T03:14:43.353012Z","record_id":"6415f40e60c5f12e17f6e23087336c2d1fa2d5415269f069810c66b6ec6f03f8","schema_fingerprint":"4aa3821a28b0b7c2400bc59aba4bcc0a76e971dadd19610d3ad38c768e124dc7","schema_version":"edge-lab-recorder.raw.v1","sequence":null,"source":"clob_market_ws"}
{"event_at":"2026-07-28T03:14:43.537000Z","event_fingerprint":"63bbac96bd4702c3321d411e68f13a47702f5730618a04de1fa69d35707a7902","payload":{"connection_id":"a6b55582af5f430fb37ad02bf0922475","event_at":"2026-07-28T03:14:43.537000Z","event_type":"price_change","frame_hash":"1d80749db0d0f1980f9f22f7b87d2ec84f3e3313930556ce5182778cd2a214da","frame_index":0,"kind":"data","monotonic_ns":310466402818041,"payload":{"event_type":"price_change","market":"0x779291bef19b6709f61e9764a954aafe9ffae488d50ae674aabdcb4f248006d5","price_changes":[{"asset_id":"14965588658799411272385430903075831224615961675357217884735713260981483529984","best_ask":"1","best_bid":"0.99","hash":"559f2f276f94d99af317946a8a66a39dbf9af65d","price":"0.02","side":"BUY","size":"530"},{"asset_id":"8761897749749422724209054078244794145777693856614463256546737399611489089783","best_ask":"0.01","best_bid":"0","hash":"1afc7fad63a687038dbfb0cc5c33080f0637ec2b","price":"0.98","side":"SELL","size":"530"}],"timestamp":"1785208483537"},"payload_hash":"c0dfd4616216d21fa186af92218551af01eeab427ea5b3a708dbe1fa3e9f628b","raw_frame":"{\"market\":\"0x779291bef19b6709f61e9764a954aafe9ffae488d50ae674aabdcb4f248006d5\", \"price_changes\":[{\"asset_id\":\"14965588658799411272385430903075831224615961675357217884735713260981483529984\", \"price\":\"0.02\", \"size\":\"530\", \"side\":\"BUY\", \"hash\":\"559f2f276f94d99af317946a8a66a39dbf9af65d\", \"best_bid\":\"0.99\", \"best_ask\":\"1\"}, {\"asset_id\":\"8761897749749422724209054078244794145777693856614463256546737399611489089783\", \"price\":\"0.98\", \"size\":\"530\", \"side\":\"SELL\", \"hash\":\"1afc7fad63a687038dbfb0cc5c33080f0637ec2b\", \"best_bid\":\"0\", \"best_ask\":\"0.01\"}], \"timestamp\":\"1785208483537\", \"event_type\":\"price_change\"}","received_at":"2026-07-28T03:14:43.367041Z","schema_version":"clob-market-ws.price_change.v1","sequence":null,"server_hash":null,"server_timestamp":"1785208483537","session_id":"3e519d9098404c15b234d96025eb1a2b","source":"clob_market_ws"},"received_at":"2026-07-28T03:14:43.367041Z","record_id":"9e51b6e8ff0f227516dca6160ae055b64815fa80b5e65b4b89d046b000e36eaf","schema_fingerprint":"4aa3821a28b0b7c2400bc59aba4bcc0a76e971dadd19610d3ad38c768e124dc7","schema_version":"edge-lab-recorder.raw.v1","sequence":null,"source":"clob_market_ws"}
