{"event_at":"2026-07-28T03:05:04.574000Z","event_fingerprint":"444e15398370554761f5a41b9933db888c8850c69fd15995e66cb567b2d1de0c","payload":{"connection_id":"a6b55582af5f430fb37ad02bf0922475","event_at":"2026-07-28T03:05:04.574000Z","event_type":"price_change","frame_hash":"94858f5bc1ae7f3bbbeb14c8b21efe81ed57e4f91b20ddbc9fdb0d427fafdf4c","frame_index":0,"kind":"data","monotonic_ns":309888983818916,"payload":{"event_type":"price_change","market":"0x779291bef19b6709f61e9764a954aafe9ffae488d50ae674aabdcb4f248006d5","price_changes":[{"asset_id":"14965588658799411272385430903075831224615961675357217884735713260981483529984","best_ask":"0.43","best_bid":"0.42","hash":"7fa265cf6fb429577da5e3b26a37cbaad0fb85b7","price":"0.26","side":"BUY","size":"228.6"},{"asset_id":"8761897749749422724209054078244794145777693856614463256546737399611489089783","best_ask":"0.58","best_bid":"0.57","hash":"a6ebfd09d548cd3268c8ba1e55745b7471e79b6a","price":"0.74","side":"SELL","size":"228.6"}],"timestamp":"1785207904574"},"payload_hash":"30d6efbe83e5228206115c812754c1ba4a8af1d0e511a5bbd8b8e46ac430fec8","raw_frame":"{\"market\":\"0x779291bef19b6709f61e9764a954aafe9ffae488d50ae674aabdcb4f248006d5\", \"price_changes\":[{\"asset_id\":\"14965588658799411272385430903075831224615961675357217884735713260981483529984\", \"price\":\"0.26\", \"size\":\"228.6\", \"side\":\"BUY\", \"hash\":\"7fa265cf6fb429577da5e3b26a37cbaad0fb85b7\", \"best_bid\":\"0.42\", \"best_ask\":\"0.43\"}, {\"asset_id\":\"8761897749749422724209054078244794145777693856614463256546737399611489089783\", \"price\":\"0.74\", \"size\":\"228.6\", \"side\":\"SELL\", \"hash\":\"a6ebfd09d548cd3268c8ba1e55745b7471e79b6a\", \"best_bid\":\"0.57\", \"best_ask\":\"0.58\"}], \"timestamp\":\"1785207904574\", \"event_type\":\"price_change\"}","received_at":"2026-07-28T03:05:05.953418Z","schema_version":"clob-market-ws.price_change.v1","sequence":null,"server_hash":null,"server_timestamp":"1785207904574","session_id":"3e519d9098404c15b234d96025eb1a2b","source":"clob_market_ws"},"received_at":"2026-07-28T03:05:05.953418Z","record_id":"20766ab05cdc46857d6a305fb0272518affc5e5740a5fbd7260ca9f52179a11a","schema_fingerprint":"4aa3821a28b0b7c2400bc59aba4bcc0a76e971dadd19610d3ad38c768e124dc7","schema_version":"edge-lab-recorder.raw.v1","sequence":null,"source":"clob_market_ws"}
{"event_at":"2026-07-28T03:05:04.586000Z","event_fingerprint":"29456cec33756542d94c20fe19de64c34b189575cbec38697e80aece8c32c4a7","payload":{"connection_id":"a6b55582af5f430fb37ad02bf0922475","event_at":"2026-07-28T03:05:04.586000Z","event_type":"price_change","frame_hash":"cbbc1b410a44c64f5ebe0ae7f72bf3f6d9cfdf823b5d53370578f2e519046442","frame_index":0,"kind":"data","monotonic_ns":309888992912541,"payload":{"event_type":"price_change","market":"0x779291bef19b6709f61e9764a954aafe9ffae488d50ae674aabdcb4f248006d5","price_changes":[{"asset_id":"8761897749749422724209054078244794145777693856614463256546737399611489089783","best_ask":"0.58","best_bid":"0.57","hash":"538f97234c0f54256d66fd964942632ab30af1b3","price":"0.51","side":"BUY","size":"230"},{"asset_id":"14965588658799411272385430903075831224615961675357217884735713260981483529984","best_ask":"0.43","best_bid":"0.42","hash":"774a1febbf6248eac47b212b29be403b7d391cd1","price":"0.49","side":"SELL","size":"230"}],"timestamp":"1785207904586"},"payload_hash":"1143b2309cb1a70cd89eb4cdd6c745d8afcd3299aa7d6d0369e334488ff8b0d6","raw_frame":"{\"market\":\"0x779291bef19b6709f61e9764a954aafe9ffae488d50ae674aabdcb4f248006d5\", \"price_changes\":[{\"asset_id\":\"8761897749749422724209054078244794145777693856614463256546737399611489089783\", \"price\":\"0.51\", \"size\":\"230\", \"side\":\"BUY\", \"hash\":\"538f97234c0f54256d66fd964942632ab30af1b3\", \"best_bid\":\"0.57\", \"best_ask\":\"0.58\"}, {\"asset_id\":\"14965588658799411272385430903075831224615961675357217884735713260981483529984\", \"price\":\"0.49\", \"size\":\"230\", \"side\":\"SELL\", \"hash\":\"774a1febbf6248eac47b212b29be403b7d391cd1\", \"best_bid\":\"0.42\", \"best_ask\":\"0.43\"}], \"timestamp\":\"1785207904586\", \"event_type\":\"price_change\"}","received_at":"2026-07-28T03:05:05.962512Z","schema_version":"clob-market-ws.price_change.v1","sequence":null,"server_hash":null,"server_timestamp":"1785207904586","session_id":"3e519d9098404c15b234d96025eb1a2b","source":"clob_market_ws"},"received_at":"2026-07-28T03:05:05.962512Z","record_id":"a947fbc2ee6d606d8cf0d6fa9222615aec12a7af1b6bdc33dacaf9f70e26255e","schema_fingerprint":"4aa3821a28b0b7c2400bc59aba4bcc0a76e971dadd19610d3ad38c768e124dc7","schema_version":"edge-lab-recorder.raw.v1","sequence":null,"source":"clob_market_ws"}
{"event_at":"2026-07-28T03:05:04.595000Z","event_fingerprint":"7ac65af6ddccffc2ee94be755232065946950d6b0b368b2d05e5c1b08adc41fe","payload":{"connection_id":"a6b55582af5f430fb37ad02bf0922475","event_at":"2026-07-28T03:05:04.595000Z","event_type":"price_change","frame_hash":"efd88efad89076df75a2079b9261b16350d808e3ad5fa4cc586c6e4c820704b9","frame_index":0,"kind":"data","monotonic_ns":309888996978500,"payload":{"event_type":"price_change","market":"0x779291bef19b6709f61e9764a954aafe9ffae488d50ae674aabdcb4f248006d5","price_changes":[{"asset_id":"8761897749749422724209054078244794145777693856614463256546737399611489089783","best_ask":"0.58","best_bid":"0.57","hash":"427c2d66d9e8688a04d8bb50e2e2324f23bc8d8e","price":"0.55","side":"BUY","size":"78.08"},{"asset_id":"14965588658799411272385430903075831224615961675357217884735713260981483529984","best_ask":"0.43","best_bid":"0.42","hash":"1d701b1f9047c1c48592c51d575425fd03b9131e","price":"0.45","side":"SELL","size":"78.08"}],"timestamp":"1785207904595"},"payload_hash":"e211416ff8387c5a0f2b3eb10d0fd2dad1cdb586965ff4c37f485801c936ac62","raw_frame":"{\"market\":\"0x779291bef19b6709f61e9764a954aafe9ffae488d50ae674aabdcb4f248006d5\", \"price_changes\":[{\"asset_id\":\"8761897749749422724209054078244794145777693856614463256546737399611489089783\", \"price\":\"0.55\", \"size\":\"78.08\", \"side\":\"BUY\", \"hash\":\"427c2d66d9e8688a04d8bb50e2e2324f23bc8d8e\", \"best_bid\":\"0.57\", \"best_ask\":\"0.58\"}, {\"asset_id\":\"14965588658799411272385430903075831224615961675357217884735713260981483529984\", \"price\":\"0.45\", \"size\":\"78.08\", \"side\":\"SELL\", \"hash\":\"1d701b1f9047c1c48592c51d575425fd03b9131e\", \"best_bid\":\"0.42\", \"best_ask\":\"0.43\"}], \"timestamp\":\"1785207904595\", \"event_type\":\"price_change\"}","received_at":"2026-07-28T03:05:05.966578Z","schema_version":"clob-market-ws.price_change.v1","sequence":null,"server_hash":null,"server_timestamp":"1785207904595","session_id":"3e519d9098404c15b234d96025eb1a2b","source":"clob_market_ws"},"received_at":"2026-07-28T03:05:05.966578Z","record_id":"57180a88376753b54d43586637a56bdee30e62fb4e28c6bfc37773bc8094ab04","schema_fingerprint":"4aa3821a28b0b7c2400bc59aba4bcc0a76e971dadd19610d3ad38c768e124dc7","schema_version":"edge-lab-recorder.raw.v1","sequence":null,"source":"clob_market_ws"}
{"event_at":"2026-07-28T03:05:04.596000Z","event_fingerprint":"61a1858bc5f8a0aab506a5f273b69c525c54246aaedf30653e5cbdd7698d12fc","payload":{"connection_id":"a6b55582af5f430fb37ad02bf0922475","event_at":"2026-07-28T03:05:04.596000Z","event_type":"price_change","frame_hash":"3ef938b9e269a6ffbe3e205f467a5aeb892a1c11d698296e2f89a2ec81e51911","frame_index":0,"kind":"data","monotonic_ns":309889000937333,"payload":{"event_type":"price_change","market":"0x779291bef19b6709f61e9764a954aafe9ffae488d50ae674aabdcb4f248006d5","price_changes":[{"asset_id":"14965588658799411272385430903075831224615961675357217884735713260981483529984","best_ask":"0.43","best_bid":"0.42","hash":"0d7d8e3414d51145ffbb12d5bc5eb33c039c59d3","price":"0.33","side":"BUY","size":"215.35"},{"asset_id":"8761897749749422724209054078244794145777693856614463256546737399611489089783","best_ask":"0.58","best_bid":"0.57","hash":"91d5cc5743a7d7b2f681d743c80255f1b0062acd","price":"0.67","side":"SELL","size":"215.35"}],"timestamp":"1785207904596"},"payload_hash":"852b3f743df6bcd7c0c4756471a90392d6abcc92782c68bbe91591f22521d598","raw_frame":"{\"market\":\"0x779291bef19b6709f61e9764a954aafe9ffae488d50ae674aabdcb4f248006d5\", \"price_changes\":[{\"asset_id\":\"14965588658799411272385430903075831224615961675357217884735713260981483529984\", \"price\":\"0.33\", \"size\":\"215.35\", \"side\":\"BUY\", \"hash\":\"0d7d8e3414d51145ffbb12d5bc5eb33c039c59d3\", \"best_bid\":\"0.42\", \"best_ask\":\"0.43\"}, {\"asset_id\":\"8761897749749422724209054078244794145777693856614463256546737399611489089783\", \"price\":\"0.67\", \"size\":\"215.35\", \"side\":\"SELL\", \"hash\":\"91d5cc5743a7d7b2f681d743c80255f1b0062acd\", \"best_bid\":\"0.57\", \"best_ask\":\"0.58\"}], \"timestamp\":\"1785207904596\", \"event_type\":\"price_change\"}","received_at":"2026-07-28T03:05:05.970529Z","schema_version":"clob-market-ws.price_change.v1","sequence":null,"server_hash":null,"server_timestamp":"1785207904596","session_id":"3e519d9098404c15b234d96025eb1a2b","source":"clob_market_ws"},"received_at":"2026-07-28T03:05:05.970529Z","record_id":"4ed002d8ca7cba99623c1e47213dd4f9ff5adeb08d9c6b1359343fd4fa98ec6a","schema_fingerprint":"4aa3821a28b0b7c2400bc59aba4bcc0a76e971dadd19610d3ad38c768e124dc7","schema_version":"edge-lab-recorder.raw.v1","sequence":null,"source":"clob_market_ws"}
{"event_at":"2026-07-28T03:05:04.597000Z","event_fingerprint":"12f91afe6f316523f21573b29a8de1255c89047af94d9ced77b1990e72c28649","payload":{"connection_id":"a6b55582af5f430fb37ad02bf0922475","event_at":"2026-07-28T03:05:04.597000Z","event_type":"price_change","frame_hash":"bc670e64b3678133eb4cc9799c5ef54f2391c41f4c7fc82db0064512d9264e5d","frame_index":0,"kind":"data","monotonic_ns":309889004499583,"payload":{"event_type":"price_change","market":"0x779291bef19b6709f61e9764a954aafe9ffae488d50ae674aabdcb4f248006d5","price_changes":[{"asset_id":"14965588658799411272385430903075831224615961675357217884735713260981483529984","best_ask":"0.43","best_bid":"0.42","hash":"62d14b89815bd7f2f797bd73d73816f87f39bca6","price":"0.32","side":"BUY","size":"226.34"},{"asset_id":"8761897749749422724209054078244794145777693856614463256546737399611489089783","best_ask":"0.58","best_bid":"0.57","hash":"a79523aac3d4fca096459640be89a3a91553ca45","price":"0.68","side":"SELL","size":"226.34"}],"timestamp":"1785207904597"},"payload_hash":"89ebe5e165d7aefb712878c4c89d1c23cf3aca83e873a6699ecb6b9b9b698fd7","raw_frame":"{\"market\":\"0x779291bef19b6709f61e9764a954aafe9ffae488d50ae674aabdcb4f248006d5\", \"price_changes\":[{\"asset_id\":\"14965588658799411272385430903075831224615961675357217884735713260981483529984\", \"price\":\"0.32\", \"size\":\"226.34\", \"side\":\"BUY\", \"hash\":\"62d14b89815bd7f2f797bd73d73816f87f39bca6\", \"best_bid\":\"0.42\", \"best_ask\":\"0.43\"}, {\"asset_id\":\"8761897749749422724209054078244794145777693856614463256546737399611489089783\", \"price\":\"0.68\", \"size\":\"226.34\", \"side\":\"SELL\", \"hash\":\"a79523aac3d4fca096459640be89a3a91553ca45\", \"best_bid\":\"0.57\", \"best_ask\":\"0.58\"}], \"timestamp\":\"1785207904597\", \"event_type\":\"price_change\"}","received_at":"2026-07-28T03:05:05.974099Z","schema_version":"clob-market-ws.price_change.v1","sequence":null,"server_hash":null,"server_timestamp":"1785207904597","session_id":"3e519d9098404c15b234d96025eb1a2b","source":"clob_market_ws"},"received_at":"2026-07-28T03:05:05.974099Z","record_id":"e6c54fd3ccfd9d8cbb69dffe1d779b12a2fc1f63a2d64853c71e14125ef28a35","schema_fingerprint":"4aa3821a28b0b7c2400bc59aba4bcc0a76e971dadd19610d3ad38c768e124dc7","schema_version":"edge-lab-recorder.raw.v1","sequence":null,"source":"clob_market_ws"}
{"event_at":"2026-07-28T03:05:04.600000Z","event_fingerprint":"d31fb29a3fe3c51bddd52a7a9144cf8f5e6fed08a668f84160cabf9b37bcb7ba","payload":{"connection_id":"a6b55582af5f430fb37ad02bf0922475","event_at":"2026-07-28T03:05:04.600000Z","event_type":"price_change","frame_hash":"b2ea21618e83165bd7172c8aeff81f288ee0de1ffd44210257e57da4a778af17","frame_index":0,"kind":"data","monotonic_ns":309889013418291,"payload":{"event_type":"price_change","market":"0x779291bef19b6709f61e9764a954aafe9ffae488d50ae674aabdcb4f248006d5","price_changes":[{"asset_id":"8761897749749422724209054078244794145777693856614463256546737399611489089783","best_ask":"0.58","best_bid":"0.57","hash":"d9f025ab93d4ae6622d96b82939f99516858b46b","price":"0.03","side":"BUY","size":"643.1"},{"asset_id":"14965588658799411272385430903075831224615961675357217884735713260981483529984","best_ask":"0.43","best_bid":"0.42","hash":"305101cbe1ffd57579f2b1b067dd7135545e5016","price":"0.97","side":"SELL","size":"643.1"}],"timestamp":"1785207904600"},"payload_hash":"cbd5a06f30e93e546bef54ae8e236c0892a9ba41d1f584cef33090cbe9a82db3","raw_frame":"{\"market\":\"0x779291bef19b6709f61e9764a954aafe9ffae488d50ae674aabdcb4f248006d5\", \"price_changes\":[{\"asset_id\":\"8761897749749422724209054078244794145777693856614463256546737399611489089783\", \"price\":\"0.03\", \"size\":\"643.1\", \"side\":\"BUY\", \"hash\":\"d9f025ab93d4ae6622d96b82939f99516858b46b\", \"best_bid\":\"0.57\", \"best_ask\":\"0.58\"}, {\"asset_id\":\"14965588658799411272385430903075831224615961675357217884735713260981483529984\", \"price\":\"0.97\", \"size\":\"643.1\", \"side\":\"SELL\", \"hash\":\"305101cbe1ffd57579f2b1b067dd7135545e5016\", \"best_bid\":\"0.42\", \"best_ask\":\"0.43\"}], \"timestamp\":\"1785207904600\", \"event_type\":\"price_change\"}","received_at":"2026-07-28T03:05:05.983017Z","schema_version":"clob-market-ws.price_change.v1","sequence":null,"server_hash":null,"server_timestamp":"1785207904600","session_id":"3e519d9098404c15b234d96025eb1a2b","source":"clob_market_ws"},"received_at":"2026-07-28T03:05:05.983017Z","record_id":"cf1f702f39b5cd61c55c10e4bedb9e544451cc90327d6414be5406685c351368","schema_fingerprint":"4aa3821a28b0b7c2400bc59aba4bcc0a76e971dadd19610d3ad38c768e124dc7","schema_version":"edge-lab-recorder.raw.v1","sequence":null,"source":"clob_market_ws"}
{"event_at":"2026-07-28T03:05:04.605000Z","event_fingerprint":"0427613373a2de669512ee0f1acd8f4f92134d331c7b8e98bbbfa636fdc79c8b","payload":{"connection_id":"a6b55582af5f430fb37ad02bf0922475","event_at":"2026-07-28T03:05:04.605000Z","event_type":"price_change","frame_hash":"c0618c255a5f3d8457467a9ddf2a3a4f882a37e7595f53f7217efb7e2358ea4a","frame_index":0,"kind":"data","monotonic_ns":309889019112125,"payload":{"event_type":"price_change","market":"0x779291bef19b6709f61e9764a954aafe9ffae488d50ae674aabdcb4f248006d5","price_changes":[{"asset_id":"14965588658799411272385430903075831224615961675357217884735713260981483529984","best_ask":"0.43","best_bid":"0.42","hash":"1b8c5d2e02b1fc7b526ab7c5c9f4265e6fa03e5d","price":"0.27","side":"BUY","size":"272.7"},{"asset_id":"8761897749749422724209054078244794145777693856614463256546737399611489089783","best_ask":"0.58","best_bid":"0.57","hash":"c8b84e9d35bc55f12411060cb8c944cbe60bc6a4","price":"0.73","side":"SELL","size":"272.7"}],"timestamp":"1785207904605"},"payload_hash":"a69d70bb1b95811d0756b099c1c368635fa71a6d9184756dc198065f94a2c086","raw_frame":"{\"market\":\"0x779291bef19b6709f61e9764a954aafe9ffae488d50ae674aabdcb4f248006d5\", \"price_changes\":[{\"asset_id\":\"14965588658799411272385430903075831224615961675357217884735713260981483529984\", \"price\":\"0.27\", \"size\":\"272.7\", \"side\":\"BUY\", \"hash\":\"1b8c5d2e02b1fc7b526ab7c5c9f4265e6fa03e5d\", \"best_bid\":\"0.42\", \"best_ask\":\"0.43\"}, {\"asset_id\":\"8761897749749422724209054078244794145777693856614463256546737399611489089783\", \"price\":\"0.73\", \"size\":\"272.7\", \"side\":\"SELL\", \"hash\":\"c8b84e9d35bc55f12411060cb8c944cbe60bc6a4\", \"best_bid\":\"0.57\", \"best_ask\":\"0.58\"}], \"timestamp\":\"1785207904605\", \"event_type\":\"price_change\"}","received_at":"2026-07-28T03:05:05.988709Z","schema_version":"clob-market-ws.price_change.v1","sequence":null,"server_hash":null,"server_timestamp":"1785207904605","session_id":"3e519d9098404c15b234d96025eb1a2b","source":"clob_market_ws"},"received_at":"2026-07-28T03:05:05.988709Z","record_id":"f5239b36631f4100ab2062498fb64604d6defb6b8a26ae19119d7a86d5a28816","schema_fingerprint":"4aa3821a28b0b7c2400bc59aba4bcc0a76e971dadd19610d3ad38c768e124dc7","schema_version":"edge-lab-recorder.raw.v1","sequence":null,"source":"clob_market_ws"}
{"event_at":"2026-07-28T03:05:04.683000Z","event_fingerprint":"864548b383357d1983b55e51736001b32db9d20c00994ed167dc78c10def58de","payload":{"connection_id":"a6b55582af5f430fb37ad02bf0922475","event_at":"2026-07-28T03:05:04.683000Z","event_type":"price_change","frame_hash":"9ed9b4a4fae464470a37404f7da1b5801e6ce4f6546c80592fadfb683035d577","frame_index":0,"kind":"data","monotonic_ns":309889027599875,"payload":{"event_type":"price_change","market":"0x779291bef19b6709f61e9764a954aafe9ffae488d50ae674aabdcb4f248006d5","price_changes":[{"asset_id":"14965588658799411272385430903075831224615961675357217884735713260981483529984","best_ask":"0.43","best_bid":"0.42","hash":"9d7037c208ff398a47dfd266e470af1ed728d270","price":"0.4","side":"BUY","size":"76.6"},{"asset_id":"8761897749749422724209054078244794145777693856614463256546737399611489089783","best_ask":"0.58","best_bid":"0.57","hash":"c987d8f0be3402146b9f0125be709078a404c469","price":"0.6","side":"SELL","size":"76.6"}],"timestamp":"1785207904683"},"payload_hash":"fa76c9365611d5a712e7a894405c85255eb98686a8fa1183a3a1399fe5ab894d","raw_frame":"{\"market\":\"0x779291bef19b6709f61e9764a954aafe9ffae488d50ae674aabdcb4f248006d5\", \"price_changes\":[{\"asset_id\":\"14965588658799411272385430903075831224615961675357217884735713260981483529984\", \"price\":\"0.4\", \"size\":\"76.6\", \"side\":\"BUY\", \"hash\":\"9d7037c208ff398a47dfd266e470af1ed728d270\", \"best_bid\":\"0.42\", \"best_ask\":\"0.43\"}, {\"asset_id\":\"8761897749749422724209054078244794145777693856614463256546737399611489089783\", \"price\":\"0.6\", \"size\":\"76.6\", \"side\":\"SELL\", \"hash\":\"c987d8f0be3402146b9f0125be709078a404c469\", \"best_bid\":\"0.57\", \"best_ask\":\"0.58\"}], \"timestamp\":\"1785207904683\", \"event_type\":\"price_change\"}","received_at":"2026-07-28T03:05:05.997197Z","schema_version":"clob-market-ws.price_change.v1","sequence":null,"server_hash":null,"server_timestamp":"1785207904683","session_id":"3e519d9098404c15b234d96025eb1a2b","source":"clob_market_ws"},"received_at":"2026-07-28T03:05:05.997197Z","record_id":"ab584e81d5dd402904f1fa727117370a5f2b1e7ee479704594265e0f0c5e4fd4","schema_fingerprint":"4aa3821a28b0b7c2400bc59aba4bcc0a76e971dadd19610d3ad38c768e124dc7","schema_version":"edge-lab-recorder.raw.v1","sequence":null,"source":"clob_market_ws"}
{"event_at":"2026-07-28T03:05:04.686000Z","event_fingerprint":"996303e74327200721c75991b1dbb231f64e40e429f1e047d6f72910157a6912","payload":{"connection_id":"a6b55582af5f430fb37ad02bf0922475","event_at":"2026-07-28T03:05:04.686000Z","event_type":"price_change","frame_hash":"193ec08547a7c9fc89269ddaea6738f89aa13024f7b9fa934c0872a719a9d7f6","frame_index":0,"kind":"data","monotonic_ns":309889034134916,"payload":{"event_type":"price_change","market":"0x779291bef19b6709f61e9764a954aafe9ffae488d50ae674aabdcb4f248006d5","price_changes":[{"asset_id":"8761897749749422724209054078244794145777693856614463256546737399611489089783","best_ask":"0.58","best_bid":"0.57","hash":"24eacd6764e519912fd2723985317a3e2ea36187","price":"0.51","side":"BUY","size":"225"},{"asset_id":"14965588658799411272385430903075831224615961675357217884735713260981483529984","best_ask":"0.43","best_bid":"0.42","hash":"713dcc72c507551ccf015ddbc16c1880dd73ab79","price":"0.49","side":"SELL","size":"225"}],"timestamp":"1785207904686"},"payload_hash":"efc681444803db551eb1b1c8ea5a84e629d58f81e6cf3349610971cd63661c5d","raw_frame":"{\"market\":\"0x779291bef19b6709f61e9764a954aafe9ffae488d50ae674aabdcb4f248006d5\", \"price_changes\":[{\"asset_id\":\"8761897749749422724209054078244794145777693856614463256546737399611489089783\", \"price\":\"0.51\", \"size\":\"225\", \"side\":\"BUY\", \"hash\":\"24eacd6764e519912fd2723985317a3e2ea36187\", \"best_bid\":\"0.57\", \"best_ask\":\"0.58\"}, {\"asset_id\":\"14965588658799411272385430903075831224615961675357217884735713260981483529984\", \"price\":\"0.49\", \"size\":\"225\", \"side\":\"SELL\", \"hash\":\"713dcc72c507551ccf015ddbc16c1880dd73ab79\", \"best_bid\":\"0.42\", \"best_ask\":\"0.43\"}], \"timestamp\":\"1785207904686\", \"event_type\":\"price_change\"}","received_at":"2026-07-28T03:05:06.003732Z","schema_version":"clob-market-ws.price_change.v1","sequence":null,"server_hash":null,"server_timestamp":"1785207904686","session_id":"3e519d9098404c15b234d96025eb1a2b","source":"clob_market_ws"},"received_at":"2026-07-28T03:05:06.003732Z","record_id":"0e714796e96608525b1a1539029afbfcb74d9f5d5430d962f8e5d22e534ea29a","schema_fingerprint":"4aa3821a28b0b7c2400bc59aba4bcc0a76e971dadd19610d3ad38c768e124dc7","schema_version":"edge-lab-recorder.raw.v1","sequence":null,"source":"clob_market_ws"}
{"event_at":"2026-07-28T03:05:04.698000Z","event_fingerprint":"1403c2519652ab40b3353eea0121b19e8f854b4a1d3b9fb94ae4da4cdeeb6f7c","payload":{"connection_id":"a6b55582af5f430fb37ad02bf0922475","event_at":"2026-07-28T03:05:04.698000Z","event_type":"price_change","frame_hash":"55b114ac176ed8a782e47838bfd8e5e8173d8328207b1d07ec800463cbace125","frame_index":0,"kind":"data","monotonic_ns":309889038654708,"payload":{"event_type":"price_change","market":"0x779291bef19b6709f61e9764a954aafe9ffae488d50ae674aabdcb4f248006d5","price_changes":[{"asset_id":"8761897749749422724209054078244794145777693856614463256546737399611489089783","best_ask":"0.58","best_bid":"0.57","hash":"5f386714c76df64dd19648b02fa70002c84604e3","price":"0.01","side":"BUY","size":"5858.02"},{"asset_id":"14965588658799411272385430903075831224615961675357217884735713260981483529984","best_ask":"0.43","best_bid":"0.42","hash":"0925a8e5de5458c57a8c96ef348e03a36fb62486","price":"0.99","side":"SELL","size":"5858.02"}],"timestamp":"1785207904698"},"payload_hash":"30768be51e18d2be5d1038593b4b2ec59e9466ff1f69073e77729e18b4b46caf","raw_frame":"{\"market\":\"0x779291bef19b6709f61e9764a954aafe9ffae488d50ae674aabdcb4f248006d5\", \"price_changes\":[{\"asset_id\":\"8761897749749422724209054078244794145777693856614463256546737399611489089783\", \"price\":\"0.01\", \"size\":\"5858.02\", \"side\":\"BUY\", \"hash\":\"5f386714c76df64dd19648b02fa70002c84604e3\", \"best_bid\":\"0.57\", \"best_ask\":\"0.58\"}, {\"asset_id\":\"14965588658799411272385430903075831224615961675357217884735713260981483529984\", \"price\":\"0.99\", \"size\":\"5858.02\", \"side\":\"SELL\", \"hash\":\"0925a8e5de5458c57a8c96ef348e03a36fb62486\", \"best_bid\":\"0.42\", \"best_ask\":\"0.43\"}], \"timestamp\":\"1785207904698\", \"event_type\":\"price_change\"}","received_at":"2026-07-28T03:05:06.008252Z","schema_version":"clob-market-ws.price_change.v1","sequence":null,"server_hash":null,"server_timestamp":"1785207904698","session_id":"3e519d9098404c15b234d96025eb1a2b","source":"clob_market_ws"},"received_at":"2026-07-28T03:05:06.008252Z","record_id":"7975426b56ffff831180ce752398066cf26d061bfb4cd956f805db28c1d91a8b","schema_fingerprint":"4aa3821a28b0b7c2400bc59aba4bcc0a76e971dadd19610d3ad38c768e124dc7","schema_version":"edge-lab-recorder.raw.v1","sequence":null,"source":"clob_market_ws"}
{"event_at":"2026-07-28T03:05:04.777000Z","event_fingerprint":"6eeedd41ccd9bda4533e3a1bc0f38c2c89e3cc1eef428c3232fd8fd86c9f39a4","payload":{"connection_id":"a6b55582af5f430fb37ad02bf0922475","event_at":"2026-07-28T03:05:04.777000Z","event_type":"price_change","frame_hash":"333c2cf464eed5c817521b8f217d821bd469623c76feb97f4d959eb2539071f1","frame_index":0,"kind":"data","monotonic_ns":309889042961875,"payload":{"event_type":"price_change","market":"0x779291bef19b6709f61e9764a954aafe9ffae488d50ae674aabdcb4f248006d5","price_changes":[{"asset_id":"8761897749749422724209054078244794145777693856614463256546737399611489089783","best_ask":"0.58","best_bid":"0.57","hash":"c2b8ec5a9d4e3233ec9e79d2518534aeb8109e7f","price":"0.57","side":"BUY","size":"48.98"},{"asset_id":"14965588658799411272385430903075831224615961675357217884735713260981483529984","best_ask":"0.43","best_bid":"0.42","hash":"5b9bf6aea66f825fdc5492a0a744b34d3509106a","price":"0.43","side":"SELL","size":"48.98"}],"timestamp":"1785207904777"},"payload_hash":"351cce23036e21e32fdb9c7e2afa49f2114efe46d317d5e46aeec246e5abede2","raw_frame":"{\"market\":\"0x779291bef19b6709f61e9764a954aafe9ffae488d50ae674aabdcb4f248006d5\", \"price_changes\":[{\"asset_id\":\"8761897749749422724209054078244794145777693856614463256546737399611489089783\", \"price\":\"0.57\", \"size\":\"48.98\", \"side\":\"BUY\", \"hash\":\"c2b8ec5a9d4e3233ec9e79d2518534aeb8109e7f\", \"best_bid\":\"0.57\", \"best_ask\":\"0.58\"}, {\"asset_id\":\"14965588658799411272385430903075831224615961675357217884735713260981483529984\", \"price\":\"0.43\", \"size\":\"48.98\", \"side\":\"SELL\", \"hash\":\"5b9bf6aea66f825fdc5492a0a744b34d3509106a\", \"best_bid\":\"0.42\", \"best_ask\":\"0.43\"}], \"timestamp\":\"1785207904777\", \"event_type\":\"price_change\"}","received_at":"2026-07-28T03:05:06.012559Z","schema_version":"clob-market-ws.price_change.v1","sequence":null,"server_hash":null,"server_timestamp":"1785207904777","session_id":"3e519d9098404c15b234d96025eb1a2b","source":"clob_market_ws"},"received_at":"2026-07-28T03:05:06.012559Z","record_id":"51f027fe43d675d17eb031462a4f32a1d17e4d964b1ed32914b6e6c44aaccded","schema_fingerprint":"4aa3821a28b0b7c2400bc59aba4bcc0a76e971dadd19610d3ad38c768e124dc7","schema_version":"edge-lab-recorder.raw.v1","sequence":null,"source":"clob_market_ws"}
{"event_at":"2026-07-28T03:05:04.778000Z","event_fingerprint":"5209b895574e6b64e5ee961972900aa9ee63687ca57c972c5a49fec6e6329c52","payload":{"connection_id":"a6b55582af5f430fb37ad02bf0922475","event_at":"2026-07-28T03:05:04.778000Z","event_type":"price_change","frame_hash":"68430198a0274eef895bf754736c3a5715e7debc244c40ffaff63b7aff801804","frame_index":0,"kind":"data","monotonic_ns":309889047226833,"payload":{"event_type":"price_change","market":"0x779291bef19b6709f61e9764a954aafe9ffae488d50ae674aabdcb4f248006d5","price_changes":[{"asset_id":"14965588658799411272385430903075831224615961675357217884735713260981483529984","best_ask":"0.43","best_bid":"0.42","hash":"668ff973a36f94488e3e7450f9d2764fdf5a45d2","price":"0.39","side":"BUY","size":"61"},{"asset_id":"8761897749749422724209054078244794145777693856614463256546737399611489089783","best_ask":"0.58","best_bid":"0.57","hash":"764e1b1b2e3960c9ad4ae5204b043d39c2e1ecf6","price":"0.61","side":"SELL","size":"61"}],"timestamp":"1785207904778"},"payload_hash":"0f6c256c5df492fee2e8c80e25388d71c5a45481ed2029890150de52522876cb","raw_frame":"{\"market\":\"0x779291bef19b6709f61e9764a954aafe9ffae488d50ae674aabdcb4f248006d5\", \"price_changes\":[{\"asset_id\":\"14965588658799411272385430903075831224615961675357217884735713260981483529984\", \"price\":\"0.39\", \"size\":\"61\", \"side\":\"BUY\", \"hash\":\"668ff973a36f94488e3e7450f9d2764fdf5a45d2\", \"best_bid\":\"0.42\", \"best_ask\":\"0.43\"}, {\"asset_id\":\"8761897749749422724209054078244794145777693856614463256546737399611489089783\", \"price\":\"0.61\", \"size\":\"61\", \"side\":\"SELL\", \"hash\":\"764e1b1b2e3960c9ad4ae5204b043d39c2e1ecf6\", \"best_bid\":\"0.57\", \"best_ask\":\"0.58\"}], \"timestamp\":\"1785207904778\", \"event_type\":\"price_change\"}","received_at":"2026-07-28T03:05:06.016824Z","schema_version":"clob-market-ws.price_change.v1","sequence":null,"server_hash":null,"server_timestamp":"1785207904778","session_id":"3e519d9098404c15b234d96025eb1a2b","source":"clob_market_ws"},"received_at":"2026-07-28T03:05:06.016824Z","record_id":"9d86cc78c3304dec1bfcbfc493a8a3a3e80eef69508b101c929d80f90294d104","schema_fingerprint":"4aa3821a28b0b7c2400bc59aba4bcc0a76e971dadd19610d3ad38c768e124dc7","schema_version":"edge-lab-recorder.raw.v1","sequence":null,"source":"clob_market_ws"}
{"event_at":"2026-07-28T03:05:04.784000Z","event_fingerprint":"2293dba321d599b59ef752af38c090198eac74ae5fe822ce2c80818ca2f74759","payload":{"connection_id":"a6b55582af5f430fb37ad02bf0922475","event_at":"2026-07-28T03:05:04.784000Z","event_type":"price_change","frame_hash":"a43c056b9a083706d8bf8cb9d1bf5f18a01c60ff11be06e1c5a4fba311264372","frame_index":0,"kind":"data","monotonic_ns":309889051503083,"payload":{"event_type":"price_change","market":"0x779291bef19b6709f61e9764a954aafe9ffae488d50ae674aabdcb4f248006d5","price_changes":[{"asset_id":"14965588658799411272385430903075831224615961675357217884735713260981483529984","best_ask":"0.43","best_bid":"0.42","hash":"e641121b436b52f538f5d641123883d2c5fb616f","price":"0.37","side":"BUY","size":"146.6"},{"asset_id":"8761897749749422724209054078244794145777693856614463256546737399611489089783","best_ask":"0.58","best_bid":"0.57","hash":"a444657720fdcd5b798fee14cadcbb186dde3337","price":"0.63","side":"SELL","size":"146.6"}],"timestamp":"1785207904784"},"payload_hash":"1a5468b360f5c4095efe9c7889c5e9d742bb0b17ac07fcde10ebbabcc5d6d7fd","raw_frame":"{\"market\":\"0x779291bef19b6709f61e9764a954aafe9ffae488d50ae674aabdcb4f248006d5\", \"price_changes\":[{\"asset_id\":\"14965588658799411272385430903075831224615961675357217884735713260981483529984\", \"price\":\"0.37\", \"size\":\"146.6\", \"side\":\"BUY\", \"hash\":\"e641121b436b52f538f5d641123883d2c5fb616f\", \"best_bid\":\"0.42\", \"best_ask\":\"0.43\"}, {\"asset_id\":\"8761897749749422724209054078244794145777693856614463256546737399611489089783\", \"price\":\"0.63\", \"size\":\"146.6\", \"side\":\"SELL\", \"hash\":\"a444657720fdcd5b798fee14cadcbb186dde3337\", \"best_bid\":\"0.57\", \"best_ask\":\"0.58\"}], \"timestamp\":\"1785207904784\", \"event_type\":\"price_change\"}","received_at":"2026-07-28T03:05:06.021100Z","schema_version":"clob-market-ws.price_change.v1","sequence":null,"server_hash":null,"server_timestamp":"1785207904784","session_id":"3e519d9098404c15b234d96025eb1a2b","source":"clob_market_ws"},"received_at":"2026-07-28T03:05:06.021100Z","record_id":"c993debe9812368d12eb84d734b3cfdfdee3caa51273b5ef3b9f140d5ab9929f","schema_fingerprint":"4aa3821a28b0b7c2400bc59aba4bcc0a76e971dadd19610d3ad38c768e124dc7","schema_version":"edge-lab-recorder.raw.v1","sequence":null,"source":"clob_market_ws"}
{"event_at":"2026-07-28T03:05:04.784000Z","event_fingerprint":"acbd0a4348e38c1f5064af312259b00e4e0108e7487f2a2f3a5474a15cc90c77","payload":{"connection_id":"a6b55582af5f430fb37ad02bf0922475","event_at":"2026-07-28T03:05:04.784000Z","event_type":"price_change","frame_hash":"10181ae3158e975f428f4be11631dde776a0135132ec9422caa26b96e90d037b","frame_index":0,"kind":"data","monotonic_ns":309889053771958,"payload":{"event_type":"price_change","market":"0x779291bef19b6709f61e9764a954aafe9ffae488d50ae674aabdcb4f248006d5","price_changes":[{"asset_id":"14965588658799411272385430903075831224615961675357217884735713260981483529984","best_ask":"0.43","best_bid":"0.42","hash":"7ca3435f948903fde1e519dbcc6d9f0ecfafe9a7","price":"0.38","side":"BUY","size":"139.2"},{"asset_id":"8761897749749422724209054078244794145777693856614463256546737399611489089783","best_ask":"0.58","best_bid":"0.57","hash":"d188cb46786e934da353b0117ee151cd0db9787e","price":"0.62","side":"SELL","size":"139.2"}],"timestamp":"1785207904784"},"payload_hash":"01988101634518b896a8ab83cd8ee528ddcb6c863cfda0b51560affd3faea473","raw_frame":"{\"market\":\"0x779291bef19b6709f61e9764a954aafe9ffae488d50ae674aabdcb4f248006d5\", \"price_changes\":[{\"asset_id\":\"14965588658799411272385430903075831224615961675357217884735713260981483529984\", \"price\":\"0.38\", \"size\":\"139.2\", \"side\":\"BUY\", \"hash\":\"7ca3435f948903fde1e519dbcc6d9f0ecfafe9a7\", \"best_bid\":\"0.42\", \"best_ask\":\"0.43\"}, {\"asset_id\":\"8761897749749422724209054078244794145777693856614463256546737399611489089783\", \"price\":\"0.62\", \"size\":\"139.2\", \"side\":\"SELL\", \"hash\":\"d188cb46786e934da353b0117ee151cd0db9787e\", \"best_bid\":\"0.57\", \"best_ask\":\"0.58\"}], \"timestamp\":\"1785207904784\", \"event_type\":\"price_change\"}","received_at":"2026-07-28T03:05:06.023369Z","schema_version":"clob-market-ws.price_change.v1","sequence":null,"server_hash":null,"server_timestamp":"1785207904784","session_id":"3e519d9098404c15b234d96025eb1a2b","source":"clob_market_ws"},"received_at":"2026-07-28T03:05:06.023369Z","record_id":"96014148453d77689881afa68f85e8fe42049798669001875f5110ce1c4e95c4","schema_fingerprint":"4aa3821a28b0b7c2400bc59aba4bcc0a76e971dadd19610d3ad38c768e124dc7","schema_version":"edge-lab-recorder.raw.v1","sequence":null,"source":"clob_market_ws"}
{"event_at":"2026-07-28T03:05:04.801000Z","event_fingerprint":"4dc0992882c0378af262e6005884e28a5889b7101e5495d8a162b430e48b1327","payload":{"connection_id":"a6b55582af5f430fb37ad02bf0922475","event_at":"2026-07-28T03:05:04.801000Z","event_type":"price_change","frame_hash":"0db28919351ccc6bf8f47d136d62d352de1a6f69b98e2d47bf9f292e4fbe7f8f","frame_index":0,"kind":"data","monotonic_ns":309889057460541,"payload":{"event_type":"price_change","market":"0x779291bef19b6709f61e9764a954aafe9ffae488d50ae674aabdcb4f248006d5","price_changes":[{"asset_id":"8761897749749422724209054078244794145777693856614463256546737399611489089783","best_ask":"0.58","best_bid":"0.57","hash":"0139bab47583dc89ad3ff23dbc117e303d1fee1b","price":"0.01","side":"BUY","size":"5853.02"},{"asset_id":"14965588658799411272385430903075831224615961675357217884735713260981483529984","best_ask":"0.43","best_bid":"0.42","hash":"c11f3cd39c440a2d7bd09b044887f7db4601b78e","price":"0.99","side":"SELL","size":"5853.02"}],"timestamp":"1785207904801"},"payload_hash":"f87aa68ad4cb86f962a4347b829727a73cfbea64f3a153766a1c0caee045847b","raw_frame":"{\"market\":\"0x779291bef19b6709f61e9764a954aafe9ffae488d50ae674aabdcb4f248006d5\", \"price_changes\":[{\"asset_id\":\"8761897749749422724209054078244794145777693856614463256546737399611489089783\", \"price\":\"0.01\", \"size\":\"5853.02\", \"side\":\"BUY\", \"hash\":\"0139bab47583dc89ad3ff23dbc117e303d1fee1b\", \"best_bid\":\"0.57\", \"best_ask\":\"0.58\"}, {\"asset_id\":\"14965588658799411272385430903075831224615961675357217884735713260981483529984\", \"price\":\"0.99\", \"size\":\"5853.02\", \"side\":\"SELL\", \"hash\":\"c11f3cd39c440a2d7bd09b044887f7db4601b78e\", \"best_bid\":\"0.42\", \"best_ask\":\"0.43\"}], \"timestamp\":\"1785207904801\", \"event_type\":\"price_change\"}","received_at":"2026-07-28T03:05:06.027057Z","schema_version":"clob-market-ws.price_change.v1","sequence":null,"server_hash":null,"server_timestamp":"1785207904801","session_id":"3e519d9098404c15b234d96025eb1a2b","source":"clob_market_ws"},"received_at":"2026-07-28T03:05:06.027057Z","record_id":"e002e8b0344e2953c2dd320d218053a758e72715a9c9d607c108dda01f4dcae5","schema_fingerprint":"4aa3821a28b0b7c2400bc59aba4bcc0a76e971dadd19610d3ad38c768e124dc7","schema_version":"edge-lab-recorder.raw.v1","sequence":null,"source":"clob_market_ws"}
{"event_at":"2026-07-28T03:05:04.818000Z","event_fingerprint":"593422e6ff833dca88adab0ac2bf882b1da57bd8be3457c3daf1104d0a274641","payload":{"connection_id":"a6b55582af5f430fb37ad02bf0922475","event_at":"2026-07-28T03:05:04.818000Z","event_type":"price_change","frame_hash":"d79224a3b3a249d8b049e2e5078cf568c6200a7a8cc14787e67a3d999e2ac9a5","frame_index":0,"kind":"data","monotonic_ns":309889061772208,"payload":{"event_type":"price_change","market":"0x779291bef19b6709f61e9764a954aafe9ffae488d50ae674aabdcb4f248006d5","price_changes":[{"asset_id":"14965588658799411272385430903075831224615961675357217884735713260981483529984","best_ask":"0.43","best_bid":"0.42","hash":"1e812b40d5522114aa95db29dffbf06c2cc2bfa9","price":"0.36","side":"BUY","size":"124.6"},{"asset_id":"8761897749749422724209054078244794145777693856614463256546737399611489089783","best_ask":"0.58","best_bid":"0.57","hash":"98d7ca620af39f0ad16e584cfd727e65eccf9058","price":"0.64","side":"SELL","size":"124.6"}],"timestamp":"1785207904818"},"payload_hash":"d1351932799d4058efce9906d22c846eae1d0857046f00d96e8fbd18b632100f","raw_frame":"{\"market\":\"0x779291bef19b6709f61e9764a954aafe9ffae488d50ae674aabdcb4f248006d5\", \"price_changes\":[{\"asset_id\":\"14965588658799411272385430903075831224615961675357217884735713260981483529984\", \"price\":\"0.36\", \"size\":\"124.6\", \"side\":\"BUY\", \"hash\":\"1e812b40d5522114aa95db29dffbf06c2cc2bfa9\", \"best_bid\":\"0.42\", \"best_ask\":\"0.43\"}, {\"asset_id\":\"8761897749749422724209054078244794145777693856614463256546737399611489089783\", \"price\":\"0.64\", \"size\":\"124.6\", \"side\":\"SELL\", \"hash\":\"98d7ca620af39f0ad16e584cfd727e65eccf9058\", \"best_bid\":\"0.57\", \"best_ask\":\"0.58\"}], \"timestamp\":\"1785207904818\", \"event_type\":\"price_change\"}","received_at":"2026-07-28T03:05:06.031369Z","schema_version":"clob-market-ws.price_change.v1","sequence":null,"server_hash":null,"server_timestamp":"1785207904818","session_id":"3e519d9098404c15b234d96025eb1a2b","source":"clob_market_ws"},"received_at":"2026-07-28T03:05:06.031369Z","record_id":"72525f75d7773a206a7bc6ffd22af559a1cb6cb6759746aaaab8aad932a29f0f","schema_fingerprint":"4aa3821a28b0b7c2400bc59aba4bcc0a76e971dadd19610d3ad38c768e124dc7","schema_version":"edge-lab-recorder.raw.v1","sequence":null,"source":"clob_market_ws"}
{"event_at":"2026-07-28T03:05:04.827000Z","event_fingerprint":"0c9922262e5bf38723db3ae6f0565fe30caf714b0e2ef2507bace82f7ac872f2","payload":{"connection_id":"a6b55582af5f430fb37ad02bf0922475","event_at":"2026-07-28T03:05:04.827000Z","event_type":"price_change","frame_hash":"1fdd36d9782da2d3a47d43d85f9decdcbe19715e0316f9eb2b9e435babadbcc2","frame_index":0,"kind":"data","monotonic_ns":309889066836291,"payload":{"event_type":"price_change","market":"0x779291bef19b6709f61e9764a954aafe9ffae488d50ae674aabdcb4f248006d5","price_changes":[{"asset_id":"8761897749749422724209054078244794145777693856614463256546737399611489089783","best_ask":"0.58","best_bid":"0.57","hash":"f521893e2ff15db3893d47c48d32ed6f6dd3497f","price":"0.51","side":"BUY","size":"230"},{"asset_id":"14965588658799411272385430903075831224615961675357217884735713260981483529984","best_ask":"0.43","best_bid":"0.42","hash":"78f4e751f91b60bd329ed918f01e02b7fdb31020","price":"0.49","side":"SELL","size":"230"}],"timestamp":"1785207904827"},"payload_hash":"855a94469a47975afc7b65e7877d38e3ae3f5d771dae304e8f5dc98c3d966178","raw_frame":"{\"market\":\"0x779291bef19b6709f61e9764a954aafe9ffae488d50ae674aabdcb4f248006d5\", \"price_changes\":[{\"asset_id\":\"8761897749749422724209054078244794145777693856614463256546737399611489089783\", \"price\":\"0.51\", \"size\":\"230\", \"side\":\"BUY\", \"hash\":\"f521893e2ff15db3893d47c48d32ed6f6dd3497f\", \"best_bid\":\"0.57\", \"best_ask\":\"0.58\"}, {\"asset_id\":\"14965588658799411272385430903075831224615961675357217884735713260981483529984\", \"price\":\"0.49\", \"size\":\"230\", \"side\":\"SELL\", \"hash\":\"78f4e751f91b60bd329ed918f01e02b7fdb31020\", \"best_bid\":\"0.42\", \"best_ask\":\"0.43\"}], \"timestamp\":\"1785207904827\", \"event_type\":\"price_change\"}","received_at":"2026-07-28T03:05:06.036433Z","schema_version":"clob-market-ws.price_change.v1","sequence":null,"server_hash":null,"server_timestamp":"1785207904827","session_id":"3e519d9098404c15b234d96025eb1a2b","source":"clob_market_ws"},"received_at":"2026-07-28T03:05:06.036433Z","record_id":"fad3546d83643e7d6942e23f944c5a9838f6e33a8e164926b875433c4215918e","schema_fingerprint":"4aa3821a28b0b7c2400bc59aba4bcc0a76e971dadd19610d3ad38c768e124dc7","schema_version":"edge-lab-recorder.raw.v1","sequence":null,"source":"clob_market_ws"}
{"event_at":"2026-07-28T03:05:04.835000Z","event_fingerprint":"f296cb566bb1df25d442477cabb800e64d3d10d118bbadbf45af32b39a27260e","payload":{"connection_id":"a6b55582af5f430fb37ad02bf0922475","event_at":"2026-07-28T03:05:04.835000Z","event_type":"price_change","frame_hash":"628e23e82443837bf59095921bd9e14ff9f16dbd859adc622011f18ec83e1739","frame_index":0,"kind":"data","monotonic_ns":309889071970750,"payload":{"event_type":"price_change","market":"0x779291bef19b6709f61e9764a954aafe9ffae488d50ae674aabdcb4f248006d5","price_changes":[{"asset_id":"14965588658799411272385430903075831224615961675357217884735713260981483529984","best_ask":"0.43","best_bid":"0.42","hash":"c60d45fd4f09dcbe6236e080f8346647443954e3","price":"0.35","side":"BUY","size":"331.13"},{"asset_id":"8761897749749422724209054078244794145777693856614463256546737399611489089783","best_ask":"0.58","best_bid":"0.57","hash":"f546c95e83fcf8160e6fd5b37f897862f0341f81","price":"0.65","side":"SELL","size":"331.13"}],"timestamp":"1785207904835"},"payload_hash":"1d0425e965592f0ed4393b47174c90d9396adefc72397ce4fa554b280e7cd64c","raw_frame":"{\"market\":\"0x779291bef19b6709f61e9764a954aafe9ffae488d50ae674aabdcb4f248006d5\", \"price_changes\":[{\"asset_id\":\"14965588658799411272385430903075831224615961675357217884735713260981483529984\", \"price\":\"0.35\", \"size\":\"331.13\", \"side\":\"BUY\", \"hash\":\"c60d45fd4f09dcbe6236e080f8346647443954e3\", \"best_bid\":\"0.42\", \"best_ask\":\"0.43\"}, {\"asset_id\":\"8761897749749422724209054078244794145777693856614463256546737399611489089783\", \"price\":\"0.65\", \"size\":\"331.13\", \"side\":\"SELL\", \"hash\":\"f546c95e83fcf8160e6fd5b37f897862f0341f81\", \"best_bid\":\"0.57\", \"best_ask\":\"0.58\"}], \"timestamp\":\"1785207904835\", \"event_type\":\"price_change\"}","received_at":"2026-07-28T03:05:06.041567Z","schema_version":"clob-market-ws.price_change.v1","sequence":null,"server_hash":null,"server_timestamp":"1785207904835","session_id":"3e519d9098404c15b234d96025eb1a2b","source":"clob_market_ws"},"received_at":"2026-07-28T03:05:06.041567Z","record_id":"1e8be924da7a2da5c760e2aed93de287ef29d26b2df07d543665d0108268a36d","schema_fingerprint":"4aa3821a28b0b7c2400bc59aba4bcc0a76e971dadd19610d3ad38c768e124dc7","schema_version":"edge-lab-recorder.raw.v1","sequence":null,"source":"clob_market_ws"}
{"event_at":"2026-07-28T03:05:04.836000Z","event_fingerprint":"deb953ca8c0cc74e45a201f6e3098cda12e5fd9b4d5d4708093b65634be357d6","payload":{"connection_id":"a6b55582af5f430fb37ad02bf0922475","event_at":"2026-07-28T03:05:04.836000Z","event_type":"price_change","frame_hash":"8adeb78c5f6244430b643ff10390faf11650bf307273ea92a09c606adc7e727b","frame_index":0,"kind":"data","monotonic_ns":309889076656416,"payload":{"event_type":"price_change","market":"0x779291bef19b6709f61e9764a954aafe9ffae488d50ae674aabdcb4f248006d5","price_changes":[{"asset_id":"14965588658799411272385430903075831224615961675357217884735713260981483529984","best_ask":"0.43","best_bid":"0.42","hash":"e6e9df0b4532ba25ac373a32dda8468b31372d21","price":"0.34","side":"BUY","size":"149.29"},{"asset_id":"8761897749749422724209054078244794145777693856614463256546737399611489089783","best_ask":"0.58","best_bid":"0.57","hash":"85403410603981437255020cab3217d52e294848","price":"0.66","side":"SELL","size":"149.29"}],"timestamp":"1785207904836"},"payload_hash":"65a20b5d1c2a71d7a5dd3e9b1305abe11f8d346e75b2e5aaaecc7e954993321e","raw_frame":"{\"market\":\"0x779291bef19b6709f61e9764a954aafe9ffae488d50ae674aabdcb4f248006d5\", \"price_changes\":[{\"asset_id\":\"14965588658799411272385430903075831224615961675357217884735713260981483529984\", \"price\":\"0.34\", \"size\":\"149.29\", \"side\":\"BUY\", \"hash\":\"e6e9df0b4532ba25ac373a32dda8468b31372d21\", \"best_bid\":\"0.42\", \"best_ask\":\"0.43\"}, {\"asset_id\":\"8761897749749422724209054078244794145777693856614463256546737399611489089783\", \"price\":\"0.66\", \"size\":\"149.29\", \"side\":\"SELL\", \"hash\":\"85403410603981437255020cab3217d52e294848\", \"best_bid\":\"0.57\", \"best_ask\":\"0.58\"}], \"timestamp\":\"1785207904836\", \"event_type\":\"price_change\"}","received_at":"2026-07-28T03:05:06.046253Z","schema_version":"clob-market-ws.price_change.v1","sequence":null,"server_hash":null,"server_timestamp":"1785207904836","session_id":"3e519d9098404c15b234d96025eb1a2b","source":"clob_market_ws"},"received_at":"2026-07-28T03:05:06.046253Z","record_id":"c60e035c3c79a7fcd948c5712162a486ff0fd92bb9f5018f4238b5ea44a8e719","schema_fingerprint":"4aa3821a28b0b7c2400bc59aba4bcc0a76e971dadd19610d3ad38c768e124dc7","schema_version":"edge-lab-recorder.raw.v1","sequence":null,"source":"clob_market_ws"}
{"event_at":"2026-07-28T03:05:04.839000Z","event_fingerprint":"40a59a4d4ca74a0593fcb0d29a45fdd8ac7fb549f0ed92de230a4df48ecd1bec","payload":{"connection_id":"a6b55582af5f430fb37ad02bf0922475","event_at":"2026-07-28T03:05:04.839000Z","event_type":"price_change","frame_hash":"e9ec47d7437a948d2c8b7ace93a44775d90c37b6a3e3181aa8f9f806ab44c0d8","frame_index":0,"kind":"data","monotonic_ns":309889080798375,"payload":{"event_type":"price_change","market":"0x779291bef19b6709f61e9764a954aafe9ffae488d50ae674aabdcb4f248006d5","price_changes":[{"asset_id":"14965588658799411272385430903075831224615961675357217884735713260981483529984","best_ask":"0.43","best_bid":"0.42","hash":"844baff15474d78cf6d3a1e07f4abbc7d56aeff0","price":"0.33","side":"BUY","size":"221.35"},{"asset_id":"8761897749749422724209054078244794145777693856614463256546737399611489089783","best_ask":"0.58","best_bid":"0.57","hash":"7ba4dbe191e97eedd598bb03657fb2fa4f0585b9","price":"0.67","side":"SELL","size":"221.35"}],"timestamp":"1785207904839"},"payload_hash":"5b0261e4288e88785b076486e4b00e54280523102d5f2464059af45943f80599","raw_frame":"{\"market\":\"0x779291bef19b6709f61e9764a954aafe9ffae488d50ae674aabdcb4f248006d5\", \"price_changes\":[{\"asset_id\":\"14965588658799411272385430903075831224615961675357217884735713260981483529984\", \"price\":\"0.33\", \"size\":\"221.35\", \"side\":\"BUY\", \"hash\":\"844baff15474d78cf6d3a1e07f4abbc7d56aeff0\", \"best_bid\":\"0.42\", \"best_ask\":\"0.43\"}, {\"asset_id\":\"8761897749749422724209054078244794145777693856614463256546737399611489089783\", \"price\":\"0.67\", \"size\":\"221.35\", \"side\":\"SELL\", \"hash\":\"7ba4dbe191e97eedd598bb03657fb2fa4f0585b9\", \"best_bid\":\"0.57\", \"best_ask\":\"0.58\"}], \"timestamp\":\"1785207904839\", \"event_type\":\"price_change\"}","received_at":"2026-07-28T03:05:06.050395Z","schema_version":"clob-market-ws.price_change.v1","sequence":null,"server_hash":null,"server_timestamp":"1785207904839","session_id":"3e519d9098404c15b234d96025eb1a2b","source":"clob_market_ws"},"received_at":"2026-07-28T03:05:06.050395Z","record_id":"7b8cae12dcdf7bd0868685a8871623a31defe21fa03b47dcc7c7fc4025c58d52","schema_fingerprint":"4aa3821a28b0b7c2400bc59aba4bcc0a76e971dadd19610d3ad38c768e124dc7","schema_version":"edge-lab-recorder.raw.v1","sequence":null,"source":"clob_market_ws"}
{"event_at":"2026-07-28T03:05:04.855000Z","event_fingerprint":"729c8bf328de7d6536e377c398be7b8ead1206a63f8095f48b6a436cb484e37b","payload":{"connection_id":"a6b55582af5f430fb37ad02bf0922475","event_at":"2026-07-28T03:05:04.855000Z","event_type":"price_change","frame_hash":"673edf4321716f368277da3029b584ec70e7418aa9b5fbd8b9667ace64539e60","frame_index":0,"kind":"data","monotonic_ns":309889084947083,"payload":{"event_type":"price_change","market":"0x779291bef19b6709f61e9764a954aafe9ffae488d50ae674aabdcb4f248006d5","price_changes":[{"asset_id":"14965588658799411272385430903075831224615961675357217884735713260981483529984","best_ask":"0.43","best_bid":"0.42","hash":"925e3bd17e3689c0a392b661fe855f902c8d0bf8","price":"0.32","side":"BUY","size":"232.34"},{"asset_id":"8761897749749422724209054078244794145777693856614463256546737399611489089783","best_ask":"0.58","best_bid":"0.57","hash":"fac011e043d66e3361e8ec837593876ee17d45f8","price":"0.68","side":"SELL","size":"232.34"}],"timestamp":"1785207904855"},"payload_hash":"e95a3e593dc9bbe4a3b958673a433f29bee1ae8a6dde33bdf85b55511df79e2e","raw_frame":"{\"market\":\"0x779291bef19b6709f61e9764a954aafe9ffae488d50ae674aabdcb4f248006d5\", \"price_changes\":[{\"asset_id\":\"14965588658799411272385430903075831224615961675357217884735713260981483529984\", \"price\":\"0.32\", \"size\":\"232.34\", \"side\":\"BUY\", \"hash\":\"925e3bd17e3689c0a392b661fe855f902c8d0bf8\", \"best_bid\":\"0.42\", \"best_ask\":\"0.43\"}, {\"asset_id\":\"8761897749749422724209054078244794145777693856614463256546737399611489089783\", \"price\":\"0.68\", \"size\":\"232.34\", \"side\":\"SELL\", \"hash\":\"fac011e043d66e3361e8ec837593876ee17d45f8\", \"best_bid\":\"0.57\", \"best_ask\":\"0.58\"}], \"timestamp\":\"1785207904855\", \"event_type\":\"price_change\"}","received_at":"2026-07-28T03:05:06.054543Z","schema_version":"clob-market-ws.price_change.v1","sequence":null,"server_hash":null,"server_timestamp":"1785207904855","session_id":"3e519d9098404c15b234d96025eb1a2b","source":"clob_market_ws"},"received_at":"2026-07-28T03:05:06.054543Z","record_id":"81be12db03b287597a67e32defe7aa3831215df4cd52c32b6f5a493415f84b10","schema_fingerprint":"4aa3821a28b0b7c2400bc59aba4bcc0a76e971dadd19610d3ad38c768e124dc7","schema_version":"edge-lab-recorder.raw.v1","sequence":null,"source":"clob_market_ws"}
{"event_at":"2026-07-28T03:05:04.878000Z","event_fingerprint":"c6bd9ae68d47d3ca58b513b188dbde057ed37ed941a36c9a34d211a2228c50a8","payload":{"connection_id":"a6b55582af5f430fb37ad02bf0922475","event_at":"2026-07-28T03:05:04.878000Z","event_type":"price_change","frame_hash":"209fbfbaa2fad8b1545bd2d7d76f7129fd9060d36e8f922d4a179a86dce950e8","frame_index":0,"kind":"data","monotonic_ns":309889089323166,"payload":{"event_type":"price_change","market":"0x779291bef19b6709f61e9764a954aafe9ffae488d50ae674aabdcb4f248006d5","price_changes":[{"asset_id":"8761897749749422724209054078244794145777693856614463256546737399611489089783","best_ask":"0.58","best_bid":"0.57","hash":"339eb1e3f1297519278b444120839935afd521c3","price":"0.03","side":"BUY","size":"648.1"},{"asset_id":"14965588658799411272385430903075831224615961675357217884735713260981483529984","best_ask":"0.43","best_bid":"0.42","hash":"b29b9dcbcb903b064597c285ff6d338cc84753af","price":"0.97","side":"SELL","size":"648.1"}],"timestamp":"1785207904878"},"payload_hash":"b3f8be098edf3eb0f7c86bbc2521dd361f97ccc2466605a85532892e60739e81","raw_frame":"{\"market\":\"0x779291bef19b6709f61e9764a954aafe9ffae488d50ae674aabdcb4f248006d5\", \"price_changes\":[{\"asset_id\":\"8761897749749422724209054078244794145777693856614463256546737399611489089783\", \"price\":\"0.03\", \"size\":\"648.1\", \"side\":\"BUY\", \"hash\":\"339eb1e3f1297519278b444120839935afd521c3\", \"best_bid\":\"0.57\", \"best_ask\":\"0.58\"}, {\"asset_id\":\"14965588658799411272385430903075831224615961675357217884735713260981483529984\", \"price\":\"0.97\", \"size\":\"648.1\", \"side\":\"SELL\", \"hash\":\"b29b9dcbcb903b064597c285ff6d338cc84753af\", \"best_bid\":\"0.42\", \"best_ask\":\"0.43\"}], \"timestamp\":\"1785207904878\", \"event_type\":\"price_change\"}","received_at":"2026-07-28T03:05:06.058920Z","schema_version":"clob-market-ws.price_change.v1","sequence":null,"server_hash":null,"server_timestamp":"1785207904878","session_id":"3e519d9098404c15b234d96025eb1a2b","source":"clob_market_ws"},"received_at":"2026-07-28T03:05:06.058920Z","record_id":"43fa1c6a65eb985e1a7ae096e1f53333da9886071461bb8358e876d36651dacf","schema_fingerprint":"4aa3821a28b0b7c2400bc59aba4bcc0a76e971dadd19610d3ad38c768e124dc7","schema_version":"edge-lab-recorder.raw.v1","sequence":null,"source":"clob_market_ws"}
{"event_at":"2026-07-28T03:05:04.915000Z","event_fingerprint":"474b5484c2b76e18b0554e76eeabdbc2cf512ad94d41f1e8f7c8c2a405181fb1","payload":{"connection_id":"a6b55582af5f430fb37ad02bf0922475","event_at":"2026-07-28T03:05:04.915000Z","event_type":"price_change","frame_hash":"38b616f394e5a6e0cb23ce6e1e8b8a9c0cfabdb43ec67e3a0535516c82cc9e66","frame_index":0,"kind":"data","monotonic_ns":309889092957166,"payload":{"event_type":"price_change","market":"0x779291bef19b6709f61e9764a954aafe9ffae488d50ae674aabdcb4f248006d5","price_changes":[{"asset_id":"8761897749749422724209054078244794145777693856614463256546737399611489089783","best_ask":"0.58","best_bid":"0.57","hash":"89213f8420a48d99f236320699a544aa214bdbb4","price":"0.01","side":"BUY","size":"5858.02"},{"asset_id":"14965588658799411272385430903075831224615961675357217884735713260981483529984","best_ask":"0.43","best_bid":"0.42","hash":"ad3e627d988fc9341504bdf927a3052f0226add8","price":"0.99","side":"SELL","size":"5858.02"}],"timestamp":"1785207904915"},"payload_hash":"098fff4785938c8cbe8516d147d708e0fe56fca53dbf03341983ded3e31f7806","raw_frame":"{\"market\":\"0x779291bef19b6709f61e9764a954aafe9ffae488d50ae674aabdcb4f248006d5\", \"price_changes\":[{\"asset_id\":\"8761897749749422724209054078244794145777693856614463256546737399611489089783\", \"price\":\"0.01\", \"size\":\"5858.02\", \"side\":\"BUY\", \"hash\":\"89213f8420a48d99f236320699a544aa214bdbb4\", \"best_bid\":\"0.57\", \"best_ask\":\"0.58\"}, {\"asset_id\":\"14965588658799411272385430903075831224615961675357217884735713260981483529984\", \"price\":\"0.99\", \"size\":\"5858.02\", \"side\":\"SELL\", \"hash\":\"ad3e627d988fc9341504bdf927a3052f0226add8\", \"best_bid\":\"0.42\", \"best_ask\":\"0.43\"}], \"timestamp\":\"1785207904915\", \"event_type\":\"price_change\"}","received_at":"2026-07-28T03:05:06.062553Z","schema_version":"clob-market-ws.price_change.v1","sequence":null,"server_hash":null,"server_timestamp":"1785207904915","session_id":"3e519d9098404c15b234d96025eb1a2b","source":"clob_market_ws"},"received_at":"2026-07-28T03:05:06.062553Z","record_id":"7a7faef26e84302521a55ad003510dde5a97f1c588e5a84e770cb08e50e1f87c","schema_fingerprint":"4aa3821a28b0b7c2400bc59aba4bcc0a76e971dadd19610d3ad38c768e124dc7","schema_version":"edge-lab-recorder.raw.v1","sequence":null,"source":"clob_market_ws"}
{"event_at":"2026-07-28T03:05:04.921000Z","event_fingerprint":"210aa4b488a8a9812ada007a9a15d0a728b60a04f9ae59132f18278c1a874591","payload":{"connection_id":"a6b55582af5f430fb37ad02bf0922475","event_at":"2026-07-28T03:05:04.921000Z","event_type":"price_change","frame_hash":"cac747650833921817ddf5a7351358033697a2d6b0055e431abe93768f27a107","frame_index":0,"kind":"data","monotonic_ns":309889095845208,"payload":{"event_type":"price_change","market":"0x779291bef19b6709f61e9764a954aafe9ffae488d50ae674aabdcb4f248006d5","price_changes":[{"asset_id":"8761897749749422724209054078244794145777693856614463256546737399611489089783","best_ask":"0.58","best_bid":"0.57","hash":"f07b07934753e36f679f992ace878ece593d6cbf","price":"0.57","side":"BUY","size":"42.98"},{"asset_id":"14965588658799411272385430903075831224615961675357217884735713260981483529984","best_ask":"0.43","best_bid":"0.42","hash":"0e8e9a98b0bb71b4d4d2a6d3317929994c8b2ee5","price":"0.43","side":"SELL","size":"42.98"}],"timestamp":"1785207904921"},"payload_hash":"4a591b856350c557f00895f887e3d5a3e32337ea1e8d30bf892b806eab5f390c","raw_frame":"{\"market\":\"0x779291bef19b6709f61e9764a954aafe9ffae488d50ae674aabdcb4f248006d5\", \"price_changes\":[{\"asset_id\":\"8761897749749422724209054078244794145777693856614463256546737399611489089783\", \"price\":\"0.57\", \"size\":\"42.98\", \"side\":\"BUY\", \"hash\":\"f07b07934753e36f679f992ace878ece593d6cbf\", \"best_bid\":\"0.57\", \"best_ask\":\"0.58\"}, {\"asset_id\":\"14965588658799411272385430903075831224615961675357217884735713260981483529984\", \"price\":\"0.43\", \"size\":\"42.98\", \"side\":\"SELL\", \"hash\":\"0e8e9a98b0bb71b4d4d2a6d3317929994c8b2ee5\", \"best_bid\":\"0.42\", \"best_ask\":\"0.43\"}], \"timestamp\":\"1785207904921\", \"event_type\":\"price_change\"}","received_at":"2026-07-28T03:05:06.065441Z","schema_version":"clob-market-ws.price_change.v1","sequence":null,"server_hash":null,"server_timestamp":"1785207904921","session_id":"3e519d9098404c15b234d96025eb1a2b","source":"clob_market_ws"},"received_at":"2026-07-28T03:05:06.065441Z","record_id":"7bfba675512ebe8c3df8458e41e93bc54484189e65f1c2c27b67c353f8158992","schema_fingerprint":"4aa3821a28b0b7c2400bc59aba4bcc0a76e971dadd19610d3ad38c768e124dc7","schema_version":"edge-lab-recorder.raw.v1","sequence":null,"source":"clob_market_ws"}
{"event_at":"2026-07-28T03:05:04.923000Z","event_fingerprint":"f765c1ec9ec75c356b122e7c16c3a463d6646d4d5a2d025949bac3e24ac0b5f9","payload":{"connection_id":"a6b55582af5f430fb37ad02bf0922475","event_at":"2026-07-28T03:05:04.923000Z","event_type":"price_change","frame_hash":"cefd5e7c849c87056f0ba2c98e960669d89ebba9c1fefcd70b3b19198df68a3a","frame_index":0,"kind":"data","monotonic_ns":309889100143625,"payload":{"event_type":"price_change","market":"0x779291bef19b6709f61e9764a954aafe9ffae488d50ae674aabdcb4f248006d5","price_changes":[{"asset_id":"8761897749749422724209054078244794145777693856614463256546737399611489089783","best_ask":"0.58","best_bid":"0.57","hash":"ab504596d83b9f14b4d655a1f31df6a02ffe2fb3","price":"0.47","side":"BUY","size":"151"},{"asset_id":"14965588658799411272385430903075831224615961675357217884735713260981483529984","best_ask":"0.43","best_bid":"0.42","hash":"a9d1d6d94a80b2077752a10853abbdd08fed7bc8","price":"0.53","side":"SELL","size":"151"}],"timestamp":"1785207904923"},"payload_hash":"a18443926de83465973db1a0608ddb6c1a8fd61c7929cb2956b30772b5ade282","raw_frame":"{\"market\":\"0x779291bef19b6709f61e9764a954aafe9ffae488d50ae674aabdcb4f248006d5\", \"price_changes\":[{\"asset_id\":\"8761897749749422724209054078244794145777693856614463256546737399611489089783\", \"price\":\"0.47\", \"size\":\"151\", \"side\":\"BUY\", \"hash\":\"ab504596d83b9f14b4d655a1f31df6a02ffe2fb3\", \"best_bid\":\"0.57\", \"best_ask\":\"0.58\"}, {\"asset_id\":\"14965588658799411272385430903075831224615961675357217884735713260981483529984\", \"price\":\"0.53\", \"size\":\"151\", \"side\":\"SELL\", \"hash\":\"a9d1d6d94a80b2077752a10853abbdd08fed7bc8\", \"best_bid\":\"0.42\", \"best_ask\":\"0.43\"}], \"timestamp\":\"1785207904923\", \"event_type\":\"price_change\"}","received_at":"2026-07-28T03:05:06.069739Z","schema_version":"clob-market-ws.price_change.v1","sequence":null,"server_hash":null,"server_timestamp":"1785207904923","session_id":"3e519d9098404c15b234d96025eb1a2b","source":"clob_market_ws"},"received_at":"2026-07-28T03:05:06.069739Z","record_id":"3808df94a9153cc9c6d5ec4872d405704e348d630dd71d1638ab5023ba4b3268","schema_fingerprint":"4aa3821a28b0b7c2400bc59aba4bcc0a76e971dadd19610d3ad38c768e124dc7","schema_version":"edge-lab-recorder.raw.v1","sequence":null,"source":"clob_market_ws"}
{"event_at":"2026-07-28T03:05:04.938000Z","event_fingerprint":"f2f0158e0a9a3d1e82cac4735548f719767c57059531f48a09aa9edacb8369b4","payload":{"connection_id":"a6b55582af5f430fb37ad02bf0922475","event_at":"2026-07-28T03:05:04.938000Z","event_type":"price_change","frame_hash":"4e727d6ec95e4e681b7b622d759ad57fcd24fd281f7b2299d4bff29294864f8a","frame_index":0,"kind":"data","monotonic_ns":309889105879791,"payload":{"event_type":"price_change","market":"0x779291bef19b6709f61e9764a954aafe9ffae488d50ae674aabdcb4f248006d5","price_changes":[{"asset_id":"8761897749749422724209054078244794145777693856614463256546737399611489089783","best_ask":"0.58","best_bid":"0.57","hash":"de9bbb38b1798779f45ea166cf33f8656e96ea34","price":"0.01","side":"BUY","size":"5853.02"},{"asset_id":"14965588658799411272385430903075831224615961675357217884735713260981483529984","best_ask":"0.43","best_bid":"0.42","hash":"c2058fdf74c49f7a178b15dce6c8ca8b6a689c6f","price":"0.99","side":"SELL","size":"5853.02"}],"timestamp":"1785207904938"},"payload_hash":"2e06c50ac3a0ad287fc60dfa6af419aeaf359b114f588c84ba657849b482f9a8","raw_frame":"{\"market\":\"0x779291bef19b6709f61e9764a954aafe9ffae488d50ae674aabdcb4f248006d5\", \"price_changes\":[{\"asset_id\":\"8761897749749422724209054078244794145777693856614463256546737399611489089783\", \"price\":\"0.01\", \"size\":\"5853.02\", \"side\":\"BUY\", \"hash\":\"de9bbb38b1798779f45ea166cf33f8656e96ea34\", \"best_bid\":\"0.57\", \"best_ask\":\"0.58\"}, {\"asset_id\":\"14965588658799411272385430903075831224615961675357217884735713260981483529984\", \"price\":\"0.99\", \"size\":\"5853.02\", \"side\":\"SELL\", \"hash\":\"c2058fdf74c49f7a178b15dce6c8ca8b6a689c6f\", \"best_bid\":\"0.42\", \"best_ask\":\"0.43\"}], \"timestamp\":\"1785207904938\", \"event_type\":\"price_change\"}","received_at":"2026-07-28T03:05:06.075475Z","schema_version":"clob-market-ws.price_change.v1","sequence":null,"server_hash":null,"server_timestamp":"1785207904938","session_id":"3e519d9098404c15b234d96025eb1a2b","source":"clob_market_ws"},"received_at":"2026-07-28T03:05:06.075475Z","record_id":"b03553c8ab3b0e6a0bc1e14f81ea5e2ba6505ef89e56dd6031ab1552edecadbc","schema_fingerprint":"4aa3821a28b0b7c2400bc59aba4bcc0a76e971dadd19610d3ad38c768e124dc7","schema_version":"edge-lab-recorder.raw.v1","sequence":null,"source":"clob_market_ws"}
{"event_at":"2026-07-28T03:05:04.940000Z","event_fingerprint":"85e6420097b51dc57182de01cdbdb6f99026a33d69a18b3c9bf6c4085f4576ea","payload":{"connection_id":"a6b55582af5f430fb37ad02bf0922475","event_at":"2026-07-28T03:05:04.940000Z","event_type":"price_change","frame_hash":"ec8429875797c54af2a89bdd70e24d4f21def33bff5d07a906d1b953a4f7f2ec","frame_index":0,"kind":"data","monotonic_ns":309889110249500,"payload":{"event_type":"price_change","market":"0x779291bef19b6709f61e9764a954aafe9ffae488d50ae674aabdcb4f248006d5","price_changes":[{"asset_id":"8761897749749422724209054078244794145777693856614463256546737399611489089783","best_ask":"0.58","best_bid":"0.57","hash":"72a8779e9836e042decef326c11baefd13362980","price":"0.03","side":"BUY","size":"643.1"},{"asset_id":"14965588658799411272385430903075831224615961675357217884735713260981483529984","best_ask":"0.43","best_bid":"0.42","hash":"f475df6d11c4bdf79d0ab9fd19c78298f7385c9c","price":"0.97","side":"SELL","size":"643.1"}],"timestamp":"1785207904940"},"payload_hash":"53f8cd3e33d9f10f5b83250eaca9c7a7542226e1657708d41cd26562f6c9a981","raw_frame":"{\"market\":\"0x779291bef19b6709f61e9764a954aafe9ffae488d50ae674aabdcb4f248006d5\", \"price_changes\":[{\"asset_id\":\"8761897749749422724209054078244794145777693856614463256546737399611489089783\", \"price\":\"0.03\", \"size\":\"643.1\", \"side\":\"BUY\", \"hash\":\"72a8779e9836e042decef326c11baefd13362980\", \"best_bid\":\"0.57\", \"best_ask\":\"0.58\"}, {\"asset_id\":\"14965588658799411272385430903075831224615961675357217884735713260981483529984\", \"price\":\"0.97\", \"size\":\"643.1\", \"side\":\"SELL\", \"hash\":\"f475df6d11c4bdf79d0ab9fd19c78298f7385c9c\", \"best_bid\":\"0.42\", \"best_ask\":\"0.43\"}], \"timestamp\":\"1785207904940\", \"event_type\":\"price_change\"}","received_at":"2026-07-28T03:05:06.079844Z","schema_version":"clob-market-ws.price_change.v1","sequence":null,"server_hash":null,"server_timestamp":"1785207904940","session_id":"3e519d9098404c15b234d96025eb1a2b","source":"clob_market_ws"},"received_at":"2026-07-28T03:05:06.079844Z","record_id":"4f13b08e56ed97199a079bafcd1357da3449fbfbdf14f90f95314a48dd4d28a1","schema_fingerprint":"4aa3821a28b0b7c2400bc59aba4bcc0a76e971dadd19610d3ad38c768e124dc7","schema_version":"edge-lab-recorder.raw.v1","sequence":null,"source":"clob_market_ws"}
{"event_at":"2026-07-28T03:05:04.973000Z","event_fingerprint":"ace6752abd1e84e67a2aa5fe2f18390d0736aa2d6fa139fa8051a5b0c3f180db","payload":{"connection_id":"a6b55582af5f430fb37ad02bf0922475","event_at":"2026-07-28T03:05:04.973000Z","event_type":"price_change","frame_hash":"27985068606dd9300b749b23dd520797304f1a85a28fd964fd72f9c86c15b031","frame_index":0,"kind":"data","monotonic_ns":309889115299666,"payload":{"event_type":"price_change","market":"0x779291bef19b6709f61e9764a954aafe9ffae488d50ae674aabdcb4f248006d5","price_changes":[{"asset_id":"8761897749749422724209054078244794145777693856614463256546737399611489089783","best_ask":"0.58","best_bid":"0.57","hash":"e99c33d0069518e65361737030452178994a1425","price":"0.53","side":"BUY","size":"227.02"},{"asset_id":"14965588658799411272385430903075831224615961675357217884735713260981483529984","best_ask":"0.43","best_bid":"0.42","hash":"c2bd5b4b5d0108d82c73dcd26073a1335e06cf78","price":"0.47","side":"SELL","size":"227.02"}],"timestamp":"1785207904973"},"payload_hash":"ed1192de5cdf56e9e94415d5e020512e359ed87c265885e903895d0da9fb97a2","raw_frame":"{\"market\":\"0x779291bef19b6709f61e9764a954aafe9ffae488d50ae674aabdcb4f248006d5\", \"price_changes\":[{\"asset_id\":\"8761897749749422724209054078244794145777693856614463256546737399611489089783\", \"price\":\"0.53\", \"size\":\"227.02\", \"side\":\"BUY\", \"hash\":\"e99c33d0069518e65361737030452178994a1425\", \"best_bid\":\"0.57\", \"best_ask\":\"0.58\"}, {\"asset_id\":\"14965588658799411272385430903075831224615961675357217884735713260981483529984\", \"price\":\"0.47\", \"size\":\"227.02\", \"side\":\"SELL\", \"hash\":\"c2bd5b4b5d0108d82c73dcd26073a1335e06cf78\", \"best_bid\":\"0.42\", \"best_ask\":\"0.43\"}], \"timestamp\":\"1785207904973\", \"event_type\":\"price_change\"}","received_at":"2026-07-28T03:05:06.084895Z","schema_version":"clob-market-ws.price_change.v1","sequence":null,"server_hash":null,"server_timestamp":"1785207904973","session_id":"3e519d9098404c15b234d96025eb1a2b","source":"clob_market_ws"},"received_at":"2026-07-28T03:05:06.084895Z","record_id":"667791318ac483609fb2bfd2d837b6005ce9392a650dec25eba275c1f89636ae","schema_fingerprint":"4aa3821a28b0b7c2400bc59aba4bcc0a76e971dadd19610d3ad38c768e124dc7","schema_version":"edge-lab-recorder.raw.v1","sequence":null,"source":"clob_market_ws"}
{"event_at":"2026-07-28T03:05:05.003000Z","event_fingerprint":"50b0af18c268587a201ac9a745f2fbf7d067da9c3b7c6f0dd816acd1cc40fe5b","payload":{"connection_id":"a6b55582af5f430fb37ad02bf0922475","event_at":"2026-07-28T03:05:05.003000Z","event_type":"price_change","frame_hash":"6bf3ae34083d4d1c34509da7f2490fce763828ba6c268aeda6fa5508552a430e","frame_index":0,"kind":"data","monotonic_ns":309889118855500,"payload":{"event_type":"price_change","market":"0x779291bef19b6709f61e9764a954aafe9ffae488d50ae674aabdcb4f248006d5","price_changes":[{"asset_id":"8761897749749422724209054078244794145777693856614463256546737399611489089783","best_ask":"0.58","best_bid":"0.57","hash":"fad392a193a5868de6515bb253691e69428a88cc","price":"0.54","side":"BUY","size":"135.04"},{"asset_id":"14965588658799411272385430903075831224615961675357217884735713260981483529984","best_ask":"0.43","best_bid":"0.42","hash":"cb61f8099636efc64c791c08139b0d810bbe24e4","price":"0.46","side":"SELL","size":"135.04"}],"timestamp":"1785207905003"},"payload_hash":"8177a3aebefe0c59fcc4bb8535a246d412a81e44973b0e6c9c8c88b4f948ad49","raw_frame":"{\"market\":\"0x779291bef19b6709f61e9764a954aafe9ffae488d50ae674aabdcb4f248006d5\", \"price_changes\":[{\"asset_id\":\"8761897749749422724209054078244794145777693856614463256546737399611489089783\", \"price\":\"0.54\", \"size\":\"135.04\", \"side\":\"BUY\", \"hash\":\"fad392a193a5868de6515bb253691e69428a88cc\", \"best_bid\":\"0.57\", \"best_ask\":\"0.58\"}, {\"asset_id\":\"14965588658799411272385430903075831224615961675357217884735713260981483529984\", \"price\":\"0.46\", \"size\":\"135.04\", \"side\":\"SELL\", \"hash\":\"cb61f8099636efc64c791c08139b0d810bbe24e4\", \"best_bid\":\"0.42\", \"best_ask\":\"0.43\"}], \"timestamp\":\"1785207905003\", \"event_type\":\"price_change\"}","received_at":"2026-07-28T03:05:06.088451Z","schema_version":"clob-market-ws.price_change.v1","sequence":null,"server_hash":null,"server_timestamp":"1785207905003","session_id":"3e519d9098404c15b234d96025eb1a2b","source":"clob_market_ws"},"received_at":"2026-07-28T03:05:06.088451Z","record_id":"5a6ebfccdabf4c42b5d74621f55d66f39a8af8775ec32dc875a99fb6acae1527","schema_fingerprint":"4aa3821a28b0b7c2400bc59aba4bcc0a76e971dadd19610d3ad38c768e124dc7","schema_version":"edge-lab-recorder.raw.v1","sequence":null,"source":"clob_market_ws"}
{"event_at":"2026-07-28T03:05:05.018000Z","event_fingerprint":"2ce9ad6ae31b3da848aa5c8a3fe93c9c235b17037a5a0b76cc08c1c61d1929cd","payload":{"connection_id":"a6b55582af5f430fb37ad02bf0922475","event_at":"2026-07-28T03:05:05.018000Z","event_type":"price_change","frame_hash":"11778975cd0d19f283ce72fe0ac0de005a2cbaf1400b6d8fd37df4b763f4c368","frame_index":0,"kind":"data","monotonic_ns":309889122134000,"payload":{"event_type":"price_change","market":"0x779291bef19b6709f61e9764a954aafe9ffae488d50ae674aabdcb4f248006d5","price_changes":[{"asset_id":"14965588658799411272385430903075831224615961675357217884735713260981483529984","best_ask":"0.43","best_bid":"0.42","hash":"2f9960dcb531141863fc37e7f32ee25b258e04b7","price":"0.01","side":"BUY","size":"5888.02"},{"asset_id":"8761897749749422724209054078244794145777693856614463256546737399611489089783","best_ask":"0.58","best_bid":"0.57","hash":"cdd984c1562c8e433e8a5a4416931352fb41caa7","price":"0.99","side":"SELL","size":"5888.02"}],"timestamp":"1785207905018"},"payload_hash":"8696c76ad3303ca393e5138b80af3baee58ae54806a4a13971fac8ee60652a56","raw_frame":"{\"market\":\"0x779291bef19b6709f61e9764a954aafe9ffae488d50ae674aabdcb4f248006d5\", \"price_changes\":[{\"asset_id\":\"14965588658799411272385430903075831224615961675357217884735713260981483529984\", \"price\":\"0.01\", \"size\":\"5888.02\", \"side\":\"BUY\", \"hash\":\"2f9960dcb531141863fc37e7f32ee25b258e04b7\", \"best_bid\":\"0.42\", \"best_ask\":\"0.43\"}, {\"asset_id\":\"8761897749749422724209054078244794145777693856614463256546737399611489089783\", \"price\":\"0.99\", \"size\":\"5888.02\", \"side\":\"SELL\", \"hash\":\"cdd984c1562c8e433e8a5a4416931352fb41caa7\", \"best_bid\":\"0.57\", \"best_ask\":\"0.58\"}], \"timestamp\":\"1785207905018\", \"event_type\":\"price_change\"}","received_at":"2026-07-28T03:05:06.091728Z","schema_version":"clob-market-ws.price_change.v1","sequence":null,"server_hash":null,"server_timestamp":"1785207905018","session_id":"3e519d9098404c15b234d96025eb1a2b","source":"clob_market_ws"},"received_at":"2026-07-28T03:05:06.091728Z","record_id":"fb203f2528d382c15ce03ff47bdd3bb69783988d3f04de646ddb73056115a300","schema_fingerprint":"4aa3821a28b0b7c2400bc59aba4bcc0a76e971dadd19610d3ad38c768e124dc7","schema_version":"edge-lab-recorder.raw.v1","sequence":null,"source":"clob_market_ws"}
{"event_at":"2026-07-28T03:05:05.020000Z","event_fingerprint":"6c522795875b00b19d36421b0f8ca4f0d35de18f14c8aa4c7673aa0920aec695","payload":{"connection_id":"a6b55582af5f430fb37ad02bf0922475","event_at":"2026-07-28T03:05:05.020000Z","event_type":"price_change","frame_hash":"4c4c011cc64562e46133b921c182ff9c44aa8a7cd2fca66670bc1558ae7b650f","frame_index":0,"kind":"data","monotonic_ns":309889126249125,"payload":{"event_type":"price_change","market":"0x779291bef19b6709f61e9764a954aafe9ffae488d50ae674aabdcb4f248006d5","price_changes":[{"asset_id":"14965588658799411272385430903075831224615961675357217884735713260981483529984","best_ask":"0.43","best_bid":"0.42","hash":"5fe5718a67c1d09ba818ccbd03ac9ef68f0d83d0","price":"0.01","side":"BUY","size":"5893.02"},{"asset_id":"8761897749749422724209054078244794145777693856614463256546737399611489089783","best_ask":"0.58","best_bid":"0.57","hash":"6564149ac845d5c6eff1219e1d4cfa0b772f8486","price":"0.99","side":"SELL","size":"5893.02"}],"timestamp":"1785207905020"},"payload_hash":"353a19a86b1ce77a4a993ceb5dc1e4cf2aca60bb14c4fdaff2b075ec4b1ea71d","raw_frame":"{\"market\":\"0x779291bef19b6709f61e9764a954aafe9ffae488d50ae674aabdcb4f248006d5\", \"price_changes\":[{\"asset_id\":\"14965588658799411272385430903075831224615961675357217884735713260981483529984\", \"price\":\"0.01\", \"size\":\"5893.02\", \"side\":\"BUY\", \"hash\":\"5fe5718a67c1d09ba818ccbd03ac9ef68f0d83d0\", \"best_bid\":\"0.42\", \"best_ask\":\"0.43\"}, {\"asset_id\":\"8761897749749422724209054078244794145777693856614463256546737399611489089783\", \"price\":\"0.99\", \"size\":\"5893.02\", \"side\":\"SELL\", \"hash\":\"6564149ac845d5c6eff1219e1d4cfa0b772f8486\", \"best_bid\":\"0.57\", \"best_ask\":\"0.58\"}], \"timestamp\":\"1785207905020\", \"event_type\":\"price_change\"}","received_at":"2026-07-28T03:05:06.095844Z","schema_version":"clob-market-ws.price_change.v1","sequence":null,"server_hash":null,"server_timestamp":"1785207905020","session_id":"3e519d9098404c15b234d96025eb1a2b","source":"clob_market_ws"},"received_at":"2026-07-28T03:05:06.095844Z","record_id":"2942ce1c3a8dd14ebc5f7c1fe394f9a63d9fa0e4b44921c49141ca6247d7a155","schema_fingerprint":"4aa3821a28b0b7c2400bc59aba4bcc0a76e971dadd19610d3ad38c768e124dc7","schema_version":"edge-lab-recorder.raw.v1","sequence":null,"source":"clob_market_ws"}
{"event_at":"2026-07-28T03:05:05.034000Z","event_fingerprint":"36ce0d9e0e1e14d20efc59f2aeedaa4f339a762201b4d4dd95d1e3fb8e8ab9c0","payload":{"connection_id":"a6b55582af5f430fb37ad02bf0922475","event_at":"2026-07-28T03:05:05.034000Z","event_type":"price_change","frame_hash":"331d45566ac2f71ec139f8fe43583e30399d071ef8518d2dabd58f66302a0884","frame_index":0,"kind":"data","monotonic_ns":309889130618875,"payload":{"event_type":"price_change","market":"0x779291bef19b6709f61e9764a954aafe9ffae488d50ae674aabdcb4f248006d5","price_changes":[{"asset_id":"8761897749749422724209054078244794145777693856614463256546737399611489089783","best_ask":"0.58","best_bid":"0.57","hash":"ccbced74ec2a9f2574d358b149fb9c40da0c7168","price":"0.03","side":"BUY","size":"648.1"},{"asset_id":"14965588658799411272385430903075831224615961675357217884735713260981483529984","best_ask":"0.43","best_bid":"0.42","hash":"0af514e8a61b4f4f02cd4b14249e4fc8bb9c8183","price":"0.97","side":"SELL","size":"648.1"}],"timestamp":"1785207905034"},"payload_hash":"825c0ee5fc0d27b93f20e43102b64b374b4106972a2e657363c3484193ec3b3e","raw_frame":"{\"market\":\"0x779291bef19b6709f61e9764a954aafe9ffae488d50ae674aabdcb4f248006d5\", \"price_changes\":[{\"asset_id\":\"8761897749749422724209054078244794145777693856614463256546737399611489089783\", \"price\":\"0.03\", \"size\":\"648.1\", \"side\":\"BUY\", \"hash\":\"ccbced74ec2a9f2574d358b149fb9c40da0c7168\", \"best_bid\":\"0.57\", \"best_ask\":\"0.58\"}, {\"asset_id\":\"14965588658799411272385430903075831224615961675357217884735713260981483529984\", \"price\":\"0.97\", \"size\":\"648.1\", \"side\":\"SELL\", \"hash\":\"0af514e8a61b4f4f02cd4b14249e4fc8bb9c8183\", \"best_bid\":\"0.42\", \"best_ask\":\"0.43\"}], \"timestamp\":\"1785207905034\", \"event_type\":\"price_change\"}","received_at":"2026-07-28T03:05:06.100213Z","schema_version":"clob-market-ws.price_change.v1","sequence":null,"server_hash":null,"server_timestamp":"1785207905034","session_id":"3e519d9098404c15b234d96025eb1a2b","source":"clob_market_ws"},"received_at":"2026-07-28T03:05:06.100213Z","record_id":"917f4c37662eae4cf97e68aa38d5df1e0ef9745588a1de0d520d2bbbda2ad193","schema_fingerprint":"4aa3821a28b0b7c2400bc59aba4bcc0a76e971dadd19610d3ad38c768e124dc7","schema_version":"edge-lab-recorder.raw.v1","sequence":null,"source":"clob_market_ws"}
{"event_at":"2026-07-28T03:05:05.040000Z","event_fingerprint":"0dbe8ba3df646c5ca4ee3984e08d9852f6ad7e178908106a383402b978d71787","payload":{"connection_id":"a6b55582af5f430fb37ad02bf0922475","event_at":"2026-07-28T03:05:05.040000Z","event_type":"price_change","frame_hash":"c4023d7efe7d6d1c7dfce7be8f0b31c31c0ca148327d334ca61b2c6fa7c8b610","frame_index":0,"kind":"data","monotonic_ns":309889135185291,"payload":{"event_type":"price_change","market":"0x779291bef19b6709f61e9764a954aafe9ffae488d50ae674aabdcb4f248006d5","price_changes":[{"asset_id":"14965588658799411272385430903075831224615961675357217884735713260981483529984","best_ask":"0.43","best_bid":"0.42","hash":"b1cdbbdef26e2ba50cef96b12897b9e15b388b60","price":"0.01","side":"BUY","size":"5888.02"},{"asset_id":"8761897749749422724209054078244794145777693856614463256546737399611489089783","best_ask":"0.58","best_bid":"0.57","hash":"7c971afb2f7eeaedd6f764fe70bd8510502e3c49","price":"0.99","side":"SELL","size":"5888.02"}],"timestamp":"1785207905040"},"payload_hash":"2e51df059f1d806a9cd310132cdfefc600057dd7c01d91ec211175ce78a607f1","raw_frame":"{\"market\":\"0x779291bef19b6709f61e9764a954aafe9ffae488d50ae674aabdcb4f248006d5\", \"price_changes\":[{\"asset_id\":\"14965588658799411272385430903075831224615961675357217884735713260981483529984\", \"price\":\"0.01\", \"size\":\"5888.02\", \"side\":\"BUY\", \"hash\":\"b1cdbbdef26e2ba50cef96b12897b9e15b388b60\", \"best_bid\":\"0.42\", \"best_ask\":\"0.43\"}, {\"asset_id\":\"8761897749749422724209054078244794145777693856614463256546737399611489089783\", \"price\":\"0.99\", \"size\":\"5888.02\", \"side\":\"SELL\", \"hash\":\"7c971afb2f7eeaedd6f764fe70bd8510502e3c49\", \"best_bid\":\"0.57\", \"best_ask\":\"0.58\"}], \"timestamp\":\"1785207905040\", \"event_type\":\"price_change\"}","received_at":"2026-07-28T03:05:06.104779Z","schema_version":"clob-market-ws.price_change.v1","sequence":null,"server_hash":null,"server_timestamp":"1785207905040","session_id":"3e519d9098404c15b234d96025eb1a2b","source":"clob_market_ws"},"received_at":"2026-07-28T03:05:06.104779Z","record_id":"c738d55a3243042d3e30ccc5ee65988a60f849042bca8a54935eaefe38330a57","schema_fingerprint":"4aa3821a28b0b7c2400bc59aba4bcc0a76e971dadd19610d3ad38c768e124dc7","schema_version":"edge-lab-recorder.raw.v1","sequence":null,"source":"clob_market_ws"}
{"event_at":"2026-07-28T03:05:05.042000Z","event_fingerprint":"3871a8db58091bdd0b8277a6bb7f04cf582ce8edba22cb24e3061b351ba9c0a5","payload":{"connection_id":"a6b55582af5f430fb37ad02bf0922475","event_at":"2026-07-28T03:05:05.042000Z","event_type":"price_change","frame_hash":"e6876ce0a4b25207e0dfcaff472d979b79a1b3e3902150fa8e900fa95cbcda56","frame_index":0,"kind":"data","monotonic_ns":309889139504083,"payload":{"event_type":"price_change","market":"0x779291bef19b6709f61e9764a954aafe9ffae488d50ae674aabdcb4f248006d5","price_changes":[{"asset_id":"8761897749749422724209054078244794145777693856614463256546737399611489089783","best_ask":"0.58","best_bid":"0.57","hash":"b36d47f84b994bb1198992da1055a1ab926295e6","price":"0.01","side":"BUY","size":"5858.02"},{"asset_id":"14965588658799411272385430903075831224615961675357217884735713260981483529984","best_ask":"0.43","best_bid":"0.42","hash":"a66ac00f6a716dc08b7f1ea4292d5b9f7a1f7831","price":"0.99","side":"SELL","size":"5858.02"}],"timestamp":"1785207905042"},"payload_hash":"f1ae591caee70f176ee54ba81447b16c527d71a9116d87d13376626e48e48c68","raw_frame":"{\"market\":\"0x779291bef19b6709f61e9764a954aafe9ffae488d50ae674aabdcb4f248006d5\", \"price_changes\":[{\"asset_id\":\"8761897749749422724209054078244794145777693856614463256546737399611489089783\", \"price\":\"0.01\", \"size\":\"5858.02\", \"side\":\"BUY\", \"hash\":\"b36d47f84b994bb1198992da1055a1ab926295e6\", \"best_bid\":\"0.57\", \"best_ask\":\"0.58\"}, {\"asset_id\":\"14965588658799411272385430903075831224615961675357217884735713260981483529984\", \"price\":\"0.99\", \"size\":\"5858.02\", \"side\":\"SELL\", \"hash\":\"a66ac00f6a716dc08b7f1ea4292d5b9f7a1f7831\", \"best_bid\":\"0.42\", \"best_ask\":\"0.43\"}], \"timestamp\":\"1785207905042\", \"event_type\":\"price_change\"}","received_at":"2026-07-28T03:05:06.109098Z","schema_version":"clob-market-ws.price_change.v1","sequence":null,"server_hash":null,"server_timestamp":"1785207905042","session_id":"3e519d9098404c15b234d96025eb1a2b","source":"clob_market_ws"},"received_at":"2026-07-28T03:05:06.109098Z","record_id":"121ffa83a3499b4140d1d8679b25a1f6e0f4c3cee61e61652de4c646be413c64","schema_fingerprint":"4aa3821a28b0b7c2400bc59aba4bcc0a76e971dadd19610d3ad38c768e124dc7","schema_version":"edge-lab-recorder.raw.v1","sequence":null,"source":"clob_market_ws"}
{"event_at":"2026-07-28T03:05:05.042000Z","event_fingerprint":"b84511d81bfb659cbc0714821f1bd12e38caa31cb6318c2d1d0629bd36c28c9d","payload":{"connection_id":"a6b55582af5f430fb37ad02bf0922475","event_at":"2026-07-28T03:05:05.042000Z","event_type":"price_change","frame_hash":"4dbcd74b990679c6a2cfb6c221338770f7529d9ca4c5eac86bc5cc3632a8a10b","frame_index":0,"kind":"data","monotonic_ns":309889143986500,"payload":{"event_type":"price_change","market":"0x779291bef19b6709f61e9764a954aafe9ffae488d50ae674aabdcb4f248006d5","price_changes":[{"asset_id":"14965588658799411272385430903075831224615961675357217884735713260981483529984","best_ask":"0.43","best_bid":"0.42","hash":"73a6fdae3a1db450790929fa0cf1b03f30ce83a9","price":"0.01","side":"BUY","size":"5883.02"},{"asset_id":"8761897749749422724209054078244794145777693856614463256546737399611489089783","best_ask":"0.58","best_bid":"0.57","hash":"facc3289ada879cbbbcc055ef8e8ea8e33a9025e","price":"0.99","side":"SELL","size":"5883.02"}],"timestamp":"1785207905042"},"payload_hash":"3880f39ffbf4dfd1b7b84665c684809f1da0a8fc2e4fe6b46dabd5517f5fd849","raw_frame":"{\"market\":\"0x779291bef19b6709f61e9764a954aafe9ffae488d50ae674aabdcb4f248006d5\", \"price_changes\":[{\"asset_id\":\"14965588658799411272385430903075831224615961675357217884735713260981483529984\", \"price\":\"0.01\", \"size\":\"5883.02\", \"side\":\"BUY\", \"hash\":\"73a6fdae3a1db450790929fa0cf1b03f30ce83a9\", \"best_bid\":\"0.42\", \"best_ask\":\"0.43\"}, {\"asset_id\":\"8761897749749422724209054078244794145777693856614463256546737399611489089783\", \"price\":\"0.99\", \"size\":\"5883.02\", \"side\":\"SELL\", \"hash\":\"facc3289ada879cbbbcc055ef8e8ea8e33a9025e\", \"best_bid\":\"0.57\", \"best_ask\":\"0.58\"}], \"timestamp\":\"1785207905042\", \"event_type\":\"price_change\"}","received_at":"2026-07-28T03:05:06.113580Z","schema_version":"clob-market-ws.price_change.v1","sequence":null,"server_hash":null,"server_timestamp":"1785207905042","session_id":"3e519d9098404c15b234d96025eb1a2b","source":"clob_market_ws"},"received_at":"2026-07-28T03:05:06.113580Z","record_id":"af3b49ce99264ba8ae621e892734fadca12c2dd287d29a6cb30eeea0c6da85e0","schema_fingerprint":"4aa3821a28b0b7c2400bc59aba4bcc0a76e971dadd19610d3ad38c768e124dc7","schema_version":"edge-lab-recorder.raw.v1","sequence":null,"source":"clob_market_ws"}
{"event_at":"2026-07-28T03:05:05.072000Z","event_fingerprint":"0665f2c643f612f7a79ad0b8932b98034ea04f57ca473aa58cb2a3b25d4af59f","payload":{"connection_id":"a6b55582af5f430fb37ad02bf0922475","event_at":"2026-07-28T03:05:05.072000Z","event_type":"price_change","frame_hash":"58de37aee0c8cc80dae4561c8d1d7795b2e2e052ba1aa84bea7dac50575bbb14","frame_index":0,"kind":"data","monotonic_ns":309889148438750,"payload":{"event_type":"price_change","market":"0x779291bef19b6709f61e9764a954aafe9ffae488d50ae674aabdcb4f248006d5","price_changes":[{"asset_id":"8761897749749422724209054078244794145777693856614463256546737399611489089783","best_ask":"0.58","best_bid":"0.57","hash":"3c7d75aaf4ffdfd6d24f5fd6a2a90cd1a60f49cc","price":"0.01","side":"BUY","size":"5853.02"},{"asset_id":"14965588658799411272385430903075831224615961675357217884735713260981483529984","best_ask":"0.43","best_bid":"0.42","hash":"54070fa5ef2125f9fc6ad4427baf2dee37604edb","price":"0.99","side":"SELL","size":"5853.02"}],"timestamp":"1785207905072"},"payload_hash":"89522415c833639dc238b314a4daf8ef4393950781aa5f0912608d1a4e55a805","raw_frame":"{\"market\":\"0x779291bef19b6709f61e9764a954aafe9ffae488d50ae674aabdcb4f248006d5\", \"price_changes\":[{\"asset_id\":\"8761897749749422724209054078244794145777693856614463256546737399611489089783\", \"price\":\"0.01\", \"size\":\"5853.02\", \"side\":\"BUY\", \"hash\":\"3c7d75aaf4ffdfd6d24f5fd6a2a90cd1a60f49cc\", \"best_bid\":\"0.57\", \"best_ask\":\"0.58\"}, {\"asset_id\":\"14965588658799411272385430903075831224615961675357217884735713260981483529984\", \"price\":\"0.99\", \"size\":\"5853.02\", \"side\":\"SELL\", \"hash\":\"54070fa5ef2125f9fc6ad4427baf2dee37604edb\", \"best_bid\":\"0.42\", \"best_ask\":\"0.43\"}], \"timestamp\":\"1785207905072\", \"event_type\":\"price_change\"}","received_at":"2026-07-28T03:05:06.118033Z","schema_version":"clob-market-ws.price_change.v1","sequence":null,"server_hash":null,"server_timestamp":"1785207905072","session_id":"3e519d9098404c15b234d96025eb1a2b","source":"clob_market_ws"},"received_at":"2026-07-28T03:05:06.118033Z","record_id":"299af01e68a6125453c0a7c54a1044afbe2b744d4dac4df2ad2019c947ab26d3","schema_fingerprint":"4aa3821a28b0b7c2400bc59aba4bcc0a76e971dadd19610d3ad38c768e124dc7","schema_version":"edge-lab-recorder.raw.v1","sequence":null,"source":"clob_market_ws"}
{"event_at":"2026-07-28T03:05:05.077000Z","event_fingerprint":"d3a5ca3b9acdf074b4bd4979376deb63169294675128d29e5ca3c8dfbe7bdfee","payload":{"connection_id":"a6b55582af5f430fb37ad02bf0922475","event_at":"2026-07-28T03:05:05.077000Z","event_type":"price_change","frame_hash":"c4de0c935804efb780bfb2626d18311ac2ae6200d55b288b0487ddbbb487ff84","frame_index":0,"kind":"data","monotonic_ns":309889152817250,"payload":{"event_type":"price_change","market":"0x779291bef19b6709f61e9764a954aafe9ffae488d50ae674aabdcb4f248006d5","price_changes":[{"asset_id":"14965588658799411272385430903075831224615961675357217884735713260981483529984","best_ask":"0.43","best_bid":"0.42","hash":"f482dc373ba710799c1cd156e3d143158faf2673","price":"0.41","side":"BUY","size":"57.8"},{"asset_id":"8761897749749422724209054078244794145777693856614463256546737399611489089783","best_ask":"0.58","best_bid":"0.57","hash":"152f8563c6a01def86f2bb0bd97d023e89e614d6","price":"0.59","side":"SELL","size":"57.8"}],"timestamp":"1785207905077"},"payload_hash":"2f3de22a985f64b32ca12dd880a1c78cc535d06731bbee8dbe81771ebfc0880c","raw_frame":"{\"market\":\"0x779291bef19b6709f61e9764a954aafe9ffae488d50ae674aabdcb4f248006d5\", \"price_changes\":[{\"asset_id\":\"14965588658799411272385430903075831224615961675357217884735713260981483529984\", \"price\":\"0.41\", \"size\":\"57.8\", \"side\":\"BUY\", \"hash\":\"f482dc373ba710799c1cd156e3d143158faf2673\", \"best_bid\":\"0.42\", \"best_ask\":\"0.43\"}, {\"asset_id\":\"8761897749749422724209054078244794145777693856614463256546737399611489089783\", \"price\":\"0.59\", \"size\":\"57.8\", \"side\":\"SELL\", \"hash\":\"152f8563c6a01def86f2bb0bd97d023e89e614d6\", \"best_bid\":\"0.57\", \"best_ask\":\"0.58\"}], \"timestamp\":\"1785207905077\", \"event_type\":\"price_change\"}","received_at":"2026-07-28T03:05:06.122411Z","schema_version":"clob-market-ws.price_change.v1","sequence":null,"server_hash":null,"server_timestamp":"1785207905077","session_id":"3e519d9098404c15b234d96025eb1a2b","source":"clob_market_ws"},"received_at":"2026-07-28T03:05:06.122411Z","record_id":"dcbc168748cd56267ae90d92ed90211c74948d9b13487b135a61cd75b0deb1d9","schema_fingerprint":"4aa3821a28b0b7c2400bc59aba4bcc0a76e971dadd19610d3ad38c768e124dc7","schema_version":"edge-lab-recorder.raw.v1","sequence":null,"source":"clob_market_ws"}
{"event_at":"2026-07-28T03:05:05.083000Z","event_fingerprint":"fca56fde757dca014d774c4b1a1c2ff4a474564ee737af1a237d5adea4199915","payload":{"connection_id":"a6b55582af5f430fb37ad02bf0922475","event_at":"2026-07-28T03:05:05.083000Z","event_type":"price_change","frame_hash":"13e5fb9760364b2469bf4f7150dbde0e2f6d50f61aaa8ce405a7c20d60a1bfd8","frame_index":0,"kind":"data","monotonic_ns":309889155285625,"payload":{"event_type":"price_change","market":"0x779291bef19b6709f61e9764a954aafe9ffae488d50ae674aabdcb4f248006d5","price_changes":[{"asset_id":"8761897749749422724209054078244794145777693856614463256546737399611489089783","best_ask":"0.58","best_bid":"0.57","hash":"c4218be93121a70e98effffde4ff07bfc4c2bd25","price":"0.54","side":"BUY","size":"110.04"},{"asset_id":"14965588658799411272385430903075831224615961675357217884735713260981483529984","best_ask":"0.43","best_bid":"0.42","hash":"150c2d05bb279a84b3422a8df4da4c4dcc8a1df9","price":"0.46","side":"SELL","size":"110.04"}],"timestamp":"1785207905083"},"payload_hash":"6e0e72e7f387108e883da1bb6c60f3dcb71374559d8afa777faa5746b3970747","raw_frame":"{\"market\":\"0x779291bef19b6709f61e9764a954aafe9ffae488d50ae674aabdcb4f248006d5\", \"price_changes\":[{\"asset_id\":\"8761897749749422724209054078244794145777693856614463256546737399611489089783\", \"price\":\"0.54\", \"size\":\"110.04\", \"side\":\"BUY\", \"hash\":\"c4218be93121a70e98effffde4ff07bfc4c2bd25\", \"best_bid\":\"0.57\", \"best_ask\":\"0.58\"}, {\"asset_id\":\"14965588658799411272385430903075831224615961675357217884735713260981483529984\", \"price\":\"0.46\", \"size\":\"110.04\", \"side\":\"SELL\", \"hash\":\"150c2d05bb279a84b3422a8df4da4c4dcc8a1df9\", \"best_bid\":\"0.42\", \"best_ask\":\"0.43\"}], \"timestamp\":\"1785207905083\", \"event_type\":\"price_change\"}","received_at":"2026-07-28T03:05:06.124878Z","schema_version":"clob-market-ws.price_change.v1","sequence":null,"server_hash":null,"server_timestamp":"1785207905083","session_id":"3e519d9098404c15b234d96025eb1a2b","source":"clob_market_ws"},"received_at":"2026-07-28T03:05:06.124878Z","record_id":"6e7c48b5fc59f054b82e72731b7cc724cd6f4150be56502701338e8b4ff51384","schema_fingerprint":"4aa3821a28b0b7c2400bc59aba4bcc0a76e971dadd19610d3ad38c768e124dc7","schema_version":"edge-lab-recorder.raw.v1","sequence":null,"source":"clob_market_ws"}
{"event_at":"2026-07-28T03:05:05.083000Z","event_fingerprint":"ea37ba978e403505082034f0f4f9a99676554875a2c63906a40cc7c4e5d3a973","payload":{"connection_id":"a6b55582af5f430fb37ad02bf0922475","event_at":"2026-07-28T03:05:05.083000Z","event_type":"price_change","frame_hash":"316711ccb962f711a63cc192bb83314ee4de8e7ee2a26e8f51a6cff75332ec4f","frame_index":0,"kind":"data","monotonic_ns":309889159897125,"payload":{"event_type":"price_change","market":"0x779291bef19b6709f61e9764a954aafe9ffae488d50ae674aabdcb4f248006d5","price_changes":[{"asset_id":"8761897749749422724209054078244794145777693856614463256546737399611489089783","best_ask":"0.58","best_bid":"0.57","hash":"9fe1521d1a9baca3041bd5c38350a34b4e6d98c0","price":"0.52","side":"BUY","size":"206"},{"asset_id":"14965588658799411272385430903075831224615961675357217884735713260981483529984","best_ask":"0.43","best_bid":"0.42","hash":"d07ac4d8cae1292a811854222a59516f6494e6ae","price":"0.48","side":"SELL","size":"206"}],"timestamp":"1785207905083"},"payload_hash":"6949649a86743875d6918a7ec9302bb153f7aee450b6835d30b7422f06af0e1d","raw_frame":"{\"market\":\"0x779291bef19b6709f61e9764a954aafe9ffae488d50ae674aabdcb4f248006d5\", \"price_changes\":[{\"asset_id\":\"8761897749749422724209054078244794145777693856614463256546737399611489089783\", \"price\":\"0.52\", \"size\":\"206\", \"side\":\"BUY\", \"hash\":\"9fe1521d1a9baca3041bd5c38350a34b4e6d98c0\", \"best_bid\":\"0.57\", \"best_ask\":\"0.58\"}, {\"asset_id\":\"14965588658799411272385430903075831224615961675357217884735713260981483529984\", \"price\":\"0.48\", \"size\":\"206\", \"side\":\"SELL\", \"hash\":\"d07ac4d8cae1292a811854222a59516f6494e6ae\", \"best_bid\":\"0.42\", \"best_ask\":\"0.43\"}], \"timestamp\":\"1785207905083\", \"event_type\":\"price_change\"}","received_at":"2026-07-28T03:05:06.129491Z","schema_version":"clob-market-ws.price_change.v1","sequence":null,"server_hash":null,"server_timestamp":"1785207905083","session_id":"3e519d9098404c15b234d96025eb1a2b","source":"clob_market_ws"},"received_at":"2026-07-28T03:05:06.129491Z","record_id":"0ed82e9dd4ada7172fa889d54012de8c070daaaedea9859f276a36bf196221e1","schema_fingerprint":"4aa3821a28b0b7c2400bc59aba4bcc0a76e971dadd19610d3ad38c768e124dc7","schema_version":"edge-lab-recorder.raw.v1","sequence":null,"source":"clob_market_ws"}
{"event_at":"2026-07-28T03:05:05.084000Z","event_fingerprint":"4a44af6327df04a86ed42197bab66468dbeaf66c24aa43d94120cb5263a14767","payload":{"connection_id":"a6b55582af5f430fb37ad02bf0922475","event_at":"2026-07-28T03:05:05.084000Z","event_type":"price_change","frame_hash":"d8204fe9885652f194a5c2a376d26564e93d283ba8a9e954b06a0eccd4a87fbf","frame_index":0,"kind":"data","monotonic_ns":309889165785333,"payload":{"event_type":"price_change","market":"0x779291bef19b6709f61e9764a954aafe9ffae488d50ae674aabdcb4f248006d5","price_changes":[{"asset_id":"8761897749749422724209054078244794145777693856614463256546737399611489089783","best_ask":"0.58","best_bid":"0.57","hash":"1d9c3cbd2bc574576fc9897d489800b170632dca","price":"0.53","side":"BUY","size":"206.02"},{"asset_id":"14965588658799411272385430903075831224615961675357217884735713260981483529984","best_ask":"0.43","best_bid":"0.42","hash":"357488794726b0d50e526fe512b15597107906a4","price":"0.47","side":"SELL","size":"206.02"}],"timestamp":"1785207905084"},"payload_hash":"f4855d97e93ee13cf1a1d9da719544df1e62fe7d1b0d6b6084319994b5e34762","raw_frame":"{\"market\":\"0x779291bef19b6709f61e9764a954aafe9ffae488d50ae674aabdcb4f248006d5\", \"price_changes\":[{\"asset_id\":\"8761897749749422724209054078244794145777693856614463256546737399611489089783\", \"price\":\"0.53\", \"size\":\"206.02\", \"side\":\"BUY\", \"hash\":\"1d9c3cbd2bc574576fc9897d489800b170632dca\", \"best_bid\":\"0.57\", \"best_ask\":\"0.58\"}, {\"asset_id\":\"14965588658799411272385430903075831224615961675357217884735713260981483529984\", \"price\":\"0.47\", \"size\":\"206.02\", \"side\":\"SELL\", \"hash\":\"357488794726b0d50e526fe512b15597107906a4\", \"best_bid\":\"0.42\", \"best_ask\":\"0.43\"}], \"timestamp\":\"1785207905084\", \"event_type\":\"price_change\"}","received_at":"2026-07-28T03:05:06.135379Z","schema_version":"clob-market-ws.price_change.v1","sequence":null,"server_hash":null,"server_timestamp":"1785207905084","session_id":"3e519d9098404c15b234d96025eb1a2b","source":"clob_market_ws"},"received_at":"2026-07-28T03:05:06.135379Z","record_id":"a0546c2682d0f9adbb7f920d0b8cf830da3cc20a1af387b763f5c39944d2b053","schema_fingerprint":"4aa3821a28b0b7c2400bc59aba4bcc0a76e971dadd19610d3ad38c768e124dc7","schema_version":"edge-lab-recorder.raw.v1","sequence":null,"source":"clob_market_ws"}
{"event_at":"2026-07-28T03:05:05.086000Z","event_fingerprint":"4a50f5f2750b2e8f10e24ad2dec98a7d8cea02fa2a9c7a2d4e8f217909ed0617","payload":{"connection_id":"a6b55582af5f430fb37ad02bf0922475","event_at":"2026-07-28T03:05:05.086000Z","event_type":"price_change","frame_hash":"e7a0284e362492c6b819a374a16b63a474ba14ce315a6557bdaf754380f503a5","frame_index":0,"kind":"data","monotonic_ns":309889169737250,"payload":{"event_type":"price_change","market":"0x779291bef19b6709f61e9764a954aafe9ffae488d50ae674aabdcb4f248006d5","price_changes":[{"asset_id":"8761897749749422724209054078244794145777693856614463256546737399611489089783","best_ask":"0.58","best_bid":"0.57","hash":"ec2f80c532574b5dd8fb905bf6156c3269f03c76","price":"0.54","side":"BUY","size":"128.04"},{"asset_id":"14965588658799411272385430903075831224615961675357217884735713260981483529984","best_ask":"0.43","best_bid":"0.42","hash":"028750d38916a4e5ca3470be70d8fa0ab7e345f4","price":"0.46","side":"SELL","size":"128.04"}],"timestamp":"1785207905086"},"payload_hash":"264e12420c3383053167aec02672b111389f0584866dd889d7b49f2ffcebd619","raw_frame":"{\"market\":\"0x779291bef19b6709f61e9764a954aafe9ffae488d50ae674aabdcb4f248006d5\", \"price_changes\":[{\"asset_id\":\"8761897749749422724209054078244794145777693856614463256546737399611489089783\", \"price\":\"0.54\", \"size\":\"128.04\", \"side\":\"BUY\", \"hash\":\"ec2f80c532574b5dd8fb905bf6156c3269f03c76\", \"best_bid\":\"0.57\", \"best_ask\":\"0.58\"}, {\"asset_id\":\"14965588658799411272385430903075831224615961675357217884735713260981483529984\", \"price\":\"0.46\", \"size\":\"128.04\", \"side\":\"SELL\", \"hash\":\"028750d38916a4e5ca3470be70d8fa0ab7e345f4\", \"best_bid\":\"0.42\", \"best_ask\":\"0.43\"}], \"timestamp\":\"1785207905086\", \"event_type\":\"price_change\"}","received_at":"2026-07-28T03:05:06.139330Z","schema_version":"clob-market-ws.price_change.v1","sequence":null,"server_hash":null,"server_timestamp":"1785207905086","session_id":"3e519d9098404c15b234d96025eb1a2b","source":"clob_market_ws"},"received_at":"2026-07-28T03:05:06.139330Z","record_id":"a8eeec8a33c090bedb0553b91e0c0e9bfb1eb3f6bd7a9ca7a15a833e19228061","schema_fingerprint":"4aa3821a28b0b7c2400bc59aba4bcc0a76e971dadd19610d3ad38c768e124dc7","schema_version":"edge-lab-recorder.raw.v1","sequence":null,"source":"clob_market_ws"}
{"event_at":"2026-07-28T03:05:05.088000Z","event_fingerprint":"74c09649572dd3691927d8363a0c4f4717c2984444771cf865a375886af93116","payload":{"connection_id":"a6b55582af5f430fb37ad02bf0922475","event_at":"2026-07-28T03:05:05.088000Z","event_type":"price_change","frame_hash":"6f19836b724a5104a846b3a9168ea7f368a49b670ec20a83749e82779b146a7d","frame_index":0,"kind":"data","monotonic_ns":309889174181125,"payload":{"event_type":"price_change","market":"0x779291bef19b6709f61e9764a954aafe9ffae488d50ae674aabdcb4f248006d5","price_changes":[{"asset_id":"8761897749749422724209054078244794145777693856614463256546737399611489089783","best_ask":"0.58","best_bid":"0.57","hash":"733caa6fbb4505c109ba13e8639de43d711dbaf1","price":"0.53","side":"BUY","size":"211.02"},{"asset_id":"14965588658799411272385430903075831224615961675357217884735713260981483529984","best_ask":"0.43","best_bid":"0.42","hash":"a27646e2b6e4b6e5988aeafd2559b7f930144b43","price":"0.47","side":"SELL","size":"211.02"}],"timestamp":"1785207905088"},"payload_hash":"2bc9cb868979da12da1d214028112e913d5f7732aa6675f76e94cdc34f743d60","raw_frame":"{\"market\":\"0x779291bef19b6709f61e9764a954aafe9ffae488d50ae674aabdcb4f248006d5\", \"price_changes\":[{\"asset_id\":\"8761897749749422724209054078244794145777693856614463256546737399611489089783\", \"price\":\"0.53\", \"size\":\"211.02\", \"side\":\"BUY\", \"hash\":\"733caa6fbb4505c109ba13e8639de43d711dbaf1\", \"best_bid\":\"0.57\", \"best_ask\":\"0.58\"}, {\"asset_id\":\"14965588658799411272385430903075831224615961675357217884735713260981483529984\", \"price\":\"0.47\", \"size\":\"211.02\", \"side\":\"SELL\", \"hash\":\"a27646e2b6e4b6e5988aeafd2559b7f930144b43\", \"best_bid\":\"0.42\", \"best_ask\":\"0.43\"}], \"timestamp\":\"1785207905088\", \"event_type\":\"price_change\"}","received_at":"2026-07-28T03:05:06.143774Z","schema_version":"clob-market-ws.price_change.v1","sequence":null,"server_hash":null,"server_timestamp":"1785207905088","session_id":"3e519d9098404c15b234d96025eb1a2b","source":"clob_market_ws"},"received_at":"2026-07-28T03:05:06.143774Z","record_id":"0231da00cc0aa17abd30433564b6fb1c899975f7e00757c731ac1bc889edda66","schema_fingerprint":"4aa3821a28b0b7c2400bc59aba4bcc0a76e971dadd19610d3ad38c768e124dc7","schema_version":"edge-lab-recorder.raw.v1","sequence":null,"source":"clob_market_ws"}
{"event_at":"2026-07-28T03:05:05.098000Z","event_fingerprint":"3c74ff7b26ee9e3053e8e0ef8306b4836737cee080f3f4e145015b4f8d924341","payload":{"connection_id":"a6b55582af5f430fb37ad02bf0922475","event_at":"2026-07-28T03:05:05.098000Z","event_type":"price_change","frame_hash":"70761d1bc35da4a76bb9d8f430dc4567f1c6482acf5499a0ae6b63f8f0415eb4","frame_index":0,"kind":"data","monotonic_ns":309889178611125,"payload":{"event_type":"price_change","market":"0x779291bef19b6709f61e9764a954aafe9ffae488d50ae674aabdcb4f248006d5","price_changes":[{"asset_id":"8761897749749422724209054078244794145777693856614463256546737399611489089783","best_ask":"0.58","best_bid":"0.57","hash":"73a422237054d232918aa2b133db80e283f056d7","price":"0.03","side":"BUY","size":"643.1"},{"asset_id":"14965588658799411272385430903075831224615961675357217884735713260981483529984","best_ask":"0.43","best_bid":"0.42","hash":"f965cf731cc1d7ca69a28313e81a21a22cb95815","price":"0.97","side":"SELL","size":"643.1"}],"timestamp":"1785207905098"},"payload_hash":"d2584acea6c3933497fa1ea79b6f91ea26d5d59909a493057e955d9dc7d8e742","raw_frame":"{\"market\":\"0x779291bef19b6709f61e9764a954aafe9ffae488d50ae674aabdcb4f248006d5\", \"price_changes\":[{\"asset_id\":\"8761897749749422724209054078244794145777693856614463256546737399611489089783\", \"price\":\"0.03\", \"size\":\"643.1\", \"side\":\"BUY\", \"hash\":\"73a422237054d232918aa2b133db80e283f056d7\", \"best_bid\":\"0.57\", \"best_ask\":\"0.58\"}, {\"asset_id\":\"14965588658799411272385430903075831224615961675357217884735713260981483529984\", \"price\":\"0.97\", \"size\":\"643.1\", \"side\":\"SELL\", \"hash\":\"f965cf731cc1d7ca69a28313e81a21a22cb95815\", \"best_bid\":\"0.42\", \"best_ask\":\"0.43\"}], \"timestamp\":\"1785207905098\", \"event_type\":\"price_change\"}","received_at":"2026-07-28T03:05:06.148204Z","schema_version":"clob-market-ws.price_change.v1","sequence":null,"server_hash":null,"server_timestamp":"1785207905098","session_id":"3e519d9098404c15b234d96025eb1a2b","source":"clob_market_ws"},"received_at":"2026-07-28T03:05:06.148204Z","record_id":"14e59339c8bc723e70b3f29b047adb4c2bd190c3a50fd03f6f3c094a6083e898","schema_fingerprint":"4aa3821a28b0b7c2400bc59aba4bcc0a76e971dadd19610d3ad38c768e124dc7","schema_version":"edge-lab-recorder.raw.v1","sequence":null,"source":"clob_market_ws"}
{"event_at":"2026-07-28T03:05:05.106000Z","event_fingerprint":"abe583b6af73fc039ecb7690348dceabfc6d467106939f054c07b98107013c18","payload":{"connection_id":"a6b55582af5f430fb37ad02bf0922475","event_at":"2026-07-28T03:05:05.106000Z","event_type":"price_change","frame_hash":"1cebd6088bda737404a32935fd08f3f4732216dcc1a9577d6739ce5531dfd25e","frame_index":0,"kind":"data","monotonic_ns":309889182829416,"payload":{"event_type":"price_change","market":"0x779291bef19b6709f61e9764a954aafe9ffae488d50ae674aabdcb4f248006d5","price_changes":[{"asset_id":"8761897749749422724209054078244794145777693856614463256546737399611489089783","best_ask":"0.58","best_bid":"0.57","hash":"914ae53957f37c79039d0c9dda2d4318075a2cca","price":"0.55","side":"BUY","size":"103.08"},{"asset_id":"14965588658799411272385430903075831224615961675357217884735713260981483529984","best_ask":"0.43","best_bid":"0.42","hash":"47591355246f77fa6dc7d0c76bfaf2173847d742","price":"0.45","side":"SELL","size":"103.08"}],"timestamp":"1785207905106"},"payload_hash":"6f125e17f346d58690be8efe34568ce08d29a7a874218ea26666fcd0d8e2e8fe","raw_frame":"{\"market\":\"0x779291bef19b6709f61e9764a954aafe9ffae488d50ae674aabdcb4f248006d5\", \"price_changes\":[{\"asset_id\":\"8761897749749422724209054078244794145777693856614463256546737399611489089783\", \"price\":\"0.55\", \"size\":\"103.08\", \"side\":\"BUY\", \"hash\":\"914ae53957f37c79039d0c9dda2d4318075a2cca\", \"best_bid\":\"0.57\", \"best_ask\":\"0.58\"}, {\"asset_id\":\"14965588658799411272385430903075831224615961675357217884735713260981483529984\", \"price\":\"0.45\", \"size\":\"103.08\", \"side\":\"SELL\", \"hash\":\"47591355246f77fa6dc7d0c76bfaf2173847d742\", \"best_bid\":\"0.42\", \"best_ask\":\"0.43\"}], \"timestamp\":\"1785207905106\", \"event_type\":\"price_change\"}","received_at":"2026-07-28T03:05:06.152423Z","schema_version":"clob-market-ws.price_change.v1","sequence":null,"server_hash":null,"server_timestamp":"1785207905106","session_id":"3e519d9098404c15b234d96025eb1a2b","source":"clob_market_ws"},"received_at":"2026-07-28T03:05:06.152423Z","record_id":"954e1852c08b2d9f4c6ba2c6e9d293f170a76971ffdc36554610ebe754e06bab","schema_fingerprint":"4aa3821a28b0b7c2400bc59aba4bcc0a76e971dadd19610d3ad38c768e124dc7","schema_version":"edge-lab-recorder.raw.v1","sequence":null,"source":"clob_market_ws"}
{"event_at":"2026-07-28T03:05:05.108000Z","event_fingerprint":"b4374f1ed87fcd5cca663637e826eb98c0dfa916c222a7966e290dffde340359","payload":{"connection_id":"a6b55582af5f430fb37ad02bf0922475","event_at":"2026-07-28T03:05:05.108000Z","event_type":"price_change","frame_hash":"fcb34da3b21860545e0b39c8a51a41c643d06c8a94645ff29f87bff8f45fee5b","frame_index":0,"kind":"data","monotonic_ns":309889187078375,"payload":{"event_type":"price_change","market":"0x779291bef19b6709f61e9764a954aafe9ffae488d50ae674aabdcb4f248006d5","price_changes":[{"asset_id":"14965588658799411272385430903075831224615961675357217884735713260981483529984","best_ask":"0.43","best_bid":"0.42","hash":"01b90a705769a4155b4a902f4cfa387aebf2dde2","price":"0.4","side":"BUY","size":"86.6"},{"asset_id":"8761897749749422724209054078244794145777693856614463256546737399611489089783","best_ask":"0.58","best_bid":"0.57","hash":"400707452be11bcdfe820b96df624f9d1eb60bca","price":"0.6","side":"SELL","size":"86.6"}],"timestamp":"1785207905108"},"payload_hash":"be7946ee1a7554cecffe2d70c5ced02340bc53b5d150a6d75078896b71848430","raw_frame":"{\"market\":\"0x779291bef19b6709f61e9764a954aafe9ffae488d50ae674aabdcb4f248006d5\", \"price_changes\":[{\"asset_id\":\"14965588658799411272385430903075831224615961675357217884735713260981483529984\", \"price\":\"0.4\", \"size\":\"86.6\", \"side\":\"BUY\", \"hash\":\"01b90a705769a4155b4a902f4cfa387aebf2dde2\", \"best_bid\":\"0.42\", \"best_ask\":\"0.43\"}, {\"asset_id\":\"8761897749749422724209054078244794145777693856614463256546737399611489089783\", \"price\":\"0.6\", \"size\":\"86.6\", \"side\":\"SELL\", \"hash\":\"400707452be11bcdfe820b96df624f9d1eb60bca\", \"best_bid\":\"0.57\", \"best_ask\":\"0.58\"}], \"timestamp\":\"1785207905108\", \"event_type\":\"price_change\"}","received_at":"2026-07-28T03:05:06.156672Z","schema_version":"clob-market-ws.price_change.v1","sequence":null,"server_hash":null,"server_timestamp":"1785207905108","session_id":"3e519d9098404c15b234d96025eb1a2b","source":"clob_market_ws"},"received_at":"2026-07-28T03:05:06.156672Z","record_id":"3cf20a6f3f99fff583e2c8375a91a2932d30c711bb9f302ad5b86eaa1dd5cb50","schema_fingerprint":"4aa3821a28b0b7c2400bc59aba4bcc0a76e971dadd19610d3ad38c768e124dc7","schema_version":"edge-lab-recorder.raw.v1","sequence":null,"source":"clob_market_ws"}
{"event_at":"2026-07-28T03:05:05.155000Z","event_fingerprint":"66904d4f9cb9c80683ea43626ca0a98bd7adfadb9c6634ea8bcf2e8b148af8b0","payload":{"connection_id":"a6b55582af5f430fb37ad02bf0922475","event_at":"2026-07-28T03:05:05.155000Z","event_type":"price_change","frame_hash":"3d1b78e9c1b6254388f23a2cb313ac6f2320f866147fd3b2ce036775155a2ed9","frame_index":0,"kind":"data","monotonic_ns":309889191363041,"payload":{"event_type":"price_change","market":"0x779291bef19b6709f61e9764a954aafe9ffae488d50ae674aabdcb4f248006d5","price_changes":[{"asset_id":"14965588658799411272385430903075831224615961675357217884735713260981483529984","best_ask":"0.43","best_bid":"0.42","hash":"0a2eabb7aae874c054138a4dd3cf28616a460d1c","price":"0.42","side":"BUY","size":"100.2"},{"asset_id":"8761897749749422724209054078244794145777693856614463256546737399611489089783","best_ask":"0.58","best_bid":"0.57","hash":"d5cb614aaece492ae010ac8e34b09392983c2317","price":"0.58","side":"SELL","size":"100.2"}],"timestamp":"1785207905155"},"payload_hash":"7a6f8e5787355977b0d1ecd0949c86fe47a7db95399505209a39c40bae68a12c","raw_frame":"{\"market\":\"0x779291bef19b6709f61e9764a954aafe9ffae488d50ae674aabdcb4f248006d5\", \"price_changes\":[{\"asset_id\":\"14965588658799411272385430903075831224615961675357217884735713260981483529984\", \"price\":\"0.42\", \"size\":\"100.2\", \"side\":\"BUY\", \"hash\":\"0a2eabb7aae874c054138a4dd3cf28616a460d1c\", \"best_bid\":\"0.42\", \"best_ask\":\"0.43\"}, {\"asset_id\":\"8761897749749422724209054078244794145777693856614463256546737399611489089783\", \"price\":\"0.58\", \"size\":\"100.2\", \"side\":\"SELL\", \"hash\":\"d5cb614aaece492ae010ac8e34b09392983c2317\", \"best_bid\":\"0.57\", \"best_ask\":\"0.58\"}], \"timestamp\":\"1785207905155\", \"event_type\":\"price_change\"}","received_at":"2026-07-28T03:05:06.160956Z","schema_version":"clob-market-ws.price_change.v1","sequence":null,"server_hash":null,"server_timestamp":"1785207905155","session_id":"3e519d9098404c15b234d96025eb1a2b","source":"clob_market_ws"},"received_at":"2026-07-28T03:05:06.160956Z","record_id":"9f505db06c931357141d342f5c6dd3674e81bacc05741aaa15f6760ff864d3c7","schema_fingerprint":"4aa3821a28b0b7c2400bc59aba4bcc0a76e971dadd19610d3ad38c768e124dc7","schema_version":"edge-lab-recorder.raw.v1","sequence":null,"source":"clob_market_ws"}
{"event_at":"2026-07-28T03:05:05.156000Z","event_fingerprint":"48e72411876aa49b65ecabfe9a0849cf3c657e8943ce5e8577dd8ac553b7cd2a","payload":{"connection_id":"a6b55582af5f430fb37ad02bf0922475","event_at":"2026-07-28T03:05:05.156000Z","event_type":"price_change","frame_hash":"bfb7514f2b8e04b86bcca1e0db0c555f79ea868bfce1b37bda1e09867e2ab3f9","frame_index":0,"kind":"data","monotonic_ns":309889194190250,"payload":{"event_type":"price_change","market":"0x779291bef19b6709f61e9764a954aafe9ffae488d50ae674aabdcb4f248006d5","price_changes":[{"asset_id":"14965588658799411272385430903075831224615961675357217884735713260981483529984","best_ask":"0.43","best_bid":"0.42","hash":"b7f847b0aad45f3635dd986511b455e3ec7e6e29","price":"0.42","side":"BUY","size":"87.6"},{"asset_id":"8761897749749422724209054078244794145777693856614463256546737399611489089783","best_ask":"0.58","best_bid":"0.57","hash":"7550b6c485dc7b41ba8db095106ab993d94c649f","price":"0.58","side":"SELL","size":"87.6"}],"timestamp":"1785207905156"},"payload_hash":"218dc2b0c3aaee1cf670c0ea173e0f692e1cddb35437c66da0e58d30a33afef0","raw_frame":"{\"market\":\"0x779291bef19b6709f61e9764a954aafe9ffae488d50ae674aabdcb4f248006d5\", \"price_changes\":[{\"asset_id\":\"14965588658799411272385430903075831224615961675357217884735713260981483529984\", \"price\":\"0.42\", \"size\":\"87.6\", \"side\":\"BUY\", \"hash\":\"b7f847b0aad45f3635dd986511b455e3ec7e6e29\", \"best_bid\":\"0.42\", \"best_ask\":\"0.43\"}, {\"asset_id\":\"8761897749749422724209054078244794145777693856614463256546737399611489089783\", \"price\":\"0.58\", \"size\":\"87.6\", \"side\":\"SELL\", \"hash\":\"7550b6c485dc7b41ba8db095106ab993d94c649f\", \"best_bid\":\"0.57\", \"best_ask\":\"0.58\"}], \"timestamp\":\"1785207905156\", \"event_type\":\"price_change\"}","received_at":"2026-07-28T03:05:06.163783Z","schema_version":"clob-market-ws.price_change.v1","sequence":null,"server_hash":null,"server_timestamp":"1785207905156","session_id":"3e519d9098404c15b234d96025eb1a2b","source":"clob_market_ws"},"received_at":"2026-07-28T03:05:06.163783Z","record_id":"8c06009fd0cc0427c90985e42e6b56e76364ac7301b3c92a818a6e96b03f864e","schema_fingerprint":"4aa3821a28b0b7c2400bc59aba4bcc0a76e971dadd19610d3ad38c768e124dc7","schema_version":"edge-lab-recorder.raw.v1","sequence":null,"source":"clob_market_ws"}
{"event_at":"2026-07-28T03:05:05.166000Z","event_fingerprint":"6e12e5ede38a2e7bd3da22bd2b78ced20a9a65ef8f76d8c91866c07c5c1ac0aa","payload":{"connection_id":"a6b55582af5f430fb37ad02bf0922475","event_at":"2026-07-28T03:05:05.166000Z","event_type":"price_change","frame_hash":"b6c3e48040ac8a733aadc3f369895280deaac7849d8baf192579322ce12df1bf","frame_index":0,"kind":"data","monotonic_ns":309889198535541,"payload":{"event_type":"price_change","market":"0x779291bef19b6709f61e9764a954aafe9ffae488d50ae674aabdcb4f248006d5","price_changes":[{"asset_id":"8761897749749422724209054078244794145777693856614463256546737399611489089783","best_ask":"0.58","best_bid":"0.57","hash":"3d46c24a6df242e6e8b1dd3960259b2bad2c0bba","price":"0.45","side":"BUY","size":"188"},{"asset_id":"14965588658799411272385430903075831224615961675357217884735713260981483529984","best_ask":"0.43","best_bid":"0.42","hash":"9715deda2c881fc33766f1d4e1cb360dbb2d1f7a","price":"0.55","side":"SELL","size":"188"}],"timestamp":"1785207905166"},"payload_hash":"bc99d822d3ca50d3247f62ff6520f23d408aa1a305cb04642d5601e3a9155909","raw_frame":"{\"market\":\"0x779291bef19b6709f61e9764a954aafe9ffae488d50ae674aabdcb4f248006d5\", \"price_changes\":[{\"asset_id\":\"8761897749749422724209054078244794145777693856614463256546737399611489089783\", \"price\":\"0.45\", \"size\":\"188\", \"side\":\"BUY\", \"hash\":\"3d46c24a6df242e6e8b1dd3960259b2bad2c0bba\", \"best_bid\":\"0.57\", \"best_ask\":\"0.58\"}, {\"asset_id\":\"14965588658799411272385430903075831224615961675357217884735713260981483529984\", \"price\":\"0.55\", \"size\":\"188\", \"side\":\"SELL\", \"hash\":\"9715deda2c881fc33766f1d4e1cb360dbb2d1f7a\", \"best_bid\":\"0.42\", \"best_ask\":\"0.43\"}], \"timestamp\":\"1785207905166\", \"event_type\":\"price_change\"}","received_at":"2026-07-28T03:05:06.168128Z","schema_version":"clob-market-ws.price_change.v1","sequence":null,"server_hash":null,"server_timestamp":"1785207905166","session_id":"3e519d9098404c15b234d96025eb1a2b","source":"clob_market_ws"},"received_at":"2026-07-28T03:05:06.168128Z","record_id":"ef90f0be12bd5325efa38d4e37eaa905d878b8bc9c8a589ccedc00be31ec3135","schema_fingerprint":"4aa3821a28b0b7c2400bc59aba4bcc0a76e971dadd19610d3ad38c768e124dc7","schema_version":"edge-lab-recorder.raw.v1","sequence":null,"source":"clob_market_ws"}
{"event_at":"2026-07-28T03:05:05.167000Z","event_fingerprint":"77359ea333ca2edf250ea0585b7c15dcc745dce642a7af5090c06e44d61ce3d9","payload":{"connection_id":"a6b55582af5f430fb37ad02bf0922475","event_at":"2026-07-28T03:05:05.167000Z","event_type":"price_change","frame_hash":"7c9f51705697f5a4fc090c8a0dfabde06cf32b20169ce21f918afd756e008f97","frame_index":0,"kind":"data","monotonic_ns":309889202887958,"payload":{"event_type":"price_change","market":"0x779291bef19b6709f61e9764a954aafe9ffae488d50ae674aabdcb4f248006d5","price_changes":[{"asset_id":"8761897749749422724209054078244794145777693856614463256546737399611489089783","best_ask":"0.58","best_bid":"0.57","hash":"477f6599c8f83b4a97bbd9db018a531c34778961","price":"0.55","side":"BUY","size":"118.08"},{"asset_id":"14965588658799411272385430903075831224615961675357217884735713260981483529984","best_ask":"0.43","best_bid":"0.42","hash":"5c42075a1590f8915402be7c58c69d3f65bc91a4","price":"0.45","side":"SELL","size":"118.08"}],"timestamp":"1785207905167"},"payload_hash":"f0fdc91058a50beb71966891891f58ddc9fd7d7780fc8dcec1be456b09f83f58","raw_frame":"{\"market\":\"0x779291bef19b6709f61e9764a954aafe9ffae488d50ae674aabdcb4f248006d5\", \"price_changes\":[{\"asset_id\":\"8761897749749422724209054078244794145777693856614463256546737399611489089783\", \"price\":\"0.55\", \"size\":\"118.08\", \"side\":\"BUY\", \"hash\":\"477f6599c8f83b4a97bbd9db018a531c34778961\", \"best_bid\":\"0.57\", \"best_ask\":\"0.58\"}, {\"asset_id\":\"14965588658799411272385430903075831224615961675357217884735713260981483529984\", \"price\":\"0.45\", \"size\":\"118.08\", \"side\":\"SELL\", \"hash\":\"5c42075a1590f8915402be7c58c69d3f65bc91a4\", \"best_bid\":\"0.42\", \"best_ask\":\"0.43\"}], \"timestamp\":\"1785207905167\", \"event_type\":\"price_change\"}","received_at":"2026-07-28T03:05:06.172478Z","schema_version":"clob-market-ws.price_change.v1","sequence":null,"server_hash":null,"server_timestamp":"1785207905167","session_id":"3e519d9098404c15b234d96025eb1a2b","source":"clob_market_ws"},"received_at":"2026-07-28T03:05:06.172478Z","record_id":"e8bfe1922ff1d3b720d28914b794f5a5dd890858e737a5a1f33fe6349e126d4a","schema_fingerprint":"4aa3821a28b0b7c2400bc59aba4bcc0a76e971dadd19610d3ad38c768e124dc7","schema_version":"edge-lab-recorder.raw.v1","sequence":null,"source":"clob_market_ws"}
{"event_at":"2026-07-28T03:05:05.180000Z","event_fingerprint":"c866304f2d7b1ae7038cdcb5d6d43ed0e7e6231a83c75c7a9e4fce07881c17a2","payload":{"connection_id":"a6b55582af5f430fb37ad02bf0922475","event_at":"2026-07-28T03:05:05.180000Z","event_type":"price_change","frame_hash":"fe64592363ae6dcd93c1a4279676107b70ec132123db3a62af8e3f3a2a010a37","frame_index":0,"kind":"data","monotonic_ns":309889207867958,"payload":{"event_type":"price_change","market":"0x779291bef19b6709f61e9764a954aafe9ffae488d50ae674aabdcb4f248006d5","price_changes":[{"asset_id":"8761897749749422724209054078244794145777693856614463256546737399611489089783","best_ask":"0.58","best_bid":"0.57","hash":"7dc2ac4297517d8449b194f2278fa1cc5d80da5a","price":"0.02","side":"BUY","size":"688.1"},{"asset_id":"14965588658799411272385430903075831224615961675357217884735713260981483529984","best_ask":"0.43","best_bid":"0.42","hash":"9c0ac97965ff89b057a1b847a6005a9752dd133a","price":"0.98","side":"SELL","size":"688.1"}],"timestamp":"1785207905180"},"payload_hash":"fce24956ab7fa24426bd2292f8ca7c0b3d4f394da193953dc767972b17f4f385","raw_frame":"{\"market\":\"0x779291bef19b6709f61e9764a954aafe9ffae488d50ae674aabdcb4f248006d5\", \"price_changes\":[{\"asset_id\":\"8761897749749422724209054078244794145777693856614463256546737399611489089783\", \"price\":\"0.02\", \"size\":\"688.1\", \"side\":\"BUY\", \"hash\":\"7dc2ac4297517d8449b194f2278fa1cc5d80da5a\", \"best_bid\":\"0.57\", \"best_ask\":\"0.58\"}, {\"asset_id\":\"14965588658799411272385430903075831224615961675357217884735713260981483529984\", \"price\":\"0.98\", \"size\":\"688.1\", \"side\":\"SELL\", \"hash\":\"9c0ac97965ff89b057a1b847a6005a9752dd133a\", \"best_bid\":\"0.42\", \"best_ask\":\"0.43\"}], \"timestamp\":\"1785207905180\", \"event_type\":\"price_change\"}","received_at":"2026-07-28T03:05:06.177461Z","schema_version":"clob-market-ws.price_change.v1","sequence":null,"server_hash":null,"server_timestamp":"1785207905180","session_id":"3e519d9098404c15b234d96025eb1a2b","source":"clob_market_ws"},"received_at":"2026-07-28T03:05:06.177461Z","record_id":"eba88758faa1c01a3a9f5b6e217983d6d44d3c9f92498c203c448ca0d02c5fee","schema_fingerprint":"4aa3821a28b0b7c2400bc59aba4bcc0a76e971dadd19610d3ad38c768e124dc7","schema_version":"edge-lab-recorder.raw.v1","sequence":null,"source":"clob_market_ws"}
{"event_at":"2026-07-28T03:05:05.184000Z","event_fingerprint":"59870d07400d57bcade67e4789e41f58627f1fbb502746e2203cda5e8b8e31af","payload":{"connection_id":"a6b55582af5f430fb37ad02bf0922475","event_at":"2026-07-28T03:05:05.184000Z","event_type":"price_change","frame_hash":"37f68d21f476d11c321518ffa11e9b1807cf615fa89696921a372975ecadae7d","frame_index":0,"kind":"data","monotonic_ns":309889212100958,"payload":{"event_type":"price_change","market":"0x779291bef19b6709f61e9764a954aafe9ffae488d50ae674aabdcb4f248006d5","price_changes":[{"asset_id":"14965588658799411272385430903075831224615961675357217884735713260981483529984","best_ask":"0.43","best_bid":"0.42","hash":"d117ef4adb0b0437894c1d3925f84fc6a446608a","price":"0.42","side":"BUY","size":"62.6"},{"asset_id":"8761897749749422724209054078244794145777693856614463256546737399611489089783","best_ask":"0.58","best_bid":"0.57","hash":"63348faa485553f6ca8138a7f3c1e55e54e0e8db","price":"0.58","side":"SELL","size":"62.6"}],"timestamp":"1785207905184"},"payload_hash":"2489554fb879e7a39a3b249110229bb10e25db59b106fdde2fd0559ab732d72d","raw_frame":"{\"market\":\"0x779291bef19b6709f61e9764a954aafe9ffae488d50ae674aabdcb4f248006d5\", \"price_changes\":[{\"asset_id\":\"14965588658799411272385430903075831224615961675357217884735713260981483529984\", \"price\":\"0.42\", \"size\":\"62.6\", \"side\":\"BUY\", \"hash\":\"d117ef4adb0b0437894c1d3925f84fc6a446608a\", \"best_bid\":\"0.42\", \"best_ask\":\"0.43\"}, {\"asset_id\":\"8761897749749422724209054078244794145777693856614463256546737399611489089783\", \"price\":\"0.58\", \"size\":\"62.6\", \"side\":\"SELL\", \"hash\":\"63348faa485553f6ca8138a7f3c1e55e54e0e8db\", \"best_bid\":\"0.57\", \"best_ask\":\"0.58\"}], \"timestamp\":\"1785207905184\", \"event_type\":\"price_change\"}","received_at":"2026-07-28T03:05:06.181693Z","schema_version":"clob-market-ws.price_change.v1","sequence":null,"server_hash":null,"server_timestamp":"1785207905184","session_id":"3e519d9098404c15b234d96025eb1a2b","source":"clob_market_ws"},"received_at":"2026-07-28T03:05:06.181693Z","record_id":"44d9baceff1d28a7b6874fe948a457fb88632973cc911bd476946978aa23de1d","schema_fingerprint":"4aa3821a28b0b7c2400bc59aba4bcc0a76e971dadd19610d3ad38c768e124dc7","schema_version":"edge-lab-recorder.raw.v1","sequence":null,"source":"clob_market_ws"}
{"event_at":"2026-07-28T03:05:05.189000Z","event_fingerprint":"9bedfed691110ced0995176fb0dac6d0e1e2b6ef1059d11f53ace79661258c04","payload":{"connection_id":"a6b55582af5f430fb37ad02bf0922475","event_at":"2026-07-28T03:05:05.189000Z","event_type":"price_change","frame_hash":"97dcd165685ef30ad42ccd471c634490e3df11d675924d0022402519f61813f9","frame_index":0,"kind":"data","monotonic_ns":309889216337208,"payload":{"event_type":"price_change","market":"0x779291bef19b6709f61e9764a954aafe9ffae488d50ae674aabdcb4f248006d5","price_changes":[{"asset_id":"8761897749749422724209054078244794145777693856614463256546737399611489089783","best_ask":"0.58","best_bid":"0.57","hash":"328b625e59ed00405e2a7d74a65cfe30d64c40b3","price":"0.52","side":"BUY","size":"211"},{"asset_id":"14965588658799411272385430903075831224615961675357217884735713260981483529984","best_ask":"0.43","best_bid":"0.42","hash":"b69a7a8f59b865619ed67edfec0e01fe5973411e","price":"0.48","side":"SELL","size":"211"}],"timestamp":"1785207905189"},"payload_hash":"bc60f665b48bbf7958693c6a5825d465bfec13fd6d6f310c46ea6fb1257d7d61","raw_frame":"{\"market\":\"0x779291bef19b6709f61e9764a954aafe9ffae488d50ae674aabdcb4f248006d5\", \"price_changes\":[{\"asset_id\":\"8761897749749422724209054078244794145777693856614463256546737399611489089783\", \"price\":\"0.52\", \"size\":\"211\", \"side\":\"BUY\", \"hash\":\"328b625e59ed00405e2a7d74a65cfe30d64c40b3\", \"best_bid\":\"0.57\", \"best_ask\":\"0.58\"}, {\"asset_id\":\"14965588658799411272385430903075831224615961675357217884735713260981483529984\", \"price\":\"0.48\", \"size\":\"211\", \"side\":\"SELL\", \"hash\":\"b69a7a8f59b865619ed67edfec0e01fe5973411e\", \"best_bid\":\"0.42\", \"best_ask\":\"0.43\"}], \"timestamp\":\"1785207905189\", \"event_type\":\"price_change\"}","received_at":"2026-07-28T03:05:06.185930Z","schema_version":"clob-market-ws.price_change.v1","sequence":null,"server_hash":null,"server_timestamp":"1785207905189","session_id":"3e519d9098404c15b234d96025eb1a2b","source":"clob_market_ws"},"received_at":"2026-07-28T03:05:06.185930Z","record_id":"f9df990b18df9d05e9ae4602c10eaf882bc9ea23cafc80d50fd6b3cb0762e994","schema_fingerprint":"4aa3821a28b0b7c2400bc59aba4bcc0a76e971dadd19610d3ad38c768e124dc7","schema_version":"edge-lab-recorder.raw.v1","sequence":null,"source":"clob_market_ws"}
{"event_at":"2026-07-28T03:05:05.205000Z","event_fingerprint":"5f46e647177c3c0796bf79bfd4ff9fcc8720013fd46b8a57b8023b290c4938a4","payload":{"connection_id":"a6b55582af5f430fb37ad02bf0922475","event_at":"2026-07-28T03:05:05.205000Z","event_type":"price_change","frame_hash":"8e8bec0c44c3a799b7602cc3e241c8062849d24d3dd02743eb938d4ea80c9cf6","frame_index":0,"kind":"data","monotonic_ns":309889221440833,"payload":{"event_type":"price_change","market":"0x779291bef19b6709f61e9764a954aafe9ffae488d50ae674aabdcb4f248006d5","price_changes":[{"asset_id":"8761897749749422724209054078244794145777693856614463256546737399611489089783","best_ask":"0.58","best_bid":"0.57","hash":"82dd1a19f526ffbb14a8076dae14b7122e93ade6","price":"0.58","side":"SELL","size":"37.6"},{"asset_id":"14965588658799411272385430903075831224615961675357217884735713260981483529984","best_ask":"0.43","best_bid":"0.42","hash":"1f452c382bd31725b3477085b0c03b486c888319","price":"0.42","side":"BUY","size":"37.6"}],"timestamp":"1785207905205"},"payload_hash":"14e5f166a7cd668cab51ce0208995339f7dab90d49bdbdb095871d8c4a324bf8","raw_frame":"{\"market\":\"0x779291bef19b6709f61e9764a954aafe9ffae488d50ae674aabdcb4f248006d5\", \"price_changes\":[{\"asset_id\":\"8761897749749422724209054078244794145777693856614463256546737399611489089783\", \"price\":\"0.58\", \"size\":\"37.6\", \"side\":\"SELL\", \"hash\":\"82dd1a19f526ffbb14a8076dae14b7122e93ade6\", \"best_bid\":\"0.57\", \"best_ask\":\"0.58\"}, {\"asset_id\":\"14965588658799411272385430903075831224615961675357217884735713260981483529984\", \"price\":\"0.42\", \"size\":\"37.6\", \"side\":\"BUY\", \"hash\":\"1f452c382bd31725b3477085b0c03b486c888319\", \"best_bid\":\"0.42\", \"best_ask\":\"0.43\"}], \"timestamp\":\"1785207905205\", \"event_type\":\"price_change\"}","received_at":"2026-07-28T03:05:06.191033Z","schema_version":"clob-market-ws.price_change.v1","sequence":null,"server_hash":null,"server_timestamp":"1785207905205","session_id":"3e519d9098404c15b234d96025eb1a2b","source":"clob_market_ws"},"received_at":"2026-07-28T03:05:06.191033Z","record_id":"bff4f41e422ac7f4f311c91814c18fe3bb30cebcdf4542c32e19702ba42a2727","schema_fingerprint":"4aa3821a28b0b7c2400bc59aba4bcc0a76e971dadd19610d3ad38c768e124dc7","schema_version":"edge-lab-recorder.raw.v1","sequence":null,"source":"clob_market_ws"}
{"event_at":"2026-07-28T03:05:05.206000Z","event_fingerprint":"ae87cf282409e4eb7877c92a688220728aa88d9db2307805d6fe99faad0b8f04","payload":{"connection_id":"a6b55582af5f430fb37ad02bf0922475","event_at":"2026-07-28T03:05:05.206000Z","event_type":"price_change","frame_hash":"ecae395ecee96de6e7711e7d1677c2bd3b42dec959ee426bd472e80947570f69","frame_index":0,"kind":"data","monotonic_ns":309889225759375,"payload":{"event_type":"price_change","market":"0x779291bef19b6709f61e9764a954aafe9ffae488d50ae674aabdcb4f248006d5","price_changes":[{"asset_id":"14965588658799411272385430903075831224615961675357217884735713260981483529984","best_ask":"0.43","best_bid":"0.42","hash":"e78ca65b541702a6bfdb8fc967a407ee41dd78c3","price":"0.41","side":"BUY","size":"52"},{"asset_id":"8761897749749422724209054078244794145777693856614463256546737399611489089783","best_ask":"0.58","best_bid":"0.57","hash":"cdd1d1049c28873a3540f075c855fd53cb17a71a","price":"0.59","side":"SELL","size":"52"}],"timestamp":"1785207905206"},"payload_hash":"5a9c2011741fdb66d904efe968e93e74bb0e9c2c7cdd6fc4f258c1ac8aecd8a4","raw_frame":"{\"market\":\"0x779291bef19b6709f61e9764a954aafe9ffae488d50ae674aabdcb4f248006d5\", \"price_changes\":[{\"asset_id\":\"14965588658799411272385430903075831224615961675357217884735713260981483529984\", \"price\":\"0.41\", \"size\":\"52\", \"side\":\"BUY\", \"hash\":\"e78ca65b541702a6bfdb8fc967a407ee41dd78c3\", \"best_bid\":\"0.42\", \"best_ask\":\"0.43\"}, {\"asset_id\":\"8761897749749422724209054078244794145777693856614463256546737399611489089783\", \"price\":\"0.59\", \"size\":\"52\", \"side\":\"SELL\", \"hash\":\"cdd1d1049c28873a3540f075c855fd53cb17a71a\", \"best_bid\":\"0.57\", \"best_ask\":\"0.58\"}], \"timestamp\":\"1785207905206\", \"event_type\":\"price_change\"}","received_at":"2026-07-28T03:05:06.195351Z","schema_version":"clob-market-ws.price_change.v1","sequence":null,"server_hash":null,"server_timestamp":"1785207905206","session_id":"3e519d9098404c15b234d96025eb1a2b","source":"clob_market_ws"},"received_at":"2026-07-28T03:05:06.195351Z","record_id":"099b56c958fcd7e08ec1a5f779ea92e2402aa353b3c40ec3b3817e6e9e1bae50","schema_fingerprint":"4aa3821a28b0b7c2400bc59aba4bcc0a76e971dadd19610d3ad38c768e124dc7","schema_version":"edge-lab-recorder.raw.v1","sequence":null,"source":"clob_market_ws"}
{"event_at":"2026-07-28T03:05:05.206000Z","event_fingerprint":"6b53a377e2093d7392addf28f6920674a78e5e81e6e05eacccc30a78d14bdedb","payload":{"connection_id":"a6b55582af5f430fb37ad02bf0922475","event_at":"2026-07-28T03:05:05.206000Z","event_type":"price_change","frame_hash":"59c83130832f498739b81c42268235b406347fdd66e65f19a0f5207e391b9eb2","frame_index":0,"kind":"data","monotonic_ns":309889230222041,"payload":{"event_type":"price_change","market":"0x779291bef19b6709f61e9764a954aafe9ffae488d50ae674aabdcb4f248006d5","price_changes":[{"asset_id":"14965588658799411272385430903075831224615961675357217884735713260981483529984","best_ask":"0.43","best_bid":"0.42","hash":"e78ca65b541702a6bfdb8fc967a407ee41dd78c3","price":"0.42","side":"BUY","size":"31.8"},{"asset_id":"8761897749749422724209054078244794145777693856614463256546737399611489089783","best_ask":"0.58","best_bid":"0.57","hash":"cdd1d1049c28873a3540f075c855fd53cb17a71a","price":"0.58","side":"SELL","size":"31.8"}],"timestamp":"1785207905206"},"payload_hash":"32561112d234f70e053a438febaeebbf6c8207e2e43b035afdbe173cc359c0a8","raw_frame":"{\"market\":\"0x779291bef19b6709f61e9764a954aafe9ffae488d50ae674aabdcb4f248006d5\", \"price_changes\":[{\"asset_id\":\"14965588658799411272385430903075831224615961675357217884735713260981483529984\", \"price\":\"0.42\", \"size\":\"31.8\", \"side\":\"BUY\", \"hash\":\"e78ca65b541702a6bfdb8fc967a407ee41dd78c3\", \"best_bid\":\"0.42\", \"best_ask\":\"0.43\"}, {\"asset_id\":\"8761897749749422724209054078244794145777693856614463256546737399611489089783\", \"price\":\"0.58\", \"size\":\"31.8\", \"side\":\"SELL\", \"hash\":\"cdd1d1049c28873a3540f075c855fd53cb17a71a\", \"best_bid\":\"0.57\", \"best_ask\":\"0.58\"}], \"timestamp\":\"1785207905206\", \"event_type\":\"price_change\"}","received_at":"2026-07-28T03:05:06.199813Z","schema_version":"clob-market-ws.price_change.v1","sequence":null,"server_hash":null,"server_timestamp":"1785207905206","session_id":"3e519d9098404c15b234d96025eb1a2b","source":"clob_market_ws"},"received_at":"2026-07-28T03:05:06.199813Z","record_id":"3845f9e6b58f934cde7ea170c57bb21df6147fd825d6752a5157062cbdf78b42","schema_fingerprint":"4aa3821a28b0b7c2400bc59aba4bcc0a76e971dadd19610d3ad38c768e124dc7","schema_version":"edge-lab-recorder.raw.v1","sequence":null,"source":"clob_market_ws"}
{"event_at":"2026-07-28T03:05:05.206000Z","event_fingerprint":"e0aab84a8e164474ee77ba96963ad095ac874d943a73e2de07aca5503994eaf0","payload":{"connection_id":"a6b55582af5f430fb37ad02bf0922475","event_at":"2026-07-28T03:05:05.206000Z","event_type":"price_change","frame_hash":"b37c8d221baedf08e91a7530f539209825b4e717d3086ac1d558662eeb9c1be7","frame_index":0,"kind":"data","monotonic_ns":309889234524583,"payload":{"event_type":"price_change","market":"0x779291bef19b6709f61e9764a954aafe9ffae488d50ae674aabdcb4f248006d5","price_changes":[{"asset_id":"14965588658799411272385430903075831224615961675357217884735713260981483529984","best_ask":"0.43","best_bid":"0.42","hash":"d9dec976ac1494e5b77ad43196ec99c56c4cc1e7","price":"0.41","side":"BUY","size":"77"},{"asset_id":"8761897749749422724209054078244794145777693856614463256546737399611489089783","best_ask":"0.58","best_bid":"0.57","hash":"8fe507874845266bd3bee5fe0ae97c4cea365b02","price":"0.59","side":"SELL","size":"77"}],"timestamp":"1785207905206"},"payload_hash":"86236f1b5c58d858d31c6d144a115a5678939408765c26885841d906a64d2c29","raw_frame":"{\"market\":\"0x779291bef19b6709f61e9764a954aafe9ffae488d50ae674aabdcb4f248006d5\", \"price_changes\":[{\"asset_id\":\"14965588658799411272385430903075831224615961675357217884735713260981483529984\", \"price\":\"0.41\", \"size\":\"77\", \"side\":\"BUY\", \"hash\":\"d9dec976ac1494e5b77ad43196ec99c56c4cc1e7\", \"best_bid\":\"0.42\", \"best_ask\":\"0.43\"}, {\"asset_id\":\"8761897749749422724209054078244794145777693856614463256546737399611489089783\", \"price\":\"0.59\", \"size\":\"77\", \"side\":\"SELL\", \"hash\":\"8fe507874845266bd3bee5fe0ae97c4cea365b02\", \"best_bid\":\"0.57\", \"best_ask\":\"0.58\"}], \"timestamp\":\"1785207905206\", \"event_type\":\"price_change\"}","received_at":"2026-07-28T03:05:06.204115Z","schema_version":"clob-market-ws.price_change.v1","sequence":null,"server_hash":null,"server_timestamp":"1785207905206","session_id":"3e519d9098404c15b234d96025eb1a2b","source":"clob_market_ws"},"received_at":"2026-07-28T03:05:06.204115Z","record_id":"0e048b147b3a66412783d6f66baa66be4a5148276021a969a014b046ed116520","schema_fingerprint":"4aa3821a28b0b7c2400bc59aba4bcc0a76e971dadd19610d3ad38c768e124dc7","schema_version":"edge-lab-recorder.raw.v1","sequence":null,"source":"clob_market_ws"}
{"event_at":"2026-07-28T03:05:05.210000Z","event_fingerprint":"2f3dd5ed820e2f00b0d7c493889d93061693eb65995ea8b377bed0d5bd5257e7","payload":{"connection_id":"a6b55582af5f430fb37ad02bf0922475","event_at":"2026-07-28T03:05:05.210000Z","event_type":"price_change","frame_hash":"bba28282d7ec41e9ae0797b7abe29b80e5ee48ddbdd8f1981d623fdf20cd0f29","frame_index":0,"kind":"data","monotonic_ns":309889238811500,"payload":{"event_type":"price_change","market":"0x779291bef19b6709f61e9764a954aafe9ffae488d50ae674aabdcb4f248006d5","price_changes":[{"asset_id":"14965588658799411272385430903075831224615961675357217884735713260981483529984","best_ask":"0.43","best_bid":"0.42","hash":"1fcf033fd2057813259d206f31c49affade938e9","price":"0.42","side":"BUY","size":"26.8"},{"asset_id":"8761897749749422724209054078244794145777693856614463256546737399611489089783","best_ask":"0.58","best_bid":"0.57","hash":"5ae809a76741c03d3cd1e7d66a7fd138d2678163","price":"0.58","side":"SELL","size":"26.8"}],"timestamp":"1785207905210"},"payload_hash":"22a73b23295a2cc66cd2d8d1e3a8f2bfbd4316b3c8ac3a510c38f0c4c54313b1","raw_frame":"{\"market\":\"0x779291bef19b6709f61e9764a954aafe9ffae488d50ae674aabdcb4f248006d5\", \"price_changes\":[{\"asset_id\":\"14965588658799411272385430903075831224615961675357217884735713260981483529984\", \"price\":\"0.42\", \"size\":\"26.8\", \"side\":\"BUY\", \"hash\":\"1fcf033fd2057813259d206f31c49affade938e9\", \"best_bid\":\"0.42\", \"best_ask\":\"0.43\"}, {\"asset_id\":\"8761897749749422724209054078244794145777693856614463256546737399611489089783\", \"price\":\"0.58\", \"size\":\"26.8\", \"side\":\"SELL\", \"hash\":\"5ae809a76741c03d3cd1e7d66a7fd138d2678163\", \"best_bid\":\"0.57\", \"best_ask\":\"0.58\"}], \"timestamp\":\"1785207905210\", \"event_type\":\"price_change\"}","received_at":"2026-07-28T03:05:06.208403Z","schema_version":"clob-market-ws.price_change.v1","sequence":null,"server_hash":null,"server_timestamp":"1785207905210","session_id":"3e519d9098404c15b234d96025eb1a2b","source":"clob_market_ws"},"received_at":"2026-07-28T03:05:06.208403Z","record_id":"7ccbe448b0d6fda45193269a8a20ea8afc76d0a641247c9490b0b5cf2520d570","schema_fingerprint":"4aa3821a28b0b7c2400bc59aba4bcc0a76e971dadd19610d3ad38c768e124dc7","schema_version":"edge-lab-recorder.raw.v1","sequence":null,"source":"clob_market_ws"}
{"event_at":"2026-07-28T03:05:05.227000Z","event_fingerprint":"ba88c76b1611566d988d579bb5f87d94b09ebcdf36877043f785fcd091d66892","payload":{"connection_id":"a6b55582af5f430fb37ad02bf0922475","event_at":"2026-07-28T03:05:05.227000Z","event_type":"price_change","frame_hash":"997deb02983badd7ddd6bd236dddc185a4ff04d24bdefa0da6c16c35ae06b07b","frame_index":0,"kind":"data","monotonic_ns":309889243058916,"payload":{"event_type":"price_change","market":"0x779291bef19b6709f61e9764a954aafe9ffae488d50ae674aabdcb4f248006d5","price_changes":[{"asset_id":"8761897749749422724209054078244794145777693856614463256546737399611489089783","best_ask":"0.58","best_bid":"0.57","hash":"b3282abf106511b54f64e0915e2f7b60ff71b7c2","price":"0.59","side":"SELL","size":"102"},{"asset_id":"14965588658799411272385430903075831224615961675357217884735713260981483529984","best_ask":"0.43","best_bid":"0.42","hash":"d8cc69a3dacff8854b53e0e992c393e71e8bd3dd","price":"0.41","side":"BUY","size":"102"}],"timestamp":"1785207905227"},"payload_hash":"c7b6ed976905b9b32ebb7aa801c06569da6c9b46387a2f06ca6aeb5da46525cd","raw_frame":"{\"market\":\"0x779291bef19b6709f61e9764a954aafe9ffae488d50ae674aabdcb4f248006d5\", \"price_changes\":[{\"asset_id\":\"8761897749749422724209054078244794145777693856614463256546737399611489089783\", \"price\":\"0.59\", \"size\":\"102\", \"side\":\"SELL\", \"hash\":\"b3282abf106511b54f64e0915e2f7b60ff71b7c2\", \"best_bid\":\"0.57\", \"best_ask\":\"0.58\"}, {\"asset_id\":\"14965588658799411272385430903075831224615961675357217884735713260981483529984\", \"price\":\"0.41\", \"size\":\"102\", \"side\":\"BUY\", \"hash\":\"d8cc69a3dacff8854b53e0e992c393e71e8bd3dd\", \"best_bid\":\"0.42\", \"best_ask\":\"0.43\"}], \"timestamp\":\"1785207905227\", \"event_type\":\"price_change\"}","received_at":"2026-07-28T03:05:06.212650Z","schema_version":"clob-market-ws.price_change.v1","sequence":null,"server_hash":null,"server_timestamp":"1785207905227","session_id":"3e519d9098404c15b234d96025eb1a2b","source":"clob_market_ws"},"received_at":"2026-07-28T03:05:06.212650Z","record_id":"040d2fd4f326e20cb18751e981175ae6f210dcd7ebbb387a866df50a68dcf241","schema_fingerprint":"4aa3821a28b0b7c2400bc59aba4bcc0a76e971dadd19610d3ad38c768e124dc7","schema_version":"edge-lab-recorder.raw.v1","sequence":null,"source":"clob_market_ws"}
{"event_at":"2026-07-28T03:05:05.231000Z","event_fingerprint":"29fdb36e496e46d2035d91bed5ae0931710ad4a2cbaed30bb91ffed6bc9e12e7","payload":{"connection_id":"a6b55582af5f430fb37ad02bf0922475","event_at":"2026-07-28T03:05:05.231000Z","event_type":"price_change","frame_hash":"42ea16b03a865b7f45332167e346abb49446ffba4acb148e21bedba8359276d9","frame_index":0,"kind":"data","monotonic_ns":309889247520083,"payload":{"event_type":"price_change","market":"0x779291bef19b6709f61e9764a954aafe9ffae488d50ae674aabdcb4f248006d5","price_changes":[{"asset_id":"14965588658799411272385430903075831224615961675357217884735713260981483529984","best_ask":"0.43","best_bid":"0.42","hash":"30155bea7a5b09e9f1a62c2f385965200c17b15c","price":"0.27","side":"BUY","size":"265.2"},{"asset_id":"8761897749749422724209054078244794145777693856614463256546737399611489089783","best_ask":"0.58","best_bid":"0.57","hash":"247bd1a7616c53c679d50224b3e5b1ade53674fa","price":"0.73","side":"SELL","size":"265.2"}],"timestamp":"1785207905231"},"payload_hash":"f60f15f2031c3dde3e5d1e8305e60d3dee95e09faf3bb95d52d3c09019205149","raw_frame":"{\"market\":\"0x779291bef19b6709f61e9764a954aafe9ffae488d50ae674aabdcb4f248006d5\", \"price_changes\":[{\"asset_id\":\"14965588658799411272385430903075831224615961675357217884735713260981483529984\", \"price\":\"0.27\", \"size\":\"265.2\", \"side\":\"BUY\", \"hash\":\"30155bea7a5b09e9f1a62c2f385965200c17b15c\", \"best_bid\":\"0.42\", \"best_ask\":\"0.43\"}, {\"asset_id\":\"8761897749749422724209054078244794145777693856614463256546737399611489089783\", \"price\":\"0.73\", \"size\":\"265.2\", \"side\":\"SELL\", \"hash\":\"247bd1a7616c53c679d50224b3e5b1ade53674fa\", \"best_bid\":\"0.57\", \"best_ask\":\"0.58\"}], \"timestamp\":\"1785207905231\", \"event_type\":\"price_change\"}","received_at":"2026-07-28T03:05:06.217111Z","schema_version":"clob-market-ws.price_change.v1","sequence":null,"server_hash":null,"server_timestamp":"1785207905231","session_id":"3e519d9098404c15b234d96025eb1a2b","source":"clob_market_ws"},"received_at":"2026-07-28T03:05:06.217111Z","record_id":"6d93fe8f938e96b2f4f5b30a0ecd359332458ad5b539b7f2612ea97932db6a1e","schema_fingerprint":"4aa3821a28b0b7c2400bc59aba4bcc0a76e971dadd19610d3ad38c768e124dc7","schema_version":"edge-lab-recorder.raw.v1","sequence":null,"source":"clob_market_ws"}
{"event_at":"2026-07-28T03:05:05.233000Z","event_fingerprint":"7939140ce4e8bcdc0f195636c0f5051158b0197b28782f4b49120ad4db4cf17d","payload":{"connection_id":"a6b55582af5f430fb37ad02bf0922475","event_at":"2026-07-28T03:05:05.233000Z","event_type":"price_change","frame_hash":"62fa09d95bfb74fd3561f51abeddb010e28ed5261a00397b52f82af02669cd98","frame_index":0,"kind":"data","monotonic_ns":309889251717416,"payload":{"event_type":"price_change","market":"0x779291bef19b6709f61e9764a954aafe9ffae488d50ae674aabdcb4f248006d5","price_changes":[{"asset_id":"8761897749749422724209054078244794145777693856614463256546737399611489089783","best_ask":"0.58","best_bid":"0.57","hash":"02d38692c8e27c597923bbcb94ae75bd5ffcf56c","price":"0.02","side":"BUY","size":"683.1"},{"asset_id":"14965588658799411272385430903075831224615961675357217884735713260981483529984","best_ask":"0.43","best_bid":"0.42","hash":"b4f03ddb791f240923962a80764f6ea39df20b29","price":"0.98","side":"SELL","size":"683.1"}],"timestamp":"1785207905233"},"payload_hash":"9de32411b294d4e22fe12a3f5d151158b73adfdeb41c49d7f028cb555f00ac34","raw_frame":"{\"market\":\"0x779291bef19b6709f61e9764a954aafe9ffae488d50ae674aabdcb4f248006d5\", \"price_changes\":[{\"asset_id\":\"8761897749749422724209054078244794145777693856614463256546737399611489089783\", \"price\":\"0.02\", \"size\":\"683.1\", \"side\":\"BUY\", \"hash\":\"02d38692c8e27c597923bbcb94ae75bd5ffcf56c\", \"best_bid\":\"0.57\", \"best_ask\":\"0.58\"}, {\"asset_id\":\"14965588658799411272385430903075831224615961675357217884735713260981483529984\", \"price\":\"0.98\", \"size\":\"683.1\", \"side\":\"SELL\", \"hash\":\"b4f03ddb791f240923962a80764f6ea39df20b29\", \"best_bid\":\"0.42\", \"best_ask\":\"0.43\"}], \"timestamp\":\"1785207905233\", \"event_type\":\"price_change\"}","received_at":"2026-07-28T03:05:06.221308Z","schema_version":"clob-market-ws.price_change.v1","sequence":null,"server_hash":null,"server_timestamp":"1785207905233","session_id":"3e519d9098404c15b234d96025eb1a2b","source":"clob_market_ws"},"received_at":"2026-07-28T03:05:06.221308Z","record_id":"b25571d97915c3d7aae336f33e2c002664a780ea8ba893aac7e2c72b453f8ffd","schema_fingerprint":"4aa3821a28b0b7c2400bc59aba4bcc0a76e971dadd19610d3ad38c768e124dc7","schema_version":"edge-lab-recorder.raw.v1","sequence":null,"source":"clob_market_ws"}
{"event_at":"2026-07-28T03:05:05.268000Z","event_fingerprint":"0f38936cfb15ff424811b13b5196fcf6f75055769fde03447fa531c10e02d497","payload":{"connection_id":"a6b55582af5f430fb37ad02bf0922475","event_at":"2026-07-28T03:05:05.268000Z","event_type":"price_change","frame_hash":"7bcb1fbe472d03f709e9ce961ea6380a19018a52e572ab1b90c6512f20123a85","frame_index":0,"kind":"data","monotonic_ns":309889254600875,"payload":{"event_type":"price_change","market":"0x779291bef19b6709f61e9764a954aafe9ffae488d50ae674aabdcb4f248006d5","price_changes":[{"asset_id":"14965588658799411272385430903075831224615961675357217884735713260981483529984","best_ask":"0.43","best_bid":"0.42","hash":"45313a41998d0a1840aca7ee5d0e00aa2135b67d","price":"0.26","side":"BUY","size":"236.1"},{"asset_id":"8761897749749422724209054078244794145777693856614463256546737399611489089783","best_ask":"0.58","best_bid":"0.57","hash":"e8bc4cf9899f13d4db12d33fb53fb54e51573391","price":"0.74","side":"SELL","size":"236.1"}],"timestamp":"1785207905268"},"payload_hash":"9cb40def1f95a864eb95faf145db0eec851fdda144755ddd61d00b3e968812a5","raw_frame":"{\"market\":\"0x779291bef19b6709f61e9764a954aafe9ffae488d50ae674aabdcb4f248006d5\", \"price_changes\":[{\"asset_id\":\"14965588658799411272385430903075831224615961675357217884735713260981483529984\", \"price\":\"0.26\", \"size\":\"236.1\", \"side\":\"BUY\", \"hash\":\"45313a41998d0a1840aca7ee5d0e00aa2135b67d\", \"best_bid\":\"0.42\", \"best_ask\":\"0.43\"}, {\"asset_id\":\"8761897749749422724209054078244794145777693856614463256546737399611489089783\", \"price\":\"0.74\", \"size\":\"236.1\", \"side\":\"SELL\", \"hash\":\"e8bc4cf9899f13d4db12d33fb53fb54e51573391\", \"best_bid\":\"0.57\", \"best_ask\":\"0.58\"}], \"timestamp\":\"1785207905268\", \"event_type\":\"price_change\"}","received_at":"2026-07-28T03:05:06.224191Z","schema_version":"clob-market-ws.price_change.v1","sequence":null,"server_hash":null,"server_timestamp":"1785207905268","session_id":"3e519d9098404c15b234d96025eb1a2b","source":"clob_market_ws"},"received_at":"2026-07-28T03:05:06.224191Z","record_id":"c646d30137e50c28f6ff962ad3829b1648ef3b9a7499b4711a9a6c77a0478bb9","schema_fingerprint":"4aa3821a28b0b7c2400bc59aba4bcc0a76e971dadd19610d3ad38c768e124dc7","schema_version":"edge-lab-recorder.raw.v1","sequence":null,"source":"clob_market_ws"}
{"event_at":"2026-07-28T03:05:05.280000Z","event_fingerprint":"d2ba9cda9cebb2b4de177efe74d5e63429917707bfeea76dc5934762d461b1e9","payload":{"connection_id":"a6b55582af5f430fb37ad02bf0922475","event_at":"2026-07-28T03:05:05.280000Z","event_type":"price_change","frame_hash":"6a97cad409d95699fbe328396bf7bfd60cb45522f0fe00776f7714c9cd62be0b","frame_index":0,"kind":"data","monotonic_ns":309889258182833,"payload":{"event_type":"price_change","market":"0x779291bef19b6709f61e9764a954aafe9ffae488d50ae674aabdcb4f248006d5","price_changes":[{"asset_id":"8761897749749422724209054078244794145777693856614463256546737399611489089783","best_ask":"0.58","best_bid":"0.57","hash":"e6d65232b1b8b3959a07eee917c5e51350500651","price":"0.53","side":"BUY","size":"111.02"},{"asset_id":"14965588658799411272385430903075831224615961675357217884735713260981483529984","best_ask":"0.43","best_bid":"0.42","hash":"3fa35bf57a1ca300f15412689f2e667371c46c8a","price":"0.47","side":"SELL","size":"111.02"}],"timestamp":"1785207905280"},"payload_hash":"b580092d8a80cbb3982efb9dc44ff1290f9c24ea3af2a027216ff68f8e5c2007","raw_frame":"{\"market\":\"0x779291bef19b6709f61e9764a954aafe9ffae488d50ae674aabdcb4f248006d5\", \"price_changes\":[{\"asset_id\":\"8761897749749422724209054078244794145777693856614463256546737399611489089783\", \"price\":\"0.53\", \"size\":\"111.02\", \"side\":\"BUY\", \"hash\":\"e6d65232b1b8b3959a07eee917c5e51350500651\", \"best_bid\":\"0.57\", \"best_ask\":\"0.58\"}, {\"asset_id\":\"14965588658799411272385430903075831224615961675357217884735713260981483529984\", \"price\":\"0.47\", \"size\":\"111.02\", \"side\":\"SELL\", \"hash\":\"3fa35bf57a1ca300f15412689f2e667371c46c8a\", \"best_bid\":\"0.42\", \"best_ask\":\"0.43\"}], \"timestamp\":\"1785207905280\", \"event_type\":\"price_change\"}","received_at":"2026-07-28T03:05:06.227774Z","schema_version":"clob-market-ws.price_change.v1","sequence":null,"server_hash":null,"server_timestamp":"1785207905280","session_id":"3e519d9098404c15b234d96025eb1a2b","source":"clob_market_ws"},"received_at":"2026-07-28T03:05:06.227774Z","record_id":"f3423bd77fdbea864def3a810ee83f4a1f4a5db3c5d940cb3748a76bb98ae000","schema_fingerprint":"4aa3821a28b0b7c2400bc59aba4bcc0a76e971dadd19610d3ad38c768e124dc7","schema_version":"edge-lab-recorder.raw.v1","sequence":null,"source":"clob_market_ws"}
{"event_at":"2026-07-28T03:05:05.280000Z","event_fingerprint":"98d1618bc97e0835cc19c5182ea39c2f902ebe81427b30104f15616e80b03796","payload":{"connection_id":"a6b55582af5f430fb37ad02bf0922475","event_at":"2026-07-28T03:05:05.280000Z","event_type":"price_change","frame_hash":"91f743a2921aff75ca179bfe50dd30946cac736a3070ea1751411bbbc5848d14","frame_index":0,"kind":"data","monotonic_ns":309889262462041,"payload":{"event_type":"price_change","market":"0x779291bef19b6709f61e9764a954aafe9ffae488d50ae674aabdcb4f248006d5","price_changes":[{"asset_id":"8761897749749422724209054078244794145777693856614463256546737399611489089783","best_ask":"0.58","best_bid":"0.57","hash":"e6d65232b1b8b3959a07eee917c5e51350500651","price":"0.52","side":"BUY","size":"111"},{"asset_id":"14965588658799411272385430903075831224615961675357217884735713260981483529984","best_ask":"0.43","best_bid":"0.42","hash":"3fa35bf57a1ca300f15412689f2e667371c46c8a","price":"0.48","side":"SELL","size":"111"}],"timestamp":"1785207905280"},"payload_hash":"8f3b53814bc6d6ebea878334af9a575254841a72257bb18640110c46f21bcad7","raw_frame":"{\"market\":\"0x779291bef19b6709f61e9764a954aafe9ffae488d50ae674aabdcb4f248006d5\", \"price_changes\":[{\"asset_id\":\"8761897749749422724209054078244794145777693856614463256546737399611489089783\", \"price\":\"0.52\", \"size\":\"111\", \"side\":\"BUY\", \"hash\":\"e6d65232b1b8b3959a07eee917c5e51350500651\", \"best_bid\":\"0.57\", \"best_ask\":\"0.58\"}, {\"asset_id\":\"14965588658799411272385430903075831224615961675357217884735713260981483529984\", \"price\":\"0.48\", \"size\":\"111\", \"side\":\"SELL\", \"hash\":\"3fa35bf57a1ca300f15412689f2e667371c46c8a\", \"best_bid\":\"0.42\", \"best_ask\":\"0.43\"}], \"timestamp\":\"1785207905280\", \"event_type\":\"price_change\"}","received_at":"2026-07-28T03:05:06.232053Z","schema_version":"clob-market-ws.price_change.v1","sequence":null,"server_hash":null,"server_timestamp":"1785207905280","session_id":"3e519d9098404c15b234d96025eb1a2b","source":"clob_market_ws"},"received_at":"2026-07-28T03:05:06.232053Z","record_id":"395c8646bb2448b855596152376642de51396ceacb1ac744e1418f3c74506ca1","schema_fingerprint":"4aa3821a28b0b7c2400bc59aba4bcc0a76e971dadd19610d3ad38c768e124dc7","schema_version":"edge-lab-recorder.raw.v1","sequence":null,"source":"clob_market_ws"}
{"event_at":"2026-07-28T03:05:05.315000Z","event_fingerprint":"2ee44e4d3997370bc7951da48813575a664f3790e3f0989caa32c6f7a8952087","payload":{"connection_id":"a6b55582af5f430fb37ad02bf0922475","event_at":"2026-07-28T03:05:05.315000Z","event_type":"price_change","frame_hash":"9ed3f55733b670f2c88baf760be370c7507b8e51312d2f98ba2ba90cf18a61e0","frame_index":0,"kind":"data","monotonic_ns":309889266199166,"payload":{"event_type":"price_change","market":"0x779291bef19b6709f61e9764a954aafe9ffae488d50ae674aabdcb4f248006d5","price_changes":[{"asset_id":"8761897749749422724209054078244794145777693856614463256546737399611489089783","best_ask":"0.58","best_bid":"0.57","hash":"1c508025ac9021973c8f4888c8eb1a495abd4334","price":"0.01","side":"BUY","size":"5858.02"},{"asset_id":"14965588658799411272385430903075831224615961675357217884735713260981483529984","best_ask":"0.43","best_bid":"0.42","hash":"d729d8224b49f2b8531884300137a4e6fa85e253","price":"0.99","side":"SELL","size":"5858.02"}],"timestamp":"1785207905315"},"payload_hash":"559707dc25892dda39fe09047477d5e895698290e3f89b53b15a020280de5e65","raw_frame":"{\"market\":\"0x779291bef19b6709f61e9764a954aafe9ffae488d50ae674aabdcb4f248006d5\", \"price_changes\":[{\"asset_id\":\"8761897749749422724209054078244794145777693856614463256546737399611489089783\", \"price\":\"0.01\", \"size\":\"5858.02\", \"side\":\"BUY\", \"hash\":\"1c508025ac9021973c8f4888c8eb1a495abd4334\", \"best_bid\":\"0.57\", \"best_ask\":\"0.58\"}, {\"asset_id\":\"14965588658799411272385430903075831224615961675357217884735713260981483529984\", \"price\":\"0.99\", \"size\":\"5858.02\", \"side\":\"SELL\", \"hash\":\"d729d8224b49f2b8531884300137a4e6fa85e253\", \"best_bid\":\"0.42\", \"best_ask\":\"0.43\"}], \"timestamp\":\"1785207905315\", \"event_type\":\"price_change\"}","received_at":"2026-07-28T03:05:06.235789Z","schema_version":"clob-market-ws.price_change.v1","sequence":null,"server_hash":null,"server_timestamp":"1785207905315","session_id":"3e519d9098404c15b234d96025eb1a2b","source":"clob_market_ws"},"received_at":"2026-07-28T03:05:06.235789Z","record_id":"66f5e321c0ad3dcd3aa6f4a927417c91e98fce8d607915d2a74986c0265fc10a","schema_fingerprint":"4aa3821a28b0b7c2400bc59aba4bcc0a76e971dadd19610d3ad38c768e124dc7","schema_version":"edge-lab-recorder.raw.v1","sequence":null,"source":"clob_market_ws"}
{"event_at":"2026-07-28T03:05:05.339000Z","event_fingerprint":"c61ce4e1cd4cec2823ebb51ecbbea5e50050b6198c1195be2cc80bbfb198282f","payload":{"connection_id":"a6b55582af5f430fb37ad02bf0922475","event_at":"2026-07-28T03:05:05.339000Z","event_type":"price_change","frame_hash":"cfd748a883637265eb9a0425cd47d1142f73d855a0758b4a2349da8fc8028ca4","frame_index":0,"kind":"data","monotonic_ns":309889273138875,"payload":{"event_type":"price_change","market":"0x779291bef19b6709f61e9764a954aafe9ffae488d50ae674aabdcb4f248006d5","price_changes":[{"asset_id":"8761897749749422724209054078244794145777693856614463256546737399611489089783","best_ask":"0.58","best_bid":"0.57","hash":"2f093ff149f8aa8420d3c9c0bffe9d38b34f3fcb","price":"0.01","side":"BUY","size":"5853.02"},{"asset_id":"14965588658799411272385430903075831224615961675357217884735713260981483529984","best_ask":"0.43","best_bid":"0.42","hash":"299bd185f91c0f05a92a2abdc49728970c028a8a","price":"0.99","side":"SELL","size":"5853.02"}],"timestamp":"1785207905339"},"payload_hash":"b3ae7025ea895112ef480d4d3e01067f6f3b4799e0660c6a13f71516ca60dec9","raw_frame":"{\"market\":\"0x779291bef19b6709f61e9764a954aafe9ffae488d50ae674aabdcb4f248006d5\", \"price_changes\":[{\"asset_id\":\"8761897749749422724209054078244794145777693856614463256546737399611489089783\", \"price\":\"0.01\", \"size\":\"5853.02\", \"side\":\"BUY\", \"hash\":\"2f093ff149f8aa8420d3c9c0bffe9d38b34f3fcb\", \"best_bid\":\"0.57\", \"best_ask\":\"0.58\"}, {\"asset_id\":\"14965588658799411272385430903075831224615961675357217884735713260981483529984\", \"price\":\"0.99\", \"size\":\"5853.02\", \"side\":\"SELL\", \"hash\":\"299bd185f91c0f05a92a2abdc49728970c028a8a\", \"best_bid\":\"0.42\", \"best_ask\":\"0.43\"}], \"timestamp\":\"1785207905339\", \"event_type\":\"price_change\"}","received_at":"2026-07-28T03:05:06.242730Z","schema_version":"clob-market-ws.price_change.v1","sequence":null,"server_hash":null,"server_timestamp":"1785207905339","session_id":"3e519d9098404c15b234d96025eb1a2b","source":"clob_market_ws"},"received_at":"2026-07-28T03:05:06.242730Z","record_id":"fc4d443a60dd190902fe624f6d4ada6943ef838d97361f7848b116ab1844bcdf","schema_fingerprint":"4aa3821a28b0b7c2400bc59aba4bcc0a76e971dadd19610d3ad38c768e124dc7","schema_version":"edge-lab-recorder.raw.v1","sequence":null,"source":"clob_market_ws"}
{"event_at":"2026-07-28T03:05:05.339000Z","event_fingerprint":"3d430a651444a6e2ffc2a77c273f7fb9ff2b4c915ca9ebc81e6020dbf0c00fd6","payload":{"connection_id":"a6b55582af5f430fb37ad02bf0922475","event_at":"2026-07-28T03:05:05.339000Z","event_type":"price_change","frame_hash":"37ed323380c2a96a3b617b94a3e3df4576bc2e355389b8d1f3285dbde3c25d6c","frame_index":0,"kind":"data","monotonic_ns":309889277514750,"payload":{"event_type":"price_change","market":"0x779291bef19b6709f61e9764a954aafe9ffae488d50ae674aabdcb4f248006d5","price_changes":[{"asset_id":"8761897749749422724209054078244794145777693856614463256546737399611489089783","best_ask":"0.58","best_bid":"0.57","hash":"6c58996e0b0fee5a491ef059123ea3f99279e3d7","price":"0.04","side":"BUY","size":"593.09"},{"asset_id":"14965588658799411272385430903075831224615961675357217884735713260981483529984","best_ask":"0.43","best_bid":"0.42","hash":"56385038e6ee0470441cbee77a910f8c11b83482","price":"0.96","side":"SELL","size":"593.09"}],"timestamp":"1785207905339"},"payload_hash":"412fc8e46c14e4c67110822bb36eaa0c0e286ad2f1d60e2291030469a5d4e8a0","raw_frame":"{\"market\":\"0x779291bef19b6709f61e9764a954aafe9ffae488d50ae674aabdcb4f248006d5\", \"price_changes\":[{\"asset_id\":\"8761897749749422724209054078244794145777693856614463256546737399611489089783\", \"price\":\"0.04\", \"size\":\"593.09\", \"side\":\"BUY\", \"hash\":\"6c58996e0b0fee5a491ef059123ea3f99279e3d7\", \"best_bid\":\"0.57\", \"best_ask\":\"0.58\"}, {\"asset_id\":\"14965588658799411272385430903075831224615961675357217884735713260981483529984\", \"price\":\"0.96\", \"size\":\"593.09\", \"side\":\"SELL\", \"hash\":\"56385038e6ee0470441cbee77a910f8c11b83482\", \"best_bid\":\"0.42\", \"best_ask\":\"0.43\"}], \"timestamp\":\"1785207905339\", \"event_type\":\"price_change\"}","received_at":"2026-07-28T03:05:06.247105Z","schema_version":"clob-market-ws.price_change.v1","sequence":null,"server_hash":null,"server_timestamp":"1785207905339","session_id":"3e519d9098404c15b234d96025eb1a2b","source":"clob_market_ws"},"received_at":"2026-07-28T03:05:06.247105Z","record_id":"c631f1c12b51af49c4b385e4cf0d6f45699d771e40800a51f2711a4fcced2dbe","schema_fingerprint":"4aa3821a28b0b7c2400bc59aba4bcc0a76e971dadd19610d3ad38c768e124dc7","schema_version":"edge-lab-recorder.raw.v1","sequence":null,"source":"clob_market_ws"}
{"event_at":"2026-07-28T03:05:05.356000Z","event_fingerprint":"7cb76b6b03aebb38598ad76a541471ff1efcdfd27b3ceebdbb9d67fd05e3f6aa","payload":{"connection_id":"a6b55582af5f430fb37ad02bf0922475","event_at":"2026-07-28T03:05:05.356000Z","event_type":"price_change","frame_hash":"ff52659a6d6f0da443210be83d1f17d9a48796c9d06049bfc4eeac8cca9135d2","frame_index":0,"kind":"data","monotonic_ns":309889281902708,"payload":{"event_type":"price_change","market":"0x779291bef19b6709f61e9764a954aafe9ffae488d50ae674aabdcb4f248006d5","price_changes":[{"asset_id":"8761897749749422724209054078244794145777693856614463256546737399611489089783","best_ask":"0.58","best_bid":"0.57","hash":"8e13828c613d0e4b57113288a57f43e9bf6ed0ed","price":"0.57","side":"BUY","size":"48.98"},{"asset_id":"14965588658799411272385430903075831224615961675357217884735713260981483529984","best_ask":"0.43","best_bid":"0.42","hash":"3b398a0242237d51aa3b8e24acb2e05f248d2cf7","price":"0.43","side":"SELL","size":"48.98"}],"timestamp":"1785207905356"},"payload_hash":"4f2e98fa97f07e9ce5626119cd55c7f32b054d12a9a550495f234d7da167a8ee","raw_frame":"{\"market\":\"0x779291bef19b6709f61e9764a954aafe9ffae488d50ae674aabdcb4f248006d5\", \"price_changes\":[{\"asset_id\":\"8761897749749422724209054078244794145777693856614463256546737399611489089783\", \"price\":\"0.57\", \"size\":\"48.98\", \"side\":\"BUY\", \"hash\":\"8e13828c613d0e4b57113288a57f43e9bf6ed0ed\", \"best_bid\":\"0.57\", \"best_ask\":\"0.58\"}, {\"asset_id\":\"14965588658799411272385430903075831224615961675357217884735713260981483529984\", \"price\":\"0.43\", \"size\":\"48.98\", \"side\":\"SELL\", \"hash\":\"3b398a0242237d51aa3b8e24acb2e05f248d2cf7\", \"best_bid\":\"0.42\", \"best_ask\":\"0.43\"}], \"timestamp\":\"1785207905356\", \"event_type\":\"price_change\"}","received_at":"2026-07-28T03:05:06.251493Z","schema_version":"clob-market-ws.price_change.v1","sequence":null,"server_hash":null,"server_timestamp":"1785207905356","session_id":"3e519d9098404c15b234d96025eb1a2b","source":"clob_market_ws"},"received_at":"2026-07-28T03:05:06.251493Z","record_id":"ca5deba19e9a1b7a675701af09c0002aee73864a4055a70a197f032bc160b9ab","schema_fingerprint":"4aa3821a28b0b7c2400bc59aba4bcc0a76e971dadd19610d3ad38c768e124dc7","schema_version":"edge-lab-recorder.raw.v1","sequence":null,"source":"clob_market_ws"}
{"event_at":"2026-07-28T03:05:05.370000Z","event_fingerprint":"cc848eb0052caadc89514a734845d40196a1aa566ecf11759af88f3eddef973a","payload":{"connection_id":"a6b55582af5f430fb37ad02bf0922475","event_at":"2026-07-28T03:05:05.370000Z","event_type":"price_change","frame_hash":"f25e04e4f0747ebffef30c61dc9814bd751e4ec702d8744a8e4e43353f564b82","frame_index":0,"kind":"data","monotonic_ns":309889288927666,"payload":{"event_type":"price_change","market":"0x779291bef19b6709f61e9764a954aafe9ffae488d50ae674aabdcb4f248006d5","price_changes":[{"asset_id":"8761897749749422724209054078244794145777693856614463256546737399611489089783","best_ask":"0.58","best_bid":"0.57","hash":"5207f10d3c83edb9169e0d7b872cf1cd5855bec6","price":"0.52","side":"BUY","size":"106"},{"asset_id":"14965588658799411272385430903075831224615961675357217884735713260981483529984","best_ask":"0.43","best_bid":"0.42","hash":"d363229e0945765c3d830b6a7c8a7124de2d3c36","price":"0.48","side":"SELL","size":"106"}],"timestamp":"1785207905370"},"payload_hash":"30226e9634905c84bc29e343cfb11329e33c9b291f1e9b377ccde0c38ee8ff31","raw_frame":"{\"market\":\"0x779291bef19b6709f61e9764a954aafe9ffae488d50ae674aabdcb4f248006d5\", \"price_changes\":[{\"asset_id\":\"8761897749749422724209054078244794145777693856614463256546737399611489089783\", \"price\":\"0.52\", \"size\":\"106\", \"side\":\"BUY\", \"hash\":\"5207f10d3c83edb9169e0d7b872cf1cd5855bec6\", \"best_bid\":\"0.57\", \"best_ask\":\"0.58\"}, {\"asset_id\":\"14965588658799411272385430903075831224615961675357217884735713260981483529984\", \"price\":\"0.48\", \"size\":\"106\", \"side\":\"SELL\", \"hash\":\"d363229e0945765c3d830b6a7c8a7124de2d3c36\", \"best_bid\":\"0.42\", \"best_ask\":\"0.43\"}], \"timestamp\":\"1785207905370\", \"event_type\":\"price_change\"}","received_at":"2026-07-28T03:05:06.258516Z","schema_version":"clob-market-ws.price_change.v1","sequence":null,"server_hash":null,"server_timestamp":"1785207905370","session_id":"3e519d9098404c15b234d96025eb1a2b","source":"clob_market_ws"},"received_at":"2026-07-28T03:05:06.258516Z","record_id":"eb9fb241cc046c5d53828b1f1f8220af3f64308a1dea852c799dab064223d088","schema_fingerprint":"4aa3821a28b0b7c2400bc59aba4bcc0a76e971dadd19610d3ad38c768e124dc7","schema_version":"edge-lab-recorder.raw.v1","sequence":null,"source":"clob_market_ws"}
{"event_at":"2026-07-28T03:05:05.394000Z","event_fingerprint":"1ccda583a9277a5e465844eafd87aeaf02a533bbe30b2e63a1f721ef8d450582","payload":{"connection_id":"a6b55582af5f430fb37ad02bf0922475","event_at":"2026-07-28T03:05:05.394000Z","event_type":"price_change","frame_hash":"75870e7783ec2311e577805455bf435e32c14b170e6b8c9827412b27b0180996","frame_index":0,"kind":"data","monotonic_ns":309889293795666,"payload":{"event_type":"price_change","market":"0x779291bef19b6709f61e9764a954aafe9ffae488d50ae674aabdcb4f248006d5","price_changes":[{"asset_id":"8761897749749422724209054078244794145777693856614463256546737399611489089783","best_ask":"0.58","best_bid":"0.57","hash":"5083dce53a998d2d34be1b63a13f4087e20870b1","price":"0.04","side":"BUY","size":"588.09"},{"asset_id":"14965588658799411272385430903075831224615961675357217884735713260981483529984","best_ask":"0.43","best_bid":"0.42","hash":"de97a001348655af2118c2b99c5f80afa82309ee","price":"0.96","side":"SELL","size":"588.09"}],"timestamp":"1785207905394"},"payload_hash":"2a4b0b44f00a4bad13c689098d10f8fe6f2e435a453c44eb6421bcf6e6922eb7","raw_frame":"{\"market\":\"0x779291bef19b6709f61e9764a954aafe9ffae488d50ae674aabdcb4f248006d5\", \"price_changes\":[{\"asset_id\":\"8761897749749422724209054078244794145777693856614463256546737399611489089783\", \"price\":\"0.04\", \"size\":\"588.09\", \"side\":\"BUY\", \"hash\":\"5083dce53a998d2d34be1b63a13f4087e20870b1\", \"best_bid\":\"0.57\", \"best_ask\":\"0.58\"}, {\"asset_id\":\"14965588658799411272385430903075831224615961675357217884735713260981483529984\", \"price\":\"0.96\", \"size\":\"588.09\", \"side\":\"SELL\", \"hash\":\"de97a001348655af2118c2b99c5f80afa82309ee\", \"best_bid\":\"0.42\", \"best_ask\":\"0.43\"}], \"timestamp\":\"1785207905394\", \"event_type\":\"price_change\"}","received_at":"2026-07-28T03:05:06.263386Z","schema_version":"clob-market-ws.price_change.v1","sequence":null,"server_hash":null,"server_timestamp":"1785207905394","session_id":"3e519d9098404c15b234d96025eb1a2b","source":"clob_market_ws"},"received_at":"2026-07-28T03:05:06.263386Z","record_id":"4751034bdd31fbc053040ef91e58c23fe3c36885d41707b97ceb3844f5601707","schema_fingerprint":"4aa3821a28b0b7c2400bc59aba4bcc0a76e971dadd19610d3ad38c768e124dc7","schema_version":"edge-lab-recorder.raw.v1","sequence":null,"source":"clob_market_ws"}
{"event_at":"2026-07-28T03:05:05.497000Z","event_fingerprint":"3f6a82f61971c88110ab7c54d5b615368edf3783bfaf7e5eac708b39d5fe63cd","payload":{"connection_id":"a6b55582af5f430fb37ad02bf0922475","event_at":"2026-07-28T03:05:05.497000Z","event_type":"price_change","frame_hash":"6e529c8c816777af0f8c934748586d24807b080c5fcef455e99929665abf093e","frame_index":0,"kind":"data","monotonic_ns":309889297444791,"payload":{"event_type":"price_change","market":"0x779291bef19b6709f61e9764a954aafe9ffae488d50ae674aabdcb4f248006d5","price_changes":[{"asset_id":"8761897749749422724209054078244794145777693856614463256546737399611489089783","best_ask":"0.58","best_bid":"0.57","hash":"e15424533ea2ea60d1a4571cab76d77ba8bee000","price":"0.04","side":"BUY","size":"593.09"},{"asset_id":"14965588658799411272385430903075831224615961675357217884735713260981483529984","best_ask":"0.43","best_bid":"0.42","hash":"68a915258e1dce03f89a677d16fd5d103a142af7","price":"0.96","side":"SELL","size":"593.09"}],"timestamp":"1785207905497"},"payload_hash":"3ae5ce12a8105c693a13f9eaac93300be497ff8ae40e02e51d324076e5983039","raw_frame":"{\"market\":\"0x779291bef19b6709f61e9764a954aafe9ffae488d50ae674aabdcb4f248006d5\", \"price_changes\":[{\"asset_id\":\"8761897749749422724209054078244794145777693856614463256546737399611489089783\", \"price\":\"0.04\", \"size\":\"593.09\", \"side\":\"BUY\", \"hash\":\"e15424533ea2ea60d1a4571cab76d77ba8bee000\", \"best_bid\":\"0.57\", \"best_ask\":\"0.58\"}, {\"asset_id\":\"14965588658799411272385430903075831224615961675357217884735713260981483529984\", \"price\":\"0.96\", \"size\":\"593.09\", \"side\":\"SELL\", \"hash\":\"68a915258e1dce03f89a677d16fd5d103a142af7\", \"best_bid\":\"0.42\", \"best_ask\":\"0.43\"}], \"timestamp\":\"1785207905497\", \"event_type\":\"price_change\"}","received_at":"2026-07-28T03:05:06.267034Z","schema_version":"clob-market-ws.price_change.v1","sequence":null,"server_hash":null,"server_timestamp":"1785207905497","session_id":"3e519d9098404c15b234d96025eb1a2b","source":"clob_market_ws"},"received_at":"2026-07-28T03:05:06.267034Z","record_id":"547596aedce97da3e607c0cc99aeeeee3936e6188476695c2446302eab6a7dea","schema_fingerprint":"4aa3821a28b0b7c2400bc59aba4bcc0a76e971dadd19610d3ad38c768e124dc7","schema_version":"edge-lab-recorder.raw.v1","sequence":null,"source":"clob_market_ws"}
{"event_at":"2026-07-28T03:05:05.504000Z","event_fingerprint":"d5db4a8486bdbb9ebd5271ba85e99364dc7eeabc7315f22097820162f4acb545","payload":{"connection_id":"a6b55582af5f430fb37ad02bf0922475","event_at":"2026-07-28T03:05:05.504000Z","event_type":"price_change","frame_hash":"b209020e79d3a6c00ffdd6e72fdbb9bbe35388e5e0f5c36958546b082eb7456b","frame_index":0,"kind":"data","monotonic_ns":309889304286458,"payload":{"event_type":"price_change","market":"0x779291bef19b6709f61e9764a954aafe9ffae488d50ae674aabdcb4f248006d5","price_changes":[{"asset_id":"14965588658799411272385430903075831224615961675357217884735713260981483529984","best_ask":"0.43","best_bid":"0.42","hash":"29587b8331af677db1272f7ad70bd1c45c499d1b","price":"0.42","side":"BUY","size":"20.8"},{"asset_id":"8761897749749422724209054078244794145777693856614463256546737399611489089783","best_ask":"0.58","best_bid":"0.57","hash":"4e57a2eb35c1ca428ab4c9351e5dd94414474e53","price":"0.58","side":"SELL","size":"20.8"}],"timestamp":"1785207905504"},"payload_hash":"2beecacc669f34ae309be7a0f156f095d3c986c4f0f6a923a7fedecb63435239","raw_frame":"{\"market\":\"0x779291bef19b6709f61e9764a954aafe9ffae488d50ae674aabdcb4f248006d5\", \"price_changes\":[{\"asset_id\":\"14965588658799411272385430903075831224615961675357217884735713260981483529984\", \"price\":\"0.42\", \"size\":\"20.8\", \"side\":\"BUY\", \"hash\":\"29587b8331af677db1272f7ad70bd1c45c499d1b\", \"best_bid\":\"0.42\", \"best_ask\":\"0.43\"}, {\"asset_id\":\"8761897749749422724209054078244794145777693856614463256546737399611489089783\", \"price\":\"0.58\", \"size\":\"20.8\", \"side\":\"SELL\", \"hash\":\"4e57a2eb35c1ca428ab4c9351e5dd94414474e53\", \"best_bid\":\"0.57\", \"best_ask\":\"0.58\"}], \"timestamp\":\"1785207905504\", \"event_type\":\"price_change\"}","received_at":"2026-07-28T03:05:06.273869Z","schema_version":"clob-market-ws.price_change.v1","sequence":null,"server_hash":null,"server_timestamp":"1785207905504","session_id":"3e519d9098404c15b234d96025eb1a2b","source":"clob_market_ws"},"received_at":"2026-07-28T03:05:06.273869Z","record_id":"ceae844b6281330635a80fbf1a4a4ac12761807c351e9870ad8257dfc80829c9","schema_fingerprint":"4aa3821a28b0b7c2400bc59aba4bcc0a76e971dadd19610d3ad38c768e124dc7","schema_version":"edge-lab-recorder.raw.v1","sequence":null,"source":"clob_market_ws"}
{"event_at":"2026-07-28T03:05:05.509000Z","event_fingerprint":"76a6e97f70acfe027ccbf8acd6755855681c21930f9b6b4b8b501dcd8a1afc03","payload":{"connection_id":"a6b55582af5f430fb37ad02bf0922475","event_at":"2026-07-28T03:05:05.509000Z","event_type":"price_change","frame_hash":"47fb0754ddd60f897f3492205b388ee3f7c468b68dd9b388947dc1a81c7bb8c9","frame_index":0,"kind":"data","monotonic_ns":309889312172250,"payload":{"event_type":"price_change","market":"0x779291bef19b6709f61e9764a954aafe9ffae488d50ae674aabdcb4f248006d5","price_changes":[{"asset_id":"8761897749749422724209054078244794145777693856614463256546737399611489089783","best_ask":"0.58","best_bid":"0.57","hash":"513a5860d02b8d03dadd0ddb0bced32b92301a4f","price":"0.52","side":"BUY","size":"111"},{"asset_id":"14965588658799411272385430903075831224615961675357217884735713260981483529984","best_ask":"0.43","best_bid":"0.42","hash":"3ac612d22f79e413e5210ffbc6d77a11c47ef442","price":"0.48","side":"SELL","size":"111"}],"timestamp":"1785207905509"},"payload_hash":"001d150335d823874037634684dbbe3389f33f5e5667b7067c976042ced55811","raw_frame":"{\"market\":\"0x779291bef19b6709f61e9764a954aafe9ffae488d50ae674aabdcb4f248006d5\", \"price_changes\":[{\"asset_id\":\"8761897749749422724209054078244794145777693856614463256546737399611489089783\", \"price\":\"0.52\", \"size\":\"111\", \"side\":\"BUY\", \"hash\":\"513a5860d02b8d03dadd0ddb0bced32b92301a4f\", \"best_bid\":\"0.57\", \"best_ask\":\"0.58\"}, {\"asset_id\":\"14965588658799411272385430903075831224615961675357217884735713260981483529984\", \"price\":\"0.48\", \"size\":\"111\", \"side\":\"SELL\", \"hash\":\"3ac612d22f79e413e5210ffbc6d77a11c47ef442\", \"best_bid\":\"0.42\", \"best_ask\":\"0.43\"}], \"timestamp\":\"1785207905509\", \"event_type\":\"price_change\"}","received_at":"2026-07-28T03:05:06.281758Z","schema_version":"clob-market-ws.price_change.v1","sequence":null,"server_hash":null,"server_timestamp":"1785207905509","session_id":"3e519d9098404c15b234d96025eb1a2b","source":"clob_market_ws"},"received_at":"2026-07-28T03:05:06.281758Z","record_id":"bae6f04e9d2faa133463fb1b0fa0ac2e15111204033fe4fa083096d79ef4c7d7","schema_fingerprint":"4aa3821a28b0b7c2400bc59aba4bcc0a76e971dadd19610d3ad38c768e124dc7","schema_version":"edge-lab-recorder.raw.v1","sequence":null,"source":"clob_market_ws"}
{"event_at":"2026-07-28T03:05:05.536000Z","event_fingerprint":"76f433f7309e480d35cfda7c238d39f87dc34a637569c5d0e345ec6eb539532d","payload":{"connection_id":"a6b55582af5f430fb37ad02bf0922475","event_at":"2026-07-28T03:05:05.536000Z","event_type":"price_change","frame_hash":"36b0669fe4ca6b661e188c340b4ac5a76e29387abffa99ed23f88d6c234e6e86","frame_index":0,"kind":"data","monotonic_ns":309889325568583,"payload":{"event_type":"price_change","market":"0x779291bef19b6709f61e9764a954aafe9ffae488d50ae674aabdcb4f248006d5","price_changes":[{"asset_id":"14965588658799411272385430903075831224615961675357217884735713260981483529984","best_ask":"0.43","best_bid":"0.42","hash":"12fc4812ee6a76d3b88cc852415c87694df1c0ad","price":"0.36","side":"BUY","size":"129.6"},{"asset_id":"8761897749749422724209054078244794145777693856614463256546737399611489089783","best_ask":"0.58","best_bid":"0.57","hash":"1dd8314354d6ca9d67cc257e5242686fafa8991c","price":"0.64","side":"SELL","size":"129.6"}],"timestamp":"1785207905536"},"payload_hash":"310f4a9f21c750ce1a298a917dbd2a3208ccb903ce65c29f64b887295bfc0e70","raw_frame":"{\"market\":\"0x779291bef19b6709f61e9764a954aafe9ffae488d50ae674aabdcb4f248006d5\", \"price_changes\":[{\"asset_id\":\"14965588658799411272385430903075831224615961675357217884735713260981483529984\", \"price\":\"0.36\", \"size\":\"129.6\", \"side\":\"BUY\", \"hash\":\"12fc4812ee6a76d3b88cc852415c87694df1c0ad\", \"best_bid\":\"0.42\", \"best_ask\":\"0.43\"}, {\"asset_id\":\"8761897749749422724209054078244794145777693856614463256546737399611489089783\", \"price\":\"0.64\", \"size\":\"129.6\", \"side\":\"SELL\", \"hash\":\"1dd8314354d6ca9d67cc257e5242686fafa8991c\", \"best_bid\":\"0.57\", \"best_ask\":\"0.58\"}], \"timestamp\":\"1785207905536\", \"event_type\":\"price_change\"}","received_at":"2026-07-28T03:05:06.295157Z","schema_version":"clob-market-ws.price_change.v1","sequence":null,"server_hash":null,"server_timestamp":"1785207905536","session_id":"3e519d9098404c15b234d96025eb1a2b","source":"clob_market_ws"},"received_at":"2026-07-28T03:05:06.295157Z","record_id":"7c4dca3fb8a063f50593cbc88fe6126e5f30f1fd7cd21e30ae180e036ed51232","schema_fingerprint":"4aa3821a28b0b7c2400bc59aba4bcc0a76e971dadd19610d3ad38c768e124dc7","schema_version":"edge-lab-recorder.raw.v1","sequence":null,"source":"clob_market_ws"}
{"event_at":"2026-07-28T03:05:05.550000Z","event_fingerprint":"8626841fd892a9e4faeddb83d6c91d804c1331c997660aae557d709afbe59104","payload":{"connection_id":"a6b55582af5f430fb37ad02bf0922475","event_at":"2026-07-28T03:05:05.550000Z","event_type":"price_change","frame_hash":"d5d634f20196bc0d2ddfeff97534e32561651680f9635d3865ae0f020e091983","frame_index":0,"kind":"data","monotonic_ns":309889336539708,"payload":{"event_type":"price_change","market":"0x779291bef19b6709f61e9764a954aafe9ffae488d50ae674aabdcb4f248006d5","price_changes":[{"asset_id":"8761897749749422724209054078244794145777693856614463256546737399611489089783","best_ask":"0.58","best_bid":"0.57","hash":"d3478eeb47920585b21883627e648daca78a294a","price":"0.01","side":"BUY","size":"5858.02"},{"asset_id":"14965588658799411272385430903075831224615961675357217884735713260981483529984","best_ask":"0.43","best_bid":"0.42","hash":"baa4d5aa13b67d31b642d930641c5b2dda8c159a","price":"0.99","side":"SELL","size":"5858.02"}],"timestamp":"1785207905550"},"payload_hash":"15a94a57811bbe392aca36dc269cd67e9dba2ba90b72a82ce123dd6dc54322e8","raw_frame":"{\"market\":\"0x779291bef19b6709f61e9764a954aafe9ffae488d50ae674aabdcb4f248006d5\", \"price_changes\":[{\"asset_id\":\"8761897749749422724209054078244794145777693856614463256546737399611489089783\", \"price\":\"0.01\", \"size\":\"5858.02\", \"side\":\"BUY\", \"hash\":\"d3478eeb47920585b21883627e648daca78a294a\", \"best_bid\":\"0.57\", \"best_ask\":\"0.58\"}, {\"asset_id\":\"14965588658799411272385430903075831224615961675357217884735713260981483529984\", \"price\":\"0.99\", \"size\":\"5858.02\", \"side\":\"SELL\", \"hash\":\"baa4d5aa13b67d31b642d930641c5b2dda8c159a\", \"best_bid\":\"0.42\", \"best_ask\":\"0.43\"}], \"timestamp\":\"1785207905550\", \"event_type\":\"price_change\"}","received_at":"2026-07-28T03:05:06.306127Z","schema_version":"clob-market-ws.price_change.v1","sequence":null,"server_hash":null,"server_timestamp":"1785207905550","session_id":"3e519d9098404c15b234d96025eb1a2b","source":"clob_market_ws"},"received_at":"2026-07-28T03:05:06.306127Z","record_id":"ac90729f77b4786d7ac5c98c69a1e017de94d75347a2f1e50233b6d3ad56e391","schema_fingerprint":"4aa3821a28b0b7c2400bc59aba4bcc0a76e971dadd19610d3ad38c768e124dc7","schema_version":"edge-lab-recorder.raw.v1","sequence":null,"source":"clob_market_ws"}
{"event_at":"2026-07-28T03:05:05.551000Z","event_fingerprint":"a3ab33057583eb69be72b2ebe96902c366115eaf8ce1607a1d999abe13a5eeba","payload":{"connection_id":"a6b55582af5f430fb37ad02bf0922475","event_at":"2026-07-28T03:05:05.551000Z","event_type":"price_change","frame_hash":"0273b78a31d540bdc478671e6564e43d303694137bf9f9066cd4a64c1452f05d","frame_index":0,"kind":"data","monotonic_ns":309889356009375,"payload":{"event_type":"price_change","market":"0x779291bef19b6709f61e9764a954aafe9ffae488d50ae674aabdcb4f248006d5","price_changes":[{"asset_id":"14965588658799411272385430903075831224615961675357217884735713260981483529984","best_ask":"0.43","best_bid":"0.42","hash":"1632bab6637d5c551b34b2d9594c2f18011f69e5","price":"0.38","side":"BUY","size":"86.2"},{"asset_id":"8761897749749422724209054078244794145777693856614463256546737399611489089783","best_ask":"0.58","best_bid":"0.57","hash":"be4a6a875903fd8cd69fe15d90454095c1db3e45","price":"0.62","side":"SELL","size":"86.2"}],"timestamp":"1785207905551"},"payload_hash":"b4f5ff013e9be11e8d9bef7e999dc161b6a62a1d929564a813daf1ae9f3f6d1d","raw_frame":"{\"market\":\"0x779291bef19b6709f61e9764a954aafe9ffae488d50ae674aabdcb4f248006d5\", \"price_changes\":[{\"asset_id\":\"14965588658799411272385430903075831224615961675357217884735713260981483529984\", \"price\":\"0.38\", \"size\":\"86.2\", \"side\":\"BUY\", \"hash\":\"1632bab6637d5c551b34b2d9594c2f18011f69e5\", \"best_bid\":\"0.42\", \"best_ask\":\"0.43\"}, {\"asset_id\":\"8761897749749422724209054078244794145777693856614463256546737399611489089783\", \"price\":\"0.62\", \"size\":\"86.2\", \"side\":\"SELL\", \"hash\":\"be4a6a875903fd8cd69fe15d90454095c1db3e45\", \"best_bid\":\"0.57\", \"best_ask\":\"0.58\"}], \"timestamp\":\"1785207905551\", \"event_type\":\"price_change\"}","received_at":"2026-07-28T03:05:06.325593Z","schema_version":"clob-market-ws.price_change.v1","sequence":null,"server_hash":null,"server_timestamp":"1785207905551","session_id":"3e519d9098404c15b234d96025eb1a2b","source":"clob_market_ws"},"received_at":"2026-07-28T03:05:06.325593Z","record_id":"e176ad3d59e406adb78b8d89a592ddae14f63cf3718f66a1cd7c092809683170","schema_fingerprint":"4aa3821a28b0b7c2400bc59aba4bcc0a76e971dadd19610d3ad38c768e124dc7","schema_version":"edge-lab-recorder.raw.v1","sequence":null,"source":"clob_market_ws"}
{"event_at":"2026-07-28T03:05:05.561000Z","event_fingerprint":"86f01f48f56bb953e08f2360d116998eef4f3b4da4c538befb470a40cb6f8d6f","payload":{"connection_id":"a6b55582af5f430fb37ad02bf0922475","event_at":"2026-07-28T03:05:05.561000Z","event_type":"price_change","frame_hash":"842be49cb9741dea9dfad531354357a54f2691d46a5b459a5523ca2abf90dce4","frame_index":0,"kind":"data","monotonic_ns":309889359195541,"payload":{"event_type":"price_change","market":"0x779291bef19b6709f61e9764a954aafe9ffae488d50ae674aabdcb4f248006d5","price_changes":[{"asset_id":"8761897749749422724209054078244794145777693856614463256546737399611489089783","best_ask":"0.58","best_bid":"0.57","hash":"7bf717e435757240dbfa564f80d8b2f5223950b7","price":"0.04","side":"BUY","size":"588.09"},{"asset_id":"14965588658799411272385430903075831224615961675357217884735713260981483529984","best_ask":"0.43","best_bid":"0.42","hash":"fd39f2937e0634e9566862afea730492a05203a9","price":"0.96","side":"SELL","size":"588.09"}],"timestamp":"1785207905561"},"payload_hash":"47ff63a06307d016b4ead6e97a363da2088bc0a3f23e153904f17452ac7339bb","raw_frame":"{\"market\":\"0x779291bef19b6709f61e9764a954aafe9ffae488d50ae674aabdcb4f248006d5\", \"price_changes\":[{\"asset_id\":\"8761897749749422724209054078244794145777693856614463256546737399611489089783\", \"price\":\"0.04\", \"size\":\"588.09\", \"side\":\"BUY\", \"hash\":\"7bf717e435757240dbfa564f80d8b2f5223950b7\", \"best_bid\":\"0.57\", \"best_ask\":\"0.58\"}, {\"asset_id\":\"14965588658799411272385430903075831224615961675357217884735713260981483529984\", \"price\":\"0.96\", \"size\":\"588.09\", \"side\":\"SELL\", \"hash\":\"fd39f2937e0634e9566862afea730492a05203a9\", \"best_bid\":\"0.42\", \"best_ask\":\"0.43\"}], \"timestamp\":\"1785207905561\", \"event_type\":\"price_change\"}","received_at":"2026-07-28T03:05:06.328783Z","schema_version":"clob-market-ws.price_change.v1","sequence":null,"server_hash":null,"server_timestamp":"1785207905561","session_id":"3e519d9098404c15b234d96025eb1a2b","source":"clob_market_ws"},"received_at":"2026-07-28T03:05:06.328783Z","record_id":"8ffb0b39d134ff865354d4aededcd91b81a3953bb80eec21b0fc87e278f12f1e","schema_fingerprint":"4aa3821a28b0b7c2400bc59aba4bcc0a76e971dadd19610d3ad38c768e124dc7","schema_version":"edge-lab-recorder.raw.v1","sequence":null,"source":"clob_market_ws"}
{"event_at":"2026-07-28T03:05:05.563000Z","event_fingerprint":"9b945d49c0ced9c14a5bbfb2231a2eb4d04799b4efbaf5b0f6193a024c2c741c","payload":{"connection_id":"a6b55582af5f430fb37ad02bf0922475","event_at":"2026-07-28T03:05:05.563000Z","event_type":"price_change","frame_hash":"05b2872715a3016150ce4f0c9a9be808e697c707bfe6765cfbe3c40f2aeb73a4","frame_index":0,"kind":"data","monotonic_ns":309889365970333,"payload":{"event_type":"price_change","market":"0x779291bef19b6709f61e9764a954aafe9ffae488d50ae674aabdcb4f248006d5","price_changes":[{"asset_id":"14965588658799411272385430903075831224615961675357217884735713260981483529984","best_ask":"0.43","best_bid":"0.42","hash":"b0b786a5b065b0019048e268b2651e083e80e46b","price":"0.38","side":"BUY","size":"139.2"},{"asset_id":"8761897749749422724209054078244794145777693856614463256546737399611489089783","best_ask":"0.58","best_bid":"0.57","hash":"c607d5cfc41cda56472ee7473694a344815bc717","price":"0.62","side":"SELL","size":"139.2"}],"timestamp":"1785207905563"},"payload_hash":"7b309f4dac185e5aeb5a3f2aedc0b6499304049370ed980b232a3112af590070","raw_frame":"{\"market\":\"0x779291bef19b6709f61e9764a954aafe9ffae488d50ae674aabdcb4f248006d5\", \"price_changes\":[{\"asset_id\":\"14965588658799411272385430903075831224615961675357217884735713260981483529984\", \"price\":\"0.38\", \"size\":\"139.2\", \"side\":\"BUY\", \"hash\":\"b0b786a5b065b0019048e268b2651e083e80e46b\", \"best_bid\":\"0.42\", \"best_ask\":\"0.43\"}, {\"asset_id\":\"8761897749749422724209054078244794145777693856614463256546737399611489089783\", \"price\":\"0.62\", \"size\":\"139.2\", \"side\":\"SELL\", \"hash\":\"c607d5cfc41cda56472ee7473694a344815bc717\", \"best_bid\":\"0.57\", \"best_ask\":\"0.58\"}], \"timestamp\":\"1785207905563\", \"event_type\":\"price_change\"}","received_at":"2026-07-28T03:05:06.335557Z","schema_version":"clob-market-ws.price_change.v1","sequence":null,"server_hash":null,"server_timestamp":"1785207905563","session_id":"3e519d9098404c15b234d96025eb1a2b","source":"clob_market_ws"},"received_at":"2026-07-28T03:05:06.335557Z","record_id":"c814a53cffbd7b7d1e9ada68f40f09310249de3b66068498649d1144cc1596a8","schema_fingerprint":"4aa3821a28b0b7c2400bc59aba4bcc0a76e971dadd19610d3ad38c768e124dc7","schema_version":"edge-lab-recorder.raw.v1","sequence":null,"source":"clob_market_ws"}
{"event_at":"2026-07-28T03:05:05.575000Z","event_fingerprint":"307ea3ba0e787482dc1fc93853efc33b0bfc921e706d9696d651c9df09f4986e","payload":{"connection_id":"a6b55582af5f430fb37ad02bf0922475","event_at":"2026-07-28T03:05:05.575000Z","event_type":"price_change","frame_hash":"1ab2e90afc14004693f4dba93cd56a19f502d89e2d35ccdcabcc6e93af94c09b","frame_index":0,"kind":"data","monotonic_ns":309889369596541,"payload":{"event_type":"price_change","market":"0x779291bef19b6709f61e9764a954aafe9ffae488d50ae674aabdcb4f248006d5","price_changes":[{"asset_id":"8761897749749422724209054078244794145777693856614463256546737399611489089783","best_ask":"0.58","best_bid":"0.57","hash":"76247addfef3688874e98c66c547f1bfa7fa79e2","price":"0.52","side":"BUY","size":"106"},{"asset_id":"14965588658799411272385430903075831224615961675357217884735713260981483529984","best_ask":"0.43","best_bid":"0.42","hash":"c1e3290bd531864f76aa0515dece5e21d1fbc6e3","price":"0.48","side":"SELL","size":"106"}],"timestamp":"1785207905575"},"payload_hash":"2dfc7a257423ca619e96dbfcf3774461678564f9d4bc079a3218e133567de989","raw_frame":"{\"market\":\"0x779291bef19b6709f61e9764a954aafe9ffae488d50ae674aabdcb4f248006d5\", \"price_changes\":[{\"asset_id\":\"8761897749749422724209054078244794145777693856614463256546737399611489089783\", \"price\":\"0.52\", \"size\":\"106\", \"side\":\"BUY\", \"hash\":\"76247addfef3688874e98c66c547f1bfa7fa79e2\", \"best_bid\":\"0.57\", \"best_ask\":\"0.58\"}, {\"asset_id\":\"14965588658799411272385430903075831224615961675357217884735713260981483529984\", \"price\":\"0.48\", \"size\":\"106\", \"side\":\"SELL\", \"hash\":\"c1e3290bd531864f76aa0515dece5e21d1fbc6e3\", \"best_bid\":\"0.42\", \"best_ask\":\"0.43\"}], \"timestamp\":\"1785207905575\", \"event_type\":\"price_change\"}","received_at":"2026-07-28T03:05:06.339183Z","schema_version":"clob-market-ws.price_change.v1","sequence":null,"server_hash":null,"server_timestamp":"1785207905575","session_id":"3e519d9098404c15b234d96025eb1a2b","source":"clob_market_ws"},"received_at":"2026-07-28T03:05:06.339183Z","record_id":"4fc560b5f1641cdf84188f720d10fc20dc5d4058983a89bd439f3082cc4f9ebb","schema_fingerprint":"4aa3821a28b0b7c2400bc59aba4bcc0a76e971dadd19610d3ad38c768e124dc7","schema_version":"edge-lab-recorder.raw.v1","sequence":null,"source":"clob_market_ws"}
{"event_at":"2026-07-28T03:05:05.579000Z","event_fingerprint":"04a9d0faa3e8a6e17d2e5d17140147d80ddc8620a1a65b41ebbbd4a533536a5b","payload":{"connection_id":"a6b55582af5f430fb37ad02bf0922475","event_at":"2026-07-28T03:05:05.579000Z","event_type":"price_change","frame_hash":"489641683bf86727c9e957230dac697e7cb800d363c503ce5ede232eee6b3665","frame_index":0,"kind":"data","monotonic_ns":309889372677625,"payload":{"event_type":"price_change","market":"0x779291bef19b6709f61e9764a954aafe9ffae488d50ae674aabdcb4f248006d5","price_changes":[{"asset_id":"8761897749749422724209054078244794145777693856614463256546737399611489089783","best_ask":"0.58","best_bid":"0.57","hash":"2931f39681affdf592a569181779fbf183523393","price":"0.01","side":"BUY","size":"5853.02"},{"asset_id":"14965588658799411272385430903075831224615961675357217884735713260981483529984","best_ask":"0.43","best_bid":"0.42","hash":"5fd219bd9f24f865fae18d7b95d86130f38b3666","price":"0.99","side":"SELL","size":"5853.02"}],"timestamp":"1785207905579"},"payload_hash":"bed2c833ef8aec368daacf1f71a731b6ff6ce68d40fb27a0acd0b79ec6524ef2","raw_frame":"{\"market\":\"0x779291bef19b6709f61e9764a954aafe9ffae488d50ae674aabdcb4f248006d5\", \"price_changes\":[{\"asset_id\":\"8761897749749422724209054078244794145777693856614463256546737399611489089783\", \"price\":\"0.01\", \"size\":\"5853.02\", \"side\":\"BUY\", \"hash\":\"2931f39681affdf592a569181779fbf183523393\", \"best_bid\":\"0.57\", \"best_ask\":\"0.58\"}, {\"asset_id\":\"14965588658799411272385430903075831224615961675357217884735713260981483529984\", \"price\":\"0.99\", \"size\":\"5853.02\", \"side\":\"SELL\", \"hash\":\"5fd219bd9f24f865fae18d7b95d86130f38b3666\", \"best_bid\":\"0.42\", \"best_ask\":\"0.43\"}], \"timestamp\":\"1785207905579\", \"event_type\":\"price_change\"}","received_at":"2026-07-28T03:05:06.342263Z","schema_version":"clob-market-ws.price_change.v1","sequence":null,"server_hash":null,"server_timestamp":"1785207905579","session_id":"3e519d9098404c15b234d96025eb1a2b","source":"clob_market_ws"},"received_at":"2026-07-28T03:05:06.342263Z","record_id":"03359d0204d65834c323a976165ae69e6fbb1c1115b188b3eb4f3206d59e92e6","schema_fingerprint":"4aa3821a28b0b7c2400bc59aba4bcc0a76e971dadd19610d3ad38c768e124dc7","schema_version":"edge-lab-recorder.raw.v1","sequence":null,"source":"clob_market_ws"}
{"event_at":"2026-07-28T03:05:05.579000Z","event_fingerprint":"ebbc27cb4829e92bc9a3c9c65e70c34766514864623df1f87b918b8757f242e9","payload":{"connection_id":"a6b55582af5f430fb37ad02bf0922475","event_at":"2026-07-28T03:05:05.579000Z","event_type":"price_change","frame_hash":"84c11f091ab57665b1bd5be5ceebbf9ad0ac3f2554783ab123e7809cd58bd6be","frame_index":0,"kind":"data","monotonic_ns":309889377034833,"payload":{"event_type":"price_change","market":"0x779291bef19b6709f61e9764a954aafe9ffae488d50ae674aabdcb4f248006d5","price_changes":[{"asset_id":"14965588658799411272385430903075831224615961675357217884735713260981483529984","best_ask":"0.43","best_bid":"0.42","hash":"8baf049cdb3d387d2988a02124f73f15a96e5a2a","price":"0.42","side":"BUY","size":"33.4"},{"asset_id":"8761897749749422724209054078244794145777693856614463256546737399611489089783","best_ask":"0.58","best_bid":"0.57","hash":"4134220da796f687ab8c0045a1276e429f3635d7","price":"0.58","side":"SELL","size":"33.4"}],"timestamp":"1785207905579"},"payload_hash":"fd39a503828fd98e921e8709f940aad31c34517168f3b9fb5cad73326ed3a524","raw_frame":"{\"market\":\"0x779291bef19b6709f61e9764a954aafe9ffae488d50ae674aabdcb4f248006d5\", \"price_changes\":[{\"asset_id\":\"14965588658799411272385430903075831224615961675357217884735713260981483529984\", \"price\":\"0.42\", \"size\":\"33.4\", \"side\":\"BUY\", \"hash\":\"8baf049cdb3d387d2988a02124f73f15a96e5a2a\", \"best_bid\":\"0.42\", \"best_ask\":\"0.43\"}, {\"asset_id\":\"8761897749749422724209054078244794145777693856614463256546737399611489089783\", \"price\":\"0.58\", \"size\":\"33.4\", \"side\":\"SELL\", \"hash\":\"4134220da796f687ab8c0045a1276e429f3635d7\", \"best_bid\":\"0.57\", \"best_ask\":\"0.58\"}], \"timestamp\":\"1785207905579\", \"event_type\":\"price_change\"}","received_at":"2026-07-28T03:05:06.346621Z","schema_version":"clob-market-ws.price_change.v1","sequence":null,"server_hash":null,"server_timestamp":"1785207905579","session_id":"3e519d9098404c15b234d96025eb1a2b","source":"clob_market_ws"},"received_at":"2026-07-28T03:05:06.346621Z","record_id":"0288339f4f2127f1fd7b10529d9a5e649ab98596d6970355f16b5afd9a42dd27","schema_fingerprint":"4aa3821a28b0b7c2400bc59aba4bcc0a76e971dadd19610d3ad38c768e124dc7","schema_version":"edge-lab-recorder.raw.v1","sequence":null,"source":"clob_market_ws"}
{"event_at":"2026-07-28T03:05:05.583000Z","event_fingerprint":"f8547309d7810467b7eeffe599cb4f40bd8bbe03642d1acddd062c33187619ea","payload":{"connection_id":"a6b55582af5f430fb37ad02bf0922475","event_at":"2026-07-28T03:05:05.583000Z","event_type":"price_change","frame_hash":"3e55b26f73c76e9ec294a0092190f88c8ed2c7da155dd871ebb469b518137e20","frame_index":0,"kind":"data","monotonic_ns":309889381338416,"payload":{"event_type":"price_change","market":"0x779291bef19b6709f61e9764a954aafe9ffae488d50ae674aabdcb4f248006d5","price_changes":[{"asset_id":"14965588658799411272385430903075831224615961675357217884735713260981483529984","best_ask":"0.43","best_bid":"0.42","hash":"f8501f26a078033521b9381ab15e889af9776c49","price":"0.42","side":"BUY","size":"46"},{"asset_id":"8761897749749422724209054078244794145777693856614463256546737399611489089783","best_ask":"0.58","best_bid":"0.57","hash":"16b7698679acd7188a7e78ae4840c3bb285e607f","price":"0.58","side":"SELL","size":"46"}],"timestamp":"1785207905583"},"payload_hash":"e039bc4848d1fcc4d55d140412ea9bfdb0073c257e6c8c00bb7dba04fb140909","raw_frame":"{\"market\":\"0x779291bef19b6709f61e9764a954aafe9ffae488d50ae674aabdcb4f248006d5\", \"price_changes\":[{\"asset_id\":\"14965588658799411272385430903075831224615961675357217884735713260981483529984\", \"price\":\"0.42\", \"size\":\"46\", \"side\":\"BUY\", \"hash\":\"f8501f26a078033521b9381ab15e889af9776c49\", \"best_bid\":\"0.42\", \"best_ask\":\"0.43\"}, {\"asset_id\":\"8761897749749422724209054078244794145777693856614463256546737399611489089783\", \"price\":\"0.58\", \"size\":\"46\", \"side\":\"SELL\", \"hash\":\"16b7698679acd7188a7e78ae4840c3bb285e607f\", \"best_bid\":\"0.57\", \"best_ask\":\"0.58\"}], \"timestamp\":\"1785207905583\", \"event_type\":\"price_change\"}","received_at":"2026-07-28T03:05:06.350925Z","schema_version":"clob-market-ws.price_change.v1","sequence":null,"server_hash":null,"server_timestamp":"1785207905583","session_id":"3e519d9098404c15b234d96025eb1a2b","source":"clob_market_ws"},"received_at":"2026-07-28T03:05:06.350925Z","record_id":"f41cbd1b037263b839fea565b32a7edbc5b8c606f78e029ffcea6ae5496d2c4e","schema_fingerprint":"4aa3821a28b0b7c2400bc59aba4bcc0a76e971dadd19610d3ad38c768e124dc7","schema_version":"edge-lab-recorder.raw.v1","sequence":null,"source":"clob_market_ws"}
{"event_at":"2026-07-28T03:05:05.585000Z","event_fingerprint":"cbb3a2cdfa3c6175608baaa585385fefb5260b1c0a0086d10afc3bd21d295cb3","payload":{"connection_id":"a6b55582af5f430fb37ad02bf0922475","event_at":"2026-07-28T03:05:05.585000Z","event_type":"price_change","frame_hash":"af751e86988f7da847bfde26099040fa09d4a9fb33685a575b300f300d74d127","frame_index":0,"kind":"data","monotonic_ns":309889385759083,"payload":{"event_type":"price_change","market":"0x779291bef19b6709f61e9764a954aafe9ffae488d50ae674aabdcb4f248006d5","price_changes":[{"asset_id":"8761897749749422724209054078244794145777693856614463256546737399611489089783","best_ask":"0.58","best_bid":"0.57","hash":"e51ac335da2c75723c5a6a584ec96e9c5a602e7c","price":"0.59","side":"SELL","size":"77"},{"asset_id":"14965588658799411272385430903075831224615961675357217884735713260981483529984","best_ask":"0.43","best_bid":"0.42","hash":"d7e141af84534e0c73d2f3c8af6e08c569f04fd8","price":"0.41","side":"BUY","size":"77"}],"timestamp":"1785207905585"},"payload_hash":"9a7a2db35ca067dd57c1e7dd0b6f78736cfd5b79b8f676b11ecd627e52058c70","raw_frame":"{\"market\":\"0x779291bef19b6709f61e9764a954aafe9ffae488d50ae674aabdcb4f248006d5\", \"price_changes\":[{\"asset_id\":\"8761897749749422724209054078244794145777693856614463256546737399611489089783\", \"price\":\"0.59\", \"size\":\"77\", \"side\":\"SELL\", \"hash\":\"e51ac335da2c75723c5a6a584ec96e9c5a602e7c\", \"best_bid\":\"0.57\", \"best_ask\":\"0.58\"}, {\"asset_id\":\"14965588658799411272385430903075831224615961675357217884735713260981483529984\", \"price\":\"0.41\", \"size\":\"77\", \"side\":\"BUY\", \"hash\":\"d7e141af84534e0c73d2f3c8af6e08c569f04fd8\", \"best_bid\":\"0.42\", \"best_ask\":\"0.43\"}], \"timestamp\":\"1785207905585\", \"event_type\":\"price_change\"}","received_at":"2026-07-28T03:05:06.355344Z","schema_version":"clob-market-ws.price_change.v1","sequence":null,"server_hash":null,"server_timestamp":"1785207905585","session_id":"3e519d9098404c15b234d96025eb1a2b","source":"clob_market_ws"},"received_at":"2026-07-28T03:05:06.355344Z","record_id":"e1682702866e1eb30b1e2e4a42253fe449ca7c6e33eddd75c6260416f9bfe149","schema_fingerprint":"4aa3821a28b0b7c2400bc59aba4bcc0a76e971dadd19610d3ad38c768e124dc7","schema_version":"edge-lab-recorder.raw.v1","sequence":null,"source":"clob_market_ws"}
{"event_at":"2026-07-28T03:05:05.585000Z","event_fingerprint":"fadef9147e6a9415556669fdaf6eaf4457c9eee7021534d96dd37a45f813c769","payload":{"connection_id":"a6b55582af5f430fb37ad02bf0922475","event_at":"2026-07-28T03:05:05.585000Z","event_type":"price_change","frame_hash":"fe81e1f4b9a410e10b55c950363092f9eca3f72a854a402e771616ce4aaf079f","frame_index":0,"kind":"data","monotonic_ns":309889390217000,"payload":{"event_type":"price_change","market":"0x779291bef19b6709f61e9764a954aafe9ffae488d50ae674aabdcb4f248006d5","price_changes":[{"asset_id":"14965588658799411272385430903075831224615961675357217884735713260981483529984","best_ask":"0.43","best_bid":"0.42","hash":"9d6e46e5194768e13796708b9e9525789b346f87","price":"0.4","side":"BUY","size":"76.6"},{"asset_id":"8761897749749422724209054078244794145777693856614463256546737399611489089783","best_ask":"0.58","best_bid":"0.57","hash":"84c142444142b5d7e33c9dfd619dc5e26c132cc7","price":"0.6","side":"SELL","size":"76.6"}],"timestamp":"1785207905585"},"payload_hash":"d3c558fd9f2afc956ae56f7f1f4520ea814b6ad3e312b5f1acc4ae099a139cca","raw_frame":"{\"market\":\"0x779291bef19b6709f61e9764a954aafe9ffae488d50ae674aabdcb4f248006d5\", \"price_changes\":[{\"asset_id\":\"14965588658799411272385430903075831224615961675357217884735713260981483529984\", \"price\":\"0.4\", \"size\":\"76.6\", \"side\":\"BUY\", \"hash\":\"9d6e46e5194768e13796708b9e9525789b346f87\", \"best_bid\":\"0.42\", \"best_ask\":\"0.43\"}, {\"asset_id\":\"8761897749749422724209054078244794145777693856614463256546737399611489089783\", \"price\":\"0.6\", \"size\":\"76.6\", \"side\":\"SELL\", \"hash\":\"84c142444142b5d7e33c9dfd619dc5e26c132cc7\", \"best_bid\":\"0.57\", \"best_ask\":\"0.58\"}], \"timestamp\":\"1785207905585\", \"event_type\":\"price_change\"}","received_at":"2026-07-28T03:05:06.359803Z","schema_version":"clob-market-ws.price_change.v1","sequence":null,"server_hash":null,"server_timestamp":"1785207905585","session_id":"3e519d9098404c15b234d96025eb1a2b","source":"clob_market_ws"},"received_at":"2026-07-28T03:05:06.359803Z","record_id":"1ec6dad34d1e0bc7b07e836ebf78835c7e890aff2bebf8676c4b6d98993e2c31","schema_fingerprint":"4aa3821a28b0b7c2400bc59aba4bcc0a76e971dadd19610d3ad38c768e124dc7","schema_version":"edge-lab-recorder.raw.v1","sequence":null,"source":"clob_market_ws"}
{"event_at":"2026-07-28T03:05:05.586000Z","event_fingerprint":"1d85524d9fe1209e7ec7d0561a3e04d7fca75591c7a1c44cf2160c67fc0b76c5","payload":{"connection_id":"a6b55582af5f430fb37ad02bf0922475","event_at":"2026-07-28T03:05:05.586000Z","event_type":"price_change","frame_hash":"0e3f5c4d1d5edf9eb0b3d4e3c234bfe40a118cd29f477e9fd689bbca4534070a","frame_index":0,"kind":"data","monotonic_ns":309889394507500,"payload":{"event_type":"price_change","market":"0x779291bef19b6709f61e9764a954aafe9ffae488d50ae674aabdcb4f248006d5","price_changes":[{"asset_id":"8761897749749422724209054078244794145777693856614463256546737399611489089783","best_ask":"0.58","best_bid":"0.57","hash":"32cdc44fad006eab771354021eeee1f480159dc7","price":"0.55","side":"BUY","size":"93.08"},{"asset_id":"14965588658799411272385430903075831224615961675357217884735713260981483529984","best_ask":"0.43","best_bid":"0.42","hash":"776a60c8f6e4ee656d36a5aed2e9a71be5787b82","price":"0.45","side":"SELL","size":"93.08"}],"timestamp":"1785207905586"},"payload_hash":"806ed9b8e7647451b22582285c0a7ff0b4beac82a811dc3097ed5b449659baf8","raw_frame":"{\"market\":\"0x779291bef19b6709f61e9764a954aafe9ffae488d50ae674aabdcb4f248006d5\", \"price_changes\":[{\"asset_id\":\"8761897749749422724209054078244794145777693856614463256546737399611489089783\", \"price\":\"0.55\", \"size\":\"93.08\", \"side\":\"BUY\", \"hash\":\"32cdc44fad006eab771354021eeee1f480159dc7\", \"best_bid\":\"0.57\", \"best_ask\":\"0.58\"}, {\"asset_id\":\"14965588658799411272385430903075831224615961675357217884735713260981483529984\", \"price\":\"0.45\", \"size\":\"93.08\", \"side\":\"SELL\", \"hash\":\"776a60c8f6e4ee656d36a5aed2e9a71be5787b82\", \"best_bid\":\"0.42\", \"best_ask\":\"0.43\"}], \"timestamp\":\"1785207905586\", \"event_type\":\"price_change\"}","received_at":"2026-07-28T03:05:06.364094Z","schema_version":"clob-market-ws.price_change.v1","sequence":null,"server_hash":null,"server_timestamp":"1785207905586","session_id":"3e519d9098404c15b234d96025eb1a2b","source":"clob_market_ws"},"received_at":"2026-07-28T03:05:06.364094Z","record_id":"6d8f96a5386fff1047eede7c33226f5c9d06cd208cb48c19564278d932e6ce2a","schema_fingerprint":"4aa3821a28b0b7c2400bc59aba4bcc0a76e971dadd19610d3ad38c768e124dc7","schema_version":"edge-lab-recorder.raw.v1","sequence":null,"source":"clob_market_ws"}
{"event_at":"2026-07-28T03:05:05.587000Z","event_fingerprint":"9b118368a8b69d6a1a10499c4317faf6e6ee6ad9b11e4a73397ba4cdea63c6fe","payload":{"connection_id":"a6b55582af5f430fb37ad02bf0922475","event_at":"2026-07-28T03:05:05.587000Z","event_type":"price_change","frame_hash":"6abbe87d088d6b162e2db9a6d32751a1fd6df2c3af9529e52db4f770a37486e9","frame_index":0,"kind":"data","monotonic_ns":309889398784625,"payload":{"event_type":"price_change","market":"0x779291bef19b6709f61e9764a954aafe9ffae488d50ae674aabdcb4f248006d5","price_changes":[{"asset_id":"14965588658799411272385430903075831224615961675357217884735713260981483529984","best_ask":"0.43","best_bid":"0.42","hash":"5098549e83b61db34bafd5a4cf2ebccb1711fe1c","price":"0.41","side":"BUY","size":"52"},{"asset_id":"8761897749749422724209054078244794145777693856614463256546737399611489089783","best_ask":"0.58","best_bid":"0.57","hash":"eed27853f40481175da0b28b0c466a186eab9e82","price":"0.59","side":"SELL","size":"52"}],"timestamp":"1785207905587"},"payload_hash":"22df32d3ec2e883bd490e1ff3e1eb1c8b4cc253575334c6821354c658c903dbe","raw_frame":"{\"market\":\"0x779291bef19b6709f61e9764a954aafe9ffae488d50ae674aabdcb4f248006d5\", \"price_changes\":[{\"asset_id\":\"14965588658799411272385430903075831224615961675357217884735713260981483529984\", \"price\":\"0.41\", \"size\":\"52\", \"side\":\"BUY\", \"hash\":\"5098549e83b61db34bafd5a4cf2ebccb1711fe1c\", \"best_bid\":\"0.42\", \"best_ask\":\"0.43\"}, {\"asset_id\":\"8761897749749422724209054078244794145777693856614463256546737399611489089783\", \"price\":\"0.59\", \"size\":\"52\", \"side\":\"SELL\", \"hash\":\"eed27853f40481175da0b28b0c466a186eab9e82\", \"best_bid\":\"0.57\", \"best_ask\":\"0.58\"}], \"timestamp\":\"1785207905587\", \"event_type\":\"price_change\"}","received_at":"2026-07-28T03:05:06.368371Z","schema_version":"clob-market-ws.price_change.v1","sequence":null,"server_hash":null,"server_timestamp":"1785207905587","session_id":"3e519d9098404c15b234d96025eb1a2b","source":"clob_market_ws"},"received_at":"2026-07-28T03:05:06.368371Z","record_id":"1ff39e0737d1006937f842c214eaa9ca571a704544f3c494180745e83539283b","schema_fingerprint":"4aa3821a28b0b7c2400bc59aba4bcc0a76e971dadd19610d3ad38c768e124dc7","schema_version":"edge-lab-recorder.raw.v1","sequence":null,"source":"clob_market_ws"}
{"event_at":"2026-07-28T03:05:05.600000Z","event_fingerprint":"50913f2087b2fde6cd4a52a151482f13c1b3ed57fc30a3ec75a45af6b08e3f11","payload":{"connection_id":"a6b55582af5f430fb37ad02bf0922475","event_at":"2026-07-28T03:05:05.600000Z","event_type":"price_change","frame_hash":"9021faa63dec34d318baccfb26294bb0b7a75e088f28010126008b4c84c50afb","frame_index":0,"kind":"data","monotonic_ns":309889403220750,"payload":{"event_type":"price_change","market":"0x779291bef19b6709f61e9764a954aafe9ffae488d50ae674aabdcb4f248006d5","price_changes":[{"asset_id":"8761897749749422724209054078244794145777693856614463256546737399611489089783","best_ask":"0.58","best_bid":"0.57","hash":"ae278f8ff5054deea5aed96fb482334e64fd7131","price":"0.55","side":"BUY","size":"78.08"},{"asset_id":"14965588658799411272385430903075831224615961675357217884735713260981483529984","best_ask":"0.43","best_bid":"0.42","hash":"346e96cabe67e2c36f92112417bbfb05241a1ef9","price":"0.45","side":"SELL","size":"78.08"}],"timestamp":"1785207905600"},"payload_hash":"463b249124075839831bbf52e0e2fc97d1e894c912ae040931036f1a4e29eefd","raw_frame":"{\"market\":\"0x779291bef19b6709f61e9764a954aafe9ffae488d50ae674aabdcb4f248006d5\", \"price_changes\":[{\"asset_id\":\"8761897749749422724209054078244794145777693856614463256546737399611489089783\", \"price\":\"0.55\", \"size\":\"78.08\", \"side\":\"BUY\", \"hash\":\"ae278f8ff5054deea5aed96fb482334e64fd7131\", \"best_bid\":\"0.57\", \"best_ask\":\"0.58\"}, {\"asset_id\":\"14965588658799411272385430903075831224615961675357217884735713260981483529984\", \"price\":\"0.45\", \"size\":\"78.08\", \"side\":\"SELL\", \"hash\":\"346e96cabe67e2c36f92112417bbfb05241a1ef9\", \"best_bid\":\"0.42\", \"best_ask\":\"0.43\"}], \"timestamp\":\"1785207905600\", \"event_type\":\"price_change\"}","received_at":"2026-07-28T03:05:06.372806Z","schema_version":"clob-market-ws.price_change.v1","sequence":null,"server_hash":null,"server_timestamp":"1785207905600","session_id":"3e519d9098404c15b234d96025eb1a2b","source":"clob_market_ws"},"received_at":"2026-07-28T03:05:06.372806Z","record_id":"87fbbcfd1d3310be16ef2e4ea4fb3678199f5fe1550ba58caaccd9c9f41062c0","schema_fingerprint":"4aa3821a28b0b7c2400bc59aba4bcc0a76e971dadd19610d3ad38c768e124dc7","schema_version":"edge-lab-recorder.raw.v1","sequence":null,"source":"clob_market_ws"}
