{"event_at":"2026-07-28T03:04:26.633000Z","event_fingerprint":"b0ee5f726278307ae5bf40326198f62fa82ac5d02099d9d5d5e92aecc13b6a6e","payload":{"connection_id":"a6b55582af5f430fb37ad02bf0922475","event_at":"2026-07-28T03:04:26.633000Z","event_type":"price_change","frame_hash":"386d3e8862b5575857ea5b14457767be43a42d9c9977724e485a911ab0a5798e","frame_index":0,"kind":"data","monotonic_ns":309849697333083,"payload":{"event_type":"price_change","market":"0x779291bef19b6709f61e9764a954aafe9ffae488d50ae674aabdcb4f248006d5","price_changes":[{"asset_id":"14965588658799411272385430903075831224615961675357217884735713260981483529984","best_ask":"0.41","best_bid":"0.4","hash":"c33f559c3c5d36bdb40064d15458435fdc8225f6","price":"0.39","side":"BUY","size":"113.6"},{"asset_id":"8761897749749422724209054078244794145777693856614463256546737399611489089783","best_ask":"0.6","best_bid":"0.59","hash":"63b58b2abc23ea1715473777adf18681e4b2ee7c","price":"0.61","side":"SELL","size":"113.6"}],"timestamp":"1785207866633"},"payload_hash":"aea3846841ce11627f482c43d4a65aac9b1adebff70cb8abda4a5c74ec032ddf","raw_frame":"{\"market\":\"0x779291bef19b6709f61e9764a954aafe9ffae488d50ae674aabdcb4f248006d5\", \"price_changes\":[{\"asset_id\":\"14965588658799411272385430903075831224615961675357217884735713260981483529984\", \"price\":\"0.39\", \"size\":\"113.6\", \"side\":\"BUY\", \"hash\":\"c33f559c3c5d36bdb40064d15458435fdc8225f6\", \"best_bid\":\"0.4\", \"best_ask\":\"0.41\"}, {\"asset_id\":\"8761897749749422724209054078244794145777693856614463256546737399611489089783\", \"price\":\"0.61\", \"size\":\"113.6\", \"side\":\"SELL\", \"hash\":\"63b58b2abc23ea1715473777adf18681e4b2ee7c\", \"best_bid\":\"0.59\", \"best_ask\":\"0.6\"}], \"timestamp\":\"1785207866633\", \"event_type\":\"price_change\"}","received_at":"2026-07-28T03:04:26.671391Z","schema_version":"clob-market-ws.price_change.v1","sequence":null,"server_hash":null,"server_timestamp":"1785207866633","session_id":"3e519d9098404c15b234d96025eb1a2b","source":"clob_market_ws"},"received_at":"2026-07-28T03:04:26.671391Z","record_id":"39d616b19843316f97ddbe66e3122711411c4450ad87490b60f45e63c3172821","schema_fingerprint":"4aa3821a28b0b7c2400bc59aba4bcc0a76e971dadd19610d3ad38c768e124dc7","schema_version":"edge-lab-recorder.raw.v1","sequence":null,"source":"clob_market_ws"}
{"event_at":"2026-07-28T03:04:26.634000Z","event_fingerprint":"aec07903170ddc13ab06445aa411db47a718a899cd4331409bcb97f0e60d3e97","payload":{"connection_id":"a6b55582af5f430fb37ad02bf0922475","event_at":"2026-07-28T03:04:26.634000Z","event_type":"price_change","frame_hash":"232ccde2ac3162e35ee4111ca370b7f3b0909affc6a7afb3b36d4c88c0329528","frame_index":0,"kind":"data","monotonic_ns":309849699478208,"payload":{"event_type":"price_change","market":"0x779291bef19b6709f61e9764a954aafe9ffae488d50ae674aabdcb4f248006d5","price_changes":[{"asset_id":"8761897749749422724209054078244794145777693856614463256546737399611489089783","best_ask":"0.6","best_bid":"0.59","hash":"02b51ed750fbe773320d9cf757d11f321b92e581","price":"0.58","side":"BUY","size":"81.2"},{"asset_id":"14965588658799411272385430903075831224615961675357217884735713260981483529984","best_ask":"0.41","best_bid":"0.4","hash":"18d1dce32a2383787ea5dc84b1727d36c7651191","price":"0.42","side":"SELL","size":"81.2"}],"timestamp":"1785207866634"},"payload_hash":"41a3b8f13deca468399cf8030dac4f62d07d4d78bf2813d59df02b4905ce5690","raw_frame":"{\"market\":\"0x779291bef19b6709f61e9764a954aafe9ffae488d50ae674aabdcb4f248006d5\", \"price_changes\":[{\"asset_id\":\"8761897749749422724209054078244794145777693856614463256546737399611489089783\", \"price\":\"0.58\", \"size\":\"81.2\", \"side\":\"BUY\", \"hash\":\"02b51ed750fbe773320d9cf757d11f321b92e581\", \"best_bid\":\"0.59\", \"best_ask\":\"0.6\"}, {\"asset_id\":\"14965588658799411272385430903075831224615961675357217884735713260981483529984\", \"price\":\"0.42\", \"size\":\"81.2\", \"side\":\"SELL\", \"hash\":\"18d1dce32a2383787ea5dc84b1727d36c7651191\", \"best_bid\":\"0.4\", \"best_ask\":\"0.41\"}], \"timestamp\":\"1785207866634\", \"event_type\":\"price_change\"}","received_at":"2026-07-28T03:04:26.673536Z","schema_version":"clob-market-ws.price_change.v1","sequence":null,"server_hash":null,"server_timestamp":"1785207866634","session_id":"3e519d9098404c15b234d96025eb1a2b","source":"clob_market_ws"},"received_at":"2026-07-28T03:04:26.673536Z","record_id":"93178a8363d6f9c19e32f2994a6b85694c0aadaa762e53f312206c9d74c1718f","schema_fingerprint":"4aa3821a28b0b7c2400bc59aba4bcc0a76e971dadd19610d3ad38c768e124dc7","schema_version":"edge-lab-recorder.raw.v1","sequence":null,"source":"clob_market_ws"}
{"event_at":"2026-07-28T03:04:26.642000Z","event_fingerprint":"ba3169bbb87dca8bda3280a24de102392183cde97bb8a24f0cc4c0cac549276d","payload":{"connection_id":"a6b55582af5f430fb37ad02bf0922475","event_at":"2026-07-28T03:04:26.642000Z","event_type":"price_change","frame_hash":"7bbb4220cb65901ea2f7cf0e1cdde687c4c42dce4ee06b824cb1b898ee1eb701","frame_index":0,"kind":"data","monotonic_ns":309849700974666,"payload":{"event_type":"price_change","market":"0x779291bef19b6709f61e9764a954aafe9ffae488d50ae674aabdcb4f248006d5","price_changes":[{"asset_id":"8761897749749422724209054078244794145777693856614463256546737399611489089783","best_ask":"0.6","best_bid":"0.59","hash":"320545a9729399ea98b07c983dd48771ead79fe1","price":"0.59","side":"BUY","size":"30"},{"asset_id":"14965588658799411272385430903075831224615961675357217884735713260981483529984","best_ask":"0.41","best_bid":"0.4","hash":"41837a1a5a5890f1f1f5d975742eb626a5b1fc40","price":"0.41","side":"SELL","size":"30"}],"timestamp":"1785207866642"},"payload_hash":"3019060ffa1af719665c72c82e8dd3aae03db65cfdebee7362fdff72ec7a86d6","raw_frame":"{\"market\":\"0x779291bef19b6709f61e9764a954aafe9ffae488d50ae674aabdcb4f248006d5\", \"price_changes\":[{\"asset_id\":\"8761897749749422724209054078244794145777693856614463256546737399611489089783\", \"price\":\"0.59\", \"size\":\"30\", \"side\":\"BUY\", \"hash\":\"320545a9729399ea98b07c983dd48771ead79fe1\", \"best_bid\":\"0.59\", \"best_ask\":\"0.6\"}, {\"asset_id\":\"14965588658799411272385430903075831224615961675357217884735713260981483529984\", \"price\":\"0.41\", \"size\":\"30\", \"side\":\"SELL\", \"hash\":\"41837a1a5a5890f1f1f5d975742eb626a5b1fc40\", \"best_bid\":\"0.4\", \"best_ask\":\"0.41\"}], \"timestamp\":\"1785207866642\", \"event_type\":\"price_change\"}","received_at":"2026-07-28T03:04:26.675033Z","schema_version":"clob-market-ws.price_change.v1","sequence":null,"server_hash":null,"server_timestamp":"1785207866642","session_id":"3e519d9098404c15b234d96025eb1a2b","source":"clob_market_ws"},"received_at":"2026-07-28T03:04:26.675033Z","record_id":"cef425b19dfc3643513955aaeb615ce547f904b227a8d5e3d69dd324e64ca1b4","schema_fingerprint":"4aa3821a28b0b7c2400bc59aba4bcc0a76e971dadd19610d3ad38c768e124dc7","schema_version":"edge-lab-recorder.raw.v1","sequence":null,"source":"clob_market_ws"}
{"event_at":"2026-07-28T03:04:26.646000Z","event_fingerprint":"4222c4ecd330e767891f5a90cf2540b8edf22a64335427cffdb215a2f9d52ae8","payload":{"connection_id":"a6b55582af5f430fb37ad02bf0922475","event_at":"2026-07-28T03:04:26.646000Z","event_type":"price_change","frame_hash":"64a637e9948f75a66018f347523717ca94f3304b1865564dc78a2dcf29fca34b","frame_index":0,"kind":"data","monotonic_ns":309849702436583,"payload":{"event_type":"price_change","market":"0x779291bef19b6709f61e9764a954aafe9ffae488d50ae674aabdcb4f248006d5","price_changes":[{"asset_id":"8761897749749422724209054078244794145777693856614463256546737399611489089783","best_ask":"0.6","best_bid":"0.59","hash":"5255e3da9486e13d953c19879d17941bfb619cc1","price":"0.36","side":"BUY","size":"84"},{"asset_id":"14965588658799411272385430903075831224615961675357217884735713260981483529984","best_ask":"0.41","best_bid":"0.4","hash":"23ce0259eaf96cafcc325afb415cb7e8621734b1","price":"0.64","side":"SELL","size":"84"}],"timestamp":"1785207866646"},"payload_hash":"c5d83aed97a7c133c30a27b214ba2d3af063646c359bc6f09e5465d567c2c6b3","raw_frame":"{\"market\":\"0x779291bef19b6709f61e9764a954aafe9ffae488d50ae674aabdcb4f248006d5\", \"price_changes\":[{\"asset_id\":\"8761897749749422724209054078244794145777693856614463256546737399611489089783\", \"price\":\"0.36\", \"size\":\"84\", \"side\":\"BUY\", \"hash\":\"5255e3da9486e13d953c19879d17941bfb619cc1\", \"best_bid\":\"0.59\", \"best_ask\":\"0.6\"}, {\"asset_id\":\"14965588658799411272385430903075831224615961675357217884735713260981483529984\", \"price\":\"0.64\", \"size\":\"84\", \"side\":\"SELL\", \"hash\":\"23ce0259eaf96cafcc325afb415cb7e8621734b1\", \"best_bid\":\"0.4\", \"best_ask\":\"0.41\"}], \"timestamp\":\"1785207866646\", \"event_type\":\"price_change\"}","received_at":"2026-07-28T03:04:26.676495Z","schema_version":"clob-market-ws.price_change.v1","sequence":null,"server_hash":null,"server_timestamp":"1785207866646","session_id":"3e519d9098404c15b234d96025eb1a2b","source":"clob_market_ws"},"received_at":"2026-07-28T03:04:26.676495Z","record_id":"8b8dc39bca64b6ede3e78539562bcdcb0afe94eb329cce63016c81238db6f671","schema_fingerprint":"4aa3821a28b0b7c2400bc59aba4bcc0a76e971dadd19610d3ad38c768e124dc7","schema_version":"edge-lab-recorder.raw.v1","sequence":null,"source":"clob_market_ws"}
{"event_at":"2026-07-28T03:04:26.647000Z","event_fingerprint":"bc80536fa90ffe363957955c970b115cb54dc14f732d6d1dae79bb656adaa0ea","payload":{"connection_id":"a6b55582af5f430fb37ad02bf0922475","event_at":"2026-07-28T03:04:26.647000Z","event_type":"price_change","frame_hash":"33b727905cf34673e474294b4bd8da8fd088bf2d297f872d4336f94bdb8ff766","frame_index":0,"kind":"data","monotonic_ns":309849703886416,"payload":{"event_type":"price_change","market":"0x779291bef19b6709f61e9764a954aafe9ffae488d50ae674aabdcb4f248006d5","price_changes":[{"asset_id":"8761897749749422724209054078244794145777693856614463256546737399611489089783","best_ask":"0.6","best_bid":"0.59","hash":"86fe55e0653d7b0d0e07279a6f704e6a971aed4d","price":"0.56","side":"BUY","size":"393.3"},{"asset_id":"14965588658799411272385430903075831224615961675357217884735713260981483529984","best_ask":"0.41","best_bid":"0.4","hash":"fd21fc16626e2762f4fee16dcd90849acf90dc98","price":"0.44","side":"SELL","size":"393.3"}],"timestamp":"1785207866647"},"payload_hash":"689e6e9814983a0d85541be86069134f9aee882462dab4a87b497d56e42bac67","raw_frame":"{\"market\":\"0x779291bef19b6709f61e9764a954aafe9ffae488d50ae674aabdcb4f248006d5\", \"price_changes\":[{\"asset_id\":\"8761897749749422724209054078244794145777693856614463256546737399611489089783\", \"price\":\"0.56\", \"size\":\"393.3\", \"side\":\"BUY\", \"hash\":\"86fe55e0653d7b0d0e07279a6f704e6a971aed4d\", \"best_bid\":\"0.59\", \"best_ask\":\"0.6\"}, {\"asset_id\":\"14965588658799411272385430903075831224615961675357217884735713260981483529984\", \"price\":\"0.44\", \"size\":\"393.3\", \"side\":\"SELL\", \"hash\":\"fd21fc16626e2762f4fee16dcd90849acf90dc98\", \"best_bid\":\"0.4\", \"best_ask\":\"0.41\"}], \"timestamp\":\"1785207866647\", \"event_type\":\"price_change\"}","received_at":"2026-07-28T03:04:26.677944Z","schema_version":"clob-market-ws.price_change.v1","sequence":null,"server_hash":null,"server_timestamp":"1785207866647","session_id":"3e519d9098404c15b234d96025eb1a2b","source":"clob_market_ws"},"received_at":"2026-07-28T03:04:26.677944Z","record_id":"9771c50900dcefcd28537606b85a07ae16d404b2f72bcd392c1ecad742e02111","schema_fingerprint":"4aa3821a28b0b7c2400bc59aba4bcc0a76e971dadd19610d3ad38c768e124dc7","schema_version":"edge-lab-recorder.raw.v1","sequence":null,"source":"clob_market_ws"}
{"event_at":"2026-07-28T03:04:26.647000Z","event_fingerprint":"44bf5960af01b39ffa844b8a96f6e540c02e4f1f1d9efb61172d6ae29eff946c","payload":{"connection_id":"a6b55582af5f430fb37ad02bf0922475","event_at":"2026-07-28T03:04:26.647000Z","event_type":"price_change","frame_hash":"6d6faf37835ee4be4cd0b3d79e5ba8106bcce337c1f6b725ecf99caea5bdcb66","frame_index":0,"kind":"data","monotonic_ns":309849705484958,"payload":{"event_type":"price_change","market":"0x779291bef19b6709f61e9764a954aafe9ffae488d50ae674aabdcb4f248006d5","price_changes":[{"asset_id":"14965588658799411272385430903075831224615961675357217884735713260981483529984","best_ask":"0.41","best_bid":"0.4","hash":"4d8b9f9a2a65775c92acfc75b10f1cbf182cc8c3","price":"0.39","side":"BUY","size":"98.6"},{"asset_id":"8761897749749422724209054078244794145777693856614463256546737399611489089783","best_ask":"0.6","best_bid":"0.59","hash":"e1b96405f1b3ed6a26853ab2618a254427bc65b5","price":"0.61","side":"SELL","size":"98.6"}],"timestamp":"1785207866647"},"payload_hash":"0c1b64290b6674ec26ce91ac8a1dd932fb03fd577004fa4b129d16de48a17cb6","raw_frame":"{\"market\":\"0x779291bef19b6709f61e9764a954aafe9ffae488d50ae674aabdcb4f248006d5\", \"price_changes\":[{\"asset_id\":\"14965588658799411272385430903075831224615961675357217884735713260981483529984\", \"price\":\"0.39\", \"size\":\"98.6\", \"side\":\"BUY\", \"hash\":\"4d8b9f9a2a65775c92acfc75b10f1cbf182cc8c3\", \"best_bid\":\"0.4\", \"best_ask\":\"0.41\"}, {\"asset_id\":\"8761897749749422724209054078244794145777693856614463256546737399611489089783\", \"price\":\"0.61\", \"size\":\"98.6\", \"side\":\"SELL\", \"hash\":\"e1b96405f1b3ed6a26853ab2618a254427bc65b5\", \"best_bid\":\"0.59\", \"best_ask\":\"0.6\"}], \"timestamp\":\"1785207866647\", \"event_type\":\"price_change\"}","received_at":"2026-07-28T03:04:26.679542Z","schema_version":"clob-market-ws.price_change.v1","sequence":null,"server_hash":null,"server_timestamp":"1785207866647","session_id":"3e519d9098404c15b234d96025eb1a2b","source":"clob_market_ws"},"received_at":"2026-07-28T03:04:26.679542Z","record_id":"23c3276eea721385d095ba3232d47da2df43fa4125b4d8d658e6c8809545e804","schema_fingerprint":"4aa3821a28b0b7c2400bc59aba4bcc0a76e971dadd19610d3ad38c768e124dc7","schema_version":"edge-lab-recorder.raw.v1","sequence":null,"source":"clob_market_ws"}
{"event_at":"2026-07-28T03:04:26.647000Z","event_fingerprint":"1cccd251b4c04df0972963bf4ce539dedb580e559e56ab6c822e88cb807b13aa","payload":{"connection_id":"a6b55582af5f430fb37ad02bf0922475","event_at":"2026-07-28T03:04:26.647000Z","event_type":"price_change","frame_hash":"27d5e7207e58cec685bcd715030c1450175593ee93b9512751b42a84283dc1f6","frame_index":0,"kind":"data","monotonic_ns":309849706929541,"payload":{"event_type":"price_change","market":"0x779291bef19b6709f61e9764a954aafe9ffae488d50ae674aabdcb4f248006d5","price_changes":[{"asset_id":"8761897749749422724209054078244794145777693856614463256546737399611489089783","best_ask":"0.6","best_bid":"0.59","hash":"197534bfc4e6b1fb7fcb0a5b99223feff6bf947f","price":"0.53","side":"BUY","size":"80"},{"asset_id":"14965588658799411272385430903075831224615961675357217884735713260981483529984","best_ask":"0.41","best_bid":"0.4","hash":"56f6a10f9dbb8ec3e97d20d33b0663edf37315a8","price":"0.47","side":"SELL","size":"80"}],"timestamp":"1785207866647"},"payload_hash":"dd1fba4900e0fbebe8d567c9dc0d02d2ed848ce74b3cc262e43f0fa6938cb994","raw_frame":"{\"market\":\"0x779291bef19b6709f61e9764a954aafe9ffae488d50ae674aabdcb4f248006d5\", \"price_changes\":[{\"asset_id\":\"8761897749749422724209054078244794145777693856614463256546737399611489089783\", \"price\":\"0.53\", \"size\":\"80\", \"side\":\"BUY\", \"hash\":\"197534bfc4e6b1fb7fcb0a5b99223feff6bf947f\", \"best_bid\":\"0.59\", \"best_ask\":\"0.6\"}, {\"asset_id\":\"14965588658799411272385430903075831224615961675357217884735713260981483529984\", \"price\":\"0.47\", \"size\":\"80\", \"side\":\"SELL\", \"hash\":\"56f6a10f9dbb8ec3e97d20d33b0663edf37315a8\", \"best_bid\":\"0.4\", \"best_ask\":\"0.41\"}], \"timestamp\":\"1785207866647\", \"event_type\":\"price_change\"}","received_at":"2026-07-28T03:04:26.680986Z","schema_version":"clob-market-ws.price_change.v1","sequence":null,"server_hash":null,"server_timestamp":"1785207866647","session_id":"3e519d9098404c15b234d96025eb1a2b","source":"clob_market_ws"},"received_at":"2026-07-28T03:04:26.680986Z","record_id":"ef98427ac0b8bc012039dd0fbb9f26a532169446ca53d2f4a185ef8b731cc25d","schema_fingerprint":"4aa3821a28b0b7c2400bc59aba4bcc0a76e971dadd19610d3ad38c768e124dc7","schema_version":"edge-lab-recorder.raw.v1","sequence":null,"source":"clob_market_ws"}
{"event_at":"2026-07-28T03:04:26.647000Z","event_fingerprint":"950fec2d1c57ffa466c48b2bcde13e0c29a6ee1abd381e4b0a49ec479bf9539e","payload":{"connection_id":"a6b55582af5f430fb37ad02bf0922475","event_at":"2026-07-28T03:04:26.647000Z","event_type":"price_change","frame_hash":"83814a31d7ca420132484af62f0bad5f29dfc91ab252a3506603d089797ebe82","frame_index":0,"kind":"data","monotonic_ns":309849708360541,"payload":{"event_type":"price_change","market":"0x779291bef19b6709f61e9764a954aafe9ffae488d50ae674aabdcb4f248006d5","price_changes":[{"asset_id":"14965588658799411272385430903075831224615961675357217884735713260981483529984","best_ask":"0.41","best_bid":"0.4","hash":"71b2cea035a35e69623463a8b8f8673480e41771","price":"0.38","side":"BUY","size":"99"},{"asset_id":"8761897749749422724209054078244794145777693856614463256546737399611489089783","best_ask":"0.6","best_bid":"0.59","hash":"a4ab4767ea72d7e22e6937ea2c20af61d5f2f5fc","price":"0.62","side":"SELL","size":"99"}],"timestamp":"1785207866647"},"payload_hash":"5ae51cf666bc09b2b73d5e0447b4b67e524908cc99d1c4c818cc5d1b58f989ca","raw_frame":"{\"market\":\"0x779291bef19b6709f61e9764a954aafe9ffae488d50ae674aabdcb4f248006d5\", \"price_changes\":[{\"asset_id\":\"14965588658799411272385430903075831224615961675357217884735713260981483529984\", \"price\":\"0.38\", \"size\":\"99\", \"side\":\"BUY\", \"hash\":\"71b2cea035a35e69623463a8b8f8673480e41771\", \"best_bid\":\"0.4\", \"best_ask\":\"0.41\"}, {\"asset_id\":\"8761897749749422724209054078244794145777693856614463256546737399611489089783\", \"price\":\"0.62\", \"size\":\"99\", \"side\":\"SELL\", \"hash\":\"a4ab4767ea72d7e22e6937ea2c20af61d5f2f5fc\", \"best_bid\":\"0.59\", \"best_ask\":\"0.6\"}], \"timestamp\":\"1785207866647\", \"event_type\":\"price_change\"}","received_at":"2026-07-28T03:04:26.682417Z","schema_version":"clob-market-ws.price_change.v1","sequence":null,"server_hash":null,"server_timestamp":"1785207866647","session_id":"3e519d9098404c15b234d96025eb1a2b","source":"clob_market_ws"},"received_at":"2026-07-28T03:04:26.682417Z","record_id":"354ef1417db4125139bd563728b04aa5e55d25d3aaccf2b644f60c22e1d42771","schema_fingerprint":"4aa3821a28b0b7c2400bc59aba4bcc0a76e971dadd19610d3ad38c768e124dc7","schema_version":"edge-lab-recorder.raw.v1","sequence":null,"source":"clob_market_ws"}
{"event_at":"2026-07-28T03:04:26.648000Z","event_fingerprint":"5f1d1d4e6981b74df6965fffc4377bcfc3aa46711e45e184683555d697ffdd45","payload":{"connection_id":"a6b55582af5f430fb37ad02bf0922475","event_at":"2026-07-28T03:04:26.648000Z","event_type":"price_change","frame_hash":"5d3a14d46dcb9b21b547a52d35fde603e60d2cd4b336d13b7e7f015a9cc68cbd","frame_index":0,"kind":"data","monotonic_ns":309849709786291,"payload":{"event_type":"price_change","market":"0x779291bef19b6709f61e9764a954aafe9ffae488d50ae674aabdcb4f248006d5","price_changes":[{"asset_id":"14965588658799411272385430903075831224615961675357217884735713260981483529984","best_ask":"0.41","best_bid":"0.4","hash":"e07292294a6aa5290cb6b9baf1fd64c8860a4844","price":"0.39","side":"BUY","size":"47.6"},{"asset_id":"8761897749749422724209054078244794145777693856614463256546737399611489089783","best_ask":"0.6","best_bid":"0.59","hash":"75fa59dc3e8b2378a8546333d3329da9ba011e79","price":"0.61","side":"SELL","size":"47.6"}],"timestamp":"1785207866648"},"payload_hash":"51696a8aebb50bcf44675475db5b9f5d35ce3fadcd1924a470a7c981ad9c2a2c","raw_frame":"{\"market\":\"0x779291bef19b6709f61e9764a954aafe9ffae488d50ae674aabdcb4f248006d5\", \"price_changes\":[{\"asset_id\":\"14965588658799411272385430903075831224615961675357217884735713260981483529984\", \"price\":\"0.39\", \"size\":\"47.6\", \"side\":\"BUY\", \"hash\":\"e07292294a6aa5290cb6b9baf1fd64c8860a4844\", \"best_bid\":\"0.4\", \"best_ask\":\"0.41\"}, {\"asset_id\":\"8761897749749422724209054078244794145777693856614463256546737399611489089783\", \"price\":\"0.61\", \"size\":\"47.6\", \"side\":\"SELL\", \"hash\":\"75fa59dc3e8b2378a8546333d3329da9ba011e79\", \"best_bid\":\"0.59\", \"best_ask\":\"0.6\"}], \"timestamp\":\"1785207866648\", \"event_type\":\"price_change\"}","received_at":"2026-07-28T03:04:26.683843Z","schema_version":"clob-market-ws.price_change.v1","sequence":null,"server_hash":null,"server_timestamp":"1785207866648","session_id":"3e519d9098404c15b234d96025eb1a2b","source":"clob_market_ws"},"received_at":"2026-07-28T03:04:26.683843Z","record_id":"2721aac6029a49f1d63ed32caaa2998a6206b45e67d10090268b17328b79a02c","schema_fingerprint":"4aa3821a28b0b7c2400bc59aba4bcc0a76e971dadd19610d3ad38c768e124dc7","schema_version":"edge-lab-recorder.raw.v1","sequence":null,"source":"clob_market_ws"}
{"event_at":"2026-07-28T03:04:26.648000Z","event_fingerprint":"191f4693158102760bbb47e9f135128191aa7f600b2df67accf45786c60d6430","payload":{"connection_id":"a6b55582af5f430fb37ad02bf0922475","event_at":"2026-07-28T03:04:26.648000Z","event_type":"price_change","frame_hash":"e7f5162498bf8dc575edd384b59c251dc8e287657dc26665f967e43c694fe56e","frame_index":0,"kind":"data","monotonic_ns":309849711218541,"payload":{"event_type":"price_change","market":"0x779291bef19b6709f61e9764a954aafe9ffae488d50ae674aabdcb4f248006d5","price_changes":[{"asset_id":"14965588658799411272385430903075831224615961675357217884735713260981483529984","best_ask":"0.41","best_bid":"0.4","hash":"1bb96140d7da0dcafd2eef64a354283edb513df9","price":"0.4","side":"BUY","size":"27.6"},{"asset_id":"8761897749749422724209054078244794145777693856614463256546737399611489089783","best_ask":"0.6","best_bid":"0.59","hash":"669a81427a5e49faa5d0f3837910abcdac03b0cb","price":"0.6","side":"SELL","size":"27.6"}],"timestamp":"1785207866648"},"payload_hash":"6e583101f219b17030e8781fde0b1967f520bc8b172faa8d3f3c4e40392ea8a2","raw_frame":"{\"market\":\"0x779291bef19b6709f61e9764a954aafe9ffae488d50ae674aabdcb4f248006d5\", \"price_changes\":[{\"asset_id\":\"14965588658799411272385430903075831224615961675357217884735713260981483529984\", \"price\":\"0.4\", \"size\":\"27.6\", \"side\":\"BUY\", \"hash\":\"1bb96140d7da0dcafd2eef64a354283edb513df9\", \"best_bid\":\"0.4\", \"best_ask\":\"0.41\"}, {\"asset_id\":\"8761897749749422724209054078244794145777693856614463256546737399611489089783\", \"price\":\"0.6\", \"size\":\"27.6\", \"side\":\"SELL\", \"hash\":\"669a81427a5e49faa5d0f3837910abcdac03b0cb\", \"best_bid\":\"0.59\", \"best_ask\":\"0.6\"}], \"timestamp\":\"1785207866648\", \"event_type\":\"price_change\"}","received_at":"2026-07-28T03:04:26.685274Z","schema_version":"clob-market-ws.price_change.v1","sequence":null,"server_hash":null,"server_timestamp":"1785207866648","session_id":"3e519d9098404c15b234d96025eb1a2b","source":"clob_market_ws"},"received_at":"2026-07-28T03:04:26.685274Z","record_id":"6df87337205d08407322fff6eaad185da07a985998d5d12888e5771435b12a73","schema_fingerprint":"4aa3821a28b0b7c2400bc59aba4bcc0a76e971dadd19610d3ad38c768e124dc7","schema_version":"edge-lab-recorder.raw.v1","sequence":null,"source":"clob_market_ws"}
{"event_at":"2026-07-28T03:04:26.648000Z","event_fingerprint":"71acd70108383e7517c3ae4821952ff0e64aae02949461d0014b246ccf132e9b","payload":{"connection_id":"a6b55582af5f430fb37ad02bf0922475","event_at":"2026-07-28T03:04:26.648000Z","event_type":"price_change","frame_hash":"02fa9a42a081ece23bd7366c12c52fdb36aa5684aef6fa42c453df30cc951dd9","frame_index":0,"kind":"data","monotonic_ns":309849712645416,"payload":{"event_type":"price_change","market":"0x779291bef19b6709f61e9764a954aafe9ffae488d50ae674aabdcb4f248006d5","price_changes":[{"asset_id":"8761897749749422724209054078244794145777693856614463256546737399611489089783","best_ask":"0.6","best_bid":"0.59","hash":"0571b56d093cebca03ed233eea25cd707e4b4ceb","price":"0.49","side":"BUY","size":"238"},{"asset_id":"14965588658799411272385430903075831224615961675357217884735713260981483529984","best_ask":"0.41","best_bid":"0.4","hash":"98d04e585191b793c34f8b2b34de062473f5ed2b","price":"0.51","side":"SELL","size":"238"}],"timestamp":"1785207866648"},"payload_hash":"0b7a8229bceb8267a15c0491221bdcdff485d20c988d8ef97cdad7700c6c9674","raw_frame":"{\"market\":\"0x779291bef19b6709f61e9764a954aafe9ffae488d50ae674aabdcb4f248006d5\", \"price_changes\":[{\"asset_id\":\"8761897749749422724209054078244794145777693856614463256546737399611489089783\", \"price\":\"0.49\", \"size\":\"238\", \"side\":\"BUY\", \"hash\":\"0571b56d093cebca03ed233eea25cd707e4b4ceb\", \"best_bid\":\"0.59\", \"best_ask\":\"0.6\"}, {\"asset_id\":\"14965588658799411272385430903075831224615961675357217884735713260981483529984\", \"price\":\"0.51\", \"size\":\"238\", \"side\":\"SELL\", \"hash\":\"98d04e585191b793c34f8b2b34de062473f5ed2b\", \"best_bid\":\"0.4\", \"best_ask\":\"0.41\"}], \"timestamp\":\"1785207866648\", \"event_type\":\"price_change\"}","received_at":"2026-07-28T03:04:26.686700Z","schema_version":"clob-market-ws.price_change.v1","sequence":null,"server_hash":null,"server_timestamp":"1785207866648","session_id":"3e519d9098404c15b234d96025eb1a2b","source":"clob_market_ws"},"received_at":"2026-07-28T03:04:26.686700Z","record_id":"b53c2956c35f4d52104e2456e8ecdb58b281e8e708d2560199b3372796cde685","schema_fingerprint":"4aa3821a28b0b7c2400bc59aba4bcc0a76e971dadd19610d3ad38c768e124dc7","schema_version":"edge-lab-recorder.raw.v1","sequence":null,"source":"clob_market_ws"}
{"event_at":"2026-07-28T03:04:26.649000Z","event_fingerprint":"30b6b029406c9b2999a4bcb19ed50b7a57e3e1e8bba9e6dfdb14099f21ae062c","payload":{"connection_id":"a6b55582af5f430fb37ad02bf0922475","event_at":"2026-07-28T03:04:26.649000Z","event_type":"price_change","frame_hash":"c4dd1db50ab1e7700eb9d3c82c353c3d3bf99f142291f4849dfb62527d4975fe","frame_index":0,"kind":"data","monotonic_ns":309849714068083,"payload":{"event_type":"price_change","market":"0x779291bef19b6709f61e9764a954aafe9ffae488d50ae674aabdcb4f248006d5","price_changes":[{"asset_id":"14965588658799411272385430903075831224615961675357217884735713260981483529984","best_ask":"0.41","best_bid":"0.4","hash":"5af34f45fa4b7b6506faa6feff630601ea1242ca","price":"0.4","side":"BUY","size":"15"},{"asset_id":"8761897749749422724209054078244794145777693856614463256546737399611489089783","best_ask":"0.6","best_bid":"0.59","hash":"422889f9daedba0cf86317b3a56b0d930ae644f8","price":"0.6","side":"SELL","size":"15"}],"timestamp":"1785207866649"},"payload_hash":"25144d6e4fe6b117f3e5e106360601762e1f58a85e78704c6e0702b2f4297d80","raw_frame":"{\"market\":\"0x779291bef19b6709f61e9764a954aafe9ffae488d50ae674aabdcb4f248006d5\", \"price_changes\":[{\"asset_id\":\"14965588658799411272385430903075831224615961675357217884735713260981483529984\", \"price\":\"0.4\", \"size\":\"15\", \"side\":\"BUY\", \"hash\":\"5af34f45fa4b7b6506faa6feff630601ea1242ca\", \"best_bid\":\"0.4\", \"best_ask\":\"0.41\"}, {\"asset_id\":\"8761897749749422724209054078244794145777693856614463256546737399611489089783\", \"price\":\"0.6\", \"size\":\"15\", \"side\":\"SELL\", \"hash\":\"422889f9daedba0cf86317b3a56b0d930ae644f8\", \"best_bid\":\"0.59\", \"best_ask\":\"0.6\"}], \"timestamp\":\"1785207866649\", \"event_type\":\"price_change\"}","received_at":"2026-07-28T03:04:26.688123Z","schema_version":"clob-market-ws.price_change.v1","sequence":null,"server_hash":null,"server_timestamp":"1785207866649","session_id":"3e519d9098404c15b234d96025eb1a2b","source":"clob_market_ws"},"received_at":"2026-07-28T03:04:26.688123Z","record_id":"f4d77646956a08731d8e15485e20c0b09c158658c3057dd5b410fe9a33690291","schema_fingerprint":"4aa3821a28b0b7c2400bc59aba4bcc0a76e971dadd19610d3ad38c768e124dc7","schema_version":"edge-lab-recorder.raw.v1","sequence":null,"source":"clob_market_ws"}
{"event_at":"2026-07-28T03:04:26.649000Z","event_fingerprint":"69b71c8ba976864adf8e85a9ea6c4a5b506b89bfaf21f97e0c816dfabfc27278","payload":{"connection_id":"a6b55582af5f430fb37ad02bf0922475","event_at":"2026-07-28T03:04:26.649000Z","event_type":"price_change","frame_hash":"6b59c9ae4ace0cd7da7e179714091b9b601d91401a7560d7a8b0547fbe09d19b","frame_index":0,"kind":"data","monotonic_ns":309849715479750,"payload":{"event_type":"price_change","market":"0x779291bef19b6709f61e9764a954aafe9ffae488d50ae674aabdcb4f248006d5","price_changes":[{"asset_id":"8761897749749422724209054078244794145777693856614463256546737399611489089783","best_ask":"0.6","best_bid":"0.59","hash":"3c8eeb89781445dd98386a71614a5511b93f7dfe","price":"0.01","side":"BUY","size":"5858.02"},{"asset_id":"14965588658799411272385430903075831224615961675357217884735713260981483529984","best_ask":"0.41","best_bid":"0.4","hash":"60b7de375cfdafaccf2f37d40fc223446685c66e","price":"0.99","side":"SELL","size":"5858.02"}],"timestamp":"1785207866649"},"payload_hash":"94c15c9aeb2d89df6eb6749d1a68f0500b0761dbd15fe3351e06864d7be64825","raw_frame":"{\"market\":\"0x779291bef19b6709f61e9764a954aafe9ffae488d50ae674aabdcb4f248006d5\", \"price_changes\":[{\"asset_id\":\"8761897749749422724209054078244794145777693856614463256546737399611489089783\", \"price\":\"0.01\", \"size\":\"5858.02\", \"side\":\"BUY\", \"hash\":\"3c8eeb89781445dd98386a71614a5511b93f7dfe\", \"best_bid\":\"0.59\", \"best_ask\":\"0.6\"}, {\"asset_id\":\"14965588658799411272385430903075831224615961675357217884735713260981483529984\", \"price\":\"0.99\", \"size\":\"5858.02\", \"side\":\"SELL\", \"hash\":\"60b7de375cfdafaccf2f37d40fc223446685c66e\", \"best_bid\":\"0.4\", \"best_ask\":\"0.41\"}], \"timestamp\":\"1785207866649\", \"event_type\":\"price_change\"}","received_at":"2026-07-28T03:04:26.689534Z","schema_version":"clob-market-ws.price_change.v1","sequence":null,"server_hash":null,"server_timestamp":"1785207866649","session_id":"3e519d9098404c15b234d96025eb1a2b","source":"clob_market_ws"},"received_at":"2026-07-28T03:04:26.689534Z","record_id":"57f8a1507fc7dac492ba9e6707e202629977a2ea20fcacb2f9c80b7a9b41213d","schema_fingerprint":"4aa3821a28b0b7c2400bc59aba4bcc0a76e971dadd19610d3ad38c768e124dc7","schema_version":"edge-lab-recorder.raw.v1","sequence":null,"source":"clob_market_ws"}
{"event_at":"2026-07-28T03:04:26.650000Z","event_fingerprint":"cee45b7314052fdcd2a8a3a04cb1422dbea9210b214a3d5e27b91f9b77461034","payload":{"connection_id":"a6b55582af5f430fb37ad02bf0922475","event_at":"2026-07-28T03:04:26.650000Z","event_type":"price_change","frame_hash":"5d6eb4088fe5f786d0280a2997e47732bcf2ef4cfe4d14425dcaf41b5df1a701","frame_index":0,"kind":"data","monotonic_ns":309849716918458,"payload":{"event_type":"price_change","market":"0x779291bef19b6709f61e9764a954aafe9ffae488d50ae674aabdcb4f248006d5","price_changes":[{"asset_id":"8761897749749422724209054078244794145777693856614463256546737399611489089783","best_ask":"0.6","best_bid":"0.59","hash":"929ea0ffac890a0911c2a3026455561973b0fa49","price":"0.59","side":"BUY","size":"70"},{"asset_id":"14965588658799411272385430903075831224615961675357217884735713260981483529984","best_ask":"0.41","best_bid":"0.4","hash":"b13a26487b3a76c35c83233a87fb7963487d6a3f","price":"0.41","side":"SELL","size":"70"}],"timestamp":"1785207866650"},"payload_hash":"e082775bb50ea09f96fa6a1ccba8becd88606bca4e185eedcbbe53b7d6acba07","raw_frame":"{\"market\":\"0x779291bef19b6709f61e9764a954aafe9ffae488d50ae674aabdcb4f248006d5\", \"price_changes\":[{\"asset_id\":\"8761897749749422724209054078244794145777693856614463256546737399611489089783\", \"price\":\"0.59\", \"size\":\"70\", \"side\":\"BUY\", \"hash\":\"929ea0ffac890a0911c2a3026455561973b0fa49\", \"best_bid\":\"0.59\", \"best_ask\":\"0.6\"}, {\"asset_id\":\"14965588658799411272385430903075831224615961675357217884735713260981483529984\", \"price\":\"0.41\", \"size\":\"70\", \"side\":\"SELL\", \"hash\":\"b13a26487b3a76c35c83233a87fb7963487d6a3f\", \"best_bid\":\"0.4\", \"best_ask\":\"0.41\"}], \"timestamp\":\"1785207866650\", \"event_type\":\"price_change\"}","received_at":"2026-07-28T03:04:26.690972Z","schema_version":"clob-market-ws.price_change.v1","sequence":null,"server_hash":null,"server_timestamp":"1785207866650","session_id":"3e519d9098404c15b234d96025eb1a2b","source":"clob_market_ws"},"received_at":"2026-07-28T03:04:26.690972Z","record_id":"df78d78086683c62862375c6659e76f4ee69d4e2571529d3859baae7448560e5","schema_fingerprint":"4aa3821a28b0b7c2400bc59aba4bcc0a76e971dadd19610d3ad38c768e124dc7","schema_version":"edge-lab-recorder.raw.v1","sequence":null,"source":"clob_market_ws"}
{"event_at":"2026-07-28T03:04:26.651000Z","event_fingerprint":"7be5d31859c2af6738e0c05025b66898f103d76e71777646082bc962c6cc24a4","payload":{"connection_id":"a6b55582af5f430fb37ad02bf0922475","event_at":"2026-07-28T03:04:26.651000Z","event_type":"price_change","frame_hash":"6abe24cd259cfaa96631b5b5c33c4416135babf73421822e5593a183927e9272","frame_index":0,"kind":"data","monotonic_ns":309849718332791,"payload":{"event_type":"price_change","market":"0x779291bef19b6709f61e9764a954aafe9ffae488d50ae674aabdcb4f248006d5","price_changes":[{"asset_id":"14965588658799411272385430903075831224615961675357217884735713260981483529984","best_ask":"0.41","best_bid":"0.4","hash":"b717be7a29c2670295efc6161b20277723f2dc04","price":"0.38","side":"BUY","size":"93"},{"asset_id":"8761897749749422724209054078244794145777693856614463256546737399611489089783","best_ask":"0.6","best_bid":"0.59","hash":"880d497bcaef99a4f773ce752586bbca767eaf5b","price":"0.62","side":"SELL","size":"93"}],"timestamp":"1785207866651"},"payload_hash":"1a49ea034f03b086ea254622ad68de58062f0e627a8000fd826a10f4a3d2b27c","raw_frame":"{\"market\":\"0x779291bef19b6709f61e9764a954aafe9ffae488d50ae674aabdcb4f248006d5\", \"price_changes\":[{\"asset_id\":\"14965588658799411272385430903075831224615961675357217884735713260981483529984\", \"price\":\"0.38\", \"size\":\"93\", \"side\":\"BUY\", \"hash\":\"b717be7a29c2670295efc6161b20277723f2dc04\", \"best_bid\":\"0.4\", \"best_ask\":\"0.41\"}, {\"asset_id\":\"8761897749749422724209054078244794145777693856614463256546737399611489089783\", \"price\":\"0.62\", \"size\":\"93\", \"side\":\"SELL\", \"hash\":\"880d497bcaef99a4f773ce752586bbca767eaf5b\", \"best_bid\":\"0.59\", \"best_ask\":\"0.6\"}], \"timestamp\":\"1785207866651\", \"event_type\":\"price_change\"}","received_at":"2026-07-28T03:04:26.692386Z","schema_version":"clob-market-ws.price_change.v1","sequence":null,"server_hash":null,"server_timestamp":"1785207866651","session_id":"3e519d9098404c15b234d96025eb1a2b","source":"clob_market_ws"},"received_at":"2026-07-28T03:04:26.692386Z","record_id":"9dc7eba72754b27e0d558743040036dd3dd63b7f979aee28c28337bc10a43e74","schema_fingerprint":"4aa3821a28b0b7c2400bc59aba4bcc0a76e971dadd19610d3ad38c768e124dc7","schema_version":"edge-lab-recorder.raw.v1","sequence":null,"source":"clob_market_ws"}
{"event_at":"2026-07-28T03:04:26.651000Z","event_fingerprint":"3b5c5147f3c143f4ad8d320e8f7d8f1fd755c88a47c341be270ff4cdb409bc2d","payload":{"connection_id":"a6b55582af5f430fb37ad02bf0922475","event_at":"2026-07-28T03:04:26.651000Z","event_type":"price_change","frame_hash":"35392f0b777771087b3dfa9f7691e9181d78b8d61d9fa151184b668c25f53be7","frame_index":0,"kind":"data","monotonic_ns":309849719907041,"payload":{"event_type":"price_change","market":"0x779291bef19b6709f61e9764a954aafe9ffae488d50ae674aabdcb4f248006d5","price_changes":[{"asset_id":"8761897749749422724209054078244794145777693856614463256546737399611489089783","best_ask":"0.6","best_bid":"0.59","hash":"24bd3efceac13cabe673b2ed001c18fe7a366990","price":"0.56","side":"BUY","size":"123.3"},{"asset_id":"14965588658799411272385430903075831224615961675357217884735713260981483529984","best_ask":"0.41","best_bid":"0.4","hash":"8a66064e7e617d7229b9e222ac37a189840fe6c1","price":"0.44","side":"SELL","size":"123.3"}],"timestamp":"1785207866651"},"payload_hash":"666f6daa006595460b2d4f3d458d44b93c317a80b6f40e858d9980f196aed3ec","raw_frame":"{\"market\":\"0x779291bef19b6709f61e9764a954aafe9ffae488d50ae674aabdcb4f248006d5\", \"price_changes\":[{\"asset_id\":\"8761897749749422724209054078244794145777693856614463256546737399611489089783\", \"price\":\"0.56\", \"size\":\"123.3\", \"side\":\"BUY\", \"hash\":\"24bd3efceac13cabe673b2ed001c18fe7a366990\", \"best_bid\":\"0.59\", \"best_ask\":\"0.6\"}, {\"asset_id\":\"14965588658799411272385430903075831224615961675357217884735713260981483529984\", \"price\":\"0.44\", \"size\":\"123.3\", \"side\":\"SELL\", \"hash\":\"8a66064e7e617d7229b9e222ac37a189840fe6c1\", \"best_bid\":\"0.4\", \"best_ask\":\"0.41\"}], \"timestamp\":\"1785207866651\", \"event_type\":\"price_change\"}","received_at":"2026-07-28T03:04:26.693960Z","schema_version":"clob-market-ws.price_change.v1","sequence":null,"server_hash":null,"server_timestamp":"1785207866651","session_id":"3e519d9098404c15b234d96025eb1a2b","source":"clob_market_ws"},"received_at":"2026-07-28T03:04:26.693960Z","record_id":"bd77614974dd0e3c54a6704a240742dee62ed62ef6535158d1e27685a019705c","schema_fingerprint":"4aa3821a28b0b7c2400bc59aba4bcc0a76e971dadd19610d3ad38c768e124dc7","schema_version":"edge-lab-recorder.raw.v1","sequence":null,"source":"clob_market_ws"}
{"event_at":"2026-07-28T03:04:26.652000Z","event_fingerprint":"b1ecc7b8e2b116f73c8df1fc3ca49de4972a465290f60c78a8207ed1b35ae447","payload":{"connection_id":"a6b55582af5f430fb37ad02bf0922475","event_at":"2026-07-28T03:04:26.652000Z","event_type":"price_change","frame_hash":"508ffe012386821240e37dc01bcc246d23f642ea25bd2b20925a290d2f259848","frame_index":0,"kind":"data","monotonic_ns":309849720952791,"payload":{"event_type":"price_change","market":"0x779291bef19b6709f61e9764a954aafe9ffae488d50ae674aabdcb4f248006d5","price_changes":[{"asset_id":"8761897749749422724209054078244794145777693856614463256546737399611489089783","best_ask":"0.6","best_bid":"0.59","hash":"c714b8523f962cc77770b0bcb4fbaf04cf73b662","price":"0.5","side":"BUY","size":"173.5"},{"asset_id":"14965588658799411272385430903075831224615961675357217884735713260981483529984","best_ask":"0.41","best_bid":"0.4","hash":"fe85728f297ce4dce627bb8bbfb340f094862e15","price":"0.5","side":"SELL","size":"173.5"}],"timestamp":"1785207866652"},"payload_hash":"c7198901fcf802e9e99050cc56f32dfc23af300b166929e0824f46e8525a3493","raw_frame":"{\"market\":\"0x779291bef19b6709f61e9764a954aafe9ffae488d50ae674aabdcb4f248006d5\", \"price_changes\":[{\"asset_id\":\"8761897749749422724209054078244794145777693856614463256546737399611489089783\", \"price\":\"0.5\", \"size\":\"173.5\", \"side\":\"BUY\", \"hash\":\"c714b8523f962cc77770b0bcb4fbaf04cf73b662\", \"best_bid\":\"0.59\", \"best_ask\":\"0.6\"}, {\"asset_id\":\"14965588658799411272385430903075831224615961675357217884735713260981483529984\", \"price\":\"0.5\", \"size\":\"173.5\", \"side\":\"SELL\", \"hash\":\"fe85728f297ce4dce627bb8bbfb340f094862e15\", \"best_bid\":\"0.4\", \"best_ask\":\"0.41\"}], \"timestamp\":\"1785207866652\", \"event_type\":\"price_change\"}","received_at":"2026-07-28T03:04:26.695011Z","schema_version":"clob-market-ws.price_change.v1","sequence":null,"server_hash":null,"server_timestamp":"1785207866652","session_id":"3e519d9098404c15b234d96025eb1a2b","source":"clob_market_ws"},"received_at":"2026-07-28T03:04:26.695011Z","record_id":"9f5feb926e01025d12188881f86a1c650c94f5a9dfd1cf04911039abacb823a5","schema_fingerprint":"4aa3821a28b0b7c2400bc59aba4bcc0a76e971dadd19610d3ad38c768e124dc7","schema_version":"edge-lab-recorder.raw.v1","sequence":null,"source":"clob_market_ws"}
{"event_at":"2026-07-28T03:04:26.652000Z","event_fingerprint":"5548bbd480ba3a8514a0a148cdae70d996d1da19ebb2e30cc01e8828217c8625","payload":{"connection_id":"a6b55582af5f430fb37ad02bf0922475","event_at":"2026-07-28T03:04:26.652000Z","event_type":"price_change","frame_hash":"86dd1d370da9d24916d5ef011420a2a891b58f361fc821b4bc74861404c7cc29","frame_index":0,"kind":"data","monotonic_ns":309849721533500,"payload":{"event_type":"price_change","market":"0x779291bef19b6709f61e9764a954aafe9ffae488d50ae674aabdcb4f248006d5","price_changes":[{"asset_id":"8761897749749422724209054078244794145777693856614463256546737399611489089783","best_ask":"0.6","best_bid":"0.59","hash":"8927ed591323cc849cbcc91029c149daf6264c4a","price":"0.57","side":"BUY","size":"147.35"},{"asset_id":"14965588658799411272385430903075831224615961675357217884735713260981483529984","best_ask":"0.41","best_bid":"0.4","hash":"9a77b553a3e19846902ef58ae8e40693cef96be3","price":"0.43","side":"SELL","size":"147.35"}],"timestamp":"1785207866652"},"payload_hash":"0c4818cce064e587b2c2c0eea6bfa7443f15878c202880df193789abb8cccc97","raw_frame":"{\"market\":\"0x779291bef19b6709f61e9764a954aafe9ffae488d50ae674aabdcb4f248006d5\", \"price_changes\":[{\"asset_id\":\"8761897749749422724209054078244794145777693856614463256546737399611489089783\", \"price\":\"0.57\", \"size\":\"147.35\", \"side\":\"BUY\", \"hash\":\"8927ed591323cc849cbcc91029c149daf6264c4a\", \"best_bid\":\"0.59\", \"best_ask\":\"0.6\"}, {\"asset_id\":\"14965588658799411272385430903075831224615961675357217884735713260981483529984\", \"price\":\"0.43\", \"size\":\"147.35\", \"side\":\"SELL\", \"hash\":\"9a77b553a3e19846902ef58ae8e40693cef96be3\", \"best_bid\":\"0.4\", \"best_ask\":\"0.41\"}], \"timestamp\":\"1785207866652\", \"event_type\":\"price_change\"}","received_at":"2026-07-28T03:04:26.695586Z","schema_version":"clob-market-ws.price_change.v1","sequence":null,"server_hash":null,"server_timestamp":"1785207866652","session_id":"3e519d9098404c15b234d96025eb1a2b","source":"clob_market_ws"},"received_at":"2026-07-28T03:04:26.695586Z","record_id":"15d214ec4a6ff331ad77cb165a5313c3209affc9f128a60b81653a95af231956","schema_fingerprint":"4aa3821a28b0b7c2400bc59aba4bcc0a76e971dadd19610d3ad38c768e124dc7","schema_version":"edge-lab-recorder.raw.v1","sequence":null,"source":"clob_market_ws"}
{"event_at":"2026-07-28T03:04:26.654000Z","event_fingerprint":"a07ef8b5edd5851ece252179017c35540eee78c68131c67f1edbef745e117f45","payload":{"connection_id":"a6b55582af5f430fb37ad02bf0922475","event_at":"2026-07-28T03:04:26.654000Z","event_type":"price_change","frame_hash":"f27a78ef0bc7a57c6265d4442bdd99a10e3061c6ba42df821ecd02ca820a6cf4","frame_index":0,"kind":"data","monotonic_ns":309849722970166,"payload":{"event_type":"price_change","market":"0x779291bef19b6709f61e9764a954aafe9ffae488d50ae674aabdcb4f248006d5","price_changes":[{"asset_id":"8761897749749422724209054078244794145777693856614463256546737399611489089783","best_ask":"0.6","best_bid":"0.59","hash":"ad62f686c39e6e2eb3c49bfa7faf42edf03d3519","price":"0.59","side":"BUY","size":"76"},{"asset_id":"14965588658799411272385430903075831224615961675357217884735713260981483529984","best_ask":"0.41","best_bid":"0.4","hash":"dc6d3fb6ec59732faf83ec6744583e33256e8645","price":"0.41","side":"SELL","size":"76"}],"timestamp":"1785207866654"},"payload_hash":"f6092ff7df94c0da92bc8db92794972b8f5342aafcb2901388ae6a486bbdbca5","raw_frame":"{\"market\":\"0x779291bef19b6709f61e9764a954aafe9ffae488d50ae674aabdcb4f248006d5\", \"price_changes\":[{\"asset_id\":\"8761897749749422724209054078244794145777693856614463256546737399611489089783\", \"price\":\"0.59\", \"size\":\"76\", \"side\":\"BUY\", \"hash\":\"ad62f686c39e6e2eb3c49bfa7faf42edf03d3519\", \"best_bid\":\"0.59\", \"best_ask\":\"0.6\"}, {\"asset_id\":\"14965588658799411272385430903075831224615961675357217884735713260981483529984\", \"price\":\"0.41\", \"size\":\"76\", \"side\":\"SELL\", \"hash\":\"dc6d3fb6ec59732faf83ec6744583e33256e8645\", \"best_bid\":\"0.4\", \"best_ask\":\"0.41\"}], \"timestamp\":\"1785207866654\", \"event_type\":\"price_change\"}","received_at":"2026-07-28T03:04:26.697022Z","schema_version":"clob-market-ws.price_change.v1","sequence":null,"server_hash":null,"server_timestamp":"1785207866654","session_id":"3e519d9098404c15b234d96025eb1a2b","source":"clob_market_ws"},"received_at":"2026-07-28T03:04:26.697022Z","record_id":"80c2610a43fbca652c8161b4f6dffc006f5ad4c616b1b8c89164fde2b91a6015","schema_fingerprint":"4aa3821a28b0b7c2400bc59aba4bcc0a76e971dadd19610d3ad38c768e124dc7","schema_version":"edge-lab-recorder.raw.v1","sequence":null,"source":"clob_market_ws"}
{"event_at":"2026-07-28T03:04:26.655000Z","event_fingerprint":"a9a27b05f2183767411ad500b6c555a27db7c7202c29f2aaa943050d377455d9","payload":{"connection_id":"a6b55582af5f430fb37ad02bf0922475","event_at":"2026-07-28T03:04:26.655000Z","event_type":"price_change","frame_hash":"a6ca7cf392b0b806a79c7f71d4e56982e33cb381f4120a9ed55f3f6a8422deb6","frame_index":0,"kind":"data","monotonic_ns":309849724397541,"payload":{"event_type":"price_change","market":"0x779291bef19b6709f61e9764a954aafe9ffae488d50ae674aabdcb4f248006d5","price_changes":[{"asset_id":"8761897749749422724209054078244794145777693856614463256546737399611489089783","best_ask":"0.6","best_bid":"0.59","hash":"d4cd9ac414a433cd7133231fbdd25d79ab60c0b2","price":"0.59","side":"BUY","size":"81"},{"asset_id":"14965588658799411272385430903075831224615961675357217884735713260981483529984","best_ask":"0.41","best_bid":"0.4","hash":"484d2755773dd3a413aa550c8f2cb19dec92f0e3","price":"0.41","side":"SELL","size":"81"}],"timestamp":"1785207866655"},"payload_hash":"fed397a6c8324daae016c452f4de8ba62e6e714c3381d9b0e43159ee0ec6724e","raw_frame":"{\"market\":\"0x779291bef19b6709f61e9764a954aafe9ffae488d50ae674aabdcb4f248006d5\", \"price_changes\":[{\"asset_id\":\"8761897749749422724209054078244794145777693856614463256546737399611489089783\", \"price\":\"0.59\", \"size\":\"81\", \"side\":\"BUY\", \"hash\":\"d4cd9ac414a433cd7133231fbdd25d79ab60c0b2\", \"best_bid\":\"0.59\", \"best_ask\":\"0.6\"}, {\"asset_id\":\"14965588658799411272385430903075831224615961675357217884735713260981483529984\", \"price\":\"0.41\", \"size\":\"81\", \"side\":\"SELL\", \"hash\":\"484d2755773dd3a413aa550c8f2cb19dec92f0e3\", \"best_bid\":\"0.4\", \"best_ask\":\"0.41\"}], \"timestamp\":\"1785207866655\", \"event_type\":\"price_change\"}","received_at":"2026-07-28T03:04:26.698449Z","schema_version":"clob-market-ws.price_change.v1","sequence":null,"server_hash":null,"server_timestamp":"1785207866655","session_id":"3e519d9098404c15b234d96025eb1a2b","source":"clob_market_ws"},"received_at":"2026-07-28T03:04:26.698449Z","record_id":"bd9f8dd31713a77efe6e1c8e1fb475a9188b6985bf69643db5990689ee41ac19","schema_fingerprint":"4aa3821a28b0b7c2400bc59aba4bcc0a76e971dadd19610d3ad38c768e124dc7","schema_version":"edge-lab-recorder.raw.v1","sequence":null,"source":"clob_market_ws"}
{"event_at":"2026-07-28T03:04:26.656000Z","event_fingerprint":"e4990afb5d6dbc6ea2bf7eb5a3fe4790bd8cbc8ec5bb1d5137493f366e522c55","payload":{"connection_id":"a6b55582af5f430fb37ad02bf0922475","event_at":"2026-07-28T03:04:26.656000Z","event_type":"price_change","frame_hash":"799e97fc4bb3eea5abe2408ed0bd30451a54e9bda0cf63b11d814ffe2bd36513","frame_index":0,"kind":"data","monotonic_ns":309849725831208,"payload":{"event_type":"price_change","market":"0x779291bef19b6709f61e9764a954aafe9ffae488d50ae674aabdcb4f248006d5","price_changes":[{"asset_id":"8761897749749422724209054078244794145777693856614463256546737399611489089783","best_ask":"0.6","best_bid":"0.59","hash":"ea534da2455c5b513a35f3a8eaed6275edd2ac5c","price":"0.46","side":"BUY","size":"188"},{"asset_id":"14965588658799411272385430903075831224615961675357217884735713260981483529984","best_ask":"0.41","best_bid":"0.4","hash":"66a788ca3e7531ab33fc132c0ad1eaff309b1cad","price":"0.54","side":"SELL","size":"188"}],"timestamp":"1785207866656"},"payload_hash":"0b28379729725e953f8a10d1b5bb4ba88864e979d64404cc52ed451a7497cf9d","raw_frame":"{\"market\":\"0x779291bef19b6709f61e9764a954aafe9ffae488d50ae674aabdcb4f248006d5\", \"price_changes\":[{\"asset_id\":\"8761897749749422724209054078244794145777693856614463256546737399611489089783\", \"price\":\"0.46\", \"size\":\"188\", \"side\":\"BUY\", \"hash\":\"ea534da2455c5b513a35f3a8eaed6275edd2ac5c\", \"best_bid\":\"0.59\", \"best_ask\":\"0.6\"}, {\"asset_id\":\"14965588658799411272385430903075831224615961675357217884735713260981483529984\", \"price\":\"0.54\", \"size\":\"188\", \"side\":\"SELL\", \"hash\":\"66a788ca3e7531ab33fc132c0ad1eaff309b1cad\", \"best_bid\":\"0.4\", \"best_ask\":\"0.41\"}], \"timestamp\":\"1785207866656\", \"event_type\":\"price_change\"}","received_at":"2026-07-28T03:04:26.699883Z","schema_version":"clob-market-ws.price_change.v1","sequence":null,"server_hash":null,"server_timestamp":"1785207866656","session_id":"3e519d9098404c15b234d96025eb1a2b","source":"clob_market_ws"},"received_at":"2026-07-28T03:04:26.699883Z","record_id":"66894ac25fffaba4da836684524d39e761e34f414db9f85b3cc0dbf85f165d66","schema_fingerprint":"4aa3821a28b0b7c2400bc59aba4bcc0a76e971dadd19610d3ad38c768e124dc7","schema_version":"edge-lab-recorder.raw.v1","sequence":null,"source":"clob_market_ws"}
{"event_at":"2026-07-28T03:04:26.657000Z","event_fingerprint":"6c24499c911bf0efec7395595ce5db959c778a093dafd393ac12a296ac007083","payload":{"connection_id":"a6b55582af5f430fb37ad02bf0922475","event_at":"2026-07-28T03:04:26.657000Z","event_type":"price_change","frame_hash":"25ae59e6df9ad76cb8f33761225801341cd620450853cc327ec72279e44ab3f8","frame_index":0,"kind":"data","monotonic_ns":309849727248333,"payload":{"event_type":"price_change","market":"0x779291bef19b6709f61e9764a954aafe9ffae488d50ae674aabdcb4f248006d5","price_changes":[{"asset_id":"14965588658799411272385430903075831224615961675357217884735713260981483529984","best_ask":"0.41","best_bid":"0.4","hash":"aeacf77a603ce9181882e9b171accb8173aa0ba2","price":"0.27","side":"BUY","size":"58.2"},{"asset_id":"8761897749749422724209054078244794145777693856614463256546737399611489089783","best_ask":"0.6","best_bid":"0.59","hash":"062e8230811de6056164a9d754812be5ca836050","price":"0.73","side":"SELL","size":"58.2"}],"timestamp":"1785207866657"},"payload_hash":"dbfd97173ca8c479a03708bce1a7b61cd7cce5f13eea8f7048d796beffffbf76","raw_frame":"{\"market\":\"0x779291bef19b6709f61e9764a954aafe9ffae488d50ae674aabdcb4f248006d5\", \"price_changes\":[{\"asset_id\":\"14965588658799411272385430903075831224615961675357217884735713260981483529984\", \"price\":\"0.27\", \"size\":\"58.2\", \"side\":\"BUY\", \"hash\":\"aeacf77a603ce9181882e9b171accb8173aa0ba2\", \"best_bid\":\"0.4\", \"best_ask\":\"0.41\"}, {\"asset_id\":\"8761897749749422724209054078244794145777693856614463256546737399611489089783\", \"price\":\"0.73\", \"size\":\"58.2\", \"side\":\"SELL\", \"hash\":\"062e8230811de6056164a9d754812be5ca836050\", \"best_bid\":\"0.59\", \"best_ask\":\"0.6\"}], \"timestamp\":\"1785207866657\", \"event_type\":\"price_change\"}","received_at":"2026-07-28T03:04:26.701299Z","schema_version":"clob-market-ws.price_change.v1","sequence":null,"server_hash":null,"server_timestamp":"1785207866657","session_id":"3e519d9098404c15b234d96025eb1a2b","source":"clob_market_ws"},"received_at":"2026-07-28T03:04:26.701299Z","record_id":"ebf2055a4bb45c767a0093bd0d28da93423a56f57dc46e5b4cb30f5ec26c6f01","schema_fingerprint":"4aa3821a28b0b7c2400bc59aba4bcc0a76e971dadd19610d3ad38c768e124dc7","schema_version":"edge-lab-recorder.raw.v1","sequence":null,"source":"clob_market_ws"}
{"event_at":"2026-07-28T03:04:26.657000Z","event_fingerprint":"845b717f81ff42fb48ad460a1870e6eabe649c3a5a10eb8412819aebad69bd43","payload":{"connection_id":"a6b55582af5f430fb37ad02bf0922475","event_at":"2026-07-28T03:04:26.657000Z","event_type":"price_change","frame_hash":"156c5588997fea202541318ea655e61b86a44b6fb9f4c09358bbebbfcf871dc5","frame_index":0,"kind":"data","monotonic_ns":309849728680833,"payload":{"event_type":"price_change","market":"0x779291bef19b6709f61e9764a954aafe9ffae488d50ae674aabdcb4f248006d5","price_changes":[{"asset_id":"8761897749749422724209054078244794145777693856614463256546737399611489089783","best_ask":"0.6","best_bid":"0.59","hash":"8e0d6dab9a27aca7901bbf66324b2720b586b220","price":"0.59","side":"BUY","size":"93.6"},{"asset_id":"14965588658799411272385430903075831224615961675357217884735713260981483529984","best_ask":"0.41","best_bid":"0.4","hash":"512ef8a4daf386f95eb7eb3b55f46dd403893241","price":"0.41","side":"SELL","size":"93.6"}],"timestamp":"1785207866657"},"payload_hash":"2ed345e405e527db5868c140c6f941b1669bd080c42a39343158ecaaf60f9e29","raw_frame":"{\"market\":\"0x779291bef19b6709f61e9764a954aafe9ffae488d50ae674aabdcb4f248006d5\", \"price_changes\":[{\"asset_id\":\"8761897749749422724209054078244794145777693856614463256546737399611489089783\", \"price\":\"0.59\", \"size\":\"93.6\", \"side\":\"BUY\", \"hash\":\"8e0d6dab9a27aca7901bbf66324b2720b586b220\", \"best_bid\":\"0.59\", \"best_ask\":\"0.6\"}, {\"asset_id\":\"14965588658799411272385430903075831224615961675357217884735713260981483529984\", \"price\":\"0.41\", \"size\":\"93.6\", \"side\":\"SELL\", \"hash\":\"512ef8a4daf386f95eb7eb3b55f46dd403893241\", \"best_bid\":\"0.4\", \"best_ask\":\"0.41\"}], \"timestamp\":\"1785207866657\", \"event_type\":\"price_change\"}","received_at":"2026-07-28T03:04:26.702731Z","schema_version":"clob-market-ws.price_change.v1","sequence":null,"server_hash":null,"server_timestamp":"1785207866657","session_id":"3e519d9098404c15b234d96025eb1a2b","source":"clob_market_ws"},"received_at":"2026-07-28T03:04:26.702731Z","record_id":"be45c8081ec5b5a20def786d528d9aeb1453afe61e2fa08758058337822d8100","schema_fingerprint":"4aa3821a28b0b7c2400bc59aba4bcc0a76e971dadd19610d3ad38c768e124dc7","schema_version":"edge-lab-recorder.raw.v1","sequence":null,"source":"clob_market_ws"}
{"event_at":"2026-07-28T03:04:26.659000Z","event_fingerprint":"6acc95a055c676a037ea61d392d9e876a1ab6a7245b9642400bf095c69f2ebba","payload":{"connection_id":"a6b55582af5f430fb37ad02bf0922475","event_at":"2026-07-28T03:04:26.659000Z","event_type":"price_change","frame_hash":"d6359ad18ba552aba07e8028e578de20719278d246decbbea88af5f19dc10b29","frame_index":0,"kind":"data","monotonic_ns":309849730118083,"payload":{"event_type":"price_change","market":"0x779291bef19b6709f61e9764a954aafe9ffae488d50ae674aabdcb4f248006d5","price_changes":[{"asset_id":"8761897749749422724209054078244794145777693856614463256546737399611489089783","best_ask":"0.6","best_bid":"0.59","hash":"24eab512299f993d0640a82bb05a882352dfcfcd","price":"0.59","side":"BUY","size":"98.6"},{"asset_id":"14965588658799411272385430903075831224615961675357217884735713260981483529984","best_ask":"0.41","best_bid":"0.4","hash":"56f9a4c03a0908d0412101a6b4a393b67f217f4b","price":"0.41","side":"SELL","size":"98.6"}],"timestamp":"1785207866659"},"payload_hash":"feb8e2ca7bca737ce025f803272ebd43b56bf29d66f8c0613a37bc7bd6361875","raw_frame":"{\"market\":\"0x779291bef19b6709f61e9764a954aafe9ffae488d50ae674aabdcb4f248006d5\", \"price_changes\":[{\"asset_id\":\"8761897749749422724209054078244794145777693856614463256546737399611489089783\", \"price\":\"0.59\", \"size\":\"98.6\", \"side\":\"BUY\", \"hash\":\"24eab512299f993d0640a82bb05a882352dfcfcd\", \"best_bid\":\"0.59\", \"best_ask\":\"0.6\"}, {\"asset_id\":\"14965588658799411272385430903075831224615961675357217884735713260981483529984\", \"price\":\"0.41\", \"size\":\"98.6\", \"side\":\"SELL\", \"hash\":\"56f9a4c03a0908d0412101a6b4a393b67f217f4b\", \"best_bid\":\"0.4\", \"best_ask\":\"0.41\"}], \"timestamp\":\"1785207866659\", \"event_type\":\"price_change\"}","received_at":"2026-07-28T03:04:26.704168Z","schema_version":"clob-market-ws.price_change.v1","sequence":null,"server_hash":null,"server_timestamp":"1785207866659","session_id":"3e519d9098404c15b234d96025eb1a2b","source":"clob_market_ws"},"received_at":"2026-07-28T03:04:26.704168Z","record_id":"b1442470b4208bcf7e966cdf674d93d4d4cc4badb14d053abc359ecd364c728c","schema_fingerprint":"4aa3821a28b0b7c2400bc59aba4bcc0a76e971dadd19610d3ad38c768e124dc7","schema_version":"edge-lab-recorder.raw.v1","sequence":null,"source":"clob_market_ws"}
{"event_at":"2026-07-28T03:04:26.660000Z","event_fingerprint":"9b58552b4cba9c86096b0e296a56bdc454b8d3732395b88a4309b92b05be86ed","payload":{"connection_id":"a6b55582af5f430fb37ad02bf0922475","event_at":"2026-07-28T03:04:26.660000Z","event_type":"price_change","frame_hash":"7cd43a575dc8131937112a03112f96f25eeebb7c12c8744a0ce8c175991de9b9","frame_index":0,"kind":"data","monotonic_ns":309849731553625,"payload":{"event_type":"price_change","market":"0x779291bef19b6709f61e9764a954aafe9ffae488d50ae674aabdcb4f248006d5","price_changes":[{"asset_id":"14965588658799411272385430903075831224615961675357217884735713260981483529984","best_ask":"0.41","best_bid":"0.4","hash":"768fbd29487260521245af488473ad0fcdeb376d","price":"0.26","side":"BUY","size":"58.6"},{"asset_id":"8761897749749422724209054078244794145777693856614463256546737399611489089783","best_ask":"0.6","best_bid":"0.59","hash":"0d8385578586720522e08860b9f6fadcd8c6e908","price":"0.74","side":"SELL","size":"58.6"}],"timestamp":"1785207866660"},"payload_hash":"1445ffe2117d4da74c4449211956fe96251b9335008aeec25aa7323f49cbe3e3","raw_frame":"{\"market\":\"0x779291bef19b6709f61e9764a954aafe9ffae488d50ae674aabdcb4f248006d5\", \"price_changes\":[{\"asset_id\":\"14965588658799411272385430903075831224615961675357217884735713260981483529984\", \"price\":\"0.26\", \"size\":\"58.6\", \"side\":\"BUY\", \"hash\":\"768fbd29487260521245af488473ad0fcdeb376d\", \"best_bid\":\"0.4\", \"best_ask\":\"0.41\"}, {\"asset_id\":\"8761897749749422724209054078244794145777693856614463256546737399611489089783\", \"price\":\"0.74\", \"size\":\"58.6\", \"side\":\"SELL\", \"hash\":\"0d8385578586720522e08860b9f6fadcd8c6e908\", \"best_bid\":\"0.59\", \"best_ask\":\"0.6\"}], \"timestamp\":\"1785207866660\", \"event_type\":\"price_change\"}","received_at":"2026-07-28T03:04:26.705603Z","schema_version":"clob-market-ws.price_change.v1","sequence":null,"server_hash":null,"server_timestamp":"1785207866660","session_id":"3e519d9098404c15b234d96025eb1a2b","source":"clob_market_ws"},"received_at":"2026-07-28T03:04:26.705603Z","record_id":"6ebb6f4fbec199d9b54c6a797405bad9b1134f28e5ef2e9246e6cf00866a23f5","schema_fingerprint":"4aa3821a28b0b7c2400bc59aba4bcc0a76e971dadd19610d3ad38c768e124dc7","schema_version":"edge-lab-recorder.raw.v1","sequence":null,"source":"clob_market_ws"}
{"event_at":"2026-07-28T03:04:26.660000Z","event_fingerprint":"ac500f26a0da0dbc57023b1c3b565fe1c21b9552ad016ffa0db23becf7cc7289","payload":{"connection_id":"a6b55582af5f430fb37ad02bf0922475","event_at":"2026-07-28T03:04:26.660000Z","event_type":"price_change","frame_hash":"2831fb67bd5282fc22d9747cd67090a493615940df076124dac1d748a135fcbf","frame_index":0,"kind":"data","monotonic_ns":309849732985041,"payload":{"event_type":"price_change","market":"0x779291bef19b6709f61e9764a954aafe9ffae488d50ae674aabdcb4f248006d5","price_changes":[{"asset_id":"14965588658799411272385430903075831224615961675357217884735713260981483529984","best_ask":"0.41","best_bid":"0.4","hash":"5d880388ddab9632182d7081ba4862d7653f1f75","price":"0.31","side":"BUY","size":"241"},{"asset_id":"8761897749749422724209054078244794145777693856614463256546737399611489089783","best_ask":"0.6","best_bid":"0.59","hash":"e6461b77aff10488a04b4fe2a3c3685d2b09f84b","price":"0.69","side":"SELL","size":"241"}],"timestamp":"1785207866660"},"payload_hash":"60d5e4210523c8b0e74c685ecf25dce07bacf756c3eae3d18958c4f675b1340e","raw_frame":"{\"market\":\"0x779291bef19b6709f61e9764a954aafe9ffae488d50ae674aabdcb4f248006d5\", \"price_changes\":[{\"asset_id\":\"14965588658799411272385430903075831224615961675357217884735713260981483529984\", \"price\":\"0.31\", \"size\":\"241\", \"side\":\"BUY\", \"hash\":\"5d880388ddab9632182d7081ba4862d7653f1f75\", \"best_bid\":\"0.4\", \"best_ask\":\"0.41\"}, {\"asset_id\":\"8761897749749422724209054078244794145777693856614463256546737399611489089783\", \"price\":\"0.69\", \"size\":\"241\", \"side\":\"SELL\", \"hash\":\"e6461b77aff10488a04b4fe2a3c3685d2b09f84b\", \"best_bid\":\"0.59\", \"best_ask\":\"0.6\"}], \"timestamp\":\"1785207866660\", \"event_type\":\"price_change\"}","received_at":"2026-07-28T03:04:26.707034Z","schema_version":"clob-market-ws.price_change.v1","sequence":null,"server_hash":null,"server_timestamp":"1785207866660","session_id":"3e519d9098404c15b234d96025eb1a2b","source":"clob_market_ws"},"received_at":"2026-07-28T03:04:26.707034Z","record_id":"f0512c341bcf094cc02871fd6963dbf71ab4af28600791df10aecde6e7159e8f","schema_fingerprint":"4aa3821a28b0b7c2400bc59aba4bcc0a76e971dadd19610d3ad38c768e124dc7","schema_version":"edge-lab-recorder.raw.v1","sequence":null,"source":"clob_market_ws"}
{"event_at":"2026-07-28T03:04:26.662000Z","event_fingerprint":"8b9d1a572526e93db011996abe40d6c8081bbd252c515aeccac971af4e91a2d0","payload":{"connection_id":"a6b55582af5f430fb37ad02bf0922475","event_at":"2026-07-28T03:04:26.662000Z","event_type":"price_change","frame_hash":"cee4b5409dc8167d645898cecffac210e3a4bd5c1e948a813942681fc206cc77","frame_index":0,"kind":"data","monotonic_ns":309849734503416,"payload":{"event_type":"price_change","market":"0x779291bef19b6709f61e9764a954aafe9ffae488d50ae674aabdcb4f248006d5","price_changes":[{"asset_id":"8761897749749422724209054078244794145777693856614463256546737399611489089783","best_ask":"0.6","best_bid":"0.59","hash":"ed550e06f04262bc5fefe1770cb4adf9d85546f7","price":"0.59","side":"BUY","size":"103.6"},{"asset_id":"14965588658799411272385430903075831224615961675357217884735713260981483529984","best_ask":"0.41","best_bid":"0.4","hash":"7e30a28861c24e3f57483eeb4221eb1bf8d733a4","price":"0.41","side":"SELL","size":"103.6"}],"timestamp":"1785207866662"},"payload_hash":"eff5584b08b68fbd99db6efb78ffbcefa3e32016d0da747fd25f0f6f51ceaeb1","raw_frame":"{\"market\":\"0x779291bef19b6709f61e9764a954aafe9ffae488d50ae674aabdcb4f248006d5\", \"price_changes\":[{\"asset_id\":\"8761897749749422724209054078244794145777693856614463256546737399611489089783\", \"price\":\"0.59\", \"size\":\"103.6\", \"side\":\"BUY\", \"hash\":\"ed550e06f04262bc5fefe1770cb4adf9d85546f7\", \"best_bid\":\"0.59\", \"best_ask\":\"0.6\"}, {\"asset_id\":\"14965588658799411272385430903075831224615961675357217884735713260981483529984\", \"price\":\"0.41\", \"size\":\"103.6\", \"side\":\"SELL\", \"hash\":\"7e30a28861c24e3f57483eeb4221eb1bf8d733a4\", \"best_bid\":\"0.4\", \"best_ask\":\"0.41\"}], \"timestamp\":\"1785207866662\", \"event_type\":\"price_change\"}","received_at":"2026-07-28T03:04:26.708552Z","schema_version":"clob-market-ws.price_change.v1","sequence":null,"server_hash":null,"server_timestamp":"1785207866662","session_id":"3e519d9098404c15b234d96025eb1a2b","source":"clob_market_ws"},"received_at":"2026-07-28T03:04:26.708552Z","record_id":"9088bef87c7aa53b5fe34c51f32951d2a377fa29f1548c63d5804b21762f416d","schema_fingerprint":"4aa3821a28b0b7c2400bc59aba4bcc0a76e971dadd19610d3ad38c768e124dc7","schema_version":"edge-lab-recorder.raw.v1","sequence":null,"source":"clob_market_ws"}
{"event_at":"2026-07-28T03:04:26.664000Z","event_fingerprint":"53fef22a65d36c9dc2cb5ec3673d969ed34f01d99ee3c221cede16ad49955284","payload":{"connection_id":"a6b55582af5f430fb37ad02bf0922475","event_at":"2026-07-28T03:04:26.664000Z","event_type":"price_change","frame_hash":"41f18538bf144d5c6b852c58aea6dd090ffbec89ccedc135c1570c85b31e0345","frame_index":0,"kind":"data","monotonic_ns":309849735932916,"payload":{"event_type":"price_change","market":"0x779291bef19b6709f61e9764a954aafe9ffae488d50ae674aabdcb4f248006d5","price_changes":[{"asset_id":"8761897749749422724209054078244794145777693856614463256546737399611489089783","best_ask":"0.6","best_bid":"0.59","hash":"2c9027af78d1c502f77c30870e18cbea021d7f12","price":"0.49","side":"BUY","size":"223"},{"asset_id":"14965588658799411272385430903075831224615961675357217884735713260981483529984","best_ask":"0.41","best_bid":"0.4","hash":"47f612249a4417615e552cfde2c965adbc6c3a6d","price":"0.51","side":"SELL","size":"223"}],"timestamp":"1785207866664"},"payload_hash":"43a7b04f9614f066d6cfd4040845a502438d95f01c37beab7a561b06a42282a8","raw_frame":"{\"market\":\"0x779291bef19b6709f61e9764a954aafe9ffae488d50ae674aabdcb4f248006d5\", \"price_changes\":[{\"asset_id\":\"8761897749749422724209054078244794145777693856614463256546737399611489089783\", \"price\":\"0.49\", \"size\":\"223\", \"side\":\"BUY\", \"hash\":\"2c9027af78d1c502f77c30870e18cbea021d7f12\", \"best_bid\":\"0.59\", \"best_ask\":\"0.6\"}, {\"asset_id\":\"14965588658799411272385430903075831224615961675357217884735713260981483529984\", \"price\":\"0.51\", \"size\":\"223\", \"side\":\"SELL\", \"hash\":\"47f612249a4417615e552cfde2c965adbc6c3a6d\", \"best_bid\":\"0.4\", \"best_ask\":\"0.41\"}], \"timestamp\":\"1785207866664\", \"event_type\":\"price_change\"}","received_at":"2026-07-28T03:04:26.709981Z","schema_version":"clob-market-ws.price_change.v1","sequence":null,"server_hash":null,"server_timestamp":"1785207866664","session_id":"3e519d9098404c15b234d96025eb1a2b","source":"clob_market_ws"},"received_at":"2026-07-28T03:04:26.709981Z","record_id":"7a863851e99bbe64ea7cf67c2dc9b288bf5afbaf2c845f5d75957eb5775551db","schema_fingerprint":"4aa3821a28b0b7c2400bc59aba4bcc0a76e971dadd19610d3ad38c768e124dc7","schema_version":"edge-lab-recorder.raw.v1","sequence":null,"source":"clob_market_ws"}
{"event_at":"2026-07-28T03:04:26.667000Z","event_fingerprint":"7dbbf6598efdfb74c93e08d122f37e1bc0c1249aa2291b5b71849f85e59891e1","payload":{"connection_id":"a6b55582af5f430fb37ad02bf0922475","event_at":"2026-07-28T03:04:26.667000Z","event_type":"price_change","frame_hash":"ed771dee27d7b5ffd7a6c75c2a0bc340c2aac7afe4c43dd8d48822523cdbfeb2","frame_index":0,"kind":"data","monotonic_ns":309849737367500,"payload":{"event_type":"price_change","market":"0x779291bef19b6709f61e9764a954aafe9ffae488d50ae674aabdcb4f248006d5","price_changes":[{"asset_id":"8761897749749422724209054078244794145777693856614463256546737399611489089783","best_ask":"0.6","best_bid":"0.59","hash":"a6e83c31260379d7c4ffe87a435f8ddd230f55fd","price":"0.59","side":"BUY","size":"116.2"},{"asset_id":"14965588658799411272385430903075831224615961675357217884735713260981483529984","best_ask":"0.41","best_bid":"0.4","hash":"ef37f155d6aa60d2b2cfa3d502e41319bbe4d183","price":"0.41","side":"SELL","size":"116.2"}],"timestamp":"1785207866667"},"payload_hash":"a93571b02335a50dda38d66f622d98fa2e302208ecbac03519edd4de6783659e","raw_frame":"{\"market\":\"0x779291bef19b6709f61e9764a954aafe9ffae488d50ae674aabdcb4f248006d5\", \"price_changes\":[{\"asset_id\":\"8761897749749422724209054078244794145777693856614463256546737399611489089783\", \"price\":\"0.59\", \"size\":\"116.2\", \"side\":\"BUY\", \"hash\":\"a6e83c31260379d7c4ffe87a435f8ddd230f55fd\", \"best_bid\":\"0.59\", \"best_ask\":\"0.6\"}, {\"asset_id\":\"14965588658799411272385430903075831224615961675357217884735713260981483529984\", \"price\":\"0.41\", \"size\":\"116.2\", \"side\":\"SELL\", \"hash\":\"ef37f155d6aa60d2b2cfa3d502e41319bbe4d183\", \"best_bid\":\"0.4\", \"best_ask\":\"0.41\"}], \"timestamp\":\"1785207866667\", \"event_type\":\"price_change\"}","received_at":"2026-07-28T03:04:26.711416Z","schema_version":"clob-market-ws.price_change.v1","sequence":null,"server_hash":null,"server_timestamp":"1785207866667","session_id":"3e519d9098404c15b234d96025eb1a2b","source":"clob_market_ws"},"received_at":"2026-07-28T03:04:26.711416Z","record_id":"e4a7ec53ffcc4c6eaa53e695a48a7a2e4cfad2bfb86283e14e8ff6acdff3b10a","schema_fingerprint":"4aa3821a28b0b7c2400bc59aba4bcc0a76e971dadd19610d3ad38c768e124dc7","schema_version":"edge-lab-recorder.raw.v1","sequence":null,"source":"clob_market_ws"}
{"event_at":"2026-07-28T03:04:26.672000Z","event_fingerprint":"898ed16b21a3cd084a0efeed59e3c32b6c80e0914111bd2ab25d82b6a2d46b0f","payload":{"connection_id":"a6b55582af5f430fb37ad02bf0922475","event_at":"2026-07-28T03:04:26.672000Z","event_type":"price_change","frame_hash":"45c7b298cad5244dd21ecd20f33625c9815e42a4bfaa7f26e49b10c3458b27a7","frame_index":0,"kind":"data","monotonic_ns":309849738844250,"payload":{"event_type":"price_change","market":"0x779291bef19b6709f61e9764a954aafe9ffae488d50ae674aabdcb4f248006d5","price_changes":[{"asset_id":"8761897749749422724209054078244794145777693856614463256546737399611489089783","best_ask":"0.6","best_bid":"0.59","hash":"3f4db10e658594cacf23fa2059f94af8171ed648","price":"0.59","side":"BUY","size":"121.2"},{"asset_id":"14965588658799411272385430903075831224615961675357217884735713260981483529984","best_ask":"0.41","best_bid":"0.4","hash":"e786f21c897b7053e4d99d794db64279e0a368b5","price":"0.41","side":"SELL","size":"121.2"}],"timestamp":"1785207866672"},"payload_hash":"e13ddc010039d1747f46d7b72ed31b802ac0414a28b4c15fc8bcff852499fb52","raw_frame":"{\"market\":\"0x779291bef19b6709f61e9764a954aafe9ffae488d50ae674aabdcb4f248006d5\", \"price_changes\":[{\"asset_id\":\"8761897749749422724209054078244794145777693856614463256546737399611489089783\", \"price\":\"0.59\", \"size\":\"121.2\", \"side\":\"BUY\", \"hash\":\"3f4db10e658594cacf23fa2059f94af8171ed648\", \"best_bid\":\"0.59\", \"best_ask\":\"0.6\"}, {\"asset_id\":\"14965588658799411272385430903075831224615961675357217884735713260981483529984\", \"price\":\"0.41\", \"size\":\"121.2\", \"side\":\"SELL\", \"hash\":\"e786f21c897b7053e4d99d794db64279e0a368b5\", \"best_bid\":\"0.4\", \"best_ask\":\"0.41\"}], \"timestamp\":\"1785207866672\", \"event_type\":\"price_change\"}","received_at":"2026-07-28T03:04:26.712892Z","schema_version":"clob-market-ws.price_change.v1","sequence":null,"server_hash":null,"server_timestamp":"1785207866672","session_id":"3e519d9098404c15b234d96025eb1a2b","source":"clob_market_ws"},"received_at":"2026-07-28T03:04:26.712892Z","record_id":"3e78f60091398defac5a8480445b359c13cb77ef26b079d4b12e118439baaaff","schema_fingerprint":"4aa3821a28b0b7c2400bc59aba4bcc0a76e971dadd19610d3ad38c768e124dc7","schema_version":"edge-lab-recorder.raw.v1","sequence":null,"source":"clob_market_ws"}
{"event_at":"2026-07-28T03:04:26.673000Z","event_fingerprint":"63edc3a5f7ec5ce978cb52046bb3a34b81b5bd0d59e47a0bba024979d03a35e4","payload":{"connection_id":"a6b55582af5f430fb37ad02bf0922475","event_at":"2026-07-28T03:04:26.673000Z","event_type":"price_change","frame_hash":"81e231afd87c05a604171fd79be24c7e7a9e2b06e43fd795de6e244b6753f36d","frame_index":0,"kind":"data","monotonic_ns":309849740279541,"payload":{"event_type":"price_change","market":"0x779291bef19b6709f61e9764a954aafe9ffae488d50ae674aabdcb4f248006d5","price_changes":[{"asset_id":"14965588658799411272385430903075831224615961675357217884735713260981483529984","best_ask":"0.41","best_bid":"0.4","hash":"403c7c1b63f456c875426717e22eeebd3c40d5bb","price":"0.37","side":"BUY","size":"501"},{"asset_id":"8761897749749422724209054078244794145777693856614463256546737399611489089783","best_ask":"0.6","best_bid":"0.59","hash":"32033e52601cea6efde742f71898a6331f3c30ef","price":"0.63","side":"SELL","size":"501"}],"timestamp":"1785207866673"},"payload_hash":"04d484220283e1de78c815792e8181137fdce221357264d31c62a1ccfb2dcfc6","raw_frame":"{\"market\":\"0x779291bef19b6709f61e9764a954aafe9ffae488d50ae674aabdcb4f248006d5\", \"price_changes\":[{\"asset_id\":\"14965588658799411272385430903075831224615961675357217884735713260981483529984\", \"price\":\"0.37\", \"size\":\"501\", \"side\":\"BUY\", \"hash\":\"403c7c1b63f456c875426717e22eeebd3c40d5bb\", \"best_bid\":\"0.4\", \"best_ask\":\"0.41\"}, {\"asset_id\":\"8761897749749422724209054078244794145777693856614463256546737399611489089783\", \"price\":\"0.63\", \"size\":\"501\", \"side\":\"SELL\", \"hash\":\"32033e52601cea6efde742f71898a6331f3c30ef\", \"best_bid\":\"0.59\", \"best_ask\":\"0.6\"}], \"timestamp\":\"1785207866673\", \"event_type\":\"price_change\"}","received_at":"2026-07-28T03:04:26.714327Z","schema_version":"clob-market-ws.price_change.v1","sequence":null,"server_hash":null,"server_timestamp":"1785207866673","session_id":"3e519d9098404c15b234d96025eb1a2b","source":"clob_market_ws"},"received_at":"2026-07-28T03:04:26.714327Z","record_id":"66501add39fdad32066646a174afd709866b0c1b02f288747f41a76870af63b4","schema_fingerprint":"4aa3821a28b0b7c2400bc59aba4bcc0a76e971dadd19610d3ad38c768e124dc7","schema_version":"edge-lab-recorder.raw.v1","sequence":null,"source":"clob_market_ws"}
{"event_at":"2026-07-28T03:04:26.674000Z","event_fingerprint":"1d2889e4450ac2fa4a245bd3b057e4fb5081552d247450d62e402a34698642ce","payload":{"connection_id":"a6b55582af5f430fb37ad02bf0922475","event_at":"2026-07-28T03:04:26.674000Z","event_type":"price_change","frame_hash":"da1c79943bb9b26b6a6c1e0a7148601dca01451ee5df27471dcdcb84ae8f8cac","frame_index":0,"kind":"data","monotonic_ns":309849741702000,"payload":{"event_type":"price_change","market":"0x779291bef19b6709f61e9764a954aafe9ffae488d50ae674aabdcb4f248006d5","price_changes":[{"asset_id":"8761897749749422724209054078244794145777693856614463256546737399611489089783","best_ask":"0.6","best_bid":"0.59","hash":"8934ffda298b7a0d993cc2d4fd3383729a69d72c","price":"0.54","side":"BUY","size":"148.64"},{"asset_id":"14965588658799411272385430903075831224615961675357217884735713260981483529984","best_ask":"0.41","best_bid":"0.4","hash":"8a3197efa2d03ae9b07f32daf7a740aaca33b81a","price":"0.46","side":"SELL","size":"148.64"}],"timestamp":"1785207866674"},"payload_hash":"207c35f16e05ec81987d48e07327ba4c5775a0a275df5dd904c9c70ce420f419","raw_frame":"{\"market\":\"0x779291bef19b6709f61e9764a954aafe9ffae488d50ae674aabdcb4f248006d5\", \"price_changes\":[{\"asset_id\":\"8761897749749422724209054078244794145777693856614463256546737399611489089783\", \"price\":\"0.54\", \"size\":\"148.64\", \"side\":\"BUY\", \"hash\":\"8934ffda298b7a0d993cc2d4fd3383729a69d72c\", \"best_bid\":\"0.59\", \"best_ask\":\"0.6\"}, {\"asset_id\":\"14965588658799411272385430903075831224615961675357217884735713260981483529984\", \"price\":\"0.46\", \"size\":\"148.64\", \"side\":\"SELL\", \"hash\":\"8a3197efa2d03ae9b07f32daf7a740aaca33b81a\", \"best_bid\":\"0.4\", \"best_ask\":\"0.41\"}], \"timestamp\":\"1785207866674\", \"event_type\":\"price_change\"}","received_at":"2026-07-28T03:04:26.715748Z","schema_version":"clob-market-ws.price_change.v1","sequence":null,"server_hash":null,"server_timestamp":"1785207866674","session_id":"3e519d9098404c15b234d96025eb1a2b","source":"clob_market_ws"},"received_at":"2026-07-28T03:04:26.715748Z","record_id":"a81a95ac6dd12617e0da8cca673570f21eda1f3bccc4b67263ced80aac9d1250","schema_fingerprint":"4aa3821a28b0b7c2400bc59aba4bcc0a76e971dadd19610d3ad38c768e124dc7","schema_version":"edge-lab-recorder.raw.v1","sequence":null,"source":"clob_market_ws"}
{"event_at":"2026-07-28T03:04:26.674000Z","event_fingerprint":"24b85be69f2cf76ff614a14766828a8d3ab509a9c39d96cc8d81fb24a3f51e2e","payload":{"connection_id":"a6b55582af5f430fb37ad02bf0922475","event_at":"2026-07-28T03:04:26.674000Z","event_type":"price_change","frame_hash":"fddd8c902413898e5646f966b9c0a4b495127619a7fb475c68d4977cdbffe36e","frame_index":0,"kind":"data","monotonic_ns":309849743161458,"payload":{"event_type":"price_change","market":"0x779291bef19b6709f61e9764a954aafe9ffae488d50ae674aabdcb4f248006d5","price_changes":[{"asset_id":"8761897749749422724209054078244794145777693856614463256546737399611489089783","best_ask":"0.6","best_bid":"0.59","hash":"92e3146efcc64a819c25428ededd05fb155447ee","price":"0.41","side":"BUY","size":"158.77"},{"asset_id":"14965588658799411272385430903075831224615961675357217884735713260981483529984","best_ask":"0.41","best_bid":"0.4","hash":"2702adadb117a21ce1c00a83a89d296b836ce4eb","price":"0.59","side":"SELL","size":"158.77"}],"timestamp":"1785207866674"},"payload_hash":"53f7c876d713b81025b42fbf35055a4321579e2d101d242f153ba9d594490c72","raw_frame":"{\"market\":\"0x779291bef19b6709f61e9764a954aafe9ffae488d50ae674aabdcb4f248006d5\", \"price_changes\":[{\"asset_id\":\"8761897749749422724209054078244794145777693856614463256546737399611489089783\", \"price\":\"0.41\", \"size\":\"158.77\", \"side\":\"BUY\", \"hash\":\"92e3146efcc64a819c25428ededd05fb155447ee\", \"best_bid\":\"0.59\", \"best_ask\":\"0.6\"}, {\"asset_id\":\"14965588658799411272385430903075831224615961675357217884735713260981483529984\", \"price\":\"0.59\", \"size\":\"158.77\", \"side\":\"SELL\", \"hash\":\"2702adadb117a21ce1c00a83a89d296b836ce4eb\", \"best_bid\":\"0.4\", \"best_ask\":\"0.41\"}], \"timestamp\":\"1785207866674\", \"event_type\":\"price_change\"}","received_at":"2026-07-28T03:04:26.717208Z","schema_version":"clob-market-ws.price_change.v1","sequence":null,"server_hash":null,"server_timestamp":"1785207866674","session_id":"3e519d9098404c15b234d96025eb1a2b","source":"clob_market_ws"},"received_at":"2026-07-28T03:04:26.717208Z","record_id":"aac8fe5e07dd33935527ab36ab11a27da18e891fe591a47c15524a898b2f79a5","schema_fingerprint":"4aa3821a28b0b7c2400bc59aba4bcc0a76e971dadd19610d3ad38c768e124dc7","schema_version":"edge-lab-recorder.raw.v1","sequence":null,"source":"clob_market_ws"}
{"event_at":"2026-07-28T03:04:26.676000Z","event_fingerprint":"c1d50b4f15e853c6f7718a35231507b4de1bba10baece6c9ba3079da758abd7f","payload":{"connection_id":"a6b55582af5f430fb37ad02bf0922475","event_at":"2026-07-28T03:04:26.676000Z","event_type":"price_change","frame_hash":"aed660ab88a5943c7ff76f6941e72d9ac61e8c1cea6910cbd31c0d3c43a97ca0","frame_index":0,"kind":"data","monotonic_ns":309849744580166,"payload":{"event_type":"price_change","market":"0x779291bef19b6709f61e9764a954aafe9ffae488d50ae674aabdcb4f248006d5","price_changes":[{"asset_id":"14965588658799411272385430903075831224615961675357217884735713260981483529984","best_ask":"0.41","best_bid":"0.4","hash":"4adab56056a95302ff6a409af1bbdb6d47489c1f","price":"0.39","side":"BUY","size":"35"},{"asset_id":"8761897749749422724209054078244794145777693856614463256546737399611489089783","best_ask":"0.6","best_bid":"0.59","hash":"8d23116b633ed93ab6db05ab3b8f154a7c8b961f","price":"0.61","side":"SELL","size":"35"}],"timestamp":"1785207866676"},"payload_hash":"e800ed08138db3b7f53ac4391eea9719e69f1ccdb1df9f76f35cca916c34b0e2","raw_frame":"{\"market\":\"0x779291bef19b6709f61e9764a954aafe9ffae488d50ae674aabdcb4f248006d5\", \"price_changes\":[{\"asset_id\":\"14965588658799411272385430903075831224615961675357217884735713260981483529984\", \"price\":\"0.39\", \"size\":\"35\", \"side\":\"BUY\", \"hash\":\"4adab56056a95302ff6a409af1bbdb6d47489c1f\", \"best_bid\":\"0.4\", \"best_ask\":\"0.41\"}, {\"asset_id\":\"8761897749749422724209054078244794145777693856614463256546737399611489089783\", \"price\":\"0.61\", \"size\":\"35\", \"side\":\"SELL\", \"hash\":\"8d23116b633ed93ab6db05ab3b8f154a7c8b961f\", \"best_bid\":\"0.59\", \"best_ask\":\"0.6\"}], \"timestamp\":\"1785207866676\", \"event_type\":\"price_change\"}","received_at":"2026-07-28T03:04:26.718626Z","schema_version":"clob-market-ws.price_change.v1","sequence":null,"server_hash":null,"server_timestamp":"1785207866676","session_id":"3e519d9098404c15b234d96025eb1a2b","source":"clob_market_ws"},"received_at":"2026-07-28T03:04:26.718626Z","record_id":"0c494858c648391aa63f22eafd83bdd890bb67b19e6b894ad63029cf48e310ab","schema_fingerprint":"4aa3821a28b0b7c2400bc59aba4bcc0a76e971dadd19610d3ad38c768e124dc7","schema_version":"edge-lab-recorder.raw.v1","sequence":null,"source":"clob_market_ws"}
{"event_at":"2026-07-28T03:04:26.684000Z","event_fingerprint":"a17ff11a586516b26f031a3fb9c816c259968aebf4569d9cf40d560bfdd01d57","payload":{"connection_id":"a6b55582af5f430fb37ad02bf0922475","event_at":"2026-07-28T03:04:26.684000Z","event_type":"price_change","frame_hash":"8ca6090dcfdb2df72960948f442fd7171ad1810c99604923f1b98841a7dd7a15","frame_index":0,"kind":"data","monotonic_ns":309849746010375,"payload":{"event_type":"price_change","market":"0x779291bef19b6709f61e9764a954aafe9ffae488d50ae674aabdcb4f248006d5","price_changes":[{"asset_id":"14965588658799411272385430903075831224615961675357217884735713260981483529984","best_ask":"0.41","best_bid":"0.4","hash":"c327e96c539247c6cb5e40fe2908aa50e811b73d","price":"0.38","side":"BUY","size":"105.6"},{"asset_id":"8761897749749422724209054078244794145777693856614463256546737399611489089783","best_ask":"0.6","best_bid":"0.59","hash":"5881b6c30a1ad66346440ff959699f6d4281a21b","price":"0.62","side":"SELL","size":"105.6"}],"timestamp":"1785207866684"},"payload_hash":"f4963325b691644b3bafb6109bf81e513931427bc3929d6e927f9b468a1fa8d9","raw_frame":"{\"market\":\"0x779291bef19b6709f61e9764a954aafe9ffae488d50ae674aabdcb4f248006d5\", \"price_changes\":[{\"asset_id\":\"14965588658799411272385430903075831224615961675357217884735713260981483529984\", \"price\":\"0.38\", \"size\":\"105.6\", \"side\":\"BUY\", \"hash\":\"c327e96c539247c6cb5e40fe2908aa50e811b73d\", \"best_bid\":\"0.4\", \"best_ask\":\"0.41\"}, {\"asset_id\":\"8761897749749422724209054078244794145777693856614463256546737399611489089783\", \"price\":\"0.62\", \"size\":\"105.6\", \"side\":\"SELL\", \"hash\":\"5881b6c30a1ad66346440ff959699f6d4281a21b\", \"best_bid\":\"0.59\", \"best_ask\":\"0.6\"}], \"timestamp\":\"1785207866684\", \"event_type\":\"price_change\"}","received_at":"2026-07-28T03:04:26.720056Z","schema_version":"clob-market-ws.price_change.v1","sequence":null,"server_hash":null,"server_timestamp":"1785207866684","session_id":"3e519d9098404c15b234d96025eb1a2b","source":"clob_market_ws"},"received_at":"2026-07-28T03:04:26.720056Z","record_id":"615917cc52f19ca2326d2362e16e05bdd97a4bc2f632824fc28989c4095bc3b0","schema_fingerprint":"4aa3821a28b0b7c2400bc59aba4bcc0a76e971dadd19610d3ad38c768e124dc7","schema_version":"edge-lab-recorder.raw.v1","sequence":null,"source":"clob_market_ws"}
{"event_at":"2026-07-28T03:04:26.691000Z","event_fingerprint":"3389b8a541abe99365f611196fb31dd9571b9ed6eddf693327d82e2d7c8c06ca","payload":{"connection_id":"a6b55582af5f430fb37ad02bf0922475","event_at":"2026-07-28T03:04:26.691000Z","event_type":"price_change","frame_hash":"ca74bbfd2a370dd708c57ab38495a74358e82d67986c8d24182dd8d8a50e5e00","frame_index":0,"kind":"data","monotonic_ns":309849747432750,"payload":{"event_type":"price_change","market":"0x779291bef19b6709f61e9764a954aafe9ffae488d50ae674aabdcb4f248006d5","price_changes":[{"asset_id":"8761897749749422724209054078244794145777693856614463256546737399611489089783","best_ask":"0.6","best_bid":"0.59","hash":"8ea0001104d1ec28999804ccfc49934b44fa943c","price":"0.54","side":"BUY","size":"136.04"},{"asset_id":"14965588658799411272385430903075831224615961675357217884735713260981483529984","best_ask":"0.41","best_bid":"0.4","hash":"5bf76d9a78f947013c23efed370de7d481ce6489","price":"0.46","side":"SELL","size":"136.04"}],"timestamp":"1785207866691"},"payload_hash":"57ef085cdeb5b54baa04b849d10e9cbdfaa03271451afe8ef464aaa03e8dbe7b","raw_frame":"{\"market\":\"0x779291bef19b6709f61e9764a954aafe9ffae488d50ae674aabdcb4f248006d5\", \"price_changes\":[{\"asset_id\":\"8761897749749422724209054078244794145777693856614463256546737399611489089783\", \"price\":\"0.54\", \"size\":\"136.04\", \"side\":\"BUY\", \"hash\":\"8ea0001104d1ec28999804ccfc49934b44fa943c\", \"best_bid\":\"0.59\", \"best_ask\":\"0.6\"}, {\"asset_id\":\"14965588658799411272385430903075831224615961675357217884735713260981483529984\", \"price\":\"0.46\", \"size\":\"136.04\", \"side\":\"SELL\", \"hash\":\"5bf76d9a78f947013c23efed370de7d481ce6489\", \"best_bid\":\"0.4\", \"best_ask\":\"0.41\"}], \"timestamp\":\"1785207866691\", \"event_type\":\"price_change\"}","received_at":"2026-07-28T03:04:26.721478Z","schema_version":"clob-market-ws.price_change.v1","sequence":null,"server_hash":null,"server_timestamp":"1785207866691","session_id":"3e519d9098404c15b234d96025eb1a2b","source":"clob_market_ws"},"received_at":"2026-07-28T03:04:26.721478Z","record_id":"1fc9201b546615190ed95b07cdb81f7b389f64e1b5d38487d0a0eb2b41ca5b22","schema_fingerprint":"4aa3821a28b0b7c2400bc59aba4bcc0a76e971dadd19610d3ad38c768e124dc7","schema_version":"edge-lab-recorder.raw.v1","sequence":null,"source":"clob_market_ws"}
{"event_at":"2026-07-28T03:04:26.692000Z","event_fingerprint":"8bf22f0abf707020e7feb39c519276c640a757d8b680c3efc880c9dce73b99ef","payload":{"connection_id":"a6b55582af5f430fb37ad02bf0922475","event_at":"2026-07-28T03:04:26.692000Z","event_type":"price_change","frame_hash":"abdf4085668a67f41a1c35d66e6340e69332e3be657733ef42c7d6723308d749","frame_index":0,"kind":"data","monotonic_ns":309849748871541,"payload":{"event_type":"price_change","market":"0x779291bef19b6709f61e9764a954aafe9ffae488d50ae674aabdcb4f248006d5","price_changes":[{"asset_id":"14965588658799411272385430903075831224615961675357217884735713260981483529984","best_ask":"0.41","best_bid":"0.4","hash":"2d45aee9917cc6c23f4582a4f3d7eb2902d7ae65","price":"0.37","side":"BUY","size":"506"},{"asset_id":"8761897749749422724209054078244794145777693856614463256546737399611489089783","best_ask":"0.6","best_bid":"0.59","hash":"ffe53b9e7329f864bd43ba6d1f514b456e46e87d","price":"0.63","side":"SELL","size":"506"}],"timestamp":"1785207866692"},"payload_hash":"1bbf7747139f4d4c3d67ab93419dd396d0e873a7e1ae4eaa11024785d993c0f5","raw_frame":"{\"market\":\"0x779291bef19b6709f61e9764a954aafe9ffae488d50ae674aabdcb4f248006d5\", \"price_changes\":[{\"asset_id\":\"14965588658799411272385430903075831224615961675357217884735713260981483529984\", \"price\":\"0.37\", \"size\":\"506\", \"side\":\"BUY\", \"hash\":\"2d45aee9917cc6c23f4582a4f3d7eb2902d7ae65\", \"best_bid\":\"0.4\", \"best_ask\":\"0.41\"}, {\"asset_id\":\"8761897749749422724209054078244794145777693856614463256546737399611489089783\", \"price\":\"0.63\", \"size\":\"506\", \"side\":\"SELL\", \"hash\":\"ffe53b9e7329f864bd43ba6d1f514b456e46e87d\", \"best_bid\":\"0.59\", \"best_ask\":\"0.6\"}], \"timestamp\":\"1785207866692\", \"event_type\":\"price_change\"}","received_at":"2026-07-28T03:04:26.722916Z","schema_version":"clob-market-ws.price_change.v1","sequence":null,"server_hash":null,"server_timestamp":"1785207866692","session_id":"3e519d9098404c15b234d96025eb1a2b","source":"clob_market_ws"},"received_at":"2026-07-28T03:04:26.722916Z","record_id":"e4de620bf08f3b1aa06df423bfe43e891710d5848673641ba9f143676e14092d","schema_fingerprint":"4aa3821a28b0b7c2400bc59aba4bcc0a76e971dadd19610d3ad38c768e124dc7","schema_version":"edge-lab-recorder.raw.v1","sequence":null,"source":"clob_market_ws"}
{"event_at":"2026-07-28T03:04:26.692000Z","event_fingerprint":"3b232dd3c5c8309e2ebb6c7c059b6f3f5e15c87508bcbaca6f296ecf2e0f4570","payload":{"connection_id":"a6b55582af5f430fb37ad02bf0922475","event_at":"2026-07-28T03:04:26.692000Z","event_type":"price_change","frame_hash":"57054bc1f3767565318ac3cb9b1976e6e6ff8f6dd5ac47532fe20e7d011c47d0","frame_index":0,"kind":"data","monotonic_ns":309849750282583,"payload":{"event_type":"price_change","market":"0x779291bef19b6709f61e9764a954aafe9ffae488d50ae674aabdcb4f248006d5","price_changes":[{"asset_id":"8761897749749422724209054078244794145777693856614463256546737399611489089783","best_ask":"0.6","best_bid":"0.59","hash":"9c5e62c7ef3ef72fc38e747eeb4a7d8f6f7482d2","price":"0.01","side":"BUY","size":"5853.02"},{"asset_id":"14965588658799411272385430903075831224615961675357217884735713260981483529984","best_ask":"0.41","best_bid":"0.4","hash":"5b5de19756a0a5981551362b163831e46b0e781b","price":"0.99","side":"SELL","size":"5853.02"}],"timestamp":"1785207866692"},"payload_hash":"ce14d47af9e539e4ec4642441c207cbd16b2d8812497646e49f8434a76cd47a5","raw_frame":"{\"market\":\"0x779291bef19b6709f61e9764a954aafe9ffae488d50ae674aabdcb4f248006d5\", \"price_changes\":[{\"asset_id\":\"8761897749749422724209054078244794145777693856614463256546737399611489089783\", \"price\":\"0.01\", \"size\":\"5853.02\", \"side\":\"BUY\", \"hash\":\"9c5e62c7ef3ef72fc38e747eeb4a7d8f6f7482d2\", \"best_bid\":\"0.59\", \"best_ask\":\"0.6\"}, {\"asset_id\":\"14965588658799411272385430903075831224615961675357217884735713260981483529984\", \"price\":\"0.99\", \"size\":\"5853.02\", \"side\":\"SELL\", \"hash\":\"5b5de19756a0a5981551362b163831e46b0e781b\", \"best_bid\":\"0.4\", \"best_ask\":\"0.41\"}], \"timestamp\":\"1785207866692\", \"event_type\":\"price_change\"}","received_at":"2026-07-28T03:04:26.724327Z","schema_version":"clob-market-ws.price_change.v1","sequence":null,"server_hash":null,"server_timestamp":"1785207866692","session_id":"3e519d9098404c15b234d96025eb1a2b","source":"clob_market_ws"},"received_at":"2026-07-28T03:04:26.724327Z","record_id":"65a1f0f576109d94a498990e53a7d984ff23e644dc06336a37c70a2d2810d17a","schema_fingerprint":"4aa3821a28b0b7c2400bc59aba4bcc0a76e971dadd19610d3ad38c768e124dc7","schema_version":"edge-lab-recorder.raw.v1","sequence":null,"source":"clob_market_ws"}
{"event_at":"2026-07-28T03:04:26.693000Z","event_fingerprint":"0cae4cd8b414a4c7538f9991b638b8713747a2edb48801580fc2cf10a6107e9f","payload":{"connection_id":"a6b55582af5f430fb37ad02bf0922475","event_at":"2026-07-28T03:04:26.693000Z","event_type":"price_change","frame_hash":"8e0c97fd84c2ae39dbbbfd35d847568937c0cb8e359c9759f75709c691efe5ef","frame_index":0,"kind":"data","monotonic_ns":309849751714875,"payload":{"event_type":"price_change","market":"0x779291bef19b6709f61e9764a954aafe9ffae488d50ae674aabdcb4f248006d5","price_changes":[{"asset_id":"8761897749749422724209054078244794145777693856614463256546737399611489089783","best_ask":"0.6","best_bid":"0.59","hash":"60fdd7635025b40c28170f758de2f36c98faac41","price":"0.59","side":"BUY","size":"81.2"},{"asset_id":"14965588658799411272385430903075831224615961675357217884735713260981483529984","best_ask":"0.41","best_bid":"0.4","hash":"079ee21fd58b6757b6ed8d5a27876d2a0bfdbf7c","price":"0.41","side":"SELL","size":"81.2"}],"timestamp":"1785207866693"},"payload_hash":"f6d0caf1d0a47eb227fb5a1a4f0b4f0c2cd675bc02eefbfd2174ddcc6a39c915","raw_frame":"{\"market\":\"0x779291bef19b6709f61e9764a954aafe9ffae488d50ae674aabdcb4f248006d5\", \"price_changes\":[{\"asset_id\":\"8761897749749422724209054078244794145777693856614463256546737399611489089783\", \"price\":\"0.59\", \"size\":\"81.2\", \"side\":\"BUY\", \"hash\":\"60fdd7635025b40c28170f758de2f36c98faac41\", \"best_bid\":\"0.59\", \"best_ask\":\"0.6\"}, {\"asset_id\":\"14965588658799411272385430903075831224615961675357217884735713260981483529984\", \"price\":\"0.41\", \"size\":\"81.2\", \"side\":\"SELL\", \"hash\":\"079ee21fd58b6757b6ed8d5a27876d2a0bfdbf7c\", \"best_bid\":\"0.4\", \"best_ask\":\"0.41\"}], \"timestamp\":\"1785207866693\", \"event_type\":\"price_change\"}","received_at":"2026-07-28T03:04:26.725758Z","schema_version":"clob-market-ws.price_change.v1","sequence":null,"server_hash":null,"server_timestamp":"1785207866693","session_id":"3e519d9098404c15b234d96025eb1a2b","source":"clob_market_ws"},"received_at":"2026-07-28T03:04:26.725758Z","record_id":"0bcf38f94eb93e321fe6d710d98e3e262db012426886d13ebb83e6bc6bcfb550","schema_fingerprint":"4aa3821a28b0b7c2400bc59aba4bcc0a76e971dadd19610d3ad38c768e124dc7","schema_version":"edge-lab-recorder.raw.v1","sequence":null,"source":"clob_market_ws"}
{"event_at":"2026-07-28T03:04:26.693000Z","event_fingerprint":"c283ff12a5a8f6e79b3a76e4814085f62480c145fd709104ad61a7e25ce73653","payload":{"connection_id":"a6b55582af5f430fb37ad02bf0922475","event_at":"2026-07-28T03:04:26.693000Z","event_type":"price_change","frame_hash":"94dd0bd308364ad8341168d65b4049b045377b099e90207dac83fb1da75e5d53","frame_index":0,"kind":"data","monotonic_ns":309849753133958,"payload":{"event_type":"price_change","market":"0x779291bef19b6709f61e9764a954aafe9ffae488d50ae674aabdcb4f248006d5","price_changes":[{"asset_id":"8761897749749422724209054078244794145777693856614463256546737399611489089783","best_ask":"0.6","best_bid":"0.59","hash":"03a24384bfff25a4790ad17ce3b4d3266b0bb3d7","price":"0.49","side":"BUY","size":"228"},{"asset_id":"14965588658799411272385430903075831224615961675357217884735713260981483529984","best_ask":"0.41","best_bid":"0.4","hash":"d40aa1fb173e7292b4285c9210086a8ebd016cd3","price":"0.51","side":"SELL","size":"228"}],"timestamp":"1785207866693"},"payload_hash":"76fe9a5d9f31d8be4c37d8479827b00f7e05ac134448bd0985abe8f0b61f0064","raw_frame":"{\"market\":\"0x779291bef19b6709f61e9764a954aafe9ffae488d50ae674aabdcb4f248006d5\", \"price_changes\":[{\"asset_id\":\"8761897749749422724209054078244794145777693856614463256546737399611489089783\", \"price\":\"0.49\", \"size\":\"228\", \"side\":\"BUY\", \"hash\":\"03a24384bfff25a4790ad17ce3b4d3266b0bb3d7\", \"best_bid\":\"0.59\", \"best_ask\":\"0.6\"}, {\"asset_id\":\"14965588658799411272385430903075831224615961675357217884735713260981483529984\", \"price\":\"0.51\", \"size\":\"228\", \"side\":\"SELL\", \"hash\":\"d40aa1fb173e7292b4285c9210086a8ebd016cd3\", \"best_bid\":\"0.4\", \"best_ask\":\"0.41\"}], \"timestamp\":\"1785207866693\", \"event_type\":\"price_change\"}","received_at":"2026-07-28T03:04:26.727177Z","schema_version":"clob-market-ws.price_change.v1","sequence":null,"server_hash":null,"server_timestamp":"1785207866693","session_id":"3e519d9098404c15b234d96025eb1a2b","source":"clob_market_ws"},"received_at":"2026-07-28T03:04:26.727177Z","record_id":"978921819513dd70c3ddba1f6c09b63ddd857c516f9502d0a8ad1d65a185289a","schema_fingerprint":"4aa3821a28b0b7c2400bc59aba4bcc0a76e971dadd19610d3ad38c768e124dc7","schema_version":"edge-lab-recorder.raw.v1","sequence":null,"source":"clob_market_ws"}
{"event_at":"2026-07-28T03:04:26.694000Z","event_fingerprint":"26211c5bb5f74f0d5ed9d96981d2fc2cda2e70c36e09bdafad8a39a125560809","payload":{"connection_id":"a6b55582af5f430fb37ad02bf0922475","event_at":"2026-07-28T03:04:26.694000Z","event_type":"price_change","frame_hash":"71a94ce0065d43a92052675d4abc181cc4add8112f20d2c6de4e1caee9b7adae","frame_index":0,"kind":"data","monotonic_ns":309849754554375,"payload":{"event_type":"price_change","market":"0x779291bef19b6709f61e9764a954aafe9ffae488d50ae674aabdcb4f248006d5","price_changes":[{"asset_id":"8761897749749422724209054078244794145777693856614463256546737399611489089783","best_ask":"0.6","best_bid":"0.59","hash":"9e9c935dc7f42b9776c81a0695c103bbe38978cd","price":"0.41","side":"BUY","size":"153.4"},{"asset_id":"14965588658799411272385430903075831224615961675357217884735713260981483529984","best_ask":"0.41","best_bid":"0.4","hash":"cd78a60d9b477fc880b7f8b2c5fdbc4ed948bca6","price":"0.59","side":"SELL","size":"153.4"}],"timestamp":"1785207866694"},"payload_hash":"8a438fc9cc1e81537e9c9b9f7c9f68455bd7ff8a3d7005669b829a8312ded9bc","raw_frame":"{\"market\":\"0x779291bef19b6709f61e9764a954aafe9ffae488d50ae674aabdcb4f248006d5\", \"price_changes\":[{\"asset_id\":\"8761897749749422724209054078244794145777693856614463256546737399611489089783\", \"price\":\"0.41\", \"size\":\"153.4\", \"side\":\"BUY\", \"hash\":\"9e9c935dc7f42b9776c81a0695c103bbe38978cd\", \"best_bid\":\"0.59\", \"best_ask\":\"0.6\"}, {\"asset_id\":\"14965588658799411272385430903075831224615961675357217884735713260981483529984\", \"price\":\"0.59\", \"size\":\"153.4\", \"side\":\"SELL\", \"hash\":\"cd78a60d9b477fc880b7f8b2c5fdbc4ed948bca6\", \"best_bid\":\"0.4\", \"best_ask\":\"0.41\"}], \"timestamp\":\"1785207866694\", \"event_type\":\"price_change\"}","received_at":"2026-07-28T03:04:26.728597Z","schema_version":"clob-market-ws.price_change.v1","sequence":null,"server_hash":null,"server_timestamp":"1785207866694","session_id":"3e519d9098404c15b234d96025eb1a2b","source":"clob_market_ws"},"received_at":"2026-07-28T03:04:26.728597Z","record_id":"b8cfcaf93f4bba741a9acf26258c5eb2d40e76110046f52f4357ca692c033323","schema_fingerprint":"4aa3821a28b0b7c2400bc59aba4bcc0a76e971dadd19610d3ad38c768e124dc7","schema_version":"edge-lab-recorder.raw.v1","sequence":null,"source":"clob_market_ws"}
{"event_at":"2026-07-28T03:04:26.694000Z","event_fingerprint":"1e0752b7b4b061bbd56baf814e1e641f2e0f287a1fa745aa1d28948d8a66701e","payload":{"connection_id":"a6b55582af5f430fb37ad02bf0922475","event_at":"2026-07-28T03:04:26.694000Z","event_type":"price_change","frame_hash":"798dfa5a64569a25e8f18a0e1ef9d7a58e36193dfbeb5efe712ae8c7d5d4a956","frame_index":0,"kind":"data","monotonic_ns":309849756004125,"payload":{"event_type":"price_change","market":"0x779291bef19b6709f61e9764a954aafe9ffae488d50ae674aabdcb4f248006d5","price_changes":[{"asset_id":"8761897749749422724209054078244794145777693856614463256546737399611489089783","best_ask":"0.6","best_bid":"0.59","hash":"7363a149a9728a387da2480a902f71a41cd25725","price":"0.59","side":"BUY","size":"111.2"},{"asset_id":"14965588658799411272385430903075831224615961675357217884735713260981483529984","best_ask":"0.41","best_bid":"0.4","hash":"b467ab10a6a64ef2a3e9129405e3a04da2ae2be2","price":"0.41","side":"SELL","size":"111.2"}],"timestamp":"1785207866694"},"payload_hash":"a48e084fa4e3271d36ca1747ea31262620f697e4cb63bd90cf2899cbeb9e61fd","raw_frame":"{\"market\":\"0x779291bef19b6709f61e9764a954aafe9ffae488d50ae674aabdcb4f248006d5\", \"price_changes\":[{\"asset_id\":\"8761897749749422724209054078244794145777693856614463256546737399611489089783\", \"price\":\"0.59\", \"size\":\"111.2\", \"side\":\"BUY\", \"hash\":\"7363a149a9728a387da2480a902f71a41cd25725\", \"best_bid\":\"0.59\", \"best_ask\":\"0.6\"}, {\"asset_id\":\"14965588658799411272385430903075831224615961675357217884735713260981483529984\", \"price\":\"0.41\", \"size\":\"111.2\", \"side\":\"SELL\", \"hash\":\"b467ab10a6a64ef2a3e9129405e3a04da2ae2be2\", \"best_bid\":\"0.4\", \"best_ask\":\"0.41\"}], \"timestamp\":\"1785207866694\", \"event_type\":\"price_change\"}","received_at":"2026-07-28T03:04:26.730046Z","schema_version":"clob-market-ws.price_change.v1","sequence":null,"server_hash":null,"server_timestamp":"1785207866694","session_id":"3e519d9098404c15b234d96025eb1a2b","source":"clob_market_ws"},"received_at":"2026-07-28T03:04:26.730046Z","record_id":"a1c8daabb661fc9ce470dd357dbd0fb998a3fb8955c7632f69efc19f8167fc72","schema_fingerprint":"4aa3821a28b0b7c2400bc59aba4bcc0a76e971dadd19610d3ad38c768e124dc7","schema_version":"edge-lab-recorder.raw.v1","sequence":null,"source":"clob_market_ws"}
{"event_at":"2026-07-28T03:04:26.695000Z","event_fingerprint":"fc126009eba70e33761470ddeb56507151d2a810e57caee87ca3b0037e6d69bb","payload":{"connection_id":"a6b55582af5f430fb37ad02bf0922475","event_at":"2026-07-28T03:04:26.695000Z","event_type":"price_change","frame_hash":"f754215212c09703fb257d794807d246cde6eb31de4567e58da04612a588e5e0","frame_index":0,"kind":"data","monotonic_ns":309849757421875,"payload":{"event_type":"price_change","market":"0x779291bef19b6709f61e9764a954aafe9ffae488d50ae674aabdcb4f248006d5","price_changes":[{"asset_id":"14965588658799411272385430903075831224615961675357217884735713260981483529984","best_ask":"0.41","best_bid":"0.4","hash":"fbbe8e5e13a5f48986caf2984c967dff616f1ff2","price":"0.39","side":"BUY","size":"30"},{"asset_id":"8761897749749422724209054078244794145777693856614463256546737399611489089783","best_ask":"0.6","best_bid":"0.59","hash":"e9d74638a75ebb2d0f86485531212dd656904230","price":"0.61","side":"SELL","size":"30"}],"timestamp":"1785207866695"},"payload_hash":"02743a544fb8d0071664c0fd220f2d0505867e175ba0c4401e8c2184ae4fe9ce","raw_frame":"{\"market\":\"0x779291bef19b6709f61e9764a954aafe9ffae488d50ae674aabdcb4f248006d5\", \"price_changes\":[{\"asset_id\":\"14965588658799411272385430903075831224615961675357217884735713260981483529984\", \"price\":\"0.39\", \"size\":\"30\", \"side\":\"BUY\", \"hash\":\"fbbe8e5e13a5f48986caf2984c967dff616f1ff2\", \"best_bid\":\"0.4\", \"best_ask\":\"0.41\"}, {\"asset_id\":\"8761897749749422724209054078244794145777693856614463256546737399611489089783\", \"price\":\"0.61\", \"size\":\"30\", \"side\":\"SELL\", \"hash\":\"e9d74638a75ebb2d0f86485531212dd656904230\", \"best_bid\":\"0.59\", \"best_ask\":\"0.6\"}], \"timestamp\":\"1785207866695\", \"event_type\":\"price_change\"}","received_at":"2026-07-28T03:04:26.731464Z","schema_version":"clob-market-ws.price_change.v1","sequence":null,"server_hash":null,"server_timestamp":"1785207866695","session_id":"3e519d9098404c15b234d96025eb1a2b","source":"clob_market_ws"},"received_at":"2026-07-28T03:04:26.731464Z","record_id":"8fb98e981f5da414f6fb112e9c1cc51d52bbda8178778242c5cd4b47dda70c97","schema_fingerprint":"4aa3821a28b0b7c2400bc59aba4bcc0a76e971dadd19610d3ad38c768e124dc7","schema_version":"edge-lab-recorder.raw.v1","sequence":null,"source":"clob_market_ws"}
{"event_at":"2026-07-28T03:04:26.695000Z","event_fingerprint":"e830c0dfb0653116d4e82eb8e636455a64ce54901fbd29428d4ad7ffb673923a","payload":{"connection_id":"a6b55582af5f430fb37ad02bf0922475","event_at":"2026-07-28T03:04:26.695000Z","event_type":"price_change","frame_hash":"940f044f53c5341d23e1b59316c2b0f926347b913b918a7dcc23c11ca3726068","frame_index":0,"kind":"data","monotonic_ns":309849758858583,"payload":{"event_type":"price_change","market":"0x779291bef19b6709f61e9764a954aafe9ffae488d50ae674aabdcb4f248006d5","price_changes":[{"asset_id":"14965588658799411272385430903075831224615961675357217884735713260981483529984","best_ask":"0.41","best_bid":"0.4","hash":"17ccf186f8523cadd9cabbe0040b75ab95b61f50","price":"0.3","side":"BUY","size":"220"},{"asset_id":"8761897749749422724209054078244794145777693856614463256546737399611489089783","best_ask":"0.6","best_bid":"0.59","hash":"5c48ebde77d338c1166e39a5ac90d0a438a0f49a","price":"0.7","side":"SELL","size":"220"}],"timestamp":"1785207866695"},"payload_hash":"d21dae3fc006902b7d43e55b8d01e515798b58deea6690925e291ae0b563890d","raw_frame":"{\"market\":\"0x779291bef19b6709f61e9764a954aafe9ffae488d50ae674aabdcb4f248006d5\", \"price_changes\":[{\"asset_id\":\"14965588658799411272385430903075831224615961675357217884735713260981483529984\", \"price\":\"0.3\", \"size\":\"220\", \"side\":\"BUY\", \"hash\":\"17ccf186f8523cadd9cabbe0040b75ab95b61f50\", \"best_bid\":\"0.4\", \"best_ask\":\"0.41\"}, {\"asset_id\":\"8761897749749422724209054078244794145777693856614463256546737399611489089783\", \"price\":\"0.7\", \"size\":\"220\", \"side\":\"SELL\", \"hash\":\"5c48ebde77d338c1166e39a5ac90d0a438a0f49a\", \"best_bid\":\"0.59\", \"best_ask\":\"0.6\"}], \"timestamp\":\"1785207866695\", \"event_type\":\"price_change\"}","received_at":"2026-07-28T03:04:26.732900Z","schema_version":"clob-market-ws.price_change.v1","sequence":null,"server_hash":null,"server_timestamp":"1785207866695","session_id":"3e519d9098404c15b234d96025eb1a2b","source":"clob_market_ws"},"received_at":"2026-07-28T03:04:26.732900Z","record_id":"53f214729f3bdb7e8c955de3885ae3a919e71dd81cfb154bbd5010b976695941","schema_fingerprint":"4aa3821a28b0b7c2400bc59aba4bcc0a76e971dadd19610d3ad38c768e124dc7","schema_version":"edge-lab-recorder.raw.v1","sequence":null,"source":"clob_market_ws"}
{"event_at":"2026-07-28T03:04:26.696000Z","event_fingerprint":"535f816b524c65e96a153b568a077f6f73412ae256b48ec9205a67a1d0a504e9","payload":{"connection_id":"a6b55582af5f430fb37ad02bf0922475","event_at":"2026-07-28T03:04:26.696000Z","event_type":"price_change","frame_hash":"5413b7df5d1d579adb0a0f694abb8a81565cb3b98c4d219268850d4efb2e229a","frame_index":0,"kind":"data","monotonic_ns":309849760280125,"payload":{"event_type":"price_change","market":"0x779291bef19b6709f61e9764a954aafe9ffae488d50ae674aabdcb4f248006d5","price_changes":[{"asset_id":"8761897749749422724209054078244794145777693856614463256546737399611489089783","best_ask":"0.6","best_bid":"0.59","hash":"761f0865a831f089fca30a16c50bed21ae7a08a1","price":"0.57","side":"BUY","size":"142.35"},{"asset_id":"14965588658799411272385430903075831224615961675357217884735713260981483529984","best_ask":"0.41","best_bid":"0.4","hash":"f9ae6c419a70304774e6c3d93e3798d6a1b22558","price":"0.43","side":"SELL","size":"142.35"}],"timestamp":"1785207866696"},"payload_hash":"9fbd7546839d91095272f36571cfe04cf5b10d4fa087e88c8b5b058c40dacad4","raw_frame":"{\"market\":\"0x779291bef19b6709f61e9764a954aafe9ffae488d50ae674aabdcb4f248006d5\", \"price_changes\":[{\"asset_id\":\"8761897749749422724209054078244794145777693856614463256546737399611489089783\", \"price\":\"0.57\", \"size\":\"142.35\", \"side\":\"BUY\", \"hash\":\"761f0865a831f089fca30a16c50bed21ae7a08a1\", \"best_bid\":\"0.59\", \"best_ask\":\"0.6\"}, {\"asset_id\":\"14965588658799411272385430903075831224615961675357217884735713260981483529984\", \"price\":\"0.43\", \"size\":\"142.35\", \"side\":\"SELL\", \"hash\":\"f9ae6c419a70304774e6c3d93e3798d6a1b22558\", \"best_bid\":\"0.4\", \"best_ask\":\"0.41\"}], \"timestamp\":\"1785207866696\", \"event_type\":\"price_change\"}","received_at":"2026-07-28T03:04:26.734321Z","schema_version":"clob-market-ws.price_change.v1","sequence":null,"server_hash":null,"server_timestamp":"1785207866696","session_id":"3e519d9098404c15b234d96025eb1a2b","source":"clob_market_ws"},"received_at":"2026-07-28T03:04:26.734321Z","record_id":"92a8cc6b1c89664585a447ce70b1a7d93ff82c0c39ea273e3677ea6556718c88","schema_fingerprint":"4aa3821a28b0b7c2400bc59aba4bcc0a76e971dadd19610d3ad38c768e124dc7","schema_version":"edge-lab-recorder.raw.v1","sequence":null,"source":"clob_market_ws"}
{"event_at":"2026-07-28T03:04:26.696000Z","event_fingerprint":"74838c2f42213a136e1283a81ab3e886fa7520cd48ff583109abe3fa9e07c91b","payload":{"connection_id":"a6b55582af5f430fb37ad02bf0922475","event_at":"2026-07-28T03:04:26.696000Z","event_type":"price_change","frame_hash":"1d4cd25d6801915cc0bc0c8d46600e889a3a3a3c74ea0ec7a1f1e6c0abc4324c","frame_index":0,"kind":"data","monotonic_ns":309849761720833,"payload":{"event_type":"price_change","market":"0x779291bef19b6709f61e9764a954aafe9ffae488d50ae674aabdcb4f248006d5","price_changes":[{"asset_id":"14965588658799411272385430903075831224615961675357217884735713260981483529984","best_ask":"0.41","best_bid":"0.4","hash":"a8639ba28d21757b18e73d5098e5463eb6e2937e","price":"0.37","side":"BUY","size":"500"},{"asset_id":"8761897749749422724209054078244794145777693856614463256546737399611489089783","best_ask":"0.6","best_bid":"0.59","hash":"38a79f3e2988e4403bf0c0499e000096097fb6e0","price":"0.63","side":"SELL","size":"500"}],"timestamp":"1785207866696"},"payload_hash":"306708661a51e3901840131431368a5a2add910488aa15a2c03cc9f4f201563c","raw_frame":"{\"market\":\"0x779291bef19b6709f61e9764a954aafe9ffae488d50ae674aabdcb4f248006d5\", \"price_changes\":[{\"asset_id\":\"14965588658799411272385430903075831224615961675357217884735713260981483529984\", \"price\":\"0.37\", \"size\":\"500\", \"side\":\"BUY\", \"hash\":\"a8639ba28d21757b18e73d5098e5463eb6e2937e\", \"best_bid\":\"0.4\", \"best_ask\":\"0.41\"}, {\"asset_id\":\"8761897749749422724209054078244794145777693856614463256546737399611489089783\", \"price\":\"0.63\", \"size\":\"500\", \"side\":\"SELL\", \"hash\":\"38a79f3e2988e4403bf0c0499e000096097fb6e0\", \"best_bid\":\"0.59\", \"best_ask\":\"0.6\"}], \"timestamp\":\"1785207866696\", \"event_type\":\"price_change\"}","received_at":"2026-07-28T03:04:26.735761Z","schema_version":"clob-market-ws.price_change.v1","sequence":null,"server_hash":null,"server_timestamp":"1785207866696","session_id":"3e519d9098404c15b234d96025eb1a2b","source":"clob_market_ws"},"received_at":"2026-07-28T03:04:26.735761Z","record_id":"fc2a53983c44a7e5b60c9f34642358f312d8dfb8a2bc2fad8df23c8e4b2539df","schema_fingerprint":"4aa3821a28b0b7c2400bc59aba4bcc0a76e971dadd19610d3ad38c768e124dc7","schema_version":"edge-lab-recorder.raw.v1","sequence":null,"source":"clob_market_ws"}
{"event_at":"2026-07-28T03:04:26.696000Z","event_fingerprint":"9921e0fb0b7f0a00526585790aee8f7374362cf0a40bf5aa588f67feb98d8fcd","payload":{"connection_id":"a6b55582af5f430fb37ad02bf0922475","event_at":"2026-07-28T03:04:26.696000Z","event_type":"price_change","frame_hash":"5427eb35392ed58d2985f3d50aa46260c229446a09b446a71199ed979b230466","frame_index":0,"kind":"data","monotonic_ns":309849763158375,"payload":{"event_type":"price_change","market":"0x779291bef19b6709f61e9764a954aafe9ffae488d50ae674aabdcb4f248006d5","price_changes":[{"asset_id":"8761897749749422724209054078244794145777693856614463256546737399611489089783","best_ask":"0.6","best_bid":"0.59","hash":"07b996b342e36eb26b89ff6e6b5198e6e0894a00","price":"0.57","side":"BUY","size":"137.35"},{"asset_id":"14965588658799411272385430903075831224615961675357217884735713260981483529984","best_ask":"0.41","best_bid":"0.4","hash":"85aaeb9797d8cfa2b183626b13cc97d461b8334a","price":"0.43","side":"SELL","size":"137.35"}],"timestamp":"1785207866696"},"payload_hash":"1f862b85e9b188a2d16d99b48b95238f841ca735ebe665c7c30abdca04c5373e","raw_frame":"{\"market\":\"0x779291bef19b6709f61e9764a954aafe9ffae488d50ae674aabdcb4f248006d5\", \"price_changes\":[{\"asset_id\":\"8761897749749422724209054078244794145777693856614463256546737399611489089783\", \"price\":\"0.57\", \"size\":\"137.35\", \"side\":\"BUY\", \"hash\":\"07b996b342e36eb26b89ff6e6b5198e6e0894a00\", \"best_bid\":\"0.59\", \"best_ask\":\"0.6\"}, {\"asset_id\":\"14965588658799411272385430903075831224615961675357217884735713260981483529984\", \"price\":\"0.43\", \"size\":\"137.35\", \"side\":\"SELL\", \"hash\":\"85aaeb9797d8cfa2b183626b13cc97d461b8334a\", \"best_bid\":\"0.4\", \"best_ask\":\"0.41\"}], \"timestamp\":\"1785207866696\", \"event_type\":\"price_change\"}","received_at":"2026-07-28T03:04:26.737198Z","schema_version":"clob-market-ws.price_change.v1","sequence":null,"server_hash":null,"server_timestamp":"1785207866696","session_id":"3e519d9098404c15b234d96025eb1a2b","source":"clob_market_ws"},"received_at":"2026-07-28T03:04:26.737198Z","record_id":"f426e5717afe2a471f9b12e5e3b2f5deef0665bbbbac534f58547c67247131d7","schema_fingerprint":"4aa3821a28b0b7c2400bc59aba4bcc0a76e971dadd19610d3ad38c768e124dc7","schema_version":"edge-lab-recorder.raw.v1","sequence":null,"source":"clob_market_ws"}
{"event_at":"2026-07-28T03:04:26.702000Z","event_fingerprint":"bd54832b5ce154bf5cb93ce3f5695da4999452a2d77a00075cc80472397dd100","payload":{"connection_id":"a6b55582af5f430fb37ad02bf0922475","event_at":"2026-07-28T03:04:26.702000Z","event_type":"price_change","frame_hash":"c86789f1ac73ad2197aac3779ab0a31088b65f96325d0d8fc2007d736e8a5a1a","frame_index":0,"kind":"data","monotonic_ns":309849764594250,"payload":{"event_type":"price_change","market":"0x779291bef19b6709f61e9764a954aafe9ffae488d50ae674aabdcb4f248006d5","price_changes":[{"asset_id":"14965588658799411272385430903075831224615961675357217884735713260981483529984","best_ask":"0.41","best_bid":"0.4","hash":"35c673eb49fedcccc58f419235c7bb180b239211","price":"0.25","side":"BUY","size":"109.5"},{"asset_id":"8761897749749422724209054078244794145777693856614463256546737399611489089783","best_ask":"0.6","best_bid":"0.59","hash":"cf2496dd0931209a4bbca3aed978f8208ffc1893","price":"0.75","side":"SELL","size":"109.5"}],"timestamp":"1785207866702"},"payload_hash":"ff12efd8ade1de94715d5264d24a8cc000edeba7f431967c0de35dbb1d65650b","raw_frame":"{\"market\":\"0x779291bef19b6709f61e9764a954aafe9ffae488d50ae674aabdcb4f248006d5\", \"price_changes\":[{\"asset_id\":\"14965588658799411272385430903075831224615961675357217884735713260981483529984\", \"price\":\"0.25\", \"size\":\"109.5\", \"side\":\"BUY\", \"hash\":\"35c673eb49fedcccc58f419235c7bb180b239211\", \"best_bid\":\"0.4\", \"best_ask\":\"0.41\"}, {\"asset_id\":\"8761897749749422724209054078244794145777693856614463256546737399611489089783\", \"price\":\"0.75\", \"size\":\"109.5\", \"side\":\"SELL\", \"hash\":\"cf2496dd0931209a4bbca3aed978f8208ffc1893\", \"best_bid\":\"0.59\", \"best_ask\":\"0.6\"}], \"timestamp\":\"1785207866702\", \"event_type\":\"price_change\"}","received_at":"2026-07-28T03:04:26.738634Z","schema_version":"clob-market-ws.price_change.v1","sequence":null,"server_hash":null,"server_timestamp":"1785207866702","session_id":"3e519d9098404c15b234d96025eb1a2b","source":"clob_market_ws"},"received_at":"2026-07-28T03:04:26.738634Z","record_id":"f14c5fab860da2db7bc67933f81497279e597b4bb19351b76996237e67a3bf65","schema_fingerprint":"4aa3821a28b0b7c2400bc59aba4bcc0a76e971dadd19610d3ad38c768e124dc7","schema_version":"edge-lab-recorder.raw.v1","sequence":null,"source":"clob_market_ws"}
{"event_at":"2026-07-28T03:04:26.703000Z","event_fingerprint":"8bb7da12525f9c2f1ac13ff025e5693a49e13cc7b7837115215e7ce705a5aa71","payload":{"connection_id":"a6b55582af5f430fb37ad02bf0922475","event_at":"2026-07-28T03:04:26.703000Z","event_type":"price_change","frame_hash":"821110a4d26af4aa624a41f69615548fbbedcfd111b72f9691ebb3bf80812105","frame_index":0,"kind":"data","monotonic_ns":309849766027791,"payload":{"event_type":"price_change","market":"0x779291bef19b6709f61e9764a954aafe9ffae488d50ae674aabdcb4f248006d5","price_changes":[{"asset_id":"14965588658799411272385430903075831224615961675357217884735713260981483529984","best_ask":"0.41","best_bid":"0.4","hash":"df1f4295555bdc79b2d4da8a69e525deb6a07c66","price":"0.39","side":"BUY","size":"10"},{"asset_id":"8761897749749422724209054078244794145777693856614463256546737399611489089783","best_ask":"0.6","best_bid":"0.59","hash":"d7cbc272fbdd05595323533c8830467b77e5d58f","price":"0.61","side":"SELL","size":"10"}],"timestamp":"1785207866703"},"payload_hash":"784958c6e4427b164e6cfbdc8b29674fed152e792b81fd4bffce6499e8b0a4b3","raw_frame":"{\"market\":\"0x779291bef19b6709f61e9764a954aafe9ffae488d50ae674aabdcb4f248006d5\", \"price_changes\":[{\"asset_id\":\"14965588658799411272385430903075831224615961675357217884735713260981483529984\", \"price\":\"0.39\", \"size\":\"10\", \"side\":\"BUY\", \"hash\":\"df1f4295555bdc79b2d4da8a69e525deb6a07c66\", \"best_bid\":\"0.4\", \"best_ask\":\"0.41\"}, {\"asset_id\":\"8761897749749422724209054078244794145777693856614463256546737399611489089783\", \"price\":\"0.61\", \"size\":\"10\", \"side\":\"SELL\", \"hash\":\"d7cbc272fbdd05595323533c8830467b77e5d58f\", \"best_bid\":\"0.59\", \"best_ask\":\"0.6\"}], \"timestamp\":\"1785207866703\", \"event_type\":\"price_change\"}","received_at":"2026-07-28T03:04:26.740067Z","schema_version":"clob-market-ws.price_change.v1","sequence":null,"server_hash":null,"server_timestamp":"1785207866703","session_id":"3e519d9098404c15b234d96025eb1a2b","source":"clob_market_ws"},"received_at":"2026-07-28T03:04:26.740067Z","record_id":"0f5d9eaa7e4273291f0fb938eacf1e01065388c8124d79002764a6a6aeac8c98","schema_fingerprint":"4aa3821a28b0b7c2400bc59aba4bcc0a76e971dadd19610d3ad38c768e124dc7","schema_version":"edge-lab-recorder.raw.v1","sequence":null,"source":"clob_market_ws"}
{"event_at":"2026-07-28T03:04:26.703000Z","event_fingerprint":"7728341c79ca55ea1a5edebc472301f27c99b15d2c58a1b5c72cce72c1d899ae","payload":{"connection_id":"a6b55582af5f430fb37ad02bf0922475","event_at":"2026-07-28T03:04:26.703000Z","event_type":"price_change","frame_hash":"9ea9fe0b8852c32761febb2a80ab26a17094bc7c961a39733ea535605c5f91d0","frame_index":0,"kind":"data","monotonic_ns":309849767469791,"payload":{"event_type":"price_change","market":"0x779291bef19b6709f61e9764a954aafe9ffae488d50ae674aabdcb4f248006d5","price_changes":[{"asset_id":"8761897749749422724209054078244794145777693856614463256546737399611489089783","best_ask":"0.6","best_bid":"0.59","hash":"91af44bbaaa508a88497ee9ae354ee2f76a745fc","price":"0.49","side":"BUY","size":"233"},{"asset_id":"14965588658799411272385430903075831224615961675357217884735713260981483529984","best_ask":"0.41","best_bid":"0.4","hash":"fe772dec58af23f4c5288dfc416926fbc4900aa7","price":"0.51","side":"SELL","size":"233"}],"timestamp":"1785207866703"},"payload_hash":"f8b727b3c62541c108fd05493801dc7f4c038e69a1aef7513067532052ad3622","raw_frame":"{\"market\":\"0x779291bef19b6709f61e9764a954aafe9ffae488d50ae674aabdcb4f248006d5\", \"price_changes\":[{\"asset_id\":\"8761897749749422724209054078244794145777693856614463256546737399611489089783\", \"price\":\"0.49\", \"size\":\"233\", \"side\":\"BUY\", \"hash\":\"91af44bbaaa508a88497ee9ae354ee2f76a745fc\", \"best_bid\":\"0.59\", \"best_ask\":\"0.6\"}, {\"asset_id\":\"14965588658799411272385430903075831224615961675357217884735713260981483529984\", \"price\":\"0.51\", \"size\":\"233\", \"side\":\"SELL\", \"hash\":\"fe772dec58af23f4c5288dfc416926fbc4900aa7\", \"best_bid\":\"0.4\", \"best_ask\":\"0.41\"}], \"timestamp\":\"1785207866703\", \"event_type\":\"price_change\"}","received_at":"2026-07-28T03:04:26.741508Z","schema_version":"clob-market-ws.price_change.v1","sequence":null,"server_hash":null,"server_timestamp":"1785207866703","session_id":"3e519d9098404c15b234d96025eb1a2b","source":"clob_market_ws"},"received_at":"2026-07-28T03:04:26.741508Z","record_id":"abc75212788d377bae0f57520c849305072fd4f25ec8a11c51ae0aa6470756a0","schema_fingerprint":"4aa3821a28b0b7c2400bc59aba4bcc0a76e971dadd19610d3ad38c768e124dc7","schema_version":"edge-lab-recorder.raw.v1","sequence":null,"source":"clob_market_ws"}
{"event_at":"2026-07-28T03:04:26.704000Z","event_fingerprint":"899d8f14058b0511311dda411f24473e3834af8b1cb1395eda6ad802f451b2b4","payload":{"connection_id":"a6b55582af5f430fb37ad02bf0922475","event_at":"2026-07-28T03:04:26.704000Z","event_type":"price_change","frame_hash":"9bd7fc6be1cdee463acc2278260dfd5d4ede3f08bc9715e16bb4a5a72cf6fe53","frame_index":0,"kind":"data","monotonic_ns":309849768975833,"payload":{"event_type":"price_change","market":"0x779291bef19b6709f61e9764a954aafe9ffae488d50ae674aabdcb4f248006d5","price_changes":[{"asset_id":"8761897749749422724209054078244794145777693856614463256546737399611489089783","best_ask":"0.6","best_bid":"0.59","hash":"e70b01780019b5a6eb7595c99a7c0194a37f84b4","price":"0.55","side":"BUY","size":"129.27"},{"asset_id":"14965588658799411272385430903075831224615961675357217884735713260981483529984","best_ask":"0.41","best_bid":"0.4","hash":"42898c69e6310ff7d2e814ea9f6ae9ea461cff3a","price":"0.45","side":"SELL","size":"129.27"}],"timestamp":"1785207866704"},"payload_hash":"de9ced9a3baf008803bdfb07820ce790e62d9c65d2f8ec9bea5871cb74266696","raw_frame":"{\"market\":\"0x779291bef19b6709f61e9764a954aafe9ffae488d50ae674aabdcb4f248006d5\", \"price_changes\":[{\"asset_id\":\"8761897749749422724209054078244794145777693856614463256546737399611489089783\", \"price\":\"0.55\", \"size\":\"129.27\", \"side\":\"BUY\", \"hash\":\"e70b01780019b5a6eb7595c99a7c0194a37f84b4\", \"best_bid\":\"0.59\", \"best_ask\":\"0.6\"}, {\"asset_id\":\"14965588658799411272385430903075831224615961675357217884735713260981483529984\", \"price\":\"0.45\", \"size\":\"129.27\", \"side\":\"SELL\", \"hash\":\"42898c69e6310ff7d2e814ea9f6ae9ea461cff3a\", \"best_bid\":\"0.4\", \"best_ask\":\"0.41\"}], \"timestamp\":\"1785207866704\", \"event_type\":\"price_change\"}","received_at":"2026-07-28T03:04:26.743010Z","schema_version":"clob-market-ws.price_change.v1","sequence":null,"server_hash":null,"server_timestamp":"1785207866704","session_id":"3e519d9098404c15b234d96025eb1a2b","source":"clob_market_ws"},"received_at":"2026-07-28T03:04:26.743010Z","record_id":"dd449dee3fb55b935380d186e3d208a164ea381cc8e521928faf8123cf30df81","schema_fingerprint":"4aa3821a28b0b7c2400bc59aba4bcc0a76e971dadd19610d3ad38c768e124dc7","schema_version":"edge-lab-recorder.raw.v1","sequence":null,"source":"clob_market_ws"}
{"event_at":"2026-07-28T03:04:26.705000Z","event_fingerprint":"9811071638fba616b2fdc6bfcea25d3a8a1dd064ac376ef05e596432d530696a","payload":{"connection_id":"a6b55582af5f430fb37ad02bf0922475","event_at":"2026-07-28T03:04:26.705000Z","event_type":"price_change","frame_hash":"fcdbb6e8e3ac583781f22009c25ad09c29787dbb941d21f061625dce3a374e61","frame_index":0,"kind":"data","monotonic_ns":309849770555458,"payload":{"event_type":"price_change","market":"0x779291bef19b6709f61e9764a954aafe9ffae488d50ae674aabdcb4f248006d5","price_changes":[{"asset_id":"8761897749749422724209054078244794145777693856614463256546737399611489089783","best_ask":"0.6","best_bid":"0.59","hash":"d21e5ef0094fafdd60e620d283ee8079358704c3","price":"0.59","side":"BUY","size":"133.2"},{"asset_id":"14965588658799411272385430903075831224615961675357217884735713260981483529984","best_ask":"0.41","best_bid":"0.4","hash":"60e1bbefc15e1154f4425c7f53f5beec3da19cf5","price":"0.41","side":"SELL","size":"133.2"}],"timestamp":"1785207866705"},"payload_hash":"6fe800215f27b7a3dd8dbdaef08fb8592a7a6c09248c9d7d69d7a40dc7747d5d","raw_frame":"{\"market\":\"0x779291bef19b6709f61e9764a954aafe9ffae488d50ae674aabdcb4f248006d5\", \"price_changes\":[{\"asset_id\":\"8761897749749422724209054078244794145777693856614463256546737399611489089783\", \"price\":\"0.59\", \"size\":\"133.2\", \"side\":\"BUY\", \"hash\":\"d21e5ef0094fafdd60e620d283ee8079358704c3\", \"best_bid\":\"0.59\", \"best_ask\":\"0.6\"}, {\"asset_id\":\"14965588658799411272385430903075831224615961675357217884735713260981483529984\", \"price\":\"0.41\", \"size\":\"133.2\", \"side\":\"SELL\", \"hash\":\"60e1bbefc15e1154f4425c7f53f5beec3da19cf5\", \"best_bid\":\"0.4\", \"best_ask\":\"0.41\"}], \"timestamp\":\"1785207866705\", \"event_type\":\"price_change\"}","received_at":"2026-07-28T03:04:26.744593Z","schema_version":"clob-market-ws.price_change.v1","sequence":null,"server_hash":null,"server_timestamp":"1785207866705","session_id":"3e519d9098404c15b234d96025eb1a2b","source":"clob_market_ws"},"received_at":"2026-07-28T03:04:26.744593Z","record_id":"42b1d0731ec62f603863dcf41b4569b481042f4689a3a81ae7f1e653b1a1b8ff","schema_fingerprint":"4aa3821a28b0b7c2400bc59aba4bcc0a76e971dadd19610d3ad38c768e124dc7","schema_version":"edge-lab-recorder.raw.v1","sequence":null,"source":"clob_market_ws"}
{"event_at":"2026-07-28T03:04:26.711000Z","event_fingerprint":"6b8cf8ff8f9faa0343118a98d0515e1106dd3aa7d8f83455112c1c0eebb9b0bb","payload":{"connection_id":"a6b55582af5f430fb37ad02bf0922475","event_at":"2026-07-28T03:04:26.711000Z","event_type":"price_change","frame_hash":"d261192333b66eb56ea12393246ef7699b7e07c07cdcdc6db84d2000dac159ba","frame_index":0,"kind":"data","monotonic_ns":309849772013625,"payload":{"event_type":"price_change","market":"0x779291bef19b6709f61e9764a954aafe9ffae488d50ae674aabdcb4f248006d5","price_changes":[{"asset_id":"14965588658799411272385430903075831224615961675357217884735713260981483529984","best_ask":"0.41","best_bid":"0.4","hash":"5b9ca51e1f60eaa79a2ca9f48f127f0cf36ba44f","price":"0.37","side":"BUY","size":"446"},{"asset_id":"8761897749749422724209054078244794145777693856614463256546737399611489089783","best_ask":"0.6","best_bid":"0.59","hash":"f9fcc2d982cf631025430bafb8b02dde6e0a1cd6","price":"0.63","side":"SELL","size":"446"}],"timestamp":"1785207866711"},"payload_hash":"9712d0b0fcf4b15f5f16a6d6516aa95090c8d0aa89e12035a1f7b65a564a2b64","raw_frame":"{\"market\":\"0x779291bef19b6709f61e9764a954aafe9ffae488d50ae674aabdcb4f248006d5\", \"price_changes\":[{\"asset_id\":\"14965588658799411272385430903075831224615961675357217884735713260981483529984\", \"price\":\"0.37\", \"size\":\"446\", \"side\":\"BUY\", \"hash\":\"5b9ca51e1f60eaa79a2ca9f48f127f0cf36ba44f\", \"best_bid\":\"0.4\", \"best_ask\":\"0.41\"}, {\"asset_id\":\"8761897749749422724209054078244794145777693856614463256546737399611489089783\", \"price\":\"0.63\", \"size\":\"446\", \"side\":\"SELL\", \"hash\":\"f9fcc2d982cf631025430bafb8b02dde6e0a1cd6\", \"best_bid\":\"0.59\", \"best_ask\":\"0.6\"}], \"timestamp\":\"1785207866711\", \"event_type\":\"price_change\"}","received_at":"2026-07-28T03:04:26.746051Z","schema_version":"clob-market-ws.price_change.v1","sequence":null,"server_hash":null,"server_timestamp":"1785207866711","session_id":"3e519d9098404c15b234d96025eb1a2b","source":"clob_market_ws"},"received_at":"2026-07-28T03:04:26.746051Z","record_id":"1489c9ec6ed5125c01ab14bd2db93fd85158834c16d1418d85a3ca6b202eb6e0","schema_fingerprint":"4aa3821a28b0b7c2400bc59aba4bcc0a76e971dadd19610d3ad38c768e124dc7","schema_version":"edge-lab-recorder.raw.v1","sequence":null,"source":"clob_market_ws"}
{"event_at":"2026-07-28T03:04:26.711000Z","event_fingerprint":"226f0055c82420a505bd480c3d92c37849dc231cc68afc719738dd69e4fc40d4","payload":{"connection_id":"a6b55582af5f430fb37ad02bf0922475","event_at":"2026-07-28T03:04:26.711000Z","event_type":"price_change","frame_hash":"555ca22d2d8a97166044af3b999098c74f8d625d31fd4c2eaf91969631c4495b","frame_index":0,"kind":"data","monotonic_ns":309849773443875,"payload":{"event_type":"price_change","market":"0x779291bef19b6709f61e9764a954aafe9ffae488d50ae674aabdcb4f248006d5","price_changes":[{"asset_id":"14965588658799411272385430903075831224615961675357217884735713260981483529984","best_ask":"0.41","best_bid":"0.4","hash":"4e2bd9942bd53ea690d11195d579fbf876cdc4ad","price":"0.36","side":"BUY","size":"212"},{"asset_id":"8761897749749422724209054078244794145777693856614463256546737399611489089783","best_ask":"0.6","best_bid":"0.59","hash":"494e3e3f0ca3a9ff5b4df1e2301b4e5b601971a0","price":"0.64","side":"SELL","size":"212"}],"timestamp":"1785207866711"},"payload_hash":"6a3773700cf60edb00fafa8ce6932449d10eb232dde589aaaebcdf23525e5547","raw_frame":"{\"market\":\"0x779291bef19b6709f61e9764a954aafe9ffae488d50ae674aabdcb4f248006d5\", \"price_changes\":[{\"asset_id\":\"14965588658799411272385430903075831224615961675357217884735713260981483529984\", \"price\":\"0.36\", \"size\":\"212\", \"side\":\"BUY\", \"hash\":\"4e2bd9942bd53ea690d11195d579fbf876cdc4ad\", \"best_bid\":\"0.4\", \"best_ask\":\"0.41\"}, {\"asset_id\":\"8761897749749422724209054078244794145777693856614463256546737399611489089783\", \"price\":\"0.64\", \"size\":\"212\", \"side\":\"SELL\", \"hash\":\"494e3e3f0ca3a9ff5b4df1e2301b4e5b601971a0\", \"best_bid\":\"0.59\", \"best_ask\":\"0.6\"}], \"timestamp\":\"1785207866711\", \"event_type\":\"price_change\"}","received_at":"2026-07-28T03:04:26.747481Z","schema_version":"clob-market-ws.price_change.v1","sequence":null,"server_hash":null,"server_timestamp":"1785207866711","session_id":"3e519d9098404c15b234d96025eb1a2b","source":"clob_market_ws"},"received_at":"2026-07-28T03:04:26.747481Z","record_id":"c8253471610e90be83219b42a9d650ec044c5f09ba519368c10b63143b9922f9","schema_fingerprint":"4aa3821a28b0b7c2400bc59aba4bcc0a76e971dadd19610d3ad38c768e124dc7","schema_version":"edge-lab-recorder.raw.v1","sequence":null,"source":"clob_market_ws"}
{"event_at":"2026-07-28T03:04:26.711000Z","event_fingerprint":"f47c98e8f621a2631e4049c4cf3a6fa8bc4253b44343e991e00a8e7b6d310123","payload":{"connection_id":"a6b55582af5f430fb37ad02bf0922475","event_at":"2026-07-28T03:04:26.711000Z","event_type":"price_change","frame_hash":"7111d7503adfe1bcfc3511b18bcf1979dd6ec149b92ed76b1eef07bd02c48923","frame_index":0,"kind":"data","monotonic_ns":309849774885208,"payload":{"event_type":"price_change","market":"0x779291bef19b6709f61e9764a954aafe9ffae488d50ae674aabdcb4f248006d5","price_changes":[{"asset_id":"8761897749749422724209054078244794145777693856614463256546737399611489089783","best_ask":"0.6","best_bid":"0.59","hash":"420f68f5ff606000c8d6f2bb7e1d7fcfd0fab1bd","price":"0.57","side":"BUY","size":"112.35"},{"asset_id":"14965588658799411272385430903075831224615961675357217884735713260981483529984","best_ask":"0.41","best_bid":"0.4","hash":"b541caf6ea093979c325419c8dbd3eb313e2b849","price":"0.43","side":"SELL","size":"112.35"}],"timestamp":"1785207866711"},"payload_hash":"a16c54229e22e8faf69984e39b7562761422e1e31842154f5ff41a25fec5d69f","raw_frame":"{\"market\":\"0x779291bef19b6709f61e9764a954aafe9ffae488d50ae674aabdcb4f248006d5\", \"price_changes\":[{\"asset_id\":\"8761897749749422724209054078244794145777693856614463256546737399611489089783\", \"price\":\"0.57\", \"size\":\"112.35\", \"side\":\"BUY\", \"hash\":\"420f68f5ff606000c8d6f2bb7e1d7fcfd0fab1bd\", \"best_bid\":\"0.59\", \"best_ask\":\"0.6\"}, {\"asset_id\":\"14965588658799411272385430903075831224615961675357217884735713260981483529984\", \"price\":\"0.43\", \"size\":\"112.35\", \"side\":\"SELL\", \"hash\":\"b541caf6ea093979c325419c8dbd3eb313e2b849\", \"best_bid\":\"0.4\", \"best_ask\":\"0.41\"}], \"timestamp\":\"1785207866711\", \"event_type\":\"price_change\"}","received_at":"2026-07-28T03:04:26.748922Z","schema_version":"clob-market-ws.price_change.v1","sequence":null,"server_hash":null,"server_timestamp":"1785207866711","session_id":"3e519d9098404c15b234d96025eb1a2b","source":"clob_market_ws"},"received_at":"2026-07-28T03:04:26.748922Z","record_id":"575b0b9b975702a9e2af2fc2a24c5e76cd63e244b3ef4f54e68ca9f902372fb0","schema_fingerprint":"4aa3821a28b0b7c2400bc59aba4bcc0a76e971dadd19610d3ad38c768e124dc7","schema_version":"edge-lab-recorder.raw.v1","sequence":null,"source":"clob_market_ws"}
{"event_at":"2026-07-28T03:04:26.711000Z","event_fingerprint":"7db7d35a233889925ad8cac4cfeca41e949276b489f015f4d532dab9352d1de0","payload":{"connection_id":"a6b55582af5f430fb37ad02bf0922475","event_at":"2026-07-28T03:04:26.711000Z","event_type":"price_change","frame_hash":"16b7566cac748c22406d1f0e643609dbcda04a774e171ff204cdf99e879f4e26","frame_index":0,"kind":"data","monotonic_ns":309849776376750,"payload":{"event_type":"price_change","market":"0x779291bef19b6709f61e9764a954aafe9ffae488d50ae674aabdcb4f248006d5","price_changes":[{"asset_id":"14965588658799411272385430903075831224615961675357217884735713260981483529984","best_ask":"0.41","best_bid":"0.4","hash":"3cbb455e0906ffedb44955f45613816e2ca17203","price":"0.36","side":"BUY","size":"156"},{"asset_id":"8761897749749422724209054078244794145777693856614463256546737399611489089783","best_ask":"0.6","best_bid":"0.59","hash":"66c22782e3de63d513d18b464c09083a10a1d53e","price":"0.64","side":"SELL","size":"156"}],"timestamp":"1785207866711"},"payload_hash":"4e43f34450996df9eb8a2154819ecbb12dce82f6ee78062c051159622f0ee82b","raw_frame":"{\"market\":\"0x779291bef19b6709f61e9764a954aafe9ffae488d50ae674aabdcb4f248006d5\", \"price_changes\":[{\"asset_id\":\"14965588658799411272385430903075831224615961675357217884735713260981483529984\", \"price\":\"0.36\", \"size\":\"156\", \"side\":\"BUY\", \"hash\":\"3cbb455e0906ffedb44955f45613816e2ca17203\", \"best_bid\":\"0.4\", \"best_ask\":\"0.41\"}, {\"asset_id\":\"8761897749749422724209054078244794145777693856614463256546737399611489089783\", \"price\":\"0.64\", \"size\":\"156\", \"side\":\"SELL\", \"hash\":\"66c22782e3de63d513d18b464c09083a10a1d53e\", \"best_bid\":\"0.59\", \"best_ask\":\"0.6\"}], \"timestamp\":\"1785207866711\", \"event_type\":\"price_change\"}","received_at":"2026-07-28T03:04:26.750413Z","schema_version":"clob-market-ws.price_change.v1","sequence":null,"server_hash":null,"server_timestamp":"1785207866711","session_id":"3e519d9098404c15b234d96025eb1a2b","source":"clob_market_ws"},"received_at":"2026-07-28T03:04:26.750413Z","record_id":"9597b0e52bf63c8e756f343b0a09f3e294fa1fb5776427d9c366beb2d8b07f86","schema_fingerprint":"4aa3821a28b0b7c2400bc59aba4bcc0a76e971dadd19610d3ad38c768e124dc7","schema_version":"edge-lab-recorder.raw.v1","sequence":null,"source":"clob_market_ws"}
{"event_at":"2026-07-28T03:04:26.712000Z","event_fingerprint":"2f9508490bd0b48c6c6dcc5b7b8a44eaf069f7dc602783a51f282d5fb8f242f6","payload":{"connection_id":"a6b55582af5f430fb37ad02bf0922475","event_at":"2026-07-28T03:04:26.712000Z","event_type":"price_change","frame_hash":"99e3f351191495417cc87e06f74f183275db9ded80462c3bacf80b881044373e","frame_index":0,"kind":"data","monotonic_ns":309849777825041,"payload":{"event_type":"price_change","market":"0x779291bef19b6709f61e9764a954aafe9ffae488d50ae674aabdcb4f248006d5","price_changes":[{"asset_id":"14965588658799411272385430903075831224615961675357217884735713260981483529984","best_ask":"0.41","best_bid":"0.4","hash":"035efb60ab6a65817d880b1613411df98b81d2de","price":"0.35","side":"BUY","size":"156"},{"asset_id":"8761897749749422724209054078244794145777693856614463256546737399611489089783","best_ask":"0.6","best_bid":"0.59","hash":"13ee101877a74abdbd27673bbd6cc90821968545","price":"0.65","side":"SELL","size":"156"}],"timestamp":"1785207866712"},"payload_hash":"3ea1a0b1c956022297e0dfe4524783c2cd5acb819878fb4688c2bca04738d4da","raw_frame":"{\"market\":\"0x779291bef19b6709f61e9764a954aafe9ffae488d50ae674aabdcb4f248006d5\", \"price_changes\":[{\"asset_id\":\"14965588658799411272385430903075831224615961675357217884735713260981483529984\", \"price\":\"0.35\", \"size\":\"156\", \"side\":\"BUY\", \"hash\":\"035efb60ab6a65817d880b1613411df98b81d2de\", \"best_bid\":\"0.4\", \"best_ask\":\"0.41\"}, {\"asset_id\":\"8761897749749422724209054078244794145777693856614463256546737399611489089783\", \"price\":\"0.65\", \"size\":\"156\", \"side\":\"SELL\", \"hash\":\"13ee101877a74abdbd27673bbd6cc90821968545\", \"best_bid\":\"0.59\", \"best_ask\":\"0.6\"}], \"timestamp\":\"1785207866712\", \"event_type\":\"price_change\"}","received_at":"2026-07-28T03:04:26.751860Z","schema_version":"clob-market-ws.price_change.v1","sequence":null,"server_hash":null,"server_timestamp":"1785207866712","session_id":"3e519d9098404c15b234d96025eb1a2b","source":"clob_market_ws"},"received_at":"2026-07-28T03:04:26.751860Z","record_id":"31f5965b1b17f0c350f67d606923747d13221827122b6ad96e1258b72ec7e172","schema_fingerprint":"4aa3821a28b0b7c2400bc59aba4bcc0a76e971dadd19610d3ad38c768e124dc7","schema_version":"edge-lab-recorder.raw.v1","sequence":null,"source":"clob_market_ws"}
{"event_at":"2026-07-28T03:04:26.712000Z","event_fingerprint":"8e32d13005360a559234af58624200fe676b76292f54a7a726dc9b2bb11d75b0","payload":{"connection_id":"a6b55582af5f430fb37ad02bf0922475","event_at":"2026-07-28T03:04:26.712000Z","event_type":"price_change","frame_hash":"810ee40d05b0a940aebbf5a5a7dc18f6929c23182c595bf0c4f880d791f8056c","frame_index":0,"kind":"data","monotonic_ns":309849779280041,"payload":{"event_type":"price_change","market":"0x779291bef19b6709f61e9764a954aafe9ffae488d50ae674aabdcb4f248006d5","price_changes":[{"asset_id":"8761897749749422724209054078244794145777693856614463256546737399611489089783","best_ask":"0.6","best_bid":"0.59","hash":"8667a727e3fa75ef436b90184b230d871aede601","price":"0.57","side":"BUY","size":"107.35"},{"asset_id":"14965588658799411272385430903075831224615961675357217884735713260981483529984","best_ask":"0.41","best_bid":"0.4","hash":"5d7900801fd6563efb20954801d020510dd97179","price":"0.43","side":"SELL","size":"107.35"}],"timestamp":"1785207866712"},"payload_hash":"2189b4bf6dc6795ad645f9db5ffca9e0bd9a9b04174b2742c262f4b581219ec6","raw_frame":"{\"market\":\"0x779291bef19b6709f61e9764a954aafe9ffae488d50ae674aabdcb4f248006d5\", \"price_changes\":[{\"asset_id\":\"8761897749749422724209054078244794145777693856614463256546737399611489089783\", \"price\":\"0.57\", \"size\":\"107.35\", \"side\":\"BUY\", \"hash\":\"8667a727e3fa75ef436b90184b230d871aede601\", \"best_bid\":\"0.59\", \"best_ask\":\"0.6\"}, {\"asset_id\":\"14965588658799411272385430903075831224615961675357217884735713260981483529984\", \"price\":\"0.43\", \"size\":\"107.35\", \"side\":\"SELL\", \"hash\":\"5d7900801fd6563efb20954801d020510dd97179\", \"best_bid\":\"0.4\", \"best_ask\":\"0.41\"}], \"timestamp\":\"1785207866712\", \"event_type\":\"price_change\"}","received_at":"2026-07-28T03:04:26.753315Z","schema_version":"clob-market-ws.price_change.v1","sequence":null,"server_hash":null,"server_timestamp":"1785207866712","session_id":"3e519d9098404c15b234d96025eb1a2b","source":"clob_market_ws"},"received_at":"2026-07-28T03:04:26.753315Z","record_id":"ef4a2b155e1b002ff0d84fcc805cafa75270d30dc5a827fa1c1ad7562c517b1e","schema_fingerprint":"4aa3821a28b0b7c2400bc59aba4bcc0a76e971dadd19610d3ad38c768e124dc7","schema_version":"edge-lab-recorder.raw.v1","sequence":null,"source":"clob_market_ws"}
{"event_at":"2026-07-28T03:04:26.713000Z","event_fingerprint":"648638b9cfd206f5095cfba5c5a569b80e3d67d838dddeb26ebc4d09ebd36002","payload":{"connection_id":"a6b55582af5f430fb37ad02bf0922475","event_at":"2026-07-28T03:04:26.713000Z","event_type":"price_change","frame_hash":"559cb3f3d1738fce088a843cb27ce5dc22f346a58b632ab835b75a610747f730","frame_index":0,"kind":"data","monotonic_ns":309849780700875,"payload":{"event_type":"price_change","market":"0x779291bef19b6709f61e9764a954aafe9ffae488d50ae674aabdcb4f248006d5","price_changes":[{"asset_id":"14965588658799411272385430903075831224615961675357217884735713260981483529984","best_ask":"0.41","best_bid":"0.4","hash":"60c58edb9933fe364ae4947ee2223e9a6e036c07","price":"0.4","side":"BUY","size":"10"},{"asset_id":"8761897749749422724209054078244794145777693856614463256546737399611489089783","best_ask":"0.6","best_bid":"0.59","hash":"b70e8f9efa20b3282f502684eb828f4044e35fd1","price":"0.6","side":"SELL","size":"10"}],"timestamp":"1785207866713"},"payload_hash":"5bce7b44ff7c7b9531a280220db74e829c8985dd169c26cd706818c2256a16ef","raw_frame":"{\"market\":\"0x779291bef19b6709f61e9764a954aafe9ffae488d50ae674aabdcb4f248006d5\", \"price_changes\":[{\"asset_id\":\"14965588658799411272385430903075831224615961675357217884735713260981483529984\", \"price\":\"0.4\", \"size\":\"10\", \"side\":\"BUY\", \"hash\":\"60c58edb9933fe364ae4947ee2223e9a6e036c07\", \"best_bid\":\"0.4\", \"best_ask\":\"0.41\"}, {\"asset_id\":\"8761897749749422724209054078244794145777693856614463256546737399611489089783\", \"price\":\"0.6\", \"size\":\"10\", \"side\":\"SELL\", \"hash\":\"b70e8f9efa20b3282f502684eb828f4044e35fd1\", \"best_bid\":\"0.59\", \"best_ask\":\"0.6\"}], \"timestamp\":\"1785207866713\", \"event_type\":\"price_change\"}","received_at":"2026-07-28T03:04:26.754735Z","schema_version":"clob-market-ws.price_change.v1","sequence":null,"server_hash":null,"server_timestamp":"1785207866713","session_id":"3e519d9098404c15b234d96025eb1a2b","source":"clob_market_ws"},"received_at":"2026-07-28T03:04:26.754735Z","record_id":"26c4f5f2f4b42d34c1602e7f90db55238c64dead378494a1f6a272a4ed7d59fe","schema_fingerprint":"4aa3821a28b0b7c2400bc59aba4bcc0a76e971dadd19610d3ad38c768e124dc7","schema_version":"edge-lab-recorder.raw.v1","sequence":null,"source":"clob_market_ws"}
{"event_at":"2026-07-28T03:04:26.713000Z","event_fingerprint":"d7a1a7dd267f3838b962ac683ed52c79474f5033f365ca094a029fe6655bb1f3","payload":{"connection_id":"a6b55582af5f430fb37ad02bf0922475","event_at":"2026-07-28T03:04:26.713000Z","event_type":"price_change","frame_hash":"93715a58ce0c830130fe945a87f9d0f94414e4ee84c5343cdc84ed229064d634","frame_index":0,"kind":"data","monotonic_ns":309849782150291,"payload":{"event_type":"price_change","market":"0x779291bef19b6709f61e9764a954aafe9ffae488d50ae674aabdcb4f248006d5","price_changes":[{"asset_id":"8761897749749422724209054078244794145777693856614463256546737399611489089783","best_ask":"0.6","best_bid":"0.59","hash":"bf2bc96383220195a2ee904f907521aaa7e5c9c9","price":"0.51","side":"BUY","size":"105"},{"asset_id":"14965588658799411272385430903075831224615961675357217884735713260981483529984","best_ask":"0.41","best_bid":"0.4","hash":"be13a5513d6d8699dda0a11458f92f39e478916e","price":"0.49","side":"SELL","size":"105"}],"timestamp":"1785207866713"},"payload_hash":"d7786e5f1cc59343e005733c0acb2a68dc1506def48b1170ff79ff28193d94a3","raw_frame":"{\"market\":\"0x779291bef19b6709f61e9764a954aafe9ffae488d50ae674aabdcb4f248006d5\", \"price_changes\":[{\"asset_id\":\"8761897749749422724209054078244794145777693856614463256546737399611489089783\", \"price\":\"0.51\", \"size\":\"105\", \"side\":\"BUY\", \"hash\":\"bf2bc96383220195a2ee904f907521aaa7e5c9c9\", \"best_bid\":\"0.59\", \"best_ask\":\"0.6\"}, {\"asset_id\":\"14965588658799411272385430903075831224615961675357217884735713260981483529984\", \"price\":\"0.49\", \"size\":\"105\", \"side\":\"SELL\", \"hash\":\"be13a5513d6d8699dda0a11458f92f39e478916e\", \"best_bid\":\"0.4\", \"best_ask\":\"0.41\"}], \"timestamp\":\"1785207866713\", \"event_type\":\"price_change\"}","received_at":"2026-07-28T03:04:26.756185Z","schema_version":"clob-market-ws.price_change.v1","sequence":null,"server_hash":null,"server_timestamp":"1785207866713","session_id":"3e519d9098404c15b234d96025eb1a2b","source":"clob_market_ws"},"received_at":"2026-07-28T03:04:26.756185Z","record_id":"a1cbb2c5c4677147807a100b54a0c64d3df898973bfb50c6098cd7af3eae6730","schema_fingerprint":"4aa3821a28b0b7c2400bc59aba4bcc0a76e971dadd19610d3ad38c768e124dc7","schema_version":"edge-lab-recorder.raw.v1","sequence":null,"source":"clob_market_ws"}
{"event_at":"2026-07-28T03:04:26.713000Z","event_fingerprint":"0488b52a8a26d6ea6c44545633efd70e56f716fbd3cc258f6da98b407d37ae7d","payload":{"connection_id":"a6b55582af5f430fb37ad02bf0922475","event_at":"2026-07-28T03:04:26.713000Z","event_type":"price_change","frame_hash":"0c61db676016d21243d6922a311d6f1e7587c47f822d9ead588d0b55e6af70c4","frame_index":0,"kind":"data","monotonic_ns":309849783573166,"payload":{"event_type":"price_change","market":"0x779291bef19b6709f61e9764a954aafe9ffae488d50ae674aabdcb4f248006d5","price_changes":[{"asset_id":"8761897749749422724209054078244794145777693856614463256546737399611489089783","best_ask":"0.6","best_bid":"0.59","hash":"f821b22e4cd4aca6db43d503f47a926e2ee0422c","price":"0.57","side":"BUY","size":"102.35"},{"asset_id":"14965588658799411272385430903075831224615961675357217884735713260981483529984","best_ask":"0.41","best_bid":"0.4","hash":"03e5a362a2514a17f4cedd4d9b90ded2a38457c3","price":"0.43","side":"SELL","size":"102.35"}],"timestamp":"1785207866713"},"payload_hash":"8e75b2ba1a501070a19f279b64607a49db1461dd8e5c895e59c291d70123fb2f","raw_frame":"{\"market\":\"0x779291bef19b6709f61e9764a954aafe9ffae488d50ae674aabdcb4f248006d5\", \"price_changes\":[{\"asset_id\":\"8761897749749422724209054078244794145777693856614463256546737399611489089783\", \"price\":\"0.57\", \"size\":\"102.35\", \"side\":\"BUY\", \"hash\":\"f821b22e4cd4aca6db43d503f47a926e2ee0422c\", \"best_bid\":\"0.59\", \"best_ask\":\"0.6\"}, {\"asset_id\":\"14965588658799411272385430903075831224615961675357217884735713260981483529984\", \"price\":\"0.43\", \"size\":\"102.35\", \"side\":\"SELL\", \"hash\":\"03e5a362a2514a17f4cedd4d9b90ded2a38457c3\", \"best_bid\":\"0.4\", \"best_ask\":\"0.41\"}], \"timestamp\":\"1785207866713\", \"event_type\":\"price_change\"}","received_at":"2026-07-28T03:04:26.757607Z","schema_version":"clob-market-ws.price_change.v1","sequence":null,"server_hash":null,"server_timestamp":"1785207866713","session_id":"3e519d9098404c15b234d96025eb1a2b","source":"clob_market_ws"},"received_at":"2026-07-28T03:04:26.757607Z","record_id":"935fb405e8a9bab0c38c59d9ac2dc8cfae3aa9e39b0b492ebabd74311e0b2b1a","schema_fingerprint":"4aa3821a28b0b7c2400bc59aba4bcc0a76e971dadd19610d3ad38c768e124dc7","schema_version":"edge-lab-recorder.raw.v1","sequence":null,"source":"clob_market_ws"}
{"event_at":"2026-07-28T03:04:26.715000Z","event_fingerprint":"ba9f3c0d167a304478ce4d202bbf391482818db0bdcad82aa62d81c5f2d1d689","payload":{"connection_id":"a6b55582af5f430fb37ad02bf0922475","event_at":"2026-07-28T03:04:26.715000Z","event_type":"price_change","frame_hash":"6532951d95468c20a49989db6bebb85740bd42de091b37d9fb379a2119dfd1d7","frame_index":0,"kind":"data","monotonic_ns":309849785027750,"payload":{"event_type":"price_change","market":"0x779291bef19b6709f61e9764a954aafe9ffae488d50ae674aabdcb4f248006d5","price_changes":[{"asset_id":"14965588658799411272385430903075831224615961675357217884735713260981483529984","best_ask":"0.41","best_bid":"0.4","hash":"368198aa90c75a4d929b9fe0fe1d4354caad6be6","price":"0.38","side":"BUY","size":"52.6"},{"asset_id":"8761897749749422724209054078244794145777693856614463256546737399611489089783","best_ask":"0.6","best_bid":"0.59","hash":"810ecf3cea85f895dec47abf8d4f4f27b3e8cc28","price":"0.62","side":"SELL","size":"52.6"}],"timestamp":"1785207866715"},"payload_hash":"647e3bcf0365d30689f8b98c24c68bf312e8b6d66ef9994b03bd835caf547273","raw_frame":"{\"market\":\"0x779291bef19b6709f61e9764a954aafe9ffae488d50ae674aabdcb4f248006d5\", \"price_changes\":[{\"asset_id\":\"14965588658799411272385430903075831224615961675357217884735713260981483529984\", \"price\":\"0.38\", \"size\":\"52.6\", \"side\":\"BUY\", \"hash\":\"368198aa90c75a4d929b9fe0fe1d4354caad6be6\", \"best_bid\":\"0.4\", \"best_ask\":\"0.41\"}, {\"asset_id\":\"8761897749749422724209054078244794145777693856614463256546737399611489089783\", \"price\":\"0.62\", \"size\":\"52.6\", \"side\":\"SELL\", \"hash\":\"810ecf3cea85f895dec47abf8d4f4f27b3e8cc28\", \"best_bid\":\"0.59\", \"best_ask\":\"0.6\"}], \"timestamp\":\"1785207866715\", \"event_type\":\"price_change\"}","received_at":"2026-07-28T03:04:26.759061Z","schema_version":"clob-market-ws.price_change.v1","sequence":null,"server_hash":null,"server_timestamp":"1785207866715","session_id":"3e519d9098404c15b234d96025eb1a2b","source":"clob_market_ws"},"received_at":"2026-07-28T03:04:26.759061Z","record_id":"f5acf7e55cd85e7ac96d71ce0c9545bc5ef089a94d76c6e02ec9f1e3795ceef6","schema_fingerprint":"4aa3821a28b0b7c2400bc59aba4bcc0a76e971dadd19610d3ad38c768e124dc7","schema_version":"edge-lab-recorder.raw.v1","sequence":null,"source":"clob_market_ws"}
{"event_at":"2026-07-28T03:04:26.715000Z","event_fingerprint":"f3b0ff6b3c34a58c0c431e3f35c6f839daf7404e3d2a18ebeec5339393229f4e","payload":{"connection_id":"a6b55582af5f430fb37ad02bf0922475","event_at":"2026-07-28T03:04:26.715000Z","event_type":"price_change","frame_hash":"97cc14031c3f81a5e303fd9aafc774c222e3c9954598d150de33f07fac0caeb3","frame_index":0,"kind":"data","monotonic_ns":309849786468625,"payload":{"event_type":"price_change","market":"0x779291bef19b6709f61e9764a954aafe9ffae488d50ae674aabdcb4f248006d5","price_changes":[{"asset_id":"8761897749749422724209054078244794145777693856614463256546737399611489089783","best_ask":"0.6","best_bid":"0.59","hash":"360df1a66255a03578d3bc329e084aefd738cd0e","price":"0.59","side":"BUY","size":"123.2"},{"asset_id":"14965588658799411272385430903075831224615961675357217884735713260981483529984","best_ask":"0.41","best_bid":"0.4","hash":"51b74739dcb2ec1c9e4b9b252f8c5ff8fea1c629","price":"0.41","side":"SELL","size":"123.2"}],"timestamp":"1785207866715"},"payload_hash":"d0bb6be9296a131ed92a04fb3d3c6735abe8ec01a4a2c2a5e631e5b684a2fb62","raw_frame":"{\"market\":\"0x779291bef19b6709f61e9764a954aafe9ffae488d50ae674aabdcb4f248006d5\", \"price_changes\":[{\"asset_id\":\"8761897749749422724209054078244794145777693856614463256546737399611489089783\", \"price\":\"0.59\", \"size\":\"123.2\", \"side\":\"BUY\", \"hash\":\"360df1a66255a03578d3bc329e084aefd738cd0e\", \"best_bid\":\"0.59\", \"best_ask\":\"0.6\"}, {\"asset_id\":\"14965588658799411272385430903075831224615961675357217884735713260981483529984\", \"price\":\"0.41\", \"size\":\"123.2\", \"side\":\"SELL\", \"hash\":\"51b74739dcb2ec1c9e4b9b252f8c5ff8fea1c629\", \"best_bid\":\"0.4\", \"best_ask\":\"0.41\"}], \"timestamp\":\"1785207866715\", \"event_type\":\"price_change\"}","received_at":"2026-07-28T03:04:26.760501Z","schema_version":"clob-market-ws.price_change.v1","sequence":null,"server_hash":null,"server_timestamp":"1785207866715","session_id":"3e519d9098404c15b234d96025eb1a2b","source":"clob_market_ws"},"received_at":"2026-07-28T03:04:26.760501Z","record_id":"9b44d444989c93c4d8f3aaf5c9b08a317df3c4f53fe694960a49350db9e2d041","schema_fingerprint":"4aa3821a28b0b7c2400bc59aba4bcc0a76e971dadd19610d3ad38c768e124dc7","schema_version":"edge-lab-recorder.raw.v1","sequence":null,"source":"clob_market_ws"}
{"event_at":"2026-07-28T03:04:26.715000Z","event_fingerprint":"72f3c91ed30141cbe21ede542cdc55e1cd4d4546357929f51203a2ddb1e1063b","payload":{"connection_id":"a6b55582af5f430fb37ad02bf0922475","event_at":"2026-07-28T03:04:26.715000Z","event_type":"price_change","frame_hash":"229bb6fb33599e1a317f759aaa8eae0e9caca25654d8d0c136f866cf4b0964f1","frame_index":0,"kind":"data","monotonic_ns":309849787901125,"payload":{"event_type":"price_change","market":"0x779291bef19b6709f61e9764a954aafe9ffae488d50ae674aabdcb4f248006d5","price_changes":[{"asset_id":"14965588658799411272385430903075831224615961675357217884735713260981483529984","best_ask":"0.41","best_bid":"0.4","hash":"282def901dc812439985a9bf17526119f3159cca","price":"0.39","side":"BUY","size":"0"},{"asset_id":"8761897749749422724209054078244794145777693856614463256546737399611489089783","best_ask":"0.6","best_bid":"0.59","hash":"43ecac966ff32ec1cac547ae648439c63d3e0e63","price":"0.61","side":"SELL","size":"0"}],"timestamp":"1785207866715"},"payload_hash":"c05b8801d4fb0507f27c2461396890288feda11713d73de1bebd54d52929f7b2","raw_frame":"{\"market\":\"0x779291bef19b6709f61e9764a954aafe9ffae488d50ae674aabdcb4f248006d5\", \"price_changes\":[{\"asset_id\":\"14965588658799411272385430903075831224615961675357217884735713260981483529984\", \"price\":\"0.39\", \"size\":\"0\", \"side\":\"BUY\", \"hash\":\"282def901dc812439985a9bf17526119f3159cca\", \"best_bid\":\"0.4\", \"best_ask\":\"0.41\"}, {\"asset_id\":\"8761897749749422724209054078244794145777693856614463256546737399611489089783\", \"price\":\"0.61\", \"size\":\"0\", \"side\":\"SELL\", \"hash\":\"43ecac966ff32ec1cac547ae648439c63d3e0e63\", \"best_bid\":\"0.59\", \"best_ask\":\"0.6\"}], \"timestamp\":\"1785207866715\", \"event_type\":\"price_change\"}","received_at":"2026-07-28T03:04:26.761934Z","schema_version":"clob-market-ws.price_change.v1","sequence":null,"server_hash":null,"server_timestamp":"1785207866715","session_id":"3e519d9098404c15b234d96025eb1a2b","source":"clob_market_ws"},"received_at":"2026-07-28T03:04:26.761934Z","record_id":"eb7107ee412de6d01024843774e92b7459bbf13aea17ae1b37ea878d746af04a","schema_fingerprint":"4aa3821a28b0b7c2400bc59aba4bcc0a76e971dadd19610d3ad38c768e124dc7","schema_version":"edge-lab-recorder.raw.v1","sequence":null,"source":"clob_market_ws"}
{"event_at":"2026-07-28T03:04:26.715000Z","event_fingerprint":"c630c3d9bf74796096876d012ea7c87c3eba32118bca16646d39a27d4dbd76b9","payload":{"connection_id":"a6b55582af5f430fb37ad02bf0922475","event_at":"2026-07-28T03:04:26.715000Z","event_type":"best_bid_ask","frame_hash":"e7c2151e1a4cef4e90ee8fa87b5e99f61516dfd25773b4ced0a89a592ebdb8e2","frame_index":0,"kind":"data","monotonic_ns":309849789348625,"payload":{"asset_id":"14965588658799411272385430903075831224615961675357217884735713260981483529984","best_ask":"0.41","best_bid":"0.38","event_type":"best_bid_ask","market":"0x779291bef19b6709f61e9764a954aafe9ffae488d50ae674aabdcb4f248006d5","spread":"0.03","timestamp":"1785207866715"},"payload_hash":"297fa4c17611686a400a83e5002e57a60b2ac7d317837ee1189b0cace933d51b","raw_frame":"{\"market\":\"0x779291bef19b6709f61e9764a954aafe9ffae488d50ae674aabdcb4f248006d5\", \"asset_id\":\"14965588658799411272385430903075831224615961675357217884735713260981483529984\", \"best_bid\":\"0.38\", \"best_ask\":\"0.41\", \"spread\":\"0.03\", \"timestamp\":\"1785207866715\", \"event_type\":\"best_bid_ask\"}","received_at":"2026-07-28T03:04:26.763380Z","schema_version":"clob-market-ws.best_bid_ask.v1","sequence":null,"server_hash":null,"server_timestamp":"1785207866715","session_id":"3e519d9098404c15b234d96025eb1a2b","source":"clob_market_ws"},"received_at":"2026-07-28T03:04:26.763380Z","record_id":"bc38f174be21aedaa271d3a0d74e2b59aa90836823c91abe5fd0315d6f36962e","schema_fingerprint":"8488399f31b0337811b13b266be932db7062827c2470b78bd8e9e99bab51d17d","schema_version":"edge-lab-recorder.raw.v1","sequence":null,"source":"clob_market_ws"}
{"event_at":"2026-07-28T03:04:26.715000Z","event_fingerprint":"a192e529305ba27f733767be30f6267d04d9be76498c961fc1e33383d6e31f62","payload":{"connection_id":"a6b55582af5f430fb37ad02bf0922475","event_at":"2026-07-28T03:04:26.715000Z","event_type":"best_bid_ask","frame_hash":"d333c60078622e3d029bedeb5cd78ef3a4266453c36531abd3ac8541671d33ed","frame_index":0,"kind":"data","monotonic_ns":309849790366166,"payload":{"asset_id":"8761897749749422724209054078244794145777693856614463256546737399611489089783","best_ask":"0.62","best_bid":"0.59","event_type":"best_bid_ask","market":"0x779291bef19b6709f61e9764a954aafe9ffae488d50ae674aabdcb4f248006d5","spread":"0.03","timestamp":"1785207866715"},"payload_hash":"b85d2d1c12c1af00a5892f61c4fad8a89898907c72957ca95f980c3db4652d31","raw_frame":"{\"market\":\"0x779291bef19b6709f61e9764a954aafe9ffae488d50ae674aabdcb4f248006d5\", \"asset_id\":\"8761897749749422724209054078244794145777693856614463256546737399611489089783\", \"best_bid\":\"0.59\", \"best_ask\":\"0.62\", \"spread\":\"0.03\", \"timestamp\":\"1785207866715\", \"event_type\":\"best_bid_ask\"}","received_at":"2026-07-28T03:04:26.764398Z","schema_version":"clob-market-ws.best_bid_ask.v1","sequence":null,"server_hash":null,"server_timestamp":"1785207866715","session_id":"3e519d9098404c15b234d96025eb1a2b","source":"clob_market_ws"},"received_at":"2026-07-28T03:04:26.764398Z","record_id":"cc3dbb440a8ff8a413fe7e9f46f34187ae1a59b3dd291fbf9e4665079d1cf683","schema_fingerprint":"8488399f31b0337811b13b266be932db7062827c2470b78bd8e9e99bab51d17d","schema_version":"edge-lab-recorder.raw.v1","sequence":null,"source":"clob_market_ws"}
{"event_at":"2026-07-28T03:04:26.715000Z","event_fingerprint":"90f819d10c7d3f4276d3943dc43472873756b5e9bceba7b7c6b53eda842100b7","payload":{"connection_id":"a6b55582af5f430fb37ad02bf0922475","event_at":"2026-07-28T03:04:26.715000Z","event_type":"price_change","frame_hash":"44519ae9b4da8cb482873dfbc280f3e1aa0378afb24dd62629598071caa5e42d","frame_index":0,"kind":"data","monotonic_ns":309849792744666,"payload":{"event_type":"price_change","market":"0x779291bef19b6709f61e9764a954aafe9ffae488d50ae674aabdcb4f248006d5","price_changes":[{"asset_id":"14965588658799411272385430903075831224615961675357217884735713260981483529984","best_ask":"0.41","best_bid":"0.38","hash":"b15f6570633bb8793ac6b66295855ed2dea3b3f4","price":"0.4","side":"BUY","size":"0"},{"asset_id":"8761897749749422724209054078244794145777693856614463256546737399611489089783","best_ask":"0.62","best_bid":"0.59","hash":"7e8d8b0680a88899be3af4116cc0fd24bf5e9156","price":"0.6","side":"SELL","size":"0"}],"timestamp":"1785207866715"},"payload_hash":"e4b61d21abcf1266fca30cf738ceb7cf1b478a6e4ffbe1743e69eb5f67eb0fbc","raw_frame":"{\"market\":\"0x779291bef19b6709f61e9764a954aafe9ffae488d50ae674aabdcb4f248006d5\", \"price_changes\":[{\"asset_id\":\"14965588658799411272385430903075831224615961675357217884735713260981483529984\", \"price\":\"0.4\", \"size\":\"0\", \"side\":\"BUY\", \"hash\":\"b15f6570633bb8793ac6b66295855ed2dea3b3f4\", \"best_bid\":\"0.38\", \"best_ask\":\"0.41\"}, {\"asset_id\":\"8761897749749422724209054078244794145777693856614463256546737399611489089783\", \"price\":\"0.6\", \"size\":\"0\", \"side\":\"SELL\", \"hash\":\"7e8d8b0680a88899be3af4116cc0fd24bf5e9156\", \"best_bid\":\"0.59\", \"best_ask\":\"0.62\"}], \"timestamp\":\"1785207866715\", \"event_type\":\"price_change\"}","received_at":"2026-07-28T03:04:26.766776Z","schema_version":"clob-market-ws.price_change.v1","sequence":null,"server_hash":null,"server_timestamp":"1785207866715","session_id":"3e519d9098404c15b234d96025eb1a2b","source":"clob_market_ws"},"received_at":"2026-07-28T03:04:26.766776Z","record_id":"54b74a2478e9536a529004e7f0f949ce153bff4f781c76d1ea281ca8be34523f","schema_fingerprint":"4aa3821a28b0b7c2400bc59aba4bcc0a76e971dadd19610d3ad38c768e124dc7","schema_version":"edge-lab-recorder.raw.v1","sequence":null,"source":"clob_market_ws"}
{"event_at":"2026-07-28T03:04:26.723000Z","event_fingerprint":"fdb400484241c70d69d939f9f2d67e6d2055e2a6b81330acb711e5ed0992219c","payload":{"connection_id":"a6b55582af5f430fb37ad02bf0922475","event_at":"2026-07-28T03:04:26.723000Z","event_type":"price_change","frame_hash":"f0744901c6f11ee05a37e089e5e4681859e459a02a9e9f8184dbea1ad423859e","frame_index":0,"kind":"data","monotonic_ns":309849794176708,"payload":{"event_type":"price_change","market":"0x779291bef19b6709f61e9764a954aafe9ffae488d50ae674aabdcb4f248006d5","price_changes":[{"asset_id":"14965588658799411272385430903075831224615961675357217884735713260981483529984","best_ask":"0.41","best_bid":"0.38","hash":"b977bc9779a07d689178c7dcf1205db69f07a71c","price":"0.37","side":"BUY","size":"416"},{"asset_id":"8761897749749422724209054078244794145777693856614463256546737399611489089783","best_ask":"0.62","best_bid":"0.59","hash":"5a12046560ef517379d1ee7326502803b2de099f","price":"0.63","side":"SELL","size":"416"}],"timestamp":"1785207866723"},"payload_hash":"bb13530393019cd81634caab1a866e2c54caad1e54df6ae762352cf0c4c418a3","raw_frame":"{\"market\":\"0x779291bef19b6709f61e9764a954aafe9ffae488d50ae674aabdcb4f248006d5\", \"price_changes\":[{\"asset_id\":\"14965588658799411272385430903075831224615961675357217884735713260981483529984\", \"price\":\"0.37\", \"size\":\"416\", \"side\":\"BUY\", \"hash\":\"b977bc9779a07d689178c7dcf1205db69f07a71c\", \"best_bid\":\"0.38\", \"best_ask\":\"0.41\"}, {\"asset_id\":\"8761897749749422724209054078244794145777693856614463256546737399611489089783\", \"price\":\"0.63\", \"size\":\"416\", \"side\":\"SELL\", \"hash\":\"5a12046560ef517379d1ee7326502803b2de099f\", \"best_bid\":\"0.59\", \"best_ask\":\"0.62\"}], \"timestamp\":\"1785207866723\", \"event_type\":\"price_change\"}","received_at":"2026-07-28T03:04:26.768208Z","schema_version":"clob-market-ws.price_change.v1","sequence":null,"server_hash":null,"server_timestamp":"1785207866723","session_id":"3e519d9098404c15b234d96025eb1a2b","source":"clob_market_ws"},"received_at":"2026-07-28T03:04:26.768208Z","record_id":"9dea491b0e41ccb0ecf5c23881dd9b9c33e3f50da30aa773cfcee9500795f283","schema_fingerprint":"4aa3821a28b0b7c2400bc59aba4bcc0a76e971dadd19610d3ad38c768e124dc7","schema_version":"edge-lab-recorder.raw.v1","sequence":null,"source":"clob_market_ws"}
{"event_at":"2026-07-28T03:04:26.723000Z","event_fingerprint":"90cc08268d9cb2308dfee9db231b9c8e7d472062649f0162607f123192a74bde","payload":{"connection_id":"a6b55582af5f430fb37ad02bf0922475","event_at":"2026-07-28T03:04:26.723000Z","event_type":"price_change","frame_hash":"e325f298d9446dafa99f90f18bbf20bba25b33bb8f58dbd14dcde3a18d7830d3","frame_index":0,"kind":"data","monotonic_ns":309849795626416,"payload":{"event_type":"price_change","market":"0x779291bef19b6709f61e9764a954aafe9ffae488d50ae674aabdcb4f248006d5","price_changes":[{"asset_id":"8761897749749422724209054078244794145777693856614463256546737399611489089783","best_ask":"0.62","best_bid":"0.59","hash":"d6cbf691febd4ca194ecc46b1c493398bcb4eb22","price":"0.47","side":"BUY","size":"194"},{"asset_id":"14965588658799411272385430903075831224615961675357217884735713260981483529984","best_ask":"0.41","best_bid":"0.38","hash":"24ddff48444983c9b29807c52922fea6c91bd292","price":"0.53","side":"SELL","size":"194"}],"timestamp":"1785207866723"},"payload_hash":"d1dd9324db13178456fa93ed91951f942087735069899b3279100912ab5f8084","raw_frame":"{\"market\":\"0x779291bef19b6709f61e9764a954aafe9ffae488d50ae674aabdcb4f248006d5\", \"price_changes\":[{\"asset_id\":\"8761897749749422724209054078244794145777693856614463256546737399611489089783\", \"price\":\"0.47\", \"size\":\"194\", \"side\":\"BUY\", \"hash\":\"d6cbf691febd4ca194ecc46b1c493398bcb4eb22\", \"best_bid\":\"0.59\", \"best_ask\":\"0.62\"}, {\"asset_id\":\"14965588658799411272385430903075831224615961675357217884735713260981483529984\", \"price\":\"0.53\", \"size\":\"194\", \"side\":\"SELL\", \"hash\":\"24ddff48444983c9b29807c52922fea6c91bd292\", \"best_bid\":\"0.38\", \"best_ask\":\"0.41\"}], \"timestamp\":\"1785207866723\", \"event_type\":\"price_change\"}","received_at":"2026-07-28T03:04:26.769657Z","schema_version":"clob-market-ws.price_change.v1","sequence":null,"server_hash":null,"server_timestamp":"1785207866723","session_id":"3e519d9098404c15b234d96025eb1a2b","source":"clob_market_ws"},"received_at":"2026-07-28T03:04:26.769657Z","record_id":"340f21dd5e89978ddb5d07666a61f357715eacf1cdc2739a2bfb48331b4f33e4","schema_fingerprint":"4aa3821a28b0b7c2400bc59aba4bcc0a76e971dadd19610d3ad38c768e124dc7","schema_version":"edge-lab-recorder.raw.v1","sequence":null,"source":"clob_market_ws"}
{"event_at":"2026-07-28T03:04:26.724000Z","event_fingerprint":"95f1ec493d3cd5990e9e39cddc5fd066a23d6121940889e23fecaafe85bc9614","payload":{"connection_id":"a6b55582af5f430fb37ad02bf0922475","event_at":"2026-07-28T03:04:26.724000Z","event_type":"price_change","frame_hash":"fa8236929b990f1cd6b0656ee73280a70d371226765a4f7d17637764891cc760","frame_index":0,"kind":"data","monotonic_ns":309849797062333,"payload":{"event_type":"price_change","market":"0x779291bef19b6709f61e9764a954aafe9ffae488d50ae674aabdcb4f248006d5","price_changes":[{"asset_id":"14965588658799411272385430903075831224615961675357217884735713260981483529984","best_ask":"0.41","best_bid":"0.38","hash":"984b88457e91707d10fdd5a7e7a9e85dbb0923fa","price":"0.28","side":"BUY","size":"187.34"},{"asset_id":"8761897749749422724209054078244794145777693856614463256546737399611489089783","best_ask":"0.62","best_bid":"0.59","hash":"d93d112f67c6835244df3fc1a8bb4530949db730","price":"0.72","side":"SELL","size":"187.34"}],"timestamp":"1785207866724"},"payload_hash":"5b16e8f408d5cc4c00fd41b21603b9c5ad47fef5a2fc97bb042c94a1fdd6db7e","raw_frame":"{\"market\":\"0x779291bef19b6709f61e9764a954aafe9ffae488d50ae674aabdcb4f248006d5\", \"price_changes\":[{\"asset_id\":\"14965588658799411272385430903075831224615961675357217884735713260981483529984\", \"price\":\"0.28\", \"size\":\"187.34\", \"side\":\"BUY\", \"hash\":\"984b88457e91707d10fdd5a7e7a9e85dbb0923fa\", \"best_bid\":\"0.38\", \"best_ask\":\"0.41\"}, {\"asset_id\":\"8761897749749422724209054078244794145777693856614463256546737399611489089783\", \"price\":\"0.72\", \"size\":\"187.34\", \"side\":\"SELL\", \"hash\":\"d93d112f67c6835244df3fc1a8bb4530949db730\", \"best_bid\":\"0.59\", \"best_ask\":\"0.62\"}], \"timestamp\":\"1785207866724\", \"event_type\":\"price_change\"}","received_at":"2026-07-28T03:04:26.771092Z","schema_version":"clob-market-ws.price_change.v1","sequence":null,"server_hash":null,"server_timestamp":"1785207866724","session_id":"3e519d9098404c15b234d96025eb1a2b","source":"clob_market_ws"},"received_at":"2026-07-28T03:04:26.771092Z","record_id":"8f1fe152285660746e07a13d73decd6d2ba3b6cf3dfd43405f69099afc35f3cd","schema_fingerprint":"4aa3821a28b0b7c2400bc59aba4bcc0a76e971dadd19610d3ad38c768e124dc7","schema_version":"edge-lab-recorder.raw.v1","sequence":null,"source":"clob_market_ws"}
{"event_at":"2026-07-28T03:04:26.731000Z","event_fingerprint":"443770fe1b2bb8369ad9556ecf74483c6a46e581eb6bd5a215e3646b30f2a8cc","payload":{"connection_id":"a6b55582af5f430fb37ad02bf0922475","event_at":"2026-07-28T03:04:26.731000Z","event_type":"price_change","frame_hash":"a1a83660d16734df6871096aee855812171bf6af4f293ca501895035c6a64079","frame_index":0,"kind":"data","monotonic_ns":309849798516916,"payload":{"event_type":"price_change","market":"0x779291bef19b6709f61e9764a954aafe9ffae488d50ae674aabdcb4f248006d5","price_changes":[{"asset_id":"14965588658799411272385430903075831224615961675357217884735713260981483529984","best_ask":"0.41","best_bid":"0.38","hash":"00732bc12cbad91dd260d1a20c6ef6ca6bc901e1","price":"0.38","side":"BUY","size":"47.6"},{"asset_id":"8761897749749422724209054078244794145777693856614463256546737399611489089783","best_ask":"0.62","best_bid":"0.59","hash":"6205c90654f43c9aade057c302ed3b86d18b50e4","price":"0.62","side":"SELL","size":"47.6"}],"timestamp":"1785207866731"},"payload_hash":"aef00c4a4ff0073af8abe4cb38898df429c5ef7fd6bf7e9a54f77799d90a9a44","raw_frame":"{\"market\":\"0x779291bef19b6709f61e9764a954aafe9ffae488d50ae674aabdcb4f248006d5\", \"price_changes\":[{\"asset_id\":\"14965588658799411272385430903075831224615961675357217884735713260981483529984\", \"price\":\"0.38\", \"size\":\"47.6\", \"side\":\"BUY\", \"hash\":\"00732bc12cbad91dd260d1a20c6ef6ca6bc901e1\", \"best_bid\":\"0.38\", \"best_ask\":\"0.41\"}, {\"asset_id\":\"8761897749749422724209054078244794145777693856614463256546737399611489089783\", \"price\":\"0.62\", \"size\":\"47.6\", \"side\":\"SELL\", \"hash\":\"6205c90654f43c9aade057c302ed3b86d18b50e4\", \"best_bid\":\"0.59\", \"best_ask\":\"0.62\"}], \"timestamp\":\"1785207866731\", \"event_type\":\"price_change\"}","received_at":"2026-07-28T03:04:26.772547Z","schema_version":"clob-market-ws.price_change.v1","sequence":null,"server_hash":null,"server_timestamp":"1785207866731","session_id":"3e519d9098404c15b234d96025eb1a2b","source":"clob_market_ws"},"received_at":"2026-07-28T03:04:26.772547Z","record_id":"bd0b5797c4e6724ae8857e2a594733e22c118c9acca2e8ed571096b9b30c3ab7","schema_fingerprint":"4aa3821a28b0b7c2400bc59aba4bcc0a76e971dadd19610d3ad38c768e124dc7","schema_version":"edge-lab-recorder.raw.v1","sequence":null,"source":"clob_market_ws"}
{"event_at":"2026-07-28T03:04:26.732000Z","event_fingerprint":"9b06430062d71476791f90e5725639b54306f36defdf4151a93ee1605ba0d5bd","payload":{"connection_id":"a6b55582af5f430fb37ad02bf0922475","event_at":"2026-07-28T03:04:26.732000Z","event_type":"price_change","frame_hash":"40bf7eec58ee8b12ddbcb6d2b199c8fc6dcdea19a7465007d6a5d47c64a9bb4d","frame_index":0,"kind":"data","monotonic_ns":309849799959541,"payload":{"event_type":"price_change","market":"0x779291bef19b6709f61e9764a954aafe9ffae488d50ae674aabdcb4f248006d5","price_changes":[{"asset_id":"14965588658799411272385430903075831224615961675357217884735713260981483529984","best_ask":"0.41","best_bid":"0.38","hash":"7bf88bb3507d3cd6fc5e61dd57d662cc2d5c45e5","price":"0.35","side":"BUY","size":"162"},{"asset_id":"8761897749749422724209054078244794145777693856614463256546737399611489089783","best_ask":"0.62","best_bid":"0.59","hash":"0e04e9c50fa80e1549dd64f3ec43ecb76aa5c062","price":"0.65","side":"SELL","size":"162"}],"timestamp":"1785207866732"},"payload_hash":"0d5176934ff3f00fd99d719342b6619447cfc559bed4856c2558ef7ba8241936","raw_frame":"{\"market\":\"0x779291bef19b6709f61e9764a954aafe9ffae488d50ae674aabdcb4f248006d5\", \"price_changes\":[{\"asset_id\":\"14965588658799411272385430903075831224615961675357217884735713260981483529984\", \"price\":\"0.35\", \"size\":\"162\", \"side\":\"BUY\", \"hash\":\"7bf88bb3507d3cd6fc5e61dd57d662cc2d5c45e5\", \"best_bid\":\"0.38\", \"best_ask\":\"0.41\"}, {\"asset_id\":\"8761897749749422724209054078244794145777693856614463256546737399611489089783\", \"price\":\"0.65\", \"size\":\"162\", \"side\":\"SELL\", \"hash\":\"0e04e9c50fa80e1549dd64f3ec43ecb76aa5c062\", \"best_bid\":\"0.59\", \"best_ask\":\"0.62\"}], \"timestamp\":\"1785207866732\", \"event_type\":\"price_change\"}","received_at":"2026-07-28T03:04:26.773989Z","schema_version":"clob-market-ws.price_change.v1","sequence":null,"server_hash":null,"server_timestamp":"1785207866732","session_id":"3e519d9098404c15b234d96025eb1a2b","source":"clob_market_ws"},"received_at":"2026-07-28T03:04:26.773989Z","record_id":"f7387937af94a2851a6dd4c66db8027b9c5a642fa4ffddefa21fd95a79773069","schema_fingerprint":"4aa3821a28b0b7c2400bc59aba4bcc0a76e971dadd19610d3ad38c768e124dc7","schema_version":"edge-lab-recorder.raw.v1","sequence":null,"source":"clob_market_ws"}
{"event_at":"2026-07-28T03:04:26.733000Z","event_fingerprint":"51236fbecb84a9db3cf7a5f5395abced0342f9b81132c95bd38765eb689acad0","payload":{"connection_id":"a6b55582af5f430fb37ad02bf0922475","event_at":"2026-07-28T03:04:26.733000Z","event_type":"price_change","frame_hash":"a39f418777255502b81d0522c8f5a3f9c7fa6aaa69c161f77c70e86f7484a101","frame_index":0,"kind":"data","monotonic_ns":309849801413708,"payload":{"event_type":"price_change","market":"0x779291bef19b6709f61e9764a954aafe9ffae488d50ae674aabdcb4f248006d5","price_changes":[{"asset_id":"8761897749749422724209054078244794145777693856614463256546737399611489089783","best_ask":"0.62","best_bid":"0.59","hash":"59e065979089d82794b2573efc075d38503d332d","price":"0.47","side":"BUY","size":"189"},{"asset_id":"14965588658799411272385430903075831224615961675357217884735713260981483529984","best_ask":"0.41","best_bid":"0.38","hash":"4876085fcca4b43ad9ba6f0d71ee1bb773c123d8","price":"0.53","side":"SELL","size":"189"}],"timestamp":"1785207866733"},"payload_hash":"1e8e3bae7b904629f4d9b35b2797efa5f24c31066cdd7f01e75b4bfc98d08bc3","raw_frame":"{\"market\":\"0x779291bef19b6709f61e9764a954aafe9ffae488d50ae674aabdcb4f248006d5\", \"price_changes\":[{\"asset_id\":\"8761897749749422724209054078244794145777693856614463256546737399611489089783\", \"price\":\"0.47\", \"size\":\"189\", \"side\":\"BUY\", \"hash\":\"59e065979089d82794b2573efc075d38503d332d\", \"best_bid\":\"0.59\", \"best_ask\":\"0.62\"}, {\"asset_id\":\"14965588658799411272385430903075831224615961675357217884735713260981483529984\", \"price\":\"0.53\", \"size\":\"189\", \"side\":\"SELL\", \"hash\":\"4876085fcca4b43ad9ba6f0d71ee1bb773c123d8\", \"best_bid\":\"0.38\", \"best_ask\":\"0.41\"}], \"timestamp\":\"1785207866733\", \"event_type\":\"price_change\"}","received_at":"2026-07-28T03:04:26.775443Z","schema_version":"clob-market-ws.price_change.v1","sequence":null,"server_hash":null,"server_timestamp":"1785207866733","session_id":"3e519d9098404c15b234d96025eb1a2b","source":"clob_market_ws"},"received_at":"2026-07-28T03:04:26.775443Z","record_id":"4be66d5af580a0865514b4f6639cc840060e3f489a2149281db6616beb1deb70","schema_fingerprint":"4aa3821a28b0b7c2400bc59aba4bcc0a76e971dadd19610d3ad38c768e124dc7","schema_version":"edge-lab-recorder.raw.v1","sequence":null,"source":"clob_market_ws"}
{"event_at":"2026-07-28T03:04:26.733000Z","event_fingerprint":"5bc98973b4169c6e076f5b1587cb66a446f4ce454acc15f4196998ae590e04b6","payload":{"connection_id":"a6b55582af5f430fb37ad02bf0922475","event_at":"2026-07-28T03:04:26.733000Z","event_type":"price_change","frame_hash":"7ce63033f31e8e6cf5978c040d35dfaa9f0f78405aa6ba2605f8f60a438b7417","frame_index":0,"kind":"data","monotonic_ns":309849802834208,"payload":{"event_type":"price_change","market":"0x779291bef19b6709f61e9764a954aafe9ffae488d50ae674aabdcb4f248006d5","price_changes":[{"asset_id":"8761897749749422724209054078244794145777693856614463256546737399611489089783","best_ask":"0.62","best_bid":"0.59","hash":"59e065979089d82794b2573efc075d38503d332d","price":"0.46","side":"BUY","size":"183"},{"asset_id":"14965588658799411272385430903075831224615961675357217884735713260981483529984","best_ask":"0.41","best_bid":"0.38","hash":"4876085fcca4b43ad9ba6f0d71ee1bb773c123d8","price":"0.54","side":"SELL","size":"183"}],"timestamp":"1785207866733"},"payload_hash":"39f73b9dcf47eadcc731f0b38e59307588fe1f23262ee8b776b767b5626968fe","raw_frame":"{\"market\":\"0x779291bef19b6709f61e9764a954aafe9ffae488d50ae674aabdcb4f248006d5\", \"price_changes\":[{\"asset_id\":\"8761897749749422724209054078244794145777693856614463256546737399611489089783\", \"price\":\"0.46\", \"size\":\"183\", \"side\":\"BUY\", \"hash\":\"59e065979089d82794b2573efc075d38503d332d\", \"best_bid\":\"0.59\", \"best_ask\":\"0.62\"}, {\"asset_id\":\"14965588658799411272385430903075831224615961675357217884735713260981483529984\", \"price\":\"0.54\", \"size\":\"183\", \"side\":\"SELL\", \"hash\":\"4876085fcca4b43ad9ba6f0d71ee1bb773c123d8\", \"best_bid\":\"0.38\", \"best_ask\":\"0.41\"}], \"timestamp\":\"1785207866733\", \"event_type\":\"price_change\"}","received_at":"2026-07-28T03:04:26.776862Z","schema_version":"clob-market-ws.price_change.v1","sequence":null,"server_hash":null,"server_timestamp":"1785207866733","session_id":"3e519d9098404c15b234d96025eb1a2b","source":"clob_market_ws"},"received_at":"2026-07-28T03:04:26.776862Z","record_id":"36fd391d2675ada4fd0c07f2c893682d62ceb2a605e2d283e71dd847e82e7f09","schema_fingerprint":"4aa3821a28b0b7c2400bc59aba4bcc0a76e971dadd19610d3ad38c768e124dc7","schema_version":"edge-lab-recorder.raw.v1","sequence":null,"source":"clob_market_ws"}
{"event_at":"2026-07-28T03:04:26.733000Z","event_fingerprint":"195bcdaf51b966b938da198afb17a21c484e91f1612a0e547334f9adff278b15","payload":{"connection_id":"a6b55582af5f430fb37ad02bf0922475","event_at":"2026-07-28T03:04:26.733000Z","event_type":"price_change","frame_hash":"5127c84045480af6b63a692b65f61fed1b4358f4ff1ee3b9062519d9aff71126","frame_index":0,"kind":"data","monotonic_ns":309849804286083,"payload":{"event_type":"price_change","market":"0x779291bef19b6709f61e9764a954aafe9ffae488d50ae674aabdcb4f248006d5","price_changes":[{"asset_id":"8761897749749422724209054078244794145777693856614463256546737399611489089783","best_ask":"0.62","best_bid":"0.59","hash":"132c0e5c9f059f674173d5515b5fe290a9e731fb","price":"0.49","side":"BUY","size":"193"},{"asset_id":"14965588658799411272385430903075831224615961675357217884735713260981483529984","best_ask":"0.41","best_bid":"0.38","hash":"7b7de6c4b97b5a5eb1e53de8060f255755822b17","price":"0.51","side":"SELL","size":"193"}],"timestamp":"1785207866733"},"payload_hash":"b93fda599285043433ea5628d26d0711f5874e6918504206c4a056737999ff34","raw_frame":"{\"market\":\"0x779291bef19b6709f61e9764a954aafe9ffae488d50ae674aabdcb4f248006d5\", \"price_changes\":[{\"asset_id\":\"8761897749749422724209054078244794145777693856614463256546737399611489089783\", \"price\":\"0.49\", \"size\":\"193\", \"side\":\"BUY\", \"hash\":\"132c0e5c9f059f674173d5515b5fe290a9e731fb\", \"best_bid\":\"0.59\", \"best_ask\":\"0.62\"}, {\"asset_id\":\"14965588658799411272385430903075831224615961675357217884735713260981483529984\", \"price\":\"0.51\", \"size\":\"193\", \"side\":\"SELL\", \"hash\":\"7b7de6c4b97b5a5eb1e53de8060f255755822b17\", \"best_bid\":\"0.38\", \"best_ask\":\"0.41\"}], \"timestamp\":\"1785207866733\", \"event_type\":\"price_change\"}","received_at":"2026-07-28T03:04:26.778314Z","schema_version":"clob-market-ws.price_change.v1","sequence":null,"server_hash":null,"server_timestamp":"1785207866733","session_id":"3e519d9098404c15b234d96025eb1a2b","source":"clob_market_ws"},"received_at":"2026-07-28T03:04:26.778314Z","record_id":"3aecbbe1551a6e444bb97a5d9cdfebc73a2d8b39c01f0baa5e4125aee188b462","schema_fingerprint":"4aa3821a28b0b7c2400bc59aba4bcc0a76e971dadd19610d3ad38c768e124dc7","schema_version":"edge-lab-recorder.raw.v1","sequence":null,"source":"clob_market_ws"}
{"event_at":"2026-07-28T03:04:26.733000Z","event_fingerprint":"eea44e15d4ac12e74c5943f398aee859d79e02050d5dae4bd5fd1c0e9e9060c3","payload":{"connection_id":"a6b55582af5f430fb37ad02bf0922475","event_at":"2026-07-28T03:04:26.733000Z","event_type":"best_bid_ask","frame_hash":"4162af4ab6726eed0120b0b39b44f2d94d9e9e64010be3dca962f8304900db7b","frame_index":0,"kind":"data","monotonic_ns":309849805710000,"payload":{"asset_id":"14965588658799411272385430903075831224615961675357217884735713260981483529984","best_ask":"0.4","best_bid":"0.38","event_type":"best_bid_ask","market":"0x779291bef19b6709f61e9764a954aafe9ffae488d50ae674aabdcb4f248006d5","spread":"0.02","timestamp":"1785207866733"},"payload_hash":"6c7bd5b2edd96d4f8f7b26142dead77b70fe2987976962199ce8c1236179bb12","raw_frame":"{\"market\":\"0x779291bef19b6709f61e9764a954aafe9ffae488d50ae674aabdcb4f248006d5\", \"asset_id\":\"14965588658799411272385430903075831224615961675357217884735713260981483529984\", \"best_bid\":\"0.38\", \"best_ask\":\"0.4\", \"spread\":\"0.02\", \"timestamp\":\"1785207866733\", \"event_type\":\"best_bid_ask\"}","received_at":"2026-07-28T03:04:26.779737Z","schema_version":"clob-market-ws.best_bid_ask.v1","sequence":null,"server_hash":null,"server_timestamp":"1785207866733","session_id":"3e519d9098404c15b234d96025eb1a2b","source":"clob_market_ws"},"received_at":"2026-07-28T03:04:26.779737Z","record_id":"eab9b3a783857f5f44ef25d34f561700cc2d009bda1dbd9b941d95cf5fdb3f51","schema_fingerprint":"8488399f31b0337811b13b266be932db7062827c2470b78bd8e9e99bab51d17d","schema_version":"edge-lab-recorder.raw.v1","sequence":null,"source":"clob_market_ws"}
{"event_at":"2026-07-28T03:04:26.733000Z","event_fingerprint":"e66d5d9e2742cac4fe4b5e52cc1489fc2b25f9b55ff8566b5b323081a9872595","payload":{"connection_id":"a6b55582af5f430fb37ad02bf0922475","event_at":"2026-07-28T03:04:26.733000Z","event_type":"best_bid_ask","frame_hash":"9e2602540f4c0348491a4c0423388d8458fd4443b09d00c93d15cdfb7347a10a","frame_index":0,"kind":"data","monotonic_ns":309849806717041,"payload":{"asset_id":"8761897749749422724209054078244794145777693856614463256546737399611489089783","best_ask":"0.62","best_bid":"0.6","event_type":"best_bid_ask","market":"0x779291bef19b6709f61e9764a954aafe9ffae488d50ae674aabdcb4f248006d5","spread":"0.02","timestamp":"1785207866733"},"payload_hash":"a0b361dc58860ccac14480a11c1b7f076a4d3c1df6a6bb6153cf99f386ab9bae","raw_frame":"{\"market\":\"0x779291bef19b6709f61e9764a954aafe9ffae488d50ae674aabdcb4f248006d5\", \"asset_id\":\"8761897749749422724209054078244794145777693856614463256546737399611489089783\", \"best_bid\":\"0.6\", \"best_ask\":\"0.62\", \"spread\":\"0.02\", \"timestamp\":\"1785207866733\", \"event_type\":\"best_bid_ask\"}","received_at":"2026-07-28T03:04:26.780744Z","schema_version":"clob-market-ws.best_bid_ask.v1","sequence":null,"server_hash":null,"server_timestamp":"1785207866733","session_id":"3e519d9098404c15b234d96025eb1a2b","source":"clob_market_ws"},"received_at":"2026-07-28T03:04:26.780744Z","record_id":"185d26d85362dfbb37eba9b1622aa2728e03269fd33e8a91a2cdb3981a64ff35","schema_fingerprint":"8488399f31b0337811b13b266be932db7062827c2470b78bd8e9e99bab51d17d","schema_version":"edge-lab-recorder.raw.v1","sequence":null,"source":"clob_market_ws"}
{"event_at":"2026-07-28T03:04:26.733000Z","event_fingerprint":"586cb4a87644c8df5dc36250da85badf323a01ced7ae4425f86fb3441629c0e1","payload":{"connection_id":"a6b55582af5f430fb37ad02bf0922475","event_at":"2026-07-28T03:04:26.733000Z","event_type":"price_change","frame_hash":"c45d1c43d50595a465efd3abbcee481cbf1420094c330d48ca15ee0b5a4c2d46","frame_index":0,"kind":"data","monotonic_ns":309849807771875,"payload":{"event_type":"price_change","market":"0x779291bef19b6709f61e9764a954aafe9ffae488d50ae674aabdcb4f248006d5","price_changes":[{"asset_id":"8761897749749422724209054078244794145777693856614463256546737399611489089783","best_ask":"0.62","best_bid":"0.6","hash":"94dab942a45f44f84d7a5b2af1028c069482ca9a","price":"0.6","side":"BUY","size":"12.6"},{"asset_id":"14965588658799411272385430903075831224615961675357217884735713260981483529984","best_ask":"0.4","best_bid":"0.38","hash":"dee7b113b8a40651fbb519c68199ba00af7fdd9a","price":"0.4","side":"SELL","size":"12.6"}],"timestamp":"1785207866733"},"payload_hash":"4eeba5d9c578c45b582aa371c699fccf5f83f7db116206aefe5996c14e4554df","raw_frame":"{\"market\":\"0x779291bef19b6709f61e9764a954aafe9ffae488d50ae674aabdcb4f248006d5\", \"price_changes\":[{\"asset_id\":\"8761897749749422724209054078244794145777693856614463256546737399611489089783\", \"price\":\"0.6\", \"size\":\"12.6\", \"side\":\"BUY\", \"hash\":\"94dab942a45f44f84d7a5b2af1028c069482ca9a\", \"best_bid\":\"0.6\", \"best_ask\":\"0.62\"}, {\"asset_id\":\"14965588658799411272385430903075831224615961675357217884735713260981483529984\", \"price\":\"0.4\", \"size\":\"12.6\", \"side\":\"SELL\", \"hash\":\"dee7b113b8a40651fbb519c68199ba00af7fdd9a\", \"best_bid\":\"0.38\", \"best_ask\":\"0.4\"}], \"timestamp\":\"1785207866733\", \"event_type\":\"price_change\"}","received_at":"2026-07-28T03:04:26.781796Z","schema_version":"clob-market-ws.price_change.v1","sequence":null,"server_hash":null,"server_timestamp":"1785207866733","session_id":"3e519d9098404c15b234d96025eb1a2b","source":"clob_market_ws"},"received_at":"2026-07-28T03:04:26.781796Z","record_id":"96ec906a14f0ba526519b0568c1acbbc721f247ea44b4325523af6a54c4baf99","schema_fingerprint":"4aa3821a28b0b7c2400bc59aba4bcc0a76e971dadd19610d3ad38c768e124dc7","schema_version":"edge-lab-recorder.raw.v1","sequence":null,"source":"clob_market_ws"}
{"event_at":"2026-07-28T03:04:26.734000Z","event_fingerprint":"b89942ae224266f1860fd31bc83913749713bcc232b3d0179bc8ce56b8b6053e","payload":{"connection_id":"a6b55582af5f430fb37ad02bf0922475","event_at":"2026-07-28T03:04:26.734000Z","event_type":"price_change","frame_hash":"c1818c9c32bf49a3e61fb66371a9277ff3b8f18cd5d0e67cbf45cabcb6c70bdd","frame_index":0,"kind":"data","monotonic_ns":309849809308458,"payload":{"event_type":"price_change","market":"0x779291bef19b6709f61e9764a954aafe9ffae488d50ae674aabdcb4f248006d5","price_changes":[{"asset_id":"14965588658799411272385430903075831224615961675357217884735713260981483529984","best_ask":"0.4","best_bid":"0.38","hash":"107e7bcad9ba266e34539eda2c699d1f72ab17bf","price":"0.28","side":"BUY","size":"180.9"},{"asset_id":"8761897749749422724209054078244794145777693856614463256546737399611489089783","best_ask":"0.62","best_bid":"0.6","hash":"fe432ef0c52f9c2b99ceafcfd45f80e6bdd5eb81","price":"0.72","side":"SELL","size":"180.9"}],"timestamp":"1785207866734"},"payload_hash":"c0a93afe84bb9f9cde878ae9f4b4505cdf5288d4e1b4b0f177ba00c46bac9af0","raw_frame":"{\"market\":\"0x779291bef19b6709f61e9764a954aafe9ffae488d50ae674aabdcb4f248006d5\", \"price_changes\":[{\"asset_id\":\"14965588658799411272385430903075831224615961675357217884735713260981483529984\", \"price\":\"0.28\", \"size\":\"180.9\", \"side\":\"BUY\", \"hash\":\"107e7bcad9ba266e34539eda2c699d1f72ab17bf\", \"best_bid\":\"0.38\", \"best_ask\":\"0.4\"}, {\"asset_id\":\"8761897749749422724209054078244794145777693856614463256546737399611489089783\", \"price\":\"0.72\", \"size\":\"180.9\", \"side\":\"SELL\", \"hash\":\"fe432ef0c52f9c2b99ceafcfd45f80e6bdd5eb81\", \"best_bid\":\"0.6\", \"best_ask\":\"0.62\"}], \"timestamp\":\"1785207866734\", \"event_type\":\"price_change\"}","received_at":"2026-07-28T03:04:26.783334Z","schema_version":"clob-market-ws.price_change.v1","sequence":null,"server_hash":null,"server_timestamp":"1785207866734","session_id":"3e519d9098404c15b234d96025eb1a2b","source":"clob_market_ws"},"received_at":"2026-07-28T03:04:26.783334Z","record_id":"585b4578c9b14b1f11e9d605eef9e251dfc717c5712a04388392dcb4b4be0489","schema_fingerprint":"4aa3821a28b0b7c2400bc59aba4bcc0a76e971dadd19610d3ad38c768e124dc7","schema_version":"edge-lab-recorder.raw.v1","sequence":null,"source":"clob_market_ws"}
{"event_at":"2026-07-28T03:04:26.734000Z","event_fingerprint":"516c5e4e447ccaa2fe2b04f17059d7d126daab38653f4e323d3d485b58aa4d75","payload":{"connection_id":"a6b55582af5f430fb37ad02bf0922475","event_at":"2026-07-28T03:04:26.734000Z","event_type":"price_change","frame_hash":"0b5d2b6ed4ddd76b4a2653b2848a009ba594c6ad31f5ffd961645675cba74876","frame_index":0,"kind":"data","monotonic_ns":309849810806041,"payload":{"event_type":"price_change","market":"0x779291bef19b6709f61e9764a954aafe9ffae488d50ae674aabdcb4f248006d5","price_changes":[{"asset_id":"8761897749749422724209054078244794145777693856614463256546737399611489089783","best_ask":"0.62","best_bid":"0.6","hash":"5fd6dfa981abb29b4b9cbe6ba5f9a2481ed6eccf","price":"0.59","side":"BUY","size":"93.2"},{"asset_id":"14965588658799411272385430903075831224615961675357217884735713260981483529984","best_ask":"0.4","best_bid":"0.38","hash":"d163ac2355ebc18a1dbc1d272f609e6995559dd1","price":"0.41","side":"SELL","size":"93.2"}],"timestamp":"1785207866734"},"payload_hash":"e933724c5be4c4d3605330c33c6a1f2dacf6dd4a90d44aaaa132324f715a0fcd","raw_frame":"{\"market\":\"0x779291bef19b6709f61e9764a954aafe9ffae488d50ae674aabdcb4f248006d5\", \"price_changes\":[{\"asset_id\":\"8761897749749422724209054078244794145777693856614463256546737399611489089783\", \"price\":\"0.59\", \"size\":\"93.2\", \"side\":\"BUY\", \"hash\":\"5fd6dfa981abb29b4b9cbe6ba5f9a2481ed6eccf\", \"best_bid\":\"0.6\", \"best_ask\":\"0.62\"}, {\"asset_id\":\"14965588658799411272385430903075831224615961675357217884735713260981483529984\", \"price\":\"0.41\", \"size\":\"93.2\", \"side\":\"SELL\", \"hash\":\"d163ac2355ebc18a1dbc1d272f609e6995559dd1\", \"best_bid\":\"0.38\", \"best_ask\":\"0.4\"}], \"timestamp\":\"1785207866734\", \"event_type\":\"price_change\"}","received_at":"2026-07-28T03:04:26.784832Z","schema_version":"clob-market-ws.price_change.v1","sequence":null,"server_hash":null,"server_timestamp":"1785207866734","session_id":"3e519d9098404c15b234d96025eb1a2b","source":"clob_market_ws"},"received_at":"2026-07-28T03:04:26.784832Z","record_id":"3ec35893b1c456a5fc86d1be3bde50930739d1d62821f1b20e0fb75de4b728dc","schema_fingerprint":"4aa3821a28b0b7c2400bc59aba4bcc0a76e971dadd19610d3ad38c768e124dc7","schema_version":"edge-lab-recorder.raw.v1","sequence":null,"source":"clob_market_ws"}
{"event_at":"2026-07-28T03:04:26.734000Z","event_fingerprint":"abc49122d247b6358c8a22bac87b657bdaf712c233ba0f8e6d107521b3b770bc","payload":{"connection_id":"a6b55582af5f430fb37ad02bf0922475","event_at":"2026-07-28T03:04:26.734000Z","event_type":"price_change","frame_hash":"d55cc1f741907b0bf4c17981e276b4c3b68d47de90e643cd70b7f2a53ac8c9cd","frame_index":0,"kind":"data","monotonic_ns":309849812239166,"payload":{"event_type":"price_change","market":"0x779291bef19b6709f61e9764a954aafe9ffae488d50ae674aabdcb4f248006d5","price_changes":[{"asset_id":"14965588658799411272385430903075831224615961675357217884735713260981483529984","best_ask":"0.4","best_bid":"0.38","hash":"03a43895c2a7be07f3dbb5ac0d875110e2ab6f3b","price":"0.37","side":"BUY","size":"410"},{"asset_id":"8761897749749422724209054078244794145777693856614463256546737399611489089783","best_ask":"0.62","best_bid":"0.6","hash":"2da5a73dc0604d8f6abffd582e78032012c1f4b5","price":"0.63","side":"SELL","size":"410"}],"timestamp":"1785207866734"},"payload_hash":"85d33db7dc0b9079263971e9da04fe03f32eaf15cfd2b267b13e74ca374c089b","raw_frame":"{\"market\":\"0x779291bef19b6709f61e9764a954aafe9ffae488d50ae674aabdcb4f248006d5\", \"price_changes\":[{\"asset_id\":\"14965588658799411272385430903075831224615961675357217884735713260981483529984\", \"price\":\"0.37\", \"size\":\"410\", \"side\":\"BUY\", \"hash\":\"03a43895c2a7be07f3dbb5ac0d875110e2ab6f3b\", \"best_bid\":\"0.38\", \"best_ask\":\"0.4\"}, {\"asset_id\":\"8761897749749422724209054078244794145777693856614463256546737399611489089783\", \"price\":\"0.63\", \"size\":\"410\", \"side\":\"SELL\", \"hash\":\"2da5a73dc0604d8f6abffd582e78032012c1f4b5\", \"best_bid\":\"0.6\", \"best_ask\":\"0.62\"}], \"timestamp\":\"1785207866734\", \"event_type\":\"price_change\"}","received_at":"2026-07-28T03:04:26.786264Z","schema_version":"clob-market-ws.price_change.v1","sequence":null,"server_hash":null,"server_timestamp":"1785207866734","session_id":"3e519d9098404c15b234d96025eb1a2b","source":"clob_market_ws"},"received_at":"2026-07-28T03:04:26.786264Z","record_id":"2c2b5b69c83d862fa2cdac409441cda90c5ca9d8819abae20832c15e5f3f1dc9","schema_fingerprint":"4aa3821a28b0b7c2400bc59aba4bcc0a76e971dadd19610d3ad38c768e124dc7","schema_version":"edge-lab-recorder.raw.v1","sequence":null,"source":"clob_market_ws"}
{"event_at":"2026-07-28T03:04:26.735000Z","event_fingerprint":"5ad7927ef3492da57897dc54b1a49c0f0d1773618538efb27f08612cef1ed763","payload":{"connection_id":"a6b55582af5f430fb37ad02bf0922475","event_at":"2026-07-28T03:04:26.735000Z","event_type":"price_change","frame_hash":"5d65ca326a0282ae18af3b23232f1f878e814bb75f1ebda832ab9665c0dd3a2d","frame_index":0,"kind":"data","monotonic_ns":309849813693625,"payload":{"event_type":"price_change","market":"0x779291bef19b6709f61e9764a954aafe9ffae488d50ae674aabdcb4f248006d5","price_changes":[{"asset_id":"8761897749749422724209054078244794145777693856614463256546737399611489089783","best_ask":"0.62","best_bid":"0.6","hash":"fb98c9931bbfd5c77e2db477cab527d255e98640","price":"0.6","side":"BUY","size":"22.6"},{"asset_id":"14965588658799411272385430903075831224615961675357217884735713260981483529984","best_ask":"0.4","best_bid":"0.38","hash":"886fa59998f545079a5f9ae637f18cfcc7b6d7bd","price":"0.4","side":"SELL","size":"22.6"}],"timestamp":"1785207866735"},"payload_hash":"116c6919bfc4b21d395e953dd095c071887fa8a9df0322bdf4efcb8ebda6c95f","raw_frame":"{\"market\":\"0x779291bef19b6709f61e9764a954aafe9ffae488d50ae674aabdcb4f248006d5\", \"price_changes\":[{\"asset_id\":\"8761897749749422724209054078244794145777693856614463256546737399611489089783\", \"price\":\"0.6\", \"size\":\"22.6\", \"side\":\"BUY\", \"hash\":\"fb98c9931bbfd5c77e2db477cab527d255e98640\", \"best_bid\":\"0.6\", \"best_ask\":\"0.62\"}, {\"asset_id\":\"14965588658799411272385430903075831224615961675357217884735713260981483529984\", \"price\":\"0.4\", \"size\":\"22.6\", \"side\":\"SELL\", \"hash\":\"886fa59998f545079a5f9ae637f18cfcc7b6d7bd\", \"best_bid\":\"0.38\", \"best_ask\":\"0.4\"}], \"timestamp\":\"1785207866735\", \"event_type\":\"price_change\"}","received_at":"2026-07-28T03:04:26.787719Z","schema_version":"clob-market-ws.price_change.v1","sequence":null,"server_hash":null,"server_timestamp":"1785207866735","session_id":"3e519d9098404c15b234d96025eb1a2b","source":"clob_market_ws"},"received_at":"2026-07-28T03:04:26.787719Z","record_id":"36791570a8e00dc4cd603b2ae6e35ecd52968bbd1ab2344a9d9931eb2ea8b238","schema_fingerprint":"4aa3821a28b0b7c2400bc59aba4bcc0a76e971dadd19610d3ad38c768e124dc7","schema_version":"edge-lab-recorder.raw.v1","sequence":null,"source":"clob_market_ws"}
{"event_at":"2026-07-28T03:04:26.742000Z","event_fingerprint":"7451d9dbccac851f25f79b8f7f9ae69b8073001fbc59168951bd1e9b39cc54ae","payload":{"connection_id":"a6b55582af5f430fb37ad02bf0922475","event_at":"2026-07-28T03:04:26.742000Z","event_type":"price_change","frame_hash":"d7147921308345f66c21477f83a72a6f111127092d1336a234809ade3869d5f8","frame_index":0,"kind":"data","monotonic_ns":309849815110375,"payload":{"event_type":"price_change","market":"0x779291bef19b6709f61e9764a954aafe9ffae488d50ae674aabdcb4f248006d5","price_changes":[{"asset_id":"8761897749749422724209054078244794145777693856614463256546737399611489089783","best_ask":"0.62","best_bid":"0.6","hash":"5dc36f55827e56c7a5486880ade260b7d7c433d8","price":"0.48","side":"BUY","size":"218"},{"asset_id":"14965588658799411272385430903075831224615961675357217884735713260981483529984","best_ask":"0.4","best_bid":"0.38","hash":"50ab384628c786b38ce182414948bd253fad2527","price":"0.52","side":"SELL","size":"218"}],"timestamp":"1785207866742"},"payload_hash":"2dc6b0bd922b7bd57b6ca328aa5d3daa79e340b01307139732fdf0a96291cd38","raw_frame":"{\"market\":\"0x779291bef19b6709f61e9764a954aafe9ffae488d50ae674aabdcb4f248006d5\", \"price_changes\":[{\"asset_id\":\"8761897749749422724209054078244794145777693856614463256546737399611489089783\", \"price\":\"0.48\", \"size\":\"218\", \"side\":\"BUY\", \"hash\":\"5dc36f55827e56c7a5486880ade260b7d7c433d8\", \"best_bid\":\"0.6\", \"best_ask\":\"0.62\"}, {\"asset_id\":\"14965588658799411272385430903075831224615961675357217884735713260981483529984\", \"price\":\"0.52\", \"size\":\"218\", \"side\":\"SELL\", \"hash\":\"50ab384628c786b38ce182414948bd253fad2527\", \"best_bid\":\"0.38\", \"best_ask\":\"0.4\"}], \"timestamp\":\"1785207866742\", \"event_type\":\"price_change\"}","received_at":"2026-07-28T03:04:26.789135Z","schema_version":"clob-market-ws.price_change.v1","sequence":null,"server_hash":null,"server_timestamp":"1785207866742","session_id":"3e519d9098404c15b234d96025eb1a2b","source":"clob_market_ws"},"received_at":"2026-07-28T03:04:26.789135Z","record_id":"0630790cab22318ee2e091b327b91a372bff3d037b133939cf30d42f50a6f6d5","schema_fingerprint":"4aa3821a28b0b7c2400bc59aba4bcc0a76e971dadd19610d3ad38c768e124dc7","schema_version":"edge-lab-recorder.raw.v1","sequence":null,"source":"clob_market_ws"}
{"event_at":"2026-07-28T03:04:26.747000Z","event_fingerprint":"1daa6ee28ea581455ca4929dab10e6ce4d663ed1c2dd00f71a1752f9d4a15227","payload":{"connection_id":"a6b55582af5f430fb37ad02bf0922475","event_at":"2026-07-28T03:04:26.747000Z","event_type":"price_change","frame_hash":"2576443a55cf98e37ce7214a3ce041f8912e7e4fd434cc69e9fc132e10debd6c","frame_index":0,"kind":"data","monotonic_ns":309849816555500,"payload":{"event_type":"price_change","market":"0x779291bef19b6709f61e9764a954aafe9ffae488d50ae674aabdcb4f248006d5","price_changes":[{"asset_id":"8761897749749422724209054078244794145777693856614463256546737399611489089783","best_ask":"0.62","best_bid":"0.6","hash":"23275055d70d50b1b062e9b52b878910a5dfa432","price":"0.6","side":"BUY","size":"42.6"},{"asset_id":"14965588658799411272385430903075831224615961675357217884735713260981483529984","best_ask":"0.4","best_bid":"0.38","hash":"8872bd6e1214feea5d34b61ffd042cbd8b6cd507","price":"0.4","side":"SELL","size":"42.6"}],"timestamp":"1785207866747"},"payload_hash":"3f816ea6f2fba4855801f41dc0b3b8b218840031e3cf4e1c1a1c0e4dddbd012c","raw_frame":"{\"market\":\"0x779291bef19b6709f61e9764a954aafe9ffae488d50ae674aabdcb4f248006d5\", \"price_changes\":[{\"asset_id\":\"8761897749749422724209054078244794145777693856614463256546737399611489089783\", \"price\":\"0.6\", \"size\":\"42.6\", \"side\":\"BUY\", \"hash\":\"23275055d70d50b1b062e9b52b878910a5dfa432\", \"best_bid\":\"0.6\", \"best_ask\":\"0.62\"}, {\"asset_id\":\"14965588658799411272385430903075831224615961675357217884735713260981483529984\", \"price\":\"0.4\", \"size\":\"42.6\", \"side\":\"SELL\", \"hash\":\"8872bd6e1214feea5d34b61ffd042cbd8b6cd507\", \"best_bid\":\"0.38\", \"best_ask\":\"0.4\"}], \"timestamp\":\"1785207866747\", \"event_type\":\"price_change\"}","received_at":"2026-07-28T03:04:26.790580Z","schema_version":"clob-market-ws.price_change.v1","sequence":null,"server_hash":null,"server_timestamp":"1785207866747","session_id":"3e519d9098404c15b234d96025eb1a2b","source":"clob_market_ws"},"received_at":"2026-07-28T03:04:26.790580Z","record_id":"519b77f566076cf42ecfe99db7da5151ba33548aec095544b23f35b2d56d5023","schema_fingerprint":"4aa3821a28b0b7c2400bc59aba4bcc0a76e971dadd19610d3ad38c768e124dc7","schema_version":"edge-lab-recorder.raw.v1","sequence":null,"source":"clob_market_ws"}
{"event_at":"2026-07-28T03:04:26.752000Z","event_fingerprint":"1588278a94012722d43dd52ca9f6d9653ed8d678b4a2d07768ba6d2514181f66","payload":{"connection_id":"a6b55582af5f430fb37ad02bf0922475","event_at":"2026-07-28T03:04:26.752000Z","event_type":"price_change","frame_hash":"1a1c51db8134225442ae0e648717e5d190a3efc290bb639004cf4cef307f1d6e","frame_index":0,"kind":"data","monotonic_ns":309849817972750,"payload":{"event_type":"price_change","market":"0x779291bef19b6709f61e9764a954aafe9ffae488d50ae674aabdcb4f248006d5","price_changes":[{"asset_id":"14965588658799411272385430903075831224615961675357217884735713260981483529984","best_ask":"0.4","best_bid":"0.38","hash":"52f8e43c5480d72ddf32d37130f08c16d4efdd3b","price":"0.33","side":"BUY","size":"203"},{"asset_id":"8761897749749422724209054078244794145777693856614463256546737399611489089783","best_ask":"0.62","best_bid":"0.6","hash":"56623d300d195cf4a610bc47d20851a1324ac10c","price":"0.67","side":"SELL","size":"203"}],"timestamp":"1785207866752"},"payload_hash":"6b28a541abdc6307c3d81f8a4826fa02b82375f9617e4731dd7f38c7f196b0f6","raw_frame":"{\"market\":\"0x779291bef19b6709f61e9764a954aafe9ffae488d50ae674aabdcb4f248006d5\", \"price_changes\":[{\"asset_id\":\"14965588658799411272385430903075831224615961675357217884735713260981483529984\", \"price\":\"0.33\", \"size\":\"203\", \"side\":\"BUY\", \"hash\":\"52f8e43c5480d72ddf32d37130f08c16d4efdd3b\", \"best_bid\":\"0.38\", \"best_ask\":\"0.4\"}, {\"asset_id\":\"8761897749749422724209054078244794145777693856614463256546737399611489089783\", \"price\":\"0.67\", \"size\":\"203\", \"side\":\"SELL\", \"hash\":\"56623d300d195cf4a610bc47d20851a1324ac10c\", \"best_bid\":\"0.6\", \"best_ask\":\"0.62\"}], \"timestamp\":\"1785207866752\", \"event_type\":\"price_change\"}","received_at":"2026-07-28T03:04:26.791996Z","schema_version":"clob-market-ws.price_change.v1","sequence":null,"server_hash":null,"server_timestamp":"1785207866752","session_id":"3e519d9098404c15b234d96025eb1a2b","source":"clob_market_ws"},"received_at":"2026-07-28T03:04:26.791996Z","record_id":"03fce0044a8392b2721c7d0daeb6ea20097f41352bbd8890ee7323686d6fbbef","schema_fingerprint":"4aa3821a28b0b7c2400bc59aba4bcc0a76e971dadd19610d3ad38c768e124dc7","schema_version":"edge-lab-recorder.raw.v1","sequence":null,"source":"clob_market_ws"}
{"event_at":"2026-07-28T03:04:26.752000Z","event_fingerprint":"aeb1aa611eacca555b34ae5aaef78edb8d641c119ae6d3720b8beac74e505981","payload":{"connection_id":"a6b55582af5f430fb37ad02bf0922475","event_at":"2026-07-28T03:04:26.752000Z","event_type":"price_change","frame_hash":"92289ab68d224bfc095f2c327fd983a0c37678aace2de10e7dc1e12f34adf257","frame_index":0,"kind":"data","monotonic_ns":309849819407833,"payload":{"event_type":"price_change","market":"0x779291bef19b6709f61e9764a954aafe9ffae488d50ae674aabdcb4f248006d5","price_changes":[{"asset_id":"14965588658799411272385430903075831224615961675357217884735713260981483529984","best_ask":"0.4","best_bid":"0.38","hash":"52f8e43c5480d72ddf32d37130f08c16d4efdd3b","price":"0.32","side":"BUY","size":"214"},{"asset_id":"8761897749749422724209054078244794145777693856614463256546737399611489089783","best_ask":"0.62","best_bid":"0.6","hash":"56623d300d195cf4a610bc47d20851a1324ac10c","price":"0.68","side":"SELL","size":"214"}],"timestamp":"1785207866752"},"payload_hash":"a692741547eb751d07ef15897f44e349ba8cd04c855e1eb510750c911d6d86ef","raw_frame":"{\"market\":\"0x779291bef19b6709f61e9764a954aafe9ffae488d50ae674aabdcb4f248006d5\", \"price_changes\":[{\"asset_id\":\"14965588658799411272385430903075831224615961675357217884735713260981483529984\", \"price\":\"0.32\", \"size\":\"214\", \"side\":\"BUY\", \"hash\":\"52f8e43c5480d72ddf32d37130f08c16d4efdd3b\", \"best_bid\":\"0.38\", \"best_ask\":\"0.4\"}, {\"asset_id\":\"8761897749749422724209054078244794145777693856614463256546737399611489089783\", \"price\":\"0.68\", \"size\":\"214\", \"side\":\"SELL\", \"hash\":\"56623d300d195cf4a610bc47d20851a1324ac10c\", \"best_bid\":\"0.6\", \"best_ask\":\"0.62\"}], \"timestamp\":\"1785207866752\", \"event_type\":\"price_change\"}","received_at":"2026-07-28T03:04:26.793431Z","schema_version":"clob-market-ws.price_change.v1","sequence":null,"server_hash":null,"server_timestamp":"1785207866752","session_id":"3e519d9098404c15b234d96025eb1a2b","source":"clob_market_ws"},"received_at":"2026-07-28T03:04:26.793431Z","record_id":"3a1c404bb901c87e0db59b34c8d6481d8cb9882c9a5035f00675df5ffa33e908","schema_fingerprint":"4aa3821a28b0b7c2400bc59aba4bcc0a76e971dadd19610d3ad38c768e124dc7","schema_version":"edge-lab-recorder.raw.v1","sequence":null,"source":"clob_market_ws"}
{"event_at":"2026-07-28T03:04:26.752000Z","event_fingerprint":"92fbaa650a2121488fde9ad894cbf2cbc535e685ba6816fb79485b7c08c66b75","payload":{"connection_id":"a6b55582af5f430fb37ad02bf0922475","event_at":"2026-07-28T03:04:26.752000Z","event_type":"price_change","frame_hash":"6c37309d53be9493545b9611df5f7b7e256a9264bb0b2e4ddccaf8e4989692ff","frame_index":0,"kind":"data","monotonic_ns":309849820818541,"payload":{"event_type":"price_change","market":"0x779291bef19b6709f61e9764a954aafe9ffae488d50ae674aabdcb4f248006d5","price_changes":[{"asset_id":"8761897749749422724209054078244794145777693856614463256546737399611489089783","best_ask":"0.62","best_bid":"0.6","hash":"b3043579b756b2aa516f7332c2af9faacac9f7d9","price":"0.58","side":"BUY","size":"76.2"},{"asset_id":"14965588658799411272385430903075831224615961675357217884735713260981483529984","best_ask":"0.4","best_bid":"0.38","hash":"e1ff1f66346d833fb6902bf5f6e7f57540ef1b2c","price":"0.42","side":"SELL","size":"76.2"}],"timestamp":"1785207866752"},"payload_hash":"8c4d15804b6b38d7cbc21733464c6a70a132f9923fa1bb705becaf9970c99c37","raw_frame":"{\"market\":\"0x779291bef19b6709f61e9764a954aafe9ffae488d50ae674aabdcb4f248006d5\", \"price_changes\":[{\"asset_id\":\"8761897749749422724209054078244794145777693856614463256546737399611489089783\", \"price\":\"0.58\", \"size\":\"76.2\", \"side\":\"BUY\", \"hash\":\"b3043579b756b2aa516f7332c2af9faacac9f7d9\", \"best_bid\":\"0.6\", \"best_ask\":\"0.62\"}, {\"asset_id\":\"14965588658799411272385430903075831224615961675357217884735713260981483529984\", \"price\":\"0.42\", \"size\":\"76.2\", \"side\":\"SELL\", \"hash\":\"e1ff1f66346d833fb6902bf5f6e7f57540ef1b2c\", \"best_bid\":\"0.38\", \"best_ask\":\"0.4\"}], \"timestamp\":\"1785207866752\", \"event_type\":\"price_change\"}","received_at":"2026-07-28T03:04:26.794841Z","schema_version":"clob-market-ws.price_change.v1","sequence":null,"server_hash":null,"server_timestamp":"1785207866752","session_id":"3e519d9098404c15b234d96025eb1a2b","source":"clob_market_ws"},"received_at":"2026-07-28T03:04:26.794841Z","record_id":"89dbbe84ab9eeef35e17d48007bb79bb780f79160650aebcac2208e2259e9e8c","schema_fingerprint":"4aa3821a28b0b7c2400bc59aba4bcc0a76e971dadd19610d3ad38c768e124dc7","schema_version":"edge-lab-recorder.raw.v1","sequence":null,"source":"clob_market_ws"}
