{"event_at":"2026-07-28T02:01:01.564000Z","event_fingerprint":"9ee9b0f274e292cfeb57bf3e3ebf45037f3adc37ae318a2826dd054c53be52a7","payload":{"connection_id":"5d29200f65794d4d9ab6ef271f045a9b","event_at":"2026-07-28T02:01:01.564000Z","event_type":"price_change","frame_hash":"e1bc720db69330708fe94dbd18eb86c955945f344c3c1e984eaf904486a831b9","frame_index":0,"kind":"data","monotonic_ns":306051897962500,"payload":{"event_type":"price_change","market":"0xda6f0e0e93fc8469e0159a166028d017bddbc162b86f66bac90391379603d962","price_changes":[{"asset_id":"39272994714739463168905443499424551362424437245880253267329605556587274644733","best_ask":"0.62","best_bid":"0.61","hash":"2016456b0edb346f2fef8c920f98a145ac5b1f82","price":"0.47","side":"BUY","size":"117"},{"asset_id":"20893381255801015515826997628594359667013752732428989472914000440642900266717","best_ask":"0.39","best_bid":"0.38","hash":"ddaad96a388fed6df570b72287eeab26ccf81cf0","price":"0.53","side":"SELL","size":"117"}],"timestamp":"1785204061564"},"payload_hash":"5f1f37598b35b9b878166afa96639218e77e4cb37172f625182bc6d89e4f486f","raw_frame":"{\"market\":\"0xda6f0e0e93fc8469e0159a166028d017bddbc162b86f66bac90391379603d962\", \"price_changes\":[{\"asset_id\":\"39272994714739463168905443499424551362424437245880253267329605556587274644733\", \"price\":\"0.47\", \"size\":\"117\", \"side\":\"BUY\", \"hash\":\"2016456b0edb346f2fef8c920f98a145ac5b1f82\", \"best_bid\":\"0.61\", \"best_ask\":\"0.62\"}, {\"asset_id\":\"20893381255801015515826997628594359667013752732428989472914000440642900266717\", \"price\":\"0.53\", \"size\":\"117\", \"side\":\"SELL\", \"hash\":\"ddaad96a388fed6df570b72287eeab26ccf81cf0\", \"best_bid\":\"0.38\", \"best_ask\":\"0.39\"}], \"timestamp\":\"1785204061564\", \"event_type\":\"price_change\"}","received_at":"2026-07-28T02:01:08.894012Z","schema_version":"clob-market-ws.price_change.v1","sequence":null,"server_hash":null,"server_timestamp":"1785204061564","session_id":"d2757dd6dad94f3b9fe67e8dbf1adc37","source":"clob_market_ws"},"received_at":"2026-07-28T02:01:08.894012Z","record_id":"dba5fe5d45475d3c0e86e0b6c060cac1642c1576535d310760d9edb867f12e2d","schema_fingerprint":"4aa3821a28b0b7c2400bc59aba4bcc0a76e971dadd19610d3ad38c768e124dc7","schema_version":"edge-lab-recorder.raw.v1","sequence":null,"source":"clob_market_ws"}
{"event_at":"2026-07-28T02:01:01.565000Z","event_fingerprint":"92f53dea4c2b0c2c0dee441a2b041e1c8b1ae3d3875284cf68ba2ff4eea0f014","payload":{"connection_id":"5d29200f65794d4d9ab6ef271f045a9b","event_at":"2026-07-28T02:01:01.565000Z","event_type":"price_change","frame_hash":"fe78087e2d7649c15cc15f65c304f5db0c998e543c10859758270ee65696abb8","frame_index":0,"kind":"data","monotonic_ns":306051934761041,"payload":{"event_type":"price_change","market":"0xda6f0e0e93fc8469e0159a166028d017bddbc162b86f66bac90391379603d962","price_changes":[{"asset_id":"39272994714739463168905443499424551362424437245880253267329605556587274644733","best_ask":"0.62","best_bid":"0.61","hash":"f9bc3f1e04701b3d56ab6fd787b8fecaf7414c96","price":"0.61","side":"BUY","size":"117"},{"asset_id":"20893381255801015515826997628594359667013752732428989472914000440642900266717","best_ask":"0.39","best_bid":"0.38","hash":"7464735f2b3c2d930ba5ab915b40bfcb000cf7f5","price":"0.39","side":"SELL","size":"117"}],"timestamp":"1785204061565"},"payload_hash":"d1b87c0790169256d7d89e801809d29e7c2c8b6f63ae1fbbd89e434d0d3f0f13","raw_frame":"{\"market\":\"0xda6f0e0e93fc8469e0159a166028d017bddbc162b86f66bac90391379603d962\", \"price_changes\":[{\"asset_id\":\"39272994714739463168905443499424551362424437245880253267329605556587274644733\", \"price\":\"0.61\", \"size\":\"117\", \"side\":\"BUY\", \"hash\":\"f9bc3f1e04701b3d56ab6fd787b8fecaf7414c96\", \"best_bid\":\"0.61\", \"best_ask\":\"0.62\"}, {\"asset_id\":\"20893381255801015515826997628594359667013752732428989472914000440642900266717\", \"price\":\"0.39\", \"size\":\"117\", \"side\":\"SELL\", \"hash\":\"7464735f2b3c2d930ba5ab915b40bfcb000cf7f5\", \"best_bid\":\"0.38\", \"best_ask\":\"0.39\"}], \"timestamp\":\"1785204061565\", \"event_type\":\"price_change\"}","received_at":"2026-07-28T02:01:08.930812Z","schema_version":"clob-market-ws.price_change.v1","sequence":null,"server_hash":null,"server_timestamp":"1785204061565","session_id":"d2757dd6dad94f3b9fe67e8dbf1adc37","source":"clob_market_ws"},"received_at":"2026-07-28T02:01:08.930812Z","record_id":"f73463506456cfb32e2cba07abf7b2b9df8405ff2c43f0fb6213730cb2c9e1fb","schema_fingerprint":"4aa3821a28b0b7c2400bc59aba4bcc0a76e971dadd19610d3ad38c768e124dc7","schema_version":"edge-lab-recorder.raw.v1","sequence":null,"source":"clob_market_ws"}
{"event_at":"2026-07-28T02:01:01.565000Z","event_fingerprint":"0ab24682be6b97575ab4ea717859bf0622dc2f2af67da2e4d44bec211e7b007b","payload":{"connection_id":"5d29200f65794d4d9ab6ef271f045a9b","event_at":"2026-07-28T02:01:01.565000Z","event_type":"price_change","frame_hash":"fa931bfd1574ef8f2e3afd89e03c53b5139749c28393133ba8f15448e8bd2e1e","frame_index":0,"kind":"data","monotonic_ns":306051939760666,"payload":{"event_type":"price_change","market":"0xda6f0e0e93fc8469e0159a166028d017bddbc162b86f66bac90391379603d962","price_changes":[{"asset_id":"39272994714739463168905443499424551362424437245880253267329605556587274644733","best_ask":"0.62","best_bid":"0.61","hash":"15b8ed53126d602df23425e3028cfdfc599f63cc","price":"0.61","side":"BUY","size":"122"},{"asset_id":"20893381255801015515826997628594359667013752732428989472914000440642900266717","best_ask":"0.39","best_bid":"0.38","hash":"4169b0619a21ca43bd560bb493c7fdc4765becbe","price":"0.39","side":"SELL","size":"122"}],"timestamp":"1785204061565"},"payload_hash":"9ea02865d15f778e66eba88245be9152f40219c356a67d3b9e188118b0fd5da5","raw_frame":"{\"market\":\"0xda6f0e0e93fc8469e0159a166028d017bddbc162b86f66bac90391379603d962\", \"price_changes\":[{\"asset_id\":\"39272994714739463168905443499424551362424437245880253267329605556587274644733\", \"price\":\"0.61\", \"size\":\"122\", \"side\":\"BUY\", \"hash\":\"15b8ed53126d602df23425e3028cfdfc599f63cc\", \"best_bid\":\"0.61\", \"best_ask\":\"0.62\"}, {\"asset_id\":\"20893381255801015515826997628594359667013752732428989472914000440642900266717\", \"price\":\"0.39\", \"size\":\"122\", \"side\":\"SELL\", \"hash\":\"4169b0619a21ca43bd560bb493c7fdc4765becbe\", \"best_bid\":\"0.38\", \"best_ask\":\"0.39\"}], \"timestamp\":\"1785204061565\", \"event_type\":\"price_change\"}","received_at":"2026-07-28T02:01:08.935813Z","schema_version":"clob-market-ws.price_change.v1","sequence":null,"server_hash":null,"server_timestamp":"1785204061565","session_id":"d2757dd6dad94f3b9fe67e8dbf1adc37","source":"clob_market_ws"},"received_at":"2026-07-28T02:01:08.935813Z","record_id":"7db8074a8a35f77f45dc3f4a9e8b64747acac1bd83a648784e515fb77deb4269","schema_fingerprint":"4aa3821a28b0b7c2400bc59aba4bcc0a76e971dadd19610d3ad38c768e124dc7","schema_version":"edge-lab-recorder.raw.v1","sequence":null,"source":"clob_market_ws"}
{"event_at":"2026-07-28T02:01:01.566000Z","event_fingerprint":"a970c549680462a684c35fdd1e8f4968897bf76c53a5892f3bf434e2eecca0ee","payload":{"connection_id":"5d29200f65794d4d9ab6ef271f045a9b","event_at":"2026-07-28T02:01:01.566000Z","event_type":"price_change","frame_hash":"3cd658c22be6f8845ac3c6f1dbcaa515f0f98433dd5b7a2248f13e81eba2b283","frame_index":0,"kind":"data","monotonic_ns":306051944151750,"payload":{"event_type":"price_change","market":"0xda6f0e0e93fc8469e0159a166028d017bddbc162b86f66bac90391379603d962","price_changes":[{"asset_id":"39272994714739463168905443499424551362424437245880253267329605556587274644733","best_ask":"0.62","best_bid":"0.61","hash":"9c213dabbbefa1870cf08f3b50abee76a3bf90ad","price":"0.61","side":"BUY","size":"78"},{"asset_id":"20893381255801015515826997628594359667013752732428989472914000440642900266717","best_ask":"0.39","best_bid":"0.38","hash":"bb77a17408ae8a7b1094ed9b896fdf3d78377bb5","price":"0.39","side":"SELL","size":"78"}],"timestamp":"1785204061566"},"payload_hash":"5c3938e13086e8f911080d03087c34324f8afd81b9a434fe921928c095b0277b","raw_frame":"{\"market\":\"0xda6f0e0e93fc8469e0159a166028d017bddbc162b86f66bac90391379603d962\", \"price_changes\":[{\"asset_id\":\"39272994714739463168905443499424551362424437245880253267329605556587274644733\", \"price\":\"0.61\", \"size\":\"78\", \"side\":\"BUY\", \"hash\":\"9c213dabbbefa1870cf08f3b50abee76a3bf90ad\", \"best_bid\":\"0.61\", \"best_ask\":\"0.62\"}, {\"asset_id\":\"20893381255801015515826997628594359667013752732428989472914000440642900266717\", \"price\":\"0.39\", \"size\":\"78\", \"side\":\"SELL\", \"hash\":\"bb77a17408ae8a7b1094ed9b896fdf3d78377bb5\", \"best_bid\":\"0.38\", \"best_ask\":\"0.39\"}], \"timestamp\":\"1785204061566\", \"event_type\":\"price_change\"}","received_at":"2026-07-28T02:01:08.940204Z","schema_version":"clob-market-ws.price_change.v1","sequence":null,"server_hash":null,"server_timestamp":"1785204061566","session_id":"d2757dd6dad94f3b9fe67e8dbf1adc37","source":"clob_market_ws"},"received_at":"2026-07-28T02:01:08.940204Z","record_id":"322db3f1cfd3880adbb83ccf949f324254b13942d4590e91d121f8187ccee04e","schema_fingerprint":"4aa3821a28b0b7c2400bc59aba4bcc0a76e971dadd19610d3ad38c768e124dc7","schema_version":"edge-lab-recorder.raw.v1","sequence":null,"source":"clob_market_ws"}
{"event_at":"2026-07-28T02:01:01.566000Z","event_fingerprint":"d45341dd5ffd1ee69a93f13d7fbd3a436af1f5dbb088ffafafddc4c6401a0988","payload":{"connection_id":"5d29200f65794d4d9ab6ef271f045a9b","event_at":"2026-07-28T02:01:01.566000Z","event_type":"price_change","frame_hash":"61850d81bcbc0b463c6b9ec1f9aa0c07dccaeffe30ed7eb63470e22cf7e49eb7","frame_index":0,"kind":"data","monotonic_ns":306051950612333,"payload":{"event_type":"price_change","market":"0xda6f0e0e93fc8469e0159a166028d017bddbc162b86f66bac90391379603d962","price_changes":[{"asset_id":"39272994714739463168905443499424551362424437245880253267329605556587274644733","best_ask":"0.62","best_bid":"0.61","hash":"ac6351f4440a2c50612667f6ff5b45c32f35a870","price":"0.55","side":"BUY","size":"108.1"},{"asset_id":"20893381255801015515826997628594359667013752732428989472914000440642900266717","best_ask":"0.39","best_bid":"0.38","hash":"3a61e13a89642290bc32eb0ef5da243bdaa102b7","price":"0.45","side":"SELL","size":"108.1"}],"timestamp":"1785204061566"},"payload_hash":"9d7bad0d57fffec4833fbb986762b815d89711c33864d4194d75c79be291969f","raw_frame":"{\"market\":\"0xda6f0e0e93fc8469e0159a166028d017bddbc162b86f66bac90391379603d962\", \"price_changes\":[{\"asset_id\":\"39272994714739463168905443499424551362424437245880253267329605556587274644733\", \"price\":\"0.55\", \"size\":\"108.1\", \"side\":\"BUY\", \"hash\":\"ac6351f4440a2c50612667f6ff5b45c32f35a870\", \"best_bid\":\"0.61\", \"best_ask\":\"0.62\"}, {\"asset_id\":\"20893381255801015515826997628594359667013752732428989472914000440642900266717\", \"price\":\"0.45\", \"size\":\"108.1\", \"side\":\"SELL\", \"hash\":\"3a61e13a89642290bc32eb0ef5da243bdaa102b7\", \"best_bid\":\"0.38\", \"best_ask\":\"0.39\"}], \"timestamp\":\"1785204061566\", \"event_type\":\"price_change\"}","received_at":"2026-07-28T02:01:08.946665Z","schema_version":"clob-market-ws.price_change.v1","sequence":null,"server_hash":null,"server_timestamp":"1785204061566","session_id":"d2757dd6dad94f3b9fe67e8dbf1adc37","source":"clob_market_ws"},"received_at":"2026-07-28T02:01:08.946665Z","record_id":"b2137c21f97c211e70ad594a2982268bfd9b5fe8876eccb88d2caafe93dcbd2c","schema_fingerprint":"4aa3821a28b0b7c2400bc59aba4bcc0a76e971dadd19610d3ad38c768e124dc7","schema_version":"edge-lab-recorder.raw.v1","sequence":null,"source":"clob_market_ws"}
{"event_at":"2026-07-28T02:01:01.566000Z","event_fingerprint":"e1b52b6bc7fe55b8cd8694de97058491744f533e7dc5e1d1e0a1955188cb13a3","payload":{"connection_id":"5d29200f65794d4d9ab6ef271f045a9b","event_at":"2026-07-28T02:01:01.566000Z","event_type":"price_change","frame_hash":"f77355b639568e369626e87403518606daf32e9c98860b705029605795229662","frame_index":0,"kind":"data","monotonic_ns":306051956605416,"payload":{"event_type":"price_change","market":"0xda6f0e0e93fc8469e0159a166028d017bddbc162b86f66bac90391379603d962","price_changes":[{"asset_id":"39272994714739463168905443499424551362424437245880253267329605556587274644733","best_ask":"0.62","best_bid":"0.61","hash":"e54df1d35778dd4ffa9b307b4f8490087b898c9e","price":"0.48","side":"BUY","size":"132.05"},{"asset_id":"20893381255801015515826997628594359667013752732428989472914000440642900266717","best_ask":"0.39","best_bid":"0.38","hash":"a7f574b0bc2c2732626920da18d93ba0320c0069","price":"0.52","side":"SELL","size":"132.05"}],"timestamp":"1785204061566"},"payload_hash":"c98440eda7be2ba99833a77ed3837fcec6bada03b19529e47a08091e6806c105","raw_frame":"{\"market\":\"0xda6f0e0e93fc8469e0159a166028d017bddbc162b86f66bac90391379603d962\", \"price_changes\":[{\"asset_id\":\"39272994714739463168905443499424551362424437245880253267329605556587274644733\", \"price\":\"0.48\", \"size\":\"132.05\", \"side\":\"BUY\", \"hash\":\"e54df1d35778dd4ffa9b307b4f8490087b898c9e\", \"best_bid\":\"0.61\", \"best_ask\":\"0.62\"}, {\"asset_id\":\"20893381255801015515826997628594359667013752732428989472914000440642900266717\", \"price\":\"0.52\", \"size\":\"132.05\", \"side\":\"SELL\", \"hash\":\"a7f574b0bc2c2732626920da18d93ba0320c0069\", \"best_bid\":\"0.38\", \"best_ask\":\"0.39\"}], \"timestamp\":\"1785204061566\", \"event_type\":\"price_change\"}","received_at":"2026-07-28T02:01:08.952658Z","schema_version":"clob-market-ws.price_change.v1","sequence":null,"server_hash":null,"server_timestamp":"1785204061566","session_id":"d2757dd6dad94f3b9fe67e8dbf1adc37","source":"clob_market_ws"},"received_at":"2026-07-28T02:01:08.952658Z","record_id":"86474699e4a9a7686f1964bd7408030ab3c7db7dd30d8bda577fa30fea9d7fb7","schema_fingerprint":"4aa3821a28b0b7c2400bc59aba4bcc0a76e971dadd19610d3ad38c768e124dc7","schema_version":"edge-lab-recorder.raw.v1","sequence":null,"source":"clob_market_ws"}
{"event_at":"2026-07-28T02:01:01.568000Z","event_fingerprint":"e68fa9e8d4166cede0b54d1e0884c50e6b71c300936247c4230c0dd5766250e1","payload":{"connection_id":"5d29200f65794d4d9ab6ef271f045a9b","event_at":"2026-07-28T02:01:01.568000Z","event_type":"price_change","frame_hash":"b98d5db9a98e265a7349abeab0b7257750b06061ea0af3ad87672e8e2e340782","frame_index":0,"kind":"data","monotonic_ns":306051963990708,"payload":{"event_type":"price_change","market":"0xda6f0e0e93fc8469e0159a166028d017bddbc162b86f66bac90391379603d962","price_changes":[{"asset_id":"39272994714739463168905443499424551362424437245880253267329605556587274644733","best_ask":"0.62","best_bid":"0.61","hash":"ea0156555801e5a8381cdb8dcd7726463893ae51","price":"0.61","side":"BUY","size":"34"},{"asset_id":"20893381255801015515826997628594359667013752732428989472914000440642900266717","best_ask":"0.39","best_bid":"0.38","hash":"36a95ec456900b05bb947fda24a29e624120d5d6","price":"0.39","side":"SELL","size":"34"}],"timestamp":"1785204061568"},"payload_hash":"df537459b3d50dbb2107b3a8dd9b7b64c01506f351802253627fe176e66eba90","raw_frame":"{\"market\":\"0xda6f0e0e93fc8469e0159a166028d017bddbc162b86f66bac90391379603d962\", \"price_changes\":[{\"asset_id\":\"39272994714739463168905443499424551362424437245880253267329605556587274644733\", \"price\":\"0.61\", \"size\":\"34\", \"side\":\"BUY\", \"hash\":\"ea0156555801e5a8381cdb8dcd7726463893ae51\", \"best_bid\":\"0.61\", \"best_ask\":\"0.62\"}, {\"asset_id\":\"20893381255801015515826997628594359667013752732428989472914000440642900266717\", \"price\":\"0.39\", \"size\":\"34\", \"side\":\"SELL\", \"hash\":\"36a95ec456900b05bb947fda24a29e624120d5d6\", \"best_bid\":\"0.38\", \"best_ask\":\"0.39\"}], \"timestamp\":\"1785204061568\", \"event_type\":\"price_change\"}","received_at":"2026-07-28T02:01:08.960041Z","schema_version":"clob-market-ws.price_change.v1","sequence":null,"server_hash":null,"server_timestamp":"1785204061568","session_id":"d2757dd6dad94f3b9fe67e8dbf1adc37","source":"clob_market_ws"},"received_at":"2026-07-28T02:01:08.960041Z","record_id":"485f48e8a77791b5bc0b31e6055826ea37ac9df2a19f800ee16e05b0ebea590b","schema_fingerprint":"4aa3821a28b0b7c2400bc59aba4bcc0a76e971dadd19610d3ad38c768e124dc7","schema_version":"edge-lab-recorder.raw.v1","sequence":null,"source":"clob_market_ws"}
{"event_at":"2026-07-28T02:01:01.568000Z","event_fingerprint":"d273cd5059d5315d61244ef8d930b7c54282239dd3912ea8f85e3e997f79540a","payload":{"connection_id":"5d29200f65794d4d9ab6ef271f045a9b","event_at":"2026-07-28T02:01:01.568000Z","event_type":"price_change","frame_hash":"9345f8d67f6ae6406534b84bf82bf4362f3ff3be2c550dcf02ef920ed5ec8b91","frame_index":0,"kind":"data","monotonic_ns":306051969612958,"payload":{"event_type":"price_change","market":"0xda6f0e0e93fc8469e0159a166028d017bddbc162b86f66bac90391379603d962","price_changes":[{"asset_id":"39272994714739463168905443499424551362424437245880253267329605556587274644733","best_ask":"0.62","best_bid":"0.61","hash":"3a8ce69dd1e3bf42d1c30cc9a64f4524a11fd38a","price":"0.02","side":"BUY","size":"1638.1"},{"asset_id":"20893381255801015515826997628594359667013752732428989472914000440642900266717","best_ask":"0.39","best_bid":"0.38","hash":"3b0674e843c0c1d7ed5340826e2df07e493fbcb6","price":"0.98","side":"SELL","size":"1638.1"}],"timestamp":"1785204061568"},"payload_hash":"6115ac60ecd4bc8817fdda6ac3e713f5d1a756498f9f87d9f0ed78a12097f086","raw_frame":"{\"market\":\"0xda6f0e0e93fc8469e0159a166028d017bddbc162b86f66bac90391379603d962\", \"price_changes\":[{\"asset_id\":\"39272994714739463168905443499424551362424437245880253267329605556587274644733\", \"price\":\"0.02\", \"size\":\"1638.1\", \"side\":\"BUY\", \"hash\":\"3a8ce69dd1e3bf42d1c30cc9a64f4524a11fd38a\", \"best_bid\":\"0.61\", \"best_ask\":\"0.62\"}, {\"asset_id\":\"20893381255801015515826997628594359667013752732428989472914000440642900266717\", \"price\":\"0.98\", \"size\":\"1638.1\", \"side\":\"SELL\", \"hash\":\"3b0674e843c0c1d7ed5340826e2df07e493fbcb6\", \"best_bid\":\"0.38\", \"best_ask\":\"0.39\"}], \"timestamp\":\"1785204061568\", \"event_type\":\"price_change\"}","received_at":"2026-07-28T02:01:08.965666Z","schema_version":"clob-market-ws.price_change.v1","sequence":null,"server_hash":null,"server_timestamp":"1785204061568","session_id":"d2757dd6dad94f3b9fe67e8dbf1adc37","source":"clob_market_ws"},"received_at":"2026-07-28T02:01:08.965666Z","record_id":"9ac7fd3e9c90399389d4dc8f307f861667e5d46f056e4dc6a839b8b58f69b493","schema_fingerprint":"4aa3821a28b0b7c2400bc59aba4bcc0a76e971dadd19610d3ad38c768e124dc7","schema_version":"edge-lab-recorder.raw.v1","sequence":null,"source":"clob_market_ws"}
{"event_at":"2026-07-28T02:01:01.569000Z","event_fingerprint":"d9656a40e3eeaa58611ad8f0315417fad66467a55d4af1af4736619012693aab","payload":{"connection_id":"5d29200f65794d4d9ab6ef271f045a9b","event_at":"2026-07-28T02:01:01.569000Z","event_type":"price_change","frame_hash":"0de0522629a4141b3653ddec540087c04647d87b1e8a10a60da4a3515c36fad9","frame_index":0,"kind":"data","monotonic_ns":306051974033041,"payload":{"event_type":"price_change","market":"0xda6f0e0e93fc8469e0159a166028d017bddbc162b86f66bac90391379603d962","price_changes":[{"asset_id":"39272994714739463168905443499424551362424437245880253267329605556587274644733","best_ask":"0.62","best_bid":"0.61","hash":"28256bb207727c77792d54adfedbddbcfd62dbd4","price":"0.46","side":"BUY","size":"202"},{"asset_id":"20893381255801015515826997628594359667013752732428989472914000440642900266717","best_ask":"0.39","best_bid":"0.38","hash":"6998eba6698c650f2bc6677b5bb5e36ef0bf9559","price":"0.54","side":"SELL","size":"202"}],"timestamp":"1785204061569"},"payload_hash":"447b9868d316e8190c06406eeca6e3a1e654aa7b1b7d8e24a8a507c4518ecb5e","raw_frame":"{\"market\":\"0xda6f0e0e93fc8469e0159a166028d017bddbc162b86f66bac90391379603d962\", \"price_changes\":[{\"asset_id\":\"39272994714739463168905443499424551362424437245880253267329605556587274644733\", \"price\":\"0.46\", \"size\":\"202\", \"side\":\"BUY\", \"hash\":\"28256bb207727c77792d54adfedbddbcfd62dbd4\", \"best_bid\":\"0.61\", \"best_ask\":\"0.62\"}, {\"asset_id\":\"20893381255801015515826997628594359667013752732428989472914000440642900266717\", \"price\":\"0.54\", \"size\":\"202\", \"side\":\"SELL\", \"hash\":\"6998eba6698c650f2bc6677b5bb5e36ef0bf9559\", \"best_bid\":\"0.38\", \"best_ask\":\"0.39\"}], \"timestamp\":\"1785204061569\", \"event_type\":\"price_change\"}","received_at":"2026-07-28T02:01:08.970086Z","schema_version":"clob-market-ws.price_change.v1","sequence":null,"server_hash":null,"server_timestamp":"1785204061569","session_id":"d2757dd6dad94f3b9fe67e8dbf1adc37","source":"clob_market_ws"},"received_at":"2026-07-28T02:01:08.970086Z","record_id":"2f82341237aabdca6b78c5d5e426359d3863bb06d800da17d0e997bf78293b53","schema_fingerprint":"4aa3821a28b0b7c2400bc59aba4bcc0a76e971dadd19610d3ad38c768e124dc7","schema_version":"edge-lab-recorder.raw.v1","sequence":null,"source":"clob_market_ws"}
{"event_at":"2026-07-28T02:01:01.570000Z","event_fingerprint":"c8c8f600b17fb65ffac3cb57eef99102e8b145ed23a00fe677fbb86072d914da","payload":{"connection_id":"5d29200f65794d4d9ab6ef271f045a9b","event_at":"2026-07-28T02:01:01.570000Z","event_type":"price_change","frame_hash":"05ce18d9fd377f86001decd77c9ad012339252644115c2a84fe4842b5ca400c4","frame_index":0,"kind":"data","monotonic_ns":306051986900000,"payload":{"event_type":"price_change","market":"0xda6f0e0e93fc8469e0159a166028d017bddbc162b86f66bac90391379603d962","price_changes":[{"asset_id":"20893381255801015515826997628594359667013752732428989472914000440642900266717","best_ask":"0.39","best_bid":"0.38","hash":"0619b37142f007fc9c11f13569102072091cb53f","price":"0.31","side":"BUY","size":"181"},{"asset_id":"39272994714739463168905443499424551362424437245880253267329605556587274644733","best_ask":"0.62","best_bid":"0.61","hash":"6936c4ef4d024fbb13affd4b00d108891e7c4206","price":"0.69","side":"SELL","size":"181"}],"timestamp":"1785204061570"},"payload_hash":"85482630b68f64868b8fd8bbb05d1a3fcea56a8439f9821cadc547106ceeb863","raw_frame":"{\"market\":\"0xda6f0e0e93fc8469e0159a166028d017bddbc162b86f66bac90391379603d962\", \"price_changes\":[{\"asset_id\":\"20893381255801015515826997628594359667013752732428989472914000440642900266717\", \"price\":\"0.31\", \"size\":\"181\", \"side\":\"BUY\", \"hash\":\"0619b37142f007fc9c11f13569102072091cb53f\", \"best_bid\":\"0.38\", \"best_ask\":\"0.39\"}, {\"asset_id\":\"39272994714739463168905443499424551362424437245880253267329605556587274644733\", \"price\":\"0.69\", \"size\":\"181\", \"side\":\"SELL\", \"hash\":\"6936c4ef4d024fbb13affd4b00d108891e7c4206\", \"best_bid\":\"0.61\", \"best_ask\":\"0.62\"}], \"timestamp\":\"1785204061570\", \"event_type\":\"price_change\"}","received_at":"2026-07-28T02:01:08.982952Z","schema_version":"clob-market-ws.price_change.v1","sequence":null,"server_hash":null,"server_timestamp":"1785204061570","session_id":"d2757dd6dad94f3b9fe67e8dbf1adc37","source":"clob_market_ws"},"received_at":"2026-07-28T02:01:08.982952Z","record_id":"9773eb85d6a7ea9d74fbeab03bcf2c40de20bac65380eef1c867810855cf18fc","schema_fingerprint":"4aa3821a28b0b7c2400bc59aba4bcc0a76e971dadd19610d3ad38c768e124dc7","schema_version":"edge-lab-recorder.raw.v1","sequence":null,"source":"clob_market_ws"}
{"event_at":"2026-07-28T02:01:01.571000Z","event_fingerprint":"693fcd1ab6263a763dd8e307e97fb06dc78360111aa8c7b606dce3a4845b35cf","payload":{"connection_id":"5d29200f65794d4d9ab6ef271f045a9b","event_at":"2026-07-28T02:01:01.571000Z","event_type":"price_change","frame_hash":"09a147f9e659bc6dcbb45ee3d0575e48b1a2311b3ddc689649b0cf5f38cee3b9","frame_index":0,"kind":"data","monotonic_ns":306051992190666,"payload":{"event_type":"price_change","market":"0xda6f0e0e93fc8469e0159a166028d017bddbc162b86f66bac90391379603d962","price_changes":[{"asset_id":"39272994714739463168905443499424551362424437245880253267329605556587274644733","best_ask":"0.62","best_bid":"0.61","hash":"8b78db7798d40e2b85f145685fe470f24ec1a7f7","price":"0.61","side":"BUY","size":"39"},{"asset_id":"20893381255801015515826997628594359667013752732428989472914000440642900266717","best_ask":"0.39","best_bid":"0.38","hash":"49aaa6ec799f09064fba5ab113a13d37794ec0bb","price":"0.39","side":"SELL","size":"39"}],"timestamp":"1785204061571"},"payload_hash":"0b133a0a0c40e52c75f06e58796728161199311c1d96e18be669d0c0ab8240e7","raw_frame":"{\"market\":\"0xda6f0e0e93fc8469e0159a166028d017bddbc162b86f66bac90391379603d962\", \"price_changes\":[{\"asset_id\":\"39272994714739463168905443499424551362424437245880253267329605556587274644733\", \"price\":\"0.61\", \"size\":\"39\", \"side\":\"BUY\", \"hash\":\"8b78db7798d40e2b85f145685fe470f24ec1a7f7\", \"best_bid\":\"0.61\", \"best_ask\":\"0.62\"}, {\"asset_id\":\"20893381255801015515826997628594359667013752732428989472914000440642900266717\", \"price\":\"0.39\", \"size\":\"39\", \"side\":\"SELL\", \"hash\":\"49aaa6ec799f09064fba5ab113a13d37794ec0bb\", \"best_bid\":\"0.38\", \"best_ask\":\"0.39\"}], \"timestamp\":\"1785204061571\", \"event_type\":\"price_change\"}","received_at":"2026-07-28T02:01:08.988243Z","schema_version":"clob-market-ws.price_change.v1","sequence":null,"server_hash":null,"server_timestamp":"1785204061571","session_id":"d2757dd6dad94f3b9fe67e8dbf1adc37","source":"clob_market_ws"},"received_at":"2026-07-28T02:01:08.988243Z","record_id":"396f3bf7f7e1cefe0e3b040c57ace91576e6245fe8a546f2da5f02915c812e74","schema_fingerprint":"4aa3821a28b0b7c2400bc59aba4bcc0a76e971dadd19610d3ad38c768e124dc7","schema_version":"edge-lab-recorder.raw.v1","sequence":null,"source":"clob_market_ws"}
{"event_at":"2026-07-28T02:01:01.572000Z","event_fingerprint":"ffafc16b4cd927ee4b20d7fa5974384975cb3e47ad29c5a22a6802a7505a88bf","payload":{"connection_id":"5d29200f65794d4d9ab6ef271f045a9b","event_at":"2026-07-28T02:01:01.572000Z","event_type":"price_change","frame_hash":"c6b116ef159289fae6fedcba2031d8bb55d60327e62c62cbdeea5c41075b82db","frame_index":0,"kind":"data","monotonic_ns":306051998567625,"payload":{"event_type":"price_change","market":"0xda6f0e0e93fc8469e0159a166028d017bddbc162b86f66bac90391379603d962","price_changes":[{"asset_id":"39272994714739463168905443499424551362424437245880253267329605556587274644733","best_ask":"0.62","best_bid":"0.61","hash":"75da27bf57f722d9bda065f4d442610272b408bd","price":"0.48","side":"BUY","size":"137.05"},{"asset_id":"20893381255801015515826997628594359667013752732428989472914000440642900266717","best_ask":"0.39","best_bid":"0.38","hash":"c7a1caa9b96447b943a0b3a255a49c854969b28c","price":"0.52","side":"SELL","size":"137.05"}],"timestamp":"1785204061572"},"payload_hash":"0d1d45a1ee41606001fe5e7439aeb1f2c610e0499be07c03984696be5cfbd761","raw_frame":"{\"market\":\"0xda6f0e0e93fc8469e0159a166028d017bddbc162b86f66bac90391379603d962\", \"price_changes\":[{\"asset_id\":\"39272994714739463168905443499424551362424437245880253267329605556587274644733\", \"price\":\"0.48\", \"size\":\"137.05\", \"side\":\"BUY\", \"hash\":\"75da27bf57f722d9bda065f4d442610272b408bd\", \"best_bid\":\"0.61\", \"best_ask\":\"0.62\"}, {\"asset_id\":\"20893381255801015515826997628594359667013752732428989472914000440642900266717\", \"price\":\"0.52\", \"size\":\"137.05\", \"side\":\"SELL\", \"hash\":\"c7a1caa9b96447b943a0b3a255a49c854969b28c\", \"best_bid\":\"0.38\", \"best_ask\":\"0.39\"}], \"timestamp\":\"1785204061572\", \"event_type\":\"price_change\"}","received_at":"2026-07-28T02:01:08.994620Z","schema_version":"clob-market-ws.price_change.v1","sequence":null,"server_hash":null,"server_timestamp":"1785204061572","session_id":"d2757dd6dad94f3b9fe67e8dbf1adc37","source":"clob_market_ws"},"received_at":"2026-07-28T02:01:08.994620Z","record_id":"842758496a3451f6c31caf116df4c2883998ecede5751503b02e48c5987a58d0","schema_fingerprint":"4aa3821a28b0b7c2400bc59aba4bcc0a76e971dadd19610d3ad38c768e124dc7","schema_version":"edge-lab-recorder.raw.v1","sequence":null,"source":"clob_market_ws"}
{"event_at":"2026-07-28T02:01:01.573000Z","event_fingerprint":"9510e2653ec06aaf19ac912fcca84dae0a763d9d144eeba4b6391344fda85fca","payload":{"connection_id":"5d29200f65794d4d9ab6ef271f045a9b","event_at":"2026-07-28T02:01:01.573000Z","event_type":"price_change","frame_hash":"f721992962158656822a12964815cfe4c5c21ed7d4356885f9342cd0bdb97af8","frame_index":0,"kind":"data","monotonic_ns":306052005135541,"payload":{"event_type":"price_change","market":"0xda6f0e0e93fc8469e0159a166028d017bddbc162b86f66bac90391379603d962","price_changes":[{"asset_id":"20893381255801015515826997628594359667013752732428989472914000440642900266717","best_ask":"0.39","best_bid":"0.38","hash":"31a14250a2b10e510e8b25d49e2589eba0127fa6","price":"0.31","side":"BUY","size":"211"},{"asset_id":"39272994714739463168905443499424551362424437245880253267329605556587274644733","best_ask":"0.62","best_bid":"0.61","hash":"d109cf7eb9724f861586b67f090adea516b64d8f","price":"0.69","side":"SELL","size":"211"}],"timestamp":"1785204061573"},"payload_hash":"b0ee49b38c973ece2b90389d4a89175835420ee4ee4560430ddeb84759ecc014","raw_frame":"{\"market\":\"0xda6f0e0e93fc8469e0159a166028d017bddbc162b86f66bac90391379603d962\", \"price_changes\":[{\"asset_id\":\"20893381255801015515826997628594359667013752732428989472914000440642900266717\", \"price\":\"0.31\", \"size\":\"211\", \"side\":\"BUY\", \"hash\":\"31a14250a2b10e510e8b25d49e2589eba0127fa6\", \"best_bid\":\"0.38\", \"best_ask\":\"0.39\"}, {\"asset_id\":\"39272994714739463168905443499424551362424437245880253267329605556587274644733\", \"price\":\"0.69\", \"size\":\"211\", \"side\":\"SELL\", \"hash\":\"d109cf7eb9724f861586b67f090adea516b64d8f\", \"best_bid\":\"0.61\", \"best_ask\":\"0.62\"}], \"timestamp\":\"1785204061573\", \"event_type\":\"price_change\"}","received_at":"2026-07-28T02:01:09.001188Z","schema_version":"clob-market-ws.price_change.v1","sequence":null,"server_hash":null,"server_timestamp":"1785204061573","session_id":"d2757dd6dad94f3b9fe67e8dbf1adc37","source":"clob_market_ws"},"received_at":"2026-07-28T02:01:09.001188Z","record_id":"f3fd453b58579b4c1abaa8e2109b4597fcdd94e3098cf985722f44004dc64bec","schema_fingerprint":"4aa3821a28b0b7c2400bc59aba4bcc0a76e971dadd19610d3ad38c768e124dc7","schema_version":"edge-lab-recorder.raw.v1","sequence":null,"source":"clob_market_ws"}
{"event_at":"2026-07-28T02:01:01.574000Z","event_fingerprint":"bfe7c24b6b52e281c25b6f93f3bab226c2b6922e364db887319a7fea357cb988","payload":{"connection_id":"5d29200f65794d4d9ab6ef271f045a9b","event_at":"2026-07-28T02:01:01.574000Z","event_type":"price_change","frame_hash":"1f79dd8b14f9982e07abc48acdcdfdd75d247c7482c8e967131f5b0b022104b5","frame_index":0,"kind":"data","monotonic_ns":306052010278458,"payload":{"event_type":"price_change","market":"0xda6f0e0e93fc8469e0159a166028d017bddbc162b86f66bac90391379603d962","price_changes":[{"asset_id":"39272994714739463168905443499424551362424437245880253267329605556587274644733","best_ask":"0.62","best_bid":"0.61","hash":"9f799a8c442864fd9270de579d801d12c64c2f2e","price":"0.48","side":"BUY","size":"142.25"},{"asset_id":"20893381255801015515826997628594359667013752732428989472914000440642900266717","best_ask":"0.39","best_bid":"0.38","hash":"c4215ffe10337ba689227647c1225f7bcd4289cd","price":"0.52","side":"SELL","size":"142.25"}],"timestamp":"1785204061574"},"payload_hash":"a210ef882d88ff28adabb221b4c41cd96ecb35f2d4f22d5613115c6e46654875","raw_frame":"{\"market\":\"0xda6f0e0e93fc8469e0159a166028d017bddbc162b86f66bac90391379603d962\", \"price_changes\":[{\"asset_id\":\"39272994714739463168905443499424551362424437245880253267329605556587274644733\", \"price\":\"0.48\", \"size\":\"142.25\", \"side\":\"BUY\", \"hash\":\"9f799a8c442864fd9270de579d801d12c64c2f2e\", \"best_bid\":\"0.61\", \"best_ask\":\"0.62\"}, {\"asset_id\":\"20893381255801015515826997628594359667013752732428989472914000440642900266717\", \"price\":\"0.52\", \"size\":\"142.25\", \"side\":\"SELL\", \"hash\":\"c4215ffe10337ba689227647c1225f7bcd4289cd\", \"best_bid\":\"0.38\", \"best_ask\":\"0.39\"}], \"timestamp\":\"1785204061574\", \"event_type\":\"price_change\"}","received_at":"2026-07-28T02:01:09.006330Z","schema_version":"clob-market-ws.price_change.v1","sequence":null,"server_hash":null,"server_timestamp":"1785204061574","session_id":"d2757dd6dad94f3b9fe67e8dbf1adc37","source":"clob_market_ws"},"received_at":"2026-07-28T02:01:09.006330Z","record_id":"f1443bf88f31d21291fb8b76bf8b50b967d236c0944446071a60db11b23bcade","schema_fingerprint":"4aa3821a28b0b7c2400bc59aba4bcc0a76e971dadd19610d3ad38c768e124dc7","schema_version":"edge-lab-recorder.raw.v1","sequence":null,"source":"clob_market_ws"}
{"event_at":"2026-07-28T02:01:01.575000Z","event_fingerprint":"c7f6377d249af5e1b4edc13d8119e3f5251755eb8507f948c387014c302d2d7f","payload":{"connection_id":"5d29200f65794d4d9ab6ef271f045a9b","event_at":"2026-07-28T02:01:01.575000Z","event_type":"price_change","frame_hash":"250bdacda9ad447ecb9444b7f28c83e0820b19b02dd38dfc3cda8da15d91d350","frame_index":0,"kind":"data","monotonic_ns":306052016014291,"payload":{"event_type":"price_change","market":"0xda6f0e0e93fc8469e0159a166028d017bddbc162b86f66bac90391379603d962","price_changes":[{"asset_id":"39272994714739463168905443499424551362424437245880253267329605556587274644733","best_ask":"0.62","best_bid":"0.61","hash":"d8f0710610b6cf0daac2f11e3c8942cefddb60c8","price":"0.47","side":"BUY","size":"122"},{"asset_id":"20893381255801015515826997628594359667013752732428989472914000440642900266717","best_ask":"0.39","best_bid":"0.38","hash":"30afbe9580a9c005c46871e3f17843d6ec2ace8c","price":"0.53","side":"SELL","size":"122"}],"timestamp":"1785204061575"},"payload_hash":"f45be19532a3fc7b256b8acb4323a3391895983dfcbb665f1fa61e23246c5fce","raw_frame":"{\"market\":\"0xda6f0e0e93fc8469e0159a166028d017bddbc162b86f66bac90391379603d962\", \"price_changes\":[{\"asset_id\":\"39272994714739463168905443499424551362424437245880253267329605556587274644733\", \"price\":\"0.47\", \"size\":\"122\", \"side\":\"BUY\", \"hash\":\"d8f0710610b6cf0daac2f11e3c8942cefddb60c8\", \"best_bid\":\"0.61\", \"best_ask\":\"0.62\"}, {\"asset_id\":\"20893381255801015515826997628594359667013752732428989472914000440642900266717\", \"price\":\"0.53\", \"size\":\"122\", \"side\":\"SELL\", \"hash\":\"30afbe9580a9c005c46871e3f17843d6ec2ace8c\", \"best_bid\":\"0.38\", \"best_ask\":\"0.39\"}], \"timestamp\":\"1785204061575\", \"event_type\":\"price_change\"}","received_at":"2026-07-28T02:01:09.012066Z","schema_version":"clob-market-ws.price_change.v1","sequence":null,"server_hash":null,"server_timestamp":"1785204061575","session_id":"d2757dd6dad94f3b9fe67e8dbf1adc37","source":"clob_market_ws"},"received_at":"2026-07-28T02:01:09.012066Z","record_id":"787d89564f4ea528c1d9737781836100bf6512f34f492d49554ed7d8713a88f7","schema_fingerprint":"4aa3821a28b0b7c2400bc59aba4bcc0a76e971dadd19610d3ad38c768e124dc7","schema_version":"edge-lab-recorder.raw.v1","sequence":null,"source":"clob_market_ws"}
{"event_at":"2026-07-28T02:01:01.576000Z","event_fingerprint":"63e582af03ecd6ba6ce300725e71798efd61140f433ff0ddaa30fb398d3df95a","payload":{"connection_id":"5d29200f65794d4d9ab6ef271f045a9b","event_at":"2026-07-28T02:01:01.576000Z","event_type":"price_change","frame_hash":"7915fa87182f192b24ee717b5c05b7670a536c66910a69842e73e5186f6d12f0","frame_index":0,"kind":"data","monotonic_ns":306052021248166,"payload":{"event_type":"price_change","market":"0xda6f0e0e93fc8469e0159a166028d017bddbc162b86f66bac90391379603d962","price_changes":[{"asset_id":"39272994714739463168905443499424551362424437245880253267329605556587274644733","best_ask":"0.62","best_bid":"0.61","hash":"1d21f22d4c480477338cead8229a5c90e8de16db","price":"0.61","side":"BUY","size":"44"},{"asset_id":"20893381255801015515826997628594359667013752732428989472914000440642900266717","best_ask":"0.39","best_bid":"0.38","hash":"03607530a153f2d44e09e5d05153efe8fb038e64","price":"0.39","side":"SELL","size":"44"}],"timestamp":"1785204061576"},"payload_hash":"0ff9030f617d5b57451179cbcbf2a66385d026aa7bf4b321d2c3b3693379a3aa","raw_frame":"{\"market\":\"0xda6f0e0e93fc8469e0159a166028d017bddbc162b86f66bac90391379603d962\", \"price_changes\":[{\"asset_id\":\"39272994714739463168905443499424551362424437245880253267329605556587274644733\", \"price\":\"0.61\", \"size\":\"44\", \"side\":\"BUY\", \"hash\":\"1d21f22d4c480477338cead8229a5c90e8de16db\", \"best_bid\":\"0.61\", \"best_ask\":\"0.62\"}, {\"asset_id\":\"20893381255801015515826997628594359667013752732428989472914000440642900266717\", \"price\":\"0.39\", \"size\":\"44\", \"side\":\"SELL\", \"hash\":\"03607530a153f2d44e09e5d05153efe8fb038e64\", \"best_bid\":\"0.38\", \"best_ask\":\"0.39\"}], \"timestamp\":\"1785204061576\", \"event_type\":\"price_change\"}","received_at":"2026-07-28T02:01:09.017300Z","schema_version":"clob-market-ws.price_change.v1","sequence":null,"server_hash":null,"server_timestamp":"1785204061576","session_id":"d2757dd6dad94f3b9fe67e8dbf1adc37","source":"clob_market_ws"},"received_at":"2026-07-28T02:01:09.017300Z","record_id":"2920808e6e236a107451a8381bcfb412bad8267c6d99a775663c86f1c3e72269","schema_fingerprint":"4aa3821a28b0b7c2400bc59aba4bcc0a76e971dadd19610d3ad38c768e124dc7","schema_version":"edge-lab-recorder.raw.v1","sequence":null,"source":"clob_market_ws"}
{"event_at":"2026-07-28T02:01:01.577000Z","event_fingerprint":"319af54a36471af2c1ad995b5a18add1c10eaaa00c477493ef74413f37e43dd5","payload":{"connection_id":"5d29200f65794d4d9ab6ef271f045a9b","event_at":"2026-07-28T02:01:01.577000Z","event_type":"price_change","frame_hash":"73ee772eeaa0d8b0435661eebd251e7afc949873c757082de5a3c937caa72fc0","frame_index":0,"kind":"data","monotonic_ns":306052027119541,"payload":{"event_type":"price_change","market":"0xda6f0e0e93fc8469e0159a166028d017bddbc162b86f66bac90391379603d962","price_changes":[{"asset_id":"20893381255801015515826997628594359667013752732428989472914000440642900266717","best_ask":"0.39","best_bid":"0.38","hash":"2e205dee00a9a8eaf55c103d532d8463ce4ef121","price":"0.31","side":"BUY","size":"241"},{"asset_id":"39272994714739463168905443499424551362424437245880253267329605556587274644733","best_ask":"0.62","best_bid":"0.61","hash":"25459d537295d4eb0cba5c1559cee3f24277a7fc","price":"0.69","side":"SELL","size":"241"}],"timestamp":"1785204061577"},"payload_hash":"5a42cdf49991efec5f70a62db00310dc7bb8639762331278856d31966e13986c","raw_frame":"{\"market\":\"0xda6f0e0e93fc8469e0159a166028d017bddbc162b86f66bac90391379603d962\", \"price_changes\":[{\"asset_id\":\"20893381255801015515826997628594359667013752732428989472914000440642900266717\", \"price\":\"0.31\", \"size\":\"241\", \"side\":\"BUY\", \"hash\":\"2e205dee00a9a8eaf55c103d532d8463ce4ef121\", \"best_bid\":\"0.38\", \"best_ask\":\"0.39\"}, {\"asset_id\":\"39272994714739463168905443499424551362424437245880253267329605556587274644733\", \"price\":\"0.69\", \"size\":\"241\", \"side\":\"SELL\", \"hash\":\"25459d537295d4eb0cba5c1559cee3f24277a7fc\", \"best_bid\":\"0.61\", \"best_ask\":\"0.62\"}], \"timestamp\":\"1785204061577\", \"event_type\":\"price_change\"}","received_at":"2026-07-28T02:01:09.023173Z","schema_version":"clob-market-ws.price_change.v1","sequence":null,"server_hash":null,"server_timestamp":"1785204061577","session_id":"d2757dd6dad94f3b9fe67e8dbf1adc37","source":"clob_market_ws"},"received_at":"2026-07-28T02:01:09.023173Z","record_id":"708734893c246092cc6cbf2277ea4ddd67e8c84757ed99a7a77ce1825af7a851","schema_fingerprint":"4aa3821a28b0b7c2400bc59aba4bcc0a76e971dadd19610d3ad38c768e124dc7","schema_version":"edge-lab-recorder.raw.v1","sequence":null,"source":"clob_market_ws"}
{"event_at":"2026-07-28T02:01:01.578000Z","event_fingerprint":"36be45ab8a5149a2c068c7b90a76eec48c6dc2a266f1a13f968a29064eab2aec","payload":{"connection_id":"5d29200f65794d4d9ab6ef271f045a9b","event_at":"2026-07-28T02:01:01.578000Z","event_type":"price_change","frame_hash":"4ae6aca14730f57bba3be42415d43533a5361fd9e457b90b2835d9453f9571b5","frame_index":0,"kind":"data","monotonic_ns":306052032077125,"payload":{"event_type":"price_change","market":"0xda6f0e0e93fc8469e0159a166028d017bddbc162b86f66bac90391379603d962","price_changes":[{"asset_id":"20893381255801015515826997628594359667013752732428989472914000440642900266717","best_ask":"0.39","best_bid":"0.38","hash":"ff2d99ed4695257e95d751e92989670c8f5f7542","price":"0.39","side":"SELL","size":"49"},{"asset_id":"39272994714739463168905443499424551362424437245880253267329605556587274644733","best_ask":"0.62","best_bid":"0.61","hash":"b0900ce63f7fa7b0943ebf285720096382e1dddf","price":"0.61","side":"BUY","size":"49"}],"timestamp":"1785204061578"},"payload_hash":"7c0738531b9b6c6b2ff33148728d2210c287844613d270d1409993573688877c","raw_frame":"{\"market\":\"0xda6f0e0e93fc8469e0159a166028d017bddbc162b86f66bac90391379603d962\", \"price_changes\":[{\"asset_id\":\"20893381255801015515826997628594359667013752732428989472914000440642900266717\", \"price\":\"0.39\", \"size\":\"49\", \"side\":\"SELL\", \"hash\":\"ff2d99ed4695257e95d751e92989670c8f5f7542\", \"best_bid\":\"0.38\", \"best_ask\":\"0.39\"}, {\"asset_id\":\"39272994714739463168905443499424551362424437245880253267329605556587274644733\", \"price\":\"0.61\", \"size\":\"49\", \"side\":\"BUY\", \"hash\":\"b0900ce63f7fa7b0943ebf285720096382e1dddf\", \"best_bid\":\"0.61\", \"best_ask\":\"0.62\"}], \"timestamp\":\"1785204061578\", \"event_type\":\"price_change\"}","received_at":"2026-07-28T02:01:09.028129Z","schema_version":"clob-market-ws.price_change.v1","sequence":null,"server_hash":null,"server_timestamp":"1785204061578","session_id":"d2757dd6dad94f3b9fe67e8dbf1adc37","source":"clob_market_ws"},"received_at":"2026-07-28T02:01:09.028129Z","record_id":"333dd7eea3377dd4e1239029183bd3191f75fbba50506a066dfb79e234f4b0ad","schema_fingerprint":"4aa3821a28b0b7c2400bc59aba4bcc0a76e971dadd19610d3ad38c768e124dc7","schema_version":"edge-lab-recorder.raw.v1","sequence":null,"source":"clob_market_ws"}
{"event_at":"2026-07-28T02:01:01.579000Z","event_fingerprint":"c421d1be8c08f82a033ed9dfd20532b332685e3b25d27c6b152277985e9d55c4","payload":{"connection_id":"5d29200f65794d4d9ab6ef271f045a9b","event_at":"2026-07-28T02:01:01.579000Z","event_type":"price_change","frame_hash":"c1218a47dc854b668f8fc004d4f4172189984c386a02fa89addcfce6734be906","frame_index":0,"kind":"data","monotonic_ns":306052037418208,"payload":{"event_type":"price_change","market":"0xda6f0e0e93fc8469e0159a166028d017bddbc162b86f66bac90391379603d962","price_changes":[{"asset_id":"39272994714739463168905443499424551362424437245880253267329605556587274644733","best_ask":"0.62","best_bid":"0.61","hash":"5a3fc46247fb529083c8c81204047435db078802","price":"0.46","side":"BUY","size":"207"},{"asset_id":"20893381255801015515826997628594359667013752732428989472914000440642900266717","best_ask":"0.39","best_bid":"0.38","hash":"8ce0047748d70d8bccdfd88e251a645bd97b5650","price":"0.54","side":"SELL","size":"207"}],"timestamp":"1785204061579"},"payload_hash":"0cf37312985df515900204a0d9c37468dca6b7b5f419d72c0eb002cfece9b091","raw_frame":"{\"market\":\"0xda6f0e0e93fc8469e0159a166028d017bddbc162b86f66bac90391379603d962\", \"price_changes\":[{\"asset_id\":\"39272994714739463168905443499424551362424437245880253267329605556587274644733\", \"price\":\"0.46\", \"size\":\"207\", \"side\":\"BUY\", \"hash\":\"5a3fc46247fb529083c8c81204047435db078802\", \"best_bid\":\"0.61\", \"best_ask\":\"0.62\"}, {\"asset_id\":\"20893381255801015515826997628594359667013752732428989472914000440642900266717\", \"price\":\"0.54\", \"size\":\"207\", \"side\":\"SELL\", \"hash\":\"8ce0047748d70d8bccdfd88e251a645bd97b5650\", \"best_bid\":\"0.38\", \"best_ask\":\"0.39\"}], \"timestamp\":\"1785204061579\", \"event_type\":\"price_change\"}","received_at":"2026-07-28T02:01:09.033472Z","schema_version":"clob-market-ws.price_change.v1","sequence":null,"server_hash":null,"server_timestamp":"1785204061579","session_id":"d2757dd6dad94f3b9fe67e8dbf1adc37","source":"clob_market_ws"},"received_at":"2026-07-28T02:01:09.033472Z","record_id":"192b94b084f7051d551c1141b411bc416aebb22d4415127592c80326ce469bcf","schema_fingerprint":"4aa3821a28b0b7c2400bc59aba4bcc0a76e971dadd19610d3ad38c768e124dc7","schema_version":"edge-lab-recorder.raw.v1","sequence":null,"source":"clob_market_ws"}
{"event_at":"2026-07-28T02:01:01.582000Z","event_fingerprint":"d768f1d6152daa6733a2cdd0a06ea63205100ef6bf377ba4ce3bb9c496728a96","payload":{"connection_id":"5d29200f65794d4d9ab6ef271f045a9b","event_at":"2026-07-28T02:01:01.582000Z","event_type":"price_change","frame_hash":"0bd26bc403eb540e675932f066f404236ad6cd6ffeabe29a1071b5ea08c04961","frame_index":0,"kind":"data","monotonic_ns":306052042349791,"payload":{"event_type":"price_change","market":"0xda6f0e0e93fc8469e0159a166028d017bddbc162b86f66bac90391379603d962","price_changes":[{"asset_id":"20893381255801015515826997628594359667013752732428989472914000440642900266717","best_ask":"0.39","best_bid":"0.38","hash":"3c08762afadb642f71fe4eb9334dd0b0eeb08d15","price":"0.26","side":"BUY","size":"150.1"},{"asset_id":"39272994714739463168905443499424551362424437245880253267329605556587274644733","best_ask":"0.62","best_bid":"0.61","hash":"1b96f65eee3fa356241e4b1a7a90c7ce6d9c3197","price":"0.74","side":"SELL","size":"150.1"}],"timestamp":"1785204061582"},"payload_hash":"394c86faeee3c6cb6e0510e0813f4f36930d7da4dc1a53d934f05fb2246c225a","raw_frame":"{\"market\":\"0xda6f0e0e93fc8469e0159a166028d017bddbc162b86f66bac90391379603d962\", \"price_changes\":[{\"asset_id\":\"20893381255801015515826997628594359667013752732428989472914000440642900266717\", \"price\":\"0.26\", \"size\":\"150.1\", \"side\":\"BUY\", \"hash\":\"3c08762afadb642f71fe4eb9334dd0b0eeb08d15\", \"best_bid\":\"0.38\", \"best_ask\":\"0.39\"}, {\"asset_id\":\"39272994714739463168905443499424551362424437245880253267329605556587274644733\", \"price\":\"0.74\", \"size\":\"150.1\", \"side\":\"SELL\", \"hash\":\"1b96f65eee3fa356241e4b1a7a90c7ce6d9c3197\", \"best_bid\":\"0.61\", \"best_ask\":\"0.62\"}], \"timestamp\":\"1785204061582\", \"event_type\":\"price_change\"}","received_at":"2026-07-28T02:01:09.038402Z","schema_version":"clob-market-ws.price_change.v1","sequence":null,"server_hash":null,"server_timestamp":"1785204061582","session_id":"d2757dd6dad94f3b9fe67e8dbf1adc37","source":"clob_market_ws"},"received_at":"2026-07-28T02:01:09.038402Z","record_id":"24376e5c4d5781e21405655568188784bb71928bac783ff6caf8bb54ca095c11","schema_fingerprint":"4aa3821a28b0b7c2400bc59aba4bcc0a76e971dadd19610d3ad38c768e124dc7","schema_version":"edge-lab-recorder.raw.v1","sequence":null,"source":"clob_market_ws"}
{"event_at":"2026-07-28T02:01:01.583000Z","event_fingerprint":"a27248fea9f75cf797695f7e870815e288dcaa8be9e02a61f033ca8fc87eab60","payload":{"connection_id":"5d29200f65794d4d9ab6ef271f045a9b","event_at":"2026-07-28T02:01:01.583000Z","event_type":"price_change","frame_hash":"c048d2f35d84a997efd5a3c613eddc0f013ecaf129604a1b17dfbadfd7894b6d","frame_index":0,"kind":"data","monotonic_ns":306052047381083,"payload":{"event_type":"price_change","market":"0xda6f0e0e93fc8469e0159a166028d017bddbc162b86f66bac90391379603d962","price_changes":[{"asset_id":"39272994714739463168905443499424551362424437245880253267329605556587274644733","best_ask":"0.62","best_bid":"0.61","hash":"fa37f8335a4706394de307be44e700e53b65fd59","price":"0.61","side":"BUY","size":"58"},{"asset_id":"20893381255801015515826997628594359667013752732428989472914000440642900266717","best_ask":"0.39","best_bid":"0.38","hash":"f05963ef17f7ea57640f66e189647dcea268b895","price":"0.39","side":"SELL","size":"58"}],"timestamp":"1785204061583"},"payload_hash":"8f320d6a3a513343e7efd1241dde92047bb113b4e751d340f79e15b9e33e4bbf","raw_frame":"{\"market\":\"0xda6f0e0e93fc8469e0159a166028d017bddbc162b86f66bac90391379603d962\", \"price_changes\":[{\"asset_id\":\"39272994714739463168905443499424551362424437245880253267329605556587274644733\", \"price\":\"0.61\", \"size\":\"58\", \"side\":\"BUY\", \"hash\":\"fa37f8335a4706394de307be44e700e53b65fd59\", \"best_bid\":\"0.61\", \"best_ask\":\"0.62\"}, {\"asset_id\":\"20893381255801015515826997628594359667013752732428989472914000440642900266717\", \"price\":\"0.39\", \"size\":\"58\", \"side\":\"SELL\", \"hash\":\"f05963ef17f7ea57640f66e189647dcea268b895\", \"best_bid\":\"0.38\", \"best_ask\":\"0.39\"}], \"timestamp\":\"1785204061583\", \"event_type\":\"price_change\"}","received_at":"2026-07-28T02:01:09.043434Z","schema_version":"clob-market-ws.price_change.v1","sequence":null,"server_hash":null,"server_timestamp":"1785204061583","session_id":"d2757dd6dad94f3b9fe67e8dbf1adc37","source":"clob_market_ws"},"received_at":"2026-07-28T02:01:09.043434Z","record_id":"b10d04eab7f4fedc788b81c0acf0be11de2f83923d6b5dc883436cf3912302c4","schema_fingerprint":"4aa3821a28b0b7c2400bc59aba4bcc0a76e971dadd19610d3ad38c768e124dc7","schema_version":"edge-lab-recorder.raw.v1","sequence":null,"source":"clob_market_ws"}
{"event_at":"2026-07-28T02:01:01.595000Z","event_fingerprint":"6548764d4f90bcfe71d49063a8f4135d84ecb02d707e0b221e4ed017cb0bccfd","payload":{"connection_id":"5d29200f65794d4d9ab6ef271f045a9b","event_at":"2026-07-28T02:01:01.595000Z","event_type":"price_change","frame_hash":"72430aeb58c276666207a845606d0455f6e0541478b11edd7bcaba3d33737dea","frame_index":0,"kind":"data","monotonic_ns":306052053061458,"payload":{"event_type":"price_change","market":"0xda6f0e0e93fc8469e0159a166028d017bddbc162b86f66bac90391379603d962","price_changes":[{"asset_id":"39272994714739463168905443499424551362424437245880253267329605556587274644733","best_ask":"0.62","best_bid":"0.61","hash":"aa8ee7bcb3504cf2f9842361eba138e7834a8505","price":"0.61","side":"BUY","size":"34"},{"asset_id":"20893381255801015515826997628594359667013752732428989472914000440642900266717","best_ask":"0.39","best_bid":"0.38","hash":"ddb6794a34c36baf1953a21cffc5143df8555680","price":"0.39","side":"SELL","size":"34"}],"timestamp":"1785204061595"},"payload_hash":"60a6c2004e2deadc806785b02af9091349ab6d3986fc4a8aca0be6f0520e369c","raw_frame":"{\"market\":\"0xda6f0e0e93fc8469e0159a166028d017bddbc162b86f66bac90391379603d962\", \"price_changes\":[{\"asset_id\":\"39272994714739463168905443499424551362424437245880253267329605556587274644733\", \"price\":\"0.61\", \"size\":\"34\", \"side\":\"BUY\", \"hash\":\"aa8ee7bcb3504cf2f9842361eba138e7834a8505\", \"best_bid\":\"0.61\", \"best_ask\":\"0.62\"}, {\"asset_id\":\"20893381255801015515826997628594359667013752732428989472914000440642900266717\", \"price\":\"0.39\", \"size\":\"34\", \"side\":\"SELL\", \"hash\":\"ddb6794a34c36baf1953a21cffc5143df8555680\", \"best_bid\":\"0.38\", \"best_ask\":\"0.39\"}], \"timestamp\":\"1785204061595\", \"event_type\":\"price_change\"}","received_at":"2026-07-28T02:01:09.049115Z","schema_version":"clob-market-ws.price_change.v1","sequence":null,"server_hash":null,"server_timestamp":"1785204061595","session_id":"d2757dd6dad94f3b9fe67e8dbf1adc37","source":"clob_market_ws"},"received_at":"2026-07-28T02:01:09.049115Z","record_id":"06295fe5fd3d69efe8706a711b1ac4f167817c78d18ebd5a90578c495f35cd44","schema_fingerprint":"4aa3821a28b0b7c2400bc59aba4bcc0a76e971dadd19610d3ad38c768e124dc7","schema_version":"edge-lab-recorder.raw.v1","sequence":null,"source":"clob_market_ws"}
{"event_at":"2026-07-28T02:01:01.617000Z","event_fingerprint":"df7644940a47682e0452c4b756a74886930f80e1a5cba0ecb938fd20c5fe6331","payload":{"connection_id":"5d29200f65794d4d9ab6ef271f045a9b","event_at":"2026-07-28T02:01:01.617000Z","event_type":"price_change","frame_hash":"d066d2b03259e84aac6b748d0a7147dbdf4ab4e307a9cca738ff6439ce540868","frame_index":0,"kind":"data","monotonic_ns":306052057320250,"payload":{"event_type":"price_change","market":"0xda6f0e0e93fc8469e0159a166028d017bddbc162b86f66bac90391379603d962","price_changes":[{"asset_id":"20893381255801015515826997628594359667013752732428989472914000440642900266717","best_ask":"0.39","best_bid":"0.38","hash":"95e36635eee6c015441d3afb5b558b66aadb8289","price":"0.3","side":"BUY","size":"266.3"},{"asset_id":"39272994714739463168905443499424551362424437245880253267329605556587274644733","best_ask":"0.62","best_bid":"0.61","hash":"603e6da30ae886b05f267f81129a54028fa5213b","price":"0.7","side":"SELL","size":"266.3"}],"timestamp":"1785204061617"},"payload_hash":"686aed1934b74adeb6db685e5d940de3b30810054cba808493814fb1e36405d6","raw_frame":"{\"market\":\"0xda6f0e0e93fc8469e0159a166028d017bddbc162b86f66bac90391379603d962\", \"price_changes\":[{\"asset_id\":\"20893381255801015515826997628594359667013752732428989472914000440642900266717\", \"price\":\"0.3\", \"size\":\"266.3\", \"side\":\"BUY\", \"hash\":\"95e36635eee6c015441d3afb5b558b66aadb8289\", \"best_bid\":\"0.38\", \"best_ask\":\"0.39\"}, {\"asset_id\":\"39272994714739463168905443499424551362424437245880253267329605556587274644733\", \"price\":\"0.7\", \"size\":\"266.3\", \"side\":\"SELL\", \"hash\":\"603e6da30ae886b05f267f81129a54028fa5213b\", \"best_bid\":\"0.61\", \"best_ask\":\"0.62\"}], \"timestamp\":\"1785204061617\", \"event_type\":\"price_change\"}","received_at":"2026-07-28T02:01:09.053373Z","schema_version":"clob-market-ws.price_change.v1","sequence":null,"server_hash":null,"server_timestamp":"1785204061617","session_id":"d2757dd6dad94f3b9fe67e8dbf1adc37","source":"clob_market_ws"},"received_at":"2026-07-28T02:01:09.053373Z","record_id":"8b54a5eec84828d386f0b0a2d3ef8552e97aa0ee7e204c292e753311b8374a4b","schema_fingerprint":"4aa3821a28b0b7c2400bc59aba4bcc0a76e971dadd19610d3ad38c768e124dc7","schema_version":"edge-lab-recorder.raw.v1","sequence":null,"source":"clob_market_ws"}
{"event_at":"2026-07-28T02:01:01.618000Z","event_fingerprint":"354f5e408b29bb4590e79710d66b0414011e3b08d7a252f37ed36f8c0903370e","payload":{"connection_id":"5d29200f65794d4d9ab6ef271f045a9b","event_at":"2026-07-28T02:01:01.618000Z","event_type":"price_change","frame_hash":"996fb9609a8ea0ae1ba27b36819c2708f53c802844d31d4b833beffbff94c5d5","frame_index":0,"kind":"data","monotonic_ns":306052064616708,"payload":{"event_type":"price_change","market":"0xda6f0e0e93fc8469e0159a166028d017bddbc162b86f66bac90391379603d962","price_changes":[{"asset_id":"20893381255801015515826997628594359667013752732428989472914000440642900266717","best_ask":"0.39","best_bid":"0.38","hash":"6d2c4f3a542ff731d33cd8acad375268c84eafe2","price":"0.29","side":"BUY","size":"246.6"},{"asset_id":"39272994714739463168905443499424551362424437245880253267329605556587274644733","best_ask":"0.62","best_bid":"0.61","hash":"bd228895e8cf1b122e0f241b6e7fa50ae3ee9455","price":"0.71","side":"SELL","size":"246.6"}],"timestamp":"1785204061618"},"payload_hash":"d29dd6b5ba5d5de9b470797865b8b76cce95f439e90d77e11df6adbadeab9e4b","raw_frame":"{\"market\":\"0xda6f0e0e93fc8469e0159a166028d017bddbc162b86f66bac90391379603d962\", \"price_changes\":[{\"asset_id\":\"20893381255801015515826997628594359667013752732428989472914000440642900266717\", \"price\":\"0.29\", \"size\":\"246.6\", \"side\":\"BUY\", \"hash\":\"6d2c4f3a542ff731d33cd8acad375268c84eafe2\", \"best_bid\":\"0.38\", \"best_ask\":\"0.39\"}, {\"asset_id\":\"39272994714739463168905443499424551362424437245880253267329605556587274644733\", \"price\":\"0.71\", \"size\":\"246.6\", \"side\":\"SELL\", \"hash\":\"bd228895e8cf1b122e0f241b6e7fa50ae3ee9455\", \"best_bid\":\"0.61\", \"best_ask\":\"0.62\"}], \"timestamp\":\"1785204061618\", \"event_type\":\"price_change\"}","received_at":"2026-07-28T02:01:09.060669Z","schema_version":"clob-market-ws.price_change.v1","sequence":null,"server_hash":null,"server_timestamp":"1785204061618","session_id":"d2757dd6dad94f3b9fe67e8dbf1adc37","source":"clob_market_ws"},"received_at":"2026-07-28T02:01:09.060669Z","record_id":"092832c0d88f4116f0678ae3845a7ec6fa4aaf913ae5457fb3a7c6762bf41d0d","schema_fingerprint":"4aa3821a28b0b7c2400bc59aba4bcc0a76e971dadd19610d3ad38c768e124dc7","schema_version":"edge-lab-recorder.raw.v1","sequence":null,"source":"clob_market_ws"}
{"event_at":"2026-07-28T02:01:01.619000Z","event_fingerprint":"c21031b4138aa954e1ad40323a2e834c7ac89fbf6f6f6091c0b22bb6c00a9d08","payload":{"connection_id":"5d29200f65794d4d9ab6ef271f045a9b","event_at":"2026-07-28T02:01:01.619000Z","event_type":"price_change","frame_hash":"968273eebebf4b9cc7ad7d30ef90021055cabd9b6f55e555778cc486741a9f8a","frame_index":0,"kind":"data","monotonic_ns":306052070564916,"payload":{"event_type":"price_change","market":"0xda6f0e0e93fc8469e0159a166028d017bddbc162b86f66bac90391379603d962","price_changes":[{"asset_id":"20893381255801015515826997628594359667013752732428989472914000440642900266717","best_ask":"0.39","best_bid":"0.38","hash":"f8da35424115a53cfe989009371138c9deb0c4b9","price":"0.31","side":"BUY","size":"247"},{"asset_id":"39272994714739463168905443499424551362424437245880253267329605556587274644733","best_ask":"0.62","best_bid":"0.61","hash":"68769217a434cd3709f49732ccd8a3918baf76a1","price":"0.69","side":"SELL","size":"247"}],"timestamp":"1785204061619"},"payload_hash":"c7586b4d3cbe6e9a3b77f99af306f577197964b3bdb043ff9e20b2700924b9ef","raw_frame":"{\"market\":\"0xda6f0e0e93fc8469e0159a166028d017bddbc162b86f66bac90391379603d962\", \"price_changes\":[{\"asset_id\":\"20893381255801015515826997628594359667013752732428989472914000440642900266717\", \"price\":\"0.31\", \"size\":\"247\", \"side\":\"BUY\", \"hash\":\"f8da35424115a53cfe989009371138c9deb0c4b9\", \"best_bid\":\"0.38\", \"best_ask\":\"0.39\"}, {\"asset_id\":\"39272994714739463168905443499424551362424437245880253267329605556587274644733\", \"price\":\"0.69\", \"size\":\"247\", \"side\":\"SELL\", \"hash\":\"68769217a434cd3709f49732ccd8a3918baf76a1\", \"best_bid\":\"0.61\", \"best_ask\":\"0.62\"}], \"timestamp\":\"1785204061619\", \"event_type\":\"price_change\"}","received_at":"2026-07-28T02:01:09.066618Z","schema_version":"clob-market-ws.price_change.v1","sequence":null,"server_hash":null,"server_timestamp":"1785204061619","session_id":"d2757dd6dad94f3b9fe67e8dbf1adc37","source":"clob_market_ws"},"received_at":"2026-07-28T02:01:09.066618Z","record_id":"b6c4b95ece58825ad886532cab30eb052b30822955b3b690e640023bce42604c","schema_fingerprint":"4aa3821a28b0b7c2400bc59aba4bcc0a76e971dadd19610d3ad38c768e124dc7","schema_version":"edge-lab-recorder.raw.v1","sequence":null,"source":"clob_market_ws"}
{"event_at":"2026-07-28T02:01:01.620000Z","event_fingerprint":"cb8196a029cb4e4d6b08761696f181a80f8b101b633dad95bc93ca041d68e3ce","payload":{"connection_id":"5d29200f65794d4d9ab6ef271f045a9b","event_at":"2026-07-28T02:01:01.620000Z","event_type":"price_change","frame_hash":"2674e4e0311f51254bdda700f84ba51f0c44a0f5335728fa23c59e2cf017b7d2","frame_index":0,"kind":"data","monotonic_ns":306052075473625,"payload":{"event_type":"price_change","market":"0xda6f0e0e93fc8469e0159a166028d017bddbc162b86f66bac90391379603d962","price_changes":[{"asset_id":"39272994714739463168905443499424551362424437245880253267329605556587274644733","best_ask":"0.62","best_bid":"0.61","hash":"90a71af60e7ffca7e493689bfe1c59d35aaf825f","price":"0.02","side":"BUY","size":"1633.1"},{"asset_id":"20893381255801015515826997628594359667013752732428989472914000440642900266717","best_ask":"0.39","best_bid":"0.38","hash":"21aac9eb0d89bd5eb432e7b0da4d7d894b81a330","price":"0.98","side":"SELL","size":"1633.1"}],"timestamp":"1785204061620"},"payload_hash":"34764f5fa879466d17f3fda4387789884f323c0cb92da4291801dd22e895b656","raw_frame":"{\"market\":\"0xda6f0e0e93fc8469e0159a166028d017bddbc162b86f66bac90391379603d962\", \"price_changes\":[{\"asset_id\":\"39272994714739463168905443499424551362424437245880253267329605556587274644733\", \"price\":\"0.02\", \"size\":\"1633.1\", \"side\":\"BUY\", \"hash\":\"90a71af60e7ffca7e493689bfe1c59d35aaf825f\", \"best_bid\":\"0.61\", \"best_ask\":\"0.62\"}, {\"asset_id\":\"20893381255801015515826997628594359667013752732428989472914000440642900266717\", \"price\":\"0.98\", \"size\":\"1633.1\", \"side\":\"SELL\", \"hash\":\"21aac9eb0d89bd5eb432e7b0da4d7d894b81a330\", \"best_bid\":\"0.38\", \"best_ask\":\"0.39\"}], \"timestamp\":\"1785204061620\", \"event_type\":\"price_change\"}","received_at":"2026-07-28T02:01:09.071527Z","schema_version":"clob-market-ws.price_change.v1","sequence":null,"server_hash":null,"server_timestamp":"1785204061620","session_id":"d2757dd6dad94f3b9fe67e8dbf1adc37","source":"clob_market_ws"},"received_at":"2026-07-28T02:01:09.071527Z","record_id":"41c1f7b6139e766285b6e861810101f847126c558c0a2c3204b33008e38c9cc7","schema_fingerprint":"4aa3821a28b0b7c2400bc59aba4bcc0a76e971dadd19610d3ad38c768e124dc7","schema_version":"edge-lab-recorder.raw.v1","sequence":null,"source":"clob_market_ws"}
{"event_at":"2026-07-28T02:01:01.638000Z","event_fingerprint":"2feb85c37e8eb2ac9d384d48e9aff6fe5e993a0594acab7507b6833664fc270e","payload":{"connection_id":"5d29200f65794d4d9ab6ef271f045a9b","event_at":"2026-07-28T02:01:01.638000Z","event_type":"price_change","frame_hash":"5ac62aec149c517a6315e7da1cbbd38740af9ce34124d9a368b177aab4f73f3f","frame_index":0,"kind":"data","monotonic_ns":306052080462416,"payload":{"event_type":"price_change","market":"0xda6f0e0e93fc8469e0159a166028d017bddbc162b86f66bac90391379603d962","price_changes":[{"asset_id":"20893381255801015515826997628594359667013752732428989472914000440642900266717","best_ask":"0.39","best_bid":"0.38","hash":"e58777588122f4657a05eae2b83e235cdb8e0512","price":"0.31","side":"BUY","size":"217"},{"asset_id":"39272994714739463168905443499424551362424437245880253267329605556587274644733","best_ask":"0.62","best_bid":"0.61","hash":"bf2bc768ed4bf19d057487ab3996a7e34d1489b8","price":"0.69","side":"SELL","size":"217"}],"timestamp":"1785204061638"},"payload_hash":"287f4ef4b639159f61a6100bad65bb863430b9167aa6d9d08418863212c86ed4","raw_frame":"{\"market\":\"0xda6f0e0e93fc8469e0159a166028d017bddbc162b86f66bac90391379603d962\", \"price_changes\":[{\"asset_id\":\"20893381255801015515826997628594359667013752732428989472914000440642900266717\", \"price\":\"0.31\", \"size\":\"217\", \"side\":\"BUY\", \"hash\":\"e58777588122f4657a05eae2b83e235cdb8e0512\", \"best_bid\":\"0.38\", \"best_ask\":\"0.39\"}, {\"asset_id\":\"39272994714739463168905443499424551362424437245880253267329605556587274644733\", \"price\":\"0.69\", \"size\":\"217\", \"side\":\"SELL\", \"hash\":\"bf2bc768ed4bf19d057487ab3996a7e34d1489b8\", \"best_bid\":\"0.61\", \"best_ask\":\"0.62\"}], \"timestamp\":\"1785204061638\", \"event_type\":\"price_change\"}","received_at":"2026-07-28T02:01:09.076516Z","schema_version":"clob-market-ws.price_change.v1","sequence":null,"server_hash":null,"server_timestamp":"1785204061638","session_id":"d2757dd6dad94f3b9fe67e8dbf1adc37","source":"clob_market_ws"},"received_at":"2026-07-28T02:01:09.076516Z","record_id":"040ad026d6a1361551d11f58f0770cabae665a4794daeb571ab8c00afdf8437a","schema_fingerprint":"4aa3821a28b0b7c2400bc59aba4bcc0a76e971dadd19610d3ad38c768e124dc7","schema_version":"edge-lab-recorder.raw.v1","sequence":null,"source":"clob_market_ws"}
{"event_at":"2026-07-28T02:01:01.639000Z","event_fingerprint":"540f64b6d10584132ab6d7ba42bb5327f5250e7687d62eec44f86066b3c1a9e2","payload":{"connection_id":"5d29200f65794d4d9ab6ef271f045a9b","event_at":"2026-07-28T02:01:01.639000Z","event_type":"price_change","frame_hash":"c1740fa3fc4135ac37a950e0bf5a1c26bc9fc84f8abe71d7335a685234953406","frame_index":0,"kind":"data","monotonic_ns":306052086110833,"payload":{"event_type":"price_change","market":"0xda6f0e0e93fc8469e0159a166028d017bddbc162b86f66bac90391379603d962","price_changes":[{"asset_id":"39272994714739463168905443499424551362424437245880253267329605556587274644733","best_ask":"0.62","best_bid":"0.61","hash":"ed14005a322faf1b8f4c0f74c8717df048b1add8","price":"0.6","side":"BUY","size":"127.2"},{"asset_id":"20893381255801015515826997628594359667013752732428989472914000440642900266717","best_ask":"0.39","best_bid":"0.38","hash":"03dad34f70a11c3dbd678059df49f332cef1b6b5","price":"0.4","side":"SELL","size":"127.2"}],"timestamp":"1785204061639"},"payload_hash":"e1281826c5045be99de278898aa325337fda977b6e5906b709f1b88d01c5f991","raw_frame":"{\"market\":\"0xda6f0e0e93fc8469e0159a166028d017bddbc162b86f66bac90391379603d962\", \"price_changes\":[{\"asset_id\":\"39272994714739463168905443499424551362424437245880253267329605556587274644733\", \"price\":\"0.6\", \"size\":\"127.2\", \"side\":\"BUY\", \"hash\":\"ed14005a322faf1b8f4c0f74c8717df048b1add8\", \"best_bid\":\"0.61\", \"best_ask\":\"0.62\"}, {\"asset_id\":\"20893381255801015515826997628594359667013752732428989472914000440642900266717\", \"price\":\"0.4\", \"size\":\"127.2\", \"side\":\"SELL\", \"hash\":\"03dad34f70a11c3dbd678059df49f332cef1b6b5\", \"best_bid\":\"0.38\", \"best_ask\":\"0.39\"}], \"timestamp\":\"1785204061639\", \"event_type\":\"price_change\"}","received_at":"2026-07-28T02:01:09.082164Z","schema_version":"clob-market-ws.price_change.v1","sequence":null,"server_hash":null,"server_timestamp":"1785204061639","session_id":"d2757dd6dad94f3b9fe67e8dbf1adc37","source":"clob_market_ws"},"received_at":"2026-07-28T02:01:09.082164Z","record_id":"a7826c26cc2480e3e5e564250db3b8541e8cfb44f2fe5f52dd14546b75aa14c5","schema_fingerprint":"4aa3821a28b0b7c2400bc59aba4bcc0a76e971dadd19610d3ad38c768e124dc7","schema_version":"edge-lab-recorder.raw.v1","sequence":null,"source":"clob_market_ws"}
{"event_at":"2026-07-28T02:01:01.643000Z","event_fingerprint":"1c6ddcaedf8ad9f5a60adaba7375474ca4d910d8796c2b1047d950682b28eced","payload":{"connection_id":"5d29200f65794d4d9ab6ef271f045a9b","event_at":"2026-07-28T02:01:01.643000Z","event_type":"price_change","frame_hash":"ed6b07a03de4bcfeaa106eb740c416b7614571c7b16df8349be59d6cc19db549","frame_index":0,"kind":"data","monotonic_ns":306052092542416,"payload":{"event_type":"price_change","market":"0xda6f0e0e93fc8469e0159a166028d017bddbc162b86f66bac90391379603d962","price_changes":[{"asset_id":"39272994714739463168905443499424551362424437245880253267329605556587274644733","best_ask":"0.62","best_bid":"0.61","hash":"368f4b4350104a07433283b8e97e609483494c98","price":"0.49","side":"BUY","size":"299.06"},{"asset_id":"20893381255801015515826997628594359667013752732428989472914000440642900266717","best_ask":"0.39","best_bid":"0.38","hash":"8b9ae2e2d20586f27a5270ce9180418e9c65cec8","price":"0.51","side":"SELL","size":"299.06"}],"timestamp":"1785204061643"},"payload_hash":"c39f13fefc053964b238eb9bca3717eee498022dc29c8046434dacf05f240a59","raw_frame":"{\"market\":\"0xda6f0e0e93fc8469e0159a166028d017bddbc162b86f66bac90391379603d962\", \"price_changes\":[{\"asset_id\":\"39272994714739463168905443499424551362424437245880253267329605556587274644733\", \"price\":\"0.49\", \"size\":\"299.06\", \"side\":\"BUY\", \"hash\":\"368f4b4350104a07433283b8e97e609483494c98\", \"best_bid\":\"0.61\", \"best_ask\":\"0.62\"}, {\"asset_id\":\"20893381255801015515826997628594359667013752732428989472914000440642900266717\", \"price\":\"0.51\", \"size\":\"299.06\", \"side\":\"SELL\", \"hash\":\"8b9ae2e2d20586f27a5270ce9180418e9c65cec8\", \"best_bid\":\"0.38\", \"best_ask\":\"0.39\"}], \"timestamp\":\"1785204061643\", \"event_type\":\"price_change\"}","received_at":"2026-07-28T02:01:09.088596Z","schema_version":"clob-market-ws.price_change.v1","sequence":null,"server_hash":null,"server_timestamp":"1785204061643","session_id":"d2757dd6dad94f3b9fe67e8dbf1adc37","source":"clob_market_ws"},"received_at":"2026-07-28T02:01:09.088596Z","record_id":"5236414d10d85b12a5a0ae4f254a33373cc89024c13bbfc3f3ac116e2c6a4848","schema_fingerprint":"4aa3821a28b0b7c2400bc59aba4bcc0a76e971dadd19610d3ad38c768e124dc7","schema_version":"edge-lab-recorder.raw.v1","sequence":null,"source":"clob_market_ws"}
{"event_at":"2026-07-28T02:01:01.644000Z","event_fingerprint":"f09cfc0724ce171bee5ec4059ffd3a03cb8265ee547a7cbe136ee4444a9f3761","payload":{"connection_id":"5d29200f65794d4d9ab6ef271f045a9b","event_at":"2026-07-28T02:01:01.644000Z","event_type":"price_change","frame_hash":"c6b65492daa19238599a20d05214517531ae76195510e1dda5a41e3f1ab07f38","frame_index":0,"kind":"data","monotonic_ns":306052098163458,"payload":{"event_type":"price_change","market":"0xda6f0e0e93fc8469e0159a166028d017bddbc162b86f66bac90391379603d962","price_changes":[{"asset_id":"20893381255801015515826997628594359667013752732428989472914000440642900266717","best_ask":"0.39","best_bid":"0.38","hash":"d57aa8b68f52202d8cf30e8847da802e100b17f1","price":"0.31","side":"BUY","size":"187"},{"asset_id":"39272994714739463168905443499424551362424437245880253267329605556587274644733","best_ask":"0.62","best_bid":"0.61","hash":"6f8ad874542b5f9c246a4ef23dccf666c3577ca9","price":"0.69","side":"SELL","size":"187"}],"timestamp":"1785204061644"},"payload_hash":"6023995e045561eab4492f3c99480f02495d216e5f58704d6d3847fe352afa42","raw_frame":"{\"market\":\"0xda6f0e0e93fc8469e0159a166028d017bddbc162b86f66bac90391379603d962\", \"price_changes\":[{\"asset_id\":\"20893381255801015515826997628594359667013752732428989472914000440642900266717\", \"price\":\"0.31\", \"size\":\"187\", \"side\":\"BUY\", \"hash\":\"d57aa8b68f52202d8cf30e8847da802e100b17f1\", \"best_bid\":\"0.38\", \"best_ask\":\"0.39\"}, {\"asset_id\":\"39272994714739463168905443499424551362424437245880253267329605556587274644733\", \"price\":\"0.69\", \"size\":\"187\", \"side\":\"SELL\", \"hash\":\"6f8ad874542b5f9c246a4ef23dccf666c3577ca9\", \"best_bid\":\"0.61\", \"best_ask\":\"0.62\"}], \"timestamp\":\"1785204061644\", \"event_type\":\"price_change\"}","received_at":"2026-07-28T02:01:09.094216Z","schema_version":"clob-market-ws.price_change.v1","sequence":null,"server_hash":null,"server_timestamp":"1785204061644","session_id":"d2757dd6dad94f3b9fe67e8dbf1adc37","source":"clob_market_ws"},"received_at":"2026-07-28T02:01:09.094216Z","record_id":"369a91170e8d43bebd231b77276e6739fae0ed93c3fbadf96815fc7b9d95b076","schema_fingerprint":"4aa3821a28b0b7c2400bc59aba4bcc0a76e971dadd19610d3ad38c768e124dc7","schema_version":"edge-lab-recorder.raw.v1","sequence":null,"source":"clob_market_ws"}
{"event_at":"2026-07-28T02:01:01.644000Z","event_fingerprint":"e9e14577c394474a8af52c1d8d7e4086a6208a583de3ef96fd693e58f70bed80","payload":{"connection_id":"5d29200f65794d4d9ab6ef271f045a9b","event_at":"2026-07-28T02:01:01.644000Z","event_type":"price_change","frame_hash":"1fcccaf1953a186c0d39be13be2d3af38560001be585bb453484982c27810e80","frame_index":0,"kind":"data","monotonic_ns":306052105909541,"payload":{"event_type":"price_change","market":"0xda6f0e0e93fc8469e0159a166028d017bddbc162b86f66bac90391379603d962","price_changes":[{"asset_id":"39272994714739463168905443499424551362424437245880253267329605556587274644733","best_ask":"0.62","best_bid":"0.61","hash":"8c73a03e72f09d41c13c3843fc9cfab5c6e0e4cb","price":"0.6","side":"BUY","size":"102.2"},{"asset_id":"20893381255801015515826997628594359667013752732428989472914000440642900266717","best_ask":"0.39","best_bid":"0.38","hash":"5eeabc3214bb6b511435377da622138a9317be42","price":"0.4","side":"SELL","size":"102.2"}],"timestamp":"1785204061644"},"payload_hash":"cb1cad8158deb1aa72b133d1113c68cb508ffe3e8a6f2d7505cdf31e71a23bbc","raw_frame":"{\"market\":\"0xda6f0e0e93fc8469e0159a166028d017bddbc162b86f66bac90391379603d962\", \"price_changes\":[{\"asset_id\":\"39272994714739463168905443499424551362424437245880253267329605556587274644733\", \"price\":\"0.6\", \"size\":\"102.2\", \"side\":\"BUY\", \"hash\":\"8c73a03e72f09d41c13c3843fc9cfab5c6e0e4cb\", \"best_bid\":\"0.61\", \"best_ask\":\"0.62\"}, {\"asset_id\":\"20893381255801015515826997628594359667013752732428989472914000440642900266717\", \"price\":\"0.4\", \"size\":\"102.2\", \"side\":\"SELL\", \"hash\":\"5eeabc3214bb6b511435377da622138a9317be42\", \"best_bid\":\"0.38\", \"best_ask\":\"0.39\"}], \"timestamp\":\"1785204061644\", \"event_type\":\"price_change\"}","received_at":"2026-07-28T02:01:09.101962Z","schema_version":"clob-market-ws.price_change.v1","sequence":null,"server_hash":null,"server_timestamp":"1785204061644","session_id":"d2757dd6dad94f3b9fe67e8dbf1adc37","source":"clob_market_ws"},"received_at":"2026-07-28T02:01:09.101962Z","record_id":"4c9e059059b29fb68d8f03f71c4aeb42abe79e60e724c3b379dcd4e9d8e891dc","schema_fingerprint":"4aa3821a28b0b7c2400bc59aba4bcc0a76e971dadd19610d3ad38c768e124dc7","schema_version":"edge-lab-recorder.raw.v1","sequence":null,"source":"clob_market_ws"}
{"event_at":"2026-07-28T02:01:01.644000Z","event_fingerprint":"11354cbed937bd936b2da0a394f1c38f6c6bf0d0b557f9c27acaa52113933386","payload":{"connection_id":"5d29200f65794d4d9ab6ef271f045a9b","event_at":"2026-07-28T02:01:01.644000Z","event_type":"price_change","frame_hash":"871c5d9c189df5cf4367f2313f5b37e65a69d9bbeb06e3ca73820e10c96bc00e","frame_index":0,"kind":"data","monotonic_ns":306052111082541,"payload":{"event_type":"price_change","market":"0xda6f0e0e93fc8469e0159a166028d017bddbc162b86f66bac90391379603d962","price_changes":[{"asset_id":"20893381255801015515826997628594359667013752732428989472914000440642900266717","best_ask":"0.39","best_bid":"0.38","hash":"5d7a597a4ed5f624f1103c3980ea0924b4f11ec1","price":"0.31","side":"BUY","size":"157"},{"asset_id":"39272994714739463168905443499424551362424437245880253267329605556587274644733","best_ask":"0.62","best_bid":"0.61","hash":"294ea9c570564182379640def871b1776aabd5b4","price":"0.69","side":"SELL","size":"157"}],"timestamp":"1785204061644"},"payload_hash":"db51045d50da978bda4a43fb78d4f607e2089af97e19c3ae7691e1e75373c586","raw_frame":"{\"market\":\"0xda6f0e0e93fc8469e0159a166028d017bddbc162b86f66bac90391379603d962\", \"price_changes\":[{\"asset_id\":\"20893381255801015515826997628594359667013752732428989472914000440642900266717\", \"price\":\"0.31\", \"size\":\"157\", \"side\":\"BUY\", \"hash\":\"5d7a597a4ed5f624f1103c3980ea0924b4f11ec1\", \"best_bid\":\"0.38\", \"best_ask\":\"0.39\"}, {\"asset_id\":\"39272994714739463168905443499424551362424437245880253267329605556587274644733\", \"price\":\"0.69\", \"size\":\"157\", \"side\":\"SELL\", \"hash\":\"294ea9c570564182379640def871b1776aabd5b4\", \"best_bid\":\"0.61\", \"best_ask\":\"0.62\"}], \"timestamp\":\"1785204061644\", \"event_type\":\"price_change\"}","received_at":"2026-07-28T02:01:09.107137Z","schema_version":"clob-market-ws.price_change.v1","sequence":null,"server_hash":null,"server_timestamp":"1785204061644","session_id":"d2757dd6dad94f3b9fe67e8dbf1adc37","source":"clob_market_ws"},"received_at":"2026-07-28T02:01:09.107137Z","record_id":"8f15e4d710f0b33d56e84f0689d6befcaf2844403a277316a7bae0fed36f9737","schema_fingerprint":"4aa3821a28b0b7c2400bc59aba4bcc0a76e971dadd19610d3ad38c768e124dc7","schema_version":"edge-lab-recorder.raw.v1","sequence":null,"source":"clob_market_ws"}
{"event_at":"2026-07-28T02:01:01.644000Z","event_fingerprint":"7b4f3ba8acf74f504229bfe79eda99fd784a0860861dcf3f9e584c1e1fc3527e","payload":{"connection_id":"5d29200f65794d4d9ab6ef271f045a9b","event_at":"2026-07-28T02:01:01.644000Z","event_type":"price_change","frame_hash":"72d21539e0b26978e3d256c61e7183651581dee0878b8c54ddb667ba9f24aa61","frame_index":0,"kind":"data","monotonic_ns":306052117774208,"payload":{"event_type":"price_change","market":"0xda6f0e0e93fc8469e0159a166028d017bddbc162b86f66bac90391379603d962","price_changes":[{"asset_id":"39272994714739463168905443499424551362424437245880253267329605556587274644733","best_ask":"0.62","best_bid":"0.61","hash":"72be626a2170b6ebfc373e4010de1e0d9d25acd5","price":"0.6","side":"BUY","size":"89.6"},{"asset_id":"20893381255801015515826997628594359667013752732428989472914000440642900266717","best_ask":"0.39","best_bid":"0.38","hash":"6f41b841cea1833acf76284beb6e28baffab06dd","price":"0.4","side":"SELL","size":"89.6"}],"timestamp":"1785204061644"},"payload_hash":"5ed0e8b09acba821db502e938529a64fb7868dd11fef01660ea092e2c5f8ad76","raw_frame":"{\"market\":\"0xda6f0e0e93fc8469e0159a166028d017bddbc162b86f66bac90391379603d962\", \"price_changes\":[{\"asset_id\":\"39272994714739463168905443499424551362424437245880253267329605556587274644733\", \"price\":\"0.6\", \"size\":\"89.6\", \"side\":\"BUY\", \"hash\":\"72be626a2170b6ebfc373e4010de1e0d9d25acd5\", \"best_bid\":\"0.61\", \"best_ask\":\"0.62\"}, {\"asset_id\":\"20893381255801015515826997628594359667013752732428989472914000440642900266717\", \"price\":\"0.4\", \"size\":\"89.6\", \"side\":\"SELL\", \"hash\":\"6f41b841cea1833acf76284beb6e28baffab06dd\", \"best_bid\":\"0.38\", \"best_ask\":\"0.39\"}], \"timestamp\":\"1785204061644\", \"event_type\":\"price_change\"}","received_at":"2026-07-28T02:01:09.113828Z","schema_version":"clob-market-ws.price_change.v1","sequence":null,"server_hash":null,"server_timestamp":"1785204061644","session_id":"d2757dd6dad94f3b9fe67e8dbf1adc37","source":"clob_market_ws"},"received_at":"2026-07-28T02:01:09.113828Z","record_id":"773f5dde5860cbd58fa4afc1329b94bafcb76c87550b2d7b109f69b9200dacc8","schema_fingerprint":"4aa3821a28b0b7c2400bc59aba4bcc0a76e971dadd19610d3ad38c768e124dc7","schema_version":"edge-lab-recorder.raw.v1","sequence":null,"source":"clob_market_ws"}
{"event_at":"2026-07-28T02:01:01.645000Z","event_fingerprint":"e59e18075400f401a4534455f3b365a447501d300c477cb6e19f0a63f6bea84a","payload":{"connection_id":"5d29200f65794d4d9ab6ef271f045a9b","event_at":"2026-07-28T02:01:01.645000Z","event_type":"price_change","frame_hash":"3841e447d88fddd06eee27bac0b78da78009ad9e8057a0bf1cdcc6c61a6c8f42","frame_index":0,"kind":"data","monotonic_ns":306052122865125,"payload":{"event_type":"price_change","market":"0xda6f0e0e93fc8469e0159a166028d017bddbc162b86f66bac90391379603d962","price_changes":[{"asset_id":"20893381255801015515826997628594359667013752732428989472914000440642900266717","best_ask":"0.39","best_bid":"0.38","hash":"b0b57b0f008f63eeb021f066587df46ed53ea042","price":"0.36","side":"BUY","size":"77.6"},{"asset_id":"39272994714739463168905443499424551362424437245880253267329605556587274644733","best_ask":"0.62","best_bid":"0.61","hash":"bd1737ca4c1e59db975b3149721667bf109a4cf9","price":"0.64","side":"SELL","size":"77.6"}],"timestamp":"1785204061645"},"payload_hash":"266e17dfbb74e7d8bf3c2a0a15233ef235ee871bbb6a28484323ae8e07a67a31","raw_frame":"{\"market\":\"0xda6f0e0e93fc8469e0159a166028d017bddbc162b86f66bac90391379603d962\", \"price_changes\":[{\"asset_id\":\"20893381255801015515826997628594359667013752732428989472914000440642900266717\", \"price\":\"0.36\", \"size\":\"77.6\", \"side\":\"BUY\", \"hash\":\"b0b57b0f008f63eeb021f066587df46ed53ea042\", \"best_bid\":\"0.38\", \"best_ask\":\"0.39\"}, {\"asset_id\":\"39272994714739463168905443499424551362424437245880253267329605556587274644733\", \"price\":\"0.64\", \"size\":\"77.6\", \"side\":\"SELL\", \"hash\":\"bd1737ca4c1e59db975b3149721667bf109a4cf9\", \"best_bid\":\"0.61\", \"best_ask\":\"0.62\"}], \"timestamp\":\"1785204061645\", \"event_type\":\"price_change\"}","received_at":"2026-07-28T02:01:09.118919Z","schema_version":"clob-market-ws.price_change.v1","sequence":null,"server_hash":null,"server_timestamp":"1785204061645","session_id":"d2757dd6dad94f3b9fe67e8dbf1adc37","source":"clob_market_ws"},"received_at":"2026-07-28T02:01:09.118919Z","record_id":"e0eec993b066a723afb546c1219bcbc435e88bb28a0f16e25c568b3a37c53add","schema_fingerprint":"4aa3821a28b0b7c2400bc59aba4bcc0a76e971dadd19610d3ad38c768e124dc7","schema_version":"edge-lab-recorder.raw.v1","sequence":null,"source":"clob_market_ws"}
{"event_at":"2026-07-28T02:01:01.648000Z","event_fingerprint":"25954b095640c19c6cbb1d780ba680b4028199c48bd137a8e82757367df23ca7","payload":{"connection_id":"5d29200f65794d4d9ab6ef271f045a9b","event_at":"2026-07-28T02:01:01.648000Z","event_type":"price_change","frame_hash":"d3b7338162741e1d80c1395d33cdff324fda1eb83efb324e26fe3a858d28cd74","frame_index":0,"kind":"data","monotonic_ns":306052133543583,"payload":{"event_type":"price_change","market":"0xda6f0e0e93fc8469e0159a166028d017bddbc162b86f66bac90391379603d962","price_changes":[{"asset_id":"39272994714739463168905443499424551362424437245880253267329605556587274644733","best_ask":"0.62","best_bid":"0.61","hash":"08338d1d04690327bfd05527e5a2a95804ce8965","price":"0.61","side":"BUY","size":"63"},{"asset_id":"20893381255801015515826997628594359667013752732428989472914000440642900266717","best_ask":"0.39","best_bid":"0.38","hash":"496c09ba6811c4efbb6ae0b86d5af9ea0b94f5c4","price":"0.39","side":"SELL","size":"63"}],"timestamp":"1785204061648"},"payload_hash":"ce7d2f220096ce978871b8af8e211c96831571eec6526c13946252dd03e8520a","raw_frame":"{\"market\":\"0xda6f0e0e93fc8469e0159a166028d017bddbc162b86f66bac90391379603d962\", \"price_changes\":[{\"asset_id\":\"39272994714739463168905443499424551362424437245880253267329605556587274644733\", \"price\":\"0.61\", \"size\":\"63\", \"side\":\"BUY\", \"hash\":\"08338d1d04690327bfd05527e5a2a95804ce8965\", \"best_bid\":\"0.61\", \"best_ask\":\"0.62\"}, {\"asset_id\":\"20893381255801015515826997628594359667013752732428989472914000440642900266717\", \"price\":\"0.39\", \"size\":\"63\", \"side\":\"SELL\", \"hash\":\"496c09ba6811c4efbb6ae0b86d5af9ea0b94f5c4\", \"best_bid\":\"0.38\", \"best_ask\":\"0.39\"}], \"timestamp\":\"1785204061648\", \"event_type\":\"price_change\"}","received_at":"2026-07-28T02:01:09.129593Z","schema_version":"clob-market-ws.price_change.v1","sequence":null,"server_hash":null,"server_timestamp":"1785204061648","session_id":"d2757dd6dad94f3b9fe67e8dbf1adc37","source":"clob_market_ws"},"received_at":"2026-07-28T02:01:09.129593Z","record_id":"cac13db19ed5188792c0229ef6c19e5e67a39be2b68ed7464e03c3e278dbfa5f","schema_fingerprint":"4aa3821a28b0b7c2400bc59aba4bcc0a76e971dadd19610d3ad38c768e124dc7","schema_version":"edge-lab-recorder.raw.v1","sequence":null,"source":"clob_market_ws"}
{"event_at":"2026-07-28T02:01:01.648000Z","event_fingerprint":"03bff973b772e99eb649b42668e1c45aebc4a1d75c080a1e2fafaabea06fc161","payload":{"connection_id":"5d29200f65794d4d9ab6ef271f045a9b","event_at":"2026-07-28T02:01:01.648000Z","event_type":"price_change","frame_hash":"e72e0dfff94bc8df01f87d76409d9d9bf5aa417bc6a98b3abcc223da8962390d","frame_index":0,"kind":"data","monotonic_ns":306052141123541,"payload":{"event_type":"price_change","market":"0xda6f0e0e93fc8469e0159a166028d017bddbc162b86f66bac90391379603d962","price_changes":[{"asset_id":"20893381255801015515826997628594359667013752732428989472914000440642900266717","best_ask":"0.39","best_bid":"0.38","hash":"cc96a01ef2dce0a802054ee44f2ba1e686e90484","price":"0.39","side":"SELL","size":"68"},{"asset_id":"39272994714739463168905443499424551362424437245880253267329605556587274644733","best_ask":"0.62","best_bid":"0.61","hash":"c1db92c1d40fde40a0bd07087a05892b9d3300d2","price":"0.61","side":"BUY","size":"68"}],"timestamp":"1785204061648"},"payload_hash":"8652f568f1116d95fb5b5a888959dc1fe26b358c6c90098a0a5ffa7c5a31c3a2","raw_frame":"{\"market\":\"0xda6f0e0e93fc8469e0159a166028d017bddbc162b86f66bac90391379603d962\", \"price_changes\":[{\"asset_id\":\"20893381255801015515826997628594359667013752732428989472914000440642900266717\", \"price\":\"0.39\", \"size\":\"68\", \"side\":\"SELL\", \"hash\":\"cc96a01ef2dce0a802054ee44f2ba1e686e90484\", \"best_bid\":\"0.38\", \"best_ask\":\"0.39\"}, {\"asset_id\":\"39272994714739463168905443499424551362424437245880253267329605556587274644733\", \"price\":\"0.61\", \"size\":\"68\", \"side\":\"BUY\", \"hash\":\"c1db92c1d40fde40a0bd07087a05892b9d3300d2\", \"best_bid\":\"0.61\", \"best_ask\":\"0.62\"}], \"timestamp\":\"1785204061648\", \"event_type\":\"price_change\"}","received_at":"2026-07-28T02:01:09.137177Z","schema_version":"clob-market-ws.price_change.v1","sequence":null,"server_hash":null,"server_timestamp":"1785204061648","session_id":"d2757dd6dad94f3b9fe67e8dbf1adc37","source":"clob_market_ws"},"received_at":"2026-07-28T02:01:09.137177Z","record_id":"8b3d610f3eb6a48183b91d4e87ffa3f2c6db734bb190897695d67ce46e7eebac","schema_fingerprint":"4aa3821a28b0b7c2400bc59aba4bcc0a76e971dadd19610d3ad38c768e124dc7","schema_version":"edge-lab-recorder.raw.v1","sequence":null,"source":"clob_market_ws"}
{"event_at":"2026-07-28T02:01:01.649000Z","event_fingerprint":"f4b773026075e3d7b0f5de134f2bbae7cd86fca86f846c8d205ade8e74303e86","payload":{"connection_id":"5d29200f65794d4d9ab6ef271f045a9b","event_at":"2026-07-28T02:01:01.649000Z","event_type":"price_change","frame_hash":"d38da3048777d1f181320bcbb92716987a14575aace9151ab72930f95148e3c5","frame_index":0,"kind":"data","monotonic_ns":306052146512458,"payload":{"event_type":"price_change","market":"0xda6f0e0e93fc8469e0159a166028d017bddbc162b86f66bac90391379603d962","price_changes":[{"asset_id":"20893381255801015515826997628594359667013752732428989472914000440642900266717","best_ask":"0.39","best_bid":"0.38","hash":"5921f146715b0935045d61fffc96fd76a7f78bcf","price":"0.37","side":"BUY","size":"314"},{"asset_id":"39272994714739463168905443499424551362424437245880253267329605556587274644733","best_ask":"0.62","best_bid":"0.61","hash":"41da0c650614526238f6c98e35e2dea23807a8d6","price":"0.63","side":"SELL","size":"314"}],"timestamp":"1785204061649"},"payload_hash":"1183f0b0b0f1f109dd78fbf33a8e5d63c18d3721d0be9853c6cb32156c564b40","raw_frame":"{\"market\":\"0xda6f0e0e93fc8469e0159a166028d017bddbc162b86f66bac90391379603d962\", \"price_changes\":[{\"asset_id\":\"20893381255801015515826997628594359667013752732428989472914000440642900266717\", \"price\":\"0.37\", \"size\":\"314\", \"side\":\"BUY\", \"hash\":\"5921f146715b0935045d61fffc96fd76a7f78bcf\", \"best_bid\":\"0.38\", \"best_ask\":\"0.39\"}, {\"asset_id\":\"39272994714739463168905443499424551362424437245880253267329605556587274644733\", \"price\":\"0.63\", \"size\":\"314\", \"side\":\"SELL\", \"hash\":\"41da0c650614526238f6c98e35e2dea23807a8d6\", \"best_bid\":\"0.61\", \"best_ask\":\"0.62\"}], \"timestamp\":\"1785204061649\", \"event_type\":\"price_change\"}","received_at":"2026-07-28T02:01:09.142566Z","schema_version":"clob-market-ws.price_change.v1","sequence":null,"server_hash":null,"server_timestamp":"1785204061649","session_id":"d2757dd6dad94f3b9fe67e8dbf1adc37","source":"clob_market_ws"},"received_at":"2026-07-28T02:01:09.142566Z","record_id":"73abb2e44c8d29da10a029a3836c7f77c1b83ace34273dee4be70306c58a600f","schema_fingerprint":"4aa3821a28b0b7c2400bc59aba4bcc0a76e971dadd19610d3ad38c768e124dc7","schema_version":"edge-lab-recorder.raw.v1","sequence":null,"source":"clob_market_ws"}
{"event_at":"2026-07-28T02:01:01.650000Z","event_fingerprint":"fdf81f176c29d5ec0539ae15a3ebb4aa15b16889cf4acaeda3123986a45c2300","payload":{"connection_id":"5d29200f65794d4d9ab6ef271f045a9b","event_at":"2026-07-28T02:01:01.650000Z","event_type":"price_change","frame_hash":"dfbbc18c6bb2054282573a0412a881fac8422005b30264e05c74ff93a351b907","frame_index":0,"kind":"data","monotonic_ns":306052159250791,"payload":{"event_type":"price_change","market":"0xda6f0e0e93fc8469e0159a166028d017bddbc162b86f66bac90391379603d962","price_changes":[{"asset_id":"39272994714739463168905443499424551362424437245880253267329605556587274644733","best_ask":"0.62","best_bid":"0.61","hash":"bde63e30781e1ec1e3ada2b3c12b6a601efe32db","price":"0.61","side":"BUY","size":"80.6"},{"asset_id":"20893381255801015515826997628594359667013752732428989472914000440642900266717","best_ask":"0.39","best_bid":"0.38","hash":"9bd2379f3411d56c0ba0ff7e04dc11f510574913","price":"0.39","side":"SELL","size":"80.6"}],"timestamp":"1785204061650"},"payload_hash":"404e16bc193f63edf8d4893df6e40a554369ff9756616eaff880c749cd605999","raw_frame":"{\"market\":\"0xda6f0e0e93fc8469e0159a166028d017bddbc162b86f66bac90391379603d962\", \"price_changes\":[{\"asset_id\":\"39272994714739463168905443499424551362424437245880253267329605556587274644733\", \"price\":\"0.61\", \"size\":\"80.6\", \"side\":\"BUY\", \"hash\":\"bde63e30781e1ec1e3ada2b3c12b6a601efe32db\", \"best_bid\":\"0.61\", \"best_ask\":\"0.62\"}, {\"asset_id\":\"20893381255801015515826997628594359667013752732428989472914000440642900266717\", \"price\":\"0.39\", \"size\":\"80.6\", \"side\":\"SELL\", \"hash\":\"9bd2379f3411d56c0ba0ff7e04dc11f510574913\", \"best_bid\":\"0.38\", \"best_ask\":\"0.39\"}], \"timestamp\":\"1785204061650\", \"event_type\":\"price_change\"}","received_at":"2026-07-28T02:01:09.155303Z","schema_version":"clob-market-ws.price_change.v1","sequence":null,"server_hash":null,"server_timestamp":"1785204061650","session_id":"d2757dd6dad94f3b9fe67e8dbf1adc37","source":"clob_market_ws"},"received_at":"2026-07-28T02:01:09.155303Z","record_id":"1c643fa7365678f0544b27f8ffacb04311e14f82a19e4e4b377c0cb87b6349e6","schema_fingerprint":"4aa3821a28b0b7c2400bc59aba4bcc0a76e971dadd19610d3ad38c768e124dc7","schema_version":"edge-lab-recorder.raw.v1","sequence":null,"source":"clob_market_ws"}
{"event_at":"2026-07-28T02:01:01.651000Z","event_fingerprint":"6fa6d801f863e167005a224d7534a9bb808890b76b6658e461650dc6d16107ac","payload":{"connection_id":"5d29200f65794d4d9ab6ef271f045a9b","event_at":"2026-07-28T02:01:01.651000Z","event_type":"price_change","frame_hash":"9c19fee31756615baba240047eb46b03f77e77f580ed313417f5564be6554493","frame_index":0,"kind":"data","monotonic_ns":306052164270375,"payload":{"event_type":"price_change","market":"0xda6f0e0e93fc8469e0159a166028d017bddbc162b86f66bac90391379603d962","price_changes":[{"asset_id":"39272994714739463168905443499424551362424437245880253267329605556587274644733","best_ask":"0.62","best_bid":"0.61","hash":"5b619f8d5cc4f425682c2e12d9e32a5474288e17","price":"0.61","side":"BUY","size":"93.2"},{"asset_id":"20893381255801015515826997628594359667013752732428989472914000440642900266717","best_ask":"0.39","best_bid":"0.38","hash":"61eb239aeb66b51e8abf4105713c955d4af98229","price":"0.39","side":"SELL","size":"93.2"}],"timestamp":"1785204061651"},"payload_hash":"4a2cb4d7853bf760bdf3bbaad31efa85860b6bc62b892025df57094caee804ff","raw_frame":"{\"market\":\"0xda6f0e0e93fc8469e0159a166028d017bddbc162b86f66bac90391379603d962\", \"price_changes\":[{\"asset_id\":\"39272994714739463168905443499424551362424437245880253267329605556587274644733\", \"price\":\"0.61\", \"size\":\"93.2\", \"side\":\"BUY\", \"hash\":\"5b619f8d5cc4f425682c2e12d9e32a5474288e17\", \"best_bid\":\"0.61\", \"best_ask\":\"0.62\"}, {\"asset_id\":\"20893381255801015515826997628594359667013752732428989472914000440642900266717\", \"price\":\"0.39\", \"size\":\"93.2\", \"side\":\"SELL\", \"hash\":\"61eb239aeb66b51e8abf4105713c955d4af98229\", \"best_bid\":\"0.38\", \"best_ask\":\"0.39\"}], \"timestamp\":\"1785204061651\", \"event_type\":\"price_change\"}","received_at":"2026-07-28T02:01:09.160324Z","schema_version":"clob-market-ws.price_change.v1","sequence":null,"server_hash":null,"server_timestamp":"1785204061651","session_id":"d2757dd6dad94f3b9fe67e8dbf1adc37","source":"clob_market_ws"},"received_at":"2026-07-28T02:01:09.160324Z","record_id":"d8b7c5511e0c9a78a9ad600da2efc31f08cf868c9a914453cea7c9ff51b521d4","schema_fingerprint":"4aa3821a28b0b7c2400bc59aba4bcc0a76e971dadd19610d3ad38c768e124dc7","schema_version":"edge-lab-recorder.raw.v1","sequence":null,"source":"clob_market_ws"}
{"event_at":"2026-07-28T02:01:01.652000Z","event_fingerprint":"aa01adc52811f29ec9d3de00ca248ec25ae0b05e900aa74c259a978ab144c0c5","payload":{"connection_id":"5d29200f65794d4d9ab6ef271f045a9b","event_at":"2026-07-28T02:01:01.652000Z","event_type":"price_change","frame_hash":"3af2e1178b6df071b75721eb00b8e73335c5c00b453387c8872e95fa61864f7c","frame_index":0,"kind":"data","monotonic_ns":306052169948583,"payload":{"event_type":"price_change","market":"0xda6f0e0e93fc8469e0159a166028d017bddbc162b86f66bac90391379603d962","price_changes":[{"asset_id":"20893381255801015515826997628594359667013752732428989472914000440642900266717","best_ask":"0.39","best_bid":"0.38","hash":"b94f77b358ac821d673b0f825481bbaa1c82ba9a","price":"0.37","side":"BUY","size":"44"},{"asset_id":"39272994714739463168905443499424551362424437245880253267329605556587274644733","best_ask":"0.62","best_bid":"0.61","hash":"e58bc86dd0a5932bc0a949771f48e514c80e937f","price":"0.63","side":"SELL","size":"44"}],"timestamp":"1785204061652"},"payload_hash":"d15c85c241f1ad55c132cab853cae13efa83b9cfe67a7a3a5bab5a4d810bdab5","raw_frame":"{\"market\":\"0xda6f0e0e93fc8469e0159a166028d017bddbc162b86f66bac90391379603d962\", \"price_changes\":[{\"asset_id\":\"20893381255801015515826997628594359667013752732428989472914000440642900266717\", \"price\":\"0.37\", \"size\":\"44\", \"side\":\"BUY\", \"hash\":\"b94f77b358ac821d673b0f825481bbaa1c82ba9a\", \"best_bid\":\"0.38\", \"best_ask\":\"0.39\"}, {\"asset_id\":\"39272994714739463168905443499424551362424437245880253267329605556587274644733\", \"price\":\"0.63\", \"size\":\"44\", \"side\":\"SELL\", \"hash\":\"e58bc86dd0a5932bc0a949771f48e514c80e937f\", \"best_bid\":\"0.61\", \"best_ask\":\"0.62\"}], \"timestamp\":\"1785204061652\", \"event_type\":\"price_change\"}","received_at":"2026-07-28T02:01:09.166002Z","schema_version":"clob-market-ws.price_change.v1","sequence":null,"server_hash":null,"server_timestamp":"1785204061652","session_id":"d2757dd6dad94f3b9fe67e8dbf1adc37","source":"clob_market_ws"},"received_at":"2026-07-28T02:01:09.166002Z","record_id":"ece76691c1642287cb9e28a4ecc3383cf62bcc3dc35c2166330028ce9468d88c","schema_fingerprint":"4aa3821a28b0b7c2400bc59aba4bcc0a76e971dadd19610d3ad38c768e124dc7","schema_version":"edge-lab-recorder.raw.v1","sequence":null,"source":"clob_market_ws"}
{"event_at":"2026-07-28T02:01:01.652000Z","event_fingerprint":"37fbbe8de633a3ddd6831269d441f80a35b99ee98cf50a60f54d24372df1ab6d","payload":{"connection_id":"5d29200f65794d4d9ab6ef271f045a9b","event_at":"2026-07-28T02:01:01.652000Z","event_type":"price_change","frame_hash":"2b214e0599c586f6618e2864c74751e9fef9281b1462ff251fe67482666aa431","frame_index":0,"kind":"data","monotonic_ns":306052176370833,"payload":{"event_type":"price_change","market":"0xda6f0e0e93fc8469e0159a166028d017bddbc162b86f66bac90391379603d962","price_changes":[{"asset_id":"20893381255801015515826997628594359667013752732428989472914000440642900266717","best_ask":"0.39","best_bid":"0.38","hash":"179f2b7c106ca697212c4c68c359d0e594a5b04a","price":"0.34","side":"BUY","size":"130"},{"asset_id":"39272994714739463168905443499424551362424437245880253267329605556587274644733","best_ask":"0.62","best_bid":"0.61","hash":"eb7e03bfa32fef575bb9be7b45234776eefdab0d","price":"0.66","side":"SELL","size":"130"}],"timestamp":"1785204061652"},"payload_hash":"e5d5a78ce7041cff76adbb5feb32147913bf4f875513cf53f8a160a1dbb28338","raw_frame":"{\"market\":\"0xda6f0e0e93fc8469e0159a166028d017bddbc162b86f66bac90391379603d962\", \"price_changes\":[{\"asset_id\":\"20893381255801015515826997628594359667013752732428989472914000440642900266717\", \"price\":\"0.34\", \"size\":\"130\", \"side\":\"BUY\", \"hash\":\"179f2b7c106ca697212c4c68c359d0e594a5b04a\", \"best_bid\":\"0.38\", \"best_ask\":\"0.39\"}, {\"asset_id\":\"39272994714739463168905443499424551362424437245880253267329605556587274644733\", \"price\":\"0.66\", \"size\":\"130\", \"side\":\"SELL\", \"hash\":\"eb7e03bfa32fef575bb9be7b45234776eefdab0d\", \"best_bid\":\"0.61\", \"best_ask\":\"0.62\"}], \"timestamp\":\"1785204061652\", \"event_type\":\"price_change\"}","received_at":"2026-07-28T02:01:09.172424Z","schema_version":"clob-market-ws.price_change.v1","sequence":null,"server_hash":null,"server_timestamp":"1785204061652","session_id":"d2757dd6dad94f3b9fe67e8dbf1adc37","source":"clob_market_ws"},"received_at":"2026-07-28T02:01:09.172424Z","record_id":"2f3d9a303cc017c516450d26f6b3551bd8e3959f16787774d7927764c24b26d0","schema_fingerprint":"4aa3821a28b0b7c2400bc59aba4bcc0a76e971dadd19610d3ad38c768e124dc7","schema_version":"edge-lab-recorder.raw.v1","sequence":null,"source":"clob_market_ws"}
{"event_at":"2026-07-28T02:01:01.653000Z","event_fingerprint":"74ab38cbecc50b5b212024b507f5ecb685da0b61d067a4480edc4b6e97e4f6e3","payload":{"connection_id":"5d29200f65794d4d9ab6ef271f045a9b","event_at":"2026-07-28T02:01:01.653000Z","event_type":"price_change","frame_hash":"270dd995855acb633fcdb31ae67531489319d064f329a2fdfb374e3296df4ceb","frame_index":0,"kind":"data","monotonic_ns":306052181536208,"payload":{"event_type":"price_change","market":"0xda6f0e0e93fc8469e0159a166028d017bddbc162b86f66bac90391379603d962","price_changes":[{"asset_id":"39272994714739463168905443499424551362424437245880253267329605556587274644733","best_ask":"0.62","best_bid":"0.61","hash":"ff3b34278e549c0bd3f62d34eed4f80e754cdb98","price":"0.56","side":"BUY","size":"102.14"},{"asset_id":"20893381255801015515826997628594359667013752732428989472914000440642900266717","best_ask":"0.39","best_bid":"0.38","hash":"6059fba50b27f10ce60806b6387682ee329ce2e0","price":"0.44","side":"SELL","size":"102.14"}],"timestamp":"1785204061653"},"payload_hash":"ea92a9219ea9673def08ca17aeb4527ac6c989c6271f703859b86ac849a76248","raw_frame":"{\"market\":\"0xda6f0e0e93fc8469e0159a166028d017bddbc162b86f66bac90391379603d962\", \"price_changes\":[{\"asset_id\":\"39272994714739463168905443499424551362424437245880253267329605556587274644733\", \"price\":\"0.56\", \"size\":\"102.14\", \"side\":\"BUY\", \"hash\":\"ff3b34278e549c0bd3f62d34eed4f80e754cdb98\", \"best_bid\":\"0.61\", \"best_ask\":\"0.62\"}, {\"asset_id\":\"20893381255801015515826997628594359667013752732428989472914000440642900266717\", \"price\":\"0.44\", \"size\":\"102.14\", \"side\":\"SELL\", \"hash\":\"6059fba50b27f10ce60806b6387682ee329ce2e0\", \"best_bid\":\"0.38\", \"best_ask\":\"0.39\"}], \"timestamp\":\"1785204061653\", \"event_type\":\"price_change\"}","received_at":"2026-07-28T02:01:09.177589Z","schema_version":"clob-market-ws.price_change.v1","sequence":null,"server_hash":null,"server_timestamp":"1785204061653","session_id":"d2757dd6dad94f3b9fe67e8dbf1adc37","source":"clob_market_ws"},"received_at":"2026-07-28T02:01:09.177589Z","record_id":"8d5f045c7a1f94e34a5ce0c55264fca01cd8f513797a89c00ef97a40927bc52f","schema_fingerprint":"4aa3821a28b0b7c2400bc59aba4bcc0a76e971dadd19610d3ad38c768e124dc7","schema_version":"edge-lab-recorder.raw.v1","sequence":null,"source":"clob_market_ws"}
{"event_at":"2026-07-28T02:01:01.655000Z","event_fingerprint":"e6fd6144619d5fcd1c8d132ceb11beaae31a8336861a45f66756530fb06556ab","payload":{"connection_id":"5d29200f65794d4d9ab6ef271f045a9b","event_at":"2026-07-28T02:01:01.655000Z","event_type":"price_change","frame_hash":"36c7b20ee6a12950319c573c86897b34aecae712d5f21668bfdeef5a0c39cd8a","frame_index":0,"kind":"data","monotonic_ns":306052187014791,"payload":{"event_type":"price_change","market":"0xda6f0e0e93fc8469e0159a166028d017bddbc162b86f66bac90391379603d962","price_changes":[{"asset_id":"39272994714739463168905443499424551362424437245880253267329605556587274644733","best_ask":"0.62","best_bid":"0.61","hash":"5c26c618e7d1a259c645f1e9ec2fa260696ea493","price":"0.61","side":"BUY","size":"98.2"},{"asset_id":"20893381255801015515826997628594359667013752732428989472914000440642900266717","best_ask":"0.39","best_bid":"0.38","hash":"422ded01afae250efe8da631c1c4bbc91199d5fd","price":"0.39","side":"SELL","size":"98.2"}],"timestamp":"1785204061655"},"payload_hash":"50807409a994bcc2a88d138648d045e2cd1cc96607954cd5f3154ee47fdc1d38","raw_frame":"{\"market\":\"0xda6f0e0e93fc8469e0159a166028d017bddbc162b86f66bac90391379603d962\", \"price_changes\":[{\"asset_id\":\"39272994714739463168905443499424551362424437245880253267329605556587274644733\", \"price\":\"0.61\", \"size\":\"98.2\", \"side\":\"BUY\", \"hash\":\"5c26c618e7d1a259c645f1e9ec2fa260696ea493\", \"best_bid\":\"0.61\", \"best_ask\":\"0.62\"}, {\"asset_id\":\"20893381255801015515826997628594359667013752732428989472914000440642900266717\", \"price\":\"0.39\", \"size\":\"98.2\", \"side\":\"SELL\", \"hash\":\"422ded01afae250efe8da631c1c4bbc91199d5fd\", \"best_bid\":\"0.38\", \"best_ask\":\"0.39\"}], \"timestamp\":\"1785204061655\", \"event_type\":\"price_change\"}","received_at":"2026-07-28T02:01:09.183069Z","schema_version":"clob-market-ws.price_change.v1","sequence":null,"server_hash":null,"server_timestamp":"1785204061655","session_id":"d2757dd6dad94f3b9fe67e8dbf1adc37","source":"clob_market_ws"},"received_at":"2026-07-28T02:01:09.183069Z","record_id":"92c5fd63f7108a4327e48ce743013390c4853d82a7ea8805eec9d2eb2d2088b2","schema_fingerprint":"4aa3821a28b0b7c2400bc59aba4bcc0a76e971dadd19610d3ad38c768e124dc7","schema_version":"edge-lab-recorder.raw.v1","sequence":null,"source":"clob_market_ws"}
{"event_at":"2026-07-28T02:01:01.657000Z","event_fingerprint":"693415a6c8f7c79e797a8d4ea1ab8bced7e41267d08fb0579f01730227f3fdca","payload":{"connection_id":"5d29200f65794d4d9ab6ef271f045a9b","event_at":"2026-07-28T02:01:01.657000Z","event_type":"price_change","frame_hash":"a1dcba1e0643b1b93d84cf781d83d37946fac3ba3ea8ca92753247d8856c7fbe","frame_index":0,"kind":"data","monotonic_ns":306052191930875,"payload":{"event_type":"price_change","market":"0xda6f0e0e93fc8469e0159a166028d017bddbc162b86f66bac90391379603d962","price_changes":[{"asset_id":"20893381255801015515826997628594359667013752732428989472914000440642900266717","best_ask":"0.39","best_bid":"0.38","hash":"b408159ac4304fe1d5c8df2934baab347d8a0e4f","price":"0.36","side":"BUY","size":"62.6"},{"asset_id":"39272994714739463168905443499424551362424437245880253267329605556587274644733","best_ask":"0.62","best_bid":"0.61","hash":"74b3e04f561bcc20eadadd8143f4cd1ca3bc2059","price":"0.64","side":"SELL","size":"62.6"}],"timestamp":"1785204061657"},"payload_hash":"dc38370ffb2c301a74c4abf214104c4656a7887acc0a0aa9281bb78bf11e41cc","raw_frame":"{\"market\":\"0xda6f0e0e93fc8469e0159a166028d017bddbc162b86f66bac90391379603d962\", \"price_changes\":[{\"asset_id\":\"20893381255801015515826997628594359667013752732428989472914000440642900266717\", \"price\":\"0.36\", \"size\":\"62.6\", \"side\":\"BUY\", \"hash\":\"b408159ac4304fe1d5c8df2934baab347d8a0e4f\", \"best_bid\":\"0.38\", \"best_ask\":\"0.39\"}, {\"asset_id\":\"39272994714739463168905443499424551362424437245880253267329605556587274644733\", \"price\":\"0.64\", \"size\":\"62.6\", \"side\":\"SELL\", \"hash\":\"74b3e04f561bcc20eadadd8143f4cd1ca3bc2059\", \"best_bid\":\"0.61\", \"best_ask\":\"0.62\"}], \"timestamp\":\"1785204061657\", \"event_type\":\"price_change\"}","received_at":"2026-07-28T02:01:09.187984Z","schema_version":"clob-market-ws.price_change.v1","sequence":null,"server_hash":null,"server_timestamp":"1785204061657","session_id":"d2757dd6dad94f3b9fe67e8dbf1adc37","source":"clob_market_ws"},"received_at":"2026-07-28T02:01:09.187984Z","record_id":"7e5bb49767c14ea89571de30bdc9f43f8fdd28a47c0035d7acccdeb1ee3c34ed","schema_fingerprint":"4aa3821a28b0b7c2400bc59aba4bcc0a76e971dadd19610d3ad38c768e124dc7","schema_version":"edge-lab-recorder.raw.v1","sequence":null,"source":"clob_market_ws"}
{"event_at":"2026-07-28T02:01:01.658000Z","event_fingerprint":"03f5981a690e78f9099fe4337c36fc9353ec1718eb12ada8c7b0638184d309e1","payload":{"connection_id":"5d29200f65794d4d9ab6ef271f045a9b","event_at":"2026-07-28T02:01:01.658000Z","event_type":"price_change","frame_hash":"c65d7c486bebbe013b7aec65ce91b223021f0ca2fcff984eaceb349bb92ecdf4","frame_index":0,"kind":"data","monotonic_ns":306052196760083,"payload":{"event_type":"price_change","market":"0xda6f0e0e93fc8469e0159a166028d017bddbc162b86f66bac90391379603d962","price_changes":[{"asset_id":"39272994714739463168905443499424551362424437245880253267329605556587274644733","best_ask":"0.62","best_bid":"0.61","hash":"1a211a414d42d7e2d8f94da92fe183aa2c0bb3e4","price":"0.61","side":"BUY","size":"113.2"},{"asset_id":"20893381255801015515826997628594359667013752732428989472914000440642900266717","best_ask":"0.39","best_bid":"0.38","hash":"886578e69c5a2c020310711f2e6726a37d13ff8e","price":"0.39","side":"SELL","size":"113.2"}],"timestamp":"1785204061658"},"payload_hash":"3bd045f94b86cc3fa324f4b5ee74f33a501677b9183ec561871ba15423c1a537","raw_frame":"{\"market\":\"0xda6f0e0e93fc8469e0159a166028d017bddbc162b86f66bac90391379603d962\", \"price_changes\":[{\"asset_id\":\"39272994714739463168905443499424551362424437245880253267329605556587274644733\", \"price\":\"0.61\", \"size\":\"113.2\", \"side\":\"BUY\", \"hash\":\"1a211a414d42d7e2d8f94da92fe183aa2c0bb3e4\", \"best_bid\":\"0.61\", \"best_ask\":\"0.62\"}, {\"asset_id\":\"20893381255801015515826997628594359667013752732428989472914000440642900266717\", \"price\":\"0.39\", \"size\":\"113.2\", \"side\":\"SELL\", \"hash\":\"886578e69c5a2c020310711f2e6726a37d13ff8e\", \"best_bid\":\"0.38\", \"best_ask\":\"0.39\"}], \"timestamp\":\"1785204061658\", \"event_type\":\"price_change\"}","received_at":"2026-07-28T02:01:09.192814Z","schema_version":"clob-market-ws.price_change.v1","sequence":null,"server_hash":null,"server_timestamp":"1785204061658","session_id":"d2757dd6dad94f3b9fe67e8dbf1adc37","source":"clob_market_ws"},"received_at":"2026-07-28T02:01:09.192814Z","record_id":"fb873a24c08b825260fb7116093d7c2c94d7710a5d16a97ff9ffcc8614643849","schema_fingerprint":"4aa3821a28b0b7c2400bc59aba4bcc0a76e971dadd19610d3ad38c768e124dc7","schema_version":"edge-lab-recorder.raw.v1","sequence":null,"source":"clob_market_ws"}
{"event_at":"2026-07-28T02:01:01.659000Z","event_fingerprint":"45d15ee6b734143843209a51000a9e84370d00ee48b58fb50f54a3c9638b9baa","payload":{"connection_id":"5d29200f65794d4d9ab6ef271f045a9b","event_at":"2026-07-28T02:01:01.659000Z","event_type":"price_change","frame_hash":"8029a6c5a0b029e9fdb0547b03fc6df28b0a86beff229284b110815c0a349048","frame_index":0,"kind":"data","monotonic_ns":306052202005750,"payload":{"event_type":"price_change","market":"0xda6f0e0e93fc8469e0159a166028d017bddbc162b86f66bac90391379603d962","price_changes":[{"asset_id":"39272994714739463168905443499424551362424437245880253267329605556587274644733","best_ask":"0.62","best_bid":"0.61","hash":"bc76f59139e19306836e06031a7ab04cf6aebcf6","price":"0.42","side":"BUY","size":"144.3"},{"asset_id":"20893381255801015515826997628594359667013752732428989472914000440642900266717","best_ask":"0.39","best_bid":"0.38","hash":"52c9929d33569ebae95a36f89824715b74eb84e0","price":"0.58","side":"SELL","size":"144.3"}],"timestamp":"1785204061659"},"payload_hash":"368b1ba705fca371b79dc12590f3d3abbbc0849f3f6790cf9cbcc48c5d11ebbc","raw_frame":"{\"market\":\"0xda6f0e0e93fc8469e0159a166028d017bddbc162b86f66bac90391379603d962\", \"price_changes\":[{\"asset_id\":\"39272994714739463168905443499424551362424437245880253267329605556587274644733\", \"price\":\"0.42\", \"size\":\"144.3\", \"side\":\"BUY\", \"hash\":\"bc76f59139e19306836e06031a7ab04cf6aebcf6\", \"best_bid\":\"0.61\", \"best_ask\":\"0.62\"}, {\"asset_id\":\"20893381255801015515826997628594359667013752732428989472914000440642900266717\", \"price\":\"0.58\", \"size\":\"144.3\", \"side\":\"SELL\", \"hash\":\"52c9929d33569ebae95a36f89824715b74eb84e0\", \"best_bid\":\"0.38\", \"best_ask\":\"0.39\"}], \"timestamp\":\"1785204061659\", \"event_type\":\"price_change\"}","received_at":"2026-07-28T02:01:09.198060Z","schema_version":"clob-market-ws.price_change.v1","sequence":null,"server_hash":null,"server_timestamp":"1785204061659","session_id":"d2757dd6dad94f3b9fe67e8dbf1adc37","source":"clob_market_ws"},"received_at":"2026-07-28T02:01:09.198060Z","record_id":"593ea142ca650b3bb186a61350bbf6126d61214feda6f4ae5ff62fbc6bd31c87","schema_fingerprint":"4aa3821a28b0b7c2400bc59aba4bcc0a76e971dadd19610d3ad38c768e124dc7","schema_version":"edge-lab-recorder.raw.v1","sequence":null,"source":"clob_market_ws"}
{"event_at":"2026-07-28T02:01:01.659000Z","event_fingerprint":"f008a31faccf3dc453de3e8baf0bce59a9cb489e32204b7f7a12284bf4110279","payload":{"connection_id":"5d29200f65794d4d9ab6ef271f045a9b","event_at":"2026-07-28T02:01:01.659000Z","event_type":"price_change","frame_hash":"5841ed66114d49d92e8f4cf564d8fb1708fbe7d86e40c33d85cd8a45f8064599","frame_index":0,"kind":"data","monotonic_ns":306052205506000,"payload":{"event_type":"price_change","market":"0xda6f0e0e93fc8469e0159a166028d017bddbc162b86f66bac90391379603d962","price_changes":[{"asset_id":"20893381255801015515826997628594359667013752732428989472914000440642900266717","best_ask":"0.39","best_bid":"0.38","hash":"dc167c65cdec86593b28e9fc8fc5b8e68ef3ec69","price":"0.33","side":"BUY","size":"117"},{"asset_id":"39272994714739463168905443499424551362424437245880253267329605556587274644733","best_ask":"0.62","best_bid":"0.61","hash":"c0f1fac611b75f36c80fc10a0735cc7c38311238","price":"0.67","side":"SELL","size":"117"}],"timestamp":"1785204061659"},"payload_hash":"6d65c16440bcaf5e689548a88f5494c61dea9b5b4cc14f4877bfecd69e8ee8b1","raw_frame":"{\"market\":\"0xda6f0e0e93fc8469e0159a166028d017bddbc162b86f66bac90391379603d962\", \"price_changes\":[{\"asset_id\":\"20893381255801015515826997628594359667013752732428989472914000440642900266717\", \"price\":\"0.33\", \"size\":\"117\", \"side\":\"BUY\", \"hash\":\"dc167c65cdec86593b28e9fc8fc5b8e68ef3ec69\", \"best_bid\":\"0.38\", \"best_ask\":\"0.39\"}, {\"asset_id\":\"39272994714739463168905443499424551362424437245880253267329605556587274644733\", \"price\":\"0.67\", \"size\":\"117\", \"side\":\"SELL\", \"hash\":\"c0f1fac611b75f36c80fc10a0735cc7c38311238\", \"best_bid\":\"0.61\", \"best_ask\":\"0.62\"}], \"timestamp\":\"1785204061659\", \"event_type\":\"price_change\"}","received_at":"2026-07-28T02:01:09.201559Z","schema_version":"clob-market-ws.price_change.v1","sequence":null,"server_hash":null,"server_timestamp":"1785204061659","session_id":"d2757dd6dad94f3b9fe67e8dbf1adc37","source":"clob_market_ws"},"received_at":"2026-07-28T02:01:09.201559Z","record_id":"71f597ee40f237a1a51e00868843d3d79870a1696d9d58289a2097d631c69f4e","schema_fingerprint":"4aa3821a28b0b7c2400bc59aba4bcc0a76e971dadd19610d3ad38c768e124dc7","schema_version":"edge-lab-recorder.raw.v1","sequence":null,"source":"clob_market_ws"}
{"event_at":"2026-07-28T02:01:01.660000Z","event_fingerprint":"ed3f64ddbd6e8b48a2dd371ceb4a1f954b1fcc2ba9a74c5a7e9779271f74e2d6","payload":{"connection_id":"5d29200f65794d4d9ab6ef271f045a9b","event_at":"2026-07-28T02:01:01.660000Z","event_type":"price_change","frame_hash":"3b6c9465716f84d18b053dbf3061083f68c97ea7e292fa63b88e17c89b57e4d5","frame_index":0,"kind":"data","monotonic_ns":306052211428625,"payload":{"event_type":"price_change","market":"0xda6f0e0e93fc8469e0159a166028d017bddbc162b86f66bac90391379603d962","price_changes":[{"asset_id":"20893381255801015515826997628594359667013752732428989472914000440642900266717","best_ask":"0.39","best_bid":"0.38","hash":"648a2150bfb45e07f2d0209f977d0192761beacb","price":"0.35","side":"BUY","size":"50"},{"asset_id":"39272994714739463168905443499424551362424437245880253267329605556587274644733","best_ask":"0.62","best_bid":"0.61","hash":"06db2649e333cc3a54efa7164278a7206269b6eb","price":"0.65","side":"SELL","size":"50"}],"timestamp":"1785204061660"},"payload_hash":"b41b0132e80b6e4aec00de2740cf65c4c923b6d6081f7a29fede40e29c294813","raw_frame":"{\"market\":\"0xda6f0e0e93fc8469e0159a166028d017bddbc162b86f66bac90391379603d962\", \"price_changes\":[{\"asset_id\":\"20893381255801015515826997628594359667013752732428989472914000440642900266717\", \"price\":\"0.35\", \"size\":\"50\", \"side\":\"BUY\", \"hash\":\"648a2150bfb45e07f2d0209f977d0192761beacb\", \"best_bid\":\"0.38\", \"best_ask\":\"0.39\"}, {\"asset_id\":\"39272994714739463168905443499424551362424437245880253267329605556587274644733\", \"price\":\"0.65\", \"size\":\"50\", \"side\":\"SELL\", \"hash\":\"06db2649e333cc3a54efa7164278a7206269b6eb\", \"best_bid\":\"0.61\", \"best_ask\":\"0.62\"}], \"timestamp\":\"1785204061660\", \"event_type\":\"price_change\"}","received_at":"2026-07-28T02:01:09.207480Z","schema_version":"clob-market-ws.price_change.v1","sequence":null,"server_hash":null,"server_timestamp":"1785204061660","session_id":"d2757dd6dad94f3b9fe67e8dbf1adc37","source":"clob_market_ws"},"received_at":"2026-07-28T02:01:09.207480Z","record_id":"ee402a4bf4481bc7d642702ef7462f27f150bb7985f8e4d0a35676ae7430249c","schema_fingerprint":"4aa3821a28b0b7c2400bc59aba4bcc0a76e971dadd19610d3ad38c768e124dc7","schema_version":"edge-lab-recorder.raw.v1","sequence":null,"source":"clob_market_ws"}
{"event_at":"2026-07-28T02:01:01.660000Z","event_fingerprint":"7a69496c418c0f2773c89f8105b9d48248cb4c9ebc775339b77ab2b13cc1a591","payload":{"connection_id":"5d29200f65794d4d9ab6ef271f045a9b","event_at":"2026-07-28T02:01:01.660000Z","event_type":"price_change","frame_hash":"6c9686e69c17d256bfc7cf6bea44e77add5432288e05f9260709803c0c0473a3","frame_index":0,"kind":"data","monotonic_ns":306052214997916,"payload":{"event_type":"price_change","market":"0xda6f0e0e93fc8469e0159a166028d017bddbc162b86f66bac90391379603d962","price_changes":[{"asset_id":"39272994714739463168905443499424551362424437245880253267329605556587274644733","best_ask":"0.62","best_bid":"0.61","hash":"ebaa528cb681f89924544f26f22f762e9d005957","price":"0.46","side":"BUY","size":"202"},{"asset_id":"20893381255801015515826997628594359667013752732428989472914000440642900266717","best_ask":"0.39","best_bid":"0.38","hash":"12a614960d36ae3096d17d503032172b048dfdfe","price":"0.54","side":"SELL","size":"202"}],"timestamp":"1785204061660"},"payload_hash":"607081682c6678e672d84118d5f1f4b923a19a0ff103ed90f57948b507b4a03f","raw_frame":"{\"market\":\"0xda6f0e0e93fc8469e0159a166028d017bddbc162b86f66bac90391379603d962\", \"price_changes\":[{\"asset_id\":\"39272994714739463168905443499424551362424437245880253267329605556587274644733\", \"price\":\"0.46\", \"size\":\"202\", \"side\":\"BUY\", \"hash\":\"ebaa528cb681f89924544f26f22f762e9d005957\", \"best_bid\":\"0.61\", \"best_ask\":\"0.62\"}, {\"asset_id\":\"20893381255801015515826997628594359667013752732428989472914000440642900266717\", \"price\":\"0.54\", \"size\":\"202\", \"side\":\"SELL\", \"hash\":\"12a614960d36ae3096d17d503032172b048dfdfe\", \"best_bid\":\"0.38\", \"best_ask\":\"0.39\"}], \"timestamp\":\"1785204061660\", \"event_type\":\"price_change\"}","received_at":"2026-07-28T02:01:09.211051Z","schema_version":"clob-market-ws.price_change.v1","sequence":null,"server_hash":null,"server_timestamp":"1785204061660","session_id":"d2757dd6dad94f3b9fe67e8dbf1adc37","source":"clob_market_ws"},"received_at":"2026-07-28T02:01:09.211051Z","record_id":"1b4f900cc598812dcdfaed372692732922a0bc7dfc7a01164d7b61f14599175b","schema_fingerprint":"4aa3821a28b0b7c2400bc59aba4bcc0a76e971dadd19610d3ad38c768e124dc7","schema_version":"edge-lab-recorder.raw.v1","sequence":null,"source":"clob_market_ws"}
{"event_at":"2026-07-28T02:01:01.661000Z","event_fingerprint":"f1c6bc0d1a50cd9a49c70a4fc0a0b44530332a8fcf1f5c65a19ade78680c19db","payload":{"connection_id":"5d29200f65794d4d9ab6ef271f045a9b","event_at":"2026-07-28T02:01:01.661000Z","event_type":"price_change","frame_hash":"5916e59419d834a1369b46d08d7cc90f6dd43fe827fa9c3a2a70ddfe33ac64e3","frame_index":0,"kind":"data","monotonic_ns":306052220455916,"payload":{"event_type":"price_change","market":"0xda6f0e0e93fc8469e0159a166028d017bddbc162b86f66bac90391379603d962","price_changes":[{"asset_id":"39272994714739463168905443499424551362424437245880253267329605556587274644733","best_ask":"0.62","best_bid":"0.61","hash":"457e4192ac3b40348c42f3e7c606711148c53e04","price":"0.61","side":"BUY","size":"118.2"},{"asset_id":"20893381255801015515826997628594359667013752732428989472914000440642900266717","best_ask":"0.39","best_bid":"0.38","hash":"617a4aedc922fbb802cd8bf3d6216b240ef45a35","price":"0.39","side":"SELL","size":"118.2"}],"timestamp":"1785204061661"},"payload_hash":"a33596d9f70cab779d5a08825d8234fcebef8c7f56e6fe203a42871cffebb2e8","raw_frame":"{\"market\":\"0xda6f0e0e93fc8469e0159a166028d017bddbc162b86f66bac90391379603d962\", \"price_changes\":[{\"asset_id\":\"39272994714739463168905443499424551362424437245880253267329605556587274644733\", \"price\":\"0.61\", \"size\":\"118.2\", \"side\":\"BUY\", \"hash\":\"457e4192ac3b40348c42f3e7c606711148c53e04\", \"best_bid\":\"0.61\", \"best_ask\":\"0.62\"}, {\"asset_id\":\"20893381255801015515826997628594359667013752732428989472914000440642900266717\", \"price\":\"0.39\", \"size\":\"118.2\", \"side\":\"SELL\", \"hash\":\"617a4aedc922fbb802cd8bf3d6216b240ef45a35\", \"best_bid\":\"0.38\", \"best_ask\":\"0.39\"}], \"timestamp\":\"1785204061661\", \"event_type\":\"price_change\"}","received_at":"2026-07-28T02:01:09.216510Z","schema_version":"clob-market-ws.price_change.v1","sequence":null,"server_hash":null,"server_timestamp":"1785204061661","session_id":"d2757dd6dad94f3b9fe67e8dbf1adc37","source":"clob_market_ws"},"received_at":"2026-07-28T02:01:09.216510Z","record_id":"4ebe512718b327eb148b822618ab4795d951766d2d4253d70fc61e27544ccffc","schema_fingerprint":"4aa3821a28b0b7c2400bc59aba4bcc0a76e971dadd19610d3ad38c768e124dc7","schema_version":"edge-lab-recorder.raw.v1","sequence":null,"source":"clob_market_ws"}
{"event_at":"2026-07-28T02:01:01.662000Z","event_fingerprint":"a5947113d1a03b379f831525a1009164c2c11b9eb03cf48a7fc688a6b6cd85f8","payload":{"connection_id":"5d29200f65794d4d9ab6ef271f045a9b","event_at":"2026-07-28T02:01:01.662000Z","event_type":"price_change","frame_hash":"af01e255260e87d2fd6a1222842470c91c3e9febe02a59e875c172759d2cdedf","frame_index":0,"kind":"data","monotonic_ns":306052226017000,"payload":{"event_type":"price_change","market":"0xda6f0e0e93fc8469e0159a166028d017bddbc162b86f66bac90391379603d962","price_changes":[{"asset_id":"20893381255801015515826997628594359667013752732428989472914000440642900266717","best_ask":"0.39","best_bid":"0.38","hash":"6a8e73fbbb738f4aab0f63ee8fe48884780c57f6","price":"0.27","side":"BUY","size":"139.2"},{"asset_id":"39272994714739463168905443499424551362424437245880253267329605556587274644733","best_ask":"0.62","best_bid":"0.61","hash":"8772271e51fdac998caeffdfaad72551fc475f0c","price":"0.73","side":"SELL","size":"139.2"}],"timestamp":"1785204061662"},"payload_hash":"1a76d90ea399efdeec33af102d58f4a7f29129b67fd33426ce22bc189e4b746e","raw_frame":"{\"market\":\"0xda6f0e0e93fc8469e0159a166028d017bddbc162b86f66bac90391379603d962\", \"price_changes\":[{\"asset_id\":\"20893381255801015515826997628594359667013752732428989472914000440642900266717\", \"price\":\"0.27\", \"size\":\"139.2\", \"side\":\"BUY\", \"hash\":\"6a8e73fbbb738f4aab0f63ee8fe48884780c57f6\", \"best_bid\":\"0.38\", \"best_ask\":\"0.39\"}, {\"asset_id\":\"39272994714739463168905443499424551362424437245880253267329605556587274644733\", \"price\":\"0.73\", \"size\":\"139.2\", \"side\":\"SELL\", \"hash\":\"8772271e51fdac998caeffdfaad72551fc475f0c\", \"best_bid\":\"0.61\", \"best_ask\":\"0.62\"}], \"timestamp\":\"1785204061662\", \"event_type\":\"price_change\"}","received_at":"2026-07-28T02:01:09.222071Z","schema_version":"clob-market-ws.price_change.v1","sequence":null,"server_hash":null,"server_timestamp":"1785204061662","session_id":"d2757dd6dad94f3b9fe67e8dbf1adc37","source":"clob_market_ws"},"received_at":"2026-07-28T02:01:09.222071Z","record_id":"3114c16542f7a0376b98e5b6c6bd36ae3729b03678937e6db49d6b5f80dbc015","schema_fingerprint":"4aa3821a28b0b7c2400bc59aba4bcc0a76e971dadd19610d3ad38c768e124dc7","schema_version":"edge-lab-recorder.raw.v1","sequence":null,"source":"clob_market_ws"}
{"event_at":"2026-07-28T02:01:01.663000Z","event_fingerprint":"93598e60346b6f913f8fce5b1bb0791a32268ac636d9a91dd060820646df2ab1","payload":{"connection_id":"5d29200f65794d4d9ab6ef271f045a9b","event_at":"2026-07-28T02:01:01.663000Z","event_type":"price_change","frame_hash":"8f5cca021cf90c5b20a4846dec5153cf5a8c477ad63f06de404ebd0b6d9be69c","frame_index":0,"kind":"data","monotonic_ns":306052230985708,"payload":{"event_type":"price_change","market":"0xda6f0e0e93fc8469e0159a166028d017bddbc162b86f66bac90391379603d962","price_changes":[{"asset_id":"20893381255801015515826997628594359667013752732428989472914000440642900266717","best_ask":"0.39","best_bid":"0.38","hash":"09e1ff41b96d4d70c6c9e8d60be858a291d30981","price":"0.34","side":"BUY","size":"115"},{"asset_id":"39272994714739463168905443499424551362424437245880253267329605556587274644733","best_ask":"0.62","best_bid":"0.61","hash":"97db421802cf152f1c707ea3f766cb02660a5902","price":"0.66","side":"SELL","size":"115"}],"timestamp":"1785204061663"},"payload_hash":"ebb2f84dcac8d0c86a1781bcd2f9445be5654a3687dab3558fa33e314e298517","raw_frame":"{\"market\":\"0xda6f0e0e93fc8469e0159a166028d017bddbc162b86f66bac90391379603d962\", \"price_changes\":[{\"asset_id\":\"20893381255801015515826997628594359667013752732428989472914000440642900266717\", \"price\":\"0.34\", \"size\":\"115\", \"side\":\"BUY\", \"hash\":\"09e1ff41b96d4d70c6c9e8d60be858a291d30981\", \"best_bid\":\"0.38\", \"best_ask\":\"0.39\"}, {\"asset_id\":\"39272994714739463168905443499424551362424437245880253267329605556587274644733\", \"price\":\"0.66\", \"size\":\"115\", \"side\":\"SELL\", \"hash\":\"97db421802cf152f1c707ea3f766cb02660a5902\", \"best_bid\":\"0.61\", \"best_ask\":\"0.62\"}], \"timestamp\":\"1785204061663\", \"event_type\":\"price_change\"}","received_at":"2026-07-28T02:01:09.227039Z","schema_version":"clob-market-ws.price_change.v1","sequence":null,"server_hash":null,"server_timestamp":"1785204061663","session_id":"d2757dd6dad94f3b9fe67e8dbf1adc37","source":"clob_market_ws"},"received_at":"2026-07-28T02:01:09.227039Z","record_id":"6dd4add53bf0c91921adabbf5d0ecb71723544311ef9310b9eb169173e7f994d","schema_fingerprint":"4aa3821a28b0b7c2400bc59aba4bcc0a76e971dadd19610d3ad38c768e124dc7","schema_version":"edge-lab-recorder.raw.v1","sequence":null,"source":"clob_market_ws"}
{"event_at":"2026-07-28T02:01:01.664000Z","event_fingerprint":"67bd8a27515eb7867f0e3a8b4dc6be50bacdf300bfecd09a4061970f9181694f","payload":{"connection_id":"5d29200f65794d4d9ab6ef271f045a9b","event_at":"2026-07-28T02:01:01.664000Z","event_type":"price_change","frame_hash":"d39a0443226a2ffb3c44f604e9a9b4d9d28e1526d277da308abc1d050fc0dd9c","frame_index":0,"kind":"data","monotonic_ns":306052236028791,"payload":{"event_type":"price_change","market":"0xda6f0e0e93fc8469e0159a166028d017bddbc162b86f66bac90391379603d962","price_changes":[{"asset_id":"39272994714739463168905443499424551362424437245880253267329605556587274644733","best_ask":"0.62","best_bid":"0.61","hash":"625b23f748cbed37f8a84cf784b00ad65a0b31a1","price":"0.51","side":"BUY","size":"128"},{"asset_id":"20893381255801015515826997628594359667013752732428989472914000440642900266717","best_ask":"0.39","best_bid":"0.38","hash":"cbb4f29a053e21ec7826ceb2e116b052ec826c32","price":"0.49","side":"SELL","size":"128"}],"timestamp":"1785204061664"},"payload_hash":"ed0c05b7e50be56f28d123b2517f9ce8d6eadbe08e8649b7f24ff19f3fc5444f","raw_frame":"{\"market\":\"0xda6f0e0e93fc8469e0159a166028d017bddbc162b86f66bac90391379603d962\", \"price_changes\":[{\"asset_id\":\"39272994714739463168905443499424551362424437245880253267329605556587274644733\", \"price\":\"0.51\", \"size\":\"128\", \"side\":\"BUY\", \"hash\":\"625b23f748cbed37f8a84cf784b00ad65a0b31a1\", \"best_bid\":\"0.61\", \"best_ask\":\"0.62\"}, {\"asset_id\":\"20893381255801015515826997628594359667013752732428989472914000440642900266717\", \"price\":\"0.49\", \"size\":\"128\", \"side\":\"SELL\", \"hash\":\"cbb4f29a053e21ec7826ceb2e116b052ec826c32\", \"best_bid\":\"0.38\", \"best_ask\":\"0.39\"}], \"timestamp\":\"1785204061664\", \"event_type\":\"price_change\"}","received_at":"2026-07-28T02:01:09.232082Z","schema_version":"clob-market-ws.price_change.v1","sequence":null,"server_hash":null,"server_timestamp":"1785204061664","session_id":"d2757dd6dad94f3b9fe67e8dbf1adc37","source":"clob_market_ws"},"received_at":"2026-07-28T02:01:09.232082Z","record_id":"9dec571541bd2700c938d9456e10e4355b18bf662d2c3289290ee2dc30d47c8d","schema_fingerprint":"4aa3821a28b0b7c2400bc59aba4bcc0a76e971dadd19610d3ad38c768e124dc7","schema_version":"edge-lab-recorder.raw.v1","sequence":null,"source":"clob_market_ws"}
{"event_at":"2026-07-28T02:01:01.664000Z","event_fingerprint":"0b69e09f38f869731dbd74d2d4b0793a703672eeec8b9fef39deaf1b3f88e0d3","payload":{"connection_id":"5d29200f65794d4d9ab6ef271f045a9b","event_at":"2026-07-28T02:01:01.664000Z","event_type":"price_change","frame_hash":"e7f789c41b23243a87ee2b0c07885ca3ccebb028f396f42d8bad4498fed0971a","frame_index":0,"kind":"data","monotonic_ns":306052240488500,"payload":{"event_type":"price_change","market":"0xda6f0e0e93fc8469e0159a166028d017bddbc162b86f66bac90391379603d962","price_changes":[{"asset_id":"20893381255801015515826997628594359667013752732428989472914000440642900266717","best_ask":"0.39","best_bid":"0.38","hash":"f414d7e6ddc0d2aa38c909fbc71b6a775ba9fb67","price":"0.36","side":"BUY","size":"50"},{"asset_id":"39272994714739463168905443499424551362424437245880253267329605556587274644733","best_ask":"0.62","best_bid":"0.61","hash":"76f21019ad5c12599d98141e6cb93b02f6e9390f","price":"0.64","side":"SELL","size":"50"}],"timestamp":"1785204061664"},"payload_hash":"5be1d4710c283cd88cb433a5dcfb88818267f51aa9153970235a2fd2a2b494f2","raw_frame":"{\"market\":\"0xda6f0e0e93fc8469e0159a166028d017bddbc162b86f66bac90391379603d962\", \"price_changes\":[{\"asset_id\":\"20893381255801015515826997628594359667013752732428989472914000440642900266717\", \"price\":\"0.36\", \"size\":\"50\", \"side\":\"BUY\", \"hash\":\"f414d7e6ddc0d2aa38c909fbc71b6a775ba9fb67\", \"best_bid\":\"0.38\", \"best_ask\":\"0.39\"}, {\"asset_id\":\"39272994714739463168905443499424551362424437245880253267329605556587274644733\", \"price\":\"0.64\", \"size\":\"50\", \"side\":\"SELL\", \"hash\":\"76f21019ad5c12599d98141e6cb93b02f6e9390f\", \"best_bid\":\"0.61\", \"best_ask\":\"0.62\"}], \"timestamp\":\"1785204061664\", \"event_type\":\"price_change\"}","received_at":"2026-07-28T02:01:09.236542Z","schema_version":"clob-market-ws.price_change.v1","sequence":null,"server_hash":null,"server_timestamp":"1785204061664","session_id":"d2757dd6dad94f3b9fe67e8dbf1adc37","source":"clob_market_ws"},"received_at":"2026-07-28T02:01:09.236542Z","record_id":"72f082644d5f8a68b06a7d5699a0ca579fae55f7a37db1e97c9bc5d34306fd49","schema_fingerprint":"4aa3821a28b0b7c2400bc59aba4bcc0a76e971dadd19610d3ad38c768e124dc7","schema_version":"edge-lab-recorder.raw.v1","sequence":null,"source":"clob_market_ws"}
{"event_at":"2026-07-28T02:01:01.668000Z","event_fingerprint":"f55b7f9ab7cc75d268318ba1a77422e68d8bfe004c7f08c2c3367763a8e1d459","payload":{"connection_id":"5d29200f65794d4d9ab6ef271f045a9b","event_at":"2026-07-28T02:01:01.668000Z","event_type":"price_change","frame_hash":"ed987f3510d75debae652955724e830f28b87beb7dab1db3564f50da7d991326","frame_index":0,"kind":"data","monotonic_ns":306052253591791,"payload":{"event_type":"price_change","market":"0xda6f0e0e93fc8469e0159a166028d017bddbc162b86f66bac90391379603d962","price_changes":[{"asset_id":"39272994714739463168905443499424551362424437245880253267329605556587274644733","best_ask":"0.62","best_bid":"0.61","hash":"ac50ee281661d6e73c88499c47435fb91aff12aa","price":"0.59","side":"BUY","size":"386.6"},{"asset_id":"20893381255801015515826997628594359667013752732428989472914000440642900266717","best_ask":"0.39","best_bid":"0.38","hash":"cc9796905036d020d263d908450a7dea9610deec","price":"0.41","side":"SELL","size":"386.6"}],"timestamp":"1785204061668"},"payload_hash":"f7ab55be52d6fec9b97021210535a9f37ef1511ac19705918782e71353633da7","raw_frame":"{\"market\":\"0xda6f0e0e93fc8469e0159a166028d017bddbc162b86f66bac90391379603d962\", \"price_changes\":[{\"asset_id\":\"39272994714739463168905443499424551362424437245880253267329605556587274644733\", \"price\":\"0.59\", \"size\":\"386.6\", \"side\":\"BUY\", \"hash\":\"ac50ee281661d6e73c88499c47435fb91aff12aa\", \"best_bid\":\"0.61\", \"best_ask\":\"0.62\"}, {\"asset_id\":\"20893381255801015515826997628594359667013752732428989472914000440642900266717\", \"price\":\"0.41\", \"size\":\"386.6\", \"side\":\"SELL\", \"hash\":\"cc9796905036d020d263d908450a7dea9610deec\", \"best_bid\":\"0.38\", \"best_ask\":\"0.39\"}], \"timestamp\":\"1785204061668\", \"event_type\":\"price_change\"}","received_at":"2026-07-28T02:01:09.249646Z","schema_version":"clob-market-ws.price_change.v1","sequence":null,"server_hash":null,"server_timestamp":"1785204061668","session_id":"d2757dd6dad94f3b9fe67e8dbf1adc37","source":"clob_market_ws"},"received_at":"2026-07-28T02:01:09.249646Z","record_id":"714c3eba1541f9933e9b0351e31a785e783a8ce10b5c49fd49a1513e34fecf93","schema_fingerprint":"4aa3821a28b0b7c2400bc59aba4bcc0a76e971dadd19610d3ad38c768e124dc7","schema_version":"edge-lab-recorder.raw.v1","sequence":null,"source":"clob_market_ws"}
{"event_at":"2026-07-28T02:01:01.670000Z","event_fingerprint":"21d4f2abe984e526aee083dcb1a84357c697815ce4794b895ac3b47cd13678ab","payload":{"connection_id":"5d29200f65794d4d9ab6ef271f045a9b","event_at":"2026-07-28T02:01:01.670000Z","event_type":"price_change","frame_hash":"846e935782b67dddab1f6db92a9deb036188df923fbf70fcbd28fdb075140d6c","frame_index":0,"kind":"data","monotonic_ns":306052262140583,"payload":{"event_type":"price_change","market":"0xda6f0e0e93fc8469e0159a166028d017bddbc162b86f66bac90391379603d962","price_changes":[{"asset_id":"39272994714739463168905443499424551362424437245880253267329605556587274644733","best_ask":"0.62","best_bid":"0.61","hash":"e8a9c008d65f40182b0f5338bfd6aa85c61e5953","price":"0.49","side":"BUY","size":"304.06"},{"asset_id":"20893381255801015515826997628594359667013752732428989472914000440642900266717","best_ask":"0.39","best_bid":"0.38","hash":"c42782648a43205666060fd8d039e164a4631c15","price":"0.51","side":"SELL","size":"304.06"}],"timestamp":"1785204061670"},"payload_hash":"16a8badda26e2924e161e423ef153bc25a7173509026f75fc66033962a5d8521","raw_frame":"{\"market\":\"0xda6f0e0e93fc8469e0159a166028d017bddbc162b86f66bac90391379603d962\", \"price_changes\":[{\"asset_id\":\"39272994714739463168905443499424551362424437245880253267329605556587274644733\", \"price\":\"0.49\", \"size\":\"304.06\", \"side\":\"BUY\", \"hash\":\"e8a9c008d65f40182b0f5338bfd6aa85c61e5953\", \"best_bid\":\"0.61\", \"best_ask\":\"0.62\"}, {\"asset_id\":\"20893381255801015515826997628594359667013752732428989472914000440642900266717\", \"price\":\"0.51\", \"size\":\"304.06\", \"side\":\"SELL\", \"hash\":\"c42782648a43205666060fd8d039e164a4631c15\", \"best_bid\":\"0.38\", \"best_ask\":\"0.39\"}], \"timestamp\":\"1785204061670\", \"event_type\":\"price_change\"}","received_at":"2026-07-28T02:01:09.258194Z","schema_version":"clob-market-ws.price_change.v1","sequence":null,"server_hash":null,"server_timestamp":"1785204061670","session_id":"d2757dd6dad94f3b9fe67e8dbf1adc37","source":"clob_market_ws"},"received_at":"2026-07-28T02:01:09.258194Z","record_id":"e22bc8d5546fc368aa6973efaa5fcfe4c6824777cbe605972e9e9d7ed3c29802","schema_fingerprint":"4aa3821a28b0b7c2400bc59aba4bcc0a76e971dadd19610d3ad38c768e124dc7","schema_version":"edge-lab-recorder.raw.v1","sequence":null,"source":"clob_market_ws"}
{"event_at":"2026-07-28T02:01:01.671000Z","event_fingerprint":"8031ef91b9af41e29d634c38250ca4c9b492adbc064c675e51f56eb2eedb49fe","payload":{"connection_id":"5d29200f65794d4d9ab6ef271f045a9b","event_at":"2026-07-28T02:01:01.671000Z","event_type":"price_change","frame_hash":"6cc7e43b620c95f034cd2fbdc061fc14f0301a2e7cccec57a75f28a351641000","frame_index":0,"kind":"data","monotonic_ns":306052266522208,"payload":{"event_type":"price_change","market":"0xda6f0e0e93fc8469e0159a166028d017bddbc162b86f66bac90391379603d962","price_changes":[{"asset_id":"39272994714739463168905443499424551362424437245880253267329605556587274644733","best_ask":"0.62","best_bid":"0.61","hash":"7f4a9be25d33561daef5ae790c8801dfa99fbe21","price":"0.5","side":"BUY","size":"104"},{"asset_id":"20893381255801015515826997628594359667013752732428989472914000440642900266717","best_ask":"0.39","best_bid":"0.38","hash":"4fd4b9259dab77b5ccce268f2bd270fb14f8fad5","price":"0.5","side":"SELL","size":"104"}],"timestamp":"1785204061671"},"payload_hash":"aab189c60a29985a860457a6736f829ac8545327e773f9783a815ff26cdd4470","raw_frame":"{\"market\":\"0xda6f0e0e93fc8469e0159a166028d017bddbc162b86f66bac90391379603d962\", \"price_changes\":[{\"asset_id\":\"39272994714739463168905443499424551362424437245880253267329605556587274644733\", \"price\":\"0.5\", \"size\":\"104\", \"side\":\"BUY\", \"hash\":\"7f4a9be25d33561daef5ae790c8801dfa99fbe21\", \"best_bid\":\"0.61\", \"best_ask\":\"0.62\"}, {\"asset_id\":\"20893381255801015515826997628594359667013752732428989472914000440642900266717\", \"price\":\"0.5\", \"size\":\"104\", \"side\":\"SELL\", \"hash\":\"4fd4b9259dab77b5ccce268f2bd270fb14f8fad5\", \"best_bid\":\"0.38\", \"best_ask\":\"0.39\"}], \"timestamp\":\"1785204061671\", \"event_type\":\"price_change\"}","received_at":"2026-07-28T02:01:09.262575Z","schema_version":"clob-market-ws.price_change.v1","sequence":null,"server_hash":null,"server_timestamp":"1785204061671","session_id":"d2757dd6dad94f3b9fe67e8dbf1adc37","source":"clob_market_ws"},"received_at":"2026-07-28T02:01:09.262575Z","record_id":"da6dbe6d5ae7e7ea3ac8a082b658f1625f2e9627d5a060b954dd70a43540c38c","schema_fingerprint":"4aa3821a28b0b7c2400bc59aba4bcc0a76e971dadd19610d3ad38c768e124dc7","schema_version":"edge-lab-recorder.raw.v1","sequence":null,"source":"clob_market_ws"}
{"event_at":"2026-07-28T02:01:01.671000Z","event_fingerprint":"9409e4658b7eb8d9f5ae179ebe9d114efd7b36a1c8a480875c91ebf7e9f37271","payload":{"connection_id":"5d29200f65794d4d9ab6ef271f045a9b","event_at":"2026-07-28T02:01:01.671000Z","event_type":"price_change","frame_hash":"135a94360fd395a45ebd38b62da48226bad3051cafc238832e1194a20e48f959","frame_index":0,"kind":"data","monotonic_ns":306052282184041,"payload":{"event_type":"price_change","market":"0xda6f0e0e93fc8469e0159a166028d017bddbc162b86f66bac90391379603d962","price_changes":[{"asset_id":"39272994714739463168905443499424551362424437245880253267329605556587274644733","best_ask":"0.62","best_bid":"0.61","hash":"4ed4a88871639320d7006141e6ce7cde964a2718","price":"0.59","side":"BUY","size":"366.6"},{"asset_id":"20893381255801015515826997628594359667013752732428989472914000440642900266717","best_ask":"0.39","best_bid":"0.38","hash":"3d87a066c2a888777316173118ca720832bef86c","price":"0.41","side":"SELL","size":"366.6"}],"timestamp":"1785204061671"},"payload_hash":"069d454bd4466e1203d4b9a45ce3705ada790c2621527165b237fdfdda682e08","raw_frame":"{\"market\":\"0xda6f0e0e93fc8469e0159a166028d017bddbc162b86f66bac90391379603d962\", \"price_changes\":[{\"asset_id\":\"39272994714739463168905443499424551362424437245880253267329605556587274644733\", \"price\":\"0.59\", \"size\":\"366.6\", \"side\":\"BUY\", \"hash\":\"4ed4a88871639320d7006141e6ce7cde964a2718\", \"best_bid\":\"0.61\", \"best_ask\":\"0.62\"}, {\"asset_id\":\"20893381255801015515826997628594359667013752732428989472914000440642900266717\", \"price\":\"0.41\", \"size\":\"366.6\", \"side\":\"SELL\", \"hash\":\"3d87a066c2a888777316173118ca720832bef86c\", \"best_bid\":\"0.38\", \"best_ask\":\"0.39\"}], \"timestamp\":\"1785204061671\", \"event_type\":\"price_change\"}","received_at":"2026-07-28T02:01:09.278236Z","schema_version":"clob-market-ws.price_change.v1","sequence":null,"server_hash":null,"server_timestamp":"1785204061671","session_id":"d2757dd6dad94f3b9fe67e8dbf1adc37","source":"clob_market_ws"},"received_at":"2026-07-28T02:01:09.278236Z","record_id":"81bb515eee9df0d4f159d8861a0abb125d04868ca428df8327635a8c2c90f821","schema_fingerprint":"4aa3821a28b0b7c2400bc59aba4bcc0a76e971dadd19610d3ad38c768e124dc7","schema_version":"edge-lab-recorder.raw.v1","sequence":null,"source":"clob_market_ws"}
{"event_at":"2026-07-28T02:01:01.673000Z","event_fingerprint":"562ea1c2618765922fcc9a2f767848e642c0f18a22681e521dffba68f6397b85","payload":{"connection_id":"5d29200f65794d4d9ab6ef271f045a9b","event_at":"2026-07-28T02:01:01.673000Z","event_type":"price_change","frame_hash":"4ed0666915b2b1268dc25ae85cda3ab783572ea37d7fd6d8813ba056cd1d160f","frame_index":0,"kind":"data","monotonic_ns":306052289429916,"payload":{"event_type":"price_change","market":"0xda6f0e0e93fc8469e0159a166028d017bddbc162b86f66bac90391379603d962","price_changes":[{"asset_id":"39272994714739463168905443499424551362424437245880253267329605556587274644733","best_ask":"0.62","best_bid":"0.61","hash":"7935409d72385fd5e43cd9e9bc55cad330cfbfeb","price":"0.6","side":"BUY","size":"109.6"},{"asset_id":"20893381255801015515826997628594359667013752732428989472914000440642900266717","best_ask":"0.39","best_bid":"0.38","hash":"055a75e3446bdf0afa06cdfd326b8076f8421af8","price":"0.4","side":"SELL","size":"109.6"}],"timestamp":"1785204061673"},"payload_hash":"a9086634b388204e7e23b0b5db08cc7fad17573c9d67089b141afacdca4557f0","raw_frame":"{\"market\":\"0xda6f0e0e93fc8469e0159a166028d017bddbc162b86f66bac90391379603d962\", \"price_changes\":[{\"asset_id\":\"39272994714739463168905443499424551362424437245880253267329605556587274644733\", \"price\":\"0.6\", \"size\":\"109.6\", \"side\":\"BUY\", \"hash\":\"7935409d72385fd5e43cd9e9bc55cad330cfbfeb\", \"best_bid\":\"0.61\", \"best_ask\":\"0.62\"}, {\"asset_id\":\"20893381255801015515826997628594359667013752732428989472914000440642900266717\", \"price\":\"0.4\", \"size\":\"109.6\", \"side\":\"SELL\", \"hash\":\"055a75e3446bdf0afa06cdfd326b8076f8421af8\", \"best_bid\":\"0.38\", \"best_ask\":\"0.39\"}], \"timestamp\":\"1785204061673\", \"event_type\":\"price_change\"}","received_at":"2026-07-28T02:01:09.285484Z","schema_version":"clob-market-ws.price_change.v1","sequence":null,"server_hash":null,"server_timestamp":"1785204061673","session_id":"d2757dd6dad94f3b9fe67e8dbf1adc37","source":"clob_market_ws"},"received_at":"2026-07-28T02:01:09.285484Z","record_id":"87db63400d835c9f3caffcb843cfedc924c570fe668cbc212356d0367d632a36","schema_fingerprint":"4aa3821a28b0b7c2400bc59aba4bcc0a76e971dadd19610d3ad38c768e124dc7","schema_version":"edge-lab-recorder.raw.v1","sequence":null,"source":"clob_market_ws"}
{"event_at":"2026-07-28T02:01:01.677000Z","event_fingerprint":"fc13e3fda9c734f76b7903a45b47957926137a03208f6ef81f4cd5371e198cc7","payload":{"connection_id":"5d29200f65794d4d9ab6ef271f045a9b","event_at":"2026-07-28T02:01:01.677000Z","event_type":"price_change","frame_hash":"67dedb683c1cd7a5fe0f574cfed6778f457a942d3cc83c01aed85d1cd5503a83","frame_index":0,"kind":"data","monotonic_ns":306052295672791,"payload":{"event_type":"price_change","market":"0xda6f0e0e93fc8469e0159a166028d017bddbc162b86f66bac90391379603d962","price_changes":[{"asset_id":"39272994714739463168905443499424551362424437245880253267329605556587274644733","best_ask":"0.62","best_bid":"0.61","hash":"1cbddcfb1d51b05dacf5080ee07eb2ffc7e3720e","price":"0.52","side":"BUY","size":"111"},{"asset_id":"20893381255801015515826997628594359667013752732428989472914000440642900266717","best_ask":"0.39","best_bid":"0.38","hash":"47da7e537e1012a5d341f8a5e5e16540241ed824","price":"0.48","side":"SELL","size":"111"}],"timestamp":"1785204061677"},"payload_hash":"c3477be5df18bb16bb1822c59c6e0a87a6decca9f6c1507066d0baa1edd675b9","raw_frame":"{\"market\":\"0xda6f0e0e93fc8469e0159a166028d017bddbc162b86f66bac90391379603d962\", \"price_changes\":[{\"asset_id\":\"39272994714739463168905443499424551362424437245880253267329605556587274644733\", \"price\":\"0.52\", \"size\":\"111\", \"side\":\"BUY\", \"hash\":\"1cbddcfb1d51b05dacf5080ee07eb2ffc7e3720e\", \"best_bid\":\"0.61\", \"best_ask\":\"0.62\"}, {\"asset_id\":\"20893381255801015515826997628594359667013752732428989472914000440642900266717\", \"price\":\"0.48\", \"size\":\"111\", \"side\":\"SELL\", \"hash\":\"47da7e537e1012a5d341f8a5e5e16540241ed824\", \"best_bid\":\"0.38\", \"best_ask\":\"0.39\"}], \"timestamp\":\"1785204061677\", \"event_type\":\"price_change\"}","received_at":"2026-07-28T02:01:09.291727Z","schema_version":"clob-market-ws.price_change.v1","sequence":null,"server_hash":null,"server_timestamp":"1785204061677","session_id":"d2757dd6dad94f3b9fe67e8dbf1adc37","source":"clob_market_ws"},"received_at":"2026-07-28T02:01:09.291727Z","record_id":"724e2b7933251d28fc456e4bc59d74dc4aa099b34ae132722e6ce1c5821d0519","schema_fingerprint":"4aa3821a28b0b7c2400bc59aba4bcc0a76e971dadd19610d3ad38c768e124dc7","schema_version":"edge-lab-recorder.raw.v1","sequence":null,"source":"clob_market_ws"}
{"event_at":"2026-07-28T02:01:01.679000Z","event_fingerprint":"55b7255eb26802a89cf9fff8fdf53f4e4bc7b5965ca04b5ee58f87decb68e12e","payload":{"connection_id":"5d29200f65794d4d9ab6ef271f045a9b","event_at":"2026-07-28T02:01:01.679000Z","event_type":"price_change","frame_hash":"5a3a19dbc55c165f4002911566b7a3a18f1c0352dd2c77b9589de9a66c1fd9ad","frame_index":0,"kind":"data","monotonic_ns":306052302646250,"payload":{"event_type":"price_change","market":"0xda6f0e0e93fc8469e0159a166028d017bddbc162b86f66bac90391379603d962","price_changes":[{"asset_id":"20893381255801015515826997628594359667013752732428989472914000440642900266717","best_ask":"0.39","best_bid":"0.38","hash":"24c53bf37d966ab528e95f93a52dea107cdb8f2e","price":"0.34","side":"BUY","size":"56"},{"asset_id":"39272994714739463168905443499424551362424437245880253267329605556587274644733","best_ask":"0.62","best_bid":"0.61","hash":"3ff13d538f0145d45a78bf80d34be4ecd68bb0a7","price":"0.66","side":"SELL","size":"56"}],"timestamp":"1785204061679"},"payload_hash":"58e92f11ca26f6fe25fb798edb5c341458cca4631f083fda4020acfdbbf2f298","raw_frame":"{\"market\":\"0xda6f0e0e93fc8469e0159a166028d017bddbc162b86f66bac90391379603d962\", \"price_changes\":[{\"asset_id\":\"20893381255801015515826997628594359667013752732428989472914000440642900266717\", \"price\":\"0.34\", \"size\":\"56\", \"side\":\"BUY\", \"hash\":\"24c53bf37d966ab528e95f93a52dea107cdb8f2e\", \"best_bid\":\"0.38\", \"best_ask\":\"0.39\"}, {\"asset_id\":\"39272994714739463168905443499424551362424437245880253267329605556587274644733\", \"price\":\"0.66\", \"size\":\"56\", \"side\":\"SELL\", \"hash\":\"3ff13d538f0145d45a78bf80d34be4ecd68bb0a7\", \"best_bid\":\"0.61\", \"best_ask\":\"0.62\"}], \"timestamp\":\"1785204061679\", \"event_type\":\"price_change\"}","received_at":"2026-07-28T02:01:09.298696Z","schema_version":"clob-market-ws.price_change.v1","sequence":null,"server_hash":null,"server_timestamp":"1785204061679","session_id":"d2757dd6dad94f3b9fe67e8dbf1adc37","source":"clob_market_ws"},"received_at":"2026-07-28T02:01:09.298696Z","record_id":"3f454bc00ad5b26e94961e41a49a5e5956c160d9090af811b250b6477a2e5607","schema_fingerprint":"4aa3821a28b0b7c2400bc59aba4bcc0a76e971dadd19610d3ad38c768e124dc7","schema_version":"edge-lab-recorder.raw.v1","sequence":null,"source":"clob_market_ws"}
{"event_at":"2026-07-28T02:01:01.680000Z","event_fingerprint":"25a15cab78108bff56fa06b1493de542e34f863959d3483047c2b966208764b6","payload":{"connection_id":"5d29200f65794d4d9ab6ef271f045a9b","event_at":"2026-07-28T02:01:01.680000Z","event_type":"price_change","frame_hash":"fee554a69505c01e3ca6679714e0a2fa5629c004cc530d0951bd48d0997af73f","frame_index":0,"kind":"data","monotonic_ns":306052314958000,"payload":{"event_type":"price_change","market":"0xda6f0e0e93fc8469e0159a166028d017bddbc162b86f66bac90391379603d962","price_changes":[{"asset_id":"20893381255801015515826997628594359667013752732428989472914000440642900266717","best_ask":"0.39","best_bid":"0.38","hash":"2b717e3b699fabe55c8c914ffb8561cf24499950","price":"0.23","side":"BUY","size":"173.89"},{"asset_id":"39272994714739463168905443499424551362424437245880253267329605556587274644733","best_ask":"0.62","best_bid":"0.61","hash":"f46f1ae9bc0d92109f99ea83ea3438cb9329b33d","price":"0.77","side":"SELL","size":"173.89"}],"timestamp":"1785204061680"},"payload_hash":"34db8a1126fc898fa12f1e80473bded7d9950d3e018a47f3775e8aa8ff59f969","raw_frame":"{\"market\":\"0xda6f0e0e93fc8469e0159a166028d017bddbc162b86f66bac90391379603d962\", \"price_changes\":[{\"asset_id\":\"20893381255801015515826997628594359667013752732428989472914000440642900266717\", \"price\":\"0.23\", \"size\":\"173.89\", \"side\":\"BUY\", \"hash\":\"2b717e3b699fabe55c8c914ffb8561cf24499950\", \"best_bid\":\"0.38\", \"best_ask\":\"0.39\"}, {\"asset_id\":\"39272994714739463168905443499424551362424437245880253267329605556587274644733\", \"price\":\"0.77\", \"size\":\"173.89\", \"side\":\"SELL\", \"hash\":\"f46f1ae9bc0d92109f99ea83ea3438cb9329b33d\", \"best_bid\":\"0.61\", \"best_ask\":\"0.62\"}], \"timestamp\":\"1785204061680\", \"event_type\":\"price_change\"}","received_at":"2026-07-28T02:01:09.311011Z","schema_version":"clob-market-ws.price_change.v1","sequence":null,"server_hash":null,"server_timestamp":"1785204061680","session_id":"d2757dd6dad94f3b9fe67e8dbf1adc37","source":"clob_market_ws"},"received_at":"2026-07-28T02:01:09.311011Z","record_id":"8c56cd5a494caffb442c8a24e5acf8e1116767b9de95e22c2bac0acca8758ba4","schema_fingerprint":"4aa3821a28b0b7c2400bc59aba4bcc0a76e971dadd19610d3ad38c768e124dc7","schema_version":"edge-lab-recorder.raw.v1","sequence":null,"source":"clob_market_ws"}
{"event_at":"2026-07-28T02:01:01.683000Z","event_fingerprint":"f79e63c7a5211052197e6f3e423185f48e5629f0d80560f5270f2a814e2f9c39","payload":{"connection_id":"5d29200f65794d4d9ab6ef271f045a9b","event_at":"2026-07-28T02:01:01.683000Z","event_type":"price_change","frame_hash":"3ac8d653ed06aad132b6b79b255caacbfd0277137655ed28932919483f3ad6dd","frame_index":0,"kind":"data","monotonic_ns":306052330681500,"payload":{"event_type":"price_change","market":"0xda6f0e0e93fc8469e0159a166028d017bddbc162b86f66bac90391379603d962","price_changes":[{"asset_id":"39272994714739463168905443499424551362424437245880253267329605556587274644733","best_ask":"0.62","best_bid":"0.61","hash":"fe19e6bbf6cad3ed60f6048eb7f50ba2ec8bbfb9","price":"0.59","side":"BUY","size":"371.6"},{"asset_id":"20893381255801015515826997628594359667013752732428989472914000440642900266717","best_ask":"0.39","best_bid":"0.38","hash":"ebedd11c7c992fbf7fdee2e4d44758e9ebb81e2b","price":"0.41","side":"SELL","size":"371.6"}],"timestamp":"1785204061683"},"payload_hash":"9fbd06aefe3ce06ec295faa43391e9b4172be4f511d4fe30424db36cc77d84cc","raw_frame":"{\"market\":\"0xda6f0e0e93fc8469e0159a166028d017bddbc162b86f66bac90391379603d962\", \"price_changes\":[{\"asset_id\":\"39272994714739463168905443499424551362424437245880253267329605556587274644733\", \"price\":\"0.59\", \"size\":\"371.6\", \"side\":\"BUY\", \"hash\":\"fe19e6bbf6cad3ed60f6048eb7f50ba2ec8bbfb9\", \"best_bid\":\"0.61\", \"best_ask\":\"0.62\"}, {\"asset_id\":\"20893381255801015515826997628594359667013752732428989472914000440642900266717\", \"price\":\"0.41\", \"size\":\"371.6\", \"side\":\"SELL\", \"hash\":\"ebedd11c7c992fbf7fdee2e4d44758e9ebb81e2b\", \"best_bid\":\"0.38\", \"best_ask\":\"0.39\"}], \"timestamp\":\"1785204061683\", \"event_type\":\"price_change\"}","received_at":"2026-07-28T02:01:09.326735Z","schema_version":"clob-market-ws.price_change.v1","sequence":null,"server_hash":null,"server_timestamp":"1785204061683","session_id":"d2757dd6dad94f3b9fe67e8dbf1adc37","source":"clob_market_ws"},"received_at":"2026-07-28T02:01:09.326735Z","record_id":"3a5990f8caed93dc331927683f9ceb197cb2c6e2800f6d32f1d6d5b582788641","schema_fingerprint":"4aa3821a28b0b7c2400bc59aba4bcc0a76e971dadd19610d3ad38c768e124dc7","schema_version":"edge-lab-recorder.raw.v1","sequence":null,"source":"clob_market_ws"}
{"event_at":"2026-07-28T02:01:01.684000Z","event_fingerprint":"47c9c68de6ca0f8745e4ca7851831efc3c719012ad1c16de9f4d8afe55b7c0b9","payload":{"connection_id":"5d29200f65794d4d9ab6ef271f045a9b","event_at":"2026-07-28T02:01:01.684000Z","event_type":"price_change","frame_hash":"56b46f53e25715176ed953e52669758fe8e429509e6763908d6014228dcea035","frame_index":0,"kind":"data","monotonic_ns":306052338319333,"payload":{"event_type":"price_change","market":"0xda6f0e0e93fc8469e0159a166028d017bddbc162b86f66bac90391379603d962","price_changes":[{"asset_id":"20893381255801015515826997628594359667013752732428989472914000440642900266717","best_ask":"0.39","best_bid":"0.38","hash":"547f243ddc8db6251f549276385f4f33d671b2d0","price":"0.24","side":"BUY","size":"156.39"},{"asset_id":"39272994714739463168905443499424551362424437245880253267329605556587274644733","best_ask":"0.62","best_bid":"0.61","hash":"10c5dc4e68a29828b853cf305dae6e553ae63512","price":"0.76","side":"SELL","size":"156.39"}],"timestamp":"1785204061684"},"payload_hash":"1d3d9b844a3997837c362ed914a7e768f367e71890e6ca85b983f0654220cf0a","raw_frame":"{\"market\":\"0xda6f0e0e93fc8469e0159a166028d017bddbc162b86f66bac90391379603d962\", \"price_changes\":[{\"asset_id\":\"20893381255801015515826997628594359667013752732428989472914000440642900266717\", \"price\":\"0.24\", \"size\":\"156.39\", \"side\":\"BUY\", \"hash\":\"547f243ddc8db6251f549276385f4f33d671b2d0\", \"best_bid\":\"0.38\", \"best_ask\":\"0.39\"}, {\"asset_id\":\"39272994714739463168905443499424551362424437245880253267329605556587274644733\", \"price\":\"0.76\", \"size\":\"156.39\", \"side\":\"SELL\", \"hash\":\"10c5dc4e68a29828b853cf305dae6e553ae63512\", \"best_bid\":\"0.61\", \"best_ask\":\"0.62\"}], \"timestamp\":\"1785204061684\", \"event_type\":\"price_change\"}","received_at":"2026-07-28T02:01:09.334375Z","schema_version":"clob-market-ws.price_change.v1","sequence":null,"server_hash":null,"server_timestamp":"1785204061684","session_id":"d2757dd6dad94f3b9fe67e8dbf1adc37","source":"clob_market_ws"},"received_at":"2026-07-28T02:01:09.334375Z","record_id":"76b8a8fc6e9be80203ad47225f354b5685f01d9bf572ecdf9c1dc20d84eca45f","schema_fingerprint":"4aa3821a28b0b7c2400bc59aba4bcc0a76e971dadd19610d3ad38c768e124dc7","schema_version":"edge-lab-recorder.raw.v1","sequence":null,"source":"clob_market_ws"}
{"event_at":"2026-07-28T02:01:01.684000Z","event_fingerprint":"0ef0e80df403365b49e84b6c4c8db6541b74d25f30727c803bb58342954e353f","payload":{"connection_id":"5d29200f65794d4d9ab6ef271f045a9b","event_at":"2026-07-28T02:01:01.684000Z","event_type":"price_change","frame_hash":"5a1c900db9ca0c3bc1f24f99e2e8e431bc7d83c31462bedf5391ac56f5b2379d","frame_index":0,"kind":"data","monotonic_ns":306052343858916,"payload":{"event_type":"price_change","market":"0xda6f0e0e93fc8469e0159a166028d017bddbc162b86f66bac90391379603d962","price_changes":[{"asset_id":"39272994714739463168905443499424551362424437245880253267329605556587274644733","best_ask":"0.62","best_bid":"0.61","hash":"4f37c61c8bd52ebdf5cd636aef990854aa5631ee","price":"0.49","side":"BUY","size":"236.04"},{"asset_id":"20893381255801015515826997628594359667013752732428989472914000440642900266717","best_ask":"0.39","best_bid":"0.38","hash":"ff33906ee806e89a5c44be707870e0d589052f34","price":"0.51","side":"SELL","size":"236.04"}],"timestamp":"1785204061684"},"payload_hash":"f3b7d1838ac7f56cdd9e606aafce52c486a55bb46e2e70cac07d1a503e7d7a6b","raw_frame":"{\"market\":\"0xda6f0e0e93fc8469e0159a166028d017bddbc162b86f66bac90391379603d962\", \"price_changes\":[{\"asset_id\":\"39272994714739463168905443499424551362424437245880253267329605556587274644733\", \"price\":\"0.49\", \"size\":\"236.04\", \"side\":\"BUY\", \"hash\":\"4f37c61c8bd52ebdf5cd636aef990854aa5631ee\", \"best_bid\":\"0.61\", \"best_ask\":\"0.62\"}, {\"asset_id\":\"20893381255801015515826997628594359667013752732428989472914000440642900266717\", \"price\":\"0.51\", \"size\":\"236.04\", \"side\":\"SELL\", \"hash\":\"ff33906ee806e89a5c44be707870e0d589052f34\", \"best_bid\":\"0.38\", \"best_ask\":\"0.39\"}], \"timestamp\":\"1785204061684\", \"event_type\":\"price_change\"}","received_at":"2026-07-28T02:01:09.339915Z","schema_version":"clob-market-ws.price_change.v1","sequence":null,"server_hash":null,"server_timestamp":"1785204061684","session_id":"d2757dd6dad94f3b9fe67e8dbf1adc37","source":"clob_market_ws"},"received_at":"2026-07-28T02:01:09.339915Z","record_id":"86a5a5aaaf92f827daf4498ccfec7341c8736108a3d822bf832fd53d9a4e8e8d","schema_fingerprint":"4aa3821a28b0b7c2400bc59aba4bcc0a76e971dadd19610d3ad38c768e124dc7","schema_version":"edge-lab-recorder.raw.v1","sequence":null,"source":"clob_market_ws"}
{"event_at":"2026-07-28T02:01:01.685000Z","event_fingerprint":"f0c76344d99ab6849ce83aaafffb642342767951628df57997b1c5f8f968407d","payload":{"connection_id":"5d29200f65794d4d9ab6ef271f045a9b","event_at":"2026-07-28T02:01:01.685000Z","event_type":"price_change","frame_hash":"0b5ef00c1e1c7a264625f48065866a9701ecf1d7f1f4175af6a7a993854c0f3f","frame_index":0,"kind":"data","monotonic_ns":306052351538291,"payload":{"event_type":"price_change","market":"0xda6f0e0e93fc8469e0159a166028d017bddbc162b86f66bac90391379603d962","price_changes":[{"asset_id":"39272994714739463168905443499424551362424437245880253267329605556587274644733","best_ask":"0.62","best_bid":"0.61","hash":"2db47ad023dbae7edfac853da04476380858f593","price":"0.49","side":"BUY","size":"168.02"},{"asset_id":"20893381255801015515826997628594359667013752732428989472914000440642900266717","best_ask":"0.39","best_bid":"0.38","hash":"d182249553acb02d0473bb33ce4183309f6d7575","price":"0.51","side":"SELL","size":"168.02"}],"timestamp":"1785204061685"},"payload_hash":"83dc668f203eff5fccf5c3883bd5a904b8972921105983cda38a7686e6cd883b","raw_frame":"{\"market\":\"0xda6f0e0e93fc8469e0159a166028d017bddbc162b86f66bac90391379603d962\", \"price_changes\":[{\"asset_id\":\"39272994714739463168905443499424551362424437245880253267329605556587274644733\", \"price\":\"0.49\", \"size\":\"168.02\", \"side\":\"BUY\", \"hash\":\"2db47ad023dbae7edfac853da04476380858f593\", \"best_bid\":\"0.61\", \"best_ask\":\"0.62\"}, {\"asset_id\":\"20893381255801015515826997628594359667013752732428989472914000440642900266717\", \"price\":\"0.51\", \"size\":\"168.02\", \"side\":\"SELL\", \"hash\":\"d182249553acb02d0473bb33ce4183309f6d7575\", \"best_bid\":\"0.38\", \"best_ask\":\"0.39\"}], \"timestamp\":\"1785204061685\", \"event_type\":\"price_change\"}","received_at":"2026-07-28T02:01:09.347592Z","schema_version":"clob-market-ws.price_change.v1","sequence":null,"server_hash":null,"server_timestamp":"1785204061685","session_id":"d2757dd6dad94f3b9fe67e8dbf1adc37","source":"clob_market_ws"},"received_at":"2026-07-28T02:01:09.347592Z","record_id":"d4c2d30ce97ff19989243c2d953a5ab95476f9fca95b3f1b7358224a1c18bd31","schema_fingerprint":"4aa3821a28b0b7c2400bc59aba4bcc0a76e971dadd19610d3ad38c768e124dc7","schema_version":"edge-lab-recorder.raw.v1","sequence":null,"source":"clob_market_ws"}
{"event_at":"2026-07-28T02:01:01.688000Z","event_fingerprint":"c64031604e44bc5c8ba41ba1a28972ae37b34ff508488e7f7f11f18cf9f90ff4","payload":{"connection_id":"5d29200f65794d4d9ab6ef271f045a9b","event_at":"2026-07-28T02:01:01.688000Z","event_type":"price_change","frame_hash":"b2f144cbd6041f230852eeed671b06a25faac940bc34bb4be15a33c3ff0938b9","frame_index":0,"kind":"data","monotonic_ns":306052356727708,"payload":{"event_type":"price_change","market":"0xda6f0e0e93fc8469e0159a166028d017bddbc162b86f66bac90391379603d962","price_changes":[{"asset_id":"20893381255801015515826997628594359667013752732428989472914000440642900266717","best_ask":"0.39","best_bid":"0.38","hash":"bc3f44d8f0a8b66647fc1e6bc94a22c0adda99fd","price":"0.25","side":"BUY","size":"484.66"},{"asset_id":"39272994714739463168905443499424551362424437245880253267329605556587274644733","best_ask":"0.62","best_bid":"0.61","hash":"bcc9cc41e61d703dc01b6f8ee803d863e7eaff82","price":"0.75","side":"SELL","size":"484.66"}],"timestamp":"1785204061688"},"payload_hash":"0fbb32a787296bc943f1a7874c6c17f70b248f7747f69e36740dc223f8b523de","raw_frame":"{\"market\":\"0xda6f0e0e93fc8469e0159a166028d017bddbc162b86f66bac90391379603d962\", \"price_changes\":[{\"asset_id\":\"20893381255801015515826997628594359667013752732428989472914000440642900266717\", \"price\":\"0.25\", \"size\":\"484.66\", \"side\":\"BUY\", \"hash\":\"bc3f44d8f0a8b66647fc1e6bc94a22c0adda99fd\", \"best_bid\":\"0.38\", \"best_ask\":\"0.39\"}, {\"asset_id\":\"39272994714739463168905443499424551362424437245880253267329605556587274644733\", \"price\":\"0.75\", \"size\":\"484.66\", \"side\":\"SELL\", \"hash\":\"bcc9cc41e61d703dc01b6f8ee803d863e7eaff82\", \"best_bid\":\"0.61\", \"best_ask\":\"0.62\"}], \"timestamp\":\"1785204061688\", \"event_type\":\"price_change\"}","received_at":"2026-07-28T02:01:09.352782Z","schema_version":"clob-market-ws.price_change.v1","sequence":null,"server_hash":null,"server_timestamp":"1785204061688","session_id":"d2757dd6dad94f3b9fe67e8dbf1adc37","source":"clob_market_ws"},"received_at":"2026-07-28T02:01:09.352782Z","record_id":"c216496fefa16ea5d007c197f9bb5e308cd78a5477397179f98a32c3c4358aef","schema_fingerprint":"4aa3821a28b0b7c2400bc59aba4bcc0a76e971dadd19610d3ad38c768e124dc7","schema_version":"edge-lab-recorder.raw.v1","sequence":null,"source":"clob_market_ws"}
{"event_at":"2026-07-28T02:01:01.688000Z","event_fingerprint":"b2a5768543006e0e0ea1ab7225f9b75e97009052e23054a7b31868f4e99d3ced","payload":{"connection_id":"5d29200f65794d4d9ab6ef271f045a9b","event_at":"2026-07-28T02:01:01.688000Z","event_type":"price_change","frame_hash":"f72a7a1da9ee82a4a657c879e09be78d3b8580d86f545babac418a8bf0db6726","frame_index":0,"kind":"data","monotonic_ns":306052362387875,"payload":{"event_type":"price_change","market":"0xda6f0e0e93fc8469e0159a166028d017bddbc162b86f66bac90391379603d962","price_changes":[{"asset_id":"20893381255801015515826997628594359667013752732428989472914000440642900266717","best_ask":"0.39","best_bid":"0.38","hash":"60e2d017ebb81b1278286b3a539b102e21b4979a","price":"0.25","side":"BUY","size":"351.33"},{"asset_id":"39272994714739463168905443499424551362424437245880253267329605556587274644733","best_ask":"0.62","best_bid":"0.61","hash":"79ad5b6aacaf6a9fdfde6a8db6638d772b3be63e","price":"0.75","side":"SELL","size":"351.33"}],"timestamp":"1785204061688"},"payload_hash":"5e9a7e1d8aaba2b76f7b22255b52573285cf26c707f36f25fa5c0896db9c7555","raw_frame":"{\"market\":\"0xda6f0e0e93fc8469e0159a166028d017bddbc162b86f66bac90391379603d962\", \"price_changes\":[{\"asset_id\":\"20893381255801015515826997628594359667013752732428989472914000440642900266717\", \"price\":\"0.25\", \"size\":\"351.33\", \"side\":\"BUY\", \"hash\":\"60e2d017ebb81b1278286b3a539b102e21b4979a\", \"best_bid\":\"0.38\", \"best_ask\":\"0.39\"}, {\"asset_id\":\"39272994714739463168905443499424551362424437245880253267329605556587274644733\", \"price\":\"0.75\", \"size\":\"351.33\", \"side\":\"SELL\", \"hash\":\"79ad5b6aacaf6a9fdfde6a8db6638d772b3be63e\", \"best_bid\":\"0.61\", \"best_ask\":\"0.62\"}], \"timestamp\":\"1785204061688\", \"event_type\":\"price_change\"}","received_at":"2026-07-28T02:01:09.358442Z","schema_version":"clob-market-ws.price_change.v1","sequence":null,"server_hash":null,"server_timestamp":"1785204061688","session_id":"d2757dd6dad94f3b9fe67e8dbf1adc37","source":"clob_market_ws"},"received_at":"2026-07-28T02:01:09.358442Z","record_id":"3b90f86a945391d6a3e72dd83bce6b55a9e1d0c85cb5a85f70c33b79704b5ce1","schema_fingerprint":"4aa3821a28b0b7c2400bc59aba4bcc0a76e971dadd19610d3ad38c768e124dc7","schema_version":"edge-lab-recorder.raw.v1","sequence":null,"source":"clob_market_ws"}
{"event_at":"2026-07-28T02:01:01.688000Z","event_fingerprint":"53cdde97132bb721ed4f24f8a04e2a7f8d7f673f909354aa63c969b9036893ed","payload":{"connection_id":"5d29200f65794d4d9ab6ef271f045a9b","event_at":"2026-07-28T02:01:01.688000Z","event_type":"price_change","frame_hash":"e03d19af154265b2cb6c51f03bad0ffb41e6c336fe69aa8b795546f9c93a9836","frame_index":0,"kind":"data","monotonic_ns":306052371391125,"payload":{"event_type":"price_change","market":"0xda6f0e0e93fc8469e0159a166028d017bddbc162b86f66bac90391379603d962","price_changes":[{"asset_id":"20893381255801015515826997628594359667013752732428989472914000440642900266717","best_ask":"0.39","best_bid":"0.38","hash":"b70176dec94510e047ba1a5990cc5618634f165a","price":"0.35","side":"BUY","size":"62.6"},{"asset_id":"39272994714739463168905443499424551362424437245880253267329605556587274644733","best_ask":"0.62","best_bid":"0.61","hash":"edf72d44823679b6492f5fef75fa484b4ace2742","price":"0.65","side":"SELL","size":"62.6"}],"timestamp":"1785204061688"},"payload_hash":"736fbdbe2a013f79c6e86ba7278f0f36a2d7416cf832b7493d4c46c6d800bd1b","raw_frame":"{\"market\":\"0xda6f0e0e93fc8469e0159a166028d017bddbc162b86f66bac90391379603d962\", \"price_changes\":[{\"asset_id\":\"20893381255801015515826997628594359667013752732428989472914000440642900266717\", \"price\":\"0.35\", \"size\":\"62.6\", \"side\":\"BUY\", \"hash\":\"b70176dec94510e047ba1a5990cc5618634f165a\", \"best_bid\":\"0.38\", \"best_ask\":\"0.39\"}, {\"asset_id\":\"39272994714739463168905443499424551362424437245880253267329605556587274644733\", \"price\":\"0.65\", \"size\":\"62.6\", \"side\":\"SELL\", \"hash\":\"edf72d44823679b6492f5fef75fa484b4ace2742\", \"best_bid\":\"0.61\", \"best_ask\":\"0.62\"}], \"timestamp\":\"1785204061688\", \"event_type\":\"price_change\"}","received_at":"2026-07-28T02:01:09.367445Z","schema_version":"clob-market-ws.price_change.v1","sequence":null,"server_hash":null,"server_timestamp":"1785204061688","session_id":"d2757dd6dad94f3b9fe67e8dbf1adc37","source":"clob_market_ws"},"received_at":"2026-07-28T02:01:09.367445Z","record_id":"44aab04e46e6edbf4585e15ceeadf504ebf500bd47cd7475467f4b40c1f9af5c","schema_fingerprint":"4aa3821a28b0b7c2400bc59aba4bcc0a76e971dadd19610d3ad38c768e124dc7","schema_version":"edge-lab-recorder.raw.v1","sequence":null,"source":"clob_market_ws"}
{"event_at":"2026-07-28T02:01:01.689000Z","event_fingerprint":"b635f0697fb6cc82d4f60602c253b5b157450c61a62c9b30662bd60544d8ea98","payload":{"connection_id":"5d29200f65794d4d9ab6ef271f045a9b","event_at":"2026-07-28T02:01:01.689000Z","event_type":"price_change","frame_hash":"b90520f3284849d0f92bff18ac09816ec9a6feabac30e9c555a0181c07bafbdc","frame_index":0,"kind":"data","monotonic_ns":306052383463833,"payload":{"event_type":"price_change","market":"0xda6f0e0e93fc8469e0159a166028d017bddbc162b86f66bac90391379603d962","price_changes":[{"asset_id":"39272994714739463168905443499424551362424437245880253267329605556587274644733","best_ask":"0.62","best_bid":"0.61","hash":"fa84fdd131ec8a02e82020c18e26b3793e5ae8ca","price":"0.48","side":"BUY","size":"137.05"},{"asset_id":"20893381255801015515826997628594359667013752732428989472914000440642900266717","best_ask":"0.39","best_bid":"0.38","hash":"20a6d63929cb1d637dd99ad5e0455831275e85ef","price":"0.52","side":"SELL","size":"137.05"}],"timestamp":"1785204061689"},"payload_hash":"9bfab2171872f1ab2e9d5825896c871fe07f5463d169fa50efca8e736445a397","raw_frame":"{\"market\":\"0xda6f0e0e93fc8469e0159a166028d017bddbc162b86f66bac90391379603d962\", \"price_changes\":[{\"asset_id\":\"39272994714739463168905443499424551362424437245880253267329605556587274644733\", \"price\":\"0.48\", \"size\":\"137.05\", \"side\":\"BUY\", \"hash\":\"fa84fdd131ec8a02e82020c18e26b3793e5ae8ca\", \"best_bid\":\"0.61\", \"best_ask\":\"0.62\"}, {\"asset_id\":\"20893381255801015515826997628594359667013752732428989472914000440642900266717\", \"price\":\"0.52\", \"size\":\"137.05\", \"side\":\"SELL\", \"hash\":\"20a6d63929cb1d637dd99ad5e0455831275e85ef\", \"best_bid\":\"0.38\", \"best_ask\":\"0.39\"}], \"timestamp\":\"1785204061689\", \"event_type\":\"price_change\"}","received_at":"2026-07-28T02:01:09.379518Z","schema_version":"clob-market-ws.price_change.v1","sequence":null,"server_hash":null,"server_timestamp":"1785204061689","session_id":"d2757dd6dad94f3b9fe67e8dbf1adc37","source":"clob_market_ws"},"received_at":"2026-07-28T02:01:09.379518Z","record_id":"1382383706ff6b7f8f57ec0d64f632ee59910d72616dbc0b6754fdfaf508935a","schema_fingerprint":"4aa3821a28b0b7c2400bc59aba4bcc0a76e971dadd19610d3ad38c768e124dc7","schema_version":"edge-lab-recorder.raw.v1","sequence":null,"source":"clob_market_ws"}
{"event_at":"2026-07-28T02:01:01.689000Z","event_fingerprint":"df5e9e7d12bb66239fe44ef2df18e676197d726e0465996d032ff0f3dc9e8383","payload":{"connection_id":"5d29200f65794d4d9ab6ef271f045a9b","event_at":"2026-07-28T02:01:01.689000Z","event_type":"price_change","frame_hash":"931570ffa4b9b1804b5d14309867b751108e75b5c3d7e715d4779f35dc0bf051","frame_index":0,"kind":"data","monotonic_ns":306052389011666,"payload":{"event_type":"price_change","market":"0xda6f0e0e93fc8469e0159a166028d017bddbc162b86f66bac90391379603d962","price_changes":[{"asset_id":"39272994714739463168905443499424551362424437245880253267329605556587274644733","best_ask":"0.62","best_bid":"0.61","hash":"8417a0afe635528a69085fc70b863e6d25a6f30b","price":"0.47","side":"BUY","size":"117"},{"asset_id":"20893381255801015515826997628594359667013752732428989472914000440642900266717","best_ask":"0.39","best_bid":"0.38","hash":"7d062e6b00fb63d0baf13cd497d67e0c219eb363","price":"0.53","side":"SELL","size":"117"}],"timestamp":"1785204061689"},"payload_hash":"87fba9fdb06519ca262b19eef556979c391f749865a3aa4376ef22fd22972f85","raw_frame":"{\"market\":\"0xda6f0e0e93fc8469e0159a166028d017bddbc162b86f66bac90391379603d962\", \"price_changes\":[{\"asset_id\":\"39272994714739463168905443499424551362424437245880253267329605556587274644733\", \"price\":\"0.47\", \"size\":\"117\", \"side\":\"BUY\", \"hash\":\"8417a0afe635528a69085fc70b863e6d25a6f30b\", \"best_bid\":\"0.61\", \"best_ask\":\"0.62\"}, {\"asset_id\":\"20893381255801015515826997628594359667013752732428989472914000440642900266717\", \"price\":\"0.53\", \"size\":\"117\", \"side\":\"SELL\", \"hash\":\"7d062e6b00fb63d0baf13cd497d67e0c219eb363\", \"best_bid\":\"0.38\", \"best_ask\":\"0.39\"}], \"timestamp\":\"1785204061689\", \"event_type\":\"price_change\"}","received_at":"2026-07-28T02:01:09.385066Z","schema_version":"clob-market-ws.price_change.v1","sequence":null,"server_hash":null,"server_timestamp":"1785204061689","session_id":"d2757dd6dad94f3b9fe67e8dbf1adc37","source":"clob_market_ws"},"received_at":"2026-07-28T02:01:09.385066Z","record_id":"1db98cb0135abfa0a8723928c684e8417ccb8d5f7dccc3f19ec717d64d752dba","schema_fingerprint":"4aa3821a28b0b7c2400bc59aba4bcc0a76e971dadd19610d3ad38c768e124dc7","schema_version":"edge-lab-recorder.raw.v1","sequence":null,"source":"clob_market_ws"}
{"event_at":"2026-07-28T02:01:01.689000Z","event_fingerprint":"538228c295bd16fabeaa3b0e50a7e58b6c5024c09320c2b601f7c398c9a64c1a","payload":{"connection_id":"5d29200f65794d4d9ab6ef271f045a9b","event_at":"2026-07-28T02:01:01.689000Z","event_type":"price_change","frame_hash":"29cc5bdb247656fbb31434fb863d2386f2fa5eb733dd4acb2f1906b99d18666f","frame_index":0,"kind":"data","monotonic_ns":306052396166416,"payload":{"event_type":"price_change","market":"0xda6f0e0e93fc8469e0159a166028d017bddbc162b86f66bac90391379603d962","price_changes":[{"asset_id":"20893381255801015515826997628594359667013752732428989472914000440642900266717","best_ask":"0.39","best_bid":"0.38","hash":"6a17b44592f11b8910d7acd46903a60e7808fecf","price":"0.35","side":"BUY","size":"56.6"},{"asset_id":"39272994714739463168905443499424551362424437245880253267329605556587274644733","best_ask":"0.62","best_bid":"0.61","hash":"90bb2587fbb8aa55da3e477717404896da2f3f50","price":"0.65","side":"SELL","size":"56.6"}],"timestamp":"1785204061689"},"payload_hash":"616d246bdac25f04c46b2f60e9a009cf9107099b9c40945567d924145c55b553","raw_frame":"{\"market\":\"0xda6f0e0e93fc8469e0159a166028d017bddbc162b86f66bac90391379603d962\", \"price_changes\":[{\"asset_id\":\"20893381255801015515826997628594359667013752732428989472914000440642900266717\", \"price\":\"0.35\", \"size\":\"56.6\", \"side\":\"BUY\", \"hash\":\"6a17b44592f11b8910d7acd46903a60e7808fecf\", \"best_bid\":\"0.38\", \"best_ask\":\"0.39\"}, {\"asset_id\":\"39272994714739463168905443499424551362424437245880253267329605556587274644733\", \"price\":\"0.65\", \"size\":\"56.6\", \"side\":\"SELL\", \"hash\":\"90bb2587fbb8aa55da3e477717404896da2f3f50\", \"best_bid\":\"0.61\", \"best_ask\":\"0.62\"}], \"timestamp\":\"1785204061689\", \"event_type\":\"price_change\"}","received_at":"2026-07-28T02:01:09.392221Z","schema_version":"clob-market-ws.price_change.v1","sequence":null,"server_hash":null,"server_timestamp":"1785204061689","session_id":"d2757dd6dad94f3b9fe67e8dbf1adc37","source":"clob_market_ws"},"received_at":"2026-07-28T02:01:09.392221Z","record_id":"71964265111ff9ad2e2a6f3e8ca01e2681302d5f404050d88dc1190e3e1a9520","schema_fingerprint":"4aa3821a28b0b7c2400bc59aba4bcc0a76e971dadd19610d3ad38c768e124dc7","schema_version":"edge-lab-recorder.raw.v1","sequence":null,"source":"clob_market_ws"}
{"event_at":"2026-07-28T02:01:01.689000Z","event_fingerprint":"1330d2daf1e9ec19b232881c179bc021f7980aafd6662453d8e1177474404e0a","payload":{"connection_id":"5d29200f65794d4d9ab6ef271f045a9b","event_at":"2026-07-28T02:01:01.689000Z","event_type":"price_change","frame_hash":"7e3408156048b7ebac7d5af30cec7693c029c789303c6dd11efc20a71ecab9d5","frame_index":0,"kind":"data","monotonic_ns":306052401816416,"payload":{"event_type":"price_change","market":"0xda6f0e0e93fc8469e0159a166028d017bddbc162b86f66bac90391379603d962","price_changes":[{"asset_id":"39272994714739463168905443499424551362424437245880253267329605556587274644733","best_ask":"0.62","best_bid":"0.61","hash":"ba78d8223435a2336ed8d74c6179682e5278a982","price":"0.49","side":"BUY","size":"100"},{"asset_id":"20893381255801015515826997628594359667013752732428989472914000440642900266717","best_ask":"0.39","best_bid":"0.38","hash":"4795d99675c59921193b6a1087b183902937cd81","price":"0.51","side":"SELL","size":"100"}],"timestamp":"1785204061689"},"payload_hash":"d0b52f1ae178975d18a962f2f02d0950ed335c7433e1e17873bf1f42edd42a58","raw_frame":"{\"market\":\"0xda6f0e0e93fc8469e0159a166028d017bddbc162b86f66bac90391379603d962\", \"price_changes\":[{\"asset_id\":\"39272994714739463168905443499424551362424437245880253267329605556587274644733\", \"price\":\"0.49\", \"size\":\"100\", \"side\":\"BUY\", \"hash\":\"ba78d8223435a2336ed8d74c6179682e5278a982\", \"best_bid\":\"0.61\", \"best_ask\":\"0.62\"}, {\"asset_id\":\"20893381255801015515826997628594359667013752732428989472914000440642900266717\", \"price\":\"0.51\", \"size\":\"100\", \"side\":\"SELL\", \"hash\":\"4795d99675c59921193b6a1087b183902937cd81\", \"best_bid\":\"0.38\", \"best_ask\":\"0.39\"}], \"timestamp\":\"1785204061689\", \"event_type\":\"price_change\"}","received_at":"2026-07-28T02:01:09.397871Z","schema_version":"clob-market-ws.price_change.v1","sequence":null,"server_hash":null,"server_timestamp":"1785204061689","session_id":"d2757dd6dad94f3b9fe67e8dbf1adc37","source":"clob_market_ws"},"received_at":"2026-07-28T02:01:09.397871Z","record_id":"ed9092e8a3dda94d024fffa21192dcec66f4c67c6a3ca53c522a356e38488406","schema_fingerprint":"4aa3821a28b0b7c2400bc59aba4bcc0a76e971dadd19610d3ad38c768e124dc7","schema_version":"edge-lab-recorder.raw.v1","sequence":null,"source":"clob_market_ws"}
{"event_at":"2026-07-28T02:01:01.690000Z","event_fingerprint":"527a45248d88195bfabf2f6711a286ab24831b91004554e2f8c952c0e50e3336","payload":{"connection_id":"5d29200f65794d4d9ab6ef271f045a9b","event_at":"2026-07-28T02:01:01.690000Z","event_type":"price_change","frame_hash":"5e0fcc888000ea7cf54d1ac0fd1b6d523f11ccf75a313f1b269262d83465be31","frame_index":0,"kind":"data","monotonic_ns":306052405563791,"payload":{"event_type":"price_change","market":"0xda6f0e0e93fc8469e0159a166028d017bddbc162b86f66bac90391379603d962","price_changes":[{"asset_id":"20893381255801015515826997628594359667013752732428989472914000440642900266717","best_ask":"0.39","best_bid":"0.38","hash":"de1083116204c8e6fa98b788c0ddc121fb65553a","price":"0.36","side":"BUY","size":"44"},{"asset_id":"39272994714739463168905443499424551362424437245880253267329605556587274644733","best_ask":"0.62","best_bid":"0.61","hash":"ffd19fddcc21860c2965682a14a7c818504a9db6","price":"0.64","side":"SELL","size":"44"}],"timestamp":"1785204061690"},"payload_hash":"47038aaf0c6f65d192e91375fb834ea7366984785f661b4f140e9dad9cde63f8","raw_frame":"{\"market\":\"0xda6f0e0e93fc8469e0159a166028d017bddbc162b86f66bac90391379603d962\", \"price_changes\":[{\"asset_id\":\"20893381255801015515826997628594359667013752732428989472914000440642900266717\", \"price\":\"0.36\", \"size\":\"44\", \"side\":\"BUY\", \"hash\":\"de1083116204c8e6fa98b788c0ddc121fb65553a\", \"best_bid\":\"0.38\", \"best_ask\":\"0.39\"}, {\"asset_id\":\"39272994714739463168905443499424551362424437245880253267329605556587274644733\", \"price\":\"0.64\", \"size\":\"44\", \"side\":\"SELL\", \"hash\":\"ffd19fddcc21860c2965682a14a7c818504a9db6\", \"best_bid\":\"0.61\", \"best_ask\":\"0.62\"}], \"timestamp\":\"1785204061690\", \"event_type\":\"price_change\"}","received_at":"2026-07-28T02:01:09.401617Z","schema_version":"clob-market-ws.price_change.v1","sequence":null,"server_hash":null,"server_timestamp":"1785204061690","session_id":"d2757dd6dad94f3b9fe67e8dbf1adc37","source":"clob_market_ws"},"received_at":"2026-07-28T02:01:09.401617Z","record_id":"51755d31b4262b69c1c74b988cab18f2f1c45ea5aaf79a361c3c03764cdf8ec2","schema_fingerprint":"4aa3821a28b0b7c2400bc59aba4bcc0a76e971dadd19610d3ad38c768e124dc7","schema_version":"edge-lab-recorder.raw.v1","sequence":null,"source":"clob_market_ws"}
{"event_at":"2026-07-28T02:01:01.691000Z","event_fingerprint":"c5146496f0e803efb1c6d74292e16b0256eba4bba0d092605c1dd831a41423bf","payload":{"connection_id":"5d29200f65794d4d9ab6ef271f045a9b","event_at":"2026-07-28T02:01:01.691000Z","event_type":"price_change","frame_hash":"e92a8a2879ba412c3e7e60fc374f26dfbb6c3ac834c40ba0828cef69a24dd03e","frame_index":0,"kind":"data","monotonic_ns":306052411253291,"payload":{"event_type":"price_change","market":"0xda6f0e0e93fc8469e0159a166028d017bddbc162b86f66bac90391379603d962","price_changes":[{"asset_id":"20893381255801015515826997628594359667013752732428989472914000440642900266717","best_ask":"0.39","best_bid":"0.38","hash":"4ba783335cf67fec5d9339aab610ab0d40ad3be1","price":"0.32","side":"BUY","size":"240"},{"asset_id":"39272994714739463168905443499424551362424437245880253267329605556587274644733","best_ask":"0.62","best_bid":"0.61","hash":"8203c1abb356ee0470eb4b79d12c9493c6d0a3ce","price":"0.68","side":"SELL","size":"240"}],"timestamp":"1785204061691"},"payload_hash":"3bdf72d4b53f04eda8907e0173dc3b9a40ff757f784a94a4c56b14a9e9c5fa92","raw_frame":"{\"market\":\"0xda6f0e0e93fc8469e0159a166028d017bddbc162b86f66bac90391379603d962\", \"price_changes\":[{\"asset_id\":\"20893381255801015515826997628594359667013752732428989472914000440642900266717\", \"price\":\"0.32\", \"size\":\"240\", \"side\":\"BUY\", \"hash\":\"4ba783335cf67fec5d9339aab610ab0d40ad3be1\", \"best_bid\":\"0.38\", \"best_ask\":\"0.39\"}, {\"asset_id\":\"39272994714739463168905443499424551362424437245880253267329605556587274644733\", \"price\":\"0.68\", \"size\":\"240\", \"side\":\"SELL\", \"hash\":\"8203c1abb356ee0470eb4b79d12c9493c6d0a3ce\", \"best_bid\":\"0.61\", \"best_ask\":\"0.62\"}], \"timestamp\":\"1785204061691\", \"event_type\":\"price_change\"}","received_at":"2026-07-28T02:01:09.407308Z","schema_version":"clob-market-ws.price_change.v1","sequence":null,"server_hash":null,"server_timestamp":"1785204061691","session_id":"d2757dd6dad94f3b9fe67e8dbf1adc37","source":"clob_market_ws"},"received_at":"2026-07-28T02:01:09.407308Z","record_id":"a4e0cc866f3e8f55e62dce122f7a0de0f2c3eac5a9257d2cba0b2058435a234a","schema_fingerprint":"4aa3821a28b0b7c2400bc59aba4bcc0a76e971dadd19610d3ad38c768e124dc7","schema_version":"edge-lab-recorder.raw.v1","sequence":null,"source":"clob_market_ws"}
{"event_at":"2026-07-28T02:01:01.698000Z","event_fingerprint":"b0efd5f050918334b7995e59cd0e65d67730cd7bdf7f1bba604a86748271a870","payload":{"connection_id":"5d29200f65794d4d9ab6ef271f045a9b","event_at":"2026-07-28T02:01:01.698000Z","event_type":"price_change","frame_hash":"8a5d0cd57ba98296bd56c7e07d9c46f740cc9535d23cfca7a913ec12773287e6","frame_index":0,"kind":"data","monotonic_ns":306052415962000,"payload":{"event_type":"price_change","market":"0xda6f0e0e93fc8469e0159a166028d017bddbc162b86f66bac90391379603d962","price_changes":[{"asset_id":"39272994714739463168905443499424551362424437245880253267329605556587274644733","best_ask":"0.62","best_bid":"0.61","hash":"a9457b208e1723fe6bf5cb8df0645d6fcaba8336","price":"0.6","side":"BUY","size":"89.6"},{"asset_id":"20893381255801015515826997628594359667013752732428989472914000440642900266717","best_ask":"0.39","best_bid":"0.38","hash":"c88b4170c265044d4782775451f5d868a348743d","price":"0.4","side":"SELL","size":"89.6"}],"timestamp":"1785204061698"},"payload_hash":"78305b6bc8b73f11fc0ce47c8e9b3d0512ea8fa446cbb2fd34305f32e64c36e3","raw_frame":"{\"market\":\"0xda6f0e0e93fc8469e0159a166028d017bddbc162b86f66bac90391379603d962\", \"price_changes\":[{\"asset_id\":\"39272994714739463168905443499424551362424437245880253267329605556587274644733\", \"price\":\"0.6\", \"size\":\"89.6\", \"side\":\"BUY\", \"hash\":\"a9457b208e1723fe6bf5cb8df0645d6fcaba8336\", \"best_bid\":\"0.61\", \"best_ask\":\"0.62\"}, {\"asset_id\":\"20893381255801015515826997628594359667013752732428989472914000440642900266717\", \"price\":\"0.4\", \"size\":\"89.6\", \"side\":\"SELL\", \"hash\":\"c88b4170c265044d4782775451f5d868a348743d\", \"best_bid\":\"0.38\", \"best_ask\":\"0.39\"}], \"timestamp\":\"1785204061698\", \"event_type\":\"price_change\"}","received_at":"2026-07-28T02:01:09.412017Z","schema_version":"clob-market-ws.price_change.v1","sequence":null,"server_hash":null,"server_timestamp":"1785204061698","session_id":"d2757dd6dad94f3b9fe67e8dbf1adc37","source":"clob_market_ws"},"received_at":"2026-07-28T02:01:09.412017Z","record_id":"3462876ce9c5a840eef58a036f1c539e7e59c00da94946d8f63f2bf1f0e79772","schema_fingerprint":"4aa3821a28b0b7c2400bc59aba4bcc0a76e971dadd19610d3ad38c768e124dc7","schema_version":"edge-lab-recorder.raw.v1","sequence":null,"source":"clob_market_ws"}
{"event_at":"2026-07-28T02:01:01.698000Z","event_fingerprint":"c5296b89ca41d20585d71e2989128a148982eb6ccdcba4530f6012e9e335288f","payload":{"connection_id":"5d29200f65794d4d9ab6ef271f045a9b","event_at":"2026-07-28T02:01:01.698000Z","event_type":"price_change","frame_hash":"5b7ac855989765c50461aba6227078558a68f7d5724ff8ae8ab4b4ab07263ba2","frame_index":0,"kind":"data","monotonic_ns":306052421114708,"payload":{"event_type":"price_change","market":"0xda6f0e0e93fc8469e0159a166028d017bddbc162b86f66bac90391379603d962","price_changes":[{"asset_id":"20893381255801015515826997628594359667013752732428989472914000440642900266717","best_ask":"0.39","best_bid":"0.38","hash":"c88b4170c265044d4782775451f5d868a348743d","price":"0.34","side":"BUY","size":"50"},{"asset_id":"39272994714739463168905443499424551362424437245880253267329605556587274644733","best_ask":"0.62","best_bid":"0.61","hash":"a9457b208e1723fe6bf5cb8df0645d6fcaba8336","price":"0.66","side":"SELL","size":"50"}],"timestamp":"1785204061698"},"payload_hash":"3359e2a5a4446c111b9e7f818ee6801ae066fd46ea176af97005f0f92759fc74","raw_frame":"{\"market\":\"0xda6f0e0e93fc8469e0159a166028d017bddbc162b86f66bac90391379603d962\", \"price_changes\":[{\"asset_id\":\"20893381255801015515826997628594359667013752732428989472914000440642900266717\", \"price\":\"0.34\", \"size\":\"50\", \"side\":\"BUY\", \"hash\":\"c88b4170c265044d4782775451f5d868a348743d\", \"best_bid\":\"0.38\", \"best_ask\":\"0.39\"}, {\"asset_id\":\"39272994714739463168905443499424551362424437245880253267329605556587274644733\", \"price\":\"0.66\", \"size\":\"50\", \"side\":\"SELL\", \"hash\":\"a9457b208e1723fe6bf5cb8df0645d6fcaba8336\", \"best_bid\":\"0.61\", \"best_ask\":\"0.62\"}], \"timestamp\":\"1785204061698\", \"event_type\":\"price_change\"}","received_at":"2026-07-28T02:01:09.417168Z","schema_version":"clob-market-ws.price_change.v1","sequence":null,"server_hash":null,"server_timestamp":"1785204061698","session_id":"d2757dd6dad94f3b9fe67e8dbf1adc37","source":"clob_market_ws"},"received_at":"2026-07-28T02:01:09.417168Z","record_id":"87c8b49a1bc5ec1d4054a0884c6de6b3f8469f988f6fddf2adbae561a3eee5a2","schema_fingerprint":"4aa3821a28b0b7c2400bc59aba4bcc0a76e971dadd19610d3ad38c768e124dc7","schema_version":"edge-lab-recorder.raw.v1","sequence":null,"source":"clob_market_ws"}
{"event_at":"2026-07-28T02:01:01.698000Z","event_fingerprint":"b28dad567e8c32c1b172da1dc5e2c8f636a7c41f7cc6efc20803a20645e614c1","payload":{"connection_id":"5d29200f65794d4d9ab6ef271f045a9b","event_at":"2026-07-28T02:01:01.698000Z","event_type":"price_change","frame_hash":"b89648e99365428496049e5b074c7e55201636077d843437a78364e19f7d8212","frame_index":0,"kind":"data","monotonic_ns":306052425873416,"payload":{"event_type":"price_change","market":"0xda6f0e0e93fc8469e0159a166028d017bddbc162b86f66bac90391379603d962","price_changes":[{"asset_id":"20893381255801015515826997628594359667013752732428989472914000440642900266717","best_ask":"0.39","best_bid":"0.38","hash":"c88b4170c265044d4782775451f5d868a348743d","price":"0.33","side":"BUY","size":"111"},{"asset_id":"39272994714739463168905443499424551362424437245880253267329605556587274644733","best_ask":"0.62","best_bid":"0.61","hash":"a9457b208e1723fe6bf5cb8df0645d6fcaba8336","price":"0.67","side":"SELL","size":"111"}],"timestamp":"1785204061698"},"payload_hash":"4de59c4a48121963f80563c3babd87b558c9731bbd3545c92387984baa2a19d7","raw_frame":"{\"market\":\"0xda6f0e0e93fc8469e0159a166028d017bddbc162b86f66bac90391379603d962\", \"price_changes\":[{\"asset_id\":\"20893381255801015515826997628594359667013752732428989472914000440642900266717\", \"price\":\"0.33\", \"size\":\"111\", \"side\":\"BUY\", \"hash\":\"c88b4170c265044d4782775451f5d868a348743d\", \"best_bid\":\"0.38\", \"best_ask\":\"0.39\"}, {\"asset_id\":\"39272994714739463168905443499424551362424437245880253267329605556587274644733\", \"price\":\"0.67\", \"size\":\"111\", \"side\":\"SELL\", \"hash\":\"a9457b208e1723fe6bf5cb8df0645d6fcaba8336\", \"best_bid\":\"0.61\", \"best_ask\":\"0.62\"}], \"timestamp\":\"1785204061698\", \"event_type\":\"price_change\"}","received_at":"2026-07-28T02:01:09.421929Z","schema_version":"clob-market-ws.price_change.v1","sequence":null,"server_hash":null,"server_timestamp":"1785204061698","session_id":"d2757dd6dad94f3b9fe67e8dbf1adc37","source":"clob_market_ws"},"received_at":"2026-07-28T02:01:09.421929Z","record_id":"d79e9f5025874e23065651a382b920672f7742c83e4e4e544639bc1be1e6dec3","schema_fingerprint":"4aa3821a28b0b7c2400bc59aba4bcc0a76e971dadd19610d3ad38c768e124dc7","schema_version":"edge-lab-recorder.raw.v1","sequence":null,"source":"clob_market_ws"}
{"event_at":"2026-07-28T02:01:01.701000Z","event_fingerprint":"b72b3076297cfee1df1b14d95701d8fabb3bc74ba105dc5b596a488f38a50c49","payload":{"connection_id":"5d29200f65794d4d9ab6ef271f045a9b","event_at":"2026-07-28T02:01:01.701000Z","event_type":"price_change","frame_hash":"210c0aeb2b973f7dbf22abe6ef82d9ac3e4362c1f26dccf89c2f993104d43cee","frame_index":0,"kind":"data","monotonic_ns":306052431344375,"payload":{"event_type":"price_change","market":"0xda6f0e0e93fc8469e0159a166028d017bddbc162b86f66bac90391379603d962","price_changes":[{"asset_id":"39272994714739463168905443499424551362424437245880253267329605556587274644733","best_ask":"0.62","best_bid":"0.61","hash":"0993262f5f9010d24a709c45db8177f8e45b0605","price":"0.53","side":"BUY","size":"192"},{"asset_id":"20893381255801015515826997628594359667013752732428989472914000440642900266717","best_ask":"0.39","best_bid":"0.38","hash":"71c814b60d5506f7d154524ab4a294ffe79de574","price":"0.47","side":"SELL","size":"192"}],"timestamp":"1785204061701"},"payload_hash":"852c942007aab8a17919e33541bb83adb1cb88fe25148147be1621fa1918802a","raw_frame":"{\"market\":\"0xda6f0e0e93fc8469e0159a166028d017bddbc162b86f66bac90391379603d962\", \"price_changes\":[{\"asset_id\":\"39272994714739463168905443499424551362424437245880253267329605556587274644733\", \"price\":\"0.53\", \"size\":\"192\", \"side\":\"BUY\", \"hash\":\"0993262f5f9010d24a709c45db8177f8e45b0605\", \"best_bid\":\"0.61\", \"best_ask\":\"0.62\"}, {\"asset_id\":\"20893381255801015515826997628594359667013752732428989472914000440642900266717\", \"price\":\"0.47\", \"size\":\"192\", \"side\":\"SELL\", \"hash\":\"71c814b60d5506f7d154524ab4a294ffe79de574\", \"best_bid\":\"0.38\", \"best_ask\":\"0.39\"}], \"timestamp\":\"1785204061701\", \"event_type\":\"price_change\"}","received_at":"2026-07-28T02:01:09.427399Z","schema_version":"clob-market-ws.price_change.v1","sequence":null,"server_hash":null,"server_timestamp":"1785204061701","session_id":"d2757dd6dad94f3b9fe67e8dbf1adc37","source":"clob_market_ws"},"received_at":"2026-07-28T02:01:09.427399Z","record_id":"06aba45101b473d3352d663b2367a966239caed6e2cff0fad8db557923ed45c2","schema_fingerprint":"4aa3821a28b0b7c2400bc59aba4bcc0a76e971dadd19610d3ad38c768e124dc7","schema_version":"edge-lab-recorder.raw.v1","sequence":null,"source":"clob_market_ws"}
{"event_at":"2026-07-28T02:01:01.701000Z","event_fingerprint":"41fe5bb65f4556e8eaddf26de870a07eafa3b1902dad0b17ae89b73da3bba0a8","payload":{"connection_id":"5d29200f65794d4d9ab6ef271f045a9b","event_at":"2026-07-28T02:01:01.701000Z","event_type":"price_change","frame_hash":"4dcb7f381febd3a74f8344ba4a49c0a12dfcc37434ce9d56e02c99f2c98c452a","frame_index":0,"kind":"data","monotonic_ns":306052437808708,"payload":{"event_type":"price_change","market":"0xda6f0e0e93fc8469e0159a166028d017bddbc162b86f66bac90391379603d962","price_changes":[{"asset_id":"39272994714739463168905443499424551362424437245880253267329605556587274644733","best_ask":"0.62","best_bid":"0.61","hash":"49029af43a90425479cdd7cd748b064bbbfcfa03","price":"0.59","side":"BUY","size":"101.6"},{"asset_id":"20893381255801015515826997628594359667013752732428989472914000440642900266717","best_ask":"0.39","best_bid":"0.38","hash":"108cae96b728e58dd9ffd2c1f2361e1685941b1b","price":"0.41","side":"SELL","size":"101.6"}],"timestamp":"1785204061701"},"payload_hash":"e29a40b03e940c0e6c692901578b5a527761348ad70cc440dbc4fe40dc2691ab","raw_frame":"{\"market\":\"0xda6f0e0e93fc8469e0159a166028d017bddbc162b86f66bac90391379603d962\", \"price_changes\":[{\"asset_id\":\"39272994714739463168905443499424551362424437245880253267329605556587274644733\", \"price\":\"0.59\", \"size\":\"101.6\", \"side\":\"BUY\", \"hash\":\"49029af43a90425479cdd7cd748b064bbbfcfa03\", \"best_bid\":\"0.61\", \"best_ask\":\"0.62\"}, {\"asset_id\":\"20893381255801015515826997628594359667013752732428989472914000440642900266717\", \"price\":\"0.41\", \"size\":\"101.6\", \"side\":\"SELL\", \"hash\":\"108cae96b728e58dd9ffd2c1f2361e1685941b1b\", \"best_bid\":\"0.38\", \"best_ask\":\"0.39\"}], \"timestamp\":\"1785204061701\", \"event_type\":\"price_change\"}","received_at":"2026-07-28T02:01:09.433863Z","schema_version":"clob-market-ws.price_change.v1","sequence":null,"server_hash":null,"server_timestamp":"1785204061701","session_id":"d2757dd6dad94f3b9fe67e8dbf1adc37","source":"clob_market_ws"},"received_at":"2026-07-28T02:01:09.433863Z","record_id":"2beb7f521c75d1112293d4b528511e598e80a3cdfffddbd66fdfdda78b9ae6b6","schema_fingerprint":"4aa3821a28b0b7c2400bc59aba4bcc0a76e971dadd19610d3ad38c768e124dc7","schema_version":"edge-lab-recorder.raw.v1","sequence":null,"source":"clob_market_ws"}
{"event_at":"2026-07-28T02:01:01.705000Z","event_fingerprint":"239225ead2d21c46dad9e39c0f9a903068c2ee3ce1d6e8765365e9dca3e1d96e","payload":{"connection_id":"5d29200f65794d4d9ab6ef271f045a9b","event_at":"2026-07-28T02:01:01.705000Z","event_type":"price_change","frame_hash":"00fa9f188094e52f1647ae98715f7e0f23f83a5d181e95ce9b2a03ec260e8e06","frame_index":0,"kind":"data","monotonic_ns":306052442827416,"payload":{"event_type":"price_change","market":"0xda6f0e0e93fc8469e0159a166028d017bddbc162b86f66bac90391379603d962","price_changes":[{"asset_id":"20893381255801015515826997628594359667013752732428989472914000440642900266717","best_ask":"0.39","best_bid":"0.38","hash":"011eac50a5b6660d7860e985b0ba704f08d65e0a","price":"0.31","side":"BUY","size":"163"},{"asset_id":"39272994714739463168905443499424551362424437245880253267329605556587274644733","best_ask":"0.62","best_bid":"0.61","hash":"1eaa26bcffc42a72556fc48f3fd3bc229c8d0719","price":"0.69","side":"SELL","size":"163"}],"timestamp":"1785204061705"},"payload_hash":"d6db1e8a75c3caa4c28e93abe38e34ea22f27ed82fa1ee841567f71d605c4cfd","raw_frame":"{\"market\":\"0xda6f0e0e93fc8469e0159a166028d017bddbc162b86f66bac90391379603d962\", \"price_changes\":[{\"asset_id\":\"20893381255801015515826997628594359667013752732428989472914000440642900266717\", \"price\":\"0.31\", \"size\":\"163\", \"side\":\"BUY\", \"hash\":\"011eac50a5b6660d7860e985b0ba704f08d65e0a\", \"best_bid\":\"0.38\", \"best_ask\":\"0.39\"}, {\"asset_id\":\"39272994714739463168905443499424551362424437245880253267329605556587274644733\", \"price\":\"0.69\", \"size\":\"163\", \"side\":\"SELL\", \"hash\":\"1eaa26bcffc42a72556fc48f3fd3bc229c8d0719\", \"best_bid\":\"0.61\", \"best_ask\":\"0.62\"}], \"timestamp\":\"1785204061705\", \"event_type\":\"price_change\"}","received_at":"2026-07-28T02:01:09.438882Z","schema_version":"clob-market-ws.price_change.v1","sequence":null,"server_hash":null,"server_timestamp":"1785204061705","session_id":"d2757dd6dad94f3b9fe67e8dbf1adc37","source":"clob_market_ws"},"received_at":"2026-07-28T02:01:09.438882Z","record_id":"b96f919fb471d00dd4a46a85bac91cce04f889ea4ff2624b7ecd1898ecdd913c","schema_fingerprint":"4aa3821a28b0b7c2400bc59aba4bcc0a76e971dadd19610d3ad38c768e124dc7","schema_version":"edge-lab-recorder.raw.v1","sequence":null,"source":"clob_market_ws"}
{"event_at":"2026-07-28T02:01:01.709000Z","event_fingerprint":"f4eee6d764487f13540d0f18fce34f9c4a784147b8886ea39691e935b9c4a871","payload":{"connection_id":"5d29200f65794d4d9ab6ef271f045a9b","event_at":"2026-07-28T02:01:01.709000Z","event_type":"price_change","frame_hash":"7c0b83c4eaa324991ecedb90af3c1aecc4e8944137e6ecdbfd7d2f57d7e9e509","frame_index":0,"kind":"data","monotonic_ns":306052447677208,"payload":{"event_type":"price_change","market":"0xda6f0e0e93fc8469e0159a166028d017bddbc162b86f66bac90391379603d962","price_changes":[{"asset_id":"20893381255801015515826997628594359667013752732428989472914000440642900266717","best_ask":"0.39","best_bid":"0.38","hash":"7d90ec1d9bc11d846ae10804715918bdf2f66023","price":"0.3","side":"BUY","size":"272.3"},{"asset_id":"39272994714739463168905443499424551362424437245880253267329605556587274644733","best_ask":"0.62","best_bid":"0.61","hash":"e1b005f3be9331ec7263ee66c44cbd5786d702d8","price":"0.7","side":"SELL","size":"272.3"}],"timestamp":"1785204061709"},"payload_hash":"55da6697c44323ecb2316ef88b40aa765a423e498ca8d195c2ba5434d85b2fd4","raw_frame":"{\"market\":\"0xda6f0e0e93fc8469e0159a166028d017bddbc162b86f66bac90391379603d962\", \"price_changes\":[{\"asset_id\":\"20893381255801015515826997628594359667013752732428989472914000440642900266717\", \"price\":\"0.3\", \"size\":\"272.3\", \"side\":\"BUY\", \"hash\":\"7d90ec1d9bc11d846ae10804715918bdf2f66023\", \"best_bid\":\"0.38\", \"best_ask\":\"0.39\"}, {\"asset_id\":\"39272994714739463168905443499424551362424437245880253267329605556587274644733\", \"price\":\"0.7\", \"size\":\"272.3\", \"side\":\"SELL\", \"hash\":\"e1b005f3be9331ec7263ee66c44cbd5786d702d8\", \"best_bid\":\"0.61\", \"best_ask\":\"0.62\"}], \"timestamp\":\"1785204061709\", \"event_type\":\"price_change\"}","received_at":"2026-07-28T02:01:09.443732Z","schema_version":"clob-market-ws.price_change.v1","sequence":null,"server_hash":null,"server_timestamp":"1785204061709","session_id":"d2757dd6dad94f3b9fe67e8dbf1adc37","source":"clob_market_ws"},"received_at":"2026-07-28T02:01:09.443732Z","record_id":"8e3749c31f7e90765cd82923d622ad0891ddb7ba0705bb5d7dc64347b743c27c","schema_fingerprint":"4aa3821a28b0b7c2400bc59aba4bcc0a76e971dadd19610d3ad38c768e124dc7","schema_version":"edge-lab-recorder.raw.v1","sequence":null,"source":"clob_market_ws"}
{"event_at":"2026-07-28T02:01:01.710000Z","event_fingerprint":"aa44846a13c9e4e3a104c3e66606378dd21cbf1f554a63240d9aa16ceddcce8f","payload":{"connection_id":"5d29200f65794d4d9ab6ef271f045a9b","event_at":"2026-07-28T02:01:01.710000Z","event_type":"price_change","frame_hash":"44c04cc7cf54f760c871e4338b519c9e6b09fa71534e01c61eff8387377f5ea5","frame_index":0,"kind":"data","monotonic_ns":306052453025291,"payload":{"event_type":"price_change","market":"0xda6f0e0e93fc8469e0159a166028d017bddbc162b86f66bac90391379603d962","price_changes":[{"asset_id":"20893381255801015515826997628594359667013752732428989472914000440642900266717","best_ask":"0.39","best_bid":"0.38","hash":"f419f6cf837b92088901fbdcb1ca8a04173df30f","price":"0.33","side":"BUY","size":"50"},{"asset_id":"39272994714739463168905443499424551362424437245880253267329605556587274644733","best_ask":"0.62","best_bid":"0.61","hash":"a7f251f6b654d807d122cd01b085a091523e5a00","price":"0.67","side":"SELL","size":"50"}],"timestamp":"1785204061710"},"payload_hash":"361f0d1b11bca2c162d187360c56207058c3284006ff255d4344d64364bf18de","raw_frame":"{\"market\":\"0xda6f0e0e93fc8469e0159a166028d017bddbc162b86f66bac90391379603d962\", \"price_changes\":[{\"asset_id\":\"20893381255801015515826997628594359667013752732428989472914000440642900266717\", \"price\":\"0.33\", \"size\":\"50\", \"side\":\"BUY\", \"hash\":\"f419f6cf837b92088901fbdcb1ca8a04173df30f\", \"best_bid\":\"0.38\", \"best_ask\":\"0.39\"}, {\"asset_id\":\"39272994714739463168905443499424551362424437245880253267329605556587274644733\", \"price\":\"0.67\", \"size\":\"50\", \"side\":\"SELL\", \"hash\":\"a7f251f6b654d807d122cd01b085a091523e5a00\", \"best_bid\":\"0.61\", \"best_ask\":\"0.62\"}], \"timestamp\":\"1785204061710\", \"event_type\":\"price_change\"}","received_at":"2026-07-28T02:01:09.449077Z","schema_version":"clob-market-ws.price_change.v1","sequence":null,"server_hash":null,"server_timestamp":"1785204061710","session_id":"d2757dd6dad94f3b9fe67e8dbf1adc37","source":"clob_market_ws"},"received_at":"2026-07-28T02:01:09.449077Z","record_id":"499c362b5020906fe0184c240846b6a743f34f35f8eeef47498bda0d8d010c0b","schema_fingerprint":"4aa3821a28b0b7c2400bc59aba4bcc0a76e971dadd19610d3ad38c768e124dc7","schema_version":"edge-lab-recorder.raw.v1","sequence":null,"source":"clob_market_ws"}
{"event_at":"2026-07-28T02:01:01.711000Z","event_fingerprint":"e038568e4e2a7885cbd40774f947b96d03430f8b586dfe6ff4e6d91873f8a962","payload":{"connection_id":"5d29200f65794d4d9ab6ef271f045a9b","event_at":"2026-07-28T02:01:01.711000Z","event_type":"price_change","frame_hash":"bcf47d4b2c0e78304401221e79249f6ca24dab7fa2198478cf8022dabe64a268","frame_index":0,"kind":"data","monotonic_ns":306052458753000,"payload":{"event_type":"price_change","market":"0xda6f0e0e93fc8469e0159a166028d017bddbc162b86f66bac90391379603d962","price_changes":[{"asset_id":"20893381255801015515826997628594359667013752732428989472914000440642900266717","best_ask":"0.39","best_bid":"0.38","hash":"f98635babf02f489c9191caed777d40dfc3e7d23","price":"0.31","side":"BUY","size":"133"},{"asset_id":"39272994714739463168905443499424551362424437245880253267329605556587274644733","best_ask":"0.62","best_bid":"0.61","hash":"8dea89b1ece07370a7e3218dcef0de263ccbc21c","price":"0.69","side":"SELL","size":"133"}],"timestamp":"1785204061711"},"payload_hash":"17c342461b969fb82fca735c51c9d0a3d3c45d119150093946790f4bb45e1aab","raw_frame":"{\"market\":\"0xda6f0e0e93fc8469e0159a166028d017bddbc162b86f66bac90391379603d962\", \"price_changes\":[{\"asset_id\":\"20893381255801015515826997628594359667013752732428989472914000440642900266717\", \"price\":\"0.31\", \"size\":\"133\", \"side\":\"BUY\", \"hash\":\"f98635babf02f489c9191caed777d40dfc3e7d23\", \"best_bid\":\"0.38\", \"best_ask\":\"0.39\"}, {\"asset_id\":\"39272994714739463168905443499424551362424437245880253267329605556587274644733\", \"price\":\"0.69\", \"size\":\"133\", \"side\":\"SELL\", \"hash\":\"8dea89b1ece07370a7e3218dcef0de263ccbc21c\", \"best_bid\":\"0.61\", \"best_ask\":\"0.62\"}], \"timestamp\":\"1785204061711\", \"event_type\":\"price_change\"}","received_at":"2026-07-28T02:01:09.454807Z","schema_version":"clob-market-ws.price_change.v1","sequence":null,"server_hash":null,"server_timestamp":"1785204061711","session_id":"d2757dd6dad94f3b9fe67e8dbf1adc37","source":"clob_market_ws"},"received_at":"2026-07-28T02:01:09.454807Z","record_id":"448970ad7dcae95495084d6559f28e073c6a93ecd0449d8615a7cfa6257aacf7","schema_fingerprint":"4aa3821a28b0b7c2400bc59aba4bcc0a76e971dadd19610d3ad38c768e124dc7","schema_version":"edge-lab-recorder.raw.v1","sequence":null,"source":"clob_market_ws"}
{"event_at":"2026-07-28T02:01:01.711000Z","event_fingerprint":"5ed4007447b0b0343fb575d5a1a1ca9cb9a9c7cb4caf69463bb76ba41ef6d2d3","payload":{"connection_id":"5d29200f65794d4d9ab6ef271f045a9b","event_at":"2026-07-28T02:01:01.711000Z","event_type":"price_change","frame_hash":"ff5e43730c2c879b27bbb07bb54f3b14ad91c6bace7a663e296ebbaf9782af7f","frame_index":0,"kind":"data","monotonic_ns":306052465230875,"payload":{"event_type":"price_change","market":"0xda6f0e0e93fc8469e0159a166028d017bddbc162b86f66bac90391379603d962","price_changes":[{"asset_id":"39272994714739463168905443499424551362424437245880253267329605556587274644733","best_ask":"0.62","best_bid":"0.61","hash":"ce39a3cd38e532e560157eac1b6f14ea1422b83a","price":"0.02","side":"BUY","size":"1638.1"},{"asset_id":"20893381255801015515826997628594359667013752732428989472914000440642900266717","best_ask":"0.39","best_bid":"0.38","hash":"abfd5180d9cd02d55d582dc6f17646a7cdc8823c","price":"0.98","side":"SELL","size":"1638.1"}],"timestamp":"1785204061711"},"payload_hash":"48ce57373bdffc0b8147eb9d1da963498fa48ae94c9372b25068efcc9308f26d","raw_frame":"{\"market\":\"0xda6f0e0e93fc8469e0159a166028d017bddbc162b86f66bac90391379603d962\", \"price_changes\":[{\"asset_id\":\"39272994714739463168905443499424551362424437245880253267329605556587274644733\", \"price\":\"0.02\", \"size\":\"1638.1\", \"side\":\"BUY\", \"hash\":\"ce39a3cd38e532e560157eac1b6f14ea1422b83a\", \"best_bid\":\"0.61\", \"best_ask\":\"0.62\"}, {\"asset_id\":\"20893381255801015515826997628594359667013752732428989472914000440642900266717\", \"price\":\"0.98\", \"size\":\"1638.1\", \"side\":\"SELL\", \"hash\":\"abfd5180d9cd02d55d582dc6f17646a7cdc8823c\", \"best_bid\":\"0.38\", \"best_ask\":\"0.39\"}], \"timestamp\":\"1785204061711\", \"event_type\":\"price_change\"}","received_at":"2026-07-28T02:01:09.461286Z","schema_version":"clob-market-ws.price_change.v1","sequence":null,"server_hash":null,"server_timestamp":"1785204061711","session_id":"d2757dd6dad94f3b9fe67e8dbf1adc37","source":"clob_market_ws"},"received_at":"2026-07-28T02:01:09.461286Z","record_id":"c82d1cb9b365a97e07bdb24940246c58122a86058e3e3fd68d2c656a0bc4e41f","schema_fingerprint":"4aa3821a28b0b7c2400bc59aba4bcc0a76e971dadd19610d3ad38c768e124dc7","schema_version":"edge-lab-recorder.raw.v1","sequence":null,"source":"clob_market_ws"}
{"event_at":"2026-07-28T02:01:01.712000Z","event_fingerprint":"d9c4934c728dd2e016a0828eb904c15032bf351e257aad9012b5c0cc35cae9b6","payload":{"connection_id":"5d29200f65794d4d9ab6ef271f045a9b","event_at":"2026-07-28T02:01:01.712000Z","event_type":"price_change","frame_hash":"14bf788c4cdd79091e5a1e93a1f3f4677ccd7572dd65a298478321ff95a2b6c5","frame_index":0,"kind":"data","monotonic_ns":306052470216458,"payload":{"event_type":"price_change","market":"0xda6f0e0e93fc8469e0159a166028d017bddbc162b86f66bac90391379603d962","price_changes":[{"asset_id":"20893381255801015515826997628594359667013752732428989472914000440642900266717","best_ask":"0.39","best_bid":"0.38","hash":"865ea01f2b3f682bfa3e6b6ded4e82de3517ff19","price":"0.32","side":"BUY","size":"246"},{"asset_id":"39272994714739463168905443499424551362424437245880253267329605556587274644733","best_ask":"0.62","best_bid":"0.61","hash":"4a79202336f5298b5474f518bf6640caeea2930f","price":"0.68","side":"SELL","size":"246"}],"timestamp":"1785204061712"},"payload_hash":"b79c54977ea4072f669377ca96f2c48623d061df50ae5f3d141fef38ea47e9b8","raw_frame":"{\"market\":\"0xda6f0e0e93fc8469e0159a166028d017bddbc162b86f66bac90391379603d962\", \"price_changes\":[{\"asset_id\":\"20893381255801015515826997628594359667013752732428989472914000440642900266717\", \"price\":\"0.32\", \"size\":\"246\", \"side\":\"BUY\", \"hash\":\"865ea01f2b3f682bfa3e6b6ded4e82de3517ff19\", \"best_bid\":\"0.38\", \"best_ask\":\"0.39\"}, {\"asset_id\":\"39272994714739463168905443499424551362424437245880253267329605556587274644733\", \"price\":\"0.68\", \"size\":\"246\", \"side\":\"SELL\", \"hash\":\"4a79202336f5298b5474f518bf6640caeea2930f\", \"best_bid\":\"0.61\", \"best_ask\":\"0.62\"}], \"timestamp\":\"1785204061712\", \"event_type\":\"price_change\"}","received_at":"2026-07-28T02:01:09.466271Z","schema_version":"clob-market-ws.price_change.v1","sequence":null,"server_hash":null,"server_timestamp":"1785204061712","session_id":"d2757dd6dad94f3b9fe67e8dbf1adc37","source":"clob_market_ws"},"received_at":"2026-07-28T02:01:09.466271Z","record_id":"d81bba5bbdea325e64a4509453788d41ed6e94a3010125e3e5a33ae625326663","schema_fingerprint":"4aa3821a28b0b7c2400bc59aba4bcc0a76e971dadd19610d3ad38c768e124dc7","schema_version":"edge-lab-recorder.raw.v1","sequence":null,"source":"clob_market_ws"}
