{"event_at":"2026-07-28T02:06:01.449000Z","event_fingerprint":"cedc53813485b5cad08fba1cd42fb41ab30a74e28aa906bf69468d89f9d43a72","payload":{"connection_id":"5d29200f65794d4d9ab6ef271f045a9b","event_at":"2026-07-28T02:06:01.449000Z","event_type":"price_change","frame_hash":"db156cf01c30fbdfab5edfb26142a708691176afd85ccd4082597ecb34d7b6b1","frame_index":0,"kind":"data","monotonic_ns":306344547020125,"payload":{"event_type":"price_change","market":"0xda6f0e0e93fc8469e0159a166028d017bddbc162b86f66bac90391379603d962","price_changes":[{"asset_id":"39272994714739463168905443499424551362424437245880253267329605556587274644733","best_ask":"0.74","best_bid":"0.73","hash":"f6e82c28f87ab3ecf3a4b9959d35f8056b9eba28","price":"0.73","side":"BUY","size":"54.2"},{"asset_id":"20893381255801015515826997628594359667013752732428989472914000440642900266717","best_ask":"0.27","best_bid":"0.26","hash":"e4070d581de5760f532667e1d89a6e1ec8fb38bf","price":"0.27","side":"SELL","size":"54.2"}],"timestamp":"1785204361449"},"payload_hash":"4aacc54a0e7b9f369c83f5eae5c48950578305a7d9d0b99db3d51bf4142824a3","raw_frame":"{\"market\":\"0xda6f0e0e93fc8469e0159a166028d017bddbc162b86f66bac90391379603d962\", \"price_changes\":[{\"asset_id\":\"39272994714739463168905443499424551362424437245880253267329605556587274644733\", \"price\":\"0.73\", \"size\":\"54.2\", \"side\":\"BUY\", \"hash\":\"f6e82c28f87ab3ecf3a4b9959d35f8056b9eba28\", \"best_bid\":\"0.73\", \"best_ask\":\"0.74\"}, {\"asset_id\":\"20893381255801015515826997628594359667013752732428989472914000440642900266717\", \"price\":\"0.27\", \"size\":\"54.2\", \"side\":\"SELL\", \"hash\":\"e4070d581de5760f532667e1d89a6e1ec8fb38bf\", \"best_bid\":\"0.26\", \"best_ask\":\"0.27\"}], \"timestamp\":\"1785204361449\", \"event_type\":\"price_change\"}","received_at":"2026-07-28T02:06:01.540390Z","schema_version":"clob-market-ws.price_change.v1","sequence":null,"server_hash":null,"server_timestamp":"1785204361449","session_id":"d2757dd6dad94f3b9fe67e8dbf1adc37","source":"clob_market_ws"},"received_at":"2026-07-28T02:06:01.540390Z","record_id":"caf8d3fd0366d9c9705e076b3b241ac8799ea46c87a20cbd5d450d75d6e0d426","schema_fingerprint":"4aa3821a28b0b7c2400bc59aba4bcc0a76e971dadd19610d3ad38c768e124dc7","schema_version":"edge-lab-recorder.raw.v1","sequence":null,"source":"clob_market_ws"}
{"event_at":"2026-07-28T02:06:01.458000Z","event_fingerprint":"52d0a8dfed179f746c9197cf36ab57d2d83ffa4cbf6b737517e8b9900859258f","payload":{"connection_id":"5d29200f65794d4d9ab6ef271f045a9b","event_at":"2026-07-28T02:06:01.458000Z","event_type":"price_change","frame_hash":"f8fc570146b7648e75348b29d580d863f716fbde179d254de7314434c1afb53d","frame_index":0,"kind":"data","monotonic_ns":306344557310666,"payload":{"event_type":"price_change","market":"0xda6f0e0e93fc8469e0159a166028d017bddbc162b86f66bac90391379603d962","price_changes":[{"asset_id":"20893381255801015515826997628594359667013752732428989472914000440642900266717","best_ask":"0.27","best_bid":"0.26","hash":"58ab237888f2a510fe4db1fee6a50d5d2f884b6e","price":"0.17","side":"BUY","size":"226.3"},{"asset_id":"39272994714739463168905443499424551362424437245880253267329605556587274644733","best_ask":"0.74","best_bid":"0.73","hash":"87dfa8dd94cff4ab34e99817f723512efdad0863","price":"0.83","side":"SELL","size":"226.3"}],"timestamp":"1785204361458"},"payload_hash":"6b8b8e1bee28880957ebd1f0298917d0078fd82136216c46fd75530f2969f19c","raw_frame":"{\"market\":\"0xda6f0e0e93fc8469e0159a166028d017bddbc162b86f66bac90391379603d962\", \"price_changes\":[{\"asset_id\":\"20893381255801015515826997628594359667013752732428989472914000440642900266717\", \"price\":\"0.17\", \"size\":\"226.3\", \"side\":\"BUY\", \"hash\":\"58ab237888f2a510fe4db1fee6a50d5d2f884b6e\", \"best_bid\":\"0.26\", \"best_ask\":\"0.27\"}, {\"asset_id\":\"39272994714739463168905443499424551362424437245880253267329605556587274644733\", \"price\":\"0.83\", \"size\":\"226.3\", \"side\":\"SELL\", \"hash\":\"87dfa8dd94cff4ab34e99817f723512efdad0863\", \"best_bid\":\"0.73\", \"best_ask\":\"0.74\"}], \"timestamp\":\"1785204361458\", \"event_type\":\"price_change\"}","received_at":"2026-07-28T02:06:01.550680Z","schema_version":"clob-market-ws.price_change.v1","sequence":null,"server_hash":null,"server_timestamp":"1785204361458","session_id":"d2757dd6dad94f3b9fe67e8dbf1adc37","source":"clob_market_ws"},"received_at":"2026-07-28T02:06:01.550680Z","record_id":"81e15b023b744a4660a2286c5a55e28b1539c0ffac2e8e82fb7f0116ff69e024","schema_fingerprint":"4aa3821a28b0b7c2400bc59aba4bcc0a76e971dadd19610d3ad38c768e124dc7","schema_version":"edge-lab-recorder.raw.v1","sequence":null,"source":"clob_market_ws"}
{"event_at":"2026-07-28T02:06:01.459000Z","event_fingerprint":"3529e03661196df3ceffa0bd9cc640380ae6c64336f03a6bba7019f595444f76","payload":{"connection_id":"5d29200f65794d4d9ab6ef271f045a9b","event_at":"2026-07-28T02:06:01.459000Z","event_type":"price_change","frame_hash":"4937f76fba6bd87eed8351cfb1264de3838a88b108d1ae84aa4677f87fb77119","frame_index":0,"kind":"data","monotonic_ns":306344562493666,"payload":{"event_type":"price_change","market":"0xda6f0e0e93fc8469e0159a166028d017bddbc162b86f66bac90391379603d962","price_changes":[{"asset_id":"39272994714739463168905443499424551362424437245880253267329605556587274644733","best_ask":"0.74","best_bid":"0.73","hash":"63d429c64c4617d563810653d5ad7f6cab9239b7","price":"0.72","side":"BUY","size":"151.51"},{"asset_id":"20893381255801015515826997628594359667013752732428989472914000440642900266717","best_ask":"0.27","best_bid":"0.26","hash":"e91f1f3823961a2df3d19ec74c8ca3c67f798fd0","price":"0.28","side":"SELL","size":"151.51"}],"timestamp":"1785204361459"},"payload_hash":"a1e928fe4316fd13ee7a1dbfa07052637fba72fa041aba9f46841ea965d43dda","raw_frame":"{\"market\":\"0xda6f0e0e93fc8469e0159a166028d017bddbc162b86f66bac90391379603d962\", \"price_changes\":[{\"asset_id\":\"39272994714739463168905443499424551362424437245880253267329605556587274644733\", \"price\":\"0.72\", \"size\":\"151.51\", \"side\":\"BUY\", \"hash\":\"63d429c64c4617d563810653d5ad7f6cab9239b7\", \"best_bid\":\"0.73\", \"best_ask\":\"0.74\"}, {\"asset_id\":\"20893381255801015515826997628594359667013752732428989472914000440642900266717\", \"price\":\"0.28\", \"size\":\"151.51\", \"side\":\"SELL\", \"hash\":\"e91f1f3823961a2df3d19ec74c8ca3c67f798fd0\", \"best_bid\":\"0.26\", \"best_ask\":\"0.27\"}], \"timestamp\":\"1785204361459\", \"event_type\":\"price_change\"}","received_at":"2026-07-28T02:06:01.555863Z","schema_version":"clob-market-ws.price_change.v1","sequence":null,"server_hash":null,"server_timestamp":"1785204361459","session_id":"d2757dd6dad94f3b9fe67e8dbf1adc37","source":"clob_market_ws"},"received_at":"2026-07-28T02:06:01.555863Z","record_id":"1b56ff81479f6ddb43cdd0c3ae883283edfdbbe6c5a32545be58b45e5c98551c","schema_fingerprint":"4aa3821a28b0b7c2400bc59aba4bcc0a76e971dadd19610d3ad38c768e124dc7","schema_version":"edge-lab-recorder.raw.v1","sequence":null,"source":"clob_market_ws"}
{"event_at":"2026-07-28T02:06:01.464000Z","event_fingerprint":"9afd13f936c29b5a87b15b48e4c42db581bd2424f164d388f52dca1070fe01d5","payload":{"connection_id":"5d29200f65794d4d9ab6ef271f045a9b","event_at":"2026-07-28T02:06:01.464000Z","event_type":"price_change","frame_hash":"2125e9110dcf9e3072f13c9cd83d4513b558efc25a5c3bd386cf2cd83dbd47c4","frame_index":0,"kind":"data","monotonic_ns":306344566827708,"payload":{"event_type":"price_change","market":"0xda6f0e0e93fc8469e0159a166028d017bddbc162b86f66bac90391379603d962","price_changes":[{"asset_id":"20893381255801015515826997628594359667013752732428989472914000440642900266717","best_ask":"0.27","best_bid":"0.26","hash":"2d151777008c1f54251e8441b47fc09c83dfb1e3","price":"0.14","side":"BUY","size":"321.9"},{"asset_id":"39272994714739463168905443499424551362424437245880253267329605556587274644733","best_ask":"0.74","best_bid":"0.73","hash":"d2e203f92c16e2eb89bc1b290559d3dfbcb23372","price":"0.86","side":"SELL","size":"321.9"}],"timestamp":"1785204361464"},"payload_hash":"80f11da17be3b82c87831d9ba0c6e8bcffc050c334ce40e2a5b4f56c38f6a45b","raw_frame":"{\"market\":\"0xda6f0e0e93fc8469e0159a166028d017bddbc162b86f66bac90391379603d962\", \"price_changes\":[{\"asset_id\":\"20893381255801015515826997628594359667013752732428989472914000440642900266717\", \"price\":\"0.14\", \"size\":\"321.9\", \"side\":\"BUY\", \"hash\":\"2d151777008c1f54251e8441b47fc09c83dfb1e3\", \"best_bid\":\"0.26\", \"best_ask\":\"0.27\"}, {\"asset_id\":\"39272994714739463168905443499424551362424437245880253267329605556587274644733\", \"price\":\"0.86\", \"size\":\"321.9\", \"side\":\"SELL\", \"hash\":\"d2e203f92c16e2eb89bc1b290559d3dfbcb23372\", \"best_bid\":\"0.73\", \"best_ask\":\"0.74\"}], \"timestamp\":\"1785204361464\", \"event_type\":\"price_change\"}","received_at":"2026-07-28T02:06:01.560198Z","schema_version":"clob-market-ws.price_change.v1","sequence":null,"server_hash":null,"server_timestamp":"1785204361464","session_id":"d2757dd6dad94f3b9fe67e8dbf1adc37","source":"clob_market_ws"},"received_at":"2026-07-28T02:06:01.560198Z","record_id":"a01d67a64c307692d5aa9a0fb383e6acf8860fcceac5ec9cc49431bd3dca1e8c","schema_fingerprint":"4aa3821a28b0b7c2400bc59aba4bcc0a76e971dadd19610d3ad38c768e124dc7","schema_version":"edge-lab-recorder.raw.v1","sequence":null,"source":"clob_market_ws"}
{"event_at":"2026-07-28T02:06:01.468000Z","event_fingerprint":"617dec85802f4a2be12e29b1477d0c7a058ee0e5194adfaf113b7f470a8ad0e1","payload":{"connection_id":"5d29200f65794d4d9ab6ef271f045a9b","event_at":"2026-07-28T02:06:01.468000Z","event_type":"best_bid_ask","frame_hash":"7cddc159ff2c087f67c71a5732dcccb9ccfa8086b1c137d67524a27e4a605719","frame_index":0,"kind":"data","monotonic_ns":306344575052083,"payload":{"asset_id":"20893381255801015515826997628594359667013752732428989472914000440642900266717","best_ask":"0.27","best_bid":"0.25","event_type":"best_bid_ask","market":"0xda6f0e0e93fc8469e0159a166028d017bddbc162b86f66bac90391379603d962","spread":"0.02","timestamp":"1785204361468"},"payload_hash":"68a4467b843d2946265f2c96cdd3c3cfb863a2acebd4629da6fac49b3d9c123a","raw_frame":"{\"market\":\"0xda6f0e0e93fc8469e0159a166028d017bddbc162b86f66bac90391379603d962\", \"asset_id\":\"20893381255801015515826997628594359667013752732428989472914000440642900266717\", \"best_bid\":\"0.25\", \"best_ask\":\"0.27\", \"spread\":\"0.02\", \"timestamp\":\"1785204361468\", \"event_type\":\"best_bid_ask\"}","received_at":"2026-07-28T02:06:01.568421Z","schema_version":"clob-market-ws.best_bid_ask.v1","sequence":null,"server_hash":null,"server_timestamp":"1785204361468","session_id":"d2757dd6dad94f3b9fe67e8dbf1adc37","source":"clob_market_ws"},"received_at":"2026-07-28T02:06:01.568421Z","record_id":"9d2f5733238625be4feedb499a79378c7da3523b402fd48dc9e5581b01aeab32","schema_fingerprint":"8488399f31b0337811b13b266be932db7062827c2470b78bd8e9e99bab51d17d","schema_version":"edge-lab-recorder.raw.v1","sequence":null,"source":"clob_market_ws"}
{"event_at":"2026-07-28T02:06:01.468000Z","event_fingerprint":"497957571a2a30aef8baa279330d22391bf69cf6ec929446dfdf737844b9d26b","payload":{"connection_id":"5d29200f65794d4d9ab6ef271f045a9b","event_at":"2026-07-28T02:06:01.468000Z","event_type":"best_bid_ask","frame_hash":"fc155f65d0ec7e6871e35df6ba5884aa8f85f82611986d55696da41b825ca859","frame_index":0,"kind":"data","monotonic_ns":306344577683333,"payload":{"asset_id":"39272994714739463168905443499424551362424437245880253267329605556587274644733","best_ask":"0.75","best_bid":"0.73","event_type":"best_bid_ask","market":"0xda6f0e0e93fc8469e0159a166028d017bddbc162b86f66bac90391379603d962","spread":"0.02","timestamp":"1785204361468"},"payload_hash":"378d4980c405a288114daa2d033e11c84074f5e201644cab0ac35ac1c5348034","raw_frame":"{\"market\":\"0xda6f0e0e93fc8469e0159a166028d017bddbc162b86f66bac90391379603d962\", \"asset_id\":\"39272994714739463168905443499424551362424437245880253267329605556587274644733\", \"best_bid\":\"0.73\", \"best_ask\":\"0.75\", \"spread\":\"0.02\", \"timestamp\":\"1785204361468\", \"event_type\":\"best_bid_ask\"}","received_at":"2026-07-28T02:06:01.571052Z","schema_version":"clob-market-ws.best_bid_ask.v1","sequence":null,"server_hash":null,"server_timestamp":"1785204361468","session_id":"d2757dd6dad94f3b9fe67e8dbf1adc37","source":"clob_market_ws"},"received_at":"2026-07-28T02:06:01.571052Z","record_id":"220b4dd8ecd88fdf894142d2f433acc482bb8aa1d3cd512a6a7e62c3b4003c56","schema_fingerprint":"8488399f31b0337811b13b266be932db7062827c2470b78bd8e9e99bab51d17d","schema_version":"edge-lab-recorder.raw.v1","sequence":null,"source":"clob_market_ws"}
{"event_at":"2026-07-28T02:06:01.468000Z","event_fingerprint":"7f6450dffc73e54c749e357c810cfba7f40dd47efb9fa7fe450b381c4cfa1777","payload":{"connection_id":"5d29200f65794d4d9ab6ef271f045a9b","event_at":"2026-07-28T02:06:01.468000Z","event_type":"price_change","frame_hash":"6df5d5e1d2f93654d0013a4040836175b99698aa31a9bd3b7acb07789a8d0473","frame_index":0,"kind":"data","monotonic_ns":306344581645833,"payload":{"event_type":"price_change","market":"0xda6f0e0e93fc8469e0159a166028d017bddbc162b86f66bac90391379603d962","price_changes":[{"asset_id":"20893381255801015515826997628594359667013752732428989472914000440642900266717","best_ask":"0.27","best_bid":"0.25","hash":"ff2ef9db7cc064a651f1198441bddb8e8497330c","price":"0.26","side":"BUY","size":"0"},{"asset_id":"39272994714739463168905443499424551362424437245880253267329605556587274644733","best_ask":"0.75","best_bid":"0.73","hash":"fe46d2e1cb659f044a0500d48a2e1b979c9b0b38","price":"0.74","side":"SELL","size":"0"}],"timestamp":"1785204361468"},"payload_hash":"49929c1f056e8af97c70fc7057c12c2c04d6eeb74e99939c649a8e2a5aaefc6c","raw_frame":"{\"market\":\"0xda6f0e0e93fc8469e0159a166028d017bddbc162b86f66bac90391379603d962\", \"price_changes\":[{\"asset_id\":\"20893381255801015515826997628594359667013752732428989472914000440642900266717\", \"price\":\"0.26\", \"size\":\"0\", \"side\":\"BUY\", \"hash\":\"ff2ef9db7cc064a651f1198441bddb8e8497330c\", \"best_bid\":\"0.25\", \"best_ask\":\"0.27\"}, {\"asset_id\":\"39272994714739463168905443499424551362424437245880253267329605556587274644733\", \"price\":\"0.74\", \"size\":\"0\", \"side\":\"SELL\", \"hash\":\"fe46d2e1cb659f044a0500d48a2e1b979c9b0b38\", \"best_bid\":\"0.73\", \"best_ask\":\"0.75\"}], \"timestamp\":\"1785204361468\", \"event_type\":\"price_change\"}","received_at":"2026-07-28T02:06:01.575014Z","schema_version":"clob-market-ws.price_change.v1","sequence":null,"server_hash":null,"server_timestamp":"1785204361468","session_id":"d2757dd6dad94f3b9fe67e8dbf1adc37","source":"clob_market_ws"},"received_at":"2026-07-28T02:06:01.575014Z","record_id":"871600dec893b10c8a2913b70048562d5ff0c7105cd64e0f33d94233cd544251","schema_fingerprint":"4aa3821a28b0b7c2400bc59aba4bcc0a76e971dadd19610d3ad38c768e124dc7","schema_version":"edge-lab-recorder.raw.v1","sequence":null,"source":"clob_market_ws"}
{"event_at":"2026-07-28T02:06:01.468000Z","event_fingerprint":"314b49657a40d26e383a7f33b28af3809ea0389cd334e3e48c27208b16a10cf6","payload":{"connection_id":"5d29200f65794d4d9ab6ef271f045a9b","event_at":"2026-07-28T02:06:01.468000Z","event_type":"price_change","frame_hash":"af7b0f3122542a07fd710da514feb66cec72ee7e544954893405b23d90eaf221","frame_index":0,"kind":"data","monotonic_ns":306344585992083,"payload":{"event_type":"price_change","market":"0xda6f0e0e93fc8469e0159a166028d017bddbc162b86f66bac90391379603d962","price_changes":[{"asset_id":"39272994714739463168905443499424551362424437245880253267329605556587274644733","best_ask":"0.75","best_bid":"0.73","hash":"b7951eeb8e814be93c81c873ca4895c02076c955","price":"0.57","side":"BUY","size":"177.2"},{"asset_id":"20893381255801015515826997628594359667013752732428989472914000440642900266717","best_ask":"0.27","best_bid":"0.25","hash":"2f93c16e901fba9f1a190ec224a732b2b475833f","price":"0.43","side":"SELL","size":"177.2"}],"timestamp":"1785204361468"},"payload_hash":"4e477fda9ec03feeb09bbad0e7bab882bf80156f258655b0992fe391457032a5","raw_frame":"{\"market\":\"0xda6f0e0e93fc8469e0159a166028d017bddbc162b86f66bac90391379603d962\", \"price_changes\":[{\"asset_id\":\"39272994714739463168905443499424551362424437245880253267329605556587274644733\", \"price\":\"0.57\", \"size\":\"177.2\", \"side\":\"BUY\", \"hash\":\"b7951eeb8e814be93c81c873ca4895c02076c955\", \"best_bid\":\"0.73\", \"best_ask\":\"0.75\"}, {\"asset_id\":\"20893381255801015515826997628594359667013752732428989472914000440642900266717\", \"price\":\"0.43\", \"size\":\"177.2\", \"side\":\"SELL\", \"hash\":\"2f93c16e901fba9f1a190ec224a732b2b475833f\", \"best_bid\":\"0.25\", \"best_ask\":\"0.27\"}], \"timestamp\":\"1785204361468\", \"event_type\":\"price_change\"}","received_at":"2026-07-28T02:06:01.579360Z","schema_version":"clob-market-ws.price_change.v1","sequence":null,"server_hash":null,"server_timestamp":"1785204361468","session_id":"d2757dd6dad94f3b9fe67e8dbf1adc37","source":"clob_market_ws"},"received_at":"2026-07-28T02:06:01.579360Z","record_id":"cd36109852beb2a44ac7d2cbb828b29223ec79ac49059eb591052a54f43fe760","schema_fingerprint":"4aa3821a28b0b7c2400bc59aba4bcc0a76e971dadd19610d3ad38c768e124dc7","schema_version":"edge-lab-recorder.raw.v1","sequence":null,"source":"clob_market_ws"}
{"event_at":"2026-07-28T02:06:01.469000Z","event_fingerprint":"17e64eb19d5040b58234d1e2f1589b3a79cd9cc304e5be4146869e40ef53ce3a","payload":{"connection_id":"5d29200f65794d4d9ab6ef271f045a9b","event_at":"2026-07-28T02:06:01.469000Z","event_type":"best_bid_ask","frame_hash":"a18844f491be5fe5efb5a442da2bb2b78c1299ff90144cfe6937920d9b969701","frame_index":0,"kind":"data","monotonic_ns":306344592015041,"payload":{"asset_id":"20893381255801015515826997628594359667013752732428989472914000440642900266717","best_ask":"0.27","best_bid":"0.26","event_type":"best_bid_ask","market":"0xda6f0e0e93fc8469e0159a166028d017bddbc162b86f66bac90391379603d962","spread":"0.01","timestamp":"1785204361469"},"payload_hash":"dda55b49f9066da8e38ee6c07ac2a08181e6197eed7ba0761254d0bfb1fed5cb","raw_frame":"{\"market\":\"0xda6f0e0e93fc8469e0159a166028d017bddbc162b86f66bac90391379603d962\", \"asset_id\":\"20893381255801015515826997628594359667013752732428989472914000440642900266717\", \"best_bid\":\"0.26\", \"best_ask\":\"0.27\", \"spread\":\"0.01\", \"timestamp\":\"1785204361469\", \"event_type\":\"best_bid_ask\"}","received_at":"2026-07-28T02:06:01.585384Z","schema_version":"clob-market-ws.best_bid_ask.v1","sequence":null,"server_hash":null,"server_timestamp":"1785204361469","session_id":"d2757dd6dad94f3b9fe67e8dbf1adc37","source":"clob_market_ws"},"received_at":"2026-07-28T02:06:01.585384Z","record_id":"4daae8f3b5e29e34d4207ccc0539e7104fa351ceca6f30609f2f7391bdcb7a69","schema_fingerprint":"8488399f31b0337811b13b266be932db7062827c2470b78bd8e9e99bab51d17d","schema_version":"edge-lab-recorder.raw.v1","sequence":null,"source":"clob_market_ws"}
{"event_at":"2026-07-28T02:06:01.469000Z","event_fingerprint":"62f940d8ecf091108a9d9670b12c9e3ad257d830be4ca40b7f22d6481a30df8e","payload":{"connection_id":"5d29200f65794d4d9ab6ef271f045a9b","event_at":"2026-07-28T02:06:01.469000Z","event_type":"best_bid_ask","frame_hash":"a2bf437532882a5cf2d13221a6711508ec460a1338d2ce35ca363d12852b6fee","frame_index":0,"kind":"data","monotonic_ns":306344597728375,"payload":{"asset_id":"39272994714739463168905443499424551362424437245880253267329605556587274644733","best_ask":"0.74","best_bid":"0.73","event_type":"best_bid_ask","market":"0xda6f0e0e93fc8469e0159a166028d017bddbc162b86f66bac90391379603d962","spread":"0.01","timestamp":"1785204361469"},"payload_hash":"ba79940fdc76ff21c3824822621830fb94540524722e529944b44dead6cdd352","raw_frame":"{\"market\":\"0xda6f0e0e93fc8469e0159a166028d017bddbc162b86f66bac90391379603d962\", \"asset_id\":\"39272994714739463168905443499424551362424437245880253267329605556587274644733\", \"best_bid\":\"0.73\", \"best_ask\":\"0.74\", \"spread\":\"0.01\", \"timestamp\":\"1785204361469\", \"event_type\":\"best_bid_ask\"}","received_at":"2026-07-28T02:06:01.591098Z","schema_version":"clob-market-ws.best_bid_ask.v1","sequence":null,"server_hash":null,"server_timestamp":"1785204361469","session_id":"d2757dd6dad94f3b9fe67e8dbf1adc37","source":"clob_market_ws"},"received_at":"2026-07-28T02:06:01.591098Z","record_id":"404e741474f8757fbd943536c4b355cd2896c7b719964012867b28eeaf7a27c3","schema_fingerprint":"8488399f31b0337811b13b266be932db7062827c2470b78bd8e9e99bab51d17d","schema_version":"edge-lab-recorder.raw.v1","sequence":null,"source":"clob_market_ws"}
{"event_at":"2026-07-28T02:06:01.469000Z","event_fingerprint":"1d461bde561620ddb16a5b04351c594521507764036340d8eea3440fe4881ee0","payload":{"connection_id":"5d29200f65794d4d9ab6ef271f045a9b","event_at":"2026-07-28T02:06:01.469000Z","event_type":"price_change","frame_hash":"b2a4aaec1104115c574b58aa718ec9afe7057f6e42ddf3c7b5ff7442cc486b70","frame_index":0,"kind":"data","monotonic_ns":306344601306083,"payload":{"event_type":"price_change","market":"0xda6f0e0e93fc8469e0159a166028d017bddbc162b86f66bac90391379603d962","price_changes":[{"asset_id":"20893381255801015515826997628594359667013752732428989472914000440642900266717","best_ask":"0.27","best_bid":"0.26","hash":"c00bf5f0b4e5d3d66ee929017985522159bddd2b","price":"0.26","side":"BUY","size":"5"},{"asset_id":"39272994714739463168905443499424551362424437245880253267329605556587274644733","best_ask":"0.74","best_bid":"0.73","hash":"4dc95aee2d0746e7ac9bee4fef59f43d1945fb60","price":"0.74","side":"SELL","size":"5"}],"timestamp":"1785204361469"},"payload_hash":"db4da698d9e4ec50b5cfe691368cb8dd2b061bb3f2d97c1e530542bda596b6b3","raw_frame":"{\"market\":\"0xda6f0e0e93fc8469e0159a166028d017bddbc162b86f66bac90391379603d962\", \"price_changes\":[{\"asset_id\":\"20893381255801015515826997628594359667013752732428989472914000440642900266717\", \"price\":\"0.26\", \"size\":\"5\", \"side\":\"BUY\", \"hash\":\"c00bf5f0b4e5d3d66ee929017985522159bddd2b\", \"best_bid\":\"0.26\", \"best_ask\":\"0.27\"}, {\"asset_id\":\"39272994714739463168905443499424551362424437245880253267329605556587274644733\", \"price\":\"0.74\", \"size\":\"5\", \"side\":\"SELL\", \"hash\":\"4dc95aee2d0746e7ac9bee4fef59f43d1945fb60\", \"best_bid\":\"0.73\", \"best_ask\":\"0.74\"}], \"timestamp\":\"1785204361469\", \"event_type\":\"price_change\"}","received_at":"2026-07-28T02:06:01.594673Z","schema_version":"clob-market-ws.price_change.v1","sequence":null,"server_hash":null,"server_timestamp":"1785204361469","session_id":"d2757dd6dad94f3b9fe67e8dbf1adc37","source":"clob_market_ws"},"received_at":"2026-07-28T02:06:01.594673Z","record_id":"728b8bc4447b2b404cc5b0a549ae86c39b60346dc21a069443feb936803119d0","schema_fingerprint":"4aa3821a28b0b7c2400bc59aba4bcc0a76e971dadd19610d3ad38c768e124dc7","schema_version":"edge-lab-recorder.raw.v1","sequence":null,"source":"clob_market_ws"}
{"event_at":"2026-07-28T02:06:01.470000Z","event_fingerprint":"57bccda37d00ca8a4d98d8c4f3abfff64678a3a4c6250fd3656bb941669fa07e","payload":{"connection_id":"5d29200f65794d4d9ab6ef271f045a9b","event_at":"2026-07-28T02:06:01.470000Z","event_type":"price_change","frame_hash":"da27ca4312b5007c797ac381821b1454009d8017c8fce7d96383583e16859cad","frame_index":0,"kind":"data","monotonic_ns":306344605183083,"payload":{"event_type":"price_change","market":"0xda6f0e0e93fc8469e0159a166028d017bddbc162b86f66bac90391379603d962","price_changes":[{"asset_id":"39272994714739463168905443499424551362424437245880253267329605556587274644733","best_ask":"0.74","best_bid":"0.73","hash":"fb46e76a43110d6f0176ec96dd888b383d7e1b6f","price":"0.73","side":"BUY","size":"69.2"},{"asset_id":"20893381255801015515826997628594359667013752732428989472914000440642900266717","best_ask":"0.27","best_bid":"0.26","hash":"4a4fe6c2cdb65614b9d98dba1580cb97d4069a56","price":"0.27","side":"SELL","size":"69.2"}],"timestamp":"1785204361470"},"payload_hash":"23d9067d38de5fe1f7b1409a64fc60a7ec4f3d7b38d85df550d8971ad684b0f0","raw_frame":"{\"market\":\"0xda6f0e0e93fc8469e0159a166028d017bddbc162b86f66bac90391379603d962\", \"price_changes\":[{\"asset_id\":\"39272994714739463168905443499424551362424437245880253267329605556587274644733\", \"price\":\"0.73\", \"size\":\"69.2\", \"side\":\"BUY\", \"hash\":\"fb46e76a43110d6f0176ec96dd888b383d7e1b6f\", \"best_bid\":\"0.73\", \"best_ask\":\"0.74\"}, {\"asset_id\":\"20893381255801015515826997628594359667013752732428989472914000440642900266717\", \"price\":\"0.27\", \"size\":\"69.2\", \"side\":\"SELL\", \"hash\":\"4a4fe6c2cdb65614b9d98dba1580cb97d4069a56\", \"best_bid\":\"0.26\", \"best_ask\":\"0.27\"}], \"timestamp\":\"1785204361470\", \"event_type\":\"price_change\"}","received_at":"2026-07-28T02:06:01.598552Z","schema_version":"clob-market-ws.price_change.v1","sequence":null,"server_hash":null,"server_timestamp":"1785204361470","session_id":"d2757dd6dad94f3b9fe67e8dbf1adc37","source":"clob_market_ws"},"received_at":"2026-07-28T02:06:01.598552Z","record_id":"ae7859c16b04835145655835587411610dddbaf50e9c6ea24abac1e866eb8836","schema_fingerprint":"4aa3821a28b0b7c2400bc59aba4bcc0a76e971dadd19610d3ad38c768e124dc7","schema_version":"edge-lab-recorder.raw.v1","sequence":null,"source":"clob_market_ws"}
{"event_at":"2026-07-28T02:06:01.476000Z","event_fingerprint":"2565a08e4dfb8f566be9b848f17a1f963a0555f92752fef8bc640b8aac73982c","payload":{"connection_id":"5d29200f65794d4d9ab6ef271f045a9b","event_at":"2026-07-28T02:06:01.476000Z","event_type":"price_change","frame_hash":"a3e8f9b1b8a7b4e0b18db8ebe679402f1fb47c0f0e77979f396cacd8d95cb142","frame_index":0,"kind":"data","monotonic_ns":306344609294541,"payload":{"event_type":"price_change","market":"0xda6f0e0e93fc8469e0159a166028d017bddbc162b86f66bac90391379603d962","price_changes":[{"asset_id":"20893381255801015515826997628594359667013752732428989472914000440642900266717","best_ask":"0.27","best_bid":"0.26","hash":"53ca634a43394fae0bda8ba17a46b37baf16c0cd","price":"0.24","side":"BUY","size":"94.2"},{"asset_id":"39272994714739463168905443499424551362424437245880253267329605556587274644733","best_ask":"0.74","best_bid":"0.73","hash":"0c42b7d0db538801563f104753e28aa8fefb19b0","price":"0.76","side":"SELL","size":"94.2"}],"timestamp":"1785204361476"},"payload_hash":"b1042010954b5bb79e005f1d301a0b03920145628b210f1796bf694e571b234d","raw_frame":"{\"market\":\"0xda6f0e0e93fc8469e0159a166028d017bddbc162b86f66bac90391379603d962\", \"price_changes\":[{\"asset_id\":\"20893381255801015515826997628594359667013752732428989472914000440642900266717\", \"price\":\"0.24\", \"size\":\"94.2\", \"side\":\"BUY\", \"hash\":\"53ca634a43394fae0bda8ba17a46b37baf16c0cd\", \"best_bid\":\"0.26\", \"best_ask\":\"0.27\"}, {\"asset_id\":\"39272994714739463168905443499424551362424437245880253267329605556587274644733\", \"price\":\"0.76\", \"size\":\"94.2\", \"side\":\"SELL\", \"hash\":\"0c42b7d0db538801563f104753e28aa8fefb19b0\", \"best_bid\":\"0.73\", \"best_ask\":\"0.74\"}], \"timestamp\":\"1785204361476\", \"event_type\":\"price_change\"}","received_at":"2026-07-28T02:06:01.602664Z","schema_version":"clob-market-ws.price_change.v1","sequence":null,"server_hash":null,"server_timestamp":"1785204361476","session_id":"d2757dd6dad94f3b9fe67e8dbf1adc37","source":"clob_market_ws"},"received_at":"2026-07-28T02:06:01.602664Z","record_id":"44809fa972e59ba799193752ba8556baf0100417c061ddab0959af36cba09f34","schema_fingerprint":"4aa3821a28b0b7c2400bc59aba4bcc0a76e971dadd19610d3ad38c768e124dc7","schema_version":"edge-lab-recorder.raw.v1","sequence":null,"source":"clob_market_ws"}
{"event_at":"2026-07-28T02:06:01.477000Z","event_fingerprint":"b4b874ca6587d9d7a9fdfeb165bc2f18e23f2f428720cf2bf304fd5fbcd189ea","payload":{"connection_id":"5d29200f65794d4d9ab6ef271f045a9b","event_at":"2026-07-28T02:06:01.477000Z","event_type":"price_change","frame_hash":"e68bcf4c03ebc26815f4e2ae3fa2061e658f3178e6840cfb367a7d499172fa0e","frame_index":0,"kind":"data","monotonic_ns":306344613692708,"payload":{"event_type":"price_change","market":"0xda6f0e0e93fc8469e0159a166028d017bddbc162b86f66bac90391379603d962","price_changes":[{"asset_id":"20893381255801015515826997628594359667013752732428989472914000440642900266717","best_ask":"0.27","best_bid":"0.26","hash":"ef9f2d9510e1caabbe14ab86145f83f9a1de9193","price":"0.17","side":"BUY","size":"196.3"},{"asset_id":"39272994714739463168905443499424551362424437245880253267329605556587274644733","best_ask":"0.74","best_bid":"0.73","hash":"2caaa5610625add3c555517759a3985d71f6415a","price":"0.83","side":"SELL","size":"196.3"}],"timestamp":"1785204361477"},"payload_hash":"ab4adffb1b6830058d3701717cff215bee94219cbbce230883508c60bbee038d","raw_frame":"{\"market\":\"0xda6f0e0e93fc8469e0159a166028d017bddbc162b86f66bac90391379603d962\", \"price_changes\":[{\"asset_id\":\"20893381255801015515826997628594359667013752732428989472914000440642900266717\", \"price\":\"0.17\", \"size\":\"196.3\", \"side\":\"BUY\", \"hash\":\"ef9f2d9510e1caabbe14ab86145f83f9a1de9193\", \"best_bid\":\"0.26\", \"best_ask\":\"0.27\"}, {\"asset_id\":\"39272994714739463168905443499424551362424437245880253267329605556587274644733\", \"price\":\"0.83\", \"size\":\"196.3\", \"side\":\"SELL\", \"hash\":\"2caaa5610625add3c555517759a3985d71f6415a\", \"best_bid\":\"0.73\", \"best_ask\":\"0.74\"}], \"timestamp\":\"1785204361477\", \"event_type\":\"price_change\"}","received_at":"2026-07-28T02:06:01.607062Z","schema_version":"clob-market-ws.price_change.v1","sequence":null,"server_hash":null,"server_timestamp":"1785204361477","session_id":"d2757dd6dad94f3b9fe67e8dbf1adc37","source":"clob_market_ws"},"received_at":"2026-07-28T02:06:01.607062Z","record_id":"f040222b2286f462f3d18cdc73a170c42f7016aba679b2239845ab510e026bee","schema_fingerprint":"4aa3821a28b0b7c2400bc59aba4bcc0a76e971dadd19610d3ad38c768e124dc7","schema_version":"edge-lab-recorder.raw.v1","sequence":null,"source":"clob_market_ws"}
{"event_at":"2026-07-28T02:06:01.485000Z","event_fingerprint":"a0eeef8d16be864582b1a59982f52c0f530464cf92565dafa49c1c0415ba4450","payload":{"connection_id":"5d29200f65794d4d9ab6ef271f045a9b","event_at":"2026-07-28T02:06:01.485000Z","event_type":"price_change","frame_hash":"60628822ad34d6dcbc1304e8e62ca41aae00470708d343278b0473324117e969","frame_index":0,"kind":"data","monotonic_ns":306344620565041,"payload":{"event_type":"price_change","market":"0xda6f0e0e93fc8469e0159a166028d017bddbc162b86f66bac90391379603d962","price_changes":[{"asset_id":"20893381255801015515826997628594359667013752732428989472914000440642900266717","best_ask":"0.27","best_bid":"0.26","hash":"6b36afdfac5d090f6a3f0a397ba3cafbc2aae887","price":"0.12","side":"BUY","size":"651.4"},{"asset_id":"39272994714739463168905443499424551362424437245880253267329605556587274644733","best_ask":"0.74","best_bid":"0.73","hash":"bc991033704346f5231db3073a4422b6971e6822","price":"0.88","side":"SELL","size":"651.4"}],"timestamp":"1785204361485"},"payload_hash":"6f03e2571c22627fba4eedde70ad8a9f3c36c3d079250bac1abf35ae41b75782","raw_frame":"{\"market\":\"0xda6f0e0e93fc8469e0159a166028d017bddbc162b86f66bac90391379603d962\", \"price_changes\":[{\"asset_id\":\"20893381255801015515826997628594359667013752732428989472914000440642900266717\", \"price\":\"0.12\", \"size\":\"651.4\", \"side\":\"BUY\", \"hash\":\"6b36afdfac5d090f6a3f0a397ba3cafbc2aae887\", \"best_bid\":\"0.26\", \"best_ask\":\"0.27\"}, {\"asset_id\":\"39272994714739463168905443499424551362424437245880253267329605556587274644733\", \"price\":\"0.88\", \"size\":\"651.4\", \"side\":\"SELL\", \"hash\":\"bc991033704346f5231db3073a4422b6971e6822\", \"best_bid\":\"0.73\", \"best_ask\":\"0.74\"}], \"timestamp\":\"1785204361485\", \"event_type\":\"price_change\"}","received_at":"2026-07-28T02:06:01.613934Z","schema_version":"clob-market-ws.price_change.v1","sequence":null,"server_hash":null,"server_timestamp":"1785204361485","session_id":"d2757dd6dad94f3b9fe67e8dbf1adc37","source":"clob_market_ws"},"received_at":"2026-07-28T02:06:01.613934Z","record_id":"97af55ea196a653c82102ae53d80012d3fe585696909f7a184cca6c3b232e83e","schema_fingerprint":"4aa3821a28b0b7c2400bc59aba4bcc0a76e971dadd19610d3ad38c768e124dc7","schema_version":"edge-lab-recorder.raw.v1","sequence":null,"source":"clob_market_ws"}
{"event_at":"2026-07-28T02:06:01.487000Z","event_fingerprint":"453f1569270e06927a430f1c8fd908b23235eb39ea11b7a91bd1155a5bf593cf","payload":{"connection_id":"5d29200f65794d4d9ab6ef271f045a9b","event_at":"2026-07-28T02:06:01.487000Z","event_type":"price_change","frame_hash":"f72bb2582ab9371316a4f62e57550061209de828854accc18b1563f48271bbba","frame_index":0,"kind":"data","monotonic_ns":306344628426625,"payload":{"event_type":"price_change","market":"0xda6f0e0e93fc8469e0159a166028d017bddbc162b86f66bac90391379603d962","price_changes":[{"asset_id":"39272994714739463168905443499424551362424437245880253267329605556587274644733","best_ask":"0.74","best_bid":"0.73","hash":"6cdc69de14a829879dfe4aba8b43ecd8f6fe62a0","price":"0.01","side":"BUY","size":"5603.02"},{"asset_id":"20893381255801015515826997628594359667013752732428989472914000440642900266717","best_ask":"0.27","best_bid":"0.26","hash":"b87043df060ba5b260a84c9fce2e144b839c6a35","price":"0.99","side":"SELL","size":"5603.02"}],"timestamp":"1785204361487"},"payload_hash":"cc0717a1275ac9643776afc2e573ceb3ad1363d3a7269ed0efe442cbcd1bb980","raw_frame":"{\"market\":\"0xda6f0e0e93fc8469e0159a166028d017bddbc162b86f66bac90391379603d962\", \"price_changes\":[{\"asset_id\":\"39272994714739463168905443499424551362424437245880253267329605556587274644733\", \"price\":\"0.01\", \"size\":\"5603.02\", \"side\":\"BUY\", \"hash\":\"6cdc69de14a829879dfe4aba8b43ecd8f6fe62a0\", \"best_bid\":\"0.73\", \"best_ask\":\"0.74\"}, {\"asset_id\":\"20893381255801015515826997628594359667013752732428989472914000440642900266717\", \"price\":\"0.99\", \"size\":\"5603.02\", \"side\":\"SELL\", \"hash\":\"b87043df060ba5b260a84c9fce2e144b839c6a35\", \"best_bid\":\"0.26\", \"best_ask\":\"0.27\"}], \"timestamp\":\"1785204361487\", \"event_type\":\"price_change\"}","received_at":"2026-07-28T02:06:01.621796Z","schema_version":"clob-market-ws.price_change.v1","sequence":null,"server_hash":null,"server_timestamp":"1785204361487","session_id":"d2757dd6dad94f3b9fe67e8dbf1adc37","source":"clob_market_ws"},"received_at":"2026-07-28T02:06:01.621796Z","record_id":"e8676016ab1486b6df81daccf944a36a61afbe7cba93f4c608b621f691bb1d2c","schema_fingerprint":"4aa3821a28b0b7c2400bc59aba4bcc0a76e971dadd19610d3ad38c768e124dc7","schema_version":"edge-lab-recorder.raw.v1","sequence":null,"source":"clob_market_ws"}
{"event_at":"2026-07-28T02:06:01.488000Z","event_fingerprint":"e1430551c3aae1b484b923579c3a8aaa52d1c736dd41633a0b513dd6acbf0a35","payload":{"connection_id":"5d29200f65794d4d9ab6ef271f045a9b","event_at":"2026-07-28T02:06:01.488000Z","event_type":"price_change","frame_hash":"ad70b78a94c82365334008589bea105de7438c4381d63fc7c13e12f39629e70d","frame_index":0,"kind":"data","monotonic_ns":306344643397000,"payload":{"event_type":"price_change","market":"0xda6f0e0e93fc8469e0159a166028d017bddbc162b86f66bac90391379603d962","price_changes":[{"asset_id":"39272994714739463168905443499424551362424437245880253267329605556587274644733","best_ask":"0.74","best_bid":"0.73","hash":"c14f974eebcd6ffbdc1a9c5e5c0f35758d5a3c63","price":"0.73","side":"BUY","size":"54.2"},{"asset_id":"20893381255801015515826997628594359667013752732428989472914000440642900266717","best_ask":"0.27","best_bid":"0.26","hash":"af062fa202253667a9ea38d71f2710498a8f872d","price":"0.27","side":"SELL","size":"54.2"}],"timestamp":"1785204361488"},"payload_hash":"556b5a912faec17ac87909a1cfdaf9467b9423bb9b324737ca06f2c8624644ee","raw_frame":"{\"market\":\"0xda6f0e0e93fc8469e0159a166028d017bddbc162b86f66bac90391379603d962\", \"price_changes\":[{\"asset_id\":\"39272994714739463168905443499424551362424437245880253267329605556587274644733\", \"price\":\"0.73\", \"size\":\"54.2\", \"side\":\"BUY\", \"hash\":\"c14f974eebcd6ffbdc1a9c5e5c0f35758d5a3c63\", \"best_bid\":\"0.73\", \"best_ask\":\"0.74\"}, {\"asset_id\":\"20893381255801015515826997628594359667013752732428989472914000440642900266717\", \"price\":\"0.27\", \"size\":\"54.2\", \"side\":\"SELL\", \"hash\":\"af062fa202253667a9ea38d71f2710498a8f872d\", \"best_bid\":\"0.26\", \"best_ask\":\"0.27\"}], \"timestamp\":\"1785204361488\", \"event_type\":\"price_change\"}","received_at":"2026-07-28T02:06:01.636766Z","schema_version":"clob-market-ws.price_change.v1","sequence":null,"server_hash":null,"server_timestamp":"1785204361488","session_id":"d2757dd6dad94f3b9fe67e8dbf1adc37","source":"clob_market_ws"},"received_at":"2026-07-28T02:06:01.636766Z","record_id":"76206b433201ef38e0bf663052c6a81d55b1b1f01e224eac66c9f4cbb32c7bbf","schema_fingerprint":"4aa3821a28b0b7c2400bc59aba4bcc0a76e971dadd19610d3ad38c768e124dc7","schema_version":"edge-lab-recorder.raw.v1","sequence":null,"source":"clob_market_ws"}
{"event_at":"2026-07-28T02:06:01.494000Z","event_fingerprint":"c7808bbde7c26f7639b7ce2f9450c1d769eee6d17d0e104ec833471dad61e7e0","payload":{"connection_id":"5d29200f65794d4d9ab6ef271f045a9b","event_at":"2026-07-28T02:06:01.494000Z","event_type":"price_change","frame_hash":"c24724723c1d65813cdb546b13df166936968d44cc3383833e355b0211f243ff","frame_index":0,"kind":"data","monotonic_ns":306344649937166,"payload":{"event_type":"price_change","market":"0xda6f0e0e93fc8469e0159a166028d017bddbc162b86f66bac90391379603d962","price_changes":[{"asset_id":"39272994714739463168905443499424551362424437245880253267329605556587274644733","best_ask":"0.74","best_bid":"0.73","hash":"c413c2c95841d3f27297114f8899de6684c06a00","price":"0.69","side":"BUY","size":"110.65"},{"asset_id":"20893381255801015515826997628594359667013752732428989472914000440642900266717","best_ask":"0.27","best_bid":"0.26","hash":"a5e032e4044cb1ba085918a65e788374dac167c0","price":"0.31","side":"SELL","size":"110.65"}],"timestamp":"1785204361494"},"payload_hash":"8be1d13a1ae77f2b9c042db12e9faa22a00e4559c5ca8f2f3a0bc83e5cdd1da8","raw_frame":"{\"market\":\"0xda6f0e0e93fc8469e0159a166028d017bddbc162b86f66bac90391379603d962\", \"price_changes\":[{\"asset_id\":\"39272994714739463168905443499424551362424437245880253267329605556587274644733\", \"price\":\"0.69\", \"size\":\"110.65\", \"side\":\"BUY\", \"hash\":\"c413c2c95841d3f27297114f8899de6684c06a00\", \"best_bid\":\"0.73\", \"best_ask\":\"0.74\"}, {\"asset_id\":\"20893381255801015515826997628594359667013752732428989472914000440642900266717\", \"price\":\"0.31\", \"size\":\"110.65\", \"side\":\"SELL\", \"hash\":\"a5e032e4044cb1ba085918a65e788374dac167c0\", \"best_bid\":\"0.26\", \"best_ask\":\"0.27\"}], \"timestamp\":\"1785204361494\", \"event_type\":\"price_change\"}","received_at":"2026-07-28T02:06:01.643305Z","schema_version":"clob-market-ws.price_change.v1","sequence":null,"server_hash":null,"server_timestamp":"1785204361494","session_id":"d2757dd6dad94f3b9fe67e8dbf1adc37","source":"clob_market_ws"},"received_at":"2026-07-28T02:06:01.643305Z","record_id":"efafc62f45063f2ec9f4dce8ecd8a42e3de75bb71859d7cf463e288ef5f46b98","schema_fingerprint":"4aa3821a28b0b7c2400bc59aba4bcc0a76e971dadd19610d3ad38c768e124dc7","schema_version":"edge-lab-recorder.raw.v1","sequence":null,"source":"clob_market_ws"}
{"event_at":"2026-07-28T02:06:01.495000Z","event_fingerprint":"59aa90e0e3c6dd50b2a4e30970c3b72a7fabdd3d8afdec0b3060fe199c510757","payload":{"connection_id":"5d29200f65794d4d9ab6ef271f045a9b","event_at":"2026-07-28T02:06:01.495000Z","event_type":"price_change","frame_hash":"9d552df18a0fee1f3304bf1b81451206d2cb943d16baaca107f7cb79b92339f5","frame_index":0,"kind":"data","monotonic_ns":306344655399625,"payload":{"event_type":"price_change","market":"0xda6f0e0e93fc8469e0159a166028d017bddbc162b86f66bac90391379603d962","price_changes":[{"asset_id":"39272994714739463168905443499424551362424437245880253267329605556587274644733","best_ask":"0.74","best_bid":"0.73","hash":"48a49d24d54509f25333b24165ba98dfff659a49","price":"0.68","side":"BUY","size":"127"},{"asset_id":"20893381255801015515826997628594359667013752732428989472914000440642900266717","best_ask":"0.27","best_bid":"0.26","hash":"678b706003ff5e9b9fbc7670cfd46fd8551f7177","price":"0.32","side":"SELL","size":"127"}],"timestamp":"1785204361495"},"payload_hash":"26ca1de7e1c0ecf945b147530f9ba4da4b6993f03eb0374bd28f4fa945c9e914","raw_frame":"{\"market\":\"0xda6f0e0e93fc8469e0159a166028d017bddbc162b86f66bac90391379603d962\", \"price_changes\":[{\"asset_id\":\"39272994714739463168905443499424551362424437245880253267329605556587274644733\", \"price\":\"0.68\", \"size\":\"127\", \"side\":\"BUY\", \"hash\":\"48a49d24d54509f25333b24165ba98dfff659a49\", \"best_bid\":\"0.73\", \"best_ask\":\"0.74\"}, {\"asset_id\":\"20893381255801015515826997628594359667013752732428989472914000440642900266717\", \"price\":\"0.32\", \"size\":\"127\", \"side\":\"SELL\", \"hash\":\"678b706003ff5e9b9fbc7670cfd46fd8551f7177\", \"best_bid\":\"0.26\", \"best_ask\":\"0.27\"}], \"timestamp\":\"1785204361495\", \"event_type\":\"price_change\"}","received_at":"2026-07-28T02:06:01.648768Z","schema_version":"clob-market-ws.price_change.v1","sequence":null,"server_hash":null,"server_timestamp":"1785204361495","session_id":"d2757dd6dad94f3b9fe67e8dbf1adc37","source":"clob_market_ws"},"received_at":"2026-07-28T02:06:01.648768Z","record_id":"da216db814c64f79e61345dbed2ab478aa9d0ddc2917f6325d9b2e9de5eb88b4","schema_fingerprint":"4aa3821a28b0b7c2400bc59aba4bcc0a76e971dadd19610d3ad38c768e124dc7","schema_version":"edge-lab-recorder.raw.v1","sequence":null,"source":"clob_market_ws"}
{"event_at":"2026-07-28T02:06:01.497000Z","event_fingerprint":"74b7c28e1b0d6b1e16e3d0b373fc56e46634e6140579f1492ecc4692554fd2bf","payload":{"connection_id":"5d29200f65794d4d9ab6ef271f045a9b","event_at":"2026-07-28T02:06:01.497000Z","event_type":"price_change","frame_hash":"ef4f8f2ad658f0cbf1d5d3d2160b7f005ec1fdd8016531a77e0bee2d2771b626","frame_index":0,"kind":"data","monotonic_ns":306344658479416,"payload":{"event_type":"price_change","market":"0xda6f0e0e93fc8469e0159a166028d017bddbc162b86f66bac90391379603d962","price_changes":[{"asset_id":"20893381255801015515826997628594359667013752732428989472914000440642900266717","best_ask":"0.27","best_bid":"0.26","hash":"b754e7d9f7e723c8ba5110fadb2054cc95e3ab73","price":"0.18","side":"BUY","size":"307.64"},{"asset_id":"39272994714739463168905443499424551362424437245880253267329605556587274644733","best_ask":"0.74","best_bid":"0.73","hash":"c31cf3845625ccb360507f5db73160e83dde433e","price":"0.82","side":"SELL","size":"307.64"}],"timestamp":"1785204361497"},"payload_hash":"dcadb228e08a6c328b4a7194cb799bdd40de3308834a0b913e9a38ce9e0ffe00","raw_frame":"{\"market\":\"0xda6f0e0e93fc8469e0159a166028d017bddbc162b86f66bac90391379603d962\", \"price_changes\":[{\"asset_id\":\"20893381255801015515826997628594359667013752732428989472914000440642900266717\", \"price\":\"0.18\", \"size\":\"307.64\", \"side\":\"BUY\", \"hash\":\"b754e7d9f7e723c8ba5110fadb2054cc95e3ab73\", \"best_bid\":\"0.26\", \"best_ask\":\"0.27\"}, {\"asset_id\":\"39272994714739463168905443499424551362424437245880253267329605556587274644733\", \"price\":\"0.82\", \"size\":\"307.64\", \"side\":\"SELL\", \"hash\":\"c31cf3845625ccb360507f5db73160e83dde433e\", \"best_bid\":\"0.73\", \"best_ask\":\"0.74\"}], \"timestamp\":\"1785204361497\", \"event_type\":\"price_change\"}","received_at":"2026-07-28T02:06:01.651848Z","schema_version":"clob-market-ws.price_change.v1","sequence":null,"server_hash":null,"server_timestamp":"1785204361497","session_id":"d2757dd6dad94f3b9fe67e8dbf1adc37","source":"clob_market_ws"},"received_at":"2026-07-28T02:06:01.651848Z","record_id":"895cf1da587da57dc4a1e6d5e4b7266138e8e2b8c070595ccea329cccf47deed","schema_fingerprint":"4aa3821a28b0b7c2400bc59aba4bcc0a76e971dadd19610d3ad38c768e124dc7","schema_version":"edge-lab-recorder.raw.v1","sequence":null,"source":"clob_market_ws"}
{"event_at":"2026-07-28T02:06:01.498000Z","event_fingerprint":"9e878fef2a588b21b0329a2fd6d10446ccbd1fbee8899ab11d8e93bab904062c","payload":{"connection_id":"5d29200f65794d4d9ab6ef271f045a9b","event_at":"2026-07-28T02:06:01.498000Z","event_type":"price_change","frame_hash":"3f04621a5bea616b63a6e933f85def757be171414ab41cfd69afc445791c4a58","frame_index":0,"kind":"data","monotonic_ns":306344664473666,"payload":{"event_type":"price_change","market":"0xda6f0e0e93fc8469e0159a166028d017bddbc162b86f66bac90391379603d962","price_changes":[{"asset_id":"39272994714739463168905443499424551362424437245880253267329605556587274644733","best_ask":"0.74","best_bid":"0.73","hash":"e254b4dae49130dc24db2407c551a07f01b2ad42","price":"0.68","side":"BUY","size":"97"},{"asset_id":"20893381255801015515826997628594359667013752732428989472914000440642900266717","best_ask":"0.27","best_bid":"0.26","hash":"3b4c6c27ab656bb8907dbe5eb6c801f191ae7c46","price":"0.32","side":"SELL","size":"97"}],"timestamp":"1785204361498"},"payload_hash":"c28a738ce749d110b796e825409dc5c76147e031d9716158dc6dc7de664ac87b","raw_frame":"{\"market\":\"0xda6f0e0e93fc8469e0159a166028d017bddbc162b86f66bac90391379603d962\", \"price_changes\":[{\"asset_id\":\"39272994714739463168905443499424551362424437245880253267329605556587274644733\", \"price\":\"0.68\", \"size\":\"97\", \"side\":\"BUY\", \"hash\":\"e254b4dae49130dc24db2407c551a07f01b2ad42\", \"best_bid\":\"0.73\", \"best_ask\":\"0.74\"}, {\"asset_id\":\"20893381255801015515826997628594359667013752732428989472914000440642900266717\", \"price\":\"0.32\", \"size\":\"97\", \"side\":\"SELL\", \"hash\":\"3b4c6c27ab656bb8907dbe5eb6c801f191ae7c46\", \"best_bid\":\"0.26\", \"best_ask\":\"0.27\"}], \"timestamp\":\"1785204361498\", \"event_type\":\"price_change\"}","received_at":"2026-07-28T02:06:01.657842Z","schema_version":"clob-market-ws.price_change.v1","sequence":null,"server_hash":null,"server_timestamp":"1785204361498","session_id":"d2757dd6dad94f3b9fe67e8dbf1adc37","source":"clob_market_ws"},"received_at":"2026-07-28T02:06:01.657842Z","record_id":"3a2a902a7def9d6849825162b289c983979fbfb2d1b825d853b6d3709b6f5273","schema_fingerprint":"4aa3821a28b0b7c2400bc59aba4bcc0a76e971dadd19610d3ad38c768e124dc7","schema_version":"edge-lab-recorder.raw.v1","sequence":null,"source":"clob_market_ws"}
{"event_at":"2026-07-28T02:06:01.499000Z","event_fingerprint":"3d670ac0558232237d19ab49ca80daa9f02af7610326e8c6ce3dbf4078239963","payload":{"connection_id":"5d29200f65794d4d9ab6ef271f045a9b","event_at":"2026-07-28T02:06:01.499000Z","event_type":"price_change","frame_hash":"ae6e0978e094fd42a010fa60a3cf92ba51ed7e7484f5099df9f5f658401c7ad5","frame_index":0,"kind":"data","monotonic_ns":306344668927250,"payload":{"event_type":"price_change","market":"0xda6f0e0e93fc8469e0159a166028d017bddbc162b86f66bac90391379603d962","price_changes":[{"asset_id":"20893381255801015515826997628594359667013752732428989472914000440642900266717","best_ask":"0.27","best_bid":"0.26","hash":"85bf6a23c4cc9e2253311b23416ab5c1e2db245e","price":"0.17","side":"BUY","size":"188.3"},{"asset_id":"39272994714739463168905443499424551362424437245880253267329605556587274644733","best_ask":"0.74","best_bid":"0.73","hash":"3cf25b2ab241f59052f433692f9fa9eb7758a7c5","price":"0.83","side":"SELL","size":"188.3"}],"timestamp":"1785204361499"},"payload_hash":"aa9d5f066339faa6c7db8103e0b2cad834a7852e62b42f41a772af3c986e419f","raw_frame":"{\"market\":\"0xda6f0e0e93fc8469e0159a166028d017bddbc162b86f66bac90391379603d962\", \"price_changes\":[{\"asset_id\":\"20893381255801015515826997628594359667013752732428989472914000440642900266717\", \"price\":\"0.17\", \"size\":\"188.3\", \"side\":\"BUY\", \"hash\":\"85bf6a23c4cc9e2253311b23416ab5c1e2db245e\", \"best_bid\":\"0.26\", \"best_ask\":\"0.27\"}, {\"asset_id\":\"39272994714739463168905443499424551362424437245880253267329605556587274644733\", \"price\":\"0.83\", \"size\":\"188.3\", \"side\":\"SELL\", \"hash\":\"3cf25b2ab241f59052f433692f9fa9eb7758a7c5\", \"best_bid\":\"0.73\", \"best_ask\":\"0.74\"}], \"timestamp\":\"1785204361499\", \"event_type\":\"price_change\"}","received_at":"2026-07-28T02:06:01.662295Z","schema_version":"clob-market-ws.price_change.v1","sequence":null,"server_hash":null,"server_timestamp":"1785204361499","session_id":"d2757dd6dad94f3b9fe67e8dbf1adc37","source":"clob_market_ws"},"received_at":"2026-07-28T02:06:01.662295Z","record_id":"d192a6c3f5664d85c3bf1e7923d2b81bffe4f5c6bed0c40734b6e0ac7d399718","schema_fingerprint":"4aa3821a28b0b7c2400bc59aba4bcc0a76e971dadd19610d3ad38c768e124dc7","schema_version":"edge-lab-recorder.raw.v1","sequence":null,"source":"clob_market_ws"}
{"event_at":"2026-07-28T02:06:01.499000Z","event_fingerprint":"c08571c93cb6900ecf6a0cc5b9b0d3cef0f1c3c3c57a9898c4751c002f090a2b","payload":{"connection_id":"5d29200f65794d4d9ab6ef271f045a9b","event_at":"2026-07-28T02:06:01.499000Z","event_type":"price_change","frame_hash":"a77a2c1834c4a54501095c17c6e076f2b9f8bf00b44de536b2e2c85c31075783","frame_index":0,"kind":"data","monotonic_ns":306344673350250,"payload":{"event_type":"price_change","market":"0xda6f0e0e93fc8469e0159a166028d017bddbc162b86f66bac90391379603d962","price_changes":[{"asset_id":"20893381255801015515826997628594359667013752732428989472914000440642900266717","best_ask":"0.27","best_bid":"0.26","hash":"cf6a7c73669a1a1f36bfc03b5a5148a046df85f9","price":"0.25","side":"BUY","size":"84"},{"asset_id":"39272994714739463168905443499424551362424437245880253267329605556587274644733","best_ask":"0.74","best_bid":"0.73","hash":"c6e9a496f8e68ae3c2a8912e3c0cccf03b4f0061","price":"0.75","side":"SELL","size":"84"}],"timestamp":"1785204361499"},"payload_hash":"a9140092a3d7c406855d26cd6ca7045c1db6c6bff18d836423e38f21c6327d62","raw_frame":"{\"market\":\"0xda6f0e0e93fc8469e0159a166028d017bddbc162b86f66bac90391379603d962\", \"price_changes\":[{\"asset_id\":\"20893381255801015515826997628594359667013752732428989472914000440642900266717\", \"price\":\"0.25\", \"size\":\"84\", \"side\":\"BUY\", \"hash\":\"cf6a7c73669a1a1f36bfc03b5a5148a046df85f9\", \"best_bid\":\"0.26\", \"best_ask\":\"0.27\"}, {\"asset_id\":\"39272994714739463168905443499424551362424437245880253267329605556587274644733\", \"price\":\"0.75\", \"size\":\"84\", \"side\":\"SELL\", \"hash\":\"c6e9a496f8e68ae3c2a8912e3c0cccf03b4f0061\", \"best_bid\":\"0.73\", \"best_ask\":\"0.74\"}], \"timestamp\":\"1785204361499\", \"event_type\":\"price_change\"}","received_at":"2026-07-28T02:06:01.666718Z","schema_version":"clob-market-ws.price_change.v1","sequence":null,"server_hash":null,"server_timestamp":"1785204361499","session_id":"d2757dd6dad94f3b9fe67e8dbf1adc37","source":"clob_market_ws"},"received_at":"2026-07-28T02:06:01.666718Z","record_id":"9de3db8364f8c020fde599cbc4d4d0e337bf583253ca11b117532f7227e8ccff","schema_fingerprint":"4aa3821a28b0b7c2400bc59aba4bcc0a76e971dadd19610d3ad38c768e124dc7","schema_version":"edge-lab-recorder.raw.v1","sequence":null,"source":"clob_market_ws"}
{"event_at":"2026-07-28T02:06:01.500000Z","event_fingerprint":"9cde63e5fb35138bfa8e9d36d33670cb4fa94393d60c12615883fd2d4508a22c","payload":{"connection_id":"5d29200f65794d4d9ab6ef271f045a9b","event_at":"2026-07-28T02:06:01.500000Z","event_type":"price_change","frame_hash":"e811d0a6700967b17fd14969cc030aa012f53f94b8d5da586de32a7380a8b4e3","frame_index":0,"kind":"data","monotonic_ns":306344677691833,"payload":{"event_type":"price_change","market":"0xda6f0e0e93fc8469e0159a166028d017bddbc162b86f66bac90391379603d962","price_changes":[{"asset_id":"20893381255801015515826997628594359667013752732428989472914000440642900266717","best_ask":"0.27","best_bid":"0.26","hash":"0dd3b82f5a21d1df980a18c9ff1c8b4136b44a46","price":"0.26","side":"BUY","size":"20"},{"asset_id":"39272994714739463168905443499424551362424437245880253267329605556587274644733","best_ask":"0.74","best_bid":"0.73","hash":"af2ac229f0235927e03bf5c1b9546bff059593bb","price":"0.74","side":"SELL","size":"20"}],"timestamp":"1785204361500"},"payload_hash":"7ebfedbb0caac55a7283793fbade212959283f6059ba98f4e8058720e2793bc8","raw_frame":"{\"market\":\"0xda6f0e0e93fc8469e0159a166028d017bddbc162b86f66bac90391379603d962\", \"price_changes\":[{\"asset_id\":\"20893381255801015515826997628594359667013752732428989472914000440642900266717\", \"price\":\"0.26\", \"size\":\"20\", \"side\":\"BUY\", \"hash\":\"0dd3b82f5a21d1df980a18c9ff1c8b4136b44a46\", \"best_bid\":\"0.26\", \"best_ask\":\"0.27\"}, {\"asset_id\":\"39272994714739463168905443499424551362424437245880253267329605556587274644733\", \"price\":\"0.74\", \"size\":\"20\", \"side\":\"SELL\", \"hash\":\"af2ac229f0235927e03bf5c1b9546bff059593bb\", \"best_bid\":\"0.73\", \"best_ask\":\"0.74\"}], \"timestamp\":\"1785204361500\", \"event_type\":\"price_change\"}","received_at":"2026-07-28T02:06:01.671060Z","schema_version":"clob-market-ws.price_change.v1","sequence":null,"server_hash":null,"server_timestamp":"1785204361500","session_id":"d2757dd6dad94f3b9fe67e8dbf1adc37","source":"clob_market_ws"},"received_at":"2026-07-28T02:06:01.671060Z","record_id":"039fab78abf002247667507d7209479a1da448fed92b69780dbf4ee22bec4e96","schema_fingerprint":"4aa3821a28b0b7c2400bc59aba4bcc0a76e971dadd19610d3ad38c768e124dc7","schema_version":"edge-lab-recorder.raw.v1","sequence":null,"source":"clob_market_ws"}
{"event_at":"2026-07-28T02:06:01.501000Z","event_fingerprint":"baeff4c41b104bcf236d9423a5e6356fcfa41a28d29464f233c5d828f690a746","payload":{"connection_id":"5d29200f65794d4d9ab6ef271f045a9b","event_at":"2026-07-28T02:06:01.501000Z","event_type":"price_change","frame_hash":"458eeb8fc873c770d385b99227bf0ad33152bb9569cfcb2ec8e06cefa7357cb3","frame_index":0,"kind":"data","monotonic_ns":306344682052666,"payload":{"event_type":"price_change","market":"0xda6f0e0e93fc8469e0159a166028d017bddbc162b86f66bac90391379603d962","price_changes":[{"asset_id":"39272994714739463168905443499424551362424437245880253267329605556587274644733","best_ask":"0.74","best_bid":"0.73","hash":"8df760b83c9a5579b637749eef61935bfb29aa56","price":"0.69","side":"BUY","size":"100.65"},{"asset_id":"20893381255801015515826997628594359667013752732428989472914000440642900266717","best_ask":"0.27","best_bid":"0.26","hash":"15d48136f9d3c8b8a260da450bf700183f188bef","price":"0.31","side":"SELL","size":"100.65"}],"timestamp":"1785204361501"},"payload_hash":"d4b1431a206fa3bf226bc7d8b7b313eccd2eec7459dee8e8453bfd31f21425c5","raw_frame":"{\"market\":\"0xda6f0e0e93fc8469e0159a166028d017bddbc162b86f66bac90391379603d962\", \"price_changes\":[{\"asset_id\":\"39272994714739463168905443499424551362424437245880253267329605556587274644733\", \"price\":\"0.69\", \"size\":\"100.65\", \"side\":\"BUY\", \"hash\":\"8df760b83c9a5579b637749eef61935bfb29aa56\", \"best_bid\":\"0.73\", \"best_ask\":\"0.74\"}, {\"asset_id\":\"20893381255801015515826997628594359667013752732428989472914000440642900266717\", \"price\":\"0.31\", \"size\":\"100.65\", \"side\":\"SELL\", \"hash\":\"15d48136f9d3c8b8a260da450bf700183f188bef\", \"best_bid\":\"0.26\", \"best_ask\":\"0.27\"}], \"timestamp\":\"1785204361501\", \"event_type\":\"price_change\"}","received_at":"2026-07-28T02:06:01.675421Z","schema_version":"clob-market-ws.price_change.v1","sequence":null,"server_hash":null,"server_timestamp":"1785204361501","session_id":"d2757dd6dad94f3b9fe67e8dbf1adc37","source":"clob_market_ws"},"received_at":"2026-07-28T02:06:01.675421Z","record_id":"49fc9f9bde988af6952afc1321bc5548de08b9d96a61ea2667d52802b0e7b01e","schema_fingerprint":"4aa3821a28b0b7c2400bc59aba4bcc0a76e971dadd19610d3ad38c768e124dc7","schema_version":"edge-lab-recorder.raw.v1","sequence":null,"source":"clob_market_ws"}
{"event_at":"2026-07-28T02:06:01.501000Z","event_fingerprint":"32f5d61e00bc1a7126e715d29a816a35c402c4d6b9e12c50f0412e0b89a8d985","payload":{"connection_id":"5d29200f65794d4d9ab6ef271f045a9b","event_at":"2026-07-28T02:06:01.501000Z","event_type":"price_change","frame_hash":"aebbda4f77b6484f97bb5be131a9ece6d8efd9ade8c3ef6e4230f2636fb2a7e3","frame_index":0,"kind":"data","monotonic_ns":306344686413791,"payload":{"event_type":"price_change","market":"0xda6f0e0e93fc8469e0159a166028d017bddbc162b86f66bac90391379603d962","price_changes":[{"asset_id":"20893381255801015515826997628594359667013752732428989472914000440642900266717","best_ask":"0.27","best_bid":"0.26","hash":"15d48136f9d3c8b8a260da450bf700183f188bef","price":"0.24","side":"BUY","size":"84.2"},{"asset_id":"39272994714739463168905443499424551362424437245880253267329605556587274644733","best_ask":"0.74","best_bid":"0.73","hash":"8df760b83c9a5579b637749eef61935bfb29aa56","price":"0.76","side":"SELL","size":"84.2"}],"timestamp":"1785204361501"},"payload_hash":"0e52aa087d9d6c1805f45c9e30b009777540cf5132c2ec00f73157e3e3276534","raw_frame":"{\"market\":\"0xda6f0e0e93fc8469e0159a166028d017bddbc162b86f66bac90391379603d962\", \"price_changes\":[{\"asset_id\":\"20893381255801015515826997628594359667013752732428989472914000440642900266717\", \"price\":\"0.24\", \"size\":\"84.2\", \"side\":\"BUY\", \"hash\":\"15d48136f9d3c8b8a260da450bf700183f188bef\", \"best_bid\":\"0.26\", \"best_ask\":\"0.27\"}, {\"asset_id\":\"39272994714739463168905443499424551362424437245880253267329605556587274644733\", \"price\":\"0.76\", \"size\":\"84.2\", \"side\":\"SELL\", \"hash\":\"8df760b83c9a5579b637749eef61935bfb29aa56\", \"best_bid\":\"0.73\", \"best_ask\":\"0.74\"}], \"timestamp\":\"1785204361501\", \"event_type\":\"price_change\"}","received_at":"2026-07-28T02:06:01.679782Z","schema_version":"clob-market-ws.price_change.v1","sequence":null,"server_hash":null,"server_timestamp":"1785204361501","session_id":"d2757dd6dad94f3b9fe67e8dbf1adc37","source":"clob_market_ws"},"received_at":"2026-07-28T02:06:01.679782Z","record_id":"827da7be12da950d420660a097b9c71e41a9c57a3393f7592e2ff327770be36a","schema_fingerprint":"4aa3821a28b0b7c2400bc59aba4bcc0a76e971dadd19610d3ad38c768e124dc7","schema_version":"edge-lab-recorder.raw.v1","sequence":null,"source":"clob_market_ws"}
{"event_at":"2026-07-28T02:06:01.501000Z","event_fingerprint":"8b30660d5be25817273415f1ddced992bb842b80b2cc2b09020a824e3e172305","payload":{"connection_id":"5d29200f65794d4d9ab6ef271f045a9b","event_at":"2026-07-28T02:06:01.501000Z","event_type":"price_change","frame_hash":"4abed53abb84633fbcc3fa1bfd143fc840a12e1d3c1c48737021cf0ead43a22f","frame_index":0,"kind":"data","monotonic_ns":306344690803750,"payload":{"event_type":"price_change","market":"0xda6f0e0e93fc8469e0159a166028d017bddbc162b86f66bac90391379603d962","price_changes":[{"asset_id":"20893381255801015515826997628594359667013752732428989472914000440642900266717","best_ask":"0.27","best_bid":"0.26","hash":"ec2d655dac465d82c0abb82a450d8c1715f0eb8c","price":"0.25","side":"BUY","size":"96.6"},{"asset_id":"39272994714739463168905443499424551362424437245880253267329605556587274644733","best_ask":"0.74","best_bid":"0.73","hash":"707f30db6208188bcb9fe7b9ae8138fee68d7032","price":"0.75","side":"SELL","size":"96.6"}],"timestamp":"1785204361501"},"payload_hash":"bb18a115bb683d551828e37e1ccf2db50397916d0d5890dc3d435f5aec9db087","raw_frame":"{\"market\":\"0xda6f0e0e93fc8469e0159a166028d017bddbc162b86f66bac90391379603d962\", \"price_changes\":[{\"asset_id\":\"20893381255801015515826997628594359667013752732428989472914000440642900266717\", \"price\":\"0.25\", \"size\":\"96.6\", \"side\":\"BUY\", \"hash\":\"ec2d655dac465d82c0abb82a450d8c1715f0eb8c\", \"best_bid\":\"0.26\", \"best_ask\":\"0.27\"}, {\"asset_id\":\"39272994714739463168905443499424551362424437245880253267329605556587274644733\", \"price\":\"0.75\", \"size\":\"96.6\", \"side\":\"SELL\", \"hash\":\"707f30db6208188bcb9fe7b9ae8138fee68d7032\", \"best_bid\":\"0.73\", \"best_ask\":\"0.74\"}], \"timestamp\":\"1785204361501\", \"event_type\":\"price_change\"}","received_at":"2026-07-28T02:06:01.684172Z","schema_version":"clob-market-ws.price_change.v1","sequence":null,"server_hash":null,"server_timestamp":"1785204361501","session_id":"d2757dd6dad94f3b9fe67e8dbf1adc37","source":"clob_market_ws"},"received_at":"2026-07-28T02:06:01.684172Z","record_id":"eb2d63a29bf960f649b71b19b2b828bbc3ff52713db1f05372e3589970212de0","schema_fingerprint":"4aa3821a28b0b7c2400bc59aba4bcc0a76e971dadd19610d3ad38c768e124dc7","schema_version":"edge-lab-recorder.raw.v1","sequence":null,"source":"clob_market_ws"}
{"event_at":"2026-07-28T02:06:01.503000Z","event_fingerprint":"2806b5a996349e4d9e3f480d79e98786b886785f4859ab1654dd16da0ec26db1","payload":{"connection_id":"5d29200f65794d4d9ab6ef271f045a9b","event_at":"2026-07-28T02:06:01.503000Z","event_type":"price_change","frame_hash":"731f372156ddd31f5cb94e3f4eefde0ddb8a5379032a3de519758e1e8ccc7c5c","frame_index":0,"kind":"data","monotonic_ns":306344695241208,"payload":{"event_type":"price_change","market":"0xda6f0e0e93fc8469e0159a166028d017bddbc162b86f66bac90391379603d962","price_changes":[{"asset_id":"39272994714739463168905443499424551362424437245880253267329605556587274644733","best_ask":"0.74","best_bid":"0.73","hash":"ec4e551182d6534400d17d645271bc7e3b4b26af","price":"0.72","side":"BUY","size":"144.51"},{"asset_id":"20893381255801015515826997628594359667013752732428989472914000440642900266717","best_ask":"0.27","best_bid":"0.26","hash":"e2d49a32c4f20663051becdd5274d5a08496c047","price":"0.28","side":"SELL","size":"144.51"}],"timestamp":"1785204361503"},"payload_hash":"44ee5832cc6abd0f4286551bae37b0c95afefe27d87fce5c7b55df38a5ad88f4","raw_frame":"{\"market\":\"0xda6f0e0e93fc8469e0159a166028d017bddbc162b86f66bac90391379603d962\", \"price_changes\":[{\"asset_id\":\"39272994714739463168905443499424551362424437245880253267329605556587274644733\", \"price\":\"0.72\", \"size\":\"144.51\", \"side\":\"BUY\", \"hash\":\"ec4e551182d6534400d17d645271bc7e3b4b26af\", \"best_bid\":\"0.73\", \"best_ask\":\"0.74\"}, {\"asset_id\":\"20893381255801015515826997628594359667013752732428989472914000440642900266717\", \"price\":\"0.28\", \"size\":\"144.51\", \"side\":\"SELL\", \"hash\":\"e2d49a32c4f20663051becdd5274d5a08496c047\", \"best_bid\":\"0.26\", \"best_ask\":\"0.27\"}], \"timestamp\":\"1785204361503\", \"event_type\":\"price_change\"}","received_at":"2026-07-28T02:06:01.688610Z","schema_version":"clob-market-ws.price_change.v1","sequence":null,"server_hash":null,"server_timestamp":"1785204361503","session_id":"d2757dd6dad94f3b9fe67e8dbf1adc37","source":"clob_market_ws"},"received_at":"2026-07-28T02:06:01.688610Z","record_id":"e64199376577b4d7c997a59027753efa046aed06513bfdbb987e2298593c1247","schema_fingerprint":"4aa3821a28b0b7c2400bc59aba4bcc0a76e971dadd19610d3ad38c768e124dc7","schema_version":"edge-lab-recorder.raw.v1","sequence":null,"source":"clob_market_ws"}
{"event_at":"2026-07-28T02:06:01.503000Z","event_fingerprint":"f5de65b503b4719025e6c7114277a1e31cd29a51cfd62212f86856e52e0c8fac","payload":{"connection_id":"5d29200f65794d4d9ab6ef271f045a9b","event_at":"2026-07-28T02:06:01.503000Z","event_type":"price_change","frame_hash":"c86431f92152797a6735f03ce8731b7d6e2a2c6e187e7c3dfb04fb2369e6f4df","frame_index":0,"kind":"data","monotonic_ns":306344700452625,"payload":{"event_type":"price_change","market":"0xda6f0e0e93fc8469e0159a166028d017bddbc162b86f66bac90391379603d962","price_changes":[{"asset_id":"39272994714739463168905443499424551362424437245880253267329605556587274644733","best_ask":"0.74","best_bid":"0.73","hash":"d330b9d2520f64b0b50337e61f6a13dd0a6b2015","price":"0.73","side":"BUY","size":"41.6"},{"asset_id":"20893381255801015515826997628594359667013752732428989472914000440642900266717","best_ask":"0.27","best_bid":"0.26","hash":"7d7e9320da19a344446787977b71fd8dc192bc74","price":"0.27","side":"SELL","size":"41.6"}],"timestamp":"1785204361503"},"payload_hash":"e794138685b8944b10ed7f1791e1edae05beb006e09ac65583f3bd15de13adb6","raw_frame":"{\"market\":\"0xda6f0e0e93fc8469e0159a166028d017bddbc162b86f66bac90391379603d962\", \"price_changes\":[{\"asset_id\":\"39272994714739463168905443499424551362424437245880253267329605556587274644733\", \"price\":\"0.73\", \"size\":\"41.6\", \"side\":\"BUY\", \"hash\":\"d330b9d2520f64b0b50337e61f6a13dd0a6b2015\", \"best_bid\":\"0.73\", \"best_ask\":\"0.74\"}, {\"asset_id\":\"20893381255801015515826997628594359667013752732428989472914000440642900266717\", \"price\":\"0.27\", \"size\":\"41.6\", \"side\":\"SELL\", \"hash\":\"7d7e9320da19a344446787977b71fd8dc192bc74\", \"best_bid\":\"0.26\", \"best_ask\":\"0.27\"}], \"timestamp\":\"1785204361503\", \"event_type\":\"price_change\"}","received_at":"2026-07-28T02:06:01.693820Z","schema_version":"clob-market-ws.price_change.v1","sequence":null,"server_hash":null,"server_timestamp":"1785204361503","session_id":"d2757dd6dad94f3b9fe67e8dbf1adc37","source":"clob_market_ws"},"received_at":"2026-07-28T02:06:01.693820Z","record_id":"10d2524a7d1fece0b0523537fa5db2b0e41fd31ccd7b338b570d775ac4796ed1","schema_fingerprint":"4aa3821a28b0b7c2400bc59aba4bcc0a76e971dadd19610d3ad38c768e124dc7","schema_version":"edge-lab-recorder.raw.v1","sequence":null,"source":"clob_market_ws"}
{"event_at":"2026-07-28T02:06:01.504000Z","event_fingerprint":"80a4d30377f30a4ff28cdaf0a04d178382946c7dc051eefa4589d8a9aa882696","payload":{"connection_id":"5d29200f65794d4d9ab6ef271f045a9b","event_at":"2026-07-28T02:06:01.504000Z","event_type":"price_change","frame_hash":"2c3c0fad8d8f289554f3d9d5448cb039ad4998d960a69509a53b3a611c8c0f0d","frame_index":0,"kind":"data","monotonic_ns":306344704297000,"payload":{"event_type":"price_change","market":"0xda6f0e0e93fc8469e0159a166028d017bddbc162b86f66bac90391379603d962","price_changes":[{"asset_id":"20893381255801015515826997628594359667013752732428989472914000440642900266717","best_ask":"0.27","best_bid":"0.26","hash":"42200c0779186a04ec3cf9a3bacad17426007579","price":"0.21","side":"BUY","size":"104.46"},{"asset_id":"39272994714739463168905443499424551362424437245880253267329605556587274644733","best_ask":"0.74","best_bid":"0.73","hash":"9e767be6776d448a6e89a00c30bf67bb5c5b8349","price":"0.79","side":"SELL","size":"104.46"}],"timestamp":"1785204361504"},"payload_hash":"ece212ec4d3ea72b9ae128b3886c2bb5f450c0aaa6c544cf59532ef2364d34fb","raw_frame":"{\"market\":\"0xda6f0e0e93fc8469e0159a166028d017bddbc162b86f66bac90391379603d962\", \"price_changes\":[{\"asset_id\":\"20893381255801015515826997628594359667013752732428989472914000440642900266717\", \"price\":\"0.21\", \"size\":\"104.46\", \"side\":\"BUY\", \"hash\":\"42200c0779186a04ec3cf9a3bacad17426007579\", \"best_bid\":\"0.26\", \"best_ask\":\"0.27\"}, {\"asset_id\":\"39272994714739463168905443499424551362424437245880253267329605556587274644733\", \"price\":\"0.79\", \"size\":\"104.46\", \"side\":\"SELL\", \"hash\":\"9e767be6776d448a6e89a00c30bf67bb5c5b8349\", \"best_bid\":\"0.73\", \"best_ask\":\"0.74\"}], \"timestamp\":\"1785204361504\", \"event_type\":\"price_change\"}","received_at":"2026-07-28T02:06:01.697663Z","schema_version":"clob-market-ws.price_change.v1","sequence":null,"server_hash":null,"server_timestamp":"1785204361504","session_id":"d2757dd6dad94f3b9fe67e8dbf1adc37","source":"clob_market_ws"},"received_at":"2026-07-28T02:06:01.697663Z","record_id":"ae4e9639618ce1bc2f7d326cc8954817b7ac4c9b4cd26a3370f76f5e4c3609fa","schema_fingerprint":"4aa3821a28b0b7c2400bc59aba4bcc0a76e971dadd19610d3ad38c768e124dc7","schema_version":"edge-lab-recorder.raw.v1","sequence":null,"source":"clob_market_ws"}
{"event_at":"2026-07-28T02:06:01.506000Z","event_fingerprint":"d6655a1158355fd7022b7010bb350e84281158991f75489b5bd93d58fd118019","payload":{"connection_id":"5d29200f65794d4d9ab6ef271f045a9b","event_at":"2026-07-28T02:06:01.506000Z","event_type":"price_change","frame_hash":"339d075808ec1d4592a4f099b4352e60999b5f34b2d8db32468b6bae6eb9b8d5","frame_index":0,"kind":"data","monotonic_ns":306344708665125,"payload":{"event_type":"price_change","market":"0xda6f0e0e93fc8469e0159a166028d017bddbc162b86f66bac90391379603d962","price_changes":[{"asset_id":"39272994714739463168905443499424551362424437245880253267329605556587274644733","best_ask":"0.74","best_bid":"0.73","hash":"6f11408dc21081737199d3707d83c3352af734f8","price":"0.71","side":"BUY","size":"127.22"},{"asset_id":"20893381255801015515826997628594359667013752732428989472914000440642900266717","best_ask":"0.27","best_bid":"0.26","hash":"968fab42cc5a50d2e7840d0bef2ce94dd8ac1319","price":"0.29","side":"SELL","size":"127.22"}],"timestamp":"1785204361506"},"payload_hash":"553c429550d3ee8081a4b5302611f9787942b99747bdb10f87070120bedef500","raw_frame":"{\"market\":\"0xda6f0e0e93fc8469e0159a166028d017bddbc162b86f66bac90391379603d962\", \"price_changes\":[{\"asset_id\":\"39272994714739463168905443499424551362424437245880253267329605556587274644733\", \"price\":\"0.71\", \"size\":\"127.22\", \"side\":\"BUY\", \"hash\":\"6f11408dc21081737199d3707d83c3352af734f8\", \"best_bid\":\"0.73\", \"best_ask\":\"0.74\"}, {\"asset_id\":\"20893381255801015515826997628594359667013752732428989472914000440642900266717\", \"price\":\"0.29\", \"size\":\"127.22\", \"side\":\"SELL\", \"hash\":\"968fab42cc5a50d2e7840d0bef2ce94dd8ac1319\", \"best_bid\":\"0.26\", \"best_ask\":\"0.27\"}], \"timestamp\":\"1785204361506\", \"event_type\":\"price_change\"}","received_at":"2026-07-28T02:06:01.702033Z","schema_version":"clob-market-ws.price_change.v1","sequence":null,"server_hash":null,"server_timestamp":"1785204361506","session_id":"d2757dd6dad94f3b9fe67e8dbf1adc37","source":"clob_market_ws"},"received_at":"2026-07-28T02:06:01.702033Z","record_id":"8c646a8a9e18e5cd5615f1acd3a89de36011321fe36a70f2a822c5cf14a17910","schema_fingerprint":"4aa3821a28b0b7c2400bc59aba4bcc0a76e971dadd19610d3ad38c768e124dc7","schema_version":"edge-lab-recorder.raw.v1","sequence":null,"source":"clob_market_ws"}
{"event_at":"2026-07-28T02:06:01.508000Z","event_fingerprint":"63606082f440eaa809de07d36ec5a41856f14f952307081562c976efbd5bdee1","payload":{"connection_id":"5d29200f65794d4d9ab6ef271f045a9b","event_at":"2026-07-28T02:06:01.508000Z","event_type":"price_change","frame_hash":"e176bfad09fcae4ab72fa56ea73a9bab1dbd6c16a195a29cedcc1f222e85ff20","frame_index":0,"kind":"data","monotonic_ns":306344714340375,"payload":{"event_type":"price_change","market":"0xda6f0e0e93fc8469e0159a166028d017bddbc162b86f66bac90391379603d962","price_changes":[{"asset_id":"20893381255801015515826997628594359667013752732428989472914000440642900266717","best_ask":"0.27","best_bid":"0.26","hash":"41c6a664e14fb74d57f26e75ef515f0bbe8b89d7","price":"0.25","side":"BUY","size":"109.2"},{"asset_id":"39272994714739463168905443499424551362424437245880253267329605556587274644733","best_ask":"0.74","best_bid":"0.73","hash":"ca3421bc782cb06cf490ac680c06bc279d8f23bf","price":"0.75","side":"SELL","size":"109.2"}],"timestamp":"1785204361508"},"payload_hash":"a25c0879e945a605c113c012da4cac4c1399181ea3bc36da1702e56acb4b2833","raw_frame":"{\"market\":\"0xda6f0e0e93fc8469e0159a166028d017bddbc162b86f66bac90391379603d962\", \"price_changes\":[{\"asset_id\":\"20893381255801015515826997628594359667013752732428989472914000440642900266717\", \"price\":\"0.25\", \"size\":\"109.2\", \"side\":\"BUY\", \"hash\":\"41c6a664e14fb74d57f26e75ef515f0bbe8b89d7\", \"best_bid\":\"0.26\", \"best_ask\":\"0.27\"}, {\"asset_id\":\"39272994714739463168905443499424551362424437245880253267329605556587274644733\", \"price\":\"0.75\", \"size\":\"109.2\", \"side\":\"SELL\", \"hash\":\"ca3421bc782cb06cf490ac680c06bc279d8f23bf\", \"best_bid\":\"0.73\", \"best_ask\":\"0.74\"}], \"timestamp\":\"1785204361508\", \"event_type\":\"price_change\"}","received_at":"2026-07-28T02:06:01.707708Z","schema_version":"clob-market-ws.price_change.v1","sequence":null,"server_hash":null,"server_timestamp":"1785204361508","session_id":"d2757dd6dad94f3b9fe67e8dbf1adc37","source":"clob_market_ws"},"received_at":"2026-07-28T02:06:01.707708Z","record_id":"d40bcb3c1c6823e1b27021ac4ce5817949684efeac0a781ace6f1ec92dd2e750","schema_fingerprint":"4aa3821a28b0b7c2400bc59aba4bcc0a76e971dadd19610d3ad38c768e124dc7","schema_version":"edge-lab-recorder.raw.v1","sequence":null,"source":"clob_market_ws"}
{"event_at":"2026-07-28T02:06:01.511000Z","event_fingerprint":"2840ebb4ff7bfc8b9409f82cc13cdc1c0c02b86c50aab4d9bd5f37d771e6c137","payload":{"connection_id":"5d29200f65794d4d9ab6ef271f045a9b","event_at":"2026-07-28T02:06:01.511000Z","event_type":"price_change","frame_hash":"70f2241062ac1af87944eac7b10abe6159f0bccf49ada6f676675a67addc10f3","frame_index":0,"kind":"data","monotonic_ns":306344717635333,"payload":{"event_type":"price_change","market":"0xda6f0e0e93fc8469e0159a166028d017bddbc162b86f66bac90391379603d962","price_changes":[{"asset_id":"20893381255801015515826997628594359667013752732428989472914000440642900266717","best_ask":"0.27","best_bid":"0.26","hash":"51ac034a9bab82d47e304cc9661a50b21934934a","price":"0.25","side":"BUY","size":"96.6"},{"asset_id":"39272994714739463168905443499424551362424437245880253267329605556587274644733","best_ask":"0.74","best_bid":"0.73","hash":"c6726deda1e6947887786a7473650105af7334f1","price":"0.75","side":"SELL","size":"96.6"}],"timestamp":"1785204361511"},"payload_hash":"b85bb9adddc5fd86aa7423ec301ecfd9b5cec1840c18b0f6a2a7506915b553e5","raw_frame":"{\"market\":\"0xda6f0e0e93fc8469e0159a166028d017bddbc162b86f66bac90391379603d962\", \"price_changes\":[{\"asset_id\":\"20893381255801015515826997628594359667013752732428989472914000440642900266717\", \"price\":\"0.25\", \"size\":\"96.6\", \"side\":\"BUY\", \"hash\":\"51ac034a9bab82d47e304cc9661a50b21934934a\", \"best_bid\":\"0.26\", \"best_ask\":\"0.27\"}, {\"asset_id\":\"39272994714739463168905443499424551362424437245880253267329605556587274644733\", \"price\":\"0.75\", \"size\":\"96.6\", \"side\":\"SELL\", \"hash\":\"c6726deda1e6947887786a7473650105af7334f1\", \"best_bid\":\"0.73\", \"best_ask\":\"0.74\"}], \"timestamp\":\"1785204361511\", \"event_type\":\"price_change\"}","received_at":"2026-07-28T02:06:01.711004Z","schema_version":"clob-market-ws.price_change.v1","sequence":null,"server_hash":null,"server_timestamp":"1785204361511","session_id":"d2757dd6dad94f3b9fe67e8dbf1adc37","source":"clob_market_ws"},"received_at":"2026-07-28T02:06:01.711004Z","record_id":"2f1f3f2b2dd08453e4e41f4746287a52d448931ee976373edbb46a746315e0bf","schema_fingerprint":"4aa3821a28b0b7c2400bc59aba4bcc0a76e971dadd19610d3ad38c768e124dc7","schema_version":"edge-lab-recorder.raw.v1","sequence":null,"source":"clob_market_ws"}
{"event_at":"2026-07-28T02:06:01.511000Z","event_fingerprint":"ea3b3b50875d5cfd222c0b995c9165b93890ecd4869d4ca62678447e0fbb0a47","payload":{"connection_id":"5d29200f65794d4d9ab6ef271f045a9b","event_at":"2026-07-28T02:06:01.511000Z","event_type":"price_change","frame_hash":"362fb35fb1cac6f06cf3b647e15c632f0a48741278d5a1518c6a2ab57351d56f","frame_index":0,"kind":"data","monotonic_ns":306344722446416,"payload":{"event_type":"price_change","market":"0xda6f0e0e93fc8469e0159a166028d017bddbc162b86f66bac90391379603d962","price_changes":[{"asset_id":"39272994714739463168905443499424551362424437245880253267329605556587274644733","best_ask":"0.74","best_bid":"0.73","hash":"22b6bf53a189bc5f4d8bbef0887ac96e83c27cb8","price":"0.72","side":"BUY","size":"114.51"},{"asset_id":"20893381255801015515826997628594359667013752732428989472914000440642900266717","best_ask":"0.27","best_bid":"0.26","hash":"5fc52f6ea7bcda809431645b9cabc6830ba0b85b","price":"0.28","side":"SELL","size":"114.51"}],"timestamp":"1785204361511"},"payload_hash":"b3b1020a7e22350661ce62f8c8f3e77c2510a5a2b923d65df7b260642da8a3fa","raw_frame":"{\"market\":\"0xda6f0e0e93fc8469e0159a166028d017bddbc162b86f66bac90391379603d962\", \"price_changes\":[{\"asset_id\":\"39272994714739463168905443499424551362424437245880253267329605556587274644733\", \"price\":\"0.72\", \"size\":\"114.51\", \"side\":\"BUY\", \"hash\":\"22b6bf53a189bc5f4d8bbef0887ac96e83c27cb8\", \"best_bid\":\"0.73\", \"best_ask\":\"0.74\"}, {\"asset_id\":\"20893381255801015515826997628594359667013752732428989472914000440642900266717\", \"price\":\"0.28\", \"size\":\"114.51\", \"side\":\"SELL\", \"hash\":\"5fc52f6ea7bcda809431645b9cabc6830ba0b85b\", \"best_bid\":\"0.26\", \"best_ask\":\"0.27\"}], \"timestamp\":\"1785204361511\", \"event_type\":\"price_change\"}","received_at":"2026-07-28T02:06:01.715816Z","schema_version":"clob-market-ws.price_change.v1","sequence":null,"server_hash":null,"server_timestamp":"1785204361511","session_id":"d2757dd6dad94f3b9fe67e8dbf1adc37","source":"clob_market_ws"},"received_at":"2026-07-28T02:06:01.715816Z","record_id":"442d4e66b186844069492f84cfb8e051284a786848832c2c2a9ea8dc4f384e65","schema_fingerprint":"4aa3821a28b0b7c2400bc59aba4bcc0a76e971dadd19610d3ad38c768e124dc7","schema_version":"edge-lab-recorder.raw.v1","sequence":null,"source":"clob_market_ws"}
{"event_at":"2026-07-28T02:06:01.512000Z","event_fingerprint":"35405d148e4e657f6e9625a65e02f3e7ea8ed6efe5421d23b99afd5996fb3aca","payload":{"connection_id":"5d29200f65794d4d9ab6ef271f045a9b","event_at":"2026-07-28T02:06:01.512000Z","event_type":"price_change","frame_hash":"cc381149071e3d5521ea2283d633f87e32940950c194f6b47e6773751aa4dace","frame_index":0,"kind":"data","monotonic_ns":306344730106583,"payload":{"event_type":"price_change","market":"0xda6f0e0e93fc8469e0159a166028d017bddbc162b86f66bac90391379603d962","price_changes":[{"asset_id":"39272994714739463168905443499424551362424437245880253267329605556587274644733","best_ask":"0.74","best_bid":"0.73","hash":"9134c9607d01d766bf49eab055906f7eeeb5bddd","price":"0.73","side":"BUY","size":"29"},{"asset_id":"20893381255801015515826997628594359667013752732428989472914000440642900266717","best_ask":"0.27","best_bid":"0.26","hash":"fc6b7a5cc5315e6ce0b2f9f6cced22605d68c83c","price":"0.27","side":"SELL","size":"29"}],"timestamp":"1785204361512"},"payload_hash":"7415170a09ba020da4f12f2cc0ff2d224a992627a8d81717b85754536f8421a1","raw_frame":"{\"market\":\"0xda6f0e0e93fc8469e0159a166028d017bddbc162b86f66bac90391379603d962\", \"price_changes\":[{\"asset_id\":\"39272994714739463168905443499424551362424437245880253267329605556587274644733\", \"price\":\"0.73\", \"size\":\"29\", \"side\":\"BUY\", \"hash\":\"9134c9607d01d766bf49eab055906f7eeeb5bddd\", \"best_bid\":\"0.73\", \"best_ask\":\"0.74\"}, {\"asset_id\":\"20893381255801015515826997628594359667013752732428989472914000440642900266717\", \"price\":\"0.27\", \"size\":\"29\", \"side\":\"SELL\", \"hash\":\"fc6b7a5cc5315e6ce0b2f9f6cced22605d68c83c\", \"best_bid\":\"0.26\", \"best_ask\":\"0.27\"}], \"timestamp\":\"1785204361512\", \"event_type\":\"price_change\"}","received_at":"2026-07-28T02:06:01.723474Z","schema_version":"clob-market-ws.price_change.v1","sequence":null,"server_hash":null,"server_timestamp":"1785204361512","session_id":"d2757dd6dad94f3b9fe67e8dbf1adc37","source":"clob_market_ws"},"received_at":"2026-07-28T02:06:01.723474Z","record_id":"82b7ad5dbfca280d4df2327a5e91fbead813075985b1b9d50b5c3faeeb6d204d","schema_fingerprint":"4aa3821a28b0b7c2400bc59aba4bcc0a76e971dadd19610d3ad38c768e124dc7","schema_version":"edge-lab-recorder.raw.v1","sequence":null,"source":"clob_market_ws"}
{"event_at":"2026-07-28T02:06:01.514000Z","event_fingerprint":"87c81c42f87dac928ac75e60e7dc7e34d83e0db7cde50ebc88132023a44a3367","payload":{"connection_id":"5d29200f65794d4d9ab6ef271f045a9b","event_at":"2026-07-28T02:06:01.514000Z","event_type":"price_change","frame_hash":"13d5d5b22d34b430f87a78d072a069c0a3389a5113d3891fb14910ced2f0eb58","frame_index":0,"kind":"data","monotonic_ns":306344733960208,"payload":{"event_type":"price_change","market":"0xda6f0e0e93fc8469e0159a166028d017bddbc162b86f66bac90391379603d962","price_changes":[{"asset_id":"39272994714739463168905443499424551362424437245880253267329605556587274644733","best_ask":"0.74","best_bid":"0.73","hash":"5c3cc27b3ac26d9362ab9a3287d8fa8e8eb6418c","price":"0.66","side":"BUY","size":"86"},{"asset_id":"20893381255801015515826997628594359667013752732428989472914000440642900266717","best_ask":"0.27","best_bid":"0.26","hash":"f177413ab316b50fad9094c7c2fb6ae317c7692c","price":"0.34","side":"SELL","size":"86"}],"timestamp":"1785204361514"},"payload_hash":"5acdec0c84389e4c67affd58c3ae816e5ad51d625eb0a83bc609b50141219387","raw_frame":"{\"market\":\"0xda6f0e0e93fc8469e0159a166028d017bddbc162b86f66bac90391379603d962\", \"price_changes\":[{\"asset_id\":\"39272994714739463168905443499424551362424437245880253267329605556587274644733\", \"price\":\"0.66\", \"size\":\"86\", \"side\":\"BUY\", \"hash\":\"5c3cc27b3ac26d9362ab9a3287d8fa8e8eb6418c\", \"best_bid\":\"0.73\", \"best_ask\":\"0.74\"}, {\"asset_id\":\"20893381255801015515826997628594359667013752732428989472914000440642900266717\", \"price\":\"0.34\", \"size\":\"86\", \"side\":\"SELL\", \"hash\":\"f177413ab316b50fad9094c7c2fb6ae317c7692c\", \"best_bid\":\"0.26\", \"best_ask\":\"0.27\"}], \"timestamp\":\"1785204361514\", \"event_type\":\"price_change\"}","received_at":"2026-07-28T02:06:01.727325Z","schema_version":"clob-market-ws.price_change.v1","sequence":null,"server_hash":null,"server_timestamp":"1785204361514","session_id":"d2757dd6dad94f3b9fe67e8dbf1adc37","source":"clob_market_ws"},"received_at":"2026-07-28T02:06:01.727325Z","record_id":"2cef09bb5a30d83e3d0d5606a6b2aca342e4cac10165065facec02b16f48aa7e","schema_fingerprint":"4aa3821a28b0b7c2400bc59aba4bcc0a76e971dadd19610d3ad38c768e124dc7","schema_version":"edge-lab-recorder.raw.v1","sequence":null,"source":"clob_market_ws"}
{"event_at":"2026-07-28T02:06:01.516000Z","event_fingerprint":"1be038bab1f1d4b511ae7e66dfdae63ba97e5182743ec2049b70f63516a80675","payload":{"connection_id":"5d29200f65794d4d9ab6ef271f045a9b","event_at":"2026-07-28T02:06:01.516000Z","event_type":"price_change","frame_hash":"b8ec1ac7396efbb7c80d70eeb80912e0d24aec16da369c4fc486ad13434eff90","frame_index":0,"kind":"data","monotonic_ns":306344738670416,"payload":{"event_type":"price_change","market":"0xda6f0e0e93fc8469e0159a166028d017bddbc162b86f66bac90391379603d962","price_changes":[{"asset_id":"39272994714739463168905443499424551362424437245880253267329605556587274644733","best_ask":"0.74","best_bid":"0.73","hash":"f1d858b1e430975abd6a4ff718103f68c1fc051e","price":"0.68","side":"BUY","size":"57"},{"asset_id":"20893381255801015515826997628594359667013752732428989472914000440642900266717","best_ask":"0.27","best_bid":"0.26","hash":"1e2fe913cd5cde83039decb7e1ac25afef1a2565","price":"0.32","side":"SELL","size":"57"}],"timestamp":"1785204361516"},"payload_hash":"4ee9776e660cf9fb8a5531084ae910c3e579656ecd2ee65fc171cb620d81f99d","raw_frame":"{\"market\":\"0xda6f0e0e93fc8469e0159a166028d017bddbc162b86f66bac90391379603d962\", \"price_changes\":[{\"asset_id\":\"39272994714739463168905443499424551362424437245880253267329605556587274644733\", \"price\":\"0.68\", \"size\":\"57\", \"side\":\"BUY\", \"hash\":\"f1d858b1e430975abd6a4ff718103f68c1fc051e\", \"best_bid\":\"0.73\", \"best_ask\":\"0.74\"}, {\"asset_id\":\"20893381255801015515826997628594359667013752732428989472914000440642900266717\", \"price\":\"0.32\", \"size\":\"57\", \"side\":\"SELL\", \"hash\":\"1e2fe913cd5cde83039decb7e1ac25afef1a2565\", \"best_bid\":\"0.26\", \"best_ask\":\"0.27\"}], \"timestamp\":\"1785204361516\", \"event_type\":\"price_change\"}","received_at":"2026-07-28T02:06:01.732038Z","schema_version":"clob-market-ws.price_change.v1","sequence":null,"server_hash":null,"server_timestamp":"1785204361516","session_id":"d2757dd6dad94f3b9fe67e8dbf1adc37","source":"clob_market_ws"},"received_at":"2026-07-28T02:06:01.732038Z","record_id":"8967d5888f01f351554bcd33732d3c03cb69fafcd8000017a62af0a9db703848","schema_fingerprint":"4aa3821a28b0b7c2400bc59aba4bcc0a76e971dadd19610d3ad38c768e124dc7","schema_version":"edge-lab-recorder.raw.v1","sequence":null,"source":"clob_market_ws"}
{"event_at":"2026-07-28T02:06:01.516000Z","event_fingerprint":"29dfa76a6e95d7b08a91962a4c4cdf2c7d4f6cf2c85bcb3c9f876e141e840f86","payload":{"connection_id":"5d29200f65794d4d9ab6ef271f045a9b","event_at":"2026-07-28T02:06:01.516000Z","event_type":"price_change","frame_hash":"78ad688025d2e8ddf6d67167536fa8cdca67b5f797801e7c14eb9386754aca57","frame_index":0,"kind":"data","monotonic_ns":306344743298791,"payload":{"event_type":"price_change","market":"0xda6f0e0e93fc8469e0159a166028d017bddbc162b86f66bac90391379603d962","price_changes":[{"asset_id":"20893381255801015515826997628594359667013752732428989472914000440642900266717","best_ask":"0.27","best_bid":"0.26","hash":"d0a438c426d1c01c41e1f26fb16bd0b33c49753f","price":"0.13","side":"BUY","size":"365.5"},{"asset_id":"39272994714739463168905443499424551362424437245880253267329605556587274644733","best_ask":"0.74","best_bid":"0.73","hash":"cafbacd6b2eeb37a67380289dbf08adea725c9ce","price":"0.87","side":"SELL","size":"365.5"}],"timestamp":"1785204361516"},"payload_hash":"a8e8aca3782e65e39fe75ee1bbf196d3ef2dbf47e6b1523facc070a481d54eca","raw_frame":"{\"market\":\"0xda6f0e0e93fc8469e0159a166028d017bddbc162b86f66bac90391379603d962\", \"price_changes\":[{\"asset_id\":\"20893381255801015515826997628594359667013752732428989472914000440642900266717\", \"price\":\"0.13\", \"size\":\"365.5\", \"side\":\"BUY\", \"hash\":\"d0a438c426d1c01c41e1f26fb16bd0b33c49753f\", \"best_bid\":\"0.26\", \"best_ask\":\"0.27\"}, {\"asset_id\":\"39272994714739463168905443499424551362424437245880253267329605556587274644733\", \"price\":\"0.87\", \"size\":\"365.5\", \"side\":\"SELL\", \"hash\":\"cafbacd6b2eeb37a67380289dbf08adea725c9ce\", \"best_bid\":\"0.73\", \"best_ask\":\"0.74\"}], \"timestamp\":\"1785204361516\", \"event_type\":\"price_change\"}","received_at":"2026-07-28T02:06:01.736666Z","schema_version":"clob-market-ws.price_change.v1","sequence":null,"server_hash":null,"server_timestamp":"1785204361516","session_id":"d2757dd6dad94f3b9fe67e8dbf1adc37","source":"clob_market_ws"},"received_at":"2026-07-28T02:06:01.736666Z","record_id":"18d168003256fcd2f4a667d2714b01d966224017fbc12e863d8bcb172694d194","schema_fingerprint":"4aa3821a28b0b7c2400bc59aba4bcc0a76e971dadd19610d3ad38c768e124dc7","schema_version":"edge-lab-recorder.raw.v1","sequence":null,"source":"clob_market_ws"}
{"event_at":"2026-07-28T02:06:01.516000Z","event_fingerprint":"942fd2f8eddfb03dead9acaa9ddd714af84d7caf6b12a50a7e8d02ec2ac1ae48","payload":{"connection_id":"5d29200f65794d4d9ab6ef271f045a9b","event_at":"2026-07-28T02:06:01.516000Z","event_type":"price_change","frame_hash":"ecc3c046a4140eef43fed1b9d0d2ed5001e36cf960d27dc3f8801df0ac7bc7cb","frame_index":0,"kind":"data","monotonic_ns":306344748553333,"payload":{"event_type":"price_change","market":"0xda6f0e0e93fc8469e0159a166028d017bddbc162b86f66bac90391379603d962","price_changes":[{"asset_id":"20893381255801015515826997628594359667013752732428989472914000440642900266717","best_ask":"0.27","best_bid":"0.26","hash":"e55792d01953e6616c303b4fb69152ef8585ff0f","price":"0.22","side":"BUY","size":"84.6"},{"asset_id":"39272994714739463168905443499424551362424437245880253267329605556587274644733","best_ask":"0.74","best_bid":"0.73","hash":"524370cc55b929872bf22ddb5f608a3f84812a5b","price":"0.78","side":"SELL","size":"84.6"}],"timestamp":"1785204361516"},"payload_hash":"f3251ed5241335f17f6b2ba7fd4fb024a24264eaea0df0bae13ee25b2ef4d944","raw_frame":"{\"market\":\"0xda6f0e0e93fc8469e0159a166028d017bddbc162b86f66bac90391379603d962\", \"price_changes\":[{\"asset_id\":\"20893381255801015515826997628594359667013752732428989472914000440642900266717\", \"price\":\"0.22\", \"size\":\"84.6\", \"side\":\"BUY\", \"hash\":\"e55792d01953e6616c303b4fb69152ef8585ff0f\", \"best_bid\":\"0.26\", \"best_ask\":\"0.27\"}, {\"asset_id\":\"39272994714739463168905443499424551362424437245880253267329605556587274644733\", \"price\":\"0.78\", \"size\":\"84.6\", \"side\":\"SELL\", \"hash\":\"524370cc55b929872bf22ddb5f608a3f84812a5b\", \"best_bid\":\"0.73\", \"best_ask\":\"0.74\"}], \"timestamp\":\"1785204361516\", \"event_type\":\"price_change\"}","received_at":"2026-07-28T02:06:01.741921Z","schema_version":"clob-market-ws.price_change.v1","sequence":null,"server_hash":null,"server_timestamp":"1785204361516","session_id":"d2757dd6dad94f3b9fe67e8dbf1adc37","source":"clob_market_ws"},"received_at":"2026-07-28T02:06:01.741921Z","record_id":"a74f56f43a8dc33700f9bc3b066a0a008334efb2a70019688ec89bf500e8579e","schema_fingerprint":"4aa3821a28b0b7c2400bc59aba4bcc0a76e971dadd19610d3ad38c768e124dc7","schema_version":"edge-lab-recorder.raw.v1","sequence":null,"source":"clob_market_ws"}
{"event_at":"2026-07-28T02:06:01.517000Z","event_fingerprint":"e8d6be9a580794d9e62e27541fe9d9eb0c7ee2d546d753385754df1d14bdfaeb","payload":{"connection_id":"5d29200f65794d4d9ab6ef271f045a9b","event_at":"2026-07-28T02:06:01.517000Z","event_type":"price_change","frame_hash":"8a30b79b32951eb3c88bd1845363d9add20ba60558475021dc9347a84b837b90","frame_index":0,"kind":"data","monotonic_ns":306344753006541,"payload":{"event_type":"price_change","market":"0xda6f0e0e93fc8469e0159a166028d017bddbc162b86f66bac90391379603d962","price_changes":[{"asset_id":"39272994714739463168905443499424551362424437245880253267329605556587274644733","best_ask":"0.74","best_bid":"0.73","hash":"4f38b818ba39fefffabe00042e78284c326f2d10","price":"0.66","side":"BUY","size":"92"},{"asset_id":"20893381255801015515826997628594359667013752732428989472914000440642900266717","best_ask":"0.27","best_bid":"0.26","hash":"c3309fe0f4a15ad42c3a58df10574c09886556ef","price":"0.34","side":"SELL","size":"92"}],"timestamp":"1785204361517"},"payload_hash":"6217a26c6e6ee0166a0e7189680c804a0fff8db677fa04c22fa8de23709406f3","raw_frame":"{\"market\":\"0xda6f0e0e93fc8469e0159a166028d017bddbc162b86f66bac90391379603d962\", \"price_changes\":[{\"asset_id\":\"39272994714739463168905443499424551362424437245880253267329605556587274644733\", \"price\":\"0.66\", \"size\":\"92\", \"side\":\"BUY\", \"hash\":\"4f38b818ba39fefffabe00042e78284c326f2d10\", \"best_bid\":\"0.73\", \"best_ask\":\"0.74\"}, {\"asset_id\":\"20893381255801015515826997628594359667013752732428989472914000440642900266717\", \"price\":\"0.34\", \"size\":\"92\", \"side\":\"SELL\", \"hash\":\"c3309fe0f4a15ad42c3a58df10574c09886556ef\", \"best_bid\":\"0.26\", \"best_ask\":\"0.27\"}], \"timestamp\":\"1785204361517\", \"event_type\":\"price_change\"}","received_at":"2026-07-28T02:06:01.746373Z","schema_version":"clob-market-ws.price_change.v1","sequence":null,"server_hash":null,"server_timestamp":"1785204361517","session_id":"d2757dd6dad94f3b9fe67e8dbf1adc37","source":"clob_market_ws"},"received_at":"2026-07-28T02:06:01.746373Z","record_id":"a6acb0b491bc1d4834a1037fc51456fd5f46f65696d5b1e35751110515f55d66","schema_fingerprint":"4aa3821a28b0b7c2400bc59aba4bcc0a76e971dadd19610d3ad38c768e124dc7","schema_version":"edge-lab-recorder.raw.v1","sequence":null,"source":"clob_market_ws"}
{"event_at":"2026-07-28T02:06:01.518000Z","event_fingerprint":"bc848c89dfea04b60ade22520829a8c099877b00766867c37b2e154e14f050c5","payload":{"connection_id":"5d29200f65794d4d9ab6ef271f045a9b","event_at":"2026-07-28T02:06:01.518000Z","event_type":"price_change","frame_hash":"b6a2dabffc9fe9f9973f126b8276d338f20893d377d3040a0a57f5fdbff52743","frame_index":0,"kind":"data","monotonic_ns":306344756661208,"payload":{"event_type":"price_change","market":"0xda6f0e0e93fc8469e0159a166028d017bddbc162b86f66bac90391379603d962","price_changes":[{"asset_id":"20893381255801015515826997628594359667013752732428989472914000440642900266717","best_ask":"0.27","best_bid":"0.26","hash":"41bf7fa91dcd2c68e155adef67af882bd1df63d8","price":"0.22","side":"BUY","size":"90.6"},{"asset_id":"39272994714739463168905443499424551362424437245880253267329605556587274644733","best_ask":"0.74","best_bid":"0.73","hash":"38db4045d4124390ce7c1c566f1116c4adf005d9","price":"0.78","side":"SELL","size":"90.6"}],"timestamp":"1785204361518"},"payload_hash":"2899621aa663a45c1d51cec9686eb4614f796119aa56dec38af7f743596b9eb7","raw_frame":"{\"market\":\"0xda6f0e0e93fc8469e0159a166028d017bddbc162b86f66bac90391379603d962\", \"price_changes\":[{\"asset_id\":\"20893381255801015515826997628594359667013752732428989472914000440642900266717\", \"price\":\"0.22\", \"size\":\"90.6\", \"side\":\"BUY\", \"hash\":\"41bf7fa91dcd2c68e155adef67af882bd1df63d8\", \"best_bid\":\"0.26\", \"best_ask\":\"0.27\"}, {\"asset_id\":\"39272994714739463168905443499424551362424437245880253267329605556587274644733\", \"price\":\"0.78\", \"size\":\"90.6\", \"side\":\"SELL\", \"hash\":\"38db4045d4124390ce7c1c566f1116c4adf005d9\", \"best_bid\":\"0.73\", \"best_ask\":\"0.74\"}], \"timestamp\":\"1785204361518\", \"event_type\":\"price_change\"}","received_at":"2026-07-28T02:06:01.750028Z","schema_version":"clob-market-ws.price_change.v1","sequence":null,"server_hash":null,"server_timestamp":"1785204361518","session_id":"d2757dd6dad94f3b9fe67e8dbf1adc37","source":"clob_market_ws"},"received_at":"2026-07-28T02:06:01.750028Z","record_id":"6b867498da672c2fa09d50814c4acc3a8ca8fe7bdb1a32ba7cd163354e992cf5","schema_fingerprint":"4aa3821a28b0b7c2400bc59aba4bcc0a76e971dadd19610d3ad38c768e124dc7","schema_version":"edge-lab-recorder.raw.v1","sequence":null,"source":"clob_market_ws"}
{"event_at":"2026-07-28T02:06:01.519000Z","event_fingerprint":"a81616615b619c4c4d751eee5a050e9c00e2a84f766aa528d5bfe8cf71c89a50","payload":{"connection_id":"5d29200f65794d4d9ab6ef271f045a9b","event_at":"2026-07-28T02:06:01.519000Z","event_type":"price_change","frame_hash":"84b7aea8305e2738a5b0352deaccb11bb673f161e310a9afe5bfa2a92dc267bc","frame_index":0,"kind":"data","monotonic_ns":306344759738666,"payload":{"event_type":"price_change","market":"0xda6f0e0e93fc8469e0159a166028d017bddbc162b86f66bac90391379603d962","price_changes":[{"asset_id":"39272994714739463168905443499424551362424437245880253267329605556587274644733","best_ask":"0.74","best_bid":"0.73","hash":"92754efe3f1d7bf48d5bc4f3c6afc0acdcb3ce0d","price":"0.6","side":"BUY","size":"98"},{"asset_id":"20893381255801015515826997628594359667013752732428989472914000440642900266717","best_ask":"0.27","best_bid":"0.26","hash":"1c5c12779f6b8d3a1a545c9355cd73fa721971e3","price":"0.4","side":"SELL","size":"98"}],"timestamp":"1785204361519"},"payload_hash":"6f9a84fba6a92f45c9787e0f7f40390674ba5b25fae9f868e9f542204f0279a2","raw_frame":"{\"market\":\"0xda6f0e0e93fc8469e0159a166028d017bddbc162b86f66bac90391379603d962\", \"price_changes\":[{\"asset_id\":\"39272994714739463168905443499424551362424437245880253267329605556587274644733\", \"price\":\"0.6\", \"size\":\"98\", \"side\":\"BUY\", \"hash\":\"92754efe3f1d7bf48d5bc4f3c6afc0acdcb3ce0d\", \"best_bid\":\"0.73\", \"best_ask\":\"0.74\"}, {\"asset_id\":\"20893381255801015515826997628594359667013752732428989472914000440642900266717\", \"price\":\"0.4\", \"size\":\"98\", \"side\":\"SELL\", \"hash\":\"1c5c12779f6b8d3a1a545c9355cd73fa721971e3\", \"best_bid\":\"0.26\", \"best_ask\":\"0.27\"}], \"timestamp\":\"1785204361519\", \"event_type\":\"price_change\"}","received_at":"2026-07-28T02:06:01.753106Z","schema_version":"clob-market-ws.price_change.v1","sequence":null,"server_hash":null,"server_timestamp":"1785204361519","session_id":"d2757dd6dad94f3b9fe67e8dbf1adc37","source":"clob_market_ws"},"received_at":"2026-07-28T02:06:01.753106Z","record_id":"04886d8ad0a7a51a7716fe48bf83b726e762daee82cc8e4ed837b6b4d75056d6","schema_fingerprint":"4aa3821a28b0b7c2400bc59aba4bcc0a76e971dadd19610d3ad38c768e124dc7","schema_version":"edge-lab-recorder.raw.v1","sequence":null,"source":"clob_market_ws"}
{"event_at":"2026-07-28T02:06:01.521000Z","event_fingerprint":"e693d40b0c38841264fcc21b5c584e1c1db56b05149ee4d1a54e78f7ebc1f800","payload":{"connection_id":"5d29200f65794d4d9ab6ef271f045a9b","event_at":"2026-07-28T02:06:01.521000Z","event_type":"price_change","frame_hash":"e91a588a00c767546af31163355957e1311577d3e1d9368fa2edacaa8c13bd39","frame_index":0,"kind":"data","monotonic_ns":306344765626250,"payload":{"event_type":"price_change","market":"0xda6f0e0e93fc8469e0159a166028d017bddbc162b86f66bac90391379603d962","price_changes":[{"asset_id":"20893381255801015515826997628594359667013752732428989472914000440642900266717","best_ask":"0.27","best_bid":"0.26","hash":"2fee1d6ab05d0bcf3a8369b6b9515b9b4f3e3a83","price":"0.16","side":"BUY","size":"349.3"},{"asset_id":"39272994714739463168905443499424551362424437245880253267329605556587274644733","best_ask":"0.74","best_bid":"0.73","hash":"658e9f5bce122d30966181903268654493ac102d","price":"0.84","side":"SELL","size":"349.3"}],"timestamp":"1785204361521"},"payload_hash":"5f8a1389d77ac56a46cd91f4dd788b8a8f6df6be4bd1891560fb75c10222583b","raw_frame":"{\"market\":\"0xda6f0e0e93fc8469e0159a166028d017bddbc162b86f66bac90391379603d962\", \"price_changes\":[{\"asset_id\":\"20893381255801015515826997628594359667013752732428989472914000440642900266717\", \"price\":\"0.16\", \"size\":\"349.3\", \"side\":\"BUY\", \"hash\":\"2fee1d6ab05d0bcf3a8369b6b9515b9b4f3e3a83\", \"best_bid\":\"0.26\", \"best_ask\":\"0.27\"}, {\"asset_id\":\"39272994714739463168905443499424551362424437245880253267329605556587274644733\", \"price\":\"0.84\", \"size\":\"349.3\", \"side\":\"SELL\", \"hash\":\"658e9f5bce122d30966181903268654493ac102d\", \"best_bid\":\"0.73\", \"best_ask\":\"0.74\"}], \"timestamp\":\"1785204361521\", \"event_type\":\"price_change\"}","received_at":"2026-07-28T02:06:01.758991Z","schema_version":"clob-market-ws.price_change.v1","sequence":null,"server_hash":null,"server_timestamp":"1785204361521","session_id":"d2757dd6dad94f3b9fe67e8dbf1adc37","source":"clob_market_ws"},"received_at":"2026-07-28T02:06:01.758991Z","record_id":"4aa52134945dba0ca3eceb13edc6fc22b6dbe98ce98bb55906c5c369662a986f","schema_fingerprint":"4aa3821a28b0b7c2400bc59aba4bcc0a76e971dadd19610d3ad38c768e124dc7","schema_version":"edge-lab-recorder.raw.v1","sequence":null,"source":"clob_market_ws"}
{"event_at":"2026-07-28T02:06:01.522000Z","event_fingerprint":"750268f6a01c8eec16a9a888d97041c166a5c2e0fdbec7acd5cbbe48b9ed9a9d","payload":{"connection_id":"5d29200f65794d4d9ab6ef271f045a9b","event_at":"2026-07-28T02:06:01.522000Z","event_type":"price_change","frame_hash":"f946c4d83b4915c7cb3ff0cdc02dd6fce53409ec01d54429b1b0452c74c74ceb","frame_index":0,"kind":"data","monotonic_ns":306344769454166,"payload":{"event_type":"price_change","market":"0xda6f0e0e93fc8469e0159a166028d017bddbc162b86f66bac90391379603d962","price_changes":[{"asset_id":"39272994714739463168905443499424551362424437245880253267329605556587274644733","best_ask":"0.74","best_bid":"0.73","hash":"23c51781d87c520d8b077fbe745232aa15d5f652","price":"0.71","side":"BUY","size":"113.2"},{"asset_id":"20893381255801015515826997628594359667013752732428989472914000440642900266717","best_ask":"0.27","best_bid":"0.26","hash":"ae1c321f81f3cf93ffc511b7819ad77856590720","price":"0.29","side":"SELL","size":"113.2"}],"timestamp":"1785204361522"},"payload_hash":"d65cf33d787c9df4f0ae3f3f6c91ccbc566a4b92ea5857e144224871c4930d50","raw_frame":"{\"market\":\"0xda6f0e0e93fc8469e0159a166028d017bddbc162b86f66bac90391379603d962\", \"price_changes\":[{\"asset_id\":\"39272994714739463168905443499424551362424437245880253267329605556587274644733\", \"price\":\"0.71\", \"size\":\"113.2\", \"side\":\"BUY\", \"hash\":\"23c51781d87c520d8b077fbe745232aa15d5f652\", \"best_bid\":\"0.73\", \"best_ask\":\"0.74\"}, {\"asset_id\":\"20893381255801015515826997628594359667013752732428989472914000440642900266717\", \"price\":\"0.29\", \"size\":\"113.2\", \"side\":\"SELL\", \"hash\":\"ae1c321f81f3cf93ffc511b7819ad77856590720\", \"best_bid\":\"0.26\", \"best_ask\":\"0.27\"}], \"timestamp\":\"1785204361522\", \"event_type\":\"price_change\"}","received_at":"2026-07-28T02:06:01.762822Z","schema_version":"clob-market-ws.price_change.v1","sequence":null,"server_hash":null,"server_timestamp":"1785204361522","session_id":"d2757dd6dad94f3b9fe67e8dbf1adc37","source":"clob_market_ws"},"received_at":"2026-07-28T02:06:01.762822Z","record_id":"0c54298f07cbf9c5e452d036ad35351ca0cf69cf1595e8a976d5f03be067b2b9","schema_fingerprint":"4aa3821a28b0b7c2400bc59aba4bcc0a76e971dadd19610d3ad38c768e124dc7","schema_version":"edge-lab-recorder.raw.v1","sequence":null,"source":"clob_market_ws"}
{"event_at":"2026-07-28T02:06:01.522000Z","event_fingerprint":"0bbe8de56ecf21bb29f244c05c986b4e9041921800d927649d62268e4aed9e03","payload":{"connection_id":"5d29200f65794d4d9ab6ef271f045a9b","event_at":"2026-07-28T02:06:01.522000Z","event_type":"price_change","frame_hash":"efae48292cffe54ee8cd4fb1f207ca5e5aa69f1adac75b9365c30bcb63d8982a","frame_index":0,"kind":"data","monotonic_ns":306344774419791,"payload":{"event_type":"price_change","market":"0xda6f0e0e93fc8469e0159a166028d017bddbc162b86f66bac90391379603d962","price_changes":[{"asset_id":"39272994714739463168905443499424551362424437245880253267329605556587274644733","best_ask":"0.74","best_bid":"0.73","hash":"23c51781d87c520d8b077fbe745232aa15d5f652","price":"0.72","side":"BUY","size":"100.2"},{"asset_id":"20893381255801015515826997628594359667013752732428989472914000440642900266717","best_ask":"0.27","best_bid":"0.26","hash":"ae1c321f81f3cf93ffc511b7819ad77856590720","price":"0.28","side":"SELL","size":"100.2"}],"timestamp":"1785204361522"},"payload_hash":"29caff4252dc7f44a11bd5bbcc88522c081d0595d22c94b7f63cfc9b7f5cd60a","raw_frame":"{\"market\":\"0xda6f0e0e93fc8469e0159a166028d017bddbc162b86f66bac90391379603d962\", \"price_changes\":[{\"asset_id\":\"39272994714739463168905443499424551362424437245880253267329605556587274644733\", \"price\":\"0.72\", \"size\":\"100.2\", \"side\":\"BUY\", \"hash\":\"23c51781d87c520d8b077fbe745232aa15d5f652\", \"best_bid\":\"0.73\", \"best_ask\":\"0.74\"}, {\"asset_id\":\"20893381255801015515826997628594359667013752732428989472914000440642900266717\", \"price\":\"0.28\", \"size\":\"100.2\", \"side\":\"SELL\", \"hash\":\"ae1c321f81f3cf93ffc511b7819ad77856590720\", \"best_bid\":\"0.26\", \"best_ask\":\"0.27\"}], \"timestamp\":\"1785204361522\", \"event_type\":\"price_change\"}","received_at":"2026-07-28T02:06:01.767787Z","schema_version":"clob-market-ws.price_change.v1","sequence":null,"server_hash":null,"server_timestamp":"1785204361522","session_id":"d2757dd6dad94f3b9fe67e8dbf1adc37","source":"clob_market_ws"},"received_at":"2026-07-28T02:06:01.767787Z","record_id":"518bdfd836703bc73e78e7124da745806b159eef2517172ad07623e4a5190f96","schema_fingerprint":"4aa3821a28b0b7c2400bc59aba4bcc0a76e971dadd19610d3ad38c768e124dc7","schema_version":"edge-lab-recorder.raw.v1","sequence":null,"source":"clob_market_ws"}
{"event_at":"2026-07-28T02:06:01.525000Z","event_fingerprint":"00c9070b9cf2436247d119d580e39ed893e3eac1e8a2a295d6fcb468e24aad6b","payload":{"connection_id":"5d29200f65794d4d9ab6ef271f045a9b","event_at":"2026-07-28T02:06:01.525000Z","event_type":"price_change","frame_hash":"71aa877248dc04f2cf2c52eb2e008ce9890bdf4f5cea7f884396ca6e031373ac","frame_index":0,"kind":"data","monotonic_ns":306344777851125,"payload":{"event_type":"price_change","market":"0xda6f0e0e93fc8469e0159a166028d017bddbc162b86f66bac90391379603d962","price_changes":[{"asset_id":"20893381255801015515826997628594359667013752732428989472914000440642900266717","best_ask":"0.27","best_bid":"0.26","hash":"8074d84d78bc1bcb605d54f22ad0752ba306808a","price":"0.13","side":"BUY","size":"373"},{"asset_id":"39272994714739463168905443499424551362424437245880253267329605556587274644733","best_ask":"0.74","best_bid":"0.73","hash":"a5744d7cb7723e11e78d2b326931adfa4e8a058a","price":"0.87","side":"SELL","size":"373"}],"timestamp":"1785204361525"},"payload_hash":"f016a56a47ae1198af6b71b6650fa67c6a1caa1b1e2479b96625e2c1e860c715","raw_frame":"{\"market\":\"0xda6f0e0e93fc8469e0159a166028d017bddbc162b86f66bac90391379603d962\", \"price_changes\":[{\"asset_id\":\"20893381255801015515826997628594359667013752732428989472914000440642900266717\", \"price\":\"0.13\", \"size\":\"373\", \"side\":\"BUY\", \"hash\":\"8074d84d78bc1bcb605d54f22ad0752ba306808a\", \"best_bid\":\"0.26\", \"best_ask\":\"0.27\"}, {\"asset_id\":\"39272994714739463168905443499424551362424437245880253267329605556587274644733\", \"price\":\"0.87\", \"size\":\"373\", \"side\":\"SELL\", \"hash\":\"a5744d7cb7723e11e78d2b326931adfa4e8a058a\", \"best_bid\":\"0.73\", \"best_ask\":\"0.74\"}], \"timestamp\":\"1785204361525\", \"event_type\":\"price_change\"}","received_at":"2026-07-28T02:06:01.771219Z","schema_version":"clob-market-ws.price_change.v1","sequence":null,"server_hash":null,"server_timestamp":"1785204361525","session_id":"d2757dd6dad94f3b9fe67e8dbf1adc37","source":"clob_market_ws"},"received_at":"2026-07-28T02:06:01.771219Z","record_id":"b751d245d0c2a84e067a851b4ccea1d8c84b267edfeeb90c3075b3ae6a2a905b","schema_fingerprint":"4aa3821a28b0b7c2400bc59aba4bcc0a76e971dadd19610d3ad38c768e124dc7","schema_version":"edge-lab-recorder.raw.v1","sequence":null,"source":"clob_market_ws"}
{"event_at":"2026-07-28T02:06:01.532000Z","event_fingerprint":"f9415a045de296881be9cd995c7d76d5c2cdfd4a56d1dbf84d70f0a8accb5dc7","payload":{"connection_id":"5d29200f65794d4d9ab6ef271f045a9b","event_at":"2026-07-28T02:06:01.532000Z","event_type":"price_change","frame_hash":"bf28f8da31e3bfd1215089d7f6007083251e1c31a2167a63ab7208cd034dfafa","frame_index":0,"kind":"data","monotonic_ns":306344781874166,"payload":{"event_type":"price_change","market":"0xda6f0e0e93fc8469e0159a166028d017bddbc162b86f66bac90391379603d962","price_changes":[{"asset_id":"39272994714739463168905443499424551362424437245880253267329605556587274644733","best_ask":"0.74","best_bid":"0.73","hash":"6a771a711b65269a64aab7ce7ba5dce3aab37e56","price":"0.67","side":"BUY","size":"66"},{"asset_id":"20893381255801015515826997628594359667013752732428989472914000440642900266717","best_ask":"0.27","best_bid":"0.26","hash":"2f92589e51ce02376e3634ae12988daeafd582dd","price":"0.33","side":"SELL","size":"66"}],"timestamp":"1785204361532"},"payload_hash":"e00b9433badc496b2bbc6040d635f50e5ef7b2c3e64aaaae152f6e734d6dc699","raw_frame":"{\"market\":\"0xda6f0e0e93fc8469e0159a166028d017bddbc162b86f66bac90391379603d962\", \"price_changes\":[{\"asset_id\":\"39272994714739463168905443499424551362424437245880253267329605556587274644733\", \"price\":\"0.67\", \"size\":\"66\", \"side\":\"BUY\", \"hash\":\"6a771a711b65269a64aab7ce7ba5dce3aab37e56\", \"best_bid\":\"0.73\", \"best_ask\":\"0.74\"}, {\"asset_id\":\"20893381255801015515826997628594359667013752732428989472914000440642900266717\", \"price\":\"0.33\", \"size\":\"66\", \"side\":\"SELL\", \"hash\":\"2f92589e51ce02376e3634ae12988daeafd582dd\", \"best_bid\":\"0.26\", \"best_ask\":\"0.27\"}], \"timestamp\":\"1785204361532\", \"event_type\":\"price_change\"}","received_at":"2026-07-28T02:06:01.775241Z","schema_version":"clob-market-ws.price_change.v1","sequence":null,"server_hash":null,"server_timestamp":"1785204361532","session_id":"d2757dd6dad94f3b9fe67e8dbf1adc37","source":"clob_market_ws"},"received_at":"2026-07-28T02:06:01.775241Z","record_id":"bc5708107d043a3e24ea764859767849ac6b1d2b41b232c3bc6ceb7b154532e3","schema_fingerprint":"4aa3821a28b0b7c2400bc59aba4bcc0a76e971dadd19610d3ad38c768e124dc7","schema_version":"edge-lab-recorder.raw.v1","sequence":null,"source":"clob_market_ws"}
{"event_at":"2026-07-28T02:06:01.533000Z","event_fingerprint":"bd63e5244f9eb0dc2cbc0a8118298f1ad989b7b6f8065cd17bec462ed1323fb4","payload":{"connection_id":"5d29200f65794d4d9ab6ef271f045a9b","event_at":"2026-07-28T02:06:01.533000Z","event_type":"price_change","frame_hash":"4ec51bf0eaa4d2712f5afd3ffe22b8092df15249b9685543765dbd5f0ee47055","frame_index":0,"kind":"data","monotonic_ns":306344784982458,"payload":{"event_type":"price_change","market":"0xda6f0e0e93fc8469e0159a166028d017bddbc162b86f66bac90391379603d962","price_changes":[{"asset_id":"20893381255801015515826997628594359667013752732428989472914000440642900266717","best_ask":"0.27","best_bid":"0.26","hash":"71817cf7ad330e56a4962f189de59e01c9de48b4","price":"0.25","side":"BUY","size":"106.6"},{"asset_id":"39272994714739463168905443499424551362424437245880253267329605556587274644733","best_ask":"0.74","best_bid":"0.73","hash":"cd3107bb34ad1cfd61c16dea95d49f2e072cb631","price":"0.75","side":"SELL","size":"106.6"}],"timestamp":"1785204361533"},"payload_hash":"2a67ab6c1f614d905eca7504e18445b8fbf9f319552dfc7a6b52d6a66a8b3e12","raw_frame":"{\"market\":\"0xda6f0e0e93fc8469e0159a166028d017bddbc162b86f66bac90391379603d962\", \"price_changes\":[{\"asset_id\":\"20893381255801015515826997628594359667013752732428989472914000440642900266717\", \"price\":\"0.25\", \"size\":\"106.6\", \"side\":\"BUY\", \"hash\":\"71817cf7ad330e56a4962f189de59e01c9de48b4\", \"best_bid\":\"0.26\", \"best_ask\":\"0.27\"}, {\"asset_id\":\"39272994714739463168905443499424551362424437245880253267329605556587274644733\", \"price\":\"0.75\", \"size\":\"106.6\", \"side\":\"SELL\", \"hash\":\"cd3107bb34ad1cfd61c16dea95d49f2e072cb631\", \"best_bid\":\"0.73\", \"best_ask\":\"0.74\"}], \"timestamp\":\"1785204361533\", \"event_type\":\"price_change\"}","received_at":"2026-07-28T02:06:01.778349Z","schema_version":"clob-market-ws.price_change.v1","sequence":null,"server_hash":null,"server_timestamp":"1785204361533","session_id":"d2757dd6dad94f3b9fe67e8dbf1adc37","source":"clob_market_ws"},"received_at":"2026-07-28T02:06:01.778349Z","record_id":"936e3d2e99f603e0101abdad32fefe6f66a6f6598949e5b8f57cf83ca475424d","schema_fingerprint":"4aa3821a28b0b7c2400bc59aba4bcc0a76e971dadd19610d3ad38c768e124dc7","schema_version":"edge-lab-recorder.raw.v1","sequence":null,"source":"clob_market_ws"}
{"event_at":"2026-07-28T02:06:01.534000Z","event_fingerprint":"0cf0aa3870216b6fdffdf53f5e08d3db9b4b7da94377b94355180bda274b307d","payload":{"connection_id":"5d29200f65794d4d9ab6ef271f045a9b","event_at":"2026-07-28T02:06:01.534000Z","event_type":"price_change","frame_hash":"4cb0962f72ceb5321cb73bfc58d72856ba130233b35da09f1a5f0a6f9c842b3f","frame_index":0,"kind":"data","monotonic_ns":306344790410833,"payload":{"event_type":"price_change","market":"0xda6f0e0e93fc8469e0159a166028d017bddbc162b86f66bac90391379603d962","price_changes":[{"asset_id":"20893381255801015515826997628594359667013752732428989472914000440642900266717","best_ask":"0.27","best_bid":"0.26","hash":"9b156b3f78002366dcd57eadceb6a6bb909b98a9","price":"0.25","side":"BUY","size":"119.2"},{"asset_id":"39272994714739463168905443499424551362424437245880253267329605556587274644733","best_ask":"0.74","best_bid":"0.73","hash":"51399c8906e1978eaa477761cc45b07e50357840","price":"0.75","side":"SELL","size":"119.2"}],"timestamp":"1785204361534"},"payload_hash":"9c0b9e373b7a34c2e8b40a9fed0a20b2a506a8d198878ce90b457cbb74104c5d","raw_frame":"{\"market\":\"0xda6f0e0e93fc8469e0159a166028d017bddbc162b86f66bac90391379603d962\", \"price_changes\":[{\"asset_id\":\"20893381255801015515826997628594359667013752732428989472914000440642900266717\", \"price\":\"0.25\", \"size\":\"119.2\", \"side\":\"BUY\", \"hash\":\"9b156b3f78002366dcd57eadceb6a6bb909b98a9\", \"best_bid\":\"0.26\", \"best_ask\":\"0.27\"}, {\"asset_id\":\"39272994714739463168905443499424551362424437245880253267329605556587274644733\", \"price\":\"0.75\", \"size\":\"119.2\", \"side\":\"SELL\", \"hash\":\"51399c8906e1978eaa477761cc45b07e50357840\", \"best_bid\":\"0.73\", \"best_ask\":\"0.74\"}], \"timestamp\":\"1785204361534\", \"event_type\":\"price_change\"}","received_at":"2026-07-28T02:06:01.783778Z","schema_version":"clob-market-ws.price_change.v1","sequence":null,"server_hash":null,"server_timestamp":"1785204361534","session_id":"d2757dd6dad94f3b9fe67e8dbf1adc37","source":"clob_market_ws"},"received_at":"2026-07-28T02:06:01.783778Z","record_id":"f117d7a270b395c27318f51b66e0e45d0d3d5701c72055af713010662389b0fb","schema_fingerprint":"4aa3821a28b0b7c2400bc59aba4bcc0a76e971dadd19610d3ad38c768e124dc7","schema_version":"edge-lab-recorder.raw.v1","sequence":null,"source":"clob_market_ws"}
{"event_at":"2026-07-28T02:06:01.538000Z","event_fingerprint":"bac0e7e05f0f392a88c11f8e54cf027d1e6e89f94c6b1d8fa6bfe46b78588a74","payload":{"connection_id":"5d29200f65794d4d9ab6ef271f045a9b","event_at":"2026-07-28T02:06:01.538000Z","event_type":"price_change","frame_hash":"ac175f4c27a363a2c98fda5f31f19fd3ba77582e66dbff7b2c6a062b9dddbd2b","frame_index":0,"kind":"data","monotonic_ns":306344801087916,"payload":{"event_type":"price_change","market":"0xda6f0e0e93fc8469e0159a166028d017bddbc162b86f66bac90391379603d962","price_changes":[{"asset_id":"39272994714739463168905443499424551362424437245880253267329605556587274644733","best_ask":"0.74","best_bid":"0.73","hash":"229b5865cf25afbc3cd9a8e5c9071936ca262758","price":"0.6","side":"BUY","size":"110.5"},{"asset_id":"20893381255801015515826997628594359667013752732428989472914000440642900266717","best_ask":"0.27","best_bid":"0.26","hash":"89a81dbbc7c96645ce3468530be6a137dd770293","price":"0.4","side":"SELL","size":"110.5"}],"timestamp":"1785204361538"},"payload_hash":"1796c0ed031e2940e83930459881cab7bb3194ac8dacf07cc4d5fad7107548d1","raw_frame":"{\"market\":\"0xda6f0e0e93fc8469e0159a166028d017bddbc162b86f66bac90391379603d962\", \"price_changes\":[{\"asset_id\":\"39272994714739463168905443499424551362424437245880253267329605556587274644733\", \"price\":\"0.6\", \"size\":\"110.5\", \"side\":\"BUY\", \"hash\":\"229b5865cf25afbc3cd9a8e5c9071936ca262758\", \"best_bid\":\"0.73\", \"best_ask\":\"0.74\"}, {\"asset_id\":\"20893381255801015515826997628594359667013752732428989472914000440642900266717\", \"price\":\"0.4\", \"size\":\"110.5\", \"side\":\"SELL\", \"hash\":\"89a81dbbc7c96645ce3468530be6a137dd770293\", \"best_bid\":\"0.26\", \"best_ask\":\"0.27\"}], \"timestamp\":\"1785204361538\", \"event_type\":\"price_change\"}","received_at":"2026-07-28T02:06:01.794455Z","schema_version":"clob-market-ws.price_change.v1","sequence":null,"server_hash":null,"server_timestamp":"1785204361538","session_id":"d2757dd6dad94f3b9fe67e8dbf1adc37","source":"clob_market_ws"},"received_at":"2026-07-28T02:06:01.794455Z","record_id":"faf7c2eac37be866ed1c6717d5c9e81e1856c817a386b1521aadb8f37503001a","schema_fingerprint":"4aa3821a28b0b7c2400bc59aba4bcc0a76e971dadd19610d3ad38c768e124dc7","schema_version":"edge-lab-recorder.raw.v1","sequence":null,"source":"clob_market_ws"}
{"event_at":"2026-07-28T02:06:01.542000Z","event_fingerprint":"c9004b5c4328f0d9fa7209f394eb26f0d2f1e189103790535c46902fad9b4f9a","payload":{"connection_id":"5d29200f65794d4d9ab6ef271f045a9b","event_at":"2026-07-28T02:06:01.542000Z","event_type":"price_change","frame_hash":"d10c7eedb9c9b0e123aefe630631a5de37b07dba2fc9d70153fa310abfac7612","frame_index":0,"kind":"data","monotonic_ns":306344808235000,"payload":{"event_type":"price_change","market":"0xda6f0e0e93fc8469e0159a166028d017bddbc162b86f66bac90391379603d962","price_changes":[{"asset_id":"20893381255801015515826997628594359667013752732428989472914000440642900266717","best_ask":"0.27","best_bid":"0.26","hash":"11f455e298d37eea58acefbc5f5a92119b9a0c17","price":"0.26","side":"BUY","size":"32.6"},{"asset_id":"39272994714739463168905443499424551362424437245880253267329605556587274644733","best_ask":"0.74","best_bid":"0.73","hash":"f3ec50844776df804a795b8d2b82a48c208d1371","price":"0.74","side":"SELL","size":"32.6"}],"timestamp":"1785204361542"},"payload_hash":"1fe888111a9a8646ef41bbd6f02bd4742d5288e432187f0c01ca5d2e5cb469a4","raw_frame":"{\"market\":\"0xda6f0e0e93fc8469e0159a166028d017bddbc162b86f66bac90391379603d962\", \"price_changes\":[{\"asset_id\":\"20893381255801015515826997628594359667013752732428989472914000440642900266717\", \"price\":\"0.26\", \"size\":\"32.6\", \"side\":\"BUY\", \"hash\":\"11f455e298d37eea58acefbc5f5a92119b9a0c17\", \"best_bid\":\"0.26\", \"best_ask\":\"0.27\"}, {\"asset_id\":\"39272994714739463168905443499424551362424437245880253267329605556587274644733\", \"price\":\"0.74\", \"size\":\"32.6\", \"side\":\"SELL\", \"hash\":\"f3ec50844776df804a795b8d2b82a48c208d1371\", \"best_bid\":\"0.73\", \"best_ask\":\"0.74\"}], \"timestamp\":\"1785204361542\", \"event_type\":\"price_change\"}","received_at":"2026-07-28T02:06:01.801600Z","schema_version":"clob-market-ws.price_change.v1","sequence":null,"server_hash":null,"server_timestamp":"1785204361542","session_id":"d2757dd6dad94f3b9fe67e8dbf1adc37","source":"clob_market_ws"},"received_at":"2026-07-28T02:06:01.801600Z","record_id":"1571f81969ca2f511c5290335da0d0b796b432630bb24dc59676a4f2a2d55a33","schema_fingerprint":"4aa3821a28b0b7c2400bc59aba4bcc0a76e971dadd19610d3ad38c768e124dc7","schema_version":"edge-lab-recorder.raw.v1","sequence":null,"source":"clob_market_ws"}
{"event_at":"2026-07-28T02:06:01.543000Z","event_fingerprint":"0816d53bf386e28dcadab6f9a4910940d21bef5e5fa0a7e9dd93b7f6a6cb138a","payload":{"connection_id":"5d29200f65794d4d9ab6ef271f045a9b","event_at":"2026-07-28T02:06:01.543000Z","event_type":"price_change","frame_hash":"5364a9cffdbaf06c8528535f3c0ad627f6cacdc816d011e966444377e8220c1d","frame_index":0,"kind":"data","monotonic_ns":306344818996333,"payload":{"event_type":"price_change","market":"0xda6f0e0e93fc8469e0159a166028d017bddbc162b86f66bac90391379603d962","price_changes":[{"asset_id":"39272994714739463168905443499424551362424437245880253267329605556587274644733","best_ask":"0.74","best_bid":"0.73","hash":"b1399d98cdf9642ff08323c181aab45875ba82cc","price":"0.66","side":"BUY","size":"132"},{"asset_id":"20893381255801015515826997628594359667013752732428989472914000440642900266717","best_ask":"0.27","best_bid":"0.26","hash":"032f79705442ed0afcad7ef4e6ebe182038da9bb","price":"0.34","side":"SELL","size":"132"}],"timestamp":"1785204361543"},"payload_hash":"9b085c720451dbcbe037186c6945adfc1e3524d811d73cf0594161ad27d59177","raw_frame":"{\"market\":\"0xda6f0e0e93fc8469e0159a166028d017bddbc162b86f66bac90391379603d962\", \"price_changes\":[{\"asset_id\":\"39272994714739463168905443499424551362424437245880253267329605556587274644733\", \"price\":\"0.66\", \"size\":\"132\", \"side\":\"BUY\", \"hash\":\"b1399d98cdf9642ff08323c181aab45875ba82cc\", \"best_bid\":\"0.73\", \"best_ask\":\"0.74\"}, {\"asset_id\":\"20893381255801015515826997628594359667013752732428989472914000440642900266717\", \"price\":\"0.34\", \"size\":\"132\", \"side\":\"SELL\", \"hash\":\"032f79705442ed0afcad7ef4e6ebe182038da9bb\", \"best_bid\":\"0.26\", \"best_ask\":\"0.27\"}], \"timestamp\":\"1785204361543\", \"event_type\":\"price_change\"}","received_at":"2026-07-28T02:06:01.812364Z","schema_version":"clob-market-ws.price_change.v1","sequence":null,"server_hash":null,"server_timestamp":"1785204361543","session_id":"d2757dd6dad94f3b9fe67e8dbf1adc37","source":"clob_market_ws"},"received_at":"2026-07-28T02:06:01.812364Z","record_id":"03fd098f80d42a2d129dd5e4771face6cea3b871e16846708b5f62ef20830287","schema_fingerprint":"4aa3821a28b0b7c2400bc59aba4bcc0a76e971dadd19610d3ad38c768e124dc7","schema_version":"edge-lab-recorder.raw.v1","sequence":null,"source":"clob_market_ws"}
{"event_at":"2026-07-28T02:06:01.543000Z","event_fingerprint":"733d4659660ed4e33ecfcbee8a8d411c6e1a6a6617d0513da4558b37034c391a","payload":{"connection_id":"5d29200f65794d4d9ab6ef271f045a9b","event_at":"2026-07-28T02:06:01.543000Z","event_type":"price_change","frame_hash":"d00db7dbc6235abf16551f9a516669f4f9d6ec070ecfa953948efcd6af5b3936","frame_index":0,"kind":"data","monotonic_ns":306344825923041,"payload":{"event_type":"price_change","market":"0xda6f0e0e93fc8469e0159a166028d017bddbc162b86f66bac90391379603d962","price_changes":[{"asset_id":"20893381255801015515826997628594359667013752732428989472914000440642900266717","best_ask":"0.27","best_bid":"0.26","hash":"eef7bda08d2015d3705b2b315be349fc153b88b1","price":"0.26","side":"BUY","size":"61.6"},{"asset_id":"39272994714739463168905443499424551362424437245880253267329605556587274644733","best_ask":"0.74","best_bid":"0.73","hash":"ce55c687eeb2daa7b27e33c8e22f2d8e0d9cd4f0","price":"0.74","side":"SELL","size":"61.6"}],"timestamp":"1785204361543"},"payload_hash":"36b47f06141ef5946fb378d0889cec2375c7b2c83a4bdfc8f73a5301a0d2bd83","raw_frame":"{\"market\":\"0xda6f0e0e93fc8469e0159a166028d017bddbc162b86f66bac90391379603d962\", \"price_changes\":[{\"asset_id\":\"20893381255801015515826997628594359667013752732428989472914000440642900266717\", \"price\":\"0.26\", \"size\":\"61.6\", \"side\":\"BUY\", \"hash\":\"eef7bda08d2015d3705b2b315be349fc153b88b1\", \"best_bid\":\"0.26\", \"best_ask\":\"0.27\"}, {\"asset_id\":\"39272994714739463168905443499424551362424437245880253267329605556587274644733\", \"price\":\"0.74\", \"size\":\"61.6\", \"side\":\"SELL\", \"hash\":\"ce55c687eeb2daa7b27e33c8e22f2d8e0d9cd4f0\", \"best_bid\":\"0.73\", \"best_ask\":\"0.74\"}], \"timestamp\":\"1785204361543\", \"event_type\":\"price_change\"}","received_at":"2026-07-28T02:06:01.819290Z","schema_version":"clob-market-ws.price_change.v1","sequence":null,"server_hash":null,"server_timestamp":"1785204361543","session_id":"d2757dd6dad94f3b9fe67e8dbf1adc37","source":"clob_market_ws"},"received_at":"2026-07-28T02:06:01.819290Z","record_id":"0ba1f7555badb9509f96056319e12e257a5e14d1673c2a7df633ccb97c25f56f","schema_fingerprint":"4aa3821a28b0b7c2400bc59aba4bcc0a76e971dadd19610d3ad38c768e124dc7","schema_version":"edge-lab-recorder.raw.v1","sequence":null,"source":"clob_market_ws"}
{"event_at":"2026-07-28T02:06:01.545000Z","event_fingerprint":"ec121a2fdd2417a5340045414d21d3c1e192cabc2b8c1d147362264c9f0d7a23","payload":{"connection_id":"5d29200f65794d4d9ab6ef271f045a9b","event_at":"2026-07-28T02:06:01.545000Z","event_type":"price_change","frame_hash":"72fdafc31de16a5c373c4458451485d67cfe79893d7937790c1ca2313adc31b4","frame_index":0,"kind":"data","monotonic_ns":306344830343000,"payload":{"event_type":"price_change","market":"0xda6f0e0e93fc8469e0159a166028d017bddbc162b86f66bac90391379603d962","price_changes":[{"asset_id":"20893381255801015515826997628594359667013752732428989472914000440642900266717","best_ask":"0.27","best_bid":"0.26","hash":"80da30ff1f10a2f05208bf9ce19857ccb6c1e653","price":"0.26","side":"BUY","size":"67.6"},{"asset_id":"39272994714739463168905443499424551362424437245880253267329605556587274644733","best_ask":"0.74","best_bid":"0.73","hash":"79598d81ef2074a54332dac81cc81668b32d78a0","price":"0.74","side":"SELL","size":"67.6"}],"timestamp":"1785204361545"},"payload_hash":"c7bc7e0cfdf3c2174b7cec5948bc70713e117e9ba86b90a5acdb766cd430a629","raw_frame":"{\"market\":\"0xda6f0e0e93fc8469e0159a166028d017bddbc162b86f66bac90391379603d962\", \"price_changes\":[{\"asset_id\":\"20893381255801015515826997628594359667013752732428989472914000440642900266717\", \"price\":\"0.26\", \"size\":\"67.6\", \"side\":\"BUY\", \"hash\":\"80da30ff1f10a2f05208bf9ce19857ccb6c1e653\", \"best_bid\":\"0.26\", \"best_ask\":\"0.27\"}, {\"asset_id\":\"39272994714739463168905443499424551362424437245880253267329605556587274644733\", \"price\":\"0.74\", \"size\":\"67.6\", \"side\":\"SELL\", \"hash\":\"79598d81ef2074a54332dac81cc81668b32d78a0\", \"best_bid\":\"0.73\", \"best_ask\":\"0.74\"}], \"timestamp\":\"1785204361545\", \"event_type\":\"price_change\"}","received_at":"2026-07-28T02:06:01.823710Z","schema_version":"clob-market-ws.price_change.v1","sequence":null,"server_hash":null,"server_timestamp":"1785204361545","session_id":"d2757dd6dad94f3b9fe67e8dbf1adc37","source":"clob_market_ws"},"received_at":"2026-07-28T02:06:01.823710Z","record_id":"cfbb6b7471148ecb6a01853a9c785844b29d64db007a96917c03270384455173","schema_fingerprint":"4aa3821a28b0b7c2400bc59aba4bcc0a76e971dadd19610d3ad38c768e124dc7","schema_version":"edge-lab-recorder.raw.v1","sequence":null,"source":"clob_market_ws"}
{"event_at":"2026-07-28T02:06:01.546000Z","event_fingerprint":"69b5e37bd1d97b353d3efa0032663b351684fd8a698c15e199c4a9ff36c4b40e","payload":{"connection_id":"5d29200f65794d4d9ab6ef271f045a9b","event_at":"2026-07-28T02:06:01.546000Z","event_type":"price_change","frame_hash":"cb3d12909dec6c80e5621bc59b5f3175ba586fd26f4802435bcb343ae9c19812","frame_index":0,"kind":"data","monotonic_ns":306344834139916,"payload":{"event_type":"price_change","market":"0xda6f0e0e93fc8469e0159a166028d017bddbc162b86f66bac90391379603d962","price_changes":[{"asset_id":"20893381255801015515826997628594359667013752732428989472914000440642900266717","best_ask":"0.27","best_bid":"0.26","hash":"343faa91eb31e816573a4bab40b9f6dcd2b17b41","price":"0.15","side":"BUY","size":"406.5"},{"asset_id":"39272994714739463168905443499424551362424437245880253267329605556587274644733","best_ask":"0.74","best_bid":"0.73","hash":"ea7ff2fa23c3943e892c1bfabb428c6fbdc28f6f","price":"0.85","side":"SELL","size":"406.5"}],"timestamp":"1785204361546"},"payload_hash":"df5c737ab4ac83dc3b33c13220d4447f904090f0c4063e0858f108ef6ab20827","raw_frame":"{\"market\":\"0xda6f0e0e93fc8469e0159a166028d017bddbc162b86f66bac90391379603d962\", \"price_changes\":[{\"asset_id\":\"20893381255801015515826997628594359667013752732428989472914000440642900266717\", \"price\":\"0.15\", \"size\":\"406.5\", \"side\":\"BUY\", \"hash\":\"343faa91eb31e816573a4bab40b9f6dcd2b17b41\", \"best_bid\":\"0.26\", \"best_ask\":\"0.27\"}, {\"asset_id\":\"39272994714739463168905443499424551362424437245880253267329605556587274644733\", \"price\":\"0.85\", \"size\":\"406.5\", \"side\":\"SELL\", \"hash\":\"ea7ff2fa23c3943e892c1bfabb428c6fbdc28f6f\", \"best_bid\":\"0.73\", \"best_ask\":\"0.74\"}], \"timestamp\":\"1785204361546\", \"event_type\":\"price_change\"}","received_at":"2026-07-28T02:06:01.827507Z","schema_version":"clob-market-ws.price_change.v1","sequence":null,"server_hash":null,"server_timestamp":"1785204361546","session_id":"d2757dd6dad94f3b9fe67e8dbf1adc37","source":"clob_market_ws"},"received_at":"2026-07-28T02:06:01.827507Z","record_id":"c4f3f9d4272d666c0ace24a113620ed0fc74a671b81dfdd07dbfb3e2d07040e1","schema_fingerprint":"4aa3821a28b0b7c2400bc59aba4bcc0a76e971dadd19610d3ad38c768e124dc7","schema_version":"edge-lab-recorder.raw.v1","sequence":null,"source":"clob_market_ws"}
{"event_at":"2026-07-28T02:06:01.547000Z","event_fingerprint":"11c652ae12c86ac5e141f5bf2e5c19ae11505708fe9734997cc513ea412298ba","payload":{"connection_id":"5d29200f65794d4d9ab6ef271f045a9b","event_at":"2026-07-28T02:06:01.547000Z","event_type":"price_change","frame_hash":"623542eb27b23584530b186a5b2b583e5070aebe4f9c5062ecadbf30ad1b27b4","frame_index":0,"kind":"data","monotonic_ns":306344837964541,"payload":{"event_type":"price_change","market":"0xda6f0e0e93fc8469e0159a166028d017bddbc162b86f66bac90391379603d962","price_changes":[{"asset_id":"39272994714739463168905443499424551362424437245880253267329605556587274644733","best_ask":"0.74","best_bid":"0.73","hash":"afa610ef8e0536dcd06ec4ea0137cecd0093caa2","price":"0.74","side":"SELL","size":"73.6"},{"asset_id":"20893381255801015515826997628594359667013752732428989472914000440642900266717","best_ask":"0.27","best_bid":"0.26","hash":"743b233129ad45570eace561a46b3143a5565a8e","price":"0.26","side":"BUY","size":"73.6"}],"timestamp":"1785204361547"},"payload_hash":"c388e4b6167b599c2c22aa3ea4d9652f30123cff2df323977742a3aa52dcc0ef","raw_frame":"{\"market\":\"0xda6f0e0e93fc8469e0159a166028d017bddbc162b86f66bac90391379603d962\", \"price_changes\":[{\"asset_id\":\"39272994714739463168905443499424551362424437245880253267329605556587274644733\", \"price\":\"0.74\", \"size\":\"73.6\", \"side\":\"SELL\", \"hash\":\"afa610ef8e0536dcd06ec4ea0137cecd0093caa2\", \"best_bid\":\"0.73\", \"best_ask\":\"0.74\"}, {\"asset_id\":\"20893381255801015515826997628594359667013752732428989472914000440642900266717\", \"price\":\"0.26\", \"size\":\"73.6\", \"side\":\"BUY\", \"hash\":\"743b233129ad45570eace561a46b3143a5565a8e\", \"best_bid\":\"0.26\", \"best_ask\":\"0.27\"}], \"timestamp\":\"1785204361547\", \"event_type\":\"price_change\"}","received_at":"2026-07-28T02:06:01.831331Z","schema_version":"clob-market-ws.price_change.v1","sequence":null,"server_hash":null,"server_timestamp":"1785204361547","session_id":"d2757dd6dad94f3b9fe67e8dbf1adc37","source":"clob_market_ws"},"received_at":"2026-07-28T02:06:01.831331Z","record_id":"5ec6842b58a106d79d35d46f3b0fede6155cdda959c0911d39fb7ff2847851de","schema_fingerprint":"4aa3821a28b0b7c2400bc59aba4bcc0a76e971dadd19610d3ad38c768e124dc7","schema_version":"edge-lab-recorder.raw.v1","sequence":null,"source":"clob_market_ws"}
{"event_at":"2026-07-28T02:06:01.548000Z","event_fingerprint":"d6f9a5b554e35aefc4336856776fc6d122abeec5dd4528d6d54346895a25b462","payload":{"connection_id":"5d29200f65794d4d9ab6ef271f045a9b","event_at":"2026-07-28T02:06:01.548000Z","event_type":"price_change","frame_hash":"8ac5587836849b9d151356ba4f2f63ba2e94dcf513d2f8a21bb55fb4ca222aa9","frame_index":0,"kind":"data","monotonic_ns":306344842468875,"payload":{"event_type":"price_change","market":"0xda6f0e0e93fc8469e0159a166028d017bddbc162b86f66bac90391379603d962","price_changes":[{"asset_id":"39272994714739463168905443499424551362424437245880253267329605556587274644733","best_ask":"0.74","best_bid":"0.73","hash":"e149c9c0455ce4363001c73e16ad7190a11f2063","price":"0.6","side":"BUY","size":"98"},{"asset_id":"20893381255801015515826997628594359667013752732428989472914000440642900266717","best_ask":"0.27","best_bid":"0.26","hash":"b7d678586e0a913fbc14a8990d48e89496b44f8c","price":"0.4","side":"SELL","size":"98"}],"timestamp":"1785204361548"},"payload_hash":"25c3d9ea9f4c6e0907a8ce889842bf3ef70bf4049da2224a1576272dccf42d65","raw_frame":"{\"market\":\"0xda6f0e0e93fc8469e0159a166028d017bddbc162b86f66bac90391379603d962\", \"price_changes\":[{\"asset_id\":\"39272994714739463168905443499424551362424437245880253267329605556587274644733\", \"price\":\"0.6\", \"size\":\"98\", \"side\":\"BUY\", \"hash\":\"e149c9c0455ce4363001c73e16ad7190a11f2063\", \"best_bid\":\"0.73\", \"best_ask\":\"0.74\"}, {\"asset_id\":\"20893381255801015515826997628594359667013752732428989472914000440642900266717\", \"price\":\"0.4\", \"size\":\"98\", \"side\":\"SELL\", \"hash\":\"b7d678586e0a913fbc14a8990d48e89496b44f8c\", \"best_bid\":\"0.26\", \"best_ask\":\"0.27\"}], \"timestamp\":\"1785204361548\", \"event_type\":\"price_change\"}","received_at":"2026-07-28T02:06:01.835835Z","schema_version":"clob-market-ws.price_change.v1","sequence":null,"server_hash":null,"server_timestamp":"1785204361548","session_id":"d2757dd6dad94f3b9fe67e8dbf1adc37","source":"clob_market_ws"},"received_at":"2026-07-28T02:06:01.835835Z","record_id":"871eccdf719669d58c1fcda5680ee8fe969c7b6e3ef092895f3489efdf62d2de","schema_fingerprint":"4aa3821a28b0b7c2400bc59aba4bcc0a76e971dadd19610d3ad38c768e124dc7","schema_version":"edge-lab-recorder.raw.v1","sequence":null,"source":"clob_market_ws"}
{"event_at":"2026-07-28T02:06:01.549000Z","event_fingerprint":"110f9abda2bbd9885fc4d784fabccc0f12d657aba5c755432ff7b2bbb50748b5","payload":{"connection_id":"5d29200f65794d4d9ab6ef271f045a9b","event_at":"2026-07-28T02:06:01.549000Z","event_type":"price_change","frame_hash":"5041de8748824eb8485a6c6510a2a26eadcce35ffc1d589da156293c59b5bc41","frame_index":0,"kind":"data","monotonic_ns":306344846675875,"payload":{"event_type":"price_change","market":"0xda6f0e0e93fc8469e0159a166028d017bddbc162b86f66bac90391379603d962","price_changes":[{"asset_id":"20893381255801015515826997628594359667013752732428989472914000440642900266717","best_ask":"0.27","best_bid":"0.26","hash":"c2905c3629a737d0bbff96b5bb64716e1d9bcbf5","price":"0.25","side":"BUY","size":"94.2"},{"asset_id":"39272994714739463168905443499424551362424437245880253267329605556587274644733","best_ask":"0.74","best_bid":"0.73","hash":"10a3d6cf0960bc250ae180b7f94eb954d8cb3051","price":"0.75","side":"SELL","size":"94.2"}],"timestamp":"1785204361549"},"payload_hash":"4de181e65e3724b762400092915c1f176a1ccd48903e29b6d5886c3b7e856f6e","raw_frame":"{\"market\":\"0xda6f0e0e93fc8469e0159a166028d017bddbc162b86f66bac90391379603d962\", \"price_changes\":[{\"asset_id\":\"20893381255801015515826997628594359667013752732428989472914000440642900266717\", \"price\":\"0.25\", \"size\":\"94.2\", \"side\":\"BUY\", \"hash\":\"c2905c3629a737d0bbff96b5bb64716e1d9bcbf5\", \"best_bid\":\"0.26\", \"best_ask\":\"0.27\"}, {\"asset_id\":\"39272994714739463168905443499424551362424437245880253267329605556587274644733\", \"price\":\"0.75\", \"size\":\"94.2\", \"side\":\"SELL\", \"hash\":\"10a3d6cf0960bc250ae180b7f94eb954d8cb3051\", \"best_bid\":\"0.73\", \"best_ask\":\"0.74\"}], \"timestamp\":\"1785204361549\", \"event_type\":\"price_change\"}","received_at":"2026-07-28T02:06:01.840043Z","schema_version":"clob-market-ws.price_change.v1","sequence":null,"server_hash":null,"server_timestamp":"1785204361549","session_id":"d2757dd6dad94f3b9fe67e8dbf1adc37","source":"clob_market_ws"},"received_at":"2026-07-28T02:06:01.840043Z","record_id":"6fee55c9b6310acc17cf6b98b72b77363d377072b6daac0965b3d0846d2b330a","schema_fingerprint":"4aa3821a28b0b7c2400bc59aba4bcc0a76e971dadd19610d3ad38c768e124dc7","schema_version":"edge-lab-recorder.raw.v1","sequence":null,"source":"clob_market_ws"}
{"event_at":"2026-07-28T02:06:01.555000Z","event_fingerprint":"9aca441573c8425d8a971f385e9288ab1132531e52688bd3325002c76ebc2290","payload":{"connection_id":"5d29200f65794d4d9ab6ef271f045a9b","event_at":"2026-07-28T02:06:01.555000Z","event_type":"price_change","frame_hash":"1fa46f2d000bb0d5184880f40b69f978a6bb2ff59596e8d7cb08a4b805f4230d","frame_index":0,"kind":"data","monotonic_ns":306344849825375,"payload":{"event_type":"price_change","market":"0xda6f0e0e93fc8469e0159a166028d017bddbc162b86f66bac90391379603d962","price_changes":[{"asset_id":"39272994714739463168905443499424551362424437245880253267329605556587274644733","best_ask":"0.74","best_bid":"0.73","hash":"0c118fe55e279018cf364d7c1dd3a036711fbe20","price":"0.72","side":"BUY","size":"75.2"},{"asset_id":"20893381255801015515826997628594359667013752732428989472914000440642900266717","best_ask":"0.27","best_bid":"0.26","hash":"bdfe122d5efc64fe726d48569459a525ff41c0eb","price":"0.28","side":"SELL","size":"75.2"}],"timestamp":"1785204361555"},"payload_hash":"29f32530fbba9ddd67ca2732650b85aa502c6e29bb18d7ce7e28aab5e926ff82","raw_frame":"{\"market\":\"0xda6f0e0e93fc8469e0159a166028d017bddbc162b86f66bac90391379603d962\", \"price_changes\":[{\"asset_id\":\"39272994714739463168905443499424551362424437245880253267329605556587274644733\", \"price\":\"0.72\", \"size\":\"75.2\", \"side\":\"BUY\", \"hash\":\"0c118fe55e279018cf364d7c1dd3a036711fbe20\", \"best_bid\":\"0.73\", \"best_ask\":\"0.74\"}, {\"asset_id\":\"20893381255801015515826997628594359667013752732428989472914000440642900266717\", \"price\":\"0.28\", \"size\":\"75.2\", \"side\":\"SELL\", \"hash\":\"bdfe122d5efc64fe726d48569459a525ff41c0eb\", \"best_bid\":\"0.26\", \"best_ask\":\"0.27\"}], \"timestamp\":\"1785204361555\", \"event_type\":\"price_change\"}","received_at":"2026-07-28T02:06:01.843192Z","schema_version":"clob-market-ws.price_change.v1","sequence":null,"server_hash":null,"server_timestamp":"1785204361555","session_id":"d2757dd6dad94f3b9fe67e8dbf1adc37","source":"clob_market_ws"},"received_at":"2026-07-28T02:06:01.843192Z","record_id":"152c761d142dfc4e90c973bd8084fea8c590a0c7d2baee0cf323cbfea24adb5c","schema_fingerprint":"4aa3821a28b0b7c2400bc59aba4bcc0a76e971dadd19610d3ad38c768e124dc7","schema_version":"edge-lab-recorder.raw.v1","sequence":null,"source":"clob_market_ws"}
{"event_at":"2026-07-28T02:06:01.555000Z","event_fingerprint":"70442854ed6885e73c2e94fe805f8aa54edde90f522a69e49328a5c28596c5a4","payload":{"connection_id":"5d29200f65794d4d9ab6ef271f045a9b","event_at":"2026-07-28T02:06:01.555000Z","event_type":"price_change","frame_hash":"951f2960de50bbb9511e3df2a2a1fe4b9e15e859ec40cb75c13da5ce5ca1d55b","frame_index":0,"kind":"data","monotonic_ns":306344853517958,"payload":{"event_type":"price_change","market":"0xda6f0e0e93fc8469e0159a166028d017bddbc162b86f66bac90391379603d962","price_changes":[{"asset_id":"20893381255801015515826997628594359667013752732428989472914000440642900266717","best_ask":"0.27","best_bid":"0.26","hash":"55966062fc772cedfb95bf45952d6c2a1a3063a7","price":"0.21","side":"BUY","size":"98.46"},{"asset_id":"39272994714739463168905443499424551362424437245880253267329605556587274644733","best_ask":"0.74","best_bid":"0.73","hash":"49725ac8fbbeae47be9179c78e0062d406cb91e3","price":"0.79","side":"SELL","size":"98.46"}],"timestamp":"1785204361555"},"payload_hash":"ec0449c2a6bb657a499c2847c69e9927c370cb76bdf1b9196ba2342e0105cc1f","raw_frame":"{\"market\":\"0xda6f0e0e93fc8469e0159a166028d017bddbc162b86f66bac90391379603d962\", \"price_changes\":[{\"asset_id\":\"20893381255801015515826997628594359667013752732428989472914000440642900266717\", \"price\":\"0.21\", \"size\":\"98.46\", \"side\":\"BUY\", \"hash\":\"55966062fc772cedfb95bf45952d6c2a1a3063a7\", \"best_bid\":\"0.26\", \"best_ask\":\"0.27\"}, {\"asset_id\":\"39272994714739463168905443499424551362424437245880253267329605556587274644733\", \"price\":\"0.79\", \"size\":\"98.46\", \"side\":\"SELL\", \"hash\":\"49725ac8fbbeae47be9179c78e0062d406cb91e3\", \"best_bid\":\"0.73\", \"best_ask\":\"0.74\"}], \"timestamp\":\"1785204361555\", \"event_type\":\"price_change\"}","received_at":"2026-07-28T02:06:01.846884Z","schema_version":"clob-market-ws.price_change.v1","sequence":null,"server_hash":null,"server_timestamp":"1785204361555","session_id":"d2757dd6dad94f3b9fe67e8dbf1adc37","source":"clob_market_ws"},"received_at":"2026-07-28T02:06:01.846884Z","record_id":"bf1eb349ea0fc42ad0eb1768d856f509de41e9f7c576623346356e15d9fed69e","schema_fingerprint":"4aa3821a28b0b7c2400bc59aba4bcc0a76e971dadd19610d3ad38c768e124dc7","schema_version":"edge-lab-recorder.raw.v1","sequence":null,"source":"clob_market_ws"}
{"event_at":"2026-07-28T02:06:01.558000Z","event_fingerprint":"35232bbab443b47618d079cc1ee2e807d9f1e8255acf6b140d2f22e681cbbb6a","payload":{"connection_id":"5d29200f65794d4d9ab6ef271f045a9b","event_at":"2026-07-28T02:06:01.558000Z","event_type":"price_change","frame_hash":"909454b58c5580d0de8502f080d114c4d88aa096f13dc0a64b0c46541deb933b","frame_index":0,"kind":"data","monotonic_ns":306344857122541,"payload":{"event_type":"price_change","market":"0xda6f0e0e93fc8469e0159a166028d017bddbc162b86f66bac90391379603d962","price_changes":[{"asset_id":"20893381255801015515826997628594359667013752732428989472914000440642900266717","best_ask":"0.27","best_bid":"0.26","hash":"d089bf715bbc10d26f9b8f4fbf12a8f505a3894e","price":"0.26","side":"BUY","size":"61"},{"asset_id":"39272994714739463168905443499424551362424437245880253267329605556587274644733","best_ask":"0.74","best_bid":"0.73","hash":"b8ad8962124d10dd8b3d697b6428c741ede706ba","price":"0.74","side":"SELL","size":"61"}],"timestamp":"1785204361558"},"payload_hash":"404ff8b5a3160d8c9742401c076ea575c965dcaee853f6a7183c112244076f45","raw_frame":"{\"market\":\"0xda6f0e0e93fc8469e0159a166028d017bddbc162b86f66bac90391379603d962\", \"price_changes\":[{\"asset_id\":\"20893381255801015515826997628594359667013752732428989472914000440642900266717\", \"price\":\"0.26\", \"size\":\"61\", \"side\":\"BUY\", \"hash\":\"d089bf715bbc10d26f9b8f4fbf12a8f505a3894e\", \"best_bid\":\"0.26\", \"best_ask\":\"0.27\"}, {\"asset_id\":\"39272994714739463168905443499424551362424437245880253267329605556587274644733\", \"price\":\"0.74\", \"size\":\"61\", \"side\":\"SELL\", \"hash\":\"b8ad8962124d10dd8b3d697b6428c741ede706ba\", \"best_bid\":\"0.73\", \"best_ask\":\"0.74\"}], \"timestamp\":\"1785204361558\", \"event_type\":\"price_change\"}","received_at":"2026-07-28T02:06:01.850489Z","schema_version":"clob-market-ws.price_change.v1","sequence":null,"server_hash":null,"server_timestamp":"1785204361558","session_id":"d2757dd6dad94f3b9fe67e8dbf1adc37","source":"clob_market_ws"},"received_at":"2026-07-28T02:06:01.850489Z","record_id":"d69882e4d946d8ba4594605ff6baae41804a4ba1ef07ef43d77d86b4ee7fca02","schema_fingerprint":"4aa3821a28b0b7c2400bc59aba4bcc0a76e971dadd19610d3ad38c768e124dc7","schema_version":"edge-lab-recorder.raw.v1","sequence":null,"source":"clob_market_ws"}
{"event_at":"2026-07-28T02:06:01.560000Z","event_fingerprint":"e48d41c37918712084715bb1902fbd1bbdd043a183a602e696edf036f6dd6b15","payload":{"connection_id":"5d29200f65794d4d9ab6ef271f045a9b","event_at":"2026-07-28T02:06:01.560000Z","event_type":"price_change","frame_hash":"08ac566e2bdf0e8d90fae498a73cd2e4d89b5cb957915095a167148e3c93cea0","frame_index":0,"kind":"data","monotonic_ns":306344861132041,"payload":{"event_type":"price_change","market":"0xda6f0e0e93fc8469e0159a166028d017bddbc162b86f66bac90391379603d962","price_changes":[{"asset_id":"39272994714739463168905443499424551362424437245880253267329605556587274644733","best_ask":"0.74","best_bid":"0.73","hash":"4346b686407c9019549d0889ebab5f92afbf04cb","price":"0.7","side":"BUY","size":"82.2"},{"asset_id":"20893381255801015515826997628594359667013752732428989472914000440642900266717","best_ask":"0.27","best_bid":"0.26","hash":"8896c834058ff1565f74cd76ecc9dbea6e3793c1","price":"0.3","side":"SELL","size":"82.2"}],"timestamp":"1785204361560"},"payload_hash":"4a2694b180f40cd71c39b512b55bb6b96b39925d478be4210c1ce89d42e22188","raw_frame":"{\"market\":\"0xda6f0e0e93fc8469e0159a166028d017bddbc162b86f66bac90391379603d962\", \"price_changes\":[{\"asset_id\":\"39272994714739463168905443499424551362424437245880253267329605556587274644733\", \"price\":\"0.7\", \"size\":\"82.2\", \"side\":\"BUY\", \"hash\":\"4346b686407c9019549d0889ebab5f92afbf04cb\", \"best_bid\":\"0.73\", \"best_ask\":\"0.74\"}, {\"asset_id\":\"20893381255801015515826997628594359667013752732428989472914000440642900266717\", \"price\":\"0.3\", \"size\":\"82.2\", \"side\":\"SELL\", \"hash\":\"8896c834058ff1565f74cd76ecc9dbea6e3793c1\", \"best_bid\":\"0.26\", \"best_ask\":\"0.27\"}], \"timestamp\":\"1785204361560\", \"event_type\":\"price_change\"}","received_at":"2026-07-28T02:06:01.854498Z","schema_version":"clob-market-ws.price_change.v1","sequence":null,"server_hash":null,"server_timestamp":"1785204361560","session_id":"d2757dd6dad94f3b9fe67e8dbf1adc37","source":"clob_market_ws"},"received_at":"2026-07-28T02:06:01.854498Z","record_id":"992939222b7851bf29491bc4ee0403e2b1c12896c3a11e646417a0f48be8895c","schema_fingerprint":"4aa3821a28b0b7c2400bc59aba4bcc0a76e971dadd19610d3ad38c768e124dc7","schema_version":"edge-lab-recorder.raw.v1","sequence":null,"source":"clob_market_ws"}
{"event_at":"2026-07-28T02:06:01.562000Z","event_fingerprint":"b1dcf1dc0bead6cb2eabef3bd5991ca27ff33b9ffa64e213984b6f3314e2a81a","payload":{"connection_id":"5d29200f65794d4d9ab6ef271f045a9b","event_at":"2026-07-28T02:06:01.562000Z","event_type":"price_change","frame_hash":"30318285e1abad4b5e887c685cbe92b78443a2f0bb49ed80593917fa2410590b","frame_index":0,"kind":"data","monotonic_ns":306344865421083,"payload":{"event_type":"price_change","market":"0xda6f0e0e93fc8469e0159a166028d017bddbc162b86f66bac90391379603d962","price_changes":[{"asset_id":"39272994714739463168905443499424551362424437245880253267329605556587274644733","best_ask":"0.74","best_bid":"0.73","hash":"7d6a20376aa03f8950597b4b8780b252dc65fdcd","price":"0.64","side":"BUY","size":"129.5"},{"asset_id":"20893381255801015515826997628594359667013752732428989472914000440642900266717","best_ask":"0.27","best_bid":"0.26","hash":"4aae6aa41548850b8d04380171f8683f314c402b","price":"0.36","side":"SELL","size":"129.5"}],"timestamp":"1785204361562"},"payload_hash":"4217e85f47ed0ff5858b722afe536ad5583242419c981c4a82353180bb3d093a","raw_frame":"{\"market\":\"0xda6f0e0e93fc8469e0159a166028d017bddbc162b86f66bac90391379603d962\", \"price_changes\":[{\"asset_id\":\"39272994714739463168905443499424551362424437245880253267329605556587274644733\", \"price\":\"0.64\", \"size\":\"129.5\", \"side\":\"BUY\", \"hash\":\"7d6a20376aa03f8950597b4b8780b252dc65fdcd\", \"best_bid\":\"0.73\", \"best_ask\":\"0.74\"}, {\"asset_id\":\"20893381255801015515826997628594359667013752732428989472914000440642900266717\", \"price\":\"0.36\", \"size\":\"129.5\", \"side\":\"SELL\", \"hash\":\"4aae6aa41548850b8d04380171f8683f314c402b\", \"best_bid\":\"0.26\", \"best_ask\":\"0.27\"}], \"timestamp\":\"1785204361562\", \"event_type\":\"price_change\"}","received_at":"2026-07-28T02:06:01.858788Z","schema_version":"clob-market-ws.price_change.v1","sequence":null,"server_hash":null,"server_timestamp":"1785204361562","session_id":"d2757dd6dad94f3b9fe67e8dbf1adc37","source":"clob_market_ws"},"received_at":"2026-07-28T02:06:01.858788Z","record_id":"2d0158ed2052d32202155f32bef4f83e424577cc8f53a933f3c5bc2153913ad6","schema_fingerprint":"4aa3821a28b0b7c2400bc59aba4bcc0a76e971dadd19610d3ad38c768e124dc7","schema_version":"edge-lab-recorder.raw.v1","sequence":null,"source":"clob_market_ws"}
{"event_at":"2026-07-28T02:06:01.571000Z","event_fingerprint":"4839273ed9612b9749051272d98f036b0ec9068951c7989e782f16c266531288","payload":{"connection_id":"5d29200f65794d4d9ab6ef271f045a9b","event_at":"2026-07-28T02:06:01.571000Z","event_type":"price_change","frame_hash":"3f39d84c091bb6d0df8e5d7b149344eaf16eff7a1a1a32aa2f0c7287f88585ee","frame_index":0,"kind":"data","monotonic_ns":306344872078375,"payload":{"event_type":"price_change","market":"0xda6f0e0e93fc8469e0159a166028d017bddbc162b86f66bac90391379603d962","price_changes":[{"asset_id":"20893381255801015515826997628594359667013752732428989472914000440642900266717","best_ask":"0.27","best_bid":"0.26","hash":"e7a0b2f54a0da9c750fbc47f9b082725df65326a","price":"0.26","side":"BUY","size":"86"},{"asset_id":"39272994714739463168905443499424551362424437245880253267329605556587274644733","best_ask":"0.74","best_bid":"0.73","hash":"5bc4533dfc35289118a6631c47334fad1f794daa","price":"0.74","side":"SELL","size":"86"}],"timestamp":"1785204361571"},"payload_hash":"230477cbd12e8aafb84c1615b9d295e1b6318d15d287d747c495519d4b300f1e","raw_frame":"{\"market\":\"0xda6f0e0e93fc8469e0159a166028d017bddbc162b86f66bac90391379603d962\", \"price_changes\":[{\"asset_id\":\"20893381255801015515826997628594359667013752732428989472914000440642900266717\", \"price\":\"0.26\", \"size\":\"86\", \"side\":\"BUY\", \"hash\":\"e7a0b2f54a0da9c750fbc47f9b082725df65326a\", \"best_bid\":\"0.26\", \"best_ask\":\"0.27\"}, {\"asset_id\":\"39272994714739463168905443499424551362424437245880253267329605556587274644733\", \"price\":\"0.74\", \"size\":\"86\", \"side\":\"SELL\", \"hash\":\"5bc4533dfc35289118a6631c47334fad1f794daa\", \"best_bid\":\"0.73\", \"best_ask\":\"0.74\"}], \"timestamp\":\"1785204361571\", \"event_type\":\"price_change\"}","received_at":"2026-07-28T02:06:01.865445Z","schema_version":"clob-market-ws.price_change.v1","sequence":null,"server_hash":null,"server_timestamp":"1785204361571","session_id":"d2757dd6dad94f3b9fe67e8dbf1adc37","source":"clob_market_ws"},"received_at":"2026-07-28T02:06:01.865445Z","record_id":"0003b5583263739c634a865870b6926af6ea7591e18ea0ac590fa117e87adda4","schema_fingerprint":"4aa3821a28b0b7c2400bc59aba4bcc0a76e971dadd19610d3ad38c768e124dc7","schema_version":"edge-lab-recorder.raw.v1","sequence":null,"source":"clob_market_ws"}
{"event_at":"2026-07-28T02:06:01.573000Z","event_fingerprint":"b1f841f36da358f654f8d054a54d5d6c99d97a1b79e21519117ffcc8746dd1e4","payload":{"connection_id":"5d29200f65794d4d9ab6ef271f045a9b","event_at":"2026-07-28T02:06:01.573000Z","event_type":"price_change","frame_hash":"a060c4288f364062b647c498cd8356fd9dd1141fdf535554e3e52bed1b29e5b2","frame_index":0,"kind":"data","monotonic_ns":306344876540416,"payload":{"event_type":"price_change","market":"0xda6f0e0e93fc8469e0159a166028d017bddbc162b86f66bac90391379603d962","price_changes":[{"asset_id":"39272994714739463168905443499424551362424437245880253267329605556587274644733","best_ask":"0.74","best_bid":"0.73","hash":"1461454e79a3b88c89eba25f5a959d4c54ffdb61","price":"0.03","side":"BUY","size":"648.1"},{"asset_id":"20893381255801015515826997628594359667013752732428989472914000440642900266717","best_ask":"0.27","best_bid":"0.26","hash":"3cf9bee6e9f1d5c5bf11e19815fd334969b62362","price":"0.97","side":"SELL","size":"648.1"}],"timestamp":"1785204361573"},"payload_hash":"adb54bf4bfdb0d34513ba006bb47a55c8fcb3cd40e109d05605de822f851fe73","raw_frame":"{\"market\":\"0xda6f0e0e93fc8469e0159a166028d017bddbc162b86f66bac90391379603d962\", \"price_changes\":[{\"asset_id\":\"39272994714739463168905443499424551362424437245880253267329605556587274644733\", \"price\":\"0.03\", \"size\":\"648.1\", \"side\":\"BUY\", \"hash\":\"1461454e79a3b88c89eba25f5a959d4c54ffdb61\", \"best_bid\":\"0.73\", \"best_ask\":\"0.74\"}, {\"asset_id\":\"20893381255801015515826997628594359667013752732428989472914000440642900266717\", \"price\":\"0.97\", \"size\":\"648.1\", \"side\":\"SELL\", \"hash\":\"3cf9bee6e9f1d5c5bf11e19815fd334969b62362\", \"best_bid\":\"0.26\", \"best_ask\":\"0.27\"}], \"timestamp\":\"1785204361573\", \"event_type\":\"price_change\"}","received_at":"2026-07-28T02:06:01.869907Z","schema_version":"clob-market-ws.price_change.v1","sequence":null,"server_hash":null,"server_timestamp":"1785204361573","session_id":"d2757dd6dad94f3b9fe67e8dbf1adc37","source":"clob_market_ws"},"received_at":"2026-07-28T02:06:01.869907Z","record_id":"6a59d72e3aa2a8392cf63de12a8ccde933668c8d4ff78904333dc505bbe17b60","schema_fingerprint":"4aa3821a28b0b7c2400bc59aba4bcc0a76e971dadd19610d3ad38c768e124dc7","schema_version":"edge-lab-recorder.raw.v1","sequence":null,"source":"clob_market_ws"}
{"event_at":"2026-07-28T02:06:01.573000Z","event_fingerprint":"0f491526d069163d6f628faca1c004347673720ea0101fe560e804702051481c","payload":{"connection_id":"5d29200f65794d4d9ab6ef271f045a9b","event_at":"2026-07-28T02:06:01.573000Z","event_type":"price_change","frame_hash":"d3687769ba9a157956feca410b002f46a9af18ff0f970103b6017e7d3bfbec03","frame_index":0,"kind":"data","monotonic_ns":306344879871500,"payload":{"event_type":"price_change","market":"0xda6f0e0e93fc8469e0159a166028d017bddbc162b86f66bac90391379603d962","price_changes":[{"asset_id":"39272994714739463168905443499424551362424437245880253267329605556587274644733","best_ask":"0.74","best_bid":"0.73","hash":"705bc1cf61a24a79c8441e9c4d6fdf49accc76a7","price":"0.7","side":"BUY","size":"113.2"},{"asset_id":"20893381255801015515826997628594359667013752732428989472914000440642900266717","best_ask":"0.27","best_bid":"0.26","hash":"d6200a2ab444d3a6cf904cfd961a5cb1d7e5973b","price":"0.3","side":"SELL","size":"113.2"}],"timestamp":"1785204361573"},"payload_hash":"4c5cb11bbec819aa34d5235abc5459a9281206cc78240fed258d8bde593680ca","raw_frame":"{\"market\":\"0xda6f0e0e93fc8469e0159a166028d017bddbc162b86f66bac90391379603d962\", \"price_changes\":[{\"asset_id\":\"39272994714739463168905443499424551362424437245880253267329605556587274644733\", \"price\":\"0.7\", \"size\":\"113.2\", \"side\":\"BUY\", \"hash\":\"705bc1cf61a24a79c8441e9c4d6fdf49accc76a7\", \"best_bid\":\"0.73\", \"best_ask\":\"0.74\"}, {\"asset_id\":\"20893381255801015515826997628594359667013752732428989472914000440642900266717\", \"price\":\"0.3\", \"size\":\"113.2\", \"side\":\"SELL\", \"hash\":\"d6200a2ab444d3a6cf904cfd961a5cb1d7e5973b\", \"best_bid\":\"0.26\", \"best_ask\":\"0.27\"}], \"timestamp\":\"1785204361573\", \"event_type\":\"price_change\"}","received_at":"2026-07-28T02:06:01.873238Z","schema_version":"clob-market-ws.price_change.v1","sequence":null,"server_hash":null,"server_timestamp":"1785204361573","session_id":"d2757dd6dad94f3b9fe67e8dbf1adc37","source":"clob_market_ws"},"received_at":"2026-07-28T02:06:01.873238Z","record_id":"910eeafcf11e5441730a6c6ada6be90640280182e1015faa0e4082fb32b25887","schema_fingerprint":"4aa3821a28b0b7c2400bc59aba4bcc0a76e971dadd19610d3ad38c768e124dc7","schema_version":"edge-lab-recorder.raw.v1","sequence":null,"source":"clob_market_ws"}
{"event_at":"2026-07-28T02:06:01.574000Z","event_fingerprint":"fa01cdd8571c37dbe5f5f1a1650d3629a660b40718819c718ec7cda776e7e03f","payload":{"connection_id":"5d29200f65794d4d9ab6ef271f045a9b","event_at":"2026-07-28T02:06:01.574000Z","event_type":"price_change","frame_hash":"60ef738031f0bf419a810a7698ca9527260451973b1d259d44fcf924ac6ec6b7","frame_index":0,"kind":"data","monotonic_ns":306344883594000,"payload":{"event_type":"price_change","market":"0xda6f0e0e93fc8469e0159a166028d017bddbc162b86f66bac90391379603d962","price_changes":[{"asset_id":"39272994714739463168905443499424551362424437245880253267329605556587274644733","best_ask":"0.74","best_bid":"0.73","hash":"1d9f79b395796ee5c73545d7c7e62718d6b3bdd7","price":"0.71","side":"BUY","size":"82.2"},{"asset_id":"20893381255801015515826997628594359667013752732428989472914000440642900266717","best_ask":"0.27","best_bid":"0.26","hash":"f0a3b4470aa2beca4fa959b39b4b5266f7c52775","price":"0.29","side":"SELL","size":"82.2"}],"timestamp":"1785204361574"},"payload_hash":"070c4aa139f1970aa47f35fc9095d8ed985a3fd2165e2370bf34b032bad73735","raw_frame":"{\"market\":\"0xda6f0e0e93fc8469e0159a166028d017bddbc162b86f66bac90391379603d962\", \"price_changes\":[{\"asset_id\":\"39272994714739463168905443499424551362424437245880253267329605556587274644733\", \"price\":\"0.71\", \"size\":\"82.2\", \"side\":\"BUY\", \"hash\":\"1d9f79b395796ee5c73545d7c7e62718d6b3bdd7\", \"best_bid\":\"0.73\", \"best_ask\":\"0.74\"}, {\"asset_id\":\"20893381255801015515826997628594359667013752732428989472914000440642900266717\", \"price\":\"0.29\", \"size\":\"82.2\", \"side\":\"SELL\", \"hash\":\"f0a3b4470aa2beca4fa959b39b4b5266f7c52775\", \"best_bid\":\"0.26\", \"best_ask\":\"0.27\"}], \"timestamp\":\"1785204361574\", \"event_type\":\"price_change\"}","received_at":"2026-07-28T02:06:01.876960Z","schema_version":"clob-market-ws.price_change.v1","sequence":null,"server_hash":null,"server_timestamp":"1785204361574","session_id":"d2757dd6dad94f3b9fe67e8dbf1adc37","source":"clob_market_ws"},"received_at":"2026-07-28T02:06:01.876960Z","record_id":"7daeb84c1d246f490864a2e9533e03136510e73a50560d2dea1e40307134831b","schema_fingerprint":"4aa3821a28b0b7c2400bc59aba4bcc0a76e971dadd19610d3ad38c768e124dc7","schema_version":"edge-lab-recorder.raw.v1","sequence":null,"source":"clob_market_ws"}
{"event_at":"2026-07-28T02:06:01.576000Z","event_fingerprint":"53996c2338707166ac23ef6031c6395a0c2d760ec1d9c1a255e1379639a9b441","payload":{"connection_id":"5d29200f65794d4d9ab6ef271f045a9b","event_at":"2026-07-28T02:06:01.576000Z","event_type":"price_change","frame_hash":"e93ed6f761a0883581001e06a529fe8be372e20a44bc20305cf4eac0aa7c662b","frame_index":0,"kind":"data","monotonic_ns":306344887789750,"payload":{"event_type":"price_change","market":"0xda6f0e0e93fc8469e0159a166028d017bddbc162b86f66bac90391379603d962","price_changes":[{"asset_id":"39272994714739463168905443499424551362424437245880253267329605556587274644733","best_ask":"0.74","best_bid":"0.73","hash":"7003a8a1ef3af977ff0f91f6032df4d3835cdd70","price":"0.71","side":"BUY","size":"75.2"},{"asset_id":"20893381255801015515826997628594359667013752732428989472914000440642900266717","best_ask":"0.27","best_bid":"0.26","hash":"6c119e336e055af5b17386b00bf4fe1bfc373f10","price":"0.29","side":"SELL","size":"75.2"}],"timestamp":"1785204361576"},"payload_hash":"17c877d432ae8b97e605238bce3d17e61bf03f36f9765ba694559ef9899f3107","raw_frame":"{\"market\":\"0xda6f0e0e93fc8469e0159a166028d017bddbc162b86f66bac90391379603d962\", \"price_changes\":[{\"asset_id\":\"39272994714739463168905443499424551362424437245880253267329605556587274644733\", \"price\":\"0.71\", \"size\":\"75.2\", \"side\":\"BUY\", \"hash\":\"7003a8a1ef3af977ff0f91f6032df4d3835cdd70\", \"best_bid\":\"0.73\", \"best_ask\":\"0.74\"}, {\"asset_id\":\"20893381255801015515826997628594359667013752732428989472914000440642900266717\", \"price\":\"0.29\", \"size\":\"75.2\", \"side\":\"SELL\", \"hash\":\"6c119e336e055af5b17386b00bf4fe1bfc373f10\", \"best_bid\":\"0.26\", \"best_ask\":\"0.27\"}], \"timestamp\":\"1785204361576\", \"event_type\":\"price_change\"}","received_at":"2026-07-28T02:06:01.881157Z","schema_version":"clob-market-ws.price_change.v1","sequence":null,"server_hash":null,"server_timestamp":"1785204361576","session_id":"d2757dd6dad94f3b9fe67e8dbf1adc37","source":"clob_market_ws"},"received_at":"2026-07-28T02:06:01.881157Z","record_id":"0ed5933089ce589082e5392caade41cc0ea02d26551abfab560503652baedb0d","schema_fingerprint":"4aa3821a28b0b7c2400bc59aba4bcc0a76e971dadd19610d3ad38c768e124dc7","schema_version":"edge-lab-recorder.raw.v1","sequence":null,"source":"clob_market_ws"}
{"event_at":"2026-07-28T02:06:01.580000Z","event_fingerprint":"fdcaf1ef6953e43c7025aa7d5c9ff7d9647e1b25e6ac1ad96ef178868f4beb43","payload":{"connection_id":"5d29200f65794d4d9ab6ef271f045a9b","event_at":"2026-07-28T02:06:01.580000Z","event_type":"price_change","frame_hash":"df8010638d0c8428cce7e6c8262cf9be5a53f8b662e02d6ffdaf8caa6f928b28","frame_index":0,"kind":"data","monotonic_ns":306344892006833,"payload":{"event_type":"price_change","market":"0xda6f0e0e93fc8469e0159a166028d017bddbc162b86f66bac90391379603d962","price_changes":[{"asset_id":"39272994714739463168905443499424551362424437245880253267329605556587274644733","best_ask":"0.74","best_bid":"0.73","hash":"14a94c807e9bb5d97c025e7f8614638f6f9408f4","price":"0.7","side":"BUY","size":"138.2"},{"asset_id":"20893381255801015515826997628594359667013752732428989472914000440642900266717","best_ask":"0.27","best_bid":"0.26","hash":"f18af8b77ec6104fc0568394dd073f7d557ec11c","price":"0.3","side":"SELL","size":"138.2"}],"timestamp":"1785204361580"},"payload_hash":"318b528c384a6ba5ee1432d287a41420de6dd892fbc73404e33dd8d033bb9e3a","raw_frame":"{\"market\":\"0xda6f0e0e93fc8469e0159a166028d017bddbc162b86f66bac90391379603d962\", \"price_changes\":[{\"asset_id\":\"39272994714739463168905443499424551362424437245880253267329605556587274644733\", \"price\":\"0.7\", \"size\":\"138.2\", \"side\":\"BUY\", \"hash\":\"14a94c807e9bb5d97c025e7f8614638f6f9408f4\", \"best_bid\":\"0.73\", \"best_ask\":\"0.74\"}, {\"asset_id\":\"20893381255801015515826997628594359667013752732428989472914000440642900266717\", \"price\":\"0.3\", \"size\":\"138.2\", \"side\":\"SELL\", \"hash\":\"f18af8b77ec6104fc0568394dd073f7d557ec11c\", \"best_bid\":\"0.26\", \"best_ask\":\"0.27\"}], \"timestamp\":\"1785204361580\", \"event_type\":\"price_change\"}","received_at":"2026-07-28T02:06:01.885373Z","schema_version":"clob-market-ws.price_change.v1","sequence":null,"server_hash":null,"server_timestamp":"1785204361580","session_id":"d2757dd6dad94f3b9fe67e8dbf1adc37","source":"clob_market_ws"},"received_at":"2026-07-28T02:06:01.885373Z","record_id":"2b1e914c2120058cedcbfaddc010afa9952e3f28a87ac60c26dd7edd4cb87d77","schema_fingerprint":"4aa3821a28b0b7c2400bc59aba4bcc0a76e971dadd19610d3ad38c768e124dc7","schema_version":"edge-lab-recorder.raw.v1","sequence":null,"source":"clob_market_ws"}
{"event_at":"2026-07-28T02:06:01.588000Z","event_fingerprint":"ded0a02b2d8ea976e8b47e2830bc2511944058768268c8961defc48739824d4e","payload":{"connection_id":"5d29200f65794d4d9ab6ef271f045a9b","event_at":"2026-07-28T02:06:01.588000Z","event_type":"best_bid_ask","frame_hash":"ae84b114239bde956c6eb267077f11dc46d7bb94efaf320168d43cbe6daa7a28","frame_index":0,"kind":"data","monotonic_ns":306344897162666,"payload":{"asset_id":"20893381255801015515826997628594359667013752732428989472914000440642900266717","best_ask":"0.28","best_bid":"0.26","event_type":"best_bid_ask","market":"0xda6f0e0e93fc8469e0159a166028d017bddbc162b86f66bac90391379603d962","spread":"0.02","timestamp":"1785204361588"},"payload_hash":"d0dca1dff4393910bc79148979780b0df1adb74c3180991f04681f3853780c74","raw_frame":"{\"market\":\"0xda6f0e0e93fc8469e0159a166028d017bddbc162b86f66bac90391379603d962\", \"asset_id\":\"20893381255801015515826997628594359667013752732428989472914000440642900266717\", \"best_bid\":\"0.26\", \"best_ask\":\"0.28\", \"spread\":\"0.02\", \"timestamp\":\"1785204361588\", \"event_type\":\"best_bid_ask\"}","received_at":"2026-07-28T02:06:01.890528Z","schema_version":"clob-market-ws.best_bid_ask.v1","sequence":null,"server_hash":null,"server_timestamp":"1785204361588","session_id":"d2757dd6dad94f3b9fe67e8dbf1adc37","source":"clob_market_ws"},"received_at":"2026-07-28T02:06:01.890528Z","record_id":"9cb2b7e695644cae31d802a0866ebef68c6d3523df8c56de827f071d6362fc5f","schema_fingerprint":"8488399f31b0337811b13b266be932db7062827c2470b78bd8e9e99bab51d17d","schema_version":"edge-lab-recorder.raw.v1","sequence":null,"source":"clob_market_ws"}
{"event_at":"2026-07-28T02:06:01.588000Z","event_fingerprint":"203ee84a6a080cebc1258bdb8626e852dd06a9b0da834f7c215572d19a2590cb","payload":{"connection_id":"5d29200f65794d4d9ab6ef271f045a9b","event_at":"2026-07-28T02:06:01.588000Z","event_type":"best_bid_ask","frame_hash":"89c63453a1a3ba1b6365718cb8f49b8aca9371954ce68baca3f2f47c10d7cc98","frame_index":0,"kind":"data","monotonic_ns":306344901143500,"payload":{"asset_id":"39272994714739463168905443499424551362424437245880253267329605556587274644733","best_ask":"0.74","best_bid":"0.72","event_type":"best_bid_ask","market":"0xda6f0e0e93fc8469e0159a166028d017bddbc162b86f66bac90391379603d962","spread":"0.02","timestamp":"1785204361588"},"payload_hash":"fe33a0d78a7febfa8113057bf1ffa20339e15055baf20f6db0b2879bb0ec2382","raw_frame":"{\"market\":\"0xda6f0e0e93fc8469e0159a166028d017bddbc162b86f66bac90391379603d962\", \"asset_id\":\"39272994714739463168905443499424551362424437245880253267329605556587274644733\", \"best_bid\":\"0.72\", \"best_ask\":\"0.74\", \"spread\":\"0.02\", \"timestamp\":\"1785204361588\", \"event_type\":\"best_bid_ask\"}","received_at":"2026-07-28T02:06:01.894508Z","schema_version":"clob-market-ws.best_bid_ask.v1","sequence":null,"server_hash":null,"server_timestamp":"1785204361588","session_id":"d2757dd6dad94f3b9fe67e8dbf1adc37","source":"clob_market_ws"},"received_at":"2026-07-28T02:06:01.894508Z","record_id":"2be670230dd3f94c9ce604875fb20c4d29408e7f8f8d09df4042e40e79cc904a","schema_fingerprint":"8488399f31b0337811b13b266be932db7062827c2470b78bd8e9e99bab51d17d","schema_version":"edge-lab-recorder.raw.v1","sequence":null,"source":"clob_market_ws"}
{"event_at":"2026-07-28T02:06:01.588000Z","event_fingerprint":"f34aec8dc45d557efd8020354b308624aeca0e9ff7110a50522e4d7810bcb5c5","payload":{"connection_id":"5d29200f65794d4d9ab6ef271f045a9b","event_at":"2026-07-28T02:06:01.588000Z","event_type":"price_change","frame_hash":"b928c064090b6517018fdd8da11f21adb22a189a220f3b494efd6d64b65d40e6","frame_index":0,"kind":"data","monotonic_ns":306344905029291,"payload":{"event_type":"price_change","market":"0xda6f0e0e93fc8469e0159a166028d017bddbc162b86f66bac90391379603d962","price_changes":[{"asset_id":"39272994714739463168905443499424551362424437245880253267329605556587274644733","best_ask":"0.74","best_bid":"0.72","hash":"b4d61dc098084ae8874ca03b4acad809ab7ede8e","price":"0.73","side":"BUY","size":"0"},{"asset_id":"20893381255801015515826997628594359667013752732428989472914000440642900266717","best_ask":"0.28","best_bid":"0.26","hash":"345416affa5cbd9a606ead24a81938595388d602","price":"0.27","side":"SELL","size":"0"}],"timestamp":"1785204361588"},"payload_hash":"988aa93e4b0c4df1e709b023c64dc3b362250c4c01475d208e0fcc13131dd133","raw_frame":"{\"market\":\"0xda6f0e0e93fc8469e0159a166028d017bddbc162b86f66bac90391379603d962\", \"price_changes\":[{\"asset_id\":\"39272994714739463168905443499424551362424437245880253267329605556587274644733\", \"price\":\"0.73\", \"size\":\"0\", \"side\":\"BUY\", \"hash\":\"b4d61dc098084ae8874ca03b4acad809ab7ede8e\", \"best_bid\":\"0.72\", \"best_ask\":\"0.74\"}, {\"asset_id\":\"20893381255801015515826997628594359667013752732428989472914000440642900266717\", \"price\":\"0.27\", \"size\":\"0\", \"side\":\"SELL\", \"hash\":\"345416affa5cbd9a606ead24a81938595388d602\", \"best_bid\":\"0.26\", \"best_ask\":\"0.28\"}], \"timestamp\":\"1785204361588\", \"event_type\":\"price_change\"}","received_at":"2026-07-28T02:06:01.898395Z","schema_version":"clob-market-ws.price_change.v1","sequence":null,"server_hash":null,"server_timestamp":"1785204361588","session_id":"d2757dd6dad94f3b9fe67e8dbf1adc37","source":"clob_market_ws"},"received_at":"2026-07-28T02:06:01.898395Z","record_id":"9732d9f74e8c8d47a0ab8410053c63399579338f29708b79f6798ff937ebd4ef","schema_fingerprint":"4aa3821a28b0b7c2400bc59aba4bcc0a76e971dadd19610d3ad38c768e124dc7","schema_version":"edge-lab-recorder.raw.v1","sequence":null,"source":"clob_market_ws"}
{"event_at":"2026-07-28T02:06:01.590000Z","event_fingerprint":"6e61eb689e1014e1b88ea8c72f9f45c3afff1302f52a10851ced5d2fed7eb5aa","payload":{"connection_id":"5d29200f65794d4d9ab6ef271f045a9b","event_at":"2026-07-28T02:06:01.590000Z","event_type":"price_change","frame_hash":"f3b2b16e563b5b27204166dd1b0752e64991fcacfc9dc668e160d2da6982b01b","frame_index":0,"kind":"data","monotonic_ns":306344908705250,"payload":{"event_type":"price_change","market":"0xda6f0e0e93fc8469e0159a166028d017bddbc162b86f66bac90391379603d962","price_changes":[{"asset_id":"39272994714739463168905443499424551362424437245880253267329605556587274644733","best_ask":"0.74","best_bid":"0.72","hash":"f1f75ebec02c13a364c6d55dcb2ad3dcd13ca248","price":"0.72","side":"BUY","size":"46.2"},{"asset_id":"20893381255801015515826997628594359667013752732428989472914000440642900266717","best_ask":"0.28","best_bid":"0.26","hash":"33ae09d564c3976bb02995ccbe62ec0848d3d0e5","price":"0.28","side":"SELL","size":"46.2"}],"timestamp":"1785204361590"},"payload_hash":"9ba1c3855ac3f5188eb1cdd508322e565b379d6584196e1195f166f8933afcd1","raw_frame":"{\"market\":\"0xda6f0e0e93fc8469e0159a166028d017bddbc162b86f66bac90391379603d962\", \"price_changes\":[{\"asset_id\":\"39272994714739463168905443499424551362424437245880253267329605556587274644733\", \"price\":\"0.72\", \"size\":\"46.2\", \"side\":\"BUY\", \"hash\":\"f1f75ebec02c13a364c6d55dcb2ad3dcd13ca248\", \"best_bid\":\"0.72\", \"best_ask\":\"0.74\"}, {\"asset_id\":\"20893381255801015515826997628594359667013752732428989472914000440642900266717\", \"price\":\"0.28\", \"size\":\"46.2\", \"side\":\"SELL\", \"hash\":\"33ae09d564c3976bb02995ccbe62ec0848d3d0e5\", \"best_bid\":\"0.26\", \"best_ask\":\"0.28\"}], \"timestamp\":\"1785204361590\", \"event_type\":\"price_change\"}","received_at":"2026-07-28T02:06:01.902072Z","schema_version":"clob-market-ws.price_change.v1","sequence":null,"server_hash":null,"server_timestamp":"1785204361590","session_id":"d2757dd6dad94f3b9fe67e8dbf1adc37","source":"clob_market_ws"},"received_at":"2026-07-28T02:06:01.902072Z","record_id":"c076078e546cc6cc07931fe76167e98cda42d4503105185b885dfd329faf9d74","schema_fingerprint":"4aa3821a28b0b7c2400bc59aba4bcc0a76e971dadd19610d3ad38c768e124dc7","schema_version":"edge-lab-recorder.raw.v1","sequence":null,"source":"clob_market_ws"}
{"event_at":"2026-07-28T02:06:01.593000Z","event_fingerprint":"5a702f4a27085b8c92c316ffa9da6d515c0fbb50361c2d27741f30f1662dff8c","payload":{"connection_id":"5d29200f65794d4d9ab6ef271f045a9b","event_at":"2026-07-28T02:06:01.593000Z","event_type":"price_change","frame_hash":"b9f5c412f200a54d150346e99778044fe58cf80c1bef18df0bb5a2e00368f6fc","frame_index":0,"kind":"data","monotonic_ns":306344912807708,"payload":{"event_type":"price_change","market":"0xda6f0e0e93fc8469e0159a166028d017bddbc162b86f66bac90391379603d962","price_changes":[{"asset_id":"39272994714739463168905443499424551362424437245880253267329605556587274644733","best_ask":"0.74","best_bid":"0.72","hash":"8f853d9b945c56efab4c6b774c08559a787997a9","price":"0.72","side":"BUY","size":"31.2"},{"asset_id":"20893381255801015515826997628594359667013752732428989472914000440642900266717","best_ask":"0.28","best_bid":"0.26","hash":"ec11cf0ff657fb8acd97ace7d709a8d1c6606293","price":"0.28","side":"SELL","size":"31.2"}],"timestamp":"1785204361593"},"payload_hash":"591bf9ea0ba589c6dce7e60bb0ad8844727ad805e7baf813691ef8e533a1bebc","raw_frame":"{\"market\":\"0xda6f0e0e93fc8469e0159a166028d017bddbc162b86f66bac90391379603d962\", \"price_changes\":[{\"asset_id\":\"39272994714739463168905443499424551362424437245880253267329605556587274644733\", \"price\":\"0.72\", \"size\":\"31.2\", \"side\":\"BUY\", \"hash\":\"8f853d9b945c56efab4c6b774c08559a787997a9\", \"best_bid\":\"0.72\", \"best_ask\":\"0.74\"}, {\"asset_id\":\"20893381255801015515826997628594359667013752732428989472914000440642900266717\", \"price\":\"0.28\", \"size\":\"31.2\", \"side\":\"SELL\", \"hash\":\"ec11cf0ff657fb8acd97ace7d709a8d1c6606293\", \"best_bid\":\"0.26\", \"best_ask\":\"0.28\"}], \"timestamp\":\"1785204361593\", \"event_type\":\"price_change\"}","received_at":"2026-07-28T02:06:01.906174Z","schema_version":"clob-market-ws.price_change.v1","sequence":null,"server_hash":null,"server_timestamp":"1785204361593","session_id":"d2757dd6dad94f3b9fe67e8dbf1adc37","source":"clob_market_ws"},"received_at":"2026-07-28T02:06:01.906174Z","record_id":"268c73b791e861b0fd98d18af5c6e95a8442f7d84136bb743da409a1ef2ee08d","schema_fingerprint":"4aa3821a28b0b7c2400bc59aba4bcc0a76e971dadd19610d3ad38c768e124dc7","schema_version":"edge-lab-recorder.raw.v1","sequence":null,"source":"clob_market_ws"}
{"event_at":"2026-07-28T02:06:01.595000Z","event_fingerprint":"964612c6a2c7052136d0487500e0264c2d223c44292ae5b8075faee433152f1b","payload":{"connection_id":"5d29200f65794d4d9ab6ef271f045a9b","event_at":"2026-07-28T02:06:01.595000Z","event_type":"price_change","frame_hash":"6f14e96070593d32ab8f7ce4a7f676850bb242f0abb0d8a5ef263d69bbcb6e2c","frame_index":0,"kind":"data","monotonic_ns":306344916652750,"payload":{"event_type":"price_change","market":"0xda6f0e0e93fc8469e0159a166028d017bddbc162b86f66bac90391379603d962","price_changes":[{"asset_id":"39272994714739463168905443499424551362424437245880253267329605556587274644733","best_ask":"0.74","best_bid":"0.72","hash":"caba8d45aebf4b684753813efa3398af7da22bbf","price":"0.64","side":"BUY","size":"122"},{"asset_id":"20893381255801015515826997628594359667013752732428989472914000440642900266717","best_ask":"0.28","best_bid":"0.26","hash":"e06056013c33856b0ee816665918de5b0598fa18","price":"0.36","side":"SELL","size":"122"}],"timestamp":"1785204361595"},"payload_hash":"831c17fca6c17494548eb5572fc8e0d6b48e5724fcb48ba32c3de3d22f2601bf","raw_frame":"{\"market\":\"0xda6f0e0e93fc8469e0159a166028d017bddbc162b86f66bac90391379603d962\", \"price_changes\":[{\"asset_id\":\"39272994714739463168905443499424551362424437245880253267329605556587274644733\", \"price\":\"0.64\", \"size\":\"122\", \"side\":\"BUY\", \"hash\":\"caba8d45aebf4b684753813efa3398af7da22bbf\", \"best_bid\":\"0.72\", \"best_ask\":\"0.74\"}, {\"asset_id\":\"20893381255801015515826997628594359667013752732428989472914000440642900266717\", \"price\":\"0.36\", \"size\":\"122\", \"side\":\"SELL\", \"hash\":\"e06056013c33856b0ee816665918de5b0598fa18\", \"best_bid\":\"0.26\", \"best_ask\":\"0.28\"}], \"timestamp\":\"1785204361595\", \"event_type\":\"price_change\"}","received_at":"2026-07-28T02:06:01.910019Z","schema_version":"clob-market-ws.price_change.v1","sequence":null,"server_hash":null,"server_timestamp":"1785204361595","session_id":"d2757dd6dad94f3b9fe67e8dbf1adc37","source":"clob_market_ws"},"received_at":"2026-07-28T02:06:01.910019Z","record_id":"5f115d1ef42e4b607918a25aed97c6ec6b7c5f8cd6cfb87a1d2ea2a429947b28","schema_fingerprint":"4aa3821a28b0b7c2400bc59aba4bcc0a76e971dadd19610d3ad38c768e124dc7","schema_version":"edge-lab-recorder.raw.v1","sequence":null,"source":"clob_market_ws"}
{"event_at":"2026-07-28T02:06:01.602000Z","event_fingerprint":"c34ad6eed90e8c8a5f99c380bda175747e09a284ee468ab02cd086468f0dd3ff","payload":{"connection_id":"5d29200f65794d4d9ab6ef271f045a9b","event_at":"2026-07-28T02:06:01.602000Z","event_type":"price_change","frame_hash":"12b031f2cd2d802898780fd9b2eebbff8a99f278f6a338f6ae0f43899f33038c","frame_index":0,"kind":"data","monotonic_ns":306344921060666,"payload":{"event_type":"price_change","market":"0xda6f0e0e93fc8469e0159a166028d017bddbc162b86f66bac90391379603d962","price_changes":[{"asset_id":"20893381255801015515826997628594359667013752732428989472914000440642900266717","best_ask":"0.28","best_bid":"0.26","hash":"f0bf181b377971b3c9f065ad2debba20bc3f3bfe","price":"0.03","side":"BUY","size":"662.1"},{"asset_id":"39272994714739463168905443499424551362424437245880253267329605556587274644733","best_ask":"0.74","best_bid":"0.72","hash":"8bc6edafbf356a0ed26b1da1f111608376043535","price":"0.97","side":"SELL","size":"662.1"}],"timestamp":"1785204361602"},"payload_hash":"1210d5d5c5b574f27696bc599ef9c157015fafd3c778687805a0a9e95a2bd25d","raw_frame":"{\"market\":\"0xda6f0e0e93fc8469e0159a166028d017bddbc162b86f66bac90391379603d962\", \"price_changes\":[{\"asset_id\":\"20893381255801015515826997628594359667013752732428989472914000440642900266717\", \"price\":\"0.03\", \"size\":\"662.1\", \"side\":\"BUY\", \"hash\":\"f0bf181b377971b3c9f065ad2debba20bc3f3bfe\", \"best_bid\":\"0.26\", \"best_ask\":\"0.28\"}, {\"asset_id\":\"39272994714739463168905443499424551362424437245880253267329605556587274644733\", \"price\":\"0.97\", \"size\":\"662.1\", \"side\":\"SELL\", \"hash\":\"8bc6edafbf356a0ed26b1da1f111608376043535\", \"best_bid\":\"0.72\", \"best_ask\":\"0.74\"}], \"timestamp\":\"1785204361602\", \"event_type\":\"price_change\"}","received_at":"2026-07-28T02:06:01.914427Z","schema_version":"clob-market-ws.price_change.v1","sequence":null,"server_hash":null,"server_timestamp":"1785204361602","session_id":"d2757dd6dad94f3b9fe67e8dbf1adc37","source":"clob_market_ws"},"received_at":"2026-07-28T02:06:01.914427Z","record_id":"5f3229a053eb796e5d2e0203b32042e055d4c610001586718363ee40a4d78778","schema_fingerprint":"4aa3821a28b0b7c2400bc59aba4bcc0a76e971dadd19610d3ad38c768e124dc7","schema_version":"edge-lab-recorder.raw.v1","sequence":null,"source":"clob_market_ws"}
{"event_at":"2026-07-28T02:06:01.603000Z","event_fingerprint":"77467855d71af45f0688f1c20e4b70a33f36ac17879ee30e098a15b5ae7f4c85","payload":{"connection_id":"5d29200f65794d4d9ab6ef271f045a9b","event_at":"2026-07-28T02:06:01.603000Z","event_type":"price_change","frame_hash":"46019a7efd0ee1b26d9e43d9ce85c38e3824303bf8bf3129cc9b79a8e2332423","frame_index":0,"kind":"data","monotonic_ns":306344925346125,"payload":{"event_type":"price_change","market":"0xda6f0e0e93fc8469e0159a166028d017bddbc162b86f66bac90391379603d962","price_changes":[{"asset_id":"39272994714739463168905443499424551362424437245880253267329605556587274644733","best_ask":"0.74","best_bid":"0.72","hash":"98d389fd1122c1ba40c70de5a0a979f826953419","price":"0.68","side":"BUY","size":"87"},{"asset_id":"20893381255801015515826997628594359667013752732428989472914000440642900266717","best_ask":"0.28","best_bid":"0.26","hash":"250e0de6b76c1bc011e0f26ae17f95e22de7a566","price":"0.32","side":"SELL","size":"87"}],"timestamp":"1785204361603"},"payload_hash":"fda26016769af2de06f54678688737e8cc11b5c3352ae65a39861c867252e458","raw_frame":"{\"market\":\"0xda6f0e0e93fc8469e0159a166028d017bddbc162b86f66bac90391379603d962\", \"price_changes\":[{\"asset_id\":\"39272994714739463168905443499424551362424437245880253267329605556587274644733\", \"price\":\"0.68\", \"size\":\"87\", \"side\":\"BUY\", \"hash\":\"98d389fd1122c1ba40c70de5a0a979f826953419\", \"best_bid\":\"0.72\", \"best_ask\":\"0.74\"}, {\"asset_id\":\"20893381255801015515826997628594359667013752732428989472914000440642900266717\", \"price\":\"0.32\", \"size\":\"87\", \"side\":\"SELL\", \"hash\":\"250e0de6b76c1bc011e0f26ae17f95e22de7a566\", \"best_bid\":\"0.26\", \"best_ask\":\"0.28\"}], \"timestamp\":\"1785204361603\", \"event_type\":\"price_change\"}","received_at":"2026-07-28T02:06:01.918712Z","schema_version":"clob-market-ws.price_change.v1","sequence":null,"server_hash":null,"server_timestamp":"1785204361603","session_id":"d2757dd6dad94f3b9fe67e8dbf1adc37","source":"clob_market_ws"},"received_at":"2026-07-28T02:06:01.918712Z","record_id":"4e3574928574c7da31d1b4ed3fcf17d5dbd74ea3a5cafe7cfac9318d2774db31","schema_fingerprint":"4aa3821a28b0b7c2400bc59aba4bcc0a76e971dadd19610d3ad38c768e124dc7","schema_version":"edge-lab-recorder.raw.v1","sequence":null,"source":"clob_market_ws"}
{"event_at":"2026-07-28T02:06:01.604000Z","event_fingerprint":"c1b2441d3516a7d10cc9cb431a80b1af8d9f7333a2e65d8af4120702a9e43454","payload":{"connection_id":"5d29200f65794d4d9ab6ef271f045a9b","event_at":"2026-07-28T02:06:01.604000Z","event_type":"best_bid_ask","frame_hash":"35cf7d097ddb778224522b16c309810e84bb96d4afa4c628681e14b37dccfd31","frame_index":0,"kind":"data","monotonic_ns":306344935241083,"payload":{"asset_id":"20893381255801015515826997628594359667013752732428989472914000440642900266717","best_ask":"0.28","best_bid":"0.27","event_type":"best_bid_ask","market":"0xda6f0e0e93fc8469e0159a166028d017bddbc162b86f66bac90391379603d962","spread":"0.01","timestamp":"1785204361604"},"payload_hash":"6b6583d72d9291997d0f2c4c09ca22e9f778f8145e7aede927dbc02608dcb777","raw_frame":"{\"market\":\"0xda6f0e0e93fc8469e0159a166028d017bddbc162b86f66bac90391379603d962\", \"asset_id\":\"20893381255801015515826997628594359667013752732428989472914000440642900266717\", \"best_bid\":\"0.27\", \"best_ask\":\"0.28\", \"spread\":\"0.01\", \"timestamp\":\"1785204361604\", \"event_type\":\"best_bid_ask\"}","received_at":"2026-07-28T02:06:01.928606Z","schema_version":"clob-market-ws.best_bid_ask.v1","sequence":null,"server_hash":null,"server_timestamp":"1785204361604","session_id":"d2757dd6dad94f3b9fe67e8dbf1adc37","source":"clob_market_ws"},"received_at":"2026-07-28T02:06:01.928606Z","record_id":"870058837fe5c61d7e98d60d7c5612df9b6842f5f2a84bd15b692b9cd1682629","schema_fingerprint":"8488399f31b0337811b13b266be932db7062827c2470b78bd8e9e99bab51d17d","schema_version":"edge-lab-recorder.raw.v1","sequence":null,"source":"clob_market_ws"}
{"event_at":"2026-07-28T02:06:01.604000Z","event_fingerprint":"a41a5b615a94670b906a9d7da1574253dafdf1e54941f3918db1dfda63320554","payload":{"connection_id":"5d29200f65794d4d9ab6ef271f045a9b","event_at":"2026-07-28T02:06:01.604000Z","event_type":"best_bid_ask","frame_hash":"dd6c6ea0033c36f9ca5d147851bb62726f9b898b8e25c5560ee73e84a371d8fd","frame_index":0,"kind":"data","monotonic_ns":306344939256041,"payload":{"asset_id":"39272994714739463168905443499424551362424437245880253267329605556587274644733","best_ask":"0.73","best_bid":"0.72","event_type":"best_bid_ask","market":"0xda6f0e0e93fc8469e0159a166028d017bddbc162b86f66bac90391379603d962","spread":"0.01","timestamp":"1785204361604"},"payload_hash":"7f767668a211bfcadc1f9347cc8659240e9ffaeeecf84bd4c27ab163411f7d26","raw_frame":"{\"market\":\"0xda6f0e0e93fc8469e0159a166028d017bddbc162b86f66bac90391379603d962\", \"asset_id\":\"39272994714739463168905443499424551362424437245880253267329605556587274644733\", \"best_bid\":\"0.72\", \"best_ask\":\"0.73\", \"spread\":\"0.01\", \"timestamp\":\"1785204361604\", \"event_type\":\"best_bid_ask\"}","received_at":"2026-07-28T02:06:01.932619Z","schema_version":"clob-market-ws.best_bid_ask.v1","sequence":null,"server_hash":null,"server_timestamp":"1785204361604","session_id":"d2757dd6dad94f3b9fe67e8dbf1adc37","source":"clob_market_ws"},"received_at":"2026-07-28T02:06:01.932619Z","record_id":"eec13c376e27fcb1f3a6ca2d9526c0a77eb01cbb57caba5100d09f5d5acd0043","schema_fingerprint":"8488399f31b0337811b13b266be932db7062827c2470b78bd8e9e99bab51d17d","schema_version":"edge-lab-recorder.raw.v1","sequence":null,"source":"clob_market_ws"}
{"event_at":"2026-07-28T02:06:01.604000Z","event_fingerprint":"85d73c53a2a8e8075e4032189b3ce72e771571520496161dc82d95233b0ab160","payload":{"connection_id":"5d29200f65794d4d9ab6ef271f045a9b","event_at":"2026-07-28T02:06:01.604000Z","event_type":"price_change","frame_hash":"1cf083935da0a7d26df15aa213ba36f7131b9f929a49adf41c62ac5c48fa17bf","frame_index":0,"kind":"data","monotonic_ns":306344945791583,"payload":{"event_type":"price_change","market":"0xda6f0e0e93fc8469e0159a166028d017bddbc162b86f66bac90391379603d962","price_changes":[{"asset_id":"20893381255801015515826997628594359667013752732428989472914000440642900266717","best_ask":"0.28","best_bid":"0.27","hash":"cae13728455620d0af1f3b8cfe972c70badeeb76","price":"0.27","side":"BUY","size":"15"},{"asset_id":"39272994714739463168905443499424551362424437245880253267329605556587274644733","best_ask":"0.73","best_bid":"0.72","hash":"90b73f7e8c5676fef33e0782038389eba98bf52e","price":"0.73","side":"SELL","size":"15"}],"timestamp":"1785204361604"},"payload_hash":"4921bffb0188c0190cd84bf5a616691f2aeb28feca91b0c83b01e754a5ba27ca","raw_frame":"{\"market\":\"0xda6f0e0e93fc8469e0159a166028d017bddbc162b86f66bac90391379603d962\", \"price_changes\":[{\"asset_id\":\"20893381255801015515826997628594359667013752732428989472914000440642900266717\", \"price\":\"0.27\", \"size\":\"15\", \"side\":\"BUY\", \"hash\":\"cae13728455620d0af1f3b8cfe972c70badeeb76\", \"best_bid\":\"0.27\", \"best_ask\":\"0.28\"}, {\"asset_id\":\"39272994714739463168905443499424551362424437245880253267329605556587274644733\", \"price\":\"0.73\", \"size\":\"15\", \"side\":\"SELL\", \"hash\":\"90b73f7e8c5676fef33e0782038389eba98bf52e\", \"best_bid\":\"0.72\", \"best_ask\":\"0.73\"}], \"timestamp\":\"1785204361604\", \"event_type\":\"price_change\"}","received_at":"2026-07-28T02:06:01.939158Z","schema_version":"clob-market-ws.price_change.v1","sequence":null,"server_hash":null,"server_timestamp":"1785204361604","session_id":"d2757dd6dad94f3b9fe67e8dbf1adc37","source":"clob_market_ws"},"received_at":"2026-07-28T02:06:01.939158Z","record_id":"2c0dc0e4861fcdc37c7cc950c8d2fca82e10988c528518abbf751dbac9beb372","schema_fingerprint":"4aa3821a28b0b7c2400bc59aba4bcc0a76e971dadd19610d3ad38c768e124dc7","schema_version":"edge-lab-recorder.raw.v1","sequence":null,"source":"clob_market_ws"}
{"event_at":"2026-07-28T02:06:01.606000Z","event_fingerprint":"5d345c14fc42e327d32e4531e2d6206c68a9b857ec19cb9a1d202553e7d59837","payload":{"connection_id":"5d29200f65794d4d9ab6ef271f045a9b","event_at":"2026-07-28T02:06:01.606000Z","event_type":"price_change","frame_hash":"00785bff295279b4bb3635e31f775514bfa8e1fbfb95fb4c131024a63fe4d8f9","frame_index":0,"kind":"data","monotonic_ns":306344950835333,"payload":{"event_type":"price_change","market":"0xda6f0e0e93fc8469e0159a166028d017bddbc162b86f66bac90391379603d962","price_changes":[{"asset_id":"20893381255801015515826997628594359667013752732428989472914000440642900266717","best_ask":"0.28","best_bid":"0.27","hash":"5b9aa95d17a7e7205e37bdd91b655dd64742ec27","price":"0.26","side":"BUY","size":"81"},{"asset_id":"39272994714739463168905443499424551362424437245880253267329605556587274644733","best_ask":"0.73","best_bid":"0.72","hash":"e8f5208c3212e0e1028ce10a885a8aecb097dc81","price":"0.74","side":"SELL","size":"81"}],"timestamp":"1785204361606"},"payload_hash":"0205e3f2aae12d88680f1aadb5c013a0440473598bf91a8034a4b8fda353b196","raw_frame":"{\"market\":\"0xda6f0e0e93fc8469e0159a166028d017bddbc162b86f66bac90391379603d962\", \"price_changes\":[{\"asset_id\":\"20893381255801015515826997628594359667013752732428989472914000440642900266717\", \"price\":\"0.26\", \"size\":\"81\", \"side\":\"BUY\", \"hash\":\"5b9aa95d17a7e7205e37bdd91b655dd64742ec27\", \"best_bid\":\"0.27\", \"best_ask\":\"0.28\"}, {\"asset_id\":\"39272994714739463168905443499424551362424437245880253267329605556587274644733\", \"price\":\"0.74\", \"size\":\"81\", \"side\":\"SELL\", \"hash\":\"e8f5208c3212e0e1028ce10a885a8aecb097dc81\", \"best_bid\":\"0.72\", \"best_ask\":\"0.73\"}], \"timestamp\":\"1785204361606\", \"event_type\":\"price_change\"}","received_at":"2026-07-28T02:06:01.944200Z","schema_version":"clob-market-ws.price_change.v1","sequence":null,"server_hash":null,"server_timestamp":"1785204361606","session_id":"d2757dd6dad94f3b9fe67e8dbf1adc37","source":"clob_market_ws"},"received_at":"2026-07-28T02:06:01.944200Z","record_id":"4f07d088321c11702171c89c655cdc789c5e6dd7f60ad045d75a7528c8c6c09e","schema_fingerprint":"4aa3821a28b0b7c2400bc59aba4bcc0a76e971dadd19610d3ad38c768e124dc7","schema_version":"edge-lab-recorder.raw.v1","sequence":null,"source":"clob_market_ws"}
{"event_at":"2026-07-28T02:06:01.606000Z","event_fingerprint":"5f1628708094ffc44473262156d130db50b3df4ea48124ee448cd57d9b41a25f","payload":{"connection_id":"5d29200f65794d4d9ab6ef271f045a9b","event_at":"2026-07-28T02:06:01.606000Z","event_type":"price_change","frame_hash":"a9750e21633022b418af727f9b20cf2c3040914411b861a9cc3ca9ac3e8b2ba6","frame_index":0,"kind":"data","monotonic_ns":306344954437291,"payload":{"event_type":"price_change","market":"0xda6f0e0e93fc8469e0159a166028d017bddbc162b86f66bac90391379603d962","price_changes":[{"asset_id":"39272994714739463168905443499424551362424437245880253267329605556587274644733","best_ask":"0.73","best_bid":"0.72","hash":"70654ebb83261a64e87bcd4dbcbeeea142a6caa1","price":"0.67","side":"BUY","size":"96"},{"asset_id":"20893381255801015515826997628594359667013752732428989472914000440642900266717","best_ask":"0.28","best_bid":"0.27","hash":"8333e60ac3bc5170abd82eff308621d893186225","price":"0.33","side":"SELL","size":"96"}],"timestamp":"1785204361606"},"payload_hash":"3261a9b3ccf699d35453beb33905ca77e752c4ca4d7a694a42eb0c20c42634ba","raw_frame":"{\"market\":\"0xda6f0e0e93fc8469e0159a166028d017bddbc162b86f66bac90391379603d962\", \"price_changes\":[{\"asset_id\":\"39272994714739463168905443499424551362424437245880253267329605556587274644733\", \"price\":\"0.67\", \"size\":\"96\", \"side\":\"BUY\", \"hash\":\"70654ebb83261a64e87bcd4dbcbeeea142a6caa1\", \"best_bid\":\"0.72\", \"best_ask\":\"0.73\"}, {\"asset_id\":\"20893381255801015515826997628594359667013752732428989472914000440642900266717\", \"price\":\"0.33\", \"size\":\"96\", \"side\":\"SELL\", \"hash\":\"8333e60ac3bc5170abd82eff308621d893186225\", \"best_bid\":\"0.27\", \"best_ask\":\"0.28\"}], \"timestamp\":\"1785204361606\", \"event_type\":\"price_change\"}","received_at":"2026-07-28T02:06:01.947803Z","schema_version":"clob-market-ws.price_change.v1","sequence":null,"server_hash":null,"server_timestamp":"1785204361606","session_id":"d2757dd6dad94f3b9fe67e8dbf1adc37","source":"clob_market_ws"},"received_at":"2026-07-28T02:06:01.947803Z","record_id":"632d7c530b5af37af7ad91193b28fb070348f8f56c6674f424317eb135be47c3","schema_fingerprint":"4aa3821a28b0b7c2400bc59aba4bcc0a76e971dadd19610d3ad38c768e124dc7","schema_version":"edge-lab-recorder.raw.v1","sequence":null,"source":"clob_market_ws"}
{"event_at":"2026-07-28T02:06:01.607000Z","event_fingerprint":"f11e3db74f3c02b207df0dc1df907851fe106cc08cdaab992243d291f4dfe2eb","payload":{"connection_id":"5d29200f65794d4d9ab6ef271f045a9b","event_at":"2026-07-28T02:06:01.607000Z","event_type":"price_change","frame_hash":"f14d2e70e66b8a1e6796020d82a1ba2c9b750321c651ff5fee7e806367fdeacb","frame_index":0,"kind":"data","monotonic_ns":306344960416416,"payload":{"event_type":"price_change","market":"0xda6f0e0e93fc8469e0159a166028d017bddbc162b86f66bac90391379603d962","price_changes":[{"asset_id":"39272994714739463168905443499424551362424437245880253267329605556587274644733","best_ask":"0.73","best_bid":"0.72","hash":"0b1e16311bac371b4acc8cd5b50ff8775f83d102","price":"0.72","side":"BUY","size":"25.2"},{"asset_id":"20893381255801015515826997628594359667013752732428989472914000440642900266717","best_ask":"0.28","best_bid":"0.27","hash":"154ac8f7a0f668fab7380f41b680abf066d2a5d2","price":"0.28","side":"SELL","size":"25.2"}],"timestamp":"1785204361607"},"payload_hash":"7e32c15bcb0d4bbe28902226c445293bfc8c7dacfe18853663f6d193bd009488","raw_frame":"{\"market\":\"0xda6f0e0e93fc8469e0159a166028d017bddbc162b86f66bac90391379603d962\", \"price_changes\":[{\"asset_id\":\"39272994714739463168905443499424551362424437245880253267329605556587274644733\", \"price\":\"0.72\", \"size\":\"25.2\", \"side\":\"BUY\", \"hash\":\"0b1e16311bac371b4acc8cd5b50ff8775f83d102\", \"best_bid\":\"0.72\", \"best_ask\":\"0.73\"}, {\"asset_id\":\"20893381255801015515826997628594359667013752732428989472914000440642900266717\", \"price\":\"0.28\", \"size\":\"25.2\", \"side\":\"SELL\", \"hash\":\"154ac8f7a0f668fab7380f41b680abf066d2a5d2\", \"best_bid\":\"0.27\", \"best_ask\":\"0.28\"}], \"timestamp\":\"1785204361607\", \"event_type\":\"price_change\"}","received_at":"2026-07-28T02:06:01.953782Z","schema_version":"clob-market-ws.price_change.v1","sequence":null,"server_hash":null,"server_timestamp":"1785204361607","session_id":"d2757dd6dad94f3b9fe67e8dbf1adc37","source":"clob_market_ws"},"received_at":"2026-07-28T02:06:01.953782Z","record_id":"ea90c62b9202cd0f76588a783cf1f9220abbf5423089d43fb1f77315585eb049","schema_fingerprint":"4aa3821a28b0b7c2400bc59aba4bcc0a76e971dadd19610d3ad38c768e124dc7","schema_version":"edge-lab-recorder.raw.v1","sequence":null,"source":"clob_market_ws"}
{"event_at":"2026-07-28T02:06:01.607000Z","event_fingerprint":"cd547e1b2caf57059449e612bbfc57f440fc4931ada81c7e388e7a6ec7b16ae8","payload":{"connection_id":"5d29200f65794d4d9ab6ef271f045a9b","event_at":"2026-07-28T02:06:01.607000Z","event_type":"price_change","frame_hash":"f6b37e8b3a2ec539ddacb85d46da351851249503832fe797cb3d225da8d5fab3","frame_index":0,"kind":"data","monotonic_ns":306344964627583,"payload":{"event_type":"price_change","market":"0xda6f0e0e93fc8469e0159a166028d017bddbc162b86f66bac90391379603d962","price_changes":[{"asset_id":"39272994714739463168905443499424551362424437245880253267329605556587274644733","best_ask":"0.73","best_bid":"0.72","hash":"396d9f4559fc0abe8a7d9a22765ac8f01aee53b3","price":"0.74","side":"SELL","size":"75"},{"asset_id":"20893381255801015515826997628594359667013752732428989472914000440642900266717","best_ask":"0.28","best_bid":"0.27","hash":"322c9a7017ae5a79db74e145b9a4758fffd51975","price":"0.26","side":"BUY","size":"75"}],"timestamp":"1785204361607"},"payload_hash":"6d50fc964a333aa7db062715974ad069bd4b81b963957c7dba08aa482f351f6c","raw_frame":"{\"market\":\"0xda6f0e0e93fc8469e0159a166028d017bddbc162b86f66bac90391379603d962\", \"price_changes\":[{\"asset_id\":\"39272994714739463168905443499424551362424437245880253267329605556587274644733\", \"price\":\"0.74\", \"size\":\"75\", \"side\":\"SELL\", \"hash\":\"396d9f4559fc0abe8a7d9a22765ac8f01aee53b3\", \"best_bid\":\"0.72\", \"best_ask\":\"0.73\"}, {\"asset_id\":\"20893381255801015515826997628594359667013752732428989472914000440642900266717\", \"price\":\"0.26\", \"size\":\"75\", \"side\":\"BUY\", \"hash\":\"322c9a7017ae5a79db74e145b9a4758fffd51975\", \"best_bid\":\"0.27\", \"best_ask\":\"0.28\"}], \"timestamp\":\"1785204361607\", \"event_type\":\"price_change\"}","received_at":"2026-07-28T02:06:01.957993Z","schema_version":"clob-market-ws.price_change.v1","sequence":null,"server_hash":null,"server_timestamp":"1785204361607","session_id":"d2757dd6dad94f3b9fe67e8dbf1adc37","source":"clob_market_ws"},"received_at":"2026-07-28T02:06:01.957993Z","record_id":"4fe4bc1113db7f3437ff21750372971f0e6f90cb91933c1382ca273980ee618c","schema_fingerprint":"4aa3821a28b0b7c2400bc59aba4bcc0a76e971dadd19610d3ad38c768e124dc7","schema_version":"edge-lab-recorder.raw.v1","sequence":null,"source":"clob_market_ws"}
{"event_at":"2026-07-28T02:06:01.608000Z","event_fingerprint":"1d993665198d3cf9e7ae947edafd11fea92902d759f114bc27a7ed3ef369e2ee","payload":{"connection_id":"5d29200f65794d4d9ab6ef271f045a9b","event_at":"2026-07-28T02:06:01.608000Z","event_type":"price_change","frame_hash":"0fa4b5707c755152325e1e89c8fa1c97527cdb2e93f5d90175d73fbcb1abd5da","frame_index":0,"kind":"data","monotonic_ns":306344969231166,"payload":{"event_type":"price_change","market":"0xda6f0e0e93fc8469e0159a166028d017bddbc162b86f66bac90391379603d962","price_changes":[{"asset_id":"39272994714739463168905443499424551362424437245880253267329605556587274644733","best_ask":"0.73","best_bid":"0.72","hash":"74a9f5495d64db537e555a7f9d386288e78b3fea","price":"0.68","side":"BUY","size":"117"},{"asset_id":"20893381255801015515826997628594359667013752732428989472914000440642900266717","best_ask":"0.28","best_bid":"0.27","hash":"b63299afd73b404d2d9e748917eee7d7486e781b","price":"0.32","side":"SELL","size":"117"}],"timestamp":"1785204361608"},"payload_hash":"30bd1bf67762250988639da60bd20330175e15c8871babe73b932235025d486e","raw_frame":"{\"market\":\"0xda6f0e0e93fc8469e0159a166028d017bddbc162b86f66bac90391379603d962\", \"price_changes\":[{\"asset_id\":\"39272994714739463168905443499424551362424437245880253267329605556587274644733\", \"price\":\"0.68\", \"size\":\"117\", \"side\":\"BUY\", \"hash\":\"74a9f5495d64db537e555a7f9d386288e78b3fea\", \"best_bid\":\"0.72\", \"best_ask\":\"0.73\"}, {\"asset_id\":\"20893381255801015515826997628594359667013752732428989472914000440642900266717\", \"price\":\"0.32\", \"size\":\"117\", \"side\":\"SELL\", \"hash\":\"b63299afd73b404d2d9e748917eee7d7486e781b\", \"best_bid\":\"0.27\", \"best_ask\":\"0.28\"}], \"timestamp\":\"1785204361608\", \"event_type\":\"price_change\"}","received_at":"2026-07-28T02:06:01.962596Z","schema_version":"clob-market-ws.price_change.v1","sequence":null,"server_hash":null,"server_timestamp":"1785204361608","session_id":"d2757dd6dad94f3b9fe67e8dbf1adc37","source":"clob_market_ws"},"received_at":"2026-07-28T02:06:01.962596Z","record_id":"cbf768fc494c64447e93625abb88d9eb89832e4602820a5ea504e7b9c98f7eb3","schema_fingerprint":"4aa3821a28b0b7c2400bc59aba4bcc0a76e971dadd19610d3ad38c768e124dc7","schema_version":"edge-lab-recorder.raw.v1","sequence":null,"source":"clob_market_ws"}
{"event_at":"2026-07-28T02:06:01.609000Z","event_fingerprint":"e69359a7a608bc5d1295ae6d6609d60c371d70ee71d8f09c129673eb4e50bbdf","payload":{"connection_id":"5d29200f65794d4d9ab6ef271f045a9b","event_at":"2026-07-28T02:06:01.609000Z","event_type":"price_change","frame_hash":"d1aa008a566aae479e5f71bc321492fb3aa65d3ce6798b74b1b37da0f3fc20c3","frame_index":0,"kind":"data","monotonic_ns":306344973570791,"payload":{"event_type":"price_change","market":"0xda6f0e0e93fc8469e0159a166028d017bddbc162b86f66bac90391379603d962","price_changes":[{"asset_id":"39272994714739463168905443499424551362424437245880253267329605556587274644733","best_ask":"0.73","best_bid":"0.72","hash":"f867c75153c0e0138fb9d57bbd25bedfc07b7336","price":"0.63","side":"BUY","size":"200"},{"asset_id":"20893381255801015515826997628594359667013752732428989472914000440642900266717","best_ask":"0.28","best_bid":"0.27","hash":"4bfbe4c168a50efc0f46207030a85b52ad62456f","price":"0.37","side":"SELL","size":"200"}],"timestamp":"1785204361609"},"payload_hash":"d0949d73d86ff5350bc88652cec8268898d3090d74c66632d89e77a2db9948ee","raw_frame":"{\"market\":\"0xda6f0e0e93fc8469e0159a166028d017bddbc162b86f66bac90391379603d962\", \"price_changes\":[{\"asset_id\":\"39272994714739463168905443499424551362424437245880253267329605556587274644733\", \"price\":\"0.63\", \"size\":\"200\", \"side\":\"BUY\", \"hash\":\"f867c75153c0e0138fb9d57bbd25bedfc07b7336\", \"best_bid\":\"0.72\", \"best_ask\":\"0.73\"}, {\"asset_id\":\"20893381255801015515826997628594359667013752732428989472914000440642900266717\", \"price\":\"0.37\", \"size\":\"200\", \"side\":\"SELL\", \"hash\":\"4bfbe4c168a50efc0f46207030a85b52ad62456f\", \"best_bid\":\"0.27\", \"best_ask\":\"0.28\"}], \"timestamp\":\"1785204361609\", \"event_type\":\"price_change\"}","received_at":"2026-07-28T02:06:01.966935Z","schema_version":"clob-market-ws.price_change.v1","sequence":null,"server_hash":null,"server_timestamp":"1785204361609","session_id":"d2757dd6dad94f3b9fe67e8dbf1adc37","source":"clob_market_ws"},"received_at":"2026-07-28T02:06:01.966935Z","record_id":"dbc6fbdc81361b0182e664f14ab9d1d90ec7b935a0f8a3cd089fbd6ccfa54216","schema_fingerprint":"4aa3821a28b0b7c2400bc59aba4bcc0a76e971dadd19610d3ad38c768e124dc7","schema_version":"edge-lab-recorder.raw.v1","sequence":null,"source":"clob_market_ws"}
{"event_at":"2026-07-28T02:06:01.612000Z","event_fingerprint":"01a0eda5523a82dd875c5d54911e55bf97465d70cd31d5e329d27d91073f2faa","payload":{"connection_id":"5d29200f65794d4d9ab6ef271f045a9b","event_at":"2026-07-28T02:06:01.612000Z","event_type":"price_change","frame_hash":"9ce2f78e70bd0e8fbca4c9c82841b277755b4608366ae07d1e94b710a5cf6554","frame_index":0,"kind":"data","monotonic_ns":306344977968083,"payload":{"event_type":"price_change","market":"0xda6f0e0e93fc8469e0159a166028d017bddbc162b86f66bac90391379603d962","price_changes":[{"asset_id":"20893381255801015515826997628594359667013752732428989472914000440642900266717","best_ask":"0.28","best_bid":"0.27","hash":"ecbb9c2e27cb768b3946fc8655c2e79700ee8524","price":"0.26","side":"BUY","size":"69"},{"asset_id":"39272994714739463168905443499424551362424437245880253267329605556587274644733","best_ask":"0.73","best_bid":"0.72","hash":"795bcaef0c9b64ef1c185b86af4ec2e07630521f","price":"0.74","side":"SELL","size":"69"}],"timestamp":"1785204361612"},"payload_hash":"50e5f1a810988c98be17b4436fe921755e67e8fb95df1ca83bbe163822e67b11","raw_frame":"{\"market\":\"0xda6f0e0e93fc8469e0159a166028d017bddbc162b86f66bac90391379603d962\", \"price_changes\":[{\"asset_id\":\"20893381255801015515826997628594359667013752732428989472914000440642900266717\", \"price\":\"0.26\", \"size\":\"69\", \"side\":\"BUY\", \"hash\":\"ecbb9c2e27cb768b3946fc8655c2e79700ee8524\", \"best_bid\":\"0.27\", \"best_ask\":\"0.28\"}, {\"asset_id\":\"39272994714739463168905443499424551362424437245880253267329605556587274644733\", \"price\":\"0.74\", \"size\":\"69\", \"side\":\"SELL\", \"hash\":\"795bcaef0c9b64ef1c185b86af4ec2e07630521f\", \"best_bid\":\"0.72\", \"best_ask\":\"0.73\"}], \"timestamp\":\"1785204361612\", \"event_type\":\"price_change\"}","received_at":"2026-07-28T02:06:01.971334Z","schema_version":"clob-market-ws.price_change.v1","sequence":null,"server_hash":null,"server_timestamp":"1785204361612","session_id":"d2757dd6dad94f3b9fe67e8dbf1adc37","source":"clob_market_ws"},"received_at":"2026-07-28T02:06:01.971334Z","record_id":"b757906c80dec5beab843a8e2963facc1173f591ca06451450ec2721e488e9a4","schema_fingerprint":"4aa3821a28b0b7c2400bc59aba4bcc0a76e971dadd19610d3ad38c768e124dc7","schema_version":"edge-lab-recorder.raw.v1","sequence":null,"source":"clob_market_ws"}
{"event_at":"2026-07-28T02:06:01.619000Z","event_fingerprint":"c8b4a2534ea734cf74cae34bcb1836d3bb1cce8690a3b0fe0260a69c55f5cb5f","payload":{"connection_id":"5d29200f65794d4d9ab6ef271f045a9b","event_at":"2026-07-28T02:06:01.619000Z","event_type":"price_change","frame_hash":"ad2bef7d80ca3e484318d5b1be373a7fcc68c044b15b3f9271d1a3754c5b4c21","frame_index":0,"kind":"data","monotonic_ns":306344982284291,"payload":{"event_type":"price_change","market":"0xda6f0e0e93fc8469e0159a166028d017bddbc162b86f66bac90391379603d962","price_changes":[{"asset_id":"39272994714739463168905443499424551362424437245880253267329605556587274644733","best_ask":"0.73","best_bid":"0.72","hash":"440e32f116178c40dcac9fb794d04de5598ef187","price":"0.03","side":"BUY","size":"643.1"},{"asset_id":"20893381255801015515826997628594359667013752732428989472914000440642900266717","best_ask":"0.28","best_bid":"0.27","hash":"f3c199fc10718f42cf1ad10eabb983210ae596e8","price":"0.97","side":"SELL","size":"643.1"}],"timestamp":"1785204361619"},"payload_hash":"c4a684ef8912052e8ff54408cecbfa1932fe98bfd3d3eb6582aeb43f5c0be647","raw_frame":"{\"market\":\"0xda6f0e0e93fc8469e0159a166028d017bddbc162b86f66bac90391379603d962\", \"price_changes\":[{\"asset_id\":\"39272994714739463168905443499424551362424437245880253267329605556587274644733\", \"price\":\"0.03\", \"size\":\"643.1\", \"side\":\"BUY\", \"hash\":\"440e32f116178c40dcac9fb794d04de5598ef187\", \"best_bid\":\"0.72\", \"best_ask\":\"0.73\"}, {\"asset_id\":\"20893381255801015515826997628594359667013752732428989472914000440642900266717\", \"price\":\"0.97\", \"size\":\"643.1\", \"side\":\"SELL\", \"hash\":\"f3c199fc10718f42cf1ad10eabb983210ae596e8\", \"best_bid\":\"0.27\", \"best_ask\":\"0.28\"}], \"timestamp\":\"1785204361619\", \"event_type\":\"price_change\"}","received_at":"2026-07-28T02:06:01.975649Z","schema_version":"clob-market-ws.price_change.v1","sequence":null,"server_hash":null,"server_timestamp":"1785204361619","session_id":"d2757dd6dad94f3b9fe67e8dbf1adc37","source":"clob_market_ws"},"received_at":"2026-07-28T02:06:01.975649Z","record_id":"6147e197083efc47a85c3599d337969530391cd3d4b22131504071e146d220fb","schema_fingerprint":"4aa3821a28b0b7c2400bc59aba4bcc0a76e971dadd19610d3ad38c768e124dc7","schema_version":"edge-lab-recorder.raw.v1","sequence":null,"source":"clob_market_ws"}
