{"event_at":"2026-07-28T02:01:01.532000Z","event_fingerprint":"a514487e0b1a6ce52541bda7e9cd4d7b87a75b1118553c6fdaf33b1c6762de94","payload":{"connection_id":"5d29200f65794d4d9ab6ef271f045a9b","event_at":"2026-07-28T02:01:01.532000Z","event_type":"price_change","frame_hash":"7375dcab98f0a121e02dae11b394e4a91f32aa37f30048f646d0054e3d92060d","frame_index":0,"kind":"data","monotonic_ns":306051729041041,"payload":{"event_type":"price_change","market":"0xda6f0e0e93fc8469e0159a166028d017bddbc162b86f66bac90391379603d962","price_changes":[{"asset_id":"39272994714739463168905443499424551362424437245880253267329605556587274644733","best_ask":"0.62","best_bid":"0.61","hash":"deb99918864d1e491deb81683a577bd64ba01346","price":"0.61","side":"BUY","size":"125"},{"asset_id":"20893381255801015515826997628594359667013752732428989472914000440642900266717","best_ask":"0.39","best_bid":"0.38","hash":"6c90d2d430046463374984adf32637b9b4e64825","price":"0.39","side":"SELL","size":"125"}],"timestamp":"1785204061532"},"payload_hash":"1f5e14ff7e1a4413283a73e2c35f119bae79fa73c20a88f7029085dd1abf945a","raw_frame":"{\"market\":\"0xda6f0e0e93fc8469e0159a166028d017bddbc162b86f66bac90391379603d962\", \"price_changes\":[{\"asset_id\":\"39272994714739463168905443499424551362424437245880253267329605556587274644733\", \"price\":\"0.61\", \"size\":\"125\", \"side\":\"BUY\", \"hash\":\"deb99918864d1e491deb81683a577bd64ba01346\", \"best_bid\":\"0.61\", \"best_ask\":\"0.62\"}, {\"asset_id\":\"20893381255801015515826997628594359667013752732428989472914000440642900266717\", \"price\":\"0.39\", \"size\":\"125\", \"side\":\"SELL\", \"hash\":\"6c90d2d430046463374984adf32637b9b4e64825\", \"best_bid\":\"0.38\", \"best_ask\":\"0.39\"}], \"timestamp\":\"1785204061532\", \"event_type\":\"price_change\"}","received_at":"2026-07-28T02:01:08.725093Z","schema_version":"clob-market-ws.price_change.v1","sequence":null,"server_hash":null,"server_timestamp":"1785204061532","session_id":"d2757dd6dad94f3b9fe67e8dbf1adc37","source":"clob_market_ws"},"received_at":"2026-07-28T02:01:08.725093Z","record_id":"9e43dd511b14baee08230445cad1972f4583ddad8f33e814dfce8266c28ca54e","schema_fingerprint":"4aa3821a28b0b7c2400bc59aba4bcc0a76e971dadd19610d3ad38c768e124dc7","schema_version":"edge-lab-recorder.raw.v1","sequence":null,"source":"clob_market_ws"}
{"event_at":"2026-07-28T02:01:01.533000Z","event_fingerprint":"ba0540fa18d215c214a7fcc9d742069e86717dd27d90aeb8fdd9bc73f0a44502","payload":{"connection_id":"5d29200f65794d4d9ab6ef271f045a9b","event_at":"2026-07-28T02:01:01.533000Z","event_type":"price_change","frame_hash":"95c28df32391bdbcda429d02adbccc5e1132388a563ca48cc1dae2c633bee4f0","frame_index":0,"kind":"data","monotonic_ns":306051742033083,"payload":{"event_type":"price_change","market":"0xda6f0e0e93fc8469e0159a166028d017bddbc162b86f66bac90391379603d962","price_changes":[{"asset_id":"39272994714739463168905443499424551362424437245880253267329605556587274644733","best_ask":"0.62","best_bid":"0.61","hash":"37ff1910f84f91e86dbc1848658f079c24951024","price":"0.61","side":"BUY","size":"169"},{"asset_id":"20893381255801015515826997628594359667013752732428989472914000440642900266717","best_ask":"0.39","best_bid":"0.38","hash":"560c4b3c10a843a4532612b4412e83346971bfa4","price":"0.39","side":"SELL","size":"169"}],"timestamp":"1785204061533"},"payload_hash":"f1aea6aca2435d8cd2e9c5259542dd2b5311908440b8ef2ba768b1d0c19ac8ab","raw_frame":"{\"market\":\"0xda6f0e0e93fc8469e0159a166028d017bddbc162b86f66bac90391379603d962\", \"price_changes\":[{\"asset_id\":\"39272994714739463168905443499424551362424437245880253267329605556587274644733\", \"price\":\"0.61\", \"size\":\"169\", \"side\":\"BUY\", \"hash\":\"37ff1910f84f91e86dbc1848658f079c24951024\", \"best_bid\":\"0.61\", \"best_ask\":\"0.62\"}, {\"asset_id\":\"20893381255801015515826997628594359667013752732428989472914000440642900266717\", \"price\":\"0.39\", \"size\":\"169\", \"side\":\"SELL\", \"hash\":\"560c4b3c10a843a4532612b4412e83346971bfa4\", \"best_bid\":\"0.38\", \"best_ask\":\"0.39\"}], \"timestamp\":\"1785204061533\", \"event_type\":\"price_change\"}","received_at":"2026-07-28T02:01:08.738084Z","schema_version":"clob-market-ws.price_change.v1","sequence":null,"server_hash":null,"server_timestamp":"1785204061533","session_id":"d2757dd6dad94f3b9fe67e8dbf1adc37","source":"clob_market_ws"},"received_at":"2026-07-28T02:01:08.738084Z","record_id":"d89522165a991c0250870a859fcbc581c71b6bd836bf58d8065dc8eb3e387f48","schema_fingerprint":"4aa3821a28b0b7c2400bc59aba4bcc0a76e971dadd19610d3ad38c768e124dc7","schema_version":"edge-lab-recorder.raw.v1","sequence":null,"source":"clob_market_ws"}
{"event_at":"2026-07-28T02:01:01.536000Z","event_fingerprint":"c4eb7154785429f376b9e6d90f83c70fa59cc8bc3202974a6379d3ebaa47d397","payload":{"connection_id":"5d29200f65794d4d9ab6ef271f045a9b","event_at":"2026-07-28T02:01:01.536000Z","event_type":"price_change","frame_hash":"dcd3546dc87e212a1a0510bea9f77e3129ae0f3d2625c83994fd8e23aa142392","frame_index":0,"kind":"data","monotonic_ns":306051747044750,"payload":{"event_type":"price_change","market":"0xda6f0e0e93fc8469e0159a166028d017bddbc162b86f66bac90391379603d962","price_changes":[{"asset_id":"39272994714739463168905443499424551362424437245880253267329605556587274644733","best_ask":"0.62","best_bid":"0.61","hash":"2153edd0082b80284dbf472dd2017746b0cac481","price":"0.61","side":"BUY","size":"138"},{"asset_id":"20893381255801015515826997628594359667013752732428989472914000440642900266717","best_ask":"0.39","best_bid":"0.38","hash":"bb595f25824b0aa4c603c587b852af8cb47879ce","price":"0.39","side":"SELL","size":"138"}],"timestamp":"1785204061536"},"payload_hash":"71d7c0683c33637c733d9f06fe0361fbd97508a98b51532d770bae85f8252675","raw_frame":"{\"market\":\"0xda6f0e0e93fc8469e0159a166028d017bddbc162b86f66bac90391379603d962\", \"price_changes\":[{\"asset_id\":\"39272994714739463168905443499424551362424437245880253267329605556587274644733\", \"price\":\"0.61\", \"size\":\"138\", \"side\":\"BUY\", \"hash\":\"2153edd0082b80284dbf472dd2017746b0cac481\", \"best_bid\":\"0.61\", \"best_ask\":\"0.62\"}, {\"asset_id\":\"20893381255801015515826997628594359667013752732428989472914000440642900266717\", \"price\":\"0.39\", \"size\":\"138\", \"side\":\"SELL\", \"hash\":\"bb595f25824b0aa4c603c587b852af8cb47879ce\", \"best_bid\":\"0.38\", \"best_ask\":\"0.39\"}], \"timestamp\":\"1785204061536\", \"event_type\":\"price_change\"}","received_at":"2026-07-28T02:01:08.743097Z","schema_version":"clob-market-ws.price_change.v1","sequence":null,"server_hash":null,"server_timestamp":"1785204061536","session_id":"d2757dd6dad94f3b9fe67e8dbf1adc37","source":"clob_market_ws"},"received_at":"2026-07-28T02:01:08.743097Z","record_id":"59d43f2e62fdabd4865a2e47faddafb79ae118e157ec5f660dd0262aa376bf54","schema_fingerprint":"4aa3821a28b0b7c2400bc59aba4bcc0a76e971dadd19610d3ad38c768e124dc7","schema_version":"edge-lab-recorder.raw.v1","sequence":null,"source":"clob_market_ws"}
{"event_at":"2026-07-28T02:01:01.540000Z","event_fingerprint":"0ebba14c4d7a14e727b13f288c54bbcd0cb214ac3e698dcc1f5722f1b2dcde55","payload":{"connection_id":"5d29200f65794d4d9ab6ef271f045a9b","event_at":"2026-07-28T02:01:01.540000Z","event_type":"price_change","frame_hash":"1b334e60eee6c38088b4355e13ee0c290533f583b4f9c1dc1e5cddb70a17b0b5","frame_index":0,"kind":"data","monotonic_ns":306051755638125,"payload":{"event_type":"price_change","market":"0xda6f0e0e93fc8469e0159a166028d017bddbc162b86f66bac90391379603d962","price_changes":[{"asset_id":"39272994714739463168905443499424551362424437245880253267329605556587274644733","best_ask":"0.62","best_bid":"0.61","hash":"0fee7667cec315fa76d3ce819c2f09760394c5cd","price":"0.51","side":"BUY","size":"143"},{"asset_id":"20893381255801015515826997628594359667013752732428989472914000440642900266717","best_ask":"0.39","best_bid":"0.38","hash":"bccfe17479a9714461278c445fb5d3b23ceccbc3","price":"0.49","side":"SELL","size":"143"}],"timestamp":"1785204061540"},"payload_hash":"701a49e020f39380c2f6ae1a8e13ba3924390bb8be8f223ff47d9c41eb143e00","raw_frame":"{\"market\":\"0xda6f0e0e93fc8469e0159a166028d017bddbc162b86f66bac90391379603d962\", \"price_changes\":[{\"asset_id\":\"39272994714739463168905443499424551362424437245880253267329605556587274644733\", \"price\":\"0.51\", \"size\":\"143\", \"side\":\"BUY\", \"hash\":\"0fee7667cec315fa76d3ce819c2f09760394c5cd\", \"best_bid\":\"0.61\", \"best_ask\":\"0.62\"}, {\"asset_id\":\"20893381255801015515826997628594359667013752732428989472914000440642900266717\", \"price\":\"0.49\", \"size\":\"143\", \"side\":\"SELL\", \"hash\":\"bccfe17479a9714461278c445fb5d3b23ceccbc3\", \"best_bid\":\"0.38\", \"best_ask\":\"0.39\"}], \"timestamp\":\"1785204061540\", \"event_type\":\"price_change\"}","received_at":"2026-07-28T02:01:08.751690Z","schema_version":"clob-market-ws.price_change.v1","sequence":null,"server_hash":null,"server_timestamp":"1785204061540","session_id":"d2757dd6dad94f3b9fe67e8dbf1adc37","source":"clob_market_ws"},"received_at":"2026-07-28T02:01:08.751690Z","record_id":"090201aaea6d6d3b8810df44907aefed4894a2b4b010c6169411740fe9d45b33","schema_fingerprint":"4aa3821a28b0b7c2400bc59aba4bcc0a76e971dadd19610d3ad38c768e124dc7","schema_version":"edge-lab-recorder.raw.v1","sequence":null,"source":"clob_market_ws"}
{"event_at":"2026-07-28T02:01:01.541000Z","event_fingerprint":"a50d290068cbbd68000a0a957d4058cecfe61d0700d323921271468813bc11a3","payload":{"connection_id":"5d29200f65794d4d9ab6ef271f045a9b","event_at":"2026-07-28T02:01:01.541000Z","event_type":"price_change","frame_hash":"40ed403d39a96a66c3f4b3076135a8e6b9633e44af36f46d79ffa1510deb0b0e","frame_index":0,"kind":"data","monotonic_ns":306051760322083,"payload":{"event_type":"price_change","market":"0xda6f0e0e93fc8469e0159a166028d017bddbc162b86f66bac90391379603d962","price_changes":[{"asset_id":"20893381255801015515826997628594359667013752732428989472914000440642900266717","best_ask":"0.39","best_bid":"0.38","hash":"25bbb17a804f60d035d2ee2fd24dd90f4de81763","price":"0.36","side":"BUY","size":"65"},{"asset_id":"39272994714739463168905443499424551362424437245880253267329605556587274644733","best_ask":"0.62","best_bid":"0.61","hash":"045517076036edc286f5a5d0daf66a63c06baf6a","price":"0.64","side":"SELL","size":"65"}],"timestamp":"1785204061541"},"payload_hash":"24e01f026a4167ac6f92424524fa28dd97211e0d1dfdd32c1ced35a376b7b1eb","raw_frame":"{\"market\":\"0xda6f0e0e93fc8469e0159a166028d017bddbc162b86f66bac90391379603d962\", \"price_changes\":[{\"asset_id\":\"20893381255801015515826997628594359667013752732428989472914000440642900266717\", \"price\":\"0.36\", \"size\":\"65\", \"side\":\"BUY\", \"hash\":\"25bbb17a804f60d035d2ee2fd24dd90f4de81763\", \"best_bid\":\"0.38\", \"best_ask\":\"0.39\"}, {\"asset_id\":\"39272994714739463168905443499424551362424437245880253267329605556587274644733\", \"price\":\"0.64\", \"size\":\"65\", \"side\":\"SELL\", \"hash\":\"045517076036edc286f5a5d0daf66a63c06baf6a\", \"best_bid\":\"0.61\", \"best_ask\":\"0.62\"}], \"timestamp\":\"1785204061541\", \"event_type\":\"price_change\"}","received_at":"2026-07-28T02:01:08.756370Z","schema_version":"clob-market-ws.price_change.v1","sequence":null,"server_hash":null,"server_timestamp":"1785204061541","session_id":"d2757dd6dad94f3b9fe67e8dbf1adc37","source":"clob_market_ws"},"received_at":"2026-07-28T02:01:08.756370Z","record_id":"42ac84f9f3fd146761f93064822e538bf0f43bd738f43174d6605010849f1510","schema_fingerprint":"4aa3821a28b0b7c2400bc59aba4bcc0a76e971dadd19610d3ad38c768e124dc7","schema_version":"edge-lab-recorder.raw.v1","sequence":null,"source":"clob_market_ws"}
{"event_at":"2026-07-28T02:01:01.542000Z","event_fingerprint":"0dadf0e560a0f5b7959bd1ef90488b186f9b3c127cfbcfa4e68634cf876a9c0c","payload":{"connection_id":"5d29200f65794d4d9ab6ef271f045a9b","event_at":"2026-07-28T02:01:01.542000Z","event_type":"price_change","frame_hash":"247b4e2e22918787bee43cb6d653f06cd7fc5728f50e4ef95af82e9573aab5c4","frame_index":0,"kind":"data","monotonic_ns":306051768325666,"payload":{"event_type":"price_change","market":"0xda6f0e0e93fc8469e0159a166028d017bddbc162b86f66bac90391379603d962","price_changes":[{"asset_id":"20893381255801015515826997628594359667013752732428989472914000440642900266717","best_ask":"0.39","best_bid":"0.38","hash":"b834d9e2ac0cfc43588cd461cda64bb721e5c666","price":"0.4","side":"SELL","size":"97.2"},{"asset_id":"39272994714739463168905443499424551362424437245880253267329605556587274644733","best_ask":"0.62","best_bid":"0.61","hash":"971a9767062f86195b1b7d7a0a88617087ee92b9","price":"0.6","side":"BUY","size":"97.2"}],"timestamp":"1785204061542"},"payload_hash":"e93fb665d03d5d34527e5f4c03c82d0f592c2fd3312f646088b25a2666946ade","raw_frame":"{\"market\":\"0xda6f0e0e93fc8469e0159a166028d017bddbc162b86f66bac90391379603d962\", \"price_changes\":[{\"asset_id\":\"20893381255801015515826997628594359667013752732428989472914000440642900266717\", \"price\":\"0.4\", \"size\":\"97.2\", \"side\":\"SELL\", \"hash\":\"b834d9e2ac0cfc43588cd461cda64bb721e5c666\", \"best_bid\":\"0.38\", \"best_ask\":\"0.39\"}, {\"asset_id\":\"39272994714739463168905443499424551362424437245880253267329605556587274644733\", \"price\":\"0.6\", \"size\":\"97.2\", \"side\":\"BUY\", \"hash\":\"971a9767062f86195b1b7d7a0a88617087ee92b9\", \"best_bid\":\"0.61\", \"best_ask\":\"0.62\"}], \"timestamp\":\"1785204061542\", \"event_type\":\"price_change\"}","received_at":"2026-07-28T02:01:08.764377Z","schema_version":"clob-market-ws.price_change.v1","sequence":null,"server_hash":null,"server_timestamp":"1785204061542","session_id":"d2757dd6dad94f3b9fe67e8dbf1adc37","source":"clob_market_ws"},"received_at":"2026-07-28T02:01:08.764377Z","record_id":"f824c771663b49bdb6b45ce17576f99d2ea05a5c106b1d0e92744e5fec1acf3e","schema_fingerprint":"4aa3821a28b0b7c2400bc59aba4bcc0a76e971dadd19610d3ad38c768e124dc7","schema_version":"edge-lab-recorder.raw.v1","sequence":null,"source":"clob_market_ws"}
{"event_at":"2026-07-28T02:01:01.543000Z","event_fingerprint":"bd891274eae0db9e0f13b29ddcade41828fc307f29da26850f79c9c4072e7b71","payload":{"connection_id":"5d29200f65794d4d9ab6ef271f045a9b","event_at":"2026-07-28T02:01:01.543000Z","event_type":"price_change","frame_hash":"5ba9592d95f3e7c153a888cea2ba019138474f9fdbf4b6fde284063446c04f9a","frame_index":0,"kind":"data","monotonic_ns":306051776304041,"payload":{"event_type":"price_change","market":"0xda6f0e0e93fc8469e0159a166028d017bddbc162b86f66bac90391379603d962","price_changes":[{"asset_id":"20893381255801015515826997628594359667013752732428989472914000440642900266717","best_ask":"0.39","best_bid":"0.38","hash":"3a475b314ae0bb977e9736327d28f1f8839cd04e","price":"0.25","side":"BUY","size":"617.99"},{"asset_id":"39272994714739463168905443499424551362424437245880253267329605556587274644733","best_ask":"0.62","best_bid":"0.61","hash":"246504d97cf1eec5ba32f2830158803c0761507a","price":"0.75","side":"SELL","size":"617.99"}],"timestamp":"1785204061543"},"payload_hash":"3c2f12166ef0539a3d881561e6d935dfe76ef65a1ad1105a8fc6f676fe8c7e2b","raw_frame":"{\"market\":\"0xda6f0e0e93fc8469e0159a166028d017bddbc162b86f66bac90391379603d962\", \"price_changes\":[{\"asset_id\":\"20893381255801015515826997628594359667013752732428989472914000440642900266717\", \"price\":\"0.25\", \"size\":\"617.99\", \"side\":\"BUY\", \"hash\":\"3a475b314ae0bb977e9736327d28f1f8839cd04e\", \"best_bid\":\"0.38\", \"best_ask\":\"0.39\"}, {\"asset_id\":\"39272994714739463168905443499424551362424437245880253267329605556587274644733\", \"price\":\"0.75\", \"size\":\"617.99\", \"side\":\"SELL\", \"hash\":\"246504d97cf1eec5ba32f2830158803c0761507a\", \"best_bid\":\"0.61\", \"best_ask\":\"0.62\"}], \"timestamp\":\"1785204061543\", \"event_type\":\"price_change\"}","received_at":"2026-07-28T02:01:08.772355Z","schema_version":"clob-market-ws.price_change.v1","sequence":null,"server_hash":null,"server_timestamp":"1785204061543","session_id":"d2757dd6dad94f3b9fe67e8dbf1adc37","source":"clob_market_ws"},"received_at":"2026-07-28T02:01:08.772355Z","record_id":"43c84c02fcd53d8859ee08672084f741a7a65fd36e5b493a91092d59986c948c","schema_fingerprint":"4aa3821a28b0b7c2400bc59aba4bcc0a76e971dadd19610d3ad38c768e124dc7","schema_version":"edge-lab-recorder.raw.v1","sequence":null,"source":"clob_market_ws"}
{"event_at":"2026-07-28T02:01:01.544000Z","event_fingerprint":"5febeff50ea4a33b08f78832d00f91d103724e8c4fb326e35e25697d0556fa54","payload":{"connection_id":"5d29200f65794d4d9ab6ef271f045a9b","event_at":"2026-07-28T02:01:01.544000Z","event_type":"price_change","frame_hash":"38e68b0ef3a568ef0c47625186264f5c90baca31030bacfbedcc35209b2b3417","frame_index":0,"kind":"data","monotonic_ns":306051782908500,"payload":{"event_type":"price_change","market":"0xda6f0e0e93fc8469e0159a166028d017bddbc162b86f66bac90391379603d962","price_changes":[{"asset_id":"20893381255801015515826997628594359667013752732428989472914000440642900266717","best_ask":"0.39","best_bid":"0.38","hash":"140b98b1a61f9be2acf0e0f4be57550a540ee8ed","price":"0.3","side":"BUY","size":"260.3"},{"asset_id":"39272994714739463168905443499424551362424437245880253267329605556587274644733","best_ask":"0.62","best_bid":"0.61","hash":"f184a141cc90617ffc4a3ae1a8ad9c932c2acf55","price":"0.7","side":"SELL","size":"260.3"}],"timestamp":"1785204061544"},"payload_hash":"581bcc8eaa84c49d8315b27be9b5c000c156b49263c51aaf0280491897f84b83","raw_frame":"{\"market\":\"0xda6f0e0e93fc8469e0159a166028d017bddbc162b86f66bac90391379603d962\", \"price_changes\":[{\"asset_id\":\"20893381255801015515826997628594359667013752732428989472914000440642900266717\", \"price\":\"0.3\", \"size\":\"260.3\", \"side\":\"BUY\", \"hash\":\"140b98b1a61f9be2acf0e0f4be57550a540ee8ed\", \"best_bid\":\"0.38\", \"best_ask\":\"0.39\"}, {\"asset_id\":\"39272994714739463168905443499424551362424437245880253267329605556587274644733\", \"price\":\"0.7\", \"size\":\"260.3\", \"side\":\"SELL\", \"hash\":\"f184a141cc90617ffc4a3ae1a8ad9c932c2acf55\", \"best_bid\":\"0.61\", \"best_ask\":\"0.62\"}], \"timestamp\":\"1785204061544\", \"event_type\":\"price_change\"}","received_at":"2026-07-28T02:01:08.778957Z","schema_version":"clob-market-ws.price_change.v1","sequence":null,"server_hash":null,"server_timestamp":"1785204061544","session_id":"d2757dd6dad94f3b9fe67e8dbf1adc37","source":"clob_market_ws"},"received_at":"2026-07-28T02:01:08.778957Z","record_id":"fadb827c711476b838cf9312234a74adbde60dadc1d2f6aa2a8a111aad013db4","schema_fingerprint":"4aa3821a28b0b7c2400bc59aba4bcc0a76e971dadd19610d3ad38c768e124dc7","schema_version":"edge-lab-recorder.raw.v1","sequence":null,"source":"clob_market_ws"}
{"event_at":"2026-07-28T02:01:01.544000Z","event_fingerprint":"76ca9bd2a7059aede901a0fb09811ccc3cd99701e80677ebf9129a4f13a60af3","payload":{"connection_id":"5d29200f65794d4d9ab6ef271f045a9b","event_at":"2026-07-28T02:01:01.544000Z","event_type":"price_change","frame_hash":"890ed303557acf88e493a2e1d286239e505a7a4bd5ecacac4dd5b280cde49f1f","frame_index":0,"kind":"data","monotonic_ns":306051788735750,"payload":{"event_type":"price_change","market":"0xda6f0e0e93fc8469e0159a166028d017bddbc162b86f66bac90391379603d962","price_changes":[{"asset_id":"20893381255801015515826997628594359667013752732428989472914000440642900266717","best_ask":"0.39","best_bid":"0.38","hash":"98ee003108f6735da3fd8e7cc33a41b1b93a04d0","price":"0.4","side":"SELL","size":"92.2"},{"asset_id":"39272994714739463168905443499424551362424437245880253267329605556587274644733","best_ask":"0.62","best_bid":"0.61","hash":"cf2d85d60eb8a1ce14950e5b27a7dfb8a15891db","price":"0.6","side":"BUY","size":"92.2"}],"timestamp":"1785204061544"},"payload_hash":"224aa31c6decf4068d627177e6541ad8f5686de7ea30149018c7b12695030ce3","raw_frame":"{\"market\":\"0xda6f0e0e93fc8469e0159a166028d017bddbc162b86f66bac90391379603d962\", \"price_changes\":[{\"asset_id\":\"20893381255801015515826997628594359667013752732428989472914000440642900266717\", \"price\":\"0.4\", \"size\":\"92.2\", \"side\":\"SELL\", \"hash\":\"98ee003108f6735da3fd8e7cc33a41b1b93a04d0\", \"best_bid\":\"0.38\", \"best_ask\":\"0.39\"}, {\"asset_id\":\"39272994714739463168905443499424551362424437245880253267329605556587274644733\", \"price\":\"0.6\", \"size\":\"92.2\", \"side\":\"BUY\", \"hash\":\"cf2d85d60eb8a1ce14950e5b27a7dfb8a15891db\", \"best_bid\":\"0.61\", \"best_ask\":\"0.62\"}], \"timestamp\":\"1785204061544\", \"event_type\":\"price_change\"}","received_at":"2026-07-28T02:01:08.784788Z","schema_version":"clob-market-ws.price_change.v1","sequence":null,"server_hash":null,"server_timestamp":"1785204061544","session_id":"d2757dd6dad94f3b9fe67e8dbf1adc37","source":"clob_market_ws"},"received_at":"2026-07-28T02:01:08.784788Z","record_id":"41867e666751544d7d96cd61a375f2d0b9a2952a0db71627d78c298daa0a0c13","schema_fingerprint":"4aa3821a28b0b7c2400bc59aba4bcc0a76e971dadd19610d3ad38c768e124dc7","schema_version":"edge-lab-recorder.raw.v1","sequence":null,"source":"clob_market_ws"}
{"event_at":"2026-07-28T02:01:01.544000Z","event_fingerprint":"84f857c956455ed83318755cbaa3ca116542413bddceb7fb68c71e323e486cec","payload":{"connection_id":"5d29200f65794d4d9ab6ef271f045a9b","event_at":"2026-07-28T02:01:01.544000Z","event_type":"price_change","frame_hash":"bb97080c88be9bd1a5c6c7f16e415f3f8545c5cb08059a716995b12e7bb54813","frame_index":0,"kind":"data","monotonic_ns":306051795257666,"payload":{"event_type":"price_change","market":"0xda6f0e0e93fc8469e0159a166028d017bddbc162b86f66bac90391379603d962","price_changes":[{"asset_id":"20893381255801015515826997628594359667013752732428989472914000440642900266717","best_ask":"0.39","best_bid":"0.38","hash":"5255689a3c19172eadc849dbe47355c407cb5cbf","price":"0.23","side":"BUY","size":"73.89"},{"asset_id":"39272994714739463168905443499424551362424437245880253267329605556587274644733","best_ask":"0.62","best_bid":"0.61","hash":"e1bb464019c4f10497489fd54977042ba97455a2","price":"0.77","side":"SELL","size":"73.89"}],"timestamp":"1785204061544"},"payload_hash":"7bc0a53ee338c71e79bd17ca90e8151a177efb3b206afb7bfb2faa5527e3070e","raw_frame":"{\"market\":\"0xda6f0e0e93fc8469e0159a166028d017bddbc162b86f66bac90391379603d962\", \"price_changes\":[{\"asset_id\":\"20893381255801015515826997628594359667013752732428989472914000440642900266717\", \"price\":\"0.23\", \"size\":\"73.89\", \"side\":\"BUY\", \"hash\":\"5255689a3c19172eadc849dbe47355c407cb5cbf\", \"best_bid\":\"0.38\", \"best_ask\":\"0.39\"}, {\"asset_id\":\"39272994714739463168905443499424551362424437245880253267329605556587274644733\", \"price\":\"0.77\", \"size\":\"73.89\", \"side\":\"SELL\", \"hash\":\"e1bb464019c4f10497489fd54977042ba97455a2\", \"best_bid\":\"0.61\", \"best_ask\":\"0.62\"}], \"timestamp\":\"1785204061544\", \"event_type\":\"price_change\"}","received_at":"2026-07-28T02:01:08.791309Z","schema_version":"clob-market-ws.price_change.v1","sequence":null,"server_hash":null,"server_timestamp":"1785204061544","session_id":"d2757dd6dad94f3b9fe67e8dbf1adc37","source":"clob_market_ws"},"received_at":"2026-07-28T02:01:08.791309Z","record_id":"40df6bb00b3e9f12a8d397241afc786d8d8bc2fe5e9f5ee1a9d5155a94f5854f","schema_fingerprint":"4aa3821a28b0b7c2400bc59aba4bcc0a76e971dadd19610d3ad38c768e124dc7","schema_version":"edge-lab-recorder.raw.v1","sequence":null,"source":"clob_market_ws"}
{"event_at":"2026-07-28T02:01:01.545000Z","event_fingerprint":"fb4c477f99eea4505c5563b81338076f1b39622b703dd24bcd8b5bd2c65c6906","payload":{"connection_id":"5d29200f65794d4d9ab6ef271f045a9b","event_at":"2026-07-28T02:01:01.545000Z","event_type":"price_change","frame_hash":"5884abfac51a9631a41ac32cee4d8482b18a579b2fb0247b30b5c789b1183278","frame_index":0,"kind":"data","monotonic_ns":306051801410791,"payload":{"event_type":"price_change","market":"0xda6f0e0e93fc8469e0159a166028d017bddbc162b86f66bac90391379603d962","price_changes":[{"asset_id":"39272994714739463168905443499424551362424437245880253267329605556587274644733","best_ask":"0.62","best_bid":"0.61","hash":"f98812361a7fb0c93b76c18cc6311226de14cd1b","price":"0.6","side":"BUY","size":"117.2"},{"asset_id":"20893381255801015515826997628594359667013752732428989472914000440642900266717","best_ask":"0.39","best_bid":"0.38","hash":"4db1317b29f1e0ca33155d80cfa97af2a1b59540","price":"0.4","side":"SELL","size":"117.2"}],"timestamp":"1785204061545"},"payload_hash":"0091f38dd479840578b1fccd44861fa002a3bad3817453929f8393ebb01b4edc","raw_frame":"{\"market\":\"0xda6f0e0e93fc8469e0159a166028d017bddbc162b86f66bac90391379603d962\", \"price_changes\":[{\"asset_id\":\"39272994714739463168905443499424551362424437245880253267329605556587274644733\", \"price\":\"0.6\", \"size\":\"117.2\", \"side\":\"BUY\", \"hash\":\"f98812361a7fb0c93b76c18cc6311226de14cd1b\", \"best_bid\":\"0.61\", \"best_ask\":\"0.62\"}, {\"asset_id\":\"20893381255801015515826997628594359667013752732428989472914000440642900266717\", \"price\":\"0.4\", \"size\":\"117.2\", \"side\":\"SELL\", \"hash\":\"4db1317b29f1e0ca33155d80cfa97af2a1b59540\", \"best_bid\":\"0.38\", \"best_ask\":\"0.39\"}], \"timestamp\":\"1785204061545\", \"event_type\":\"price_change\"}","received_at":"2026-07-28T02:01:08.797463Z","schema_version":"clob-market-ws.price_change.v1","sequence":null,"server_hash":null,"server_timestamp":"1785204061545","session_id":"d2757dd6dad94f3b9fe67e8dbf1adc37","source":"clob_market_ws"},"received_at":"2026-07-28T02:01:08.797463Z","record_id":"832f6cbbc01e6c1e9861dd751f89572f4ecd8407f7c54018dd9e03b0eb0d4570","schema_fingerprint":"4aa3821a28b0b7c2400bc59aba4bcc0a76e971dadd19610d3ad38c768e124dc7","schema_version":"edge-lab-recorder.raw.v1","sequence":null,"source":"clob_market_ws"}
{"event_at":"2026-07-28T02:01:01.546000Z","event_fingerprint":"f535b03c93ce27ba8349574eb4710ab769b441cb79b9e670535db93e0accc278","payload":{"connection_id":"5d29200f65794d4d9ab6ef271f045a9b","event_at":"2026-07-28T02:01:01.546000Z","event_type":"price_change","frame_hash":"5d48073c07fa775d249939e5fdefebb5c9c56a476b544b8576d510e594a2634a","frame_index":0,"kind":"data","monotonic_ns":306051807491208,"payload":{"event_type":"price_change","market":"0xda6f0e0e93fc8469e0159a166028d017bddbc162b86f66bac90391379603d962","price_changes":[{"asset_id":"20893381255801015515826997628594359667013752732428989472914000440642900266717","best_ask":"0.39","best_bid":"0.38","hash":"8269301c2eea239f4c3a229ed135cda65b0f51f0","price":"0.24","side":"BUY","size":"163.51"},{"asset_id":"39272994714739463168905443499424551362424437245880253267329605556587274644733","best_ask":"0.62","best_bid":"0.61","hash":"f344f43f927d7a364748bd58dd5a33f5dead992f","price":"0.76","side":"SELL","size":"163.51"}],"timestamp":"1785204061546"},"payload_hash":"38db79b80e19a5b5936a26ae567e20ecaedfbb972c7b1bfcf3ca8338c6217ddd","raw_frame":"{\"market\":\"0xda6f0e0e93fc8469e0159a166028d017bddbc162b86f66bac90391379603d962\", \"price_changes\":[{\"asset_id\":\"20893381255801015515826997628594359667013752732428989472914000440642900266717\", \"price\":\"0.24\", \"size\":\"163.51\", \"side\":\"BUY\", \"hash\":\"8269301c2eea239f4c3a229ed135cda65b0f51f0\", \"best_bid\":\"0.38\", \"best_ask\":\"0.39\"}, {\"asset_id\":\"39272994714739463168905443499424551362424437245880253267329605556587274644733\", \"price\":\"0.76\", \"size\":\"163.51\", \"side\":\"SELL\", \"hash\":\"f344f43f927d7a364748bd58dd5a33f5dead992f\", \"best_bid\":\"0.61\", \"best_ask\":\"0.62\"}], \"timestamp\":\"1785204061546\", \"event_type\":\"price_change\"}","received_at":"2026-07-28T02:01:08.803540Z","schema_version":"clob-market-ws.price_change.v1","sequence":null,"server_hash":null,"server_timestamp":"1785204061546","session_id":"d2757dd6dad94f3b9fe67e8dbf1adc37","source":"clob_market_ws"},"received_at":"2026-07-28T02:01:08.803540Z","record_id":"d648f8d14028332d3385ef187466b9b50991d95e1d71770ced72808ceb6354ca","schema_fingerprint":"4aa3821a28b0b7c2400bc59aba4bcc0a76e971dadd19610d3ad38c768e124dc7","schema_version":"edge-lab-recorder.raw.v1","sequence":null,"source":"clob_market_ws"}
{"event_at":"2026-07-28T02:01:01.547000Z","event_fingerprint":"fa6a9f0194641aafb952d8caf22bdbd0846c935edab0189a700e421f7e55fb93","payload":{"connection_id":"5d29200f65794d4d9ab6ef271f045a9b","event_at":"2026-07-28T02:01:01.547000Z","event_type":"price_change","frame_hash":"2facc704154657b2801bfa36fb448e54f3d9993c7b9d3673cdafa961483b2284","frame_index":0,"kind":"data","monotonic_ns":306051812592583,"payload":{"event_type":"price_change","market":"0xda6f0e0e93fc8469e0159a166028d017bddbc162b86f66bac90391379603d962","price_changes":[{"asset_id":"39272994714739463168905443499424551362424437245880253267329605556587274644733","best_ask":"0.62","best_bid":"0.61","hash":"236b8026820b28d3cae4c39a9c4bfc2c642e8532","price":"0.6","side":"BUY","size":"112.2"},{"asset_id":"20893381255801015515826997628594359667013752732428989472914000440642900266717","best_ask":"0.39","best_bid":"0.38","hash":"411b74253546fc30bf85290466b2eebe0dfdd7e3","price":"0.4","side":"SELL","size":"112.2"}],"timestamp":"1785204061547"},"payload_hash":"e0f789adabc52e1023ad1ce73056330d35fc2f2d5208a406d9053c5929552047","raw_frame":"{\"market\":\"0xda6f0e0e93fc8469e0159a166028d017bddbc162b86f66bac90391379603d962\", \"price_changes\":[{\"asset_id\":\"39272994714739463168905443499424551362424437245880253267329605556587274644733\", \"price\":\"0.6\", \"size\":\"112.2\", \"side\":\"BUY\", \"hash\":\"236b8026820b28d3cae4c39a9c4bfc2c642e8532\", \"best_bid\":\"0.61\", \"best_ask\":\"0.62\"}, {\"asset_id\":\"20893381255801015515826997628594359667013752732428989472914000440642900266717\", \"price\":\"0.4\", \"size\":\"112.2\", \"side\":\"SELL\", \"hash\":\"411b74253546fc30bf85290466b2eebe0dfdd7e3\", \"best_bid\":\"0.38\", \"best_ask\":\"0.39\"}], \"timestamp\":\"1785204061547\", \"event_type\":\"price_change\"}","received_at":"2026-07-28T02:01:08.808645Z","schema_version":"clob-market-ws.price_change.v1","sequence":null,"server_hash":null,"server_timestamp":"1785204061547","session_id":"d2757dd6dad94f3b9fe67e8dbf1adc37","source":"clob_market_ws"},"received_at":"2026-07-28T02:01:08.808645Z","record_id":"25d3478c838ddc204409cc71d2b58003a9cd627c8915f722acbc7ae69e7262ae","schema_fingerprint":"4aa3821a28b0b7c2400bc59aba4bcc0a76e971dadd19610d3ad38c768e124dc7","schema_version":"edge-lab-recorder.raw.v1","sequence":null,"source":"clob_market_ws"}
{"event_at":"2026-07-28T02:01:01.553000Z","event_fingerprint":"887cc1b733ed3b9b57e6c8d25df26f48ff7eb0b7c1dd70b64991bdb968f7acab","payload":{"connection_id":"5d29200f65794d4d9ab6ef271f045a9b","event_at":"2026-07-28T02:01:01.553000Z","event_type":"price_change","frame_hash":"82ae32be8868dbd0aa138e60e1729e27fdd48695fae0cfb00cef1f440734c08f","frame_index":0,"kind":"data","monotonic_ns":306051821431375,"payload":{"event_type":"price_change","market":"0xda6f0e0e93fc8469e0159a166028d017bddbc162b86f66bac90391379603d962","price_changes":[{"asset_id":"39272994714739463168905443499424551362424437245880253267329605556587274644733","best_ask":"0.62","best_bid":"0.61","hash":"b5250047ae1b21dd605d4e01f590c1c244334e2c","price":"0.61","side":"BUY","size":"162"},{"asset_id":"20893381255801015515826997628594359667013752732428989472914000440642900266717","best_ask":"0.39","best_bid":"0.38","hash":"d435bce9f2205a76b5173be0751fe1402527865b","price":"0.39","side":"SELL","size":"162"}],"timestamp":"1785204061553"},"payload_hash":"b464044e3a33e63cb719e98f997b4c0e1340415fa07884879177c1558c7e4ef1","raw_frame":"{\"market\":\"0xda6f0e0e93fc8469e0159a166028d017bddbc162b86f66bac90391379603d962\", \"price_changes\":[{\"asset_id\":\"39272994714739463168905443499424551362424437245880253267329605556587274644733\", \"price\":\"0.61\", \"size\":\"162\", \"side\":\"BUY\", \"hash\":\"b5250047ae1b21dd605d4e01f590c1c244334e2c\", \"best_bid\":\"0.61\", \"best_ask\":\"0.62\"}, {\"asset_id\":\"20893381255801015515826997628594359667013752732428989472914000440642900266717\", \"price\":\"0.39\", \"size\":\"162\", \"side\":\"SELL\", \"hash\":\"d435bce9f2205a76b5173be0751fe1402527865b\", \"best_bid\":\"0.38\", \"best_ask\":\"0.39\"}], \"timestamp\":\"1785204061553\", \"event_type\":\"price_change\"}","received_at":"2026-07-28T02:01:08.817483Z","schema_version":"clob-market-ws.price_change.v1","sequence":null,"server_hash":null,"server_timestamp":"1785204061553","session_id":"d2757dd6dad94f3b9fe67e8dbf1adc37","source":"clob_market_ws"},"received_at":"2026-07-28T02:01:08.817483Z","record_id":"54190ba280bce0facb98c056de415e2d30faae1daeb4c2a38a2cc60de6baea38","schema_fingerprint":"4aa3821a28b0b7c2400bc59aba4bcc0a76e971dadd19610d3ad38c768e124dc7","schema_version":"edge-lab-recorder.raw.v1","sequence":null,"source":"clob_market_ws"}
{"event_at":"2026-07-28T02:01:01.554000Z","event_fingerprint":"fba3125c79195f52e4b2bc2b416d24fa9712cabe40c92235f3e9a5b0456f785f","payload":{"connection_id":"5d29200f65794d4d9ab6ef271f045a9b","event_at":"2026-07-28T02:01:01.554000Z","event_type":"price_change","frame_hash":"dd61fb789d403089c4e2f7364a9e78e538ebee8ee5c993174f1ff9b038fdc319","frame_index":0,"kind":"data","monotonic_ns":306051831552375,"payload":{"event_type":"price_change","market":"0xda6f0e0e93fc8469e0159a166028d017bddbc162b86f66bac90391379603d962","price_changes":[{"asset_id":"39272994714739463168905443499424551362424437245880253267329605556587274644733","best_ask":"0.62","best_bid":"0.61","hash":"8bd732a1b15a7ef974f0f5f808de5ecbc3c09b2f","price":"0.61","side":"BUY","size":"138"},{"asset_id":"20893381255801015515826997628594359667013752732428989472914000440642900266717","best_ask":"0.39","best_bid":"0.38","hash":"986321320fa7bd03fea2edd622e4312bdec4072c","price":"0.39","side":"SELL","size":"138"}],"timestamp":"1785204061554"},"payload_hash":"5872e1f27eaa1424ecc6c3c914ec10a0ae09345d3375b67d30f750316891c2ea","raw_frame":"{\"market\":\"0xda6f0e0e93fc8469e0159a166028d017bddbc162b86f66bac90391379603d962\", \"price_changes\":[{\"asset_id\":\"39272994714739463168905443499424551362424437245880253267329605556587274644733\", \"price\":\"0.61\", \"size\":\"138\", \"side\":\"BUY\", \"hash\":\"8bd732a1b15a7ef974f0f5f808de5ecbc3c09b2f\", \"best_bid\":\"0.61\", \"best_ask\":\"0.62\"}, {\"asset_id\":\"20893381255801015515826997628594359667013752732428989472914000440642900266717\", \"price\":\"0.39\", \"size\":\"138\", \"side\":\"SELL\", \"hash\":\"986321320fa7bd03fea2edd622e4312bdec4072c\", \"best_bid\":\"0.38\", \"best_ask\":\"0.39\"}], \"timestamp\":\"1785204061554\", \"event_type\":\"price_change\"}","received_at":"2026-07-28T02:01:08.827604Z","schema_version":"clob-market-ws.price_change.v1","sequence":null,"server_hash":null,"server_timestamp":"1785204061554","session_id":"d2757dd6dad94f3b9fe67e8dbf1adc37","source":"clob_market_ws"},"received_at":"2026-07-28T02:01:08.827604Z","record_id":"af31456d79138ef12307e814376a6d3b66b62ab126d36472d3b2f85967a0c076","schema_fingerprint":"4aa3821a28b0b7c2400bc59aba4bcc0a76e971dadd19610d3ad38c768e124dc7","schema_version":"edge-lab-recorder.raw.v1","sequence":null,"source":"clob_market_ws"}
{"event_at":"2026-07-28T02:01:01.556000Z","event_fingerprint":"cf65301738119e7b4812392731590c76815d4bfcfb786129908bd9704d98d3bb","payload":{"connection_id":"5d29200f65794d4d9ab6ef271f045a9b","event_at":"2026-07-28T02:01:01.556000Z","event_type":"price_change","frame_hash":"132ce3a2a5f0c4895b44c9e55fc05985294701e01f86a305664c2eb186de0872","frame_index":0,"kind":"data","monotonic_ns":306051839600708,"payload":{"event_type":"price_change","market":"0xda6f0e0e93fc8469e0159a166028d017bddbc162b86f66bac90391379603d962","price_changes":[{"asset_id":"39272994714739463168905443499424551362424437245880253267329605556587274644733","best_ask":"0.62","best_bid":"0.61","hash":"1593edbf278c992a5a6535897e44c6b0c4120830","price":"0.61","side":"BUY","size":"143"},{"asset_id":"20893381255801015515826997628594359667013752732428989472914000440642900266717","best_ask":"0.39","best_bid":"0.38","hash":"8318e6760204ec024dafb8cc6f68653b0bb4e3ab","price":"0.39","side":"SELL","size":"143"}],"timestamp":"1785204061556"},"payload_hash":"afadbb36a01a1b24daf0f2835d01ca8b78668369ec3cc96fb2d400410a11f156","raw_frame":"{\"market\":\"0xda6f0e0e93fc8469e0159a166028d017bddbc162b86f66bac90391379603d962\", \"price_changes\":[{\"asset_id\":\"39272994714739463168905443499424551362424437245880253267329605556587274644733\", \"price\":\"0.61\", \"size\":\"143\", \"side\":\"BUY\", \"hash\":\"1593edbf278c992a5a6535897e44c6b0c4120830\", \"best_bid\":\"0.61\", \"best_ask\":\"0.62\"}, {\"asset_id\":\"20893381255801015515826997628594359667013752732428989472914000440642900266717\", \"price\":\"0.39\", \"size\":\"143\", \"side\":\"SELL\", \"hash\":\"8318e6760204ec024dafb8cc6f68653b0bb4e3ab\", \"best_bid\":\"0.38\", \"best_ask\":\"0.39\"}], \"timestamp\":\"1785204061556\", \"event_type\":\"price_change\"}","received_at":"2026-07-28T02:01:08.835652Z","schema_version":"clob-market-ws.price_change.v1","sequence":null,"server_hash":null,"server_timestamp":"1785204061556","session_id":"d2757dd6dad94f3b9fe67e8dbf1adc37","source":"clob_market_ws"},"received_at":"2026-07-28T02:01:08.835652Z","record_id":"b31a7066693f53c77fc70f918255de6739e99481ad4be0753613bedd3d508902","schema_fingerprint":"4aa3821a28b0b7c2400bc59aba4bcc0a76e971dadd19610d3ad38c768e124dc7","schema_version":"edge-lab-recorder.raw.v1","sequence":null,"source":"clob_market_ws"}
