{"event_at":"2026-07-28T02:14:06.622000Z","event_fingerprint":"197f71aaaecabcad56a11b124b44b4899d88280d451d7c4843609fd078149fcb","payload":{"connection_id":"5d29200f65794d4d9ab6ef271f045a9b","event_at":"2026-07-28T02:14:06.622000Z","event_type":"price_change","frame_hash":"bd77a446994f768dad1feddd81c6a8bbe965f6fef73eceae7744033e4c350543","frame_index":0,"kind":"data","monotonic_ns":306829911023583,"payload":{"event_type":"price_change","market":"0xda6f0e0e93fc8469e0159a166028d017bddbc162b86f66bac90391379603d962","price_changes":[{"asset_id":"20893381255801015515826997628594359667013752732428989472914000440642900266717","best_ask":"0.85","best_bid":"0.84","hash":"5796113fd9b2bed5a7565fe938001a4907520f8a","price":"0.8","side":"BUY","size":"74.3"},{"asset_id":"39272994714739463168905443499424551362424437245880253267329605556587274644733","best_ask":"0.16","best_bid":"0.15","hash":"869915a3e9bbabf2e39f63c715fe4cc664771c48","price":"0.2","side":"SELL","size":"74.3"}],"timestamp":"1785204846622"},"payload_hash":"a98b56f67d3cbf1f0c3d8b90e64ced44cf723e74da56920a58330fc395b379b4","raw_frame":"{\"market\":\"0xda6f0e0e93fc8469e0159a166028d017bddbc162b86f66bac90391379603d962\", \"price_changes\":[{\"asset_id\":\"20893381255801015515826997628594359667013752732428989472914000440642900266717\", \"price\":\"0.8\", \"size\":\"74.3\", \"side\":\"BUY\", \"hash\":\"5796113fd9b2bed5a7565fe938001a4907520f8a\", \"best_bid\":\"0.84\", \"best_ask\":\"0.85\"}, {\"asset_id\":\"39272994714739463168905443499424551362424437245880253267329605556587274644733\", \"price\":\"0.2\", \"size\":\"74.3\", \"side\":\"SELL\", \"hash\":\"869915a3e9bbabf2e39f63c715fe4cc664771c48\", \"best_bid\":\"0.15\", \"best_ask\":\"0.16\"}], \"timestamp\":\"1785204846622\", \"event_type\":\"price_change\"}","received_at":"2026-07-28T02:14:06.899580Z","schema_version":"clob-market-ws.price_change.v1","sequence":null,"server_hash":null,"server_timestamp":"1785204846622","session_id":"d2757dd6dad94f3b9fe67e8dbf1adc37","source":"clob_market_ws"},"received_at":"2026-07-28T02:14:06.899580Z","record_id":"8cdc4366b04bcb4b9391bfab24e38eefe480451b199e788405e9935fbd8e0f3f","schema_fingerprint":"4aa3821a28b0b7c2400bc59aba4bcc0a76e971dadd19610d3ad38c768e124dc7","schema_version":"edge-lab-recorder.raw.v1","sequence":null,"source":"clob_market_ws"}
{"event_at":"2026-07-28T02:14:06.623000Z","event_fingerprint":"b1f0c7db87c59fd0710b81ff3a1217d20f0d06592d81bd6259c13dc291c9560d","payload":{"connection_id":"5d29200f65794d4d9ab6ef271f045a9b","event_at":"2026-07-28T02:14:06.623000Z","event_type":"best_bid_ask","frame_hash":"21d9e7947f684d332ef058ff61fe11940ce836461f36742629cb45180fa0413e","frame_index":0,"kind":"data","monotonic_ns":306829919176000,"payload":{"asset_id":"20893381255801015515826997628594359667013752732428989472914000440642900266717","best_ask":"0.87","best_bid":"0.84","event_type":"best_bid_ask","market":"0xda6f0e0e93fc8469e0159a166028d017bddbc162b86f66bac90391379603d962","spread":"0.03","timestamp":"1785204846623"},"payload_hash":"a41b6fdde98090bd7c9574d4878a5199b4dde11dd7e5605aeb2bdec02f3fd666","raw_frame":"{\"market\":\"0xda6f0e0e93fc8469e0159a166028d017bddbc162b86f66bac90391379603d962\", \"asset_id\":\"20893381255801015515826997628594359667013752732428989472914000440642900266717\", \"best_bid\":\"0.84\", \"best_ask\":\"0.87\", \"spread\":\"0.03\", \"timestamp\":\"1785204846623\", \"event_type\":\"best_bid_ask\"}","received_at":"2026-07-28T02:14:06.907732Z","schema_version":"clob-market-ws.best_bid_ask.v1","sequence":null,"server_hash":null,"server_timestamp":"1785204846623","session_id":"d2757dd6dad94f3b9fe67e8dbf1adc37","source":"clob_market_ws"},"received_at":"2026-07-28T02:14:06.907732Z","record_id":"e0beefd2100752d0a22b5ab4f42bc53e62190799d0bee02245e384704ebc5697","schema_fingerprint":"8488399f31b0337811b13b266be932db7062827c2470b78bd8e9e99bab51d17d","schema_version":"edge-lab-recorder.raw.v1","sequence":null,"source":"clob_market_ws"}
{"event_at":"2026-07-28T02:14:06.623000Z","event_fingerprint":"706ccaa5a0b74289dd4c1060133f706dcd6f23033335a4b407a4f5ef15046838","payload":{"connection_id":"5d29200f65794d4d9ab6ef271f045a9b","event_at":"2026-07-28T02:14:06.623000Z","event_type":"best_bid_ask","frame_hash":"27f5153408438c126cf80baebf428ba1574b12675c3136a784c6823ff80eef13","frame_index":0,"kind":"data","monotonic_ns":306829921715291,"payload":{"asset_id":"39272994714739463168905443499424551362424437245880253267329605556587274644733","best_ask":"0.16","best_bid":"0.13","event_type":"best_bid_ask","market":"0xda6f0e0e93fc8469e0159a166028d017bddbc162b86f66bac90391379603d962","spread":"0.03","timestamp":"1785204846623"},"payload_hash":"394c9baa4378162162c7469d2e4c9aefe74ef67a620a3c280df5af2e648c9344","raw_frame":"{\"market\":\"0xda6f0e0e93fc8469e0159a166028d017bddbc162b86f66bac90391379603d962\", \"asset_id\":\"39272994714739463168905443499424551362424437245880253267329605556587274644733\", \"best_bid\":\"0.13\", \"best_ask\":\"0.16\", \"spread\":\"0.03\", \"timestamp\":\"1785204846623\", \"event_type\":\"best_bid_ask\"}","received_at":"2026-07-28T02:14:06.910272Z","schema_version":"clob-market-ws.best_bid_ask.v1","sequence":null,"server_hash":null,"server_timestamp":"1785204846623","session_id":"d2757dd6dad94f3b9fe67e8dbf1adc37","source":"clob_market_ws"},"received_at":"2026-07-28T02:14:06.910272Z","record_id":"f0009bd3e55e87581601104869965197eaf9abbc622042d38e21daea7787a472","schema_fingerprint":"8488399f31b0337811b13b266be932db7062827c2470b78bd8e9e99bab51d17d","schema_version":"edge-lab-recorder.raw.v1","sequence":null,"source":"clob_market_ws"}
{"event_at":"2026-07-28T02:14:06.623000Z","event_fingerprint":"8b0f4e0dda7ffb7488a81a5aca56099ab48255adc5dddee8acd3602490d0f7b2","payload":{"connection_id":"5d29200f65794d4d9ab6ef271f045a9b","event_at":"2026-07-28T02:14:06.623000Z","event_type":"price_change","frame_hash":"d31e1f773618088a97c2ac10331be6a68b976bdc25525eff76aa3798bb0d744d","frame_index":0,"kind":"data","monotonic_ns":306829924188916,"payload":{"event_type":"price_change","market":"0xda6f0e0e93fc8469e0159a166028d017bddbc162b86f66bac90391379603d962","price_changes":[{"asset_id":"20893381255801015515826997628594359667013752732428989472914000440642900266717","best_ask":"0.87","best_bid":"0.84","hash":"36945ee0908f63944abb51e87716fbeec93fa9f6","price":"0.75","side":"BUY","size":"74"},{"asset_id":"39272994714739463168905443499424551362424437245880253267329605556587274644733","best_ask":"0.16","best_bid":"0.13","hash":"60d9d4175a2d8de5caf3e7bc448b2fc9f1911653","price":"0.25","side":"SELL","size":"74"}],"timestamp":"1785204846623"},"payload_hash":"9b7a206905b561ce48d8ed1efa8be43cd12a7d1a16011d96e9cf4c6e0dfef8e7","raw_frame":"{\"market\":\"0xda6f0e0e93fc8469e0159a166028d017bddbc162b86f66bac90391379603d962\", \"price_changes\":[{\"asset_id\":\"20893381255801015515826997628594359667013752732428989472914000440642900266717\", \"price\":\"0.75\", \"size\":\"74\", \"side\":\"BUY\", \"hash\":\"36945ee0908f63944abb51e87716fbeec93fa9f6\", \"best_bid\":\"0.84\", \"best_ask\":\"0.87\"}, {\"asset_id\":\"39272994714739463168905443499424551362424437245880253267329605556587274644733\", \"price\":\"0.25\", \"size\":\"74\", \"side\":\"SELL\", \"hash\":\"60d9d4175a2d8de5caf3e7bc448b2fc9f1911653\", \"best_bid\":\"0.13\", \"best_ask\":\"0.16\"}], \"timestamp\":\"1785204846623\", \"event_type\":\"price_change\"}","received_at":"2026-07-28T02:14:06.912746Z","schema_version":"clob-market-ws.price_change.v1","sequence":null,"server_hash":null,"server_timestamp":"1785204846623","session_id":"d2757dd6dad94f3b9fe67e8dbf1adc37","source":"clob_market_ws"},"received_at":"2026-07-28T02:14:06.912746Z","record_id":"2b7b25ccfc14e71b798b8d8d8652a70db2ed78419a5f63dc5e3dce3d36999792","schema_fingerprint":"4aa3821a28b0b7c2400bc59aba4bcc0a76e971dadd19610d3ad38c768e124dc7","schema_version":"edge-lab-recorder.raw.v1","sequence":null,"source":"clob_market_ws"}
{"event_at":"2026-07-28T02:14:06.623000Z","event_fingerprint":"4ee9f9be6e1e3f21365fd9ec17433d07b22f708e6083ea1b40e27a01c9603a04","payload":{"connection_id":"5d29200f65794d4d9ab6ef271f045a9b","event_at":"2026-07-28T02:14:06.623000Z","event_type":"price_change","frame_hash":"67a6b8b047ce1083fb6f4e7c9e1f55ae0974216ff0bdba912dc64a30250deb79","frame_index":0,"kind":"data","monotonic_ns":306829927110125,"payload":{"event_type":"price_change","market":"0xda6f0e0e93fc8469e0159a166028d017bddbc162b86f66bac90391379603d962","price_changes":[{"asset_id":"20893381255801015515826997628594359667013752732428989472914000440642900266717","best_ask":"0.87","best_bid":"0.84","hash":"36945ee0908f63944abb51e87716fbeec93fa9f6","price":"0.74","side":"BUY","size":"44"},{"asset_id":"39272994714739463168905443499424551362424437245880253267329605556587274644733","best_ask":"0.16","best_bid":"0.13","hash":"60d9d4175a2d8de5caf3e7bc448b2fc9f1911653","price":"0.26","side":"SELL","size":"44"}],"timestamp":"1785204846623"},"payload_hash":"81eb9e7cb7bf9bdbd55a869bed5b5a6a41b087a852561fef8b1c7e4522b1c509","raw_frame":"{\"market\":\"0xda6f0e0e93fc8469e0159a166028d017bddbc162b86f66bac90391379603d962\", \"price_changes\":[{\"asset_id\":\"20893381255801015515826997628594359667013752732428989472914000440642900266717\", \"price\":\"0.74\", \"size\":\"44\", \"side\":\"BUY\", \"hash\":\"36945ee0908f63944abb51e87716fbeec93fa9f6\", \"best_bid\":\"0.84\", \"best_ask\":\"0.87\"}, {\"asset_id\":\"39272994714739463168905443499424551362424437245880253267329605556587274644733\", \"price\":\"0.26\", \"size\":\"44\", \"side\":\"SELL\", \"hash\":\"60d9d4175a2d8de5caf3e7bc448b2fc9f1911653\", \"best_bid\":\"0.13\", \"best_ask\":\"0.16\"}], \"timestamp\":\"1785204846623\", \"event_type\":\"price_change\"}","received_at":"2026-07-28T02:14:06.915667Z","schema_version":"clob-market-ws.price_change.v1","sequence":null,"server_hash":null,"server_timestamp":"1785204846623","session_id":"d2757dd6dad94f3b9fe67e8dbf1adc37","source":"clob_market_ws"},"received_at":"2026-07-28T02:14:06.915667Z","record_id":"0e1af1813c8bf44d2eb2911781e26116f386efc80263540d454d53e6b044184f","schema_fingerprint":"4aa3821a28b0b7c2400bc59aba4bcc0a76e971dadd19610d3ad38c768e124dc7","schema_version":"edge-lab-recorder.raw.v1","sequence":null,"source":"clob_market_ws"}
{"event_at":"2026-07-28T02:14:06.623000Z","event_fingerprint":"571af4fbe3b4846335f0e240835d3a528cfe6084b1156134a056ceefe4ed047e","payload":{"connection_id":"5d29200f65794d4d9ab6ef271f045a9b","event_at":"2026-07-28T02:14:06.623000Z","event_type":"price_change","frame_hash":"cfe98a9f5046e9e1e1d487af9a69013c2c70c759a09fafda7139be70179ef798","frame_index":0,"kind":"data","monotonic_ns":306829929986500,"payload":{"event_type":"price_change","market":"0xda6f0e0e93fc8469e0159a166028d017bddbc162b86f66bac90391379603d962","price_changes":[{"asset_id":"39272994714739463168905443499424551362424437245880253267329605556587274644733","best_ask":"0.16","best_bid":"0.13","hash":"60d9d4175a2d8de5caf3e7bc448b2fc9f1911653","price":"0.15","side":"BUY","size":"0"},{"asset_id":"20893381255801015515826997628594359667013752732428989472914000440642900266717","best_ask":"0.87","best_bid":"0.84","hash":"36945ee0908f63944abb51e87716fbeec93fa9f6","price":"0.85","side":"SELL","size":"0"}],"timestamp":"1785204846623"},"payload_hash":"55ad5b030b16fabce06dc4b6b66baae42f2e9281364b7cbce58e3b7093a735d0","raw_frame":"{\"market\":\"0xda6f0e0e93fc8469e0159a166028d017bddbc162b86f66bac90391379603d962\", \"price_changes\":[{\"asset_id\":\"39272994714739463168905443499424551362424437245880253267329605556587274644733\", \"price\":\"0.15\", \"size\":\"0\", \"side\":\"BUY\", \"hash\":\"60d9d4175a2d8de5caf3e7bc448b2fc9f1911653\", \"best_bid\":\"0.13\", \"best_ask\":\"0.16\"}, {\"asset_id\":\"20893381255801015515826997628594359667013752732428989472914000440642900266717\", \"price\":\"0.85\", \"size\":\"0\", \"side\":\"SELL\", \"hash\":\"36945ee0908f63944abb51e87716fbeec93fa9f6\", \"best_bid\":\"0.84\", \"best_ask\":\"0.87\"}], \"timestamp\":\"1785204846623\", \"event_type\":\"price_change\"}","received_at":"2026-07-28T02:14:06.918544Z","schema_version":"clob-market-ws.price_change.v1","sequence":null,"server_hash":null,"server_timestamp":"1785204846623","session_id":"d2757dd6dad94f3b9fe67e8dbf1adc37","source":"clob_market_ws"},"received_at":"2026-07-28T02:14:06.918544Z","record_id":"73d599a6d50bc1ce373b0cebe6d607934dff4ecf46e5f4e37bf2b1fa8d8a73a6","schema_fingerprint":"4aa3821a28b0b7c2400bc59aba4bcc0a76e971dadd19610d3ad38c768e124dc7","schema_version":"edge-lab-recorder.raw.v1","sequence":null,"source":"clob_market_ws"}
{"event_at":"2026-07-28T02:14:06.623000Z","event_fingerprint":"e652f64e1e4bb199ac271a2bb57fbb769f21178ebd9663c4b319e65c470820d7","payload":{"connection_id":"5d29200f65794d4d9ab6ef271f045a9b","event_at":"2026-07-28T02:14:06.623000Z","event_type":"price_change","frame_hash":"fe735e4f28db96ea2c1f39f850a2d197d2be34a1a949caffccaf7546b59239ec","frame_index":0,"kind":"data","monotonic_ns":306829932868166,"payload":{"event_type":"price_change","market":"0xda6f0e0e93fc8469e0159a166028d017bddbc162b86f66bac90391379603d962","price_changes":[{"asset_id":"39272994714739463168905443499424551362424437245880253267329605556587274644733","best_ask":"0.16","best_bid":"0.13","hash":"60d9d4175a2d8de5caf3e7bc448b2fc9f1911653","price":"0.24","side":"SELL","size":"88.55"},{"asset_id":"20893381255801015515826997628594359667013752732428989472914000440642900266717","best_ask":"0.87","best_bid":"0.84","hash":"36945ee0908f63944abb51e87716fbeec93fa9f6","price":"0.76","side":"BUY","size":"88.55"}],"timestamp":"1785204846623"},"payload_hash":"4692f03a351c8e128c5332b849f7d27ed462ac30758fba31271e9bd3f11728ee","raw_frame":"{\"market\":\"0xda6f0e0e93fc8469e0159a166028d017bddbc162b86f66bac90391379603d962\", \"price_changes\":[{\"asset_id\":\"39272994714739463168905443499424551362424437245880253267329605556587274644733\", \"price\":\"0.24\", \"size\":\"88.55\", \"side\":\"SELL\", \"hash\":\"60d9d4175a2d8de5caf3e7bc448b2fc9f1911653\", \"best_bid\":\"0.13\", \"best_ask\":\"0.16\"}, {\"asset_id\":\"20893381255801015515826997628594359667013752732428989472914000440642900266717\", \"price\":\"0.76\", \"size\":\"88.55\", \"side\":\"BUY\", \"hash\":\"36945ee0908f63944abb51e87716fbeec93fa9f6\", \"best_bid\":\"0.84\", \"best_ask\":\"0.87\"}], \"timestamp\":\"1785204846623\", \"event_type\":\"price_change\"}","received_at":"2026-07-28T02:14:06.921425Z","schema_version":"clob-market-ws.price_change.v1","sequence":null,"server_hash":null,"server_timestamp":"1785204846623","session_id":"d2757dd6dad94f3b9fe67e8dbf1adc37","source":"clob_market_ws"},"received_at":"2026-07-28T02:14:06.921425Z","record_id":"50b00bac154634ed741389d749ffdbb4fd9ab1c4006f28d710f61f5e6b8e749e","schema_fingerprint":"4aa3821a28b0b7c2400bc59aba4bcc0a76e971dadd19610d3ad38c768e124dc7","schema_version":"edge-lab-recorder.raw.v1","sequence":null,"source":"clob_market_ws"}
{"event_at":"2026-07-28T02:14:06.623000Z","event_fingerprint":"99a96c3006c500b63bab49bada1438d7c664450c7878040c8020451a41a4e4a0","payload":{"connection_id":"5d29200f65794d4d9ab6ef271f045a9b","event_at":"2026-07-28T02:14:06.623000Z","event_type":"price_change","frame_hash":"232b2ce2e264f8dbe28feabfcae1155ef70a641ccc151edb89d9daa79a294a87","frame_index":0,"kind":"data","monotonic_ns":306829937824458,"payload":{"event_type":"price_change","market":"0xda6f0e0e93fc8469e0159a166028d017bddbc162b86f66bac90391379603d962","price_changes":[{"asset_id":"39272994714739463168905443499424551362424437245880253267329605556587274644733","best_ask":"0.16","best_bid":"0.13","hash":"60d9d4175a2d8de5caf3e7bc448b2fc9f1911653","price":"0.14","side":"BUY","size":"0"},{"asset_id":"20893381255801015515826997628594359667013752732428989472914000440642900266717","best_ask":"0.87","best_bid":"0.84","hash":"36945ee0908f63944abb51e87716fbeec93fa9f6","price":"0.86","side":"SELL","size":"0"}],"timestamp":"1785204846623"},"payload_hash":"9f1d0b8ca983497a529925909d16679fd97500294aa8790d926fc4461e65d8e1","raw_frame":"{\"market\":\"0xda6f0e0e93fc8469e0159a166028d017bddbc162b86f66bac90391379603d962\", \"price_changes\":[{\"asset_id\":\"39272994714739463168905443499424551362424437245880253267329605556587274644733\", \"price\":\"0.14\", \"size\":\"0\", \"side\":\"BUY\", \"hash\":\"60d9d4175a2d8de5caf3e7bc448b2fc9f1911653\", \"best_bid\":\"0.13\", \"best_ask\":\"0.16\"}, {\"asset_id\":\"20893381255801015515826997628594359667013752732428989472914000440642900266717\", \"price\":\"0.86\", \"size\":\"0\", \"side\":\"SELL\", \"hash\":\"36945ee0908f63944abb51e87716fbeec93fa9f6\", \"best_bid\":\"0.84\", \"best_ask\":\"0.87\"}], \"timestamp\":\"1785204846623\", \"event_type\":\"price_change\"}","received_at":"2026-07-28T02:14:06.926381Z","schema_version":"clob-market-ws.price_change.v1","sequence":null,"server_hash":null,"server_timestamp":"1785204846623","session_id":"d2757dd6dad94f3b9fe67e8dbf1adc37","source":"clob_market_ws"},"received_at":"2026-07-28T02:14:06.926381Z","record_id":"09252e15394a8ac2a04c50a2cfde4742aa8f1f8e1ac93f31eb3b55ea91954a40","schema_fingerprint":"4aa3821a28b0b7c2400bc59aba4bcc0a76e971dadd19610d3ad38c768e124dc7","schema_version":"edge-lab-recorder.raw.v1","sequence":null,"source":"clob_market_ws"}
{"event_at":"2026-07-28T02:14:06.623000Z","event_fingerprint":"d96d40be9759db78e76bb1f26c63fbabce9c640430f8f3914b9aee3934823757","payload":{"connection_id":"5d29200f65794d4d9ab6ef271f045a9b","event_at":"2026-07-28T02:14:06.623000Z","event_type":"price_change","frame_hash":"77a27ecc0b31fffbf54bbe50155aab2905b083d83bf7ff16e540650e6b6a17f6","frame_index":0,"kind":"data","monotonic_ns":306829940809458,"payload":{"event_type":"price_change","market":"0xda6f0e0e93fc8469e0159a166028d017bddbc162b86f66bac90391379603d962","price_changes":[{"asset_id":"39272994714739463168905443499424551362424437245880253267329605556587274644733","best_ask":"0.16","best_bid":"0.13","hash":"60d9d4175a2d8de5caf3e7bc448b2fc9f1911653","price":"0.13","side":"BUY","size":"10"},{"asset_id":"20893381255801015515826997628594359667013752732428989472914000440642900266717","best_ask":"0.87","best_bid":"0.84","hash":"36945ee0908f63944abb51e87716fbeec93fa9f6","price":"0.87","side":"SELL","size":"10"}],"timestamp":"1785204846623"},"payload_hash":"56ee075e14d45cf21f743b0ad830dbc71edb7bfa4f33afe341f7878339655ce9","raw_frame":"{\"market\":\"0xda6f0e0e93fc8469e0159a166028d017bddbc162b86f66bac90391379603d962\", \"price_changes\":[{\"asset_id\":\"39272994714739463168905443499424551362424437245880253267329605556587274644733\", \"price\":\"0.13\", \"size\":\"10\", \"side\":\"BUY\", \"hash\":\"60d9d4175a2d8de5caf3e7bc448b2fc9f1911653\", \"best_bid\":\"0.13\", \"best_ask\":\"0.16\"}, {\"asset_id\":\"20893381255801015515826997628594359667013752732428989472914000440642900266717\", \"price\":\"0.87\", \"size\":\"10\", \"side\":\"SELL\", \"hash\":\"36945ee0908f63944abb51e87716fbeec93fa9f6\", \"best_bid\":\"0.84\", \"best_ask\":\"0.87\"}], \"timestamp\":\"1785204846623\", \"event_type\":\"price_change\"}","received_at":"2026-07-28T02:14:06.929366Z","schema_version":"clob-market-ws.price_change.v1","sequence":null,"server_hash":null,"server_timestamp":"1785204846623","session_id":"d2757dd6dad94f3b9fe67e8dbf1adc37","source":"clob_market_ws"},"received_at":"2026-07-28T02:14:06.929366Z","record_id":"e144e597c375fec49a622956ca9b44e96e2444f0e7058d6fa4ebc4dc344445ef","schema_fingerprint":"4aa3821a28b0b7c2400bc59aba4bcc0a76e971dadd19610d3ad38c768e124dc7","schema_version":"edge-lab-recorder.raw.v1","sequence":null,"source":"clob_market_ws"}
{"event_at":"2026-07-28T02:14:06.623000Z","event_fingerprint":"a5d118a703032142c6191766088f71d50df66d215ea4ed91657f70b41fbd62f9","payload":{"connection_id":"5d29200f65794d4d9ab6ef271f045a9b","event_at":"2026-07-28T02:14:06.623000Z","event_type":"price_change","frame_hash":"956560c56704eea16e499790d06f0a6d8415a7eac75c73b05afbf3b07316a79e","frame_index":0,"kind":"data","monotonic_ns":306829943745666,"payload":{"event_type":"price_change","market":"0xda6f0e0e93fc8469e0159a166028d017bddbc162b86f66bac90391379603d962","price_changes":[{"asset_id":"39272994714739463168905443499424551362424437245880253267329605556587274644733","best_ask":"0.16","best_bid":"0.13","hash":"db202f4bccb06e490a4e8318422e2ace7839c106","price":"0.12","side":"BUY","size":"167"},{"asset_id":"20893381255801015515826997628594359667013752732428989472914000440642900266717","best_ask":"0.87","best_bid":"0.84","hash":"695b7176040408df7262a6141083adffec90dc47","price":"0.88","side":"SELL","size":"167"}],"timestamp":"1785204846623"},"payload_hash":"9c399099d8b957acac015c7aa2022718d3fbea3c0dc406b848e835c462d8ac15","raw_frame":"{\"market\":\"0xda6f0e0e93fc8469e0159a166028d017bddbc162b86f66bac90391379603d962\", \"price_changes\":[{\"asset_id\":\"39272994714739463168905443499424551362424437245880253267329605556587274644733\", \"price\":\"0.12\", \"size\":\"167\", \"side\":\"BUY\", \"hash\":\"db202f4bccb06e490a4e8318422e2ace7839c106\", \"best_bid\":\"0.13\", \"best_ask\":\"0.16\"}, {\"asset_id\":\"20893381255801015515826997628594359667013752732428989472914000440642900266717\", \"price\":\"0.88\", \"size\":\"167\", \"side\":\"SELL\", \"hash\":\"695b7176040408df7262a6141083adffec90dc47\", \"best_bid\":\"0.84\", \"best_ask\":\"0.87\"}], \"timestamp\":\"1785204846623\", \"event_type\":\"price_change\"}","received_at":"2026-07-28T02:14:06.932302Z","schema_version":"clob-market-ws.price_change.v1","sequence":null,"server_hash":null,"server_timestamp":"1785204846623","session_id":"d2757dd6dad94f3b9fe67e8dbf1adc37","source":"clob_market_ws"},"received_at":"2026-07-28T02:14:06.932302Z","record_id":"6db70775c32eb84f62ef5c9972e1a1693ca93b53f00e59025537816d0e9d1479","schema_fingerprint":"4aa3821a28b0b7c2400bc59aba4bcc0a76e971dadd19610d3ad38c768e124dc7","schema_version":"edge-lab-recorder.raw.v1","sequence":null,"source":"clob_market_ws"}
{"event_at":"2026-07-28T02:14:06.623000Z","event_fingerprint":"f432217f7340e06d6766ba8b1578fa682591d83816c4dfae81a9d046377027cd","payload":{"connection_id":"5d29200f65794d4d9ab6ef271f045a9b","event_at":"2026-07-28T02:14:06.623000Z","event_type":"price_change","frame_hash":"ae60a28405a80ec94fe3167debe13fb965d3dec1af2c7cca55a2a9ef88d39cdf","frame_index":0,"kind":"data","monotonic_ns":306829946781416,"payload":{"event_type":"price_change","market":"0xda6f0e0e93fc8469e0159a166028d017bddbc162b86f66bac90391379603d962","price_changes":[{"asset_id":"20893381255801015515826997628594359667013752732428989472914000440642900266717","best_ask":"0.87","best_bid":"0.84","hash":"a31785751fae7bcd5c69083ba585f4924c285bca","price":"0.01","side":"BUY","size":"5315"},{"asset_id":"39272994714739463168905443499424551362424437245880253267329605556587274644733","best_ask":"0.16","best_bid":"0.13","hash":"f317189f6b823dc326f00c73ff665345b487a0bb","price":"0.99","side":"SELL","size":"5315"}],"timestamp":"1785204846623"},"payload_hash":"41420e11f663bf2a51fc32340aa4ed1e013f94987629e023caf41d86e5dd7403","raw_frame":"{\"market\":\"0xda6f0e0e93fc8469e0159a166028d017bddbc162b86f66bac90391379603d962\", \"price_changes\":[{\"asset_id\":\"20893381255801015515826997628594359667013752732428989472914000440642900266717\", \"price\":\"0.01\", \"size\":\"5315\", \"side\":\"BUY\", \"hash\":\"a31785751fae7bcd5c69083ba585f4924c285bca\", \"best_bid\":\"0.84\", \"best_ask\":\"0.87\"}, {\"asset_id\":\"39272994714739463168905443499424551362424437245880253267329605556587274644733\", \"price\":\"0.99\", \"size\":\"5315\", \"side\":\"SELL\", \"hash\":\"f317189f6b823dc326f00c73ff665345b487a0bb\", \"best_bid\":\"0.13\", \"best_ask\":\"0.16\"}], \"timestamp\":\"1785204846623\", \"event_type\":\"price_change\"}","received_at":"2026-07-28T02:14:06.935338Z","schema_version":"clob-market-ws.price_change.v1","sequence":null,"server_hash":null,"server_timestamp":"1785204846623","session_id":"d2757dd6dad94f3b9fe67e8dbf1adc37","source":"clob_market_ws"},"received_at":"2026-07-28T02:14:06.935338Z","record_id":"4c799613d9207254f184d5a86b7af1f62855a2e1f8f57e4b4f606ed558895a24","schema_fingerprint":"4aa3821a28b0b7c2400bc59aba4bcc0a76e971dadd19610d3ad38c768e124dc7","schema_version":"edge-lab-recorder.raw.v1","sequence":null,"source":"clob_market_ws"}
{"event_at":"2026-07-28T02:14:06.626000Z","event_fingerprint":"df0db9a8277e9aaf27d25b73eed2224feae22c4605343c2edde1f27f64fc9311","payload":{"connection_id":"5d29200f65794d4d9ab6ef271f045a9b","event_at":"2026-07-28T02:14:06.626000Z","event_type":"price_change","frame_hash":"88d4748a5605666396b93ed023106f0bcd309b1fff398645b7f816bcd0c6d6a0","frame_index":0,"kind":"data","monotonic_ns":306829954770000,"payload":{"event_type":"price_change","market":"0xda6f0e0e93fc8469e0159a166028d017bddbc162b86f66bac90391379603d962","price_changes":[{"asset_id":"39272994714739463168905443499424551362424437245880253267329605556587274644733","best_ask":"0.16","best_bid":"0.13","hash":"db5c88f00a469e3f634a27ed9246b732d99f12f2","price":"0.19","side":"SELL","size":"74.5"},{"asset_id":"20893381255801015515826997628594359667013752732428989472914000440642900266717","best_ask":"0.87","best_bid":"0.84","hash":"9c0746a2a89327c985c8dbad178bd449f57ddf1c","price":"0.81","side":"BUY","size":"74.5"}],"timestamp":"1785204846626"},"payload_hash":"03931918d84499fdbcca8cd9ee609897ef0f915646a5662f25a2c7f7b271b6b7","raw_frame":"{\"market\":\"0xda6f0e0e93fc8469e0159a166028d017bddbc162b86f66bac90391379603d962\", \"price_changes\":[{\"asset_id\":\"39272994714739463168905443499424551362424437245880253267329605556587274644733\", \"price\":\"0.19\", \"size\":\"74.5\", \"side\":\"SELL\", \"hash\":\"db5c88f00a469e3f634a27ed9246b732d99f12f2\", \"best_bid\":\"0.13\", \"best_ask\":\"0.16\"}, {\"asset_id\":\"20893381255801015515826997628594359667013752732428989472914000440642900266717\", \"price\":\"0.81\", \"size\":\"74.5\", \"side\":\"BUY\", \"hash\":\"9c0746a2a89327c985c8dbad178bd449f57ddf1c\", \"best_bid\":\"0.84\", \"best_ask\":\"0.87\"}], \"timestamp\":\"1785204846626\", \"event_type\":\"price_change\"}","received_at":"2026-07-28T02:14:06.943327Z","schema_version":"clob-market-ws.price_change.v1","sequence":null,"server_hash":null,"server_timestamp":"1785204846626","session_id":"d2757dd6dad94f3b9fe67e8dbf1adc37","source":"clob_market_ws"},"received_at":"2026-07-28T02:14:06.943327Z","record_id":"eab6f10d90f7e0cfc348adf1261af4796062d1e50dc6fd45f46ada2c7838cb91","schema_fingerprint":"4aa3821a28b0b7c2400bc59aba4bcc0a76e971dadd19610d3ad38c768e124dc7","schema_version":"edge-lab-recorder.raw.v1","sequence":null,"source":"clob_market_ws"}
{"event_at":"2026-07-28T02:14:06.627000Z","event_fingerprint":"55add92f1341883f8c8ef6e103a4f5e69b8009a754c8d79552c8b2b41ab40db3","payload":{"connection_id":"5d29200f65794d4d9ab6ef271f045a9b","event_at":"2026-07-28T02:14:06.627000Z","event_type":"price_change","frame_hash":"b912a4bd12b20b2e3fd56fd222278073f1866dcc045e76cfe678a624bb9d840c","frame_index":0,"kind":"data","monotonic_ns":306829962052833,"payload":{"event_type":"price_change","market":"0xda6f0e0e93fc8469e0159a166028d017bddbc162b86f66bac90391379603d962","price_changes":[{"asset_id":"20893381255801015515826997628594359667013752732428989472914000440642900266717","best_ask":"0.87","best_bid":"0.84","hash":"6dd17effcfefac5dd35e71349331c0f53b288565","price":"0.82","side":"BUY","size":"49"},{"asset_id":"39272994714739463168905443499424551362424437245880253267329605556587274644733","best_ask":"0.16","best_bid":"0.13","hash":"23c2cf5d69964d46d1cf870a3af6984736f3ec0d","price":"0.18","side":"SELL","size":"49"}],"timestamp":"1785204846627"},"payload_hash":"d4f7ce9bfae1fc0d50513f59cbb78817497deb072f5cb2f66a8120d5aae71c1d","raw_frame":"{\"market\":\"0xda6f0e0e93fc8469e0159a166028d017bddbc162b86f66bac90391379603d962\", \"price_changes\":[{\"asset_id\":\"20893381255801015515826997628594359667013752732428989472914000440642900266717\", \"price\":\"0.82\", \"size\":\"49\", \"side\":\"BUY\", \"hash\":\"6dd17effcfefac5dd35e71349331c0f53b288565\", \"best_bid\":\"0.84\", \"best_ask\":\"0.87\"}, {\"asset_id\":\"39272994714739463168905443499424551362424437245880253267329605556587274644733\", \"price\":\"0.18\", \"size\":\"49\", \"side\":\"SELL\", \"hash\":\"23c2cf5d69964d46d1cf870a3af6984736f3ec0d\", \"best_bid\":\"0.13\", \"best_ask\":\"0.16\"}], \"timestamp\":\"1785204846627\", \"event_type\":\"price_change\"}","received_at":"2026-07-28T02:14:06.950610Z","schema_version":"clob-market-ws.price_change.v1","sequence":null,"server_hash":null,"server_timestamp":"1785204846627","session_id":"d2757dd6dad94f3b9fe67e8dbf1adc37","source":"clob_market_ws"},"received_at":"2026-07-28T02:14:06.950610Z","record_id":"b4b1c8f2ed90311c945bd9975a352e0c16b43b3f8db2f13296d716b7f0f07252","schema_fingerprint":"4aa3821a28b0b7c2400bc59aba4bcc0a76e971dadd19610d3ad38c768e124dc7","schema_version":"edge-lab-recorder.raw.v1","sequence":null,"source":"clob_market_ws"}
{"event_at":"2026-07-28T02:14:06.628000Z","event_fingerprint":"326d0f085b4f50941c2ec006763a00cbf0665eb06e765771f12adf7a05803676","payload":{"connection_id":"5d29200f65794d4d9ab6ef271f045a9b","event_at":"2026-07-28T02:14:06.628000Z","event_type":"price_change","frame_hash":"55d14a1f868a2abce9c2755c2c9e598eb8ec4ffdeb5085386af9b6ab88ba509b","frame_index":0,"kind":"data","monotonic_ns":306829965896333,"payload":{"event_type":"price_change","market":"0xda6f0e0e93fc8469e0159a166028d017bddbc162b86f66bac90391379603d962","price_changes":[{"asset_id":"20893381255801015515826997628594359667013752732428989472914000440642900266717","best_ask":"0.87","best_bid":"0.84","hash":"e4d5d2c4f00cafe5eb17e09b519867f6e3993a94","price":"0.8","side":"BUY","size":"66.3"},{"asset_id":"39272994714739463168905443499424551362424437245880253267329605556587274644733","best_ask":"0.16","best_bid":"0.13","hash":"fdd2b268403ad01374e65043810d9f3da1d2c586","price":"0.2","side":"SELL","size":"66.3"}],"timestamp":"1785204846628"},"payload_hash":"efddc7723195773e9d370468984c81a15c880813af142187f10976a87d59a7c9","raw_frame":"{\"market\":\"0xda6f0e0e93fc8469e0159a166028d017bddbc162b86f66bac90391379603d962\", \"price_changes\":[{\"asset_id\":\"20893381255801015515826997628594359667013752732428989472914000440642900266717\", \"price\":\"0.8\", \"size\":\"66.3\", \"side\":\"BUY\", \"hash\":\"e4d5d2c4f00cafe5eb17e09b519867f6e3993a94\", \"best_bid\":\"0.84\", \"best_ask\":\"0.87\"}, {\"asset_id\":\"39272994714739463168905443499424551362424437245880253267329605556587274644733\", \"price\":\"0.2\", \"size\":\"66.3\", \"side\":\"SELL\", \"hash\":\"fdd2b268403ad01374e65043810d9f3da1d2c586\", \"best_bid\":\"0.13\", \"best_ask\":\"0.16\"}], \"timestamp\":\"1785204846628\", \"event_type\":\"price_change\"}","received_at":"2026-07-28T02:14:06.954452Z","schema_version":"clob-market-ws.price_change.v1","sequence":null,"server_hash":null,"server_timestamp":"1785204846628","session_id":"d2757dd6dad94f3b9fe67e8dbf1adc37","source":"clob_market_ws"},"received_at":"2026-07-28T02:14:06.954452Z","record_id":"cc2b3454680911d1a2a167a4c241d22605af4418bf6a998a1f6040519ee36f65","schema_fingerprint":"4aa3821a28b0b7c2400bc59aba4bcc0a76e971dadd19610d3ad38c768e124dc7","schema_version":"edge-lab-recorder.raw.v1","sequence":null,"source":"clob_market_ws"}
{"event_at":"2026-07-28T02:14:06.629000Z","event_fingerprint":"f84c0ea1ff7115a24686f46a8bbc6a47c08f26c16d6c799ef7b80581b18da005","payload":{"connection_id":"5d29200f65794d4d9ab6ef271f045a9b","event_at":"2026-07-28T02:14:06.629000Z","event_type":"price_change","frame_hash":"6e9aca4588dbdfec2e3ed96b0fcaa7bc6170ebfc56c46c8fdd1555a43b8d7570","frame_index":0,"kind":"data","monotonic_ns":306829970336791,"payload":{"event_type":"price_change","market":"0xda6f0e0e93fc8469e0159a166028d017bddbc162b86f66bac90391379603d962","price_changes":[{"asset_id":"39272994714739463168905443499424551362424437245880253267329605556587274644733","best_ask":"0.16","best_bid":"0.13","hash":"4c6ab04853b50062cae53494c800fcdd5d162dee","price":"0.19","side":"SELL","size":"54.5"},{"asset_id":"20893381255801015515826997628594359667013752732428989472914000440642900266717","best_ask":"0.87","best_bid":"0.84","hash":"373911d08941f7aeea095a96a072ae1d6d09c58f","price":"0.81","side":"BUY","size":"54.5"}],"timestamp":"1785204846629"},"payload_hash":"fe256d50a3a4a52fc1f08bd9d4915d6d6861b26a4129c20df3eba5627511a1fc","raw_frame":"{\"market\":\"0xda6f0e0e93fc8469e0159a166028d017bddbc162b86f66bac90391379603d962\", \"price_changes\":[{\"asset_id\":\"39272994714739463168905443499424551362424437245880253267329605556587274644733\", \"price\":\"0.19\", \"size\":\"54.5\", \"side\":\"SELL\", \"hash\":\"4c6ab04853b50062cae53494c800fcdd5d162dee\", \"best_bid\":\"0.13\", \"best_ask\":\"0.16\"}, {\"asset_id\":\"20893381255801015515826997628594359667013752732428989472914000440642900266717\", \"price\":\"0.81\", \"size\":\"54.5\", \"side\":\"BUY\", \"hash\":\"373911d08941f7aeea095a96a072ae1d6d09c58f\", \"best_bid\":\"0.84\", \"best_ask\":\"0.87\"}], \"timestamp\":\"1785204846629\", \"event_type\":\"price_change\"}","received_at":"2026-07-28T02:14:06.958892Z","schema_version":"clob-market-ws.price_change.v1","sequence":null,"server_hash":null,"server_timestamp":"1785204846629","session_id":"d2757dd6dad94f3b9fe67e8dbf1adc37","source":"clob_market_ws"},"received_at":"2026-07-28T02:14:06.958892Z","record_id":"569e8cd3f9c0bb42d908d644015b752d11151310927efccc9cb4052e676359d6","schema_fingerprint":"4aa3821a28b0b7c2400bc59aba4bcc0a76e971dadd19610d3ad38c768e124dc7","schema_version":"edge-lab-recorder.raw.v1","sequence":null,"source":"clob_market_ws"}
{"event_at":"2026-07-28T02:14:06.629000Z","event_fingerprint":"4899efd7281e73c0960a52dd59d8348284729ee846724759552c4cfa2466f4ae","payload":{"connection_id":"5d29200f65794d4d9ab6ef271f045a9b","event_at":"2026-07-28T02:14:06.629000Z","event_type":"price_change","frame_hash":"a539c289bc0162a2055624c9a5abcb6bb4ad25c8eccdc62b230b0a347ab8ecf6","frame_index":0,"kind":"data","monotonic_ns":306829977238791,"payload":{"event_type":"price_change","market":"0xda6f0e0e93fc8469e0159a166028d017bddbc162b86f66bac90391379603d962","price_changes":[{"asset_id":"20893381255801015515826997628594359667013752732428989472914000440642900266717","best_ask":"0.87","best_bid":"0.84","hash":"41fdec649c4ef261e1d04f132e5b7c24d2ac8bc8","price":"0.57","side":"BUY","size":"0"},{"asset_id":"39272994714739463168905443499424551362424437245880253267329605556587274644733","best_ask":"0.16","best_bid":"0.13","hash":"e8fd0840e5521d1ce79bba2d408005dd86fc61ea","price":"0.43","side":"SELL","size":"0"}],"timestamp":"1785204846629"},"payload_hash":"a5100db0a7613a721893833e86cfcc8f59d1a6cdbfff90d133f7dee6b9af0c03","raw_frame":"{\"market\":\"0xda6f0e0e93fc8469e0159a166028d017bddbc162b86f66bac90391379603d962\", \"price_changes\":[{\"asset_id\":\"20893381255801015515826997628594359667013752732428989472914000440642900266717\", \"price\":\"0.57\", \"size\":\"0\", \"side\":\"BUY\", \"hash\":\"41fdec649c4ef261e1d04f132e5b7c24d2ac8bc8\", \"best_bid\":\"0.84\", \"best_ask\":\"0.87\"}, {\"asset_id\":\"39272994714739463168905443499424551362424437245880253267329605556587274644733\", \"price\":\"0.43\", \"size\":\"0\", \"side\":\"SELL\", \"hash\":\"e8fd0840e5521d1ce79bba2d408005dd86fc61ea\", \"best_bid\":\"0.13\", \"best_ask\":\"0.16\"}], \"timestamp\":\"1785204846629\", \"event_type\":\"price_change\"}","received_at":"2026-07-28T02:14:06.965795Z","schema_version":"clob-market-ws.price_change.v1","sequence":null,"server_hash":null,"server_timestamp":"1785204846629","session_id":"d2757dd6dad94f3b9fe67e8dbf1adc37","source":"clob_market_ws"},"received_at":"2026-07-28T02:14:06.965795Z","record_id":"16a0359a77fdadf87ca9d8961d7f35ccc39dde451959b24586b438273d9e2ba5","schema_fingerprint":"4aa3821a28b0b7c2400bc59aba4bcc0a76e971dadd19610d3ad38c768e124dc7","schema_version":"edge-lab-recorder.raw.v1","sequence":null,"source":"clob_market_ws"}
