{"event_at":"2026-07-28T02:06:38.623000Z","event_fingerprint":"92ffe9335f19f957d7eddf0e5766140d8ea1ca6d8e8bb3a8046e97fe7292a305","payload":{"connection_id":"5d29200f65794d4d9ab6ef271f045a9b","event_at":"2026-07-28T02:06:38.623000Z","event_type":"price_change","frame_hash":"be99334c692963abb90de3c9393e0b781865b77d289e443b702b229ac1742089","frame_index":0,"kind":"data","monotonic_ns":306382486348666,"payload":{"event_type":"price_change","market":"0xda6f0e0e93fc8469e0159a166028d017bddbc162b86f66bac90391379603d962","price_changes":[{"asset_id":"20893381255801015515826997628594359667013752732428989472914000440642900266717","best_ask":"0.4","best_bid":"0.39","hash":"b46f8d0ef3d508bb8e529dcf51d92f3e898cf89a","price":"0.39","side":"BUY","size":"61"},{"asset_id":"39272994714739463168905443499424551362424437245880253267329605556587274644733","best_ask":"0.61","best_bid":"0.6","hash":"139df5256ae71f4fcd5614a1e692d8e872497200","price":"0.61","side":"SELL","size":"61"}],"timestamp":"1785204398623"},"payload_hash":"5d475715adf6d1c3e2e93401a7e4b1fed22b2220fd1e5d1e99ef91480a4cf976","raw_frame":"{\"market\":\"0xda6f0e0e93fc8469e0159a166028d017bddbc162b86f66bac90391379603d962\", \"price_changes\":[{\"asset_id\":\"20893381255801015515826997628594359667013752732428989472914000440642900266717\", \"price\":\"0.39\", \"size\":\"61\", \"side\":\"BUY\", \"hash\":\"b46f8d0ef3d508bb8e529dcf51d92f3e898cf89a\", \"best_bid\":\"0.39\", \"best_ask\":\"0.4\"}, {\"asset_id\":\"39272994714739463168905443499424551362424437245880253267329605556587274644733\", \"price\":\"0.61\", \"size\":\"61\", \"side\":\"SELL\", \"hash\":\"139df5256ae71f4fcd5614a1e692d8e872497200\", \"best_bid\":\"0.6\", \"best_ask\":\"0.61\"}], \"timestamp\":\"1785204398623\", \"event_type\":\"price_change\"}","received_at":"2026-07-28T02:06:39.479342Z","schema_version":"clob-market-ws.price_change.v1","sequence":null,"server_hash":null,"server_timestamp":"1785204398623","session_id":"d2757dd6dad94f3b9fe67e8dbf1adc37","source":"clob_market_ws"},"received_at":"2026-07-28T02:06:39.479342Z","record_id":"df81b7af5f7e4f3d11bd46615540766deb0f7924297882ce0d926ad75e6daaa8","schema_fingerprint":"4aa3821a28b0b7c2400bc59aba4bcc0a76e971dadd19610d3ad38c768e124dc7","schema_version":"edge-lab-recorder.raw.v1","sequence":null,"source":"clob_market_ws"}
{"event_at":"2026-07-28T02:06:38.623000Z","event_fingerprint":"cc2f6f827f80e2f0297b82b9172b0aa8955815070a75cfbcdc565457949bed17","payload":{"connection_id":"5d29200f65794d4d9ab6ef271f045a9b","event_at":"2026-07-28T02:06:38.623000Z","event_type":"price_change","frame_hash":"93451b09cde088ca29613191d5bc17c3d30cdaac89bae0704c5ed066909f0c46","frame_index":0,"kind":"data","monotonic_ns":306382507098875,"payload":{"event_type":"price_change","market":"0xda6f0e0e93fc8469e0159a166028d017bddbc162b86f66bac90391379603d962","price_changes":[{"asset_id":"39272994714739463168905443499424551362424437245880253267329605556587274644733","best_ask":"0.61","best_bid":"0.6","hash":"fc7553dcb737b9e37b9e16fbaa16fcd1183db7f4","price":"0.59","side":"BUY","size":"55"},{"asset_id":"20893381255801015515826997628594359667013752732428989472914000440642900266717","best_ask":"0.4","best_bid":"0.39","hash":"0213da0cdb7bb7fcbab167bcdd5da8950ff8b036","price":"0.41","side":"SELL","size":"55"}],"timestamp":"1785204398623"},"payload_hash":"7877943e0807b32086f88a6a8e9c4c021926a70b62c98cd07cbfac320c245176","raw_frame":"{\"market\":\"0xda6f0e0e93fc8469e0159a166028d017bddbc162b86f66bac90391379603d962\", \"price_changes\":[{\"asset_id\":\"39272994714739463168905443499424551362424437245880253267329605556587274644733\", \"price\":\"0.59\", \"size\":\"55\", \"side\":\"BUY\", \"hash\":\"fc7553dcb737b9e37b9e16fbaa16fcd1183db7f4\", \"best_bid\":\"0.6\", \"best_ask\":\"0.61\"}, {\"asset_id\":\"20893381255801015515826997628594359667013752732428989472914000440642900266717\", \"price\":\"0.41\", \"size\":\"55\", \"side\":\"SELL\", \"hash\":\"0213da0cdb7bb7fcbab167bcdd5da8950ff8b036\", \"best_bid\":\"0.39\", \"best_ask\":\"0.4\"}], \"timestamp\":\"1785204398623\", \"event_type\":\"price_change\"}","received_at":"2026-07-28T02:06:39.500090Z","schema_version":"clob-market-ws.price_change.v1","sequence":null,"server_hash":null,"server_timestamp":"1785204398623","session_id":"d2757dd6dad94f3b9fe67e8dbf1adc37","source":"clob_market_ws"},"received_at":"2026-07-28T02:06:39.500090Z","record_id":"141c06947dfd433f9118a129bbc2e9e475e04faa8e5f7eaeb8f2dc72fe1b67f8","schema_fingerprint":"4aa3821a28b0b7c2400bc59aba4bcc0a76e971dadd19610d3ad38c768e124dc7","schema_version":"edge-lab-recorder.raw.v1","sequence":null,"source":"clob_market_ws"}
{"event_at":"2026-07-28T02:06:38.624000Z","event_fingerprint":"c689912eb5a515a5bc38dc790ce4f6f3271263857a8b175ba1182f7e6875a34c","payload":{"connection_id":"5d29200f65794d4d9ab6ef271f045a9b","event_at":"2026-07-28T02:06:38.624000Z","event_type":"price_change","frame_hash":"dc28d15cecbc21f6e05380646f2ad3d88432375dfe76fabeb8560226cfb2b830","frame_index":0,"kind":"data","monotonic_ns":306382513088875,"payload":{"event_type":"price_change","market":"0xda6f0e0e93fc8469e0159a166028d017bddbc162b86f66bac90391379603d962","price_changes":[{"asset_id":"20893381255801015515826997628594359667013752732428989472914000440642900266717","best_ask":"0.4","best_bid":"0.39","hash":"938a8a1920fee64b3c0021599fefb9a82dda4bca","price":"0.24","side":"BUY","size":"167.39"},{"asset_id":"39272994714739463168905443499424551362424437245880253267329605556587274644733","best_ask":"0.61","best_bid":"0.6","hash":"673384e06ca5696f8a9303ddb5e9877c79727673","price":"0.76","side":"SELL","size":"167.39"}],"timestamp":"1785204398624"},"payload_hash":"82093217d6d2154200abf9b2980b1257f6786914a5ce0bd07b2247cd07ee33e6","raw_frame":"{\"market\":\"0xda6f0e0e93fc8469e0159a166028d017bddbc162b86f66bac90391379603d962\", \"price_changes\":[{\"asset_id\":\"20893381255801015515826997628594359667013752732428989472914000440642900266717\", \"price\":\"0.24\", \"size\":\"167.39\", \"side\":\"BUY\", \"hash\":\"938a8a1920fee64b3c0021599fefb9a82dda4bca\", \"best_bid\":\"0.39\", \"best_ask\":\"0.4\"}, {\"asset_id\":\"39272994714739463168905443499424551362424437245880253267329605556587274644733\", \"price\":\"0.76\", \"size\":\"167.39\", \"side\":\"SELL\", \"hash\":\"673384e06ca5696f8a9303ddb5e9877c79727673\", \"best_bid\":\"0.6\", \"best_ask\":\"0.61\"}], \"timestamp\":\"1785204398624\", \"event_type\":\"price_change\"}","received_at":"2026-07-28T02:06:39.506082Z","schema_version":"clob-market-ws.price_change.v1","sequence":null,"server_hash":null,"server_timestamp":"1785204398624","session_id":"d2757dd6dad94f3b9fe67e8dbf1adc37","source":"clob_market_ws"},"received_at":"2026-07-28T02:06:39.506082Z","record_id":"c4b6b007e0d660c880c53614595851d65d9817aea8d62b2420dcaed883863c2d","schema_fingerprint":"4aa3821a28b0b7c2400bc59aba4bcc0a76e971dadd19610d3ad38c768e124dc7","schema_version":"edge-lab-recorder.raw.v1","sequence":null,"source":"clob_market_ws"}
{"event_at":"2026-07-28T02:06:38.624000Z","event_fingerprint":"c9a6b587531c86399e2ce816f7bf000931844e4157c7f83fdca1f560a71a9b8b","payload":{"connection_id":"5d29200f65794d4d9ab6ef271f045a9b","event_at":"2026-07-28T02:06:38.624000Z","event_type":"price_change","frame_hash":"b91bd7ed9feb6f7852cd44394bfc6e5775dd05e166c770dd95867a21554df536","frame_index":0,"kind":"data","monotonic_ns":306382517988208,"payload":{"event_type":"price_change","market":"0xda6f0e0e93fc8469e0159a166028d017bddbc162b86f66bac90391379603d962","price_changes":[{"asset_id":"20893381255801015515826997628594359667013752732428989472914000440642900266717","best_ask":"0.4","best_bid":"0.39","hash":"ec0c2527016fc85cade1be56b78290d58074cf4e","price":"0.33","side":"BUY","size":"87.58"},{"asset_id":"39272994714739463168905443499424551362424437245880253267329605556587274644733","best_ask":"0.61","best_bid":"0.6","hash":"f3322f9ccfb10a64da7281c27dd5e5590f1189d8","price":"0.67","side":"SELL","size":"87.58"}],"timestamp":"1785204398624"},"payload_hash":"67e6be9bc2373feadaed487ea28ca5f4fe11e64c9609c5871b4f4bdfa39a039e","raw_frame":"{\"market\":\"0xda6f0e0e93fc8469e0159a166028d017bddbc162b86f66bac90391379603d962\", \"price_changes\":[{\"asset_id\":\"20893381255801015515826997628594359667013752732428989472914000440642900266717\", \"price\":\"0.33\", \"size\":\"87.58\", \"side\":\"BUY\", \"hash\":\"ec0c2527016fc85cade1be56b78290d58074cf4e\", \"best_bid\":\"0.39\", \"best_ask\":\"0.4\"}, {\"asset_id\":\"39272994714739463168905443499424551362424437245880253267329605556587274644733\", \"price\":\"0.67\", \"size\":\"87.58\", \"side\":\"SELL\", \"hash\":\"f3322f9ccfb10a64da7281c27dd5e5590f1189d8\", \"best_bid\":\"0.6\", \"best_ask\":\"0.61\"}], \"timestamp\":\"1785204398624\", \"event_type\":\"price_change\"}","received_at":"2026-07-28T02:06:39.510980Z","schema_version":"clob-market-ws.price_change.v1","sequence":null,"server_hash":null,"server_timestamp":"1785204398624","session_id":"d2757dd6dad94f3b9fe67e8dbf1adc37","source":"clob_market_ws"},"received_at":"2026-07-28T02:06:39.510980Z","record_id":"e46270e8b4701fc98773556c5be789d05aa0967635eb1cb6801891439eb270c2","schema_fingerprint":"4aa3821a28b0b7c2400bc59aba4bcc0a76e971dadd19610d3ad38c768e124dc7","schema_version":"edge-lab-recorder.raw.v1","sequence":null,"source":"clob_market_ws"}
{"event_at":"2026-07-28T02:06:38.624000Z","event_fingerprint":"5567784c9669c53bf11d2ee42e932e1efcb3757192b78a28e28a1dff08bf6730","payload":{"connection_id":"5d29200f65794d4d9ab6ef271f045a9b","event_at":"2026-07-28T02:06:38.624000Z","event_type":"price_change","frame_hash":"83f10d199b385a59c2d015ca6fd90ccc2f43620ed572ac5de3f9c549ccf6e686","frame_index":0,"kind":"data","monotonic_ns":306382522219500,"payload":{"event_type":"price_change","market":"0xda6f0e0e93fc8469e0159a166028d017bddbc162b86f66bac90391379603d962","price_changes":[{"asset_id":"39272994714739463168905443499424551362424437245880253267329605556587274644733","best_ask":"0.61","best_bid":"0.6","hash":"ee8bab9bf01847883c2e8cf20596019dc35ac244","price":"0.56","side":"BUY","size":"93.12"},{"asset_id":"20893381255801015515826997628594359667013752732428989472914000440642900266717","best_ask":"0.4","best_bid":"0.39","hash":"74f203c6b143e7d443e57280354ecd4ad689a8af","price":"0.44","side":"SELL","size":"93.12"}],"timestamp":"1785204398624"},"payload_hash":"eda27af792c635a278767edf86211b9eb77bdbf86d8905e9b49237eaa4b237fc","raw_frame":"{\"market\":\"0xda6f0e0e93fc8469e0159a166028d017bddbc162b86f66bac90391379603d962\", \"price_changes\":[{\"asset_id\":\"39272994714739463168905443499424551362424437245880253267329605556587274644733\", \"price\":\"0.56\", \"size\":\"93.12\", \"side\":\"BUY\", \"hash\":\"ee8bab9bf01847883c2e8cf20596019dc35ac244\", \"best_bid\":\"0.6\", \"best_ask\":\"0.61\"}, {\"asset_id\":\"20893381255801015515826997628594359667013752732428989472914000440642900266717\", \"price\":\"0.44\", \"size\":\"93.12\", \"side\":\"SELL\", \"hash\":\"74f203c6b143e7d443e57280354ecd4ad689a8af\", \"best_bid\":\"0.39\", \"best_ask\":\"0.4\"}], \"timestamp\":\"1785204398624\", \"event_type\":\"price_change\"}","received_at":"2026-07-28T02:06:39.515213Z","schema_version":"clob-market-ws.price_change.v1","sequence":null,"server_hash":null,"server_timestamp":"1785204398624","session_id":"d2757dd6dad94f3b9fe67e8dbf1adc37","source":"clob_market_ws"},"received_at":"2026-07-28T02:06:39.515213Z","record_id":"1e206fe072b80412e36742b1688a2f1530b1315bc6ad39ee6dbba14da0ddd3ee","schema_fingerprint":"4aa3821a28b0b7c2400bc59aba4bcc0a76e971dadd19610d3ad38c768e124dc7","schema_version":"edge-lab-recorder.raw.v1","sequence":null,"source":"clob_market_ws"}
{"event_at":"2026-07-28T02:06:38.625000Z","event_fingerprint":"93479ed1f081293be7ca80a02b97cdde0f0967eb94702e205f314c5bad5cbd35","payload":{"connection_id":"5d29200f65794d4d9ab6ef271f045a9b","event_at":"2026-07-28T02:06:38.625000Z","event_type":"price_change","frame_hash":"fdb8324b1f013a0d9f5e65a23e16686df75d9347b76aa109f093ad48d1190840","frame_index":0,"kind":"data","monotonic_ns":306382526442583,"payload":{"event_type":"price_change","market":"0xda6f0e0e93fc8469e0159a166028d017bddbc162b86f66bac90391379603d962","price_changes":[{"asset_id":"39272994714739463168905443499424551362424437245880253267329605556587274644733","best_ask":"0.61","best_bid":"0.6","hash":"1a0282ca3d1d89d191889ecc9ee399a55a9ecba8","price":"0.58","side":"BUY","size":"95"},{"asset_id":"20893381255801015515826997628594359667013752732428989472914000440642900266717","best_ask":"0.4","best_bid":"0.39","hash":"fc90c2ce9ebec62d2dae2e5b76ac0ba64ade26d4","price":"0.42","side":"SELL","size":"95"}],"timestamp":"1785204398625"},"payload_hash":"c23f014df6ab56149186e362bfff320188a6157447d3d2db0a2f20c0f9497f38","raw_frame":"{\"market\":\"0xda6f0e0e93fc8469e0159a166028d017bddbc162b86f66bac90391379603d962\", \"price_changes\":[{\"asset_id\":\"39272994714739463168905443499424551362424437245880253267329605556587274644733\", \"price\":\"0.58\", \"size\":\"95\", \"side\":\"BUY\", \"hash\":\"1a0282ca3d1d89d191889ecc9ee399a55a9ecba8\", \"best_bid\":\"0.6\", \"best_ask\":\"0.61\"}, {\"asset_id\":\"20893381255801015515826997628594359667013752732428989472914000440642900266717\", \"price\":\"0.42\", \"size\":\"95\", \"side\":\"SELL\", \"hash\":\"fc90c2ce9ebec62d2dae2e5b76ac0ba64ade26d4\", \"best_bid\":\"0.39\", \"best_ask\":\"0.4\"}], \"timestamp\":\"1785204398625\", \"event_type\":\"price_change\"}","received_at":"2026-07-28T02:06:39.519436Z","schema_version":"clob-market-ws.price_change.v1","sequence":null,"server_hash":null,"server_timestamp":"1785204398625","session_id":"d2757dd6dad94f3b9fe67e8dbf1adc37","source":"clob_market_ws"},"received_at":"2026-07-28T02:06:39.519436Z","record_id":"b6f4921af5e7882534d41da0f470534e8e43a76432075b10791f19ab6ba4d013","schema_fingerprint":"4aa3821a28b0b7c2400bc59aba4bcc0a76e971dadd19610d3ad38c768e124dc7","schema_version":"edge-lab-recorder.raw.v1","sequence":null,"source":"clob_market_ws"}
{"event_at":"2026-07-28T02:06:38.626000Z","event_fingerprint":"37275ded7129a812084b99f31e039c92ae158070aa8448f82a77b6e27186062f","payload":{"connection_id":"5d29200f65794d4d9ab6ef271f045a9b","event_at":"2026-07-28T02:06:38.626000Z","event_type":"price_change","frame_hash":"d865b2ec2f02470af455430c97ff177ebec20db31aa92ba3e46cc53c2a604cfe","frame_index":0,"kind":"data","monotonic_ns":306382531699083,"payload":{"event_type":"price_change","market":"0xda6f0e0e93fc8469e0159a166028d017bddbc162b86f66bac90391379603d962","price_changes":[{"asset_id":"20893381255801015515826997628594359667013752732428989472914000440642900266717","best_ask":"0.4","best_bid":"0.39","hash":"74bf66cf6a07e9df26504fb8c3748a8ee318f60a","price":"0.39","side":"BUY","size":"83"},{"asset_id":"39272994714739463168905443499424551362424437245880253267329605556587274644733","best_ask":"0.61","best_bid":"0.6","hash":"750ef7077b7a366110e7fccb451367bfad155bd3","price":"0.61","side":"SELL","size":"83"}],"timestamp":"1785204398626"},"payload_hash":"f4d385c63e2672b57bb3dd37de5a61067437cdf27bada415df44c7e81276fe3e","raw_frame":"{\"market\":\"0xda6f0e0e93fc8469e0159a166028d017bddbc162b86f66bac90391379603d962\", \"price_changes\":[{\"asset_id\":\"20893381255801015515826997628594359667013752732428989472914000440642900266717\", \"price\":\"0.39\", \"size\":\"83\", \"side\":\"BUY\", \"hash\":\"74bf66cf6a07e9df26504fb8c3748a8ee318f60a\", \"best_bid\":\"0.39\", \"best_ask\":\"0.4\"}, {\"asset_id\":\"39272994714739463168905443499424551362424437245880253267329605556587274644733\", \"price\":\"0.61\", \"size\":\"83\", \"side\":\"SELL\", \"hash\":\"750ef7077b7a366110e7fccb451367bfad155bd3\", \"best_bid\":\"0.6\", \"best_ask\":\"0.61\"}], \"timestamp\":\"1785204398626\", \"event_type\":\"price_change\"}","received_at":"2026-07-28T02:06:39.524692Z","schema_version":"clob-market-ws.price_change.v1","sequence":null,"server_hash":null,"server_timestamp":"1785204398626","session_id":"d2757dd6dad94f3b9fe67e8dbf1adc37","source":"clob_market_ws"},"received_at":"2026-07-28T02:06:39.524692Z","record_id":"9d945ba43b2521b8aed29ff2badc34baa34d4f48b6f3d12a2dbccc52e101daea","schema_fingerprint":"4aa3821a28b0b7c2400bc59aba4bcc0a76e971dadd19610d3ad38c768e124dc7","schema_version":"edge-lab-recorder.raw.v1","sequence":null,"source":"clob_market_ws"}
{"event_at":"2026-07-28T02:06:38.627000Z","event_fingerprint":"00511fe8058894243f505978131de12d71a69071e527f009a5b16466f75e8a0e","payload":{"connection_id":"5d29200f65794d4d9ab6ef271f045a9b","event_at":"2026-07-28T02:06:38.627000Z","event_type":"price_change","frame_hash":"ab9fe0fb8bb8e883f500044eb633293824a43459e13354a1e67e4124eb36940f","frame_index":0,"kind":"data","monotonic_ns":306382536053291,"payload":{"event_type":"price_change","market":"0xda6f0e0e93fc8469e0159a166028d017bddbc162b86f66bac90391379603d962","price_changes":[{"asset_id":"39272994714739463168905443499424551362424437245880253267329605556587274644733","best_ask":"0.61","best_bid":"0.6","hash":"4166a6c32796c2e3ee58e90ae44f25a6b6ca004f","price":"0.53","side":"BUY","size":"87.5"},{"asset_id":"20893381255801015515826997628594359667013752732428989472914000440642900266717","best_ask":"0.4","best_bid":"0.39","hash":"018f3b933e045d3b1a893940c711815f8d95e323","price":"0.47","side":"SELL","size":"87.5"}],"timestamp":"1785204398627"},"payload_hash":"d990a3aa9431d53edccefdaf807012a0e2fe217153500bc37468ee7756cb8947","raw_frame":"{\"market\":\"0xda6f0e0e93fc8469e0159a166028d017bddbc162b86f66bac90391379603d962\", \"price_changes\":[{\"asset_id\":\"39272994714739463168905443499424551362424437245880253267329605556587274644733\", \"price\":\"0.53\", \"size\":\"87.5\", \"side\":\"BUY\", \"hash\":\"4166a6c32796c2e3ee58e90ae44f25a6b6ca004f\", \"best_bid\":\"0.6\", \"best_ask\":\"0.61\"}, {\"asset_id\":\"20893381255801015515826997628594359667013752732428989472914000440642900266717\", \"price\":\"0.47\", \"size\":\"87.5\", \"side\":\"SELL\", \"hash\":\"018f3b933e045d3b1a893940c711815f8d95e323\", \"best_bid\":\"0.39\", \"best_ask\":\"0.4\"}], \"timestamp\":\"1785204398627\", \"event_type\":\"price_change\"}","received_at":"2026-07-28T02:06:39.529046Z","schema_version":"clob-market-ws.price_change.v1","sequence":null,"server_hash":null,"server_timestamp":"1785204398627","session_id":"d2757dd6dad94f3b9fe67e8dbf1adc37","source":"clob_market_ws"},"received_at":"2026-07-28T02:06:39.529046Z","record_id":"d19937ae0f9247eaac7c0bb8527cdb83e38ff954d53b12adf0a0ff7f1743f741","schema_fingerprint":"4aa3821a28b0b7c2400bc59aba4bcc0a76e971dadd19610d3ad38c768e124dc7","schema_version":"edge-lab-recorder.raw.v1","sequence":null,"source":"clob_market_ws"}
{"event_at":"2026-07-28T02:06:38.628000Z","event_fingerprint":"888c394119c7e5926f7f9312b4e62ccde8cbd3ae524977334277e18d08295d63","payload":{"connection_id":"5d29200f65794d4d9ab6ef271f045a9b","event_at":"2026-07-28T02:06:38.628000Z","event_type":"price_change","frame_hash":"5d6c1b41425caceb494ce071435536127367bd8535bda0c038dcf22bfad6d032","frame_index":0,"kind":"data","monotonic_ns":306382543339916,"payload":{"event_type":"price_change","market":"0xda6f0e0e93fc8469e0159a166028d017bddbc162b86f66bac90391379603d962","price_changes":[{"asset_id":"20893381255801015515826997628594359667013752732428989472914000440642900266717","best_ask":"0.4","best_bid":"0.39","hash":"e451e4522875575ac429419cbbcfd7b67e7b13c9","price":"0.22","side":"BUY","size":"198.5"},{"asset_id":"39272994714739463168905443499424551362424437245880253267329605556587274644733","best_ask":"0.61","best_bid":"0.6","hash":"88f348d8e9ffadda73616ea00396ff0ab28fa50d","price":"0.78","side":"SELL","size":"198.5"}],"timestamp":"1785204398628"},"payload_hash":"ec51646da5a29a11a0d65988d7e65f7083efb100b483b31dfb055331106888d4","raw_frame":"{\"market\":\"0xda6f0e0e93fc8469e0159a166028d017bddbc162b86f66bac90391379603d962\", \"price_changes\":[{\"asset_id\":\"20893381255801015515826997628594359667013752732428989472914000440642900266717\", \"price\":\"0.22\", \"size\":\"198.5\", \"side\":\"BUY\", \"hash\":\"e451e4522875575ac429419cbbcfd7b67e7b13c9\", \"best_bid\":\"0.39\", \"best_ask\":\"0.4\"}, {\"asset_id\":\"39272994714739463168905443499424551362424437245880253267329605556587274644733\", \"price\":\"0.78\", \"size\":\"198.5\", \"side\":\"SELL\", \"hash\":\"88f348d8e9ffadda73616ea00396ff0ab28fa50d\", \"best_bid\":\"0.6\", \"best_ask\":\"0.61\"}], \"timestamp\":\"1785204398628\", \"event_type\":\"price_change\"}","received_at":"2026-07-28T02:06:39.536333Z","schema_version":"clob-market-ws.price_change.v1","sequence":null,"server_hash":null,"server_timestamp":"1785204398628","session_id":"d2757dd6dad94f3b9fe67e8dbf1adc37","source":"clob_market_ws"},"received_at":"2026-07-28T02:06:39.536333Z","record_id":"49bb99e3b87571dbd3ab44ee80a5d2b2ea6f88c7ac71e70a836439028015e41e","schema_fingerprint":"4aa3821a28b0b7c2400bc59aba4bcc0a76e971dadd19610d3ad38c768e124dc7","schema_version":"edge-lab-recorder.raw.v1","sequence":null,"source":"clob_market_ws"}
{"event_at":"2026-07-28T02:06:38.628000Z","event_fingerprint":"916447d3e7e0a759f1471afbe2ed1a1756a577ee3b2da5c73d1f26d172ab3abe","payload":{"connection_id":"5d29200f65794d4d9ab6ef271f045a9b","event_at":"2026-07-28T02:06:38.628000Z","event_type":"price_change","frame_hash":"c7b2d7e947949759d0111a2d7221e5d84e559caa8083719aae74d3a262ec4343","frame_index":0,"kind":"data","monotonic_ns":306382548514666,"payload":{"event_type":"price_change","market":"0xda6f0e0e93fc8469e0159a166028d017bddbc162b86f66bac90391379603d962","price_changes":[{"asset_id":"20893381255801015515826997628594359667013752732428989472914000440642900266717","best_ask":"0.4","best_bid":"0.39","hash":"6d55921f9ee435c076d4acd5efd5b5071f1bda56","price":"0.39","side":"BUY","size":"108"},{"asset_id":"39272994714739463168905443499424551362424437245880253267329605556587274644733","best_ask":"0.61","best_bid":"0.6","hash":"6c2d8894cb77c7ee557b2f6466d47d86ed2a084f","price":"0.61","side":"SELL","size":"108"}],"timestamp":"1785204398628"},"payload_hash":"edc811e7a84055dd3272b98c3f00c3ac5e24afcc80f49af3497a036796eae56c","raw_frame":"{\"market\":\"0xda6f0e0e93fc8469e0159a166028d017bddbc162b86f66bac90391379603d962\", \"price_changes\":[{\"asset_id\":\"20893381255801015515826997628594359667013752732428989472914000440642900266717\", \"price\":\"0.39\", \"size\":\"108\", \"side\":\"BUY\", \"hash\":\"6d55921f9ee435c076d4acd5efd5b5071f1bda56\", \"best_bid\":\"0.39\", \"best_ask\":\"0.4\"}, {\"asset_id\":\"39272994714739463168905443499424551362424437245880253267329605556587274644733\", \"price\":\"0.61\", \"size\":\"108\", \"side\":\"SELL\", \"hash\":\"6c2d8894cb77c7ee557b2f6466d47d86ed2a084f\", \"best_bid\":\"0.6\", \"best_ask\":\"0.61\"}], \"timestamp\":\"1785204398628\", \"event_type\":\"price_change\"}","received_at":"2026-07-28T02:06:39.541508Z","schema_version":"clob-market-ws.price_change.v1","sequence":null,"server_hash":null,"server_timestamp":"1785204398628","session_id":"d2757dd6dad94f3b9fe67e8dbf1adc37","source":"clob_market_ws"},"received_at":"2026-07-28T02:06:39.541508Z","record_id":"7888c88554c8c27f3c1fb8f320219f11537aa5e241c8d0bc2aa7030c3b34dfee","schema_fingerprint":"4aa3821a28b0b7c2400bc59aba4bcc0a76e971dadd19610d3ad38c768e124dc7","schema_version":"edge-lab-recorder.raw.v1","sequence":null,"source":"clob_market_ws"}
{"event_at":"2026-07-28T02:06:38.630000Z","event_fingerprint":"73d37dff6ce0cd8dc5772fda9f3bfbf1a2cefba97c244c51159ce3015ae52c11","payload":{"connection_id":"5d29200f65794d4d9ab6ef271f045a9b","event_at":"2026-07-28T02:06:38.630000Z","event_type":"price_change","frame_hash":"2e7e2bc2ab226d77ad34e4ff7a4bd00040f537c25652f00e716f3564fb2b833a","frame_index":0,"kind":"data","monotonic_ns":306382560203541,"payload":{"event_type":"price_change","market":"0xda6f0e0e93fc8469e0159a166028d017bddbc162b86f66bac90391379603d962","price_changes":[{"asset_id":"39272994714739463168905443499424551362424437245880253267329605556587274644733","best_ask":"0.61","best_bid":"0.6","hash":"d7f05c588e31b9aaa0f7aaa857951386ff257c67","price":"0.03","side":"BUY","size":"648.1"},{"asset_id":"20893381255801015515826997628594359667013752732428989472914000440642900266717","best_ask":"0.4","best_bid":"0.39","hash":"2ceeade8c5a33e4a052456d05727f6fad1d27073","price":"0.97","side":"SELL","size":"648.1"}],"timestamp":"1785204398630"},"payload_hash":"6f2c2c837a97ded14a52d1a5649b7772df21998aa25bb870a753b0120fa239cb","raw_frame":"{\"market\":\"0xda6f0e0e93fc8469e0159a166028d017bddbc162b86f66bac90391379603d962\", \"price_changes\":[{\"asset_id\":\"39272994714739463168905443499424551362424437245880253267329605556587274644733\", \"price\":\"0.03\", \"size\":\"648.1\", \"side\":\"BUY\", \"hash\":\"d7f05c588e31b9aaa0f7aaa857951386ff257c67\", \"best_bid\":\"0.6\", \"best_ask\":\"0.61\"}, {\"asset_id\":\"20893381255801015515826997628594359667013752732428989472914000440642900266717\", \"price\":\"0.97\", \"size\":\"648.1\", \"side\":\"SELL\", \"hash\":\"2ceeade8c5a33e4a052456d05727f6fad1d27073\", \"best_bid\":\"0.39\", \"best_ask\":\"0.4\"}], \"timestamp\":\"1785204398630\", \"event_type\":\"price_change\"}","received_at":"2026-07-28T02:06:39.553196Z","schema_version":"clob-market-ws.price_change.v1","sequence":null,"server_hash":null,"server_timestamp":"1785204398630","session_id":"d2757dd6dad94f3b9fe67e8dbf1adc37","source":"clob_market_ws"},"received_at":"2026-07-28T02:06:39.553196Z","record_id":"5ed3591c3a58a627169ac49b8932bae0daf3b9b639b2e06838a64c3c361895a4","schema_fingerprint":"4aa3821a28b0b7c2400bc59aba4bcc0a76e971dadd19610d3ad38c768e124dc7","schema_version":"edge-lab-recorder.raw.v1","sequence":null,"source":"clob_market_ws"}
{"event_at":"2026-07-28T02:06:38.630000Z","event_fingerprint":"86f696491aba697b9235b12605851101ae4a403287757bff8dbb6bb302de3f04","payload":{"connection_id":"5d29200f65794d4d9ab6ef271f045a9b","event_at":"2026-07-28T02:06:38.630000Z","event_type":"price_change","frame_hash":"8c8a1e8732ec13f3089fc40d09313744d02f592e2e448de8d38d76c8efd4188a","frame_index":0,"kind":"data","monotonic_ns":306382564545250,"payload":{"event_type":"price_change","market":"0xda6f0e0e93fc8469e0159a166028d017bddbc162b86f66bac90391379603d962","price_changes":[{"asset_id":"20893381255801015515826997628594359667013752732428989472914000440642900266717","best_ask":"0.4","best_bid":"0.39","hash":"85b1937e344e3a4ccbece1ac0cc648483e2f92a9","price":"0.33","side":"BUY","size":"74.98"},{"asset_id":"39272994714739463168905443499424551362424437245880253267329605556587274644733","best_ask":"0.61","best_bid":"0.6","hash":"bac198368d50126bb08701770d2f90fbf7e20e91","price":"0.67","side":"SELL","size":"74.98"}],"timestamp":"1785204398630"},"payload_hash":"0916721678ea48dd816b429e166bdeae9d69b9ab1655e0ce787a0adbfc2f36c8","raw_frame":"{\"market\":\"0xda6f0e0e93fc8469e0159a166028d017bddbc162b86f66bac90391379603d962\", \"price_changes\":[{\"asset_id\":\"20893381255801015515826997628594359667013752732428989472914000440642900266717\", \"price\":\"0.33\", \"size\":\"74.98\", \"side\":\"BUY\", \"hash\":\"85b1937e344e3a4ccbece1ac0cc648483e2f92a9\", \"best_bid\":\"0.39\", \"best_ask\":\"0.4\"}, {\"asset_id\":\"39272994714739463168905443499424551362424437245880253267329605556587274644733\", \"price\":\"0.67\", \"size\":\"74.98\", \"side\":\"SELL\", \"hash\":\"bac198368d50126bb08701770d2f90fbf7e20e91\", \"best_bid\":\"0.6\", \"best_ask\":\"0.61\"}], \"timestamp\":\"1785204398630\", \"event_type\":\"price_change\"}","received_at":"2026-07-28T02:06:39.557539Z","schema_version":"clob-market-ws.price_change.v1","sequence":null,"server_hash":null,"server_timestamp":"1785204398630","session_id":"d2757dd6dad94f3b9fe67e8dbf1adc37","source":"clob_market_ws"},"received_at":"2026-07-28T02:06:39.557539Z","record_id":"b5048d4add2a72fcb3f1b406f6686d5b973563e67c0448b26813e65ccd31a013","schema_fingerprint":"4aa3821a28b0b7c2400bc59aba4bcc0a76e971dadd19610d3ad38c768e124dc7","schema_version":"edge-lab-recorder.raw.v1","sequence":null,"source":"clob_market_ws"}
{"event_at":"2026-07-28T02:06:38.632000Z","event_fingerprint":"6152dc524160028c28faff0f759f6e4de1567b5e013bf4627acf6388cd24ce4a","payload":{"connection_id":"5d29200f65794d4d9ab6ef271f045a9b","event_at":"2026-07-28T02:06:38.632000Z","event_type":"price_change","frame_hash":"066b4a263c277fef7813c4a280b17d0d50126eb04f7e1724ae961d36e1597817","frame_index":0,"kind":"data","monotonic_ns":306382568820791,"payload":{"event_type":"price_change","market":"0xda6f0e0e93fc8469e0159a166028d017bddbc162b86f66bac90391379603d962","price_changes":[{"asset_id":"20893381255801015515826997628594359667013752732428989472914000440642900266717","best_ask":"0.4","best_bid":"0.39","hash":"fe0e9c1d0ebdbe02b871b1b306f62a21779e8670","price":"0.39","side":"BUY","size":"72"},{"asset_id":"39272994714739463168905443499424551362424437245880253267329605556587274644733","best_ask":"0.61","best_bid":"0.6","hash":"cbe72846d1a35a31582ae5265ffb6bd507288298","price":"0.61","side":"SELL","size":"72"}],"timestamp":"1785204398632"},"payload_hash":"e0908e1ba1dbe8bbea10a7e16002d6df4ba881127d258962b073cdccdd576f55","raw_frame":"{\"market\":\"0xda6f0e0e93fc8469e0159a166028d017bddbc162b86f66bac90391379603d962\", \"price_changes\":[{\"asset_id\":\"20893381255801015515826997628594359667013752732428989472914000440642900266717\", \"price\":\"0.39\", \"size\":\"72\", \"side\":\"BUY\", \"hash\":\"fe0e9c1d0ebdbe02b871b1b306f62a21779e8670\", \"best_bid\":\"0.39\", \"best_ask\":\"0.4\"}, {\"asset_id\":\"39272994714739463168905443499424551362424437245880253267329605556587274644733\", \"price\":\"0.61\", \"size\":\"72\", \"side\":\"SELL\", \"hash\":\"cbe72846d1a35a31582ae5265ffb6bd507288298\", \"best_bid\":\"0.6\", \"best_ask\":\"0.61\"}], \"timestamp\":\"1785204398632\", \"event_type\":\"price_change\"}","received_at":"2026-07-28T02:06:39.561814Z","schema_version":"clob-market-ws.price_change.v1","sequence":null,"server_hash":null,"server_timestamp":"1785204398632","session_id":"d2757dd6dad94f3b9fe67e8dbf1adc37","source":"clob_market_ws"},"received_at":"2026-07-28T02:06:39.561814Z","record_id":"72dbe8b60cf4166796f057bc2e264fb08533df3568d18c3e143326a0f16ac53a","schema_fingerprint":"4aa3821a28b0b7c2400bc59aba4bcc0a76e971dadd19610d3ad38c768e124dc7","schema_version":"edge-lab-recorder.raw.v1","sequence":null,"source":"clob_market_ws"}
{"event_at":"2026-07-28T02:06:38.633000Z","event_fingerprint":"d068d9d9aa9811ac8b3c537bb19640c2f3754a5b4d44a28e71a583ee9e6a7803","payload":{"connection_id":"5d29200f65794d4d9ab6ef271f045a9b","event_at":"2026-07-28T02:06:38.633000Z","event_type":"price_change","frame_hash":"013f071e85e778996bad4ea6d21f76c6bf7fe65cc6e52a7bef1493c9fb315587","frame_index":0,"kind":"data","monotonic_ns":306382573107166,"payload":{"event_type":"price_change","market":"0xda6f0e0e93fc8469e0159a166028d017bddbc162b86f66bac90391379603d962","price_changes":[{"asset_id":"39272994714739463168905443499424551362424437245880253267329605556587274644733","best_ask":"0.61","best_bid":"0.6","hash":"ba0bd3eb4de12827582ad264dafb78f54b2cf857","price":"0.6","side":"BUY","size":"79.2"},{"asset_id":"20893381255801015515826997628594359667013752732428989472914000440642900266717","best_ask":"0.4","best_bid":"0.39","hash":"90bf29f4bb5a253fa8f97f1f9d028180b67806ed","price":"0.4","side":"SELL","size":"79.2"}],"timestamp":"1785204398633"},"payload_hash":"d729de947d53ddabb58b75508fa605f25ec39292c9f7712ef0f2b382c47b6839","raw_frame":"{\"market\":\"0xda6f0e0e93fc8469e0159a166028d017bddbc162b86f66bac90391379603d962\", \"price_changes\":[{\"asset_id\":\"39272994714739463168905443499424551362424437245880253267329605556587274644733\", \"price\":\"0.6\", \"size\":\"79.2\", \"side\":\"BUY\", \"hash\":\"ba0bd3eb4de12827582ad264dafb78f54b2cf857\", \"best_bid\":\"0.6\", \"best_ask\":\"0.61\"}, {\"asset_id\":\"20893381255801015515826997628594359667013752732428989472914000440642900266717\", \"price\":\"0.4\", \"size\":\"79.2\", \"side\":\"SELL\", \"hash\":\"90bf29f4bb5a253fa8f97f1f9d028180b67806ed\", \"best_bid\":\"0.39\", \"best_ask\":\"0.4\"}], \"timestamp\":\"1785204398633\", \"event_type\":\"price_change\"}","received_at":"2026-07-28T02:06:39.566100Z","schema_version":"clob-market-ws.price_change.v1","sequence":null,"server_hash":null,"server_timestamp":"1785204398633","session_id":"d2757dd6dad94f3b9fe67e8dbf1adc37","source":"clob_market_ws"},"received_at":"2026-07-28T02:06:39.566100Z","record_id":"b3016bdae6b743a93ed364b1f8a8e99fe1e9caa5dde448fec84d08c332786b49","schema_fingerprint":"4aa3821a28b0b7c2400bc59aba4bcc0a76e971dadd19610d3ad38c768e124dc7","schema_version":"edge-lab-recorder.raw.v1","sequence":null,"source":"clob_market_ws"}
{"event_at":"2026-07-28T02:06:38.635000Z","event_fingerprint":"e861cecf63e1c2892b59cc033e24dbd504a80cb45a0803607c4f07ae189d6444","payload":{"connection_id":"5d29200f65794d4d9ab6ef271f045a9b","event_at":"2026-07-28T02:06:38.635000Z","event_type":"price_change","frame_hash":"163f05a546748ce897c1b8f79073728d1c2828a041e57d9e7571425d4b90398a","frame_index":0,"kind":"data","monotonic_ns":306382577356250,"payload":{"event_type":"price_change","market":"0xda6f0e0e93fc8469e0159a166028d017bddbc162b86f66bac90391379603d962","price_changes":[{"asset_id":"39272994714739463168905443499424551362424437245880253267329605556587274644733","best_ask":"0.61","best_bid":"0.6","hash":"664e269a74b625bd7721b5e9c8c36a8a262c569f","price":"0.61","side":"SELL","size":"81"},{"asset_id":"20893381255801015515826997628594359667013752732428989472914000440642900266717","best_ask":"0.4","best_bid":"0.39","hash":"03ba083870e63500b3a96b83cd911246703eb5de","price":"0.39","side":"BUY","size":"81"}],"timestamp":"1785204398635"},"payload_hash":"239ceb2b4cc691581aa92c02533587cb1f9f2d83ec66783a08694ff1646f704a","raw_frame":"{\"market\":\"0xda6f0e0e93fc8469e0159a166028d017bddbc162b86f66bac90391379603d962\", \"price_changes\":[{\"asset_id\":\"39272994714739463168905443499424551362424437245880253267329605556587274644733\", \"price\":\"0.61\", \"size\":\"81\", \"side\":\"SELL\", \"hash\":\"664e269a74b625bd7721b5e9c8c36a8a262c569f\", \"best_bid\":\"0.6\", \"best_ask\":\"0.61\"}, {\"asset_id\":\"20893381255801015515826997628594359667013752732428989472914000440642900266717\", \"price\":\"0.39\", \"size\":\"81\", \"side\":\"BUY\", \"hash\":\"03ba083870e63500b3a96b83cd911246703eb5de\", \"best_bid\":\"0.39\", \"best_ask\":\"0.4\"}], \"timestamp\":\"1785204398635\", \"event_type\":\"price_change\"}","received_at":"2026-07-28T02:06:39.570349Z","schema_version":"clob-market-ws.price_change.v1","sequence":null,"server_hash":null,"server_timestamp":"1785204398635","session_id":"d2757dd6dad94f3b9fe67e8dbf1adc37","source":"clob_market_ws"},"received_at":"2026-07-28T02:06:39.570349Z","record_id":"c11d849a1e100e10665b160c06e2ec588d1c70d4731e63402c59ba71a888d942","schema_fingerprint":"4aa3821a28b0b7c2400bc59aba4bcc0a76e971dadd19610d3ad38c768e124dc7","schema_version":"edge-lab-recorder.raw.v1","sequence":null,"source":"clob_market_ws"}
{"event_at":"2026-07-28T02:06:38.639000Z","event_fingerprint":"03a39d8d485e2bc390e5b20ca0cdb3dc32ac22f35bd8d061a68014822fda3edf","payload":{"connection_id":"5d29200f65794d4d9ab6ef271f045a9b","event_at":"2026-07-28T02:06:38.639000Z","event_type":"price_change","frame_hash":"9ba00f2f384e6e823ed0b5f4084c617104ac84fec8e609eaa618a4caf5dcc336","frame_index":0,"kind":"data","monotonic_ns":306382581818958,"payload":{"event_type":"price_change","market":"0xda6f0e0e93fc8469e0159a166028d017bddbc162b86f66bac90391379603d962","price_changes":[{"asset_id":"20893381255801015515826997628594359667013752732428989472914000440642900266717","best_ask":"0.4","best_bid":"0.39","hash":"a355ed196a3e1dce61c5bfdfe20bf0f58c160822","price":"0.25","side":"BUY","size":"202.5"},{"asset_id":"39272994714739463168905443499424551362424437245880253267329605556587274644733","best_ask":"0.61","best_bid":"0.6","hash":"3af0ae3b6ef2236a5eb9ef183d1119f3a17fb678","price":"0.75","side":"SELL","size":"202.5"}],"timestamp":"1785204398639"},"payload_hash":"9078322c0d9b9f8a25c56c155bc3520476576c7b699445cdf1862eeb2d9f9a59","raw_frame":"{\"market\":\"0xda6f0e0e93fc8469e0159a166028d017bddbc162b86f66bac90391379603d962\", \"price_changes\":[{\"asset_id\":\"20893381255801015515826997628594359667013752732428989472914000440642900266717\", \"price\":\"0.25\", \"size\":\"202.5\", \"side\":\"BUY\", \"hash\":\"a355ed196a3e1dce61c5bfdfe20bf0f58c160822\", \"best_bid\":\"0.39\", \"best_ask\":\"0.4\"}, {\"asset_id\":\"39272994714739463168905443499424551362424437245880253267329605556587274644733\", \"price\":\"0.75\", \"size\":\"202.5\", \"side\":\"SELL\", \"hash\":\"3af0ae3b6ef2236a5eb9ef183d1119f3a17fb678\", \"best_bid\":\"0.6\", \"best_ask\":\"0.61\"}], \"timestamp\":\"1785204398639\", \"event_type\":\"price_change\"}","received_at":"2026-07-28T02:06:39.574812Z","schema_version":"clob-market-ws.price_change.v1","sequence":null,"server_hash":null,"server_timestamp":"1785204398639","session_id":"d2757dd6dad94f3b9fe67e8dbf1adc37","source":"clob_market_ws"},"received_at":"2026-07-28T02:06:39.574812Z","record_id":"a0acc5f42e5b26aa9a12f18703af827bf243af2eab3c0f9ad62da10a7fb31280","schema_fingerprint":"4aa3821a28b0b7c2400bc59aba4bcc0a76e971dadd19610d3ad38c768e124dc7","schema_version":"edge-lab-recorder.raw.v1","sequence":null,"source":"clob_market_ws"}
{"event_at":"2026-07-28T02:06:38.647000Z","event_fingerprint":"c743940aab6eb1b119e70fcf124f0cdffd211525d3ac604640ac32bfce5dfec2","payload":{"connection_id":"5d29200f65794d4d9ab6ef271f045a9b","event_at":"2026-07-28T02:06:38.647000Z","event_type":"price_change","frame_hash":"dc61855be12e2c859e3530360290f878c5364aa42374405ee3ea736c5195d175","frame_index":0,"kind":"data","monotonic_ns":306382584753750,"payload":{"event_type":"price_change","market":"0xda6f0e0e93fc8469e0159a166028d017bddbc162b86f66bac90391379603d962","price_changes":[{"asset_id":"20893381255801015515826997628594359667013752732428989472914000440642900266717","best_ask":"0.4","best_bid":"0.39","hash":"70955a1868690ae662d9ffca71726dad5da01c9e","price":"0.37","side":"BUY","size":"59"},{"asset_id":"39272994714739463168905443499424551362424437245880253267329605556587274644733","best_ask":"0.61","best_bid":"0.6","hash":"23b81c40e52c8cb9ba39b82635a15057812ba7ea","price":"0.63","side":"SELL","size":"59"}],"timestamp":"1785204398647"},"payload_hash":"31af2f1b2d520968756fcbdf9b0e7ae767cc1398a862f12828d75c1ef03ab313","raw_frame":"{\"market\":\"0xda6f0e0e93fc8469e0159a166028d017bddbc162b86f66bac90391379603d962\", \"price_changes\":[{\"asset_id\":\"20893381255801015515826997628594359667013752732428989472914000440642900266717\", \"price\":\"0.37\", \"size\":\"59\", \"side\":\"BUY\", \"hash\":\"70955a1868690ae662d9ffca71726dad5da01c9e\", \"best_bid\":\"0.39\", \"best_ask\":\"0.4\"}, {\"asset_id\":\"39272994714739463168905443499424551362424437245880253267329605556587274644733\", \"price\":\"0.63\", \"size\":\"59\", \"side\":\"SELL\", \"hash\":\"23b81c40e52c8cb9ba39b82635a15057812ba7ea\", \"best_bid\":\"0.6\", \"best_ask\":\"0.61\"}], \"timestamp\":\"1785204398647\", \"event_type\":\"price_change\"}","received_at":"2026-07-28T02:06:39.577746Z","schema_version":"clob-market-ws.price_change.v1","sequence":null,"server_hash":null,"server_timestamp":"1785204398647","session_id":"d2757dd6dad94f3b9fe67e8dbf1adc37","source":"clob_market_ws"},"received_at":"2026-07-28T02:06:39.577746Z","record_id":"69b32f8dc5c44aaf435ea5f06042a6f006a57710cdc931a176c349c9959e1663","schema_fingerprint":"4aa3821a28b0b7c2400bc59aba4bcc0a76e971dadd19610d3ad38c768e124dc7","schema_version":"edge-lab-recorder.raw.v1","sequence":null,"source":"clob_market_ws"}
{"event_at":"2026-07-28T02:06:38.647000Z","event_fingerprint":"6a056ca6175636e4021aea24232dcade60b660d54395bce85c33a9aa6a40ab19","payload":{"connection_id":"5d29200f65794d4d9ab6ef271f045a9b","event_at":"2026-07-28T02:06:38.647000Z","event_type":"price_change","frame_hash":"a766ff9219899820431cac12322d8307ece59733e74916716acab4d3175aa627","frame_index":0,"kind":"data","monotonic_ns":306382589183833,"payload":{"event_type":"price_change","market":"0xda6f0e0e93fc8469e0159a166028d017bddbc162b86f66bac90391379603d962","price_changes":[{"asset_id":"20893381255801015515826997628594359667013752732428989472914000440642900266717","best_ask":"0.4","best_bid":"0.39","hash":"1838f708690d47fae85fb3e8e62c45cd1d4fe711","price":"0.39","side":"BUY","size":"56"},{"asset_id":"39272994714739463168905443499424551362424437245880253267329605556587274644733","best_ask":"0.61","best_bid":"0.6","hash":"ab9c52565468ddc4eb907ea337a48b470f7d3f32","price":"0.61","side":"SELL","size":"56"}],"timestamp":"1785204398647"},"payload_hash":"b364577301445d3fbe59cfc3b14bbe4faddb6061aca8314802f4ea90aec49a67","raw_frame":"{\"market\":\"0xda6f0e0e93fc8469e0159a166028d017bddbc162b86f66bac90391379603d962\", \"price_changes\":[{\"asset_id\":\"20893381255801015515826997628594359667013752732428989472914000440642900266717\", \"price\":\"0.39\", \"size\":\"56\", \"side\":\"BUY\", \"hash\":\"1838f708690d47fae85fb3e8e62c45cd1d4fe711\", \"best_bid\":\"0.39\", \"best_ask\":\"0.4\"}, {\"asset_id\":\"39272994714739463168905443499424551362424437245880253267329605556587274644733\", \"price\":\"0.61\", \"size\":\"56\", \"side\":\"SELL\", \"hash\":\"ab9c52565468ddc4eb907ea337a48b470f7d3f32\", \"best_bid\":\"0.6\", \"best_ask\":\"0.61\"}], \"timestamp\":\"1785204398647\", \"event_type\":\"price_change\"}","received_at":"2026-07-28T02:06:39.582177Z","schema_version":"clob-market-ws.price_change.v1","sequence":null,"server_hash":null,"server_timestamp":"1785204398647","session_id":"d2757dd6dad94f3b9fe67e8dbf1adc37","source":"clob_market_ws"},"received_at":"2026-07-28T02:06:39.582177Z","record_id":"045f5afe13c4a0ff70ad7f7171898d73c77b7d75d05fbf83294cf20a396b207e","schema_fingerprint":"4aa3821a28b0b7c2400bc59aba4bcc0a76e971dadd19610d3ad38c768e124dc7","schema_version":"edge-lab-recorder.raw.v1","sequence":null,"source":"clob_market_ws"}
{"event_at":"2026-07-28T02:06:38.649000Z","event_fingerprint":"f883b4af500f1cca1babe4cb81b41c20c3497ac4f5b3c839ff5cdcf5306bf74f","payload":{"connection_id":"5d29200f65794d4d9ab6ef271f045a9b","event_at":"2026-07-28T02:06:38.649000Z","event_type":"price_change","frame_hash":"f5c7db4833936fb2681e48374f14b1c0bd79407961e7560e88f40a22ce24696e","frame_index":0,"kind":"data","monotonic_ns":306382593589666,"payload":{"event_type":"price_change","market":"0xda6f0e0e93fc8469e0159a166028d017bddbc162b86f66bac90391379603d962","price_changes":[{"asset_id":"20893381255801015515826997628594359667013752732428989472914000440642900266717","best_ask":"0.4","best_bid":"0.39","hash":"bfce048d3857b0622c5083d1ddf3ed7f907117b0","price":"0.25","side":"BUY","size":"242.5"},{"asset_id":"39272994714739463168905443499424551362424437245880253267329605556587274644733","best_ask":"0.61","best_bid":"0.6","hash":"12888f3d53dc14943ed2231cf51e310e01c014d7","price":"0.75","side":"SELL","size":"242.5"}],"timestamp":"1785204398649"},"payload_hash":"d98e80ac5510051ae7374f28e93a3ef23af2108608447643a9defb990706f1ad","raw_frame":"{\"market\":\"0xda6f0e0e93fc8469e0159a166028d017bddbc162b86f66bac90391379603d962\", \"price_changes\":[{\"asset_id\":\"20893381255801015515826997628594359667013752732428989472914000440642900266717\", \"price\":\"0.25\", \"size\":\"242.5\", \"side\":\"BUY\", \"hash\":\"bfce048d3857b0622c5083d1ddf3ed7f907117b0\", \"best_bid\":\"0.39\", \"best_ask\":\"0.4\"}, {\"asset_id\":\"39272994714739463168905443499424551362424437245880253267329605556587274644733\", \"price\":\"0.75\", \"size\":\"242.5\", \"side\":\"SELL\", \"hash\":\"12888f3d53dc14943ed2231cf51e310e01c014d7\", \"best_bid\":\"0.6\", \"best_ask\":\"0.61\"}], \"timestamp\":\"1785204398649\", \"event_type\":\"price_change\"}","received_at":"2026-07-28T02:06:39.586582Z","schema_version":"clob-market-ws.price_change.v1","sequence":null,"server_hash":null,"server_timestamp":"1785204398649","session_id":"d2757dd6dad94f3b9fe67e8dbf1adc37","source":"clob_market_ws"},"received_at":"2026-07-28T02:06:39.586582Z","record_id":"5664fd0b79ffef3fda7a5e750c57e6963e7bdd9ace73561c13396d9bbf4df02b","schema_fingerprint":"4aa3821a28b0b7c2400bc59aba4bcc0a76e971dadd19610d3ad38c768e124dc7","schema_version":"edge-lab-recorder.raw.v1","sequence":null,"source":"clob_market_ws"}
{"event_at":"2026-07-28T02:06:38.651000Z","event_fingerprint":"ba6694adc4eec169698647ba6065935d3e0cf42a0d18878b5f66eda1a8556773","payload":{"connection_id":"5d29200f65794d4d9ab6ef271f045a9b","event_at":"2026-07-28T02:06:38.651000Z","event_type":"price_change","frame_hash":"b310a5181663d023b94905f4bee27e1bb53567f909632d36b2ee3f6d3ba02db8","frame_index":0,"kind":"data","monotonic_ns":306382597923916,"payload":{"event_type":"price_change","market":"0xda6f0e0e93fc8469e0159a166028d017bddbc162b86f66bac90391379603d962","price_changes":[{"asset_id":"20893381255801015515826997628594359667013752732428989472914000440642900266717","best_ask":"0.4","best_bid":"0.39","hash":"62a530d130e39d686413bcdeddcb56489d0ebd18","price":"0.39","side":"BUY","size":"66"},{"asset_id":"39272994714739463168905443499424551362424437245880253267329605556587274644733","best_ask":"0.61","best_bid":"0.6","hash":"d02078b4598d324fe4cd5972f3f54fdd957c20a3","price":"0.61","side":"SELL","size":"66"}],"timestamp":"1785204398651"},"payload_hash":"a37d40608d35ba312b626c39345b418ae3672ede341eef2b8572a8819520cff5","raw_frame":"{\"market\":\"0xda6f0e0e93fc8469e0159a166028d017bddbc162b86f66bac90391379603d962\", \"price_changes\":[{\"asset_id\":\"20893381255801015515826997628594359667013752732428989472914000440642900266717\", \"price\":\"0.39\", \"size\":\"66\", \"side\":\"BUY\", \"hash\":\"62a530d130e39d686413bcdeddcb56489d0ebd18\", \"best_bid\":\"0.39\", \"best_ask\":\"0.4\"}, {\"asset_id\":\"39272994714739463168905443499424551362424437245880253267329605556587274644733\", \"price\":\"0.61\", \"size\":\"66\", \"side\":\"SELL\", \"hash\":\"d02078b4598d324fe4cd5972f3f54fdd957c20a3\", \"best_bid\":\"0.6\", \"best_ask\":\"0.61\"}], \"timestamp\":\"1785204398651\", \"event_type\":\"price_change\"}","received_at":"2026-07-28T02:06:39.590916Z","schema_version":"clob-market-ws.price_change.v1","sequence":null,"server_hash":null,"server_timestamp":"1785204398651","session_id":"d2757dd6dad94f3b9fe67e8dbf1adc37","source":"clob_market_ws"},"received_at":"2026-07-28T02:06:39.590916Z","record_id":"19dceaa56c783970d3c2570de69be5e1fe9a064cea25d6001046ea1f09278aef","schema_fingerprint":"4aa3821a28b0b7c2400bc59aba4bcc0a76e971dadd19610d3ad38c768e124dc7","schema_version":"edge-lab-recorder.raw.v1","sequence":null,"source":"clob_market_ws"}
{"event_at":"2026-07-28T02:06:38.653000Z","event_fingerprint":"17aa236ca6c25d4c8a7fcb0d3f78d0193b4c033023325291db1e8b3918d7be9f","payload":{"connection_id":"5d29200f65794d4d9ab6ef271f045a9b","event_at":"2026-07-28T02:06:38.653000Z","event_type":"price_change","frame_hash":"2bea86e602272986cb4eba1c45569ce1103a4229f6e6d40175dd5ad5271316c5","frame_index":0,"kind":"data","monotonic_ns":306382602267375,"payload":{"event_type":"price_change","market":"0xda6f0e0e93fc8469e0159a166028d017bddbc162b86f66bac90391379603d962","price_changes":[{"asset_id":"20893381255801015515826997628594359667013752732428989472914000440642900266717","best_ask":"0.4","best_bid":"0.39","hash":"5d6b561024b6c79e5326dc09621515f90ac99d3f","price":"0.39","side":"BUY","size":"84"},{"asset_id":"39272994714739463168905443499424551362424437245880253267329605556587274644733","best_ask":"0.61","best_bid":"0.6","hash":"027a15de5c6719baadf5cb4af2bf2bb99a945feb","price":"0.61","side":"SELL","size":"84"}],"timestamp":"1785204398653"},"payload_hash":"f0630232e870abc42cd55f44cee370e05e4ccb1e6edd030dd432657d75cc43f5","raw_frame":"{\"market\":\"0xda6f0e0e93fc8469e0159a166028d017bddbc162b86f66bac90391379603d962\", \"price_changes\":[{\"asset_id\":\"20893381255801015515826997628594359667013752732428989472914000440642900266717\", \"price\":\"0.39\", \"size\":\"84\", \"side\":\"BUY\", \"hash\":\"5d6b561024b6c79e5326dc09621515f90ac99d3f\", \"best_bid\":\"0.39\", \"best_ask\":\"0.4\"}, {\"asset_id\":\"39272994714739463168905443499424551362424437245880253267329605556587274644733\", \"price\":\"0.61\", \"size\":\"84\", \"side\":\"SELL\", \"hash\":\"027a15de5c6719baadf5cb4af2bf2bb99a945feb\", \"best_bid\":\"0.6\", \"best_ask\":\"0.61\"}], \"timestamp\":\"1785204398653\", \"event_type\":\"price_change\"}","received_at":"2026-07-28T02:06:39.595260Z","schema_version":"clob-market-ws.price_change.v1","sequence":null,"server_hash":null,"server_timestamp":"1785204398653","session_id":"d2757dd6dad94f3b9fe67e8dbf1adc37","source":"clob_market_ws"},"received_at":"2026-07-28T02:06:39.595260Z","record_id":"9b98dda647f77f8886673693079f707a4226adef2154542215ca82bd88dbe68e","schema_fingerprint":"4aa3821a28b0b7c2400bc59aba4bcc0a76e971dadd19610d3ad38c768e124dc7","schema_version":"edge-lab-recorder.raw.v1","sequence":null,"source":"clob_market_ws"}
{"event_at":"2026-07-28T02:06:38.654000Z","event_fingerprint":"3c5d9e4e0d2ab6991f6bfc571e80b24d2f9242474394a12f7059bec9c81a8280","payload":{"connection_id":"5d29200f65794d4d9ab6ef271f045a9b","event_at":"2026-07-28T02:06:38.654000Z","event_type":"price_change","frame_hash":"cd81a600a2873824649beb318c457be0187ce577dc0d4261b379595f46aa0d23","frame_index":0,"kind":"data","monotonic_ns":306382606556000,"payload":{"event_type":"price_change","market":"0xda6f0e0e93fc8469e0159a166028d017bddbc162b86f66bac90391379603d962","price_changes":[{"asset_id":"39272994714739463168905443499424551362424437245880253267329605556587274644733","best_ask":"0.61","best_bid":"0.6","hash":"33db2b5754d8cc85fbeb092513219d53ddcdc54b","price":"0.53","side":"BUY","size":"80"},{"asset_id":"20893381255801015515826997628594359667013752732428989472914000440642900266717","best_ask":"0.4","best_bid":"0.39","hash":"9bbc2148ec7b0edfb9c4b0c805bfafbb1f74c867","price":"0.47","side":"SELL","size":"80"}],"timestamp":"1785204398654"},"payload_hash":"e0cb53560c24e64273885364c038b8d76d9758f1e929501105ddc50f3eb0c163","raw_frame":"{\"market\":\"0xda6f0e0e93fc8469e0159a166028d017bddbc162b86f66bac90391379603d962\", \"price_changes\":[{\"asset_id\":\"39272994714739463168905443499424551362424437245880253267329605556587274644733\", \"price\":\"0.53\", \"size\":\"80\", \"side\":\"BUY\", \"hash\":\"33db2b5754d8cc85fbeb092513219d53ddcdc54b\", \"best_bid\":\"0.6\", \"best_ask\":\"0.61\"}, {\"asset_id\":\"20893381255801015515826997628594359667013752732428989472914000440642900266717\", \"price\":\"0.47\", \"size\":\"80\", \"side\":\"SELL\", \"hash\":\"9bbc2148ec7b0edfb9c4b0c805bfafbb1f74c867\", \"best_bid\":\"0.39\", \"best_ask\":\"0.4\"}], \"timestamp\":\"1785204398654\", \"event_type\":\"price_change\"}","received_at":"2026-07-28T02:06:39.599549Z","schema_version":"clob-market-ws.price_change.v1","sequence":null,"server_hash":null,"server_timestamp":"1785204398654","session_id":"d2757dd6dad94f3b9fe67e8dbf1adc37","source":"clob_market_ws"},"received_at":"2026-07-28T02:06:39.599549Z","record_id":"69fa63817dd7d47a7f0a7770114824e2d3ef39e84297bbff960814c01732cafe","schema_fingerprint":"4aa3821a28b0b7c2400bc59aba4bcc0a76e971dadd19610d3ad38c768e124dc7","schema_version":"edge-lab-recorder.raw.v1","sequence":null,"source":"clob_market_ws"}
{"event_at":"2026-07-28T02:06:38.655000Z","event_fingerprint":"e0ce999a8ef3fbb74cf1fdc2c3d5ea7320991de664082a37f26d72acab024d79","payload":{"connection_id":"5d29200f65794d4d9ab6ef271f045a9b","event_at":"2026-07-28T02:06:38.655000Z","event_type":"price_change","frame_hash":"fed2f9166d23eb84ecf47a1649cfadc0c00e6e0f81fb5f4510f22025a5a2b788","frame_index":0,"kind":"data","monotonic_ns":306382611116625,"payload":{"event_type":"price_change","market":"0xda6f0e0e93fc8469e0159a166028d017bddbc162b86f66bac90391379603d962","price_changes":[{"asset_id":"20893381255801015515826997628594359667013752732428989472914000440642900266717","best_ask":"0.4","best_bid":"0.39","hash":"f45fb03166917eb665a2ed341b9f0d11af0ea934","price":"0.39","side":"BUY","size":"62"},{"asset_id":"39272994714739463168905443499424551362424437245880253267329605556587274644733","best_ask":"0.61","best_bid":"0.6","hash":"e999126d2c71c113466972b568d8c7aae05b4f28","price":"0.61","side":"SELL","size":"62"}],"timestamp":"1785204398655"},"payload_hash":"521afb01c14d28d5525c8ca5f0aa0a73510bd9262d766811e812617c72b9901b","raw_frame":"{\"market\":\"0xda6f0e0e93fc8469e0159a166028d017bddbc162b86f66bac90391379603d962\", \"price_changes\":[{\"asset_id\":\"20893381255801015515826997628594359667013752732428989472914000440642900266717\", \"price\":\"0.39\", \"size\":\"62\", \"side\":\"BUY\", \"hash\":\"f45fb03166917eb665a2ed341b9f0d11af0ea934\", \"best_bid\":\"0.39\", \"best_ask\":\"0.4\"}, {\"asset_id\":\"39272994714739463168905443499424551362424437245880253267329605556587274644733\", \"price\":\"0.61\", \"size\":\"62\", \"side\":\"SELL\", \"hash\":\"e999126d2c71c113466972b568d8c7aae05b4f28\", \"best_bid\":\"0.6\", \"best_ask\":\"0.61\"}], \"timestamp\":\"1785204398655\", \"event_type\":\"price_change\"}","received_at":"2026-07-28T02:06:39.604107Z","schema_version":"clob-market-ws.price_change.v1","sequence":null,"server_hash":null,"server_timestamp":"1785204398655","session_id":"d2757dd6dad94f3b9fe67e8dbf1adc37","source":"clob_market_ws"},"received_at":"2026-07-28T02:06:39.604107Z","record_id":"e1a7ddf0cd134a7a11ab3b07a5942788d288558c714367f109e9fd7dac7ab7b5","schema_fingerprint":"4aa3821a28b0b7c2400bc59aba4bcc0a76e971dadd19610d3ad38c768e124dc7","schema_version":"edge-lab-recorder.raw.v1","sequence":null,"source":"clob_market_ws"}
{"event_at":"2026-07-28T02:06:38.657000Z","event_fingerprint":"6db72b2d8f816064488d07c8b3c6649ce3c59241fdf94e283e1945051bdf6ded","payload":{"connection_id":"5d29200f65794d4d9ab6ef271f045a9b","event_at":"2026-07-28T02:06:38.657000Z","event_type":"price_change","frame_hash":"300e5fa116e67d7dbe3f505508326544f731b8a8dcbd9266912edc977d2fdf3d","frame_index":0,"kind":"data","monotonic_ns":306382615542083,"payload":{"event_type":"price_change","market":"0xda6f0e0e93fc8469e0159a166028d017bddbc162b86f66bac90391379603d962","price_changes":[{"asset_id":"20893381255801015515826997628594359667013752732428989472914000440642900266717","best_ask":"0.4","best_bid":"0.39","hash":"ef203b371b08bb46910631412217c547deb69bc8","price":"0.39","side":"BUY","size":"37"},{"asset_id":"39272994714739463168905443499424551362424437245880253267329605556587274644733","best_ask":"0.61","best_bid":"0.6","hash":"4ade94ad04ed15419e0142ae961b06951a42c00f","price":"0.61","side":"SELL","size":"37"}],"timestamp":"1785204398657"},"payload_hash":"eeaedf128661b78627e599e6cfa93a703dc87b5203ee629c4cfdd2586b3904f0","raw_frame":"{\"market\":\"0xda6f0e0e93fc8469e0159a166028d017bddbc162b86f66bac90391379603d962\", \"price_changes\":[{\"asset_id\":\"20893381255801015515826997628594359667013752732428989472914000440642900266717\", \"price\":\"0.39\", \"size\":\"37\", \"side\":\"BUY\", \"hash\":\"ef203b371b08bb46910631412217c547deb69bc8\", \"best_bid\":\"0.39\", \"best_ask\":\"0.4\"}, {\"asset_id\":\"39272994714739463168905443499424551362424437245880253267329605556587274644733\", \"price\":\"0.61\", \"size\":\"37\", \"side\":\"SELL\", \"hash\":\"4ade94ad04ed15419e0142ae961b06951a42c00f\", \"best_bid\":\"0.6\", \"best_ask\":\"0.61\"}], \"timestamp\":\"1785204398657\", \"event_type\":\"price_change\"}","received_at":"2026-07-28T02:06:39.608535Z","schema_version":"clob-market-ws.price_change.v1","sequence":null,"server_hash":null,"server_timestamp":"1785204398657","session_id":"d2757dd6dad94f3b9fe67e8dbf1adc37","source":"clob_market_ws"},"received_at":"2026-07-28T02:06:39.608535Z","record_id":"49297ca0bde5ed90b5ebca48904662e04c778ef60dae127b8f30e323783eb617","schema_fingerprint":"4aa3821a28b0b7c2400bc59aba4bcc0a76e971dadd19610d3ad38c768e124dc7","schema_version":"edge-lab-recorder.raw.v1","sequence":null,"source":"clob_market_ws"}
{"event_at":"2026-07-28T02:06:38.658000Z","event_fingerprint":"38e84ea07a1b49e9d644f0b87a9d3a65c4ec5a46a9303d2c9b6c552dc1104a83","payload":{"connection_id":"5d29200f65794d4d9ab6ef271f045a9b","event_at":"2026-07-28T02:06:38.658000Z","event_type":"price_change","frame_hash":"eef3a929fdd0c81d2fccfca2a78a9f11c1090b7ecee52ccef03c81f5a0746f2a","frame_index":0,"kind":"data","monotonic_ns":306382619887166,"payload":{"event_type":"price_change","market":"0xda6f0e0e93fc8469e0159a166028d017bddbc162b86f66bac90391379603d962","price_changes":[{"asset_id":"39272994714739463168905443499424551362424437245880253267329605556587274644733","best_ask":"0.61","best_bid":"0.6","hash":"17011ddd3572216880f8905e13c59b8193714c44","price":"0.61","side":"SELL","size":"50"},{"asset_id":"20893381255801015515826997628594359667013752732428989472914000440642900266717","best_ask":"0.4","best_bid":"0.39","hash":"51d110ff05b160208a349d233436d716bd8cb0cf","price":"0.39","side":"BUY","size":"50"}],"timestamp":"1785204398658"},"payload_hash":"e08930b09379204e0afec53b6a9ccd2d115c40dee062143948a41b7d807773ef","raw_frame":"{\"market\":\"0xda6f0e0e93fc8469e0159a166028d017bddbc162b86f66bac90391379603d962\", \"price_changes\":[{\"asset_id\":\"39272994714739463168905443499424551362424437245880253267329605556587274644733\", \"price\":\"0.61\", \"size\":\"50\", \"side\":\"SELL\", \"hash\":\"17011ddd3572216880f8905e13c59b8193714c44\", \"best_bid\":\"0.6\", \"best_ask\":\"0.61\"}, {\"asset_id\":\"20893381255801015515826997628594359667013752732428989472914000440642900266717\", \"price\":\"0.39\", \"size\":\"50\", \"side\":\"BUY\", \"hash\":\"51d110ff05b160208a349d233436d716bd8cb0cf\", \"best_bid\":\"0.39\", \"best_ask\":\"0.4\"}], \"timestamp\":\"1785204398658\", \"event_type\":\"price_change\"}","received_at":"2026-07-28T02:06:39.612878Z","schema_version":"clob-market-ws.price_change.v1","sequence":null,"server_hash":null,"server_timestamp":"1785204398658","session_id":"d2757dd6dad94f3b9fe67e8dbf1adc37","source":"clob_market_ws"},"received_at":"2026-07-28T02:06:39.612878Z","record_id":"8714a3fd8ba220c9d65d0b349b00c1ba56ca8f5291c00e86cf6552cba4a42e57","schema_fingerprint":"4aa3821a28b0b7c2400bc59aba4bcc0a76e971dadd19610d3ad38c768e124dc7","schema_version":"edge-lab-recorder.raw.v1","sequence":null,"source":"clob_market_ws"}
{"event_at":"2026-07-28T02:06:38.663000Z","event_fingerprint":"9462d6919eca094f243067025914a2c793e568716dbbee2e037690bec78ef0df","payload":{"connection_id":"5d29200f65794d4d9ab6ef271f045a9b","event_at":"2026-07-28T02:06:38.663000Z","event_type":"best_bid_ask","frame_hash":"023d201c508fe1310c6833bb33c02130beafdc41691c1f48ba9d2fddbac9330f","frame_index":0,"kind":"data","monotonic_ns":306382624148083,"payload":{"asset_id":"20893381255801015515826997628594359667013752732428989472914000440642900266717","best_ask":"0.4","best_bid":"0.39","event_type":"best_bid_ask","market":"0xda6f0e0e93fc8469e0159a166028d017bddbc162b86f66bac90391379603d962","spread":"0.01","timestamp":"1785204398663"},"payload_hash":"bb5725f100cfca343d6a6c1f77977aacea4fa19fb10aa497c4290b2d61ed2f0a","raw_frame":"{\"market\":\"0xda6f0e0e93fc8469e0159a166028d017bddbc162b86f66bac90391379603d962\", \"asset_id\":\"20893381255801015515826997628594359667013752732428989472914000440642900266717\", \"best_bid\":\"0.39\", \"best_ask\":\"0.4\", \"spread\":\"0.01\", \"timestamp\":\"1785204398663\", \"event_type\":\"best_bid_ask\"}","received_at":"2026-07-28T02:06:39.617140Z","schema_version":"clob-market-ws.best_bid_ask.v1","sequence":null,"server_hash":null,"server_timestamp":"1785204398663","session_id":"d2757dd6dad94f3b9fe67e8dbf1adc37","source":"clob_market_ws"},"received_at":"2026-07-28T02:06:39.617140Z","record_id":"d9f66b812a6c20f75eae2f3b6e36e899c4eaa6d275fb9e55d8747f75b16d1eae","schema_fingerprint":"8488399f31b0337811b13b266be932db7062827c2470b78bd8e9e99bab51d17d","schema_version":"edge-lab-recorder.raw.v1","sequence":null,"source":"clob_market_ws"}
{"event_at":"2026-07-28T02:06:38.663000Z","event_fingerprint":"1806fad216c87fedd8db72dccf230ec69bd675dcdc0a5fd4abf7f8b00bde19da","payload":{"connection_id":"5d29200f65794d4d9ab6ef271f045a9b","event_at":"2026-07-28T02:06:38.663000Z","event_type":"best_bid_ask","frame_hash":"de78328f63a0730f3d84941b3d89db677b1f51353d7b782fbe0fe220f5999732","frame_index":0,"kind":"data","monotonic_ns":306382628249041,"payload":{"asset_id":"39272994714739463168905443499424551362424437245880253267329605556587274644733","best_ask":"0.61","best_bid":"0.6","event_type":"best_bid_ask","market":"0xda6f0e0e93fc8469e0159a166028d017bddbc162b86f66bac90391379603d962","spread":"0.01","timestamp":"1785204398663"},"payload_hash":"6bbcad6a8cb49fbb269ffbbc7442a854aeb1b7585f732be5b59c38f5617152c1","raw_frame":"{\"market\":\"0xda6f0e0e93fc8469e0159a166028d017bddbc162b86f66bac90391379603d962\", \"asset_id\":\"39272994714739463168905443499424551362424437245880253267329605556587274644733\", \"best_bid\":\"0.6\", \"best_ask\":\"0.61\", \"spread\":\"0.01\", \"timestamp\":\"1785204398663\", \"event_type\":\"best_bid_ask\"}","received_at":"2026-07-28T02:06:39.621241Z","schema_version":"clob-market-ws.best_bid_ask.v1","sequence":null,"server_hash":null,"server_timestamp":"1785204398663","session_id":"d2757dd6dad94f3b9fe67e8dbf1adc37","source":"clob_market_ws"},"received_at":"2026-07-28T02:06:39.621241Z","record_id":"8dff780e924418133c83259eb01d17d2b12277bde448d1b126a93e8065e0bc47","schema_fingerprint":"8488399f31b0337811b13b266be932db7062827c2470b78bd8e9e99bab51d17d","schema_version":"edge-lab-recorder.raw.v1","sequence":null,"source":"clob_market_ws"}
{"event_at":"2026-07-28T02:06:38.662000Z","event_fingerprint":"115e5f0260f6a213625381dc99af2130c5af4a431bac74ad39f78df64b6c7a91","payload":{"connection_id":"5d29200f65794d4d9ab6ef271f045a9b","event_at":"2026-07-28T02:06:38.662000Z","event_type":"price_change","frame_hash":"270574a6daf97f827e0845ebefedd610ab26ecec801bc256fe61df2457b9fa79","frame_index":0,"kind":"data","monotonic_ns":306382632114208,"payload":{"event_type":"price_change","market":"0xda6f0e0e93fc8469e0159a166028d017bddbc162b86f66bac90391379603d962","price_changes":[{"asset_id":"39272994714739463168905443499424551362424437245880253267329605556587274644733","best_ask":"0.61","best_bid":"0.6","hash":"7a3a6350a492cadcdf056a57ea185afdeeaee7c5","price":"0.6","side":"BUY","size":"79.18"},{"asset_id":"20893381255801015515826997628594359667013752732428989472914000440642900266717","best_ask":"0.4","best_bid":"0.39","hash":"0f05ef28d4778a96f8761b34e494087a3b1c175d","price":"0.4","side":"SELL","size":"79.18"}],"timestamp":"1785204398662"},"payload_hash":"be15f0dfeb6d349144e64ad007234447414374804914823ce4d3d0f91b09d7e7","raw_frame":"{\"market\":\"0xda6f0e0e93fc8469e0159a166028d017bddbc162b86f66bac90391379603d962\", \"price_changes\":[{\"asset_id\":\"39272994714739463168905443499424551362424437245880253267329605556587274644733\", \"price\":\"0.6\", \"size\":\"79.18\", \"side\":\"BUY\", \"hash\":\"7a3a6350a492cadcdf056a57ea185afdeeaee7c5\", \"best_bid\":\"0.6\", \"best_ask\":\"0.61\"}, {\"asset_id\":\"20893381255801015515826997628594359667013752732428989472914000440642900266717\", \"price\":\"0.4\", \"size\":\"79.18\", \"side\":\"SELL\", \"hash\":\"0f05ef28d4778a96f8761b34e494087a3b1c175d\", \"best_bid\":\"0.39\", \"best_ask\":\"0.4\"}], \"timestamp\":\"1785204398662\", \"event_type\":\"price_change\"}","received_at":"2026-07-28T02:06:39.625107Z","schema_version":"clob-market-ws.price_change.v1","sequence":null,"server_hash":null,"server_timestamp":"1785204398662","session_id":"d2757dd6dad94f3b9fe67e8dbf1adc37","source":"clob_market_ws"},"received_at":"2026-07-28T02:06:39.625107Z","record_id":"eacd154c5016592ddd484cfd0eb7b5fe0239ab8b4e3cfb11bdc3f12f04d6d81a","schema_fingerprint":"4aa3821a28b0b7c2400bc59aba4bcc0a76e971dadd19610d3ad38c768e124dc7","schema_version":"edge-lab-recorder.raw.v1","sequence":null,"source":"clob_market_ws"}
{"event_at":null,"event_fingerprint":"8ce69173e3daef07b40d2a13371a0c1067d0254b3c1f313c6b93f39da4fbfcc2","payload":{"connection_id":"5d29200f65794d4d9ab6ef271f045a9b","detail":{"current_server_timestamp":"1785204398662","entity":"clob_market_ws:20893381255801015515826997628594359667013752732428989472914000440642900266717","previous_server_timestamp":"1785204398663"},"event_type":"anomaly.time_regression","kind":"diagnostic","monotonic_ns":306382636830708,"received_at":"2026-07-28T02:06:39.629823Z","schema_version":"edge-lab-recorder.anomaly.v1","session_id":"d2757dd6dad94f3b9fe67e8dbf1adc37","source":"clob_market_ws","trigger_frame_hash":"739302fd66f9e4db10d263538e8ae2151d3bb6544d553d7faa9de2559ea80f34","trigger_server_hash":"0f05ef28d4778a96f8761b34e494087a3b1c175d"},"received_at":"2026-07-28T02:06:39.629823Z","record_id":"37ff9d7aa6209d3ee4482b73f9c34f0c6eba746e0ef78c4e73fcfc6cf45ba9e8","schema_fingerprint":"cb1780324c96914017c24d4692a681315845f9745a5a4a3a289c5a43388b35c3","schema_version":"edge-lab-recorder.raw.v1","sequence":null,"source":"clob_market_ws"}
{"event_at":"2026-07-28T02:06:38.662000Z","event_fingerprint":"3aa0088a1f154e3339ed43ae0805b135d1508e5abe70150fd59909584f944fd4","payload":{"connection_id":"5d29200f65794d4d9ab6ef271f045a9b","event_at":"2026-07-28T02:06:38.662000Z","event_type":"book","frame_hash":"739302fd66f9e4db10d263538e8ae2151d3bb6544d553d7faa9de2559ea80f34","frame_index":0,"kind":"data","monotonic_ns":306382636441541,"payload":{"asks":[{"price":"0.99","size":"5608.02"},{"price":"0.98","size":"688.1"},{"price":"0.97","size":"648.1"},{"price":"0.96","size":"588.09"},{"price":"0.95","size":"723.2"},{"price":"0.94","size":"583.2"},{"price":"0.93","size":"546.1"},{"price":"0.92","size":"550.79"},{"price":"0.91","size":"566.6"},{"price":"0.9","size":"223.29"},{"price":"0.89","size":"30.6"},{"price":"0.88","size":"68.4"},{"price":"0.87","size":"26.5"},{"price":"0.86","size":"24.9"},{"price":"0.85","size":"114.17"},{"price":"0.84","size":"32.3"},{"price":"0.83","size":"21.3"},{"price":"0.82","size":"50.3"},{"price":"0.81","size":"19.5"},{"price":"0.8","size":"68.8"},{"price":"0.79","size":"48.1"},{"price":"0.78","size":"24.5"},{"price":"0.77","size":"23.89"},{"price":"0.76","size":"53.39"},{"price":"0.75","size":"66"},{"price":"0.74","size":"21.6"},{"price":"0.73","size":"51.2"},{"price":"0.72","size":"20.9"},{"price":"0.71","size":"20.6"},{"price":"0.7","size":"118.3"},{"price":"0.69","size":"64"},{"price":"0.68","size":"63.8"},{"price":"0.67","size":"93.6"},{"price":"0.66","size":"63.4"},{"price":"0.65","size":"92.2"},{"price":"0.64","size":"92"},{"price":"0.63","size":"61.9"},{"price":"0.62","size":"61.7"},{"price":"0.61","size":"91.6"},{"price":"0.6","size":"84.5"},{"price":"0.59","size":"61.4"},{"price":"0.58","size":"91.3"},{"price":"0.57","size":"61.2"},{"price":"0.56","size":"61.2"},{"price":"0.55","size":"95"},{"price":"0.54","size":"49"},{"price":"0.53","size":"49"},{"price":"0.52","size":"80.05"},{"price":"0.51","size":"59"},{"price":"0.5","size":"263.98"},{"price":"0.49","size":"79"},{"price":"0.48","size":"59"},{"price":"0.47","size":"80"},{"price":"0.46","size":"91.06"},{"price":"0.45","size":"161.09"},{"price":"0.44","size":"93.12"},{"price":"0.43","size":"75.19"},{"price":"0.42","size":"95"},{"price":"0.41","size":"55"},{"price":"0.4","size":"79.18"}],"asset_id":"20893381255801015515826997628594359667013752732428989472914000440642900266717","bids":[{"price":"0.01","size":"5672.02"},{"price":"0.02","size":"822.1"},{"price":"0.03","size":"662.1"},{"price":"0.04","size":"662.09"},{"price":"0.05","size":"793.2"},{"price":"0.06","size":"619.2"},{"price":"0.07","size":"425.1"},{"price":"0.08","size":"361.79"},{"price":"0.09","size":"317.6"},{"price":"0.1","size":"401.29"},{"price":"0.11","size":"269.6"},{"price":"0.12","size":"261.4"},{"price":"0.13","size":"265.5"},{"price":"0.14","size":"221.9"},{"price":"0.15","size":"257.5"},{"price":"0.16","size":"240.3"},{"price":"0.17","size":"292.3"},{"price":"0.18","size":"295.3"},{"price":"0.19","size":"841.79"},{"price":"0.2","size":"278.8"},{"price":"0.21","size":"173.1"},{"price":"0.22","size":"198.5"},{"price":"0.23","size":"171.89"},{"price":"0.24","size":"167.39"},{"price":"0.25","size":"242.5"},{"price":"0.26","size":"165.6"},{"price":"0.27","size":"162.2"},{"price":"0.28","size":"214.9"},{"price":"0.29","size":"313.6"},{"price":"0.3","size":"90.33"},{"price":"0.31","size":"102"},{"price":"0.32","size":"72.57"},{"price":"0.33","size":"74.98"},{"price":"0.34","size":"97.41"},{"price":"0.35","size":"84.2"},{"price":"0.36","size":"84.2"},{"price":"0.37","size":"59"},{"price":"0.38","size":"44"},{"price":"0.39","size":"50"}],"event_type":"book","hash":"0f05ef28d4778a96f8761b34e494087a3b1c175d","market":"0xda6f0e0e93fc8469e0159a166028d017bddbc162b86f66bac90391379603d962","timestamp":"1785204398662"},"payload_hash":"4e513d776a76b4d601d58216e64c4aef6a2daf9e301803142a1c88021c843528","raw_frame":"{\"market\":\"0xda6f0e0e93fc8469e0159a166028d017bddbc162b86f66bac90391379603d962\", \"asset_id\":\"20893381255801015515826997628594359667013752732428989472914000440642900266717\", \"bids\":[{\"price\":\"0.01\", \"size\":\"5672.02\"}, {\"price\":\"0.02\", \"size\":\"822.1\"}, {\"price\":\"0.03\", \"size\":\"662.1\"}, {\"price\":\"0.04\", \"size\":\"662.09\"}, {\"price\":\"0.05\", \"size\":\"793.2\"}, {\"price\":\"0.06\", \"size\":\"619.2\"}, {\"price\":\"0.07\", \"size\":\"425.1\"}, {\"price\":\"0.08\", \"size\":\"361.79\"}, {\"price\":\"0.09\", \"size\":\"317.6\"}, {\"price\":\"0.1\", \"size\":\"401.29\"}, {\"price\":\"0.11\", \"size\":\"269.6\"}, {\"price\":\"0.12\", \"size\":\"261.4\"}, {\"price\":\"0.13\", \"size\":\"265.5\"}, {\"price\":\"0.14\", \"size\":\"221.9\"}, {\"price\":\"0.15\", \"size\":\"257.5\"}, {\"price\":\"0.16\", \"size\":\"240.3\"}, {\"price\":\"0.17\", \"size\":\"292.3\"}, {\"price\":\"0.18\", \"size\":\"295.3\"}, {\"price\":\"0.19\", \"size\":\"841.79\"}, {\"price\":\"0.2\", \"size\":\"278.8\"}, {\"price\":\"0.21\", \"size\":\"173.1\"}, {\"price\":\"0.22\", \"size\":\"198.5\"}, {\"price\":\"0.23\", \"size\":\"171.89\"}, {\"price\":\"0.24\", \"size\":\"167.39\"}, {\"price\":\"0.25\", \"size\":\"242.5\"}, {\"price\":\"0.26\", \"size\":\"165.6\"}, {\"price\":\"0.27\", \"size\":\"162.2\"}, {\"price\":\"0.28\", \"size\":\"214.9\"}, {\"price\":\"0.29\", \"size\":\"313.6\"}, {\"price\":\"0.3\", \"size\":\"90.33\"}, {\"price\":\"0.31\", \"size\":\"102\"}, {\"price\":\"0.32\", \"size\":\"72.57\"}, {\"price\":\"0.33\", \"size\":\"74.98\"}, {\"price\":\"0.34\", \"size\":\"97.41\"}, {\"price\":\"0.35\", \"size\":\"84.2\"}, {\"price\":\"0.36\", \"size\":\"84.2\"}, {\"price\":\"0.37\", \"size\":\"59\"}, {\"price\":\"0.38\", \"size\":\"44\"}, {\"price\":\"0.39\", \"size\":\"50\"}], \"asks\":[{\"price\":\"0.99\", \"size\":\"5608.02\"}, {\"price\":\"0.98\", \"size\":\"688.1\"}, {\"price\":\"0.97\", \"size\":\"648.1\"}, {\"price\":\"0.96\", \"size\":\"588.09\"}, {\"price\":\"0.95\", \"size\":\"723.2\"}, {\"price\":\"0.94\", \"size\":\"583.2\"}, {\"price\":\"0.93\", \"size\":\"546.1\"}, {\"price\":\"0.92\", \"size\":\"550.79\"}, {\"price\":\"0.91\", \"size\":\"566.6\"}, {\"price\":\"0.9\", \"size\":\"223.29\"}, {\"price\":\"0.89\", \"size\":\"30.6\"}, {\"price\":\"0.88\", \"size\":\"68.4\"}, {\"price\":\"0.87\", \"size\":\"26.5\"}, {\"price\":\"0.86\", \"size\":\"24.9\"}, {\"price\":\"0.85\", \"size\":\"114.17\"}, {\"price\":\"0.84\", \"size\":\"32.3\"}, {\"price\":\"0.83\", \"size\":\"21.3\"}, {\"price\":\"0.82\", \"size\":\"50.3\"}, {\"price\":\"0.81\", \"size\":\"19.5\"}, {\"price\":\"0.8\", \"size\":\"68.8\"}, {\"price\":\"0.79\", \"size\":\"48.1\"}, {\"price\":\"0.78\", \"size\":\"24.5\"}, {\"price\":\"0.77\", \"size\":\"23.89\"}, {\"price\":\"0.76\", \"size\":\"53.39\"}, {\"price\":\"0.75\", \"size\":\"66\"}, {\"price\":\"0.74\", \"size\":\"21.6\"}, {\"price\":\"0.73\", \"size\":\"51.2\"}, {\"price\":\"0.72\", \"size\":\"20.9\"}, {\"price\":\"0.71\", \"size\":\"20.6\"}, {\"price\":\"0.7\", \"size\":\"118.3\"}, {\"price\":\"0.69\", \"size\":\"64\"}, {\"price\":\"0.68\", \"size\":\"63.8\"}, {\"price\":\"0.67\", \"size\":\"93.6\"}, {\"price\":\"0.66\", \"size\":\"63.4\"}, {\"price\":\"0.65\", \"size\":\"92.2\"}, {\"price\":\"0.64\", \"size\":\"92\"}, {\"price\":\"0.63\", \"size\":\"61.9\"}, {\"price\":\"0.62\", \"size\":\"61.7\"}, {\"price\":\"0.61\", \"size\":\"91.6\"}, {\"price\":\"0.6\", \"size\":\"84.5\"}, {\"price\":\"0.59\", \"size\":\"61.4\"}, {\"price\":\"0.58\", \"size\":\"91.3\"}, {\"price\":\"0.57\", \"size\":\"61.2\"}, {\"price\":\"0.56\", \"size\":\"61.2\"}, {\"price\":\"0.55\", \"size\":\"95\"}, {\"price\":\"0.54\", \"size\":\"49\"}, {\"price\":\"0.53\", \"size\":\"49\"}, {\"price\":\"0.52\", \"size\":\"80.05\"}, {\"price\":\"0.51\", \"size\":\"59\"}, {\"price\":\"0.5\", \"size\":\"263.98\"}, {\"price\":\"0.49\", \"size\":\"79\"}, {\"price\":\"0.48\", \"size\":\"59\"}, {\"price\":\"0.47\", \"size\":\"80\"}, {\"price\":\"0.46\", \"size\":\"91.06\"}, {\"price\":\"0.45\", \"size\":\"161.09\"}, {\"price\":\"0.44\", \"size\":\"93.12\"}, {\"price\":\"0.43\", \"size\":\"75.19\"}, {\"price\":\"0.42\", \"size\":\"95\"}, {\"price\":\"0.41\", \"size\":\"55\"}, {\"price\":\"0.4\", \"size\":\"79.18\"}], \"hash\":\"0f05ef28d4778a96f8761b34e494087a3b1c175d\", \"timestamp\":\"1785204398662\", \"event_type\":\"book\"}","received_at":"2026-07-28T02:06:39.629434Z","schema_version":"clob-market-ws.book.v1","sequence":null,"server_hash":"0f05ef28d4778a96f8761b34e494087a3b1c175d","server_timestamp":"1785204398662","session_id":"d2757dd6dad94f3b9fe67e8dbf1adc37","source":"clob_market_ws"},"received_at":"2026-07-28T02:06:39.629434Z","record_id":"2f38b07296b39049657a3bdec6b720eb55e72da4a34cab106dd7c20a7c20f972","schema_fingerprint":"dc2caa1c89c6a7426e2e07ff925910cd4d0a8a223a515d4092d91d6d127aacb6","schema_version":"edge-lab-recorder.raw.v1","sequence":null,"source":"clob_market_ws"}
{"event_at":null,"event_fingerprint":"65f964ef70a3fc57e519851b11ad6286279838a527562cf0cf3fd9e901562e06","payload":{"connection_id":"5d29200f65794d4d9ab6ef271f045a9b","detail":{"current_server_timestamp":"1785204398662","entity":"clob_market_ws:39272994714739463168905443499424551362424437245880253267329605556587274644733","previous_server_timestamp":"1785204398663"},"event_type":"anomaly.time_regression","kind":"diagnostic","monotonic_ns":306382655288500,"received_at":"2026-07-28T02:06:39.648281Z","schema_version":"edge-lab-recorder.anomaly.v1","session_id":"d2757dd6dad94f3b9fe67e8dbf1adc37","source":"clob_market_ws","trigger_frame_hash":"79050c4461cc1de6170d6756778eb5599f684098ecacf080eca0d3b2dad586a9","trigger_server_hash":"7a3a6350a492cadcdf056a57ea185afdeeaee7c5"},"received_at":"2026-07-28T02:06:39.648281Z","record_id":"9a1c3f4845ab6763cc1de3231e9d35387e57f84e8a4da0c368904c4847142e39","schema_fingerprint":"cb1780324c96914017c24d4692a681315845f9745a5a4a3a289c5a43388b35c3","schema_version":"edge-lab-recorder.raw.v1","sequence":null,"source":"clob_market_ws"}
{"event_at":"2026-07-28T02:06:38.662000Z","event_fingerprint":"156657d4778127ac31297acc9e90ebc91c07e10b3227dc875941c4d98634914e","payload":{"connection_id":"5d29200f65794d4d9ab6ef271f045a9b","event_at":"2026-07-28T02:06:38.662000Z","event_type":"book","frame_hash":"79050c4461cc1de6170d6756778eb5599f684098ecacf080eca0d3b2dad586a9","frame_index":0,"kind":"data","monotonic_ns":306382654918958,"payload":{"asks":[{"price":"0.99","size":"5672.02"},{"price":"0.98","size":"822.1"},{"price":"0.97","size":"662.1"},{"price":"0.96","size":"662.09"},{"price":"0.95","size":"793.2"},{"price":"0.94","size":"619.2"},{"price":"0.93","size":"425.1"},{"price":"0.92","size":"361.79"},{"price":"0.91","size":"317.6"},{"price":"0.9","size":"401.29"},{"price":"0.89","size":"269.6"},{"price":"0.88","size":"261.4"},{"price":"0.87","size":"265.5"},{"price":"0.86","size":"221.9"},{"price":"0.85","size":"257.5"},{"price":"0.84","size":"240.3"},{"price":"0.83","size":"292.3"},{"price":"0.82","size":"295.3"},{"price":"0.81","size":"841.79"},{"price":"0.8","size":"278.8"},{"price":"0.79","size":"173.1"},{"price":"0.78","size":"198.5"},{"price":"0.77","size":"171.89"},{"price":"0.76","size":"167.39"},{"price":"0.75","size":"242.5"},{"price":"0.74","size":"165.6"},{"price":"0.73","size":"162.2"},{"price":"0.72","size":"214.9"},{"price":"0.71","size":"313.6"},{"price":"0.7","size":"90.33"},{"price":"0.69","size":"102"},{"price":"0.68","size":"72.57"},{"price":"0.67","size":"74.98"},{"price":"0.66","size":"97.41"},{"price":"0.65","size":"84.2"},{"price":"0.64","size":"84.2"},{"price":"0.63","size":"59"},{"price":"0.62","size":"44"},{"price":"0.61","size":"50"}],"asset_id":"39272994714739463168905443499424551362424437245880253267329605556587274644733","bids":[{"price":"0.01","size":"5608.02"},{"price":"0.02","size":"688.1"},{"price":"0.03","size":"648.1"},{"price":"0.04","size":"588.09"},{"price":"0.05","size":"723.2"},{"price":"0.06","size":"583.2"},{"price":"0.07","size":"546.1"},{"price":"0.08","size":"550.79"},{"price":"0.09","size":"566.6"},{"price":"0.1","size":"223.29"},{"price":"0.11","size":"30.6"},{"price":"0.12","size":"68.4"},{"price":"0.13","size":"26.5"},{"price":"0.14","size":"24.9"},{"price":"0.15","size":"114.17"},{"price":"0.16","size":"32.3"},{"price":"0.17","size":"21.3"},{"price":"0.18","size":"50.3"},{"price":"0.19","size":"19.5"},{"price":"0.2","size":"68.8"},{"price":"0.21","size":"48.1"},{"price":"0.22","size":"24.5"},{"price":"0.23","size":"23.89"},{"price":"0.24","size":"53.39"},{"price":"0.25","size":"66"},{"price":"0.26","size":"21.6"},{"price":"0.27","size":"51.2"},{"price":"0.28","size":"20.9"},{"price":"0.29","size":"20.6"},{"price":"0.3","size":"118.3"},{"price":"0.31","size":"64"},{"price":"0.32","size":"63.8"},{"price":"0.33","size":"93.6"},{"price":"0.34","size":"63.4"},{"price":"0.35","size":"92.2"},{"price":"0.36","size":"92"},{"price":"0.37","size":"61.9"},{"price":"0.38","size":"61.7"},{"price":"0.39","size":"91.6"},{"price":"0.4","size":"84.5"},{"price":"0.41","size":"61.4"},{"price":"0.42","size":"91.3"},{"price":"0.43","size":"61.2"},{"price":"0.44","size":"61.2"},{"price":"0.45","size":"95"},{"price":"0.46","size":"49"},{"price":"0.47","size":"49"},{"price":"0.48","size":"80.05"},{"price":"0.49","size":"59"},{"price":"0.5","size":"263.98"},{"price":"0.51","size":"79"},{"price":"0.52","size":"59"},{"price":"0.53","size":"80"},{"price":"0.54","size":"91.06"},{"price":"0.55","size":"161.09"},{"price":"0.56","size":"93.12"},{"price":"0.57","size":"75.19"},{"price":"0.58","size":"95"},{"price":"0.59","size":"55"},{"price":"0.6","size":"79.18"}],"event_type":"book","hash":"7a3a6350a492cadcdf056a57ea185afdeeaee7c5","market":"0xda6f0e0e93fc8469e0159a166028d017bddbc162b86f66bac90391379603d962","timestamp":"1785204398662"},"payload_hash":"f6b94795205ab2bba642c65cb2779dfe33f5a6e3fda35d89e8b5970f4025892d","raw_frame":"{\"market\":\"0xda6f0e0e93fc8469e0159a166028d017bddbc162b86f66bac90391379603d962\", \"asset_id\":\"39272994714739463168905443499424551362424437245880253267329605556587274644733\", \"bids\":[{\"price\":\"0.01\", \"size\":\"5608.02\"}, {\"price\":\"0.02\", \"size\":\"688.1\"}, {\"price\":\"0.03\", \"size\":\"648.1\"}, {\"price\":\"0.04\", \"size\":\"588.09\"}, {\"price\":\"0.05\", \"size\":\"723.2\"}, {\"price\":\"0.06\", \"size\":\"583.2\"}, {\"price\":\"0.07\", \"size\":\"546.1\"}, {\"price\":\"0.08\", \"size\":\"550.79\"}, {\"price\":\"0.09\", \"size\":\"566.6\"}, {\"price\":\"0.1\", \"size\":\"223.29\"}, {\"price\":\"0.11\", \"size\":\"30.6\"}, {\"price\":\"0.12\", \"size\":\"68.4\"}, {\"price\":\"0.13\", \"size\":\"26.5\"}, {\"price\":\"0.14\", \"size\":\"24.9\"}, {\"price\":\"0.15\", \"size\":\"114.17\"}, {\"price\":\"0.16\", \"size\":\"32.3\"}, {\"price\":\"0.17\", \"size\":\"21.3\"}, {\"price\":\"0.18\", \"size\":\"50.3\"}, {\"price\":\"0.19\", \"size\":\"19.5\"}, {\"price\":\"0.2\", \"size\":\"68.8\"}, {\"price\":\"0.21\", \"size\":\"48.1\"}, {\"price\":\"0.22\", \"size\":\"24.5\"}, {\"price\":\"0.23\", \"size\":\"23.89\"}, {\"price\":\"0.24\", \"size\":\"53.39\"}, {\"price\":\"0.25\", \"size\":\"66\"}, {\"price\":\"0.26\", \"size\":\"21.6\"}, {\"price\":\"0.27\", \"size\":\"51.2\"}, {\"price\":\"0.28\", \"size\":\"20.9\"}, {\"price\":\"0.29\", \"size\":\"20.6\"}, {\"price\":\"0.3\", \"size\":\"118.3\"}, {\"price\":\"0.31\", \"size\":\"64\"}, {\"price\":\"0.32\", \"size\":\"63.8\"}, {\"price\":\"0.33\", \"size\":\"93.6\"}, {\"price\":\"0.34\", \"size\":\"63.4\"}, {\"price\":\"0.35\", \"size\":\"92.2\"}, {\"price\":\"0.36\", \"size\":\"92\"}, {\"price\":\"0.37\", \"size\":\"61.9\"}, {\"price\":\"0.38\", \"size\":\"61.7\"}, {\"price\":\"0.39\", \"size\":\"91.6\"}, {\"price\":\"0.4\", \"size\":\"84.5\"}, {\"price\":\"0.41\", \"size\":\"61.4\"}, {\"price\":\"0.42\", \"size\":\"91.3\"}, {\"price\":\"0.43\", \"size\":\"61.2\"}, {\"price\":\"0.44\", \"size\":\"61.2\"}, {\"price\":\"0.45\", \"size\":\"95\"}, {\"price\":\"0.46\", \"size\":\"49\"}, {\"price\":\"0.47\", \"size\":\"49\"}, {\"price\":\"0.48\", \"size\":\"80.05\"}, {\"price\":\"0.49\", \"size\":\"59\"}, {\"price\":\"0.5\", \"size\":\"263.98\"}, {\"price\":\"0.51\", \"size\":\"79\"}, {\"price\":\"0.52\", \"size\":\"59\"}, {\"price\":\"0.53\", \"size\":\"80\"}, {\"price\":\"0.54\", \"size\":\"91.06\"}, {\"price\":\"0.55\", \"size\":\"161.09\"}, {\"price\":\"0.56\", \"size\":\"93.12\"}, {\"price\":\"0.57\", \"size\":\"75.19\"}, {\"price\":\"0.58\", \"size\":\"95\"}, {\"price\":\"0.59\", \"size\":\"55\"}, {\"price\":\"0.6\", \"size\":\"79.18\"}], \"asks\":[{\"price\":\"0.99\", \"size\":\"5672.02\"}, {\"price\":\"0.98\", \"size\":\"822.1\"}, {\"price\":\"0.97\", \"size\":\"662.1\"}, {\"price\":\"0.96\", \"size\":\"662.09\"}, {\"price\":\"0.95\", \"size\":\"793.2\"}, {\"price\":\"0.94\", \"size\":\"619.2\"}, {\"price\":\"0.93\", \"size\":\"425.1\"}, {\"price\":\"0.92\", \"size\":\"361.79\"}, {\"price\":\"0.91\", \"size\":\"317.6\"}, {\"price\":\"0.9\", \"size\":\"401.29\"}, {\"price\":\"0.89\", \"size\":\"269.6\"}, {\"price\":\"0.88\", \"size\":\"261.4\"}, {\"price\":\"0.87\", \"size\":\"265.5\"}, {\"price\":\"0.86\", \"size\":\"221.9\"}, {\"price\":\"0.85\", \"size\":\"257.5\"}, {\"price\":\"0.84\", \"size\":\"240.3\"}, {\"price\":\"0.83\", \"size\":\"292.3\"}, {\"price\":\"0.82\", \"size\":\"295.3\"}, {\"price\":\"0.81\", \"size\":\"841.79\"}, {\"price\":\"0.8\", \"size\":\"278.8\"}, {\"price\":\"0.79\", \"size\":\"173.1\"}, {\"price\":\"0.78\", \"size\":\"198.5\"}, {\"price\":\"0.77\", \"size\":\"171.89\"}, {\"price\":\"0.76\", \"size\":\"167.39\"}, {\"price\":\"0.75\", \"size\":\"242.5\"}, {\"price\":\"0.74\", \"size\":\"165.6\"}, {\"price\":\"0.73\", \"size\":\"162.2\"}, {\"price\":\"0.72\", \"size\":\"214.9\"}, {\"price\":\"0.71\", \"size\":\"313.6\"}, {\"price\":\"0.7\", \"size\":\"90.33\"}, {\"price\":\"0.69\", \"size\":\"102\"}, {\"price\":\"0.68\", \"size\":\"72.57\"}, {\"price\":\"0.67\", \"size\":\"74.98\"}, {\"price\":\"0.66\", \"size\":\"97.41\"}, {\"price\":\"0.65\", \"size\":\"84.2\"}, {\"price\":\"0.64\", \"size\":\"84.2\"}, {\"price\":\"0.63\", \"size\":\"59\"}, {\"price\":\"0.62\", \"size\":\"44\"}, {\"price\":\"0.61\", \"size\":\"50\"}], \"hash\":\"7a3a6350a492cadcdf056a57ea185afdeeaee7c5\", \"timestamp\":\"1785204398662\", \"event_type\":\"book\"}","received_at":"2026-07-28T02:06:39.647911Z","schema_version":"clob-market-ws.book.v1","sequence":null,"server_hash":"7a3a6350a492cadcdf056a57ea185afdeeaee7c5","server_timestamp":"1785204398662","session_id":"d2757dd6dad94f3b9fe67e8dbf1adc37","source":"clob_market_ws"},"received_at":"2026-07-28T02:06:39.647911Z","record_id":"b593696abcddaae013248b803dbd61498c89f2815e45805ef38d3dd95833a8a0","schema_fingerprint":"dc2caa1c89c6a7426e2e07ff925910cd4d0a8a223a515d4092d91d6d127aacb6","schema_version":"edge-lab-recorder.raw.v1","sequence":null,"source":"clob_market_ws"}
{"event_at":"2026-07-28T02:06:38.666000Z","event_fingerprint":"15e66dc48ce19f5a0fc986e811739adae6a28d0b9e449535207001ffd1172248","payload":{"connection_id":"5d29200f65794d4d9ab6ef271f045a9b","event_at":"2026-07-28T02:06:38.666000Z","event_type":"price_change","frame_hash":"d5c1698c9a0f2593019dd3e94ea0dc1f49a37259b285d3bc067e5781a2a28a61","frame_index":0,"kind":"data","monotonic_ns":306382673027500,"payload":{"event_type":"price_change","market":"0xda6f0e0e93fc8469e0159a166028d017bddbc162b86f66bac90391379603d962","price_changes":[{"asset_id":"20893381255801015515826997628594359667013752732428989472914000440642900266717","best_ask":"0.4","best_bid":"0.39","hash":"f7bbe6003472df93e6ce567e71f2f7a5dc4031fc","price":"0.39","side":"BUY","size":"75"},{"asset_id":"39272994714739463168905443499424551362424437245880253267329605556587274644733","best_ask":"0.61","best_bid":"0.6","hash":"4ae9e78a9b479ae91ca563031f22c6d578043eb8","price":"0.61","side":"SELL","size":"75"}],"timestamp":"1785204398666"},"payload_hash":"a07bd784726b8456e4f8902b6b4630c9d69b1155a033fef2a1e2b00bd9010fb7","raw_frame":"{\"market\":\"0xda6f0e0e93fc8469e0159a166028d017bddbc162b86f66bac90391379603d962\", \"price_changes\":[{\"asset_id\":\"20893381255801015515826997628594359667013752732428989472914000440642900266717\", \"price\":\"0.39\", \"size\":\"75\", \"side\":\"BUY\", \"hash\":\"f7bbe6003472df93e6ce567e71f2f7a5dc4031fc\", \"best_bid\":\"0.39\", \"best_ask\":\"0.4\"}, {\"asset_id\":\"39272994714739463168905443499424551362424437245880253267329605556587274644733\", \"price\":\"0.61\", \"size\":\"75\", \"side\":\"SELL\", \"hash\":\"4ae9e78a9b479ae91ca563031f22c6d578043eb8\", \"best_bid\":\"0.6\", \"best_ask\":\"0.61\"}], \"timestamp\":\"1785204398666\", \"event_type\":\"price_change\"}","received_at":"2026-07-28T02:06:39.666019Z","schema_version":"clob-market-ws.price_change.v1","sequence":null,"server_hash":null,"server_timestamp":"1785204398666","session_id":"d2757dd6dad94f3b9fe67e8dbf1adc37","source":"clob_market_ws"},"received_at":"2026-07-28T02:06:39.666019Z","record_id":"7038fe07855a2c8781efec4cb4b8c7f2d8bed4a9b9c4e8f56fdae7a40ff2d616","schema_fingerprint":"4aa3821a28b0b7c2400bc59aba4bcc0a76e971dadd19610d3ad38c768e124dc7","schema_version":"edge-lab-recorder.raw.v1","sequence":null,"source":"clob_market_ws"}
{"event_at":"2026-07-28T02:06:38.668000Z","event_fingerprint":"b2cff50834e9b4fb674eadb6b0d8764bc6a8422c696d457bc68b67467af35d58","payload":{"connection_id":"5d29200f65794d4d9ab6ef271f045a9b","event_at":"2026-07-28T02:06:38.668000Z","event_type":"price_change","frame_hash":"56237de6780a31ad56fda2a9ae06f933341a884d669d7269f4446e54f0f4bbe4","frame_index":0,"kind":"data","monotonic_ns":306382676850166,"payload":{"event_type":"price_change","market":"0xda6f0e0e93fc8469e0159a166028d017bddbc162b86f66bac90391379603d962","price_changes":[{"asset_id":"39272994714739463168905443499424551362424437245880253267329605556587274644733","best_ask":"0.61","best_bid":"0.6","hash":"b2fd216d3b4e8c4454a21e0e5d833d2418a983f5","price":"0.59","side":"BUY","size":"26"},{"asset_id":"20893381255801015515826997628594359667013752732428989472914000440642900266717","best_ask":"0.4","best_bid":"0.39","hash":"879872c41a72b2d629d8b9bdaddc0e1418eccda8","price":"0.41","side":"SELL","size":"26"}],"timestamp":"1785204398668"},"payload_hash":"7f6dbca25855fecfd3d1ea19fd7d16f0cfb5397723760309c010101c643634b6","raw_frame":"{\"market\":\"0xda6f0e0e93fc8469e0159a166028d017bddbc162b86f66bac90391379603d962\", \"price_changes\":[{\"asset_id\":\"39272994714739463168905443499424551362424437245880253267329605556587274644733\", \"price\":\"0.59\", \"size\":\"26\", \"side\":\"BUY\", \"hash\":\"b2fd216d3b4e8c4454a21e0e5d833d2418a983f5\", \"best_bid\":\"0.6\", \"best_ask\":\"0.61\"}, {\"asset_id\":\"20893381255801015515826997628594359667013752732428989472914000440642900266717\", \"price\":\"0.41\", \"size\":\"26\", \"side\":\"SELL\", \"hash\":\"879872c41a72b2d629d8b9bdaddc0e1418eccda8\", \"best_bid\":\"0.39\", \"best_ask\":\"0.4\"}], \"timestamp\":\"1785204398668\", \"event_type\":\"price_change\"}","received_at":"2026-07-28T02:06:39.669841Z","schema_version":"clob-market-ws.price_change.v1","sequence":null,"server_hash":null,"server_timestamp":"1785204398668","session_id":"d2757dd6dad94f3b9fe67e8dbf1adc37","source":"clob_market_ws"},"received_at":"2026-07-28T02:06:39.669841Z","record_id":"6e9c6c487e33175af68a7e6c5c9ddd8cb6381a18b4cee8afbe973f8e031d1174","schema_fingerprint":"4aa3821a28b0b7c2400bc59aba4bcc0a76e971dadd19610d3ad38c768e124dc7","schema_version":"edge-lab-recorder.raw.v1","sequence":null,"source":"clob_market_ws"}
{"event_at":"2026-07-28T02:06:38.668000Z","event_fingerprint":"edd48273d981a63e493b51412de41800b26ad863a0c17831ca5af22a10886c62","payload":{"connection_id":"5d29200f65794d4d9ab6ef271f045a9b","event_at":"2026-07-28T02:06:38.668000Z","event_type":"price_change","frame_hash":"68c2d1ee3547c261c2ba03bf085ba71cf4e0cb63b57fbb58bc2aac5d6ed0e8b0","frame_index":0,"kind":"data","monotonic_ns":306382681157625,"payload":{"event_type":"price_change","market":"0xda6f0e0e93fc8469e0159a166028d017bddbc162b86f66bac90391379603d962","price_changes":[{"asset_id":"39272994714739463168905443499424551362424437245880253267329605556587274644733","best_ask":"0.61","best_bid":"0.6","hash":"0fe391bc5d344008ffa3512097ce7da1d5a3bc5a","price":"0.6","side":"BUY","size":"50.2"},{"asset_id":"20893381255801015515826997628594359667013752732428989472914000440642900266717","best_ask":"0.4","best_bid":"0.39","hash":"0fa2c641c92ec7dfa01771c3bb207e46aec90197","price":"0.4","side":"SELL","size":"50.2"}],"timestamp":"1785204398668"},"payload_hash":"f0a1bb7cd99c45ae2f55f042b95f37e0c5c2ce7994122ff06c9881284f64e622","raw_frame":"{\"market\":\"0xda6f0e0e93fc8469e0159a166028d017bddbc162b86f66bac90391379603d962\", \"price_changes\":[{\"asset_id\":\"39272994714739463168905443499424551362424437245880253267329605556587274644733\", \"price\":\"0.6\", \"size\":\"50.2\", \"side\":\"BUY\", \"hash\":\"0fe391bc5d344008ffa3512097ce7da1d5a3bc5a\", \"best_bid\":\"0.6\", \"best_ask\":\"0.61\"}, {\"asset_id\":\"20893381255801015515826997628594359667013752732428989472914000440642900266717\", \"price\":\"0.4\", \"size\":\"50.2\", \"side\":\"SELL\", \"hash\":\"0fa2c641c92ec7dfa01771c3bb207e46aec90197\", \"best_bid\":\"0.39\", \"best_ask\":\"0.4\"}], \"timestamp\":\"1785204398668\", \"event_type\":\"price_change\"}","received_at":"2026-07-28T02:06:39.674150Z","schema_version":"clob-market-ws.price_change.v1","sequence":null,"server_hash":null,"server_timestamp":"1785204398668","session_id":"d2757dd6dad94f3b9fe67e8dbf1adc37","source":"clob_market_ws"},"received_at":"2026-07-28T02:06:39.674150Z","record_id":"149370eff5110b53eccc2a40d68f01f03a9bd6baa5e4d47697a0b9ba30b4f735","schema_fingerprint":"4aa3821a28b0b7c2400bc59aba4bcc0a76e971dadd19610d3ad38c768e124dc7","schema_version":"edge-lab-recorder.raw.v1","sequence":null,"source":"clob_market_ws"}
{"event_at":"2026-07-28T02:06:38.668000Z","event_fingerprint":"e35f600f41793e769932031397b2c24bc9741a180befff04c63309dcb8b84336","payload":{"connection_id":"5d29200f65794d4d9ab6ef271f045a9b","event_at":"2026-07-28T02:06:38.668000Z","event_type":"price_change","frame_hash":"e745e897f5c5437264e63e1acff66c6eb74839e80c036ee857502d4f2d6be958","frame_index":0,"kind":"data","monotonic_ns":306382684995000,"payload":{"event_type":"price_change","market":"0xda6f0e0e93fc8469e0159a166028d017bddbc162b86f66bac90391379603d962","price_changes":[{"asset_id":"39272994714739463168905443499424551362424437245880253267329605556587274644733","best_ask":"0.61","best_bid":"0.6","hash":"4b03986daf2de76d24c04d789002866113f9e20f","price":"0.59","side":"BUY","size":"11"},{"asset_id":"20893381255801015515826997628594359667013752732428989472914000440642900266717","best_ask":"0.4","best_bid":"0.39","hash":"476fa447471320d9faf8e29cb3c1c4618b5462b9","price":"0.41","side":"SELL","size":"11"}],"timestamp":"1785204398668"},"payload_hash":"19f094835aeb1667788f96cd2699f308cb3a83ca7bbac64bf6c2d11764a4ef14","raw_frame":"{\"market\":\"0xda6f0e0e93fc8469e0159a166028d017bddbc162b86f66bac90391379603d962\", \"price_changes\":[{\"asset_id\":\"39272994714739463168905443499424551362424437245880253267329605556587274644733\", \"price\":\"0.59\", \"size\":\"11\", \"side\":\"BUY\", \"hash\":\"4b03986daf2de76d24c04d789002866113f9e20f\", \"best_bid\":\"0.6\", \"best_ask\":\"0.61\"}, {\"asset_id\":\"20893381255801015515826997628594359667013752732428989472914000440642900266717\", \"price\":\"0.41\", \"size\":\"11\", \"side\":\"SELL\", \"hash\":\"476fa447471320d9faf8e29cb3c1c4618b5462b9\", \"best_bid\":\"0.39\", \"best_ask\":\"0.4\"}], \"timestamp\":\"1785204398668\", \"event_type\":\"price_change\"}","received_at":"2026-07-28T02:06:39.677986Z","schema_version":"clob-market-ws.price_change.v1","sequence":null,"server_hash":null,"server_timestamp":"1785204398668","session_id":"d2757dd6dad94f3b9fe67e8dbf1adc37","source":"clob_market_ws"},"received_at":"2026-07-28T02:06:39.677986Z","record_id":"61b293d8b8e8853424d8cb5ea3c1e78e73adda3fab043e4c517b2ddaea1c053d","schema_fingerprint":"4aa3821a28b0b7c2400bc59aba4bcc0a76e971dadd19610d3ad38c768e124dc7","schema_version":"edge-lab-recorder.raw.v1","sequence":null,"source":"clob_market_ws"}
{"event_at":"2026-07-28T02:06:38.671000Z","event_fingerprint":"124bb492a11dec0b43d144682c3bd16bd88cc1dff2b1e837c1f5b51f61fdfb57","payload":{"connection_id":"5d29200f65794d4d9ab6ef271f045a9b","event_at":"2026-07-28T02:06:38.671000Z","event_type":"price_change","frame_hash":"05df5de2c2a97a48ca266a43d04264afeae1674e7d4da8864a5bd79d2d34ad00","frame_index":0,"kind":"data","monotonic_ns":306382689449500,"payload":{"event_type":"price_change","market":"0xda6f0e0e93fc8469e0159a166028d017bddbc162b86f66bac90391379603d962","price_changes":[{"asset_id":"39272994714739463168905443499424551362424437245880253267329605556587274644733","best_ask":"0.61","best_bid":"0.6","hash":"e984d0e4be683b240b53eef0e836cf18ea9694ff","price":"0.6","side":"BUY","size":"35.2"},{"asset_id":"20893381255801015515826997628594359667013752732428989472914000440642900266717","best_ask":"0.4","best_bid":"0.39","hash":"37f41ac841f44ed06058c737568bc658c084127d","price":"0.4","side":"SELL","size":"35.2"}],"timestamp":"1785204398671"},"payload_hash":"ddfbb34dcd647a7f9873a81a1751d7b8ee5d8edfc830c9fb4ef3618d95ca1ddc","raw_frame":"{\"market\":\"0xda6f0e0e93fc8469e0159a166028d017bddbc162b86f66bac90391379603d962\", \"price_changes\":[{\"asset_id\":\"39272994714739463168905443499424551362424437245880253267329605556587274644733\", \"price\":\"0.6\", \"size\":\"35.2\", \"side\":\"BUY\", \"hash\":\"e984d0e4be683b240b53eef0e836cf18ea9694ff\", \"best_bid\":\"0.6\", \"best_ask\":\"0.61\"}, {\"asset_id\":\"20893381255801015515826997628594359667013752732428989472914000440642900266717\", \"price\":\"0.4\", \"size\":\"35.2\", \"side\":\"SELL\", \"hash\":\"37f41ac841f44ed06058c737568bc658c084127d\", \"best_bid\":\"0.39\", \"best_ask\":\"0.4\"}], \"timestamp\":\"1785204398671\", \"event_type\":\"price_change\"}","received_at":"2026-07-28T02:06:39.682442Z","schema_version":"clob-market-ws.price_change.v1","sequence":null,"server_hash":null,"server_timestamp":"1785204398671","session_id":"d2757dd6dad94f3b9fe67e8dbf1adc37","source":"clob_market_ws"},"received_at":"2026-07-28T02:06:39.682442Z","record_id":"18530e4720096d125738a57b52487c05bc4294ffe3f1ddb2355386da05f567ad","schema_fingerprint":"4aa3821a28b0b7c2400bc59aba4bcc0a76e971dadd19610d3ad38c768e124dc7","schema_version":"edge-lab-recorder.raw.v1","sequence":null,"source":"clob_market_ws"}
{"event_at":"2026-07-28T02:06:38.702000Z","event_fingerprint":"251fc357cb05936496aded82b141d4b41676f1ded691a8b92a9fd4879e8330b5","payload":{"connection_id":"5d29200f65794d4d9ab6ef271f045a9b","event_at":"2026-07-28T02:06:38.702000Z","event_type":"price_change","frame_hash":"6deab1c09636c59f4e01c5c757931662c66cfe91c2ee53480e29aef028b49168","frame_index":0,"kind":"data","monotonic_ns":306382693758125,"payload":{"event_type":"price_change","market":"0xda6f0e0e93fc8469e0159a166028d017bddbc162b86f66bac90391379603d962","price_changes":[{"asset_id":"39272994714739463168905443499424551362424437245880253267329605556587274644733","best_ask":"0.61","best_bid":"0.6","hash":"44d6f3bb203d8b14cd6bedef0f1ef40c3f950297","price":"0.51","side":"BUY","size":"86.5"},{"asset_id":"20893381255801015515826997628594359667013752732428989472914000440642900266717","best_ask":"0.4","best_bid":"0.39","hash":"fe461739eabc50ab536492712636d9c9fc833f1f","price":"0.49","side":"SELL","size":"86.5"}],"timestamp":"1785204398702"},"payload_hash":"b2e651a40534c02bb180ca185d72fed562186c1046feda7a5d35e69fc329bd98","raw_frame":"{\"market\":\"0xda6f0e0e93fc8469e0159a166028d017bddbc162b86f66bac90391379603d962\", \"price_changes\":[{\"asset_id\":\"39272994714739463168905443499424551362424437245880253267329605556587274644733\", \"price\":\"0.51\", \"size\":\"86.5\", \"side\":\"BUY\", \"hash\":\"44d6f3bb203d8b14cd6bedef0f1ef40c3f950297\", \"best_bid\":\"0.6\", \"best_ask\":\"0.61\"}, {\"asset_id\":\"20893381255801015515826997628594359667013752732428989472914000440642900266717\", \"price\":\"0.49\", \"size\":\"86.5\", \"side\":\"SELL\", \"hash\":\"fe461739eabc50ab536492712636d9c9fc833f1f\", \"best_bid\":\"0.39\", \"best_ask\":\"0.4\"}], \"timestamp\":\"1785204398702\", \"event_type\":\"price_change\"}","received_at":"2026-07-28T02:06:39.686750Z","schema_version":"clob-market-ws.price_change.v1","sequence":null,"server_hash":null,"server_timestamp":"1785204398702","session_id":"d2757dd6dad94f3b9fe67e8dbf1adc37","source":"clob_market_ws"},"received_at":"2026-07-28T02:06:39.686750Z","record_id":"ba9d2f3b14161afd48b8966a3c80e95155842e61ae1ffefdfd2550c6ce06a38f","schema_fingerprint":"4aa3821a28b0b7c2400bc59aba4bcc0a76e971dadd19610d3ad38c768e124dc7","schema_version":"edge-lab-recorder.raw.v1","sequence":null,"source":"clob_market_ws"}
{"event_at":"2026-07-28T02:06:38.704000Z","event_fingerprint":"95645618f538759d9309e0a9d8a874e68c9ea653e9d99009edb92187eae06c89","payload":{"connection_id":"5d29200f65794d4d9ab6ef271f045a9b","event_at":"2026-07-28T02:06:38.704000Z","event_type":"price_change","frame_hash":"c0c708a54bacb6688aa1be9b662fdd31f00fbfdb4dca9033dea5704a936d6cf9","frame_index":0,"kind":"data","monotonic_ns":306382698061250,"payload":{"event_type":"price_change","market":"0xda6f0e0e93fc8469e0159a166028d017bddbc162b86f66bac90391379603d962","price_changes":[{"asset_id":"20893381255801015515826997628594359667013752732428989472914000440642900266717","best_ask":"0.4","best_bid":"0.39","hash":"bf50b9144fe729de764bcb534c09c83f38bf57c4","price":"0.28","side":"BUY","size":"208.9"},{"asset_id":"39272994714739463168905443499424551362424437245880253267329605556587274644733","best_ask":"0.61","best_bid":"0.6","hash":"fcb0040c75d206685507da4a9ee90d82616f7d6a","price":"0.72","side":"SELL","size":"208.9"}],"timestamp":"1785204398704"},"payload_hash":"b8f7154d97170f802b219f1d9c64f90f65fc71562ec424ea9d388c0182313330","raw_frame":"{\"market\":\"0xda6f0e0e93fc8469e0159a166028d017bddbc162b86f66bac90391379603d962\", \"price_changes\":[{\"asset_id\":\"20893381255801015515826997628594359667013752732428989472914000440642900266717\", \"price\":\"0.28\", \"size\":\"208.9\", \"side\":\"BUY\", \"hash\":\"bf50b9144fe729de764bcb534c09c83f38bf57c4\", \"best_bid\":\"0.39\", \"best_ask\":\"0.4\"}, {\"asset_id\":\"39272994714739463168905443499424551362424437245880253267329605556587274644733\", \"price\":\"0.72\", \"size\":\"208.9\", \"side\":\"SELL\", \"hash\":\"fcb0040c75d206685507da4a9ee90d82616f7d6a\", \"best_bid\":\"0.6\", \"best_ask\":\"0.61\"}], \"timestamp\":\"1785204398704\", \"event_type\":\"price_change\"}","received_at":"2026-07-28T02:06:39.691053Z","schema_version":"clob-market-ws.price_change.v1","sequence":null,"server_hash":null,"server_timestamp":"1785204398704","session_id":"d2757dd6dad94f3b9fe67e8dbf1adc37","source":"clob_market_ws"},"received_at":"2026-07-28T02:06:39.691053Z","record_id":"82b19c72f23e948e4d64e89cbecfbe9b592c7d7387b31254b3eb723d2b019468","schema_fingerprint":"4aa3821a28b0b7c2400bc59aba4bcc0a76e971dadd19610d3ad38c768e124dc7","schema_version":"edge-lab-recorder.raw.v1","sequence":null,"source":"clob_market_ws"}
{"event_at":"2026-07-28T02:06:38.727000Z","event_fingerprint":"d7e1fceecf193c28935544db48d704cb7d61c32bb9204e68dc8af7f6c4e627c5","payload":{"connection_id":"5d29200f65794d4d9ab6ef271f045a9b","event_at":"2026-07-28T02:06:38.727000Z","event_type":"price_change","frame_hash":"61352c55b622eae8b2620179873e9f06dd2efcc364f82834f5634177713d9af4","frame_index":0,"kind":"data","monotonic_ns":306382702404000,"payload":{"event_type":"price_change","market":"0xda6f0e0e93fc8469e0159a166028d017bddbc162b86f66bac90391379603d962","price_changes":[{"asset_id":"39272994714739463168905443499424551362424437245880253267329605556587274644733","best_ask":"0.61","best_bid":"0.6","hash":"84484779e2dc0aaf918a0d7aceb4f5bbddd766e8","price":"0.03","side":"BUY","size":"653.1"},{"asset_id":"20893381255801015515826997628594359667013752732428989472914000440642900266717","best_ask":"0.4","best_bid":"0.39","hash":"1d60d40f7d3cad3c58b877115a12a541e055878d","price":"0.97","side":"SELL","size":"653.1"}],"timestamp":"1785204398727"},"payload_hash":"7d73410deb246c55c9ea2e6f4930b472facace89f4083f0fbcd020e69a34eaa9","raw_frame":"{\"market\":\"0xda6f0e0e93fc8469e0159a166028d017bddbc162b86f66bac90391379603d962\", \"price_changes\":[{\"asset_id\":\"39272994714739463168905443499424551362424437245880253267329605556587274644733\", \"price\":\"0.03\", \"size\":\"653.1\", \"side\":\"BUY\", \"hash\":\"84484779e2dc0aaf918a0d7aceb4f5bbddd766e8\", \"best_bid\":\"0.6\", \"best_ask\":\"0.61\"}, {\"asset_id\":\"20893381255801015515826997628594359667013752732428989472914000440642900266717\", \"price\":\"0.97\", \"size\":\"653.1\", \"side\":\"SELL\", \"hash\":\"1d60d40f7d3cad3c58b877115a12a541e055878d\", \"best_bid\":\"0.39\", \"best_ask\":\"0.4\"}], \"timestamp\":\"1785204398727\", \"event_type\":\"price_change\"}","received_at":"2026-07-28T02:06:39.695394Z","schema_version":"clob-market-ws.price_change.v1","sequence":null,"server_hash":null,"server_timestamp":"1785204398727","session_id":"d2757dd6dad94f3b9fe67e8dbf1adc37","source":"clob_market_ws"},"received_at":"2026-07-28T02:06:39.695394Z","record_id":"48ac2b4e3271649fe4d76cf406fc489440eda38c3b24c5c02299740be2cdd50a","schema_fingerprint":"4aa3821a28b0b7c2400bc59aba4bcc0a76e971dadd19610d3ad38c768e124dc7","schema_version":"edge-lab-recorder.raw.v1","sequence":null,"source":"clob_market_ws"}
{"event_at":"2026-07-28T02:06:38.732000Z","event_fingerprint":"1833e502b26c91367bbaeed8658ab66fcd3c777c1493ae15558d62a236d8fd21","payload":{"connection_id":"5d29200f65794d4d9ab6ef271f045a9b","event_at":"2026-07-28T02:06:38.732000Z","event_type":"price_change","frame_hash":"849e1b27f6383f739e34385b01187635b5d66f4da1dd86ac240c4ecfa471d98e","frame_index":0,"kind":"data","monotonic_ns":306382706752750,"payload":{"event_type":"price_change","market":"0xda6f0e0e93fc8469e0159a166028d017bddbc162b86f66bac90391379603d962","price_changes":[{"asset_id":"39272994714739463168905443499424551362424437245880253267329605556587274644733","best_ask":"0.61","best_bid":"0.6","hash":"79a51342feb94e4d60f4ed22b1300f5e088f4881","price":"0.54","side":"BUY","size":"79"},{"asset_id":"20893381255801015515826997628594359667013752732428989472914000440642900266717","best_ask":"0.4","best_bid":"0.39","hash":"f9248834c214f913e1b6705299f29f1f42cd6735","price":"0.46","side":"SELL","size":"79"}],"timestamp":"1785204398732"},"payload_hash":"f12a3a0d9d7fc641df8c9d59d7cd6d36257a52c149d8ac42a122383335ee958b","raw_frame":"{\"market\":\"0xda6f0e0e93fc8469e0159a166028d017bddbc162b86f66bac90391379603d962\", \"price_changes\":[{\"asset_id\":\"39272994714739463168905443499424551362424437245880253267329605556587274644733\", \"price\":\"0.54\", \"size\":\"79\", \"side\":\"BUY\", \"hash\":\"79a51342feb94e4d60f4ed22b1300f5e088f4881\", \"best_bid\":\"0.6\", \"best_ask\":\"0.61\"}, {\"asset_id\":\"20893381255801015515826997628594359667013752732428989472914000440642900266717\", \"price\":\"0.46\", \"size\":\"79\", \"side\":\"SELL\", \"hash\":\"f9248834c214f913e1b6705299f29f1f42cd6735\", \"best_bid\":\"0.39\", \"best_ask\":\"0.4\"}], \"timestamp\":\"1785204398732\", \"event_type\":\"price_change\"}","received_at":"2026-07-28T02:06:39.699744Z","schema_version":"clob-market-ws.price_change.v1","sequence":null,"server_hash":null,"server_timestamp":"1785204398732","session_id":"d2757dd6dad94f3b9fe67e8dbf1adc37","source":"clob_market_ws"},"received_at":"2026-07-28T02:06:39.699744Z","record_id":"8d2b4d60117b76646c5c346e022ad54fbb6ef7badc387ca9c48e37d2c9a4f4ac","schema_fingerprint":"4aa3821a28b0b7c2400bc59aba4bcc0a76e971dadd19610d3ad38c768e124dc7","schema_version":"edge-lab-recorder.raw.v1","sequence":null,"source":"clob_market_ws"}
{"event_at":"2026-07-28T02:06:38.729000Z","event_fingerprint":"bbdd5052491caf885fce50efcdd631c6621b97f9b017effffcc34dfc130ea010","payload":{"connection_id":"5d29200f65794d4d9ab6ef271f045a9b","event_at":"2026-07-28T02:06:38.729000Z","event_type":"last_trade_price","frame_hash":"01fa3cb6f76fe06e02966f9cb4b1a16e0b8fb1603110c1c0d30db4e7bc9c8933","frame_index":0,"kind":"data","monotonic_ns":306382709584500,"payload":{"asset_id":"39272994714739463168905443499424551362424437245880253267329605556587274644733","event_type":"last_trade_price","fee_rate_bps":"0","market":"0xda6f0e0e93fc8469e0159a166028d017bddbc162b86f66bac90391379603d962","price":"0.6","side":"SELL","size":"0.02","timestamp":"1785204398729","transaction_hash":"0xadd58a4b500ae058159f9547bbdfa30ca2df45aee8f2e4d96572cc8a2f044e45"},"payload_hash":"877aa829b4f6e637647e8c67c3a08275197ac9ce756b794fba2f8bd59dc6a024","raw_frame":"{\"market\":\"0xda6f0e0e93fc8469e0159a166028d017bddbc162b86f66bac90391379603d962\", \"asset_id\":\"39272994714739463168905443499424551362424437245880253267329605556587274644733\", \"price\":\"0.6\", \"size\":\"0.02\", \"fee_rate_bps\":\"0\", \"side\":\"SELL\", \"timestamp\":\"1785204398729\", \"event_type\":\"last_trade_price\", \"transaction_hash\":\"0xadd58a4b500ae058159f9547bbdfa30ca2df45aee8f2e4d96572cc8a2f044e45\"}","received_at":"2026-07-28T02:06:39.702576Z","schema_version":"clob-market-ws.last_trade_price.v1","sequence":null,"server_hash":null,"server_timestamp":"1785204398729","session_id":"d2757dd6dad94f3b9fe67e8dbf1adc37","source":"clob_market_ws"},"received_at":"2026-07-28T02:06:39.702576Z","record_id":"5d30ea90b2f6b9aadeb417a02e905fa69b33f52c260a89f6498ee524df17c9ed","schema_fingerprint":"95ad9be75a4b695cd99991e12b2592bc7346f3f5388a82d0000ba65bc0d9fd0a","schema_version":"edge-lab-recorder.raw.v1","sequence":null,"source":"clob_market_ws"}
{"event_at":"2026-07-28T02:06:38.741000Z","event_fingerprint":"a14a1705b1af1c8d50b523d3c49c29de6f1c4051c947e34a0e931faa84520619","payload":{"connection_id":"5d29200f65794d4d9ab6ef271f045a9b","event_at":"2026-07-28T02:06:38.741000Z","event_type":"price_change","frame_hash":"ee36f80a88caef836f69b72c0eac0d09e4a379836272dfbb97bf91a181ac20bd","frame_index":0,"kind":"data","monotonic_ns":306382714311916,"payload":{"event_type":"price_change","market":"0xda6f0e0e93fc8469e0159a166028d017bddbc162b86f66bac90391379603d962","price_changes":[{"asset_id":"39272994714739463168905443499424551362424437245880253267329605556587274644733","best_ask":"0.61","best_bid":"0.6","hash":"f0b9d20ff3116b15a4b30c3a0cfbfa6d2c9628da","price":"0.58","side":"BUY","size":"107.21"},{"asset_id":"20893381255801015515826997628594359667013752732428989472914000440642900266717","best_ask":"0.4","best_bid":"0.39","hash":"1bdd3ca42a100d780a6d5900f7facb3cd3a7cb55","price":"0.42","side":"SELL","size":"107.21"}],"timestamp":"1785204398741"},"payload_hash":"ac18bf4a086890758f357d58a1387f10223dea842db082ff7d02ff5ae8b26894","raw_frame":"{\"market\":\"0xda6f0e0e93fc8469e0159a166028d017bddbc162b86f66bac90391379603d962\", \"price_changes\":[{\"asset_id\":\"39272994714739463168905443499424551362424437245880253267329605556587274644733\", \"price\":\"0.58\", \"size\":\"107.21\", \"side\":\"BUY\", \"hash\":\"f0b9d20ff3116b15a4b30c3a0cfbfa6d2c9628da\", \"best_bid\":\"0.6\", \"best_ask\":\"0.61\"}, {\"asset_id\":\"20893381255801015515826997628594359667013752732428989472914000440642900266717\", \"price\":\"0.42\", \"size\":\"107.21\", \"side\":\"SELL\", \"hash\":\"1bdd3ca42a100d780a6d5900f7facb3cd3a7cb55\", \"best_bid\":\"0.39\", \"best_ask\":\"0.4\"}], \"timestamp\":\"1785204398741\", \"event_type\":\"price_change\"}","received_at":"2026-07-28T02:06:39.707304Z","schema_version":"clob-market-ws.price_change.v1","sequence":null,"server_hash":null,"server_timestamp":"1785204398741","session_id":"d2757dd6dad94f3b9fe67e8dbf1adc37","source":"clob_market_ws"},"received_at":"2026-07-28T02:06:39.707304Z","record_id":"030e0ae91d24e0ab4ae86afc64a59eea66ef105af9df11331ff5938ef132f599","schema_fingerprint":"4aa3821a28b0b7c2400bc59aba4bcc0a76e971dadd19610d3ad38c768e124dc7","schema_version":"edge-lab-recorder.raw.v1","sequence":null,"source":"clob_market_ws"}
{"event_at":"2026-07-28T02:06:38.757000Z","event_fingerprint":"75e22647de15192edbfd7eea202539d16522af95c483c4e0966f00d287ad06a2","payload":{"connection_id":"5d29200f65794d4d9ab6ef271f045a9b","event_at":"2026-07-28T02:06:38.757000Z","event_type":"price_change","frame_hash":"ba9b39c36658bcb4e82d4971344da2a034ba3cef3e644e380d2bb3167106bf20","frame_index":0,"kind":"data","monotonic_ns":306382718653708,"payload":{"event_type":"price_change","market":"0xda6f0e0e93fc8469e0159a166028d017bddbc162b86f66bac90391379603d962","price_changes":[{"asset_id":"20893381255801015515826997628594359667013752732428989472914000440642900266717","best_ask":"0.4","best_bid":"0.39","hash":"a8f1e75e61f5295f0ec62c624f0c0957a7fb8b5a","price":"0.39","side":"BUY","size":"50"},{"asset_id":"39272994714739463168905443499424551362424437245880253267329605556587274644733","best_ask":"0.61","best_bid":"0.6","hash":"7e649ee39fdefaa44f2e1b64ea3db2705f2e1763","price":"0.61","side":"SELL","size":"50"}],"timestamp":"1785204398757"},"payload_hash":"e664a43f9ba148dbc79ed395c4b03b31d7311d65ffce41a80030ae4363b4ff87","raw_frame":"{\"market\":\"0xda6f0e0e93fc8469e0159a166028d017bddbc162b86f66bac90391379603d962\", \"price_changes\":[{\"asset_id\":\"20893381255801015515826997628594359667013752732428989472914000440642900266717\", \"price\":\"0.39\", \"size\":\"50\", \"side\":\"BUY\", \"hash\":\"a8f1e75e61f5295f0ec62c624f0c0957a7fb8b5a\", \"best_bid\":\"0.39\", \"best_ask\":\"0.4\"}, {\"asset_id\":\"39272994714739463168905443499424551362424437245880253267329605556587274644733\", \"price\":\"0.61\", \"size\":\"50\", \"side\":\"SELL\", \"hash\":\"7e649ee39fdefaa44f2e1b64ea3db2705f2e1763\", \"best_bid\":\"0.6\", \"best_ask\":\"0.61\"}], \"timestamp\":\"1785204398757\", \"event_type\":\"price_change\"}","received_at":"2026-07-28T02:06:39.711646Z","schema_version":"clob-market-ws.price_change.v1","sequence":null,"server_hash":null,"server_timestamp":"1785204398757","session_id":"d2757dd6dad94f3b9fe67e8dbf1adc37","source":"clob_market_ws"},"received_at":"2026-07-28T02:06:39.711646Z","record_id":"1d6950141385e3f6ec435bfd699cb8bb258fdad70987249c8fd798e96986e22f","schema_fingerprint":"4aa3821a28b0b7c2400bc59aba4bcc0a76e971dadd19610d3ad38c768e124dc7","schema_version":"edge-lab-recorder.raw.v1","sequence":null,"source":"clob_market_ws"}
{"event_at":"2026-07-28T02:06:38.770000Z","event_fingerprint":"b6d58c7e7ff0ea6df3468e899f66040ba8013baa9447632051ef9a9ab38a96a6","payload":{"connection_id":"5d29200f65794d4d9ab6ef271f045a9b","event_at":"2026-07-28T02:06:38.770000Z","event_type":"price_change","frame_hash":"66ca2d7186369121ab6508ec0c7fa3d29acd0530baf6ee65ab9d693a15c422dd","frame_index":0,"kind":"data","monotonic_ns":306382723894708,"payload":{"event_type":"price_change","market":"0xda6f0e0e93fc8469e0159a166028d017bddbc162b86f66bac90391379603d962","price_changes":[{"asset_id":"20893381255801015515826997628594359667013752732428989472914000440642900266717","best_ask":"0.4","best_bid":"0.39","hash":"ea1d6730d03b78248280383a641b7133246641fc","price":"0.39","side":"BUY","size":"32"},{"asset_id":"39272994714739463168905443499424551362424437245880253267329605556587274644733","best_ask":"0.61","best_bid":"0.6","hash":"5d2d99bf8c95b6bca76e5065f5371bf30403fe6c","price":"0.61","side":"SELL","size":"32"}],"timestamp":"1785204398770"},"payload_hash":"7a4353bd03fadb5e404c1af90141f2fccca4fb45cad176ae05403e9da91fd006","raw_frame":"{\"market\":\"0xda6f0e0e93fc8469e0159a166028d017bddbc162b86f66bac90391379603d962\", \"price_changes\":[{\"asset_id\":\"20893381255801015515826997628594359667013752732428989472914000440642900266717\", \"price\":\"0.39\", \"size\":\"32\", \"side\":\"BUY\", \"hash\":\"ea1d6730d03b78248280383a641b7133246641fc\", \"best_bid\":\"0.39\", \"best_ask\":\"0.4\"}, {\"asset_id\":\"39272994714739463168905443499424551362424437245880253267329605556587274644733\", \"price\":\"0.61\", \"size\":\"32\", \"side\":\"SELL\", \"hash\":\"5d2d99bf8c95b6bca76e5065f5371bf30403fe6c\", \"best_bid\":\"0.6\", \"best_ask\":\"0.61\"}], \"timestamp\":\"1785204398770\", \"event_type\":\"price_change\"}","received_at":"2026-07-28T02:06:39.716886Z","schema_version":"clob-market-ws.price_change.v1","sequence":null,"server_hash":null,"server_timestamp":"1785204398770","session_id":"d2757dd6dad94f3b9fe67e8dbf1adc37","source":"clob_market_ws"},"received_at":"2026-07-28T02:06:39.716886Z","record_id":"920b5ebfc87ee04efe7f52f131d8ebaa02dc80ffceccca3039cd7195ccd90763","schema_fingerprint":"4aa3821a28b0b7c2400bc59aba4bcc0a76e971dadd19610d3ad38c768e124dc7","schema_version":"edge-lab-recorder.raw.v1","sequence":null,"source":"clob_market_ws"}
{"event_at":"2026-07-28T02:06:38.770000Z","event_fingerprint":"c8b1ee8235cc416af2ee5eb2d3030032487ffcbd534cf64d1bebf28da1a4a33c","payload":{"connection_id":"5d29200f65794d4d9ab6ef271f045a9b","event_at":"2026-07-28T02:06:38.770000Z","event_type":"price_change","frame_hash":"c234205ecef94aabd82c5ec5ed27a1d63e64f52acb60b5f603a7be63cac457c1","frame_index":0,"kind":"data","monotonic_ns":306382729335166,"payload":{"event_type":"price_change","market":"0xda6f0e0e93fc8469e0159a166028d017bddbc162b86f66bac90391379603d962","price_changes":[{"asset_id":"20893381255801015515826997628594359667013752732428989472914000440642900266717","best_ask":"0.4","best_bid":"0.39","hash":"2c8eb419d8ad6815d93a80225adaa9aab26e550a","price":"0.39","side":"BUY","size":"22"},{"asset_id":"39272994714739463168905443499424551362424437245880253267329605556587274644733","best_ask":"0.61","best_bid":"0.6","hash":"385fe9fa56317bfb8dfbb6f4b3759d20d52343b7","price":"0.61","side":"SELL","size":"22"}],"timestamp":"1785204398770"},"payload_hash":"9d11d0861df66be649b91cb68779329dc4cb37fb4c98b0a8c1ff1ade036f62a7","raw_frame":"{\"market\":\"0xda6f0e0e93fc8469e0159a166028d017bddbc162b86f66bac90391379603d962\", \"price_changes\":[{\"asset_id\":\"20893381255801015515826997628594359667013752732428989472914000440642900266717\", \"price\":\"0.39\", \"size\":\"22\", \"side\":\"BUY\", \"hash\":\"2c8eb419d8ad6815d93a80225adaa9aab26e550a\", \"best_bid\":\"0.39\", \"best_ask\":\"0.4\"}, {\"asset_id\":\"39272994714739463168905443499424551362424437245880253267329605556587274644733\", \"price\":\"0.61\", \"size\":\"22\", \"side\":\"SELL\", \"hash\":\"385fe9fa56317bfb8dfbb6f4b3759d20d52343b7\", \"best_bid\":\"0.6\", \"best_ask\":\"0.61\"}], \"timestamp\":\"1785204398770\", \"event_type\":\"price_change\"}","received_at":"2026-07-28T02:06:39.722325Z","schema_version":"clob-market-ws.price_change.v1","sequence":null,"server_hash":null,"server_timestamp":"1785204398770","session_id":"d2757dd6dad94f3b9fe67e8dbf1adc37","source":"clob_market_ws"},"received_at":"2026-07-28T02:06:39.722325Z","record_id":"240923ffdf7ba2644aa316bf3ec1dda571fa837b890c4be5764618e6ee0813be","schema_fingerprint":"4aa3821a28b0b7c2400bc59aba4bcc0a76e971dadd19610d3ad38c768e124dc7","schema_version":"edge-lab-recorder.raw.v1","sequence":null,"source":"clob_market_ws"}
{"event_at":"2026-07-28T02:06:38.782000Z","event_fingerprint":"96f4231e380e66d77dc8713c743cccf4dcd683d42771747f22f02a7907eb2395","payload":{"connection_id":"5d29200f65794d4d9ab6ef271f045a9b","event_at":"2026-07-28T02:06:38.782000Z","event_type":"price_change","frame_hash":"8cca64f8dcb624e974d8fdf4bf729dc0b1ac276f74c3f26c590cacc5664aa92b","frame_index":0,"kind":"data","monotonic_ns":306382734472333,"payload":{"event_type":"price_change","market":"0xda6f0e0e93fc8469e0159a166028d017bddbc162b86f66bac90391379603d962","price_changes":[{"asset_id":"39272994714739463168905443499424551362424437245880253267329605556587274644733","best_ask":"0.61","best_bid":"0.6","hash":"beff82595d70e3dca7a74f720b26f4f76bfdfaba","price":"0.03","side":"BUY","size":"648.1"},{"asset_id":"20893381255801015515826997628594359667013752732428989472914000440642900266717","best_ask":"0.4","best_bid":"0.39","hash":"d524d4948203d61bc878839a95d77cb069247a97","price":"0.97","side":"SELL","size":"648.1"}],"timestamp":"1785204398782"},"payload_hash":"73ea17b1c16fc13df8c24aa7051edbdc6eb1dc84914b3ba7456124760bfb5ddf","raw_frame":"{\"market\":\"0xda6f0e0e93fc8469e0159a166028d017bddbc162b86f66bac90391379603d962\", \"price_changes\":[{\"asset_id\":\"39272994714739463168905443499424551362424437245880253267329605556587274644733\", \"price\":\"0.03\", \"size\":\"648.1\", \"side\":\"BUY\", \"hash\":\"beff82595d70e3dca7a74f720b26f4f76bfdfaba\", \"best_bid\":\"0.6\", \"best_ask\":\"0.61\"}, {\"asset_id\":\"20893381255801015515826997628594359667013752732428989472914000440642900266717\", \"price\":\"0.97\", \"size\":\"648.1\", \"side\":\"SELL\", \"hash\":\"d524d4948203d61bc878839a95d77cb069247a97\", \"best_bid\":\"0.39\", \"best_ask\":\"0.4\"}], \"timestamp\":\"1785204398782\", \"event_type\":\"price_change\"}","received_at":"2026-07-28T02:06:39.727462Z","schema_version":"clob-market-ws.price_change.v1","sequence":null,"server_hash":null,"server_timestamp":"1785204398782","session_id":"d2757dd6dad94f3b9fe67e8dbf1adc37","source":"clob_market_ws"},"received_at":"2026-07-28T02:06:39.727462Z","record_id":"1169fb2fbead2291c23c0b2e26c42b0bd07633eb7b5c8b4db621143d65bcab24","schema_fingerprint":"4aa3821a28b0b7c2400bc59aba4bcc0a76e971dadd19610d3ad38c768e124dc7","schema_version":"edge-lab-recorder.raw.v1","sequence":null,"source":"clob_market_ws"}
{"event_at":"2026-07-28T02:06:38.783000Z","event_fingerprint":"7680462db64b1b8eb1445fcdb631a8ee8d15893669b9413fc641d1d98ca636c2","payload":{"connection_id":"5d29200f65794d4d9ab6ef271f045a9b","event_at":"2026-07-28T02:06:38.783000Z","event_type":"price_change","frame_hash":"306019ac13baaf0c70dba774bd4ed1b1780d2254e53143148d50742b3b03289e","frame_index":0,"kind":"data","monotonic_ns":306382738013708,"payload":{"event_type":"price_change","market":"0xda6f0e0e93fc8469e0159a166028d017bddbc162b86f66bac90391379603d962","price_changes":[{"asset_id":"39272994714739463168905443499424551362424437245880253267329605556587274644733","best_ask":"0.61","best_bid":"0.6","hash":"aa30405c53a4c7ab5c16725f568aca3c082ed47b","price":"0.54","side":"BUY","size":"109"},{"asset_id":"20893381255801015515826997628594359667013752732428989472914000440642900266717","best_ask":"0.4","best_bid":"0.39","hash":"817faeaeaaa3dc9bf5019d1fe953bbaf677367cd","price":"0.46","side":"SELL","size":"109"}],"timestamp":"1785204398783"},"payload_hash":"4dd6b9857d140286d16763f3a811a6753c05c2fa2a9f9a3b97ce9a0ba0a3fafc","raw_frame":"{\"market\":\"0xda6f0e0e93fc8469e0159a166028d017bddbc162b86f66bac90391379603d962\", \"price_changes\":[{\"asset_id\":\"39272994714739463168905443499424551362424437245880253267329605556587274644733\", \"price\":\"0.54\", \"size\":\"109\", \"side\":\"BUY\", \"hash\":\"aa30405c53a4c7ab5c16725f568aca3c082ed47b\", \"best_bid\":\"0.6\", \"best_ask\":\"0.61\"}, {\"asset_id\":\"20893381255801015515826997628594359667013752732428989472914000440642900266717\", \"price\":\"0.46\", \"size\":\"109\", \"side\":\"SELL\", \"hash\":\"817faeaeaaa3dc9bf5019d1fe953bbaf677367cd\", \"best_bid\":\"0.39\", \"best_ask\":\"0.4\"}], \"timestamp\":\"1785204398783\", \"event_type\":\"price_change\"}","received_at":"2026-07-28T02:06:39.731005Z","schema_version":"clob-market-ws.price_change.v1","sequence":null,"server_hash":null,"server_timestamp":"1785204398783","session_id":"d2757dd6dad94f3b9fe67e8dbf1adc37","source":"clob_market_ws"},"received_at":"2026-07-28T02:06:39.731005Z","record_id":"49ee29f9f14a8acf176c81a010682092abab68a16cd0eae44866d05e1981d948","schema_fingerprint":"4aa3821a28b0b7c2400bc59aba4bcc0a76e971dadd19610d3ad38c768e124dc7","schema_version":"edge-lab-recorder.raw.v1","sequence":null,"source":"clob_market_ws"}
{"event_at":"2026-07-28T02:06:38.784000Z","event_fingerprint":"bcfd99acd2e4a5d18fb00fc0e3927dc715078f83a51b6a8582bd96b2ab2add61","payload":{"connection_id":"5d29200f65794d4d9ab6ef271f045a9b","event_at":"2026-07-28T02:06:38.784000Z","event_type":"price_change","frame_hash":"56ba1c5ae6651cc908e8cf4bc017acd80791d3104096f89c8b126f6de189bfe2","frame_index":0,"kind":"data","monotonic_ns":306382742420541,"payload":{"event_type":"price_change","market":"0xda6f0e0e93fc8469e0159a166028d017bddbc162b86f66bac90391379603d962","price_changes":[{"asset_id":"39272994714739463168905443499424551362424437245880253267329605556587274644733","best_ask":"0.61","best_bid":"0.6","hash":"d3aed5f7d4987247b785d47cb7ebe31bfc1c4fbf","price":"0.54","side":"BUY","size":"139"},{"asset_id":"20893381255801015515826997628594359667013752732428989472914000440642900266717","best_ask":"0.4","best_bid":"0.39","hash":"bcca3eda239ab3bf809cda2cff36ba6084779091","price":"0.46","side":"SELL","size":"139"}],"timestamp":"1785204398784"},"payload_hash":"c8d3b05ca98948c05043d5755d57277bf683a6ecfc2c6935d7d57dfe443e637d","raw_frame":"{\"market\":\"0xda6f0e0e93fc8469e0159a166028d017bddbc162b86f66bac90391379603d962\", \"price_changes\":[{\"asset_id\":\"39272994714739463168905443499424551362424437245880253267329605556587274644733\", \"price\":\"0.54\", \"size\":\"139\", \"side\":\"BUY\", \"hash\":\"d3aed5f7d4987247b785d47cb7ebe31bfc1c4fbf\", \"best_bid\":\"0.6\", \"best_ask\":\"0.61\"}, {\"asset_id\":\"20893381255801015515826997628594359667013752732428989472914000440642900266717\", \"price\":\"0.46\", \"size\":\"139\", \"side\":\"SELL\", \"hash\":\"bcca3eda239ab3bf809cda2cff36ba6084779091\", \"best_bid\":\"0.39\", \"best_ask\":\"0.4\"}], \"timestamp\":\"1785204398784\", \"event_type\":\"price_change\"}","received_at":"2026-07-28T02:06:39.735411Z","schema_version":"clob-market-ws.price_change.v1","sequence":null,"server_hash":null,"server_timestamp":"1785204398784","session_id":"d2757dd6dad94f3b9fe67e8dbf1adc37","source":"clob_market_ws"},"received_at":"2026-07-28T02:06:39.735411Z","record_id":"1129e8aa5590e8c73ae779ab26e4487c13ec2f2dff10a36ca67d6d255610a998","schema_fingerprint":"4aa3821a28b0b7c2400bc59aba4bcc0a76e971dadd19610d3ad38c768e124dc7","schema_version":"edge-lab-recorder.raw.v1","sequence":null,"source":"clob_market_ws"}
{"event_at":"2026-07-28T02:06:38.787000Z","event_fingerprint":"7a5bd76ccca51e9266112ea157e02c2966e47a1b4553095b403ce93a601c760d","payload":{"connection_id":"5d29200f65794d4d9ab6ef271f045a9b","event_at":"2026-07-28T02:06:38.787000Z","event_type":"price_change","frame_hash":"95e745224d4dbb66216437c227b06afd108204e2d3b9c74c2f0b0637484838a2","frame_index":0,"kind":"data","monotonic_ns":306382746714875,"payload":{"event_type":"price_change","market":"0xda6f0e0e93fc8469e0159a166028d017bddbc162b86f66bac90391379603d962","price_changes":[{"asset_id":"39272994714739463168905443499424551362424437245880253267329605556587274644733","best_ask":"0.61","best_bid":"0.6","hash":"cb265855b94e9186a02ef008841c0ba28f7ad143","price":"0.54","side":"BUY","size":"169"},{"asset_id":"20893381255801015515826997628594359667013752732428989472914000440642900266717","best_ask":"0.4","best_bid":"0.39","hash":"b19b4ed17be5afa7d5187709f2dd6ff1f387625c","price":"0.46","side":"SELL","size":"169"}],"timestamp":"1785204398787"},"payload_hash":"ba1a42fe43d547b7cd7796088fa63f5e50a220867b92b9e0ceb3cad4eca519f4","raw_frame":"{\"market\":\"0xda6f0e0e93fc8469e0159a166028d017bddbc162b86f66bac90391379603d962\", \"price_changes\":[{\"asset_id\":\"39272994714739463168905443499424551362424437245880253267329605556587274644733\", \"price\":\"0.54\", \"size\":\"169\", \"side\":\"BUY\", \"hash\":\"cb265855b94e9186a02ef008841c0ba28f7ad143\", \"best_bid\":\"0.6\", \"best_ask\":\"0.61\"}, {\"asset_id\":\"20893381255801015515826997628594359667013752732428989472914000440642900266717\", \"price\":\"0.46\", \"size\":\"169\", \"side\":\"SELL\", \"hash\":\"b19b4ed17be5afa7d5187709f2dd6ff1f387625c\", \"best_bid\":\"0.39\", \"best_ask\":\"0.4\"}], \"timestamp\":\"1785204398787\", \"event_type\":\"price_change\"}","received_at":"2026-07-28T02:06:39.739706Z","schema_version":"clob-market-ws.price_change.v1","sequence":null,"server_hash":null,"server_timestamp":"1785204398787","session_id":"d2757dd6dad94f3b9fe67e8dbf1adc37","source":"clob_market_ws"},"received_at":"2026-07-28T02:06:39.739706Z","record_id":"08dd4f02d17947f90b68b47ed45ab53ceca763653d50c575e6cfcbf7d052edf0","schema_fingerprint":"4aa3821a28b0b7c2400bc59aba4bcc0a76e971dadd19610d3ad38c768e124dc7","schema_version":"edge-lab-recorder.raw.v1","sequence":null,"source":"clob_market_ws"}
{"event_at":"2026-07-28T02:06:38.798000Z","event_fingerprint":"270eaa77e35d7dc031a0a277887fb9edd4d8f9bcdd10c54af27bdf12a4d5a884","payload":{"connection_id":"5d29200f65794d4d9ab6ef271f045a9b","event_at":"2026-07-28T02:06:38.798000Z","event_type":"price_change","frame_hash":"c87b6d532871f60a0b53c9523730ed082fb31c9b4faadc25700e488272f0cf2e","frame_index":0,"kind":"data","monotonic_ns":306382752397666,"payload":{"event_type":"price_change","market":"0xda6f0e0e93fc8469e0159a166028d017bddbc162b86f66bac90391379603d962","price_changes":[{"asset_id":"20893381255801015515826997628594359667013752732428989472914000440642900266717","best_ask":"0.4","best_bid":"0.39","hash":"1b9996a13dc72d0d9e32ab0235f8b04b7224eae0","price":"0.39","side":"BUY","size":"38"},{"asset_id":"39272994714739463168905443499424551362424437245880253267329605556587274644733","best_ask":"0.61","best_bid":"0.6","hash":"c337b7dda4eaf2f8bc7bc063904803be843df6ab","price":"0.61","side":"SELL","size":"38"}],"timestamp":"1785204398798"},"payload_hash":"2acecc9a4e16a7d53cea1e01798820673dfedc36c923f72d52e0993b3e02c803","raw_frame":"{\"market\":\"0xda6f0e0e93fc8469e0159a166028d017bddbc162b86f66bac90391379603d962\", \"price_changes\":[{\"asset_id\":\"20893381255801015515826997628594359667013752732428989472914000440642900266717\", \"price\":\"0.39\", \"size\":\"38\", \"side\":\"BUY\", \"hash\":\"1b9996a13dc72d0d9e32ab0235f8b04b7224eae0\", \"best_bid\":\"0.39\", \"best_ask\":\"0.4\"}, {\"asset_id\":\"39272994714739463168905443499424551362424437245880253267329605556587274644733\", \"price\":\"0.61\", \"size\":\"38\", \"side\":\"SELL\", \"hash\":\"c337b7dda4eaf2f8bc7bc063904803be843df6ab\", \"best_bid\":\"0.6\", \"best_ask\":\"0.61\"}], \"timestamp\":\"1785204398798\", \"event_type\":\"price_change\"}","received_at":"2026-07-28T02:06:39.745387Z","schema_version":"clob-market-ws.price_change.v1","sequence":null,"server_hash":null,"server_timestamp":"1785204398798","session_id":"d2757dd6dad94f3b9fe67e8dbf1adc37","source":"clob_market_ws"},"received_at":"2026-07-28T02:06:39.745387Z","record_id":"a1f5702b4a2ede31459785c05c1296dfee9eea185054ab8f38c471d38b47afc6","schema_fingerprint":"4aa3821a28b0b7c2400bc59aba4bcc0a76e971dadd19610d3ad38c768e124dc7","schema_version":"edge-lab-recorder.raw.v1","sequence":null,"source":"clob_market_ws"}
{"event_at":"2026-07-28T02:06:38.806000Z","event_fingerprint":"949247101a656ffad70c2400f16e3feacc4cbe71a6152864fa126a85ed001bde","payload":{"connection_id":"5d29200f65794d4d9ab6ef271f045a9b","event_at":"2026-07-28T02:06:38.806000Z","event_type":"price_change","frame_hash":"3f1101c30c0949f4afb74ec9c798c15f93a0730fe2e221e1335385ca8bb6d3d5","frame_index":0,"kind":"data","monotonic_ns":306382757717625,"payload":{"event_type":"price_change","market":"0xda6f0e0e93fc8469e0159a166028d017bddbc162b86f66bac90391379603d962","price_changes":[{"asset_id":"20893381255801015515826997628594359667013752732428989472914000440642900266717","best_ask":"0.4","best_bid":"0.39","hash":"609a8b4c0b3e1eea589f85e3116d0e535d268f3a","price":"0.39","side":"BUY","size":"46"},{"asset_id":"39272994714739463168905443499424551362424437245880253267329605556587274644733","best_ask":"0.61","best_bid":"0.6","hash":"50fd0318b95e041de76b18a13ff8bae3f774f95e","price":"0.61","side":"SELL","size":"46"}],"timestamp":"1785204398806"},"payload_hash":"6a09e11981af55480a0a58a5485dbb5c6bb88c87b8e916b0ec1d07c6cc4d548d","raw_frame":"{\"market\":\"0xda6f0e0e93fc8469e0159a166028d017bddbc162b86f66bac90391379603d962\", \"price_changes\":[{\"asset_id\":\"20893381255801015515826997628594359667013752732428989472914000440642900266717\", \"price\":\"0.39\", \"size\":\"46\", \"side\":\"BUY\", \"hash\":\"609a8b4c0b3e1eea589f85e3116d0e535d268f3a\", \"best_bid\":\"0.39\", \"best_ask\":\"0.4\"}, {\"asset_id\":\"39272994714739463168905443499424551362424437245880253267329605556587274644733\", \"price\":\"0.61\", \"size\":\"46\", \"side\":\"SELL\", \"hash\":\"50fd0318b95e041de76b18a13ff8bae3f774f95e\", \"best_bid\":\"0.6\", \"best_ask\":\"0.61\"}], \"timestamp\":\"1785204398806\", \"event_type\":\"price_change\"}","received_at":"2026-07-28T02:06:39.750708Z","schema_version":"clob-market-ws.price_change.v1","sequence":null,"server_hash":null,"server_timestamp":"1785204398806","session_id":"d2757dd6dad94f3b9fe67e8dbf1adc37","source":"clob_market_ws"},"received_at":"2026-07-28T02:06:39.750708Z","record_id":"76cf604bcb99679a83b5e72cc0472a5562d19e1d056aca127111cd395c1c3e07","schema_fingerprint":"4aa3821a28b0b7c2400bc59aba4bcc0a76e971dadd19610d3ad38c768e124dc7","schema_version":"edge-lab-recorder.raw.v1","sequence":null,"source":"clob_market_ws"}
{"event_at":"2026-07-28T02:06:38.810000Z","event_fingerprint":"2125f5f125bec3edf81ed5f9208ba5ae2ef2e9745909ebeca30a10a909f7d5fc","payload":{"connection_id":"5d29200f65794d4d9ab6ef271f045a9b","event_at":"2026-07-28T02:06:38.810000Z","event_type":"price_change","frame_hash":"7d5f453531b7e8ee484c0c6bd7cd1997cc9b5d1137bd78d5aa856102b4e491c6","frame_index":0,"kind":"data","monotonic_ns":306382761944250,"payload":{"event_type":"price_change","market":"0xda6f0e0e93fc8469e0159a166028d017bddbc162b86f66bac90391379603d962","price_changes":[{"asset_id":"20893381255801015515826997628594359667013752732428989472914000440642900266717","best_ask":"0.4","best_bid":"0.39","hash":"4f42df9cf9d5d813574c1e3c97c4b3d48e5212d3","price":"0.18","side":"BUY","size":"195.3"},{"asset_id":"39272994714739463168905443499424551362424437245880253267329605556587274644733","best_ask":"0.61","best_bid":"0.6","hash":"9d42fe2b7a70f247863ce50844ab53be4e1db920","price":"0.82","side":"SELL","size":"195.3"}],"timestamp":"1785204398810"},"payload_hash":"00a22f185a7e584d607d7326835a047703606821368def4702a0f4acc82ad411","raw_frame":"{\"market\":\"0xda6f0e0e93fc8469e0159a166028d017bddbc162b86f66bac90391379603d962\", \"price_changes\":[{\"asset_id\":\"20893381255801015515826997628594359667013752732428989472914000440642900266717\", \"price\":\"0.18\", \"size\":\"195.3\", \"side\":\"BUY\", \"hash\":\"4f42df9cf9d5d813574c1e3c97c4b3d48e5212d3\", \"best_bid\":\"0.39\", \"best_ask\":\"0.4\"}, {\"asset_id\":\"39272994714739463168905443499424551362424437245880253267329605556587274644733\", \"price\":\"0.82\", \"size\":\"195.3\", \"side\":\"SELL\", \"hash\":\"9d42fe2b7a70f247863ce50844ab53be4e1db920\", \"best_bid\":\"0.6\", \"best_ask\":\"0.61\"}], \"timestamp\":\"1785204398810\", \"event_type\":\"price_change\"}","received_at":"2026-07-28T02:06:39.754936Z","schema_version":"clob-market-ws.price_change.v1","sequence":null,"server_hash":null,"server_timestamp":"1785204398810","session_id":"d2757dd6dad94f3b9fe67e8dbf1adc37","source":"clob_market_ws"},"received_at":"2026-07-28T02:06:39.754936Z","record_id":"d5214503a5a9ce043d139bd6fc25249be6aa80524d08fc74a4ee98800258df4c","schema_fingerprint":"4aa3821a28b0b7c2400bc59aba4bcc0a76e971dadd19610d3ad38c768e124dc7","schema_version":"edge-lab-recorder.raw.v1","sequence":null,"source":"clob_market_ws"}
{"event_at":"2026-07-28T02:06:38.810000Z","event_fingerprint":"74cfbcb7dd8bb36b2b655683efb471a41ab2d3c093a98550e42d31ddd303a7bd","payload":{"connection_id":"5d29200f65794d4d9ab6ef271f045a9b","event_at":"2026-07-28T02:06:38.810000Z","event_type":"price_change","frame_hash":"477ea3539ba4b03d651db7a4e27305f55e5c39fcd23371347644ff12b7318225","frame_index":0,"kind":"data","monotonic_ns":306382773481041,"payload":{"event_type":"price_change","market":"0xda6f0e0e93fc8469e0159a166028d017bddbc162b86f66bac90391379603d962","price_changes":[{"asset_id":"20893381255801015515826997628594359667013752732428989472914000440642900266717","best_ask":"0.4","best_bid":"0.39","hash":"4f42df9cf9d5d813574c1e3c97c4b3d48e5212d3","price":"0.17","side":"BUY","size":"192.3"},{"asset_id":"39272994714739463168905443499424551362424437245880253267329605556587274644733","best_ask":"0.61","best_bid":"0.6","hash":"9d42fe2b7a70f247863ce50844ab53be4e1db920","price":"0.83","side":"SELL","size":"192.3"}],"timestamp":"1785204398810"},"payload_hash":"83fd8a4d459b1a397a0a416c84aad10b2bd150b730f16d5bc7732c6bc1e7fd0e","raw_frame":"{\"market\":\"0xda6f0e0e93fc8469e0159a166028d017bddbc162b86f66bac90391379603d962\", \"price_changes\":[{\"asset_id\":\"20893381255801015515826997628594359667013752732428989472914000440642900266717\", \"price\":\"0.17\", \"size\":\"192.3\", \"side\":\"BUY\", \"hash\":\"4f42df9cf9d5d813574c1e3c97c4b3d48e5212d3\", \"best_bid\":\"0.39\", \"best_ask\":\"0.4\"}, {\"asset_id\":\"39272994714739463168905443499424551362424437245880253267329605556587274644733\", \"price\":\"0.83\", \"size\":\"192.3\", \"side\":\"SELL\", \"hash\":\"9d42fe2b7a70f247863ce50844ab53be4e1db920\", \"best_bid\":\"0.6\", \"best_ask\":\"0.61\"}], \"timestamp\":\"1785204398810\", \"event_type\":\"price_change\"}","received_at":"2026-07-28T02:06:39.766471Z","schema_version":"clob-market-ws.price_change.v1","sequence":null,"server_hash":null,"server_timestamp":"1785204398810","session_id":"d2757dd6dad94f3b9fe67e8dbf1adc37","source":"clob_market_ws"},"received_at":"2026-07-28T02:06:39.766471Z","record_id":"5c0e0559a0045287d18680892b2db512210d65aad53e734a60962d0aeb4c0778","schema_fingerprint":"4aa3821a28b0b7c2400bc59aba4bcc0a76e971dadd19610d3ad38c768e124dc7","schema_version":"edge-lab-recorder.raw.v1","sequence":null,"source":"clob_market_ws"}
{"event_at":"2026-07-28T02:06:38.831000Z","event_fingerprint":"f4a73f9dc86cc55bc4772636c59627ae5edd0ce08c0c34f09ffeb11731349cab","payload":{"connection_id":"5d29200f65794d4d9ab6ef271f045a9b","event_at":"2026-07-28T02:06:38.831000Z","event_type":"price_change","frame_hash":"8ff7cb4a130814ccc2fc79a3878319959f7d461d7e5943229cb44f2a3157481e","frame_index":0,"kind":"data","monotonic_ns":306382779308416,"payload":{"event_type":"price_change","market":"0xda6f0e0e93fc8469e0159a166028d017bddbc162b86f66bac90391379603d962","price_changes":[{"asset_id":"20893381255801015515826997628594359667013752732428989472914000440642900266717","best_ask":"0.4","best_bid":"0.39","hash":"8c0b26aeb1298f47588dc2ae358e077687bdf742","price":"0.38","side":"BUY","size":"54"},{"asset_id":"39272994714739463168905443499424551362424437245880253267329605556587274644733","best_ask":"0.61","best_bid":"0.6","hash":"f2ab146ea5b2eef669be8a2cfaef48ad5d269754","price":"0.62","side":"SELL","size":"54"}],"timestamp":"1785204398831"},"payload_hash":"26925b675e1820bb1883983729b277cd30e4a5a679a0db02476bfcf9b5c214a1","raw_frame":"{\"market\":\"0xda6f0e0e93fc8469e0159a166028d017bddbc162b86f66bac90391379603d962\", \"price_changes\":[{\"asset_id\":\"20893381255801015515826997628594359667013752732428989472914000440642900266717\", \"price\":\"0.38\", \"size\":\"54\", \"side\":\"BUY\", \"hash\":\"8c0b26aeb1298f47588dc2ae358e077687bdf742\", \"best_bid\":\"0.39\", \"best_ask\":\"0.4\"}, {\"asset_id\":\"39272994714739463168905443499424551362424437245880253267329605556587274644733\", \"price\":\"0.62\", \"size\":\"54\", \"side\":\"SELL\", \"hash\":\"f2ab146ea5b2eef669be8a2cfaef48ad5d269754\", \"best_bid\":\"0.6\", \"best_ask\":\"0.61\"}], \"timestamp\":\"1785204398831\", \"event_type\":\"price_change\"}","received_at":"2026-07-28T02:06:39.772299Z","schema_version":"clob-market-ws.price_change.v1","sequence":null,"server_hash":null,"server_timestamp":"1785204398831","session_id":"d2757dd6dad94f3b9fe67e8dbf1adc37","source":"clob_market_ws"},"received_at":"2026-07-28T02:06:39.772299Z","record_id":"443e9b3d9e0faed7bb11080dccc2835b45d35e8a274d198583fdbd24df590da4","schema_fingerprint":"4aa3821a28b0b7c2400bc59aba4bcc0a76e971dadd19610d3ad38c768e124dc7","schema_version":"edge-lab-recorder.raw.v1","sequence":null,"source":"clob_market_ws"}
{"event_at":"2026-07-28T02:06:38.851000Z","event_fingerprint":"4e4968a9264687b86c5618d0dbeeb9c39ea1481aba0f1520c1017e6918c5f091","payload":{"connection_id":"5d29200f65794d4d9ab6ef271f045a9b","event_at":"2026-07-28T02:06:38.851000Z","event_type":"price_change","frame_hash":"1f8f7bc94e6cadfac884713a4cf10f89bff996b2fe49336f8846e55142a45af3","frame_index":0,"kind":"data","monotonic_ns":306382789045333,"payload":{"event_type":"price_change","market":"0xda6f0e0e93fc8469e0159a166028d017bddbc162b86f66bac90391379603d962","price_changes":[{"asset_id":"39272994714739463168905443499424551362424437245880253267329605556587274644733","best_ask":"0.61","best_bid":"0.6","hash":"37ae6e3ffd7ecbfce283de92dcfae7f894b6c8e2","price":"0.01","side":"BUY","size":"5613.02"},{"asset_id":"20893381255801015515826997628594359667013752732428989472914000440642900266717","best_ask":"0.4","best_bid":"0.39","hash":"56451968ddd4ec1643322aa0713a6a83e71c1438","price":"0.99","side":"SELL","size":"5613.02"}],"timestamp":"1785204398851"},"payload_hash":"3eaeda4d3b359e5f55968bc120ec958b9812c5d0ee201f9fca832207cf5da69d","raw_frame":"{\"market\":\"0xda6f0e0e93fc8469e0159a166028d017bddbc162b86f66bac90391379603d962\", \"price_changes\":[{\"asset_id\":\"39272994714739463168905443499424551362424437245880253267329605556587274644733\", \"price\":\"0.01\", \"size\":\"5613.02\", \"side\":\"BUY\", \"hash\":\"37ae6e3ffd7ecbfce283de92dcfae7f894b6c8e2\", \"best_bid\":\"0.6\", \"best_ask\":\"0.61\"}, {\"asset_id\":\"20893381255801015515826997628594359667013752732428989472914000440642900266717\", \"price\":\"0.99\", \"size\":\"5613.02\", \"side\":\"SELL\", \"hash\":\"56451968ddd4ec1643322aa0713a6a83e71c1438\", \"best_bid\":\"0.39\", \"best_ask\":\"0.4\"}], \"timestamp\":\"1785204398851\", \"event_type\":\"price_change\"}","received_at":"2026-07-28T02:06:39.782035Z","schema_version":"clob-market-ws.price_change.v1","sequence":null,"server_hash":null,"server_timestamp":"1785204398851","session_id":"d2757dd6dad94f3b9fe67e8dbf1adc37","source":"clob_market_ws"},"received_at":"2026-07-28T02:06:39.782035Z","record_id":"6bcda706aa534d8106455976e2cb78d4e422f6df11929b4a81fff3c3283aefc8","schema_fingerprint":"4aa3821a28b0b7c2400bc59aba4bcc0a76e971dadd19610d3ad38c768e124dc7","schema_version":"edge-lab-recorder.raw.v1","sequence":null,"source":"clob_market_ws"}
{"event_at":"2026-07-28T02:06:38.857000Z","event_fingerprint":"7bc64852043de8c640a20ed82d719609f76bcc0ac0197723f4d4dbbc1d9d371b","payload":{"connection_id":"5d29200f65794d4d9ab6ef271f045a9b","event_at":"2026-07-28T02:06:38.857000Z","event_type":"price_change","frame_hash":"713e4fb2005804888092a25072ec428687b167be32644a5b937abd686fe60b6a","frame_index":0,"kind":"data","monotonic_ns":306382793469625,"payload":{"event_type":"price_change","market":"0xda6f0e0e93fc8469e0159a166028d017bddbc162b86f66bac90391379603d962","price_changes":[{"asset_id":"39272994714739463168905443499424551362424437245880253267329605556587274644733","best_ask":"0.61","best_bid":"0.6","hash":"4c0abc79b2298b942f5f89bd11aa312fa93fa615","price":"0.56","side":"BUY","size":"103.12"},{"asset_id":"20893381255801015515826997628594359667013752732428989472914000440642900266717","best_ask":"0.4","best_bid":"0.39","hash":"34563ea7a957e4e9bef726e4821fb083f8da6143","price":"0.44","side":"SELL","size":"103.12"}],"timestamp":"1785204398857"},"payload_hash":"f1fbeccc016a6ac43f0a1e6f62c52dbb839bcb89be1c91b6c76b59af569971b3","raw_frame":"{\"market\":\"0xda6f0e0e93fc8469e0159a166028d017bddbc162b86f66bac90391379603d962\", \"price_changes\":[{\"asset_id\":\"39272994714739463168905443499424551362424437245880253267329605556587274644733\", \"price\":\"0.56\", \"size\":\"103.12\", \"side\":\"BUY\", \"hash\":\"4c0abc79b2298b942f5f89bd11aa312fa93fa615\", \"best_bid\":\"0.6\", \"best_ask\":\"0.61\"}, {\"asset_id\":\"20893381255801015515826997628594359667013752732428989472914000440642900266717\", \"price\":\"0.44\", \"size\":\"103.12\", \"side\":\"SELL\", \"hash\":\"34563ea7a957e4e9bef726e4821fb083f8da6143\", \"best_bid\":\"0.39\", \"best_ask\":\"0.4\"}], \"timestamp\":\"1785204398857\", \"event_type\":\"price_change\"}","received_at":"2026-07-28T02:06:39.786459Z","schema_version":"clob-market-ws.price_change.v1","sequence":null,"server_hash":null,"server_timestamp":"1785204398857","session_id":"d2757dd6dad94f3b9fe67e8dbf1adc37","source":"clob_market_ws"},"received_at":"2026-07-28T02:06:39.786459Z","record_id":"a2452da859614739e4feacab1be66659308a2db20d7606136352dcbe11993d26","schema_fingerprint":"4aa3821a28b0b7c2400bc59aba4bcc0a76e971dadd19610d3ad38c768e124dc7","schema_version":"edge-lab-recorder.raw.v1","sequence":null,"source":"clob_market_ws"}
{"event_at":"2026-07-28T02:06:38.862000Z","event_fingerprint":"fc4bb1253a3e6f3292d476e94ed21f6e63decf670bdb3e901848cfd0caa7180a","payload":{"connection_id":"5d29200f65794d4d9ab6ef271f045a9b","event_at":"2026-07-28T02:06:38.862000Z","event_type":"price_change","frame_hash":"5f625a10125905b9241ae03652f944213735fe1e560ba9e71561bd8a3d1ef15d","frame_index":0,"kind":"data","monotonic_ns":306382797935291,"payload":{"event_type":"price_change","market":"0xda6f0e0e93fc8469e0159a166028d017bddbc162b86f66bac90391379603d962","price_changes":[{"asset_id":"20893381255801015515826997628594359667013752732428989472914000440642900266717","best_ask":"0.4","best_bid":"0.39","hash":"075279f7653c1d762ad72d8582d10891dc5c78ab","price":"0.38","side":"BUY","size":"79"},{"asset_id":"39272994714739463168905443499424551362424437245880253267329605556587274644733","best_ask":"0.61","best_bid":"0.6","hash":"2919c19d2f3412ffa76e37eb832520bc57b8616e","price":"0.62","side":"SELL","size":"79"}],"timestamp":"1785204398862"},"payload_hash":"40052d62f90c7db10f2e2698414bbd4bf8d50b4ec381e428e0c048580954e7f4","raw_frame":"{\"market\":\"0xda6f0e0e93fc8469e0159a166028d017bddbc162b86f66bac90391379603d962\", \"price_changes\":[{\"asset_id\":\"20893381255801015515826997628594359667013752732428989472914000440642900266717\", \"price\":\"0.38\", \"size\":\"79\", \"side\":\"BUY\", \"hash\":\"075279f7653c1d762ad72d8582d10891dc5c78ab\", \"best_bid\":\"0.39\", \"best_ask\":\"0.4\"}, {\"asset_id\":\"39272994714739463168905443499424551362424437245880253267329605556587274644733\", \"price\":\"0.62\", \"size\":\"79\", \"side\":\"SELL\", \"hash\":\"2919c19d2f3412ffa76e37eb832520bc57b8616e\", \"best_bid\":\"0.6\", \"best_ask\":\"0.61\"}], \"timestamp\":\"1785204398862\", \"event_type\":\"price_change\"}","received_at":"2026-07-28T02:06:39.790927Z","schema_version":"clob-market-ws.price_change.v1","sequence":null,"server_hash":null,"server_timestamp":"1785204398862","session_id":"d2757dd6dad94f3b9fe67e8dbf1adc37","source":"clob_market_ws"},"received_at":"2026-07-28T02:06:39.790927Z","record_id":"ef9f3c68cc058635ba1d6e9019c9c7fb2e5c22e6d2435a4b5bbbec3b76a09bdc","schema_fingerprint":"4aa3821a28b0b7c2400bc59aba4bcc0a76e971dadd19610d3ad38c768e124dc7","schema_version":"edge-lab-recorder.raw.v1","sequence":null,"source":"clob_market_ws"}
{"event_at":"2026-07-28T02:06:38.875000Z","event_fingerprint":"06d5ae0ace15f27681a90536e3ecd71faa69477858e1af402021ed64e04f3ad6","payload":{"connection_id":"5d29200f65794d4d9ab6ef271f045a9b","event_at":"2026-07-28T02:06:38.875000Z","event_type":"price_change","frame_hash":"eaedeab681f09c2f06d7f09b62fbcf8c8ac0874882aafd4281a59e5a9975c429","frame_index":0,"kind":"data","monotonic_ns":306382802316000,"payload":{"event_type":"price_change","market":"0xda6f0e0e93fc8469e0159a166028d017bddbc162b86f66bac90391379603d962","price_changes":[{"asset_id":"39272994714739463168905443499424551362424437245880253267329605556587274644733","best_ask":"0.61","best_bid":"0.6","hash":"1636453e719b732680f71b768b5265eb0f77b785","price":"0.61","side":"SELL","size":"33"},{"asset_id":"20893381255801015515826997628594359667013752732428989472914000440642900266717","best_ask":"0.4","best_bid":"0.39","hash":"79bdc27835d53c3de5e2d7131b95b8834f5cb038","price":"0.39","side":"BUY","size":"33"}],"timestamp":"1785204398875"},"payload_hash":"96fade64e1b8e0e5ecaa35345069eab9bc8ff1adc0f7717c8f7d06804cdd0527","raw_frame":"{\"market\":\"0xda6f0e0e93fc8469e0159a166028d017bddbc162b86f66bac90391379603d962\", \"price_changes\":[{\"asset_id\":\"39272994714739463168905443499424551362424437245880253267329605556587274644733\", \"price\":\"0.61\", \"size\":\"33\", \"side\":\"SELL\", \"hash\":\"1636453e719b732680f71b768b5265eb0f77b785\", \"best_bid\":\"0.6\", \"best_ask\":\"0.61\"}, {\"asset_id\":\"20893381255801015515826997628594359667013752732428989472914000440642900266717\", \"price\":\"0.39\", \"size\":\"33\", \"side\":\"BUY\", \"hash\":\"79bdc27835d53c3de5e2d7131b95b8834f5cb038\", \"best_bid\":\"0.39\", \"best_ask\":\"0.4\"}], \"timestamp\":\"1785204398875\", \"event_type\":\"price_change\"}","received_at":"2026-07-28T02:06:39.795306Z","schema_version":"clob-market-ws.price_change.v1","sequence":null,"server_hash":null,"server_timestamp":"1785204398875","session_id":"d2757dd6dad94f3b9fe67e8dbf1adc37","source":"clob_market_ws"},"received_at":"2026-07-28T02:06:39.795306Z","record_id":"7dd7641f0f243432f13e239a2acf5d65ba6d22a01c4eeffa5706dbc78707a268","schema_fingerprint":"4aa3821a28b0b7c2400bc59aba4bcc0a76e971dadd19610d3ad38c768e124dc7","schema_version":"edge-lab-recorder.raw.v1","sequence":null,"source":"clob_market_ws"}
{"event_at":"2026-07-28T02:06:38.878000Z","event_fingerprint":"66e596815b1ffbced35bb8475f9cdd94c49fb247e35096e5b29cbad313e2ba25","payload":{"connection_id":"5d29200f65794d4d9ab6ef271f045a9b","event_at":"2026-07-28T02:06:38.878000Z","event_type":"price_change","frame_hash":"6cab40342f6c27d6ab69a10dd9cefe9450e06efb825aa7e7b02ee08940a1507d","frame_index":0,"kind":"data","monotonic_ns":306382807526041,"payload":{"event_type":"price_change","market":"0xda6f0e0e93fc8469e0159a166028d017bddbc162b86f66bac90391379603d962","price_changes":[{"asset_id":"39272994714739463168905443499424551362424437245880253267329605556587274644733","best_ask":"0.61","best_bid":"0.6","hash":"ddb5606b2384492f7d3c3dd27cc46137aacb6150","price":"0.03","side":"BUY","size":"653.1"},{"asset_id":"20893381255801015515826997628594359667013752732428989472914000440642900266717","best_ask":"0.4","best_bid":"0.39","hash":"2d6b1b9163f9af05a835329c7aab914bccf8c2ae","price":"0.97","side":"SELL","size":"653.1"}],"timestamp":"1785204398878"},"payload_hash":"72f23be8b324d3e9c492f3305fdc200af8f86bc6604c1bd18706ea7438fb5bd8","raw_frame":"{\"market\":\"0xda6f0e0e93fc8469e0159a166028d017bddbc162b86f66bac90391379603d962\", \"price_changes\":[{\"asset_id\":\"39272994714739463168905443499424551362424437245880253267329605556587274644733\", \"price\":\"0.03\", \"size\":\"653.1\", \"side\":\"BUY\", \"hash\":\"ddb5606b2384492f7d3c3dd27cc46137aacb6150\", \"best_bid\":\"0.6\", \"best_ask\":\"0.61\"}, {\"asset_id\":\"20893381255801015515826997628594359667013752732428989472914000440642900266717\", \"price\":\"0.97\", \"size\":\"653.1\", \"side\":\"SELL\", \"hash\":\"2d6b1b9163f9af05a835329c7aab914bccf8c2ae\", \"best_bid\":\"0.39\", \"best_ask\":\"0.4\"}], \"timestamp\":\"1785204398878\", \"event_type\":\"price_change\"}","received_at":"2026-07-28T02:06:39.800513Z","schema_version":"clob-market-ws.price_change.v1","sequence":null,"server_hash":null,"server_timestamp":"1785204398878","session_id":"d2757dd6dad94f3b9fe67e8dbf1adc37","source":"clob_market_ws"},"received_at":"2026-07-28T02:06:39.800513Z","record_id":"baf96e92ccaf323bea496dda06387451262604f42d70171318b217e4e83e6780","schema_fingerprint":"4aa3821a28b0b7c2400bc59aba4bcc0a76e971dadd19610d3ad38c768e124dc7","schema_version":"edge-lab-recorder.raw.v1","sequence":null,"source":"clob_market_ws"}
{"event_at":"2026-07-28T02:06:38.879000Z","event_fingerprint":"118f6e0c1674675be19229f8d683f3b5f3315f02858d38c1ae3bfaee1bb97dfa","payload":{"connection_id":"5d29200f65794d4d9ab6ef271f045a9b","event_at":"2026-07-28T02:06:38.879000Z","event_type":"price_change","frame_hash":"210d183fe0d094349ac2840f32bf51db32f01af92dbb4e67af5cd29b87443570","frame_index":0,"kind":"data","monotonic_ns":306382812022833,"payload":{"event_type":"price_change","market":"0xda6f0e0e93fc8469e0159a166028d017bddbc162b86f66bac90391379603d962","price_changes":[{"asset_id":"39272994714739463168905443499424551362424437245880253267329605556587274644733","best_ask":"0.61","best_bid":"0.6","hash":"62197dbc667822d1b01af91e95300d5bcbeb16cb","price":"0.01","side":"BUY","size":"5608.02"},{"asset_id":"20893381255801015515826997628594359667013752732428989472914000440642900266717","best_ask":"0.4","best_bid":"0.39","hash":"c912f2cefd25ddd73b68f978625730208670b7ee","price":"0.99","side":"SELL","size":"5608.02"}],"timestamp":"1785204398879"},"payload_hash":"4c2df05fb33b5aff5b3574ef628e47a055da00243efaee3b27325e1d67c3091b","raw_frame":"{\"market\":\"0xda6f0e0e93fc8469e0159a166028d017bddbc162b86f66bac90391379603d962\", \"price_changes\":[{\"asset_id\":\"39272994714739463168905443499424551362424437245880253267329605556587274644733\", \"price\":\"0.01\", \"size\":\"5608.02\", \"side\":\"BUY\", \"hash\":\"62197dbc667822d1b01af91e95300d5bcbeb16cb\", \"best_bid\":\"0.6\", \"best_ask\":\"0.61\"}, {\"asset_id\":\"20893381255801015515826997628594359667013752732428989472914000440642900266717\", \"price\":\"0.99\", \"size\":\"5608.02\", \"side\":\"SELL\", \"hash\":\"c912f2cefd25ddd73b68f978625730208670b7ee\", \"best_bid\":\"0.39\", \"best_ask\":\"0.4\"}], \"timestamp\":\"1785204398879\", \"event_type\":\"price_change\"}","received_at":"2026-07-28T02:06:39.805013Z","schema_version":"clob-market-ws.price_change.v1","sequence":null,"server_hash":null,"server_timestamp":"1785204398879","session_id":"d2757dd6dad94f3b9fe67e8dbf1adc37","source":"clob_market_ws"},"received_at":"2026-07-28T02:06:39.805013Z","record_id":"526a7dd1545db2b86e445964b04b1015062e401e4bfefbc2c95621d405843714","schema_fingerprint":"4aa3821a28b0b7c2400bc59aba4bcc0a76e971dadd19610d3ad38c768e124dc7","schema_version":"edge-lab-recorder.raw.v1","sequence":null,"source":"clob_market_ws"}
{"event_at":"2026-07-28T02:06:38.891000Z","event_fingerprint":"c3945d61a8fb670af98156f6fd7f442eb8471a48ea15644f5d25fc6c8f12ebb5","payload":{"connection_id":"5d29200f65794d4d9ab6ef271f045a9b","event_at":"2026-07-28T02:06:38.891000Z","event_type":"price_change","frame_hash":"c678c733f341be7edc9f64a6eff388ef3240fc43d7d95d447327d9947a1f7f91","frame_index":0,"kind":"data","monotonic_ns":306382816353750,"payload":{"event_type":"price_change","market":"0xda6f0e0e93fc8469e0159a166028d017bddbc162b86f66bac90391379603d962","price_changes":[{"asset_id":"39272994714739463168905443499424551362424437245880253267329605556587274644733","best_ask":"0.61","best_bid":"0.6","hash":"2a215dae372820cd99bebaca3d6eea85207d6ae1","price":"0.54","side":"BUY","size":"139"},{"asset_id":"20893381255801015515826997628594359667013752732428989472914000440642900266717","best_ask":"0.4","best_bid":"0.39","hash":"b7f7ae736fee00e12fa6d4c734da1aa27e3a2d00","price":"0.46","side":"SELL","size":"139"}],"timestamp":"1785204398891"},"payload_hash":"ab73cbc13e3734b71c88741ddc68047a83249261350577be58ba352222ad1c90","raw_frame":"{\"market\":\"0xda6f0e0e93fc8469e0159a166028d017bddbc162b86f66bac90391379603d962\", \"price_changes\":[{\"asset_id\":\"39272994714739463168905443499424551362424437245880253267329605556587274644733\", \"price\":\"0.54\", \"size\":\"139\", \"side\":\"BUY\", \"hash\":\"2a215dae372820cd99bebaca3d6eea85207d6ae1\", \"best_bid\":\"0.6\", \"best_ask\":\"0.61\"}, {\"asset_id\":\"20893381255801015515826997628594359667013752732428989472914000440642900266717\", \"price\":\"0.46\", \"size\":\"139\", \"side\":\"SELL\", \"hash\":\"b7f7ae736fee00e12fa6d4c734da1aa27e3a2d00\", \"best_bid\":\"0.39\", \"best_ask\":\"0.4\"}], \"timestamp\":\"1785204398891\", \"event_type\":\"price_change\"}","received_at":"2026-07-28T02:06:39.809344Z","schema_version":"clob-market-ws.price_change.v1","sequence":null,"server_hash":null,"server_timestamp":"1785204398891","session_id":"d2757dd6dad94f3b9fe67e8dbf1adc37","source":"clob_market_ws"},"received_at":"2026-07-28T02:06:39.809344Z","record_id":"fd1e140f48a90e7eac11da38f44ef74e8724f5231cdc10a328c799b99a4a95dd","schema_fingerprint":"4aa3821a28b0b7c2400bc59aba4bcc0a76e971dadd19610d3ad38c768e124dc7","schema_version":"edge-lab-recorder.raw.v1","sequence":null,"source":"clob_market_ws"}
{"event_at":"2026-07-28T02:06:38.892000Z","event_fingerprint":"c8815a49a9e3ae6a0246d507a3362d12158f2c65e02627c937d0811756ed6228","payload":{"connection_id":"5d29200f65794d4d9ab6ef271f045a9b","event_at":"2026-07-28T02:06:38.892000Z","event_type":"price_change","frame_hash":"4421c6c1bc1da3a76eb98cc1116fb069d7fc6ce03fadc6ffaf0f51fed36720a2","frame_index":0,"kind":"data","monotonic_ns":306382820665375,"payload":{"event_type":"price_change","market":"0xda6f0e0e93fc8469e0159a166028d017bddbc162b86f66bac90391379603d962","price_changes":[{"asset_id":"39272994714739463168905443499424551362424437245880253267329605556587274644733","best_ask":"0.61","best_bid":"0.6","hash":"feb928690ae47f7a9b5ba0e826d7524784ebfe7b","price":"0.54","side":"BUY","size":"109"},{"asset_id":"20893381255801015515826997628594359667013752732428989472914000440642900266717","best_ask":"0.4","best_bid":"0.39","hash":"7a06e60ab91fa19a2eb94cb6f9b3bb2d4ba17586","price":"0.46","side":"SELL","size":"109"}],"timestamp":"1785204398892"},"payload_hash":"fdaae21fdf1004d6becc35da38a9a33586967e76622e402da84723ad8e7972da","raw_frame":"{\"market\":\"0xda6f0e0e93fc8469e0159a166028d017bddbc162b86f66bac90391379603d962\", \"price_changes\":[{\"asset_id\":\"39272994714739463168905443499424551362424437245880253267329605556587274644733\", \"price\":\"0.54\", \"size\":\"109\", \"side\":\"BUY\", \"hash\":\"feb928690ae47f7a9b5ba0e826d7524784ebfe7b\", \"best_bid\":\"0.6\", \"best_ask\":\"0.61\"}, {\"asset_id\":\"20893381255801015515826997628594359667013752732428989472914000440642900266717\", \"price\":\"0.46\", \"size\":\"109\", \"side\":\"SELL\", \"hash\":\"7a06e60ab91fa19a2eb94cb6f9b3bb2d4ba17586\", \"best_bid\":\"0.39\", \"best_ask\":\"0.4\"}], \"timestamp\":\"1785204398892\", \"event_type\":\"price_change\"}","received_at":"2026-07-28T02:06:39.813656Z","schema_version":"clob-market-ws.price_change.v1","sequence":null,"server_hash":null,"server_timestamp":"1785204398892","session_id":"d2757dd6dad94f3b9fe67e8dbf1adc37","source":"clob_market_ws"},"received_at":"2026-07-28T02:06:39.813656Z","record_id":"06376da1520d49d911e6f1dd29db8bf5a545c4088029c7f18527e0a1245e654e","schema_fingerprint":"4aa3821a28b0b7c2400bc59aba4bcc0a76e971dadd19610d3ad38c768e124dc7","schema_version":"edge-lab-recorder.raw.v1","sequence":null,"source":"clob_market_ws"}
{"event_at":"2026-07-28T02:06:38.893000Z","event_fingerprint":"9d639710d9e504f323687fbeec4111c146a6aefd75f37ddd20244f8085830c8b","payload":{"connection_id":"5d29200f65794d4d9ab6ef271f045a9b","event_at":"2026-07-28T02:06:38.893000Z","event_type":"price_change","frame_hash":"ad3dada51b398dfb8bd6e0b7d579694eb56c01e7d6fee5fa0b0fe80618af6d7a","frame_index":0,"kind":"data","monotonic_ns":306382824986750,"payload":{"event_type":"price_change","market":"0xda6f0e0e93fc8469e0159a166028d017bddbc162b86f66bac90391379603d962","price_changes":[{"asset_id":"39272994714739463168905443499424551362424437245880253267329605556587274644733","best_ask":"0.61","best_bid":"0.6","hash":"c09e0c48ffb77bd353a7997719501b4bdd3b7465","price":"0.54","side":"BUY","size":"79"},{"asset_id":"20893381255801015515826997628594359667013752732428989472914000440642900266717","best_ask":"0.4","best_bid":"0.39","hash":"08b5b51299fa9539f0c4583d45c8702e6ffecf10","price":"0.46","side":"SELL","size":"79"}],"timestamp":"1785204398893"},"payload_hash":"4a6af4c0df5430c877cf1802a33aeecc50f5d79410bcef8d242aa41fb9a6c4ea","raw_frame":"{\"market\":\"0xda6f0e0e93fc8469e0159a166028d017bddbc162b86f66bac90391379603d962\", \"price_changes\":[{\"asset_id\":\"39272994714739463168905443499424551362424437245880253267329605556587274644733\", \"price\":\"0.54\", \"size\":\"79\", \"side\":\"BUY\", \"hash\":\"c09e0c48ffb77bd353a7997719501b4bdd3b7465\", \"best_bid\":\"0.6\", \"best_ask\":\"0.61\"}, {\"asset_id\":\"20893381255801015515826997628594359667013752732428989472914000440642900266717\", \"price\":\"0.46\", \"size\":\"79\", \"side\":\"SELL\", \"hash\":\"08b5b51299fa9539f0c4583d45c8702e6ffecf10\", \"best_bid\":\"0.39\", \"best_ask\":\"0.4\"}], \"timestamp\":\"1785204398893\", \"event_type\":\"price_change\"}","received_at":"2026-07-28T02:06:39.817977Z","schema_version":"clob-market-ws.price_change.v1","sequence":null,"server_hash":null,"server_timestamp":"1785204398893","session_id":"d2757dd6dad94f3b9fe67e8dbf1adc37","source":"clob_market_ws"},"received_at":"2026-07-28T02:06:39.817977Z","record_id":"aceb1fc8b72bff5d2d3e3e0b4a9f240dc4b3d4e8b2499e88b3593dd2dafa8cfa","schema_fingerprint":"4aa3821a28b0b7c2400bc59aba4bcc0a76e971dadd19610d3ad38c768e124dc7","schema_version":"edge-lab-recorder.raw.v1","sequence":null,"source":"clob_market_ws"}
{"event_at":"2026-07-28T02:06:38.902000Z","event_fingerprint":"1b3419700fae00af32bda013c2d56401e60350c92a2091852fd5a6ba294fccb4","payload":{"connection_id":"5d29200f65794d4d9ab6ef271f045a9b","event_at":"2026-07-28T02:06:38.902000Z","event_type":"price_change","frame_hash":"68affa6d7b6df7402a1dac1eab95d3ebee76bdea100f0bc332548cd7fc8e1ce8","frame_index":0,"kind":"data","monotonic_ns":306382827935208,"payload":{"event_type":"price_change","market":"0xda6f0e0e93fc8469e0159a166028d017bddbc162b86f66bac90391379603d962","price_changes":[{"asset_id":"39272994714739463168905443499424551362424437245880253267329605556587274644733","best_ask":"0.61","best_bid":"0.6","hash":"25cfe5b5cf04efd29b8bf59bc9983dd46c73e3ad","price":"0.61","side":"SELL","size":"44"},{"asset_id":"20893381255801015515826997628594359667013752732428989472914000440642900266717","best_ask":"0.4","best_bid":"0.39","hash":"9d298340d5bde999163c82e51ff6319d22eaa4c8","price":"0.39","side":"BUY","size":"44"}],"timestamp":"1785204398902"},"payload_hash":"f37ee0b2e62e6005eef5e656100083bf94d82f51fcfe31299752acf56da64a5e","raw_frame":"{\"market\":\"0xda6f0e0e93fc8469e0159a166028d017bddbc162b86f66bac90391379603d962\", \"price_changes\":[{\"asset_id\":\"39272994714739463168905443499424551362424437245880253267329605556587274644733\", \"price\":\"0.61\", \"size\":\"44\", \"side\":\"SELL\", \"hash\":\"25cfe5b5cf04efd29b8bf59bc9983dd46c73e3ad\", \"best_bid\":\"0.6\", \"best_ask\":\"0.61\"}, {\"asset_id\":\"20893381255801015515826997628594359667013752732428989472914000440642900266717\", \"price\":\"0.39\", \"size\":\"44\", \"side\":\"BUY\", \"hash\":\"9d298340d5bde999163c82e51ff6319d22eaa4c8\", \"best_bid\":\"0.39\", \"best_ask\":\"0.4\"}], \"timestamp\":\"1785204398902\", \"event_type\":\"price_change\"}","received_at":"2026-07-28T02:06:39.820925Z","schema_version":"clob-market-ws.price_change.v1","sequence":null,"server_hash":null,"server_timestamp":"1785204398902","session_id":"d2757dd6dad94f3b9fe67e8dbf1adc37","source":"clob_market_ws"},"received_at":"2026-07-28T02:06:39.820925Z","record_id":"0170bae011c63400238f73a5e333c7c16d78af4206b6e8f20a7fcc849607e4b7","schema_fingerprint":"4aa3821a28b0b7c2400bc59aba4bcc0a76e971dadd19610d3ad38c768e124dc7","schema_version":"edge-lab-recorder.raw.v1","sequence":null,"source":"clob_market_ws"}
{"event_at":"2026-07-28T02:06:38.912000Z","event_fingerprint":"d9b3e843e4c9ac83a8a63c13be5174813fd9cd078a4a3dd054691cb2606af45f","payload":{"connection_id":"5d29200f65794d4d9ab6ef271f045a9b","event_at":"2026-07-28T02:06:38.912000Z","event_type":"price_change","frame_hash":"a932b4b01b69514571a0aa576e8259c603a6117ee8cb02e39be9640fade13604","frame_index":0,"kind":"data","monotonic_ns":306382832280708,"payload":{"event_type":"price_change","market":"0xda6f0e0e93fc8469e0159a166028d017bddbc162b86f66bac90391379603d962","price_changes":[{"asset_id":"39272994714739463168905443499424551362424437245880253267329605556587274644733","best_ask":"0.61","best_bid":"0.6","hash":"bba450f7765749e97bf1f0267639ecd74ffcec8f","price":"0.01","side":"BUY","size":"5613.02"},{"asset_id":"20893381255801015515826997628594359667013752732428989472914000440642900266717","best_ask":"0.4","best_bid":"0.39","hash":"d863015d2936a1774335659c2740a22bc6c9a432","price":"0.99","side":"SELL","size":"5613.02"}],"timestamp":"1785204398912"},"payload_hash":"b6f211ce6d574d6331d8dcc4ba6bf3f0aca790c07b8570cafa5c7c389f414cb7","raw_frame":"{\"market\":\"0xda6f0e0e93fc8469e0159a166028d017bddbc162b86f66bac90391379603d962\", \"price_changes\":[{\"asset_id\":\"39272994714739463168905443499424551362424437245880253267329605556587274644733\", \"price\":\"0.01\", \"size\":\"5613.02\", \"side\":\"BUY\", \"hash\":\"bba450f7765749e97bf1f0267639ecd74ffcec8f\", \"best_bid\":\"0.6\", \"best_ask\":\"0.61\"}, {\"asset_id\":\"20893381255801015515826997628594359667013752732428989472914000440642900266717\", \"price\":\"0.99\", \"size\":\"5613.02\", \"side\":\"SELL\", \"hash\":\"d863015d2936a1774335659c2740a22bc6c9a432\", \"best_bid\":\"0.39\", \"best_ask\":\"0.4\"}], \"timestamp\":\"1785204398912\", \"event_type\":\"price_change\"}","received_at":"2026-07-28T02:06:39.825271Z","schema_version":"clob-market-ws.price_change.v1","sequence":null,"server_hash":null,"server_timestamp":"1785204398912","session_id":"d2757dd6dad94f3b9fe67e8dbf1adc37","source":"clob_market_ws"},"received_at":"2026-07-28T02:06:39.825271Z","record_id":"05c4ed32cafc79e7bc7b3ce019b9d9911c039cdb9b37b544b34aae7e3d7b6354","schema_fingerprint":"4aa3821a28b0b7c2400bc59aba4bcc0a76e971dadd19610d3ad38c768e124dc7","schema_version":"edge-lab-recorder.raw.v1","sequence":null,"source":"clob_market_ws"}
{"event_at":"2026-07-28T02:06:38.917000Z","event_fingerprint":"a69d42e3c37c1c5d60235f53aa7895fa51dfd42fa2e1b6f1b4564578f5f31fdd","payload":{"connection_id":"5d29200f65794d4d9ab6ef271f045a9b","event_at":"2026-07-28T02:06:38.917000Z","event_type":"price_change","frame_hash":"a7a82d0f9eedda1339a563be4e6b7ca0e32d798839fa12709c3914a4e8e89c42","frame_index":0,"kind":"data","monotonic_ns":306382835126666,"payload":{"event_type":"price_change","market":"0xda6f0e0e93fc8469e0159a166028d017bddbc162b86f66bac90391379603d962","price_changes":[{"asset_id":"20893381255801015515826997628594359667013752732428989472914000440642900266717","best_ask":"0.4","best_bid":"0.39","hash":"5b0a6320ba9ee862524e8bb32cbbc6b9064379e1","price":"0.29","side":"BUY","size":"244.6"},{"asset_id":"39272994714739463168905443499424551362424437245880253267329605556587274644733","best_ask":"0.61","best_bid":"0.6","hash":"700eae24cc15e63887aa0ef5d5c84d7ec25255f9","price":"0.71","side":"SELL","size":"244.6"}],"timestamp":"1785204398917"},"payload_hash":"ddd333cd06c670e4d7cacd38bb54ded51123fe6b4fec23a18e3646db64a16ecf","raw_frame":"{\"market\":\"0xda6f0e0e93fc8469e0159a166028d017bddbc162b86f66bac90391379603d962\", \"price_changes\":[{\"asset_id\":\"20893381255801015515826997628594359667013752732428989472914000440642900266717\", \"price\":\"0.29\", \"size\":\"244.6\", \"side\":\"BUY\", \"hash\":\"5b0a6320ba9ee862524e8bb32cbbc6b9064379e1\", \"best_bid\":\"0.39\", \"best_ask\":\"0.4\"}, {\"asset_id\":\"39272994714739463168905443499424551362424437245880253267329605556587274644733\", \"price\":\"0.71\", \"size\":\"244.6\", \"side\":\"SELL\", \"hash\":\"700eae24cc15e63887aa0ef5d5c84d7ec25255f9\", \"best_bid\":\"0.6\", \"best_ask\":\"0.61\"}], \"timestamp\":\"1785204398917\", \"event_type\":\"price_change\"}","received_at":"2026-07-28T02:06:39.828117Z","schema_version":"clob-market-ws.price_change.v1","sequence":null,"server_hash":null,"server_timestamp":"1785204398917","session_id":"d2757dd6dad94f3b9fe67e8dbf1adc37","source":"clob_market_ws"},"received_at":"2026-07-28T02:06:39.828117Z","record_id":"bc63222fc663ca0d84cbecee2112ff700c4bc52dd48557ff881c35a74185e35d","schema_fingerprint":"4aa3821a28b0b7c2400bc59aba4bcc0a76e971dadd19610d3ad38c768e124dc7","schema_version":"edge-lab-recorder.raw.v1","sequence":null,"source":"clob_market_ws"}
{"event_at":"2026-07-28T02:06:38.930000Z","event_fingerprint":"449b84e341c299057ff356d6420565cb95d2f5b4290b70606722694422277e16","payload":{"connection_id":"5d29200f65794d4d9ab6ef271f045a9b","event_at":"2026-07-28T02:06:38.930000Z","event_type":"price_change","frame_hash":"7f4223e92c0b8e64ca8b2d613c4a4188610d450d0c8a9deb70fb82bcfe50909d","frame_index":0,"kind":"data","monotonic_ns":306382840199125,"payload":{"event_type":"price_change","market":"0xda6f0e0e93fc8469e0159a166028d017bddbc162b86f66bac90391379603d962","price_changes":[{"asset_id":"39272994714739463168905443499424551362424437245880253267329605556587274644733","best_ask":"0.61","best_bid":"0.6","hash":"e81c3b016cf60015935ba23724557de82b42ef84","price":"0.03","side":"BUY","size":"648.1"},{"asset_id":"20893381255801015515826997628594359667013752732428989472914000440642900266717","best_ask":"0.4","best_bid":"0.39","hash":"b63f3a03ec6edf2eb6cb69b045cd475bcd46bde8","price":"0.97","side":"SELL","size":"648.1"}],"timestamp":"1785204398930"},"payload_hash":"76b4795e9011d15cb320715bad83a0e7d5c3dcac0bca0dac1a61dcda559923e5","raw_frame":"{\"market\":\"0xda6f0e0e93fc8469e0159a166028d017bddbc162b86f66bac90391379603d962\", \"price_changes\":[{\"asset_id\":\"39272994714739463168905443499424551362424437245880253267329605556587274644733\", \"price\":\"0.03\", \"size\":\"648.1\", \"side\":\"BUY\", \"hash\":\"e81c3b016cf60015935ba23724557de82b42ef84\", \"best_bid\":\"0.6\", \"best_ask\":\"0.61\"}, {\"asset_id\":\"20893381255801015515826997628594359667013752732428989472914000440642900266717\", \"price\":\"0.97\", \"size\":\"648.1\", \"side\":\"SELL\", \"hash\":\"b63f3a03ec6edf2eb6cb69b045cd475bcd46bde8\", \"best_bid\":\"0.39\", \"best_ask\":\"0.4\"}], \"timestamp\":\"1785204398930\", \"event_type\":\"price_change\"}","received_at":"2026-07-28T02:06:39.833189Z","schema_version":"clob-market-ws.price_change.v1","sequence":null,"server_hash":null,"server_timestamp":"1785204398930","session_id":"d2757dd6dad94f3b9fe67e8dbf1adc37","source":"clob_market_ws"},"received_at":"2026-07-28T02:06:39.833189Z","record_id":"e56257945ef8a518d3d8a8892d1f96488a3ef823283da9847c4137f1ecfe864f","schema_fingerprint":"4aa3821a28b0b7c2400bc59aba4bcc0a76e971dadd19610d3ad38c768e124dc7","schema_version":"edge-lab-recorder.raw.v1","sequence":null,"source":"clob_market_ws"}
{"event_at":"2026-07-28T02:06:38.930000Z","event_fingerprint":"9430e144ab923cf648bea58df7377bc9db3ed5d6c76e45f19c7ed722131e96cb","payload":{"connection_id":"5d29200f65794d4d9ab6ef271f045a9b","event_at":"2026-07-28T02:06:38.930000Z","event_type":"price_change","frame_hash":"c2c501c4df7ea99016c90bbe63df43ca0c67889e631cc7c84205c45b502bd519","frame_index":0,"kind":"data","monotonic_ns":306382844494583,"payload":{"event_type":"price_change","market":"0xda6f0e0e93fc8469e0159a166028d017bddbc162b86f66bac90391379603d962","price_changes":[{"asset_id":"39272994714739463168905443499424551362424437245880253267329605556587274644733","best_ask":"0.61","best_bid":"0.6","hash":"eb9503a45c6ecc27568b659f997b116fdf7d8509","price":"0.01","side":"BUY","size":"5608.02"},{"asset_id":"20893381255801015515826997628594359667013752732428989472914000440642900266717","best_ask":"0.4","best_bid":"0.39","hash":"7221bece49e88328cf11524571ec541da58630b5","price":"0.99","side":"SELL","size":"5608.02"}],"timestamp":"1785204398930"},"payload_hash":"58ef965f94d0c045f3b8a64c5f00d6e33519e86acc4e7ab4cc197559be9ecae2","raw_frame":"{\"market\":\"0xda6f0e0e93fc8469e0159a166028d017bddbc162b86f66bac90391379603d962\", \"price_changes\":[{\"asset_id\":\"39272994714739463168905443499424551362424437245880253267329605556587274644733\", \"price\":\"0.01\", \"size\":\"5608.02\", \"side\":\"BUY\", \"hash\":\"eb9503a45c6ecc27568b659f997b116fdf7d8509\", \"best_bid\":\"0.6\", \"best_ask\":\"0.61\"}, {\"asset_id\":\"20893381255801015515826997628594359667013752732428989472914000440642900266717\", \"price\":\"0.99\", \"size\":\"5608.02\", \"side\":\"SELL\", \"hash\":\"7221bece49e88328cf11524571ec541da58630b5\", \"best_bid\":\"0.39\", \"best_ask\":\"0.4\"}], \"timestamp\":\"1785204398930\", \"event_type\":\"price_change\"}","received_at":"2026-07-28T02:06:39.837485Z","schema_version":"clob-market-ws.price_change.v1","sequence":null,"server_hash":null,"server_timestamp":"1785204398930","session_id":"d2757dd6dad94f3b9fe67e8dbf1adc37","source":"clob_market_ws"},"received_at":"2026-07-28T02:06:39.837485Z","record_id":"9da732030a03e2d551fda024f8379c44297256242012b6a23da2287a5c56e196","schema_fingerprint":"4aa3821a28b0b7c2400bc59aba4bcc0a76e971dadd19610d3ad38c768e124dc7","schema_version":"edge-lab-recorder.raw.v1","sequence":null,"source":"clob_market_ws"}
{"event_at":"2026-07-28T02:06:38.967000Z","event_fingerprint":"9466e85d4cf3933054675952e315ce8fb284ed78c464d12ced9019894e91de36","payload":{"connection_id":"5d29200f65794d4d9ab6ef271f045a9b","event_at":"2026-07-28T02:06:38.967000Z","event_type":"price_change","frame_hash":"a8fac55244f67c2a9a52027b4d75838253b563cff7ad955cd256124af26cb100","frame_index":0,"kind":"data","monotonic_ns":306382848888625,"payload":{"event_type":"price_change","market":"0xda6f0e0e93fc8469e0159a166028d017bddbc162b86f66bac90391379603d962","price_changes":[{"asset_id":"20893381255801015515826997628594359667013752732428989472914000440642900266717","best_ask":"0.4","best_bid":"0.39","hash":"18174e3b94db1189b5330af53a39b99b7a94b7b6","price":"0.35","side":"BUY","size":"90.2"},{"asset_id":"39272994714739463168905443499424551362424437245880253267329605556587274644733","best_ask":"0.61","best_bid":"0.6","hash":"c33e3e84b27417d6959793eed72d515dd75c78ef","price":"0.65","side":"SELL","size":"90.2"}],"timestamp":"1785204398967"},"payload_hash":"e2ce84efbe1d69bab62659e1e256b2064c0c219080b2c3720c9bb87bf9b2fcc4","raw_frame":"{\"market\":\"0xda6f0e0e93fc8469e0159a166028d017bddbc162b86f66bac90391379603d962\", \"price_changes\":[{\"asset_id\":\"20893381255801015515826997628594359667013752732428989472914000440642900266717\", \"price\":\"0.35\", \"size\":\"90.2\", \"side\":\"BUY\", \"hash\":\"18174e3b94db1189b5330af53a39b99b7a94b7b6\", \"best_bid\":\"0.39\", \"best_ask\":\"0.4\"}, {\"asset_id\":\"39272994714739463168905443499424551362424437245880253267329605556587274644733\", \"price\":\"0.65\", \"size\":\"90.2\", \"side\":\"SELL\", \"hash\":\"c33e3e84b27417d6959793eed72d515dd75c78ef\", \"best_bid\":\"0.6\", \"best_ask\":\"0.61\"}], \"timestamp\":\"1785204398967\", \"event_type\":\"price_change\"}","received_at":"2026-07-28T02:06:39.841880Z","schema_version":"clob-market-ws.price_change.v1","sequence":null,"server_hash":null,"server_timestamp":"1785204398967","session_id":"d2757dd6dad94f3b9fe67e8dbf1adc37","source":"clob_market_ws"},"received_at":"2026-07-28T02:06:39.841880Z","record_id":"ed6ddcb137a82013e88b7744d755ba0a14a1d14e4b5fe37b80f0670855269e52","schema_fingerprint":"4aa3821a28b0b7c2400bc59aba4bcc0a76e971dadd19610d3ad38c768e124dc7","schema_version":"edge-lab-recorder.raw.v1","sequence":null,"source":"clob_market_ws"}
{"event_at":"2026-07-28T02:06:38.984000Z","event_fingerprint":"3de3159506d82b720f83dd638c10e5896989db6549b56cb4a1b5023f9c04f89e","payload":{"connection_id":"5d29200f65794d4d9ab6ef271f045a9b","event_at":"2026-07-28T02:06:38.984000Z","event_type":"price_change","frame_hash":"c099ad8fae53a00f8e795fca59af72df7920a8de4e085efc59371e37c9bf3e86","frame_index":0,"kind":"data","monotonic_ns":306382853247125,"payload":{"event_type":"price_change","market":"0xda6f0e0e93fc8469e0159a166028d017bddbc162b86f66bac90391379603d962","price_changes":[{"asset_id":"20893381255801015515826997628594359667013752732428989472914000440642900266717","best_ask":"0.4","best_bid":"0.39","hash":"4be636ca1e80a77f76b9bde2ffd2c5cd866f0b73","price":"0.29","side":"BUY","size":"250.6"},{"asset_id":"39272994714739463168905443499424551362424437245880253267329605556587274644733","best_ask":"0.61","best_bid":"0.6","hash":"a5bcff36e1c606fe18964a2df99a1845209b88ff","price":"0.71","side":"SELL","size":"250.6"}],"timestamp":"1785204398984"},"payload_hash":"28d9e156b613430d539263ab48fa2fc2bd58a2cbca6977cbdbba0466df7ee048","raw_frame":"{\"market\":\"0xda6f0e0e93fc8469e0159a166028d017bddbc162b86f66bac90391379603d962\", \"price_changes\":[{\"asset_id\":\"20893381255801015515826997628594359667013752732428989472914000440642900266717\", \"price\":\"0.29\", \"size\":\"250.6\", \"side\":\"BUY\", \"hash\":\"4be636ca1e80a77f76b9bde2ffd2c5cd866f0b73\", \"best_bid\":\"0.39\", \"best_ask\":\"0.4\"}, {\"asset_id\":\"39272994714739463168905443499424551362424437245880253267329605556587274644733\", \"price\":\"0.71\", \"size\":\"250.6\", \"side\":\"SELL\", \"hash\":\"a5bcff36e1c606fe18964a2df99a1845209b88ff\", \"best_bid\":\"0.6\", \"best_ask\":\"0.61\"}], \"timestamp\":\"1785204398984\", \"event_type\":\"price_change\"}","received_at":"2026-07-28T02:06:39.846238Z","schema_version":"clob-market-ws.price_change.v1","sequence":null,"server_hash":null,"server_timestamp":"1785204398984","session_id":"d2757dd6dad94f3b9fe67e8dbf1adc37","source":"clob_market_ws"},"received_at":"2026-07-28T02:06:39.846238Z","record_id":"a06cc3e559e6cabee5a3b3ab0ec7891714109b4ff95f28f9eb83ffbac9fd4421","schema_fingerprint":"4aa3821a28b0b7c2400bc59aba4bcc0a76e971dadd19610d3ad38c768e124dc7","schema_version":"edge-lab-recorder.raw.v1","sequence":null,"source":"clob_market_ws"}
{"event_at":"2026-07-28T02:06:39.009000Z","event_fingerprint":"782bc62ec006294caecb72ab2e7e515b34aa030028d0395a671aa714711385a2","payload":{"connection_id":"5d29200f65794d4d9ab6ef271f045a9b","event_at":"2026-07-28T02:06:39.009000Z","event_type":"price_change","frame_hash":"249757ef9e79ca706e1f539002d65374e017d43153283dda802aa2959524968f","frame_index":0,"kind":"data","monotonic_ns":306382857323708,"payload":{"event_type":"price_change","market":"0xda6f0e0e93fc8469e0159a166028d017bddbc162b86f66bac90391379603d962","price_changes":[{"asset_id":"39272994714739463168905443499424551362424437245880253267329605556587274644733","best_ask":"0.61","best_bid":"0.6","hash":"1cadd82cd881e13c00e05ace4c47f9756a0eccd6","price":"0.54","side":"BUY","size":"109"},{"asset_id":"20893381255801015515826997628594359667013752732428989472914000440642900266717","best_ask":"0.4","best_bid":"0.39","hash":"b86e998e92db356aea9180351f94929eddbccfcb","price":"0.46","side":"SELL","size":"109"}],"timestamp":"1785204399009"},"payload_hash":"f10e20a29b8b9905f294afbeee265892b16711e59e0c98cebec4eddced64d4dd","raw_frame":"{\"market\":\"0xda6f0e0e93fc8469e0159a166028d017bddbc162b86f66bac90391379603d962\", \"price_changes\":[{\"asset_id\":\"39272994714739463168905443499424551362424437245880253267329605556587274644733\", \"price\":\"0.54\", \"size\":\"109\", \"side\":\"BUY\", \"hash\":\"1cadd82cd881e13c00e05ace4c47f9756a0eccd6\", \"best_bid\":\"0.6\", \"best_ask\":\"0.61\"}, {\"asset_id\":\"20893381255801015515826997628594359667013752732428989472914000440642900266717\", \"price\":\"0.46\", \"size\":\"109\", \"side\":\"SELL\", \"hash\":\"b86e998e92db356aea9180351f94929eddbccfcb\", \"best_bid\":\"0.39\", \"best_ask\":\"0.4\"}], \"timestamp\":\"1785204399009\", \"event_type\":\"price_change\"}","received_at":"2026-07-28T02:06:39.850312Z","schema_version":"clob-market-ws.price_change.v1","sequence":null,"server_hash":null,"server_timestamp":"1785204399009","session_id":"d2757dd6dad94f3b9fe67e8dbf1adc37","source":"clob_market_ws"},"received_at":"2026-07-28T02:06:39.850312Z","record_id":"e0d02e848a8071e10e76e61d3043074fe94678b8c6d2018d6ab81ed6e233b027","schema_fingerprint":"4aa3821a28b0b7c2400bc59aba4bcc0a76e971dadd19610d3ad38c768e124dc7","schema_version":"edge-lab-recorder.raw.v1","sequence":null,"source":"clob_market_ws"}
{"event_at":"2026-07-28T02:06:39.010000Z","event_fingerprint":"b96c3532fd02e7e9cbaf18aca5f15d5296a2e0fe485c84341cf5a604ad9cde2f","payload":{"connection_id":"5d29200f65794d4d9ab6ef271f045a9b","event_at":"2026-07-28T02:06:39.010000Z","event_type":"price_change","frame_hash":"fedb5f8ad52e5900bdcc8b2aab96a8ce1286379c299a36a86c9602a8afc10c0d","frame_index":0,"kind":"data","monotonic_ns":306382861421166,"payload":{"event_type":"price_change","market":"0xda6f0e0e93fc8469e0159a166028d017bddbc162b86f66bac90391379603d962","price_changes":[{"asset_id":"39272994714739463168905443499424551362424437245880253267329605556587274644733","best_ask":"0.61","best_bid":"0.6","hash":"f413ca5d8ce6a5deca66a2ceaacae7ddd44fdeaf","price":"0.53","side":"BUY","size":"110"},{"asset_id":"20893381255801015515826997628594359667013752732428989472914000440642900266717","best_ask":"0.4","best_bid":"0.39","hash":"e88552291f56988f4470a6c9c6fc82ba957775b1","price":"0.47","side":"SELL","size":"110"}],"timestamp":"1785204399010"},"payload_hash":"bf6430ac0b19e5e2aa69f25efdefe07a47ee9a13cf234c67f679f8e46c8f4a58","raw_frame":"{\"market\":\"0xda6f0e0e93fc8469e0159a166028d017bddbc162b86f66bac90391379603d962\", \"price_changes\":[{\"asset_id\":\"39272994714739463168905443499424551362424437245880253267329605556587274644733\", \"price\":\"0.53\", \"size\":\"110\", \"side\":\"BUY\", \"hash\":\"f413ca5d8ce6a5deca66a2ceaacae7ddd44fdeaf\", \"best_bid\":\"0.6\", \"best_ask\":\"0.61\"}, {\"asset_id\":\"20893381255801015515826997628594359667013752732428989472914000440642900266717\", \"price\":\"0.47\", \"size\":\"110\", \"side\":\"SELL\", \"hash\":\"e88552291f56988f4470a6c9c6fc82ba957775b1\", \"best_bid\":\"0.39\", \"best_ask\":\"0.4\"}], \"timestamp\":\"1785204399010\", \"event_type\":\"price_change\"}","received_at":"2026-07-28T02:06:39.854411Z","schema_version":"clob-market-ws.price_change.v1","sequence":null,"server_hash":null,"server_timestamp":"1785204399010","session_id":"d2757dd6dad94f3b9fe67e8dbf1adc37","source":"clob_market_ws"},"received_at":"2026-07-28T02:06:39.854411Z","record_id":"78192d0c689a963a5755a5d7419d31430169955708e716bec51bf92ad593f841","schema_fingerprint":"4aa3821a28b0b7c2400bc59aba4bcc0a76e971dadd19610d3ad38c768e124dc7","schema_version":"edge-lab-recorder.raw.v1","sequence":null,"source":"clob_market_ws"}
{"event_at":"2026-07-28T02:06:39.014000Z","event_fingerprint":"2b94f47e3772a62e46c5fd95a20e27c0efcbb5faad5b424346a29dc1ea4986da","payload":{"connection_id":"5d29200f65794d4d9ab6ef271f045a9b","event_at":"2026-07-28T02:06:39.014000Z","event_type":"price_change","frame_hash":"bcb99cdf2f0341b2e93c7edd74d187c72c736c0bfa3643b2eb25c36320b7448e","frame_index":0,"kind":"data","monotonic_ns":306382865397541,"payload":{"event_type":"price_change","market":"0xda6f0e0e93fc8469e0159a166028d017bddbc162b86f66bac90391379603d962","price_changes":[{"asset_id":"39272994714739463168905443499424551362424437245880253267329605556587274644733","best_ask":"0.61","best_bid":"0.6","hash":"5959ba4bd9a122401873503b606fb1bc453925da","price":"0.03","side":"BUY","size":"653.1"},{"asset_id":"20893381255801015515826997628594359667013752732428989472914000440642900266717","best_ask":"0.4","best_bid":"0.39","hash":"e1d53789eab38fad5d70bd2b84e142c11b325adb","price":"0.97","side":"SELL","size":"653.1"}],"timestamp":"1785204399014"},"payload_hash":"04b8cf9b75c675391e3eafd43e6232058ef6f52f46e85f121fa942148c71081b","raw_frame":"{\"market\":\"0xda6f0e0e93fc8469e0159a166028d017bddbc162b86f66bac90391379603d962\", \"price_changes\":[{\"asset_id\":\"39272994714739463168905443499424551362424437245880253267329605556587274644733\", \"price\":\"0.03\", \"size\":\"653.1\", \"side\":\"BUY\", \"hash\":\"5959ba4bd9a122401873503b606fb1bc453925da\", \"best_bid\":\"0.6\", \"best_ask\":\"0.61\"}, {\"asset_id\":\"20893381255801015515826997628594359667013752732428989472914000440642900266717\", \"price\":\"0.97\", \"size\":\"653.1\", \"side\":\"SELL\", \"hash\":\"e1d53789eab38fad5d70bd2b84e142c11b325adb\", \"best_bid\":\"0.39\", \"best_ask\":\"0.4\"}], \"timestamp\":\"1785204399014\", \"event_type\":\"price_change\"}","received_at":"2026-07-28T02:06:39.858387Z","schema_version":"clob-market-ws.price_change.v1","sequence":null,"server_hash":null,"server_timestamp":"1785204399014","session_id":"d2757dd6dad94f3b9fe67e8dbf1adc37","source":"clob_market_ws"},"received_at":"2026-07-28T02:06:39.858387Z","record_id":"e1889b6bbf1daa35c659d0a0fba26f0e13668014001641abfe1f821a73b59ecc","schema_fingerprint":"4aa3821a28b0b7c2400bc59aba4bcc0a76e971dadd19610d3ad38c768e124dc7","schema_version":"edge-lab-recorder.raw.v1","sequence":null,"source":"clob_market_ws"}
{"event_at":"2026-07-28T02:06:39.018000Z","event_fingerprint":"b56fa725681d634efd3bfb75729e140fb4899286327f6ec4fb21476c35bbf0c0","payload":{"connection_id":"5d29200f65794d4d9ab6ef271f045a9b","event_at":"2026-07-28T02:06:39.018000Z","event_type":"price_change","frame_hash":"a878bf2d3068821451f30fc0b59f45f2c1b8624c98bc33729393d1ed26fe72fa","frame_index":0,"kind":"data","monotonic_ns":306382870100041,"payload":{"event_type":"price_change","market":"0xda6f0e0e93fc8469e0159a166028d017bddbc162b86f66bac90391379603d962","price_changes":[{"asset_id":"39272994714739463168905443499424551362424437245880253267329605556587274644733","best_ask":"0.61","best_bid":"0.6","hash":"4c7bfadefe64b9f82ee9fe8b002761523bafbeab","price":"0.53","side":"BUY","size":"140"},{"asset_id":"20893381255801015515826997628594359667013752732428989472914000440642900266717","best_ask":"0.4","best_bid":"0.39","hash":"47f83ced9027599b1cb5984b645e1119037b6b1c","price":"0.47","side":"SELL","size":"140"}],"timestamp":"1785204399018"},"payload_hash":"38e7037bd32131024728b574ccd020bc67fd3aa303b092fbcc1b950a8cf9ae7e","raw_frame":"{\"market\":\"0xda6f0e0e93fc8469e0159a166028d017bddbc162b86f66bac90391379603d962\", \"price_changes\":[{\"asset_id\":\"39272994714739463168905443499424551362424437245880253267329605556587274644733\", \"price\":\"0.53\", \"size\":\"140\", \"side\":\"BUY\", \"hash\":\"4c7bfadefe64b9f82ee9fe8b002761523bafbeab\", \"best_bid\":\"0.6\", \"best_ask\":\"0.61\"}, {\"asset_id\":\"20893381255801015515826997628594359667013752732428989472914000440642900266717\", \"price\":\"0.47\", \"size\":\"140\", \"side\":\"SELL\", \"hash\":\"47f83ced9027599b1cb5984b645e1119037b6b1c\", \"best_bid\":\"0.39\", \"best_ask\":\"0.4\"}], \"timestamp\":\"1785204399018\", \"event_type\":\"price_change\"}","received_at":"2026-07-28T02:06:39.863090Z","schema_version":"clob-market-ws.price_change.v1","sequence":null,"server_hash":null,"server_timestamp":"1785204399018","session_id":"d2757dd6dad94f3b9fe67e8dbf1adc37","source":"clob_market_ws"},"received_at":"2026-07-28T02:06:39.863090Z","record_id":"29429ced15c42a9442af43a20bf332bb9bae4cef5346a7e968e6e5e89b77d100","schema_fingerprint":"4aa3821a28b0b7c2400bc59aba4bcc0a76e971dadd19610d3ad38c768e124dc7","schema_version":"edge-lab-recorder.raw.v1","sequence":null,"source":"clob_market_ws"}
{"event_at":"2026-07-28T02:06:39.023000Z","event_fingerprint":"eebafd24de333c0aa8d4d42997310e878797af0bd1bdf31aaa8950101e4025fc","payload":{"connection_id":"5d29200f65794d4d9ab6ef271f045a9b","event_at":"2026-07-28T02:06:39.023000Z","event_type":"price_change","frame_hash":"6c5bff911909bc0a81b383d1386e2fec6765bb93f08cd4d67d4515cf9c412528","frame_index":0,"kind":"data","monotonic_ns":306382874341750,"payload":{"event_type":"price_change","market":"0xda6f0e0e93fc8469e0159a166028d017bddbc162b86f66bac90391379603d962","price_changes":[{"asset_id":"20893381255801015515826997628594359667013752732428989472914000440642900266717","best_ask":"0.4","best_bid":"0.39","hash":"1551724b80840a6ab45d54ceb55cf434a8c68460","price":"0.01","side":"BUY","size":"5677.02"},{"asset_id":"39272994714739463168905443499424551362424437245880253267329605556587274644733","best_ask":"0.61","best_bid":"0.6","hash":"928cfb416e7e585b77d72f4e38cb9e7143ed06fe","price":"0.99","side":"SELL","size":"5677.02"}],"timestamp":"1785204399023"},"payload_hash":"7888c34c9802f23db94c61bb1de3a1ac4a3c03db04fab2ee8cfe5723cbdf9389","raw_frame":"{\"market\":\"0xda6f0e0e93fc8469e0159a166028d017bddbc162b86f66bac90391379603d962\", \"price_changes\":[{\"asset_id\":\"20893381255801015515826997628594359667013752732428989472914000440642900266717\", \"price\":\"0.01\", \"size\":\"5677.02\", \"side\":\"BUY\", \"hash\":\"1551724b80840a6ab45d54ceb55cf434a8c68460\", \"best_bid\":\"0.39\", \"best_ask\":\"0.4\"}, {\"asset_id\":\"39272994714739463168905443499424551362424437245880253267329605556587274644733\", \"price\":\"0.99\", \"size\":\"5677.02\", \"side\":\"SELL\", \"hash\":\"928cfb416e7e585b77d72f4e38cb9e7143ed06fe\", \"best_bid\":\"0.6\", \"best_ask\":\"0.61\"}], \"timestamp\":\"1785204399023\", \"event_type\":\"price_change\"}","received_at":"2026-07-28T02:06:39.867331Z","schema_version":"clob-market-ws.price_change.v1","sequence":null,"server_hash":null,"server_timestamp":"1785204399023","session_id":"d2757dd6dad94f3b9fe67e8dbf1adc37","source":"clob_market_ws"},"received_at":"2026-07-28T02:06:39.867331Z","record_id":"cc459acce13e3b235a88b443b20005b50c9a028a640f20b50e9ad6b5d386f28c","schema_fingerprint":"4aa3821a28b0b7c2400bc59aba4bcc0a76e971dadd19610d3ad38c768e124dc7","schema_version":"edge-lab-recorder.raw.v1","sequence":null,"source":"clob_market_ws"}
{"event_at":"2026-07-28T02:06:39.028000Z","event_fingerprint":"e85ec940bc5c5a34eca5194fa675a5e1567c50bf00672fbd634768e04966c89b","payload":{"connection_id":"5d29200f65794d4d9ab6ef271f045a9b","event_at":"2026-07-28T02:06:39.028000Z","event_type":"price_change","frame_hash":"6eceeeee572e5d7b49c3fcb04c4855553c8d843463afb26fe3d2c072dce6a720","frame_index":0,"kind":"data","monotonic_ns":306382878658166,"payload":{"event_type":"price_change","market":"0xda6f0e0e93fc8469e0159a166028d017bddbc162b86f66bac90391379603d962","price_changes":[{"asset_id":"20893381255801015515826997628594359667013752732428989472914000440642900266717","best_ask":"0.4","best_bid":"0.39","hash":"ee8ac9a1e9b7dbe88bd4468112be37ef3d4f53d4","price":"0.01","side":"BUY","size":"5682.02"},{"asset_id":"39272994714739463168905443499424551362424437245880253267329605556587274644733","best_ask":"0.61","best_bid":"0.6","hash":"5114a50447a49e7a5d77d9b3917ca6f426052733","price":"0.99","side":"SELL","size":"5682.02"}],"timestamp":"1785204399028"},"payload_hash":"6c33bb4a728114d3c5345b2163004af87c55826c96dead264db07312e16d5174","raw_frame":"{\"market\":\"0xda6f0e0e93fc8469e0159a166028d017bddbc162b86f66bac90391379603d962\", \"price_changes\":[{\"asset_id\":\"20893381255801015515826997628594359667013752732428989472914000440642900266717\", \"price\":\"0.01\", \"size\":\"5682.02\", \"side\":\"BUY\", \"hash\":\"ee8ac9a1e9b7dbe88bd4468112be37ef3d4f53d4\", \"best_bid\":\"0.39\", \"best_ask\":\"0.4\"}, {\"asset_id\":\"39272994714739463168905443499424551362424437245880253267329605556587274644733\", \"price\":\"0.99\", \"size\":\"5682.02\", \"side\":\"SELL\", \"hash\":\"5114a50447a49e7a5d77d9b3917ca6f426052733\", \"best_bid\":\"0.6\", \"best_ask\":\"0.61\"}], \"timestamp\":\"1785204399028\", \"event_type\":\"price_change\"}","received_at":"2026-07-28T02:06:39.871648Z","schema_version":"clob-market-ws.price_change.v1","sequence":null,"server_hash":null,"server_timestamp":"1785204399028","session_id":"d2757dd6dad94f3b9fe67e8dbf1adc37","source":"clob_market_ws"},"received_at":"2026-07-28T02:06:39.871648Z","record_id":"1c5ec59bc9160561e8d130426e1ad7c9f8e34b8ef50aa004cc8ce531e39da87e","schema_fingerprint":"4aa3821a28b0b7c2400bc59aba4bcc0a76e971dadd19610d3ad38c768e124dc7","schema_version":"edge-lab-recorder.raw.v1","sequence":null,"source":"clob_market_ws"}
{"event_at":"2026-07-28T02:06:39.045000Z","event_fingerprint":"dca160624b9604497523176926cec90ff81e16a7bcf07de96395d55f0221a252","payload":{"connection_id":"5d29200f65794d4d9ab6ef271f045a9b","event_at":"2026-07-28T02:06:39.045000Z","event_type":"price_change","frame_hash":"b254d58a001908c5944685c7f4114cef40a44fe91efd014229ef9d7f5b46f498","frame_index":0,"kind":"data","monotonic_ns":306382882994833,"payload":{"event_type":"price_change","market":"0xda6f0e0e93fc8469e0159a166028d017bddbc162b86f66bac90391379603d962","price_changes":[{"asset_id":"20893381255801015515826997628594359667013752732428989472914000440642900266717","best_ask":"0.4","best_bid":"0.39","hash":"25d4a8ef2f101a75e084ff97f3612effd8520bfe","price":"0.01","side":"BUY","size":"5677.02"},{"asset_id":"39272994714739463168905443499424551362424437245880253267329605556587274644733","best_ask":"0.61","best_bid":"0.6","hash":"7e81bcaffd7d3f81dff1d5f273e3f6230194c772","price":"0.99","side":"SELL","size":"5677.02"}],"timestamp":"1785204399045"},"payload_hash":"2f57d9f1434243ce5e2ea413cd6629a32681d700a28551d37198fc040e676711","raw_frame":"{\"market\":\"0xda6f0e0e93fc8469e0159a166028d017bddbc162b86f66bac90391379603d962\", \"price_changes\":[{\"asset_id\":\"20893381255801015515826997628594359667013752732428989472914000440642900266717\", \"price\":\"0.01\", \"size\":\"5677.02\", \"side\":\"BUY\", \"hash\":\"25d4a8ef2f101a75e084ff97f3612effd8520bfe\", \"best_bid\":\"0.39\", \"best_ask\":\"0.4\"}, {\"asset_id\":\"39272994714739463168905443499424551362424437245880253267329605556587274644733\", \"price\":\"0.99\", \"size\":\"5677.02\", \"side\":\"SELL\", \"hash\":\"7e81bcaffd7d3f81dff1d5f273e3f6230194c772\", \"best_bid\":\"0.6\", \"best_ask\":\"0.61\"}], \"timestamp\":\"1785204399045\", \"event_type\":\"price_change\"}","received_at":"2026-07-28T02:06:39.875985Z","schema_version":"clob-market-ws.price_change.v1","sequence":null,"server_hash":null,"server_timestamp":"1785204399045","session_id":"d2757dd6dad94f3b9fe67e8dbf1adc37","source":"clob_market_ws"},"received_at":"2026-07-28T02:06:39.875985Z","record_id":"922d025e55368d3c4bf77cfd96509e29e6ec35f9e3eab67aec54266e63ed83f7","schema_fingerprint":"4aa3821a28b0b7c2400bc59aba4bcc0a76e971dadd19610d3ad38c768e124dc7","schema_version":"edge-lab-recorder.raw.v1","sequence":null,"source":"clob_market_ws"}
{"event_at":"2026-07-28T02:06:39.071000Z","event_fingerprint":"6f723d5e95629bd6b48056c4ce87fef78c99401087841fcd24bb539a0e2d9c60","payload":{"connection_id":"5d29200f65794d4d9ab6ef271f045a9b","event_at":"2026-07-28T02:06:39.071000Z","event_type":"price_change","frame_hash":"06ef14fa18a467bc93c556eaba5ddbcebaf5b71173322739d1d08cf32d71d755","frame_index":0,"kind":"data","monotonic_ns":306382887321375,"payload":{"event_type":"price_change","market":"0xda6f0e0e93fc8469e0159a166028d017bddbc162b86f66bac90391379603d962","price_changes":[{"asset_id":"39272994714739463168905443499424551362424437245880253267329605556587274644733","best_ask":"0.61","best_bid":"0.6","hash":"5b14dddeea02946e8bd7745f6a2f29729c976b9a","price":"0.03","side":"BUY","size":"648.1"},{"asset_id":"20893381255801015515826997628594359667013752732428989472914000440642900266717","best_ask":"0.4","best_bid":"0.39","hash":"e5a468bd259531510296dce7cfb978ea285870c6","price":"0.97","side":"SELL","size":"648.1"}],"timestamp":"1785204399071"},"payload_hash":"32004b5397eaa43dc818f12cef247fbdad0bde64fad5e9c7cb19b629ec2a313e","raw_frame":"{\"market\":\"0xda6f0e0e93fc8469e0159a166028d017bddbc162b86f66bac90391379603d962\", \"price_changes\":[{\"asset_id\":\"39272994714739463168905443499424551362424437245880253267329605556587274644733\", \"price\":\"0.03\", \"size\":\"648.1\", \"side\":\"BUY\", \"hash\":\"5b14dddeea02946e8bd7745f6a2f29729c976b9a\", \"best_bid\":\"0.6\", \"best_ask\":\"0.61\"}, {\"asset_id\":\"20893381255801015515826997628594359667013752732428989472914000440642900266717\", \"price\":\"0.97\", \"size\":\"648.1\", \"side\":\"SELL\", \"hash\":\"e5a468bd259531510296dce7cfb978ea285870c6\", \"best_bid\":\"0.39\", \"best_ask\":\"0.4\"}], \"timestamp\":\"1785204399071\", \"event_type\":\"price_change\"}","received_at":"2026-07-28T02:06:39.880311Z","schema_version":"clob-market-ws.price_change.v1","sequence":null,"server_hash":null,"server_timestamp":"1785204399071","session_id":"d2757dd6dad94f3b9fe67e8dbf1adc37","source":"clob_market_ws"},"received_at":"2026-07-28T02:06:39.880311Z","record_id":"48447c21a19022c2b77333d2b581ff9e50d00a0da0292f715613d35cca646c1d","schema_fingerprint":"4aa3821a28b0b7c2400bc59aba4bcc0a76e971dadd19610d3ad38c768e124dc7","schema_version":"edge-lab-recorder.raw.v1","sequence":null,"source":"clob_market_ws"}
{"event_at":"2026-07-28T02:06:39.117000Z","event_fingerprint":"4aa9d6b70341c7d285f782cefcca826a445d01e46f57113dac7243d15f4a2981","payload":{"connection_id":"5d29200f65794d4d9ab6ef271f045a9b","event_at":"2026-07-28T02:06:39.117000Z","event_type":"price_change","frame_hash":"fdc07b38e14501486d720813c2b0972e1c1c179d0070f351558fdeaf760f398b","frame_index":0,"kind":"data","monotonic_ns":306382891171125,"payload":{"event_type":"price_change","market":"0xda6f0e0e93fc8469e0159a166028d017bddbc162b86f66bac90391379603d962","price_changes":[{"asset_id":"39272994714739463168905443499424551362424437245880253267329605556587274644733","best_ask":"0.61","best_bid":"0.6","hash":"7d54ac83ba10052597299ff518ed79700a975480","price":"0.61","side":"SELL","size":"35"},{"asset_id":"20893381255801015515826997628594359667013752732428989472914000440642900266717","best_ask":"0.4","best_bid":"0.39","hash":"975834e5ef02dde3065d7fdab33bb1d4ca59d7b1","price":"0.39","side":"BUY","size":"35"}],"timestamp":"1785204399117"},"payload_hash":"4d1650b07635bfc2fe3a8775d129c8207c30954dafcad3fa5611179ee847a482","raw_frame":"{\"market\":\"0xda6f0e0e93fc8469e0159a166028d017bddbc162b86f66bac90391379603d962\", \"price_changes\":[{\"asset_id\":\"39272994714739463168905443499424551362424437245880253267329605556587274644733\", \"price\":\"0.61\", \"size\":\"35\", \"side\":\"SELL\", \"hash\":\"7d54ac83ba10052597299ff518ed79700a975480\", \"best_bid\":\"0.6\", \"best_ask\":\"0.61\"}, {\"asset_id\":\"20893381255801015515826997628594359667013752732428989472914000440642900266717\", \"price\":\"0.39\", \"size\":\"35\", \"side\":\"BUY\", \"hash\":\"975834e5ef02dde3065d7fdab33bb1d4ca59d7b1\", \"best_bid\":\"0.39\", \"best_ask\":\"0.4\"}], \"timestamp\":\"1785204399117\", \"event_type\":\"price_change\"}","received_at":"2026-07-28T02:06:39.884158Z","schema_version":"clob-market-ws.price_change.v1","sequence":null,"server_hash":null,"server_timestamp":"1785204399117","session_id":"d2757dd6dad94f3b9fe67e8dbf1adc37","source":"clob_market_ws"},"received_at":"2026-07-28T02:06:39.884158Z","record_id":"7aec8dcaad3382d930192e14b340b012a18320bff92f1a959ce9cb6ff1479840","schema_fingerprint":"4aa3821a28b0b7c2400bc59aba4bcc0a76e971dadd19610d3ad38c768e124dc7","schema_version":"edge-lab-recorder.raw.v1","sequence":null,"source":"clob_market_ws"}
{"event_at":"2026-07-28T02:06:39.181000Z","event_fingerprint":"f378a2ac549a95d7fcb5e3366a450e853a4b258024030d04b5020e56b454d395","payload":{"connection_id":"5d29200f65794d4d9ab6ef271f045a9b","event_at":"2026-07-28T02:06:39.181000Z","event_type":"price_change","frame_hash":"523d5ed3276306cabe95f6cdbc924350c6e0c64ca7d6ba413d4e68c878dda00f","frame_index":0,"kind":"data","monotonic_ns":306382895535958,"payload":{"event_type":"price_change","market":"0xda6f0e0e93fc8469e0159a166028d017bddbc162b86f66bac90391379603d962","price_changes":[{"asset_id":"39272994714739463168905443499424551362424437245880253267329605556587274644733","best_ask":"0.61","best_bid":"0.6","hash":"9f79f8651dbeee3f4190bf90f074b475c8dc7687","price":"0.02","side":"BUY","size":"693.1"},{"asset_id":"20893381255801015515826997628594359667013752732428989472914000440642900266717","best_ask":"0.4","best_bid":"0.39","hash":"0b28b5b4f600ea6c969467bbbf5baa1586b3fa66","price":"0.98","side":"SELL","size":"693.1"}],"timestamp":"1785204399181"},"payload_hash":"45107cb5ed8add59acdd6ecf7537b88163d61c372ad0d6065cea03df4f5e3ef4","raw_frame":"{\"market\":\"0xda6f0e0e93fc8469e0159a166028d017bddbc162b86f66bac90391379603d962\", \"price_changes\":[{\"asset_id\":\"39272994714739463168905443499424551362424437245880253267329605556587274644733\", \"price\":\"0.02\", \"size\":\"693.1\", \"side\":\"BUY\", \"hash\":\"9f79f8651dbeee3f4190bf90f074b475c8dc7687\", \"best_bid\":\"0.6\", \"best_ask\":\"0.61\"}, {\"asset_id\":\"20893381255801015515826997628594359667013752732428989472914000440642900266717\", \"price\":\"0.98\", \"size\":\"693.1\", \"side\":\"SELL\", \"hash\":\"0b28b5b4f600ea6c969467bbbf5baa1586b3fa66\", \"best_bid\":\"0.39\", \"best_ask\":\"0.4\"}], \"timestamp\":\"1785204399181\", \"event_type\":\"price_change\"}","received_at":"2026-07-28T02:06:39.888526Z","schema_version":"clob-market-ws.price_change.v1","sequence":null,"server_hash":null,"server_timestamp":"1785204399181","session_id":"d2757dd6dad94f3b9fe67e8dbf1adc37","source":"clob_market_ws"},"received_at":"2026-07-28T02:06:39.888526Z","record_id":"43fb0e930db118c8aefa1e23d3095390c520cd7f6a0e2ef31944df0d73896c01","schema_fingerprint":"4aa3821a28b0b7c2400bc59aba4bcc0a76e971dadd19610d3ad38c768e124dc7","schema_version":"edge-lab-recorder.raw.v1","sequence":null,"source":"clob_market_ws"}
{"event_at":"2026-07-28T02:06:39.196000Z","event_fingerprint":"e38f328614ff8fb1411e237b70874e4c12bc82b0bb7617d7d18fb0aff3393eb6","payload":{"connection_id":"5d29200f65794d4d9ab6ef271f045a9b","event_at":"2026-07-28T02:06:39.196000Z","event_type":"price_change","frame_hash":"7fc94649a26f3c3bd31ecf49c61fccb08b9975976a033ac2e76c38b495116b56","frame_index":0,"kind":"data","monotonic_ns":306382899135708,"payload":{"event_type":"price_change","market":"0xda6f0e0e93fc8469e0159a166028d017bddbc162b86f66bac90391379603d962","price_changes":[{"asset_id":"20893381255801015515826997628594359667013752732428989472914000440642900266717","best_ask":"0.4","best_bid":"0.39","hash":"828d15e27a0734104c9434e39a7bf7f40eec02b0","price":"0.01","side":"BUY","size":"5672.02"},{"asset_id":"39272994714739463168905443499424551362424437245880253267329605556587274644733","best_ask":"0.61","best_bid":"0.6","hash":"ecb9017b1a545be896e13d0daf593e74d25f649b","price":"0.99","side":"SELL","size":"5672.02"}],"timestamp":"1785204399196"},"payload_hash":"614d8862ececc56d773193b7809d1d6ba24f695f02808b4ad37a3420f381eada","raw_frame":"{\"market\":\"0xda6f0e0e93fc8469e0159a166028d017bddbc162b86f66bac90391379603d962\", \"price_changes\":[{\"asset_id\":\"20893381255801015515826997628594359667013752732428989472914000440642900266717\", \"price\":\"0.01\", \"size\":\"5672.02\", \"side\":\"BUY\", \"hash\":\"828d15e27a0734104c9434e39a7bf7f40eec02b0\", \"best_bid\":\"0.39\", \"best_ask\":\"0.4\"}, {\"asset_id\":\"39272994714739463168905443499424551362424437245880253267329605556587274644733\", \"price\":\"0.99\", \"size\":\"5672.02\", \"side\":\"SELL\", \"hash\":\"ecb9017b1a545be896e13d0daf593e74d25f649b\", \"best_bid\":\"0.6\", \"best_ask\":\"0.61\"}], \"timestamp\":\"1785204399196\", \"event_type\":\"price_change\"}","received_at":"2026-07-28T02:06:39.892125Z","schema_version":"clob-market-ws.price_change.v1","sequence":null,"server_hash":null,"server_timestamp":"1785204399196","session_id":"d2757dd6dad94f3b9fe67e8dbf1adc37","source":"clob_market_ws"},"received_at":"2026-07-28T02:06:39.892125Z","record_id":"ddf94dc3bc9d7c9b837583038ad3accdcd0c12af6feaaaab4915b4b362951f68","schema_fingerprint":"4aa3821a28b0b7c2400bc59aba4bcc0a76e971dadd19610d3ad38c768e124dc7","schema_version":"edge-lab-recorder.raw.v1","sequence":null,"source":"clob_market_ws"}
