{"event_at":"2026-07-28T02:13:37.468000Z","event_fingerprint":"62bf8732d8d55b1dec2b214a924b42389ad7a43783461a286601dffe8db44d79","payload":{"connection_id":"5d29200f65794d4d9ab6ef271f045a9b","event_at":"2026-07-28T02:13:37.468000Z","event_type":"price_change","frame_hash":"b95391f132991157a753866dd7454ffdebe9f1023ce81a0fdc6b6201f321b6fb","frame_index":0,"kind":"data","monotonic_ns":306800414226666,"payload":{"event_type":"price_change","market":"0xda6f0e0e93fc8469e0159a166028d017bddbc162b86f66bac90391379603d962","price_changes":[{"asset_id":"39272994714739463168905443499424551362424437245880253267329605556587274644733","best_ask":"0.28","best_bid":"0.26","hash":"e042c972bf08bf1000daf83644055f4f9e3d7498","price":"0.27","side":"BUY","size":"0"},{"asset_id":"20893381255801015515826997628594359667013752732428989472914000440642900266717","best_ask":"0.74","best_bid":"0.72","hash":"cdd742f64caaadbb9e53ffd758870d2c8ac2bfac","price":"0.73","side":"SELL","size":"0"}],"timestamp":"1785204817468"},"payload_hash":"f697951f441d67270dd344852608bffe80fa3374e717a8beac46a3019c3660e4","raw_frame":"{\"market\":\"0xda6f0e0e93fc8469e0159a166028d017bddbc162b86f66bac90391379603d962\", \"price_changes\":[{\"asset_id\":\"39272994714739463168905443499424551362424437245880253267329605556587274644733\", \"price\":\"0.27\", \"size\":\"0\", \"side\":\"BUY\", \"hash\":\"e042c972bf08bf1000daf83644055f4f9e3d7498\", \"best_bid\":\"0.26\", \"best_ask\":\"0.28\"}, {\"asset_id\":\"20893381255801015515826997628594359667013752732428989472914000440642900266717\", \"price\":\"0.73\", \"size\":\"0\", \"side\":\"SELL\", \"hash\":\"cdd742f64caaadbb9e53ffd758870d2c8ac2bfac\", \"best_bid\":\"0.72\", \"best_ask\":\"0.74\"}], \"timestamp\":\"1785204817468\", \"event_type\":\"price_change\"}","received_at":"2026-07-28T02:13:37.403069Z","schema_version":"clob-market-ws.price_change.v1","sequence":null,"server_hash":null,"server_timestamp":"1785204817468","session_id":"d2757dd6dad94f3b9fe67e8dbf1adc37","source":"clob_market_ws"},"received_at":"2026-07-28T02:13:37.403069Z","record_id":"e670a9e54757129c036d35c37877f1762a2b6a17b347352bf573132688561883","schema_fingerprint":"4aa3821a28b0b7c2400bc59aba4bcc0a76e971dadd19610d3ad38c768e124dc7","schema_version":"edge-lab-recorder.raw.v1","sequence":null,"source":"clob_market_ws"}
{"event_at":"2026-07-28T02:13:37.476000Z","event_fingerprint":"67f411ed2daf833cc69bf802ed5d1ec5a0efb55df589342adb1728d9a45a5feb","payload":{"connection_id":"5d29200f65794d4d9ab6ef271f045a9b","event_at":"2026-07-28T02:13:37.476000Z","event_type":"price_change","frame_hash":"d4d3905a324cc4f56cf41363e99421fead4bb7e3d7c7a1dfacee54b1552e97e7","frame_index":0,"kind":"data","monotonic_ns":306800416672125,"payload":{"event_type":"price_change","market":"0xda6f0e0e93fc8469e0159a166028d017bddbc162b86f66bac90391379603d962","price_changes":[{"asset_id":"20893381255801015515826997628594359667013752732428989472914000440642900266717","best_ask":"0.74","best_bid":"0.72","hash":"7bfba136561e65d187e032cfcf2290b0c9b3f9bf","price":"0.72","side":"BUY","size":"110.99"},{"asset_id":"39272994714739463168905443499424551362424437245880253267329605556587274644733","best_ask":"0.28","best_bid":"0.26","hash":"8aca0c1be8d5bdcb82e6d331f4f72495ab5aa3fc","price":"0.28","side":"SELL","size":"110.99"}],"timestamp":"1785204817476"},"payload_hash":"8ecf61a0c96c5b80a2016bc7cc1bde06834883a0aee6c759e58db5fde9781ede","raw_frame":"{\"market\":\"0xda6f0e0e93fc8469e0159a166028d017bddbc162b86f66bac90391379603d962\", \"price_changes\":[{\"asset_id\":\"20893381255801015515826997628594359667013752732428989472914000440642900266717\", \"price\":\"0.72\", \"size\":\"110.99\", \"side\":\"BUY\", \"hash\":\"7bfba136561e65d187e032cfcf2290b0c9b3f9bf\", \"best_bid\":\"0.72\", \"best_ask\":\"0.74\"}, {\"asset_id\":\"39272994714739463168905443499424551362424437245880253267329605556587274644733\", \"price\":\"0.28\", \"size\":\"110.99\", \"side\":\"SELL\", \"hash\":\"8aca0c1be8d5bdcb82e6d331f4f72495ab5aa3fc\", \"best_bid\":\"0.26\", \"best_ask\":\"0.28\"}], \"timestamp\":\"1785204817476\", \"event_type\":\"price_change\"}","received_at":"2026-07-28T02:13:37.405518Z","schema_version":"clob-market-ws.price_change.v1","sequence":null,"server_hash":null,"server_timestamp":"1785204817476","session_id":"d2757dd6dad94f3b9fe67e8dbf1adc37","source":"clob_market_ws"},"received_at":"2026-07-28T02:13:37.405518Z","record_id":"ce1fd8685b391db0e11752abf1bb978d61487f2377c632f94ca3e2b7d2e1de09","schema_fingerprint":"4aa3821a28b0b7c2400bc59aba4bcc0a76e971dadd19610d3ad38c768e124dc7","schema_version":"edge-lab-recorder.raw.v1","sequence":null,"source":"clob_market_ws"}
{"event_at":"2026-07-28T02:13:37.481000Z","event_fingerprint":"d4849eee90745585140d4e74f106486f27d48c8b1cff80c4efc3e435c5a907db","payload":{"connection_id":"5d29200f65794d4d9ab6ef271f045a9b","event_at":"2026-07-28T02:13:37.481000Z","event_type":"price_change","frame_hash":"f447a88afbd929ce8ae799b9ad8bb1d9ce03a5762bcae62187fe9dbbc74e4b4d","frame_index":0,"kind":"data","monotonic_ns":306800418316250,"payload":{"event_type":"price_change","market":"0xda6f0e0e93fc8469e0159a166028d017bddbc162b86f66bac90391379603d962","price_changes":[{"asset_id":"20893381255801015515826997628594359667013752732428989472914000440642900266717","best_ask":"0.74","best_bid":"0.72","hash":"3d7ead477cf32610e25e03d116768b92efe7a266","price":"0.72","side":"BUY","size":"27.52"},{"asset_id":"39272994714739463168905443499424551362424437245880253267329605556587274644733","best_ask":"0.28","best_bid":"0.26","hash":"84d23821e77bfd308c03477bc81439fe6d73c591","price":"0.28","side":"SELL","size":"27.52"}],"timestamp":"1785204817481"},"payload_hash":"cc1815b702c4e3ba5801d69bb99bd17c480c0bc5b475041ed2e844a61290c8a4","raw_frame":"{\"market\":\"0xda6f0e0e93fc8469e0159a166028d017bddbc162b86f66bac90391379603d962\", \"price_changes\":[{\"asset_id\":\"20893381255801015515826997628594359667013752732428989472914000440642900266717\", \"price\":\"0.72\", \"size\":\"27.52\", \"side\":\"BUY\", \"hash\":\"3d7ead477cf32610e25e03d116768b92efe7a266\", \"best_bid\":\"0.72\", \"best_ask\":\"0.74\"}, {\"asset_id\":\"39272994714739463168905443499424551362424437245880253267329605556587274644733\", \"price\":\"0.28\", \"size\":\"27.52\", \"side\":\"SELL\", \"hash\":\"84d23821e77bfd308c03477bc81439fe6d73c591\", \"best_bid\":\"0.26\", \"best_ask\":\"0.28\"}], \"timestamp\":\"1785204817481\", \"event_type\":\"price_change\"}","received_at":"2026-07-28T02:13:37.407165Z","schema_version":"clob-market-ws.price_change.v1","sequence":null,"server_hash":null,"server_timestamp":"1785204817481","session_id":"d2757dd6dad94f3b9fe67e8dbf1adc37","source":"clob_market_ws"},"received_at":"2026-07-28T02:13:37.407165Z","record_id":"e52256b5d1eb290a7862af4109e4b14daba41bb264c52e2bc480580b22c76434","schema_fingerprint":"4aa3821a28b0b7c2400bc59aba4bcc0a76e971dadd19610d3ad38c768e124dc7","schema_version":"edge-lab-recorder.raw.v1","sequence":null,"source":"clob_market_ws"}
{"event_at":"2026-07-28T02:13:37.483000Z","event_fingerprint":"6a728fe0780f0ddf406b00ee7d9b5b31b3d6fd457a5b3308258634a9ce8eb7aa","payload":{"connection_id":"5d29200f65794d4d9ab6ef271f045a9b","event_at":"2026-07-28T02:13:37.483000Z","event_type":"price_change","frame_hash":"4e9e55564cca25c93e1fccbb7e359d23048ea756cc1d39bc62bd96569039ae65","frame_index":0,"kind":"data","monotonic_ns":306800419882333,"payload":{"event_type":"price_change","market":"0xda6f0e0e93fc8469e0159a166028d017bddbc162b86f66bac90391379603d962","price_changes":[{"asset_id":"39272994714739463168905443499424551362424437245880253267329605556587274644733","best_ask":"0.28","best_bid":"0.26","hash":"e7182baa2de0377585298cf17fe2a9e24c55b504","price":"0.28","side":"SELL","size":"105.99"},{"asset_id":"20893381255801015515826997628594359667013752732428989472914000440642900266717","best_ask":"0.74","best_bid":"0.72","hash":"69d733e8e0f04b4b8aa861255fc923c2e5b0c81d","price":"0.72","side":"BUY","size":"105.99"}],"timestamp":"1785204817483"},"payload_hash":"a934b374e173334df4dc53a502e594fc0679a466aba78878bdf4c4ec8b475bf2","raw_frame":"{\"market\":\"0xda6f0e0e93fc8469e0159a166028d017bddbc162b86f66bac90391379603d962\", \"price_changes\":[{\"asset_id\":\"39272994714739463168905443499424551362424437245880253267329605556587274644733\", \"price\":\"0.28\", \"size\":\"105.99\", \"side\":\"SELL\", \"hash\":\"e7182baa2de0377585298cf17fe2a9e24c55b504\", \"best_bid\":\"0.26\", \"best_ask\":\"0.28\"}, {\"asset_id\":\"20893381255801015515826997628594359667013752732428989472914000440642900266717\", \"price\":\"0.72\", \"size\":\"105.99\", \"side\":\"BUY\", \"hash\":\"69d733e8e0f04b4b8aa861255fc923c2e5b0c81d\", \"best_bid\":\"0.72\", \"best_ask\":\"0.74\"}], \"timestamp\":\"1785204817483\", \"event_type\":\"price_change\"}","received_at":"2026-07-28T02:13:37.408731Z","schema_version":"clob-market-ws.price_change.v1","sequence":null,"server_hash":null,"server_timestamp":"1785204817483","session_id":"d2757dd6dad94f3b9fe67e8dbf1adc37","source":"clob_market_ws"},"received_at":"2026-07-28T02:13:37.408731Z","record_id":"9612d6973f721b2c8145f4b267c9819faa7366b64b56c77ac39b35c8c1e28887","schema_fingerprint":"4aa3821a28b0b7c2400bc59aba4bcc0a76e971dadd19610d3ad38c768e124dc7","schema_version":"edge-lab-recorder.raw.v1","sequence":null,"source":"clob_market_ws"}
{"event_at":"2026-07-28T02:13:37.485000Z","event_fingerprint":"acfea84efd58f396ea646e9110a4ad1f5763791a6c927b4beb367f401a87b523","payload":{"connection_id":"5d29200f65794d4d9ab6ef271f045a9b","event_at":"2026-07-28T02:13:37.485000Z","event_type":"price_change","frame_hash":"6a35e150fccff78ffe9b7b235ec31c34b670a2bd3825d99c6fc1055ac7583946","frame_index":0,"kind":"data","monotonic_ns":306800421407625,"payload":{"event_type":"price_change","market":"0xda6f0e0e93fc8469e0159a166028d017bddbc162b86f66bac90391379603d962","price_changes":[{"asset_id":"20893381255801015515826997628594359667013752732428989472914000440642900266717","best_ask":"0.74","best_bid":"0.72","hash":"8f739d8b8b819948d50049e9faf055d4d89c15da","price":"0.72","side":"BUY","size":"100.99"},{"asset_id":"39272994714739463168905443499424551362424437245880253267329605556587274644733","best_ask":"0.28","best_bid":"0.26","hash":"a85ae92a62a6ed31473eddd8a05311a0ebf100b5","price":"0.28","side":"SELL","size":"100.99"}],"timestamp":"1785204817485"},"payload_hash":"02d5a9f73fcaa02eb155e9c1c5fc0b29e646e983774f4d157b460e19857a58aa","raw_frame":"{\"market\":\"0xda6f0e0e93fc8469e0159a166028d017bddbc162b86f66bac90391379603d962\", \"price_changes\":[{\"asset_id\":\"20893381255801015515826997628594359667013752732428989472914000440642900266717\", \"price\":\"0.72\", \"size\":\"100.99\", \"side\":\"BUY\", \"hash\":\"8f739d8b8b819948d50049e9faf055d4d89c15da\", \"best_bid\":\"0.72\", \"best_ask\":\"0.74\"}, {\"asset_id\":\"39272994714739463168905443499424551362424437245880253267329605556587274644733\", \"price\":\"0.28\", \"size\":\"100.99\", \"side\":\"SELL\", \"hash\":\"a85ae92a62a6ed31473eddd8a05311a0ebf100b5\", \"best_bid\":\"0.26\", \"best_ask\":\"0.28\"}], \"timestamp\":\"1785204817485\", \"event_type\":\"price_change\"}","received_at":"2026-07-28T02:13:37.410256Z","schema_version":"clob-market-ws.price_change.v1","sequence":null,"server_hash":null,"server_timestamp":"1785204817485","session_id":"d2757dd6dad94f3b9fe67e8dbf1adc37","source":"clob_market_ws"},"received_at":"2026-07-28T02:13:37.410256Z","record_id":"79460d6c47a4a06639546f22bf6a627ead373579871824719d7bb1d30a38d0b0","schema_fingerprint":"4aa3821a28b0b7c2400bc59aba4bcc0a76e971dadd19610d3ad38c768e124dc7","schema_version":"edge-lab-recorder.raw.v1","sequence":null,"source":"clob_market_ws"}
{"event_at":"2026-07-28T02:13:37.487000Z","event_fingerprint":"d1176d6109a75c6f0102e2ad2839b53138869561575325726702b6f1ef7b0731","payload":{"connection_id":"5d29200f65794d4d9ab6ef271f045a9b","event_at":"2026-07-28T02:13:37.487000Z","event_type":"price_change","frame_hash":"0ee300a77b07693efdb06565ebef6a3c11d3c5b5160435eaa15de8ab687a0715","frame_index":0,"kind":"data","monotonic_ns":306800422881291,"payload":{"event_type":"price_change","market":"0xda6f0e0e93fc8469e0159a166028d017bddbc162b86f66bac90391379603d962","price_changes":[{"asset_id":"20893381255801015515826997628594359667013752732428989472914000440642900266717","best_ask":"0.74","best_bid":"0.72","hash":"207579b2b23a7fd301788757d7aaf141f20e3f87","price":"0.7","side":"BUY","size":"32"},{"asset_id":"39272994714739463168905443499424551362424437245880253267329605556587274644733","best_ask":"0.28","best_bid":"0.26","hash":"47a0973bf1d2db56348c7312f0e360e9d8fa9a3f","price":"0.3","side":"SELL","size":"32"}],"timestamp":"1785204817487"},"payload_hash":"d795acbdf04f5e37fd8cf323aeb8414af367d2081afe8927a8e8436f904f593a","raw_frame":"{\"market\":\"0xda6f0e0e93fc8469e0159a166028d017bddbc162b86f66bac90391379603d962\", \"price_changes\":[{\"asset_id\":\"20893381255801015515826997628594359667013752732428989472914000440642900266717\", \"price\":\"0.7\", \"size\":\"32\", \"side\":\"BUY\", \"hash\":\"207579b2b23a7fd301788757d7aaf141f20e3f87\", \"best_bid\":\"0.72\", \"best_ask\":\"0.74\"}, {\"asset_id\":\"39272994714739463168905443499424551362424437245880253267329605556587274644733\", \"price\":\"0.3\", \"size\":\"32\", \"side\":\"SELL\", \"hash\":\"47a0973bf1d2db56348c7312f0e360e9d8fa9a3f\", \"best_bid\":\"0.26\", \"best_ask\":\"0.28\"}], \"timestamp\":\"1785204817487\", \"event_type\":\"price_change\"}","received_at":"2026-07-28T02:13:37.411731Z","schema_version":"clob-market-ws.price_change.v1","sequence":null,"server_hash":null,"server_timestamp":"1785204817487","session_id":"d2757dd6dad94f3b9fe67e8dbf1adc37","source":"clob_market_ws"},"received_at":"2026-07-28T02:13:37.411731Z","record_id":"18641fd0f6ec3d45f5f28f1fbe6a877cd0a801c63b55f0af1342350bde8ae9c0","schema_fingerprint":"4aa3821a28b0b7c2400bc59aba4bcc0a76e971dadd19610d3ad38c768e124dc7","schema_version":"edge-lab-recorder.raw.v1","sequence":null,"source":"clob_market_ws"}
{"event_at":"2026-07-28T02:13:37.494000Z","event_fingerprint":"5310a91f23082d785bd6c50eec485b647faf420dbb33dae9838fb1012d9a74d3","payload":{"connection_id":"5d29200f65794d4d9ab6ef271f045a9b","event_at":"2026-07-28T02:13:37.494000Z","event_type":"price_change","frame_hash":"3708ba57a128a255aa8674b54207528488e06e241a2579cd311641d33bf79104","frame_index":0,"kind":"data","monotonic_ns":306800424473625,"payload":{"event_type":"price_change","market":"0xda6f0e0e93fc8469e0159a166028d017bddbc162b86f66bac90391379603d962","price_changes":[{"asset_id":"20893381255801015515826997628594359667013752732428989472914000440642900266717","best_ask":"0.74","best_bid":"0.72","hash":"edac34c6d75253432f3918b507dad939e18ea204","price":"0.02","side":"BUY","size":"574"},{"asset_id":"39272994714739463168905443499424551362424437245880253267329605556587274644733","best_ask":"0.28","best_bid":"0.26","hash":"aa0d92d97d058493d66eddd5ef5cc8e69d78144b","price":"0.98","side":"SELL","size":"574"}],"timestamp":"1785204817494"},"payload_hash":"bb3317e928d3bd581cf63477376a18f0477994f6443076ec17ee7b729852e8aa","raw_frame":"{\"market\":\"0xda6f0e0e93fc8469e0159a166028d017bddbc162b86f66bac90391379603d962\", \"price_changes\":[{\"asset_id\":\"20893381255801015515826997628594359667013752732428989472914000440642900266717\", \"price\":\"0.02\", \"size\":\"574\", \"side\":\"BUY\", \"hash\":\"edac34c6d75253432f3918b507dad939e18ea204\", \"best_bid\":\"0.72\", \"best_ask\":\"0.74\"}, {\"asset_id\":\"39272994714739463168905443499424551362424437245880253267329605556587274644733\", \"price\":\"0.98\", \"size\":\"574\", \"side\":\"SELL\", \"hash\":\"aa0d92d97d058493d66eddd5ef5cc8e69d78144b\", \"best_bid\":\"0.26\", \"best_ask\":\"0.28\"}], \"timestamp\":\"1785204817494\", \"event_type\":\"price_change\"}","received_at":"2026-07-28T02:13:37.413321Z","schema_version":"clob-market-ws.price_change.v1","sequence":null,"server_hash":null,"server_timestamp":"1785204817494","session_id":"d2757dd6dad94f3b9fe67e8dbf1adc37","source":"clob_market_ws"},"received_at":"2026-07-28T02:13:37.413321Z","record_id":"b976f0b859714712c4e4b63d056f489d41398fef5158647da57e55349dc53d98","schema_fingerprint":"4aa3821a28b0b7c2400bc59aba4bcc0a76e971dadd19610d3ad38c768e124dc7","schema_version":"edge-lab-recorder.raw.v1","sequence":null,"source":"clob_market_ws"}
{"event_at":"2026-07-28T02:13:37.498000Z","event_fingerprint":"2aefe9f0aac744c1c98fbf84343f6d94e484f6556e8624d5494dbbd34f519ac6","payload":{"connection_id":"5d29200f65794d4d9ab6ef271f045a9b","event_at":"2026-07-28T02:13:37.498000Z","event_type":"best_bid_ask","frame_hash":"66b6d3bc82205e8c50e6067512b6b9f0fdcd3bb3b22319663cd17b19425d397a","frame_index":0,"kind":"data","monotonic_ns":306800426152541,"payload":{"asset_id":"20893381255801015515826997628594359667013752732428989472914000440642900266717","best_ask":"0.73","best_bid":"0.72","event_type":"best_bid_ask","market":"0xda6f0e0e93fc8469e0159a166028d017bddbc162b86f66bac90391379603d962","spread":"0.01","timestamp":"1785204817498"},"payload_hash":"59517d4bf6be1ef0bfd2e02a5e3211bb21aefb1d71cccfd4e1185d8b39553345","raw_frame":"{\"market\":\"0xda6f0e0e93fc8469e0159a166028d017bddbc162b86f66bac90391379603d962\", \"asset_id\":\"20893381255801015515826997628594359667013752732428989472914000440642900266717\", \"best_bid\":\"0.72\", \"best_ask\":\"0.73\", \"spread\":\"0.01\", \"timestamp\":\"1785204817498\", \"event_type\":\"best_bid_ask\"}","received_at":"2026-07-28T02:13:37.415002Z","schema_version":"clob-market-ws.best_bid_ask.v1","sequence":null,"server_hash":null,"server_timestamp":"1785204817498","session_id":"d2757dd6dad94f3b9fe67e8dbf1adc37","source":"clob_market_ws"},"received_at":"2026-07-28T02:13:37.415002Z","record_id":"135c0ebe3085db009e90f05ed08b42c1d633fb43325397a0b0a062848bea31d9","schema_fingerprint":"8488399f31b0337811b13b266be932db7062827c2470b78bd8e9e99bab51d17d","schema_version":"edge-lab-recorder.raw.v1","sequence":null,"source":"clob_market_ws"}
{"event_at":"2026-07-28T02:13:37.498000Z","event_fingerprint":"2027377a8ae75dec4fa7d69961eef6ee5a61fd2908326b84192838b392781b62","payload":{"connection_id":"5d29200f65794d4d9ab6ef271f045a9b","event_at":"2026-07-28T02:13:37.498000Z","event_type":"best_bid_ask","frame_hash":"1e9969467c9f98bbca1d813f099d62cc25e5eedbd812bb34b582b1008340e70d","frame_index":0,"kind":"data","monotonic_ns":306800427303125,"payload":{"asset_id":"39272994714739463168905443499424551362424437245880253267329605556587274644733","best_ask":"0.28","best_bid":"0.27","event_type":"best_bid_ask","market":"0xda6f0e0e93fc8469e0159a166028d017bddbc162b86f66bac90391379603d962","spread":"0.01","timestamp":"1785204817498"},"payload_hash":"8eefd37690b93b91f1a9b978111dddadc92e878301724ffe1be62ba3cdde46b6","raw_frame":"{\"market\":\"0xda6f0e0e93fc8469e0159a166028d017bddbc162b86f66bac90391379603d962\", \"asset_id\":\"39272994714739463168905443499424551362424437245880253267329605556587274644733\", \"best_bid\":\"0.27\", \"best_ask\":\"0.28\", \"spread\":\"0.01\", \"timestamp\":\"1785204817498\", \"event_type\":\"best_bid_ask\"}","received_at":"2026-07-28T02:13:37.416153Z","schema_version":"clob-market-ws.best_bid_ask.v1","sequence":null,"server_hash":null,"server_timestamp":"1785204817498","session_id":"d2757dd6dad94f3b9fe67e8dbf1adc37","source":"clob_market_ws"},"received_at":"2026-07-28T02:13:37.416153Z","record_id":"3a151770c37fdeab3bf78b83d2cad9921569419564843c1ed8db3915f2540bd8","schema_fingerprint":"8488399f31b0337811b13b266be932db7062827c2470b78bd8e9e99bab51d17d","schema_version":"edge-lab-recorder.raw.v1","sequence":null,"source":"clob_market_ws"}
{"event_at":"2026-07-28T02:13:37.498000Z","event_fingerprint":"c9f1b830e8c14644241f0f1c937da43f499a6d09efff503254e6472dcea86671","payload":{"connection_id":"5d29200f65794d4d9ab6ef271f045a9b","event_at":"2026-07-28T02:13:37.498000Z","event_type":"price_change","frame_hash":"13846978c827b2b84f9ddaeb72503cbc2f5b90c8855f86b27e28c54b8ace8ed1","frame_index":0,"kind":"data","monotonic_ns":306800428340583,"payload":{"event_type":"price_change","market":"0xda6f0e0e93fc8469e0159a166028d017bddbc162b86f66bac90391379603d962","price_changes":[{"asset_id":"39272994714739463168905443499424551362424437245880253267329605556587274644733","best_ask":"0.28","best_bid":"0.27","hash":"701d8881f53a34a6fdb0163352ba007db200d193","price":"0.27","side":"BUY","size":"5"},{"asset_id":"20893381255801015515826997628594359667013752732428989472914000440642900266717","best_ask":"0.73","best_bid":"0.72","hash":"02a396126c4c26e08541636b3ae3442b69499614","price":"0.73","side":"SELL","size":"5"}],"timestamp":"1785204817498"},"payload_hash":"2444c727e36417f4d87439733020e564f2aeb3d9dac6498a6a9e38e75e2adf86","raw_frame":"{\"market\":\"0xda6f0e0e93fc8469e0159a166028d017bddbc162b86f66bac90391379603d962\", \"price_changes\":[{\"asset_id\":\"39272994714739463168905443499424551362424437245880253267329605556587274644733\", \"price\":\"0.27\", \"size\":\"5\", \"side\":\"BUY\", \"hash\":\"701d8881f53a34a6fdb0163352ba007db200d193\", \"best_bid\":\"0.27\", \"best_ask\":\"0.28\"}, {\"asset_id\":\"20893381255801015515826997628594359667013752732428989472914000440642900266717\", \"price\":\"0.73\", \"size\":\"5\", \"side\":\"SELL\", \"hash\":\"02a396126c4c26e08541636b3ae3442b69499614\", \"best_bid\":\"0.72\", \"best_ask\":\"0.73\"}], \"timestamp\":\"1785204817498\", \"event_type\":\"price_change\"}","received_at":"2026-07-28T02:13:37.417189Z","schema_version":"clob-market-ws.price_change.v1","sequence":null,"server_hash":null,"server_timestamp":"1785204817498","session_id":"d2757dd6dad94f3b9fe67e8dbf1adc37","source":"clob_market_ws"},"received_at":"2026-07-28T02:13:37.417189Z","record_id":"19926715137337eb7efa71c551e5735c73831e3453a8498745d38060d2e9733c","schema_fingerprint":"4aa3821a28b0b7c2400bc59aba4bcc0a76e971dadd19610d3ad38c768e124dc7","schema_version":"edge-lab-recorder.raw.v1","sequence":null,"source":"clob_market_ws"}
{"event_at":"2026-07-28T02:13:37.513000Z","event_fingerprint":"8019189385307223714c5a7d015d892eaf5186579ef524b549c1b30c9a4b5582","payload":{"connection_id":"5d29200f65794d4d9ab6ef271f045a9b","event_at":"2026-07-28T02:13:37.513000Z","event_type":"best_bid_ask","frame_hash":"7a7439d4c94e826640677711450ffbd5446c89b6091b8da564b93d4b2f0c0396","frame_index":0,"kind":"data","monotonic_ns":306800429837375,"payload":{"asset_id":"20893381255801015515826997628594359667013752732428989472914000440642900266717","best_ask":"0.74","best_bid":"0.72","event_type":"best_bid_ask","market":"0xda6f0e0e93fc8469e0159a166028d017bddbc162b86f66bac90391379603d962","spread":"0.02","timestamp":"1785204817513"},"payload_hash":"f1712194b1ae8fc883e0564a00f342a895f7e52bec340b34015924e4078eac6e","raw_frame":"{\"market\":\"0xda6f0e0e93fc8469e0159a166028d017bddbc162b86f66bac90391379603d962\", \"asset_id\":\"20893381255801015515826997628594359667013752732428989472914000440642900266717\", \"best_bid\":\"0.72\", \"best_ask\":\"0.74\", \"spread\":\"0.02\", \"timestamp\":\"1785204817513\", \"event_type\":\"best_bid_ask\"}","received_at":"2026-07-28T02:13:37.418687Z","schema_version":"clob-market-ws.best_bid_ask.v1","sequence":null,"server_hash":null,"server_timestamp":"1785204817513","session_id":"d2757dd6dad94f3b9fe67e8dbf1adc37","source":"clob_market_ws"},"received_at":"2026-07-28T02:13:37.418687Z","record_id":"3a6395b55375715bcdb8a50b94a446733c37828ddfd2b686f37e62389fd7189c","schema_fingerprint":"8488399f31b0337811b13b266be932db7062827c2470b78bd8e9e99bab51d17d","schema_version":"edge-lab-recorder.raw.v1","sequence":null,"source":"clob_market_ws"}
{"event_at":"2026-07-28T02:13:37.513000Z","event_fingerprint":"cdcfc6eb36eb7ffb44a462a4cc75dd50985949efcc1b583d9e47a7db2c74b33d","payload":{"connection_id":"5d29200f65794d4d9ab6ef271f045a9b","event_at":"2026-07-28T02:13:37.513000Z","event_type":"best_bid_ask","frame_hash":"a3209d02f531ec29f357d29356d8bfea7a12d5b8903a828aff1a133d9f00c31b","frame_index":0,"kind":"data","monotonic_ns":306800430834625,"payload":{"asset_id":"39272994714739463168905443499424551362424437245880253267329605556587274644733","best_ask":"0.28","best_bid":"0.26","event_type":"best_bid_ask","market":"0xda6f0e0e93fc8469e0159a166028d017bddbc162b86f66bac90391379603d962","spread":"0.02","timestamp":"1785204817513"},"payload_hash":"f6cf91b3848807963b12d43d9015fd70c9689a57424434b2b00099f2312f770d","raw_frame":"{\"market\":\"0xda6f0e0e93fc8469e0159a166028d017bddbc162b86f66bac90391379603d962\", \"asset_id\":\"39272994714739463168905443499424551362424437245880253267329605556587274644733\", \"best_bid\":\"0.26\", \"best_ask\":\"0.28\", \"spread\":\"0.02\", \"timestamp\":\"1785204817513\", \"event_type\":\"best_bid_ask\"}","received_at":"2026-07-28T02:13:37.419684Z","schema_version":"clob-market-ws.best_bid_ask.v1","sequence":null,"server_hash":null,"server_timestamp":"1785204817513","session_id":"d2757dd6dad94f3b9fe67e8dbf1adc37","source":"clob_market_ws"},"received_at":"2026-07-28T02:13:37.419684Z","record_id":"7cb86ff210a4b11161fa7235b84ac68cb3b853f80bd355c21270787b5667fb28","schema_fingerprint":"8488399f31b0337811b13b266be932db7062827c2470b78bd8e9e99bab51d17d","schema_version":"edge-lab-recorder.raw.v1","sequence":null,"source":"clob_market_ws"}
{"event_at":"2026-07-28T02:13:37.513000Z","event_fingerprint":"194d9284174b5f1c58aa8555c721ff97fa53d20293b9d81d706559d2a3f34332","payload":{"connection_id":"5d29200f65794d4d9ab6ef271f045a9b","event_at":"2026-07-28T02:13:37.513000Z","event_type":"price_change","frame_hash":"e46655e0ad19e9f239d903276acbf1d4b287e7527604f1d3e86366005ac57a8c","frame_index":0,"kind":"data","monotonic_ns":306800431876500,"payload":{"event_type":"price_change","market":"0xda6f0e0e93fc8469e0159a166028d017bddbc162b86f66bac90391379603d962","price_changes":[{"asset_id":"39272994714739463168905443499424551362424437245880253267329605556587274644733","best_ask":"0.28","best_bid":"0.26","hash":"5a0e64563fc762b337b7a922c63afe91e7625ed9","price":"0.27","side":"BUY","size":"0"},{"asset_id":"20893381255801015515826997628594359667013752732428989472914000440642900266717","best_ask":"0.74","best_bid":"0.72","hash":"6cf4eed2d03f30daf9298999d6f066719360d253","price":"0.73","side":"SELL","size":"0"}],"timestamp":"1785204817513"},"payload_hash":"14dcc26f7d4ad488d108bd446c4ba0db45466e414fdc043c3f64bf86699109f3","raw_frame":"{\"market\":\"0xda6f0e0e93fc8469e0159a166028d017bddbc162b86f66bac90391379603d962\", \"price_changes\":[{\"asset_id\":\"39272994714739463168905443499424551362424437245880253267329605556587274644733\", \"price\":\"0.27\", \"size\":\"0\", \"side\":\"BUY\", \"hash\":\"5a0e64563fc762b337b7a922c63afe91e7625ed9\", \"best_bid\":\"0.26\", \"best_ask\":\"0.28\"}, {\"asset_id\":\"20893381255801015515826997628594359667013752732428989472914000440642900266717\", \"price\":\"0.73\", \"size\":\"0\", \"side\":\"SELL\", \"hash\":\"6cf4eed2d03f30daf9298999d6f066719360d253\", \"best_bid\":\"0.72\", \"best_ask\":\"0.74\"}], \"timestamp\":\"1785204817513\", \"event_type\":\"price_change\"}","received_at":"2026-07-28T02:13:37.420727Z","schema_version":"clob-market-ws.price_change.v1","sequence":null,"server_hash":null,"server_timestamp":"1785204817513","session_id":"d2757dd6dad94f3b9fe67e8dbf1adc37","source":"clob_market_ws"},"received_at":"2026-07-28T02:13:37.420727Z","record_id":"344876f46138f780ec5f2069bdf9a77a96a05fecacdc857e9b1f1649e45bf8a5","schema_fingerprint":"4aa3821a28b0b7c2400bc59aba4bcc0a76e971dadd19610d3ad38c768e124dc7","schema_version":"edge-lab-recorder.raw.v1","sequence":null,"source":"clob_market_ws"}
{"event_at":"2026-07-28T02:13:37.522000Z","event_fingerprint":"d158f29728f2de306ed71eedf596bd9c1165f17a7c5556eb3790ad5b8ad1aca8","payload":{"connection_id":"5d29200f65794d4d9ab6ef271f045a9b","event_at":"2026-07-28T02:13:37.522000Z","event_type":"price_change","frame_hash":"966cad040b6b1003cd5e0738db5a2686a5dec7ca9a871a01809fbb049962df8c","frame_index":0,"kind":"data","monotonic_ns":306800433332083,"payload":{"event_type":"price_change","market":"0xda6f0e0e93fc8469e0159a166028d017bddbc162b86f66bac90391379603d962","price_changes":[{"asset_id":"20893381255801015515826997628594359667013752732428989472914000440642900266717","best_ask":"0.74","best_bid":"0.72","hash":"de475727dcac2e07bac25c97cb687d12712e1dd2","price":"0.72","side":"BUY","size":"105.99"},{"asset_id":"39272994714739463168905443499424551362424437245880253267329605556587274644733","best_ask":"0.28","best_bid":"0.26","hash":"5049c86408c46b84b323b5b9e49eba5f85376a78","price":"0.28","side":"SELL","size":"105.99"}],"timestamp":"1785204817522"},"payload_hash":"78d028b016d68749977aefea0cfc6615b58230899c9c68b501e3fe34216ed7e4","raw_frame":"{\"market\":\"0xda6f0e0e93fc8469e0159a166028d017bddbc162b86f66bac90391379603d962\", \"price_changes\":[{\"asset_id\":\"20893381255801015515826997628594359667013752732428989472914000440642900266717\", \"price\":\"0.72\", \"size\":\"105.99\", \"side\":\"BUY\", \"hash\":\"de475727dcac2e07bac25c97cb687d12712e1dd2\", \"best_bid\":\"0.72\", \"best_ask\":\"0.74\"}, {\"asset_id\":\"39272994714739463168905443499424551362424437245880253267329605556587274644733\", \"price\":\"0.28\", \"size\":\"105.99\", \"side\":\"SELL\", \"hash\":\"5049c86408c46b84b323b5b9e49eba5f85376a78\", \"best_bid\":\"0.26\", \"best_ask\":\"0.28\"}], \"timestamp\":\"1785204817522\", \"event_type\":\"price_change\"}","received_at":"2026-07-28T02:13:37.422181Z","schema_version":"clob-market-ws.price_change.v1","sequence":null,"server_hash":null,"server_timestamp":"1785204817522","session_id":"d2757dd6dad94f3b9fe67e8dbf1adc37","source":"clob_market_ws"},"received_at":"2026-07-28T02:13:37.422181Z","record_id":"ad73bf7cc56e0df96542f636a3e70b27e0d4c60930209b700ae03be4e9c7914f","schema_fingerprint":"4aa3821a28b0b7c2400bc59aba4bcc0a76e971dadd19610d3ad38c768e124dc7","schema_version":"edge-lab-recorder.raw.v1","sequence":null,"source":"clob_market_ws"}
{"event_at":"2026-07-28T02:13:37.531000Z","event_fingerprint":"741b944d9142bab2f4200540a8049ce0bcfcb0f36ee96ceeb16928dbe6cadbd8","payload":{"connection_id":"5d29200f65794d4d9ab6ef271f045a9b","event_at":"2026-07-28T02:13:37.531000Z","event_type":"price_change","frame_hash":"dfb07c43c79df408ca1ff25828ca31f6f152fb3ecc8b6189caa267ab4549aa26","frame_index":0,"kind":"data","monotonic_ns":306800434808375,"payload":{"event_type":"price_change","market":"0xda6f0e0e93fc8469e0159a166028d017bddbc162b86f66bac90391379603d962","price_changes":[{"asset_id":"20893381255801015515826997628594359667013752732428989472914000440642900266717","best_ask":"0.74","best_bid":"0.72","hash":"9de7a916a78d99803a8df0b94bfd11e1e992bff5","price":"0.72","side":"BUY","size":"100.99"},{"asset_id":"39272994714739463168905443499424551362424437245880253267329605556587274644733","best_ask":"0.28","best_bid":"0.26","hash":"2fa56b808ff6c466f63fd9b5cc46459cee201f93","price":"0.28","side":"SELL","size":"100.99"}],"timestamp":"1785204817531"},"payload_hash":"2feaab2b096d48da7c139897a31ba0d7c99ffe3433567f067480f4c8643a2663","raw_frame":"{\"market\":\"0xda6f0e0e93fc8469e0159a166028d017bddbc162b86f66bac90391379603d962\", \"price_changes\":[{\"asset_id\":\"20893381255801015515826997628594359667013752732428989472914000440642900266717\", \"price\":\"0.72\", \"size\":\"100.99\", \"side\":\"BUY\", \"hash\":\"9de7a916a78d99803a8df0b94bfd11e1e992bff5\", \"best_bid\":\"0.72\", \"best_ask\":\"0.74\"}, {\"asset_id\":\"39272994714739463168905443499424551362424437245880253267329605556587274644733\", \"price\":\"0.28\", \"size\":\"100.99\", \"side\":\"SELL\", \"hash\":\"2fa56b808ff6c466f63fd9b5cc46459cee201f93\", \"best_bid\":\"0.26\", \"best_ask\":\"0.28\"}], \"timestamp\":\"1785204817531\", \"event_type\":\"price_change\"}","received_at":"2026-07-28T02:13:37.423658Z","schema_version":"clob-market-ws.price_change.v1","sequence":null,"server_hash":null,"server_timestamp":"1785204817531","session_id":"d2757dd6dad94f3b9fe67e8dbf1adc37","source":"clob_market_ws"},"received_at":"2026-07-28T02:13:37.423658Z","record_id":"3bf9778dc5d13c3ebf3ddfaa33dd9421128ee1371c4deb7c8d1bc661116da68f","schema_fingerprint":"4aa3821a28b0b7c2400bc59aba4bcc0a76e971dadd19610d3ad38c768e124dc7","schema_version":"edge-lab-recorder.raw.v1","sequence":null,"source":"clob_market_ws"}
