{"event_at":"2026-07-28T02:13:12.526000Z","event_fingerprint":"76cbdb96a11e1db3e1b0ceab64b66dac35ead67a4b73dec12b8cb200694384b4","payload":{"connection_id":"5d29200f65794d4d9ab6ef271f045a9b","event_at":"2026-07-28T02:13:12.526000Z","event_type":"price_change","frame_hash":"6089647c9a78b5afb1510d96b029b708faeb6f118897cc5591f5564c20df2a18","frame_index":0,"kind":"data","monotonic_ns":306775547232333,"payload":{"event_type":"price_change","market":"0xda6f0e0e93fc8469e0159a166028d017bddbc162b86f66bac90391379603d962","price_changes":[{"asset_id":"39272994714739463168905443499424551362424437245880253267329605556587274644733","best_ask":"0.28","best_bid":"0.27","hash":"eab9f3e9eccda2e33c379cf6fdc4cc49f24ceafd","price":"0.25","side":"BUY","size":"54"},{"asset_id":"20893381255801015515826997628594359667013752732428989472914000440642900266717","best_ask":"0.73","best_bid":"0.72","hash":"5288277080e46d3a741ff161224484a98a4e4773","price":"0.75","side":"SELL","size":"54"}],"timestamp":"1785204792526"},"payload_hash":"73e1260cea08077f6341c8c8cbaa58beefadf0eb67abaefe711f27c324e68cba","raw_frame":"{\"market\":\"0xda6f0e0e93fc8469e0159a166028d017bddbc162b86f66bac90391379603d962\", \"price_changes\":[{\"asset_id\":\"39272994714739463168905443499424551362424437245880253267329605556587274644733\", \"price\":\"0.25\", \"size\":\"54\", \"side\":\"BUY\", \"hash\":\"eab9f3e9eccda2e33c379cf6fdc4cc49f24ceafd\", \"best_bid\":\"0.27\", \"best_ask\":\"0.28\"}, {\"asset_id\":\"20893381255801015515826997628594359667013752732428989472914000440642900266717\", \"price\":\"0.75\", \"size\":\"54\", \"side\":\"SELL\", \"hash\":\"5288277080e46d3a741ff161224484a98a4e4773\", \"best_bid\":\"0.72\", \"best_ask\":\"0.73\"}], \"timestamp\":\"1785204792526\", \"event_type\":\"price_change\"}","received_at":"2026-07-28T02:13:12.536328Z","schema_version":"clob-market-ws.price_change.v1","sequence":null,"server_hash":null,"server_timestamp":"1785204792526","session_id":"d2757dd6dad94f3b9fe67e8dbf1adc37","source":"clob_market_ws"},"received_at":"2026-07-28T02:13:12.536328Z","record_id":"3f9e04bee36b1e43d301c93b20e3c7b4caf2ed359594119c358b3024fd4b390c","schema_fingerprint":"4aa3821a28b0b7c2400bc59aba4bcc0a76e971dadd19610d3ad38c768e124dc7","schema_version":"edge-lab-recorder.raw.v1","sequence":null,"source":"clob_market_ws"}
{"event_at":"2026-07-28T02:13:12.526000Z","event_fingerprint":"8473611c881bc547bbb58a896153191175b91fc78d4db6a7d5be1633235b0eb8","payload":{"connection_id":"5d29200f65794d4d9ab6ef271f045a9b","event_at":"2026-07-28T02:13:12.526000Z","event_type":"price_change","frame_hash":"28ed4d39d1d39df88d28c6a2ddb3fb7fc622557f750460014218757c9ad3096e","frame_index":0,"kind":"data","monotonic_ns":306775552196000,"payload":{"event_type":"price_change","market":"0xda6f0e0e93fc8469e0159a166028d017bddbc162b86f66bac90391379603d962","price_changes":[{"asset_id":"39272994714739463168905443499424551362424437245880253267329605556587274644733","best_ask":"0.28","best_bid":"0.27","hash":"caf262c58a970370645bf1a1781e90233696f0a0","price":"0.16","side":"BUY","size":"226"},{"asset_id":"20893381255801015515826997628594359667013752732428989472914000440642900266717","best_ask":"0.73","best_bid":"0.72","hash":"a2c61ceb74b4957401ac9d2b3c77281c5b8c2b21","price":"0.84","side":"SELL","size":"226"}],"timestamp":"1785204792526"},"payload_hash":"1ceaf86d1d9d921001e9d997afdf9c34ff2345c542c7904af96bd2017336c88b","raw_frame":"{\"market\":\"0xda6f0e0e93fc8469e0159a166028d017bddbc162b86f66bac90391379603d962\", \"price_changes\":[{\"asset_id\":\"39272994714739463168905443499424551362424437245880253267329605556587274644733\", \"price\":\"0.16\", \"size\":\"226\", \"side\":\"BUY\", \"hash\":\"caf262c58a970370645bf1a1781e90233696f0a0\", \"best_bid\":\"0.27\", \"best_ask\":\"0.28\"}, {\"asset_id\":\"20893381255801015515826997628594359667013752732428989472914000440642900266717\", \"price\":\"0.84\", \"size\":\"226\", \"side\":\"SELL\", \"hash\":\"a2c61ceb74b4957401ac9d2b3c77281c5b8c2b21\", \"best_bid\":\"0.72\", \"best_ask\":\"0.73\"}], \"timestamp\":\"1785204792526\", \"event_type\":\"price_change\"}","received_at":"2026-07-28T02:13:12.541292Z","schema_version":"clob-market-ws.price_change.v1","sequence":null,"server_hash":null,"server_timestamp":"1785204792526","session_id":"d2757dd6dad94f3b9fe67e8dbf1adc37","source":"clob_market_ws"},"received_at":"2026-07-28T02:13:12.541292Z","record_id":"358b056933f87869a9b4c40b88ba57d5d0d472ec32073c12cc8bb08d2b53457e","schema_fingerprint":"4aa3821a28b0b7c2400bc59aba4bcc0a76e971dadd19610d3ad38c768e124dc7","schema_version":"edge-lab-recorder.raw.v1","sequence":null,"source":"clob_market_ws"}
{"event_at":"2026-07-28T02:13:12.528000Z","event_fingerprint":"a610ec8184250dee2096b8bffc8e1e5767ba5e4a6f5be73a696aed03901de84b","payload":{"connection_id":"5d29200f65794d4d9ab6ef271f045a9b","event_at":"2026-07-28T02:13:12.528000Z","event_type":"best_bid_ask","frame_hash":"105bf3ca74d4b6aba2a24eb67e39f2d2f42237bb48657090f62b8b1c203dc9cc","frame_index":0,"kind":"data","monotonic_ns":306775555201791,"payload":{"asset_id":"20893381255801015515826997628594359667013752732428989472914000440642900266717","best_ask":"0.73","best_bid":"0.72","event_type":"best_bid_ask","market":"0xda6f0e0e93fc8469e0159a166028d017bddbc162b86f66bac90391379603d962","spread":"0.01","timestamp":"1785204792528"},"payload_hash":"7a86efa1bc85dcff2317ed3f550141efe177c76166836b8b8ede64a58952139d","raw_frame":"{\"market\":\"0xda6f0e0e93fc8469e0159a166028d017bddbc162b86f66bac90391379603d962\", \"asset_id\":\"20893381255801015515826997628594359667013752732428989472914000440642900266717\", \"best_bid\":\"0.72\", \"best_ask\":\"0.73\", \"spread\":\"0.01\", \"timestamp\":\"1785204792528\", \"event_type\":\"best_bid_ask\"}","received_at":"2026-07-28T02:13:12.544297Z","schema_version":"clob-market-ws.best_bid_ask.v1","sequence":null,"server_hash":null,"server_timestamp":"1785204792528","session_id":"d2757dd6dad94f3b9fe67e8dbf1adc37","source":"clob_market_ws"},"received_at":"2026-07-28T02:13:12.544297Z","record_id":"db8c73059911b0b12a7cf6e7a6412c1f8240c7d9415a616d7e1ff5cca7bd6d9d","schema_fingerprint":"8488399f31b0337811b13b266be932db7062827c2470b78bd8e9e99bab51d17d","schema_version":"edge-lab-recorder.raw.v1","sequence":null,"source":"clob_market_ws"}
{"event_at":"2026-07-28T02:13:12.528000Z","event_fingerprint":"04b1a58defb366187821a3519485a4687d4c1c1dfd5344d5a0eb5ff1053bb88e","payload":{"connection_id":"5d29200f65794d4d9ab6ef271f045a9b","event_at":"2026-07-28T02:13:12.528000Z","event_type":"best_bid_ask","frame_hash":"08bbaa315bbfe89e0e866a741c22f0192ea7ad6138868ca894fe349ca41037b9","frame_index":0,"kind":"data","monotonic_ns":306775557754083,"payload":{"asset_id":"39272994714739463168905443499424551362424437245880253267329605556587274644733","best_ask":"0.28","best_bid":"0.27","event_type":"best_bid_ask","market":"0xda6f0e0e93fc8469e0159a166028d017bddbc162b86f66bac90391379603d962","spread":"0.01","timestamp":"1785204792528"},"payload_hash":"c7ae91902810ff3b213e96d786508832f71c3035dd2ee38c82e39fe25c3373ff","raw_frame":"{\"market\":\"0xda6f0e0e93fc8469e0159a166028d017bddbc162b86f66bac90391379603d962\", \"asset_id\":\"39272994714739463168905443499424551362424437245880253267329605556587274644733\", \"best_bid\":\"0.27\", \"best_ask\":\"0.28\", \"spread\":\"0.01\", \"timestamp\":\"1785204792528\", \"event_type\":\"best_bid_ask\"}","received_at":"2026-07-28T02:13:12.546849Z","schema_version":"clob-market-ws.best_bid_ask.v1","sequence":null,"server_hash":null,"server_timestamp":"1785204792528","session_id":"d2757dd6dad94f3b9fe67e8dbf1adc37","source":"clob_market_ws"},"received_at":"2026-07-28T02:13:12.546849Z","record_id":"266db5243d285fe82a96707e1e27e6bc20bf4661d4775c1433c638f7856d4fd9","schema_fingerprint":"8488399f31b0337811b13b266be932db7062827c2470b78bd8e9e99bab51d17d","schema_version":"edge-lab-recorder.raw.v1","sequence":null,"source":"clob_market_ws"}
{"event_at":"2026-07-28T02:13:12.528000Z","event_fingerprint":"b600e773f0413deafd44822fc843766755e6c3a732e54e272cc7c0f0bfa946aa","payload":{"connection_id":"5d29200f65794d4d9ab6ef271f045a9b","event_at":"2026-07-28T02:13:12.528000Z","event_type":"price_change","frame_hash":"f07f49873096945d4ff02dd58107cd11c392823eecee47e4019d025bdad6ba62","frame_index":0,"kind":"data","monotonic_ns":306775560362416,"payload":{"event_type":"price_change","market":"0xda6f0e0e93fc8469e0159a166028d017bddbc162b86f66bac90391379603d962","price_changes":[{"asset_id":"20893381255801015515826997628594359667013752732428989472914000440642900266717","best_ask":"0.73","best_bid":"0.72","hash":"a07877a63bc650dd110b0ae54135d29c1a647b5e","price":"0.72","side":"BUY","size":"17.98"},{"asset_id":"39272994714739463168905443499424551362424437245880253267329605556587274644733","best_ask":"0.28","best_bid":"0.27","hash":"8586f41a243d5e8478c1d8529b0050bb1f0469cc","price":"0.28","side":"SELL","size":"17.98"}],"timestamp":"1785204792528"},"payload_hash":"e750106e71624874bf1b1e1170c9a179b291407d03a80242f670fbe13782d5df","raw_frame":"{\"market\":\"0xda6f0e0e93fc8469e0159a166028d017bddbc162b86f66bac90391379603d962\", \"price_changes\":[{\"asset_id\":\"20893381255801015515826997628594359667013752732428989472914000440642900266717\", \"price\":\"0.72\", \"size\":\"17.98\", \"side\":\"BUY\", \"hash\":\"a07877a63bc650dd110b0ae54135d29c1a647b5e\", \"best_bid\":\"0.72\", \"best_ask\":\"0.73\"}, {\"asset_id\":\"39272994714739463168905443499424551362424437245880253267329605556587274644733\", \"price\":\"0.28\", \"size\":\"17.98\", \"side\":\"SELL\", \"hash\":\"8586f41a243d5e8478c1d8529b0050bb1f0469cc\", \"best_bid\":\"0.27\", \"best_ask\":\"0.28\"}], \"timestamp\":\"1785204792528\", \"event_type\":\"price_change\"}","received_at":"2026-07-28T02:13:12.549458Z","schema_version":"clob-market-ws.price_change.v1","sequence":null,"server_hash":null,"server_timestamp":"1785204792528","session_id":"d2757dd6dad94f3b9fe67e8dbf1adc37","source":"clob_market_ws"},"received_at":"2026-07-28T02:13:12.549458Z","record_id":"16e79c6f950c3292ed3a9e05dbb241c6f52995170b683c801ad1a16a43b7bea9","schema_fingerprint":"4aa3821a28b0b7c2400bc59aba4bcc0a76e971dadd19610d3ad38c768e124dc7","schema_version":"edge-lab-recorder.raw.v1","sequence":null,"source":"clob_market_ws"}
{"event_at":"2026-07-28T02:13:12.528000Z","event_fingerprint":"c99d25e750f0654f99ee5d2eaa25521c8d044b1c5824df926235d686b9e4bef8","payload":{"connection_id":"5d29200f65794d4d9ab6ef271f045a9b","event_at":"2026-07-28T02:13:12.528000Z","event_type":"book","frame_hash":"bd5e6a51f651187f2f5bcc7e9b5483e06cf5d4e737f66557708b50bed9802649","frame_index":0,"kind":"data","monotonic_ns":306775563399416,"payload":{"asks":[{"price":"0.99","size":"8098.02"},{"price":"0.98","size":"1334"},{"price":"0.97","size":"925"},{"price":"0.96","size":"659.9"},{"price":"0.95","size":"583"},{"price":"0.94","size":"510"},{"price":"0.93","size":"400"},{"price":"0.92","size":"361"},{"price":"0.91","size":"360"},{"price":"0.9","size":"299"},{"price":"0.89","size":"276"},{"price":"0.88","size":"288"},{"price":"0.87","size":"241.98"},{"price":"0.86","size":"210"},{"price":"0.85","size":"235"},{"price":"0.84","size":"226"},{"price":"0.83","size":"55"},{"price":"0.82","size":"83"},{"price":"0.81","size":"58.3"},{"price":"0.8","size":"52"},{"price":"0.79","size":"74"},{"price":"0.78","size":"44"},{"price":"0.77","size":"44"},{"price":"0.75","size":"54"},{"price":"0.74","size":"49"},{"price":"0.73","size":"54"}],"asset_id":"20893381255801015515826997628594359667013752732428989472914000440642900266717","bids":[{"price":"0.01","size":"5374.02"},{"price":"0.02","size":"574"},{"price":"0.03","size":"554"},{"price":"0.04","size":"584"},{"price":"0.05","size":"564"},{"price":"0.06","size":"544"},{"price":"0.07","size":"74"},{"price":"0.08","size":"54"},{"price":"0.09","size":"44"},{"price":"0.1","size":"84"},{"price":"0.11","size":"44"},{"price":"0.12","size":"54"},{"price":"0.13","size":"74"},{"price":"0.14","size":"44"},{"price":"0.15","size":"151"},{"price":"0.16","size":"84"},{"price":"0.17","size":"44"},{"price":"0.18","size":"49.56"},{"price":"0.19","size":"74"},{"price":"0.2","size":"49"},{"price":"0.21","size":"91.61"},{"price":"0.22","size":"74"},{"price":"0.23","size":"44"},{"price":"0.24","size":"44"},{"price":"0.25","size":"79"},{"price":"0.26","size":"44"},{"price":"0.27","size":"44"},{"price":"0.28","size":"74"},{"price":"0.29","size":"44"},{"price":"0.3","size":"44"},{"price":"0.31","size":"74"},{"price":"0.32","size":"45.05"},{"price":"0.33","size":"44"},{"price":"0.34","size":"74"},{"price":"0.35","size":"44"},{"price":"0.36","size":"44"},{"price":"0.37","size":"74"},{"price":"0.38","size":"44"},{"price":"0.39","size":"49"},{"price":"0.4","size":"84"},{"price":"0.41","size":"49"},{"price":"0.42","size":"49"},{"price":"0.43","size":"79"},{"price":"0.44","size":"49"},{"price":"0.45","size":"49"},{"price":"0.46","size":"79"},{"price":"0.47","size":"49"},{"price":"0.48","size":"49"},{"price":"0.49","size":"79"},{"price":"0.5","size":"49"},{"price":"0.51","size":"49"},{"price":"0.52","size":"79"},{"price":"0.53","size":"49"},{"price":"0.54","size":"49"},{"price":"0.55","size":"79"},{"price":"0.56","size":"49"},{"price":"0.57","size":"49"},{"price":"0.58","size":"79"},{"price":"0.59","size":"49"},{"price":"0.6","size":"49"},{"price":"0.61","size":"79"},{"price":"0.62","size":"49"},{"price":"0.63","size":"49"},{"price":"0.64","size":"79"},{"price":"0.65","size":"49"},{"price":"0.66","size":"50"},{"price":"0.67","size":"50"},{"price":"0.68","size":"21"},{"price":"0.72","size":"17.98"}],"event_type":"book","hash":"a07877a63bc650dd110b0ae54135d29c1a647b5e","market":"0xda6f0e0e93fc8469e0159a166028d017bddbc162b86f66bac90391379603d962","timestamp":"1785204792528"},"payload_hash":"05739b921e56890476db1fca193d3efc98dfadc9e473bb5df8303ad4d7996d1a","raw_frame":"{\"market\":\"0xda6f0e0e93fc8469e0159a166028d017bddbc162b86f66bac90391379603d962\", \"asset_id\":\"20893381255801015515826997628594359667013752732428989472914000440642900266717\", \"bids\":[{\"price\":\"0.01\", \"size\":\"5374.02\"}, {\"price\":\"0.02\", \"size\":\"574\"}, {\"price\":\"0.03\", \"size\":\"554\"}, {\"price\":\"0.04\", \"size\":\"584\"}, {\"price\":\"0.05\", \"size\":\"564\"}, {\"price\":\"0.06\", \"size\":\"544\"}, {\"price\":\"0.07\", \"size\":\"74\"}, {\"price\":\"0.08\", \"size\":\"54\"}, {\"price\":\"0.09\", \"size\":\"44\"}, {\"price\":\"0.1\", \"size\":\"84\"}, {\"price\":\"0.11\", \"size\":\"44\"}, {\"price\":\"0.12\", \"size\":\"54\"}, {\"price\":\"0.13\", \"size\":\"74\"}, {\"price\":\"0.14\", \"size\":\"44\"}, {\"price\":\"0.15\", \"size\":\"151\"}, {\"price\":\"0.16\", \"size\":\"84\"}, {\"price\":\"0.17\", \"size\":\"44\"}, {\"price\":\"0.18\", \"size\":\"49.56\"}, {\"price\":\"0.19\", \"size\":\"74\"}, {\"price\":\"0.2\", \"size\":\"49\"}, {\"price\":\"0.21\", \"size\":\"91.61\"}, {\"price\":\"0.22\", \"size\":\"74\"}, {\"price\":\"0.23\", \"size\":\"44\"}, {\"price\":\"0.24\", \"size\":\"44\"}, {\"price\":\"0.25\", \"size\":\"79\"}, {\"price\":\"0.26\", \"size\":\"44\"}, {\"price\":\"0.27\", \"size\":\"44\"}, {\"price\":\"0.28\", \"size\":\"74\"}, {\"price\":\"0.29\", \"size\":\"44\"}, {\"price\":\"0.3\", \"size\":\"44\"}, {\"price\":\"0.31\", \"size\":\"74\"}, {\"price\":\"0.32\", \"size\":\"45.05\"}, {\"price\":\"0.33\", \"size\":\"44\"}, {\"price\":\"0.34\", \"size\":\"74\"}, {\"price\":\"0.35\", \"size\":\"44\"}, {\"price\":\"0.36\", \"size\":\"44\"}, {\"price\":\"0.37\", \"size\":\"74\"}, {\"price\":\"0.38\", \"size\":\"44\"}, {\"price\":\"0.39\", \"size\":\"49\"}, {\"price\":\"0.4\", \"size\":\"84\"}, {\"price\":\"0.41\", \"size\":\"49\"}, {\"price\":\"0.42\", \"size\":\"49\"}, {\"price\":\"0.43\", \"size\":\"79\"}, {\"price\":\"0.44\", \"size\":\"49\"}, {\"price\":\"0.45\", \"size\":\"49\"}, {\"price\":\"0.46\", \"size\":\"79\"}, {\"price\":\"0.47\", \"size\":\"49\"}, {\"price\":\"0.48\", \"size\":\"49\"}, {\"price\":\"0.49\", \"size\":\"79\"}, {\"price\":\"0.5\", \"size\":\"49\"}, {\"price\":\"0.51\", \"size\":\"49\"}, {\"price\":\"0.52\", \"size\":\"79\"}, {\"price\":\"0.53\", \"size\":\"49\"}, {\"price\":\"0.54\", \"size\":\"49\"}, {\"price\":\"0.55\", \"size\":\"79\"}, {\"price\":\"0.56\", \"size\":\"49\"}, {\"price\":\"0.57\", \"size\":\"49\"}, {\"price\":\"0.58\", \"size\":\"79\"}, {\"price\":\"0.59\", \"size\":\"49\"}, {\"price\":\"0.6\", \"size\":\"49\"}, {\"price\":\"0.61\", \"size\":\"79\"}, {\"price\":\"0.62\", \"size\":\"49\"}, {\"price\":\"0.63\", \"size\":\"49\"}, {\"price\":\"0.64\", \"size\":\"79\"}, {\"price\":\"0.65\", \"size\":\"49\"}, {\"price\":\"0.66\", \"size\":\"50\"}, {\"price\":\"0.67\", \"size\":\"50\"}, {\"price\":\"0.68\", \"size\":\"21\"}, {\"price\":\"0.72\", \"size\":\"17.98\"}], \"asks\":[{\"price\":\"0.99\", \"size\":\"8098.02\"}, {\"price\":\"0.98\", \"size\":\"1334\"}, {\"price\":\"0.97\", \"size\":\"925\"}, {\"price\":\"0.96\", \"size\":\"659.9\"}, {\"price\":\"0.95\", \"size\":\"583\"}, {\"price\":\"0.94\", \"size\":\"510\"}, {\"price\":\"0.93\", \"size\":\"400\"}, {\"price\":\"0.92\", \"size\":\"361\"}, {\"price\":\"0.91\", \"size\":\"360\"}, {\"price\":\"0.9\", \"size\":\"299\"}, {\"price\":\"0.89\", \"size\":\"276\"}, {\"price\":\"0.88\", \"size\":\"288\"}, {\"price\":\"0.87\", \"size\":\"241.98\"}, {\"price\":\"0.86\", \"size\":\"210\"}, {\"price\":\"0.85\", \"size\":\"235\"}, {\"price\":\"0.84\", \"size\":\"226\"}, {\"price\":\"0.83\", \"size\":\"55\"}, {\"price\":\"0.82\", \"size\":\"83\"}, {\"price\":\"0.81\", \"size\":\"58.3\"}, {\"price\":\"0.8\", \"size\":\"52\"}, {\"price\":\"0.79\", \"size\":\"74\"}, {\"price\":\"0.78\", \"size\":\"44\"}, {\"price\":\"0.77\", \"size\":\"44\"}, {\"price\":\"0.75\", \"size\":\"54\"}, {\"price\":\"0.74\", \"size\":\"49\"}, {\"price\":\"0.73\", \"size\":\"54\"}], \"hash\":\"a07877a63bc650dd110b0ae54135d29c1a647b5e\", \"timestamp\":\"1785204792528\", \"event_type\":\"book\"}","received_at":"2026-07-28T02:13:12.552493Z","schema_version":"clob-market-ws.book.v1","sequence":null,"server_hash":"a07877a63bc650dd110b0ae54135d29c1a647b5e","server_timestamp":"1785204792528","session_id":"d2757dd6dad94f3b9fe67e8dbf1adc37","source":"clob_market_ws"},"received_at":"2026-07-28T02:13:12.552493Z","record_id":"db64248032b48da43bbac06a106df6845842ef776212380e6405ec4b4f3cba50","schema_fingerprint":"dc2caa1c89c6a7426e2e07ff925910cd4d0a8a223a515d4092d91d6d127aacb6","schema_version":"edge-lab-recorder.raw.v1","sequence":null,"source":"clob_market_ws"}
{"event_at":"2026-07-28T02:13:12.528000Z","event_fingerprint":"26f1adab2231c5daa7361a1957b62d0bc054b16dffbca0934e648873de587b4b","payload":{"connection_id":"5d29200f65794d4d9ab6ef271f045a9b","event_at":"2026-07-28T02:13:12.528000Z","event_type":"book","frame_hash":"1d72bca50fdc543bf5c4dcd05a4519abb738a8d4f656c6cdaeeb7317917df6ed","frame_index":0,"kind":"data","monotonic_ns":306775574626666,"payload":{"asks":[{"price":"0.99","size":"5374.02"},{"price":"0.98","size":"574"},{"price":"0.97","size":"554"},{"price":"0.96","size":"584"},{"price":"0.95","size":"564"},{"price":"0.94","size":"544"},{"price":"0.93","size":"74"},{"price":"0.92","size":"54"},{"price":"0.91","size":"44"},{"price":"0.9","size":"84"},{"price":"0.89","size":"44"},{"price":"0.88","size":"54"},{"price":"0.87","size":"74"},{"price":"0.86","size":"44"},{"price":"0.85","size":"151"},{"price":"0.84","size":"84"},{"price":"0.83","size":"44"},{"price":"0.82","size":"49.56"},{"price":"0.81","size":"74"},{"price":"0.8","size":"49"},{"price":"0.79","size":"91.61"},{"price":"0.78","size":"74"},{"price":"0.77","size":"44"},{"price":"0.76","size":"44"},{"price":"0.75","size":"79"},{"price":"0.74","size":"44"},{"price":"0.73","size":"44"},{"price":"0.72","size":"74"},{"price":"0.71","size":"44"},{"price":"0.7","size":"44"},{"price":"0.69","size":"74"},{"price":"0.68","size":"45.05"},{"price":"0.67","size":"44"},{"price":"0.66","size":"74"},{"price":"0.65","size":"44"},{"price":"0.64","size":"44"},{"price":"0.63","size":"74"},{"price":"0.62","size":"44"},{"price":"0.61","size":"49"},{"price":"0.6","size":"84"},{"price":"0.59","size":"49"},{"price":"0.58","size":"49"},{"price":"0.57","size":"79"},{"price":"0.56","size":"49"},{"price":"0.55","size":"49"},{"price":"0.54","size":"79"},{"price":"0.53","size":"49"},{"price":"0.52","size":"49"},{"price":"0.51","size":"79"},{"price":"0.5","size":"49"},{"price":"0.49","size":"49"},{"price":"0.48","size":"79"},{"price":"0.47","size":"49"},{"price":"0.46","size":"49"},{"price":"0.45","size":"79"},{"price":"0.44","size":"49"},{"price":"0.43","size":"49"},{"price":"0.42","size":"79"},{"price":"0.41","size":"49"},{"price":"0.4","size":"49"},{"price":"0.39","size":"79"},{"price":"0.38","size":"49"},{"price":"0.37","size":"49"},{"price":"0.36","size":"79"},{"price":"0.35","size":"49"},{"price":"0.34","size":"50"},{"price":"0.33","size":"50"},{"price":"0.32","size":"21"},{"price":"0.28","size":"17.98"}],"asset_id":"39272994714739463168905443499424551362424437245880253267329605556587274644733","bids":[{"price":"0.01","size":"8098.02"},{"price":"0.02","size":"1334"},{"price":"0.03","size":"925"},{"price":"0.04","size":"659.9"},{"price":"0.05","size":"583"},{"price":"0.06","size":"510"},{"price":"0.07","size":"400"},{"price":"0.08","size":"361"},{"price":"0.09","size":"360"},{"price":"0.1","size":"299"},{"price":"0.11","size":"276"},{"price":"0.12","size":"288"},{"price":"0.13","size":"241.98"},{"price":"0.14","size":"210"},{"price":"0.15","size":"235"},{"price":"0.16","size":"226"},{"price":"0.17","size":"55"},{"price":"0.18","size":"83"},{"price":"0.19","size":"58.3"},{"price":"0.2","size":"52"},{"price":"0.21","size":"74"},{"price":"0.22","size":"44"},{"price":"0.23","size":"44"},{"price":"0.25","size":"54"},{"price":"0.26","size":"49"},{"price":"0.27","size":"54"}],"event_type":"book","hash":"8586f41a243d5e8478c1d8529b0050bb1f0469cc","market":"0xda6f0e0e93fc8469e0159a166028d017bddbc162b86f66bac90391379603d962","timestamp":"1785204792528"},"payload_hash":"9e04ede906c10a141c7f6f82ad60e3db7a69efd2f8232de51ddd105dbf8059f8","raw_frame":"{\"market\":\"0xda6f0e0e93fc8469e0159a166028d017bddbc162b86f66bac90391379603d962\", \"asset_id\":\"39272994714739463168905443499424551362424437245880253267329605556587274644733\", \"bids\":[{\"price\":\"0.01\", \"size\":\"8098.02\"}, {\"price\":\"0.02\", \"size\":\"1334\"}, {\"price\":\"0.03\", \"size\":\"925\"}, {\"price\":\"0.04\", \"size\":\"659.9\"}, {\"price\":\"0.05\", \"size\":\"583\"}, {\"price\":\"0.06\", \"size\":\"510\"}, {\"price\":\"0.07\", \"size\":\"400\"}, {\"price\":\"0.08\", \"size\":\"361\"}, {\"price\":\"0.09\", \"size\":\"360\"}, {\"price\":\"0.1\", \"size\":\"299\"}, {\"price\":\"0.11\", \"size\":\"276\"}, {\"price\":\"0.12\", \"size\":\"288\"}, {\"price\":\"0.13\", \"size\":\"241.98\"}, {\"price\":\"0.14\", \"size\":\"210\"}, {\"price\":\"0.15\", \"size\":\"235\"}, {\"price\":\"0.16\", \"size\":\"226\"}, {\"price\":\"0.17\", \"size\":\"55\"}, {\"price\":\"0.18\", \"size\":\"83\"}, {\"price\":\"0.19\", \"size\":\"58.3\"}, {\"price\":\"0.2\", \"size\":\"52\"}, {\"price\":\"0.21\", \"size\":\"74\"}, {\"price\":\"0.22\", \"size\":\"44\"}, {\"price\":\"0.23\", \"size\":\"44\"}, {\"price\":\"0.25\", \"size\":\"54\"}, {\"price\":\"0.26\", \"size\":\"49\"}, {\"price\":\"0.27\", \"size\":\"54\"}], \"asks\":[{\"price\":\"0.99\", \"size\":\"5374.02\"}, {\"price\":\"0.98\", \"size\":\"574\"}, {\"price\":\"0.97\", \"size\":\"554\"}, {\"price\":\"0.96\", \"size\":\"584\"}, {\"price\":\"0.95\", \"size\":\"564\"}, {\"price\":\"0.94\", \"size\":\"544\"}, {\"price\":\"0.93\", \"size\":\"74\"}, {\"price\":\"0.92\", \"size\":\"54\"}, {\"price\":\"0.91\", \"size\":\"44\"}, {\"price\":\"0.9\", \"size\":\"84\"}, {\"price\":\"0.89\", \"size\":\"44\"}, {\"price\":\"0.88\", \"size\":\"54\"}, {\"price\":\"0.87\", \"size\":\"74\"}, {\"price\":\"0.86\", \"size\":\"44\"}, {\"price\":\"0.85\", \"size\":\"151\"}, {\"price\":\"0.84\", \"size\":\"84\"}, {\"price\":\"0.83\", \"size\":\"44\"}, {\"price\":\"0.82\", \"size\":\"49.56\"}, {\"price\":\"0.81\", \"size\":\"74\"}, {\"price\":\"0.8\", \"size\":\"49\"}, {\"price\":\"0.79\", \"size\":\"91.61\"}, {\"price\":\"0.78\", \"size\":\"74\"}, {\"price\":\"0.77\", \"size\":\"44\"}, {\"price\":\"0.76\", \"size\":\"44\"}, {\"price\":\"0.75\", \"size\":\"79\"}, {\"price\":\"0.74\", \"size\":\"44\"}, {\"price\":\"0.73\", \"size\":\"44\"}, {\"price\":\"0.72\", \"size\":\"74\"}, {\"price\":\"0.71\", \"size\":\"44\"}, {\"price\":\"0.7\", \"size\":\"44\"}, {\"price\":\"0.69\", \"size\":\"74\"}, {\"price\":\"0.68\", \"size\":\"45.05\"}, {\"price\":\"0.67\", \"size\":\"44\"}, {\"price\":\"0.66\", \"size\":\"74\"}, {\"price\":\"0.65\", \"size\":\"44\"}, {\"price\":\"0.64\", \"size\":\"44\"}, {\"price\":\"0.63\", \"size\":\"74\"}, {\"price\":\"0.62\", \"size\":\"44\"}, {\"price\":\"0.61\", \"size\":\"49\"}, {\"price\":\"0.6\", \"size\":\"84\"}, {\"price\":\"0.59\", \"size\":\"49\"}, {\"price\":\"0.58\", \"size\":\"49\"}, {\"price\":\"0.57\", \"size\":\"79\"}, {\"price\":\"0.56\", \"size\":\"49\"}, {\"price\":\"0.55\", \"size\":\"49\"}, {\"price\":\"0.54\", \"size\":\"79\"}, {\"price\":\"0.53\", \"size\":\"49\"}, {\"price\":\"0.52\", \"size\":\"49\"}, {\"price\":\"0.51\", \"size\":\"79\"}, {\"price\":\"0.5\", \"size\":\"49\"}, {\"price\":\"0.49\", \"size\":\"49\"}, {\"price\":\"0.48\", \"size\":\"79\"}, {\"price\":\"0.47\", \"size\":\"49\"}, {\"price\":\"0.46\", \"size\":\"49\"}, {\"price\":\"0.45\", \"size\":\"79\"}, {\"price\":\"0.44\", \"size\":\"49\"}, {\"price\":\"0.43\", \"size\":\"49\"}, {\"price\":\"0.42\", \"size\":\"79\"}, {\"price\":\"0.41\", \"size\":\"49\"}, {\"price\":\"0.4\", \"size\":\"49\"}, {\"price\":\"0.39\", \"size\":\"79\"}, {\"price\":\"0.38\", \"size\":\"49\"}, {\"price\":\"0.37\", \"size\":\"49\"}, {\"price\":\"0.36\", \"size\":\"79\"}, {\"price\":\"0.35\", \"size\":\"49\"}, {\"price\":\"0.34\", \"size\":\"50\"}, {\"price\":\"0.33\", \"size\":\"50\"}, {\"price\":\"0.32\", \"size\":\"21\"}, {\"price\":\"0.28\", \"size\":\"17.98\"}], \"hash\":\"8586f41a243d5e8478c1d8529b0050bb1f0469cc\", \"timestamp\":\"1785204792528\", \"event_type\":\"book\"}","received_at":"2026-07-28T02:13:12.563722Z","schema_version":"clob-market-ws.book.v1","sequence":null,"server_hash":"8586f41a243d5e8478c1d8529b0050bb1f0469cc","server_timestamp":"1785204792528","session_id":"d2757dd6dad94f3b9fe67e8dbf1adc37","source":"clob_market_ws"},"received_at":"2026-07-28T02:13:12.563722Z","record_id":"02deccbab41bf331448e78c802d64ee672d5912da719195a9907f34e2b642e91","schema_fingerprint":"dc2caa1c89c6a7426e2e07ff925910cd4d0a8a223a515d4092d91d6d127aacb6","schema_version":"edge-lab-recorder.raw.v1","sequence":null,"source":"clob_market_ws"}
{"event_at":"2026-07-28T02:13:12.532000Z","event_fingerprint":"2f347ca57f153a105fd658442a74070cf9f41ffbc8a703bed66f077e01fd989a","payload":{"connection_id":"5d29200f65794d4d9ab6ef271f045a9b","event_at":"2026-07-28T02:13:12.532000Z","event_type":"price_change","frame_hash":"9a2bf87e2e75397d285c9021ee9f7480544e7d6c3198e13cc38e3290985850da","frame_index":0,"kind":"data","monotonic_ns":306775585266083,"payload":{"event_type":"price_change","market":"0xda6f0e0e93fc8469e0159a166028d017bddbc162b86f66bac90391379603d962","price_changes":[{"asset_id":"39272994714739463168905443499424551362424437245880253267329605556587274644733","best_ask":"0.28","best_bid":"0.27","hash":"7c35e3423e9136122bd364aee21742ea1c0358fc","price":"0.04","side":"BUY","size":"1034.9"},{"asset_id":"20893381255801015515826997628594359667013752732428989472914000440642900266717","best_ask":"0.73","best_bid":"0.72","hash":"6ccc81aeaa2ea3208223a636a78c37d9b5017483","price":"0.96","side":"SELL","size":"1034.9"}],"timestamp":"1785204792532"},"payload_hash":"95fa1aa15cb47320d94f6aebffed28c91b8c5df71ff9b98619fbbbb7fd5ddf00","raw_frame":"{\"market\":\"0xda6f0e0e93fc8469e0159a166028d017bddbc162b86f66bac90391379603d962\", \"price_changes\":[{\"asset_id\":\"39272994714739463168905443499424551362424437245880253267329605556587274644733\", \"price\":\"0.04\", \"size\":\"1034.9\", \"side\":\"BUY\", \"hash\":\"7c35e3423e9136122bd364aee21742ea1c0358fc\", \"best_bid\":\"0.27\", \"best_ask\":\"0.28\"}, {\"asset_id\":\"20893381255801015515826997628594359667013752732428989472914000440642900266717\", \"price\":\"0.96\", \"size\":\"1034.9\", \"side\":\"SELL\", \"hash\":\"6ccc81aeaa2ea3208223a636a78c37d9b5017483\", \"best_bid\":\"0.72\", \"best_ask\":\"0.73\"}], \"timestamp\":\"1785204792532\", \"event_type\":\"price_change\"}","received_at":"2026-07-28T02:13:12.574360Z","schema_version":"clob-market-ws.price_change.v1","sequence":null,"server_hash":null,"server_timestamp":"1785204792532","session_id":"d2757dd6dad94f3b9fe67e8dbf1adc37","source":"clob_market_ws"},"received_at":"2026-07-28T02:13:12.574360Z","record_id":"1ef920c189cd1fbed7740d597add5876d56a8854ccf293ea257b445cd88837bd","schema_fingerprint":"4aa3821a28b0b7c2400bc59aba4bcc0a76e971dadd19610d3ad38c768e124dc7","schema_version":"edge-lab-recorder.raw.v1","sequence":null,"source":"clob_market_ws"}
{"event_at":"2026-07-28T02:13:12.533000Z","event_fingerprint":"4b0c5e6fada62bbe28172538ee1a3352c5806eb3bbcc6e875d7670c522258377","payload":{"connection_id":"5d29200f65794d4d9ab6ef271f045a9b","event_at":"2026-07-28T02:13:12.533000Z","event_type":"price_change","frame_hash":"37f95cbd60cd2b31801d569857c06ea16921bee81346b507eba0d975818da68e","frame_index":0,"kind":"data","monotonic_ns":306775589734958,"payload":{"event_type":"price_change","market":"0xda6f0e0e93fc8469e0159a166028d017bddbc162b86f66bac90391379603d962","price_changes":[{"asset_id":"20893381255801015515826997628594359667013752732428989472914000440642900266717","best_ask":"0.73","best_bid":"0.72","hash":"1af763ac9d88fb251495578497f2d23e9cbd40a0","price":"0.28","side":"BUY","size":"188.94"},{"asset_id":"39272994714739463168905443499424551362424437245880253267329605556587274644733","best_ask":"0.28","best_bid":"0.27","hash":"547a9e0c74e2211a37d8d4a6b4fdeb08ac408b3e","price":"0.72","side":"SELL","size":"188.94"}],"timestamp":"1785204792533"},"payload_hash":"dff4aaa8f4d7ce9907a9484037f181765262023d7b8b3f3cb6323a4365f76d8a","raw_frame":"{\"market\":\"0xda6f0e0e93fc8469e0159a166028d017bddbc162b86f66bac90391379603d962\", \"price_changes\":[{\"asset_id\":\"20893381255801015515826997628594359667013752732428989472914000440642900266717\", \"price\":\"0.28\", \"size\":\"188.94\", \"side\":\"BUY\", \"hash\":\"1af763ac9d88fb251495578497f2d23e9cbd40a0\", \"best_bid\":\"0.72\", \"best_ask\":\"0.73\"}, {\"asset_id\":\"39272994714739463168905443499424551362424437245880253267329605556587274644733\", \"price\":\"0.72\", \"size\":\"188.94\", \"side\":\"SELL\", \"hash\":\"547a9e0c74e2211a37d8d4a6b4fdeb08ac408b3e\", \"best_bid\":\"0.27\", \"best_ask\":\"0.28\"}], \"timestamp\":\"1785204792533\", \"event_type\":\"price_change\"}","received_at":"2026-07-28T02:13:12.578830Z","schema_version":"clob-market-ws.price_change.v1","sequence":null,"server_hash":null,"server_timestamp":"1785204792533","session_id":"d2757dd6dad94f3b9fe67e8dbf1adc37","source":"clob_market_ws"},"received_at":"2026-07-28T02:13:12.578830Z","record_id":"f2db2f288ae0db6137cf52e0e23099f6412361713113fc3bd3f180b51d2b03be","schema_fingerprint":"4aa3821a28b0b7c2400bc59aba4bcc0a76e971dadd19610d3ad38c768e124dc7","schema_version":"edge-lab-recorder.raw.v1","sequence":null,"source":"clob_market_ws"}
{"event_at":"2026-07-28T02:13:12.533000Z","event_fingerprint":"e91cf444201c64b10f2038679ac76d6e90bef26f85c2177cfdb9b968e6809af7","payload":{"connection_id":"5d29200f65794d4d9ab6ef271f045a9b","event_at":"2026-07-28T02:13:12.533000Z","event_type":"price_change","frame_hash":"a4c01df86defca4f63983919d29a933e53bbead558f4eab835e9892639c0d979","frame_index":0,"kind":"data","monotonic_ns":306775592289375,"payload":{"event_type":"price_change","market":"0xda6f0e0e93fc8469e0159a166028d017bddbc162b86f66bac90391379603d962","price_changes":[{"asset_id":"39272994714739463168905443499424551362424437245880253267329605556587274644733","best_ask":"0.28","best_bid":"0.27","hash":"f1e48232b840d1e20bd098cead234d55ee98462e","price":"0.48","side":"SELL","size":"89"},{"asset_id":"20893381255801015515826997628594359667013752732428989472914000440642900266717","best_ask":"0.73","best_bid":"0.72","hash":"b8638e839beee9e2f86df7a0537b2f3ba02c1332","price":"0.52","side":"BUY","size":"89"}],"timestamp":"1785204792533"},"payload_hash":"d83d4b8c07d2ae98e21be83a7a2dd393603b6d52c67cdda88fd6856773108ecd","raw_frame":"{\"market\":\"0xda6f0e0e93fc8469e0159a166028d017bddbc162b86f66bac90391379603d962\", \"price_changes\":[{\"asset_id\":\"39272994714739463168905443499424551362424437245880253267329605556587274644733\", \"price\":\"0.48\", \"size\":\"89\", \"side\":\"SELL\", \"hash\":\"f1e48232b840d1e20bd098cead234d55ee98462e\", \"best_bid\":\"0.27\", \"best_ask\":\"0.28\"}, {\"asset_id\":\"20893381255801015515826997628594359667013752732428989472914000440642900266717\", \"price\":\"0.52\", \"size\":\"89\", \"side\":\"BUY\", \"hash\":\"b8638e839beee9e2f86df7a0537b2f3ba02c1332\", \"best_bid\":\"0.72\", \"best_ask\":\"0.73\"}], \"timestamp\":\"1785204792533\", \"event_type\":\"price_change\"}","received_at":"2026-07-28T02:13:12.581385Z","schema_version":"clob-market-ws.price_change.v1","sequence":null,"server_hash":null,"server_timestamp":"1785204792533","session_id":"d2757dd6dad94f3b9fe67e8dbf1adc37","source":"clob_market_ws"},"received_at":"2026-07-28T02:13:12.581385Z","record_id":"443aff3b6a4ff8d8ee7c67a27f49aed321c6ce4b02869fddd79ed13e0f5066f8","schema_fingerprint":"4aa3821a28b0b7c2400bc59aba4bcc0a76e971dadd19610d3ad38c768e124dc7","schema_version":"edge-lab-recorder.raw.v1","sequence":null,"source":"clob_market_ws"}
{"event_at":"2026-07-28T02:13:12.534000Z","event_fingerprint":"4d9c0901a288ac9c6601f451d3ded835f807e2fda7ed6198417465c0597d7448","payload":{"connection_id":"5d29200f65794d4d9ab6ef271f045a9b","event_at":"2026-07-28T02:13:12.534000Z","event_type":"price_change","frame_hash":"742fcb522ddbf06412f6c35aa58f0423d10fcb4223edca05d199ebf067764a80","frame_index":0,"kind":"data","monotonic_ns":306775594835333,"payload":{"event_type":"price_change","market":"0xda6f0e0e93fc8469e0159a166028d017bddbc162b86f66bac90391379603d962","price_changes":[{"asset_id":"20893381255801015515826997628594359667013752732428989472914000440642900266717","best_ask":"0.73","best_bid":"0.72","hash":"7121698e263943a179bd5a03e4de2971ac5fe7ec","price":"0.01","side":"BUY","size":"5379.02"},{"asset_id":"39272994714739463168905443499424551362424437245880253267329605556587274644733","best_ask":"0.28","best_bid":"0.27","hash":"71fb5fd981039e21d2591aecf5b2b22d0d09495f","price":"0.99","side":"SELL","size":"5379.02"}],"timestamp":"1785204792534"},"payload_hash":"e6aa5c587323313b094770e3c49135dff1cc0fb3a0c543300a198f1c7ab8e0e5","raw_frame":"{\"market\":\"0xda6f0e0e93fc8469e0159a166028d017bddbc162b86f66bac90391379603d962\", \"price_changes\":[{\"asset_id\":\"20893381255801015515826997628594359667013752732428989472914000440642900266717\", \"price\":\"0.01\", \"size\":\"5379.02\", \"side\":\"BUY\", \"hash\":\"7121698e263943a179bd5a03e4de2971ac5fe7ec\", \"best_bid\":\"0.72\", \"best_ask\":\"0.73\"}, {\"asset_id\":\"39272994714739463168905443499424551362424437245880253267329605556587274644733\", \"price\":\"0.99\", \"size\":\"5379.02\", \"side\":\"SELL\", \"hash\":\"71fb5fd981039e21d2591aecf5b2b22d0d09495f\", \"best_bid\":\"0.27\", \"best_ask\":\"0.28\"}], \"timestamp\":\"1785204792534\", \"event_type\":\"price_change\"}","received_at":"2026-07-28T02:13:12.583931Z","schema_version":"clob-market-ws.price_change.v1","sequence":null,"server_hash":null,"server_timestamp":"1785204792534","session_id":"d2757dd6dad94f3b9fe67e8dbf1adc37","source":"clob_market_ws"},"received_at":"2026-07-28T02:13:12.583931Z","record_id":"0264905237dfd3ceb8b15d61c7c20aecf6a1e4c261ddfaf714de53127c54a2d3","schema_fingerprint":"4aa3821a28b0b7c2400bc59aba4bcc0a76e971dadd19610d3ad38c768e124dc7","schema_version":"edge-lab-recorder.raw.v1","sequence":null,"source":"clob_market_ws"}
{"event_at":"2026-07-28T02:13:12.535000Z","event_fingerprint":"a2080f16f8848c22fcd8150edd4532ded2444de538f8f594750786072603278e","payload":{"connection_id":"5d29200f65794d4d9ab6ef271f045a9b","event_at":"2026-07-28T02:13:12.535000Z","event_type":"price_change","frame_hash":"e23b4904e45393ee0340b055d7ed553dd6a2af35e0b38811057de44a8ca158d6","frame_index":0,"kind":"data","monotonic_ns":306775597794083,"payload":{"event_type":"price_change","market":"0xda6f0e0e93fc8469e0159a166028d017bddbc162b86f66bac90391379603d962","price_changes":[{"asset_id":"39272994714739463168905443499424551362424437245880253267329605556587274644733","best_ask":"0.28","best_bid":"0.27","hash":"549c4ec6d4e82da79379e5fdfb623694d7cf664b","price":"0.28","side":"SELL","size":"96.45"},{"asset_id":"20893381255801015515826997628594359667013752732428989472914000440642900266717","best_ask":"0.73","best_bid":"0.72","hash":"f7bedc5c59ca47e2c25191ea13071c9e2714dada","price":"0.72","side":"BUY","size":"96.45"}],"timestamp":"1785204792535"},"payload_hash":"b857d1288aab98dc35e8c72c08d0e84c4096f1c44e566f3d89458ff78577ed46","raw_frame":"{\"market\":\"0xda6f0e0e93fc8469e0159a166028d017bddbc162b86f66bac90391379603d962\", \"price_changes\":[{\"asset_id\":\"39272994714739463168905443499424551362424437245880253267329605556587274644733\", \"price\":\"0.28\", \"size\":\"96.45\", \"side\":\"SELL\", \"hash\":\"549c4ec6d4e82da79379e5fdfb623694d7cf664b\", \"best_bid\":\"0.27\", \"best_ask\":\"0.28\"}, {\"asset_id\":\"20893381255801015515826997628594359667013752732428989472914000440642900266717\", \"price\":\"0.72\", \"size\":\"96.45\", \"side\":\"BUY\", \"hash\":\"f7bedc5c59ca47e2c25191ea13071c9e2714dada\", \"best_bid\":\"0.72\", \"best_ask\":\"0.73\"}], \"timestamp\":\"1785204792535\", \"event_type\":\"price_change\"}","received_at":"2026-07-28T02:13:12.586889Z","schema_version":"clob-market-ws.price_change.v1","sequence":null,"server_hash":null,"server_timestamp":"1785204792535","session_id":"d2757dd6dad94f3b9fe67e8dbf1adc37","source":"clob_market_ws"},"received_at":"2026-07-28T02:13:12.586889Z","record_id":"143b4a5c955b1c8d7308adda5978e55029ae4ab8bab8be59616b176bfd0b2e29","schema_fingerprint":"4aa3821a28b0b7c2400bc59aba4bcc0a76e971dadd19610d3ad38c768e124dc7","schema_version":"edge-lab-recorder.raw.v1","sequence":null,"source":"clob_market_ws"}
{"event_at":"2026-07-28T02:13:12.544000Z","event_fingerprint":"f9277cd51e46ee4dc91ea502c481143ebef32612786271a557326f9c8a2041f1","payload":{"connection_id":"5d29200f65794d4d9ab6ef271f045a9b","event_at":"2026-07-28T02:13:12.544000Z","event_type":"price_change","frame_hash":"09f2ddb7d6a40b6ad0417447314291d3262e811c12d2559d10d762ea9cc39c3d","frame_index":0,"kind":"data","monotonic_ns":306775600712750,"payload":{"event_type":"price_change","market":"0xda6f0e0e93fc8469e0159a166028d017bddbc162b86f66bac90391379603d962","price_changes":[{"asset_id":"39272994714739463168905443499424551362424437245880253267329605556587274644733","best_ask":"0.28","best_bid":"0.27","hash":"7ea3bee8c7a8891bc4d8cb3f347d0c81f64a77e5","price":"0.17","side":"BUY","size":"77"},{"asset_id":"20893381255801015515826997628594359667013752732428989472914000440642900266717","best_ask":"0.73","best_bid":"0.72","hash":"194e90dc9bcd66e6a4b2ade40bed60999bb1abf5","price":"0.83","side":"SELL","size":"77"}],"timestamp":"1785204792544"},"payload_hash":"cf312e8317ebe9281fc3b1908b07a32650d9c55ac34ba16933b34e20153e25d6","raw_frame":"{\"market\":\"0xda6f0e0e93fc8469e0159a166028d017bddbc162b86f66bac90391379603d962\", \"price_changes\":[{\"asset_id\":\"39272994714739463168905443499424551362424437245880253267329605556587274644733\", \"price\":\"0.17\", \"size\":\"77\", \"side\":\"BUY\", \"hash\":\"7ea3bee8c7a8891bc4d8cb3f347d0c81f64a77e5\", \"best_bid\":\"0.27\", \"best_ask\":\"0.28\"}, {\"asset_id\":\"20893381255801015515826997628594359667013752732428989472914000440642900266717\", \"price\":\"0.83\", \"size\":\"77\", \"side\":\"SELL\", \"hash\":\"194e90dc9bcd66e6a4b2ade40bed60999bb1abf5\", \"best_bid\":\"0.72\", \"best_ask\":\"0.73\"}], \"timestamp\":\"1785204792544\", \"event_type\":\"price_change\"}","received_at":"2026-07-28T02:13:12.589809Z","schema_version":"clob-market-ws.price_change.v1","sequence":null,"server_hash":null,"server_timestamp":"1785204792544","session_id":"d2757dd6dad94f3b9fe67e8dbf1adc37","source":"clob_market_ws"},"received_at":"2026-07-28T02:13:12.589809Z","record_id":"1cd1cd8d3b30f40a6aa85e5ede645199644c973adc852b3465c57f3a838b366b","schema_fingerprint":"4aa3821a28b0b7c2400bc59aba4bcc0a76e971dadd19610d3ad38c768e124dc7","schema_version":"edge-lab-recorder.raw.v1","sequence":null,"source":"clob_market_ws"}
{"event_at":"2026-07-28T02:13:12.546000Z","event_fingerprint":"a4ca843998174dedfc7b75581bbb34fb8cd8b04fb9bb5fb0482fb6b941f4a8b7","payload":{"connection_id":"5d29200f65794d4d9ab6ef271f045a9b","event_at":"2026-07-28T02:13:12.546000Z","event_type":"price_change","frame_hash":"75043f5eec193b25790dff6afc56fde3c8f89f0b5c7173d3d11d3046da1dffcb","frame_index":0,"kind":"data","monotonic_ns":306775603616958,"payload":{"event_type":"price_change","market":"0xda6f0e0e93fc8469e0159a166028d017bddbc162b86f66bac90391379603d962","price_changes":[{"asset_id":"39272994714739463168905443499424551362424437245880253267329605556587274644733","best_ask":"0.28","best_bid":"0.27","hash":"3ddc0dc64e8cc2fec41171105252a2a869d4c4dd","price":"0.16","side":"BUY","size":"256"},{"asset_id":"20893381255801015515826997628594359667013752732428989472914000440642900266717","best_ask":"0.73","best_bid":"0.72","hash":"0807e9085835e2fe83bd58c9ba889339f53b5bea","price":"0.84","side":"SELL","size":"256"}],"timestamp":"1785204792546"},"payload_hash":"89832a44d6651d1f2436b679eb3a3868dd82842e622b1613f14c9294341bea8d","raw_frame":"{\"market\":\"0xda6f0e0e93fc8469e0159a166028d017bddbc162b86f66bac90391379603d962\", \"price_changes\":[{\"asset_id\":\"39272994714739463168905443499424551362424437245880253267329605556587274644733\", \"price\":\"0.16\", \"size\":\"256\", \"side\":\"BUY\", \"hash\":\"3ddc0dc64e8cc2fec41171105252a2a869d4c4dd\", \"best_bid\":\"0.27\", \"best_ask\":\"0.28\"}, {\"asset_id\":\"20893381255801015515826997628594359667013752732428989472914000440642900266717\", \"price\":\"0.84\", \"size\":\"256\", \"side\":\"SELL\", \"hash\":\"0807e9085835e2fe83bd58c9ba889339f53b5bea\", \"best_bid\":\"0.72\", \"best_ask\":\"0.73\"}], \"timestamp\":\"1785204792546\", \"event_type\":\"price_change\"}","received_at":"2026-07-28T02:13:12.592712Z","schema_version":"clob-market-ws.price_change.v1","sequence":null,"server_hash":null,"server_timestamp":"1785204792546","session_id":"d2757dd6dad94f3b9fe67e8dbf1adc37","source":"clob_market_ws"},"received_at":"2026-07-28T02:13:12.592712Z","record_id":"82f21b4a981faa876c5b32744ad21ef145a0566ee2756fe907fffda04f826586","schema_fingerprint":"4aa3821a28b0b7c2400bc59aba4bcc0a76e971dadd19610d3ad38c768e124dc7","schema_version":"edge-lab-recorder.raw.v1","sequence":null,"source":"clob_market_ws"}
{"event_at":"2026-07-28T02:13:12.547000Z","event_fingerprint":"30a553d28e733c820dea76e7340e7cd9721b7b52c2efe6fc90526894fc402420","payload":{"connection_id":"5d29200f65794d4d9ab6ef271f045a9b","event_at":"2026-07-28T02:13:12.547000Z","event_type":"price_change","frame_hash":"29e6acc78a024d4bcb68796cc7c6324a2c72dbab1bc3490a748f253490975c21","frame_index":0,"kind":"data","monotonic_ns":306775606611166,"payload":{"event_type":"price_change","market":"0xda6f0e0e93fc8469e0159a166028d017bddbc162b86f66bac90391379603d962","price_changes":[{"asset_id":"39272994714739463168905443499424551362424437245880253267329605556587274644733","best_ask":"0.28","best_bid":"0.27","hash":"95bad78985c341b2112a3cd39a1bbf5e6bfb83dd","price":"0.16","side":"BUY","size":"226"},{"asset_id":"20893381255801015515826997628594359667013752732428989472914000440642900266717","best_ask":"0.73","best_bid":"0.72","hash":"ecf2f972d56fe14d138221b3ada76a6692e1773a","price":"0.84","side":"SELL","size":"226"}],"timestamp":"1785204792547"},"payload_hash":"a04d4c35af242ad317bb251c34fe1734dd88de944e20cfdbaef9c738c5be90a8","raw_frame":"{\"market\":\"0xda6f0e0e93fc8469e0159a166028d017bddbc162b86f66bac90391379603d962\", \"price_changes\":[{\"asset_id\":\"39272994714739463168905443499424551362424437245880253267329605556587274644733\", \"price\":\"0.16\", \"size\":\"226\", \"side\":\"BUY\", \"hash\":\"95bad78985c341b2112a3cd39a1bbf5e6bfb83dd\", \"best_bid\":\"0.27\", \"best_ask\":\"0.28\"}, {\"asset_id\":\"20893381255801015515826997628594359667013752732428989472914000440642900266717\", \"price\":\"0.84\", \"size\":\"226\", \"side\":\"SELL\", \"hash\":\"ecf2f972d56fe14d138221b3ada76a6692e1773a\", \"best_bid\":\"0.72\", \"best_ask\":\"0.73\"}], \"timestamp\":\"1785204792547\", \"event_type\":\"price_change\"}","received_at":"2026-07-28T02:13:12.595707Z","schema_version":"clob-market-ws.price_change.v1","sequence":null,"server_hash":null,"server_timestamp":"1785204792547","session_id":"d2757dd6dad94f3b9fe67e8dbf1adc37","source":"clob_market_ws"},"received_at":"2026-07-28T02:13:12.595707Z","record_id":"6cec026664c37b2c6d07c0cc3403cbb0e6d7c4144912bbfea2966f8d247b0058","schema_fingerprint":"4aa3821a28b0b7c2400bc59aba4bcc0a76e971dadd19610d3ad38c768e124dc7","schema_version":"edge-lab-recorder.raw.v1","sequence":null,"source":"clob_market_ws"}
{"event_at":"2026-07-28T02:13:12.550000Z","event_fingerprint":"d87be4a5af6489691199c212b80490814aaf632c5f2cdd7644fa09443172af6a","payload":{"connection_id":"5d29200f65794d4d9ab6ef271f045a9b","event_at":"2026-07-28T02:13:12.550000Z","event_type":"price_change","frame_hash":"4869a0c96d3f02d105793db112451cf871f945ec31d2e89725a453a2ade14ee9","frame_index":0,"kind":"data","monotonic_ns":306775609528541,"payload":{"event_type":"price_change","market":"0xda6f0e0e93fc8469e0159a166028d017bddbc162b86f66bac90391379603d962","price_changes":[{"asset_id":"20893381255801015515826997628594359667013752732428989472914000440642900266717","best_ask":"0.73","best_bid":"0.72","hash":"f87d7a0fddbdfd934e9e0cb281f9ff6534232e33","price":"0.59","side":"BUY","size":"79"},{"asset_id":"39272994714739463168905443499424551362424437245880253267329605556587274644733","best_ask":"0.28","best_bid":"0.27","hash":"300395365af0437ae598945a9fa20772da8b00b3","price":"0.41","side":"SELL","size":"79"}],"timestamp":"1785204792550"},"payload_hash":"87122d76dbc09d576785be2c3ff17f00e9c190b52b96e8711be5513cb76ae52b","raw_frame":"{\"market\":\"0xda6f0e0e93fc8469e0159a166028d017bddbc162b86f66bac90391379603d962\", \"price_changes\":[{\"asset_id\":\"20893381255801015515826997628594359667013752732428989472914000440642900266717\", \"price\":\"0.59\", \"size\":\"79\", \"side\":\"BUY\", \"hash\":\"f87d7a0fddbdfd934e9e0cb281f9ff6534232e33\", \"best_bid\":\"0.72\", \"best_ask\":\"0.73\"}, {\"asset_id\":\"39272994714739463168905443499424551362424437245880253267329605556587274644733\", \"price\":\"0.41\", \"size\":\"79\", \"side\":\"SELL\", \"hash\":\"300395365af0437ae598945a9fa20772da8b00b3\", \"best_bid\":\"0.27\", \"best_ask\":\"0.28\"}], \"timestamp\":\"1785204792550\", \"event_type\":\"price_change\"}","received_at":"2026-07-28T02:13:12.598624Z","schema_version":"clob-market-ws.price_change.v1","sequence":null,"server_hash":null,"server_timestamp":"1785204792550","session_id":"d2757dd6dad94f3b9fe67e8dbf1adc37","source":"clob_market_ws"},"received_at":"2026-07-28T02:13:12.598624Z","record_id":"c17c6e9778157e5a96640d43fb1e898427d78d0536c2990133d2e5e59adeac79","schema_fingerprint":"4aa3821a28b0b7c2400bc59aba4bcc0a76e971dadd19610d3ad38c768e124dc7","schema_version":"edge-lab-recorder.raw.v1","sequence":null,"source":"clob_market_ws"}
{"event_at":"2026-07-28T02:13:12.552000Z","event_fingerprint":"1cac612ea3bb8b39faac7695e0c330827e2f9e03bb228de1b718675c16bf06c3","payload":{"connection_id":"5d29200f65794d4d9ab6ef271f045a9b","event_at":"2026-07-28T02:13:12.552000Z","event_type":"price_change","frame_hash":"3d4a848be35b3bceede26cbd57862c8436b7579c68ee3a6c6c99d3425bdc88f9","frame_index":0,"kind":"data","monotonic_ns":306775612435166,"payload":{"event_type":"price_change","market":"0xda6f0e0e93fc8469e0159a166028d017bddbc162b86f66bac90391379603d962","price_changes":[{"asset_id":"39272994714739463168905443499424551362424437245880253267329605556587274644733","best_ask":"0.28","best_bid":"0.27","hash":"278fc6b156814a574c5b85d3bf7d739abad8f047","price":"0.26","side":"BUY","size":"74"},{"asset_id":"20893381255801015515826997628594359667013752732428989472914000440642900266717","best_ask":"0.73","best_bid":"0.72","hash":"59b720f61adb1d5cb261c345800cd4db2b4ac3e8","price":"0.74","side":"SELL","size":"74"}],"timestamp":"1785204792552"},"payload_hash":"04e5d365be6fd372847e8415f718a7132dc01310c1a25001dc1e9ad329014e09","raw_frame":"{\"market\":\"0xda6f0e0e93fc8469e0159a166028d017bddbc162b86f66bac90391379603d962\", \"price_changes\":[{\"asset_id\":\"39272994714739463168905443499424551362424437245880253267329605556587274644733\", \"price\":\"0.26\", \"size\":\"74\", \"side\":\"BUY\", \"hash\":\"278fc6b156814a574c5b85d3bf7d739abad8f047\", \"best_bid\":\"0.27\", \"best_ask\":\"0.28\"}, {\"asset_id\":\"20893381255801015515826997628594359667013752732428989472914000440642900266717\", \"price\":\"0.74\", \"size\":\"74\", \"side\":\"SELL\", \"hash\":\"59b720f61adb1d5cb261c345800cd4db2b4ac3e8\", \"best_bid\":\"0.72\", \"best_ask\":\"0.73\"}], \"timestamp\":\"1785204792552\", \"event_type\":\"price_change\"}","received_at":"2026-07-28T02:13:12.601531Z","schema_version":"clob-market-ws.price_change.v1","sequence":null,"server_hash":null,"server_timestamp":"1785204792552","session_id":"d2757dd6dad94f3b9fe67e8dbf1adc37","source":"clob_market_ws"},"received_at":"2026-07-28T02:13:12.601531Z","record_id":"60296e8dceb89271c2008e5032ad69b9c66aca1339d5a0a9116eacffdce42eae","schema_fingerprint":"4aa3821a28b0b7c2400bc59aba4bcc0a76e971dadd19610d3ad38c768e124dc7","schema_version":"edge-lab-recorder.raw.v1","sequence":null,"source":"clob_market_ws"}
{"event_at":"2026-07-28T02:13:12.553000Z","event_fingerprint":"e2e2c64b9a70cbd40185f931b574a80c43edf635106fb43322dedaaefd1af04d","payload":{"connection_id":"5d29200f65794d4d9ab6ef271f045a9b","event_at":"2026-07-28T02:13:12.553000Z","event_type":"price_change","frame_hash":"b85bbce6f1705c2bca8f0e08c1abbbbb8168340fffaf1f1e5f8964bdc53b05db","frame_index":0,"kind":"data","monotonic_ns":306775613705833,"payload":{"event_type":"price_change","market":"0xda6f0e0e93fc8469e0159a166028d017bddbc162b86f66bac90391379603d962","price_changes":[{"asset_id":"39272994714739463168905443499424551362424437245880253267329605556587274644733","best_ask":"0.28","best_bid":"0.27","hash":"aa774581fac6269e839a394768753ee8fcaedf1f","price":"0.27","side":"BUY","size":"25"},{"asset_id":"20893381255801015515826997628594359667013752732428989472914000440642900266717","best_ask":"0.73","best_bid":"0.72","hash":"3461822102ff9f86f1937bb5feb30ae733bd1aec","price":"0.73","side":"SELL","size":"25"}],"timestamp":"1785204792553"},"payload_hash":"5957f5aada8079d96e1bb3f06bc0e726103dd8441ed2caf2a0bc5743fb62ef90","raw_frame":"{\"market\":\"0xda6f0e0e93fc8469e0159a166028d017bddbc162b86f66bac90391379603d962\", \"price_changes\":[{\"asset_id\":\"39272994714739463168905443499424551362424437245880253267329605556587274644733\", \"price\":\"0.27\", \"size\":\"25\", \"side\":\"BUY\", \"hash\":\"aa774581fac6269e839a394768753ee8fcaedf1f\", \"best_bid\":\"0.27\", \"best_ask\":\"0.28\"}, {\"asset_id\":\"20893381255801015515826997628594359667013752732428989472914000440642900266717\", \"price\":\"0.73\", \"size\":\"25\", \"side\":\"SELL\", \"hash\":\"3461822102ff9f86f1937bb5feb30ae733bd1aec\", \"best_bid\":\"0.72\", \"best_ask\":\"0.73\"}], \"timestamp\":\"1785204792553\", \"event_type\":\"price_change\"}","received_at":"2026-07-28T02:13:12.602807Z","schema_version":"clob-market-ws.price_change.v1","sequence":null,"server_hash":null,"server_timestamp":"1785204792553","session_id":"d2757dd6dad94f3b9fe67e8dbf1adc37","source":"clob_market_ws"},"received_at":"2026-07-28T02:13:12.602807Z","record_id":"f4614826105244c7f9b1870ff45d1378dccc0ce074a1d8d2f4574dced59b36f8","schema_fingerprint":"4aa3821a28b0b7c2400bc59aba4bcc0a76e971dadd19610d3ad38c768e124dc7","schema_version":"edge-lab-recorder.raw.v1","sequence":null,"source":"clob_market_ws"}
{"event_at":"2026-07-28T02:13:12.553000Z","event_fingerprint":"9620e87b842fa99d0a2987dd9f55d1e93788244b270c8a3a5dab37aa9f2b68a1","payload":{"connection_id":"5d29200f65794d4d9ab6ef271f045a9b","event_at":"2026-07-28T02:13:12.553000Z","event_type":"price_change","frame_hash":"820142247481cb50050a00fe607344edbaf38ba78291829e2bd6fe0fbc22fbd8","frame_index":0,"kind":"data","monotonic_ns":306775614976041,"payload":{"event_type":"price_change","market":"0xda6f0e0e93fc8469e0159a166028d017bddbc162b86f66bac90391379603d962","price_changes":[{"asset_id":"20893381255801015515826997628594359667013752732428989472914000440642900266717","best_ask":"0.73","best_bid":"0.72","hash":"88eea33b9e842cfc6ea6762a6ed8b983658b25fa","price":"0.01","side":"BUY","size":"5374.02"},{"asset_id":"39272994714739463168905443499424551362424437245880253267329605556587274644733","best_ask":"0.28","best_bid":"0.27","hash":"8d6d86fd1aacc8e8e61da525fbe04dd3ffd4b33e","price":"0.99","side":"SELL","size":"5374.02"}],"timestamp":"1785204792553"},"payload_hash":"26969fdf8f1cdd3b108a469b060ffb8e4597d337c0d0067ca875ec79b836a5d7","raw_frame":"{\"market\":\"0xda6f0e0e93fc8469e0159a166028d017bddbc162b86f66bac90391379603d962\", \"price_changes\":[{\"asset_id\":\"20893381255801015515826997628594359667013752732428989472914000440642900266717\", \"price\":\"0.01\", \"size\":\"5374.02\", \"side\":\"BUY\", \"hash\":\"88eea33b9e842cfc6ea6762a6ed8b983658b25fa\", \"best_bid\":\"0.72\", \"best_ask\":\"0.73\"}, {\"asset_id\":\"39272994714739463168905443499424551362424437245880253267329605556587274644733\", \"price\":\"0.99\", \"size\":\"5374.02\", \"side\":\"SELL\", \"hash\":\"8d6d86fd1aacc8e8e61da525fbe04dd3ffd4b33e\", \"best_bid\":\"0.27\", \"best_ask\":\"0.28\"}], \"timestamp\":\"1785204792553\", \"event_type\":\"price_change\"}","received_at":"2026-07-28T02:13:12.604071Z","schema_version":"clob-market-ws.price_change.v1","sequence":null,"server_hash":null,"server_timestamp":"1785204792553","session_id":"d2757dd6dad94f3b9fe67e8dbf1adc37","source":"clob_market_ws"},"received_at":"2026-07-28T02:13:12.604071Z","record_id":"d70828930f1d5520eb1c80c23c7bd2ffab420c856ccbca172cb77d2a4f32dbfe","schema_fingerprint":"4aa3821a28b0b7c2400bc59aba4bcc0a76e971dadd19610d3ad38c768e124dc7","schema_version":"edge-lab-recorder.raw.v1","sequence":null,"source":"clob_market_ws"}
{"event_at":"2026-07-28T02:13:12.560000Z","event_fingerprint":"45d3fea44f3b8bf40e401d7b6ef291471ed2ec9eac8a863516bfb21197df9db3","payload":{"connection_id":"5d29200f65794d4d9ab6ef271f045a9b","event_at":"2026-07-28T02:13:12.560000Z","event_type":"price_change","frame_hash":"6677dd742c82e9132dc1230657792a25aa08185c05383b61cbb3218ea143a94e","frame_index":0,"kind":"data","monotonic_ns":306775617959375,"payload":{"event_type":"price_change","market":"0xda6f0e0e93fc8469e0159a166028d017bddbc162b86f66bac90391379603d962","price_changes":[{"asset_id":"39272994714739463168905443499424551362424437245880253267329605556587274644733","best_ask":"0.28","best_bid":"0.27","hash":"646cb81a29326c96f0b70c8c3b82f0f7c9c7879f","price":"0.25","side":"BUY","size":"44"},{"asset_id":"20893381255801015515826997628594359667013752732428989472914000440642900266717","best_ask":"0.73","best_bid":"0.72","hash":"a43b84e4fd0d889f7d58b9dc3ea8bb215d73fa5f","price":"0.75","side":"SELL","size":"44"}],"timestamp":"1785204792560"},"payload_hash":"2416ee5590eb8f16d71ddff74d74bb2a054172f61687a38be3d71581667d6f5f","raw_frame":"{\"market\":\"0xda6f0e0e93fc8469e0159a166028d017bddbc162b86f66bac90391379603d962\", \"price_changes\":[{\"asset_id\":\"39272994714739463168905443499424551362424437245880253267329605556587274644733\", \"price\":\"0.25\", \"size\":\"44\", \"side\":\"BUY\", \"hash\":\"646cb81a29326c96f0b70c8c3b82f0f7c9c7879f\", \"best_bid\":\"0.27\", \"best_ask\":\"0.28\"}, {\"asset_id\":\"20893381255801015515826997628594359667013752732428989472914000440642900266717\", \"price\":\"0.75\", \"size\":\"44\", \"side\":\"SELL\", \"hash\":\"a43b84e4fd0d889f7d58b9dc3ea8bb215d73fa5f\", \"best_bid\":\"0.72\", \"best_ask\":\"0.73\"}], \"timestamp\":\"1785204792560\", \"event_type\":\"price_change\"}","received_at":"2026-07-28T02:13:12.607054Z","schema_version":"clob-market-ws.price_change.v1","sequence":null,"server_hash":null,"server_timestamp":"1785204792560","session_id":"d2757dd6dad94f3b9fe67e8dbf1adc37","source":"clob_market_ws"},"received_at":"2026-07-28T02:13:12.607054Z","record_id":"04458ad3c93c0e7f2b5951b12b11ceeba74a1648e2250cfd52db788eed52b384","schema_fingerprint":"4aa3821a28b0b7c2400bc59aba4bcc0a76e971dadd19610d3ad38c768e124dc7","schema_version":"edge-lab-recorder.raw.v1","sequence":null,"source":"clob_market_ws"}
{"event_at":"2026-07-28T02:13:12.561000Z","event_fingerprint":"c086ce978a38c81fa315230638d0c92b32d4020fb82aaf8bdd76f4b372562b63","payload":{"connection_id":"5d29200f65794d4d9ab6ef271f045a9b","event_at":"2026-07-28T02:13:12.561000Z","event_type":"price_change","frame_hash":"ac7a6ad3a7223180e1489958a200e5eb695c1b91cfbb98ba747f0f7b7387ff8b","frame_index":0,"kind":"data","monotonic_ns":306775620012958,"payload":{"event_type":"price_change","market":"0xda6f0e0e93fc8469e0159a166028d017bddbc162b86f66bac90391379603d962","price_changes":[{"asset_id":"39272994714739463168905443499424551362424437245880253267329605556587274644733","best_ask":"0.28","best_bid":"0.27","hash":"41647a610e446c74e011cc94b11895a591a22ea8","price":"0.18","side":"BUY","size":"96.46"},{"asset_id":"20893381255801015515826997628594359667013752732428989472914000440642900266717","best_ask":"0.73","best_bid":"0.72","hash":"541f7dfa6ffa90288798f9a824c6a60508f15d1a","price":"0.82","side":"SELL","size":"96.46"}],"timestamp":"1785204792561"},"payload_hash":"71530105a21896b8307d6cc05954fb3143834504829dcb22980c2244fca0ff8d","raw_frame":"{\"market\":\"0xda6f0e0e93fc8469e0159a166028d017bddbc162b86f66bac90391379603d962\", \"price_changes\":[{\"asset_id\":\"39272994714739463168905443499424551362424437245880253267329605556587274644733\", \"price\":\"0.18\", \"size\":\"96.46\", \"side\":\"BUY\", \"hash\":\"41647a610e446c74e011cc94b11895a591a22ea8\", \"best_bid\":\"0.27\", \"best_ask\":\"0.28\"}, {\"asset_id\":\"20893381255801015515826997628594359667013752732428989472914000440642900266717\", \"price\":\"0.82\", \"size\":\"96.46\", \"side\":\"SELL\", \"hash\":\"541f7dfa6ffa90288798f9a824c6a60508f15d1a\", \"best_bid\":\"0.72\", \"best_ask\":\"0.73\"}], \"timestamp\":\"1785204792561\", \"event_type\":\"price_change\"}","received_at":"2026-07-28T02:13:12.609109Z","schema_version":"clob-market-ws.price_change.v1","sequence":null,"server_hash":null,"server_timestamp":"1785204792561","session_id":"d2757dd6dad94f3b9fe67e8dbf1adc37","source":"clob_market_ws"},"received_at":"2026-07-28T02:13:12.609109Z","record_id":"eaccdc47095ee2a7be5ba260d2b4cf5c9dd2ab3d2dfc53c98d0391874658febc","schema_fingerprint":"4aa3821a28b0b7c2400bc59aba4bcc0a76e971dadd19610d3ad38c768e124dc7","schema_version":"edge-lab-recorder.raw.v1","sequence":null,"source":"clob_market_ws"}
{"event_at":"2026-07-28T02:13:12.562000Z","event_fingerprint":"85567dca853fcf46775bee7a366c11c32e78faaf603ae4f0e66f057eb855fcae","payload":{"connection_id":"5d29200f65794d4d9ab6ef271f045a9b","event_at":"2026-07-28T02:13:12.562000Z","event_type":"price_change","frame_hash":"6cfde6cffe03c12d3240824d5056167ffea6ba40ffc6d2b3d8bc83358f579367","frame_index":0,"kind":"data","monotonic_ns":306775622156791,"payload":{"event_type":"price_change","market":"0xda6f0e0e93fc8469e0159a166028d017bddbc162b86f66bac90391379603d962","price_changes":[{"asset_id":"20893381255801015515826997628594359667013752732428989472914000440642900266717","best_ask":"0.73","best_bid":"0.72","hash":"009075c5c8993ce3d9d63ff656c412284054a8ec","price":"0.71","side":"BUY","size":"17"},{"asset_id":"39272994714739463168905443499424551362424437245880253267329605556587274644733","best_ask":"0.28","best_bid":"0.27","hash":"eeead7408179c91d49e0dbed6b28d0faa1ac22ed","price":"0.29","side":"SELL","size":"17"}],"timestamp":"1785204792562"},"payload_hash":"8d3e67057e3b9810d8036c4c31b4f1b0d91f47e74fd9127ef1b6966dc094e7d5","raw_frame":"{\"market\":\"0xda6f0e0e93fc8469e0159a166028d017bddbc162b86f66bac90391379603d962\", \"price_changes\":[{\"asset_id\":\"20893381255801015515826997628594359667013752732428989472914000440642900266717\", \"price\":\"0.71\", \"size\":\"17\", \"side\":\"BUY\", \"hash\":\"009075c5c8993ce3d9d63ff656c412284054a8ec\", \"best_bid\":\"0.72\", \"best_ask\":\"0.73\"}, {\"asset_id\":\"39272994714739463168905443499424551362424437245880253267329605556587274644733\", \"price\":\"0.29\", \"size\":\"17\", \"side\":\"SELL\", \"hash\":\"eeead7408179c91d49e0dbed6b28d0faa1ac22ed\", \"best_bid\":\"0.27\", \"best_ask\":\"0.28\"}], \"timestamp\":\"1785204792562\", \"event_type\":\"price_change\"}","received_at":"2026-07-28T02:13:12.611251Z","schema_version":"clob-market-ws.price_change.v1","sequence":null,"server_hash":null,"server_timestamp":"1785204792562","session_id":"d2757dd6dad94f3b9fe67e8dbf1adc37","source":"clob_market_ws"},"received_at":"2026-07-28T02:13:12.611251Z","record_id":"de06dba4ac2a2ff125952aa246b94048721d1e0b8bc3c18e22e1eb86e0f719a1","schema_fingerprint":"4aa3821a28b0b7c2400bc59aba4bcc0a76e971dadd19610d3ad38c768e124dc7","schema_version":"edge-lab-recorder.raw.v1","sequence":null,"source":"clob_market_ws"}
{"event_at":"2026-07-28T02:13:12.563000Z","event_fingerprint":"bdaffc7125583016a5f71c66c20efe4c8a59ee7bb6037168ae74f90fde5a6fc3","payload":{"connection_id":"5d29200f65794d4d9ab6ef271f045a9b","event_at":"2026-07-28T02:13:12.563000Z","event_type":"price_change","frame_hash":"f20fd259a51281dddabb723ea4ef7b3c47e0549ed141f3a6c7fd644916d1146c","frame_index":0,"kind":"data","monotonic_ns":306775624732375,"payload":{"event_type":"price_change","market":"0xda6f0e0e93fc8469e0159a166028d017bddbc162b86f66bac90391379603d962","price_changes":[{"asset_id":"39272994714739463168905443499424551362424437245880253267329605556587274644733","best_ask":"0.28","best_bid":"0.27","hash":"628f796091282c07590f9652acb211d46c796d64","price":"0.18","side":"BUY","size":"107.99"},{"asset_id":"20893381255801015515826997628594359667013752732428989472914000440642900266717","best_ask":"0.73","best_bid":"0.72","hash":"213a65499e6246699c6536800fe9b6e6120ffee9","price":"0.82","side":"SELL","size":"107.99"}],"timestamp":"1785204792563"},"payload_hash":"f80c0081c5bb55f78aba8df72a8b54177cc5dac5faabf26770cde9e37b04d699","raw_frame":"{\"market\":\"0xda6f0e0e93fc8469e0159a166028d017bddbc162b86f66bac90391379603d962\", \"price_changes\":[{\"asset_id\":\"39272994714739463168905443499424551362424437245880253267329605556587274644733\", \"price\":\"0.18\", \"size\":\"107.99\", \"side\":\"BUY\", \"hash\":\"628f796091282c07590f9652acb211d46c796d64\", \"best_bid\":\"0.27\", \"best_ask\":\"0.28\"}, {\"asset_id\":\"20893381255801015515826997628594359667013752732428989472914000440642900266717\", \"price\":\"0.82\", \"size\":\"107.99\", \"side\":\"SELL\", \"hash\":\"213a65499e6246699c6536800fe9b6e6120ffee9\", \"best_bid\":\"0.72\", \"best_ask\":\"0.73\"}], \"timestamp\":\"1785204792563\", \"event_type\":\"price_change\"}","received_at":"2026-07-28T02:13:12.613828Z","schema_version":"clob-market-ws.price_change.v1","sequence":null,"server_hash":null,"server_timestamp":"1785204792563","session_id":"d2757dd6dad94f3b9fe67e8dbf1adc37","source":"clob_market_ws"},"received_at":"2026-07-28T02:13:12.613828Z","record_id":"39e4d55f3b87acf9c5b1c6fdbe9acd4bc5c35500dc338a301e010689c446d318","schema_fingerprint":"4aa3821a28b0b7c2400bc59aba4bcc0a76e971dadd19610d3ad38c768e124dc7","schema_version":"edge-lab-recorder.raw.v1","sequence":null,"source":"clob_market_ws"}
{"event_at":"2026-07-28T02:13:12.565000Z","event_fingerprint":"fbcd10cd4ad702e01dc04df273e2ebf58638d2b00a7f804a6c1a0af69289c20b","payload":{"connection_id":"5d29200f65794d4d9ab6ef271f045a9b","event_at":"2026-07-28T02:13:12.565000Z","event_type":"price_change","frame_hash":"e3bbe1714e1e9889a3df9afb7c1530a9fb02bed226c909f4773c34f53de5d5ce","frame_index":0,"kind":"data","monotonic_ns":306775627725166,"payload":{"event_type":"price_change","market":"0xda6f0e0e93fc8469e0159a166028d017bddbc162b86f66bac90391379603d962","price_changes":[{"asset_id":"20893381255801015515826997628594359667013752732428989472914000440642900266717","best_ask":"0.73","best_bid":"0.72","hash":"1d13efbb323bf20d92ec3e6c24b4cd4d72c46e1e","price":"0.01","side":"BUY","size":"5379.02"},{"asset_id":"39272994714739463168905443499424551362424437245880253267329605556587274644733","best_ask":"0.28","best_bid":"0.27","hash":"32f0ec6318f42e0a39b921274d530065eb8d381e","price":"0.99","side":"SELL","size":"5379.02"}],"timestamp":"1785204792565"},"payload_hash":"c750aef51e38d7086027d7b5777bbe9f36f088c9e902f3097d6f0dd1ddd2b3a9","raw_frame":"{\"market\":\"0xda6f0e0e93fc8469e0159a166028d017bddbc162b86f66bac90391379603d962\", \"price_changes\":[{\"asset_id\":\"20893381255801015515826997628594359667013752732428989472914000440642900266717\", \"price\":\"0.01\", \"size\":\"5379.02\", \"side\":\"BUY\", \"hash\":\"1d13efbb323bf20d92ec3e6c24b4cd4d72c46e1e\", \"best_bid\":\"0.72\", \"best_ask\":\"0.73\"}, {\"asset_id\":\"39272994714739463168905443499424551362424437245880253267329605556587274644733\", \"price\":\"0.99\", \"size\":\"5379.02\", \"side\":\"SELL\", \"hash\":\"32f0ec6318f42e0a39b921274d530065eb8d381e\", \"best_bid\":\"0.27\", \"best_ask\":\"0.28\"}], \"timestamp\":\"1785204792565\", \"event_type\":\"price_change\"}","received_at":"2026-07-28T02:13:12.616820Z","schema_version":"clob-market-ws.price_change.v1","sequence":null,"server_hash":null,"server_timestamp":"1785204792565","session_id":"d2757dd6dad94f3b9fe67e8dbf1adc37","source":"clob_market_ws"},"received_at":"2026-07-28T02:13:12.616820Z","record_id":"218165a1c01d9f1fc95702567e5e248d01c8f1f7febe4177bfaf66a6c8d1a42d","schema_fingerprint":"4aa3821a28b0b7c2400bc59aba4bcc0a76e971dadd19610d3ad38c768e124dc7","schema_version":"edge-lab-recorder.raw.v1","sequence":null,"source":"clob_market_ws"}
{"event_at":"2026-07-28T02:13:12.568000Z","event_fingerprint":"4066b0ffdb786cd492adec7a2b02998a416ec2dd0e447e48cbb6215dbe83ee26","payload":{"connection_id":"5d29200f65794d4d9ab6ef271f045a9b","event_at":"2026-07-28T02:13:12.568000Z","event_type":"price_change","frame_hash":"6a0056c10934f3ff78e2c2a4747f4bf826778f4f654f051b88bf083b6ff651d2","frame_index":0,"kind":"data","monotonic_ns":306775630596125,"payload":{"event_type":"price_change","market":"0xda6f0e0e93fc8469e0159a166028d017bddbc162b86f66bac90391379603d962","price_changes":[{"asset_id":"39272994714739463168905443499424551362424437245880253267329605556587274644733","best_ask":"0.28","best_bid":"0.27","hash":"7f4b9e91461a53b802a1109553d8b33e81ab1e3c","price":"0.16","side":"BUY","size":"196"},{"asset_id":"20893381255801015515826997628594359667013752732428989472914000440642900266717","best_ask":"0.73","best_bid":"0.72","hash":"8fb47933f0099fac2fea49de7077ca30460ee8b9","price":"0.84","side":"SELL","size":"196"}],"timestamp":"1785204792568"},"payload_hash":"d4bed254ee3d59c459842baf99ef205b10d5f8a4d62d11d6cf91d0dccdefbe2e","raw_frame":"{\"market\":\"0xda6f0e0e93fc8469e0159a166028d017bddbc162b86f66bac90391379603d962\", \"price_changes\":[{\"asset_id\":\"39272994714739463168905443499424551362424437245880253267329605556587274644733\", \"price\":\"0.16\", \"size\":\"196\", \"side\":\"BUY\", \"hash\":\"7f4b9e91461a53b802a1109553d8b33e81ab1e3c\", \"best_bid\":\"0.27\", \"best_ask\":\"0.28\"}, {\"asset_id\":\"20893381255801015515826997628594359667013752732428989472914000440642900266717\", \"price\":\"0.84\", \"size\":\"196\", \"side\":\"SELL\", \"hash\":\"8fb47933f0099fac2fea49de7077ca30460ee8b9\", \"best_bid\":\"0.72\", \"best_ask\":\"0.73\"}], \"timestamp\":\"1785204792568\", \"event_type\":\"price_change\"}","received_at":"2026-07-28T02:13:12.619691Z","schema_version":"clob-market-ws.price_change.v1","sequence":null,"server_hash":null,"server_timestamp":"1785204792568","session_id":"d2757dd6dad94f3b9fe67e8dbf1adc37","source":"clob_market_ws"},"received_at":"2026-07-28T02:13:12.619691Z","record_id":"e82ae6ff592660eb31a34cac63dba23a98e07f91ef8725d778c1d29a89948ae6","schema_fingerprint":"4aa3821a28b0b7c2400bc59aba4bcc0a76e971dadd19610d3ad38c768e124dc7","schema_version":"edge-lab-recorder.raw.v1","sequence":null,"source":"clob_market_ws"}
{"event_at":"2026-07-28T02:13:12.571000Z","event_fingerprint":"cb24ea9c1c9d44665292f5b2250f6a713b9af348e114278201a896c14d02d53b","payload":{"connection_id":"5d29200f65794d4d9ab6ef271f045a9b","event_at":"2026-07-28T02:13:12.571000Z","event_type":"price_change","frame_hash":"8687dbbdaa41e457c0b72a6cdcbb2e6c017e4543c423f94a7c67ce8cd1c274af","frame_index":0,"kind":"data","monotonic_ns":306775633112541,"payload":{"event_type":"price_change","market":"0xda6f0e0e93fc8469e0159a166028d017bddbc162b86f66bac90391379603d962","price_changes":[{"asset_id":"20893381255801015515826997628594359667013752732428989472914000440642900266717","best_ask":"0.73","best_bid":"0.72","hash":"5ddda9eeb15b459cbda3d1ea7eddd0366624aca4","price":"0.7","side":"BUY","size":"17"},{"asset_id":"39272994714739463168905443499424551362424437245880253267329605556587274644733","best_ask":"0.28","best_bid":"0.27","hash":"01447a6a37bcdf7b11953fcbf1ba20cb62763e97","price":"0.3","side":"SELL","size":"17"}],"timestamp":"1785204792571"},"payload_hash":"972708a09dd1db466f1e5fdf5a22ee363b546f2eea32a671261012c532809abf","raw_frame":"{\"market\":\"0xda6f0e0e93fc8469e0159a166028d017bddbc162b86f66bac90391379603d962\", \"price_changes\":[{\"asset_id\":\"20893381255801015515826997628594359667013752732428989472914000440642900266717\", \"price\":\"0.7\", \"size\":\"17\", \"side\":\"BUY\", \"hash\":\"5ddda9eeb15b459cbda3d1ea7eddd0366624aca4\", \"best_bid\":\"0.72\", \"best_ask\":\"0.73\"}, {\"asset_id\":\"39272994714739463168905443499424551362424437245880253267329605556587274644733\", \"price\":\"0.3\", \"size\":\"17\", \"side\":\"SELL\", \"hash\":\"01447a6a37bcdf7b11953fcbf1ba20cb62763e97\", \"best_bid\":\"0.27\", \"best_ask\":\"0.28\"}], \"timestamp\":\"1785204792571\", \"event_type\":\"price_change\"}","received_at":"2026-07-28T02:13:12.622214Z","schema_version":"clob-market-ws.price_change.v1","sequence":null,"server_hash":null,"server_timestamp":"1785204792571","session_id":"d2757dd6dad94f3b9fe67e8dbf1adc37","source":"clob_market_ws"},"received_at":"2026-07-28T02:13:12.622214Z","record_id":"ba70baf6e5a353380a6242a667511077249c5c772d2996687dececcde5dddc03","schema_fingerprint":"4aa3821a28b0b7c2400bc59aba4bcc0a76e971dadd19610d3ad38c768e124dc7","schema_version":"edge-lab-recorder.raw.v1","sequence":null,"source":"clob_market_ws"}
{"event_at":"2026-07-28T02:13:12.574000Z","event_fingerprint":"9c71518c2a3098f7cc0e62034df972e0f02da045f70e1e2f966510c0ec3e77cf","payload":{"connection_id":"5d29200f65794d4d9ab6ef271f045a9b","event_at":"2026-07-28T02:13:12.574000Z","event_type":"price_change","frame_hash":"2d1599665dc17ccb7f83341bd2e2dbe4ff5d3d43bdf43b0489a991bd24a00cc1","frame_index":0,"kind":"data","monotonic_ns":306775634746791,"payload":{"event_type":"price_change","market":"0xda6f0e0e93fc8469e0159a166028d017bddbc162b86f66bac90391379603d962","price_changes":[{"asset_id":"39272994714739463168905443499424551362424437245880253267329605556587274644733","best_ask":"0.28","best_bid":"0.27","hash":"6a0ac5428d4114ce9d55e1cb2d287db1dc25578b","price":"0.26","side":"BUY","size":"49"},{"asset_id":"20893381255801015515826997628594359667013752732428989472914000440642900266717","best_ask":"0.73","best_bid":"0.72","hash":"51cfb9fac2ffb60e120afb7385f6aa82835b5f39","price":"0.74","side":"SELL","size":"49"}],"timestamp":"1785204792574"},"payload_hash":"b55a0809d870b7563e9ea995d8fd65339edd8c7e0815f1d14a82d12ac1f7e29e","raw_frame":"{\"market\":\"0xda6f0e0e93fc8469e0159a166028d017bddbc162b86f66bac90391379603d962\", \"price_changes\":[{\"asset_id\":\"39272994714739463168905443499424551362424437245880253267329605556587274644733\", \"price\":\"0.26\", \"size\":\"49\", \"side\":\"BUY\", \"hash\":\"6a0ac5428d4114ce9d55e1cb2d287db1dc25578b\", \"best_bid\":\"0.27\", \"best_ask\":\"0.28\"}, {\"asset_id\":\"20893381255801015515826997628594359667013752732428989472914000440642900266717\", \"price\":\"0.74\", \"size\":\"49\", \"side\":\"SELL\", \"hash\":\"51cfb9fac2ffb60e120afb7385f6aa82835b5f39\", \"best_bid\":\"0.72\", \"best_ask\":\"0.73\"}], \"timestamp\":\"1785204792574\", \"event_type\":\"price_change\"}","received_at":"2026-07-28T02:13:12.623842Z","schema_version":"clob-market-ws.price_change.v1","sequence":null,"server_hash":null,"server_timestamp":"1785204792574","session_id":"d2757dd6dad94f3b9fe67e8dbf1adc37","source":"clob_market_ws"},"received_at":"2026-07-28T02:13:12.623842Z","record_id":"d1f1ebd8f21ad792a8616e149052d7f24e55dd0a6621a23decfb19dc07c70abe","schema_fingerprint":"4aa3821a28b0b7c2400bc59aba4bcc0a76e971dadd19610d3ad38c768e124dc7","schema_version":"edge-lab-recorder.raw.v1","sequence":null,"source":"clob_market_ws"}
{"event_at":"2026-07-28T02:13:12.578000Z","event_fingerprint":"88258723a626c201381250f85c51bee7d13e232e6c1002d6fb5c22c2e443ae82","payload":{"connection_id":"5d29200f65794d4d9ab6ef271f045a9b","event_at":"2026-07-28T02:13:12.578000Z","event_type":"price_change","frame_hash":"dc26447eea7dd1d19b9acbc4cb9f1f5e643152c58ea1a127ca24b44e75b91e37","frame_index":0,"kind":"data","monotonic_ns":306775637677291,"payload":{"event_type":"price_change","market":"0xda6f0e0e93fc8469e0159a166028d017bddbc162b86f66bac90391379603d962","price_changes":[{"asset_id":"20893381255801015515826997628594359667013752732428989472914000440642900266717","best_ask":"0.73","best_bid":"0.72","hash":"8edc9b0fed5ba6671f9ec06edf1531087de5c5fa","price":"0.03","side":"BUY","size":"559"},{"asset_id":"39272994714739463168905443499424551362424437245880253267329605556587274644733","best_ask":"0.28","best_bid":"0.27","hash":"7dcd8c4f0febb16f2cce5e8276c77d513a9546d3","price":"0.97","side":"SELL","size":"559"}],"timestamp":"1785204792578"},"payload_hash":"70bb5e76e1d037788cab3ea5ed40d5d5ab999a4f5ef872804438a63428a7d741","raw_frame":"{\"market\":\"0xda6f0e0e93fc8469e0159a166028d017bddbc162b86f66bac90391379603d962\", \"price_changes\":[{\"asset_id\":\"20893381255801015515826997628594359667013752732428989472914000440642900266717\", \"price\":\"0.03\", \"size\":\"559\", \"side\":\"BUY\", \"hash\":\"8edc9b0fed5ba6671f9ec06edf1531087de5c5fa\", \"best_bid\":\"0.72\", \"best_ask\":\"0.73\"}, {\"asset_id\":\"39272994714739463168905443499424551362424437245880253267329605556587274644733\", \"price\":\"0.97\", \"size\":\"559\", \"side\":\"SELL\", \"hash\":\"7dcd8c4f0febb16f2cce5e8276c77d513a9546d3\", \"best_bid\":\"0.27\", \"best_ask\":\"0.28\"}], \"timestamp\":\"1785204792578\", \"event_type\":\"price_change\"}","received_at":"2026-07-28T02:13:12.626772Z","schema_version":"clob-market-ws.price_change.v1","sequence":null,"server_hash":null,"server_timestamp":"1785204792578","session_id":"d2757dd6dad94f3b9fe67e8dbf1adc37","source":"clob_market_ws"},"received_at":"2026-07-28T02:13:12.626772Z","record_id":"83ebca6c2ebff94458948032b9b22f3167f75df749d377d127c3325af2d7a877","schema_fingerprint":"4aa3821a28b0b7c2400bc59aba4bcc0a76e971dadd19610d3ad38c768e124dc7","schema_version":"edge-lab-recorder.raw.v1","sequence":null,"source":"clob_market_ws"}
{"event_at":"2026-07-28T02:13:12.579000Z","event_fingerprint":"16e286267896651476d2e267a25c75cf5a5230faa59ea12609c0cd10479af1ec","payload":{"connection_id":"5d29200f65794d4d9ab6ef271f045a9b","event_at":"2026-07-28T02:13:12.579000Z","event_type":"price_change","frame_hash":"04c83d7ae317b05c30143ba569fc0056c0edddc12c6f0c0931d9a95553386c74","frame_index":0,"kind":"data","monotonic_ns":306775640628666,"payload":{"event_type":"price_change","market":"0xda6f0e0e93fc8469e0159a166028d017bddbc162b86f66bac90391379603d962","price_changes":[{"asset_id":"39272994714739463168905443499424551362424437245880253267329605556587274644733","best_ask":"0.28","best_bid":"0.27","hash":"c66b74be388deedde0161c7434d4f6bc3e00c511","price":"0.16","side":"BUY","size":"226"},{"asset_id":"20893381255801015515826997628594359667013752732428989472914000440642900266717","best_ask":"0.73","best_bid":"0.72","hash":"f22670d0c887dbc32531be16276ccf00d881dbd5","price":"0.84","side":"SELL","size":"226"}],"timestamp":"1785204792579"},"payload_hash":"cd8835ffaa78997bf33b7eeb14df9b5cd9cedfaa83d34f3c382994c9960b4920","raw_frame":"{\"market\":\"0xda6f0e0e93fc8469e0159a166028d017bddbc162b86f66bac90391379603d962\", \"price_changes\":[{\"asset_id\":\"39272994714739463168905443499424551362424437245880253267329605556587274644733\", \"price\":\"0.16\", \"size\":\"226\", \"side\":\"BUY\", \"hash\":\"c66b74be388deedde0161c7434d4f6bc3e00c511\", \"best_bid\":\"0.27\", \"best_ask\":\"0.28\"}, {\"asset_id\":\"20893381255801015515826997628594359667013752732428989472914000440642900266717\", \"price\":\"0.84\", \"size\":\"226\", \"side\":\"SELL\", \"hash\":\"f22670d0c887dbc32531be16276ccf00d881dbd5\", \"best_bid\":\"0.72\", \"best_ask\":\"0.73\"}], \"timestamp\":\"1785204792579\", \"event_type\":\"price_change\"}","received_at":"2026-07-28T02:13:12.629722Z","schema_version":"clob-market-ws.price_change.v1","sequence":null,"server_hash":null,"server_timestamp":"1785204792579","session_id":"d2757dd6dad94f3b9fe67e8dbf1adc37","source":"clob_market_ws"},"received_at":"2026-07-28T02:13:12.629722Z","record_id":"16fd5415fe9af23f087c29023b42d6cb347876d53bfd924305d1959f6c348c9d","schema_fingerprint":"4aa3821a28b0b7c2400bc59aba4bcc0a76e971dadd19610d3ad38c768e124dc7","schema_version":"edge-lab-recorder.raw.v1","sequence":null,"source":"clob_market_ws"}
{"event_at":"2026-07-28T02:13:12.590000Z","event_fingerprint":"42df6fa943519669d384f519058d389172718ccd4ff56b9432f7307f8d73e25a","payload":{"connection_id":"5d29200f65794d4d9ab6ef271f045a9b","event_at":"2026-07-28T02:13:12.590000Z","event_type":"price_change","frame_hash":"2a48c166d38cc3f8486da59cf05d1f8e9f34f19561008c0f56e15f8c92a40e97","frame_index":0,"kind":"data","monotonic_ns":306775643576458,"payload":{"event_type":"price_change","market":"0xda6f0e0e93fc8469e0159a166028d017bddbc162b86f66bac90391379603d962","price_changes":[{"asset_id":"39272994714739463168905443499424551362424437245880253267329605556587274644733","best_ask":"0.28","best_bid":"0.27","hash":"9c7b50394737e4a4c5ba466c4641a2ea9c9631dc","price":"0.26","side":"BUY","size":"54"},{"asset_id":"20893381255801015515826997628594359667013752732428989472914000440642900266717","best_ask":"0.73","best_bid":"0.72","hash":"a234323b7edffb04b9aacfdd633c57f5501dd79e","price":"0.74","side":"SELL","size":"54"}],"timestamp":"1785204792590"},"payload_hash":"6e5de745c402f08c69eca6c3ee43e572cdbe69d6ae4ffac5cd5c530355a20396","raw_frame":"{\"market\":\"0xda6f0e0e93fc8469e0159a166028d017bddbc162b86f66bac90391379603d962\", \"price_changes\":[{\"asset_id\":\"39272994714739463168905443499424551362424437245880253267329605556587274644733\", \"price\":\"0.26\", \"size\":\"54\", \"side\":\"BUY\", \"hash\":\"9c7b50394737e4a4c5ba466c4641a2ea9c9631dc\", \"best_bid\":\"0.27\", \"best_ask\":\"0.28\"}, {\"asset_id\":\"20893381255801015515826997628594359667013752732428989472914000440642900266717\", \"price\":\"0.74\", \"size\":\"54\", \"side\":\"SELL\", \"hash\":\"a234323b7edffb04b9aacfdd633c57f5501dd79e\", \"best_bid\":\"0.72\", \"best_ask\":\"0.73\"}], \"timestamp\":\"1785204792590\", \"event_type\":\"price_change\"}","received_at":"2026-07-28T02:13:12.632671Z","schema_version":"clob-market-ws.price_change.v1","sequence":null,"server_hash":null,"server_timestamp":"1785204792590","session_id":"d2757dd6dad94f3b9fe67e8dbf1adc37","source":"clob_market_ws"},"received_at":"2026-07-28T02:13:12.632671Z","record_id":"b6fb1c362c262c6ff020d52d3a1bade37479297d89fe0415aed8d15b792aba62","schema_fingerprint":"4aa3821a28b0b7c2400bc59aba4bcc0a76e971dadd19610d3ad38c768e124dc7","schema_version":"edge-lab-recorder.raw.v1","sequence":null,"source":"clob_market_ws"}
{"event_at":"2026-07-28T02:13:12.592000Z","event_fingerprint":"9d03834e3cc72eb13cfcc8ab03149af4a52c1b639ac5612ad60e4c9d95086c6e","payload":{"connection_id":"5d29200f65794d4d9ab6ef271f045a9b","event_at":"2026-07-28T02:13:12.592000Z","event_type":"price_change","frame_hash":"6fb76cff20c22bdebf15db0451e99c364c88389fd72a19bbb9f74285e8be6455","frame_index":0,"kind":"data","monotonic_ns":306775646489625,"payload":{"event_type":"price_change","market":"0xda6f0e0e93fc8469e0159a166028d017bddbc162b86f66bac90391379603d962","price_changes":[{"asset_id":"39272994714739463168905443499424551362424437245880253267329605556587274644733","best_ask":"0.28","best_bid":"0.27","hash":"10bbb1da79f6cd83293772b764d8cbe4109cc230","price":"0.17","side":"BUY","size":"82"},{"asset_id":"20893381255801015515826997628594359667013752732428989472914000440642900266717","best_ask":"0.73","best_bid":"0.72","hash":"6d9199a4773b6f45a2deed430192979f1d033f77","price":"0.83","side":"SELL","size":"82"}],"timestamp":"1785204792592"},"payload_hash":"d73b10e8b37ee81480b9357a54edf3adf5b4a87615674474c9452053fdc9e2ac","raw_frame":"{\"market\":\"0xda6f0e0e93fc8469e0159a166028d017bddbc162b86f66bac90391379603d962\", \"price_changes\":[{\"asset_id\":\"39272994714739463168905443499424551362424437245880253267329605556587274644733\", \"price\":\"0.17\", \"size\":\"82\", \"side\":\"BUY\", \"hash\":\"10bbb1da79f6cd83293772b764d8cbe4109cc230\", \"best_bid\":\"0.27\", \"best_ask\":\"0.28\"}, {\"asset_id\":\"20893381255801015515826997628594359667013752732428989472914000440642900266717\", \"price\":\"0.83\", \"size\":\"82\", \"side\":\"SELL\", \"hash\":\"6d9199a4773b6f45a2deed430192979f1d033f77\", \"best_bid\":\"0.72\", \"best_ask\":\"0.73\"}], \"timestamp\":\"1785204792592\", \"event_type\":\"price_change\"}","received_at":"2026-07-28T02:13:12.635584Z","schema_version":"clob-market-ws.price_change.v1","sequence":null,"server_hash":null,"server_timestamp":"1785204792592","session_id":"d2757dd6dad94f3b9fe67e8dbf1adc37","source":"clob_market_ws"},"received_at":"2026-07-28T02:13:12.635584Z","record_id":"7e38cc06ff96439a0c006c4086c1d053bdbf940f1b9648ca0fb3b5be72f58645","schema_fingerprint":"4aa3821a28b0b7c2400bc59aba4bcc0a76e971dadd19610d3ad38c768e124dc7","schema_version":"edge-lab-recorder.raw.v1","sequence":null,"source":"clob_market_ws"}
{"event_at":"2026-07-28T02:13:12.593000Z","event_fingerprint":"f3bfd9159a3c87598f7bb6e94748908f8669f6f2f774c25f2c444b26ed0aeaaf","payload":{"connection_id":"5d29200f65794d4d9ab6ef271f045a9b","event_at":"2026-07-28T02:13:12.593000Z","event_type":"price_change","frame_hash":"e1a3bf098887bc240d14f385a286fb20eee5407cd189fce03cf96ba742ef39df","frame_index":0,"kind":"data","monotonic_ns":306775649494500,"payload":{"event_type":"price_change","market":"0xda6f0e0e93fc8469e0159a166028d017bddbc162b86f66bac90391379603d962","price_changes":[{"asset_id":"39272994714739463168905443499424551362424437245880253267329605556587274644733","best_ask":"0.28","best_bid":"0.27","hash":"651b50a0223d94a69e7b35ea7c66b94ed27a1ffb","price":"0.27","side":"BUY","size":"54"},{"asset_id":"20893381255801015515826997628594359667013752732428989472914000440642900266717","best_ask":"0.73","best_bid":"0.72","hash":"5763470234e4f8195fdcc835909d47227ca3de1f","price":"0.73","side":"SELL","size":"54"}],"timestamp":"1785204792593"},"payload_hash":"3789bf14cf789a98243498956124d05b88aa5ed66a4dd467a67a1b7e1504559e","raw_frame":"{\"market\":\"0xda6f0e0e93fc8469e0159a166028d017bddbc162b86f66bac90391379603d962\", \"price_changes\":[{\"asset_id\":\"39272994714739463168905443499424551362424437245880253267329605556587274644733\", \"price\":\"0.27\", \"size\":\"54\", \"side\":\"BUY\", \"hash\":\"651b50a0223d94a69e7b35ea7c66b94ed27a1ffb\", \"best_bid\":\"0.27\", \"best_ask\":\"0.28\"}, {\"asset_id\":\"20893381255801015515826997628594359667013752732428989472914000440642900266717\", \"price\":\"0.73\", \"size\":\"54\", \"side\":\"SELL\", \"hash\":\"5763470234e4f8195fdcc835909d47227ca3de1f\", \"best_bid\":\"0.72\", \"best_ask\":\"0.73\"}], \"timestamp\":\"1785204792593\", \"event_type\":\"price_change\"}","received_at":"2026-07-28T02:13:12.638589Z","schema_version":"clob-market-ws.price_change.v1","sequence":null,"server_hash":null,"server_timestamp":"1785204792593","session_id":"d2757dd6dad94f3b9fe67e8dbf1adc37","source":"clob_market_ws"},"received_at":"2026-07-28T02:13:12.638589Z","record_id":"a807fd6ff7ceacc4c8aad48292b3d28dd87e9d7a95ca4806516a72d3115a5e89","schema_fingerprint":"4aa3821a28b0b7c2400bc59aba4bcc0a76e971dadd19610d3ad38c768e124dc7","schema_version":"edge-lab-recorder.raw.v1","sequence":null,"source":"clob_market_ws"}
{"event_at":"2026-07-28T02:13:12.594000Z","event_fingerprint":"d8896d043d99813717bf3bbfa317c1788e161d95ed0467dcccdffe5d9fa1bb2b","payload":{"connection_id":"5d29200f65794d4d9ab6ef271f045a9b","event_at":"2026-07-28T02:13:12.594000Z","event_type":"price_change","frame_hash":"7967adf68a2133d8ef64aac48eb47ec8d0c08bb692a54548ff761d3509000eae","frame_index":0,"kind":"data","monotonic_ns":306775652529916,"payload":{"event_type":"price_change","market":"0xda6f0e0e93fc8469e0159a166028d017bddbc162b86f66bac90391379603d962","price_changes":[{"asset_id":"39272994714739463168905443499424551362424437245880253267329605556587274644733","best_ask":"0.28","best_bid":"0.27","hash":"83aa6a9e2e8db574c88f6b05510acdeedf04427b","price":"0.27","side":"BUY","size":"61"},{"asset_id":"20893381255801015515826997628594359667013752732428989472914000440642900266717","best_ask":"0.73","best_bid":"0.72","hash":"53ebe1387dfaa0ce31da8410f3784a665c0b3595","price":"0.73","side":"SELL","size":"61"}],"timestamp":"1785204792594"},"payload_hash":"9506e2b6dea6dd0a22540843e3ed0f9859da9e9fe3ab47f219640d33fe6c4c83","raw_frame":"{\"market\":\"0xda6f0e0e93fc8469e0159a166028d017bddbc162b86f66bac90391379603d962\", \"price_changes\":[{\"asset_id\":\"39272994714739463168905443499424551362424437245880253267329605556587274644733\", \"price\":\"0.27\", \"size\":\"61\", \"side\":\"BUY\", \"hash\":\"83aa6a9e2e8db574c88f6b05510acdeedf04427b\", \"best_bid\":\"0.27\", \"best_ask\":\"0.28\"}, {\"asset_id\":\"20893381255801015515826997628594359667013752732428989472914000440642900266717\", \"price\":\"0.73\", \"size\":\"61\", \"side\":\"SELL\", \"hash\":\"53ebe1387dfaa0ce31da8410f3784a665c0b3595\", \"best_bid\":\"0.72\", \"best_ask\":\"0.73\"}], \"timestamp\":\"1785204792594\", \"event_type\":\"price_change\"}","received_at":"2026-07-28T02:13:12.641624Z","schema_version":"clob-market-ws.price_change.v1","sequence":null,"server_hash":null,"server_timestamp":"1785204792594","session_id":"d2757dd6dad94f3b9fe67e8dbf1adc37","source":"clob_market_ws"},"received_at":"2026-07-28T02:13:12.641624Z","record_id":"70838b682b65954738247aa9e9106026b30267b2b4ce8c25a017450e7827780b","schema_fingerprint":"4aa3821a28b0b7c2400bc59aba4bcc0a76e971dadd19610d3ad38c768e124dc7","schema_version":"edge-lab-recorder.raw.v1","sequence":null,"source":"clob_market_ws"}
{"event_at":"2026-07-28T02:13:12.595000Z","event_fingerprint":"793f6ee8afac345ac35f21307ea269251f0b7693de63419175e0171cc3fddb2a","payload":{"connection_id":"5d29200f65794d4d9ab6ef271f045a9b","event_at":"2026-07-28T02:13:12.595000Z","event_type":"price_change","frame_hash":"95707a7ecf3f4831545801a84536c421bb3852a7eee5d3623ca08c1a28988c7b","frame_index":0,"kind":"data","monotonic_ns":306775655543833,"payload":{"event_type":"price_change","market":"0xda6f0e0e93fc8469e0159a166028d017bddbc162b86f66bac90391379603d962","price_changes":[{"asset_id":"39272994714739463168905443499424551362424437245880253267329605556587274644733","best_ask":"0.28","best_bid":"0.27","hash":"c303549210dd921ee591d96d55411f51fc1a50c7","price":"0.18","side":"BUY","size":"112.99"},{"asset_id":"20893381255801015515826997628594359667013752732428989472914000440642900266717","best_ask":"0.73","best_bid":"0.72","hash":"d906aa351179dcfb9ebbb6a944a3742b2dec1e8d","price":"0.82","side":"SELL","size":"112.99"}],"timestamp":"1785204792595"},"payload_hash":"8fae6e60bb323cc29b830e5566388e4ca4f6ea2017c6c1724e8d84101d365eeb","raw_frame":"{\"market\":\"0xda6f0e0e93fc8469e0159a166028d017bddbc162b86f66bac90391379603d962\", \"price_changes\":[{\"asset_id\":\"39272994714739463168905443499424551362424437245880253267329605556587274644733\", \"price\":\"0.18\", \"size\":\"112.99\", \"side\":\"BUY\", \"hash\":\"c303549210dd921ee591d96d55411f51fc1a50c7\", \"best_bid\":\"0.27\", \"best_ask\":\"0.28\"}, {\"asset_id\":\"20893381255801015515826997628594359667013752732428989472914000440642900266717\", \"price\":\"0.82\", \"size\":\"112.99\", \"side\":\"SELL\", \"hash\":\"d906aa351179dcfb9ebbb6a944a3742b2dec1e8d\", \"best_bid\":\"0.72\", \"best_ask\":\"0.73\"}], \"timestamp\":\"1785204792595\", \"event_type\":\"price_change\"}","received_at":"2026-07-28T02:13:12.644637Z","schema_version":"clob-market-ws.price_change.v1","sequence":null,"server_hash":null,"server_timestamp":"1785204792595","session_id":"d2757dd6dad94f3b9fe67e8dbf1adc37","source":"clob_market_ws"},"received_at":"2026-07-28T02:13:12.644637Z","record_id":"1204506bcffd3bcfe1d05e24c622326485b888a68017f7afc15e6dbba9893d56","schema_fingerprint":"4aa3821a28b0b7c2400bc59aba4bcc0a76e971dadd19610d3ad38c768e124dc7","schema_version":"edge-lab-recorder.raw.v1","sequence":null,"source":"clob_market_ws"}
{"event_at":"2026-07-28T02:13:12.596000Z","event_fingerprint":"8240b4ac87f62a7abc0ed31472553631e571bf2960642634fe414ee5c54dc4a9","payload":{"connection_id":"5d29200f65794d4d9ab6ef271f045a9b","event_at":"2026-07-28T02:13:12.596000Z","event_type":"price_change","frame_hash":"8c9315906cc0877d705eb38adb6fa1084762d108538bab6aa88806cc8b22f1db","frame_index":0,"kind":"data","monotonic_ns":306775658558125,"payload":{"event_type":"price_change","market":"0xda6f0e0e93fc8469e0159a166028d017bddbc162b86f66bac90391379603d962","price_changes":[{"asset_id":"39272994714739463168905443499424551362424437245880253267329605556587274644733","best_ask":"0.28","best_bid":"0.27","hash":"4b1ae90c7f2c9a1ad3b125a76c8ee2b4dcac8c8f","price":"0.19","side":"BUY","size":"63.3"},{"asset_id":"20893381255801015515826997628594359667013752732428989472914000440642900266717","best_ask":"0.73","best_bid":"0.72","hash":"d4d9d96fe5288a180d7f823fb539fb8f0b25ab4b","price":"0.81","side":"SELL","size":"63.3"}],"timestamp":"1785204792596"},"payload_hash":"c7ee98bcbf009bcd81c53c026f815440df2f1c66e7e96b2d81862afc5bb7f0ec","raw_frame":"{\"market\":\"0xda6f0e0e93fc8469e0159a166028d017bddbc162b86f66bac90391379603d962\", \"price_changes\":[{\"asset_id\":\"39272994714739463168905443499424551362424437245880253267329605556587274644733\", \"price\":\"0.19\", \"size\":\"63.3\", \"side\":\"BUY\", \"hash\":\"4b1ae90c7f2c9a1ad3b125a76c8ee2b4dcac8c8f\", \"best_bid\":\"0.27\", \"best_ask\":\"0.28\"}, {\"asset_id\":\"20893381255801015515826997628594359667013752732428989472914000440642900266717\", \"price\":\"0.81\", \"size\":\"63.3\", \"side\":\"SELL\", \"hash\":\"d4d9d96fe5288a180d7f823fb539fb8f0b25ab4b\", \"best_bid\":\"0.72\", \"best_ask\":\"0.73\"}], \"timestamp\":\"1785204792596\", \"event_type\":\"price_change\"}","received_at":"2026-07-28T02:13:12.647652Z","schema_version":"clob-market-ws.price_change.v1","sequence":null,"server_hash":null,"server_timestamp":"1785204792596","session_id":"d2757dd6dad94f3b9fe67e8dbf1adc37","source":"clob_market_ws"},"received_at":"2026-07-28T02:13:12.647652Z","record_id":"855fcfea673fd9e6074b31710e231a910e5677a902a0b1eb77a3d254687a9bd2","schema_fingerprint":"4aa3821a28b0b7c2400bc59aba4bcc0a76e971dadd19610d3ad38c768e124dc7","schema_version":"edge-lab-recorder.raw.v1","sequence":null,"source":"clob_market_ws"}
{"event_at":"2026-07-28T02:13:12.607000Z","event_fingerprint":"a1dc584d4a81fb67e192333f8585aa1b0680e7e0d5b282feaafddc223d810619","payload":{"connection_id":"5d29200f65794d4d9ab6ef271f045a9b","event_at":"2026-07-28T02:13:12.607000Z","event_type":"price_change","frame_hash":"7d7e339c9403d9e9dcfb170c0cfd4cbe7ac6634614fa033e856236249cd0fae5","frame_index":0,"kind":"data","monotonic_ns":306775661247083,"payload":{"event_type":"price_change","market":"0xda6f0e0e93fc8469e0159a166028d017bddbc162b86f66bac90391379603d962","price_changes":[{"asset_id":"20893381255801015515826997628594359667013752732428989472914000440642900266717","best_ask":"0.73","best_bid":"0.72","hash":"83184fa1f4ae8c9263428ada63a82568235c4677","price":"0.67","side":"BUY","size":"60"},{"asset_id":"39272994714739463168905443499424551362424437245880253267329605556587274644733","best_ask":"0.28","best_bid":"0.27","hash":"80d50793c529334f672969994c44d610baa6ba3a","price":"0.33","side":"SELL","size":"60"}],"timestamp":"1785204792607"},"payload_hash":"4e1b5af7e3e068f614f1cc7e29499bb9af3be21afdbf5897d83a1fa4e366d916","raw_frame":"{\"market\":\"0xda6f0e0e93fc8469e0159a166028d017bddbc162b86f66bac90391379603d962\", \"price_changes\":[{\"asset_id\":\"20893381255801015515826997628594359667013752732428989472914000440642900266717\", \"price\":\"0.67\", \"size\":\"60\", \"side\":\"BUY\", \"hash\":\"83184fa1f4ae8c9263428ada63a82568235c4677\", \"best_bid\":\"0.72\", \"best_ask\":\"0.73\"}, {\"asset_id\":\"39272994714739463168905443499424551362424437245880253267329605556587274644733\", \"price\":\"0.33\", \"size\":\"60\", \"side\":\"SELL\", \"hash\":\"80d50793c529334f672969994c44d610baa6ba3a\", \"best_bid\":\"0.27\", \"best_ask\":\"0.28\"}], \"timestamp\":\"1785204792607\", \"event_type\":\"price_change\"}","received_at":"2026-07-28T02:13:12.650343Z","schema_version":"clob-market-ws.price_change.v1","sequence":null,"server_hash":null,"server_timestamp":"1785204792607","session_id":"d2757dd6dad94f3b9fe67e8dbf1adc37","source":"clob_market_ws"},"received_at":"2026-07-28T02:13:12.650343Z","record_id":"1271742051e56d6db95dc5a784be99413f772c018f795bb5b23fd7cf63805aa9","schema_fingerprint":"4aa3821a28b0b7c2400bc59aba4bcc0a76e971dadd19610d3ad38c768e124dc7","schema_version":"edge-lab-recorder.raw.v1","sequence":null,"source":"clob_market_ws"}
{"event_at":"2026-07-28T02:13:12.608000Z","event_fingerprint":"639cd16aa19ecdf9bc8cc276c85604817c081921ac5fd0dc139e3c0961f852ed","payload":{"connection_id":"5d29200f65794d4d9ab6ef271f045a9b","event_at":"2026-07-28T02:13:12.608000Z","event_type":"price_change","frame_hash":"15d375d25a5f99bbf654e7012fa4a9fcc7646628d5be62f8330178d1f340825e","frame_index":0,"kind":"data","monotonic_ns":306775664058833,"payload":{"event_type":"price_change","market":"0xda6f0e0e93fc8469e0159a166028d017bddbc162b86f66bac90391379603d962","price_changes":[{"asset_id":"39272994714739463168905443499424551362424437245880253267329605556587274644733","best_ask":"0.28","best_bid":"0.27","hash":"0623101c08990b690dbcf7b3b3b8f17a480e8ec9","price":"0.27","side":"BUY","size":"75"},{"asset_id":"20893381255801015515826997628594359667013752732428989472914000440642900266717","best_ask":"0.73","best_bid":"0.72","hash":"e6112e9e143a6cb541a36929fb739cd2f4d5ae83","price":"0.73","side":"SELL","size":"75"}],"timestamp":"1785204792608"},"payload_hash":"136e0f307571874feb68abfa7f44bba49fe9a3e33b9f72ae63926134ebfec7c4","raw_frame":"{\"market\":\"0xda6f0e0e93fc8469e0159a166028d017bddbc162b86f66bac90391379603d962\", \"price_changes\":[{\"asset_id\":\"39272994714739463168905443499424551362424437245880253267329605556587274644733\", \"price\":\"0.27\", \"size\":\"75\", \"side\":\"BUY\", \"hash\":\"0623101c08990b690dbcf7b3b3b8f17a480e8ec9\", \"best_bid\":\"0.27\", \"best_ask\":\"0.28\"}, {\"asset_id\":\"20893381255801015515826997628594359667013752732428989472914000440642900266717\", \"price\":\"0.73\", \"size\":\"75\", \"side\":\"SELL\", \"hash\":\"e6112e9e143a6cb541a36929fb739cd2f4d5ae83\", \"best_bid\":\"0.72\", \"best_ask\":\"0.73\"}], \"timestamp\":\"1785204792608\", \"event_type\":\"price_change\"}","received_at":"2026-07-28T02:13:12.653154Z","schema_version":"clob-market-ws.price_change.v1","sequence":null,"server_hash":null,"server_timestamp":"1785204792608","session_id":"d2757dd6dad94f3b9fe67e8dbf1adc37","source":"clob_market_ws"},"received_at":"2026-07-28T02:13:12.653154Z","record_id":"7dd951f43d515452a4b49fbce1603879a592ffa9a9aba91bf38885e5f600bf4b","schema_fingerprint":"4aa3821a28b0b7c2400bc59aba4bcc0a76e971dadd19610d3ad38c768e124dc7","schema_version":"edge-lab-recorder.raw.v1","sequence":null,"source":"clob_market_ws"}
{"event_at":"2026-07-28T02:13:12.609000Z","event_fingerprint":"cc2c704239fce8d210924beb2f6c016405aba3cc6acf2e2d8a7f2d69afe1213e","payload":{"connection_id":"5d29200f65794d4d9ab6ef271f045a9b","event_at":"2026-07-28T02:13:12.609000Z","event_type":"price_change","frame_hash":"fb6a73d7fd6ddfb25da442d407190363455d45baf9bba4ddd1b687792ceaed9c","frame_index":0,"kind":"data","monotonic_ns":306775667104125,"payload":{"event_type":"price_change","market":"0xda6f0e0e93fc8469e0159a166028d017bddbc162b86f66bac90391379603d962","price_changes":[{"asset_id":"39272994714739463168905443499424551362424437245880253267329605556587274644733","best_ask":"0.28","best_bid":"0.27","hash":"9591d51bfae0bef2b22468a06bec11214cacabdf","price":"0.27","side":"BUY","size":"85"},{"asset_id":"20893381255801015515826997628594359667013752732428989472914000440642900266717","best_ask":"0.73","best_bid":"0.72","hash":"7f32a37132f0664dd21298d908c386ae65e8385b","price":"0.73","side":"SELL","size":"85"}],"timestamp":"1785204792609"},"payload_hash":"643e21564caab994d5e13127acc4000424281ff73c85088ad34a093c10bcf862","raw_frame":"{\"market\":\"0xda6f0e0e93fc8469e0159a166028d017bddbc162b86f66bac90391379603d962\", \"price_changes\":[{\"asset_id\":\"39272994714739463168905443499424551362424437245880253267329605556587274644733\", \"price\":\"0.27\", \"size\":\"85\", \"side\":\"BUY\", \"hash\":\"9591d51bfae0bef2b22468a06bec11214cacabdf\", \"best_bid\":\"0.27\", \"best_ask\":\"0.28\"}, {\"asset_id\":\"20893381255801015515826997628594359667013752732428989472914000440642900266717\", \"price\":\"0.73\", \"size\":\"85\", \"side\":\"SELL\", \"hash\":\"7f32a37132f0664dd21298d908c386ae65e8385b\", \"best_bid\":\"0.72\", \"best_ask\":\"0.73\"}], \"timestamp\":\"1785204792609\", \"event_type\":\"price_change\"}","received_at":"2026-07-28T02:13:12.656198Z","schema_version":"clob-market-ws.price_change.v1","sequence":null,"server_hash":null,"server_timestamp":"1785204792609","session_id":"d2757dd6dad94f3b9fe67e8dbf1adc37","source":"clob_market_ws"},"received_at":"2026-07-28T02:13:12.656198Z","record_id":"8dc3a6dad53da1c857ecb8289830f3151cb4d68c6770334b42b3d9ac3ccbbb5c","schema_fingerprint":"4aa3821a28b0b7c2400bc59aba4bcc0a76e971dadd19610d3ad38c768e124dc7","schema_version":"edge-lab-recorder.raw.v1","sequence":null,"source":"clob_market_ws"}
{"event_at":"2026-07-28T02:13:12.611000Z","event_fingerprint":"af018daa25b7ea02b6bff2eac69dabffb3fafee036ee46491dd09a8367b0b7d7","payload":{"connection_id":"5d29200f65794d4d9ab6ef271f045a9b","event_at":"2026-07-28T02:13:12.611000Z","event_type":"price_change","frame_hash":"830fb590dc24dfc8ccac8ca3a682051aae2ffe73b228ba81e106098de069eb1b","frame_index":0,"kind":"data","monotonic_ns":306775668845250,"payload":{"event_type":"price_change","market":"0xda6f0e0e93fc8469e0159a166028d017bddbc162b86f66bac90391379603d962","price_changes":[{"asset_id":"39272994714739463168905443499424551362424437245880253267329605556587274644733","best_ask":"0.28","best_bid":"0.27","hash":"e5d30e24b7e557c3798782f80e6dd5353655b06c","price":"0.01","side":"BUY","size":"8093.02"},{"asset_id":"20893381255801015515826997628594359667013752732428989472914000440642900266717","best_ask":"0.73","best_bid":"0.72","hash":"a88967b9d4054215b7840e629c4271aff795bc77","price":"0.99","side":"SELL","size":"8093.02"}],"timestamp":"1785204792611"},"payload_hash":"e8d41cccc66bfa5b9e4cfc3ec3c10a6d3aa574e5b5d781cb0c1cbdd91376e66b","raw_frame":"{\"market\":\"0xda6f0e0e93fc8469e0159a166028d017bddbc162b86f66bac90391379603d962\", \"price_changes\":[{\"asset_id\":\"39272994714739463168905443499424551362424437245880253267329605556587274644733\", \"price\":\"0.01\", \"size\":\"8093.02\", \"side\":\"BUY\", \"hash\":\"e5d30e24b7e557c3798782f80e6dd5353655b06c\", \"best_bid\":\"0.27\", \"best_ask\":\"0.28\"}, {\"asset_id\":\"20893381255801015515826997628594359667013752732428989472914000440642900266717\", \"price\":\"0.99\", \"size\":\"8093.02\", \"side\":\"SELL\", \"hash\":\"a88967b9d4054215b7840e629c4271aff795bc77\", \"best_bid\":\"0.72\", \"best_ask\":\"0.73\"}], \"timestamp\":\"1785204792611\", \"event_type\":\"price_change\"}","received_at":"2026-07-28T02:13:12.657946Z","schema_version":"clob-market-ws.price_change.v1","sequence":null,"server_hash":null,"server_timestamp":"1785204792611","session_id":"d2757dd6dad94f3b9fe67e8dbf1adc37","source":"clob_market_ws"},"received_at":"2026-07-28T02:13:12.657946Z","record_id":"55057e036ba8a97dd8874573789f45a75129b46aec5443a71994da3a310ed617","schema_fingerprint":"4aa3821a28b0b7c2400bc59aba4bcc0a76e971dadd19610d3ad38c768e124dc7","schema_version":"edge-lab-recorder.raw.v1","sequence":null,"source":"clob_market_ws"}
{"event_at":"2026-07-28T02:13:12.614000Z","event_fingerprint":"d4b27fae065a319310fb84ef28df7214c2d1b355965daaa420ccf1dab2c32e9d","payload":{"connection_id":"5d29200f65794d4d9ab6ef271f045a9b","event_at":"2026-07-28T02:13:12.614000Z","event_type":"price_change","frame_hash":"3b192c9b80095d3124779384ebaeb69af293599989d8b8c9371ab839d23e17df","frame_index":0,"kind":"data","monotonic_ns":306775671280166,"payload":{"event_type":"price_change","market":"0xda6f0e0e93fc8469e0159a166028d017bddbc162b86f66bac90391379603d962","price_changes":[{"asset_id":"39272994714739463168905443499424551362424437245880253267329605556587274644733","best_ask":"0.28","best_bid":"0.27","hash":"cb4021f85166ea09be8f7b650cef1108e1c0ea3f","price":"0.27","side":"BUY","size":"56"},{"asset_id":"20893381255801015515826997628594359667013752732428989472914000440642900266717","best_ask":"0.73","best_bid":"0.72","hash":"7377ec6984aa6e8a80b0d5e048f0aefe2913cb35","price":"0.73","side":"SELL","size":"56"}],"timestamp":"1785204792614"},"payload_hash":"f8d7f5d2b7d570c211385267eb53e0ea1036f005c1079769c205b316f678bf21","raw_frame":"{\"market\":\"0xda6f0e0e93fc8469e0159a166028d017bddbc162b86f66bac90391379603d962\", \"price_changes\":[{\"asset_id\":\"39272994714739463168905443499424551362424437245880253267329605556587274644733\", \"price\":\"0.27\", \"size\":\"56\", \"side\":\"BUY\", \"hash\":\"cb4021f85166ea09be8f7b650cef1108e1c0ea3f\", \"best_bid\":\"0.27\", \"best_ask\":\"0.28\"}, {\"asset_id\":\"20893381255801015515826997628594359667013752732428989472914000440642900266717\", \"price\":\"0.73\", \"size\":\"56\", \"side\":\"SELL\", \"hash\":\"7377ec6984aa6e8a80b0d5e048f0aefe2913cb35\", \"best_bid\":\"0.72\", \"best_ask\":\"0.73\"}], \"timestamp\":\"1785204792614\", \"event_type\":\"price_change\"}","received_at":"2026-07-28T02:13:12.660374Z","schema_version":"clob-market-ws.price_change.v1","sequence":null,"server_hash":null,"server_timestamp":"1785204792614","session_id":"d2757dd6dad94f3b9fe67e8dbf1adc37","source":"clob_market_ws"},"received_at":"2026-07-28T02:13:12.660374Z","record_id":"eceadf261fe1752e45f969caa050aa40d041d50de9d97e825ee825f313e17dfe","schema_fingerprint":"4aa3821a28b0b7c2400bc59aba4bcc0a76e971dadd19610d3ad38c768e124dc7","schema_version":"edge-lab-recorder.raw.v1","sequence":null,"source":"clob_market_ws"}
{"event_at":"2026-07-28T02:13:12.619000Z","event_fingerprint":"fe534350cc2ac34f24027000ef604b8342416b77c6b6e23e4116d569c97fdd47","payload":{"connection_id":"5d29200f65794d4d9ab6ef271f045a9b","event_at":"2026-07-28T02:13:12.619000Z","event_type":"price_change","frame_hash":"fe7e2c4414393b7764d47c2589b5c1df9524d4c3e6b8356833645c4ca53e7543","frame_index":0,"kind":"data","monotonic_ns":306775674270916,"payload":{"event_type":"price_change","market":"0xda6f0e0e93fc8469e0159a166028d017bddbc162b86f66bac90391379603d962","price_changes":[{"asset_id":"39272994714739463168905443499424551362424437245880253267329605556587274644733","best_ask":"0.28","best_bid":"0.27","hash":"989a2f42887333ba09babe6a63e25a28c7d810db","price":"0.16","side":"BUY","size":"196"},{"asset_id":"20893381255801015515826997628594359667013752732428989472914000440642900266717","best_ask":"0.73","best_bid":"0.72","hash":"29aa7ebde10ce6b2d79a8678e7178145430e9226","price":"0.84","side":"SELL","size":"196"}],"timestamp":"1785204792619"},"payload_hash":"901febb7913a34f92330a0b43f618a3d1a8168df00c5fae0b247c875db0eb997","raw_frame":"{\"market\":\"0xda6f0e0e93fc8469e0159a166028d017bddbc162b86f66bac90391379603d962\", \"price_changes\":[{\"asset_id\":\"39272994714739463168905443499424551362424437245880253267329605556587274644733\", \"price\":\"0.16\", \"size\":\"196\", \"side\":\"BUY\", \"hash\":\"989a2f42887333ba09babe6a63e25a28c7d810db\", \"best_bid\":\"0.27\", \"best_ask\":\"0.28\"}, {\"asset_id\":\"20893381255801015515826997628594359667013752732428989472914000440642900266717\", \"price\":\"0.84\", \"size\":\"196\", \"side\":\"SELL\", \"hash\":\"29aa7ebde10ce6b2d79a8678e7178145430e9226\", \"best_bid\":\"0.72\", \"best_ask\":\"0.73\"}], \"timestamp\":\"1785204792619\", \"event_type\":\"price_change\"}","received_at":"2026-07-28T02:13:12.663365Z","schema_version":"clob-market-ws.price_change.v1","sequence":null,"server_hash":null,"server_timestamp":"1785204792619","session_id":"d2757dd6dad94f3b9fe67e8dbf1adc37","source":"clob_market_ws"},"received_at":"2026-07-28T02:13:12.663365Z","record_id":"b8ecce93728bcdd3abfd72303cda1c4c5eeb606a11c040108a9476b75f7e6a64","schema_fingerprint":"4aa3821a28b0b7c2400bc59aba4bcc0a76e971dadd19610d3ad38c768e124dc7","schema_version":"edge-lab-recorder.raw.v1","sequence":null,"source":"clob_market_ws"}
{"event_at":"2026-07-28T02:13:12.623000Z","event_fingerprint":"1587a7d50d665324d22990f56b84dff63784b17047003dc109391946f93c3f63","payload":{"connection_id":"5d29200f65794d4d9ab6ef271f045a9b","event_at":"2026-07-28T02:13:12.623000Z","event_type":"price_change","frame_hash":"6782ba1ba2701bbec82ed66068139db1d168c900f110245c64f5eb0eff6d013c","frame_index":0,"kind":"data","monotonic_ns":306775677240041,"payload":{"event_type":"price_change","market":"0xda6f0e0e93fc8469e0159a166028d017bddbc162b86f66bac90391379603d962","price_changes":[{"asset_id":"20893381255801015515826997628594359667013752732428989472914000440642900266717","best_ask":"0.73","best_bid":"0.72","hash":"964c8ace143cea4d778792548b237695b2027252","price":"0.59","side":"BUY","size":"109"},{"asset_id":"39272994714739463168905443499424551362424437245880253267329605556587274644733","best_ask":"0.28","best_bid":"0.27","hash":"00052093db98471fd93259f72db0872693cdd964","price":"0.41","side":"SELL","size":"109"}],"timestamp":"1785204792623"},"payload_hash":"6475d1d8afe1ce6f3c91e758aaf41b46896906e6bbe0e329b92f978109230df5","raw_frame":"{\"market\":\"0xda6f0e0e93fc8469e0159a166028d017bddbc162b86f66bac90391379603d962\", \"price_changes\":[{\"asset_id\":\"20893381255801015515826997628594359667013752732428989472914000440642900266717\", \"price\":\"0.59\", \"size\":\"109\", \"side\":\"BUY\", \"hash\":\"964c8ace143cea4d778792548b237695b2027252\", \"best_bid\":\"0.72\", \"best_ask\":\"0.73\"}, {\"asset_id\":\"39272994714739463168905443499424551362424437245880253267329605556587274644733\", \"price\":\"0.41\", \"size\":\"109\", \"side\":\"SELL\", \"hash\":\"00052093db98471fd93259f72db0872693cdd964\", \"best_bid\":\"0.27\", \"best_ask\":\"0.28\"}], \"timestamp\":\"1785204792623\", \"event_type\":\"price_change\"}","received_at":"2026-07-28T02:13:12.666335Z","schema_version":"clob-market-ws.price_change.v1","sequence":null,"server_hash":null,"server_timestamp":"1785204792623","session_id":"d2757dd6dad94f3b9fe67e8dbf1adc37","source":"clob_market_ws"},"received_at":"2026-07-28T02:13:12.666335Z","record_id":"4e73618b918098dd0ba4dbdb535bb585ad0682aaad34a42f6d3fc68f38d28650","schema_fingerprint":"4aa3821a28b0b7c2400bc59aba4bcc0a76e971dadd19610d3ad38c768e124dc7","schema_version":"edge-lab-recorder.raw.v1","sequence":null,"source":"clob_market_ws"}
{"event_at":"2026-07-28T02:13:12.624000Z","event_fingerprint":"a2093bf6923745545b712540c91f14ab6346423ab45b42d06a4909d63725ed2d","payload":{"connection_id":"5d29200f65794d4d9ab6ef271f045a9b","event_at":"2026-07-28T02:13:12.624000Z","event_type":"price_change","frame_hash":"ec178d7ca309841fc515e7b823a6b54616d2a41815814cdcdd41187190cd7828","frame_index":0,"kind":"data","monotonic_ns":306775680206083,"payload":{"event_type":"price_change","market":"0xda6f0e0e93fc8469e0159a166028d017bddbc162b86f66bac90391379603d962","price_changes":[{"asset_id":"39272994714739463168905443499424551362424437245880253267329605556587274644733","best_ask":"0.28","best_bid":"0.27","hash":"d1e80d9fd4f8bfadde28390375997cadfe57c37a","price":"0.18","side":"BUY","size":"142.99"},{"asset_id":"20893381255801015515826997628594359667013752732428989472914000440642900266717","best_ask":"0.73","best_bid":"0.72","hash":"96b41f88f05670414963fc1184cb82252bdc097f","price":"0.82","side":"SELL","size":"142.99"}],"timestamp":"1785204792624"},"payload_hash":"0cbc3bd7f0e3ed941b4cf52f3e80614a49f94140d45f76c5a768b904d2c39cfe","raw_frame":"{\"market\":\"0xda6f0e0e93fc8469e0159a166028d017bddbc162b86f66bac90391379603d962\", \"price_changes\":[{\"asset_id\":\"39272994714739463168905443499424551362424437245880253267329605556587274644733\", \"price\":\"0.18\", \"size\":\"142.99\", \"side\":\"BUY\", \"hash\":\"d1e80d9fd4f8bfadde28390375997cadfe57c37a\", \"best_bid\":\"0.27\", \"best_ask\":\"0.28\"}, {\"asset_id\":\"20893381255801015515826997628594359667013752732428989472914000440642900266717\", \"price\":\"0.82\", \"size\":\"142.99\", \"side\":\"SELL\", \"hash\":\"96b41f88f05670414963fc1184cb82252bdc097f\", \"best_bid\":\"0.72\", \"best_ask\":\"0.73\"}], \"timestamp\":\"1785204792624\", \"event_type\":\"price_change\"}","received_at":"2026-07-28T02:13:12.669301Z","schema_version":"clob-market-ws.price_change.v1","sequence":null,"server_hash":null,"server_timestamp":"1785204792624","session_id":"d2757dd6dad94f3b9fe67e8dbf1adc37","source":"clob_market_ws"},"received_at":"2026-07-28T02:13:12.669301Z","record_id":"d345e9f3a6e02fe8bdeee4975688b1e53b9c1c1db3fa9be6bb3190b2b6c5a724","schema_fingerprint":"4aa3821a28b0b7c2400bc59aba4bcc0a76e971dadd19610d3ad38c768e124dc7","schema_version":"edge-lab-recorder.raw.v1","sequence":null,"source":"clob_market_ws"}
{"event_at":"2026-07-28T02:13:12.631000Z","event_fingerprint":"1132a3f476f24957df26d00d16e8c74ccad3b4ed190c759d7f05d8fa15212fde","payload":{"connection_id":"5d29200f65794d4d9ab6ef271f045a9b","event_at":"2026-07-28T02:13:12.631000Z","event_type":"last_trade_price","frame_hash":"fb64890961410d2b4804a91e39f5de6b7f534f275776085e646f5f4cdb83535a","frame_index":0,"kind":"data","monotonic_ns":306775683223083,"payload":{"asset_id":"20893381255801015515826997628594359667013752732428989472914000440642900266717","event_type":"last_trade_price","fee_rate_bps":"0","market":"0xda6f0e0e93fc8469e0159a166028d017bddbc162b86f66bac90391379603d962","price":"0.72","side":"SELL","size":"0.02","timestamp":"1785204792631","transaction_hash":"0xd0b66cd224fe68cd13295d75caf5ff44db4d62fe76d42b5d4f73bcca3b7d4654"},"payload_hash":"cc44f2ac708fb44c240c1d446b6c61ae483d275744d53ea72278ce5e3a0ef80f","raw_frame":"{\"market\":\"0xda6f0e0e93fc8469e0159a166028d017bddbc162b86f66bac90391379603d962\", \"asset_id\":\"20893381255801015515826997628594359667013752732428989472914000440642900266717\", \"price\":\"0.72\", \"size\":\"0.02\", \"fee_rate_bps\":\"0\", \"side\":\"SELL\", \"timestamp\":\"1785204792631\", \"event_type\":\"last_trade_price\", \"transaction_hash\":\"0xd0b66cd224fe68cd13295d75caf5ff44db4d62fe76d42b5d4f73bcca3b7d4654\"}","received_at":"2026-07-28T02:13:12.672318Z","schema_version":"clob-market-ws.last_trade_price.v1","sequence":null,"server_hash":null,"server_timestamp":"1785204792631","session_id":"d2757dd6dad94f3b9fe67e8dbf1adc37","source":"clob_market_ws"},"received_at":"2026-07-28T02:13:12.672318Z","record_id":"a3e26dfd58e707d7f7eaffced502c80a0112bc36ab3edd4fcaa3f992e2efc1fd","schema_fingerprint":"95ad9be75a4b695cd99991e12b2592bc7346f3f5388a82d0000ba65bc0d9fd0a","schema_version":"edge-lab-recorder.raw.v1","sequence":null,"source":"clob_market_ws"}
{"event_at":"2026-07-28T02:13:12.636000Z","event_fingerprint":"b0cfca85632815ce0461028c0fd8f882a7489dac45cb873e18d71972e1f895f4","payload":{"connection_id":"5d29200f65794d4d9ab6ef271f045a9b","event_at":"2026-07-28T02:13:12.636000Z","event_type":"price_change","frame_hash":"f87fce7db0c7675cee718725f9e6fcf0c5ff58bf48d4f62d56a3b59538e60cb0","frame_index":0,"kind":"data","monotonic_ns":306775685200125,"payload":{"event_type":"price_change","market":"0xda6f0e0e93fc8469e0159a166028d017bddbc162b86f66bac90391379603d962","price_changes":[{"asset_id":"20893381255801015515826997628594359667013752732428989472914000440642900266717","best_ask":"0.73","best_bid":"0.72","hash":"8c23a753882158113812b5d554d111d37355153d","price":"0.7","side":"BUY","size":"0"},{"asset_id":"39272994714739463168905443499424551362424437245880253267329605556587274644733","best_ask":"0.28","best_bid":"0.27","hash":"8e685e91970d3288470f1ccd9a31d09629c22aad","price":"0.3","side":"SELL","size":"0"}],"timestamp":"1785204792636"},"payload_hash":"1d174eb827a15d17078c2ede1f564a1532df8a7dad0e8009a4b8a00e88eb99a7","raw_frame":"{\"market\":\"0xda6f0e0e93fc8469e0159a166028d017bddbc162b86f66bac90391379603d962\", \"price_changes\":[{\"asset_id\":\"20893381255801015515826997628594359667013752732428989472914000440642900266717\", \"price\":\"0.7\", \"size\":\"0\", \"side\":\"BUY\", \"hash\":\"8c23a753882158113812b5d554d111d37355153d\", \"best_bid\":\"0.72\", \"best_ask\":\"0.73\"}, {\"asset_id\":\"39272994714739463168905443499424551362424437245880253267329605556587274644733\", \"price\":\"0.3\", \"size\":\"0\", \"side\":\"SELL\", \"hash\":\"8e685e91970d3288470f1ccd9a31d09629c22aad\", \"best_bid\":\"0.27\", \"best_ask\":\"0.28\"}], \"timestamp\":\"1785204792636\", \"event_type\":\"price_change\"}","received_at":"2026-07-28T02:13:12.674290Z","schema_version":"clob-market-ws.price_change.v1","sequence":null,"server_hash":null,"server_timestamp":"1785204792636","session_id":"d2757dd6dad94f3b9fe67e8dbf1adc37","source":"clob_market_ws"},"received_at":"2026-07-28T02:13:12.674290Z","record_id":"3918a9b928f14bbaf78a1b14b85ecf6fe387d5db98cdb6368089fe66913366b2","schema_fingerprint":"4aa3821a28b0b7c2400bc59aba4bcc0a76e971dadd19610d3ad38c768e124dc7","schema_version":"edge-lab-recorder.raw.v1","sequence":null,"source":"clob_market_ws"}
{"event_at":"2026-07-28T02:13:12.636000Z","event_fingerprint":"6040ef3391ced7d9decb271770c604953434f7cc43e47aad94c57c60c9a9b7e7","payload":{"connection_id":"5d29200f65794d4d9ab6ef271f045a9b","event_at":"2026-07-28T02:13:12.636000Z","event_type":"price_change","frame_hash":"30714caea4bea82bb35ab796b22d6c746e57b7f09987f6f366bfae223baa01c1","frame_index":0,"kind":"data","monotonic_ns":306775687780916,"payload":{"event_type":"price_change","market":"0xda6f0e0e93fc8469e0159a166028d017bddbc162b86f66bac90391379603d962","price_changes":[{"asset_id":"39272994714739463168905443499424551362424437245880253267329605556587274644733","best_ask":"0.28","best_bid":"0.27","hash":"f22330b5d5aab668c04e03cef9cb0ddf8b51f0b9","price":"0.28","side":"SELL","size":"17.98"},{"asset_id":"20893381255801015515826997628594359667013752732428989472914000440642900266717","best_ask":"0.73","best_bid":"0.72","hash":"c7f7af0bccf889b3e82e6dd70d2d91d121cfae8d","price":"0.72","side":"BUY","size":"17.98"}],"timestamp":"1785204792636"},"payload_hash":"1ec35f1e31dcf9f8f4d9130b60440e8974eb7e231b4e236152ef2c5a414a9655","raw_frame":"{\"market\":\"0xda6f0e0e93fc8469e0159a166028d017bddbc162b86f66bac90391379603d962\", \"price_changes\":[{\"asset_id\":\"39272994714739463168905443499424551362424437245880253267329605556587274644733\", \"price\":\"0.28\", \"size\":\"17.98\", \"side\":\"SELL\", \"hash\":\"f22330b5d5aab668c04e03cef9cb0ddf8b51f0b9\", \"best_bid\":\"0.27\", \"best_ask\":\"0.28\"}, {\"asset_id\":\"20893381255801015515826997628594359667013752732428989472914000440642900266717\", \"price\":\"0.72\", \"size\":\"17.98\", \"side\":\"BUY\", \"hash\":\"c7f7af0bccf889b3e82e6dd70d2d91d121cfae8d\", \"best_bid\":\"0.72\", \"best_ask\":\"0.73\"}], \"timestamp\":\"1785204792636\", \"event_type\":\"price_change\"}","received_at":"2026-07-28T02:13:12.676882Z","schema_version":"clob-market-ws.price_change.v1","sequence":null,"server_hash":null,"server_timestamp":"1785204792636","session_id":"d2757dd6dad94f3b9fe67e8dbf1adc37","source":"clob_market_ws"},"received_at":"2026-07-28T02:13:12.676882Z","record_id":"846e8b83fbf330516459b7d4f15b6dcb45a76003fb4683507d094dd54f864f89","schema_fingerprint":"4aa3821a28b0b7c2400bc59aba4bcc0a76e971dadd19610d3ad38c768e124dc7","schema_version":"edge-lab-recorder.raw.v1","sequence":null,"source":"clob_market_ws"}
{"event_at":"2026-07-28T02:13:12.636000Z","event_fingerprint":"8eed702f85617bc4d478c2d2ea16187628d705143dbad50b499a1f6abafcb04e","payload":{"connection_id":"5d29200f65794d4d9ab6ef271f045a9b","event_at":"2026-07-28T02:13:12.636000Z","event_type":"price_change","frame_hash":"55cdc22f6d74552826eee48339fc6b1695ccb26b84788522c92899001dd5fcff","frame_index":0,"kind":"data","monotonic_ns":306775689996541,"payload":{"event_type":"price_change","market":"0xda6f0e0e93fc8469e0159a166028d017bddbc162b86f66bac90391379603d962","price_changes":[{"asset_id":"20893381255801015515826997628594359667013752732428989472914000440642900266717","best_ask":"0.73","best_bid":"0.72","hash":"391875b7681e8350cb7da6c0bcccd77e6d896f4e","price":"0.03","side":"BUY","size":"554"},{"asset_id":"39272994714739463168905443499424551362424437245880253267329605556587274644733","best_ask":"0.28","best_bid":"0.27","hash":"b3e7281d1cfe38b9d216dc41c3052b33ea009869","price":"0.97","side":"SELL","size":"554"}],"timestamp":"1785204792636"},"payload_hash":"6e07e3823bda89cf7bdd902a995578bd9c9e72272cd69f57be7f61b9d199c257","raw_frame":"{\"market\":\"0xda6f0e0e93fc8469e0159a166028d017bddbc162b86f66bac90391379603d962\", \"price_changes\":[{\"asset_id\":\"20893381255801015515826997628594359667013752732428989472914000440642900266717\", \"price\":\"0.03\", \"size\":\"554\", \"side\":\"BUY\", \"hash\":\"391875b7681e8350cb7da6c0bcccd77e6d896f4e\", \"best_bid\":\"0.72\", \"best_ask\":\"0.73\"}, {\"asset_id\":\"39272994714739463168905443499424551362424437245880253267329605556587274644733\", \"price\":\"0.97\", \"size\":\"554\", \"side\":\"SELL\", \"hash\":\"b3e7281d1cfe38b9d216dc41c3052b33ea009869\", \"best_bid\":\"0.27\", \"best_ask\":\"0.28\"}], \"timestamp\":\"1785204792636\", \"event_type\":\"price_change\"}","received_at":"2026-07-28T02:13:12.679097Z","schema_version":"clob-market-ws.price_change.v1","sequence":null,"server_hash":null,"server_timestamp":"1785204792636","session_id":"d2757dd6dad94f3b9fe67e8dbf1adc37","source":"clob_market_ws"},"received_at":"2026-07-28T02:13:12.679097Z","record_id":"8dc485d6bbac1d0bf8f23bb40804667ed1d186b310a10063c11e409484624a5d","schema_fingerprint":"4aa3821a28b0b7c2400bc59aba4bcc0a76e971dadd19610d3ad38c768e124dc7","schema_version":"edge-lab-recorder.raw.v1","sequence":null,"source":"clob_market_ws"}
{"event_at":"2026-07-28T02:13:12.640000Z","event_fingerprint":"4867d66f30a5b35bc5a0ddf0aad1afcdb6f1120c466d3fdcbb4312f54187daec","payload":{"connection_id":"5d29200f65794d4d9ab6ef271f045a9b","event_at":"2026-07-28T02:13:12.640000Z","event_type":"price_change","frame_hash":"9defcfd8744ead9e0b3ac4441e39f7108f37673e02590d4d4b26c6e702d4a563","frame_index":0,"kind":"data","monotonic_ns":306775692040958,"payload":{"event_type":"price_change","market":"0xda6f0e0e93fc8469e0159a166028d017bddbc162b86f66bac90391379603d962","price_changes":[{"asset_id":"20893381255801015515826997628594359667013752732428989472914000440642900266717","best_ask":"0.73","best_bid":"0.72","hash":"57b7c186a0be7bedccb10e7713cb194048daabd3","price":"0.72","side":"BUY","size":"24.16"},{"asset_id":"39272994714739463168905443499424551362424437245880253267329605556587274644733","best_ask":"0.28","best_bid":"0.27","hash":"98d1249c1d96f1f6d90b2db5aa69feaeb1e6a732","price":"0.28","side":"SELL","size":"24.16"}],"timestamp":"1785204792640"},"payload_hash":"1611483f494578ff7139347f8d802ef7963df41b7567629d0526dc94d6a1b535","raw_frame":"{\"market\":\"0xda6f0e0e93fc8469e0159a166028d017bddbc162b86f66bac90391379603d962\", \"price_changes\":[{\"asset_id\":\"20893381255801015515826997628594359667013752732428989472914000440642900266717\", \"price\":\"0.72\", \"size\":\"24.16\", \"side\":\"BUY\", \"hash\":\"57b7c186a0be7bedccb10e7713cb194048daabd3\", \"best_bid\":\"0.72\", \"best_ask\":\"0.73\"}, {\"asset_id\":\"39272994714739463168905443499424551362424437245880253267329605556587274644733\", \"price\":\"0.28\", \"size\":\"24.16\", \"side\":\"SELL\", \"hash\":\"98d1249c1d96f1f6d90b2db5aa69feaeb1e6a732\", \"best_bid\":\"0.27\", \"best_ask\":\"0.28\"}], \"timestamp\":\"1785204792640\", \"event_type\":\"price_change\"}","received_at":"2026-07-28T02:13:12.681135Z","schema_version":"clob-market-ws.price_change.v1","sequence":null,"server_hash":null,"server_timestamp":"1785204792640","session_id":"d2757dd6dad94f3b9fe67e8dbf1adc37","source":"clob_market_ws"},"received_at":"2026-07-28T02:13:12.681135Z","record_id":"0dd53a5e77c03024108e2105a3b5ccb7be86ba1fb868288ae122b9bd12b87181","schema_fingerprint":"4aa3821a28b0b7c2400bc59aba4bcc0a76e971dadd19610d3ad38c768e124dc7","schema_version":"edge-lab-recorder.raw.v1","sequence":null,"source":"clob_market_ws"}
{"event_at":"2026-07-28T02:13:12.642000Z","event_fingerprint":"9b6786cfaf9d693ffbcdfa0a68b89c01ba232f9aa15312a7a2110d3dd356dbd1","payload":{"connection_id":"5d29200f65794d4d9ab6ef271f045a9b","event_at":"2026-07-28T02:13:12.642000Z","event_type":"price_change","frame_hash":"5454dc4b4d0d78f75ec4eb2ea4f6be6e551f9bc0067cb32ba7e649ef5209a2de","frame_index":0,"kind":"data","monotonic_ns":306775695054583,"payload":{"event_type":"price_change","market":"0xda6f0e0e93fc8469e0159a166028d017bddbc162b86f66bac90391379603d962","price_changes":[{"asset_id":"39272994714739463168905443499424551362424437245880253267329605556587274644733","best_ask":"0.28","best_bid":"0.27","hash":"db3ec3084dbd67e29a4f69dcacc042b7c700cff1","price":"0.12","side":"BUY","size":"303"},{"asset_id":"20893381255801015515826997628594359667013752732428989472914000440642900266717","best_ask":"0.73","best_bid":"0.72","hash":"a2b4495fca3ff5b43a4a9a723b37d2d257616dbb","price":"0.88","side":"SELL","size":"303"}],"timestamp":"1785204792642"},"payload_hash":"97c06a84508c5f21bc0e45787fa857a43ed8f84607814c3edfac37860c8dee74","raw_frame":"{\"market\":\"0xda6f0e0e93fc8469e0159a166028d017bddbc162b86f66bac90391379603d962\", \"price_changes\":[{\"asset_id\":\"39272994714739463168905443499424551362424437245880253267329605556587274644733\", \"price\":\"0.12\", \"size\":\"303\", \"side\":\"BUY\", \"hash\":\"db3ec3084dbd67e29a4f69dcacc042b7c700cff1\", \"best_bid\":\"0.27\", \"best_ask\":\"0.28\"}, {\"asset_id\":\"20893381255801015515826997628594359667013752732428989472914000440642900266717\", \"price\":\"0.88\", \"size\":\"303\", \"side\":\"SELL\", \"hash\":\"a2b4495fca3ff5b43a4a9a723b37d2d257616dbb\", \"best_bid\":\"0.72\", \"best_ask\":\"0.73\"}], \"timestamp\":\"1785204792642\", \"event_type\":\"price_change\"}","received_at":"2026-07-28T02:13:12.684149Z","schema_version":"clob-market-ws.price_change.v1","sequence":null,"server_hash":null,"server_timestamp":"1785204792642","session_id":"d2757dd6dad94f3b9fe67e8dbf1adc37","source":"clob_market_ws"},"received_at":"2026-07-28T02:13:12.684149Z","record_id":"a9d53930a63debd88e6f8720ee238aa38de8edb255b03f39e5201b66f03945ed","schema_fingerprint":"4aa3821a28b0b7c2400bc59aba4bcc0a76e971dadd19610d3ad38c768e124dc7","schema_version":"edge-lab-recorder.raw.v1","sequence":null,"source":"clob_market_ws"}
{"event_at":"2026-07-28T02:13:12.645000Z","event_fingerprint":"8fdc6f77b4caa9e7c64fa6032b97a3d82588770b2104272247fc4a659d0f7de8","payload":{"connection_id":"5d29200f65794d4d9ab6ef271f045a9b","event_at":"2026-07-28T02:13:12.645000Z","event_type":"price_change","frame_hash":"731ef215696a8165c8fe8eb31ec34ebb9f1e335733445e2e833121e72d1c161d","frame_index":0,"kind":"data","monotonic_ns":306775697955750,"payload":{"event_type":"price_change","market":"0xda6f0e0e93fc8469e0159a166028d017bddbc162b86f66bac90391379603d962","price_changes":[{"asset_id":"20893381255801015515826997628594359667013752732428989472914000440642900266717","best_ask":"0.73","best_bid":"0.72","hash":"14871ca552af0d6e93f635de224ab8f1b3a641a8","price":"0.72","side":"BUY","size":"105.16"},{"asset_id":"39272994714739463168905443499424551362424437245880253267329605556587274644733","best_ask":"0.28","best_bid":"0.27","hash":"70d8d5e33eeef779048a1cc5a11552143978d5f8","price":"0.28","side":"SELL","size":"105.16"}],"timestamp":"1785204792645"},"payload_hash":"eed72fe39087545bc31160edb0c4e04de86b1ec5e4683475d83b140b92db2599","raw_frame":"{\"market\":\"0xda6f0e0e93fc8469e0159a166028d017bddbc162b86f66bac90391379603d962\", \"price_changes\":[{\"asset_id\":\"20893381255801015515826997628594359667013752732428989472914000440642900266717\", \"price\":\"0.72\", \"size\":\"105.16\", \"side\":\"BUY\", \"hash\":\"14871ca552af0d6e93f635de224ab8f1b3a641a8\", \"best_bid\":\"0.72\", \"best_ask\":\"0.73\"}, {\"asset_id\":\"39272994714739463168905443499424551362424437245880253267329605556587274644733\", \"price\":\"0.28\", \"size\":\"105.16\", \"side\":\"SELL\", \"hash\":\"70d8d5e33eeef779048a1cc5a11552143978d5f8\", \"best_bid\":\"0.27\", \"best_ask\":\"0.28\"}], \"timestamp\":\"1785204792645\", \"event_type\":\"price_change\"}","received_at":"2026-07-28T02:13:12.687050Z","schema_version":"clob-market-ws.price_change.v1","sequence":null,"server_hash":null,"server_timestamp":"1785204792645","session_id":"d2757dd6dad94f3b9fe67e8dbf1adc37","source":"clob_market_ws"},"received_at":"2026-07-28T02:13:12.687050Z","record_id":"3f7ee2d73e54f97c50fa24311671eefb33b28a16354f999a62824821c64a5978","schema_fingerprint":"4aa3821a28b0b7c2400bc59aba4bcc0a76e971dadd19610d3ad38c768e124dc7","schema_version":"edge-lab-recorder.raw.v1","sequence":null,"source":"clob_market_ws"}
{"event_at":"2026-07-28T02:13:12.646000Z","event_fingerprint":"3785e8d6cecc6ff4ad942bcd066db4324b01a2abbd6a886b26124e8e0c763a1c","payload":{"connection_id":"5d29200f65794d4d9ab6ef271f045a9b","event_at":"2026-07-28T02:13:12.646000Z","event_type":"price_change","frame_hash":"57aacd12a94ba580c295c46437b354918b79fa17c803d9810a33d928f947d791","frame_index":0,"kind":"data","monotonic_ns":306775700941333,"payload":{"event_type":"price_change","market":"0xda6f0e0e93fc8469e0159a166028d017bddbc162b86f66bac90391379603d962","price_changes":[{"asset_id":"39272994714739463168905443499424551362424437245880253267329605556587274644733","best_ask":"0.28","best_bid":"0.27","hash":"c1d16734016fbd3cc11606318de8f29a92f0bd79","price":"0.18","side":"BUY","size":"172.99"},{"asset_id":"20893381255801015515826997628594359667013752732428989472914000440642900266717","best_ask":"0.73","best_bid":"0.72","hash":"79e5f2cb6384fafd9c18c1a02fdcd370104275d4","price":"0.82","side":"SELL","size":"172.99"}],"timestamp":"1785204792646"},"payload_hash":"049d59c1ecf11ac4023df0b9e0253704491aec4e0081c2b29d10a8bec0860552","raw_frame":"{\"market\":\"0xda6f0e0e93fc8469e0159a166028d017bddbc162b86f66bac90391379603d962\", \"price_changes\":[{\"asset_id\":\"39272994714739463168905443499424551362424437245880253267329605556587274644733\", \"price\":\"0.18\", \"size\":\"172.99\", \"side\":\"BUY\", \"hash\":\"c1d16734016fbd3cc11606318de8f29a92f0bd79\", \"best_bid\":\"0.27\", \"best_ask\":\"0.28\"}, {\"asset_id\":\"20893381255801015515826997628594359667013752732428989472914000440642900266717\", \"price\":\"0.82\", \"size\":\"172.99\", \"side\":\"SELL\", \"hash\":\"79e5f2cb6384fafd9c18c1a02fdcd370104275d4\", \"best_bid\":\"0.72\", \"best_ask\":\"0.73\"}], \"timestamp\":\"1785204792646\", \"event_type\":\"price_change\"}","received_at":"2026-07-28T02:13:12.690035Z","schema_version":"clob-market-ws.price_change.v1","sequence":null,"server_hash":null,"server_timestamp":"1785204792646","session_id":"d2757dd6dad94f3b9fe67e8dbf1adc37","source":"clob_market_ws"},"received_at":"2026-07-28T02:13:12.690035Z","record_id":"cd8e0e9446ceb63e9fdb19a97a971e0950971d9e9049fa8b2f9ea245475c0acb","schema_fingerprint":"4aa3821a28b0b7c2400bc59aba4bcc0a76e971dadd19610d3ad38c768e124dc7","schema_version":"edge-lab-recorder.raw.v1","sequence":null,"source":"clob_market_ws"}
{"event_at":"2026-07-28T02:13:12.647000Z","event_fingerprint":"cde8f0ec5c10009262a08ac54c519e1f731401375a2208e02ead1cc6cd2e76f9","payload":{"connection_id":"5d29200f65794d4d9ab6ef271f045a9b","event_at":"2026-07-28T02:13:12.647000Z","event_type":"price_change","frame_hash":"b5d20d3fc6712f5b9e25d95fcc6540887086f24b6b0f812b5d1596f48f083e16","frame_index":0,"kind":"data","monotonic_ns":306775702534125,"payload":{"event_type":"price_change","market":"0xda6f0e0e93fc8469e0159a166028d017bddbc162b86f66bac90391379603d962","price_changes":[{"asset_id":"39272994714739463168905443499424551362424437245880253267329605556587274644733","best_ask":"0.28","best_bid":"0.27","hash":"8d69a3c423aa2929e2afeaf6536da9b38e009c72","price":"0.27","side":"BUY","size":"85"},{"asset_id":"20893381255801015515826997628594359667013752732428989472914000440642900266717","best_ask":"0.73","best_bid":"0.72","hash":"b328f30664692661e9a73cbda84a90062ddb4a44","price":"0.73","side":"SELL","size":"85"}],"timestamp":"1785204792647"},"payload_hash":"da51d5683aa25564b152e6999cc23ad93e5fb54227b52572d8a05acdff036240","raw_frame":"{\"market\":\"0xda6f0e0e93fc8469e0159a166028d017bddbc162b86f66bac90391379603d962\", \"price_changes\":[{\"asset_id\":\"39272994714739463168905443499424551362424437245880253267329605556587274644733\", \"price\":\"0.27\", \"size\":\"85\", \"side\":\"BUY\", \"hash\":\"8d69a3c423aa2929e2afeaf6536da9b38e009c72\", \"best_bid\":\"0.27\", \"best_ask\":\"0.28\"}, {\"asset_id\":\"20893381255801015515826997628594359667013752732428989472914000440642900266717\", \"price\":\"0.73\", \"size\":\"85\", \"side\":\"SELL\", \"hash\":\"b328f30664692661e9a73cbda84a90062ddb4a44\", \"best_bid\":\"0.72\", \"best_ask\":\"0.73\"}], \"timestamp\":\"1785204792647\", \"event_type\":\"price_change\"}","received_at":"2026-07-28T02:13:12.691634Z","schema_version":"clob-market-ws.price_change.v1","sequence":null,"server_hash":null,"server_timestamp":"1785204792647","session_id":"d2757dd6dad94f3b9fe67e8dbf1adc37","source":"clob_market_ws"},"received_at":"2026-07-28T02:13:12.691634Z","record_id":"8d53058e7a0689480368a06c572bebcb3e625017faccd342f7b68138c17db603","schema_fingerprint":"4aa3821a28b0b7c2400bc59aba4bcc0a76e971dadd19610d3ad38c768e124dc7","schema_version":"edge-lab-recorder.raw.v1","sequence":null,"source":"clob_market_ws"}
{"event_at":"2026-07-28T02:13:12.652000Z","event_fingerprint":"169d2745420b1981a4849181fe24c1f993bd2368541fdd50ff40e4237b12bf3d","payload":{"connection_id":"5d29200f65794d4d9ab6ef271f045a9b","event_at":"2026-07-28T02:13:12.652000Z","event_type":"price_change","frame_hash":"e4e380f71c364180732b3111f6371dee0177999b807bb59d751a4a6c3000150f","frame_index":0,"kind":"data","monotonic_ns":306775705891708,"payload":{"event_type":"price_change","market":"0xda6f0e0e93fc8469e0159a166028d017bddbc162b86f66bac90391379603d962","price_changes":[{"asset_id":"20893381255801015515826997628594359667013752732428989472914000440642900266717","best_ask":"0.73","best_bid":"0.72","hash":"f710ff21a97692e19e79b09880f7b378f58ad31c","price":"0.01","side":"BUY","size":"5374.02"},{"asset_id":"39272994714739463168905443499424551362424437245880253267329605556587274644733","best_ask":"0.28","best_bid":"0.27","hash":"4b45c3fabf0a8dae41c99612c46dbf4c4cb7d574","price":"0.99","side":"SELL","size":"5374.02"}],"timestamp":"1785204792652"},"payload_hash":"872292bbb0da60ab4b0b60040042c58279a6b6eacc629ac0039ccd32d49f694e","raw_frame":"{\"market\":\"0xda6f0e0e93fc8469e0159a166028d017bddbc162b86f66bac90391379603d962\", \"price_changes\":[{\"asset_id\":\"20893381255801015515826997628594359667013752732428989472914000440642900266717\", \"price\":\"0.01\", \"size\":\"5374.02\", \"side\":\"BUY\", \"hash\":\"f710ff21a97692e19e79b09880f7b378f58ad31c\", \"best_bid\":\"0.72\", \"best_ask\":\"0.73\"}, {\"asset_id\":\"39272994714739463168905443499424551362424437245880253267329605556587274644733\", \"price\":\"0.99\", \"size\":\"5374.02\", \"side\":\"SELL\", \"hash\":\"4b45c3fabf0a8dae41c99612c46dbf4c4cb7d574\", \"best_bid\":\"0.27\", \"best_ask\":\"0.28\"}], \"timestamp\":\"1785204792652\", \"event_type\":\"price_change\"}","received_at":"2026-07-28T02:13:12.694986Z","schema_version":"clob-market-ws.price_change.v1","sequence":null,"server_hash":null,"server_timestamp":"1785204792652","session_id":"d2757dd6dad94f3b9fe67e8dbf1adc37","source":"clob_market_ws"},"received_at":"2026-07-28T02:13:12.694986Z","record_id":"d7710da90a9d8298b93d7d3606484c4c4b1a6bdf94417abf4ec244746fbcd53a","schema_fingerprint":"4aa3821a28b0b7c2400bc59aba4bcc0a76e971dadd19610d3ad38c768e124dc7","schema_version":"edge-lab-recorder.raw.v1","sequence":null,"source":"clob_market_ws"}
{"event_at":"2026-07-28T02:13:12.655000Z","event_fingerprint":"0a6f46f9f5d340a9f3fd17b6f95ce1f511bdae8ec2b498fe04e952cdcddb787d","payload":{"connection_id":"5d29200f65794d4d9ab6ef271f045a9b","event_at":"2026-07-28T02:13:12.655000Z","event_type":"price_change","frame_hash":"d26472df06fa35a37703dfe062dac64e4c09f21dad2202102ddf734b5caa2cd1","frame_index":0,"kind":"data","monotonic_ns":306775710010791,"payload":{"event_type":"price_change","market":"0xda6f0e0e93fc8469e0159a166028d017bddbc162b86f66bac90391379603d962","price_changes":[{"asset_id":"39272994714739463168905443499424551362424437245880253267329605556587274644733","best_ask":"0.28","best_bid":"0.27","hash":"015ff0bb931c5032fe16a4c4516ffec2e0d0d752","price":"0.27","side":"BUY","size":"91"},{"asset_id":"20893381255801015515826997628594359667013752732428989472914000440642900266717","best_ask":"0.73","best_bid":"0.72","hash":"69554045cb2ef296e7f4429d59116eb422a40a00","price":"0.73","side":"SELL","size":"91"}],"timestamp":"1785204792655"},"payload_hash":"e9b7d7169515457b70a9881174e5793180456a08769eae21c30920df3ca93668","raw_frame":"{\"market\":\"0xda6f0e0e93fc8469e0159a166028d017bddbc162b86f66bac90391379603d962\", \"price_changes\":[{\"asset_id\":\"39272994714739463168905443499424551362424437245880253267329605556587274644733\", \"price\":\"0.27\", \"size\":\"91\", \"side\":\"BUY\", \"hash\":\"015ff0bb931c5032fe16a4c4516ffec2e0d0d752\", \"best_bid\":\"0.27\", \"best_ask\":\"0.28\"}, {\"asset_id\":\"20893381255801015515826997628594359667013752732428989472914000440642900266717\", \"price\":\"0.73\", \"size\":\"91\", \"side\":\"SELL\", \"hash\":\"69554045cb2ef296e7f4429d59116eb422a40a00\", \"best_bid\":\"0.72\", \"best_ask\":\"0.73\"}], \"timestamp\":\"1785204792655\", \"event_type\":\"price_change\"}","received_at":"2026-07-28T02:13:12.699106Z","schema_version":"clob-market-ws.price_change.v1","sequence":null,"server_hash":null,"server_timestamp":"1785204792655","session_id":"d2757dd6dad94f3b9fe67e8dbf1adc37","source":"clob_market_ws"},"received_at":"2026-07-28T02:13:12.699106Z","record_id":"10799fbca31cc5f7d71b56a3028e5de5e1d2c3a1b543b499fb639169e0f41361","schema_fingerprint":"4aa3821a28b0b7c2400bc59aba4bcc0a76e971dadd19610d3ad38c768e124dc7","schema_version":"edge-lab-recorder.raw.v1","sequence":null,"source":"clob_market_ws"}
{"event_at":"2026-07-28T02:13:12.657000Z","event_fingerprint":"8c7e0a6f493d962e986930d6521a5ead05efd050e33e7e87ee1c54a67af3804f","payload":{"connection_id":"5d29200f65794d4d9ab6ef271f045a9b","event_at":"2026-07-28T02:13:12.657000Z","event_type":"price_change","frame_hash":"00dfb91b4cb6b18cb5da53ee2104e0eaee3b3b23d814c6d7bb6cd864e2bdc999","frame_index":0,"kind":"data","monotonic_ns":306775714364500,"payload":{"event_type":"price_change","market":"0xda6f0e0e93fc8469e0159a166028d017bddbc162b86f66bac90391379603d962","price_changes":[{"asset_id":"39272994714739463168905443499424551362424437245880253267329605556587274644733","best_ask":"0.28","best_bid":"0.27","hash":"4500f65d6bfc7ed94eae7b5a0481338ea01f5389","price":"0.04","side":"BUY","size":"1409.9"},{"asset_id":"20893381255801015515826997628594359667013752732428989472914000440642900266717","best_ask":"0.73","best_bid":"0.72","hash":"ecde892803f524565022dfe4584d936a69bb6c87","price":"0.96","side":"SELL","size":"1409.9"}],"timestamp":"1785204792657"},"payload_hash":"f5f8c12b9386952c8c767433d725568f9717fe2bf4b58e8b5aeeac541920836c","raw_frame":"{\"market\":\"0xda6f0e0e93fc8469e0159a166028d017bddbc162b86f66bac90391379603d962\", \"price_changes\":[{\"asset_id\":\"39272994714739463168905443499424551362424437245880253267329605556587274644733\", \"price\":\"0.04\", \"size\":\"1409.9\", \"side\":\"BUY\", \"hash\":\"4500f65d6bfc7ed94eae7b5a0481338ea01f5389\", \"best_bid\":\"0.27\", \"best_ask\":\"0.28\"}, {\"asset_id\":\"20893381255801015515826997628594359667013752732428989472914000440642900266717\", \"price\":\"0.96\", \"size\":\"1409.9\", \"side\":\"SELL\", \"hash\":\"ecde892803f524565022dfe4584d936a69bb6c87\", \"best_bid\":\"0.72\", \"best_ask\":\"0.73\"}], \"timestamp\":\"1785204792657\", \"event_type\":\"price_change\"}","received_at":"2026-07-28T02:13:12.703457Z","schema_version":"clob-market-ws.price_change.v1","sequence":null,"server_hash":null,"server_timestamp":"1785204792657","session_id":"d2757dd6dad94f3b9fe67e8dbf1adc37","source":"clob_market_ws"},"received_at":"2026-07-28T02:13:12.703457Z","record_id":"1339673b2e6f6e72b330370022606ca1386a78ccee7f3dd8f57eb0f3da8a4f10","schema_fingerprint":"4aa3821a28b0b7c2400bc59aba4bcc0a76e971dadd19610d3ad38c768e124dc7","schema_version":"edge-lab-recorder.raw.v1","sequence":null,"source":"clob_market_ws"}
{"event_at":"2026-07-28T02:13:12.659000Z","event_fingerprint":"807294344993528cb97a307e38d9b437866e913f436bd44158765d81f1aff70a","payload":{"connection_id":"5d29200f65794d4d9ab6ef271f045a9b","event_at":"2026-07-28T02:13:12.659000Z","event_type":"price_change","frame_hash":"eb8658f3936ea4a1ad01714df9f9790acf90a5f7eec48c687a1206a7b0ae4162","frame_index":0,"kind":"data","monotonic_ns":306775725621750,"payload":{"event_type":"price_change","market":"0xda6f0e0e93fc8469e0159a166028d017bddbc162b86f66bac90391379603d962","price_changes":[{"asset_id":"20893381255801015515826997628594359667013752732428989472914000440642900266717","best_ask":"0.73","best_bid":"0.72","hash":"2de43c5eb9fbe181ea47e2719e6f1ae090fd0b08","price":"0.59","side":"BUY","size":"139"},{"asset_id":"39272994714739463168905443499424551362424437245880253267329605556587274644733","best_ask":"0.28","best_bid":"0.27","hash":"e5fb5cf0871fc643723ecb08db718da502231982","price":"0.41","side":"SELL","size":"139"}],"timestamp":"1785204792659"},"payload_hash":"7d74ddc8df2a26f397e135167f0dd5beda9f8144a61133630f12bd2a50416975","raw_frame":"{\"market\":\"0xda6f0e0e93fc8469e0159a166028d017bddbc162b86f66bac90391379603d962\", \"price_changes\":[{\"asset_id\":\"20893381255801015515826997628594359667013752732428989472914000440642900266717\", \"price\":\"0.59\", \"size\":\"139\", \"side\":\"BUY\", \"hash\":\"2de43c5eb9fbe181ea47e2719e6f1ae090fd0b08\", \"best_bid\":\"0.72\", \"best_ask\":\"0.73\"}, {\"asset_id\":\"39272994714739463168905443499424551362424437245880253267329605556587274644733\", \"price\":\"0.41\", \"size\":\"139\", \"side\":\"SELL\", \"hash\":\"e5fb5cf0871fc643723ecb08db718da502231982\", \"best_bid\":\"0.27\", \"best_ask\":\"0.28\"}], \"timestamp\":\"1785204792659\", \"event_type\":\"price_change\"}","received_at":"2026-07-28T02:13:12.714715Z","schema_version":"clob-market-ws.price_change.v1","sequence":null,"server_hash":null,"server_timestamp":"1785204792659","session_id":"d2757dd6dad94f3b9fe67e8dbf1adc37","source":"clob_market_ws"},"received_at":"2026-07-28T02:13:12.714715Z","record_id":"b13e5c9be5aad0579152b95dd02707f093d258fe42c67d2f5a55d31d16b6d9b9","schema_fingerprint":"4aa3821a28b0b7c2400bc59aba4bcc0a76e971dadd19610d3ad38c768e124dc7","schema_version":"edge-lab-recorder.raw.v1","sequence":null,"source":"clob_market_ws"}
{"event_at":"2026-07-28T02:13:12.660000Z","event_fingerprint":"cc709ad396d3a6e3bcd46e981350cd30fc3410b7e0818ecad2489d2805d760e1","payload":{"connection_id":"5d29200f65794d4d9ab6ef271f045a9b","event_at":"2026-07-28T02:13:12.660000Z","event_type":"price_change","frame_hash":"4a9462b41764ab3704816fa7ae2d3100b963b4bb1034395d226eb672bd194a66","frame_index":0,"kind":"data","monotonic_ns":306775728892625,"payload":{"event_type":"price_change","market":"0xda6f0e0e93fc8469e0159a166028d017bddbc162b86f66bac90391379603d962","price_changes":[{"asset_id":"20893381255801015515826997628594359667013752732428989472914000440642900266717","best_ask":"0.73","best_bid":"0.72","hash":"c5eb156021220e5c0b61d325c3f6882adbf8bd45","price":"0.28","side":"BUY","size":"303.88"},{"asset_id":"39272994714739463168905443499424551362424437245880253267329605556587274644733","best_ask":"0.28","best_bid":"0.27","hash":"52cfaaeebee9b3b3416914c6e7da9c64dfca63fd","price":"0.72","side":"SELL","size":"303.88"}],"timestamp":"1785204792660"},"payload_hash":"7c123611d0f22b1492f92fc0b3770f7acb2672c96231510abf11eabfc7ffd15c","raw_frame":"{\"market\":\"0xda6f0e0e93fc8469e0159a166028d017bddbc162b86f66bac90391379603d962\", \"price_changes\":[{\"asset_id\":\"20893381255801015515826997628594359667013752732428989472914000440642900266717\", \"price\":\"0.28\", \"size\":\"303.88\", \"side\":\"BUY\", \"hash\":\"c5eb156021220e5c0b61d325c3f6882adbf8bd45\", \"best_bid\":\"0.72\", \"best_ask\":\"0.73\"}, {\"asset_id\":\"39272994714739463168905443499424551362424437245880253267329605556587274644733\", \"price\":\"0.72\", \"size\":\"303.88\", \"side\":\"SELL\", \"hash\":\"52cfaaeebee9b3b3416914c6e7da9c64dfca63fd\", \"best_bid\":\"0.27\", \"best_ask\":\"0.28\"}], \"timestamp\":\"1785204792660\", \"event_type\":\"price_change\"}","received_at":"2026-07-28T02:13:12.717985Z","schema_version":"clob-market-ws.price_change.v1","sequence":null,"server_hash":null,"server_timestamp":"1785204792660","session_id":"d2757dd6dad94f3b9fe67e8dbf1adc37","source":"clob_market_ws"},"received_at":"2026-07-28T02:13:12.717985Z","record_id":"5de95b5f8672309615e97f20d3924ea20e9ba401e1bbc927e24b469a3892fb1f","schema_fingerprint":"4aa3821a28b0b7c2400bc59aba4bcc0a76e971dadd19610d3ad38c768e124dc7","schema_version":"edge-lab-recorder.raw.v1","sequence":null,"source":"clob_market_ws"}
{"event_at":"2026-07-28T02:13:12.661000Z","event_fingerprint":"884a8e7f6b3294517320d42ef6b35f2d143df58c00d12e7e06249d29120c44d9","payload":{"connection_id":"5d29200f65794d4d9ab6ef271f045a9b","event_at":"2026-07-28T02:13:12.661000Z","event_type":"price_change","frame_hash":"3ce612de5fcb273e2fbc938e8ef4e7695969a628f9f7d4b8827190e70a95f5e7","frame_index":0,"kind":"data","monotonic_ns":306775731909500,"payload":{"event_type":"price_change","market":"0xda6f0e0e93fc8469e0159a166028d017bddbc162b86f66bac90391379603d962","price_changes":[{"asset_id":"39272994714739463168905443499424551362424437245880253267329605556587274644733","best_ask":"0.28","best_bid":"0.27","hash":"746128fab3da088550c8de33510b6ee3eb3e329e","price":"0.18","side":"BUY","size":"202.99"},{"asset_id":"20893381255801015515826997628594359667013752732428989472914000440642900266717","best_ask":"0.73","best_bid":"0.72","hash":"28fd1ff6b6e33c8eabcba7fdb1dad83a91511d6f","price":"0.82","side":"SELL","size":"202.99"}],"timestamp":"1785204792661"},"payload_hash":"3404c6b9ae32faf5fe80026e1cf211513481d77461d4b0162559f7449d99c9f0","raw_frame":"{\"market\":\"0xda6f0e0e93fc8469e0159a166028d017bddbc162b86f66bac90391379603d962\", \"price_changes\":[{\"asset_id\":\"39272994714739463168905443499424551362424437245880253267329605556587274644733\", \"price\":\"0.18\", \"size\":\"202.99\", \"side\":\"BUY\", \"hash\":\"746128fab3da088550c8de33510b6ee3eb3e329e\", \"best_bid\":\"0.27\", \"best_ask\":\"0.28\"}, {\"asset_id\":\"20893381255801015515826997628594359667013752732428989472914000440642900266717\", \"price\":\"0.82\", \"size\":\"202.99\", \"side\":\"SELL\", \"hash\":\"28fd1ff6b6e33c8eabcba7fdb1dad83a91511d6f\", \"best_bid\":\"0.72\", \"best_ask\":\"0.73\"}], \"timestamp\":\"1785204792661\", \"event_type\":\"price_change\"}","received_at":"2026-07-28T02:13:12.721004Z","schema_version":"clob-market-ws.price_change.v1","sequence":null,"server_hash":null,"server_timestamp":"1785204792661","session_id":"d2757dd6dad94f3b9fe67e8dbf1adc37","source":"clob_market_ws"},"received_at":"2026-07-28T02:13:12.721004Z","record_id":"0808f68ae4f965ca92514ab33985b219b0e524b415f1da78ac71c9af902d761d","schema_fingerprint":"4aa3821a28b0b7c2400bc59aba4bcc0a76e971dadd19610d3ad38c768e124dc7","schema_version":"edge-lab-recorder.raw.v1","sequence":null,"source":"clob_market_ws"}
{"event_at":"2026-07-28T02:13:12.669000Z","event_fingerprint":"f302dbe7b347b9667f1f235add4dac3a13eb2f4d6f2ed04f2ed745d630a4a0ce","payload":{"connection_id":"5d29200f65794d4d9ab6ef271f045a9b","event_at":"2026-07-28T02:13:12.669000Z","event_type":"price_change","frame_hash":"f757a86e879d15ff128a3e933f3956e0f42ce56c1281b0cdbd6c62d7e8893cd4","frame_index":0,"kind":"data","monotonic_ns":306775734891291,"payload":{"event_type":"price_change","market":"0xda6f0e0e93fc8469e0159a166028d017bddbc162b86f66bac90391379603d962","price_changes":[{"asset_id":"20893381255801015515826997628594359667013752732428989472914000440642900266717","best_ask":"0.73","best_bid":"0.72","hash":"f921a049cf1e4f391d3fcb619b30f3c2ec91d837","price":"0.72","side":"BUY","size":"24.16"},{"asset_id":"39272994714739463168905443499424551362424437245880253267329605556587274644733","best_ask":"0.28","best_bid":"0.27","hash":"b0e9faea2d8d398da0e93983f4e39ae51de009b6","price":"0.28","side":"SELL","size":"24.16"}],"timestamp":"1785204792669"},"payload_hash":"dd6ca470d42c880fe4a87f2e70476a3a76509794ececfb7ca4ddff72ae0b973f","raw_frame":"{\"market\":\"0xda6f0e0e93fc8469e0159a166028d017bddbc162b86f66bac90391379603d962\", \"price_changes\":[{\"asset_id\":\"20893381255801015515826997628594359667013752732428989472914000440642900266717\", \"price\":\"0.72\", \"size\":\"24.16\", \"side\":\"BUY\", \"hash\":\"f921a049cf1e4f391d3fcb619b30f3c2ec91d837\", \"best_bid\":\"0.72\", \"best_ask\":\"0.73\"}, {\"asset_id\":\"39272994714739463168905443499424551362424437245880253267329605556587274644733\", \"price\":\"0.28\", \"size\":\"24.16\", \"side\":\"SELL\", \"hash\":\"b0e9faea2d8d398da0e93983f4e39ae51de009b6\", \"best_bid\":\"0.27\", \"best_ask\":\"0.28\"}], \"timestamp\":\"1785204792669\", \"event_type\":\"price_change\"}","received_at":"2026-07-28T02:13:12.723985Z","schema_version":"clob-market-ws.price_change.v1","sequence":null,"server_hash":null,"server_timestamp":"1785204792669","session_id":"d2757dd6dad94f3b9fe67e8dbf1adc37","source":"clob_market_ws"},"received_at":"2026-07-28T02:13:12.723985Z","record_id":"ebbbe71be707ffee5c5c06c12f3169548d8174d44c7fa4467ec23f57019a9edd","schema_fingerprint":"4aa3821a28b0b7c2400bc59aba4bcc0a76e971dadd19610d3ad38c768e124dc7","schema_version":"edge-lab-recorder.raw.v1","sequence":null,"source":"clob_market_ws"}
{"event_at":"2026-07-28T02:13:12.671000Z","event_fingerprint":"10b56fe4e03d1c3e382f3b5248e91c7f405d193a4a6f2847b7b6fee465fb0311","payload":{"connection_id":"5d29200f65794d4d9ab6ef271f045a9b","event_at":"2026-07-28T02:13:12.671000Z","event_type":"price_change","frame_hash":"e87790c8e24b7a3e52720d3b30cea4f53ce141b9035c5da76e40547f1c5fd0f3","frame_index":0,"kind":"data","monotonic_ns":306775738974875,"payload":{"event_type":"price_change","market":"0xda6f0e0e93fc8469e0159a166028d017bddbc162b86f66bac90391379603d962","price_changes":[{"asset_id":"20893381255801015515826997628594359667013752732428989472914000440642900266717","best_ask":"0.73","best_bid":"0.72","hash":"415d0c30ea6d8ce926944ecdbbd653f459087d78","price":"0.73","side":"SELL","size":"96"},{"asset_id":"39272994714739463168905443499424551362424437245880253267329605556587274644733","best_ask":"0.28","best_bid":"0.27","hash":"05e2efdcd27d5ff4ba8163d6269173ad46f457bc","price":"0.27","side":"BUY","size":"96"}],"timestamp":"1785204792671"},"payload_hash":"35859f3d5ed73614863e85c3c5c9fbb85c5c22539e51cc6177e67037e800bf11","raw_frame":"{\"market\":\"0xda6f0e0e93fc8469e0159a166028d017bddbc162b86f66bac90391379603d962\", \"price_changes\":[{\"asset_id\":\"20893381255801015515826997628594359667013752732428989472914000440642900266717\", \"price\":\"0.73\", \"size\":\"96\", \"side\":\"SELL\", \"hash\":\"415d0c30ea6d8ce926944ecdbbd653f459087d78\", \"best_bid\":\"0.72\", \"best_ask\":\"0.73\"}, {\"asset_id\":\"39272994714739463168905443499424551362424437245880253267329605556587274644733\", \"price\":\"0.27\", \"size\":\"96\", \"side\":\"BUY\", \"hash\":\"05e2efdcd27d5ff4ba8163d6269173ad46f457bc\", \"best_bid\":\"0.27\", \"best_ask\":\"0.28\"}], \"timestamp\":\"1785204792671\", \"event_type\":\"price_change\"}","received_at":"2026-07-28T02:13:12.728068Z","schema_version":"clob-market-ws.price_change.v1","sequence":null,"server_hash":null,"server_timestamp":"1785204792671","session_id":"d2757dd6dad94f3b9fe67e8dbf1adc37","source":"clob_market_ws"},"received_at":"2026-07-28T02:13:12.728068Z","record_id":"86b72a9a41e5a1183fc3d0c806b6c46b14a69774a4f987e04e17ad798fd459fb","schema_fingerprint":"4aa3821a28b0b7c2400bc59aba4bcc0a76e971dadd19610d3ad38c768e124dc7","schema_version":"edge-lab-recorder.raw.v1","sequence":null,"source":"clob_market_ws"}
{"event_at":"2026-07-28T02:13:12.671000Z","event_fingerprint":"e4d584656e1ed9b60cc56e1efdde6754ad7eea6a83fdcee4c8219c2bca8c002b","payload":{"connection_id":"5d29200f65794d4d9ab6ef271f045a9b","event_at":"2026-07-28T02:13:12.671000Z","event_type":"price_change","frame_hash":"78b5dced0f0c56950627b27175e4d12b788db6ed99ec1430e87325813b03e1fd","frame_index":0,"kind":"data","monotonic_ns":306775741317208,"payload":{"event_type":"price_change","market":"0xda6f0e0e93fc8469e0159a166028d017bddbc162b86f66bac90391379603d962","price_changes":[{"asset_id":"20893381255801015515826997628594359667013752732428989472914000440642900266717","best_ask":"0.73","best_bid":"0.72","hash":"c22a6e09d5f254dc7e4a8f9b5b4b1daa17871f5e","price":"0.73","side":"SELL","size":"102"},{"asset_id":"39272994714739463168905443499424551362424437245880253267329605556587274644733","best_ask":"0.28","best_bid":"0.27","hash":"328a4114983d1fe62b673029c3b0572a5fab83fc","price":"0.27","side":"BUY","size":"102"}],"timestamp":"1785204792671"},"payload_hash":"420ce45b1fe7e82502cb1df492f231ffc32bf957fe065722153e8302eaa1f39c","raw_frame":"{\"market\":\"0xda6f0e0e93fc8469e0159a166028d017bddbc162b86f66bac90391379603d962\", \"price_changes\":[{\"asset_id\":\"20893381255801015515826997628594359667013752732428989472914000440642900266717\", \"price\":\"0.73\", \"size\":\"102\", \"side\":\"SELL\", \"hash\":\"c22a6e09d5f254dc7e4a8f9b5b4b1daa17871f5e\", \"best_bid\":\"0.72\", \"best_ask\":\"0.73\"}, {\"asset_id\":\"39272994714739463168905443499424551362424437245880253267329605556587274644733\", \"price\":\"0.27\", \"size\":\"102\", \"side\":\"BUY\", \"hash\":\"328a4114983d1fe62b673029c3b0572a5fab83fc\", \"best_bid\":\"0.27\", \"best_ask\":\"0.28\"}], \"timestamp\":\"1785204792671\", \"event_type\":\"price_change\"}","received_at":"2026-07-28T02:13:12.730411Z","schema_version":"clob-market-ws.price_change.v1","sequence":null,"server_hash":null,"server_timestamp":"1785204792671","session_id":"d2757dd6dad94f3b9fe67e8dbf1adc37","source":"clob_market_ws"},"received_at":"2026-07-28T02:13:12.730411Z","record_id":"fd16b7c67eb43327105d7080c050ca45d4e046dc4f36cb58805e5349c46ce764","schema_fingerprint":"4aa3821a28b0b7c2400bc59aba4bcc0a76e971dadd19610d3ad38c768e124dc7","schema_version":"edge-lab-recorder.raw.v1","sequence":null,"source":"clob_market_ws"}
{"event_at":"2026-07-28T02:13:12.672000Z","event_fingerprint":"bb34491b7cae9b91eb7cd04abab317de7f3101c01e7ea89f791e56ca32afaec0","payload":{"connection_id":"5d29200f65794d4d9ab6ef271f045a9b","event_at":"2026-07-28T02:13:12.672000Z","event_type":"price_change","frame_hash":"de19db2a762f75059b4defdad177574fee7fdb378c30bda48324d1994b268370","frame_index":0,"kind":"data","monotonic_ns":306775744309458,"payload":{"event_type":"price_change","market":"0xda6f0e0e93fc8469e0159a166028d017bddbc162b86f66bac90391379603d962","price_changes":[{"asset_id":"39272994714739463168905443499424551362424437245880253267329605556587274644733","best_ask":"0.28","best_bid":"0.27","hash":"ef4d20539574a72f79971e273e08a4850f75e081","price":"0.12","side":"BUY","size":"288"},{"asset_id":"20893381255801015515826997628594359667013752732428989472914000440642900266717","best_ask":"0.73","best_bid":"0.72","hash":"64bfcd68f7c070f35054ee95c8832843d0b2e31e","price":"0.88","side":"SELL","size":"288"}],"timestamp":"1785204792672"},"payload_hash":"a01789287491e6166cc05429ef73d5511ef055cafe692a3907a2b3c151fe1d16","raw_frame":"{\"market\":\"0xda6f0e0e93fc8469e0159a166028d017bddbc162b86f66bac90391379603d962\", \"price_changes\":[{\"asset_id\":\"39272994714739463168905443499424551362424437245880253267329605556587274644733\", \"price\":\"0.12\", \"size\":\"288\", \"side\":\"BUY\", \"hash\":\"ef4d20539574a72f79971e273e08a4850f75e081\", \"best_bid\":\"0.27\", \"best_ask\":\"0.28\"}, {\"asset_id\":\"20893381255801015515826997628594359667013752732428989472914000440642900266717\", \"price\":\"0.88\", \"size\":\"288\", \"side\":\"SELL\", \"hash\":\"64bfcd68f7c070f35054ee95c8832843d0b2e31e\", \"best_bid\":\"0.72\", \"best_ask\":\"0.73\"}], \"timestamp\":\"1785204792672\", \"event_type\":\"price_change\"}","received_at":"2026-07-28T02:13:12.733403Z","schema_version":"clob-market-ws.price_change.v1","sequence":null,"server_hash":null,"server_timestamp":"1785204792672","session_id":"d2757dd6dad94f3b9fe67e8dbf1adc37","source":"clob_market_ws"},"received_at":"2026-07-28T02:13:12.733403Z","record_id":"e2c952eec332c98955c4f6780beb94a66811514d84c95014349a63ec8a9fd709","schema_fingerprint":"4aa3821a28b0b7c2400bc59aba4bcc0a76e971dadd19610d3ad38c768e124dc7","schema_version":"edge-lab-recorder.raw.v1","sequence":null,"source":"clob_market_ws"}
{"event_at":"2026-07-28T02:13:12.678000Z","event_fingerprint":"5f50bc78f32efb77f346fd33b37aef7da04f0ac295ee4f56f739465dda7ab825","payload":{"connection_id":"5d29200f65794d4d9ab6ef271f045a9b","event_at":"2026-07-28T02:13:12.678000Z","event_type":"price_change","frame_hash":"cd2d60d2676507b7d66e9ee692b6091803309e64dca123c746702e5f3cc8e95c","frame_index":0,"kind":"data","monotonic_ns":306775745878375,"payload":{"event_type":"price_change","market":"0xda6f0e0e93fc8469e0159a166028d017bddbc162b86f66bac90391379603d962","price_changes":[{"asset_id":"39272994714739463168905443499424551362424437245880253267329605556587274644733","best_ask":"0.28","best_bid":"0.27","hash":"a3178c9b67c9c87b3f5c19bd89995299bef1ce0f","price":"0.27","side":"BUY","size":"73"},{"asset_id":"20893381255801015515826997628594359667013752732428989472914000440642900266717","best_ask":"0.73","best_bid":"0.72","hash":"f3defca396ba06b14d1b748b643f87df409fd60b","price":"0.73","side":"SELL","size":"73"}],"timestamp":"1785204792678"},"payload_hash":"3f41b977b511e18185ec2c9af85363588b77f7821e3d1283de921a56ac42334a","raw_frame":"{\"market\":\"0xda6f0e0e93fc8469e0159a166028d017bddbc162b86f66bac90391379603d962\", \"price_changes\":[{\"asset_id\":\"39272994714739463168905443499424551362424437245880253267329605556587274644733\", \"price\":\"0.27\", \"size\":\"73\", \"side\":\"BUY\", \"hash\":\"a3178c9b67c9c87b3f5c19bd89995299bef1ce0f\", \"best_bid\":\"0.27\", \"best_ask\":\"0.28\"}, {\"asset_id\":\"20893381255801015515826997628594359667013752732428989472914000440642900266717\", \"price\":\"0.73\", \"size\":\"73\", \"side\":\"SELL\", \"hash\":\"f3defca396ba06b14d1b748b643f87df409fd60b\", \"best_bid\":\"0.72\", \"best_ask\":\"0.73\"}], \"timestamp\":\"1785204792678\", \"event_type\":\"price_change\"}","received_at":"2026-07-28T02:13:12.734978Z","schema_version":"clob-market-ws.price_change.v1","sequence":null,"server_hash":null,"server_timestamp":"1785204792678","session_id":"d2757dd6dad94f3b9fe67e8dbf1adc37","source":"clob_market_ws"},"received_at":"2026-07-28T02:13:12.734978Z","record_id":"f05ced42f2c00ae8f1b9769e2e8ce0a86bc5b9f6ec39b9b177cc066ec5f9cf39","schema_fingerprint":"4aa3821a28b0b7c2400bc59aba4bcc0a76e971dadd19610d3ad38c768e124dc7","schema_version":"edge-lab-recorder.raw.v1","sequence":null,"source":"clob_market_ws"}
{"event_at":"2026-07-28T02:13:12.685000Z","event_fingerprint":"1ec2a6d9fe786b9ee43de4927fe55017970b47f35599b0bf777453028497abb6","payload":{"connection_id":"5d29200f65794d4d9ab6ef271f045a9b","event_at":"2026-07-28T02:13:12.685000Z","event_type":"price_change","frame_hash":"96167ab8de2373d799b1a465022dddfb7159133e8c447216f937471fb2f5d2f7","frame_index":0,"kind":"data","monotonic_ns":306775748734625,"payload":{"event_type":"price_change","market":"0xda6f0e0e93fc8469e0159a166028d017bddbc162b86f66bac90391379603d962","price_changes":[{"asset_id":"39272994714739463168905443499424551362424437245880253267329605556587274644733","best_ask":"0.28","best_bid":"0.27","hash":"4cbac20159d967b4c059ea14be1db2214283439b","price":"0.21","side":"BUY","size":"91.17"},{"asset_id":"20893381255801015515826997628594359667013752732428989472914000440642900266717","best_ask":"0.73","best_bid":"0.72","hash":"fb51357dec4349993cccdcc16584565a8cc2e81b","price":"0.79","side":"SELL","size":"91.17"}],"timestamp":"1785204792685"},"payload_hash":"136f7351e89675df06d18e1aca0078f0f0764a23ed7249d09cd9446afedda5a3","raw_frame":"{\"market\":\"0xda6f0e0e93fc8469e0159a166028d017bddbc162b86f66bac90391379603d962\", \"price_changes\":[{\"asset_id\":\"39272994714739463168905443499424551362424437245880253267329605556587274644733\", \"price\":\"0.21\", \"size\":\"91.17\", \"side\":\"BUY\", \"hash\":\"4cbac20159d967b4c059ea14be1db2214283439b\", \"best_bid\":\"0.27\", \"best_ask\":\"0.28\"}, {\"asset_id\":\"20893381255801015515826997628594359667013752732428989472914000440642900266717\", \"price\":\"0.79\", \"size\":\"91.17\", \"side\":\"SELL\", \"hash\":\"fb51357dec4349993cccdcc16584565a8cc2e81b\", \"best_bid\":\"0.72\", \"best_ask\":\"0.73\"}], \"timestamp\":\"1785204792685\", \"event_type\":\"price_change\"}","received_at":"2026-07-28T02:13:12.737828Z","schema_version":"clob-market-ws.price_change.v1","sequence":null,"server_hash":null,"server_timestamp":"1785204792685","session_id":"d2757dd6dad94f3b9fe67e8dbf1adc37","source":"clob_market_ws"},"received_at":"2026-07-28T02:13:12.737828Z","record_id":"67f7713e5f41165d733f5aeae792e4e5e4df9bf22201ff5bcaf9a5d3301973e1","schema_fingerprint":"4aa3821a28b0b7c2400bc59aba4bcc0a76e971dadd19610d3ad38c768e124dc7","schema_version":"edge-lab-recorder.raw.v1","sequence":null,"source":"clob_market_ws"}
{"event_at":"2026-07-28T02:13:12.685000Z","event_fingerprint":"6746ea4977f66766cf0a82321744269b42169f53f656b39d9c0e5fcc22e02e0f","payload":{"connection_id":"5d29200f65794d4d9ab6ef271f045a9b","event_at":"2026-07-28T02:13:12.685000Z","event_type":"price_change","frame_hash":"2490b368a12b5a26a1f7c3c31ea2a957e9a8443b9d2a296c33d19dce5308a438","frame_index":0,"kind":"data","monotonic_ns":306775751673166,"payload":{"event_type":"price_change","market":"0xda6f0e0e93fc8469e0159a166028d017bddbc162b86f66bac90391379603d962","price_changes":[{"asset_id":"20893381255801015515826997628594359667013752732428989472914000440642900266717","best_ask":"0.73","best_bid":"0.72","hash":"00011adeced2df7772a5d19c84b0c9559a8b7d83","price":"0.53","side":"BUY","size":"61.02"},{"asset_id":"39272994714739463168905443499424551362424437245880253267329605556587274644733","best_ask":"0.28","best_bid":"0.27","hash":"3015c6545849ac53ab0c18e0bcc11ce80afb23be","price":"0.47","side":"SELL","size":"61.02"}],"timestamp":"1785204792685"},"payload_hash":"3870af14810e3f6a3673fa92c362ffa0ba04e5a15b8dde0213f348469510bae9","raw_frame":"{\"market\":\"0xda6f0e0e93fc8469e0159a166028d017bddbc162b86f66bac90391379603d962\", \"price_changes\":[{\"asset_id\":\"20893381255801015515826997628594359667013752732428989472914000440642900266717\", \"price\":\"0.53\", \"size\":\"61.02\", \"side\":\"BUY\", \"hash\":\"00011adeced2df7772a5d19c84b0c9559a8b7d83\", \"best_bid\":\"0.72\", \"best_ask\":\"0.73\"}, {\"asset_id\":\"39272994714739463168905443499424551362424437245880253267329605556587274644733\", \"price\":\"0.47\", \"size\":\"61.02\", \"side\":\"SELL\", \"hash\":\"3015c6545849ac53ab0c18e0bcc11ce80afb23be\", \"best_bid\":\"0.27\", \"best_ask\":\"0.28\"}], \"timestamp\":\"1785204792685\", \"event_type\":\"price_change\"}","received_at":"2026-07-28T02:13:12.740767Z","schema_version":"clob-market-ws.price_change.v1","sequence":null,"server_hash":null,"server_timestamp":"1785204792685","session_id":"d2757dd6dad94f3b9fe67e8dbf1adc37","source":"clob_market_ws"},"received_at":"2026-07-28T02:13:12.740767Z","record_id":"23b6d5963210e70769dbf2ce4fb2d6662cfc658a15e99162af6040f8f80e4ef3","schema_fingerprint":"4aa3821a28b0b7c2400bc59aba4bcc0a76e971dadd19610d3ad38c768e124dc7","schema_version":"edge-lab-recorder.raw.v1","sequence":null,"source":"clob_market_ws"}
{"event_at":"2026-07-28T02:13:12.686000Z","event_fingerprint":"0c5f9dda51b00685c55f013ad35483e95037865cc4356747c52ada9c1be0599e","payload":{"connection_id":"5d29200f65794d4d9ab6ef271f045a9b","event_at":"2026-07-28T02:13:12.686000Z","event_type":"price_change","frame_hash":"0993203d3f141194f229bb2dee0f9370ee251c569e6fb3a7f1156a4027cf7c4f","frame_index":0,"kind":"data","monotonic_ns":306775754609916,"payload":{"event_type":"price_change","market":"0xda6f0e0e93fc8469e0159a166028d017bddbc162b86f66bac90391379603d962","price_changes":[{"asset_id":"20893381255801015515826997628594359667013752732428989472914000440642900266717","best_ask":"0.73","best_bid":"0.72","hash":"aaf13cee3bb4aa11ff5e8ddb9762fe85f27d2088","price":"0.69","side":"BUY","size":"17"},{"asset_id":"39272994714739463168905443499424551362424437245880253267329605556587274644733","best_ask":"0.28","best_bid":"0.27","hash":"c118e11adb07d6c0d3524c7f1c41a852304ef915","price":"0.31","side":"SELL","size":"17"}],"timestamp":"1785204792686"},"payload_hash":"b03f3cc29c9f9c2ca0d3965383540e9e0f623177c48b2ab1574ecd6ed02db2b0","raw_frame":"{\"market\":\"0xda6f0e0e93fc8469e0159a166028d017bddbc162b86f66bac90391379603d962\", \"price_changes\":[{\"asset_id\":\"20893381255801015515826997628594359667013752732428989472914000440642900266717\", \"price\":\"0.69\", \"size\":\"17\", \"side\":\"BUY\", \"hash\":\"aaf13cee3bb4aa11ff5e8ddb9762fe85f27d2088\", \"best_bid\":\"0.72\", \"best_ask\":\"0.73\"}, {\"asset_id\":\"39272994714739463168905443499424551362424437245880253267329605556587274644733\", \"price\":\"0.31\", \"size\":\"17\", \"side\":\"SELL\", \"hash\":\"c118e11adb07d6c0d3524c7f1c41a852304ef915\", \"best_bid\":\"0.27\", \"best_ask\":\"0.28\"}], \"timestamp\":\"1785204792686\", \"event_type\":\"price_change\"}","received_at":"2026-07-28T02:13:12.743704Z","schema_version":"clob-market-ws.price_change.v1","sequence":null,"server_hash":null,"server_timestamp":"1785204792686","session_id":"d2757dd6dad94f3b9fe67e8dbf1adc37","source":"clob_market_ws"},"received_at":"2026-07-28T02:13:12.743704Z","record_id":"5c36f247ad22d42c2148a2f66e81f07df4309041066920be319d6a116ed332c4","schema_fingerprint":"4aa3821a28b0b7c2400bc59aba4bcc0a76e971dadd19610d3ad38c768e124dc7","schema_version":"edge-lab-recorder.raw.v1","sequence":null,"source":"clob_market_ws"}
{"event_at":"2026-07-28T02:13:12.687000Z","event_fingerprint":"c1d3aab7342bdcd14e511b3e2c864fd9fb05bee74e47a6a275f2242923a4702b","payload":{"connection_id":"5d29200f65794d4d9ab6ef271f045a9b","event_at":"2026-07-28T02:13:12.687000Z","event_type":"price_change","frame_hash":"95145bd6495881ab38fb977e6c1ecc599363e0491f3a062ea4b1e5dac37635a4","frame_index":0,"kind":"data","monotonic_ns":306775756963125,"payload":{"event_type":"price_change","market":"0xda6f0e0e93fc8469e0159a166028d017bddbc162b86f66bac90391379603d962","price_changes":[{"asset_id":"39272994714739463168905443499424551362424437245880253267329605556587274644733","best_ask":"0.28","best_bid":"0.27","hash":"7468d41ef036d542a0f0ac179dce871ae2fcdf00","price":"0.29","side":"SELL","size":"95.47"},{"asset_id":"20893381255801015515826997628594359667013752732428989472914000440642900266717","best_ask":"0.73","best_bid":"0.72","hash":"87a3c5f11e1e73bded848721122b09932a0fd0ba","price":"0.71","side":"BUY","size":"95.47"}],"timestamp":"1785204792687"},"payload_hash":"216342cb28c0046b906d183a32439c7ab4a2311e03bd41aefa0b18435ffe2ddb","raw_frame":"{\"market\":\"0xda6f0e0e93fc8469e0159a166028d017bddbc162b86f66bac90391379603d962\", \"price_changes\":[{\"asset_id\":\"39272994714739463168905443499424551362424437245880253267329605556587274644733\", \"price\":\"0.29\", \"size\":\"95.47\", \"side\":\"SELL\", \"hash\":\"7468d41ef036d542a0f0ac179dce871ae2fcdf00\", \"best_bid\":\"0.27\", \"best_ask\":\"0.28\"}, {\"asset_id\":\"20893381255801015515826997628594359667013752732428989472914000440642900266717\", \"price\":\"0.71\", \"size\":\"95.47\", \"side\":\"BUY\", \"hash\":\"87a3c5f11e1e73bded848721122b09932a0fd0ba\", \"best_bid\":\"0.72\", \"best_ask\":\"0.73\"}], \"timestamp\":\"1785204792687\", \"event_type\":\"price_change\"}","received_at":"2026-07-28T02:13:12.746057Z","schema_version":"clob-market-ws.price_change.v1","sequence":null,"server_hash":null,"server_timestamp":"1785204792687","session_id":"d2757dd6dad94f3b9fe67e8dbf1adc37","source":"clob_market_ws"},"received_at":"2026-07-28T02:13:12.746057Z","record_id":"43ba1eecfde7f19c7656ad1d05e409e19920974afdebb5ca836f713388aac22f","schema_fingerprint":"4aa3821a28b0b7c2400bc59aba4bcc0a76e971dadd19610d3ad38c768e124dc7","schema_version":"edge-lab-recorder.raw.v1","sequence":null,"source":"clob_market_ws"}
{"event_at":"2026-07-28T02:13:12.688000Z","event_fingerprint":"b8bc8d08f56a4d1a5fc5174946d16e71ba57ca76ca60b986dcbe89ea59b26e68","payload":{"connection_id":"5d29200f65794d4d9ab6ef271f045a9b","event_at":"2026-07-28T02:13:12.688000Z","event_type":"price_change","frame_hash":"d13b897aa8379a4b5a941edaf97d18daa6903597328e56be322225a19efc8ccd","frame_index":0,"kind":"data","monotonic_ns":306775759190708,"payload":{"event_type":"price_change","market":"0xda6f0e0e93fc8469e0159a166028d017bddbc162b86f66bac90391379603d962","price_changes":[{"asset_id":"20893381255801015515826997628594359667013752732428989472914000440642900266717","best_ask":"0.73","best_bid":"0.72","hash":"d5d6d76b5c4567719d37a51d566dce2a95897ca3","price":"0.54","side":"BUY","size":"61.05"},{"asset_id":"39272994714739463168905443499424551362424437245880253267329605556587274644733","best_ask":"0.28","best_bid":"0.27","hash":"339f27904f24ae1401eca360717f4024892e4cef","price":"0.46","side":"SELL","size":"61.05"}],"timestamp":"1785204792688"},"payload_hash":"c52273debf4384218b687a44a1983f81c7bfb273cf9cf08707f192b1a206efbf","raw_frame":"{\"market\":\"0xda6f0e0e93fc8469e0159a166028d017bddbc162b86f66bac90391379603d962\", \"price_changes\":[{\"asset_id\":\"20893381255801015515826997628594359667013752732428989472914000440642900266717\", \"price\":\"0.54\", \"size\":\"61.05\", \"side\":\"BUY\", \"hash\":\"d5d6d76b5c4567719d37a51d566dce2a95897ca3\", \"best_bid\":\"0.72\", \"best_ask\":\"0.73\"}, {\"asset_id\":\"39272994714739463168905443499424551362424437245880253267329605556587274644733\", \"price\":\"0.46\", \"size\":\"61.05\", \"side\":\"SELL\", \"hash\":\"339f27904f24ae1401eca360717f4024892e4cef\", \"best_bid\":\"0.27\", \"best_ask\":\"0.28\"}], \"timestamp\":\"1785204792688\", \"event_type\":\"price_change\"}","received_at":"2026-07-28T02:13:12.748284Z","schema_version":"clob-market-ws.price_change.v1","sequence":null,"server_hash":null,"server_timestamp":"1785204792688","session_id":"d2757dd6dad94f3b9fe67e8dbf1adc37","source":"clob_market_ws"},"received_at":"2026-07-28T02:13:12.748284Z","record_id":"e960a67c5ed62f52f43515c2ab15e80dda9db5ef9c0e61d46346ac335875fc1f","schema_fingerprint":"4aa3821a28b0b7c2400bc59aba4bcc0a76e971dadd19610d3ad38c768e124dc7","schema_version":"edge-lab-recorder.raw.v1","sequence":null,"source":"clob_market_ws"}
{"event_at":"2026-07-28T02:13:12.689000Z","event_fingerprint":"c11f64e6aa8bb96a5af14841fde11daf87d9e810907d1502adb36f22a41f4ecb","payload":{"connection_id":"5d29200f65794d4d9ab6ef271f045a9b","event_at":"2026-07-28T02:13:12.689000Z","event_type":"price_change","frame_hash":"0169bca260ca26ace77095981737eca32119b921e3112f772b83b0477a093fc7","frame_index":0,"kind":"data","monotonic_ns":306775762187791,"payload":{"event_type":"price_change","market":"0xda6f0e0e93fc8469e0159a166028d017bddbc162b86f66bac90391379603d962","price_changes":[{"asset_id":"39272994714739463168905443499424551362424437245880253267329605556587274644733","best_ask":"0.28","best_bid":"0.27","hash":"e704a06757506026a4621f3725bb4540a88f6e40","price":"0.19","side":"BUY","size":"78.81"},{"asset_id":"20893381255801015515826997628594359667013752732428989472914000440642900266717","best_ask":"0.73","best_bid":"0.72","hash":"85c0c31f0a14c6b173648f09860e1a2b769738a9","price":"0.81","side":"SELL","size":"78.81"}],"timestamp":"1785204792689"},"payload_hash":"5d41e109b0af6f91bf71fb8d5207a7a48d04c8e7f608c5658d14c0f5d680e165","raw_frame":"{\"market\":\"0xda6f0e0e93fc8469e0159a166028d017bddbc162b86f66bac90391379603d962\", \"price_changes\":[{\"asset_id\":\"39272994714739463168905443499424551362424437245880253267329605556587274644733\", \"price\":\"0.19\", \"size\":\"78.81\", \"side\":\"BUY\", \"hash\":\"e704a06757506026a4621f3725bb4540a88f6e40\", \"best_bid\":\"0.27\", \"best_ask\":\"0.28\"}, {\"asset_id\":\"20893381255801015515826997628594359667013752732428989472914000440642900266717\", \"price\":\"0.81\", \"size\":\"78.81\", \"side\":\"SELL\", \"hash\":\"85c0c31f0a14c6b173648f09860e1a2b769738a9\", \"best_bid\":\"0.72\", \"best_ask\":\"0.73\"}], \"timestamp\":\"1785204792689\", \"event_type\":\"price_change\"}","received_at":"2026-07-28T02:13:12.751281Z","schema_version":"clob-market-ws.price_change.v1","sequence":null,"server_hash":null,"server_timestamp":"1785204792689","session_id":"d2757dd6dad94f3b9fe67e8dbf1adc37","source":"clob_market_ws"},"received_at":"2026-07-28T02:13:12.751281Z","record_id":"b25ea51d672dadb9450ebc0a87bbb8774b9a3134824c039b718f66ce66df9d17","schema_fingerprint":"4aa3821a28b0b7c2400bc59aba4bcc0a76e971dadd19610d3ad38c768e124dc7","schema_version":"edge-lab-recorder.raw.v1","sequence":null,"source":"clob_market_ws"}
{"event_at":"2026-07-28T02:13:12.690000Z","event_fingerprint":"8fe1b272cd0524a011e259924097d4fcda6cc87687de2d02e36aa0d376eb020d","payload":{"connection_id":"5d29200f65794d4d9ab6ef271f045a9b","event_at":"2026-07-28T02:13:12.690000Z","event_type":"price_change","frame_hash":"02a34df7907b063db7dd103a27de1f608b1ab7a32ed011aef0f0875272431a82","frame_index":0,"kind":"data","monotonic_ns":306775764831916,"payload":{"event_type":"price_change","market":"0xda6f0e0e93fc8469e0159a166028d017bddbc162b86f66bac90391379603d962","price_changes":[{"asset_id":"20893381255801015515826997628594359667013752732428989472914000440642900266717","best_ask":"0.73","best_bid":"0.72","hash":"bff24e04a3abbf4f9a8283cdf9adc7eaf76c7843","price":"0.55","side":"BUY","size":"91.08"},{"asset_id":"39272994714739463168905443499424551362424437245880253267329605556587274644733","best_ask":"0.28","best_bid":"0.27","hash":"aa310eef53dcaebe62ab28c1dbeb6ba7b82b16f0","price":"0.45","side":"SELL","size":"91.08"}],"timestamp":"1785204792690"},"payload_hash":"7d13a63621d0f6e7c496cd1888e6f75c69c8a63da6fa746f47f2228cc5a8a213","raw_frame":"{\"market\":\"0xda6f0e0e93fc8469e0159a166028d017bddbc162b86f66bac90391379603d962\", \"price_changes\":[{\"asset_id\":\"20893381255801015515826997628594359667013752732428989472914000440642900266717\", \"price\":\"0.55\", \"size\":\"91.08\", \"side\":\"BUY\", \"hash\":\"bff24e04a3abbf4f9a8283cdf9adc7eaf76c7843\", \"best_bid\":\"0.72\", \"best_ask\":\"0.73\"}, {\"asset_id\":\"39272994714739463168905443499424551362424437245880253267329605556587274644733\", \"price\":\"0.45\", \"size\":\"91.08\", \"side\":\"SELL\", \"hash\":\"aa310eef53dcaebe62ab28c1dbeb6ba7b82b16f0\", \"best_bid\":\"0.27\", \"best_ask\":\"0.28\"}], \"timestamp\":\"1785204792690\", \"event_type\":\"price_change\"}","received_at":"2026-07-28T02:13:12.753931Z","schema_version":"clob-market-ws.price_change.v1","sequence":null,"server_hash":null,"server_timestamp":"1785204792690","session_id":"d2757dd6dad94f3b9fe67e8dbf1adc37","source":"clob_market_ws"},"received_at":"2026-07-28T02:13:12.753931Z","record_id":"5a6468f5658f93912621f1807c6cf26d07ce112e1349ca25b15b9e59255e21e6","schema_fingerprint":"4aa3821a28b0b7c2400bc59aba4bcc0a76e971dadd19610d3ad38c768e124dc7","schema_version":"edge-lab-recorder.raw.v1","sequence":null,"source":"clob_market_ws"}
{"event_at":"2026-07-28T02:13:12.691000Z","event_fingerprint":"5493bda6e2be44ad6c924a161d41c2ca2afc27adcbd5ff63a678791a1b59840c","payload":{"connection_id":"5d29200f65794d4d9ab6ef271f045a9b","event_at":"2026-07-28T02:13:12.691000Z","event_type":"price_change","frame_hash":"1995f5c2d7df3a4c855572f9581c8019456f093cd54436f1e75b2569cd4b9876","frame_index":0,"kind":"data","monotonic_ns":306775766365416,"payload":{"event_type":"price_change","market":"0xda6f0e0e93fc8469e0159a166028d017bddbc162b86f66bac90391379603d962","price_changes":[{"asset_id":"20893381255801015515826997628594359667013752732428989472914000440642900266717","best_ask":"0.73","best_bid":"0.72","hash":"7363aa09ba4d39329fd7661e285520ef3cead534","price":"0.7","side":"BUY","size":"20"},{"asset_id":"39272994714739463168905443499424551362424437245880253267329605556587274644733","best_ask":"0.28","best_bid":"0.27","hash":"149ce427901f695add41f460cb860195aa3e6070","price":"0.3","side":"SELL","size":"20"}],"timestamp":"1785204792691"},"payload_hash":"d385f8b149d1c0c743348541997979512fabde7fe2689617bd5e95a4eb1e5a3a","raw_frame":"{\"market\":\"0xda6f0e0e93fc8469e0159a166028d017bddbc162b86f66bac90391379603d962\", \"price_changes\":[{\"asset_id\":\"20893381255801015515826997628594359667013752732428989472914000440642900266717\", \"price\":\"0.7\", \"size\":\"20\", \"side\":\"BUY\", \"hash\":\"7363aa09ba4d39329fd7661e285520ef3cead534\", \"best_bid\":\"0.72\", \"best_ask\":\"0.73\"}, {\"asset_id\":\"39272994714739463168905443499424551362424437245880253267329605556587274644733\", \"price\":\"0.3\", \"size\":\"20\", \"side\":\"SELL\", \"hash\":\"149ce427901f695add41f460cb860195aa3e6070\", \"best_bid\":\"0.27\", \"best_ask\":\"0.28\"}], \"timestamp\":\"1785204792691\", \"event_type\":\"price_change\"}","received_at":"2026-07-28T02:13:12.755459Z","schema_version":"clob-market-ws.price_change.v1","sequence":null,"server_hash":null,"server_timestamp":"1785204792691","session_id":"d2757dd6dad94f3b9fe67e8dbf1adc37","source":"clob_market_ws"},"received_at":"2026-07-28T02:13:12.755459Z","record_id":"c3fe9ac06182077825d0548070180fbe91f93a41049bfe20cf1ba30bbd760d3b","schema_fingerprint":"4aa3821a28b0b7c2400bc59aba4bcc0a76e971dadd19610d3ad38c768e124dc7","schema_version":"edge-lab-recorder.raw.v1","sequence":null,"source":"clob_market_ws"}
{"event_at":"2026-07-28T02:13:12.691000Z","event_fingerprint":"2654465a4f4075788aaf406791b9d808f9b665c08cdb891e1b3e1e1047b2f51a","payload":{"connection_id":"5d29200f65794d4d9ab6ef271f045a9b","event_at":"2026-07-28T02:13:12.691000Z","event_type":"price_change","frame_hash":"395415d3a514fbefe96a64c27314734c857d173b06bdeba8b235c7ec41b9bce9","frame_index":0,"kind":"data","monotonic_ns":306775769243625,"payload":{"event_type":"price_change","market":"0xda6f0e0e93fc8469e0159a166028d017bddbc162b86f66bac90391379603d962","price_changes":[{"asset_id":"39272994714739463168905443499424551362424437245880253267329605556587274644733","best_ask":"0.28","best_bid":"0.27","hash":"56c642c8c3b94b1e034d585fb78229d36a7fd998","price":"0.2","side":"BUY","size":"69.72"},{"asset_id":"20893381255801015515826997628594359667013752732428989472914000440642900266717","best_ask":"0.73","best_bid":"0.72","hash":"762e1b2969c37c898565c4244d27cf378900da58","price":"0.8","side":"SELL","size":"69.72"}],"timestamp":"1785204792691"},"payload_hash":"5e91b8d188a6670bd8fd9c1b751df8b3fd4755e99df1bf24006de78cb1f96b82","raw_frame":"{\"market\":\"0xda6f0e0e93fc8469e0159a166028d017bddbc162b86f66bac90391379603d962\", \"price_changes\":[{\"asset_id\":\"39272994714739463168905443499424551362424437245880253267329605556587274644733\", \"price\":\"0.2\", \"size\":\"69.72\", \"side\":\"BUY\", \"hash\":\"56c642c8c3b94b1e034d585fb78229d36a7fd998\", \"best_bid\":\"0.27\", \"best_ask\":\"0.28\"}, {\"asset_id\":\"20893381255801015515826997628594359667013752732428989472914000440642900266717\", \"price\":\"0.8\", \"size\":\"69.72\", \"side\":\"SELL\", \"hash\":\"762e1b2969c37c898565c4244d27cf378900da58\", \"best_bid\":\"0.72\", \"best_ask\":\"0.73\"}], \"timestamp\":\"1785204792691\", \"event_type\":\"price_change\"}","received_at":"2026-07-28T02:13:12.758337Z","schema_version":"clob-market-ws.price_change.v1","sequence":null,"server_hash":null,"server_timestamp":"1785204792691","session_id":"d2757dd6dad94f3b9fe67e8dbf1adc37","source":"clob_market_ws"},"received_at":"2026-07-28T02:13:12.758337Z","record_id":"5dc7a230e841e5c5ef99496607610dad23b9c5c04886d332c9181a05aa67a7ec","schema_fingerprint":"4aa3821a28b0b7c2400bc59aba4bcc0a76e971dadd19610d3ad38c768e124dc7","schema_version":"edge-lab-recorder.raw.v1","sequence":null,"source":"clob_market_ws"}
{"event_at":"2026-07-28T02:13:12.694000Z","event_fingerprint":"0dea5718b47c21f22e974648ec5f9668d4ded7eaba3f2f5869a7e850e44b0ba6","payload":{"connection_id":"5d29200f65794d4d9ab6ef271f045a9b","event_at":"2026-07-28T02:13:12.694000Z","event_type":"price_change","frame_hash":"e4bf04faca5eb83a012a2322288ed6f6ae453240d39f63e30f7d9d4fd054ab4f","frame_index":0,"kind":"data","monotonic_ns":306775772198125,"payload":{"event_type":"price_change","market":"0xda6f0e0e93fc8469e0159a166028d017bddbc162b86f66bac90391379603d962","price_changes":[{"asset_id":"20893381255801015515826997628594359667013752732428989472914000440642900266717","best_ask":"0.73","best_bid":"0.72","hash":"9358aea52592a9d396ce3ffbce74de28da918b0f","price":"0.72","side":"BUY","size":"6.18"},{"asset_id":"39272994714739463168905443499424551362424437245880253267329605556587274644733","best_ask":"0.28","best_bid":"0.27","hash":"ef97b6c65132fae7fa221af8c546e35844e5b959","price":"0.28","side":"SELL","size":"6.18"}],"timestamp":"1785204792694"},"payload_hash":"651a035d6139ea53105f7dec06ad3cca1ae94533c347fa1db8c4d1e82bb86114","raw_frame":"{\"market\":\"0xda6f0e0e93fc8469e0159a166028d017bddbc162b86f66bac90391379603d962\", \"price_changes\":[{\"asset_id\":\"20893381255801015515826997628594359667013752732428989472914000440642900266717\", \"price\":\"0.72\", \"size\":\"6.18\", \"side\":\"BUY\", \"hash\":\"9358aea52592a9d396ce3ffbce74de28da918b0f\", \"best_bid\":\"0.72\", \"best_ask\":\"0.73\"}, {\"asset_id\":\"39272994714739463168905443499424551362424437245880253267329605556587274644733\", \"price\":\"0.28\", \"size\":\"6.18\", \"side\":\"SELL\", \"hash\":\"ef97b6c65132fae7fa221af8c546e35844e5b959\", \"best_bid\":\"0.27\", \"best_ask\":\"0.28\"}], \"timestamp\":\"1785204792694\", \"event_type\":\"price_change\"}","received_at":"2026-07-28T02:13:12.761291Z","schema_version":"clob-market-ws.price_change.v1","sequence":null,"server_hash":null,"server_timestamp":"1785204792694","session_id":"d2757dd6dad94f3b9fe67e8dbf1adc37","source":"clob_market_ws"},"received_at":"2026-07-28T02:13:12.761291Z","record_id":"4cfbcf6d2ab10531bdc09fcc7afc1142a7390098c58fbc00233de7e6a750e0f2","schema_fingerprint":"4aa3821a28b0b7c2400bc59aba4bcc0a76e971dadd19610d3ad38c768e124dc7","schema_version":"edge-lab-recorder.raw.v1","sequence":null,"source":"clob_market_ws"}
{"event_at":"2026-07-28T02:13:12.705000Z","event_fingerprint":"1efa4f9ef3cb1e6ac1b18a501c682cb80ff16fd123d3ef1bfde5ccf03a4041f8","payload":{"connection_id":"5d29200f65794d4d9ab6ef271f045a9b","event_at":"2026-07-28T02:13:12.705000Z","event_type":"price_change","frame_hash":"d116379f02abf3efa31ac63dac76e4a9ecb3a2f8bb173952d49475182e226031","frame_index":0,"kind":"data","monotonic_ns":306775775276083,"payload":{"event_type":"price_change","market":"0xda6f0e0e93fc8469e0159a166028d017bddbc162b86f66bac90391379603d962","price_changes":[{"asset_id":"20893381255801015515826997628594359667013752732428989472914000440642900266717","best_ask":"0.73","best_bid":"0.72","hash":"37dea449f0a2c6898b65c705449a134f42a54b73","price":"0.64","side":"BUY","size":"49"},{"asset_id":"39272994714739463168905443499424551362424437245880253267329605556587274644733","best_ask":"0.28","best_bid":"0.27","hash":"da0b5733ae16c6ad55c119d2438e4a5feb4a1e19","price":"0.36","side":"SELL","size":"49"}],"timestamp":"1785204792705"},"payload_hash":"d4acf8c3d8548936ea00999e57af1acbb298c67ecbd0c5c5683388ae74442062","raw_frame":"{\"market\":\"0xda6f0e0e93fc8469e0159a166028d017bddbc162b86f66bac90391379603d962\", \"price_changes\":[{\"asset_id\":\"20893381255801015515826997628594359667013752732428989472914000440642900266717\", \"price\":\"0.64\", \"size\":\"49\", \"side\":\"BUY\", \"hash\":\"37dea449f0a2c6898b65c705449a134f42a54b73\", \"best_bid\":\"0.72\", \"best_ask\":\"0.73\"}, {\"asset_id\":\"39272994714739463168905443499424551362424437245880253267329605556587274644733\", \"price\":\"0.36\", \"size\":\"49\", \"side\":\"SELL\", \"hash\":\"da0b5733ae16c6ad55c119d2438e4a5feb4a1e19\", \"best_bid\":\"0.27\", \"best_ask\":\"0.28\"}], \"timestamp\":\"1785204792705\", \"event_type\":\"price_change\"}","received_at":"2026-07-28T02:13:12.764369Z","schema_version":"clob-market-ws.price_change.v1","sequence":null,"server_hash":null,"server_timestamp":"1785204792705","session_id":"d2757dd6dad94f3b9fe67e8dbf1adc37","source":"clob_market_ws"},"received_at":"2026-07-28T02:13:12.764369Z","record_id":"b6a4788f28548dbd506fc1eff321c12d0348ec2faa96f6bf4782e3844325cde8","schema_fingerprint":"4aa3821a28b0b7c2400bc59aba4bcc0a76e971dadd19610d3ad38c768e124dc7","schema_version":"edge-lab-recorder.raw.v1","sequence":null,"source":"clob_market_ws"}
{"event_at":"2026-07-28T02:13:12.713000Z","event_fingerprint":"b9bd0a4b83e59efe20fb2a79c3a57c94c460beb9dc184d9b9e8ab0081cffd78f","payload":{"connection_id":"5d29200f65794d4d9ab6ef271f045a9b","event_at":"2026-07-28T02:13:12.713000Z","event_type":"price_change","frame_hash":"77c955819ac8f6790bc1a95193b55908e46aa589a4f47511dd48e45bf1f62b98","frame_index":0,"kind":"data","monotonic_ns":306775778261833,"payload":{"event_type":"price_change","market":"0xda6f0e0e93fc8469e0159a166028d017bddbc162b86f66bac90391379603d962","price_changes":[{"asset_id":"20893381255801015515826997628594359667013752732428989472914000440642900266717","best_ask":"0.73","best_bid":"0.72","hash":"3017be9a2423abb74a000cfe1b51365bc63bc2c1","price":"0.02","side":"BUY","size":"579"},{"asset_id":"39272994714739463168905443499424551362424437245880253267329605556587274644733","best_ask":"0.28","best_bid":"0.27","hash":"198c834172a47c99d0bb66d51ff0da53676f3cb6","price":"0.98","side":"SELL","size":"579"}],"timestamp":"1785204792713"},"payload_hash":"bc9a630b39493aa748f8e5791f231d703481642ebff15c320b3cb09679f5d96e","raw_frame":"{\"market\":\"0xda6f0e0e93fc8469e0159a166028d017bddbc162b86f66bac90391379603d962\", \"price_changes\":[{\"asset_id\":\"20893381255801015515826997628594359667013752732428989472914000440642900266717\", \"price\":\"0.02\", \"size\":\"579\", \"side\":\"BUY\", \"hash\":\"3017be9a2423abb74a000cfe1b51365bc63bc2c1\", \"best_bid\":\"0.72\", \"best_ask\":\"0.73\"}, {\"asset_id\":\"39272994714739463168905443499424551362424437245880253267329605556587274644733\", \"price\":\"0.98\", \"size\":\"579\", \"side\":\"SELL\", \"hash\":\"198c834172a47c99d0bb66d51ff0da53676f3cb6\", \"best_bid\":\"0.27\", \"best_ask\":\"0.28\"}], \"timestamp\":\"1785204792713\", \"event_type\":\"price_change\"}","received_at":"2026-07-28T02:13:12.767355Z","schema_version":"clob-market-ws.price_change.v1","sequence":null,"server_hash":null,"server_timestamp":"1785204792713","session_id":"d2757dd6dad94f3b9fe67e8dbf1adc37","source":"clob_market_ws"},"received_at":"2026-07-28T02:13:12.767355Z","record_id":"9513147660dfd7a1098c54800523f9bf56b0ad0544f48f5170629a2f19be6c73","schema_fingerprint":"4aa3821a28b0b7c2400bc59aba4bcc0a76e971dadd19610d3ad38c768e124dc7","schema_version":"edge-lab-recorder.raw.v1","sequence":null,"source":"clob_market_ws"}
{"event_at":"2026-07-28T02:13:12.715000Z","event_fingerprint":"dd9d05a228262ba2ccc288e80ba5058ad65f897f5631e34499ee2bd9ac75c458","payload":{"connection_id":"5d29200f65794d4d9ab6ef271f045a9b","event_at":"2026-07-28T02:13:12.715000Z","event_type":"price_change","frame_hash":"cd8a598d8d6e79c2299cd56844a4e2648b840cc4cd902345f544f58e1774ec1d","frame_index":0,"kind":"data","monotonic_ns":306775781160041,"payload":{"event_type":"price_change","market":"0xda6f0e0e93fc8469e0159a166028d017bddbc162b86f66bac90391379603d962","price_changes":[{"asset_id":"20893381255801015515826997628594359667013752732428989472914000440642900266717","best_ask":"0.73","best_bid":"0.72","hash":"dbbbc0e3a43b1c1adeb2c1ac8fb91df364798550","price":"0.28","side":"BUY","size":"188.94"},{"asset_id":"39272994714739463168905443499424551362424437245880253267329605556587274644733","best_ask":"0.28","best_bid":"0.27","hash":"cd4e2ad462bd7053ddb072f4c42679b1d3e973be","price":"0.72","side":"SELL","size":"188.94"}],"timestamp":"1785204792715"},"payload_hash":"7cea7e2735fdee28ee7a5c08e8b632c4c77ec5c24a1f4641c4c18a1c6e97b3a1","raw_frame":"{\"market\":\"0xda6f0e0e93fc8469e0159a166028d017bddbc162b86f66bac90391379603d962\", \"price_changes\":[{\"asset_id\":\"20893381255801015515826997628594359667013752732428989472914000440642900266717\", \"price\":\"0.28\", \"size\":\"188.94\", \"side\":\"BUY\", \"hash\":\"dbbbc0e3a43b1c1adeb2c1ac8fb91df364798550\", \"best_bid\":\"0.72\", \"best_ask\":\"0.73\"}, {\"asset_id\":\"39272994714739463168905443499424551362424437245880253267329605556587274644733\", \"price\":\"0.72\", \"size\":\"188.94\", \"side\":\"SELL\", \"hash\":\"cd4e2ad462bd7053ddb072f4c42679b1d3e973be\", \"best_bid\":\"0.27\", \"best_ask\":\"0.28\"}], \"timestamp\":\"1785204792715\", \"event_type\":\"price_change\"}","received_at":"2026-07-28T02:13:12.770254Z","schema_version":"clob-market-ws.price_change.v1","sequence":null,"server_hash":null,"server_timestamp":"1785204792715","session_id":"d2757dd6dad94f3b9fe67e8dbf1adc37","source":"clob_market_ws"},"received_at":"2026-07-28T02:13:12.770254Z","record_id":"c15aba7253bc52e694cf147d997d8dbca18ace0533f9e321bf315e5433fa88f7","schema_fingerprint":"4aa3821a28b0b7c2400bc59aba4bcc0a76e971dadd19610d3ad38c768e124dc7","schema_version":"edge-lab-recorder.raw.v1","sequence":null,"source":"clob_market_ws"}
{"event_at":"2026-07-28T02:13:12.715000Z","event_fingerprint":"fabb17a3081fb675ebbb3ea06b4fa5f8af476480d8d76bfaf7c3578e4acba3df","payload":{"connection_id":"5d29200f65794d4d9ab6ef271f045a9b","event_at":"2026-07-28T02:13:12.715000Z","event_type":"price_change","frame_hash":"844de94b17528629894c0211a6460b943029c500aaea2447c2eebfe6578849df","frame_index":0,"kind":"data","monotonic_ns":306775785890375,"payload":{"event_type":"price_change","market":"0xda6f0e0e93fc8469e0159a166028d017bddbc162b86f66bac90391379603d962","price_changes":[{"asset_id":"20893381255801015515826997628594359667013752732428989472914000440642900266717","best_ask":"0.73","best_bid":"0.72","hash":"20797d46030a06746186ad33a83c9758cb3379b4","price":"0.28","side":"BUY","size":"74"},{"asset_id":"39272994714739463168905443499424551362424437245880253267329605556587274644733","best_ask":"0.28","best_bid":"0.27","hash":"43dfcc0178f1f221e30c0275da98c7fc3c1f9db0","price":"0.72","side":"SELL","size":"74"}],"timestamp":"1785204792715"},"payload_hash":"7dd785d5a2277cd0d132b5c1ad85ef366610c6e3fc7bee5f13e2c58775383750","raw_frame":"{\"market\":\"0xda6f0e0e93fc8469e0159a166028d017bddbc162b86f66bac90391379603d962\", \"price_changes\":[{\"asset_id\":\"20893381255801015515826997628594359667013752732428989472914000440642900266717\", \"price\":\"0.28\", \"size\":\"74\", \"side\":\"BUY\", \"hash\":\"20797d46030a06746186ad33a83c9758cb3379b4\", \"best_bid\":\"0.72\", \"best_ask\":\"0.73\"}, {\"asset_id\":\"39272994714739463168905443499424551362424437245880253267329605556587274644733\", \"price\":\"0.72\", \"size\":\"74\", \"side\":\"SELL\", \"hash\":\"43dfcc0178f1f221e30c0275da98c7fc3c1f9db0\", \"best_bid\":\"0.27\", \"best_ask\":\"0.28\"}], \"timestamp\":\"1785204792715\", \"event_type\":\"price_change\"}","received_at":"2026-07-28T02:13:12.774982Z","schema_version":"clob-market-ws.price_change.v1","sequence":null,"server_hash":null,"server_timestamp":"1785204792715","session_id":"d2757dd6dad94f3b9fe67e8dbf1adc37","source":"clob_market_ws"},"received_at":"2026-07-28T02:13:12.774982Z","record_id":"780c1d0632592aeccdf8f82eaa02a1e0f5e3e180821dda15394356a5fe68d579","schema_fingerprint":"4aa3821a28b0b7c2400bc59aba4bcc0a76e971dadd19610d3ad38c768e124dc7","schema_version":"edge-lab-recorder.raw.v1","sequence":null,"source":"clob_market_ws"}
{"event_at":"2026-07-28T02:13:12.716000Z","event_fingerprint":"b02c4244691ad7682be822a968feac76ab8c348a07e6aba8cb13005b79cf6ae7","payload":{"connection_id":"5d29200f65794d4d9ab6ef271f045a9b","event_at":"2026-07-28T02:13:12.716000Z","event_type":"price_change","frame_hash":"10a63722f843d0cf5485f4bb38d46cf0e9879bb2dc691bfc4afbd4beac1b2f88","frame_index":0,"kind":"data","monotonic_ns":306775791478500,"payload":{"event_type":"price_change","market":"0xda6f0e0e93fc8469e0159a166028d017bddbc162b86f66bac90391379603d962","price_changes":[{"asset_id":"39272994714739463168905443499424551362424437245880253267329605556587274644733","best_ask":"0.28","best_bid":"0.27","hash":"18cd67e93094e3ca1156708c867c32a93dca0d8d","price":"0.27","side":"BUY","size":"102"},{"asset_id":"20893381255801015515826997628594359667013752732428989472914000440642900266717","best_ask":"0.73","best_bid":"0.72","hash":"1ef3eda0db5e84dfcc7d5c6a63c52bda74f6af6c","price":"0.73","side":"SELL","size":"102"}],"timestamp":"1785204792716"},"payload_hash":"36bc516b0386db4a814b89da9ffbbf40d94e0c3116522e5d7c37396088f74442","raw_frame":"{\"market\":\"0xda6f0e0e93fc8469e0159a166028d017bddbc162b86f66bac90391379603d962\", \"price_changes\":[{\"asset_id\":\"39272994714739463168905443499424551362424437245880253267329605556587274644733\", \"price\":\"0.27\", \"size\":\"102\", \"side\":\"BUY\", \"hash\":\"18cd67e93094e3ca1156708c867c32a93dca0d8d\", \"best_bid\":\"0.27\", \"best_ask\":\"0.28\"}, {\"asset_id\":\"20893381255801015515826997628594359667013752732428989472914000440642900266717\", \"price\":\"0.73\", \"size\":\"102\", \"side\":\"SELL\", \"hash\":\"1ef3eda0db5e84dfcc7d5c6a63c52bda74f6af6c\", \"best_bid\":\"0.72\", \"best_ask\":\"0.73\"}], \"timestamp\":\"1785204792716\", \"event_type\":\"price_change\"}","received_at":"2026-07-28T02:13:12.780573Z","schema_version":"clob-market-ws.price_change.v1","sequence":null,"server_hash":null,"server_timestamp":"1785204792716","session_id":"d2757dd6dad94f3b9fe67e8dbf1adc37","source":"clob_market_ws"},"received_at":"2026-07-28T02:13:12.780573Z","record_id":"c71bfdfd8fd6c2806465dfa0021a798037ee589d41e3c333e28d6c955216e03b","schema_fingerprint":"4aa3821a28b0b7c2400bc59aba4bcc0a76e971dadd19610d3ad38c768e124dc7","schema_version":"edge-lab-recorder.raw.v1","sequence":null,"source":"clob_market_ws"}
{"event_at":"2026-07-28T02:13:12.744000Z","event_fingerprint":"53f6dd61c48bd4960f1036092cc87f0c6a0a5f364d4aa0c4023d5ac80af3605f","payload":{"connection_id":"5d29200f65794d4d9ab6ef271f045a9b","event_at":"2026-07-28T02:13:12.744000Z","event_type":"price_change","frame_hash":"32f4d143ee10b9b2f93a8ba20ee934d2750ff0564aa9afa8800932c3183441f7","frame_index":0,"kind":"data","monotonic_ns":306775795161333,"payload":{"event_type":"price_change","market":"0xda6f0e0e93fc8469e0159a166028d017bddbc162b86f66bac90391379603d962","price_changes":[{"asset_id":"39272994714739463168905443499424551362424437245880253267329605556587274644733","best_ask":"0.28","best_bid":"0.27","hash":"d9d0903ad47b9703377c6638b4ba48aed07d676e","price":"0.27","side":"BUY","size":"73"},{"asset_id":"20893381255801015515826997628594359667013752732428989472914000440642900266717","best_ask":"0.73","best_bid":"0.72","hash":"79dda07dd765f4a580ef291550264968b80c4394","price":"0.73","side":"SELL","size":"73"}],"timestamp":"1785204792744"},"payload_hash":"267b967305d18f4afe28781031575e2997a88f5c95e73f0868b35be5adec349e","raw_frame":"{\"market\":\"0xda6f0e0e93fc8469e0159a166028d017bddbc162b86f66bac90391379603d962\", \"price_changes\":[{\"asset_id\":\"39272994714739463168905443499424551362424437245880253267329605556587274644733\", \"price\":\"0.27\", \"size\":\"73\", \"side\":\"BUY\", \"hash\":\"d9d0903ad47b9703377c6638b4ba48aed07d676e\", \"best_bid\":\"0.27\", \"best_ask\":\"0.28\"}, {\"asset_id\":\"20893381255801015515826997628594359667013752732428989472914000440642900266717\", \"price\":\"0.73\", \"size\":\"73\", \"side\":\"SELL\", \"hash\":\"79dda07dd765f4a580ef291550264968b80c4394\", \"best_bid\":\"0.72\", \"best_ask\":\"0.73\"}], \"timestamp\":\"1785204792744\", \"event_type\":\"price_change\"}","received_at":"2026-07-28T02:13:12.784255Z","schema_version":"clob-market-ws.price_change.v1","sequence":null,"server_hash":null,"server_timestamp":"1785204792744","session_id":"d2757dd6dad94f3b9fe67e8dbf1adc37","source":"clob_market_ws"},"received_at":"2026-07-28T02:13:12.784255Z","record_id":"257f4c30b6b514e5973a4b0a86393037366ccbe6d8644fcd90e3a4992dd16fdc","schema_fingerprint":"4aa3821a28b0b7c2400bc59aba4bcc0a76e971dadd19610d3ad38c768e124dc7","schema_version":"edge-lab-recorder.raw.v1","sequence":null,"source":"clob_market_ws"}
{"event_at":"2026-07-28T02:13:12.746000Z","event_fingerprint":"d00c6f3e5ec31e2644991d928d5435fa3fc49451fe85345859e50ed5c1bd8c61","payload":{"connection_id":"5d29200f65794d4d9ab6ef271f045a9b","event_at":"2026-07-28T02:13:12.746000Z","event_type":"price_change","frame_hash":"61b5e6ef8b3997947769a4e2ae0e45f9a2c6c6d98c1c95917ce6cac950b05ba6","frame_index":0,"kind":"data","monotonic_ns":306775798808750,"payload":{"event_type":"price_change","market":"0xda6f0e0e93fc8469e0159a166028d017bddbc162b86f66bac90391379603d962","price_changes":[{"asset_id":"39272994714739463168905443499424551362424437245880253267329605556587274644733","best_ask":"0.28","best_bid":"0.27","hash":"d2bf978e2f87735db8361722dac44dc991016b16","price":"0.21","side":"BUY","size":"108.6"},{"asset_id":"20893381255801015515826997628594359667013752732428989472914000440642900266717","best_ask":"0.73","best_bid":"0.72","hash":"1db4d9a4e08e0b498a0b9ce601464de556993fb8","price":"0.79","side":"SELL","size":"108.6"}],"timestamp":"1785204792746"},"payload_hash":"5a326604fb4435ed9490651e198ec9f599f20755ea80d59ec0743594ae33b6ef","raw_frame":"{\"market\":\"0xda6f0e0e93fc8469e0159a166028d017bddbc162b86f66bac90391379603d962\", \"price_changes\":[{\"asset_id\":\"39272994714739463168905443499424551362424437245880253267329605556587274644733\", \"price\":\"0.21\", \"size\":\"108.6\", \"side\":\"BUY\", \"hash\":\"d2bf978e2f87735db8361722dac44dc991016b16\", \"best_bid\":\"0.27\", \"best_ask\":\"0.28\"}, {\"asset_id\":\"20893381255801015515826997628594359667013752732428989472914000440642900266717\", \"price\":\"0.79\", \"size\":\"108.6\", \"side\":\"SELL\", \"hash\":\"1db4d9a4e08e0b498a0b9ce601464de556993fb8\", \"best_bid\":\"0.72\", \"best_ask\":\"0.73\"}], \"timestamp\":\"1785204792746\", \"event_type\":\"price_change\"}","received_at":"2026-07-28T02:13:12.787903Z","schema_version":"clob-market-ws.price_change.v1","sequence":null,"server_hash":null,"server_timestamp":"1785204792746","session_id":"d2757dd6dad94f3b9fe67e8dbf1adc37","source":"clob_market_ws"},"received_at":"2026-07-28T02:13:12.787903Z","record_id":"7158c493f97481478f17004538e4ec06013a987cb03f8d5de76818eb8948e25c","schema_fingerprint":"4aa3821a28b0b7c2400bc59aba4bcc0a76e971dadd19610d3ad38c768e124dc7","schema_version":"edge-lab-recorder.raw.v1","sequence":null,"source":"clob_market_ws"}
{"event_at":"2026-07-28T02:13:12.751000Z","event_fingerprint":"42e88b0fb25cabb687952893ae53c4b4dbc866828d861f4960f10b433ae5ba5a","payload":{"connection_id":"5d29200f65794d4d9ab6ef271f045a9b","event_at":"2026-07-28T02:13:12.751000Z","event_type":"price_change","frame_hash":"adef73e2ac5261c4d997f736e9278e876ea1c3df3fb7a6df701d54d127402158","frame_index":0,"kind":"data","monotonic_ns":306775805324500,"payload":{"event_type":"price_change","market":"0xda6f0e0e93fc8469e0159a166028d017bddbc162b86f66bac90391379603d962","price_changes":[{"asset_id":"39272994714739463168905443499424551362424437245880253267329605556587274644733","best_ask":"0.28","best_bid":"0.27","hash":"43821a8119d5c19cff69a552213aebf5c10773a6","price":"0.14","side":"BUY","size":"220"},{"asset_id":"20893381255801015515826997628594359667013752732428989472914000440642900266717","best_ask":"0.73","best_bid":"0.72","hash":"feaa9f9d36331311372da53c211a14084f5e4446","price":"0.86","side":"SELL","size":"220"}],"timestamp":"1785204792751"},"payload_hash":"d2251778b7140f85fc900b3b55493a0a9550976fe0062dc1dea6c3c94f4500b8","raw_frame":"{\"market\":\"0xda6f0e0e93fc8469e0159a166028d017bddbc162b86f66bac90391379603d962\", \"price_changes\":[{\"asset_id\":\"39272994714739463168905443499424551362424437245880253267329605556587274644733\", \"price\":\"0.14\", \"size\":\"220\", \"side\":\"BUY\", \"hash\":\"43821a8119d5c19cff69a552213aebf5c10773a6\", \"best_bid\":\"0.27\", \"best_ask\":\"0.28\"}, {\"asset_id\":\"20893381255801015515826997628594359667013752732428989472914000440642900266717\", \"price\":\"0.86\", \"size\":\"220\", \"side\":\"SELL\", \"hash\":\"feaa9f9d36331311372da53c211a14084f5e4446\", \"best_bid\":\"0.72\", \"best_ask\":\"0.73\"}], \"timestamp\":\"1785204792751\", \"event_type\":\"price_change\"}","received_at":"2026-07-28T02:13:12.794418Z","schema_version":"clob-market-ws.price_change.v1","sequence":null,"server_hash":null,"server_timestamp":"1785204792751","session_id":"d2757dd6dad94f3b9fe67e8dbf1adc37","source":"clob_market_ws"},"received_at":"2026-07-28T02:13:12.794418Z","record_id":"0e9087ee37e74999a32e46016622f56bef47e6b43f82d125de746285927ef65f","schema_fingerprint":"4aa3821a28b0b7c2400bc59aba4bcc0a76e971dadd19610d3ad38c768e124dc7","schema_version":"edge-lab-recorder.raw.v1","sequence":null,"source":"clob_market_ws"}
