{"event_at":"2026-07-28T02:09:36.456000Z","event_fingerprint":"02b94dca6f8ba88d5864820c66c6d990d2f228f896e8c5b4eeb22dedd78fcbf5","payload":{"connection_id":"5d29200f65794d4d9ab6ef271f045a9b","event_at":"2026-07-28T02:09:36.456000Z","event_type":"price_change","frame_hash":"25829f619679661c04dc2d2a73889aa8b723f7280675fa6eb79e88c95afb7060","frame_index":0,"kind":"data","monotonic_ns":306559364035541,"payload":{"event_type":"price_change","market":"0xda6f0e0e93fc8469e0159a166028d017bddbc162b86f66bac90391379603d962","price_changes":[{"asset_id":"20893381255801015515826997628594359667013752732428989472914000440642900266717","best_ask":"0.65","best_bid":"0.64","hash":"64ee8e62e62b7ab845a6907a093200d85aa83828","price":"0.01","side":"BUY","size":"5682.02"},{"asset_id":"39272994714739463168905443499424551362424437245880253267329605556587274644733","best_ask":"0.36","best_bid":"0.35","hash":"846a507aacd487a33f5a22f5dc004b76e990bc14","price":"0.99","side":"SELL","size":"5682.02"}],"timestamp":"1785204576456"},"payload_hash":"153176696c4e0883e90934002953977c1fdb0cabdb46a381eabccf9a5597cc2f","raw_frame":"{\"market\":\"0xda6f0e0e93fc8469e0159a166028d017bddbc162b86f66bac90391379603d962\", \"price_changes\":[{\"asset_id\":\"20893381255801015515826997628594359667013752732428989472914000440642900266717\", \"price\":\"0.01\", \"size\":\"5682.02\", \"side\":\"BUY\", \"hash\":\"64ee8e62e62b7ab845a6907a093200d85aa83828\", \"best_bid\":\"0.64\", \"best_ask\":\"0.65\"}, {\"asset_id\":\"39272994714739463168905443499424551362424437245880253267329605556587274644733\", \"price\":\"0.99\", \"size\":\"5682.02\", \"side\":\"SELL\", \"hash\":\"846a507aacd487a33f5a22f5dc004b76e990bc14\", \"best_bid\":\"0.35\", \"best_ask\":\"0.36\"}], \"timestamp\":\"1785204576456\", \"event_type\":\"price_change\"}","received_at":"2026-07-28T02:09:36.355272Z","schema_version":"clob-market-ws.price_change.v1","sequence":null,"server_hash":null,"server_timestamp":"1785204576456","session_id":"d2757dd6dad94f3b9fe67e8dbf1adc37","source":"clob_market_ws"},"received_at":"2026-07-28T02:09:36.355272Z","record_id":"f4d8988d221fbb3005cde9772bb08f2e946d703e0ad91c9a5f7b030c68cb5f94","schema_fingerprint":"4aa3821a28b0b7c2400bc59aba4bcc0a76e971dadd19610d3ad38c768e124dc7","schema_version":"edge-lab-recorder.raw.v1","sequence":null,"source":"clob_market_ws"}
{"event_at":"2026-07-28T02:09:36.475000Z","event_fingerprint":"081d8f5249d503d37d1c6570f4cf1fb0efb2189cc9cde197dc8fb0a09af0f8c8","payload":{"connection_id":"5d29200f65794d4d9ab6ef271f045a9b","event_at":"2026-07-28T02:09:36.475000Z","event_type":"price_change","frame_hash":"f43506f65288e6074de1e81096902d3db027e632ceccec3542d3d855068d34b2","frame_index":0,"kind":"data","monotonic_ns":306559369119833,"payload":{"event_type":"price_change","market":"0xda6f0e0e93fc8469e0159a166028d017bddbc162b86f66bac90391379603d962","price_changes":[{"asset_id":"39272994714739463168905443499424551362424437245880253267329605556587274644733","best_ask":"0.36","best_bid":"0.35","hash":"90f936e8a182eb5bdec5689ac178f4628c4cafd3","price":"0.22","side":"BUY","size":"297.5"},{"asset_id":"20893381255801015515826997628594359667013752732428989472914000440642900266717","best_ask":"0.65","best_bid":"0.64","hash":"b5ac8fa047c42d6f544b212dda183814f24c6668","price":"0.78","side":"SELL","size":"297.5"}],"timestamp":"1785204576475"},"payload_hash":"bd15df0a99fa492f18fdaa827fbc3739168833fb94e5ceab6d140507c1445e65","raw_frame":"{\"market\":\"0xda6f0e0e93fc8469e0159a166028d017bddbc162b86f66bac90391379603d962\", \"price_changes\":[{\"asset_id\":\"39272994714739463168905443499424551362424437245880253267329605556587274644733\", \"price\":\"0.22\", \"size\":\"297.5\", \"side\":\"BUY\", \"hash\":\"90f936e8a182eb5bdec5689ac178f4628c4cafd3\", \"best_bid\":\"0.35\", \"best_ask\":\"0.36\"}, {\"asset_id\":\"20893381255801015515826997628594359667013752732428989472914000440642900266717\", \"price\":\"0.78\", \"size\":\"297.5\", \"side\":\"SELL\", \"hash\":\"b5ac8fa047c42d6f544b212dda183814f24c6668\", \"best_bid\":\"0.64\", \"best_ask\":\"0.65\"}], \"timestamp\":\"1785204576475\", \"event_type\":\"price_change\"}","received_at":"2026-07-28T02:09:36.360356Z","schema_version":"clob-market-ws.price_change.v1","sequence":null,"server_hash":null,"server_timestamp":"1785204576475","session_id":"d2757dd6dad94f3b9fe67e8dbf1adc37","source":"clob_market_ws"},"received_at":"2026-07-28T02:09:36.360356Z","record_id":"66f2bde9ccda3a81e305b179c5cba60b9878ece84e6536bc968ca18816db4b2a","schema_fingerprint":"4aa3821a28b0b7c2400bc59aba4bcc0a76e971dadd19610d3ad38c768e124dc7","schema_version":"edge-lab-recorder.raw.v1","sequence":null,"source":"clob_market_ws"}
{"event_at":"2026-07-28T02:09:36.476000Z","event_fingerprint":"96da571fe8c1907f86fce8f5646031cf1f94624ba5d75c7be1786da7e6e0f123","payload":{"connection_id":"5d29200f65794d4d9ab6ef271f045a9b","event_at":"2026-07-28T02:09:36.476000Z","event_type":"price_change","frame_hash":"d7dca30ca129b618444a65ad63dc6b2a2fae29e06f540003ca02ffa4a6622e8b","frame_index":0,"kind":"data","monotonic_ns":306559378595666,"payload":{"event_type":"price_change","market":"0xda6f0e0e93fc8469e0159a166028d017bddbc162b86f66bac90391379603d962","price_changes":[{"asset_id":"39272994714739463168905443499424551362424437245880253267329605556587274644733","best_ask":"0.36","best_bid":"0.35","hash":"43c50975294b021af15fb0bdb6736c8f555db1ed","price":"0.24","side":"BUY","size":"296"},{"asset_id":"20893381255801015515826997628594359667013752732428989472914000440642900266717","best_ask":"0.65","best_bid":"0.64","hash":"1c8a00931fda94afbef3856cccd1b8ded44b85ca","price":"0.76","side":"SELL","size":"296"}],"timestamp":"1785204576476"},"payload_hash":"8f1a38c285693ef81fb9041f6cbff6e0b709267204f227884f40bb5ecdc15786","raw_frame":"{\"market\":\"0xda6f0e0e93fc8469e0159a166028d017bddbc162b86f66bac90391379603d962\", \"price_changes\":[{\"asset_id\":\"39272994714739463168905443499424551362424437245880253267329605556587274644733\", \"price\":\"0.24\", \"size\":\"296\", \"side\":\"BUY\", \"hash\":\"43c50975294b021af15fb0bdb6736c8f555db1ed\", \"best_bid\":\"0.35\", \"best_ask\":\"0.36\"}, {\"asset_id\":\"20893381255801015515826997628594359667013752732428989472914000440642900266717\", \"price\":\"0.76\", \"size\":\"296\", \"side\":\"SELL\", \"hash\":\"1c8a00931fda94afbef3856cccd1b8ded44b85ca\", \"best_bid\":\"0.64\", \"best_ask\":\"0.65\"}], \"timestamp\":\"1785204576476\", \"event_type\":\"price_change\"}","received_at":"2026-07-28T02:09:36.369831Z","schema_version":"clob-market-ws.price_change.v1","sequence":null,"server_hash":null,"server_timestamp":"1785204576476","session_id":"d2757dd6dad94f3b9fe67e8dbf1adc37","source":"clob_market_ws"},"received_at":"2026-07-28T02:09:36.369831Z","record_id":"9dffbc90f9b314e570c9e3129d5b682efa846db3f2058548fa8c1f522d7f66ff","schema_fingerprint":"4aa3821a28b0b7c2400bc59aba4bcc0a76e971dadd19610d3ad38c768e124dc7","schema_version":"edge-lab-recorder.raw.v1","sequence":null,"source":"clob_market_ws"}
{"event_at":"2026-07-28T02:09:36.477000Z","event_fingerprint":"204ccaa30cb4c3a6650f0cf57fbf13008402bc7c4e10cfb3b2daef6d296d1fc9","payload":{"connection_id":"5d29200f65794d4d9ab6ef271f045a9b","event_at":"2026-07-28T02:09:36.477000Z","event_type":"price_change","frame_hash":"6385d1dabca963bbd030699d122cfe758eb5e88a15304ea266f2fadaeafba131","frame_index":0,"kind":"data","monotonic_ns":306559380168250,"payload":{"event_type":"price_change","market":"0xda6f0e0e93fc8469e0159a166028d017bddbc162b86f66bac90391379603d962","price_changes":[{"asset_id":"39272994714739463168905443499424551362424437245880253267329605556587274644733","best_ask":"0.36","best_bid":"0.35","hash":"6292ce600112478ed3f48b062eb8c10c870e0c23","price":"0.25","side":"BUY","size":"325"},{"asset_id":"20893381255801015515826997628594359667013752732428989472914000440642900266717","best_ask":"0.65","best_bid":"0.64","hash":"8abd5a9be3807ec738364ed08db37a404a3ce7fb","price":"0.75","side":"SELL","size":"325"}],"timestamp":"1785204576477"},"payload_hash":"0e8f53b7a52ba5436925957cbe2aa303a2e18e1405395df6e6ffbf7abafdd052","raw_frame":"{\"market\":\"0xda6f0e0e93fc8469e0159a166028d017bddbc162b86f66bac90391379603d962\", \"price_changes\":[{\"asset_id\":\"39272994714739463168905443499424551362424437245880253267329605556587274644733\", \"price\":\"0.25\", \"size\":\"325\", \"side\":\"BUY\", \"hash\":\"6292ce600112478ed3f48b062eb8c10c870e0c23\", \"best_bid\":\"0.35\", \"best_ask\":\"0.36\"}, {\"asset_id\":\"20893381255801015515826997628594359667013752732428989472914000440642900266717\", \"price\":\"0.75\", \"size\":\"325\", \"side\":\"SELL\", \"hash\":\"8abd5a9be3807ec738364ed08db37a404a3ce7fb\", \"best_bid\":\"0.64\", \"best_ask\":\"0.65\"}], \"timestamp\":\"1785204576477\", \"event_type\":\"price_change\"}","received_at":"2026-07-28T02:09:36.371404Z","schema_version":"clob-market-ws.price_change.v1","sequence":null,"server_hash":null,"server_timestamp":"1785204576477","session_id":"d2757dd6dad94f3b9fe67e8dbf1adc37","source":"clob_market_ws"},"received_at":"2026-07-28T02:09:36.371404Z","record_id":"79eab954595056537bfdba553ac577c6024e805976bee6efba04e28d93dd54f5","schema_fingerprint":"4aa3821a28b0b7c2400bc59aba4bcc0a76e971dadd19610d3ad38c768e124dc7","schema_version":"edge-lab-recorder.raw.v1","sequence":null,"source":"clob_market_ws"}
{"event_at":"2026-07-28T02:09:36.478000Z","event_fingerprint":"3c43fff25bd32dee13dcff925dd5e67b01d69216534b793b7ca1c6dedc43192b","payload":{"connection_id":"5d29200f65794d4d9ab6ef271f045a9b","event_at":"2026-07-28T02:09:36.478000Z","event_type":"price_change","frame_hash":"29a3b6e8b74ecbb22ff5acaed8c594fc7264d2b80450ff17157c1df527444a02","frame_index":0,"kind":"data","monotonic_ns":306559381874083,"payload":{"event_type":"price_change","market":"0xda6f0e0e93fc8469e0159a166028d017bddbc162b86f66bac90391379603d962","price_changes":[{"asset_id":"39272994714739463168905443499424551362424437245880253267329605556587274644733","best_ask":"0.36","best_bid":"0.35","hash":"23092c3cc27855874fd5c30c96cf2f4eec6a1154","price":"0.23","side":"BUY","size":"261"},{"asset_id":"20893381255801015515826997628594359667013752732428989472914000440642900266717","best_ask":"0.65","best_bid":"0.64","hash":"9a65986a962c36b549fb195438a7bb46754a6c5f","price":"0.77","side":"SELL","size":"261"}],"timestamp":"1785204576478"},"payload_hash":"661e608d1738c1a79a52e02d1c25d866c0c2a81507f1a1bab16fff40471e051b","raw_frame":"{\"market\":\"0xda6f0e0e93fc8469e0159a166028d017bddbc162b86f66bac90391379603d962\", \"price_changes\":[{\"asset_id\":\"39272994714739463168905443499424551362424437245880253267329605556587274644733\", \"price\":\"0.23\", \"size\":\"261\", \"side\":\"BUY\", \"hash\":\"23092c3cc27855874fd5c30c96cf2f4eec6a1154\", \"best_bid\":\"0.35\", \"best_ask\":\"0.36\"}, {\"asset_id\":\"20893381255801015515826997628594359667013752732428989472914000440642900266717\", \"price\":\"0.77\", \"size\":\"261\", \"side\":\"SELL\", \"hash\":\"9a65986a962c36b549fb195438a7bb46754a6c5f\", \"best_bid\":\"0.64\", \"best_ask\":\"0.65\"}], \"timestamp\":\"1785204576478\", \"event_type\":\"price_change\"}","received_at":"2026-07-28T02:09:36.373110Z","schema_version":"clob-market-ws.price_change.v1","sequence":null,"server_hash":null,"server_timestamp":"1785204576478","session_id":"d2757dd6dad94f3b9fe67e8dbf1adc37","source":"clob_market_ws"},"received_at":"2026-07-28T02:09:36.373110Z","record_id":"d3e6df2eaddce2a9e5159430fa5de01dc4ddda8cbd163f9e2c4fbe3060ab5234","schema_fingerprint":"4aa3821a28b0b7c2400bc59aba4bcc0a76e971dadd19610d3ad38c768e124dc7","schema_version":"edge-lab-recorder.raw.v1","sequence":null,"source":"clob_market_ws"}
{"event_at":"2026-07-28T02:09:36.479000Z","event_fingerprint":"c29a7937b269a1a3850f1918be91de8bc9e404d1c07688232d3c33b6791e1252","payload":{"connection_id":"5d29200f65794d4d9ab6ef271f045a9b","event_at":"2026-07-28T02:09:36.479000Z","event_type":"price_change","frame_hash":"fe7fa3a8fa58a2e01a259f659fa3017340569a16bd484527b77ec3d72a8ab92a","frame_index":0,"kind":"data","monotonic_ns":306559383464958,"payload":{"event_type":"price_change","market":"0xda6f0e0e93fc8469e0159a166028d017bddbc162b86f66bac90391379603d962","price_changes":[{"asset_id":"20893381255801015515826997628594359667013752732428989472914000440642900266717","best_ask":"0.65","best_bid":"0.64","hash":"a888094392c8ea82f9e1754250d5fce670029e35","price":"0.62","side":"BUY","size":"137.2"},{"asset_id":"39272994714739463168905443499424551362424437245880253267329605556587274644733","best_ask":"0.36","best_bid":"0.35","hash":"71427f076c021bccd5d8da52a2bb3639b9825a92","price":"0.38","side":"SELL","size":"137.2"}],"timestamp":"1785204576479"},"payload_hash":"a6d8864d3e8b8ab9d41efefb4ec679da06147839fe916156cc89dcc6a6dab8db","raw_frame":"{\"market\":\"0xda6f0e0e93fc8469e0159a166028d017bddbc162b86f66bac90391379603d962\", \"price_changes\":[{\"asset_id\":\"20893381255801015515826997628594359667013752732428989472914000440642900266717\", \"price\":\"0.62\", \"size\":\"137.2\", \"side\":\"BUY\", \"hash\":\"a888094392c8ea82f9e1754250d5fce670029e35\", \"best_bid\":\"0.64\", \"best_ask\":\"0.65\"}, {\"asset_id\":\"39272994714739463168905443499424551362424437245880253267329605556587274644733\", \"price\":\"0.38\", \"size\":\"137.2\", \"side\":\"SELL\", \"hash\":\"71427f076c021bccd5d8da52a2bb3639b9825a92\", \"best_bid\":\"0.35\", \"best_ask\":\"0.36\"}], \"timestamp\":\"1785204576479\", \"event_type\":\"price_change\"}","received_at":"2026-07-28T02:09:36.374704Z","schema_version":"clob-market-ws.price_change.v1","sequence":null,"server_hash":null,"server_timestamp":"1785204576479","session_id":"d2757dd6dad94f3b9fe67e8dbf1adc37","source":"clob_market_ws"},"received_at":"2026-07-28T02:09:36.374704Z","record_id":"89b293f8b4c32e8abe315b615c17a54f72fb82d39b4b4f4ee13c67a8789410e0","schema_fingerprint":"4aa3821a28b0b7c2400bc59aba4bcc0a76e971dadd19610d3ad38c768e124dc7","schema_version":"edge-lab-recorder.raw.v1","sequence":null,"source":"clob_market_ws"}
{"event_at":"2026-07-28T02:09:36.489000Z","event_fingerprint":"f46e0a33bbb1bf445f5a7634ee35708100c592127bef995d98f5c3957cd479de","payload":{"connection_id":"5d29200f65794d4d9ab6ef271f045a9b","event_at":"2026-07-28T02:09:36.489000Z","event_type":"price_change","frame_hash":"005452b831fa60fb72d3ce6a14b29afaafde08f9deee4d95efe70338884ca219","frame_index":0,"kind":"data","monotonic_ns":306559385170583,"payload":{"event_type":"price_change","market":"0xda6f0e0e93fc8469e0159a166028d017bddbc162b86f66bac90391379603d962","price_changes":[{"asset_id":"20893381255801015515826997628594359667013752732428989472914000440642900266717","best_ask":"0.65","best_bid":"0.64","hash":"853bf2fb09d3bd1dcc73bb7f4febb199762fcb5e","price":"0.01","side":"BUY","size":"5677.02"},{"asset_id":"39272994714739463168905443499424551362424437245880253267329605556587274644733","best_ask":"0.36","best_bid":"0.35","hash":"90d161f5fe1b4d1dafb5a2236bd0937584614259","price":"0.99","side":"SELL","size":"5677.02"}],"timestamp":"1785204576489"},"payload_hash":"dc9da1656e9194a4018e538251b39d847afceb1fae4a53cedd8fdc75d7ab5dfb","raw_frame":"{\"market\":\"0xda6f0e0e93fc8469e0159a166028d017bddbc162b86f66bac90391379603d962\", \"price_changes\":[{\"asset_id\":\"20893381255801015515826997628594359667013752732428989472914000440642900266717\", \"price\":\"0.01\", \"size\":\"5677.02\", \"side\":\"BUY\", \"hash\":\"853bf2fb09d3bd1dcc73bb7f4febb199762fcb5e\", \"best_bid\":\"0.64\", \"best_ask\":\"0.65\"}, {\"asset_id\":\"39272994714739463168905443499424551362424437245880253267329605556587274644733\", \"price\":\"0.99\", \"size\":\"5677.02\", \"side\":\"SELL\", \"hash\":\"90d161f5fe1b4d1dafb5a2236bd0937584614259\", \"best_bid\":\"0.35\", \"best_ask\":\"0.36\"}], \"timestamp\":\"1785204576489\", \"event_type\":\"price_change\"}","received_at":"2026-07-28T02:09:36.376408Z","schema_version":"clob-market-ws.price_change.v1","sequence":null,"server_hash":null,"server_timestamp":"1785204576489","session_id":"d2757dd6dad94f3b9fe67e8dbf1adc37","source":"clob_market_ws"},"received_at":"2026-07-28T02:09:36.376408Z","record_id":"269c9bdc49176765cd22229054418e251f32a5bdca5e30463695def7c27df498","schema_fingerprint":"4aa3821a28b0b7c2400bc59aba4bcc0a76e971dadd19610d3ad38c768e124dc7","schema_version":"edge-lab-recorder.raw.v1","sequence":null,"source":"clob_market_ws"}
{"event_at":"2026-07-28T02:09:36.501000Z","event_fingerprint":"01b7207d2bdc62eed5e8fdb3c6e2b4fe46cb69bcd513bf95514029351a7d27d2","payload":{"connection_id":"5d29200f65794d4d9ab6ef271f045a9b","event_at":"2026-07-28T02:09:36.501000Z","event_type":"price_change","frame_hash":"661d182afd3dc547f9dae2fb1ecf6c16af8a7bd502f01e269649a968aff8f864","frame_index":0,"kind":"data","monotonic_ns":306559397690458,"payload":{"event_type":"price_change","market":"0xda6f0e0e93fc8469e0159a166028d017bddbc162b86f66bac90391379603d962","price_changes":[{"asset_id":"20893381255801015515826997628594359667013752732428989472914000440642900266717","best_ask":"0.65","best_bid":"0.64","hash":"043ed95e136b220706a648d602e9eabc48bd3441","price":"0.63","side":"BUY","size":"138.2"},{"asset_id":"39272994714739463168905443499424551362424437245880253267329605556587274644733","best_ask":"0.36","best_bid":"0.35","hash":"4e29937842f5bc068ee6de99f923210403ec377b","price":"0.37","side":"SELL","size":"138.2"}],"timestamp":"1785204576501"},"payload_hash":"5c1ac1014cce09084c4886cf9853c1d34f28eaef098a12caed76ed51f38261ac","raw_frame":"{\"market\":\"0xda6f0e0e93fc8469e0159a166028d017bddbc162b86f66bac90391379603d962\", \"price_changes\":[{\"asset_id\":\"20893381255801015515826997628594359667013752732428989472914000440642900266717\", \"price\":\"0.63\", \"size\":\"138.2\", \"side\":\"BUY\", \"hash\":\"043ed95e136b220706a648d602e9eabc48bd3441\", \"best_bid\":\"0.64\", \"best_ask\":\"0.65\"}, {\"asset_id\":\"39272994714739463168905443499424551362424437245880253267329605556587274644733\", \"price\":\"0.37\", \"size\":\"138.2\", \"side\":\"SELL\", \"hash\":\"4e29937842f5bc068ee6de99f923210403ec377b\", \"best_bid\":\"0.35\", \"best_ask\":\"0.36\"}], \"timestamp\":\"1785204576501\", \"event_type\":\"price_change\"}","received_at":"2026-07-28T02:09:36.388927Z","schema_version":"clob-market-ws.price_change.v1","sequence":null,"server_hash":null,"server_timestamp":"1785204576501","session_id":"d2757dd6dad94f3b9fe67e8dbf1adc37","source":"clob_market_ws"},"received_at":"2026-07-28T02:09:36.388927Z","record_id":"9064d43b815782e4e14f28fd825e7e5c348b7b23a748983c00fa9692bb5f8e76","schema_fingerprint":"4aa3821a28b0b7c2400bc59aba4bcc0a76e971dadd19610d3ad38c768e124dc7","schema_version":"edge-lab-recorder.raw.v1","sequence":null,"source":"clob_market_ws"}
{"event_at":"2026-07-28T02:09:36.504000Z","event_fingerprint":"2d5bc344e8fad194d68bf717e6337713b85a37bdc3a9cb434a497468fc86569a","payload":{"connection_id":"5d29200f65794d4d9ab6ef271f045a9b","event_at":"2026-07-28T02:09:36.504000Z","event_type":"price_change","frame_hash":"a9dd291382bbabcbd487c82626c1e13eba879d32bce5705f6b0b05c62870ebd0","frame_index":0,"kind":"data","monotonic_ns":306559400437166,"payload":{"event_type":"price_change","market":"0xda6f0e0e93fc8469e0159a166028d017bddbc162b86f66bac90391379603d962","price_changes":[{"asset_id":"20893381255801015515826997628594359667013752732428989472914000440642900266717","best_ask":"0.65","best_bid":"0.64","hash":"249448ba20cc1f43ad4fe7d4d00b1b13ac9b6468","price":"0.02","side":"BUY","size":"727.1"},{"asset_id":"39272994714739463168905443499424551362424437245880253267329605556587274644733","best_ask":"0.36","best_bid":"0.35","hash":"9d839ecacc9e511ee812fb1bf97aeea4883b9808","price":"0.98","side":"SELL","size":"727.1"}],"timestamp":"1785204576504"},"payload_hash":"3be38156a11697570132c7417849623527fbc76570ba556fa7e80d765c9f6c8a","raw_frame":"{\"market\":\"0xda6f0e0e93fc8469e0159a166028d017bddbc162b86f66bac90391379603d962\", \"price_changes\":[{\"asset_id\":\"20893381255801015515826997628594359667013752732428989472914000440642900266717\", \"price\":\"0.02\", \"size\":\"727.1\", \"side\":\"BUY\", \"hash\":\"249448ba20cc1f43ad4fe7d4d00b1b13ac9b6468\", \"best_bid\":\"0.64\", \"best_ask\":\"0.65\"}, {\"asset_id\":\"39272994714739463168905443499424551362424437245880253267329605556587274644733\", \"price\":\"0.98\", \"size\":\"727.1\", \"side\":\"SELL\", \"hash\":\"9d839ecacc9e511ee812fb1bf97aeea4883b9808\", \"best_bid\":\"0.35\", \"best_ask\":\"0.36\"}], \"timestamp\":\"1785204576504\", \"event_type\":\"price_change\"}","received_at":"2026-07-28T02:09:36.391674Z","schema_version":"clob-market-ws.price_change.v1","sequence":null,"server_hash":null,"server_timestamp":"1785204576504","session_id":"d2757dd6dad94f3b9fe67e8dbf1adc37","source":"clob_market_ws"},"received_at":"2026-07-28T02:09:36.391674Z","record_id":"01fc0458a70d674b323be75ab404d363c9cc0d03d7f4b185fe1e5ae6e9a3dc4c","schema_fingerprint":"4aa3821a28b0b7c2400bc59aba4bcc0a76e971dadd19610d3ad38c768e124dc7","schema_version":"edge-lab-recorder.raw.v1","sequence":null,"source":"clob_market_ws"}
{"event_at":"2026-07-28T02:09:36.504000Z","event_fingerprint":"93c327ec571100f04afb573d81685a181aa96d0606a6df6213322c0ce01de8be","payload":{"connection_id":"5d29200f65794d4d9ab6ef271f045a9b","event_at":"2026-07-28T02:09:36.504000Z","event_type":"price_change","frame_hash":"86d277515448540e20c3962553f3a5d9c9a06ece5a20b8f4f55b7d937297f97f","frame_index":0,"kind":"data","monotonic_ns":306559402039000,"payload":{"event_type":"price_change","market":"0xda6f0e0e93fc8469e0159a166028d017bddbc162b86f66bac90391379603d962","price_changes":[{"asset_id":"39272994714739463168905443499424551362424437245880253267329605556587274644733","best_ask":"0.36","best_bid":"0.35","hash":"759076022c18c4aaf4250bd3080d707c213be6ad","price":"0.27","side":"BUY","size":"219.8"},{"asset_id":"20893381255801015515826997628594359667013752732428989472914000440642900266717","best_ask":"0.65","best_bid":"0.64","hash":"cb19f1ab30a2fa8568c859ba5f0972eb0f344d19","price":"0.73","side":"SELL","size":"219.8"}],"timestamp":"1785204576504"},"payload_hash":"b6e88577cf07cb5ccfb14cac532902d84c10c2d029e8aba75f6e065be40cdcaa","raw_frame":"{\"market\":\"0xda6f0e0e93fc8469e0159a166028d017bddbc162b86f66bac90391379603d962\", \"price_changes\":[{\"asset_id\":\"39272994714739463168905443499424551362424437245880253267329605556587274644733\", \"price\":\"0.27\", \"size\":\"219.8\", \"side\":\"BUY\", \"hash\":\"759076022c18c4aaf4250bd3080d707c213be6ad\", \"best_bid\":\"0.35\", \"best_ask\":\"0.36\"}, {\"asset_id\":\"20893381255801015515826997628594359667013752732428989472914000440642900266717\", \"price\":\"0.73\", \"size\":\"219.8\", \"side\":\"SELL\", \"hash\":\"cb19f1ab30a2fa8568c859ba5f0972eb0f344d19\", \"best_bid\":\"0.64\", \"best_ask\":\"0.65\"}], \"timestamp\":\"1785204576504\", \"event_type\":\"price_change\"}","received_at":"2026-07-28T02:09:36.393276Z","schema_version":"clob-market-ws.price_change.v1","sequence":null,"server_hash":null,"server_timestamp":"1785204576504","session_id":"d2757dd6dad94f3b9fe67e8dbf1adc37","source":"clob_market_ws"},"received_at":"2026-07-28T02:09:36.393276Z","record_id":"ce14c6de199ccfb7904cbf992bb05695a108527cd1dbd5aad5fa088c3ef64b16","schema_fingerprint":"4aa3821a28b0b7c2400bc59aba4bcc0a76e971dadd19610d3ad38c768e124dc7","schema_version":"edge-lab-recorder.raw.v1","sequence":null,"source":"clob_market_ws"}
{"event_at":"2026-07-28T02:09:36.512000Z","event_fingerprint":"c643f5ecfc2bb2cd0aabb96a225591198f5a8541419882e659a5e3c455b370cd","payload":{"connection_id":"5d29200f65794d4d9ab6ef271f045a9b","event_at":"2026-07-28T02:09:36.512000Z","event_type":"price_change","frame_hash":"c65698469aa06cfe3141a7df95c39ec7be4a25d067af774c2182194ac82efcbe","frame_index":0,"kind":"data","monotonic_ns":306559407660000,"payload":{"event_type":"price_change","market":"0xda6f0e0e93fc8469e0159a166028d017bddbc162b86f66bac90391379603d962","price_changes":[{"asset_id":"20893381255801015515826997628594359667013752732428989472914000440642900266717","best_ask":"0.65","best_bid":"0.64","hash":"2bd0486a3dce1de4c4c6e013baf94feae7aefa7f","price":"0.01","side":"BUY","size":"5682.02"},{"asset_id":"39272994714739463168905443499424551362424437245880253267329605556587274644733","best_ask":"0.36","best_bid":"0.35","hash":"c695454abbda6a6d70ad09e7d07be6cb3abd611c","price":"0.99","side":"SELL","size":"5682.02"}],"timestamp":"1785204576512"},"payload_hash":"f3f879a1f4b85ece2cd54784e7933a21c0514bdf6fb5bf60182e5b4a2899892f","raw_frame":"{\"market\":\"0xda6f0e0e93fc8469e0159a166028d017bddbc162b86f66bac90391379603d962\", \"price_changes\":[{\"asset_id\":\"20893381255801015515826997628594359667013752732428989472914000440642900266717\", \"price\":\"0.01\", \"size\":\"5682.02\", \"side\":\"BUY\", \"hash\":\"2bd0486a3dce1de4c4c6e013baf94feae7aefa7f\", \"best_bid\":\"0.64\", \"best_ask\":\"0.65\"}, {\"asset_id\":\"39272994714739463168905443499424551362424437245880253267329605556587274644733\", \"price\":\"0.99\", \"size\":\"5682.02\", \"side\":\"SELL\", \"hash\":\"c695454abbda6a6d70ad09e7d07be6cb3abd611c\", \"best_bid\":\"0.35\", \"best_ask\":\"0.36\"}], \"timestamp\":\"1785204576512\", \"event_type\":\"price_change\"}","received_at":"2026-07-28T02:09:36.398898Z","schema_version":"clob-market-ws.price_change.v1","sequence":null,"server_hash":null,"server_timestamp":"1785204576512","session_id":"d2757dd6dad94f3b9fe67e8dbf1adc37","source":"clob_market_ws"},"received_at":"2026-07-28T02:09:36.398898Z","record_id":"459e84354952a369df8e55cbad80f8695f8db879cfa437c0d415c0340e61d151","schema_fingerprint":"4aa3821a28b0b7c2400bc59aba4bcc0a76e971dadd19610d3ad38c768e124dc7","schema_version":"edge-lab-recorder.raw.v1","sequence":null,"source":"clob_market_ws"}
{"event_at":"2026-07-28T02:09:36.530000Z","event_fingerprint":"fa72ecb1a8dee982e4cbbcb5d60f3a1b2b265f6df32da94e6a2b41457cc261d4","payload":{"connection_id":"5d29200f65794d4d9ab6ef271f045a9b","event_at":"2026-07-28T02:09:36.530000Z","event_type":"price_change","frame_hash":"eb9ee318ec5c993e7aaae64f6edb70a77ecce3796b7cdfb27700f148d0f14644","frame_index":0,"kind":"data","monotonic_ns":306559423572583,"payload":{"event_type":"price_change","market":"0xda6f0e0e93fc8469e0159a166028d017bddbc162b86f66bac90391379603d962","price_changes":[{"asset_id":"20893381255801015515826997628594359667013752732428989472914000440642900266717","best_ask":"0.65","best_bid":"0.64","hash":"06e024111189507a02eadd7788a7b89a009a3ce7","price":"0.01","side":"BUY","size":"5677.02"},{"asset_id":"39272994714739463168905443499424551362424437245880253267329605556587274644733","best_ask":"0.36","best_bid":"0.35","hash":"bfa341299ff7a3194cb4fbee8eac8b0b4cd565a4","price":"0.99","side":"SELL","size":"5677.02"}],"timestamp":"1785204576530"},"payload_hash":"5fbe0823902a3c7f3be888f2fc969c90fdab1ad269184d7168fe0df6b00289c4","raw_frame":"{\"market\":\"0xda6f0e0e93fc8469e0159a166028d017bddbc162b86f66bac90391379603d962\", \"price_changes\":[{\"asset_id\":\"20893381255801015515826997628594359667013752732428989472914000440642900266717\", \"price\":\"0.01\", \"size\":\"5677.02\", \"side\":\"BUY\", \"hash\":\"06e024111189507a02eadd7788a7b89a009a3ce7\", \"best_bid\":\"0.64\", \"best_ask\":\"0.65\"}, {\"asset_id\":\"39272994714739463168905443499424551362424437245880253267329605556587274644733\", \"price\":\"0.99\", \"size\":\"5677.02\", \"side\":\"SELL\", \"hash\":\"bfa341299ff7a3194cb4fbee8eac8b0b4cd565a4\", \"best_bid\":\"0.35\", \"best_ask\":\"0.36\"}], \"timestamp\":\"1785204576530\", \"event_type\":\"price_change\"}","received_at":"2026-07-28T02:09:36.414816Z","schema_version":"clob-market-ws.price_change.v1","sequence":null,"server_hash":null,"server_timestamp":"1785204576530","session_id":"d2757dd6dad94f3b9fe67e8dbf1adc37","source":"clob_market_ws"},"received_at":"2026-07-28T02:09:36.414816Z","record_id":"9b6f50d15760abaa8f42730910dfb17b0f37574b9d69c9761ed7fc4e3d477171","schema_fingerprint":"4aa3821a28b0b7c2400bc59aba4bcc0a76e971dadd19610d3ad38c768e124dc7","schema_version":"edge-lab-recorder.raw.v1","sequence":null,"source":"clob_market_ws"}
{"event_at":"2026-07-28T02:09:36.536000Z","event_fingerprint":"60f962b17e71ab4fbd2c8fd6de3103b36fe3f1def8d64649a46f07cc3532a6bd","payload":{"connection_id":"5d29200f65794d4d9ab6ef271f045a9b","event_at":"2026-07-28T02:09:36.536000Z","event_type":"price_change","frame_hash":"3fa65c6cd1747d255b9ab145b553e8895867a7edcc92e1125d4214212486fb5b","frame_index":0,"kind":"data","monotonic_ns":306559429436333,"payload":{"event_type":"price_change","market":"0xda6f0e0e93fc8469e0159a166028d017bddbc162b86f66bac90391379603d962","price_changes":[{"asset_id":"39272994714739463168905443499424551362424437245880253267329605556587274644733","best_ask":"0.36","best_bid":"0.35","hash":"50999543aa6295f190f61b1d302a1195d91d3fff","price":"0.26","side":"BUY","size":"304.01"},{"asset_id":"20893381255801015515826997628594359667013752732428989472914000440642900266717","best_ask":"0.65","best_bid":"0.64","hash":"b47bb850240976221ec460981679ad46c77d4ecc","price":"0.74","side":"SELL","size":"304.01"}],"timestamp":"1785204576536"},"payload_hash":"4b5d35b6399665251233e768f7554a0ae546b369d511e1fe82f13742b8c1c8d2","raw_frame":"{\"market\":\"0xda6f0e0e93fc8469e0159a166028d017bddbc162b86f66bac90391379603d962\", \"price_changes\":[{\"asset_id\":\"39272994714739463168905443499424551362424437245880253267329605556587274644733\", \"price\":\"0.26\", \"size\":\"304.01\", \"side\":\"BUY\", \"hash\":\"50999543aa6295f190f61b1d302a1195d91d3fff\", \"best_bid\":\"0.35\", \"best_ask\":\"0.36\"}, {\"asset_id\":\"20893381255801015515826997628594359667013752732428989472914000440642900266717\", \"price\":\"0.74\", \"size\":\"304.01\", \"side\":\"SELL\", \"hash\":\"b47bb850240976221ec460981679ad46c77d4ecc\", \"best_bid\":\"0.64\", \"best_ask\":\"0.65\"}], \"timestamp\":\"1785204576536\", \"event_type\":\"price_change\"}","received_at":"2026-07-28T02:09:36.420679Z","schema_version":"clob-market-ws.price_change.v1","sequence":null,"server_hash":null,"server_timestamp":"1785204576536","session_id":"d2757dd6dad94f3b9fe67e8dbf1adc37","source":"clob_market_ws"},"received_at":"2026-07-28T02:09:36.420679Z","record_id":"6b1dcb338eed7c93e2b4a003b34e6d7648e42b3fb0f1f1b214d522fa89688c5b","schema_fingerprint":"4aa3821a28b0b7c2400bc59aba4bcc0a76e971dadd19610d3ad38c768e124dc7","schema_version":"edge-lab-recorder.raw.v1","sequence":null,"source":"clob_market_ws"}
{"event_at":"2026-07-28T02:09:36.562000Z","event_fingerprint":"459de1e99d14ea41a70236e28657380301d2fda2c801dd7e35286601a7d9f7d5","payload":{"connection_id":"5d29200f65794d4d9ab6ef271f045a9b","event_at":"2026-07-28T02:09:36.562000Z","event_type":"price_change","frame_hash":"72787c759cee78543ad4bd3b3a26d2d3ce53243157277d74262ea49fc74337e5","frame_index":0,"kind":"data","monotonic_ns":306559456505916,"payload":{"event_type":"price_change","market":"0xda6f0e0e93fc8469e0159a166028d017bddbc162b86f66bac90391379603d962","price_changes":[{"asset_id":"39272994714739463168905443499424551362424437245880253267329605556587274644733","best_ask":"0.36","best_bid":"0.35","hash":"d902801e1ccfd3168ea60b512aeb1a1b3c3d133e","price":"0.25","side":"BUY","size":"355"},{"asset_id":"20893381255801015515826997628594359667013752732428989472914000440642900266717","best_ask":"0.65","best_bid":"0.64","hash":"854c3d018315e86b067fadb534b0ae2ac9363a3c","price":"0.75","side":"SELL","size":"355"}],"timestamp":"1785204576562"},"payload_hash":"4b7398d0fb993d0f29fc4abaf374bdaee893a1dff8c4de646270a66640d19943","raw_frame":"{\"market\":\"0xda6f0e0e93fc8469e0159a166028d017bddbc162b86f66bac90391379603d962\", \"price_changes\":[{\"asset_id\":\"39272994714739463168905443499424551362424437245880253267329605556587274644733\", \"price\":\"0.25\", \"size\":\"355\", \"side\":\"BUY\", \"hash\":\"d902801e1ccfd3168ea60b512aeb1a1b3c3d133e\", \"best_bid\":\"0.35\", \"best_ask\":\"0.36\"}, {\"asset_id\":\"20893381255801015515826997628594359667013752732428989472914000440642900266717\", \"price\":\"0.75\", \"size\":\"355\", \"side\":\"SELL\", \"hash\":\"854c3d018315e86b067fadb534b0ae2ac9363a3c\", \"best_bid\":\"0.64\", \"best_ask\":\"0.65\"}], \"timestamp\":\"1785204576562\", \"event_type\":\"price_change\"}","received_at":"2026-07-28T02:09:36.447737Z","schema_version":"clob-market-ws.price_change.v1","sequence":null,"server_hash":null,"server_timestamp":"1785204576562","session_id":"d2757dd6dad94f3b9fe67e8dbf1adc37","source":"clob_market_ws"},"received_at":"2026-07-28T02:09:36.447737Z","record_id":"d97c8f93f59cb07c755b80b5c44f801b38761f0e13641ef3617649b4a652bb79","schema_fingerprint":"4aa3821a28b0b7c2400bc59aba4bcc0a76e971dadd19610d3ad38c768e124dc7","schema_version":"edge-lab-recorder.raw.v1","sequence":null,"source":"clob_market_ws"}
{"event_at":"2026-07-28T02:09:36.586000Z","event_fingerprint":"f9791ce53fe384e9d4858f97a352ba1429ad82cdc75a83221c8cca11c248aec8","payload":{"connection_id":"5d29200f65794d4d9ab6ef271f045a9b","event_at":"2026-07-28T02:09:36.586000Z","event_type":"price_change","frame_hash":"f43a9bef043c306aa2bcb3c811380970780ee34c798ff35f9861d2a5afbaea93","frame_index":0,"kind":"data","monotonic_ns":306559481648958,"payload":{"event_type":"price_change","market":"0xda6f0e0e93fc8469e0159a166028d017bddbc162b86f66bac90391379603d962","price_changes":[{"asset_id":"20893381255801015515826997628594359667013752732428989472914000440642900266717","best_ask":"0.65","best_bid":"0.64","hash":"c85bad36fd5cd4e37f17fb3e2770eef128abefb6","price":"0.03","side":"BUY","size":"662.1"},{"asset_id":"39272994714739463168905443499424551362424437245880253267329605556587274644733","best_ask":"0.36","best_bid":"0.35","hash":"92e8dc23660f08fed921d48aad4daf8343607a03","price":"0.97","side":"SELL","size":"662.1"}],"timestamp":"1785204576586"},"payload_hash":"537f624e4b6396d99e50632876e03a677151ef0c8c3747b4a292529c5321e10a","raw_frame":"{\"market\":\"0xda6f0e0e93fc8469e0159a166028d017bddbc162b86f66bac90391379603d962\", \"price_changes\":[{\"asset_id\":\"20893381255801015515826997628594359667013752732428989472914000440642900266717\", \"price\":\"0.03\", \"size\":\"662.1\", \"side\":\"BUY\", \"hash\":\"c85bad36fd5cd4e37f17fb3e2770eef128abefb6\", \"best_bid\":\"0.64\", \"best_ask\":\"0.65\"}, {\"asset_id\":\"39272994714739463168905443499424551362424437245880253267329605556587274644733\", \"price\":\"0.97\", \"size\":\"662.1\", \"side\":\"SELL\", \"hash\":\"92e8dc23660f08fed921d48aad4daf8343607a03\", \"best_bid\":\"0.35\", \"best_ask\":\"0.36\"}], \"timestamp\":\"1785204576586\", \"event_type\":\"price_change\"}","received_at":"2026-07-28T02:09:36.472882Z","schema_version":"clob-market-ws.price_change.v1","sequence":null,"server_hash":null,"server_timestamp":"1785204576586","session_id":"d2757dd6dad94f3b9fe67e8dbf1adc37","source":"clob_market_ws"},"received_at":"2026-07-28T02:09:36.472882Z","record_id":"1ff7abd6ee975f36333bc503ea76b3383ac42a8f4440ad99576736e27d74beb7","schema_fingerprint":"4aa3821a28b0b7c2400bc59aba4bcc0a76e971dadd19610d3ad38c768e124dc7","schema_version":"edge-lab-recorder.raw.v1","sequence":null,"source":"clob_market_ws"}
{"event_at":"2026-07-28T02:09:36.612000Z","event_fingerprint":"036608f240fcbf1fe9856129a18e8ff9f02df39a7bca25e51b252d3062017b06","payload":{"connection_id":"5d29200f65794d4d9ab6ef271f045a9b","event_at":"2026-07-28T02:09:36.612000Z","event_type":"price_change","frame_hash":"4b9ba4d978d5fe5ae430d2a93040619945e5bb94a0daf23e6831c00e6ae0d0de","frame_index":0,"kind":"data","monotonic_ns":306559506167000,"payload":{"event_type":"price_change","market":"0xda6f0e0e93fc8469e0159a166028d017bddbc162b86f66bac90391379603d962","price_changes":[{"asset_id":"39272994714739463168905443499424551362424437245880253267329605556587274644733","best_ask":"0.36","best_bid":"0.35","hash":"d81b729760e2c003747baf9f8581d1c50e9214a5","price":"0.25","side":"BUY","size":"325"},{"asset_id":"20893381255801015515826997628594359667013752732428989472914000440642900266717","best_ask":"0.65","best_bid":"0.64","hash":"57da3ba8b360a4877552e44e52e1929cdbea5fe4","price":"0.75","side":"SELL","size":"325"}],"timestamp":"1785204576612"},"payload_hash":"1e8a6a75268ef5ddbd388f3a6ccf6be025a047138abe80af830739988955b4cc","raw_frame":"{\"market\":\"0xda6f0e0e93fc8469e0159a166028d017bddbc162b86f66bac90391379603d962\", \"price_changes\":[{\"asset_id\":\"39272994714739463168905443499424551362424437245880253267329605556587274644733\", \"price\":\"0.25\", \"size\":\"325\", \"side\":\"BUY\", \"hash\":\"d81b729760e2c003747baf9f8581d1c50e9214a5\", \"best_bid\":\"0.35\", \"best_ask\":\"0.36\"}, {\"asset_id\":\"20893381255801015515826997628594359667013752732428989472914000440642900266717\", \"price\":\"0.75\", \"size\":\"325\", \"side\":\"SELL\", \"hash\":\"57da3ba8b360a4877552e44e52e1929cdbea5fe4\", \"best_bid\":\"0.64\", \"best_ask\":\"0.65\"}], \"timestamp\":\"1785204576612\", \"event_type\":\"price_change\"}","received_at":"2026-07-28T02:09:36.497402Z","schema_version":"clob-market-ws.price_change.v1","sequence":null,"server_hash":null,"server_timestamp":"1785204576612","session_id":"d2757dd6dad94f3b9fe67e8dbf1adc37","source":"clob_market_ws"},"received_at":"2026-07-28T02:09:36.497402Z","record_id":"e639a9b1fe72d200cf05bcd71f4acf42ec18a3db2a34db99f4966916d7e12701","schema_fingerprint":"4aa3821a28b0b7c2400bc59aba4bcc0a76e971dadd19610d3ad38c768e124dc7","schema_version":"edge-lab-recorder.raw.v1","sequence":null,"source":"clob_market_ws"}
{"event_at":"2026-07-28T02:09:36.622000Z","event_fingerprint":"13a7fc31e3548fcd8d3646424fa549cd8b8255e62df9e30cd010c551a6f92c6f","payload":{"connection_id":"5d29200f65794d4d9ab6ef271f045a9b","event_at":"2026-07-28T02:09:36.622000Z","event_type":"price_change","frame_hash":"a78df7ef311c4c2fa2ab4e0d6b5ed9604a6639ccd57ea6e5d8b5975fa4b7c7de","frame_index":0,"kind":"data","monotonic_ns":306559517811916,"payload":{"event_type":"price_change","market":"0xda6f0e0e93fc8469e0159a166028d017bddbc162b86f66bac90391379603d962","price_changes":[{"asset_id":"20893381255801015515826997628594359667013752732428989472914000440642900266717","best_ask":"0.65","best_bid":"0.64","hash":"34a0fb1ca92d6ab488e243a024c97e1b8f72c5d5","price":"0.63","side":"BUY","size":"158.2"},{"asset_id":"39272994714739463168905443499424551362424437245880253267329605556587274644733","best_ask":"0.36","best_bid":"0.35","hash":"8bf874824d2d6b35bb9aed367f20c55d0d3f3ad4","price":"0.37","side":"SELL","size":"158.2"}],"timestamp":"1785204576622"},"payload_hash":"3f981fa3a0dbd42714a06daaf7ae33afd4a38311ccb560e00bde0a4181921f37","raw_frame":"{\"market\":\"0xda6f0e0e93fc8469e0159a166028d017bddbc162b86f66bac90391379603d962\", \"price_changes\":[{\"asset_id\":\"20893381255801015515826997628594359667013752732428989472914000440642900266717\", \"price\":\"0.63\", \"size\":\"158.2\", \"side\":\"BUY\", \"hash\":\"34a0fb1ca92d6ab488e243a024c97e1b8f72c5d5\", \"best_bid\":\"0.64\", \"best_ask\":\"0.65\"}, {\"asset_id\":\"39272994714739463168905443499424551362424437245880253267329605556587274644733\", \"price\":\"0.37\", \"size\":\"158.2\", \"side\":\"SELL\", \"hash\":\"8bf874824d2d6b35bb9aed367f20c55d0d3f3ad4\", \"best_bid\":\"0.35\", \"best_ask\":\"0.36\"}], \"timestamp\":\"1785204576622\", \"event_type\":\"price_change\"}","received_at":"2026-07-28T02:09:36.509045Z","schema_version":"clob-market-ws.price_change.v1","sequence":null,"server_hash":null,"server_timestamp":"1785204576622","session_id":"d2757dd6dad94f3b9fe67e8dbf1adc37","source":"clob_market_ws"},"received_at":"2026-07-28T02:09:36.509045Z","record_id":"bf44f66a8667369c7d0c7015c961fb8a322d250fbf188a0245856b65c33a0c1b","schema_fingerprint":"4aa3821a28b0b7c2400bc59aba4bcc0a76e971dadd19610d3ad38c768e124dc7","schema_version":"edge-lab-recorder.raw.v1","sequence":null,"source":"clob_market_ws"}
{"event_at":"2026-07-28T02:09:36.622000Z","event_fingerprint":"71f33065b091539ad6882195b059ae8b4784d135fb3e53f2703813a52459a503","payload":{"connection_id":"5d29200f65794d4d9ab6ef271f045a9b","event_at":"2026-07-28T02:09:36.622000Z","event_type":"price_change","frame_hash":"eb9b0cda1664a762debfca09b87c39e66b21ea1daa04e2c716f0be5ac436a418","frame_index":0,"kind":"data","monotonic_ns":306559519471458,"payload":{"event_type":"price_change","market":"0xda6f0e0e93fc8469e0159a166028d017bddbc162b86f66bac90391379603d962","price_changes":[{"asset_id":"39272994714739463168905443499424551362424437245880253267329605556587274644733","best_ask":"0.36","best_bid":"0.35","hash":"6b73500ec1259f2e2b216414cd4b148984b5c6fd","price":"0.27","side":"BUY","size":"239.8"},{"asset_id":"20893381255801015515826997628594359667013752732428989472914000440642900266717","best_ask":"0.65","best_bid":"0.64","hash":"cf6a14688ba42ad1783423837fdd95f416e8182d","price":"0.73","side":"SELL","size":"239.8"}],"timestamp":"1785204576622"},"payload_hash":"aeef08b31877f1372a786f873eab165e8651d4e35e67066f20dda5ece9d35fe5","raw_frame":"{\"market\":\"0xda6f0e0e93fc8469e0159a166028d017bddbc162b86f66bac90391379603d962\", \"price_changes\":[{\"asset_id\":\"39272994714739463168905443499424551362424437245880253267329605556587274644733\", \"price\":\"0.27\", \"size\":\"239.8\", \"side\":\"BUY\", \"hash\":\"6b73500ec1259f2e2b216414cd4b148984b5c6fd\", \"best_bid\":\"0.35\", \"best_ask\":\"0.36\"}, {\"asset_id\":\"20893381255801015515826997628594359667013752732428989472914000440642900266717\", \"price\":\"0.73\", \"size\":\"239.8\", \"side\":\"SELL\", \"hash\":\"cf6a14688ba42ad1783423837fdd95f416e8182d\", \"best_bid\":\"0.64\", \"best_ask\":\"0.65\"}], \"timestamp\":\"1785204576622\", \"event_type\":\"price_change\"}","received_at":"2026-07-28T02:09:36.510707Z","schema_version":"clob-market-ws.price_change.v1","sequence":null,"server_hash":null,"server_timestamp":"1785204576622","session_id":"d2757dd6dad94f3b9fe67e8dbf1adc37","source":"clob_market_ws"},"received_at":"2026-07-28T02:09:36.510707Z","record_id":"9c5508051bf7105d1005279fcab3af2c883f1dbbc60b0ce7af466f30946da14d","schema_fingerprint":"4aa3821a28b0b7c2400bc59aba4bcc0a76e971dadd19610d3ad38c768e124dc7","schema_version":"edge-lab-recorder.raw.v1","sequence":null,"source":"clob_market_ws"}
{"event_at":"2026-07-28T02:09:36.640000Z","event_fingerprint":"527efb2c504c583c13afab47e6cc546d943b21c73d55ea175da994d2a869c205","payload":{"connection_id":"5d29200f65794d4d9ab6ef271f045a9b","event_at":"2026-07-28T02:09:36.640000Z","event_type":"price_change","frame_hash":"3d1d73bb80397817342a844018ec0031f6230abb1e4f971ab09dad684b5e7495","frame_index":0,"kind":"data","monotonic_ns":306559533639583,"payload":{"event_type":"price_change","market":"0xda6f0e0e93fc8469e0159a166028d017bddbc162b86f66bac90391379603d962","price_changes":[{"asset_id":"20893381255801015515826997628594359667013752732428989472914000440642900266717","best_ask":"0.65","best_bid":"0.64","hash":"827a448cef87ca26a300faf25c21a11b00989d8a","price":"0.03","side":"BUY","size":"657.1"},{"asset_id":"39272994714739463168905443499424551362424437245880253267329605556587274644733","best_ask":"0.36","best_bid":"0.35","hash":"2ceaba803d8a1f824b5aceff7e971f99518b67c0","price":"0.97","side":"SELL","size":"657.1"}],"timestamp":"1785204576640"},"payload_hash":"5336390026e7bb4e443a8e6fe23d267bf89985d12f99a72a31b77352b3be17d3","raw_frame":"{\"market\":\"0xda6f0e0e93fc8469e0159a166028d017bddbc162b86f66bac90391379603d962\", \"price_changes\":[{\"asset_id\":\"20893381255801015515826997628594359667013752732428989472914000440642900266717\", \"price\":\"0.03\", \"size\":\"657.1\", \"side\":\"BUY\", \"hash\":\"827a448cef87ca26a300faf25c21a11b00989d8a\", \"best_bid\":\"0.64\", \"best_ask\":\"0.65\"}, {\"asset_id\":\"39272994714739463168905443499424551362424437245880253267329605556587274644733\", \"price\":\"0.97\", \"size\":\"657.1\", \"side\":\"SELL\", \"hash\":\"2ceaba803d8a1f824b5aceff7e971f99518b67c0\", \"best_bid\":\"0.35\", \"best_ask\":\"0.36\"}], \"timestamp\":\"1785204576640\", \"event_type\":\"price_change\"}","received_at":"2026-07-28T02:09:36.524873Z","schema_version":"clob-market-ws.price_change.v1","sequence":null,"server_hash":null,"server_timestamp":"1785204576640","session_id":"d2757dd6dad94f3b9fe67e8dbf1adc37","source":"clob_market_ws"},"received_at":"2026-07-28T02:09:36.524873Z","record_id":"46511c0a2852d7969a467c56eaf9b713334c636d90c5f9ab4af47d10825a332a","schema_fingerprint":"4aa3821a28b0b7c2400bc59aba4bcc0a76e971dadd19610d3ad38c768e124dc7","schema_version":"edge-lab-recorder.raw.v1","sequence":null,"source":"clob_market_ws"}
{"event_at":"2026-07-28T02:09:36.643000Z","event_fingerprint":"d7a8a66033d9c6603cc9cdcffec214de16b1cfa4c61c1f146349dd84d3d1df4b","payload":{"connection_id":"5d29200f65794d4d9ab6ef271f045a9b","event_at":"2026-07-28T02:09:36.643000Z","event_type":"price_change","frame_hash":"b8b3f7bc2e8bbb6224375bb43346250be76e75c5cdf3bcdffe6e607f01d48f59","frame_index":0,"kind":"data","monotonic_ns":306559537132125,"payload":{"event_type":"price_change","market":"0xda6f0e0e93fc8469e0159a166028d017bddbc162b86f66bac90391379603d962","price_changes":[{"asset_id":"39272994714739463168905443499424551362424437245880253267329605556587274644733","best_ask":"0.36","best_bid":"0.35","hash":"e7e8ab9dfe64256ebaab74d40f3c534fcc46435a","price":"0.26","side":"BUY","size":"334.01"},{"asset_id":"20893381255801015515826997628594359667013752732428989472914000440642900266717","best_ask":"0.65","best_bid":"0.64","hash":"7b7e356eeb481f4df6ce7cbfd89d7a647085f633","price":"0.74","side":"SELL","size":"334.01"}],"timestamp":"1785204576643"},"payload_hash":"12ee6abc64aa1d9f7e07b2d4a08696f85f477e920a423c478129425814daaf60","raw_frame":"{\"market\":\"0xda6f0e0e93fc8469e0159a166028d017bddbc162b86f66bac90391379603d962\", \"price_changes\":[{\"asset_id\":\"39272994714739463168905443499424551362424437245880253267329605556587274644733\", \"price\":\"0.26\", \"size\":\"334.01\", \"side\":\"BUY\", \"hash\":\"e7e8ab9dfe64256ebaab74d40f3c534fcc46435a\", \"best_bid\":\"0.35\", \"best_ask\":\"0.36\"}, {\"asset_id\":\"20893381255801015515826997628594359667013752732428989472914000440642900266717\", \"price\":\"0.74\", \"size\":\"334.01\", \"side\":\"SELL\", \"hash\":\"7b7e356eeb481f4df6ce7cbfd89d7a647085f633\", \"best_bid\":\"0.64\", \"best_ask\":\"0.65\"}], \"timestamp\":\"1785204576643\", \"event_type\":\"price_change\"}","received_at":"2026-07-28T02:09:36.528367Z","schema_version":"clob-market-ws.price_change.v1","sequence":null,"server_hash":null,"server_timestamp":"1785204576643","session_id":"d2757dd6dad94f3b9fe67e8dbf1adc37","source":"clob_market_ws"},"received_at":"2026-07-28T02:09:36.528367Z","record_id":"b022655d1ac5ef5bff07fff27fb9b49838a77e0d4b01d7e2b8d74c509e27fcc5","schema_fingerprint":"4aa3821a28b0b7c2400bc59aba4bcc0a76e971dadd19610d3ad38c768e124dc7","schema_version":"edge-lab-recorder.raw.v1","sequence":null,"source":"clob_market_ws"}
{"event_at":"2026-07-28T02:09:36.665000Z","event_fingerprint":"41742d3fff5676ef5ff9b0f3bd6046387223a1c2591d6356d3ccd767c6d67f2b","payload":{"connection_id":"5d29200f65794d4d9ab6ef271f045a9b","event_at":"2026-07-28T02:09:36.665000Z","event_type":"price_change","frame_hash":"52c85e722ee7d686f9ef6fb14164aae8b536f5d3a299d7f3aeef6008952dfd75","frame_index":0,"kind":"data","monotonic_ns":306559558745000,"payload":{"event_type":"price_change","market":"0xda6f0e0e93fc8469e0159a166028d017bddbc162b86f66bac90391379603d962","price_changes":[{"asset_id":"20893381255801015515826997628594359667013752732428989472914000440642900266717","best_ask":"0.65","best_bid":"0.64","hash":"6ca1fca2ecd723a638701a3b5451e7976e2459f2","price":"0.63","side":"BUY","size":"138.2"},{"asset_id":"39272994714739463168905443499424551362424437245880253267329605556587274644733","best_ask":"0.36","best_bid":"0.35","hash":"005d27bbee82a10ea162ba6b1363f0052aa45cfd","price":"0.37","side":"SELL","size":"138.2"}],"timestamp":"1785204576665"},"payload_hash":"458d79eacfa4552790881f663e88dbf23bf4831eeed5a5a950f53a508292c36c","raw_frame":"{\"market\":\"0xda6f0e0e93fc8469e0159a166028d017bddbc162b86f66bac90391379603d962\", \"price_changes\":[{\"asset_id\":\"20893381255801015515826997628594359667013752732428989472914000440642900266717\", \"price\":\"0.63\", \"size\":\"138.2\", \"side\":\"BUY\", \"hash\":\"6ca1fca2ecd723a638701a3b5451e7976e2459f2\", \"best_bid\":\"0.64\", \"best_ask\":\"0.65\"}, {\"asset_id\":\"39272994714739463168905443499424551362424437245880253267329605556587274644733\", \"price\":\"0.37\", \"size\":\"138.2\", \"side\":\"SELL\", \"hash\":\"005d27bbee82a10ea162ba6b1363f0052aa45cfd\", \"best_bid\":\"0.35\", \"best_ask\":\"0.36\"}], \"timestamp\":\"1785204576665\", \"event_type\":\"price_change\"}","received_at":"2026-07-28T02:09:36.549980Z","schema_version":"clob-market-ws.price_change.v1","sequence":null,"server_hash":null,"server_timestamp":"1785204576665","session_id":"d2757dd6dad94f3b9fe67e8dbf1adc37","source":"clob_market_ws"},"received_at":"2026-07-28T02:09:36.549980Z","record_id":"1ccbfef9a08f3f91d34ce944ba41df8852c48d8d85fc0f8493d02e493f0192fc","schema_fingerprint":"4aa3821a28b0b7c2400bc59aba4bcc0a76e971dadd19610d3ad38c768e124dc7","schema_version":"edge-lab-recorder.raw.v1","sequence":null,"source":"clob_market_ws"}
{"event_at":"2026-07-28T02:09:36.665000Z","event_fingerprint":"6fcee5f2b987741193ec9d86a2eccc4a01f2c982f068d250adda27109c9307a9","payload":{"connection_id":"5d29200f65794d4d9ab6ef271f045a9b","event_at":"2026-07-28T02:09:36.665000Z","event_type":"price_change","frame_hash":"b2cccec41a84bd409b2a31aaed8493f36789ad25f8a5b7d912bf86c82064db32","frame_index":0,"kind":"data","monotonic_ns":306559560358833,"payload":{"event_type":"price_change","market":"0xda6f0e0e93fc8469e0159a166028d017bddbc162b86f66bac90391379603d962","price_changes":[{"asset_id":"39272994714739463168905443499424551362424437245880253267329605556587274644733","best_ask":"0.36","best_bid":"0.35","hash":"005d27bbee82a10ea162ba6b1363f0052aa45cfd","price":"0.27","side":"BUY","size":"219.8"},{"asset_id":"20893381255801015515826997628594359667013752732428989472914000440642900266717","best_ask":"0.65","best_bid":"0.64","hash":"6ca1fca2ecd723a638701a3b5451e7976e2459f2","price":"0.73","side":"SELL","size":"219.8"}],"timestamp":"1785204576665"},"payload_hash":"c494bf8401e0e1125cfc42d2943eb81d9b063b7cb9c27255f17bf7fe655378d9","raw_frame":"{\"market\":\"0xda6f0e0e93fc8469e0159a166028d017bddbc162b86f66bac90391379603d962\", \"price_changes\":[{\"asset_id\":\"39272994714739463168905443499424551362424437245880253267329605556587274644733\", \"price\":\"0.27\", \"size\":\"219.8\", \"side\":\"BUY\", \"hash\":\"005d27bbee82a10ea162ba6b1363f0052aa45cfd\", \"best_bid\":\"0.35\", \"best_ask\":\"0.36\"}, {\"asset_id\":\"20893381255801015515826997628594359667013752732428989472914000440642900266717\", \"price\":\"0.73\", \"size\":\"219.8\", \"side\":\"SELL\", \"hash\":\"6ca1fca2ecd723a638701a3b5451e7976e2459f2\", \"best_bid\":\"0.64\", \"best_ask\":\"0.65\"}], \"timestamp\":\"1785204576665\", \"event_type\":\"price_change\"}","received_at":"2026-07-28T02:09:36.551593Z","schema_version":"clob-market-ws.price_change.v1","sequence":null,"server_hash":null,"server_timestamp":"1785204576665","session_id":"d2757dd6dad94f3b9fe67e8dbf1adc37","source":"clob_market_ws"},"received_at":"2026-07-28T02:09:36.551593Z","record_id":"3f9e5616eacfedce0f404bef6aba39ac11bc1daa50a3c6b4a3c2f522d3170c1a","schema_fingerprint":"4aa3821a28b0b7c2400bc59aba4bcc0a76e971dadd19610d3ad38c768e124dc7","schema_version":"edge-lab-recorder.raw.v1","sequence":null,"source":"clob_market_ws"}
{"event_at":"2026-07-28T02:09:36.670000Z","event_fingerprint":"621312be879bf87033eb56510b3206783308ce6844bf57e6c044dab89c8dcc9b","payload":{"connection_id":"5d29200f65794d4d9ab6ef271f045a9b","event_at":"2026-07-28T02:09:36.670000Z","event_type":"price_change","frame_hash":"02b7636fc940540fc267f5f58fd8986bc7440d409a4998d32cefab2a0361f213","frame_index":0,"kind":"data","monotonic_ns":306559563712583,"payload":{"event_type":"price_change","market":"0xda6f0e0e93fc8469e0159a166028d017bddbc162b86f66bac90391379603d962","price_changes":[{"asset_id":"39272994714739463168905443499424551362424437245880253267329605556587274644733","best_ask":"0.36","best_bid":"0.35","hash":"c3ed376f71a3c709b9cfb1262c70cd652fe8cafa","price":"0.25","side":"BUY","size":"295"},{"asset_id":"20893381255801015515826997628594359667013752732428989472914000440642900266717","best_ask":"0.65","best_bid":"0.64","hash":"c9fb3ec3be22cf4a0ee74ced61f7d4bdbd5eac74","price":"0.75","side":"SELL","size":"295"}],"timestamp":"1785204576670"},"payload_hash":"dc4dc3c8885058d734b180b5983f1c6affe8a3b0123a7b42d745167960818262","raw_frame":"{\"market\":\"0xda6f0e0e93fc8469e0159a166028d017bddbc162b86f66bac90391379603d962\", \"price_changes\":[{\"asset_id\":\"39272994714739463168905443499424551362424437245880253267329605556587274644733\", \"price\":\"0.25\", \"size\":\"295\", \"side\":\"BUY\", \"hash\":\"c3ed376f71a3c709b9cfb1262c70cd652fe8cafa\", \"best_bid\":\"0.35\", \"best_ask\":\"0.36\"}, {\"asset_id\":\"20893381255801015515826997628594359667013752732428989472914000440642900266717\", \"price\":\"0.75\", \"size\":\"295\", \"side\":\"SELL\", \"hash\":\"c9fb3ec3be22cf4a0ee74ced61f7d4bdbd5eac74\", \"best_bid\":\"0.64\", \"best_ask\":\"0.65\"}], \"timestamp\":\"1785204576670\", \"event_type\":\"price_change\"}","received_at":"2026-07-28T02:09:36.554946Z","schema_version":"clob-market-ws.price_change.v1","sequence":null,"server_hash":null,"server_timestamp":"1785204576670","session_id":"d2757dd6dad94f3b9fe67e8dbf1adc37","source":"clob_market_ws"},"received_at":"2026-07-28T02:09:36.554946Z","record_id":"2de51df9f473b1ada59d5ebd7dffb3357b219c78db718a0f2d1b212f8e15f695","schema_fingerprint":"4aa3821a28b0b7c2400bc59aba4bcc0a76e971dadd19610d3ad38c768e124dc7","schema_version":"edge-lab-recorder.raw.v1","sequence":null,"source":"clob_market_ws"}
{"event_at":"2026-07-28T02:09:36.731000Z","event_fingerprint":"9c4c01e8d93fc6810d32cb3ed1e561c21aecdbce3ca1e3a878ebaf56253567e6","payload":{"connection_id":"5d29200f65794d4d9ab6ef271f045a9b","event_at":"2026-07-28T02:09:36.731000Z","event_type":"price_change","frame_hash":"bf2e733867ec77662c53e8aa3283410dbd614ff0bba0fe3dbd51902d0608cecd","frame_index":0,"kind":"data","monotonic_ns":306559626599083,"payload":{"event_type":"price_change","market":"0xda6f0e0e93fc8469e0159a166028d017bddbc162b86f66bac90391379603d962","price_changes":[{"asset_id":"20893381255801015515826997628594359667013752732428989472914000440642900266717","best_ask":"0.65","best_bid":"0.64","hash":"6f92431af461fb4f68f0bf1373986525d0e584e2","price":"0.62","side":"BUY","size":"157.2"},{"asset_id":"39272994714739463168905443499424551362424437245880253267329605556587274644733","best_ask":"0.36","best_bid":"0.35","hash":"a50f7ac9b8bc68a3700638980326c4b54b44c63e","price":"0.38","side":"SELL","size":"157.2"}],"timestamp":"1785204576731"},"payload_hash":"d6d96c4f8cf072374734cba934b229d27c3f2103043da0b0a584dcadf1414e75","raw_frame":"{\"market\":\"0xda6f0e0e93fc8469e0159a166028d017bddbc162b86f66bac90391379603d962\", \"price_changes\":[{\"asset_id\":\"20893381255801015515826997628594359667013752732428989472914000440642900266717\", \"price\":\"0.62\", \"size\":\"157.2\", \"side\":\"BUY\", \"hash\":\"6f92431af461fb4f68f0bf1373986525d0e584e2\", \"best_bid\":\"0.64\", \"best_ask\":\"0.65\"}, {\"asset_id\":\"39272994714739463168905443499424551362424437245880253267329605556587274644733\", \"price\":\"0.38\", \"size\":\"157.2\", \"side\":\"SELL\", \"hash\":\"a50f7ac9b8bc68a3700638980326c4b54b44c63e\", \"best_bid\":\"0.35\", \"best_ask\":\"0.36\"}], \"timestamp\":\"1785204576731\", \"event_type\":\"price_change\"}","received_at":"2026-07-28T02:09:36.617835Z","schema_version":"clob-market-ws.price_change.v1","sequence":null,"server_hash":null,"server_timestamp":"1785204576731","session_id":"d2757dd6dad94f3b9fe67e8dbf1adc37","source":"clob_market_ws"},"received_at":"2026-07-28T02:09:36.617835Z","record_id":"4353c8e39fb2088d390be98af0bf4f4718fd2858e0310d7cfa90a7df9cb4e85e","schema_fingerprint":"4aa3821a28b0b7c2400bc59aba4bcc0a76e971dadd19610d3ad38c768e124dc7","schema_version":"edge-lab-recorder.raw.v1","sequence":null,"source":"clob_market_ws"}
{"event_at":"2026-07-28T02:09:36.732000Z","event_fingerprint":"428c5de9f503cee55638bb8583095131dbe1a8a6697792965d55086036c3cf59","payload":{"connection_id":"5d29200f65794d4d9ab6ef271f045a9b","event_at":"2026-07-28T02:09:36.732000Z","event_type":"price_change","frame_hash":"a21b6d8886d7b161db341f22ac3f9d1edb39ea70be4299a711d8be2d7c8e2302","frame_index":0,"kind":"data","monotonic_ns":306559628175375,"payload":{"event_type":"price_change","market":"0xda6f0e0e93fc8469e0159a166028d017bddbc162b86f66bac90391379603d962","price_changes":[{"asset_id":"39272994714739463168905443499424551362424437245880253267329605556587274644733","best_ask":"0.36","best_bid":"0.35","hash":"3c52b9560c25e0dbf2d60e766d9233f98a055415","price":"0.27","side":"BUY","size":"239.8"},{"asset_id":"20893381255801015515826997628594359667013752732428989472914000440642900266717","best_ask":"0.65","best_bid":"0.64","hash":"6b77619dc06daaf225642d4b9a730cf8435d70e7","price":"0.73","side":"SELL","size":"239.8"}],"timestamp":"1785204576732"},"payload_hash":"8d2a15316f96ef5d0c558018c3949acd83a331b13ced0c572c7364a586829ea0","raw_frame":"{\"market\":\"0xda6f0e0e93fc8469e0159a166028d017bddbc162b86f66bac90391379603d962\", \"price_changes\":[{\"asset_id\":\"39272994714739463168905443499424551362424437245880253267329605556587274644733\", \"price\":\"0.27\", \"size\":\"239.8\", \"side\":\"BUY\", \"hash\":\"3c52b9560c25e0dbf2d60e766d9233f98a055415\", \"best_bid\":\"0.35\", \"best_ask\":\"0.36\"}, {\"asset_id\":\"20893381255801015515826997628594359667013752732428989472914000440642900266717\", \"price\":\"0.73\", \"size\":\"239.8\", \"side\":\"SELL\", \"hash\":\"6b77619dc06daaf225642d4b9a730cf8435d70e7\", \"best_bid\":\"0.64\", \"best_ask\":\"0.65\"}], \"timestamp\":\"1785204576732\", \"event_type\":\"price_change\"}","received_at":"2026-07-28T02:09:36.619410Z","schema_version":"clob-market-ws.price_change.v1","sequence":null,"server_hash":null,"server_timestamp":"1785204576732","session_id":"d2757dd6dad94f3b9fe67e8dbf1adc37","source":"clob_market_ws"},"received_at":"2026-07-28T02:09:36.619410Z","record_id":"c6f971da3d5b8609e5985b4744dc06874d6140916e7d231a86b4ae9db1c37a0a","schema_fingerprint":"4aa3821a28b0b7c2400bc59aba4bcc0a76e971dadd19610d3ad38c768e124dc7","schema_version":"edge-lab-recorder.raw.v1","sequence":null,"source":"clob_market_ws"}
{"event_at":"2026-07-28T02:09:36.754000Z","event_fingerprint":"ee5611ff0110f689b8eaa9e945d6bacd5bb36981a0c25b67d4b96c805c8b6289","payload":{"connection_id":"5d29200f65794d4d9ab6ef271f045a9b","event_at":"2026-07-28T02:09:36.754000Z","event_type":"price_change","frame_hash":"e2321f2a9b6004d8fc4ef8e44ead55ffbbe791c501f31ef60c65172b55cee6dc","frame_index":0,"kind":"data","monotonic_ns":306559648504916,"payload":{"event_type":"price_change","market":"0xda6f0e0e93fc8469e0159a166028d017bddbc162b86f66bac90391379603d962","price_changes":[{"asset_id":"20893381255801015515826997628594359667013752732428989472914000440642900266717","best_ask":"0.65","best_bid":"0.64","hash":"faa607525e16592fe684013e01099808781a409e","price":"0.04","side":"BUY","size":"667.09"},{"asset_id":"39272994714739463168905443499424551362424437245880253267329605556587274644733","best_ask":"0.36","best_bid":"0.35","hash":"de0779dd7d0cf4852533739f3c67de6488a4e6a4","price":"0.96","side":"SELL","size":"667.09"}],"timestamp":"1785204576754"},"payload_hash":"6253c539bd6375ffa75391be0f39eceaa997dcd4fa28ebccebfee3c496dc7920","raw_frame":"{\"market\":\"0xda6f0e0e93fc8469e0159a166028d017bddbc162b86f66bac90391379603d962\", \"price_changes\":[{\"asset_id\":\"20893381255801015515826997628594359667013752732428989472914000440642900266717\", \"price\":\"0.04\", \"size\":\"667.09\", \"side\":\"BUY\", \"hash\":\"faa607525e16592fe684013e01099808781a409e\", \"best_bid\":\"0.64\", \"best_ask\":\"0.65\"}, {\"asset_id\":\"39272994714739463168905443499424551362424437245880253267329605556587274644733\", \"price\":\"0.96\", \"size\":\"667.09\", \"side\":\"SELL\", \"hash\":\"de0779dd7d0cf4852533739f3c67de6488a4e6a4\", \"best_bid\":\"0.35\", \"best_ask\":\"0.36\"}], \"timestamp\":\"1785204576754\", \"event_type\":\"price_change\"}","received_at":"2026-07-28T02:09:36.639738Z","schema_version":"clob-market-ws.price_change.v1","sequence":null,"server_hash":null,"server_timestamp":"1785204576754","session_id":"d2757dd6dad94f3b9fe67e8dbf1adc37","source":"clob_market_ws"},"received_at":"2026-07-28T02:09:36.639738Z","record_id":"92abf9c7c0fe78efb8f255c2c602950eca44c960abc12cfca4f5765a56f237cd","schema_fingerprint":"4aa3821a28b0b7c2400bc59aba4bcc0a76e971dadd19610d3ad38c768e124dc7","schema_version":"edge-lab-recorder.raw.v1","sequence":null,"source":"clob_market_ws"}
{"event_at":"2026-07-28T02:09:36.758000Z","event_fingerprint":"209b5478dd043e78891200ebfdf8d8d2915e610de86040ad88c935133ac63388","payload":{"connection_id":"5d29200f65794d4d9ab6ef271f045a9b","event_at":"2026-07-28T02:09:36.758000Z","event_type":"price_change","frame_hash":"cb1a2e643e5c226a4d148c11b21ad233a408e1a5c482f59a0f15e25ef6bd1ec5","frame_index":0,"kind":"data","monotonic_ns":306559652365125,"payload":{"event_type":"price_change","market":"0xda6f0e0e93fc8469e0159a166028d017bddbc162b86f66bac90391379603d962","price_changes":[{"asset_id":"39272994714739463168905443499424551362424437245880253267329605556587274644733","best_ask":"0.36","best_bid":"0.35","hash":"831a8cd16ce5a6e4b0ed9ca54b2b62774754f080","price":"0.25","side":"BUY","size":"325"},{"asset_id":"20893381255801015515826997628594359667013752732428989472914000440642900266717","best_ask":"0.65","best_bid":"0.64","hash":"bf7a4ba16feddc83f30362b4179ac345ed12d794","price":"0.75","side":"SELL","size":"325"}],"timestamp":"1785204576758"},"payload_hash":"1a128f4e906b183350acc6ecaea617537f28f02b3c503a5b033cd8ccf62eefe1","raw_frame":"{\"market\":\"0xda6f0e0e93fc8469e0159a166028d017bddbc162b86f66bac90391379603d962\", \"price_changes\":[{\"asset_id\":\"39272994714739463168905443499424551362424437245880253267329605556587274644733\", \"price\":\"0.25\", \"size\":\"325\", \"side\":\"BUY\", \"hash\":\"831a8cd16ce5a6e4b0ed9ca54b2b62774754f080\", \"best_bid\":\"0.35\", \"best_ask\":\"0.36\"}, {\"asset_id\":\"20893381255801015515826997628594359667013752732428989472914000440642900266717\", \"price\":\"0.75\", \"size\":\"325\", \"side\":\"SELL\", \"hash\":\"bf7a4ba16feddc83f30362b4179ac345ed12d794\", \"best_bid\":\"0.64\", \"best_ask\":\"0.65\"}], \"timestamp\":\"1785204576758\", \"event_type\":\"price_change\"}","received_at":"2026-07-28T02:09:36.643601Z","schema_version":"clob-market-ws.price_change.v1","sequence":null,"server_hash":null,"server_timestamp":"1785204576758","session_id":"d2757dd6dad94f3b9fe67e8dbf1adc37","source":"clob_market_ws"},"received_at":"2026-07-28T02:09:36.643601Z","record_id":"5df95910ad72e21f317bed7f09f93da62b3139c7ccaa6469c3f0a396ab269389","schema_fingerprint":"4aa3821a28b0b7c2400bc59aba4bcc0a76e971dadd19610d3ad38c768e124dc7","schema_version":"edge-lab-recorder.raw.v1","sequence":null,"source":"clob_market_ws"}
{"event_at":"2026-07-28T02:09:36.875000Z","event_fingerprint":"711f7b1bded555b389c68c3d5cb98df7fa2897209234991021d2e87281781eac","payload":{"connection_id":"5d29200f65794d4d9ab6ef271f045a9b","event_at":"2026-07-28T02:09:36.875000Z","event_type":"price_change","frame_hash":"efb1c5f61c51481fb660e6c0ed1a50a39656681f80a33826725f5133b90eadf8","frame_index":0,"kind":"data","monotonic_ns":306559768954666,"payload":{"event_type":"price_change","market":"0xda6f0e0e93fc8469e0159a166028d017bddbc162b86f66bac90391379603d962","price_changes":[{"asset_id":"39272994714739463168905443499424551362424437245880253267329605556587274644733","best_ask":"0.36","best_bid":"0.35","hash":"50d4341a362b8c29dd380cb55dbd34ac730f9abe","price":"0.26","side":"BUY","size":"304.01"},{"asset_id":"20893381255801015515826997628594359667013752732428989472914000440642900266717","best_ask":"0.65","best_bid":"0.64","hash":"d0ba6001e5ae12cc0bc8cf25142865d8a5f8dd89","price":"0.74","side":"SELL","size":"304.01"}],"timestamp":"1785204576875"},"payload_hash":"d430b231cada4c01a6dae020c27ece60f23357385d4e637fa494536e5011d937","raw_frame":"{\"market\":\"0xda6f0e0e93fc8469e0159a166028d017bddbc162b86f66bac90391379603d962\", \"price_changes\":[{\"asset_id\":\"39272994714739463168905443499424551362424437245880253267329605556587274644733\", \"price\":\"0.26\", \"size\":\"304.01\", \"side\":\"BUY\", \"hash\":\"50d4341a362b8c29dd380cb55dbd34ac730f9abe\", \"best_bid\":\"0.35\", \"best_ask\":\"0.36\"}, {\"asset_id\":\"20893381255801015515826997628594359667013752732428989472914000440642900266717\", \"price\":\"0.74\", \"size\":\"304.01\", \"side\":\"SELL\", \"hash\":\"d0ba6001e5ae12cc0bc8cf25142865d8a5f8dd89\", \"best_bid\":\"0.64\", \"best_ask\":\"0.65\"}], \"timestamp\":\"1785204576875\", \"event_type\":\"price_change\"}","received_at":"2026-07-28T02:09:36.760186Z","schema_version":"clob-market-ws.price_change.v1","sequence":null,"server_hash":null,"server_timestamp":"1785204576875","session_id":"d2757dd6dad94f3b9fe67e8dbf1adc37","source":"clob_market_ws"},"received_at":"2026-07-28T02:09:36.760186Z","record_id":"20834607aff46dafa6c48013299d39f916850b9c76dbacff9b40558962f414c3","schema_fingerprint":"4aa3821a28b0b7c2400bc59aba4bcc0a76e971dadd19610d3ad38c768e124dc7","schema_version":"edge-lab-recorder.raw.v1","sequence":null,"source":"clob_market_ws"}
{"event_at":"2026-07-28T02:09:36.882000Z","event_fingerprint":"e51f34f91dd364a974295986c4c4789933198dd035d617efda32431e1ea64961","payload":{"connection_id":"5d29200f65794d4d9ab6ef271f045a9b","event_at":"2026-07-28T02:09:36.882000Z","event_type":"price_change","frame_hash":"be74b5ca8ad80a853e949d262b250b22fe3708523ed55d311cfc43fda0107330","frame_index":0,"kind":"data","monotonic_ns":306559776083750,"payload":{"event_type":"price_change","market":"0xda6f0e0e93fc8469e0159a166028d017bddbc162b86f66bac90391379603d962","price_changes":[{"asset_id":"20893381255801015515826997628594359667013752732428989472914000440642900266717","best_ask":"0.65","best_bid":"0.64","hash":"a4e50b0adade4ee03a691289a2d7c0e7d430bc43","price":"0.04","side":"BUY","size":"662.09"},{"asset_id":"39272994714739463168905443499424551362424437245880253267329605556587274644733","best_ask":"0.36","best_bid":"0.35","hash":"265b50647b9f312ddb2988953d8ea35fdbe430c4","price":"0.96","side":"SELL","size":"662.09"}],"timestamp":"1785204576882"},"payload_hash":"0cd254171cd26cdeced24547fb1fbb395d5d83ad8c16872a5cf563065582e738","raw_frame":"{\"market\":\"0xda6f0e0e93fc8469e0159a166028d017bddbc162b86f66bac90391379603d962\", \"price_changes\":[{\"asset_id\":\"20893381255801015515826997628594359667013752732428989472914000440642900266717\", \"price\":\"0.04\", \"size\":\"662.09\", \"side\":\"BUY\", \"hash\":\"a4e50b0adade4ee03a691289a2d7c0e7d430bc43\", \"best_bid\":\"0.64\", \"best_ask\":\"0.65\"}, {\"asset_id\":\"39272994714739463168905443499424551362424437245880253267329605556587274644733\", \"price\":\"0.96\", \"size\":\"662.09\", \"side\":\"SELL\", \"hash\":\"265b50647b9f312ddb2988953d8ea35fdbe430c4\", \"best_bid\":\"0.35\", \"best_ask\":\"0.36\"}], \"timestamp\":\"1785204576882\", \"event_type\":\"price_change\"}","received_at":"2026-07-28T02:09:36.767315Z","schema_version":"clob-market-ws.price_change.v1","sequence":null,"server_hash":null,"server_timestamp":"1785204576882","session_id":"d2757dd6dad94f3b9fe67e8dbf1adc37","source":"clob_market_ws"},"received_at":"2026-07-28T02:09:36.767315Z","record_id":"bc3ed9e6ab01dbc9692414b5febd74799b0522a1f662c35980f8a0586e37ed6b","schema_fingerprint":"4aa3821a28b0b7c2400bc59aba4bcc0a76e971dadd19610d3ad38c768e124dc7","schema_version":"edge-lab-recorder.raw.v1","sequence":null,"source":"clob_market_ws"}
{"event_at":"2026-07-28T02:09:36.908000Z","event_fingerprint":"dec99fa587feb1d644d8d4be58e42caef538bffd85b272ca50d46e7a49bd13ee","payload":{"connection_id":"5d29200f65794d4d9ab6ef271f045a9b","event_at":"2026-07-28T02:09:36.908000Z","event_type":"price_change","frame_hash":"bd7c88875d9efb944a17edf20f9cc11877223a274ca682dd2c148e57e95f87f7","frame_index":0,"kind":"data","monotonic_ns":306559802627958,"payload":{"event_type":"price_change","market":"0xda6f0e0e93fc8469e0159a166028d017bddbc162b86f66bac90391379603d962","price_changes":[{"asset_id":"39272994714739463168905443499424551362424437245880253267329605556587274644733","best_ask":"0.36","best_bid":"0.35","hash":"6f604bd012793d3e9de9bbcbd59001e8f7f4139a","price":"0.25","side":"BUY","size":"355"},{"asset_id":"20893381255801015515826997628594359667013752732428989472914000440642900266717","best_ask":"0.65","best_bid":"0.64","hash":"101a9f8744db5129eaf0c1e08a543ba71a84d74c","price":"0.75","side":"SELL","size":"355"}],"timestamp":"1785204576908"},"payload_hash":"240829ba0d127e48bcc0c9554bfa138ef4a7d6d56554b9eb97976b70eab20dc2","raw_frame":"{\"market\":\"0xda6f0e0e93fc8469e0159a166028d017bddbc162b86f66bac90391379603d962\", \"price_changes\":[{\"asset_id\":\"39272994714739463168905443499424551362424437245880253267329605556587274644733\", \"price\":\"0.25\", \"size\":\"355\", \"side\":\"BUY\", \"hash\":\"6f604bd012793d3e9de9bbcbd59001e8f7f4139a\", \"best_bid\":\"0.35\", \"best_ask\":\"0.36\"}, {\"asset_id\":\"20893381255801015515826997628594359667013752732428989472914000440642900266717\", \"price\":\"0.75\", \"size\":\"355\", \"side\":\"SELL\", \"hash\":\"101a9f8744db5129eaf0c1e08a543ba71a84d74c\", \"best_bid\":\"0.64\", \"best_ask\":\"0.65\"}], \"timestamp\":\"1785204576908\", \"event_type\":\"price_change\"}","received_at":"2026-07-28T02:09:36.793862Z","schema_version":"clob-market-ws.price_change.v1","sequence":null,"server_hash":null,"server_timestamp":"1785204576908","session_id":"d2757dd6dad94f3b9fe67e8dbf1adc37","source":"clob_market_ws"},"received_at":"2026-07-28T02:09:36.793862Z","record_id":"72bcb3f8edb3315b27b70631856f7e1d735cd9c5a19c3fb810e4c40c61c61941","schema_fingerprint":"4aa3821a28b0b7c2400bc59aba4bcc0a76e971dadd19610d3ad38c768e124dc7","schema_version":"edge-lab-recorder.raw.v1","sequence":null,"source":"clob_market_ws"}
{"event_at":"2026-07-28T02:09:36.914000Z","event_fingerprint":"c08142d606e8c43c4a2cd1cdcd504c763d19ea7ec6b37466d8d73bf00cb30a47","payload":{"connection_id":"5d29200f65794d4d9ab6ef271f045a9b","event_at":"2026-07-28T02:09:36.914000Z","event_type":"price_change","frame_hash":"1b35a09b36d2570e12ec7f3bac8e45ddec12183a6718cfead21acf5ff7362b3f","frame_index":0,"kind":"data","monotonic_ns":306559808333708,"payload":{"event_type":"price_change","market":"0xda6f0e0e93fc8469e0159a166028d017bddbc162b86f66bac90391379603d962","price_changes":[{"asset_id":"20893381255801015515826997628594359667013752732428989472914000440642900266717","best_ask":"0.65","best_bid":"0.64","hash":"09fe4e5981e16d3fe4eda0954b77c748bcb0b68f","price":"0.01","side":"BUY","size":"5682.02"},{"asset_id":"39272994714739463168905443499424551362424437245880253267329605556587274644733","best_ask":"0.36","best_bid":"0.35","hash":"c8cbb74a83c4006ee75a6ef1c378a079548769f4","price":"0.99","side":"SELL","size":"5682.02"}],"timestamp":"1785204576914"},"payload_hash":"1931072f0a1bc30401a0b185bead647f607d5a32113da3b031d3d896d81dcbf4","raw_frame":"{\"market\":\"0xda6f0e0e93fc8469e0159a166028d017bddbc162b86f66bac90391379603d962\", \"price_changes\":[{\"asset_id\":\"20893381255801015515826997628594359667013752732428989472914000440642900266717\", \"price\":\"0.01\", \"size\":\"5682.02\", \"side\":\"BUY\", \"hash\":\"09fe4e5981e16d3fe4eda0954b77c748bcb0b68f\", \"best_bid\":\"0.64\", \"best_ask\":\"0.65\"}, {\"asset_id\":\"39272994714739463168905443499424551362424437245880253267329605556587274644733\", \"price\":\"0.99\", \"size\":\"5682.02\", \"side\":\"SELL\", \"hash\":\"c8cbb74a83c4006ee75a6ef1c378a079548769f4\", \"best_bid\":\"0.35\", \"best_ask\":\"0.36\"}], \"timestamp\":\"1785204576914\", \"event_type\":\"price_change\"}","received_at":"2026-07-28T02:09:36.799568Z","schema_version":"clob-market-ws.price_change.v1","sequence":null,"server_hash":null,"server_timestamp":"1785204576914","session_id":"d2757dd6dad94f3b9fe67e8dbf1adc37","source":"clob_market_ws"},"received_at":"2026-07-28T02:09:36.799568Z","record_id":"72d45e21ac62803daa4dd18e6abdfa7cb1e93ccbb7d15d0df5d54f4bd31ffcc4","schema_fingerprint":"4aa3821a28b0b7c2400bc59aba4bcc0a76e971dadd19610d3ad38c768e124dc7","schema_version":"edge-lab-recorder.raw.v1","sequence":null,"source":"clob_market_ws"}
{"event_at":"2026-07-28T02:09:36.932000Z","event_fingerprint":"3ab81a0576a712ecd9807efefa68a2de40bb6c80bcc4934e961ea9198f7df70d","payload":{"connection_id":"5d29200f65794d4d9ab6ef271f045a9b","event_at":"2026-07-28T02:09:36.932000Z","event_type":"price_change","frame_hash":"9992da2f4acc2501e47d23dbe6a634097aafc3a57996437f55a2aafe871ec406","frame_index":0,"kind":"data","monotonic_ns":306559826343666,"payload":{"event_type":"price_change","market":"0xda6f0e0e93fc8469e0159a166028d017bddbc162b86f66bac90391379603d962","price_changes":[{"asset_id":"20893381255801015515826997628594359667013752732428989472914000440642900266717","best_ask":"0.65","best_bid":"0.64","hash":"9ff52c7292f93d72f161e0c7e41b07e17ef0bad6","price":"0.01","side":"BUY","size":"5677.02"},{"asset_id":"39272994714739463168905443499424551362424437245880253267329605556587274644733","best_ask":"0.36","best_bid":"0.35","hash":"578fa3e238ffedd47a8aab1d5d30b8ea395d8677","price":"0.99","side":"SELL","size":"5677.02"}],"timestamp":"1785204576932"},"payload_hash":"d9f1dc8010bd125247e6785767ebd0cbe8de1b7d3e38508a6a21e219f00b430d","raw_frame":"{\"market\":\"0xda6f0e0e93fc8469e0159a166028d017bddbc162b86f66bac90391379603d962\", \"price_changes\":[{\"asset_id\":\"20893381255801015515826997628594359667013752732428989472914000440642900266717\", \"price\":\"0.01\", \"size\":\"5677.02\", \"side\":\"BUY\", \"hash\":\"9ff52c7292f93d72f161e0c7e41b07e17ef0bad6\", \"best_bid\":\"0.64\", \"best_ask\":\"0.65\"}, {\"asset_id\":\"39272994714739463168905443499424551362424437245880253267329605556587274644733\", \"price\":\"0.99\", \"size\":\"5677.02\", \"side\":\"SELL\", \"hash\":\"578fa3e238ffedd47a8aab1d5d30b8ea395d8677\", \"best_bid\":\"0.35\", \"best_ask\":\"0.36\"}], \"timestamp\":\"1785204576932\", \"event_type\":\"price_change\"}","received_at":"2026-07-28T02:09:36.817573Z","schema_version":"clob-market-ws.price_change.v1","sequence":null,"server_hash":null,"server_timestamp":"1785204576932","session_id":"d2757dd6dad94f3b9fe67e8dbf1adc37","source":"clob_market_ws"},"received_at":"2026-07-28T02:09:36.817573Z","record_id":"e0433c12eb61937a26732399b15d9761c6f820d51e053aca4bc42edac82dc740","schema_fingerprint":"4aa3821a28b0b7c2400bc59aba4bcc0a76e971dadd19610d3ad38c768e124dc7","schema_version":"edge-lab-recorder.raw.v1","sequence":null,"source":"clob_market_ws"}
{"event_at":"2026-07-28T02:09:36.936000Z","event_fingerprint":"97011b2b61ce70f7b07cbf46f76d710ce5b1999ee250de327eefcd977a421c7b","payload":{"connection_id":"5d29200f65794d4d9ab6ef271f045a9b","event_at":"2026-07-28T02:09:36.936000Z","event_type":"price_change","frame_hash":"3a9fcd814ea2a9e98150ce32d13b828ef3e1c6ca2d6c2c5e4e5e0472be8584b5","frame_index":0,"kind":"data","monotonic_ns":306559830992416,"payload":{"event_type":"price_change","market":"0xda6f0e0e93fc8469e0159a166028d017bddbc162b86f66bac90391379603d962","price_changes":[{"asset_id":"39272994714739463168905443499424551362424437245880253267329605556587274644733","best_ask":"0.36","best_bid":"0.35","hash":"4c542fb5bca363955a6db4a50711dde55e523852","price":"0.01","side":"BUY","size":"5598.02"},{"asset_id":"20893381255801015515826997628594359667013752732428989472914000440642900266717","best_ask":"0.65","best_bid":"0.64","hash":"f917f63bf805861ea89d81ab5477558d1f5624db","price":"0.99","side":"SELL","size":"5598.02"}],"timestamp":"1785204576936"},"payload_hash":"6c811fb6f731fe0e09875595479e13b1db918c4ab464b510b1c1f1a3c75a04d1","raw_frame":"{\"market\":\"0xda6f0e0e93fc8469e0159a166028d017bddbc162b86f66bac90391379603d962\", \"price_changes\":[{\"asset_id\":\"39272994714739463168905443499424551362424437245880253267329605556587274644733\", \"price\":\"0.01\", \"size\":\"5598.02\", \"side\":\"BUY\", \"hash\":\"4c542fb5bca363955a6db4a50711dde55e523852\", \"best_bid\":\"0.35\", \"best_ask\":\"0.36\"}, {\"asset_id\":\"20893381255801015515826997628594359667013752732428989472914000440642900266717\", \"price\":\"0.99\", \"size\":\"5598.02\", \"side\":\"SELL\", \"hash\":\"f917f63bf805861ea89d81ab5477558d1f5624db\", \"best_bid\":\"0.64\", \"best_ask\":\"0.65\"}], \"timestamp\":\"1785204576936\", \"event_type\":\"price_change\"}","received_at":"2026-07-28T02:09:36.822225Z","schema_version":"clob-market-ws.price_change.v1","sequence":null,"server_hash":null,"server_timestamp":"1785204576936","session_id":"d2757dd6dad94f3b9fe67e8dbf1adc37","source":"clob_market_ws"},"received_at":"2026-07-28T02:09:36.822225Z","record_id":"64754bfed601e240b0b7316f9e83d3645f1e25db97a15c388b8d2cb626abfc17","schema_fingerprint":"4aa3821a28b0b7c2400bc59aba4bcc0a76e971dadd19610d3ad38c768e124dc7","schema_version":"edge-lab-recorder.raw.v1","sequence":null,"source":"clob_market_ws"}
{"event_at":"2026-07-28T02:09:36.936000Z","event_fingerprint":"ae039a035d95d8029f595a20dd85f9db8d9222f6f3a0203c61efa773599dba1f","payload":{"connection_id":"5d29200f65794d4d9ab6ef271f045a9b","event_at":"2026-07-28T02:09:36.936000Z","event_type":"price_change","frame_hash":"1d5a540ef6de592d1a00f1226618d02db4092c8d8bd2497c3fa8ceaf6e24ce23","frame_index":0,"kind":"data","monotonic_ns":306559832625500,"payload":{"event_type":"price_change","market":"0xda6f0e0e93fc8469e0159a166028d017bddbc162b86f66bac90391379603d962","price_changes":[{"asset_id":"20893381255801015515826997628594359667013752732428989472914000440642900266717","best_ask":"0.65","best_bid":"0.64","hash":"679739d6a4058712831f13fc4adcb1197cc550fc","price":"0.01","side":"BUY","size":"5682.02"},{"asset_id":"39272994714739463168905443499424551362424437245880253267329605556587274644733","best_ask":"0.36","best_bid":"0.35","hash":"756a6f58ef0a6e954e3aac79a8583e6f5619320f","price":"0.99","side":"SELL","size":"5682.02"}],"timestamp":"1785204576936"},"payload_hash":"649fc663fd3e0cbf52da4c141a6345e7c597aaf4f2a1d3aead8d86db04b9565f","raw_frame":"{\"market\":\"0xda6f0e0e93fc8469e0159a166028d017bddbc162b86f66bac90391379603d962\", \"price_changes\":[{\"asset_id\":\"20893381255801015515826997628594359667013752732428989472914000440642900266717\", \"price\":\"0.01\", \"size\":\"5682.02\", \"side\":\"BUY\", \"hash\":\"679739d6a4058712831f13fc4adcb1197cc550fc\", \"best_bid\":\"0.64\", \"best_ask\":\"0.65\"}, {\"asset_id\":\"39272994714739463168905443499424551362424437245880253267329605556587274644733\", \"price\":\"0.99\", \"size\":\"5682.02\", \"side\":\"SELL\", \"hash\":\"756a6f58ef0a6e954e3aac79a8583e6f5619320f\", \"best_bid\":\"0.35\", \"best_ask\":\"0.36\"}], \"timestamp\":\"1785204576936\", \"event_type\":\"price_change\"}","received_at":"2026-07-28T02:09:36.823856Z","schema_version":"clob-market-ws.price_change.v1","sequence":null,"server_hash":null,"server_timestamp":"1785204576936","session_id":"d2757dd6dad94f3b9fe67e8dbf1adc37","source":"clob_market_ws"},"received_at":"2026-07-28T02:09:36.823856Z","record_id":"4f39aa3c0539de01de4fadd8e28268622792378e8aa2a6265a69b7d01254a262","schema_fingerprint":"4aa3821a28b0b7c2400bc59aba4bcc0a76e971dadd19610d3ad38c768e124dc7","schema_version":"edge-lab-recorder.raw.v1","sequence":null,"source":"clob_market_ws"}
{"event_at":"2026-07-28T02:09:36.956000Z","event_fingerprint":"b8e5094b2290d43c3d878e8e2c60dad1e9f65e3648a5ada7d4472688bbf6fda5","payload":{"connection_id":"5d29200f65794d4d9ab6ef271f045a9b","event_at":"2026-07-28T02:09:36.956000Z","event_type":"price_change","frame_hash":"cc2500d3cf6239d7935134cc0bbe1fdb67f75ee836d5b17327ba997abdd8afce","frame_index":0,"kind":"data","monotonic_ns":306559850858125,"payload":{"event_type":"price_change","market":"0xda6f0e0e93fc8469e0159a166028d017bddbc162b86f66bac90391379603d962","price_changes":[{"asset_id":"20893381255801015515826997628594359667013752732428989472914000440642900266717","best_ask":"0.65","best_bid":"0.64","hash":"49aff00186756525a12bbb96fb2ef8f5bbadde07","price":"0.01","side":"BUY","size":"5677.02"},{"asset_id":"39272994714739463168905443499424551362424437245880253267329605556587274644733","best_ask":"0.36","best_bid":"0.35","hash":"b2fa20ecde29a63fb8f669db5c22ac5c62a2ecba","price":"0.99","side":"SELL","size":"5677.02"}],"timestamp":"1785204576956"},"payload_hash":"7e39b9e0a37f76d1672e8b28a6cfb5db28fbd97a59766e326bbbe03530b27fcf","raw_frame":"{\"market\":\"0xda6f0e0e93fc8469e0159a166028d017bddbc162b86f66bac90391379603d962\", \"price_changes\":[{\"asset_id\":\"20893381255801015515826997628594359667013752732428989472914000440642900266717\", \"price\":\"0.01\", \"size\":\"5677.02\", \"side\":\"BUY\", \"hash\":\"49aff00186756525a12bbb96fb2ef8f5bbadde07\", \"best_bid\":\"0.64\", \"best_ask\":\"0.65\"}, {\"asset_id\":\"39272994714739463168905443499424551362424437245880253267329605556587274644733\", \"price\":\"0.99\", \"size\":\"5677.02\", \"side\":\"SELL\", \"hash\":\"b2fa20ecde29a63fb8f669db5c22ac5c62a2ecba\", \"best_bid\":\"0.35\", \"best_ask\":\"0.36\"}], \"timestamp\":\"1785204576956\", \"event_type\":\"price_change\"}","received_at":"2026-07-28T02:09:36.842086Z","schema_version":"clob-market-ws.price_change.v1","sequence":null,"server_hash":null,"server_timestamp":"1785204576956","session_id":"d2757dd6dad94f3b9fe67e8dbf1adc37","source":"clob_market_ws"},"received_at":"2026-07-28T02:09:36.842086Z","record_id":"66a04fd514b29d01c16f45bc8796f274112ac8b2e8f19c1abca2b7435b28a5a5","schema_fingerprint":"4aa3821a28b0b7c2400bc59aba4bcc0a76e971dadd19610d3ad38c768e124dc7","schema_version":"edge-lab-recorder.raw.v1","sequence":null,"source":"clob_market_ws"}
{"event_at":"2026-07-28T02:09:36.961000Z","event_fingerprint":"e3fea18c4e8758fcdc25dd05e04032ff15dd10a1c13baee06bded4923fce1c38","payload":{"connection_id":"5d29200f65794d4d9ab6ef271f045a9b","event_at":"2026-07-28T02:09:36.961000Z","event_type":"price_change","frame_hash":"2a7dc7efdcc8db4e55e17e3448420f9d81c593590844b3db8d36db41459b7b41","frame_index":0,"kind":"data","monotonic_ns":306559856496833,"payload":{"event_type":"price_change","market":"0xda6f0e0e93fc8469e0159a166028d017bddbc162b86f66bac90391379603d962","price_changes":[{"asset_id":"20893381255801015515826997628594359667013752732428989472914000440642900266717","best_ask":"0.65","best_bid":"0.64","hash":"e44b91bca4beeedf8dce00923f30149cfef4f925","price":"0.02","side":"BUY","size":"732.1"},{"asset_id":"39272994714739463168905443499424551362424437245880253267329605556587274644733","best_ask":"0.36","best_bid":"0.35","hash":"c94e27b84cf9e37fa90ab7102919af68fd743c94","price":"0.98","side":"SELL","size":"732.1"}],"timestamp":"1785204576961"},"payload_hash":"d9543862f910368cadcf6ecee3d65e3a10200db878d5b3dd1017d22766723312","raw_frame":"{\"market\":\"0xda6f0e0e93fc8469e0159a166028d017bddbc162b86f66bac90391379603d962\", \"price_changes\":[{\"asset_id\":\"20893381255801015515826997628594359667013752732428989472914000440642900266717\", \"price\":\"0.02\", \"size\":\"732.1\", \"side\":\"BUY\", \"hash\":\"e44b91bca4beeedf8dce00923f30149cfef4f925\", \"best_bid\":\"0.64\", \"best_ask\":\"0.65\"}, {\"asset_id\":\"39272994714739463168905443499424551362424437245880253267329605556587274644733\", \"price\":\"0.98\", \"size\":\"732.1\", \"side\":\"SELL\", \"hash\":\"c94e27b84cf9e37fa90ab7102919af68fd743c94\", \"best_bid\":\"0.35\", \"best_ask\":\"0.36\"}], \"timestamp\":\"1785204576961\", \"event_type\":\"price_change\"}","received_at":"2026-07-28T02:09:36.847730Z","schema_version":"clob-market-ws.price_change.v1","sequence":null,"server_hash":null,"server_timestamp":"1785204576961","session_id":"d2757dd6dad94f3b9fe67e8dbf1adc37","source":"clob_market_ws"},"received_at":"2026-07-28T02:09:36.847730Z","record_id":"35143a92ed6d1b1b29d92c0b109325aafa73a513fef0f459267845cbd6d6e10d","schema_fingerprint":"4aa3821a28b0b7c2400bc59aba4bcc0a76e971dadd19610d3ad38c768e124dc7","schema_version":"edge-lab-recorder.raw.v1","sequence":null,"source":"clob_market_ws"}
{"event_at":"2026-07-28T02:09:37.018000Z","event_fingerprint":"5343d6e3bf9b1900612d0825158bf7c3293483c2c02e91f0bc1e21e3395003a2","payload":{"connection_id":"5d29200f65794d4d9ab6ef271f045a9b","event_at":"2026-07-28T02:09:37.018000Z","event_type":"price_change","frame_hash":"f7739ecc99a86dbeb3ebc83f42d1ad4e1898785e6f0f0312279b45404d768753","frame_index":0,"kind":"data","monotonic_ns":306559912354500,"payload":{"event_type":"price_change","market":"0xda6f0e0e93fc8469e0159a166028d017bddbc162b86f66bac90391379603d962","price_changes":[{"asset_id":"39272994714739463168905443499424551362424437245880253267329605556587274644733","best_ask":"0.36","best_bid":"0.35","hash":"ccbb0f7ebb5d0ba3d7af83f1952f49ec36dd3382","price":"0.01","side":"BUY","size":"5603.02"},{"asset_id":"20893381255801015515826997628594359667013752732428989472914000440642900266717","best_ask":"0.65","best_bid":"0.64","hash":"70e6f1feb21583b6617c66a250e5e97d646b1bb0","price":"0.99","side":"SELL","size":"5603.02"}],"timestamp":"1785204577018"},"payload_hash":"bf54aef7043179e96505c7eb2fc00021900e29801b3e7df9879fa2f26da98721","raw_frame":"{\"market\":\"0xda6f0e0e93fc8469e0159a166028d017bddbc162b86f66bac90391379603d962\", \"price_changes\":[{\"asset_id\":\"39272994714739463168905443499424551362424437245880253267329605556587274644733\", \"price\":\"0.01\", \"size\":\"5603.02\", \"side\":\"BUY\", \"hash\":\"ccbb0f7ebb5d0ba3d7af83f1952f49ec36dd3382\", \"best_bid\":\"0.35\", \"best_ask\":\"0.36\"}, {\"asset_id\":\"20893381255801015515826997628594359667013752732428989472914000440642900266717\", \"price\":\"0.99\", \"size\":\"5603.02\", \"side\":\"SELL\", \"hash\":\"70e6f1feb21583b6617c66a250e5e97d646b1bb0\", \"best_bid\":\"0.64\", \"best_ask\":\"0.65\"}], \"timestamp\":\"1785204577018\", \"event_type\":\"price_change\"}","received_at":"2026-07-28T02:09:36.903581Z","schema_version":"clob-market-ws.price_change.v1","sequence":null,"server_hash":null,"server_timestamp":"1785204577018","session_id":"d2757dd6dad94f3b9fe67e8dbf1adc37","source":"clob_market_ws"},"received_at":"2026-07-28T02:09:36.903581Z","record_id":"d64a6acd7d2de4019ac00bde75e6a51b9a1da314a52532c9257b15bbd2d6ac65","schema_fingerprint":"4aa3821a28b0b7c2400bc59aba4bcc0a76e971dadd19610d3ad38c768e124dc7","schema_version":"edge-lab-recorder.raw.v1","sequence":null,"source":"clob_market_ws"}
{"event_at":"2026-07-28T02:09:37.023000Z","event_fingerprint":"84b74f8b36758f65d55739d53cbbc46775fecb38b1d061dcee5509d423868377","payload":{"connection_id":"5d29200f65794d4d9ab6ef271f045a9b","event_at":"2026-07-28T02:09:37.023000Z","event_type":"price_change","frame_hash":"d4543dd587f1f85465158e3a995c8764b0819870b8ff87ea12708271df1a3367","frame_index":0,"kind":"data","monotonic_ns":306559917469416,"payload":{"event_type":"price_change","market":"0xda6f0e0e93fc8469e0159a166028d017bddbc162b86f66bac90391379603d962","price_changes":[{"asset_id":"39272994714739463168905443499424551362424437245880253267329605556587274644733","best_ask":"0.36","best_bid":"0.35","hash":"d272b709522d2c584f090ec406338a97e23f7a8b","price":"0.01","side":"BUY","size":"5608.02"},{"asset_id":"20893381255801015515826997628594359667013752732428989472914000440642900266717","best_ask":"0.65","best_bid":"0.64","hash":"2d9d68758e21fc883bcb0c538dbe0a9bae0e8c7c","price":"0.99","side":"SELL","size":"5608.02"}],"timestamp":"1785204577023"},"payload_hash":"a158a49cde4fa80f7de1cb209b72d9bf2f27280200ef8bdc3b51f35cc4dd2899","raw_frame":"{\"market\":\"0xda6f0e0e93fc8469e0159a166028d017bddbc162b86f66bac90391379603d962\", \"price_changes\":[{\"asset_id\":\"39272994714739463168905443499424551362424437245880253267329605556587274644733\", \"price\":\"0.01\", \"size\":\"5608.02\", \"side\":\"BUY\", \"hash\":\"d272b709522d2c584f090ec406338a97e23f7a8b\", \"best_bid\":\"0.35\", \"best_ask\":\"0.36\"}, {\"asset_id\":\"20893381255801015515826997628594359667013752732428989472914000440642900266717\", \"price\":\"0.99\", \"size\":\"5608.02\", \"side\":\"SELL\", \"hash\":\"2d9d68758e21fc883bcb0c538dbe0a9bae0e8c7c\", \"best_bid\":\"0.64\", \"best_ask\":\"0.65\"}], \"timestamp\":\"1785204577023\", \"event_type\":\"price_change\"}","received_at":"2026-07-28T02:09:36.908702Z","schema_version":"clob-market-ws.price_change.v1","sequence":null,"server_hash":null,"server_timestamp":"1785204577023","session_id":"d2757dd6dad94f3b9fe67e8dbf1adc37","source":"clob_market_ws"},"received_at":"2026-07-28T02:09:36.908702Z","record_id":"a5d0c16100e31dece007a1ade1986b6170b82f97867f394a823254ae0d33f7b0","schema_fingerprint":"4aa3821a28b0b7c2400bc59aba4bcc0a76e971dadd19610d3ad38c768e124dc7","schema_version":"edge-lab-recorder.raw.v1","sequence":null,"source":"clob_market_ws"}
{"event_at":"2026-07-28T02:09:37.036000Z","event_fingerprint":"de062cf808887b754a7f4c31fb3c721c34c50df36f4f6a9aaf4f1d3672d34285","payload":{"connection_id":"5d29200f65794d4d9ab6ef271f045a9b","event_at":"2026-07-28T02:09:37.036000Z","event_type":"price_change","frame_hash":"675d885f1f064939882b2addd7b4c1885bd02b22f1fafcf0846343032cfab8c4","frame_index":0,"kind":"data","monotonic_ns":306559945804083,"payload":{"event_type":"price_change","market":"0xda6f0e0e93fc8469e0159a166028d017bddbc162b86f66bac90391379603d962","price_changes":[{"asset_id":"39272994714739463168905443499424551362424437245880253267329605556587274644733","best_ask":"0.36","best_bid":"0.35","hash":"c885bee62dd365ec61e5d0bf9585ebd6f0b11186","price":"0.26","side":"BUY","size":"274.01"},{"asset_id":"20893381255801015515826997628594359667013752732428989472914000440642900266717","best_ask":"0.65","best_bid":"0.64","hash":"dcd0521c08fcf5fde84e321e69740161e3a6abbb","price":"0.74","side":"SELL","size":"274.01"}],"timestamp":"1785204577036"},"payload_hash":"b97c75d9cd029c6f7724f0e305eb824eb3d9186cd0c4a45afb0f2626084f5b8d","raw_frame":"{\"market\":\"0xda6f0e0e93fc8469e0159a166028d017bddbc162b86f66bac90391379603d962\", \"price_changes\":[{\"asset_id\":\"39272994714739463168905443499424551362424437245880253267329605556587274644733\", \"price\":\"0.26\", \"size\":\"274.01\", \"side\":\"BUY\", \"hash\":\"c885bee62dd365ec61e5d0bf9585ebd6f0b11186\", \"best_bid\":\"0.35\", \"best_ask\":\"0.36\"}, {\"asset_id\":\"20893381255801015515826997628594359667013752732428989472914000440642900266717\", \"price\":\"0.74\", \"size\":\"274.01\", \"side\":\"SELL\", \"hash\":\"dcd0521c08fcf5fde84e321e69740161e3a6abbb\", \"best_bid\":\"0.64\", \"best_ask\":\"0.65\"}], \"timestamp\":\"1785204577036\", \"event_type\":\"price_change\"}","received_at":"2026-07-28T02:09:36.937041Z","schema_version":"clob-market-ws.price_change.v1","sequence":null,"server_hash":null,"server_timestamp":"1785204577036","session_id":"d2757dd6dad94f3b9fe67e8dbf1adc37","source":"clob_market_ws"},"received_at":"2026-07-28T02:09:36.937041Z","record_id":"ad470c0b37705c6505cf6bed8859806d00353658b106e6249d3547b77ad965b7","schema_fingerprint":"4aa3821a28b0b7c2400bc59aba4bcc0a76e971dadd19610d3ad38c768e124dc7","schema_version":"edge-lab-recorder.raw.v1","sequence":null,"source":"clob_market_ws"}
{"event_at":"2026-07-28T02:09:37.043000Z","event_fingerprint":"319e9b565f44321f3743df40b05e87c42def9a504661bb8d02f55b5933d151f2","payload":{"connection_id":"5d29200f65794d4d9ab6ef271f045a9b","event_at":"2026-07-28T02:09:37.043000Z","event_type":"price_change","frame_hash":"59d64bfad0f4bf40a420ae35915026b76283faf2b7264cf7923f1704b7d8a35a","frame_index":0,"kind":"data","monotonic_ns":306559946553125,"payload":{"event_type":"price_change","market":"0xda6f0e0e93fc8469e0159a166028d017bddbc162b86f66bac90391379603d962","price_changes":[{"asset_id":"20893381255801015515826997628594359667013752732428989472914000440642900266717","best_ask":"0.65","best_bid":"0.64","hash":"e0cebdf80e3320f4f717e6bf42aaf18e8dcc9c88","price":"0.02","side":"BUY","size":"727.1"},{"asset_id":"39272994714739463168905443499424551362424437245880253267329605556587274644733","best_ask":"0.36","best_bid":"0.35","hash":"506f985d6f6ac27faf874a57676821e817d9d4d6","price":"0.98","side":"SELL","size":"727.1"}],"timestamp":"1785204577043"},"payload_hash":"0a24c8eb12342ef4f473c2f9846c9646f1c0680029cf992d66a1b2a38d300b6e","raw_frame":"{\"market\":\"0xda6f0e0e93fc8469e0159a166028d017bddbc162b86f66bac90391379603d962\", \"price_changes\":[{\"asset_id\":\"20893381255801015515826997628594359667013752732428989472914000440642900266717\", \"price\":\"0.02\", \"size\":\"727.1\", \"side\":\"BUY\", \"hash\":\"e0cebdf80e3320f4f717e6bf42aaf18e8dcc9c88\", \"best_bid\":\"0.64\", \"best_ask\":\"0.65\"}, {\"asset_id\":\"39272994714739463168905443499424551362424437245880253267329605556587274644733\", \"price\":\"0.98\", \"size\":\"727.1\", \"side\":\"SELL\", \"hash\":\"506f985d6f6ac27faf874a57676821e817d9d4d6\", \"best_bid\":\"0.35\", \"best_ask\":\"0.36\"}], \"timestamp\":\"1785204577043\", \"event_type\":\"price_change\"}","received_at":"2026-07-28T02:09:36.937786Z","schema_version":"clob-market-ws.price_change.v1","sequence":null,"server_hash":null,"server_timestamp":"1785204577043","session_id":"d2757dd6dad94f3b9fe67e8dbf1adc37","source":"clob_market_ws"},"received_at":"2026-07-28T02:09:36.937786Z","record_id":"5c51e9e1b1c1e9fc38b646117d8b518de36d0e18d63a6b5aa1f2e2e72e7b650f","schema_fingerprint":"4aa3821a28b0b7c2400bc59aba4bcc0a76e971dadd19610d3ad38c768e124dc7","schema_version":"edge-lab-recorder.raw.v1","sequence":null,"source":"clob_market_ws"}
{"event_at":"2026-07-28T02:09:37.049000Z","event_fingerprint":"165a9d4ab49121ef1108f7d10e778ed1280de2f7b192e1319de0b0f731603b6d","payload":{"connection_id":"5d29200f65794d4d9ab6ef271f045a9b","event_at":"2026-07-28T02:09:37.049000Z","event_type":"price_change","frame_hash":"a3aa5e4c59bb72a43877fcacf444045c6a70f011a1b92e002d3935748d0db52d","frame_index":0,"kind":"data","monotonic_ns":306559948141791,"payload":{"event_type":"price_change","market":"0xda6f0e0e93fc8469e0159a166028d017bddbc162b86f66bac90391379603d962","price_changes":[{"asset_id":"39272994714739463168905443499424551362424437245880253267329605556587274644733","best_ask":"0.36","best_bid":"0.35","hash":"2b4c3c986aa4f94adfd1015a6dc0074386276e6a","price":"0.01","side":"BUY","size":"5603.02"},{"asset_id":"20893381255801015515826997628594359667013752732428989472914000440642900266717","best_ask":"0.65","best_bid":"0.64","hash":"e2ddaf43e52cb23b95de702576d650240c6bbedf","price":"0.99","side":"SELL","size":"5603.02"}],"timestamp":"1785204577049"},"payload_hash":"2959ec77e3cd8d501e8ad3121d8148a7b1cb42c90a65b87806e0336ceed2cbfc","raw_frame":"{\"market\":\"0xda6f0e0e93fc8469e0159a166028d017bddbc162b86f66bac90391379603d962\", \"price_changes\":[{\"asset_id\":\"39272994714739463168905443499424551362424437245880253267329605556587274644733\", \"price\":\"0.01\", \"size\":\"5603.02\", \"side\":\"BUY\", \"hash\":\"2b4c3c986aa4f94adfd1015a6dc0074386276e6a\", \"best_bid\":\"0.35\", \"best_ask\":\"0.36\"}, {\"asset_id\":\"20893381255801015515826997628594359667013752732428989472914000440642900266717\", \"price\":\"0.99\", \"size\":\"5603.02\", \"side\":\"SELL\", \"hash\":\"e2ddaf43e52cb23b95de702576d650240c6bbedf\", \"best_bid\":\"0.64\", \"best_ask\":\"0.65\"}], \"timestamp\":\"1785204577049\", \"event_type\":\"price_change\"}","received_at":"2026-07-28T02:09:36.939381Z","schema_version":"clob-market-ws.price_change.v1","sequence":null,"server_hash":null,"server_timestamp":"1785204577049","session_id":"d2757dd6dad94f3b9fe67e8dbf1adc37","source":"clob_market_ws"},"received_at":"2026-07-28T02:09:36.939381Z","record_id":"709b735a078d795cba1d66b32d71e102c4ff9ca5a8510022d1c149d4b4738fbb","schema_fingerprint":"4aa3821a28b0b7c2400bc59aba4bcc0a76e971dadd19610d3ad38c768e124dc7","schema_version":"edge-lab-recorder.raw.v1","sequence":null,"source":"clob_market_ws"}
{"event_at":"2026-07-28T02:09:37.069000Z","event_fingerprint":"65efdf8942151eef5b339215c8c193f075d6fc640ef328afc9d501cced733c53","payload":{"connection_id":"5d29200f65794d4d9ab6ef271f045a9b","event_at":"2026-07-28T02:09:37.069000Z","event_type":"price_change","frame_hash":"a73380fe1e2a4e07b00f843fd27f08c9789d052d404a9d57ebac2eebe07c4a2e","frame_index":0,"kind":"data","monotonic_ns":306559965289250,"payload":{"event_type":"price_change","market":"0xda6f0e0e93fc8469e0159a166028d017bddbc162b86f66bac90391379603d962","price_changes":[{"asset_id":"39272994714739463168905443499424551362424437245880253267329605556587274644733","best_ask":"0.36","best_bid":"0.35","hash":"752d2b29c8bc2a69a9983c432795fe39b45f8b8f","price":"0.25","side":"BUY","size":"385"},{"asset_id":"20893381255801015515826997628594359667013752732428989472914000440642900266717","best_ask":"0.65","best_bid":"0.64","hash":"ee5d657a11804dd2a636250d3979c740eff76158","price":"0.75","side":"SELL","size":"385"}],"timestamp":"1785204577069"},"payload_hash":"a414f5a358b0ca33e1f31a7c78e1003f9f4f60faf88ee0c66cfb1e9d789ba7bd","raw_frame":"{\"market\":\"0xda6f0e0e93fc8469e0159a166028d017bddbc162b86f66bac90391379603d962\", \"price_changes\":[{\"asset_id\":\"39272994714739463168905443499424551362424437245880253267329605556587274644733\", \"price\":\"0.25\", \"size\":\"385\", \"side\":\"BUY\", \"hash\":\"752d2b29c8bc2a69a9983c432795fe39b45f8b8f\", \"best_bid\":\"0.35\", \"best_ask\":\"0.36\"}, {\"asset_id\":\"20893381255801015515826997628594359667013752732428989472914000440642900266717\", \"price\":\"0.75\", \"size\":\"385\", \"side\":\"SELL\", \"hash\":\"ee5d657a11804dd2a636250d3979c740eff76158\", \"best_bid\":\"0.64\", \"best_ask\":\"0.65\"}], \"timestamp\":\"1785204577069\", \"event_type\":\"price_change\"}","received_at":"2026-07-28T02:09:36.956525Z","schema_version":"clob-market-ws.price_change.v1","sequence":null,"server_hash":null,"server_timestamp":"1785204577069","session_id":"d2757dd6dad94f3b9fe67e8dbf1adc37","source":"clob_market_ws"},"received_at":"2026-07-28T02:09:36.956525Z","record_id":"d0b71959f932ac52c4d8386170dbbc87c9a15373ef2be7d6c44a8d3fa01d7e15","schema_fingerprint":"4aa3821a28b0b7c2400bc59aba4bcc0a76e971dadd19610d3ad38c768e124dc7","schema_version":"edge-lab-recorder.raw.v1","sequence":null,"source":"clob_market_ws"}
{"event_at":"2026-07-28T02:09:37.080000Z","event_fingerprint":"6bea708fd254b0e0e0631ac7e5a31fb13bdd34474500a725a3e67aff27331550","payload":{"connection_id":"5d29200f65794d4d9ab6ef271f045a9b","event_at":"2026-07-28T02:09:37.080000Z","event_type":"price_change","frame_hash":"3e923c0257edd59364b6e15aed54474cb2582cc77975ba388759cf3225c9aaba","frame_index":0,"kind":"data","monotonic_ns":306559982536791,"payload":{"event_type":"price_change","market":"0xda6f0e0e93fc8469e0159a166028d017bddbc162b86f66bac90391379603d962","price_changes":[{"asset_id":"39272994714739463168905443499424551362424437245880253267329605556587274644733","best_ask":"0.36","best_bid":"0.35","hash":"241259674f403037ccfb5124f62e3918097a7f62","price":"0.01","side":"BUY","size":"5598.02"},{"asset_id":"20893381255801015515826997628594359667013752732428989472914000440642900266717","best_ask":"0.65","best_bid":"0.64","hash":"08e8be02001d8ab4f99a133adb028ba83a48c8f0","price":"0.99","side":"SELL","size":"5598.02"}],"timestamp":"1785204577080"},"payload_hash":"389fc95bb29585897ca0e791c3198b5734ca07f6467cf726a8363ef866f710c7","raw_frame":"{\"market\":\"0xda6f0e0e93fc8469e0159a166028d017bddbc162b86f66bac90391379603d962\", \"price_changes\":[{\"asset_id\":\"39272994714739463168905443499424551362424437245880253267329605556587274644733\", \"price\":\"0.01\", \"size\":\"5598.02\", \"side\":\"BUY\", \"hash\":\"241259674f403037ccfb5124f62e3918097a7f62\", \"best_bid\":\"0.35\", \"best_ask\":\"0.36\"}, {\"asset_id\":\"20893381255801015515826997628594359667013752732428989472914000440642900266717\", \"price\":\"0.99\", \"size\":\"5598.02\", \"side\":\"SELL\", \"hash\":\"08e8be02001d8ab4f99a133adb028ba83a48c8f0\", \"best_bid\":\"0.64\", \"best_ask\":\"0.65\"}], \"timestamp\":\"1785204577080\", \"event_type\":\"price_change\"}","received_at":"2026-07-28T02:09:36.973768Z","schema_version":"clob-market-ws.price_change.v1","sequence":null,"server_hash":null,"server_timestamp":"1785204577080","session_id":"d2757dd6dad94f3b9fe67e8dbf1adc37","source":"clob_market_ws"},"received_at":"2026-07-28T02:09:36.973768Z","record_id":"1bfcae058eb2935617da45d04bad0c7abf9dee2ca4421d6a0a820704568a93a7","schema_fingerprint":"4aa3821a28b0b7c2400bc59aba4bcc0a76e971dadd19610d3ad38c768e124dc7","schema_version":"edge-lab-recorder.raw.v1","sequence":null,"source":"clob_market_ws"}
{"event_at":"2026-07-28T02:09:37.120000Z","event_fingerprint":"fcb631de5cbabf51e3989943cf89e26f2c3d4ea765d1f78e9b1da17edbb2805c","payload":{"connection_id":"5d29200f65794d4d9ab6ef271f045a9b","event_at":"2026-07-28T02:09:37.120000Z","event_type":"price_change","frame_hash":"10483664a8636a4544408a9d100211d8ef44f72579901cd6eca3c25c9b5fa66d","frame_index":0,"kind":"data","monotonic_ns":306560017463916,"payload":{"event_type":"price_change","market":"0xda6f0e0e93fc8469e0159a166028d017bddbc162b86f66bac90391379603d962","price_changes":[{"asset_id":"39272994714739463168905443499424551362424437245880253267329605556587274644733","best_ask":"0.36","best_bid":"0.35","hash":"b37a38f77d42f8af58cc8d5933f3dec54000a7a4","price":"0.31","side":"BUY","size":"10"},{"asset_id":"20893381255801015515826997628594359667013752732428989472914000440642900266717","best_ask":"0.65","best_bid":"0.64","hash":"668869d3faf134706fd2c64efa202def57cfc4a4","price":"0.69","side":"SELL","size":"10"}],"timestamp":"1785204577120"},"payload_hash":"ad73d6191ae42cb706019ef024b9ac81ead541dc43c4318cf39ca2248c177124","raw_frame":"{\"market\":\"0xda6f0e0e93fc8469e0159a166028d017bddbc162b86f66bac90391379603d962\", \"price_changes\":[{\"asset_id\":\"39272994714739463168905443499424551362424437245880253267329605556587274644733\", \"price\":\"0.31\", \"size\":\"10\", \"side\":\"BUY\", \"hash\":\"b37a38f77d42f8af58cc8d5933f3dec54000a7a4\", \"best_bid\":\"0.35\", \"best_ask\":\"0.36\"}, {\"asset_id\":\"20893381255801015515826997628594359667013752732428989472914000440642900266717\", \"price\":\"0.69\", \"size\":\"10\", \"side\":\"SELL\", \"hash\":\"668869d3faf134706fd2c64efa202def57cfc4a4\", \"best_bid\":\"0.64\", \"best_ask\":\"0.65\"}], \"timestamp\":\"1785204577120\", \"event_type\":\"price_change\"}","received_at":"2026-07-28T02:09:37.008694Z","schema_version":"clob-market-ws.price_change.v1","sequence":null,"server_hash":null,"server_timestamp":"1785204577120","session_id":"d2757dd6dad94f3b9fe67e8dbf1adc37","source":"clob_market_ws"},"received_at":"2026-07-28T02:09:37.008694Z","record_id":"33e80de2b400e3ff7b7d783311def021bba859fb995129270f62ccf817156640","schema_fingerprint":"4aa3821a28b0b7c2400bc59aba4bcc0a76e971dadd19610d3ad38c768e124dc7","schema_version":"edge-lab-recorder.raw.v1","sequence":null,"source":"clob_market_ws"}
{"event_at":"2026-07-28T02:09:37.143000Z","event_fingerprint":"b587016b43c50fb7cc97e544370796ccddcfaf3982621c1de5b2a17ba1db1d05","payload":{"connection_id":"5d29200f65794d4d9ab6ef271f045a9b","event_at":"2026-07-28T02:09:37.143000Z","event_type":"price_change","frame_hash":"98f41c68889e993e0e0f65e1033b00d22463cebbcfbeb7328a41f2461ff8b56b","frame_index":0,"kind":"data","monotonic_ns":306560037957333,"payload":{"event_type":"price_change","market":"0xda6f0e0e93fc8469e0159a166028d017bddbc162b86f66bac90391379603d962","price_changes":[{"asset_id":"39272994714739463168905443499424551362424437245880253267329605556587274644733","best_ask":"0.36","best_bid":"0.35","hash":"d4d81446214d6b077a8679a366eed3c61a5ea478","price":"0.32","side":"BUY","size":"46.6"},{"asset_id":"20893381255801015515826997628594359667013752732428989472914000440642900266717","best_ask":"0.65","best_bid":"0.64","hash":"61a0a4afdc30c940c54ae2faa0e4a816e65414ae","price":"0.68","side":"SELL","size":"46.6"}],"timestamp":"1785204577143"},"payload_hash":"270c22a1a1c1a5afe0c761e83a378017005b510398c4d0f85c438823ef04799d","raw_frame":"{\"market\":\"0xda6f0e0e93fc8469e0159a166028d017bddbc162b86f66bac90391379603d962\", \"price_changes\":[{\"asset_id\":\"39272994714739463168905443499424551362424437245880253267329605556587274644733\", \"price\":\"0.32\", \"size\":\"46.6\", \"side\":\"BUY\", \"hash\":\"d4d81446214d6b077a8679a366eed3c61a5ea478\", \"best_bid\":\"0.35\", \"best_ask\":\"0.36\"}, {\"asset_id\":\"20893381255801015515826997628594359667013752732428989472914000440642900266717\", \"price\":\"0.68\", \"size\":\"46.6\", \"side\":\"SELL\", \"hash\":\"61a0a4afdc30c940c54ae2faa0e4a816e65414ae\", \"best_bid\":\"0.64\", \"best_ask\":\"0.65\"}], \"timestamp\":\"1785204577143\", \"event_type\":\"price_change\"}","received_at":"2026-07-28T02:09:37.029187Z","schema_version":"clob-market-ws.price_change.v1","sequence":null,"server_hash":null,"server_timestamp":"1785204577143","session_id":"d2757dd6dad94f3b9fe67e8dbf1adc37","source":"clob_market_ws"},"received_at":"2026-07-28T02:09:37.029187Z","record_id":"fc4a36654afb91a6a4c5de40339c42d1f8e986a61f0cd4bf40be417359c3bcf1","schema_fingerprint":"4aa3821a28b0b7c2400bc59aba4bcc0a76e971dadd19610d3ad38c768e124dc7","schema_version":"edge-lab-recorder.raw.v1","sequence":null,"source":"clob_market_ws"}
{"event_at":"2026-07-28T02:09:37.144000Z","event_fingerprint":"290a8f1a773cfb20bd1dc04eb6d3622853162e5d443200f090bb7bd81e0c86c6","payload":{"connection_id":"5d29200f65794d4d9ab6ef271f045a9b","event_at":"2026-07-28T02:09:37.144000Z","event_type":"price_change","frame_hash":"9fbfab6affcdc39dc9ffefbe562120e30c2f920c72f24b3f944a3b71e6117427","frame_index":0,"kind":"data","monotonic_ns":306560039528208,"payload":{"event_type":"price_change","market":"0xda6f0e0e93fc8469e0159a166028d017bddbc162b86f66bac90391379603d962","price_changes":[{"asset_id":"20893381255801015515826997628594359667013752732428989472914000440642900266717","best_ask":"0.65","best_bid":"0.64","hash":"4ea59328401a44d87421485e1ee69053707cef60","price":"0.04","side":"BUY","size":"667.09"},{"asset_id":"39272994714739463168905443499424551362424437245880253267329605556587274644733","best_ask":"0.36","best_bid":"0.35","hash":"1e73ae7787358e297d9e69b948b3d8bdb169dc6c","price":"0.96","side":"SELL","size":"667.09"}],"timestamp":"1785204577144"},"payload_hash":"10b73b387eca5171bef72fb25dcc0b8f674fc7fc81531f3a6b563580814ecfe9","raw_frame":"{\"market\":\"0xda6f0e0e93fc8469e0159a166028d017bddbc162b86f66bac90391379603d962\", \"price_changes\":[{\"asset_id\":\"20893381255801015515826997628594359667013752732428989472914000440642900266717\", \"price\":\"0.04\", \"size\":\"667.09\", \"side\":\"BUY\", \"hash\":\"4ea59328401a44d87421485e1ee69053707cef60\", \"best_bid\":\"0.64\", \"best_ask\":\"0.65\"}, {\"asset_id\":\"39272994714739463168905443499424551362424437245880253267329605556587274644733\", \"price\":\"0.96\", \"size\":\"667.09\", \"side\":\"SELL\", \"hash\":\"1e73ae7787358e297d9e69b948b3d8bdb169dc6c\", \"best_bid\":\"0.35\", \"best_ask\":\"0.36\"}], \"timestamp\":\"1785204577144\", \"event_type\":\"price_change\"}","received_at":"2026-07-28T02:09:37.030757Z","schema_version":"clob-market-ws.price_change.v1","sequence":null,"server_hash":null,"server_timestamp":"1785204577144","session_id":"d2757dd6dad94f3b9fe67e8dbf1adc37","source":"clob_market_ws"},"received_at":"2026-07-28T02:09:37.030757Z","record_id":"5f72917aff74e18aa0ac8aa543b045887eecdcb656a0eaabfa32644c71266d7a","schema_fingerprint":"4aa3821a28b0b7c2400bc59aba4bcc0a76e971dadd19610d3ad38c768e124dc7","schema_version":"edge-lab-recorder.raw.v1","sequence":null,"source":"clob_market_ws"}
{"event_at":"2026-07-28T02:09:37.221000Z","event_fingerprint":"ddbc06a75fbe754591d46398a03f28fd72bf7d3ddbeca7bbcc030cdefe256832","payload":{"connection_id":"5d29200f65794d4d9ab6ef271f045a9b","event_at":"2026-07-28T02:09:37.221000Z","event_type":"price_change","frame_hash":"21183ff05449267e7758e41551771181bcd7553ad6a64a3c8d04be2922ac8d9a","frame_index":0,"kind":"data","monotonic_ns":306560117372583,"payload":{"event_type":"price_change","market":"0xda6f0e0e93fc8469e0159a166028d017bddbc162b86f66bac90391379603d962","price_changes":[{"asset_id":"39272994714739463168905443499424551362424437245880253267329605556587274644733","best_ask":"0.36","best_bid":"0.35","hash":"dc11cc84f60e6d1ed96f1de2e84395516795366b","price":"0.32","side":"BUY","size":"21.6"},{"asset_id":"20893381255801015515826997628594359667013752732428989472914000440642900266717","best_ask":"0.65","best_bid":"0.64","hash":"b6642e0b4c611a357f8e10022fe7b6309b1cf53e","price":"0.68","side":"SELL","size":"21.6"}],"timestamp":"1785204577221"},"payload_hash":"872de1d8c9f462860df841c4b40dc48a60b575541677c8d021ad72013951c51d","raw_frame":"{\"market\":\"0xda6f0e0e93fc8469e0159a166028d017bddbc162b86f66bac90391379603d962\", \"price_changes\":[{\"asset_id\":\"39272994714739463168905443499424551362424437245880253267329605556587274644733\", \"price\":\"0.32\", \"size\":\"21.6\", \"side\":\"BUY\", \"hash\":\"dc11cc84f60e6d1ed96f1de2e84395516795366b\", \"best_bid\":\"0.35\", \"best_ask\":\"0.36\"}, {\"asset_id\":\"20893381255801015515826997628594359667013752732428989472914000440642900266717\", \"price\":\"0.68\", \"size\":\"21.6\", \"side\":\"SELL\", \"hash\":\"b6642e0b4c611a357f8e10022fe7b6309b1cf53e\", \"best_bid\":\"0.64\", \"best_ask\":\"0.65\"}], \"timestamp\":\"1785204577221\", \"event_type\":\"price_change\"}","received_at":"2026-07-28T02:09:37.108601Z","schema_version":"clob-market-ws.price_change.v1","sequence":null,"server_hash":null,"server_timestamp":"1785204577221","session_id":"d2757dd6dad94f3b9fe67e8dbf1adc37","source":"clob_market_ws"},"received_at":"2026-07-28T02:09:37.108601Z","record_id":"50039fd1495d60bd63568838b32e9c65d3e19c8dccbf353095bc5751594dc934","schema_fingerprint":"4aa3821a28b0b7c2400bc59aba4bcc0a76e971dadd19610d3ad38c768e124dc7","schema_version":"edge-lab-recorder.raw.v1","sequence":null,"source":"clob_market_ws"}
{"event_at":"2026-07-28T02:09:37.246000Z","event_fingerprint":"4b84e49d97a95778f8e973fe4c8f3d3a979f306e00423466613d3bf63cb20928","payload":{"connection_id":"5d29200f65794d4d9ab6ef271f045a9b","event_at":"2026-07-28T02:09:37.246000Z","event_type":"price_change","frame_hash":"325f132a046d6ca37348be35038a247b73064a14bcc270e8e1487bc91c644a8b","frame_index":0,"kind":"data","monotonic_ns":306560151856041,"payload":{"event_type":"price_change","market":"0xda6f0e0e93fc8469e0159a166028d017bddbc162b86f66bac90391379603d962","price_changes":[{"asset_id":"20893381255801015515826997628594359667013752732428989472914000440642900266717","best_ask":"0.65","best_bid":"0.64","hash":"48741a66b981dff71aee8e2535c41a77e73a87f5","price":"0.04","side":"BUY","size":"662.09"},{"asset_id":"39272994714739463168905443499424551362424437245880253267329605556587274644733","best_ask":"0.36","best_bid":"0.35","hash":"32f8b7920560a194b09dbac446f4c75cc7adc3df","price":"0.96","side":"SELL","size":"662.09"}],"timestamp":"1785204577246"},"payload_hash":"f2897f79eb26f21f19f38538ae786ed5439ad8a24b8259ba30b81c2c24c9352b","raw_frame":"{\"market\":\"0xda6f0e0e93fc8469e0159a166028d017bddbc162b86f66bac90391379603d962\", \"price_changes\":[{\"asset_id\":\"20893381255801015515826997628594359667013752732428989472914000440642900266717\", \"price\":\"0.04\", \"size\":\"662.09\", \"side\":\"BUY\", \"hash\":\"48741a66b981dff71aee8e2535c41a77e73a87f5\", \"best_bid\":\"0.64\", \"best_ask\":\"0.65\"}, {\"asset_id\":\"39272994714739463168905443499424551362424437245880253267329605556587274644733\", \"price\":\"0.96\", \"size\":\"662.09\", \"side\":\"SELL\", \"hash\":\"32f8b7920560a194b09dbac446f4c75cc7adc3df\", \"best_bid\":\"0.35\", \"best_ask\":\"0.36\"}], \"timestamp\":\"1785204577246\", \"event_type\":\"price_change\"}","received_at":"2026-07-28T02:09:37.143082Z","schema_version":"clob-market-ws.price_change.v1","sequence":null,"server_hash":null,"server_timestamp":"1785204577246","session_id":"d2757dd6dad94f3b9fe67e8dbf1adc37","source":"clob_market_ws"},"received_at":"2026-07-28T02:09:37.143082Z","record_id":"fccdb2fb37f3231f9412e88d8709fb548929801532be9ae479d759e3a3424766","schema_fingerprint":"4aa3821a28b0b7c2400bc59aba4bcc0a76e971dadd19610d3ad38c768e124dc7","schema_version":"edge-lab-recorder.raw.v1","sequence":null,"source":"clob_market_ws"}
{"event_at":"2026-07-28T02:09:37.307000Z","event_fingerprint":"22f2d4e07737be603119fec5314d480d85d1cb171101f49674a393a052ea6dc9","payload":{"connection_id":"5d29200f65794d4d9ab6ef271f045a9b","event_at":"2026-07-28T02:09:37.307000Z","event_type":"price_change","frame_hash":"4e945b7fc932186d4c5f52b2f94f02b37b2bf1e62ab06e5074ef1fc731560b2f","frame_index":0,"kind":"data","monotonic_ns":306560201827583,"payload":{"event_type":"price_change","market":"0xda6f0e0e93fc8469e0159a166028d017bddbc162b86f66bac90391379603d962","price_changes":[{"asset_id":"39272994714739463168905443499424551362424437245880253267329605556587274644733","best_ask":"0.36","best_bid":"0.35","hash":"4431707b8b67021fea7d7cd12c6294b5384387a1","price":"0.27","side":"BUY","size":"339.8"},{"asset_id":"20893381255801015515826997628594359667013752732428989472914000440642900266717","best_ask":"0.65","best_bid":"0.64","hash":"2301668a82eafb34b61891ee8a9f3de9ef834b6d","price":"0.73","side":"SELL","size":"339.8"}],"timestamp":"1785204577307"},"payload_hash":"e66f0401c4997cd02e09d14c07b94f57fa89fd206bed6d82b10a3bd0df353798","raw_frame":"{\"market\":\"0xda6f0e0e93fc8469e0159a166028d017bddbc162b86f66bac90391379603d962\", \"price_changes\":[{\"asset_id\":\"39272994714739463168905443499424551362424437245880253267329605556587274644733\", \"price\":\"0.27\", \"size\":\"339.8\", \"side\":\"BUY\", \"hash\":\"4431707b8b67021fea7d7cd12c6294b5384387a1\", \"best_bid\":\"0.35\", \"best_ask\":\"0.36\"}, {\"asset_id\":\"20893381255801015515826997628594359667013752732428989472914000440642900266717\", \"price\":\"0.73\", \"size\":\"339.8\", \"side\":\"SELL\", \"hash\":\"2301668a82eafb34b61891ee8a9f3de9ef834b6d\", \"best_bid\":\"0.64\", \"best_ask\":\"0.65\"}], \"timestamp\":\"1785204577307\", \"event_type\":\"price_change\"}","received_at":"2026-07-28T02:09:37.193055Z","schema_version":"clob-market-ws.price_change.v1","sequence":null,"server_hash":null,"server_timestamp":"1785204577307","session_id":"d2757dd6dad94f3b9fe67e8dbf1adc37","source":"clob_market_ws"},"received_at":"2026-07-28T02:09:37.193055Z","record_id":"ae8e321c0f7669c1a72d89e33654f9b59ca27712e649243f4f805531edaf45b0","schema_fingerprint":"4aa3821a28b0b7c2400bc59aba4bcc0a76e971dadd19610d3ad38c768e124dc7","schema_version":"edge-lab-recorder.raw.v1","sequence":null,"source":"clob_market_ws"}
{"event_at":"2026-07-28T02:09:37.312000Z","event_fingerprint":"25463b0986c8b21005df7063e6a90b906eb2dadda9e660a87859bd15a1f6e721","payload":{"connection_id":"5d29200f65794d4d9ab6ef271f045a9b","event_at":"2026-07-28T02:09:37.312000Z","event_type":"price_change","frame_hash":"15800f1e1d6f3c23f853ff826c52186ede3c5a0c9edd38b04e0a7496dd4d644a","frame_index":0,"kind":"data","monotonic_ns":306560217251416,"payload":{"event_type":"price_change","market":"0xda6f0e0e93fc8469e0159a166028d017bddbc162b86f66bac90391379603d962","price_changes":[{"asset_id":"20893381255801015515826997628594359667013752732428989472914000440642900266717","best_ask":"0.65","best_bid":"0.64","hash":"2b2e1eaace0e23ef29582bc5bfe6fe6f481cedaa","price":"0.01","side":"BUY","size":"5682.02"},{"asset_id":"39272994714739463168905443499424551362424437245880253267329605556587274644733","best_ask":"0.36","best_bid":"0.35","hash":"7838c36394d19eb9ad2a9c47ec836b929cc13733","price":"0.99","side":"SELL","size":"5682.02"}],"timestamp":"1785204577312"},"payload_hash":"1827770ce40ea1aa918a8a0744be86256b5a18e2395beeb505d0e7061e5be97f","raw_frame":"{\"market\":\"0xda6f0e0e93fc8469e0159a166028d017bddbc162b86f66bac90391379603d962\", \"price_changes\":[{\"asset_id\":\"20893381255801015515826997628594359667013752732428989472914000440642900266717\", \"price\":\"0.01\", \"size\":\"5682.02\", \"side\":\"BUY\", \"hash\":\"2b2e1eaace0e23ef29582bc5bfe6fe6f481cedaa\", \"best_bid\":\"0.64\", \"best_ask\":\"0.65\"}, {\"asset_id\":\"39272994714739463168905443499424551362424437245880253267329605556587274644733\", \"price\":\"0.99\", \"size\":\"5682.02\", \"side\":\"SELL\", \"hash\":\"7838c36394d19eb9ad2a9c47ec836b929cc13733\", \"best_bid\":\"0.35\", \"best_ask\":\"0.36\"}], \"timestamp\":\"1785204577312\", \"event_type\":\"price_change\"}","received_at":"2026-07-28T02:09:37.208481Z","schema_version":"clob-market-ws.price_change.v1","sequence":null,"server_hash":null,"server_timestamp":"1785204577312","session_id":"d2757dd6dad94f3b9fe67e8dbf1adc37","source":"clob_market_ws"},"received_at":"2026-07-28T02:09:37.208481Z","record_id":"7024be1cfb390b173ba2641afb51a098e4c98ff9c3d97c7c5041fef29516f38f","schema_fingerprint":"4aa3821a28b0b7c2400bc59aba4bcc0a76e971dadd19610d3ad38c768e124dc7","schema_version":"edge-lab-recorder.raw.v1","sequence":null,"source":"clob_market_ws"}
{"event_at":"2026-07-28T02:09:37.326000Z","event_fingerprint":"d52983e8bccfb1482789e4e310bdb0a317543657bdfb227c40c6e7a54d2eed54","payload":{"connection_id":"5d29200f65794d4d9ab6ef271f045a9b","event_at":"2026-07-28T02:09:37.326000Z","event_type":"price_change","frame_hash":"d11167198090f8ce2ad5ccb9f0f6d1f14985199888071f6ef21f8b37ae5dda0f","frame_index":0,"kind":"data","monotonic_ns":306560220172500,"payload":{"event_type":"price_change","market":"0xda6f0e0e93fc8469e0159a166028d017bddbc162b86f66bac90391379603d962","price_changes":[{"asset_id":"39272994714739463168905443499424551362424437245880253267329605556587274644733","best_ask":"0.36","best_bid":"0.35","hash":"69c4c99e5565680ed49b5113b71e2c9e8640b36f","price":"0.31","side":"BUY","size":"35"},{"asset_id":"20893381255801015515826997628594359667013752732428989472914000440642900266717","best_ask":"0.65","best_bid":"0.64","hash":"ad0a87fdb993b4efeb5d84b59b285b0bf8344299","price":"0.69","side":"SELL","size":"35"}],"timestamp":"1785204577326"},"payload_hash":"66341546f62f8c92d2efb4f63ae78cd1b7bfd0c3e35b034d7f1dae7f533df796","raw_frame":"{\"market\":\"0xda6f0e0e93fc8469e0159a166028d017bddbc162b86f66bac90391379603d962\", \"price_changes\":[{\"asset_id\":\"39272994714739463168905443499424551362424437245880253267329605556587274644733\", \"price\":\"0.31\", \"size\":\"35\", \"side\":\"BUY\", \"hash\":\"69c4c99e5565680ed49b5113b71e2c9e8640b36f\", \"best_bid\":\"0.35\", \"best_ask\":\"0.36\"}, {\"asset_id\":\"20893381255801015515826997628594359667013752732428989472914000440642900266717\", \"price\":\"0.69\", \"size\":\"35\", \"side\":\"SELL\", \"hash\":\"ad0a87fdb993b4efeb5d84b59b285b0bf8344299\", \"best_bid\":\"0.64\", \"best_ask\":\"0.65\"}], \"timestamp\":\"1785204577326\", \"event_type\":\"price_change\"}","received_at":"2026-07-28T02:09:37.211403Z","schema_version":"clob-market-ws.price_change.v1","sequence":null,"server_hash":null,"server_timestamp":"1785204577326","session_id":"d2757dd6dad94f3b9fe67e8dbf1adc37","source":"clob_market_ws"},"received_at":"2026-07-28T02:09:37.211403Z","record_id":"b0856504602f4c9db9c1c58168da000eaca2543f8889711b2fe940e6379d9248","schema_fingerprint":"4aa3821a28b0b7c2400bc59aba4bcc0a76e971dadd19610d3ad38c768e124dc7","schema_version":"edge-lab-recorder.raw.v1","sequence":null,"source":"clob_market_ws"}
{"event_at":"2026-07-28T02:09:37.330000Z","event_fingerprint":"c9e47b08b2e693e9ee334665f20b747640a73dc6ed917e8a9d9ff91137e93371","payload":{"connection_id":"5d29200f65794d4d9ab6ef271f045a9b","event_at":"2026-07-28T02:09:37.330000Z","event_type":"price_change","frame_hash":"31f37314a6ab7ac6a52ae6d150c547fa8b1c9054a3268cb69517633dc7e4eb8a","frame_index":0,"kind":"data","monotonic_ns":306560223922000,"payload":{"event_type":"price_change","market":"0xda6f0e0e93fc8469e0159a166028d017bddbc162b86f66bac90391379603d962","price_changes":[{"asset_id":"20893381255801015515826997628594359667013752732428989472914000440642900266717","best_ask":"0.65","best_bid":"0.64","hash":"b7db9a638c5775c5962d878e0f116045dbd1af03","price":"0.01","side":"BUY","size":"5677.02"},{"asset_id":"39272994714739463168905443499424551362424437245880253267329605556587274644733","best_ask":"0.36","best_bid":"0.35","hash":"9fced6d0ad95599f85facb561d9765a8fcd38426","price":"0.99","side":"SELL","size":"5677.02"}],"timestamp":"1785204577330"},"payload_hash":"4dfa2ed6214f6beb49153edd699e7c5e043aeebe68fdee2898606697b36f2141","raw_frame":"{\"market\":\"0xda6f0e0e93fc8469e0159a166028d017bddbc162b86f66bac90391379603d962\", \"price_changes\":[{\"asset_id\":\"20893381255801015515826997628594359667013752732428989472914000440642900266717\", \"price\":\"0.01\", \"size\":\"5677.02\", \"side\":\"BUY\", \"hash\":\"b7db9a638c5775c5962d878e0f116045dbd1af03\", \"best_bid\":\"0.64\", \"best_ask\":\"0.65\"}, {\"asset_id\":\"39272994714739463168905443499424551362424437245880253267329605556587274644733\", \"price\":\"0.99\", \"size\":\"5677.02\", \"side\":\"SELL\", \"hash\":\"9fced6d0ad95599f85facb561d9765a8fcd38426\", \"best_bid\":\"0.35\", \"best_ask\":\"0.36\"}], \"timestamp\":\"1785204577330\", \"event_type\":\"price_change\"}","received_at":"2026-07-28T02:09:37.215151Z","schema_version":"clob-market-ws.price_change.v1","sequence":null,"server_hash":null,"server_timestamp":"1785204577330","session_id":"d2757dd6dad94f3b9fe67e8dbf1adc37","source":"clob_market_ws"},"received_at":"2026-07-28T02:09:37.215151Z","record_id":"d633a87c90faab168a149955660d20ec688868cdf0d9270dd4653848cffd146f","schema_fingerprint":"4aa3821a28b0b7c2400bc59aba4bcc0a76e971dadd19610d3ad38c768e124dc7","schema_version":"edge-lab-recorder.raw.v1","sequence":null,"source":"clob_market_ws"}
{"event_at":"2026-07-28T02:09:37.349000Z","event_fingerprint":"0777b619615e11ecf5c06f4ced53d68446b110d1b4c6af5d6f9c2065a3494824","payload":{"connection_id":"5d29200f65794d4d9ab6ef271f045a9b","event_at":"2026-07-28T02:09:37.349000Z","event_type":"price_change","frame_hash":"6b739f55c79cc6d0651a0cb3f262c346ba484886f5ee9cd88d1cade61e98d99e","frame_index":0,"kind":"data","monotonic_ns":306560245381083,"payload":{"event_type":"price_change","market":"0xda6f0e0e93fc8469e0159a166028d017bddbc162b86f66bac90391379603d962","price_changes":[{"asset_id":"20893381255801015515826997628594359667013752732428989472914000440642900266717","best_ask":"0.65","best_bid":"0.64","hash":"219e426888f48145b1ebe6038bfe55f0c15c316a","price":"0.02","side":"BUY","size":"732.1"},{"asset_id":"39272994714739463168905443499424551362424437245880253267329605556587274644733","best_ask":"0.36","best_bid":"0.35","hash":"c10a6d008ffe9d08b6e4fcaabcbccac8488a3d32","price":"0.98","side":"SELL","size":"732.1"}],"timestamp":"1785204577349"},"payload_hash":"7f8fca68eb0e5da710b517d699088690a97e1a5b3f27a7e0780244a80bdbc188","raw_frame":"{\"market\":\"0xda6f0e0e93fc8469e0159a166028d017bddbc162b86f66bac90391379603d962\", \"price_changes\":[{\"asset_id\":\"20893381255801015515826997628594359667013752732428989472914000440642900266717\", \"price\":\"0.02\", \"size\":\"732.1\", \"side\":\"BUY\", \"hash\":\"219e426888f48145b1ebe6038bfe55f0c15c316a\", \"best_bid\":\"0.64\", \"best_ask\":\"0.65\"}, {\"asset_id\":\"39272994714739463168905443499424551362424437245880253267329605556587274644733\", \"price\":\"0.98\", \"size\":\"732.1\", \"side\":\"SELL\", \"hash\":\"c10a6d008ffe9d08b6e4fcaabcbccac8488a3d32\", \"best_bid\":\"0.35\", \"best_ask\":\"0.36\"}], \"timestamp\":\"1785204577349\", \"event_type\":\"price_change\"}","received_at":"2026-07-28T02:09:37.236607Z","schema_version":"clob-market-ws.price_change.v1","sequence":null,"server_hash":null,"server_timestamp":"1785204577349","session_id":"d2757dd6dad94f3b9fe67e8dbf1adc37","source":"clob_market_ws"},"received_at":"2026-07-28T02:09:37.236607Z","record_id":"5a58af2236571d00326fb29b545e85bb06df4b276eb00309dd10533e5ae3d9df","schema_fingerprint":"4aa3821a28b0b7c2400bc59aba4bcc0a76e971dadd19610d3ad38c768e124dc7","schema_version":"edge-lab-recorder.raw.v1","sequence":null,"source":"clob_market_ws"}
{"event_at":"2026-07-28T02:09:37.391000Z","event_fingerprint":"002f1951a1180c5b1595599ce630148ed1d23908d4152e02527833739bda461e","payload":{"connection_id":"5d29200f65794d4d9ab6ef271f045a9b","event_at":"2026-07-28T02:09:37.391000Z","event_type":"price_change","frame_hash":"a193b30c03ab63c5ed81b47d0435437c6374001bdca230cf80d326793a2cb161","frame_index":0,"kind":"data","monotonic_ns":306560286254333,"payload":{"event_type":"price_change","market":"0xda6f0e0e93fc8469e0159a166028d017bddbc162b86f66bac90391379603d962","price_changes":[{"asset_id":"20893381255801015515826997628594359667013752732428989472914000440642900266717","best_ask":"0.65","best_bid":"0.64","hash":"230e11f423aa33414eaf6a52a998eed7a1afd2fb","price":"0.55","side":"BUY","size":"307.1"},{"asset_id":"39272994714739463168905443499424551362424437245880253267329605556587274644733","best_ask":"0.36","best_bid":"0.35","hash":"0acb4ca27b6d254383ea93adc17e649f82b57023","price":"0.45","side":"SELL","size":"307.1"}],"timestamp":"1785204577391"},"payload_hash":"9f9d6220d7056bd916cf70c9c7d792afb2b4c8c55079d7a26f1d6b3c07a16861","raw_frame":"{\"market\":\"0xda6f0e0e93fc8469e0159a166028d017bddbc162b86f66bac90391379603d962\", \"price_changes\":[{\"asset_id\":\"20893381255801015515826997628594359667013752732428989472914000440642900266717\", \"price\":\"0.55\", \"size\":\"307.1\", \"side\":\"BUY\", \"hash\":\"230e11f423aa33414eaf6a52a998eed7a1afd2fb\", \"best_bid\":\"0.64\", \"best_ask\":\"0.65\"}, {\"asset_id\":\"39272994714739463168905443499424551362424437245880253267329605556587274644733\", \"price\":\"0.45\", \"size\":\"307.1\", \"side\":\"SELL\", \"hash\":\"0acb4ca27b6d254383ea93adc17e649f82b57023\", \"best_bid\":\"0.35\", \"best_ask\":\"0.36\"}], \"timestamp\":\"1785204577391\", \"event_type\":\"price_change\"}","received_at":"2026-07-28T02:09:37.277480Z","schema_version":"clob-market-ws.price_change.v1","sequence":null,"server_hash":null,"server_timestamp":"1785204577391","session_id":"d2757dd6dad94f3b9fe67e8dbf1adc37","source":"clob_market_ws"},"received_at":"2026-07-28T02:09:37.277480Z","record_id":"a95f857fa93305a65754d1be9ebc347d8d27f9d9ba7e5858f47d1a22fb0bf283","schema_fingerprint":"4aa3821a28b0b7c2400bc59aba4bcc0a76e971dadd19610d3ad38c768e124dc7","schema_version":"edge-lab-recorder.raw.v1","sequence":null,"source":"clob_market_ws"}
{"event_at":"2026-07-28T02:09:37.393000Z","event_fingerprint":"b479a009ac6d8e15c95915de91b7b1462bfdd5f8a7a6b9925e89b853d40aef54","payload":{"connection_id":"5d29200f65794d4d9ab6ef271f045a9b","event_at":"2026-07-28T02:09:37.393000Z","event_type":"price_change","frame_hash":"896c3064139dcb5ae3c3c7dcf74080a0b71b9caa560f216188dbdf2e1155ead4","frame_index":0,"kind":"data","monotonic_ns":306560289394875,"payload":{"event_type":"price_change","market":"0xda6f0e0e93fc8469e0159a166028d017bddbc162b86f66bac90391379603d962","price_changes":[{"asset_id":"20893381255801015515826997628594359667013752732428989472914000440642900266717","best_ask":"0.65","best_bid":"0.64","hash":"15f38ca6f605b92da3347794c24937cbe676a671","price":"0.55","side":"BUY","size":"277.1"},{"asset_id":"39272994714739463168905443499424551362424437245880253267329605556587274644733","best_ask":"0.36","best_bid":"0.35","hash":"03886273a17bf7c82ab3fcada0546d6cfb91419b","price":"0.45","side":"SELL","size":"277.1"}],"timestamp":"1785204577393"},"payload_hash":"e5b8f1d10587a39f849b6323c8319a7d87e8ba9f214691880cf8d798e2574e39","raw_frame":"{\"market\":\"0xda6f0e0e93fc8469e0159a166028d017bddbc162b86f66bac90391379603d962\", \"price_changes\":[{\"asset_id\":\"20893381255801015515826997628594359667013752732428989472914000440642900266717\", \"price\":\"0.55\", \"size\":\"277.1\", \"side\":\"BUY\", \"hash\":\"15f38ca6f605b92da3347794c24937cbe676a671\", \"best_bid\":\"0.64\", \"best_ask\":\"0.65\"}, {\"asset_id\":\"39272994714739463168905443499424551362424437245880253267329605556587274644733\", \"price\":\"0.45\", \"size\":\"277.1\", \"side\":\"SELL\", \"hash\":\"03886273a17bf7c82ab3fcada0546d6cfb91419b\", \"best_bid\":\"0.35\", \"best_ask\":\"0.36\"}], \"timestamp\":\"1785204577393\", \"event_type\":\"price_change\"}","received_at":"2026-07-28T02:09:37.280620Z","schema_version":"clob-market-ws.price_change.v1","sequence":null,"server_hash":null,"server_timestamp":"1785204577393","session_id":"d2757dd6dad94f3b9fe67e8dbf1adc37","source":"clob_market_ws"},"received_at":"2026-07-28T02:09:37.280620Z","record_id":"9411471433608fd17ef20d4e212c552a928836b5d5ca1d5ebff51b00d7371260","schema_fingerprint":"4aa3821a28b0b7c2400bc59aba4bcc0a76e971dadd19610d3ad38c768e124dc7","schema_version":"edge-lab-recorder.raw.v1","sequence":null,"source":"clob_market_ws"}
{"event_at":"2026-07-28T02:09:37.393000Z","event_fingerprint":"c3bd469e1d251414aafea8976a5c5025fe00240d5ace7a9ce099c6c6d3a67bb6","payload":{"connection_id":"5d29200f65794d4d9ab6ef271f045a9b","event_at":"2026-07-28T02:09:37.393000Z","event_type":"price_change","frame_hash":"2adc3d127b1ac197c73e1a16fadea5f93aadbe7aebf8600e966dcec2ba4c09eb","frame_index":0,"kind":"data","monotonic_ns":306560291061375,"payload":{"event_type":"price_change","market":"0xda6f0e0e93fc8469e0159a166028d017bddbc162b86f66bac90391379603d962","price_changes":[{"asset_id":"20893381255801015515826997628594359667013752732428989472914000440642900266717","best_ask":"0.65","best_bid":"0.64","hash":"7d855c7344a983aff97745dafe1372dc94841f8c","price":"0.55","side":"BUY","size":"247.1"},{"asset_id":"39272994714739463168905443499424551362424437245880253267329605556587274644733","best_ask":"0.36","best_bid":"0.35","hash":"f92104f8bab0ce3eedcfdc0d5c69ca3c85c6d0c5","price":"0.45","side":"SELL","size":"247.1"}],"timestamp":"1785204577393"},"payload_hash":"79665ad974afe16cd1bf8e266e19bb8fd5b84a5b903c3418fbecb928204a834d","raw_frame":"{\"market\":\"0xda6f0e0e93fc8469e0159a166028d017bddbc162b86f66bac90391379603d962\", \"price_changes\":[{\"asset_id\":\"20893381255801015515826997628594359667013752732428989472914000440642900266717\", \"price\":\"0.55\", \"size\":\"247.1\", \"side\":\"BUY\", \"hash\":\"7d855c7344a983aff97745dafe1372dc94841f8c\", \"best_bid\":\"0.64\", \"best_ask\":\"0.65\"}, {\"asset_id\":\"39272994714739463168905443499424551362424437245880253267329605556587274644733\", \"price\":\"0.45\", \"size\":\"247.1\", \"side\":\"SELL\", \"hash\":\"f92104f8bab0ce3eedcfdc0d5c69ca3c85c6d0c5\", \"best_bid\":\"0.35\", \"best_ask\":\"0.36\"}], \"timestamp\":\"1785204577393\", \"event_type\":\"price_change\"}","received_at":"2026-07-28T02:09:37.282290Z","schema_version":"clob-market-ws.price_change.v1","sequence":null,"server_hash":null,"server_timestamp":"1785204577393","session_id":"d2757dd6dad94f3b9fe67e8dbf1adc37","source":"clob_market_ws"},"received_at":"2026-07-28T02:09:37.282290Z","record_id":"f792b8ede0376bf8e2ec8c8fb845bead0265d3ae34c55eaae95cb48d5f2785e1","schema_fingerprint":"4aa3821a28b0b7c2400bc59aba4bcc0a76e971dadd19610d3ad38c768e124dc7","schema_version":"edge-lab-recorder.raw.v1","sequence":null,"source":"clob_market_ws"}
{"event_at":"2026-07-28T02:09:37.418000Z","event_fingerprint":"d12889299e2ae78f4821d1fc203dd14f5214116d74e436b36b456153e090d3e9","payload":{"connection_id":"5d29200f65794d4d9ab6ef271f045a9b","event_at":"2026-07-28T02:09:37.418000Z","event_type":"price_change","frame_hash":"3b4cf5560f4c5587c66be08973cc34256c4144c094ad16dd13fade118ac06aa3","frame_index":0,"kind":"data","monotonic_ns":306560319306875,"payload":{"event_type":"price_change","market":"0xda6f0e0e93fc8469e0159a166028d017bddbc162b86f66bac90391379603d962","price_changes":[{"asset_id":"20893381255801015515826997628594359667013752732428989472914000440642900266717","best_ask":"0.65","best_bid":"0.64","hash":"855977d584097ce38afe152977cbc687ef58e972","price":"0.02","side":"BUY","size":"727.1"},{"asset_id":"39272994714739463168905443499424551362424437245880253267329605556587274644733","best_ask":"0.36","best_bid":"0.35","hash":"a19dc896e1ff9a833f3ce5b8daf651a446f83dc7","price":"0.98","side":"SELL","size":"727.1"}],"timestamp":"1785204577418"},"payload_hash":"86bc05fef826c7f7931ddbc419478fdffcb03538a2fd711030ba696c7f4281a8","raw_frame":"{\"market\":\"0xda6f0e0e93fc8469e0159a166028d017bddbc162b86f66bac90391379603d962\", \"price_changes\":[{\"asset_id\":\"20893381255801015515826997628594359667013752732428989472914000440642900266717\", \"price\":\"0.02\", \"size\":\"727.1\", \"side\":\"BUY\", \"hash\":\"855977d584097ce38afe152977cbc687ef58e972\", \"best_bid\":\"0.64\", \"best_ask\":\"0.65\"}, {\"asset_id\":\"39272994714739463168905443499424551362424437245880253267329605556587274644733\", \"price\":\"0.98\", \"size\":\"727.1\", \"side\":\"SELL\", \"hash\":\"a19dc896e1ff9a833f3ce5b8daf651a446f83dc7\", \"best_bid\":\"0.35\", \"best_ask\":\"0.36\"}], \"timestamp\":\"1785204577418\", \"event_type\":\"price_change\"}","received_at":"2026-07-28T02:09:37.310535Z","schema_version":"clob-market-ws.price_change.v1","sequence":null,"server_hash":null,"server_timestamp":"1785204577418","session_id":"d2757dd6dad94f3b9fe67e8dbf1adc37","source":"clob_market_ws"},"received_at":"2026-07-28T02:09:37.310535Z","record_id":"f112292e713b7ffc0579c3310fafca0bbb80e3fb48edb66ea37db930fc0fd6fb","schema_fingerprint":"4aa3821a28b0b7c2400bc59aba4bcc0a76e971dadd19610d3ad38c768e124dc7","schema_version":"edge-lab-recorder.raw.v1","sequence":null,"source":"clob_market_ws"}
{"event_at":"2026-07-28T02:09:37.419000Z","event_fingerprint":"8847bcf026a80ef2d1bb0322960491c9214bd135efe63b3508efaf7bebd42391","payload":{"connection_id":"5d29200f65794d4d9ab6ef271f045a9b","event_at":"2026-07-28T02:09:37.419000Z","event_type":"price_change","frame_hash":"27449ff0bbabfa59465fb5553589df430af9691b15f97620468e09c054e54f4c","frame_index":0,"kind":"data","monotonic_ns":306560320849166,"payload":{"event_type":"price_change","market":"0xda6f0e0e93fc8469e0159a166028d017bddbc162b86f66bac90391379603d962","price_changes":[{"asset_id":"20893381255801015515826997628594359667013752732428989472914000440642900266717","best_ask":"0.65","best_bid":"0.64","hash":"718fdcb777dde713a2935ad231c1d7aae65990ea","price":"0.56","side":"BUY","size":"230.5"},{"asset_id":"39272994714739463168905443499424551362424437245880253267329605556587274644733","best_ask":"0.36","best_bid":"0.35","hash":"3d121616b4b7fbbabcbdf001d2e958019104dfd2","price":"0.44","side":"SELL","size":"230.5"}],"timestamp":"1785204577419"},"payload_hash":"44d1568856c196f1b84468061846b55b4fcf64f563c0b770c592abfb604d52cb","raw_frame":"{\"market\":\"0xda6f0e0e93fc8469e0159a166028d017bddbc162b86f66bac90391379603d962\", \"price_changes\":[{\"asset_id\":\"20893381255801015515826997628594359667013752732428989472914000440642900266717\", \"price\":\"0.56\", \"size\":\"230.5\", \"side\":\"BUY\", \"hash\":\"718fdcb777dde713a2935ad231c1d7aae65990ea\", \"best_bid\":\"0.64\", \"best_ask\":\"0.65\"}, {\"asset_id\":\"39272994714739463168905443499424551362424437245880253267329605556587274644733\", \"price\":\"0.44\", \"size\":\"230.5\", \"side\":\"SELL\", \"hash\":\"3d121616b4b7fbbabcbdf001d2e958019104dfd2\", \"best_bid\":\"0.35\", \"best_ask\":\"0.36\"}], \"timestamp\":\"1785204577419\", \"event_type\":\"price_change\"}","received_at":"2026-07-28T02:09:37.312076Z","schema_version":"clob-market-ws.price_change.v1","sequence":null,"server_hash":null,"server_timestamp":"1785204577419","session_id":"d2757dd6dad94f3b9fe67e8dbf1adc37","source":"clob_market_ws"},"received_at":"2026-07-28T02:09:37.312076Z","record_id":"07690badb526a7fac48f6d6ce5466f8e90aa99e374a2cfe9334510d98cb81476","schema_fingerprint":"4aa3821a28b0b7c2400bc59aba4bcc0a76e971dadd19610d3ad38c768e124dc7","schema_version":"edge-lab-recorder.raw.v1","sequence":null,"source":"clob_market_ws"}
{"event_at":"2026-07-28T02:09:37.441000Z","event_fingerprint":"a32c13add9574ca63509ca55859e28e85c61d1b63c615fc49ec5b8a07830eb01","payload":{"connection_id":"5d29200f65794d4d9ab6ef271f045a9b","event_at":"2026-07-28T02:09:37.441000Z","event_type":"price_change","frame_hash":"cdf1252d9f94f999bbc7a5a237e628ee526cacc841f660e81787af0a4277549f","frame_index":0,"kind":"data","monotonic_ns":306560336672833,"payload":{"event_type":"price_change","market":"0xda6f0e0e93fc8469e0159a166028d017bddbc162b86f66bac90391379603d962","price_changes":[{"asset_id":"20893381255801015515826997628594359667013752732428989472914000440642900266717","best_ask":"0.65","best_bid":"0.64","hash":"9da0672155fd878c5b26bb8ceb11f9734d5781db","price":"0.56","side":"BUY","size":"260.5"},{"asset_id":"39272994714739463168905443499424551362424437245880253267329605556587274644733","best_ask":"0.36","best_bid":"0.35","hash":"450e2964f6754c27dcfc1289782af0e36bb6e52a","price":"0.44","side":"SELL","size":"260.5"}],"timestamp":"1785204577441"},"payload_hash":"162baf197717d028024271ebe3eaf6d4aa0ea3103914f83122290c012acd2cda","raw_frame":"{\"market\":\"0xda6f0e0e93fc8469e0159a166028d017bddbc162b86f66bac90391379603d962\", \"price_changes\":[{\"asset_id\":\"20893381255801015515826997628594359667013752732428989472914000440642900266717\", \"price\":\"0.56\", \"size\":\"260.5\", \"side\":\"BUY\", \"hash\":\"9da0672155fd878c5b26bb8ceb11f9734d5781db\", \"best_bid\":\"0.64\", \"best_ask\":\"0.65\"}, {\"asset_id\":\"39272994714739463168905443499424551362424437245880253267329605556587274644733\", \"price\":\"0.44\", \"size\":\"260.5\", \"side\":\"SELL\", \"hash\":\"450e2964f6754c27dcfc1289782af0e36bb6e52a\", \"best_bid\":\"0.35\", \"best_ask\":\"0.36\"}], \"timestamp\":\"1785204577441\", \"event_type\":\"price_change\"}","received_at":"2026-07-28T02:09:37.327899Z","schema_version":"clob-market-ws.price_change.v1","sequence":null,"server_hash":null,"server_timestamp":"1785204577441","session_id":"d2757dd6dad94f3b9fe67e8dbf1adc37","source":"clob_market_ws"},"received_at":"2026-07-28T02:09:37.327899Z","record_id":"97fd0fd31508d34acec53b7533a17fc75f5ab33ac5fb393bfed6a90775354eb8","schema_fingerprint":"4aa3821a28b0b7c2400bc59aba4bcc0a76e971dadd19610d3ad38c768e124dc7","schema_version":"edge-lab-recorder.raw.v1","sequence":null,"source":"clob_market_ws"}
{"event_at":"2026-07-28T02:09:37.443000Z","event_fingerprint":"3ea895e9e65a8e5193b39bf0920886be846fe12c98587a2ab32947f4af69c79c","payload":{"connection_id":"5d29200f65794d4d9ab6ef271f045a9b","event_at":"2026-07-28T02:09:37.443000Z","event_type":"price_change","frame_hash":"80e21ec96edfd9320cc40e973945cbd6cae43f5025f61a9636695d03dd437737","frame_index":0,"kind":"data","monotonic_ns":306560338155750,"payload":{"event_type":"price_change","market":"0xda6f0e0e93fc8469e0159a166028d017bddbc162b86f66bac90391379603d962","price_changes":[{"asset_id":"20893381255801015515826997628594359667013752732428989472914000440642900266717","best_ask":"0.65","best_bid":"0.64","hash":"018e486614f99138d5d9d4c30bce22efbb806ac3","price":"0.56","side":"BUY","size":"290.5"},{"asset_id":"39272994714739463168905443499424551362424437245880253267329605556587274644733","best_ask":"0.36","best_bid":"0.35","hash":"966c21f5f329198b779194d02c8057fbd7bfbe82","price":"0.44","side":"SELL","size":"290.5"}],"timestamp":"1785204577443"},"payload_hash":"3f0fb0fc7fb37c25a752a538e7b21193618808e27c2c08d78e298f2ec25ca99d","raw_frame":"{\"market\":\"0xda6f0e0e93fc8469e0159a166028d017bddbc162b86f66bac90391379603d962\", \"price_changes\":[{\"asset_id\":\"20893381255801015515826997628594359667013752732428989472914000440642900266717\", \"price\":\"0.56\", \"size\":\"290.5\", \"side\":\"BUY\", \"hash\":\"018e486614f99138d5d9d4c30bce22efbb806ac3\", \"best_bid\":\"0.64\", \"best_ask\":\"0.65\"}, {\"asset_id\":\"39272994714739463168905443499424551362424437245880253267329605556587274644733\", \"price\":\"0.44\", \"size\":\"290.5\", \"side\":\"SELL\", \"hash\":\"966c21f5f329198b779194d02c8057fbd7bfbe82\", \"best_bid\":\"0.35\", \"best_ask\":\"0.36\"}], \"timestamp\":\"1785204577443\", \"event_type\":\"price_change\"}","received_at":"2026-07-28T02:09:37.329385Z","schema_version":"clob-market-ws.price_change.v1","sequence":null,"server_hash":null,"server_timestamp":"1785204577443","session_id":"d2757dd6dad94f3b9fe67e8dbf1adc37","source":"clob_market_ws"},"received_at":"2026-07-28T02:09:37.329385Z","record_id":"3891357a62f49a145a8ebf371e078c328ac6b2545fe6636569d979a138cc1cca","schema_fingerprint":"4aa3821a28b0b7c2400bc59aba4bcc0a76e971dadd19610d3ad38c768e124dc7","schema_version":"edge-lab-recorder.raw.v1","sequence":null,"source":"clob_market_ws"}
{"event_at":"2026-07-28T02:09:37.460000Z","event_fingerprint":"ea45dc79385b2b6278a95930d99c514f54bc9e43c2cbf0e8c9f4608d5f18ad61","payload":{"connection_id":"5d29200f65794d4d9ab6ef271f045a9b","event_at":"2026-07-28T02:09:37.460000Z","event_type":"price_change","frame_hash":"7992fd000fe9ea87af3b6977f9ef5695287a6c5ceb87badd62fa18924b1ba022","frame_index":0,"kind":"data","monotonic_ns":306560356473458,"payload":{"event_type":"price_change","market":"0xda6f0e0e93fc8469e0159a166028d017bddbc162b86f66bac90391379603d962","price_changes":[{"asset_id":"20893381255801015515826997628594359667013752732428989472914000440642900266717","best_ask":"0.65","best_bid":"0.64","hash":"3ffb136936a2e91ce884d2943a1d141752ac370c","price":"0.01","side":"BUY","size":"5682.02"},{"asset_id":"39272994714739463168905443499424551362424437245880253267329605556587274644733","best_ask":"0.36","best_bid":"0.35","hash":"36c89a1d3d9f98a7a05d2ca218b34aa09cae1f20","price":"0.99","side":"SELL","size":"5682.02"}],"timestamp":"1785204577460"},"payload_hash":"b01963f4a277b85020c261cd8340fc09a675e8d3153fc7b93d51037c0e0a3c20","raw_frame":"{\"market\":\"0xda6f0e0e93fc8469e0159a166028d017bddbc162b86f66bac90391379603d962\", \"price_changes\":[{\"asset_id\":\"20893381255801015515826997628594359667013752732428989472914000440642900266717\", \"price\":\"0.01\", \"size\":\"5682.02\", \"side\":\"BUY\", \"hash\":\"3ffb136936a2e91ce884d2943a1d141752ac370c\", \"best_bid\":\"0.64\", \"best_ask\":\"0.65\"}, {\"asset_id\":\"39272994714739463168905443499424551362424437245880253267329605556587274644733\", \"price\":\"0.99\", \"size\":\"5682.02\", \"side\":\"SELL\", \"hash\":\"36c89a1d3d9f98a7a05d2ca218b34aa09cae1f20\", \"best_bid\":\"0.35\", \"best_ask\":\"0.36\"}], \"timestamp\":\"1785204577460\", \"event_type\":\"price_change\"}","received_at":"2026-07-28T02:09:37.347698Z","schema_version":"clob-market-ws.price_change.v1","sequence":null,"server_hash":null,"server_timestamp":"1785204577460","session_id":"d2757dd6dad94f3b9fe67e8dbf1adc37","source":"clob_market_ws"},"received_at":"2026-07-28T02:09:37.347698Z","record_id":"a14da4957006447964837c8dc6c0c212d05e12b3a4eb1b949922bebbfc2c8991","schema_fingerprint":"4aa3821a28b0b7c2400bc59aba4bcc0a76e971dadd19610d3ad38c768e124dc7","schema_version":"edge-lab-recorder.raw.v1","sequence":null,"source":"clob_market_ws"}
{"event_at":"2026-07-28T02:09:37.488000Z","event_fingerprint":"3ee24aab9bee9909c71a36e86ba6da97f49097dad4564208570d174c5b2a682c","payload":{"connection_id":"5d29200f65794d4d9ab6ef271f045a9b","event_at":"2026-07-28T02:09:37.488000Z","event_type":"price_change","frame_hash":"2df940ec767a6bb53320ad89a1f78d4b9f6f330782a11d531d71ac767584c2ef","frame_index":0,"kind":"data","monotonic_ns":306560388544666,"payload":{"event_type":"price_change","market":"0xda6f0e0e93fc8469e0159a166028d017bddbc162b86f66bac90391379603d962","price_changes":[{"asset_id":"20893381255801015515826997628594359667013752732428989472914000440642900266717","best_ask":"0.65","best_bid":"0.64","hash":"80a2a834d0080ba709916ced4d398baaee599fae","price":"0.01","side":"BUY","size":"5677.02"},{"asset_id":"39272994714739463168905443499424551362424437245880253267329605556587274644733","best_ask":"0.36","best_bid":"0.35","hash":"c0a7cbeeaa8348f89f4c47d73831b76b5baa5931","price":"0.99","side":"SELL","size":"5677.02"}],"timestamp":"1785204577488"},"payload_hash":"6f731d16666b03d128ce97d240138b02f17100610f2ceedff2e2050b1f4bc4f6","raw_frame":"{\"market\":\"0xda6f0e0e93fc8469e0159a166028d017bddbc162b86f66bac90391379603d962\", \"price_changes\":[{\"asset_id\":\"20893381255801015515826997628594359667013752732428989472914000440642900266717\", \"price\":\"0.01\", \"size\":\"5677.02\", \"side\":\"BUY\", \"hash\":\"80a2a834d0080ba709916ced4d398baaee599fae\", \"best_bid\":\"0.64\", \"best_ask\":\"0.65\"}, {\"asset_id\":\"39272994714739463168905443499424551362424437245880253267329605556587274644733\", \"price\":\"0.99\", \"size\":\"5677.02\", \"side\":\"SELL\", \"hash\":\"c0a7cbeeaa8348f89f4c47d73831b76b5baa5931\", \"best_bid\":\"0.35\", \"best_ask\":\"0.36\"}], \"timestamp\":\"1785204577488\", \"event_type\":\"price_change\"}","received_at":"2026-07-28T02:09:37.379770Z","schema_version":"clob-market-ws.price_change.v1","sequence":null,"server_hash":null,"server_timestamp":"1785204577488","session_id":"d2757dd6dad94f3b9fe67e8dbf1adc37","source":"clob_market_ws"},"received_at":"2026-07-28T02:09:37.379770Z","record_id":"855aaa84ccc0c1f37bbd0a8c4aa7332b3b970fa942e054306e4b5d486cfe5e09","schema_fingerprint":"4aa3821a28b0b7c2400bc59aba4bcc0a76e971dadd19610d3ad38c768e124dc7","schema_version":"edge-lab-recorder.raw.v1","sequence":null,"source":"clob_market_ws"}
{"event_at":"2026-07-28T02:09:37.514000Z","event_fingerprint":"2ebdd70a838bf4b9abedb2a6da6cb4d244c5bbeda1a728ae23708cd96bf9eacb","payload":{"connection_id":"5d29200f65794d4d9ab6ef271f045a9b","event_at":"2026-07-28T02:09:37.514000Z","event_type":"price_change","frame_hash":"a06653d61ba154b16e6891d41d2c83fc65c0881f3feef1f008bb4fd02e2d2396","frame_index":0,"kind":"data","monotonic_ns":306560409135208,"payload":{"event_type":"price_change","market":"0xda6f0e0e93fc8469e0159a166028d017bddbc162b86f66bac90391379603d962","price_changes":[{"asset_id":"20893381255801015515826997628594359667013752732428989472914000440642900266717","best_ask":"0.65","best_bid":"0.64","hash":"ae72d1835a08550dc22d552daf547da9a591b5d0","price":"0.04","side":"BUY","size":"667.09"},{"asset_id":"39272994714739463168905443499424551362424437245880253267329605556587274644733","best_ask":"0.36","best_bid":"0.35","hash":"55ed7b605b3971f1dafcc7639721488d6c00e042","price":"0.96","side":"SELL","size":"667.09"}],"timestamp":"1785204577514"},"payload_hash":"369e7dd2438cbb5930dcdddc87e090df3a466994f1f65776a3221b2878851e36","raw_frame":"{\"market\":\"0xda6f0e0e93fc8469e0159a166028d017bddbc162b86f66bac90391379603d962\", \"price_changes\":[{\"asset_id\":\"20893381255801015515826997628594359667013752732428989472914000440642900266717\", \"price\":\"0.04\", \"size\":\"667.09\", \"side\":\"BUY\", \"hash\":\"ae72d1835a08550dc22d552daf547da9a591b5d0\", \"best_bid\":\"0.64\", \"best_ask\":\"0.65\"}, {\"asset_id\":\"39272994714739463168905443499424551362424437245880253267329605556587274644733\", \"price\":\"0.96\", \"size\":\"667.09\", \"side\":\"SELL\", \"hash\":\"55ed7b605b3971f1dafcc7639721488d6c00e042\", \"best_bid\":\"0.35\", \"best_ask\":\"0.36\"}], \"timestamp\":\"1785204577514\", \"event_type\":\"price_change\"}","received_at":"2026-07-28T02:09:37.400358Z","schema_version":"clob-market-ws.price_change.v1","sequence":null,"server_hash":null,"server_timestamp":"1785204577514","session_id":"d2757dd6dad94f3b9fe67e8dbf1adc37","source":"clob_market_ws"},"received_at":"2026-07-28T02:09:37.400358Z","record_id":"ea12cc6a8ea0c81c24429620bcd5618929cf433aadeafc493d7374f0091557e0","schema_fingerprint":"4aa3821a28b0b7c2400bc59aba4bcc0a76e971dadd19610d3ad38c768e124dc7","schema_version":"edge-lab-recorder.raw.v1","sequence":null,"source":"clob_market_ws"}
{"event_at":"2026-07-28T02:09:37.526000Z","event_fingerprint":"b30f7ff48fb14e6cb938949e261379088b9fc91f083a023bdb28340583785112","payload":{"connection_id":"5d29200f65794d4d9ab6ef271f045a9b","event_at":"2026-07-28T02:09:37.526000Z","event_type":"price_change","frame_hash":"35317b829f8ddb6d50b62117aaa0de03b9b9e8e5095c507b34b05db81f53e29e","frame_index":0,"kind":"data","monotonic_ns":306560421013416,"payload":{"event_type":"price_change","market":"0xda6f0e0e93fc8469e0159a166028d017bddbc162b86f66bac90391379603d962","price_changes":[{"asset_id":"39272994714739463168905443499424551362424437245880253267329605556587274644733","best_ask":"0.36","best_bid":"0.35","hash":"a2699aaad493c0cfb56cb4ca9c820bdb4a37642f","price":"0.3","side":"BUY","size":"87.96"},{"asset_id":"20893381255801015515826997628594359667013752732428989472914000440642900266717","best_ask":"0.65","best_bid":"0.64","hash":"144e22288073d809d77c8b03c4cb81a2bca21585","price":"0.7","side":"SELL","size":"87.96"}],"timestamp":"1785204577526"},"payload_hash":"7150e867f0b947f1178cefe8db78aedba3d1ec827780f327ad51d926d547c67e","raw_frame":"{\"market\":\"0xda6f0e0e93fc8469e0159a166028d017bddbc162b86f66bac90391379603d962\", \"price_changes\":[{\"asset_id\":\"39272994714739463168905443499424551362424437245880253267329605556587274644733\", \"price\":\"0.3\", \"size\":\"87.96\", \"side\":\"BUY\", \"hash\":\"a2699aaad493c0cfb56cb4ca9c820bdb4a37642f\", \"best_bid\":\"0.35\", \"best_ask\":\"0.36\"}, {\"asset_id\":\"20893381255801015515826997628594359667013752732428989472914000440642900266717\", \"price\":\"0.7\", \"size\":\"87.96\", \"side\":\"SELL\", \"hash\":\"144e22288073d809d77c8b03c4cb81a2bca21585\", \"best_bid\":\"0.64\", \"best_ask\":\"0.65\"}], \"timestamp\":\"1785204577526\", \"event_type\":\"price_change\"}","received_at":"2026-07-28T02:09:37.412236Z","schema_version":"clob-market-ws.price_change.v1","sequence":null,"server_hash":null,"server_timestamp":"1785204577526","session_id":"d2757dd6dad94f3b9fe67e8dbf1adc37","source":"clob_market_ws"},"received_at":"2026-07-28T02:09:37.412236Z","record_id":"e75fa26c5961a8cdbea2e7bf7c7ab63ffb483dc869b6ebaae654153df02cf93a","schema_fingerprint":"4aa3821a28b0b7c2400bc59aba4bcc0a76e971dadd19610d3ad38c768e124dc7","schema_version":"edge-lab-recorder.raw.v1","sequence":null,"source":"clob_market_ws"}
{"event_at":"2026-07-28T02:09:37.526000Z","event_fingerprint":"6f1fa350af3578aed012ba0e053a3f200240c9f134fa97b31c49c2239d1affb2","payload":{"connection_id":"5d29200f65794d4d9ab6ef271f045a9b","event_at":"2026-07-28T02:09:37.526000Z","event_type":"price_change","frame_hash":"539319afa536df549849b6274cd21a91d0432b7b2d25af81c800b65894abb47d","frame_index":0,"kind":"data","monotonic_ns":306560428902041,"payload":{"event_type":"price_change","market":"0xda6f0e0e93fc8469e0159a166028d017bddbc162b86f66bac90391379603d962","price_changes":[{"asset_id":"39272994714739463168905443499424551362424437245880253267329605556587274644733","best_ask":"0.36","best_bid":"0.35","hash":"d7739fc0c83e6f4c90fcaedf93b673a720ca2d87","price":"0.29","side":"BUY","size":"119.3"},{"asset_id":"20893381255801015515826997628594359667013752732428989472914000440642900266717","best_ask":"0.65","best_bid":"0.64","hash":"0c24575fcb68b0ce7fbbc2b2594a05e916cfa6cb","price":"0.71","side":"SELL","size":"119.3"}],"timestamp":"1785204577526"},"payload_hash":"281bde4370220d4e81b32068ca714644b153173c8f8a83d16d12f3a24ee1a44b","raw_frame":"{\"market\":\"0xda6f0e0e93fc8469e0159a166028d017bddbc162b86f66bac90391379603d962\", \"price_changes\":[{\"asset_id\":\"39272994714739463168905443499424551362424437245880253267329605556587274644733\", \"price\":\"0.29\", \"size\":\"119.3\", \"side\":\"BUY\", \"hash\":\"d7739fc0c83e6f4c90fcaedf93b673a720ca2d87\", \"best_bid\":\"0.35\", \"best_ask\":\"0.36\"}, {\"asset_id\":\"20893381255801015515826997628594359667013752732428989472914000440642900266717\", \"price\":\"0.71\", \"size\":\"119.3\", \"side\":\"SELL\", \"hash\":\"0c24575fcb68b0ce7fbbc2b2594a05e916cfa6cb\", \"best_bid\":\"0.64\", \"best_ask\":\"0.65\"}], \"timestamp\":\"1785204577526\", \"event_type\":\"price_change\"}","received_at":"2026-07-28T02:09:37.420129Z","schema_version":"clob-market-ws.price_change.v1","sequence":null,"server_hash":null,"server_timestamp":"1785204577526","session_id":"d2757dd6dad94f3b9fe67e8dbf1adc37","source":"clob_market_ws"},"received_at":"2026-07-28T02:09:37.420129Z","record_id":"589ac481983b6e08f0fa9d6a1c2c1f6e7132f227ccdcd2bf22a73f77950981c2","schema_fingerprint":"4aa3821a28b0b7c2400bc59aba4bcc0a76e971dadd19610d3ad38c768e124dc7","schema_version":"edge-lab-recorder.raw.v1","sequence":null,"source":"clob_market_ws"}
{"event_at":"2026-07-28T02:09:37.527000Z","event_fingerprint":"916ab093e46f890279ba7561b37affb058962e60146a301f08185722bf26584b","payload":{"connection_id":"5d29200f65794d4d9ab6ef271f045a9b","event_at":"2026-07-28T02:09:37.527000Z","event_type":"price_change","frame_hash":"4b6bb49358d9d5a04d40ea904dad0e591ef842c922e843598919c0d62ecb5c5d","frame_index":0,"kind":"data","monotonic_ns":306560430459250,"payload":{"event_type":"price_change","market":"0xda6f0e0e93fc8469e0159a166028d017bddbc162b86f66bac90391379603d962","price_changes":[{"asset_id":"39272994714739463168905443499424551362424437245880253267329605556587274644733","best_ask":"0.36","best_bid":"0.35","hash":"f1987a649f45a8790a0adb898d0f6ebc29692ad1","price":"0.3","side":"BUY","size":"116.96"},{"asset_id":"20893381255801015515826997628594359667013752732428989472914000440642900266717","best_ask":"0.65","best_bid":"0.64","hash":"99beaa8cd161aa9c1c8634b1a4f7da94284bc5da","price":"0.7","side":"SELL","size":"116.96"}],"timestamp":"1785204577527"},"payload_hash":"62f60cfb3671435a834e2c300611be84a1b6f229716f13a692fe2ec4cbced8ee","raw_frame":"{\"market\":\"0xda6f0e0e93fc8469e0159a166028d017bddbc162b86f66bac90391379603d962\", \"price_changes\":[{\"asset_id\":\"39272994714739463168905443499424551362424437245880253267329605556587274644733\", \"price\":\"0.3\", \"size\":\"116.96\", \"side\":\"BUY\", \"hash\":\"f1987a649f45a8790a0adb898d0f6ebc29692ad1\", \"best_bid\":\"0.35\", \"best_ask\":\"0.36\"}, {\"asset_id\":\"20893381255801015515826997628594359667013752732428989472914000440642900266717\", \"price\":\"0.7\", \"size\":\"116.96\", \"side\":\"SELL\", \"hash\":\"99beaa8cd161aa9c1c8634b1a4f7da94284bc5da\", \"best_bid\":\"0.64\", \"best_ask\":\"0.65\"}], \"timestamp\":\"1785204577527\", \"event_type\":\"price_change\"}","received_at":"2026-07-28T02:09:37.421686Z","schema_version":"clob-market-ws.price_change.v1","sequence":null,"server_hash":null,"server_timestamp":"1785204577527","session_id":"d2757dd6dad94f3b9fe67e8dbf1adc37","source":"clob_market_ws"},"received_at":"2026-07-28T02:09:37.421686Z","record_id":"9ba1f34343b3b451d0093d405e76551fc807f063cb67338cb04e0d70f3b65c64","schema_fingerprint":"4aa3821a28b0b7c2400bc59aba4bcc0a76e971dadd19610d3ad38c768e124dc7","schema_version":"edge-lab-recorder.raw.v1","sequence":null,"source":"clob_market_ws"}
{"event_at":"2026-07-28T02:09:37.530000Z","event_fingerprint":"f7183c303bdae21aef63f3f7160113875d8165b293235986752a2967fcee8624","payload":{"connection_id":"5d29200f65794d4d9ab6ef271f045a9b","event_at":"2026-07-28T02:09:37.530000Z","event_type":"price_change","frame_hash":"4a4c0ecec1f5ea4dadeae4ed55411920b3e31f32a0a4d6f45a4ba764ca2b6e08","frame_index":0,"kind":"data","monotonic_ns":306560432023208,"payload":{"event_type":"price_change","market":"0xda6f0e0e93fc8469e0159a166028d017bddbc162b86f66bac90391379603d962","price_changes":[{"asset_id":"39272994714739463168905443499424551362424437245880253267329605556587274644733","best_ask":"0.36","best_bid":"0.35","hash":"f9127eb91953deeb5c0a2d83c918f188f043057c","price":"0.29","side":"BUY","size":"148.3"},{"asset_id":"20893381255801015515826997628594359667013752732428989472914000440642900266717","best_ask":"0.65","best_bid":"0.64","hash":"5f8fdd2f2550d347d50444e4d5de85457b37d6b5","price":"0.71","side":"SELL","size":"148.3"}],"timestamp":"1785204577530"},"payload_hash":"d8db2ebb01ece6e6b8f1201d026cb696cba865b6e8bf75ec12cedf32de9e9e00","raw_frame":"{\"market\":\"0xda6f0e0e93fc8469e0159a166028d017bddbc162b86f66bac90391379603d962\", \"price_changes\":[{\"asset_id\":\"39272994714739463168905443499424551362424437245880253267329605556587274644733\", \"price\":\"0.29\", \"size\":\"148.3\", \"side\":\"BUY\", \"hash\":\"f9127eb91953deeb5c0a2d83c918f188f043057c\", \"best_bid\":\"0.35\", \"best_ask\":\"0.36\"}, {\"asset_id\":\"20893381255801015515826997628594359667013752732428989472914000440642900266717\", \"price\":\"0.71\", \"size\":\"148.3\", \"side\":\"SELL\", \"hash\":\"5f8fdd2f2550d347d50444e4d5de85457b37d6b5\", \"best_bid\":\"0.64\", \"best_ask\":\"0.65\"}], \"timestamp\":\"1785204577530\", \"event_type\":\"price_change\"}","received_at":"2026-07-28T02:09:37.423252Z","schema_version":"clob-market-ws.price_change.v1","sequence":null,"server_hash":null,"server_timestamp":"1785204577530","session_id":"d2757dd6dad94f3b9fe67e8dbf1adc37","source":"clob_market_ws"},"received_at":"2026-07-28T02:09:37.423252Z","record_id":"516bf1f5784572c12957d8313ee50194aa5bb6fab8f14dd87a3c16a0408e6d56","schema_fingerprint":"4aa3821a28b0b7c2400bc59aba4bcc0a76e971dadd19610d3ad38c768e124dc7","schema_version":"edge-lab-recorder.raw.v1","sequence":null,"source":"clob_market_ws"}
{"event_at":"2026-07-28T02:09:37.532000Z","event_fingerprint":"2f24fcc6d80d1a9f7d7d652d7f512caee4d254b15b4fe5dc7a904900b9e7187b","payload":{"connection_id":"5d29200f65794d4d9ab6ef271f045a9b","event_at":"2026-07-28T02:09:37.532000Z","event_type":"price_change","frame_hash":"94431f7579c1e577c23e757032b7f27b353ac2bc967362e2e92de2340ca2750c","frame_index":0,"kind":"data","monotonic_ns":306560433526791,"payload":{"event_type":"price_change","market":"0xda6f0e0e93fc8469e0159a166028d017bddbc162b86f66bac90391379603d962","price_changes":[{"asset_id":"39272994714739463168905443499424551362424437245880253267329605556587274644733","best_ask":"0.36","best_bid":"0.35","hash":"53a7c18f49eafc3a422ade4a005a55240ce55ef8","price":"0.28","side":"BUY","size":"150.56"},{"asset_id":"20893381255801015515826997628594359667013752732428989472914000440642900266717","best_ask":"0.65","best_bid":"0.64","hash":"b4633f2e5dd3ddb30d5b655c1c5da877b18ca0de","price":"0.72","side":"SELL","size":"150.56"}],"timestamp":"1785204577532"},"payload_hash":"2a580d4efc6d0fffb2637c903f9c45a1fdf0194f886aa8cf02655556a7309bc0","raw_frame":"{\"market\":\"0xda6f0e0e93fc8469e0159a166028d017bddbc162b86f66bac90391379603d962\", \"price_changes\":[{\"asset_id\":\"39272994714739463168905443499424551362424437245880253267329605556587274644733\", \"price\":\"0.28\", \"size\":\"150.56\", \"side\":\"BUY\", \"hash\":\"53a7c18f49eafc3a422ade4a005a55240ce55ef8\", \"best_bid\":\"0.35\", \"best_ask\":\"0.36\"}, {\"asset_id\":\"20893381255801015515826997628594359667013752732428989472914000440642900266717\", \"price\":\"0.72\", \"size\":\"150.56\", \"side\":\"SELL\", \"hash\":\"b4633f2e5dd3ddb30d5b655c1c5da877b18ca0de\", \"best_bid\":\"0.64\", \"best_ask\":\"0.65\"}], \"timestamp\":\"1785204577532\", \"event_type\":\"price_change\"}","received_at":"2026-07-28T02:09:37.424756Z","schema_version":"clob-market-ws.price_change.v1","sequence":null,"server_hash":null,"server_timestamp":"1785204577532","session_id":"d2757dd6dad94f3b9fe67e8dbf1adc37","source":"clob_market_ws"},"received_at":"2026-07-28T02:09:37.424756Z","record_id":"9bc4c69f4a5e15aed503ab70490018f4050aaa94edd157963743fd85ef4ac15a","schema_fingerprint":"4aa3821a28b0b7c2400bc59aba4bcc0a76e971dadd19610d3ad38c768e124dc7","schema_version":"edge-lab-recorder.raw.v1","sequence":null,"source":"clob_market_ws"}
{"event_at":"2026-07-28T02:09:37.532000Z","event_fingerprint":"4a93e7a225655b72f3a66cc5c2fed547597809350a78ffb72736dc85b3d8f7d0","payload":{"connection_id":"5d29200f65794d4d9ab6ef271f045a9b","event_at":"2026-07-28T02:09:37.532000Z","event_type":"new_market","frame_hash":"4d30f94bc77c48cdd93f072d0f52ee105cb0de70221e085d2195d3ad6b9524ed","frame_index":0,"kind":"data","monotonic_ns":306560441986583,"payload":{"active":false,"assets_ids":["108062157697286015622577469023612672353592876674616452087163180572487677591037","56057232265226431967967218399897950548398905217954763659783014333347417342313"],"clob_token_ids":["108062157697286015622577469023612672353592876674616452087163180572487677591037","56057232265226431967967218399897950548398905217954763659783014333347417342313"],"condition_id":"0xd067f308ce079cb36142aa0079a087a47f8cba2adeb2e153935aa134ef7bf3fa","description":"Episode 7 of House of the Dragon Season 3 is scheduled to air on August 2, 2026. \n\nThis market will resolve to \"Yes\" if anyone says the listed term during the specified episode of House of the Dragon. Otherwise, the market will resolve to \"No\". Terms audible in background music will not be considered toward the resolution of this market, neither will terms said within a \"previously on\" recap or \"next time on\" preview segment.\n\nIf this episode of House of the Dragon has not been released in its entirety by August 3, 2026, 11:59 PM ET, this market will resolve based on what has been released up to that point. If no episode has been released by this time, or if the release is otherwise definitively cancelled, \"-No Qualifying Event-\" will resolve to \"Yes\" and all other brackets will resolve to \"No\".\n\nThe resolution source for this market will be the initial release of the named episode of House of the Dragon. Reruns, re-releases, or transcripts which differ from the initially released episode will not be considered.\n\nFor full rules, see: https://polymarket-upload.s3.us-east-2.amazonaws.com/market_products/Event+Mentions+Contract+DeFi.pdf","event_message":{"description":"Episode 7 of House of the Dragon Season 3 is scheduled to air on August 2, 2026. \n\nThis market will resolve to \"Yes\" if anyone says the listed term during the specified episode of House of the Dragon. Otherwise, the market will resolve to \"No\". Terms audible in background music will not be considered toward the resolution of this market, neither will terms said within a \"previously on\" recap or \"next time on\" preview segment.\n\nIf this episode of House of the Dragon has not been released in its entirety by August 3, 2026, 11:59 PM ET, this market will resolve based on what has been released up to that point. If no episode has been released by this time, or if the release is otherwise definitively cancelled, \"-No Qualifying Event-\" will resolve to \"Yes\" and all other brackets will resolve to \"No\".\n\nThe resolution source for this market will be the initial release of the named episode of House of the Dragon. Reruns, re-releases, or transcripts which differ from the initially released episode will not be considered.\n\nFor full rules, see: https://polymarket-upload.s3.us-east-2.amazonaws.com/market_products/Event+Mentions+Contract+DeFi.pdf","id":"758896","slug":"what-will-be-said-during-the-seventh-episode-of-house-of-the-dragon-season-3-20260727205600937","ticker":"what-will-be-said-during-the-seventh-episode-of-house-of-the-dragon-season-3-20260727205600937","title":"What will be said during the seventh episode of House of the Dragon: Season 3?"},"event_type":"new_market","fee_schedule":{"exponent":"1","rate":"0.04","rebate_rate":"0.25","taker_only":true},"fees_enabled":true,"game_start_time":"","group_item_title":"Queen 10+ times","id":"3142911","line":"","market":"0xd067f308ce079cb36142aa0079a087a47f8cba2adeb2e153935aa134ef7bf3fa","order_price_min_tick_size":"0.01","outcomes":["Yes","No"],"question":"Will anyone say \"Queen\" 10+ times during House of the Dragon E7 S3?","slug":"will-anyone-say-queen-10-times-during-house-of-the-dragon-e7-s3-20260727205600940","sports_market_type":"","tags":[],"taker_base_fee":"1000","timestamp":"1785204577532"},"payload_hash":"1f72555855af17fe7033df1fef777bb785acc393593eab48a83c588773e66644","raw_frame":"{\"id\":\"3142911\", \"question\":\"Will anyone say \\\"Queen\\\" 10+ times during House of the Dragon E7 S3?\", \"market\":\"0xd067f308ce079cb36142aa0079a087a47f8cba2adeb2e153935aa134ef7bf3fa\", \"slug\":\"will-anyone-say-queen-10-times-during-house-of-the-dragon-e7-s3-20260727205600940\", \"description\":\"Episode 7 of House of the Dragon Season 3 is scheduled to air on August 2, 2026. \\n\\nThis market will resolve to \\\"Yes\\\" if anyone says the listed term during the specified episode of House of the Dragon. Otherwise, the market will resolve to \\\"No\\\". Terms audible in background music will not be considered toward the resolution of this market, neither will terms said within a \\\"previously on\\\" recap or \\\"next time on\\\" preview segment.\\n\\nIf this episode of House of the Dragon has not been released in its entirety by August 3, 2026, 11:59 PM ET, this market will resolve based on what has been released up to that point. If no episode has been released by this time, or if the release is otherwise definitively cancelled, \\\"-No Qualifying Event-\\\" will resolve to \\\"Yes\\\" and all other brackets will resolve to \\\"No\\\".\\n\\nThe resolution source for this market will be the initial release of the named episode of House of the Dragon. Reruns, re-releases, or transcripts which differ from the initially released episode will not be considered.\\n\\nFor full rules, see: https://polymarket-upload.s3.us-east-2.amazonaws.com/market_products/Event+Mentions+Contract+DeFi.pdf\", \"assets_ids\":[\"108062157697286015622577469023612672353592876674616452087163180572487677591037\", \"56057232265226431967967218399897950548398905217954763659783014333347417342313\"], \"outcomes\":[\"Yes\", \"No\"], \"event_message\":{\"id\":\"758896\", \"ticker\":\"what-will-be-said-during-the-seventh-episode-of-house-of-the-dragon-season-3-20260727205600937\", \"slug\":\"what-will-be-said-during-the-seventh-episode-of-house-of-the-dragon-season-3-20260727205600937\", \"title\":\"What will be said during the seventh episode of House of the Dragon: Season 3?\", \"description\":\"Episode 7 of House of the Dragon Season 3 is scheduled to air on August 2, 2026. \\n\\nThis market will resolve to \\\"Yes\\\" if anyone says the listed term during the specified episode of House of the Dragon. Otherwise, the market will resolve to \\\"No\\\". Terms audible in background music will not be considered toward the resolution of this market, neither will terms said within a \\\"previously on\\\" recap or \\\"next time on\\\" preview segment.\\n\\nIf this episode of House of the Dragon has not been released in its entirety by August 3, 2026, 11:59 PM ET, this market will resolve based on what has been released up to that point. If no episode has been released by this time, or if the release is otherwise definitively cancelled, \\\"-No Qualifying Event-\\\" will resolve to \\\"Yes\\\" and all other brackets will resolve to \\\"No\\\".\\n\\nThe resolution source for this market will be the initial release of the named episode of House of the Dragon. Reruns, re-releases, or transcripts which differ from the initially released episode will not be considered.\\n\\nFor full rules, see: https://polymarket-upload.s3.us-east-2.amazonaws.com/market_products/Event+Mentions+Contract+DeFi.pdf\"}, \"timestamp\":\"1785204577532\", \"event_type\":\"new_market\", \"tags\":[], \"condition_id\":\"0xd067f308ce079cb36142aa0079a087a47f8cba2adeb2e153935aa134ef7bf3fa\", \"active\":false, \"clob_token_ids\":[\"108062157697286015622577469023612672353592876674616452087163180572487677591037\", \"56057232265226431967967218399897950548398905217954763659783014333347417342313\"], \"sports_market_type\":\"\", \"line\":\"\", \"game_start_time\":\"\", \"order_price_min_tick_size\":\"0.01\", \"group_item_title\":\"Queen 10+ times\", \"taker_base_fee\":\"1000\", \"fees_enabled\":true, \"fee_schedule\":{\"exponent\":\"1\", \"rate\":\"0.04\", \"taker_only\":true, \"rebate_rate\":\"0.25\"}}","received_at":"2026-07-28T02:09:37.433212Z","schema_version":"clob-market-ws.new_market.v1","sequence":null,"server_hash":null,"server_timestamp":"1785204577532","session_id":"d2757dd6dad94f3b9fe67e8dbf1adc37","source":"clob_market_ws"},"received_at":"2026-07-28T02:09:37.433212Z","record_id":"1db0aa2b74d33d5f657c5e727f334b22fb3712138ad1b72a81de1b0219b64980","schema_fingerprint":"6639a822a7b79cfa4c3fc0044066e4f66ba8611f5bf361772bd6902a2319b82d","schema_version":"edge-lab-recorder.raw.v1","sequence":null,"source":"clob_market_ws"}
{"event_at":"2026-07-28T02:09:37.571000Z","event_fingerprint":"e375a849444571a32bdc6c4432383e2e24d0ae5cc323317017320e59459f9cd7","payload":{"connection_id":"5d29200f65794d4d9ab6ef271f045a9b","event_at":"2026-07-28T02:09:37.571000Z","event_type":"price_change","frame_hash":"4f66bc406b66b57aaece8fe69d47146da44318c3ed21f936493f7f723bf02dc1","frame_index":0,"kind":"data","monotonic_ns":306560466522916,"payload":{"event_type":"price_change","market":"0xda6f0e0e93fc8469e0159a166028d017bddbc162b86f66bac90391379603d962","price_changes":[{"asset_id":"39272994714739463168905443499424551362424437245880253267329605556587274644733","best_ask":"0.36","best_bid":"0.35","hash":"d9f2bb9652f7a1aef5cc832968f7d52e8256642d","price":"0.18","side":"BUY","size":"117.3"},{"asset_id":"20893381255801015515826997628594359667013752732428989472914000440642900266717","best_ask":"0.65","best_bid":"0.64","hash":"2c4249997a29fdbb0032c0806b0386a51e175310","price":"0.82","side":"SELL","size":"117.3"}],"timestamp":"1785204577571"},"payload_hash":"98d262b36e68da97e67ece1ef9d706badbadb82a4003874f47f58d61de7dd5ba","raw_frame":"{\"market\":\"0xda6f0e0e93fc8469e0159a166028d017bddbc162b86f66bac90391379603d962\", \"price_changes\":[{\"asset_id\":\"39272994714739463168905443499424551362424437245880253267329605556587274644733\", \"price\":\"0.18\", \"size\":\"117.3\", \"side\":\"BUY\", \"hash\":\"d9f2bb9652f7a1aef5cc832968f7d52e8256642d\", \"best_bid\":\"0.35\", \"best_ask\":\"0.36\"}, {\"asset_id\":\"20893381255801015515826997628594359667013752732428989472914000440642900266717\", \"price\":\"0.82\", \"size\":\"117.3\", \"side\":\"SELL\", \"hash\":\"2c4249997a29fdbb0032c0806b0386a51e175310\", \"best_bid\":\"0.64\", \"best_ask\":\"0.65\"}], \"timestamp\":\"1785204577571\", \"event_type\":\"price_change\"}","received_at":"2026-07-28T02:09:37.457748Z","schema_version":"clob-market-ws.price_change.v1","sequence":null,"server_hash":null,"server_timestamp":"1785204577571","session_id":"d2757dd6dad94f3b9fe67e8dbf1adc37","source":"clob_market_ws"},"received_at":"2026-07-28T02:09:37.457748Z","record_id":"8ac2ee315b649feeadfa8697fc40b3b911efec533b264ec75e4072db7a98081f","schema_fingerprint":"4aa3821a28b0b7c2400bc59aba4bcc0a76e971dadd19610d3ad38c768e124dc7","schema_version":"edge-lab-recorder.raw.v1","sequence":null,"source":"clob_market_ws"}
{"event_at":"2026-07-28T02:09:37.571000Z","event_fingerprint":"4d3c03f13cb6475fb2df2e94e62d2bfa831b20ff9f820f2ae79c9678173330d7","payload":{"connection_id":"5d29200f65794d4d9ab6ef271f045a9b","event_at":"2026-07-28T02:09:37.571000Z","event_type":"price_change","frame_hash":"3c796d62385183767c18595d502e805897922199434be9c946d9d75303486991","frame_index":0,"kind":"data","monotonic_ns":306560468136875,"payload":{"event_type":"price_change","market":"0xda6f0e0e93fc8469e0159a166028d017bddbc162b86f66bac90391379603d962","price_changes":[{"asset_id":"20893381255801015515826997628594359667013752732428989472914000440642900266717","best_ask":"0.65","best_bid":"0.64","hash":"bf739f1bbd9f744086ad7dc9e8301ea8dca50e7a","price":"0.63","side":"BUY","size":"153.2"},{"asset_id":"39272994714739463168905443499424551362424437245880253267329605556587274644733","best_ask":"0.36","best_bid":"0.35","hash":"a70c53a1a0c6b1e7e183f8a1c7597aaefd55a462","price":"0.37","side":"SELL","size":"153.2"}],"timestamp":"1785204577571"},"payload_hash":"da8683f53fc777032e5dbfa1eb78d825b637af0cecc76ae75bdeb3377fc5aec7","raw_frame":"{\"market\":\"0xda6f0e0e93fc8469e0159a166028d017bddbc162b86f66bac90391379603d962\", \"price_changes\":[{\"asset_id\":\"20893381255801015515826997628594359667013752732428989472914000440642900266717\", \"price\":\"0.63\", \"size\":\"153.2\", \"side\":\"BUY\", \"hash\":\"bf739f1bbd9f744086ad7dc9e8301ea8dca50e7a\", \"best_bid\":\"0.64\", \"best_ask\":\"0.65\"}, {\"asset_id\":\"39272994714739463168905443499424551362424437245880253267329605556587274644733\", \"price\":\"0.37\", \"size\":\"153.2\", \"side\":\"SELL\", \"hash\":\"a70c53a1a0c6b1e7e183f8a1c7597aaefd55a462\", \"best_bid\":\"0.35\", \"best_ask\":\"0.36\"}], \"timestamp\":\"1785204577571\", \"event_type\":\"price_change\"}","received_at":"2026-07-28T02:09:37.459362Z","schema_version":"clob-market-ws.price_change.v1","sequence":null,"server_hash":null,"server_timestamp":"1785204577571","session_id":"d2757dd6dad94f3b9fe67e8dbf1adc37","source":"clob_market_ws"},"received_at":"2026-07-28T02:09:37.459362Z","record_id":"80647146bacbcfac449c671590e3b42f56fc9226c50ff6793e9896dfa6bba464","schema_fingerprint":"4aa3821a28b0b7c2400bc59aba4bcc0a76e971dadd19610d3ad38c768e124dc7","schema_version":"edge-lab-recorder.raw.v1","sequence":null,"source":"clob_market_ws"}
{"event_at":"2026-07-28T02:09:37.579000Z","event_fingerprint":"fba7e82914e2f890938cfbb5a9cd9bcf66126bb539e7b4bb9eb82d9acddd111f","payload":{"connection_id":"5d29200f65794d4d9ab6ef271f045a9b","event_at":"2026-07-28T02:09:37.579000Z","event_type":"price_change","frame_hash":"2cd4526dc176391dcc4c3ac88a7ed01db81c6c190e734684b7e12fc68369247d","frame_index":0,"kind":"data","monotonic_ns":306560474797208,"payload":{"event_type":"price_change","market":"0xda6f0e0e93fc8469e0159a166028d017bddbc162b86f66bac90391379603d962","price_changes":[{"asset_id":"20893381255801015515826997628594359667013752732428989472914000440642900266717","best_ask":"0.65","best_bid":"0.64","hash":"1311ada3a72f4f1736cfec17302854ce4bcafcfe","price":"0.04","side":"BUY","size":"662.09"},{"asset_id":"39272994714739463168905443499424551362424437245880253267329605556587274644733","best_ask":"0.36","best_bid":"0.35","hash":"d31479420a6a9746430bee26b4ae54df285ebcbd","price":"0.96","side":"SELL","size":"662.09"}],"timestamp":"1785204577579"},"payload_hash":"557a712517af64b069e6f65fea9e876bb72262fba19afbf9a757c95868297f6f","raw_frame":"{\"market\":\"0xda6f0e0e93fc8469e0159a166028d017bddbc162b86f66bac90391379603d962\", \"price_changes\":[{\"asset_id\":\"20893381255801015515826997628594359667013752732428989472914000440642900266717\", \"price\":\"0.04\", \"size\":\"662.09\", \"side\":\"BUY\", \"hash\":\"1311ada3a72f4f1736cfec17302854ce4bcafcfe\", \"best_bid\":\"0.64\", \"best_ask\":\"0.65\"}, {\"asset_id\":\"39272994714739463168905443499424551362424437245880253267329605556587274644733\", \"price\":\"0.96\", \"size\":\"662.09\", \"side\":\"SELL\", \"hash\":\"d31479420a6a9746430bee26b4ae54df285ebcbd\", \"best_bid\":\"0.35\", \"best_ask\":\"0.36\"}], \"timestamp\":\"1785204577579\", \"event_type\":\"price_change\"}","received_at":"2026-07-28T02:09:37.466022Z","schema_version":"clob-market-ws.price_change.v1","sequence":null,"server_hash":null,"server_timestamp":"1785204577579","session_id":"d2757dd6dad94f3b9fe67e8dbf1adc37","source":"clob_market_ws"},"received_at":"2026-07-28T02:09:37.466022Z","record_id":"463562b36840ad3ce03627e52f64e0ffadf5d574bbb38d60c0870dd67b56930d","schema_fingerprint":"4aa3821a28b0b7c2400bc59aba4bcc0a76e971dadd19610d3ad38c768e124dc7","schema_version":"edge-lab-recorder.raw.v1","sequence":null,"source":"clob_market_ws"}
{"event_at":"2026-07-28T02:09:37.684000Z","event_fingerprint":"df0dd8a2f010001e1c444d64caeed82559925031475b3e2c57b3f2cffa0d4e43","payload":{"connection_id":"5d29200f65794d4d9ab6ef271f045a9b","event_at":"2026-07-28T02:09:37.684000Z","event_type":"price_change","frame_hash":"c9a410ee4a04f282a36b26eeb0056735a985971389dabfd65f88927d4954b6bf","frame_index":0,"kind":"data","monotonic_ns":306560592672583,"payload":{"event_type":"price_change","market":"0xda6f0e0e93fc8469e0159a166028d017bddbc162b86f66bac90391379603d962","price_changes":[{"asset_id":"20893381255801015515826997628594359667013752732428989472914000440642900266717","best_ask":"0.65","best_bid":"0.64","hash":"e56323af8ddbc88facd6ebabfe1c22e1f8296ad3","price":"0.62","side":"BUY","size":"152.2"},{"asset_id":"39272994714739463168905443499424551362424437245880253267329605556587274644733","best_ask":"0.36","best_bid":"0.35","hash":"1e6aff6d48267a6263adfc7b8fe8538a930c207f","price":"0.38","side":"SELL","size":"152.2"}],"timestamp":"1785204577684"},"payload_hash":"f45964ed6949175a798528649a80473f0756370384bcabf629deef32a497c97d","raw_frame":"{\"market\":\"0xda6f0e0e93fc8469e0159a166028d017bddbc162b86f66bac90391379603d962\", \"price_changes\":[{\"asset_id\":\"20893381255801015515826997628594359667013752732428989472914000440642900266717\", \"price\":\"0.62\", \"size\":\"152.2\", \"side\":\"BUY\", \"hash\":\"e56323af8ddbc88facd6ebabfe1c22e1f8296ad3\", \"best_bid\":\"0.64\", \"best_ask\":\"0.65\"}, {\"asset_id\":\"39272994714739463168905443499424551362424437245880253267329605556587274644733\", \"price\":\"0.38\", \"size\":\"152.2\", \"side\":\"SELL\", \"hash\":\"1e6aff6d48267a6263adfc7b8fe8538a930c207f\", \"best_bid\":\"0.35\", \"best_ask\":\"0.36\"}], \"timestamp\":\"1785204577684\", \"event_type\":\"price_change\"}","received_at":"2026-07-28T02:09:37.583878Z","schema_version":"clob-market-ws.price_change.v1","sequence":null,"server_hash":null,"server_timestamp":"1785204577684","session_id":"d2757dd6dad94f3b9fe67e8dbf1adc37","source":"clob_market_ws"},"received_at":"2026-07-28T02:09:37.583878Z","record_id":"8166f300a55abf7f5d951d8a09470814889ee4a7af04bb249b92c691dfed71b3","schema_fingerprint":"4aa3821a28b0b7c2400bc59aba4bcc0a76e971dadd19610d3ad38c768e124dc7","schema_version":"edge-lab-recorder.raw.v1","sequence":null,"source":"clob_market_ws"}
{"event_at":"2026-07-28T02:09:37.689000Z","event_fingerprint":"86c5b948efe7e05a4947feac80f8c927d74dd2411ff79e427332cebccc7d2191","payload":{"connection_id":"5d29200f65794d4d9ab6ef271f045a9b","event_at":"2026-07-28T02:09:37.689000Z","event_type":"price_change","frame_hash":"0ef075150a96e430d8aa233af97a06afd50019384974405c4c0bab165130564c","frame_index":0,"kind":"data","monotonic_ns":306560595010916,"payload":{"event_type":"price_change","market":"0xda6f0e0e93fc8469e0159a166028d017bddbc162b86f66bac90391379603d962","price_changes":[{"asset_id":"20893381255801015515826997628594359667013752732428989472914000440642900266717","best_ask":"0.65","best_bid":"0.64","hash":"185c6d2aa07844b99859b0db8d4462d105a750f4","price":"0.02","side":"BUY","size":"732.1"},{"asset_id":"39272994714739463168905443499424551362424437245880253267329605556587274644733","best_ask":"0.36","best_bid":"0.35","hash":"d2ed51f5ab85f3dfa21f92a92a8806195b99af73","price":"0.98","side":"SELL","size":"732.1"}],"timestamp":"1785204577689"},"payload_hash":"add0d3118a4c134e73f453afadd5264e3d537c5a40936884efe8a718e746a5a6","raw_frame":"{\"market\":\"0xda6f0e0e93fc8469e0159a166028d017bddbc162b86f66bac90391379603d962\", \"price_changes\":[{\"asset_id\":\"20893381255801015515826997628594359667013752732428989472914000440642900266717\", \"price\":\"0.02\", \"size\":\"732.1\", \"side\":\"BUY\", \"hash\":\"185c6d2aa07844b99859b0db8d4462d105a750f4\", \"best_bid\":\"0.64\", \"best_ask\":\"0.65\"}, {\"asset_id\":\"39272994714739463168905443499424551362424437245880253267329605556587274644733\", \"price\":\"0.98\", \"size\":\"732.1\", \"side\":\"SELL\", \"hash\":\"d2ed51f5ab85f3dfa21f92a92a8806195b99af73\", \"best_bid\":\"0.35\", \"best_ask\":\"0.36\"}], \"timestamp\":\"1785204577689\", \"event_type\":\"price_change\"}","received_at":"2026-07-28T02:09:37.586230Z","schema_version":"clob-market-ws.price_change.v1","sequence":null,"server_hash":null,"server_timestamp":"1785204577689","session_id":"d2757dd6dad94f3b9fe67e8dbf1adc37","source":"clob_market_ws"},"received_at":"2026-07-28T02:09:37.586230Z","record_id":"ae2034e179efafbd017e6ebd3717665a759fae6528f185fca0d3ad0ac337b2ec","schema_fingerprint":"4aa3821a28b0b7c2400bc59aba4bcc0a76e971dadd19610d3ad38c768e124dc7","schema_version":"edge-lab-recorder.raw.v1","sequence":null,"source":"clob_market_ws"}
{"event_at":"2026-07-28T02:09:37.716000Z","event_fingerprint":"ffe4a196d9ebde8d284227e9d891d894eca88bf58c43fb21981e7e8b170e5af3","payload":{"connection_id":"5d29200f65794d4d9ab6ef271f045a9b","event_at":"2026-07-28T02:09:37.716000Z","event_type":"price_change","frame_hash":"2fd57a04597763492c9231d20867044e10814a6af9823132620eda98f9bb5858","frame_index":0,"kind":"data","monotonic_ns":306560621993208,"payload":{"event_type":"price_change","market":"0xda6f0e0e93fc8469e0159a166028d017bddbc162b86f66bac90391379603d962","price_changes":[{"asset_id":"20893381255801015515826997628594359667013752732428989472914000440642900266717","best_ask":"0.65","best_bid":"0.64","hash":"6ece75cbb2aaf6e763a7725836006750fe2d666d","price":"0.01","side":"BUY","size":"5682.02"},{"asset_id":"39272994714739463168905443499424551362424437245880253267329605556587274644733","best_ask":"0.36","best_bid":"0.35","hash":"ef01d4df85988e1946e7acfc708870b95076c6d9","price":"0.99","side":"SELL","size":"5682.02"}],"timestamp":"1785204577716"},"payload_hash":"c8f5352358e922a4ebb9c0a702589aa3ea1367ba40938a074fba7cf4d65347c3","raw_frame":"{\"market\":\"0xda6f0e0e93fc8469e0159a166028d017bddbc162b86f66bac90391379603d962\", \"price_changes\":[{\"asset_id\":\"20893381255801015515826997628594359667013752732428989472914000440642900266717\", \"price\":\"0.01\", \"size\":\"5682.02\", \"side\":\"BUY\", \"hash\":\"6ece75cbb2aaf6e763a7725836006750fe2d666d\", \"best_bid\":\"0.64\", \"best_ask\":\"0.65\"}, {\"asset_id\":\"39272994714739463168905443499424551362424437245880253267329605556587274644733\", \"price\":\"0.99\", \"size\":\"5682.02\", \"side\":\"SELL\", \"hash\":\"ef01d4df85988e1946e7acfc708870b95076c6d9\", \"best_bid\":\"0.35\", \"best_ask\":\"0.36\"}], \"timestamp\":\"1785204577716\", \"event_type\":\"price_change\"}","received_at":"2026-07-28T02:09:37.613217Z","schema_version":"clob-market-ws.price_change.v1","sequence":null,"server_hash":null,"server_timestamp":"1785204577716","session_id":"d2757dd6dad94f3b9fe67e8dbf1adc37","source":"clob_market_ws"},"received_at":"2026-07-28T02:09:37.613217Z","record_id":"573fb6818c28232ab09067cb7e577f8e0848a5313278523db5a2720cde7f7375","schema_fingerprint":"4aa3821a28b0b7c2400bc59aba4bcc0a76e971dadd19610d3ad38c768e124dc7","schema_version":"edge-lab-recorder.raw.v1","sequence":null,"source":"clob_market_ws"}
{"event_at":"2026-07-28T02:09:37.732000Z","event_fingerprint":"7a587c9c459acb012060fa5a128c822eef6c5f8253a268b6609def71a602d985","payload":{"connection_id":"5d29200f65794d4d9ab6ef271f045a9b","event_at":"2026-07-28T02:09:37.732000Z","event_type":"price_change","frame_hash":"44d1ae094ed1d963d9336553df452bd91b282d283c43950699ff06a24a0ee89e","frame_index":0,"kind":"data","monotonic_ns":306560629137000,"payload":{"event_type":"price_change","market":"0xda6f0e0e93fc8469e0159a166028d017bddbc162b86f66bac90391379603d962","price_changes":[{"asset_id":"20893381255801015515826997628594359667013752732428989472914000440642900266717","best_ask":"0.65","best_bid":"0.64","hash":"933d39e2f51e20b46ce7b0b31505487d4fc1d3d9","price":"0.01","side":"BUY","size":"5677.02"},{"asset_id":"39272994714739463168905443499424551362424437245880253267329605556587274644733","best_ask":"0.36","best_bid":"0.35","hash":"d96a0ac568776c6408ab554170076fef6d8c7c37","price":"0.99","side":"SELL","size":"5677.02"}],"timestamp":"1785204577732"},"payload_hash":"845d519f0e9beb3f870c44eeca9da23b5797af0a95d738123e350646a60ab564","raw_frame":"{\"market\":\"0xda6f0e0e93fc8469e0159a166028d017bddbc162b86f66bac90391379603d962\", \"price_changes\":[{\"asset_id\":\"20893381255801015515826997628594359667013752732428989472914000440642900266717\", \"price\":\"0.01\", \"size\":\"5677.02\", \"side\":\"BUY\", \"hash\":\"933d39e2f51e20b46ce7b0b31505487d4fc1d3d9\", \"best_bid\":\"0.64\", \"best_ask\":\"0.65\"}, {\"asset_id\":\"39272994714739463168905443499424551362424437245880253267329605556587274644733\", \"price\":\"0.99\", \"size\":\"5677.02\", \"side\":\"SELL\", \"hash\":\"d96a0ac568776c6408ab554170076fef6d8c7c37\", \"best_bid\":\"0.35\", \"best_ask\":\"0.36\"}], \"timestamp\":\"1785204577732\", \"event_type\":\"price_change\"}","received_at":"2026-07-28T02:09:37.620360Z","schema_version":"clob-market-ws.price_change.v1","sequence":null,"server_hash":null,"server_timestamp":"1785204577732","session_id":"d2757dd6dad94f3b9fe67e8dbf1adc37","source":"clob_market_ws"},"received_at":"2026-07-28T02:09:37.620360Z","record_id":"d6a8a673a0a3d3c1841e0272f7d0a4c7cc5833b45d19411952921cdce42bf649","schema_fingerprint":"4aa3821a28b0b7c2400bc59aba4bcc0a76e971dadd19610d3ad38c768e124dc7","schema_version":"edge-lab-recorder.raw.v1","sequence":null,"source":"clob_market_ws"}
{"event_at":"2026-07-28T02:09:37.742000Z","event_fingerprint":"f17a84fe97ac1d9e131089436be375a028ea482f577db504a4b921298cbaa8a5","payload":{"connection_id":"5d29200f65794d4d9ab6ef271f045a9b","event_at":"2026-07-28T02:09:37.742000Z","event_type":"price_change","frame_hash":"e5ebaab8b374b004a0aba76c3bd2a3ac89a412127746fd25fb369e809c5471ce","frame_index":0,"kind":"data","monotonic_ns":306560641369500,"payload":{"event_type":"price_change","market":"0xda6f0e0e93fc8469e0159a166028d017bddbc162b86f66bac90391379603d962","price_changes":[{"asset_id":"20893381255801015515826997628594359667013752732428989472914000440642900266717","best_ask":"0.65","best_bid":"0.64","hash":"0b1c4553ecd72eece7edc88ee1c7493eb3b2bb2c","price":"0.02","side":"BUY","size":"727.1"},{"asset_id":"39272994714739463168905443499424551362424437245880253267329605556587274644733","best_ask":"0.36","best_bid":"0.35","hash":"aa9622257eb59b872958f8fe6213964ea29d32bf","price":"0.98","side":"SELL","size":"727.1"}],"timestamp":"1785204577742"},"payload_hash":"391038dfb7cdf62e2350c8aac2fd57e75b09641c0ab45195ff9eafbda9a3e70f","raw_frame":"{\"market\":\"0xda6f0e0e93fc8469e0159a166028d017bddbc162b86f66bac90391379603d962\", \"price_changes\":[{\"asset_id\":\"20893381255801015515826997628594359667013752732428989472914000440642900266717\", \"price\":\"0.02\", \"size\":\"727.1\", \"side\":\"BUY\", \"hash\":\"0b1c4553ecd72eece7edc88ee1c7493eb3b2bb2c\", \"best_bid\":\"0.64\", \"best_ask\":\"0.65\"}, {\"asset_id\":\"39272994714739463168905443499424551362424437245880253267329605556587274644733\", \"price\":\"0.98\", \"size\":\"727.1\", \"side\":\"SELL\", \"hash\":\"aa9622257eb59b872958f8fe6213964ea29d32bf\", \"best_bid\":\"0.35\", \"best_ask\":\"0.36\"}], \"timestamp\":\"1785204577742\", \"event_type\":\"price_change\"}","received_at":"2026-07-28T02:09:37.632590Z","schema_version":"clob-market-ws.price_change.v1","sequence":null,"server_hash":null,"server_timestamp":"1785204577742","session_id":"d2757dd6dad94f3b9fe67e8dbf1adc37","source":"clob_market_ws"},"received_at":"2026-07-28T02:09:37.632590Z","record_id":"b78313f4484425b2ad58a0ae2812071cfdeab048fe267f32606466286022630a","schema_fingerprint":"4aa3821a28b0b7c2400bc59aba4bcc0a76e971dadd19610d3ad38c768e124dc7","schema_version":"edge-lab-recorder.raw.v1","sequence":null,"source":"clob_market_ws"}
{"event_at":"2026-07-28T02:09:37.749000Z","event_fingerprint":"598890518a2acb3c4a1bc94b34b8dd70cd4a43a4d03ec82e293fdc85e4722a0f","payload":{"connection_id":"5d29200f65794d4d9ab6ef271f045a9b","event_at":"2026-07-28T02:09:37.749000Z","event_type":"price_change","frame_hash":"a644c2ca310c8568811b973700dfaee742951db3d51dab7f0d71722eb150b871","frame_index":0,"kind":"data","monotonic_ns":306560645495208,"payload":{"event_type":"price_change","market":"0xda6f0e0e93fc8469e0159a166028d017bddbc162b86f66bac90391379603d962","price_changes":[{"asset_id":"39272994714739463168905443499424551362424437245880253267329605556587274644733","best_ask":"0.36","best_bid":"0.35","hash":"735e4e55642adc5e39ecd1dd7821d7451634fb87","price":"0.26","side":"BUY","size":"259.01"},{"asset_id":"20893381255801015515826997628594359667013752732428989472914000440642900266717","best_ask":"0.65","best_bid":"0.64","hash":"0c95e0d462e4f7e9dc37f9bd0d8cfe9324ac5c3a","price":"0.74","side":"SELL","size":"259.01"}],"timestamp":"1785204577749"},"payload_hash":"64d0eaa556de5c6d4935dceb27300ea039b9ee92276dd6e522a7aefb1e0f9b71","raw_frame":"{\"market\":\"0xda6f0e0e93fc8469e0159a166028d017bddbc162b86f66bac90391379603d962\", \"price_changes\":[{\"asset_id\":\"39272994714739463168905443499424551362424437245880253267329605556587274644733\", \"price\":\"0.26\", \"size\":\"259.01\", \"side\":\"BUY\", \"hash\":\"735e4e55642adc5e39ecd1dd7821d7451634fb87\", \"best_bid\":\"0.35\", \"best_ask\":\"0.36\"}, {\"asset_id\":\"20893381255801015515826997628594359667013752732428989472914000440642900266717\", \"price\":\"0.74\", \"size\":\"259.01\", \"side\":\"SELL\", \"hash\":\"0c95e0d462e4f7e9dc37f9bd0d8cfe9324ac5c3a\", \"best_bid\":\"0.64\", \"best_ask\":\"0.65\"}], \"timestamp\":\"1785204577749\", \"event_type\":\"price_change\"}","received_at":"2026-07-28T02:09:37.636718Z","schema_version":"clob-market-ws.price_change.v1","sequence":null,"server_hash":null,"server_timestamp":"1785204577749","session_id":"d2757dd6dad94f3b9fe67e8dbf1adc37","source":"clob_market_ws"},"received_at":"2026-07-28T02:09:37.636718Z","record_id":"5546ada7af1df743080164c39383979d4423b59f53e1ae96672429193e1aae9a","schema_fingerprint":"4aa3821a28b0b7c2400bc59aba4bcc0a76e971dadd19610d3ad38c768e124dc7","schema_version":"edge-lab-recorder.raw.v1","sequence":null,"source":"clob_market_ws"}
{"event_at":"2026-07-28T02:09:37.777000Z","event_fingerprint":"4e7a0d907be4b1c92a08c25bb758e8ec5cb08aeda241eaea768c9459cbff0913","payload":{"connection_id":"5d29200f65794d4d9ab6ef271f045a9b","event_at":"2026-07-28T02:09:37.777000Z","event_type":"price_change","frame_hash":"29b43984854637e533d2610ccf39b68fe3c7aff883a05347e94f036e90b3f64f","frame_index":0,"kind":"data","monotonic_ns":306560677155250,"payload":{"event_type":"price_change","market":"0xda6f0e0e93fc8469e0159a166028d017bddbc162b86f66bac90391379603d962","price_changes":[{"asset_id":"39272994714739463168905443499424551362424437245880253267329605556587274644733","best_ask":"0.36","best_bid":"0.35","hash":"8f133fcef6034a9397a88a613224242d39c6cac3","price":"0.28","side":"BUY","size":"165.56"},{"asset_id":"20893381255801015515826997628594359667013752732428989472914000440642900266717","best_ask":"0.65","best_bid":"0.64","hash":"c7b9be2b23b9fe43795c0339e143b3c2fffdc49d","price":"0.72","side":"SELL","size":"165.56"}],"timestamp":"1785204577777"},"payload_hash":"37073fe880fc28218a5d01d788cbcb3905c314edb3f03a94c057e8c9d6639758","raw_frame":"{\"market\":\"0xda6f0e0e93fc8469e0159a166028d017bddbc162b86f66bac90391379603d962\", \"price_changes\":[{\"asset_id\":\"39272994714739463168905443499424551362424437245880253267329605556587274644733\", \"price\":\"0.28\", \"size\":\"165.56\", \"side\":\"BUY\", \"hash\":\"8f133fcef6034a9397a88a613224242d39c6cac3\", \"best_bid\":\"0.35\", \"best_ask\":\"0.36\"}, {\"asset_id\":\"20893381255801015515826997628594359667013752732428989472914000440642900266717\", \"price\":\"0.72\", \"size\":\"165.56\", \"side\":\"SELL\", \"hash\":\"c7b9be2b23b9fe43795c0339e143b3c2fffdc49d\", \"best_bid\":\"0.64\", \"best_ask\":\"0.65\"}], \"timestamp\":\"1785204577777\", \"event_type\":\"price_change\"}","received_at":"2026-07-28T02:09:37.668377Z","schema_version":"clob-market-ws.price_change.v1","sequence":null,"server_hash":null,"server_timestamp":"1785204577777","session_id":"d2757dd6dad94f3b9fe67e8dbf1adc37","source":"clob_market_ws"},"received_at":"2026-07-28T02:09:37.668377Z","record_id":"e4050dd49690495a1a8927276f3c297fc6c49b3a7024d5db5e821f0b19caa63d","schema_fingerprint":"4aa3821a28b0b7c2400bc59aba4bcc0a76e971dadd19610d3ad38c768e124dc7","schema_version":"edge-lab-recorder.raw.v1","sequence":null,"source":"clob_market_ws"}
{"event_at":"2026-07-28T02:09:37.804000Z","event_fingerprint":"66710d78d7419e4b2c42371fa83d1ca64ac8df291902c0cb3b19f9ab6869bd4a","payload":{"connection_id":"5d29200f65794d4d9ab6ef271f045a9b","event_at":"2026-07-28T02:09:37.804000Z","event_type":"price_change","frame_hash":"d1b814d090448b6c1b4c0f4397b999769e8baedb6bc5d24db9a3e5e1e400450d","frame_index":0,"kind":"data","monotonic_ns":306560698039416,"payload":{"event_type":"price_change","market":"0xda6f0e0e93fc8469e0159a166028d017bddbc162b86f66bac90391379603d962","price_changes":[{"asset_id":"39272994714739463168905443499424551362424437245880253267329605556587274644733","best_ask":"0.36","best_bid":"0.35","hash":"aa382842ee0802691eec4b272403cd9615377d2e","price":"0.28","side":"BUY","size":"150.56"},{"asset_id":"20893381255801015515826997628594359667013752732428989472914000440642900266717","best_ask":"0.65","best_bid":"0.64","hash":"007cc9f6ff195a788c1922154ff8c81bab8fc1c5","price":"0.72","side":"SELL","size":"150.56"}],"timestamp":"1785204577804"},"payload_hash":"5b5245f7f6641fc228193c21dc28c5636cf8c42e188428041f7544cb9f655b9d","raw_frame":"{\"market\":\"0xda6f0e0e93fc8469e0159a166028d017bddbc162b86f66bac90391379603d962\", \"price_changes\":[{\"asset_id\":\"39272994714739463168905443499424551362424437245880253267329605556587274644733\", \"price\":\"0.28\", \"size\":\"150.56\", \"side\":\"BUY\", \"hash\":\"aa382842ee0802691eec4b272403cd9615377d2e\", \"best_bid\":\"0.35\", \"best_ask\":\"0.36\"}, {\"asset_id\":\"20893381255801015515826997628594359667013752732428989472914000440642900266717\", \"price\":\"0.72\", \"size\":\"150.56\", \"side\":\"SELL\", \"hash\":\"007cc9f6ff195a788c1922154ff8c81bab8fc1c5\", \"best_bid\":\"0.64\", \"best_ask\":\"0.65\"}], \"timestamp\":\"1785204577804\", \"event_type\":\"price_change\"}","received_at":"2026-07-28T02:09:37.689261Z","schema_version":"clob-market-ws.price_change.v1","sequence":null,"server_hash":null,"server_timestamp":"1785204577804","session_id":"d2757dd6dad94f3b9fe67e8dbf1adc37","source":"clob_market_ws"},"received_at":"2026-07-28T02:09:37.689261Z","record_id":"04c68473d87bcbe3bf7d28468abf89eea95559db9800e22b36d427150c962278","schema_fingerprint":"4aa3821a28b0b7c2400bc59aba4bcc0a76e971dadd19610d3ad38c768e124dc7","schema_version":"edge-lab-recorder.raw.v1","sequence":null,"source":"clob_market_ws"}
{"event_at":"2026-07-28T02:09:37.812000Z","event_fingerprint":"ac3aed062c00e0e398e3c77eded0b46376cb27cf7fc8734750a3a76f0b13c0c4","payload":{"connection_id":"5d29200f65794d4d9ab6ef271f045a9b","event_at":"2026-07-28T02:09:37.812000Z","event_type":"price_change","frame_hash":"61bdcc72d23d99bd054ec19dcc4b700f14214ddb55ce3f0f2ac9341e702f30cb","frame_index":0,"kind":"data","monotonic_ns":306560707842375,"payload":{"event_type":"price_change","market":"0xda6f0e0e93fc8469e0159a166028d017bddbc162b86f66bac90391379603d962","price_changes":[{"asset_id":"20893381255801015515826997628594359667013752732428989472914000440642900266717","best_ask":"0.65","best_bid":"0.64","hash":"c4e64c2ebf5b661b499fe69c1d006656f4f26f37","price":"0.58","side":"BUY","size":"113"},{"asset_id":"39272994714739463168905443499424551362424437245880253267329605556587274644733","best_ask":"0.36","best_bid":"0.35","hash":"8576551ad93cd75c57402f5e6e72a96e092f75a3","price":"0.42","side":"SELL","size":"113"}],"timestamp":"1785204577812"},"payload_hash":"091806123382248d869c71299815754c24bf59962af83ad1c219280082f9b9e4","raw_frame":"{\"market\":\"0xda6f0e0e93fc8469e0159a166028d017bddbc162b86f66bac90391379603d962\", \"price_changes\":[{\"asset_id\":\"20893381255801015515826997628594359667013752732428989472914000440642900266717\", \"price\":\"0.58\", \"size\":\"113\", \"side\":\"BUY\", \"hash\":\"c4e64c2ebf5b661b499fe69c1d006656f4f26f37\", \"best_bid\":\"0.64\", \"best_ask\":\"0.65\"}, {\"asset_id\":\"39272994714739463168905443499424551362424437245880253267329605556587274644733\", \"price\":\"0.42\", \"size\":\"113\", \"side\":\"SELL\", \"hash\":\"8576551ad93cd75c57402f5e6e72a96e092f75a3\", \"best_bid\":\"0.35\", \"best_ask\":\"0.36\"}], \"timestamp\":\"1785204577812\", \"event_type\":\"price_change\"}","received_at":"2026-07-28T02:09:37.699062Z","schema_version":"clob-market-ws.price_change.v1","sequence":null,"server_hash":null,"server_timestamp":"1785204577812","session_id":"d2757dd6dad94f3b9fe67e8dbf1adc37","source":"clob_market_ws"},"received_at":"2026-07-28T02:09:37.699062Z","record_id":"2990749fba8fca2f5ae088f5b14b1af5b9347c573db062e7e19fca175419eddc","schema_fingerprint":"4aa3821a28b0b7c2400bc59aba4bcc0a76e971dadd19610d3ad38c768e124dc7","schema_version":"edge-lab-recorder.raw.v1","sequence":null,"source":"clob_market_ws"}
{"event_at":"2026-07-28T02:09:37.820000Z","event_fingerprint":"ef5f4fe4dd8f04ac9c13876532cf82a4d789873ed6cfc877acc517b4ec582375","payload":{"connection_id":"5d29200f65794d4d9ab6ef271f045a9b","event_at":"2026-07-28T02:09:37.820000Z","event_type":"price_change","frame_hash":"97a9063b6e8db5682ec1d2c6aed23df28813cc050917923ce99ee40604257b9e","frame_index":0,"kind":"data","monotonic_ns":306560724113125,"payload":{"event_type":"price_change","market":"0xda6f0e0e93fc8469e0159a166028d017bddbc162b86f66bac90391379603d962","price_changes":[{"asset_id":"20893381255801015515826997628594359667013752732428989472914000440642900266717","best_ask":"0.65","best_bid":"0.64","hash":"8dd59a2a1709ea5afe52bf89e5f83617746bab57","price":"0.62","side":"BUY","size":"164.71"},{"asset_id":"39272994714739463168905443499424551362424437245880253267329605556587274644733","best_ask":"0.36","best_bid":"0.35","hash":"52a4c02c912c12efcfa8ef041fab9ca0080ce097","price":"0.38","side":"SELL","size":"164.71"}],"timestamp":"1785204577820"},"payload_hash":"4345ed636f7a407c12f5e7a2135b7aa9b9f960a11e133bd6de49fb2ac7b475aa","raw_frame":"{\"market\":\"0xda6f0e0e93fc8469e0159a166028d017bddbc162b86f66bac90391379603d962\", \"price_changes\":[{\"asset_id\":\"20893381255801015515826997628594359667013752732428989472914000440642900266717\", \"price\":\"0.62\", \"size\":\"164.71\", \"side\":\"BUY\", \"hash\":\"8dd59a2a1709ea5afe52bf89e5f83617746bab57\", \"best_bid\":\"0.64\", \"best_ask\":\"0.65\"}, {\"asset_id\":\"39272994714739463168905443499424551362424437245880253267329605556587274644733\", \"price\":\"0.38\", \"size\":\"164.71\", \"side\":\"SELL\", \"hash\":\"52a4c02c912c12efcfa8ef041fab9ca0080ce097\", \"best_bid\":\"0.35\", \"best_ask\":\"0.36\"}], \"timestamp\":\"1785204577820\", \"event_type\":\"price_change\"}","received_at":"2026-07-28T02:09:37.715338Z","schema_version":"clob-market-ws.price_change.v1","sequence":null,"server_hash":null,"server_timestamp":"1785204577820","session_id":"d2757dd6dad94f3b9fe67e8dbf1adc37","source":"clob_market_ws"},"received_at":"2026-07-28T02:09:37.715338Z","record_id":"89012251497c7bedb1c348fc5c602aa8fd760c4448a74ce75823cff7b3783b48","schema_fingerprint":"4aa3821a28b0b7c2400bc59aba4bcc0a76e971dadd19610d3ad38c768e124dc7","schema_version":"edge-lab-recorder.raw.v1","sequence":null,"source":"clob_market_ws"}
{"event_at":"2026-07-28T02:09:37.830000Z","event_fingerprint":"efe068fe8395ffb33100638192386717f1fdbac72fedefb0f9db59a8428530e4","payload":{"connection_id":"5d29200f65794d4d9ab6ef271f045a9b","event_at":"2026-07-28T02:09:37.830000Z","event_type":"price_change","frame_hash":"fdd06ece19eb7d87cd08201370889bb699af8cf4b4eec1457e404efdf48da48b","frame_index":0,"kind":"data","monotonic_ns":306560738405708,"payload":{"event_type":"price_change","market":"0xda6f0e0e93fc8469e0159a166028d017bddbc162b86f66bac90391379603d962","price_changes":[{"asset_id":"20893381255801015515826997628594359667013752732428989472914000440642900266717","best_ask":"0.65","best_bid":"0.64","hash":"9c558d365618011f765c3563cd01f4b5a2132aad","price":"0.02","side":"BUY","size":"732.1"},{"asset_id":"39272994714739463168905443499424551362424437245880253267329605556587274644733","best_ask":"0.36","best_bid":"0.35","hash":"3777dd04089f74a0733a3e9ab1fcc4fa455b21ab","price":"0.98","side":"SELL","size":"732.1"}],"timestamp":"1785204577830"},"payload_hash":"f03df83e0e4592bb298a9bb226fb1f523fa26534d7248d34cb502c7b3f676d6d","raw_frame":"{\"market\":\"0xda6f0e0e93fc8469e0159a166028d017bddbc162b86f66bac90391379603d962\", \"price_changes\":[{\"asset_id\":\"20893381255801015515826997628594359667013752732428989472914000440642900266717\", \"price\":\"0.02\", \"size\":\"732.1\", \"side\":\"BUY\", \"hash\":\"9c558d365618011f765c3563cd01f4b5a2132aad\", \"best_bid\":\"0.64\", \"best_ask\":\"0.65\"}, {\"asset_id\":\"39272994714739463168905443499424551362424437245880253267329605556587274644733\", \"price\":\"0.98\", \"size\":\"732.1\", \"side\":\"SELL\", \"hash\":\"3777dd04089f74a0733a3e9ab1fcc4fa455b21ab\", \"best_bid\":\"0.35\", \"best_ask\":\"0.36\"}], \"timestamp\":\"1785204577830\", \"event_type\":\"price_change\"}","received_at":"2026-07-28T02:09:37.729627Z","schema_version":"clob-market-ws.price_change.v1","sequence":null,"server_hash":null,"server_timestamp":"1785204577830","session_id":"d2757dd6dad94f3b9fe67e8dbf1adc37","source":"clob_market_ws"},"received_at":"2026-07-28T02:09:37.729627Z","record_id":"111e39a368fffa9decf99abff40a4596ec9e0a9edd56c8986c4653cf5c8f107a","schema_fingerprint":"4aa3821a28b0b7c2400bc59aba4bcc0a76e971dadd19610d3ad38c768e124dc7","schema_version":"edge-lab-recorder.raw.v1","sequence":null,"source":"clob_market_ws"}
