{"event_at":"2026-07-28T02:04:47.718000Z","event_fingerprint":"6b654f44e51b42c2ea469448fe6c7315e7b09f84a1011cdbd4ea9f26026cc269","payload":{"connection_id":"5d29200f65794d4d9ab6ef271f045a9b","event_at":"2026-07-28T02:04:47.718000Z","event_type":"price_change","frame_hash":"6ef8035df1aa8cf30ebbd5bc6b8baf50855632caa084153b37be80e30beacd96","frame_index":0,"kind":"data","monotonic_ns":306291052694958,"payload":{"event_type":"price_change","market":"0xda6f0e0e93fc8469e0159a166028d017bddbc162b86f66bac90391379603d962","price_changes":[{"asset_id":"20893381255801015515826997628594359667013752732428989472914000440642900266717","best_ask":"0.27","best_bid":"0.26","hash":"1b800a7a6f46d8ee5cd89fb57055b7c9020e9b70","price":"0.21","side":"BUY","size":"100.75"},{"asset_id":"39272994714739463168905443499424551362424437245880253267329605556587274644733","best_ask":"0.74","best_bid":"0.73","hash":"002e228f2293e3d72eb02f09423bbf9c84c64823","price":"0.79","side":"SELL","size":"100.75"}],"timestamp":"1785204287718"},"payload_hash":"0daf91cf2edae35a0d637e354f3c811afea1921f2ae947b119e61ef3afb1d095","raw_frame":"{\"market\":\"0xda6f0e0e93fc8469e0159a166028d017bddbc162b86f66bac90391379603d962\", \"price_changes\":[{\"asset_id\":\"20893381255801015515826997628594359667013752732428989472914000440642900266717\", \"price\":\"0.21\", \"size\":\"100.75\", \"side\":\"BUY\", \"hash\":\"1b800a7a6f46d8ee5cd89fb57055b7c9020e9b70\", \"best_bid\":\"0.26\", \"best_ask\":\"0.27\"}, {\"asset_id\":\"39272994714739463168905443499424551362424437245880253267329605556587274644733\", \"price\":\"0.79\", \"size\":\"100.75\", \"side\":\"SELL\", \"hash\":\"002e228f2293e3d72eb02f09423bbf9c84c64823\", \"best_bid\":\"0.73\", \"best_ask\":\"0.74\"}], \"timestamp\":\"1785204287718\", \"event_type\":\"price_change\"}","received_at":"2026-07-28T02:05:08.046596Z","schema_version":"clob-market-ws.price_change.v1","sequence":null,"server_hash":null,"server_timestamp":"1785204287718","session_id":"d2757dd6dad94f3b9fe67e8dbf1adc37","source":"clob_market_ws"},"received_at":"2026-07-28T02:05:08.046596Z","record_id":"50ba330c7bd11690d1dd90890a1cca99052e0c0972147da8cf026718e3081c0a","schema_fingerprint":"4aa3821a28b0b7c2400bc59aba4bcc0a76e971dadd19610d3ad38c768e124dc7","schema_version":"edge-lab-recorder.raw.v1","sequence":null,"source":"clob_market_ws"}
{"event_at":"2026-07-28T02:04:47.719000Z","event_fingerprint":"16eebd71d713bd82d6f44b250ebe53eadaabf16c8b64aa31aa36c029fb073e86","payload":{"connection_id":"5d29200f65794d4d9ab6ef271f045a9b","event_at":"2026-07-28T02:04:47.719000Z","event_type":"price_change","frame_hash":"54079b4b52036e9051b755919bb59a8a52d056dd9ef5a19f4b875f9320d2f012","frame_index":0,"kind":"data","monotonic_ns":306291067422208,"payload":{"event_type":"price_change","market":"0xda6f0e0e93fc8469e0159a166028d017bddbc162b86f66bac90391379603d962","price_changes":[{"asset_id":"39272994714739463168905443499424551362424437245880253267329605556587274644733","best_ask":"0.74","best_bid":"0.73","hash":"1235b658b3ce3a4cc03628364be993e7f1e789cd","price":"0.73","side":"BUY","size":"71"},{"asset_id":"20893381255801015515826997628594359667013752732428989472914000440642900266717","best_ask":"0.27","best_bid":"0.26","hash":"89de8ef77769a97a971141a0259050128e6173c7","price":"0.27","side":"SELL","size":"71"}],"timestamp":"1785204287719"},"payload_hash":"e88423ae5d34eb27057ca3437e33d399b7cbf5e0e61359f21bf8f487e7af6df3","raw_frame":"{\"market\":\"0xda6f0e0e93fc8469e0159a166028d017bddbc162b86f66bac90391379603d962\", \"price_changes\":[{\"asset_id\":\"39272994714739463168905443499424551362424437245880253267329605556587274644733\", \"price\":\"0.73\", \"size\":\"71\", \"side\":\"BUY\", \"hash\":\"1235b658b3ce3a4cc03628364be993e7f1e789cd\", \"best_bid\":\"0.73\", \"best_ask\":\"0.74\"}, {\"asset_id\":\"20893381255801015515826997628594359667013752732428989472914000440642900266717\", \"price\":\"0.27\", \"size\":\"71\", \"side\":\"SELL\", \"hash\":\"89de8ef77769a97a971141a0259050128e6173c7\", \"best_bid\":\"0.26\", \"best_ask\":\"0.27\"}], \"timestamp\":\"1785204287719\", \"event_type\":\"price_change\"}","received_at":"2026-07-28T02:05:08.061321Z","schema_version":"clob-market-ws.price_change.v1","sequence":null,"server_hash":null,"server_timestamp":"1785204287719","session_id":"d2757dd6dad94f3b9fe67e8dbf1adc37","source":"clob_market_ws"},"received_at":"2026-07-28T02:05:08.061321Z","record_id":"a43c4a1fd39315ce08edaa13b65ecba093fc82bcb5c62707cdef746b01b944fd","schema_fingerprint":"4aa3821a28b0b7c2400bc59aba4bcc0a76e971dadd19610d3ad38c768e124dc7","schema_version":"edge-lab-recorder.raw.v1","sequence":null,"source":"clob_market_ws"}
{"event_at":"2026-07-28T02:04:47.719000Z","event_fingerprint":"5bebfc8de05195d75b7e6fa63788fff24bb46966e3e78bf8d6c615e47e2dfb3a","payload":{"connection_id":"5d29200f65794d4d9ab6ef271f045a9b","event_at":"2026-07-28T02:04:47.719000Z","event_type":"price_change","frame_hash":"797efcb1dd18d355704f939a08273a1e2c6ba375a6b5d9187141a0eeac995d8b","frame_index":0,"kind":"data","monotonic_ns":306291071441416,"payload":{"event_type":"price_change","market":"0xda6f0e0e93fc8469e0159a166028d017bddbc162b86f66bac90391379603d962","price_changes":[{"asset_id":"20893381255801015515826997628594359667013752732428989472914000440642900266717","best_ask":"0.27","best_bid":"0.26","hash":"98fed9991aae6196565d09ba7bf6867c62b74c3d","price":"0.17","side":"BUY","size":"197.3"},{"asset_id":"39272994714739463168905443499424551362424437245880253267329605556587274644733","best_ask":"0.74","best_bid":"0.73","hash":"649fed4db27b8c7d99ef9062e5b9843e538f95ec","price":"0.83","side":"SELL","size":"197.3"}],"timestamp":"1785204287719"},"payload_hash":"c9455bd71769f26e48fd3181c457a7fc3572bb806bb630c30d6b6bb23e487cca","raw_frame":"{\"market\":\"0xda6f0e0e93fc8469e0159a166028d017bddbc162b86f66bac90391379603d962\", \"price_changes\":[{\"asset_id\":\"20893381255801015515826997628594359667013752732428989472914000440642900266717\", \"price\":\"0.17\", \"size\":\"197.3\", \"side\":\"BUY\", \"hash\":\"98fed9991aae6196565d09ba7bf6867c62b74c3d\", \"best_bid\":\"0.26\", \"best_ask\":\"0.27\"}, {\"asset_id\":\"39272994714739463168905443499424551362424437245880253267329605556587274644733\", \"price\":\"0.83\", \"size\":\"197.3\", \"side\":\"SELL\", \"hash\":\"649fed4db27b8c7d99ef9062e5b9843e538f95ec\", \"best_bid\":\"0.73\", \"best_ask\":\"0.74\"}], \"timestamp\":\"1785204287719\", \"event_type\":\"price_change\"}","received_at":"2026-07-28T02:05:08.065341Z","schema_version":"clob-market-ws.price_change.v1","sequence":null,"server_hash":null,"server_timestamp":"1785204287719","session_id":"d2757dd6dad94f3b9fe67e8dbf1adc37","source":"clob_market_ws"},"received_at":"2026-07-28T02:05:08.065341Z","record_id":"f1b152f3deb9f7c53ff2415dec33eaa18011dfd955a6931b28ed48056a1d93ee","schema_fingerprint":"4aa3821a28b0b7c2400bc59aba4bcc0a76e971dadd19610d3ad38c768e124dc7","schema_version":"edge-lab-recorder.raw.v1","sequence":null,"source":"clob_market_ws"}
{"event_at":"2026-07-28T02:04:47.719000Z","event_fingerprint":"a41bcf4e8f05694814a4b982ad579510e7084096c5f49f487a251a6c56ef14f8","payload":{"connection_id":"5d29200f65794d4d9ab6ef271f045a9b","event_at":"2026-07-28T02:04:47.719000Z","event_type":"price_change","frame_hash":"c06e2d461cec6009ddc0314ef00d13843b3c37eceda382a10fbb0e568eaaf4bb","frame_index":0,"kind":"data","monotonic_ns":306291076207416,"payload":{"event_type":"price_change","market":"0xda6f0e0e93fc8469e0159a166028d017bddbc162b86f66bac90391379603d962","price_changes":[{"asset_id":"39272994714739463168905443499424551362424437245880253267329605556587274644733","best_ask":"0.74","best_bid":"0.73","hash":"636a54bfde3a5ddeacb8db26b4fb9ec89ec334ca","price":"0.73","side":"BUY","size":"54"},{"asset_id":"20893381255801015515826997628594359667013752732428989472914000440642900266717","best_ask":"0.27","best_bid":"0.26","hash":"1518011da0443d9fb7220d80c2db715e9e258a7f","price":"0.27","side":"SELL","size":"54"}],"timestamp":"1785204287719"},"payload_hash":"451ade860d1500c48cdaa1eaed0911eb2801f098a9a9971a893a018e39ed8309","raw_frame":"{\"market\":\"0xda6f0e0e93fc8469e0159a166028d017bddbc162b86f66bac90391379603d962\", \"price_changes\":[{\"asset_id\":\"39272994714739463168905443499424551362424437245880253267329605556587274644733\", \"price\":\"0.73\", \"size\":\"54\", \"side\":\"BUY\", \"hash\":\"636a54bfde3a5ddeacb8db26b4fb9ec89ec334ca\", \"best_bid\":\"0.73\", \"best_ask\":\"0.74\"}, {\"asset_id\":\"20893381255801015515826997628594359667013752732428989472914000440642900266717\", \"price\":\"0.27\", \"size\":\"54\", \"side\":\"SELL\", \"hash\":\"1518011da0443d9fb7220d80c2db715e9e258a7f\", \"best_bid\":\"0.26\", \"best_ask\":\"0.27\"}], \"timestamp\":\"1785204287719\", \"event_type\":\"price_change\"}","received_at":"2026-07-28T02:05:08.070106Z","schema_version":"clob-market-ws.price_change.v1","sequence":null,"server_hash":null,"server_timestamp":"1785204287719","session_id":"d2757dd6dad94f3b9fe67e8dbf1adc37","source":"clob_market_ws"},"received_at":"2026-07-28T02:05:08.070106Z","record_id":"07039e7a53931e7e0bd9e901ce2fd1a2bec23e4ad6e1d7d0661ee5fa6aa82b9a","schema_fingerprint":"4aa3821a28b0b7c2400bc59aba4bcc0a76e971dadd19610d3ad38c768e124dc7","schema_version":"edge-lab-recorder.raw.v1","sequence":null,"source":"clob_market_ws"}
{"event_at":"2026-07-28T02:04:47.720000Z","event_fingerprint":"b8b1f1732c1d8d8765b900d748ea9ca756c3924cd3c3c3e8f29db8c0e74496e8","payload":{"connection_id":"5d29200f65794d4d9ab6ef271f045a9b","event_at":"2026-07-28T02:04:47.720000Z","event_type":"price_change","frame_hash":"cb3cb91c5161a83941c7fcf6c11ef08e6724d7f6f28487780190a7b393b9d261","frame_index":0,"kind":"data","monotonic_ns":306291081863958,"payload":{"event_type":"price_change","market":"0xda6f0e0e93fc8469e0159a166028d017bddbc162b86f66bac90391379603d962","price_changes":[{"asset_id":"39272994714739463168905443499424551362424437245880253267329605556587274644733","best_ask":"0.74","best_bid":"0.73","hash":"f811a7b3dda77b4358dbbadd90af24843bb90411","price":"0.67","side":"BUY","size":"180"},{"asset_id":"20893381255801015515826997628594359667013752732428989472914000440642900266717","best_ask":"0.27","best_bid":"0.26","hash":"68f23c2851377d323156ce6ee5515ab6675db377","price":"0.33","side":"SELL","size":"180"}],"timestamp":"1785204287720"},"payload_hash":"0d7c2764c9126500b4ede5f9349e1dbc949b8577588963e5e01d215dc9a9fc92","raw_frame":"{\"market\":\"0xda6f0e0e93fc8469e0159a166028d017bddbc162b86f66bac90391379603d962\", \"price_changes\":[{\"asset_id\":\"39272994714739463168905443499424551362424437245880253267329605556587274644733\", \"price\":\"0.67\", \"size\":\"180\", \"side\":\"BUY\", \"hash\":\"f811a7b3dda77b4358dbbadd90af24843bb90411\", \"best_bid\":\"0.73\", \"best_ask\":\"0.74\"}, {\"asset_id\":\"20893381255801015515826997628594359667013752732428989472914000440642900266717\", \"price\":\"0.33\", \"size\":\"180\", \"side\":\"SELL\", \"hash\":\"68f23c2851377d323156ce6ee5515ab6675db377\", \"best_bid\":\"0.26\", \"best_ask\":\"0.27\"}], \"timestamp\":\"1785204287720\", \"event_type\":\"price_change\"}","received_at":"2026-07-28T02:05:08.075762Z","schema_version":"clob-market-ws.price_change.v1","sequence":null,"server_hash":null,"server_timestamp":"1785204287720","session_id":"d2757dd6dad94f3b9fe67e8dbf1adc37","source":"clob_market_ws"},"received_at":"2026-07-28T02:05:08.075762Z","record_id":"786f3db1b624ca1cfb593930cf53bd71678fc152f4394422542e8324ead9892e","schema_fingerprint":"4aa3821a28b0b7c2400bc59aba4bcc0a76e971dadd19610d3ad38c768e124dc7","schema_version":"edge-lab-recorder.raw.v1","sequence":null,"source":"clob_market_ws"}
{"event_at":"2026-07-28T02:04:47.720000Z","event_fingerprint":"8d63c669f62eee8115f7e73d8f4009f1cef8841790e2b78e13ea83d31cc96319","payload":{"connection_id":"5d29200f65794d4d9ab6ef271f045a9b","event_at":"2026-07-28T02:04:47.720000Z","event_type":"price_change","frame_hash":"5896fec6e7e3fe6cfa38a8f1173ce031541a6acea2eb1cfe55ab5981f0902c67","frame_index":0,"kind":"data","monotonic_ns":306291085906791,"payload":{"event_type":"price_change","market":"0xda6f0e0e93fc8469e0159a166028d017bddbc162b86f66bac90391379603d962","price_changes":[{"asset_id":"20893381255801015515826997628594359667013752732428989472914000440642900266717","best_ask":"0.27","best_bid":"0.26","hash":"6eec1e353ababf0fa3ff6ba43fa596c47bd7263c","price":"0.25","side":"BUY","size":"119.2"},{"asset_id":"39272994714739463168905443499424551362424437245880253267329605556587274644733","best_ask":"0.74","best_bid":"0.73","hash":"1dfd211fdf40aff494fa1d4d7b205ac8cbd3e6ea","price":"0.75","side":"SELL","size":"119.2"}],"timestamp":"1785204287720"},"payload_hash":"beae6bf647bcec3e30432fbbdcb8b51f791200cc2625fb2a3d0493966482fa7f","raw_frame":"{\"market\":\"0xda6f0e0e93fc8469e0159a166028d017bddbc162b86f66bac90391379603d962\", \"price_changes\":[{\"asset_id\":\"20893381255801015515826997628594359667013752732428989472914000440642900266717\", \"price\":\"0.25\", \"size\":\"119.2\", \"side\":\"BUY\", \"hash\":\"6eec1e353ababf0fa3ff6ba43fa596c47bd7263c\", \"best_bid\":\"0.26\", \"best_ask\":\"0.27\"}, {\"asset_id\":\"39272994714739463168905443499424551362424437245880253267329605556587274644733\", \"price\":\"0.75\", \"size\":\"119.2\", \"side\":\"SELL\", \"hash\":\"1dfd211fdf40aff494fa1d4d7b205ac8cbd3e6ea\", \"best_bid\":\"0.73\", \"best_ask\":\"0.74\"}], \"timestamp\":\"1785204287720\", \"event_type\":\"price_change\"}","received_at":"2026-07-28T02:05:08.079806Z","schema_version":"clob-market-ws.price_change.v1","sequence":null,"server_hash":null,"server_timestamp":"1785204287720","session_id":"d2757dd6dad94f3b9fe67e8dbf1adc37","source":"clob_market_ws"},"received_at":"2026-07-28T02:05:08.079806Z","record_id":"6b714d52837de69c5375aed923e339f5d11422e0de82027fb470bc38e1e85271","schema_fingerprint":"4aa3821a28b0b7c2400bc59aba4bcc0a76e971dadd19610d3ad38c768e124dc7","schema_version":"edge-lab-recorder.raw.v1","sequence":null,"source":"clob_market_ws"}
{"event_at":"2026-07-28T02:04:47.720000Z","event_fingerprint":"e2b2afc53524ac2c371fff55d5bc8b42acf1a2441b564c5d1b180b3e3268ad4d","payload":{"connection_id":"5d29200f65794d4d9ab6ef271f045a9b","event_at":"2026-07-28T02:04:47.720000Z","event_type":"price_change","frame_hash":"2f3f6c1edc1e9bff38d3d8f4e9eb34f6133100ba96641d2e2ab74e7ef8328c20","frame_index":0,"kind":"data","monotonic_ns":306291089664375,"payload":{"event_type":"price_change","market":"0xda6f0e0e93fc8469e0159a166028d017bddbc162b86f66bac90391379603d962","price_changes":[{"asset_id":"20893381255801015515826997628594359667013752732428989472914000440642900266717","best_ask":"0.27","best_bid":"0.26","hash":"cd61d6b8f1863ee73ab2d2681e78f237409153c8","price":"0.23","side":"BUY","size":"93.2"},{"asset_id":"39272994714739463168905443499424551362424437245880253267329605556587274644733","best_ask":"0.74","best_bid":"0.73","hash":"b57b65873bc08104217ad99515a35dd0aaf0d1cf","price":"0.77","side":"SELL","size":"93.2"}],"timestamp":"1785204287720"},"payload_hash":"a3b7428ab21c0630245e38755026d1c15b27d0254d410cb05b6b7aa49771d198","raw_frame":"{\"market\":\"0xda6f0e0e93fc8469e0159a166028d017bddbc162b86f66bac90391379603d962\", \"price_changes\":[{\"asset_id\":\"20893381255801015515826997628594359667013752732428989472914000440642900266717\", \"price\":\"0.23\", \"size\":\"93.2\", \"side\":\"BUY\", \"hash\":\"cd61d6b8f1863ee73ab2d2681e78f237409153c8\", \"best_bid\":\"0.26\", \"best_ask\":\"0.27\"}, {\"asset_id\":\"39272994714739463168905443499424551362424437245880253267329605556587274644733\", \"price\":\"0.77\", \"size\":\"93.2\", \"side\":\"SELL\", \"hash\":\"b57b65873bc08104217ad99515a35dd0aaf0d1cf\", \"best_bid\":\"0.73\", \"best_ask\":\"0.74\"}], \"timestamp\":\"1785204287720\", \"event_type\":\"price_change\"}","received_at":"2026-07-28T02:05:08.083564Z","schema_version":"clob-market-ws.price_change.v1","sequence":null,"server_hash":null,"server_timestamp":"1785204287720","session_id":"d2757dd6dad94f3b9fe67e8dbf1adc37","source":"clob_market_ws"},"received_at":"2026-07-28T02:05:08.083564Z","record_id":"c3d53207d99a6a839e9da6df3ef215902b061218cb31cd6a005f7548e73cbeca","schema_fingerprint":"4aa3821a28b0b7c2400bc59aba4bcc0a76e971dadd19610d3ad38c768e124dc7","schema_version":"edge-lab-recorder.raw.v1","sequence":null,"source":"clob_market_ws"}
{"event_at":"2026-07-28T02:04:47.721000Z","event_fingerprint":"d03b9abbf396837b38e9f469f27d1664d7f6dda2292fc228a3c74124e353acf7","payload":{"connection_id":"5d29200f65794d4d9ab6ef271f045a9b","event_at":"2026-07-28T02:04:47.721000Z","event_type":"price_change","frame_hash":"1d6160d814aa11cf8369fb2de8d76449e75500791afb93c781886c92b6bf9cf5","frame_index":0,"kind":"data","monotonic_ns":306291093838916,"payload":{"event_type":"price_change","market":"0xda6f0e0e93fc8469e0159a166028d017bddbc162b86f66bac90391379603d962","price_changes":[{"asset_id":"39272994714739463168905443499424551362424437245880253267329605556587274644733","best_ask":"0.74","best_bid":"0.73","hash":"5400714c32b4ddb4fb8fad3c6b227ef71eb5110b","price":"0.01","side":"BUY","size":"5858.02"},{"asset_id":"20893381255801015515826997628594359667013752732428989472914000440642900266717","best_ask":"0.27","best_bid":"0.26","hash":"0c6858481f65802ae17c7b38c883f17b93f69fce","price":"0.99","side":"SELL","size":"5858.02"}],"timestamp":"1785204287721"},"payload_hash":"65b43fd8c44a05bd70a7e5b7c95c05cbae3e806e2e627618a14fb141769b3d67","raw_frame":"{\"market\":\"0xda6f0e0e93fc8469e0159a166028d017bddbc162b86f66bac90391379603d962\", \"price_changes\":[{\"asset_id\":\"39272994714739463168905443499424551362424437245880253267329605556587274644733\", \"price\":\"0.01\", \"size\":\"5858.02\", \"side\":\"BUY\", \"hash\":\"5400714c32b4ddb4fb8fad3c6b227ef71eb5110b\", \"best_bid\":\"0.73\", \"best_ask\":\"0.74\"}, {\"asset_id\":\"20893381255801015515826997628594359667013752732428989472914000440642900266717\", \"price\":\"0.99\", \"size\":\"5858.02\", \"side\":\"SELL\", \"hash\":\"0c6858481f65802ae17c7b38c883f17b93f69fce\", \"best_bid\":\"0.26\", \"best_ask\":\"0.27\"}], \"timestamp\":\"1785204287721\", \"event_type\":\"price_change\"}","received_at":"2026-07-28T02:05:08.087735Z","schema_version":"clob-market-ws.price_change.v1","sequence":null,"server_hash":null,"server_timestamp":"1785204287721","session_id":"d2757dd6dad94f3b9fe67e8dbf1adc37","source":"clob_market_ws"},"received_at":"2026-07-28T02:05:08.087735Z","record_id":"488452ac51f281d559f483728fabb800bbc0bda7ded7fd792344510bfed2be4f","schema_fingerprint":"4aa3821a28b0b7c2400bc59aba4bcc0a76e971dadd19610d3ad38c768e124dc7","schema_version":"edge-lab-recorder.raw.v1","sequence":null,"source":"clob_market_ws"}
{"event_at":"2026-07-28T02:04:47.721000Z","event_fingerprint":"5bd1200c0484fc0791612ea7ececcc19a3801b4279dccefd2ecf98ba65532747","payload":{"connection_id":"5d29200f65794d4d9ab6ef271f045a9b","event_at":"2026-07-28T02:04:47.721000Z","event_type":"price_change","frame_hash":"9281cc7a177ad8956266fb46632f0100e3d25662daeea3a54d74335dceaacde9","frame_index":0,"kind":"data","monotonic_ns":306291099827208,"payload":{"event_type":"price_change","market":"0xda6f0e0e93fc8469e0159a166028d017bddbc162b86f66bac90391379603d962","price_changes":[{"asset_id":"39272994714739463168905443499424551362424437245880253267329605556587274644733","best_ask":"0.74","best_bid":"0.73","hash":"9f4f2a53b8714bbb009e33af06ca86d7a2ef8fb8","price":"0.73","side":"BUY","size":"44"},{"asset_id":"20893381255801015515826997628594359667013752732428989472914000440642900266717","best_ask":"0.27","best_bid":"0.26","hash":"8f3eeeabb576c22c6e2d9bd4aac2781ed3e16484","price":"0.27","side":"SELL","size":"44"}],"timestamp":"1785204287721"},"payload_hash":"dcd631fe05c64a289b9c0dc8bad9cd16a1a947fddb948d50882bfc7576d7eab4","raw_frame":"{\"market\":\"0xda6f0e0e93fc8469e0159a166028d017bddbc162b86f66bac90391379603d962\", \"price_changes\":[{\"asset_id\":\"39272994714739463168905443499424551362424437245880253267329605556587274644733\", \"price\":\"0.73\", \"size\":\"44\", \"side\":\"BUY\", \"hash\":\"9f4f2a53b8714bbb009e33af06ca86d7a2ef8fb8\", \"best_bid\":\"0.73\", \"best_ask\":\"0.74\"}, {\"asset_id\":\"20893381255801015515826997628594359667013752732428989472914000440642900266717\", \"price\":\"0.27\", \"size\":\"44\", \"side\":\"SELL\", \"hash\":\"8f3eeeabb576c22c6e2d9bd4aac2781ed3e16484\", \"best_bid\":\"0.26\", \"best_ask\":\"0.27\"}], \"timestamp\":\"1785204287721\", \"event_type\":\"price_change\"}","received_at":"2026-07-28T02:05:08.093725Z","schema_version":"clob-market-ws.price_change.v1","sequence":null,"server_hash":null,"server_timestamp":"1785204287721","session_id":"d2757dd6dad94f3b9fe67e8dbf1adc37","source":"clob_market_ws"},"received_at":"2026-07-28T02:05:08.093725Z","record_id":"f344b4545ae720d8de5981668671674b1c82746d52495b01b4da920077595941","schema_fingerprint":"4aa3821a28b0b7c2400bc59aba4bcc0a76e971dadd19610d3ad38c768e124dc7","schema_version":"edge-lab-recorder.raw.v1","sequence":null,"source":"clob_market_ws"}
{"event_at":"2026-07-28T02:04:47.722000Z","event_fingerprint":"4a1aa9f8e26b67b3afaaa018346841611119ee57c7cba32fed37b573697c0a48","payload":{"connection_id":"5d29200f65794d4d9ab6ef271f045a9b","event_at":"2026-07-28T02:04:47.722000Z","event_type":"price_change","frame_hash":"aceec633f41a1bd3bceba00a67d965e01f6c891b09736a74427984ff782d510c","frame_index":0,"kind":"data","monotonic_ns":306291104380375,"payload":{"event_type":"price_change","market":"0xda6f0e0e93fc8469e0159a166028d017bddbc162b86f66bac90391379603d962","price_changes":[{"asset_id":"20893381255801015515826997628594359667013752732428989472914000440642900266717","best_ask":"0.27","best_bid":"0.26","hash":"e502d8e6c301e3a82fd661ba9c36531110d22534","price":"0.18","side":"BUY","size":"298.7"},{"asset_id":"39272994714739463168905443499424551362424437245880253267329605556587274644733","best_ask":"0.74","best_bid":"0.73","hash":"e3980ff09acb289586aa112500e2e27044faa7c1","price":"0.82","side":"SELL","size":"298.7"}],"timestamp":"1785204287722"},"payload_hash":"8ae1f3f88c7cb550459753b79e73933f70fb47dd8895f9bfe53b387ecb5cfcbb","raw_frame":"{\"market\":\"0xda6f0e0e93fc8469e0159a166028d017bddbc162b86f66bac90391379603d962\", \"price_changes\":[{\"asset_id\":\"20893381255801015515826997628594359667013752732428989472914000440642900266717\", \"price\":\"0.18\", \"size\":\"298.7\", \"side\":\"BUY\", \"hash\":\"e502d8e6c301e3a82fd661ba9c36531110d22534\", \"best_bid\":\"0.26\", \"best_ask\":\"0.27\"}, {\"asset_id\":\"39272994714739463168905443499424551362424437245880253267329605556587274644733\", \"price\":\"0.82\", \"size\":\"298.7\", \"side\":\"SELL\", \"hash\":\"e3980ff09acb289586aa112500e2e27044faa7c1\", \"best_bid\":\"0.73\", \"best_ask\":\"0.74\"}], \"timestamp\":\"1785204287722\", \"event_type\":\"price_change\"}","received_at":"2026-07-28T02:05:08.098279Z","schema_version":"clob-market-ws.price_change.v1","sequence":null,"server_hash":null,"server_timestamp":"1785204287722","session_id":"d2757dd6dad94f3b9fe67e8dbf1adc37","source":"clob_market_ws"},"received_at":"2026-07-28T02:05:08.098279Z","record_id":"9040c0ab34fa8e7146adb1b0077f8fa6724862f0fc1c71a412feba3c9291a823","schema_fingerprint":"4aa3821a28b0b7c2400bc59aba4bcc0a76e971dadd19610d3ad38c768e124dc7","schema_version":"edge-lab-recorder.raw.v1","sequence":null,"source":"clob_market_ws"}
{"event_at":"2026-07-28T02:04:47.722000Z","event_fingerprint":"f708bcd8d267e2705c101a0a8f36f5cda92061039dcda0e80274bf012571f13e","payload":{"connection_id":"5d29200f65794d4d9ab6ef271f045a9b","event_at":"2026-07-28T02:04:47.722000Z","event_type":"price_change","frame_hash":"05b34de882224f75ed9d170b5fba8cb1694ac684cdb4c5f845c38aacece9b40f","frame_index":0,"kind":"data","monotonic_ns":306291108198666,"payload":{"event_type":"price_change","market":"0xda6f0e0e93fc8469e0159a166028d017bddbc162b86f66bac90391379603d962","price_changes":[{"asset_id":"39272994714739463168905443499424551362424437245880253267329605556587274644733","best_ask":"0.74","best_bid":"0.73","hash":"ce2d0b156765159d844c6fdda73db39447d7feed","price":"0.62","side":"BUY","size":"149"},{"asset_id":"20893381255801015515826997628594359667013752732428989472914000440642900266717","best_ask":"0.27","best_bid":"0.26","hash":"bf5ab787aeebfdb2fd9de77f48d969a51f78427d","price":"0.38","side":"SELL","size":"149"}],"timestamp":"1785204287722"},"payload_hash":"f1427e59ca0bfa813b10e01b229fad428eb641711007196ec5bc4f6c1278d819","raw_frame":"{\"market\":\"0xda6f0e0e93fc8469e0159a166028d017bddbc162b86f66bac90391379603d962\", \"price_changes\":[{\"asset_id\":\"39272994714739463168905443499424551362424437245880253267329605556587274644733\", \"price\":\"0.62\", \"size\":\"149\", \"side\":\"BUY\", \"hash\":\"ce2d0b156765159d844c6fdda73db39447d7feed\", \"best_bid\":\"0.73\", \"best_ask\":\"0.74\"}, {\"asset_id\":\"20893381255801015515826997628594359667013752732428989472914000440642900266717\", \"price\":\"0.38\", \"size\":\"149\", \"side\":\"SELL\", \"hash\":\"bf5ab787aeebfdb2fd9de77f48d969a51f78427d\", \"best_bid\":\"0.26\", \"best_ask\":\"0.27\"}], \"timestamp\":\"1785204287722\", \"event_type\":\"price_change\"}","received_at":"2026-07-28T02:05:08.102098Z","schema_version":"clob-market-ws.price_change.v1","sequence":null,"server_hash":null,"server_timestamp":"1785204287722","session_id":"d2757dd6dad94f3b9fe67e8dbf1adc37","source":"clob_market_ws"},"received_at":"2026-07-28T02:05:08.102098Z","record_id":"d98188236eaaa46cb55b6d182fef13dc4d517955560295ab65ba42e8870e5f19","schema_fingerprint":"4aa3821a28b0b7c2400bc59aba4bcc0a76e971dadd19610d3ad38c768e124dc7","schema_version":"edge-lab-recorder.raw.v1","sequence":null,"source":"clob_market_ws"}
{"event_at":"2026-07-28T02:04:47.722000Z","event_fingerprint":"6572f9b8946a1054ea203d677f3d3259bb3c3cb52573b91e052842a9df7a7504","payload":{"connection_id":"5d29200f65794d4d9ab6ef271f045a9b","event_at":"2026-07-28T02:04:47.722000Z","event_type":"price_change","frame_hash":"95ce4c3cb475d878f2f9b12af443a1901f7e41adc1f10c2ba6c63ccc0087c28e","frame_index":0,"kind":"data","monotonic_ns":306291112881166,"payload":{"event_type":"price_change","market":"0xda6f0e0e93fc8469e0159a166028d017bddbc162b86f66bac90391379603d962","price_changes":[{"asset_id":"39272994714739463168905443499424551362424437245880253267329605556587274644733","best_ask":"0.74","best_bid":"0.73","hash":"98a2365711bbe13e5db52eaccd9ee8c54db96a44","price":"0.7","side":"BUY","size":"121.43"},{"asset_id":"20893381255801015515826997628594359667013752732428989472914000440642900266717","best_ask":"0.27","best_bid":"0.26","hash":"d262df871abff390a2fd3a28834647cd47b7bb85","price":"0.3","side":"SELL","size":"121.43"}],"timestamp":"1785204287722"},"payload_hash":"d2f64f7fa0f08ce85e6c8bbb23b431d670ced0f6fedeac56385c15e07edb5a57","raw_frame":"{\"market\":\"0xda6f0e0e93fc8469e0159a166028d017bddbc162b86f66bac90391379603d962\", \"price_changes\":[{\"asset_id\":\"39272994714739463168905443499424551362424437245880253267329605556587274644733\", \"price\":\"0.7\", \"size\":\"121.43\", \"side\":\"BUY\", \"hash\":\"98a2365711bbe13e5db52eaccd9ee8c54db96a44\", \"best_bid\":\"0.73\", \"best_ask\":\"0.74\"}, {\"asset_id\":\"20893381255801015515826997628594359667013752732428989472914000440642900266717\", \"price\":\"0.3\", \"size\":\"121.43\", \"side\":\"SELL\", \"hash\":\"d262df871abff390a2fd3a28834647cd47b7bb85\", \"best_bid\":\"0.26\", \"best_ask\":\"0.27\"}], \"timestamp\":\"1785204287722\", \"event_type\":\"price_change\"}","received_at":"2026-07-28T02:05:08.106779Z","schema_version":"clob-market-ws.price_change.v1","sequence":null,"server_hash":null,"server_timestamp":"1785204287722","session_id":"d2757dd6dad94f3b9fe67e8dbf1adc37","source":"clob_market_ws"},"received_at":"2026-07-28T02:05:08.106779Z","record_id":"5ef8ab6c8ae6229931efb308d9115183c4ad17cfe1e81220c0cc8cb76fb413f5","schema_fingerprint":"4aa3821a28b0b7c2400bc59aba4bcc0a76e971dadd19610d3ad38c768e124dc7","schema_version":"edge-lab-recorder.raw.v1","sequence":null,"source":"clob_market_ws"}
{"event_at":"2026-07-28T02:04:47.723000Z","event_fingerprint":"87bc8364057cf29bc7d378a9df3e3db32c0f91670d3f970024b5dd92b043f9bd","payload":{"connection_id":"5d29200f65794d4d9ab6ef271f045a9b","event_at":"2026-07-28T02:04:47.723000Z","event_type":"price_change","frame_hash":"166e53588f276155def8515c7bcdb1f9ff437cab93c49e210a7e2431930d61e0","frame_index":0,"kind":"data","monotonic_ns":306291118367375,"payload":{"event_type":"price_change","market":"0xda6f0e0e93fc8469e0159a166028d017bddbc162b86f66bac90391379603d962","price_changes":[{"asset_id":"20893381255801015515826997628594359667013752732428989472914000440642900266717","best_ask":"0.27","best_bid":"0.26","hash":"256172989fd19ffc9ec03fd9b9ebacb7b090a558","price":"0.16","side":"BUY","size":"366.3"},{"asset_id":"39272994714739463168905443499424551362424437245880253267329605556587274644733","best_ask":"0.74","best_bid":"0.73","hash":"c1ec221a7863cea0e48663d40b90e21a5a152db9","price":"0.84","side":"SELL","size":"366.3"}],"timestamp":"1785204287723"},"payload_hash":"19a33c1ab6193782cf2f54996356a3bd0eb6d049b72b403f0a47604aa3b44472","raw_frame":"{\"market\":\"0xda6f0e0e93fc8469e0159a166028d017bddbc162b86f66bac90391379603d962\", \"price_changes\":[{\"asset_id\":\"20893381255801015515826997628594359667013752732428989472914000440642900266717\", \"price\":\"0.16\", \"size\":\"366.3\", \"side\":\"BUY\", \"hash\":\"256172989fd19ffc9ec03fd9b9ebacb7b090a558\", \"best_bid\":\"0.26\", \"best_ask\":\"0.27\"}, {\"asset_id\":\"39272994714739463168905443499424551362424437245880253267329605556587274644733\", \"price\":\"0.84\", \"size\":\"366.3\", \"side\":\"SELL\", \"hash\":\"c1ec221a7863cea0e48663d40b90e21a5a152db9\", \"best_bid\":\"0.73\", \"best_ask\":\"0.74\"}], \"timestamp\":\"1785204287723\", \"event_type\":\"price_change\"}","received_at":"2026-07-28T02:05:08.112264Z","schema_version":"clob-market-ws.price_change.v1","sequence":null,"server_hash":null,"server_timestamp":"1785204287723","session_id":"d2757dd6dad94f3b9fe67e8dbf1adc37","source":"clob_market_ws"},"received_at":"2026-07-28T02:05:08.112264Z","record_id":"fc871f1773cb622713bbf9d519f661066b03ee8f4022f7ee769dc5121d986412","schema_fingerprint":"4aa3821a28b0b7c2400bc59aba4bcc0a76e971dadd19610d3ad38c768e124dc7","schema_version":"edge-lab-recorder.raw.v1","sequence":null,"source":"clob_market_ws"}
{"event_at":"2026-07-28T02:04:47.724000Z","event_fingerprint":"aa60c47a525e4871128a298d62704f02c23a4db8e28cfb43202d0f6c79d9307d","payload":{"connection_id":"5d29200f65794d4d9ab6ef271f045a9b","event_at":"2026-07-28T02:04:47.724000Z","event_type":"price_change","frame_hash":"df1ec7b6c2fb74d7ca80aebc4e0506112de938ed2a8658153f056a692fafaee3","frame_index":0,"kind":"data","monotonic_ns":306291124250083,"payload":{"event_type":"price_change","market":"0xda6f0e0e93fc8469e0159a166028d017bddbc162b86f66bac90391379603d962","price_changes":[{"asset_id":"39272994714739463168905443499424551362424437245880253267329605556587274644733","best_ask":"0.74","best_bid":"0.73","hash":"d8d8ecd3d13ed39d0671021255db188130083e38","price":"0.01","side":"BUY","size":"5863.02"},{"asset_id":"20893381255801015515826997628594359667013752732428989472914000440642900266717","best_ask":"0.27","best_bid":"0.26","hash":"d99b6f43c5742ad8fd4426da0c8ff94f9e18907a","price":"0.99","side":"SELL","size":"5863.02"}],"timestamp":"1785204287724"},"payload_hash":"c6e2921c0600920b80187e71edc0253674418f3e5a4cb19e061f4d13479d4b1b","raw_frame":"{\"market\":\"0xda6f0e0e93fc8469e0159a166028d017bddbc162b86f66bac90391379603d962\", \"price_changes\":[{\"asset_id\":\"39272994714739463168905443499424551362424437245880253267329605556587274644733\", \"price\":\"0.01\", \"size\":\"5863.02\", \"side\":\"BUY\", \"hash\":\"d8d8ecd3d13ed39d0671021255db188130083e38\", \"best_bid\":\"0.73\", \"best_ask\":\"0.74\"}, {\"asset_id\":\"20893381255801015515826997628594359667013752732428989472914000440642900266717\", \"price\":\"0.99\", \"size\":\"5863.02\", \"side\":\"SELL\", \"hash\":\"d99b6f43c5742ad8fd4426da0c8ff94f9e18907a\", \"best_bid\":\"0.26\", \"best_ask\":\"0.27\"}], \"timestamp\":\"1785204287724\", \"event_type\":\"price_change\"}","received_at":"2026-07-28T02:05:08.118148Z","schema_version":"clob-market-ws.price_change.v1","sequence":null,"server_hash":null,"server_timestamp":"1785204287724","session_id":"d2757dd6dad94f3b9fe67e8dbf1adc37","source":"clob_market_ws"},"received_at":"2026-07-28T02:05:08.118148Z","record_id":"6ba98fcaed4e3a686765ba231c7e21f9458eec9cd9d3ef26c7a711a0f00824b2","schema_fingerprint":"4aa3821a28b0b7c2400bc59aba4bcc0a76e971dadd19610d3ad38c768e124dc7","schema_version":"edge-lab-recorder.raw.v1","sequence":null,"source":"clob_market_ws"}
{"event_at":"2026-07-28T02:04:47.725000Z","event_fingerprint":"302e78159285cfb2833e3d4e6cc8df7c09dd5a7cfc53b73e7da9ad6f76a3e999","payload":{"connection_id":"5d29200f65794d4d9ab6ef271f045a9b","event_at":"2026-07-28T02:04:47.725000Z","event_type":"price_change","frame_hash":"8a4bb937c02c8b3feab4c3f4ea39859e878c3d366b1bdda8aefadc6f9dfa6170","frame_index":0,"kind":"data","monotonic_ns":306291128607791,"payload":{"event_type":"price_change","market":"0xda6f0e0e93fc8469e0159a166028d017bddbc162b86f66bac90391379603d962","price_changes":[{"asset_id":"39272994714739463168905443499424551362424437245880253267329605556587274644733","best_ask":"0.74","best_bid":"0.73","hash":"8e70c7baae63bb67ca2b9e09305cab33f151f627","price":"0.72","side":"BUY","size":"81.32"},{"asset_id":"20893381255801015515826997628594359667013752732428989472914000440642900266717","best_ask":"0.27","best_bid":"0.26","hash":"ecca3631bf12f18a637ca1cec2a773aeb41098e5","price":"0.28","side":"SELL","size":"81.32"}],"timestamp":"1785204287725"},"payload_hash":"fab13f24fc5703f8f3302dcb590f3bd617970e0996053a462c6bfc723aef0b42","raw_frame":"{\"market\":\"0xda6f0e0e93fc8469e0159a166028d017bddbc162b86f66bac90391379603d962\", \"price_changes\":[{\"asset_id\":\"39272994714739463168905443499424551362424437245880253267329605556587274644733\", \"price\":\"0.72\", \"size\":\"81.32\", \"side\":\"BUY\", \"hash\":\"8e70c7baae63bb67ca2b9e09305cab33f151f627\", \"best_bid\":\"0.73\", \"best_ask\":\"0.74\"}, {\"asset_id\":\"20893381255801015515826997628594359667013752732428989472914000440642900266717\", \"price\":\"0.28\", \"size\":\"81.32\", \"side\":\"SELL\", \"hash\":\"ecca3631bf12f18a637ca1cec2a773aeb41098e5\", \"best_bid\":\"0.26\", \"best_ask\":\"0.27\"}], \"timestamp\":\"1785204287725\", \"event_type\":\"price_change\"}","received_at":"2026-07-28T02:05:08.122503Z","schema_version":"clob-market-ws.price_change.v1","sequence":null,"server_hash":null,"server_timestamp":"1785204287725","session_id":"d2757dd6dad94f3b9fe67e8dbf1adc37","source":"clob_market_ws"},"received_at":"2026-07-28T02:05:08.122503Z","record_id":"f901f40221bc4ae7dab2c8b808cb7fa831019206ce12c4e3582e075301ca1f8c","schema_fingerprint":"4aa3821a28b0b7c2400bc59aba4bcc0a76e971dadd19610d3ad38c768e124dc7","schema_version":"edge-lab-recorder.raw.v1","sequence":null,"source":"clob_market_ws"}
{"event_at":"2026-07-28T02:04:47.725000Z","event_fingerprint":"722a8f07fe2a615ac63ac42b9037b083cc25c319929f686d9af2df8e685a4d3e","payload":{"connection_id":"5d29200f65794d4d9ab6ef271f045a9b","event_at":"2026-07-28T02:04:47.725000Z","event_type":"price_change","frame_hash":"1a7398b0d2cb65990357fac2708bfb1949eaf0a603785680461ba36fba59e987","frame_index":0,"kind":"data","monotonic_ns":306291134399333,"payload":{"event_type":"price_change","market":"0xda6f0e0e93fc8469e0159a166028d017bddbc162b86f66bac90391379603d962","price_changes":[{"asset_id":"20893381255801015515826997628594359667013752732428989472914000440642900266717","best_ask":"0.27","best_bid":"0.26","hash":"8aa40082298537e201cc1b5d5ab095d67f62103a","price":"0.25","side":"BUY","size":"94.2"},{"asset_id":"39272994714739463168905443499424551362424437245880253267329605556587274644733","best_ask":"0.74","best_bid":"0.73","hash":"8ce35dfb901abd5a89d591df0d95c815baff1e8a","price":"0.75","side":"SELL","size":"94.2"}],"timestamp":"1785204287725"},"payload_hash":"3033d8695ca7e33ffd2c07a75c559283e70971b4bfa9a7829b1fb1c5a81ed781","raw_frame":"{\"market\":\"0xda6f0e0e93fc8469e0159a166028d017bddbc162b86f66bac90391379603d962\", \"price_changes\":[{\"asset_id\":\"20893381255801015515826997628594359667013752732428989472914000440642900266717\", \"price\":\"0.25\", \"size\":\"94.2\", \"side\":\"BUY\", \"hash\":\"8aa40082298537e201cc1b5d5ab095d67f62103a\", \"best_bid\":\"0.26\", \"best_ask\":\"0.27\"}, {\"asset_id\":\"39272994714739463168905443499424551362424437245880253267329605556587274644733\", \"price\":\"0.75\", \"size\":\"94.2\", \"side\":\"SELL\", \"hash\":\"8ce35dfb901abd5a89d591df0d95c815baff1e8a\", \"best_bid\":\"0.73\", \"best_ask\":\"0.74\"}], \"timestamp\":\"1785204287725\", \"event_type\":\"price_change\"}","received_at":"2026-07-28T02:05:08.128298Z","schema_version":"clob-market-ws.price_change.v1","sequence":null,"server_hash":null,"server_timestamp":"1785204287725","session_id":"d2757dd6dad94f3b9fe67e8dbf1adc37","source":"clob_market_ws"},"received_at":"2026-07-28T02:05:08.128298Z","record_id":"7f889f992ca8a5eddfe6298bbad87b96daaa7c128805ab63d75ee152d017f9ef","schema_fingerprint":"4aa3821a28b0b7c2400bc59aba4bcc0a76e971dadd19610d3ad38c768e124dc7","schema_version":"edge-lab-recorder.raw.v1","sequence":null,"source":"clob_market_ws"}
