{"event_at":"2026-07-28T02:13:37.566000Z","event_fingerprint":"388f1d5c0b7410f2fd6aef738c09bd7d6e12c231ec8b0eea8210ee283d8d29cd","payload":{"connection_id":"5d29200f65794d4d9ab6ef271f045a9b","event_at":"2026-07-28T02:13:37.566000Z","event_type":"best_bid_ask","frame_hash":"94461b55f2b6b5c6ad2ae0a38f4b3bd79f9dc6f4ef5d0772b31caa65eb54c2cb","frame_index":0,"kind":"data","monotonic_ns":306800460439916,"payload":{"asset_id":"20893381255801015515826997628594359667013752732428989472914000440642900266717","best_ask":"0.73","best_bid":"0.72","event_type":"best_bid_ask","market":"0xda6f0e0e93fc8469e0159a166028d017bddbc162b86f66bac90391379603d962","spread":"0.01","timestamp":"1785204817566"},"payload_hash":"09925ef07560d5f681b95c7520b8ee1d150d8ad6c0e8d91be3066886fed69cba","raw_frame":"{\"market\":\"0xda6f0e0e93fc8469e0159a166028d017bddbc162b86f66bac90391379603d962\", \"asset_id\":\"20893381255801015515826997628594359667013752732428989472914000440642900266717\", \"best_bid\":\"0.72\", \"best_ask\":\"0.73\", \"spread\":\"0.01\", \"timestamp\":\"1785204817566\", \"event_type\":\"best_bid_ask\"}","received_at":"2026-07-28T02:13:37.449284Z","schema_version":"clob-market-ws.best_bid_ask.v1","sequence":null,"server_hash":null,"server_timestamp":"1785204817566","session_id":"d2757dd6dad94f3b9fe67e8dbf1adc37","source":"clob_market_ws"},"received_at":"2026-07-28T02:13:37.449284Z","record_id":"cd72082c03181e0d1b60777e2a29a5dfc96c591391488a4955e6dd7c528ac19d","schema_fingerprint":"8488399f31b0337811b13b266be932db7062827c2470b78bd8e9e99bab51d17d","schema_version":"edge-lab-recorder.raw.v1","sequence":null,"source":"clob_market_ws"}
{"event_at":"2026-07-28T02:13:37.566000Z","event_fingerprint":"ddf829ae720d8a140eccbe7593a593d845bc961c2707f02320fc669d5d77ecd1","payload":{"connection_id":"5d29200f65794d4d9ab6ef271f045a9b","event_at":"2026-07-28T02:13:37.566000Z","event_type":"best_bid_ask","frame_hash":"53788f675e3251c5dd99b7a601523c71e2085a0bfd9801c27bccb3904d14d53e","frame_index":0,"kind":"data","monotonic_ns":306800462147250,"payload":{"asset_id":"39272994714739463168905443499424551362424437245880253267329605556587274644733","best_ask":"0.28","best_bid":"0.27","event_type":"best_bid_ask","market":"0xda6f0e0e93fc8469e0159a166028d017bddbc162b86f66bac90391379603d962","spread":"0.01","timestamp":"1785204817566"},"payload_hash":"6c7b2bcc294b5e43026e6e8a6a4d26a31de73ff5a8c1e5c92f9b8085334360de","raw_frame":"{\"market\":\"0xda6f0e0e93fc8469e0159a166028d017bddbc162b86f66bac90391379603d962\", \"asset_id\":\"39272994714739463168905443499424551362424437245880253267329605556587274644733\", \"best_bid\":\"0.27\", \"best_ask\":\"0.28\", \"spread\":\"0.01\", \"timestamp\":\"1785204817566\", \"event_type\":\"best_bid_ask\"}","received_at":"2026-07-28T02:13:37.450995Z","schema_version":"clob-market-ws.best_bid_ask.v1","sequence":null,"server_hash":null,"server_timestamp":"1785204817566","session_id":"d2757dd6dad94f3b9fe67e8dbf1adc37","source":"clob_market_ws"},"received_at":"2026-07-28T02:13:37.450995Z","record_id":"068551f25c47224c8ae38fd0d956a4f223401c2c185cf737de5e8241169b38b8","schema_fingerprint":"8488399f31b0337811b13b266be932db7062827c2470b78bd8e9e99bab51d17d","schema_version":"edge-lab-recorder.raw.v1","sequence":null,"source":"clob_market_ws"}
{"event_at":"2026-07-28T02:13:37.566000Z","event_fingerprint":"6f262042e82c97118aa20680f8e4005cae6a18c2d197dcae8ce2dc228a5d3bbb","payload":{"connection_id":"5d29200f65794d4d9ab6ef271f045a9b","event_at":"2026-07-28T02:13:37.566000Z","event_type":"price_change","frame_hash":"fad655c2bc7c0a56b82ebceb4d3648604c58f77eeeaed341ae028b3fa48a0fdf","frame_index":0,"kind":"data","monotonic_ns":306800463216541,"payload":{"event_type":"price_change","market":"0xda6f0e0e93fc8469e0159a166028d017bddbc162b86f66bac90391379603d962","price_changes":[{"asset_id":"39272994714739463168905443499424551362424437245880253267329605556587274644733","best_ask":"0.28","best_bid":"0.27","hash":"38aa78f98604c1fd1b85c98789a07cfda083128c","price":"0.27","side":"BUY","size":"5"},{"asset_id":"20893381255801015515826997628594359667013752732428989472914000440642900266717","best_ask":"0.73","best_bid":"0.72","hash":"dee805944e3aea3d4d0e42d702ffd2c011fe8a4b","price":"0.73","side":"SELL","size":"5"}],"timestamp":"1785204817566"},"payload_hash":"35d41e0dc2448a97be0eb3ef44cdaac9b5684dc2c9bd63fe5c1c30894b57b51b","raw_frame":"{\"market\":\"0xda6f0e0e93fc8469e0159a166028d017bddbc162b86f66bac90391379603d962\", \"price_changes\":[{\"asset_id\":\"39272994714739463168905443499424551362424437245880253267329605556587274644733\", \"price\":\"0.27\", \"size\":\"5\", \"side\":\"BUY\", \"hash\":\"38aa78f98604c1fd1b85c98789a07cfda083128c\", \"best_bid\":\"0.27\", \"best_ask\":\"0.28\"}, {\"asset_id\":\"20893381255801015515826997628594359667013752732428989472914000440642900266717\", \"price\":\"0.73\", \"size\":\"5\", \"side\":\"SELL\", \"hash\":\"dee805944e3aea3d4d0e42d702ffd2c011fe8a4b\", \"best_bid\":\"0.72\", \"best_ask\":\"0.73\"}], \"timestamp\":\"1785204817566\", \"event_type\":\"price_change\"}","received_at":"2026-07-28T02:13:37.452064Z","schema_version":"clob-market-ws.price_change.v1","sequence":null,"server_hash":null,"server_timestamp":"1785204817566","session_id":"d2757dd6dad94f3b9fe67e8dbf1adc37","source":"clob_market_ws"},"received_at":"2026-07-28T02:13:37.452064Z","record_id":"6d77bbff2ef931bcd1e7e6efcb943a4c308b18de00ab2bdd437d8bd5630be590","schema_fingerprint":"4aa3821a28b0b7c2400bc59aba4bcc0a76e971dadd19610d3ad38c768e124dc7","schema_version":"edge-lab-recorder.raw.v1","sequence":null,"source":"clob_market_ws"}
{"event_at":"2026-07-28T02:13:37.580000Z","event_fingerprint":"b93b20261d26492bf22fa4d2028c37ed38144fa5bda9d0ad85ad800223b6e375","payload":{"connection_id":"5d29200f65794d4d9ab6ef271f045a9b","event_at":"2026-07-28T02:13:37.580000Z","event_type":"price_change","frame_hash":"82bb3691c9262e029acb85087c52d9dcb696a8526548055b444135f8ca835ebe","frame_index":0,"kind":"data","monotonic_ns":306800472896458,"payload":{"event_type":"price_change","market":"0xda6f0e0e93fc8469e0159a166028d017bddbc162b86f66bac90391379603d962","price_changes":[{"asset_id":"39272994714739463168905443499424551362424437245880253267329605556587274644733","best_ask":"0.28","best_bid":"0.27","hash":"767f9900538ae685f96cde1e3f9438d8d3b68530","price":"0.28","side":"SELL","size":"22.52"},{"asset_id":"20893381255801015515826997628594359667013752732428989472914000440642900266717","best_ask":"0.73","best_bid":"0.72","hash":"9fd8f69483c57e11337447e8e57c0ad3b1c6a413","price":"0.72","side":"BUY","size":"22.52"}],"timestamp":"1785204817580"},"payload_hash":"69d97670973fdc18146a0e26204ead50d68ac112da89140485fff9d1789cee16","raw_frame":"{\"market\":\"0xda6f0e0e93fc8469e0159a166028d017bddbc162b86f66bac90391379603d962\", \"price_changes\":[{\"asset_id\":\"39272994714739463168905443499424551362424437245880253267329605556587274644733\", \"price\":\"0.28\", \"size\":\"22.52\", \"side\":\"SELL\", \"hash\":\"767f9900538ae685f96cde1e3f9438d8d3b68530\", \"best_bid\":\"0.27\", \"best_ask\":\"0.28\"}, {\"asset_id\":\"20893381255801015515826997628594359667013752732428989472914000440642900266717\", \"price\":\"0.72\", \"size\":\"22.52\", \"side\":\"BUY\", \"hash\":\"9fd8f69483c57e11337447e8e57c0ad3b1c6a413\", \"best_bid\":\"0.72\", \"best_ask\":\"0.73\"}], \"timestamp\":\"1785204817580\", \"event_type\":\"price_change\"}","received_at":"2026-07-28T02:13:37.461743Z","schema_version":"clob-market-ws.price_change.v1","sequence":null,"server_hash":null,"server_timestamp":"1785204817580","session_id":"d2757dd6dad94f3b9fe67e8dbf1adc37","source":"clob_market_ws"},"received_at":"2026-07-28T02:13:37.461743Z","record_id":"3794fc89ffbc1ba3493634c8ce57a756d99788a060933999cbec31baa9c96c95","schema_fingerprint":"4aa3821a28b0b7c2400bc59aba4bcc0a76e971dadd19610d3ad38c768e124dc7","schema_version":"edge-lab-recorder.raw.v1","sequence":null,"source":"clob_market_ws"}
{"event_at":"2026-07-28T02:13:37.581000Z","event_fingerprint":"4ec08a2c46b81e9b9123fec6b84b17297c7410e1ac6bef8369e5af4c6883a784","payload":{"connection_id":"5d29200f65794d4d9ab6ef271f045a9b","event_at":"2026-07-28T02:13:37.581000Z","event_type":"price_change","frame_hash":"0444603219d59926c19e420507e7e70b67c7ab1c7e3ac9f5f0ebb70d062f6cd5","frame_index":0,"kind":"data","monotonic_ns":306800487395125,"payload":{"event_type":"price_change","market":"0xda6f0e0e93fc8469e0159a166028d017bddbc162b86f66bac90391379603d962","price_changes":[{"asset_id":"20893381255801015515826997628594359667013752732428989472914000440642900266717","best_ask":"0.73","best_bid":"0.72","hash":"9a6150b6285fa3c426c9d439e8038388dd1a5c29","price":"0.02","side":"BUY","size":"579"},{"asset_id":"39272994714739463168905443499424551362424437245880253267329605556587274644733","best_ask":"0.28","best_bid":"0.27","hash":"23721d744b3ee3067f9d6fa04c2acfe6791b68e1","price":"0.98","side":"SELL","size":"579"}],"timestamp":"1785204817581"},"payload_hash":"c71cf55419dff5813b9983b5e6f35a22208e229aa9b37e7e26a3461b15955923","raw_frame":"{\"market\":\"0xda6f0e0e93fc8469e0159a166028d017bddbc162b86f66bac90391379603d962\", \"price_changes\":[{\"asset_id\":\"20893381255801015515826997628594359667013752732428989472914000440642900266717\", \"price\":\"0.02\", \"size\":\"579\", \"side\":\"BUY\", \"hash\":\"9a6150b6285fa3c426c9d439e8038388dd1a5c29\", \"best_bid\":\"0.72\", \"best_ask\":\"0.73\"}, {\"asset_id\":\"39272994714739463168905443499424551362424437245880253267329605556587274644733\", \"price\":\"0.98\", \"size\":\"579\", \"side\":\"SELL\", \"hash\":\"23721d744b3ee3067f9d6fa04c2acfe6791b68e1\", \"best_bid\":\"0.27\", \"best_ask\":\"0.28\"}], \"timestamp\":\"1785204817581\", \"event_type\":\"price_change\"}","received_at":"2026-07-28T02:13:37.476241Z","schema_version":"clob-market-ws.price_change.v1","sequence":null,"server_hash":null,"server_timestamp":"1785204817581","session_id":"d2757dd6dad94f3b9fe67e8dbf1adc37","source":"clob_market_ws"},"received_at":"2026-07-28T02:13:37.476241Z","record_id":"64424103e385d82ac74f9964de6d58dc096c47804f0cf6278b5d9a09fc98043c","schema_fingerprint":"4aa3821a28b0b7c2400bc59aba4bcc0a76e971dadd19610d3ad38c768e124dc7","schema_version":"edge-lab-recorder.raw.v1","sequence":null,"source":"clob_market_ws"}
{"event_at":"2026-07-28T02:13:37.582000Z","event_fingerprint":"e1aab6544895ba71a66f01b6b80e20657b074e065c221785745e49f7eaec1ec8","payload":{"connection_id":"5d29200f65794d4d9ab6ef271f045a9b","event_at":"2026-07-28T02:13:37.582000Z","event_type":"best_bid_ask","frame_hash":"142073945800ada64d75976477463587a3d303fc1cd22c86080f01ef0d376c3b","frame_index":0,"kind":"data","monotonic_ns":306800488947500,"payload":{"asset_id":"20893381255801015515826997628594359667013752732428989472914000440642900266717","best_ask":"0.74","best_bid":"0.72","event_type":"best_bid_ask","market":"0xda6f0e0e93fc8469e0159a166028d017bddbc162b86f66bac90391379603d962","spread":"0.02","timestamp":"1785204817582"},"payload_hash":"6dd8ea1b63d21a0f0d08f2c050d245c7f705383c902a15f0acf5b59ed4c0d192","raw_frame":"{\"market\":\"0xda6f0e0e93fc8469e0159a166028d017bddbc162b86f66bac90391379603d962\", \"asset_id\":\"20893381255801015515826997628594359667013752732428989472914000440642900266717\", \"best_bid\":\"0.72\", \"best_ask\":\"0.74\", \"spread\":\"0.02\", \"timestamp\":\"1785204817582\", \"event_type\":\"best_bid_ask\"}","received_at":"2026-07-28T02:13:37.477794Z","schema_version":"clob-market-ws.best_bid_ask.v1","sequence":null,"server_hash":null,"server_timestamp":"1785204817582","session_id":"d2757dd6dad94f3b9fe67e8dbf1adc37","source":"clob_market_ws"},"received_at":"2026-07-28T02:13:37.477794Z","record_id":"a91592604bfd737d3331b785fb330246d5bb516ad374a001cd98fc67aaedb9cd","schema_fingerprint":"8488399f31b0337811b13b266be932db7062827c2470b78bd8e9e99bab51d17d","schema_version":"edge-lab-recorder.raw.v1","sequence":null,"source":"clob_market_ws"}
{"event_at":"2026-07-28T02:13:37.582000Z","event_fingerprint":"257a55f875d102b22c5b4ff6986ad8b82ca7f09c219bb55b0f32f5e5cb223c3b","payload":{"connection_id":"5d29200f65794d4d9ab6ef271f045a9b","event_at":"2026-07-28T02:13:37.582000Z","event_type":"best_bid_ask","frame_hash":"13c7954f3b99e99c77906e8f7a03297c72f3f9112744e1492eeb1f34742bfd98","frame_index":0,"kind":"data","monotonic_ns":306800490097708,"payload":{"asset_id":"39272994714739463168905443499424551362424437245880253267329605556587274644733","best_ask":"0.28","best_bid":"0.26","event_type":"best_bid_ask","market":"0xda6f0e0e93fc8469e0159a166028d017bddbc162b86f66bac90391379603d962","spread":"0.02","timestamp":"1785204817582"},"payload_hash":"b4aa192c4f2798302c75c53035d79902542ef86b8a2418f6f60625dbcd7d5569","raw_frame":"{\"market\":\"0xda6f0e0e93fc8469e0159a166028d017bddbc162b86f66bac90391379603d962\", \"asset_id\":\"39272994714739463168905443499424551362424437245880253267329605556587274644733\", \"best_bid\":\"0.26\", \"best_ask\":\"0.28\", \"spread\":\"0.02\", \"timestamp\":\"1785204817582\", \"event_type\":\"best_bid_ask\"}","received_at":"2026-07-28T02:13:37.478945Z","schema_version":"clob-market-ws.best_bid_ask.v1","sequence":null,"server_hash":null,"server_timestamp":"1785204817582","session_id":"d2757dd6dad94f3b9fe67e8dbf1adc37","source":"clob_market_ws"},"received_at":"2026-07-28T02:13:37.478945Z","record_id":"0006c6e68c5e4e50e5c2b1ababee33b68fdfdb767b1e2bbbd23cd032a753057b","schema_fingerprint":"8488399f31b0337811b13b266be932db7062827c2470b78bd8e9e99bab51d17d","schema_version":"edge-lab-recorder.raw.v1","sequence":null,"source":"clob_market_ws"}
{"event_at":"2026-07-28T02:13:37.582000Z","event_fingerprint":"b7e887292a55471c8f201703057241d35db684fdd3f8c69f6c825d06cc3babe5","payload":{"connection_id":"5d29200f65794d4d9ab6ef271f045a9b","event_at":"2026-07-28T02:13:37.582000Z","event_type":"price_change","frame_hash":"1eddc11eb204539336107621eb4f1b6c9721742a0b7ae4c7f7fc957cdd08e589","frame_index":0,"kind":"data","monotonic_ns":306800491143583,"payload":{"event_type":"price_change","market":"0xda6f0e0e93fc8469e0159a166028d017bddbc162b86f66bac90391379603d962","price_changes":[{"asset_id":"39272994714739463168905443499424551362424437245880253267329605556587274644733","best_ask":"0.28","best_bid":"0.26","hash":"7e11d54da30414f61fc86f04424d4bc6155f7560","price":"0.27","side":"BUY","size":"0"},{"asset_id":"20893381255801015515826997628594359667013752732428989472914000440642900266717","best_ask":"0.74","best_bid":"0.72","hash":"daa13367fa27eb7f101bb0ceb6f016f654996750","price":"0.73","side":"SELL","size":"0"}],"timestamp":"1785204817582"},"payload_hash":"65f4e5a0f0ce1e44f8f841584884dfc0a47ab5cdc9ac59a879ceb195ef7d31f2","raw_frame":"{\"market\":\"0xda6f0e0e93fc8469e0159a166028d017bddbc162b86f66bac90391379603d962\", \"price_changes\":[{\"asset_id\":\"39272994714739463168905443499424551362424437245880253267329605556587274644733\", \"price\":\"0.27\", \"size\":\"0\", \"side\":\"BUY\", \"hash\":\"7e11d54da30414f61fc86f04424d4bc6155f7560\", \"best_bid\":\"0.26\", \"best_ask\":\"0.28\"}, {\"asset_id\":\"20893381255801015515826997628594359667013752732428989472914000440642900266717\", \"price\":\"0.73\", \"size\":\"0\", \"side\":\"SELL\", \"hash\":\"daa13367fa27eb7f101bb0ceb6f016f654996750\", \"best_bid\":\"0.72\", \"best_ask\":\"0.74\"}], \"timestamp\":\"1785204817582\", \"event_type\":\"price_change\"}","received_at":"2026-07-28T02:13:37.479991Z","schema_version":"clob-market-ws.price_change.v1","sequence":null,"server_hash":null,"server_timestamp":"1785204817582","session_id":"d2757dd6dad94f3b9fe67e8dbf1adc37","source":"clob_market_ws"},"received_at":"2026-07-28T02:13:37.479991Z","record_id":"13313f439cea0a84a009dd40b5363a20ca51a8e309d629d24c3d9d1a5dea0369","schema_fingerprint":"4aa3821a28b0b7c2400bc59aba4bcc0a76e971dadd19610d3ad38c768e124dc7","schema_version":"edge-lab-recorder.raw.v1","sequence":null,"source":"clob_market_ws"}
{"event_at":"2026-07-28T02:13:37.583000Z","event_fingerprint":"21502dae5b15f980c2cf8eff692c8f87d7a51f522e797f715c9b0c5bcf68c8ba","payload":{"connection_id":"5d29200f65794d4d9ab6ef271f045a9b","event_at":"2026-07-28T02:13:37.583000Z","event_type":"price_change","frame_hash":"68e66cf64796b7d0675c6233772ca593c6bb30fc36b071d08c97963018a58dac","frame_index":0,"kind":"data","monotonic_ns":306800492738750,"payload":{"event_type":"price_change","market":"0xda6f0e0e93fc8469e0159a166028d017bddbc162b86f66bac90391379603d962","price_changes":[{"asset_id":"20893381255801015515826997628594359667013752732428989472914000440642900266717","best_ask":"0.74","best_bid":"0.72","hash":"910c156ad92769ab56a2657e77978849c709a823","price":"0.72","side":"BUY","size":"105.99"},{"asset_id":"39272994714739463168905443499424551362424437245880253267329605556587274644733","best_ask":"0.28","best_bid":"0.26","hash":"e8313a88e73948739df8fe29ed5d2c95d2040f4b","price":"0.28","side":"SELL","size":"105.99"}],"timestamp":"1785204817583"},"payload_hash":"7391853d53499485cfd7834bcf3afc5699c58043333be39b64286606de68b3d3","raw_frame":"{\"market\":\"0xda6f0e0e93fc8469e0159a166028d017bddbc162b86f66bac90391379603d962\", \"price_changes\":[{\"asset_id\":\"20893381255801015515826997628594359667013752732428989472914000440642900266717\", \"price\":\"0.72\", \"size\":\"105.99\", \"side\":\"BUY\", \"hash\":\"910c156ad92769ab56a2657e77978849c709a823\", \"best_bid\":\"0.72\", \"best_ask\":\"0.74\"}, {\"asset_id\":\"39272994714739463168905443499424551362424437245880253267329605556587274644733\", \"price\":\"0.28\", \"size\":\"105.99\", \"side\":\"SELL\", \"hash\":\"e8313a88e73948739df8fe29ed5d2c95d2040f4b\", \"best_bid\":\"0.26\", \"best_ask\":\"0.28\"}], \"timestamp\":\"1785204817583\", \"event_type\":\"price_change\"}","received_at":"2026-07-28T02:13:37.481587Z","schema_version":"clob-market-ws.price_change.v1","sequence":null,"server_hash":null,"server_timestamp":"1785204817583","session_id":"d2757dd6dad94f3b9fe67e8dbf1adc37","source":"clob_market_ws"},"received_at":"2026-07-28T02:13:37.481587Z","record_id":"25a974a3e2e6904fee883046efcbf7c0d87ddbb2ef7639cc415f14bba4b6bc2e","schema_fingerprint":"4aa3821a28b0b7c2400bc59aba4bcc0a76e971dadd19610d3ad38c768e124dc7","schema_version":"edge-lab-recorder.raw.v1","sequence":null,"source":"clob_market_ws"}
{"event_at":"2026-07-28T02:13:37.584000Z","event_fingerprint":"07767b9f040a0bb54b43a75c5aa823718512f1ef37ce3b03630a160ad7e2d5d0","payload":{"connection_id":"5d29200f65794d4d9ab6ef271f045a9b","event_at":"2026-07-28T02:13:37.584000Z","event_type":"price_change","frame_hash":"2d11bfc463db5cdf038a8f95c742268f2f2d6be5918d364a310b42a6556ab06e","frame_index":0,"kind":"data","monotonic_ns":306800494251208,"payload":{"event_type":"price_change","market":"0xda6f0e0e93fc8469e0159a166028d017bddbc162b86f66bac90391379603d962","price_changes":[{"asset_id":"20893381255801015515826997628594359667013752732428989472914000440642900266717","best_ask":"0.74","best_bid":"0.72","hash":"d8ab6c1e4a26ae1cfc1557a8c201507f81f9d1ca","price":"0.7","side":"BUY","size":"15"},{"asset_id":"39272994714739463168905443499424551362424437245880253267329605556587274644733","best_ask":"0.28","best_bid":"0.26","hash":"a00c59f6c646aa547e43d84aeabfbedb7e8f82c1","price":"0.3","side":"SELL","size":"15"}],"timestamp":"1785204817584"},"payload_hash":"09a73b0f57380c227b7cbb24790e61904b356c7885a83f1c8924cb7d16b9732e","raw_frame":"{\"market\":\"0xda6f0e0e93fc8469e0159a166028d017bddbc162b86f66bac90391379603d962\", \"price_changes\":[{\"asset_id\":\"20893381255801015515826997628594359667013752732428989472914000440642900266717\", \"price\":\"0.7\", \"size\":\"15\", \"side\":\"BUY\", \"hash\":\"d8ab6c1e4a26ae1cfc1557a8c201507f81f9d1ca\", \"best_bid\":\"0.72\", \"best_ask\":\"0.74\"}, {\"asset_id\":\"39272994714739463168905443499424551362424437245880253267329605556587274644733\", \"price\":\"0.3\", \"size\":\"15\", \"side\":\"SELL\", \"hash\":\"a00c59f6c646aa547e43d84aeabfbedb7e8f82c1\", \"best_bid\":\"0.26\", \"best_ask\":\"0.28\"}], \"timestamp\":\"1785204817584\", \"event_type\":\"price_change\"}","received_at":"2026-07-28T02:13:37.483099Z","schema_version":"clob-market-ws.price_change.v1","sequence":null,"server_hash":null,"server_timestamp":"1785204817584","session_id":"d2757dd6dad94f3b9fe67e8dbf1adc37","source":"clob_market_ws"},"received_at":"2026-07-28T02:13:37.483099Z","record_id":"b9e93cfd5516f69a0fe0b6a2f1e1f879912a721672bdd3cfc57d126732f36519","schema_fingerprint":"4aa3821a28b0b7c2400bc59aba4bcc0a76e971dadd19610d3ad38c768e124dc7","schema_version":"edge-lab-recorder.raw.v1","sequence":null,"source":"clob_market_ws"}
{"event_at":"2026-07-28T02:13:37.599000Z","event_fingerprint":"f0e9fc986bfc4cbef936582b815e19878a9ea96c792b5978486ab4e407c0a6b3","payload":{"connection_id":"5d29200f65794d4d9ab6ef271f045a9b","event_at":"2026-07-28T02:13:37.599000Z","event_type":"price_change","frame_hash":"0b686ae4952a067412b608eacfb4c670521cb78254b76571c2ec7015b903fb50","frame_index":0,"kind":"data","monotonic_ns":306800495731291,"payload":{"event_type":"price_change","market":"0xda6f0e0e93fc8469e0159a166028d017bddbc162b86f66bac90391379603d962","price_changes":[{"asset_id":"20893381255801015515826997628594359667013752732428989472914000440642900266717","best_ask":"0.74","best_bid":"0.72","hash":"5f5ec80b3bdfa013a01f9cd492543bc39355bf0b","price":"0.72","side":"BUY","size":"110.99"},{"asset_id":"39272994714739463168905443499424551362424437245880253267329605556587274644733","best_ask":"0.28","best_bid":"0.26","hash":"e4a1d103ec18b31518f0a1bc66dda87f9bab263f","price":"0.28","side":"SELL","size":"110.99"}],"timestamp":"1785204817599"},"payload_hash":"83a38cea7cff508cf40ff2d31df3ecb337d45ef7dcaa5ff92b70a0e9bfcb7a8c","raw_frame":"{\"market\":\"0xda6f0e0e93fc8469e0159a166028d017bddbc162b86f66bac90391379603d962\", \"price_changes\":[{\"asset_id\":\"20893381255801015515826997628594359667013752732428989472914000440642900266717\", \"price\":\"0.72\", \"size\":\"110.99\", \"side\":\"BUY\", \"hash\":\"5f5ec80b3bdfa013a01f9cd492543bc39355bf0b\", \"best_bid\":\"0.72\", \"best_ask\":\"0.74\"}, {\"asset_id\":\"39272994714739463168905443499424551362424437245880253267329605556587274644733\", \"price\":\"0.28\", \"size\":\"110.99\", \"side\":\"SELL\", \"hash\":\"e4a1d103ec18b31518f0a1bc66dda87f9bab263f\", \"best_bid\":\"0.26\", \"best_ask\":\"0.28\"}], \"timestamp\":\"1785204817599\", \"event_type\":\"price_change\"}","received_at":"2026-07-28T02:13:37.484579Z","schema_version":"clob-market-ws.price_change.v1","sequence":null,"server_hash":null,"server_timestamp":"1785204817599","session_id":"d2757dd6dad94f3b9fe67e8dbf1adc37","source":"clob_market_ws"},"received_at":"2026-07-28T02:13:37.484579Z","record_id":"2279c276c2006851354001f8b88fa43140cfbac611293faa68236c92e90834f1","schema_fingerprint":"4aa3821a28b0b7c2400bc59aba4bcc0a76e971dadd19610d3ad38c768e124dc7","schema_version":"edge-lab-recorder.raw.v1","sequence":null,"source":"clob_market_ws"}
{"event_at":"2026-07-28T02:13:37.601000Z","event_fingerprint":"e3ca31a78a5e74c8960b52d00b41a465cba44e77d6a005a51e5e9565f982f434","payload":{"connection_id":"5d29200f65794d4d9ab6ef271f045a9b","event_at":"2026-07-28T02:13:37.601000Z","event_type":"price_change","frame_hash":"8a35062f7b15804fbace245dba1323968e23bbb31e70c7c2e3ef55a68a0eab71","frame_index":0,"kind":"data","monotonic_ns":306800502818958,"payload":{"event_type":"price_change","market":"0xda6f0e0e93fc8469e0159a166028d017bddbc162b86f66bac90391379603d962","price_changes":[{"asset_id":"20893381255801015515826997628594359667013752732428989472914000440642900266717","best_ask":"0.74","best_bid":"0.72","hash":"6d0a330a1f130339f93e356629a483db51dc2e90","price":"0.72","side":"BUY","size":"105.99"},{"asset_id":"39272994714739463168905443499424551362424437245880253267329605556587274644733","best_ask":"0.28","best_bid":"0.26","hash":"ea966e563cb50ad937a26bfa36c2b4efdfbc629e","price":"0.28","side":"SELL","size":"105.99"}],"timestamp":"1785204817601"},"payload_hash":"f60c8b45a3b6c530b7eb6a4775cb3d6b61898104d936e35d1de4a908a61a76cc","raw_frame":"{\"market\":\"0xda6f0e0e93fc8469e0159a166028d017bddbc162b86f66bac90391379603d962\", \"price_changes\":[{\"asset_id\":\"20893381255801015515826997628594359667013752732428989472914000440642900266717\", \"price\":\"0.72\", \"size\":\"105.99\", \"side\":\"BUY\", \"hash\":\"6d0a330a1f130339f93e356629a483db51dc2e90\", \"best_bid\":\"0.72\", \"best_ask\":\"0.74\"}, {\"asset_id\":\"39272994714739463168905443499424551362424437245880253267329605556587274644733\", \"price\":\"0.28\", \"size\":\"105.99\", \"side\":\"SELL\", \"hash\":\"ea966e563cb50ad937a26bfa36c2b4efdfbc629e\", \"best_bid\":\"0.26\", \"best_ask\":\"0.28\"}], \"timestamp\":\"1785204817601\", \"event_type\":\"price_change\"}","received_at":"2026-07-28T02:13:37.491668Z","schema_version":"clob-market-ws.price_change.v1","sequence":null,"server_hash":null,"server_timestamp":"1785204817601","session_id":"d2757dd6dad94f3b9fe67e8dbf1adc37","source":"clob_market_ws"},"received_at":"2026-07-28T02:13:37.491668Z","record_id":"37d0bdeeb7db33b11c59231136a1f1484f8962c6790d2a7570567b3cc5794bc3","schema_fingerprint":"4aa3821a28b0b7c2400bc59aba4bcc0a76e971dadd19610d3ad38c768e124dc7","schema_version":"edge-lab-recorder.raw.v1","sequence":null,"source":"clob_market_ws"}
{"event_at":"2026-07-28T02:13:37.607000Z","event_fingerprint":"0e3eb3236eabe29f1301d86d2ec15aebca069ad53d9c3c83b937018bbb554a20","payload":{"connection_id":"5d29200f65794d4d9ab6ef271f045a9b","event_at":"2026-07-28T02:13:37.607000Z","event_type":"price_change","frame_hash":"9b13a3de502f699ecc89e608ff2d62cb6965b03a015573d8439f06e6b2651a2e","frame_index":0,"kind":"data","monotonic_ns":306800505158625,"payload":{"event_type":"price_change","market":"0xda6f0e0e93fc8469e0159a166028d017bddbc162b86f66bac90391379603d962","price_changes":[{"asset_id":"20893381255801015515826997628594359667013752732428989472914000440642900266717","best_ask":"0.74","best_bid":"0.72","hash":"6d50fa7e1702a5d5fd30cfaf2389fca3872c39c7","price":"0.01","side":"BUY","size":"5379.02"},{"asset_id":"39272994714739463168905443499424551362424437245880253267329605556587274644733","best_ask":"0.28","best_bid":"0.26","hash":"50284a519857b391992697f2fb7049a35c58b385","price":"0.99","side":"SELL","size":"5379.02"}],"timestamp":"1785204817607"},"payload_hash":"357b00a262364a6ed1f6123d11a489c49e6ec31efbda0c8f6919b05162a54775","raw_frame":"{\"market\":\"0xda6f0e0e93fc8469e0159a166028d017bddbc162b86f66bac90391379603d962\", \"price_changes\":[{\"asset_id\":\"20893381255801015515826997628594359667013752732428989472914000440642900266717\", \"price\":\"0.01\", \"size\":\"5379.02\", \"side\":\"BUY\", \"hash\":\"6d50fa7e1702a5d5fd30cfaf2389fca3872c39c7\", \"best_bid\":\"0.72\", \"best_ask\":\"0.74\"}, {\"asset_id\":\"39272994714739463168905443499424551362424437245880253267329605556587274644733\", \"price\":\"0.99\", \"size\":\"5379.02\", \"side\":\"SELL\", \"hash\":\"50284a519857b391992697f2fb7049a35c58b385\", \"best_bid\":\"0.26\", \"best_ask\":\"0.28\"}], \"timestamp\":\"1785204817607\", \"event_type\":\"price_change\"}","received_at":"2026-07-28T02:13:37.494007Z","schema_version":"clob-market-ws.price_change.v1","sequence":null,"server_hash":null,"server_timestamp":"1785204817607","session_id":"d2757dd6dad94f3b9fe67e8dbf1adc37","source":"clob_market_ws"},"received_at":"2026-07-28T02:13:37.494007Z","record_id":"d446d545886269523f9a1a08ac1430546443e67d44ef0bab56e8c0af4eb092bb","schema_fingerprint":"4aa3821a28b0b7c2400bc59aba4bcc0a76e971dadd19610d3ad38c768e124dc7","schema_version":"edge-lab-recorder.raw.v1","sequence":null,"source":"clob_market_ws"}
{"event_at":"2026-07-28T02:13:37.634000Z","event_fingerprint":"14ee1e269671d416a793625c8914868da389063c51913cb03719999beafea5ed","payload":{"connection_id":"5d29200f65794d4d9ab6ef271f045a9b","event_at":"2026-07-28T02:13:37.634000Z","event_type":"price_change","frame_hash":"a229b83390ffc8b476593765005e029a0db7e2123e3f4f351a0c2d5373354419","frame_index":0,"kind":"data","monotonic_ns":306800528963041,"payload":{"event_type":"price_change","market":"0xda6f0e0e93fc8469e0159a166028d017bddbc162b86f66bac90391379603d962","price_changes":[{"asset_id":"20893381255801015515826997628594359667013752732428989472914000440642900266717","best_ask":"0.74","best_bid":"0.72","hash":"25850ab31c4d60f420b4241bdfacf49d3e5e1153","price":"0.02","side":"BUY","size":"574"},{"asset_id":"39272994714739463168905443499424551362424437245880253267329605556587274644733","best_ask":"0.28","best_bid":"0.26","hash":"2f0c86b28eb1befdf83b49bd7be0778bba03ee63","price":"0.98","side":"SELL","size":"574"}],"timestamp":"1785204817634"},"payload_hash":"e1c08808d574a8e0acea8e7502cb15dd8dd49d2ded2308fc25a5a935594a7924","raw_frame":"{\"market\":\"0xda6f0e0e93fc8469e0159a166028d017bddbc162b86f66bac90391379603d962\", \"price_changes\":[{\"asset_id\":\"20893381255801015515826997628594359667013752732428989472914000440642900266717\", \"price\":\"0.02\", \"size\":\"574\", \"side\":\"BUY\", \"hash\":\"25850ab31c4d60f420b4241bdfacf49d3e5e1153\", \"best_bid\":\"0.72\", \"best_ask\":\"0.74\"}, {\"asset_id\":\"39272994714739463168905443499424551362424437245880253267329605556587274644733\", \"price\":\"0.98\", \"size\":\"574\", \"side\":\"SELL\", \"hash\":\"2f0c86b28eb1befdf83b49bd7be0778bba03ee63\", \"best_bid\":\"0.26\", \"best_ask\":\"0.28\"}], \"timestamp\":\"1785204817634\", \"event_type\":\"price_change\"}","received_at":"2026-07-28T02:13:37.517811Z","schema_version":"clob-market-ws.price_change.v1","sequence":null,"server_hash":null,"server_timestamp":"1785204817634","session_id":"d2757dd6dad94f3b9fe67e8dbf1adc37","source":"clob_market_ws"},"received_at":"2026-07-28T02:13:37.517811Z","record_id":"9de5c483930b985997fcfa56e6b77f30dbef25b5adc4c93fce651742ae86c4cc","schema_fingerprint":"4aa3821a28b0b7c2400bc59aba4bcc0a76e971dadd19610d3ad38c768e124dc7","schema_version":"edge-lab-recorder.raw.v1","sequence":null,"source":"clob_market_ws"}
{"event_at":"2026-07-28T02:13:37.640000Z","event_fingerprint":"721b2f83bdd2ad8d836792c5669cf68902957d8c966eeb5627e7c3390e9b54bb","payload":{"connection_id":"5d29200f65794d4d9ab6ef271f045a9b","event_at":"2026-07-28T02:13:37.640000Z","event_type":"price_change","frame_hash":"07e185560e695e4fb44f4aad945dd2d2b9cbf97816a9270b95d787bae8590f68","frame_index":0,"kind":"data","monotonic_ns":306800538404166,"payload":{"event_type":"price_change","market":"0xda6f0e0e93fc8469e0159a166028d017bddbc162b86f66bac90391379603d962","price_changes":[{"asset_id":"20893381255801015515826997628594359667013752732428989472914000440642900266717","best_ask":"0.74","best_bid":"0.72","hash":"04ce803a277721e5108634415a9adefc9566ecbd","price":"0.01","side":"BUY","size":"5374.02"},{"asset_id":"39272994714739463168905443499424551362424437245880253267329605556587274644733","best_ask":"0.28","best_bid":"0.26","hash":"5f752f8236d5de33ce62c96027ca4be62044224d","price":"0.99","side":"SELL","size":"5374.02"}],"timestamp":"1785204817640"},"payload_hash":"991a7eb6753cb3234659882e2775668f3155a5c2c99846ab7a6d924cef6614db","raw_frame":"{\"market\":\"0xda6f0e0e93fc8469e0159a166028d017bddbc162b86f66bac90391379603d962\", \"price_changes\":[{\"asset_id\":\"20893381255801015515826997628594359667013752732428989472914000440642900266717\", \"price\":\"0.01\", \"size\":\"5374.02\", \"side\":\"BUY\", \"hash\":\"04ce803a277721e5108634415a9adefc9566ecbd\", \"best_bid\":\"0.72\", \"best_ask\":\"0.74\"}, {\"asset_id\":\"39272994714739463168905443499424551362424437245880253267329605556587274644733\", \"price\":\"0.99\", \"size\":\"5374.02\", \"side\":\"SELL\", \"hash\":\"5f752f8236d5de33ce62c96027ca4be62044224d\", \"best_bid\":\"0.26\", \"best_ask\":\"0.28\"}], \"timestamp\":\"1785204817640\", \"event_type\":\"price_change\"}","received_at":"2026-07-28T02:13:37.527251Z","schema_version":"clob-market-ws.price_change.v1","sequence":null,"server_hash":null,"server_timestamp":"1785204817640","session_id":"d2757dd6dad94f3b9fe67e8dbf1adc37","source":"clob_market_ws"},"received_at":"2026-07-28T02:13:37.527251Z","record_id":"496cce3529be78763bb3caee83db1e4b22aa66679ae859123809cf67e2918050","schema_fingerprint":"4aa3821a28b0b7c2400bc59aba4bcc0a76e971dadd19610d3ad38c768e124dc7","schema_version":"edge-lab-recorder.raw.v1","sequence":null,"source":"clob_market_ws"}
{"event_at":"2026-07-28T02:13:37.641000Z","event_fingerprint":"3ea71ff75ca22d27d3e473fb6de846caa210a011544b27bffd484d972d953bc6","payload":{"connection_id":"5d29200f65794d4d9ab6ef271f045a9b","event_at":"2026-07-28T02:13:37.641000Z","event_type":"price_change","frame_hash":"4369ea11dab56eeaa4b05820ef064a5f626d63e597cd8d5009b98ff78a9a468f","frame_index":0,"kind":"data","monotonic_ns":306800542099041,"payload":{"event_type":"price_change","market":"0xda6f0e0e93fc8469e0159a166028d017bddbc162b86f66bac90391379603d962","price_changes":[{"asset_id":"39272994714739463168905443499424551362424437245880253267329605556587274644733","best_ask":"0.28","best_bid":"0.26","hash":"bbbcacf9fa241540f619594d86dde3a498185d1d","price":"0.21","side":"BUY","size":"67"},{"asset_id":"20893381255801015515826997628594359667013752732428989472914000440642900266717","best_ask":"0.74","best_bid":"0.72","hash":"a499ced13bcadd7f77b3c11085d14e8c8a7f434a","price":"0.79","side":"SELL","size":"67"}],"timestamp":"1785204817641"},"payload_hash":"457eb2841f9338d37aabef88a260061a00039b54e1f53a79d9f1a4cea0c29278","raw_frame":"{\"market\":\"0xda6f0e0e93fc8469e0159a166028d017bddbc162b86f66bac90391379603d962\", \"price_changes\":[{\"asset_id\":\"39272994714739463168905443499424551362424437245880253267329605556587274644733\", \"price\":\"0.21\", \"size\":\"67\", \"side\":\"BUY\", \"hash\":\"bbbcacf9fa241540f619594d86dde3a498185d1d\", \"best_bid\":\"0.26\", \"best_ask\":\"0.28\"}, {\"asset_id\":\"20893381255801015515826997628594359667013752732428989472914000440642900266717\", \"price\":\"0.79\", \"size\":\"67\", \"side\":\"SELL\", \"hash\":\"a499ced13bcadd7f77b3c11085d14e8c8a7f434a\", \"best_bid\":\"0.72\", \"best_ask\":\"0.74\"}], \"timestamp\":\"1785204817641\", \"event_type\":\"price_change\"}","received_at":"2026-07-28T02:13:37.530946Z","schema_version":"clob-market-ws.price_change.v1","sequence":null,"server_hash":null,"server_timestamp":"1785204817641","session_id":"d2757dd6dad94f3b9fe67e8dbf1adc37","source":"clob_market_ws"},"received_at":"2026-07-28T02:13:37.530946Z","record_id":"d936865c60336e0962ea336611fe1a81d6529c2e4701b03826411dc81881aa05","schema_fingerprint":"4aa3821a28b0b7c2400bc59aba4bcc0a76e971dadd19610d3ad38c768e124dc7","schema_version":"edge-lab-recorder.raw.v1","sequence":null,"source":"clob_market_ws"}
{"event_at":"2026-07-28T02:13:37.668000Z","event_fingerprint":"ff4a65cf8de834e7d462416855bb77ba0633d583e88009ca4ddbfac5ddfdaf54","payload":{"connection_id":"5d29200f65794d4d9ab6ef271f045a9b","event_at":"2026-07-28T02:13:37.668000Z","event_type":"price_change","frame_hash":"a85ff8b88b54b64ed3b184f6153857e14bd34ce233c27e16320d4161d460568f","frame_index":0,"kind":"data","monotonic_ns":306800563645708,"payload":{"event_type":"price_change","market":"0xda6f0e0e93fc8469e0159a166028d017bddbc162b86f66bac90391379603d962","price_changes":[{"asset_id":"39272994714739463168905443499424551362424437245880253267329605556587274644733","best_ask":"0.28","best_bid":"0.26","hash":"e70725d589f4d1fca0ea9f3002d300a76cbc7b90","price":"0.2","side":"BUY","size":"62"},{"asset_id":"20893381255801015515826997628594359667013752732428989472914000440642900266717","best_ask":"0.74","best_bid":"0.72","hash":"01efe00e50f9aadb8efd2436a602529cb822316a","price":"0.8","side":"SELL","size":"62"}],"timestamp":"1785204817668"},"payload_hash":"5e274c0dadfdf87e6e56332d98995dc1c0cbe78c485f7c76f9e428cdce13f527","raw_frame":"{\"market\":\"0xda6f0e0e93fc8469e0159a166028d017bddbc162b86f66bac90391379603d962\", \"price_changes\":[{\"asset_id\":\"39272994714739463168905443499424551362424437245880253267329605556587274644733\", \"price\":\"0.2\", \"size\":\"62\", \"side\":\"BUY\", \"hash\":\"e70725d589f4d1fca0ea9f3002d300a76cbc7b90\", \"best_bid\":\"0.26\", \"best_ask\":\"0.28\"}, {\"asset_id\":\"20893381255801015515826997628594359667013752732428989472914000440642900266717\", \"price\":\"0.8\", \"size\":\"62\", \"side\":\"SELL\", \"hash\":\"01efe00e50f9aadb8efd2436a602529cb822316a\", \"best_bid\":\"0.72\", \"best_ask\":\"0.74\"}], \"timestamp\":\"1785204817668\", \"event_type\":\"price_change\"}","received_at":"2026-07-28T02:13:37.552498Z","schema_version":"clob-market-ws.price_change.v1","sequence":null,"server_hash":null,"server_timestamp":"1785204817668","session_id":"d2757dd6dad94f3b9fe67e8dbf1adc37","source":"clob_market_ws"},"received_at":"2026-07-28T02:13:37.552498Z","record_id":"d331dce763a12742022f13a10cb83ad8106213db4f1d561883b26c8774194f8e","schema_fingerprint":"4aa3821a28b0b7c2400bc59aba4bcc0a76e971dadd19610d3ad38c768e124dc7","schema_version":"edge-lab-recorder.raw.v1","sequence":null,"source":"clob_market_ws"}
{"event_at":"2026-07-28T02:13:37.714000Z","event_fingerprint":"a3148c6b374b9a7685ecdafa88d80943c60698837d683aba0155feef521a7a66","payload":{"connection_id":"5d29200f65794d4d9ab6ef271f045a9b","event_at":"2026-07-28T02:13:37.714000Z","event_type":"price_change","frame_hash":"7926794feaf7fcccc3b9168d37cde9c975f5c8b3ed0bdf7f9ecce247a44d6a35","frame_index":0,"kind":"data","monotonic_ns":306800607609916,"payload":{"event_type":"price_change","market":"0xda6f0e0e93fc8469e0159a166028d017bddbc162b86f66bac90391379603d962","price_changes":[{"asset_id":"20893381255801015515826997628594359667013752732428989472914000440642900266717","best_ask":"0.74","best_bid":"0.72","hash":"fd4e21fc3c38740f39af15eda50bf661d744464e","price":"0.01","side":"BUY","size":"5379.02"},{"asset_id":"39272994714739463168905443499424551362424437245880253267329605556587274644733","best_ask":"0.28","best_bid":"0.26","hash":"b0f877ba96537cd910df083931291507b7d93752","price":"0.99","side":"SELL","size":"5379.02"}],"timestamp":"1785204817714"},"payload_hash":"0d816565d28ffff0345bfa4b2e801ab2d7b5622bf88bfc2801180b5ab59c2094","raw_frame":"{\"market\":\"0xda6f0e0e93fc8469e0159a166028d017bddbc162b86f66bac90391379603d962\", \"price_changes\":[{\"asset_id\":\"20893381255801015515826997628594359667013752732428989472914000440642900266717\", \"price\":\"0.01\", \"size\":\"5379.02\", \"side\":\"BUY\", \"hash\":\"fd4e21fc3c38740f39af15eda50bf661d744464e\", \"best_bid\":\"0.72\", \"best_ask\":\"0.74\"}, {\"asset_id\":\"39272994714739463168905443499424551362424437245880253267329605556587274644733\", \"price\":\"0.99\", \"size\":\"5379.02\", \"side\":\"SELL\", \"hash\":\"b0f877ba96537cd910df083931291507b7d93752\", \"best_bid\":\"0.26\", \"best_ask\":\"0.28\"}], \"timestamp\":\"1785204817714\", \"event_type\":\"price_change\"}","received_at":"2026-07-28T02:13:37.596456Z","schema_version":"clob-market-ws.price_change.v1","sequence":null,"server_hash":null,"server_timestamp":"1785204817714","session_id":"d2757dd6dad94f3b9fe67e8dbf1adc37","source":"clob_market_ws"},"received_at":"2026-07-28T02:13:37.596456Z","record_id":"ff3bea485d1de3c2ff14e3bc5e2a0a845ef78bbcf8f618f82a0da98e5fe8e512","schema_fingerprint":"4aa3821a28b0b7c2400bc59aba4bcc0a76e971dadd19610d3ad38c768e124dc7","schema_version":"edge-lab-recorder.raw.v1","sequence":null,"source":"clob_market_ws"}
{"event_at":"2026-07-28T02:13:37.726000Z","event_fingerprint":"c7c2fafb3b399fad3aa62fcbdf8dd0593ec1115f55e97314629615cb3960c5fb","payload":{"connection_id":"5d29200f65794d4d9ab6ef271f045a9b","event_at":"2026-07-28T02:13:37.726000Z","event_type":"price_change","frame_hash":"364d355b1d47115fc1af257043d719f8645b304fbefd87f60f30003b77cd23c0","frame_index":0,"kind":"data","monotonic_ns":306800620936916,"payload":{"event_type":"price_change","market":"0xda6f0e0e93fc8469e0159a166028d017bddbc162b86f66bac90391379603d962","price_changes":[{"asset_id":"20893381255801015515826997628594359667013752732428989472914000440642900266717","best_ask":"0.74","best_bid":"0.72","hash":"708c42622e6866c7bced5c649781da191395d592","price":"0.72","side":"BUY","size":"22.52"},{"asset_id":"39272994714739463168905443499424551362424437245880253267329605556587274644733","best_ask":"0.28","best_bid":"0.26","hash":"a3e3012df61516d13c743464643d1ad70c9cf230","price":"0.28","side":"SELL","size":"22.52"}],"timestamp":"1785204817726"},"payload_hash":"07fc27dfd319a6caba22562a7f772902e4e859d842c977eee42680f376a2d561","raw_frame":"{\"market\":\"0xda6f0e0e93fc8469e0159a166028d017bddbc162b86f66bac90391379603d962\", \"price_changes\":[{\"asset_id\":\"20893381255801015515826997628594359667013752732428989472914000440642900266717\", \"price\":\"0.72\", \"size\":\"22.52\", \"side\":\"BUY\", \"hash\":\"708c42622e6866c7bced5c649781da191395d592\", \"best_bid\":\"0.72\", \"best_ask\":\"0.74\"}, {\"asset_id\":\"39272994714739463168905443499424551362424437245880253267329605556587274644733\", \"price\":\"0.28\", \"size\":\"22.52\", \"side\":\"SELL\", \"hash\":\"a3e3012df61516d13c743464643d1ad70c9cf230\", \"best_bid\":\"0.26\", \"best_ask\":\"0.28\"}], \"timestamp\":\"1785204817726\", \"event_type\":\"price_change\"}","received_at":"2026-07-28T02:13:37.609783Z","schema_version":"clob-market-ws.price_change.v1","sequence":null,"server_hash":null,"server_timestamp":"1785204817726","session_id":"d2757dd6dad94f3b9fe67e8dbf1adc37","source":"clob_market_ws"},"received_at":"2026-07-28T02:13:37.609783Z","record_id":"20e9366e95760e017fd42e289bd32f5c62461fe7188dc61c2393365dd53ea4fe","schema_fingerprint":"4aa3821a28b0b7c2400bc59aba4bcc0a76e971dadd19610d3ad38c768e124dc7","schema_version":"edge-lab-recorder.raw.v1","sequence":null,"source":"clob_market_ws"}
{"event_at":"2026-07-28T02:13:37.728000Z","event_fingerprint":"457104b08cb64759577be45f71f04163d0b9f2aa348cccbdae2c7835ca64b289","payload":{"connection_id":"5d29200f65794d4d9ab6ef271f045a9b","event_at":"2026-07-28T02:13:37.728000Z","event_type":"price_change","frame_hash":"ba3d4f188a0089400ff3e0a684225f5a2a669ded34ff8e7b0388ffe311267543","frame_index":0,"kind":"data","monotonic_ns":306800623185708,"payload":{"event_type":"price_change","market":"0xda6f0e0e93fc8469e0159a166028d017bddbc162b86f66bac90391379603d962","price_changes":[{"asset_id":"39272994714739463168905443499424551362424437245880253267329605556587274644733","best_ask":"0.28","best_bid":"0.26","hash":"f8cfc2b623ba2385d9b8ae03b91a52734e039f89","price":"0.28","side":"SELL","size":"100.99"},{"asset_id":"20893381255801015515826997628594359667013752732428989472914000440642900266717","best_ask":"0.74","best_bid":"0.72","hash":"dcea98265d846862fd03f98bcca7a3e093bc43ef","price":"0.72","side":"BUY","size":"100.99"}],"timestamp":"1785204817728"},"payload_hash":"bd3b5d69b971895c2cbdedc13f336aa509b486e8e6878a2568cd3c8c3bb1365a","raw_frame":"{\"market\":\"0xda6f0e0e93fc8469e0159a166028d017bddbc162b86f66bac90391379603d962\", \"price_changes\":[{\"asset_id\":\"39272994714739463168905443499424551362424437245880253267329605556587274644733\", \"price\":\"0.28\", \"size\":\"100.99\", \"side\":\"SELL\", \"hash\":\"f8cfc2b623ba2385d9b8ae03b91a52734e039f89\", \"best_bid\":\"0.26\", \"best_ask\":\"0.28\"}, {\"asset_id\":\"20893381255801015515826997628594359667013752732428989472914000440642900266717\", \"price\":\"0.72\", \"size\":\"100.99\", \"side\":\"BUY\", \"hash\":\"dcea98265d846862fd03f98bcca7a3e093bc43ef\", \"best_bid\":\"0.72\", \"best_ask\":\"0.74\"}], \"timestamp\":\"1785204817728\", \"event_type\":\"price_change\"}","received_at":"2026-07-28T02:13:37.612031Z","schema_version":"clob-market-ws.price_change.v1","sequence":null,"server_hash":null,"server_timestamp":"1785204817728","session_id":"d2757dd6dad94f3b9fe67e8dbf1adc37","source":"clob_market_ws"},"received_at":"2026-07-28T02:13:37.612031Z","record_id":"df297638773f3f6b6c06571540768a428e0db46d2a3b2155ea6cc41fe556fcab","schema_fingerprint":"4aa3821a28b0b7c2400bc59aba4bcc0a76e971dadd19610d3ad38c768e124dc7","schema_version":"edge-lab-recorder.raw.v1","sequence":null,"source":"clob_market_ws"}
{"event_at":"2026-07-28T02:13:37.730000Z","event_fingerprint":"fe99f685fbd986bd7409b9eb671f4348d18f8ffaf18d348354e32a1da8d274ac","payload":{"connection_id":"5d29200f65794d4d9ab6ef271f045a9b","event_at":"2026-07-28T02:13:37.730000Z","event_type":"price_change","frame_hash":"15550367d5b816f083a989c0da6f3e3ad1e35e4daff619104a1d5e296430acc1","frame_index":0,"kind":"data","monotonic_ns":306800624813208,"payload":{"event_type":"price_change","market":"0xda6f0e0e93fc8469e0159a166028d017bddbc162b86f66bac90391379603d962","price_changes":[{"asset_id":"20893381255801015515826997628594359667013752732428989472914000440642900266717","best_ask":"0.74","best_bid":"0.72","hash":"0ede68a34615bd8ab87d8c7c1209d795421367bd","price":"0.01","side":"BUY","size":"5374.02"},{"asset_id":"39272994714739463168905443499424551362424437245880253267329605556587274644733","best_ask":"0.28","best_bid":"0.26","hash":"3d103121d1f5a70a735f331311f15ba3c19a45f2","price":"0.99","side":"SELL","size":"5374.02"}],"timestamp":"1785204817730"},"payload_hash":"c7101794d0b450383b1eed63021e060fb3304a1e20dcd3ba481f8616b01f0633","raw_frame":"{\"market\":\"0xda6f0e0e93fc8469e0159a166028d017bddbc162b86f66bac90391379603d962\", \"price_changes\":[{\"asset_id\":\"20893381255801015515826997628594359667013752732428989472914000440642900266717\", \"price\":\"0.01\", \"size\":\"5374.02\", \"side\":\"BUY\", \"hash\":\"0ede68a34615bd8ab87d8c7c1209d795421367bd\", \"best_bid\":\"0.72\", \"best_ask\":\"0.74\"}, {\"asset_id\":\"39272994714739463168905443499424551362424437245880253267329605556587274644733\", \"price\":\"0.99\", \"size\":\"5374.02\", \"side\":\"SELL\", \"hash\":\"3d103121d1f5a70a735f331311f15ba3c19a45f2\", \"best_bid\":\"0.26\", \"best_ask\":\"0.28\"}], \"timestamp\":\"1785204817730\", \"event_type\":\"price_change\"}","received_at":"2026-07-28T02:13:37.613660Z","schema_version":"clob-market-ws.price_change.v1","sequence":null,"server_hash":null,"server_timestamp":"1785204817730","session_id":"d2757dd6dad94f3b9fe67e8dbf1adc37","source":"clob_market_ws"},"received_at":"2026-07-28T02:13:37.613660Z","record_id":"495a336f8a3bd0ff3eb499278859b882a06255a7f28fa3d8e6210c12934793e5","schema_fingerprint":"4aa3821a28b0b7c2400bc59aba4bcc0a76e971dadd19610d3ad38c768e124dc7","schema_version":"edge-lab-recorder.raw.v1","sequence":null,"source":"clob_market_ws"}
{"event_at":"2026-07-28T02:13:37.731000Z","event_fingerprint":"4a0be5bc20f34e6f81de16efa03456d47a5dea1ee8f238be4767dc69e180477c","payload":{"connection_id":"5d29200f65794d4d9ab6ef271f045a9b","event_at":"2026-07-28T02:13:37.731000Z","event_type":"price_change","frame_hash":"aab1fa802ecdae1d383c37c4a216171c7ed447de595134c72d7ee713a0ce349c","frame_index":0,"kind":"data","monotonic_ns":306800628249291,"payload":{"event_type":"price_change","market":"0xda6f0e0e93fc8469e0159a166028d017bddbc162b86f66bac90391379603d962","price_changes":[{"asset_id":"20893381255801015515826997628594359667013752732428989472914000440642900266717","best_ask":"0.74","best_bid":"0.72","hash":"d742820e18f4d8dcd9f99b5b1fe2e8e8b1c8981e","price":"0.7","side":"BUY","size":"32"},{"asset_id":"39272994714739463168905443499424551362424437245880253267329605556587274644733","best_ask":"0.28","best_bid":"0.26","hash":"b1a6b4e6c2431451cc8865d9c0767e696186bb97","price":"0.3","side":"SELL","size":"32"}],"timestamp":"1785204817731"},"payload_hash":"e76386dad48a00b60c813f6773b4ead53ce648f0193fd918fbfee71f7d9f976b","raw_frame":"{\"market\":\"0xda6f0e0e93fc8469e0159a166028d017bddbc162b86f66bac90391379603d962\", \"price_changes\":[{\"asset_id\":\"20893381255801015515826997628594359667013752732428989472914000440642900266717\", \"price\":\"0.7\", \"size\":\"32\", \"side\":\"BUY\", \"hash\":\"d742820e18f4d8dcd9f99b5b1fe2e8e8b1c8981e\", \"best_bid\":\"0.72\", \"best_ask\":\"0.74\"}, {\"asset_id\":\"39272994714739463168905443499424551362424437245880253267329605556587274644733\", \"price\":\"0.3\", \"size\":\"32\", \"side\":\"SELL\", \"hash\":\"b1a6b4e6c2431451cc8865d9c0767e696186bb97\", \"best_bid\":\"0.26\", \"best_ask\":\"0.28\"}], \"timestamp\":\"1785204817731\", \"event_type\":\"price_change\"}","received_at":"2026-07-28T02:13:37.617095Z","schema_version":"clob-market-ws.price_change.v1","sequence":null,"server_hash":null,"server_timestamp":"1785204817731","session_id":"d2757dd6dad94f3b9fe67e8dbf1adc37","source":"clob_market_ws"},"received_at":"2026-07-28T02:13:37.617095Z","record_id":"16e7be831ec427f547aba72cdf54c97405e0e97021ab1fa069f47e5d95bfd8e2","schema_fingerprint":"4aa3821a28b0b7c2400bc59aba4bcc0a76e971dadd19610d3ad38c768e124dc7","schema_version":"edge-lab-recorder.raw.v1","sequence":null,"source":"clob_market_ws"}
{"event_at":"2026-07-28T02:13:37.739000Z","event_fingerprint":"2aea0da7bfbef54e6e71dc8552b7110dafda7bdf954bd77752307ef56d140558","payload":{"connection_id":"5d29200f65794d4d9ab6ef271f045a9b","event_at":"2026-07-28T02:13:37.739000Z","event_type":"price_change","frame_hash":"567cd4ba600ee021345c935c22d6aaec8861446dda7ce8b39ebcc27a5befb110","frame_index":0,"kind":"data","monotonic_ns":306800632845000,"payload":{"event_type":"price_change","market":"0xda6f0e0e93fc8469e0159a166028d017bddbc162b86f66bac90391379603d962","price_changes":[{"asset_id":"20893381255801015515826997628594359667013752732428989472914000440642900266717","best_ask":"0.74","best_bid":"0.72","hash":"3ac3e9cadfe94f8ad60dfc05b99cf48e303c85ce","price":"0.03","side":"BUY","size":"559"},{"asset_id":"39272994714739463168905443499424551362424437245880253267329605556587274644733","best_ask":"0.28","best_bid":"0.26","hash":"6373f29e9d3a62e6a71dbfa607d073fb346058f2","price":"0.97","side":"SELL","size":"559"}],"timestamp":"1785204817739"},"payload_hash":"9a9ab7ea9f8f819e13d9aefd47f21eb24a5d6dff0b58aee23d03ed5a5196c252","raw_frame":"{\"market\":\"0xda6f0e0e93fc8469e0159a166028d017bddbc162b86f66bac90391379603d962\", \"price_changes\":[{\"asset_id\":\"20893381255801015515826997628594359667013752732428989472914000440642900266717\", \"price\":\"0.03\", \"size\":\"559\", \"side\":\"BUY\", \"hash\":\"3ac3e9cadfe94f8ad60dfc05b99cf48e303c85ce\", \"best_bid\":\"0.72\", \"best_ask\":\"0.74\"}, {\"asset_id\":\"39272994714739463168905443499424551362424437245880253267329605556587274644733\", \"price\":\"0.97\", \"size\":\"559\", \"side\":\"SELL\", \"hash\":\"6373f29e9d3a62e6a71dbfa607d073fb346058f2\", \"best_bid\":\"0.26\", \"best_ask\":\"0.28\"}], \"timestamp\":\"1785204817739\", \"event_type\":\"price_change\"}","received_at":"2026-07-28T02:13:37.621691Z","schema_version":"clob-market-ws.price_change.v1","sequence":null,"server_hash":null,"server_timestamp":"1785204817739","session_id":"d2757dd6dad94f3b9fe67e8dbf1adc37","source":"clob_market_ws"},"received_at":"2026-07-28T02:13:37.621691Z","record_id":"19f5c743e28bf0167747862aa04c608eeb31ae7e7e0a6e49b5c8e93eb152cb86","schema_fingerprint":"4aa3821a28b0b7c2400bc59aba4bcc0a76e971dadd19610d3ad38c768e124dc7","schema_version":"edge-lab-recorder.raw.v1","sequence":null,"source":"clob_market_ws"}
{"event_at":"2026-07-28T02:13:37.841000Z","event_fingerprint":"8a23796ed2c5c447d79270b7e42c3e7faf6812a5d9ee785ae383871e716670c5","payload":{"connection_id":"5d29200f65794d4d9ab6ef271f045a9b","event_at":"2026-07-28T02:13:37.841000Z","event_type":"price_change","frame_hash":"5e251da5084c76df893374918d7ec22deb420f6c450556445fe19e336d55320c","frame_index":0,"kind":"data","monotonic_ns":306800739679583,"payload":{"event_type":"price_change","market":"0xda6f0e0e93fc8469e0159a166028d017bddbc162b86f66bac90391379603d962","price_changes":[{"asset_id":"20893381255801015515826997628594359667013752732428989472914000440642900266717","best_ask":"0.74","best_bid":"0.72","hash":"380c095050c2f70a3d6b470bc644b793640b741b","price":"0.7","side":"BUY","size":"15"},{"asset_id":"39272994714739463168905443499424551362424437245880253267329605556587274644733","best_ask":"0.28","best_bid":"0.26","hash":"1124e32e500da3d974b509938991083791c00fc4","price":"0.3","side":"SELL","size":"15"}],"timestamp":"1785204817841"},"payload_hash":"6c1e13bfa329d07e0860aea32ae1fba9860a43a2f01e8cffc9ad1391f538acda","raw_frame":"{\"market\":\"0xda6f0e0e93fc8469e0159a166028d017bddbc162b86f66bac90391379603d962\", \"price_changes\":[{\"asset_id\":\"20893381255801015515826997628594359667013752732428989472914000440642900266717\", \"price\":\"0.7\", \"size\":\"15\", \"side\":\"BUY\", \"hash\":\"380c095050c2f70a3d6b470bc644b793640b741b\", \"best_bid\":\"0.72\", \"best_ask\":\"0.74\"}, {\"asset_id\":\"39272994714739463168905443499424551362424437245880253267329605556587274644733\", \"price\":\"0.3\", \"size\":\"15\", \"side\":\"SELL\", \"hash\":\"1124e32e500da3d974b509938991083791c00fc4\", \"best_bid\":\"0.26\", \"best_ask\":\"0.28\"}], \"timestamp\":\"1785204817841\", \"event_type\":\"price_change\"}","received_at":"2026-07-28T02:13:37.728526Z","schema_version":"clob-market-ws.price_change.v1","sequence":null,"server_hash":null,"server_timestamp":"1785204817841","session_id":"d2757dd6dad94f3b9fe67e8dbf1adc37","source":"clob_market_ws"},"received_at":"2026-07-28T02:13:37.728526Z","record_id":"70fce43e89876e65ebd8fb14a7e2a584e059fdceb5b0df6edc559b53332f8c4d","schema_fingerprint":"4aa3821a28b0b7c2400bc59aba4bcc0a76e971dadd19610d3ad38c768e124dc7","schema_version":"edge-lab-recorder.raw.v1","sequence":null,"source":"clob_market_ws"}
{"event_at":"2026-07-28T02:13:37.842000Z","event_fingerprint":"f9fc0b694128173fcdf735ee87fe7bef84c54abfaa4f19aaeb2e15d441cf54c0","payload":{"connection_id":"5d29200f65794d4d9ab6ef271f045a9b","event_at":"2026-07-28T02:13:37.842000Z","event_type":"price_change","frame_hash":"bfea84dcec2fd2a47d6438e2ef525b878fb3f4666742678866dd3617f7b072ad","frame_index":0,"kind":"data","monotonic_ns":306800742715625,"payload":{"event_type":"price_change","market":"0xda6f0e0e93fc8469e0159a166028d017bddbc162b86f66bac90391379603d962","price_changes":[{"asset_id":"39272994714739463168905443499424551362424437245880253267329605556587274644733","best_ask":"0.28","best_bid":"0.26","hash":"89b578726a9e05e41f3b91ea08e6e53e7dff88a4","price":"0.28","side":"SELL","size":"22.52"},{"asset_id":"20893381255801015515826997628594359667013752732428989472914000440642900266717","best_ask":"0.74","best_bid":"0.72","hash":"030e3d3f82ba438273c3a0e5e63178b025d15bef","price":"0.72","side":"BUY","size":"22.52"}],"timestamp":"1785204817842"},"payload_hash":"6e51bc52a2615f957090de437126047337cd6145104f5b21e51405978b8bef96","raw_frame":"{\"market\":\"0xda6f0e0e93fc8469e0159a166028d017bddbc162b86f66bac90391379603d962\", \"price_changes\":[{\"asset_id\":\"39272994714739463168905443499424551362424437245880253267329605556587274644733\", \"price\":\"0.28\", \"size\":\"22.52\", \"side\":\"SELL\", \"hash\":\"89b578726a9e05e41f3b91ea08e6e53e7dff88a4\", \"best_bid\":\"0.26\", \"best_ask\":\"0.28\"}, {\"asset_id\":\"20893381255801015515826997628594359667013752732428989472914000440642900266717\", \"price\":\"0.72\", \"size\":\"22.52\", \"side\":\"BUY\", \"hash\":\"030e3d3f82ba438273c3a0e5e63178b025d15bef\", \"best_bid\":\"0.72\", \"best_ask\":\"0.74\"}], \"timestamp\":\"1785204817842\", \"event_type\":\"price_change\"}","received_at":"2026-07-28T02:13:37.731562Z","schema_version":"clob-market-ws.price_change.v1","sequence":null,"server_hash":null,"server_timestamp":"1785204817842","session_id":"d2757dd6dad94f3b9fe67e8dbf1adc37","source":"clob_market_ws"},"received_at":"2026-07-28T02:13:37.731562Z","record_id":"7b72cd21965b49727a1289c83d00c763500e256db3872ddc10d56310d79a46d9","schema_fingerprint":"4aa3821a28b0b7c2400bc59aba4bcc0a76e971dadd19610d3ad38c768e124dc7","schema_version":"edge-lab-recorder.raw.v1","sequence":null,"source":"clob_market_ws"}
{"event_at":"2026-07-28T02:13:37.842000Z","event_fingerprint":"b81d1e64a10097f5517c70206b0d9dbc47a2f6e06418abf2012de025f66732af","payload":{"connection_id":"5d29200f65794d4d9ab6ef271f045a9b","event_at":"2026-07-28T02:13:37.842000Z","event_type":"price_change","frame_hash":"ce9934bf8f7416d81662758e869acf09e626feb2a2e87c264e403b4f6673a3be","frame_index":0,"kind":"data","monotonic_ns":306800745125250,"payload":{"event_type":"price_change","market":"0xda6f0e0e93fc8469e0159a166028d017bddbc162b86f66bac90391379603d962","price_changes":[{"asset_id":"20893381255801015515826997628594359667013752732428989472914000440642900266717","best_ask":"0.74","best_bid":"0.72","hash":"7a6979aef84c5418bfb38c1dd80f366008a56c58","price":"0.81","side":"SELL","size":"252"},{"asset_id":"39272994714739463168905443499424551362424437245880253267329605556587274644733","best_ask":"0.28","best_bid":"0.26","hash":"de8f793edc20688589ed090346cdcd8e74c02983","price":"0.19","side":"BUY","size":"252"}],"timestamp":"1785204817842"},"payload_hash":"3ee8a7f5b2f61d81c0156048e8e9c9a2ea4a578d2cfae117ef489534d2aba7e4","raw_frame":"{\"market\":\"0xda6f0e0e93fc8469e0159a166028d017bddbc162b86f66bac90391379603d962\", \"price_changes\":[{\"asset_id\":\"20893381255801015515826997628594359667013752732428989472914000440642900266717\", \"price\":\"0.81\", \"size\":\"252\", \"side\":\"SELL\", \"hash\":\"7a6979aef84c5418bfb38c1dd80f366008a56c58\", \"best_bid\":\"0.72\", \"best_ask\":\"0.74\"}, {\"asset_id\":\"39272994714739463168905443499424551362424437245880253267329605556587274644733\", \"price\":\"0.19\", \"size\":\"252\", \"side\":\"BUY\", \"hash\":\"de8f793edc20688589ed090346cdcd8e74c02983\", \"best_bid\":\"0.26\", \"best_ask\":\"0.28\"}], \"timestamp\":\"1785204817842\", \"event_type\":\"price_change\"}","received_at":"2026-07-28T02:13:37.733971Z","schema_version":"clob-market-ws.price_change.v1","sequence":null,"server_hash":null,"server_timestamp":"1785204817842","session_id":"d2757dd6dad94f3b9fe67e8dbf1adc37","source":"clob_market_ws"},"received_at":"2026-07-28T02:13:37.733971Z","record_id":"a1232f63d304177c6c50e7061520890cc83861d6d0140591dbfa2418085fce33","schema_fingerprint":"4aa3821a28b0b7c2400bc59aba4bcc0a76e971dadd19610d3ad38c768e124dc7","schema_version":"edge-lab-recorder.raw.v1","sequence":null,"source":"clob_market_ws"}
{"event_at":"2026-07-28T02:13:37.846000Z","event_fingerprint":"4d17f431f1d9ef419939c839969aaf76452d47d9c79e007e9e02a64dc03a122b","payload":{"connection_id":"5d29200f65794d4d9ab6ef271f045a9b","event_at":"2026-07-28T02:13:37.846000Z","event_type":"price_change","frame_hash":"f89748ced1bcdacf7c372090f204e6ed9b185178bbef73a4d3a7e59c7533a7f8","frame_index":0,"kind":"data","monotonic_ns":306800746621791,"payload":{"event_type":"price_change","market":"0xda6f0e0e93fc8469e0159a166028d017bddbc162b86f66bac90391379603d962","price_changes":[{"asset_id":"20893381255801015515826997628594359667013752732428989472914000440642900266717","best_ask":"0.74","best_bid":"0.72","hash":"33cc10ea300fd7e11ad1288194dad776f6377d4d","price":"0.72","side":"BUY","size":"102.99"},{"asset_id":"39272994714739463168905443499424551362424437245880253267329605556587274644733","best_ask":"0.28","best_bid":"0.26","hash":"2a9581004fecb5cf7aef295cf8583277b2936e36","price":"0.28","side":"SELL","size":"102.99"}],"timestamp":"1785204817846"},"payload_hash":"c6a7433731886ed4b51e02969cc020617c448d75a32228bc6fe6dc512dc56812","raw_frame":"{\"market\":\"0xda6f0e0e93fc8469e0159a166028d017bddbc162b86f66bac90391379603d962\", \"price_changes\":[{\"asset_id\":\"20893381255801015515826997628594359667013752732428989472914000440642900266717\", \"price\":\"0.72\", \"size\":\"102.99\", \"side\":\"BUY\", \"hash\":\"33cc10ea300fd7e11ad1288194dad776f6377d4d\", \"best_bid\":\"0.72\", \"best_ask\":\"0.74\"}, {\"asset_id\":\"39272994714739463168905443499424551362424437245880253267329605556587274644733\", \"price\":\"0.28\", \"size\":\"102.99\", \"side\":\"SELL\", \"hash\":\"2a9581004fecb5cf7aef295cf8583277b2936e36\", \"best_bid\":\"0.26\", \"best_ask\":\"0.28\"}], \"timestamp\":\"1785204817846\", \"event_type\":\"price_change\"}","received_at":"2026-07-28T02:13:37.735466Z","schema_version":"clob-market-ws.price_change.v1","sequence":null,"server_hash":null,"server_timestamp":"1785204817846","session_id":"d2757dd6dad94f3b9fe67e8dbf1adc37","source":"clob_market_ws"},"received_at":"2026-07-28T02:13:37.735466Z","record_id":"b59f2a74a0af8f7c0e7a15e989fec3a0e73c1d122399fa9a94bdadf678536e8a","schema_fingerprint":"4aa3821a28b0b7c2400bc59aba4bcc0a76e971dadd19610d3ad38c768e124dc7","schema_version":"edge-lab-recorder.raw.v1","sequence":null,"source":"clob_market_ws"}
{"event_at":"2026-07-28T02:13:37.869000Z","event_fingerprint":"6cea576758a4e54b84b2421be21de00362f80fc8b39ecd85bf649820358a48b9","payload":{"connection_id":"5d29200f65794d4d9ab6ef271f045a9b","event_at":"2026-07-28T02:13:37.869000Z","event_type":"price_change","frame_hash":"6a3e07b717eda713f9ce415f0d620e2b657fb725d8497748804ac5820ef78fd4","frame_index":0,"kind":"data","monotonic_ns":306800769926041,"payload":{"event_type":"price_change","market":"0xda6f0e0e93fc8469e0159a166028d017bddbc162b86f66bac90391379603d962","price_changes":[{"asset_id":"20893381255801015515826997628594359667013752732428989472914000440642900266717","best_ask":"0.74","best_bid":"0.72","hash":"ffc3f2043dfed705ebaa44da4bb3f46b004b3692","price":"0.03","side":"BUY","size":"554"},{"asset_id":"39272994714739463168905443499424551362424437245880253267329605556587274644733","best_ask":"0.28","best_bid":"0.26","hash":"937afa08c7e281b8870fe25f2b10ece1a24e88dc","price":"0.97","side":"SELL","size":"554"}],"timestamp":"1785204817869"},"payload_hash":"a827f4d7ae1feaea9376cde08df419a427ed27dc2f9366f391fdab23a618a562","raw_frame":"{\"market\":\"0xda6f0e0e93fc8469e0159a166028d017bddbc162b86f66bac90391379603d962\", \"price_changes\":[{\"asset_id\":\"20893381255801015515826997628594359667013752732428989472914000440642900266717\", \"price\":\"0.03\", \"size\":\"554\", \"side\":\"BUY\", \"hash\":\"ffc3f2043dfed705ebaa44da4bb3f46b004b3692\", \"best_bid\":\"0.72\", \"best_ask\":\"0.74\"}, {\"asset_id\":\"39272994714739463168905443499424551362424437245880253267329605556587274644733\", \"price\":\"0.97\", \"size\":\"554\", \"side\":\"SELL\", \"hash\":\"937afa08c7e281b8870fe25f2b10ece1a24e88dc\", \"best_bid\":\"0.26\", \"best_ask\":\"0.28\"}], \"timestamp\":\"1785204817869\", \"event_type\":\"price_change\"}","received_at":"2026-07-28T02:13:37.758771Z","schema_version":"clob-market-ws.price_change.v1","sequence":null,"server_hash":null,"server_timestamp":"1785204817869","session_id":"d2757dd6dad94f3b9fe67e8dbf1adc37","source":"clob_market_ws"},"received_at":"2026-07-28T02:13:37.758771Z","record_id":"39bfd38520ca5fcc074b43c196be36e4c0e012ce96369f69a602c3e0c7c7d2d2","schema_fingerprint":"4aa3821a28b0b7c2400bc59aba4bcc0a76e971dadd19610d3ad38c768e124dc7","schema_version":"edge-lab-recorder.raw.v1","sequence":null,"source":"clob_market_ws"}
{"event_at":"2026-07-28T02:13:37.886000Z","event_fingerprint":"a1836ed0cb4baf55f1f1478a483c6b09ed33eb742609296ce649c38a26046265","payload":{"connection_id":"5d29200f65794d4d9ab6ef271f045a9b","event_at":"2026-07-28T02:13:37.886000Z","event_type":"price_change","frame_hash":"d1963f2a2e19023b84bcf0c27834e8f22cf93a88560fba000cb791d145bb6cca","frame_index":0,"kind":"data","monotonic_ns":306800781504375,"payload":{"event_type":"price_change","market":"0xda6f0e0e93fc8469e0159a166028d017bddbc162b86f66bac90391379603d962","price_changes":[{"asset_id":"20893381255801015515826997628594359667013752732428989472914000440642900266717","best_ask":"0.74","best_bid":"0.72","hash":"29e474f8533c170f45ec846086eda8a66b07f37d","price":"0.72","side":"BUY","size":"92.99"},{"asset_id":"39272994714739463168905443499424551362424437245880253267329605556587274644733","best_ask":"0.28","best_bid":"0.26","hash":"e107f76ed125263ec9a7bed83e7743184426e6da","price":"0.28","side":"SELL","size":"92.99"}],"timestamp":"1785204817886"},"payload_hash":"0f5cdbb831b4a88bf6aceb1949d618910993510daafa56f9dd10a268f9d30413","raw_frame":"{\"market\":\"0xda6f0e0e93fc8469e0159a166028d017bddbc162b86f66bac90391379603d962\", \"price_changes\":[{\"asset_id\":\"20893381255801015515826997628594359667013752732428989472914000440642900266717\", \"price\":\"0.72\", \"size\":\"92.99\", \"side\":\"BUY\", \"hash\":\"29e474f8533c170f45ec846086eda8a66b07f37d\", \"best_bid\":\"0.72\", \"best_ask\":\"0.74\"}, {\"asset_id\":\"39272994714739463168905443499424551362424437245880253267329605556587274644733\", \"price\":\"0.28\", \"size\":\"92.99\", \"side\":\"SELL\", \"hash\":\"e107f76ed125263ec9a7bed83e7743184426e6da\", \"best_bid\":\"0.26\", \"best_ask\":\"0.28\"}], \"timestamp\":\"1785204817886\", \"event_type\":\"price_change\"}","received_at":"2026-07-28T02:13:37.770348Z","schema_version":"clob-market-ws.price_change.v1","sequence":null,"server_hash":null,"server_timestamp":"1785204817886","session_id":"d2757dd6dad94f3b9fe67e8dbf1adc37","source":"clob_market_ws"},"received_at":"2026-07-28T02:13:37.770348Z","record_id":"d8922dc055c785c203d37d5f03bdbc5091792ebb9919f3923710b8882d1e0fe0","schema_fingerprint":"4aa3821a28b0b7c2400bc59aba4bcc0a76e971dadd19610d3ad38c768e124dc7","schema_version":"edge-lab-recorder.raw.v1","sequence":null,"source":"clob_market_ws"}
{"event_at":"2026-07-28T02:13:37.914000Z","event_fingerprint":"308d93bf370d349465fe03ee2713ea35a3de39ec239c19f8799b2ce11b5af664","payload":{"connection_id":"5d29200f65794d4d9ab6ef271f045a9b","event_at":"2026-07-28T02:13:37.914000Z","event_type":"price_change","frame_hash":"7e0d1adc600285d11e4a8eb352ee14ab063cfad38b89e7f2fc3f8ff5ea222024","frame_index":0,"kind":"data","monotonic_ns":306800817641583,"payload":{"event_type":"price_change","market":"0xda6f0e0e93fc8469e0159a166028d017bddbc162b86f66bac90391379603d962","price_changes":[{"asset_id":"20893381255801015515826997628594359667013752732428989472914000440642900266717","best_ask":"0.74","best_bid":"0.72","hash":"56809d61ab43c75130258fd555abde5fb2e8ce67","price":"0.66","side":"BUY","size":"69"},{"asset_id":"39272994714739463168905443499424551362424437245880253267329605556587274644733","best_ask":"0.28","best_bid":"0.26","hash":"f660ed82f1269bdb235bb9c151fbc95d3ef44973","price":"0.34","side":"SELL","size":"69"}],"timestamp":"1785204817914"},"payload_hash":"4ccb76a4b1b4b886edd291d2e238b957786d3753b6b1b3f0e57c852cb48ba79f","raw_frame":"{\"market\":\"0xda6f0e0e93fc8469e0159a166028d017bddbc162b86f66bac90391379603d962\", \"price_changes\":[{\"asset_id\":\"20893381255801015515826997628594359667013752732428989472914000440642900266717\", \"price\":\"0.66\", \"size\":\"69\", \"side\":\"BUY\", \"hash\":\"56809d61ab43c75130258fd555abde5fb2e8ce67\", \"best_bid\":\"0.72\", \"best_ask\":\"0.74\"}, {\"asset_id\":\"39272994714739463168905443499424551362424437245880253267329605556587274644733\", \"price\":\"0.34\", \"size\":\"69\", \"side\":\"SELL\", \"hash\":\"f660ed82f1269bdb235bb9c151fbc95d3ef44973\", \"best_bid\":\"0.26\", \"best_ask\":\"0.28\"}], \"timestamp\":\"1785204817914\", \"event_type\":\"price_change\"}","received_at":"2026-07-28T02:13:37.806484Z","schema_version":"clob-market-ws.price_change.v1","sequence":null,"server_hash":null,"server_timestamp":"1785204817914","session_id":"d2757dd6dad94f3b9fe67e8dbf1adc37","source":"clob_market_ws"},"received_at":"2026-07-28T02:13:37.806484Z","record_id":"ba5d9db0af1b5b88d6b3e6167b436b4299d1c0dcc7c99c10b8916c21f4059b01","schema_fingerprint":"4aa3821a28b0b7c2400bc59aba4bcc0a76e971dadd19610d3ad38c768e124dc7","schema_version":"edge-lab-recorder.raw.v1","sequence":null,"source":"clob_market_ws"}
{"event_at":"2026-07-28T02:13:37.956000Z","event_fingerprint":"89d7937cd7357d4c535bebdb360fd2e989496135ec32edfd7de9053d9e8cddb1","payload":{"connection_id":"5d29200f65794d4d9ab6ef271f045a9b","event_at":"2026-07-28T02:13:37.956000Z","event_type":"price_change","frame_hash":"d8e5a1875bd371124d56da4ad510e7411853921ad2ef934d4a2c877509764b21","frame_index":0,"kind":"data","monotonic_ns":306800855377958,"payload":{"event_type":"price_change","market":"0xda6f0e0e93fc8469e0159a166028d017bddbc162b86f66bac90391379603d962","price_changes":[{"asset_id":"20893381255801015515826997628594359667013752732428989472914000440642900266717","best_ask":"0.74","best_bid":"0.72","hash":"647cb8fefae06ebe54a661ca693b50d5ea03819c","price":"0.72","side":"BUY","size":"12.52"},{"asset_id":"39272994714739463168905443499424551362424437245880253267329605556587274644733","best_ask":"0.28","best_bid":"0.26","hash":"fd83964c2b1b5916018ac3fa9ef49324b87d9357","price":"0.28","side":"SELL","size":"12.52"}],"timestamp":"1785204817956"},"payload_hash":"e52a5bffc12d212d2d12f065718a283f6a075ec2a47ebd21ae14e51920fe32f6","raw_frame":"{\"market\":\"0xda6f0e0e93fc8469e0159a166028d017bddbc162b86f66bac90391379603d962\", \"price_changes\":[{\"asset_id\":\"20893381255801015515826997628594359667013752732428989472914000440642900266717\", \"price\":\"0.72\", \"size\":\"12.52\", \"side\":\"BUY\", \"hash\":\"647cb8fefae06ebe54a661ca693b50d5ea03819c\", \"best_bid\":\"0.72\", \"best_ask\":\"0.74\"}, {\"asset_id\":\"39272994714739463168905443499424551362424437245880253267329605556587274644733\", \"price\":\"0.28\", \"size\":\"12.52\", \"side\":\"SELL\", \"hash\":\"fd83964c2b1b5916018ac3fa9ef49324b87d9357\", \"best_bid\":\"0.26\", \"best_ask\":\"0.28\"}], \"timestamp\":\"1785204817956\", \"event_type\":\"price_change\"}","received_at":"2026-07-28T02:13:37.844220Z","schema_version":"clob-market-ws.price_change.v1","sequence":null,"server_hash":null,"server_timestamp":"1785204817956","session_id":"d2757dd6dad94f3b9fe67e8dbf1adc37","source":"clob_market_ws"},"received_at":"2026-07-28T02:13:37.844220Z","record_id":"19f3038ba4b6512e4194d5d56a8c67b9ee3dfde4cd68c6b48d901662cabe8058","schema_fingerprint":"4aa3821a28b0b7c2400bc59aba4bcc0a76e971dadd19610d3ad38c768e124dc7","schema_version":"edge-lab-recorder.raw.v1","sequence":null,"source":"clob_market_ws"}
{"event_at":"2026-07-28T02:13:37.958000Z","event_fingerprint":"cc3705816287156faf1eae529d6ce1d5486fa768fc4ff575ab8fa2338ad04d0f","payload":{"connection_id":"5d29200f65794d4d9ab6ef271f045a9b","event_at":"2026-07-28T02:13:37.958000Z","event_type":"price_change","frame_hash":"355d6552ee9caa186511ff7d91426c61b93b9cd58a9278e624aee665868796e2","frame_index":0,"kind":"data","monotonic_ns":306800856943250,"payload":{"event_type":"price_change","market":"0xda6f0e0e93fc8469e0159a166028d017bddbc162b86f66bac90391379603d962","price_changes":[{"asset_id":"39272994714739463168905443499424551362424437245880253267329605556587274644733","best_ask":"0.28","best_bid":"0.26","hash":"feabd656e856e212f88d52b7efb44452faa019ef","price":"0.28","side":"SELL","size":"90.99"},{"asset_id":"20893381255801015515826997628594359667013752732428989472914000440642900266717","best_ask":"0.74","best_bid":"0.72","hash":"eeaaafbb9a3637d69ec1647262e7f3782183d9ad","price":"0.72","side":"BUY","size":"90.99"}],"timestamp":"1785204817958"},"payload_hash":"3962ce3555ffb022e4324a279f4401080280ea6a10b5feba09199a8ed9379b01","raw_frame":"{\"market\":\"0xda6f0e0e93fc8469e0159a166028d017bddbc162b86f66bac90391379603d962\", \"price_changes\":[{\"asset_id\":\"39272994714739463168905443499424551362424437245880253267329605556587274644733\", \"price\":\"0.28\", \"size\":\"90.99\", \"side\":\"SELL\", \"hash\":\"feabd656e856e212f88d52b7efb44452faa019ef\", \"best_bid\":\"0.26\", \"best_ask\":\"0.28\"}, {\"asset_id\":\"20893381255801015515826997628594359667013752732428989472914000440642900266717\", \"price\":\"0.72\", \"size\":\"90.99\", \"side\":\"BUY\", \"hash\":\"eeaaafbb9a3637d69ec1647262e7f3782183d9ad\", \"best_bid\":\"0.72\", \"best_ask\":\"0.74\"}], \"timestamp\":\"1785204817958\", \"event_type\":\"price_change\"}","received_at":"2026-07-28T02:13:37.845787Z","schema_version":"clob-market-ws.price_change.v1","sequence":null,"server_hash":null,"server_timestamp":"1785204817958","session_id":"d2757dd6dad94f3b9fe67e8dbf1adc37","source":"clob_market_ws"},"received_at":"2026-07-28T02:13:37.845787Z","record_id":"fc815158e285556ac0f6df43ef23dcfdf610cc7130f2920330802f8977dd6dff","schema_fingerprint":"4aa3821a28b0b7c2400bc59aba4bcc0a76e971dadd19610d3ad38c768e124dc7","schema_version":"edge-lab-recorder.raw.v1","sequence":null,"source":"clob_market_ws"}
{"event_at":"2026-07-28T02:13:37.959000Z","event_fingerprint":"dc693c210a0f889ced883316172151a4c96dda18b7ce83209ba521589cfa2d3c","payload":{"connection_id":"5d29200f65794d4d9ab6ef271f045a9b","event_at":"2026-07-28T02:13:37.959000Z","event_type":"price_change","frame_hash":"f4053f8e94e38f7dda2c8bcdba983c4697c8c2e79c9ea9e4a3e2fe88c13c1409","frame_index":0,"kind":"data","monotonic_ns":306800858508875,"payload":{"event_type":"price_change","market":"0xda6f0e0e93fc8469e0159a166028d017bddbc162b86f66bac90391379603d962","price_changes":[{"asset_id":"20893381255801015515826997628594359667013752732428989472914000440642900266717","best_ask":"0.74","best_bid":"0.72","hash":"cf71e37e59cbe286e52249838b0fa10209988b04","price":"0.7","side":"BUY","size":"32"},{"asset_id":"39272994714739463168905443499424551362424437245880253267329605556587274644733","best_ask":"0.28","best_bid":"0.26","hash":"c83347136355fd1024945aaf5d95cb0d6426916d","price":"0.3","side":"SELL","size":"32"}],"timestamp":"1785204817959"},"payload_hash":"2177f2f300d95084255beb14bcd31b2ce8ae5f9406e412f106ccc72078094a63","raw_frame":"{\"market\":\"0xda6f0e0e93fc8469e0159a166028d017bddbc162b86f66bac90391379603d962\", \"price_changes\":[{\"asset_id\":\"20893381255801015515826997628594359667013752732428989472914000440642900266717\", \"price\":\"0.7\", \"size\":\"32\", \"side\":\"BUY\", \"hash\":\"cf71e37e59cbe286e52249838b0fa10209988b04\", \"best_bid\":\"0.72\", \"best_ask\":\"0.74\"}, {\"asset_id\":\"39272994714739463168905443499424551362424437245880253267329605556587274644733\", \"price\":\"0.3\", \"size\":\"32\", \"side\":\"SELL\", \"hash\":\"c83347136355fd1024945aaf5d95cb0d6426916d\", \"best_bid\":\"0.26\", \"best_ask\":\"0.28\"}], \"timestamp\":\"1785204817959\", \"event_type\":\"price_change\"}","received_at":"2026-07-28T02:13:37.847346Z","schema_version":"clob-market-ws.price_change.v1","sequence":null,"server_hash":null,"server_timestamp":"1785204817959","session_id":"d2757dd6dad94f3b9fe67e8dbf1adc37","source":"clob_market_ws"},"received_at":"2026-07-28T02:13:37.847346Z","record_id":"7b09239575736f9e65955404f8d34f74cadbb5560c4033d293b3b931509179c4","schema_fingerprint":"4aa3821a28b0b7c2400bc59aba4bcc0a76e971dadd19610d3ad38c768e124dc7","schema_version":"edge-lab-recorder.raw.v1","sequence":null,"source":"clob_market_ws"}
{"event_at":"2026-07-28T02:13:37.960000Z","event_fingerprint":"6438fc2f391cc24426e950dab0450a933fb8ce015ee0bf3e85679fd770ba50c4","payload":{"connection_id":"5d29200f65794d4d9ab6ef271f045a9b","event_at":"2026-07-28T02:13:37.960000Z","event_type":"price_change","frame_hash":"9159e8b31a189c2ee91e98f4b40c2cb85cb4e1560141ec59312c099f689e27cf","frame_index":0,"kind":"data","monotonic_ns":306800861676500,"payload":{"event_type":"price_change","market":"0xda6f0e0e93fc8469e0159a166028d017bddbc162b86f66bac90391379603d962","price_changes":[{"asset_id":"20893381255801015515826997628594359667013752732428989472914000440642900266717","best_ask":"0.74","best_bid":"0.72","hash":"de3ec5aa2704a377f5ac0b8b8785a650dae001d2","price":"0.82","side":"SELL","size":"240.85"},{"asset_id":"39272994714739463168905443499424551362424437245880253267329605556587274644733","best_ask":"0.28","best_bid":"0.26","hash":"b7f2b3d870f0aef7243e9ec56389bde1d8ba2c93","price":"0.18","side":"BUY","size":"240.85"}],"timestamp":"1785204817960"},"payload_hash":"43f238c897099bc2a6592ae44a7be282af4163a2bdfccf9ce327cb5bbc43318b","raw_frame":"{\"market\":\"0xda6f0e0e93fc8469e0159a166028d017bddbc162b86f66bac90391379603d962\", \"price_changes\":[{\"asset_id\":\"20893381255801015515826997628594359667013752732428989472914000440642900266717\", \"price\":\"0.82\", \"size\":\"240.85\", \"side\":\"SELL\", \"hash\":\"de3ec5aa2704a377f5ac0b8b8785a650dae001d2\", \"best_bid\":\"0.72\", \"best_ask\":\"0.74\"}, {\"asset_id\":\"39272994714739463168905443499424551362424437245880253267329605556587274644733\", \"price\":\"0.18\", \"size\":\"240.85\", \"side\":\"BUY\", \"hash\":\"b7f2b3d870f0aef7243e9ec56389bde1d8ba2c93\", \"best_bid\":\"0.26\", \"best_ask\":\"0.28\"}], \"timestamp\":\"1785204817960\", \"event_type\":\"price_change\"}","received_at":"2026-07-28T02:13:37.850520Z","schema_version":"clob-market-ws.price_change.v1","sequence":null,"server_hash":null,"server_timestamp":"1785204817960","session_id":"d2757dd6dad94f3b9fe67e8dbf1adc37","source":"clob_market_ws"},"received_at":"2026-07-28T02:13:37.850520Z","record_id":"07401ceeac50a33664e35f225008b7202f2e0d7a15734f604e6b643522f1bf8f","schema_fingerprint":"4aa3821a28b0b7c2400bc59aba4bcc0a76e971dadd19610d3ad38c768e124dc7","schema_version":"edge-lab-recorder.raw.v1","sequence":null,"source":"clob_market_ws"}
{"event_at":"2026-07-28T02:13:37.984000Z","event_fingerprint":"5bf5074144b988d057d072de9b024071cc29afd9609ff022eb75c918bdfa0f72","payload":{"connection_id":"5d29200f65794d4d9ab6ef271f045a9b","event_at":"2026-07-28T02:13:37.984000Z","event_type":"price_change","frame_hash":"86b3228226fd776fa60f2f6d13167e887358309300a3b72bfd2f19d28441ac3c","frame_index":0,"kind":"data","monotonic_ns":306800879392833,"payload":{"event_type":"price_change","market":"0xda6f0e0e93fc8469e0159a166028d017bddbc162b86f66bac90391379603d962","price_changes":[{"asset_id":"20893381255801015515826997628594359667013752732428989472914000440642900266717","best_ask":"0.74","best_bid":"0.72","hash":"517d672634925fdaaa895a94763d494d2b365585","price":"0.04","side":"BUY","size":"589"},{"asset_id":"39272994714739463168905443499424551362424437245880253267329605556587274644733","best_ask":"0.28","best_bid":"0.26","hash":"3c78a60c7c67a90b685c97bfb7399da1bb5077a7","price":"0.96","side":"SELL","size":"589"}],"timestamp":"1785204817984"},"payload_hash":"6c320373ba4532cefbd2e7d7bd489e4f961b19e88a55e7c3dcc21666bad76557","raw_frame":"{\"market\":\"0xda6f0e0e93fc8469e0159a166028d017bddbc162b86f66bac90391379603d962\", \"price_changes\":[{\"asset_id\":\"20893381255801015515826997628594359667013752732428989472914000440642900266717\", \"price\":\"0.04\", \"size\":\"589\", \"side\":\"BUY\", \"hash\":\"517d672634925fdaaa895a94763d494d2b365585\", \"best_bid\":\"0.72\", \"best_ask\":\"0.74\"}, {\"asset_id\":\"39272994714739463168905443499424551362424437245880253267329605556587274644733\", \"price\":\"0.96\", \"size\":\"589\", \"side\":\"SELL\", \"hash\":\"3c78a60c7c67a90b685c97bfb7399da1bb5077a7\", \"best_bid\":\"0.26\", \"best_ask\":\"0.28\"}], \"timestamp\":\"1785204817984\", \"event_type\":\"price_change\"}","received_at":"2026-07-28T02:13:37.868231Z","schema_version":"clob-market-ws.price_change.v1","sequence":null,"server_hash":null,"server_timestamp":"1785204817984","session_id":"d2757dd6dad94f3b9fe67e8dbf1adc37","source":"clob_market_ws"},"received_at":"2026-07-28T02:13:37.868231Z","record_id":"69ed46e195d2e253661ac3e16b375ef0bbcb2aefeeea7d6a8565c1e3f6182c60","schema_fingerprint":"4aa3821a28b0b7c2400bc59aba4bcc0a76e971dadd19610d3ad38c768e124dc7","schema_version":"edge-lab-recorder.raw.v1","sequence":null,"source":"clob_market_ws"}
{"event_at":"2026-07-28T02:13:38.003000Z","event_fingerprint":"7b4360c81477125bfb1b934f1120836779ca742a1da2ed6e6b09ee6447de69f7","payload":{"connection_id":"5d29200f65794d4d9ab6ef271f045a9b","event_at":"2026-07-28T02:13:38.003000Z","event_type":"price_change","frame_hash":"b7932ba37860ec90fc15885d2fb3f9e6eb5e6a6ca9ab4e03d1e733e57e7ea12e","frame_index":0,"kind":"data","monotonic_ns":306800897425583,"payload":{"event_type":"price_change","market":"0xda6f0e0e93fc8469e0159a166028d017bddbc162b86f66bac90391379603d962","price_changes":[{"asset_id":"20893381255801015515826997628594359667013752732428989472914000440642900266717","best_ask":"0.74","best_bid":"0.72","hash":"3ba3fd852a146f9d3fbcaa591296991944f625a0","price":"0.61","side":"BUY","size":"79"},{"asset_id":"39272994714739463168905443499424551362424437245880253267329605556587274644733","best_ask":"0.28","best_bid":"0.26","hash":"4bea9d40cccc3804b5d11cc977ee83901dda7c31","price":"0.39","side":"SELL","size":"79"}],"timestamp":"1785204818003"},"payload_hash":"1a0aac729ae1a7e605c87fdf14a68263004be3b2fe82aec61a508cf8a3daa860","raw_frame":"{\"market\":\"0xda6f0e0e93fc8469e0159a166028d017bddbc162b86f66bac90391379603d962\", \"price_changes\":[{\"asset_id\":\"20893381255801015515826997628594359667013752732428989472914000440642900266717\", \"price\":\"0.61\", \"size\":\"79\", \"side\":\"BUY\", \"hash\":\"3ba3fd852a146f9d3fbcaa591296991944f625a0\", \"best_bid\":\"0.72\", \"best_ask\":\"0.74\"}, {\"asset_id\":\"39272994714739463168905443499424551362424437245880253267329605556587274644733\", \"price\":\"0.39\", \"size\":\"79\", \"side\":\"SELL\", \"hash\":\"4bea9d40cccc3804b5d11cc977ee83901dda7c31\", \"best_bid\":\"0.26\", \"best_ask\":\"0.28\"}], \"timestamp\":\"1785204818003\", \"event_type\":\"price_change\"}","received_at":"2026-07-28T02:13:37.886269Z","schema_version":"clob-market-ws.price_change.v1","sequence":null,"server_hash":null,"server_timestamp":"1785204818003","session_id":"d2757dd6dad94f3b9fe67e8dbf1adc37","source":"clob_market_ws"},"received_at":"2026-07-28T02:13:37.886269Z","record_id":"15f846b559833e70f490c1c666d95834d25bdd0b0b6ddc534d6bd5513a4a8f35","schema_fingerprint":"4aa3821a28b0b7c2400bc59aba4bcc0a76e971dadd19610d3ad38c768e124dc7","schema_version":"edge-lab-recorder.raw.v1","sequence":null,"source":"clob_market_ws"}
{"event_at":"2026-07-28T02:13:38.005000Z","event_fingerprint":"1351a2d2ec511a186e341b14fba2f81e1ae6d72cb6f41654bc8ce0c955309a97","payload":{"connection_id":"5d29200f65794d4d9ab6ef271f045a9b","event_at":"2026-07-28T02:13:38.005000Z","event_type":"price_change","frame_hash":"dc5c75507a4a8a327a5e965e71ec8ee764e77bf9dead3c462a47175c3723a325","frame_index":0,"kind":"data","monotonic_ns":306800907131958,"payload":{"event_type":"price_change","market":"0xda6f0e0e93fc8469e0159a166028d017bddbc162b86f66bac90391379603d962","price_changes":[{"asset_id":"20893381255801015515826997628594359667013752732428989472914000440642900266717","best_ask":"0.74","best_bid":"0.72","hash":"1f1c19359565e3a25042a4d20a474461480cadf6","price":"0.68","side":"BUY","size":"69"},{"asset_id":"39272994714739463168905443499424551362424437245880253267329605556587274644733","best_ask":"0.28","best_bid":"0.26","hash":"6ee231bc603bcec4b7bbc1548c2d7bbd09caf344","price":"0.32","side":"SELL","size":"69"}],"timestamp":"1785204818005"},"payload_hash":"c7af0c1e9c7b4a5d163646947902cb368d00d2a9ec8223272f0b7a1cdcc7d9c3","raw_frame":"{\"market\":\"0xda6f0e0e93fc8469e0159a166028d017bddbc162b86f66bac90391379603d962\", \"price_changes\":[{\"asset_id\":\"20893381255801015515826997628594359667013752732428989472914000440642900266717\", \"price\":\"0.68\", \"size\":\"69\", \"side\":\"BUY\", \"hash\":\"1f1c19359565e3a25042a4d20a474461480cadf6\", \"best_bid\":\"0.72\", \"best_ask\":\"0.74\"}, {\"asset_id\":\"39272994714739463168905443499424551362424437245880253267329605556587274644733\", \"price\":\"0.32\", \"size\":\"69\", \"side\":\"SELL\", \"hash\":\"6ee231bc603bcec4b7bbc1548c2d7bbd09caf344\", \"best_bid\":\"0.26\", \"best_ask\":\"0.28\"}], \"timestamp\":\"1785204818005\", \"event_type\":\"price_change\"}","received_at":"2026-07-28T02:13:37.895974Z","schema_version":"clob-market-ws.price_change.v1","sequence":null,"server_hash":null,"server_timestamp":"1785204818005","session_id":"d2757dd6dad94f3b9fe67e8dbf1adc37","source":"clob_market_ws"},"received_at":"2026-07-28T02:13:37.895974Z","record_id":"f87ce41003175133d5d15781c3d4525502029d1323ad4f69ac3e20adb9dce99e","schema_fingerprint":"4aa3821a28b0b7c2400bc59aba4bcc0a76e971dadd19610d3ad38c768e124dc7","schema_version":"edge-lab-recorder.raw.v1","sequence":null,"source":"clob_market_ws"}
{"event_at":"2026-07-28T02:13:38.008000Z","event_fingerprint":"402a13c5cd2e199cfe344691bc83608060e460ba53c6f9d53677013a80b1863a","payload":{"connection_id":"5d29200f65794d4d9ab6ef271f045a9b","event_at":"2026-07-28T02:13:38.008000Z","event_type":"price_change","frame_hash":"5ce57b3d6dae05c94a1b3c4fdb35dc953089bc829c3b68af4f5fe35e9ad5297d","frame_index":0,"kind":"data","monotonic_ns":306800910123083,"payload":{"event_type":"price_change","market":"0xda6f0e0e93fc8469e0159a166028d017bddbc162b86f66bac90391379603d962","price_changes":[{"asset_id":"39272994714739463168905443499424551362424437245880253267329605556587274644733","best_ask":"0.28","best_bid":"0.26","hash":"50f65cbb5cfad9331ce9e490ad34268081f9690e","price":"0.16","side":"BUY","size":"221"},{"asset_id":"20893381255801015515826997628594359667013752732428989472914000440642900266717","best_ask":"0.74","best_bid":"0.72","hash":"1160316ba0741fa2761709ceea64a7c15c1b7f51","price":"0.84","side":"SELL","size":"221"}],"timestamp":"1785204818008"},"payload_hash":"aaeb8fe6aa94160c5a3aa35075185b4dd8caea00d10807e0d6fc2078996fb8fa","raw_frame":"{\"market\":\"0xda6f0e0e93fc8469e0159a166028d017bddbc162b86f66bac90391379603d962\", \"price_changes\":[{\"asset_id\":\"39272994714739463168905443499424551362424437245880253267329605556587274644733\", \"price\":\"0.16\", \"size\":\"221\", \"side\":\"BUY\", \"hash\":\"50f65cbb5cfad9331ce9e490ad34268081f9690e\", \"best_bid\":\"0.26\", \"best_ask\":\"0.28\"}, {\"asset_id\":\"20893381255801015515826997628594359667013752732428989472914000440642900266717\", \"price\":\"0.84\", \"size\":\"221\", \"side\":\"SELL\", \"hash\":\"1160316ba0741fa2761709ceea64a7c15c1b7f51\", \"best_bid\":\"0.72\", \"best_ask\":\"0.74\"}], \"timestamp\":\"1785204818008\", \"event_type\":\"price_change\"}","received_at":"2026-07-28T02:13:37.898966Z","schema_version":"clob-market-ws.price_change.v1","sequence":null,"server_hash":null,"server_timestamp":"1785204818008","session_id":"d2757dd6dad94f3b9fe67e8dbf1adc37","source":"clob_market_ws"},"received_at":"2026-07-28T02:13:37.898966Z","record_id":"611139910c7ae2e85b799c874b19caa2447764cbe6e50ac6d1105c44de6878c7","schema_fingerprint":"4aa3821a28b0b7c2400bc59aba4bcc0a76e971dadd19610d3ad38c768e124dc7","schema_version":"edge-lab-recorder.raw.v1","sequence":null,"source":"clob_market_ws"}
{"event_at":"2026-07-28T02:13:38.009000Z","event_fingerprint":"0e324eb61a9407422726417ba5ab7f5af03a86cfcf2c7ee3b9135026cad23a86","payload":{"connection_id":"5d29200f65794d4d9ab6ef271f045a9b","event_at":"2026-07-28T02:13:38.009000Z","event_type":"price_change","frame_hash":"20663ec9916910702a700b98fa5843ac6894c145c1b1bec90c41fb90853338c3","frame_index":0,"kind":"data","monotonic_ns":306800913059291,"payload":{"event_type":"price_change","market":"0xda6f0e0e93fc8469e0159a166028d017bddbc162b86f66bac90391379603d962","price_changes":[{"asset_id":"39272994714739463168905443499424551362424437245880253267329605556587274644733","best_ask":"0.28","best_bid":"0.26","hash":"7381a760add062cf245bc31e33e42e582c957ebe","price":"0.25","side":"BUY","size":"30"},{"asset_id":"20893381255801015515826997628594359667013752732428989472914000440642900266717","best_ask":"0.74","best_bid":"0.72","hash":"46b48ea3bbb740a785f3880d8c0aa2743b72673b","price":"0.75","side":"SELL","size":"30"}],"timestamp":"1785204818009"},"payload_hash":"6df0ffa6550a118c1bf241b96822099dc5afbb2ac72333fe68ccef5129ea41e6","raw_frame":"{\"market\":\"0xda6f0e0e93fc8469e0159a166028d017bddbc162b86f66bac90391379603d962\", \"price_changes\":[{\"asset_id\":\"39272994714739463168905443499424551362424437245880253267329605556587274644733\", \"price\":\"0.25\", \"size\":\"30\", \"side\":\"BUY\", \"hash\":\"7381a760add062cf245bc31e33e42e582c957ebe\", \"best_bid\":\"0.26\", \"best_ask\":\"0.28\"}, {\"asset_id\":\"20893381255801015515826997628594359667013752732428989472914000440642900266717\", \"price\":\"0.75\", \"size\":\"30\", \"side\":\"SELL\", \"hash\":\"46b48ea3bbb740a785f3880d8c0aa2743b72673b\", \"best_bid\":\"0.72\", \"best_ask\":\"0.74\"}], \"timestamp\":\"1785204818009\", \"event_type\":\"price_change\"}","received_at":"2026-07-28T02:13:37.901904Z","schema_version":"clob-market-ws.price_change.v1","sequence":null,"server_hash":null,"server_timestamp":"1785204818009","session_id":"d2757dd6dad94f3b9fe67e8dbf1adc37","source":"clob_market_ws"},"received_at":"2026-07-28T02:13:37.901904Z","record_id":"0a9bb7edb0b05062b032dac1c2740f9dd31936b1ad58f3423dd0b2fbf444a59e","schema_fingerprint":"4aa3821a28b0b7c2400bc59aba4bcc0a76e971dadd19610d3ad38c768e124dc7","schema_version":"edge-lab-recorder.raw.v1","sequence":null,"source":"clob_market_ws"}
{"event_at":"2026-07-28T02:13:38.010000Z","event_fingerprint":"78dd4b86db566ba05e32470cd5db76c0b9f6ac2394d885d0336490d9ca2a471b","payload":{"connection_id":"5d29200f65794d4d9ab6ef271f045a9b","event_at":"2026-07-28T02:13:38.010000Z","event_type":"price_change","frame_hash":"c2d755a1b1550c7e9e5a3786986ef262e56af845faeabbdca01dac12a68748fd","frame_index":0,"kind":"data","monotonic_ns":306800916119458,"payload":{"event_type":"price_change","market":"0xda6f0e0e93fc8469e0159a166028d017bddbc162b86f66bac90391379603d962","price_changes":[{"asset_id":"20893381255801015515826997628594359667013752732428989472914000440642900266717","best_ask":"0.74","best_bid":"0.72","hash":"9044bf74a76b5ed94720a9b3905b4de1a7c21454","price":"0.71","side":"BUY","size":"127.98"},{"asset_id":"39272994714739463168905443499424551362424437245880253267329605556587274644733","best_ask":"0.28","best_bid":"0.26","hash":"4e41a4423a5ab9cc5a148309bcdabdce0600400f","price":"0.29","side":"SELL","size":"127.98"}],"timestamp":"1785204818010"},"payload_hash":"8e7de40ba50effab669ceb84f12a54d0c420768bee69c978ef432213ee9c0c2a","raw_frame":"{\"market\":\"0xda6f0e0e93fc8469e0159a166028d017bddbc162b86f66bac90391379603d962\", \"price_changes\":[{\"asset_id\":\"20893381255801015515826997628594359667013752732428989472914000440642900266717\", \"price\":\"0.71\", \"size\":\"127.98\", \"side\":\"BUY\", \"hash\":\"9044bf74a76b5ed94720a9b3905b4de1a7c21454\", \"best_bid\":\"0.72\", \"best_ask\":\"0.74\"}, {\"asset_id\":\"39272994714739463168905443499424551362424437245880253267329605556587274644733\", \"price\":\"0.29\", \"size\":\"127.98\", \"side\":\"SELL\", \"hash\":\"4e41a4423a5ab9cc5a148309bcdabdce0600400f\", \"best_bid\":\"0.26\", \"best_ask\":\"0.28\"}], \"timestamp\":\"1785204818010\", \"event_type\":\"price_change\"}","received_at":"2026-07-28T02:13:37.904964Z","schema_version":"clob-market-ws.price_change.v1","sequence":null,"server_hash":null,"server_timestamp":"1785204818010","session_id":"d2757dd6dad94f3b9fe67e8dbf1adc37","source":"clob_market_ws"},"received_at":"2026-07-28T02:13:37.904964Z","record_id":"9f564447e89672fae1717376928e5d01f0f7c29cb17bada8918103a01e2ad6e3","schema_fingerprint":"4aa3821a28b0b7c2400bc59aba4bcc0a76e971dadd19610d3ad38c768e124dc7","schema_version":"edge-lab-recorder.raw.v1","sequence":null,"source":"clob_market_ws"}
{"event_at":"2026-07-28T02:13:38.019000Z","event_fingerprint":"00adf1b5ee0570caba3f6355131f4a7c84db3df9723815e4484293674e72ef34","payload":{"connection_id":"5d29200f65794d4d9ab6ef271f045a9b","event_at":"2026-07-28T02:13:38.019000Z","event_type":"price_change","frame_hash":"bceae83c6c044cb460e5f5e9da695073d5f900b9bef9ac9789c6f746e9cfcfbe","frame_index":0,"kind":"data","monotonic_ns":306800918968750,"payload":{"event_type":"price_change","market":"0xda6f0e0e93fc8469e0159a166028d017bddbc162b86f66bac90391379603d962","price_changes":[{"asset_id":"39272994714739463168905443499424551362424437245880253267329605556587274644733","best_ask":"0.28","best_bid":"0.26","hash":"b881ad93519666a09918d237d910f9a8f1a3125b","price":"0.01","side":"BUY","size":"7444.02"},{"asset_id":"20893381255801015515826997628594359667013752732428989472914000440642900266717","best_ask":"0.74","best_bid":"0.72","hash":"ade5e77cbc908e77282b21fa9233a993740946be","price":"0.99","side":"SELL","size":"7444.02"}],"timestamp":"1785204818019"},"payload_hash":"84b275ef949041a974f3a9957b6341e0bdd4fc88db6efba98d2cc137c9230a09","raw_frame":"{\"market\":\"0xda6f0e0e93fc8469e0159a166028d017bddbc162b86f66bac90391379603d962\", \"price_changes\":[{\"asset_id\":\"39272994714739463168905443499424551362424437245880253267329605556587274644733\", \"price\":\"0.01\", \"size\":\"7444.02\", \"side\":\"BUY\", \"hash\":\"b881ad93519666a09918d237d910f9a8f1a3125b\", \"best_bid\":\"0.26\", \"best_ask\":\"0.28\"}, {\"asset_id\":\"20893381255801015515826997628594359667013752732428989472914000440642900266717\", \"price\":\"0.99\", \"size\":\"7444.02\", \"side\":\"SELL\", \"hash\":\"ade5e77cbc908e77282b21fa9233a993740946be\", \"best_bid\":\"0.72\", \"best_ask\":\"0.74\"}], \"timestamp\":\"1785204818019\", \"event_type\":\"price_change\"}","received_at":"2026-07-28T02:13:37.907813Z","schema_version":"clob-market-ws.price_change.v1","sequence":null,"server_hash":null,"server_timestamp":"1785204818019","session_id":"d2757dd6dad94f3b9fe67e8dbf1adc37","source":"clob_market_ws"},"received_at":"2026-07-28T02:13:37.907813Z","record_id":"cdd2ae5c07adb56dbd2e1221c0f523561facc729f60b53d3bd9050b0f5ee267d","schema_fingerprint":"4aa3821a28b0b7c2400bc59aba4bcc0a76e971dadd19610d3ad38c768e124dc7","schema_version":"edge-lab-recorder.raw.v1","sequence":null,"source":"clob_market_ws"}
{"event_at":"2026-07-28T02:13:38.027000Z","event_fingerprint":"2af4a10c39089dca3ec97dd76c900dcebd4af3c4f6d6d1a72fcd53d5499ab8d7","payload":{"connection_id":"5d29200f65794d4d9ab6ef271f045a9b","event_at":"2026-07-28T02:13:38.027000Z","event_type":"price_change","frame_hash":"1ccd7d94e66c9feabbab620f6c9e7880166e8ce5b2a4efb77219b5952a040800","frame_index":0,"kind":"data","monotonic_ns":306800926227083,"payload":{"event_type":"price_change","market":"0xda6f0e0e93fc8469e0159a166028d017bddbc162b86f66bac90391379603d962","price_changes":[{"asset_id":"39272994714739463168905443499424551362424437245880253267329605556587274644733","best_ask":"0.28","best_bid":"0.26","hash":"2f27d4606292d68ee58e28eec60d1282ecf00648","price":"0.01","side":"BUY","size":"7449.02"},{"asset_id":"20893381255801015515826997628594359667013752732428989472914000440642900266717","best_ask":"0.74","best_bid":"0.72","hash":"8e4f85af5d6191142b521c0040c55027d448e8ba","price":"0.99","side":"SELL","size":"7449.02"}],"timestamp":"1785204818027"},"payload_hash":"0a3e00cc512c92f72dd8529300eb4e752d4f55590627caa24b9041a0425e90f0","raw_frame":"{\"market\":\"0xda6f0e0e93fc8469e0159a166028d017bddbc162b86f66bac90391379603d962\", \"price_changes\":[{\"asset_id\":\"39272994714739463168905443499424551362424437245880253267329605556587274644733\", \"price\":\"0.01\", \"size\":\"7449.02\", \"side\":\"BUY\", \"hash\":\"2f27d4606292d68ee58e28eec60d1282ecf00648\", \"best_bid\":\"0.26\", \"best_ask\":\"0.28\"}, {\"asset_id\":\"20893381255801015515826997628594359667013752732428989472914000440642900266717\", \"price\":\"0.99\", \"size\":\"7449.02\", \"side\":\"SELL\", \"hash\":\"8e4f85af5d6191142b521c0040c55027d448e8ba\", \"best_bid\":\"0.72\", \"best_ask\":\"0.74\"}], \"timestamp\":\"1785204818027\", \"event_type\":\"price_change\"}","received_at":"2026-07-28T02:13:37.915072Z","schema_version":"clob-market-ws.price_change.v1","sequence":null,"server_hash":null,"server_timestamp":"1785204818027","session_id":"d2757dd6dad94f3b9fe67e8dbf1adc37","source":"clob_market_ws"},"received_at":"2026-07-28T02:13:37.915072Z","record_id":"165ef51ba460efc1a0b47d91cc01411bebd919456c2a5e2e6aff662c5a0928b5","schema_fingerprint":"4aa3821a28b0b7c2400bc59aba4bcc0a76e971dadd19610d3ad38c768e124dc7","schema_version":"edge-lab-recorder.raw.v1","sequence":null,"source":"clob_market_ws"}
{"event_at":"2026-07-28T02:13:38.030000Z","event_fingerprint":"0e2e92a46a84d514533487544f7d63d9a83d3365fdfabaafba78a7ae89d35d1e","payload":{"connection_id":"5d29200f65794d4d9ab6ef271f045a9b","event_at":"2026-07-28T02:13:38.030000Z","event_type":"price_change","frame_hash":"360980030604179b4180c1b0f3e6205e41873e154a9d536e110ab81b79df3705","frame_index":0,"kind":"data","monotonic_ns":306800929197833,"payload":{"event_type":"price_change","market":"0xda6f0e0e93fc8469e0159a166028d017bddbc162b86f66bac90391379603d962","price_changes":[{"asset_id":"20893381255801015515826997628594359667013752732428989472914000440642900266717","best_ask":"0.74","best_bid":"0.72","hash":"420c0d2f8c6b6662b943d15d72ca6457ac4c944e","price":"0.04","side":"BUY","size":"584"},{"asset_id":"39272994714739463168905443499424551362424437245880253267329605556587274644733","best_ask":"0.28","best_bid":"0.26","hash":"61204ae898eded08a04c204494f0919f9e6eb3a6","price":"0.96","side":"SELL","size":"584"}],"timestamp":"1785204818030"},"payload_hash":"907df1b03bb914c1523ab42b4b404376fa9fa25d18a84c2c5dc05da73c62fdb8","raw_frame":"{\"market\":\"0xda6f0e0e93fc8469e0159a166028d017bddbc162b86f66bac90391379603d962\", \"price_changes\":[{\"asset_id\":\"20893381255801015515826997628594359667013752732428989472914000440642900266717\", \"price\":\"0.04\", \"size\":\"584\", \"side\":\"BUY\", \"hash\":\"420c0d2f8c6b6662b943d15d72ca6457ac4c944e\", \"best_bid\":\"0.72\", \"best_ask\":\"0.74\"}, {\"asset_id\":\"39272994714739463168905443499424551362424437245880253267329605556587274644733\", \"price\":\"0.96\", \"size\":\"584\", \"side\":\"SELL\", \"hash\":\"61204ae898eded08a04c204494f0919f9e6eb3a6\", \"best_bid\":\"0.26\", \"best_ask\":\"0.28\"}], \"timestamp\":\"1785204818030\", \"event_type\":\"price_change\"}","received_at":"2026-07-28T02:13:37.918042Z","schema_version":"clob-market-ws.price_change.v1","sequence":null,"server_hash":null,"server_timestamp":"1785204818030","session_id":"d2757dd6dad94f3b9fe67e8dbf1adc37","source":"clob_market_ws"},"received_at":"2026-07-28T02:13:37.918042Z","record_id":"01a1c4840953decd32b5b084d6ba62db26d1c58b1c884637beeda3e98c1fa2e3","schema_fingerprint":"4aa3821a28b0b7c2400bc59aba4bcc0a76e971dadd19610d3ad38c768e124dc7","schema_version":"edge-lab-recorder.raw.v1","sequence":null,"source":"clob_market_ws"}
{"event_at":"2026-07-28T02:13:38.036000Z","event_fingerprint":"64ce2e82045146202ef4690d8f900fe6defac0823c03555c0d8e0f2266465b4e","payload":{"connection_id":"5d29200f65794d4d9ab6ef271f045a9b","event_at":"2026-07-28T02:13:38.036000Z","event_type":"price_change","frame_hash":"65cd3f30d7ed50cc2e3588123440e46c946c02e92de20c8567035b23e3f546ea","frame_index":0,"kind":"data","monotonic_ns":306800932117416,"payload":{"event_type":"price_change","market":"0xda6f0e0e93fc8469e0159a166028d017bddbc162b86f66bac90391379603d962","price_changes":[{"asset_id":"39272994714739463168905443499424551362424437245880253267329605556587274644733","best_ask":"0.28","best_bid":"0.26","hash":"267f1748f11bd721e8ec5ecc3eff450554dd1fab","price":"0.25","side":"BUY","size":"15"},{"asset_id":"20893381255801015515826997628594359667013752732428989472914000440642900266717","best_ask":"0.74","best_bid":"0.72","hash":"bcc9d1416eded29255df49386ea10f2676272e5b","price":"0.75","side":"SELL","size":"15"}],"timestamp":"1785204818036"},"payload_hash":"e6cebf05698fef324dbeac8086708adcfc1d35d6c20d338e56fc6f61444d3d50","raw_frame":"{\"market\":\"0xda6f0e0e93fc8469e0159a166028d017bddbc162b86f66bac90391379603d962\", \"price_changes\":[{\"asset_id\":\"39272994714739463168905443499424551362424437245880253267329605556587274644733\", \"price\":\"0.25\", \"size\":\"15\", \"side\":\"BUY\", \"hash\":\"267f1748f11bd721e8ec5ecc3eff450554dd1fab\", \"best_bid\":\"0.26\", \"best_ask\":\"0.28\"}, {\"asset_id\":\"20893381255801015515826997628594359667013752732428989472914000440642900266717\", \"price\":\"0.75\", \"size\":\"15\", \"side\":\"SELL\", \"hash\":\"bcc9d1416eded29255df49386ea10f2676272e5b\", \"best_bid\":\"0.72\", \"best_ask\":\"0.74\"}], \"timestamp\":\"1785204818036\", \"event_type\":\"price_change\"}","received_at":"2026-07-28T02:13:37.920962Z","schema_version":"clob-market-ws.price_change.v1","sequence":null,"server_hash":null,"server_timestamp":"1785204818036","session_id":"d2757dd6dad94f3b9fe67e8dbf1adc37","source":"clob_market_ws"},"received_at":"2026-07-28T02:13:37.920962Z","record_id":"016f7ab5247486c6b64d10398dfd5a1b8c4659bfac8a2d2897ac8259f655d09b","schema_fingerprint":"4aa3821a28b0b7c2400bc59aba4bcc0a76e971dadd19610d3ad38c768e124dc7","schema_version":"edge-lab-recorder.raw.v1","sequence":null,"source":"clob_market_ws"}
{"event_at":"2026-07-28T02:13:38.038000Z","event_fingerprint":"5a414e3f476d30cdf8615ae98ddc55c457fbedf0e22ac14d1d58d5496cb9d12e","payload":{"connection_id":"5d29200f65794d4d9ab6ef271f045a9b","event_at":"2026-07-28T02:13:38.038000Z","event_type":"price_change","frame_hash":"e421cb76fe0f61231872b55a07456866d2f42ee704c8cec767dc7be5abbfde9a","frame_index":0,"kind":"data","monotonic_ns":306800935106041,"payload":{"event_type":"price_change","market":"0xda6f0e0e93fc8469e0159a166028d017bddbc162b86f66bac90391379603d962","price_changes":[{"asset_id":"39272994714739463168905443499424551362424437245880253267329605556587274644733","best_ask":"0.28","best_bid":"0.26","hash":"97a971c9c3a71c8d529414fc9acea36a4136dce2","price":"0.01","side":"BUY","size":"7444.02"},{"asset_id":"20893381255801015515826997628594359667013752732428989472914000440642900266717","best_ask":"0.74","best_bid":"0.72","hash":"59ae12d18fd916338859655e4730df6f75df7ecc","price":"0.99","side":"SELL","size":"7444.02"}],"timestamp":"1785204818038"},"payload_hash":"6fe9ebca917d6c6da836835d36f96c8dea6ad259856703ff020ef800cc56fc56","raw_frame":"{\"market\":\"0xda6f0e0e93fc8469e0159a166028d017bddbc162b86f66bac90391379603d962\", \"price_changes\":[{\"asset_id\":\"39272994714739463168905443499424551362424437245880253267329605556587274644733\", \"price\":\"0.01\", \"size\":\"7444.02\", \"side\":\"BUY\", \"hash\":\"97a971c9c3a71c8d529414fc9acea36a4136dce2\", \"best_bid\":\"0.26\", \"best_ask\":\"0.28\"}, {\"asset_id\":\"20893381255801015515826997628594359667013752732428989472914000440642900266717\", \"price\":\"0.99\", \"size\":\"7444.02\", \"side\":\"SELL\", \"hash\":\"59ae12d18fd916338859655e4730df6f75df7ecc\", \"best_bid\":\"0.72\", \"best_ask\":\"0.74\"}], \"timestamp\":\"1785204818038\", \"event_type\":\"price_change\"}","received_at":"2026-07-28T02:13:37.923950Z","schema_version":"clob-market-ws.price_change.v1","sequence":null,"server_hash":null,"server_timestamp":"1785204818038","session_id":"d2757dd6dad94f3b9fe67e8dbf1adc37","source":"clob_market_ws"},"received_at":"2026-07-28T02:13:37.923950Z","record_id":"8a2f15cf4fd8a2c36a8ba2c5294253236a9459d78785a10ba046d1d688352bd3","schema_fingerprint":"4aa3821a28b0b7c2400bc59aba4bcc0a76e971dadd19610d3ad38c768e124dc7","schema_version":"edge-lab-recorder.raw.v1","sequence":null,"source":"clob_market_ws"}
{"event_at":"2026-07-28T02:13:38.052000Z","event_fingerprint":"8b3148ebaf17ac1dc06f1cbb31953cc78a6a18411ac2726ce7dff6c8de5e409d","payload":{"connection_id":"5d29200f65794d4d9ab6ef271f045a9b","event_at":"2026-07-28T02:13:38.052000Z","event_type":"price_change","frame_hash":"8498552fb42828ce3aced05298efefa7b9b5a237b5b0325a9c92910c11a0b6dc","frame_index":0,"kind":"data","monotonic_ns":306800959174333,"payload":{"event_type":"price_change","market":"0xda6f0e0e93fc8469e0159a166028d017bddbc162b86f66bac90391379603d962","price_changes":[{"asset_id":"20893381255801015515826997628594359667013752732428989472914000440642900266717","best_ask":"0.74","best_bid":"0.72","hash":"4454d78f26ba0da06cd58433d1d81b35c17da2e8","price":"0.01","side":"BUY","size":"5379.02"},{"asset_id":"39272994714739463168905443499424551362424437245880253267329605556587274644733","best_ask":"0.28","best_bid":"0.26","hash":"ff6beafe9f8679f6f5dd1b27678d946607e7aecb","price":"0.99","side":"SELL","size":"5379.02"}],"timestamp":"1785204818052"},"payload_hash":"4ff026b78ae7041469a907d54809e825134056379c258629f058df730e8357a5","raw_frame":"{\"market\":\"0xda6f0e0e93fc8469e0159a166028d017bddbc162b86f66bac90391379603d962\", \"price_changes\":[{\"asset_id\":\"20893381255801015515826997628594359667013752732428989472914000440642900266717\", \"price\":\"0.01\", \"size\":\"5379.02\", \"side\":\"BUY\", \"hash\":\"4454d78f26ba0da06cd58433d1d81b35c17da2e8\", \"best_bid\":\"0.72\", \"best_ask\":\"0.74\"}, {\"asset_id\":\"39272994714739463168905443499424551362424437245880253267329605556587274644733\", \"price\":\"0.99\", \"size\":\"5379.02\", \"side\":\"SELL\", \"hash\":\"ff6beafe9f8679f6f5dd1b27678d946607e7aecb\", \"best_bid\":\"0.26\", \"best_ask\":\"0.28\"}], \"timestamp\":\"1785204818052\", \"event_type\":\"price_change\"}","received_at":"2026-07-28T02:13:37.948017Z","schema_version":"clob-market-ws.price_change.v1","sequence":null,"server_hash":null,"server_timestamp":"1785204818052","session_id":"d2757dd6dad94f3b9fe67e8dbf1adc37","source":"clob_market_ws"},"received_at":"2026-07-28T02:13:37.948017Z","record_id":"81b0b42f4959ccea6c8917011841f437ab1af544bf0ff22e07093a5d33866db7","schema_fingerprint":"4aa3821a28b0b7c2400bc59aba4bcc0a76e971dadd19610d3ad38c768e124dc7","schema_version":"edge-lab-recorder.raw.v1","sequence":null,"source":"clob_market_ws"}
{"event_at":"2026-07-28T02:13:38.054000Z","event_fingerprint":"31f8951692d248847bacd7158c6a93e9029dedc25e0606d9cb92419d2ef8c492","payload":{"connection_id":"5d29200f65794d4d9ab6ef271f045a9b","event_at":"2026-07-28T02:13:38.054000Z","event_type":"price_change","frame_hash":"164598d6b088098257dfd312e361205e1ccd7d5e43e661f20fd22cd2835dd006","frame_index":0,"kind":"data","monotonic_ns":306800960664041,"payload":{"event_type":"price_change","market":"0xda6f0e0e93fc8469e0159a166028d017bddbc162b86f66bac90391379603d962","price_changes":[{"asset_id":"39272994714739463168905443499424551362424437245880253267329605556587274644733","best_ask":"0.28","best_bid":"0.26","hash":"9b2f17020ff417e831f2df0f55bc9e7db394e869","price":"0.01","side":"BUY","size":"7439.02"},{"asset_id":"20893381255801015515826997628594359667013752732428989472914000440642900266717","best_ask":"0.74","best_bid":"0.72","hash":"26cf6156708275ad5ec90c3d4173a6f31f75b2e7","price":"0.99","side":"SELL","size":"7439.02"}],"timestamp":"1785204818054"},"payload_hash":"1642272049475cb91c25aff7a3510f4c5c549fc8e24093b6f02bb5af3beec745","raw_frame":"{\"market\":\"0xda6f0e0e93fc8469e0159a166028d017bddbc162b86f66bac90391379603d962\", \"price_changes\":[{\"asset_id\":\"39272994714739463168905443499424551362424437245880253267329605556587274644733\", \"price\":\"0.01\", \"size\":\"7439.02\", \"side\":\"BUY\", \"hash\":\"9b2f17020ff417e831f2df0f55bc9e7db394e869\", \"best_bid\":\"0.26\", \"best_ask\":\"0.28\"}, {\"asset_id\":\"20893381255801015515826997628594359667013752732428989472914000440642900266717\", \"price\":\"0.99\", \"size\":\"7439.02\", \"side\":\"SELL\", \"hash\":\"26cf6156708275ad5ec90c3d4173a6f31f75b2e7\", \"best_bid\":\"0.72\", \"best_ask\":\"0.74\"}], \"timestamp\":\"1785204818054\", \"event_type\":\"price_change\"}","received_at":"2026-07-28T02:13:37.949507Z","schema_version":"clob-market-ws.price_change.v1","sequence":null,"server_hash":null,"server_timestamp":"1785204818054","session_id":"d2757dd6dad94f3b9fe67e8dbf1adc37","source":"clob_market_ws"},"received_at":"2026-07-28T02:13:37.949507Z","record_id":"7b16f74399bae63f3c02cf8fbad94cb857cfc85e72cc79f0d2cb4014b9be7b85","schema_fingerprint":"4aa3821a28b0b7c2400bc59aba4bcc0a76e971dadd19610d3ad38c768e124dc7","schema_version":"edge-lab-recorder.raw.v1","sequence":null,"source":"clob_market_ws"}
{"event_at":"2026-07-28T02:13:38.056000Z","event_fingerprint":"5e6a7ce28d021e9326206900cb6f867e7cc6294a9564ff509cec222768727faa","payload":{"connection_id":"5d29200f65794d4d9ab6ef271f045a9b","event_at":"2026-07-28T02:13:38.056000Z","event_type":"price_change","frame_hash":"84c20dff4e21daa39d31d2a2c77ac13e5f1c320ef9d5be8018171067552feefd","frame_index":0,"kind":"data","monotonic_ns":306800962187958,"payload":{"event_type":"price_change","market":"0xda6f0e0e93fc8469e0159a166028d017bddbc162b86f66bac90391379603d962","price_changes":[{"asset_id":"20893381255801015515826997628594359667013752732428989472914000440642900266717","best_ask":"0.74","best_bid":"0.72","hash":"5c8751711ad6966addbd9e99467550d8ed9b8926","price":"0.65","side":"BUY","size":"44"},{"asset_id":"39272994714739463168905443499424551362424437245880253267329605556587274644733","best_ask":"0.28","best_bid":"0.26","hash":"65a967a971034d6a9c57492a234b61839f6fbdf7","price":"0.35","side":"SELL","size":"44"}],"timestamp":"1785204818056"},"payload_hash":"2333ae4be4ac5c21d4217cda230762730d7e7c48ef3f7f7bb79312ec1153f206","raw_frame":"{\"market\":\"0xda6f0e0e93fc8469e0159a166028d017bddbc162b86f66bac90391379603d962\", \"price_changes\":[{\"asset_id\":\"20893381255801015515826997628594359667013752732428989472914000440642900266717\", \"price\":\"0.65\", \"size\":\"44\", \"side\":\"BUY\", \"hash\":\"5c8751711ad6966addbd9e99467550d8ed9b8926\", \"best_bid\":\"0.72\", \"best_ask\":\"0.74\"}, {\"asset_id\":\"39272994714739463168905443499424551362424437245880253267329605556587274644733\", \"price\":\"0.35\", \"size\":\"44\", \"side\":\"SELL\", \"hash\":\"65a967a971034d6a9c57492a234b61839f6fbdf7\", \"best_bid\":\"0.26\", \"best_ask\":\"0.28\"}], \"timestamp\":\"1785204818056\", \"event_type\":\"price_change\"}","received_at":"2026-07-28T02:13:37.951031Z","schema_version":"clob-market-ws.price_change.v1","sequence":null,"server_hash":null,"server_timestamp":"1785204818056","session_id":"d2757dd6dad94f3b9fe67e8dbf1adc37","source":"clob_market_ws"},"received_at":"2026-07-28T02:13:37.951031Z","record_id":"8eaddcd73d0113386116be2d237617ac04be22d92fa6a7235b1884e7327bbd33","schema_fingerprint":"4aa3821a28b0b7c2400bc59aba4bcc0a76e971dadd19610d3ad38c768e124dc7","schema_version":"edge-lab-recorder.raw.v1","sequence":null,"source":"clob_market_ws"}
{"event_at":"2026-07-28T02:13:38.074000Z","event_fingerprint":"737abd991df8f7457d3ccbee7177b58f9a19c7441e5641a115aabd2bded09c64","payload":{"connection_id":"5d29200f65794d4d9ab6ef271f045a9b","event_at":"2026-07-28T02:13:38.074000Z","event_type":"price_change","frame_hash":"4e4aba60592d5bcaeb7450e2d71537970d00638cbcaf3f34c2e37fe2a2d7b68f","frame_index":0,"kind":"data","monotonic_ns":306800970931416,"payload":{"event_type":"price_change","market":"0xda6f0e0e93fc8469e0159a166028d017bddbc162b86f66bac90391379603d962","price_changes":[{"asset_id":"20893381255801015515826997628594359667013752732428989472914000440642900266717","best_ask":"0.74","best_bid":"0.72","hash":"c5695f33fa61d8561b6af37c3a88ffec8ddaba7b","price":"0.01","side":"BUY","size":"5374.02"},{"asset_id":"39272994714739463168905443499424551362424437245880253267329605556587274644733","best_ask":"0.28","best_bid":"0.26","hash":"fe7435c181b5eb752c89b20aeab06a73e374c2a6","price":"0.99","side":"SELL","size":"5374.02"}],"timestamp":"1785204818074"},"payload_hash":"4db289bae20e82deb5556174289d960dc0c901bb20e92af7cf41a441eae0733b","raw_frame":"{\"market\":\"0xda6f0e0e93fc8469e0159a166028d017bddbc162b86f66bac90391379603d962\", \"price_changes\":[{\"asset_id\":\"20893381255801015515826997628594359667013752732428989472914000440642900266717\", \"price\":\"0.01\", \"size\":\"5374.02\", \"side\":\"BUY\", \"hash\":\"c5695f33fa61d8561b6af37c3a88ffec8ddaba7b\", \"best_bid\":\"0.72\", \"best_ask\":\"0.74\"}, {\"asset_id\":\"39272994714739463168905443499424551362424437245880253267329605556587274644733\", \"price\":\"0.99\", \"size\":\"5374.02\", \"side\":\"SELL\", \"hash\":\"fe7435c181b5eb752c89b20aeab06a73e374c2a6\", \"best_bid\":\"0.26\", \"best_ask\":\"0.28\"}], \"timestamp\":\"1785204818074\", \"event_type\":\"price_change\"}","received_at":"2026-07-28T02:13:37.959775Z","schema_version":"clob-market-ws.price_change.v1","sequence":null,"server_hash":null,"server_timestamp":"1785204818074","session_id":"d2757dd6dad94f3b9fe67e8dbf1adc37","source":"clob_market_ws"},"received_at":"2026-07-28T02:13:37.959775Z","record_id":"1f2f63ed2801937ae1cf1ca20e7ad22018cf597f797638bb4b421b67d5893985","schema_fingerprint":"4aa3821a28b0b7c2400bc59aba4bcc0a76e971dadd19610d3ad38c768e124dc7","schema_version":"edge-lab-recorder.raw.v1","sequence":null,"source":"clob_market_ws"}
{"event_at":"2026-07-28T02:13:38.075000Z","event_fingerprint":"e9de5a51dceb0b728535d9945feb0256776f70c7dd3e3a17fb638aebdf1794aa","payload":{"connection_id":"5d29200f65794d4d9ab6ef271f045a9b","event_at":"2026-07-28T02:13:38.075000Z","event_type":"price_change","frame_hash":"701fceaa62d8bb466f6413f6e4f68527271618f9a3ba20bce6563635caf12472","frame_index":0,"kind":"data","monotonic_ns":306800973852875,"payload":{"event_type":"price_change","market":"0xda6f0e0e93fc8469e0159a166028d017bddbc162b86f66bac90391379603d962","price_changes":[{"asset_id":"20893381255801015515826997628594359667013752732428989472914000440642900266717","best_ask":"0.74","best_bid":"0.72","hash":"31ca41fccb11fd2d534b8b0f05a47a8ecf9b6b31","price":"0.82","side":"SELL","size":"230"},{"asset_id":"39272994714739463168905443499424551362424437245880253267329605556587274644733","best_ask":"0.28","best_bid":"0.26","hash":"53664aa3673ed6c47813ab5b1dbaef37ae720fc6","price":"0.18","side":"BUY","size":"230"}],"timestamp":"1785204818075"},"payload_hash":"f4f33c03700e45789ad4c85a7a18af150af7cab746c4243fd5018b2ff8b606ee","raw_frame":"{\"market\":\"0xda6f0e0e93fc8469e0159a166028d017bddbc162b86f66bac90391379603d962\", \"price_changes\":[{\"asset_id\":\"20893381255801015515826997628594359667013752732428989472914000440642900266717\", \"price\":\"0.82\", \"size\":\"230\", \"side\":\"SELL\", \"hash\":\"31ca41fccb11fd2d534b8b0f05a47a8ecf9b6b31\", \"best_bid\":\"0.72\", \"best_ask\":\"0.74\"}, {\"asset_id\":\"39272994714739463168905443499424551362424437245880253267329605556587274644733\", \"price\":\"0.18\", \"size\":\"230\", \"side\":\"BUY\", \"hash\":\"53664aa3673ed6c47813ab5b1dbaef37ae720fc6\", \"best_bid\":\"0.26\", \"best_ask\":\"0.28\"}], \"timestamp\":\"1785204818075\", \"event_type\":\"price_change\"}","received_at":"2026-07-28T02:13:37.962696Z","schema_version":"clob-market-ws.price_change.v1","sequence":null,"server_hash":null,"server_timestamp":"1785204818075","session_id":"d2757dd6dad94f3b9fe67e8dbf1adc37","source":"clob_market_ws"},"received_at":"2026-07-28T02:13:37.962696Z","record_id":"fb575777c4e8249af366eaf88ccfb0e66bea32d1e708ca852e059ed4af11c489","schema_fingerprint":"4aa3821a28b0b7c2400bc59aba4bcc0a76e971dadd19610d3ad38c768e124dc7","schema_version":"edge-lab-recorder.raw.v1","sequence":null,"source":"clob_market_ws"}
{"event_at":"2026-07-28T02:13:38.075000Z","event_fingerprint":"53b3b9843e785707bbfca2e0f61f337895ec894f2324f493c4a85bc3a39f9231","payload":{"connection_id":"5d29200f65794d4d9ab6ef271f045a9b","event_at":"2026-07-28T02:13:38.075000Z","event_type":"price_change","frame_hash":"ad2a2b5d36bf00e4b98029bc2f7cfe26e98c853213359a036ee1349243ddf674","frame_index":0,"kind":"data","monotonic_ns":306800976789250,"payload":{"event_type":"price_change","market":"0xda6f0e0e93fc8469e0159a166028d017bddbc162b86f66bac90391379603d962","price_changes":[{"asset_id":"20893381255801015515826997628594359667013752732428989472914000440642900266717","best_ask":"0.74","best_bid":"0.72","hash":"be755c89606afa4478ff26cceafe4101d28815c3","price":"0.68","side":"BUY","size":"44"},{"asset_id":"39272994714739463168905443499424551362424437245880253267329605556587274644733","best_ask":"0.28","best_bid":"0.26","hash":"46f6ea08b9922af6dbf05d90489f55375b0353e4","price":"0.32","side":"SELL","size":"44"}],"timestamp":"1785204818075"},"payload_hash":"1de031586e5bb9f90758d44522f4f4ee413277a0e04b6561fb0bf04bd4c1a22c","raw_frame":"{\"market\":\"0xda6f0e0e93fc8469e0159a166028d017bddbc162b86f66bac90391379603d962\", \"price_changes\":[{\"asset_id\":\"20893381255801015515826997628594359667013752732428989472914000440642900266717\", \"price\":\"0.68\", \"size\":\"44\", \"side\":\"BUY\", \"hash\":\"be755c89606afa4478ff26cceafe4101d28815c3\", \"best_bid\":\"0.72\", \"best_ask\":\"0.74\"}, {\"asset_id\":\"39272994714739463168905443499424551362424437245880253267329605556587274644733\", \"price\":\"0.32\", \"size\":\"44\", \"side\":\"SELL\", \"hash\":\"46f6ea08b9922af6dbf05d90489f55375b0353e4\", \"best_bid\":\"0.26\", \"best_ask\":\"0.28\"}], \"timestamp\":\"1785204818075\", \"event_type\":\"price_change\"}","received_at":"2026-07-28T02:13:37.965633Z","schema_version":"clob-market-ws.price_change.v1","sequence":null,"server_hash":null,"server_timestamp":"1785204818075","session_id":"d2757dd6dad94f3b9fe67e8dbf1adc37","source":"clob_market_ws"},"received_at":"2026-07-28T02:13:37.965633Z","record_id":"173b645046cdb847f46f6b6b30bd0f9b06f5c7a4978b079973dd467ac1d82b99","schema_fingerprint":"4aa3821a28b0b7c2400bc59aba4bcc0a76e971dadd19610d3ad38c768e124dc7","schema_version":"edge-lab-recorder.raw.v1","sequence":null,"source":"clob_market_ws"}
{"event_at":"2026-07-28T02:13:38.075000Z","event_fingerprint":"ae0ef74a1326cf3890a9c4d4cea89b72d7e6d90f4273a311df9c4a5ca64e993d","payload":{"connection_id":"5d29200f65794d4d9ab6ef271f045a9b","event_at":"2026-07-28T02:13:38.075000Z","event_type":"price_change","frame_hash":"2334beb1125d219ab400474d95ff5c6e1a4bc918898603f2033df2aa54642e6e","frame_index":0,"kind":"data","monotonic_ns":306800980020708,"payload":{"event_type":"price_change","market":"0xda6f0e0e93fc8469e0159a166028d017bddbc162b86f66bac90391379603d962","price_changes":[{"asset_id":"39272994714739463168905443499424551362424437245880253267329605556587274644733","best_ask":"0.28","best_bid":"0.26","hash":"534df13e18d2dd7574f4db730c06033eac8fc9d2","price":"0.28","side":"SELL","size":"12.52"},{"asset_id":"20893381255801015515826997628594359667013752732428989472914000440642900266717","best_ask":"0.74","best_bid":"0.72","hash":"c8cdb54f2c2d6bb5347183e12a7cb78ed83500b2","price":"0.72","side":"BUY","size":"12.52"}],"timestamp":"1785204818075"},"payload_hash":"9effbcd5ec629878fadc8a731a78ac95d0fc4c96200902287f2cbcd21d2fc210","raw_frame":"{\"market\":\"0xda6f0e0e93fc8469e0159a166028d017bddbc162b86f66bac90391379603d962\", \"price_changes\":[{\"asset_id\":\"39272994714739463168905443499424551362424437245880253267329605556587274644733\", \"price\":\"0.28\", \"size\":\"12.52\", \"side\":\"SELL\", \"hash\":\"534df13e18d2dd7574f4db730c06033eac8fc9d2\", \"best_bid\":\"0.26\", \"best_ask\":\"0.28\"}, {\"asset_id\":\"20893381255801015515826997628594359667013752732428989472914000440642900266717\", \"price\":\"0.72\", \"size\":\"12.52\", \"side\":\"BUY\", \"hash\":\"c8cdb54f2c2d6bb5347183e12a7cb78ed83500b2\", \"best_bid\":\"0.72\", \"best_ask\":\"0.74\"}], \"timestamp\":\"1785204818075\", \"event_type\":\"price_change\"}","received_at":"2026-07-28T02:13:37.968864Z","schema_version":"clob-market-ws.price_change.v1","sequence":null,"server_hash":null,"server_timestamp":"1785204818075","session_id":"d2757dd6dad94f3b9fe67e8dbf1adc37","source":"clob_market_ws"},"received_at":"2026-07-28T02:13:37.968864Z","record_id":"bc0382b48e9324b3e9ca411b8ba40595c7b9a6142950adee9478be954e4d8a05","schema_fingerprint":"4aa3821a28b0b7c2400bc59aba4bcc0a76e971dadd19610d3ad38c768e124dc7","schema_version":"edge-lab-recorder.raw.v1","sequence":null,"source":"clob_market_ws"}
{"event_at":"2026-07-28T02:13:38.077000Z","event_fingerprint":"489a5df140bd93698acc24b2742c00c30ace9ac5b085b1b335b7d6f278547b56","payload":{"connection_id":"5d29200f65794d4d9ab6ef271f045a9b","event_at":"2026-07-28T02:13:38.077000Z","event_type":"price_change","frame_hash":"ec3a27bb841131cb73787218b9fa3cd8fe73410cab3b082364fcff05b8f91d1f","frame_index":0,"kind":"data","monotonic_ns":306800983227125,"payload":{"event_type":"price_change","market":"0xda6f0e0e93fc8469e0159a166028d017bddbc162b86f66bac90391379603d962","price_changes":[{"asset_id":"20893381255801015515826997628594359667013752732428989472914000440642900266717","best_ask":"0.74","best_bid":"0.72","hash":"0246ac47f6744846aa3fcf34ed3eab80756b02d8","price":"0.71","side":"BUY","size":"111"},{"asset_id":"39272994714739463168905443499424551362424437245880253267329605556587274644733","best_ask":"0.28","best_bid":"0.26","hash":"23ba52fae31db00cc8fbdc7662321817885e0e1c","price":"0.29","side":"SELL","size":"111"}],"timestamp":"1785204818077"},"payload_hash":"f0e54da4650c92200b6588d3542abf9611ba9b9e5b0770972574dbc57b0d5cb0","raw_frame":"{\"market\":\"0xda6f0e0e93fc8469e0159a166028d017bddbc162b86f66bac90391379603d962\", \"price_changes\":[{\"asset_id\":\"20893381255801015515826997628594359667013752732428989472914000440642900266717\", \"price\":\"0.71\", \"size\":\"111\", \"side\":\"BUY\", \"hash\":\"0246ac47f6744846aa3fcf34ed3eab80756b02d8\", \"best_bid\":\"0.72\", \"best_ask\":\"0.74\"}, {\"asset_id\":\"39272994714739463168905443499424551362424437245880253267329605556587274644733\", \"price\":\"0.29\", \"size\":\"111\", \"side\":\"SELL\", \"hash\":\"23ba52fae31db00cc8fbdc7662321817885e0e1c\", \"best_bid\":\"0.26\", \"best_ask\":\"0.28\"}], \"timestamp\":\"1785204818077\", \"event_type\":\"price_change\"}","received_at":"2026-07-28T02:13:37.972069Z","schema_version":"clob-market-ws.price_change.v1","sequence":null,"server_hash":null,"server_timestamp":"1785204818077","session_id":"d2757dd6dad94f3b9fe67e8dbf1adc37","source":"clob_market_ws"},"received_at":"2026-07-28T02:13:37.972069Z","record_id":"a1a16573259106e2c6677aaf94ced8357542984b1052d181d785c6b76c971a6c","schema_fingerprint":"4aa3821a28b0b7c2400bc59aba4bcc0a76e971dadd19610d3ad38c768e124dc7","schema_version":"edge-lab-recorder.raw.v1","sequence":null,"source":"clob_market_ws"}
{"event_at":"2026-07-28T02:13:38.080000Z","event_fingerprint":"c7251aaaa3d4b09abee98ebf6edc04400fb9485816a4609a90b0498e22455a6b","payload":{"connection_id":"5d29200f65794d4d9ab6ef271f045a9b","event_at":"2026-07-28T02:13:38.080000Z","event_type":"price_change","frame_hash":"e8b738487b3bd5e3ba02d4532f713f481cd61a578ea57a68fe94e36376271140","frame_index":0,"kind":"data","monotonic_ns":306800987161416,"payload":{"event_type":"price_change","market":"0xda6f0e0e93fc8469e0159a166028d017bddbc162b86f66bac90391379603d962","price_changes":[{"asset_id":"39272994714739463168905443499424551362424437245880253267329605556587274644733","best_ask":"0.28","best_bid":"0.26","hash":"d1319e90b03f93ea166dbe8dc7a51e699d1f4dc3","price":"0.26","side":"BUY","size":"106"},{"asset_id":"20893381255801015515826997628594359667013752732428989472914000440642900266717","best_ask":"0.74","best_bid":"0.72","hash":"c5a986bf2469206a9e924b5a2dfb53e0821f6be6","price":"0.74","side":"SELL","size":"106"}],"timestamp":"1785204818080"},"payload_hash":"b22dcc7293d23344095667c51ed448263d741de6079ccc810344e599c5aedca7","raw_frame":"{\"market\":\"0xda6f0e0e93fc8469e0159a166028d017bddbc162b86f66bac90391379603d962\", \"price_changes\":[{\"asset_id\":\"39272994714739463168905443499424551362424437245880253267329605556587274644733\", \"price\":\"0.26\", \"size\":\"106\", \"side\":\"BUY\", \"hash\":\"d1319e90b03f93ea166dbe8dc7a51e699d1f4dc3\", \"best_bid\":\"0.26\", \"best_ask\":\"0.28\"}, {\"asset_id\":\"20893381255801015515826997628594359667013752732428989472914000440642900266717\", \"price\":\"0.74\", \"size\":\"106\", \"side\":\"SELL\", \"hash\":\"c5a986bf2469206a9e924b5a2dfb53e0821f6be6\", \"best_bid\":\"0.72\", \"best_ask\":\"0.74\"}], \"timestamp\":\"1785204818080\", \"event_type\":\"price_change\"}","received_at":"2026-07-28T02:13:37.976005Z","schema_version":"clob-market-ws.price_change.v1","sequence":null,"server_hash":null,"server_timestamp":"1785204818080","session_id":"d2757dd6dad94f3b9fe67e8dbf1adc37","source":"clob_market_ws"},"received_at":"2026-07-28T02:13:37.976005Z","record_id":"b02f8edebaed1dbf056795db65cab89589d810100db7d6641c8831a23c498f8b","schema_fingerprint":"4aa3821a28b0b7c2400bc59aba4bcc0a76e971dadd19610d3ad38c768e124dc7","schema_version":"edge-lab-recorder.raw.v1","sequence":null,"source":"clob_market_ws"}
{"event_at":"2026-07-28T02:13:38.080000Z","event_fingerprint":"90f6ca94dbc1a6da628654a12bf3ccbecd45636f3f128a44b03adb99d6271d80","payload":{"connection_id":"5d29200f65794d4d9ab6ef271f045a9b","event_at":"2026-07-28T02:13:38.080000Z","event_type":"best_bid_ask","frame_hash":"ce9dac9c02f223518a8b0bcc2281db7db2cf20aa74dade40f19a9bb9db180511","frame_index":0,"kind":"data","monotonic_ns":306800990683083,"payload":{"asset_id":"20893381255801015515826997628594359667013752732428989472914000440642900266717","best_ask":"0.74","best_bid":"0.73","event_type":"best_bid_ask","market":"0xda6f0e0e93fc8469e0159a166028d017bddbc162b86f66bac90391379603d962","spread":"0.01","timestamp":"1785204818080"},"payload_hash":"e17de0f45f7b0688361d8a328b3788e0549ece351546b4c1164d5d1062130078","raw_frame":"{\"market\":\"0xda6f0e0e93fc8469e0159a166028d017bddbc162b86f66bac90391379603d962\", \"asset_id\":\"20893381255801015515826997628594359667013752732428989472914000440642900266717\", \"best_bid\":\"0.73\", \"best_ask\":\"0.74\", \"spread\":\"0.01\", \"timestamp\":\"1785204818080\", \"event_type\":\"best_bid_ask\"}","received_at":"2026-07-28T02:13:37.979526Z","schema_version":"clob-market-ws.best_bid_ask.v1","sequence":null,"server_hash":null,"server_timestamp":"1785204818080","session_id":"d2757dd6dad94f3b9fe67e8dbf1adc37","source":"clob_market_ws"},"received_at":"2026-07-28T02:13:37.979526Z","record_id":"e9e38d12d2aac464b4f616beba11fe0cb779c6d746980a9b59b346de4b066136","schema_fingerprint":"8488399f31b0337811b13b266be932db7062827c2470b78bd8e9e99bab51d17d","schema_version":"edge-lab-recorder.raw.v1","sequence":null,"source":"clob_market_ws"}
{"event_at":"2026-07-28T02:13:38.080000Z","event_fingerprint":"c6c7ccb5188d962abb6a7265dce98ea17f00b5f0ca3b605225ce63fee219a776","payload":{"connection_id":"5d29200f65794d4d9ab6ef271f045a9b","event_at":"2026-07-28T02:13:38.080000Z","event_type":"best_bid_ask","frame_hash":"96a5d5081042e8ac77847cc3e8b4a68ad52726cb5cd8b65dc6a7cd58336b0ead","frame_index":0,"kind":"data","monotonic_ns":306800993180791,"payload":{"asset_id":"39272994714739463168905443499424551362424437245880253267329605556587274644733","best_ask":"0.27","best_bid":"0.26","event_type":"best_bid_ask","market":"0xda6f0e0e93fc8469e0159a166028d017bddbc162b86f66bac90391379603d962","spread":"0.01","timestamp":"1785204818080"},"payload_hash":"ef3f953e81cd7cae7a83c2678b0e5ed5d83859e603aafe49691e0426af6f1102","raw_frame":"{\"market\":\"0xda6f0e0e93fc8469e0159a166028d017bddbc162b86f66bac90391379603d962\", \"asset_id\":\"39272994714739463168905443499424551362424437245880253267329605556587274644733\", \"best_bid\":\"0.26\", \"best_ask\":\"0.27\", \"spread\":\"0.01\", \"timestamp\":\"1785204818080\", \"event_type\":\"best_bid_ask\"}","received_at":"2026-07-28T02:13:37.982024Z","schema_version":"clob-market-ws.best_bid_ask.v1","sequence":null,"server_hash":null,"server_timestamp":"1785204818080","session_id":"d2757dd6dad94f3b9fe67e8dbf1adc37","source":"clob_market_ws"},"received_at":"2026-07-28T02:13:37.982024Z","record_id":"24e548242cb7459e09b4b0a9c548bc85fa2299e54c2242da885068f98f0609e4","schema_fingerprint":"8488399f31b0337811b13b266be932db7062827c2470b78bd8e9e99bab51d17d","schema_version":"edge-lab-recorder.raw.v1","sequence":null,"source":"clob_market_ws"}
{"event_at":"2026-07-28T02:13:38.080000Z","event_fingerprint":"6bb22fcccfefb9360abb92ea49fe283f53b93f4653289e0b86291a686271019f","payload":{"connection_id":"5d29200f65794d4d9ab6ef271f045a9b","event_at":"2026-07-28T02:13:38.080000Z","event_type":"price_change","frame_hash":"216abaf88f2996540fa1812a42504046194fab8e1eb054cdc2036d7a1a7dac81","frame_index":0,"kind":"data","monotonic_ns":306800995589000,"payload":{"event_type":"price_change","market":"0xda6f0e0e93fc8469e0159a166028d017bddbc162b86f66bac90391379603d962","price_changes":[{"asset_id":"20893381255801015515826997628594359667013752732428989472914000440642900266717","best_ask":"0.74","best_bid":"0.73","hash":"cc62c0382617cd8f6c1f66a27ef5a48fdbe9e1c8","price":"0.73","side":"BUY","size":"6"},{"asset_id":"39272994714739463168905443499424551362424437245880253267329605556587274644733","best_ask":"0.27","best_bid":"0.26","hash":"4db191d22d70aff6cde39b8c543f1cdf81879381","price":"0.27","side":"SELL","size":"6"}],"timestamp":"1785204818080"},"payload_hash":"01249d9e1206d149c895f984e8bf5eb17b58cee17b58fb46785081011eb37660","raw_frame":"{\"market\":\"0xda6f0e0e93fc8469e0159a166028d017bddbc162b86f66bac90391379603d962\", \"price_changes\":[{\"asset_id\":\"20893381255801015515826997628594359667013752732428989472914000440642900266717\", \"price\":\"0.73\", \"size\":\"6\", \"side\":\"BUY\", \"hash\":\"cc62c0382617cd8f6c1f66a27ef5a48fdbe9e1c8\", \"best_bid\":\"0.73\", \"best_ask\":\"0.74\"}, {\"asset_id\":\"39272994714739463168905443499424551362424437245880253267329605556587274644733\", \"price\":\"0.27\", \"size\":\"6\", \"side\":\"SELL\", \"hash\":\"4db191d22d70aff6cde39b8c543f1cdf81879381\", \"best_bid\":\"0.26\", \"best_ask\":\"0.27\"}], \"timestamp\":\"1785204818080\", \"event_type\":\"price_change\"}","received_at":"2026-07-28T02:13:37.984433Z","schema_version":"clob-market-ws.price_change.v1","sequence":null,"server_hash":null,"server_timestamp":"1785204818080","session_id":"d2757dd6dad94f3b9fe67e8dbf1adc37","source":"clob_market_ws"},"received_at":"2026-07-28T02:13:37.984433Z","record_id":"ff820686f02dea0aec9dac384cee6bd5c4ee189f3a4d51de3a6645c2a6c7f4e7","schema_fingerprint":"4aa3821a28b0b7c2400bc59aba4bcc0a76e971dadd19610d3ad38c768e124dc7","schema_version":"edge-lab-recorder.raw.v1","sequence":null,"source":"clob_market_ws"}
{"event_at":"2026-07-28T02:13:38.081000Z","event_fingerprint":"cc8c8949cfe9f02fc52695ff07c4a3d369fe034525d33bd995c3feb4906c7a3f","payload":{"connection_id":"5d29200f65794d4d9ab6ef271f045a9b","event_at":"2026-07-28T02:13:38.081000Z","event_type":"price_change","frame_hash":"3ae92f359eb33a496d8a04a881ee4994eed9435d8822ee4ee27e90d0a36de058","frame_index":0,"kind":"data","monotonic_ns":306800998438041,"payload":{"event_type":"price_change","market":"0xda6f0e0e93fc8469e0159a166028d017bddbc162b86f66bac90391379603d962","price_changes":[{"asset_id":"20893381255801015515826997628594359667013752732428989472914000440642900266717","best_ask":"0.74","best_bid":"0.73","hash":"ad6633e62950be0bbba4a353b9e801d80c6d44bb","price":"0.71","side":"BUY","size":"116.82"},{"asset_id":"39272994714739463168905443499424551362424437245880253267329605556587274644733","best_ask":"0.27","best_bid":"0.26","hash":"d96f8ed31e4e7e64dac9750e790e6d9c955c4bf5","price":"0.29","side":"SELL","size":"116.82"}],"timestamp":"1785204818081"},"payload_hash":"1089a06983b2cd608dc9828bc518a3d80df61fb37fe1dece3527c15f40c5b88b","raw_frame":"{\"market\":\"0xda6f0e0e93fc8469e0159a166028d017bddbc162b86f66bac90391379603d962\", \"price_changes\":[{\"asset_id\":\"20893381255801015515826997628594359667013752732428989472914000440642900266717\", \"price\":\"0.71\", \"size\":\"116.82\", \"side\":\"BUY\", \"hash\":\"ad6633e62950be0bbba4a353b9e801d80c6d44bb\", \"best_bid\":\"0.73\", \"best_ask\":\"0.74\"}, {\"asset_id\":\"39272994714739463168905443499424551362424437245880253267329605556587274644733\", \"price\":\"0.29\", \"size\":\"116.82\", \"side\":\"SELL\", \"hash\":\"d96f8ed31e4e7e64dac9750e790e6d9c955c4bf5\", \"best_bid\":\"0.26\", \"best_ask\":\"0.27\"}], \"timestamp\":\"1785204818081\", \"event_type\":\"price_change\"}","received_at":"2026-07-28T02:13:37.987282Z","schema_version":"clob-market-ws.price_change.v1","sequence":null,"server_hash":null,"server_timestamp":"1785204818081","session_id":"d2757dd6dad94f3b9fe67e8dbf1adc37","source":"clob_market_ws"},"received_at":"2026-07-28T02:13:37.987282Z","record_id":"6161071f6710b93e378d486f9f85a211d00e6a304d882aa34e7c6d96241b3e90","schema_fingerprint":"4aa3821a28b0b7c2400bc59aba4bcc0a76e971dadd19610d3ad38c768e124dc7","schema_version":"edge-lab-recorder.raw.v1","sequence":null,"source":"clob_market_ws"}
{"event_at":"2026-07-28T02:13:38.082000Z","event_fingerprint":"3306bb1cb38d837f8a3c7b86d15f5917475cab060192752ed25f2f3026318ef5","payload":{"connection_id":"5d29200f65794d4d9ab6ef271f045a9b","event_at":"2026-07-28T02:13:38.082000Z","event_type":"price_change","frame_hash":"f367238767def23790c448adab7e79354c9d98acc4be4474c5613f2cb5a3730c","frame_index":0,"kind":"data","monotonic_ns":306801000857708,"payload":{"event_type":"price_change","market":"0xda6f0e0e93fc8469e0159a166028d017bddbc162b86f66bac90391379603d962","price_changes":[{"asset_id":"20893381255801015515826997628594359667013752732428989472914000440642900266717","best_ask":"0.74","best_bid":"0.73","hash":"1791c791a067e98361115ae428d049b82e5fded6","price":"0.73","side":"BUY","size":"89"},{"asset_id":"39272994714739463168905443499424551362424437245880253267329605556587274644733","best_ask":"0.27","best_bid":"0.26","hash":"747e8c3a9b8ad6e7f0bcf05fa236eaa03ac9065b","price":"0.27","side":"SELL","size":"89"}],"timestamp":"1785204818082"},"payload_hash":"478875d7debee52027360324cd11ffce81646984fa4ef86033be0c1a937d0f0e","raw_frame":"{\"market\":\"0xda6f0e0e93fc8469e0159a166028d017bddbc162b86f66bac90391379603d962\", \"price_changes\":[{\"asset_id\":\"20893381255801015515826997628594359667013752732428989472914000440642900266717\", \"price\":\"0.73\", \"size\":\"89\", \"side\":\"BUY\", \"hash\":\"1791c791a067e98361115ae428d049b82e5fded6\", \"best_bid\":\"0.73\", \"best_ask\":\"0.74\"}, {\"asset_id\":\"39272994714739463168905443499424551362424437245880253267329605556587274644733\", \"price\":\"0.27\", \"size\":\"89\", \"side\":\"SELL\", \"hash\":\"747e8c3a9b8ad6e7f0bcf05fa236eaa03ac9065b\", \"best_bid\":\"0.26\", \"best_ask\":\"0.27\"}], \"timestamp\":\"1785204818082\", \"event_type\":\"price_change\"}","received_at":"2026-07-28T02:13:37.989702Z","schema_version":"clob-market-ws.price_change.v1","sequence":null,"server_hash":null,"server_timestamp":"1785204818082","session_id":"d2757dd6dad94f3b9fe67e8dbf1adc37","source":"clob_market_ws"},"received_at":"2026-07-28T02:13:37.989702Z","record_id":"35ca309ca64e75e9ca9e849a393634647eb51d3a204ee5106ae5a0537c5cc0c7","schema_fingerprint":"4aa3821a28b0b7c2400bc59aba4bcc0a76e971dadd19610d3ad38c768e124dc7","schema_version":"edge-lab-recorder.raw.v1","sequence":null,"source":"clob_market_ws"}
{"event_at":"2026-07-28T02:13:38.083000Z","event_fingerprint":"3f1e4263e37e9708a03e1d5e8122aadf83e8e286c48ecc265e75213813c77a26","payload":{"connection_id":"5d29200f65794d4d9ab6ef271f045a9b","event_at":"2026-07-28T02:13:38.083000Z","event_type":"price_change","frame_hash":"f79c9164232dd4d1363869e894eda0594c92725bcc1066597441db3e5dbdc971","frame_index":0,"kind":"data","monotonic_ns":306801003854291,"payload":{"event_type":"price_change","market":"0xda6f0e0e93fc8469e0159a166028d017bddbc162b86f66bac90391379603d962","price_changes":[{"asset_id":"20893381255801015515826997628594359667013752732428989472914000440642900266717","best_ask":"0.74","best_bid":"0.73","hash":"6bb30bf5d5eff3ea38720b4708cc35c28f8bdba6","price":"0.66","side":"BUY","size":"79"},{"asset_id":"39272994714739463168905443499424551362424437245880253267329605556587274644733","best_ask":"0.27","best_bid":"0.26","hash":"f1fad4ecb9f11eac79d8dd20c4c3402c2ffa4ab3","price":"0.34","side":"SELL","size":"79"}],"timestamp":"1785204818083"},"payload_hash":"a5214a0b83e23b5248290f652cda404bcc2324748acac35bac91afeea1a54beb","raw_frame":"{\"market\":\"0xda6f0e0e93fc8469e0159a166028d017bddbc162b86f66bac90391379603d962\", \"price_changes\":[{\"asset_id\":\"20893381255801015515826997628594359667013752732428989472914000440642900266717\", \"price\":\"0.66\", \"size\":\"79\", \"side\":\"BUY\", \"hash\":\"6bb30bf5d5eff3ea38720b4708cc35c28f8bdba6\", \"best_bid\":\"0.73\", \"best_ask\":\"0.74\"}, {\"asset_id\":\"39272994714739463168905443499424551362424437245880253267329605556587274644733\", \"price\":\"0.34\", \"size\":\"79\", \"side\":\"SELL\", \"hash\":\"f1fad4ecb9f11eac79d8dd20c4c3402c2ffa4ab3\", \"best_bid\":\"0.26\", \"best_ask\":\"0.27\"}], \"timestamp\":\"1785204818083\", \"event_type\":\"price_change\"}","received_at":"2026-07-28T02:13:37.992698Z","schema_version":"clob-market-ws.price_change.v1","sequence":null,"server_hash":null,"server_timestamp":"1785204818083","session_id":"d2757dd6dad94f3b9fe67e8dbf1adc37","source":"clob_market_ws"},"received_at":"2026-07-28T02:13:37.992698Z","record_id":"2239d09dc81129586a2f91a1fb25f8b4929f26ed735c5f1f595f25e92c16c5c3","schema_fingerprint":"4aa3821a28b0b7c2400bc59aba4bcc0a76e971dadd19610d3ad38c768e124dc7","schema_version":"edge-lab-recorder.raw.v1","sequence":null,"source":"clob_market_ws"}
{"event_at":"2026-07-28T02:13:38.090000Z","event_fingerprint":"4f2ae78df068343ce7e08101ef490285376612300ea94c6d42bf92cd738f3322","payload":{"connection_id":"5d29200f65794d4d9ab6ef271f045a9b","event_at":"2026-07-28T02:13:38.090000Z","event_type":"price_change","frame_hash":"002170595fa597f0fd307741cd66d78a0e5dbebd89199db29562469900aaaa3b","frame_index":0,"kind":"data","monotonic_ns":306801006750416,"payload":{"event_type":"price_change","market":"0xda6f0e0e93fc8469e0159a166028d017bddbc162b86f66bac90391379603d962","price_changes":[{"asset_id":"39272994714739463168905443499424551362424437245880253267329605556587274644733","best_ask":"0.27","best_bid":"0.26","hash":"5224a613ea2b53353bcec8efb9a4279a14b3f000","price":"0.24","side":"BUY","size":"7"},{"asset_id":"20893381255801015515826997628594359667013752732428989472914000440642900266717","best_ask":"0.74","best_bid":"0.73","hash":"631605982c7e3321204fdab250123b0c3c4f3c13","price":"0.76","side":"SELL","size":"7"}],"timestamp":"1785204818090"},"payload_hash":"97bd48578afba6f4e42850a101a5ca3bc7befb78567e254e16d72fe9855b9124","raw_frame":"{\"market\":\"0xda6f0e0e93fc8469e0159a166028d017bddbc162b86f66bac90391379603d962\", \"price_changes\":[{\"asset_id\":\"39272994714739463168905443499424551362424437245880253267329605556587274644733\", \"price\":\"0.24\", \"size\":\"7\", \"side\":\"BUY\", \"hash\":\"5224a613ea2b53353bcec8efb9a4279a14b3f000\", \"best_bid\":\"0.26\", \"best_ask\":\"0.27\"}, {\"asset_id\":\"20893381255801015515826997628594359667013752732428989472914000440642900266717\", \"price\":\"0.76\", \"size\":\"7\", \"side\":\"SELL\", \"hash\":\"631605982c7e3321204fdab250123b0c3c4f3c13\", \"best_bid\":\"0.73\", \"best_ask\":\"0.74\"}], \"timestamp\":\"1785204818090\", \"event_type\":\"price_change\"}","received_at":"2026-07-28T02:13:37.995594Z","schema_version":"clob-market-ws.price_change.v1","sequence":null,"server_hash":null,"server_timestamp":"1785204818090","session_id":"d2757dd6dad94f3b9fe67e8dbf1adc37","source":"clob_market_ws"},"received_at":"2026-07-28T02:13:37.995594Z","record_id":"dbc8435be6198673544d3e807429b3cbf19c727a4674180f2149eb0e7a56c79f","schema_fingerprint":"4aa3821a28b0b7c2400bc59aba4bcc0a76e971dadd19610d3ad38c768e124dc7","schema_version":"edge-lab-recorder.raw.v1","sequence":null,"source":"clob_market_ws"}
{"event_at":"2026-07-28T02:13:38.091000Z","event_fingerprint":"803687d233bdb912b7ce44612935daab1fef9a0cca81acc767683631a1bbed91","payload":{"connection_id":"5d29200f65794d4d9ab6ef271f045a9b","event_at":"2026-07-28T02:13:38.091000Z","event_type":"price_change","frame_hash":"b4c5f370664a22f23ff187b135afe3560dfcf61d4a806a43cf539d802a5f842e","frame_index":0,"kind":"data","monotonic_ns":306801010782666,"payload":{"event_type":"price_change","market":"0xda6f0e0e93fc8469e0159a166028d017bddbc162b86f66bac90391379603d962","price_changes":[{"asset_id":"20893381255801015515826997628594359667013752732428989472914000440642900266717","best_ask":"0.74","best_bid":"0.73","hash":"4b8fea96b55b5e6fc025845920a15fe3ca62c165","price":"0.73","side":"BUY","size":"94"},{"asset_id":"39272994714739463168905443499424551362424437245880253267329605556587274644733","best_ask":"0.27","best_bid":"0.26","hash":"40635afdb95a8904b90efc23b2bf362daa704283","price":"0.27","side":"SELL","size":"94"}],"timestamp":"1785204818091"},"payload_hash":"fded0542251ddc4b62ba869ce8a5dae85cad4bf170b464aabc8ae9594cf6dcf0","raw_frame":"{\"market\":\"0xda6f0e0e93fc8469e0159a166028d017bddbc162b86f66bac90391379603d962\", \"price_changes\":[{\"asset_id\":\"20893381255801015515826997628594359667013752732428989472914000440642900266717\", \"price\":\"0.73\", \"size\":\"94\", \"side\":\"BUY\", \"hash\":\"4b8fea96b55b5e6fc025845920a15fe3ca62c165\", \"best_bid\":\"0.73\", \"best_ask\":\"0.74\"}, {\"asset_id\":\"39272994714739463168905443499424551362424437245880253267329605556587274644733\", \"price\":\"0.27\", \"size\":\"94\", \"side\":\"SELL\", \"hash\":\"40635afdb95a8904b90efc23b2bf362daa704283\", \"best_bid\":\"0.26\", \"best_ask\":\"0.27\"}], \"timestamp\":\"1785204818091\", \"event_type\":\"price_change\"}","received_at":"2026-07-28T02:13:37.999626Z","schema_version":"clob-market-ws.price_change.v1","sequence":null,"server_hash":null,"server_timestamp":"1785204818091","session_id":"d2757dd6dad94f3b9fe67e8dbf1adc37","source":"clob_market_ws"},"received_at":"2026-07-28T02:13:37.999626Z","record_id":"1830a59f0bec3840c6fb2ce2cb569b884e9a239a9a8f6c9fbaba517b290e2a16","schema_fingerprint":"4aa3821a28b0b7c2400bc59aba4bcc0a76e971dadd19610d3ad38c768e124dc7","schema_version":"edge-lab-recorder.raw.v1","sequence":null,"source":"clob_market_ws"}
{"event_at":"2026-07-28T02:13:38.094000Z","event_fingerprint":"dc2c48c66650b0db0048d467aba6f886e5334c7d03830c816ec3794b91c171ba","payload":{"connection_id":"5d29200f65794d4d9ab6ef271f045a9b","event_at":"2026-07-28T02:13:38.094000Z","event_type":"price_change","frame_hash":"e4c6dc7bf392fb2d372c8726488a6914176de535bdc925e6d2514c6351852e72","frame_index":0,"kind":"data","monotonic_ns":306801013660625,"payload":{"event_type":"price_change","market":"0xda6f0e0e93fc8469e0159a166028d017bddbc162b86f66bac90391379603d962","price_changes":[{"asset_id":"39272994714739463168905443499424551362424437245880253267329605556587274644733","best_ask":"0.27","best_bid":"0.26","hash":"5799fad1927cedc3def624a97b9cf302f3349c9a","price":"0.27","side":"SELL","size":"99"},{"asset_id":"20893381255801015515826997628594359667013752732428989472914000440642900266717","best_ask":"0.74","best_bid":"0.73","hash":"34934e9191c962db31021e52c2f09c4594366e66","price":"0.73","side":"BUY","size":"99"}],"timestamp":"1785204818094"},"payload_hash":"572c022b6d5b09ce2d1f30519660f1c012ab6bdaba85d795ba2ed751b8988f76","raw_frame":"{\"market\":\"0xda6f0e0e93fc8469e0159a166028d017bddbc162b86f66bac90391379603d962\", \"price_changes\":[{\"asset_id\":\"39272994714739463168905443499424551362424437245880253267329605556587274644733\", \"price\":\"0.27\", \"size\":\"99\", \"side\":\"SELL\", \"hash\":\"5799fad1927cedc3def624a97b9cf302f3349c9a\", \"best_bid\":\"0.26\", \"best_ask\":\"0.27\"}, {\"asset_id\":\"20893381255801015515826997628594359667013752732428989472914000440642900266717\", \"price\":\"0.73\", \"size\":\"99\", \"side\":\"BUY\", \"hash\":\"34934e9191c962db31021e52c2f09c4594366e66\", \"best_bid\":\"0.73\", \"best_ask\":\"0.74\"}], \"timestamp\":\"1785204818094\", \"event_type\":\"price_change\"}","received_at":"2026-07-28T02:13:38.002504Z","schema_version":"clob-market-ws.price_change.v1","sequence":null,"server_hash":null,"server_timestamp":"1785204818094","session_id":"d2757dd6dad94f3b9fe67e8dbf1adc37","source":"clob_market_ws"},"received_at":"2026-07-28T02:13:38.002504Z","record_id":"fa08fb2412ec90350030d2c30f6ed411f2a823b9249e0be261ddb6b292532df6","schema_fingerprint":"4aa3821a28b0b7c2400bc59aba4bcc0a76e971dadd19610d3ad38c768e124dc7","schema_version":"edge-lab-recorder.raw.v1","sequence":null,"source":"clob_market_ws"}
{"event_at":"2026-07-28T02:13:38.099000Z","event_fingerprint":"2055bed7c0970c8a1ffe0c56c842eb31326bf6b9c9babee44c0c679f4b9fb728","payload":{"connection_id":"5d29200f65794d4d9ab6ef271f045a9b","event_at":"2026-07-28T02:13:38.099000Z","event_type":"price_change","frame_hash":"3644372286b6ca09593b6d52b999fab1e787772d70528d6f1ae647dbecb3c074","frame_index":0,"kind":"data","monotonic_ns":306801015989875,"payload":{"event_type":"price_change","market":"0xda6f0e0e93fc8469e0159a166028d017bddbc162b86f66bac90391379603d962","price_changes":[{"asset_id":"20893381255801015515826997628594359667013752732428989472914000440642900266717","best_ask":"0.74","best_bid":"0.73","hash":"79105b6f42dbc2f425854855ecf248c478b8b958","price":"0.72","side":"BUY","size":"37.52"},{"asset_id":"39272994714739463168905443499424551362424437245880253267329605556587274644733","best_ask":"0.27","best_bid":"0.26","hash":"27a0ba5c4dde8890c2091c726f499a3aece0983e","price":"0.28","side":"SELL","size":"37.52"}],"timestamp":"1785204818099"},"payload_hash":"3f46c881c9330b26c5b8639d4625e9229cbf0e74e1da1e430b81d4443a1934b3","raw_frame":"{\"market\":\"0xda6f0e0e93fc8469e0159a166028d017bddbc162b86f66bac90391379603d962\", \"price_changes\":[{\"asset_id\":\"20893381255801015515826997628594359667013752732428989472914000440642900266717\", \"price\":\"0.72\", \"size\":\"37.52\", \"side\":\"BUY\", \"hash\":\"79105b6f42dbc2f425854855ecf248c478b8b958\", \"best_bid\":\"0.73\", \"best_ask\":\"0.74\"}, {\"asset_id\":\"39272994714739463168905443499424551362424437245880253267329605556587274644733\", \"price\":\"0.28\", \"size\":\"37.52\", \"side\":\"SELL\", \"hash\":\"27a0ba5c4dde8890c2091c726f499a3aece0983e\", \"best_bid\":\"0.26\", \"best_ask\":\"0.27\"}], \"timestamp\":\"1785204818099\", \"event_type\":\"price_change\"}","received_at":"2026-07-28T02:13:38.004833Z","schema_version":"clob-market-ws.price_change.v1","sequence":null,"server_hash":null,"server_timestamp":"1785204818099","session_id":"d2757dd6dad94f3b9fe67e8dbf1adc37","source":"clob_market_ws"},"received_at":"2026-07-28T02:13:38.004833Z","record_id":"7084d71556fa091f8f46fe4dbffd4dcd51fc556d36e08ff68d51c03326251b71","schema_fingerprint":"4aa3821a28b0b7c2400bc59aba4bcc0a76e971dadd19610d3ad38c768e124dc7","schema_version":"edge-lab-recorder.raw.v1","sequence":null,"source":"clob_market_ws"}
{"event_at":"2026-07-28T02:13:38.104000Z","event_fingerprint":"21c11dee501ef7359a7502f61bae130e5cd6e947115763f08009d790b94d4a65","payload":{"connection_id":"5d29200f65794d4d9ab6ef271f045a9b","event_at":"2026-07-28T02:13:38.104000Z","event_type":"price_change","frame_hash":"a8b89d9d00fd44f88134993dbb600ca110a2d428a702e6a1e6672222b708b821","frame_index":0,"kind":"data","monotonic_ns":306801018281333,"payload":{"event_type":"price_change","market":"0xda6f0e0e93fc8469e0159a166028d017bddbc162b86f66bac90391379603d962","price_changes":[{"asset_id":"39272994714739463168905443499424551362424437245880253267329605556587274644733","best_ask":"0.27","best_bid":"0.26","hash":"14c163630d7815f2f69e869d4237a58274067b0e","price":"0.22","side":"BUY","size":"111"},{"asset_id":"20893381255801015515826997628594359667013752732428989472914000440642900266717","best_ask":"0.74","best_bid":"0.73","hash":"11b215147f7d05091d3ef837c743ff19e819a6b4","price":"0.78","side":"SELL","size":"111"}],"timestamp":"1785204818104"},"payload_hash":"8555e2a81f5107a2875178b5a7c7f1b68046dc35bbf789e002745560e8700419","raw_frame":"{\"market\":\"0xda6f0e0e93fc8469e0159a166028d017bddbc162b86f66bac90391379603d962\", \"price_changes\":[{\"asset_id\":\"39272994714739463168905443499424551362424437245880253267329605556587274644733\", \"price\":\"0.22\", \"size\":\"111\", \"side\":\"BUY\", \"hash\":\"14c163630d7815f2f69e869d4237a58274067b0e\", \"best_bid\":\"0.26\", \"best_ask\":\"0.27\"}, {\"asset_id\":\"20893381255801015515826997628594359667013752732428989472914000440642900266717\", \"price\":\"0.78\", \"size\":\"111\", \"side\":\"SELL\", \"hash\":\"11b215147f7d05091d3ef837c743ff19e819a6b4\", \"best_bid\":\"0.73\", \"best_ask\":\"0.74\"}], \"timestamp\":\"1785204818104\", \"event_type\":\"price_change\"}","received_at":"2026-07-28T02:13:38.007123Z","schema_version":"clob-market-ws.price_change.v1","sequence":null,"server_hash":null,"server_timestamp":"1785204818104","session_id":"d2757dd6dad94f3b9fe67e8dbf1adc37","source":"clob_market_ws"},"received_at":"2026-07-28T02:13:38.007123Z","record_id":"8f0255841225b564b72d5dd2f0fe16543f6915018cf2901bee4037c398593ab7","schema_fingerprint":"4aa3821a28b0b7c2400bc59aba4bcc0a76e971dadd19610d3ad38c768e124dc7","schema_version":"edge-lab-recorder.raw.v1","sequence":null,"source":"clob_market_ws"}
{"event_at":"2026-07-28T02:13:38.105000Z","event_fingerprint":"18357ef0f3676dda3dfdf60e0b7036dd5a0765dac92ec051ed458be94ff48823","payload":{"connection_id":"5d29200f65794d4d9ab6ef271f045a9b","event_at":"2026-07-28T02:13:38.105000Z","event_type":"price_change","frame_hash":"73923e8f1c5fc65399126215fa6462bf0aed5aabef8d8dc92a4d583dc8165ba7","frame_index":0,"kind":"data","monotonic_ns":306801019778875,"payload":{"event_type":"price_change","market":"0xda6f0e0e93fc8469e0159a166028d017bddbc162b86f66bac90391379603d962","price_changes":[{"asset_id":"39272994714739463168905443499424551362424437245880253267329605556587274644733","best_ask":"0.27","best_bid":"0.26","hash":"7d5f269ac9e59d58374921d678911297d15e5ed0","price":"0.26","side":"BUY","size":"10"},{"asset_id":"20893381255801015515826997628594359667013752732428989472914000440642900266717","best_ask":"0.74","best_bid":"0.73","hash":"bbbb4c8826872d8c4e613e5d657059447e00dd07","price":"0.74","side":"SELL","size":"10"}],"timestamp":"1785204818105"},"payload_hash":"f091aa9bae21c87601c1983df28a60b43f5e55f69a3bdb824896c3050fbf6f3b","raw_frame":"{\"market\":\"0xda6f0e0e93fc8469e0159a166028d017bddbc162b86f66bac90391379603d962\", \"price_changes\":[{\"asset_id\":\"39272994714739463168905443499424551362424437245880253267329605556587274644733\", \"price\":\"0.26\", \"size\":\"10\", \"side\":\"BUY\", \"hash\":\"7d5f269ac9e59d58374921d678911297d15e5ed0\", \"best_bid\":\"0.26\", \"best_ask\":\"0.27\"}, {\"asset_id\":\"20893381255801015515826997628594359667013752732428989472914000440642900266717\", \"price\":\"0.74\", \"size\":\"10\", \"side\":\"SELL\", \"hash\":\"bbbb4c8826872d8c4e613e5d657059447e00dd07\", \"best_bid\":\"0.73\", \"best_ask\":\"0.74\"}], \"timestamp\":\"1785204818105\", \"event_type\":\"price_change\"}","received_at":"2026-07-28T02:13:38.008620Z","schema_version":"clob-market-ws.price_change.v1","sequence":null,"server_hash":null,"server_timestamp":"1785204818105","session_id":"d2757dd6dad94f3b9fe67e8dbf1adc37","source":"clob_market_ws"},"received_at":"2026-07-28T02:13:38.008620Z","record_id":"65c76bd9901f81a5e5848ff12c564b79f2272ac1dd1c029331c865d89caf576e","schema_fingerprint":"4aa3821a28b0b7c2400bc59aba4bcc0a76e971dadd19610d3ad38c768e124dc7","schema_version":"edge-lab-recorder.raw.v1","sequence":null,"source":"clob_market_ws"}
{"event_at":"2026-07-28T02:13:38.109000Z","event_fingerprint":"f795ced3bfe3972ae20ea8c82ff47bbc034bff4c68115544f5018e77c74a7142","payload":{"connection_id":"5d29200f65794d4d9ab6ef271f045a9b","event_at":"2026-07-28T02:13:38.109000Z","event_type":"price_change","frame_hash":"03c6f793cdeccb9240eee9e67fa9e7c0d1c144aa2c5bb10bdb35e2d77e1c30fa","frame_index":0,"kind":"data","monotonic_ns":306801021298000,"payload":{"event_type":"price_change","market":"0xda6f0e0e93fc8469e0159a166028d017bddbc162b86f66bac90391379603d962","price_changes":[{"asset_id":"20893381255801015515826997628594359667013752732428989472914000440642900266717","best_ask":"0.74","best_bid":"0.73","hash":"7497ccbc8914778c4a21ad08f2d0a06231d8b9ad","price":"0.01","side":"BUY","size":"5379.02"},{"asset_id":"39272994714739463168905443499424551362424437245880253267329605556587274644733","best_ask":"0.27","best_bid":"0.26","hash":"5a205a07171eb508e362b3586bac50ccbb0509fe","price":"0.99","side":"SELL","size":"5379.02"}],"timestamp":"1785204818109"},"payload_hash":"231b10d84ac9974118923ba4b7eed7f18d24d7353a03d18d965702c2e1dc6c43","raw_frame":"{\"market\":\"0xda6f0e0e93fc8469e0159a166028d017bddbc162b86f66bac90391379603d962\", \"price_changes\":[{\"asset_id\":\"20893381255801015515826997628594359667013752732428989472914000440642900266717\", \"price\":\"0.01\", \"size\":\"5379.02\", \"side\":\"BUY\", \"hash\":\"7497ccbc8914778c4a21ad08f2d0a06231d8b9ad\", \"best_bid\":\"0.73\", \"best_ask\":\"0.74\"}, {\"asset_id\":\"39272994714739463168905443499424551362424437245880253267329605556587274644733\", \"price\":\"0.99\", \"size\":\"5379.02\", \"side\":\"SELL\", \"hash\":\"5a205a07171eb508e362b3586bac50ccbb0509fe\", \"best_bid\":\"0.26\", \"best_ask\":\"0.27\"}], \"timestamp\":\"1785204818109\", \"event_type\":\"price_change\"}","received_at":"2026-07-28T02:13:38.010141Z","schema_version":"clob-market-ws.price_change.v1","sequence":null,"server_hash":null,"server_timestamp":"1785204818109","session_id":"d2757dd6dad94f3b9fe67e8dbf1adc37","source":"clob_market_ws"},"received_at":"2026-07-28T02:13:38.010141Z","record_id":"c9e30513923b05c469b266a0e1694cbd126f139af5d179ed29f3de01f174e7c9","schema_fingerprint":"4aa3821a28b0b7c2400bc59aba4bcc0a76e971dadd19610d3ad38c768e124dc7","schema_version":"edge-lab-recorder.raw.v1","sequence":null,"source":"clob_market_ws"}
{"event_at":"2026-07-28T02:13:38.114000Z","event_fingerprint":"b65929744dc51cf10c02dddceabfa28c320ef83e70307b0b50f0a44e7ba3ff58","payload":{"connection_id":"5d29200f65794d4d9ab6ef271f045a9b","event_at":"2026-07-28T02:13:38.114000Z","event_type":"price_change","frame_hash":"5b4961270df2fcda87f592401776d09f7d4fe7e90d0454829c39a6ca9687584e","frame_index":0,"kind":"data","monotonic_ns":306801022753250,"payload":{"event_type":"price_change","market":"0xda6f0e0e93fc8469e0159a166028d017bddbc162b86f66bac90391379603d962","price_changes":[{"asset_id":"39272994714739463168905443499424551362424437245880253267329605556587274644733","best_ask":"0.27","best_bid":"0.26","hash":"f62c081d913cd44d3081658c4fe42c5d44787d26","price":"0.25","side":"BUY","size":"111"},{"asset_id":"20893381255801015515826997628594359667013752732428989472914000440642900266717","best_ask":"0.74","best_bid":"0.73","hash":"ac9fafba638074682e4967b68196ac7fcd8046e7","price":"0.75","side":"SELL","size":"111"}],"timestamp":"1785204818114"},"payload_hash":"e1e3fda1dad4dd19e9de6d6f448caa4c85b213224d0173f6044f8dd3a6d80d0c","raw_frame":"{\"market\":\"0xda6f0e0e93fc8469e0159a166028d017bddbc162b86f66bac90391379603d962\", \"price_changes\":[{\"asset_id\":\"39272994714739463168905443499424551362424437245880253267329605556587274644733\", \"price\":\"0.25\", \"size\":\"111\", \"side\":\"BUY\", \"hash\":\"f62c081d913cd44d3081658c4fe42c5d44787d26\", \"best_bid\":\"0.26\", \"best_ask\":\"0.27\"}, {\"asset_id\":\"20893381255801015515826997628594359667013752732428989472914000440642900266717\", \"price\":\"0.75\", \"size\":\"111\", \"side\":\"SELL\", \"hash\":\"ac9fafba638074682e4967b68196ac7fcd8046e7\", \"best_bid\":\"0.73\", \"best_ask\":\"0.74\"}], \"timestamp\":\"1785204818114\", \"event_type\":\"price_change\"}","received_at":"2026-07-28T02:13:38.011595Z","schema_version":"clob-market-ws.price_change.v1","sequence":null,"server_hash":null,"server_timestamp":"1785204818114","session_id":"d2757dd6dad94f3b9fe67e8dbf1adc37","source":"clob_market_ws"},"received_at":"2026-07-28T02:13:38.011595Z","record_id":"296b06b0a8677887ed861e0a22a5d5bc6417af1341201af6eb12be4a445dbeaf","schema_fingerprint":"4aa3821a28b0b7c2400bc59aba4bcc0a76e971dadd19610d3ad38c768e124dc7","schema_version":"edge-lab-recorder.raw.v1","sequence":null,"source":"clob_market_ws"}
{"event_at":"2026-07-28T02:13:38.116000Z","event_fingerprint":"641d7af0207cebd8c3573bec375b66d9201bf07a8445e63d156a9b24633f9e3b","payload":{"connection_id":"5d29200f65794d4d9ab6ef271f045a9b","event_at":"2026-07-28T02:13:38.116000Z","event_type":"price_change","frame_hash":"c140026316b24a0adda297522a3a9c10c0cf2d3832b6a915a5ccf67a231394ab","frame_index":0,"kind":"data","monotonic_ns":306801024230000,"payload":{"event_type":"price_change","market":"0xda6f0e0e93fc8469e0159a166028d017bddbc162b86f66bac90391379603d962","price_changes":[{"asset_id":"20893381255801015515826997628594359667013752732428989472914000440642900266717","best_ask":"0.74","best_bid":"0.73","hash":"b0c922879fd7ad57df8fb73f2ca75bcd10c7abce","price":"0.01","side":"BUY","size":"5384.02"},{"asset_id":"39272994714739463168905443499424551362424437245880253267329605556587274644733","best_ask":"0.27","best_bid":"0.26","hash":"37538f0fe1246e7944278d215fafc7eae50c2dd6","price":"0.99","side":"SELL","size":"5384.02"}],"timestamp":"1785204818116"},"payload_hash":"3685b65828b8744b77698dbf2f462e777d75fb81312722a791eb9e01da12dd66","raw_frame":"{\"market\":\"0xda6f0e0e93fc8469e0159a166028d017bddbc162b86f66bac90391379603d962\", \"price_changes\":[{\"asset_id\":\"20893381255801015515826997628594359667013752732428989472914000440642900266717\", \"price\":\"0.01\", \"size\":\"5384.02\", \"side\":\"BUY\", \"hash\":\"b0c922879fd7ad57df8fb73f2ca75bcd10c7abce\", \"best_bid\":\"0.73\", \"best_ask\":\"0.74\"}, {\"asset_id\":\"39272994714739463168905443499424551362424437245880253267329605556587274644733\", \"price\":\"0.99\", \"size\":\"5384.02\", \"side\":\"SELL\", \"hash\":\"37538f0fe1246e7944278d215fafc7eae50c2dd6\", \"best_bid\":\"0.26\", \"best_ask\":\"0.27\"}], \"timestamp\":\"1785204818116\", \"event_type\":\"price_change\"}","received_at":"2026-07-28T02:13:38.013073Z","schema_version":"clob-market-ws.price_change.v1","sequence":null,"server_hash":null,"server_timestamp":"1785204818116","session_id":"d2757dd6dad94f3b9fe67e8dbf1adc37","source":"clob_market_ws"},"received_at":"2026-07-28T02:13:38.013073Z","record_id":"0b66043ea328398d498858a26689af5fda5e03ea5493abf042dc1ea0faefcb0b","schema_fingerprint":"4aa3821a28b0b7c2400bc59aba4bcc0a76e971dadd19610d3ad38c768e124dc7","schema_version":"edge-lab-recorder.raw.v1","sequence":null,"source":"clob_market_ws"}
{"event_at":"2026-07-28T02:13:38.117000Z","event_fingerprint":"9d8b7e11d69f21a8376cecb45b2dc168ddc06718cb6102ab0302182467d46f13","payload":{"connection_id":"5d29200f65794d4d9ab6ef271f045a9b","event_at":"2026-07-28T02:13:38.117000Z","event_type":"price_change","frame_hash":"15d4c136d2fa2e193f0322b2cca1a277ced8e9ef0252de190517052cc64ea581","frame_index":0,"kind":"data","monotonic_ns":306801025723000,"payload":{"event_type":"price_change","market":"0xda6f0e0e93fc8469e0159a166028d017bddbc162b86f66bac90391379603d962","price_changes":[{"asset_id":"39272994714739463168905443499424551362424437245880253267329605556587274644733","best_ask":"0.27","best_bid":"0.26","hash":"f87e67c7d84b61d2d3335b1c8e0622b181a1f249","price":"0.2","side":"BUY","size":"77"},{"asset_id":"20893381255801015515826997628594359667013752732428989472914000440642900266717","best_ask":"0.74","best_bid":"0.73","hash":"48dc98645273c8035d8dcb411da4d8d4af08e2f1","price":"0.8","side":"SELL","size":"77"}],"timestamp":"1785204818117"},"payload_hash":"dfdc0437688ccf599f5f94d9b013e10f15b47f694d7244e36329d5b2073cbf80","raw_frame":"{\"market\":\"0xda6f0e0e93fc8469e0159a166028d017bddbc162b86f66bac90391379603d962\", \"price_changes\":[{\"asset_id\":\"39272994714739463168905443499424551362424437245880253267329605556587274644733\", \"price\":\"0.2\", \"size\":\"77\", \"side\":\"BUY\", \"hash\":\"f87e67c7d84b61d2d3335b1c8e0622b181a1f249\", \"best_bid\":\"0.26\", \"best_ask\":\"0.27\"}, {\"asset_id\":\"20893381255801015515826997628594359667013752732428989472914000440642900266717\", \"price\":\"0.8\", \"size\":\"77\", \"side\":\"SELL\", \"hash\":\"48dc98645273c8035d8dcb411da4d8d4af08e2f1\", \"best_bid\":\"0.73\", \"best_ask\":\"0.74\"}], \"timestamp\":\"1785204818117\", \"event_type\":\"price_change\"}","received_at":"2026-07-28T02:13:38.014565Z","schema_version":"clob-market-ws.price_change.v1","sequence":null,"server_hash":null,"server_timestamp":"1785204818117","session_id":"d2757dd6dad94f3b9fe67e8dbf1adc37","source":"clob_market_ws"},"received_at":"2026-07-28T02:13:38.014565Z","record_id":"b0e125421212e08268a59ec56755d5986222609a2c82afc37b8fd99cca30742f","schema_fingerprint":"4aa3821a28b0b7c2400bc59aba4bcc0a76e971dadd19610d3ad38c768e124dc7","schema_version":"edge-lab-recorder.raw.v1","sequence":null,"source":"clob_market_ws"}
{"event_at":"2026-07-28T02:13:38.133000Z","event_fingerprint":"bbec045332dcda4b345cd6817ef44ec73ecddf85cd0119814e160870d8596e5a","payload":{"connection_id":"5d29200f65794d4d9ab6ef271f045a9b","event_at":"2026-07-28T02:13:38.133000Z","event_type":"price_change","frame_hash":"9b6c1b7dc1d7369a4629ede97e0a08a32c79e9b98cae9d8ed9e5e9630e23b781","frame_index":0,"kind":"data","monotonic_ns":306801033054333,"payload":{"event_type":"price_change","market":"0xda6f0e0e93fc8469e0159a166028d017bddbc162b86f66bac90391379603d962","price_changes":[{"asset_id":"20893381255801015515826997628594359667013752732428989472914000440642900266717","best_ask":"0.74","best_bid":"0.73","hash":"e2416837973b862a0e97684522ceb73985da2faa","price":"0.01","side":"BUY","size":"5379.02"},{"asset_id":"39272994714739463168905443499424551362424437245880253267329605556587274644733","best_ask":"0.27","best_bid":"0.26","hash":"aa307df5e7626850070ef161dc4ffdb50c50c791","price":"0.99","side":"SELL","size":"5379.02"}],"timestamp":"1785204818133"},"payload_hash":"d8848f5511cfd90cc6aca44a6bedf7c4d9b45b1a029b816b86b1168823c5ff4e","raw_frame":"{\"market\":\"0xda6f0e0e93fc8469e0159a166028d017bddbc162b86f66bac90391379603d962\", \"price_changes\":[{\"asset_id\":\"20893381255801015515826997628594359667013752732428989472914000440642900266717\", \"price\":\"0.01\", \"size\":\"5379.02\", \"side\":\"BUY\", \"hash\":\"e2416837973b862a0e97684522ceb73985da2faa\", \"best_bid\":\"0.73\", \"best_ask\":\"0.74\"}, {\"asset_id\":\"39272994714739463168905443499424551362424437245880253267329605556587274644733\", \"price\":\"0.99\", \"size\":\"5379.02\", \"side\":\"SELL\", \"hash\":\"aa307df5e7626850070ef161dc4ffdb50c50c791\", \"best_bid\":\"0.26\", \"best_ask\":\"0.27\"}], \"timestamp\":\"1785204818133\", \"event_type\":\"price_change\"}","received_at":"2026-07-28T02:13:38.021896Z","schema_version":"clob-market-ws.price_change.v1","sequence":null,"server_hash":null,"server_timestamp":"1785204818133","session_id":"d2757dd6dad94f3b9fe67e8dbf1adc37","source":"clob_market_ws"},"received_at":"2026-07-28T02:13:38.021896Z","record_id":"eb514702ac364b04cefdca444b41c4cfcfaf07e806413deafb4e50f9fd1b317a","schema_fingerprint":"4aa3821a28b0b7c2400bc59aba4bcc0a76e971dadd19610d3ad38c768e124dc7","schema_version":"edge-lab-recorder.raw.v1","sequence":null,"source":"clob_market_ws"}
{"event_at":"2026-07-28T02:13:38.170000Z","event_fingerprint":"df075c3c8e57f03cb901b5b0b23c181b81d58cb782ac4a419ab4380d83a53c96","payload":{"connection_id":"5d29200f65794d4d9ab6ef271f045a9b","event_at":"2026-07-28T02:13:38.170000Z","event_type":"price_change","frame_hash":"b33b155223eafe4ce1055f5b881d23666cd785b4fcee4dad676d6b0c0e0ef376","frame_index":0,"kind":"data","monotonic_ns":306801063421625,"payload":{"event_type":"price_change","market":"0xda6f0e0e93fc8469e0159a166028d017bddbc162b86f66bac90391379603d962","price_changes":[{"asset_id":"20893381255801015515826997628594359667013752732428989472914000440642900266717","best_ask":"0.74","best_bid":"0.73","hash":"3ea1c5213128fd9213555274ea38c097c4e62d36","price":"0.01","side":"BUY","size":"5374.02"},{"asset_id":"39272994714739463168905443499424551362424437245880253267329605556587274644733","best_ask":"0.27","best_bid":"0.26","hash":"04125810b5ac6279186b44ef2460f4cf65bd9255","price":"0.99","side":"SELL","size":"5374.02"}],"timestamp":"1785204818170"},"payload_hash":"84e19db47d5cd13be202d33a367e749d3d319018fb5e88c11840b908f6eb78f9","raw_frame":"{\"market\":\"0xda6f0e0e93fc8469e0159a166028d017bddbc162b86f66bac90391379603d962\", \"price_changes\":[{\"asset_id\":\"20893381255801015515826997628594359667013752732428989472914000440642900266717\", \"price\":\"0.01\", \"size\":\"5374.02\", \"side\":\"BUY\", \"hash\":\"3ea1c5213128fd9213555274ea38c097c4e62d36\", \"best_bid\":\"0.73\", \"best_ask\":\"0.74\"}, {\"asset_id\":\"39272994714739463168905443499424551362424437245880253267329605556587274644733\", \"price\":\"0.99\", \"size\":\"5374.02\", \"side\":\"SELL\", \"hash\":\"04125810b5ac6279186b44ef2460f4cf65bd9255\", \"best_bid\":\"0.26\", \"best_ask\":\"0.27\"}], \"timestamp\":\"1785204818170\", \"event_type\":\"price_change\"}","received_at":"2026-07-28T02:13:38.052263Z","schema_version":"clob-market-ws.price_change.v1","sequence":null,"server_hash":null,"server_timestamp":"1785204818170","session_id":"d2757dd6dad94f3b9fe67e8dbf1adc37","source":"clob_market_ws"},"received_at":"2026-07-28T02:13:38.052263Z","record_id":"722248732387afb1c2f6fd3a7de4e538e6ebe65ea1bd0953f80d710dbae7057f","schema_fingerprint":"4aa3821a28b0b7c2400bc59aba4bcc0a76e971dadd19610d3ad38c768e124dc7","schema_version":"edge-lab-recorder.raw.v1","sequence":null,"source":"clob_market_ws"}
{"event_at":"2026-07-28T02:13:38.176000Z","event_fingerprint":"c8bca1224ac976618370e8a8491994492454e09232b3ab564894e65200d06113","payload":{"connection_id":"5d29200f65794d4d9ab6ef271f045a9b","event_at":"2026-07-28T02:13:38.176000Z","event_type":"price_change","frame_hash":"158a078b194aadf76f31ca6bb582355c6c2571aaca173bbd576e3d67b1cbe654","frame_index":0,"kind":"data","monotonic_ns":306801069591791,"payload":{"event_type":"price_change","market":"0xda6f0e0e93fc8469e0159a166028d017bddbc162b86f66bac90391379603d962","price_changes":[{"asset_id":"20893381255801015515826997628594359667013752732428989472914000440642900266717","best_ask":"0.74","best_bid":"0.73","hash":"6a1c6f621f3efa6bd9e90eb0ea51bf47cf19857a","price":"0.72","side":"BUY","size":"12.52"},{"asset_id":"39272994714739463168905443499424551362424437245880253267329605556587274644733","best_ask":"0.27","best_bid":"0.26","hash":"e96cb12f4d5872ff6a74abbb88949755db12252a","price":"0.28","side":"SELL","size":"12.52"}],"timestamp":"1785204818176"},"payload_hash":"530bc25638a7d351fd894630b00e441355a6e2e338afa2d51a0ad922a5630311","raw_frame":"{\"market\":\"0xda6f0e0e93fc8469e0159a166028d017bddbc162b86f66bac90391379603d962\", \"price_changes\":[{\"asset_id\":\"20893381255801015515826997628594359667013752732428989472914000440642900266717\", \"price\":\"0.72\", \"size\":\"12.52\", \"side\":\"BUY\", \"hash\":\"6a1c6f621f3efa6bd9e90eb0ea51bf47cf19857a\", \"best_bid\":\"0.73\", \"best_ask\":\"0.74\"}, {\"asset_id\":\"39272994714739463168905443499424551362424437245880253267329605556587274644733\", \"price\":\"0.28\", \"size\":\"12.52\", \"side\":\"SELL\", \"hash\":\"e96cb12f4d5872ff6a74abbb88949755db12252a\", \"best_bid\":\"0.26\", \"best_ask\":\"0.27\"}], \"timestamp\":\"1785204818176\", \"event_type\":\"price_change\"}","received_at":"2026-07-28T02:13:38.058433Z","schema_version":"clob-market-ws.price_change.v1","sequence":null,"server_hash":null,"server_timestamp":"1785204818176","session_id":"d2757dd6dad94f3b9fe67e8dbf1adc37","source":"clob_market_ws"},"received_at":"2026-07-28T02:13:38.058433Z","record_id":"98667bf5032caa40e8a440bae14d7f4121d529178a8c9d5c21c1133b85811826","schema_fingerprint":"4aa3821a28b0b7c2400bc59aba4bcc0a76e971dadd19610d3ad38c768e124dc7","schema_version":"edge-lab-recorder.raw.v1","sequence":null,"source":"clob_market_ws"}
{"event_at":"2026-07-28T02:13:38.187000Z","event_fingerprint":"6f7ce86f8e6c5081dc6eb7e7427cacac1aa30df72f9a66af6efa48fc28cd87d8","payload":{"connection_id":"5d29200f65794d4d9ab6ef271f045a9b","event_at":"2026-07-28T02:13:38.187000Z","event_type":"price_change","frame_hash":"41cffd2145bd4b8e020037e5de7c464f0afe1059f8eb22a8833ce7170b59d104","frame_index":0,"kind":"data","monotonic_ns":306801080929791,"payload":{"event_type":"price_change","market":"0xda6f0e0e93fc8469e0159a166028d017bddbc162b86f66bac90391379603d962","price_changes":[{"asset_id":"20893381255801015515826997628594359667013752732428989472914000440642900266717","best_ask":"0.74","best_bid":"0.73","hash":"b60af5b700ed93b0fbb1daf38bab1322f825a745","price":"0.73","side":"BUY","size":"16"},{"asset_id":"39272994714739463168905443499424551362424437245880253267329605556587274644733","best_ask":"0.27","best_bid":"0.26","hash":"6ae634593d51f2b0b25d9c000b0463a6dd2e5e8e","price":"0.27","side":"SELL","size":"16"}],"timestamp":"1785204818187"},"payload_hash":"c075cdc387fba349d0c3b01bf1a8e5347414f0e36208d6d2f0f1d38a8d50096d","raw_frame":"{\"market\":\"0xda6f0e0e93fc8469e0159a166028d017bddbc162b86f66bac90391379603d962\", \"price_changes\":[{\"asset_id\":\"20893381255801015515826997628594359667013752732428989472914000440642900266717\", \"price\":\"0.73\", \"size\":\"16\", \"side\":\"BUY\", \"hash\":\"b60af5b700ed93b0fbb1daf38bab1322f825a745\", \"best_bid\":\"0.73\", \"best_ask\":\"0.74\"}, {\"asset_id\":\"39272994714739463168905443499424551362424437245880253267329605556587274644733\", \"price\":\"0.27\", \"size\":\"16\", \"side\":\"SELL\", \"hash\":\"6ae634593d51f2b0b25d9c000b0463a6dd2e5e8e\", \"best_bid\":\"0.26\", \"best_ask\":\"0.27\"}], \"timestamp\":\"1785204818187\", \"event_type\":\"price_change\"}","received_at":"2026-07-28T02:13:38.069771Z","schema_version":"clob-market-ws.price_change.v1","sequence":null,"server_hash":null,"server_timestamp":"1785204818187","session_id":"d2757dd6dad94f3b9fe67e8dbf1adc37","source":"clob_market_ws"},"received_at":"2026-07-28T02:13:38.069771Z","record_id":"6a33a87ce9aee8282fc6a6f9800a7944b308b7d192fac49fcdc92ef85e609a6f","schema_fingerprint":"4aa3821a28b0b7c2400bc59aba4bcc0a76e971dadd19610d3ad38c768e124dc7","schema_version":"edge-lab-recorder.raw.v1","sequence":null,"source":"clob_market_ws"}
{"event_at":"2026-07-28T02:13:38.189000Z","event_fingerprint":"86fd641c022124c9671ea520d19bf53888eb6f90c375708abce5b897f01d8abd","payload":{"connection_id":"5d29200f65794d4d9ab6ef271f045a9b","event_at":"2026-07-28T02:13:38.189000Z","event_type":"price_change","frame_hash":"5b9982deaea1fe90128a944f358c04832a5c8a96711be92cd1a1e6ce3a27ad0c","frame_index":0,"kind":"data","monotonic_ns":306801083663000,"payload":{"event_type":"price_change","market":"0xda6f0e0e93fc8469e0159a166028d017bddbc162b86f66bac90391379603d962","price_changes":[{"asset_id":"39272994714739463168905443499424551362424437245880253267329605556587274644733","best_ask":"0.27","best_bid":"0.26","hash":"1a5e213969cebb757dcf35ed4af011539662cb1d","price":"0.28","side":"SELL","size":"90.99"},{"asset_id":"20893381255801015515826997628594359667013752732428989472914000440642900266717","best_ask":"0.74","best_bid":"0.73","hash":"fc5fe5de77ba51021a36205029fe4e5944b8faeb","price":"0.72","side":"BUY","size":"90.99"}],"timestamp":"1785204818189"},"payload_hash":"34258f9bb5ceb9785b2f3c0f3443d24da47e4b744ea65416da5b625bb1cb95e3","raw_frame":"{\"market\":\"0xda6f0e0e93fc8469e0159a166028d017bddbc162b86f66bac90391379603d962\", \"price_changes\":[{\"asset_id\":\"39272994714739463168905443499424551362424437245880253267329605556587274644733\", \"price\":\"0.28\", \"size\":\"90.99\", \"side\":\"SELL\", \"hash\":\"1a5e213969cebb757dcf35ed4af011539662cb1d\", \"best_bid\":\"0.26\", \"best_ask\":\"0.27\"}, {\"asset_id\":\"20893381255801015515826997628594359667013752732428989472914000440642900266717\", \"price\":\"0.72\", \"size\":\"90.99\", \"side\":\"BUY\", \"hash\":\"fc5fe5de77ba51021a36205029fe4e5944b8faeb\", \"best_bid\":\"0.73\", \"best_ask\":\"0.74\"}], \"timestamp\":\"1785204818189\", \"event_type\":\"price_change\"}","received_at":"2026-07-28T02:13:38.072505Z","schema_version":"clob-market-ws.price_change.v1","sequence":null,"server_hash":null,"server_timestamp":"1785204818189","session_id":"d2757dd6dad94f3b9fe67e8dbf1adc37","source":"clob_market_ws"},"received_at":"2026-07-28T02:13:38.072505Z","record_id":"bf28d36a7556e64b3aef9d4089fe3fc13693e6441118de35943bf49d4a7f811c","schema_fingerprint":"4aa3821a28b0b7c2400bc59aba4bcc0a76e971dadd19610d3ad38c768e124dc7","schema_version":"edge-lab-recorder.raw.v1","sequence":null,"source":"clob_market_ws"}
{"event_at":"2026-07-28T02:13:38.190000Z","event_fingerprint":"d06782bc0f7b7ca6524cf3ee3cc1f70f78971b0ecc7ccba8664ba8de885ae3ad","payload":{"connection_id":"5d29200f65794d4d9ab6ef271f045a9b","event_at":"2026-07-28T02:13:38.190000Z","event_type":"price_change","frame_hash":"9d1ccb416ca24a6a36480161ea789691021cc703f775eac71d262f8fd9a8f550","frame_index":0,"kind":"data","monotonic_ns":306801087756166,"payload":{"event_type":"price_change","market":"0xda6f0e0e93fc8469e0159a166028d017bddbc162b86f66bac90391379603d962","price_changes":[{"asset_id":"20893381255801015515826997628594359667013752732428989472914000440642900266717","best_ask":"0.74","best_bid":"0.73","hash":"3fb960e98fbcd08f463a6ee84248124fa822637d","price":"0.71","side":"BUY","size":"131.99"},{"asset_id":"39272994714739463168905443499424551362424437245880253267329605556587274644733","best_ask":"0.27","best_bid":"0.26","hash":"2c037af46c3a54ca171e6ee64ce0c2720c268579","price":"0.29","side":"SELL","size":"131.99"}],"timestamp":"1785204818190"},"payload_hash":"f637c37de5a069b82dc3a17aacd0c30b6adec05b3af5b26c4fdd161fab03a355","raw_frame":"{\"market\":\"0xda6f0e0e93fc8469e0159a166028d017bddbc162b86f66bac90391379603d962\", \"price_changes\":[{\"asset_id\":\"20893381255801015515826997628594359667013752732428989472914000440642900266717\", \"price\":\"0.71\", \"size\":\"131.99\", \"side\":\"BUY\", \"hash\":\"3fb960e98fbcd08f463a6ee84248124fa822637d\", \"best_bid\":\"0.73\", \"best_ask\":\"0.74\"}, {\"asset_id\":\"39272994714739463168905443499424551362424437245880253267329605556587274644733\", \"price\":\"0.29\", \"size\":\"131.99\", \"side\":\"SELL\", \"hash\":\"2c037af46c3a54ca171e6ee64ce0c2720c268579\", \"best_bid\":\"0.26\", \"best_ask\":\"0.27\"}], \"timestamp\":\"1785204818190\", \"event_type\":\"price_change\"}","received_at":"2026-07-28T02:13:38.076599Z","schema_version":"clob-market-ws.price_change.v1","sequence":null,"server_hash":null,"server_timestamp":"1785204818190","session_id":"d2757dd6dad94f3b9fe67e8dbf1adc37","source":"clob_market_ws"},"received_at":"2026-07-28T02:13:38.076599Z","record_id":"c16b3d033d80495bb117ee20f681222fd80e6a72cb1e6b3de5fb334510850b99","schema_fingerprint":"4aa3821a28b0b7c2400bc59aba4bcc0a76e971dadd19610d3ad38c768e124dc7","schema_version":"edge-lab-recorder.raw.v1","sequence":null,"source":"clob_market_ws"}
{"event_at":"2026-07-28T02:13:38.191000Z","event_fingerprint":"aa64730a9619c09e852034d6e1daba026e99df7f09607d2a4ad084a3ab9432e0","payload":{"connection_id":"5d29200f65794d4d9ab6ef271f045a9b","event_at":"2026-07-28T02:13:38.191000Z","event_type":"price_change","frame_hash":"59f56ae58f526888bdb7a9af460487464be05d160efc4792fcf9034cc132f688","frame_index":0,"kind":"data","monotonic_ns":306801089034250,"payload":{"event_type":"price_change","market":"0xda6f0e0e93fc8469e0159a166028d017bddbc162b86f66bac90391379603d962","price_changes":[{"asset_id":"20893381255801015515826997628594359667013752732428989472914000440642900266717","best_ask":"0.74","best_bid":"0.73","hash":"ed8170583c2237ab02c4003cbb195b5bec09707f","price":"0.82","side":"SELL","size":"240.85"},{"asset_id":"39272994714739463168905443499424551362424437245880253267329605556587274644733","best_ask":"0.27","best_bid":"0.26","hash":"128b5220fc7cbe57ea4f3d6ae20be21fc9af96df","price":"0.18","side":"BUY","size":"240.85"}],"timestamp":"1785204818191"},"payload_hash":"5846013c09fe2a9f0b32025472a621da96257c254f47d830c61bd48958891320","raw_frame":"{\"market\":\"0xda6f0e0e93fc8469e0159a166028d017bddbc162b86f66bac90391379603d962\", \"price_changes\":[{\"asset_id\":\"20893381255801015515826997628594359667013752732428989472914000440642900266717\", \"price\":\"0.82\", \"size\":\"240.85\", \"side\":\"SELL\", \"hash\":\"ed8170583c2237ab02c4003cbb195b5bec09707f\", \"best_bid\":\"0.73\", \"best_ask\":\"0.74\"}, {\"asset_id\":\"39272994714739463168905443499424551362424437245880253267329605556587274644733\", \"price\":\"0.18\", \"size\":\"240.85\", \"side\":\"BUY\", \"hash\":\"128b5220fc7cbe57ea4f3d6ae20be21fc9af96df\", \"best_bid\":\"0.26\", \"best_ask\":\"0.27\"}], \"timestamp\":\"1785204818191\", \"event_type\":\"price_change\"}","received_at":"2026-07-28T02:13:38.077877Z","schema_version":"clob-market-ws.price_change.v1","sequence":null,"server_hash":null,"server_timestamp":"1785204818191","session_id":"d2757dd6dad94f3b9fe67e8dbf1adc37","source":"clob_market_ws"},"received_at":"2026-07-28T02:13:38.077877Z","record_id":"4caeee9e45ec3727b676ef3c1145afc2df03260735844b39d2c42ad80af49546","schema_fingerprint":"4aa3821a28b0b7c2400bc59aba4bcc0a76e971dadd19610d3ad38c768e124dc7","schema_version":"edge-lab-recorder.raw.v1","sequence":null,"source":"clob_market_ws"}
{"event_at":"2026-07-28T02:13:38.217000Z","event_fingerprint":"f79749caf2d5c0c9d2ff771ddd5258a375f5c6b8aef8c99361c5b6babaf29269","payload":{"connection_id":"5d29200f65794d4d9ab6ef271f045a9b","event_at":"2026-07-28T02:13:38.217000Z","event_type":"price_change","frame_hash":"7ca65b1e8d3e70fe7396d93b1da8aa4957652a0d9d204bef124037b8ae9c2a8b","frame_index":0,"kind":"data","monotonic_ns":306801111010708,"payload":{"event_type":"price_change","market":"0xda6f0e0e93fc8469e0159a166028d017bddbc162b86f66bac90391379603d962","price_changes":[{"asset_id":"20893381255801015515826997628594359667013752732428989472914000440642900266717","best_ask":"0.74","best_bid":"0.73","hash":"5da44fff210a538b9e5f1bb269f332e9995cdef0","price":"0.66","side":"BUY","size":"84"},{"asset_id":"39272994714739463168905443499424551362424437245880253267329605556587274644733","best_ask":"0.27","best_bid":"0.26","hash":"32ebb41dc391dedf6131e99c3d508fac5dbb9c3d","price":"0.34","side":"SELL","size":"84"}],"timestamp":"1785204818217"},"payload_hash":"6721b04c2c74c9e8e8e46166df9e2f5276ee0df54a308155fcfbf6a5e0b4e519","raw_frame":"{\"market\":\"0xda6f0e0e93fc8469e0159a166028d017bddbc162b86f66bac90391379603d962\", \"price_changes\":[{\"asset_id\":\"20893381255801015515826997628594359667013752732428989472914000440642900266717\", \"price\":\"0.66\", \"size\":\"84\", \"side\":\"BUY\", \"hash\":\"5da44fff210a538b9e5f1bb269f332e9995cdef0\", \"best_bid\":\"0.73\", \"best_ask\":\"0.74\"}, {\"asset_id\":\"39272994714739463168905443499424551362424437245880253267329605556587274644733\", \"price\":\"0.34\", \"size\":\"84\", \"side\":\"SELL\", \"hash\":\"32ebb41dc391dedf6131e99c3d508fac5dbb9c3d\", \"best_bid\":\"0.26\", \"best_ask\":\"0.27\"}], \"timestamp\":\"1785204818217\", \"event_type\":\"price_change\"}","received_at":"2026-07-28T02:13:38.099852Z","schema_version":"clob-market-ws.price_change.v1","sequence":null,"server_hash":null,"server_timestamp":"1785204818217","session_id":"d2757dd6dad94f3b9fe67e8dbf1adc37","source":"clob_market_ws"},"received_at":"2026-07-28T02:13:38.099852Z","record_id":"b49dd7aec1755541125f9aa7f2a62e4aa905c7dbad480c267863a63cd79881d1","schema_fingerprint":"4aa3821a28b0b7c2400bc59aba4bcc0a76e971dadd19610d3ad38c768e124dc7","schema_version":"edge-lab-recorder.raw.v1","sequence":null,"source":"clob_market_ws"}
{"event_at":"2026-07-28T02:13:38.218000Z","event_fingerprint":"3b33ccea0e70f2cac6d5516123986849c5d3e3aab95a478194786188a6f491a7","payload":{"connection_id":"5d29200f65794d4d9ab6ef271f045a9b","event_at":"2026-07-28T02:13:38.218000Z","event_type":"price_change","frame_hash":"74eeb1e04918e122b6711c22ae4adffef468d31c1b240fb45ef25386b97571b2","frame_index":0,"kind":"data","monotonic_ns":306801114069500,"payload":{"event_type":"price_change","market":"0xda6f0e0e93fc8469e0159a166028d017bddbc162b86f66bac90391379603d962","price_changes":[{"asset_id":"20893381255801015515826997628594359667013752732428989472914000440642900266717","best_ask":"0.74","best_bid":"0.73","hash":"b5f52cabbe789a31601c73ba00753464f70ca97d","price":"0.65","side":"BUY","size":"49"},{"asset_id":"39272994714739463168905443499424551362424437245880253267329605556587274644733","best_ask":"0.27","best_bid":"0.26","hash":"788801e99c926ad67e970d0d6e8322827099d2ca","price":"0.35","side":"SELL","size":"49"}],"timestamp":"1785204818218"},"payload_hash":"6b51c30cfbf56b0dd22d1568f11910f33303a30eb7216766ab9ff09a66ea0ac4","raw_frame":"{\"market\":\"0xda6f0e0e93fc8469e0159a166028d017bddbc162b86f66bac90391379603d962\", \"price_changes\":[{\"asset_id\":\"20893381255801015515826997628594359667013752732428989472914000440642900266717\", \"price\":\"0.65\", \"size\":\"49\", \"side\":\"BUY\", \"hash\":\"b5f52cabbe789a31601c73ba00753464f70ca97d\", \"best_bid\":\"0.73\", \"best_ask\":\"0.74\"}, {\"asset_id\":\"39272994714739463168905443499424551362424437245880253267329605556587274644733\", \"price\":\"0.35\", \"size\":\"49\", \"side\":\"SELL\", \"hash\":\"788801e99c926ad67e970d0d6e8322827099d2ca\", \"best_bid\":\"0.26\", \"best_ask\":\"0.27\"}], \"timestamp\":\"1785204818218\", \"event_type\":\"price_change\"}","received_at":"2026-07-28T02:13:38.102912Z","schema_version":"clob-market-ws.price_change.v1","sequence":null,"server_hash":null,"server_timestamp":"1785204818218","session_id":"d2757dd6dad94f3b9fe67e8dbf1adc37","source":"clob_market_ws"},"received_at":"2026-07-28T02:13:38.102912Z","record_id":"74cf5e634bb653ceb54315c4104e4d00b145a0fa25e8452175fcbd4702bfb9bc","schema_fingerprint":"4aa3821a28b0b7c2400bc59aba4bcc0a76e971dadd19610d3ad38c768e124dc7","schema_version":"edge-lab-recorder.raw.v1","sequence":null,"source":"clob_market_ws"}
{"event_at":"2026-07-28T02:13:38.219000Z","event_fingerprint":"29edd2869ae67401b46213b29a2ca5d8284ef42c34cc240ff185c8ef6e281c66","payload":{"connection_id":"5d29200f65794d4d9ab6ef271f045a9b","event_at":"2026-07-28T02:13:38.219000Z","event_type":"price_change","frame_hash":"1fe3e116d0a38ecfad797231a820df900e7c91f2dcc35bf3dd3f5cb7160c221d","frame_index":0,"kind":"data","monotonic_ns":306801117080541,"payload":{"event_type":"price_change","market":"0xda6f0e0e93fc8469e0159a166028d017bddbc162b86f66bac90391379603d962","price_changes":[{"asset_id":"20893381255801015515826997628594359667013752732428989472914000440642900266717","best_ask":"0.74","best_bid":"0.73","hash":"f319ab92cc19f8222d48e9cbd1b27031c8cedac5","price":"0.67","side":"BUY","size":"49"},{"asset_id":"39272994714739463168905443499424551362424437245880253267329605556587274644733","best_ask":"0.27","best_bid":"0.26","hash":"c7fd236ba584beda718b13d97c7692f96c218511","price":"0.33","side":"SELL","size":"49"}],"timestamp":"1785204818219"},"payload_hash":"adbaefd3a3493aa5d7b4428ae4603f2af8cf1681c0ede9c13dc1d1bac94da59c","raw_frame":"{\"market\":\"0xda6f0e0e93fc8469e0159a166028d017bddbc162b86f66bac90391379603d962\", \"price_changes\":[{\"asset_id\":\"20893381255801015515826997628594359667013752732428989472914000440642900266717\", \"price\":\"0.67\", \"size\":\"49\", \"side\":\"BUY\", \"hash\":\"f319ab92cc19f8222d48e9cbd1b27031c8cedac5\", \"best_bid\":\"0.73\", \"best_ask\":\"0.74\"}, {\"asset_id\":\"39272994714739463168905443499424551362424437245880253267329605556587274644733\", \"price\":\"0.33\", \"size\":\"49\", \"side\":\"SELL\", \"hash\":\"c7fd236ba584beda718b13d97c7692f96c218511\", \"best_bid\":\"0.26\", \"best_ask\":\"0.27\"}], \"timestamp\":\"1785204818219\", \"event_type\":\"price_change\"}","received_at":"2026-07-28T02:13:38.105923Z","schema_version":"clob-market-ws.price_change.v1","sequence":null,"server_hash":null,"server_timestamp":"1785204818219","session_id":"d2757dd6dad94f3b9fe67e8dbf1adc37","source":"clob_market_ws"},"received_at":"2026-07-28T02:13:38.105923Z","record_id":"64db6f393691a059562818f7ac9bbe5e55e77dfa806f12d886b6e75191824bd8","schema_fingerprint":"4aa3821a28b0b7c2400bc59aba4bcc0a76e971dadd19610d3ad38c768e124dc7","schema_version":"edge-lab-recorder.raw.v1","sequence":null,"source":"clob_market_ws"}
{"event_at":"2026-07-28T02:13:38.247000Z","event_fingerprint":"e608f14487fd8ac59226f3f09103eafe4da4e4c464721971847ec87ed0b48bf4","payload":{"connection_id":"5d29200f65794d4d9ab6ef271f045a9b","event_at":"2026-07-28T02:13:38.247000Z","event_type":"price_change","frame_hash":"2f7ae6b72ae808a8763c67f8cd05e094f8beb336659fc812bcd7a75b3e7279c7","frame_index":0,"kind":"data","monotonic_ns":306801141944916,"payload":{"event_type":"price_change","market":"0xda6f0e0e93fc8469e0159a166028d017bddbc162b86f66bac90391379603d962","price_changes":[{"asset_id":"39272994714739463168905443499424551362424437245880253267329605556587274644733","best_ask":"0.27","best_bid":"0.26","hash":"307f4173e26cea69a6a254fad0d451ad1cdbc948","price":"0.27","side":"SELL","size":"21"},{"asset_id":"20893381255801015515826997628594359667013752732428989472914000440642900266717","best_ask":"0.74","best_bid":"0.73","hash":"02e1a0f0ce0faf3c8f2c2a28199853d5aef9e91d","price":"0.73","side":"BUY","size":"21"}],"timestamp":"1785204818247"},"payload_hash":"f6f08ccacbde63129bdf680093c5e10785acfcad1ae300681e361ea6db1675a3","raw_frame":"{\"market\":\"0xda6f0e0e93fc8469e0159a166028d017bddbc162b86f66bac90391379603d962\", \"price_changes\":[{\"asset_id\":\"39272994714739463168905443499424551362424437245880253267329605556587274644733\", \"price\":\"0.27\", \"size\":\"21\", \"side\":\"SELL\", \"hash\":\"307f4173e26cea69a6a254fad0d451ad1cdbc948\", \"best_bid\":\"0.26\", \"best_ask\":\"0.27\"}, {\"asset_id\":\"20893381255801015515826997628594359667013752732428989472914000440642900266717\", \"price\":\"0.73\", \"size\":\"21\", \"side\":\"BUY\", \"hash\":\"02e1a0f0ce0faf3c8f2c2a28199853d5aef9e91d\", \"best_bid\":\"0.73\", \"best_ask\":\"0.74\"}], \"timestamp\":\"1785204818247\", \"event_type\":\"price_change\"}","received_at":"2026-07-28T02:13:38.130786Z","schema_version":"clob-market-ws.price_change.v1","sequence":null,"server_hash":null,"server_timestamp":"1785204818247","session_id":"d2757dd6dad94f3b9fe67e8dbf1adc37","source":"clob_market_ws"},"received_at":"2026-07-28T02:13:38.130786Z","record_id":"889fccf10959193f01fb5f61ac51b4e8ed180cef1d2cadc9046d9bd3f7e6e6c3","schema_fingerprint":"4aa3821a28b0b7c2400bc59aba4bcc0a76e971dadd19610d3ad38c768e124dc7","schema_version":"edge-lab-recorder.raw.v1","sequence":null,"source":"clob_market_ws"}
{"event_at":"2026-07-28T02:13:38.270000Z","event_fingerprint":"de39c10fbd3c747465b2c749514138f392d879524836058245cd63d0313853aa","payload":{"connection_id":"5d29200f65794d4d9ab6ef271f045a9b","event_at":"2026-07-28T02:13:38.270000Z","event_type":"price_change","frame_hash":"897f57b7a3640ca4c1f7fe4786869a64e255ff14a8c93d8a5a87fda45a5168c0","frame_index":0,"kind":"data","monotonic_ns":306801163955375,"payload":{"event_type":"price_change","market":"0xda6f0e0e93fc8469e0159a166028d017bddbc162b86f66bac90391379603d962","price_changes":[{"asset_id":"20893381255801015515826997628594359667013752732428989472914000440642900266717","best_ask":"0.74","best_bid":"0.73","hash":"d1c3d7176dbcd54082ae3d9396bd43d33a0218a4","price":"0.01","side":"BUY","size":"5379.02"},{"asset_id":"39272994714739463168905443499424551362424437245880253267329605556587274644733","best_ask":"0.27","best_bid":"0.26","hash":"51895ed93662828fa5fd795eca32ef7cce06115d","price":"0.99","side":"SELL","size":"5379.02"}],"timestamp":"1785204818270"},"payload_hash":"97be2ea59b5b9484e27310e54e5d68c73a0494ac739a0323da53e4b5f1761ed6","raw_frame":"{\"market\":\"0xda6f0e0e93fc8469e0159a166028d017bddbc162b86f66bac90391379603d962\", \"price_changes\":[{\"asset_id\":\"20893381255801015515826997628594359667013752732428989472914000440642900266717\", \"price\":\"0.01\", \"size\":\"5379.02\", \"side\":\"BUY\", \"hash\":\"d1c3d7176dbcd54082ae3d9396bd43d33a0218a4\", \"best_bid\":\"0.73\", \"best_ask\":\"0.74\"}, {\"asset_id\":\"39272994714739463168905443499424551362424437245880253267329605556587274644733\", \"price\":\"0.99\", \"size\":\"5379.02\", \"side\":\"SELL\", \"hash\":\"51895ed93662828fa5fd795eca32ef7cce06115d\", \"best_bid\":\"0.26\", \"best_ask\":\"0.27\"}], \"timestamp\":\"1785204818270\", \"event_type\":\"price_change\"}","received_at":"2026-07-28T02:13:38.152795Z","schema_version":"clob-market-ws.price_change.v1","sequence":null,"server_hash":null,"server_timestamp":"1785204818270","session_id":"d2757dd6dad94f3b9fe67e8dbf1adc37","source":"clob_market_ws"},"received_at":"2026-07-28T02:13:38.152795Z","record_id":"d2037b8a036926f26ccff9da0ea3137d3c11242e12d912e05c44c611c29268bd","schema_fingerprint":"4aa3821a28b0b7c2400bc59aba4bcc0a76e971dadd19610d3ad38c768e124dc7","schema_version":"edge-lab-recorder.raw.v1","sequence":null,"source":"clob_market_ws"}
{"event_at":"2026-07-28T02:13:38.276000Z","event_fingerprint":"0eb77391b54cd5b1e3f31b8b1e445a6a2d703e786212e6d8336074b8a7b4ca9e","payload":{"connection_id":"5d29200f65794d4d9ab6ef271f045a9b","event_at":"2026-07-28T02:13:38.276000Z","event_type":"price_change","frame_hash":"d2cafb2f0c1a98d89474cff77daf2b4988358144e4b8cdd8dbb0b7c9faf1ed0a","frame_index":0,"kind":"data","monotonic_ns":306801170828291,"payload":{"event_type":"price_change","market":"0xda6f0e0e93fc8469e0159a166028d017bddbc162b86f66bac90391379603d962","price_changes":[{"asset_id":"20893381255801015515826997628594359667013752732428989472914000440642900266717","best_ask":"0.74","best_bid":"0.73","hash":"cace3b5e7254a2e1b40c066899c3ac2a5812ddb0","price":"0.73","side":"BUY","size":"46"},{"asset_id":"39272994714739463168905443499424551362424437245880253267329605556587274644733","best_ask":"0.27","best_bid":"0.26","hash":"f6abea8bdb24016fe5022e84483ae072a8948843","price":"0.27","side":"SELL","size":"46"}],"timestamp":"1785204818276"},"payload_hash":"3178ceaf65b40ad3d5c3f8f39dc9d00d501579cbe9a0f57548075be06b22d422","raw_frame":"{\"market\":\"0xda6f0e0e93fc8469e0159a166028d017bddbc162b86f66bac90391379603d962\", \"price_changes\":[{\"asset_id\":\"20893381255801015515826997628594359667013752732428989472914000440642900266717\", \"price\":\"0.73\", \"size\":\"46\", \"side\":\"BUY\", \"hash\":\"cace3b5e7254a2e1b40c066899c3ac2a5812ddb0\", \"best_bid\":\"0.73\", \"best_ask\":\"0.74\"}, {\"asset_id\":\"39272994714739463168905443499424551362424437245880253267329605556587274644733\", \"price\":\"0.27\", \"size\":\"46\", \"side\":\"SELL\", \"hash\":\"f6abea8bdb24016fe5022e84483ae072a8948843\", \"best_bid\":\"0.26\", \"best_ask\":\"0.27\"}], \"timestamp\":\"1785204818276\", \"event_type\":\"price_change\"}","received_at":"2026-07-28T02:13:38.159671Z","schema_version":"clob-market-ws.price_change.v1","sequence":null,"server_hash":null,"server_timestamp":"1785204818276","session_id":"d2757dd6dad94f3b9fe67e8dbf1adc37","source":"clob_market_ws"},"received_at":"2026-07-28T02:13:38.159671Z","record_id":"93575662b507bc7805c660f8db55a7a1605f9cb6bda505673ea1688a145c4a9b","schema_fingerprint":"4aa3821a28b0b7c2400bc59aba4bcc0a76e971dadd19610d3ad38c768e124dc7","schema_version":"edge-lab-recorder.raw.v1","sequence":null,"source":"clob_market_ws"}
{"event_at":"2026-07-28T02:13:38.301000Z","event_fingerprint":"354e4840a8a3bef6fa9b0a2dd72fcabde34328500f75866fc630835415e69443","payload":{"connection_id":"5d29200f65794d4d9ab6ef271f045a9b","event_at":"2026-07-28T02:13:38.301000Z","event_type":"price_change","frame_hash":"6b14ddcc32dfb8f32baad40fff3d1d6848e2a1d2d2d409d94f34856fb11db792","frame_index":0,"kind":"data","monotonic_ns":306801195730500,"payload":{"event_type":"price_change","market":"0xda6f0e0e93fc8469e0159a166028d017bddbc162b86f66bac90391379603d962","price_changes":[{"asset_id":"20893381255801015515826997628594359667013752732428989472914000440642900266717","best_ask":"0.74","best_bid":"0.73","hash":"a4e0e417363fc941163c9085747421d57f584ef3","price":"0.7","side":"BUY","size":"15"},{"asset_id":"39272994714739463168905443499424551362424437245880253267329605556587274644733","best_ask":"0.27","best_bid":"0.26","hash":"f9ab804eb8ef1cdf8059cd6183ced6aa56417f98","price":"0.3","side":"SELL","size":"15"}],"timestamp":"1785204818301"},"payload_hash":"1c0af8859cbc05da3db02ff15bb229f96e0974e9a4a6f1767d69a91007aebdcd","raw_frame":"{\"market\":\"0xda6f0e0e93fc8469e0159a166028d017bddbc162b86f66bac90391379603d962\", \"price_changes\":[{\"asset_id\":\"20893381255801015515826997628594359667013752732428989472914000440642900266717\", \"price\":\"0.7\", \"size\":\"15\", \"side\":\"BUY\", \"hash\":\"a4e0e417363fc941163c9085747421d57f584ef3\", \"best_bid\":\"0.73\", \"best_ask\":\"0.74\"}, {\"asset_id\":\"39272994714739463168905443499424551362424437245880253267329605556587274644733\", \"price\":\"0.3\", \"size\":\"15\", \"side\":\"SELL\", \"hash\":\"f9ab804eb8ef1cdf8059cd6183ced6aa56417f98\", \"best_bid\":\"0.26\", \"best_ask\":\"0.27\"}], \"timestamp\":\"1785204818301\", \"event_type\":\"price_change\"}","received_at":"2026-07-28T02:13:38.184571Z","schema_version":"clob-market-ws.price_change.v1","sequence":null,"server_hash":null,"server_timestamp":"1785204818301","session_id":"d2757dd6dad94f3b9fe67e8dbf1adc37","source":"clob_market_ws"},"received_at":"2026-07-28T02:13:38.184571Z","record_id":"9a4f64ea63f6820e854d227282af6e3e86a89eda2b8d1ca3a26550be894948ee","schema_fingerprint":"4aa3821a28b0b7c2400bc59aba4bcc0a76e971dadd19610d3ad38c768e124dc7","schema_version":"edge-lab-recorder.raw.v1","sequence":null,"source":"clob_market_ws"}
{"event_at":"2026-07-28T02:13:38.303000Z","event_fingerprint":"79239656e5c8ded3fc2c697c69acbe7862484f087708fa5df603067bbc476f1b","payload":{"connection_id":"5d29200f65794d4d9ab6ef271f045a9b","event_at":"2026-07-28T02:13:38.303000Z","event_type":"price_change","frame_hash":"55577240877e7c2e63c71c9f4088515c0b44f5bb4d36d8aa97350e577166ea02","frame_index":0,"kind":"data","monotonic_ns":306801199748916,"payload":{"event_type":"price_change","market":"0xda6f0e0e93fc8469e0159a166028d017bddbc162b86f66bac90391379603d962","price_changes":[{"asset_id":"20893381255801015515826997628594359667013752732428989472914000440642900266717","best_ask":"0.74","best_bid":"0.73","hash":"3465d804476479b4199c9c1c6602c239fb2a3ffc","price":"0.82","side":"SELL","size":"230"},{"asset_id":"39272994714739463168905443499424551362424437245880253267329605556587274644733","best_ask":"0.27","best_bid":"0.26","hash":"79a0ada82435b5e48298c8b3ec3c6e7011d9b880","price":"0.18","side":"BUY","size":"230"}],"timestamp":"1785204818303"},"payload_hash":"920ea8fe49f7813d48c2b868bac8c7194bd0136c5a377f33af1da454cee08833","raw_frame":"{\"market\":\"0xda6f0e0e93fc8469e0159a166028d017bddbc162b86f66bac90391379603d962\", \"price_changes\":[{\"asset_id\":\"20893381255801015515826997628594359667013752732428989472914000440642900266717\", \"price\":\"0.82\", \"size\":\"230\", \"side\":\"SELL\", \"hash\":\"3465d804476479b4199c9c1c6602c239fb2a3ffc\", \"best_bid\":\"0.73\", \"best_ask\":\"0.74\"}, {\"asset_id\":\"39272994714739463168905443499424551362424437245880253267329605556587274644733\", \"price\":\"0.18\", \"size\":\"230\", \"side\":\"BUY\", \"hash\":\"79a0ada82435b5e48298c8b3ec3c6e7011d9b880\", \"best_bid\":\"0.26\", \"best_ask\":\"0.27\"}], \"timestamp\":\"1785204818303\", \"event_type\":\"price_change\"}","received_at":"2026-07-28T02:13:38.188589Z","schema_version":"clob-market-ws.price_change.v1","sequence":null,"server_hash":null,"server_timestamp":"1785204818303","session_id":"d2757dd6dad94f3b9fe67e8dbf1adc37","source":"clob_market_ws"},"received_at":"2026-07-28T02:13:38.188589Z","record_id":"7f8734b5effb09758266b3dc00250bf460b2af9c34ce988b03dd97df5e753949","schema_fingerprint":"4aa3821a28b0b7c2400bc59aba4bcc0a76e971dadd19610d3ad38c768e124dc7","schema_version":"edge-lab-recorder.raw.v1","sequence":null,"source":"clob_market_ws"}
{"event_at":"2026-07-28T02:13:38.303000Z","event_fingerprint":"f5fbb564a6142458ac4e157f7cc132c619d9c9d1f892de9d3e5b9a603f418300","payload":{"connection_id":"5d29200f65794d4d9ab6ef271f045a9b","event_at":"2026-07-28T02:13:38.303000Z","event_type":"price_change","frame_hash":"7d59fae3f9646c2155ac30257f557bdf0655b7215e1f03da44357ca5b6a19ad6","frame_index":0,"kind":"data","monotonic_ns":306801210112958,"payload":{"event_type":"price_change","market":"0xda6f0e0e93fc8469e0159a166028d017bddbc162b86f66bac90391379603d962","price_changes":[{"asset_id":"39272994714739463168905443499424551362424437245880253267329605556587274644733","best_ask":"0.27","best_bid":"0.26","hash":"133608eec52d9975c199bc19197cbc5866236553","price":"0.28","side":"SELL","size":"12.52"},{"asset_id":"20893381255801015515826997628594359667013752732428989472914000440642900266717","best_ask":"0.74","best_bid":"0.73","hash":"7d9f6d89384163e104c2e8e673150d26be46b7dc","price":"0.72","side":"BUY","size":"12.52"}],"timestamp":"1785204818303"},"payload_hash":"6cc99eb4cab0539bfedc077d2d5c1ab81d41cd23481e85006176fe1da0255013","raw_frame":"{\"market\":\"0xda6f0e0e93fc8469e0159a166028d017bddbc162b86f66bac90391379603d962\", \"price_changes\":[{\"asset_id\":\"39272994714739463168905443499424551362424437245880253267329605556587274644733\", \"price\":\"0.28\", \"size\":\"12.52\", \"side\":\"SELL\", \"hash\":\"133608eec52d9975c199bc19197cbc5866236553\", \"best_bid\":\"0.26\", \"best_ask\":\"0.27\"}, {\"asset_id\":\"20893381255801015515826997628594359667013752732428989472914000440642900266717\", \"price\":\"0.72\", \"size\":\"12.52\", \"side\":\"BUY\", \"hash\":\"7d9f6d89384163e104c2e8e673150d26be46b7dc\", \"best_bid\":\"0.73\", \"best_ask\":\"0.74\"}], \"timestamp\":\"1785204818303\", \"event_type\":\"price_change\"}","received_at":"2026-07-28T02:13:38.198952Z","schema_version":"clob-market-ws.price_change.v1","sequence":null,"server_hash":null,"server_timestamp":"1785204818303","session_id":"d2757dd6dad94f3b9fe67e8dbf1adc37","source":"clob_market_ws"},"received_at":"2026-07-28T02:13:38.198952Z","record_id":"6feef75ba5b9de24bcee3fb5e49d08551038a310fc04c1a5caf5a5ac980c55b9","schema_fingerprint":"4aa3821a28b0b7c2400bc59aba4bcc0a76e971dadd19610d3ad38c768e124dc7","schema_version":"edge-lab-recorder.raw.v1","sequence":null,"source":"clob_market_ws"}
{"event_at":"2026-07-28T02:13:38.309000Z","event_fingerprint":"449c2d9c85c2719e6c11ac5fa8fd00a373e9fb05a776473d1e8b49e7ebd162b5","payload":{"connection_id":"5d29200f65794d4d9ab6ef271f045a9b","event_at":"2026-07-28T02:13:38.309000Z","event_type":"price_change","frame_hash":"24922e4d07c94269cd1b61de8e4bbfdfaaa789035cb094a9aa458c16b2623562","frame_index":0,"kind":"data","monotonic_ns":306801213266500,"payload":{"event_type":"price_change","market":"0xda6f0e0e93fc8469e0159a166028d017bddbc162b86f66bac90391379603d962","price_changes":[{"asset_id":"20893381255801015515826997628594359667013752732428989472914000440642900266717","best_ask":"0.74","best_bid":"0.73","hash":"a79bf765c7f145ec12a39e459cc4c9e3bfa6c657","price":"0.72","side":"BUY","size":"92.99"},{"asset_id":"39272994714739463168905443499424551362424437245880253267329605556587274644733","best_ask":"0.27","best_bid":"0.26","hash":"97e226d5d30f247891eadd90ba23360168832c00","price":"0.28","side":"SELL","size":"92.99"}],"timestamp":"1785204818309"},"payload_hash":"41c3fca42a14cc01212e84ab334f5c56eef557a52be86d4c537edfd151d20447","raw_frame":"{\"market\":\"0xda6f0e0e93fc8469e0159a166028d017bddbc162b86f66bac90391379603d962\", \"price_changes\":[{\"asset_id\":\"20893381255801015515826997628594359667013752732428989472914000440642900266717\", \"price\":\"0.72\", \"size\":\"92.99\", \"side\":\"BUY\", \"hash\":\"a79bf765c7f145ec12a39e459cc4c9e3bfa6c657\", \"best_bid\":\"0.73\", \"best_ask\":\"0.74\"}, {\"asset_id\":\"39272994714739463168905443499424551362424437245880253267329605556587274644733\", \"price\":\"0.28\", \"size\":\"92.99\", \"side\":\"SELL\", \"hash\":\"97e226d5d30f247891eadd90ba23360168832c00\", \"best_bid\":\"0.26\", \"best_ask\":\"0.27\"}], \"timestamp\":\"1785204818309\", \"event_type\":\"price_change\"}","received_at":"2026-07-28T02:13:38.202106Z","schema_version":"clob-market-ws.price_change.v1","sequence":null,"server_hash":null,"server_timestamp":"1785204818309","session_id":"d2757dd6dad94f3b9fe67e8dbf1adc37","source":"clob_market_ws"},"received_at":"2026-07-28T02:13:38.202106Z","record_id":"fdc34741b3e76ac55c566d9a43ef73e9f362b3c5c92c8acd5040d1743d1ddbe4","schema_fingerprint":"4aa3821a28b0b7c2400bc59aba4bcc0a76e971dadd19610d3ad38c768e124dc7","schema_version":"edge-lab-recorder.raw.v1","sequence":null,"source":"clob_market_ws"}
