{"event_at":"2026-07-28T02:13:12.402000Z","event_fingerprint":"70942e70fd94198baaefd8c0cc144b321dd2ca81dda5d164d1f1663da840f8ca","payload":{"connection_id":"5d29200f65794d4d9ab6ef271f045a9b","event_at":"2026-07-28T02:13:12.402000Z","event_type":"price_change","frame_hash":"f5a90080834d8c34eeac96a6b4488878bce5e6f5973edf90849cf2fdd1f81a2d","frame_index":0,"kind":"data","monotonic_ns":306775436096375,"payload":{"event_type":"price_change","market":"0xda6f0e0e93fc8469e0159a166028d017bddbc162b86f66bac90391379603d962","price_changes":[{"asset_id":"39272994714739463168905443499424551362424437245880253267329605556587274644733","best_ask":"0.27","best_bid":"0.26","hash":"09ec1c314f65bf4be618dfb52b336e8e174892bf","price":"0.16","side":"BUY","size":"196"},{"asset_id":"20893381255801015515826997628594359667013752732428989472914000440642900266717","best_ask":"0.74","best_bid":"0.73","hash":"59caaccce7d1e5deb7258d53b0a75c07d4046307","price":"0.84","side":"SELL","size":"196"}],"timestamp":"1785204792402"},"payload_hash":"d2ffeefbf0c39d73fd2f678e958a580e696f5fe056eaa990291df96aacbb171b","raw_frame":"{\"market\":\"0xda6f0e0e93fc8469e0159a166028d017bddbc162b86f66bac90391379603d962\", \"price_changes\":[{\"asset_id\":\"39272994714739463168905443499424551362424437245880253267329605556587274644733\", \"price\":\"0.16\", \"size\":\"196\", \"side\":\"BUY\", \"hash\":\"09ec1c314f65bf4be618dfb52b336e8e174892bf\", \"best_bid\":\"0.26\", \"best_ask\":\"0.27\"}, {\"asset_id\":\"20893381255801015515826997628594359667013752732428989472914000440642900266717\", \"price\":\"0.84\", \"size\":\"196\", \"side\":\"SELL\", \"hash\":\"59caaccce7d1e5deb7258d53b0a75c07d4046307\", \"best_bid\":\"0.73\", \"best_ask\":\"0.74\"}], \"timestamp\":\"1785204792402\", \"event_type\":\"price_change\"}","received_at":"2026-07-28T02:13:12.425192Z","schema_version":"clob-market-ws.price_change.v1","sequence":null,"server_hash":null,"server_timestamp":"1785204792402","session_id":"d2757dd6dad94f3b9fe67e8dbf1adc37","source":"clob_market_ws"},"received_at":"2026-07-28T02:13:12.425192Z","record_id":"310f32dbf88db4d6c210d217303926ffc450702b3492a66200b3a955165df779","schema_fingerprint":"4aa3821a28b0b7c2400bc59aba4bcc0a76e971dadd19610d3ad38c768e124dc7","schema_version":"edge-lab-recorder.raw.v1","sequence":null,"source":"clob_market_ws"}
{"event_at":"2026-07-28T02:13:12.412000Z","event_fingerprint":"329e82a9795f1f7d38d5b02058da325bf255134cf7d55ea16a47947a6960f984","payload":{"connection_id":"5d29200f65794d4d9ab6ef271f045a9b","event_at":"2026-07-28T02:13:12.412000Z","event_type":"price_change","frame_hash":"c236fa5cb8503060e9ccac61ee82501cde86b8b38df7ae508df69a4c1a5a7ec5","frame_index":0,"kind":"data","monotonic_ns":306775455644250,"payload":{"event_type":"price_change","market":"0xda6f0e0e93fc8469e0159a166028d017bddbc162b86f66bac90391379603d962","price_changes":[{"asset_id":"20893381255801015515826997628594359667013752732428989472914000440642900266717","best_ask":"0.74","best_bid":"0.73","hash":"685ad2a7d841c1fde2c2845ff5dceccf36ec32ff","price":"0.01","side":"BUY","size":"5379.02"},{"asset_id":"39272994714739463168905443499424551362424437245880253267329605556587274644733","best_ask":"0.27","best_bid":"0.26","hash":"f2e9104a42e6d56a3b8888faf388eb7c68f0a844","price":"0.99","side":"SELL","size":"5379.02"}],"timestamp":"1785204792412"},"payload_hash":"fcd5eb9306b8467347b78bbeb8ddf8175df69a36aa5273b31f8d3e91d7c73360","raw_frame":"{\"market\":\"0xda6f0e0e93fc8469e0159a166028d017bddbc162b86f66bac90391379603d962\", \"price_changes\":[{\"asset_id\":\"20893381255801015515826997628594359667013752732428989472914000440642900266717\", \"price\":\"0.01\", \"size\":\"5379.02\", \"side\":\"BUY\", \"hash\":\"685ad2a7d841c1fde2c2845ff5dceccf36ec32ff\", \"best_bid\":\"0.73\", \"best_ask\":\"0.74\"}, {\"asset_id\":\"39272994714739463168905443499424551362424437245880253267329605556587274644733\", \"price\":\"0.99\", \"size\":\"5379.02\", \"side\":\"SELL\", \"hash\":\"f2e9104a42e6d56a3b8888faf388eb7c68f0a844\", \"best_bid\":\"0.26\", \"best_ask\":\"0.27\"}], \"timestamp\":\"1785204792412\", \"event_type\":\"price_change\"}","received_at":"2026-07-28T02:13:12.444740Z","schema_version":"clob-market-ws.price_change.v1","sequence":null,"server_hash":null,"server_timestamp":"1785204792412","session_id":"d2757dd6dad94f3b9fe67e8dbf1adc37","source":"clob_market_ws"},"received_at":"2026-07-28T02:13:12.444740Z","record_id":"0258e2b089de42484349c6864e92cb5ea8e6351b2346848e137a250ecedbd382","schema_fingerprint":"4aa3821a28b0b7c2400bc59aba4bcc0a76e971dadd19610d3ad38c768e124dc7","schema_version":"edge-lab-recorder.raw.v1","sequence":null,"source":"clob_market_ws"}
{"event_at":"2026-07-28T02:13:12.427000Z","event_fingerprint":"cc80510675fed5762a4022f9a8d38fa35606753f9c9834262fef9baad9e38ba5","payload":{"connection_id":"5d29200f65794d4d9ab6ef271f045a9b","event_at":"2026-07-28T02:13:12.427000Z","event_type":"best_bid_ask","frame_hash":"40c70314e6f483aa94f7d14dd33d62520f941d30ba6910c91656b23a6075a8c5","frame_index":0,"kind":"data","monotonic_ns":306775460129458,"payload":{"asset_id":"20893381255801015515826997628594359667013752732428989472914000440642900266717","best_ask":"0.74","best_bid":"0.72","event_type":"best_bid_ask","market":"0xda6f0e0e93fc8469e0159a166028d017bddbc162b86f66bac90391379603d962","spread":"0.02","timestamp":"1785204792427"},"payload_hash":"a0f2b3f0f8078ce350cfd33ff19c87d6e6ee3ba892a9a864c19311ce3f56150d","raw_frame":"{\"market\":\"0xda6f0e0e93fc8469e0159a166028d017bddbc162b86f66bac90391379603d962\", \"asset_id\":\"20893381255801015515826997628594359667013752732428989472914000440642900266717\", \"best_bid\":\"0.72\", \"best_ask\":\"0.74\", \"spread\":\"0.02\", \"timestamp\":\"1785204792427\", \"event_type\":\"best_bid_ask\"}","received_at":"2026-07-28T02:13:12.449226Z","schema_version":"clob-market-ws.best_bid_ask.v1","sequence":null,"server_hash":null,"server_timestamp":"1785204792427","session_id":"d2757dd6dad94f3b9fe67e8dbf1adc37","source":"clob_market_ws"},"received_at":"2026-07-28T02:13:12.449226Z","record_id":"310cd20a7e0c3a8e18877ec1e097c7e4780483db1d4ac4daa5d4055425429bac","schema_fingerprint":"8488399f31b0337811b13b266be932db7062827c2470b78bd8e9e99bab51d17d","schema_version":"edge-lab-recorder.raw.v1","sequence":null,"source":"clob_market_ws"}
{"event_at":"2026-07-28T02:13:12.427000Z","event_fingerprint":"59aee65f30318583a404f1bd2512ca1debde3ee47b90ed4bb9c617f3f572ee2a","payload":{"connection_id":"5d29200f65794d4d9ab6ef271f045a9b","event_at":"2026-07-28T02:13:12.427000Z","event_type":"best_bid_ask","frame_hash":"ab04c0b2896156fe374f3181b3095d0403d89bba72efd3c576ab550fba195b1d","frame_index":0,"kind":"data","monotonic_ns":306775463989000,"payload":{"asset_id":"39272994714739463168905443499424551362424437245880253267329605556587274644733","best_ask":"0.28","best_bid":"0.26","event_type":"best_bid_ask","market":"0xda6f0e0e93fc8469e0159a166028d017bddbc162b86f66bac90391379603d962","spread":"0.02","timestamp":"1785204792427"},"payload_hash":"5e55f944147082f0840c03ab5ae1a326064b0317a082f17aaf71d68ba3617ab6","raw_frame":"{\"market\":\"0xda6f0e0e93fc8469e0159a166028d017bddbc162b86f66bac90391379603d962\", \"asset_id\":\"39272994714739463168905443499424551362424437245880253267329605556587274644733\", \"best_bid\":\"0.26\", \"best_ask\":\"0.28\", \"spread\":\"0.02\", \"timestamp\":\"1785204792427\", \"event_type\":\"best_bid_ask\"}","received_at":"2026-07-28T02:13:12.453086Z","schema_version":"clob-market-ws.best_bid_ask.v1","sequence":null,"server_hash":null,"server_timestamp":"1785204792427","session_id":"d2757dd6dad94f3b9fe67e8dbf1adc37","source":"clob_market_ws"},"received_at":"2026-07-28T02:13:12.453086Z","record_id":"41cc136b92ca6c10b056d8644e059887fc82da861672812040ba92f368c416ea","schema_fingerprint":"8488399f31b0337811b13b266be932db7062827c2470b78bd8e9e99bab51d17d","schema_version":"edge-lab-recorder.raw.v1","sequence":null,"source":"clob_market_ws"}
{"event_at":"2026-07-28T02:13:12.427000Z","event_fingerprint":"ead6894cd9514dafc901c38177e99fdb6ea5a7e018f058618ee1022b17176f17","payload":{"connection_id":"5d29200f65794d4d9ab6ef271f045a9b","event_at":"2026-07-28T02:13:12.427000Z","event_type":"price_change","frame_hash":"8cda40c982b4e5aac5ab7ce0be7efa22884b465baacdcf07549e7b4c1806d288","frame_index":0,"kind":"data","monotonic_ns":306775470081541,"payload":{"event_type":"price_change","market":"0xda6f0e0e93fc8469e0159a166028d017bddbc162b86f66bac90391379603d962","price_changes":[{"asset_id":"20893381255801015515826997628594359667013752732428989472914000440642900266717","best_ask":"0.74","best_bid":"0.72","hash":"601ebb3a9fadf626643212e10d6d06068635a62f","price":"0.73","side":"BUY","size":"0"},{"asset_id":"39272994714739463168905443499424551362424437245880253267329605556587274644733","best_ask":"0.28","best_bid":"0.26","hash":"b7481b234d0d74c9ce92ca40ec7d19339e76ac9c","price":"0.27","side":"SELL","size":"0"}],"timestamp":"1785204792427"},"payload_hash":"c844badc3dc1fbe1c76d121f0bf036d283e5dfe4ccba43285144d100993ab226","raw_frame":"{\"market\":\"0xda6f0e0e93fc8469e0159a166028d017bddbc162b86f66bac90391379603d962\", \"price_changes\":[{\"asset_id\":\"20893381255801015515826997628594359667013752732428989472914000440642900266717\", \"price\":\"0.73\", \"size\":\"0\", \"side\":\"BUY\", \"hash\":\"601ebb3a9fadf626643212e10d6d06068635a62f\", \"best_bid\":\"0.72\", \"best_ask\":\"0.74\"}, {\"asset_id\":\"39272994714739463168905443499424551362424437245880253267329605556587274644733\", \"price\":\"0.27\", \"size\":\"0\", \"side\":\"SELL\", \"hash\":\"b7481b234d0d74c9ce92ca40ec7d19339e76ac9c\", \"best_bid\":\"0.26\", \"best_ask\":\"0.28\"}], \"timestamp\":\"1785204792427\", \"event_type\":\"price_change\"}","received_at":"2026-07-28T02:13:12.459179Z","schema_version":"clob-market-ws.price_change.v1","sequence":null,"server_hash":null,"server_timestamp":"1785204792427","session_id":"d2757dd6dad94f3b9fe67e8dbf1adc37","source":"clob_market_ws"},"received_at":"2026-07-28T02:13:12.459179Z","record_id":"4f170ed464ad7c9b8bffc61437a569ba8bd9ff9fbffe0edd8d4fec1fdfe1f265","schema_fingerprint":"4aa3821a28b0b7c2400bc59aba4bcc0a76e971dadd19610d3ad38c768e124dc7","schema_version":"edge-lab-recorder.raw.v1","sequence":null,"source":"clob_market_ws"}
{"event_at":"2026-07-28T02:13:12.435000Z","event_fingerprint":"895eda975b1b9adc7c01e9e51ed3e7a31372121fd8ed63f728fe1ca70ff043b4","payload":{"connection_id":"5d29200f65794d4d9ab6ef271f045a9b","event_at":"2026-07-28T02:13:12.435000Z","event_type":"price_change","frame_hash":"e45c5e9a6f144e30e14926d976eb1b524da6dba4de98a68d866a45cb4ff65225","frame_index":0,"kind":"data","monotonic_ns":306775472551125,"payload":{"event_type":"price_change","market":"0xda6f0e0e93fc8469e0159a166028d017bddbc162b86f66bac90391379603d962","price_changes":[{"asset_id":"20893381255801015515826997628594359667013752732428989472914000440642900266717","best_ask":"0.74","best_bid":"0.72","hash":"88f6620804b08619af528b5a422fc83c4818af9a","price":"0.33","side":"BUY","size":"44"},{"asset_id":"39272994714739463168905443499424551362424437245880253267329605556587274644733","best_ask":"0.28","best_bid":"0.26","hash":"d7aa5e1a5dc8876af327ed83d83232555c47da94","price":"0.67","side":"SELL","size":"44"}],"timestamp":"1785204792435"},"payload_hash":"eeb93c194f70724d9ac5935255dc5cd5ce492636d2ade075b88892e14760371a","raw_frame":"{\"market\":\"0xda6f0e0e93fc8469e0159a166028d017bddbc162b86f66bac90391379603d962\", \"price_changes\":[{\"asset_id\":\"20893381255801015515826997628594359667013752732428989472914000440642900266717\", \"price\":\"0.33\", \"size\":\"44\", \"side\":\"BUY\", \"hash\":\"88f6620804b08619af528b5a422fc83c4818af9a\", \"best_bid\":\"0.72\", \"best_ask\":\"0.74\"}, {\"asset_id\":\"39272994714739463168905443499424551362424437245880253267329605556587274644733\", \"price\":\"0.67\", \"size\":\"44\", \"side\":\"SELL\", \"hash\":\"d7aa5e1a5dc8876af327ed83d83232555c47da94\", \"best_bid\":\"0.26\", \"best_ask\":\"0.28\"}], \"timestamp\":\"1785204792435\", \"event_type\":\"price_change\"}","received_at":"2026-07-28T02:13:12.461647Z","schema_version":"clob-market-ws.price_change.v1","sequence":null,"server_hash":null,"server_timestamp":"1785204792435","session_id":"d2757dd6dad94f3b9fe67e8dbf1adc37","source":"clob_market_ws"},"received_at":"2026-07-28T02:13:12.461647Z","record_id":"f4cf671a20ed712020e0116b616c38200b4b8154db6a882a1f3e699e84af3e69","schema_fingerprint":"4aa3821a28b0b7c2400bc59aba4bcc0a76e971dadd19610d3ad38c768e124dc7","schema_version":"edge-lab-recorder.raw.v1","sequence":null,"source":"clob_market_ws"}
{"event_at":"2026-07-28T02:13:12.437000Z","event_fingerprint":"915695de34fbf0c40d33be96516a2d0f983c66354099342fff407d63f4d2241a","payload":{"connection_id":"5d29200f65794d4d9ab6ef271f045a9b","event_at":"2026-07-28T02:13:12.437000Z","event_type":"best_bid_ask","frame_hash":"c45fa336fd7f34a96f1f972bbf50e64092a51acaff76c599f7992f2f5a99a303","frame_index":0,"kind":"data","monotonic_ns":306775475444208,"payload":{"asset_id":"20893381255801015515826997628594359667013752732428989472914000440642900266717","best_ask":"0.73","best_bid":"0.72","event_type":"best_bid_ask","market":"0xda6f0e0e93fc8469e0159a166028d017bddbc162b86f66bac90391379603d962","spread":"0.01","timestamp":"1785204792437"},"payload_hash":"6a95fa29865bd06ec03dca38da76c70845b40468f25287c7b4bac2dffca62913","raw_frame":"{\"market\":\"0xda6f0e0e93fc8469e0159a166028d017bddbc162b86f66bac90391379603d962\", \"asset_id\":\"20893381255801015515826997628594359667013752732428989472914000440642900266717\", \"best_bid\":\"0.72\", \"best_ask\":\"0.73\", \"spread\":\"0.01\", \"timestamp\":\"1785204792437\", \"event_type\":\"best_bid_ask\"}","received_at":"2026-07-28T02:13:12.464541Z","schema_version":"clob-market-ws.best_bid_ask.v1","sequence":null,"server_hash":null,"server_timestamp":"1785204792437","session_id":"d2757dd6dad94f3b9fe67e8dbf1adc37","source":"clob_market_ws"},"received_at":"2026-07-28T02:13:12.464541Z","record_id":"dbe95025e900504856ac2c41fbc57ff08a789ac2af312dc8068f361a7a334242","schema_fingerprint":"8488399f31b0337811b13b266be932db7062827c2470b78bd8e9e99bab51d17d","schema_version":"edge-lab-recorder.raw.v1","sequence":null,"source":"clob_market_ws"}
{"event_at":"2026-07-28T02:13:12.437000Z","event_fingerprint":"fb3739d8c3ae49801d9107699800a137a259c558d1bcf5b0adf56341d20b6a88","payload":{"connection_id":"5d29200f65794d4d9ab6ef271f045a9b","event_at":"2026-07-28T02:13:12.437000Z","event_type":"best_bid_ask","frame_hash":"eaaf1b8771079c5d92023195699e4a37b006e9993ac874edc2e449ad2defaae0","frame_index":0,"kind":"data","monotonic_ns":306775477972875,"payload":{"asset_id":"39272994714739463168905443499424551362424437245880253267329605556587274644733","best_ask":"0.28","best_bid":"0.27","event_type":"best_bid_ask","market":"0xda6f0e0e93fc8469e0159a166028d017bddbc162b86f66bac90391379603d962","spread":"0.01","timestamp":"1785204792437"},"payload_hash":"7ed730f71947b0bed967e8fc0e83e7b50ef95f59e0b4f6711540f6014f190de1","raw_frame":"{\"market\":\"0xda6f0e0e93fc8469e0159a166028d017bddbc162b86f66bac90391379603d962\", \"asset_id\":\"39272994714739463168905443499424551362424437245880253267329605556587274644733\", \"best_bid\":\"0.27\", \"best_ask\":\"0.28\", \"spread\":\"0.01\", \"timestamp\":\"1785204792437\", \"event_type\":\"best_bid_ask\"}","received_at":"2026-07-28T02:13:12.467070Z","schema_version":"clob-market-ws.best_bid_ask.v1","sequence":null,"server_hash":null,"server_timestamp":"1785204792437","session_id":"d2757dd6dad94f3b9fe67e8dbf1adc37","source":"clob_market_ws"},"received_at":"2026-07-28T02:13:12.467070Z","record_id":"734815a66e3585b479b13d9bee504d47347cd5f25e756bdb8ff71209c7eead44","schema_fingerprint":"8488399f31b0337811b13b266be932db7062827c2470b78bd8e9e99bab51d17d","schema_version":"edge-lab-recorder.raw.v1","sequence":null,"source":"clob_market_ws"}
{"event_at":"2026-07-28T02:13:12.437000Z","event_fingerprint":"880eb2b4781242aba3e9df9418391691f19f86d5f7ff0c3b3bf6a78565ae1e14","payload":{"connection_id":"5d29200f65794d4d9ab6ef271f045a9b","event_at":"2026-07-28T02:13:12.437000Z","event_type":"price_change","frame_hash":"a3f9603cbfad7d3988248b10e1c011d14313d9d61cbe3b9a4dd14d0d4c1dfc09","frame_index":0,"kind":"data","monotonic_ns":306775480031583,"payload":{"event_type":"price_change","market":"0xda6f0e0e93fc8469e0159a166028d017bddbc162b86f66bac90391379603d962","price_changes":[{"asset_id":"39272994714739463168905443499424551362424437245880253267329605556587274644733","best_ask":"0.28","best_bid":"0.27","hash":"2d30778f5baa00445f96866edbbd4fc27ae494d1","price":"0.27","side":"BUY","size":"29"},{"asset_id":"20893381255801015515826997628594359667013752732428989472914000440642900266717","best_ask":"0.73","best_bid":"0.72","hash":"b3567e205c6e518095bd027859c5f98d43018103","price":"0.73","side":"SELL","size":"29"}],"timestamp":"1785204792437"},"payload_hash":"12f06280d157946bcc412820d2a10761d637893cbbcae74463dcd86405e9993a","raw_frame":"{\"market\":\"0xda6f0e0e93fc8469e0159a166028d017bddbc162b86f66bac90391379603d962\", \"price_changes\":[{\"asset_id\":\"39272994714739463168905443499424551362424437245880253267329605556587274644733\", \"price\":\"0.27\", \"size\":\"29\", \"side\":\"BUY\", \"hash\":\"2d30778f5baa00445f96866edbbd4fc27ae494d1\", \"best_bid\":\"0.27\", \"best_ask\":\"0.28\"}, {\"asset_id\":\"20893381255801015515826997628594359667013752732428989472914000440642900266717\", \"price\":\"0.73\", \"size\":\"29\", \"side\":\"SELL\", \"hash\":\"b3567e205c6e518095bd027859c5f98d43018103\", \"best_bid\":\"0.72\", \"best_ask\":\"0.73\"}], \"timestamp\":\"1785204792437\", \"event_type\":\"price_change\"}","received_at":"2026-07-28T02:13:12.469128Z","schema_version":"clob-market-ws.price_change.v1","sequence":null,"server_hash":null,"server_timestamp":"1785204792437","session_id":"d2757dd6dad94f3b9fe67e8dbf1adc37","source":"clob_market_ws"},"received_at":"2026-07-28T02:13:12.469128Z","record_id":"7e718f34118dba9f192b42239f40f901cc2ce0464e67385cea779e78098bcb9c","schema_fingerprint":"4aa3821a28b0b7c2400bc59aba4bcc0a76e971dadd19610d3ad38c768e124dc7","schema_version":"edge-lab-recorder.raw.v1","sequence":null,"source":"clob_market_ws"}
{"event_at":"2026-07-28T02:13:12.438000Z","event_fingerprint":"81944edc50b07290f5ec37644b8011adf6769a12f661592a655df73e3ad6f19e","payload":{"connection_id":"5d29200f65794d4d9ab6ef271f045a9b","event_at":"2026-07-28T02:13:12.438000Z","event_type":"price_change","frame_hash":"3ddd024fd980388a7f83fbfb7f1fa52ce88b535a3a331c7be61f6d776553ca70","frame_index":0,"kind":"data","monotonic_ns":306775482569125,"payload":{"event_type":"price_change","market":"0xda6f0e0e93fc8469e0159a166028d017bddbc162b86f66bac90391379603d962","price_changes":[{"asset_id":"39272994714739463168905443499424551362424437245880253267329605556587274644733","best_ask":"0.28","best_bid":"0.27","hash":"2c574895855b7dea273ec0c4efed131b75727f3a","price":"0.25","side":"BUY","size":"79"},{"asset_id":"20893381255801015515826997628594359667013752732428989472914000440642900266717","best_ask":"0.73","best_bid":"0.72","hash":"ce87b84d7e0b64182cea6783818a73c4c895f2f5","price":"0.75","side":"SELL","size":"79"}],"timestamp":"1785204792438"},"payload_hash":"bb0176dd12afb9163cd51055de0a615c8ba35edf1fdb948f87b125bfe0d0d810","raw_frame":"{\"market\":\"0xda6f0e0e93fc8469e0159a166028d017bddbc162b86f66bac90391379603d962\", \"price_changes\":[{\"asset_id\":\"39272994714739463168905443499424551362424437245880253267329605556587274644733\", \"price\":\"0.25\", \"size\":\"79\", \"side\":\"BUY\", \"hash\":\"2c574895855b7dea273ec0c4efed131b75727f3a\", \"best_bid\":\"0.27\", \"best_ask\":\"0.28\"}, {\"asset_id\":\"20893381255801015515826997628594359667013752732428989472914000440642900266717\", \"price\":\"0.75\", \"size\":\"79\", \"side\":\"SELL\", \"hash\":\"ce87b84d7e0b64182cea6783818a73c4c895f2f5\", \"best_bid\":\"0.72\", \"best_ask\":\"0.73\"}], \"timestamp\":\"1785204792438\", \"event_type\":\"price_change\"}","received_at":"2026-07-28T02:13:12.471666Z","schema_version":"clob-market-ws.price_change.v1","sequence":null,"server_hash":null,"server_timestamp":"1785204792438","session_id":"d2757dd6dad94f3b9fe67e8dbf1adc37","source":"clob_market_ws"},"received_at":"2026-07-28T02:13:12.471666Z","record_id":"f69e934a7d6a9cbf73c52ca65914df0607d1bba1f28da90f7e7145a95b41caa1","schema_fingerprint":"4aa3821a28b0b7c2400bc59aba4bcc0a76e971dadd19610d3ad38c768e124dc7","schema_version":"edge-lab-recorder.raw.v1","sequence":null,"source":"clob_market_ws"}
{"event_at":"2026-07-28T02:13:12.438000Z","event_fingerprint":"5f2ce6e2ebdf088646fe48b2341fea5414fbb34b78eecb9864a0160f347a3b71","payload":{"connection_id":"5d29200f65794d4d9ab6ef271f045a9b","event_at":"2026-07-28T02:13:12.438000Z","event_type":"price_change","frame_hash":"520b0e6b86d9e41d4b782d0b17d2e606301a1adfcf430f824957644f46ae94a1","frame_index":0,"kind":"data","monotonic_ns":306775484861541,"payload":{"event_type":"price_change","market":"0xda6f0e0e93fc8469e0159a166028d017bddbc162b86f66bac90391379603d962","price_changes":[{"asset_id":"20893381255801015515826997628594359667013752732428989472914000440642900266717","best_ask":"0.73","best_bid":"0.72","hash":"02162436d426bf03dc0366872c1d0500ca5486aa","price":"0.75","side":"SELL","size":"74"},{"asset_id":"39272994714739463168905443499424551362424437245880253267329605556587274644733","best_ask":"0.28","best_bid":"0.27","hash":"45eda3dbea558223bb16c456a3d15fdf3b429842","price":"0.25","side":"BUY","size":"74"}],"timestamp":"1785204792438"},"payload_hash":"1296b63b7a14f7b12a17c9ad2583d11b6a3b4559c2a38d32fae6242c3d73deac","raw_frame":"{\"market\":\"0xda6f0e0e93fc8469e0159a166028d017bddbc162b86f66bac90391379603d962\", \"price_changes\":[{\"asset_id\":\"20893381255801015515826997628594359667013752732428989472914000440642900266717\", \"price\":\"0.75\", \"size\":\"74\", \"side\":\"SELL\", \"hash\":\"02162436d426bf03dc0366872c1d0500ca5486aa\", \"best_bid\":\"0.72\", \"best_ask\":\"0.73\"}, {\"asset_id\":\"39272994714739463168905443499424551362424437245880253267329605556587274644733\", \"price\":\"0.25\", \"size\":\"74\", \"side\":\"BUY\", \"hash\":\"45eda3dbea558223bb16c456a3d15fdf3b429842\", \"best_bid\":\"0.27\", \"best_ask\":\"0.28\"}], \"timestamp\":\"1785204792438\", \"event_type\":\"price_change\"}","received_at":"2026-07-28T02:13:12.473958Z","schema_version":"clob-market-ws.price_change.v1","sequence":null,"server_hash":null,"server_timestamp":"1785204792438","session_id":"d2757dd6dad94f3b9fe67e8dbf1adc37","source":"clob_market_ws"},"received_at":"2026-07-28T02:13:12.473958Z","record_id":"3b25f3b421a685baee1c2bbde82af71d7f042fe4187f90ed6f3b98fabf5c953d","schema_fingerprint":"4aa3821a28b0b7c2400bc59aba4bcc0a76e971dadd19610d3ad38c768e124dc7","schema_version":"edge-lab-recorder.raw.v1","sequence":null,"source":"clob_market_ws"}
{"event_at":"2026-07-28T02:13:12.439000Z","event_fingerprint":"746b9f3fe4f87baaae3f630d2014a1d94cb357b53c992d643da2ab1e5b12e8d8","payload":{"connection_id":"5d29200f65794d4d9ab6ef271f045a9b","event_at":"2026-07-28T02:13:12.439000Z","event_type":"price_change","frame_hash":"287e00d33c78edc880876e3a7ab29cead7a1687f2fea8ca1374d3338a7193b7c","frame_index":0,"kind":"data","monotonic_ns":306775487119250,"payload":{"event_type":"price_change","market":"0xda6f0e0e93fc8469e0159a166028d017bddbc162b86f66bac90391379603d962","price_changes":[{"asset_id":"20893381255801015515826997628594359667013752732428989472914000440642900266717","best_ask":"0.73","best_bid":"0.72","hash":"d579390a481f819ec126b8714874bbc18f6e9867","price":"0.67","side":"BUY","size":"50"},{"asset_id":"39272994714739463168905443499424551362424437245880253267329605556587274644733","best_ask":"0.28","best_bid":"0.27","hash":"dfdc01cec14a9ca73592101a1e1428cfe1397aab","price":"0.33","side":"SELL","size":"50"}],"timestamp":"1785204792439"},"payload_hash":"90479e99e2f710e3740888ec212061b639bfa9d0d30393a69ccc11d3aac6ddbf","raw_frame":"{\"market\":\"0xda6f0e0e93fc8469e0159a166028d017bddbc162b86f66bac90391379603d962\", \"price_changes\":[{\"asset_id\":\"20893381255801015515826997628594359667013752732428989472914000440642900266717\", \"price\":\"0.67\", \"size\":\"50\", \"side\":\"BUY\", \"hash\":\"d579390a481f819ec126b8714874bbc18f6e9867\", \"best_bid\":\"0.72\", \"best_ask\":\"0.73\"}, {\"asset_id\":\"39272994714739463168905443499424551362424437245880253267329605556587274644733\", \"price\":\"0.33\", \"size\":\"50\", \"side\":\"SELL\", \"hash\":\"dfdc01cec14a9ca73592101a1e1428cfe1397aab\", \"best_bid\":\"0.27\", \"best_ask\":\"0.28\"}], \"timestamp\":\"1785204792439\", \"event_type\":\"price_change\"}","received_at":"2026-07-28T02:13:12.476216Z","schema_version":"clob-market-ws.price_change.v1","sequence":null,"server_hash":null,"server_timestamp":"1785204792439","session_id":"d2757dd6dad94f3b9fe67e8dbf1adc37","source":"clob_market_ws"},"received_at":"2026-07-28T02:13:12.476216Z","record_id":"8217f893a17268a3bf731bf3bf9f3d214eb63edb14838e57a19eb3722a773a9d","schema_fingerprint":"4aa3821a28b0b7c2400bc59aba4bcc0a76e971dadd19610d3ad38c768e124dc7","schema_version":"edge-lab-recorder.raw.v1","sequence":null,"source":"clob_market_ws"}
{"event_at":"2026-07-28T02:13:12.439000Z","event_fingerprint":"22eafcc0c53f3276c2159038183ec6e8e35b94498bce7d6206a030e3b6ac487d","payload":{"connection_id":"5d29200f65794d4d9ab6ef271f045a9b","event_at":"2026-07-28T02:13:12.439000Z","event_type":"price_change","frame_hash":"b2ceb4c88c859744a916b26c24e9f2a0b96d99e803086c2cf2eebdeac01f772c","frame_index":0,"kind":"data","monotonic_ns":306775490082333,"payload":{"event_type":"price_change","market":"0xda6f0e0e93fc8469e0159a166028d017bddbc162b86f66bac90391379603d962","price_changes":[{"asset_id":"20893381255801015515826997628594359667013752732428989472914000440642900266717","best_ask":"0.73","best_bid":"0.72","hash":"daa00c32c97d09d229d1aa9847656f382f6118a7","price":"0.75","side":"SELL","size":"69"},{"asset_id":"39272994714739463168905443499424551362424437245880253267329605556587274644733","best_ask":"0.28","best_bid":"0.27","hash":"82b4c25609cf4a50386bdafe3121561f1c89a1bb","price":"0.25","side":"BUY","size":"69"}],"timestamp":"1785204792439"},"payload_hash":"6f3acd6af745fef5d723fe84aa925801d3f5ef30213590e5054f1ba1a1f90f6f","raw_frame":"{\"market\":\"0xda6f0e0e93fc8469e0159a166028d017bddbc162b86f66bac90391379603d962\", \"price_changes\":[{\"asset_id\":\"20893381255801015515826997628594359667013752732428989472914000440642900266717\", \"price\":\"0.75\", \"size\":\"69\", \"side\":\"SELL\", \"hash\":\"daa00c32c97d09d229d1aa9847656f382f6118a7\", \"best_bid\":\"0.72\", \"best_ask\":\"0.73\"}, {\"asset_id\":\"39272994714739463168905443499424551362424437245880253267329605556587274644733\", \"price\":\"0.25\", \"size\":\"69\", \"side\":\"BUY\", \"hash\":\"82b4c25609cf4a50386bdafe3121561f1c89a1bb\", \"best_bid\":\"0.27\", \"best_ask\":\"0.28\"}], \"timestamp\":\"1785204792439\", \"event_type\":\"price_change\"}","received_at":"2026-07-28T02:13:12.479179Z","schema_version":"clob-market-ws.price_change.v1","sequence":null,"server_hash":null,"server_timestamp":"1785204792439","session_id":"d2757dd6dad94f3b9fe67e8dbf1adc37","source":"clob_market_ws"},"received_at":"2026-07-28T02:13:12.479179Z","record_id":"e3895bccc7c18561368bcaff6c8f807ac968e7e3bc5182832d8db4731bf577af","schema_fingerprint":"4aa3821a28b0b7c2400bc59aba4bcc0a76e971dadd19610d3ad38c768e124dc7","schema_version":"edge-lab-recorder.raw.v1","sequence":null,"source":"clob_market_ws"}
{"event_at":"2026-07-28T02:13:12.444000Z","event_fingerprint":"d51f3c3c5346bc3ffca3eddbb79e1e7aeb3c6f3e180c6bcf2c9449866e6fed9b","payload":{"connection_id":"5d29200f65794d4d9ab6ef271f045a9b","event_at":"2026-07-28T02:13:12.444000Z","event_type":"price_change","frame_hash":"bbd3d56701d64ed6d416a832863fe0a7157e45dcdf55301fb6cbbc08b0025011","frame_index":0,"kind":"data","monotonic_ns":306775493002583,"payload":{"event_type":"price_change","market":"0xda6f0e0e93fc8469e0159a166028d017bddbc162b86f66bac90391379603d962","price_changes":[{"asset_id":"39272994714739463168905443499424551362424437245880253267329605556587274644733","best_ask":"0.28","best_bid":"0.27","hash":"cc26571d5d660db1d1c7765406175c1b21c1bfc6","price":"0.26","side":"BUY","size":"49"},{"asset_id":"20893381255801015515826997628594359667013752732428989472914000440642900266717","best_ask":"0.73","best_bid":"0.72","hash":"904bf0c12a0bbb1926870c98dcfb8361065a395f","price":"0.74","side":"SELL","size":"49"}],"timestamp":"1785204792444"},"payload_hash":"03834b8ff9c33fdd71ac860c5eb05b7de30602d88cf33ecb4b21f8d51f41e831","raw_frame":"{\"market\":\"0xda6f0e0e93fc8469e0159a166028d017bddbc162b86f66bac90391379603d962\", \"price_changes\":[{\"asset_id\":\"39272994714739463168905443499424551362424437245880253267329605556587274644733\", \"price\":\"0.26\", \"size\":\"49\", \"side\":\"BUY\", \"hash\":\"cc26571d5d660db1d1c7765406175c1b21c1bfc6\", \"best_bid\":\"0.27\", \"best_ask\":\"0.28\"}, {\"asset_id\":\"20893381255801015515826997628594359667013752732428989472914000440642900266717\", \"price\":\"0.74\", \"size\":\"49\", \"side\":\"SELL\", \"hash\":\"904bf0c12a0bbb1926870c98dcfb8361065a395f\", \"best_bid\":\"0.72\", \"best_ask\":\"0.73\"}], \"timestamp\":\"1785204792444\", \"event_type\":\"price_change\"}","received_at":"2026-07-28T02:13:12.482099Z","schema_version":"clob-market-ws.price_change.v1","sequence":null,"server_hash":null,"server_timestamp":"1785204792444","session_id":"d2757dd6dad94f3b9fe67e8dbf1adc37","source":"clob_market_ws"},"received_at":"2026-07-28T02:13:12.482099Z","record_id":"b96a19d9e6142fb3d22399e535bc9b394e355d9cac5af2879fdfca7ca455a03c","schema_fingerprint":"4aa3821a28b0b7c2400bc59aba4bcc0a76e971dadd19610d3ad38c768e124dc7","schema_version":"edge-lab-recorder.raw.v1","sequence":null,"source":"clob_market_ws"}
{"event_at":"2026-07-28T02:13:12.454000Z","event_fingerprint":"8b89d15b4cf49816a8adafa11e7c9f2cbd010958502c112d05f9beb759d92261","payload":{"connection_id":"5d29200f65794d4d9ab6ef271f045a9b","event_at":"2026-07-28T02:13:12.454000Z","event_type":"price_change","frame_hash":"37191013982ab498bb311cd3bf372f7f7290b4db4e0b43bab53e95528f35189f","frame_index":0,"kind":"data","monotonic_ns":306775496280916,"payload":{"event_type":"price_change","market":"0xda6f0e0e93fc8469e0159a166028d017bddbc162b86f66bac90391379603d962","price_changes":[{"asset_id":"39272994714739463168905443499424551362424437245880253267329605556587274644733","best_ask":"0.28","best_bid":"0.27","hash":"df598fb46720b7eb5f7e5a59b7976b1e42fcb250","price":"0.27","side":"BUY","size":"34"},{"asset_id":"20893381255801015515826997628594359667013752732428989472914000440642900266717","best_ask":"0.73","best_bid":"0.72","hash":"d4e7f3c5be003bb4a9867043fb1e5c96e70518d6","price":"0.73","side":"SELL","size":"34"}],"timestamp":"1785204792454"},"payload_hash":"db5b6d0f6bbbc2f5a6b481acca329e5150cd7b5427cc3fe895b0f5e4a440d4d2","raw_frame":"{\"market\":\"0xda6f0e0e93fc8469e0159a166028d017bddbc162b86f66bac90391379603d962\", \"price_changes\":[{\"asset_id\":\"39272994714739463168905443499424551362424437245880253267329605556587274644733\", \"price\":\"0.27\", \"size\":\"34\", \"side\":\"BUY\", \"hash\":\"df598fb46720b7eb5f7e5a59b7976b1e42fcb250\", \"best_bid\":\"0.27\", \"best_ask\":\"0.28\"}, {\"asset_id\":\"20893381255801015515826997628594359667013752732428989472914000440642900266717\", \"price\":\"0.73\", \"size\":\"34\", \"side\":\"SELL\", \"hash\":\"d4e7f3c5be003bb4a9867043fb1e5c96e70518d6\", \"best_bid\":\"0.72\", \"best_ask\":\"0.73\"}], \"timestamp\":\"1785204792454\", \"event_type\":\"price_change\"}","received_at":"2026-07-28T02:13:12.485378Z","schema_version":"clob-market-ws.price_change.v1","sequence":null,"server_hash":null,"server_timestamp":"1785204792454","session_id":"d2757dd6dad94f3b9fe67e8dbf1adc37","source":"clob_market_ws"},"received_at":"2026-07-28T02:13:12.485378Z","record_id":"45adddeb5f7dbe598ed8051db638b52cc69ed17ac75e6432da9d2472ceaa3853","schema_fingerprint":"4aa3821a28b0b7c2400bc59aba4bcc0a76e971dadd19610d3ad38c768e124dc7","schema_version":"edge-lab-recorder.raw.v1","sequence":null,"source":"clob_market_ws"}
{"event_at":"2026-07-28T02:13:12.466000Z","event_fingerprint":"17d113832bd84af94972596d6726a4064d5445cc9250061026e45836c8dff8cf","payload":{"connection_id":"5d29200f65794d4d9ab6ef271f045a9b","event_at":"2026-07-28T02:13:12.466000Z","event_type":"price_change","frame_hash":"2509bb2af4d4d32a4fda1f16cf796c57f735459b8776253da2f78bc843a5448d","frame_index":0,"kind":"data","monotonic_ns":306775499184541,"payload":{"event_type":"price_change","market":"0xda6f0e0e93fc8469e0159a166028d017bddbc162b86f66bac90391379603d962","price_changes":[{"asset_id":"39272994714739463168905443499424551362424437245880253267329605556587274644733","best_ask":"0.28","best_bid":"0.27","hash":"b293a4126fd4f7cb3848f6d0f7e229f71b337dcb","price":"0.27","side":"BUY","size":"39"},{"asset_id":"20893381255801015515826997628594359667013752732428989472914000440642900266717","best_ask":"0.73","best_bid":"0.72","hash":"e15092883266e9e8c846dc2c9423fd7b2f709471","price":"0.73","side":"SELL","size":"39"}],"timestamp":"1785204792466"},"payload_hash":"91fcf17e72bb75e46ddea75b8983a09479a5b4e1d28004914fd1ec7f7175b9e2","raw_frame":"{\"market\":\"0xda6f0e0e93fc8469e0159a166028d017bddbc162b86f66bac90391379603d962\", \"price_changes\":[{\"asset_id\":\"39272994714739463168905443499424551362424437245880253267329605556587274644733\", \"price\":\"0.27\", \"size\":\"39\", \"side\":\"BUY\", \"hash\":\"b293a4126fd4f7cb3848f6d0f7e229f71b337dcb\", \"best_bid\":\"0.27\", \"best_ask\":\"0.28\"}, {\"asset_id\":\"20893381255801015515826997628594359667013752732428989472914000440642900266717\", \"price\":\"0.73\", \"size\":\"39\", \"side\":\"SELL\", \"hash\":\"e15092883266e9e8c846dc2c9423fd7b2f709471\", \"best_bid\":\"0.72\", \"best_ask\":\"0.73\"}], \"timestamp\":\"1785204792466\", \"event_type\":\"price_change\"}","received_at":"2026-07-28T02:13:12.488281Z","schema_version":"clob-market-ws.price_change.v1","sequence":null,"server_hash":null,"server_timestamp":"1785204792466","session_id":"d2757dd6dad94f3b9fe67e8dbf1adc37","source":"clob_market_ws"},"received_at":"2026-07-28T02:13:12.488281Z","record_id":"201c10af0b96480d944eaa61e83099db4f9885747504a51c3ead1c58388c69e6","schema_fingerprint":"4aa3821a28b0b7c2400bc59aba4bcc0a76e971dadd19610d3ad38c768e124dc7","schema_version":"edge-lab-recorder.raw.v1","sequence":null,"source":"clob_market_ws"}
{"event_at":"2026-07-28T02:13:12.477000Z","event_fingerprint":"9b342dbf9e94efd159c05f82e47c7ffeccd449302912ee8e1299472545bf3322","payload":{"connection_id":"5d29200f65794d4d9ab6ef271f045a9b","event_at":"2026-07-28T02:13:12.477000Z","event_type":"price_change","frame_hash":"498229a14643855fdfc08dcccd995c444c493d3b79bc37fd7de36eb3a51902c2","frame_index":0,"kind":"data","monotonic_ns":306775502145250,"payload":{"event_type":"price_change","market":"0xda6f0e0e93fc8469e0159a166028d017bddbc162b86f66bac90391379603d962","price_changes":[{"asset_id":"39272994714739463168905443499424551362424437245880253267329605556587274644733","best_ask":"0.28","best_bid":"0.27","hash":"9c9b9a1cf318755f977b997f939857dcdb4ef1e7","price":"0.27","side":"BUY","size":"10"},{"asset_id":"20893381255801015515826997628594359667013752732428989472914000440642900266717","best_ask":"0.73","best_bid":"0.72","hash":"bf07587b4c10cefcbeb325a26347f54eadb8b607","price":"0.73","side":"SELL","size":"10"}],"timestamp":"1785204792477"},"payload_hash":"b7491e3857266f4cb9c6e516c1b8d51177ba119a8b87d122581f2b92f7f5ac89","raw_frame":"{\"market\":\"0xda6f0e0e93fc8469e0159a166028d017bddbc162b86f66bac90391379603d962\", \"price_changes\":[{\"asset_id\":\"39272994714739463168905443499424551362424437245880253267329605556587274644733\", \"price\":\"0.27\", \"size\":\"10\", \"side\":\"BUY\", \"hash\":\"9c9b9a1cf318755f977b997f939857dcdb4ef1e7\", \"best_bid\":\"0.27\", \"best_ask\":\"0.28\"}, {\"asset_id\":\"20893381255801015515826997628594359667013752732428989472914000440642900266717\", \"price\":\"0.73\", \"size\":\"10\", \"side\":\"SELL\", \"hash\":\"bf07587b4c10cefcbeb325a26347f54eadb8b607\", \"best_bid\":\"0.72\", \"best_ask\":\"0.73\"}], \"timestamp\":\"1785204792477\", \"event_type\":\"price_change\"}","received_at":"2026-07-28T02:13:12.491242Z","schema_version":"clob-market-ws.price_change.v1","sequence":null,"server_hash":null,"server_timestamp":"1785204792477","session_id":"d2757dd6dad94f3b9fe67e8dbf1adc37","source":"clob_market_ws"},"received_at":"2026-07-28T02:13:12.491242Z","record_id":"5a528b341be43b3f735c5be976ae9274875c3be66931a0ee01cb1118f42b1806","schema_fingerprint":"4aa3821a28b0b7c2400bc59aba4bcc0a76e971dadd19610d3ad38c768e124dc7","schema_version":"edge-lab-recorder.raw.v1","sequence":null,"source":"clob_market_ws"}
{"event_at":"2026-07-28T02:13:12.478000Z","event_fingerprint":"a0ae7920e7ca8d2a28c34463a3f0455bcb8cd944af490de0f4c177c279f4eff2","payload":{"connection_id":"5d29200f65794d4d9ab6ef271f045a9b","event_at":"2026-07-28T02:13:12.478000Z","event_type":"price_change","frame_hash":"cb9cc27f206b8822a9a4e6f5e3826ff88d09ba987c41c22e5c4dd3e5499955f2","frame_index":0,"kind":"data","monotonic_ns":306775505037416,"payload":{"event_type":"price_change","market":"0xda6f0e0e93fc8469e0159a166028d017bddbc162b86f66bac90391379603d962","price_changes":[{"asset_id":"20893381255801015515826997628594359667013752732428989472914000440642900266717","best_ask":"0.73","best_bid":"0.72","hash":"3103f0f634e05d6cfd94b2f1ca7657f9130b74b4","price":"0.01","side":"BUY","size":"5374.02"},{"asset_id":"39272994714739463168905443499424551362424437245880253267329605556587274644733","best_ask":"0.28","best_bid":"0.27","hash":"b6c436c321871f07376931d443637b4679ebdc88","price":"0.99","side":"SELL","size":"5374.02"}],"timestamp":"1785204792478"},"payload_hash":"477b2e0657d09eabbeba40c203ae3c5fad65b519c52461027dbecd83451ff1db","raw_frame":"{\"market\":\"0xda6f0e0e93fc8469e0159a166028d017bddbc162b86f66bac90391379603d962\", \"price_changes\":[{\"asset_id\":\"20893381255801015515826997628594359667013752732428989472914000440642900266717\", \"price\":\"0.01\", \"size\":\"5374.02\", \"side\":\"BUY\", \"hash\":\"3103f0f634e05d6cfd94b2f1ca7657f9130b74b4\", \"best_bid\":\"0.72\", \"best_ask\":\"0.73\"}, {\"asset_id\":\"39272994714739463168905443499424551362424437245880253267329605556587274644733\", \"price\":\"0.99\", \"size\":\"5374.02\", \"side\":\"SELL\", \"hash\":\"b6c436c321871f07376931d443637b4679ebdc88\", \"best_bid\":\"0.27\", \"best_ask\":\"0.28\"}], \"timestamp\":\"1785204792478\", \"event_type\":\"price_change\"}","received_at":"2026-07-28T02:13:12.494134Z","schema_version":"clob-market-ws.price_change.v1","sequence":null,"server_hash":null,"server_timestamp":"1785204792478","session_id":"d2757dd6dad94f3b9fe67e8dbf1adc37","source":"clob_market_ws"},"received_at":"2026-07-28T02:13:12.494134Z","record_id":"88c454eae5775dcad94bf88e0fcb26be893f7cc83d02cf3605ca82f7866be060","schema_fingerprint":"4aa3821a28b0b7c2400bc59aba4bcc0a76e971dadd19610d3ad38c768e124dc7","schema_version":"edge-lab-recorder.raw.v1","sequence":null,"source":"clob_market_ws"}
{"event_at":"2026-07-28T02:13:12.494000Z","event_fingerprint":"3bfc84e63f3cfdc8805cb122acd92cc23e98efb0f7ed8d864cd371cd731c1662","payload":{"connection_id":"5d29200f65794d4d9ab6ef271f045a9b","event_at":"2026-07-28T02:13:12.494000Z","event_type":"price_change","frame_hash":"9e68110cc19ff292a55d7d8a72e72227f9532c42d1c059970a7d01443e2cf5d3","frame_index":0,"kind":"data","monotonic_ns":306775507981250,"payload":{"event_type":"price_change","market":"0xda6f0e0e93fc8469e0159a166028d017bddbc162b86f66bac90391379603d962","price_changes":[{"asset_id":"39272994714739463168905443499424551362424437245880253267329605556587274644733","best_ask":"0.28","best_bid":"0.27","hash":"af569b1c94c2e1239e942be2d20c99cc187b2678","price":"0.51","side":"SELL","size":"79"},{"asset_id":"20893381255801015515826997628594359667013752732428989472914000440642900266717","best_ask":"0.73","best_bid":"0.72","hash":"fbf3c1d68c9dfc3148ca8d7607768bd9c87ba372","price":"0.49","side":"BUY","size":"79"}],"timestamp":"1785204792494"},"payload_hash":"78a9134d9d32d0c8722d5f260efc18342ec3fd8c20cb100cd0f081f2ec0dbc09","raw_frame":"{\"market\":\"0xda6f0e0e93fc8469e0159a166028d017bddbc162b86f66bac90391379603d962\", \"price_changes\":[{\"asset_id\":\"39272994714739463168905443499424551362424437245880253267329605556587274644733\", \"price\":\"0.51\", \"size\":\"79\", \"side\":\"SELL\", \"hash\":\"af569b1c94c2e1239e942be2d20c99cc187b2678\", \"best_bid\":\"0.27\", \"best_ask\":\"0.28\"}, {\"asset_id\":\"20893381255801015515826997628594359667013752732428989472914000440642900266717\", \"price\":\"0.49\", \"size\":\"79\", \"side\":\"BUY\", \"hash\":\"fbf3c1d68c9dfc3148ca8d7607768bd9c87ba372\", \"best_bid\":\"0.72\", \"best_ask\":\"0.73\"}], \"timestamp\":\"1785204792494\", \"event_type\":\"price_change\"}","received_at":"2026-07-28T02:13:12.497076Z","schema_version":"clob-market-ws.price_change.v1","sequence":null,"server_hash":null,"server_timestamp":"1785204792494","session_id":"d2757dd6dad94f3b9fe67e8dbf1adc37","source":"clob_market_ws"},"received_at":"2026-07-28T02:13:12.497076Z","record_id":"a58e2fe97fca8f6f770dcafa9d41e91733785b300c2e86b991b15186736c9d25","schema_fingerprint":"4aa3821a28b0b7c2400bc59aba4bcc0a76e971dadd19610d3ad38c768e124dc7","schema_version":"edge-lab-recorder.raw.v1","sequence":null,"source":"clob_market_ws"}
{"event_at":"2026-07-28T02:13:12.513000Z","event_fingerprint":"e71179b36dc42921ba2875dd6e827f20d7410cf73663e43d07a792d1a815f507","payload":{"connection_id":"5d29200f65794d4d9ab6ef271f045a9b","event_at":"2026-07-28T02:13:12.513000Z","event_type":"price_change","frame_hash":"38f3137c0d8dfee33b20b7a2ab99e12ac72299d6ebed09a00ba7801bea90d3ed","frame_index":0,"kind":"data","monotonic_ns":306775511087625,"payload":{"event_type":"price_change","market":"0xda6f0e0e93fc8469e0159a166028d017bddbc162b86f66bac90391379603d962","price_changes":[{"asset_id":"39272994714739463168905443499424551362424437245880253267329605556587274644733","best_ask":"0.28","best_bid":"0.27","hash":"47ed9c08250042c6c47f83046c8892d926a48a55","price":"0.18","side":"BUY","size":"83"},{"asset_id":"20893381255801015515826997628594359667013752732428989472914000440642900266717","best_ask":"0.73","best_bid":"0.72","hash":"f5a2a3691bef6a2996fbf2e7d249cf5be61afa6f","price":"0.82","side":"SELL","size":"83"}],"timestamp":"1785204792513"},"payload_hash":"dbab883c610283a17fd94a8bd71032289b2c39123a5072095f3f71a4cd9eab6d","raw_frame":"{\"market\":\"0xda6f0e0e93fc8469e0159a166028d017bddbc162b86f66bac90391379603d962\", \"price_changes\":[{\"asset_id\":\"39272994714739463168905443499424551362424437245880253267329605556587274644733\", \"price\":\"0.18\", \"size\":\"83\", \"side\":\"BUY\", \"hash\":\"47ed9c08250042c6c47f83046c8892d926a48a55\", \"best_bid\":\"0.27\", \"best_ask\":\"0.28\"}, {\"asset_id\":\"20893381255801015515826997628594359667013752732428989472914000440642900266717\", \"price\":\"0.82\", \"size\":\"83\", \"side\":\"SELL\", \"hash\":\"f5a2a3691bef6a2996fbf2e7d249cf5be61afa6f\", \"best_bid\":\"0.72\", \"best_ask\":\"0.73\"}], \"timestamp\":\"1785204792513\", \"event_type\":\"price_change\"}","received_at":"2026-07-28T02:13:12.500184Z","schema_version":"clob-market-ws.price_change.v1","sequence":null,"server_hash":null,"server_timestamp":"1785204792513","session_id":"d2757dd6dad94f3b9fe67e8dbf1adc37","source":"clob_market_ws"},"received_at":"2026-07-28T02:13:12.500184Z","record_id":"05bf318e05d70007b8e681b31d8ee26f3f2e9ec22706c8f81a068830e765dd58","schema_fingerprint":"4aa3821a28b0b7c2400bc59aba4bcc0a76e971dadd19610d3ad38c768e124dc7","schema_version":"edge-lab-recorder.raw.v1","sequence":null,"source":"clob_market_ws"}
{"event_at":"2026-07-28T02:13:12.518000Z","event_fingerprint":"1db07198cd7846da3671fd003b46f76a9c66fc4b68e006cc609f91f2cd982f98","payload":{"connection_id":"5d29200f65794d4d9ab6ef271f045a9b","event_at":"2026-07-28T02:13:12.518000Z","event_type":"price_change","frame_hash":"bf3b8671f23d4d9ad2b361159269ac1651a51459a9840dc6a807add3e094e3ac","frame_index":0,"kind":"data","monotonic_ns":306775515489166,"payload":{"event_type":"price_change","market":"0xda6f0e0e93fc8469e0159a166028d017bddbc162b86f66bac90391379603d962","price_changes":[{"asset_id":"39272994714739463168905443499424551362424437245880253267329605556587274644733","best_ask":"0.28","best_bid":"0.27","hash":"22d9c8d500d718f838ce1bd9c58605c7eeb8e00d","price":"0.25","side":"BUY","size":"79"},{"asset_id":"20893381255801015515826997628594359667013752732428989472914000440642900266717","best_ask":"0.73","best_bid":"0.72","hash":"2b60f807dbc6c4cc01eed67f28881405ee0a0be0","price":"0.75","side":"SELL","size":"79"}],"timestamp":"1785204792518"},"payload_hash":"3d10268dcb0a6cadf94c10b1759dd7504b4356fe9160008303623b9859469904","raw_frame":"{\"market\":\"0xda6f0e0e93fc8469e0159a166028d017bddbc162b86f66bac90391379603d962\", \"price_changes\":[{\"asset_id\":\"39272994714739463168905443499424551362424437245880253267329605556587274644733\", \"price\":\"0.25\", \"size\":\"79\", \"side\":\"BUY\", \"hash\":\"22d9c8d500d718f838ce1bd9c58605c7eeb8e00d\", \"best_bid\":\"0.27\", \"best_ask\":\"0.28\"}, {\"asset_id\":\"20893381255801015515826997628594359667013752732428989472914000440642900266717\", \"price\":\"0.75\", \"size\":\"79\", \"side\":\"SELL\", \"hash\":\"2b60f807dbc6c4cc01eed67f28881405ee0a0be0\", \"best_bid\":\"0.72\", \"best_ask\":\"0.73\"}], \"timestamp\":\"1785204792518\", \"event_type\":\"price_change\"}","received_at":"2026-07-28T02:13:12.504586Z","schema_version":"clob-market-ws.price_change.v1","sequence":null,"server_hash":null,"server_timestamp":"1785204792518","session_id":"d2757dd6dad94f3b9fe67e8dbf1adc37","source":"clob_market_ws"},"received_at":"2026-07-28T02:13:12.504586Z","record_id":"00de765c66928e518b487fced76071e17b0c944f72c34306eb0a80e75e1f8129","schema_fingerprint":"4aa3821a28b0b7c2400bc59aba4bcc0a76e971dadd19610d3ad38c768e124dc7","schema_version":"edge-lab-recorder.raw.v1","sequence":null,"source":"clob_market_ws"}
{"event_at":"2026-07-28T02:13:12.521000Z","event_fingerprint":"a61a984f36ccd78983211a208fbaebbdfa26ada3d4921a0606e6f67f22ad578f","payload":{"connection_id":"5d29200f65794d4d9ab6ef271f045a9b","event_at":"2026-07-28T02:13:12.521000Z","event_type":"price_change","frame_hash":"84f0d0e45a3144b7e9d583df1849e81643675ccc2fed745ebf08019742df2f0b","frame_index":0,"kind":"data","monotonic_ns":306775518455958,"payload":{"event_type":"price_change","market":"0xda6f0e0e93fc8469e0159a166028d017bddbc162b86f66bac90391379603d962","price_changes":[{"asset_id":"39272994714739463168905443499424551362424437245880253267329605556587274644733","best_ask":"0.28","best_bid":"0.27","hash":"604f9aa3b1daa04cfe850ccf3da25c845edf4cc7","price":"0.27","side":"BUY","size":"25"},{"asset_id":"20893381255801015515826997628594359667013752732428989472914000440642900266717","best_ask":"0.73","best_bid":"0.72","hash":"6467040b69560e54bf209991497ef6d69e994a1b","price":"0.73","side":"SELL","size":"25"}],"timestamp":"1785204792521"},"payload_hash":"79dc7fa45663066057f0e06fd5f53f346b76e7847a8411cd09e1a3707f7f700d","raw_frame":"{\"market\":\"0xda6f0e0e93fc8469e0159a166028d017bddbc162b86f66bac90391379603d962\", \"price_changes\":[{\"asset_id\":\"39272994714739463168905443499424551362424437245880253267329605556587274644733\", \"price\":\"0.27\", \"size\":\"25\", \"side\":\"BUY\", \"hash\":\"604f9aa3b1daa04cfe850ccf3da25c845edf4cc7\", \"best_bid\":\"0.27\", \"best_ask\":\"0.28\"}, {\"asset_id\":\"20893381255801015515826997628594359667013752732428989472914000440642900266717\", \"price\":\"0.73\", \"size\":\"25\", \"side\":\"SELL\", \"hash\":\"6467040b69560e54bf209991497ef6d69e994a1b\", \"best_bid\":\"0.72\", \"best_ask\":\"0.73\"}], \"timestamp\":\"1785204792521\", \"event_type\":\"price_change\"}","received_at":"2026-07-28T02:13:12.507552Z","schema_version":"clob-market-ws.price_change.v1","sequence":null,"server_hash":null,"server_timestamp":"1785204792521","session_id":"d2757dd6dad94f3b9fe67e8dbf1adc37","source":"clob_market_ws"},"received_at":"2026-07-28T02:13:12.507552Z","record_id":"3024c59ac8bf7a364dd7a0e9320baded64f2183f66b0cfefe11e50a4ead9ad45","schema_fingerprint":"4aa3821a28b0b7c2400bc59aba4bcc0a76e971dadd19610d3ad38c768e124dc7","schema_version":"edge-lab-recorder.raw.v1","sequence":null,"source":"clob_market_ws"}
{"event_at":"2026-07-28T02:13:12.524000Z","event_fingerprint":"8c9c96ee9231d8fd4f837c5153abefb8525ef6465d30eb6133c07f6b0622376d","payload":{"connection_id":"5d29200f65794d4d9ab6ef271f045a9b","event_at":"2026-07-28T02:13:12.524000Z","event_type":"price_change","frame_hash":"e5c47af2bffcee35dc6c51d6b6410abd496fec6c5a62199b9d8b1db74e204530","frame_index":0,"kind":"data","monotonic_ns":306775521421208,"payload":{"event_type":"price_change","market":"0xda6f0e0e93fc8469e0159a166028d017bddbc162b86f66bac90391379603d962","price_changes":[{"asset_id":"39272994714739463168905443499424551362424437245880253267329605556587274644733","best_ask":"0.28","best_bid":"0.27","hash":"52a2244ea3eca069955b9c6375cdbcffc1804fcc","price":"0.01","side":"BUY","size":"8098.02"},{"asset_id":"20893381255801015515826997628594359667013752732428989472914000440642900266717","best_ask":"0.73","best_bid":"0.72","hash":"b4f38dcff7f26109c70e64f5b730f3f021c941d8","price":"0.99","side":"SELL","size":"8098.02"}],"timestamp":"1785204792524"},"payload_hash":"155823fa6fea34fb4a6187c17dae402a5fd4aa2f1ee79fbc75f71d1c62cbb2c4","raw_frame":"{\"market\":\"0xda6f0e0e93fc8469e0159a166028d017bddbc162b86f66bac90391379603d962\", \"price_changes\":[{\"asset_id\":\"39272994714739463168905443499424551362424437245880253267329605556587274644733\", \"price\":\"0.01\", \"size\":\"8098.02\", \"side\":\"BUY\", \"hash\":\"52a2244ea3eca069955b9c6375cdbcffc1804fcc\", \"best_bid\":\"0.27\", \"best_ask\":\"0.28\"}, {\"asset_id\":\"20893381255801015515826997628594359667013752732428989472914000440642900266717\", \"price\":\"0.99\", \"size\":\"8098.02\", \"side\":\"SELL\", \"hash\":\"b4f38dcff7f26109c70e64f5b730f3f021c941d8\", \"best_bid\":\"0.72\", \"best_ask\":\"0.73\"}], \"timestamp\":\"1785204792524\", \"event_type\":\"price_change\"}","received_at":"2026-07-28T02:13:12.510517Z","schema_version":"clob-market-ws.price_change.v1","sequence":null,"server_hash":null,"server_timestamp":"1785204792524","session_id":"d2757dd6dad94f3b9fe67e8dbf1adc37","source":"clob_market_ws"},"received_at":"2026-07-28T02:13:12.510517Z","record_id":"e6ec52c45754f8b729d0a706609657cb7f23acf6dd95a169ccfb7732d4b59466","schema_fingerprint":"4aa3821a28b0b7c2400bc59aba4bcc0a76e971dadd19610d3ad38c768e124dc7","schema_version":"edge-lab-recorder.raw.v1","sequence":null,"source":"clob_market_ws"}
{"event_at":"2026-07-28T02:13:12.525000Z","event_fingerprint":"7717ea2ab856ee8e2457a3e12894e6fc22b67280c848d643f443cf0f0169e11f","payload":{"connection_id":"5d29200f65794d4d9ab6ef271f045a9b","event_at":"2026-07-28T02:13:12.525000Z","event_type":"price_change","frame_hash":"674cd20faa78d57fcb92910f90762c557fa75dbcbf57a7fd3655c761871e35fd","frame_index":0,"kind":"data","monotonic_ns":306775524356666,"payload":{"event_type":"price_change","market":"0xda6f0e0e93fc8469e0159a166028d017bddbc162b86f66bac90391379603d962","price_changes":[{"asset_id":"39272994714739463168905443499424551362424437245880253267329605556587274644733","best_ask":"0.28","best_bid":"0.27","hash":"1ad2a2d4c1bc44493e1f6c55c1d3c151f3ade178","price":"0.27","side":"BUY","size":"54"},{"asset_id":"20893381255801015515826997628594359667013752732428989472914000440642900266717","best_ask":"0.73","best_bid":"0.72","hash":"f9c6aa24cfc11d409b642275c843ee9f9b8c6e72","price":"0.73","side":"SELL","size":"54"}],"timestamp":"1785204792525"},"payload_hash":"a74f5a9ec5033e5dbe61d890758ee5c2346d1b9fcb943a7447e30dba9a26e70a","raw_frame":"{\"market\":\"0xda6f0e0e93fc8469e0159a166028d017bddbc162b86f66bac90391379603d962\", \"price_changes\":[{\"asset_id\":\"39272994714739463168905443499424551362424437245880253267329605556587274644733\", \"price\":\"0.27\", \"size\":\"54\", \"side\":\"BUY\", \"hash\":\"1ad2a2d4c1bc44493e1f6c55c1d3c151f3ade178\", \"best_bid\":\"0.27\", \"best_ask\":\"0.28\"}, {\"asset_id\":\"20893381255801015515826997628594359667013752732428989472914000440642900266717\", \"price\":\"0.73\", \"size\":\"54\", \"side\":\"SELL\", \"hash\":\"f9c6aa24cfc11d409b642275c843ee9f9b8c6e72\", \"best_bid\":\"0.72\", \"best_ask\":\"0.73\"}], \"timestamp\":\"1785204792525\", \"event_type\":\"price_change\"}","received_at":"2026-07-28T02:13:12.513453Z","schema_version":"clob-market-ws.price_change.v1","sequence":null,"server_hash":null,"server_timestamp":"1785204792525","session_id":"d2757dd6dad94f3b9fe67e8dbf1adc37","source":"clob_market_ws"},"received_at":"2026-07-28T02:13:12.513453Z","record_id":"fa980fc997967976c1d0aaf4e5853a4fbfe87d0453ef5bdc25c90d44f5e57780","schema_fingerprint":"4aa3821a28b0b7c2400bc59aba4bcc0a76e971dadd19610d3ad38c768e124dc7","schema_version":"edge-lab-recorder.raw.v1","sequence":null,"source":"clob_market_ws"}
