{"event_at":"2026-07-28T02:02:53.230000Z","event_fingerprint":"db76f1aef603c66f0e751557696e0cce72dbb820f6a9099c78158f3040be58d6","payload":{"connection_id":"5d29200f65794d4d9ab6ef271f045a9b","event_at":"2026-07-28T02:02:53.230000Z","event_type":"price_change","frame_hash":"871efd2293c5f82fd7d8c4631c41d0086d8a8f073e4157f06986e3074385fcb2","frame_index":0,"kind":"data","monotonic_ns":306157060382750,"payload":{"event_type":"price_change","market":"0xda6f0e0e93fc8469e0159a166028d017bddbc162b86f66bac90391379603d962","price_changes":[{"asset_id":"20893381255801015515826997628594359667013752732428989472914000440642900266717","best_ask":"0.41","best_bid":"0.4","hash":"96879824a17fe4a215cbeab5c16d96e83936cc6d","price":"0.4","side":"BUY","size":"95.2"},{"asset_id":"39272994714739463168905443499424551362424437245880253267329605556587274644733","best_ask":"0.6","best_bid":"0.59","hash":"76053508ae4cc11c3ea2702a99527ad0d60b3835","price":"0.6","side":"SELL","size":"95.2"}],"timestamp":"1785204173230"},"payload_hash":"97877e13ced95a57d2efa9434df71c16a5efe36be5a33eafafa6db92a3435542","raw_frame":"{\"market\":\"0xda6f0e0e93fc8469e0159a166028d017bddbc162b86f66bac90391379603d962\", \"price_changes\":[{\"asset_id\":\"20893381255801015515826997628594359667013752732428989472914000440642900266717\", \"price\":\"0.4\", \"size\":\"95.2\", \"side\":\"BUY\", \"hash\":\"96879824a17fe4a215cbeab5c16d96e83936cc6d\", \"best_bid\":\"0.4\", \"best_ask\":\"0.41\"}, {\"asset_id\":\"39272994714739463168905443499424551362424437245880253267329605556587274644733\", \"price\":\"0.6\", \"size\":\"95.2\", \"side\":\"SELL\", \"hash\":\"76053508ae4cc11c3ea2702a99527ad0d60b3835\", \"best_bid\":\"0.59\", \"best_ask\":\"0.6\"}], \"timestamp\":\"1785204173230\", \"event_type\":\"price_change\"}","received_at":"2026-07-28T02:02:54.055611Z","schema_version":"clob-market-ws.price_change.v1","sequence":null,"server_hash":null,"server_timestamp":"1785204173230","session_id":"d2757dd6dad94f3b9fe67e8dbf1adc37","source":"clob_market_ws"},"received_at":"2026-07-28T02:02:54.055611Z","record_id":"f38cfbcf48af58644e75c620a05e738a4d8d20b4a8bff7575ef89e8759ec88c3","schema_fingerprint":"4aa3821a28b0b7c2400bc59aba4bcc0a76e971dadd19610d3ad38c768e124dc7","schema_version":"edge-lab-recorder.raw.v1","sequence":null,"source":"clob_market_ws"}
{"event_at":"2026-07-28T02:02:53.232000Z","event_fingerprint":"07e4da510c3f96377203c832899c2cb9892a63cfdfcd44f7b9f4055267a4af6d","payload":{"connection_id":"5d29200f65794d4d9ab6ef271f045a9b","event_at":"2026-07-28T02:02:53.232000Z","event_type":"price_change","frame_hash":"dc50605fedbed60ac5eb3b12df69fecdf7a34ceb4dfb3f869b4480c7cfefa46e","frame_index":0,"kind":"data","monotonic_ns":306157066086958,"payload":{"event_type":"price_change","market":"0xda6f0e0e93fc8469e0159a166028d017bddbc162b86f66bac90391379603d962","price_changes":[{"asset_id":"39272994714739463168905443499424551362424437245880253267329605556587274644733","best_ask":"0.6","best_bid":"0.59","hash":"7a799efd77713763f8bad526b22a6aea029274a1","price":"0.57","side":"BUY","size":"87.16"},{"asset_id":"20893381255801015515826997628594359667013752732428989472914000440642900266717","best_ask":"0.41","best_bid":"0.4","hash":"a7442b174de4fb33423a13e6a4c38d27cb65f905","price":"0.43","side":"SELL","size":"87.16"}],"timestamp":"1785204173232"},"payload_hash":"91358324de197bcd71a3773a43ce9aac2f4b6d83d28d7f8261b252bd4997761a","raw_frame":"{\"market\":\"0xda6f0e0e93fc8469e0159a166028d017bddbc162b86f66bac90391379603d962\", \"price_changes\":[{\"asset_id\":\"39272994714739463168905443499424551362424437245880253267329605556587274644733\", \"price\":\"0.57\", \"size\":\"87.16\", \"side\":\"BUY\", \"hash\":\"7a799efd77713763f8bad526b22a6aea029274a1\", \"best_bid\":\"0.59\", \"best_ask\":\"0.6\"}, {\"asset_id\":\"20893381255801015515826997628594359667013752732428989472914000440642900266717\", \"price\":\"0.43\", \"size\":\"87.16\", \"side\":\"SELL\", \"hash\":\"a7442b174de4fb33423a13e6a4c38d27cb65f905\", \"best_bid\":\"0.4\", \"best_ask\":\"0.41\"}], \"timestamp\":\"1785204173232\", \"event_type\":\"price_change\"}","received_at":"2026-07-28T02:02:54.061314Z","schema_version":"clob-market-ws.price_change.v1","sequence":null,"server_hash":null,"server_timestamp":"1785204173232","session_id":"d2757dd6dad94f3b9fe67e8dbf1adc37","source":"clob_market_ws"},"received_at":"2026-07-28T02:02:54.061314Z","record_id":"655762ae0dc45b4facce412bb11bf146a80152b9633a729c58d89dea8450d0c7","schema_fingerprint":"4aa3821a28b0b7c2400bc59aba4bcc0a76e971dadd19610d3ad38c768e124dc7","schema_version":"edge-lab-recorder.raw.v1","sequence":null,"source":"clob_market_ws"}
{"event_at":"2026-07-28T02:02:53.240000Z","event_fingerprint":"497df17d6c42bddd3be48e2873b7fcb48ca3e2c123995e1e22db709e30568680","payload":{"connection_id":"5d29200f65794d4d9ab6ef271f045a9b","event_at":"2026-07-28T02:02:53.240000Z","event_type":"price_change","frame_hash":"1f1390d223575108bf661630276908188e8ce7eb469aeb61089768b13467b591","frame_index":0,"kind":"data","monotonic_ns":306157069793666,"payload":{"event_type":"price_change","market":"0xda6f0e0e93fc8469e0159a166028d017bddbc162b86f66bac90391379603d962","price_changes":[{"asset_id":"20893381255801015515826997628594359667013752732428989472914000440642900266717","best_ask":"0.41","best_bid":"0.4","hash":"e68964a587ef879e1fd31ff2eaf46bcc1fa02060","price":"0.39","side":"BUY","size":"385.2"},{"asset_id":"39272994714739463168905443499424551362424437245880253267329605556587274644733","best_ask":"0.6","best_bid":"0.59","hash":"0a491af52ac274b575e3a0b99c73bfc11691a725","price":"0.61","side":"SELL","size":"385.2"}],"timestamp":"1785204173240"},"payload_hash":"45c75812ef695c8601964cdf2c4120befd22d8fab92fe6ce6d75e86ea2640ff2","raw_frame":"{\"market\":\"0xda6f0e0e93fc8469e0159a166028d017bddbc162b86f66bac90391379603d962\", \"price_changes\":[{\"asset_id\":\"20893381255801015515826997628594359667013752732428989472914000440642900266717\", \"price\":\"0.39\", \"size\":\"385.2\", \"side\":\"BUY\", \"hash\":\"e68964a587ef879e1fd31ff2eaf46bcc1fa02060\", \"best_bid\":\"0.4\", \"best_ask\":\"0.41\"}, {\"asset_id\":\"39272994714739463168905443499424551362424437245880253267329605556587274644733\", \"price\":\"0.61\", \"size\":\"385.2\", \"side\":\"SELL\", \"hash\":\"0a491af52ac274b575e3a0b99c73bfc11691a725\", \"best_bid\":\"0.59\", \"best_ask\":\"0.6\"}], \"timestamp\":\"1785204173240\", \"event_type\":\"price_change\"}","received_at":"2026-07-28T02:02:54.065021Z","schema_version":"clob-market-ws.price_change.v1","sequence":null,"server_hash":null,"server_timestamp":"1785204173240","session_id":"d2757dd6dad94f3b9fe67e8dbf1adc37","source":"clob_market_ws"},"received_at":"2026-07-28T02:02:54.065021Z","record_id":"c974c15afb867755d39c0ebc6abecba782d20a21c2d83a5785df48f8d349544d","schema_fingerprint":"4aa3821a28b0b7c2400bc59aba4bcc0a76e971dadd19610d3ad38c768e124dc7","schema_version":"edge-lab-recorder.raw.v1","sequence":null,"source":"clob_market_ws"}
{"event_at":"2026-07-28T02:02:53.248000Z","event_fingerprint":"656745635a96506ca37dcd32729b19f32a7c6a90300c02ff52a56de8c7e2351e","payload":{"connection_id":"5d29200f65794d4d9ab6ef271f045a9b","event_at":"2026-07-28T02:02:53.248000Z","event_type":"price_change","frame_hash":"25614ddf180b70eb571ccfe39e53c9c55a3624d30a9d468b0bcc28d07d5ba58a","frame_index":0,"kind":"data","monotonic_ns":306157072851083,"payload":{"event_type":"price_change","market":"0xda6f0e0e93fc8469e0159a166028d017bddbc162b86f66bac90391379603d962","price_changes":[{"asset_id":"20893381255801015515826997628594359667013752732428989472914000440642900266717","best_ask":"0.41","best_bid":"0.4","hash":"88fa3c16f3358595c4e44acbf7d06a5b063f590d","price":"0.4","side":"BUY","size":"110.2"},{"asset_id":"39272994714739463168905443499424551362424437245880253267329605556587274644733","best_ask":"0.6","best_bid":"0.59","hash":"466be2548ba3abdf76e369915ee36d8dd760bea1","price":"0.6","side":"SELL","size":"110.2"}],"timestamp":"1785204173248"},"payload_hash":"22c60d7f3f5dc86b3b819f0a8601328e94eb797012b08911c73003ef0050c4f7","raw_frame":"{\"market\":\"0xda6f0e0e93fc8469e0159a166028d017bddbc162b86f66bac90391379603d962\", \"price_changes\":[{\"asset_id\":\"20893381255801015515826997628594359667013752732428989472914000440642900266717\", \"price\":\"0.4\", \"size\":\"110.2\", \"side\":\"BUY\", \"hash\":\"88fa3c16f3358595c4e44acbf7d06a5b063f590d\", \"best_bid\":\"0.4\", \"best_ask\":\"0.41\"}, {\"asset_id\":\"39272994714739463168905443499424551362424437245880253267329605556587274644733\", \"price\":\"0.6\", \"size\":\"110.2\", \"side\":\"SELL\", \"hash\":\"466be2548ba3abdf76e369915ee36d8dd760bea1\", \"best_bid\":\"0.59\", \"best_ask\":\"0.6\"}], \"timestamp\":\"1785204173248\", \"event_type\":\"price_change\"}","received_at":"2026-07-28T02:02:54.068079Z","schema_version":"clob-market-ws.price_change.v1","sequence":null,"server_hash":null,"server_timestamp":"1785204173248","session_id":"d2757dd6dad94f3b9fe67e8dbf1adc37","source":"clob_market_ws"},"received_at":"2026-07-28T02:02:54.068079Z","record_id":"94325f78ffaa320876f343b907dc61ebb6a4de19d0ebfb1ed3cd222d5cab9cb0","schema_fingerprint":"4aa3821a28b0b7c2400bc59aba4bcc0a76e971dadd19610d3ad38c768e124dc7","schema_version":"edge-lab-recorder.raw.v1","sequence":null,"source":"clob_market_ws"}
{"event_at":"2026-07-28T02:02:53.250000Z","event_fingerprint":"aae67657e24127ed15caf7b1d1ac350e0b7a036608ba3eebd381a1668d21a818","payload":{"connection_id":"5d29200f65794d4d9ab6ef271f045a9b","event_at":"2026-07-28T02:02:53.250000Z","event_type":"price_change","frame_hash":"c4f94de09b2b0d78317592f010b06d8fe32484db36f896f92745483b9a136238","frame_index":0,"kind":"data","monotonic_ns":306157075713708,"payload":{"event_type":"price_change","market":"0xda6f0e0e93fc8469e0159a166028d017bddbc162b86f66bac90391379603d962","price_changes":[{"asset_id":"20893381255801015515826997628594359667013752732428989472914000440642900266717","best_ask":"0.41","best_bid":"0.4","hash":"17903932e246af85623117df4cdffbb3d4eab3a4","price":"0.34","side":"BUY","size":"216.23"},{"asset_id":"39272994714739463168905443499424551362424437245880253267329605556587274644733","best_ask":"0.6","best_bid":"0.59","hash":"3d23bbb81a881c8dbeb6ccaca448c7fab96d2ff9","price":"0.66","side":"SELL","size":"216.23"}],"timestamp":"1785204173250"},"payload_hash":"624630f3ab35b65e33e738b286cf36ae52d7828d97ca20fda668c6242000b6b0","raw_frame":"{\"market\":\"0xda6f0e0e93fc8469e0159a166028d017bddbc162b86f66bac90391379603d962\", \"price_changes\":[{\"asset_id\":\"20893381255801015515826997628594359667013752732428989472914000440642900266717\", \"price\":\"0.34\", \"size\":\"216.23\", \"side\":\"BUY\", \"hash\":\"17903932e246af85623117df4cdffbb3d4eab3a4\", \"best_bid\":\"0.4\", \"best_ask\":\"0.41\"}, {\"asset_id\":\"39272994714739463168905443499424551362424437245880253267329605556587274644733\", \"price\":\"0.66\", \"size\":\"216.23\", \"side\":\"SELL\", \"hash\":\"3d23bbb81a881c8dbeb6ccaca448c7fab96d2ff9\", \"best_bid\":\"0.59\", \"best_ask\":\"0.6\"}], \"timestamp\":\"1785204173250\", \"event_type\":\"price_change\"}","received_at":"2026-07-28T02:02:54.070942Z","schema_version":"clob-market-ws.price_change.v1","sequence":null,"server_hash":null,"server_timestamp":"1785204173250","session_id":"d2757dd6dad94f3b9fe67e8dbf1adc37","source":"clob_market_ws"},"received_at":"2026-07-28T02:02:54.070942Z","record_id":"5107f853931989a2551bc8dc1439b0a4263ce08972f322729ad1a659f0d25976","schema_fingerprint":"4aa3821a28b0b7c2400bc59aba4bcc0a76e971dadd19610d3ad38c768e124dc7","schema_version":"edge-lab-recorder.raw.v1","sequence":null,"source":"clob_market_ws"}
{"event_at":"2026-07-28T02:02:53.252000Z","event_fingerprint":"1c3ae48ca996a84c0921f2bcbad9d36ac687507183b1ce35fea8e337076476ef","payload":{"connection_id":"5d29200f65794d4d9ab6ef271f045a9b","event_at":"2026-07-28T02:02:53.252000Z","event_type":"best_bid_ask","frame_hash":"3d62c8cd9a908335fe83ac2465a35dfc27cadf6047e5efa86565e5ea07f42a44","frame_index":0,"kind":"data","monotonic_ns":306157078755708,"payload":{"asset_id":"20893381255801015515826997628594359667013752732428989472914000440642900266717","best_ask":"0.42","best_bid":"0.4","event_type":"best_bid_ask","market":"0xda6f0e0e93fc8469e0159a166028d017bddbc162b86f66bac90391379603d962","spread":"0.02","timestamp":"1785204173252"},"payload_hash":"ea7b88b288b053d579434b2d98b6b9986dc80388659d6eccf924b0bd7a387ee8","raw_frame":"{\"market\":\"0xda6f0e0e93fc8469e0159a166028d017bddbc162b86f66bac90391379603d962\", \"asset_id\":\"20893381255801015515826997628594359667013752732428989472914000440642900266717\", \"best_bid\":\"0.4\", \"best_ask\":\"0.42\", \"spread\":\"0.02\", \"timestamp\":\"1785204173252\", \"event_type\":\"best_bid_ask\"}","received_at":"2026-07-28T02:02:54.073983Z","schema_version":"clob-market-ws.best_bid_ask.v1","sequence":null,"server_hash":null,"server_timestamp":"1785204173252","session_id":"d2757dd6dad94f3b9fe67e8dbf1adc37","source":"clob_market_ws"},"received_at":"2026-07-28T02:02:54.073983Z","record_id":"88eaf5725ddb20f7ae0e4644087fd5c2a74322fb16a5d9b9c80f5ad479d7ce2d","schema_fingerprint":"8488399f31b0337811b13b266be932db7062827c2470b78bd8e9e99bab51d17d","schema_version":"edge-lab-recorder.raw.v1","sequence":null,"source":"clob_market_ws"}
{"event_at":"2026-07-28T02:02:53.252000Z","event_fingerprint":"bc52a04aae4f77692e0498548e9d2e01797d7a1b8933cc7f0c8ff036b6d98d83","payload":{"connection_id":"5d29200f65794d4d9ab6ef271f045a9b","event_at":"2026-07-28T02:02:53.252000Z","event_type":"best_bid_ask","frame_hash":"2fb8296f8af40ecd8d79268ca65f6ac25d6f05a8f650f89625d3b1a5e5e6d4dc","frame_index":0,"kind":"data","monotonic_ns":306157081153416,"payload":{"asset_id":"39272994714739463168905443499424551362424437245880253267329605556587274644733","best_ask":"0.6","best_bid":"0.58","event_type":"best_bid_ask","market":"0xda6f0e0e93fc8469e0159a166028d017bddbc162b86f66bac90391379603d962","spread":"0.02","timestamp":"1785204173252"},"payload_hash":"aeff0e0d653f3737352bc5013efe7eee3e2d4af67fbf610b648b24adda6ec114","raw_frame":"{\"market\":\"0xda6f0e0e93fc8469e0159a166028d017bddbc162b86f66bac90391379603d962\", \"asset_id\":\"39272994714739463168905443499424551362424437245880253267329605556587274644733\", \"best_bid\":\"0.58\", \"best_ask\":\"0.6\", \"spread\":\"0.02\", \"timestamp\":\"1785204173252\", \"event_type\":\"best_bid_ask\"}","received_at":"2026-07-28T02:02:54.076381Z","schema_version":"clob-market-ws.best_bid_ask.v1","sequence":null,"server_hash":null,"server_timestamp":"1785204173252","session_id":"d2757dd6dad94f3b9fe67e8dbf1adc37","source":"clob_market_ws"},"received_at":"2026-07-28T02:02:54.076381Z","record_id":"4b123d7b8f6f29357014a76e6c8f00fd1dffce9c8ed344e2ed0bccd2c96623b5","schema_fingerprint":"8488399f31b0337811b13b266be932db7062827c2470b78bd8e9e99bab51d17d","schema_version":"edge-lab-recorder.raw.v1","sequence":null,"source":"clob_market_ws"}
{"event_at":"2026-07-28T02:02:53.251000Z","event_fingerprint":"2f59197e5a07eb1241f0362fc1146bcec8062df6ed4f483d8a68ed94b5af2ea0","payload":{"connection_id":"5d29200f65794d4d9ab6ef271f045a9b","event_at":"2026-07-28T02:02:53.251000Z","event_type":"price_change","frame_hash":"1374f157f610fe21e18b631391338d221b2c3c53c0a9f86ce52efb5f642ee795","frame_index":0,"kind":"data","monotonic_ns":306157083711625,"payload":{"event_type":"price_change","market":"0xda6f0e0e93fc8469e0159a166028d017bddbc162b86f66bac90391379603d962","price_changes":[{"asset_id":"39272994714739463168905443499424551362424437245880253267329605556587274644733","best_ask":"0.6","best_bid":"0.58","hash":"cdbccb90a92ca49d27fb15da227c0bd870bb8b99","price":"0.59","side":"BUY","size":"0"},{"asset_id":"20893381255801015515826997628594359667013752732428989472914000440642900266717","best_ask":"0.42","best_bid":"0.4","hash":"bbf9639cd0d14d0d11042d50a2910a609110a438","price":"0.41","side":"SELL","size":"0"}],"timestamp":"1785204173251"},"payload_hash":"22d73d3389c3274dae18998b47834ca39e529ed6266599707fd64b0b0f4e3efd","raw_frame":"{\"market\":\"0xda6f0e0e93fc8469e0159a166028d017bddbc162b86f66bac90391379603d962\", \"price_changes\":[{\"asset_id\":\"39272994714739463168905443499424551362424437245880253267329605556587274644733\", \"price\":\"0.59\", \"size\":\"0\", \"side\":\"BUY\", \"hash\":\"cdbccb90a92ca49d27fb15da227c0bd870bb8b99\", \"best_bid\":\"0.58\", \"best_ask\":\"0.6\"}, {\"asset_id\":\"20893381255801015515826997628594359667013752732428989472914000440642900266717\", \"price\":\"0.41\", \"size\":\"0\", \"side\":\"SELL\", \"hash\":\"bbf9639cd0d14d0d11042d50a2910a609110a438\", \"best_bid\":\"0.4\", \"best_ask\":\"0.42\"}], \"timestamp\":\"1785204173251\", \"event_type\":\"price_change\"}","received_at":"2026-07-28T02:02:54.078938Z","schema_version":"clob-market-ws.price_change.v1","sequence":null,"server_hash":null,"server_timestamp":"1785204173251","session_id":"d2757dd6dad94f3b9fe67e8dbf1adc37","source":"clob_market_ws"},"received_at":"2026-07-28T02:02:54.078938Z","record_id":"e0e658b55a85edec4315903ec5b63b088114ead4175a48793252cdb713140652","schema_fingerprint":"4aa3821a28b0b7c2400bc59aba4bcc0a76e971dadd19610d3ad38c768e124dc7","schema_version":"edge-lab-recorder.raw.v1","sequence":null,"source":"clob_market_ws"}
{"event_at":"2026-07-28T02:02:53.260000Z","event_fingerprint":"b89d451ecebb35a2b1b8304e80b2c4a556611e6fcf76cd0e0ee4dd178e00a7bd","payload":{"connection_id":"5d29200f65794d4d9ab6ef271f045a9b","event_at":"2026-07-28T02:02:53.260000Z","event_type":"price_change","frame_hash":"0affa06f757c9ce0f8cb71029cab75e730de4818e9f19f56ea938a4fc7857b8a","frame_index":0,"kind":"data","monotonic_ns":306157086736125,"payload":{"event_type":"price_change","market":"0xda6f0e0e93fc8469e0159a166028d017bddbc162b86f66bac90391379603d962","price_changes":[{"asset_id":"20893381255801015515826997628594359667013752732428989472914000440642900266717","best_ask":"0.42","best_bid":"0.4","hash":"345d692bd0631efa70800c1b20fa5d0f8f310829","price":"0.35","side":"BUY","size":"160.07"},{"asset_id":"39272994714739463168905443499424551362424437245880253267329605556587274644733","best_ask":"0.6","best_bid":"0.58","hash":"a6b95f63da9fa34f5b840a3fdf362eeb5ca60100","price":"0.65","side":"SELL","size":"160.07"}],"timestamp":"1785204173260"},"payload_hash":"c919692b4c58acc5f140587e6d1fb0177581b160d979971ffde0a24f8383aeb9","raw_frame":"{\"market\":\"0xda6f0e0e93fc8469e0159a166028d017bddbc162b86f66bac90391379603d962\", \"price_changes\":[{\"asset_id\":\"20893381255801015515826997628594359667013752732428989472914000440642900266717\", \"price\":\"0.35\", \"size\":\"160.07\", \"side\":\"BUY\", \"hash\":\"345d692bd0631efa70800c1b20fa5d0f8f310829\", \"best_bid\":\"0.4\", \"best_ask\":\"0.42\"}, {\"asset_id\":\"39272994714739463168905443499424551362424437245880253267329605556587274644733\", \"price\":\"0.65\", \"size\":\"160.07\", \"side\":\"SELL\", \"hash\":\"a6b95f63da9fa34f5b840a3fdf362eeb5ca60100\", \"best_bid\":\"0.58\", \"best_ask\":\"0.6\"}], \"timestamp\":\"1785204173260\", \"event_type\":\"price_change\"}","received_at":"2026-07-28T02:02:54.081964Z","schema_version":"clob-market-ws.price_change.v1","sequence":null,"server_hash":null,"server_timestamp":"1785204173260","session_id":"d2757dd6dad94f3b9fe67e8dbf1adc37","source":"clob_market_ws"},"received_at":"2026-07-28T02:02:54.081964Z","record_id":"c83292c2e75f97617e3883e15e10727f9d53b0ef2e96c5d3ebd1249b6835ee36","schema_fingerprint":"4aa3821a28b0b7c2400bc59aba4bcc0a76e971dadd19610d3ad38c768e124dc7","schema_version":"edge-lab-recorder.raw.v1","sequence":null,"source":"clob_market_ws"}
{"event_at":"2026-07-28T02:02:53.261000Z","event_fingerprint":"4c0b6379cf56e2e9db21514734ce2a8e2370629e28fdabf90ca5d37f49ca1e83","payload":{"connection_id":"5d29200f65794d4d9ab6ef271f045a9b","event_at":"2026-07-28T02:02:53.261000Z","event_type":"price_change","frame_hash":"ece0a3404eb67949244dc9cc04ca7f9fcb2cedcca313afec5ea68ec197559b1c","frame_index":0,"kind":"data","monotonic_ns":306157091082750,"payload":{"event_type":"price_change","market":"0xda6f0e0e93fc8469e0159a166028d017bddbc162b86f66bac90391379603d962","price_changes":[{"asset_id":"39272994714739463168905443499424551362424437245880253267329605556587274644733","best_ask":"0.6","best_bid":"0.58","hash":"6fc55ca777f66668c853660a1a4b5650cc47ad0b","price":"0.57","side":"BUY","size":"62.16"},{"asset_id":"20893381255801015515826997628594359667013752732428989472914000440642900266717","best_ask":"0.42","best_bid":"0.4","hash":"0abe10b34c00b35ff37e0c7ed09297efdc55193e","price":"0.43","side":"SELL","size":"62.16"}],"timestamp":"1785204173261"},"payload_hash":"3495076d854ba739b6aea2fb89b669bc727393e6c9ef5e6e12606550c1e4ef35","raw_frame":"{\"market\":\"0xda6f0e0e93fc8469e0159a166028d017bddbc162b86f66bac90391379603d962\", \"price_changes\":[{\"asset_id\":\"39272994714739463168905443499424551362424437245880253267329605556587274644733\", \"price\":\"0.57\", \"size\":\"62.16\", \"side\":\"BUY\", \"hash\":\"6fc55ca777f66668c853660a1a4b5650cc47ad0b\", \"best_bid\":\"0.58\", \"best_ask\":\"0.6\"}, {\"asset_id\":\"20893381255801015515826997628594359667013752732428989472914000440642900266717\", \"price\":\"0.43\", \"size\":\"62.16\", \"side\":\"SELL\", \"hash\":\"0abe10b34c00b35ff37e0c7ed09297efdc55193e\", \"best_bid\":\"0.4\", \"best_ask\":\"0.42\"}], \"timestamp\":\"1785204173261\", \"event_type\":\"price_change\"}","received_at":"2026-07-28T02:02:54.086312Z","schema_version":"clob-market-ws.price_change.v1","sequence":null,"server_hash":null,"server_timestamp":"1785204173261","session_id":"d2757dd6dad94f3b9fe67e8dbf1adc37","source":"clob_market_ws"},"received_at":"2026-07-28T02:02:54.086312Z","record_id":"d1d2c19b3681c1adcebde427cf1874a2dcb8577a0c0dd9fd2000601fd3eb2e46","schema_fingerprint":"4aa3821a28b0b7c2400bc59aba4bcc0a76e971dadd19610d3ad38c768e124dc7","schema_version":"edge-lab-recorder.raw.v1","sequence":null,"source":"clob_market_ws"}
{"event_at":"2026-07-28T02:02:53.262000Z","event_fingerprint":"f6c0b48c39b81fdfeedc98182a49a5cfe2940f4660f4d592648970b37c2729fe","payload":{"connection_id":"5d29200f65794d4d9ab6ef271f045a9b","event_at":"2026-07-28T02:02:53.262000Z","event_type":"price_change","frame_hash":"ed60b5e3639cdd922e4b370b73b899df4101e949240ed38a977c182989b39382","frame_index":0,"kind":"data","monotonic_ns":306157094335458,"payload":{"event_type":"price_change","market":"0xda6f0e0e93fc8469e0159a166028d017bddbc162b86f66bac90391379603d962","price_changes":[{"asset_id":"39272994714739463168905443499424551362424437245880253267329605556587274644733","best_ask":"0.6","best_bid":"0.58","hash":"371d3819b9e0f645fd52d7aa8f58306d1f8c89fb","price":"0.6","side":"SELL","size":"115.2"},{"asset_id":"20893381255801015515826997628594359667013752732428989472914000440642900266717","best_ask":"0.42","best_bid":"0.4","hash":"8a444664c5970e5ddd7b47a3f67189b1f3e96be8","price":"0.4","side":"BUY","size":"115.2"}],"timestamp":"1785204173262"},"payload_hash":"517ff853bcbcc8cd995d0e6c524f49e5976bf6bf00b6338e4986c3c98209c6b7","raw_frame":"{\"market\":\"0xda6f0e0e93fc8469e0159a166028d017bddbc162b86f66bac90391379603d962\", \"price_changes\":[{\"asset_id\":\"39272994714739463168905443499424551362424437245880253267329605556587274644733\", \"price\":\"0.6\", \"size\":\"115.2\", \"side\":\"SELL\", \"hash\":\"371d3819b9e0f645fd52d7aa8f58306d1f8c89fb\", \"best_bid\":\"0.58\", \"best_ask\":\"0.6\"}, {\"asset_id\":\"20893381255801015515826997628594359667013752732428989472914000440642900266717\", \"price\":\"0.4\", \"size\":\"115.2\", \"side\":\"BUY\", \"hash\":\"8a444664c5970e5ddd7b47a3f67189b1f3e96be8\", \"best_bid\":\"0.4\", \"best_ask\":\"0.42\"}], \"timestamp\":\"1785204173262\", \"event_type\":\"price_change\"}","received_at":"2026-07-28T02:02:54.089563Z","schema_version":"clob-market-ws.price_change.v1","sequence":null,"server_hash":null,"server_timestamp":"1785204173262","session_id":"d2757dd6dad94f3b9fe67e8dbf1adc37","source":"clob_market_ws"},"received_at":"2026-07-28T02:02:54.089563Z","record_id":"2548ab92452140b36dccc5d0d804c958e88c0db7478c90b3e82fc80253b1f231","schema_fingerprint":"4aa3821a28b0b7c2400bc59aba4bcc0a76e971dadd19610d3ad38c768e124dc7","schema_version":"edge-lab-recorder.raw.v1","sequence":null,"source":"clob_market_ws"}
{"event_at":"2026-07-28T02:02:53.263000Z","event_fingerprint":"c0a04dc00043b031a837883024367aaabdd2cb356027b15636f3f7659ef14a04","payload":{"connection_id":"5d29200f65794d4d9ab6ef271f045a9b","event_at":"2026-07-28T02:02:53.263000Z","event_type":"price_change","frame_hash":"f31176d57ed53e7e295409c53d0c3acbc4124a30f6dbd5647c673155f5c93bfe","frame_index":0,"kind":"data","monotonic_ns":306157097254833,"payload":{"event_type":"price_change","market":"0xda6f0e0e93fc8469e0159a166028d017bddbc162b86f66bac90391379603d962","price_changes":[{"asset_id":"39272994714739463168905443499424551362424437245880253267329605556587274644733","best_ask":"0.6","best_bid":"0.58","hash":"93c1782b97f0d783099906af8b78716527eb248c","price":"0.54","side":"BUY","size":"177"},{"asset_id":"20893381255801015515826997628594359667013752732428989472914000440642900266717","best_ask":"0.42","best_bid":"0.4","hash":"8603e01390d6f599135d81efea16ddc9df24f119","price":"0.46","side":"SELL","size":"177"}],"timestamp":"1785204173263"},"payload_hash":"b23dc7db15e9639b36960c85ca82c6cbc1b7406bb02dec1de479da2ed31559c9","raw_frame":"{\"market\":\"0xda6f0e0e93fc8469e0159a166028d017bddbc162b86f66bac90391379603d962\", \"price_changes\":[{\"asset_id\":\"39272994714739463168905443499424551362424437245880253267329605556587274644733\", \"price\":\"0.54\", \"size\":\"177\", \"side\":\"BUY\", \"hash\":\"93c1782b97f0d783099906af8b78716527eb248c\", \"best_bid\":\"0.58\", \"best_ask\":\"0.6\"}, {\"asset_id\":\"20893381255801015515826997628594359667013752732428989472914000440642900266717\", \"price\":\"0.46\", \"size\":\"177\", \"side\":\"SELL\", \"hash\":\"8603e01390d6f599135d81efea16ddc9df24f119\", \"best_bid\":\"0.4\", \"best_ask\":\"0.42\"}], \"timestamp\":\"1785204173263\", \"event_type\":\"price_change\"}","received_at":"2026-07-28T02:02:54.092481Z","schema_version":"clob-market-ws.price_change.v1","sequence":null,"server_hash":null,"server_timestamp":"1785204173263","session_id":"d2757dd6dad94f3b9fe67e8dbf1adc37","source":"clob_market_ws"},"received_at":"2026-07-28T02:02:54.092481Z","record_id":"a5ad4bacfeb185816e484f73535a02a719d9bf9ac6b3baceb9a9d187e402beaa","schema_fingerprint":"4aa3821a28b0b7c2400bc59aba4bcc0a76e971dadd19610d3ad38c768e124dc7","schema_version":"edge-lab-recorder.raw.v1","sequence":null,"source":"clob_market_ws"}
{"event_at":"2026-07-28T02:02:53.263000Z","event_fingerprint":"c593b20a5de48c43f47bc349c3071727103ba87fed89380bb3923ffe154627d1","payload":{"connection_id":"5d29200f65794d4d9ab6ef271f045a9b","event_at":"2026-07-28T02:02:53.263000Z","event_type":"price_change","frame_hash":"a08025dd054801dc893ada120f9a25bcfd76d9f7af4f53f314497598cc135588","frame_index":0,"kind":"data","monotonic_ns":306157100290208,"payload":{"event_type":"price_change","market":"0xda6f0e0e93fc8469e0159a166028d017bddbc162b86f66bac90391379603d962","price_changes":[{"asset_id":"39272994714739463168905443499424551362424437245880253267329605556587274644733","best_ask":"0.6","best_bid":"0.58","hash":"62130afe23bb15145563b6b9683af691e3c5058e","price":"0.54","side":"BUY","size":"137"},{"asset_id":"20893381255801015515826997628594359667013752732428989472914000440642900266717","best_ask":"0.42","best_bid":"0.4","hash":"3b7402a41c5dd4ca9a002b379d75fca7fbf65b5b","price":"0.46","side":"SELL","size":"137"}],"timestamp":"1785204173263"},"payload_hash":"f23988f17d36793980b2773c5b319f31a22eaffe15dee99a1bdbe651f6c981a1","raw_frame":"{\"market\":\"0xda6f0e0e93fc8469e0159a166028d017bddbc162b86f66bac90391379603d962\", \"price_changes\":[{\"asset_id\":\"39272994714739463168905443499424551362424437245880253267329605556587274644733\", \"price\":\"0.54\", \"size\":\"137\", \"side\":\"BUY\", \"hash\":\"62130afe23bb15145563b6b9683af691e3c5058e\", \"best_bid\":\"0.58\", \"best_ask\":\"0.6\"}, {\"asset_id\":\"20893381255801015515826997628594359667013752732428989472914000440642900266717\", \"price\":\"0.46\", \"size\":\"137\", \"side\":\"SELL\", \"hash\":\"3b7402a41c5dd4ca9a002b379d75fca7fbf65b5b\", \"best_bid\":\"0.4\", \"best_ask\":\"0.42\"}], \"timestamp\":\"1785204173263\", \"event_type\":\"price_change\"}","received_at":"2026-07-28T02:02:54.095518Z","schema_version":"clob-market-ws.price_change.v1","sequence":null,"server_hash":null,"server_timestamp":"1785204173263","session_id":"d2757dd6dad94f3b9fe67e8dbf1adc37","source":"clob_market_ws"},"received_at":"2026-07-28T02:02:54.095518Z","record_id":"9e7a47e7dea99c41abe70e5d13cf7dda36493ea13dc02b23d92529603e99d590","schema_fingerprint":"4aa3821a28b0b7c2400bc59aba4bcc0a76e971dadd19610d3ad38c768e124dc7","schema_version":"edge-lab-recorder.raw.v1","sequence":null,"source":"clob_market_ws"}
{"event_at":"2026-07-28T02:02:53.264000Z","event_fingerprint":"be81b7c43b8095b60258ba80da1ce7e7125bd51eb41dcfe221dfb746d87d3c50","payload":{"connection_id":"5d29200f65794d4d9ab6ef271f045a9b","event_at":"2026-07-28T02:02:53.264000Z","event_type":"price_change","frame_hash":"874a50262d13209635e0c49e0e3369a880abfd03282e8224b35bf362466985ee","frame_index":0,"kind":"data","monotonic_ns":306157104054666,"payload":{"event_type":"price_change","market":"0xda6f0e0e93fc8469e0159a166028d017bddbc162b86f66bac90391379603d962","price_changes":[{"asset_id":"39272994714739463168905443499424551362424437245880253267329605556587274644733","best_ask":"0.6","best_bid":"0.58","hash":"c4844a8643217db7ff9017d2857236f4e0e957b3","price":"0.45","side":"BUY","size":"79"},{"asset_id":"20893381255801015515826997628594359667013752732428989472914000440642900266717","best_ask":"0.42","best_bid":"0.4","hash":"6d558e306e4112e25d7d46c23e816bdcf6fffc21","price":"0.55","side":"SELL","size":"79"}],"timestamp":"1785204173264"},"payload_hash":"ad77474324e687238d491ef5b72c8dc4b69c6f5cf9065094f55e94e6ad9237a5","raw_frame":"{\"market\":\"0xda6f0e0e93fc8469e0159a166028d017bddbc162b86f66bac90391379603d962\", \"price_changes\":[{\"asset_id\":\"39272994714739463168905443499424551362424437245880253267329605556587274644733\", \"price\":\"0.45\", \"size\":\"79\", \"side\":\"BUY\", \"hash\":\"c4844a8643217db7ff9017d2857236f4e0e957b3\", \"best_bid\":\"0.58\", \"best_ask\":\"0.6\"}, {\"asset_id\":\"20893381255801015515826997628594359667013752732428989472914000440642900266717\", \"price\":\"0.55\", \"size\":\"79\", \"side\":\"SELL\", \"hash\":\"6d558e306e4112e25d7d46c23e816bdcf6fffc21\", \"best_bid\":\"0.4\", \"best_ask\":\"0.42\"}], \"timestamp\":\"1785204173264\", \"event_type\":\"price_change\"}","received_at":"2026-07-28T02:02:54.099283Z","schema_version":"clob-market-ws.price_change.v1","sequence":null,"server_hash":null,"server_timestamp":"1785204173264","session_id":"d2757dd6dad94f3b9fe67e8dbf1adc37","source":"clob_market_ws"},"received_at":"2026-07-28T02:02:54.099283Z","record_id":"d04f8eb1b0031868597576192ab88788c7082e0d7cd3dfa047e3de668e599acb","schema_fingerprint":"4aa3821a28b0b7c2400bc59aba4bcc0a76e971dadd19610d3ad38c768e124dc7","schema_version":"edge-lab-recorder.raw.v1","sequence":null,"source":"clob_market_ws"}
{"event_at":"2026-07-28T02:02:53.264000Z","event_fingerprint":"9f0e1b29d622fc164f44a46b4eb0a75be7ae615050443c679c4d06894a7ce416","payload":{"connection_id":"5d29200f65794d4d9ab6ef271f045a9b","event_at":"2026-07-28T02:02:53.264000Z","event_type":"best_bid_ask","frame_hash":"d17283a8333626de2beaf628482f6bba7a939970d4bfdbc4b1b5a5fed9f9b272","frame_index":0,"kind":"data","monotonic_ns":306157107349791,"payload":{"asset_id":"20893381255801015515826997628594359667013752732428989472914000440642900266717","best_ask":"0.42","best_bid":"0.41","event_type":"best_bid_ask","market":"0xda6f0e0e93fc8469e0159a166028d017bddbc162b86f66bac90391379603d962","spread":"0.01","timestamp":"1785204173264"},"payload_hash":"588cc4591fcab7be083ef72e263c01e3d3b6d8f735547fe1534e0e8b730aa55a","raw_frame":"{\"market\":\"0xda6f0e0e93fc8469e0159a166028d017bddbc162b86f66bac90391379603d962\", \"asset_id\":\"20893381255801015515826997628594359667013752732428989472914000440642900266717\", \"best_bid\":\"0.41\", \"best_ask\":\"0.42\", \"spread\":\"0.01\", \"timestamp\":\"1785204173264\", \"event_type\":\"best_bid_ask\"}","received_at":"2026-07-28T02:02:54.102577Z","schema_version":"clob-market-ws.best_bid_ask.v1","sequence":null,"server_hash":null,"server_timestamp":"1785204173264","session_id":"d2757dd6dad94f3b9fe67e8dbf1adc37","source":"clob_market_ws"},"received_at":"2026-07-28T02:02:54.102577Z","record_id":"0aa9beb67b609f72d0df5b0470349fa75f0cec4ba1d79303091bdb40645a40e2","schema_fingerprint":"8488399f31b0337811b13b266be932db7062827c2470b78bd8e9e99bab51d17d","schema_version":"edge-lab-recorder.raw.v1","sequence":null,"source":"clob_market_ws"}
{"event_at":"2026-07-28T02:02:53.264000Z","event_fingerprint":"c55bed6cb64b62cabf23d121bcff2fa0bc6c95c6d1a34e3aac4dbf9529b2cb29","payload":{"connection_id":"5d29200f65794d4d9ab6ef271f045a9b","event_at":"2026-07-28T02:02:53.264000Z","event_type":"best_bid_ask","frame_hash":"c31351695f78a59c320eb204652f73ddceada240f15a586c5360a005708aae40","frame_index":0,"kind":"data","monotonic_ns":306157109907375,"payload":{"asset_id":"39272994714739463168905443499424551362424437245880253267329605556587274644733","best_ask":"0.59","best_bid":"0.58","event_type":"best_bid_ask","market":"0xda6f0e0e93fc8469e0159a166028d017bddbc162b86f66bac90391379603d962","spread":"0.01","timestamp":"1785204173264"},"payload_hash":"17959b1141ce2b0948a3b04cf2078f2541323c94b86fc15d8ca419a4281a3008","raw_frame":"{\"market\":\"0xda6f0e0e93fc8469e0159a166028d017bddbc162b86f66bac90391379603d962\", \"asset_id\":\"39272994714739463168905443499424551362424437245880253267329605556587274644733\", \"best_bid\":\"0.58\", \"best_ask\":\"0.59\", \"spread\":\"0.01\", \"timestamp\":\"1785204173264\", \"event_type\":\"best_bid_ask\"}","received_at":"2026-07-28T02:02:54.105135Z","schema_version":"clob-market-ws.best_bid_ask.v1","sequence":null,"server_hash":null,"server_timestamp":"1785204173264","session_id":"d2757dd6dad94f3b9fe67e8dbf1adc37","source":"clob_market_ws"},"received_at":"2026-07-28T02:02:54.105135Z","record_id":"f9457fb1865515de135c6e3ae9d45508dbc0678ea1e0e73b058b3bca00afe78e","schema_fingerprint":"8488399f31b0337811b13b266be932db7062827c2470b78bd8e9e99bab51d17d","schema_version":"edge-lab-recorder.raw.v1","sequence":null,"source":"clob_market_ws"}
{"event_at":"2026-07-28T02:02:53.264000Z","event_fingerprint":"7c4ea29a031f48207bcf7c97c05a1b28fff10d95a402ed5e7df64efc2edd8770","payload":{"connection_id":"5d29200f65794d4d9ab6ef271f045a9b","event_at":"2026-07-28T02:02:53.264000Z","event_type":"price_change","frame_hash":"789983bf926b2fab72944e4ce9f79ff097f49b36f56eec130921d2dec9c24584","frame_index":0,"kind":"data","monotonic_ns":306157112438500,"payload":{"event_type":"price_change","market":"0xda6f0e0e93fc8469e0159a166028d017bddbc162b86f66bac90391379603d962","price_changes":[{"asset_id":"20893381255801015515826997628594359667013752732428989472914000440642900266717","best_ask":"0.42","best_bid":"0.41","hash":"1bb150f557dea9b4c9df18e88cce7fde86df54dc","price":"0.41","side":"BUY","size":"40"},{"asset_id":"39272994714739463168905443499424551362424437245880253267329605556587274644733","best_ask":"0.59","best_bid":"0.58","hash":"a7da3abc3accdddb82018cda5a6ee0035d454138","price":"0.59","side":"SELL","size":"40"}],"timestamp":"1785204173264"},"payload_hash":"7e32616e8811ec8b08cee322d51950fc1cdff12236f32867fc4dcf35c3cb5f62","raw_frame":"{\"market\":\"0xda6f0e0e93fc8469e0159a166028d017bddbc162b86f66bac90391379603d962\", \"price_changes\":[{\"asset_id\":\"20893381255801015515826997628594359667013752732428989472914000440642900266717\", \"price\":\"0.41\", \"size\":\"40\", \"side\":\"BUY\", \"hash\":\"1bb150f557dea9b4c9df18e88cce7fde86df54dc\", \"best_bid\":\"0.41\", \"best_ask\":\"0.42\"}, {\"asset_id\":\"39272994714739463168905443499424551362424437245880253267329605556587274644733\", \"price\":\"0.59\", \"size\":\"40\", \"side\":\"SELL\", \"hash\":\"a7da3abc3accdddb82018cda5a6ee0035d454138\", \"best_bid\":\"0.58\", \"best_ask\":\"0.59\"}], \"timestamp\":\"1785204173264\", \"event_type\":\"price_change\"}","received_at":"2026-07-28T02:02:54.107666Z","schema_version":"clob-market-ws.price_change.v1","sequence":null,"server_hash":null,"server_timestamp":"1785204173264","session_id":"d2757dd6dad94f3b9fe67e8dbf1adc37","source":"clob_market_ws"},"received_at":"2026-07-28T02:02:54.107666Z","record_id":"5c9b5d85f5a00e706d6e4431d07a303dfda05dfdcda9c703299df9594220324d","schema_fingerprint":"4aa3821a28b0b7c2400bc59aba4bcc0a76e971dadd19610d3ad38c768e124dc7","schema_version":"edge-lab-recorder.raw.v1","sequence":null,"source":"clob_market_ws"}
{"event_at":"2026-07-28T02:02:53.265000Z","event_fingerprint":"9ca9483fdcb85da8bbdf68e0eec3fc45bf3c42594908fb1c70ecdf672e74c080","payload":{"connection_id":"5d29200f65794d4d9ab6ef271f045a9b","event_at":"2026-07-28T02:02:53.265000Z","event_type":"price_change","frame_hash":"bd14e644a0e4e94ae3de69648b26444600c6a1c5331a2ae7c0aeca101b35b146","frame_index":0,"kind":"data","monotonic_ns":306157115398416,"payload":{"event_type":"price_change","market":"0xda6f0e0e93fc8469e0159a166028d017bddbc162b86f66bac90391379603d962","price_changes":[{"asset_id":"39272994714739463168905443499424551362424437245880253267329605556587274644733","best_ask":"0.59","best_bid":"0.58","hash":"6e9ddeb931df6e91bcacf602db9af663c14c3e1b","price":"0.56","side":"BUY","size":"417.29"},{"asset_id":"20893381255801015515826997628594359667013752732428989472914000440642900266717","best_ask":"0.42","best_bid":"0.41","hash":"6085320ad1904a347b8dd2a46e79c6d88312c9f4","price":"0.44","side":"SELL","size":"417.29"}],"timestamp":"1785204173265"},"payload_hash":"cfb69621ecf3895994b2dfbca99c6f60bf2855e8b3a652730f1c1fa0e7edf9ee","raw_frame":"{\"market\":\"0xda6f0e0e93fc8469e0159a166028d017bddbc162b86f66bac90391379603d962\", \"price_changes\":[{\"asset_id\":\"39272994714739463168905443499424551362424437245880253267329605556587274644733\", \"price\":\"0.56\", \"size\":\"417.29\", \"side\":\"BUY\", \"hash\":\"6e9ddeb931df6e91bcacf602db9af663c14c3e1b\", \"best_bid\":\"0.58\", \"best_ask\":\"0.59\"}, {\"asset_id\":\"20893381255801015515826997628594359667013752732428989472914000440642900266717\", \"price\":\"0.44\", \"size\":\"417.29\", \"side\":\"SELL\", \"hash\":\"6085320ad1904a347b8dd2a46e79c6d88312c9f4\", \"best_bid\":\"0.41\", \"best_ask\":\"0.42\"}], \"timestamp\":\"1785204173265\", \"event_type\":\"price_change\"}","received_at":"2026-07-28T02:02:54.110626Z","schema_version":"clob-market-ws.price_change.v1","sequence":null,"server_hash":null,"server_timestamp":"1785204173265","session_id":"d2757dd6dad94f3b9fe67e8dbf1adc37","source":"clob_market_ws"},"received_at":"2026-07-28T02:02:54.110626Z","record_id":"0885a8559135d124ac71278709ea548cfa57a73ad9cd4af35de3f95a6ba30931","schema_fingerprint":"4aa3821a28b0b7c2400bc59aba4bcc0a76e971dadd19610d3ad38c768e124dc7","schema_version":"edge-lab-recorder.raw.v1","sequence":null,"source":"clob_market_ws"}
{"event_at":"2026-07-28T02:02:53.266000Z","event_fingerprint":"0c9dd8c1a9a25a5715f401b36b7aa3fbd12dd7ac9666b2e3a748feb2262f25cb","payload":{"connection_id":"5d29200f65794d4d9ab6ef271f045a9b","event_at":"2026-07-28T02:02:53.266000Z","event_type":"price_change","frame_hash":"bd76dde223effc167a2a7d5892b8f4950d350886ebdef17abee0b94f970c2cc7","frame_index":0,"kind":"data","monotonic_ns":306157119233750,"payload":{"event_type":"price_change","market":"0xda6f0e0e93fc8469e0159a166028d017bddbc162b86f66bac90391379603d962","price_changes":[{"asset_id":"20893381255801015515826997628594359667013752732428989472914000440642900266717","best_ask":"0.42","best_bid":"0.41","hash":"03dd8712c42b1fb4df0a695c1019cf9aa831bf0b","price":"0.41","side":"BUY","size":"69"},{"asset_id":"39272994714739463168905443499424551362424437245880253267329605556587274644733","best_ask":"0.59","best_bid":"0.58","hash":"541716c19df138b38fec7696e75c6fbbbbd3ab45","price":"0.59","side":"SELL","size":"69"}],"timestamp":"1785204173266"},"payload_hash":"ba7a2a0a972b02ee6b621ca0def871ec85d83d9040ac417c64d5a8f957221334","raw_frame":"{\"market\":\"0xda6f0e0e93fc8469e0159a166028d017bddbc162b86f66bac90391379603d962\", \"price_changes\":[{\"asset_id\":\"20893381255801015515826997628594359667013752732428989472914000440642900266717\", \"price\":\"0.41\", \"size\":\"69\", \"side\":\"BUY\", \"hash\":\"03dd8712c42b1fb4df0a695c1019cf9aa831bf0b\", \"best_bid\":\"0.41\", \"best_ask\":\"0.42\"}, {\"asset_id\":\"39272994714739463168905443499424551362424437245880253267329605556587274644733\", \"price\":\"0.59\", \"size\":\"69\", \"side\":\"SELL\", \"hash\":\"541716c19df138b38fec7696e75c6fbbbbd3ab45\", \"best_bid\":\"0.58\", \"best_ask\":\"0.59\"}], \"timestamp\":\"1785204173266\", \"event_type\":\"price_change\"}","received_at":"2026-07-28T02:02:54.114461Z","schema_version":"clob-market-ws.price_change.v1","sequence":null,"server_hash":null,"server_timestamp":"1785204173266","session_id":"d2757dd6dad94f3b9fe67e8dbf1adc37","source":"clob_market_ws"},"received_at":"2026-07-28T02:02:54.114461Z","record_id":"94556bb36431559378a3f8b518fdc64aecc20839b19176b4d7d332b9ec4b2a0c","schema_fingerprint":"4aa3821a28b0b7c2400bc59aba4bcc0a76e971dadd19610d3ad38c768e124dc7","schema_version":"edge-lab-recorder.raw.v1","sequence":null,"source":"clob_market_ws"}
{"event_at":"2026-07-28T02:02:53.267000Z","event_fingerprint":"8a4ebef7998e3810f826aa7f6c7b9579ba2f47692508b109859a8d3374989f25","payload":{"connection_id":"5d29200f65794d4d9ab6ef271f045a9b","event_at":"2026-07-28T02:02:53.267000Z","event_type":"price_change","frame_hash":"6a54e6706918504b5b51e1e5a4e21d8b652a33d2f3c669fae03f72514f727c29","frame_index":0,"kind":"data","monotonic_ns":306157122515416,"payload":{"event_type":"price_change","market":"0xda6f0e0e93fc8469e0159a166028d017bddbc162b86f66bac90391379603d962","price_changes":[{"asset_id":"39272994714739463168905443499424551362424437245880253267329605556587274644733","best_ask":"0.59","best_bid":"0.58","hash":"7dca339f6ffc1f8d65227e2a25a40aed28a0604b","price":"0.42","side":"BUY","size":"101.3"},{"asset_id":"20893381255801015515826997628594359667013752732428989472914000440642900266717","best_ask":"0.42","best_bid":"0.41","hash":"33d9f7d5f2aac3ef68cb4395c03ac6bb3e54f92a","price":"0.58","side":"SELL","size":"101.3"}],"timestamp":"1785204173267"},"payload_hash":"413b4457db4e1f5f130a27b9bf47ce0c95b0794cc94a462e139df12c16b67fc4","raw_frame":"{\"market\":\"0xda6f0e0e93fc8469e0159a166028d017bddbc162b86f66bac90391379603d962\", \"price_changes\":[{\"asset_id\":\"39272994714739463168905443499424551362424437245880253267329605556587274644733\", \"price\":\"0.42\", \"size\":\"101.3\", \"side\":\"BUY\", \"hash\":\"7dca339f6ffc1f8d65227e2a25a40aed28a0604b\", \"best_bid\":\"0.58\", \"best_ask\":\"0.59\"}, {\"asset_id\":\"20893381255801015515826997628594359667013752732428989472914000440642900266717\", \"price\":\"0.58\", \"size\":\"101.3\", \"side\":\"SELL\", \"hash\":\"33d9f7d5f2aac3ef68cb4395c03ac6bb3e54f92a\", \"best_bid\":\"0.41\", \"best_ask\":\"0.42\"}], \"timestamp\":\"1785204173267\", \"event_type\":\"price_change\"}","received_at":"2026-07-28T02:02:54.117743Z","schema_version":"clob-market-ws.price_change.v1","sequence":null,"server_hash":null,"server_timestamp":"1785204173267","session_id":"d2757dd6dad94f3b9fe67e8dbf1adc37","source":"clob_market_ws"},"received_at":"2026-07-28T02:02:54.117743Z","record_id":"be5fd284f4bd4ec61e8a19897bc32a9ab11d54b1d13a57e83824791128aaec34","schema_fingerprint":"4aa3821a28b0b7c2400bc59aba4bcc0a76e971dadd19610d3ad38c768e124dc7","schema_version":"edge-lab-recorder.raw.v1","sequence":null,"source":"clob_market_ws"}
{"event_at":"2026-07-28T02:02:53.267000Z","event_fingerprint":"68f7878a75c5189290bf190d4361fa2ec468ab1bc8d79520689dc3d7293c2426","payload":{"connection_id":"5d29200f65794d4d9ab6ef271f045a9b","event_at":"2026-07-28T02:02:53.267000Z","event_type":"price_change","frame_hash":"e8141d4b8d2db9a2307fa78f87e49201bf3497bce9c7def25d235e7db929f180","frame_index":0,"kind":"data","monotonic_ns":306157125601750,"payload":{"event_type":"price_change","market":"0xda6f0e0e93fc8469e0159a166028d017bddbc162b86f66bac90391379603d962","price_changes":[{"asset_id":"20893381255801015515826997628594359667013752732428989472914000440642900266717","best_ask":"0.42","best_bid":"0.41","hash":"3829f1dd1a60c6e054f60e95979a036eedc3c41c","price":"0.4","side":"BUY","size":"120.2"},{"asset_id":"39272994714739463168905443499424551362424437245880253267329605556587274644733","best_ask":"0.59","best_bid":"0.58","hash":"894e73c5e1db18f8a583cc75a699ef338c97b8ab","price":"0.6","side":"SELL","size":"120.2"}],"timestamp":"1785204173267"},"payload_hash":"4d47503ade70f17babd469ef6d5b8dfaaff8a544f908c4bdf7a0820452cfb41d","raw_frame":"{\"market\":\"0xda6f0e0e93fc8469e0159a166028d017bddbc162b86f66bac90391379603d962\", \"price_changes\":[{\"asset_id\":\"20893381255801015515826997628594359667013752732428989472914000440642900266717\", \"price\":\"0.4\", \"size\":\"120.2\", \"side\":\"BUY\", \"hash\":\"3829f1dd1a60c6e054f60e95979a036eedc3c41c\", \"best_bid\":\"0.41\", \"best_ask\":\"0.42\"}, {\"asset_id\":\"39272994714739463168905443499424551362424437245880253267329605556587274644733\", \"price\":\"0.6\", \"size\":\"120.2\", \"side\":\"SELL\", \"hash\":\"894e73c5e1db18f8a583cc75a699ef338c97b8ab\", \"best_bid\":\"0.58\", \"best_ask\":\"0.59\"}], \"timestamp\":\"1785204173267\", \"event_type\":\"price_change\"}","received_at":"2026-07-28T02:02:54.120829Z","schema_version":"clob-market-ws.price_change.v1","sequence":null,"server_hash":null,"server_timestamp":"1785204173267","session_id":"d2757dd6dad94f3b9fe67e8dbf1adc37","source":"clob_market_ws"},"received_at":"2026-07-28T02:02:54.120829Z","record_id":"030657268aafaf9016b4cde313723f2fa39556284cf4bd0116a6875f4dac0f34","schema_fingerprint":"4aa3821a28b0b7c2400bc59aba4bcc0a76e971dadd19610d3ad38c768e124dc7","schema_version":"edge-lab-recorder.raw.v1","sequence":null,"source":"clob_market_ws"}
{"event_at":"2026-07-28T02:02:53.268000Z","event_fingerprint":"51f8cbb657562f5a085e41a3f1b411e37433e76abed5fffef8bbfbc814b8d9cf","payload":{"connection_id":"5d29200f65794d4d9ab6ef271f045a9b","event_at":"2026-07-28T02:02:53.268000Z","event_type":"price_change","frame_hash":"97b765a794058cf4db28acad133b6a856a40f7b09d4c6320879a8e5373a566be","frame_index":0,"kind":"data","monotonic_ns":306157129940125,"payload":{"event_type":"price_change","market":"0xda6f0e0e93fc8469e0159a166028d017bddbc162b86f66bac90391379603d962","price_changes":[{"asset_id":"20893381255801015515826997628594359667013752732428989472914000440642900266717","best_ask":"0.42","best_bid":"0.41","hash":"035d7cf22d20fd43dcbfb2025d01e6e5db321fba","price":"0.4","side":"BUY","size":"115.2"},{"asset_id":"39272994714739463168905443499424551362424437245880253267329605556587274644733","best_ask":"0.59","best_bid":"0.58","hash":"39a01ff245d66214794a194c3a3b4d03207924bb","price":"0.6","side":"SELL","size":"115.2"}],"timestamp":"1785204173268"},"payload_hash":"8bb0af25ed96402a619e410e0a340cb519e937ce189f4834cc86d88a6af2b8c4","raw_frame":"{\"market\":\"0xda6f0e0e93fc8469e0159a166028d017bddbc162b86f66bac90391379603d962\", \"price_changes\":[{\"asset_id\":\"20893381255801015515826997628594359667013752732428989472914000440642900266717\", \"price\":\"0.4\", \"size\":\"115.2\", \"side\":\"BUY\", \"hash\":\"035d7cf22d20fd43dcbfb2025d01e6e5db321fba\", \"best_bid\":\"0.41\", \"best_ask\":\"0.42\"}, {\"asset_id\":\"39272994714739463168905443499424551362424437245880253267329605556587274644733\", \"price\":\"0.6\", \"size\":\"115.2\", \"side\":\"SELL\", \"hash\":\"39a01ff245d66214794a194c3a3b4d03207924bb\", \"best_bid\":\"0.58\", \"best_ask\":\"0.59\"}], \"timestamp\":\"1785204173268\", \"event_type\":\"price_change\"}","received_at":"2026-07-28T02:02:54.125166Z","schema_version":"clob-market-ws.price_change.v1","sequence":null,"server_hash":null,"server_timestamp":"1785204173268","session_id":"d2757dd6dad94f3b9fe67e8dbf1adc37","source":"clob_market_ws"},"received_at":"2026-07-28T02:02:54.125166Z","record_id":"6f34d8480cf849718819388d5facda731c98e461400cc50d3bc54a38948641ce","schema_fingerprint":"4aa3821a28b0b7c2400bc59aba4bcc0a76e971dadd19610d3ad38c768e124dc7","schema_version":"edge-lab-recorder.raw.v1","sequence":null,"source":"clob_market_ws"}
{"event_at":"2026-07-28T02:02:53.269000Z","event_fingerprint":"8370578b5de1c1df02db3c205c281f4535e137c8645137806dd4e47e4d7df4b2","payload":{"connection_id":"5d29200f65794d4d9ab6ef271f045a9b","event_at":"2026-07-28T02:02:53.269000Z","event_type":"price_change","frame_hash":"5bba05c4988412c0fabd3d75a38c2fe51369006b65ddaf900c0ca13ee55e8bd2","frame_index":0,"kind":"data","monotonic_ns":306157133080208,"payload":{"event_type":"price_change","market":"0xda6f0e0e93fc8469e0159a166028d017bddbc162b86f66bac90391379603d962","price_changes":[{"asset_id":"20893381255801015515826997628594359667013752732428989472914000440642900266717","best_ask":"0.42","best_bid":"0.41","hash":"117fe299e7ad3d55b78e63de9cf98a5018821d47","price":"0.33","side":"BUY","size":"134"},{"asset_id":"39272994714739463168905443499424551362424437245880253267329605556587274644733","best_ask":"0.59","best_bid":"0.58","hash":"44775c310d6f557edea292ab8fda18e099a2f162","price":"0.67","side":"SELL","size":"134"}],"timestamp":"1785204173269"},"payload_hash":"f97e0305a23c101253ffc5c668ced88d66533851e96921f9f9e5df24721c8bfd","raw_frame":"{\"market\":\"0xda6f0e0e93fc8469e0159a166028d017bddbc162b86f66bac90391379603d962\", \"price_changes\":[{\"asset_id\":\"20893381255801015515826997628594359667013752732428989472914000440642900266717\", \"price\":\"0.33\", \"size\":\"134\", \"side\":\"BUY\", \"hash\":\"117fe299e7ad3d55b78e63de9cf98a5018821d47\", \"best_bid\":\"0.41\", \"best_ask\":\"0.42\"}, {\"asset_id\":\"39272994714739463168905443499424551362424437245880253267329605556587274644733\", \"price\":\"0.67\", \"size\":\"134\", \"side\":\"SELL\", \"hash\":\"44775c310d6f557edea292ab8fda18e099a2f162\", \"best_bid\":\"0.58\", \"best_ask\":\"0.59\"}], \"timestamp\":\"1785204173269\", \"event_type\":\"price_change\"}","received_at":"2026-07-28T02:02:54.128306Z","schema_version":"clob-market-ws.price_change.v1","sequence":null,"server_hash":null,"server_timestamp":"1785204173269","session_id":"d2757dd6dad94f3b9fe67e8dbf1adc37","source":"clob_market_ws"},"received_at":"2026-07-28T02:02:54.128306Z","record_id":"6a5496d6d93e3164754d50f81e7768a9554dad57bb41d4f9f34665a1b94cf02d","schema_fingerprint":"4aa3821a28b0b7c2400bc59aba4bcc0a76e971dadd19610d3ad38c768e124dc7","schema_version":"edge-lab-recorder.raw.v1","sequence":null,"source":"clob_market_ws"}
{"event_at":"2026-07-28T02:02:53.271000Z","event_fingerprint":"29fc598806e40aa53c5a8146ff05a01c55f405fc74b288f4ba9292d607745e05","payload":{"connection_id":"5d29200f65794d4d9ab6ef271f045a9b","event_at":"2026-07-28T02:02:53.271000Z","event_type":"price_change","frame_hash":"ab395e7936c464c962095b0096690a35d5549cd72e69458cb49ba3f96b7d2bdf","frame_index":0,"kind":"data","monotonic_ns":306157136105666,"payload":{"event_type":"price_change","market":"0xda6f0e0e93fc8469e0159a166028d017bddbc162b86f66bac90391379603d962","price_changes":[{"asset_id":"39272994714739463168905443499424551362424437245880253267329605556587274644733","best_ask":"0.59","best_bid":"0.58","hash":"3d14d9cf61fb859f7a2b36df70d83f537bdd005d","price":"0.01","side":"BUY","size":"7858.02"},{"asset_id":"20893381255801015515826997628594359667013752732428989472914000440642900266717","best_ask":"0.42","best_bid":"0.41","hash":"4e3976256aece799264cdc0a96f28dd2b44d6ad2","price":"0.99","side":"SELL","size":"7858.02"}],"timestamp":"1785204173271"},"payload_hash":"2857a4fa80b6d567add49388fc4978262d2b10d36f1bc014ae152c4a599a8130","raw_frame":"{\"market\":\"0xda6f0e0e93fc8469e0159a166028d017bddbc162b86f66bac90391379603d962\", \"price_changes\":[{\"asset_id\":\"39272994714739463168905443499424551362424437245880253267329605556587274644733\", \"price\":\"0.01\", \"size\":\"7858.02\", \"side\":\"BUY\", \"hash\":\"3d14d9cf61fb859f7a2b36df70d83f537bdd005d\", \"best_bid\":\"0.58\", \"best_ask\":\"0.59\"}, {\"asset_id\":\"20893381255801015515826997628594359667013752732428989472914000440642900266717\", \"price\":\"0.99\", \"size\":\"7858.02\", \"side\":\"SELL\", \"hash\":\"4e3976256aece799264cdc0a96f28dd2b44d6ad2\", \"best_bid\":\"0.41\", \"best_ask\":\"0.42\"}], \"timestamp\":\"1785204173271\", \"event_type\":\"price_change\"}","received_at":"2026-07-28T02:02:54.131333Z","schema_version":"clob-market-ws.price_change.v1","sequence":null,"server_hash":null,"server_timestamp":"1785204173271","session_id":"d2757dd6dad94f3b9fe67e8dbf1adc37","source":"clob_market_ws"},"received_at":"2026-07-28T02:02:54.131333Z","record_id":"9766dc3e6f3981398f263e2c8effe320dc33d0c9dda2ab1bec38166724c76e8c","schema_fingerprint":"4aa3821a28b0b7c2400bc59aba4bcc0a76e971dadd19610d3ad38c768e124dc7","schema_version":"edge-lab-recorder.raw.v1","sequence":null,"source":"clob_market_ws"}
{"event_at":"2026-07-28T02:02:53.272000Z","event_fingerprint":"7594ab4a6edb804b6d6543cdf4e579d80eee4ff69ee85923fa0d92cf371230a3","payload":{"connection_id":"5d29200f65794d4d9ab6ef271f045a9b","event_at":"2026-07-28T02:02:53.272000Z","event_type":"price_change","frame_hash":"3617c0e31d989eba6795ef33da38a948f77d769072da0d822c2e22f5797bad31","frame_index":0,"kind":"data","monotonic_ns":306157139122833,"payload":{"event_type":"price_change","market":"0xda6f0e0e93fc8469e0159a166028d017bddbc162b86f66bac90391379603d962","price_changes":[{"asset_id":"20893381255801015515826997628594359667013752732428989472914000440642900266717","best_ask":"0.42","best_bid":"0.41","hash":"49e9eafb5c759751daee8a15010afc3463ac2661","price":"0.4","side":"BUY","size":"110.2"},{"asset_id":"39272994714739463168905443499424551362424437245880253267329605556587274644733","best_ask":"0.59","best_bid":"0.58","hash":"22484f72aed3dcdb853a24d9cad34ef6f25c1564","price":"0.6","side":"SELL","size":"110.2"}],"timestamp":"1785204173272"},"payload_hash":"d1707ace4671d391c8ed38a3666329a20a3a53bd92a352960a2445f9b39e3ba3","raw_frame":"{\"market\":\"0xda6f0e0e93fc8469e0159a166028d017bddbc162b86f66bac90391379603d962\", \"price_changes\":[{\"asset_id\":\"20893381255801015515826997628594359667013752732428989472914000440642900266717\", \"price\":\"0.4\", \"size\":\"110.2\", \"side\":\"BUY\", \"hash\":\"49e9eafb5c759751daee8a15010afc3463ac2661\", \"best_bid\":\"0.41\", \"best_ask\":\"0.42\"}, {\"asset_id\":\"39272994714739463168905443499424551362424437245880253267329605556587274644733\", \"price\":\"0.6\", \"size\":\"110.2\", \"side\":\"SELL\", \"hash\":\"22484f72aed3dcdb853a24d9cad34ef6f25c1564\", \"best_bid\":\"0.58\", \"best_ask\":\"0.59\"}], \"timestamp\":\"1785204173272\", \"event_type\":\"price_change\"}","received_at":"2026-07-28T02:02:54.134351Z","schema_version":"clob-market-ws.price_change.v1","sequence":null,"server_hash":null,"server_timestamp":"1785204173272","session_id":"d2757dd6dad94f3b9fe67e8dbf1adc37","source":"clob_market_ws"},"received_at":"2026-07-28T02:02:54.134351Z","record_id":"6f863501d51c3083c5bcd07aca2c8a087ff0aa37202921302145f1bd6ac57a7c","schema_fingerprint":"4aa3821a28b0b7c2400bc59aba4bcc0a76e971dadd19610d3ad38c768e124dc7","schema_version":"edge-lab-recorder.raw.v1","sequence":null,"source":"clob_market_ws"}
{"event_at":"2026-07-28T02:02:53.273000Z","event_fingerprint":"9d6ff24183f4a767174f25aa3e8efbde7d8cfe25ded1fcfcb2ea1433d7beb29e","payload":{"connection_id":"5d29200f65794d4d9ab6ef271f045a9b","event_at":"2026-07-28T02:02:53.273000Z","event_type":"price_change","frame_hash":"7789902e6a1cb06725761ba8009fe7b4cf3a3de9189184cfba1701e66b489b2e","frame_index":0,"kind":"data","monotonic_ns":306157142474541,"payload":{"event_type":"price_change","market":"0xda6f0e0e93fc8469e0159a166028d017bddbc162b86f66bac90391379603d962","price_changes":[{"asset_id":"39272994714739463168905443499424551362424437245880253267329605556587274644733","best_ask":"0.59","best_bid":"0.58","hash":"9c1e8bfcc08b1d4d3c7d17b659a2fa72039763cd","price":"0.04","side":"BUY","size":"638.09"},{"asset_id":"20893381255801015515826997628594359667013752732428989472914000440642900266717","best_ask":"0.42","best_bid":"0.41","hash":"e3e85fb41deae35e339d901b8d633dcac88ca7ce","price":"0.96","side":"SELL","size":"638.09"}],"timestamp":"1785204173273"},"payload_hash":"e337c644ecb1a4e5e10597c8b495389f5790a96d7f1f21b38649569dc1b83f2e","raw_frame":"{\"market\":\"0xda6f0e0e93fc8469e0159a166028d017bddbc162b86f66bac90391379603d962\", \"price_changes\":[{\"asset_id\":\"39272994714739463168905443499424551362424437245880253267329605556587274644733\", \"price\":\"0.04\", \"size\":\"638.09\", \"side\":\"BUY\", \"hash\":\"9c1e8bfcc08b1d4d3c7d17b659a2fa72039763cd\", \"best_bid\":\"0.58\", \"best_ask\":\"0.59\"}, {\"asset_id\":\"20893381255801015515826997628594359667013752732428989472914000440642900266717\", \"price\":\"0.96\", \"size\":\"638.09\", \"side\":\"SELL\", \"hash\":\"e3e85fb41deae35e339d901b8d633dcac88ca7ce\", \"best_bid\":\"0.41\", \"best_ask\":\"0.42\"}], \"timestamp\":\"1785204173273\", \"event_type\":\"price_change\"}","received_at":"2026-07-28T02:02:54.137701Z","schema_version":"clob-market-ws.price_change.v1","sequence":null,"server_hash":null,"server_timestamp":"1785204173273","session_id":"d2757dd6dad94f3b9fe67e8dbf1adc37","source":"clob_market_ws"},"received_at":"2026-07-28T02:02:54.137701Z","record_id":"a4d4f243a96b9318f4a1fbb308e52cef6927c581b5bcb61d095d76d756a14969","schema_fingerprint":"4aa3821a28b0b7c2400bc59aba4bcc0a76e971dadd19610d3ad38c768e124dc7","schema_version":"edge-lab-recorder.raw.v1","sequence":null,"source":"clob_market_ws"}
{"event_at":"2026-07-28T02:02:53.275000Z","event_fingerprint":"5c56e57e35bfd1ff0fb9f12ecf9afe5ad49d688723add7d7abeee682524b5dea","payload":{"connection_id":"5d29200f65794d4d9ab6ef271f045a9b","event_at":"2026-07-28T02:02:53.275000Z","event_type":"price_change","frame_hash":"0b03c49c2fa098f4b6265e34a7a31e857578ce366a7eaa029a13eb9b497a60ae","frame_index":0,"kind":"data","monotonic_ns":306157145628125,"payload":{"event_type":"price_change","market":"0xda6f0e0e93fc8469e0159a166028d017bddbc162b86f66bac90391379603d962","price_changes":[{"asset_id":"20893381255801015515826997628594359667013752732428989472914000440642900266717","best_ask":"0.42","best_bid":"0.41","hash":"1a8ae7103023bd02bdf8765e521c11eb6f9e618d","price":"0.41","side":"BUY","size":"93"},{"asset_id":"39272994714739463168905443499424551362424437245880253267329605556587274644733","best_ask":"0.59","best_bid":"0.58","hash":"7d90a060ba5035d34c3434de156a7714044624ef","price":"0.59","side":"SELL","size":"93"}],"timestamp":"1785204173275"},"payload_hash":"69dc6f957f8356939f5f7f7f9ec1fe07a9267166fc78fd9954563a3489a78777","raw_frame":"{\"market\":\"0xda6f0e0e93fc8469e0159a166028d017bddbc162b86f66bac90391379603d962\", \"price_changes\":[{\"asset_id\":\"20893381255801015515826997628594359667013752732428989472914000440642900266717\", \"price\":\"0.41\", \"size\":\"93\", \"side\":\"BUY\", \"hash\":\"1a8ae7103023bd02bdf8765e521c11eb6f9e618d\", \"best_bid\":\"0.41\", \"best_ask\":\"0.42\"}, {\"asset_id\":\"39272994714739463168905443499424551362424437245880253267329605556587274644733\", \"price\":\"0.59\", \"size\":\"93\", \"side\":\"SELL\", \"hash\":\"7d90a060ba5035d34c3434de156a7714044624ef\", \"best_bid\":\"0.58\", \"best_ask\":\"0.59\"}], \"timestamp\":\"1785204173275\", \"event_type\":\"price_change\"}","received_at":"2026-07-28T02:02:54.140855Z","schema_version":"clob-market-ws.price_change.v1","sequence":null,"server_hash":null,"server_timestamp":"1785204173275","session_id":"d2757dd6dad94f3b9fe67e8dbf1adc37","source":"clob_market_ws"},"received_at":"2026-07-28T02:02:54.140855Z","record_id":"eb0e8b8a6d99c37e75cc1f032cc2c0637e3063fd1f0a838d70f7dc87edb261c2","schema_fingerprint":"4aa3821a28b0b7c2400bc59aba4bcc0a76e971dadd19610d3ad38c768e124dc7","schema_version":"edge-lab-recorder.raw.v1","sequence":null,"source":"clob_market_ws"}
{"event_at":"2026-07-28T02:02:53.276000Z","event_fingerprint":"14e6236d1a3dd2d57451d2a349428b6eae1fafc4aeff590f61f207a9fd544f24","payload":{"connection_id":"5d29200f65794d4d9ab6ef271f045a9b","event_at":"2026-07-28T02:02:53.276000Z","event_type":"price_change","frame_hash":"68664d0640b2bd27b6af739d87142759e45359d4c3284717ac89dfd6f3794157","frame_index":0,"kind":"data","monotonic_ns":306157149576625,"payload":{"event_type":"price_change","market":"0xda6f0e0e93fc8469e0159a166028d017bddbc162b86f66bac90391379603d962","price_changes":[{"asset_id":"20893381255801015515826997628594359667013752732428989472914000440642900266717","best_ask":"0.42","best_bid":"0.41","hash":"40317c43e45f410795ec4d8e186656cfaea43bb0","price":"0.4","side":"BUY","size":"120.2"},{"asset_id":"39272994714739463168905443499424551362424437245880253267329605556587274644733","best_ask":"0.59","best_bid":"0.58","hash":"96aab92eb881555e14aba2fcd34e769096839b78","price":"0.6","side":"SELL","size":"120.2"}],"timestamp":"1785204173276"},"payload_hash":"6e83a95a442c31457c3b9d7ed2d73cc0b4160d7a3be571f2c69720645f0b6f84","raw_frame":"{\"market\":\"0xda6f0e0e93fc8469e0159a166028d017bddbc162b86f66bac90391379603d962\", \"price_changes\":[{\"asset_id\":\"20893381255801015515826997628594359667013752732428989472914000440642900266717\", \"price\":\"0.4\", \"size\":\"120.2\", \"side\":\"BUY\", \"hash\":\"40317c43e45f410795ec4d8e186656cfaea43bb0\", \"best_bid\":\"0.41\", \"best_ask\":\"0.42\"}, {\"asset_id\":\"39272994714739463168905443499424551362424437245880253267329605556587274644733\", \"price\":\"0.6\", \"size\":\"120.2\", \"side\":\"SELL\", \"hash\":\"96aab92eb881555e14aba2fcd34e769096839b78\", \"best_bid\":\"0.58\", \"best_ask\":\"0.59\"}], \"timestamp\":\"1785204173276\", \"event_type\":\"price_change\"}","received_at":"2026-07-28T02:02:54.144799Z","schema_version":"clob-market-ws.price_change.v1","sequence":null,"server_hash":null,"server_timestamp":"1785204173276","session_id":"d2757dd6dad94f3b9fe67e8dbf1adc37","source":"clob_market_ws"},"received_at":"2026-07-28T02:02:54.144799Z","record_id":"6884afcdd6ce11efff6f25a0c9db212e6d54fa9fee7fb05ba53c04771138072b","schema_fingerprint":"4aa3821a28b0b7c2400bc59aba4bcc0a76e971dadd19610d3ad38c768e124dc7","schema_version":"edge-lab-recorder.raw.v1","sequence":null,"source":"clob_market_ws"}
{"event_at":"2026-07-28T02:02:53.278000Z","event_fingerprint":"bd45bd37f8d2030491d7a97805845ed045de4b131258c0ec102795f5d68284d9","payload":{"connection_id":"5d29200f65794d4d9ab6ef271f045a9b","event_at":"2026-07-28T02:02:53.278000Z","event_type":"price_change","frame_hash":"a96fe4ba071fe46575313833c04c22161e666852cb601352fa4eec63b1daef27","frame_index":0,"kind":"data","monotonic_ns":306157152047000,"payload":{"event_type":"price_change","market":"0xda6f0e0e93fc8469e0159a166028d017bddbc162b86f66bac90391379603d962","price_changes":[{"asset_id":"20893381255801015515826997628594359667013752732428989472914000440642900266717","best_ask":"0.42","best_bid":"0.41","hash":"7af64a76758a230cc44fdf699007c6b0562c66e1","price":"0.39","side":"BUY","size":"360.2"},{"asset_id":"39272994714739463168905443499424551362424437245880253267329605556587274644733","best_ask":"0.59","best_bid":"0.58","hash":"eeb19728c371a4253d614421d6d107d53bd23edf","price":"0.61","side":"SELL","size":"360.2"}],"timestamp":"1785204173278"},"payload_hash":"44543cd25d5aaee593d582b6faf19c7334564e352466322fcce18b5ce600c762","raw_frame":"{\"market\":\"0xda6f0e0e93fc8469e0159a166028d017bddbc162b86f66bac90391379603d962\", \"price_changes\":[{\"asset_id\":\"20893381255801015515826997628594359667013752732428989472914000440642900266717\", \"price\":\"0.39\", \"size\":\"360.2\", \"side\":\"BUY\", \"hash\":\"7af64a76758a230cc44fdf699007c6b0562c66e1\", \"best_bid\":\"0.41\", \"best_ask\":\"0.42\"}, {\"asset_id\":\"39272994714739463168905443499424551362424437245880253267329605556587274644733\", \"price\":\"0.61\", \"size\":\"360.2\", \"side\":\"SELL\", \"hash\":\"eeb19728c371a4253d614421d6d107d53bd23edf\", \"best_bid\":\"0.58\", \"best_ask\":\"0.59\"}], \"timestamp\":\"1785204173278\", \"event_type\":\"price_change\"}","received_at":"2026-07-28T02:02:54.147276Z","schema_version":"clob-market-ws.price_change.v1","sequence":null,"server_hash":null,"server_timestamp":"1785204173278","session_id":"d2757dd6dad94f3b9fe67e8dbf1adc37","source":"clob_market_ws"},"received_at":"2026-07-28T02:02:54.147276Z","record_id":"b0226e7e61a45a19365415ccf610b133a7499adc83dd44be82c5eb9165fee258","schema_fingerprint":"4aa3821a28b0b7c2400bc59aba4bcc0a76e971dadd19610d3ad38c768e124dc7","schema_version":"edge-lab-recorder.raw.v1","sequence":null,"source":"clob_market_ws"}
{"event_at":"2026-07-28T02:02:53.279000Z","event_fingerprint":"2f4ceead5cf7f6bfcdea650864a8ba06e2ea5a9abab1ca1f1afdc0a96942c94d","payload":{"connection_id":"5d29200f65794d4d9ab6ef271f045a9b","event_at":"2026-07-28T02:02:53.279000Z","event_type":"price_change","frame_hash":"0ca7b3ee78078e2de722ffd16f1d3f9846b30d906e9f3e7fdeaf56f59f71fd26","frame_index":0,"kind":"data","monotonic_ns":306157154398083,"payload":{"event_type":"price_change","market":"0xda6f0e0e93fc8469e0159a166028d017bddbc162b86f66bac90391379603d962","price_changes":[{"asset_id":"39272994714739463168905443499424551362424437245880253267329605556587274644733","best_ask":"0.59","best_bid":"0.58","hash":"8e43d19381e5427255ceeab6d6f1da5937d3c19e","price":"0.54","side":"BUY","size":"149.06"},{"asset_id":"20893381255801015515826997628594359667013752732428989472914000440642900266717","best_ask":"0.42","best_bid":"0.41","hash":"7b16efab778b54b396c3d879d483e67cd3d47f3f","price":"0.46","side":"SELL","size":"149.06"}],"timestamp":"1785204173279"},"payload_hash":"2a09920546b79d51b677aa55d388664e761cd720ae61f22d4032300109c47a43","raw_frame":"{\"market\":\"0xda6f0e0e93fc8469e0159a166028d017bddbc162b86f66bac90391379603d962\", \"price_changes\":[{\"asset_id\":\"39272994714739463168905443499424551362424437245880253267329605556587274644733\", \"price\":\"0.54\", \"size\":\"149.06\", \"side\":\"BUY\", \"hash\":\"8e43d19381e5427255ceeab6d6f1da5937d3c19e\", \"best_bid\":\"0.58\", \"best_ask\":\"0.59\"}, {\"asset_id\":\"20893381255801015515826997628594359667013752732428989472914000440642900266717\", \"price\":\"0.46\", \"size\":\"149.06\", \"side\":\"SELL\", \"hash\":\"7b16efab778b54b396c3d879d483e67cd3d47f3f\", \"best_bid\":\"0.41\", \"best_ask\":\"0.42\"}], \"timestamp\":\"1785204173279\", \"event_type\":\"price_change\"}","received_at":"2026-07-28T02:02:54.149625Z","schema_version":"clob-market-ws.price_change.v1","sequence":null,"server_hash":null,"server_timestamp":"1785204173279","session_id":"d2757dd6dad94f3b9fe67e8dbf1adc37","source":"clob_market_ws"},"received_at":"2026-07-28T02:02:54.149625Z","record_id":"b4f61a9383af9a3a6d6bbbee750c19f70e0bc00a96c5684250b1d7a5042ce0b5","schema_fingerprint":"4aa3821a28b0b7c2400bc59aba4bcc0a76e971dadd19610d3ad38c768e124dc7","schema_version":"edge-lab-recorder.raw.v1","sequence":null,"source":"clob_market_ws"}
{"event_at":"2026-07-28T02:02:53.280000Z","event_fingerprint":"3a6a14fd7ab6d7f0e18fcc00da4384f3e0e57a089417c8acd3f99987cb96855d","payload":{"connection_id":"5d29200f65794d4d9ab6ef271f045a9b","event_at":"2026-07-28T02:02:53.280000Z","event_type":"price_change","frame_hash":"72cf0760bc8feb60c84bb1affac0d11bce1c9a89587e1a6d798073a74e7ad477","frame_index":0,"kind":"data","monotonic_ns":306157157664875,"payload":{"event_type":"price_change","market":"0xda6f0e0e93fc8469e0159a166028d017bddbc162b86f66bac90391379603d962","price_changes":[{"asset_id":"39272994714739463168905443499424551362424437245880253267329605556587274644733","best_ask":"0.59","best_bid":"0.58","hash":"8774fe0001daf5360d9c83407916165b5ae6907d","price":"0.6","side":"SELL","size":"115.2"},{"asset_id":"20893381255801015515826997628594359667013752732428989472914000440642900266717","best_ask":"0.42","best_bid":"0.41","hash":"763d425148aaed76ce65ed204d26c36a7404976d","price":"0.4","side":"BUY","size":"115.2"}],"timestamp":"1785204173280"},"payload_hash":"89b98bdeb0b684827071aec659da0d904ff99b81b507c4a530524c8c7c95ea1e","raw_frame":"{\"market\":\"0xda6f0e0e93fc8469e0159a166028d017bddbc162b86f66bac90391379603d962\", \"price_changes\":[{\"asset_id\":\"39272994714739463168905443499424551362424437245880253267329605556587274644733\", \"price\":\"0.6\", \"size\":\"115.2\", \"side\":\"SELL\", \"hash\":\"8774fe0001daf5360d9c83407916165b5ae6907d\", \"best_bid\":\"0.58\", \"best_ask\":\"0.59\"}, {\"asset_id\":\"20893381255801015515826997628594359667013752732428989472914000440642900266717\", \"price\":\"0.4\", \"size\":\"115.2\", \"side\":\"BUY\", \"hash\":\"763d425148aaed76ce65ed204d26c36a7404976d\", \"best_bid\":\"0.41\", \"best_ask\":\"0.42\"}], \"timestamp\":\"1785204173280\", \"event_type\":\"price_change\"}","received_at":"2026-07-28T02:02:54.152892Z","schema_version":"clob-market-ws.price_change.v1","sequence":null,"server_hash":null,"server_timestamp":"1785204173280","session_id":"d2757dd6dad94f3b9fe67e8dbf1adc37","source":"clob_market_ws"},"received_at":"2026-07-28T02:02:54.152892Z","record_id":"93a8768d2be7db38aeb6356fe4413cc2acd560df16808b682f022c08b22b3a85","schema_fingerprint":"4aa3821a28b0b7c2400bc59aba4bcc0a76e971dadd19610d3ad38c768e124dc7","schema_version":"edge-lab-recorder.raw.v1","sequence":null,"source":"clob_market_ws"}
{"event_at":"2026-07-28T02:02:53.280000Z","event_fingerprint":"32fbb4e5fe48fc3e5aa1f3bca188c4c2231f2e8950152d6375ad762e692cae13","payload":{"connection_id":"5d29200f65794d4d9ab6ef271f045a9b","event_at":"2026-07-28T02:02:53.280000Z","event_type":"price_change","frame_hash":"0621f49390b11fd8941ea3c0d82540fcd7bf4495dcf18318ecebc9538db3eb22","frame_index":0,"kind":"data","monotonic_ns":306157160917291,"payload":{"event_type":"price_change","market":"0xda6f0e0e93fc8469e0159a166028d017bddbc162b86f66bac90391379603d962","price_changes":[{"asset_id":"20893381255801015515826997628594359667013752732428989472914000440642900266717","best_ask":"0.42","best_bid":"0.41","hash":"6b124a606413e88d019d653adc4776cfc7572986","price":"0.41","side":"BUY","size":"105.6"},{"asset_id":"39272994714739463168905443499424551362424437245880253267329605556587274644733","best_ask":"0.59","best_bid":"0.58","hash":"4e89d5b9911923087da9f8a8027004933cda1978","price":"0.59","side":"SELL","size":"105.6"}],"timestamp":"1785204173280"},"payload_hash":"023977f8a7606fabcea260521d1e680fce35616aa4f569b4afa45555096df000","raw_frame":"{\"market\":\"0xda6f0e0e93fc8469e0159a166028d017bddbc162b86f66bac90391379603d962\", \"price_changes\":[{\"asset_id\":\"20893381255801015515826997628594359667013752732428989472914000440642900266717\", \"price\":\"0.41\", \"size\":\"105.6\", \"side\":\"BUY\", \"hash\":\"6b124a606413e88d019d653adc4776cfc7572986\", \"best_bid\":\"0.41\", \"best_ask\":\"0.42\"}, {\"asset_id\":\"39272994714739463168905443499424551362424437245880253267329605556587274644733\", \"price\":\"0.59\", \"size\":\"105.6\", \"side\":\"SELL\", \"hash\":\"4e89d5b9911923087da9f8a8027004933cda1978\", \"best_bid\":\"0.58\", \"best_ask\":\"0.59\"}], \"timestamp\":\"1785204173280\", \"event_type\":\"price_change\"}","received_at":"2026-07-28T02:02:54.156144Z","schema_version":"clob-market-ws.price_change.v1","sequence":null,"server_hash":null,"server_timestamp":"1785204173280","session_id":"d2757dd6dad94f3b9fe67e8dbf1adc37","source":"clob_market_ws"},"received_at":"2026-07-28T02:02:54.156144Z","record_id":"79ab6507de970ba666d3ce2ecd5986d67f48ce39c2e7b2a3054dd8927c165fff","schema_fingerprint":"4aa3821a28b0b7c2400bc59aba4bcc0a76e971dadd19610d3ad38c768e124dc7","schema_version":"edge-lab-recorder.raw.v1","sequence":null,"source":"clob_market_ws"}
{"event_at":"2026-07-28T02:02:53.281000Z","event_fingerprint":"492bd66398ddd17ea1d8f68b6d0d3cd761986141a98ae3df1f340bf61a308c36","payload":{"connection_id":"5d29200f65794d4d9ab6ef271f045a9b","event_at":"2026-07-28T02:02:53.281000Z","event_type":"price_change","frame_hash":"1a42d6177369f50223f5cc3c3ab9e5a6a7c9cefeefa52ff1067a185b41a2524b","frame_index":0,"kind":"data","monotonic_ns":306157164080166,"payload":{"event_type":"price_change","market":"0xda6f0e0e93fc8469e0159a166028d017bddbc162b86f66bac90391379603d962","price_changes":[{"asset_id":"20893381255801015515826997628594359667013752732428989472914000440642900266717","best_ask":"0.42","best_bid":"0.41","hash":"9c20e5a0907aec634c978d233bd4703b001c8102","price":"0.37","side":"BUY","size":"149.05"},{"asset_id":"39272994714739463168905443499424551362424437245880253267329605556587274644733","best_ask":"0.59","best_bid":"0.58","hash":"fd89af116e3c9952efaebb71007b0d13a0404ebf","price":"0.63","side":"SELL","size":"149.05"}],"timestamp":"1785204173281"},"payload_hash":"5cbb4f24de27206f26a909a44410aaf2aac38a55095911b13658bca261af8c6f","raw_frame":"{\"market\":\"0xda6f0e0e93fc8469e0159a166028d017bddbc162b86f66bac90391379603d962\", \"price_changes\":[{\"asset_id\":\"20893381255801015515826997628594359667013752732428989472914000440642900266717\", \"price\":\"0.37\", \"size\":\"149.05\", \"side\":\"BUY\", \"hash\":\"9c20e5a0907aec634c978d233bd4703b001c8102\", \"best_bid\":\"0.41\", \"best_ask\":\"0.42\"}, {\"asset_id\":\"39272994714739463168905443499424551362424437245880253267329605556587274644733\", \"price\":\"0.63\", \"size\":\"149.05\", \"side\":\"SELL\", \"hash\":\"fd89af116e3c9952efaebb71007b0d13a0404ebf\", \"best_bid\":\"0.58\", \"best_ask\":\"0.59\"}], \"timestamp\":\"1785204173281\", \"event_type\":\"price_change\"}","received_at":"2026-07-28T02:02:54.159306Z","schema_version":"clob-market-ws.price_change.v1","sequence":null,"server_hash":null,"server_timestamp":"1785204173281","session_id":"d2757dd6dad94f3b9fe67e8dbf1adc37","source":"clob_market_ws"},"received_at":"2026-07-28T02:02:54.159306Z","record_id":"f672c7604471028654ee8c9b146697c3d96e9ec32b432c456ccddc989c6f7b74","schema_fingerprint":"4aa3821a28b0b7c2400bc59aba4bcc0a76e971dadd19610d3ad38c768e124dc7","schema_version":"edge-lab-recorder.raw.v1","sequence":null,"source":"clob_market_ws"}
{"event_at":"2026-07-28T02:02:53.282000Z","event_fingerprint":"221c25ac365477f37998efb2206e37cd52c5c3910cb6f9efcff40f68a16b3b07","payload":{"connection_id":"5d29200f65794d4d9ab6ef271f045a9b","event_at":"2026-07-28T02:02:53.282000Z","event_type":"price_change","frame_hash":"a9a269561ff7d261faa4dd61b3f2a3f2f0a393db650d9266d8b51ea2bdc82040","frame_index":0,"kind":"data","monotonic_ns":306157167120375,"payload":{"event_type":"price_change","market":"0xda6f0e0e93fc8469e0159a166028d017bddbc162b86f66bac90391379603d962","price_changes":[{"asset_id":"39272994714739463168905443499424551362424437245880253267329605556587274644733","best_ask":"0.59","best_bid":"0.58","hash":"4249dabbd345a4fab5d1b6fa585b91c47b7dd456","price":"0.52","side":"BUY","size":"112"},{"asset_id":"20893381255801015515826997628594359667013752732428989472914000440642900266717","best_ask":"0.42","best_bid":"0.41","hash":"b05e0bf6ad7d34a052a71aa871dfa29a44704d6e","price":"0.48","side":"SELL","size":"112"}],"timestamp":"1785204173282"},"payload_hash":"f78c40e0a8178785b97d472f138f07088ba996f5a4d50c31cda731a68de88fa0","raw_frame":"{\"market\":\"0xda6f0e0e93fc8469e0159a166028d017bddbc162b86f66bac90391379603d962\", \"price_changes\":[{\"asset_id\":\"39272994714739463168905443499424551362424437245880253267329605556587274644733\", \"price\":\"0.52\", \"size\":\"112\", \"side\":\"BUY\", \"hash\":\"4249dabbd345a4fab5d1b6fa585b91c47b7dd456\", \"best_bid\":\"0.58\", \"best_ask\":\"0.59\"}, {\"asset_id\":\"20893381255801015515826997628594359667013752732428989472914000440642900266717\", \"price\":\"0.48\", \"size\":\"112\", \"side\":\"SELL\", \"hash\":\"b05e0bf6ad7d34a052a71aa871dfa29a44704d6e\", \"best_bid\":\"0.41\", \"best_ask\":\"0.42\"}], \"timestamp\":\"1785204173282\", \"event_type\":\"price_change\"}","received_at":"2026-07-28T02:02:54.162348Z","schema_version":"clob-market-ws.price_change.v1","sequence":null,"server_hash":null,"server_timestamp":"1785204173282","session_id":"d2757dd6dad94f3b9fe67e8dbf1adc37","source":"clob_market_ws"},"received_at":"2026-07-28T02:02:54.162348Z","record_id":"58a234a64c53ac4a68797ad0dbcfee1fefd1c2382714f370e06a28c54ca99dda","schema_fingerprint":"4aa3821a28b0b7c2400bc59aba4bcc0a76e971dadd19610d3ad38c768e124dc7","schema_version":"edge-lab-recorder.raw.v1","sequence":null,"source":"clob_market_ws"}
{"event_at":"2026-07-28T02:02:53.283000Z","event_fingerprint":"fdb255a976c9245d1a0483c4de69c7b27d48f2cd5c4ef95df140a22620629eee","payload":{"connection_id":"5d29200f65794d4d9ab6ef271f045a9b","event_at":"2026-07-28T02:02:53.283000Z","event_type":"price_change","frame_hash":"82949177ea75978d2ab7550cbbdbe5c03d4413a1ce3c76c5cd1598256d533797","frame_index":0,"kind":"data","monotonic_ns":306157170616708,"payload":{"event_type":"price_change","market":"0xda6f0e0e93fc8469e0159a166028d017bddbc162b86f66bac90391379603d962","price_changes":[{"asset_id":"39272994714739463168905443499424551362424437245880253267329605556587274644733","best_ask":"0.59","best_bid":"0.58","hash":"eabe9fee9c90034eaaacdde1fc7d46f9eee48c1c","price":"0.56","side":"BUY","size":"412.29"},{"asset_id":"20893381255801015515826997628594359667013752732428989472914000440642900266717","best_ask":"0.42","best_bid":"0.41","hash":"c23014af711c2eea0774a7bb51979856e8ae659e","price":"0.44","side":"SELL","size":"412.29"}],"timestamp":"1785204173283"},"payload_hash":"2b3c16d9558bd32c74153a5cb0a6ab9b9fa84648c8a1f4129cd6aadc5a9be719","raw_frame":"{\"market\":\"0xda6f0e0e93fc8469e0159a166028d017bddbc162b86f66bac90391379603d962\", \"price_changes\":[{\"asset_id\":\"39272994714739463168905443499424551362424437245880253267329605556587274644733\", \"price\":\"0.56\", \"size\":\"412.29\", \"side\":\"BUY\", \"hash\":\"eabe9fee9c90034eaaacdde1fc7d46f9eee48c1c\", \"best_bid\":\"0.58\", \"best_ask\":\"0.59\"}, {\"asset_id\":\"20893381255801015515826997628594359667013752732428989472914000440642900266717\", \"price\":\"0.44\", \"size\":\"412.29\", \"side\":\"SELL\", \"hash\":\"c23014af711c2eea0774a7bb51979856e8ae659e\", \"best_bid\":\"0.41\", \"best_ask\":\"0.42\"}], \"timestamp\":\"1785204173283\", \"event_type\":\"price_change\"}","received_at":"2026-07-28T02:02:54.165844Z","schema_version":"clob-market-ws.price_change.v1","sequence":null,"server_hash":null,"server_timestamp":"1785204173283","session_id":"d2757dd6dad94f3b9fe67e8dbf1adc37","source":"clob_market_ws"},"received_at":"2026-07-28T02:02:54.165844Z","record_id":"40445a8ea73e77d4a312a2034b4d09eaa0dd0f220f9ca7d7552feb8e9659496a","schema_fingerprint":"4aa3821a28b0b7c2400bc59aba4bcc0a76e971dadd19610d3ad38c768e124dc7","schema_version":"edge-lab-recorder.raw.v1","sequence":null,"source":"clob_market_ws"}
{"event_at":"2026-07-28T02:02:53.283000Z","event_fingerprint":"ca3d543b95c35dcde4efad52b9ae2d70da3d6807c70d48a2bef6fee8c376c042","payload":{"connection_id":"5d29200f65794d4d9ab6ef271f045a9b","event_at":"2026-07-28T02:02:53.283000Z","event_type":"price_change","frame_hash":"37d85c693bba1cd15416ea5b7688952e4fdbbb5a6be59ad89539b8e5ce37f8d3","frame_index":0,"kind":"data","monotonic_ns":306157173662375,"payload":{"event_type":"price_change","market":"0xda6f0e0e93fc8469e0159a166028d017bddbc162b86f66bac90391379603d962","price_changes":[{"asset_id":"39272994714739463168905443499424551362424437245880253267329605556587274644733","best_ask":"0.59","best_bid":"0.58","hash":"59df73f54c248613e0acbfbdd08c3ee55b8d2dea","price":"0.6","side":"SELL","size":"110.2"},{"asset_id":"20893381255801015515826997628594359667013752732428989472914000440642900266717","best_ask":"0.42","best_bid":"0.41","hash":"8d2ec31a0cebaa6783f94fc2de6f234aa8ecdcec","price":"0.4","side":"BUY","size":"110.2"}],"timestamp":"1785204173283"},"payload_hash":"537506ce831e84b844c70bb84ef7cc4f140cc9139ef887f1c7970d719db403b3","raw_frame":"{\"market\":\"0xda6f0e0e93fc8469e0159a166028d017bddbc162b86f66bac90391379603d962\", \"price_changes\":[{\"asset_id\":\"39272994714739463168905443499424551362424437245880253267329605556587274644733\", \"price\":\"0.6\", \"size\":\"110.2\", \"side\":\"SELL\", \"hash\":\"59df73f54c248613e0acbfbdd08c3ee55b8d2dea\", \"best_bid\":\"0.58\", \"best_ask\":\"0.59\"}, {\"asset_id\":\"20893381255801015515826997628594359667013752732428989472914000440642900266717\", \"price\":\"0.4\", \"size\":\"110.2\", \"side\":\"BUY\", \"hash\":\"8d2ec31a0cebaa6783f94fc2de6f234aa8ecdcec\", \"best_bid\":\"0.41\", \"best_ask\":\"0.42\"}], \"timestamp\":\"1785204173283\", \"event_type\":\"price_change\"}","received_at":"2026-07-28T02:02:54.168888Z","schema_version":"clob-market-ws.price_change.v1","sequence":null,"server_hash":null,"server_timestamp":"1785204173283","session_id":"d2757dd6dad94f3b9fe67e8dbf1adc37","source":"clob_market_ws"},"received_at":"2026-07-28T02:02:54.168888Z","record_id":"3c84e82a0035264de1f7258cd0933af7d538a920b9a2ebb412742c4f82679453","schema_fingerprint":"4aa3821a28b0b7c2400bc59aba4bcc0a76e971dadd19610d3ad38c768e124dc7","schema_version":"edge-lab-recorder.raw.v1","sequence":null,"source":"clob_market_ws"}
{"event_at":"2026-07-28T02:02:53.284000Z","event_fingerprint":"c00acca0f47fe3064d3d0523dd43b92bc080b923b307d5edc539ce601fce60fb","payload":{"connection_id":"5d29200f65794d4d9ab6ef271f045a9b","event_at":"2026-07-28T02:02:53.284000Z","event_type":"price_change","frame_hash":"48d73a89552fb6acffd9fb70b674e182a881f68e8a53daf938a114e326076d93","frame_index":0,"kind":"data","monotonic_ns":306157177169791,"payload":{"event_type":"price_change","market":"0xda6f0e0e93fc8469e0159a166028d017bddbc162b86f66bac90391379603d962","price_changes":[{"asset_id":"39272994714739463168905443499424551362424437245880253267329605556587274644733","best_ask":"0.59","best_bid":"0.58","hash":"8f2fcbf82bb267ebe344d8625b368cbe225e3fa4","price":"0.56","side":"BUY","size":"397.29"},{"asset_id":"20893381255801015515826997628594359667013752732428989472914000440642900266717","best_ask":"0.42","best_bid":"0.41","hash":"e9f7121327f4e0813d64e200d55427692eef46e0","price":"0.44","side":"SELL","size":"397.29"}],"timestamp":"1785204173284"},"payload_hash":"a97f276baa6660022deae2682f28a63c80e7c611b24dbac0dcc72f6b6712b3a8","raw_frame":"{\"market\":\"0xda6f0e0e93fc8469e0159a166028d017bddbc162b86f66bac90391379603d962\", \"price_changes\":[{\"asset_id\":\"39272994714739463168905443499424551362424437245880253267329605556587274644733\", \"price\":\"0.56\", \"size\":\"397.29\", \"side\":\"BUY\", \"hash\":\"8f2fcbf82bb267ebe344d8625b368cbe225e3fa4\", \"best_bid\":\"0.58\", \"best_ask\":\"0.59\"}, {\"asset_id\":\"20893381255801015515826997628594359667013752732428989472914000440642900266717\", \"price\":\"0.44\", \"size\":\"397.29\", \"side\":\"SELL\", \"hash\":\"e9f7121327f4e0813d64e200d55427692eef46e0\", \"best_bid\":\"0.41\", \"best_ask\":\"0.42\"}], \"timestamp\":\"1785204173284\", \"event_type\":\"price_change\"}","received_at":"2026-07-28T02:02:54.172397Z","schema_version":"clob-market-ws.price_change.v1","sequence":null,"server_hash":null,"server_timestamp":"1785204173284","session_id":"d2757dd6dad94f3b9fe67e8dbf1adc37","source":"clob_market_ws"},"received_at":"2026-07-28T02:02:54.172397Z","record_id":"2481595cdb6c44c1a005dc728ccbb7f1ec8e6256541a2963f422dfc7fdab85c0","schema_fingerprint":"4aa3821a28b0b7c2400bc59aba4bcc0a76e971dadd19610d3ad38c768e124dc7","schema_version":"edge-lab-recorder.raw.v1","sequence":null,"source":"clob_market_ws"}
{"event_at":"2026-07-28T02:02:53.284000Z","event_fingerprint":"738eb6163dcc646105ab6a562738750ed45ad993bf728b02653dd5afa1832c5e","payload":{"connection_id":"5d29200f65794d4d9ab6ef271f045a9b","event_at":"2026-07-28T02:02:53.284000Z","event_type":"price_change","frame_hash":"ef121bb7e22d1236d7c49689203d3f485139d4711f89bed0921c46cf0f96bc1e","frame_index":0,"kind":"data","monotonic_ns":306157181543458,"payload":{"event_type":"price_change","market":"0xda6f0e0e93fc8469e0159a166028d017bddbc162b86f66bac90391379603d962","price_changes":[{"asset_id":"20893381255801015515826997628594359667013752732428989472914000440642900266717","best_ask":"0.42","best_bid":"0.41","hash":"0d52583b05a0405728282978fb305c8f3cfcf3e0","price":"0.39","side":"BUY","size":"354.2"},{"asset_id":"39272994714739463168905443499424551362424437245880253267329605556587274644733","best_ask":"0.59","best_bid":"0.58","hash":"d2d0372cadc4daa83fb8a41fc7bd90279000d8d5","price":"0.61","side":"SELL","size":"354.2"}],"timestamp":"1785204173284"},"payload_hash":"e86a688cd2be7a72bf5aa115b83b73132a9940085dbfd5073de42cb1d41929a3","raw_frame":"{\"market\":\"0xda6f0e0e93fc8469e0159a166028d017bddbc162b86f66bac90391379603d962\", \"price_changes\":[{\"asset_id\":\"20893381255801015515826997628594359667013752732428989472914000440642900266717\", \"price\":\"0.39\", \"size\":\"354.2\", \"side\":\"BUY\", \"hash\":\"0d52583b05a0405728282978fb305c8f3cfcf3e0\", \"best_bid\":\"0.41\", \"best_ask\":\"0.42\"}, {\"asset_id\":\"39272994714739463168905443499424551362424437245880253267329605556587274644733\", \"price\":\"0.61\", \"size\":\"354.2\", \"side\":\"SELL\", \"hash\":\"d2d0372cadc4daa83fb8a41fc7bd90279000d8d5\", \"best_bid\":\"0.58\", \"best_ask\":\"0.59\"}], \"timestamp\":\"1785204173284\", \"event_type\":\"price_change\"}","received_at":"2026-07-28T02:02:54.176771Z","schema_version":"clob-market-ws.price_change.v1","sequence":null,"server_hash":null,"server_timestamp":"1785204173284","session_id":"d2757dd6dad94f3b9fe67e8dbf1adc37","source":"clob_market_ws"},"received_at":"2026-07-28T02:02:54.176771Z","record_id":"221eaa2fac704560d739181c1ca386970743a5a4ffae625ad6ac7061a20cac6f","schema_fingerprint":"4aa3821a28b0b7c2400bc59aba4bcc0a76e971dadd19610d3ad38c768e124dc7","schema_version":"edge-lab-recorder.raw.v1","sequence":null,"source":"clob_market_ws"}
{"event_at":"2026-07-28T02:02:53.284000Z","event_fingerprint":"ac36d5a94b489fa609202c538333db4ca7c9dc9b68a1fd27e44c3697e57654e7","payload":{"connection_id":"5d29200f65794d4d9ab6ef271f045a9b","event_at":"2026-07-28T02:02:53.284000Z","event_type":"price_change","frame_hash":"74ab1a4dce5353d8d7cb0ffae4469bbe2f0de8dd73e0de5ef7c24f4a2c2e8631","frame_index":0,"kind":"data","monotonic_ns":306157184615000,"payload":{"event_type":"price_change","market":"0xda6f0e0e93fc8469e0159a166028d017bddbc162b86f66bac90391379603d962","price_changes":[{"asset_id":"20893381255801015515826997628594359667013752732428989472914000440642900266717","best_ask":"0.42","best_bid":"0.41","hash":"505d097ae1bb2c9cf0575877c2418ab86b97df42","price":"0.39","side":"BUY","size":"84.2"},{"asset_id":"39272994714739463168905443499424551362424437245880253267329605556587274644733","best_ask":"0.59","best_bid":"0.58","hash":"74ee30f158921bc60caef0aa06ddc20233b6d8d0","price":"0.61","side":"SELL","size":"84.2"}],"timestamp":"1785204173284"},"payload_hash":"707dc72c6171061e71d63ec62c54a2f9116bfc3e09d6a5e5b0dac351f8bae004","raw_frame":"{\"market\":\"0xda6f0e0e93fc8469e0159a166028d017bddbc162b86f66bac90391379603d962\", \"price_changes\":[{\"asset_id\":\"20893381255801015515826997628594359667013752732428989472914000440642900266717\", \"price\":\"0.39\", \"size\":\"84.2\", \"side\":\"BUY\", \"hash\":\"505d097ae1bb2c9cf0575877c2418ab86b97df42\", \"best_bid\":\"0.41\", \"best_ask\":\"0.42\"}, {\"asset_id\":\"39272994714739463168905443499424551362424437245880253267329605556587274644733\", \"price\":\"0.61\", \"size\":\"84.2\", \"side\":\"SELL\", \"hash\":\"74ee30f158921bc60caef0aa06ddc20233b6d8d0\", \"best_bid\":\"0.58\", \"best_ask\":\"0.59\"}], \"timestamp\":\"1785204173284\", \"event_type\":\"price_change\"}","received_at":"2026-07-28T02:02:54.179842Z","schema_version":"clob-market-ws.price_change.v1","sequence":null,"server_hash":null,"server_timestamp":"1785204173284","session_id":"d2757dd6dad94f3b9fe67e8dbf1adc37","source":"clob_market_ws"},"received_at":"2026-07-28T02:02:54.179842Z","record_id":"6ab058972321fca18a31aa3ea9dce41d2ccdae777b81c2d0f896d5959a0410fc","schema_fingerprint":"4aa3821a28b0b7c2400bc59aba4bcc0a76e971dadd19610d3ad38c768e124dc7","schema_version":"edge-lab-recorder.raw.v1","sequence":null,"source":"clob_market_ws"}
{"event_at":"2026-07-28T02:02:53.284000Z","event_fingerprint":"b63d1005d5aaecf586fe150487184593878b62380e72606cb856eb4f31563dfe","payload":{"connection_id":"5d29200f65794d4d9ab6ef271f045a9b","event_at":"2026-07-28T02:02:53.284000Z","event_type":"price_change","frame_hash":"7a3cdc610cfa458553f933c4a397afc628c5047823f8871c255cb85dd66fb9ab","frame_index":0,"kind":"data","monotonic_ns":306157187918541,"payload":{"event_type":"price_change","market":"0xda6f0e0e93fc8469e0159a166028d017bddbc162b86f66bac90391379603d962","price_changes":[{"asset_id":"20893381255801015515826997628594359667013752732428989472914000440642900266717","best_ask":"0.42","best_bid":"0.41","hash":"884b24f2c09eb8de7d74fac5c9308f4084bbb32e","price":"0.41","side":"BUY","size":"120.6"},{"asset_id":"39272994714739463168905443499424551362424437245880253267329605556587274644733","best_ask":"0.59","best_bid":"0.58","hash":"3130d9fb8aefb079ea07752a2b2f377b1230759a","price":"0.59","side":"SELL","size":"120.6"}],"timestamp":"1785204173284"},"payload_hash":"d7fdcf486a0eff8727ee77435a555748527e964def638a8fff21a10f24ef698b","raw_frame":"{\"market\":\"0xda6f0e0e93fc8469e0159a166028d017bddbc162b86f66bac90391379603d962\", \"price_changes\":[{\"asset_id\":\"20893381255801015515826997628594359667013752732428989472914000440642900266717\", \"price\":\"0.41\", \"size\":\"120.6\", \"side\":\"BUY\", \"hash\":\"884b24f2c09eb8de7d74fac5c9308f4084bbb32e\", \"best_bid\":\"0.41\", \"best_ask\":\"0.42\"}, {\"asset_id\":\"39272994714739463168905443499424551362424437245880253267329605556587274644733\", \"price\":\"0.59\", \"size\":\"120.6\", \"side\":\"SELL\", \"hash\":\"3130d9fb8aefb079ea07752a2b2f377b1230759a\", \"best_bid\":\"0.58\", \"best_ask\":\"0.59\"}], \"timestamp\":\"1785204173284\", \"event_type\":\"price_change\"}","received_at":"2026-07-28T02:02:54.183146Z","schema_version":"clob-market-ws.price_change.v1","sequence":null,"server_hash":null,"server_timestamp":"1785204173284","session_id":"d2757dd6dad94f3b9fe67e8dbf1adc37","source":"clob_market_ws"},"received_at":"2026-07-28T02:02:54.183146Z","record_id":"07748ad2a5364b4e6821fbc87eb82e736d495b5467163799509b5c814ade0308","schema_fingerprint":"4aa3821a28b0b7c2400bc59aba4bcc0a76e971dadd19610d3ad38c768e124dc7","schema_version":"edge-lab-recorder.raw.v1","sequence":null,"source":"clob_market_ws"}
{"event_at":"2026-07-28T02:02:53.285000Z","event_fingerprint":"c38094ade65fff60ced50161b29db05f58ed75a5575a84f91699e7481948e218","payload":{"connection_id":"5d29200f65794d4d9ab6ef271f045a9b","event_at":"2026-07-28T02:02:53.285000Z","event_type":"price_change","frame_hash":"3afa7cdf6fd851df9d51349a94c07709f610e2fc9439226f7cb427148fc7be31","frame_index":0,"kind":"data","monotonic_ns":306157191166416,"payload":{"event_type":"price_change","market":"0xda6f0e0e93fc8469e0159a166028d017bddbc162b86f66bac90391379603d962","price_changes":[{"asset_id":"20893381255801015515826997628594359667013752732428989472914000440642900266717","best_ask":"0.42","best_bid":"0.41","hash":"9739535bf792263cef9e3ca77d320727e8725f8d","price":"0.33","side":"BUY","size":"147.6"},{"asset_id":"39272994714739463168905443499424551362424437245880253267329605556587274644733","best_ask":"0.59","best_bid":"0.58","hash":"1e17d6d0a84307b979b457bb20b7746bd5c735ca","price":"0.67","side":"SELL","size":"147.6"}],"timestamp":"1785204173285"},"payload_hash":"40686e18320142376189562e088b2aebb97a8bc706aa4599af1afe89e4760b2e","raw_frame":"{\"market\":\"0xda6f0e0e93fc8469e0159a166028d017bddbc162b86f66bac90391379603d962\", \"price_changes\":[{\"asset_id\":\"20893381255801015515826997628594359667013752732428989472914000440642900266717\", \"price\":\"0.33\", \"size\":\"147.6\", \"side\":\"BUY\", \"hash\":\"9739535bf792263cef9e3ca77d320727e8725f8d\", \"best_bid\":\"0.41\", \"best_ask\":\"0.42\"}, {\"asset_id\":\"39272994714739463168905443499424551362424437245880253267329605556587274644733\", \"price\":\"0.67\", \"size\":\"147.6\", \"side\":\"SELL\", \"hash\":\"1e17d6d0a84307b979b457bb20b7746bd5c735ca\", \"best_bid\":\"0.58\", \"best_ask\":\"0.59\"}], \"timestamp\":\"1785204173285\", \"event_type\":\"price_change\"}","received_at":"2026-07-28T02:02:54.186394Z","schema_version":"clob-market-ws.price_change.v1","sequence":null,"server_hash":null,"server_timestamp":"1785204173285","session_id":"d2757dd6dad94f3b9fe67e8dbf1adc37","source":"clob_market_ws"},"received_at":"2026-07-28T02:02:54.186394Z","record_id":"d5e862564f04d1234d58c3d1316c3726fd80c9dbb684463154f570813df5c819","schema_fingerprint":"4aa3821a28b0b7c2400bc59aba4bcc0a76e971dadd19610d3ad38c768e124dc7","schema_version":"edge-lab-recorder.raw.v1","sequence":null,"source":"clob_market_ws"}
{"event_at":"2026-07-28T02:02:53.287000Z","event_fingerprint":"cf8a0024fb5138244d6354d81711c4bf021c4d2d707e5c47dc5d27cae2cb4894","payload":{"connection_id":"5d29200f65794d4d9ab6ef271f045a9b","event_at":"2026-07-28T02:02:53.287000Z","event_type":"price_change","frame_hash":"c6a3f0a8027bca4b688d2bcb847858c40be861894f91975ee84357056eef7700","frame_index":0,"kind":"data","monotonic_ns":306157194739958,"payload":{"event_type":"price_change","market":"0xda6f0e0e93fc8469e0159a166028d017bddbc162b86f66bac90391379603d962","price_changes":[{"asset_id":"39272994714739463168905443499424551362424437245880253267329605556587274644733","best_ask":"0.59","best_bid":"0.58","hash":"eced3ec0e9e9b0ff4660146516d297bd165a87ba","price":"0.55","side":"BUY","size":"119.08"},{"asset_id":"20893381255801015515826997628594359667013752732428989472914000440642900266717","best_ask":"0.42","best_bid":"0.41","hash":"5b5d58aa2308cf6e72e5a5c3c8873c5189dcf8ff","price":"0.45","side":"SELL","size":"119.08"}],"timestamp":"1785204173287"},"payload_hash":"2f0d3b554bdd02394f84e5f6cf0c37f13dd5d73530fa9c75d144467338c286ba","raw_frame":"{\"market\":\"0xda6f0e0e93fc8469e0159a166028d017bddbc162b86f66bac90391379603d962\", \"price_changes\":[{\"asset_id\":\"39272994714739463168905443499424551362424437245880253267329605556587274644733\", \"price\":\"0.55\", \"size\":\"119.08\", \"side\":\"BUY\", \"hash\":\"eced3ec0e9e9b0ff4660146516d297bd165a87ba\", \"best_bid\":\"0.58\", \"best_ask\":\"0.59\"}, {\"asset_id\":\"20893381255801015515826997628594359667013752732428989472914000440642900266717\", \"price\":\"0.45\", \"size\":\"119.08\", \"side\":\"SELL\", \"hash\":\"5b5d58aa2308cf6e72e5a5c3c8873c5189dcf8ff\", \"best_bid\":\"0.41\", \"best_ask\":\"0.42\"}], \"timestamp\":\"1785204173287\", \"event_type\":\"price_change\"}","received_at":"2026-07-28T02:02:54.189970Z","schema_version":"clob-market-ws.price_change.v1","sequence":null,"server_hash":null,"server_timestamp":"1785204173287","session_id":"d2757dd6dad94f3b9fe67e8dbf1adc37","source":"clob_market_ws"},"received_at":"2026-07-28T02:02:54.189970Z","record_id":"91d5dc11aad7c3b129eb447cbe178f02d9a466038b2015d86202d12583efd2d1","schema_fingerprint":"4aa3821a28b0b7c2400bc59aba4bcc0a76e971dadd19610d3ad38c768e124dc7","schema_version":"edge-lab-recorder.raw.v1","sequence":null,"source":"clob_market_ws"}
{"event_at":"2026-07-28T02:02:53.288000Z","event_fingerprint":"e963eb2911d6c7f271c251882d82aabb80f2d7c5f999df0cd82658712acbf2e1","payload":{"connection_id":"5d29200f65794d4d9ab6ef271f045a9b","event_at":"2026-07-28T02:02:53.288000Z","event_type":"price_change","frame_hash":"234b71c67102086f9062c4df91afd2314fc732b12de6382f019cba6a1939b3ff","frame_index":0,"kind":"data","monotonic_ns":306157197960541,"payload":{"event_type":"price_change","market":"0xda6f0e0e93fc8469e0159a166028d017bddbc162b86f66bac90391379603d962","price_changes":[{"asset_id":"20893381255801015515826997628594359667013752732428989472914000440642900266717","best_ask":"0.42","best_bid":"0.41","hash":"222277c7ba1973b377a09e965f3616ec390be314","price":"0.39","side":"BUY","size":"90.2"},{"asset_id":"39272994714739463168905443499424551362424437245880253267329605556587274644733","best_ask":"0.59","best_bid":"0.58","hash":"714e903ffa32fac2ec67e57e6ca19a92a5097226","price":"0.61","side":"SELL","size":"90.2"}],"timestamp":"1785204173288"},"payload_hash":"95b6063de8e4f65dbde277ac70fd1989c05f5c6876acde2804c90efa82dfd9c1","raw_frame":"{\"market\":\"0xda6f0e0e93fc8469e0159a166028d017bddbc162b86f66bac90391379603d962\", \"price_changes\":[{\"asset_id\":\"20893381255801015515826997628594359667013752732428989472914000440642900266717\", \"price\":\"0.39\", \"size\":\"90.2\", \"side\":\"BUY\", \"hash\":\"222277c7ba1973b377a09e965f3616ec390be314\", \"best_bid\":\"0.41\", \"best_ask\":\"0.42\"}, {\"asset_id\":\"39272994714739463168905443499424551362424437245880253267329605556587274644733\", \"price\":\"0.61\", \"size\":\"90.2\", \"side\":\"SELL\", \"hash\":\"714e903ffa32fac2ec67e57e6ca19a92a5097226\", \"best_bid\":\"0.58\", \"best_ask\":\"0.59\"}], \"timestamp\":\"1785204173288\", \"event_type\":\"price_change\"}","received_at":"2026-07-28T02:02:54.193188Z","schema_version":"clob-market-ws.price_change.v1","sequence":null,"server_hash":null,"server_timestamp":"1785204173288","session_id":"d2757dd6dad94f3b9fe67e8dbf1adc37","source":"clob_market_ws"},"received_at":"2026-07-28T02:02:54.193188Z","record_id":"a9035cccbcd17d7539adaaf0433977c7820f4245f334d928e1e58fc0c240f069","schema_fingerprint":"4aa3821a28b0b7c2400bc59aba4bcc0a76e971dadd19610d3ad38c768e124dc7","schema_version":"edge-lab-recorder.raw.v1","sequence":null,"source":"clob_market_ws"}
{"event_at":"2026-07-28T02:02:53.289000Z","event_fingerprint":"e2354e9a035e054230884199a89937e82a68c36e2b3815ce958157b75205d2e6","payload":{"connection_id":"5d29200f65794d4d9ab6ef271f045a9b","event_at":"2026-07-28T02:02:53.289000Z","event_type":"price_change","frame_hash":"e068afd74f01032e297083f6de6991eaaf367983af66d21f2cce5cb20c05bd73","frame_index":0,"kind":"data","monotonic_ns":306157201212375,"payload":{"event_type":"price_change","market":"0xda6f0e0e93fc8469e0159a166028d017bddbc162b86f66bac90391379603d962","price_changes":[{"asset_id":"20893381255801015515826997628594359667013752732428989472914000440642900266717","best_ask":"0.42","best_bid":"0.41","hash":"d5c8ae0dd30e42500e0cf95ce2a0c800f15dabc6","price":"0.41","side":"BUY","size":"80.6"},{"asset_id":"39272994714739463168905443499424551362424437245880253267329605556587274644733","best_ask":"0.59","best_bid":"0.58","hash":"91f82ca095cd48baf1a7f9a3107881e3e4d07e59","price":"0.59","side":"SELL","size":"80.6"}],"timestamp":"1785204173289"},"payload_hash":"9dca33da1feebab214e4043d0f8d47581714cb6337a00eb814c30e5d156c85c8","raw_frame":"{\"market\":\"0xda6f0e0e93fc8469e0159a166028d017bddbc162b86f66bac90391379603d962\", \"price_changes\":[{\"asset_id\":\"20893381255801015515826997628594359667013752732428989472914000440642900266717\", \"price\":\"0.41\", \"size\":\"80.6\", \"side\":\"BUY\", \"hash\":\"d5c8ae0dd30e42500e0cf95ce2a0c800f15dabc6\", \"best_bid\":\"0.41\", \"best_ask\":\"0.42\"}, {\"asset_id\":\"39272994714739463168905443499424551362424437245880253267329605556587274644733\", \"price\":\"0.59\", \"size\":\"80.6\", \"side\":\"SELL\", \"hash\":\"91f82ca095cd48baf1a7f9a3107881e3e4d07e59\", \"best_bid\":\"0.58\", \"best_ask\":\"0.59\"}], \"timestamp\":\"1785204173289\", \"event_type\":\"price_change\"}","received_at":"2026-07-28T02:02:54.196438Z","schema_version":"clob-market-ws.price_change.v1","sequence":null,"server_hash":null,"server_timestamp":"1785204173289","session_id":"d2757dd6dad94f3b9fe67e8dbf1adc37","source":"clob_market_ws"},"received_at":"2026-07-28T02:02:54.196438Z","record_id":"677e0c92de8692f846b5079cf7c8c6be74a94ea45b425e21a7182129af1833fd","schema_fingerprint":"4aa3821a28b0b7c2400bc59aba4bcc0a76e971dadd19610d3ad38c768e124dc7","schema_version":"edge-lab-recorder.raw.v1","sequence":null,"source":"clob_market_ws"}
{"event_at":"2026-07-28T02:02:53.290000Z","event_fingerprint":"5f4f1e98e52182bbd3ce093105db730e25f178f252fcfc38f3586631ef86f1da","payload":{"connection_id":"5d29200f65794d4d9ab6ef271f045a9b","event_at":"2026-07-28T02:02:53.290000Z","event_type":"price_change","frame_hash":"089a13cd79f9d1c81500db0a7009f668a92fd04abdebc7821d7f18162264c424","frame_index":0,"kind":"data","monotonic_ns":306157204268208,"payload":{"event_type":"price_change","market":"0xda6f0e0e93fc8469e0159a166028d017bddbc162b86f66bac90391379603d962","price_changes":[{"asset_id":"20893381255801015515826997628594359667013752732428989472914000440642900266717","best_ask":"0.42","best_bid":"0.41","hash":"c09e383ce42a66ae17d99161cf16e87e5e4d4475","price":"0.38","side":"BUY","size":"88.6"},{"asset_id":"39272994714739463168905443499424551362424437245880253267329605556587274644733","best_ask":"0.59","best_bid":"0.58","hash":"944ddca9dbffa56133f125185e35454c6308c7c6","price":"0.62","side":"SELL","size":"88.6"}],"timestamp":"1785204173290"},"payload_hash":"d8e21a96cfadac9875504c39746126c1005b2ccfeb42b23e6c699d2bb01bb851","raw_frame":"{\"market\":\"0xda6f0e0e93fc8469e0159a166028d017bddbc162b86f66bac90391379603d962\", \"price_changes\":[{\"asset_id\":\"20893381255801015515826997628594359667013752732428989472914000440642900266717\", \"price\":\"0.38\", \"size\":\"88.6\", \"side\":\"BUY\", \"hash\":\"c09e383ce42a66ae17d99161cf16e87e5e4d4475\", \"best_bid\":\"0.41\", \"best_ask\":\"0.42\"}, {\"asset_id\":\"39272994714739463168905443499424551362424437245880253267329605556587274644733\", \"price\":\"0.62\", \"size\":\"88.6\", \"side\":\"SELL\", \"hash\":\"944ddca9dbffa56133f125185e35454c6308c7c6\", \"best_bid\":\"0.58\", \"best_ask\":\"0.59\"}], \"timestamp\":\"1785204173290\", \"event_type\":\"price_change\"}","received_at":"2026-07-28T02:02:54.199494Z","schema_version":"clob-market-ws.price_change.v1","sequence":null,"server_hash":null,"server_timestamp":"1785204173290","session_id":"d2757dd6dad94f3b9fe67e8dbf1adc37","source":"clob_market_ws"},"received_at":"2026-07-28T02:02:54.199494Z","record_id":"8ca2cfbb8f07fbc7044f1f1747ff9662b03c8eabe87e35f87ea5e782a23831a6","schema_fingerprint":"4aa3821a28b0b7c2400bc59aba4bcc0a76e971dadd19610d3ad38c768e124dc7","schema_version":"edge-lab-recorder.raw.v1","sequence":null,"source":"clob_market_ws"}
{"event_at":"2026-07-28T02:02:53.293000Z","event_fingerprint":"28b0e8472292208914fbcbf210e3177a110e2925cbb65a5717af3a37fdcdabf9","payload":{"connection_id":"5d29200f65794d4d9ab6ef271f045a9b","event_at":"2026-07-28T02:02:53.293000Z","event_type":"price_change","frame_hash":"46b01e5c4cec5b6ac9951b0bcbd72648fd65f2af891dd69b03bd5356b62fc83d","frame_index":0,"kind":"data","monotonic_ns":306157207858458,"payload":{"event_type":"price_change","market":"0xda6f0e0e93fc8469e0159a166028d017bddbc162b86f66bac90391379603d962","price_changes":[{"asset_id":"20893381255801015515826997628594359667013752732428989472914000440642900266717","best_ask":"0.42","best_bid":"0.41","hash":"07df6e9824853f6eb36022ad72f734f7884277e7","price":"0.4","side":"BUY","size":"100.2"},{"asset_id":"39272994714739463168905443499424551362424437245880253267329605556587274644733","best_ask":"0.59","best_bid":"0.58","hash":"430a7f6c1407ffe41d1065a8b5e3ec06b3e5321d","price":"0.6","side":"SELL","size":"100.2"}],"timestamp":"1785204173293"},"payload_hash":"b1731566602e3f309b15f04c6784367e9af85ad906764c1960701fbba0071131","raw_frame":"{\"market\":\"0xda6f0e0e93fc8469e0159a166028d017bddbc162b86f66bac90391379603d962\", \"price_changes\":[{\"asset_id\":\"20893381255801015515826997628594359667013752732428989472914000440642900266717\", \"price\":\"0.4\", \"size\":\"100.2\", \"side\":\"BUY\", \"hash\":\"07df6e9824853f6eb36022ad72f734f7884277e7\", \"best_bid\":\"0.41\", \"best_ask\":\"0.42\"}, {\"asset_id\":\"39272994714739463168905443499424551362424437245880253267329605556587274644733\", \"price\":\"0.6\", \"size\":\"100.2\", \"side\":\"SELL\", \"hash\":\"430a7f6c1407ffe41d1065a8b5e3ec06b3e5321d\", \"best_bid\":\"0.58\", \"best_ask\":\"0.59\"}], \"timestamp\":\"1785204173293\", \"event_type\":\"price_change\"}","received_at":"2026-07-28T02:02:54.203085Z","schema_version":"clob-market-ws.price_change.v1","sequence":null,"server_hash":null,"server_timestamp":"1785204173293","session_id":"d2757dd6dad94f3b9fe67e8dbf1adc37","source":"clob_market_ws"},"received_at":"2026-07-28T02:02:54.203085Z","record_id":"6a9338d4621492e3e4920b65307d05baf55d6bda2246baf40ad7630a4ba40d5e","schema_fingerprint":"4aa3821a28b0b7c2400bc59aba4bcc0a76e971dadd19610d3ad38c768e124dc7","schema_version":"edge-lab-recorder.raw.v1","sequence":null,"source":"clob_market_ws"}
{"event_at":"2026-07-28T02:02:53.294000Z","event_fingerprint":"ce4e1cb4884df69e836eb5074fbc670cc689851f2173b6b2166c642ad29c7a5c","payload":{"connection_id":"5d29200f65794d4d9ab6ef271f045a9b","event_at":"2026-07-28T02:02:53.294000Z","event_type":"price_change","frame_hash":"f145eb7e3b4bb1fc976c040fe8d8c10f2e5a57da2c0b96781a7132cd3e113f9e","frame_index":0,"kind":"data","monotonic_ns":306157210887875,"payload":{"event_type":"price_change","market":"0xda6f0e0e93fc8469e0159a166028d017bddbc162b86f66bac90391379603d962","price_changes":[{"asset_id":"20893381255801015515826997628594359667013752732428989472914000440642900266717","best_ask":"0.42","best_bid":"0.41","hash":"1bc25d425ff1ad9d8ae000d11afeb2d4f6c8062a","price":"0.41","side":"BUY","size":"102.6"},{"asset_id":"39272994714739463168905443499424551362424437245880253267329605556587274644733","best_ask":"0.59","best_bid":"0.58","hash":"bf31b73202165d8521213110087bbe85cb9b8731","price":"0.59","side":"SELL","size":"102.6"}],"timestamp":"1785204173294"},"payload_hash":"f623c3ee0b4200164806f1f665a18393842b869ae60352e47cf40aa0b7c6f75f","raw_frame":"{\"market\":\"0xda6f0e0e93fc8469e0159a166028d017bddbc162b86f66bac90391379603d962\", \"price_changes\":[{\"asset_id\":\"20893381255801015515826997628594359667013752732428989472914000440642900266717\", \"price\":\"0.41\", \"size\":\"102.6\", \"side\":\"BUY\", \"hash\":\"1bc25d425ff1ad9d8ae000d11afeb2d4f6c8062a\", \"best_bid\":\"0.41\", \"best_ask\":\"0.42\"}, {\"asset_id\":\"39272994714739463168905443499424551362424437245880253267329605556587274644733\", \"price\":\"0.59\", \"size\":\"102.6\", \"side\":\"SELL\", \"hash\":\"bf31b73202165d8521213110087bbe85cb9b8731\", \"best_bid\":\"0.58\", \"best_ask\":\"0.59\"}], \"timestamp\":\"1785204173294\", \"event_type\":\"price_change\"}","received_at":"2026-07-28T02:02:54.206115Z","schema_version":"clob-market-ws.price_change.v1","sequence":null,"server_hash":null,"server_timestamp":"1785204173294","session_id":"d2757dd6dad94f3b9fe67e8dbf1adc37","source":"clob_market_ws"},"received_at":"2026-07-28T02:02:54.206115Z","record_id":"89090e8269d58b9a4a1ac43b50f0a92eac056a879f5476c78a65864d429f6cf8","schema_fingerprint":"4aa3821a28b0b7c2400bc59aba4bcc0a76e971dadd19610d3ad38c768e124dc7","schema_version":"edge-lab-recorder.raw.v1","sequence":null,"source":"clob_market_ws"}
{"event_at":"2026-07-28T02:02:53.298000Z","event_fingerprint":"4a31ed8cf02567a42584d7ae03aa65966d09b659a3783cade36fbb2d2ebe8a32","payload":{"connection_id":"5d29200f65794d4d9ab6ef271f045a9b","event_at":"2026-07-28T02:02:53.298000Z","event_type":"price_change","frame_hash":"523b0d54f675d696b5e126b2b88bd81969f5c0fa6545987bb266051b3ba412c7","frame_index":0,"kind":"data","monotonic_ns":306157213312708,"payload":{"event_type":"price_change","market":"0xda6f0e0e93fc8469e0159a166028d017bddbc162b86f66bac90391379603d962","price_changes":[{"asset_id":"20893381255801015515826997628594359667013752732428989472914000440642900266717","best_ask":"0.42","best_bid":"0.41","hash":"2db7993ec655f2e5859141e2692947cc896e9827","price":"0.37","side":"BUY","size":"179.05"},{"asset_id":"39272994714739463168905443499424551362424437245880253267329605556587274644733","best_ask":"0.59","best_bid":"0.58","hash":"cc5ce51cdfd86229605d1ec3db5bddec6bb4dca8","price":"0.63","side":"SELL","size":"179.05"}],"timestamp":"1785204173298"},"payload_hash":"b25eeb6996570e4ce4ebee8772c05324baf11027c30f7ff5da9cd61adae843d3","raw_frame":"{\"market\":\"0xda6f0e0e93fc8469e0159a166028d017bddbc162b86f66bac90391379603d962\", \"price_changes\":[{\"asset_id\":\"20893381255801015515826997628594359667013752732428989472914000440642900266717\", \"price\":\"0.37\", \"size\":\"179.05\", \"side\":\"BUY\", \"hash\":\"2db7993ec655f2e5859141e2692947cc896e9827\", \"best_bid\":\"0.41\", \"best_ask\":\"0.42\"}, {\"asset_id\":\"39272994714739463168905443499424551362424437245880253267329605556587274644733\", \"price\":\"0.63\", \"size\":\"179.05\", \"side\":\"SELL\", \"hash\":\"cc5ce51cdfd86229605d1ec3db5bddec6bb4dca8\", \"best_bid\":\"0.58\", \"best_ask\":\"0.59\"}], \"timestamp\":\"1785204173298\", \"event_type\":\"price_change\"}","received_at":"2026-07-28T02:02:54.208540Z","schema_version":"clob-market-ws.price_change.v1","sequence":null,"server_hash":null,"server_timestamp":"1785204173298","session_id":"d2757dd6dad94f3b9fe67e8dbf1adc37","source":"clob_market_ws"},"received_at":"2026-07-28T02:02:54.208540Z","record_id":"215fee38572a7e7f25aef1f883d9d3646caa13abe629e0254213474d008146aa","schema_fingerprint":"4aa3821a28b0b7c2400bc59aba4bcc0a76e971dadd19610d3ad38c768e124dc7","schema_version":"edge-lab-recorder.raw.v1","sequence":null,"source":"clob_market_ws"}
{"event_at":"2026-07-28T02:02:53.299000Z","event_fingerprint":"aa8c9b54013fcbb5fb733b878dd441a50521d50a9c5b81e19efb4d4259f386e0","payload":{"connection_id":"5d29200f65794d4d9ab6ef271f045a9b","event_at":"2026-07-28T02:02:53.299000Z","event_type":"price_change","frame_hash":"51c3219b9dd51b267b259eec51b10daddcb56282bbf2ccf1d6f4832a2c224358","frame_index":0,"kind":"data","monotonic_ns":306157217050541,"payload":{"event_type":"price_change","market":"0xda6f0e0e93fc8469e0159a166028d017bddbc162b86f66bac90391379603d962","price_changes":[{"asset_id":"39272994714739463168905443499424551362424437245880253267329605556587274644733","best_ask":"0.59","best_bid":"0.58","hash":"310c5208fd3380d4eb53aec03e74a8f9fb505d65","price":"0.01","side":"BUY","size":"7853.02"},{"asset_id":"20893381255801015515826997628594359667013752732428989472914000440642900266717","best_ask":"0.42","best_bid":"0.41","hash":"04eaa6f3a7f9405fd002c3a69c5cf40d1bdf124b","price":"0.99","side":"SELL","size":"7853.02"}],"timestamp":"1785204173299"},"payload_hash":"3056e1084eada9e1deaee314bda4995d139fda6f2f1415a718548e3fdff4ef44","raw_frame":"{\"market\":\"0xda6f0e0e93fc8469e0159a166028d017bddbc162b86f66bac90391379603d962\", \"price_changes\":[{\"asset_id\":\"39272994714739463168905443499424551362424437245880253267329605556587274644733\", \"price\":\"0.01\", \"size\":\"7853.02\", \"side\":\"BUY\", \"hash\":\"310c5208fd3380d4eb53aec03e74a8f9fb505d65\", \"best_bid\":\"0.58\", \"best_ask\":\"0.59\"}, {\"asset_id\":\"20893381255801015515826997628594359667013752732428989472914000440642900266717\", \"price\":\"0.99\", \"size\":\"7853.02\", \"side\":\"SELL\", \"hash\":\"04eaa6f3a7f9405fd002c3a69c5cf40d1bdf124b\", \"best_bid\":\"0.41\", \"best_ask\":\"0.42\"}], \"timestamp\":\"1785204173299\", \"event_type\":\"price_change\"}","received_at":"2026-07-28T02:02:54.212276Z","schema_version":"clob-market-ws.price_change.v1","sequence":null,"server_hash":null,"server_timestamp":"1785204173299","session_id":"d2757dd6dad94f3b9fe67e8dbf1adc37","source":"clob_market_ws"},"received_at":"2026-07-28T02:02:54.212276Z","record_id":"0337b7ece64c99b188c0dbb3984d0d0534d96f9ba838735047356477d611e249","schema_fingerprint":"4aa3821a28b0b7c2400bc59aba4bcc0a76e971dadd19610d3ad38c768e124dc7","schema_version":"edge-lab-recorder.raw.v1","sequence":null,"source":"clob_market_ws"}
{"event_at":"2026-07-28T02:02:53.301000Z","event_fingerprint":"919c4595b510e97b847f1378fc53c10daa9a44f344684a87984f079e374c1fa6","payload":{"connection_id":"5d29200f65794d4d9ab6ef271f045a9b","event_at":"2026-07-28T02:02:53.301000Z","event_type":"price_change","frame_hash":"80681dd6db9a8a28abdad6b3930255c13f4bbb5c82471eca1cc036df8a611898","frame_index":0,"kind":"data","monotonic_ns":306157220524750,"payload":{"event_type":"price_change","market":"0xda6f0e0e93fc8469e0159a166028d017bddbc162b86f66bac90391379603d962","price_changes":[{"asset_id":"20893381255801015515826997628594359667013752732428989472914000440642900266717","best_ask":"0.42","best_bid":"0.41","hash":"2f2015bbb1414a780db39c43e8a1813802994481","price":"0.4","side":"BUY","size":"90.2"},{"asset_id":"39272994714739463168905443499424551362424437245880253267329605556587274644733","best_ask":"0.59","best_bid":"0.58","hash":"0101afbfdb7a54daaa75858ce6772b7a7792b93e","price":"0.6","side":"SELL","size":"90.2"}],"timestamp":"1785204173301"},"payload_hash":"a6a88e48a9d9718cc1ccfa80848178ec672d7bcd15d4e5494f68d990e0f481db","raw_frame":"{\"market\":\"0xda6f0e0e93fc8469e0159a166028d017bddbc162b86f66bac90391379603d962\", \"price_changes\":[{\"asset_id\":\"20893381255801015515826997628594359667013752732428989472914000440642900266717\", \"price\":\"0.4\", \"size\":\"90.2\", \"side\":\"BUY\", \"hash\":\"2f2015bbb1414a780db39c43e8a1813802994481\", \"best_bid\":\"0.41\", \"best_ask\":\"0.42\"}, {\"asset_id\":\"39272994714739463168905443499424551362424437245880253267329605556587274644733\", \"price\":\"0.6\", \"size\":\"90.2\", \"side\":\"SELL\", \"hash\":\"0101afbfdb7a54daaa75858ce6772b7a7792b93e\", \"best_bid\":\"0.58\", \"best_ask\":\"0.59\"}], \"timestamp\":\"1785204173301\", \"event_type\":\"price_change\"}","received_at":"2026-07-28T02:02:54.215752Z","schema_version":"clob-market-ws.price_change.v1","sequence":null,"server_hash":null,"server_timestamp":"1785204173301","session_id":"d2757dd6dad94f3b9fe67e8dbf1adc37","source":"clob_market_ws"},"received_at":"2026-07-28T02:02:54.215752Z","record_id":"50c48e80740b3cea0a1c8ee2b3122633ba948785b6fb6dbf24cfbbc34f65660a","schema_fingerprint":"4aa3821a28b0b7c2400bc59aba4bcc0a76e971dadd19610d3ad38c768e124dc7","schema_version":"edge-lab-recorder.raw.v1","sequence":null,"source":"clob_market_ws"}
{"event_at":"2026-07-28T02:02:53.302000Z","event_fingerprint":"663ab8039a010f84f2280f4cef90872f099487403d320140a067a42fe4c47f92","payload":{"connection_id":"5d29200f65794d4d9ab6ef271f045a9b","event_at":"2026-07-28T02:02:53.302000Z","event_type":"price_change","frame_hash":"05755bdaaaef30da9eae755127fb19fe49d7fa02bb693911280ca975e9b72887","frame_index":0,"kind":"data","monotonic_ns":306157223670291,"payload":{"event_type":"price_change","market":"0xda6f0e0e93fc8469e0159a166028d017bddbc162b86f66bac90391379603d962","price_changes":[{"asset_id":"39272994714739463168905443499424551362424437245880253267329605556587274644733","best_ask":"0.59","best_bid":"0.58","hash":"629cebaeb7a56dc1230f6d47496a9cd6998573d0","price":"0.54","side":"BUY","size":"139.06"},{"asset_id":"20893381255801015515826997628594359667013752732428989472914000440642900266717","best_ask":"0.42","best_bid":"0.41","hash":"2ae5aad035a770d0e333936a72e57a48e66885b6","price":"0.46","side":"SELL","size":"139.06"}],"timestamp":"1785204173302"},"payload_hash":"4ff3f263353cd164f7fce3ea10a2b1f772ae213df09d8ae10f6895616778438d","raw_frame":"{\"market\":\"0xda6f0e0e93fc8469e0159a166028d017bddbc162b86f66bac90391379603d962\", \"price_changes\":[{\"asset_id\":\"39272994714739463168905443499424551362424437245880253267329605556587274644733\", \"price\":\"0.54\", \"size\":\"139.06\", \"side\":\"BUY\", \"hash\":\"629cebaeb7a56dc1230f6d47496a9cd6998573d0\", \"best_bid\":\"0.58\", \"best_ask\":\"0.59\"}, {\"asset_id\":\"20893381255801015515826997628594359667013752732428989472914000440642900266717\", \"price\":\"0.46\", \"size\":\"139.06\", \"side\":\"SELL\", \"hash\":\"2ae5aad035a770d0e333936a72e57a48e66885b6\", \"best_bid\":\"0.41\", \"best_ask\":\"0.42\"}], \"timestamp\":\"1785204173302\", \"event_type\":\"price_change\"}","received_at":"2026-07-28T02:02:54.218896Z","schema_version":"clob-market-ws.price_change.v1","sequence":null,"server_hash":null,"server_timestamp":"1785204173302","session_id":"d2757dd6dad94f3b9fe67e8dbf1adc37","source":"clob_market_ws"},"received_at":"2026-07-28T02:02:54.218896Z","record_id":"07382f3b0e3cdf64de84289ff4a45e28ef465fe8c577a61dac1fd4322fa58d98","schema_fingerprint":"4aa3821a28b0b7c2400bc59aba4bcc0a76e971dadd19610d3ad38c768e124dc7","schema_version":"edge-lab-recorder.raw.v1","sequence":null,"source":"clob_market_ws"}
{"event_at":"2026-07-28T02:02:53.304000Z","event_fingerprint":"909c1076ac97c361151744338e448cdfab2907cd4c8b0bf57356df99894b0e71","payload":{"connection_id":"5d29200f65794d4d9ab6ef271f045a9b","event_at":"2026-07-28T02:02:53.304000Z","event_type":"price_change","frame_hash":"ff10763b1cfd01f94995f49c5588e37db6a460484b758753e1936698b6d88804","frame_index":0,"kind":"data","monotonic_ns":306157226796625,"payload":{"event_type":"price_change","market":"0xda6f0e0e93fc8469e0159a166028d017bddbc162b86f66bac90391379603d962","price_changes":[{"asset_id":"20893381255801015515826997628594359667013752732428989472914000440642900266717","best_ask":"0.42","best_bid":"0.41","hash":"d6b1494ee57cb356e490a9778d2d49ee5f6682c7","price":"0.41","side":"BUY","size":"107.6"},{"asset_id":"39272994714739463168905443499424551362424437245880253267329605556587274644733","best_ask":"0.59","best_bid":"0.58","hash":"8fc15533d57da238d99fdb7c34c60b7ccff0bfa9","price":"0.59","side":"SELL","size":"107.6"}],"timestamp":"1785204173304"},"payload_hash":"d609d1c51dd9686caf885c2742892c886a050886a641f4362231b33e64aa69fd","raw_frame":"{\"market\":\"0xda6f0e0e93fc8469e0159a166028d017bddbc162b86f66bac90391379603d962\", \"price_changes\":[{\"asset_id\":\"20893381255801015515826997628594359667013752732428989472914000440642900266717\", \"price\":\"0.41\", \"size\":\"107.6\", \"side\":\"BUY\", \"hash\":\"d6b1494ee57cb356e490a9778d2d49ee5f6682c7\", \"best_bid\":\"0.41\", \"best_ask\":\"0.42\"}, {\"asset_id\":\"39272994714739463168905443499424551362424437245880253267329605556587274644733\", \"price\":\"0.59\", \"size\":\"107.6\", \"side\":\"SELL\", \"hash\":\"8fc15533d57da238d99fdb7c34c60b7ccff0bfa9\", \"best_bid\":\"0.58\", \"best_ask\":\"0.59\"}], \"timestamp\":\"1785204173304\", \"event_type\":\"price_change\"}","received_at":"2026-07-28T02:02:54.222022Z","schema_version":"clob-market-ws.price_change.v1","sequence":null,"server_hash":null,"server_timestamp":"1785204173304","session_id":"d2757dd6dad94f3b9fe67e8dbf1adc37","source":"clob_market_ws"},"received_at":"2026-07-28T02:02:54.222022Z","record_id":"40c896095a35f933210bf285d142275d321670c9b3188d0a2725bf0d04953183","schema_fingerprint":"4aa3821a28b0b7c2400bc59aba4bcc0a76e971dadd19610d3ad38c768e124dc7","schema_version":"edge-lab-recorder.raw.v1","sequence":null,"source":"clob_market_ws"}
{"event_at":"2026-07-28T02:02:53.311000Z","event_fingerprint":"249b5c8e84064ddbe8eb14ac7cedf84937218d5fbbae5a1c8a510730bc9faad9","payload":{"connection_id":"5d29200f65794d4d9ab6ef271f045a9b","event_at":"2026-07-28T02:02:53.311000Z","event_type":"price_change","frame_hash":"7cad0d85cc6521270c819d6fbd8b6fbb4cb66636abcfb0b4abb60fcc59a32f3c","frame_index":0,"kind":"data","monotonic_ns":306157230061333,"payload":{"event_type":"price_change","market":"0xda6f0e0e93fc8469e0159a166028d017bddbc162b86f66bac90391379603d962","price_changes":[{"asset_id":"20893381255801015515826997628594359667013752732428989472914000440642900266717","best_ask":"0.42","best_bid":"0.41","hash":"135ac1452a05d8dc738c8b4798e19ea78e79b812","price":"0.36","side":"BUY","size":"147.55"},{"asset_id":"39272994714739463168905443499424551362424437245880253267329605556587274644733","best_ask":"0.59","best_bid":"0.58","hash":"783a2d28f9d0053c299091569e3c937357b4c026","price":"0.64","side":"SELL","size":"147.55"}],"timestamp":"1785204173311"},"payload_hash":"97650c8224df542ff98a667ebb05fbc44d0f76496b7a8f2c6d8d2901ab64a75d","raw_frame":"{\"market\":\"0xda6f0e0e93fc8469e0159a166028d017bddbc162b86f66bac90391379603d962\", \"price_changes\":[{\"asset_id\":\"20893381255801015515826997628594359667013752732428989472914000440642900266717\", \"price\":\"0.36\", \"size\":\"147.55\", \"side\":\"BUY\", \"hash\":\"135ac1452a05d8dc738c8b4798e19ea78e79b812\", \"best_bid\":\"0.41\", \"best_ask\":\"0.42\"}, {\"asset_id\":\"39272994714739463168905443499424551362424437245880253267329605556587274644733\", \"price\":\"0.64\", \"size\":\"147.55\", \"side\":\"SELL\", \"hash\":\"783a2d28f9d0053c299091569e3c937357b4c026\", \"best_bid\":\"0.58\", \"best_ask\":\"0.59\"}], \"timestamp\":\"1785204173311\", \"event_type\":\"price_change\"}","received_at":"2026-07-28T02:02:54.225286Z","schema_version":"clob-market-ws.price_change.v1","sequence":null,"server_hash":null,"server_timestamp":"1785204173311","session_id":"d2757dd6dad94f3b9fe67e8dbf1adc37","source":"clob_market_ws"},"received_at":"2026-07-28T02:02:54.225286Z","record_id":"1352889c37bf1554995bd77a41fcf208f068cc538c85dc55fa190143fbc7af4b","schema_fingerprint":"4aa3821a28b0b7c2400bc59aba4bcc0a76e971dadd19610d3ad38c768e124dc7","schema_version":"edge-lab-recorder.raw.v1","sequence":null,"source":"clob_market_ws"}
{"event_at":"2026-07-28T02:02:53.311000Z","event_fingerprint":"56b7da09cbd0ff3886b8255baedf97a7528fe50112bb33651c18fea9f4ac47fa","payload":{"connection_id":"5d29200f65794d4d9ab6ef271f045a9b","event_at":"2026-07-28T02:02:53.311000Z","event_type":"price_change","frame_hash":"019dc9ec57ef7efe4954aef8394f989e9c1422a5ad43c809a98922025d733ebb","frame_index":0,"kind":"data","monotonic_ns":306157233356625,"payload":{"event_type":"price_change","market":"0xda6f0e0e93fc8469e0159a166028d017bddbc162b86f66bac90391379603d962","price_changes":[{"asset_id":"39272994714739463168905443499424551362424437245880253267329605556587274644733","best_ask":"0.59","best_bid":"0.58","hash":"b24572120657dee209bea59d23180dce10360bb7","price":"0.59","side":"SELL","size":"113.6"},{"asset_id":"20893381255801015515826997628594359667013752732428989472914000440642900266717","best_ask":"0.42","best_bid":"0.41","hash":"fefec3508338cce7274500e428eb1a03f870eee9","price":"0.41","side":"BUY","size":"113.6"}],"timestamp":"1785204173311"},"payload_hash":"7270cc178ab9568b6aa09d4aca96c23294f5c31fad52a2b6126f90523f06cb6d","raw_frame":"{\"market\":\"0xda6f0e0e93fc8469e0159a166028d017bddbc162b86f66bac90391379603d962\", \"price_changes\":[{\"asset_id\":\"39272994714739463168905443499424551362424437245880253267329605556587274644733\", \"price\":\"0.59\", \"size\":\"113.6\", \"side\":\"SELL\", \"hash\":\"b24572120657dee209bea59d23180dce10360bb7\", \"best_bid\":\"0.58\", \"best_ask\":\"0.59\"}, {\"asset_id\":\"20893381255801015515826997628594359667013752732428989472914000440642900266717\", \"price\":\"0.41\", \"size\":\"113.6\", \"side\":\"BUY\", \"hash\":\"fefec3508338cce7274500e428eb1a03f870eee9\", \"best_bid\":\"0.41\", \"best_ask\":\"0.42\"}], \"timestamp\":\"1785204173311\", \"event_type\":\"price_change\"}","received_at":"2026-07-28T02:02:54.228584Z","schema_version":"clob-market-ws.price_change.v1","sequence":null,"server_hash":null,"server_timestamp":"1785204173311","session_id":"d2757dd6dad94f3b9fe67e8dbf1adc37","source":"clob_market_ws"},"received_at":"2026-07-28T02:02:54.228584Z","record_id":"03a6bbd81d199358c88633d3fc6db1de4ff72534b6fea6917f499de8bcc18311","schema_fingerprint":"4aa3821a28b0b7c2400bc59aba4bcc0a76e971dadd19610d3ad38c768e124dc7","schema_version":"edge-lab-recorder.raw.v1","sequence":null,"source":"clob_market_ws"}
{"event_at":"2026-07-28T02:02:53.312000Z","event_fingerprint":"2b3d4e9e351e05599358f63d6903485a00cf122ffd3e39b61f59ec46e405f1e9","payload":{"connection_id":"5d29200f65794d4d9ab6ef271f045a9b","event_at":"2026-07-28T02:02:53.312000Z","event_type":"price_change","frame_hash":"28dbfb40b1962145655babc4ae496264f67a9c809bd3210de794b932a69e8af1","frame_index":0,"kind":"data","monotonic_ns":306157235764541,"payload":{"event_type":"price_change","market":"0xda6f0e0e93fc8469e0159a166028d017bddbc162b86f66bac90391379603d962","price_changes":[{"asset_id":"20893381255801015515826997628594359667013752732428989472914000440642900266717","best_ask":"0.42","best_bid":"0.41","hash":"84f17da99aa881cca6b3213f04f3c0cc5e5be682","price":"0.41","side":"BUY","size":"89.6"},{"asset_id":"39272994714739463168905443499424551362424437245880253267329605556587274644733","best_ask":"0.59","best_bid":"0.58","hash":"9a38bd36ff83870fdbba04c9b7a70a276e4b6736","price":"0.59","side":"SELL","size":"89.6"}],"timestamp":"1785204173312"},"payload_hash":"f0ac6890d96a6d4d1ea58ccafcaf471d5a8f7e831367539b1076b5b0738ff99e","raw_frame":"{\"market\":\"0xda6f0e0e93fc8469e0159a166028d017bddbc162b86f66bac90391379603d962\", \"price_changes\":[{\"asset_id\":\"20893381255801015515826997628594359667013752732428989472914000440642900266717\", \"price\":\"0.41\", \"size\":\"89.6\", \"side\":\"BUY\", \"hash\":\"84f17da99aa881cca6b3213f04f3c0cc5e5be682\", \"best_bid\":\"0.41\", \"best_ask\":\"0.42\"}, {\"asset_id\":\"39272994714739463168905443499424551362424437245880253267329605556587274644733\", \"price\":\"0.59\", \"size\":\"89.6\", \"side\":\"SELL\", \"hash\":\"9a38bd36ff83870fdbba04c9b7a70a276e4b6736\", \"best_bid\":\"0.58\", \"best_ask\":\"0.59\"}], \"timestamp\":\"1785204173312\", \"event_type\":\"price_change\"}","received_at":"2026-07-28T02:02:54.230992Z","schema_version":"clob-market-ws.price_change.v1","sequence":null,"server_hash":null,"server_timestamp":"1785204173312","session_id":"d2757dd6dad94f3b9fe67e8dbf1adc37","source":"clob_market_ws"},"received_at":"2026-07-28T02:02:54.230992Z","record_id":"d76ddb0702c7e93c3aab636dc0531f71fbeac9649abcccbd5790ace08d419d3e","schema_fingerprint":"4aa3821a28b0b7c2400bc59aba4bcc0a76e971dadd19610d3ad38c768e124dc7","schema_version":"edge-lab-recorder.raw.v1","sequence":null,"source":"clob_market_ws"}
{"event_at":"2026-07-28T02:02:53.313000Z","event_fingerprint":"1f6bdd52c879a958017e3a3ca18718a10fe2ef867adf913a5f6d7d4ea1f4f7be","payload":{"connection_id":"5d29200f65794d4d9ab6ef271f045a9b","event_at":"2026-07-28T02:02:53.313000Z","event_type":"price_change","frame_hash":"e2b2a85327889923b93e8b427a3047f635090ac5eb5b3d8102d3a55f7cf02232","frame_index":0,"kind":"data","monotonic_ns":306157238681750,"payload":{"event_type":"price_change","market":"0xda6f0e0e93fc8469e0159a166028d017bddbc162b86f66bac90391379603d962","price_changes":[{"asset_id":"39272994714739463168905443499424551362424437245880253267329605556587274644733","best_ask":"0.59","best_bid":"0.58","hash":"2200954c754518499880533649a197f2394cfa59","price":"0.43","side":"BUY","size":"321.53"},{"asset_id":"20893381255801015515826997628594359667013752732428989472914000440642900266717","best_ask":"0.42","best_bid":"0.41","hash":"8baf95af144d14e706b06e4054118a0e6ddf4e7a","price":"0.57","side":"SELL","size":"321.53"}],"timestamp":"1785204173313"},"payload_hash":"94c5c5050f4c6b46a8b7e958e8a32313743ff23ccd96ef7a8fcfc431b3fa9f00","raw_frame":"{\"market\":\"0xda6f0e0e93fc8469e0159a166028d017bddbc162b86f66bac90391379603d962\", \"price_changes\":[{\"asset_id\":\"39272994714739463168905443499424551362424437245880253267329605556587274644733\", \"price\":\"0.43\", \"size\":\"321.53\", \"side\":\"BUY\", \"hash\":\"2200954c754518499880533649a197f2394cfa59\", \"best_bid\":\"0.58\", \"best_ask\":\"0.59\"}, {\"asset_id\":\"20893381255801015515826997628594359667013752732428989472914000440642900266717\", \"price\":\"0.57\", \"size\":\"321.53\", \"side\":\"SELL\", \"hash\":\"8baf95af144d14e706b06e4054118a0e6ddf4e7a\", \"best_bid\":\"0.41\", \"best_ask\":\"0.42\"}], \"timestamp\":\"1785204173313\", \"event_type\":\"price_change\"}","received_at":"2026-07-28T02:02:54.233907Z","schema_version":"clob-market-ws.price_change.v1","sequence":null,"server_hash":null,"server_timestamp":"1785204173313","session_id":"d2757dd6dad94f3b9fe67e8dbf1adc37","source":"clob_market_ws"},"received_at":"2026-07-28T02:02:54.233907Z","record_id":"3cc5b9b9cbc49b1b0f0d110d3b5e27146381fc011e830075ad0e506ebb04a576","schema_fingerprint":"4aa3821a28b0b7c2400bc59aba4bcc0a76e971dadd19610d3ad38c768e124dc7","schema_version":"edge-lab-recorder.raw.v1","sequence":null,"source":"clob_market_ws"}
{"event_at":"2026-07-28T02:02:53.313000Z","event_fingerprint":"e1e5db66e27871c5176771345d74df94c11c4d5867fd38c76c395aee55491d64","payload":{"connection_id":"5d29200f65794d4d9ab6ef271f045a9b","event_at":"2026-07-28T02:02:53.313000Z","event_type":"price_change","frame_hash":"1ae8760424705d023bd511a006d9728e0ebad3f06556d5d7c9c6163ae4cc45b1","frame_index":0,"kind":"data","monotonic_ns":306157241772708,"payload":{"event_type":"price_change","market":"0xda6f0e0e93fc8469e0159a166028d017bddbc162b86f66bac90391379603d962","price_changes":[{"asset_id":"39272994714739463168905443499424551362424437245880253267329605556587274644733","best_ask":"0.59","best_bid":"0.58","hash":"9c890df52643c58c69e496e0975145f7fa817644","price":"0.57","side":"BUY","size":"50"},{"asset_id":"20893381255801015515826997628594359667013752732428989472914000440642900266717","best_ask":"0.42","best_bid":"0.41","hash":"a4c825d5f7421238ff7d241b87ade59cd0e96b2b","price":"0.43","side":"SELL","size":"50"}],"timestamp":"1785204173313"},"payload_hash":"ba2e5f1b6f387dcd6e616c066d1d6ac5e76f87534202e1209c071cde1073c4b1","raw_frame":"{\"market\":\"0xda6f0e0e93fc8469e0159a166028d017bddbc162b86f66bac90391379603d962\", \"price_changes\":[{\"asset_id\":\"39272994714739463168905443499424551362424437245880253267329605556587274644733\", \"price\":\"0.57\", \"size\":\"50\", \"side\":\"BUY\", \"hash\":\"9c890df52643c58c69e496e0975145f7fa817644\", \"best_bid\":\"0.58\", \"best_ask\":\"0.59\"}, {\"asset_id\":\"20893381255801015515826997628594359667013752732428989472914000440642900266717\", \"price\":\"0.43\", \"size\":\"50\", \"side\":\"SELL\", \"hash\":\"a4c825d5f7421238ff7d241b87ade59cd0e96b2b\", \"best_bid\":\"0.41\", \"best_ask\":\"0.42\"}], \"timestamp\":\"1785204173313\", \"event_type\":\"price_change\"}","received_at":"2026-07-28T02:02:54.236999Z","schema_version":"clob-market-ws.price_change.v1","sequence":null,"server_hash":null,"server_timestamp":"1785204173313","session_id":"d2757dd6dad94f3b9fe67e8dbf1adc37","source":"clob_market_ws"},"received_at":"2026-07-28T02:02:54.236999Z","record_id":"8e190c82ee2254c88f295c4cbc916f3a64c6c2a42615b2f0a6d83d4e1ff7c258","schema_fingerprint":"4aa3821a28b0b7c2400bc59aba4bcc0a76e971dadd19610d3ad38c768e124dc7","schema_version":"edge-lab-recorder.raw.v1","sequence":null,"source":"clob_market_ws"}
{"event_at":"2026-07-28T02:02:53.314000Z","event_fingerprint":"f2316ae3a160860637e262bd26a7bbfdbfa258c5eeb797d9ca45e9cadf56725c","payload":{"connection_id":"5d29200f65794d4d9ab6ef271f045a9b","event_at":"2026-07-28T02:02:53.314000Z","event_type":"price_change","frame_hash":"19c1972c05eefa5b04b740f629c0d30934e04d72eb618dd5bb459f8b1f4645fa","frame_index":0,"kind":"data","monotonic_ns":306157244866750,"payload":{"event_type":"price_change","market":"0xda6f0e0e93fc8469e0159a166028d017bddbc162b86f66bac90391379603d962","price_changes":[{"asset_id":"20893381255801015515826997628594359667013752732428989472914000440642900266717","best_ask":"0.42","best_bid":"0.41","hash":"97fe642a2a885b99433a0429008b51369ca70cba","price":"0.41","side":"BUY","size":"104.6"},{"asset_id":"39272994714739463168905443499424551362424437245880253267329605556587274644733","best_ask":"0.59","best_bid":"0.58","hash":"5fab4d707fd0037e48b8581c69fc5e54799e58ff","price":"0.59","side":"SELL","size":"104.6"}],"timestamp":"1785204173314"},"payload_hash":"6e1a327c79c6d7920853b64290b4744fc70c1c0749a39c0a030d290103f0cf9f","raw_frame":"{\"market\":\"0xda6f0e0e93fc8469e0159a166028d017bddbc162b86f66bac90391379603d962\", \"price_changes\":[{\"asset_id\":\"20893381255801015515826997628594359667013752732428989472914000440642900266717\", \"price\":\"0.41\", \"size\":\"104.6\", \"side\":\"BUY\", \"hash\":\"97fe642a2a885b99433a0429008b51369ca70cba\", \"best_bid\":\"0.41\", \"best_ask\":\"0.42\"}, {\"asset_id\":\"39272994714739463168905443499424551362424437245880253267329605556587274644733\", \"price\":\"0.59\", \"size\":\"104.6\", \"side\":\"SELL\", \"hash\":\"5fab4d707fd0037e48b8581c69fc5e54799e58ff\", \"best_bid\":\"0.58\", \"best_ask\":\"0.59\"}], \"timestamp\":\"1785204173314\", \"event_type\":\"price_change\"}","received_at":"2026-07-28T02:02:54.240091Z","schema_version":"clob-market-ws.price_change.v1","sequence":null,"server_hash":null,"server_timestamp":"1785204173314","session_id":"d2757dd6dad94f3b9fe67e8dbf1adc37","source":"clob_market_ws"},"received_at":"2026-07-28T02:02:54.240091Z","record_id":"56f65155acb41a2bc8fadf338c5344be2cde13eb12e121205d0843d70c458a89","schema_fingerprint":"4aa3821a28b0b7c2400bc59aba4bcc0a76e971dadd19610d3ad38c768e124dc7","schema_version":"edge-lab-recorder.raw.v1","sequence":null,"source":"clob_market_ws"}
{"event_at":"2026-07-28T02:02:53.315000Z","event_fingerprint":"6df131c0528742d31f6e8a773ec36d1d71be0c9603c4fc2b1ae986c3c39f3e37","payload":{"connection_id":"5d29200f65794d4d9ab6ef271f045a9b","event_at":"2026-07-28T02:02:53.315000Z","event_type":"price_change","frame_hash":"f43fdb6b82ee246092cdde717949737d6cca7bf4c5beae254c9be6fe96c109e6","frame_index":0,"kind":"data","monotonic_ns":306157248400541,"payload":{"event_type":"price_change","market":"0xda6f0e0e93fc8469e0159a166028d017bddbc162b86f66bac90391379603d962","price_changes":[{"asset_id":"39272994714739463168905443499424551362424437245880253267329605556587274644733","best_ask":"0.59","best_bid":"0.58","hash":"eeabcb7f5070d6c1d90a74d732473ef5695d8ec5","price":"0.48","side":"BUY","size":"149.55"},{"asset_id":"20893381255801015515826997628594359667013752732428989472914000440642900266717","best_ask":"0.42","best_bid":"0.41","hash":"f434161e5a3a5fe7698dd22bcda7bbb6666a4766","price":"0.52","side":"SELL","size":"149.55"}],"timestamp":"1785204173315"},"payload_hash":"93928a5da6996dcfcddc684c4467cb0ee9d6ea34b2932813b088e55d945dee99","raw_frame":"{\"market\":\"0xda6f0e0e93fc8469e0159a166028d017bddbc162b86f66bac90391379603d962\", \"price_changes\":[{\"asset_id\":\"39272994714739463168905443499424551362424437245880253267329605556587274644733\", \"price\":\"0.48\", \"size\":\"149.55\", \"side\":\"BUY\", \"hash\":\"eeabcb7f5070d6c1d90a74d732473ef5695d8ec5\", \"best_bid\":\"0.58\", \"best_ask\":\"0.59\"}, {\"asset_id\":\"20893381255801015515826997628594359667013752732428989472914000440642900266717\", \"price\":\"0.52\", \"size\":\"149.55\", \"side\":\"SELL\", \"hash\":\"f434161e5a3a5fe7698dd22bcda7bbb6666a4766\", \"best_bid\":\"0.41\", \"best_ask\":\"0.42\"}], \"timestamp\":\"1785204173315\", \"event_type\":\"price_change\"}","received_at":"2026-07-28T02:02:54.243629Z","schema_version":"clob-market-ws.price_change.v1","sequence":null,"server_hash":null,"server_timestamp":"1785204173315","session_id":"d2757dd6dad94f3b9fe67e8dbf1adc37","source":"clob_market_ws"},"received_at":"2026-07-28T02:02:54.243629Z","record_id":"e9b22b1af62f89e7e03d96b8ac9a94ab3514b5d382a8094827e18408d750f6ea","schema_fingerprint":"4aa3821a28b0b7c2400bc59aba4bcc0a76e971dadd19610d3ad38c768e124dc7","schema_version":"edge-lab-recorder.raw.v1","sequence":null,"source":"clob_market_ws"}
{"event_at":"2026-07-28T02:02:53.319000Z","event_fingerprint":"44c22592c6988df59a5ffbb716b9a693b2a4a7d335a8ddf80af4fcef955d8e67","payload":{"connection_id":"5d29200f65794d4d9ab6ef271f045a9b","event_at":"2026-07-28T02:02:53.319000Z","event_type":"price_change","frame_hash":"c53c73bb5dd12ff248235b8bb6259e0fbfc478ccc3e2740310b566809d3815ff","frame_index":0,"kind":"data","monotonic_ns":306157250309666,"payload":{"event_type":"price_change","market":"0xda6f0e0e93fc8469e0159a166028d017bddbc162b86f66bac90391379603d962","price_changes":[{"asset_id":"39272994714739463168905443499424551362424437245880253267329605556587274644733","best_ask":"0.59","best_bid":"0.58","hash":"2cff1dd97aaada8ec1b6dae18aff72d83d8406f9","price":"0.58","side":"BUY","size":"26"},{"asset_id":"20893381255801015515826997628594359667013752732428989472914000440642900266717","best_ask":"0.42","best_bid":"0.41","hash":"ffc80e385975e2677919933e7f9f7adc79c4d44a","price":"0.42","side":"SELL","size":"26"}],"timestamp":"1785204173319"},"payload_hash":"4b468924352459dd4c0424b83597e1a66939c1c405fb3eb72262e58e833222c3","raw_frame":"{\"market\":\"0xda6f0e0e93fc8469e0159a166028d017bddbc162b86f66bac90391379603d962\", \"price_changes\":[{\"asset_id\":\"39272994714739463168905443499424551362424437245880253267329605556587274644733\", \"price\":\"0.58\", \"size\":\"26\", \"side\":\"BUY\", \"hash\":\"2cff1dd97aaada8ec1b6dae18aff72d83d8406f9\", \"best_bid\":\"0.58\", \"best_ask\":\"0.59\"}, {\"asset_id\":\"20893381255801015515826997628594359667013752732428989472914000440642900266717\", \"price\":\"0.42\", \"size\":\"26\", \"side\":\"SELL\", \"hash\":\"ffc80e385975e2677919933e7f9f7adc79c4d44a\", \"best_bid\":\"0.41\", \"best_ask\":\"0.42\"}], \"timestamp\":\"1785204173319\", \"event_type\":\"price_change\"}","received_at":"2026-07-28T02:02:54.245540Z","schema_version":"clob-market-ws.price_change.v1","sequence":null,"server_hash":null,"server_timestamp":"1785204173319","session_id":"d2757dd6dad94f3b9fe67e8dbf1adc37","source":"clob_market_ws"},"received_at":"2026-07-28T02:02:54.245540Z","record_id":"6e1db8c2f44a092b28e8a53f1b56e0305504baf93b31f4a5fa3e8c36d893a789","schema_fingerprint":"4aa3821a28b0b7c2400bc59aba4bcc0a76e971dadd19610d3ad38c768e124dc7","schema_version":"edge-lab-recorder.raw.v1","sequence":null,"source":"clob_market_ws"}
{"event_at":"2026-07-28T02:02:53.319000Z","event_fingerprint":"ed9871a606a2e510322d61ee32594f66b08baa316221a1922485c76d6ab81842","payload":{"connection_id":"5d29200f65794d4d9ab6ef271f045a9b","event_at":"2026-07-28T02:02:53.319000Z","event_type":"price_change","frame_hash":"9e9e696acceb37fbc169e4a0d465f38adeab19a6b0c23930abd0d85996795766","frame_index":0,"kind":"data","monotonic_ns":306157253610666,"payload":{"event_type":"price_change","market":"0xda6f0e0e93fc8469e0159a166028d017bddbc162b86f66bac90391379603d962","price_changes":[{"asset_id":"20893381255801015515826997628594359667013752732428989472914000440642900266717","best_ask":"0.42","best_bid":"0.41","hash":"7eb120c26a1f86dca1419962b05d069cf6fa5160","price":"0.41","side":"BUY","size":"117.2"},{"asset_id":"39272994714739463168905443499424551362424437245880253267329605556587274644733","best_ask":"0.59","best_bid":"0.58","hash":"58fcf4e75398c1740a75a59e49b036aa778d9bef","price":"0.59","side":"SELL","size":"117.2"}],"timestamp":"1785204173319"},"payload_hash":"e934edb80e379f19a86b951ff57919a9a80419e3cbad86be965a4e65df48a957","raw_frame":"{\"market\":\"0xda6f0e0e93fc8469e0159a166028d017bddbc162b86f66bac90391379603d962\", \"price_changes\":[{\"asset_id\":\"20893381255801015515826997628594359667013752732428989472914000440642900266717\", \"price\":\"0.41\", \"size\":\"117.2\", \"side\":\"BUY\", \"hash\":\"7eb120c26a1f86dca1419962b05d069cf6fa5160\", \"best_bid\":\"0.41\", \"best_ask\":\"0.42\"}, {\"asset_id\":\"39272994714739463168905443499424551362424437245880253267329605556587274644733\", \"price\":\"0.59\", \"size\":\"117.2\", \"side\":\"SELL\", \"hash\":\"58fcf4e75398c1740a75a59e49b036aa778d9bef\", \"best_bid\":\"0.58\", \"best_ask\":\"0.59\"}], \"timestamp\":\"1785204173319\", \"event_type\":\"price_change\"}","received_at":"2026-07-28T02:02:54.248837Z","schema_version":"clob-market-ws.price_change.v1","sequence":null,"server_hash":null,"server_timestamp":"1785204173319","session_id":"d2757dd6dad94f3b9fe67e8dbf1adc37","source":"clob_market_ws"},"received_at":"2026-07-28T02:02:54.248837Z","record_id":"7918dd7299ecb49a8e1a422cbcbb02c61533b1d0057f89ad915e0e247add5e1d","schema_fingerprint":"4aa3821a28b0b7c2400bc59aba4bcc0a76e971dadd19610d3ad38c768e124dc7","schema_version":"edge-lab-recorder.raw.v1","sequence":null,"source":"clob_market_ws"}
{"event_at":"2026-07-28T02:02:53.320000Z","event_fingerprint":"3e59c7dd20853c6f37b78520c84bfb91422d8fab7e2a69977e3a5594c5ae24ec","payload":{"connection_id":"5d29200f65794d4d9ab6ef271f045a9b","event_at":"2026-07-28T02:02:53.320000Z","event_type":"price_change","frame_hash":"8f7e1f7d72a77d166fab41505ff5736f4fd73c1594109c116d971e179573a789","frame_index":0,"kind":"data","monotonic_ns":306157256219041,"payload":{"event_type":"price_change","market":"0xda6f0e0e93fc8469e0159a166028d017bddbc162b86f66bac90391379603d962","price_changes":[{"asset_id":"39272994714739463168905443499424551362424437245880253267329605556587274644733","best_ask":"0.59","best_bid":"0.58","hash":"7377e3f99463a1491154c0bf74062c3f4702701c","price":"0.57","side":"BUY","size":"35"},{"asset_id":"20893381255801015515826997628594359667013752732428989472914000440642900266717","best_ask":"0.42","best_bid":"0.41","hash":"7954c59691d0e8d3e6f253cb6913f4f078b9e150","price":"0.43","side":"SELL","size":"35"}],"timestamp":"1785204173320"},"payload_hash":"7d824651b63caaf3777fdb0fc8392f50d30b8254fdadc6bf7e0ca59ee754c585","raw_frame":"{\"market\":\"0xda6f0e0e93fc8469e0159a166028d017bddbc162b86f66bac90391379603d962\", \"price_changes\":[{\"asset_id\":\"39272994714739463168905443499424551362424437245880253267329605556587274644733\", \"price\":\"0.57\", \"size\":\"35\", \"side\":\"BUY\", \"hash\":\"7377e3f99463a1491154c0bf74062c3f4702701c\", \"best_bid\":\"0.58\", \"best_ask\":\"0.59\"}, {\"asset_id\":\"20893381255801015515826997628594359667013752732428989472914000440642900266717\", \"price\":\"0.43\", \"size\":\"35\", \"side\":\"SELL\", \"hash\":\"7954c59691d0e8d3e6f253cb6913f4f078b9e150\", \"best_bid\":\"0.41\", \"best_ask\":\"0.42\"}], \"timestamp\":\"1785204173320\", \"event_type\":\"price_change\"}","received_at":"2026-07-28T02:02:54.251448Z","schema_version":"clob-market-ws.price_change.v1","sequence":null,"server_hash":null,"server_timestamp":"1785204173320","session_id":"d2757dd6dad94f3b9fe67e8dbf1adc37","source":"clob_market_ws"},"received_at":"2026-07-28T02:02:54.251448Z","record_id":"502eb72df3f7de538d66af3e420a99253352aa3257e0573f5c106834a992e138","schema_fingerprint":"4aa3821a28b0b7c2400bc59aba4bcc0a76e971dadd19610d3ad38c768e124dc7","schema_version":"edge-lab-recorder.raw.v1","sequence":null,"source":"clob_market_ws"}
{"event_at":"2026-07-28T02:02:53.320000Z","event_fingerprint":"1e21b04c4bc3bf3b4471a476993241ac6cc3ab23fbee74e9041de9d12038243c","payload":{"connection_id":"5d29200f65794d4d9ab6ef271f045a9b","event_at":"2026-07-28T02:02:53.320000Z","event_type":"price_change","frame_hash":"2894be76dfe6edf6d2220ff9b8e0bf38d49a15f5844b36dad9e0dcd666f0aed9","frame_index":0,"kind":"data","monotonic_ns":306157259297041,"payload":{"event_type":"price_change","market":"0xda6f0e0e93fc8469e0159a166028d017bddbc162b86f66bac90391379603d962","price_changes":[{"asset_id":"39272994714739463168905443499424551362424437245880253267329605556587274644733","best_ask":"0.59","best_bid":"0.58","hash":"523aa6f930cf7cbd63a4b2861ce3426961cdcb7c","price":"0.58","side":"BUY","size":"11"},{"asset_id":"20893381255801015515826997628594359667013752732428989472914000440642900266717","best_ask":"0.42","best_bid":"0.41","hash":"0dfc8adcd98ed0b625f6a7bfd9cbb53809d42317","price":"0.42","side":"SELL","size":"11"}],"timestamp":"1785204173320"},"payload_hash":"b09c35e18b692dc7e97fa3596f9e312bbb30e21fdd95c6b301eb245716ed863d","raw_frame":"{\"market\":\"0xda6f0e0e93fc8469e0159a166028d017bddbc162b86f66bac90391379603d962\", \"price_changes\":[{\"asset_id\":\"39272994714739463168905443499424551362424437245880253267329605556587274644733\", \"price\":\"0.58\", \"size\":\"11\", \"side\":\"BUY\", \"hash\":\"523aa6f930cf7cbd63a4b2861ce3426961cdcb7c\", \"best_bid\":\"0.58\", \"best_ask\":\"0.59\"}, {\"asset_id\":\"20893381255801015515826997628594359667013752732428989472914000440642900266717\", \"price\":\"0.42\", \"size\":\"11\", \"side\":\"SELL\", \"hash\":\"0dfc8adcd98ed0b625f6a7bfd9cbb53809d42317\", \"best_bid\":\"0.41\", \"best_ask\":\"0.42\"}], \"timestamp\":\"1785204173320\", \"event_type\":\"price_change\"}","received_at":"2026-07-28T02:02:54.254523Z","schema_version":"clob-market-ws.price_change.v1","sequence":null,"server_hash":null,"server_timestamp":"1785204173320","session_id":"d2757dd6dad94f3b9fe67e8dbf1adc37","source":"clob_market_ws"},"received_at":"2026-07-28T02:02:54.254523Z","record_id":"2f14293a4131b83729ac21683f1e2a5975d098d2cf6640bfd1427cb26563a094","schema_fingerprint":"4aa3821a28b0b7c2400bc59aba4bcc0a76e971dadd19610d3ad38c768e124dc7","schema_version":"edge-lab-recorder.raw.v1","sequence":null,"source":"clob_market_ws"}
{"event_at":"2026-07-28T02:02:53.329000Z","event_fingerprint":"506c5e563df166792701b6ee37b85ff38f0a15f950c1b6d1db948784c9229da4","payload":{"connection_id":"5d29200f65794d4d9ab6ef271f045a9b","event_at":"2026-07-28T02:02:53.329000Z","event_type":"price_change","frame_hash":"8630afb998bc9abee9b8fcc74182f59f10c4595dca99db68b054672bf98761ef","frame_index":0,"kind":"data","monotonic_ns":306157262290833,"payload":{"event_type":"price_change","market":"0xda6f0e0e93fc8469e0159a166028d017bddbc162b86f66bac90391379603d962","price_changes":[{"asset_id":"39272994714739463168905443499424551362424437245880253267329605556587274644733","best_ask":"0.59","best_bid":"0.58","hash":"039a1500cd5e803873f519c58283ce2ad57a8baa","price":"0.53","side":"BUY","size":"103"},{"asset_id":"20893381255801015515826997628594359667013752732428989472914000440642900266717","best_ask":"0.42","best_bid":"0.41","hash":"746e53b295853dd365f28f5fceaecdd4e72b969d","price":"0.47","side":"SELL","size":"103"}],"timestamp":"1785204173329"},"payload_hash":"87b6f4f23ca5b3c6e97ee841adae2906f32ac326d521bc26dac2afb1fd8d183f","raw_frame":"{\"market\":\"0xda6f0e0e93fc8469e0159a166028d017bddbc162b86f66bac90391379603d962\", \"price_changes\":[{\"asset_id\":\"39272994714739463168905443499424551362424437245880253267329605556587274644733\", \"price\":\"0.53\", \"size\":\"103\", \"side\":\"BUY\", \"hash\":\"039a1500cd5e803873f519c58283ce2ad57a8baa\", \"best_bid\":\"0.58\", \"best_ask\":\"0.59\"}, {\"asset_id\":\"20893381255801015515826997628594359667013752732428989472914000440642900266717\", \"price\":\"0.47\", \"size\":\"103\", \"side\":\"SELL\", \"hash\":\"746e53b295853dd365f28f5fceaecdd4e72b969d\", \"best_bid\":\"0.41\", \"best_ask\":\"0.42\"}], \"timestamp\":\"1785204173329\", \"event_type\":\"price_change\"}","received_at":"2026-07-28T02:02:54.257516Z","schema_version":"clob-market-ws.price_change.v1","sequence":null,"server_hash":null,"server_timestamp":"1785204173329","session_id":"d2757dd6dad94f3b9fe67e8dbf1adc37","source":"clob_market_ws"},"received_at":"2026-07-28T02:02:54.257516Z","record_id":"4d25e0c01f166a96bc1ac3e3178ee8e599405b97b6f22fc510b34a746a835989","schema_fingerprint":"4aa3821a28b0b7c2400bc59aba4bcc0a76e971dadd19610d3ad38c768e124dc7","schema_version":"edge-lab-recorder.raw.v1","sequence":null,"source":"clob_market_ws"}
{"event_at":"2026-07-28T02:02:53.330000Z","event_fingerprint":"ed13073cff08192787d8efb5c7967f0432f6d73fed5e084890f7c4821bd7a422","payload":{"connection_id":"5d29200f65794d4d9ab6ef271f045a9b","event_at":"2026-07-28T02:02:53.330000Z","event_type":"price_change","frame_hash":"b55a6688fb6dab4a59745ccb99aa599b26535736b465dc3a9e629b4d5ebb9a1a","frame_index":0,"kind":"data","monotonic_ns":306157266715250,"payload":{"event_type":"price_change","market":"0xda6f0e0e93fc8469e0159a166028d017bddbc162b86f66bac90391379603d962","price_changes":[{"asset_id":"20893381255801015515826997628594359667013752732428989472914000440642900266717","best_ask":"0.42","best_bid":"0.41","hash":"13a41b2e2414ee9574a1be44618b8847ef217d9d","price":"0.41","side":"BUY","size":"127.2"},{"asset_id":"39272994714739463168905443499424551362424437245880253267329605556587274644733","best_ask":"0.59","best_bid":"0.58","hash":"9a52efeb7b20ba8f047df355adc2a9bae9e1b75c","price":"0.59","side":"SELL","size":"127.2"}],"timestamp":"1785204173330"},"payload_hash":"a789ccbb0b586556c4e63c6e965c32546d57f950e357196dc4f974e16645ed16","raw_frame":"{\"market\":\"0xda6f0e0e93fc8469e0159a166028d017bddbc162b86f66bac90391379603d962\", \"price_changes\":[{\"asset_id\":\"20893381255801015515826997628594359667013752732428989472914000440642900266717\", \"price\":\"0.41\", \"size\":\"127.2\", \"side\":\"BUY\", \"hash\":\"13a41b2e2414ee9574a1be44618b8847ef217d9d\", \"best_bid\":\"0.41\", \"best_ask\":\"0.42\"}, {\"asset_id\":\"39272994714739463168905443499424551362424437245880253267329605556587274644733\", \"price\":\"0.59\", \"size\":\"127.2\", \"side\":\"SELL\", \"hash\":\"9a52efeb7b20ba8f047df355adc2a9bae9e1b75c\", \"best_bid\":\"0.58\", \"best_ask\":\"0.59\"}], \"timestamp\":\"1785204173330\", \"event_type\":\"price_change\"}","received_at":"2026-07-28T02:02:54.261941Z","schema_version":"clob-market-ws.price_change.v1","sequence":null,"server_hash":null,"server_timestamp":"1785204173330","session_id":"d2757dd6dad94f3b9fe67e8dbf1adc37","source":"clob_market_ws"},"received_at":"2026-07-28T02:02:54.261941Z","record_id":"b1ccab16b2614b670b18b7591864f6f5184937c8cb19f1e00e96c431b8bfaaf7","schema_fingerprint":"4aa3821a28b0b7c2400bc59aba4bcc0a76e971dadd19610d3ad38c768e124dc7","schema_version":"edge-lab-recorder.raw.v1","sequence":null,"source":"clob_market_ws"}
{"event_at":"2026-07-28T02:02:53.337000Z","event_fingerprint":"24e9fd7c19d336a55b4c45203d41e0a4aed622ee5b8a7fe6dd22a6ce8129d562","payload":{"connection_id":"5d29200f65794d4d9ab6ef271f045a9b","event_at":"2026-07-28T02:02:53.337000Z","event_type":"price_change","frame_hash":"bd71ec133ff65a2d065782eb8a1d60f12f05076475e7e39910f55c36755cc318","frame_index":0,"kind":"data","monotonic_ns":306157269200166,"payload":{"event_type":"price_change","market":"0xda6f0e0e93fc8469e0159a166028d017bddbc162b86f66bac90391379603d962","price_changes":[{"asset_id":"39272994714739463168905443499424551362424437245880253267329605556587274644733","best_ask":"0.59","best_bid":"0.58","hash":"9213f042224b1076691d52758ea3f2567f9d6b02","price":"0.51","side":"BUY","size":"159"},{"asset_id":"20893381255801015515826997628594359667013752732428989472914000440642900266717","best_ask":"0.42","best_bid":"0.41","hash":"9984371f056feae636779642830662f8bee7bc45","price":"0.49","side":"SELL","size":"159"}],"timestamp":"1785204173337"},"payload_hash":"dc1458a4e1dc12783bab742c416d73010c225b6bcee5cb5f4820b984acc36d80","raw_frame":"{\"market\":\"0xda6f0e0e93fc8469e0159a166028d017bddbc162b86f66bac90391379603d962\", \"price_changes\":[{\"asset_id\":\"39272994714739463168905443499424551362424437245880253267329605556587274644733\", \"price\":\"0.51\", \"size\":\"159\", \"side\":\"BUY\", \"hash\":\"9213f042224b1076691d52758ea3f2567f9d6b02\", \"best_bid\":\"0.58\", \"best_ask\":\"0.59\"}, {\"asset_id\":\"20893381255801015515826997628594359667013752732428989472914000440642900266717\", \"price\":\"0.49\", \"size\":\"159\", \"side\":\"SELL\", \"hash\":\"9984371f056feae636779642830662f8bee7bc45\", \"best_bid\":\"0.41\", \"best_ask\":\"0.42\"}], \"timestamp\":\"1785204173337\", \"event_type\":\"price_change\"}","received_at":"2026-07-28T02:02:54.264425Z","schema_version":"clob-market-ws.price_change.v1","sequence":null,"server_hash":null,"server_timestamp":"1785204173337","session_id":"d2757dd6dad94f3b9fe67e8dbf1adc37","source":"clob_market_ws"},"received_at":"2026-07-28T02:02:54.264425Z","record_id":"58207cadc81cc3fdabcfdafcc3eebaf4a107eca81ee0684942d2db79d5e4c202","schema_fingerprint":"4aa3821a28b0b7c2400bc59aba4bcc0a76e971dadd19610d3ad38c768e124dc7","schema_version":"edge-lab-recorder.raw.v1","sequence":null,"source":"clob_market_ws"}
{"event_at":"2026-07-28T02:02:53.338000Z","event_fingerprint":"398f66cc3e7e0e412d2945e995062ffea444e266a16d3f89cb970f46005ff39a","payload":{"connection_id":"5d29200f65794d4d9ab6ef271f045a9b","event_at":"2026-07-28T02:02:53.338000Z","event_type":"price_change","frame_hash":"1e43f434274b6088fcd487366451275c6d8cdeb08e288769f2f5860b6f997811","frame_index":0,"kind":"data","monotonic_ns":306157270897708,"payload":{"event_type":"price_change","market":"0xda6f0e0e93fc8469e0159a166028d017bddbc162b86f66bac90391379603d962","price_changes":[{"asset_id":"20893381255801015515826997628594359667013752732428989472914000440642900266717","best_ask":"0.42","best_bid":"0.41","hash":"003ec572e1f921159ad868d45bf028ed55d844ae","price":"0.41","side":"BUY","size":"105.2"},{"asset_id":"39272994714739463168905443499424551362424437245880253267329605556587274644733","best_ask":"0.59","best_bid":"0.58","hash":"321eac5c189fa1bc78d8461fcb8a992223b370b4","price":"0.59","side":"SELL","size":"105.2"}],"timestamp":"1785204173338"},"payload_hash":"e719a07253a0bdbaa93d71c5e408b85a72bef5e903f6d4314f7b7f3319fa0ce4","raw_frame":"{\"market\":\"0xda6f0e0e93fc8469e0159a166028d017bddbc162b86f66bac90391379603d962\", \"price_changes\":[{\"asset_id\":\"20893381255801015515826997628594359667013752732428989472914000440642900266717\", \"price\":\"0.41\", \"size\":\"105.2\", \"side\":\"BUY\", \"hash\":\"003ec572e1f921159ad868d45bf028ed55d844ae\", \"best_bid\":\"0.41\", \"best_ask\":\"0.42\"}, {\"asset_id\":\"39272994714739463168905443499424551362424437245880253267329605556587274644733\", \"price\":\"0.59\", \"size\":\"105.2\", \"side\":\"SELL\", \"hash\":\"321eac5c189fa1bc78d8461fcb8a992223b370b4\", \"best_bid\":\"0.58\", \"best_ask\":\"0.59\"}], \"timestamp\":\"1785204173338\", \"event_type\":\"price_change\"}","received_at":"2026-07-28T02:02:54.266121Z","schema_version":"clob-market-ws.price_change.v1","sequence":null,"server_hash":null,"server_timestamp":"1785204173338","session_id":"d2757dd6dad94f3b9fe67e8dbf1adc37","source":"clob_market_ws"},"received_at":"2026-07-28T02:02:54.266121Z","record_id":"bee7fe8d3e54082e54d06a6a7bc381509e6091a092b0e0db435ccb93285ab9b7","schema_fingerprint":"4aa3821a28b0b7c2400bc59aba4bcc0a76e971dadd19610d3ad38c768e124dc7","schema_version":"edge-lab-recorder.raw.v1","sequence":null,"source":"clob_market_ws"}
{"event_at":"2026-07-28T02:02:53.339000Z","event_fingerprint":"6cb855246e29cca3f78b256c8f10f8948ee23162d217a12883fa618cab2755c0","payload":{"connection_id":"5d29200f65794d4d9ab6ef271f045a9b","event_at":"2026-07-28T02:02:53.339000Z","event_type":"price_change","frame_hash":"05f565444e1d36165bad0c2e4faeda43a6b42654d9bc1137b7af3c12b3da022d","frame_index":0,"kind":"data","monotonic_ns":306157272691458,"payload":{"event_type":"price_change","market":"0xda6f0e0e93fc8469e0159a166028d017bddbc162b86f66bac90391379603d962","price_changes":[{"asset_id":"39272994714739463168905443499424551362424437245880253267329605556587274644733","best_ask":"0.59","best_bid":"0.58","hash":"8599c392f360c7f0110897304c8cc2d733bec768","price":"0.48","side":"BUY","size":"134.55"},{"asset_id":"20893381255801015515826997628594359667013752732428989472914000440642900266717","best_ask":"0.42","best_bid":"0.41","hash":"c64d57a51e11c0548071775674325c539cec3b45","price":"0.52","side":"SELL","size":"134.55"}],"timestamp":"1785204173339"},"payload_hash":"1ad9c8407badc7cb38b6aaddc4365ccdab264c901a049375f97bdf2a234f6b9e","raw_frame":"{\"market\":\"0xda6f0e0e93fc8469e0159a166028d017bddbc162b86f66bac90391379603d962\", \"price_changes\":[{\"asset_id\":\"39272994714739463168905443499424551362424437245880253267329605556587274644733\", \"price\":\"0.48\", \"size\":\"134.55\", \"side\":\"BUY\", \"hash\":\"8599c392f360c7f0110897304c8cc2d733bec768\", \"best_bid\":\"0.58\", \"best_ask\":\"0.59\"}, {\"asset_id\":\"20893381255801015515826997628594359667013752732428989472914000440642900266717\", \"price\":\"0.52\", \"size\":\"134.55\", \"side\":\"SELL\", \"hash\":\"c64d57a51e11c0548071775674325c539cec3b45\", \"best_bid\":\"0.41\", \"best_ask\":\"0.42\"}], \"timestamp\":\"1785204173339\", \"event_type\":\"price_change\"}","received_at":"2026-07-28T02:02:54.267914Z","schema_version":"clob-market-ws.price_change.v1","sequence":null,"server_hash":null,"server_timestamp":"1785204173339","session_id":"d2757dd6dad94f3b9fe67e8dbf1adc37","source":"clob_market_ws"},"received_at":"2026-07-28T02:02:54.267914Z","record_id":"21dac4f58f03bae5f77411dcadcd53f919da31615bc0c3fe8c5ee6144cf9c70f","schema_fingerprint":"4aa3821a28b0b7c2400bc59aba4bcc0a76e971dadd19610d3ad38c768e124dc7","schema_version":"edge-lab-recorder.raw.v1","sequence":null,"source":"clob_market_ws"}
{"event_at":"2026-07-28T02:02:53.343000Z","event_fingerprint":"2801aca1dfbf107f1c21e12d67758f9633f8107531cb623acb473d1fbf898db9","payload":{"connection_id":"5d29200f65794d4d9ab6ef271f045a9b","event_at":"2026-07-28T02:02:53.343000Z","event_type":"price_change","frame_hash":"414e96fc431276d5ff88fdca552540710c042a0022dcacd733b3d7637fbd7a21","frame_index":0,"kind":"data","monotonic_ns":306157274297458,"payload":{"event_type":"price_change","market":"0xda6f0e0e93fc8469e0159a166028d017bddbc162b86f66bac90391379603d962","price_changes":[{"asset_id":"39272994714739463168905443499424551362424437245880253267329605556587274644733","best_ask":"0.59","best_bid":"0.58","hash":"41af016ed774f72396ce2bb97524129275924ca0","price":"0.51","side":"BUY","size":"189"},{"asset_id":"20893381255801015515826997628594359667013752732428989472914000440642900266717","best_ask":"0.42","best_bid":"0.41","hash":"33e79c919b17d1ffff44fc67c7e2719e48b11ce3","price":"0.49","side":"SELL","size":"189"}],"timestamp":"1785204173343"},"payload_hash":"8648545a84b0ce4a96a4c00e4f6676f61fc1cb230410c6467e6d84d6f2938aa1","raw_frame":"{\"market\":\"0xda6f0e0e93fc8469e0159a166028d017bddbc162b86f66bac90391379603d962\", \"price_changes\":[{\"asset_id\":\"39272994714739463168905443499424551362424437245880253267329605556587274644733\", \"price\":\"0.51\", \"size\":\"189\", \"side\":\"BUY\", \"hash\":\"41af016ed774f72396ce2bb97524129275924ca0\", \"best_bid\":\"0.58\", \"best_ask\":\"0.59\"}, {\"asset_id\":\"20893381255801015515826997628594359667013752732428989472914000440642900266717\", \"price\":\"0.49\", \"size\":\"189\", \"side\":\"SELL\", \"hash\":\"33e79c919b17d1ffff44fc67c7e2719e48b11ce3\", \"best_bid\":\"0.41\", \"best_ask\":\"0.42\"}], \"timestamp\":\"1785204173343\", \"event_type\":\"price_change\"}","received_at":"2026-07-28T02:02:54.269523Z","schema_version":"clob-market-ws.price_change.v1","sequence":null,"server_hash":null,"server_timestamp":"1785204173343","session_id":"d2757dd6dad94f3b9fe67e8dbf1adc37","source":"clob_market_ws"},"received_at":"2026-07-28T02:02:54.269523Z","record_id":"afb8a0eaa61f3ff2a4cfdb09e656ea4f7d6f85d16a3780b6ac3d6febecfd591a","schema_fingerprint":"4aa3821a28b0b7c2400bc59aba4bcc0a76e971dadd19610d3ad38c768e124dc7","schema_version":"edge-lab-recorder.raw.v1","sequence":null,"source":"clob_market_ws"}
{"event_at":"2026-07-28T02:02:53.345000Z","event_fingerprint":"feb344f7516dff1808ecb7e3157904dcfb338a5a41fdf7581f58563086daf5ba","payload":{"connection_id":"5d29200f65794d4d9ab6ef271f045a9b","event_at":"2026-07-28T02:02:53.345000Z","event_type":"price_change","frame_hash":"040d8ca7173181843096010a4b4146312b9b3fcdac465b524f39ee76b29561fc","frame_index":0,"kind":"data","monotonic_ns":306157275839916,"payload":{"event_type":"price_change","market":"0xda6f0e0e93fc8469e0159a166028d017bddbc162b86f66bac90391379603d962","price_changes":[{"asset_id":"39272994714739463168905443499424551362424437245880253267329605556587274644733","best_ask":"0.59","best_bid":"0.58","hash":"1d00e98d6d6bedd114a35a90f94bd3e4aac04ffb","price":"0.51","side":"BUY","size":"219"},{"asset_id":"20893381255801015515826997628594359667013752732428989472914000440642900266717","best_ask":"0.42","best_bid":"0.41","hash":"47b0197486cc5cfe375d28995fb70f7ebbbbf921","price":"0.49","side":"SELL","size":"219"}],"timestamp":"1785204173345"},"payload_hash":"b188a8f77029d0d022a1e0582eef6abf4a7fa78594547fe53b8748377002b881","raw_frame":"{\"market\":\"0xda6f0e0e93fc8469e0159a166028d017bddbc162b86f66bac90391379603d962\", \"price_changes\":[{\"asset_id\":\"39272994714739463168905443499424551362424437245880253267329605556587274644733\", \"price\":\"0.51\", \"size\":\"219\", \"side\":\"BUY\", \"hash\":\"1d00e98d6d6bedd114a35a90f94bd3e4aac04ffb\", \"best_bid\":\"0.58\", \"best_ask\":\"0.59\"}, {\"asset_id\":\"20893381255801015515826997628594359667013752732428989472914000440642900266717\", \"price\":\"0.49\", \"size\":\"219\", \"side\":\"SELL\", \"hash\":\"47b0197486cc5cfe375d28995fb70f7ebbbbf921\", \"best_bid\":\"0.41\", \"best_ask\":\"0.42\"}], \"timestamp\":\"1785204173345\", \"event_type\":\"price_change\"}","received_at":"2026-07-28T02:02:54.271065Z","schema_version":"clob-market-ws.price_change.v1","sequence":null,"server_hash":null,"server_timestamp":"1785204173345","session_id":"d2757dd6dad94f3b9fe67e8dbf1adc37","source":"clob_market_ws"},"received_at":"2026-07-28T02:02:54.271065Z","record_id":"d50404f4d6562b954768b916cbe96ffd85487b68ac6ccaaf7d03dfadd399d5a3","schema_fingerprint":"4aa3821a28b0b7c2400bc59aba4bcc0a76e971dadd19610d3ad38c768e124dc7","schema_version":"edge-lab-recorder.raw.v1","sequence":null,"source":"clob_market_ws"}
{"event_at":"2026-07-28T02:02:53.346000Z","event_fingerprint":"3f02e30031de47a8a58602c943323c09817a90f7f3db2f3ef9ec9aa759e117e6","payload":{"connection_id":"5d29200f65794d4d9ab6ef271f045a9b","event_at":"2026-07-28T02:02:53.346000Z","event_type":"price_change","frame_hash":"f66036efdbbbdeb8a0e7e780350ba0a28ccee1b12fdeb1cc29faf46e7c9e07ef","frame_index":0,"kind":"data","monotonic_ns":306157277525875,"payload":{"event_type":"price_change","market":"0xda6f0e0e93fc8469e0159a166028d017bddbc162b86f66bac90391379603d962","price_changes":[{"asset_id":"20893381255801015515826997628594359667013752732428989472914000440642900266717","best_ask":"0.42","best_bid":"0.41","hash":"c575ee5284ac764500713ef493254f9f76c70495","price":"0.41","side":"BUY","size":"111.2"},{"asset_id":"39272994714739463168905443499424551362424437245880253267329605556587274644733","best_ask":"0.59","best_bid":"0.58","hash":"0ac946b5dbb48c348d11b004b7b63af44ff25f7c","price":"0.59","side":"SELL","size":"111.2"}],"timestamp":"1785204173346"},"payload_hash":"029314186be550bace3d80e19b3fe12e3737abc19f69c79592badaffa27d9ab3","raw_frame":"{\"market\":\"0xda6f0e0e93fc8469e0159a166028d017bddbc162b86f66bac90391379603d962\", \"price_changes\":[{\"asset_id\":\"20893381255801015515826997628594359667013752732428989472914000440642900266717\", \"price\":\"0.41\", \"size\":\"111.2\", \"side\":\"BUY\", \"hash\":\"c575ee5284ac764500713ef493254f9f76c70495\", \"best_bid\":\"0.41\", \"best_ask\":\"0.42\"}, {\"asset_id\":\"39272994714739463168905443499424551362424437245880253267329605556587274644733\", \"price\":\"0.59\", \"size\":\"111.2\", \"side\":\"SELL\", \"hash\":\"0ac946b5dbb48c348d11b004b7b63af44ff25f7c\", \"best_bid\":\"0.58\", \"best_ask\":\"0.59\"}], \"timestamp\":\"1785204173346\", \"event_type\":\"price_change\"}","received_at":"2026-07-28T02:02:54.272751Z","schema_version":"clob-market-ws.price_change.v1","sequence":null,"server_hash":null,"server_timestamp":"1785204173346","session_id":"d2757dd6dad94f3b9fe67e8dbf1adc37","source":"clob_market_ws"},"received_at":"2026-07-28T02:02:54.272751Z","record_id":"d0bc5a4b16e9a23a315708d6799d34cbf479ba83f6d6f1efc019a8a326c402cb","schema_fingerprint":"4aa3821a28b0b7c2400bc59aba4bcc0a76e971dadd19610d3ad38c768e124dc7","schema_version":"edge-lab-recorder.raw.v1","sequence":null,"source":"clob_market_ws"}
{"event_at":"2026-07-28T02:02:53.349000Z","event_fingerprint":"975694a70d096956812dfba5f0ebdad1772c830e4784e13232dfa44d269fe05c","payload":{"connection_id":"5d29200f65794d4d9ab6ef271f045a9b","event_at":"2026-07-28T02:02:53.349000Z","event_type":"price_change","frame_hash":"0580dc08963e2e309b50dbb082db701d35a25d210297b6aca27aeb6d2e62c250","frame_index":0,"kind":"data","monotonic_ns":306157278689250,"payload":{"event_type":"price_change","market":"0xda6f0e0e93fc8469e0159a166028d017bddbc162b86f66bac90391379603d962","price_changes":[{"asset_id":"20893381255801015515826997628594359667013752732428989472914000440642900266717","best_ask":"0.42","best_bid":"0.41","hash":"125bb453bba9318b000ddf8e3d8a475c4c37eea5","price":"0.4","side":"BUY","size":"360.2"},{"asset_id":"39272994714739463168905443499424551362424437245880253267329605556587274644733","best_ask":"0.59","best_bid":"0.58","hash":"9be77b1e25add9f06d53c006c25dd1c5948fc0b0","price":"0.6","side":"SELL","size":"360.2"}],"timestamp":"1785204173349"},"payload_hash":"6e2f5e06f9c5978a0bbb98f16deca879b4dbf8d4009c232b9adff1557dbbf330","raw_frame":"{\"market\":\"0xda6f0e0e93fc8469e0159a166028d017bddbc162b86f66bac90391379603d962\", \"price_changes\":[{\"asset_id\":\"20893381255801015515826997628594359667013752732428989472914000440642900266717\", \"price\":\"0.4\", \"size\":\"360.2\", \"side\":\"BUY\", \"hash\":\"125bb453bba9318b000ddf8e3d8a475c4c37eea5\", \"best_bid\":\"0.41\", \"best_ask\":\"0.42\"}, {\"asset_id\":\"39272994714739463168905443499424551362424437245880253267329605556587274644733\", \"price\":\"0.6\", \"size\":\"360.2\", \"side\":\"SELL\", \"hash\":\"9be77b1e25add9f06d53c006c25dd1c5948fc0b0\", \"best_bid\":\"0.58\", \"best_ask\":\"0.59\"}], \"timestamp\":\"1785204173349\", \"event_type\":\"price_change\"}","received_at":"2026-07-28T02:02:54.273917Z","schema_version":"clob-market-ws.price_change.v1","sequence":null,"server_hash":null,"server_timestamp":"1785204173349","session_id":"d2757dd6dad94f3b9fe67e8dbf1adc37","source":"clob_market_ws"},"received_at":"2026-07-28T02:02:54.273917Z","record_id":"7f64b329297eb4ac3d542acc8a1651051a01f2415350452019a146335badd263","schema_fingerprint":"4aa3821a28b0b7c2400bc59aba4bcc0a76e971dadd19610d3ad38c768e124dc7","schema_version":"edge-lab-recorder.raw.v1","sequence":null,"source":"clob_market_ws"}
{"event_at":"2026-07-28T02:02:53.377000Z","event_fingerprint":"05cab54345f9c839839ad1475b743ae1f796c5f4f59fdb01396d673038784415","payload":{"connection_id":"5d29200f65794d4d9ab6ef271f045a9b","event_at":"2026-07-28T02:02:53.377000Z","event_type":"price_change","frame_hash":"580a665eb2680ad4b99db49f5e8def87296b5be4ffafc382ab0e9ada852e3104","frame_index":0,"kind":"data","monotonic_ns":306157279703125,"payload":{"event_type":"price_change","market":"0xda6f0e0e93fc8469e0159a166028d017bddbc162b86f66bac90391379603d962","price_changes":[{"asset_id":"20893381255801015515826997628594359667013752732428989472914000440642900266717","best_ask":"0.42","best_bid":"0.41","hash":"303dfb977657c0e1c9c7aba88065827bbd0e2302","price":"0.41","side":"BUY","size":"121.2"},{"asset_id":"39272994714739463168905443499424551362424437245880253267329605556587274644733","best_ask":"0.59","best_bid":"0.58","hash":"2bc6cd11848adf209eb61040e40eca6e06822d79","price":"0.59","side":"SELL","size":"121.2"}],"timestamp":"1785204173377"},"payload_hash":"90044b66b04b448e5ff46205c7a43d9bd3a84717f3df3787d3fe7bfab14206d1","raw_frame":"{\"market\":\"0xda6f0e0e93fc8469e0159a166028d017bddbc162b86f66bac90391379603d962\", \"price_changes\":[{\"asset_id\":\"20893381255801015515826997628594359667013752732428989472914000440642900266717\", \"price\":\"0.41\", \"size\":\"121.2\", \"side\":\"BUY\", \"hash\":\"303dfb977657c0e1c9c7aba88065827bbd0e2302\", \"best_bid\":\"0.41\", \"best_ask\":\"0.42\"}, {\"asset_id\":\"39272994714739463168905443499424551362424437245880253267329605556587274644733\", \"price\":\"0.59\", \"size\":\"121.2\", \"side\":\"SELL\", \"hash\":\"2bc6cd11848adf209eb61040e40eca6e06822d79\", \"best_bid\":\"0.58\", \"best_ask\":\"0.59\"}], \"timestamp\":\"1785204173377\", \"event_type\":\"price_change\"}","received_at":"2026-07-28T02:02:54.274931Z","schema_version":"clob-market-ws.price_change.v1","sequence":null,"server_hash":null,"server_timestamp":"1785204173377","session_id":"d2757dd6dad94f3b9fe67e8dbf1adc37","source":"clob_market_ws"},"received_at":"2026-07-28T02:02:54.274931Z","record_id":"5bec68b25b344af52e3af09bea89eff6d0f818ed8b6f2f7fd8d9cdeb15b24221","schema_fingerprint":"4aa3821a28b0b7c2400bc59aba4bcc0a76e971dadd19610d3ad38c768e124dc7","schema_version":"edge-lab-recorder.raw.v1","sequence":null,"source":"clob_market_ws"}
{"event_at":"2026-07-28T02:02:53.383000Z","event_fingerprint":"152271087647e445642100fb644259b0b2fca3dded67cc1ddeb9349069680708","payload":{"connection_id":"5d29200f65794d4d9ab6ef271f045a9b","event_at":"2026-07-28T02:02:53.383000Z","event_type":"price_change","frame_hash":"c35dd80b4b14813877876ea8a690b23aa06861915c92ddecd73e145b6946bc1e","frame_index":0,"kind":"data","monotonic_ns":306157280545500,"payload":{"event_type":"price_change","market":"0xda6f0e0e93fc8469e0159a166028d017bddbc162b86f66bac90391379603d962","price_changes":[{"asset_id":"20893381255801015515826997628594359667013752732428989472914000440642900266717","best_ask":"0.42","best_bid":"0.41","hash":"53bed38971d597bf5ec05e5d49d2f610937c7cdc","price":"0.41","side":"BUY","size":"146.2"},{"asset_id":"39272994714739463168905443499424551362424437245880253267329605556587274644733","best_ask":"0.59","best_bid":"0.58","hash":"a4aa6df12b5cd484bb09efad41aca6c44edd67c9","price":"0.59","side":"SELL","size":"146.2"}],"timestamp":"1785204173383"},"payload_hash":"eebc89d1365a45e62409d6cc81bb3be55a46ae1b838c3f719d38579a4fcf0c6e","raw_frame":"{\"market\":\"0xda6f0e0e93fc8469e0159a166028d017bddbc162b86f66bac90391379603d962\", \"price_changes\":[{\"asset_id\":\"20893381255801015515826997628594359667013752732428989472914000440642900266717\", \"price\":\"0.41\", \"size\":\"146.2\", \"side\":\"BUY\", \"hash\":\"53bed38971d597bf5ec05e5d49d2f610937c7cdc\", \"best_bid\":\"0.41\", \"best_ask\":\"0.42\"}, {\"asset_id\":\"39272994714739463168905443499424551362424437245880253267329605556587274644733\", \"price\":\"0.59\", \"size\":\"146.2\", \"side\":\"SELL\", \"hash\":\"a4aa6df12b5cd484bb09efad41aca6c44edd67c9\", \"best_bid\":\"0.58\", \"best_ask\":\"0.59\"}], \"timestamp\":\"1785204173383\", \"event_type\":\"price_change\"}","received_at":"2026-07-28T02:02:54.275777Z","schema_version":"clob-market-ws.price_change.v1","sequence":null,"server_hash":null,"server_timestamp":"1785204173383","session_id":"d2757dd6dad94f3b9fe67e8dbf1adc37","source":"clob_market_ws"},"received_at":"2026-07-28T02:02:54.275777Z","record_id":"207a9b466086913e7791045f88b28c9a0e4bfaa85b59d4c9ea921c501cd000d3","schema_fingerprint":"4aa3821a28b0b7c2400bc59aba4bcc0a76e971dadd19610d3ad38c768e124dc7","schema_version":"edge-lab-recorder.raw.v1","sequence":null,"source":"clob_market_ws"}
{"event_at":"2026-07-28T02:02:53.388000Z","event_fingerprint":"8ef759b55884200a92434267861e3ec794da45126d7ee2c7d78db9e97cddfa44","payload":{"connection_id":"5d29200f65794d4d9ab6ef271f045a9b","event_at":"2026-07-28T02:02:53.388000Z","event_type":"price_change","frame_hash":"ffa6a37adfc338dfd6694df1873675dfedc382fe8666d70b2b28b77510758796","frame_index":0,"kind":"data","monotonic_ns":306157281506416,"payload":{"event_type":"price_change","market":"0xda6f0e0e93fc8469e0159a166028d017bddbc162b86f66bac90391379603d962","price_changes":[{"asset_id":"39272994714739463168905443499424551362424437245880253267329605556587274644733","best_ask":"0.59","best_bid":"0.58","hash":"cb69d686d26772aa1556026424bfd2553451f0f2","price":"0.38","side":"BUY","size":"76.7"},{"asset_id":"20893381255801015515826997628594359667013752732428989472914000440642900266717","best_ask":"0.42","best_bid":"0.41","hash":"91d6eb938ab45d7c094e3c030e90be51b4045a07","price":"0.62","side":"SELL","size":"76.7"}],"timestamp":"1785204173388"},"payload_hash":"208a5460f1445016c8b13102edf77c0fcce213d266861fc6bbd61c52b8313cd7","raw_frame":"{\"market\":\"0xda6f0e0e93fc8469e0159a166028d017bddbc162b86f66bac90391379603d962\", \"price_changes\":[{\"asset_id\":\"39272994714739463168905443499424551362424437245880253267329605556587274644733\", \"price\":\"0.38\", \"size\":\"76.7\", \"side\":\"BUY\", \"hash\":\"cb69d686d26772aa1556026424bfd2553451f0f2\", \"best_bid\":\"0.58\", \"best_ask\":\"0.59\"}, {\"asset_id\":\"20893381255801015515826997628594359667013752732428989472914000440642900266717\", \"price\":\"0.62\", \"size\":\"76.7\", \"side\":\"SELL\", \"hash\":\"91d6eb938ab45d7c094e3c030e90be51b4045a07\", \"best_bid\":\"0.41\", \"best_ask\":\"0.42\"}], \"timestamp\":\"1785204173388\", \"event_type\":\"price_change\"}","received_at":"2026-07-28T02:02:54.276730Z","schema_version":"clob-market-ws.price_change.v1","sequence":null,"server_hash":null,"server_timestamp":"1785204173388","session_id":"d2757dd6dad94f3b9fe67e8dbf1adc37","source":"clob_market_ws"},"received_at":"2026-07-28T02:02:54.276730Z","record_id":"0d8f210d01be30b887e50d5a7a5e2a5e2328fdece678279131193ec64ac2e386","schema_fingerprint":"4aa3821a28b0b7c2400bc59aba4bcc0a76e971dadd19610d3ad38c768e124dc7","schema_version":"edge-lab-recorder.raw.v1","sequence":null,"source":"clob_market_ws"}
{"event_at":"2026-07-28T02:02:53.390000Z","event_fingerprint":"14fb6d020b544282951604fb5849f6800a710dae3ce0701e01e3c569df413887","payload":{"connection_id":"5d29200f65794d4d9ab6ef271f045a9b","event_at":"2026-07-28T02:02:53.390000Z","event_type":"price_change","frame_hash":"50ce96047b6acb3bb464874a16e595f22760bfac98484d2a0c6c46da44349d90","frame_index":0,"kind":"data","monotonic_ns":306157284663958,"payload":{"event_type":"price_change","market":"0xda6f0e0e93fc8469e0159a166028d017bddbc162b86f66bac90391379603d962","price_changes":[{"asset_id":"20893381255801015515826997628594359667013752732428989472914000440642900266717","best_ask":"0.42","best_bid":"0.41","hash":"b12b66626a0b2d4c2d044416fd73ec05a266e6ae","price":"0.37","side":"BUY","size":"185.05"},{"asset_id":"39272994714739463168905443499424551362424437245880253267329605556587274644733","best_ask":"0.59","best_bid":"0.58","hash":"5518edab5fa6464e9a9e46f60737a0bc1559a3fe","price":"0.63","side":"SELL","size":"185.05"}],"timestamp":"1785204173390"},"payload_hash":"0598492f8e25cde78db89dce1f372c7eb20e9b2ce27a98ef5667880ef3546219","raw_frame":"{\"market\":\"0xda6f0e0e93fc8469e0159a166028d017bddbc162b86f66bac90391379603d962\", \"price_changes\":[{\"asset_id\":\"20893381255801015515826997628594359667013752732428989472914000440642900266717\", \"price\":\"0.37\", \"size\":\"185.05\", \"side\":\"BUY\", \"hash\":\"b12b66626a0b2d4c2d044416fd73ec05a266e6ae\", \"best_bid\":\"0.41\", \"best_ask\":\"0.42\"}, {\"asset_id\":\"39272994714739463168905443499424551362424437245880253267329605556587274644733\", \"price\":\"0.63\", \"size\":\"185.05\", \"side\":\"SELL\", \"hash\":\"5518edab5fa6464e9a9e46f60737a0bc1559a3fe\", \"best_bid\":\"0.58\", \"best_ask\":\"0.59\"}], \"timestamp\":\"1785204173390\", \"event_type\":\"price_change\"}","received_at":"2026-07-28T02:02:54.279888Z","schema_version":"clob-market-ws.price_change.v1","sequence":null,"server_hash":null,"server_timestamp":"1785204173390","session_id":"d2757dd6dad94f3b9fe67e8dbf1adc37","source":"clob_market_ws"},"received_at":"2026-07-28T02:02:54.279888Z","record_id":"9a11cf759e3690c3c6537f381584c4501f951924926b3d79fe39cf55a64fc2a0","schema_fingerprint":"4aa3821a28b0b7c2400bc59aba4bcc0a76e971dadd19610d3ad38c768e124dc7","schema_version":"edge-lab-recorder.raw.v1","sequence":null,"source":"clob_market_ws"}
{"event_at":"2026-07-28T02:02:53.391000Z","event_fingerprint":"9a06dc902b2b5b01b0f5eea44edcd047ff96a533a439ea59470ff458bd87633f","payload":{"connection_id":"5d29200f65794d4d9ab6ef271f045a9b","event_at":"2026-07-28T02:02:53.391000Z","event_type":"price_change","frame_hash":"35f49e4abff26e0df00c7f42030e4db197afa8254eb1155aecf6ea00f5d8f996","frame_index":0,"kind":"data","monotonic_ns":306157286228000,"payload":{"event_type":"price_change","market":"0xda6f0e0e93fc8469e0159a166028d017bddbc162b86f66bac90391379603d962","price_changes":[{"asset_id":"20893381255801015515826997628594359667013752732428989472914000440642900266717","best_ask":"0.42","best_bid":"0.41","hash":"16c212ce038c372ff9b75bb2be34be9ba4accd57","price":"0.38","side":"BUY","size":"94.6"},{"asset_id":"39272994714739463168905443499424551362424437245880253267329605556587274644733","best_ask":"0.59","best_bid":"0.58","hash":"8e88ba8a2a21a7753115a2011efdabe92f69d20f","price":"0.62","side":"SELL","size":"94.6"}],"timestamp":"1785204173391"},"payload_hash":"cea62ee9ec741c9333d6acdaecfeef274003d9734a8f97ca3061e5af1466515f","raw_frame":"{\"market\":\"0xda6f0e0e93fc8469e0159a166028d017bddbc162b86f66bac90391379603d962\", \"price_changes\":[{\"asset_id\":\"20893381255801015515826997628594359667013752732428989472914000440642900266717\", \"price\":\"0.38\", \"size\":\"94.6\", \"side\":\"BUY\", \"hash\":\"16c212ce038c372ff9b75bb2be34be9ba4accd57\", \"best_bid\":\"0.41\", \"best_ask\":\"0.42\"}, {\"asset_id\":\"39272994714739463168905443499424551362424437245880253267329605556587274644733\", \"price\":\"0.62\", \"size\":\"94.6\", \"side\":\"SELL\", \"hash\":\"8e88ba8a2a21a7753115a2011efdabe92f69d20f\", \"best_bid\":\"0.58\", \"best_ask\":\"0.59\"}], \"timestamp\":\"1785204173391\", \"event_type\":\"price_change\"}","received_at":"2026-07-28T02:02:54.281453Z","schema_version":"clob-market-ws.price_change.v1","sequence":null,"server_hash":null,"server_timestamp":"1785204173391","session_id":"d2757dd6dad94f3b9fe67e8dbf1adc37","source":"clob_market_ws"},"received_at":"2026-07-28T02:02:54.281453Z","record_id":"054759a6d69913fcb116e10c01b83f77ef2a9fdbff5a6efd3f5d1dca653fbcf8","schema_fingerprint":"4aa3821a28b0b7c2400bc59aba4bcc0a76e971dadd19610d3ad38c768e124dc7","schema_version":"edge-lab-recorder.raw.v1","sequence":null,"source":"clob_market_ws"}
{"event_at":"2026-07-28T02:02:53.392000Z","event_fingerprint":"94747538c64bb15396b618b82993877b94bc87851e416aa925a9016987365008","payload":{"connection_id":"5d29200f65794d4d9ab6ef271f045a9b","event_at":"2026-07-28T02:02:53.392000Z","event_type":"price_change","frame_hash":"5f3cf46aeb8260f4d28a9c7840dc60704777bcb5c59de7ec66d2c036b286313f","frame_index":0,"kind":"data","monotonic_ns":306157287749750,"payload":{"event_type":"price_change","market":"0xda6f0e0e93fc8469e0159a166028d017bddbc162b86f66bac90391379603d962","price_changes":[{"asset_id":"20893381255801015515826997628594359667013752732428989472914000440642900266717","best_ask":"0.42","best_bid":"0.41","hash":"2ab87aa9abfd132e8ac3e50023c8fd356acd316a","price":"0.34","side":"BUY","size":"186.23"},{"asset_id":"39272994714739463168905443499424551362424437245880253267329605556587274644733","best_ask":"0.59","best_bid":"0.58","hash":"8ab408d79462cf25db1fa4c0900a002ebd38a894","price":"0.66","side":"SELL","size":"186.23"}],"timestamp":"1785204173392"},"payload_hash":"11594ad49c4539578711e3365b027b0b12f24d8867d10eab6d3f971bdf363c7f","raw_frame":"{\"market\":\"0xda6f0e0e93fc8469e0159a166028d017bddbc162b86f66bac90391379603d962\", \"price_changes\":[{\"asset_id\":\"20893381255801015515826997628594359667013752732428989472914000440642900266717\", \"price\":\"0.34\", \"size\":\"186.23\", \"side\":\"BUY\", \"hash\":\"2ab87aa9abfd132e8ac3e50023c8fd356acd316a\", \"best_bid\":\"0.41\", \"best_ask\":\"0.42\"}, {\"asset_id\":\"39272994714739463168905443499424551362424437245880253267329605556587274644733\", \"price\":\"0.66\", \"size\":\"186.23\", \"side\":\"SELL\", \"hash\":\"8ab408d79462cf25db1fa4c0900a002ebd38a894\", \"best_bid\":\"0.58\", \"best_ask\":\"0.59\"}], \"timestamp\":\"1785204173392\", \"event_type\":\"price_change\"}","received_at":"2026-07-28T02:02:54.282975Z","schema_version":"clob-market-ws.price_change.v1","sequence":null,"server_hash":null,"server_timestamp":"1785204173392","session_id":"d2757dd6dad94f3b9fe67e8dbf1adc37","source":"clob_market_ws"},"received_at":"2026-07-28T02:02:54.282975Z","record_id":"e2acc85863cfd5757cd510aa83c92cecb671c24f36b7634c906e884f6ec41d1d","schema_fingerprint":"4aa3821a28b0b7c2400bc59aba4bcc0a76e971dadd19610d3ad38c768e124dc7","schema_version":"edge-lab-recorder.raw.v1","sequence":null,"source":"clob_market_ws"}
{"event_at":"2026-07-28T02:02:53.394000Z","event_fingerprint":"b075fbca9fd9a16c924f873dac6d36a9d28625952a754fe7d80aa0d78f3dd3c2","payload":{"connection_id":"5d29200f65794d4d9ab6ef271f045a9b","event_at":"2026-07-28T02:02:53.394000Z","event_type":"price_change","frame_hash":"62db8db7525229a4dad0260c986fed672c40d1aa1e03c858fa9ce6bac57862b8","frame_index":0,"kind":"data","monotonic_ns":306157289239750,"payload":{"event_type":"price_change","market":"0xda6f0e0e93fc8469e0159a166028d017bddbc162b86f66bac90391379603d962","price_changes":[{"asset_id":"20893381255801015515826997628594359667013752732428989472914000440642900266717","best_ask":"0.42","best_bid":"0.41","hash":"23ffcc4ecc4d10ac3b131a9ce884b07d293f69a2","price":"0.34","side":"BUY","size":"156.23"},{"asset_id":"39272994714739463168905443499424551362424437245880253267329605556587274644733","best_ask":"0.59","best_bid":"0.58","hash":"4ee637663d83c77e3c079b2d4eeb0c02269024a1","price":"0.66","side":"SELL","size":"156.23"}],"timestamp":"1785204173394"},"payload_hash":"f7f97696bd33d4b2f5e786ebc5bb90c2f617ed42b2374c486acae61b2b9d818d","raw_frame":"{\"market\":\"0xda6f0e0e93fc8469e0159a166028d017bddbc162b86f66bac90391379603d962\", \"price_changes\":[{\"asset_id\":\"20893381255801015515826997628594359667013752732428989472914000440642900266717\", \"price\":\"0.34\", \"size\":\"156.23\", \"side\":\"BUY\", \"hash\":\"23ffcc4ecc4d10ac3b131a9ce884b07d293f69a2\", \"best_bid\":\"0.41\", \"best_ask\":\"0.42\"}, {\"asset_id\":\"39272994714739463168905443499424551362424437245880253267329605556587274644733\", \"price\":\"0.66\", \"size\":\"156.23\", \"side\":\"SELL\", \"hash\":\"4ee637663d83c77e3c079b2d4eeb0c02269024a1\", \"best_bid\":\"0.58\", \"best_ask\":\"0.59\"}], \"timestamp\":\"1785204173394\", \"event_type\":\"price_change\"}","received_at":"2026-07-28T02:02:54.284465Z","schema_version":"clob-market-ws.price_change.v1","sequence":null,"server_hash":null,"server_timestamp":"1785204173394","session_id":"d2757dd6dad94f3b9fe67e8dbf1adc37","source":"clob_market_ws"},"received_at":"2026-07-28T02:02:54.284465Z","record_id":"16427f4a01dc068e89f2aac7ec9ffba2a8e1273b4d74db075bcb03599e953e80","schema_fingerprint":"4aa3821a28b0b7c2400bc59aba4bcc0a76e971dadd19610d3ad38c768e124dc7","schema_version":"edge-lab-recorder.raw.v1","sequence":null,"source":"clob_market_ws"}
{"event_at":"2026-07-28T02:02:53.399000Z","event_fingerprint":"8ef8cbf9051b48ce98f1d207467ddf6ea7849dbcc4ba7f76c2a1c6772a22a2ca","payload":{"connection_id":"5d29200f65794d4d9ab6ef271f045a9b","event_at":"2026-07-28T02:02:53.399000Z","event_type":"price_change","frame_hash":"9328af4c79d3ffb3f84acb9f04ab4e86685d949a34c2bb91a9392b7a6717bd2c","frame_index":0,"kind":"data","monotonic_ns":306157290754875,"payload":{"event_type":"price_change","market":"0xda6f0e0e93fc8469e0159a166028d017bddbc162b86f66bac90391379603d962","price_changes":[{"asset_id":"20893381255801015515826997628594359667013752732428989472914000440642900266717","best_ask":"0.42","best_bid":"0.41","hash":"051ac35449fa7e95ba7a5f8476fa8e3313c11b99","price":"0.41","side":"BUY","size":"141.2"},{"asset_id":"39272994714739463168905443499424551362424437245880253267329605556587274644733","best_ask":"0.59","best_bid":"0.58","hash":"3c02e7b6f6dec2bdd29144accbbd4188bc3096f6","price":"0.59","side":"SELL","size":"141.2"}],"timestamp":"1785204173399"},"payload_hash":"09115ec80c6c06d40057d1adeafc6c8c2bc5a5fbd944adc9d2ade9412c46b2ea","raw_frame":"{\"market\":\"0xda6f0e0e93fc8469e0159a166028d017bddbc162b86f66bac90391379603d962\", \"price_changes\":[{\"asset_id\":\"20893381255801015515826997628594359667013752732428989472914000440642900266717\", \"price\":\"0.41\", \"size\":\"141.2\", \"side\":\"BUY\", \"hash\":\"051ac35449fa7e95ba7a5f8476fa8e3313c11b99\", \"best_bid\":\"0.41\", \"best_ask\":\"0.42\"}, {\"asset_id\":\"39272994714739463168905443499424551362424437245880253267329605556587274644733\", \"price\":\"0.59\", \"size\":\"141.2\", \"side\":\"SELL\", \"hash\":\"3c02e7b6f6dec2bdd29144accbbd4188bc3096f6\", \"best_bid\":\"0.58\", \"best_ask\":\"0.59\"}], \"timestamp\":\"1785204173399\", \"event_type\":\"price_change\"}","received_at":"2026-07-28T02:02:54.285981Z","schema_version":"clob-market-ws.price_change.v1","sequence":null,"server_hash":null,"server_timestamp":"1785204173399","session_id":"d2757dd6dad94f3b9fe67e8dbf1adc37","source":"clob_market_ws"},"received_at":"2026-07-28T02:02:54.285981Z","record_id":"dc3e5eabc2620adb384387f1420e8715e630abeacc58d3ba98e6ec157b56225e","schema_fingerprint":"4aa3821a28b0b7c2400bc59aba4bcc0a76e971dadd19610d3ad38c768e124dc7","schema_version":"edge-lab-recorder.raw.v1","sequence":null,"source":"clob_market_ws"}
{"event_at":"2026-07-28T02:02:53.400000Z","event_fingerprint":"bdcde18ba40b54774b68c7269bf298495411da30f94e59a166f3939773141846","payload":{"connection_id":"5d29200f65794d4d9ab6ef271f045a9b","event_at":"2026-07-28T02:02:53.400000Z","event_type":"price_change","frame_hash":"a7bb4c74e369724fcf1248a86474780813326187e0cb6e9c820d404fa94bae94","frame_index":0,"kind":"data","monotonic_ns":306157292261500,"payload":{"event_type":"price_change","market":"0xda6f0e0e93fc8469e0159a166028d017bddbc162b86f66bac90391379603d962","price_changes":[{"asset_id":"39272994714739463168905443499424551362424437245880253267329605556587274644733","best_ask":"0.59","best_bid":"0.58","hash":"57d9e80ce1fcdd53cebc900f1fc40d46a4c4777e","price":"0.01","side":"BUY","size":"7858.02"},{"asset_id":"20893381255801015515826997628594359667013752732428989472914000440642900266717","best_ask":"0.42","best_bid":"0.41","hash":"974aa545aba3e6f3c302af50218044ab28ed2395","price":"0.99","side":"SELL","size":"7858.02"}],"timestamp":"1785204173400"},"payload_hash":"45b0d62b5a8ef79c95018dfdb72d6a5a3c9b3b8c7f5f0c65419c333283994781","raw_frame":"{\"market\":\"0xda6f0e0e93fc8469e0159a166028d017bddbc162b86f66bac90391379603d962\", \"price_changes\":[{\"asset_id\":\"39272994714739463168905443499424551362424437245880253267329605556587274644733\", \"price\":\"0.01\", \"size\":\"7858.02\", \"side\":\"BUY\", \"hash\":\"57d9e80ce1fcdd53cebc900f1fc40d46a4c4777e\", \"best_bid\":\"0.58\", \"best_ask\":\"0.59\"}, {\"asset_id\":\"20893381255801015515826997628594359667013752732428989472914000440642900266717\", \"price\":\"0.99\", \"size\":\"7858.02\", \"side\":\"SELL\", \"hash\":\"974aa545aba3e6f3c302af50218044ab28ed2395\", \"best_bid\":\"0.41\", \"best_ask\":\"0.42\"}], \"timestamp\":\"1785204173400\", \"event_type\":\"price_change\"}","received_at":"2026-07-28T02:02:54.287487Z","schema_version":"clob-market-ws.price_change.v1","sequence":null,"server_hash":null,"server_timestamp":"1785204173400","session_id":"d2757dd6dad94f3b9fe67e8dbf1adc37","source":"clob_market_ws"},"received_at":"2026-07-28T02:02:54.287487Z","record_id":"e204f3d52a0a2bef7d71a9065e870f40bc9af8819d3f3f72764e94634126952c","schema_fingerprint":"4aa3821a28b0b7c2400bc59aba4bcc0a76e971dadd19610d3ad38c768e124dc7","schema_version":"edge-lab-recorder.raw.v1","sequence":null,"source":"clob_market_ws"}
{"event_at":"2026-07-28T02:02:53.401000Z","event_fingerprint":"3fbadd36fb3bf910487064ed559a203958b2a76d2eb8a52bd61b2990c9e9259a","payload":{"connection_id":"5d29200f65794d4d9ab6ef271f045a9b","event_at":"2026-07-28T02:02:53.401000Z","event_type":"price_change","frame_hash":"abfe56b17c2f8680ff50b395b4d65f1715ba9e7fbce4e773adb257757403ce53","frame_index":0,"kind":"data","monotonic_ns":306157293755750,"payload":{"event_type":"price_change","market":"0xda6f0e0e93fc8469e0159a166028d017bddbc162b86f66bac90391379603d962","price_changes":[{"asset_id":"39272994714739463168905443499424551362424437245880253267329605556587274644733","best_ask":"0.59","best_bid":"0.58","hash":"2ddde407f83442592c9dc1190aef226f66ee679c","price":"0.53","side":"BUY","size":"93"},{"asset_id":"20893381255801015515826997628594359667013752732428989472914000440642900266717","best_ask":"0.42","best_bid":"0.41","hash":"df772125c349f3ae723797e3b026ddc5fb8be0e0","price":"0.47","side":"SELL","size":"93"}],"timestamp":"1785204173401"},"payload_hash":"1747e2e7dc18573e6e85dc34a71ff856b69740d46a51f7b6decbab3347205b2d","raw_frame":"{\"market\":\"0xda6f0e0e93fc8469e0159a166028d017bddbc162b86f66bac90391379603d962\", \"price_changes\":[{\"asset_id\":\"39272994714739463168905443499424551362424437245880253267329605556587274644733\", \"price\":\"0.53\", \"size\":\"93\", \"side\":\"BUY\", \"hash\":\"2ddde407f83442592c9dc1190aef226f66ee679c\", \"best_bid\":\"0.58\", \"best_ask\":\"0.59\"}, {\"asset_id\":\"20893381255801015515826997628594359667013752732428989472914000440642900266717\", \"price\":\"0.47\", \"size\":\"93\", \"side\":\"SELL\", \"hash\":\"df772125c349f3ae723797e3b026ddc5fb8be0e0\", \"best_bid\":\"0.41\", \"best_ask\":\"0.42\"}], \"timestamp\":\"1785204173401\", \"event_type\":\"price_change\"}","received_at":"2026-07-28T02:02:54.288982Z","schema_version":"clob-market-ws.price_change.v1","sequence":null,"server_hash":null,"server_timestamp":"1785204173401","session_id":"d2757dd6dad94f3b9fe67e8dbf1adc37","source":"clob_market_ws"},"received_at":"2026-07-28T02:02:54.288982Z","record_id":"03b152fd9f459090a4136dfaa94902a727d897b1315658c541a0e38a2fb5a3e7","schema_fingerprint":"4aa3821a28b0b7c2400bc59aba4bcc0a76e971dadd19610d3ad38c768e124dc7","schema_version":"edge-lab-recorder.raw.v1","sequence":null,"source":"clob_market_ws"}
{"event_at":"2026-07-28T02:02:53.416000Z","event_fingerprint":"2f374eee7738b3826ea5c89d30f7b1070c1aed231d4972f1196ee4993b2b3ce3","payload":{"connection_id":"5d29200f65794d4d9ab6ef271f045a9b","event_at":"2026-07-28T02:02:53.416000Z","event_type":"price_change","frame_hash":"cc63801f17d304d0ab0a86a19c7e90773e48d92e23a4efbb84d27363c1fdd011","frame_index":0,"kind":"data","monotonic_ns":306157295225625,"payload":{"event_type":"price_change","market":"0xda6f0e0e93fc8469e0159a166028d017bddbc162b86f66bac90391379603d962","price_changes":[{"asset_id":"20893381255801015515826997628594359667013752732428989472914000440642900266717","best_ask":"0.42","best_bid":"0.41","hash":"2e13242cd7f06bdd6467333712633c7d02b72c69","price":"0.35","side":"BUY","size":"190.07"},{"asset_id":"39272994714739463168905443499424551362424437245880253267329605556587274644733","best_ask":"0.59","best_bid":"0.58","hash":"5b10148b720a719b05c0f2243acc090a041d97fe","price":"0.65","side":"SELL","size":"190.07"}],"timestamp":"1785204173416"},"payload_hash":"7a3aa9f31e9993d6a6a5c13a73683fb0babb1deb046b1499b8789af1029d603c","raw_frame":"{\"market\":\"0xda6f0e0e93fc8469e0159a166028d017bddbc162b86f66bac90391379603d962\", \"price_changes\":[{\"asset_id\":\"20893381255801015515826997628594359667013752732428989472914000440642900266717\", \"price\":\"0.35\", \"size\":\"190.07\", \"side\":\"BUY\", \"hash\":\"2e13242cd7f06bdd6467333712633c7d02b72c69\", \"best_bid\":\"0.41\", \"best_ask\":\"0.42\"}, {\"asset_id\":\"39272994714739463168905443499424551362424437245880253267329605556587274644733\", \"price\":\"0.65\", \"size\":\"190.07\", \"side\":\"SELL\", \"hash\":\"5b10148b720a719b05c0f2243acc090a041d97fe\", \"best_bid\":\"0.58\", \"best_ask\":\"0.59\"}], \"timestamp\":\"1785204173416\", \"event_type\":\"price_change\"}","received_at":"2026-07-28T02:02:54.290452Z","schema_version":"clob-market-ws.price_change.v1","sequence":null,"server_hash":null,"server_timestamp":"1785204173416","session_id":"d2757dd6dad94f3b9fe67e8dbf1adc37","source":"clob_market_ws"},"received_at":"2026-07-28T02:02:54.290452Z","record_id":"5f2495fc13229656dd992a728a5e7ae958b8c0a313854f1f4c44f744d917f1fe","schema_fingerprint":"4aa3821a28b0b7c2400bc59aba4bcc0a76e971dadd19610d3ad38c768e124dc7","schema_version":"edge-lab-recorder.raw.v1","sequence":null,"source":"clob_market_ws"}
{"event_at":"2026-07-28T02:02:53.417000Z","event_fingerprint":"4747f14f4253899f6bb9fce280c29287fc1d4323ae1acc7789bb2ff409b271a5","payload":{"connection_id":"5d29200f65794d4d9ab6ef271f045a9b","event_at":"2026-07-28T02:02:53.417000Z","event_type":"price_change","frame_hash":"1daa1e359043ce0d1e5890d0e35ecbef75361c6e4ab888364ad8caea38a40acb","frame_index":0,"kind":"data","monotonic_ns":306157296755083,"payload":{"event_type":"price_change","market":"0xda6f0e0e93fc8469e0159a166028d017bddbc162b86f66bac90391379603d962","price_changes":[{"asset_id":"39272994714739463168905443499424551362424437245880253267329605556587274644733","best_ask":"0.59","best_bid":"0.58","hash":"1fa48b1b4015f8a4d6a86db864529fc8cacb69cd","price":"0.38","side":"BUY","size":"61.7"},{"asset_id":"20893381255801015515826997628594359667013752732428989472914000440642900266717","best_ask":"0.42","best_bid":"0.41","hash":"0c18b3c257d72d8605f94c3ea4be02f4e3f969fe","price":"0.62","side":"SELL","size":"61.7"}],"timestamp":"1785204173417"},"payload_hash":"325691f19ccd98f50e57877b53da116d2ed94dd8d64e2aa3c2973164839ac562","raw_frame":"{\"market\":\"0xda6f0e0e93fc8469e0159a166028d017bddbc162b86f66bac90391379603d962\", \"price_changes\":[{\"asset_id\":\"39272994714739463168905443499424551362424437245880253267329605556587274644733\", \"price\":\"0.38\", \"size\":\"61.7\", \"side\":\"BUY\", \"hash\":\"1fa48b1b4015f8a4d6a86db864529fc8cacb69cd\", \"best_bid\":\"0.58\", \"best_ask\":\"0.59\"}, {\"asset_id\":\"20893381255801015515826997628594359667013752732428989472914000440642900266717\", \"price\":\"0.62\", \"size\":\"61.7\", \"side\":\"SELL\", \"hash\":\"0c18b3c257d72d8605f94c3ea4be02f4e3f969fe\", \"best_bid\":\"0.41\", \"best_ask\":\"0.42\"}], \"timestamp\":\"1785204173417\", \"event_type\":\"price_change\"}","received_at":"2026-07-28T02:02:54.291979Z","schema_version":"clob-market-ws.price_change.v1","sequence":null,"server_hash":null,"server_timestamp":"1785204173417","session_id":"d2757dd6dad94f3b9fe67e8dbf1adc37","source":"clob_market_ws"},"received_at":"2026-07-28T02:02:54.291979Z","record_id":"ec3f74bf22465cc5f6f2a167ff3f5816fdc6b75c3d54ae105608d93304bd59c7","schema_fingerprint":"4aa3821a28b0b7c2400bc59aba4bcc0a76e971dadd19610d3ad38c768e124dc7","schema_version":"edge-lab-recorder.raw.v1","sequence":null,"source":"clob_market_ws"}
{"event_at":"2026-07-28T02:02:53.425000Z","event_fingerprint":"188af1e7e28b2f5fd3152e2d4ffbd07f69d472f76ab28143763ac1719f3a7a85","payload":{"connection_id":"5d29200f65794d4d9ab6ef271f045a9b","event_at":"2026-07-28T02:02:53.425000Z","event_type":"price_change","frame_hash":"30b5d91c56e9cdc31621186b946bee11fe84304f0c239a27cdc1b573b05b607e","frame_index":0,"kind":"data","monotonic_ns":306157298290125,"payload":{"event_type":"price_change","market":"0xda6f0e0e93fc8469e0159a166028d017bddbc162b86f66bac90391379603d962","price_changes":[{"asset_id":"20893381255801015515826997628594359667013752732428989472914000440642900266717","best_ask":"0.42","best_bid":"0.41","hash":"645e9fc5b48067670d08100a9026897b326339aa","price":"0.35","side":"BUY","size":"220.07"},{"asset_id":"39272994714739463168905443499424551362424437245880253267329605556587274644733","best_ask":"0.59","best_bid":"0.58","hash":"9b1376f2354c3380303272356ce08ad77a8ca5c0","price":"0.65","side":"SELL","size":"220.07"}],"timestamp":"1785204173425"},"payload_hash":"19fc1de420d4415ad7d97aaa6862ca2969c82c96b7044e4c8fdc177604f6699a","raw_frame":"{\"market\":\"0xda6f0e0e93fc8469e0159a166028d017bddbc162b86f66bac90391379603d962\", \"price_changes\":[{\"asset_id\":\"20893381255801015515826997628594359667013752732428989472914000440642900266717\", \"price\":\"0.35\", \"size\":\"220.07\", \"side\":\"BUY\", \"hash\":\"645e9fc5b48067670d08100a9026897b326339aa\", \"best_bid\":\"0.41\", \"best_ask\":\"0.42\"}, {\"asset_id\":\"39272994714739463168905443499424551362424437245880253267329605556587274644733\", \"price\":\"0.65\", \"size\":\"220.07\", \"side\":\"SELL\", \"hash\":\"9b1376f2354c3380303272356ce08ad77a8ca5c0\", \"best_bid\":\"0.58\", \"best_ask\":\"0.59\"}], \"timestamp\":\"1785204173425\", \"event_type\":\"price_change\"}","received_at":"2026-07-28T02:02:54.293515Z","schema_version":"clob-market-ws.price_change.v1","sequence":null,"server_hash":null,"server_timestamp":"1785204173425","session_id":"d2757dd6dad94f3b9fe67e8dbf1adc37","source":"clob_market_ws"},"received_at":"2026-07-28T02:02:54.293515Z","record_id":"1030fa9911257fc320832e6d88bb657af9b5c3683f4e2d144796402857e7303b","schema_fingerprint":"4aa3821a28b0b7c2400bc59aba4bcc0a76e971dadd19610d3ad38c768e124dc7","schema_version":"edge-lab-recorder.raw.v1","sequence":null,"source":"clob_market_ws"}
{"event_at":"2026-07-28T02:02:53.426000Z","event_fingerprint":"fcd254842bc8e0e2d829a56f00f66808312b6bd69f82a233556e5ef9d594532a","payload":{"connection_id":"5d29200f65794d4d9ab6ef271f045a9b","event_at":"2026-07-28T02:02:53.426000Z","event_type":"price_change","frame_hash":"02cd5cfe2a917e388a5ae6b3c8a1b79674eca955091e65cf5f6e338b733989d6","frame_index":0,"kind":"data","monotonic_ns":306157299783833,"payload":{"event_type":"price_change","market":"0xda6f0e0e93fc8469e0159a166028d017bddbc162b86f66bac90391379603d962","price_changes":[{"asset_id":"39272994714739463168905443499424551362424437245880253267329605556587274644733","best_ask":"0.59","best_bid":"0.58","hash":"b4a7e40da28a578181aef3077984f601439dc8ac","price":"0.54","side":"BUY","size":"149.06"},{"asset_id":"20893381255801015515826997628594359667013752732428989472914000440642900266717","best_ask":"0.42","best_bid":"0.41","hash":"2aa155dd7f90c4ebbab12e18498449f7c830c689","price":"0.46","side":"SELL","size":"149.06"}],"timestamp":"1785204173426"},"payload_hash":"04dd0f5d22532cfeeeb41aca0df19b17d56eada4934ce81e261fb5bad3eeb978","raw_frame":"{\"market\":\"0xda6f0e0e93fc8469e0159a166028d017bddbc162b86f66bac90391379603d962\", \"price_changes\":[{\"asset_id\":\"39272994714739463168905443499424551362424437245880253267329605556587274644733\", \"price\":\"0.54\", \"size\":\"149.06\", \"side\":\"BUY\", \"hash\":\"b4a7e40da28a578181aef3077984f601439dc8ac\", \"best_bid\":\"0.58\", \"best_ask\":\"0.59\"}, {\"asset_id\":\"20893381255801015515826997628594359667013752732428989472914000440642900266717\", \"price\":\"0.46\", \"size\":\"149.06\", \"side\":\"SELL\", \"hash\":\"2aa155dd7f90c4ebbab12e18498449f7c830c689\", \"best_bid\":\"0.41\", \"best_ask\":\"0.42\"}], \"timestamp\":\"1785204173426\", \"event_type\":\"price_change\"}","received_at":"2026-07-28T02:02:54.295009Z","schema_version":"clob-market-ws.price_change.v1","sequence":null,"server_hash":null,"server_timestamp":"1785204173426","session_id":"d2757dd6dad94f3b9fe67e8dbf1adc37","source":"clob_market_ws"},"received_at":"2026-07-28T02:02:54.295009Z","record_id":"3ec39e8a361eea3e3191384daea4f205604b23f75944c9143bc43b0367c09ddc","schema_fingerprint":"4aa3821a28b0b7c2400bc59aba4bcc0a76e971dadd19610d3ad38c768e124dc7","schema_version":"edge-lab-recorder.raw.v1","sequence":null,"source":"clob_market_ws"}
{"event_at":"2026-07-28T02:02:53.428000Z","event_fingerprint":"5f18aeb0a10a81cf5941f944fcf775ad034293acb6e6ef1e416b5b7880c270d1","payload":{"connection_id":"5d29200f65794d4d9ab6ef271f045a9b","event_at":"2026-07-28T02:02:53.428000Z","event_type":"price_change","frame_hash":"735949e48d9cd895259e714e688eca6328562ad638bbfd097a888033c62f8c6b","frame_index":0,"kind":"data","monotonic_ns":306157301366000,"payload":{"event_type":"price_change","market":"0xda6f0e0e93fc8469e0159a166028d017bddbc162b86f66bac90391379603d962","price_changes":[{"asset_id":"39272994714739463168905443499424551362424437245880253267329605556587274644733","best_ask":"0.59","best_bid":"0.58","hash":"47641e1ea4529ab6a72c9acbb47318964d7c32d1","price":"0.01","side":"BUY","size":"7853.02"},{"asset_id":"20893381255801015515826997628594359667013752732428989472914000440642900266717","best_ask":"0.42","best_bid":"0.41","hash":"b1a573d860e088bda181d0f8786db9b0c295cad9","price":"0.99","side":"SELL","size":"7853.02"}],"timestamp":"1785204173428"},"payload_hash":"8a6a0457df44c60f0e7e3078a2ea74d9df73f6ccd8e66e167f87cc1a9965f9f4","raw_frame":"{\"market\":\"0xda6f0e0e93fc8469e0159a166028d017bddbc162b86f66bac90391379603d962\", \"price_changes\":[{\"asset_id\":\"39272994714739463168905443499424551362424437245880253267329605556587274644733\", \"price\":\"0.01\", \"size\":\"7853.02\", \"side\":\"BUY\", \"hash\":\"47641e1ea4529ab6a72c9acbb47318964d7c32d1\", \"best_bid\":\"0.58\", \"best_ask\":\"0.59\"}, {\"asset_id\":\"20893381255801015515826997628594359667013752732428989472914000440642900266717\", \"price\":\"0.99\", \"size\":\"7853.02\", \"side\":\"SELL\", \"hash\":\"b1a573d860e088bda181d0f8786db9b0c295cad9\", \"best_bid\":\"0.41\", \"best_ask\":\"0.42\"}], \"timestamp\":\"1785204173428\", \"event_type\":\"price_change\"}","received_at":"2026-07-28T02:02:54.296590Z","schema_version":"clob-market-ws.price_change.v1","sequence":null,"server_hash":null,"server_timestamp":"1785204173428","session_id":"d2757dd6dad94f3b9fe67e8dbf1adc37","source":"clob_market_ws"},"received_at":"2026-07-28T02:02:54.296590Z","record_id":"88d41d9f393c26066a9d325742b8bcfb67baf75946c0b3669d6ed88bf8090fc5","schema_fingerprint":"4aa3821a28b0b7c2400bc59aba4bcc0a76e971dadd19610d3ad38c768e124dc7","schema_version":"edge-lab-recorder.raw.v1","sequence":null,"source":"clob_market_ws"}
