{"event_at":null,"event_fingerprint":"e7cd181567419b517c884c5444d1afa14a5145eb03cfa40af2939e934c7e73eb","payload":{"connection_id":"5d29200f65794d4d9ab6ef271f045a9b","detail":{"interval_seconds":10.0,"message":"PING"},"event_type":"heartbeat","kind":"lifecycle","monotonic_ns":305693724843583,"received_at":"2026-07-28T01:55:10.716726Z","schema_version":"edge-lab-recorder.lifecycle.v1","session_id":"d2757dd6dad94f3b9fe67e8dbf1adc37","source":"clob_market_ws"},"received_at":"2026-07-28T01:55:10.716726Z","record_id":"33a83f6e8999cd2db44bdbc81e7235cb6cf0f127c8804e643cdf617cd0d29a98","schema_fingerprint":"cb8aa3aa4cb168a4b724fd9077bee6ecfb9bc586c57cfdf0ab89f00d82045e3c","schema_version":"edge-lab-recorder.raw.v1","sequence":null,"source":"clob_market_ws"}
{"event_at":null,"event_fingerprint":"40e9d99a0584c2f5ce49e64902a15870faa2bb9bc669d516cc0a6205002f9928","payload":{"connection_id":"5d29200f65794d4d9ab6ef271f045a9b","event_type":"heartbeat_ack","frame_hash":"95784973cc639977bff93619700168505cb8f7855e44fa643d34622a43706c87","kind":"lifecycle","monotonic_ns":305693929195375,"raw_frame":"PONG","received_at":"2026-07-28T01:55:10.921075Z","schema_version":"edge-lab-recorder.heartbeat-ack.v1","session_id":"d2757dd6dad94f3b9fe67e8dbf1adc37","source":"clob_market_ws"},"received_at":"2026-07-28T01:55:10.921075Z","record_id":"dcce3dd8adfd396b1fd4c755526d760ab103380391e4c3cdd98f1efcad1e7243","schema_fingerprint":"c14ee1aab3ca674ee738e5268877b544d74c41ad3c427cedc09236467dc68ba1","schema_version":"edge-lab-recorder.raw.v1","sequence":null,"source":"clob_market_ws"}
{"event_at":null,"event_fingerprint":"baaf26b702dcfb1223d4e6f6f89699e95f6f16dc4dab9b01e56d48a522acfede","payload":{"connection_id":"5d29200f65794d4d9ab6ef271f045a9b","detail":{"interval_seconds":10.0,"message":"PING"},"event_type":"heartbeat","kind":"lifecycle","monotonic_ns":305703737343166,"received_at":"2026-07-28T01:55:20.729108Z","schema_version":"edge-lab-recorder.lifecycle.v1","session_id":"d2757dd6dad94f3b9fe67e8dbf1adc37","source":"clob_market_ws"},"received_at":"2026-07-28T01:55:20.729108Z","record_id":"05ad5f1052608e20de822da4892777f52e3c15b38ac56b3a802b8e68707b7b48","schema_fingerprint":"cb8aa3aa4cb168a4b724fd9077bee6ecfb9bc586c57cfdf0ab89f00d82045e3c","schema_version":"edge-lab-recorder.raw.v1","sequence":null,"source":"clob_market_ws"}
{"event_at":null,"event_fingerprint":"9451db491ee809aed52d48d079d627b9c94fe8fec18beeae7f1831816c0684f7","payload":{"connection_id":"5d29200f65794d4d9ab6ef271f045a9b","event_type":"heartbeat_ack","frame_hash":"95784973cc639977bff93619700168505cb8f7855e44fa643d34622a43706c87","kind":"lifecycle","monotonic_ns":305703943215125,"raw_frame":"PONG","received_at":"2026-07-28T01:55:20.934979Z","schema_version":"edge-lab-recorder.heartbeat-ack.v1","session_id":"d2757dd6dad94f3b9fe67e8dbf1adc37","source":"clob_market_ws"},"received_at":"2026-07-28T01:55:20.934979Z","record_id":"8b3fb830ea9b50eb091955fd513169178faafb16dd0e98c18514f5b153c9897a","schema_fingerprint":"c14ee1aab3ca674ee738e5268877b544d74c41ad3c427cedc09236467dc68ba1","schema_version":"edge-lab-recorder.raw.v1","sequence":null,"source":"clob_market_ws"}
{"event_at":"2026-07-28T01:55:29.002000Z","event_fingerprint":"4ecebbc21b6d05c65d1162dc3267e80f73d96fc4bbfd62df3856e3ee5db5a7b5","payload":{"connection_id":"5d29200f65794d4d9ab6ef271f045a9b","event_at":"2026-07-28T01:55:29.002000Z","event_type":"price_change","frame_hash":"342fe6d2860104c21e71da5d37b2fd88f88db51dabd92fa8063095a8bcc1ee72","frame_index":0,"kind":"data","monotonic_ns":305711902336000,"payload":{"event_type":"price_change","market":"0xda6f0e0e93fc8469e0159a166028d017bddbc162b86f66bac90391379603d962","price_changes":[{"asset_id":"20893381255801015515826997628594359667013752732428989472914000440642900266717","best_ask":"0.52","best_bid":"0.51","hash":"606803d650d0cf04b1a707c012c808dacc3ea2cd","price":"0.35","side":"BUY","size":"15"},{"asset_id":"39272994714739463168905443499424551362424437245880253267329605556587274644733","best_ask":"0.49","best_bid":"0.48","hash":"3b05a6e85489968c1cba10d24eb224cb5ebce6f5","price":"0.65","side":"SELL","size":"15"}],"timestamp":"1785203729002"},"payload_hash":"7bce222481436bbc7f282cca76c0c68e8fb5f93a685224537e51024361b11845","raw_frame":"{\"market\":\"0xda6f0e0e93fc8469e0159a166028d017bddbc162b86f66bac90391379603d962\", \"price_changes\":[{\"asset_id\":\"20893381255801015515826997628594359667013752732428989472914000440642900266717\", \"price\":\"0.35\", \"size\":\"15\", \"side\":\"BUY\", \"hash\":\"606803d650d0cf04b1a707c012c808dacc3ea2cd\", \"best_bid\":\"0.51\", \"best_ask\":\"0.52\"}, {\"asset_id\":\"39272994714739463168905443499424551362424437245880253267329605556587274644733\", \"price\":\"0.65\", \"size\":\"15\", \"side\":\"SELL\", \"hash\":\"3b05a6e85489968c1cba10d24eb224cb5ebce6f5\", \"best_bid\":\"0.48\", \"best_ask\":\"0.49\"}], \"timestamp\":\"1785203729002\", \"event_type\":\"price_change\"}","received_at":"2026-07-28T01:55:28.894009Z","schema_version":"clob-market-ws.price_change.v1","sequence":null,"server_hash":null,"server_timestamp":"1785203729002","session_id":"d2757dd6dad94f3b9fe67e8dbf1adc37","source":"clob_market_ws"},"received_at":"2026-07-28T01:55:28.894009Z","record_id":"ab436e4922c1b5e91dbfc0ff2438b2822c6f582b1098eb58d1a2f386a4800227","schema_fingerprint":"4aa3821a28b0b7c2400bc59aba4bcc0a76e971dadd19610d3ad38c768e124dc7","schema_version":"edge-lab-recorder.raw.v1","sequence":null,"source":"clob_market_ws"}
{"event_at":"2026-07-28T01:55:29.003000Z","event_fingerprint":"1392ec21c5f6f008991b2d536a9393cd577facaf6963ac7713fc22e1e7dea6f5","payload":{"connection_id":"5d29200f65794d4d9ab6ef271f045a9b","event_at":"2026-07-28T01:55:29.003000Z","event_type":"price_change","frame_hash":"e7e4fb7d1bc07eba72a3eb0e58b174c3a2f40e2da196f8facaab12ec98f7eead","frame_index":0,"kind":"data","monotonic_ns":305711906624333,"payload":{"event_type":"price_change","market":"0xda6f0e0e93fc8469e0159a166028d017bddbc162b86f66bac90391379603d962","price_changes":[{"asset_id":"20893381255801015515826997628594359667013752732428989472914000440642900266717","best_ask":"0.52","best_bid":"0.51","hash":"8e9d298b202d9bb5c941990cfaabe4ef904f2b60","price":"0.35","side":"BUY","size":"15"},{"asset_id":"39272994714739463168905443499424551362424437245880253267329605556587274644733","best_ask":"0.49","best_bid":"0.48","hash":"b731887d8cb9eccc5c619407d371152707b8ba5a","price":"0.65","side":"SELL","size":"15"}],"timestamp":"1785203729003"},"payload_hash":"d67c85565563928f22c5cfee116b9671e0b738af0eb0a32a9d709292800dfba5","raw_frame":"{\"market\":\"0xda6f0e0e93fc8469e0159a166028d017bddbc162b86f66bac90391379603d962\", \"price_changes\":[{\"asset_id\":\"20893381255801015515826997628594359667013752732428989472914000440642900266717\", \"price\":\"0.35\", \"size\":\"15\", \"side\":\"BUY\", \"hash\":\"8e9d298b202d9bb5c941990cfaabe4ef904f2b60\", \"best_bid\":\"0.51\", \"best_ask\":\"0.52\"}, {\"asset_id\":\"39272994714739463168905443499424551362424437245880253267329605556587274644733\", \"price\":\"0.65\", \"size\":\"15\", \"side\":\"SELL\", \"hash\":\"b731887d8cb9eccc5c619407d371152707b8ba5a\", \"best_bid\":\"0.48\", \"best_ask\":\"0.49\"}], \"timestamp\":\"1785203729003\", \"event_type\":\"price_change\"}","received_at":"2026-07-28T01:55:28.898298Z","schema_version":"clob-market-ws.price_change.v1","sequence":null,"server_hash":null,"server_timestamp":"1785203729003","session_id":"d2757dd6dad94f3b9fe67e8dbf1adc37","source":"clob_market_ws"},"received_at":"2026-07-28T01:55:28.898298Z","record_id":"4a1e632a939e50cf4867ff21ce5d9cf011660fe857ae1853fbfca38521220f98","schema_fingerprint":"4aa3821a28b0b7c2400bc59aba4bcc0a76e971dadd19610d3ad38c768e124dc7","schema_version":"edge-lab-recorder.raw.v1","sequence":null,"source":"clob_market_ws"}
{"event_at":"2026-07-28T01:55:30.003000Z","event_fingerprint":"2db508a0899377d876ac488f01b7535d753d3d687d155cf4d162cce11d1d507d","payload":{"connection_id":"5d29200f65794d4d9ab6ef271f045a9b","event_at":"2026-07-28T01:55:30.003000Z","event_type":"price_change","frame_hash":"10517abb911b735afd6f5f503236d676ef3a8be328656a8fede1fe20235ad5e6","frame_index":0,"kind":"data","monotonic_ns":305712904203833,"payload":{"event_type":"price_change","market":"0xda6f0e0e93fc8469e0159a166028d017bddbc162b86f66bac90391379603d962","price_changes":[{"asset_id":"39272994714739463168905443499424551362424437245880253267329605556587274644733","best_ask":"0.49","best_bid":"0.48","hash":"8af9223d947ae455a853f107755958c30dc8acef","price":"0.35","side":"BUY","size":"115"},{"asset_id":"20893381255801015515826997628594359667013752732428989472914000440642900266717","best_ask":"0.52","best_bid":"0.51","hash":"c331ef0dbee3019677b19993f6324f15ec52203a","price":"0.65","side":"SELL","size":"115"}],"timestamp":"1785203730003"},"payload_hash":"249062cc44be15763471f4925d1eda3e95b475dfb4695393358a2dc5dd46638a","raw_frame":"{\"market\":\"0xda6f0e0e93fc8469e0159a166028d017bddbc162b86f66bac90391379603d962\", \"price_changes\":[{\"asset_id\":\"39272994714739463168905443499424551362424437245880253267329605556587274644733\", \"price\":\"0.35\", \"size\":\"115\", \"side\":\"BUY\", \"hash\":\"8af9223d947ae455a853f107755958c30dc8acef\", \"best_bid\":\"0.48\", \"best_ask\":\"0.49\"}, {\"asset_id\":\"20893381255801015515826997628594359667013752732428989472914000440642900266717\", \"price\":\"0.65\", \"size\":\"115\", \"side\":\"SELL\", \"hash\":\"c331ef0dbee3019677b19993f6324f15ec52203a\", \"best_bid\":\"0.51\", \"best_ask\":\"0.52\"}], \"timestamp\":\"1785203730003\", \"event_type\":\"price_change\"}","received_at":"2026-07-28T01:55:29.895864Z","schema_version":"clob-market-ws.price_change.v1","sequence":null,"server_hash":null,"server_timestamp":"1785203730003","session_id":"d2757dd6dad94f3b9fe67e8dbf1adc37","source":"clob_market_ws"},"received_at":"2026-07-28T01:55:29.895864Z","record_id":"2c9f0d009a10a90e50594bd48ecbdb7b6371122ad15c28545ba691c21d9cd551","schema_fingerprint":"4aa3821a28b0b7c2400bc59aba4bcc0a76e971dadd19610d3ad38c768e124dc7","schema_version":"edge-lab-recorder.raw.v1","sequence":null,"source":"clob_market_ws"}
{"event_at":"2026-07-28T01:55:30.004000Z","event_fingerprint":"88570bc3a859a2f84c9b609cb70072975cca541bafa3d945efeca5b647b2de17","payload":{"connection_id":"5d29200f65794d4d9ab6ef271f045a9b","event_at":"2026-07-28T01:55:30.004000Z","event_type":"price_change","frame_hash":"c0ef52b3166c0b70ccec4b47f893542be1c6f2295f51cacdd847a17d19a9e7af","frame_index":0,"kind":"data","monotonic_ns":305712910098000,"payload":{"event_type":"price_change","market":"0xda6f0e0e93fc8469e0159a166028d017bddbc162b86f66bac90391379603d962","price_changes":[{"asset_id":"39272994714739463168905443499424551362424437245880253267329605556587274644733","best_ask":"0.49","best_bid":"0.48","hash":"417493e825ab3b2ca359a15d809d570966ddf050","price":"0.35","side":"BUY","size":"115"},{"asset_id":"20893381255801015515826997628594359667013752732428989472914000440642900266717","best_ask":"0.52","best_bid":"0.51","hash":"163e58eafb931c8d816d37690c48b48604b4372c","price":"0.65","side":"SELL","size":"115"}],"timestamp":"1785203730004"},"payload_hash":"d708645a9b39837a57e47968914570124e8b4aafe079675f5aa0362823bb1e26","raw_frame":"{\"market\":\"0xda6f0e0e93fc8469e0159a166028d017bddbc162b86f66bac90391379603d962\", \"price_changes\":[{\"asset_id\":\"39272994714739463168905443499424551362424437245880253267329605556587274644733\", \"price\":\"0.35\", \"size\":\"115\", \"side\":\"BUY\", \"hash\":\"417493e825ab3b2ca359a15d809d570966ddf050\", \"best_bid\":\"0.48\", \"best_ask\":\"0.49\"}, {\"asset_id\":\"20893381255801015515826997628594359667013752732428989472914000440642900266717\", \"price\":\"0.65\", \"size\":\"115\", \"side\":\"SELL\", \"hash\":\"163e58eafb931c8d816d37690c48b48604b4372c\", \"best_bid\":\"0.51\", \"best_ask\":\"0.52\"}], \"timestamp\":\"1785203730004\", \"event_type\":\"price_change\"}","received_at":"2026-07-28T01:55:29.901759Z","schema_version":"clob-market-ws.price_change.v1","sequence":null,"server_hash":null,"server_timestamp":"1785203730004","session_id":"d2757dd6dad94f3b9fe67e8dbf1adc37","source":"clob_market_ws"},"received_at":"2026-07-28T01:55:29.901759Z","record_id":"6608c74b5b3011a1c91effa61a5993c3ea720a4fd7d47677270fd6b2b8860093","schema_fingerprint":"4aa3821a28b0b7c2400bc59aba4bcc0a76e971dadd19610d3ad38c768e124dc7","schema_version":"edge-lab-recorder.raw.v1","sequence":null,"source":"clob_market_ws"}
{"event_at":null,"event_fingerprint":"8d9c7d8d430933e429cb65dcb7d41e178781a334b9a5c79a4ff5c01aecb2005e","payload":{"connection_id":"5d29200f65794d4d9ab6ef271f045a9b","detail":{"interval_seconds":10.0,"message":"PING"},"event_type":"heartbeat","kind":"lifecycle","monotonic_ns":305713743276083,"received_at":"2026-07-28T01:55:30.734925Z","schema_version":"edge-lab-recorder.lifecycle.v1","session_id":"d2757dd6dad94f3b9fe67e8dbf1adc37","source":"clob_market_ws"},"received_at":"2026-07-28T01:55:30.734925Z","record_id":"a9dafc00a489181561e02c7723f2807c422855a6506a27f91ac189dc212ab9d0","schema_fingerprint":"cb8aa3aa4cb168a4b724fd9077bee6ecfb9bc586c57cfdf0ab89f00d82045e3c","schema_version":"edge-lab-recorder.raw.v1","sequence":null,"source":"clob_market_ws"}
{"event_at":null,"event_fingerprint":"c3a11a95635d7e899e4b310f75e6b0dd10dc7e975b79aa12fb2b519c1df9ce1b","payload":{"connection_id":"5d29200f65794d4d9ab6ef271f045a9b","event_type":"heartbeat_ack","frame_hash":"95784973cc639977bff93619700168505cb8f7855e44fa643d34622a43706c87","kind":"lifecycle","monotonic_ns":305713971542583,"raw_frame":"PONG","received_at":"2026-07-28T01:55:30.963191Z","schema_version":"edge-lab-recorder.heartbeat-ack.v1","session_id":"d2757dd6dad94f3b9fe67e8dbf1adc37","source":"clob_market_ws"},"received_at":"2026-07-28T01:55:30.963191Z","record_id":"9b341263ffabd0c9cde4504b893ee4d39f92cdd95c15e60a95a0c248b59012ee","schema_fingerprint":"c14ee1aab3ca674ee738e5268877b544d74c41ad3c427cedc09236467dc68ba1","schema_version":"edge-lab-recorder.raw.v1","sequence":null,"source":"clob_market_ws"}
{"event_at":null,"event_fingerprint":"eee5a2feba5f888dfa12f8329c6109db64ae6f849bff88a2dff65e30336e2ac4","payload":{"connection_id":"5d29200f65794d4d9ab6ef271f045a9b","detail":{"interval_seconds":10.0,"message":"PING"},"event_type":"heartbeat","kind":"lifecycle","monotonic_ns":305723746241583,"received_at":"2026-07-28T01:55:40.737775Z","schema_version":"edge-lab-recorder.lifecycle.v1","session_id":"d2757dd6dad94f3b9fe67e8dbf1adc37","source":"clob_market_ws"},"received_at":"2026-07-28T01:55:40.737775Z","record_id":"7d03c99b38c5689593cfb55db007cc765d104ed6b5b9f92b0b3a053b0de6a7b9","schema_fingerprint":"cb8aa3aa4cb168a4b724fd9077bee6ecfb9bc586c57cfdf0ab89f00d82045e3c","schema_version":"edge-lab-recorder.raw.v1","sequence":null,"source":"clob_market_ws"}
{"event_at":null,"event_fingerprint":"7d21d1ef251c71d565cc375629a538df7f51aa1f61d688532c95f1b58601eb8b","payload":{"connection_id":"5d29200f65794d4d9ab6ef271f045a9b","event_type":"heartbeat_ack","frame_hash":"95784973cc639977bff93619700168505cb8f7855e44fa643d34622a43706c87","kind":"lifecycle","monotonic_ns":305723959779500,"raw_frame":"PONG","received_at":"2026-07-28T01:55:40.951310Z","schema_version":"edge-lab-recorder.heartbeat-ack.v1","session_id":"d2757dd6dad94f3b9fe67e8dbf1adc37","source":"clob_market_ws"},"received_at":"2026-07-28T01:55:40.951310Z","record_id":"23da8e10b71bd450365dfab9c7031229491a8c0423222f6f380a5fa883d75704","schema_fingerprint":"c14ee1aab3ca674ee738e5268877b544d74c41ad3c427cedc09236467dc68ba1","schema_version":"edge-lab-recorder.raw.v1","sequence":null,"source":"clob_market_ws"}
{"event_at":"2026-07-28T01:55:41.953000Z","event_fingerprint":"b7805aa29218d26be229cdb026c23ba111b2e37cf637f11440fd959a5dd6fac5","payload":{"connection_id":"5d29200f65794d4d9ab6ef271f045a9b","event_at":"2026-07-28T01:55:41.953000Z","event_type":"new_market","frame_hash":"303669b1858676454d5118a345c75c69ab5a848e60ed45a9b59f0b7d1ff2e743","frame_index":0,"kind":"data","monotonic_ns":305725633889333,"payload":{"active":true,"assets_ids":["27280889757160348604637486216243397154594346214618199977530055036752048064215","112460501529673969745910904384031309596855908726403438052767343856926109375819"],"clob_token_ids":["27280889757160348604637486216243397154594346214618199977530055036752048064215","112460501529673969745910904384031309596855908726403438052767343856926109375819"],"condition_id":"0x0a4c38b19065281e34fefb5c2c835ccde7d86a8b85c84036cc4a89dacc9b47db","description":"This market refers to the LoL Round 1 match between Nongshim Red Force and T1 in the KeSPA Cup Last Chance Qualifier, initially scheduled for August 3 at 6:30AM ET.\n\nThis market will resolve to \"T1\" if T1 wins 2 or more games than Nongshim Red Force in this match.\n\nOtherwise, this market will resolve to \"Nongshim Red Force\". \n\nGames won by forfeit, disqualification, walkover, or default are counted towards the handicap, provided that the match is completed.\n\nIf the match is canceled (not played at all for any reason), ends in a tie, or is delayed beyond 7 days from the scheduled date without a winner determined, this market will resolve to 50-50. \n\nIf the match begins but is not completed, and one team wins due to the opponent's match forfeiture, disqualification, or walkover, this market will resolve to 50-50. \n\nIf the match ends due to the clinching game being forfeited this will count as a completed match.\n\nThe resolution source for this market will be official information from https://gol.gg/esports/home. However, if https://gol.gg/esports/home has not published final results within 2 hours after the event’s conclusion, a consensus of credible reporting may be used instead including video evidence.","event_message":{"description":"This market refers to the LoL Round 1 match between Nongshim Red Force and T1 in the KeSPA Cup Last Chance Qualifier, initially scheduled for August 3 at 6:30AM ET.\n\nThis market will resolve to \"Nongshim Red Force\" if Nongshim Red Force win the match against T1.\n\nThis market will resolve to \"T1\" if T1 win the match against Nongshim Red Force.\n\nIf the match is canceled (not played at all), ends in a tie, or is delayed beyond 7 days from the scheduled date without a winner determined, this market will resolve to 50-50. \n\nIf the match begins but is not completed, and one team wins due to the opponent's forfeiture, disqualification, or walkover, this market will resolve to the team who wins. \n\nIf the match ends in a forfeit, disqualification, or walkover (team withdraws before the start and the other wins automatically), this market will resolve to 50-50. \n\nThe resolution source for this market will be official information from https://gol.gg/esports/home. However, if https://gol.gg/esports/home has not published final results within 2 hours after the event’s conclusion, a consensus of credible reporting may be used instead including video evidence.\n\nIn cases where a team’s listed name includes minor discrepancies from the resolution source, this market will resolve based on the underlying real-world match rather than exact name matching. Recognizable abbreviations, alternate or erroneous spellings, sponsor tags, affiliate or academy designations, regional identifiers, and minor formatting differences will be treated as referring to the same team, provided the intended team can be clearly and uniquely identified within the relevant competition. If a listed team name has no reasonable connection to any participating team, or if it matches or could reasonably refer to another team in the same competition such that the intended team cannot be unambiguously determined, this market will resolve 50-50.","id":"756182","slug":"lol-ns-t1-2026-08-03","ticker":"lol-ns-t1-2026-08-03","title":"LoL: Nongshim Red Force vs T1 (BO3) - KeSPA Cup Last Chance Qualifier"},"event_type":"new_market","fee_schedule":{"exponent":"1","rate":"0.05","rebate_rate":"0.15","taker_only":true},"fees_enabled":true,"game_start_time":"2026-08-03 10:30:00+00","group_item_title":"Game Handicap: T1 (-1.5) vs Nongshim Red Force (+1.5)","id":"3142782","line":"-1.5","market":"0x0a4c38b19065281e34fefb5c2c835ccde7d86a8b85c84036cc4a89dacc9b47db","order_price_min_tick_size":"0.01","outcomes":["T1","Nongshim Red Force"],"question":"Game Handicap: T1 (-1.5) vs Nongshim Red Force (+1.5)","slug":"lol-ns-t1-2026-08-03-game-handicap-home-1pt5","sports_market_type":"map_handicap","tags":[],"taker_base_fee":"1000","timestamp":"1785203741953"},"payload_hash":"4f96b84d0be59ccfa0a50da1e99b32fe18bfa275329da44db29805ac03d375c7","raw_frame":"{\"id\":\"3142782\", \"question\":\"Game Handicap: T1 (-1.5) vs Nongshim Red Force (+1.5)\", \"market\":\"0x0a4c38b19065281e34fefb5c2c835ccde7d86a8b85c84036cc4a89dacc9b47db\", \"slug\":\"lol-ns-t1-2026-08-03-game-handicap-home-1pt5\", \"description\":\"This market refers to the LoL Round 1 match between Nongshim Red Force and T1 in the KeSPA Cup Last Chance Qualifier, initially scheduled for August 3 at 6:30AM ET.\\n\\nThis market will resolve to \\\"T1\\\" if T1 wins 2 or more games than Nongshim Red Force in this match.\\n\\nOtherwise, this market will resolve to \\\"Nongshim Red Force\\\". \\n\\nGames won by forfeit, disqualification, walkover, or default are counted towards the handicap, provided that the match is completed.\\n\\nIf the match is canceled (not played at all for any reason), ends in a tie, or is delayed beyond 7 days from the scheduled date without a winner determined, this market will resolve to 50-50. \\n\\nIf the match begins but is not completed, and one team wins due to the opponent's match forfeiture, disqualification, or walkover, this market will resolve to 50-50. \\n\\nIf the match ends due to the clinching game being forfeited this will count as a completed match.\\n\\nThe resolution source for this market will be official information from https://gol.gg/esports/home. However, if https://gol.gg/esports/home has not published final results within 2 hours after the event’s conclusion, a consensus of credible reporting may be used instead including video evidence.\", \"assets_ids\":[\"27280889757160348604637486216243397154594346214618199977530055036752048064215\", \"112460501529673969745910904384031309596855908726403438052767343856926109375819\"], \"outcomes\":[\"T1\", \"Nongshim Red Force\"], \"event_message\":{\"id\":\"756182\", \"ticker\":\"lol-ns-t1-2026-08-03\", \"slug\":\"lol-ns-t1-2026-08-03\", \"title\":\"LoL: Nongshim Red Force vs T1 (BO3) - KeSPA Cup Last Chance Qualifier\", \"description\":\"This market refers to the LoL Round 1 match between Nongshim Red Force and T1 in the KeSPA Cup Last Chance Qualifier, initially scheduled for August 3 at 6:30AM ET.\\n\\nThis market will resolve to \\\"Nongshim Red Force\\\" if Nongshim Red Force win the match against T1.\\n\\nThis market will resolve to \\\"T1\\\" if T1 win the match against Nongshim Red Force.\\n\\nIf the match is canceled (not played at all), ends in a tie, or is delayed beyond 7 days from the scheduled date without a winner determined, this market will resolve to 50-50. \\n\\nIf the match begins but is not completed, and one team wins due to the opponent's forfeiture, disqualification, or walkover, this market will resolve to the team who wins. \\n\\nIf the match ends in a forfeit, disqualification, or walkover (team withdraws before the start and the other wins automatically), this market will resolve to 50-50. \\n\\nThe resolution source for this market will be official information from https://gol.gg/esports/home. However, if https://gol.gg/esports/home has not published final results within 2 hours after the event’s conclusion, a consensus of credible reporting may be used instead including video evidence.\\n\\nIn cases where a team’s listed name includes minor discrepancies from the resolution source, this market will resolve based on the underlying real-world match rather than exact name matching. Recognizable abbreviations, alternate or erroneous spellings, sponsor tags, affiliate or academy designations, regional identifiers, and minor formatting differences will be treated as referring to the same team, provided the intended team can be clearly and uniquely identified within the relevant competition. If a listed team name has no reasonable connection to any participating team, or if it matches or could reasonably refer to another team in the same competition such that the intended team cannot be unambiguously determined, this market will resolve 50-50.\"}, \"timestamp\":\"1785203741953\", \"event_type\":\"new_market\", \"tags\":[], \"condition_id\":\"0x0a4c38b19065281e34fefb5c2c835ccde7d86a8b85c84036cc4a89dacc9b47db\", \"active\":true, \"clob_token_ids\":[\"27280889757160348604637486216243397154594346214618199977530055036752048064215\", \"112460501529673969745910904384031309596855908726403438052767343856926109375819\"], \"sports_market_type\":\"map_handicap\", \"line\":\"-1.5\", \"game_start_time\":\"2026-08-03 10:30:00+00\", \"order_price_min_tick_size\":\"0.01\", \"group_item_title\":\"Game Handicap: T1 (-1.5) vs Nongshim Red Force (+1.5)\", \"taker_base_fee\":\"1000\", \"fees_enabled\":true, \"fee_schedule\":{\"exponent\":\"1\", \"rate\":\"0.05\", \"taker_only\":true, \"rebate_rate\":\"0.15\"}}","received_at":"2026-07-28T01:55:42.625403Z","schema_version":"clob-market-ws.new_market.v1","sequence":null,"server_hash":null,"server_timestamp":"1785203741953","session_id":"d2757dd6dad94f3b9fe67e8dbf1adc37","source":"clob_market_ws"},"received_at":"2026-07-28T01:55:42.625403Z","record_id":"5e8460cd9de7034137752e583d968a554c2a34103747b4d9356bb69eaa0e3d5f","schema_fingerprint":"6639a822a7b79cfa4c3fc0044066e4f66ba8611f5bf361772bd6902a2319b82d","schema_version":"edge-lab-recorder.raw.v1","sequence":null,"source":"clob_market_ws"}
{"event_at":null,"event_fingerprint":"9567ace27a5111bb62f3f0acee6396c34855492c7817bb17cde34a549a8d34f1","payload":{"connection_id":"5d29200f65794d4d9ab6ef271f045a9b","detail":{"interval_seconds":10.0,"message":"PING"},"event_type":"heartbeat","kind":"lifecycle","monotonic_ns":305733750250458,"received_at":"2026-07-28T01:55:50.741669Z","schema_version":"edge-lab-recorder.lifecycle.v1","session_id":"d2757dd6dad94f3b9fe67e8dbf1adc37","source":"clob_market_ws"},"received_at":"2026-07-28T01:55:50.741669Z","record_id":"33a974db54295630c2e3d01bb25479694e6043f06da7dfe709d625c79d39a46d","schema_fingerprint":"cb8aa3aa4cb168a4b724fd9077bee6ecfb9bc586c57cfdf0ab89f00d82045e3c","schema_version":"edge-lab-recorder.raw.v1","sequence":null,"source":"clob_market_ws"}
{"event_at":null,"event_fingerprint":"4a53cd47085ee564e4b42c0a92d18cf3d8b9e0d88ed187d35fabeeef00f94117","payload":{"connection_id":"5d29200f65794d4d9ab6ef271f045a9b","event_type":"heartbeat_ack","frame_hash":"95784973cc639977bff93619700168505cb8f7855e44fa643d34622a43706c87","kind":"lifecycle","monotonic_ns":305733955907583,"raw_frame":"PONG","received_at":"2026-07-28T01:55:50.947325Z","schema_version":"edge-lab-recorder.heartbeat-ack.v1","session_id":"d2757dd6dad94f3b9fe67e8dbf1adc37","source":"clob_market_ws"},"received_at":"2026-07-28T01:55:50.947325Z","record_id":"6d6f30559233e64dec76de3954e31145ee1186c7d6cc3278e1808454c6b28211","schema_fingerprint":"c14ee1aab3ca674ee738e5268877b544d74c41ad3c427cedc09236467dc68ba1","schema_version":"edge-lab-recorder.raw.v1","sequence":null,"source":"clob_market_ws"}
{"event_at":"2026-07-28T01:55:52.103000Z","event_fingerprint":"2b8e131346415889ad6bc0367b7ef2fc02cf60060763749515fb99fe0e0e1074","payload":{"connection_id":"5d29200f65794d4d9ab6ef271f045a9b","event_at":"2026-07-28T01:55:52.103000Z","event_type":"price_change","frame_hash":"b650ad3b8c09edb0efbd23f33eeca4708696f1eab6b7de58b3c45df371abb4a2","frame_index":0,"kind":"data","monotonic_ns":305735107719125,"payload":{"event_type":"price_change","market":"0xda6f0e0e93fc8469e0159a166028d017bddbc162b86f66bac90391379603d962","price_changes":[{"asset_id":"39272994714739463168905443499424551362424437245880253267329605556587274644733","best_ask":"0.49","best_bid":"0.48","hash":"b1439929d8a6620b192784d9508017e7cbd4694e","price":"0.46","side":"BUY","size":"130"},{"asset_id":"20893381255801015515826997628594359667013752732428989472914000440642900266717","best_ask":"0.52","best_bid":"0.51","hash":"cb7e9ce0f60bc54f8f4bb1155246459e85b41e85","price":"0.54","side":"SELL","size":"130"}],"timestamp":"1785203752103"},"payload_hash":"8da6c83b5391797993b1060fe1e849ab3e3dc19d3493932d201e93941ac7df8e","raw_frame":"{\"market\":\"0xda6f0e0e93fc8469e0159a166028d017bddbc162b86f66bac90391379603d962\", \"price_changes\":[{\"asset_id\":\"39272994714739463168905443499424551362424437245880253267329605556587274644733\", \"price\":\"0.46\", \"size\":\"130\", \"side\":\"BUY\", \"hash\":\"b1439929d8a6620b192784d9508017e7cbd4694e\", \"best_bid\":\"0.48\", \"best_ask\":\"0.49\"}, {\"asset_id\":\"20893381255801015515826997628594359667013752732428989472914000440642900266717\", \"price\":\"0.54\", \"size\":\"130\", \"side\":\"SELL\", \"hash\":\"cb7e9ce0f60bc54f8f4bb1155246459e85b41e85\", \"best_bid\":\"0.51\", \"best_ask\":\"0.52\"}], \"timestamp\":\"1785203752103\", \"event_type\":\"price_change\"}","received_at":"2026-07-28T01:55:52.099123Z","schema_version":"clob-market-ws.price_change.v1","sequence":null,"server_hash":null,"server_timestamp":"1785203752103","session_id":"d2757dd6dad94f3b9fe67e8dbf1adc37","source":"clob_market_ws"},"received_at":"2026-07-28T01:55:52.099123Z","record_id":"2eab651317dba5491928d0baeb366a73f8f08490f04951536fc17f70f4babdab","schema_fingerprint":"4aa3821a28b0b7c2400bc59aba4bcc0a76e971dadd19610d3ad38c768e124dc7","schema_version":"edge-lab-recorder.raw.v1","sequence":null,"source":"clob_market_ws"}
{"event_at":"2026-07-28T01:55:52.110000Z","event_fingerprint":"ca6c7f77ba5f6cb58c965bbeb394ff1c17d095f1de41ba0eed5776ff2bd4494d","payload":{"connection_id":"5d29200f65794d4d9ab6ef271f045a9b","event_at":"2026-07-28T01:55:52.110000Z","event_type":"price_change","frame_hash":"591c14b8d40d48acf3f46956acfff1b3be8a6bee145fb8c262aa3f62e2b27bdb","frame_index":0,"kind":"data","monotonic_ns":305735112412625,"payload":{"event_type":"price_change","market":"0xda6f0e0e93fc8469e0159a166028d017bddbc162b86f66bac90391379603d962","price_changes":[{"asset_id":"39272994714739463168905443499424551362424437245880253267329605556587274644733","best_ask":"0.49","best_bid":"0.48","hash":"8ec37b2d82251fcf7f60c33826988c3ca899085c","price":"0.46","side":"BUY","size":"30"},{"asset_id":"20893381255801015515826997628594359667013752732428989472914000440642900266717","best_ask":"0.52","best_bid":"0.51","hash":"bc7130aa98e0d79bd7fde53d217969a08d328503","price":"0.54","side":"SELL","size":"30"}],"timestamp":"1785203752110"},"payload_hash":"1aa694c9bba6bd17e6b11ec1fce17bbcd297ce1a5b24f8fa7266b360493305e6","raw_frame":"{\"market\":\"0xda6f0e0e93fc8469e0159a166028d017bddbc162b86f66bac90391379603d962\", \"price_changes\":[{\"asset_id\":\"39272994714739463168905443499424551362424437245880253267329605556587274644733\", \"price\":\"0.46\", \"size\":\"30\", \"side\":\"BUY\", \"hash\":\"8ec37b2d82251fcf7f60c33826988c3ca899085c\", \"best_bid\":\"0.48\", \"best_ask\":\"0.49\"}, {\"asset_id\":\"20893381255801015515826997628594359667013752732428989472914000440642900266717\", \"price\":\"0.54\", \"size\":\"30\", \"side\":\"SELL\", \"hash\":\"bc7130aa98e0d79bd7fde53d217969a08d328503\", \"best_bid\":\"0.51\", \"best_ask\":\"0.52\"}], \"timestamp\":\"1785203752110\", \"event_type\":\"price_change\"}","received_at":"2026-07-28T01:55:52.103818Z","schema_version":"clob-market-ws.price_change.v1","sequence":null,"server_hash":null,"server_timestamp":"1785203752110","session_id":"d2757dd6dad94f3b9fe67e8dbf1adc37","source":"clob_market_ws"},"received_at":"2026-07-28T01:55:52.103818Z","record_id":"b9828e1169ba611fedcbc51b0ef7bc337f8c40b7d855bc424aad9a2a66502c74","schema_fingerprint":"4aa3821a28b0b7c2400bc59aba4bcc0a76e971dadd19610d3ad38c768e124dc7","schema_version":"edge-lab-recorder.raw.v1","sequence":null,"source":"clob_market_ws"}
{"event_at":"2026-07-28T01:55:52.161000Z","event_fingerprint":"0edde0cf971a54ac1a66ad2b2fb7c75b7373001cdc2748940aeb2ee78a3a32e4","payload":{"connection_id":"5d29200f65794d4d9ab6ef271f045a9b","event_at":"2026-07-28T01:55:52.161000Z","event_type":"price_change","frame_hash":"9f344a3c1dc1fe8bddf278a0b860441f065e265455e9552e1cd4cf1da325af40","frame_index":0,"kind":"data","monotonic_ns":305735120884583,"payload":{"event_type":"price_change","market":"0xda6f0e0e93fc8469e0159a166028d017bddbc162b86f66bac90391379603d962","price_changes":[{"asset_id":"39272994714739463168905443499424551362424437245880253267329605556587274644733","best_ask":"0.49","best_bid":"0.48","hash":"cbcbe47f7b0b50a8500145778cd8c92cd6db68a0","price":"0.43","side":"BUY","size":"120"},{"asset_id":"20893381255801015515826997628594359667013752732428989472914000440642900266717","best_ask":"0.52","best_bid":"0.51","hash":"61b396f26e1e3efd05b1faa1db8059df123c0a0f","price":"0.57","side":"SELL","size":"120"}],"timestamp":"1785203752161"},"payload_hash":"fcd93bfe29a92c9c54977cc849ca7ece208181f969165972c964cd3ab33f3501","raw_frame":"{\"market\":\"0xda6f0e0e93fc8469e0159a166028d017bddbc162b86f66bac90391379603d962\", \"price_changes\":[{\"asset_id\":\"39272994714739463168905443499424551362424437245880253267329605556587274644733\", \"price\":\"0.43\", \"size\":\"120\", \"side\":\"BUY\", \"hash\":\"cbcbe47f7b0b50a8500145778cd8c92cd6db68a0\", \"best_bid\":\"0.48\", \"best_ask\":\"0.49\"}, {\"asset_id\":\"20893381255801015515826997628594359667013752732428989472914000440642900266717\", \"price\":\"0.57\", \"size\":\"120\", \"side\":\"SELL\", \"hash\":\"61b396f26e1e3efd05b1faa1db8059df123c0a0f\", \"best_bid\":\"0.51\", \"best_ask\":\"0.52\"}], \"timestamp\":\"1785203752161\", \"event_type\":\"price_change\"}","received_at":"2026-07-28T01:55:52.112289Z","schema_version":"clob-market-ws.price_change.v1","sequence":null,"server_hash":null,"server_timestamp":"1785203752161","session_id":"d2757dd6dad94f3b9fe67e8dbf1adc37","source":"clob_market_ws"},"received_at":"2026-07-28T01:55:52.112289Z","record_id":"1fa30c40e13dd2bc759dbc390211c53b690115b5010ca63dbfd89de960e11b3e","schema_fingerprint":"4aa3821a28b0b7c2400bc59aba4bcc0a76e971dadd19610d3ad38c768e124dc7","schema_version":"edge-lab-recorder.raw.v1","sequence":null,"source":"clob_market_ws"}
{"event_at":"2026-07-28T01:55:52.162000Z","event_fingerprint":"5431a21781a7ae48e3b1fae318b5285acf07c88bf8f920b7b6cf0cc7c6b0491a","payload":{"connection_id":"5d29200f65794d4d9ab6ef271f045a9b","event_at":"2026-07-28T01:55:52.162000Z","event_type":"price_change","frame_hash":"b0f4dfdd64b495c3dad84bc4d210b6b4c730c3460bc93cc927dd31673bfa63bd","frame_index":0,"kind":"data","monotonic_ns":305735127283250,"payload":{"event_type":"price_change","market":"0xda6f0e0e93fc8469e0159a166028d017bddbc162b86f66bac90391379603d962","price_changes":[{"asset_id":"39272994714739463168905443499424551362424437245880253267329605556587274644733","best_ask":"0.49","best_bid":"0.48","hash":"8f536b04a68f9d6507c774c89b83868f58249827","price":"0.43","side":"BUY","size":"125"},{"asset_id":"20893381255801015515826997628594359667013752732428989472914000440642900266717","best_ask":"0.52","best_bid":"0.51","hash":"eb4bc2869e299484153f5bf4161f39b92a62f40d","price":"0.57","side":"SELL","size":"125"}],"timestamp":"1785203752162"},"payload_hash":"7798a338c2d44420c9eba6b45162533b55f577ba4d940c10a754c90fc8aeb321","raw_frame":"{\"market\":\"0xda6f0e0e93fc8469e0159a166028d017bddbc162b86f66bac90391379603d962\", \"price_changes\":[{\"asset_id\":\"39272994714739463168905443499424551362424437245880253267329605556587274644733\", \"price\":\"0.43\", \"size\":\"125\", \"side\":\"BUY\", \"hash\":\"8f536b04a68f9d6507c774c89b83868f58249827\", \"best_bid\":\"0.48\", \"best_ask\":\"0.49\"}, {\"asset_id\":\"20893381255801015515826997628594359667013752732428989472914000440642900266717\", \"price\":\"0.57\", \"size\":\"125\", \"side\":\"SELL\", \"hash\":\"eb4bc2869e299484153f5bf4161f39b92a62f40d\", \"best_bid\":\"0.51\", \"best_ask\":\"0.52\"}], \"timestamp\":\"1785203752162\", \"event_type\":\"price_change\"}","received_at":"2026-07-28T01:55:52.118688Z","schema_version":"clob-market-ws.price_change.v1","sequence":null,"server_hash":null,"server_timestamp":"1785203752162","session_id":"d2757dd6dad94f3b9fe67e8dbf1adc37","source":"clob_market_ws"},"received_at":"2026-07-28T01:55:52.118688Z","record_id":"963cada7a08a40212f322ee6a56482b183ef942ba029f1707e23b54253d13502","schema_fingerprint":"4aa3821a28b0b7c2400bc59aba4bcc0a76e971dadd19610d3ad38c768e124dc7","schema_version":"edge-lab-recorder.raw.v1","sequence":null,"source":"clob_market_ws"}
{"event_at":"2026-07-28T01:55:52.163000Z","event_fingerprint":"e308b1342730d887dc994eb77171066d706680fb50eb8a5bf53935b77505d7a0","payload":{"connection_id":"5d29200f65794d4d9ab6ef271f045a9b","event_at":"2026-07-28T01:55:52.163000Z","event_type":"price_change","frame_hash":"2b85aba7b0bfdadaeae3578de4f98b653d3b57e929e14e97f795f1f015de68e2","frame_index":0,"kind":"data","monotonic_ns":305735132954875,"payload":{"event_type":"price_change","market":"0xda6f0e0e93fc8469e0159a166028d017bddbc162b86f66bac90391379603d962","price_changes":[{"asset_id":"39272994714739463168905443499424551362424437245880253267329605556587274644733","best_ask":"0.49","best_bid":"0.48","hash":"8212625915ba8577a48266ed435fc28808f63489","price":"0.43","side":"BUY","size":"130"},{"asset_id":"20893381255801015515826997628594359667013752732428989472914000440642900266717","best_ask":"0.52","best_bid":"0.51","hash":"878790e5448f626c2b2252ea9336566ca6c605d4","price":"0.57","side":"SELL","size":"130"}],"timestamp":"1785203752163"},"payload_hash":"47c452dbc35bb59ce696d6bcc1b5d8c1ef3d191484d1377e3411a05e8db245be","raw_frame":"{\"market\":\"0xda6f0e0e93fc8469e0159a166028d017bddbc162b86f66bac90391379603d962\", \"price_changes\":[{\"asset_id\":\"39272994714739463168905443499424551362424437245880253267329605556587274644733\", \"price\":\"0.43\", \"size\":\"130\", \"side\":\"BUY\", \"hash\":\"8212625915ba8577a48266ed435fc28808f63489\", \"best_bid\":\"0.48\", \"best_ask\":\"0.49\"}, {\"asset_id\":\"20893381255801015515826997628594359667013752732428989472914000440642900266717\", \"price\":\"0.57\", \"size\":\"130\", \"side\":\"SELL\", \"hash\":\"878790e5448f626c2b2252ea9336566ca6c605d4\", \"best_bid\":\"0.51\", \"best_ask\":\"0.52\"}], \"timestamp\":\"1785203752163\", \"event_type\":\"price_change\"}","received_at":"2026-07-28T01:55:52.124360Z","schema_version":"clob-market-ws.price_change.v1","sequence":null,"server_hash":null,"server_timestamp":"1785203752163","session_id":"d2757dd6dad94f3b9fe67e8dbf1adc37","source":"clob_market_ws"},"received_at":"2026-07-28T01:55:52.124360Z","record_id":"5689eb4a70bfb2a5d0aa6a12066b27b7b60c727b76f588dae7881a2df78c32b3","schema_fingerprint":"4aa3821a28b0b7c2400bc59aba4bcc0a76e971dadd19610d3ad38c768e124dc7","schema_version":"edge-lab-recorder.raw.v1","sequence":null,"source":"clob_market_ws"}
{"event_at":"2026-07-28T01:55:52.164000Z","event_fingerprint":"0288782506645fa89e38068184c44f44a8308e3fb44171f7cb0660556fd1a471","payload":{"connection_id":"5d29200f65794d4d9ab6ef271f045a9b","event_at":"2026-07-28T01:55:52.164000Z","event_type":"price_change","frame_hash":"f460f72fd3eec0a560a7ec0d5fb33086802c4beb8ad9da2e79db7a27163abe19","frame_index":0,"kind":"data","monotonic_ns":305735138205875,"payload":{"event_type":"price_change","market":"0xda6f0e0e93fc8469e0159a166028d017bddbc162b86f66bac90391379603d962","price_changes":[{"asset_id":"39272994714739463168905443499424551362424437245880253267329605556587274644733","best_ask":"0.49","best_bid":"0.48","hash":"4c856edd070c59cbeb014be73da33c5bc4828d6e","price":"0.43","side":"BUY","size":"135"},{"asset_id":"20893381255801015515826997628594359667013752732428989472914000440642900266717","best_ask":"0.52","best_bid":"0.51","hash":"fe252d0a31897ec82c3add03a2169df99619139e","price":"0.57","side":"SELL","size":"135"}],"timestamp":"1785203752164"},"payload_hash":"138163aefeaa118fbfb7353ec5c16d713f17d5622839cf222cf498985a2cd9ef","raw_frame":"{\"market\":\"0xda6f0e0e93fc8469e0159a166028d017bddbc162b86f66bac90391379603d962\", \"price_changes\":[{\"asset_id\":\"39272994714739463168905443499424551362424437245880253267329605556587274644733\", \"price\":\"0.43\", \"size\":\"135\", \"side\":\"BUY\", \"hash\":\"4c856edd070c59cbeb014be73da33c5bc4828d6e\", \"best_bid\":\"0.48\", \"best_ask\":\"0.49\"}, {\"asset_id\":\"20893381255801015515826997628594359667013752732428989472914000440642900266717\", \"price\":\"0.57\", \"size\":\"135\", \"side\":\"SELL\", \"hash\":\"fe252d0a31897ec82c3add03a2169df99619139e\", \"best_bid\":\"0.51\", \"best_ask\":\"0.52\"}], \"timestamp\":\"1785203752164\", \"event_type\":\"price_change\"}","received_at":"2026-07-28T01:55:52.129611Z","schema_version":"clob-market-ws.price_change.v1","sequence":null,"server_hash":null,"server_timestamp":"1785203752164","session_id":"d2757dd6dad94f3b9fe67e8dbf1adc37","source":"clob_market_ws"},"received_at":"2026-07-28T01:55:52.129611Z","record_id":"e699b44255d49c323f21f8a8bbf236c616461e6bd604af5c01a139e293da2cb2","schema_fingerprint":"4aa3821a28b0b7c2400bc59aba4bcc0a76e971dadd19610d3ad38c768e124dc7","schema_version":"edge-lab-recorder.raw.v1","sequence":null,"source":"clob_market_ws"}
{"event_at":"2026-07-28T01:55:52.165000Z","event_fingerprint":"51538b0dd99bad5f3eeb38275ba38e39aaa55813942b6ba42a1a0707bb8dd249","payload":{"connection_id":"5d29200f65794d4d9ab6ef271f045a9b","event_at":"2026-07-28T01:55:52.165000Z","event_type":"price_change","frame_hash":"6a4a69d9f800fb559321e217fb51296029c41cd1c2a78587200fd82970b9cb5e","frame_index":0,"kind":"data","monotonic_ns":305735143456291,"payload":{"event_type":"price_change","market":"0xda6f0e0e93fc8469e0159a166028d017bddbc162b86f66bac90391379603d962","price_changes":[{"asset_id":"39272994714739463168905443499424551362424437245880253267329605556587274644733","best_ask":"0.49","best_bid":"0.48","hash":"dde601b83f6b76dd9f5d13d34be9601972552cf3","price":"0.43","side":"BUY","size":"140"},{"asset_id":"20893381255801015515826997628594359667013752732428989472914000440642900266717","best_ask":"0.52","best_bid":"0.51","hash":"b012ecd6c1f488a2360386015e1caadfe60a135a","price":"0.57","side":"SELL","size":"140"}],"timestamp":"1785203752165"},"payload_hash":"d7ab13a96634e6028a0de2bcc15d3fa6660e69ded991656128410949e761a6a4","raw_frame":"{\"market\":\"0xda6f0e0e93fc8469e0159a166028d017bddbc162b86f66bac90391379603d962\", \"price_changes\":[{\"asset_id\":\"39272994714739463168905443499424551362424437245880253267329605556587274644733\", \"price\":\"0.43\", \"size\":\"140\", \"side\":\"BUY\", \"hash\":\"dde601b83f6b76dd9f5d13d34be9601972552cf3\", \"best_bid\":\"0.48\", \"best_ask\":\"0.49\"}, {\"asset_id\":\"20893381255801015515826997628594359667013752732428989472914000440642900266717\", \"price\":\"0.57\", \"size\":\"140\", \"side\":\"SELL\", \"hash\":\"b012ecd6c1f488a2360386015e1caadfe60a135a\", \"best_bid\":\"0.51\", \"best_ask\":\"0.52\"}], \"timestamp\":\"1785203752165\", \"event_type\":\"price_change\"}","received_at":"2026-07-28T01:55:52.134861Z","schema_version":"clob-market-ws.price_change.v1","sequence":null,"server_hash":null,"server_timestamp":"1785203752165","session_id":"d2757dd6dad94f3b9fe67e8dbf1adc37","source":"clob_market_ws"},"received_at":"2026-07-28T01:55:52.134861Z","record_id":"2e13b23f702711c8aadb262e634b4bc4cef7f2f64121a0e2f8de8825a5aabaea","schema_fingerprint":"4aa3821a28b0b7c2400bc59aba4bcc0a76e971dadd19610d3ad38c768e124dc7","schema_version":"edge-lab-recorder.raw.v1","sequence":null,"source":"clob_market_ws"}
{"event_at":"2026-07-28T01:55:52.170000Z","event_fingerprint":"b9add246c3f38043f7f64b3e649bf862272e30f3ba0560c3930257d5710166fd","payload":{"connection_id":"5d29200f65794d4d9ab6ef271f045a9b","event_at":"2026-07-28T01:55:52.170000Z","event_type":"price_change","frame_hash":"bc24fac40ca52f33c56234dce43c7342c5f52717b696922894d777b31dc2a1a2","frame_index":0,"kind":"data","monotonic_ns":305735148560833,"payload":{"event_type":"price_change","market":"0xda6f0e0e93fc8469e0159a166028d017bddbc162b86f66bac90391379603d962","price_changes":[{"asset_id":"39272994714739463168905443499424551362424437245880253267329605556587274644733","best_ask":"0.49","best_bid":"0.48","hash":"637025d1b669bf223acaef6898a3e14b64d423b7","price":"0.43","side":"BUY","size":"145"},{"asset_id":"20893381255801015515826997628594359667013752732428989472914000440642900266717","best_ask":"0.52","best_bid":"0.51","hash":"796f9bd19d2b0d4ebbb58fd49f24dd5d35c1d4c1","price":"0.57","side":"SELL","size":"145"}],"timestamp":"1785203752170"},"payload_hash":"88087b7def7c8e037636d17a1de846377f571d83d7a3c523480dee11cd91d78d","raw_frame":"{\"market\":\"0xda6f0e0e93fc8469e0159a166028d017bddbc162b86f66bac90391379603d962\", \"price_changes\":[{\"asset_id\":\"39272994714739463168905443499424551362424437245880253267329605556587274644733\", \"price\":\"0.43\", \"size\":\"145\", \"side\":\"BUY\", \"hash\":\"637025d1b669bf223acaef6898a3e14b64d423b7\", \"best_bid\":\"0.48\", \"best_ask\":\"0.49\"}, {\"asset_id\":\"20893381255801015515826997628594359667013752732428989472914000440642900266717\", \"price\":\"0.57\", \"size\":\"145\", \"side\":\"SELL\", \"hash\":\"796f9bd19d2b0d4ebbb58fd49f24dd5d35c1d4c1\", \"best_bid\":\"0.51\", \"best_ask\":\"0.52\"}], \"timestamp\":\"1785203752170\", \"event_type\":\"price_change\"}","received_at":"2026-07-28T01:55:52.139965Z","schema_version":"clob-market-ws.price_change.v1","sequence":null,"server_hash":null,"server_timestamp":"1785203752170","session_id":"d2757dd6dad94f3b9fe67e8dbf1adc37","source":"clob_market_ws"},"received_at":"2026-07-28T01:55:52.139965Z","record_id":"fc273f11fa03e20b6275adf238e45f86f8359874582bb00649cf01aecedc82ec","schema_fingerprint":"4aa3821a28b0b7c2400bc59aba4bcc0a76e971dadd19610d3ad38c768e124dc7","schema_version":"edge-lab-recorder.raw.v1","sequence":null,"source":"clob_market_ws"}
{"event_at":"2026-07-28T01:55:52.171000Z","event_fingerprint":"787eaab8d708bfd6d88a7e52690f970582ed270f9ffdff4f172a3d1d2f5df1ae","payload":{"connection_id":"5d29200f65794d4d9ab6ef271f045a9b","event_at":"2026-07-28T01:55:52.171000Z","event_type":"price_change","frame_hash":"d94bc5e09be42127a05ba3ebe7b9cbf587221aabb9c8111a1c0e8fac426c8e1d","frame_index":0,"kind":"data","monotonic_ns":305735152666750,"payload":{"event_type":"price_change","market":"0xda6f0e0e93fc8469e0159a166028d017bddbc162b86f66bac90391379603d962","price_changes":[{"asset_id":"39272994714739463168905443499424551362424437245880253267329605556587274644733","best_ask":"0.49","best_bid":"0.48","hash":"73c454b2f3376603955d8e573ead5f1531dccc87","price":"0.43","side":"BUY","size":"150"},{"asset_id":"20893381255801015515826997628594359667013752732428989472914000440642900266717","best_ask":"0.52","best_bid":"0.51","hash":"95f0a6657ebf2d810e12537315e8494b0468fe4f","price":"0.57","side":"SELL","size":"150"}],"timestamp":"1785203752171"},"payload_hash":"4d1845286a0adbbef996078644c12ebf472344c2a17a763f34cb331ba67afd00","raw_frame":"{\"market\":\"0xda6f0e0e93fc8469e0159a166028d017bddbc162b86f66bac90391379603d962\", \"price_changes\":[{\"asset_id\":\"39272994714739463168905443499424551362424437245880253267329605556587274644733\", \"price\":\"0.43\", \"size\":\"150\", \"side\":\"BUY\", \"hash\":\"73c454b2f3376603955d8e573ead5f1531dccc87\", \"best_bid\":\"0.48\", \"best_ask\":\"0.49\"}, {\"asset_id\":\"20893381255801015515826997628594359667013752732428989472914000440642900266717\", \"price\":\"0.57\", \"size\":\"150\", \"side\":\"SELL\", \"hash\":\"95f0a6657ebf2d810e12537315e8494b0468fe4f\", \"best_bid\":\"0.51\", \"best_ask\":\"0.52\"}], \"timestamp\":\"1785203752171\", \"event_type\":\"price_change\"}","received_at":"2026-07-28T01:55:52.144072Z","schema_version":"clob-market-ws.price_change.v1","sequence":null,"server_hash":null,"server_timestamp":"1785203752171","session_id":"d2757dd6dad94f3b9fe67e8dbf1adc37","source":"clob_market_ws"},"received_at":"2026-07-28T01:55:52.144072Z","record_id":"3b487b4ff80bc34c0a86818f1e7211404bd668566d4afbc9ce6fe6a2a2c2bb2e","schema_fingerprint":"4aa3821a28b0b7c2400bc59aba4bcc0a76e971dadd19610d3ad38c768e124dc7","schema_version":"edge-lab-recorder.raw.v1","sequence":null,"source":"clob_market_ws"}
{"event_at":"2026-07-28T01:55:52.172000Z","event_fingerprint":"b839cce5e012b5238b3480b1da9a995e89b72012b84571f4264e6ea9e42b71aa","payload":{"connection_id":"5d29200f65794d4d9ab6ef271f045a9b","event_at":"2026-07-28T01:55:52.172000Z","event_type":"price_change","frame_hash":"5cdc27eeb988f29e290965fde88a5adca303b366bfff73f1060a77ac76072179","frame_index":0,"kind":"data","monotonic_ns":305735156592625,"payload":{"event_type":"price_change","market":"0xda6f0e0e93fc8469e0159a166028d017bddbc162b86f66bac90391379603d962","price_changes":[{"asset_id":"39272994714739463168905443499424551362424437245880253267329605556587274644733","best_ask":"0.49","best_bid":"0.48","hash":"52e64b3e52b49eb81d3dc01d809d7147a179d21e","price":"0.43","side":"BUY","size":"155"},{"asset_id":"20893381255801015515826997628594359667013752732428989472914000440642900266717","best_ask":"0.52","best_bid":"0.51","hash":"bf48bd3961d497d9078d31fb3b3617f041c339fd","price":"0.57","side":"SELL","size":"155"}],"timestamp":"1785203752172"},"payload_hash":"80013c097ef2f23c5235ecc757abc5ce50e56ca32b72ca4e894c170d8262ae80","raw_frame":"{\"market\":\"0xda6f0e0e93fc8469e0159a166028d017bddbc162b86f66bac90391379603d962\", \"price_changes\":[{\"asset_id\":\"39272994714739463168905443499424551362424437245880253267329605556587274644733\", \"price\":\"0.43\", \"size\":\"155\", \"side\":\"BUY\", \"hash\":\"52e64b3e52b49eb81d3dc01d809d7147a179d21e\", \"best_bid\":\"0.48\", \"best_ask\":\"0.49\"}, {\"asset_id\":\"20893381255801015515826997628594359667013752732428989472914000440642900266717\", \"price\":\"0.57\", \"size\":\"155\", \"side\":\"SELL\", \"hash\":\"bf48bd3961d497d9078d31fb3b3617f041c339fd\", \"best_bid\":\"0.51\", \"best_ask\":\"0.52\"}], \"timestamp\":\"1785203752172\", \"event_type\":\"price_change\"}","received_at":"2026-07-28T01:55:52.147997Z","schema_version":"clob-market-ws.price_change.v1","sequence":null,"server_hash":null,"server_timestamp":"1785203752172","session_id":"d2757dd6dad94f3b9fe67e8dbf1adc37","source":"clob_market_ws"},"received_at":"2026-07-28T01:55:52.147997Z","record_id":"3c533ea3aa250dde75166ee53afe6ac174c93b3a69442bc0a37e9a36f5f9e956","schema_fingerprint":"4aa3821a28b0b7c2400bc59aba4bcc0a76e971dadd19610d3ad38c768e124dc7","schema_version":"edge-lab-recorder.raw.v1","sequence":null,"source":"clob_market_ws"}
{"event_at":"2026-07-28T01:55:52.173000Z","event_fingerprint":"5d0ebd38b56928caa7f5323456529e13ad50fec62bb05195e072b9279799b20d","payload":{"connection_id":"5d29200f65794d4d9ab6ef271f045a9b","event_at":"2026-07-28T01:55:52.173000Z","event_type":"price_change","frame_hash":"f9f4f8276a60d49bc092d4be2e4e8e14894a5ccf6a79738decaaa87f63c2dc4d","frame_index":0,"kind":"data","monotonic_ns":305735160672083,"payload":{"event_type":"price_change","market":"0xda6f0e0e93fc8469e0159a166028d017bddbc162b86f66bac90391379603d962","price_changes":[{"asset_id":"39272994714739463168905443499424551362424437245880253267329605556587274644733","best_ask":"0.49","best_bid":"0.48","hash":"9b1db71a06094585b4792cdcacea72aa6f4a196e","price":"0.43","side":"BUY","size":"160"},{"asset_id":"20893381255801015515826997628594359667013752732428989472914000440642900266717","best_ask":"0.52","best_bid":"0.51","hash":"4099a4c3b34f1368b2cac15e704b7903dfb96fc8","price":"0.57","side":"SELL","size":"160"}],"timestamp":"1785203752173"},"payload_hash":"4c42e7f78c928454fade070b6561f5975c9b0c00c3cb4615cd8cc2eca7ca7d07","raw_frame":"{\"market\":\"0xda6f0e0e93fc8469e0159a166028d017bddbc162b86f66bac90391379603d962\", \"price_changes\":[{\"asset_id\":\"39272994714739463168905443499424551362424437245880253267329605556587274644733\", \"price\":\"0.43\", \"size\":\"160\", \"side\":\"BUY\", \"hash\":\"9b1db71a06094585b4792cdcacea72aa6f4a196e\", \"best_bid\":\"0.48\", \"best_ask\":\"0.49\"}, {\"asset_id\":\"20893381255801015515826997628594359667013752732428989472914000440642900266717\", \"price\":\"0.57\", \"size\":\"160\", \"side\":\"SELL\", \"hash\":\"4099a4c3b34f1368b2cac15e704b7903dfb96fc8\", \"best_bid\":\"0.51\", \"best_ask\":\"0.52\"}], \"timestamp\":\"1785203752173\", \"event_type\":\"price_change\"}","received_at":"2026-07-28T01:55:52.152077Z","schema_version":"clob-market-ws.price_change.v1","sequence":null,"server_hash":null,"server_timestamp":"1785203752173","session_id":"d2757dd6dad94f3b9fe67e8dbf1adc37","source":"clob_market_ws"},"received_at":"2026-07-28T01:55:52.152077Z","record_id":"9b7e123ca074278b5bbef8be0afb70ae687751bff90028309efdc6628742ec77","schema_fingerprint":"4aa3821a28b0b7c2400bc59aba4bcc0a76e971dadd19610d3ad38c768e124dc7","schema_version":"edge-lab-recorder.raw.v1","sequence":null,"source":"clob_market_ws"}
{"event_at":"2026-07-28T01:55:52.174000Z","event_fingerprint":"cdbc293e987fdda5ef892678e3cde8fe9b61af822fb97cb8ade068bcd3cded61","payload":{"connection_id":"5d29200f65794d4d9ab6ef271f045a9b","event_at":"2026-07-28T01:55:52.174000Z","event_type":"price_change","frame_hash":"2e8aca0183f1387ea684813ea5154ac759bbc40567c4bc30f2fe800b9f77fd39","frame_index":0,"kind":"data","monotonic_ns":305735164985708,"payload":{"event_type":"price_change","market":"0xda6f0e0e93fc8469e0159a166028d017bddbc162b86f66bac90391379603d962","price_changes":[{"asset_id":"39272994714739463168905443499424551362424437245880253267329605556587274644733","best_ask":"0.49","best_bid":"0.48","hash":"c18f74b340e92f29675a1b05a669482c8cb65198","price":"0.43","side":"BUY","size":"165"},{"asset_id":"20893381255801015515826997628594359667013752732428989472914000440642900266717","best_ask":"0.52","best_bid":"0.51","hash":"c24a96ab7d7893e5d36c359077092ccf6020c931","price":"0.57","side":"SELL","size":"165"}],"timestamp":"1785203752174"},"payload_hash":"3a1a832f8448835cf99cc698dfe918c0b4caa28696dd3d89c942d4d1567a1723","raw_frame":"{\"market\":\"0xda6f0e0e93fc8469e0159a166028d017bddbc162b86f66bac90391379603d962\", \"price_changes\":[{\"asset_id\":\"39272994714739463168905443499424551362424437245880253267329605556587274644733\", \"price\":\"0.43\", \"size\":\"165\", \"side\":\"BUY\", \"hash\":\"c18f74b340e92f29675a1b05a669482c8cb65198\", \"best_bid\":\"0.48\", \"best_ask\":\"0.49\"}, {\"asset_id\":\"20893381255801015515826997628594359667013752732428989472914000440642900266717\", \"price\":\"0.57\", \"size\":\"165\", \"side\":\"SELL\", \"hash\":\"c24a96ab7d7893e5d36c359077092ccf6020c931\", \"best_bid\":\"0.51\", \"best_ask\":\"0.52\"}], \"timestamp\":\"1785203752174\", \"event_type\":\"price_change\"}","received_at":"2026-07-28T01:55:52.156391Z","schema_version":"clob-market-ws.price_change.v1","sequence":null,"server_hash":null,"server_timestamp":"1785203752174","session_id":"d2757dd6dad94f3b9fe67e8dbf1adc37","source":"clob_market_ws"},"received_at":"2026-07-28T01:55:52.156391Z","record_id":"765a10b17fa5861506a051cfab8d787003b54e120fbcce7f98610604072a013a","schema_fingerprint":"4aa3821a28b0b7c2400bc59aba4bcc0a76e971dadd19610d3ad38c768e124dc7","schema_version":"edge-lab-recorder.raw.v1","sequence":null,"source":"clob_market_ws"}
{"event_at":"2026-07-28T01:55:52.208000Z","event_fingerprint":"8c0df1a4470a046a88e66a2514130a607dfd15e261f4bf1e40b4c429de2bfafe","payload":{"connection_id":"5d29200f65794d4d9ab6ef271f045a9b","event_at":"2026-07-28T01:55:52.208000Z","event_type":"price_change","frame_hash":"f53e33a6358c40aede71e5aa1044e39c40396ab40244d24825c9fcfeffeb4f42","frame_index":0,"kind":"data","monotonic_ns":305735297279250,"payload":{"event_type":"price_change","market":"0xda6f0e0e93fc8469e0159a166028d017bddbc162b86f66bac90391379603d962","price_changes":[{"asset_id":"39272994714739463168905443499424551362424437245880253267329605556587274644733","best_ask":"0.49","best_bid":"0.48","hash":"96d7670b84c7df626b0373af16f87739d39eff62","price":"0.43","side":"BUY","size":"170"},{"asset_id":"20893381255801015515826997628594359667013752732428989472914000440642900266717","best_ask":"0.52","best_bid":"0.51","hash":"74fd129ff5e16128a4ce01abbf5a3a4fd1579739","price":"0.57","side":"SELL","size":"170"}],"timestamp":"1785203752208"},"payload_hash":"6618ec25f731c8d537d199e8a4e7dd626c4f14ecbb649e10a5869c079090439d","raw_frame":"{\"market\":\"0xda6f0e0e93fc8469e0159a166028d017bddbc162b86f66bac90391379603d962\", \"price_changes\":[{\"asset_id\":\"39272994714739463168905443499424551362424437245880253267329605556587274644733\", \"price\":\"0.43\", \"size\":\"170\", \"side\":\"BUY\", \"hash\":\"96d7670b84c7df626b0373af16f87739d39eff62\", \"best_bid\":\"0.48\", \"best_ask\":\"0.49\"}, {\"asset_id\":\"20893381255801015515826997628594359667013752732428989472914000440642900266717\", \"price\":\"0.57\", \"size\":\"170\", \"side\":\"SELL\", \"hash\":\"74fd129ff5e16128a4ce01abbf5a3a4fd1579739\", \"best_bid\":\"0.51\", \"best_ask\":\"0.52\"}], \"timestamp\":\"1785203752208\", \"event_type\":\"price_change\"}","received_at":"2026-07-28T01:55:52.288681Z","schema_version":"clob-market-ws.price_change.v1","sequence":null,"server_hash":null,"server_timestamp":"1785203752208","session_id":"d2757dd6dad94f3b9fe67e8dbf1adc37","source":"clob_market_ws"},"received_at":"2026-07-28T01:55:52.288681Z","record_id":"fbf1be5c1dcada680ec1e59059e06fa611dc1b5460dc48fe79f0e775c46df379","schema_fingerprint":"4aa3821a28b0b7c2400bc59aba4bcc0a76e971dadd19610d3ad38c768e124dc7","schema_version":"edge-lab-recorder.raw.v1","sequence":null,"source":"clob_market_ws"}
{"event_at":"2026-07-28T01:55:52.209000Z","event_fingerprint":"d17d2854fb7053df34b6a2a8b93fc5a6cc99cced882cafef2e88aa9af218ebd6","payload":{"connection_id":"5d29200f65794d4d9ab6ef271f045a9b","event_at":"2026-07-28T01:55:52.209000Z","event_type":"price_change","frame_hash":"3d32db2d3bb3e94cb7b4a6017de9b14ed42b4a70c4970b32818f8db3c5296fd2","frame_index":0,"kind":"data","monotonic_ns":305735302664833,"payload":{"event_type":"price_change","market":"0xda6f0e0e93fc8469e0159a166028d017bddbc162b86f66bac90391379603d962","price_changes":[{"asset_id":"39272994714739463168905443499424551362424437245880253267329605556587274644733","best_ask":"0.49","best_bid":"0.48","hash":"8cc75700fe22cde7f7f883e854f5f59f3a2c389d","price":"0.43","side":"BUY","size":"175"},{"asset_id":"20893381255801015515826997628594359667013752732428989472914000440642900266717","best_ask":"0.52","best_bid":"0.51","hash":"38ec0de9c00225e053182cfde8200599a8738bd8","price":"0.57","side":"SELL","size":"175"}],"timestamp":"1785203752209"},"payload_hash":"c1bd520ed60548e1a9a7f5c4501d2b96d0b1c5b7b6bacfae9d5a21b61abd94fc","raw_frame":"{\"market\":\"0xda6f0e0e93fc8469e0159a166028d017bddbc162b86f66bac90391379603d962\", \"price_changes\":[{\"asset_id\":\"39272994714739463168905443499424551362424437245880253267329605556587274644733\", \"price\":\"0.43\", \"size\":\"175\", \"side\":\"BUY\", \"hash\":\"8cc75700fe22cde7f7f883e854f5f59f3a2c389d\", \"best_bid\":\"0.48\", \"best_ask\":\"0.49\"}, {\"asset_id\":\"20893381255801015515826997628594359667013752732428989472914000440642900266717\", \"price\":\"0.57\", \"size\":\"175\", \"side\":\"SELL\", \"hash\":\"38ec0de9c00225e053182cfde8200599a8738bd8\", \"best_bid\":\"0.51\", \"best_ask\":\"0.52\"}], \"timestamp\":\"1785203752209\", \"event_type\":\"price_change\"}","received_at":"2026-07-28T01:55:52.294069Z","schema_version":"clob-market-ws.price_change.v1","sequence":null,"server_hash":null,"server_timestamp":"1785203752209","session_id":"d2757dd6dad94f3b9fe67e8dbf1adc37","source":"clob_market_ws"},"received_at":"2026-07-28T01:55:52.294069Z","record_id":"258be612a3673c0e48eeca8164d9a0fa247b8e8a2e7546fd001f1a7e7f69c47b","schema_fingerprint":"4aa3821a28b0b7c2400bc59aba4bcc0a76e971dadd19610d3ad38c768e124dc7","schema_version":"edge-lab-recorder.raw.v1","sequence":null,"source":"clob_market_ws"}
{"event_at":"2026-07-28T01:55:52.210000Z","event_fingerprint":"6ba9f826aed7d7f8f6565164c2a7f9c4e4a6330d9f2c102d124615723927f403","payload":{"connection_id":"5d29200f65794d4d9ab6ef271f045a9b","event_at":"2026-07-28T01:55:52.210000Z","event_type":"price_change","frame_hash":"a1190e7bbae21179d4c3f7e1db10c3ca5e8a7dd1f92aca4aaa99ad01f634d2b4","frame_index":0,"kind":"data","monotonic_ns":305735307626333,"payload":{"event_type":"price_change","market":"0xda6f0e0e93fc8469e0159a166028d017bddbc162b86f66bac90391379603d962","price_changes":[{"asset_id":"39272994714739463168905443499424551362424437245880253267329605556587274644733","best_ask":"0.49","best_bid":"0.48","hash":"2633a2b0b13ecfda4f4405a049948c00408a5488","price":"0.43","side":"BUY","size":"180"},{"asset_id":"20893381255801015515826997628594359667013752732428989472914000440642900266717","best_ask":"0.52","best_bid":"0.51","hash":"c6380bb23fe7eac8ba9c1e00a46b5b6cee9bfee9","price":"0.57","side":"SELL","size":"180"}],"timestamp":"1785203752210"},"payload_hash":"d40dc71c0ca7a8727ebddc6c513d093ed1567d0d87e42483449e8ebc91557a70","raw_frame":"{\"market\":\"0xda6f0e0e93fc8469e0159a166028d017bddbc162b86f66bac90391379603d962\", \"price_changes\":[{\"asset_id\":\"39272994714739463168905443499424551362424437245880253267329605556587274644733\", \"price\":\"0.43\", \"size\":\"180\", \"side\":\"BUY\", \"hash\":\"2633a2b0b13ecfda4f4405a049948c00408a5488\", \"best_bid\":\"0.48\", \"best_ask\":\"0.49\"}, {\"asset_id\":\"20893381255801015515826997628594359667013752732428989472914000440642900266717\", \"price\":\"0.57\", \"size\":\"180\", \"side\":\"SELL\", \"hash\":\"c6380bb23fe7eac8ba9c1e00a46b5b6cee9bfee9\", \"best_bid\":\"0.51\", \"best_ask\":\"0.52\"}], \"timestamp\":\"1785203752210\", \"event_type\":\"price_change\"}","received_at":"2026-07-28T01:55:52.299029Z","schema_version":"clob-market-ws.price_change.v1","sequence":null,"server_hash":null,"server_timestamp":"1785203752210","session_id":"d2757dd6dad94f3b9fe67e8dbf1adc37","source":"clob_market_ws"},"received_at":"2026-07-28T01:55:52.299029Z","record_id":"2522982bbd6df12c3dc35baff5b05b5e006357dacfffdd4b101ba1abc4e81a6d","schema_fingerprint":"4aa3821a28b0b7c2400bc59aba4bcc0a76e971dadd19610d3ad38c768e124dc7","schema_version":"edge-lab-recorder.raw.v1","sequence":null,"source":"clob_market_ws"}
{"event_at":"2026-07-28T01:55:52.211000Z","event_fingerprint":"fed2923852c83bc5bc173c11ae5679056119bbde9d060f003c038135ff304e14","payload":{"connection_id":"5d29200f65794d4d9ab6ef271f045a9b","event_at":"2026-07-28T01:55:52.211000Z","event_type":"price_change","frame_hash":"68b0fb218996d71d9d0f91104eaa198f10faade7ca17a123abcdaab32925fa4a","frame_index":0,"kind":"data","monotonic_ns":305735313787625,"payload":{"event_type":"price_change","market":"0xda6f0e0e93fc8469e0159a166028d017bddbc162b86f66bac90391379603d962","price_changes":[{"asset_id":"39272994714739463168905443499424551362424437245880253267329605556587274644733","best_ask":"0.49","best_bid":"0.48","hash":"229ef5008939b71bee95e087df8c43d39f3e01b9","price":"0.43","side":"BUY","size":"185"},{"asset_id":"20893381255801015515826997628594359667013752732428989472914000440642900266717","best_ask":"0.52","best_bid":"0.51","hash":"d8961902b98bf82ff78f7d2f182c5e77ba307007","price":"0.57","side":"SELL","size":"185"}],"timestamp":"1785203752211"},"payload_hash":"7c10807eafe6cb7810300ad881164f76a54aa53560e216dc435681e556b17a57","raw_frame":"{\"market\":\"0xda6f0e0e93fc8469e0159a166028d017bddbc162b86f66bac90391379603d962\", \"price_changes\":[{\"asset_id\":\"39272994714739463168905443499424551362424437245880253267329605556587274644733\", \"price\":\"0.43\", \"size\":\"185\", \"side\":\"BUY\", \"hash\":\"229ef5008939b71bee95e087df8c43d39f3e01b9\", \"best_bid\":\"0.48\", \"best_ask\":\"0.49\"}, {\"asset_id\":\"20893381255801015515826997628594359667013752732428989472914000440642900266717\", \"price\":\"0.57\", \"size\":\"185\", \"side\":\"SELL\", \"hash\":\"d8961902b98bf82ff78f7d2f182c5e77ba307007\", \"best_bid\":\"0.51\", \"best_ask\":\"0.52\"}], \"timestamp\":\"1785203752211\", \"event_type\":\"price_change\"}","received_at":"2026-07-28T01:55:52.305191Z","schema_version":"clob-market-ws.price_change.v1","sequence":null,"server_hash":null,"server_timestamp":"1785203752211","session_id":"d2757dd6dad94f3b9fe67e8dbf1adc37","source":"clob_market_ws"},"received_at":"2026-07-28T01:55:52.305191Z","record_id":"62270b198f1e8258034af82b502177307b940631f7bc63f3033fc47d9e692cde","schema_fingerprint":"4aa3821a28b0b7c2400bc59aba4bcc0a76e971dadd19610d3ad38c768e124dc7","schema_version":"edge-lab-recorder.raw.v1","sequence":null,"source":"clob_market_ws"}
{"event_at":"2026-07-28T01:55:52.213000Z","event_fingerprint":"f4af2e1c8a4f7342978d82ec2193aab76c379b1a26dbf0d1bbe235edad7b1095","payload":{"connection_id":"5d29200f65794d4d9ab6ef271f045a9b","event_at":"2026-07-28T01:55:52.213000Z","event_type":"price_change","frame_hash":"7fdf35287024a85d6b36d2984434508feeeac4770719c4cc41cea98c2dbafe68","frame_index":0,"kind":"data","monotonic_ns":305735317958291,"payload":{"event_type":"price_change","market":"0xda6f0e0e93fc8469e0159a166028d017bddbc162b86f66bac90391379603d962","price_changes":[{"asset_id":"39272994714739463168905443499424551362424437245880253267329605556587274644733","best_ask":"0.49","best_bid":"0.48","hash":"9cc7d8ae0586187e6a6a90f0e403ea65db2fa68a","price":"0.43","side":"BUY","size":"190"},{"asset_id":"20893381255801015515826997628594359667013752732428989472914000440642900266717","best_ask":"0.52","best_bid":"0.51","hash":"c88a3323314762d6ff4f6e5ba9afee9f9daafd04","price":"0.57","side":"SELL","size":"190"}],"timestamp":"1785203752213"},"payload_hash":"b36ef33f947377b7092c460c930f400f67c1c52f19cc5b83802bcedfa4b9f0f2","raw_frame":"{\"market\":\"0xda6f0e0e93fc8469e0159a166028d017bddbc162b86f66bac90391379603d962\", \"price_changes\":[{\"asset_id\":\"39272994714739463168905443499424551362424437245880253267329605556587274644733\", \"price\":\"0.43\", \"size\":\"190\", \"side\":\"BUY\", \"hash\":\"9cc7d8ae0586187e6a6a90f0e403ea65db2fa68a\", \"best_bid\":\"0.48\", \"best_ask\":\"0.49\"}, {\"asset_id\":\"20893381255801015515826997628594359667013752732428989472914000440642900266717\", \"price\":\"0.57\", \"size\":\"190\", \"side\":\"SELL\", \"hash\":\"c88a3323314762d6ff4f6e5ba9afee9f9daafd04\", \"best_bid\":\"0.51\", \"best_ask\":\"0.52\"}], \"timestamp\":\"1785203752213\", \"event_type\":\"price_change\"}","received_at":"2026-07-28T01:55:52.309362Z","schema_version":"clob-market-ws.price_change.v1","sequence":null,"server_hash":null,"server_timestamp":"1785203752213","session_id":"d2757dd6dad94f3b9fe67e8dbf1adc37","source":"clob_market_ws"},"received_at":"2026-07-28T01:55:52.309362Z","record_id":"7150311ce436b63b0798276d477d2bb2c180c6feb5f5a84e21543454de32a410","schema_fingerprint":"4aa3821a28b0b7c2400bc59aba4bcc0a76e971dadd19610d3ad38c768e124dc7","schema_version":"edge-lab-recorder.raw.v1","sequence":null,"source":"clob_market_ws"}
{"event_at":"2026-07-28T01:55:52.214000Z","event_fingerprint":"90f2ce6af5b0d5f8e4b7ff814112865e9d7a6ecdc9f35d5e1890da07959f003b","payload":{"connection_id":"5d29200f65794d4d9ab6ef271f045a9b","event_at":"2026-07-28T01:55:52.214000Z","event_type":"price_change","frame_hash":"ec8c6a2d5fcc2f4d5f4dcfd942c4ddad7ec09cccbdcff02bd7bc6d74768350fd","frame_index":0,"kind":"data","monotonic_ns":305735322819000,"payload":{"event_type":"price_change","market":"0xda6f0e0e93fc8469e0159a166028d017bddbc162b86f66bac90391379603d962","price_changes":[{"asset_id":"39272994714739463168905443499424551362424437245880253267329605556587274644733","best_ask":"0.49","best_bid":"0.48","hash":"5b50d0f2be58be56075259a45bc4214d63d43f5a","price":"0.43","side":"BUY","size":"195"},{"asset_id":"20893381255801015515826997628594359667013752732428989472914000440642900266717","best_ask":"0.52","best_bid":"0.51","hash":"873032f756c536d00f178711292d84ac28d2a32a","price":"0.57","side":"SELL","size":"195"}],"timestamp":"1785203752214"},"payload_hash":"eb2cde1bc8a56e65a5ac4f7dffa31e93299aa9533c15b24d6662c48855036eb7","raw_frame":"{\"market\":\"0xda6f0e0e93fc8469e0159a166028d017bddbc162b86f66bac90391379603d962\", \"price_changes\":[{\"asset_id\":\"39272994714739463168905443499424551362424437245880253267329605556587274644733\", \"price\":\"0.43\", \"size\":\"195\", \"side\":\"BUY\", \"hash\":\"5b50d0f2be58be56075259a45bc4214d63d43f5a\", \"best_bid\":\"0.48\", \"best_ask\":\"0.49\"}, {\"asset_id\":\"20893381255801015515826997628594359667013752732428989472914000440642900266717\", \"price\":\"0.57\", \"size\":\"195\", \"side\":\"SELL\", \"hash\":\"873032f756c536d00f178711292d84ac28d2a32a\", \"best_bid\":\"0.51\", \"best_ask\":\"0.52\"}], \"timestamp\":\"1785203752214\", \"event_type\":\"price_change\"}","received_at":"2026-07-28T01:55:52.314222Z","schema_version":"clob-market-ws.price_change.v1","sequence":null,"server_hash":null,"server_timestamp":"1785203752214","session_id":"d2757dd6dad94f3b9fe67e8dbf1adc37","source":"clob_market_ws"},"received_at":"2026-07-28T01:55:52.314222Z","record_id":"e874424f7d8b78441a4c70642d891d93cd52a6cf612df82f91c2129c7e99a425","schema_fingerprint":"4aa3821a28b0b7c2400bc59aba4bcc0a76e971dadd19610d3ad38c768e124dc7","schema_version":"edge-lab-recorder.raw.v1","sequence":null,"source":"clob_market_ws"}
{"event_at":"2026-07-28T01:55:52.215000Z","event_fingerprint":"875ed2c68b67c816c4469bbda3317e7801301d432a9dc755e10d9bf7d3d86f76","payload":{"connection_id":"5d29200f65794d4d9ab6ef271f045a9b","event_at":"2026-07-28T01:55:52.215000Z","event_type":"price_change","frame_hash":"b3d3c72cb1d9578345e06d9e610ba457c5975f49c6518fa654d4081e21c8750b","frame_index":0,"kind":"data","monotonic_ns":305735327922791,"payload":{"event_type":"price_change","market":"0xda6f0e0e93fc8469e0159a166028d017bddbc162b86f66bac90391379603d962","price_changes":[{"asset_id":"39272994714739463168905443499424551362424437245880253267329605556587274644733","best_ask":"0.49","best_bid":"0.48","hash":"a20a32777b946f0884b9ae2382cfa68603e4b4bd","price":"0.43","side":"BUY","size":"200"},{"asset_id":"20893381255801015515826997628594359667013752732428989472914000440642900266717","best_ask":"0.52","best_bid":"0.51","hash":"b1bd4c5e57d2281c2564aade8f07fe1ba9c5faec","price":"0.57","side":"SELL","size":"200"}],"timestamp":"1785203752215"},"payload_hash":"e9ec87f6ee74bfb33edf1255b83cd072d43c078d4ca1e8f8a2eeb93b39cbda42","raw_frame":"{\"market\":\"0xda6f0e0e93fc8469e0159a166028d017bddbc162b86f66bac90391379603d962\", \"price_changes\":[{\"asset_id\":\"39272994714739463168905443499424551362424437245880253267329605556587274644733\", \"price\":\"0.43\", \"size\":\"200\", \"side\":\"BUY\", \"hash\":\"a20a32777b946f0884b9ae2382cfa68603e4b4bd\", \"best_bid\":\"0.48\", \"best_ask\":\"0.49\"}, {\"asset_id\":\"20893381255801015515826997628594359667013752732428989472914000440642900266717\", \"price\":\"0.57\", \"size\":\"200\", \"side\":\"SELL\", \"hash\":\"b1bd4c5e57d2281c2564aade8f07fe1ba9c5faec\", \"best_bid\":\"0.51\", \"best_ask\":\"0.52\"}], \"timestamp\":\"1785203752215\", \"event_type\":\"price_change\"}","received_at":"2026-07-28T01:55:52.319325Z","schema_version":"clob-market-ws.price_change.v1","sequence":null,"server_hash":null,"server_timestamp":"1785203752215","session_id":"d2757dd6dad94f3b9fe67e8dbf1adc37","source":"clob_market_ws"},"received_at":"2026-07-28T01:55:52.319325Z","record_id":"91021b7d41d11135126de09278915905f4788ceb6c48ef9abf4465982d84a8da","schema_fingerprint":"4aa3821a28b0b7c2400bc59aba4bcc0a76e971dadd19610d3ad38c768e124dc7","schema_version":"edge-lab-recorder.raw.v1","sequence":null,"source":"clob_market_ws"}
{"event_at":"2026-07-28T01:55:52.216000Z","event_fingerprint":"81f389eb5a04f2def4d4a9c73ef83f4ceb13bc02798354f98baaee6681fae9bb","payload":{"connection_id":"5d29200f65794d4d9ab6ef271f045a9b","event_at":"2026-07-28T01:55:52.216000Z","event_type":"price_change","frame_hash":"aca7992b0a27a6a98fb201ab32462dab298c5ec2aac92b0ca680d1e80dc30475","frame_index":0,"kind":"data","monotonic_ns":305735333689791,"payload":{"event_type":"price_change","market":"0xda6f0e0e93fc8469e0159a166028d017bddbc162b86f66bac90391379603d962","price_changes":[{"asset_id":"39272994714739463168905443499424551362424437245880253267329605556587274644733","best_ask":"0.49","best_bid":"0.48","hash":"33d6d63a4dd0e5ac541356135ee763582dd977b2","price":"0.43","side":"BUY","size":"205"},{"asset_id":"20893381255801015515826997628594359667013752732428989472914000440642900266717","best_ask":"0.52","best_bid":"0.51","hash":"33dbf54649f0badaa6c86b2ed35e163e6dd289f7","price":"0.57","side":"SELL","size":"205"}],"timestamp":"1785203752216"},"payload_hash":"8d10b51475c609a7156f1e7775945c0bc8a4bcb41e9f0f2f351f1d3da610518f","raw_frame":"{\"market\":\"0xda6f0e0e93fc8469e0159a166028d017bddbc162b86f66bac90391379603d962\", \"price_changes\":[{\"asset_id\":\"39272994714739463168905443499424551362424437245880253267329605556587274644733\", \"price\":\"0.43\", \"size\":\"205\", \"side\":\"BUY\", \"hash\":\"33d6d63a4dd0e5ac541356135ee763582dd977b2\", \"best_bid\":\"0.48\", \"best_ask\":\"0.49\"}, {\"asset_id\":\"20893381255801015515826997628594359667013752732428989472914000440642900266717\", \"price\":\"0.57\", \"size\":\"205\", \"side\":\"SELL\", \"hash\":\"33dbf54649f0badaa6c86b2ed35e163e6dd289f7\", \"best_bid\":\"0.51\", \"best_ask\":\"0.52\"}], \"timestamp\":\"1785203752216\", \"event_type\":\"price_change\"}","received_at":"2026-07-28T01:55:52.325093Z","schema_version":"clob-market-ws.price_change.v1","sequence":null,"server_hash":null,"server_timestamp":"1785203752216","session_id":"d2757dd6dad94f3b9fe67e8dbf1adc37","source":"clob_market_ws"},"received_at":"2026-07-28T01:55:52.325093Z","record_id":"c6fe04f54f46a28883536e51c8ee5134a053db3e8fec92bafbe4deb283e3c92e","schema_fingerprint":"4aa3821a28b0b7c2400bc59aba4bcc0a76e971dadd19610d3ad38c768e124dc7","schema_version":"edge-lab-recorder.raw.v1","sequence":null,"source":"clob_market_ws"}
{"event_at":"2026-07-28T01:55:52.217000Z","event_fingerprint":"13f0e51c79d0ff3394a69d4038fe52aa783487a50fd216c247b5364e29cd4fd9","payload":{"connection_id":"5d29200f65794d4d9ab6ef271f045a9b","event_at":"2026-07-28T01:55:52.217000Z","event_type":"price_change","frame_hash":"57f8c0edc2d7a6b955fef52551d12c17153cc86c77947e176172cfbe951a018c","frame_index":0,"kind":"data","monotonic_ns":305735339489000,"payload":{"event_type":"price_change","market":"0xda6f0e0e93fc8469e0159a166028d017bddbc162b86f66bac90391379603d962","price_changes":[{"asset_id":"39272994714739463168905443499424551362424437245880253267329605556587274644733","best_ask":"0.49","best_bid":"0.48","hash":"4cd2431409ea5c63d9f0ff3ed6c8f0b050759a68","price":"0.43","side":"BUY","size":"210"},{"asset_id":"20893381255801015515826997628594359667013752732428989472914000440642900266717","best_ask":"0.52","best_bid":"0.51","hash":"f6ffa6208718c905baaa1ab49b67905aac6b841f","price":"0.57","side":"SELL","size":"210"}],"timestamp":"1785203752217"},"payload_hash":"ba34355abeb6fe92c18663871a9b3fa67b99b1c5275d9e5192157b266a2a8464","raw_frame":"{\"market\":\"0xda6f0e0e93fc8469e0159a166028d017bddbc162b86f66bac90391379603d962\", \"price_changes\":[{\"asset_id\":\"39272994714739463168905443499424551362424437245880253267329605556587274644733\", \"price\":\"0.43\", \"size\":\"210\", \"side\":\"BUY\", \"hash\":\"4cd2431409ea5c63d9f0ff3ed6c8f0b050759a68\", \"best_bid\":\"0.48\", \"best_ask\":\"0.49\"}, {\"asset_id\":\"20893381255801015515826997628594359667013752732428989472914000440642900266717\", \"price\":\"0.57\", \"size\":\"210\", \"side\":\"SELL\", \"hash\":\"f6ffa6208718c905baaa1ab49b67905aac6b841f\", \"best_bid\":\"0.51\", \"best_ask\":\"0.52\"}], \"timestamp\":\"1785203752217\", \"event_type\":\"price_change\"}","received_at":"2026-07-28T01:55:52.330892Z","schema_version":"clob-market-ws.price_change.v1","sequence":null,"server_hash":null,"server_timestamp":"1785203752217","session_id":"d2757dd6dad94f3b9fe67e8dbf1adc37","source":"clob_market_ws"},"received_at":"2026-07-28T01:55:52.330892Z","record_id":"595915b8b6b98a282befba6957e89d88d6b9909588a9b91bdeef51db55537fe3","schema_fingerprint":"4aa3821a28b0b7c2400bc59aba4bcc0a76e971dadd19610d3ad38c768e124dc7","schema_version":"edge-lab-recorder.raw.v1","sequence":null,"source":"clob_market_ws"}
{"event_at":"2026-07-28T01:55:52.218000Z","event_fingerprint":"150ffb0008d928ce88dffbb6910b6d5e9e18e9495ceac3cf6b741676f484aab0","payload":{"connection_id":"5d29200f65794d4d9ab6ef271f045a9b","event_at":"2026-07-28T01:55:52.218000Z","event_type":"price_change","frame_hash":"4c77b06e7c3f12970e7490f4c537f6d6a8b151e6ba82b11abe38b0fd5f98c34a","frame_index":0,"kind":"data","monotonic_ns":305735344398750,"payload":{"event_type":"price_change","market":"0xda6f0e0e93fc8469e0159a166028d017bddbc162b86f66bac90391379603d962","price_changes":[{"asset_id":"39272994714739463168905443499424551362424437245880253267329605556587274644733","best_ask":"0.49","best_bid":"0.48","hash":"c0f602612b7c198c1dbc6fd8f412a213df754f6e","price":"0.43","side":"BUY","size":"215"},{"asset_id":"20893381255801015515826997628594359667013752732428989472914000440642900266717","best_ask":"0.52","best_bid":"0.51","hash":"0b8ff09c3a993bf5dcd12a562eca66beed2a247e","price":"0.57","side":"SELL","size":"215"}],"timestamp":"1785203752218"},"payload_hash":"4fbe150da38995e0b3f4e11242ae1480b0fad4658da23316b1066555c6314c54","raw_frame":"{\"market\":\"0xda6f0e0e93fc8469e0159a166028d017bddbc162b86f66bac90391379603d962\", \"price_changes\":[{\"asset_id\":\"39272994714739463168905443499424551362424437245880253267329605556587274644733\", \"price\":\"0.43\", \"size\":\"215\", \"side\":\"BUY\", \"hash\":\"c0f602612b7c198c1dbc6fd8f412a213df754f6e\", \"best_bid\":\"0.48\", \"best_ask\":\"0.49\"}, {\"asset_id\":\"20893381255801015515826997628594359667013752732428989472914000440642900266717\", \"price\":\"0.57\", \"size\":\"215\", \"side\":\"SELL\", \"hash\":\"0b8ff09c3a993bf5dcd12a562eca66beed2a247e\", \"best_bid\":\"0.51\", \"best_ask\":\"0.52\"}], \"timestamp\":\"1785203752218\", \"event_type\":\"price_change\"}","received_at":"2026-07-28T01:55:52.335801Z","schema_version":"clob-market-ws.price_change.v1","sequence":null,"server_hash":null,"server_timestamp":"1785203752218","session_id":"d2757dd6dad94f3b9fe67e8dbf1adc37","source":"clob_market_ws"},"received_at":"2026-07-28T01:55:52.335801Z","record_id":"96efbf2aec5e6756f692eac35ac3201380ff35a7bf0ce5ed160880fdf756f9d5","schema_fingerprint":"4aa3821a28b0b7c2400bc59aba4bcc0a76e971dadd19610d3ad38c768e124dc7","schema_version":"edge-lab-recorder.raw.v1","sequence":null,"source":"clob_market_ws"}
{"event_at":"2026-07-28T01:55:52.219000Z","event_fingerprint":"ffcbc3ce3ab93d90a4beda1187e88f571b7bf354b517315f39690987a0688b39","payload":{"connection_id":"5d29200f65794d4d9ab6ef271f045a9b","event_at":"2026-07-28T01:55:52.219000Z","event_type":"price_change","frame_hash":"1b24f0dffa52d1e07a17568c5a67577f53a5ebc1942a52c2304ccf5a2cbe3362","frame_index":0,"kind":"data","monotonic_ns":305735350554791,"payload":{"event_type":"price_change","market":"0xda6f0e0e93fc8469e0159a166028d017bddbc162b86f66bac90391379603d962","price_changes":[{"asset_id":"39272994714739463168905443499424551362424437245880253267329605556587274644733","best_ask":"0.49","best_bid":"0.48","hash":"cd004b9c3440b5ac8dec7b36546dcc67d9db2fb7","price":"0.43","side":"BUY","size":"220"},{"asset_id":"20893381255801015515826997628594359667013752732428989472914000440642900266717","best_ask":"0.52","best_bid":"0.51","hash":"1503c368d66be7c744c087e73a94ceae4872383b","price":"0.57","side":"SELL","size":"220"}],"timestamp":"1785203752219"},"payload_hash":"d00984b554b063edf58b2cd80e062bb3fd7794a7945b2d92bf5efdc64e599689","raw_frame":"{\"market\":\"0xda6f0e0e93fc8469e0159a166028d017bddbc162b86f66bac90391379603d962\", \"price_changes\":[{\"asset_id\":\"39272994714739463168905443499424551362424437245880253267329605556587274644733\", \"price\":\"0.43\", \"size\":\"220\", \"side\":\"BUY\", \"hash\":\"cd004b9c3440b5ac8dec7b36546dcc67d9db2fb7\", \"best_bid\":\"0.48\", \"best_ask\":\"0.49\"}, {\"asset_id\":\"20893381255801015515826997628594359667013752732428989472914000440642900266717\", \"price\":\"0.57\", \"size\":\"220\", \"side\":\"SELL\", \"hash\":\"1503c368d66be7c744c087e73a94ceae4872383b\", \"best_bid\":\"0.51\", \"best_ask\":\"0.52\"}], \"timestamp\":\"1785203752219\", \"event_type\":\"price_change\"}","received_at":"2026-07-28T01:55:52.341958Z","schema_version":"clob-market-ws.price_change.v1","sequence":null,"server_hash":null,"server_timestamp":"1785203752219","session_id":"d2757dd6dad94f3b9fe67e8dbf1adc37","source":"clob_market_ws"},"received_at":"2026-07-28T01:55:52.341958Z","record_id":"c59b7fd53fa7a0273283b18f5e96c0b9aef72745b1eb1917b2e76812b0bba038","schema_fingerprint":"4aa3821a28b0b7c2400bc59aba4bcc0a76e971dadd19610d3ad38c768e124dc7","schema_version":"edge-lab-recorder.raw.v1","sequence":null,"source":"clob_market_ws"}
{"event_at":"2026-07-28T01:55:52.220000Z","event_fingerprint":"bdc944ebb31a48dafa94b042662fcebf7f7b3df1ce98f64254828161a3149108","payload":{"connection_id":"5d29200f65794d4d9ab6ef271f045a9b","event_at":"2026-07-28T01:55:52.220000Z","event_type":"price_change","frame_hash":"b42491d45c58adaffea97ab63fb90694bba38552e376dcfb836a74f08cc366a4","frame_index":0,"kind":"data","monotonic_ns":305735354956875,"payload":{"event_type":"price_change","market":"0xda6f0e0e93fc8469e0159a166028d017bddbc162b86f66bac90391379603d962","price_changes":[{"asset_id":"39272994714739463168905443499424551362424437245880253267329605556587274644733","best_ask":"0.49","best_bid":"0.48","hash":"70641130c9f5c11b89308458da23849967984ef1","price":"0.43","side":"BUY","size":"225"},{"asset_id":"20893381255801015515826997628594359667013752732428989472914000440642900266717","best_ask":"0.52","best_bid":"0.51","hash":"6390863ca3570ba49b79f3c7e9021da31d799b0a","price":"0.57","side":"SELL","size":"225"}],"timestamp":"1785203752220"},"payload_hash":"835a9a9980c2cac6d7c0834379ff6dce19710c7f5953c8904865f65f47139039","raw_frame":"{\"market\":\"0xda6f0e0e93fc8469e0159a166028d017bddbc162b86f66bac90391379603d962\", \"price_changes\":[{\"asset_id\":\"39272994714739463168905443499424551362424437245880253267329605556587274644733\", \"price\":\"0.43\", \"size\":\"225\", \"side\":\"BUY\", \"hash\":\"70641130c9f5c11b89308458da23849967984ef1\", \"best_bid\":\"0.48\", \"best_ask\":\"0.49\"}, {\"asset_id\":\"20893381255801015515826997628594359667013752732428989472914000440642900266717\", \"price\":\"0.57\", \"size\":\"225\", \"side\":\"SELL\", \"hash\":\"6390863ca3570ba49b79f3c7e9021da31d799b0a\", \"best_bid\":\"0.51\", \"best_ask\":\"0.52\"}], \"timestamp\":\"1785203752220\", \"event_type\":\"price_change\"}","received_at":"2026-07-28T01:55:52.346359Z","schema_version":"clob-market-ws.price_change.v1","sequence":null,"server_hash":null,"server_timestamp":"1785203752220","session_id":"d2757dd6dad94f3b9fe67e8dbf1adc37","source":"clob_market_ws"},"received_at":"2026-07-28T01:55:52.346359Z","record_id":"87f48ad2e9e226e34ba3fce162ce505c855328369d52f895f8033ff5ef986ca7","schema_fingerprint":"4aa3821a28b0b7c2400bc59aba4bcc0a76e971dadd19610d3ad38c768e124dc7","schema_version":"edge-lab-recorder.raw.v1","sequence":null,"source":"clob_market_ws"}
{"event_at":"2026-07-28T01:55:52.221000Z","event_fingerprint":"49c49fd5e28e6d4d25129f9ca3e43391a82c2991c70295b530730324ad0b86a6","payload":{"connection_id":"5d29200f65794d4d9ab6ef271f045a9b","event_at":"2026-07-28T01:55:52.221000Z","event_type":"price_change","frame_hash":"6fbc3696d7ab17308cb09c957f5464a9a4666b4f14664eef2284a3b2e8c02685","frame_index":0,"kind":"data","monotonic_ns":305735361689708,"payload":{"event_type":"price_change","market":"0xda6f0e0e93fc8469e0159a166028d017bddbc162b86f66bac90391379603d962","price_changes":[{"asset_id":"39272994714739463168905443499424551362424437245880253267329605556587274644733","best_ask":"0.49","best_bid":"0.48","hash":"474ed0cd01cf19683c0d64b8f95606c64a0e08d3","price":"0.43","side":"BUY","size":"230"},{"asset_id":"20893381255801015515826997628594359667013752732428989472914000440642900266717","best_ask":"0.52","best_bid":"0.51","hash":"c00a41393f94f35eedfcb13957afa65e2a6f45a1","price":"0.57","side":"SELL","size":"230"}],"timestamp":"1785203752221"},"payload_hash":"22baa7db44a8fe61cb585b172ee86f5b3ca178f9f6334ae5d5dc1d7e3b860439","raw_frame":"{\"market\":\"0xda6f0e0e93fc8469e0159a166028d017bddbc162b86f66bac90391379603d962\", \"price_changes\":[{\"asset_id\":\"39272994714739463168905443499424551362424437245880253267329605556587274644733\", \"price\":\"0.43\", \"size\":\"230\", \"side\":\"BUY\", \"hash\":\"474ed0cd01cf19683c0d64b8f95606c64a0e08d3\", \"best_bid\":\"0.48\", \"best_ask\":\"0.49\"}, {\"asset_id\":\"20893381255801015515826997628594359667013752732428989472914000440642900266717\", \"price\":\"0.57\", \"size\":\"230\", \"side\":\"SELL\", \"hash\":\"c00a41393f94f35eedfcb13957afa65e2a6f45a1\", \"best_bid\":\"0.51\", \"best_ask\":\"0.52\"}], \"timestamp\":\"1785203752221\", \"event_type\":\"price_change\"}","received_at":"2026-07-28T01:55:52.353092Z","schema_version":"clob-market-ws.price_change.v1","sequence":null,"server_hash":null,"server_timestamp":"1785203752221","session_id":"d2757dd6dad94f3b9fe67e8dbf1adc37","source":"clob_market_ws"},"received_at":"2026-07-28T01:55:52.353092Z","record_id":"7563199df5f4188a992acbbeebc8ab6fcb5ffc8c7127fe8181637c3639ba7284","schema_fingerprint":"4aa3821a28b0b7c2400bc59aba4bcc0a76e971dadd19610d3ad38c768e124dc7","schema_version":"edge-lab-recorder.raw.v1","sequence":null,"source":"clob_market_ws"}
{"event_at":"2026-07-28T01:55:52.222000Z","event_fingerprint":"8c759ee611187b5123246a5f7d8e5c4a601e2107218af41d1ca3e2e51f1b5fd2","payload":{"connection_id":"5d29200f65794d4d9ab6ef271f045a9b","event_at":"2026-07-28T01:55:52.222000Z","event_type":"price_change","frame_hash":"f65b8b7a2b8b1c11dac358e90b920edc9693fc038a9e2f7b8e0b948953c947b9","frame_index":0,"kind":"data","monotonic_ns":305735366658250,"payload":{"event_type":"price_change","market":"0xda6f0e0e93fc8469e0159a166028d017bddbc162b86f66bac90391379603d962","price_changes":[{"asset_id":"39272994714739463168905443499424551362424437245880253267329605556587274644733","best_ask":"0.49","best_bid":"0.48","hash":"f6b39572145decdce4ee59a2247bbd3f2795ccc8","price":"0.43","side":"BUY","size":"235"},{"asset_id":"20893381255801015515826997628594359667013752732428989472914000440642900266717","best_ask":"0.52","best_bid":"0.51","hash":"40d56386461ba0aa3516a4dc8e2ea0b4edff3284","price":"0.57","side":"SELL","size":"235"}],"timestamp":"1785203752222"},"payload_hash":"03909f1ad7ebc25fe3a74050468e201f62782262bef90600fa193d20b92f3371","raw_frame":"{\"market\":\"0xda6f0e0e93fc8469e0159a166028d017bddbc162b86f66bac90391379603d962\", \"price_changes\":[{\"asset_id\":\"39272994714739463168905443499424551362424437245880253267329605556587274644733\", \"price\":\"0.43\", \"size\":\"235\", \"side\":\"BUY\", \"hash\":\"f6b39572145decdce4ee59a2247bbd3f2795ccc8\", \"best_bid\":\"0.48\", \"best_ask\":\"0.49\"}, {\"asset_id\":\"20893381255801015515826997628594359667013752732428989472914000440642900266717\", \"price\":\"0.57\", \"size\":\"235\", \"side\":\"SELL\", \"hash\":\"40d56386461ba0aa3516a4dc8e2ea0b4edff3284\", \"best_bid\":\"0.51\", \"best_ask\":\"0.52\"}], \"timestamp\":\"1785203752222\", \"event_type\":\"price_change\"}","received_at":"2026-07-28T01:55:52.358061Z","schema_version":"clob-market-ws.price_change.v1","sequence":null,"server_hash":null,"server_timestamp":"1785203752222","session_id":"d2757dd6dad94f3b9fe67e8dbf1adc37","source":"clob_market_ws"},"received_at":"2026-07-28T01:55:52.358061Z","record_id":"2889935f87407626baa5a8cb7256abeabd94ac4a9071e90756557919623af409","schema_fingerprint":"4aa3821a28b0b7c2400bc59aba4bcc0a76e971dadd19610d3ad38c768e124dc7","schema_version":"edge-lab-recorder.raw.v1","sequence":null,"source":"clob_market_ws"}
{"event_at":"2026-07-28T01:55:52.223000Z","event_fingerprint":"0120cd097aae33688e85d4a669ebc94cc5fe52625653398b49b1bd1dea2e4f83","payload":{"connection_id":"5d29200f65794d4d9ab6ef271f045a9b","event_at":"2026-07-28T01:55:52.223000Z","event_type":"price_change","frame_hash":"2c1394f5208b76b95cc462e557a9ef702e2cadddee58cf9e3c21900c4451e01d","frame_index":0,"kind":"data","monotonic_ns":305735372358166,"payload":{"event_type":"price_change","market":"0xda6f0e0e93fc8469e0159a166028d017bddbc162b86f66bac90391379603d962","price_changes":[{"asset_id":"39272994714739463168905443499424551362424437245880253267329605556587274644733","best_ask":"0.49","best_bid":"0.48","hash":"79d85aeae878e2c1e5ab9a3bc0ad23a42b219b78","price":"0.43","side":"BUY","size":"240"},{"asset_id":"20893381255801015515826997628594359667013752732428989472914000440642900266717","best_ask":"0.52","best_bid":"0.51","hash":"632ff6c0bdf3437618136822d04e24976a9621c5","price":"0.57","side":"SELL","size":"240"}],"timestamp":"1785203752223"},"payload_hash":"6318f1c7ea7431ee6054f2539103afaf6c977dfa18badfd6acc8968ddd34e8df","raw_frame":"{\"market\":\"0xda6f0e0e93fc8469e0159a166028d017bddbc162b86f66bac90391379603d962\", \"price_changes\":[{\"asset_id\":\"39272994714739463168905443499424551362424437245880253267329605556587274644733\", \"price\":\"0.43\", \"size\":\"240\", \"side\":\"BUY\", \"hash\":\"79d85aeae878e2c1e5ab9a3bc0ad23a42b219b78\", \"best_bid\":\"0.48\", \"best_ask\":\"0.49\"}, {\"asset_id\":\"20893381255801015515826997628594359667013752732428989472914000440642900266717\", \"price\":\"0.57\", \"size\":\"240\", \"side\":\"SELL\", \"hash\":\"632ff6c0bdf3437618136822d04e24976a9621c5\", \"best_bid\":\"0.51\", \"best_ask\":\"0.52\"}], \"timestamp\":\"1785203752223\", \"event_type\":\"price_change\"}","received_at":"2026-07-28T01:55:52.363761Z","schema_version":"clob-market-ws.price_change.v1","sequence":null,"server_hash":null,"server_timestamp":"1785203752223","session_id":"d2757dd6dad94f3b9fe67e8dbf1adc37","source":"clob_market_ws"},"received_at":"2026-07-28T01:55:52.363761Z","record_id":"1fabf3b2cabf072dd2f5ab1046d7f9d86d4e046f7c5ddfe7f3be6dd3f5c458fc","schema_fingerprint":"4aa3821a28b0b7c2400bc59aba4bcc0a76e971dadd19610d3ad38c768e124dc7","schema_version":"edge-lab-recorder.raw.v1","sequence":null,"source":"clob_market_ws"}
{"event_at":"2026-07-28T01:55:52.224000Z","event_fingerprint":"6df12a8132efac337970d473c15479054efa982483ba2ebe71ef44142f5d6fbe","payload":{"connection_id":"5d29200f65794d4d9ab6ef271f045a9b","event_at":"2026-07-28T01:55:52.224000Z","event_type":"price_change","frame_hash":"a03f5393c5291c882ef2d2175de1de3c01faee0d66938e0be180077ffea6db9a","frame_index":0,"kind":"data","monotonic_ns":305735376661291,"payload":{"event_type":"price_change","market":"0xda6f0e0e93fc8469e0159a166028d017bddbc162b86f66bac90391379603d962","price_changes":[{"asset_id":"39272994714739463168905443499424551362424437245880253267329605556587274644733","best_ask":"0.49","best_bid":"0.48","hash":"77188d2cfa1b4ff4c640d898f789615b84383060","price":"0.43","side":"BUY","size":"245"},{"asset_id":"20893381255801015515826997628594359667013752732428989472914000440642900266717","best_ask":"0.52","best_bid":"0.51","hash":"d08de94a437d4dfb3b5709337bfa15ce879566eb","price":"0.57","side":"SELL","size":"245"}],"timestamp":"1785203752224"},"payload_hash":"9541437dab1f3e0ff08d2bf2be0b5f34f8d357c9a43f2717060098d1f2f03eaf","raw_frame":"{\"market\":\"0xda6f0e0e93fc8469e0159a166028d017bddbc162b86f66bac90391379603d962\", \"price_changes\":[{\"asset_id\":\"39272994714739463168905443499424551362424437245880253267329605556587274644733\", \"price\":\"0.43\", \"size\":\"245\", \"side\":\"BUY\", \"hash\":\"77188d2cfa1b4ff4c640d898f789615b84383060\", \"best_bid\":\"0.48\", \"best_ask\":\"0.49\"}, {\"asset_id\":\"20893381255801015515826997628594359667013752732428989472914000440642900266717\", \"price\":\"0.57\", \"size\":\"245\", \"side\":\"SELL\", \"hash\":\"d08de94a437d4dfb3b5709337bfa15ce879566eb\", \"best_bid\":\"0.51\", \"best_ask\":\"0.52\"}], \"timestamp\":\"1785203752224\", \"event_type\":\"price_change\"}","received_at":"2026-07-28T01:55:52.368064Z","schema_version":"clob-market-ws.price_change.v1","sequence":null,"server_hash":null,"server_timestamp":"1785203752224","session_id":"d2757dd6dad94f3b9fe67e8dbf1adc37","source":"clob_market_ws"},"received_at":"2026-07-28T01:55:52.368064Z","record_id":"84a3c74bb913f7ce1fa098769307e420febff416442a63c4632d4576059f0a02","schema_fingerprint":"4aa3821a28b0b7c2400bc59aba4bcc0a76e971dadd19610d3ad38c768e124dc7","schema_version":"edge-lab-recorder.raw.v1","sequence":null,"source":"clob_market_ws"}
{"event_at":"2026-07-28T01:55:52.225000Z","event_fingerprint":"1e1e045deac9dae3e7204409d7e02486e2cf23dc5c2b56211802f2b7361fee18","payload":{"connection_id":"5d29200f65794d4d9ab6ef271f045a9b","event_at":"2026-07-28T01:55:52.225000Z","event_type":"price_change","frame_hash":"b551e8c0e614be819d2628682e1af3e51a3154b26300c19534ba971ce4497085","frame_index":0,"kind":"data","monotonic_ns":305735390122541,"payload":{"event_type":"price_change","market":"0xda6f0e0e93fc8469e0159a166028d017bddbc162b86f66bac90391379603d962","price_changes":[{"asset_id":"39272994714739463168905443499424551362424437245880253267329605556587274644733","best_ask":"0.49","best_bid":"0.48","hash":"de8d173431bf7cca2e1413d34f7ff5f6fa542145","price":"0.43","side":"BUY","size":"250"},{"asset_id":"20893381255801015515826997628594359667013752732428989472914000440642900266717","best_ask":"0.52","best_bid":"0.51","hash":"2bd4b5d084ba2ad90174076a1b93193ad04424fb","price":"0.57","side":"SELL","size":"250"}],"timestamp":"1785203752225"},"payload_hash":"871e6a953e519daf9b814771fb50eb318d36dbd5be4f1637578990fd15cb1821","raw_frame":"{\"market\":\"0xda6f0e0e93fc8469e0159a166028d017bddbc162b86f66bac90391379603d962\", \"price_changes\":[{\"asset_id\":\"39272994714739463168905443499424551362424437245880253267329605556587274644733\", \"price\":\"0.43\", \"size\":\"250\", \"side\":\"BUY\", \"hash\":\"de8d173431bf7cca2e1413d34f7ff5f6fa542145\", \"best_bid\":\"0.48\", \"best_ask\":\"0.49\"}, {\"asset_id\":\"20893381255801015515826997628594359667013752732428989472914000440642900266717\", \"price\":\"0.57\", \"size\":\"250\", \"side\":\"SELL\", \"hash\":\"2bd4b5d084ba2ad90174076a1b93193ad04424fb\", \"best_bid\":\"0.51\", \"best_ask\":\"0.52\"}], \"timestamp\":\"1785203752225\", \"event_type\":\"price_change\"}","received_at":"2026-07-28T01:55:52.381524Z","schema_version":"clob-market-ws.price_change.v1","sequence":null,"server_hash":null,"server_timestamp":"1785203752225","session_id":"d2757dd6dad94f3b9fe67e8dbf1adc37","source":"clob_market_ws"},"received_at":"2026-07-28T01:55:52.381524Z","record_id":"5fa55a2fde122092303306d96c6d88e13bd5732ffd86b8d2c45231d6b8fb22e9","schema_fingerprint":"4aa3821a28b0b7c2400bc59aba4bcc0a76e971dadd19610d3ad38c768e124dc7","schema_version":"edge-lab-recorder.raw.v1","sequence":null,"source":"clob_market_ws"}
{"event_at":"2026-07-28T01:55:52.226000Z","event_fingerprint":"89f3840d7b48d4d6accdd72171ccae42399e9a8495a1a9471482ffe88181a4e6","payload":{"connection_id":"5d29200f65794d4d9ab6ef271f045a9b","event_at":"2026-07-28T01:55:52.226000Z","event_type":"price_change","frame_hash":"ffff2e6c25968082beff85fa7e6226054364a2ff3e0cb61f9b52b3ef586de5c2","frame_index":0,"kind":"data","monotonic_ns":305735395722416,"payload":{"event_type":"price_change","market":"0xda6f0e0e93fc8469e0159a166028d017bddbc162b86f66bac90391379603d962","price_changes":[{"asset_id":"39272994714739463168905443499424551362424437245880253267329605556587274644733","best_ask":"0.49","best_bid":"0.48","hash":"bdc45ea4133570129fe0333920cd5827d7fc617e","price":"0.43","side":"BUY","size":"255"},{"asset_id":"20893381255801015515826997628594359667013752732428989472914000440642900266717","best_ask":"0.52","best_bid":"0.51","hash":"51aea5aff20e71f8ff72814ab58e442633202c14","price":"0.57","side":"SELL","size":"255"}],"timestamp":"1785203752226"},"payload_hash":"572272a097090936c22f6ef7c579591d30888520a8358ba93f8ab1362a7dfdea","raw_frame":"{\"market\":\"0xda6f0e0e93fc8469e0159a166028d017bddbc162b86f66bac90391379603d962\", \"price_changes\":[{\"asset_id\":\"39272994714739463168905443499424551362424437245880253267329605556587274644733\", \"price\":\"0.43\", \"size\":\"255\", \"side\":\"BUY\", \"hash\":\"bdc45ea4133570129fe0333920cd5827d7fc617e\", \"best_bid\":\"0.48\", \"best_ask\":\"0.49\"}, {\"asset_id\":\"20893381255801015515826997628594359667013752732428989472914000440642900266717\", \"price\":\"0.57\", \"size\":\"255\", \"side\":\"SELL\", \"hash\":\"51aea5aff20e71f8ff72814ab58e442633202c14\", \"best_bid\":\"0.51\", \"best_ask\":\"0.52\"}], \"timestamp\":\"1785203752226\", \"event_type\":\"price_change\"}","received_at":"2026-07-28T01:55:52.387124Z","schema_version":"clob-market-ws.price_change.v1","sequence":null,"server_hash":null,"server_timestamp":"1785203752226","session_id":"d2757dd6dad94f3b9fe67e8dbf1adc37","source":"clob_market_ws"},"received_at":"2026-07-28T01:55:52.387124Z","record_id":"13abe3871aae74f102f95f02739174f73086231d09b4a614380e09c765511598","schema_fingerprint":"4aa3821a28b0b7c2400bc59aba4bcc0a76e971dadd19610d3ad38c768e124dc7","schema_version":"edge-lab-recorder.raw.v1","sequence":null,"source":"clob_market_ws"}
{"event_at":"2026-07-28T01:55:52.227000Z","event_fingerprint":"92d4d1a484491898e3aa7c70560a863bf052469dc625c724094559390ed88e45","payload":{"connection_id":"5d29200f65794d4d9ab6ef271f045a9b","event_at":"2026-07-28T01:55:52.227000Z","event_type":"price_change","frame_hash":"0703e446671eb18371c3f12a685d75609ba3bf946778e771ef15643829ff236a","frame_index":0,"kind":"data","monotonic_ns":305735485477083,"payload":{"event_type":"price_change","market":"0xda6f0e0e93fc8469e0159a166028d017bddbc162b86f66bac90391379603d962","price_changes":[{"asset_id":"39272994714739463168905443499424551362424437245880253267329605556587274644733","best_ask":"0.49","best_bid":"0.48","hash":"53dd1e2b6e1460d08cbed3a36399fcf8cbc848db","price":"0.43","side":"BUY","size":"260"},{"asset_id":"20893381255801015515826997628594359667013752732428989472914000440642900266717","best_ask":"0.52","best_bid":"0.51","hash":"446af34d256f8afbe37c4efb7f2b12490cb313a7","price":"0.57","side":"SELL","size":"260"}],"timestamp":"1785203752227"},"payload_hash":"884d33e9ef322ac02ce19159ea7e1af6a5007d7afde2d9f95a0967a73ecefcac","raw_frame":"{\"market\":\"0xda6f0e0e93fc8469e0159a166028d017bddbc162b86f66bac90391379603d962\", \"price_changes\":[{\"asset_id\":\"39272994714739463168905443499424551362424437245880253267329605556587274644733\", \"price\":\"0.43\", \"size\":\"260\", \"side\":\"BUY\", \"hash\":\"53dd1e2b6e1460d08cbed3a36399fcf8cbc848db\", \"best_bid\":\"0.48\", \"best_ask\":\"0.49\"}, {\"asset_id\":\"20893381255801015515826997628594359667013752732428989472914000440642900266717\", \"price\":\"0.57\", \"size\":\"260\", \"side\":\"SELL\", \"hash\":\"446af34d256f8afbe37c4efb7f2b12490cb313a7\", \"best_bid\":\"0.51\", \"best_ask\":\"0.52\"}], \"timestamp\":\"1785203752227\", \"event_type\":\"price_change\"}","received_at":"2026-07-28T01:55:52.476877Z","schema_version":"clob-market-ws.price_change.v1","sequence":null,"server_hash":null,"server_timestamp":"1785203752227","session_id":"d2757dd6dad94f3b9fe67e8dbf1adc37","source":"clob_market_ws"},"received_at":"2026-07-28T01:55:52.476877Z","record_id":"bf6090b98f226f9b57f4095ba85b77b08adcc457fadf0852b79e3a943022f76f","schema_fingerprint":"4aa3821a28b0b7c2400bc59aba4bcc0a76e971dadd19610d3ad38c768e124dc7","schema_version":"edge-lab-recorder.raw.v1","sequence":null,"source":"clob_market_ws"}
{"event_at":"2026-07-28T01:55:52.228000Z","event_fingerprint":"620676dbeeb396702522d899d7e49b7d87ce1b015a593c0942ffa2c9b7833930","payload":{"connection_id":"5d29200f65794d4d9ab6ef271f045a9b","event_at":"2026-07-28T01:55:52.228000Z","event_type":"price_change","frame_hash":"ecfb9e707742719efff042884b8747ac951e3d14c36eba2c5ec235926fca9a58","frame_index":0,"kind":"data","monotonic_ns":305735489703625,"payload":{"event_type":"price_change","market":"0xda6f0e0e93fc8469e0159a166028d017bddbc162b86f66bac90391379603d962","price_changes":[{"asset_id":"39272994714739463168905443499424551362424437245880253267329605556587274644733","best_ask":"0.49","best_bid":"0.48","hash":"ea0d24e72666ddb0599eceb6a5f42386b26093c3","price":"0.43","side":"BUY","size":"265"},{"asset_id":"20893381255801015515826997628594359667013752732428989472914000440642900266717","best_ask":"0.52","best_bid":"0.51","hash":"9334803487f839424c9d170f2296c81346ed7222","price":"0.57","side":"SELL","size":"265"}],"timestamp":"1785203752228"},"payload_hash":"8faf14039e8afddb97e8aa20f5457fd3d4054e86da99feeb8a3c27f150d394d7","raw_frame":"{\"market\":\"0xda6f0e0e93fc8469e0159a166028d017bddbc162b86f66bac90391379603d962\", \"price_changes\":[{\"asset_id\":\"39272994714739463168905443499424551362424437245880253267329605556587274644733\", \"price\":\"0.43\", \"size\":\"265\", \"side\":\"BUY\", \"hash\":\"ea0d24e72666ddb0599eceb6a5f42386b26093c3\", \"best_bid\":\"0.48\", \"best_ask\":\"0.49\"}, {\"asset_id\":\"20893381255801015515826997628594359667013752732428989472914000440642900266717\", \"price\":\"0.57\", \"size\":\"265\", \"side\":\"SELL\", \"hash\":\"9334803487f839424c9d170f2296c81346ed7222\", \"best_bid\":\"0.51\", \"best_ask\":\"0.52\"}], \"timestamp\":\"1785203752228\", \"event_type\":\"price_change\"}","received_at":"2026-07-28T01:55:52.481104Z","schema_version":"clob-market-ws.price_change.v1","sequence":null,"server_hash":null,"server_timestamp":"1785203752228","session_id":"d2757dd6dad94f3b9fe67e8dbf1adc37","source":"clob_market_ws"},"received_at":"2026-07-28T01:55:52.481104Z","record_id":"2627fef7387dd5020ee501f6bd8ebe38d9aca938792aac3313484e1b2abac52a","schema_fingerprint":"4aa3821a28b0b7c2400bc59aba4bcc0a76e971dadd19610d3ad38c768e124dc7","schema_version":"edge-lab-recorder.raw.v1","sequence":null,"source":"clob_market_ws"}
{"event_at":"2026-07-28T01:55:52.229000Z","event_fingerprint":"74e05964e6f889b3aa56bceeddac462586f23aac8629988fffbb667eb89b0057","payload":{"connection_id":"5d29200f65794d4d9ab6ef271f045a9b","event_at":"2026-07-28T01:55:52.229000Z","event_type":"price_change","frame_hash":"4ec8a1c9d77ef1a02117f095cbb79ab2e261d31c7ad6a3e51c84070b65344199","frame_index":0,"kind":"data","monotonic_ns":305735493898750,"payload":{"event_type":"price_change","market":"0xda6f0e0e93fc8469e0159a166028d017bddbc162b86f66bac90391379603d962","price_changes":[{"asset_id":"39272994714739463168905443499424551362424437245880253267329605556587274644733","best_ask":"0.49","best_bid":"0.48","hash":"1370909dcd73fd31881afd0967b1a222f2cf911f","price":"0.43","side":"BUY","size":"270"},{"asset_id":"20893381255801015515826997628594359667013752732428989472914000440642900266717","best_ask":"0.52","best_bid":"0.51","hash":"6337c15431dd105dc638618395e9e1b9a21a9370","price":"0.57","side":"SELL","size":"270"}],"timestamp":"1785203752229"},"payload_hash":"6711c292afabb90a4d155d8493d4d88ad139637e8b1227fd939babd74f57cf81","raw_frame":"{\"market\":\"0xda6f0e0e93fc8469e0159a166028d017bddbc162b86f66bac90391379603d962\", \"price_changes\":[{\"asset_id\":\"39272994714739463168905443499424551362424437245880253267329605556587274644733\", \"price\":\"0.43\", \"size\":\"270\", \"side\":\"BUY\", \"hash\":\"1370909dcd73fd31881afd0967b1a222f2cf911f\", \"best_bid\":\"0.48\", \"best_ask\":\"0.49\"}, {\"asset_id\":\"20893381255801015515826997628594359667013752732428989472914000440642900266717\", \"price\":\"0.57\", \"size\":\"270\", \"side\":\"SELL\", \"hash\":\"6337c15431dd105dc638618395e9e1b9a21a9370\", \"best_bid\":\"0.51\", \"best_ask\":\"0.52\"}], \"timestamp\":\"1785203752229\", \"event_type\":\"price_change\"}","received_at":"2026-07-28T01:55:52.485299Z","schema_version":"clob-market-ws.price_change.v1","sequence":null,"server_hash":null,"server_timestamp":"1785203752229","session_id":"d2757dd6dad94f3b9fe67e8dbf1adc37","source":"clob_market_ws"},"received_at":"2026-07-28T01:55:52.485299Z","record_id":"11f4bd8682b08b190bdd3c35a6100f25d79e4fe68fe5ddfb6c156111c05b512a","schema_fingerprint":"4aa3821a28b0b7c2400bc59aba4bcc0a76e971dadd19610d3ad38c768e124dc7","schema_version":"edge-lab-recorder.raw.v1","sequence":null,"source":"clob_market_ws"}
{"event_at":"2026-07-28T01:55:52.230000Z","event_fingerprint":"7377e2372ff87811d167e4942044722d9dee0e1f10c1185438fe385ab239ba77","payload":{"connection_id":"5d29200f65794d4d9ab6ef271f045a9b","event_at":"2026-07-28T01:55:52.230000Z","event_type":"price_change","frame_hash":"6a173d944d8668a51ebcd04f52569bde907fe2ee721686baa0ab93fe3b433d46","frame_index":0,"kind":"data","monotonic_ns":305735498119833,"payload":{"event_type":"price_change","market":"0xda6f0e0e93fc8469e0159a166028d017bddbc162b86f66bac90391379603d962","price_changes":[{"asset_id":"39272994714739463168905443499424551362424437245880253267329605556587274644733","best_ask":"0.49","best_bid":"0.48","hash":"7a7c813891074b017338f532362cf6f8c33bf566","price":"0.43","side":"BUY","size":"275"},{"asset_id":"20893381255801015515826997628594359667013752732428989472914000440642900266717","best_ask":"0.52","best_bid":"0.51","hash":"7678c951203b8eeb96ce61f4c9731fc52fc6ae47","price":"0.57","side":"SELL","size":"275"}],"timestamp":"1785203752230"},"payload_hash":"a35ca4c904a7cbaa7ba92cd015044d64e5c05eacd705d10b3875d8a0e54d3437","raw_frame":"{\"market\":\"0xda6f0e0e93fc8469e0159a166028d017bddbc162b86f66bac90391379603d962\", \"price_changes\":[{\"asset_id\":\"39272994714739463168905443499424551362424437245880253267329605556587274644733\", \"price\":\"0.43\", \"size\":\"275\", \"side\":\"BUY\", \"hash\":\"7a7c813891074b017338f532362cf6f8c33bf566\", \"best_bid\":\"0.48\", \"best_ask\":\"0.49\"}, {\"asset_id\":\"20893381255801015515826997628594359667013752732428989472914000440642900266717\", \"price\":\"0.57\", \"size\":\"275\", \"side\":\"SELL\", \"hash\":\"7678c951203b8eeb96ce61f4c9731fc52fc6ae47\", \"best_bid\":\"0.51\", \"best_ask\":\"0.52\"}], \"timestamp\":\"1785203752230\", \"event_type\":\"price_change\"}","received_at":"2026-07-28T01:55:52.489522Z","schema_version":"clob-market-ws.price_change.v1","sequence":null,"server_hash":null,"server_timestamp":"1785203752230","session_id":"d2757dd6dad94f3b9fe67e8dbf1adc37","source":"clob_market_ws"},"received_at":"2026-07-28T01:55:52.489522Z","record_id":"f06dc7f1410cd81e6da282d0429a2da2fd2e3eafde369500ff52c015ebb79bce","schema_fingerprint":"4aa3821a28b0b7c2400bc59aba4bcc0a76e971dadd19610d3ad38c768e124dc7","schema_version":"edge-lab-recorder.raw.v1","sequence":null,"source":"clob_market_ws"}
{"event_at":"2026-07-28T01:55:52.231000Z","event_fingerprint":"f41941736c8c068f5d5b09a2a615c2c7b2d61f5075e739f5d7e4a1d3f6f10ecd","payload":{"connection_id":"5d29200f65794d4d9ab6ef271f045a9b","event_at":"2026-07-28T01:55:52.231000Z","event_type":"price_change","frame_hash":"405d0f2259c26a89ba5a428d8350d90649a6251de8c5f2242d803906ab9c5019","frame_index":0,"kind":"data","monotonic_ns":305735501722458,"payload":{"event_type":"price_change","market":"0xda6f0e0e93fc8469e0159a166028d017bddbc162b86f66bac90391379603d962","price_changes":[{"asset_id":"39272994714739463168905443499424551362424437245880253267329605556587274644733","best_ask":"0.49","best_bid":"0.48","hash":"e6f2ecf7241dbf15b05a0b14dc18ec55bb0466e7","price":"0.43","side":"BUY","size":"280"},{"asset_id":"20893381255801015515826997628594359667013752732428989472914000440642900266717","best_ask":"0.52","best_bid":"0.51","hash":"98c813167dfe34cf3762c95b8e8f080aec81d702","price":"0.57","side":"SELL","size":"280"}],"timestamp":"1785203752231"},"payload_hash":"32716ebfe8576b8f80719c8082103d46d6895930be9df08ec3e13a661ac638f5","raw_frame":"{\"market\":\"0xda6f0e0e93fc8469e0159a166028d017bddbc162b86f66bac90391379603d962\", \"price_changes\":[{\"asset_id\":\"39272994714739463168905443499424551362424437245880253267329605556587274644733\", \"price\":\"0.43\", \"size\":\"280\", \"side\":\"BUY\", \"hash\":\"e6f2ecf7241dbf15b05a0b14dc18ec55bb0466e7\", \"best_bid\":\"0.48\", \"best_ask\":\"0.49\"}, {\"asset_id\":\"20893381255801015515826997628594359667013752732428989472914000440642900266717\", \"price\":\"0.57\", \"size\":\"280\", \"side\":\"SELL\", \"hash\":\"98c813167dfe34cf3762c95b8e8f080aec81d702\", \"best_bid\":\"0.51\", \"best_ask\":\"0.52\"}], \"timestamp\":\"1785203752231\", \"event_type\":\"price_change\"}","received_at":"2026-07-28T01:55:52.493124Z","schema_version":"clob-market-ws.price_change.v1","sequence":null,"server_hash":null,"server_timestamp":"1785203752231","session_id":"d2757dd6dad94f3b9fe67e8dbf1adc37","source":"clob_market_ws"},"received_at":"2026-07-28T01:55:52.493124Z","record_id":"9617c718f82e54012ff18d539ecc3f0b66864b041c52a35409c92136986400a7","schema_fingerprint":"4aa3821a28b0b7c2400bc59aba4bcc0a76e971dadd19610d3ad38c768e124dc7","schema_version":"edge-lab-recorder.raw.v1","sequence":null,"source":"clob_market_ws"}
{"event_at":"2026-07-28T01:55:52.232000Z","event_fingerprint":"4051d2d31dc67911fd960bf13251ca18673a34a7e0aed9869755eb4686c9bba1","payload":{"connection_id":"5d29200f65794d4d9ab6ef271f045a9b","event_at":"2026-07-28T01:55:52.232000Z","event_type":"price_change","frame_hash":"0d281e333fb516abcda41dac648ec5b262ab221d3ee2b48e597070284c99c884","frame_index":0,"kind":"data","monotonic_ns":305735505964250,"payload":{"event_type":"price_change","market":"0xda6f0e0e93fc8469e0159a166028d017bddbc162b86f66bac90391379603d962","price_changes":[{"asset_id":"39272994714739463168905443499424551362424437245880253267329605556587274644733","best_ask":"0.49","best_bid":"0.48","hash":"f49eed151ab859c20375190b7cbdbe0b5e79abf0","price":"0.43","side":"BUY","size":"285"},{"asset_id":"20893381255801015515826997628594359667013752732428989472914000440642900266717","best_ask":"0.52","best_bid":"0.51","hash":"74a0787e6a5335fd02323d2d0dc4369f4d6dfd5f","price":"0.57","side":"SELL","size":"285"}],"timestamp":"1785203752232"},"payload_hash":"83dc64c8791505ad11673e0181d2b6c797c13d8656e41904b20da26e2dfd25a5","raw_frame":"{\"market\":\"0xda6f0e0e93fc8469e0159a166028d017bddbc162b86f66bac90391379603d962\", \"price_changes\":[{\"asset_id\":\"39272994714739463168905443499424551362424437245880253267329605556587274644733\", \"price\":\"0.43\", \"size\":\"285\", \"side\":\"BUY\", \"hash\":\"f49eed151ab859c20375190b7cbdbe0b5e79abf0\", \"best_bid\":\"0.48\", \"best_ask\":\"0.49\"}, {\"asset_id\":\"20893381255801015515826997628594359667013752732428989472914000440642900266717\", \"price\":\"0.57\", \"size\":\"285\", \"side\":\"SELL\", \"hash\":\"74a0787e6a5335fd02323d2d0dc4369f4d6dfd5f\", \"best_bid\":\"0.51\", \"best_ask\":\"0.52\"}], \"timestamp\":\"1785203752232\", \"event_type\":\"price_change\"}","received_at":"2026-07-28T01:55:52.497365Z","schema_version":"clob-market-ws.price_change.v1","sequence":null,"server_hash":null,"server_timestamp":"1785203752232","session_id":"d2757dd6dad94f3b9fe67e8dbf1adc37","source":"clob_market_ws"},"received_at":"2026-07-28T01:55:52.497365Z","record_id":"edb78133f9c0da1826265ac1ab4895aa13e79edaab4f9e838257ec174ef22448","schema_fingerprint":"4aa3821a28b0b7c2400bc59aba4bcc0a76e971dadd19610d3ad38c768e124dc7","schema_version":"edge-lab-recorder.raw.v1","sequence":null,"source":"clob_market_ws"}
{"event_at":"2026-07-28T01:55:52.233000Z","event_fingerprint":"eb1d7f5f794361bab5adef064f2f996c94805fef3a7c37883a9f923ba4a7a4e5","payload":{"connection_id":"5d29200f65794d4d9ab6ef271f045a9b","event_at":"2026-07-28T01:55:52.233000Z","event_type":"price_change","frame_hash":"8f5ecb74b3f3f4480008578d8e5a72e5220902e03f63c45b10d41aa3e03d3cce","frame_index":0,"kind":"data","monotonic_ns":305735510184208,"payload":{"event_type":"price_change","market":"0xda6f0e0e93fc8469e0159a166028d017bddbc162b86f66bac90391379603d962","price_changes":[{"asset_id":"39272994714739463168905443499424551362424437245880253267329605556587274644733","best_ask":"0.49","best_bid":"0.48","hash":"2d76c0f224fd8e80ab2c6cf5cebfef50179cd615","price":"0.43","side":"BUY","size":"290"},{"asset_id":"20893381255801015515826997628594359667013752732428989472914000440642900266717","best_ask":"0.52","best_bid":"0.51","hash":"8b25b96f4fd44138372197add8aa2d3b2cbb2760","price":"0.57","side":"SELL","size":"290"}],"timestamp":"1785203752233"},"payload_hash":"b9ff1c83e072e89442df6494118dad9358c71c6e935f62bcf40c29df36d3aec7","raw_frame":"{\"market\":\"0xda6f0e0e93fc8469e0159a166028d017bddbc162b86f66bac90391379603d962\", \"price_changes\":[{\"asset_id\":\"39272994714739463168905443499424551362424437245880253267329605556587274644733\", \"price\":\"0.43\", \"size\":\"290\", \"side\":\"BUY\", \"hash\":\"2d76c0f224fd8e80ab2c6cf5cebfef50179cd615\", \"best_bid\":\"0.48\", \"best_ask\":\"0.49\"}, {\"asset_id\":\"20893381255801015515826997628594359667013752732428989472914000440642900266717\", \"price\":\"0.57\", \"size\":\"290\", \"side\":\"SELL\", \"hash\":\"8b25b96f4fd44138372197add8aa2d3b2cbb2760\", \"best_bid\":\"0.51\", \"best_ask\":\"0.52\"}], \"timestamp\":\"1785203752233\", \"event_type\":\"price_change\"}","received_at":"2026-07-28T01:55:52.501585Z","schema_version":"clob-market-ws.price_change.v1","sequence":null,"server_hash":null,"server_timestamp":"1785203752233","session_id":"d2757dd6dad94f3b9fe67e8dbf1adc37","source":"clob_market_ws"},"received_at":"2026-07-28T01:55:52.501585Z","record_id":"3f5aeff08fe57a6bdebcbbf983dfcaca50f3f45739c12bfd8b78a977ed6eaa4e","schema_fingerprint":"4aa3821a28b0b7c2400bc59aba4bcc0a76e971dadd19610d3ad38c768e124dc7","schema_version":"edge-lab-recorder.raw.v1","sequence":null,"source":"clob_market_ws"}
{"event_at":"2026-07-28T01:55:52.234000Z","event_fingerprint":"d4922604d7fd26a9dde3c4c8fdfa096ce95e1865aeb440b3320e9b966bf24fda","payload":{"connection_id":"5d29200f65794d4d9ab6ef271f045a9b","event_at":"2026-07-28T01:55:52.234000Z","event_type":"price_change","frame_hash":"e0a4971f574f5d9a8048d7e8229e81287ab1860484c62adedf37adcf69a83b15","frame_index":0,"kind":"data","monotonic_ns":305735514463458,"payload":{"event_type":"price_change","market":"0xda6f0e0e93fc8469e0159a166028d017bddbc162b86f66bac90391379603d962","price_changes":[{"asset_id":"39272994714739463168905443499424551362424437245880253267329605556587274644733","best_ask":"0.49","best_bid":"0.48","hash":"005df790665c9789f7adf21c21df45fe70af6852","price":"0.43","side":"BUY","size":"295"},{"asset_id":"20893381255801015515826997628594359667013752732428989472914000440642900266717","best_ask":"0.52","best_bid":"0.51","hash":"a8c921151e1c0bff8b3200b18286ee1fb518c830","price":"0.57","side":"SELL","size":"295"}],"timestamp":"1785203752234"},"payload_hash":"7d70e210866f0f1a05f4e21786529b15d929268224bb9d7d99aa0c3ac5d46e00","raw_frame":"{\"market\":\"0xda6f0e0e93fc8469e0159a166028d017bddbc162b86f66bac90391379603d962\", \"price_changes\":[{\"asset_id\":\"39272994714739463168905443499424551362424437245880253267329605556587274644733\", \"price\":\"0.43\", \"size\":\"295\", \"side\":\"BUY\", \"hash\":\"005df790665c9789f7adf21c21df45fe70af6852\", \"best_bid\":\"0.48\", \"best_ask\":\"0.49\"}, {\"asset_id\":\"20893381255801015515826997628594359667013752732428989472914000440642900266717\", \"price\":\"0.57\", \"size\":\"295\", \"side\":\"SELL\", \"hash\":\"a8c921151e1c0bff8b3200b18286ee1fb518c830\", \"best_bid\":\"0.51\", \"best_ask\":\"0.52\"}], \"timestamp\":\"1785203752234\", \"event_type\":\"price_change\"}","received_at":"2026-07-28T01:55:52.505864Z","schema_version":"clob-market-ws.price_change.v1","sequence":null,"server_hash":null,"server_timestamp":"1785203752234","session_id":"d2757dd6dad94f3b9fe67e8dbf1adc37","source":"clob_market_ws"},"received_at":"2026-07-28T01:55:52.505864Z","record_id":"4d8611403da334dfe5d1955d49d8da5511c39a3bc9e68e976ad882fc8953d54e","schema_fingerprint":"4aa3821a28b0b7c2400bc59aba4bcc0a76e971dadd19610d3ad38c768e124dc7","schema_version":"edge-lab-recorder.raw.v1","sequence":null,"source":"clob_market_ws"}
{"event_at":"2026-07-28T01:55:52.235000Z","event_fingerprint":"802d1134cffb26ada6265e069970c8da769873dcd037e3a6ae76e7368996ecbd","payload":{"connection_id":"5d29200f65794d4d9ab6ef271f045a9b","event_at":"2026-07-28T01:55:52.235000Z","event_type":"price_change","frame_hash":"d5f76ffe7348ba164d946d2fd28e9dcffbaa92fa44d88622eba5133ed229b022","frame_index":0,"kind":"data","monotonic_ns":305735518845125,"payload":{"event_type":"price_change","market":"0xda6f0e0e93fc8469e0159a166028d017bddbc162b86f66bac90391379603d962","price_changes":[{"asset_id":"39272994714739463168905443499424551362424437245880253267329605556587274644733","best_ask":"0.49","best_bid":"0.48","hash":"5afe59eb9281da0962e79da7ad32b304c6316614","price":"0.43","side":"BUY","size":"300"},{"asset_id":"20893381255801015515826997628594359667013752732428989472914000440642900266717","best_ask":"0.52","best_bid":"0.51","hash":"0b034aa3cfa13943dcbede18f233228f15e7f3e8","price":"0.57","side":"SELL","size":"300"}],"timestamp":"1785203752235"},"payload_hash":"cb39b11855628b7723150dbe1246cb8a353b566494adbefb49df109dfe998e68","raw_frame":"{\"market\":\"0xda6f0e0e93fc8469e0159a166028d017bddbc162b86f66bac90391379603d962\", \"price_changes\":[{\"asset_id\":\"39272994714739463168905443499424551362424437245880253267329605556587274644733\", \"price\":\"0.43\", \"size\":\"300\", \"side\":\"BUY\", \"hash\":\"5afe59eb9281da0962e79da7ad32b304c6316614\", \"best_bid\":\"0.48\", \"best_ask\":\"0.49\"}, {\"asset_id\":\"20893381255801015515826997628594359667013752732428989472914000440642900266717\", \"price\":\"0.57\", \"size\":\"300\", \"side\":\"SELL\", \"hash\":\"0b034aa3cfa13943dcbede18f233228f15e7f3e8\", \"best_bid\":\"0.51\", \"best_ask\":\"0.52\"}], \"timestamp\":\"1785203752235\", \"event_type\":\"price_change\"}","received_at":"2026-07-28T01:55:52.510245Z","schema_version":"clob-market-ws.price_change.v1","sequence":null,"server_hash":null,"server_timestamp":"1785203752235","session_id":"d2757dd6dad94f3b9fe67e8dbf1adc37","source":"clob_market_ws"},"received_at":"2026-07-28T01:55:52.510245Z","record_id":"cce041da43e1cb45a1e3dc919f4573c3cf6cdd2d84baa7a11ebdb0137811387b","schema_fingerprint":"4aa3821a28b0b7c2400bc59aba4bcc0a76e971dadd19610d3ad38c768e124dc7","schema_version":"edge-lab-recorder.raw.v1","sequence":null,"source":"clob_market_ws"}
{"event_at":"2026-07-28T01:55:52.236000Z","event_fingerprint":"379c57ef2f37202731891799255dcce6e5339c770e9b8204f395efe6e08bded2","payload":{"connection_id":"5d29200f65794d4d9ab6ef271f045a9b","event_at":"2026-07-28T01:55:52.236000Z","event_type":"price_change","frame_hash":"cfab3ec348ce613c515681fb25b266a58e3c23f9d4c7de6cd1ffca1110692ce8","frame_index":0,"kind":"data","monotonic_ns":305735523133708,"payload":{"event_type":"price_change","market":"0xda6f0e0e93fc8469e0159a166028d017bddbc162b86f66bac90391379603d962","price_changes":[{"asset_id":"39272994714739463168905443499424551362424437245880253267329605556587274644733","best_ask":"0.49","best_bid":"0.48","hash":"d9deb7b9518282539d2976e6c91f09f184305795","price":"0.43","side":"BUY","size":"305"},{"asset_id":"20893381255801015515826997628594359667013752732428989472914000440642900266717","best_ask":"0.52","best_bid":"0.51","hash":"d779abf9cabac9f9ccb3b647ca9c3914ce8175a4","price":"0.57","side":"SELL","size":"305"}],"timestamp":"1785203752236"},"payload_hash":"972964983f5ec224bbd67f33230a9f66f81be7db03c3a08fcacd223b49b0e8ca","raw_frame":"{\"market\":\"0xda6f0e0e93fc8469e0159a166028d017bddbc162b86f66bac90391379603d962\", \"price_changes\":[{\"asset_id\":\"39272994714739463168905443499424551362424437245880253267329605556587274644733\", \"price\":\"0.43\", \"size\":\"305\", \"side\":\"BUY\", \"hash\":\"d9deb7b9518282539d2976e6c91f09f184305795\", \"best_bid\":\"0.48\", \"best_ask\":\"0.49\"}, {\"asset_id\":\"20893381255801015515826997628594359667013752732428989472914000440642900266717\", \"price\":\"0.57\", \"size\":\"305\", \"side\":\"SELL\", \"hash\":\"d779abf9cabac9f9ccb3b647ca9c3914ce8175a4\", \"best_bid\":\"0.51\", \"best_ask\":\"0.52\"}], \"timestamp\":\"1785203752236\", \"event_type\":\"price_change\"}","received_at":"2026-07-28T01:55:52.514534Z","schema_version":"clob-market-ws.price_change.v1","sequence":null,"server_hash":null,"server_timestamp":"1785203752236","session_id":"d2757dd6dad94f3b9fe67e8dbf1adc37","source":"clob_market_ws"},"received_at":"2026-07-28T01:55:52.514534Z","record_id":"99989707e3eb2f48ecc1889303dbe445ef981ddb65b48c6a8a5fa847a5812dc3","schema_fingerprint":"4aa3821a28b0b7c2400bc59aba4bcc0a76e971dadd19610d3ad38c768e124dc7","schema_version":"edge-lab-recorder.raw.v1","sequence":null,"source":"clob_market_ws"}
{"event_at":"2026-07-28T01:55:52.237000Z","event_fingerprint":"5cf229a5bbfe05aac41ddb74e1871a79bad409adcead1574c17c403afde0f748","payload":{"connection_id":"5d29200f65794d4d9ab6ef271f045a9b","event_at":"2026-07-28T01:55:52.237000Z","event_type":"price_change","frame_hash":"e5da54c64a2977dfed4a04f9894cb494262791fcbfad34534684cb04c7dfcb2d","frame_index":0,"kind":"data","monotonic_ns":305735527306125,"payload":{"event_type":"price_change","market":"0xda6f0e0e93fc8469e0159a166028d017bddbc162b86f66bac90391379603d962","price_changes":[{"asset_id":"39272994714739463168905443499424551362424437245880253267329605556587274644733","best_ask":"0.49","best_bid":"0.48","hash":"70286fab22a66d54e60436ffc0753dc3ecae7d24","price":"0.43","side":"BUY","size":"310"},{"asset_id":"20893381255801015515826997628594359667013752732428989472914000440642900266717","best_ask":"0.52","best_bid":"0.51","hash":"e93ccb539acab3cd42789dbf4893bb5f6b08959c","price":"0.57","side":"SELL","size":"310"}],"timestamp":"1785203752237"},"payload_hash":"0f2b0fd03ecca4b12907c369c99f04b28063644f40526d5150ee2393ba9a4d71","raw_frame":"{\"market\":\"0xda6f0e0e93fc8469e0159a166028d017bddbc162b86f66bac90391379603d962\", \"price_changes\":[{\"asset_id\":\"39272994714739463168905443499424551362424437245880253267329605556587274644733\", \"price\":\"0.43\", \"size\":\"310\", \"side\":\"BUY\", \"hash\":\"70286fab22a66d54e60436ffc0753dc3ecae7d24\", \"best_bid\":\"0.48\", \"best_ask\":\"0.49\"}, {\"asset_id\":\"20893381255801015515826997628594359667013752732428989472914000440642900266717\", \"price\":\"0.57\", \"size\":\"310\", \"side\":\"SELL\", \"hash\":\"e93ccb539acab3cd42789dbf4893bb5f6b08959c\", \"best_bid\":\"0.51\", \"best_ask\":\"0.52\"}], \"timestamp\":\"1785203752237\", \"event_type\":\"price_change\"}","received_at":"2026-07-28T01:55:52.518706Z","schema_version":"clob-market-ws.price_change.v1","sequence":null,"server_hash":null,"server_timestamp":"1785203752237","session_id":"d2757dd6dad94f3b9fe67e8dbf1adc37","source":"clob_market_ws"},"received_at":"2026-07-28T01:55:52.518706Z","record_id":"64cdbf4f8e25995ff883ad0df37ab4db930be3ff2e855530992cfda373129c15","schema_fingerprint":"4aa3821a28b0b7c2400bc59aba4bcc0a76e971dadd19610d3ad38c768e124dc7","schema_version":"edge-lab-recorder.raw.v1","sequence":null,"source":"clob_market_ws"}
{"event_at":"2026-07-28T01:55:52.238000Z","event_fingerprint":"3362d073be4c80350e4529282ef83024e73171643c57593e8d80a2dc150bfac6","payload":{"connection_id":"5d29200f65794d4d9ab6ef271f045a9b","event_at":"2026-07-28T01:55:52.238000Z","event_type":"price_change","frame_hash":"8d7e2e08251347304cf1f958fd086c7e0c1871dbace55c33cac165ebd397ae1a","frame_index":0,"kind":"data","monotonic_ns":305735531654000,"payload":{"event_type":"price_change","market":"0xda6f0e0e93fc8469e0159a166028d017bddbc162b86f66bac90391379603d962","price_changes":[{"asset_id":"39272994714739463168905443499424551362424437245880253267329605556587274644733","best_ask":"0.49","best_bid":"0.48","hash":"d1fdfe4c4c0f5e91b51a59e97983fe69d0d9ead0","price":"0.43","side":"BUY","size":"315"},{"asset_id":"20893381255801015515826997628594359667013752732428989472914000440642900266717","best_ask":"0.52","best_bid":"0.51","hash":"520f53db81506fdf1a4550e54fc964e1d2e26049","price":"0.57","side":"SELL","size":"315"}],"timestamp":"1785203752238"},"payload_hash":"725538504d49d7db42db21e639b148e2819c37512a60e76120a2bc97cc2234c2","raw_frame":"{\"market\":\"0xda6f0e0e93fc8469e0159a166028d017bddbc162b86f66bac90391379603d962\", \"price_changes\":[{\"asset_id\":\"39272994714739463168905443499424551362424437245880253267329605556587274644733\", \"price\":\"0.43\", \"size\":\"315\", \"side\":\"BUY\", \"hash\":\"d1fdfe4c4c0f5e91b51a59e97983fe69d0d9ead0\", \"best_bid\":\"0.48\", \"best_ask\":\"0.49\"}, {\"asset_id\":\"20893381255801015515826997628594359667013752732428989472914000440642900266717\", \"price\":\"0.57\", \"size\":\"315\", \"side\":\"SELL\", \"hash\":\"520f53db81506fdf1a4550e54fc964e1d2e26049\", \"best_bid\":\"0.51\", \"best_ask\":\"0.52\"}], \"timestamp\":\"1785203752238\", \"event_type\":\"price_change\"}","received_at":"2026-07-28T01:55:52.523054Z","schema_version":"clob-market-ws.price_change.v1","sequence":null,"server_hash":null,"server_timestamp":"1785203752238","session_id":"d2757dd6dad94f3b9fe67e8dbf1adc37","source":"clob_market_ws"},"received_at":"2026-07-28T01:55:52.523054Z","record_id":"e598cc9c57d8e039868827278463dacf7bb0407b87ed850f7c8eacdd8670b7e7","schema_fingerprint":"4aa3821a28b0b7c2400bc59aba4bcc0a76e971dadd19610d3ad38c768e124dc7","schema_version":"edge-lab-recorder.raw.v1","sequence":null,"source":"clob_market_ws"}
{"event_at":null,"event_fingerprint":"e7e69804537d2f1e1312fe23dfef103b32bfb758977b675adf8b536c44a00737","payload":{"connection_id":"5d29200f65794d4d9ab6ef271f045a9b","detail":{"interval_seconds":10.0,"message":"PING"},"event_type":"heartbeat","kind":"lifecycle","monotonic_ns":305743756743833,"received_at":"2026-07-28T01:56:00.748047Z","schema_version":"edge-lab-recorder.lifecycle.v1","session_id":"d2757dd6dad94f3b9fe67e8dbf1adc37","source":"clob_market_ws"},"received_at":"2026-07-28T01:56:00.748047Z","record_id":"7f1f0ea497ab2094683b68112ace6f669e8725280b0a0873b47778f9017be198","schema_fingerprint":"cb8aa3aa4cb168a4b724fd9077bee6ecfb9bc586c57cfdf0ab89f00d82045e3c","schema_version":"edge-lab-recorder.raw.v1","sequence":null,"source":"clob_market_ws"}
{"event_at":null,"event_fingerprint":"5a8d0eb7f4b53cdf2ea93e6d3440230e67ddf7649c1784d8e5e43feb68ea17c3","payload":{"connection_id":"5d29200f65794d4d9ab6ef271f045a9b","event_type":"heartbeat_ack","frame_hash":"95784973cc639977bff93619700168505cb8f7855e44fa643d34622a43706c87","kind":"lifecycle","monotonic_ns":305743964107125,"raw_frame":"PONG","received_at":"2026-07-28T01:56:00.955409Z","schema_version":"edge-lab-recorder.heartbeat-ack.v1","session_id":"d2757dd6dad94f3b9fe67e8dbf1adc37","source":"clob_market_ws"},"received_at":"2026-07-28T01:56:00.955409Z","record_id":"f6d544fc2508465409dd49623596d0d3458166ae19ae29c8014163c7556b2d5a","schema_fingerprint":"c14ee1aab3ca674ee738e5268877b544d74c41ad3c427cedc09236467dc68ba1","schema_version":"edge-lab-recorder.raw.v1","sequence":null,"source":"clob_market_ws"}
{"event_at":null,"event_fingerprint":"b95f71d64c5ad25f9d38abc6a49a92d73dc98d16253983f1fb4d165d520d4634","payload":{"connection_id":"5d29200f65794d4d9ab6ef271f045a9b","detail":{"interval_seconds":10.0,"message":"PING"},"event_type":"heartbeat","kind":"lifecycle","monotonic_ns":305753762936625,"received_at":"2026-07-28T01:56:10.754125Z","schema_version":"edge-lab-recorder.lifecycle.v1","session_id":"d2757dd6dad94f3b9fe67e8dbf1adc37","source":"clob_market_ws"},"received_at":"2026-07-28T01:56:10.754125Z","record_id":"c955f4d7e148bce68a345adac96261a15c7b8e01c8531d4eee194c70f13a9a67","schema_fingerprint":"cb8aa3aa4cb168a4b724fd9077bee6ecfb9bc586c57cfdf0ab89f00d82045e3c","schema_version":"edge-lab-recorder.raw.v1","sequence":null,"source":"clob_market_ws"}
{"event_at":null,"event_fingerprint":"4100ee9ff563278224ebd879ccba144e81884ff6dd3eef3e4b68c32ab02db378","payload":{"connection_id":"5d29200f65794d4d9ab6ef271f045a9b","event_type":"heartbeat_ack","frame_hash":"95784973cc639977bff93619700168505cb8f7855e44fa643d34622a43706c87","kind":"lifecycle","monotonic_ns":305753971797541,"raw_frame":"PONG","received_at":"2026-07-28T01:56:10.962984Z","schema_version":"edge-lab-recorder.heartbeat-ack.v1","session_id":"d2757dd6dad94f3b9fe67e8dbf1adc37","source":"clob_market_ws"},"received_at":"2026-07-28T01:56:10.962984Z","record_id":"a7a5f7d7c8e6416c3dd310aa781ebecb634c6e994b043a5c807399b8eb919db7","schema_fingerprint":"c14ee1aab3ca674ee738e5268877b544d74c41ad3c427cedc09236467dc68ba1","schema_version":"edge-lab-recorder.raw.v1","sequence":null,"source":"clob_market_ws"}
{"event_at":"2026-07-28T01:56:11.238000Z","event_fingerprint":"5d5870379dda045181312bb6d64f36235986bddbadd973cdc2b5433e5ddd128e","payload":{"connection_id":"5d29200f65794d4d9ab6ef271f045a9b","event_at":"2026-07-28T01:56:11.238000Z","event_type":"price_change","frame_hash":"d0306a77b6931970512cc6cd881af25c26145cab0cb73d2cfd6c63b357391743","frame_index":0,"kind":"data","monotonic_ns":305754140319000,"payload":{"event_type":"price_change","market":"0xda6f0e0e93fc8469e0159a166028d017bddbc162b86f66bac90391379603d962","price_changes":[{"asset_id":"39272994714739463168905443499424551362424437245880253267329605556587274644733","best_ask":"0.49","best_bid":"0.48","hash":"2df4db3e72420fbc1cc64a8e6f48dc6000fc4296","price":"0.43","side":"BUY","size":"215"},{"asset_id":"20893381255801015515826997628594359667013752732428989472914000440642900266717","best_ask":"0.52","best_bid":"0.51","hash":"32263024739eb99ac2cbf766a4aa48ad7f0d5424","price":"0.57","side":"SELL","size":"215"}],"timestamp":"1785203771238"},"payload_hash":"41b5a5684776660df1bc8f17cd479553625eb8b8f7e754ba9a0fbf9d34772a1b","raw_frame":"{\"market\":\"0xda6f0e0e93fc8469e0159a166028d017bddbc162b86f66bac90391379603d962\", \"price_changes\":[{\"asset_id\":\"39272994714739463168905443499424551362424437245880253267329605556587274644733\", \"price\":\"0.43\", \"size\":\"215\", \"side\":\"BUY\", \"hash\":\"2df4db3e72420fbc1cc64a8e6f48dc6000fc4296\", \"best_bid\":\"0.48\", \"best_ask\":\"0.49\"}, {\"asset_id\":\"20893381255801015515826997628594359667013752732428989472914000440642900266717\", \"price\":\"0.57\", \"size\":\"215\", \"side\":\"SELL\", \"hash\":\"32263024739eb99ac2cbf766a4aa48ad7f0d5424\", \"best_bid\":\"0.51\", \"best_ask\":\"0.52\"}], \"timestamp\":\"1785203771238\", \"event_type\":\"price_change\"}","received_at":"2026-07-28T01:56:11.131505Z","schema_version":"clob-market-ws.price_change.v1","sequence":null,"server_hash":null,"server_timestamp":"1785203771238","session_id":"d2757dd6dad94f3b9fe67e8dbf1adc37","source":"clob_market_ws"},"received_at":"2026-07-28T01:56:11.131505Z","record_id":"55e06fbb7f17ed5ab425cb058fd10e5363c71ae7270676b16c05cc1d0b4b9d51","schema_fingerprint":"4aa3821a28b0b7c2400bc59aba4bcc0a76e971dadd19610d3ad38c768e124dc7","schema_version":"edge-lab-recorder.raw.v1","sequence":null,"source":"clob_market_ws"}
{"event_at":"2026-07-28T01:56:11.239000Z","event_fingerprint":"58f9554a2d4187b12267af2fcb549ba8e9bf34024abf83e756feb5952ccb7b5e","payload":{"connection_id":"5d29200f65794d4d9ab6ef271f045a9b","event_at":"2026-07-28T01:56:11.239000Z","event_type":"price_change","frame_hash":"1b538955705d0f3bd4b56836dbdadc2e9975c1f0e88009e0a8120d5035ddcdd4","frame_index":0,"kind":"data","monotonic_ns":305754149564083,"payload":{"event_type":"price_change","market":"0xda6f0e0e93fc8469e0159a166028d017bddbc162b86f66bac90391379603d962","price_changes":[{"asset_id":"39272994714739463168905443499424551362424437245880253267329605556587274644733","best_ask":"0.49","best_bid":"0.48","hash":"268cd37b9e0705c1aae3328508905f99405800e3","price":"0.43","side":"BUY","size":"115"},{"asset_id":"20893381255801015515826997628594359667013752732428989472914000440642900266717","best_ask":"0.52","best_bid":"0.51","hash":"e375f4615f0b7b09139ea7d6255d5ab2139247d6","price":"0.57","side":"SELL","size":"115"}],"timestamp":"1785203771239"},"payload_hash":"10a86e52d2a3de3dc693da79cd493f2072f287d3a6534efaa0aecf086921005c","raw_frame":"{\"market\":\"0xda6f0e0e93fc8469e0159a166028d017bddbc162b86f66bac90391379603d962\", \"price_changes\":[{\"asset_id\":\"39272994714739463168905443499424551362424437245880253267329605556587274644733\", \"price\":\"0.43\", \"size\":\"115\", \"side\":\"BUY\", \"hash\":\"268cd37b9e0705c1aae3328508905f99405800e3\", \"best_bid\":\"0.48\", \"best_ask\":\"0.49\"}, {\"asset_id\":\"20893381255801015515826997628594359667013752732428989472914000440642900266717\", \"price\":\"0.57\", \"size\":\"115\", \"side\":\"SELL\", \"hash\":\"e375f4615f0b7b09139ea7d6255d5ab2139247d6\", \"best_bid\":\"0.51\", \"best_ask\":\"0.52\"}], \"timestamp\":\"1785203771239\", \"event_type\":\"price_change\"}","received_at":"2026-07-28T01:56:11.140748Z","schema_version":"clob-market-ws.price_change.v1","sequence":null,"server_hash":null,"server_timestamp":"1785203771239","session_id":"d2757dd6dad94f3b9fe67e8dbf1adc37","source":"clob_market_ws"},"received_at":"2026-07-28T01:56:11.140748Z","record_id":"107d59a474e3ae479a2adf0541e88b63aa2e7a954adc2eb2449f8452b1ddd2d6","schema_fingerprint":"4aa3821a28b0b7c2400bc59aba4bcc0a76e971dadd19610d3ad38c768e124dc7","schema_version":"edge-lab-recorder.raw.v1","sequence":null,"source":"clob_market_ws"}
{"event_at":"2026-07-28T01:56:11.274000Z","event_fingerprint":"25f217293c3806450a2932f6e8e360e2d78cff7d78c9f0269ff16573bb5c5bc0","payload":{"connection_id":"5d29200f65794d4d9ab6ef271f045a9b","event_at":"2026-07-28T01:56:11.274000Z","event_type":"price_change","frame_hash":"04e8e7c6f951c51421f1bd49bd6574f43fb2c8696450cf4e6ae7628a7d74eb27","frame_index":0,"kind":"data","monotonic_ns":305754177837041,"payload":{"event_type":"price_change","market":"0xda6f0e0e93fc8469e0159a166028d017bddbc162b86f66bac90391379603d962","price_changes":[{"asset_id":"39272994714739463168905443499424551362424437245880253267329605556587274644733","best_ask":"0.49","best_bid":"0.48","hash":"83386f988986558a997ae76b7d999d34152ccf7b","price":"0.46","side":"BUY","size":"35"},{"asset_id":"20893381255801015515826997628594359667013752732428989472914000440642900266717","best_ask":"0.52","best_bid":"0.51","hash":"ba7c2210a9fa2f0688318995e6f6643bb285fb79","price":"0.54","side":"SELL","size":"35"}],"timestamp":"1785203771274"},"payload_hash":"51a284b6391e3d93a5beb6570130ef45f74dd51a247e0a996596741575d6e31d","raw_frame":"{\"market\":\"0xda6f0e0e93fc8469e0159a166028d017bddbc162b86f66bac90391379603d962\", \"price_changes\":[{\"asset_id\":\"39272994714739463168905443499424551362424437245880253267329605556587274644733\", \"price\":\"0.46\", \"size\":\"35\", \"side\":\"BUY\", \"hash\":\"83386f988986558a997ae76b7d999d34152ccf7b\", \"best_bid\":\"0.48\", \"best_ask\":\"0.49\"}, {\"asset_id\":\"20893381255801015515826997628594359667013752732428989472914000440642900266717\", \"price\":\"0.54\", \"size\":\"35\", \"side\":\"SELL\", \"hash\":\"ba7c2210a9fa2f0688318995e6f6643bb285fb79\", \"best_bid\":\"0.51\", \"best_ask\":\"0.52\"}], \"timestamp\":\"1785203771274\", \"event_type\":\"price_change\"}","received_at":"2026-07-28T01:56:11.169022Z","schema_version":"clob-market-ws.price_change.v1","sequence":null,"server_hash":null,"server_timestamp":"1785203771274","session_id":"d2757dd6dad94f3b9fe67e8dbf1adc37","source":"clob_market_ws"},"received_at":"2026-07-28T01:56:11.169022Z","record_id":"f2d4e17a50fa190d08ea44a39b3df1c14d66ccba965d23d11a54ba5aefed6e7a","schema_fingerprint":"4aa3821a28b0b7c2400bc59aba4bcc0a76e971dadd19610d3ad38c768e124dc7","schema_version":"edge-lab-recorder.raw.v1","sequence":null,"source":"clob_market_ws"}
{"event_at":"2026-07-28T01:56:11.276000Z","event_fingerprint":"4e1a029f38fb8133d2d35f0a9aa0ac99723854087010c4ea57267c14c59aa015","payload":{"connection_id":"5d29200f65794d4d9ab6ef271f045a9b","event_at":"2026-07-28T01:56:11.276000Z","event_type":"price_change","frame_hash":"35be18e3690b2a330873d962e83bfc0a8ec406f25907b8659a500442d98ef8bf","frame_index":0,"kind":"data","monotonic_ns":305754186043083,"payload":{"event_type":"price_change","market":"0xda6f0e0e93fc8469e0159a166028d017bddbc162b86f66bac90391379603d962","price_changes":[{"asset_id":"39272994714739463168905443499424551362424437245880253267329605556587274644733","best_ask":"0.49","best_bid":"0.48","hash":"c4c0ef118ce330d31236cc19c9e26b0acf5211a1","price":"0.46","side":"BUY","size":"40"},{"asset_id":"20893381255801015515826997628594359667013752732428989472914000440642900266717","best_ask":"0.52","best_bid":"0.51","hash":"a9a74448d666a3b8925bec44105562bd463b87d7","price":"0.54","side":"SELL","size":"40"}],"timestamp":"1785203771276"},"payload_hash":"aa3ec5b0224d9d03c7bd88a0b8fa24c97dd381d3ee31a6911d446577b4be19ab","raw_frame":"{\"market\":\"0xda6f0e0e93fc8469e0159a166028d017bddbc162b86f66bac90391379603d962\", \"price_changes\":[{\"asset_id\":\"39272994714739463168905443499424551362424437245880253267329605556587274644733\", \"price\":\"0.46\", \"size\":\"40\", \"side\":\"BUY\", \"hash\":\"c4c0ef118ce330d31236cc19c9e26b0acf5211a1\", \"best_bid\":\"0.48\", \"best_ask\":\"0.49\"}, {\"asset_id\":\"20893381255801015515826997628594359667013752732428989472914000440642900266717\", \"price\":\"0.54\", \"size\":\"40\", \"side\":\"SELL\", \"hash\":\"a9a74448d666a3b8925bec44105562bd463b87d7\", \"best_bid\":\"0.51\", \"best_ask\":\"0.52\"}], \"timestamp\":\"1785203771276\", \"event_type\":\"price_change\"}","received_at":"2026-07-28T01:56:11.177229Z","schema_version":"clob-market-ws.price_change.v1","sequence":null,"server_hash":null,"server_timestamp":"1785203771276","session_id":"d2757dd6dad94f3b9fe67e8dbf1adc37","source":"clob_market_ws"},"received_at":"2026-07-28T01:56:11.177229Z","record_id":"d75607d0e2860d20203206cd07b1a35c8b861c2de3f86be91b8c31f5c6d7a3a6","schema_fingerprint":"4aa3821a28b0b7c2400bc59aba4bcc0a76e971dadd19610d3ad38c768e124dc7","schema_version":"edge-lab-recorder.raw.v1","sequence":null,"source":"clob_market_ws"}
{"event_at":"2026-07-28T01:56:11.277000Z","event_fingerprint":"c2cafacc94af74340fd48bbd47e3c50870027aaa45fb3ebd90f4a132f024c6b5","payload":{"connection_id":"5d29200f65794d4d9ab6ef271f045a9b","event_at":"2026-07-28T01:56:11.277000Z","event_type":"price_change","frame_hash":"244467e134d1425942f029e343ac55ab7e7c3aabef58bf5a911d19f8b375237a","frame_index":0,"kind":"data","monotonic_ns":305754193794250,"payload":{"event_type":"price_change","market":"0xda6f0e0e93fc8469e0159a166028d017bddbc162b86f66bac90391379603d962","price_changes":[{"asset_id":"39272994714739463168905443499424551362424437245880253267329605556587274644733","best_ask":"0.49","best_bid":"0.48","hash":"5fd8dbea60cec3f0414ebad34deaafd5499fba04","price":"0.46","side":"BUY","size":"45"},{"asset_id":"20893381255801015515826997628594359667013752732428989472914000440642900266717","best_ask":"0.52","best_bid":"0.51","hash":"13c7194063a0bdcb578a555b5fa717349b24654a","price":"0.54","side":"SELL","size":"45"}],"timestamp":"1785203771277"},"payload_hash":"4805f6631a92b1fadafc4c146874b7898177109352c64367ae5eafe21f0a9675","raw_frame":"{\"market\":\"0xda6f0e0e93fc8469e0159a166028d017bddbc162b86f66bac90391379603d962\", \"price_changes\":[{\"asset_id\":\"39272994714739463168905443499424551362424437245880253267329605556587274644733\", \"price\":\"0.46\", \"size\":\"45\", \"side\":\"BUY\", \"hash\":\"5fd8dbea60cec3f0414ebad34deaafd5499fba04\", \"best_bid\":\"0.48\", \"best_ask\":\"0.49\"}, {\"asset_id\":\"20893381255801015515826997628594359667013752732428989472914000440642900266717\", \"price\":\"0.54\", \"size\":\"45\", \"side\":\"SELL\", \"hash\":\"13c7194063a0bdcb578a555b5fa717349b24654a\", \"best_bid\":\"0.51\", \"best_ask\":\"0.52\"}], \"timestamp\":\"1785203771277\", \"event_type\":\"price_change\"}","received_at":"2026-07-28T01:56:11.184978Z","schema_version":"clob-market-ws.price_change.v1","sequence":null,"server_hash":null,"server_timestamp":"1785203771277","session_id":"d2757dd6dad94f3b9fe67e8dbf1adc37","source":"clob_market_ws"},"received_at":"2026-07-28T01:56:11.184978Z","record_id":"a00e66a7c5a0c3eaf9a368f0379e41c776596f039ab927e72a0c11e293d1efd3","schema_fingerprint":"4aa3821a28b0b7c2400bc59aba4bcc0a76e971dadd19610d3ad38c768e124dc7","schema_version":"edge-lab-recorder.raw.v1","sequence":null,"source":"clob_market_ws"}
{"event_at":"2026-07-28T01:56:11.277000Z","event_fingerprint":"5e013fb8dfaa6065e8c3ee14e8a03867c469dc2a64b2661bb346884084ca58eb","payload":{"connection_id":"5d29200f65794d4d9ab6ef271f045a9b","event_at":"2026-07-28T01:56:11.277000Z","event_type":"price_change","frame_hash":"4229f4a6f5c4cf5981b1e6bd20f68dbd7fafc6a002b5286278b782964694decc","frame_index":0,"kind":"data","monotonic_ns":305754199562875,"payload":{"event_type":"price_change","market":"0xda6f0e0e93fc8469e0159a166028d017bddbc162b86f66bac90391379603d962","price_changes":[{"asset_id":"39272994714739463168905443499424551362424437245880253267329605556587274644733","best_ask":"0.49","best_bid":"0.48","hash":"81976c381000295e903b725d491f618d3295b6cc","price":"0.46","side":"BUY","size":"50"},{"asset_id":"20893381255801015515826997628594359667013752732428989472914000440642900266717","best_ask":"0.52","best_bid":"0.51","hash":"d0d5ff6421f9178ca88264927dff46cb0d2664ae","price":"0.54","side":"SELL","size":"50"}],"timestamp":"1785203771277"},"payload_hash":"610d3be04674a3dc3ce1e74dafd5d9ade7e472a653e6098d7f1f1dcc04df55e9","raw_frame":"{\"market\":\"0xda6f0e0e93fc8469e0159a166028d017bddbc162b86f66bac90391379603d962\", \"price_changes\":[{\"asset_id\":\"39272994714739463168905443499424551362424437245880253267329605556587274644733\", \"price\":\"0.46\", \"size\":\"50\", \"side\":\"BUY\", \"hash\":\"81976c381000295e903b725d491f618d3295b6cc\", \"best_bid\":\"0.48\", \"best_ask\":\"0.49\"}, {\"asset_id\":\"20893381255801015515826997628594359667013752732428989472914000440642900266717\", \"price\":\"0.54\", \"size\":\"50\", \"side\":\"SELL\", \"hash\":\"d0d5ff6421f9178ca88264927dff46cb0d2664ae\", \"best_bid\":\"0.51\", \"best_ask\":\"0.52\"}], \"timestamp\":\"1785203771277\", \"event_type\":\"price_change\"}","received_at":"2026-07-28T01:56:11.190747Z","schema_version":"clob-market-ws.price_change.v1","sequence":null,"server_hash":null,"server_timestamp":"1785203771277","session_id":"d2757dd6dad94f3b9fe67e8dbf1adc37","source":"clob_market_ws"},"received_at":"2026-07-28T01:56:11.190747Z","record_id":"ef292d08d7615eb11b41b4755b21328c21260f9edb7e7c3657a793955ad8cfd8","schema_fingerprint":"4aa3821a28b0b7c2400bc59aba4bcc0a76e971dadd19610d3ad38c768e124dc7","schema_version":"edge-lab-recorder.raw.v1","sequence":null,"source":"clob_market_ws"}
{"event_at":"2026-07-28T01:56:11.278000Z","event_fingerprint":"fd5d1676241eb331315926c62f408d1223ff5cf9c28eafb97bfcebce3a293e1b","payload":{"connection_id":"5d29200f65794d4d9ab6ef271f045a9b","event_at":"2026-07-28T01:56:11.278000Z","event_type":"price_change","frame_hash":"987f1255312d765ca88f0b57f176a682bae053c5ca76aeae0c79a074a4754904","frame_index":0,"kind":"data","monotonic_ns":305754204916333,"payload":{"event_type":"price_change","market":"0xda6f0e0e93fc8469e0159a166028d017bddbc162b86f66bac90391379603d962","price_changes":[{"asset_id":"39272994714739463168905443499424551362424437245880253267329605556587274644733","best_ask":"0.49","best_bid":"0.48","hash":"3015caee938db7647b5bf6bc01635f89c2ad2f77","price":"0.46","side":"BUY","size":"55"},{"asset_id":"20893381255801015515826997628594359667013752732428989472914000440642900266717","best_ask":"0.52","best_bid":"0.51","hash":"37a7a352b6243001c116dbb86a2471d2a4f586a4","price":"0.54","side":"SELL","size":"55"}],"timestamp":"1785203771278"},"payload_hash":"645e9e56288fd670a1ecee22e486e0bcdb34e4e4d4ad90e1b9777c386c853b26","raw_frame":"{\"market\":\"0xda6f0e0e93fc8469e0159a166028d017bddbc162b86f66bac90391379603d962\", \"price_changes\":[{\"asset_id\":\"39272994714739463168905443499424551362424437245880253267329605556587274644733\", \"price\":\"0.46\", \"size\":\"55\", \"side\":\"BUY\", \"hash\":\"3015caee938db7647b5bf6bc01635f89c2ad2f77\", \"best_bid\":\"0.48\", \"best_ask\":\"0.49\"}, {\"asset_id\":\"20893381255801015515826997628594359667013752732428989472914000440642900266717\", \"price\":\"0.54\", \"size\":\"55\", \"side\":\"SELL\", \"hash\":\"37a7a352b6243001c116dbb86a2471d2a4f586a4\", \"best_bid\":\"0.51\", \"best_ask\":\"0.52\"}], \"timestamp\":\"1785203771278\", \"event_type\":\"price_change\"}","received_at":"2026-07-28T01:56:11.196099Z","schema_version":"clob-market-ws.price_change.v1","sequence":null,"server_hash":null,"server_timestamp":"1785203771278","session_id":"d2757dd6dad94f3b9fe67e8dbf1adc37","source":"clob_market_ws"},"received_at":"2026-07-28T01:56:11.196099Z","record_id":"7cfe26b35613c305d0111892df9b78ed1fb76af7fed4901cce34ad92b2c54758","schema_fingerprint":"4aa3821a28b0b7c2400bc59aba4bcc0a76e971dadd19610d3ad38c768e124dc7","schema_version":"edge-lab-recorder.raw.v1","sequence":null,"source":"clob_market_ws"}
{"event_at":"2026-07-28T01:56:11.283000Z","event_fingerprint":"d489f3c5a9f0556df3b5468816da0a54e4701902b87e282bc7d59f5d4047f398","payload":{"connection_id":"5d29200f65794d4d9ab6ef271f045a9b","event_at":"2026-07-28T01:56:11.283000Z","event_type":"price_change","frame_hash":"9044d21f5686ca148ecc9f7c2f51203aa23dbce120f90f51a0236a47d018308f","frame_index":0,"kind":"data","monotonic_ns":305754213702250,"payload":{"event_type":"price_change","market":"0xda6f0e0e93fc8469e0159a166028d017bddbc162b86f66bac90391379603d962","price_changes":[{"asset_id":"39272994714739463168905443499424551362424437245880253267329605556587274644733","best_ask":"0.49","best_bid":"0.48","hash":"e6a19c6c15fbb2ff3637155058cfe90bd9fbb332","price":"0.46","side":"BUY","size":"60"},{"asset_id":"20893381255801015515826997628594359667013752732428989472914000440642900266717","best_ask":"0.52","best_bid":"0.51","hash":"01a31d446c60dad5dc3b8af9e4c784f06b8d9344","price":"0.54","side":"SELL","size":"60"}],"timestamp":"1785203771283"},"payload_hash":"5a089084d6cd1268a8a4599c575aaec9d5615855b98555b9d070374862875819","raw_frame":"{\"market\":\"0xda6f0e0e93fc8469e0159a166028d017bddbc162b86f66bac90391379603d962\", \"price_changes\":[{\"asset_id\":\"39272994714739463168905443499424551362424437245880253267329605556587274644733\", \"price\":\"0.46\", \"size\":\"60\", \"side\":\"BUY\", \"hash\":\"e6a19c6c15fbb2ff3637155058cfe90bd9fbb332\", \"best_bid\":\"0.48\", \"best_ask\":\"0.49\"}, {\"asset_id\":\"20893381255801015515826997628594359667013752732428989472914000440642900266717\", \"price\":\"0.54\", \"size\":\"60\", \"side\":\"SELL\", \"hash\":\"01a31d446c60dad5dc3b8af9e4c784f06b8d9344\", \"best_bid\":\"0.51\", \"best_ask\":\"0.52\"}], \"timestamp\":\"1785203771283\", \"event_type\":\"price_change\"}","received_at":"2026-07-28T01:56:11.204887Z","schema_version":"clob-market-ws.price_change.v1","sequence":null,"server_hash":null,"server_timestamp":"1785203771283","session_id":"d2757dd6dad94f3b9fe67e8dbf1adc37","source":"clob_market_ws"},"received_at":"2026-07-28T01:56:11.204887Z","record_id":"11e2c5d0fb145b0164868a67728fec241a1f71091353d22e5fd26a62849c8480","schema_fingerprint":"4aa3821a28b0b7c2400bc59aba4bcc0a76e971dadd19610d3ad38c768e124dc7","schema_version":"edge-lab-recorder.raw.v1","sequence":null,"source":"clob_market_ws"}
{"event_at":"2026-07-28T01:56:11.284000Z","event_fingerprint":"80ee1bb7e98a4b8d6c1a5070134b8b3fc84b9d612cce2a845b8f9c647bd16b12","payload":{"connection_id":"5d29200f65794d4d9ab6ef271f045a9b","event_at":"2026-07-28T01:56:11.284000Z","event_type":"price_change","frame_hash":"5f42f7b322316ec5f7530ef589a785214e1e1e508e81d2f1608b7e4798a61884","frame_index":0,"kind":"data","monotonic_ns":305754218917166,"payload":{"event_type":"price_change","market":"0xda6f0e0e93fc8469e0159a166028d017bddbc162b86f66bac90391379603d962","price_changes":[{"asset_id":"39272994714739463168905443499424551362424437245880253267329605556587274644733","best_ask":"0.49","best_bid":"0.48","hash":"f5a1762b370be91d2b563f84be2c4432561c3fd0","price":"0.46","side":"BUY","size":"65"},{"asset_id":"20893381255801015515826997628594359667013752732428989472914000440642900266717","best_ask":"0.52","best_bid":"0.51","hash":"c85197f3e8453dd3b811de76dc2a1288df80cdb9","price":"0.54","side":"SELL","size":"65"}],"timestamp":"1785203771284"},"payload_hash":"c0d5259de056c2be934dbc14ce31c2a749796596b1a7115448fd492c9a3b80e7","raw_frame":"{\"market\":\"0xda6f0e0e93fc8469e0159a166028d017bddbc162b86f66bac90391379603d962\", \"price_changes\":[{\"asset_id\":\"39272994714739463168905443499424551362424437245880253267329605556587274644733\", \"price\":\"0.46\", \"size\":\"65\", \"side\":\"BUY\", \"hash\":\"f5a1762b370be91d2b563f84be2c4432561c3fd0\", \"best_bid\":\"0.48\", \"best_ask\":\"0.49\"}, {\"asset_id\":\"20893381255801015515826997628594359667013752732428989472914000440642900266717\", \"price\":\"0.54\", \"size\":\"65\", \"side\":\"SELL\", \"hash\":\"c85197f3e8453dd3b811de76dc2a1288df80cdb9\", \"best_bid\":\"0.51\", \"best_ask\":\"0.52\"}], \"timestamp\":\"1785203771284\", \"event_type\":\"price_change\"}","received_at":"2026-07-28T01:56:11.210102Z","schema_version":"clob-market-ws.price_change.v1","sequence":null,"server_hash":null,"server_timestamp":"1785203771284","session_id":"d2757dd6dad94f3b9fe67e8dbf1adc37","source":"clob_market_ws"},"received_at":"2026-07-28T01:56:11.210102Z","record_id":"7e2a087ba56eb739d3f8fefb27be26e545bd46942fd617ae086a29bfd2e9295d","schema_fingerprint":"4aa3821a28b0b7c2400bc59aba4bcc0a76e971dadd19610d3ad38c768e124dc7","schema_version":"edge-lab-recorder.raw.v1","sequence":null,"source":"clob_market_ws"}
{"event_at":"2026-07-28T01:56:11.285000Z","event_fingerprint":"c2df33cb00cd048f919687a29382a800549261b32a0c8adcbf02d3224f7fa917","payload":{"connection_id":"5d29200f65794d4d9ab6ef271f045a9b","event_at":"2026-07-28T01:56:11.285000Z","event_type":"price_change","frame_hash":"96c7996d96c02109fff22e0e7e71c98496ff05a6012251b038e6d753d46f444a","frame_index":0,"kind":"data","monotonic_ns":305754226132041,"payload":{"event_type":"price_change","market":"0xda6f0e0e93fc8469e0159a166028d017bddbc162b86f66bac90391379603d962","price_changes":[{"asset_id":"39272994714739463168905443499424551362424437245880253267329605556587274644733","best_ask":"0.49","best_bid":"0.48","hash":"db6c32de5f3b510a6f9bb88e7d5e45ccca6f21f2","price":"0.46","side":"BUY","size":"70"},{"asset_id":"20893381255801015515826997628594359667013752732428989472914000440642900266717","best_ask":"0.52","best_bid":"0.51","hash":"17dbe3ef3a165c7e81cc0af850def0c2cd17c40d","price":"0.54","side":"SELL","size":"70"}],"timestamp":"1785203771285"},"payload_hash":"258f4001ace6bf026fcf6b6cfbaa44a2ea8cf978edacf7f2bbbcd6aca12619a5","raw_frame":"{\"market\":\"0xda6f0e0e93fc8469e0159a166028d017bddbc162b86f66bac90391379603d962\", \"price_changes\":[{\"asset_id\":\"39272994714739463168905443499424551362424437245880253267329605556587274644733\", \"price\":\"0.46\", \"size\":\"70\", \"side\":\"BUY\", \"hash\":\"db6c32de5f3b510a6f9bb88e7d5e45ccca6f21f2\", \"best_bid\":\"0.48\", \"best_ask\":\"0.49\"}, {\"asset_id\":\"20893381255801015515826997628594359667013752732428989472914000440642900266717\", \"price\":\"0.54\", \"size\":\"70\", \"side\":\"SELL\", \"hash\":\"17dbe3ef3a165c7e81cc0af850def0c2cd17c40d\", \"best_bid\":\"0.51\", \"best_ask\":\"0.52\"}], \"timestamp\":\"1785203771285\", \"event_type\":\"price_change\"}","received_at":"2026-07-28T01:56:11.217317Z","schema_version":"clob-market-ws.price_change.v1","sequence":null,"server_hash":null,"server_timestamp":"1785203771285","session_id":"d2757dd6dad94f3b9fe67e8dbf1adc37","source":"clob_market_ws"},"received_at":"2026-07-28T01:56:11.217317Z","record_id":"cab23c9e4d3ec4275a0e26ddc5adabb6af7ab08323dc06851b46e2f05ddfdad7","schema_fingerprint":"4aa3821a28b0b7c2400bc59aba4bcc0a76e971dadd19610d3ad38c768e124dc7","schema_version":"edge-lab-recorder.raw.v1","sequence":null,"source":"clob_market_ws"}
{"event_at":"2026-07-28T01:56:11.286000Z","event_fingerprint":"80dccba2ef63ba2ab569f79d1301208d23ea2220bf2715fd87e8b7536f038ad6","payload":{"connection_id":"5d29200f65794d4d9ab6ef271f045a9b","event_at":"2026-07-28T01:56:11.286000Z","event_type":"price_change","frame_hash":"19629ee4c634e7bb1542a951a5549cb364efeff3621c052dd73b33ba5d05306d","frame_index":0,"kind":"data","monotonic_ns":305754335139291,"payload":{"event_type":"price_change","market":"0xda6f0e0e93fc8469e0159a166028d017bddbc162b86f66bac90391379603d962","price_changes":[{"asset_id":"39272994714739463168905443499424551362424437245880253267329605556587274644733","best_ask":"0.49","best_bid":"0.48","hash":"d6d2cc48da39905d228b47aefb832a29620099ac","price":"0.46","side":"BUY","size":"75"},{"asset_id":"20893381255801015515826997628594359667013752732428989472914000440642900266717","best_ask":"0.52","best_bid":"0.51","hash":"829f0cfd1fb0139fe0be57fbcb85dd7195e28804","price":"0.54","side":"SELL","size":"75"}],"timestamp":"1785203771286"},"payload_hash":"3af90beba540ad4e6ba981079caf1a292befeb9f0e9ec716c48115f95be59f7c","raw_frame":"{\"market\":\"0xda6f0e0e93fc8469e0159a166028d017bddbc162b86f66bac90391379603d962\", \"price_changes\":[{\"asset_id\":\"39272994714739463168905443499424551362424437245880253267329605556587274644733\", \"price\":\"0.46\", \"size\":\"75\", \"side\":\"BUY\", \"hash\":\"d6d2cc48da39905d228b47aefb832a29620099ac\", \"best_bid\":\"0.48\", \"best_ask\":\"0.49\"}, {\"asset_id\":\"20893381255801015515826997628594359667013752732428989472914000440642900266717\", \"price\":\"0.54\", \"size\":\"75\", \"side\":\"SELL\", \"hash\":\"829f0cfd1fb0139fe0be57fbcb85dd7195e28804\", \"best_bid\":\"0.51\", \"best_ask\":\"0.52\"}], \"timestamp\":\"1785203771286\", \"event_type\":\"price_change\"}","received_at":"2026-07-28T01:56:11.326322Z","schema_version":"clob-market-ws.price_change.v1","sequence":null,"server_hash":null,"server_timestamp":"1785203771286","session_id":"d2757dd6dad94f3b9fe67e8dbf1adc37","source":"clob_market_ws"},"received_at":"2026-07-28T01:56:11.326322Z","record_id":"b6dc63bac72ec518356b79dc2b01939e15b039b6f2ce0197478299680e578dc0","schema_fingerprint":"4aa3821a28b0b7c2400bc59aba4bcc0a76e971dadd19610d3ad38c768e124dc7","schema_version":"edge-lab-recorder.raw.v1","sequence":null,"source":"clob_market_ws"}
{"event_at":"2026-07-28T01:56:11.288000Z","event_fingerprint":"5cf3e02fe864054afac1037b0eb54ef6c595fe33879e07f15b14fa673fa80524","payload":{"connection_id":"5d29200f65794d4d9ab6ef271f045a9b","event_at":"2026-07-28T01:56:11.288000Z","event_type":"price_change","frame_hash":"89d32c9a3cbac61b20f1b903a59cdde7ff26fe679dfee7ceb4846bdf292f6af5","frame_index":0,"kind":"data","monotonic_ns":305754341867666,"payload":{"event_type":"price_change","market":"0xda6f0e0e93fc8469e0159a166028d017bddbc162b86f66bac90391379603d962","price_changes":[{"asset_id":"39272994714739463168905443499424551362424437245880253267329605556587274644733","best_ask":"0.49","best_bid":"0.48","hash":"7594ec383ca0be9bb7815e24e9d8d0f601f46109","price":"0.46","side":"BUY","size":"80"},{"asset_id":"20893381255801015515826997628594359667013752732428989472914000440642900266717","best_ask":"0.52","best_bid":"0.51","hash":"6658bba58a21aa0a93fa870bab0815a6fee036a7","price":"0.54","side":"SELL","size":"80"}],"timestamp":"1785203771288"},"payload_hash":"8d86df784b02557ccf020e7495cf1ac934a7cd910df828e23fa4a2a24ce0355c","raw_frame":"{\"market\":\"0xda6f0e0e93fc8469e0159a166028d017bddbc162b86f66bac90391379603d962\", \"price_changes\":[{\"asset_id\":\"39272994714739463168905443499424551362424437245880253267329605556587274644733\", \"price\":\"0.46\", \"size\":\"80\", \"side\":\"BUY\", \"hash\":\"7594ec383ca0be9bb7815e24e9d8d0f601f46109\", \"best_bid\":\"0.48\", \"best_ask\":\"0.49\"}, {\"asset_id\":\"20893381255801015515826997628594359667013752732428989472914000440642900266717\", \"price\":\"0.54\", \"size\":\"80\", \"side\":\"SELL\", \"hash\":\"6658bba58a21aa0a93fa870bab0815a6fee036a7\", \"best_bid\":\"0.51\", \"best_ask\":\"0.52\"}], \"timestamp\":\"1785203771288\", \"event_type\":\"price_change\"}","received_at":"2026-07-28T01:56:11.333050Z","schema_version":"clob-market-ws.price_change.v1","sequence":null,"server_hash":null,"server_timestamp":"1785203771288","session_id":"d2757dd6dad94f3b9fe67e8dbf1adc37","source":"clob_market_ws"},"received_at":"2026-07-28T01:56:11.333050Z","record_id":"6fe0def4cd8f971140dbb1522ded26f56b69ab028fab4546625c8f80e66bd0bc","schema_fingerprint":"4aa3821a28b0b7c2400bc59aba4bcc0a76e971dadd19610d3ad38c768e124dc7","schema_version":"edge-lab-recorder.raw.v1","sequence":null,"source":"clob_market_ws"}
{"event_at":"2026-07-28T01:56:11.297000Z","event_fingerprint":"e7e5b27635e2f7869c9eb1356f79ee7cb376d14783606e6a49d539de0c355906","payload":{"connection_id":"5d29200f65794d4d9ab6ef271f045a9b","event_at":"2026-07-28T01:56:11.297000Z","event_type":"price_change","frame_hash":"034fc4074d84a44020266c1cd6e6b6692eb288ecb92293abe4d9599c15c31488","frame_index":0,"kind":"data","monotonic_ns":305754364640208,"payload":{"event_type":"price_change","market":"0xda6f0e0e93fc8469e0159a166028d017bddbc162b86f66bac90391379603d962","price_changes":[{"asset_id":"39272994714739463168905443499424551362424437245880253267329605556587274644733","best_ask":"0.49","best_bid":"0.48","hash":"a25d8a70d22332f24935e50fa71e2ccfda6c4aef","price":"0.46","side":"BUY","size":"85"},{"asset_id":"20893381255801015515826997628594359667013752732428989472914000440642900266717","best_ask":"0.52","best_bid":"0.51","hash":"49ae714f9fbb736cf9b363c236caba0ec15f4fa9","price":"0.54","side":"SELL","size":"85"}],"timestamp":"1785203771297"},"payload_hash":"763e4a9a10cd07a2fc9b6276915480da9d5cd369adb55a621fd90ba035f017b1","raw_frame":"{\"market\":\"0xda6f0e0e93fc8469e0159a166028d017bddbc162b86f66bac90391379603d962\", \"price_changes\":[{\"asset_id\":\"39272994714739463168905443499424551362424437245880253267329605556587274644733\", \"price\":\"0.46\", \"size\":\"85\", \"side\":\"BUY\", \"hash\":\"a25d8a70d22332f24935e50fa71e2ccfda6c4aef\", \"best_bid\":\"0.48\", \"best_ask\":\"0.49\"}, {\"asset_id\":\"20893381255801015515826997628594359667013752732428989472914000440642900266717\", \"price\":\"0.54\", \"size\":\"85\", \"side\":\"SELL\", \"hash\":\"49ae714f9fbb736cf9b363c236caba0ec15f4fa9\", \"best_bid\":\"0.51\", \"best_ask\":\"0.52\"}], \"timestamp\":\"1785203771297\", \"event_type\":\"price_change\"}","received_at":"2026-07-28T01:56:11.355823Z","schema_version":"clob-market-ws.price_change.v1","sequence":null,"server_hash":null,"server_timestamp":"1785203771297","session_id":"d2757dd6dad94f3b9fe67e8dbf1adc37","source":"clob_market_ws"},"received_at":"2026-07-28T01:56:11.355823Z","record_id":"edf40fc66afb9f62d5efc70b2c1201e6f8b56e3f3f84d9b5c69742dd61ed6bd9","schema_fingerprint":"4aa3821a28b0b7c2400bc59aba4bcc0a76e971dadd19610d3ad38c768e124dc7","schema_version":"edge-lab-recorder.raw.v1","sequence":null,"source":"clob_market_ws"}
{"event_at":"2026-07-28T01:56:11.298000Z","event_fingerprint":"6bfec4ba8663a9e7a47570a185bb865705021ea11d8f69b91b63569784a4f579","payload":{"connection_id":"5d29200f65794d4d9ab6ef271f045a9b","event_at":"2026-07-28T01:56:11.298000Z","event_type":"price_change","frame_hash":"7125ff8ea055e758ebfa0f31c4f8c0b3b8101d545fe3207304a7d73e210fa3ea","frame_index":0,"kind":"data","monotonic_ns":305754370598833,"payload":{"event_type":"price_change","market":"0xda6f0e0e93fc8469e0159a166028d017bddbc162b86f66bac90391379603d962","price_changes":[{"asset_id":"39272994714739463168905443499424551362424437245880253267329605556587274644733","best_ask":"0.49","best_bid":"0.48","hash":"049c73c2ddbfab84fe6bf519e0ea508f3f3935da","price":"0.46","side":"BUY","size":"90"},{"asset_id":"20893381255801015515826997628594359667013752732428989472914000440642900266717","best_ask":"0.52","best_bid":"0.51","hash":"e30f1d57657118f05a7cd8605dc4ae948c8b24f1","price":"0.54","side":"SELL","size":"90"}],"timestamp":"1785203771298"},"payload_hash":"729522a596755401648fb9f4bacd65e7d146428c28d0d3529bf306b1b065311b","raw_frame":"{\"market\":\"0xda6f0e0e93fc8469e0159a166028d017bddbc162b86f66bac90391379603d962\", \"price_changes\":[{\"asset_id\":\"39272994714739463168905443499424551362424437245880253267329605556587274644733\", \"price\":\"0.46\", \"size\":\"90\", \"side\":\"BUY\", \"hash\":\"049c73c2ddbfab84fe6bf519e0ea508f3f3935da\", \"best_bid\":\"0.48\", \"best_ask\":\"0.49\"}, {\"asset_id\":\"20893381255801015515826997628594359667013752732428989472914000440642900266717\", \"price\":\"0.54\", \"size\":\"90\", \"side\":\"SELL\", \"hash\":\"e30f1d57657118f05a7cd8605dc4ae948c8b24f1\", \"best_bid\":\"0.51\", \"best_ask\":\"0.52\"}], \"timestamp\":\"1785203771298\", \"event_type\":\"price_change\"}","received_at":"2026-07-28T01:56:11.361782Z","schema_version":"clob-market-ws.price_change.v1","sequence":null,"server_hash":null,"server_timestamp":"1785203771298","session_id":"d2757dd6dad94f3b9fe67e8dbf1adc37","source":"clob_market_ws"},"received_at":"2026-07-28T01:56:11.361782Z","record_id":"df035a7ddd10a97ed0e0bbec62c3573b89281d1fde4b4b257b10aef4caef4bda","schema_fingerprint":"4aa3821a28b0b7c2400bc59aba4bcc0a76e971dadd19610d3ad38c768e124dc7","schema_version":"edge-lab-recorder.raw.v1","sequence":null,"source":"clob_market_ws"}
{"event_at":"2026-07-28T01:56:11.299000Z","event_fingerprint":"1cfb68d988af378e625b7b700e0f8268b9612461895d8daae91c80fe12f53adc","payload":{"connection_id":"5d29200f65794d4d9ab6ef271f045a9b","event_at":"2026-07-28T01:56:11.299000Z","event_type":"price_change","frame_hash":"88661ab366d3b9e7c3ae49ecf5634fab341f2918ff721c6bff4f162c5ef7f8ae","frame_index":0,"kind":"data","monotonic_ns":305754376723458,"payload":{"event_type":"price_change","market":"0xda6f0e0e93fc8469e0159a166028d017bddbc162b86f66bac90391379603d962","price_changes":[{"asset_id":"39272994714739463168905443499424551362424437245880253267329605556587274644733","best_ask":"0.49","best_bid":"0.48","hash":"b13ac0a44abbbdbe787b4e7d9b6b3c79a26c1119","price":"0.46","side":"BUY","size":"95"},{"asset_id":"20893381255801015515826997628594359667013752732428989472914000440642900266717","best_ask":"0.52","best_bid":"0.51","hash":"605e268168cd0867071dd9273566f0240aa212c4","price":"0.54","side":"SELL","size":"95"}],"timestamp":"1785203771299"},"payload_hash":"44ef72165faf7bb0d83489ec254721d9d9051242a31f1206e1f45654a2984292","raw_frame":"{\"market\":\"0xda6f0e0e93fc8469e0159a166028d017bddbc162b86f66bac90391379603d962\", \"price_changes\":[{\"asset_id\":\"39272994714739463168905443499424551362424437245880253267329605556587274644733\", \"price\":\"0.46\", \"size\":\"95\", \"side\":\"BUY\", \"hash\":\"b13ac0a44abbbdbe787b4e7d9b6b3c79a26c1119\", \"best_bid\":\"0.48\", \"best_ask\":\"0.49\"}, {\"asset_id\":\"20893381255801015515826997628594359667013752732428989472914000440642900266717\", \"price\":\"0.54\", \"size\":\"95\", \"side\":\"SELL\", \"hash\":\"605e268168cd0867071dd9273566f0240aa212c4\", \"best_bid\":\"0.51\", \"best_ask\":\"0.52\"}], \"timestamp\":\"1785203771299\", \"event_type\":\"price_change\"}","received_at":"2026-07-28T01:56:11.367906Z","schema_version":"clob-market-ws.price_change.v1","sequence":null,"server_hash":null,"server_timestamp":"1785203771299","session_id":"d2757dd6dad94f3b9fe67e8dbf1adc37","source":"clob_market_ws"},"received_at":"2026-07-28T01:56:11.367906Z","record_id":"a356656f76f1f63f19bcb4a31fe7739b450667f40dc68def3ec914bf57af77b9","schema_fingerprint":"4aa3821a28b0b7c2400bc59aba4bcc0a76e971dadd19610d3ad38c768e124dc7","schema_version":"edge-lab-recorder.raw.v1","sequence":null,"source":"clob_market_ws"}
{"event_at":"2026-07-28T01:56:11.300000Z","event_fingerprint":"dfaad3af88da112ae850a31f83113b9c6509d40e810de6bcf73cdbf3e49b4628","payload":{"connection_id":"5d29200f65794d4d9ab6ef271f045a9b","event_at":"2026-07-28T01:56:11.300000Z","event_type":"price_change","frame_hash":"747ba83842f5e7b38210ecad38770c0e132edc47828eaedee5ed3a03a8a3371a","frame_index":0,"kind":"data","monotonic_ns":305754381682625,"payload":{"event_type":"price_change","market":"0xda6f0e0e93fc8469e0159a166028d017bddbc162b86f66bac90391379603d962","price_changes":[{"asset_id":"39272994714739463168905443499424551362424437245880253267329605556587274644733","best_ask":"0.49","best_bid":"0.48","hash":"ed6e284d91d7ac6ca45d209223b56ae810ce3241","price":"0.46","side":"BUY","size":"100"},{"asset_id":"20893381255801015515826997628594359667013752732428989472914000440642900266717","best_ask":"0.52","best_bid":"0.51","hash":"f09c998bcf3f263549216f1463d8ab581534432b","price":"0.54","side":"SELL","size":"100"}],"timestamp":"1785203771300"},"payload_hash":"fb515aacff478b796803b18dc7fa5fbb533bc3e8e9ba5d2bb2c1fa793e1c0a22","raw_frame":"{\"market\":\"0xda6f0e0e93fc8469e0159a166028d017bddbc162b86f66bac90391379603d962\", \"price_changes\":[{\"asset_id\":\"39272994714739463168905443499424551362424437245880253267329605556587274644733\", \"price\":\"0.46\", \"size\":\"100\", \"side\":\"BUY\", \"hash\":\"ed6e284d91d7ac6ca45d209223b56ae810ce3241\", \"best_bid\":\"0.48\", \"best_ask\":\"0.49\"}, {\"asset_id\":\"20893381255801015515826997628594359667013752732428989472914000440642900266717\", \"price\":\"0.54\", \"size\":\"100\", \"side\":\"SELL\", \"hash\":\"f09c998bcf3f263549216f1463d8ab581534432b\", \"best_bid\":\"0.51\", \"best_ask\":\"0.52\"}], \"timestamp\":\"1785203771300\", \"event_type\":\"price_change\"}","received_at":"2026-07-28T01:56:11.372865Z","schema_version":"clob-market-ws.price_change.v1","sequence":null,"server_hash":null,"server_timestamp":"1785203771300","session_id":"d2757dd6dad94f3b9fe67e8dbf1adc37","source":"clob_market_ws"},"received_at":"2026-07-28T01:56:11.372865Z","record_id":"9f27807bd08b2add7be40812dbfa599746ba3ef18c48eadeab3f882c02d9a22c","schema_fingerprint":"4aa3821a28b0b7c2400bc59aba4bcc0a76e971dadd19610d3ad38c768e124dc7","schema_version":"edge-lab-recorder.raw.v1","sequence":null,"source":"clob_market_ws"}
{"event_at":"2026-07-28T01:56:11.301000Z","event_fingerprint":"50b7d3221bc31fb9cab8a8bcca5837f0eb6da6357e19cc715a9d3de69904c46e","payload":{"connection_id":"5d29200f65794d4d9ab6ef271f045a9b","event_at":"2026-07-28T01:56:11.301000Z","event_type":"price_change","frame_hash":"05d723108abfd13dd004f1a6aff46b0079ae9d82d1e13eb760b61f8550860186","frame_index":0,"kind":"data","monotonic_ns":305754388873375,"payload":{"event_type":"price_change","market":"0xda6f0e0e93fc8469e0159a166028d017bddbc162b86f66bac90391379603d962","price_changes":[{"asset_id":"39272994714739463168905443499424551362424437245880253267329605556587274644733","best_ask":"0.49","best_bid":"0.48","hash":"a815fa0e69805e6e961cc990b4eea1b72d4ea1de","price":"0.46","side":"BUY","size":"105"},{"asset_id":"20893381255801015515826997628594359667013752732428989472914000440642900266717","best_ask":"0.52","best_bid":"0.51","hash":"15b05784b34ff340769bbb6a9896b38b32a29ea4","price":"0.54","side":"SELL","size":"105"}],"timestamp":"1785203771301"},"payload_hash":"297e9ba68b0fdb50e8827a7ddd865f730c00e3944663a16232d93e05b94aa2c3","raw_frame":"{\"market\":\"0xda6f0e0e93fc8469e0159a166028d017bddbc162b86f66bac90391379603d962\", \"price_changes\":[{\"asset_id\":\"39272994714739463168905443499424551362424437245880253267329605556587274644733\", \"price\":\"0.46\", \"size\":\"105\", \"side\":\"BUY\", \"hash\":\"a815fa0e69805e6e961cc990b4eea1b72d4ea1de\", \"best_bid\":\"0.48\", \"best_ask\":\"0.49\"}, {\"asset_id\":\"20893381255801015515826997628594359667013752732428989472914000440642900266717\", \"price\":\"0.54\", \"size\":\"105\", \"side\":\"SELL\", \"hash\":\"15b05784b34ff340769bbb6a9896b38b32a29ea4\", \"best_bid\":\"0.51\", \"best_ask\":\"0.52\"}], \"timestamp\":\"1785203771301\", \"event_type\":\"price_change\"}","received_at":"2026-07-28T01:56:11.380056Z","schema_version":"clob-market-ws.price_change.v1","sequence":null,"server_hash":null,"server_timestamp":"1785203771301","session_id":"d2757dd6dad94f3b9fe67e8dbf1adc37","source":"clob_market_ws"},"received_at":"2026-07-28T01:56:11.380056Z","record_id":"90f9d651d4b8b2d4154a79aa4fce83601b0b06a7192155dd58535a28fc0219e0","schema_fingerprint":"4aa3821a28b0b7c2400bc59aba4bcc0a76e971dadd19610d3ad38c768e124dc7","schema_version":"edge-lab-recorder.raw.v1","sequence":null,"source":"clob_market_ws"}
{"event_at":"2026-07-28T01:56:11.302000Z","event_fingerprint":"c4a860fda48f0d6a7d8067a308c0c954e170503997ef8e2b31533b79b6095d38","payload":{"connection_id":"5d29200f65794d4d9ab6ef271f045a9b","event_at":"2026-07-28T01:56:11.302000Z","event_type":"price_change","frame_hash":"2023ab178d1632a50dde6b516a5c34f15ada826ffd382ac12b269b41b3208711","frame_index":0,"kind":"data","monotonic_ns":305754393814500,"payload":{"event_type":"price_change","market":"0xda6f0e0e93fc8469e0159a166028d017bddbc162b86f66bac90391379603d962","price_changes":[{"asset_id":"39272994714739463168905443499424551362424437245880253267329605556587274644733","best_ask":"0.49","best_bid":"0.48","hash":"c09f8e35a44953782ad1f04ca6eba59988b06dbc","price":"0.46","side":"BUY","size":"110"},{"asset_id":"20893381255801015515826997628594359667013752732428989472914000440642900266717","best_ask":"0.52","best_bid":"0.51","hash":"6a53c32cc8676adf77387c0d57882ad8fa567281","price":"0.54","side":"SELL","size":"110"}],"timestamp":"1785203771302"},"payload_hash":"9e738aa7953e369b2b1414f1be86396b981866e47df993322856482d36cf16f0","raw_frame":"{\"market\":\"0xda6f0e0e93fc8469e0159a166028d017bddbc162b86f66bac90391379603d962\", \"price_changes\":[{\"asset_id\":\"39272994714739463168905443499424551362424437245880253267329605556587274644733\", \"price\":\"0.46\", \"size\":\"110\", \"side\":\"BUY\", \"hash\":\"c09f8e35a44953782ad1f04ca6eba59988b06dbc\", \"best_bid\":\"0.48\", \"best_ask\":\"0.49\"}, {\"asset_id\":\"20893381255801015515826997628594359667013752732428989472914000440642900266717\", \"price\":\"0.54\", \"size\":\"110\", \"side\":\"SELL\", \"hash\":\"6a53c32cc8676adf77387c0d57882ad8fa567281\", \"best_bid\":\"0.51\", \"best_ask\":\"0.52\"}], \"timestamp\":\"1785203771302\", \"event_type\":\"price_change\"}","received_at":"2026-07-28T01:56:11.384997Z","schema_version":"clob-market-ws.price_change.v1","sequence":null,"server_hash":null,"server_timestamp":"1785203771302","session_id":"d2757dd6dad94f3b9fe67e8dbf1adc37","source":"clob_market_ws"},"received_at":"2026-07-28T01:56:11.384997Z","record_id":"b79f45292bfe9b7c4a0538684539c7f9066ace2462e36cecc4eb83ab6dffc798","schema_fingerprint":"4aa3821a28b0b7c2400bc59aba4bcc0a76e971dadd19610d3ad38c768e124dc7","schema_version":"edge-lab-recorder.raw.v1","sequence":null,"source":"clob_market_ws"}
{"event_at":"2026-07-28T01:56:11.304000Z","event_fingerprint":"c9391b37453f275e272748d9b30bd712c28768548ce4e1429ffb4f977e0abe82","payload":{"connection_id":"5d29200f65794d4d9ab6ef271f045a9b","event_at":"2026-07-28T01:56:11.304000Z","event_type":"price_change","frame_hash":"3c4cb2759b72e0993b6e95d40b67d7ca8b86efc60ba3c20ad73dfc48d10af2a1","frame_index":0,"kind":"data","monotonic_ns":305754399683708,"payload":{"event_type":"price_change","market":"0xda6f0e0e93fc8469e0159a166028d017bddbc162b86f66bac90391379603d962","price_changes":[{"asset_id":"39272994714739463168905443499424551362424437245880253267329605556587274644733","best_ask":"0.49","best_bid":"0.48","hash":"5de103e6a1330c64f88d6cb69c8093c8e277f852","price":"0.46","side":"BUY","size":"115"},{"asset_id":"20893381255801015515826997628594359667013752732428989472914000440642900266717","best_ask":"0.52","best_bid":"0.51","hash":"31f4e013269b9dfb81122b1e7d3179c7b071a787","price":"0.54","side":"SELL","size":"115"}],"timestamp":"1785203771304"},"payload_hash":"b9cb048fea990f09573600118690bac517d452116c07b88b97d75e36b6ae0451","raw_frame":"{\"market\":\"0xda6f0e0e93fc8469e0159a166028d017bddbc162b86f66bac90391379603d962\", \"price_changes\":[{\"asset_id\":\"39272994714739463168905443499424551362424437245880253267329605556587274644733\", \"price\":\"0.46\", \"size\":\"115\", \"side\":\"BUY\", \"hash\":\"5de103e6a1330c64f88d6cb69c8093c8e277f852\", \"best_bid\":\"0.48\", \"best_ask\":\"0.49\"}, {\"asset_id\":\"20893381255801015515826997628594359667013752732428989472914000440642900266717\", \"price\":\"0.54\", \"size\":\"115\", \"side\":\"SELL\", \"hash\":\"31f4e013269b9dfb81122b1e7d3179c7b071a787\", \"best_bid\":\"0.51\", \"best_ask\":\"0.52\"}], \"timestamp\":\"1785203771304\", \"event_type\":\"price_change\"}","received_at":"2026-07-28T01:56:11.390866Z","schema_version":"clob-market-ws.price_change.v1","sequence":null,"server_hash":null,"server_timestamp":"1785203771304","session_id":"d2757dd6dad94f3b9fe67e8dbf1adc37","source":"clob_market_ws"},"received_at":"2026-07-28T01:56:11.390866Z","record_id":"06cc6c0597e2ae0d3f92e2527cd59e5bb4108d33abbe6c5456fe5a0f2bed2653","schema_fingerprint":"4aa3821a28b0b7c2400bc59aba4bcc0a76e971dadd19610d3ad38c768e124dc7","schema_version":"edge-lab-recorder.raw.v1","sequence":null,"source":"clob_market_ws"}
{"event_at":"2026-07-28T01:56:11.305000Z","event_fingerprint":"d64311382d7b0c812c9c30d4152d7b5b48289b4a6dae3c45349fe7133c67d629","payload":{"connection_id":"5d29200f65794d4d9ab6ef271f045a9b","event_at":"2026-07-28T01:56:11.305000Z","event_type":"price_change","frame_hash":"6821305e1842277275e7b28c9310e51ccdbae2744da7582c1ffffa6207f0ffa6","frame_index":0,"kind":"data","monotonic_ns":305754406166708,"payload":{"event_type":"price_change","market":"0xda6f0e0e93fc8469e0159a166028d017bddbc162b86f66bac90391379603d962","price_changes":[{"asset_id":"39272994714739463168905443499424551362424437245880253267329605556587274644733","best_ask":"0.49","best_bid":"0.48","hash":"054ec4c197c868e1d07d0e2303095355a57ce326","price":"0.46","side":"BUY","size":"120"},{"asset_id":"20893381255801015515826997628594359667013752732428989472914000440642900266717","best_ask":"0.52","best_bid":"0.51","hash":"2d375e60212d5c42be1ccf97b77beb6585da862a","price":"0.54","side":"SELL","size":"120"}],"timestamp":"1785203771305"},"payload_hash":"d411db72f31c1b744319e439981212e1741d1796b9c73e433bf2b868c9bd62e6","raw_frame":"{\"market\":\"0xda6f0e0e93fc8469e0159a166028d017bddbc162b86f66bac90391379603d962\", \"price_changes\":[{\"asset_id\":\"39272994714739463168905443499424551362424437245880253267329605556587274644733\", \"price\":\"0.46\", \"size\":\"120\", \"side\":\"BUY\", \"hash\":\"054ec4c197c868e1d07d0e2303095355a57ce326\", \"best_bid\":\"0.48\", \"best_ask\":\"0.49\"}, {\"asset_id\":\"20893381255801015515826997628594359667013752732428989472914000440642900266717\", \"price\":\"0.54\", \"size\":\"120\", \"side\":\"SELL\", \"hash\":\"2d375e60212d5c42be1ccf97b77beb6585da862a\", \"best_bid\":\"0.51\", \"best_ask\":\"0.52\"}], \"timestamp\":\"1785203771305\", \"event_type\":\"price_change\"}","received_at":"2026-07-28T01:56:11.397349Z","schema_version":"clob-market-ws.price_change.v1","sequence":null,"server_hash":null,"server_timestamp":"1785203771305","session_id":"d2757dd6dad94f3b9fe67e8dbf1adc37","source":"clob_market_ws"},"received_at":"2026-07-28T01:56:11.397349Z","record_id":"c3ec7077c7c29d597956975df35e48882e5e766fc30977081dd53c0e96a2710b","schema_fingerprint":"4aa3821a28b0b7c2400bc59aba4bcc0a76e971dadd19610d3ad38c768e124dc7","schema_version":"edge-lab-recorder.raw.v1","sequence":null,"source":"clob_market_ws"}
{"event_at":"2026-07-28T01:56:11.306000Z","event_fingerprint":"57991775054bfc30df9682bd9fdbd6808f6567f8791d26f61a5c907e017604fe","payload":{"connection_id":"5d29200f65794d4d9ab6ef271f045a9b","event_at":"2026-07-28T01:56:11.306000Z","event_type":"price_change","frame_hash":"6da2f0186c36568f56d6d6e5983ece8da66f0cd2b5fcae4733d1c1d6aacf563a","frame_index":0,"kind":"data","monotonic_ns":305754410006375,"payload":{"event_type":"price_change","market":"0xda6f0e0e93fc8469e0159a166028d017bddbc162b86f66bac90391379603d962","price_changes":[{"asset_id":"39272994714739463168905443499424551362424437245880253267329605556587274644733","best_ask":"0.49","best_bid":"0.48","hash":"61dea289fb761de823efa75f043b8e177e9ffd13","price":"0.46","side":"BUY","size":"125"},{"asset_id":"20893381255801015515826997628594359667013752732428989472914000440642900266717","best_ask":"0.52","best_bid":"0.51","hash":"1ee6b151d206dac465dc51ee957968554864589c","price":"0.54","side":"SELL","size":"125"}],"timestamp":"1785203771306"},"payload_hash":"63b6977b683403bf376e4115ea060ec80a1a65925e4db59095cde0a75657ff12","raw_frame":"{\"market\":\"0xda6f0e0e93fc8469e0159a166028d017bddbc162b86f66bac90391379603d962\", \"price_changes\":[{\"asset_id\":\"39272994714739463168905443499424551362424437245880253267329605556587274644733\", \"price\":\"0.46\", \"size\":\"125\", \"side\":\"BUY\", \"hash\":\"61dea289fb761de823efa75f043b8e177e9ffd13\", \"best_bid\":\"0.48\", \"best_ask\":\"0.49\"}, {\"asset_id\":\"20893381255801015515826997628594359667013752732428989472914000440642900266717\", \"price\":\"0.54\", \"size\":\"125\", \"side\":\"SELL\", \"hash\":\"1ee6b151d206dac465dc51ee957968554864589c\", \"best_bid\":\"0.51\", \"best_ask\":\"0.52\"}], \"timestamp\":\"1785203771306\", \"event_type\":\"price_change\"}","received_at":"2026-07-28T01:56:11.401193Z","schema_version":"clob-market-ws.price_change.v1","sequence":null,"server_hash":null,"server_timestamp":"1785203771306","session_id":"d2757dd6dad94f3b9fe67e8dbf1adc37","source":"clob_market_ws"},"received_at":"2026-07-28T01:56:11.401193Z","record_id":"f6c4029a1cea90e673d9492b6b01542deb769bc771f525aab1ed8a748f312f71","schema_fingerprint":"4aa3821a28b0b7c2400bc59aba4bcc0a76e971dadd19610d3ad38c768e124dc7","schema_version":"edge-lab-recorder.raw.v1","sequence":null,"source":"clob_market_ws"}
{"event_at":"2026-07-28T01:56:11.307000Z","event_fingerprint":"0e9a9277ae69597f0ff043c7ae794b3452d7656a17621b177bedcdada243fdba","payload":{"connection_id":"5d29200f65794d4d9ab6ef271f045a9b","event_at":"2026-07-28T01:56:11.307000Z","event_type":"price_change","frame_hash":"fa412405009b332b88cc7125a5f99163d4012b086445846ee23f0cab5512164e","frame_index":0,"kind":"data","monotonic_ns":305754413155083,"payload":{"event_type":"price_change","market":"0xda6f0e0e93fc8469e0159a166028d017bddbc162b86f66bac90391379603d962","price_changes":[{"asset_id":"39272994714739463168905443499424551362424437245880253267329605556587274644733","best_ask":"0.49","best_bid":"0.48","hash":"989892eb1ffaf24f9fee5937faf2fd8ae1fd76e8","price":"0.46","side":"BUY","size":"130"},{"asset_id":"20893381255801015515826997628594359667013752732428989472914000440642900266717","best_ask":"0.52","best_bid":"0.51","hash":"35f5fcb08b6793fcef1eceeade0ca1ee23fc1006","price":"0.54","side":"SELL","size":"130"}],"timestamp":"1785203771307"},"payload_hash":"b32569fe884fa44380b88dad089a56ce726aba78d011e927d2d01164f1935b47","raw_frame":"{\"market\":\"0xda6f0e0e93fc8469e0159a166028d017bddbc162b86f66bac90391379603d962\", \"price_changes\":[{\"asset_id\":\"39272994714739463168905443499424551362424437245880253267329605556587274644733\", \"price\":\"0.46\", \"size\":\"130\", \"side\":\"BUY\", \"hash\":\"989892eb1ffaf24f9fee5937faf2fd8ae1fd76e8\", \"best_bid\":\"0.48\", \"best_ask\":\"0.49\"}, {\"asset_id\":\"20893381255801015515826997628594359667013752732428989472914000440642900266717\", \"price\":\"0.54\", \"size\":\"130\", \"side\":\"SELL\", \"hash\":\"35f5fcb08b6793fcef1eceeade0ca1ee23fc1006\", \"best_bid\":\"0.51\", \"best_ask\":\"0.52\"}], \"timestamp\":\"1785203771307\", \"event_type\":\"price_change\"}","received_at":"2026-07-28T01:56:11.404336Z","schema_version":"clob-market-ws.price_change.v1","sequence":null,"server_hash":null,"server_timestamp":"1785203771307","session_id":"d2757dd6dad94f3b9fe67e8dbf1adc37","source":"clob_market_ws"},"received_at":"2026-07-28T01:56:11.404336Z","record_id":"1fb8127402383ed0b3cc4ddbb0f3dcd0cb17613601476f1cc2c4d76a07d5fcf2","schema_fingerprint":"4aa3821a28b0b7c2400bc59aba4bcc0a76e971dadd19610d3ad38c768e124dc7","schema_version":"edge-lab-recorder.raw.v1","sequence":null,"source":"clob_market_ws"}
{"event_at":"2026-07-28T01:56:11.308000Z","event_fingerprint":"0fb423b071694fe1b72ef08e955f403dc118129be5f1477ee6e1796ee1be218e","payload":{"connection_id":"5d29200f65794d4d9ab6ef271f045a9b","event_at":"2026-07-28T01:56:11.308000Z","event_type":"price_change","frame_hash":"57c762a1b181b4a27dae8e151ea0c0d3460a5289a01b924288c96ca162b03b1d","frame_index":0,"kind":"data","monotonic_ns":305754417613416,"payload":{"event_type":"price_change","market":"0xda6f0e0e93fc8469e0159a166028d017bddbc162b86f66bac90391379603d962","price_changes":[{"asset_id":"39272994714739463168905443499424551362424437245880253267329605556587274644733","best_ask":"0.49","best_bid":"0.48","hash":"cc1eae24db281b214ba22a3cf6b6be3e424cbd51","price":"0.46","side":"BUY","size":"135"},{"asset_id":"20893381255801015515826997628594359667013752732428989472914000440642900266717","best_ask":"0.52","best_bid":"0.51","hash":"cd53e7745ba211807abdf5a1e0eebc21d0258126","price":"0.54","side":"SELL","size":"135"}],"timestamp":"1785203771308"},"payload_hash":"da9d5302e3b1db16a73b6d381ca3d8b783a90e3c7392be539d4d39c819f8bf1c","raw_frame":"{\"market\":\"0xda6f0e0e93fc8469e0159a166028d017bddbc162b86f66bac90391379603d962\", \"price_changes\":[{\"asset_id\":\"39272994714739463168905443499424551362424437245880253267329605556587274644733\", \"price\":\"0.46\", \"size\":\"135\", \"side\":\"BUY\", \"hash\":\"cc1eae24db281b214ba22a3cf6b6be3e424cbd51\", \"best_bid\":\"0.48\", \"best_ask\":\"0.49\"}, {\"asset_id\":\"20893381255801015515826997628594359667013752732428989472914000440642900266717\", \"price\":\"0.54\", \"size\":\"135\", \"side\":\"SELL\", \"hash\":\"cd53e7745ba211807abdf5a1e0eebc21d0258126\", \"best_bid\":\"0.51\", \"best_ask\":\"0.52\"}], \"timestamp\":\"1785203771308\", \"event_type\":\"price_change\"}","received_at":"2026-07-28T01:56:11.408793Z","schema_version":"clob-market-ws.price_change.v1","sequence":null,"server_hash":null,"server_timestamp":"1785203771308","session_id":"d2757dd6dad94f3b9fe67e8dbf1adc37","source":"clob_market_ws"},"received_at":"2026-07-28T01:56:11.408793Z","record_id":"bf1f7851d0b2ba4246ed33f70b91c8f735f9f3cc0b5c564dba8c35e31c7bdd7b","schema_fingerprint":"4aa3821a28b0b7c2400bc59aba4bcc0a76e971dadd19610d3ad38c768e124dc7","schema_version":"edge-lab-recorder.raw.v1","sequence":null,"source":"clob_market_ws"}
{"event_at":"2026-07-28T01:56:11.309000Z","event_fingerprint":"e83a47d23f463a874a57558d1efb3e1ab1c91674af2b9acb7789aa99a7182059","payload":{"connection_id":"5d29200f65794d4d9ab6ef271f045a9b","event_at":"2026-07-28T01:56:11.309000Z","event_type":"price_change","frame_hash":"3e7b844d938180a8f71b40116079403873fee7f81a616ed002a0bc1a3c29f2e6","frame_index":0,"kind":"data","monotonic_ns":305754422138250,"payload":{"event_type":"price_change","market":"0xda6f0e0e93fc8469e0159a166028d017bddbc162b86f66bac90391379603d962","price_changes":[{"asset_id":"39272994714739463168905443499424551362424437245880253267329605556587274644733","best_ask":"0.49","best_bid":"0.48","hash":"cd1b85356f550e62b2cfb38b07ae978bd22385b0","price":"0.46","side":"BUY","size":"140"},{"asset_id":"20893381255801015515826997628594359667013752732428989472914000440642900266717","best_ask":"0.52","best_bid":"0.51","hash":"cbe72365a57f3ee794439023d6f601c2fa0695f9","price":"0.54","side":"SELL","size":"140"}],"timestamp":"1785203771309"},"payload_hash":"f31ee8f5dca6db66fb62b51d2fe41e1c906eb08f6b03205933cad23341420dd4","raw_frame":"{\"market\":\"0xda6f0e0e93fc8469e0159a166028d017bddbc162b86f66bac90391379603d962\", \"price_changes\":[{\"asset_id\":\"39272994714739463168905443499424551362424437245880253267329605556587274644733\", \"price\":\"0.46\", \"size\":\"140\", \"side\":\"BUY\", \"hash\":\"cd1b85356f550e62b2cfb38b07ae978bd22385b0\", \"best_bid\":\"0.48\", \"best_ask\":\"0.49\"}, {\"asset_id\":\"20893381255801015515826997628594359667013752732428989472914000440642900266717\", \"price\":\"0.54\", \"size\":\"140\", \"side\":\"SELL\", \"hash\":\"cbe72365a57f3ee794439023d6f601c2fa0695f9\", \"best_bid\":\"0.51\", \"best_ask\":\"0.52\"}], \"timestamp\":\"1785203771309\", \"event_type\":\"price_change\"}","received_at":"2026-07-28T01:56:11.413321Z","schema_version":"clob-market-ws.price_change.v1","sequence":null,"server_hash":null,"server_timestamp":"1785203771309","session_id":"d2757dd6dad94f3b9fe67e8dbf1adc37","source":"clob_market_ws"},"received_at":"2026-07-28T01:56:11.413321Z","record_id":"3f66401a9afdd82e6ffd12ae45be5b61803504e3b2efa0a278621b1fe8cc6b91","schema_fingerprint":"4aa3821a28b0b7c2400bc59aba4bcc0a76e971dadd19610d3ad38c768e124dc7","schema_version":"edge-lab-recorder.raw.v1","sequence":null,"source":"clob_market_ws"}
{"event_at":"2026-07-28T01:56:11.310000Z","event_fingerprint":"2439f3d69df6a9fe35efd555b1f4481876bd036a7e99d842879c7fa3f19deea2","payload":{"connection_id":"5d29200f65794d4d9ab6ef271f045a9b","event_at":"2026-07-28T01:56:11.310000Z","event_type":"price_change","frame_hash":"1561a9cb661492f8e3f8a5501901d44b048799ad1583851d9c33d0be0b4ec2a2","frame_index":0,"kind":"data","monotonic_ns":305754426479541,"payload":{"event_type":"price_change","market":"0xda6f0e0e93fc8469e0159a166028d017bddbc162b86f66bac90391379603d962","price_changes":[{"asset_id":"39272994714739463168905443499424551362424437245880253267329605556587274644733","best_ask":"0.49","best_bid":"0.48","hash":"6ce80633b56a9fe34835b373fec4ee78c29eff2e","price":"0.46","side":"BUY","size":"145"},{"asset_id":"20893381255801015515826997628594359667013752732428989472914000440642900266717","best_ask":"0.52","best_bid":"0.51","hash":"336dbd3fac1182b2da8b30a67b6ec310a8402e66","price":"0.54","side":"SELL","size":"145"}],"timestamp":"1785203771310"},"payload_hash":"feced6d532503da82d8dc2fb4535e04addb81f2905fbde845d3f4bbd1cf1bb6f","raw_frame":"{\"market\":\"0xda6f0e0e93fc8469e0159a166028d017bddbc162b86f66bac90391379603d962\", \"price_changes\":[{\"asset_id\":\"39272994714739463168905443499424551362424437245880253267329605556587274644733\", \"price\":\"0.46\", \"size\":\"145\", \"side\":\"BUY\", \"hash\":\"6ce80633b56a9fe34835b373fec4ee78c29eff2e\", \"best_bid\":\"0.48\", \"best_ask\":\"0.49\"}, {\"asset_id\":\"20893381255801015515826997628594359667013752732428989472914000440642900266717\", \"price\":\"0.54\", \"size\":\"145\", \"side\":\"SELL\", \"hash\":\"336dbd3fac1182b2da8b30a67b6ec310a8402e66\", \"best_bid\":\"0.51\", \"best_ask\":\"0.52\"}], \"timestamp\":\"1785203771310\", \"event_type\":\"price_change\"}","received_at":"2026-07-28T01:56:11.417662Z","schema_version":"clob-market-ws.price_change.v1","sequence":null,"server_hash":null,"server_timestamp":"1785203771310","session_id":"d2757dd6dad94f3b9fe67e8dbf1adc37","source":"clob_market_ws"},"received_at":"2026-07-28T01:56:11.417662Z","record_id":"a527c65fb057b22928d928fc316e415e49ef4d410efcd17d4a5627d00c15fce0","schema_fingerprint":"4aa3821a28b0b7c2400bc59aba4bcc0a76e971dadd19610d3ad38c768e124dc7","schema_version":"edge-lab-recorder.raw.v1","sequence":null,"source":"clob_market_ws"}
{"event_at":"2026-07-28T01:56:11.311000Z","event_fingerprint":"3ebaaebbb85ff0b3cb1194c52894e08d4ffde4053c6ccb84ce1eec0fac4d5a3f","payload":{"connection_id":"5d29200f65794d4d9ab6ef271f045a9b","event_at":"2026-07-28T01:56:11.311000Z","event_type":"price_change","frame_hash":"27b0acb700f9d5a19de68aa36c617973c4bb2747e6d9080671225c5e7d6957f9","frame_index":0,"kind":"data","monotonic_ns":305754431917625,"payload":{"event_type":"price_change","market":"0xda6f0e0e93fc8469e0159a166028d017bddbc162b86f66bac90391379603d962","price_changes":[{"asset_id":"39272994714739463168905443499424551362424437245880253267329605556587274644733","best_ask":"0.49","best_bid":"0.48","hash":"d9176fce47bec1d57f83df2670c1ff9686dc8ec1","price":"0.46","side":"BUY","size":"150"},{"asset_id":"20893381255801015515826997628594359667013752732428989472914000440642900266717","best_ask":"0.52","best_bid":"0.51","hash":"54b6981dbd3d1c53a616596bbf2e8ccda7b52ab2","price":"0.54","side":"SELL","size":"150"}],"timestamp":"1785203771311"},"payload_hash":"662fdd70b9c70c8ef307be3786faa07abe53c9c97fbc041cc41e61274f3276e7","raw_frame":"{\"market\":\"0xda6f0e0e93fc8469e0159a166028d017bddbc162b86f66bac90391379603d962\", \"price_changes\":[{\"asset_id\":\"39272994714739463168905443499424551362424437245880253267329605556587274644733\", \"price\":\"0.46\", \"size\":\"150\", \"side\":\"BUY\", \"hash\":\"d9176fce47bec1d57f83df2670c1ff9686dc8ec1\", \"best_bid\":\"0.48\", \"best_ask\":\"0.49\"}, {\"asset_id\":\"20893381255801015515826997628594359667013752732428989472914000440642900266717\", \"price\":\"0.54\", \"size\":\"150\", \"side\":\"SELL\", \"hash\":\"54b6981dbd3d1c53a616596bbf2e8ccda7b52ab2\", \"best_bid\":\"0.51\", \"best_ask\":\"0.52\"}], \"timestamp\":\"1785203771311\", \"event_type\":\"price_change\"}","received_at":"2026-07-28T01:56:11.423099Z","schema_version":"clob-market-ws.price_change.v1","sequence":null,"server_hash":null,"server_timestamp":"1785203771311","session_id":"d2757dd6dad94f3b9fe67e8dbf1adc37","source":"clob_market_ws"},"received_at":"2026-07-28T01:56:11.423099Z","record_id":"c68e162670f303929e679f2e8a4f723fa98deafe61b79e07093ab869034688a2","schema_fingerprint":"4aa3821a28b0b7c2400bc59aba4bcc0a76e971dadd19610d3ad38c768e124dc7","schema_version":"edge-lab-recorder.raw.v1","sequence":null,"source":"clob_market_ws"}
{"event_at":"2026-07-28T01:56:11.312000Z","event_fingerprint":"95b65f96ec9dfe47d47b1eaf58ffedf67583a09562f3562380f95da74573ffba","payload":{"connection_id":"5d29200f65794d4d9ab6ef271f045a9b","event_at":"2026-07-28T01:56:11.312000Z","event_type":"price_change","frame_hash":"1dc86421fff3289a80cf8e715590d03434124306ab300470cf59ec9063cc2782","frame_index":0,"kind":"data","monotonic_ns":305754436417291,"payload":{"event_type":"price_change","market":"0xda6f0e0e93fc8469e0159a166028d017bddbc162b86f66bac90391379603d962","price_changes":[{"asset_id":"39272994714739463168905443499424551362424437245880253267329605556587274644733","best_ask":"0.49","best_bid":"0.48","hash":"1fb43af4208fc92338d8b119449f5b1ccf766812","price":"0.46","side":"BUY","size":"155"},{"asset_id":"20893381255801015515826997628594359667013752732428989472914000440642900266717","best_ask":"0.52","best_bid":"0.51","hash":"eafc8a56cbfdabd2583ae4bd9e2b323f527b5069","price":"0.54","side":"SELL","size":"155"}],"timestamp":"1785203771312"},"payload_hash":"296e68233dbabfe63fc9e934ecdf063aaf21c80295c69a4544a9f6fa8b342b9a","raw_frame":"{\"market\":\"0xda6f0e0e93fc8469e0159a166028d017bddbc162b86f66bac90391379603d962\", \"price_changes\":[{\"asset_id\":\"39272994714739463168905443499424551362424437245880253267329605556587274644733\", \"price\":\"0.46\", \"size\":\"155\", \"side\":\"BUY\", \"hash\":\"1fb43af4208fc92338d8b119449f5b1ccf766812\", \"best_bid\":\"0.48\", \"best_ask\":\"0.49\"}, {\"asset_id\":\"20893381255801015515826997628594359667013752732428989472914000440642900266717\", \"price\":\"0.54\", \"size\":\"155\", \"side\":\"SELL\", \"hash\":\"eafc8a56cbfdabd2583ae4bd9e2b323f527b5069\", \"best_bid\":\"0.51\", \"best_ask\":\"0.52\"}], \"timestamp\":\"1785203771312\", \"event_type\":\"price_change\"}","received_at":"2026-07-28T01:56:11.427599Z","schema_version":"clob-market-ws.price_change.v1","sequence":null,"server_hash":null,"server_timestamp":"1785203771312","session_id":"d2757dd6dad94f3b9fe67e8dbf1adc37","source":"clob_market_ws"},"received_at":"2026-07-28T01:56:11.427599Z","record_id":"b38083417d4229c98b29947690a1f6ccca07c3397f1bc851a01e35b1bb93806c","schema_fingerprint":"4aa3821a28b0b7c2400bc59aba4bcc0a76e971dadd19610d3ad38c768e124dc7","schema_version":"edge-lab-recorder.raw.v1","sequence":null,"source":"clob_market_ws"}
{"event_at":"2026-07-28T01:56:11.313000Z","event_fingerprint":"cb96c42facd983868323ffe1d8c7e4d2d484d88b1e9a39e81de1e68549fbbe79","payload":{"connection_id":"5d29200f65794d4d9ab6ef271f045a9b","event_at":"2026-07-28T01:56:11.313000Z","event_type":"price_change","frame_hash":"3d32ab28498fd4e40bcd95b9c3571f555a5689dc4ab31bc30cec47dc4a150192","frame_index":0,"kind":"data","monotonic_ns":305754441856041,"payload":{"event_type":"price_change","market":"0xda6f0e0e93fc8469e0159a166028d017bddbc162b86f66bac90391379603d962","price_changes":[{"asset_id":"39272994714739463168905443499424551362424437245880253267329605556587274644733","best_ask":"0.49","best_bid":"0.48","hash":"96c5434aadecb76a3da97808e875887c89bd962c","price":"0.46","side":"BUY","size":"160"},{"asset_id":"20893381255801015515826997628594359667013752732428989472914000440642900266717","best_ask":"0.52","best_bid":"0.51","hash":"250e1b54ba9c9c21d745129611d3f91d1f1ed61b","price":"0.54","side":"SELL","size":"160"}],"timestamp":"1785203771313"},"payload_hash":"741cd7bb3278b0892fbb7ab1a85faacbb9c7cf95418bf1573495a3d0b50d59f6","raw_frame":"{\"market\":\"0xda6f0e0e93fc8469e0159a166028d017bddbc162b86f66bac90391379603d962\", \"price_changes\":[{\"asset_id\":\"39272994714739463168905443499424551362424437245880253267329605556587274644733\", \"price\":\"0.46\", \"size\":\"160\", \"side\":\"BUY\", \"hash\":\"96c5434aadecb76a3da97808e875887c89bd962c\", \"best_bid\":\"0.48\", \"best_ask\":\"0.49\"}, {\"asset_id\":\"20893381255801015515826997628594359667013752732428989472914000440642900266717\", \"price\":\"0.54\", \"size\":\"160\", \"side\":\"SELL\", \"hash\":\"250e1b54ba9c9c21d745129611d3f91d1f1ed61b\", \"best_bid\":\"0.51\", \"best_ask\":\"0.52\"}], \"timestamp\":\"1785203771313\", \"event_type\":\"price_change\"}","received_at":"2026-07-28T01:56:11.433038Z","schema_version":"clob-market-ws.price_change.v1","sequence":null,"server_hash":null,"server_timestamp":"1785203771313","session_id":"d2757dd6dad94f3b9fe67e8dbf1adc37","source":"clob_market_ws"},"received_at":"2026-07-28T01:56:11.433038Z","record_id":"e0d9c416f0708211cfb1b1f1a0f983bf97d1571d94424d850003c9c2d69035ce","schema_fingerprint":"4aa3821a28b0b7c2400bc59aba4bcc0a76e971dadd19610d3ad38c768e124dc7","schema_version":"edge-lab-recorder.raw.v1","sequence":null,"source":"clob_market_ws"}
{"event_at":"2026-07-28T01:56:11.314000Z","event_fingerprint":"5b25560f4d977204691cabe40ef80655089bcd52be201098b8dac07729ac85ca","payload":{"connection_id":"5d29200f65794d4d9ab6ef271f045a9b","event_at":"2026-07-28T01:56:11.314000Z","event_type":"price_change","frame_hash":"f21f953f2e2283cf4ef9e20b81f4de64d6b59666a346dae7fde8fb910fe24746","frame_index":0,"kind":"data","monotonic_ns":305754446328083,"payload":{"event_type":"price_change","market":"0xda6f0e0e93fc8469e0159a166028d017bddbc162b86f66bac90391379603d962","price_changes":[{"asset_id":"39272994714739463168905443499424551362424437245880253267329605556587274644733","best_ask":"0.49","best_bid":"0.48","hash":"b66fec14b04288352d711cb258ba0dca17678838","price":"0.46","side":"BUY","size":"165"},{"asset_id":"20893381255801015515826997628594359667013752732428989472914000440642900266717","best_ask":"0.52","best_bid":"0.51","hash":"6785dd4073f9764bab22d96316cbf64332131b65","price":"0.54","side":"SELL","size":"165"}],"timestamp":"1785203771314"},"payload_hash":"7456b789fd90845362a368a1c11613dfd443f4fd1e7b2e6835fd6f16fb98c716","raw_frame":"{\"market\":\"0xda6f0e0e93fc8469e0159a166028d017bddbc162b86f66bac90391379603d962\", \"price_changes\":[{\"asset_id\":\"39272994714739463168905443499424551362424437245880253267329605556587274644733\", \"price\":\"0.46\", \"size\":\"165\", \"side\":\"BUY\", \"hash\":\"b66fec14b04288352d711cb258ba0dca17678838\", \"best_bid\":\"0.48\", \"best_ask\":\"0.49\"}, {\"asset_id\":\"20893381255801015515826997628594359667013752732428989472914000440642900266717\", \"price\":\"0.54\", \"size\":\"165\", \"side\":\"SELL\", \"hash\":\"6785dd4073f9764bab22d96316cbf64332131b65\", \"best_bid\":\"0.51\", \"best_ask\":\"0.52\"}], \"timestamp\":\"1785203771314\", \"event_type\":\"price_change\"}","received_at":"2026-07-28T01:56:11.437507Z","schema_version":"clob-market-ws.price_change.v1","sequence":null,"server_hash":null,"server_timestamp":"1785203771314","session_id":"d2757dd6dad94f3b9fe67e8dbf1adc37","source":"clob_market_ws"},"received_at":"2026-07-28T01:56:11.437507Z","record_id":"94f14c9a9b7f335febcebba8cd71a5502bb4e46c425842e23e6c784835e4b6f3","schema_fingerprint":"4aa3821a28b0b7c2400bc59aba4bcc0a76e971dadd19610d3ad38c768e124dc7","schema_version":"edge-lab-recorder.raw.v1","sequence":null,"source":"clob_market_ws"}
{"event_at":"2026-07-28T01:56:11.315000Z","event_fingerprint":"daf92226d0b6b999fee1605684c58088c38a301d4a344d8abdf1ac90f4bab4db","payload":{"connection_id":"5d29200f65794d4d9ab6ef271f045a9b","event_at":"2026-07-28T01:56:11.315000Z","event_type":"price_change","frame_hash":"fc8e8a64d404b3f2ff4cbd0490b2b2b075c127d6ce38c7c0e7a834d37fe08d90","frame_index":0,"kind":"data","monotonic_ns":305754448538541,"payload":{"event_type":"price_change","market":"0xda6f0e0e93fc8469e0159a166028d017bddbc162b86f66bac90391379603d962","price_changes":[{"asset_id":"39272994714739463168905443499424551362424437245880253267329605556587274644733","best_ask":"0.49","best_bid":"0.48","hash":"dd945f37c189bf6dd80378b2e0f7650588f326a1","price":"0.46","side":"BUY","size":"170"},{"asset_id":"20893381255801015515826997628594359667013752732428989472914000440642900266717","best_ask":"0.52","best_bid":"0.51","hash":"915d72438e9497388fc4689e2b726b145a54dee8","price":"0.54","side":"SELL","size":"170"}],"timestamp":"1785203771315"},"payload_hash":"1e594a75ede3b92222441ce31d6a1c3041643e193dbda8bb55a9cd6bb4e8c729","raw_frame":"{\"market\":\"0xda6f0e0e93fc8469e0159a166028d017bddbc162b86f66bac90391379603d962\", \"price_changes\":[{\"asset_id\":\"39272994714739463168905443499424551362424437245880253267329605556587274644733\", \"price\":\"0.46\", \"size\":\"170\", \"side\":\"BUY\", \"hash\":\"dd945f37c189bf6dd80378b2e0f7650588f326a1\", \"best_bid\":\"0.48\", \"best_ask\":\"0.49\"}, {\"asset_id\":\"20893381255801015515826997628594359667013752732428989472914000440642900266717\", \"price\":\"0.54\", \"size\":\"170\", \"side\":\"SELL\", \"hash\":\"915d72438e9497388fc4689e2b726b145a54dee8\", \"best_bid\":\"0.51\", \"best_ask\":\"0.52\"}], \"timestamp\":\"1785203771315\", \"event_type\":\"price_change\"}","received_at":"2026-07-28T01:56:11.439720Z","schema_version":"clob-market-ws.price_change.v1","sequence":null,"server_hash":null,"server_timestamp":"1785203771315","session_id":"d2757dd6dad94f3b9fe67e8dbf1adc37","source":"clob_market_ws"},"received_at":"2026-07-28T01:56:11.439720Z","record_id":"75894ce360bc1d451205811e02bd14363fdb5e8805e35f27e61c3a0398993f59","schema_fingerprint":"4aa3821a28b0b7c2400bc59aba4bcc0a76e971dadd19610d3ad38c768e124dc7","schema_version":"edge-lab-recorder.raw.v1","sequence":null,"source":"clob_market_ws"}
{"event_at":"2026-07-28T01:56:11.315000Z","event_fingerprint":"ff6bc7c07ef0eb69ce1785d12d32807c44a75055aa9d4e1968378ac2c3b5f5c5","payload":{"connection_id":"5d29200f65794d4d9ab6ef271f045a9b","event_at":"2026-07-28T01:56:11.315000Z","event_type":"price_change","frame_hash":"07e1efcd11a6e8cfd4339ff6efeaebb2e08a42fe05979f1c98f03867b9a5a61b","frame_index":0,"kind":"data","monotonic_ns":305754453214125,"payload":{"event_type":"price_change","market":"0xda6f0e0e93fc8469e0159a166028d017bddbc162b86f66bac90391379603d962","price_changes":[{"asset_id":"39272994714739463168905443499424551362424437245880253267329605556587274644733","best_ask":"0.49","best_bid":"0.48","hash":"3ee10b04bb10c64e86527f0cefdc4282c9fe72f7","price":"0.46","side":"BUY","size":"175"},{"asset_id":"20893381255801015515826997628594359667013752732428989472914000440642900266717","best_ask":"0.52","best_bid":"0.51","hash":"1942406eee6902a937f7128e153a4748cb576d17","price":"0.54","side":"SELL","size":"175"}],"timestamp":"1785203771315"},"payload_hash":"36195baceee543f8b2212d693d5e6f22193af6bf318a7b09af5391756663e8eb","raw_frame":"{\"market\":\"0xda6f0e0e93fc8469e0159a166028d017bddbc162b86f66bac90391379603d962\", \"price_changes\":[{\"asset_id\":\"39272994714739463168905443499424551362424437245880253267329605556587274644733\", \"price\":\"0.46\", \"size\":\"175\", \"side\":\"BUY\", \"hash\":\"3ee10b04bb10c64e86527f0cefdc4282c9fe72f7\", \"best_bid\":\"0.48\", \"best_ask\":\"0.49\"}, {\"asset_id\":\"20893381255801015515826997628594359667013752732428989472914000440642900266717\", \"price\":\"0.54\", \"size\":\"175\", \"side\":\"SELL\", \"hash\":\"1942406eee6902a937f7128e153a4748cb576d17\", \"best_bid\":\"0.51\", \"best_ask\":\"0.52\"}], \"timestamp\":\"1785203771315\", \"event_type\":\"price_change\"}","received_at":"2026-07-28T01:56:11.444393Z","schema_version":"clob-market-ws.price_change.v1","sequence":null,"server_hash":null,"server_timestamp":"1785203771315","session_id":"d2757dd6dad94f3b9fe67e8dbf1adc37","source":"clob_market_ws"},"received_at":"2026-07-28T01:56:11.444393Z","record_id":"ef2d901a82c9d046521136fb4565485cbd7da9afa26bf78fa58fe29dd957603d","schema_fingerprint":"4aa3821a28b0b7c2400bc59aba4bcc0a76e971dadd19610d3ad38c768e124dc7","schema_version":"edge-lab-recorder.raw.v1","sequence":null,"source":"clob_market_ws"}
