{"event_at":"2026-07-28T02:02:14.162000Z","event_fingerprint":"a47e39b5bda50923c25307c2588f41df274dd064dc06b1bc31e718711dd41c14","payload":{"connection_id":"5d29200f65794d4d9ab6ef271f045a9b","event_at":"2026-07-28T02:02:14.162000Z","event_type":"price_change","frame_hash":"98529e93bb9d60b5e9faefa692d48085612955260d1e690e6c79f2cb6fddca62","frame_index":0,"kind":"data","monotonic_ns":306118443029750,"payload":{"event_type":"price_change","market":"0xda6f0e0e93fc8469e0159a166028d017bddbc162b86f66bac90391379603d962","price_changes":[{"asset_id":"39272994714739463168905443499424551362424437245880253267329605556587274644733","best_ask":"0.58","best_bid":"0.57","hash":"3c34b07600436747088afc227a7c59588792c5c0","price":"0.53","side":"BUY","size":"105.03"},{"asset_id":"20893381255801015515826997628594359667013752732428989472914000440642900266717","best_ask":"0.43","best_bid":"0.42","hash":"646add4bbdc347534f674ef1795d2c9afeb269a5","price":"0.47","side":"SELL","size":"105.03"}],"timestamp":"1785204134162"},"payload_hash":"f474a10eb38cea7da0d32871a7a5cc159b6d4ecbdee4ab5326b25b2cf9e4dd66","raw_frame":"{\"market\":\"0xda6f0e0e93fc8469e0159a166028d017bddbc162b86f66bac90391379603d962\", \"price_changes\":[{\"asset_id\":\"39272994714739463168905443499424551362424437245880253267329605556587274644733\", \"price\":\"0.53\", \"size\":\"105.03\", \"side\":\"BUY\", \"hash\":\"3c34b07600436747088afc227a7c59588792c5c0\", \"best_bid\":\"0.57\", \"best_ask\":\"0.58\"}, {\"asset_id\":\"20893381255801015515826997628594359667013752732428989472914000440642900266717\", \"price\":\"0.47\", \"size\":\"105.03\", \"side\":\"SELL\", \"hash\":\"646add4bbdc347534f674ef1795d2c9afeb269a5\", \"best_bid\":\"0.42\", \"best_ask\":\"0.43\"}], \"timestamp\":\"1785204134162\", \"event_type\":\"price_change\"}","received_at":"2026-07-28T02:02:15.438638Z","schema_version":"clob-market-ws.price_change.v1","sequence":null,"server_hash":null,"server_timestamp":"1785204134162","session_id":"d2757dd6dad94f3b9fe67e8dbf1adc37","source":"clob_market_ws"},"received_at":"2026-07-28T02:02:15.438638Z","record_id":"032816c4ee6d334dd6414a8130cb8ca97ef3a1ecd22aa8552038fc11a7942905","schema_fingerprint":"4aa3821a28b0b7c2400bc59aba4bcc0a76e971dadd19610d3ad38c768e124dc7","schema_version":"edge-lab-recorder.raw.v1","sequence":null,"source":"clob_market_ws"}
{"event_at":"2026-07-28T02:02:14.162000Z","event_fingerprint":"910875a8a39f5916cffad0b50900aee50984f675c4042a8c159e2749eca134a5","payload":{"connection_id":"5d29200f65794d4d9ab6ef271f045a9b","event_at":"2026-07-28T02:02:14.162000Z","event_type":"price_change","frame_hash":"61ebe284ed10001a63499eb77ed79569fb112cf6d91cb60ebf232c11770ddcb6","frame_index":0,"kind":"data","monotonic_ns":306118458296833,"payload":{"event_type":"price_change","market":"0xda6f0e0e93fc8469e0159a166028d017bddbc162b86f66bac90391379603d962","price_changes":[{"asset_id":"20893381255801015515826997628594359667013752732428989472914000440642900266717","best_ask":"0.43","best_bid":"0.42","hash":"c697ead02f50158add7bcb63d1d1cc4cf1e19835","price":"0.34","side":"BUY","size":"225"},{"asset_id":"39272994714739463168905443499424551362424437245880253267329605556587274644733","best_ask":"0.58","best_bid":"0.57","hash":"d386a0ec8a8f919a64bf336703c5ec88feddea69","price":"0.66","side":"SELL","size":"225"}],"timestamp":"1785204134162"},"payload_hash":"4fd33f5ac76da9b2d90fc16d93f268727954085b056b131bb15a62d08a082456","raw_frame":"{\"market\":\"0xda6f0e0e93fc8469e0159a166028d017bddbc162b86f66bac90391379603d962\", \"price_changes\":[{\"asset_id\":\"20893381255801015515826997628594359667013752732428989472914000440642900266717\", \"price\":\"0.34\", \"size\":\"225\", \"side\":\"BUY\", \"hash\":\"c697ead02f50158add7bcb63d1d1cc4cf1e19835\", \"best_bid\":\"0.42\", \"best_ask\":\"0.43\"}, {\"asset_id\":\"39272994714739463168905443499424551362424437245880253267329605556587274644733\", \"price\":\"0.66\", \"size\":\"225\", \"side\":\"SELL\", \"hash\":\"d386a0ec8a8f919a64bf336703c5ec88feddea69\", \"best_bid\":\"0.57\", \"best_ask\":\"0.58\"}], \"timestamp\":\"1785204134162\", \"event_type\":\"price_change\"}","received_at":"2026-07-28T02:02:15.453906Z","schema_version":"clob-market-ws.price_change.v1","sequence":null,"server_hash":null,"server_timestamp":"1785204134162","session_id":"d2757dd6dad94f3b9fe67e8dbf1adc37","source":"clob_market_ws"},"received_at":"2026-07-28T02:02:15.453906Z","record_id":"d3a12824e8b9dadfafd15684926fd0c07ea1a346f1567c6d911ef20e2bae4e4d","schema_fingerprint":"4aa3821a28b0b7c2400bc59aba4bcc0a76e971dadd19610d3ad38c768e124dc7","schema_version":"edge-lab-recorder.raw.v1","sequence":null,"source":"clob_market_ws"}
{"event_at":"2026-07-28T02:02:14.163000Z","event_fingerprint":"ec1b6b9b60afe4ab576f8a93560eaf1de0d6b803b777be3a646b5e26faa37cbe","payload":{"connection_id":"5d29200f65794d4d9ab6ef271f045a9b","event_at":"2026-07-28T02:02:14.163000Z","event_type":"price_change","frame_hash":"24e56259775aa3a2b43af6a80a48528d2986be652fdb4c690c9d863250b33b0c","frame_index":0,"kind":"data","monotonic_ns":306118464091791,"payload":{"event_type":"price_change","market":"0xda6f0e0e93fc8469e0159a166028d017bddbc162b86f66bac90391379603d962","price_changes":[{"asset_id":"20893381255801015515826997628594359667013752732428989472914000440642900266717","best_ask":"0.43","best_bid":"0.42","hash":"580bef197741a2e28143a81d04befd394786dbf8","price":"0.42","side":"BUY","size":"140.2"},{"asset_id":"39272994714739463168905443499424551362424437245880253267329605556587274644733","best_ask":"0.58","best_bid":"0.57","hash":"d97519f79ebf4b5785383e598f41eaa386372d44","price":"0.58","side":"SELL","size":"140.2"}],"timestamp":"1785204134163"},"payload_hash":"bd9ea1aa95b08dc1f1d9781a6782c73a32d10678574bcfbfab2d1cdf89fd41d9","raw_frame":"{\"market\":\"0xda6f0e0e93fc8469e0159a166028d017bddbc162b86f66bac90391379603d962\", \"price_changes\":[{\"asset_id\":\"20893381255801015515826997628594359667013752732428989472914000440642900266717\", \"price\":\"0.42\", \"size\":\"140.2\", \"side\":\"BUY\", \"hash\":\"580bef197741a2e28143a81d04befd394786dbf8\", \"best_bid\":\"0.42\", \"best_ask\":\"0.43\"}, {\"asset_id\":\"39272994714739463168905443499424551362424437245880253267329605556587274644733\", \"price\":\"0.58\", \"size\":\"140.2\", \"side\":\"SELL\", \"hash\":\"d97519f79ebf4b5785383e598f41eaa386372d44\", \"best_bid\":\"0.57\", \"best_ask\":\"0.58\"}], \"timestamp\":\"1785204134163\", \"event_type\":\"price_change\"}","received_at":"2026-07-28T02:02:15.459697Z","schema_version":"clob-market-ws.price_change.v1","sequence":null,"server_hash":null,"server_timestamp":"1785204134163","session_id":"d2757dd6dad94f3b9fe67e8dbf1adc37","source":"clob_market_ws"},"received_at":"2026-07-28T02:02:15.459697Z","record_id":"9abc34117879cf45cdd142e015df7d051d5b5dfa34ef07d53f993d220ac6eac7","schema_fingerprint":"4aa3821a28b0b7c2400bc59aba4bcc0a76e971dadd19610d3ad38c768e124dc7","schema_version":"edge-lab-recorder.raw.v1","sequence":null,"source":"clob_market_ws"}
{"event_at":"2026-07-28T02:02:14.164000Z","event_fingerprint":"7eaef6ce18ca7ef151af775225b18375374ab8dac8c837dc5f9debba3e36da22","payload":{"connection_id":"5d29200f65794d4d9ab6ef271f045a9b","event_at":"2026-07-28T02:02:14.164000Z","event_type":"price_change","frame_hash":"7200c3eab13513cd4fa8fa94c0c41d19b491db90761a5dda75a399f174dba455","frame_index":0,"kind":"data","monotonic_ns":306118479948875,"payload":{"event_type":"price_change","market":"0xda6f0e0e93fc8469e0159a166028d017bddbc162b86f66bac90391379603d962","price_changes":[{"asset_id":"39272994714739463168905443499424551362424437245880253267329605556587274644733","best_ask":"0.58","best_bid":"0.57","hash":"acea30e328dc3edc20c7fe6075d8cada073ef113","price":"0.54","side":"BUY","size":"190.04"},{"asset_id":"20893381255801015515826997628594359667013752732428989472914000440642900266717","best_ask":"0.43","best_bid":"0.42","hash":"9838f16dc2e8541e63e510523c92297a8dccea5b","price":"0.46","side":"SELL","size":"190.04"}],"timestamp":"1785204134164"},"payload_hash":"cfd54b22dc097737df633827a4e9fbecdfad73c0783a19e15c7daa81cbcf6d89","raw_frame":"{\"market\":\"0xda6f0e0e93fc8469e0159a166028d017bddbc162b86f66bac90391379603d962\", \"price_changes\":[{\"asset_id\":\"39272994714739463168905443499424551362424437245880253267329605556587274644733\", \"price\":\"0.54\", \"size\":\"190.04\", \"side\":\"BUY\", \"hash\":\"acea30e328dc3edc20c7fe6075d8cada073ef113\", \"best_bid\":\"0.57\", \"best_ask\":\"0.58\"}, {\"asset_id\":\"20893381255801015515826997628594359667013752732428989472914000440642900266717\", \"price\":\"0.46\", \"size\":\"190.04\", \"side\":\"SELL\", \"hash\":\"9838f16dc2e8541e63e510523c92297a8dccea5b\", \"best_bid\":\"0.42\", \"best_ask\":\"0.43\"}], \"timestamp\":\"1785204134164\", \"event_type\":\"price_change\"}","received_at":"2026-07-28T02:02:15.475556Z","schema_version":"clob-market-ws.price_change.v1","sequence":null,"server_hash":null,"server_timestamp":"1785204134164","session_id":"d2757dd6dad94f3b9fe67e8dbf1adc37","source":"clob_market_ws"},"received_at":"2026-07-28T02:02:15.475556Z","record_id":"cf1ea07ec5a49af1b84446737313c8626cb559e33c767236017cbcd981a527a8","schema_fingerprint":"4aa3821a28b0b7c2400bc59aba4bcc0a76e971dadd19610d3ad38c768e124dc7","schema_version":"edge-lab-recorder.raw.v1","sequence":null,"source":"clob_market_ws"}
{"event_at":"2026-07-28T02:02:14.164000Z","event_fingerprint":"8e12b164bb4ddeb5b8dda8f3d9c5d78b27a8b5329c48f8e49984dd6359d35913","payload":{"connection_id":"5d29200f65794d4d9ab6ef271f045a9b","event_at":"2026-07-28T02:02:14.164000Z","event_type":"price_change","frame_hash":"748f49a4162e9789f658734cdb802cff203c0f1cd88b29ec05279f39b7299c5c","frame_index":0,"kind":"data","monotonic_ns":306118486409791,"payload":{"event_type":"price_change","market":"0xda6f0e0e93fc8469e0159a166028d017bddbc162b86f66bac90391379603d962","price_changes":[{"asset_id":"20893381255801015515826997628594359667013752732428989472914000440642900266717","best_ask":"0.43","best_bid":"0.42","hash":"9838f16dc2e8541e63e510523c92297a8dccea5b","price":"0.41","side":"BUY","size":"347.6"},{"asset_id":"39272994714739463168905443499424551362424437245880253267329605556587274644733","best_ask":"0.58","best_bid":"0.57","hash":"acea30e328dc3edc20c7fe6075d8cada073ef113","price":"0.59","side":"SELL","size":"347.6"}],"timestamp":"1785204134164"},"payload_hash":"140fbbbe5a8f9aa80b7827f305ab3d300981259a3562f73bf20da117bcd09df2","raw_frame":"{\"market\":\"0xda6f0e0e93fc8469e0159a166028d017bddbc162b86f66bac90391379603d962\", \"price_changes\":[{\"asset_id\":\"20893381255801015515826997628594359667013752732428989472914000440642900266717\", \"price\":\"0.41\", \"size\":\"347.6\", \"side\":\"BUY\", \"hash\":\"9838f16dc2e8541e63e510523c92297a8dccea5b\", \"best_bid\":\"0.42\", \"best_ask\":\"0.43\"}, {\"asset_id\":\"39272994714739463168905443499424551362424437245880253267329605556587274644733\", \"price\":\"0.59\", \"size\":\"347.6\", \"side\":\"SELL\", \"hash\":\"acea30e328dc3edc20c7fe6075d8cada073ef113\", \"best_bid\":\"0.57\", \"best_ask\":\"0.58\"}], \"timestamp\":\"1785204134164\", \"event_type\":\"price_change\"}","received_at":"2026-07-28T02:02:15.482019Z","schema_version":"clob-market-ws.price_change.v1","sequence":null,"server_hash":null,"server_timestamp":"1785204134164","session_id":"d2757dd6dad94f3b9fe67e8dbf1adc37","source":"clob_market_ws"},"received_at":"2026-07-28T02:02:15.482019Z","record_id":"29964b2bcebe5b86c8a785bc8c5c0f45b3fc734c56270b23c29e16887e86b132","schema_fingerprint":"4aa3821a28b0b7c2400bc59aba4bcc0a76e971dadd19610d3ad38c768e124dc7","schema_version":"edge-lab-recorder.raw.v1","sequence":null,"source":"clob_market_ws"}
{"event_at":"2026-07-28T02:02:14.164000Z","event_fingerprint":"e3a0ed28b2fce1170d9cd9c870606a353d3f7f3b64feea8eb947848912e3bf52","payload":{"connection_id":"5d29200f65794d4d9ab6ef271f045a9b","event_at":"2026-07-28T02:02:14.164000Z","event_type":"price_change","frame_hash":"12143bb3b4b4710a2280e61f8428d5f85d278582dc3852971cf213a2af79a7d3","frame_index":0,"kind":"data","monotonic_ns":306118492309625,"payload":{"event_type":"price_change","market":"0xda6f0e0e93fc8469e0159a166028d017bddbc162b86f66bac90391379603d962","price_changes":[{"asset_id":"39272994714739463168905443499424551362424437245880253267329605556587274644733","best_ask":"0.58","best_bid":"0.57","hash":"b84cd28d351858f48fd64323982b477c6fd50c53","price":"0.56","side":"BUY","size":"59.6"},{"asset_id":"20893381255801015515826997628594359667013752732428989472914000440642900266717","best_ask":"0.43","best_bid":"0.42","hash":"95a0784dd3addca927426cdcf23cfa4360bb9be4","price":"0.44","side":"SELL","size":"59.6"}],"timestamp":"1785204134164"},"payload_hash":"524f6c7862b348cdb389ea3d6cbd72871106c60e241d152dc56c75a569972a32","raw_frame":"{\"market\":\"0xda6f0e0e93fc8469e0159a166028d017bddbc162b86f66bac90391379603d962\", \"price_changes\":[{\"asset_id\":\"39272994714739463168905443499424551362424437245880253267329605556587274644733\", \"price\":\"0.56\", \"size\":\"59.6\", \"side\":\"BUY\", \"hash\":\"b84cd28d351858f48fd64323982b477c6fd50c53\", \"best_bid\":\"0.57\", \"best_ask\":\"0.58\"}, {\"asset_id\":\"20893381255801015515826997628594359667013752732428989472914000440642900266717\", \"price\":\"0.44\", \"size\":\"59.6\", \"side\":\"SELL\", \"hash\":\"95a0784dd3addca927426cdcf23cfa4360bb9be4\", \"best_bid\":\"0.42\", \"best_ask\":\"0.43\"}], \"timestamp\":\"1785204134164\", \"event_type\":\"price_change\"}","received_at":"2026-07-28T02:02:15.487918Z","schema_version":"clob-market-ws.price_change.v1","sequence":null,"server_hash":null,"server_timestamp":"1785204134164","session_id":"d2757dd6dad94f3b9fe67e8dbf1adc37","source":"clob_market_ws"},"received_at":"2026-07-28T02:02:15.487918Z","record_id":"27794ba61c5dbb6341a2c4da186039fb36612314a12a8f2bb83c78c8538549ee","schema_fingerprint":"4aa3821a28b0b7c2400bc59aba4bcc0a76e971dadd19610d3ad38c768e124dc7","schema_version":"edge-lab-recorder.raw.v1","sequence":null,"source":"clob_market_ws"}
{"event_at":"2026-07-28T02:02:14.164000Z","event_fingerprint":"d3a1d36f46a9eb29720d28e548c9fc0468d4284c0a5e52b72601d76254652bc2","payload":{"connection_id":"5d29200f65794d4d9ab6ef271f045a9b","event_at":"2026-07-28T02:02:14.164000Z","event_type":"price_change","frame_hash":"9d19dc244b3d68407109263f5b9a74e2a88b8c341cfeb54e18113c873989bf08","frame_index":0,"kind":"data","monotonic_ns":306118497601416,"payload":{"event_type":"price_change","market":"0xda6f0e0e93fc8469e0159a166028d017bddbc162b86f66bac90391379603d962","price_changes":[{"asset_id":"20893381255801015515826997628594359667013752732428989472914000440642900266717","best_ask":"0.43","best_bid":"0.42","hash":"fc84bb5d4c07a9ff422603f039f48f674b2e1d67","price":"0.42","side":"BUY","size":"410.2"},{"asset_id":"39272994714739463168905443499424551362424437245880253267329605556587274644733","best_ask":"0.58","best_bid":"0.57","hash":"6964f007baeb0da53f9d918178364bb35b422c65","price":"0.58","side":"SELL","size":"410.2"}],"timestamp":"1785204134164"},"payload_hash":"48c60b323f1fa6f10f35a00261f019ed71432e5df4bd8eeab53fa12d63f938f7","raw_frame":"{\"market\":\"0xda6f0e0e93fc8469e0159a166028d017bddbc162b86f66bac90391379603d962\", \"price_changes\":[{\"asset_id\":\"20893381255801015515826997628594359667013752732428989472914000440642900266717\", \"price\":\"0.42\", \"size\":\"410.2\", \"side\":\"BUY\", \"hash\":\"fc84bb5d4c07a9ff422603f039f48f674b2e1d67\", \"best_bid\":\"0.42\", \"best_ask\":\"0.43\"}, {\"asset_id\":\"39272994714739463168905443499424551362424437245880253267329605556587274644733\", \"price\":\"0.58\", \"size\":\"410.2\", \"side\":\"SELL\", \"hash\":\"6964f007baeb0da53f9d918178364bb35b422c65\", \"best_bid\":\"0.57\", \"best_ask\":\"0.58\"}], \"timestamp\":\"1785204134164\", \"event_type\":\"price_change\"}","received_at":"2026-07-28T02:02:15.493210Z","schema_version":"clob-market-ws.price_change.v1","sequence":null,"server_hash":null,"server_timestamp":"1785204134164","session_id":"d2757dd6dad94f3b9fe67e8dbf1adc37","source":"clob_market_ws"},"received_at":"2026-07-28T02:02:15.493210Z","record_id":"15c19920588a6b49b38469e7d634e53489b3d6c597756857fc2b4d327d0d8a07","schema_fingerprint":"4aa3821a28b0b7c2400bc59aba4bcc0a76e971dadd19610d3ad38c768e124dc7","schema_version":"edge-lab-recorder.raw.v1","sequence":null,"source":"clob_market_ws"}
{"event_at":"2026-07-28T02:02:14.167000Z","event_fingerprint":"d8f27e37b066c07b9e85ee620545632c5c1a5428e4647ddd427c281242378eb8","payload":{"connection_id":"5d29200f65794d4d9ab6ef271f045a9b","event_at":"2026-07-28T02:02:14.167000Z","event_type":"price_change","frame_hash":"eb20a62d5d25a59704a62f42ce75b78a96186fb72adce68790fb967cc6d053b8","frame_index":0,"kind":"data","monotonic_ns":306118501988875,"payload":{"event_type":"price_change","market":"0xda6f0e0e93fc8469e0159a166028d017bddbc162b86f66bac90391379603d962","price_changes":[{"asset_id":"39272994714739463168905443499424551362424437245880253267329605556587274644733","best_ask":"0.58","best_bid":"0.57","hash":"b0a777aff385b5ad6141616979dccee925584bf0","price":"0.55","side":"BUY","size":"370.67"},{"asset_id":"20893381255801015515826997628594359667013752732428989472914000440642900266717","best_ask":"0.43","best_bid":"0.42","hash":"5690b8942b6f8c899a6fb93c1bbbdc3216e2f8b1","price":"0.45","side":"SELL","size":"370.67"}],"timestamp":"1785204134167"},"payload_hash":"3e9bda9d757faee0920bec0badc1e3cc1d7266ffa324577bb6577dc678ff473a","raw_frame":"{\"market\":\"0xda6f0e0e93fc8469e0159a166028d017bddbc162b86f66bac90391379603d962\", \"price_changes\":[{\"asset_id\":\"39272994714739463168905443499424551362424437245880253267329605556587274644733\", \"price\":\"0.55\", \"size\":\"370.67\", \"side\":\"BUY\", \"hash\":\"b0a777aff385b5ad6141616979dccee925584bf0\", \"best_bid\":\"0.57\", \"best_ask\":\"0.58\"}, {\"asset_id\":\"20893381255801015515826997628594359667013752732428989472914000440642900266717\", \"price\":\"0.45\", \"size\":\"370.67\", \"side\":\"SELL\", \"hash\":\"5690b8942b6f8c899a6fb93c1bbbdc3216e2f8b1\", \"best_bid\":\"0.42\", \"best_ask\":\"0.43\"}], \"timestamp\":\"1785204134167\", \"event_type\":\"price_change\"}","received_at":"2026-07-28T02:02:15.497597Z","schema_version":"clob-market-ws.price_change.v1","sequence":null,"server_hash":null,"server_timestamp":"1785204134167","session_id":"d2757dd6dad94f3b9fe67e8dbf1adc37","source":"clob_market_ws"},"received_at":"2026-07-28T02:02:15.497597Z","record_id":"28ee09754aa67230279b0d31490d5485fcd70a3832a43e455e52b8e55a4fb7ee","schema_fingerprint":"4aa3821a28b0b7c2400bc59aba4bcc0a76e971dadd19610d3ad38c768e124dc7","schema_version":"edge-lab-recorder.raw.v1","sequence":null,"source":"clob_market_ws"}
{"event_at":"2026-07-28T02:02:14.168000Z","event_fingerprint":"cf542a2e878898b8a337bca1ca84eec6ad58490256bcd7d6b3fa0cee07f6b11a","payload":{"connection_id":"5d29200f65794d4d9ab6ef271f045a9b","event_at":"2026-07-28T02:02:14.168000Z","event_type":"price_change","frame_hash":"6ce0f6dcb6a09b7dd711067c8374b0c0e6e5b5a779774f93de003b2f4020078d","frame_index":0,"kind":"data","monotonic_ns":306118507023458,"payload":{"event_type":"price_change","market":"0xda6f0e0e93fc8469e0159a166028d017bddbc162b86f66bac90391379603d962","price_changes":[{"asset_id":"20893381255801015515826997628594359667013752732428989472914000440642900266717","best_ask":"0.43","best_bid":"0.42","hash":"dd28a411fcb8ed42150ebbf8e1b0348f06984099","price":"0.02","side":"BUY","size":"723.1"},{"asset_id":"39272994714739463168905443499424551362424437245880253267329605556587274644733","best_ask":"0.58","best_bid":"0.57","hash":"a823ebfa2f99acd0ba105294fb5e16cf4ffe31c1","price":"0.98","side":"SELL","size":"723.1"}],"timestamp":"1785204134168"},"payload_hash":"d9d686208a2be5650e10f166c1e38c99bf817221ea6518a21cd3ea3a1f2619b8","raw_frame":"{\"market\":\"0xda6f0e0e93fc8469e0159a166028d017bddbc162b86f66bac90391379603d962\", \"price_changes\":[{\"asset_id\":\"20893381255801015515826997628594359667013752732428989472914000440642900266717\", \"price\":\"0.02\", \"size\":\"723.1\", \"side\":\"BUY\", \"hash\":\"dd28a411fcb8ed42150ebbf8e1b0348f06984099\", \"best_bid\":\"0.42\", \"best_ask\":\"0.43\"}, {\"asset_id\":\"39272994714739463168905443499424551362424437245880253267329605556587274644733\", \"price\":\"0.98\", \"size\":\"723.1\", \"side\":\"SELL\", \"hash\":\"a823ebfa2f99acd0ba105294fb5e16cf4ffe31c1\", \"best_bid\":\"0.57\", \"best_ask\":\"0.58\"}], \"timestamp\":\"1785204134168\", \"event_type\":\"price_change\"}","received_at":"2026-07-28T02:02:15.502632Z","schema_version":"clob-market-ws.price_change.v1","sequence":null,"server_hash":null,"server_timestamp":"1785204134168","session_id":"d2757dd6dad94f3b9fe67e8dbf1adc37","source":"clob_market_ws"},"received_at":"2026-07-28T02:02:15.502632Z","record_id":"fa4b5bd7a500fdc0e3060fa1c461796b737206caa74e5fd3ab77f0ffc8d60c60","schema_fingerprint":"4aa3821a28b0b7c2400bc59aba4bcc0a76e971dadd19610d3ad38c768e124dc7","schema_version":"edge-lab-recorder.raw.v1","sequence":null,"source":"clob_market_ws"}
{"event_at":"2026-07-28T02:02:14.168000Z","event_fingerprint":"a7b8c37d4a151958d4fc8857526862c6ec52390473a5f8d80cd9f883176a7bbe","payload":{"connection_id":"5d29200f65794d4d9ab6ef271f045a9b","event_at":"2026-07-28T02:02:14.168000Z","event_type":"price_change","frame_hash":"4c8c8e881c82614ebe630c78a26e6223836d08ec40e0ddc212e2545dbb2598a5","frame_index":0,"kind":"data","monotonic_ns":306118513488875,"payload":{"event_type":"price_change","market":"0xda6f0e0e93fc8469e0159a166028d017bddbc162b86f66bac90391379603d962","price_changes":[{"asset_id":"39272994714739463168905443499424551362424437245880253267329605556587274644733","best_ask":"0.58","best_bid":"0.57","hash":"a823ebfa2f99acd0ba105294fb5e16cf4ffe31c1","price":"0.1","side":"BUY","size":"128.29"},{"asset_id":"20893381255801015515826997628594359667013752732428989472914000440642900266717","best_ask":"0.43","best_bid":"0.42","hash":"dd28a411fcb8ed42150ebbf8e1b0348f06984099","price":"0.9","side":"SELL","size":"128.29"}],"timestamp":"1785204134168"},"payload_hash":"8708c58775021e379614bf135f0e4a130c0eec0fa2dbfc108b4a4cff319203c1","raw_frame":"{\"market\":\"0xda6f0e0e93fc8469e0159a166028d017bddbc162b86f66bac90391379603d962\", \"price_changes\":[{\"asset_id\":\"39272994714739463168905443499424551362424437245880253267329605556587274644733\", \"price\":\"0.1\", \"size\":\"128.29\", \"side\":\"BUY\", \"hash\":\"a823ebfa2f99acd0ba105294fb5e16cf4ffe31c1\", \"best_bid\":\"0.57\", \"best_ask\":\"0.58\"}, {\"asset_id\":\"20893381255801015515826997628594359667013752732428989472914000440642900266717\", \"price\":\"0.9\", \"size\":\"128.29\", \"side\":\"SELL\", \"hash\":\"dd28a411fcb8ed42150ebbf8e1b0348f06984099\", \"best_bid\":\"0.42\", \"best_ask\":\"0.43\"}], \"timestamp\":\"1785204134168\", \"event_type\":\"price_change\"}","received_at":"2026-07-28T02:02:15.509097Z","schema_version":"clob-market-ws.price_change.v1","sequence":null,"server_hash":null,"server_timestamp":"1785204134168","session_id":"d2757dd6dad94f3b9fe67e8dbf1adc37","source":"clob_market_ws"},"received_at":"2026-07-28T02:02:15.509097Z","record_id":"5fd0d447d34c427e673b096048fbe396996fa000731e026d2d382f4518bdc908","schema_fingerprint":"4aa3821a28b0b7c2400bc59aba4bcc0a76e971dadd19610d3ad38c768e124dc7","schema_version":"edge-lab-recorder.raw.v1","sequence":null,"source":"clob_market_ws"}
{"event_at":"2026-07-28T02:02:14.172000Z","event_fingerprint":"9b5df297acefa8f19c0593c5f9c680c371c8e193b7d5d78cfaad38f7842086bc","payload":{"connection_id":"5d29200f65794d4d9ab6ef271f045a9b","event_at":"2026-07-28T02:02:14.172000Z","event_type":"price_change","frame_hash":"7d7e5c76ee289abc94653e27f7451e725397086d0dcc46aa1e63324875635b4f","frame_index":0,"kind":"data","monotonic_ns":306118520139958,"payload":{"event_type":"price_change","market":"0xda6f0e0e93fc8469e0159a166028d017bddbc162b86f66bac90391379603d962","price_changes":[{"asset_id":"20893381255801015515826997628594359667013752732428989472914000440642900266717","best_ask":"0.43","best_bid":"0.42","hash":"79e46c418348f04030b9d66f7aeaf150914996ae","price":"0.41","side":"BUY","size":"77.6"},{"asset_id":"39272994714739463168905443499424551362424437245880253267329605556587274644733","best_ask":"0.58","best_bid":"0.57","hash":"c9a44ac1b7508f96e4d8ee98f018cbf3c4edc5ab","price":"0.59","side":"SELL","size":"77.6"}],"timestamp":"1785204134172"},"payload_hash":"48b66d5347e293d6dc1544381f965c568672d39bbe1294c6b4eedcaffe2068db","raw_frame":"{\"market\":\"0xda6f0e0e93fc8469e0159a166028d017bddbc162b86f66bac90391379603d962\", \"price_changes\":[{\"asset_id\":\"20893381255801015515826997628594359667013752732428989472914000440642900266717\", \"price\":\"0.41\", \"size\":\"77.6\", \"side\":\"BUY\", \"hash\":\"79e46c418348f04030b9d66f7aeaf150914996ae\", \"best_bid\":\"0.42\", \"best_ask\":\"0.43\"}, {\"asset_id\":\"39272994714739463168905443499424551362424437245880253267329605556587274644733\", \"price\":\"0.59\", \"size\":\"77.6\", \"side\":\"SELL\", \"hash\":\"c9a44ac1b7508f96e4d8ee98f018cbf3c4edc5ab\", \"best_bid\":\"0.57\", \"best_ask\":\"0.58\"}], \"timestamp\":\"1785204134172\", \"event_type\":\"price_change\"}","received_at":"2026-07-28T02:02:15.515748Z","schema_version":"clob-market-ws.price_change.v1","sequence":null,"server_hash":null,"server_timestamp":"1785204134172","session_id":"d2757dd6dad94f3b9fe67e8dbf1adc37","source":"clob_market_ws"},"received_at":"2026-07-28T02:02:15.515748Z","record_id":"dbc14d72e5a676834dc0bf12894b05fcffeaab42c26b40dc964bfb8c4a368887","schema_fingerprint":"4aa3821a28b0b7c2400bc59aba4bcc0a76e971dadd19610d3ad38c768e124dc7","schema_version":"edge-lab-recorder.raw.v1","sequence":null,"source":"clob_market_ws"}
{"event_at":"2026-07-28T02:02:14.172000Z","event_fingerprint":"5781438ee2ee3c5326d2a958d30b4ee79fc0ab04582fc034683e767307a01b9a","payload":{"connection_id":"5d29200f65794d4d9ab6ef271f045a9b","event_at":"2026-07-28T02:02:14.172000Z","event_type":"price_change","frame_hash":"c8804a3a9d7d0b229713020ae47f6e3a4e870a619468395ab22624a1152e8498","frame_index":0,"kind":"data","monotonic_ns":306118526070958,"payload":{"event_type":"price_change","market":"0xda6f0e0e93fc8469e0159a166028d017bddbc162b86f66bac90391379603d962","price_changes":[{"asset_id":"39272994714739463168905443499424551362424437245880253267329605556587274644733","best_ask":"0.58","best_bid":"0.57","hash":"c9a44ac1b7508f96e4d8ee98f018cbf3c4edc5ab","price":"0.55","side":"BUY","size":"100.67"},{"asset_id":"20893381255801015515826997628594359667013752732428989472914000440642900266717","best_ask":"0.43","best_bid":"0.42","hash":"79e46c418348f04030b9d66f7aeaf150914996ae","price":"0.45","side":"SELL","size":"100.67"}],"timestamp":"1785204134172"},"payload_hash":"30855e35f5e0667663861bf95be267ffb9cdc4004027bcbdcdcafddaf768a394","raw_frame":"{\"market\":\"0xda6f0e0e93fc8469e0159a166028d017bddbc162b86f66bac90391379603d962\", \"price_changes\":[{\"asset_id\":\"39272994714739463168905443499424551362424437245880253267329605556587274644733\", \"price\":\"0.55\", \"size\":\"100.67\", \"side\":\"BUY\", \"hash\":\"c9a44ac1b7508f96e4d8ee98f018cbf3c4edc5ab\", \"best_bid\":\"0.57\", \"best_ask\":\"0.58\"}, {\"asset_id\":\"20893381255801015515826997628594359667013752732428989472914000440642900266717\", \"price\":\"0.45\", \"size\":\"100.67\", \"side\":\"SELL\", \"hash\":\"79e46c418348f04030b9d66f7aeaf150914996ae\", \"best_bid\":\"0.42\", \"best_ask\":\"0.43\"}], \"timestamp\":\"1785204134172\", \"event_type\":\"price_change\"}","received_at":"2026-07-28T02:02:15.521679Z","schema_version":"clob-market-ws.price_change.v1","sequence":null,"server_hash":null,"server_timestamp":"1785204134172","session_id":"d2757dd6dad94f3b9fe67e8dbf1adc37","source":"clob_market_ws"},"received_at":"2026-07-28T02:02:15.521679Z","record_id":"1c709c052c55951a8e8959005b11e67ef81578e1df53a2320af3d07e9d0fc8bc","schema_fingerprint":"4aa3821a28b0b7c2400bc59aba4bcc0a76e971dadd19610d3ad38c768e124dc7","schema_version":"edge-lab-recorder.raw.v1","sequence":null,"source":"clob_market_ws"}
{"event_at":"2026-07-28T02:02:14.173000Z","event_fingerprint":"b4d8b102d58c0992701b047a8e61abcacc8894a124c182f7714f53b2c0c583a0","payload":{"connection_id":"5d29200f65794d4d9ab6ef271f045a9b","event_at":"2026-07-28T02:02:14.173000Z","event_type":"price_change","frame_hash":"ac0c6092747efce6ca993cd77d38472523dcd057a464d5189f96b136b10549ed","frame_index":0,"kind":"data","monotonic_ns":306118532634625,"payload":{"event_type":"price_change","market":"0xda6f0e0e93fc8469e0159a166028d017bddbc162b86f66bac90391379603d962","price_changes":[{"asset_id":"39272994714739463168905443499424551362424437245880253267329605556587274644733","best_ask":"0.58","best_bid":"0.57","hash":"446db4c6015106e45743de5d07ac463d2bda1c1c","price":"0.56","side":"BUY","size":"47"},{"asset_id":"20893381255801015515826997628594359667013752732428989472914000440642900266717","best_ask":"0.43","best_bid":"0.42","hash":"0ba2cb1a345c176340ef3cab3d2cb218b8b0f328","price":"0.44","side":"SELL","size":"47"}],"timestamp":"1785204134173"},"payload_hash":"d79732facdc788bf136ec7a318f57f5a447e46f7d337f8fd20fb22ebdb1fd376","raw_frame":"{\"market\":\"0xda6f0e0e93fc8469e0159a166028d017bddbc162b86f66bac90391379603d962\", \"price_changes\":[{\"asset_id\":\"39272994714739463168905443499424551362424437245880253267329605556587274644733\", \"price\":\"0.56\", \"size\":\"47\", \"side\":\"BUY\", \"hash\":\"446db4c6015106e45743de5d07ac463d2bda1c1c\", \"best_bid\":\"0.57\", \"best_ask\":\"0.58\"}, {\"asset_id\":\"20893381255801015515826997628594359667013752732428989472914000440642900266717\", \"price\":\"0.44\", \"size\":\"47\", \"side\":\"SELL\", \"hash\":\"0ba2cb1a345c176340ef3cab3d2cb218b8b0f328\", \"best_bid\":\"0.42\", \"best_ask\":\"0.43\"}], \"timestamp\":\"1785204134173\", \"event_type\":\"price_change\"}","received_at":"2026-07-28T02:02:15.528243Z","schema_version":"clob-market-ws.price_change.v1","sequence":null,"server_hash":null,"server_timestamp":"1785204134173","session_id":"d2757dd6dad94f3b9fe67e8dbf1adc37","source":"clob_market_ws"},"received_at":"2026-07-28T02:02:15.528243Z","record_id":"d203e8e22b1bf3c3cda07398648a72afa811b22b9f0669e2e15c20cbcb3d13dc","schema_fingerprint":"4aa3821a28b0b7c2400bc59aba4bcc0a76e971dadd19610d3ad38c768e124dc7","schema_version":"edge-lab-recorder.raw.v1","sequence":null,"source":"clob_market_ws"}
{"event_at":"2026-07-28T02:02:14.174000Z","event_fingerprint":"084c6bb94eddb96b094290e90254357cb6f22b33ec5c6cca889acb582b82f2eb","payload":{"connection_id":"5d29200f65794d4d9ab6ef271f045a9b","event_at":"2026-07-28T02:02:14.174000Z","event_type":"price_change","frame_hash":"dc5d61d573b683533136e45d4e8b5b061a57ecb5e4aa8eaf368350b0c812ea07","frame_index":0,"kind":"data","monotonic_ns":306118538523166,"payload":{"event_type":"price_change","market":"0xda6f0e0e93fc8469e0159a166028d017bddbc162b86f66bac90391379603d962","price_changes":[{"asset_id":"39272994714739463168905443499424551362424437245880253267329605556587274644733","best_ask":"0.58","best_bid":"0.57","hash":"9c03d1b226520915e6b77409df80961c3f6d1282","price":"0.45","side":"BUY","size":"186.5"},{"asset_id":"20893381255801015515826997628594359667013752732428989472914000440642900266717","best_ask":"0.43","best_bid":"0.42","hash":"e6916d0449e608e99cc62a74dec1958e358dc590","price":"0.55","side":"SELL","size":"186.5"}],"timestamp":"1785204134174"},"payload_hash":"34932efc278540ac06a89722c52828aeea494f078532ed33dc22bcbd17dc38cd","raw_frame":"{\"market\":\"0xda6f0e0e93fc8469e0159a166028d017bddbc162b86f66bac90391379603d962\", \"price_changes\":[{\"asset_id\":\"39272994714739463168905443499424551362424437245880253267329605556587274644733\", \"price\":\"0.45\", \"size\":\"186.5\", \"side\":\"BUY\", \"hash\":\"9c03d1b226520915e6b77409df80961c3f6d1282\", \"best_bid\":\"0.57\", \"best_ask\":\"0.58\"}, {\"asset_id\":\"20893381255801015515826997628594359667013752732428989472914000440642900266717\", \"price\":\"0.55\", \"size\":\"186.5\", \"side\":\"SELL\", \"hash\":\"e6916d0449e608e99cc62a74dec1958e358dc590\", \"best_bid\":\"0.42\", \"best_ask\":\"0.43\"}], \"timestamp\":\"1785204134174\", \"event_type\":\"price_change\"}","received_at":"2026-07-28T02:02:15.534131Z","schema_version":"clob-market-ws.price_change.v1","sequence":null,"server_hash":null,"server_timestamp":"1785204134174","session_id":"d2757dd6dad94f3b9fe67e8dbf1adc37","source":"clob_market_ws"},"received_at":"2026-07-28T02:02:15.534131Z","record_id":"b4900f387f36713aaec21015478ba1a95cbae39de7ca6b2f1b9f6df8fd66211c","schema_fingerprint":"4aa3821a28b0b7c2400bc59aba4bcc0a76e971dadd19610d3ad38c768e124dc7","schema_version":"edge-lab-recorder.raw.v1","sequence":null,"source":"clob_market_ws"}
{"event_at":"2026-07-28T02:02:14.175000Z","event_fingerprint":"cebfb16b4cdb67c08087ea89de59cbb4db6cf8525dabb48778334483c6b55af2","payload":{"connection_id":"5d29200f65794d4d9ab6ef271f045a9b","event_at":"2026-07-28T02:02:14.175000Z","event_type":"price_change","frame_hash":"5b9b24908f1faea4aa5e410437a67518d089f00943a981b1f5127187000e6475","frame_index":0,"kind":"data","monotonic_ns":306118542894041,"payload":{"event_type":"price_change","market":"0xda6f0e0e93fc8469e0159a166028d017bddbc162b86f66bac90391379603d962","price_changes":[{"asset_id":"39272994714739463168905443499424551362424437245880253267329605556587274644733","best_ask":"0.58","best_bid":"0.57","hash":"93b60def45cb1c48a7b533cc2944aebfe429ad37","price":"0.43","side":"BUY","size":"214.02"},{"asset_id":"20893381255801015515826997628594359667013752732428989472914000440642900266717","best_ask":"0.43","best_bid":"0.42","hash":"755c483967177a73245aa434ded907cf1cedd74b","price":"0.57","side":"SELL","size":"214.02"}],"timestamp":"1785204134175"},"payload_hash":"65d742952d026d299bb799af4cc66956665f52bd740be7739120ae3e3aaed34a","raw_frame":"{\"market\":\"0xda6f0e0e93fc8469e0159a166028d017bddbc162b86f66bac90391379603d962\", \"price_changes\":[{\"asset_id\":\"39272994714739463168905443499424551362424437245880253267329605556587274644733\", \"price\":\"0.43\", \"size\":\"214.02\", \"side\":\"BUY\", \"hash\":\"93b60def45cb1c48a7b533cc2944aebfe429ad37\", \"best_bid\":\"0.57\", \"best_ask\":\"0.58\"}, {\"asset_id\":\"20893381255801015515826997628594359667013752732428989472914000440642900266717\", \"price\":\"0.57\", \"size\":\"214.02\", \"side\":\"SELL\", \"hash\":\"755c483967177a73245aa434ded907cf1cedd74b\", \"best_bid\":\"0.42\", \"best_ask\":\"0.43\"}], \"timestamp\":\"1785204134175\", \"event_type\":\"price_change\"}","received_at":"2026-07-28T02:02:15.538502Z","schema_version":"clob-market-ws.price_change.v1","sequence":null,"server_hash":null,"server_timestamp":"1785204134175","session_id":"d2757dd6dad94f3b9fe67e8dbf1adc37","source":"clob_market_ws"},"received_at":"2026-07-28T02:02:15.538502Z","record_id":"e3a706986afee9da8c689e64231383119ce0acd2ae96f23f9260737a0ab0324b","schema_fingerprint":"4aa3821a28b0b7c2400bc59aba4bcc0a76e971dadd19610d3ad38c768e124dc7","schema_version":"edge-lab-recorder.raw.v1","sequence":null,"source":"clob_market_ws"}
{"event_at":"2026-07-28T02:02:14.179000Z","event_fingerprint":"47eedcd78ddc9caf142a11c500431032ffa3638b482b01457d9f1984b6f1484b","payload":{"connection_id":"5d29200f65794d4d9ab6ef271f045a9b","event_at":"2026-07-28T02:02:14.179000Z","event_type":"price_change","frame_hash":"c795b37e9c2b5dbeb88f8d6af00bc556f90d81c4d7c91fcf0822cb3f69c7556a","frame_index":0,"kind":"data","monotonic_ns":306118548109041,"payload":{"event_type":"price_change","market":"0xda6f0e0e93fc8469e0159a166028d017bddbc162b86f66bac90391379603d962","price_changes":[{"asset_id":"39272994714739463168905443499424551362424437245880253267329605556587274644733","best_ask":"0.58","best_bid":"0.57","hash":"1eb0ad5ff5d9ddf15bd27ceb86606813c09e9cfc","price":"0.02","side":"BUY","size":"733.1"},{"asset_id":"20893381255801015515826997628594359667013752732428989472914000440642900266717","best_ask":"0.43","best_bid":"0.42","hash":"92ea55605ef8995f1e69bb5532aa5bba8c3290f8","price":"0.98","side":"SELL","size":"733.1"}],"timestamp":"1785204134179"},"payload_hash":"53e33fdcc9db5f2af301cf9c2bcf96aa92838370cb696926569075b7ed62ea19","raw_frame":"{\"market\":\"0xda6f0e0e93fc8469e0159a166028d017bddbc162b86f66bac90391379603d962\", \"price_changes\":[{\"asset_id\":\"39272994714739463168905443499424551362424437245880253267329605556587274644733\", \"price\":\"0.02\", \"size\":\"733.1\", \"side\":\"BUY\", \"hash\":\"1eb0ad5ff5d9ddf15bd27ceb86606813c09e9cfc\", \"best_bid\":\"0.57\", \"best_ask\":\"0.58\"}, {\"asset_id\":\"20893381255801015515826997628594359667013752732428989472914000440642900266717\", \"price\":\"0.98\", \"size\":\"733.1\", \"side\":\"SELL\", \"hash\":\"92ea55605ef8995f1e69bb5532aa5bba8c3290f8\", \"best_bid\":\"0.42\", \"best_ask\":\"0.43\"}], \"timestamp\":\"1785204134179\", \"event_type\":\"price_change\"}","received_at":"2026-07-28T02:02:15.543716Z","schema_version":"clob-market-ws.price_change.v1","sequence":null,"server_hash":null,"server_timestamp":"1785204134179","session_id":"d2757dd6dad94f3b9fe67e8dbf1adc37","source":"clob_market_ws"},"received_at":"2026-07-28T02:02:15.543716Z","record_id":"4b6353a324cf7376458911564fad86d610c84ddb41f787ca288e379eacd60e2a","schema_fingerprint":"4aa3821a28b0b7c2400bc59aba4bcc0a76e971dadd19610d3ad38c768e124dc7","schema_version":"edge-lab-recorder.raw.v1","sequence":null,"source":"clob_market_ws"}
{"event_at":"2026-07-28T02:02:14.185000Z","event_fingerprint":"a57489af3ea50926d1af751bbaf43c12ae2ef01e6ba777b652602a3a8d19e06a","payload":{"connection_id":"5d29200f65794d4d9ab6ef271f045a9b","event_at":"2026-07-28T02:02:14.185000Z","event_type":"price_change","frame_hash":"3efa49caa59ccf128e1a78360a1f84568bc3f5c74f9c407e9e2f8ad3e7bd0893","frame_index":0,"kind":"data","monotonic_ns":306118557704875,"payload":{"event_type":"price_change","market":"0xda6f0e0e93fc8469e0159a166028d017bddbc162b86f66bac90391379603d962","price_changes":[{"asset_id":"39272994714739463168905443499424551362424437245880253267329605556587274644733","best_ask":"0.58","best_bid":"0.57","hash":"c2df87f50f2898d779f779c52a8e20ff28f5466e","price":"0.57","side":"BUY","size":"5"},{"asset_id":"20893381255801015515826997628594359667013752732428989472914000440642900266717","best_ask":"0.43","best_bid":"0.42","hash":"6429ab96c672e6eede8ff277130d6af5216a2f70","price":"0.43","side":"SELL","size":"5"}],"timestamp":"1785204134185"},"payload_hash":"413843e67eb4cce6ef2ef1c7cf69596a7429a238c3656fc6f1cedbcc6da02f20","raw_frame":"{\"market\":\"0xda6f0e0e93fc8469e0159a166028d017bddbc162b86f66bac90391379603d962\", \"price_changes\":[{\"asset_id\":\"39272994714739463168905443499424551362424437245880253267329605556587274644733\", \"price\":\"0.57\", \"size\":\"5\", \"side\":\"BUY\", \"hash\":\"c2df87f50f2898d779f779c52a8e20ff28f5466e\", \"best_bid\":\"0.57\", \"best_ask\":\"0.58\"}, {\"asset_id\":\"20893381255801015515826997628594359667013752732428989472914000440642900266717\", \"price\":\"0.43\", \"size\":\"5\", \"side\":\"SELL\", \"hash\":\"6429ab96c672e6eede8ff277130d6af5216a2f70\", \"best_bid\":\"0.42\", \"best_ask\":\"0.43\"}], \"timestamp\":\"1785204134185\", \"event_type\":\"price_change\"}","received_at":"2026-07-28T02:02:15.553312Z","schema_version":"clob-market-ws.price_change.v1","sequence":null,"server_hash":null,"server_timestamp":"1785204134185","session_id":"d2757dd6dad94f3b9fe67e8dbf1adc37","source":"clob_market_ws"},"received_at":"2026-07-28T02:02:15.553312Z","record_id":"33bedc7f80ee76149dd55a2c08985f2e99dd8ca9d349d176d85b75e57514b0fc","schema_fingerprint":"4aa3821a28b0b7c2400bc59aba4bcc0a76e971dadd19610d3ad38c768e124dc7","schema_version":"edge-lab-recorder.raw.v1","sequence":null,"source":"clob_market_ws"}
{"event_at":"2026-07-28T02:02:14.190000Z","event_fingerprint":"431579df2a23c876b84dc783878947f780df863198c6c3ff4acc8ec3be905b73","payload":{"connection_id":"5d29200f65794d4d9ab6ef271f045a9b","event_at":"2026-07-28T02:02:14.190000Z","event_type":"price_change","frame_hash":"82487e29c21da4af5cddb5b78dff19bf9e80f6863be13d017b052dd737935423","frame_index":0,"kind":"data","monotonic_ns":306118564213625,"payload":{"event_type":"price_change","market":"0xda6f0e0e93fc8469e0159a166028d017bddbc162b86f66bac90391379603d962","price_changes":[{"asset_id":"39272994714739463168905443499424551362424437245880253267329605556587274644733","best_ask":"0.58","best_bid":"0.57","hash":"13ab9b3e14b8847836641c8d5879e2e0f76b9917","price":"0.47","side":"BUY","size":"192"},{"asset_id":"20893381255801015515826997628594359667013752732428989472914000440642900266717","best_ask":"0.43","best_bid":"0.42","hash":"a4c5af1e54319f4a29ed27004b886b9997fcf0e5","price":"0.53","side":"SELL","size":"192"}],"timestamp":"1785204134190"},"payload_hash":"a65b43189d3a86dff4c74502a620dc93b87a58b560ba11bb7fe53758472f22f9","raw_frame":"{\"market\":\"0xda6f0e0e93fc8469e0159a166028d017bddbc162b86f66bac90391379603d962\", \"price_changes\":[{\"asset_id\":\"39272994714739463168905443499424551362424437245880253267329605556587274644733\", \"price\":\"0.47\", \"size\":\"192\", \"side\":\"BUY\", \"hash\":\"13ab9b3e14b8847836641c8d5879e2e0f76b9917\", \"best_bid\":\"0.57\", \"best_ask\":\"0.58\"}, {\"asset_id\":\"20893381255801015515826997628594359667013752732428989472914000440642900266717\", \"price\":\"0.53\", \"size\":\"192\", \"side\":\"SELL\", \"hash\":\"a4c5af1e54319f4a29ed27004b886b9997fcf0e5\", \"best_bid\":\"0.42\", \"best_ask\":\"0.43\"}], \"timestamp\":\"1785204134190\", \"event_type\":\"price_change\"}","received_at":"2026-07-28T02:02:15.559820Z","schema_version":"clob-market-ws.price_change.v1","sequence":null,"server_hash":null,"server_timestamp":"1785204134190","session_id":"d2757dd6dad94f3b9fe67e8dbf1adc37","source":"clob_market_ws"},"received_at":"2026-07-28T02:02:15.559820Z","record_id":"acca3cd4a7ee29f80e803e920320625c7f93db66b881453c3e0736e5d8e0f5d7","schema_fingerprint":"4aa3821a28b0b7c2400bc59aba4bcc0a76e971dadd19610d3ad38c768e124dc7","schema_version":"edge-lab-recorder.raw.v1","sequence":null,"source":"clob_market_ws"}
{"event_at":"2026-07-28T02:02:14.191000Z","event_fingerprint":"363cb1f1c3a35aefc93842ac366c46d0f96abde0a9c02e4cb6105f8609250bc1","payload":{"connection_id":"5d29200f65794d4d9ab6ef271f045a9b","event_at":"2026-07-28T02:02:14.191000Z","event_type":"price_change","frame_hash":"803a2600b80a5ec39dbf84324273ddb8d4af5478cdf4caf7ea349ffe176c1e0d","frame_index":0,"kind":"data","monotonic_ns":306118569514958,"payload":{"event_type":"price_change","market":"0xda6f0e0e93fc8469e0159a166028d017bddbc162b86f66bac90391379603d962","price_changes":[{"asset_id":"39272994714739463168905443499424551362424437245880253267329605556587274644733","best_ask":"0.58","best_bid":"0.57","hash":"1fbf70f609befa8207b2997774cc589bba78bb31","price":"0.52","side":"BUY","size":"169"},{"asset_id":"20893381255801015515826997628594359667013752732428989472914000440642900266717","best_ask":"0.43","best_bid":"0.42","hash":"658af80438696617e0b09ecf634493a0ca8ca9b8","price":"0.48","side":"SELL","size":"169"}],"timestamp":"1785204134191"},"payload_hash":"7a8cb3d8b02b22c5bbbd205280e33d0c9cb28ac01cfc52f591a266f1a1d58daf","raw_frame":"{\"market\":\"0xda6f0e0e93fc8469e0159a166028d017bddbc162b86f66bac90391379603d962\", \"price_changes\":[{\"asset_id\":\"39272994714739463168905443499424551362424437245880253267329605556587274644733\", \"price\":\"0.52\", \"size\":\"169\", \"side\":\"BUY\", \"hash\":\"1fbf70f609befa8207b2997774cc589bba78bb31\", \"best_bid\":\"0.57\", \"best_ask\":\"0.58\"}, {\"asset_id\":\"20893381255801015515826997628594359667013752732428989472914000440642900266717\", \"price\":\"0.48\", \"size\":\"169\", \"side\":\"SELL\", \"hash\":\"658af80438696617e0b09ecf634493a0ca8ca9b8\", \"best_bid\":\"0.42\", \"best_ask\":\"0.43\"}], \"timestamp\":\"1785204134191\", \"event_type\":\"price_change\"}","received_at":"2026-07-28T02:02:15.565122Z","schema_version":"clob-market-ws.price_change.v1","sequence":null,"server_hash":null,"server_timestamp":"1785204134191","session_id":"d2757dd6dad94f3b9fe67e8dbf1adc37","source":"clob_market_ws"},"received_at":"2026-07-28T02:02:15.565122Z","record_id":"1e47841bf3889b7d585194ee5fd178e63c4e5476007756631abcac307d4213e9","schema_fingerprint":"4aa3821a28b0b7c2400bc59aba4bcc0a76e971dadd19610d3ad38c768e124dc7","schema_version":"edge-lab-recorder.raw.v1","sequence":null,"source":"clob_market_ws"}
{"event_at":"2026-07-28T02:02:14.192000Z","event_fingerprint":"086143c37ff0fd00ff44979af1045b744913a1ab78f05f28bccb91303f71ee76","payload":{"connection_id":"5d29200f65794d4d9ab6ef271f045a9b","event_at":"2026-07-28T02:02:14.192000Z","event_type":"price_change","frame_hash":"8a0ccbf2d7f0351b2afd10a9a81718fd3e7524c48fd285fadc1d3b6d4e80958e","frame_index":0,"kind":"data","monotonic_ns":306118575726041,"payload":{"event_type":"price_change","market":"0xda6f0e0e93fc8469e0159a166028d017bddbc162b86f66bac90391379603d962","price_changes":[{"asset_id":"39272994714739463168905443499424551362424437245880253267329605556587274644733","best_ask":"0.58","best_bid":"0.57","hash":"76cc996c0f37f12f601eeebfa8d95d75ed84e9a8","price":"0.53","side":"BUY","size":"130.03"},{"asset_id":"20893381255801015515826997628594359667013752732428989472914000440642900266717","best_ask":"0.43","best_bid":"0.42","hash":"6c5739943aca1fcfdb6c9e2c1bcb744a6fc3ffa9","price":"0.47","side":"SELL","size":"130.03"}],"timestamp":"1785204134192"},"payload_hash":"f2c4ef7b0218f88fe5e9c239a37a8d457f5eaf4d0fd652cf09e65e7372e3843e","raw_frame":"{\"market\":\"0xda6f0e0e93fc8469e0159a166028d017bddbc162b86f66bac90391379603d962\", \"price_changes\":[{\"asset_id\":\"39272994714739463168905443499424551362424437245880253267329605556587274644733\", \"price\":\"0.53\", \"size\":\"130.03\", \"side\":\"BUY\", \"hash\":\"76cc996c0f37f12f601eeebfa8d95d75ed84e9a8\", \"best_bid\":\"0.57\", \"best_ask\":\"0.58\"}, {\"asset_id\":\"20893381255801015515826997628594359667013752732428989472914000440642900266717\", \"price\":\"0.47\", \"size\":\"130.03\", \"side\":\"SELL\", \"hash\":\"6c5739943aca1fcfdb6c9e2c1bcb744a6fc3ffa9\", \"best_bid\":\"0.42\", \"best_ask\":\"0.43\"}], \"timestamp\":\"1785204134192\", \"event_type\":\"price_change\"}","received_at":"2026-07-28T02:02:15.571332Z","schema_version":"clob-market-ws.price_change.v1","sequence":null,"server_hash":null,"server_timestamp":"1785204134192","session_id":"d2757dd6dad94f3b9fe67e8dbf1adc37","source":"clob_market_ws"},"received_at":"2026-07-28T02:02:15.571332Z","record_id":"49f0ba5a117f30d357849148340fe5d0653c1698e0406fc27e4fa50ee50fbd79","schema_fingerprint":"4aa3821a28b0b7c2400bc59aba4bcc0a76e971dadd19610d3ad38c768e124dc7","schema_version":"edge-lab-recorder.raw.v1","sequence":null,"source":"clob_market_ws"}
{"event_at":"2026-07-28T02:02:14.197000Z","event_fingerprint":"2e29234284cf1a7cc1a65dacc76973358aab9859fab63fc62209a051931933f1","payload":{"connection_id":"5d29200f65794d4d9ab6ef271f045a9b","event_at":"2026-07-28T02:02:14.197000Z","event_type":"price_change","frame_hash":"ed32637eb4cb15429c496b116266a969d82eeb4390397cc4947887ce7d677121","frame_index":0,"kind":"data","monotonic_ns":306118580347750,"payload":{"event_type":"price_change","market":"0xda6f0e0e93fc8469e0159a166028d017bddbc162b86f66bac90391379603d962","price_changes":[{"asset_id":"39272994714739463168905443499424551362424437245880253267329605556587274644733","best_ask":"0.58","best_bid":"0.57","hash":"b090f8a137487e2e3f12c525ef085a4219ae9bc5","price":"0.44","side":"BUY","size":"174"},{"asset_id":"20893381255801015515826997628594359667013752732428989472914000440642900266717","best_ask":"0.43","best_bid":"0.42","hash":"b24e576c297f02220cb20a2ff348427dab306ecf","price":"0.56","side":"SELL","size":"174"}],"timestamp":"1785204134197"},"payload_hash":"c71e7ae95b5555495c256b61c9d4e4058a3f0aee51b4880c1bbd37eaecdff1af","raw_frame":"{\"market\":\"0xda6f0e0e93fc8469e0159a166028d017bddbc162b86f66bac90391379603d962\", \"price_changes\":[{\"asset_id\":\"39272994714739463168905443499424551362424437245880253267329605556587274644733\", \"price\":\"0.44\", \"size\":\"174\", \"side\":\"BUY\", \"hash\":\"b090f8a137487e2e3f12c525ef085a4219ae9bc5\", \"best_bid\":\"0.57\", \"best_ask\":\"0.58\"}, {\"asset_id\":\"20893381255801015515826997628594359667013752732428989472914000440642900266717\", \"price\":\"0.56\", \"size\":\"174\", \"side\":\"SELL\", \"hash\":\"b24e576c297f02220cb20a2ff348427dab306ecf\", \"best_bid\":\"0.42\", \"best_ask\":\"0.43\"}], \"timestamp\":\"1785204134197\", \"event_type\":\"price_change\"}","received_at":"2026-07-28T02:02:15.575955Z","schema_version":"clob-market-ws.price_change.v1","sequence":null,"server_hash":null,"server_timestamp":"1785204134197","session_id":"d2757dd6dad94f3b9fe67e8dbf1adc37","source":"clob_market_ws"},"received_at":"2026-07-28T02:02:15.575955Z","record_id":"ba8d051b05f821b436f0f21c8839391193309d405da7682672b275f2e7515c8f","schema_fingerprint":"4aa3821a28b0b7c2400bc59aba4bcc0a76e971dadd19610d3ad38c768e124dc7","schema_version":"edge-lab-recorder.raw.v1","sequence":null,"source":"clob_market_ws"}
{"event_at":"2026-07-28T02:02:14.198000Z","event_fingerprint":"d681b184ca47ffa5bbffac3e5ae85872bef70f6d0bc07f0f7a6bd27274b1b4e2","payload":{"connection_id":"5d29200f65794d4d9ab6ef271f045a9b","event_at":"2026-07-28T02:02:14.198000Z","event_type":"price_change","frame_hash":"2607507018fb520c27732e0d830723d69f26c7adaf02c170846c0fb10366639a","frame_index":0,"kind":"data","monotonic_ns":306118586474583,"payload":{"event_type":"price_change","market":"0xda6f0e0e93fc8469e0159a166028d017bddbc162b86f66bac90391379603d962","price_changes":[{"asset_id":"39272994714739463168905443499424551362424437245880253267329605556587274644733","best_ask":"0.58","best_bid":"0.57","hash":"b2d91795becdae1582eb3b46ba17be8e9e439f82","price":"0.56","side":"BUY","size":"11"},{"asset_id":"20893381255801015515826997628594359667013752732428989472914000440642900266717","best_ask":"0.43","best_bid":"0.42","hash":"88fe6ab5acf53f3a608e1befb3279e9c7c30c0d6","price":"0.44","side":"SELL","size":"11"}],"timestamp":"1785204134198"},"payload_hash":"793c7577c9a4ce15213a6d671ef6c40af7a0d1266ce743cb2d807fc982077d46","raw_frame":"{\"market\":\"0xda6f0e0e93fc8469e0159a166028d017bddbc162b86f66bac90391379603d962\", \"price_changes\":[{\"asset_id\":\"39272994714739463168905443499424551362424437245880253267329605556587274644733\", \"price\":\"0.56\", \"size\":\"11\", \"side\":\"BUY\", \"hash\":\"b2d91795becdae1582eb3b46ba17be8e9e439f82\", \"best_bid\":\"0.57\", \"best_ask\":\"0.58\"}, {\"asset_id\":\"20893381255801015515826997628594359667013752732428989472914000440642900266717\", \"price\":\"0.44\", \"size\":\"11\", \"side\":\"SELL\", \"hash\":\"88fe6ab5acf53f3a608e1befb3279e9c7c30c0d6\", \"best_bid\":\"0.42\", \"best_ask\":\"0.43\"}], \"timestamp\":\"1785204134198\", \"event_type\":\"price_change\"}","received_at":"2026-07-28T02:02:15.582082Z","schema_version":"clob-market-ws.price_change.v1","sequence":null,"server_hash":null,"server_timestamp":"1785204134198","session_id":"d2757dd6dad94f3b9fe67e8dbf1adc37","source":"clob_market_ws"},"received_at":"2026-07-28T02:02:15.582082Z","record_id":"2b696f0827fafa8b099eb083cb1aa97f729ac784c41c917fdc69589e3f1a84ee","schema_fingerprint":"4aa3821a28b0b7c2400bc59aba4bcc0a76e971dadd19610d3ad38c768e124dc7","schema_version":"edge-lab-recorder.raw.v1","sequence":null,"source":"clob_market_ws"}
{"event_at":"2026-07-28T02:02:14.199000Z","event_fingerprint":"347cae55e754f15058e387dc190c02396f92685cd4d0b1b9d46c7e5b26e13ced","payload":{"connection_id":"5d29200f65794d4d9ab6ef271f045a9b","event_at":"2026-07-28T02:02:14.199000Z","event_type":"price_change","frame_hash":"89fef26a73b358988ce86b6c639c1552fc040c3c5fe691f388e3a0ce8d8f8423","frame_index":0,"kind":"data","monotonic_ns":306118592501458,"payload":{"event_type":"price_change","market":"0xda6f0e0e93fc8469e0159a166028d017bddbc162b86f66bac90391379603d962","price_changes":[{"asset_id":"39272994714739463168905443499424551362424437245880253267329605556587274644733","best_ask":"0.58","best_bid":"0.57","hash":"788c9bfa055cd5476751332ba9da1d4036bc6d07","price":"0.42","side":"BUY","size":"104"},{"asset_id":"20893381255801015515826997628594359667013752732428989472914000440642900266717","best_ask":"0.43","best_bid":"0.42","hash":"c90dbe50dc36883ef8a65082c3416f22694256d8","price":"0.58","side":"SELL","size":"104"}],"timestamp":"1785204134199"},"payload_hash":"951bd22b7cb64c80d650aaac35c78a5048f57a7f38be580534dae69fecca4149","raw_frame":"{\"market\":\"0xda6f0e0e93fc8469e0159a166028d017bddbc162b86f66bac90391379603d962\", \"price_changes\":[{\"asset_id\":\"39272994714739463168905443499424551362424437245880253267329605556587274644733\", \"price\":\"0.42\", \"size\":\"104\", \"side\":\"BUY\", \"hash\":\"788c9bfa055cd5476751332ba9da1d4036bc6d07\", \"best_bid\":\"0.57\", \"best_ask\":\"0.58\"}, {\"asset_id\":\"20893381255801015515826997628594359667013752732428989472914000440642900266717\", \"price\":\"0.58\", \"size\":\"104\", \"side\":\"SELL\", \"hash\":\"c90dbe50dc36883ef8a65082c3416f22694256d8\", \"best_bid\":\"0.42\", \"best_ask\":\"0.43\"}], \"timestamp\":\"1785204134199\", \"event_type\":\"price_change\"}","received_at":"2026-07-28T02:02:15.588107Z","schema_version":"clob-market-ws.price_change.v1","sequence":null,"server_hash":null,"server_timestamp":"1785204134199","session_id":"d2757dd6dad94f3b9fe67e8dbf1adc37","source":"clob_market_ws"},"received_at":"2026-07-28T02:02:15.588107Z","record_id":"ed0d5022a6c004d24e89f1c7a62ed9e6f64e88bba8a239d197e01552a97d11a4","schema_fingerprint":"4aa3821a28b0b7c2400bc59aba4bcc0a76e971dadd19610d3ad38c768e124dc7","schema_version":"edge-lab-recorder.raw.v1","sequence":null,"source":"clob_market_ws"}
{"event_at":"2026-07-28T02:02:14.204000Z","event_fingerprint":"1a0848ffd5bc8b1d880760b775d7314ede7fd7065844c4783687ab62d0315d89","payload":{"connection_id":"5d29200f65794d4d9ab6ef271f045a9b","event_at":"2026-07-28T02:02:14.204000Z","event_type":"price_change","frame_hash":"f3bcd171700e92256101e08f7cf995a57e07dccf93484103bf870a0c38dd2861","frame_index":0,"kind":"data","monotonic_ns":306118598583083,"payload":{"event_type":"price_change","market":"0xda6f0e0e93fc8469e0159a166028d017bddbc162b86f66bac90391379603d962","price_changes":[{"asset_id":"39272994714739463168905443499424551362424437245880253267329605556587274644733","best_ask":"0.58","best_bid":"0.57","hash":"6f3d649e174798ffc6cb1c5f15e315654d622b7b","price":"0.46","side":"BUY","size":"192"},{"asset_id":"20893381255801015515826997628594359667013752732428989472914000440642900266717","best_ask":"0.43","best_bid":"0.42","hash":"eb83fd8b295086ae1a3b23e5e1cc6f498f36c56d","price":"0.54","side":"SELL","size":"192"}],"timestamp":"1785204134204"},"payload_hash":"67158c3aa5d026447bde52a186da70df680cde0c50733650be9c604381afc7ae","raw_frame":"{\"market\":\"0xda6f0e0e93fc8469e0159a166028d017bddbc162b86f66bac90391379603d962\", \"price_changes\":[{\"asset_id\":\"39272994714739463168905443499424551362424437245880253267329605556587274644733\", \"price\":\"0.46\", \"size\":\"192\", \"side\":\"BUY\", \"hash\":\"6f3d649e174798ffc6cb1c5f15e315654d622b7b\", \"best_bid\":\"0.57\", \"best_ask\":\"0.58\"}, {\"asset_id\":\"20893381255801015515826997628594359667013752732428989472914000440642900266717\", \"price\":\"0.54\", \"size\":\"192\", \"side\":\"SELL\", \"hash\":\"eb83fd8b295086ae1a3b23e5e1cc6f498f36c56d\", \"best_bid\":\"0.42\", \"best_ask\":\"0.43\"}], \"timestamp\":\"1785204134204\", \"event_type\":\"price_change\"}","received_at":"2026-07-28T02:02:15.594191Z","schema_version":"clob-market-ws.price_change.v1","sequence":null,"server_hash":null,"server_timestamp":"1785204134204","session_id":"d2757dd6dad94f3b9fe67e8dbf1adc37","source":"clob_market_ws"},"received_at":"2026-07-28T02:02:15.594191Z","record_id":"d7ad8322f015dd2351df2b88c952ec397c6c04df1ebced551d537601a5a73c07","schema_fingerprint":"4aa3821a28b0b7c2400bc59aba4bcc0a76e971dadd19610d3ad38c768e124dc7","schema_version":"edge-lab-recorder.raw.v1","sequence":null,"source":"clob_market_ws"}
{"event_at":"2026-07-28T02:02:14.205000Z","event_fingerprint":"d8a39da247fefdc696e0b057bbd8bd164fc6c42aef2cda1a54733689b89a96be","payload":{"connection_id":"5d29200f65794d4d9ab6ef271f045a9b","event_at":"2026-07-28T02:02:14.205000Z","event_type":"price_change","frame_hash":"3d10f87acb51d195dc4ec8a8c032a7f591c20db771717be9cb2955f1c3e4ce17","frame_index":0,"kind":"data","monotonic_ns":306118606222375,"payload":{"event_type":"price_change","market":"0xda6f0e0e93fc8469e0159a166028d017bddbc162b86f66bac90391379603d962","price_changes":[{"asset_id":"20893381255801015515826997628594359667013752732428989472914000440642900266717","best_ask":"0.43","best_bid":"0.42","hash":"8b64552dae7e9de778a8404d8013942d202e42b2","price":"0.42","side":"BUY","size":"416.2"},{"asset_id":"39272994714739463168905443499424551362424437245880253267329605556587274644733","best_ask":"0.58","best_bid":"0.57","hash":"39a97296b75771f367b3e9f17f314e848e08669c","price":"0.58","side":"SELL","size":"416.2"}],"timestamp":"1785204134205"},"payload_hash":"439bf8f7efc01e22973d59ebc5bbf130e3224028532f033ddab011e54cf6d1e8","raw_frame":"{\"market\":\"0xda6f0e0e93fc8469e0159a166028d017bddbc162b86f66bac90391379603d962\", \"price_changes\":[{\"asset_id\":\"20893381255801015515826997628594359667013752732428989472914000440642900266717\", \"price\":\"0.42\", \"size\":\"416.2\", \"side\":\"BUY\", \"hash\":\"8b64552dae7e9de778a8404d8013942d202e42b2\", \"best_bid\":\"0.42\", \"best_ask\":\"0.43\"}, {\"asset_id\":\"39272994714739463168905443499424551362424437245880253267329605556587274644733\", \"price\":\"0.58\", \"size\":\"416.2\", \"side\":\"SELL\", \"hash\":\"39a97296b75771f367b3e9f17f314e848e08669c\", \"best_bid\":\"0.57\", \"best_ask\":\"0.58\"}], \"timestamp\":\"1785204134205\", \"event_type\":\"price_change\"}","received_at":"2026-07-28T02:02:15.601829Z","schema_version":"clob-market-ws.price_change.v1","sequence":null,"server_hash":null,"server_timestamp":"1785204134205","session_id":"d2757dd6dad94f3b9fe67e8dbf1adc37","source":"clob_market_ws"},"received_at":"2026-07-28T02:02:15.601829Z","record_id":"cb19059d22fa693ad5f4c0ab734081866d252005d9395c923fa8776ac249e630","schema_fingerprint":"4aa3821a28b0b7c2400bc59aba4bcc0a76e971dadd19610d3ad38c768e124dc7","schema_version":"edge-lab-recorder.raw.v1","sequence":null,"source":"clob_market_ws"}
{"event_at":"2026-07-28T02:02:14.211000Z","event_fingerprint":"b32e75ca46fb6c4d64bdd73ba019dfe648d17db3518da15d1ac6513d780098f3","payload":{"connection_id":"5d29200f65794d4d9ab6ef271f045a9b","event_at":"2026-07-28T02:02:14.211000Z","event_type":"price_change","frame_hash":"426b8be89441cae3b80606800cbc60a3b7dfdafa6c52cb07648e5444bd13e30f","frame_index":0,"kind":"data","monotonic_ns":306118611492166,"payload":{"event_type":"price_change","market":"0xda6f0e0e93fc8469e0159a166028d017bddbc162b86f66bac90391379603d962","price_changes":[{"asset_id":"39272994714739463168905443499424551362424437245880253267329605556587274644733","best_ask":"0.58","best_bid":"0.57","hash":"8430e4b70e9657b0d70c7ef50956b4bd00965667","price":"0.54","side":"BUY","size":"170.04"},{"asset_id":"20893381255801015515826997628594359667013752732428989472914000440642900266717","best_ask":"0.43","best_bid":"0.42","hash":"346112eb81babf6fedbfa5ac5635c96e33320329","price":"0.46","side":"SELL","size":"170.04"}],"timestamp":"1785204134211"},"payload_hash":"f7bbe0641546b3296a413fe2d4ab99bb1048f79772ff986c8bf1d1bad8f91702","raw_frame":"{\"market\":\"0xda6f0e0e93fc8469e0159a166028d017bddbc162b86f66bac90391379603d962\", \"price_changes\":[{\"asset_id\":\"39272994714739463168905443499424551362424437245880253267329605556587274644733\", \"price\":\"0.54\", \"size\":\"170.04\", \"side\":\"BUY\", \"hash\":\"8430e4b70e9657b0d70c7ef50956b4bd00965667\", \"best_bid\":\"0.57\", \"best_ask\":\"0.58\"}, {\"asset_id\":\"20893381255801015515826997628594359667013752732428989472914000440642900266717\", \"price\":\"0.46\", \"size\":\"170.04\", \"side\":\"SELL\", \"hash\":\"346112eb81babf6fedbfa5ac5635c96e33320329\", \"best_bid\":\"0.42\", \"best_ask\":\"0.43\"}], \"timestamp\":\"1785204134211\", \"event_type\":\"price_change\"}","received_at":"2026-07-28T02:02:15.607099Z","schema_version":"clob-market-ws.price_change.v1","sequence":null,"server_hash":null,"server_timestamp":"1785204134211","session_id":"d2757dd6dad94f3b9fe67e8dbf1adc37","source":"clob_market_ws"},"received_at":"2026-07-28T02:02:15.607099Z","record_id":"78e737f40ad67f8cc2e61949ffd66318b4f5e9cc2d26b84e4a97dc1f3a90b09c","schema_fingerprint":"4aa3821a28b0b7c2400bc59aba4bcc0a76e971dadd19610d3ad38c768e124dc7","schema_version":"edge-lab-recorder.raw.v1","sequence":null,"source":"clob_market_ws"}
{"event_at":"2026-07-28T02:02:14.212000Z","event_fingerprint":"581d57f27ee1c8de246619c291d56530e0b94c737f59debff2e36322281e95d7","payload":{"connection_id":"5d29200f65794d4d9ab6ef271f045a9b","event_at":"2026-07-28T02:02:14.212000Z","event_type":"price_change","frame_hash":"2deaea7c6bdb53bf6b011b4547638c66b5db47af8f5bcbb033027c9316b0e016","frame_index":0,"kind":"data","monotonic_ns":306118616796625,"payload":{"event_type":"price_change","market":"0xda6f0e0e93fc8469e0159a166028d017bddbc162b86f66bac90391379603d962","price_changes":[{"asset_id":"39272994714739463168905443499424551362424437245880253267329605556587274644733","best_ask":"0.58","best_bid":"0.57","hash":"764518b51c5e687f8548812e8becdffb8a5c3a16","price":"0.41","side":"BUY","size":"64"},{"asset_id":"20893381255801015515826997628594359667013752732428989472914000440642900266717","best_ask":"0.43","best_bid":"0.42","hash":"b63978134a9279af662ec696a09315638892e1b1","price":"0.59","side":"SELL","size":"64"}],"timestamp":"1785204134212"},"payload_hash":"6025653377b73743126e59f34c3b1d205536a95f0ff9f9d9b6f6af556d00d0df","raw_frame":"{\"market\":\"0xda6f0e0e93fc8469e0159a166028d017bddbc162b86f66bac90391379603d962\", \"price_changes\":[{\"asset_id\":\"39272994714739463168905443499424551362424437245880253267329605556587274644733\", \"price\":\"0.41\", \"size\":\"64\", \"side\":\"BUY\", \"hash\":\"764518b51c5e687f8548812e8becdffb8a5c3a16\", \"best_bid\":\"0.57\", \"best_ask\":\"0.58\"}, {\"asset_id\":\"20893381255801015515826997628594359667013752732428989472914000440642900266717\", \"price\":\"0.59\", \"size\":\"64\", \"side\":\"SELL\", \"hash\":\"b63978134a9279af662ec696a09315638892e1b1\", \"best_bid\":\"0.42\", \"best_ask\":\"0.43\"}], \"timestamp\":\"1785204134212\", \"event_type\":\"price_change\"}","received_at":"2026-07-28T02:02:15.612403Z","schema_version":"clob-market-ws.price_change.v1","sequence":null,"server_hash":null,"server_timestamp":"1785204134212","session_id":"d2757dd6dad94f3b9fe67e8dbf1adc37","source":"clob_market_ws"},"received_at":"2026-07-28T02:02:15.612403Z","record_id":"a36cae70d21563c75ff01238157c942a942990c5ffce2e918eb973af77066a42","schema_fingerprint":"4aa3821a28b0b7c2400bc59aba4bcc0a76e971dadd19610d3ad38c768e124dc7","schema_version":"edge-lab-recorder.raw.v1","sequence":null,"source":"clob_market_ws"}
{"event_at":"2026-07-28T02:02:14.213000Z","event_fingerprint":"fdae895cefa3c8cd8d356a20f0fb3a554a76c9e06d41bd9e65ac7e5281f7aae3","payload":{"connection_id":"5d29200f65794d4d9ab6ef271f045a9b","event_at":"2026-07-28T02:02:14.213000Z","event_type":"price_change","frame_hash":"4dc46b9f6067deb06aef1f850288090bcf356e4a4337af48960b37a60fcec5e6","frame_index":0,"kind":"data","monotonic_ns":306118621962625,"payload":{"event_type":"price_change","market":"0xda6f0e0e93fc8469e0159a166028d017bddbc162b86f66bac90391379603d962","price_changes":[{"asset_id":"39272994714739463168905443499424551362424437245880253267329605556587274644733","best_ask":"0.58","best_bid":"0.57","hash":"6c402adaf0eee70db37e2b96bbc964e6ca150377","price":"0.54","side":"BUY","size":"158"},{"asset_id":"20893381255801015515826997628594359667013752732428989472914000440642900266717","best_ask":"0.43","best_bid":"0.42","hash":"cc17ce9e2d7228eab2732cc4629b8eb3289803d1","price":"0.46","side":"SELL","size":"158"}],"timestamp":"1785204134213"},"payload_hash":"cf5af16d47254579ad8afc371dc663a498cc5c44142b568c741cc3b1295c2ceb","raw_frame":"{\"market\":\"0xda6f0e0e93fc8469e0159a166028d017bddbc162b86f66bac90391379603d962\", \"price_changes\":[{\"asset_id\":\"39272994714739463168905443499424551362424437245880253267329605556587274644733\", \"price\":\"0.54\", \"size\":\"158\", \"side\":\"BUY\", \"hash\":\"6c402adaf0eee70db37e2b96bbc964e6ca150377\", \"best_bid\":\"0.57\", \"best_ask\":\"0.58\"}, {\"asset_id\":\"20893381255801015515826997628594359667013752732428989472914000440642900266717\", \"price\":\"0.46\", \"size\":\"158\", \"side\":\"SELL\", \"hash\":\"cc17ce9e2d7228eab2732cc4629b8eb3289803d1\", \"best_bid\":\"0.42\", \"best_ask\":\"0.43\"}], \"timestamp\":\"1785204134213\", \"event_type\":\"price_change\"}","received_at":"2026-07-28T02:02:15.617570Z","schema_version":"clob-market-ws.price_change.v1","sequence":null,"server_hash":null,"server_timestamp":"1785204134213","session_id":"d2757dd6dad94f3b9fe67e8dbf1adc37","source":"clob_market_ws"},"received_at":"2026-07-28T02:02:15.617570Z","record_id":"5ce8b6ded19b16294a7625bc73b819bfb58180877a441d1dec73a9f6373d8e8e","schema_fingerprint":"4aa3821a28b0b7c2400bc59aba4bcc0a76e971dadd19610d3ad38c768e124dc7","schema_version":"edge-lab-recorder.raw.v1","sequence":null,"source":"clob_market_ws"}
{"event_at":"2026-07-28T02:02:14.213000Z","event_fingerprint":"f1eee8721565e99f1ccf095a6d6004d0a823fa4b54c0d0e744e2ec0454f2bfe0","payload":{"connection_id":"5d29200f65794d4d9ab6ef271f045a9b","event_at":"2026-07-28T02:02:14.213000Z","event_type":"price_change","frame_hash":"dc2ac2258c1a95b0c9ef1500ef5251cf062eb2b8735800fc763697747a12b676","frame_index":0,"kind":"data","monotonic_ns":306118629143958,"payload":{"event_type":"price_change","market":"0xda6f0e0e93fc8469e0159a166028d017bddbc162b86f66bac90391379603d962","price_changes":[{"asset_id":"39272994714739463168905443499424551362424437245880253267329605556587274644733","best_ask":"0.58","best_bid":"0.57","hash":"6c402adaf0eee70db37e2b96bbc964e6ca150377","price":"0.55","side":"BUY","size":"88.6"},{"asset_id":"20893381255801015515826997628594359667013752732428989472914000440642900266717","best_ask":"0.43","best_bid":"0.42","hash":"cc17ce9e2d7228eab2732cc4629b8eb3289803d1","price":"0.45","side":"SELL","size":"88.6"}],"timestamp":"1785204134213"},"payload_hash":"2c37d02088a7224e550e03c274e494fc5e66275d59ca10e908b94d2d645501b4","raw_frame":"{\"market\":\"0xda6f0e0e93fc8469e0159a166028d017bddbc162b86f66bac90391379603d962\", \"price_changes\":[{\"asset_id\":\"39272994714739463168905443499424551362424437245880253267329605556587274644733\", \"price\":\"0.55\", \"size\":\"88.6\", \"side\":\"BUY\", \"hash\":\"6c402adaf0eee70db37e2b96bbc964e6ca150377\", \"best_bid\":\"0.57\", \"best_ask\":\"0.58\"}, {\"asset_id\":\"20893381255801015515826997628594359667013752732428989472914000440642900266717\", \"price\":\"0.45\", \"size\":\"88.6\", \"side\":\"SELL\", \"hash\":\"cc17ce9e2d7228eab2732cc4629b8eb3289803d1\", \"best_bid\":\"0.42\", \"best_ask\":\"0.43\"}], \"timestamp\":\"1785204134213\", \"event_type\":\"price_change\"}","received_at":"2026-07-28T02:02:15.624749Z","schema_version":"clob-market-ws.price_change.v1","sequence":null,"server_hash":null,"server_timestamp":"1785204134213","session_id":"d2757dd6dad94f3b9fe67e8dbf1adc37","source":"clob_market_ws"},"received_at":"2026-07-28T02:02:15.624749Z","record_id":"a07d3fd6d7ab080cdcbd7d4d1cfcd18d6d1d9f14a423a89ba8e018770ad572f9","schema_fingerprint":"4aa3821a28b0b7c2400bc59aba4bcc0a76e971dadd19610d3ad38c768e124dc7","schema_version":"edge-lab-recorder.raw.v1","sequence":null,"source":"clob_market_ws"}
{"event_at":"2026-07-28T02:02:14.214000Z","event_fingerprint":"fb04c3a7004a93278cb3413b724bb5856600fd8f662a492e49e40958e04cbdfd","payload":{"connection_id":"5d29200f65794d4d9ab6ef271f045a9b","event_at":"2026-07-28T02:02:14.214000Z","event_type":"price_change","frame_hash":"83ef828a302a613b9243126c2e77e76d9cd9a72a013626b9eaa365645fb6d477","frame_index":0,"kind":"data","monotonic_ns":306118639173250,"payload":{"event_type":"price_change","market":"0xda6f0e0e93fc8469e0159a166028d017bddbc162b86f66bac90391379603d962","price_changes":[{"asset_id":"39272994714739463168905443499424551362424437245880253267329605556587274644733","best_ask":"0.58","best_bid":"0.57","hash":"8a775e193b3e57edae6146692ce7c245a461c495","price":"0.56","side":"BUY","size":"5"},{"asset_id":"20893381255801015515826997628594359667013752732428989472914000440642900266717","best_ask":"0.43","best_bid":"0.42","hash":"92ca925412502687600a9bad19bf037d59c44cdc","price":"0.44","side":"SELL","size":"5"}],"timestamp":"1785204134214"},"payload_hash":"bff25fcd75dcb2a8ff720c2b1c05f0cd5559f4d2204b67e2154312fe4dd9732d","raw_frame":"{\"market\":\"0xda6f0e0e93fc8469e0159a166028d017bddbc162b86f66bac90391379603d962\", \"price_changes\":[{\"asset_id\":\"39272994714739463168905443499424551362424437245880253267329605556587274644733\", \"price\":\"0.56\", \"size\":\"5\", \"side\":\"BUY\", \"hash\":\"8a775e193b3e57edae6146692ce7c245a461c495\", \"best_bid\":\"0.57\", \"best_ask\":\"0.58\"}, {\"asset_id\":\"20893381255801015515826997628594359667013752732428989472914000440642900266717\", \"price\":\"0.44\", \"size\":\"5\", \"side\":\"SELL\", \"hash\":\"92ca925412502687600a9bad19bf037d59c44cdc\", \"best_bid\":\"0.42\", \"best_ask\":\"0.43\"}], \"timestamp\":\"1785204134214\", \"event_type\":\"price_change\"}","received_at":"2026-07-28T02:02:15.634780Z","schema_version":"clob-market-ws.price_change.v1","sequence":null,"server_hash":null,"server_timestamp":"1785204134214","session_id":"d2757dd6dad94f3b9fe67e8dbf1adc37","source":"clob_market_ws"},"received_at":"2026-07-28T02:02:15.634780Z","record_id":"6b3ba64b33ced64f7e10a572ca12aa99142f97d676ffa19814b895ad4a7504cd","schema_fingerprint":"4aa3821a28b0b7c2400bc59aba4bcc0a76e971dadd19610d3ad38c768e124dc7","schema_version":"edge-lab-recorder.raw.v1","sequence":null,"source":"clob_market_ws"}
{"event_at":"2026-07-28T02:02:14.216000Z","event_fingerprint":"eb7e4b0e539024bd2b8a006a79a3ff644fbf469ee9f9d5529133dc15f7dfeeb6","payload":{"connection_id":"5d29200f65794d4d9ab6ef271f045a9b","event_at":"2026-07-28T02:02:14.216000Z","event_type":"price_change","frame_hash":"c872e8368c94ab64a6ef94bd0a373c26e304423c70762e0645a6197f779350f3","frame_index":0,"kind":"data","monotonic_ns":306118644424208,"payload":{"event_type":"price_change","market":"0xda6f0e0e93fc8469e0159a166028d017bddbc162b86f66bac90391379603d962","price_changes":[{"asset_id":"39272994714739463168905443499424551362424437245880253267329605556587274644733","best_ask":"0.58","best_bid":"0.57","hash":"1ec910ba52aa877b5b3fffb8917b5c2ac161f81c","price":"0.52","side":"BUY","size":"129"},{"asset_id":"20893381255801015515826997628594359667013752732428989472914000440642900266717","best_ask":"0.43","best_bid":"0.42","hash":"2a126a95d5f095191185f8c1b73846edda0dd923","price":"0.48","side":"SELL","size":"129"}],"timestamp":"1785204134216"},"payload_hash":"08a9372ff66c201074f1128c778a93f9ea74811d6efdb2a618a2d5f6412a49d4","raw_frame":"{\"market\":\"0xda6f0e0e93fc8469e0159a166028d017bddbc162b86f66bac90391379603d962\", \"price_changes\":[{\"asset_id\":\"39272994714739463168905443499424551362424437245880253267329605556587274644733\", \"price\":\"0.52\", \"size\":\"129\", \"side\":\"BUY\", \"hash\":\"1ec910ba52aa877b5b3fffb8917b5c2ac161f81c\", \"best_bid\":\"0.57\", \"best_ask\":\"0.58\"}, {\"asset_id\":\"20893381255801015515826997628594359667013752732428989472914000440642900266717\", \"price\":\"0.48\", \"size\":\"129\", \"side\":\"SELL\", \"hash\":\"2a126a95d5f095191185f8c1b73846edda0dd923\", \"best_bid\":\"0.42\", \"best_ask\":\"0.43\"}], \"timestamp\":\"1785204134216\", \"event_type\":\"price_change\"}","received_at":"2026-07-28T02:02:15.640024Z","schema_version":"clob-market-ws.price_change.v1","sequence":null,"server_hash":null,"server_timestamp":"1785204134216","session_id":"d2757dd6dad94f3b9fe67e8dbf1adc37","source":"clob_market_ws"},"received_at":"2026-07-28T02:02:15.640024Z","record_id":"681ca5aae62fae6dd21403f08e13241a56055203ff21935f0e72a36a9362883a","schema_fingerprint":"4aa3821a28b0b7c2400bc59aba4bcc0a76e971dadd19610d3ad38c768e124dc7","schema_version":"edge-lab-recorder.raw.v1","sequence":null,"source":"clob_market_ws"}
{"event_at":"2026-07-28T02:02:14.224000Z","event_fingerprint":"b0c81fdee8b1a634822fad57ffcc619e9cbef46eba8bea0b22e86ec0d3e987a5","payload":{"connection_id":"5d29200f65794d4d9ab6ef271f045a9b","event_at":"2026-07-28T02:02:14.224000Z","event_type":"price_change","frame_hash":"c771f77583899bce2adbd445ef712db00d4268ff6cff01ced8f0b3c603e1bcb3","frame_index":0,"kind":"data","monotonic_ns":306118658172833,"payload":{"event_type":"price_change","market":"0xda6f0e0e93fc8469e0159a166028d017bddbc162b86f66bac90391379603d962","price_changes":[{"asset_id":"20893381255801015515826997628594359667013752732428989472914000440642900266717","best_ask":"0.43","best_bid":"0.42","hash":"bc598e30755ddaa2abebc5b0dd3b43afef503929","price":"0.35","side":"BUY","size":"159"},{"asset_id":"39272994714739463168905443499424551362424437245880253267329605556587274644733","best_ask":"0.58","best_bid":"0.57","hash":"16c3c8cd5cfed064d6f79ff77ddcc0cafc7f5658","price":"0.65","side":"SELL","size":"159"}],"timestamp":"1785204134224"},"payload_hash":"d80846df3b30042fac5ae5efe6d8e64b0ab4ba3aec663011ce8f1a855936998d","raw_frame":"{\"market\":\"0xda6f0e0e93fc8469e0159a166028d017bddbc162b86f66bac90391379603d962\", \"price_changes\":[{\"asset_id\":\"20893381255801015515826997628594359667013752732428989472914000440642900266717\", \"price\":\"0.35\", \"size\":\"159\", \"side\":\"BUY\", \"hash\":\"bc598e30755ddaa2abebc5b0dd3b43afef503929\", \"best_bid\":\"0.42\", \"best_ask\":\"0.43\"}, {\"asset_id\":\"39272994714739463168905443499424551362424437245880253267329605556587274644733\", \"price\":\"0.65\", \"size\":\"159\", \"side\":\"SELL\", \"hash\":\"16c3c8cd5cfed064d6f79ff77ddcc0cafc7f5658\", \"best_bid\":\"0.57\", \"best_ask\":\"0.58\"}], \"timestamp\":\"1785204134224\", \"event_type\":\"price_change\"}","received_at":"2026-07-28T02:02:15.653779Z","schema_version":"clob-market-ws.price_change.v1","sequence":null,"server_hash":null,"server_timestamp":"1785204134224","session_id":"d2757dd6dad94f3b9fe67e8dbf1adc37","source":"clob_market_ws"},"received_at":"2026-07-28T02:02:15.653779Z","record_id":"1b74f8e8ac90e26dfaddd8c0249e326d62c087233491fe6e3b2379b80d83cd30","schema_fingerprint":"4aa3821a28b0b7c2400bc59aba4bcc0a76e971dadd19610d3ad38c768e124dc7","schema_version":"edge-lab-recorder.raw.v1","sequence":null,"source":"clob_market_ws"}
{"event_at":"2026-07-28T02:02:14.226000Z","event_fingerprint":"ad0d8c109113b0216d783692a2cc17a8b0c16e28d3ab7f4786af3ec19b24bbd6","payload":{"connection_id":"5d29200f65794d4d9ab6ef271f045a9b","event_at":"2026-07-28T02:02:14.226000Z","event_type":"price_change","frame_hash":"85be58bb297daf4d4e2f5aa98d0496236adc33b1e41ece517cd2415319993945","frame_index":0,"kind":"data","monotonic_ns":306118664472541,"payload":{"event_type":"price_change","market":"0xda6f0e0e93fc8469e0159a166028d017bddbc162b86f66bac90391379603d962","price_changes":[{"asset_id":"39272994714739463168905443499424551362424437245880253267329605556587274644733","best_ask":"0.58","best_bid":"0.57","hash":"f336e9b036cc39c439d0151c6e5786cb448e1306","price":"0.41","side":"BUY","size":"145.3"},{"asset_id":"20893381255801015515826997628594359667013752732428989472914000440642900266717","best_ask":"0.43","best_bid":"0.42","hash":"f4df8564b80077644a6cbfae89dc327ae7f415de","price":"0.59","side":"SELL","size":"145.3"}],"timestamp":"1785204134226"},"payload_hash":"4b3f312371ee6aa9c3b27bf12a14974082650cbb09f556361b6f1837b6598d3b","raw_frame":"{\"market\":\"0xda6f0e0e93fc8469e0159a166028d017bddbc162b86f66bac90391379603d962\", \"price_changes\":[{\"asset_id\":\"39272994714739463168905443499424551362424437245880253267329605556587274644733\", \"price\":\"0.41\", \"size\":\"145.3\", \"side\":\"BUY\", \"hash\":\"f336e9b036cc39c439d0151c6e5786cb448e1306\", \"best_bid\":\"0.57\", \"best_ask\":\"0.58\"}, {\"asset_id\":\"20893381255801015515826997628594359667013752732428989472914000440642900266717\", \"price\":\"0.59\", \"size\":\"145.3\", \"side\":\"SELL\", \"hash\":\"f4df8564b80077644a6cbfae89dc327ae7f415de\", \"best_bid\":\"0.42\", \"best_ask\":\"0.43\"}], \"timestamp\":\"1785204134226\", \"event_type\":\"price_change\"}","received_at":"2026-07-28T02:02:15.660080Z","schema_version":"clob-market-ws.price_change.v1","sequence":null,"server_hash":null,"server_timestamp":"1785204134226","session_id":"d2757dd6dad94f3b9fe67e8dbf1adc37","source":"clob_market_ws"},"received_at":"2026-07-28T02:02:15.660080Z","record_id":"4a3c0c12a8833fd8baebbec61c7190aaa295230faacef25287281cfe5416458c","schema_fingerprint":"4aa3821a28b0b7c2400bc59aba4bcc0a76e971dadd19610d3ad38c768e124dc7","schema_version":"edge-lab-recorder.raw.v1","sequence":null,"source":"clob_market_ws"}
{"event_at":"2026-07-28T02:02:14.229000Z","event_fingerprint":"b25351bc9bcd496145bcee6592a5987b206d2caf3b1cee39091d740a16b4895c","payload":{"connection_id":"5d29200f65794d4d9ab6ef271f045a9b","event_at":"2026-07-28T02:02:14.229000Z","event_type":"price_change","frame_hash":"2792e407a6ccce3da0cb4549b51df83505321f400651c99be7ee7a723f740c86","frame_index":0,"kind":"data","monotonic_ns":306118671515000,"payload":{"event_type":"price_change","market":"0xda6f0e0e93fc8469e0159a166028d017bddbc162b86f66bac90391379603d962","price_changes":[{"asset_id":"20893381255801015515826997628594359667013752732428989472914000440642900266717","best_ask":"0.43","best_bid":"0.42","hash":"0579703dd151944a85e2347b2775507d8e5a61fe","price":"0.34","side":"BUY","size":"238.4"},{"asset_id":"39272994714739463168905443499424551362424437245880253267329605556587274644733","best_ask":"0.58","best_bid":"0.57","hash":"ae4f4d68bcfccccce88259d5b77f5e0f6f85104b","price":"0.66","side":"SELL","size":"238.4"}],"timestamp":"1785204134229"},"payload_hash":"59965714d392e9f4a3f18de8dfc4aa6e701d8616b859b9cbe589c05074e99713","raw_frame":"{\"market\":\"0xda6f0e0e93fc8469e0159a166028d017bddbc162b86f66bac90391379603d962\", \"price_changes\":[{\"asset_id\":\"20893381255801015515826997628594359667013752732428989472914000440642900266717\", \"price\":\"0.34\", \"size\":\"238.4\", \"side\":\"BUY\", \"hash\":\"0579703dd151944a85e2347b2775507d8e5a61fe\", \"best_bid\":\"0.42\", \"best_ask\":\"0.43\"}, {\"asset_id\":\"39272994714739463168905443499424551362424437245880253267329605556587274644733\", \"price\":\"0.66\", \"size\":\"238.4\", \"side\":\"SELL\", \"hash\":\"ae4f4d68bcfccccce88259d5b77f5e0f6f85104b\", \"best_bid\":\"0.57\", \"best_ask\":\"0.58\"}], \"timestamp\":\"1785204134229\", \"event_type\":\"price_change\"}","received_at":"2026-07-28T02:02:15.667118Z","schema_version":"clob-market-ws.price_change.v1","sequence":null,"server_hash":null,"server_timestamp":"1785204134229","session_id":"d2757dd6dad94f3b9fe67e8dbf1adc37","source":"clob_market_ws"},"received_at":"2026-07-28T02:02:15.667118Z","record_id":"c35be8bf5bb7497534fcb354f3356b3fd3a7d068efbd0dead5b6432819522c0a","schema_fingerprint":"4aa3821a28b0b7c2400bc59aba4bcc0a76e971dadd19610d3ad38c768e124dc7","schema_version":"edge-lab-recorder.raw.v1","sequence":null,"source":"clob_market_ws"}
{"event_at":"2026-07-28T02:02:14.230000Z","event_fingerprint":"0b01746a01a6c8cde5d2d0e581474137a321e6d6d1e098e344515dbcc0f32e8d","payload":{"connection_id":"5d29200f65794d4d9ab6ef271f045a9b","event_at":"2026-07-28T02:02:14.230000Z","event_type":"price_change","frame_hash":"e30dd5cc0818f509f280132f84a0b2efd6855d6469423a84aa1d4e8051e923e7","frame_index":0,"kind":"data","monotonic_ns":306118680670875,"payload":{"event_type":"price_change","market":"0xda6f0e0e93fc8469e0159a166028d017bddbc162b86f66bac90391379603d962","price_changes":[{"asset_id":"20893381255801015515826997628594359667013752732428989472914000440642900266717","best_ask":"0.43","best_bid":"0.42","hash":"54576c34bebf2425ec7ecd43df4a0964a709a9e5","price":"0.42","side":"BUY","size":"426.2"},{"asset_id":"39272994714739463168905443499424551362424437245880253267329605556587274644733","best_ask":"0.58","best_bid":"0.57","hash":"72bd4d56f4dc08c2ca8d88de7cfc2a22095dfdcf","price":"0.58","side":"SELL","size":"426.2"}],"timestamp":"1785204134230"},"payload_hash":"c0f21575c22b4e852a32b9f121bb08e858501f808691838666f6f6b4060785ee","raw_frame":"{\"market\":\"0xda6f0e0e93fc8469e0159a166028d017bddbc162b86f66bac90391379603d962\", \"price_changes\":[{\"asset_id\":\"20893381255801015515826997628594359667013752732428989472914000440642900266717\", \"price\":\"0.42\", \"size\":\"426.2\", \"side\":\"BUY\", \"hash\":\"54576c34bebf2425ec7ecd43df4a0964a709a9e5\", \"best_bid\":\"0.42\", \"best_ask\":\"0.43\"}, {\"asset_id\":\"39272994714739463168905443499424551362424437245880253267329605556587274644733\", \"price\":\"0.58\", \"size\":\"426.2\", \"side\":\"SELL\", \"hash\":\"72bd4d56f4dc08c2ca8d88de7cfc2a22095dfdcf\", \"best_bid\":\"0.57\", \"best_ask\":\"0.58\"}], \"timestamp\":\"1785204134230\", \"event_type\":\"price_change\"}","received_at":"2026-07-28T02:02:15.676274Z","schema_version":"clob-market-ws.price_change.v1","sequence":null,"server_hash":null,"server_timestamp":"1785204134230","session_id":"d2757dd6dad94f3b9fe67e8dbf1adc37","source":"clob_market_ws"},"received_at":"2026-07-28T02:02:15.676274Z","record_id":"70bdc2117bfb2257bbb23209328b4ea267b3bfdecb1fcab7cd76beedeca98867","schema_fingerprint":"4aa3821a28b0b7c2400bc59aba4bcc0a76e971dadd19610d3ad38c768e124dc7","schema_version":"edge-lab-recorder.raw.v1","sequence":null,"source":"clob_market_ws"}
{"event_at":"2026-07-28T02:02:14.230000Z","event_fingerprint":"5f099d6b6a37568c811863ad1eaa953b521663171d0c83af741d02fe5e910576","payload":{"connection_id":"5d29200f65794d4d9ab6ef271f045a9b","event_at":"2026-07-28T02:02:14.230000Z","event_type":"price_change","frame_hash":"0b55f9f4b3444ab3eab48e818aea5c4006ef42a7063dafbf31d9d78dedfbcf06","frame_index":0,"kind":"data","monotonic_ns":306118687344125,"payload":{"event_type":"price_change","market":"0xda6f0e0e93fc8469e0159a166028d017bddbc162b86f66bac90391379603d962","price_changes":[{"asset_id":"39272994714739463168905443499424551362424437245880253267329605556587274644733","best_ask":"0.58","best_bid":"0.57","hash":"cae628b255e26a813905c42bb851c42ae516f894","price":"0.53","side":"BUY","size":"105.03"},{"asset_id":"20893381255801015515826997628594359667013752732428989472914000440642900266717","best_ask":"0.43","best_bid":"0.42","hash":"356d746919efb15e4323686a0736f96ff4faa89f","price":"0.47","side":"SELL","size":"105.03"}],"timestamp":"1785204134230"},"payload_hash":"524d20fd5d327d2ae4608fa73762c4c0ccdf547115cc7632e245b7719b3a1d56","raw_frame":"{\"market\":\"0xda6f0e0e93fc8469e0159a166028d017bddbc162b86f66bac90391379603d962\", \"price_changes\":[{\"asset_id\":\"39272994714739463168905443499424551362424437245880253267329605556587274644733\", \"price\":\"0.53\", \"size\":\"105.03\", \"side\":\"BUY\", \"hash\":\"cae628b255e26a813905c42bb851c42ae516f894\", \"best_bid\":\"0.57\", \"best_ask\":\"0.58\"}, {\"asset_id\":\"20893381255801015515826997628594359667013752732428989472914000440642900266717\", \"price\":\"0.47\", \"size\":\"105.03\", \"side\":\"SELL\", \"hash\":\"356d746919efb15e4323686a0736f96ff4faa89f\", \"best_bid\":\"0.42\", \"best_ask\":\"0.43\"}], \"timestamp\":\"1785204134230\", \"event_type\":\"price_change\"}","received_at":"2026-07-28T02:02:15.682949Z","schema_version":"clob-market-ws.price_change.v1","sequence":null,"server_hash":null,"server_timestamp":"1785204134230","session_id":"d2757dd6dad94f3b9fe67e8dbf1adc37","source":"clob_market_ws"},"received_at":"2026-07-28T02:02:15.682949Z","record_id":"72b32d1a104f1b2ccde3f6206d533bec54bc8a1dbbb0085d32b8b3e6efd53439","schema_fingerprint":"4aa3821a28b0b7c2400bc59aba4bcc0a76e971dadd19610d3ad38c768e124dc7","schema_version":"edge-lab-recorder.raw.v1","sequence":null,"source":"clob_market_ws"}
{"event_at":"2026-07-28T02:02:14.231000Z","event_fingerprint":"765a5cf5434a49e11bc104d03707646eba448b0b11df0e0ecff2231770415233","payload":{"connection_id":"5d29200f65794d4d9ab6ef271f045a9b","event_at":"2026-07-28T02:02:14.231000Z","event_type":"price_change","frame_hash":"a9e39c5055b4140e07c18442f748dbdf073abeab598cf6ba334b6df386b3fb61","frame_index":0,"kind":"data","monotonic_ns":306118694681208,"payload":{"event_type":"price_change","market":"0xda6f0e0e93fc8469e0159a166028d017bddbc162b86f66bac90391379603d962","price_changes":[{"asset_id":"39272994714739463168905443499424551362424437245880253267329605556587274644733","best_ask":"0.58","best_bid":"0.57","hash":"91d8232e95a0dd6f9ad2d33b03f44826eb4cc56b","price":"0.53","side":"BUY","size":"115.03"},{"asset_id":"20893381255801015515826997628594359667013752732428989472914000440642900266717","best_ask":"0.43","best_bid":"0.42","hash":"38ef09e3ca8d1d0a912009fd4818e110be01481a","price":"0.47","side":"SELL","size":"115.03"}],"timestamp":"1785204134231"},"payload_hash":"e0db47c164d042ca5fb015b272e3b88045c9448405266358eb8c770ea0e589ee","raw_frame":"{\"market\":\"0xda6f0e0e93fc8469e0159a166028d017bddbc162b86f66bac90391379603d962\", \"price_changes\":[{\"asset_id\":\"39272994714739463168905443499424551362424437245880253267329605556587274644733\", \"price\":\"0.53\", \"size\":\"115.03\", \"side\":\"BUY\", \"hash\":\"91d8232e95a0dd6f9ad2d33b03f44826eb4cc56b\", \"best_bid\":\"0.57\", \"best_ask\":\"0.58\"}, {\"asset_id\":\"20893381255801015515826997628594359667013752732428989472914000440642900266717\", \"price\":\"0.47\", \"size\":\"115.03\", \"side\":\"SELL\", \"hash\":\"38ef09e3ca8d1d0a912009fd4818e110be01481a\", \"best_bid\":\"0.42\", \"best_ask\":\"0.43\"}], \"timestamp\":\"1785204134231\", \"event_type\":\"price_change\"}","received_at":"2026-07-28T02:02:15.690287Z","schema_version":"clob-market-ws.price_change.v1","sequence":null,"server_hash":null,"server_timestamp":"1785204134231","session_id":"d2757dd6dad94f3b9fe67e8dbf1adc37","source":"clob_market_ws"},"received_at":"2026-07-28T02:02:15.690287Z","record_id":"449bc0a042f6bb7d6647aa3f66cea8a9d2234ba918fdb57ef5737c026f0483e2","schema_fingerprint":"4aa3821a28b0b7c2400bc59aba4bcc0a76e971dadd19610d3ad38c768e124dc7","schema_version":"edge-lab-recorder.raw.v1","sequence":null,"source":"clob_market_ws"}
{"event_at":"2026-07-28T02:02:14.232000Z","event_fingerprint":"6b0880685fe40e3a02d5dd29ae4f96c00cd78130370dc69d85f18ff36a711ec6","payload":{"connection_id":"5d29200f65794d4d9ab6ef271f045a9b","event_at":"2026-07-28T02:02:14.232000Z","event_type":"price_change","frame_hash":"b2e5ebb00a1756522b2eb7ceff239e21eb45b13ac02ab004a611986ac93e4e7a","frame_index":0,"kind":"data","monotonic_ns":306118701253083,"payload":{"event_type":"price_change","market":"0xda6f0e0e93fc8469e0159a166028d017bddbc162b86f66bac90391379603d962","price_changes":[{"asset_id":"39272994714739463168905443499424551362424437245880253267329605556587274644733","best_ask":"0.58","best_bid":"0.57","hash":"8cfc3ebe6ad77a3ebda37b4a0f8220570c871371","price":"0.37","side":"BUY","size":"61.9"},{"asset_id":"20893381255801015515826997628594359667013752732428989472914000440642900266717","best_ask":"0.43","best_bid":"0.42","hash":"15f15aeb16c0f814fb873cd7fa245b5c6e908119","price":"0.63","side":"SELL","size":"61.9"}],"timestamp":"1785204134232"},"payload_hash":"12d351049e4ecb845dfa4b30e87e40e7886e33a807b5c16ddf660c3aec3ee3cb","raw_frame":"{\"market\":\"0xda6f0e0e93fc8469e0159a166028d017bddbc162b86f66bac90391379603d962\", \"price_changes\":[{\"asset_id\":\"39272994714739463168905443499424551362424437245880253267329605556587274644733\", \"price\":\"0.37\", \"size\":\"61.9\", \"side\":\"BUY\", \"hash\":\"8cfc3ebe6ad77a3ebda37b4a0f8220570c871371\", \"best_bid\":\"0.57\", \"best_ask\":\"0.58\"}, {\"asset_id\":\"20893381255801015515826997628594359667013752732428989472914000440642900266717\", \"price\":\"0.63\", \"size\":\"61.9\", \"side\":\"SELL\", \"hash\":\"15f15aeb16c0f814fb873cd7fa245b5c6e908119\", \"best_bid\":\"0.42\", \"best_ask\":\"0.43\"}], \"timestamp\":\"1785204134232\", \"event_type\":\"price_change\"}","received_at":"2026-07-28T02:02:15.696858Z","schema_version":"clob-market-ws.price_change.v1","sequence":null,"server_hash":null,"server_timestamp":"1785204134232","session_id":"d2757dd6dad94f3b9fe67e8dbf1adc37","source":"clob_market_ws"},"received_at":"2026-07-28T02:02:15.696858Z","record_id":"2a622569dbc2190c411d80e65c3febf1a2fbc6f2f3923fc06da5db59890c29b0","schema_fingerprint":"4aa3821a28b0b7c2400bc59aba4bcc0a76e971dadd19610d3ad38c768e124dc7","schema_version":"edge-lab-recorder.raw.v1","sequence":null,"source":"clob_market_ws"}
{"event_at":"2026-07-28T02:02:14.232000Z","event_fingerprint":"c96b719bca7ecc171477daf6bcccbefdef6a0ffcdc93e372c9b80bbfaf074910","payload":{"connection_id":"5d29200f65794d4d9ab6ef271f045a9b","event_at":"2026-07-28T02:02:14.232000Z","event_type":"price_change","frame_hash":"71c40b1f8183e222dd99c3021000290670d9915cac7d3a50190df1578fd64d79","frame_index":0,"kind":"data","monotonic_ns":306118706695708,"payload":{"event_type":"price_change","market":"0xda6f0e0e93fc8469e0159a166028d017bddbc162b86f66bac90391379603d962","price_changes":[{"asset_id":"39272994714739463168905443499424551362424437245880253267329605556587274644733","best_ask":"0.58","best_bid":"0.57","hash":"8208f8913795cc7b051262a0d6bbbce334ed47ee","price":"0.54","side":"BUY","size":"428"},{"asset_id":"20893381255801015515826997628594359667013752732428989472914000440642900266717","best_ask":"0.43","best_bid":"0.42","hash":"2070dac11f704ec88fddbdfae4112c29dc71f9b7","price":"0.46","side":"SELL","size":"428"}],"timestamp":"1785204134232"},"payload_hash":"61165dbb1fb34abe858899ca6dc9a92e616c9d0e8d1b8ac33ea0dcfafd72bc47","raw_frame":"{\"market\":\"0xda6f0e0e93fc8469e0159a166028d017bddbc162b86f66bac90391379603d962\", \"price_changes\":[{\"asset_id\":\"39272994714739463168905443499424551362424437245880253267329605556587274644733\", \"price\":\"0.54\", \"size\":\"428\", \"side\":\"BUY\", \"hash\":\"8208f8913795cc7b051262a0d6bbbce334ed47ee\", \"best_bid\":\"0.57\", \"best_ask\":\"0.58\"}, {\"asset_id\":\"20893381255801015515826997628594359667013752732428989472914000440642900266717\", \"price\":\"0.46\", \"size\":\"428\", \"side\":\"SELL\", \"hash\":\"2070dac11f704ec88fddbdfae4112c29dc71f9b7\", \"best_bid\":\"0.42\", \"best_ask\":\"0.43\"}], \"timestamp\":\"1785204134232\", \"event_type\":\"price_change\"}","received_at":"2026-07-28T02:02:15.702300Z","schema_version":"clob-market-ws.price_change.v1","sequence":null,"server_hash":null,"server_timestamp":"1785204134232","session_id":"d2757dd6dad94f3b9fe67e8dbf1adc37","source":"clob_market_ws"},"received_at":"2026-07-28T02:02:15.702300Z","record_id":"6a04512274edd6a5120e1b8bee87177a64e9c898f01f844aa7892177a023fd45","schema_fingerprint":"4aa3821a28b0b7c2400bc59aba4bcc0a76e971dadd19610d3ad38c768e124dc7","schema_version":"edge-lab-recorder.raw.v1","sequence":null,"source":"clob_market_ws"}
{"event_at":"2026-07-28T02:02:14.233000Z","event_fingerprint":"b265b3744c424e227e50e57ee1c2395be0679d318a146c7f857689ef6563efb1","payload":{"connection_id":"5d29200f65794d4d9ab6ef271f045a9b","event_at":"2026-07-28T02:02:14.233000Z","event_type":"price_change","frame_hash":"bc3b0d44762a7c6a055829683778f52a937a73fac660f929878f2d8805a37a90","frame_index":0,"kind":"data","monotonic_ns":306118711577458,"payload":{"event_type":"price_change","market":"0xda6f0e0e93fc8469e0159a166028d017bddbc162b86f66bac90391379603d962","price_changes":[{"asset_id":"39272994714739463168905443499424551362424437245880253267329605556587274644733","best_ask":"0.58","best_bid":"0.57","hash":"ee32495a4e1f7b0cfdd4971e112fe3ab8b02de4e","price":"0.54","side":"BUY","size":"408"},{"asset_id":"20893381255801015515826997628594359667013752732428989472914000440642900266717","best_ask":"0.43","best_bid":"0.42","hash":"8e861e81f1c5af86ac74385359c3632a76b30d96","price":"0.46","side":"SELL","size":"408"}],"timestamp":"1785204134233"},"payload_hash":"2aead0afced82b262eaf0ec6312305cab1322c519a349f55714eb70d3233547d","raw_frame":"{\"market\":\"0xda6f0e0e93fc8469e0159a166028d017bddbc162b86f66bac90391379603d962\", \"price_changes\":[{\"asset_id\":\"39272994714739463168905443499424551362424437245880253267329605556587274644733\", \"price\":\"0.54\", \"size\":\"408\", \"side\":\"BUY\", \"hash\":\"ee32495a4e1f7b0cfdd4971e112fe3ab8b02de4e\", \"best_bid\":\"0.57\", \"best_ask\":\"0.58\"}, {\"asset_id\":\"20893381255801015515826997628594359667013752732428989472914000440642900266717\", \"price\":\"0.46\", \"size\":\"408\", \"side\":\"SELL\", \"hash\":\"8e861e81f1c5af86ac74385359c3632a76b30d96\", \"best_bid\":\"0.42\", \"best_ask\":\"0.43\"}], \"timestamp\":\"1785204134233\", \"event_type\":\"price_change\"}","received_at":"2026-07-28T02:02:15.707181Z","schema_version":"clob-market-ws.price_change.v1","sequence":null,"server_hash":null,"server_timestamp":"1785204134233","session_id":"d2757dd6dad94f3b9fe67e8dbf1adc37","source":"clob_market_ws"},"received_at":"2026-07-28T02:02:15.707181Z","record_id":"9fd36f43cdb49872b5450dd622b346f54d7b9298ca6ad4fd00cb6a8018bafea7","schema_fingerprint":"4aa3821a28b0b7c2400bc59aba4bcc0a76e971dadd19610d3ad38c768e124dc7","schema_version":"edge-lab-recorder.raw.v1","sequence":null,"source":"clob_market_ws"}
{"event_at":"2026-07-28T02:02:14.234000Z","event_fingerprint":"e415ef60c682d25973b47561188bb37e6f5eeabb72f6b0aa945aff06bc6851d3","payload":{"connection_id":"5d29200f65794d4d9ab6ef271f045a9b","event_at":"2026-07-28T02:02:14.234000Z","event_type":"price_change","frame_hash":"e8e036029c13a716cd6cbdf57602c1aa89eb8669857aa7b97176e8bdfe5ec224","frame_index":0,"kind":"data","monotonic_ns":306118717012208,"payload":{"event_type":"price_change","market":"0xda6f0e0e93fc8469e0159a166028d017bddbc162b86f66bac90391379603d962","price_changes":[{"asset_id":"39272994714739463168905443499424551362424437245880253267329605556587274644733","best_ask":"0.58","best_bid":"0.57","hash":"0c9a0ba83b2ed1d09eb5887f7b6da0f89f73655d","price":"0.45","side":"BUY","size":"201.5"},{"asset_id":"20893381255801015515826997628594359667013752732428989472914000440642900266717","best_ask":"0.43","best_bid":"0.42","hash":"35188f105347fe20911a0eb5e753f3f353e0b420","price":"0.55","side":"SELL","size":"201.5"}],"timestamp":"1785204134234"},"payload_hash":"05bdd317ca782e57f580b5b14ba3ca9e9a2cd387fd1f6b04aa8a68a9245353a1","raw_frame":"{\"market\":\"0xda6f0e0e93fc8469e0159a166028d017bddbc162b86f66bac90391379603d962\", \"price_changes\":[{\"asset_id\":\"39272994714739463168905443499424551362424437245880253267329605556587274644733\", \"price\":\"0.45\", \"size\":\"201.5\", \"side\":\"BUY\", \"hash\":\"0c9a0ba83b2ed1d09eb5887f7b6da0f89f73655d\", \"best_bid\":\"0.57\", \"best_ask\":\"0.58\"}, {\"asset_id\":\"20893381255801015515826997628594359667013752732428989472914000440642900266717\", \"price\":\"0.55\", \"size\":\"201.5\", \"side\":\"SELL\", \"hash\":\"35188f105347fe20911a0eb5e753f3f353e0b420\", \"best_bid\":\"0.42\", \"best_ask\":\"0.43\"}], \"timestamp\":\"1785204134234\", \"event_type\":\"price_change\"}","received_at":"2026-07-28T02:02:15.712617Z","schema_version":"clob-market-ws.price_change.v1","sequence":null,"server_hash":null,"server_timestamp":"1785204134234","session_id":"d2757dd6dad94f3b9fe67e8dbf1adc37","source":"clob_market_ws"},"received_at":"2026-07-28T02:02:15.712617Z","record_id":"ce69d4e7871499d3f2a10b2711f8a98546d46eefad21a7efe1a4f1b4e2c4f2f0","schema_fingerprint":"4aa3821a28b0b7c2400bc59aba4bcc0a76e971dadd19610d3ad38c768e124dc7","schema_version":"edge-lab-recorder.raw.v1","sequence":null,"source":"clob_market_ws"}
{"event_at":"2026-07-28T02:02:14.234000Z","event_fingerprint":"1fbd9a51a8897ac541ccc6f9aed3133aead5e8e68dc50cc0d5e42840c0f17915","payload":{"connection_id":"5d29200f65794d4d9ab6ef271f045a9b","event_at":"2026-07-28T02:02:14.234000Z","event_type":"price_change","frame_hash":"62f7fe653d777dd01c81bdf75b81455c6ae8167d1a8e75259ea99f0d817a808d","frame_index":0,"kind":"data","monotonic_ns":306118728994750,"payload":{"event_type":"price_change","market":"0xda6f0e0e93fc8469e0159a166028d017bddbc162b86f66bac90391379603d962","price_changes":[{"asset_id":"20893381255801015515826997628594359667013752732428989472914000440642900266717","best_ask":"0.43","best_bid":"0.42","hash":"84c5585943369dc8b09ae66b366183f2f34ab552","price":"0.4","side":"BUY","size":"86.68"},{"asset_id":"39272994714739463168905443499424551362424437245880253267329605556587274644733","best_ask":"0.58","best_bid":"0.57","hash":"98453cea181544c94d34b50beb0ffe3879655abb","price":"0.6","side":"SELL","size":"86.68"}],"timestamp":"1785204134234"},"payload_hash":"0a43a2d5258c63821095d756e33df4bea3455db9aa3409281449efe3ed06ab25","raw_frame":"{\"market\":\"0xda6f0e0e93fc8469e0159a166028d017bddbc162b86f66bac90391379603d962\", \"price_changes\":[{\"asset_id\":\"20893381255801015515826997628594359667013752732428989472914000440642900266717\", \"price\":\"0.4\", \"size\":\"86.68\", \"side\":\"BUY\", \"hash\":\"84c5585943369dc8b09ae66b366183f2f34ab552\", \"best_bid\":\"0.42\", \"best_ask\":\"0.43\"}, {\"asset_id\":\"39272994714739463168905443499424551362424437245880253267329605556587274644733\", \"price\":\"0.6\", \"size\":\"86.68\", \"side\":\"SELL\", \"hash\":\"98453cea181544c94d34b50beb0ffe3879655abb\", \"best_bid\":\"0.57\", \"best_ask\":\"0.58\"}], \"timestamp\":\"1785204134234\", \"event_type\":\"price_change\"}","received_at":"2026-07-28T02:02:15.724597Z","schema_version":"clob-market-ws.price_change.v1","sequence":null,"server_hash":null,"server_timestamp":"1785204134234","session_id":"d2757dd6dad94f3b9fe67e8dbf1adc37","source":"clob_market_ws"},"received_at":"2026-07-28T02:02:15.724597Z","record_id":"386bd9d72510f131a3a53545f5a2beaba837c762a817589f8edde5a8c9d0c4ad","schema_fingerprint":"4aa3821a28b0b7c2400bc59aba4bcc0a76e971dadd19610d3ad38c768e124dc7","schema_version":"edge-lab-recorder.raw.v1","sequence":null,"source":"clob_market_ws"}
{"event_at":"2026-07-28T02:02:14.235000Z","event_fingerprint":"8d9438d965da760cba163e1c18487c20598059dcdfc05f2070efb7afc92e323d","payload":{"connection_id":"5d29200f65794d4d9ab6ef271f045a9b","event_at":"2026-07-28T02:02:14.235000Z","event_type":"price_change","frame_hash":"7869b5720fb074636781597ffeeb104e4a5a2d0f1aeb168198f85c047702a234","frame_index":0,"kind":"data","monotonic_ns":306118744029583,"payload":{"event_type":"price_change","market":"0xda6f0e0e93fc8469e0159a166028d017bddbc162b86f66bac90391379603d962","price_changes":[{"asset_id":"39272994714739463168905443499424551362424437245880253267329605556587274644733","best_ask":"0.58","best_bid":"0.57","hash":"083e8206cefd8b5295ff87f2d585e0c2ccbd5898","price":"0.4","side":"BUY","size":"99.5"},{"asset_id":"20893381255801015515826997628594359667013752732428989472914000440642900266717","best_ask":"0.43","best_bid":"0.42","hash":"fa2d68cf62a068ca3be79afb9104825b6207b013","price":"0.6","side":"SELL","size":"99.5"}],"timestamp":"1785204134235"},"payload_hash":"a82cb3b1eefbcd99c9185d214c58433a5f6ddeea953353aa825efc3e61fb83d4","raw_frame":"{\"market\":\"0xda6f0e0e93fc8469e0159a166028d017bddbc162b86f66bac90391379603d962\", \"price_changes\":[{\"asset_id\":\"39272994714739463168905443499424551362424437245880253267329605556587274644733\", \"price\":\"0.4\", \"size\":\"99.5\", \"side\":\"BUY\", \"hash\":\"083e8206cefd8b5295ff87f2d585e0c2ccbd5898\", \"best_bid\":\"0.57\", \"best_ask\":\"0.58\"}, {\"asset_id\":\"20893381255801015515826997628594359667013752732428989472914000440642900266717\", \"price\":\"0.6\", \"size\":\"99.5\", \"side\":\"SELL\", \"hash\":\"fa2d68cf62a068ca3be79afb9104825b6207b013\", \"best_bid\":\"0.42\", \"best_ask\":\"0.43\"}], \"timestamp\":\"1785204134235\", \"event_type\":\"price_change\"}","received_at":"2026-07-28T02:02:15.739629Z","schema_version":"clob-market-ws.price_change.v1","sequence":null,"server_hash":null,"server_timestamp":"1785204134235","session_id":"d2757dd6dad94f3b9fe67e8dbf1adc37","source":"clob_market_ws"},"received_at":"2026-07-28T02:02:15.739629Z","record_id":"446d645103f5bd5a948f2b8c63f263050b70bacf857b06cc7fa2b2084a951b36","schema_fingerprint":"4aa3821a28b0b7c2400bc59aba4bcc0a76e971dadd19610d3ad38c768e124dc7","schema_version":"edge-lab-recorder.raw.v1","sequence":null,"source":"clob_market_ws"}
{"event_at":"2026-07-28T02:02:14.242000Z","event_fingerprint":"ae6cb035aeb3f3435693d68f3307b0eabafeedb6e46c4ce9f9d9803f6d22e1db","payload":{"connection_id":"5d29200f65794d4d9ab6ef271f045a9b","event_at":"2026-07-28T02:02:14.242000Z","event_type":"price_change","frame_hash":"a85ca2ef268e3b6991969e631e19e7f3350d334a62b43391df6458944e601b18","frame_index":0,"kind":"data","monotonic_ns":306118750642041,"payload":{"event_type":"price_change","market":"0xda6f0e0e93fc8469e0159a166028d017bddbc162b86f66bac90391379603d962","price_changes":[{"asset_id":"20893381255801015515826997628594359667013752732428989472914000440642900266717","best_ask":"0.43","best_bid":"0.42","hash":"c99e120b77b2bbf5e547221acf5125a088095ae0","price":"0.32","side":"BUY","size":"248.8"},{"asset_id":"39272994714739463168905443499424551362424437245880253267329605556587274644733","best_ask":"0.58","best_bid":"0.57","hash":"e31e386b98dacf6519d22e54f7f914f78304601c","price":"0.68","side":"SELL","size":"248.8"}],"timestamp":"1785204134242"},"payload_hash":"c1450c2802716deabbe4528e93b87b693ae520c8cdf03f6e57b2e356d7b00159","raw_frame":"{\"market\":\"0xda6f0e0e93fc8469e0159a166028d017bddbc162b86f66bac90391379603d962\", \"price_changes\":[{\"asset_id\":\"20893381255801015515826997628594359667013752732428989472914000440642900266717\", \"price\":\"0.32\", \"size\":\"248.8\", \"side\":\"BUY\", \"hash\":\"c99e120b77b2bbf5e547221acf5125a088095ae0\", \"best_bid\":\"0.42\", \"best_ask\":\"0.43\"}, {\"asset_id\":\"39272994714739463168905443499424551362424437245880253267329605556587274644733\", \"price\":\"0.68\", \"size\":\"248.8\", \"side\":\"SELL\", \"hash\":\"e31e386b98dacf6519d22e54f7f914f78304601c\", \"best_bid\":\"0.57\", \"best_ask\":\"0.58\"}], \"timestamp\":\"1785204134242\", \"event_type\":\"price_change\"}","received_at":"2026-07-28T02:02:15.746246Z","schema_version":"clob-market-ws.price_change.v1","sequence":null,"server_hash":null,"server_timestamp":"1785204134242","session_id":"d2757dd6dad94f3b9fe67e8dbf1adc37","source":"clob_market_ws"},"received_at":"2026-07-28T02:02:15.746246Z","record_id":"04a06886f7031117d391005a26c7fa10839e0bc6f9327fada6bc884179e3b2d2","schema_fingerprint":"4aa3821a28b0b7c2400bc59aba4bcc0a76e971dadd19610d3ad38c768e124dc7","schema_version":"edge-lab-recorder.raw.v1","sequence":null,"source":"clob_market_ws"}
{"event_at":"2026-07-28T02:02:14.242000Z","event_fingerprint":"d177ed31ccbd23cd2bfc1883ec7442d5f42c513b2796aadb489409e3d99ee250","payload":{"connection_id":"5d29200f65794d4d9ab6ef271f045a9b","event_at":"2026-07-28T02:02:14.242000Z","event_type":"price_change","frame_hash":"6bb451039404891b12e98a013600d3301449d27aee92d9dfc6ffe03c5518bb5d","frame_index":0,"kind":"data","monotonic_ns":306118755158333,"payload":{"event_type":"price_change","market":"0xda6f0e0e93fc8469e0159a166028d017bddbc162b86f66bac90391379603d962","price_changes":[{"asset_id":"39272994714739463168905443499424551362424437245880253267329605556587274644733","best_ask":"0.58","best_bid":"0.57","hash":"e31e386b98dacf6519d22e54f7f914f78304601c","price":"0.45","side":"BUY","size":"194"},{"asset_id":"20893381255801015515826997628594359667013752732428989472914000440642900266717","best_ask":"0.43","best_bid":"0.42","hash":"c99e120b77b2bbf5e547221acf5125a088095ae0","price":"0.55","side":"SELL","size":"194"}],"timestamp":"1785204134242"},"payload_hash":"0f12cf84f0066f94a6794e43d4bf38d543bfb6d27e2bfb4335b2998a14ae5107","raw_frame":"{\"market\":\"0xda6f0e0e93fc8469e0159a166028d017bddbc162b86f66bac90391379603d962\", \"price_changes\":[{\"asset_id\":\"39272994714739463168905443499424551362424437245880253267329605556587274644733\", \"price\":\"0.45\", \"size\":\"194\", \"side\":\"BUY\", \"hash\":\"e31e386b98dacf6519d22e54f7f914f78304601c\", \"best_bid\":\"0.57\", \"best_ask\":\"0.58\"}, {\"asset_id\":\"20893381255801015515826997628594359667013752732428989472914000440642900266717\", \"price\":\"0.55\", \"size\":\"194\", \"side\":\"SELL\", \"hash\":\"c99e120b77b2bbf5e547221acf5125a088095ae0\", \"best_bid\":\"0.42\", \"best_ask\":\"0.43\"}], \"timestamp\":\"1785204134242\", \"event_type\":\"price_change\"}","received_at":"2026-07-28T02:02:15.750762Z","schema_version":"clob-market-ws.price_change.v1","sequence":null,"server_hash":null,"server_timestamp":"1785204134242","session_id":"d2757dd6dad94f3b9fe67e8dbf1adc37","source":"clob_market_ws"},"received_at":"2026-07-28T02:02:15.750762Z","record_id":"09a5eb695e0895fce1a629863e4b56d2475f90aaac2aa3a84d2d2324b2ab1dbc","schema_fingerprint":"4aa3821a28b0b7c2400bc59aba4bcc0a76e971dadd19610d3ad38c768e124dc7","schema_version":"edge-lab-recorder.raw.v1","sequence":null,"source":"clob_market_ws"}
{"event_at":"2026-07-28T02:02:14.253000Z","event_fingerprint":"56109144415eb2f41551c48e29342f77441ecd78218095c67fc5ba025d8e06c6","payload":{"connection_id":"5d29200f65794d4d9ab6ef271f045a9b","event_at":"2026-07-28T02:02:14.253000Z","event_type":"price_change","frame_hash":"a4282626dc35b4eb3bb32da04d946352abccfae08fa344690dfa46bfbc1d26e5","frame_index":0,"kind":"data","monotonic_ns":306118759628791,"payload":{"event_type":"price_change","market":"0xda6f0e0e93fc8469e0159a166028d017bddbc162b86f66bac90391379603d962","price_changes":[{"asset_id":"39272994714739463168905443499424551362424437245880253267329605556587274644733","best_ask":"0.58","best_bid":"0.57","hash":"8d45354d63a2749d421775a5e2aa8e988c2215e5","price":"0.55","side":"BUY","size":"59.6"},{"asset_id":"20893381255801015515826997628594359667013752732428989472914000440642900266717","best_ask":"0.43","best_bid":"0.42","hash":"2fb0967a44499fa4799af15acbbc598c58384259","price":"0.45","side":"SELL","size":"59.6"}],"timestamp":"1785204134253"},"payload_hash":"4dd2f3afceb62ac5afd85f586d30dbbb3c02da571a67f5fce233c4d95d129d78","raw_frame":"{\"market\":\"0xda6f0e0e93fc8469e0159a166028d017bddbc162b86f66bac90391379603d962\", \"price_changes\":[{\"asset_id\":\"39272994714739463168905443499424551362424437245880253267329605556587274644733\", \"price\":\"0.55\", \"size\":\"59.6\", \"side\":\"BUY\", \"hash\":\"8d45354d63a2749d421775a5e2aa8e988c2215e5\", \"best_bid\":\"0.57\", \"best_ask\":\"0.58\"}, {\"asset_id\":\"20893381255801015515826997628594359667013752732428989472914000440642900266717\", \"price\":\"0.45\", \"size\":\"59.6\", \"side\":\"SELL\", \"hash\":\"2fb0967a44499fa4799af15acbbc598c58384259\", \"best_bid\":\"0.42\", \"best_ask\":\"0.43\"}], \"timestamp\":\"1785204134253\", \"event_type\":\"price_change\"}","received_at":"2026-07-28T02:02:15.755233Z","schema_version":"clob-market-ws.price_change.v1","sequence":null,"server_hash":null,"server_timestamp":"1785204134253","session_id":"d2757dd6dad94f3b9fe67e8dbf1adc37","source":"clob_market_ws"},"received_at":"2026-07-28T02:02:15.755233Z","record_id":"bec5f0597e357c0c7b3cfe61c40edf8613722941fde37cf05fefdc3824948d5f","schema_fingerprint":"4aa3821a28b0b7c2400bc59aba4bcc0a76e971dadd19610d3ad38c768e124dc7","schema_version":"edge-lab-recorder.raw.v1","sequence":null,"source":"clob_market_ws"}
{"event_at":"2026-07-28T02:02:14.253000Z","event_fingerprint":"ec9b2529c4bf88b9fd744713fe1437918bab2b0032406521cdfa9480f58c39b9","payload":{"connection_id":"5d29200f65794d4d9ab6ef271f045a9b","event_at":"2026-07-28T02:02:14.253000Z","event_type":"price_change","frame_hash":"92e4ca400571ea15c1a3fec2b6b64757f2fbe812667627ab9fa2a59a126e9a61","frame_index":0,"kind":"data","monotonic_ns":306118763492500,"payload":{"event_type":"price_change","market":"0xda6f0e0e93fc8469e0159a166028d017bddbc162b86f66bac90391379603d962","price_changes":[{"asset_id":"39272994714739463168905443499424551362424437245880253267329605556587274644733","best_ask":"0.58","best_bid":"0.57","hash":"f906f4e1f2e57716e80fd24b89db23164f07b637","price":"0.05","side":"BUY","size":"873.2"},{"asset_id":"20893381255801015515826997628594359667013752732428989472914000440642900266717","best_ask":"0.43","best_bid":"0.42","hash":"39ea558dec5a785f7e3f64aba3ad757acff24697","price":"0.95","side":"SELL","size":"873.2"}],"timestamp":"1785204134253"},"payload_hash":"52ee8bc1d862a6273a2d2eb20a0e59825d2d6782d8c9adee8edb01080b20c400","raw_frame":"{\"market\":\"0xda6f0e0e93fc8469e0159a166028d017bddbc162b86f66bac90391379603d962\", \"price_changes\":[{\"asset_id\":\"39272994714739463168905443499424551362424437245880253267329605556587274644733\", \"price\":\"0.05\", \"size\":\"873.2\", \"side\":\"BUY\", \"hash\":\"f906f4e1f2e57716e80fd24b89db23164f07b637\", \"best_bid\":\"0.57\", \"best_ask\":\"0.58\"}, {\"asset_id\":\"20893381255801015515826997628594359667013752732428989472914000440642900266717\", \"price\":\"0.95\", \"size\":\"873.2\", \"side\":\"SELL\", \"hash\":\"39ea558dec5a785f7e3f64aba3ad757acff24697\", \"best_bid\":\"0.42\", \"best_ask\":\"0.43\"}], \"timestamp\":\"1785204134253\", \"event_type\":\"price_change\"}","received_at":"2026-07-28T02:02:15.759098Z","schema_version":"clob-market-ws.price_change.v1","sequence":null,"server_hash":null,"server_timestamp":"1785204134253","session_id":"d2757dd6dad94f3b9fe67e8dbf1adc37","source":"clob_market_ws"},"received_at":"2026-07-28T02:02:15.759098Z","record_id":"98cfd390c55697e548a9630f607622e7bb360959c2d9d1e594843c20fc4ff119","schema_fingerprint":"4aa3821a28b0b7c2400bc59aba4bcc0a76e971dadd19610d3ad38c768e124dc7","schema_version":"edge-lab-recorder.raw.v1","sequence":null,"source":"clob_market_ws"}
{"event_at":"2026-07-28T02:02:14.254000Z","event_fingerprint":"2b4caf89dd45583730d03730ac8431924a1f26697a122d36a23ce22c7031dce8","payload":{"connection_id":"5d29200f65794d4d9ab6ef271f045a9b","event_at":"2026-07-28T02:02:14.254000Z","event_type":"price_change","frame_hash":"d3836718fa00d20ec244a148f7e2f6e3f3f926039ec680be162356e9685ebd4f","frame_index":0,"kind":"data","monotonic_ns":306118769390750,"payload":{"event_type":"price_change","market":"0xda6f0e0e93fc8469e0159a166028d017bddbc162b86f66bac90391379603d962","price_changes":[{"asset_id":"20893381255801015515826997628594359667013752732428989472914000440642900266717","best_ask":"0.43","best_bid":"0.42","hash":"8fb293eab342f8c57db2bc30d6fb2a3d96feda8f","price":"0.03","side":"BUY","size":"746.43"},{"asset_id":"39272994714739463168905443499424551362424437245880253267329605556587274644733","best_ask":"0.58","best_bid":"0.57","hash":"6fed065e3c36ea9507d420f201b8b15927390500","price":"0.97","side":"SELL","size":"746.43"}],"timestamp":"1785204134254"},"payload_hash":"6200d75a91d60d20867a8be24c1ea9d3767409f5459ed3a6fc30777e65d67e8c","raw_frame":"{\"market\":\"0xda6f0e0e93fc8469e0159a166028d017bddbc162b86f66bac90391379603d962\", \"price_changes\":[{\"asset_id\":\"20893381255801015515826997628594359667013752732428989472914000440642900266717\", \"price\":\"0.03\", \"size\":\"746.43\", \"side\":\"BUY\", \"hash\":\"8fb293eab342f8c57db2bc30d6fb2a3d96feda8f\", \"best_bid\":\"0.42\", \"best_ask\":\"0.43\"}, {\"asset_id\":\"39272994714739463168905443499424551362424437245880253267329605556587274644733\", \"price\":\"0.97\", \"size\":\"746.43\", \"side\":\"SELL\", \"hash\":\"6fed065e3c36ea9507d420f201b8b15927390500\", \"best_bid\":\"0.57\", \"best_ask\":\"0.58\"}], \"timestamp\":\"1785204134254\", \"event_type\":\"price_change\"}","received_at":"2026-07-28T02:02:15.764996Z","schema_version":"clob-market-ws.price_change.v1","sequence":null,"server_hash":null,"server_timestamp":"1785204134254","session_id":"d2757dd6dad94f3b9fe67e8dbf1adc37","source":"clob_market_ws"},"received_at":"2026-07-28T02:02:15.764996Z","record_id":"4d0ac108f503e2dd2093101c8532fa163cb51392f3941b63c47fe7a7978ae7bb","schema_fingerprint":"4aa3821a28b0b7c2400bc59aba4bcc0a76e971dadd19610d3ad38c768e124dc7","schema_version":"edge-lab-recorder.raw.v1","sequence":null,"source":"clob_market_ws"}
{"event_at":"2026-07-28T02:02:14.256000Z","event_fingerprint":"cdb3fc164507b3adbaae00c7ad09f2eb5b27444b5d15c63adff47c6adba00eea","payload":{"connection_id":"5d29200f65794d4d9ab6ef271f045a9b","event_at":"2026-07-28T02:02:14.256000Z","event_type":"price_change","frame_hash":"ebaf1e3b5e669f45bc7155779aba830b261cf6ac50ddbbe6f1699d71f400688f","frame_index":0,"kind":"data","monotonic_ns":306118776015958,"payload":{"event_type":"price_change","market":"0xda6f0e0e93fc8469e0159a166028d017bddbc162b86f66bac90391379603d962","price_changes":[{"asset_id":"39272994714739463168905443499424551362424437245880253267329605556587274644733","best_ask":"0.58","best_bid":"0.57","hash":"1f709dd82fdd562971f4a58a5ca9429dc407eb85","price":"0.53","side":"BUY","size":"105.03"},{"asset_id":"20893381255801015515826997628594359667013752732428989472914000440642900266717","best_ask":"0.43","best_bid":"0.42","hash":"bb15259d8d12b09b3b04d9049ce4a6b23a070ef7","price":"0.47","side":"SELL","size":"105.03"}],"timestamp":"1785204134256"},"payload_hash":"4e7d1b74fa75b11028552f0c0c6cdce22c12f7b0bbdd37de12c44c03acd01166","raw_frame":"{\"market\":\"0xda6f0e0e93fc8469e0159a166028d017bddbc162b86f66bac90391379603d962\", \"price_changes\":[{\"asset_id\":\"39272994714739463168905443499424551362424437245880253267329605556587274644733\", \"price\":\"0.53\", \"size\":\"105.03\", \"side\":\"BUY\", \"hash\":\"1f709dd82fdd562971f4a58a5ca9429dc407eb85\", \"best_bid\":\"0.57\", \"best_ask\":\"0.58\"}, {\"asset_id\":\"20893381255801015515826997628594359667013752732428989472914000440642900266717\", \"price\":\"0.47\", \"size\":\"105.03\", \"side\":\"SELL\", \"hash\":\"bb15259d8d12b09b3b04d9049ce4a6b23a070ef7\", \"best_bid\":\"0.42\", \"best_ask\":\"0.43\"}], \"timestamp\":\"1785204134256\", \"event_type\":\"price_change\"}","received_at":"2026-07-28T02:02:15.771621Z","schema_version":"clob-market-ws.price_change.v1","sequence":null,"server_hash":null,"server_timestamp":"1785204134256","session_id":"d2757dd6dad94f3b9fe67e8dbf1adc37","source":"clob_market_ws"},"received_at":"2026-07-28T02:02:15.771621Z","record_id":"fb3bb35e7c43f0998de7c95dec53afa65e663d6ac5e95c25fd15d3ab95a99f40","schema_fingerprint":"4aa3821a28b0b7c2400bc59aba4bcc0a76e971dadd19610d3ad38c768e124dc7","schema_version":"edge-lab-recorder.raw.v1","sequence":null,"source":"clob_market_ws"}
{"event_at":"2026-07-28T02:02:14.258000Z","event_fingerprint":"8b53c830aecfaf3342089b5f40a7a341b4c74247b42f4f644afa00d9f8d6139f","payload":{"connection_id":"5d29200f65794d4d9ab6ef271f045a9b","event_at":"2026-07-28T02:02:14.258000Z","event_type":"price_change","frame_hash":"4b1e9047a6248ee438a5f21b4a4f1824c51d6daed0fbd34bd2b837e251547515","frame_index":0,"kind":"data","monotonic_ns":306118781207166,"payload":{"event_type":"price_change","market":"0xda6f0e0e93fc8469e0159a166028d017bddbc162b86f66bac90391379603d962","price_changes":[{"asset_id":"39272994714739463168905443499424551362424437245880253267329605556587274644733","best_ask":"0.58","best_bid":"0.57","hash":"ad721c37d2efec066a00f5932ecd797506463139","price":"0.54","side":"BUY","size":"378"},{"asset_id":"20893381255801015515826997628594359667013752732428989472914000440642900266717","best_ask":"0.43","best_bid":"0.42","hash":"5a46fc9a0a721a379b6be57c5cb91e439e139919","price":"0.46","side":"SELL","size":"378"}],"timestamp":"1785204134258"},"payload_hash":"e92be095a84a5a13f1bda29e3ae53a885bc5f94731dad4f19c8a861b47e5da6f","raw_frame":"{\"market\":\"0xda6f0e0e93fc8469e0159a166028d017bddbc162b86f66bac90391379603d962\", \"price_changes\":[{\"asset_id\":\"39272994714739463168905443499424551362424437245880253267329605556587274644733\", \"price\":\"0.54\", \"size\":\"378\", \"side\":\"BUY\", \"hash\":\"ad721c37d2efec066a00f5932ecd797506463139\", \"best_bid\":\"0.57\", \"best_ask\":\"0.58\"}, {\"asset_id\":\"20893381255801015515826997628594359667013752732428989472914000440642900266717\", \"price\":\"0.46\", \"size\":\"378\", \"side\":\"SELL\", \"hash\":\"5a46fc9a0a721a379b6be57c5cb91e439e139919\", \"best_bid\":\"0.42\", \"best_ask\":\"0.43\"}], \"timestamp\":\"1785204134258\", \"event_type\":\"price_change\"}","received_at":"2026-07-28T02:02:15.776812Z","schema_version":"clob-market-ws.price_change.v1","sequence":null,"server_hash":null,"server_timestamp":"1785204134258","session_id":"d2757dd6dad94f3b9fe67e8dbf1adc37","source":"clob_market_ws"},"received_at":"2026-07-28T02:02:15.776812Z","record_id":"937cb80f45f6b5826b4911122a292993808efab84844a423332c448f44997c2a","schema_fingerprint":"4aa3821a28b0b7c2400bc59aba4bcc0a76e971dadd19610d3ad38c768e124dc7","schema_version":"edge-lab-recorder.raw.v1","sequence":null,"source":"clob_market_ws"}
{"event_at":"2026-07-28T02:02:14.260000Z","event_fingerprint":"9594ceae2aa90e2ed670242d3b645f758584d92f7f9fadbbf0546831c5af6fbd","payload":{"connection_id":"5d29200f65794d4d9ab6ef271f045a9b","event_at":"2026-07-28T02:02:14.260000Z","event_type":"price_change","frame_hash":"889a7de5080917d27816e1e1f55e971b8eab2e635c5882437de3ce35515c5ee3","frame_index":0,"kind":"data","monotonic_ns":306118788923291,"payload":{"event_type":"price_change","market":"0xda6f0e0e93fc8469e0159a166028d017bddbc162b86f66bac90391379603d962","price_changes":[{"asset_id":"20893381255801015515826997628594359667013752732428989472914000440642900266717","best_ask":"0.43","best_bid":"0.42","hash":"ab6cbfd9ef4fa56f375d6841862ed7e1319188e9","price":"0.37","side":"BUY","size":"219.4"},{"asset_id":"39272994714739463168905443499424551362424437245880253267329605556587274644733","best_ask":"0.58","best_bid":"0.57","hash":"f8d1c797d2727485a6f815418d09687e68635f1a","price":"0.63","side":"SELL","size":"219.4"}],"timestamp":"1785204134260"},"payload_hash":"f138e857f2d1533dd86773629b63b11e69c5eeeb9963f29165b2138165b54643","raw_frame":"{\"market\":\"0xda6f0e0e93fc8469e0159a166028d017bddbc162b86f66bac90391379603d962\", \"price_changes\":[{\"asset_id\":\"20893381255801015515826997628594359667013752732428989472914000440642900266717\", \"price\":\"0.37\", \"size\":\"219.4\", \"side\":\"BUY\", \"hash\":\"ab6cbfd9ef4fa56f375d6841862ed7e1319188e9\", \"best_bid\":\"0.42\", \"best_ask\":\"0.43\"}, {\"asset_id\":\"39272994714739463168905443499424551362424437245880253267329605556587274644733\", \"price\":\"0.63\", \"size\":\"219.4\", \"side\":\"SELL\", \"hash\":\"f8d1c797d2727485a6f815418d09687e68635f1a\", \"best_bid\":\"0.57\", \"best_ask\":\"0.58\"}], \"timestamp\":\"1785204134260\", \"event_type\":\"price_change\"}","received_at":"2026-07-28T02:02:15.784527Z","schema_version":"clob-market-ws.price_change.v1","sequence":null,"server_hash":null,"server_timestamp":"1785204134260","session_id":"d2757dd6dad94f3b9fe67e8dbf1adc37","source":"clob_market_ws"},"received_at":"2026-07-28T02:02:15.784527Z","record_id":"b8a98972efe26f11c6717d6c8ec6919b5d1f56494bbe5953ba9def33cf76fe1e","schema_fingerprint":"4aa3821a28b0b7c2400bc59aba4bcc0a76e971dadd19610d3ad38c768e124dc7","schema_version":"edge-lab-recorder.raw.v1","sequence":null,"source":"clob_market_ws"}
{"event_at":"2026-07-28T02:02:14.262000Z","event_fingerprint":"a506ed00fde1fdabbeac6db4f25159f3ac699a80b20e4ee2dcc20cbb0eb75c70","payload":{"connection_id":"5d29200f65794d4d9ab6ef271f045a9b","event_at":"2026-07-28T02:02:14.262000Z","event_type":"price_change","frame_hash":"95c0f6c0df0c7eb0a9ba10ddc217fd9c8118afeb67b9a09b80a7ee39d7a2aa6a","frame_index":0,"kind":"data","monotonic_ns":306118794334291,"payload":{"event_type":"price_change","market":"0xda6f0e0e93fc8469e0159a166028d017bddbc162b86f66bac90391379603d962","price_changes":[{"asset_id":"39272994714739463168905443499424551362424437245880253267329605556587274644733","best_ask":"0.58","best_bid":"0.57","hash":"4a29c972a2b77a49c9fb957b9ac19fa61681019e","price":"0.48","side":"BUY","size":"252.05"},{"asset_id":"20893381255801015515826997628594359667013752732428989472914000440642900266717","best_ask":"0.43","best_bid":"0.42","hash":"5d1d6e3b85322c069bf57b2945aae31531a18496","price":"0.52","side":"SELL","size":"252.05"}],"timestamp":"1785204134262"},"payload_hash":"81e281646527aaa03ed0f112db0f04bf5ff69c99a1d5b05de12b8354ad7574b7","raw_frame":"{\"market\":\"0xda6f0e0e93fc8469e0159a166028d017bddbc162b86f66bac90391379603d962\", \"price_changes\":[{\"asset_id\":\"39272994714739463168905443499424551362424437245880253267329605556587274644733\", \"price\":\"0.48\", \"size\":\"252.05\", \"side\":\"BUY\", \"hash\":\"4a29c972a2b77a49c9fb957b9ac19fa61681019e\", \"best_bid\":\"0.57\", \"best_ask\":\"0.58\"}, {\"asset_id\":\"20893381255801015515826997628594359667013752732428989472914000440642900266717\", \"price\":\"0.52\", \"size\":\"252.05\", \"side\":\"SELL\", \"hash\":\"5d1d6e3b85322c069bf57b2945aae31531a18496\", \"best_bid\":\"0.42\", \"best_ask\":\"0.43\"}], \"timestamp\":\"1785204134262\", \"event_type\":\"price_change\"}","received_at":"2026-07-28T02:02:15.789939Z","schema_version":"clob-market-ws.price_change.v1","sequence":null,"server_hash":null,"server_timestamp":"1785204134262","session_id":"d2757dd6dad94f3b9fe67e8dbf1adc37","source":"clob_market_ws"},"received_at":"2026-07-28T02:02:15.789939Z","record_id":"d9849858cddbe73418c4d9363157b996f5cead06103a16449d82d30cb94dc3fd","schema_fingerprint":"4aa3821a28b0b7c2400bc59aba4bcc0a76e971dadd19610d3ad38c768e124dc7","schema_version":"edge-lab-recorder.raw.v1","sequence":null,"source":"clob_market_ws"}
{"event_at":"2026-07-28T02:02:14.263000Z","event_fingerprint":"4bbceac54fc2eeae9121bd28e4917ebd6cc8101f75ad1590f36e086c2f9563ce","payload":{"connection_id":"5d29200f65794d4d9ab6ef271f045a9b","event_at":"2026-07-28T02:02:14.263000Z","event_type":"price_change","frame_hash":"6be5650aecbac003675546bf545a6d4f266814820d61528f30e452abddd7177c","frame_index":0,"kind":"data","monotonic_ns":306118798468208,"payload":{"event_type":"price_change","market":"0xda6f0e0e93fc8469e0159a166028d017bddbc162b86f66bac90391379603d962","price_changes":[{"asset_id":"39272994714739463168905443499424551362424437245880253267329605556587274644733","best_ask":"0.58","best_bid":"0.57","hash":"106d051dbf096d0a8cfb51a03cb4910487dfb4d7","price":"0.54","side":"BUY","size":"108"},{"asset_id":"20893381255801015515826997628594359667013752732428989472914000440642900266717","best_ask":"0.43","best_bid":"0.42","hash":"5366d99f6fce7a34fe0ddd4639d85961b8ed607e","price":"0.46","side":"SELL","size":"108"}],"timestamp":"1785204134263"},"payload_hash":"99597e7b152ec7992982dbc1986a6e7dfd104fc61cf0745e08a8ef585d47fc2f","raw_frame":"{\"market\":\"0xda6f0e0e93fc8469e0159a166028d017bddbc162b86f66bac90391379603d962\", \"price_changes\":[{\"asset_id\":\"39272994714739463168905443499424551362424437245880253267329605556587274644733\", \"price\":\"0.54\", \"size\":\"108\", \"side\":\"BUY\", \"hash\":\"106d051dbf096d0a8cfb51a03cb4910487dfb4d7\", \"best_bid\":\"0.57\", \"best_ask\":\"0.58\"}, {\"asset_id\":\"20893381255801015515826997628594359667013752732428989472914000440642900266717\", \"price\":\"0.46\", \"size\":\"108\", \"side\":\"SELL\", \"hash\":\"5366d99f6fce7a34fe0ddd4639d85961b8ed607e\", \"best_bid\":\"0.42\", \"best_ask\":\"0.43\"}], \"timestamp\":\"1785204134263\", \"event_type\":\"price_change\"}","received_at":"2026-07-28T02:02:15.794072Z","schema_version":"clob-market-ws.price_change.v1","sequence":null,"server_hash":null,"server_timestamp":"1785204134263","session_id":"d2757dd6dad94f3b9fe67e8dbf1adc37","source":"clob_market_ws"},"received_at":"2026-07-28T02:02:15.794072Z","record_id":"7420037c30f56631c4f1d93869794c11c039c6f0e2e425271f2e33c658f94bc9","schema_fingerprint":"4aa3821a28b0b7c2400bc59aba4bcc0a76e971dadd19610d3ad38c768e124dc7","schema_version":"edge-lab-recorder.raw.v1","sequence":null,"source":"clob_market_ws"}
{"event_at":"2026-07-28T02:02:14.265000Z","event_fingerprint":"eb114bec6b4b69eace0fac12501e29fe7f41af15b81110101981f9dcc6c5ae36","payload":{"connection_id":"5d29200f65794d4d9ab6ef271f045a9b","event_at":"2026-07-28T02:02:14.265000Z","event_type":"price_change","frame_hash":"1dbcb57bddf74130a6d07d8dec1977f8b69b74f33308af2617c7c3e41f371c8f","frame_index":0,"kind":"data","monotonic_ns":306118806589000,"payload":{"event_type":"price_change","market":"0xda6f0e0e93fc8469e0159a166028d017bddbc162b86f66bac90391379603d962","price_changes":[{"asset_id":"39272994714739463168905443499424551362424437245880253267329605556587274644733","best_ask":"0.58","best_bid":"0.57","hash":"8c2e127a6e603cda2af2977dbccba910bce9c41f","price":"0.48","side":"BUY","size":"282.05"},{"asset_id":"20893381255801015515826997628594359667013752732428989472914000440642900266717","best_ask":"0.43","best_bid":"0.42","hash":"a3ee9ea68a4ba44f35d13f00d8bfa23db4c5b976","price":"0.52","side":"SELL","size":"282.05"}],"timestamp":"1785204134265"},"payload_hash":"22e289b1fa87df1e666f4c23f9a7c855bf9aa37270001fc32d8c2b9ff1249b5e","raw_frame":"{\"market\":\"0xda6f0e0e93fc8469e0159a166028d017bddbc162b86f66bac90391379603d962\", \"price_changes\":[{\"asset_id\":\"39272994714739463168905443499424551362424437245880253267329605556587274644733\", \"price\":\"0.48\", \"size\":\"282.05\", \"side\":\"BUY\", \"hash\":\"8c2e127a6e603cda2af2977dbccba910bce9c41f\", \"best_bid\":\"0.57\", \"best_ask\":\"0.58\"}, {\"asset_id\":\"20893381255801015515826997628594359667013752732428989472914000440642900266717\", \"price\":\"0.52\", \"size\":\"282.05\", \"side\":\"SELL\", \"hash\":\"a3ee9ea68a4ba44f35d13f00d8bfa23db4c5b976\", \"best_bid\":\"0.42\", \"best_ask\":\"0.43\"}], \"timestamp\":\"1785204134265\", \"event_type\":\"price_change\"}","received_at":"2026-07-28T02:02:15.802194Z","schema_version":"clob-market-ws.price_change.v1","sequence":null,"server_hash":null,"server_timestamp":"1785204134265","session_id":"d2757dd6dad94f3b9fe67e8dbf1adc37","source":"clob_market_ws"},"received_at":"2026-07-28T02:02:15.802194Z","record_id":"b101226c7cc8a59cdc4625893f346673eb28abde68abe1c5a516fc9d37fd455f","schema_fingerprint":"4aa3821a28b0b7c2400bc59aba4bcc0a76e971dadd19610d3ad38c768e124dc7","schema_version":"edge-lab-recorder.raw.v1","sequence":null,"source":"clob_market_ws"}
{"event_at":"2026-07-28T02:02:14.267000Z","event_fingerprint":"5c14a06c06b031bc2ec26fcacc80b339cbd914ec5a1b3ac0da8f4aff7aaecc24","payload":{"connection_id":"5d29200f65794d4d9ab6ef271f045a9b","event_at":"2026-07-28T02:02:14.267000Z","event_type":"price_change","frame_hash":"a3ad4702ff0f2d4de86d56aa1f49a7754ca05b2c569b1d4fc7df9874b7900caa","frame_index":0,"kind":"data","monotonic_ns":306118812639541,"payload":{"event_type":"price_change","market":"0xda6f0e0e93fc8469e0159a166028d017bddbc162b86f66bac90391379603d962","price_changes":[{"asset_id":"39272994714739463168905443499424551362424437245880253267329605556587274644733","best_ask":"0.58","best_bid":"0.57","hash":"d8900581f62c46c561a1dcd5e876db03dd8c6ef3","price":"0.01","side":"BUY","size":"7858.02"},{"asset_id":"20893381255801015515826997628594359667013752732428989472914000440642900266717","best_ask":"0.43","best_bid":"0.42","hash":"91403789ace65a08f35e88ab6adf96d66a0afad1","price":"0.99","side":"SELL","size":"7858.02"}],"timestamp":"1785204134267"},"payload_hash":"c5b6fff2150b2c56b13d22593dda66987dee8ad50e48999ae456cae5d99fa5ff","raw_frame":"{\"market\":\"0xda6f0e0e93fc8469e0159a166028d017bddbc162b86f66bac90391379603d962\", \"price_changes\":[{\"asset_id\":\"39272994714739463168905443499424551362424437245880253267329605556587274644733\", \"price\":\"0.01\", \"size\":\"7858.02\", \"side\":\"BUY\", \"hash\":\"d8900581f62c46c561a1dcd5e876db03dd8c6ef3\", \"best_bid\":\"0.57\", \"best_ask\":\"0.58\"}, {\"asset_id\":\"20893381255801015515826997628594359667013752732428989472914000440642900266717\", \"price\":\"0.99\", \"size\":\"7858.02\", \"side\":\"SELL\", \"hash\":\"91403789ace65a08f35e88ab6adf96d66a0afad1\", \"best_bid\":\"0.42\", \"best_ask\":\"0.43\"}], \"timestamp\":\"1785204134267\", \"event_type\":\"price_change\"}","received_at":"2026-07-28T02:02:15.808245Z","schema_version":"clob-market-ws.price_change.v1","sequence":null,"server_hash":null,"server_timestamp":"1785204134267","session_id":"d2757dd6dad94f3b9fe67e8dbf1adc37","source":"clob_market_ws"},"received_at":"2026-07-28T02:02:15.808245Z","record_id":"199ba6adddd10243107469974bb27d123afe63aaca33e7a0eb57c40e3d03fff5","schema_fingerprint":"4aa3821a28b0b7c2400bc59aba4bcc0a76e971dadd19610d3ad38c768e124dc7","schema_version":"edge-lab-recorder.raw.v1","sequence":null,"source":"clob_market_ws"}
{"event_at":"2026-07-28T02:02:14.269000Z","event_fingerprint":"a5be907cc1aa73ed9615dc5053ada1d15c6e788f783a82fa201d63488c4a2dd8","payload":{"connection_id":"5d29200f65794d4d9ab6ef271f045a9b","event_at":"2026-07-28T02:02:14.269000Z","event_type":"price_change","frame_hash":"f6eca2a84bf3c3986d8e9de2773f040b23a5a12355b1b886280573265b64fae6","frame_index":0,"kind":"data","monotonic_ns":306118817895375,"payload":{"event_type":"price_change","market":"0xda6f0e0e93fc8469e0159a166028d017bddbc162b86f66bac90391379603d962","price_changes":[{"asset_id":"39272994714739463168905443499424551362424437245880253267329605556587274644733","best_ask":"0.58","best_bid":"0.57","hash":"1f5fcf4c4511e9c865369e98b9b3c1d7d6fcb592","price":"0.48","side":"BUY","size":"312.05"},{"asset_id":"20893381255801015515826997628594359667013752732428989472914000440642900266717","best_ask":"0.43","best_bid":"0.42","hash":"327e11748cb33280085dde338a0ca84e5b4a64b0","price":"0.52","side":"SELL","size":"312.05"}],"timestamp":"1785204134269"},"payload_hash":"2f8686e9d6e5478ffdd7dbf87deb6c08b5eb253c1ad1c63def8ac7978db1b3d7","raw_frame":"{\"market\":\"0xda6f0e0e93fc8469e0159a166028d017bddbc162b86f66bac90391379603d962\", \"price_changes\":[{\"asset_id\":\"39272994714739463168905443499424551362424437245880253267329605556587274644733\", \"price\":\"0.48\", \"size\":\"312.05\", \"side\":\"BUY\", \"hash\":\"1f5fcf4c4511e9c865369e98b9b3c1d7d6fcb592\", \"best_bid\":\"0.57\", \"best_ask\":\"0.58\"}, {\"asset_id\":\"20893381255801015515826997628594359667013752732428989472914000440642900266717\", \"price\":\"0.52\", \"size\":\"312.05\", \"side\":\"SELL\", \"hash\":\"327e11748cb33280085dde338a0ca84e5b4a64b0\", \"best_bid\":\"0.42\", \"best_ask\":\"0.43\"}], \"timestamp\":\"1785204134269\", \"event_type\":\"price_change\"}","received_at":"2026-07-28T02:02:15.813500Z","schema_version":"clob-market-ws.price_change.v1","sequence":null,"server_hash":null,"server_timestamp":"1785204134269","session_id":"d2757dd6dad94f3b9fe67e8dbf1adc37","source":"clob_market_ws"},"received_at":"2026-07-28T02:02:15.813500Z","record_id":"e334ee55445d0c0cb5cfad2f69c0a95ffe7347a63e962912ecb31f951345bd36","schema_fingerprint":"4aa3821a28b0b7c2400bc59aba4bcc0a76e971dadd19610d3ad38c768e124dc7","schema_version":"edge-lab-recorder.raw.v1","sequence":null,"source":"clob_market_ws"}
{"event_at":"2026-07-28T02:02:14.280000Z","event_fingerprint":"e7f0b7b86339555025deefcb15b76dd2f90863ceb340ee43732fae5206e3a7b9","payload":{"connection_id":"5d29200f65794d4d9ab6ef271f045a9b","event_at":"2026-07-28T02:02:14.280000Z","event_type":"price_change","frame_hash":"918c78b0e6c4f4e833ef8f4a7ffc0970922b884f96a6920d0be9abdc89bbb0dc","frame_index":0,"kind":"data","monotonic_ns":306118825615208,"payload":{"event_type":"price_change","market":"0xda6f0e0e93fc8469e0159a166028d017bddbc162b86f66bac90391379603d962","price_changes":[{"asset_id":"20893381255801015515826997628594359667013752732428989472914000440642900266717","best_ask":"0.43","best_bid":"0.42","hash":"5daaa0c01a25d66c067dd982e8b4254011baa9f8","price":"0.34","side":"BUY","size":"208.4"},{"asset_id":"39272994714739463168905443499424551362424437245880253267329605556587274644733","best_ask":"0.58","best_bid":"0.57","hash":"c20fc84158e030e7939dea171898b334cdb0203e","price":"0.66","side":"SELL","size":"208.4"}],"timestamp":"1785204134280"},"payload_hash":"c2ad54022d9ce63a35a7bd70a16089c0241873b776eabbefbb9dcf32978a6187","raw_frame":"{\"market\":\"0xda6f0e0e93fc8469e0159a166028d017bddbc162b86f66bac90391379603d962\", \"price_changes\":[{\"asset_id\":\"20893381255801015515826997628594359667013752732428989472914000440642900266717\", \"price\":\"0.34\", \"size\":\"208.4\", \"side\":\"BUY\", \"hash\":\"5daaa0c01a25d66c067dd982e8b4254011baa9f8\", \"best_bid\":\"0.42\", \"best_ask\":\"0.43\"}, {\"asset_id\":\"39272994714739463168905443499424551362424437245880253267329605556587274644733\", \"price\":\"0.66\", \"size\":\"208.4\", \"side\":\"SELL\", \"hash\":\"c20fc84158e030e7939dea171898b334cdb0203e\", \"best_bid\":\"0.57\", \"best_ask\":\"0.58\"}], \"timestamp\":\"1785204134280\", \"event_type\":\"price_change\"}","received_at":"2026-07-28T02:02:15.821221Z","schema_version":"clob-market-ws.price_change.v1","sequence":null,"server_hash":null,"server_timestamp":"1785204134280","session_id":"d2757dd6dad94f3b9fe67e8dbf1adc37","source":"clob_market_ws"},"received_at":"2026-07-28T02:02:15.821221Z","record_id":"a32a3145adf14db2617bbf4eefa04783055c3dd7030dfffe5d3043017ebbe441","schema_fingerprint":"4aa3821a28b0b7c2400bc59aba4bcc0a76e971dadd19610d3ad38c768e124dc7","schema_version":"edge-lab-recorder.raw.v1","sequence":null,"source":"clob_market_ws"}
{"event_at":"2026-07-28T02:02:14.280000Z","event_fingerprint":"a8428820c73ec263cc7acbbdd1b1dd50fc4c3c07ed05a53129541c3e4df8f370","payload":{"connection_id":"5d29200f65794d4d9ab6ef271f045a9b","event_at":"2026-07-28T02:02:14.280000Z","event_type":"price_change","frame_hash":"0558a4a82775c2b04828e114898fc90588537c8dcad393590ab028a9cad163b3","frame_index":0,"kind":"data","monotonic_ns":306118831321125,"payload":{"event_type":"price_change","market":"0xda6f0e0e93fc8469e0159a166028d017bddbc162b86f66bac90391379603d962","price_changes":[{"asset_id":"20893381255801015515826997628594359667013752732428989472914000440642900266717","best_ask":"0.43","best_bid":"0.42","hash":"7fdb247d303190cdbc658b798df5a340f1cdc435","price":"0.34","side":"BUY","size":"178.4"},{"asset_id":"39272994714739463168905443499424551362424437245880253267329605556587274644733","best_ask":"0.58","best_bid":"0.57","hash":"0a762b51d3ed1e11c549e5f2941e9a024389b48a","price":"0.66","side":"SELL","size":"178.4"}],"timestamp":"1785204134280"},"payload_hash":"90aca900a95bae4cf0cbddcbe240a16006677bd9b31c76565405f1e238d3f264","raw_frame":"{\"market\":\"0xda6f0e0e93fc8469e0159a166028d017bddbc162b86f66bac90391379603d962\", \"price_changes\":[{\"asset_id\":\"20893381255801015515826997628594359667013752732428989472914000440642900266717\", \"price\":\"0.34\", \"size\":\"178.4\", \"side\":\"BUY\", \"hash\":\"7fdb247d303190cdbc658b798df5a340f1cdc435\", \"best_bid\":\"0.42\", \"best_ask\":\"0.43\"}, {\"asset_id\":\"39272994714739463168905443499424551362424437245880253267329605556587274644733\", \"price\":\"0.66\", \"size\":\"178.4\", \"side\":\"SELL\", \"hash\":\"0a762b51d3ed1e11c549e5f2941e9a024389b48a\", \"best_bid\":\"0.57\", \"best_ask\":\"0.58\"}], \"timestamp\":\"1785204134280\", \"event_type\":\"price_change\"}","received_at":"2026-07-28T02:02:15.826930Z","schema_version":"clob-market-ws.price_change.v1","sequence":null,"server_hash":null,"server_timestamp":"1785204134280","session_id":"d2757dd6dad94f3b9fe67e8dbf1adc37","source":"clob_market_ws"},"received_at":"2026-07-28T02:02:15.826930Z","record_id":"12f696d7f7712e22d9db95c66155dbe99596281aa4092065857fe4d26dcc733a","schema_fingerprint":"4aa3821a28b0b7c2400bc59aba4bcc0a76e971dadd19610d3ad38c768e124dc7","schema_version":"edge-lab-recorder.raw.v1","sequence":null,"source":"clob_market_ws"}
{"event_at":"2026-07-28T02:02:14.280000Z","event_fingerprint":"acd23a38772d51f58c2afd29cf70245720e5f28994a34cd1775361d0c9673f2f","payload":{"connection_id":"5d29200f65794d4d9ab6ef271f045a9b","event_at":"2026-07-28T02:02:14.280000Z","event_type":"price_change","frame_hash":"9c14b4c7d1b2ba1209d0030c0bbeccece03aeebb767d6ab9f846455d86c1d7a9","frame_index":0,"kind":"data","monotonic_ns":306118838272958,"payload":{"event_type":"price_change","market":"0xda6f0e0e93fc8469e0159a166028d017bddbc162b86f66bac90391379603d962","price_changes":[{"asset_id":"39272994714739463168905443499424551362424437245880253267329605556587274644733","best_ask":"0.58","best_bid":"0.57","hash":"d96091add639360990e508016ee97fb17eca2cfc","price":"0.45","side":"BUY","size":"179"},{"asset_id":"20893381255801015515826997628594359667013752732428989472914000440642900266717","best_ask":"0.43","best_bid":"0.42","hash":"473381ebf58b9945c3b57ea1b81647f697859d19","price":"0.55","side":"SELL","size":"179"}],"timestamp":"1785204134280"},"payload_hash":"65ef4b79fe01610075c30655da50c19580234f08d2fe538521cc01f72e11f819","raw_frame":"{\"market\":\"0xda6f0e0e93fc8469e0159a166028d017bddbc162b86f66bac90391379603d962\", \"price_changes\":[{\"asset_id\":\"39272994714739463168905443499424551362424437245880253267329605556587274644733\", \"price\":\"0.45\", \"size\":\"179\", \"side\":\"BUY\", \"hash\":\"d96091add639360990e508016ee97fb17eca2cfc\", \"best_bid\":\"0.57\", \"best_ask\":\"0.58\"}, {\"asset_id\":\"20893381255801015515826997628594359667013752732428989472914000440642900266717\", \"price\":\"0.55\", \"size\":\"179\", \"side\":\"SELL\", \"hash\":\"473381ebf58b9945c3b57ea1b81647f697859d19\", \"best_bid\":\"0.42\", \"best_ask\":\"0.43\"}], \"timestamp\":\"1785204134280\", \"event_type\":\"price_change\"}","received_at":"2026-07-28T02:02:15.833880Z","schema_version":"clob-market-ws.price_change.v1","sequence":null,"server_hash":null,"server_timestamp":"1785204134280","session_id":"d2757dd6dad94f3b9fe67e8dbf1adc37","source":"clob_market_ws"},"received_at":"2026-07-28T02:02:15.833880Z","record_id":"20420dbff851179415e9facab2653fb750492806dc9b1384d60abc429ace8035","schema_fingerprint":"4aa3821a28b0b7c2400bc59aba4bcc0a76e971dadd19610d3ad38c768e124dc7","schema_version":"edge-lab-recorder.raw.v1","sequence":null,"source":"clob_market_ws"}
{"event_at":"2026-07-28T02:02:14.281000Z","event_fingerprint":"056ac3fdec05f14b1285528e1c573f88c6dc84f26772a29124e8b5e6472fffa3","payload":{"connection_id":"5d29200f65794d4d9ab6ef271f045a9b","event_at":"2026-07-28T02:02:14.281000Z","event_type":"price_change","frame_hash":"91318c8ab1f895dd019ad0de1564593afb5dc40f81c42665d369dca4b0a45403","frame_index":0,"kind":"data","monotonic_ns":306118846656833,"payload":{"event_type":"price_change","market":"0xda6f0e0e93fc8469e0159a166028d017bddbc162b86f66bac90391379603d962","price_changes":[{"asset_id":"39272994714739463168905443499424551362424437245880253267329605556587274644733","best_ask":"0.58","best_bid":"0.57","hash":"e07dd0fcbddcad591598544cca4b07c02c5f235e","price":"0.54","side":"BUY","size":"93"},{"asset_id":"20893381255801015515826997628594359667013752732428989472914000440642900266717","best_ask":"0.43","best_bid":"0.42","hash":"883b7338806e7320f29b6a530e0616a923a051bd","price":"0.46","side":"SELL","size":"93"}],"timestamp":"1785204134281"},"payload_hash":"a7d1025777a0d683c856ef3d68e36fb45769ced9459379185c6b0a6a95d74dfe","raw_frame":"{\"market\":\"0xda6f0e0e93fc8469e0159a166028d017bddbc162b86f66bac90391379603d962\", \"price_changes\":[{\"asset_id\":\"39272994714739463168905443499424551362424437245880253267329605556587274644733\", \"price\":\"0.54\", \"size\":\"93\", \"side\":\"BUY\", \"hash\":\"e07dd0fcbddcad591598544cca4b07c02c5f235e\", \"best_bid\":\"0.57\", \"best_ask\":\"0.58\"}, {\"asset_id\":\"20893381255801015515826997628594359667013752732428989472914000440642900266717\", \"price\":\"0.46\", \"size\":\"93\", \"side\":\"SELL\", \"hash\":\"883b7338806e7320f29b6a530e0616a923a051bd\", \"best_bid\":\"0.42\", \"best_ask\":\"0.43\"}], \"timestamp\":\"1785204134281\", \"event_type\":\"price_change\"}","received_at":"2026-07-28T02:02:15.842259Z","schema_version":"clob-market-ws.price_change.v1","sequence":null,"server_hash":null,"server_timestamp":"1785204134281","session_id":"d2757dd6dad94f3b9fe67e8dbf1adc37","source":"clob_market_ws"},"received_at":"2026-07-28T02:02:15.842259Z","record_id":"c0a296981df37a844071c27f27177b72e2b05d6e0b5cee7f41ac80ca27e25a58","schema_fingerprint":"4aa3821a28b0b7c2400bc59aba4bcc0a76e971dadd19610d3ad38c768e124dc7","schema_version":"edge-lab-recorder.raw.v1","sequence":null,"source":"clob_market_ws"}
{"event_at":"2026-07-28T02:02:14.281000Z","event_fingerprint":"428914331c1e479d910993f4cc0accb97b6f78bd559cec5c1d7d2ec1f7be205a","payload":{"connection_id":"5d29200f65794d4d9ab6ef271f045a9b","event_at":"2026-07-28T02:02:14.281000Z","event_type":"price_change","frame_hash":"e442019b8c76a679cf49d78af439c413612f3f12de799fb11876f2ecc77dd7a0","frame_index":0,"kind":"data","monotonic_ns":306118849337708,"payload":{"event_type":"price_change","market":"0xda6f0e0e93fc8469e0159a166028d017bddbc162b86f66bac90391379603d962","price_changes":[{"asset_id":"39272994714739463168905443499424551362424437245880253267329605556587274644733","best_ask":"0.58","best_bid":"0.57","hash":"f2b777a2d4c25f993c2506fe5338a2e038e9adf4","price":"0.04","side":"BUY","size":"643.09"},{"asset_id":"20893381255801015515826997628594359667013752732428989472914000440642900266717","best_ask":"0.43","best_bid":"0.42","hash":"534a5b49cdc090d18df22eaa640410b127509d00","price":"0.96","side":"SELL","size":"643.09"}],"timestamp":"1785204134281"},"payload_hash":"8e6752315999947aa170df63ca4544cdf94130c69333a2b22c8b7bf826a86f58","raw_frame":"{\"market\":\"0xda6f0e0e93fc8469e0159a166028d017bddbc162b86f66bac90391379603d962\", \"price_changes\":[{\"asset_id\":\"39272994714739463168905443499424551362424437245880253267329605556587274644733\", \"price\":\"0.04\", \"size\":\"643.09\", \"side\":\"BUY\", \"hash\":\"f2b777a2d4c25f993c2506fe5338a2e038e9adf4\", \"best_bid\":\"0.57\", \"best_ask\":\"0.58\"}, {\"asset_id\":\"20893381255801015515826997628594359667013752732428989472914000440642900266717\", \"price\":\"0.96\", \"size\":\"643.09\", \"side\":\"SELL\", \"hash\":\"534a5b49cdc090d18df22eaa640410b127509d00\", \"best_bid\":\"0.42\", \"best_ask\":\"0.43\"}], \"timestamp\":\"1785204134281\", \"event_type\":\"price_change\"}","received_at":"2026-07-28T02:02:15.844947Z","schema_version":"clob-market-ws.price_change.v1","sequence":null,"server_hash":null,"server_timestamp":"1785204134281","session_id":"d2757dd6dad94f3b9fe67e8dbf1adc37","source":"clob_market_ws"},"received_at":"2026-07-28T02:02:15.844947Z","record_id":"2990a63dc568cae23c0b46eab159353aa64ff555ee1fd35fe70fdb1d36855036","schema_fingerprint":"4aa3821a28b0b7c2400bc59aba4bcc0a76e971dadd19610d3ad38c768e124dc7","schema_version":"edge-lab-recorder.raw.v1","sequence":null,"source":"clob_market_ws"}
{"event_at":"2026-07-28T02:02:14.282000Z","event_fingerprint":"39b2f0f3bb7cd26878c9de083ab99bf73f4c917708406a986ec31268967f631d","payload":{"connection_id":"5d29200f65794d4d9ab6ef271f045a9b","event_at":"2026-07-28T02:02:14.282000Z","event_type":"price_change","frame_hash":"aab6fdecfee4dedcf0889a233091726fae70a5d78727e3ab7a37af579abdc774","frame_index":0,"kind":"data","monotonic_ns":306118852025666,"payload":{"event_type":"price_change","market":"0xda6f0e0e93fc8469e0159a166028d017bddbc162b86f66bac90391379603d962","price_changes":[{"asset_id":"39272994714739463168905443499424551362424437245880253267329605556587274644733","best_ask":"0.58","best_bid":"0.57","hash":"39e8a28ebc935dfabdab73e3251b1548a050ac37","price":"0.54","side":"BUY","size":"64"},{"asset_id":"20893381255801015515826997628594359667013752732428989472914000440642900266717","best_ask":"0.43","best_bid":"0.42","hash":"e4e9fdf460651369829db1f99c0d87b7b9b48201","price":"0.46","side":"SELL","size":"64"}],"timestamp":"1785204134282"},"payload_hash":"7c3eb35a4b15c38d627de3fca3a97d8fc36ca34264ef02c96d65fb5fa4fa0ea1","raw_frame":"{\"market\":\"0xda6f0e0e93fc8469e0159a166028d017bddbc162b86f66bac90391379603d962\", \"price_changes\":[{\"asset_id\":\"39272994714739463168905443499424551362424437245880253267329605556587274644733\", \"price\":\"0.54\", \"size\":\"64\", \"side\":\"BUY\", \"hash\":\"39e8a28ebc935dfabdab73e3251b1548a050ac37\", \"best_bid\":\"0.57\", \"best_ask\":\"0.58\"}, {\"asset_id\":\"20893381255801015515826997628594359667013752732428989472914000440642900266717\", \"price\":\"0.46\", \"size\":\"64\", \"side\":\"SELL\", \"hash\":\"e4e9fdf460651369829db1f99c0d87b7b9b48201\", \"best_bid\":\"0.42\", \"best_ask\":\"0.43\"}], \"timestamp\":\"1785204134282\", \"event_type\":\"price_change\"}","received_at":"2026-07-28T02:02:15.847635Z","schema_version":"clob-market-ws.price_change.v1","sequence":null,"server_hash":null,"server_timestamp":"1785204134282","session_id":"d2757dd6dad94f3b9fe67e8dbf1adc37","source":"clob_market_ws"},"received_at":"2026-07-28T02:02:15.847635Z","record_id":"a645999360a64874bee684279027ce47f94c1906336cbaea922bc38df24380d0","schema_fingerprint":"4aa3821a28b0b7c2400bc59aba4bcc0a76e971dadd19610d3ad38c768e124dc7","schema_version":"edge-lab-recorder.raw.v1","sequence":null,"source":"clob_market_ws"}
{"event_at":"2026-07-28T02:02:14.282000Z","event_fingerprint":"09f13ee548308fd1abe6a4b2fccf83785ecfaf6fe9b9007d32a1783473aca075","payload":{"connection_id":"5d29200f65794d4d9ab6ef271f045a9b","event_at":"2026-07-28T02:02:14.282000Z","event_type":"price_change","frame_hash":"7fb34f07115f3281ffe9df21009006c4a9094500dec6347f59557312708b639a","frame_index":0,"kind":"data","monotonic_ns":306118854196041,"payload":{"event_type":"price_change","market":"0xda6f0e0e93fc8469e0159a166028d017bddbc162b86f66bac90391379603d962","price_changes":[{"asset_id":"39272994714739463168905443499424551362424437245880253267329605556587274644733","best_ask":"0.58","best_bid":"0.57","hash":"feda5e9845e2295fa6293d6cde415927ccdf86d7","price":"0.55","side":"BUY","size":"47"},{"asset_id":"20893381255801015515826997628594359667013752732428989472914000440642900266717","best_ask":"0.43","best_bid":"0.42","hash":"cc63453204a82f7c07c1c52bce657ed36c7f5ab7","price":"0.45","side":"SELL","size":"47"}],"timestamp":"1785204134282"},"payload_hash":"38ae2892dd558484e29616e6ef6c1bf6d402a1c75b8dd340e9f0b167ee6d8427","raw_frame":"{\"market\":\"0xda6f0e0e93fc8469e0159a166028d017bddbc162b86f66bac90391379603d962\", \"price_changes\":[{\"asset_id\":\"39272994714739463168905443499424551362424437245880253267329605556587274644733\", \"price\":\"0.55\", \"size\":\"47\", \"side\":\"BUY\", \"hash\":\"feda5e9845e2295fa6293d6cde415927ccdf86d7\", \"best_bid\":\"0.57\", \"best_ask\":\"0.58\"}, {\"asset_id\":\"20893381255801015515826997628594359667013752732428989472914000440642900266717\", \"price\":\"0.45\", \"size\":\"47\", \"side\":\"SELL\", \"hash\":\"cc63453204a82f7c07c1c52bce657ed36c7f5ab7\", \"best_bid\":\"0.42\", \"best_ask\":\"0.43\"}], \"timestamp\":\"1785204134282\", \"event_type\":\"price_change\"}","received_at":"2026-07-28T02:02:15.849806Z","schema_version":"clob-market-ws.price_change.v1","sequence":null,"server_hash":null,"server_timestamp":"1785204134282","session_id":"d2757dd6dad94f3b9fe67e8dbf1adc37","source":"clob_market_ws"},"received_at":"2026-07-28T02:02:15.849806Z","record_id":"ef5283566f5903ff86e07eaeb17b82185f6eef5573e2e36e6b1f367292803e1c","schema_fingerprint":"4aa3821a28b0b7c2400bc59aba4bcc0a76e971dadd19610d3ad38c768e124dc7","schema_version":"edge-lab-recorder.raw.v1","sequence":null,"source":"clob_market_ws"}
{"event_at":"2026-07-28T02:02:14.283000Z","event_fingerprint":"cfbe7deabaad659a2e4a43565eab259bb500e7ff2e2d7a886ca21f7874fe0b69","payload":{"connection_id":"5d29200f65794d4d9ab6ef271f045a9b","event_at":"2026-07-28T02:02:14.283000Z","event_type":"price_change","frame_hash":"d19a585fa1aec88a90085d10ce237ddf623d8bd7390acbc17a11022cb85383fd","frame_index":0,"kind":"data","monotonic_ns":306118856068250,"payload":{"event_type":"price_change","market":"0xda6f0e0e93fc8469e0159a166028d017bddbc162b86f66bac90391379603d962","price_changes":[{"asset_id":"20893381255801015515826997628594359667013752732428989472914000440642900266717","best_ask":"0.43","best_bid":"0.42","hash":"52e78e17cade68cfda61682840e9de669ad123cb","price":"0.33","side":"BUY","size":"257.1"},{"asset_id":"39272994714739463168905443499424551362424437245880253267329605556587274644733","best_ask":"0.58","best_bid":"0.57","hash":"e424c1175aed781a21a2640c4ca9e9e31647c53c","price":"0.67","side":"SELL","size":"257.1"}],"timestamp":"1785204134283"},"payload_hash":"252e8d7e29b03f0a432bc008a1716480b2997aefae74cddc67647f204bfbfa6f","raw_frame":"{\"market\":\"0xda6f0e0e93fc8469e0159a166028d017bddbc162b86f66bac90391379603d962\", \"price_changes\":[{\"asset_id\":\"20893381255801015515826997628594359667013752732428989472914000440642900266717\", \"price\":\"0.33\", \"size\":\"257.1\", \"side\":\"BUY\", \"hash\":\"52e78e17cade68cfda61682840e9de669ad123cb\", \"best_bid\":\"0.42\", \"best_ask\":\"0.43\"}, {\"asset_id\":\"39272994714739463168905443499424551362424437245880253267329605556587274644733\", \"price\":\"0.67\", \"size\":\"257.1\", \"side\":\"SELL\", \"hash\":\"e424c1175aed781a21a2640c4ca9e9e31647c53c\", \"best_bid\":\"0.57\", \"best_ask\":\"0.58\"}], \"timestamp\":\"1785204134283\", \"event_type\":\"price_change\"}","received_at":"2026-07-28T02:02:15.851678Z","schema_version":"clob-market-ws.price_change.v1","sequence":null,"server_hash":null,"server_timestamp":"1785204134283","session_id":"d2757dd6dad94f3b9fe67e8dbf1adc37","source":"clob_market_ws"},"received_at":"2026-07-28T02:02:15.851678Z","record_id":"e9c9641931c9f0f4a57ad56efb33a1325b66e5d39c464f02b36dae226a5e2feb","schema_fingerprint":"4aa3821a28b0b7c2400bc59aba4bcc0a76e971dadd19610d3ad38c768e124dc7","schema_version":"edge-lab-recorder.raw.v1","sequence":null,"source":"clob_market_ws"}
{"event_at":"2026-07-28T02:02:14.285000Z","event_fingerprint":"9c22223e250318e4f1535bc06ee9cf29977731d584be0f3fa2d16a7717597d17","payload":{"connection_id":"5d29200f65794d4d9ab6ef271f045a9b","event_at":"2026-07-28T02:02:14.285000Z","event_type":"price_change","frame_hash":"95071c67b147c12b59d46026f60ebb31238ba814b20a802e68db0e7ae158247b","frame_index":0,"kind":"data","monotonic_ns":306118858343416,"payload":{"event_type":"price_change","market":"0xda6f0e0e93fc8469e0159a166028d017bddbc162b86f66bac90391379603d962","price_changes":[{"asset_id":"39272994714739463168905443499424551362424437245880253267329605556587274644733","best_ask":"0.58","best_bid":"0.57","hash":"6a1d4228931df0b07451bd073664c6ed22ed2353","price":"0.48","side":"BUY","size":"282.05"},{"asset_id":"20893381255801015515826997628594359667013752732428989472914000440642900266717","best_ask":"0.43","best_bid":"0.42","hash":"4954bdf82a1ee3a83e50be8e99629b54d85a840c","price":"0.52","side":"SELL","size":"282.05"}],"timestamp":"1785204134285"},"payload_hash":"861afe59ecaf491acb2a5d89c0f1523f313a9d325722a1d78930af42ba1737aa","raw_frame":"{\"market\":\"0xda6f0e0e93fc8469e0159a166028d017bddbc162b86f66bac90391379603d962\", \"price_changes\":[{\"asset_id\":\"39272994714739463168905443499424551362424437245880253267329605556587274644733\", \"price\":\"0.48\", \"size\":\"282.05\", \"side\":\"BUY\", \"hash\":\"6a1d4228931df0b07451bd073664c6ed22ed2353\", \"best_bid\":\"0.57\", \"best_ask\":\"0.58\"}, {\"asset_id\":\"20893381255801015515826997628594359667013752732428989472914000440642900266717\", \"price\":\"0.52\", \"size\":\"282.05\", \"side\":\"SELL\", \"hash\":\"4954bdf82a1ee3a83e50be8e99629b54d85a840c\", \"best_bid\":\"0.42\", \"best_ask\":\"0.43\"}], \"timestamp\":\"1785204134285\", \"event_type\":\"price_change\"}","received_at":"2026-07-28T02:02:15.853948Z","schema_version":"clob-market-ws.price_change.v1","sequence":null,"server_hash":null,"server_timestamp":"1785204134285","session_id":"d2757dd6dad94f3b9fe67e8dbf1adc37","source":"clob_market_ws"},"received_at":"2026-07-28T02:02:15.853948Z","record_id":"2fcf93bdb89ba6d1fa2d4ca83461a92eaaf6227995fe42cf4f9ddb1f8e7e1643","schema_fingerprint":"4aa3821a28b0b7c2400bc59aba4bcc0a76e971dadd19610d3ad38c768e124dc7","schema_version":"edge-lab-recorder.raw.v1","sequence":null,"source":"clob_market_ws"}
{"event_at":"2026-07-28T02:02:14.285000Z","event_fingerprint":"f2ad309ccd50b001e7d41b7f668319c4a5be3ff15570efb3f255e80cd2bcc235","payload":{"connection_id":"5d29200f65794d4d9ab6ef271f045a9b","event_at":"2026-07-28T02:02:14.285000Z","event_type":"price_change","frame_hash":"974a1f752199a8601521d421c445c92b95b140a19737ecc4e7a5c4a9fc157f10","frame_index":0,"kind":"data","monotonic_ns":306118864570833,"payload":{"event_type":"price_change","market":"0xda6f0e0e93fc8469e0159a166028d017bddbc162b86f66bac90391379603d962","price_changes":[{"asset_id":"39272994714739463168905443499424551362424437245880253267329605556587274644733","best_ask":"0.58","best_bid":"0.57","hash":"6aa85e92b98febfda66a30245f884dc687ee2a06","price":"0.43","side":"BUY","size":"221.52"},{"asset_id":"20893381255801015515826997628594359667013752732428989472914000440642900266717","best_ask":"0.43","best_bid":"0.42","hash":"6be17346e3ab7832fba5ec5424b0d7ccbbcf432b","price":"0.57","side":"SELL","size":"221.52"}],"timestamp":"1785204134285"},"payload_hash":"657ab4a99fedb9aa57fe37bc1fcb717b8ace8d48135ac7184ed8aef085b6197f","raw_frame":"{\"market\":\"0xda6f0e0e93fc8469e0159a166028d017bddbc162b86f66bac90391379603d962\", \"price_changes\":[{\"asset_id\":\"39272994714739463168905443499424551362424437245880253267329605556587274644733\", \"price\":\"0.43\", \"size\":\"221.52\", \"side\":\"BUY\", \"hash\":\"6aa85e92b98febfda66a30245f884dc687ee2a06\", \"best_bid\":\"0.57\", \"best_ask\":\"0.58\"}, {\"asset_id\":\"20893381255801015515826997628594359667013752732428989472914000440642900266717\", \"price\":\"0.57\", \"size\":\"221.52\", \"side\":\"SELL\", \"hash\":\"6be17346e3ab7832fba5ec5424b0d7ccbbcf432b\", \"best_bid\":\"0.42\", \"best_ask\":\"0.43\"}], \"timestamp\":\"1785204134285\", \"event_type\":\"price_change\"}","received_at":"2026-07-28T02:02:15.860174Z","schema_version":"clob-market-ws.price_change.v1","sequence":null,"server_hash":null,"server_timestamp":"1785204134285","session_id":"d2757dd6dad94f3b9fe67e8dbf1adc37","source":"clob_market_ws"},"received_at":"2026-07-28T02:02:15.860174Z","record_id":"2396c26c004e9f1a93701a85aec4cd64b7587ca656249f94e4f1a561a803fc07","schema_fingerprint":"4aa3821a28b0b7c2400bc59aba4bcc0a76e971dadd19610d3ad38c768e124dc7","schema_version":"edge-lab-recorder.raw.v1","sequence":null,"source":"clob_market_ws"}
{"event_at":"2026-07-28T02:02:14.287000Z","event_fingerprint":"5a25d2d2c436eea0b83e4d0a17345d6d628508cd97e42c5b122ce7cfb9265eb9","payload":{"connection_id":"5d29200f65794d4d9ab6ef271f045a9b","event_at":"2026-07-28T02:02:14.287000Z","event_type":"price_change","frame_hash":"37d951af9a02a70abf30481ecc8b578c354cc196b1bc796cfc0964205326d6fc","frame_index":0,"kind":"data","monotonic_ns":306118867012916,"payload":{"event_type":"price_change","market":"0xda6f0e0e93fc8469e0159a166028d017bddbc162b86f66bac90391379603d962","price_changes":[{"asset_id":"39272994714739463168905443499424551362424437245880253267329605556587274644733","best_ask":"0.58","best_bid":"0.57","hash":"0176593340b8f6962c56d34d9f59e8cd2c517c1e","price":"0.53","side":"BUY","size":"375.03"},{"asset_id":"20893381255801015515826997628594359667013752732428989472914000440642900266717","best_ask":"0.43","best_bid":"0.42","hash":"e812c2916da9b5a0cfe36d37de7fb166fd20668b","price":"0.47","side":"SELL","size":"375.03"}],"timestamp":"1785204134287"},"payload_hash":"3b6d417261e695a512b6064166b1f60f967f77b8b82df955142850a1740e01b5","raw_frame":"{\"market\":\"0xda6f0e0e93fc8469e0159a166028d017bddbc162b86f66bac90391379603d962\", \"price_changes\":[{\"asset_id\":\"39272994714739463168905443499424551362424437245880253267329605556587274644733\", \"price\":\"0.53\", \"size\":\"375.03\", \"side\":\"BUY\", \"hash\":\"0176593340b8f6962c56d34d9f59e8cd2c517c1e\", \"best_bid\":\"0.57\", \"best_ask\":\"0.58\"}, {\"asset_id\":\"20893381255801015515826997628594359667013752732428989472914000440642900266717\", \"price\":\"0.47\", \"size\":\"375.03\", \"side\":\"SELL\", \"hash\":\"e812c2916da9b5a0cfe36d37de7fb166fd20668b\", \"best_bid\":\"0.42\", \"best_ask\":\"0.43\"}], \"timestamp\":\"1785204134287\", \"event_type\":\"price_change\"}","received_at":"2026-07-28T02:02:15.862619Z","schema_version":"clob-market-ws.price_change.v1","sequence":null,"server_hash":null,"server_timestamp":"1785204134287","session_id":"d2757dd6dad94f3b9fe67e8dbf1adc37","source":"clob_market_ws"},"received_at":"2026-07-28T02:02:15.862619Z","record_id":"239dabc901e7446b25ce9b9684340365acf8b01e33ba1cc1239755cb21dac9b5","schema_fingerprint":"4aa3821a28b0b7c2400bc59aba4bcc0a76e971dadd19610d3ad38c768e124dc7","schema_version":"edge-lab-recorder.raw.v1","sequence":null,"source":"clob_market_ws"}
{"event_at":"2026-07-28T02:02:14.288000Z","event_fingerprint":"adad31fe9120504aa12355cfe9ebdd8123d8666c019ee0ac4f79a8857c573dc3","payload":{"connection_id":"5d29200f65794d4d9ab6ef271f045a9b","event_at":"2026-07-28T02:02:14.288000Z","event_type":"price_change","frame_hash":"93bfa3053041a3eeb4fdd91c1d564c1e47eac665482d12935133621d7a3cb620","frame_index":0,"kind":"data","monotonic_ns":306118870457625,"payload":{"event_type":"price_change","market":"0xda6f0e0e93fc8469e0159a166028d017bddbc162b86f66bac90391379603d962","price_changes":[{"asset_id":"20893381255801015515826997628594359667013752732428989472914000440642900266717","best_ask":"0.43","best_bid":"0.42","hash":"cd282c37ad92465b829f5d4ff37fbf4b645b5b72","price":"0.38","side":"BUY","size":"194.87"},{"asset_id":"39272994714739463168905443499424551362424437245880253267329605556587274644733","best_ask":"0.58","best_bid":"0.57","hash":"e420f3fe7b411a933e68765a5b27911bce6d9786","price":"0.62","side":"SELL","size":"194.87"}],"timestamp":"1785204134288"},"payload_hash":"243e85fa03248e32d327ed0daa6a02d830a231ef7d0e6e812ca6cedf9b98924f","raw_frame":"{\"market\":\"0xda6f0e0e93fc8469e0159a166028d017bddbc162b86f66bac90391379603d962\", \"price_changes\":[{\"asset_id\":\"20893381255801015515826997628594359667013752732428989472914000440642900266717\", \"price\":\"0.38\", \"size\":\"194.87\", \"side\":\"BUY\", \"hash\":\"cd282c37ad92465b829f5d4ff37fbf4b645b5b72\", \"best_bid\":\"0.42\", \"best_ask\":\"0.43\"}, {\"asset_id\":\"39272994714739463168905443499424551362424437245880253267329605556587274644733\", \"price\":\"0.62\", \"size\":\"194.87\", \"side\":\"SELL\", \"hash\":\"e420f3fe7b411a933e68765a5b27911bce6d9786\", \"best_bid\":\"0.57\", \"best_ask\":\"0.58\"}], \"timestamp\":\"1785204134288\", \"event_type\":\"price_change\"}","received_at":"2026-07-28T02:02:15.866067Z","schema_version":"clob-market-ws.price_change.v1","sequence":null,"server_hash":null,"server_timestamp":"1785204134288","session_id":"d2757dd6dad94f3b9fe67e8dbf1adc37","source":"clob_market_ws"},"received_at":"2026-07-28T02:02:15.866067Z","record_id":"1a46c3ebf0dd8102505d0d6e1dc78096ed4b6e703337319b0b5f1702bfe6afd7","schema_fingerprint":"4aa3821a28b0b7c2400bc59aba4bcc0a76e971dadd19610d3ad38c768e124dc7","schema_version":"edge-lab-recorder.raw.v1","sequence":null,"source":"clob_market_ws"}
{"event_at":"2026-07-28T02:02:14.290000Z","event_fingerprint":"c3b8c069bd22f37cd398bef2e950e187c1f174901d24eee30d8531f371985047","payload":{"connection_id":"5d29200f65794d4d9ab6ef271f045a9b","event_at":"2026-07-28T02:02:14.290000Z","event_type":"price_change","frame_hash":"db094f824b6e0393a30590bdc3b5da69f8791de0ccb2bbd3c920dc1fdd74ef8d","frame_index":0,"kind":"data","monotonic_ns":306118872130291,"payload":{"event_type":"price_change","market":"0xda6f0e0e93fc8469e0159a166028d017bddbc162b86f66bac90391379603d962","price_changes":[{"asset_id":"39272994714739463168905443499424551362424437245880253267329605556587274644733","best_ask":"0.58","best_bid":"0.57","hash":"4b9dc2828254374c95a6ca48752dc98f99121297","price":"0.01","side":"BUY","size":"7853.02"},{"asset_id":"20893381255801015515826997628594359667013752732428989472914000440642900266717","best_ask":"0.43","best_bid":"0.42","hash":"602445eec4b231cc26cd091ccd2076a7e562fe08","price":"0.99","side":"SELL","size":"7853.02"}],"timestamp":"1785204134290"},"payload_hash":"e7c4186c5bcb28dbd4c15f64d7d3e358e013ccf804869ee82a23efd13b595ece","raw_frame":"{\"market\":\"0xda6f0e0e93fc8469e0159a166028d017bddbc162b86f66bac90391379603d962\", \"price_changes\":[{\"asset_id\":\"39272994714739463168905443499424551362424437245880253267329605556587274644733\", \"price\":\"0.01\", \"size\":\"7853.02\", \"side\":\"BUY\", \"hash\":\"4b9dc2828254374c95a6ca48752dc98f99121297\", \"best_bid\":\"0.57\", \"best_ask\":\"0.58\"}, {\"asset_id\":\"20893381255801015515826997628594359667013752732428989472914000440642900266717\", \"price\":\"0.99\", \"size\":\"7853.02\", \"side\":\"SELL\", \"hash\":\"602445eec4b231cc26cd091ccd2076a7e562fe08\", \"best_bid\":\"0.42\", \"best_ask\":\"0.43\"}], \"timestamp\":\"1785204134290\", \"event_type\":\"price_change\"}","received_at":"2026-07-28T02:02:15.867741Z","schema_version":"clob-market-ws.price_change.v1","sequence":null,"server_hash":null,"server_timestamp":"1785204134290","session_id":"d2757dd6dad94f3b9fe67e8dbf1adc37","source":"clob_market_ws"},"received_at":"2026-07-28T02:02:15.867741Z","record_id":"0e77fd6479b374e29bca090e673556a3728221346ba7a0a413b0267aa74f3259","schema_fingerprint":"4aa3821a28b0b7c2400bc59aba4bcc0a76e971dadd19610d3ad38c768e124dc7","schema_version":"edge-lab-recorder.raw.v1","sequence":null,"source":"clob_market_ws"}
{"event_at":"2026-07-28T02:02:14.291000Z","event_fingerprint":"8c126e23fd13f327f06a59c9a1660128c217be1ee4627602a1d0a62663b67b07","payload":{"connection_id":"5d29200f65794d4d9ab6ef271f045a9b","event_at":"2026-07-28T02:02:14.291000Z","event_type":"price_change","frame_hash":"a9412d139af532c9d458c4c3a88a0b9b583394c8cad9dab764b345cf9dbd78c1","frame_index":0,"kind":"data","monotonic_ns":306118873642625,"payload":{"event_type":"price_change","market":"0xda6f0e0e93fc8469e0159a166028d017bddbc162b86f66bac90391379603d962","price_changes":[{"asset_id":"39272994714739463168905443499424551362424437245880253267329605556587274644733","best_ask":"0.58","best_bid":"0.57","hash":"1b43509bda7f7e874bc905875299d7a41083da47","price":"0.54","side":"BUY","size":"59"},{"asset_id":"20893381255801015515826997628594359667013752732428989472914000440642900266717","best_ask":"0.43","best_bid":"0.42","hash":"e03a92cb4b1ed2905fa37b1a17619e2678731829","price":"0.46","side":"SELL","size":"59"}],"timestamp":"1785204134291"},"payload_hash":"4917ac3a68ac5f27b22a38760e075afa6b2eddaad1b397e5ca27c9921d1caf9a","raw_frame":"{\"market\":\"0xda6f0e0e93fc8469e0159a166028d017bddbc162b86f66bac90391379603d962\", \"price_changes\":[{\"asset_id\":\"39272994714739463168905443499424551362424437245880253267329605556587274644733\", \"price\":\"0.54\", \"size\":\"59\", \"side\":\"BUY\", \"hash\":\"1b43509bda7f7e874bc905875299d7a41083da47\", \"best_bid\":\"0.57\", \"best_ask\":\"0.58\"}, {\"asset_id\":\"20893381255801015515826997628594359667013752732428989472914000440642900266717\", \"price\":\"0.46\", \"size\":\"59\", \"side\":\"SELL\", \"hash\":\"e03a92cb4b1ed2905fa37b1a17619e2678731829\", \"best_bid\":\"0.42\", \"best_ask\":\"0.43\"}], \"timestamp\":\"1785204134291\", \"event_type\":\"price_change\"}","received_at":"2026-07-28T02:02:15.869253Z","schema_version":"clob-market-ws.price_change.v1","sequence":null,"server_hash":null,"server_timestamp":"1785204134291","session_id":"d2757dd6dad94f3b9fe67e8dbf1adc37","source":"clob_market_ws"},"received_at":"2026-07-28T02:02:15.869253Z","record_id":"fa0f1b00821a9b340639117e7735fd100b4ab83a89a19ad9c52cad1c5b464c38","schema_fingerprint":"4aa3821a28b0b7c2400bc59aba4bcc0a76e971dadd19610d3ad38c768e124dc7","schema_version":"edge-lab-recorder.raw.v1","sequence":null,"source":"clob_market_ws"}
{"event_at":"2026-07-28T02:02:14.293000Z","event_fingerprint":"8825558c95a8ba756726700d59a735dfc4e50a40b41a895213767f6eaf988f3a","payload":{"connection_id":"5d29200f65794d4d9ab6ef271f045a9b","event_at":"2026-07-28T02:02:14.293000Z","event_type":"price_change","frame_hash":"1b297d13fac9346f09022535e5d00ebc75cf5cd30dc265f32a1e74460b175e44","frame_index":0,"kind":"data","monotonic_ns":306118877249166,"payload":{"event_type":"price_change","market":"0xda6f0e0e93fc8469e0159a166028d017bddbc162b86f66bac90391379603d962","price_changes":[{"asset_id":"39272994714739463168905443499424551362424437245880253267329605556587274644733","best_ask":"0.58","best_bid":"0.57","hash":"1e2d4eb7bed65ad12ee4610645b977090a8c258e","price":"0.55","side":"BUY","size":"11"},{"asset_id":"20893381255801015515826997628594359667013752732428989472914000440642900266717","best_ask":"0.43","best_bid":"0.42","hash":"40403e0e110e1261e1c000c3dd8522ebbf4ee96e","price":"0.45","side":"SELL","size":"11"}],"timestamp":"1785204134293"},"payload_hash":"903d60cb91fdc71bb5a46f6894770026d6565dc047a414c313016f5b6808e3ad","raw_frame":"{\"market\":\"0xda6f0e0e93fc8469e0159a166028d017bddbc162b86f66bac90391379603d962\", \"price_changes\":[{\"asset_id\":\"39272994714739463168905443499424551362424437245880253267329605556587274644733\", \"price\":\"0.55\", \"size\":\"11\", \"side\":\"BUY\", \"hash\":\"1e2d4eb7bed65ad12ee4610645b977090a8c258e\", \"best_bid\":\"0.57\", \"best_ask\":\"0.58\"}, {\"asset_id\":\"20893381255801015515826997628594359667013752732428989472914000440642900266717\", \"price\":\"0.45\", \"size\":\"11\", \"side\":\"SELL\", \"hash\":\"40403e0e110e1261e1c000c3dd8522ebbf4ee96e\", \"best_bid\":\"0.42\", \"best_ask\":\"0.43\"}], \"timestamp\":\"1785204134293\", \"event_type\":\"price_change\"}","received_at":"2026-07-28T02:02:15.872859Z","schema_version":"clob-market-ws.price_change.v1","sequence":null,"server_hash":null,"server_timestamp":"1785204134293","session_id":"d2757dd6dad94f3b9fe67e8dbf1adc37","source":"clob_market_ws"},"received_at":"2026-07-28T02:02:15.872859Z","record_id":"499afd51d7a21e25248dcc308788779901d52af84fddd93dc9b4ea1cc0e644ab","schema_fingerprint":"4aa3821a28b0b7c2400bc59aba4bcc0a76e971dadd19610d3ad38c768e124dc7","schema_version":"edge-lab-recorder.raw.v1","sequence":null,"source":"clob_market_ws"}
{"event_at":"2026-07-28T02:02:14.294000Z","event_fingerprint":"84044a7f42dbaa1d83f5a52a847a418b9244fcbc88f6bd4937efbac964d0092f","payload":{"connection_id":"5d29200f65794d4d9ab6ef271f045a9b","event_at":"2026-07-28T02:02:14.294000Z","event_type":"price_change","frame_hash":"631e729eb5e9dbcf0dfabda01db6784108bde4c0006a021ce84c09ab8aad9ddb","frame_index":0,"kind":"data","monotonic_ns":306118880170041,"payload":{"event_type":"price_change","market":"0xda6f0e0e93fc8469e0159a166028d017bddbc162b86f66bac90391379603d962","price_changes":[{"asset_id":"39272994714739463168905443499424551362424437245880253267329605556587274644733","best_ask":"0.58","best_bid":"0.57","hash":"e66eda5c56e265913c4ffba95d0669f6efb60ce4","price":"0.54","side":"BUY","size":"43"},{"asset_id":"20893381255801015515826997628594359667013752732428989472914000440642900266717","best_ask":"0.43","best_bid":"0.42","hash":"45dfa6d7af12c67052a65b143f8b1b96cd2066f0","price":"0.46","side":"SELL","size":"43"}],"timestamp":"1785204134294"},"payload_hash":"a08c023b94bc73f518156d353cdd5d9907e09f4ca7e1d1c398f6f0d8e078cff1","raw_frame":"{\"market\":\"0xda6f0e0e93fc8469e0159a166028d017bddbc162b86f66bac90391379603d962\", \"price_changes\":[{\"asset_id\":\"39272994714739463168905443499424551362424437245880253267329605556587274644733\", \"price\":\"0.54\", \"size\":\"43\", \"side\":\"BUY\", \"hash\":\"e66eda5c56e265913c4ffba95d0669f6efb60ce4\", \"best_bid\":\"0.57\", \"best_ask\":\"0.58\"}, {\"asset_id\":\"20893381255801015515826997628594359667013752732428989472914000440642900266717\", \"price\":\"0.46\", \"size\":\"43\", \"side\":\"SELL\", \"hash\":\"45dfa6d7af12c67052a65b143f8b1b96cd2066f0\", \"best_bid\":\"0.42\", \"best_ask\":\"0.43\"}], \"timestamp\":\"1785204134294\", \"event_type\":\"price_change\"}","received_at":"2026-07-28T02:02:15.875780Z","schema_version":"clob-market-ws.price_change.v1","sequence":null,"server_hash":null,"server_timestamp":"1785204134294","session_id":"d2757dd6dad94f3b9fe67e8dbf1adc37","source":"clob_market_ws"},"received_at":"2026-07-28T02:02:15.875780Z","record_id":"c28ec63d14e99b95fbd22b6b9deaa14ed4a22b6e3a5df7579b7fd841a8c46894","schema_fingerprint":"4aa3821a28b0b7c2400bc59aba4bcc0a76e971dadd19610d3ad38c768e124dc7","schema_version":"edge-lab-recorder.raw.v1","sequence":null,"source":"clob_market_ws"}
{"event_at":"2026-07-28T02:02:14.294000Z","event_fingerprint":"43f7e5d7adbb4f5346f84656b2324b909a6396098e1d541b3f9d5cb686d8eba1","payload":{"connection_id":"5d29200f65794d4d9ab6ef271f045a9b","event_at":"2026-07-28T02:02:14.294000Z","event_type":"price_change","frame_hash":"9ba6b17a7bb5cc8677aef1f6c7105cf847ee909a25ec4c994f536b191d95f335","frame_index":0,"kind":"data","monotonic_ns":306118884907750,"payload":{"event_type":"price_change","market":"0xda6f0e0e93fc8469e0159a166028d017bddbc162b86f66bac90391379603d962","price_changes":[{"asset_id":"39272994714739463168905443499424551362424437245880253267329605556587274644733","best_ask":"0.58","best_bid":"0.57","hash":"6ea100d73941d5cf661f3aca3d5eca03314dfad9","price":"0.43","side":"BUY","size":"144.01"},{"asset_id":"20893381255801015515826997628594359667013752732428989472914000440642900266717","best_ask":"0.43","best_bid":"0.42","hash":"4ac231ea56117b3131e85bf857b06b212c273bba","price":"0.57","side":"SELL","size":"144.01"}],"timestamp":"1785204134294"},"payload_hash":"a391a96308baa0b15a05218c482d00c3aa909708304a05e3a85fd7dd249db181","raw_frame":"{\"market\":\"0xda6f0e0e93fc8469e0159a166028d017bddbc162b86f66bac90391379603d962\", \"price_changes\":[{\"asset_id\":\"39272994714739463168905443499424551362424437245880253267329605556587274644733\", \"price\":\"0.43\", \"size\":\"144.01\", \"side\":\"BUY\", \"hash\":\"6ea100d73941d5cf661f3aca3d5eca03314dfad9\", \"best_bid\":\"0.57\", \"best_ask\":\"0.58\"}, {\"asset_id\":\"20893381255801015515826997628594359667013752732428989472914000440642900266717\", \"price\":\"0.57\", \"size\":\"144.01\", \"side\":\"SELL\", \"hash\":\"4ac231ea56117b3131e85bf857b06b212c273bba\", \"best_bid\":\"0.42\", \"best_ask\":\"0.43\"}], \"timestamp\":\"1785204134294\", \"event_type\":\"price_change\"}","received_at":"2026-07-28T02:02:15.880517Z","schema_version":"clob-market-ws.price_change.v1","sequence":null,"server_hash":null,"server_timestamp":"1785204134294","session_id":"d2757dd6dad94f3b9fe67e8dbf1adc37","source":"clob_market_ws"},"received_at":"2026-07-28T02:02:15.880517Z","record_id":"e01d65a2f85fcc078c06b30faadd254cf53932dc2321889f6cf54ce7054d942e","schema_fingerprint":"4aa3821a28b0b7c2400bc59aba4bcc0a76e971dadd19610d3ad38c768e124dc7","schema_version":"edge-lab-recorder.raw.v1","sequence":null,"source":"clob_market_ws"}
{"event_at":"2026-07-28T02:02:14.297000Z","event_fingerprint":"e5ca0232b88d07f32787f5a6c15dc541c3c1e9965f415727c90b9fe1e5139240","payload":{"connection_id":"5d29200f65794d4d9ab6ef271f045a9b","event_at":"2026-07-28T02:02:14.297000Z","event_type":"price_change","frame_hash":"fff0d7f4962222b8fb5ad028203ef8fc4c50c7c9062ae456e97386241426fde9","frame_index":0,"kind":"data","monotonic_ns":306118888629875,"payload":{"event_type":"price_change","market":"0xda6f0e0e93fc8469e0159a166028d017bddbc162b86f66bac90391379603d962","price_changes":[{"asset_id":"20893381255801015515826997628594359667013752732428989472914000440642900266717","best_ask":"0.43","best_bid":"0.42","hash":"37b2d6281e84702bbd8abf4541addb28918ccd68","price":"0.26","side":"BUY","size":"179.6"},{"asset_id":"39272994714739463168905443499424551362424437245880253267329605556587274644733","best_ask":"0.58","best_bid":"0.57","hash":"9029110f29a6d76ac00c622c5f273e9e569e2ba6","price":"0.74","side":"SELL","size":"179.6"}],"timestamp":"1785204134297"},"payload_hash":"e0820938f109791f8399d398d97b160572c19f809202664a09e91a4b20dce52c","raw_frame":"{\"market\":\"0xda6f0e0e93fc8469e0159a166028d017bddbc162b86f66bac90391379603d962\", \"price_changes\":[{\"asset_id\":\"20893381255801015515826997628594359667013752732428989472914000440642900266717\", \"price\":\"0.26\", \"size\":\"179.6\", \"side\":\"BUY\", \"hash\":\"37b2d6281e84702bbd8abf4541addb28918ccd68\", \"best_bid\":\"0.42\", \"best_ask\":\"0.43\"}, {\"asset_id\":\"39272994714739463168905443499424551362424437245880253267329605556587274644733\", \"price\":\"0.74\", \"size\":\"179.6\", \"side\":\"SELL\", \"hash\":\"9029110f29a6d76ac00c622c5f273e9e569e2ba6\", \"best_bid\":\"0.57\", \"best_ask\":\"0.58\"}], \"timestamp\":\"1785204134297\", \"event_type\":\"price_change\"}","received_at":"2026-07-28T02:02:15.884240Z","schema_version":"clob-market-ws.price_change.v1","sequence":null,"server_hash":null,"server_timestamp":"1785204134297","session_id":"d2757dd6dad94f3b9fe67e8dbf1adc37","source":"clob_market_ws"},"received_at":"2026-07-28T02:02:15.884240Z","record_id":"30a243be155e6960922756f6c6472c2cbd4d43c116da16ed78264d77bbe47f44","schema_fingerprint":"4aa3821a28b0b7c2400bc59aba4bcc0a76e971dadd19610d3ad38c768e124dc7","schema_version":"edge-lab-recorder.raw.v1","sequence":null,"source":"clob_market_ws"}
{"event_at":"2026-07-28T02:02:14.298000Z","event_fingerprint":"fe377f21040e8a6f21f84dbf4dcff0aa5d752976b5a09e3ad76bafd05182608c","payload":{"connection_id":"5d29200f65794d4d9ab6ef271f045a9b","event_at":"2026-07-28T02:02:14.298000Z","event_type":"price_change","frame_hash":"22898e1306f05e74b1021e8fca6f1bd8efdb91c65c07f3dbe409f9a667534cff","frame_index":0,"kind":"data","monotonic_ns":306118896664916,"payload":{"event_type":"price_change","market":"0xda6f0e0e93fc8469e0159a166028d017bddbc162b86f66bac90391379603d962","price_changes":[{"asset_id":"39272994714739463168905443499424551362424437245880253267329605556587274644733","best_ask":"0.58","best_bid":"0.57","hash":"19dc252f46767f2b3937d212cb77e91ac6cde61c","price":"0.43","side":"BUY","size":"66.5"},{"asset_id":"20893381255801015515826997628594359667013752732428989472914000440642900266717","best_ask":"0.43","best_bid":"0.42","hash":"652f22a66efc654a65da3d4fcb54fa53be0619d7","price":"0.57","side":"SELL","size":"66.5"}],"timestamp":"1785204134298"},"payload_hash":"56c2996b727badd7f9d7967135300e9908d94a68193140774cdee197f609db68","raw_frame":"{\"market\":\"0xda6f0e0e93fc8469e0159a166028d017bddbc162b86f66bac90391379603d962\", \"price_changes\":[{\"asset_id\":\"39272994714739463168905443499424551362424437245880253267329605556587274644733\", \"price\":\"0.43\", \"size\":\"66.5\", \"side\":\"BUY\", \"hash\":\"19dc252f46767f2b3937d212cb77e91ac6cde61c\", \"best_bid\":\"0.57\", \"best_ask\":\"0.58\"}, {\"asset_id\":\"20893381255801015515826997628594359667013752732428989472914000440642900266717\", \"price\":\"0.57\", \"size\":\"66.5\", \"side\":\"SELL\", \"hash\":\"652f22a66efc654a65da3d4fcb54fa53be0619d7\", \"best_bid\":\"0.42\", \"best_ask\":\"0.43\"}], \"timestamp\":\"1785204134298\", \"event_type\":\"price_change\"}","received_at":"2026-07-28T02:02:15.892270Z","schema_version":"clob-market-ws.price_change.v1","sequence":null,"server_hash":null,"server_timestamp":"1785204134298","session_id":"d2757dd6dad94f3b9fe67e8dbf1adc37","source":"clob_market_ws"},"received_at":"2026-07-28T02:02:15.892270Z","record_id":"7398e9c53a6960165df86d5ed46b76d3836ea28a2d755a2ef0ddaf3354c9d18e","schema_fingerprint":"4aa3821a28b0b7c2400bc59aba4bcc0a76e971dadd19610d3ad38c768e124dc7","schema_version":"edge-lab-recorder.raw.v1","sequence":null,"source":"clob_market_ws"}
{"event_at":"2026-07-28T02:02:14.298000Z","event_fingerprint":"9e1aa1505b32b5fa528f2bf1e6e3063ff5040656759fa1ec05e63196d94522c2","payload":{"connection_id":"5d29200f65794d4d9ab6ef271f045a9b","event_at":"2026-07-28T02:02:14.298000Z","event_type":"price_change","frame_hash":"7ff9bd01d06b7132cf1590c32d9087f1f62f30fb8a3eae0f8f84fa34364f5513","frame_index":0,"kind":"data","monotonic_ns":306118899749125,"payload":{"event_type":"price_change","market":"0xda6f0e0e93fc8469e0159a166028d017bddbc162b86f66bac90391379603d962","price_changes":[{"asset_id":"39272994714739463168905443499424551362424437245880253267329605556587274644733","best_ask":"0.58","best_bid":"0.57","hash":"9fe8c9cf97f0adb8de2c98fcd22cce1b8216298b","price":"0.48","side":"BUY","size":"252.05"},{"asset_id":"20893381255801015515826997628594359667013752732428989472914000440642900266717","best_ask":"0.43","best_bid":"0.42","hash":"2e7d58c98d1ef3de74e7ad4e4b042c10a39eae52","price":"0.52","side":"SELL","size":"252.05"}],"timestamp":"1785204134298"},"payload_hash":"c25f97046fdad177181deb01eaeb0152e6569f959e37ab4a1504ec5b444c8f1a","raw_frame":"{\"market\":\"0xda6f0e0e93fc8469e0159a166028d017bddbc162b86f66bac90391379603d962\", \"price_changes\":[{\"asset_id\":\"39272994714739463168905443499424551362424437245880253267329605556587274644733\", \"price\":\"0.48\", \"size\":\"252.05\", \"side\":\"BUY\", \"hash\":\"9fe8c9cf97f0adb8de2c98fcd22cce1b8216298b\", \"best_bid\":\"0.57\", \"best_ask\":\"0.58\"}, {\"asset_id\":\"20893381255801015515826997628594359667013752732428989472914000440642900266717\", \"price\":\"0.52\", \"size\":\"252.05\", \"side\":\"SELL\", \"hash\":\"2e7d58c98d1ef3de74e7ad4e4b042c10a39eae52\", \"best_bid\":\"0.42\", \"best_ask\":\"0.43\"}], \"timestamp\":\"1785204134298\", \"event_type\":\"price_change\"}","received_at":"2026-07-28T02:02:15.895358Z","schema_version":"clob-market-ws.price_change.v1","sequence":null,"server_hash":null,"server_timestamp":"1785204134298","session_id":"d2757dd6dad94f3b9fe67e8dbf1adc37","source":"clob_market_ws"},"received_at":"2026-07-28T02:02:15.895358Z","record_id":"7ddd57afc83a5591ec394d79aa783f8e112ca25760fd33095eb8db5fbdeff30a","schema_fingerprint":"4aa3821a28b0b7c2400bc59aba4bcc0a76e971dadd19610d3ad38c768e124dc7","schema_version":"edge-lab-recorder.raw.v1","sequence":null,"source":"clob_market_ws"}
{"event_at":"2026-07-28T02:02:14.300000Z","event_fingerprint":"7949f7c49ba104e5ef9a9fbf5911da601b12df86c532a58b9d0706958b41494d","payload":{"connection_id":"5d29200f65794d4d9ab6ef271f045a9b","event_at":"2026-07-28T02:02:14.300000Z","event_type":"price_change","frame_hash":"6893a3fa5b097f86d5ac0258b36651932b37e2fa6e98f32c6ef7615b974aa55b","frame_index":0,"kind":"data","monotonic_ns":306118905127708,"payload":{"event_type":"price_change","market":"0xda6f0e0e93fc8469e0159a166028d017bddbc162b86f66bac90391379603d962","price_changes":[{"asset_id":"39272994714739463168905443499424551362424437245880253267329605556587274644733","best_ask":"0.58","best_bid":"0.57","hash":"05224e87a60d8fd61667b3e1f54dca73f4fb3591","price":"0.45","side":"BUY","size":"223"},{"asset_id":"20893381255801015515826997628594359667013752732428989472914000440642900266717","best_ask":"0.43","best_bid":"0.42","hash":"6f93214891dfe48491da5cd72c3faeed80587dc7","price":"0.55","side":"SELL","size":"223"}],"timestamp":"1785204134300"},"payload_hash":"7e3285c3bd2b847862b9cfa1dfdd0092e6fa87b1adfa21887c8212ea3fac5bbe","raw_frame":"{\"market\":\"0xda6f0e0e93fc8469e0159a166028d017bddbc162b86f66bac90391379603d962\", \"price_changes\":[{\"asset_id\":\"39272994714739463168905443499424551362424437245880253267329605556587274644733\", \"price\":\"0.45\", \"size\":\"223\", \"side\":\"BUY\", \"hash\":\"05224e87a60d8fd61667b3e1f54dca73f4fb3591\", \"best_bid\":\"0.57\", \"best_ask\":\"0.58\"}, {\"asset_id\":\"20893381255801015515826997628594359667013752732428989472914000440642900266717\", \"price\":\"0.55\", \"size\":\"223\", \"side\":\"SELL\", \"hash\":\"6f93214891dfe48491da5cd72c3faeed80587dc7\", \"best_bid\":\"0.42\", \"best_ask\":\"0.43\"}], \"timestamp\":\"1785204134300\", \"event_type\":\"price_change\"}","received_at":"2026-07-28T02:02:15.900731Z","schema_version":"clob-market-ws.price_change.v1","sequence":null,"server_hash":null,"server_timestamp":"1785204134300","session_id":"d2757dd6dad94f3b9fe67e8dbf1adc37","source":"clob_market_ws"},"received_at":"2026-07-28T02:02:15.900731Z","record_id":"c5c932a38ee5e289d67a6e7e1bda1ea67faffaf24e0cce07c29e2786195c05dc","schema_fingerprint":"4aa3821a28b0b7c2400bc59aba4bcc0a76e971dadd19610d3ad38c768e124dc7","schema_version":"edge-lab-recorder.raw.v1","sequence":null,"source":"clob_market_ws"}
{"event_at":"2026-07-28T02:02:14.301000Z","event_fingerprint":"5c496545e9aa2f60e1a8bb8f653a7379ff986a56d1c25b2ec5aa02cf74e3b23f","payload":{"connection_id":"5d29200f65794d4d9ab6ef271f045a9b","event_at":"2026-07-28T02:02:14.301000Z","event_type":"price_change","frame_hash":"2b74959372a6fd588104cb544fada44df3d9c5b8ddc2bf72f32aaa4d076b3cbb","frame_index":0,"kind":"data","monotonic_ns":306118911075000,"payload":{"event_type":"price_change","market":"0xda6f0e0e93fc8469e0159a166028d017bddbc162b86f66bac90391379603d962","price_changes":[{"asset_id":"20893381255801015515826997628594359667013752732428989472914000440642900266717","best_ask":"0.43","best_bid":"0.42","hash":"18db8823b0e8056ad0077c83eb22075ec3b655f3","price":"0.35","side":"BUY","size":"189"},{"asset_id":"39272994714739463168905443499424551362424437245880253267329605556587274644733","best_ask":"0.58","best_bid":"0.57","hash":"98f496dc6224ec1ca2cdc11746906a0528070370","price":"0.65","side":"SELL","size":"189"}],"timestamp":"1785204134301"},"payload_hash":"fd709ff9178ec28cf6409398ee537c74d46449084d266ee090be6dd6c946ae39","raw_frame":"{\"market\":\"0xda6f0e0e93fc8469e0159a166028d017bddbc162b86f66bac90391379603d962\", \"price_changes\":[{\"asset_id\":\"20893381255801015515826997628594359667013752732428989472914000440642900266717\", \"price\":\"0.35\", \"size\":\"189\", \"side\":\"BUY\", \"hash\":\"18db8823b0e8056ad0077c83eb22075ec3b655f3\", \"best_bid\":\"0.42\", \"best_ask\":\"0.43\"}, {\"asset_id\":\"39272994714739463168905443499424551362424437245880253267329605556587274644733\", \"price\":\"0.65\", \"size\":\"189\", \"side\":\"SELL\", \"hash\":\"98f496dc6224ec1ca2cdc11746906a0528070370\", \"best_bid\":\"0.57\", \"best_ask\":\"0.58\"}], \"timestamp\":\"1785204134301\", \"event_type\":\"price_change\"}","received_at":"2026-07-28T02:02:15.906679Z","schema_version":"clob-market-ws.price_change.v1","sequence":null,"server_hash":null,"server_timestamp":"1785204134301","session_id":"d2757dd6dad94f3b9fe67e8dbf1adc37","source":"clob_market_ws"},"received_at":"2026-07-28T02:02:15.906679Z","record_id":"b953b3a8a6c51d257faea34f2d1ae9e91e4ea541322d83d808eb3c94ae68d44b","schema_fingerprint":"4aa3821a28b0b7c2400bc59aba4bcc0a76e971dadd19610d3ad38c768e124dc7","schema_version":"edge-lab-recorder.raw.v1","sequence":null,"source":"clob_market_ws"}
{"event_at":"2026-07-28T02:02:14.303000Z","event_fingerprint":"ceabc51a09df16fd9c54c7e2349f71b58bac6885a9fa7ab6fb7ac7e2845ee3ae","payload":{"connection_id":"5d29200f65794d4d9ab6ef271f045a9b","event_at":"2026-07-28T02:02:14.303000Z","event_type":"price_change","frame_hash":"fe423a13add3fbc28ca2d4903b62b869ad63268212f60166c6321d0d6b3ddb4b","frame_index":0,"kind":"data","monotonic_ns":306118916271958,"payload":{"event_type":"price_change","market":"0xda6f0e0e93fc8469e0159a166028d017bddbc162b86f66bac90391379603d962","price_changes":[{"asset_id":"20893381255801015515826997628594359667013752732428989472914000440642900266717","best_ask":"0.43","best_bid":"0.42","hash":"c6c5b673b6a048f5827343baa78e0984bb95ccc1","price":"0.32","side":"BUY","size":"242.8"},{"asset_id":"39272994714739463168905443499424551362424437245880253267329605556587274644733","best_ask":"0.58","best_bid":"0.57","hash":"5b157b6c90acc5f485bb7e3188a63bcee9575f7e","price":"0.68","side":"SELL","size":"242.8"}],"timestamp":"1785204134303"},"payload_hash":"464f5f428749b36c8145276c0f07e728dc74e488051e5d8c2232ecc1ce3b2d41","raw_frame":"{\"market\":\"0xda6f0e0e93fc8469e0159a166028d017bddbc162b86f66bac90391379603d962\", \"price_changes\":[{\"asset_id\":\"20893381255801015515826997628594359667013752732428989472914000440642900266717\", \"price\":\"0.32\", \"size\":\"242.8\", \"side\":\"BUY\", \"hash\":\"c6c5b673b6a048f5827343baa78e0984bb95ccc1\", \"best_bid\":\"0.42\", \"best_ask\":\"0.43\"}, {\"asset_id\":\"39272994714739463168905443499424551362424437245880253267329605556587274644733\", \"price\":\"0.68\", \"size\":\"242.8\", \"side\":\"SELL\", \"hash\":\"5b157b6c90acc5f485bb7e3188a63bcee9575f7e\", \"best_bid\":\"0.57\", \"best_ask\":\"0.58\"}], \"timestamp\":\"1785204134303\", \"event_type\":\"price_change\"}","received_at":"2026-07-28T02:02:15.911876Z","schema_version":"clob-market-ws.price_change.v1","sequence":null,"server_hash":null,"server_timestamp":"1785204134303","session_id":"d2757dd6dad94f3b9fe67e8dbf1adc37","source":"clob_market_ws"},"received_at":"2026-07-28T02:02:15.911876Z","record_id":"52613203b80bd860bee40fdf4f3fec2edd5d7220d67438aa5ccb7638cbdf4aaf","schema_fingerprint":"4aa3821a28b0b7c2400bc59aba4bcc0a76e971dadd19610d3ad38c768e124dc7","schema_version":"edge-lab-recorder.raw.v1","sequence":null,"source":"clob_market_ws"}
{"event_at":"2026-07-28T02:02:14.303000Z","event_fingerprint":"f1ce3a68d5c6203c559cb44ded64595121d12508467934dfccd0b3af96dcf57a","payload":{"connection_id":"5d29200f65794d4d9ab6ef271f045a9b","event_at":"2026-07-28T02:02:14.303000Z","event_type":"price_change","frame_hash":"43afc3f8f9ccce0cb61803f04691150a8d65fa1b4808de638a822c0dfed43c68","frame_index":0,"kind":"data","monotonic_ns":306118921412583,"payload":{"event_type":"price_change","market":"0xda6f0e0e93fc8469e0159a166028d017bddbc162b86f66bac90391379603d962","price_changes":[{"asset_id":"39272994714739463168905443499424551362424437245880253267329605556587274644733","best_ask":"0.58","best_bid":"0.57","hash":"db27eab2a479a5d860cdba038c1e64748717b4e2","price":"0.55","side":"BUY","size":"47"},{"asset_id":"20893381255801015515826997628594359667013752732428989472914000440642900266717","best_ask":"0.43","best_bid":"0.42","hash":"2d5e3e4c024c75a4cde9644ec05b5f5291d15b92","price":"0.45","side":"SELL","size":"47"}],"timestamp":"1785204134303"},"payload_hash":"0755e2f004ce7940b287e6d0140c06d9dab54978fc3bdc55d36ac07ba8316ccd","raw_frame":"{\"market\":\"0xda6f0e0e93fc8469e0159a166028d017bddbc162b86f66bac90391379603d962\", \"price_changes\":[{\"asset_id\":\"39272994714739463168905443499424551362424437245880253267329605556587274644733\", \"price\":\"0.55\", \"size\":\"47\", \"side\":\"BUY\", \"hash\":\"db27eab2a479a5d860cdba038c1e64748717b4e2\", \"best_bid\":\"0.57\", \"best_ask\":\"0.58\"}, {\"asset_id\":\"20893381255801015515826997628594359667013752732428989472914000440642900266717\", \"price\":\"0.45\", \"size\":\"47\", \"side\":\"SELL\", \"hash\":\"2d5e3e4c024c75a4cde9644ec05b5f5291d15b92\", \"best_bid\":\"0.42\", \"best_ask\":\"0.43\"}], \"timestamp\":\"1785204134303\", \"event_type\":\"price_change\"}","received_at":"2026-07-28T02:02:15.917016Z","schema_version":"clob-market-ws.price_change.v1","sequence":null,"server_hash":null,"server_timestamp":"1785204134303","session_id":"d2757dd6dad94f3b9fe67e8dbf1adc37","source":"clob_market_ws"},"received_at":"2026-07-28T02:02:15.917016Z","record_id":"86209e80ffc798721d40b8c7acaee761ebce991e263ae5170e2e802d6d61503a","schema_fingerprint":"4aa3821a28b0b7c2400bc59aba4bcc0a76e971dadd19610d3ad38c768e124dc7","schema_version":"edge-lab-recorder.raw.v1","sequence":null,"source":"clob_market_ws"}
{"event_at":"2026-07-28T02:02:14.304000Z","event_fingerprint":"b692c552d5106ac7b3b7ea163c62401d43fec6a535ba6e1427a496f0631aa065","payload":{"connection_id":"5d29200f65794d4d9ab6ef271f045a9b","event_at":"2026-07-28T02:02:14.304000Z","event_type":"price_change","frame_hash":"b5047de9637abfc1ccb595d947853bce717bdb983a60c5b3bbe79e4ade30944b","frame_index":0,"kind":"data","monotonic_ns":306118926687583,"payload":{"event_type":"price_change","market":"0xda6f0e0e93fc8469e0159a166028d017bddbc162b86f66bac90391379603d962","price_changes":[{"asset_id":"20893381255801015515826997628594359667013752732428989472914000440642900266717","best_ask":"0.43","best_bid":"0.42","hash":"8629d0dee6bfe7ee8ef4171d7b2a5552f05cdf3f","price":"0.39","side":"BUY","size":"101.75"},{"asset_id":"39272994714739463168905443499424551362424437245880253267329605556587274644733","best_ask":"0.58","best_bid":"0.57","hash":"0dc32d80c56584a7af9a93383f40445d63297bac","price":"0.61","side":"SELL","size":"101.75"}],"timestamp":"1785204134304"},"payload_hash":"d09c07f438550a47eed7089d624761f50406c33765c5325d52e39bcaad8b8790","raw_frame":"{\"market\":\"0xda6f0e0e93fc8469e0159a166028d017bddbc162b86f66bac90391379603d962\", \"price_changes\":[{\"asset_id\":\"20893381255801015515826997628594359667013752732428989472914000440642900266717\", \"price\":\"0.39\", \"size\":\"101.75\", \"side\":\"BUY\", \"hash\":\"8629d0dee6bfe7ee8ef4171d7b2a5552f05cdf3f\", \"best_bid\":\"0.42\", \"best_ask\":\"0.43\"}, {\"asset_id\":\"39272994714739463168905443499424551362424437245880253267329605556587274644733\", \"price\":\"0.61\", \"size\":\"101.75\", \"side\":\"SELL\", \"hash\":\"0dc32d80c56584a7af9a93383f40445d63297bac\", \"best_bid\":\"0.57\", \"best_ask\":\"0.58\"}], \"timestamp\":\"1785204134304\", \"event_type\":\"price_change\"}","received_at":"2026-07-28T02:02:15.922292Z","schema_version":"clob-market-ws.price_change.v1","sequence":null,"server_hash":null,"server_timestamp":"1785204134304","session_id":"d2757dd6dad94f3b9fe67e8dbf1adc37","source":"clob_market_ws"},"received_at":"2026-07-28T02:02:15.922292Z","record_id":"56f59e04ef8a06789bca01c8d38e385add6610212ffc91b4518e6870f623a50d","schema_fingerprint":"4aa3821a28b0b7c2400bc59aba4bcc0a76e971dadd19610d3ad38c768e124dc7","schema_version":"edge-lab-recorder.raw.v1","sequence":null,"source":"clob_market_ws"}
{"event_at":"2026-07-28T02:02:14.305000Z","event_fingerprint":"420c620cd0452a7a174b7c9f2cf41e340c5c877a12b8c5a14229253c34b708ae","payload":{"connection_id":"5d29200f65794d4d9ab6ef271f045a9b","event_at":"2026-07-28T02:02:14.305000Z","event_type":"price_change","frame_hash":"13a6d6de30dbd707e9223cbb1f43b32f779b19737610a9919cb5ab54b4c31d3f","frame_index":0,"kind":"data","monotonic_ns":306118933821166,"payload":{"event_type":"price_change","market":"0xda6f0e0e93fc8469e0159a166028d017bddbc162b86f66bac90391379603d962","price_changes":[{"asset_id":"20893381255801015515826997628594359667013752732428989472914000440642900266717","best_ask":"0.43","best_bid":"0.42","hash":"65a5944b6f2dc172316fc31db56dc7c861e44f04","price":"0.4","side":"BUY","size":"92.68"},{"asset_id":"39272994714739463168905443499424551362424437245880253267329605556587274644733","best_ask":"0.58","best_bid":"0.57","hash":"6836272e6b6a867c540f3beab68cd470e9140186","price":"0.6","side":"SELL","size":"92.68"}],"timestamp":"1785204134305"},"payload_hash":"68fdc6541b964feafdf0140875b8f7720484bb89865bb35eccbe1358852ccde3","raw_frame":"{\"market\":\"0xda6f0e0e93fc8469e0159a166028d017bddbc162b86f66bac90391379603d962\", \"price_changes\":[{\"asset_id\":\"20893381255801015515826997628594359667013752732428989472914000440642900266717\", \"price\":\"0.4\", \"size\":\"92.68\", \"side\":\"BUY\", \"hash\":\"65a5944b6f2dc172316fc31db56dc7c861e44f04\", \"best_bid\":\"0.42\", \"best_ask\":\"0.43\"}, {\"asset_id\":\"39272994714739463168905443499424551362424437245880253267329605556587274644733\", \"price\":\"0.6\", \"size\":\"92.68\", \"side\":\"SELL\", \"hash\":\"6836272e6b6a867c540f3beab68cd470e9140186\", \"best_bid\":\"0.57\", \"best_ask\":\"0.58\"}], \"timestamp\":\"1785204134305\", \"event_type\":\"price_change\"}","received_at":"2026-07-28T02:02:15.929426Z","schema_version":"clob-market-ws.price_change.v1","sequence":null,"server_hash":null,"server_timestamp":"1785204134305","session_id":"d2757dd6dad94f3b9fe67e8dbf1adc37","source":"clob_market_ws"},"received_at":"2026-07-28T02:02:15.929426Z","record_id":"f98cd0cda1a3a1c4a7e5c68e52f1ba731c774fa7dd2789fcab07ea0faef17cc8","schema_fingerprint":"4aa3821a28b0b7c2400bc59aba4bcc0a76e971dadd19610d3ad38c768e124dc7","schema_version":"edge-lab-recorder.raw.v1","sequence":null,"source":"clob_market_ws"}
{"event_at":"2026-07-28T02:02:14.307000Z","event_fingerprint":"af46d0fe1956008420560b1c6eba2a872c80041266c5e75e1a397b7522b5691e","payload":{"connection_id":"5d29200f65794d4d9ab6ef271f045a9b","event_at":"2026-07-28T02:02:14.307000Z","event_type":"price_change","frame_hash":"0ab296e564157c7bb6e95a361f986fe9f437b6c398c5112e782cfcf6b1dca914","frame_index":0,"kind":"data","monotonic_ns":306118938469375,"payload":{"event_type":"price_change","market":"0xda6f0e0e93fc8469e0159a166028d017bddbc162b86f66bac90391379603d962","price_changes":[{"asset_id":"39272994714739463168905443499424551362424437245880253267329605556587274644733","best_ask":"0.58","best_bid":"0.57","hash":"8c33b0a12bdbd3728976203174abbafe15b06899","price":"0.44","side":"BUY","size":"169"},{"asset_id":"20893381255801015515826997628594359667013752732428989472914000440642900266717","best_ask":"0.43","best_bid":"0.42","hash":"32ed20c938c8ba6a79ac44dd7d955132eb8ec93b","price":"0.56","side":"SELL","size":"169"}],"timestamp":"1785204134307"},"payload_hash":"a0adb55da748c1aa7ab0c4a3f84e77a9f39ec65fd75f063eb58f3fa5bb017eb3","raw_frame":"{\"market\":\"0xda6f0e0e93fc8469e0159a166028d017bddbc162b86f66bac90391379603d962\", \"price_changes\":[{\"asset_id\":\"39272994714739463168905443499424551362424437245880253267329605556587274644733\", \"price\":\"0.44\", \"size\":\"169\", \"side\":\"BUY\", \"hash\":\"8c33b0a12bdbd3728976203174abbafe15b06899\", \"best_bid\":\"0.57\", \"best_ask\":\"0.58\"}, {\"asset_id\":\"20893381255801015515826997628594359667013752732428989472914000440642900266717\", \"price\":\"0.56\", \"size\":\"169\", \"side\":\"SELL\", \"hash\":\"32ed20c938c8ba6a79ac44dd7d955132eb8ec93b\", \"best_bid\":\"0.42\", \"best_ask\":\"0.43\"}], \"timestamp\":\"1785204134307\", \"event_type\":\"price_change\"}","received_at":"2026-07-28T02:02:15.934069Z","schema_version":"clob-market-ws.price_change.v1","sequence":null,"server_hash":null,"server_timestamp":"1785204134307","session_id":"d2757dd6dad94f3b9fe67e8dbf1adc37","source":"clob_market_ws"},"received_at":"2026-07-28T02:02:15.934069Z","record_id":"d2f2015f850c26ffcdf13a21bddad2f9b75833dd1a304764164c84ed6d01179e","schema_fingerprint":"4aa3821a28b0b7c2400bc59aba4bcc0a76e971dadd19610d3ad38c768e124dc7","schema_version":"edge-lab-recorder.raw.v1","sequence":null,"source":"clob_market_ws"}
{"event_at":"2026-07-28T02:02:14.307000Z","event_fingerprint":"f8b11ac0519d9e31ce68a735cc9b3ee8ab5409e09e9fcf18099b7bd9ed460c54","payload":{"connection_id":"5d29200f65794d4d9ab6ef271f045a9b","event_at":"2026-07-28T02:02:14.307000Z","event_type":"price_change","frame_hash":"a33dcbd608feb7923f47df1669d77e30c52a905f20afaee8b06b770e8079b6d8","frame_index":0,"kind":"data","monotonic_ns":306118946841666,"payload":{"event_type":"price_change","market":"0xda6f0e0e93fc8469e0159a166028d017bddbc162b86f66bac90391379603d962","price_changes":[{"asset_id":"39272994714739463168905443499424551362424437245880253267329605556587274644733","best_ask":"0.58","best_bid":"0.57","hash":"5f3052bf86178946b602129a177b4c06d0299c4d","price":"0.44","side":"BUY","size":"164"},{"asset_id":"20893381255801015515826997628594359667013752732428989472914000440642900266717","best_ask":"0.43","best_bid":"0.42","hash":"ddff8c37ca1d7ad843b13e2250fafd6803089d09","price":"0.56","side":"SELL","size":"164"}],"timestamp":"1785204134307"},"payload_hash":"d0a9d2f07af9f7423e5455ee772c520602b840050b02497d4c2335b66a3a9736","raw_frame":"{\"market\":\"0xda6f0e0e93fc8469e0159a166028d017bddbc162b86f66bac90391379603d962\", \"price_changes\":[{\"asset_id\":\"39272994714739463168905443499424551362424437245880253267329605556587274644733\", \"price\":\"0.44\", \"size\":\"164\", \"side\":\"BUY\", \"hash\":\"5f3052bf86178946b602129a177b4c06d0299c4d\", \"best_bid\":\"0.57\", \"best_ask\":\"0.58\"}, {\"asset_id\":\"20893381255801015515826997628594359667013752732428989472914000440642900266717\", \"price\":\"0.56\", \"size\":\"164\", \"side\":\"SELL\", \"hash\":\"ddff8c37ca1d7ad843b13e2250fafd6803089d09\", \"best_bid\":\"0.42\", \"best_ask\":\"0.43\"}], \"timestamp\":\"1785204134307\", \"event_type\":\"price_change\"}","received_at":"2026-07-28T02:02:15.942447Z","schema_version":"clob-market-ws.price_change.v1","sequence":null,"server_hash":null,"server_timestamp":"1785204134307","session_id":"d2757dd6dad94f3b9fe67e8dbf1adc37","source":"clob_market_ws"},"received_at":"2026-07-28T02:02:15.942447Z","record_id":"bca1a29f418198dafda9c677c6c76c6cb3cb5b1b2a7b81064b9d65097ffb9fdc","schema_fingerprint":"4aa3821a28b0b7c2400bc59aba4bcc0a76e971dadd19610d3ad38c768e124dc7","schema_version":"edge-lab-recorder.raw.v1","sequence":null,"source":"clob_market_ws"}
{"event_at":"2026-07-28T02:02:14.308000Z","event_fingerprint":"c756abc7f1db91b1a39c062b493330dc3dd1ea66c627992ca1591bb54dd6d744","payload":{"connection_id":"5d29200f65794d4d9ab6ef271f045a9b","event_at":"2026-07-28T02:02:14.308000Z","event_type":"price_change","frame_hash":"24ea13f892b5dff4ce269c5085ed48dc57f633942fe59dfc16cd222dd6db0645","frame_index":0,"kind":"data","monotonic_ns":306118949741333,"payload":{"event_type":"price_change","market":"0xda6f0e0e93fc8469e0159a166028d017bddbc162b86f66bac90391379603d962","price_changes":[{"asset_id":"20893381255801015515826997628594359667013752732428989472914000440642900266717","best_ask":"0.43","best_bid":"0.42","hash":"63d8d6dc7065d6fcc1f5fe43081ccff59a2518cb","price":"0.39","side":"BUY","size":"152.75"},{"asset_id":"39272994714739463168905443499424551362424437245880253267329605556587274644733","best_ask":"0.58","best_bid":"0.57","hash":"36efd5fd8e1c525a8b798636580351fe17c1f524","price":"0.61","side":"SELL","size":"152.75"}],"timestamp":"1785204134308"},"payload_hash":"9ebc4ce862e24cef478ee824964cd22f7c08905a9c4d1a0e1b15ada7b011fe34","raw_frame":"{\"market\":\"0xda6f0e0e93fc8469e0159a166028d017bddbc162b86f66bac90391379603d962\", \"price_changes\":[{\"asset_id\":\"20893381255801015515826997628594359667013752732428989472914000440642900266717\", \"price\":\"0.39\", \"size\":\"152.75\", \"side\":\"BUY\", \"hash\":\"63d8d6dc7065d6fcc1f5fe43081ccff59a2518cb\", \"best_bid\":\"0.42\", \"best_ask\":\"0.43\"}, {\"asset_id\":\"39272994714739463168905443499424551362424437245880253267329605556587274644733\", \"price\":\"0.61\", \"size\":\"152.75\", \"side\":\"SELL\", \"hash\":\"36efd5fd8e1c525a8b798636580351fe17c1f524\", \"best_bid\":\"0.57\", \"best_ask\":\"0.58\"}], \"timestamp\":\"1785204134308\", \"event_type\":\"price_change\"}","received_at":"2026-07-28T02:02:15.945349Z","schema_version":"clob-market-ws.price_change.v1","sequence":null,"server_hash":null,"server_timestamp":"1785204134308","session_id":"d2757dd6dad94f3b9fe67e8dbf1adc37","source":"clob_market_ws"},"received_at":"2026-07-28T02:02:15.945349Z","record_id":"5f591ea0fe7f7c131c0460688e08d93b936585204f33ff73a346ffda35c7cd17","schema_fingerprint":"4aa3821a28b0b7c2400bc59aba4bcc0a76e971dadd19610d3ad38c768e124dc7","schema_version":"edge-lab-recorder.raw.v1","sequence":null,"source":"clob_market_ws"}
{"event_at":"2026-07-28T02:02:14.311000Z","event_fingerprint":"740e589fabec0d022ca8bda2d4f1ea8bb57ef6bd414c7e14b401f5362a66ddc6","payload":{"connection_id":"5d29200f65794d4d9ab6ef271f045a9b","event_at":"2026-07-28T02:02:14.311000Z","event_type":"price_change","frame_hash":"b3ad585533e3ccc2ae9a51d3e1ab769e59cfd390c7906a7d7b40f9190ee55e7e","frame_index":0,"kind":"data","monotonic_ns":306118954137500,"payload":{"event_type":"price_change","market":"0xda6f0e0e93fc8469e0159a166028d017bddbc162b86f66bac90391379603d962","price_changes":[{"asset_id":"39272994714739463168905443499424551362424437245880253267329605556587274644733","best_ask":"0.58","best_bid":"0.57","hash":"17c01e1f0a734bbc78bb0f967dc23124702ea4cf","price":"0.41","side":"BUY","size":"150.3"},{"asset_id":"20893381255801015515826997628594359667013752732428989472914000440642900266717","best_ask":"0.43","best_bid":"0.42","hash":"d96583706ca64c3fc46406ef63c89379e39d9f8a","price":"0.59","side":"SELL","size":"150.3"}],"timestamp":"1785204134311"},"payload_hash":"5d3c2f514e0277362a852e3bc2615b5bc7773c20a6d9e83fbaf8b2893b5d8ee0","raw_frame":"{\"market\":\"0xda6f0e0e93fc8469e0159a166028d017bddbc162b86f66bac90391379603d962\", \"price_changes\":[{\"asset_id\":\"39272994714739463168905443499424551362424437245880253267329605556587274644733\", \"price\":\"0.41\", \"size\":\"150.3\", \"side\":\"BUY\", \"hash\":\"17c01e1f0a734bbc78bb0f967dc23124702ea4cf\", \"best_bid\":\"0.57\", \"best_ask\":\"0.58\"}, {\"asset_id\":\"20893381255801015515826997628594359667013752732428989472914000440642900266717\", \"price\":\"0.59\", \"size\":\"150.3\", \"side\":\"SELL\", \"hash\":\"d96583706ca64c3fc46406ef63c89379e39d9f8a\", \"best_bid\":\"0.42\", \"best_ask\":\"0.43\"}], \"timestamp\":\"1785204134311\", \"event_type\":\"price_change\"}","received_at":"2026-07-28T02:02:15.949742Z","schema_version":"clob-market-ws.price_change.v1","sequence":null,"server_hash":null,"server_timestamp":"1785204134311","session_id":"d2757dd6dad94f3b9fe67e8dbf1adc37","source":"clob_market_ws"},"received_at":"2026-07-28T02:02:15.949742Z","record_id":"389c4b09a693c6967eb2a9a821a434bba07e8ed73b8e49a0e5c14a497a85847e","schema_fingerprint":"4aa3821a28b0b7c2400bc59aba4bcc0a76e971dadd19610d3ad38c768e124dc7","schema_version":"edge-lab-recorder.raw.v1","sequence":null,"source":"clob_market_ws"}
