{"event_at":"2026-07-28T02:08:52.910000Z","event_fingerprint":"65fedceaa01340b51ab706b3e8a5a57dea224f22e45ae706f1ac79390fc157eb","payload":{"connection_id":"5d29200f65794d4d9ab6ef271f045a9b","event_at":"2026-07-28T02:08:52.910000Z","event_type":"price_change","frame_hash":"c33960cefd0df9f6e460ddcc1933562b08c216852919d0f9eb878b5f5d87b35b","frame_index":0,"kind":"data","monotonic_ns":306516597163416,"payload":{"event_type":"price_change","market":"0xda6f0e0e93fc8469e0159a166028d017bddbc162b86f66bac90391379603d962","price_changes":[{"asset_id":"20893381255801015515826997628594359667013752732428989472914000440642900266717","best_ask":"0.57","best_bid":"0.56","hash":"1260b90bf51e1e7582d78f8647f362499f0738f4","price":"0.57","side":"SELL","size":"70"},{"asset_id":"39272994714739463168905443499424551362424437245880253267329605556587274644733","best_ask":"0.44","best_bid":"0.43","hash":"b467ada0d7f027f317a165efbf83b52e89b8b200","price":"0.43","side":"BUY","size":"70"}],"timestamp":"1785204532910"},"payload_hash":"c911bd888fce9cc5ad584dc3e61721ed1eeb37c27b88d1fa3825dfa5a57d1170","raw_frame":"{\"market\":\"0xda6f0e0e93fc8469e0159a166028d017bddbc162b86f66bac90391379603d962\", \"price_changes\":[{\"asset_id\":\"20893381255801015515826997628594359667013752732428989472914000440642900266717\", \"price\":\"0.57\", \"size\":\"70\", \"side\":\"SELL\", \"hash\":\"1260b90bf51e1e7582d78f8647f362499f0738f4\", \"best_bid\":\"0.56\", \"best_ask\":\"0.57\"}, {\"asset_id\":\"39272994714739463168905443499424551362424437245880253267329605556587274644733\", \"price\":\"0.43\", \"size\":\"70\", \"side\":\"BUY\", \"hash\":\"b467ada0d7f027f317a165efbf83b52e89b8b200\", \"best_bid\":\"0.43\", \"best_ask\":\"0.44\"}], \"timestamp\":\"1785204532910\", \"event_type\":\"price_change\"}","received_at":"2026-07-28T02:08:53.588826Z","schema_version":"clob-market-ws.price_change.v1","sequence":null,"server_hash":null,"server_timestamp":"1785204532910","session_id":"d2757dd6dad94f3b9fe67e8dbf1adc37","source":"clob_market_ws"},"received_at":"2026-07-28T02:08:53.588826Z","record_id":"7ea03fe4ac2754fd2d1dd2ae08188540483509a4582815407e7571d2c4fc8d98","schema_fingerprint":"4aa3821a28b0b7c2400bc59aba4bcc0a76e971dadd19610d3ad38c768e124dc7","schema_version":"edge-lab-recorder.raw.v1","sequence":null,"source":"clob_market_ws"}
{"event_at":"2026-07-28T02:08:52.911000Z","event_fingerprint":"ff931249f173bdf98dbd65d887ec605cc7ee167a0ed7b231e48f2090b4022583","payload":{"connection_id":"5d29200f65794d4d9ab6ef271f045a9b","event_at":"2026-07-28T02:08:52.911000Z","event_type":"price_change","frame_hash":"839d964182e475e2d14f82450f4c5c5f88d22da07021b0a68f9f4ffe0b552854","frame_index":0,"kind":"data","monotonic_ns":306516603730708,"payload":{"event_type":"price_change","market":"0xda6f0e0e93fc8469e0159a166028d017bddbc162b86f66bac90391379603d962","price_changes":[{"asset_id":"39272994714739463168905443499424551362424437245880253267329605556587274644733","best_ask":"0.44","best_bid":"0.43","hash":"b55d8da1e10a7fa34f648a6836031afd8bc92aa5","price":"0.28","side":"BUY","size":"187.9"},{"asset_id":"20893381255801015515826997628594359667013752732428989472914000440642900266717","best_ask":"0.57","best_bid":"0.56","hash":"c379e75bdfbbdaa44311d68e5478945dce97bcfb","price":"0.72","side":"SELL","size":"187.9"}],"timestamp":"1785204532911"},"payload_hash":"053d81a0646eae00ffa7c07ffa9b32d8e8188526f1ec5c0926d12c5d80bcfeba","raw_frame":"{\"market\":\"0xda6f0e0e93fc8469e0159a166028d017bddbc162b86f66bac90391379603d962\", \"price_changes\":[{\"asset_id\":\"39272994714739463168905443499424551362424437245880253267329605556587274644733\", \"price\":\"0.28\", \"size\":\"187.9\", \"side\":\"BUY\", \"hash\":\"b55d8da1e10a7fa34f648a6836031afd8bc92aa5\", \"best_bid\":\"0.43\", \"best_ask\":\"0.44\"}, {\"asset_id\":\"20893381255801015515826997628594359667013752732428989472914000440642900266717\", \"price\":\"0.72\", \"size\":\"187.9\", \"side\":\"SELL\", \"hash\":\"c379e75bdfbbdaa44311d68e5478945dce97bcfb\", \"best_bid\":\"0.56\", \"best_ask\":\"0.57\"}], \"timestamp\":\"1785204532911\", \"event_type\":\"price_change\"}","received_at":"2026-07-28T02:08:53.595392Z","schema_version":"clob-market-ws.price_change.v1","sequence":null,"server_hash":null,"server_timestamp":"1785204532911","session_id":"d2757dd6dad94f3b9fe67e8dbf1adc37","source":"clob_market_ws"},"received_at":"2026-07-28T02:08:53.595392Z","record_id":"fd033c662db89c605f371ceb914013e3e8bae1f1d470f56d5f280b259850ecf2","schema_fingerprint":"4aa3821a28b0b7c2400bc59aba4bcc0a76e971dadd19610d3ad38c768e124dc7","schema_version":"edge-lab-recorder.raw.v1","sequence":null,"source":"clob_market_ws"}
{"event_at":"2026-07-28T02:08:52.912000Z","event_fingerprint":"b3afd8290238affff3598771eed32c7990cc028171a0a747554fb0f64e5d4c27","payload":{"connection_id":"5d29200f65794d4d9ab6ef271f045a9b","event_at":"2026-07-28T02:08:52.912000Z","event_type":"price_change","frame_hash":"6e4f7bc221adbbc1ef2c05cc8d2d6b72383af14978c7d8a26034d6f2c2527bd2","frame_index":0,"kind":"data","monotonic_ns":306516607639708,"payload":{"event_type":"price_change","market":"0xda6f0e0e93fc8469e0159a166028d017bddbc162b86f66bac90391379603d962","price_changes":[{"asset_id":"39272994714739463168905443499424551362424437245880253267329605556587274644733","best_ask":"0.44","best_bid":"0.43","hash":"b6d912010d850e6b057da9625e2bb26153a8524f","price":"0.41","side":"BUY","size":"115.99"},{"asset_id":"20893381255801015515826997628594359667013752732428989472914000440642900266717","best_ask":"0.57","best_bid":"0.56","hash":"281461969307f37c1d632e0d8937b97d73f9d475","price":"0.59","side":"SELL","size":"115.99"}],"timestamp":"1785204532912"},"payload_hash":"9e5c288e21e865a7d86fbf05c25e99f6e2ac3e7506bc38761c5821c5ed8ff74d","raw_frame":"{\"market\":\"0xda6f0e0e93fc8469e0159a166028d017bddbc162b86f66bac90391379603d962\", \"price_changes\":[{\"asset_id\":\"39272994714739463168905443499424551362424437245880253267329605556587274644733\", \"price\":\"0.41\", \"size\":\"115.99\", \"side\":\"BUY\", \"hash\":\"b6d912010d850e6b057da9625e2bb26153a8524f\", \"best_bid\":\"0.43\", \"best_ask\":\"0.44\"}, {\"asset_id\":\"20893381255801015515826997628594359667013752732428989472914000440642900266717\", \"price\":\"0.59\", \"size\":\"115.99\", \"side\":\"SELL\", \"hash\":\"281461969307f37c1d632e0d8937b97d73f9d475\", \"best_bid\":\"0.56\", \"best_ask\":\"0.57\"}], \"timestamp\":\"1785204532912\", \"event_type\":\"price_change\"}","received_at":"2026-07-28T02:08:53.599303Z","schema_version":"clob-market-ws.price_change.v1","sequence":null,"server_hash":null,"server_timestamp":"1785204532912","session_id":"d2757dd6dad94f3b9fe67e8dbf1adc37","source":"clob_market_ws"},"received_at":"2026-07-28T02:08:53.599303Z","record_id":"1fcc9ddcbf6fd4b2574437d19ec1055b0559d5d67b1019ad05324d9b5cb8d9e2","schema_fingerprint":"4aa3821a28b0b7c2400bc59aba4bcc0a76e971dadd19610d3ad38c768e124dc7","schema_version":"edge-lab-recorder.raw.v1","sequence":null,"source":"clob_market_ws"}
{"event_at":"2026-07-28T02:08:52.912000Z","event_fingerprint":"9a58abfa8d6cd18cc6101099bc1605fb72a6701ab8d75472372e41412445aa95","payload":{"connection_id":"5d29200f65794d4d9ab6ef271f045a9b","event_at":"2026-07-28T02:08:52.912000Z","event_type":"price_change","frame_hash":"926aa370a0cbcd89bf195da7ab2d51563f6318df9df33892664a86ebe0c5355f","frame_index":0,"kind":"data","monotonic_ns":306516611337000,"payload":{"event_type":"price_change","market":"0xda6f0e0e93fc8469e0159a166028d017bddbc162b86f66bac90391379603d962","price_changes":[{"asset_id":"39272994714739463168905443499424551362424437245880253267329605556587274644733","best_ask":"0.44","best_bid":"0.43","hash":"b6d912010d850e6b057da9625e2bb26153a8524f","price":"0.42","side":"BUY","size":"44"},{"asset_id":"20893381255801015515826997628594359667013752732428989472914000440642900266717","best_ask":"0.57","best_bid":"0.56","hash":"281461969307f37c1d632e0d8937b97d73f9d475","price":"0.58","side":"SELL","size":"44"}],"timestamp":"1785204532912"},"payload_hash":"21e9580f368445af62d08f6ae338787d6305e5fce6d943bb5eab904d2d8c1522","raw_frame":"{\"market\":\"0xda6f0e0e93fc8469e0159a166028d017bddbc162b86f66bac90391379603d962\", \"price_changes\":[{\"asset_id\":\"39272994714739463168905443499424551362424437245880253267329605556587274644733\", \"price\":\"0.42\", \"size\":\"44\", \"side\":\"BUY\", \"hash\":\"b6d912010d850e6b057da9625e2bb26153a8524f\", \"best_bid\":\"0.43\", \"best_ask\":\"0.44\"}, {\"asset_id\":\"20893381255801015515826997628594359667013752732428989472914000440642900266717\", \"price\":\"0.58\", \"size\":\"44\", \"side\":\"SELL\", \"hash\":\"281461969307f37c1d632e0d8937b97d73f9d475\", \"best_bid\":\"0.56\", \"best_ask\":\"0.57\"}], \"timestamp\":\"1785204532912\", \"event_type\":\"price_change\"}","received_at":"2026-07-28T02:08:53.603000Z","schema_version":"clob-market-ws.price_change.v1","sequence":null,"server_hash":null,"server_timestamp":"1785204532912","session_id":"d2757dd6dad94f3b9fe67e8dbf1adc37","source":"clob_market_ws"},"received_at":"2026-07-28T02:08:53.603000Z","record_id":"2fca795ebc72847a0e9757e1993cf176a5642c895f7cd35d38c3645a99c38c94","schema_fingerprint":"4aa3821a28b0b7c2400bc59aba4bcc0a76e971dadd19610d3ad38c768e124dc7","schema_version":"edge-lab-recorder.raw.v1","sequence":null,"source":"clob_market_ws"}
{"event_at":"2026-07-28T02:08:52.912000Z","event_fingerprint":"94040aee8ee9432c96abccad094d619cc89c0f73b2e0f7ab8b3e248fd187c7b9","payload":{"connection_id":"5d29200f65794d4d9ab6ef271f045a9b","event_at":"2026-07-28T02:08:52.912000Z","event_type":"price_change","frame_hash":"7f33f0c6f87dbe228f533bbcfb2d125b6106d561c90acb506f9c90d966c3931f","frame_index":0,"kind":"data","monotonic_ns":306516614331000,"payload":{"event_type":"price_change","market":"0xda6f0e0e93fc8469e0159a166028d017bddbc162b86f66bac90391379603d962","price_changes":[{"asset_id":"20893381255801015515826997628594359667013752732428989472914000440642900266717","best_ask":"0.57","best_bid":"0.56","hash":"9197b8440d4a780d6318b04db2f6506984a1abf4","price":"0.01","side":"BUY","size":"5687.02"},{"asset_id":"39272994714739463168905443499424551362424437245880253267329605556587274644733","best_ask":"0.44","best_bid":"0.43","hash":"6e8a39dc10b09e1cf97f4fc5072481bd6eb28e72","price":"0.99","side":"SELL","size":"5687.02"}],"timestamp":"1785204532912"},"payload_hash":"82e32466bf2ea153ed642f3f9f61d08fcd3dadeafb35fa787766c7ebdf9bfa5b","raw_frame":"{\"market\":\"0xda6f0e0e93fc8469e0159a166028d017bddbc162b86f66bac90391379603d962\", \"price_changes\":[{\"asset_id\":\"20893381255801015515826997628594359667013752732428989472914000440642900266717\", \"price\":\"0.01\", \"size\":\"5687.02\", \"side\":\"BUY\", \"hash\":\"9197b8440d4a780d6318b04db2f6506984a1abf4\", \"best_bid\":\"0.56\", \"best_ask\":\"0.57\"}, {\"asset_id\":\"39272994714739463168905443499424551362424437245880253267329605556587274644733\", \"price\":\"0.99\", \"size\":\"5687.02\", \"side\":\"SELL\", \"hash\":\"6e8a39dc10b09e1cf97f4fc5072481bd6eb28e72\", \"best_bid\":\"0.43\", \"best_ask\":\"0.44\"}], \"timestamp\":\"1785204532912\", \"event_type\":\"price_change\"}","received_at":"2026-07-28T02:08:53.605995Z","schema_version":"clob-market-ws.price_change.v1","sequence":null,"server_hash":null,"server_timestamp":"1785204532912","session_id":"d2757dd6dad94f3b9fe67e8dbf1adc37","source":"clob_market_ws"},"received_at":"2026-07-28T02:08:53.605995Z","record_id":"7cc2ba04a5be2739c8be1868279333ed34959694cc8ce7694eeede867edd9191","schema_fingerprint":"4aa3821a28b0b7c2400bc59aba4bcc0a76e971dadd19610d3ad38c768e124dc7","schema_version":"edge-lab-recorder.raw.v1","sequence":null,"source":"clob_market_ws"}
{"event_at":"2026-07-28T02:08:52.913000Z","event_fingerprint":"e9db4b630f13a8c9992bc0f03843becfde2c84653062b47e241f8c9c958cd707","payload":{"connection_id":"5d29200f65794d4d9ab6ef271f045a9b","event_at":"2026-07-28T02:08:52.913000Z","event_type":"price_change","frame_hash":"ce208b417bde3884b851e4b8a3998f980f6c1bf91b31ce5ba0604b5dd78a6522","frame_index":0,"kind":"data","monotonic_ns":306516618015250,"payload":{"event_type":"price_change","market":"0xda6f0e0e93fc8469e0159a166028d017bddbc162b86f66bac90391379603d962","price_changes":[{"asset_id":"39272994714739463168905443499424551362424437245880253267329605556587274644733","best_ask":"0.44","best_bid":"0.43","hash":"a444b56aea6996953940127b610e76edb0b6ca27","price":"0.41","side":"BUY","size":"90.99"},{"asset_id":"20893381255801015515826997628594359667013752732428989472914000440642900266717","best_ask":"0.57","best_bid":"0.56","hash":"02ee3b22d30124716c4281b42608c67438f5ad8f","price":"0.59","side":"SELL","size":"90.99"}],"timestamp":"1785204532913"},"payload_hash":"787e8decf8c8f61f43dc9cc10f60bcfc6ba56fc6c8614a90841e720d7680c37a","raw_frame":"{\"market\":\"0xda6f0e0e93fc8469e0159a166028d017bddbc162b86f66bac90391379603d962\", \"price_changes\":[{\"asset_id\":\"39272994714739463168905443499424551362424437245880253267329605556587274644733\", \"price\":\"0.41\", \"size\":\"90.99\", \"side\":\"BUY\", \"hash\":\"a444b56aea6996953940127b610e76edb0b6ca27\", \"best_bid\":\"0.43\", \"best_ask\":\"0.44\"}, {\"asset_id\":\"20893381255801015515826997628594359667013752732428989472914000440642900266717\", \"price\":\"0.59\", \"size\":\"90.99\", \"side\":\"SELL\", \"hash\":\"02ee3b22d30124716c4281b42608c67438f5ad8f\", \"best_bid\":\"0.56\", \"best_ask\":\"0.57\"}], \"timestamp\":\"1785204532913\", \"event_type\":\"price_change\"}","received_at":"2026-07-28T02:08:53.609677Z","schema_version":"clob-market-ws.price_change.v1","sequence":null,"server_hash":null,"server_timestamp":"1785204532913","session_id":"d2757dd6dad94f3b9fe67e8dbf1adc37","source":"clob_market_ws"},"received_at":"2026-07-28T02:08:53.609677Z","record_id":"9de4f625270c2a97ce0bcaff926dcee109550d37252b44b1b0b3ec054c4d2658","schema_fingerprint":"4aa3821a28b0b7c2400bc59aba4bcc0a76e971dadd19610d3ad38c768e124dc7","schema_version":"edge-lab-recorder.raw.v1","sequence":null,"source":"clob_market_ws"}
{"event_at":"2026-07-28T02:08:52.917000Z","event_fingerprint":"03ae9c1fbf868af6ba6e37c18648fd6ed3e3d131f31c8bb8cdebf3773a4fc68d","payload":{"connection_id":"5d29200f65794d4d9ab6ef271f045a9b","event_at":"2026-07-28T02:08:52.917000Z","event_type":"price_change","frame_hash":"4a134d6652e0c3a6b92dd8520aaf4ecef2b64f2a4a68ab17a57dc0dd2a796ded","frame_index":0,"kind":"data","monotonic_ns":306516621809791,"payload":{"event_type":"price_change","market":"0xda6f0e0e93fc8469e0159a166028d017bddbc162b86f66bac90391379603d962","price_changes":[{"asset_id":"39272994714739463168905443499424551362424437245880253267329605556587274644733","best_ask":"0.44","best_bid":"0.43","hash":"7f6852c7d6a062c14d8af1008d1d01ab52997091","price":"0.43","side":"BUY","size":"65"},{"asset_id":"20893381255801015515826997628594359667013752732428989472914000440642900266717","best_ask":"0.57","best_bid":"0.56","hash":"eb54c764b5f3d4913e4ab90f1741b2e095456a9a","price":"0.57","side":"SELL","size":"65"}],"timestamp":"1785204532917"},"payload_hash":"fd94911caecb42c9e460ca88d6a368da38eac2e704fc4e85dd309dc5017dd47a","raw_frame":"{\"market\":\"0xda6f0e0e93fc8469e0159a166028d017bddbc162b86f66bac90391379603d962\", \"price_changes\":[{\"asset_id\":\"39272994714739463168905443499424551362424437245880253267329605556587274644733\", \"price\":\"0.43\", \"size\":\"65\", \"side\":\"BUY\", \"hash\":\"7f6852c7d6a062c14d8af1008d1d01ab52997091\", \"best_bid\":\"0.43\", \"best_ask\":\"0.44\"}, {\"asset_id\":\"20893381255801015515826997628594359667013752732428989472914000440642900266717\", \"price\":\"0.57\", \"size\":\"65\", \"side\":\"SELL\", \"hash\":\"eb54c764b5f3d4913e4ab90f1741b2e095456a9a\", \"best_bid\":\"0.56\", \"best_ask\":\"0.57\"}], \"timestamp\":\"1785204532917\", \"event_type\":\"price_change\"}","received_at":"2026-07-28T02:08:53.613473Z","schema_version":"clob-market-ws.price_change.v1","sequence":null,"server_hash":null,"server_timestamp":"1785204532917","session_id":"d2757dd6dad94f3b9fe67e8dbf1adc37","source":"clob_market_ws"},"received_at":"2026-07-28T02:08:53.613473Z","record_id":"200b6953925db7c878cdddc027c7a52e3707f9efcdb1caf1eb3430e51e47fc76","schema_fingerprint":"4aa3821a28b0b7c2400bc59aba4bcc0a76e971dadd19610d3ad38c768e124dc7","schema_version":"edge-lab-recorder.raw.v1","sequence":null,"source":"clob_market_ws"}
{"event_at":"2026-07-28T02:08:52.919000Z","event_fingerprint":"9932bf90d5e66152dcde259e9d3de2aecc0025facde0bc5c79d4992e0f3e23d1","payload":{"connection_id":"5d29200f65794d4d9ab6ef271f045a9b","event_at":"2026-07-28T02:08:52.919000Z","event_type":"price_change","frame_hash":"b58677166c3dbbfb733f1c9f86176b15887d03ebf1b90c4283e57572133bc52c","frame_index":0,"kind":"data","monotonic_ns":306516624911291,"payload":{"event_type":"price_change","market":"0xda6f0e0e93fc8469e0159a166028d017bddbc162b86f66bac90391379603d962","price_changes":[{"asset_id":"20893381255801015515826997628594359667013752732428989472914000440642900266717","best_ask":"0.57","best_bid":"0.56","hash":"3502181709b048e80262511bf70f4eda942bff2e","price":"0.45","side":"BUY","size":"227"},{"asset_id":"39272994714739463168905443499424551362424437245880253267329605556587274644733","best_ask":"0.44","best_bid":"0.43","hash":"03e37b55d685f33feb1dbe07487d1948793c8bca","price":"0.55","side":"SELL","size":"227"}],"timestamp":"1785204532919"},"payload_hash":"8e1286e039f38f2f026e2fefd3dd27f5db98b8cee515e7f678793b8e0b886015","raw_frame":"{\"market\":\"0xda6f0e0e93fc8469e0159a166028d017bddbc162b86f66bac90391379603d962\", \"price_changes\":[{\"asset_id\":\"20893381255801015515826997628594359667013752732428989472914000440642900266717\", \"price\":\"0.45\", \"size\":\"227\", \"side\":\"BUY\", \"hash\":\"3502181709b048e80262511bf70f4eda942bff2e\", \"best_bid\":\"0.56\", \"best_ask\":\"0.57\"}, {\"asset_id\":\"39272994714739463168905443499424551362424437245880253267329605556587274644733\", \"price\":\"0.55\", \"size\":\"227\", \"side\":\"SELL\", \"hash\":\"03e37b55d685f33feb1dbe07487d1948793c8bca\", \"best_bid\":\"0.43\", \"best_ask\":\"0.44\"}], \"timestamp\":\"1785204532919\", \"event_type\":\"price_change\"}","received_at":"2026-07-28T02:08:53.616574Z","schema_version":"clob-market-ws.price_change.v1","sequence":null,"server_hash":null,"server_timestamp":"1785204532919","session_id":"d2757dd6dad94f3b9fe67e8dbf1adc37","source":"clob_market_ws"},"received_at":"2026-07-28T02:08:53.616574Z","record_id":"b8315263caa7d29b6caa588932f3784f795d7ec1ad8877a7fc24b535e564bc25","schema_fingerprint":"4aa3821a28b0b7c2400bc59aba4bcc0a76e971dadd19610d3ad38c768e124dc7","schema_version":"edge-lab-recorder.raw.v1","sequence":null,"source":"clob_market_ws"}
{"event_at":"2026-07-28T02:08:52.923000Z","event_fingerprint":"949d584c85ec5a57891a94a4c8a5ebc840bc8fa8c516e9894f5fe15a7b877284","payload":{"connection_id":"5d29200f65794d4d9ab6ef271f045a9b","event_at":"2026-07-28T02:08:52.923000Z","event_type":"price_change","frame_hash":"224736ea5874d493c239a934ff183cd599042f83776882ad782041122e230e2b","frame_index":0,"kind":"data","monotonic_ns":306516627174833,"payload":{"event_type":"price_change","market":"0xda6f0e0e93fc8469e0159a166028d017bddbc162b86f66bac90391379603d962","price_changes":[{"asset_id":"20893381255801015515826997628594359667013752732428989472914000440642900266717","best_ask":"0.57","best_bid":"0.56","hash":"94512b7e94b9e242e13a5e5274d5427a952f84a3","price":"0.03","side":"BUY","size":"662.1"},{"asset_id":"39272994714739463168905443499424551362424437245880253267329605556587274644733","best_ask":"0.44","best_bid":"0.43","hash":"48047ea71e43573ae7eec034dea7f2feafbb4e2f","price":"0.97","side":"SELL","size":"662.1"}],"timestamp":"1785204532923"},"payload_hash":"e70682c7650f7d76a36f1fd704124eb673ec4176fc1a3f4ce35aa2f4bbbb01a1","raw_frame":"{\"market\":\"0xda6f0e0e93fc8469e0159a166028d017bddbc162b86f66bac90391379603d962\", \"price_changes\":[{\"asset_id\":\"20893381255801015515826997628594359667013752732428989472914000440642900266717\", \"price\":\"0.03\", \"size\":\"662.1\", \"side\":\"BUY\", \"hash\":\"94512b7e94b9e242e13a5e5274d5427a952f84a3\", \"best_bid\":\"0.56\", \"best_ask\":\"0.57\"}, {\"asset_id\":\"39272994714739463168905443499424551362424437245880253267329605556587274644733\", \"price\":\"0.97\", \"size\":\"662.1\", \"side\":\"SELL\", \"hash\":\"48047ea71e43573ae7eec034dea7f2feafbb4e2f\", \"best_bid\":\"0.43\", \"best_ask\":\"0.44\"}], \"timestamp\":\"1785204532923\", \"event_type\":\"price_change\"}","received_at":"2026-07-28T02:08:53.618838Z","schema_version":"clob-market-ws.price_change.v1","sequence":null,"server_hash":null,"server_timestamp":"1785204532923","session_id":"d2757dd6dad94f3b9fe67e8dbf1adc37","source":"clob_market_ws"},"received_at":"2026-07-28T02:08:53.618838Z","record_id":"0ef3936a9dce5bada68cf48af5ba2f06e8022f7e65bb24e533fa7e23501f5a2f","schema_fingerprint":"4aa3821a28b0b7c2400bc59aba4bcc0a76e971dadd19610d3ad38c768e124dc7","schema_version":"edge-lab-recorder.raw.v1","sequence":null,"source":"clob_market_ws"}
{"event_at":"2026-07-28T02:08:52.930000Z","event_fingerprint":"87dd7453ce2b99ec2c586b0b1b99dd16c216cd6bcf763a176cd44e51622e5e80","payload":{"connection_id":"5d29200f65794d4d9ab6ef271f045a9b","event_at":"2026-07-28T02:08:52.930000Z","event_type":"price_change","frame_hash":"ddc978b0115898f1c385ded326b1d5ebcaac129fb78b609b722b7e1118341ef6","frame_index":0,"kind":"data","monotonic_ns":306516630825458,"payload":{"event_type":"price_change","market":"0xda6f0e0e93fc8469e0159a166028d017bddbc162b86f66bac90391379603d962","price_changes":[{"asset_id":"20893381255801015515826997628594359667013752732428989472914000440642900266717","best_ask":"0.57","best_bid":"0.56","hash":"9a5e9151fd9aee7067858339856007dcf3b5b7e8","price":"0.01","side":"BUY","size":"5682.02"},{"asset_id":"39272994714739463168905443499424551362424437245880253267329605556587274644733","best_ask":"0.44","best_bid":"0.43","hash":"b25d7a96628c1363adaf9c720154295874a2fadd","price":"0.99","side":"SELL","size":"5682.02"}],"timestamp":"1785204532930"},"payload_hash":"fb36ccca2264478bd29bc56e76f1bbc37b22a93d96f604314df9560df2fb663b","raw_frame":"{\"market\":\"0xda6f0e0e93fc8469e0159a166028d017bddbc162b86f66bac90391379603d962\", \"price_changes\":[{\"asset_id\":\"20893381255801015515826997628594359667013752732428989472914000440642900266717\", \"price\":\"0.01\", \"size\":\"5682.02\", \"side\":\"BUY\", \"hash\":\"9a5e9151fd9aee7067858339856007dcf3b5b7e8\", \"best_bid\":\"0.56\", \"best_ask\":\"0.57\"}, {\"asset_id\":\"39272994714739463168905443499424551362424437245880253267329605556587274644733\", \"price\":\"0.99\", \"size\":\"5682.02\", \"side\":\"SELL\", \"hash\":\"b25d7a96628c1363adaf9c720154295874a2fadd\", \"best_bid\":\"0.43\", \"best_ask\":\"0.44\"}], \"timestamp\":\"1785204532930\", \"event_type\":\"price_change\"}","received_at":"2026-07-28T02:08:53.622489Z","schema_version":"clob-market-ws.price_change.v1","sequence":null,"server_hash":null,"server_timestamp":"1785204532930","session_id":"d2757dd6dad94f3b9fe67e8dbf1adc37","source":"clob_market_ws"},"received_at":"2026-07-28T02:08:53.622489Z","record_id":"d99f5f54e25fe617a2700f11dfff14f93b504f233d565d9be6dee27e23fc2eb2","schema_fingerprint":"4aa3821a28b0b7c2400bc59aba4bcc0a76e971dadd19610d3ad38c768e124dc7","schema_version":"edge-lab-recorder.raw.v1","sequence":null,"source":"clob_market_ws"}
{"event_at":"2026-07-28T02:08:52.936000Z","event_fingerprint":"ed1f5fb188ec0dca5baf070e76b18ee473691f57514e590b84c4665268dd29e3","payload":{"connection_id":"5d29200f65794d4d9ab6ef271f045a9b","event_at":"2026-07-28T02:08:52.936000Z","event_type":"price_change","frame_hash":"fe5dbf0420b4e46b965e6e9f82babec27d78080562c332ab36fc96f043409387","frame_index":0,"kind":"data","monotonic_ns":306516633116541,"payload":{"event_type":"price_change","market":"0xda6f0e0e93fc8469e0159a166028d017bddbc162b86f66bac90391379603d962","price_changes":[{"asset_id":"39272994714739463168905443499424551362424437245880253267329605556587274644733","best_ask":"0.44","best_bid":"0.43","hash":"6a332abf370c33f182e2bbb35a0b0700545b9c96","price":"0.43","side":"BUY","size":"90"},{"asset_id":"20893381255801015515826997628594359667013752732428989472914000440642900266717","best_ask":"0.57","best_bid":"0.56","hash":"066f4b234f55faf212d6145c8fb895cb11a4511b","price":"0.57","side":"SELL","size":"90"}],"timestamp":"1785204532936"},"payload_hash":"ce72b4f6b29b7b1538f185155e8781d3cf5cf1129e34aca6516858c609727ba3","raw_frame":"{\"market\":\"0xda6f0e0e93fc8469e0159a166028d017bddbc162b86f66bac90391379603d962\", \"price_changes\":[{\"asset_id\":\"39272994714739463168905443499424551362424437245880253267329605556587274644733\", \"price\":\"0.43\", \"size\":\"90\", \"side\":\"BUY\", \"hash\":\"6a332abf370c33f182e2bbb35a0b0700545b9c96\", \"best_bid\":\"0.43\", \"best_ask\":\"0.44\"}, {\"asset_id\":\"20893381255801015515826997628594359667013752732428989472914000440642900266717\", \"price\":\"0.57\", \"size\":\"90\", \"side\":\"SELL\", \"hash\":\"066f4b234f55faf212d6145c8fb895cb11a4511b\", \"best_bid\":\"0.56\", \"best_ask\":\"0.57\"}], \"timestamp\":\"1785204532936\", \"event_type\":\"price_change\"}","received_at":"2026-07-28T02:08:53.624779Z","schema_version":"clob-market-ws.price_change.v1","sequence":null,"server_hash":null,"server_timestamp":"1785204532936","session_id":"d2757dd6dad94f3b9fe67e8dbf1adc37","source":"clob_market_ws"},"received_at":"2026-07-28T02:08:53.624779Z","record_id":"021190da6d2f243cafd0a239c83ae4af55df36c7ef58662dbd3bc38db7f94f07","schema_fingerprint":"4aa3821a28b0b7c2400bc59aba4bcc0a76e971dadd19610d3ad38c768e124dc7","schema_version":"edge-lab-recorder.raw.v1","sequence":null,"source":"clob_market_ws"}
{"event_at":"2026-07-28T02:08:52.940000Z","event_fingerprint":"adb82f60856e1ed5e979fe434b0fdb80a1913ab33d9d437da92dbb1de9f512c5","payload":{"connection_id":"5d29200f65794d4d9ab6ef271f045a9b","event_at":"2026-07-28T02:08:52.940000Z","event_type":"price_change","frame_hash":"205430c89d39e641a7c31bb22addc99a89c63dbca868023a3709a8968d154680","frame_index":0,"kind":"data","monotonic_ns":306516636739875,"payload":{"event_type":"price_change","market":"0xda6f0e0e93fc8469e0159a166028d017bddbc162b86f66bac90391379603d962","price_changes":[{"asset_id":"39272994714739463168905443499424551362424437245880253267329605556587274644733","best_ask":"0.44","best_bid":"0.43","hash":"79f6e12ae0712f880b2563c48be161d4758bbd22","price":"0.29","side":"BUY","size":"217.1"},{"asset_id":"20893381255801015515826997628594359667013752732428989472914000440642900266717","best_ask":"0.57","best_bid":"0.56","hash":"d34bffb49f2768597f5d115351d93118939118b4","price":"0.71","side":"SELL","size":"217.1"}],"timestamp":"1785204532940"},"payload_hash":"dceabd70c2409a98f2024aecc978c1d6e6538f66e68e77af4ba8fd55c22f34c3","raw_frame":"{\"market\":\"0xda6f0e0e93fc8469e0159a166028d017bddbc162b86f66bac90391379603d962\", \"price_changes\":[{\"asset_id\":\"39272994714739463168905443499424551362424437245880253267329605556587274644733\", \"price\":\"0.29\", \"size\":\"217.1\", \"side\":\"BUY\", \"hash\":\"79f6e12ae0712f880b2563c48be161d4758bbd22\", \"best_bid\":\"0.43\", \"best_ask\":\"0.44\"}, {\"asset_id\":\"20893381255801015515826997628594359667013752732428989472914000440642900266717\", \"price\":\"0.71\", \"size\":\"217.1\", \"side\":\"SELL\", \"hash\":\"d34bffb49f2768597f5d115351d93118939118b4\", \"best_bid\":\"0.56\", \"best_ask\":\"0.57\"}], \"timestamp\":\"1785204532940\", \"event_type\":\"price_change\"}","received_at":"2026-07-28T02:08:53.628404Z","schema_version":"clob-market-ws.price_change.v1","sequence":null,"server_hash":null,"server_timestamp":"1785204532940","session_id":"d2757dd6dad94f3b9fe67e8dbf1adc37","source":"clob_market_ws"},"received_at":"2026-07-28T02:08:53.628404Z","record_id":"a62ebfd80840daf8884835f9dbc403260a669f8ff9c75e603b05def670f87fe4","schema_fingerprint":"4aa3821a28b0b7c2400bc59aba4bcc0a76e971dadd19610d3ad38c768e124dc7","schema_version":"edge-lab-recorder.raw.v1","sequence":null,"source":"clob_market_ws"}
{"event_at":"2026-07-28T02:08:52.941000Z","event_fingerprint":"7f4f9a07f8149d49175eeeab260327a527ddcbe6d22ce861b953b8fd24b4060b","payload":{"connection_id":"5d29200f65794d4d9ab6ef271f045a9b","event_at":"2026-07-28T02:08:52.941000Z","event_type":"price_change","frame_hash":"4b7f46c288a2997d30aedc2bfad9581fb3c5e72f00b2a629cd434089178914d4","frame_index":0,"kind":"data","monotonic_ns":306516639761000,"payload":{"event_type":"price_change","market":"0xda6f0e0e93fc8469e0159a166028d017bddbc162b86f66bac90391379603d962","price_changes":[{"asset_id":"20893381255801015515826997628594359667013752732428989472914000440642900266717","best_ask":"0.57","best_bid":"0.56","hash":"8127f6558d56742ac46ff71d52b5465856c34b97","price":"0.01","side":"BUY","size":"5687.02"},{"asset_id":"39272994714739463168905443499424551362424437245880253267329605556587274644733","best_ask":"0.44","best_bid":"0.43","hash":"521e78d46ee20ee74818e61d27a4482fe8f728eb","price":"0.99","side":"SELL","size":"5687.02"}],"timestamp":"1785204532941"},"payload_hash":"2b1470bbf95e3d49c176aca958f061d6b209c3f7f145f49002e4743403ed8d58","raw_frame":"{\"market\":\"0xda6f0e0e93fc8469e0159a166028d017bddbc162b86f66bac90391379603d962\", \"price_changes\":[{\"asset_id\":\"20893381255801015515826997628594359667013752732428989472914000440642900266717\", \"price\":\"0.01\", \"size\":\"5687.02\", \"side\":\"BUY\", \"hash\":\"8127f6558d56742ac46ff71d52b5465856c34b97\", \"best_bid\":\"0.56\", \"best_ask\":\"0.57\"}, {\"asset_id\":\"39272994714739463168905443499424551362424437245880253267329605556587274644733\", \"price\":\"0.99\", \"size\":\"5687.02\", \"side\":\"SELL\", \"hash\":\"521e78d46ee20ee74818e61d27a4482fe8f728eb\", \"best_bid\":\"0.43\", \"best_ask\":\"0.44\"}], \"timestamp\":\"1785204532941\", \"event_type\":\"price_change\"}","received_at":"2026-07-28T02:08:53.631424Z","schema_version":"clob-market-ws.price_change.v1","sequence":null,"server_hash":null,"server_timestamp":"1785204532941","session_id":"d2757dd6dad94f3b9fe67e8dbf1adc37","source":"clob_market_ws"},"received_at":"2026-07-28T02:08:53.631424Z","record_id":"0c3febfe23f88843be06ab33a3f2aba8033148a682ff77442b7ce26fb065ec69","schema_fingerprint":"4aa3821a28b0b7c2400bc59aba4bcc0a76e971dadd19610d3ad38c768e124dc7","schema_version":"edge-lab-recorder.raw.v1","sequence":null,"source":"clob_market_ws"}
{"event_at":"2026-07-28T02:08:52.953000Z","event_fingerprint":"70dcc2f28495c3733cb0898f6478cd96e83e704409c9e975df4ed2495bb752b1","payload":{"connection_id":"5d29200f65794d4d9ab6ef271f045a9b","event_at":"2026-07-28T02:08:52.953000Z","event_type":"price_change","frame_hash":"664e933332e924f2ea4f2e13d0f4fed7d79ece209e3695b551e501b9d499373b","frame_index":0,"kind":"data","monotonic_ns":306516642904541,"payload":{"event_type":"price_change","market":"0xda6f0e0e93fc8469e0159a166028d017bddbc162b86f66bac90391379603d962","price_changes":[{"asset_id":"39272994714739463168905443499424551362424437245880253267329605556587274644733","best_ask":"0.44","best_bid":"0.43","hash":"a8dd200f4193f1e18866deb71faa95ce4e3ad1d0","price":"0.22","side":"BUY","size":"68.5"},{"asset_id":"20893381255801015515826997628594359667013752732428989472914000440642900266717","best_ask":"0.57","best_bid":"0.56","hash":"e429bdfa96f8cabe8e7fad180490cfcea69ceeae","price":"0.78","side":"SELL","size":"68.5"}],"timestamp":"1785204532953"},"payload_hash":"2b709c573e6e371c693858e63919cadcfff19624ada997a7119fe7923964efa5","raw_frame":"{\"market\":\"0xda6f0e0e93fc8469e0159a166028d017bddbc162b86f66bac90391379603d962\", \"price_changes\":[{\"asset_id\":\"39272994714739463168905443499424551362424437245880253267329605556587274644733\", \"price\":\"0.22\", \"size\":\"68.5\", \"side\":\"BUY\", \"hash\":\"a8dd200f4193f1e18866deb71faa95ce4e3ad1d0\", \"best_bid\":\"0.43\", \"best_ask\":\"0.44\"}, {\"asset_id\":\"20893381255801015515826997628594359667013752732428989472914000440642900266717\", \"price\":\"0.78\", \"size\":\"68.5\", \"side\":\"SELL\", \"hash\":\"e429bdfa96f8cabe8e7fad180490cfcea69ceeae\", \"best_bid\":\"0.56\", \"best_ask\":\"0.57\"}], \"timestamp\":\"1785204532953\", \"event_type\":\"price_change\"}","received_at":"2026-07-28T02:08:53.634566Z","schema_version":"clob-market-ws.price_change.v1","sequence":null,"server_hash":null,"server_timestamp":"1785204532953","session_id":"d2757dd6dad94f3b9fe67e8dbf1adc37","source":"clob_market_ws"},"received_at":"2026-07-28T02:08:53.634566Z","record_id":"08f20a06e08c3c55d5f65135c495f7c1880bf16871efcd475064e03a30e7d1d3","schema_fingerprint":"4aa3821a28b0b7c2400bc59aba4bcc0a76e971dadd19610d3ad38c768e124dc7","schema_version":"edge-lab-recorder.raw.v1","sequence":null,"source":"clob_market_ws"}
{"event_at":"2026-07-28T02:08:52.953000Z","event_fingerprint":"2514c6faaa73b9af9cdd10bfe988d421b2814653945b63cae7acb1c2c34593d7","payload":{"connection_id":"5d29200f65794d4d9ab6ef271f045a9b","event_at":"2026-07-28T02:08:52.953000Z","event_type":"price_change","frame_hash":"9c5e77a3a32654f9c1c52bd5522135352f313215ef7ef79712b8715a94331c80","frame_index":0,"kind":"data","monotonic_ns":306516647191708,"payload":{"event_type":"price_change","market":"0xda6f0e0e93fc8469e0159a166028d017bddbc162b86f66bac90391379603d962","price_changes":[{"asset_id":"20893381255801015515826997628594359667013752732428989472914000440642900266717","best_ask":"0.57","best_bid":"0.56","hash":"6c4268cc9a952c48f2b84579b1f3fb911c482078","price":"0.55","side":"BUY","size":"30"},{"asset_id":"39272994714739463168905443499424551362424437245880253267329605556587274644733","best_ask":"0.44","best_bid":"0.43","hash":"5185ae53789cf2353bf0637fe08a6b8f334ddc96","price":"0.45","side":"SELL","size":"30"}],"timestamp":"1785204532953"},"payload_hash":"b2efc15fa2a2cb2185e807d4d427c372ed46cc9952a3818dbb1b51392313c237","raw_frame":"{\"market\":\"0xda6f0e0e93fc8469e0159a166028d017bddbc162b86f66bac90391379603d962\", \"price_changes\":[{\"asset_id\":\"20893381255801015515826997628594359667013752732428989472914000440642900266717\", \"price\":\"0.55\", \"size\":\"30\", \"side\":\"BUY\", \"hash\":\"6c4268cc9a952c48f2b84579b1f3fb911c482078\", \"best_bid\":\"0.56\", \"best_ask\":\"0.57\"}, {\"asset_id\":\"39272994714739463168905443499424551362424437245880253267329605556587274644733\", \"price\":\"0.45\", \"size\":\"30\", \"side\":\"SELL\", \"hash\":\"5185ae53789cf2353bf0637fe08a6b8f334ddc96\", \"best_bid\":\"0.43\", \"best_ask\":\"0.44\"}], \"timestamp\":\"1785204532953\", \"event_type\":\"price_change\"}","received_at":"2026-07-28T02:08:53.638855Z","schema_version":"clob-market-ws.price_change.v1","sequence":null,"server_hash":null,"server_timestamp":"1785204532953","session_id":"d2757dd6dad94f3b9fe67e8dbf1adc37","source":"clob_market_ws"},"received_at":"2026-07-28T02:08:53.638855Z","record_id":"f1dd94a0ebc4b9ed197c9182eef651f32f1ac8186fae25a3ab370f317db8c12b","schema_fingerprint":"4aa3821a28b0b7c2400bc59aba4bcc0a76e971dadd19610d3ad38c768e124dc7","schema_version":"edge-lab-recorder.raw.v1","sequence":null,"source":"clob_market_ws"}
{"event_at":"2026-07-28T02:08:52.954000Z","event_fingerprint":"7896315ff42b8c469de714e3e598d43a764741fd668c1732f11a6fc42535ad6d","payload":{"connection_id":"5d29200f65794d4d9ab6ef271f045a9b","event_at":"2026-07-28T02:08:52.954000Z","event_type":"price_change","frame_hash":"32679295c6511e3504d88ef36865caea22897bb6e90d7e49e16e9d01ac9722d2","frame_index":0,"kind":"data","monotonic_ns":306516650258083,"payload":{"event_type":"price_change","market":"0xda6f0e0e93fc8469e0159a166028d017bddbc162b86f66bac90391379603d962","price_changes":[{"asset_id":"20893381255801015515826997628594359667013752732428989472914000440642900266717","best_ask":"0.57","best_bid":"0.56","hash":"d3bc11c1b4d9e721d3fbb7e8c7685683a995247b","price":"0.54","side":"BUY","size":"81"},{"asset_id":"39272994714739463168905443499424551362424437245880253267329605556587274644733","best_ask":"0.44","best_bid":"0.43","hash":"5bd4cdd6b80307c923eab82089e58fd8af3253e2","price":"0.46","side":"SELL","size":"81"}],"timestamp":"1785204532954"},"payload_hash":"5a3d8183928491962dbc513181b70eac7ae60361c4552cd6246d9d4ecef9837b","raw_frame":"{\"market\":\"0xda6f0e0e93fc8469e0159a166028d017bddbc162b86f66bac90391379603d962\", \"price_changes\":[{\"asset_id\":\"20893381255801015515826997628594359667013752732428989472914000440642900266717\", \"price\":\"0.54\", \"size\":\"81\", \"side\":\"BUY\", \"hash\":\"d3bc11c1b4d9e721d3fbb7e8c7685683a995247b\", \"best_bid\":\"0.56\", \"best_ask\":\"0.57\"}, {\"asset_id\":\"39272994714739463168905443499424551362424437245880253267329605556587274644733\", \"price\":\"0.46\", \"size\":\"81\", \"side\":\"SELL\", \"hash\":\"5bd4cdd6b80307c923eab82089e58fd8af3253e2\", \"best_bid\":\"0.43\", \"best_ask\":\"0.44\"}], \"timestamp\":\"1785204532954\", \"event_type\":\"price_change\"}","received_at":"2026-07-28T02:08:53.641921Z","schema_version":"clob-market-ws.price_change.v1","sequence":null,"server_hash":null,"server_timestamp":"1785204532954","session_id":"d2757dd6dad94f3b9fe67e8dbf1adc37","source":"clob_market_ws"},"received_at":"2026-07-28T02:08:53.641921Z","record_id":"04e4abe78c19a636c0dbbbf2b9203a9271e50d6e3a5a29d007978b1bd0eb0d1f","schema_fingerprint":"4aa3821a28b0b7c2400bc59aba4bcc0a76e971dadd19610d3ad38c768e124dc7","schema_version":"edge-lab-recorder.raw.v1","sequence":null,"source":"clob_market_ws"}
{"event_at":"2026-07-28T02:08:52.955000Z","event_fingerprint":"763a546004903445bf212e0321864f6f27a6c9c1cbc87b8d9ba53d00c8df2163","payload":{"connection_id":"5d29200f65794d4d9ab6ef271f045a9b","event_at":"2026-07-28T02:08:52.955000Z","event_type":"price_change","frame_hash":"fe5e8e087fa32277240734bc4dfae07f93ac8e55fc56182bdcc9b21d041bf03f","frame_index":0,"kind":"data","monotonic_ns":306516653257958,"payload":{"event_type":"price_change","market":"0xda6f0e0e93fc8469e0159a166028d017bddbc162b86f66bac90391379603d962","price_changes":[{"asset_id":"20893381255801015515826997628594359667013752732428989472914000440642900266717","best_ask":"0.57","best_bid":"0.56","hash":"6c9e146bbb83c0f8d9cb189dffc8d4f5bf58aaf2","price":"0.54","side":"BUY","size":"52"},{"asset_id":"39272994714739463168905443499424551362424437245880253267329605556587274644733","best_ask":"0.44","best_bid":"0.43","hash":"a141dbabe06e42a40e7aebea9ae4466de5eddd4b","price":"0.46","side":"SELL","size":"52"}],"timestamp":"1785204532955"},"payload_hash":"56db8036d23f977e97123e518f94221f3b8729d87b8362b60c07b1aa1122b549","raw_frame":"{\"market\":\"0xda6f0e0e93fc8469e0159a166028d017bddbc162b86f66bac90391379603d962\", \"price_changes\":[{\"asset_id\":\"20893381255801015515826997628594359667013752732428989472914000440642900266717\", \"price\":\"0.54\", \"size\":\"52\", \"side\":\"BUY\", \"hash\":\"6c9e146bbb83c0f8d9cb189dffc8d4f5bf58aaf2\", \"best_bid\":\"0.56\", \"best_ask\":\"0.57\"}, {\"asset_id\":\"39272994714739463168905443499424551362424437245880253267329605556587274644733\", \"price\":\"0.46\", \"size\":\"52\", \"side\":\"SELL\", \"hash\":\"a141dbabe06e42a40e7aebea9ae4466de5eddd4b\", \"best_bid\":\"0.43\", \"best_ask\":\"0.44\"}], \"timestamp\":\"1785204532955\", \"event_type\":\"price_change\"}","received_at":"2026-07-28T02:08:53.644920Z","schema_version":"clob-market-ws.price_change.v1","sequence":null,"server_hash":null,"server_timestamp":"1785204532955","session_id":"d2757dd6dad94f3b9fe67e8dbf1adc37","source":"clob_market_ws"},"received_at":"2026-07-28T02:08:53.644920Z","record_id":"a24ffb665f518c8f77080f6caff3fe7bf6eb310c4ef621d752cbc2d54c8611bd","schema_fingerprint":"4aa3821a28b0b7c2400bc59aba4bcc0a76e971dadd19610d3ad38c768e124dc7","schema_version":"edge-lab-recorder.raw.v1","sequence":null,"source":"clob_market_ws"}
{"event_at":"2026-07-28T02:08:52.955000Z","event_fingerprint":"8590966767084d78f332894994da2b02f69ae234fb1847d844a8f8e31b6d989e","payload":{"connection_id":"5d29200f65794d4d9ab6ef271f045a9b","event_at":"2026-07-28T02:08:52.955000Z","event_type":"price_change","frame_hash":"21dcdcd7dc2510da5a1ceb3382c6e28d294449c2dde79802a4fd0ab41d2725f3","frame_index":0,"kind":"data","monotonic_ns":306516656223125,"payload":{"event_type":"price_change","market":"0xda6f0e0e93fc8469e0159a166028d017bddbc162b86f66bac90391379603d962","price_changes":[{"asset_id":"20893381255801015515826997628594359667013752732428989472914000440642900266717","best_ask":"0.57","best_bid":"0.56","hash":"b99577e1ec62864258be927eca48092734e790b7","price":"0.56","side":"BUY","size":"40.2"},{"asset_id":"39272994714739463168905443499424551362424437245880253267329605556587274644733","best_ask":"0.44","best_bid":"0.43","hash":"4623b3d58082620192f88f174a32815c62f39ba9","price":"0.44","side":"SELL","size":"40.2"}],"timestamp":"1785204532955"},"payload_hash":"c7b1f21e852d522e333c73d048cca958c085dd3bda9c546f306c9ed2e435ff9e","raw_frame":"{\"market\":\"0xda6f0e0e93fc8469e0159a166028d017bddbc162b86f66bac90391379603d962\", \"price_changes\":[{\"asset_id\":\"20893381255801015515826997628594359667013752732428989472914000440642900266717\", \"price\":\"0.56\", \"size\":\"40.2\", \"side\":\"BUY\", \"hash\":\"b99577e1ec62864258be927eca48092734e790b7\", \"best_bid\":\"0.56\", \"best_ask\":\"0.57\"}, {\"asset_id\":\"39272994714739463168905443499424551362424437245880253267329605556587274644733\", \"price\":\"0.44\", \"size\":\"40.2\", \"side\":\"SELL\", \"hash\":\"4623b3d58082620192f88f174a32815c62f39ba9\", \"best_bid\":\"0.43\", \"best_ask\":\"0.44\"}], \"timestamp\":\"1785204532955\", \"event_type\":\"price_change\"}","received_at":"2026-07-28T02:08:53.647887Z","schema_version":"clob-market-ws.price_change.v1","sequence":null,"server_hash":null,"server_timestamp":"1785204532955","session_id":"d2757dd6dad94f3b9fe67e8dbf1adc37","source":"clob_market_ws"},"received_at":"2026-07-28T02:08:53.647887Z","record_id":"5c6ea3512af2eeac58b276a8a0d7075994c79b042337bd05b6942cd2f9ccda11","schema_fingerprint":"4aa3821a28b0b7c2400bc59aba4bcc0a76e971dadd19610d3ad38c768e124dc7","schema_version":"edge-lab-recorder.raw.v1","sequence":null,"source":"clob_market_ws"}
{"event_at":"2026-07-28T02:08:52.955000Z","event_fingerprint":"7b65071f8b6565d1d3d766b22a625741d5c14ca45af52e67a99425ad24a91a5f","payload":{"connection_id":"5d29200f65794d4d9ab6ef271f045a9b","event_at":"2026-07-28T02:08:52.955000Z","event_type":"price_change","frame_hash":"4ae5b3c5a1f3cce4f5e3e8987508cf42caaf4b11118793c08e08e5f9249371e9","frame_index":0,"kind":"data","monotonic_ns":306516659125791,"payload":{"event_type":"price_change","market":"0xda6f0e0e93fc8469e0159a166028d017bddbc162b86f66bac90391379603d962","price_changes":[{"asset_id":"20893381255801015515826997628594359667013752732428989472914000440642900266717","best_ask":"0.57","best_bid":"0.56","hash":"c822508d4ac237bbfa46728234f333f593b73dd1","price":"0.56","side":"BUY","size":"25.2"},{"asset_id":"39272994714739463168905443499424551362424437245880253267329605556587274644733","best_ask":"0.44","best_bid":"0.43","hash":"14b84c2b7bca4fc3726fccc3da47fb0cef87c00e","price":"0.44","side":"SELL","size":"25.2"}],"timestamp":"1785204532955"},"payload_hash":"66ca38d192fe0999bc4e21eb72d2ee1586390f004ca1e648c97e1f57d2b541ae","raw_frame":"{\"market\":\"0xda6f0e0e93fc8469e0159a166028d017bddbc162b86f66bac90391379603d962\", \"price_changes\":[{\"asset_id\":\"20893381255801015515826997628594359667013752732428989472914000440642900266717\", \"price\":\"0.56\", \"size\":\"25.2\", \"side\":\"BUY\", \"hash\":\"c822508d4ac237bbfa46728234f333f593b73dd1\", \"best_bid\":\"0.56\", \"best_ask\":\"0.57\"}, {\"asset_id\":\"39272994714739463168905443499424551362424437245880253267329605556587274644733\", \"price\":\"0.44\", \"size\":\"25.2\", \"side\":\"SELL\", \"hash\":\"14b84c2b7bca4fc3726fccc3da47fb0cef87c00e\", \"best_bid\":\"0.43\", \"best_ask\":\"0.44\"}], \"timestamp\":\"1785204532955\", \"event_type\":\"price_change\"}","received_at":"2026-07-28T02:08:53.650789Z","schema_version":"clob-market-ws.price_change.v1","sequence":null,"server_hash":null,"server_timestamp":"1785204532955","session_id":"d2757dd6dad94f3b9fe67e8dbf1adc37","source":"clob_market_ws"},"received_at":"2026-07-28T02:08:53.650789Z","record_id":"7bf591c0e38c236c195a470fcec9e092cc192fc10f67f981a05c2d891f4913cf","schema_fingerprint":"4aa3821a28b0b7c2400bc59aba4bcc0a76e971dadd19610d3ad38c768e124dc7","schema_version":"edge-lab-recorder.raw.v1","sequence":null,"source":"clob_market_ws"}
{"event_at":"2026-07-28T02:08:52.956000Z","event_fingerprint":"532fd9e38398bb4eaa5a71cdc296089455abaa618b16c7c385201d1eb50dffc9","payload":{"connection_id":"5d29200f65794d4d9ab6ef271f045a9b","event_at":"2026-07-28T02:08:52.956000Z","event_type":"price_change","frame_hash":"6760398509948422b0a5f544576f8c820da8f83df20e25c9a2c8a845ccdd8648","frame_index":0,"kind":"data","monotonic_ns":306516662249833,"payload":{"event_type":"price_change","market":"0xda6f0e0e93fc8469e0159a166028d017bddbc162b86f66bac90391379603d962","price_changes":[{"asset_id":"20893381255801015515826997628594359667013752732428989472914000440642900266717","best_ask":"0.57","best_bid":"0.56","hash":"967c0bbb6822a4736c8401c25aad1f5e4f1b4ead","price":"0.55","side":"BUY","size":"15"},{"asset_id":"39272994714739463168905443499424551362424437245880253267329605556587274644733","best_ask":"0.44","best_bid":"0.43","hash":"ff974835aca10e443137596550f1179b1b9a5938","price":"0.45","side":"SELL","size":"15"}],"timestamp":"1785204532956"},"payload_hash":"c81d6e0c70e77a471be11b7576a7aee3b891036077639ef7e5c5bc33784182db","raw_frame":"{\"market\":\"0xda6f0e0e93fc8469e0159a166028d017bddbc162b86f66bac90391379603d962\", \"price_changes\":[{\"asset_id\":\"20893381255801015515826997628594359667013752732428989472914000440642900266717\", \"price\":\"0.55\", \"size\":\"15\", \"side\":\"BUY\", \"hash\":\"967c0bbb6822a4736c8401c25aad1f5e4f1b4ead\", \"best_bid\":\"0.56\", \"best_ask\":\"0.57\"}, {\"asset_id\":\"39272994714739463168905443499424551362424437245880253267329605556587274644733\", \"price\":\"0.45\", \"size\":\"15\", \"side\":\"SELL\", \"hash\":\"ff974835aca10e443137596550f1179b1b9a5938\", \"best_bid\":\"0.43\", \"best_ask\":\"0.44\"}], \"timestamp\":\"1785204532956\", \"event_type\":\"price_change\"}","received_at":"2026-07-28T02:08:53.653912Z","schema_version":"clob-market-ws.price_change.v1","sequence":null,"server_hash":null,"server_timestamp":"1785204532956","session_id":"d2757dd6dad94f3b9fe67e8dbf1adc37","source":"clob_market_ws"},"received_at":"2026-07-28T02:08:53.653912Z","record_id":"d765f9f5431168e708346c4ceec43605c33d5cb4a47dbecdc9726917f9ff78e3","schema_fingerprint":"4aa3821a28b0b7c2400bc59aba4bcc0a76e971dadd19610d3ad38c768e124dc7","schema_version":"edge-lab-recorder.raw.v1","sequence":null,"source":"clob_market_ws"}
{"event_at":"2026-07-28T02:08:52.957000Z","event_fingerprint":"fafbab7142ea3d4c8f2dc8bfdf3bcfe55aba496584b9060776fbd453d4330153","payload":{"connection_id":"5d29200f65794d4d9ab6ef271f045a9b","event_at":"2026-07-28T02:08:52.957000Z","event_type":"price_change","frame_hash":"3025ab155ef8c5e8e34dcacd4be41e671c019346deb055753c751ece9e85d7cc","frame_index":0,"kind":"data","monotonic_ns":306516665144208,"payload":{"event_type":"price_change","market":"0xda6f0e0e93fc8469e0159a166028d017bddbc162b86f66bac90391379603d962","price_changes":[{"asset_id":"39272994714739463168905443499424551362424437245880253267329605556587274644733","best_ask":"0.44","best_bid":"0.43","hash":"b805f0912f71c28da236baba0fc85e151573eda5","price":"0.33","side":"BUY","size":"128"},{"asset_id":"20893381255801015515826997628594359667013752732428989472914000440642900266717","best_ask":"0.57","best_bid":"0.56","hash":"825e2d83490a1484d829edfd0a5399f718337089","price":"0.67","side":"SELL","size":"128"}],"timestamp":"1785204532957"},"payload_hash":"50d4dbea6fbbab55b290592d8d1763a2b652b322a0e5d99c9e1716656561cbed","raw_frame":"{\"market\":\"0xda6f0e0e93fc8469e0159a166028d017bddbc162b86f66bac90391379603d962\", \"price_changes\":[{\"asset_id\":\"39272994714739463168905443499424551362424437245880253267329605556587274644733\", \"price\":\"0.33\", \"size\":\"128\", \"side\":\"BUY\", \"hash\":\"b805f0912f71c28da236baba0fc85e151573eda5\", \"best_bid\":\"0.43\", \"best_ask\":\"0.44\"}, {\"asset_id\":\"20893381255801015515826997628594359667013752732428989472914000440642900266717\", \"price\":\"0.67\", \"size\":\"128\", \"side\":\"SELL\", \"hash\":\"825e2d83490a1484d829edfd0a5399f718337089\", \"best_bid\":\"0.56\", \"best_ask\":\"0.57\"}], \"timestamp\":\"1785204532957\", \"event_type\":\"price_change\"}","received_at":"2026-07-28T02:08:53.656806Z","schema_version":"clob-market-ws.price_change.v1","sequence":null,"server_hash":null,"server_timestamp":"1785204532957","session_id":"d2757dd6dad94f3b9fe67e8dbf1adc37","source":"clob_market_ws"},"received_at":"2026-07-28T02:08:53.656806Z","record_id":"bded3feb72c9a93de798680651ee1683bb53627910c2d163e91b0d3b47499d9a","schema_fingerprint":"4aa3821a28b0b7c2400bc59aba4bcc0a76e971dadd19610d3ad38c768e124dc7","schema_version":"edge-lab-recorder.raw.v1","sequence":null,"source":"clob_market_ws"}
{"event_at":"2026-07-28T02:08:52.962000Z","event_fingerprint":"72233267af392a697be4a022b1f8f6c374ced9b550417846cc6c43067504d77b","payload":{"connection_id":"5d29200f65794d4d9ab6ef271f045a9b","event_at":"2026-07-28T02:08:52.962000Z","event_type":"price_change","frame_hash":"211ab503b42512de3b9c7ed25af4b05b2da4386bbf07fe5b6f2f1f79b1de2772","frame_index":0,"kind":"data","monotonic_ns":306516668052083,"payload":{"event_type":"price_change","market":"0xda6f0e0e93fc8469e0159a166028d017bddbc162b86f66bac90391379603d962","price_changes":[{"asset_id":"20893381255801015515826997628594359667013752732428989472914000440642900266717","best_ask":"0.57","best_bid":"0.56","hash":"61c89231b0b4a45b5e6ee50a32d4a2c4eb2715ea","price":"0.47","side":"BUY","size":"266.06"},{"asset_id":"39272994714739463168905443499424551362424437245880253267329605556587274644733","best_ask":"0.44","best_bid":"0.43","hash":"64f5ec5792b97817a29a55a81eabe7320493a5d8","price":"0.53","side":"SELL","size":"266.06"}],"timestamp":"1785204532962"},"payload_hash":"72d8dc33a15eb43cdd60d1f36ec03aadb3aa6d23ea193c8f62a8b8560db70974","raw_frame":"{\"market\":\"0xda6f0e0e93fc8469e0159a166028d017bddbc162b86f66bac90391379603d962\", \"price_changes\":[{\"asset_id\":\"20893381255801015515826997628594359667013752732428989472914000440642900266717\", \"price\":\"0.47\", \"size\":\"266.06\", \"side\":\"BUY\", \"hash\":\"61c89231b0b4a45b5e6ee50a32d4a2c4eb2715ea\", \"best_bid\":\"0.56\", \"best_ask\":\"0.57\"}, {\"asset_id\":\"39272994714739463168905443499424551362424437245880253267329605556587274644733\", \"price\":\"0.53\", \"size\":\"266.06\", \"side\":\"SELL\", \"hash\":\"64f5ec5792b97817a29a55a81eabe7320493a5d8\", \"best_bid\":\"0.43\", \"best_ask\":\"0.44\"}], \"timestamp\":\"1785204532962\", \"event_type\":\"price_change\"}","received_at":"2026-07-28T02:08:53.659715Z","schema_version":"clob-market-ws.price_change.v1","sequence":null,"server_hash":null,"server_timestamp":"1785204532962","session_id":"d2757dd6dad94f3b9fe67e8dbf1adc37","source":"clob_market_ws"},"received_at":"2026-07-28T02:08:53.659715Z","record_id":"3f4c89927321d612f08be125b3e9dad15a0e794ac3b027c8557ddd71635d3543","schema_fingerprint":"4aa3821a28b0b7c2400bc59aba4bcc0a76e971dadd19610d3ad38c768e124dc7","schema_version":"edge-lab-recorder.raw.v1","sequence":null,"source":"clob_market_ws"}
{"event_at":"2026-07-28T02:08:52.965000Z","event_fingerprint":"a9e7c1ce2278186be9065bd33104f83815d64a6ecf4000762ee7864193f272ec","payload":{"connection_id":"5d29200f65794d4d9ab6ef271f045a9b","event_at":"2026-07-28T02:08:52.965000Z","event_type":"price_change","frame_hash":"f63c32f5f2b4e343c86fcdcdb4004fefc262e1eb18d06b50023c6c43dda77e75","frame_index":0,"kind":"data","monotonic_ns":306516670961833,"payload":{"event_type":"price_change","market":"0xda6f0e0e93fc8469e0159a166028d017bddbc162b86f66bac90391379603d962","price_changes":[{"asset_id":"20893381255801015515826997628594359667013752732428989472914000440642900266717","best_ask":"0.57","best_bid":"0.56","hash":"2bd69e3c2d85ee2f9d1d7c46debc1f7beaf45ca2","price":"0.01","side":"BUY","size":"5682.02"},{"asset_id":"39272994714739463168905443499424551362424437245880253267329605556587274644733","best_ask":"0.44","best_bid":"0.43","hash":"26d80789d4cdd86495b5a8bffefb8883b55e1374","price":"0.99","side":"SELL","size":"5682.02"}],"timestamp":"1785204532965"},"payload_hash":"6778a31da1f3ed10c2036b69d5b37e40d649eca28b8f9553a76adc6649882e63","raw_frame":"{\"market\":\"0xda6f0e0e93fc8469e0159a166028d017bddbc162b86f66bac90391379603d962\", \"price_changes\":[{\"asset_id\":\"20893381255801015515826997628594359667013752732428989472914000440642900266717\", \"price\":\"0.01\", \"size\":\"5682.02\", \"side\":\"BUY\", \"hash\":\"2bd69e3c2d85ee2f9d1d7c46debc1f7beaf45ca2\", \"best_bid\":\"0.56\", \"best_ask\":\"0.57\"}, {\"asset_id\":\"39272994714739463168905443499424551362424437245880253267329605556587274644733\", \"price\":\"0.99\", \"size\":\"5682.02\", \"side\":\"SELL\", \"hash\":\"26d80789d4cdd86495b5a8bffefb8883b55e1374\", \"best_bid\":\"0.43\", \"best_ask\":\"0.44\"}], \"timestamp\":\"1785204532965\", \"event_type\":\"price_change\"}","received_at":"2026-07-28T02:08:53.662624Z","schema_version":"clob-market-ws.price_change.v1","sequence":null,"server_hash":null,"server_timestamp":"1785204532965","session_id":"d2757dd6dad94f3b9fe67e8dbf1adc37","source":"clob_market_ws"},"received_at":"2026-07-28T02:08:53.662624Z","record_id":"c0fccbf018b0fd3263c637800c0f8d2ce2dc01825772842899433cf6156765d9","schema_fingerprint":"4aa3821a28b0b7c2400bc59aba4bcc0a76e971dadd19610d3ad38c768e124dc7","schema_version":"edge-lab-recorder.raw.v1","sequence":null,"source":"clob_market_ws"}
{"event_at":"2026-07-28T02:08:52.966000Z","event_fingerprint":"e0d349826bcc3c17b62cce3038467efebc4c8151c046379be0e0ec5018785646","payload":{"connection_id":"5d29200f65794d4d9ab6ef271f045a9b","event_at":"2026-07-28T02:08:52.966000Z","event_type":"price_change","frame_hash":"31048c60a2655ec346e1bc44577238b6b89dad71873dac1f2bf5dae92b91a9b3","frame_index":0,"kind":"data","monotonic_ns":306516673562375,"payload":{"event_type":"price_change","market":"0xda6f0e0e93fc8469e0159a166028d017bddbc162b86f66bac90391379603d962","price_changes":[{"asset_id":"20893381255801015515826997628594359667013752732428989472914000440642900266717","best_ask":"0.57","best_bid":"0.56","hash":"8b244b1ee581dff82457c4778f936825e69dc20e","price":"0.47","side":"BUY","size":"296.06"},{"asset_id":"39272994714739463168905443499424551362424437245880253267329605556587274644733","best_ask":"0.44","best_bid":"0.43","hash":"7f6958d71ccadd01392795ff208150ccffdc4a0b","price":"0.53","side":"SELL","size":"296.06"}],"timestamp":"1785204532966"},"payload_hash":"593ee9ae373657b6d8da99ae630a0ca02fa71f87ae1a8f2cd08e8f411ef881d8","raw_frame":"{\"market\":\"0xda6f0e0e93fc8469e0159a166028d017bddbc162b86f66bac90391379603d962\", \"price_changes\":[{\"asset_id\":\"20893381255801015515826997628594359667013752732428989472914000440642900266717\", \"price\":\"0.47\", \"size\":\"296.06\", \"side\":\"BUY\", \"hash\":\"8b244b1ee581dff82457c4778f936825e69dc20e\", \"best_bid\":\"0.56\", \"best_ask\":\"0.57\"}, {\"asset_id\":\"39272994714739463168905443499424551362424437245880253267329605556587274644733\", \"price\":\"0.53\", \"size\":\"296.06\", \"side\":\"SELL\", \"hash\":\"7f6958d71ccadd01392795ff208150ccffdc4a0b\", \"best_bid\":\"0.43\", \"best_ask\":\"0.44\"}], \"timestamp\":\"1785204532966\", \"event_type\":\"price_change\"}","received_at":"2026-07-28T02:08:53.665224Z","schema_version":"clob-market-ws.price_change.v1","sequence":null,"server_hash":null,"server_timestamp":"1785204532966","session_id":"d2757dd6dad94f3b9fe67e8dbf1adc37","source":"clob_market_ws"},"received_at":"2026-07-28T02:08:53.665224Z","record_id":"84d7794ee3e30bc6efa21f2f850bbf992227aa582ea997193788fc31c570012c","schema_fingerprint":"4aa3821a28b0b7c2400bc59aba4bcc0a76e971dadd19610d3ad38c768e124dc7","schema_version":"edge-lab-recorder.raw.v1","sequence":null,"source":"clob_market_ws"}
{"event_at":"2026-07-28T02:08:52.974000Z","event_fingerprint":"6313754ad0a68f8765d383c150b290b048a37c47576c3e06bbd20f52aba2ebd2","payload":{"connection_id":"5d29200f65794d4d9ab6ef271f045a9b","event_at":"2026-07-28T02:08:52.974000Z","event_type":"price_change","frame_hash":"c49bc70fc24e2814ef75f1e6eb2d79765be754b06bda2c16f75372c5d81a8367","frame_index":0,"kind":"data","monotonic_ns":306516675832666,"payload":{"event_type":"price_change","market":"0xda6f0e0e93fc8469e0159a166028d017bddbc162b86f66bac90391379603d962","price_changes":[{"asset_id":"20893381255801015515826997628594359667013752732428989472914000440642900266717","best_ask":"0.57","best_bid":"0.56","hash":"a171525d4cfcd599d01817786647e1534f5e30eb","price":"0.47","side":"BUY","size":"326.06"},{"asset_id":"39272994714739463168905443499424551362424437245880253267329605556587274644733","best_ask":"0.44","best_bid":"0.43","hash":"6d27a1080ff6387a7e082fe70bb33b7aeaa5106f","price":"0.53","side":"SELL","size":"326.06"}],"timestamp":"1785204532974"},"payload_hash":"4e85c0ddc62c03237944a93478ae8c0d0d1998e0881eeefb4b67c488014430a2","raw_frame":"{\"market\":\"0xda6f0e0e93fc8469e0159a166028d017bddbc162b86f66bac90391379603d962\", \"price_changes\":[{\"asset_id\":\"20893381255801015515826997628594359667013752732428989472914000440642900266717\", \"price\":\"0.47\", \"size\":\"326.06\", \"side\":\"BUY\", \"hash\":\"a171525d4cfcd599d01817786647e1534f5e30eb\", \"best_bid\":\"0.56\", \"best_ask\":\"0.57\"}, {\"asset_id\":\"39272994714739463168905443499424551362424437245880253267329605556587274644733\", \"price\":\"0.53\", \"size\":\"326.06\", \"side\":\"SELL\", \"hash\":\"6d27a1080ff6387a7e082fe70bb33b7aeaa5106f\", \"best_bid\":\"0.43\", \"best_ask\":\"0.44\"}], \"timestamp\":\"1785204532974\", \"event_type\":\"price_change\"}","received_at":"2026-07-28T02:08:53.667496Z","schema_version":"clob-market-ws.price_change.v1","sequence":null,"server_hash":null,"server_timestamp":"1785204532974","session_id":"d2757dd6dad94f3b9fe67e8dbf1adc37","source":"clob_market_ws"},"received_at":"2026-07-28T02:08:53.667496Z","record_id":"5e3dd95b1e857d722da7cfef67ad4e0173dcc2d1962ba1bd0992d9d627b720a5","schema_fingerprint":"4aa3821a28b0b7c2400bc59aba4bcc0a76e971dadd19610d3ad38c768e124dc7","schema_version":"edge-lab-recorder.raw.v1","sequence":null,"source":"clob_market_ws"}
{"event_at":"2026-07-28T02:08:53.010000Z","event_fingerprint":"be8af7c374fc0c41cf99e5809e7c283bac71d77d018f14c32c98f7f157a6d2e3","payload":{"connection_id":"5d29200f65794d4d9ab6ef271f045a9b","event_at":"2026-07-28T02:08:53.010000Z","event_type":"price_change","frame_hash":"ea94241e2a5cc81eb57d93678fe7a8631ee02af50de8275c74502ddbd504e37b","frame_index":0,"kind":"data","monotonic_ns":306516679628958,"payload":{"event_type":"price_change","market":"0xda6f0e0e93fc8469e0159a166028d017bddbc162b86f66bac90391379603d962","price_changes":[{"asset_id":"20893381255801015515826997628594359667013752732428989472914000440642900266717","best_ask":"0.57","best_bid":"0.56","hash":"f83585c499b952229efea0ec38b2e2e14055dea5","price":"0.32","side":"BUY","size":"169.01"},{"asset_id":"39272994714739463168905443499424551362424437245880253267329605556587274644733","best_ask":"0.44","best_bid":"0.43","hash":"0e49142d5d97b23e73187017a64877d211e554a2","price":"0.68","side":"SELL","size":"169.01"}],"timestamp":"1785204533010"},"payload_hash":"d1005497db73f8efff5a53f83da3855d8d22c779fb2a892bcc66ed2f3ecba144","raw_frame":"{\"market\":\"0xda6f0e0e93fc8469e0159a166028d017bddbc162b86f66bac90391379603d962\", \"price_changes\":[{\"asset_id\":\"20893381255801015515826997628594359667013752732428989472914000440642900266717\", \"price\":\"0.32\", \"size\":\"169.01\", \"side\":\"BUY\", \"hash\":\"f83585c499b952229efea0ec38b2e2e14055dea5\", \"best_bid\":\"0.56\", \"best_ask\":\"0.57\"}, {\"asset_id\":\"39272994714739463168905443499424551362424437245880253267329605556587274644733\", \"price\":\"0.68\", \"size\":\"169.01\", \"side\":\"SELL\", \"hash\":\"0e49142d5d97b23e73187017a64877d211e554a2\", \"best_bid\":\"0.43\", \"best_ask\":\"0.44\"}], \"timestamp\":\"1785204533010\", \"event_type\":\"price_change\"}","received_at":"2026-07-28T02:08:53.671291Z","schema_version":"clob-market-ws.price_change.v1","sequence":null,"server_hash":null,"server_timestamp":"1785204533010","session_id":"d2757dd6dad94f3b9fe67e8dbf1adc37","source":"clob_market_ws"},"received_at":"2026-07-28T02:08:53.671291Z","record_id":"45e6f545c66167e9cefafa6dbd4f1cff87cd23cd3b5ea4b6761bac36820b73be","schema_fingerprint":"4aa3821a28b0b7c2400bc59aba4bcc0a76e971dadd19610d3ad38c768e124dc7","schema_version":"edge-lab-recorder.raw.v1","sequence":null,"source":"clob_market_ws"}
{"event_at":"2026-07-28T02:08:53.015000Z","event_fingerprint":"365a976b45e9646fc70f5fc5da3ae95f41d9dc73d08ca71da1fbb5d2980ad4fc","payload":{"connection_id":"5d29200f65794d4d9ab6ef271f045a9b","event_at":"2026-07-28T02:08:53.015000Z","event_type":"price_change","frame_hash":"9587a7c5b8b9dd1a16f08942d60585ec6d4c24b20e815594a2b8ac4d23cab7b1","frame_index":0,"kind":"data","monotonic_ns":306516682582375,"payload":{"event_type":"price_change","market":"0xda6f0e0e93fc8469e0159a166028d017bddbc162b86f66bac90391379603d962","price_changes":[{"asset_id":"20893381255801015515826997628594359667013752732428989472914000440642900266717","best_ask":"0.57","best_bid":"0.56","hash":"dab5c60773ab97ff45d171bd866f4bf85a3179e3","price":"0.53","side":"BUY","size":"102"},{"asset_id":"39272994714739463168905443499424551362424437245880253267329605556587274644733","best_ask":"0.44","best_bid":"0.43","hash":"c8b231071fde7846613b25efb3c7cd5fcc60273a","price":"0.47","side":"SELL","size":"102"}],"timestamp":"1785204533015"},"payload_hash":"6f361208d62893dfed05a65c6c51ff590623f84b67e0e95f64068509b1492251","raw_frame":"{\"market\":\"0xda6f0e0e93fc8469e0159a166028d017bddbc162b86f66bac90391379603d962\", \"price_changes\":[{\"asset_id\":\"20893381255801015515826997628594359667013752732428989472914000440642900266717\", \"price\":\"0.53\", \"size\":\"102\", \"side\":\"BUY\", \"hash\":\"dab5c60773ab97ff45d171bd866f4bf85a3179e3\", \"best_bid\":\"0.56\", \"best_ask\":\"0.57\"}, {\"asset_id\":\"39272994714739463168905443499424551362424437245880253267329605556587274644733\", \"price\":\"0.47\", \"size\":\"102\", \"side\":\"SELL\", \"hash\":\"c8b231071fde7846613b25efb3c7cd5fcc60273a\", \"best_bid\":\"0.43\", \"best_ask\":\"0.44\"}], \"timestamp\":\"1785204533015\", \"event_type\":\"price_change\"}","received_at":"2026-07-28T02:08:53.674246Z","schema_version":"clob-market-ws.price_change.v1","sequence":null,"server_hash":null,"server_timestamp":"1785204533015","session_id":"d2757dd6dad94f3b9fe67e8dbf1adc37","source":"clob_market_ws"},"received_at":"2026-07-28T02:08:53.674246Z","record_id":"e2d1f3d82d328256d0ec7f4cf16b4c334a682066dad8e400efb929ce4717016e","schema_fingerprint":"4aa3821a28b0b7c2400bc59aba4bcc0a76e971dadd19610d3ad38c768e124dc7","schema_version":"edge-lab-recorder.raw.v1","sequence":null,"source":"clob_market_ws"}
{"event_at":"2026-07-28T02:08:53.018000Z","event_fingerprint":"5c3412fc393d37a6b2312945880145b060c254685a0ba059e11642d172be43b4","payload":{"connection_id":"5d29200f65794d4d9ab6ef271f045a9b","event_at":"2026-07-28T02:08:53.018000Z","event_type":"price_change","frame_hash":"24bede2d3d32d772ac3f101dbcca9273675703673c5546cf826a38bc80718df9","frame_index":0,"kind":"data","monotonic_ns":306516685511666,"payload":{"event_type":"price_change","market":"0xda6f0e0e93fc8469e0159a166028d017bddbc162b86f66bac90391379603d962","price_changes":[{"asset_id":"39272994714739463168905443499424551362424437245880253267329605556587274644733","best_ask":"0.44","best_bid":"0.43","hash":"b2310ffebfaf635bb653ba5b5fcb3a701e69d1c8","price":"0.47","side":"SELL","size":"110"},{"asset_id":"20893381255801015515826997628594359667013752732428989472914000440642900266717","best_ask":"0.57","best_bid":"0.56","hash":"cd2e6858df73e955d67c749f4a33982819ef6dc2","price":"0.53","side":"BUY","size":"110"}],"timestamp":"1785204533018"},"payload_hash":"ae6cf05e583912bf4f094818fb8c126fb84e89146ffcf9f6d719f79a68446c8b","raw_frame":"{\"market\":\"0xda6f0e0e93fc8469e0159a166028d017bddbc162b86f66bac90391379603d962\", \"price_changes\":[{\"asset_id\":\"39272994714739463168905443499424551362424437245880253267329605556587274644733\", \"price\":\"0.47\", \"size\":\"110\", \"side\":\"SELL\", \"hash\":\"b2310ffebfaf635bb653ba5b5fcb3a701e69d1c8\", \"best_bid\":\"0.43\", \"best_ask\":\"0.44\"}, {\"asset_id\":\"20893381255801015515826997628594359667013752732428989472914000440642900266717\", \"price\":\"0.53\", \"size\":\"110\", \"side\":\"BUY\", \"hash\":\"cd2e6858df73e955d67c749f4a33982819ef6dc2\", \"best_bid\":\"0.56\", \"best_ask\":\"0.57\"}], \"timestamp\":\"1785204533018\", \"event_type\":\"price_change\"}","received_at":"2026-07-28T02:08:53.677175Z","schema_version":"clob-market-ws.price_change.v1","sequence":null,"server_hash":null,"server_timestamp":"1785204533018","session_id":"d2757dd6dad94f3b9fe67e8dbf1adc37","source":"clob_market_ws"},"received_at":"2026-07-28T02:08:53.677175Z","record_id":"c36310cbb59e2f72c037bda95854beed0846efef292f28e58e37a33c2da6efb4","schema_fingerprint":"4aa3821a28b0b7c2400bc59aba4bcc0a76e971dadd19610d3ad38c768e124dc7","schema_version":"edge-lab-recorder.raw.v1","sequence":null,"source":"clob_market_ws"}
{"event_at":"2026-07-28T02:08:53.019000Z","event_fingerprint":"ee344d50ab8f40ee7bef340b2731312aa488c4fe8160731a7dc91c6c1b28e739","payload":{"connection_id":"5d29200f65794d4d9ab6ef271f045a9b","event_at":"2026-07-28T02:08:53.019000Z","event_type":"price_change","frame_hash":"34fb48d16268dbfc53d58179865e9962f2f013a299c7c367a3c287979b8d7904","frame_index":0,"kind":"data","monotonic_ns":306516688394291,"payload":{"event_type":"price_change","market":"0xda6f0e0e93fc8469e0159a166028d017bddbc162b86f66bac90391379603d962","price_changes":[{"asset_id":"39272994714739463168905443499424551362424437245880253267329605556587274644733","best_ask":"0.44","best_bid":"0.43","hash":"ebe488b9ed4c84ee03cfbe7a50f9ee31c4638d86","price":"0.01","side":"BUY","size":"5613.02"},{"asset_id":"20893381255801015515826997628594359667013752732428989472914000440642900266717","best_ask":"0.57","best_bid":"0.56","hash":"1543673d3ecd6152ca7504b7f1c9de6cb1fa62ed","price":"0.99","side":"SELL","size":"5613.02"}],"timestamp":"1785204533019"},"payload_hash":"4bf40ba4be48370625bb77af728dc75013cbf2a6be799456f620c1441b18bd8b","raw_frame":"{\"market\":\"0xda6f0e0e93fc8469e0159a166028d017bddbc162b86f66bac90391379603d962\", \"price_changes\":[{\"asset_id\":\"39272994714739463168905443499424551362424437245880253267329605556587274644733\", \"price\":\"0.01\", \"size\":\"5613.02\", \"side\":\"BUY\", \"hash\":\"ebe488b9ed4c84ee03cfbe7a50f9ee31c4638d86\", \"best_bid\":\"0.43\", \"best_ask\":\"0.44\"}, {\"asset_id\":\"20893381255801015515826997628594359667013752732428989472914000440642900266717\", \"price\":\"0.99\", \"size\":\"5613.02\", \"side\":\"SELL\", \"hash\":\"1543673d3ecd6152ca7504b7f1c9de6cb1fa62ed\", \"best_bid\":\"0.56\", \"best_ask\":\"0.57\"}], \"timestamp\":\"1785204533019\", \"event_type\":\"price_change\"}","received_at":"2026-07-28T02:08:53.680057Z","schema_version":"clob-market-ws.price_change.v1","sequence":null,"server_hash":null,"server_timestamp":"1785204533019","session_id":"d2757dd6dad94f3b9fe67e8dbf1adc37","source":"clob_market_ws"},"received_at":"2026-07-28T02:08:53.680057Z","record_id":"d490327fee5ae9a76f8666760d87f1aebc9ae662ad0824db46f017041b0b1545","schema_fingerprint":"4aa3821a28b0b7c2400bc59aba4bcc0a76e971dadd19610d3ad38c768e124dc7","schema_version":"edge-lab-recorder.raw.v1","sequence":null,"source":"clob_market_ws"}
{"event_at":"2026-07-28T02:08:53.023000Z","event_fingerprint":"d72fe9cf1ffbde67fc9f5b2ebc82e3977d7fb0245cba1a18ad598502b407f8ee","payload":{"connection_id":"5d29200f65794d4d9ab6ef271f045a9b","event_at":"2026-07-28T02:08:53.023000Z","event_type":"price_change","frame_hash":"947a213c8091d3be8507e8a9bac8b325d306241f7a9a1e124a8e70e5e19b650a","frame_index":0,"kind":"data","monotonic_ns":306516691361250,"payload":{"event_type":"price_change","market":"0xda6f0e0e93fc8469e0159a166028d017bddbc162b86f66bac90391379603d962","price_changes":[{"asset_id":"39272994714739463168905443499424551362424437245880253267329605556587274644733","best_ask":"0.44","best_bid":"0.43","hash":"5e56730baa284be4b140b2e46771d7699cce0a42","price":"0.22","side":"BUY","size":"220.01"},{"asset_id":"20893381255801015515826997628594359667013752732428989472914000440642900266717","best_ask":"0.57","best_bid":"0.56","hash":"ec3f62c6db2a94cbd1b8415ea6651b50e8081cbb","price":"0.78","side":"SELL","size":"220.01"}],"timestamp":"1785204533023"},"payload_hash":"3f616f22b64383df0942374798a02ff58739b22ba1084d98e6785199478e8aa5","raw_frame":"{\"market\":\"0xda6f0e0e93fc8469e0159a166028d017bddbc162b86f66bac90391379603d962\", \"price_changes\":[{\"asset_id\":\"39272994714739463168905443499424551362424437245880253267329605556587274644733\", \"price\":\"0.22\", \"size\":\"220.01\", \"side\":\"BUY\", \"hash\":\"5e56730baa284be4b140b2e46771d7699cce0a42\", \"best_bid\":\"0.43\", \"best_ask\":\"0.44\"}, {\"asset_id\":\"20893381255801015515826997628594359667013752732428989472914000440642900266717\", \"price\":\"0.78\", \"size\":\"220.01\", \"side\":\"SELL\", \"hash\":\"ec3f62c6db2a94cbd1b8415ea6651b50e8081cbb\", \"best_bid\":\"0.56\", \"best_ask\":\"0.57\"}], \"timestamp\":\"1785204533023\", \"event_type\":\"price_change\"}","received_at":"2026-07-28T02:08:53.683024Z","schema_version":"clob-market-ws.price_change.v1","sequence":null,"server_hash":null,"server_timestamp":"1785204533023","session_id":"d2757dd6dad94f3b9fe67e8dbf1adc37","source":"clob_market_ws"},"received_at":"2026-07-28T02:08:53.683024Z","record_id":"402834d71a741346da89b5a461035273d22516bfd256d33191cf83ced9c44775","schema_fingerprint":"4aa3821a28b0b7c2400bc59aba4bcc0a76e971dadd19610d3ad38c768e124dc7","schema_version":"edge-lab-recorder.raw.v1","sequence":null,"source":"clob_market_ws"}
{"event_at":"2026-07-28T02:08:53.029000Z","event_fingerprint":"2ffaf81946fe900e8e0fc925e0d3f069352d4c5b64d373d006d262601d0d88ca","payload":{"connection_id":"5d29200f65794d4d9ab6ef271f045a9b","event_at":"2026-07-28T02:08:53.029000Z","event_type":"price_change","frame_hash":"41f903e2f83140c6f024269fa8de6056689dc4df7ebff1e66df019d31ee19d3d","frame_index":0,"kind":"data","monotonic_ns":306516694320458,"payload":{"event_type":"price_change","market":"0xda6f0e0e93fc8469e0159a166028d017bddbc162b86f66bac90391379603d962","price_changes":[{"asset_id":"39272994714739463168905443499424551362424437245880253267329605556587274644733","best_ask":"0.44","best_bid":"0.43","hash":"b837193096e9c1e90ba2d1e9d1b3bfd1b04527cb","price":"0.01","side":"BUY","size":"5618.02"},{"asset_id":"20893381255801015515826997628594359667013752732428989472914000440642900266717","best_ask":"0.57","best_bid":"0.56","hash":"3ee4e45a2903d99b6589d052fba663d0ea0c6a45","price":"0.99","side":"SELL","size":"5618.02"}],"timestamp":"1785204533029"},"payload_hash":"ff906974a3a0112bd28c68ff6a04f48b799b0d350b2c759ff07552a82a37106a","raw_frame":"{\"market\":\"0xda6f0e0e93fc8469e0159a166028d017bddbc162b86f66bac90391379603d962\", \"price_changes\":[{\"asset_id\":\"39272994714739463168905443499424551362424437245880253267329605556587274644733\", \"price\":\"0.01\", \"size\":\"5618.02\", \"side\":\"BUY\", \"hash\":\"b837193096e9c1e90ba2d1e9d1b3bfd1b04527cb\", \"best_bid\":\"0.43\", \"best_ask\":\"0.44\"}, {\"asset_id\":\"20893381255801015515826997628594359667013752732428989472914000440642900266717\", \"price\":\"0.99\", \"size\":\"5618.02\", \"side\":\"SELL\", \"hash\":\"3ee4e45a2903d99b6589d052fba663d0ea0c6a45\", \"best_bid\":\"0.56\", \"best_ask\":\"0.57\"}], \"timestamp\":\"1785204533029\", \"event_type\":\"price_change\"}","received_at":"2026-07-28T02:08:53.685983Z","schema_version":"clob-market-ws.price_change.v1","sequence":null,"server_hash":null,"server_timestamp":"1785204533029","session_id":"d2757dd6dad94f3b9fe67e8dbf1adc37","source":"clob_market_ws"},"received_at":"2026-07-28T02:08:53.685983Z","record_id":"e60a5bac0bc197200647c7094606aad8047b93a91b01f99ee636d121fb67d318","schema_fingerprint":"4aa3821a28b0b7c2400bc59aba4bcc0a76e971dadd19610d3ad38c768e124dc7","schema_version":"edge-lab-recorder.raw.v1","sequence":null,"source":"clob_market_ws"}
{"event_at":"2026-07-28T02:08:53.036000Z","event_fingerprint":"a5771316f005059484f92005413bfaec49620bc4581cde6e96a922ffabcbda68","payload":{"connection_id":"5d29200f65794d4d9ab6ef271f045a9b","event_at":"2026-07-28T02:08:53.036000Z","event_type":"price_change","frame_hash":"e3fbba4ed9e2ceb1008d808b4eaeabee148ace53df6e20a540b2622a683b7dba","frame_index":0,"kind":"data","monotonic_ns":306516697441083,"payload":{"event_type":"price_change","market":"0xda6f0e0e93fc8469e0159a166028d017bddbc162b86f66bac90391379603d962","price_changes":[{"asset_id":"20893381255801015515826997628594359667013752732428989472914000440642900266717","best_ask":"0.57","best_bid":"0.56","hash":"7edcdb5c41495948979586ef4970b60dac107b0f","price":"0.02","side":"BUY","size":"737.1"},{"asset_id":"39272994714739463168905443499424551362424437245880253267329605556587274644733","best_ask":"0.44","best_bid":"0.43","hash":"fba7033b8aabcfac2860b0fecbf4962413932ee9","price":"0.98","side":"SELL","size":"737.1"}],"timestamp":"1785204533036"},"payload_hash":"bc19fdae4bf1a7a0e6c8f80c435638788308b7fd8ac0893c64823b5a4a8bb16a","raw_frame":"{\"market\":\"0xda6f0e0e93fc8469e0159a166028d017bddbc162b86f66bac90391379603d962\", \"price_changes\":[{\"asset_id\":\"20893381255801015515826997628594359667013752732428989472914000440642900266717\", \"price\":\"0.02\", \"size\":\"737.1\", \"side\":\"BUY\", \"hash\":\"7edcdb5c41495948979586ef4970b60dac107b0f\", \"best_bid\":\"0.56\", \"best_ask\":\"0.57\"}, {\"asset_id\":\"39272994714739463168905443499424551362424437245880253267329605556587274644733\", \"price\":\"0.98\", \"size\":\"737.1\", \"side\":\"SELL\", \"hash\":\"fba7033b8aabcfac2860b0fecbf4962413932ee9\", \"best_bid\":\"0.43\", \"best_ask\":\"0.44\"}], \"timestamp\":\"1785204533036\", \"event_type\":\"price_change\"}","received_at":"2026-07-28T02:08:53.689101Z","schema_version":"clob-market-ws.price_change.v1","sequence":null,"server_hash":null,"server_timestamp":"1785204533036","session_id":"d2757dd6dad94f3b9fe67e8dbf1adc37","source":"clob_market_ws"},"received_at":"2026-07-28T02:08:53.689101Z","record_id":"1ebdb4224da1a7128f4611759e73ed069cf8c5111dc1ab071fe0743bfbb7cda5","schema_fingerprint":"4aa3821a28b0b7c2400bc59aba4bcc0a76e971dadd19610d3ad38c768e124dc7","schema_version":"edge-lab-recorder.raw.v1","sequence":null,"source":"clob_market_ws"}
{"event_at":"2026-07-28T02:08:53.038000Z","event_fingerprint":"59f706a21b36c502c5c838b83acbc59b6af019ea36493e8c34f118f55516cdc6","payload":{"connection_id":"5d29200f65794d4d9ab6ef271f045a9b","event_at":"2026-07-28T02:08:53.038000Z","event_type":"price_change","frame_hash":"1616124b14519ccded62a0d17f54c588380994318c66cbd8eb909a0d4a4ccb9b","frame_index":0,"kind":"data","monotonic_ns":306516700708458,"payload":{"event_type":"price_change","market":"0xda6f0e0e93fc8469e0159a166028d017bddbc162b86f66bac90391379603d962","price_changes":[{"asset_id":"20893381255801015515826997628594359667013752732428989472914000440642900266717","best_ask":"0.57","best_bid":"0.56","hash":"f37dab327e6918168c3e373058f82099c6a2485d","price":"0.35","side":"BUY","size":"82.2"},{"asset_id":"39272994714739463168905443499424551362424437245880253267329605556587274644733","best_ask":"0.44","best_bid":"0.43","hash":"ecec4de679b7d2f5bc0c7e6162846757bd80d208","price":"0.65","side":"SELL","size":"82.2"}],"timestamp":"1785204533038"},"payload_hash":"58d9c3634b2c8ffc47d8f97934dec284b412bbd5d0e745e8947540a7e9d79495","raw_frame":"{\"market\":\"0xda6f0e0e93fc8469e0159a166028d017bddbc162b86f66bac90391379603d962\", \"price_changes\":[{\"asset_id\":\"20893381255801015515826997628594359667013752732428989472914000440642900266717\", \"price\":\"0.35\", \"size\":\"82.2\", \"side\":\"BUY\", \"hash\":\"f37dab327e6918168c3e373058f82099c6a2485d\", \"best_bid\":\"0.56\", \"best_ask\":\"0.57\"}, {\"asset_id\":\"39272994714739463168905443499424551362424437245880253267329605556587274644733\", \"price\":\"0.65\", \"size\":\"82.2\", \"side\":\"SELL\", \"hash\":\"ecec4de679b7d2f5bc0c7e6162846757bd80d208\", \"best_bid\":\"0.43\", \"best_ask\":\"0.44\"}], \"timestamp\":\"1785204533038\", \"event_type\":\"price_change\"}","received_at":"2026-07-28T02:08:53.692371Z","schema_version":"clob-market-ws.price_change.v1","sequence":null,"server_hash":null,"server_timestamp":"1785204533038","session_id":"d2757dd6dad94f3b9fe67e8dbf1adc37","source":"clob_market_ws"},"received_at":"2026-07-28T02:08:53.692371Z","record_id":"f9a68dd6e874b4340e782d6439b7cbf3e9f04bcde97fd9922da41c4175fc2632","schema_fingerprint":"4aa3821a28b0b7c2400bc59aba4bcc0a76e971dadd19610d3ad38c768e124dc7","schema_version":"edge-lab-recorder.raw.v1","sequence":null,"source":"clob_market_ws"}
{"event_at":"2026-07-28T02:08:53.051000Z","event_fingerprint":"5fd1bf90a3524abab68bad337d9899c71175c6ab3b469c5e68aa41e83fe7cde6","payload":{"connection_id":"5d29200f65794d4d9ab6ef271f045a9b","event_at":"2026-07-28T02:08:53.051000Z","event_type":"price_change","frame_hash":"f37a7dfcb24fb055ffaab231867094c9aadf1e3a7da3308bcfc43d67406c31df","frame_index":0,"kind":"data","monotonic_ns":306516703397666,"payload":{"event_type":"price_change","market":"0xda6f0e0e93fc8469e0159a166028d017bddbc162b86f66bac90391379603d962","price_changes":[{"asset_id":"39272994714739463168905443499424551362424437245880253267329605556587274644733","best_ask":"0.44","best_bid":"0.43","hash":"17c2178a86f34e2fddeb7c0c6744efad4cc23e60","price":"0.33","side":"BUY","size":"88"},{"asset_id":"20893381255801015515826997628594359667013752732428989472914000440642900266717","best_ask":"0.57","best_bid":"0.56","hash":"48d4466951428d4574fe328d1d8eb033bcd1cd78","price":"0.67","side":"SELL","size":"88"}],"timestamp":"1785204533051"},"payload_hash":"c5e7a753597dbfb43d9e6d3129e141ee0b27676959a283519573d0182432fb2e","raw_frame":"{\"market\":\"0xda6f0e0e93fc8469e0159a166028d017bddbc162b86f66bac90391379603d962\", \"price_changes\":[{\"asset_id\":\"39272994714739463168905443499424551362424437245880253267329605556587274644733\", \"price\":\"0.33\", \"size\":\"88\", \"side\":\"BUY\", \"hash\":\"17c2178a86f34e2fddeb7c0c6744efad4cc23e60\", \"best_bid\":\"0.43\", \"best_ask\":\"0.44\"}, {\"asset_id\":\"20893381255801015515826997628594359667013752732428989472914000440642900266717\", \"price\":\"0.67\", \"size\":\"88\", \"side\":\"SELL\", \"hash\":\"48d4466951428d4574fe328d1d8eb033bcd1cd78\", \"best_bid\":\"0.56\", \"best_ask\":\"0.57\"}], \"timestamp\":\"1785204533051\", \"event_type\":\"price_change\"}","received_at":"2026-07-28T02:08:53.695060Z","schema_version":"clob-market-ws.price_change.v1","sequence":null,"server_hash":null,"server_timestamp":"1785204533051","session_id":"d2757dd6dad94f3b9fe67e8dbf1adc37","source":"clob_market_ws"},"received_at":"2026-07-28T02:08:53.695060Z","record_id":"87f0689a02a2a9569548911818039a719f4a3e7d771af163d8bf92c1ee131318","schema_fingerprint":"4aa3821a28b0b7c2400bc59aba4bcc0a76e971dadd19610d3ad38c768e124dc7","schema_version":"edge-lab-recorder.raw.v1","sequence":null,"source":"clob_market_ws"}
{"event_at":"2026-07-28T02:08:53.059000Z","event_fingerprint":"91d27711d8685c70188014f28badef0ec5184c89211583ca7d7b569f31d5581c","payload":{"connection_id":"5d29200f65794d4d9ab6ef271f045a9b","event_at":"2026-07-28T02:08:53.059000Z","event_type":"price_change","frame_hash":"a27e3a0b890bcad33231309e92a140b34c57ace4da637c88e08f7242c755683f","frame_index":0,"kind":"data","monotonic_ns":306516708682833,"payload":{"event_type":"price_change","market":"0xda6f0e0e93fc8469e0159a166028d017bddbc162b86f66bac90391379603d962","price_changes":[{"asset_id":"20893381255801015515826997628594359667013752732428989472914000440642900266717","best_ask":"0.57","best_bid":"0.56","hash":"14a0e5da4e2f99c716cf2ec85bc6d91737724044","price":"0.43","side":"BUY","size":"242.2"},{"asset_id":"39272994714739463168905443499424551362424437245880253267329605556587274644733","best_ask":"0.44","best_bid":"0.43","hash":"576c79a5a200d30fca5b1fc466414c1caa28e0eb","price":"0.57","side":"SELL","size":"242.2"}],"timestamp":"1785204533059"},"payload_hash":"4ea42608b786781c2415f0c2541220ee17fa99433639b726df219c5075a95acc","raw_frame":"{\"market\":\"0xda6f0e0e93fc8469e0159a166028d017bddbc162b86f66bac90391379603d962\", \"price_changes\":[{\"asset_id\":\"20893381255801015515826997628594359667013752732428989472914000440642900266717\", \"price\":\"0.43\", \"size\":\"242.2\", \"side\":\"BUY\", \"hash\":\"14a0e5da4e2f99c716cf2ec85bc6d91737724044\", \"best_bid\":\"0.56\", \"best_ask\":\"0.57\"}, {\"asset_id\":\"39272994714739463168905443499424551362424437245880253267329605556587274644733\", \"price\":\"0.57\", \"size\":\"242.2\", \"side\":\"SELL\", \"hash\":\"576c79a5a200d30fca5b1fc466414c1caa28e0eb\", \"best_bid\":\"0.43\", \"best_ask\":\"0.44\"}], \"timestamp\":\"1785204533059\", \"event_type\":\"price_change\"}","received_at":"2026-07-28T02:08:53.700345Z","schema_version":"clob-market-ws.price_change.v1","sequence":null,"server_hash":null,"server_timestamp":"1785204533059","session_id":"d2757dd6dad94f3b9fe67e8dbf1adc37","source":"clob_market_ws"},"received_at":"2026-07-28T02:08:53.700345Z","record_id":"2c2ff141f325c05470512c297046cc3b73c13294894e01093c1e05d3f0b9e06b","schema_fingerprint":"4aa3821a28b0b7c2400bc59aba4bcc0a76e971dadd19610d3ad38c768e124dc7","schema_version":"edge-lab-recorder.raw.v1","sequence":null,"source":"clob_market_ws"}
{"event_at":"2026-07-28T02:08:53.060000Z","event_fingerprint":"f7b08989a5e7fe4ec910bda12e7f02bc2bd07aec4c43a0ecc125fd51c7479b49","payload":{"connection_id":"5d29200f65794d4d9ab6ef271f045a9b","event_at":"2026-07-28T02:08:53.060000Z","event_type":"price_change","frame_hash":"a795ae5ada809043c6e0bffb96a21c0f20899f053d8590b0e0817e1bdc5f8e49","frame_index":0,"kind":"data","monotonic_ns":306516717904791,"payload":{"event_type":"price_change","market":"0xda6f0e0e93fc8469e0159a166028d017bddbc162b86f66bac90391379603d962","price_changes":[{"asset_id":"39272994714739463168905443499424551362424437245880253267329605556587274644733","best_ask":"0.44","best_bid":"0.43","hash":"84509b11a9f3ae0e96525d1b391982fb65c3757c","price":"0.01","side":"BUY","size":"5613.02"},{"asset_id":"20893381255801015515826997628594359667013752732428989472914000440642900266717","best_ask":"0.57","best_bid":"0.56","hash":"62aba33033bdebf6c270c935334f061092b9dfaa","price":"0.99","side":"SELL","size":"5613.02"}],"timestamp":"1785204533060"},"payload_hash":"18d63a9fa62c1acbc6f62a9fcb5e8b82cc139e7cefde599bbbc99e5af0bfd1f8","raw_frame":"{\"market\":\"0xda6f0e0e93fc8469e0159a166028d017bddbc162b86f66bac90391379603d962\", \"price_changes\":[{\"asset_id\":\"39272994714739463168905443499424551362424437245880253267329605556587274644733\", \"price\":\"0.01\", \"size\":\"5613.02\", \"side\":\"BUY\", \"hash\":\"84509b11a9f3ae0e96525d1b391982fb65c3757c\", \"best_bid\":\"0.43\", \"best_ask\":\"0.44\"}, {\"asset_id\":\"20893381255801015515826997628594359667013752732428989472914000440642900266717\", \"price\":\"0.99\", \"size\":\"5613.02\", \"side\":\"SELL\", \"hash\":\"62aba33033bdebf6c270c935334f061092b9dfaa\", \"best_bid\":\"0.56\", \"best_ask\":\"0.57\"}], \"timestamp\":\"1785204533060\", \"event_type\":\"price_change\"}","received_at":"2026-07-28T02:08:53.709567Z","schema_version":"clob-market-ws.price_change.v1","sequence":null,"server_hash":null,"server_timestamp":"1785204533060","session_id":"d2757dd6dad94f3b9fe67e8dbf1adc37","source":"clob_market_ws"},"received_at":"2026-07-28T02:08:53.709567Z","record_id":"e0b09038998eb2410d082d85df50e234ef0d53d924f52aacb93ce7face3239e2","schema_fingerprint":"4aa3821a28b0b7c2400bc59aba4bcc0a76e971dadd19610d3ad38c768e124dc7","schema_version":"edge-lab-recorder.raw.v1","sequence":null,"source":"clob_market_ws"}
{"event_at":"2026-07-28T02:08:53.066000Z","event_fingerprint":"3d18a1711a0212f57fa083a12ca0f45af3c5edff9d853924f7a8b1d72c3e178e","payload":{"connection_id":"5d29200f65794d4d9ab6ef271f045a9b","event_at":"2026-07-28T02:08:53.066000Z","event_type":"price_change","frame_hash":"37350d793d9426c9154f56e2242b892370da5d53ef8f1bcd29e1c9b9fc38738a","frame_index":0,"kind":"data","monotonic_ns":306516729575250,"payload":{"event_type":"price_change","market":"0xda6f0e0e93fc8469e0159a166028d017bddbc162b86f66bac90391379603d962","price_changes":[{"asset_id":"20893381255801015515826997628594359667013752732428989472914000440642900266717","best_ask":"0.57","best_bid":"0.56","hash":"94b0b51f433535f1979de46688c519df3d322d91","price":"0.55","side":"BUY","size":"51"},{"asset_id":"39272994714739463168905443499424551362424437245880253267329605556587274644733","best_ask":"0.44","best_bid":"0.43","hash":"79020a3d395c8c1d0a8840f519d8093d7cfd24f0","price":"0.45","side":"SELL","size":"51"}],"timestamp":"1785204533066"},"payload_hash":"a456362b84f7c364eebc4d5000a9e5d8cd7aeefe19a324fd1f23e1d58db3fd5d","raw_frame":"{\"market\":\"0xda6f0e0e93fc8469e0159a166028d017bddbc162b86f66bac90391379603d962\", \"price_changes\":[{\"asset_id\":\"20893381255801015515826997628594359667013752732428989472914000440642900266717\", \"price\":\"0.55\", \"size\":\"51\", \"side\":\"BUY\", \"hash\":\"94b0b51f433535f1979de46688c519df3d322d91\", \"best_bid\":\"0.56\", \"best_ask\":\"0.57\"}, {\"asset_id\":\"39272994714739463168905443499424551362424437245880253267329605556587274644733\", \"price\":\"0.45\", \"size\":\"51\", \"side\":\"SELL\", \"hash\":\"79020a3d395c8c1d0a8840f519d8093d7cfd24f0\", \"best_bid\":\"0.43\", \"best_ask\":\"0.44\"}], \"timestamp\":\"1785204533066\", \"event_type\":\"price_change\"}","received_at":"2026-07-28T02:08:53.721238Z","schema_version":"clob-market-ws.price_change.v1","sequence":null,"server_hash":null,"server_timestamp":"1785204533066","session_id":"d2757dd6dad94f3b9fe67e8dbf1adc37","source":"clob_market_ws"},"received_at":"2026-07-28T02:08:53.721238Z","record_id":"c9401879481c19d9996ffb7b1e5887010fc0db40e137fa78e7b170ea97cb7edf","schema_fingerprint":"4aa3821a28b0b7c2400bc59aba4bcc0a76e971dadd19610d3ad38c768e124dc7","schema_version":"edge-lab-recorder.raw.v1","sequence":null,"source":"clob_market_ws"}
{"event_at":"2026-07-28T02:08:53.075000Z","event_fingerprint":"4dbd7da29efe6fd3db52b9a8ddb2c81de7fcd9af5d6dafef9f3f00e4128349a2","payload":{"connection_id":"5d29200f65794d4d9ab6ef271f045a9b","event_at":"2026-07-28T02:08:53.075000Z","event_type":"price_change","frame_hash":"4d4bf4df71c15a87f8551f963b323cce7409a9af1c3d93814c1e3d69e37a9a98","frame_index":0,"kind":"data","monotonic_ns":306516733413583,"payload":{"event_type":"price_change","market":"0xda6f0e0e93fc8469e0159a166028d017bddbc162b86f66bac90391379603d962","price_changes":[{"asset_id":"39272994714739463168905443499424551362424437245880253267329605556587274644733","best_ask":"0.44","best_bid":"0.43","hash":"a3f226d38c3915920454c86b939238755ffcf05b","price":"0.01","side":"BUY","size":"5608.02"},{"asset_id":"20893381255801015515826997628594359667013752732428989472914000440642900266717","best_ask":"0.57","best_bid":"0.56","hash":"3d684bdd89a9a3c6fb0bddb3b6e4e3080496d061","price":"0.99","side":"SELL","size":"5608.02"}],"timestamp":"1785204533075"},"payload_hash":"70776eb44f4ba4e499a992cd9a8fe8bdf26145e25dae406c8831276e5b39e9e5","raw_frame":"{\"market\":\"0xda6f0e0e93fc8469e0159a166028d017bddbc162b86f66bac90391379603d962\", \"price_changes\":[{\"asset_id\":\"39272994714739463168905443499424551362424437245880253267329605556587274644733\", \"price\":\"0.01\", \"size\":\"5608.02\", \"side\":\"BUY\", \"hash\":\"a3f226d38c3915920454c86b939238755ffcf05b\", \"best_bid\":\"0.43\", \"best_ask\":\"0.44\"}, {\"asset_id\":\"20893381255801015515826997628594359667013752732428989472914000440642900266717\", \"price\":\"0.99\", \"size\":\"5608.02\", \"side\":\"SELL\", \"hash\":\"3d684bdd89a9a3c6fb0bddb3b6e4e3080496d061\", \"best_bid\":\"0.56\", \"best_ask\":\"0.57\"}], \"timestamp\":\"1785204533075\", \"event_type\":\"price_change\"}","received_at":"2026-07-28T02:08:53.725075Z","schema_version":"clob-market-ws.price_change.v1","sequence":null,"server_hash":null,"server_timestamp":"1785204533075","session_id":"d2757dd6dad94f3b9fe67e8dbf1adc37","source":"clob_market_ws"},"received_at":"2026-07-28T02:08:53.725075Z","record_id":"5c7f7132705cf8b446d9bbf8a47f94fed0fb77211cef5b66623c068175c5b4f5","schema_fingerprint":"4aa3821a28b0b7c2400bc59aba4bcc0a76e971dadd19610d3ad38c768e124dc7","schema_version":"edge-lab-recorder.raw.v1","sequence":null,"source":"clob_market_ws"}
{"event_at":"2026-07-28T02:08:53.109000Z","event_fingerprint":"d31216d70dcbeb87bfa3965e8f3bd58c775d4189e73bf5613779be04452b6b41","payload":{"connection_id":"5d29200f65794d4d9ab6ef271f045a9b","event_at":"2026-07-28T02:08:53.109000Z","event_type":"price_change","frame_hash":"3ce402b7423325d8b546a0a3c012e82c3e35a7bbd05e70e6c2f0936741cc1d7c","frame_index":0,"kind":"data","monotonic_ns":306516736469750,"payload":{"event_type":"price_change","market":"0xda6f0e0e93fc8469e0159a166028d017bddbc162b86f66bac90391379603d962","price_changes":[{"asset_id":"20893381255801015515826997628594359667013752732428989472914000440642900266717","best_ask":"0.57","best_bid":"0.56","hash":"9e3eaac92f128f4dad6a4460f68f8ac85db2bb35","price":"0.02","side":"BUY","size":"732.1"},{"asset_id":"39272994714739463168905443499424551362424437245880253267329605556587274644733","best_ask":"0.44","best_bid":"0.43","hash":"92952e46212de109eeea4d0e975eb1d04379864b","price":"0.98","side":"SELL","size":"732.1"}],"timestamp":"1785204533109"},"payload_hash":"9d687ff03d0f7c5e06262b76cd543098440b505da349ad07188150948079132c","raw_frame":"{\"market\":\"0xda6f0e0e93fc8469e0159a166028d017bddbc162b86f66bac90391379603d962\", \"price_changes\":[{\"asset_id\":\"20893381255801015515826997628594359667013752732428989472914000440642900266717\", \"price\":\"0.02\", \"size\":\"732.1\", \"side\":\"BUY\", \"hash\":\"9e3eaac92f128f4dad6a4460f68f8ac85db2bb35\", \"best_bid\":\"0.56\", \"best_ask\":\"0.57\"}, {\"asset_id\":\"39272994714739463168905443499424551362424437245880253267329605556587274644733\", \"price\":\"0.98\", \"size\":\"732.1\", \"side\":\"SELL\", \"hash\":\"92952e46212de109eeea4d0e975eb1d04379864b\", \"best_bid\":\"0.43\", \"best_ask\":\"0.44\"}], \"timestamp\":\"1785204533109\", \"event_type\":\"price_change\"}","received_at":"2026-07-28T02:08:53.728132Z","schema_version":"clob-market-ws.price_change.v1","sequence":null,"server_hash":null,"server_timestamp":"1785204533109","session_id":"d2757dd6dad94f3b9fe67e8dbf1adc37","source":"clob_market_ws"},"received_at":"2026-07-28T02:08:53.728132Z","record_id":"804e98aa8a1ff63dc1948f6734556c5025ea8b6b9bbeb9b75176878e2ec5ef60","schema_fingerprint":"4aa3821a28b0b7c2400bc59aba4bcc0a76e971dadd19610d3ad38c768e124dc7","schema_version":"edge-lab-recorder.raw.v1","sequence":null,"source":"clob_market_ws"}
{"event_at":"2026-07-28T02:08:53.110000Z","event_fingerprint":"a6a5cd4a5b4df299a2256f2aa08d3cda616ee6babb1f6d3676e97a4dd5dcfcef","payload":{"connection_id":"5d29200f65794d4d9ab6ef271f045a9b","event_at":"2026-07-28T02:08:53.110000Z","event_type":"price_change","frame_hash":"174b6b1e854bddcfb76f055c1ab6840fc540fe2a28dc4212762e9d7457dec908","frame_index":0,"kind":"data","monotonic_ns":306516740363083,"payload":{"event_type":"price_change","market":"0xda6f0e0e93fc8469e0159a166028d017bddbc162b86f66bac90391379603d962","price_changes":[{"asset_id":"20893381255801015515826997628594359667013752732428989472914000440642900266717","best_ask":"0.57","best_bid":"0.56","hash":"222c2a349bd49bf267f3456a7229e4108deb89b9","price":"0.53","side":"BUY","size":"135"},{"asset_id":"39272994714739463168905443499424551362424437245880253267329605556587274644733","best_ask":"0.44","best_bid":"0.43","hash":"2fd289cf017329eaa6e952bda26120ba9510253d","price":"0.47","side":"SELL","size":"135"}],"timestamp":"1785204533110"},"payload_hash":"32c95008f215d23954f89cb00210343c3fa57a445acd48b245ecad9a2fe11a33","raw_frame":"{\"market\":\"0xda6f0e0e93fc8469e0159a166028d017bddbc162b86f66bac90391379603d962\", \"price_changes\":[{\"asset_id\":\"20893381255801015515826997628594359667013752732428989472914000440642900266717\", \"price\":\"0.53\", \"size\":\"135\", \"side\":\"BUY\", \"hash\":\"222c2a349bd49bf267f3456a7229e4108deb89b9\", \"best_bid\":\"0.56\", \"best_ask\":\"0.57\"}, {\"asset_id\":\"39272994714739463168905443499424551362424437245880253267329605556587274644733\", \"price\":\"0.47\", \"size\":\"135\", \"side\":\"SELL\", \"hash\":\"2fd289cf017329eaa6e952bda26120ba9510253d\", \"best_bid\":\"0.43\", \"best_ask\":\"0.44\"}], \"timestamp\":\"1785204533110\", \"event_type\":\"price_change\"}","received_at":"2026-07-28T02:08:53.732025Z","schema_version":"clob-market-ws.price_change.v1","sequence":null,"server_hash":null,"server_timestamp":"1785204533110","session_id":"d2757dd6dad94f3b9fe67e8dbf1adc37","source":"clob_market_ws"},"received_at":"2026-07-28T02:08:53.732025Z","record_id":"ea94b353563f57fb81f8074de04b65a05659462fcc2966d8f2224309ae041c9e","schema_fingerprint":"4aa3821a28b0b7c2400bc59aba4bcc0a76e971dadd19610d3ad38c768e124dc7","schema_version":"edge-lab-recorder.raw.v1","sequence":null,"source":"clob_market_ws"}
{"event_at":"2026-07-28T02:08:53.117000Z","event_fingerprint":"721b11e27a918f5c9955dddd2a7786bb16d1116e544a583b5b910005bb65bea5","payload":{"connection_id":"5d29200f65794d4d9ab6ef271f045a9b","event_at":"2026-07-28T02:08:53.117000Z","event_type":"price_change","frame_hash":"ed9d4aecbfa42990755328710bf5333878e4b4081bf40bd11080c2527dcf3be4","frame_index":0,"kind":"data","monotonic_ns":306516743033250,"payload":{"event_type":"price_change","market":"0xda6f0e0e93fc8469e0159a166028d017bddbc162b86f66bac90391379603d962","price_changes":[{"asset_id":"20893381255801015515826997628594359667013752732428989472914000440642900266717","best_ask":"0.57","best_bid":"0.56","hash":"772499a4731894024ef05cea14e4cc642128c3a0","price":"0.32","side":"BUY","size":"64.85"},{"asset_id":"39272994714739463168905443499424551362424437245880253267329605556587274644733","best_ask":"0.44","best_bid":"0.43","hash":"9a3c18fbd6a29ff04badaffdb59d0188754dc713","price":"0.68","side":"SELL","size":"64.85"}],"timestamp":"1785204533117"},"payload_hash":"1e2d027186c59c243c757f0df9c6a66f626da878ce36cbf7bc6ce060cd66cb7a","raw_frame":"{\"market\":\"0xda6f0e0e93fc8469e0159a166028d017bddbc162b86f66bac90391379603d962\", \"price_changes\":[{\"asset_id\":\"20893381255801015515826997628594359667013752732428989472914000440642900266717\", \"price\":\"0.32\", \"size\":\"64.85\", \"side\":\"BUY\", \"hash\":\"772499a4731894024ef05cea14e4cc642128c3a0\", \"best_bid\":\"0.56\", \"best_ask\":\"0.57\"}, {\"asset_id\":\"39272994714739463168905443499424551362424437245880253267329605556587274644733\", \"price\":\"0.68\", \"size\":\"64.85\", \"side\":\"SELL\", \"hash\":\"9a3c18fbd6a29ff04badaffdb59d0188754dc713\", \"best_bid\":\"0.43\", \"best_ask\":\"0.44\"}], \"timestamp\":\"1785204533117\", \"event_type\":\"price_change\"}","received_at":"2026-07-28T02:08:53.734695Z","schema_version":"clob-market-ws.price_change.v1","sequence":null,"server_hash":null,"server_timestamp":"1785204533117","session_id":"d2757dd6dad94f3b9fe67e8dbf1adc37","source":"clob_market_ws"},"received_at":"2026-07-28T02:08:53.734695Z","record_id":"4eea814eb7b0754a1173cea2425255605712245601e7a9cc6ef5a9e482529d8f","schema_fingerprint":"4aa3821a28b0b7c2400bc59aba4bcc0a76e971dadd19610d3ad38c768e124dc7","schema_version":"edge-lab-recorder.raw.v1","sequence":null,"source":"clob_market_ws"}
{"event_at":"2026-07-28T02:08:53.118000Z","event_fingerprint":"718820eafb8c1b1d08979109bd09988cb5ffcf07ac6a66a8153ca43ab0b045f2","payload":{"connection_id":"5d29200f65794d4d9ab6ef271f045a9b","event_at":"2026-07-28T02:08:53.118000Z","event_type":"price_change","frame_hash":"c8a80ee12a10b80427fbf077604928bb8a63be21ad58fbaf38d044deb0875f00","frame_index":0,"kind":"data","monotonic_ns":306516749360625,"payload":{"event_type":"price_change","market":"0xda6f0e0e93fc8469e0159a166028d017bddbc162b86f66bac90391379603d962","price_changes":[{"asset_id":"39272994714739463168905443499424551362424437245880253267329605556587274644733","best_ask":"0.44","best_bid":"0.43","hash":"22154ba0e2e8fb17a4e215831c06b13a504ce6f4","price":"0.43","side":"BUY","size":"82"},{"asset_id":"20893381255801015515826997628594359667013752732428989472914000440642900266717","best_ask":"0.57","best_bid":"0.56","hash":"a20188c5c7a79cb7bdf2ddb7802cd572d372071c","price":"0.57","side":"SELL","size":"82"}],"timestamp":"1785204533118"},"payload_hash":"09da2b21a015688b8ad0e2377334c239627975b640198c367b379f64da53b12a","raw_frame":"{\"market\":\"0xda6f0e0e93fc8469e0159a166028d017bddbc162b86f66bac90391379603d962\", \"price_changes\":[{\"asset_id\":\"39272994714739463168905443499424551362424437245880253267329605556587274644733\", \"price\":\"0.43\", \"size\":\"82\", \"side\":\"BUY\", \"hash\":\"22154ba0e2e8fb17a4e215831c06b13a504ce6f4\", \"best_bid\":\"0.43\", \"best_ask\":\"0.44\"}, {\"asset_id\":\"20893381255801015515826997628594359667013752732428989472914000440642900266717\", \"price\":\"0.57\", \"size\":\"82\", \"side\":\"SELL\", \"hash\":\"a20188c5c7a79cb7bdf2ddb7802cd572d372071c\", \"best_bid\":\"0.56\", \"best_ask\":\"0.57\"}], \"timestamp\":\"1785204533118\", \"event_type\":\"price_change\"}","received_at":"2026-07-28T02:08:53.741022Z","schema_version":"clob-market-ws.price_change.v1","sequence":null,"server_hash":null,"server_timestamp":"1785204533118","session_id":"d2757dd6dad94f3b9fe67e8dbf1adc37","source":"clob_market_ws"},"received_at":"2026-07-28T02:08:53.741022Z","record_id":"aa24526a2fdeecebe08ccc43089c49ba7cd99106818168d029db32858499afe2","schema_fingerprint":"4aa3821a28b0b7c2400bc59aba4bcc0a76e971dadd19610d3ad38c768e124dc7","schema_version":"edge-lab-recorder.raw.v1","sequence":null,"source":"clob_market_ws"}
{"event_at":"2026-07-28T02:08:53.130000Z","event_fingerprint":"e18ba69b9a6a62fc7647c0490d1b00d1bcb3624029666c1b77ebb3af9c0ddc9c","payload":{"connection_id":"5d29200f65794d4d9ab6ef271f045a9b","event_at":"2026-07-28T02:08:53.130000Z","event_type":"price_change","frame_hash":"a7de639f11ddccea38f8f695943e87ec89e0a10907c63e722dea853ee995c6ac","frame_index":0,"kind":"data","monotonic_ns":306516752574041,"payload":{"event_type":"price_change","market":"0xda6f0e0e93fc8469e0159a166028d017bddbc162b86f66bac90391379603d962","price_changes":[{"asset_id":"20893381255801015515826997628594359667013752732428989472914000440642900266717","best_ask":"0.57","best_bid":"0.56","hash":"e622c47558c5ff0facffad3e0524ef9c61cc537b","price":"0.53","side":"BUY","size":"140.95"},{"asset_id":"39272994714739463168905443499424551362424437245880253267329605556587274644733","best_ask":"0.44","best_bid":"0.43","hash":"bdac9f09a777136686c06225daabc78e481f9be7","price":"0.47","side":"SELL","size":"140.95"}],"timestamp":"1785204533130"},"payload_hash":"31ac7c4f5c5c686b72afef0486095fb566e2a0ebcccda4af82342e5acba8fa99","raw_frame":"{\"market\":\"0xda6f0e0e93fc8469e0159a166028d017bddbc162b86f66bac90391379603d962\", \"price_changes\":[{\"asset_id\":\"20893381255801015515826997628594359667013752732428989472914000440642900266717\", \"price\":\"0.53\", \"size\":\"140.95\", \"side\":\"BUY\", \"hash\":\"e622c47558c5ff0facffad3e0524ef9c61cc537b\", \"best_bid\":\"0.56\", \"best_ask\":\"0.57\"}, {\"asset_id\":\"39272994714739463168905443499424551362424437245880253267329605556587274644733\", \"price\":\"0.47\", \"size\":\"140.95\", \"side\":\"SELL\", \"hash\":\"bdac9f09a777136686c06225daabc78e481f9be7\", \"best_bid\":\"0.43\", \"best_ask\":\"0.44\"}], \"timestamp\":\"1785204533130\", \"event_type\":\"price_change\"}","received_at":"2026-07-28T02:08:53.744230Z","schema_version":"clob-market-ws.price_change.v1","sequence":null,"server_hash":null,"server_timestamp":"1785204533130","session_id":"d2757dd6dad94f3b9fe67e8dbf1adc37","source":"clob_market_ws"},"received_at":"2026-07-28T02:08:53.744230Z","record_id":"da6c7fbf1d92a078785f551fabf887f3de89e553b541eddf78e222ba8dccb227","schema_fingerprint":"4aa3821a28b0b7c2400bc59aba4bcc0a76e971dadd19610d3ad38c768e124dc7","schema_version":"edge-lab-recorder.raw.v1","sequence":null,"source":"clob_market_ws"}
{"event_at":"2026-07-28T02:08:53.135000Z","event_fingerprint":"2471911c9ce540f3eedbe4e4e90d5d1ee3a5ca1ddd1a9732af48a40a5c710182","payload":{"connection_id":"5d29200f65794d4d9ab6ef271f045a9b","event_at":"2026-07-28T02:08:53.135000Z","event_type":"price_change","frame_hash":"6f68ce3b3a8c5e7617e42847961ad604940b2c7a3de714a9809fd5af49cc3533","frame_index":0,"kind":"data","monotonic_ns":306516762742916,"payload":{"event_type":"price_change","market":"0xda6f0e0e93fc8469e0159a166028d017bddbc162b86f66bac90391379603d962","price_changes":[{"asset_id":"20893381255801015515826997628594359667013752732428989472914000440642900266717","best_ask":"0.57","best_bid":"0.56","hash":"a3ad340cb9f924131dd3e7a7912147c71ebf78d1","price":"0.35","side":"BUY","size":"177.43"},{"asset_id":"39272994714739463168905443499424551362424437245880253267329605556587274644733","best_ask":"0.44","best_bid":"0.43","hash":"4e853a261e63a00c2cae947119dc94e1d592521b","price":"0.65","side":"SELL","size":"177.43"}],"timestamp":"1785204533135"},"payload_hash":"efd211771b4269b148c8212d61e4b198e5c902b9473b18787d46a3991b009bc7","raw_frame":"{\"market\":\"0xda6f0e0e93fc8469e0159a166028d017bddbc162b86f66bac90391379603d962\", \"price_changes\":[{\"asset_id\":\"20893381255801015515826997628594359667013752732428989472914000440642900266717\", \"price\":\"0.35\", \"size\":\"177.43\", \"side\":\"BUY\", \"hash\":\"a3ad340cb9f924131dd3e7a7912147c71ebf78d1\", \"best_bid\":\"0.56\", \"best_ask\":\"0.57\"}, {\"asset_id\":\"39272994714739463168905443499424551362424437245880253267329605556587274644733\", \"price\":\"0.65\", \"size\":\"177.43\", \"side\":\"SELL\", \"hash\":\"4e853a261e63a00c2cae947119dc94e1d592521b\", \"best_bid\":\"0.43\", \"best_ask\":\"0.44\"}], \"timestamp\":\"1785204533135\", \"event_type\":\"price_change\"}","received_at":"2026-07-28T02:08:53.754404Z","schema_version":"clob-market-ws.price_change.v1","sequence":null,"server_hash":null,"server_timestamp":"1785204533135","session_id":"d2757dd6dad94f3b9fe67e8dbf1adc37","source":"clob_market_ws"},"received_at":"2026-07-28T02:08:53.754404Z","record_id":"63b35ddde9afc620082c8a0ac33dc51c9af30eb2026b1312813544d76eb00af0","schema_fingerprint":"4aa3821a28b0b7c2400bc59aba4bcc0a76e971dadd19610d3ad38c768e124dc7","schema_version":"edge-lab-recorder.raw.v1","sequence":null,"source":"clob_market_ws"}
{"event_at":"2026-07-28T02:08:53.137000Z","event_fingerprint":"52ffbbab1f775f7cd1370b2d96c6b6bd553635195356c50ee1502d309e942bce","payload":{"connection_id":"5d29200f65794d4d9ab6ef271f045a9b","event_at":"2026-07-28T02:08:53.137000Z","event_type":"price_change","frame_hash":"3c98078f01b4ca1305694f84b353bd2972f82320f2c2704e31f7e9fc69b185b9","frame_index":0,"kind":"data","monotonic_ns":306516769353500,"payload":{"event_type":"price_change","market":"0xda6f0e0e93fc8469e0159a166028d017bddbc162b86f66bac90391379603d962","price_changes":[{"asset_id":"39272994714739463168905443499424551362424437245880253267329605556587274644733","best_ask":"0.44","best_bid":"0.43","hash":"94ab7cb79401569633f16fdf6a14f29cd17907ae","price":"0.43","side":"BUY","size":"77"},{"asset_id":"20893381255801015515826997628594359667013752732428989472914000440642900266717","best_ask":"0.57","best_bid":"0.56","hash":"7a8d51842a6f9c8cc3533f9143624f7ca3447cc8","price":"0.57","side":"SELL","size":"77"}],"timestamp":"1785204533137"},"payload_hash":"aad7395b8588bf19f98bc60829c2cb4e973788074f854f5cb47cb6811c89f479","raw_frame":"{\"market\":\"0xda6f0e0e93fc8469e0159a166028d017bddbc162b86f66bac90391379603d962\", \"price_changes\":[{\"asset_id\":\"39272994714739463168905443499424551362424437245880253267329605556587274644733\", \"price\":\"0.43\", \"size\":\"77\", \"side\":\"BUY\", \"hash\":\"94ab7cb79401569633f16fdf6a14f29cd17907ae\", \"best_bid\":\"0.43\", \"best_ask\":\"0.44\"}, {\"asset_id\":\"20893381255801015515826997628594359667013752732428989472914000440642900266717\", \"price\":\"0.57\", \"size\":\"77\", \"side\":\"SELL\", \"hash\":\"7a8d51842a6f9c8cc3533f9143624f7ca3447cc8\", \"best_bid\":\"0.56\", \"best_ask\":\"0.57\"}], \"timestamp\":\"1785204533137\", \"event_type\":\"price_change\"}","received_at":"2026-07-28T02:08:53.761016Z","schema_version":"clob-market-ws.price_change.v1","sequence":null,"server_hash":null,"server_timestamp":"1785204533137","session_id":"d2757dd6dad94f3b9fe67e8dbf1adc37","source":"clob_market_ws"},"received_at":"2026-07-28T02:08:53.761016Z","record_id":"a20e1088915374656987f652af55599dce3ff0b210162213a16b692bc8456604","schema_fingerprint":"4aa3821a28b0b7c2400bc59aba4bcc0a76e971dadd19610d3ad38c768e124dc7","schema_version":"edge-lab-recorder.raw.v1","sequence":null,"source":"clob_market_ws"}
{"event_at":"2026-07-28T02:08:53.139000Z","event_fingerprint":"526f5292519bcc8954a8aab4a120d909a22f6d50c7c9c6cd94080aaa3fa13659","payload":{"connection_id":"5d29200f65794d4d9ab6ef271f045a9b","event_at":"2026-07-28T02:08:53.139000Z","event_type":"price_change","frame_hash":"e8f3c2e96de341692a2cd52cdae529cccb5b34faf99d7753c2262b1e27c9cb91","frame_index":0,"kind":"data","monotonic_ns":306516775375166,"payload":{"event_type":"price_change","market":"0xda6f0e0e93fc8469e0159a166028d017bddbc162b86f66bac90391379603d962","price_changes":[{"asset_id":"20893381255801015515826997628594359667013752732428989472914000440642900266717","best_ask":"0.57","best_bid":"0.56","hash":"a5ba0b6c1b6318b3a5ec30c83eca6dad2b86da4b","price":"0.57","side":"SELL","size":"69"},{"asset_id":"39272994714739463168905443499424551362424437245880253267329605556587274644733","best_ask":"0.44","best_bid":"0.43","hash":"2d363194895aaf8e658cf4cb3d2c654d8d97f7ad","price":"0.43","side":"BUY","size":"69"}],"timestamp":"1785204533139"},"payload_hash":"f508319947baa984538050bebb321d83d069db0bcd2216461aae66427085f167","raw_frame":"{\"market\":\"0xda6f0e0e93fc8469e0159a166028d017bddbc162b86f66bac90391379603d962\", \"price_changes\":[{\"asset_id\":\"20893381255801015515826997628594359667013752732428989472914000440642900266717\", \"price\":\"0.57\", \"size\":\"69\", \"side\":\"SELL\", \"hash\":\"a5ba0b6c1b6318b3a5ec30c83eca6dad2b86da4b\", \"best_bid\":\"0.56\", \"best_ask\":\"0.57\"}, {\"asset_id\":\"39272994714739463168905443499424551362424437245880253267329605556587274644733\", \"price\":\"0.43\", \"size\":\"69\", \"side\":\"BUY\", \"hash\":\"2d363194895aaf8e658cf4cb3d2c654d8d97f7ad\", \"best_bid\":\"0.43\", \"best_ask\":\"0.44\"}], \"timestamp\":\"1785204533139\", \"event_type\":\"price_change\"}","received_at":"2026-07-28T02:08:53.767037Z","schema_version":"clob-market-ws.price_change.v1","sequence":null,"server_hash":null,"server_timestamp":"1785204533139","session_id":"d2757dd6dad94f3b9fe67e8dbf1adc37","source":"clob_market_ws"},"received_at":"2026-07-28T02:08:53.767037Z","record_id":"379ba496b12e30a0c9bdf92e5b68d4d0fb3a410464e23b984b06e0c29d1adda1","schema_fingerprint":"4aa3821a28b0b7c2400bc59aba4bcc0a76e971dadd19610d3ad38c768e124dc7","schema_version":"edge-lab-recorder.raw.v1","sequence":null,"source":"clob_market_ws"}
{"event_at":"2026-07-28T02:08:53.139000Z","event_fingerprint":"7dcfd0093528293b65877b5f5e221444257f9931d9101f42855a05ea9222a8b2","payload":{"connection_id":"5d29200f65794d4d9ab6ef271f045a9b","event_at":"2026-07-28T02:08:53.139000Z","event_type":"price_change","frame_hash":"a21c10669447581cdc04b433551234393e83cf6d02e7f6243dc6dd8e473a10c2","frame_index":0,"kind":"data","monotonic_ns":306516778962166,"payload":{"event_type":"price_change","market":"0xda6f0e0e93fc8469e0159a166028d017bddbc162b86f66bac90391379603d962","price_changes":[{"asset_id":"20893381255801015515826997628594359667013752732428989472914000440642900266717","best_ask":"0.57","best_bid":"0.56","hash":"2bc0edc07233b6285d51b6f420d28f39099bbd63","price":"0.49","side":"BUY","size":"246"},{"asset_id":"39272994714739463168905443499424551362424437245880253267329605556587274644733","best_ask":"0.44","best_bid":"0.43","hash":"848efc25959178339ef2735d87b5a7de2bf10d75","price":"0.51","side":"SELL","size":"246"}],"timestamp":"1785204533139"},"payload_hash":"67dd55db3fea2e4963e2fe42257407e029378ec9b54812ba2325d3557f940586","raw_frame":"{\"market\":\"0xda6f0e0e93fc8469e0159a166028d017bddbc162b86f66bac90391379603d962\", \"price_changes\":[{\"asset_id\":\"20893381255801015515826997628594359667013752732428989472914000440642900266717\", \"price\":\"0.49\", \"size\":\"246\", \"side\":\"BUY\", \"hash\":\"2bc0edc07233b6285d51b6f420d28f39099bbd63\", \"best_bid\":\"0.56\", \"best_ask\":\"0.57\"}, {\"asset_id\":\"39272994714739463168905443499424551362424437245880253267329605556587274644733\", \"price\":\"0.51\", \"size\":\"246\", \"side\":\"SELL\", \"hash\":\"848efc25959178339ef2735d87b5a7de2bf10d75\", \"best_bid\":\"0.43\", \"best_ask\":\"0.44\"}], \"timestamp\":\"1785204533139\", \"event_type\":\"price_change\"}","received_at":"2026-07-28T02:08:53.770624Z","schema_version":"clob-market-ws.price_change.v1","sequence":null,"server_hash":null,"server_timestamp":"1785204533139","session_id":"d2757dd6dad94f3b9fe67e8dbf1adc37","source":"clob_market_ws"},"received_at":"2026-07-28T02:08:53.770624Z","record_id":"be0cdfd9029732c614fb37337f0efdfd46d5861a45051fae127a435b3a493598","schema_fingerprint":"4aa3821a28b0b7c2400bc59aba4bcc0a76e971dadd19610d3ad38c768e124dc7","schema_version":"edge-lab-recorder.raw.v1","sequence":null,"source":"clob_market_ws"}
{"event_at":"2026-07-28T02:08:53.139000Z","event_fingerprint":"c50370098e39317e5ab7d41b0acfa6005c8e956b5be83ce0d154bb411b365d1d","payload":{"connection_id":"5d29200f65794d4d9ab6ef271f045a9b","event_at":"2026-07-28T02:08:53.139000Z","event_type":"price_change","frame_hash":"dc2b59797786250a5ca015938cb3e902106f64fffde7160cdebc3ae669081294","frame_index":0,"kind":"data","monotonic_ns":306516782141416,"payload":{"event_type":"price_change","market":"0xda6f0e0e93fc8469e0159a166028d017bddbc162b86f66bac90391379603d962","price_changes":[{"asset_id":"39272994714739463168905443499424551362424437245880253267329605556587274644733","best_ask":"0.44","best_bid":"0.43","hash":"848efc25959178339ef2735d87b5a7de2bf10d75","price":"0.38","side":"BUY","size":"64.6"},{"asset_id":"20893381255801015515826997628594359667013752732428989472914000440642900266717","best_ask":"0.57","best_bid":"0.56","hash":"2bc0edc07233b6285d51b6f420d28f39099bbd63","price":"0.62","side":"SELL","size":"64.6"}],"timestamp":"1785204533139"},"payload_hash":"1bdffacf6dfe5d3eef48f183ad698807d866421225de22d738ab2b0308a49253","raw_frame":"{\"market\":\"0xda6f0e0e93fc8469e0159a166028d017bddbc162b86f66bac90391379603d962\", \"price_changes\":[{\"asset_id\":\"39272994714739463168905443499424551362424437245880253267329605556587274644733\", \"price\":\"0.38\", \"size\":\"64.6\", \"side\":\"BUY\", \"hash\":\"848efc25959178339ef2735d87b5a7de2bf10d75\", \"best_bid\":\"0.43\", \"best_ask\":\"0.44\"}, {\"asset_id\":\"20893381255801015515826997628594359667013752732428989472914000440642900266717\", \"price\":\"0.62\", \"size\":\"64.6\", \"side\":\"SELL\", \"hash\":\"2bc0edc07233b6285d51b6f420d28f39099bbd63\", \"best_bid\":\"0.56\", \"best_ask\":\"0.57\"}], \"timestamp\":\"1785204533139\", \"event_type\":\"price_change\"}","received_at":"2026-07-28T02:08:53.773803Z","schema_version":"clob-market-ws.price_change.v1","sequence":null,"server_hash":null,"server_timestamp":"1785204533139","session_id":"d2757dd6dad94f3b9fe67e8dbf1adc37","source":"clob_market_ws"},"received_at":"2026-07-28T02:08:53.773803Z","record_id":"c2e7672215c9fe142dfd7b9e503fdc5866363bc27a066a0ed36a09d350ecbb4f","schema_fingerprint":"4aa3821a28b0b7c2400bc59aba4bcc0a76e971dadd19610d3ad38c768e124dc7","schema_version":"edge-lab-recorder.raw.v1","sequence":null,"source":"clob_market_ws"}
{"event_at":"2026-07-28T02:08:53.150000Z","event_fingerprint":"8a1935141b5e17620137f03d49a24cb79a2a2227a2f659bdaa68badacd7b8ba9","payload":{"connection_id":"5d29200f65794d4d9ab6ef271f045a9b","event_at":"2026-07-28T02:08:53.150000Z","event_type":"price_change","frame_hash":"d5db1f697312bf95a02a35696ea99209e96d5c66806b6511d8492eb722b92710","frame_index":0,"kind":"data","monotonic_ns":306516785201458,"payload":{"event_type":"price_change","market":"0xda6f0e0e93fc8469e0159a166028d017bddbc162b86f66bac90391379603d962","price_changes":[{"asset_id":"39272994714739463168905443499424551362424437245880253267329605556587274644733","best_ask":"0.44","best_bid":"0.43","hash":"f3070374785531c8b3633b9c722b761646f2119b","price":"0.42","side":"BUY","size":"56.31"},{"asset_id":"20893381255801015515826997628594359667013752732428989472914000440642900266717","best_ask":"0.57","best_bid":"0.56","hash":"30e9816df22e344596c7c42c9fcac6a0bf058782","price":"0.58","side":"SELL","size":"56.31"}],"timestamp":"1785204533150"},"payload_hash":"bac05a74bd05fac7a96d221d6fb7560d2ff1de60c81f275e4449c97762ef96b8","raw_frame":"{\"market\":\"0xda6f0e0e93fc8469e0159a166028d017bddbc162b86f66bac90391379603d962\", \"price_changes\":[{\"asset_id\":\"39272994714739463168905443499424551362424437245880253267329605556587274644733\", \"price\":\"0.42\", \"size\":\"56.31\", \"side\":\"BUY\", \"hash\":\"f3070374785531c8b3633b9c722b761646f2119b\", \"best_bid\":\"0.43\", \"best_ask\":\"0.44\"}, {\"asset_id\":\"20893381255801015515826997628594359667013752732428989472914000440642900266717\", \"price\":\"0.58\", \"size\":\"56.31\", \"side\":\"SELL\", \"hash\":\"30e9816df22e344596c7c42c9fcac6a0bf058782\", \"best_bid\":\"0.56\", \"best_ask\":\"0.57\"}], \"timestamp\":\"1785204533150\", \"event_type\":\"price_change\"}","received_at":"2026-07-28T02:08:53.776862Z","schema_version":"clob-market-ws.price_change.v1","sequence":null,"server_hash":null,"server_timestamp":"1785204533150","session_id":"d2757dd6dad94f3b9fe67e8dbf1adc37","source":"clob_market_ws"},"received_at":"2026-07-28T02:08:53.776862Z","record_id":"450edf11512fc0acb2be5f5e6c2259d0f7d1983ce1f9280770dc49cb3b8b6cbe","schema_fingerprint":"4aa3821a28b0b7c2400bc59aba4bcc0a76e971dadd19610d3ad38c768e124dc7","schema_version":"edge-lab-recorder.raw.v1","sequence":null,"source":"clob_market_ws"}
{"event_at":"2026-07-28T02:08:53.151000Z","event_fingerprint":"b82870edd6ba09b57c96fe7ffb35fbac3efdb60288f7e472b129c68702d9b0d5","payload":{"connection_id":"5d29200f65794d4d9ab6ef271f045a9b","event_at":"2026-07-28T02:08:53.151000Z","event_type":"price_change","frame_hash":"aeb55e26c9a9bed0263e566f6e21397e9f5c1656af79d7c594fdfcff493c278c","frame_index":0,"kind":"data","monotonic_ns":306516788184000,"payload":{"event_type":"price_change","market":"0xda6f0e0e93fc8469e0159a166028d017bddbc162b86f66bac90391379603d962","price_changes":[{"asset_id":"20893381255801015515826997628594359667013752732428989472914000440642900266717","best_ask":"0.57","best_bid":"0.56","hash":"bec85141478584f6f1eb051e3d5e8c708fbf6dd0","price":"0.45","side":"BUY","size":"239.11"},{"asset_id":"39272994714739463168905443499424551362424437245880253267329605556587274644733","best_ask":"0.44","best_bid":"0.43","hash":"f6ab7a2496763205a292412731911396c5b86443","price":"0.55","side":"SELL","size":"239.11"}],"timestamp":"1785204533151"},"payload_hash":"850de9a9e1342b3f2c6e1410a7eb4ced975392357abc00f04782c0edb7d15660","raw_frame":"{\"market\":\"0xda6f0e0e93fc8469e0159a166028d017bddbc162b86f66bac90391379603d962\", \"price_changes\":[{\"asset_id\":\"20893381255801015515826997628594359667013752732428989472914000440642900266717\", \"price\":\"0.45\", \"size\":\"239.11\", \"side\":\"BUY\", \"hash\":\"bec85141478584f6f1eb051e3d5e8c708fbf6dd0\", \"best_bid\":\"0.56\", \"best_ask\":\"0.57\"}, {\"asset_id\":\"39272994714739463168905443499424551362424437245880253267329605556587274644733\", \"price\":\"0.55\", \"size\":\"239.11\", \"side\":\"SELL\", \"hash\":\"f6ab7a2496763205a292412731911396c5b86443\", \"best_bid\":\"0.43\", \"best_ask\":\"0.44\"}], \"timestamp\":\"1785204533151\", \"event_type\":\"price_change\"}","received_at":"2026-07-28T02:08:53.779845Z","schema_version":"clob-market-ws.price_change.v1","sequence":null,"server_hash":null,"server_timestamp":"1785204533151","session_id":"d2757dd6dad94f3b9fe67e8dbf1adc37","source":"clob_market_ws"},"received_at":"2026-07-28T02:08:53.779845Z","record_id":"c1a0fb98896f063455f429ae531d416858be9de1620d41c39055a653e66946de","schema_fingerprint":"4aa3821a28b0b7c2400bc59aba4bcc0a76e971dadd19610d3ad38c768e124dc7","schema_version":"edge-lab-recorder.raw.v1","sequence":null,"source":"clob_market_ws"}
{"event_at":"2026-07-28T02:08:53.152000Z","event_fingerprint":"961ea131ad692dd4a76fc180ae7797bbf2720f973914c1f836a9d4b84611a726","payload":{"connection_id":"5d29200f65794d4d9ab6ef271f045a9b","event_at":"2026-07-28T02:08:53.152000Z","event_type":"price_change","frame_hash":"1ba4ebc562faaee65b2e0bc3441b6a0c679527404bd40bf481a9486fe04ac0dc","frame_index":0,"kind":"data","monotonic_ns":306516791111791,"payload":{"event_type":"price_change","market":"0xda6f0e0e93fc8469e0159a166028d017bddbc162b86f66bac90391379603d962","price_changes":[{"asset_id":"39272994714739463168905443499424551362424437245880253267329605556587274644733","best_ask":"0.44","best_bid":"0.43","hash":"728c62eefc5ceb1949739829d17c50e7b6457553","price":"0.43","side":"BUY","size":"75"},{"asset_id":"20893381255801015515826997628594359667013752732428989472914000440642900266717","best_ask":"0.57","best_bid":"0.56","hash":"32c09ce8733b511210a822e90edf626513cd4964","price":"0.57","side":"SELL","size":"75"}],"timestamp":"1785204533152"},"payload_hash":"05bd29af6967c344765d6894d81834ac955392edae3bebb2345aa4798637df1c","raw_frame":"{\"market\":\"0xda6f0e0e93fc8469e0159a166028d017bddbc162b86f66bac90391379603d962\", \"price_changes\":[{\"asset_id\":\"39272994714739463168905443499424551362424437245880253267329605556587274644733\", \"price\":\"0.43\", \"size\":\"75\", \"side\":\"BUY\", \"hash\":\"728c62eefc5ceb1949739829d17c50e7b6457553\", \"best_bid\":\"0.43\", \"best_ask\":\"0.44\"}, {\"asset_id\":\"20893381255801015515826997628594359667013752732428989472914000440642900266717\", \"price\":\"0.57\", \"size\":\"75\", \"side\":\"SELL\", \"hash\":\"32c09ce8733b511210a822e90edf626513cd4964\", \"best_bid\":\"0.56\", \"best_ask\":\"0.57\"}], \"timestamp\":\"1785204533152\", \"event_type\":\"price_change\"}","received_at":"2026-07-28T02:08:53.782774Z","schema_version":"clob-market-ws.price_change.v1","sequence":null,"server_hash":null,"server_timestamp":"1785204533152","session_id":"d2757dd6dad94f3b9fe67e8dbf1adc37","source":"clob_market_ws"},"received_at":"2026-07-28T02:08:53.782774Z","record_id":"1cd0686b9f186ab68a649a88f0f07b1a0f9d2ad8dc30aff169d1d906d5ea7be5","schema_fingerprint":"4aa3821a28b0b7c2400bc59aba4bcc0a76e971dadd19610d3ad38c768e124dc7","schema_version":"edge-lab-recorder.raw.v1","sequence":null,"source":"clob_market_ws"}
{"event_at":"2026-07-28T02:08:53.158000Z","event_fingerprint":"e1fa5e33b7a62ca6fbd94fe169aee84b3b5ad7175e93894e8790a5cd7e2ee4b8","payload":{"connection_id":"5d29200f65794d4d9ab6ef271f045a9b","event_at":"2026-07-28T02:08:53.158000Z","event_type":"price_change","frame_hash":"7cb387ac3c007025ce2dc65e154412f3573a3ada09e094ec7bcbd46f8fcbbf15","frame_index":0,"kind":"data","monotonic_ns":306516794081583,"payload":{"event_type":"price_change","market":"0xda6f0e0e93fc8469e0159a166028d017bddbc162b86f66bac90391379603d962","price_changes":[{"asset_id":"39272994714739463168905443499424551362424437245880253267329605556587274644733","best_ask":"0.44","best_bid":"0.43","hash":"c9fcd7ccc26ff6b5b1c73714e08fe3f53a160ce0","price":"0.34","side":"BUY","size":"99"},{"asset_id":"20893381255801015515826997628594359667013752732428989472914000440642900266717","best_ask":"0.57","best_bid":"0.56","hash":"455869878a90b4adbe19487d0172814621338329","price":"0.66","side":"SELL","size":"99"}],"timestamp":"1785204533158"},"payload_hash":"e6e8828f2feecb34f22ad051d35c815698128da7f1824834d78cf34fdf51087e","raw_frame":"{\"market\":\"0xda6f0e0e93fc8469e0159a166028d017bddbc162b86f66bac90391379603d962\", \"price_changes\":[{\"asset_id\":\"39272994714739463168905443499424551362424437245880253267329605556587274644733\", \"price\":\"0.34\", \"size\":\"99\", \"side\":\"BUY\", \"hash\":\"c9fcd7ccc26ff6b5b1c73714e08fe3f53a160ce0\", \"best_bid\":\"0.43\", \"best_ask\":\"0.44\"}, {\"asset_id\":\"20893381255801015515826997628594359667013752732428989472914000440642900266717\", \"price\":\"0.66\", \"size\":\"99\", \"side\":\"SELL\", \"hash\":\"455869878a90b4adbe19487d0172814621338329\", \"best_bid\":\"0.56\", \"best_ask\":\"0.57\"}], \"timestamp\":\"1785204533158\", \"event_type\":\"price_change\"}","received_at":"2026-07-28T02:08:53.785743Z","schema_version":"clob-market-ws.price_change.v1","sequence":null,"server_hash":null,"server_timestamp":"1785204533158","session_id":"d2757dd6dad94f3b9fe67e8dbf1adc37","source":"clob_market_ws"},"received_at":"2026-07-28T02:08:53.785743Z","record_id":"59bcbf9656a0639bee0a03dd470fb915ff0a4f325ddf53b27209ed46575db680","schema_fingerprint":"4aa3821a28b0b7c2400bc59aba4bcc0a76e971dadd19610d3ad38c768e124dc7","schema_version":"edge-lab-recorder.raw.v1","sequence":null,"source":"clob_market_ws"}
{"event_at":"2026-07-28T02:08:53.160000Z","event_fingerprint":"d1a634a5b00eb9330ac3436aecce4b8572be8382364e4bfb09e9e9c41004622f","payload":{"connection_id":"5d29200f65794d4d9ab6ef271f045a9b","event_at":"2026-07-28T02:08:53.160000Z","event_type":"best_bid_ask","frame_hash":"4fded9aafe54f66daa7875024363ab2acd6fd4da142612b10347fa0f0b7ca335","frame_index":0,"kind":"data","monotonic_ns":306516797031750,"payload":{"asset_id":"20893381255801015515826997628594359667013752732428989472914000440642900266717","best_ask":"0.57","best_bid":"0.56","event_type":"best_bid_ask","market":"0xda6f0e0e93fc8469e0159a166028d017bddbc162b86f66bac90391379603d962","spread":"0.01","timestamp":"1785204533160"},"payload_hash":"a1a03a7b9b5355a050547f5adc4febf98bf536e3940a733a471f286436fd9cf4","raw_frame":"{\"market\":\"0xda6f0e0e93fc8469e0159a166028d017bddbc162b86f66bac90391379603d962\", \"asset_id\":\"20893381255801015515826997628594359667013752732428989472914000440642900266717\", \"best_bid\":\"0.56\", \"best_ask\":\"0.57\", \"spread\":\"0.01\", \"timestamp\":\"1785204533160\", \"event_type\":\"best_bid_ask\"}","received_at":"2026-07-28T02:08:53.788693Z","schema_version":"clob-market-ws.best_bid_ask.v1","sequence":null,"server_hash":null,"server_timestamp":"1785204533160","session_id":"d2757dd6dad94f3b9fe67e8dbf1adc37","source":"clob_market_ws"},"received_at":"2026-07-28T02:08:53.788693Z","record_id":"703cc7f0207bf0c8c1f88e5d3ac0151901b38cc8d8e7f8a7c77ccf2b766f56e8","schema_fingerprint":"8488399f31b0337811b13b266be932db7062827c2470b78bd8e9e99bab51d17d","schema_version":"edge-lab-recorder.raw.v1","sequence":null,"source":"clob_market_ws"}
{"event_at":"2026-07-28T02:08:53.160000Z","event_fingerprint":"e77d7400d395a744478ac1960ea60c3238438f58a934effe335672d88ed83392","payload":{"connection_id":"5d29200f65794d4d9ab6ef271f045a9b","event_at":"2026-07-28T02:08:53.160000Z","event_type":"best_bid_ask","frame_hash":"68dc957c80ed59bc254de6f6738e65c48776fe50c1cd3620a24ab3a3b8e3bcc3","frame_index":0,"kind":"data","monotonic_ns":306516799198958,"payload":{"asset_id":"39272994714739463168905443499424551362424437245880253267329605556587274644733","best_ask":"0.44","best_bid":"0.43","event_type":"best_bid_ask","market":"0xda6f0e0e93fc8469e0159a166028d017bddbc162b86f66bac90391379603d962","spread":"0.01","timestamp":"1785204533160"},"payload_hash":"7411d469de62c545cf63603a1d984fe6ca7e02e2c12e00814a0f9d3b206bd9af","raw_frame":"{\"market\":\"0xda6f0e0e93fc8469e0159a166028d017bddbc162b86f66bac90391379603d962\", \"asset_id\":\"39272994714739463168905443499424551362424437245880253267329605556587274644733\", \"best_bid\":\"0.43\", \"best_ask\":\"0.44\", \"spread\":\"0.01\", \"timestamp\":\"1785204533160\", \"event_type\":\"best_bid_ask\"}","received_at":"2026-07-28T02:08:53.790860Z","schema_version":"clob-market-ws.best_bid_ask.v1","sequence":null,"server_hash":null,"server_timestamp":"1785204533160","session_id":"d2757dd6dad94f3b9fe67e8dbf1adc37","source":"clob_market_ws"},"received_at":"2026-07-28T02:08:53.790860Z","record_id":"4d7acf4f60bd5926c799b3ffbd5783fb16970e45ddcc8ca615eff5f3534b67eb","schema_fingerprint":"8488399f31b0337811b13b266be932db7062827c2470b78bd8e9e99bab51d17d","schema_version":"edge-lab-recorder.raw.v1","sequence":null,"source":"clob_market_ws"}
{"event_at":"2026-07-28T02:08:53.160000Z","event_fingerprint":"a5a4666c1918cb6cd46fe3e19271ee21e616542b1d978c1340898c5675cc0066","payload":{"connection_id":"5d29200f65794d4d9ab6ef271f045a9b","event_at":"2026-07-28T02:08:53.160000Z","event_type":"price_change","frame_hash":"024267fbeb65122a49b36a47270a128cac5bd0b5c4ffd0b90f02a5bcac3ffbf4","frame_index":0,"kind":"data","monotonic_ns":306516801252000,"payload":{"event_type":"price_change","market":"0xda6f0e0e93fc8469e0159a166028d017bddbc162b86f66bac90391379603d962","price_changes":[{"asset_id":"20893381255801015515826997628594359667013752732428989472914000440642900266717","best_ask":"0.57","best_bid":"0.56","hash":"d7591254a2202bc528630be0934bfbaf2f2c025a","price":"0.56","side":"BUY","size":"22.7"},{"asset_id":"39272994714739463168905443499424551362424437245880253267329605556587274644733","best_ask":"0.44","best_bid":"0.43","hash":"abd9d55ad8cd1541be08f4b2acdaa9f0fc1203d5","price":"0.44","side":"SELL","size":"22.7"}],"timestamp":"1785204533160"},"payload_hash":"823a3b5858474dad338bfc81f9bc91a0d9c0a7ae5781e08945c1d6428890ab75","raw_frame":"{\"market\":\"0xda6f0e0e93fc8469e0159a166028d017bddbc162b86f66bac90391379603d962\", \"price_changes\":[{\"asset_id\":\"20893381255801015515826997628594359667013752732428989472914000440642900266717\", \"price\":\"0.56\", \"size\":\"22.7\", \"side\":\"BUY\", \"hash\":\"d7591254a2202bc528630be0934bfbaf2f2c025a\", \"best_bid\":\"0.56\", \"best_ask\":\"0.57\"}, {\"asset_id\":\"39272994714739463168905443499424551362424437245880253267329605556587274644733\", \"price\":\"0.44\", \"size\":\"22.7\", \"side\":\"SELL\", \"hash\":\"abd9d55ad8cd1541be08f4b2acdaa9f0fc1203d5\", \"best_bid\":\"0.43\", \"best_ask\":\"0.44\"}], \"timestamp\":\"1785204533160\", \"event_type\":\"price_change\"}","received_at":"2026-07-28T02:08:53.792914Z","schema_version":"clob-market-ws.price_change.v1","sequence":null,"server_hash":null,"server_timestamp":"1785204533160","session_id":"d2757dd6dad94f3b9fe67e8dbf1adc37","source":"clob_market_ws"},"received_at":"2026-07-28T02:08:53.792914Z","record_id":"99480d32b6f0399a8a5827cc2e9e4d33b38fd183d885f5d224f17bb445965e86","schema_fingerprint":"4aa3821a28b0b7c2400bc59aba4bcc0a76e971dadd19610d3ad38c768e124dc7","schema_version":"edge-lab-recorder.raw.v1","sequence":null,"source":"clob_market_ws"}
{"event_at":"2026-07-28T02:08:53.160000Z","event_fingerprint":"b21df36e382dff7dff0829da31b3fb3b8c9c8968bdf291733feed832ddf3ad89","payload":{"connection_id":"5d29200f65794d4d9ab6ef271f045a9b","event_at":"2026-07-28T02:08:53.160000Z","event_type":"book","frame_hash":"3326210df7b5f0734c887bbd1f76db97f152bac456dc59dcf4684186655bae74","frame_index":0,"kind":"data","monotonic_ns":306516804255250,"payload":{"asks":[{"price":"0.99","size":"5608.02"},{"price":"0.98","size":"678.1"},{"price":"0.97","size":"781.43"},{"price":"0.96","size":"588.09"},{"price":"0.95","size":"749.2"},{"price":"0.94","size":"605.2"},{"price":"0.93","size":"565.1"},{"price":"0.92","size":"567.79"},{"price":"0.91","size":"581.6"},{"price":"0.9","size":"165.59"},{"price":"0.89","size":"43.6"},{"price":"0.88","size":"109.4"},{"price":"0.87","size":"66.5"},{"price":"0.86","size":"78.9"},{"price":"0.85","size":"161.5"},{"price":"0.84","size":"85.3"},{"price":"0.83","size":"74.3"},{"price":"0.82","size":"102.3"},{"price":"0.81","size":"71.5"},{"price":"0.8","size":"120.8"},{"price":"0.79","size":"100.1"},{"price":"0.78","size":"220.01"},{"price":"0.77","size":"312.8"},{"price":"0.76","size":"336.27"},{"price":"0.75","size":"210"},{"price":"0.74","size":"183.6"},{"price":"0.73","size":"219.2"},{"price":"0.72","size":"187.9"},{"price":"0.71","size":"217.1"},{"price":"0.7","size":"231.96"},{"price":"0.69","size":"175"},{"price":"0.68","size":"159"},{"price":"0.67","size":"88"},{"price":"0.66","size":"99"},{"price":"0.65","size":"161"},{"price":"0.64","size":"87"},{"price":"0.63","size":"79.98"},{"price":"0.62","size":"64.6"},{"price":"0.61","size":"117.18"},{"price":"0.6","size":"91.08"},{"price":"0.59","size":"90.99"},{"price":"0.58","size":"56.31"},{"price":"0.57","size":"75"}],"asset_id":"20893381255801015515826997628594359667013752732428989472914000440642900266717","bids":[{"price":"0.01","size":"5682.02"},{"price":"0.02","size":"732.1"},{"price":"0.03","size":"662.1"},{"price":"0.04","size":"662.09"},{"price":"0.05","size":"867.2"},{"price":"0.06","size":"597.2"},{"price":"0.07","size":"120.1"},{"price":"0.08","size":"94.79"},{"price":"0.09","size":"95.6"},{"price":"0.1","size":"211.29"},{"price":"0.11","size":"87.6"},{"price":"0.12","size":"94.4"},{"price":"0.13","size":"111.5"},{"price":"0.14","size":"78.9"},{"price":"0.15","size":"131.5"},{"price":"0.16","size":"115.3"},{"price":"0.17","size":"74.3"},{"price":"0.18","size":"77.86"},{"price":"0.19","size":"101.5"},{"price":"0.2","size":"110.8"},{"price":"0.21","size":"70.1"},{"price":"0.22","size":"98.5"},{"price":"0.23","size":"67.89"},{"price":"0.24","size":"67.39"},{"price":"0.25","size":"125"},{"price":"0.26","size":"65.6"},{"price":"0.27","size":"65.2"},{"price":"0.28","size":"94.9"},{"price":"0.29","size":"64.6"},{"price":"0.3","size":"88.3"},{"price":"0.31","size":"94"},{"price":"0.32","size":"64.85"},{"price":"0.33","size":"63.6"},{"price":"0.34","size":"93.4"},{"price":"0.35","size":"177.43"},{"price":"0.36","size":"62"},{"price":"0.37","size":"91.9"},{"price":"0.38","size":"61.7"},{"price":"0.39","size":"61.6"},{"price":"0.4","size":"96.5"},{"price":"0.41","size":"67.4"},{"price":"0.42","size":"171.3"},{"price":"0.43","size":"242.2"},{"price":"0.44","size":"169.2"},{"price":"0.45","size":"239.11"},{"price":"0.46","size":"253.09"},{"price":"0.47","size":"326.06"},{"price":"0.48","size":"217.53"},{"price":"0.49","size":"246"},{"price":"0.5","size":"194"},{"price":"0.51","size":"194"},{"price":"0.52","size":"237"},{"price":"0.53","size":"140.95"},{"price":"0.54","size":"52"},{"price":"0.55","size":"51"},{"price":"0.56","size":"22.7"}],"event_type":"book","hash":"d7591254a2202bc528630be0934bfbaf2f2c025a","market":"0xda6f0e0e93fc8469e0159a166028d017bddbc162b86f66bac90391379603d962","timestamp":"1785204533160"},"payload_hash":"c5cb28c06510e87b94ce57ca07d707d9800470194f1be6146cd465a21b8bc325","raw_frame":"{\"market\":\"0xda6f0e0e93fc8469e0159a166028d017bddbc162b86f66bac90391379603d962\", \"asset_id\":\"20893381255801015515826997628594359667013752732428989472914000440642900266717\", \"bids\":[{\"price\":\"0.01\", \"size\":\"5682.02\"}, {\"price\":\"0.02\", \"size\":\"732.1\"}, {\"price\":\"0.03\", \"size\":\"662.1\"}, {\"price\":\"0.04\", \"size\":\"662.09\"}, {\"price\":\"0.05\", \"size\":\"867.2\"}, {\"price\":\"0.06\", \"size\":\"597.2\"}, {\"price\":\"0.07\", \"size\":\"120.1\"}, {\"price\":\"0.08\", \"size\":\"94.79\"}, {\"price\":\"0.09\", \"size\":\"95.6\"}, {\"price\":\"0.1\", \"size\":\"211.29\"}, {\"price\":\"0.11\", \"size\":\"87.6\"}, {\"price\":\"0.12\", \"size\":\"94.4\"}, {\"price\":\"0.13\", \"size\":\"111.5\"}, {\"price\":\"0.14\", \"size\":\"78.9\"}, {\"price\":\"0.15\", \"size\":\"131.5\"}, {\"price\":\"0.16\", \"size\":\"115.3\"}, {\"price\":\"0.17\", \"size\":\"74.3\"}, {\"price\":\"0.18\", \"size\":\"77.86\"}, {\"price\":\"0.19\", \"size\":\"101.5\"}, {\"price\":\"0.2\", \"size\":\"110.8\"}, {\"price\":\"0.21\", \"size\":\"70.1\"}, {\"price\":\"0.22\", \"size\":\"98.5\"}, {\"price\":\"0.23\", \"size\":\"67.89\"}, {\"price\":\"0.24\", \"size\":\"67.39\"}, {\"price\":\"0.25\", \"size\":\"125\"}, {\"price\":\"0.26\", \"size\":\"65.6\"}, {\"price\":\"0.27\", \"size\":\"65.2\"}, {\"price\":\"0.28\", \"size\":\"94.9\"}, {\"price\":\"0.29\", \"size\":\"64.6\"}, {\"price\":\"0.3\", \"size\":\"88.3\"}, {\"price\":\"0.31\", \"size\":\"94\"}, {\"price\":\"0.32\", \"size\":\"64.85\"}, {\"price\":\"0.33\", \"size\":\"63.6\"}, {\"price\":\"0.34\", \"size\":\"93.4\"}, {\"price\":\"0.35\", \"size\":\"177.43\"}, {\"price\":\"0.36\", \"size\":\"62\"}, {\"price\":\"0.37\", \"size\":\"91.9\"}, {\"price\":\"0.38\", \"size\":\"61.7\"}, {\"price\":\"0.39\", \"size\":\"61.6\"}, {\"price\":\"0.4\", \"size\":\"96.5\"}, {\"price\":\"0.41\", \"size\":\"67.4\"}, {\"price\":\"0.42\", \"size\":\"171.3\"}, {\"price\":\"0.43\", \"size\":\"242.2\"}, {\"price\":\"0.44\", \"size\":\"169.2\"}, {\"price\":\"0.45\", \"size\":\"239.11\"}, {\"price\":\"0.46\", \"size\":\"253.09\"}, {\"price\":\"0.47\", \"size\":\"326.06\"}, {\"price\":\"0.48\", \"size\":\"217.53\"}, {\"price\":\"0.49\", \"size\":\"246\"}, {\"price\":\"0.5\", \"size\":\"194\"}, {\"price\":\"0.51\", \"size\":\"194\"}, {\"price\":\"0.52\", \"size\":\"237\"}, {\"price\":\"0.53\", \"size\":\"140.95\"}, {\"price\":\"0.54\", \"size\":\"52\"}, {\"price\":\"0.55\", \"size\":\"51\"}, {\"price\":\"0.56\", \"size\":\"22.7\"}], \"asks\":[{\"price\":\"0.99\", \"size\":\"5608.02\"}, {\"price\":\"0.98\", \"size\":\"678.1\"}, {\"price\":\"0.97\", \"size\":\"781.43\"}, {\"price\":\"0.96\", \"size\":\"588.09\"}, {\"price\":\"0.95\", \"size\":\"749.2\"}, {\"price\":\"0.94\", \"size\":\"605.2\"}, {\"price\":\"0.93\", \"size\":\"565.1\"}, {\"price\":\"0.92\", \"size\":\"567.79\"}, {\"price\":\"0.91\", \"size\":\"581.6\"}, {\"price\":\"0.9\", \"size\":\"165.59\"}, {\"price\":\"0.89\", \"size\":\"43.6\"}, {\"price\":\"0.88\", \"size\":\"109.4\"}, {\"price\":\"0.87\", \"size\":\"66.5\"}, {\"price\":\"0.86\", \"size\":\"78.9\"}, {\"price\":\"0.85\", \"size\":\"161.5\"}, {\"price\":\"0.84\", \"size\":\"85.3\"}, {\"price\":\"0.83\", \"size\":\"74.3\"}, {\"price\":\"0.82\", \"size\":\"102.3\"}, {\"price\":\"0.81\", \"size\":\"71.5\"}, {\"price\":\"0.8\", \"size\":\"120.8\"}, {\"price\":\"0.79\", \"size\":\"100.1\"}, {\"price\":\"0.78\", \"size\":\"220.01\"}, {\"price\":\"0.77\", \"size\":\"312.8\"}, {\"price\":\"0.76\", \"size\":\"336.27\"}, {\"price\":\"0.75\", \"size\":\"210\"}, {\"price\":\"0.74\", \"size\":\"183.6\"}, {\"price\":\"0.73\", \"size\":\"219.2\"}, {\"price\":\"0.72\", \"size\":\"187.9\"}, {\"price\":\"0.71\", \"size\":\"217.1\"}, {\"price\":\"0.7\", \"size\":\"231.96\"}, {\"price\":\"0.69\", \"size\":\"175\"}, {\"price\":\"0.68\", \"size\":\"159\"}, {\"price\":\"0.67\", \"size\":\"88\"}, {\"price\":\"0.66\", \"size\":\"99\"}, {\"price\":\"0.65\", \"size\":\"161\"}, {\"price\":\"0.64\", \"size\":\"87\"}, {\"price\":\"0.63\", \"size\":\"79.98\"}, {\"price\":\"0.62\", \"size\":\"64.6\"}, {\"price\":\"0.61\", \"size\":\"117.18\"}, {\"price\":\"0.6\", \"size\":\"91.08\"}, {\"price\":\"0.59\", \"size\":\"90.99\"}, {\"price\":\"0.58\", \"size\":\"56.31\"}, {\"price\":\"0.57\", \"size\":\"75\"}], \"hash\":\"d7591254a2202bc528630be0934bfbaf2f2c025a\", \"timestamp\":\"1785204533160\", \"event_type\":\"book\"}","received_at":"2026-07-28T02:08:53.795917Z","schema_version":"clob-market-ws.book.v1","sequence":null,"server_hash":"d7591254a2202bc528630be0934bfbaf2f2c025a","server_timestamp":"1785204533160","session_id":"d2757dd6dad94f3b9fe67e8dbf1adc37","source":"clob_market_ws"},"received_at":"2026-07-28T02:08:53.795917Z","record_id":"06ae18d36421ffbfad530126fff8467ad80714cf1a1a8cb6f6e2f1195fbee7f4","schema_fingerprint":"dc2caa1c89c6a7426e2e07ff925910cd4d0a8a223a515d4092d91d6d127aacb6","schema_version":"edge-lab-recorder.raw.v1","sequence":null,"source":"clob_market_ws"}
{"event_at":"2026-07-28T02:08:53.160000Z","event_fingerprint":"5afafcaee47b4ac113797c825e6bc9dfd9a01533a8169bc3620bc6c847a70f3d","payload":{"connection_id":"5d29200f65794d4d9ab6ef271f045a9b","event_at":"2026-07-28T02:08:53.160000Z","event_type":"book","frame_hash":"0cbee62acb18577a44d9a79132e7652baa567a5eb1289c4c9d6e5751d0f74a42","frame_index":0,"kind":"data","monotonic_ns":306516815496833,"payload":{"asks":[{"price":"0.99","size":"5682.02"},{"price":"0.98","size":"732.1"},{"price":"0.97","size":"662.1"},{"price":"0.96","size":"662.09"},{"price":"0.95","size":"867.2"},{"price":"0.94","size":"597.2"},{"price":"0.93","size":"120.1"},{"price":"0.92","size":"94.79"},{"price":"0.91","size":"95.6"},{"price":"0.9","size":"211.29"},{"price":"0.89","size":"87.6"},{"price":"0.88","size":"94.4"},{"price":"0.87","size":"111.5"},{"price":"0.86","size":"78.9"},{"price":"0.85","size":"131.5"},{"price":"0.84","size":"115.3"},{"price":"0.83","size":"74.3"},{"price":"0.82","size":"77.86"},{"price":"0.81","size":"101.5"},{"price":"0.8","size":"110.8"},{"price":"0.79","size":"70.1"},{"price":"0.78","size":"98.5"},{"price":"0.77","size":"67.89"},{"price":"0.76","size":"67.39"},{"price":"0.75","size":"125"},{"price":"0.74","size":"65.6"},{"price":"0.73","size":"65.2"},{"price":"0.72","size":"94.9"},{"price":"0.71","size":"64.6"},{"price":"0.7","size":"88.3"},{"price":"0.69","size":"94"},{"price":"0.68","size":"64.85"},{"price":"0.67","size":"63.6"},{"price":"0.66","size":"93.4"},{"price":"0.65","size":"177.43"},{"price":"0.64","size":"62"},{"price":"0.63","size":"91.9"},{"price":"0.62","size":"61.7"},{"price":"0.61","size":"61.6"},{"price":"0.6","size":"96.5"},{"price":"0.59","size":"67.4"},{"price":"0.58","size":"171.3"},{"price":"0.57","size":"242.2"},{"price":"0.56","size":"169.2"},{"price":"0.55","size":"239.11"},{"price":"0.54","size":"253.09"},{"price":"0.53","size":"326.06"},{"price":"0.52","size":"217.53"},{"price":"0.51","size":"246"},{"price":"0.5","size":"194"},{"price":"0.49","size":"194"},{"price":"0.48","size":"237"},{"price":"0.47","size":"140.95"},{"price":"0.46","size":"52"},{"price":"0.45","size":"51"},{"price":"0.44","size":"22.7"}],"asset_id":"39272994714739463168905443499424551362424437245880253267329605556587274644733","bids":[{"price":"0.01","size":"5608.02"},{"price":"0.02","size":"678.1"},{"price":"0.03","size":"781.43"},{"price":"0.04","size":"588.09"},{"price":"0.05","size":"749.2"},{"price":"0.06","size":"605.2"},{"price":"0.07","size":"565.1"},{"price":"0.08","size":"567.79"},{"price":"0.09","size":"581.6"},{"price":"0.1","size":"165.59"},{"price":"0.11","size":"43.6"},{"price":"0.12","size":"109.4"},{"price":"0.13","size":"66.5"},{"price":"0.14","size":"78.9"},{"price":"0.15","size":"161.5"},{"price":"0.16","size":"85.3"},{"price":"0.17","size":"74.3"},{"price":"0.18","size":"102.3"},{"price":"0.19","size":"71.5"},{"price":"0.2","size":"120.8"},{"price":"0.21","size":"100.1"},{"price":"0.22","size":"220.01"},{"price":"0.23","size":"312.8"},{"price":"0.24","size":"336.27"},{"price":"0.25","size":"210"},{"price":"0.26","size":"183.6"},{"price":"0.27","size":"219.2"},{"price":"0.28","size":"187.9"},{"price":"0.29","size":"217.1"},{"price":"0.3","size":"231.96"},{"price":"0.31","size":"175"},{"price":"0.32","size":"159"},{"price":"0.33","size":"88"},{"price":"0.34","size":"99"},{"price":"0.35","size":"161"},{"price":"0.36","size":"87"},{"price":"0.37","size":"79.98"},{"price":"0.38","size":"64.6"},{"price":"0.39","size":"117.18"},{"price":"0.4","size":"91.08"},{"price":"0.41","size":"90.99"},{"price":"0.42","size":"56.31"},{"price":"0.43","size":"75"}],"event_type":"book","hash":"abd9d55ad8cd1541be08f4b2acdaa9f0fc1203d5","market":"0xda6f0e0e93fc8469e0159a166028d017bddbc162b86f66bac90391379603d962","timestamp":"1785204533160"},"payload_hash":"e82284f6d535af2a389fe2a4f7be17931f65f190a2357cd5a6befc697acaea26","raw_frame":"{\"market\":\"0xda6f0e0e93fc8469e0159a166028d017bddbc162b86f66bac90391379603d962\", \"asset_id\":\"39272994714739463168905443499424551362424437245880253267329605556587274644733\", \"bids\":[{\"price\":\"0.01\", \"size\":\"5608.02\"}, {\"price\":\"0.02\", \"size\":\"678.1\"}, {\"price\":\"0.03\", \"size\":\"781.43\"}, {\"price\":\"0.04\", \"size\":\"588.09\"}, {\"price\":\"0.05\", \"size\":\"749.2\"}, {\"price\":\"0.06\", \"size\":\"605.2\"}, {\"price\":\"0.07\", \"size\":\"565.1\"}, {\"price\":\"0.08\", \"size\":\"567.79\"}, {\"price\":\"0.09\", \"size\":\"581.6\"}, {\"price\":\"0.1\", \"size\":\"165.59\"}, {\"price\":\"0.11\", \"size\":\"43.6\"}, {\"price\":\"0.12\", \"size\":\"109.4\"}, {\"price\":\"0.13\", \"size\":\"66.5\"}, {\"price\":\"0.14\", \"size\":\"78.9\"}, {\"price\":\"0.15\", \"size\":\"161.5\"}, {\"price\":\"0.16\", \"size\":\"85.3\"}, {\"price\":\"0.17\", \"size\":\"74.3\"}, {\"price\":\"0.18\", \"size\":\"102.3\"}, {\"price\":\"0.19\", \"size\":\"71.5\"}, {\"price\":\"0.2\", \"size\":\"120.8\"}, {\"price\":\"0.21\", \"size\":\"100.1\"}, {\"price\":\"0.22\", \"size\":\"220.01\"}, {\"price\":\"0.23\", \"size\":\"312.8\"}, {\"price\":\"0.24\", \"size\":\"336.27\"}, {\"price\":\"0.25\", \"size\":\"210\"}, {\"price\":\"0.26\", \"size\":\"183.6\"}, {\"price\":\"0.27\", \"size\":\"219.2\"}, {\"price\":\"0.28\", \"size\":\"187.9\"}, {\"price\":\"0.29\", \"size\":\"217.1\"}, {\"price\":\"0.3\", \"size\":\"231.96\"}, {\"price\":\"0.31\", \"size\":\"175\"}, {\"price\":\"0.32\", \"size\":\"159\"}, {\"price\":\"0.33\", \"size\":\"88\"}, {\"price\":\"0.34\", \"size\":\"99\"}, {\"price\":\"0.35\", \"size\":\"161\"}, {\"price\":\"0.36\", \"size\":\"87\"}, {\"price\":\"0.37\", \"size\":\"79.98\"}, {\"price\":\"0.38\", \"size\":\"64.6\"}, {\"price\":\"0.39\", \"size\":\"117.18\"}, {\"price\":\"0.4\", \"size\":\"91.08\"}, {\"price\":\"0.41\", \"size\":\"90.99\"}, {\"price\":\"0.42\", \"size\":\"56.31\"}, {\"price\":\"0.43\", \"size\":\"75\"}], \"asks\":[{\"price\":\"0.99\", \"size\":\"5682.02\"}, {\"price\":\"0.98\", \"size\":\"732.1\"}, {\"price\":\"0.97\", \"size\":\"662.1\"}, {\"price\":\"0.96\", \"size\":\"662.09\"}, {\"price\":\"0.95\", \"size\":\"867.2\"}, {\"price\":\"0.94\", \"size\":\"597.2\"}, {\"price\":\"0.93\", \"size\":\"120.1\"}, {\"price\":\"0.92\", \"size\":\"94.79\"}, {\"price\":\"0.91\", \"size\":\"95.6\"}, {\"price\":\"0.9\", \"size\":\"211.29\"}, {\"price\":\"0.89\", \"size\":\"87.6\"}, {\"price\":\"0.88\", \"size\":\"94.4\"}, {\"price\":\"0.87\", \"size\":\"111.5\"}, {\"price\":\"0.86\", \"size\":\"78.9\"}, {\"price\":\"0.85\", \"size\":\"131.5\"}, {\"price\":\"0.84\", \"size\":\"115.3\"}, {\"price\":\"0.83\", \"size\":\"74.3\"}, {\"price\":\"0.82\", \"size\":\"77.86\"}, {\"price\":\"0.81\", \"size\":\"101.5\"}, {\"price\":\"0.8\", \"size\":\"110.8\"}, {\"price\":\"0.79\", \"size\":\"70.1\"}, {\"price\":\"0.78\", \"size\":\"98.5\"}, {\"price\":\"0.77\", \"size\":\"67.89\"}, {\"price\":\"0.76\", \"size\":\"67.39\"}, {\"price\":\"0.75\", \"size\":\"125\"}, {\"price\":\"0.74\", \"size\":\"65.6\"}, {\"price\":\"0.73\", \"size\":\"65.2\"}, {\"price\":\"0.72\", \"size\":\"94.9\"}, {\"price\":\"0.71\", \"size\":\"64.6\"}, {\"price\":\"0.7\", \"size\":\"88.3\"}, {\"price\":\"0.69\", \"size\":\"94\"}, {\"price\":\"0.68\", \"size\":\"64.85\"}, {\"price\":\"0.67\", \"size\":\"63.6\"}, {\"price\":\"0.66\", \"size\":\"93.4\"}, {\"price\":\"0.65\", \"size\":\"177.43\"}, {\"price\":\"0.64\", \"size\":\"62\"}, {\"price\":\"0.63\", \"size\":\"91.9\"}, {\"price\":\"0.62\", \"size\":\"61.7\"}, {\"price\":\"0.61\", \"size\":\"61.6\"}, {\"price\":\"0.6\", \"size\":\"96.5\"}, {\"price\":\"0.59\", \"size\":\"67.4\"}, {\"price\":\"0.58\", \"size\":\"171.3\"}, {\"price\":\"0.57\", \"size\":\"242.2\"}, {\"price\":\"0.56\", \"size\":\"169.2\"}, {\"price\":\"0.55\", \"size\":\"239.11\"}, {\"price\":\"0.54\", \"size\":\"253.09\"}, {\"price\":\"0.53\", \"size\":\"326.06\"}, {\"price\":\"0.52\", \"size\":\"217.53\"}, {\"price\":\"0.51\", \"size\":\"246\"}, {\"price\":\"0.5\", \"size\":\"194\"}, {\"price\":\"0.49\", \"size\":\"194\"}, {\"price\":\"0.48\", \"size\":\"237\"}, {\"price\":\"0.47\", \"size\":\"140.95\"}, {\"price\":\"0.46\", \"size\":\"52\"}, {\"price\":\"0.45\", \"size\":\"51\"}, {\"price\":\"0.44\", \"size\":\"22.7\"}], \"hash\":\"abd9d55ad8cd1541be08f4b2acdaa9f0fc1203d5\", \"timestamp\":\"1785204533160\", \"event_type\":\"book\"}","received_at":"2026-07-28T02:08:53.807158Z","schema_version":"clob-market-ws.book.v1","sequence":null,"server_hash":"abd9d55ad8cd1541be08f4b2acdaa9f0fc1203d5","server_timestamp":"1785204533160","session_id":"d2757dd6dad94f3b9fe67e8dbf1adc37","source":"clob_market_ws"},"received_at":"2026-07-28T02:08:53.807158Z","record_id":"23c036ad1399ae8d27a0cd86b2329212136a0fc9438df0128660fed72679247b","schema_fingerprint":"dc2caa1c89c6a7426e2e07ff925910cd4d0a8a223a515d4092d91d6d127aacb6","schema_version":"edge-lab-recorder.raw.v1","sequence":null,"source":"clob_market_ws"}
{"event_at":"2026-07-28T02:08:53.174000Z","event_fingerprint":"1ccc896dfc149ed5705ac1b3192c438f4af7bcdbf09ab72c5cb7d6326b20ae98","payload":{"connection_id":"5d29200f65794d4d9ab6ef271f045a9b","event_at":"2026-07-28T02:08:53.174000Z","event_type":"best_bid_ask","frame_hash":"c46753ec2202efab8183760020c9697115e782c2de3ffba5724fefb3b0520b40","frame_index":0,"kind":"data","monotonic_ns":306516833942625,"payload":{"asset_id":"20893381255801015515826997628594359667013752732428989472914000440642900266717","best_ask":"0.57","best_bid":"0.56","event_type":"best_bid_ask","market":"0xda6f0e0e93fc8469e0159a166028d017bddbc162b86f66bac90391379603d962","spread":"0.01","timestamp":"1785204533174"},"payload_hash":"7381b6324daad79fe522cdfa2b0b2f6eec01e398483513ce20990d152271130f","raw_frame":"{\"market\":\"0xda6f0e0e93fc8469e0159a166028d017bddbc162b86f66bac90391379603d962\", \"asset_id\":\"20893381255801015515826997628594359667013752732428989472914000440642900266717\", \"best_bid\":\"0.56\", \"best_ask\":\"0.57\", \"spread\":\"0.01\", \"timestamp\":\"1785204533174\", \"event_type\":\"best_bid_ask\"}","received_at":"2026-07-28T02:08:53.825603Z","schema_version":"clob-market-ws.best_bid_ask.v1","sequence":null,"server_hash":null,"server_timestamp":"1785204533174","session_id":"d2757dd6dad94f3b9fe67e8dbf1adc37","source":"clob_market_ws"},"received_at":"2026-07-28T02:08:53.825603Z","record_id":"81a52e87803978eb6edefdc4cbbad7ca9490fb53b21b2f57b94815bdb44f6c82","schema_fingerprint":"8488399f31b0337811b13b266be932db7062827c2470b78bd8e9e99bab51d17d","schema_version":"edge-lab-recorder.raw.v1","sequence":null,"source":"clob_market_ws"}
{"event_at":"2026-07-28T02:08:53.174000Z","event_fingerprint":"ce4feb2966ea021b7fe9b6a64dc68573327c4767ffe4c4542bd561fd9f1bc1d3","payload":{"connection_id":"5d29200f65794d4d9ab6ef271f045a9b","event_at":"2026-07-28T02:08:53.174000Z","event_type":"best_bid_ask","frame_hash":"518787cc5fb56f3023fb5d07c4d375ca81b5c2fc4d844fbc8236fec6d340b36e","frame_index":0,"kind":"data","monotonic_ns":306516836083541,"payload":{"asset_id":"39272994714739463168905443499424551362424437245880253267329605556587274644733","best_ask":"0.44","best_bid":"0.43","event_type":"best_bid_ask","market":"0xda6f0e0e93fc8469e0159a166028d017bddbc162b86f66bac90391379603d962","spread":"0.01","timestamp":"1785204533174"},"payload_hash":"78132376adc839ca07546f1a39f5a489cfc5870f03f3c10d9e2624d1aeeb5c7c","raw_frame":"{\"market\":\"0xda6f0e0e93fc8469e0159a166028d017bddbc162b86f66bac90391379603d962\", \"asset_id\":\"39272994714739463168905443499424551362424437245880253267329605556587274644733\", \"best_bid\":\"0.43\", \"best_ask\":\"0.44\", \"spread\":\"0.01\", \"timestamp\":\"1785204533174\", \"event_type\":\"best_bid_ask\"}","received_at":"2026-07-28T02:08:53.827745Z","schema_version":"clob-market-ws.best_bid_ask.v1","sequence":null,"server_hash":null,"server_timestamp":"1785204533174","session_id":"d2757dd6dad94f3b9fe67e8dbf1adc37","source":"clob_market_ws"},"received_at":"2026-07-28T02:08:53.827745Z","record_id":"1e3a5a0a4c53f2bedddddb472459c8a4ac16fe9ec19de16ed6d5b90ddb7abc00","schema_fingerprint":"8488399f31b0337811b13b266be932db7062827c2470b78bd8e9e99bab51d17d","schema_version":"edge-lab-recorder.raw.v1","sequence":null,"source":"clob_market_ws"}
{"event_at":"2026-07-28T02:08:53.174000Z","event_fingerprint":"9bfd6605be818c46561f32023ef144a00e053cd13d7507a180205f74aef93bd0","payload":{"connection_id":"5d29200f65794d4d9ab6ef271f045a9b","event_at":"2026-07-28T02:08:53.174000Z","event_type":"price_change","frame_hash":"71f14dc249219bec93eb721d50ec4402d5b29dc98b4012b88f9c429d0996e3ec","frame_index":0,"kind":"data","monotonic_ns":306516842934375,"payload":{"event_type":"price_change","market":"0xda6f0e0e93fc8469e0159a166028d017bddbc162b86f66bac90391379603d962","price_changes":[{"asset_id":"20893381255801015515826997628594359667013752732428989472914000440642900266717","best_ask":"0.57","best_bid":"0.56","hash":"7962b6c2f0e955a9d737628c1642369a404e46b3","price":"0.56","side":"BUY","size":"22.68"},{"asset_id":"39272994714739463168905443499424551362424437245880253267329605556587274644733","best_ask":"0.44","best_bid":"0.43","hash":"b91b33a8ea67e4d732c02709be3c150cc9790bb2","price":"0.44","side":"SELL","size":"22.68"}],"timestamp":"1785204533174"},"payload_hash":"78ab1bc2267008bc399bd573f48a37e1e1dae6fe099ebba060d540a013de80bc","raw_frame":"{\"market\":\"0xda6f0e0e93fc8469e0159a166028d017bddbc162b86f66bac90391379603d962\", \"price_changes\":[{\"asset_id\":\"20893381255801015515826997628594359667013752732428989472914000440642900266717\", \"price\":\"0.56\", \"size\":\"22.68\", \"side\":\"BUY\", \"hash\":\"7962b6c2f0e955a9d737628c1642369a404e46b3\", \"best_bid\":\"0.56\", \"best_ask\":\"0.57\"}, {\"asset_id\":\"39272994714739463168905443499424551362424437245880253267329605556587274644733\", \"price\":\"0.44\", \"size\":\"22.68\", \"side\":\"SELL\", \"hash\":\"b91b33a8ea67e4d732c02709be3c150cc9790bb2\", \"best_bid\":\"0.43\", \"best_ask\":\"0.44\"}], \"timestamp\":\"1785204533174\", \"event_type\":\"price_change\"}","received_at":"2026-07-28T02:08:53.834594Z","schema_version":"clob-market-ws.price_change.v1","sequence":null,"server_hash":null,"server_timestamp":"1785204533174","session_id":"d2757dd6dad94f3b9fe67e8dbf1adc37","source":"clob_market_ws"},"received_at":"2026-07-28T02:08:53.834594Z","record_id":"7af61be52265aa01a290cc61f8d1039dd7d79e62b0ab028956e89d9fb4da59ca","schema_fingerprint":"4aa3821a28b0b7c2400bc59aba4bcc0a76e971dadd19610d3ad38c768e124dc7","schema_version":"edge-lab-recorder.raw.v1","sequence":null,"source":"clob_market_ws"}
{"event_at":"2026-07-28T02:08:53.174000Z","event_fingerprint":"298893e7949bc370be95dc59652383113a5a34140b9ff9ae2be9167f6cbe9a92","payload":{"connection_id":"5d29200f65794d4d9ab6ef271f045a9b","event_at":"2026-07-28T02:08:53.174000Z","event_type":"book","frame_hash":"4831ab544b706c79d56eb3e966f8cf33ffdefef0f3713563060c9fd1ac352a6e","frame_index":0,"kind":"data","monotonic_ns":306516848267500,"payload":{"asks":[{"price":"0.99","size":"5608.02"},{"price":"0.98","size":"678.1"},{"price":"0.97","size":"781.43"},{"price":"0.96","size":"588.09"},{"price":"0.95","size":"749.2"},{"price":"0.94","size":"605.2"},{"price":"0.93","size":"565.1"},{"price":"0.92","size":"567.79"},{"price":"0.91","size":"581.6"},{"price":"0.9","size":"165.59"},{"price":"0.89","size":"43.6"},{"price":"0.88","size":"109.4"},{"price":"0.87","size":"66.5"},{"price":"0.86","size":"78.9"},{"price":"0.85","size":"161.5"},{"price":"0.84","size":"85.3"},{"price":"0.83","size":"74.3"},{"price":"0.82","size":"102.3"},{"price":"0.81","size":"71.5"},{"price":"0.8","size":"120.8"},{"price":"0.79","size":"100.1"},{"price":"0.78","size":"220.01"},{"price":"0.77","size":"312.8"},{"price":"0.76","size":"336.27"},{"price":"0.75","size":"210"},{"price":"0.74","size":"183.6"},{"price":"0.73","size":"219.2"},{"price":"0.72","size":"187.9"},{"price":"0.71","size":"217.1"},{"price":"0.7","size":"231.96"},{"price":"0.69","size":"175"},{"price":"0.68","size":"159"},{"price":"0.67","size":"88"},{"price":"0.66","size":"99"},{"price":"0.65","size":"161"},{"price":"0.64","size":"87"},{"price":"0.63","size":"79.98"},{"price":"0.62","size":"64.6"},{"price":"0.61","size":"117.18"},{"price":"0.6","size":"91.08"},{"price":"0.59","size":"90.99"},{"price":"0.58","size":"56.31"},{"price":"0.57","size":"75"}],"asset_id":"20893381255801015515826997628594359667013752732428989472914000440642900266717","bids":[{"price":"0.01","size":"5682.02"},{"price":"0.02","size":"732.1"},{"price":"0.03","size":"662.1"},{"price":"0.04","size":"662.09"},{"price":"0.05","size":"867.2"},{"price":"0.06","size":"597.2"},{"price":"0.07","size":"120.1"},{"price":"0.08","size":"94.79"},{"price":"0.09","size":"95.6"},{"price":"0.1","size":"211.29"},{"price":"0.11","size":"87.6"},{"price":"0.12","size":"94.4"},{"price":"0.13","size":"111.5"},{"price":"0.14","size":"78.9"},{"price":"0.15","size":"131.5"},{"price":"0.16","size":"115.3"},{"price":"0.17","size":"74.3"},{"price":"0.18","size":"77.86"},{"price":"0.19","size":"101.5"},{"price":"0.2","size":"110.8"},{"price":"0.21","size":"70.1"},{"price":"0.22","size":"98.5"},{"price":"0.23","size":"67.89"},{"price":"0.24","size":"67.39"},{"price":"0.25","size":"125"},{"price":"0.26","size":"65.6"},{"price":"0.27","size":"65.2"},{"price":"0.28","size":"94.9"},{"price":"0.29","size":"64.6"},{"price":"0.3","size":"88.3"},{"price":"0.31","size":"94"},{"price":"0.32","size":"64.85"},{"price":"0.33","size":"63.6"},{"price":"0.34","size":"93.4"},{"price":"0.35","size":"177.43"},{"price":"0.36","size":"62"},{"price":"0.37","size":"91.9"},{"price":"0.38","size":"61.7"},{"price":"0.39","size":"61.6"},{"price":"0.4","size":"96.5"},{"price":"0.41","size":"67.4"},{"price":"0.42","size":"171.3"},{"price":"0.43","size":"242.2"},{"price":"0.44","size":"169.2"},{"price":"0.45","size":"239.11"},{"price":"0.46","size":"253.09"},{"price":"0.47","size":"326.06"},{"price":"0.48","size":"217.53"},{"price":"0.49","size":"246"},{"price":"0.5","size":"194"},{"price":"0.51","size":"194"},{"price":"0.52","size":"237"},{"price":"0.53","size":"140.95"},{"price":"0.54","size":"52"},{"price":"0.55","size":"51"},{"price":"0.56","size":"22.68"}],"event_type":"book","hash":"7962b6c2f0e955a9d737628c1642369a404e46b3","market":"0xda6f0e0e93fc8469e0159a166028d017bddbc162b86f66bac90391379603d962","timestamp":"1785204533174"},"payload_hash":"e3b1782b964e67c40412888b910971b7203cd9be92e9d19f9699ddc16a321930","raw_frame":"{\"market\":\"0xda6f0e0e93fc8469e0159a166028d017bddbc162b86f66bac90391379603d962\", \"asset_id\":\"20893381255801015515826997628594359667013752732428989472914000440642900266717\", \"bids\":[{\"price\":\"0.01\", \"size\":\"5682.02\"}, {\"price\":\"0.02\", \"size\":\"732.1\"}, {\"price\":\"0.03\", \"size\":\"662.1\"}, {\"price\":\"0.04\", \"size\":\"662.09\"}, {\"price\":\"0.05\", \"size\":\"867.2\"}, {\"price\":\"0.06\", \"size\":\"597.2\"}, {\"price\":\"0.07\", \"size\":\"120.1\"}, {\"price\":\"0.08\", \"size\":\"94.79\"}, {\"price\":\"0.09\", \"size\":\"95.6\"}, {\"price\":\"0.1\", \"size\":\"211.29\"}, {\"price\":\"0.11\", \"size\":\"87.6\"}, {\"price\":\"0.12\", \"size\":\"94.4\"}, {\"price\":\"0.13\", \"size\":\"111.5\"}, {\"price\":\"0.14\", \"size\":\"78.9\"}, {\"price\":\"0.15\", \"size\":\"131.5\"}, {\"price\":\"0.16\", \"size\":\"115.3\"}, {\"price\":\"0.17\", \"size\":\"74.3\"}, {\"price\":\"0.18\", \"size\":\"77.86\"}, {\"price\":\"0.19\", \"size\":\"101.5\"}, {\"price\":\"0.2\", \"size\":\"110.8\"}, {\"price\":\"0.21\", \"size\":\"70.1\"}, {\"price\":\"0.22\", \"size\":\"98.5\"}, {\"price\":\"0.23\", \"size\":\"67.89\"}, {\"price\":\"0.24\", \"size\":\"67.39\"}, {\"price\":\"0.25\", \"size\":\"125\"}, {\"price\":\"0.26\", \"size\":\"65.6\"}, {\"price\":\"0.27\", \"size\":\"65.2\"}, {\"price\":\"0.28\", \"size\":\"94.9\"}, {\"price\":\"0.29\", \"size\":\"64.6\"}, {\"price\":\"0.3\", \"size\":\"88.3\"}, {\"price\":\"0.31\", \"size\":\"94\"}, {\"price\":\"0.32\", \"size\":\"64.85\"}, {\"price\":\"0.33\", \"size\":\"63.6\"}, {\"price\":\"0.34\", \"size\":\"93.4\"}, {\"price\":\"0.35\", \"size\":\"177.43\"}, {\"price\":\"0.36\", \"size\":\"62\"}, {\"price\":\"0.37\", \"size\":\"91.9\"}, {\"price\":\"0.38\", \"size\":\"61.7\"}, {\"price\":\"0.39\", \"size\":\"61.6\"}, {\"price\":\"0.4\", \"size\":\"96.5\"}, {\"price\":\"0.41\", \"size\":\"67.4\"}, {\"price\":\"0.42\", \"size\":\"171.3\"}, {\"price\":\"0.43\", \"size\":\"242.2\"}, {\"price\":\"0.44\", \"size\":\"169.2\"}, {\"price\":\"0.45\", \"size\":\"239.11\"}, {\"price\":\"0.46\", \"size\":\"253.09\"}, {\"price\":\"0.47\", \"size\":\"326.06\"}, {\"price\":\"0.48\", \"size\":\"217.53\"}, {\"price\":\"0.49\", \"size\":\"246\"}, {\"price\":\"0.5\", \"size\":\"194\"}, {\"price\":\"0.51\", \"size\":\"194\"}, {\"price\":\"0.52\", \"size\":\"237\"}, {\"price\":\"0.53\", \"size\":\"140.95\"}, {\"price\":\"0.54\", \"size\":\"52\"}, {\"price\":\"0.55\", \"size\":\"51\"}, {\"price\":\"0.56\", \"size\":\"22.68\"}], \"asks\":[{\"price\":\"0.99\", \"size\":\"5608.02\"}, {\"price\":\"0.98\", \"size\":\"678.1\"}, {\"price\":\"0.97\", \"size\":\"781.43\"}, {\"price\":\"0.96\", \"size\":\"588.09\"}, {\"price\":\"0.95\", \"size\":\"749.2\"}, {\"price\":\"0.94\", \"size\":\"605.2\"}, {\"price\":\"0.93\", \"size\":\"565.1\"}, {\"price\":\"0.92\", \"size\":\"567.79\"}, {\"price\":\"0.91\", \"size\":\"581.6\"}, {\"price\":\"0.9\", \"size\":\"165.59\"}, {\"price\":\"0.89\", \"size\":\"43.6\"}, {\"price\":\"0.88\", \"size\":\"109.4\"}, {\"price\":\"0.87\", \"size\":\"66.5\"}, {\"price\":\"0.86\", \"size\":\"78.9\"}, {\"price\":\"0.85\", \"size\":\"161.5\"}, {\"price\":\"0.84\", \"size\":\"85.3\"}, {\"price\":\"0.83\", \"size\":\"74.3\"}, {\"price\":\"0.82\", \"size\":\"102.3\"}, {\"price\":\"0.81\", \"size\":\"71.5\"}, {\"price\":\"0.8\", \"size\":\"120.8\"}, {\"price\":\"0.79\", \"size\":\"100.1\"}, {\"price\":\"0.78\", \"size\":\"220.01\"}, {\"price\":\"0.77\", \"size\":\"312.8\"}, {\"price\":\"0.76\", \"size\":\"336.27\"}, {\"price\":\"0.75\", \"size\":\"210\"}, {\"price\":\"0.74\", \"size\":\"183.6\"}, {\"price\":\"0.73\", \"size\":\"219.2\"}, {\"price\":\"0.72\", \"size\":\"187.9\"}, {\"price\":\"0.71\", \"size\":\"217.1\"}, {\"price\":\"0.7\", \"size\":\"231.96\"}, {\"price\":\"0.69\", \"size\":\"175\"}, {\"price\":\"0.68\", \"size\":\"159\"}, {\"price\":\"0.67\", \"size\":\"88\"}, {\"price\":\"0.66\", \"size\":\"99\"}, {\"price\":\"0.65\", \"size\":\"161\"}, {\"price\":\"0.64\", \"size\":\"87\"}, {\"price\":\"0.63\", \"size\":\"79.98\"}, {\"price\":\"0.62\", \"size\":\"64.6\"}, {\"price\":\"0.61\", \"size\":\"117.18\"}, {\"price\":\"0.6\", \"size\":\"91.08\"}, {\"price\":\"0.59\", \"size\":\"90.99\"}, {\"price\":\"0.58\", \"size\":\"56.31\"}, {\"price\":\"0.57\", \"size\":\"75\"}], \"hash\":\"7962b6c2f0e955a9d737628c1642369a404e46b3\", \"timestamp\":\"1785204533174\", \"event_type\":\"book\"}","received_at":"2026-07-28T02:08:53.839929Z","schema_version":"clob-market-ws.book.v1","sequence":null,"server_hash":"7962b6c2f0e955a9d737628c1642369a404e46b3","server_timestamp":"1785204533174","session_id":"d2757dd6dad94f3b9fe67e8dbf1adc37","source":"clob_market_ws"},"received_at":"2026-07-28T02:08:53.839929Z","record_id":"33905ffc1bf1c07e1c70b865892ea3a9aebeed89c7d2098433427b66632f32bf","schema_fingerprint":"dc2caa1c89c6a7426e2e07ff925910cd4d0a8a223a515d4092d91d6d127aacb6","schema_version":"edge-lab-recorder.raw.v1","sequence":null,"source":"clob_market_ws"}
{"event_at":"2026-07-28T02:08:53.174000Z","event_fingerprint":"55d96c1312507efe06621ae492bbc1b6ef84771804ac1e0b00c5b90dc91e31c4","payload":{"connection_id":"5d29200f65794d4d9ab6ef271f045a9b","event_at":"2026-07-28T02:08:53.174000Z","event_type":"book","frame_hash":"36a376521b93d706b44ac5fd053e7f1b1f9a4e292f27463ac91bfb89b028e022","frame_index":0,"kind":"data","monotonic_ns":306516859621041,"payload":{"asks":[{"price":"0.99","size":"5682.02"},{"price":"0.98","size":"732.1"},{"price":"0.97","size":"662.1"},{"price":"0.96","size":"662.09"},{"price":"0.95","size":"867.2"},{"price":"0.94","size":"597.2"},{"price":"0.93","size":"120.1"},{"price":"0.92","size":"94.79"},{"price":"0.91","size":"95.6"},{"price":"0.9","size":"211.29"},{"price":"0.89","size":"87.6"},{"price":"0.88","size":"94.4"},{"price":"0.87","size":"111.5"},{"price":"0.86","size":"78.9"},{"price":"0.85","size":"131.5"},{"price":"0.84","size":"115.3"},{"price":"0.83","size":"74.3"},{"price":"0.82","size":"77.86"},{"price":"0.81","size":"101.5"},{"price":"0.8","size":"110.8"},{"price":"0.79","size":"70.1"},{"price":"0.78","size":"98.5"},{"price":"0.77","size":"67.89"},{"price":"0.76","size":"67.39"},{"price":"0.75","size":"125"},{"price":"0.74","size":"65.6"},{"price":"0.73","size":"65.2"},{"price":"0.72","size":"94.9"},{"price":"0.71","size":"64.6"},{"price":"0.7","size":"88.3"},{"price":"0.69","size":"94"},{"price":"0.68","size":"64.85"},{"price":"0.67","size":"63.6"},{"price":"0.66","size":"93.4"},{"price":"0.65","size":"177.43"},{"price":"0.64","size":"62"},{"price":"0.63","size":"91.9"},{"price":"0.62","size":"61.7"},{"price":"0.61","size":"61.6"},{"price":"0.6","size":"96.5"},{"price":"0.59","size":"67.4"},{"price":"0.58","size":"171.3"},{"price":"0.57","size":"242.2"},{"price":"0.56","size":"169.2"},{"price":"0.55","size":"239.11"},{"price":"0.54","size":"253.09"},{"price":"0.53","size":"326.06"},{"price":"0.52","size":"217.53"},{"price":"0.51","size":"246"},{"price":"0.5","size":"194"},{"price":"0.49","size":"194"},{"price":"0.48","size":"237"},{"price":"0.47","size":"140.95"},{"price":"0.46","size":"52"},{"price":"0.45","size":"51"},{"price":"0.44","size":"22.68"}],"asset_id":"39272994714739463168905443499424551362424437245880253267329605556587274644733","bids":[{"price":"0.01","size":"5608.02"},{"price":"0.02","size":"678.1"},{"price":"0.03","size":"781.43"},{"price":"0.04","size":"588.09"},{"price":"0.05","size":"749.2"},{"price":"0.06","size":"605.2"},{"price":"0.07","size":"565.1"},{"price":"0.08","size":"567.79"},{"price":"0.09","size":"581.6"},{"price":"0.1","size":"165.59"},{"price":"0.11","size":"43.6"},{"price":"0.12","size":"109.4"},{"price":"0.13","size":"66.5"},{"price":"0.14","size":"78.9"},{"price":"0.15","size":"161.5"},{"price":"0.16","size":"85.3"},{"price":"0.17","size":"74.3"},{"price":"0.18","size":"102.3"},{"price":"0.19","size":"71.5"},{"price":"0.2","size":"120.8"},{"price":"0.21","size":"100.1"},{"price":"0.22","size":"220.01"},{"price":"0.23","size":"312.8"},{"price":"0.24","size":"336.27"},{"price":"0.25","size":"210"},{"price":"0.26","size":"183.6"},{"price":"0.27","size":"219.2"},{"price":"0.28","size":"187.9"},{"price":"0.29","size":"217.1"},{"price":"0.3","size":"231.96"},{"price":"0.31","size":"175"},{"price":"0.32","size":"159"},{"price":"0.33","size":"88"},{"price":"0.34","size":"99"},{"price":"0.35","size":"161"},{"price":"0.36","size":"87"},{"price":"0.37","size":"79.98"},{"price":"0.38","size":"64.6"},{"price":"0.39","size":"117.18"},{"price":"0.4","size":"91.08"},{"price":"0.41","size":"90.99"},{"price":"0.42","size":"56.31"},{"price":"0.43","size":"75"}],"event_type":"book","hash":"b91b33a8ea67e4d732c02709be3c150cc9790bb2","market":"0xda6f0e0e93fc8469e0159a166028d017bddbc162b86f66bac90391379603d962","timestamp":"1785204533174"},"payload_hash":"b35083897b657c810940185e83dd3f456cf843d544f9270e3c406b9a982d7eb6","raw_frame":"{\"market\":\"0xda6f0e0e93fc8469e0159a166028d017bddbc162b86f66bac90391379603d962\", \"asset_id\":\"39272994714739463168905443499424551362424437245880253267329605556587274644733\", \"bids\":[{\"price\":\"0.01\", \"size\":\"5608.02\"}, {\"price\":\"0.02\", \"size\":\"678.1\"}, {\"price\":\"0.03\", \"size\":\"781.43\"}, {\"price\":\"0.04\", \"size\":\"588.09\"}, {\"price\":\"0.05\", \"size\":\"749.2\"}, {\"price\":\"0.06\", \"size\":\"605.2\"}, {\"price\":\"0.07\", \"size\":\"565.1\"}, {\"price\":\"0.08\", \"size\":\"567.79\"}, {\"price\":\"0.09\", \"size\":\"581.6\"}, {\"price\":\"0.1\", \"size\":\"165.59\"}, {\"price\":\"0.11\", \"size\":\"43.6\"}, {\"price\":\"0.12\", \"size\":\"109.4\"}, {\"price\":\"0.13\", \"size\":\"66.5\"}, {\"price\":\"0.14\", \"size\":\"78.9\"}, {\"price\":\"0.15\", \"size\":\"161.5\"}, {\"price\":\"0.16\", \"size\":\"85.3\"}, {\"price\":\"0.17\", \"size\":\"74.3\"}, {\"price\":\"0.18\", \"size\":\"102.3\"}, {\"price\":\"0.19\", \"size\":\"71.5\"}, {\"price\":\"0.2\", \"size\":\"120.8\"}, {\"price\":\"0.21\", \"size\":\"100.1\"}, {\"price\":\"0.22\", \"size\":\"220.01\"}, {\"price\":\"0.23\", \"size\":\"312.8\"}, {\"price\":\"0.24\", \"size\":\"336.27\"}, {\"price\":\"0.25\", \"size\":\"210\"}, {\"price\":\"0.26\", \"size\":\"183.6\"}, {\"price\":\"0.27\", \"size\":\"219.2\"}, {\"price\":\"0.28\", \"size\":\"187.9\"}, {\"price\":\"0.29\", \"size\":\"217.1\"}, {\"price\":\"0.3\", \"size\":\"231.96\"}, {\"price\":\"0.31\", \"size\":\"175\"}, {\"price\":\"0.32\", \"size\":\"159\"}, {\"price\":\"0.33\", \"size\":\"88\"}, {\"price\":\"0.34\", \"size\":\"99\"}, {\"price\":\"0.35\", \"size\":\"161\"}, {\"price\":\"0.36\", \"size\":\"87\"}, {\"price\":\"0.37\", \"size\":\"79.98\"}, {\"price\":\"0.38\", \"size\":\"64.6\"}, {\"price\":\"0.39\", \"size\":\"117.18\"}, {\"price\":\"0.4\", \"size\":\"91.08\"}, {\"price\":\"0.41\", \"size\":\"90.99\"}, {\"price\":\"0.42\", \"size\":\"56.31\"}, {\"price\":\"0.43\", \"size\":\"75\"}], \"asks\":[{\"price\":\"0.99\", \"size\":\"5682.02\"}, {\"price\":\"0.98\", \"size\":\"732.1\"}, {\"price\":\"0.97\", \"size\":\"662.1\"}, {\"price\":\"0.96\", \"size\":\"662.09\"}, {\"price\":\"0.95\", \"size\":\"867.2\"}, {\"price\":\"0.94\", \"size\":\"597.2\"}, {\"price\":\"0.93\", \"size\":\"120.1\"}, {\"price\":\"0.92\", \"size\":\"94.79\"}, {\"price\":\"0.91\", \"size\":\"95.6\"}, {\"price\":\"0.9\", \"size\":\"211.29\"}, {\"price\":\"0.89\", \"size\":\"87.6\"}, {\"price\":\"0.88\", \"size\":\"94.4\"}, {\"price\":\"0.87\", \"size\":\"111.5\"}, {\"price\":\"0.86\", \"size\":\"78.9\"}, {\"price\":\"0.85\", \"size\":\"131.5\"}, {\"price\":\"0.84\", \"size\":\"115.3\"}, {\"price\":\"0.83\", \"size\":\"74.3\"}, {\"price\":\"0.82\", \"size\":\"77.86\"}, {\"price\":\"0.81\", \"size\":\"101.5\"}, {\"price\":\"0.8\", \"size\":\"110.8\"}, {\"price\":\"0.79\", \"size\":\"70.1\"}, {\"price\":\"0.78\", \"size\":\"98.5\"}, {\"price\":\"0.77\", \"size\":\"67.89\"}, {\"price\":\"0.76\", \"size\":\"67.39\"}, {\"price\":\"0.75\", \"size\":\"125\"}, {\"price\":\"0.74\", \"size\":\"65.6\"}, {\"price\":\"0.73\", \"size\":\"65.2\"}, {\"price\":\"0.72\", \"size\":\"94.9\"}, {\"price\":\"0.71\", \"size\":\"64.6\"}, {\"price\":\"0.7\", \"size\":\"88.3\"}, {\"price\":\"0.69\", \"size\":\"94\"}, {\"price\":\"0.68\", \"size\":\"64.85\"}, {\"price\":\"0.67\", \"size\":\"63.6\"}, {\"price\":\"0.66\", \"size\":\"93.4\"}, {\"price\":\"0.65\", \"size\":\"177.43\"}, {\"price\":\"0.64\", \"size\":\"62\"}, {\"price\":\"0.63\", \"size\":\"91.9\"}, {\"price\":\"0.62\", \"size\":\"61.7\"}, {\"price\":\"0.61\", \"size\":\"61.6\"}, {\"price\":\"0.6\", \"size\":\"96.5\"}, {\"price\":\"0.59\", \"size\":\"67.4\"}, {\"price\":\"0.58\", \"size\":\"171.3\"}, {\"price\":\"0.57\", \"size\":\"242.2\"}, {\"price\":\"0.56\", \"size\":\"169.2\"}, {\"price\":\"0.55\", \"size\":\"239.11\"}, {\"price\":\"0.54\", \"size\":\"253.09\"}, {\"price\":\"0.53\", \"size\":\"326.06\"}, {\"price\":\"0.52\", \"size\":\"217.53\"}, {\"price\":\"0.51\", \"size\":\"246\"}, {\"price\":\"0.5\", \"size\":\"194\"}, {\"price\":\"0.49\", \"size\":\"194\"}, {\"price\":\"0.48\", \"size\":\"237\"}, {\"price\":\"0.47\", \"size\":\"140.95\"}, {\"price\":\"0.46\", \"size\":\"52\"}, {\"price\":\"0.45\", \"size\":\"51\"}, {\"price\":\"0.44\", \"size\":\"22.68\"}], \"hash\":\"b91b33a8ea67e4d732c02709be3c150cc9790bb2\", \"timestamp\":\"1785204533174\", \"event_type\":\"book\"}","received_at":"2026-07-28T02:08:53.851282Z","schema_version":"clob-market-ws.book.v1","sequence":null,"server_hash":"b91b33a8ea67e4d732c02709be3c150cc9790bb2","server_timestamp":"1785204533174","session_id":"d2757dd6dad94f3b9fe67e8dbf1adc37","source":"clob_market_ws"},"received_at":"2026-07-28T02:08:53.851282Z","record_id":"5e82cb312aa12f26cef2f8dc0cd4b63f0f063988588c625e622b4ed07f58e39f","schema_fingerprint":"dc2caa1c89c6a7426e2e07ff925910cd4d0a8a223a515d4092d91d6d127aacb6","schema_version":"edge-lab-recorder.raw.v1","sequence":null,"source":"clob_market_ws"}
{"event_at":"2026-07-28T02:08:53.178000Z","event_fingerprint":"8ae638af1ba31ec989819f1bd4a568f8cb65c6a62796add3fce6b8681cb2845d","payload":{"connection_id":"5d29200f65794d4d9ab6ef271f045a9b","event_at":"2026-07-28T02:08:53.178000Z","event_type":"price_change","frame_hash":"584d48b5158d2540ab19c55d53fde60b2e5663132c3a47b707d21c17b077853b","frame_index":0,"kind":"data","monotonic_ns":306516871226750,"payload":{"event_type":"price_change","market":"0xda6f0e0e93fc8469e0159a166028d017bddbc162b86f66bac90391379603d962","price_changes":[{"asset_id":"20893381255801015515826997628594359667013752732428989472914000440642900266717","best_ask":"0.57","best_bid":"0.56","hash":"0306f44847938e198a1a7bea438b804462902a0d","price":"0.57","side":"SELL","size":"80"},{"asset_id":"39272994714739463168905443499424551362424437245880253267329605556587274644733","best_ask":"0.44","best_bid":"0.43","hash":"4801b69c3c917955887f63d2e214b96e1a55362c","price":"0.43","side":"BUY","size":"80"}],"timestamp":"1785204533178"},"payload_hash":"f3c5359e55e11695a2eed2af378dc374fa736ddc80c829860334d53bf94c252f","raw_frame":"{\"market\":\"0xda6f0e0e93fc8469e0159a166028d017bddbc162b86f66bac90391379603d962\", \"price_changes\":[{\"asset_id\":\"20893381255801015515826997628594359667013752732428989472914000440642900266717\", \"price\":\"0.57\", \"size\":\"80\", \"side\":\"SELL\", \"hash\":\"0306f44847938e198a1a7bea438b804462902a0d\", \"best_bid\":\"0.56\", \"best_ask\":\"0.57\"}, {\"asset_id\":\"39272994714739463168905443499424551362424437245880253267329605556587274644733\", \"price\":\"0.43\", \"size\":\"80\", \"side\":\"BUY\", \"hash\":\"4801b69c3c917955887f63d2e214b96e1a55362c\", \"best_bid\":\"0.43\", \"best_ask\":\"0.44\"}], \"timestamp\":\"1785204533178\", \"event_type\":\"price_change\"}","received_at":"2026-07-28T02:08:53.862888Z","schema_version":"clob-market-ws.price_change.v1","sequence":null,"server_hash":null,"server_timestamp":"1785204533178","session_id":"d2757dd6dad94f3b9fe67e8dbf1adc37","source":"clob_market_ws"},"received_at":"2026-07-28T02:08:53.862888Z","record_id":"436862a85ff8b1d052cffa8e35b22bfa412effbc62cc7e27a005185f1b1c2419","schema_fingerprint":"4aa3821a28b0b7c2400bc59aba4bcc0a76e971dadd19610d3ad38c768e124dc7","schema_version":"edge-lab-recorder.raw.v1","sequence":null,"source":"clob_market_ws"}
{"event_at":"2026-07-28T02:08:53.186000Z","event_fingerprint":"a61763bcd9a0ea2e1b16ccfab12383986896a0dd28f95721bcf112438c23d23f","payload":{"connection_id":"5d29200f65794d4d9ab6ef271f045a9b","event_at":"2026-07-28T02:08:53.186000Z","event_type":"price_change","frame_hash":"b63ca35c6c55a08a01dace8c7ec4a6566246981c886a37de43574a7e365eaf5b","frame_index":0,"kind":"data","monotonic_ns":306516874198583,"payload":{"event_type":"price_change","market":"0xda6f0e0e93fc8469e0159a166028d017bddbc162b86f66bac90391379603d962","price_changes":[{"asset_id":"20893381255801015515826997628594359667013752732428989472914000440642900266717","best_ask":"0.57","best_bid":"0.56","hash":"7076974188e0bc4257557f91c0e0b8328b87d24b","price":"0.03","side":"BUY","size":"667.1"},{"asset_id":"39272994714739463168905443499424551362424437245880253267329605556587274644733","best_ask":"0.44","best_bid":"0.43","hash":"eb181c9108de870063fd3e6fe9b0bd34fa91b4b9","price":"0.97","side":"SELL","size":"667.1"}],"timestamp":"1785204533186"},"payload_hash":"44acdab8112cfcdb38086e884a8abc9d9e192b60bb2a018148f55ba8ffb491e4","raw_frame":"{\"market\":\"0xda6f0e0e93fc8469e0159a166028d017bddbc162b86f66bac90391379603d962\", \"price_changes\":[{\"asset_id\":\"20893381255801015515826997628594359667013752732428989472914000440642900266717\", \"price\":\"0.03\", \"size\":\"667.1\", \"side\":\"BUY\", \"hash\":\"7076974188e0bc4257557f91c0e0b8328b87d24b\", \"best_bid\":\"0.56\", \"best_ask\":\"0.57\"}, {\"asset_id\":\"39272994714739463168905443499424551362424437245880253267329605556587274644733\", \"price\":\"0.97\", \"size\":\"667.1\", \"side\":\"SELL\", \"hash\":\"eb181c9108de870063fd3e6fe9b0bd34fa91b4b9\", \"best_bid\":\"0.43\", \"best_ask\":\"0.44\"}], \"timestamp\":\"1785204533186\", \"event_type\":\"price_change\"}","received_at":"2026-07-28T02:08:53.865860Z","schema_version":"clob-market-ws.price_change.v1","sequence":null,"server_hash":null,"server_timestamp":"1785204533186","session_id":"d2757dd6dad94f3b9fe67e8dbf1adc37","source":"clob_market_ws"},"received_at":"2026-07-28T02:08:53.865860Z","record_id":"cb39c65691471f8e6b72f1acf6724f7f6faeac7b1fa03adb9f097fcfe79196eb","schema_fingerprint":"4aa3821a28b0b7c2400bc59aba4bcc0a76e971dadd19610d3ad38c768e124dc7","schema_version":"edge-lab-recorder.raw.v1","sequence":null,"source":"clob_market_ws"}
{"event_at":"2026-07-28T02:08:53.194000Z","event_fingerprint":"051acce4d9d643aca153a22aa26fa8bce93a3f834b916407f7ab84f29304453f","payload":{"connection_id":"5d29200f65794d4d9ab6ef271f045a9b","event_at":"2026-07-28T02:08:53.194000Z","event_type":"price_change","frame_hash":"fc456f15227df6a7e488265d84725130148b4d7e92f0c366d4059d1ea666a5b1","frame_index":0,"kind":"data","monotonic_ns":306516877150708,"payload":{"event_type":"price_change","market":"0xda6f0e0e93fc8469e0159a166028d017bddbc162b86f66bac90391379603d962","price_changes":[{"asset_id":"20893381255801015515826997628594359667013752732428989472914000440642900266717","best_ask":"0.57","best_bid":"0.56","hash":"b8d0ed7f056f68bc2c31a6f101362645f3dbf202","price":"0.45","side":"BUY","size":"224.11"},{"asset_id":"39272994714739463168905443499424551362424437245880253267329605556587274644733","best_ask":"0.44","best_bid":"0.43","hash":"1a574d910cc560a0b9bff8da943dc54419017413","price":"0.55","side":"SELL","size":"224.11"}],"timestamp":"1785204533194"},"payload_hash":"85ada722c0ce001dc5c4161e63f8948e8e1720b925904e9a290747278f62981c","raw_frame":"{\"market\":\"0xda6f0e0e93fc8469e0159a166028d017bddbc162b86f66bac90391379603d962\", \"price_changes\":[{\"asset_id\":\"20893381255801015515826997628594359667013752732428989472914000440642900266717\", \"price\":\"0.45\", \"size\":\"224.11\", \"side\":\"BUY\", \"hash\":\"b8d0ed7f056f68bc2c31a6f101362645f3dbf202\", \"best_bid\":\"0.56\", \"best_ask\":\"0.57\"}, {\"asset_id\":\"39272994714739463168905443499424551362424437245880253267329605556587274644733\", \"price\":\"0.55\", \"size\":\"224.11\", \"side\":\"SELL\", \"hash\":\"1a574d910cc560a0b9bff8da943dc54419017413\", \"best_bid\":\"0.43\", \"best_ask\":\"0.44\"}], \"timestamp\":\"1785204533194\", \"event_type\":\"price_change\"}","received_at":"2026-07-28T02:08:53.868812Z","schema_version":"clob-market-ws.price_change.v1","sequence":null,"server_hash":null,"server_timestamp":"1785204533194","session_id":"d2757dd6dad94f3b9fe67e8dbf1adc37","source":"clob_market_ws"},"received_at":"2026-07-28T02:08:53.868812Z","record_id":"a400f4fb535902f104bc289a50ec49f848c9da44bc4873994d9693bd8d31081d","schema_fingerprint":"4aa3821a28b0b7c2400bc59aba4bcc0a76e971dadd19610d3ad38c768e124dc7","schema_version":"edge-lab-recorder.raw.v1","sequence":null,"source":"clob_market_ws"}
{"event_at":"2026-07-28T02:08:53.199000Z","event_fingerprint":"f2d509fa8e8ca217b45d2482eb07f42cce197a3b1a91cd9cc032f010fc985ab7","payload":{"connection_id":"5d29200f65794d4d9ab6ef271f045a9b","event_at":"2026-07-28T02:08:53.199000Z","event_type":"price_change","frame_hash":"c21ceb81b6886b09a7fe1479c18c86788ebb4147555b571f74d6499aca59bd4f","frame_index":0,"kind":"data","monotonic_ns":306516880177958,"payload":{"event_type":"price_change","market":"0xda6f0e0e93fc8469e0159a166028d017bddbc162b86f66bac90391379603d962","price_changes":[{"asset_id":"39272994714739463168905443499424551362424437245880253267329605556587274644733","best_ask":"0.44","best_bid":"0.43","hash":"ae91bbcf7ffc21625b176061254f0c5447b04596","price":"0.3","side":"BUY","size":"246.26"},{"asset_id":"20893381255801015515826997628594359667013752732428989472914000440642900266717","best_ask":"0.57","best_bid":"0.56","hash":"d410ae3b1464d94cde89aee377780c097e73b9dd","price":"0.7","side":"SELL","size":"246.26"}],"timestamp":"1785204533199"},"payload_hash":"86c5caba63267a504d6b6035f3be432cd8a8840a1a9526ace0e623477b7a9d8b","raw_frame":"{\"market\":\"0xda6f0e0e93fc8469e0159a166028d017bddbc162b86f66bac90391379603d962\", \"price_changes\":[{\"asset_id\":\"39272994714739463168905443499424551362424437245880253267329605556587274644733\", \"price\":\"0.3\", \"size\":\"246.26\", \"side\":\"BUY\", \"hash\":\"ae91bbcf7ffc21625b176061254f0c5447b04596\", \"best_bid\":\"0.43\", \"best_ask\":\"0.44\"}, {\"asset_id\":\"20893381255801015515826997628594359667013752732428989472914000440642900266717\", \"price\":\"0.7\", \"size\":\"246.26\", \"side\":\"SELL\", \"hash\":\"d410ae3b1464d94cde89aee377780c097e73b9dd\", \"best_bid\":\"0.56\", \"best_ask\":\"0.57\"}], \"timestamp\":\"1785204533199\", \"event_type\":\"price_change\"}","received_at":"2026-07-28T02:08:53.871838Z","schema_version":"clob-market-ws.price_change.v1","sequence":null,"server_hash":null,"server_timestamp":"1785204533199","session_id":"d2757dd6dad94f3b9fe67e8dbf1adc37","source":"clob_market_ws"},"received_at":"2026-07-28T02:08:53.871838Z","record_id":"49f196922cba66474b2db2f2f53cd0019297fe8e3f9d530781a99bb0c00a3d04","schema_fingerprint":"4aa3821a28b0b7c2400bc59aba4bcc0a76e971dadd19610d3ad38c768e124dc7","schema_version":"edge-lab-recorder.raw.v1","sequence":null,"source":"clob_market_ws"}
{"event_at":"2026-07-28T02:08:53.219000Z","event_fingerprint":"2334aef0ab1185297cfe160f446d1f7fe4e6eb36b71dc5c2add2c7fca0058b8d","payload":{"connection_id":"5d29200f65794d4d9ab6ef271f045a9b","event_at":"2026-07-28T02:08:53.219000Z","event_type":"price_change","frame_hash":"4d6e0cd6599ea10eaf7ddd232e349ddebd8f41d80c33736c0216b65c56d245de","frame_index":0,"kind":"data","monotonic_ns":306516883185250,"payload":{"event_type":"price_change","market":"0xda6f0e0e93fc8469e0159a166028d017bddbc162b86f66bac90391379603d962","price_changes":[{"asset_id":"20893381255801015515826997628594359667013752732428989472914000440642900266717","best_ask":"0.57","best_bid":"0.56","hash":"9c6aa347be74493624456a2a02b1712310872508","price":"0.54","side":"BUY","size":"67"},{"asset_id":"39272994714739463168905443499424551362424437245880253267329605556587274644733","best_ask":"0.44","best_bid":"0.43","hash":"925e6c9f582635193c054832a4272f643563a1ca","price":"0.46","side":"SELL","size":"67"}],"timestamp":"1785204533219"},"payload_hash":"ed820069afb95b1e666ee016c178082384a1a2609951dfb2206c7028de1e3e2c","raw_frame":"{\"market\":\"0xda6f0e0e93fc8469e0159a166028d017bddbc162b86f66bac90391379603d962\", \"price_changes\":[{\"asset_id\":\"20893381255801015515826997628594359667013752732428989472914000440642900266717\", \"price\":\"0.54\", \"size\":\"67\", \"side\":\"BUY\", \"hash\":\"9c6aa347be74493624456a2a02b1712310872508\", \"best_bid\":\"0.56\", \"best_ask\":\"0.57\"}, {\"asset_id\":\"39272994714739463168905443499424551362424437245880253267329605556587274644733\", \"price\":\"0.46\", \"size\":\"67\", \"side\":\"SELL\", \"hash\":\"925e6c9f582635193c054832a4272f643563a1ca\", \"best_bid\":\"0.43\", \"best_ask\":\"0.44\"}], \"timestamp\":\"1785204533219\", \"event_type\":\"price_change\"}","received_at":"2026-07-28T02:08:53.874845Z","schema_version":"clob-market-ws.price_change.v1","sequence":null,"server_hash":null,"server_timestamp":"1785204533219","session_id":"d2757dd6dad94f3b9fe67e8dbf1adc37","source":"clob_market_ws"},"received_at":"2026-07-28T02:08:53.874845Z","record_id":"88689f647053b476d1bf7c12135b6d5dc3e431d0d8ef5b50f8d3c969d0d723dc","schema_fingerprint":"4aa3821a28b0b7c2400bc59aba4bcc0a76e971dadd19610d3ad38c768e124dc7","schema_version":"edge-lab-recorder.raw.v1","sequence":null,"source":"clob_market_ws"}
{"event_at":"2026-07-28T02:08:53.223000Z","event_fingerprint":"b9d7472f086ddd170d5c78d4dbba67748dddafaeeff5e113933bffa9d99f913d","payload":{"connection_id":"5d29200f65794d4d9ab6ef271f045a9b","event_at":"2026-07-28T02:08:53.223000Z","event_type":"price_change","frame_hash":"12bd42188edac00b04aa6b2103bdc593d7a4ac3f987a96029337c7b4d8c69deb","frame_index":0,"kind":"data","monotonic_ns":306516886140333,"payload":{"event_type":"price_change","market":"0xda6f0e0e93fc8469e0159a166028d017bddbc162b86f66bac90391379603d962","price_changes":[{"asset_id":"39272994714739463168905443499424551362424437245880253267329605556587274644733","best_ask":"0.44","best_bid":"0.43","hash":"20c3b02832271dc450eb3f89b87a10315b36f7d7","price":"0.43","side":"BUY","size":"74"},{"asset_id":"20893381255801015515826997628594359667013752732428989472914000440642900266717","best_ask":"0.57","best_bid":"0.56","hash":"3434dc1e071bab1a76cf04f7f9b173e561fb36d8","price":"0.57","side":"SELL","size":"74"}],"timestamp":"1785204533223"},"payload_hash":"37c4065bf993e1b5948ed6b0691dbba516771972b97748cf30d4ff0c4d6f5c3e","raw_frame":"{\"market\":\"0xda6f0e0e93fc8469e0159a166028d017bddbc162b86f66bac90391379603d962\", \"price_changes\":[{\"asset_id\":\"39272994714739463168905443499424551362424437245880253267329605556587274644733\", \"price\":\"0.43\", \"size\":\"74\", \"side\":\"BUY\", \"hash\":\"20c3b02832271dc450eb3f89b87a10315b36f7d7\", \"best_bid\":\"0.43\", \"best_ask\":\"0.44\"}, {\"asset_id\":\"20893381255801015515826997628594359667013752732428989472914000440642900266717\", \"price\":\"0.57\", \"size\":\"74\", \"side\":\"SELL\", \"hash\":\"3434dc1e071bab1a76cf04f7f9b173e561fb36d8\", \"best_bid\":\"0.56\", \"best_ask\":\"0.57\"}], \"timestamp\":\"1785204533223\", \"event_type\":\"price_change\"}","received_at":"2026-07-28T02:08:53.877801Z","schema_version":"clob-market-ws.price_change.v1","sequence":null,"server_hash":null,"server_timestamp":"1785204533223","session_id":"d2757dd6dad94f3b9fe67e8dbf1adc37","source":"clob_market_ws"},"received_at":"2026-07-28T02:08:53.877801Z","record_id":"1dba0f8997e769d2b10484f22a771872620a5058046a35c390eb0d1ba4b644ac","schema_fingerprint":"4aa3821a28b0b7c2400bc59aba4bcc0a76e971dadd19610d3ad38c768e124dc7","schema_version":"edge-lab-recorder.raw.v1","sequence":null,"source":"clob_market_ws"}
{"event_at":"2026-07-28T02:08:53.224000Z","event_fingerprint":"a5ab33231cb5c6ac25f73a1282874c289b81ef9422b61f4d0b97301f698b2687","payload":{"connection_id":"5d29200f65794d4d9ab6ef271f045a9b","event_at":"2026-07-28T02:08:53.224000Z","event_type":"price_change","frame_hash":"0959e1aaffa39ab97277576c01125d40c1eae64b3bb9539314f75b119e0ac806","frame_index":0,"kind":"data","monotonic_ns":306516889069500,"payload":{"event_type":"price_change","market":"0xda6f0e0e93fc8469e0159a166028d017bddbc162b86f66bac90391379603d962","price_changes":[{"asset_id":"39272994714739463168905443499424551362424437245880253267329605556587274644733","best_ask":"0.44","best_bid":"0.43","hash":"e749c3fecafb9451230c804a084773849029e197","price":"0.31","side":"BUY","size":"160"},{"asset_id":"20893381255801015515826997628594359667013752732428989472914000440642900266717","best_ask":"0.57","best_bid":"0.56","hash":"1de43d207d5b06a4f4ba29291e5b1065ada16b87","price":"0.69","side":"SELL","size":"160"}],"timestamp":"1785204533224"},"payload_hash":"4c777b1a2b651ba53d486f03fb72feb586736bab8de98680a93523e97afbefc2","raw_frame":"{\"market\":\"0xda6f0e0e93fc8469e0159a166028d017bddbc162b86f66bac90391379603d962\", \"price_changes\":[{\"asset_id\":\"39272994714739463168905443499424551362424437245880253267329605556587274644733\", \"price\":\"0.31\", \"size\":\"160\", \"side\":\"BUY\", \"hash\":\"e749c3fecafb9451230c804a084773849029e197\", \"best_bid\":\"0.43\", \"best_ask\":\"0.44\"}, {\"asset_id\":\"20893381255801015515826997628594359667013752732428989472914000440642900266717\", \"price\":\"0.69\", \"size\":\"160\", \"side\":\"SELL\", \"hash\":\"1de43d207d5b06a4f4ba29291e5b1065ada16b87\", \"best_bid\":\"0.56\", \"best_ask\":\"0.57\"}], \"timestamp\":\"1785204533224\", \"event_type\":\"price_change\"}","received_at":"2026-07-28T02:08:53.880731Z","schema_version":"clob-market-ws.price_change.v1","sequence":null,"server_hash":null,"server_timestamp":"1785204533224","session_id":"d2757dd6dad94f3b9fe67e8dbf1adc37","source":"clob_market_ws"},"received_at":"2026-07-28T02:08:53.880731Z","record_id":"e0d78f48e332765a2e9cc6aa6d8021cbb6b839b7c901f58b3cefcf0713fc9087","schema_fingerprint":"4aa3821a28b0b7c2400bc59aba4bcc0a76e971dadd19610d3ad38c768e124dc7","schema_version":"edge-lab-recorder.raw.v1","sequence":null,"source":"clob_market_ws"}
{"event_at":"2026-07-28T02:08:53.224000Z","event_fingerprint":"7f9d40ec0c6ae2a67226920845a2fe707549db207f2967812dcb20f473e6eee1","payload":{"connection_id":"5d29200f65794d4d9ab6ef271f045a9b","event_at":"2026-07-28T02:08:53.224000Z","event_type":"price_change","frame_hash":"96816b3ba30c92c057fd578e6048b862637dd26bae855a33626f6e5dd037545f","frame_index":0,"kind":"data","monotonic_ns":306516892024708,"payload":{"event_type":"price_change","market":"0xda6f0e0e93fc8469e0159a166028d017bddbc162b86f66bac90391379603d962","price_changes":[{"asset_id":"39272994714739463168905443499424551362424437245880253267329605556587274644733","best_ask":"0.44","best_bid":"0.43","hash":"cf5e4d91d7854bc56ca8b1e0138daa4fb7a487b9","price":"0.41","side":"BUY","size":"78.39"},{"asset_id":"20893381255801015515826997628594359667013752732428989472914000440642900266717","best_ask":"0.57","best_bid":"0.56","hash":"f19c023368b5b94bdf0f15e68a1c4ea39d2336a9","price":"0.59","side":"SELL","size":"78.39"}],"timestamp":"1785204533224"},"payload_hash":"a7b2ed4f32424d586f7262ca016e9c97b829982115aaa8f9d31d3ba328b72714","raw_frame":"{\"market\":\"0xda6f0e0e93fc8469e0159a166028d017bddbc162b86f66bac90391379603d962\", \"price_changes\":[{\"asset_id\":\"39272994714739463168905443499424551362424437245880253267329605556587274644733\", \"price\":\"0.41\", \"size\":\"78.39\", \"side\":\"BUY\", \"hash\":\"cf5e4d91d7854bc56ca8b1e0138daa4fb7a487b9\", \"best_bid\":\"0.43\", \"best_ask\":\"0.44\"}, {\"asset_id\":\"20893381255801015515826997628594359667013752732428989472914000440642900266717\", \"price\":\"0.59\", \"size\":\"78.39\", \"side\":\"SELL\", \"hash\":\"f19c023368b5b94bdf0f15e68a1c4ea39d2336a9\", \"best_bid\":\"0.56\", \"best_ask\":\"0.57\"}], \"timestamp\":\"1785204533224\", \"event_type\":\"price_change\"}","received_at":"2026-07-28T02:08:53.883684Z","schema_version":"clob-market-ws.price_change.v1","sequence":null,"server_hash":null,"server_timestamp":"1785204533224","session_id":"d2757dd6dad94f3b9fe67e8dbf1adc37","source":"clob_market_ws"},"received_at":"2026-07-28T02:08:53.883684Z","record_id":"349f206ee9393f04a6d94ddbd7a29f8df51ce6fb04fac040067dd50520b00679","schema_fingerprint":"4aa3821a28b0b7c2400bc59aba4bcc0a76e971dadd19610d3ad38c768e124dc7","schema_version":"edge-lab-recorder.raw.v1","sequence":null,"source":"clob_market_ws"}
{"event_at":"2026-07-28T02:08:53.224000Z","event_fingerprint":"3d1222ca78927fdf67cfe54e944a84eb2215710f38020fb251b213e5a81e20b3","payload":{"connection_id":"5d29200f65794d4d9ab6ef271f045a9b","event_at":"2026-07-28T02:08:53.224000Z","event_type":"price_change","frame_hash":"1b8c8361e7419a394dfc4f7d16af61b32e9c00201da9d7202090adae002e07d9","frame_index":0,"kind":"data","monotonic_ns":306516894966625,"payload":{"event_type":"price_change","market":"0xda6f0e0e93fc8469e0159a166028d017bddbc162b86f66bac90391379603d962","price_changes":[{"asset_id":"39272994714739463168905443499424551362424437245880253267329605556587274644733","best_ask":"0.44","best_bid":"0.43","hash":"2e74c23f8e1463662900da8d1c995525b39dae79","price":"0.4","side":"BUY","size":"76.08"},{"asset_id":"20893381255801015515826997628594359667013752732428989472914000440642900266717","best_ask":"0.57","best_bid":"0.56","hash":"62929371771b1f43d5e6a50bdece6df32f6e4c14","price":"0.6","side":"SELL","size":"76.08"}],"timestamp":"1785204533224"},"payload_hash":"02f965ecb6be1a04b60916bc3a46528f8f8cd7c32c581e5a99eaf4da397e95cd","raw_frame":"{\"market\":\"0xda6f0e0e93fc8469e0159a166028d017bddbc162b86f66bac90391379603d962\", \"price_changes\":[{\"asset_id\":\"39272994714739463168905443499424551362424437245880253267329605556587274644733\", \"price\":\"0.4\", \"size\":\"76.08\", \"side\":\"BUY\", \"hash\":\"2e74c23f8e1463662900da8d1c995525b39dae79\", \"best_bid\":\"0.43\", \"best_ask\":\"0.44\"}, {\"asset_id\":\"20893381255801015515826997628594359667013752732428989472914000440642900266717\", \"price\":\"0.6\", \"size\":\"76.08\", \"side\":\"SELL\", \"hash\":\"62929371771b1f43d5e6a50bdece6df32f6e4c14\", \"best_bid\":\"0.56\", \"best_ask\":\"0.57\"}], \"timestamp\":\"1785204533224\", \"event_type\":\"price_change\"}","received_at":"2026-07-28T02:08:53.886628Z","schema_version":"clob-market-ws.price_change.v1","sequence":null,"server_hash":null,"server_timestamp":"1785204533224","session_id":"d2757dd6dad94f3b9fe67e8dbf1adc37","source":"clob_market_ws"},"received_at":"2026-07-28T02:08:53.886628Z","record_id":"6dd4a5255b8d70b8eb10c87c345ccbe34b811ebfe7c34176a3189caf52f77bb7","schema_fingerprint":"4aa3821a28b0b7c2400bc59aba4bcc0a76e971dadd19610d3ad38c768e124dc7","schema_version":"edge-lab-recorder.raw.v1","sequence":null,"source":"clob_market_ws"}
{"event_at":"2026-07-28T02:08:53.227000Z","event_fingerprint":"3fb29c2d780177bb7853e4a5732c9d71bcad595ac091d9efbde4944db1b741af","payload":{"connection_id":"5d29200f65794d4d9ab6ef271f045a9b","event_at":"2026-07-28T02:08:53.227000Z","event_type":"price_change","frame_hash":"f51eb6e897631b3d85606173f69e5e653524cc0a88a99815276ea2e1254d769b","frame_index":0,"kind":"data","monotonic_ns":306516897920666,"payload":{"event_type":"price_change","market":"0xda6f0e0e93fc8469e0159a166028d017bddbc162b86f66bac90391379603d962","price_changes":[{"asset_id":"20893381255801015515826997628594359667013752732428989472914000440642900266717","best_ask":"0.57","best_bid":"0.56","hash":"da7a988d00e6bdb7b85589efa8dafa59eff71c27","price":"0.54","side":"BUY","size":"96"},{"asset_id":"39272994714739463168905443499424551362424437245880253267329605556587274644733","best_ask":"0.44","best_bid":"0.43","hash":"9cb0f98a09bd9a12a93dc410511cd2fc716bd29a","price":"0.46","side":"SELL","size":"96"}],"timestamp":"1785204533227"},"payload_hash":"c8b8ead5fbb3eadb48cc9880dceb66da5eeef8926718a423e7661db73a720e14","raw_frame":"{\"market\":\"0xda6f0e0e93fc8469e0159a166028d017bddbc162b86f66bac90391379603d962\", \"price_changes\":[{\"asset_id\":\"20893381255801015515826997628594359667013752732428989472914000440642900266717\", \"price\":\"0.54\", \"size\":\"96\", \"side\":\"BUY\", \"hash\":\"da7a988d00e6bdb7b85589efa8dafa59eff71c27\", \"best_bid\":\"0.56\", \"best_ask\":\"0.57\"}, {\"asset_id\":\"39272994714739463168905443499424551362424437245880253267329605556587274644733\", \"price\":\"0.46\", \"size\":\"96\", \"side\":\"SELL\", \"hash\":\"9cb0f98a09bd9a12a93dc410511cd2fc716bd29a\", \"best_bid\":\"0.43\", \"best_ask\":\"0.44\"}], \"timestamp\":\"1785204533227\", \"event_type\":\"price_change\"}","received_at":"2026-07-28T02:08:53.889581Z","schema_version":"clob-market-ws.price_change.v1","sequence":null,"server_hash":null,"server_timestamp":"1785204533227","session_id":"d2757dd6dad94f3b9fe67e8dbf1adc37","source":"clob_market_ws"},"received_at":"2026-07-28T02:08:53.889581Z","record_id":"610903c94c463141aa7022e8c2ccc529529ad1b7665dd1b0129d12da1ba6874a","schema_fingerprint":"4aa3821a28b0b7c2400bc59aba4bcc0a76e971dadd19610d3ad38c768e124dc7","schema_version":"edge-lab-recorder.raw.v1","sequence":null,"source":"clob_market_ws"}
{"event_at":"2026-07-28T02:08:53.238000Z","event_fingerprint":"d547fafe1df807adcaa1240d6cb71ea19cfac805ac4f3737ce090eb09d53a73a","payload":{"connection_id":"5d29200f65794d4d9ab6ef271f045a9b","event_at":"2026-07-28T02:08:53.238000Z","event_type":"price_change","frame_hash":"7a0f1fbd3d853420e80be06959600cac3a8d05d7b0841784ab85ca7e3f55ddb0","frame_index":0,"kind":"data","monotonic_ns":306516900912833,"payload":{"event_type":"price_change","market":"0xda6f0e0e93fc8469e0159a166028d017bddbc162b86f66bac90391379603d962","price_changes":[{"asset_id":"20893381255801015515826997628594359667013752732428989472914000440642900266717","best_ask":"0.57","best_bid":"0.56","hash":"d08a4e1e35cde83a28d8315090fe2f141589df8e","price":"0.51","side":"BUY","size":"209"},{"asset_id":"39272994714739463168905443499424551362424437245880253267329605556587274644733","best_ask":"0.44","best_bid":"0.43","hash":"1520edd79701d8498568e6964b718dfaa9f9ab14","price":"0.49","side":"SELL","size":"209"}],"timestamp":"1785204533238"},"payload_hash":"44d2b83f7a4561311185457cf29e75045b4597dd2b779c52377d964d34e0ce29","raw_frame":"{\"market\":\"0xda6f0e0e93fc8469e0159a166028d017bddbc162b86f66bac90391379603d962\", \"price_changes\":[{\"asset_id\":\"20893381255801015515826997628594359667013752732428989472914000440642900266717\", \"price\":\"0.51\", \"size\":\"209\", \"side\":\"BUY\", \"hash\":\"d08a4e1e35cde83a28d8315090fe2f141589df8e\", \"best_bid\":\"0.56\", \"best_ask\":\"0.57\"}, {\"asset_id\":\"39272994714739463168905443499424551362424437245880253267329605556587274644733\", \"price\":\"0.49\", \"size\":\"209\", \"side\":\"SELL\", \"hash\":\"1520edd79701d8498568e6964b718dfaa9f9ab14\", \"best_bid\":\"0.43\", \"best_ask\":\"0.44\"}], \"timestamp\":\"1785204533238\", \"event_type\":\"price_change\"}","received_at":"2026-07-28T02:08:53.892574Z","schema_version":"clob-market-ws.price_change.v1","sequence":null,"server_hash":null,"server_timestamp":"1785204533238","session_id":"d2757dd6dad94f3b9fe67e8dbf1adc37","source":"clob_market_ws"},"received_at":"2026-07-28T02:08:53.892574Z","record_id":"c25c82973dc4d2f81ac7c7879e167e1a18c6b43950ff36b7720dab0b465b3693","schema_fingerprint":"4aa3821a28b0b7c2400bc59aba4bcc0a76e971dadd19610d3ad38c768e124dc7","schema_version":"edge-lab-recorder.raw.v1","sequence":null,"source":"clob_market_ws"}
{"event_at":"2026-07-28T02:08:53.239000Z","event_fingerprint":"3fb289038aa31168d0c7de5696001793983a6c03a906929c5cc129d731f7239a","payload":{"connection_id":"5d29200f65794d4d9ab6ef271f045a9b","event_at":"2026-07-28T02:08:53.239000Z","event_type":"price_change","frame_hash":"99a7352375bf1ad7e2ffb9a03812c3d1c754edcc7f356ad07ea5bf1c6ff97462","frame_index":0,"kind":"data","monotonic_ns":306516903867833,"payload":{"event_type":"price_change","market":"0xda6f0e0e93fc8469e0159a166028d017bddbc162b86f66bac90391379603d962","price_changes":[{"asset_id":"20893381255801015515826997628594359667013752732428989472914000440642900266717","best_ask":"0.57","best_bid":"0.56","hash":"256f98392be7ed1ca7120b13397d73cefdeb9b49","price":"0.55","side":"BUY","size":"66"},{"asset_id":"39272994714739463168905443499424551362424437245880253267329605556587274644733","best_ask":"0.44","best_bid":"0.43","hash":"d54a27258ec071a218680f26b4cfe9b9fc04adc6","price":"0.45","side":"SELL","size":"66"}],"timestamp":"1785204533239"},"payload_hash":"f9092552c471c3d9f8077d2298a5fcabdce8bf5669889b9d196ca5eab1175dcb","raw_frame":"{\"market\":\"0xda6f0e0e93fc8469e0159a166028d017bddbc162b86f66bac90391379603d962\", \"price_changes\":[{\"asset_id\":\"20893381255801015515826997628594359667013752732428989472914000440642900266717\", \"price\":\"0.55\", \"size\":\"66\", \"side\":\"BUY\", \"hash\":\"256f98392be7ed1ca7120b13397d73cefdeb9b49\", \"best_bid\":\"0.56\", \"best_ask\":\"0.57\"}, {\"asset_id\":\"39272994714739463168905443499424551362424437245880253267329605556587274644733\", \"price\":\"0.45\", \"size\":\"66\", \"side\":\"SELL\", \"hash\":\"d54a27258ec071a218680f26b4cfe9b9fc04adc6\", \"best_bid\":\"0.43\", \"best_ask\":\"0.44\"}], \"timestamp\":\"1785204533239\", \"event_type\":\"price_change\"}","received_at":"2026-07-28T02:08:53.895527Z","schema_version":"clob-market-ws.price_change.v1","sequence":null,"server_hash":null,"server_timestamp":"1785204533239","session_id":"d2757dd6dad94f3b9fe67e8dbf1adc37","source":"clob_market_ws"},"received_at":"2026-07-28T02:08:53.895527Z","record_id":"39e79308b041d8bb483540af4f3c0af56a67f74cf1a79cb1f08fe7eea5509ac9","schema_fingerprint":"4aa3821a28b0b7c2400bc59aba4bcc0a76e971dadd19610d3ad38c768e124dc7","schema_version":"edge-lab-recorder.raw.v1","sequence":null,"source":"clob_market_ws"}
{"event_at":"2026-07-28T02:08:53.240000Z","event_fingerprint":"b82000ffb486101da7c616f8b71aeaf9f510e2e5e9319d0d4bf7ed8206a586be","payload":{"connection_id":"5d29200f65794d4d9ab6ef271f045a9b","event_at":"2026-07-28T02:08:53.240000Z","event_type":"price_change","frame_hash":"fe9c871a9ea61c38c6eadedf69bfdf413dbc6004cb11297f07b7dde0316d563e","frame_index":0,"kind":"data","monotonic_ns":306516906779666,"payload":{"event_type":"price_change","market":"0xda6f0e0e93fc8469e0159a166028d017bddbc162b86f66bac90391379603d962","price_changes":[{"asset_id":"39272994714739463168905443499424551362424437245880253267329605556587274644733","best_ask":"0.44","best_bid":"0.43","hash":"8d1098cbb6f90de5611c5a71bdc34bfbeca78c9f","price":"0.39","side":"BUY","size":"132.18"},{"asset_id":"20893381255801015515826997628594359667013752732428989472914000440642900266717","best_ask":"0.57","best_bid":"0.56","hash":"70e0c01e5bc2493217a49d113b5babd23ce7f53f","price":"0.61","side":"SELL","size":"132.18"}],"timestamp":"1785204533240"},"payload_hash":"ce9c7ff9be98d2d08791ff33c9575b8281a6e81fe1a1bff07af9191a9a34ae4d","raw_frame":"{\"market\":\"0xda6f0e0e93fc8469e0159a166028d017bddbc162b86f66bac90391379603d962\", \"price_changes\":[{\"asset_id\":\"39272994714739463168905443499424551362424437245880253267329605556587274644733\", \"price\":\"0.39\", \"size\":\"132.18\", \"side\":\"BUY\", \"hash\":\"8d1098cbb6f90de5611c5a71bdc34bfbeca78c9f\", \"best_bid\":\"0.43\", \"best_ask\":\"0.44\"}, {\"asset_id\":\"20893381255801015515826997628594359667013752732428989472914000440642900266717\", \"price\":\"0.61\", \"size\":\"132.18\", \"side\":\"SELL\", \"hash\":\"70e0c01e5bc2493217a49d113b5babd23ce7f53f\", \"best_bid\":\"0.56\", \"best_ask\":\"0.57\"}], \"timestamp\":\"1785204533240\", \"event_type\":\"price_change\"}","received_at":"2026-07-28T02:08:53.898438Z","schema_version":"clob-market-ws.price_change.v1","sequence":null,"server_hash":null,"server_timestamp":"1785204533240","session_id":"d2757dd6dad94f3b9fe67e8dbf1adc37","source":"clob_market_ws"},"received_at":"2026-07-28T02:08:53.898438Z","record_id":"33e7a82bb27454f5e551da8399b300a6fe83ad5ddcf56a5444bcc34c0616c663","schema_fingerprint":"4aa3821a28b0b7c2400bc59aba4bcc0a76e971dadd19610d3ad38c768e124dc7","schema_version":"edge-lab-recorder.raw.v1","sequence":null,"source":"clob_market_ws"}
