{"event_at":"2026-07-28T02:10:12.861000Z","event_fingerprint":"8009d6937fe9a4dd79a79a8dbafee638304069547e7b358bdddbf049cdb7a70a","payload":{"connection_id":"5d29200f65794d4d9ab6ef271f045a9b","event_at":"2026-07-28T02:10:12.861000Z","event_type":"price_change","frame_hash":"2bfffcf7f9cc77191c02a95a9a2dff08bbc92a2eff7318530a704a27cd5fd57e","frame_index":0,"kind":"data","monotonic_ns":306595941581625,"payload":{"event_type":"price_change","market":"0xda6f0e0e93fc8469e0159a166028d017bddbc162b86f66bac90391379603d962","price_changes":[{"asset_id":"20893381255801015515826997628594359667013752732428989472914000440642900266717","best_ask":"0.74","best_bid":"0.73","hash":"9538ab53fbe2a8937b83ee9f2b5cb42894d67b8f","price":"0.66","side":"BUY","size":"196"},{"asset_id":"39272994714739463168905443499424551362424437245880253267329605556587274644733","best_ask":"0.27","best_bid":"0.26","hash":"ea469dafe2bf1f5ee325b75eb95de0e1c5bfeb5f","price":"0.34","side":"SELL","size":"196"}],"timestamp":"1785204612861"},"payload_hash":"5b7892c5f4a137a6f1148d2e293ffae7860f823e07266b5fbb31e27aa6697aac","raw_frame":"{\"market\":\"0xda6f0e0e93fc8469e0159a166028d017bddbc162b86f66bac90391379603d962\", \"price_changes\":[{\"asset_id\":\"20893381255801015515826997628594359667013752732428989472914000440642900266717\", \"price\":\"0.66\", \"size\":\"196\", \"side\":\"BUY\", \"hash\":\"9538ab53fbe2a8937b83ee9f2b5cb42894d67b8f\", \"best_bid\":\"0.73\", \"best_ask\":\"0.74\"}, {\"asset_id\":\"39272994714739463168905443499424551362424437245880253267329605556587274644733\", \"price\":\"0.34\", \"size\":\"196\", \"side\":\"SELL\", \"hash\":\"ea469dafe2bf1f5ee325b75eb95de0e1c5bfeb5f\", \"best_bid\":\"0.26\", \"best_ask\":\"0.27\"}], \"timestamp\":\"1785204612861\", \"event_type\":\"price_change\"}","received_at":"2026-07-28T02:10:12.932455Z","schema_version":"clob-market-ws.price_change.v1","sequence":null,"server_hash":null,"server_timestamp":"1785204612861","session_id":"d2757dd6dad94f3b9fe67e8dbf1adc37","source":"clob_market_ws"},"received_at":"2026-07-28T02:10:12.932455Z","record_id":"3a2297ef58dd435fe1b0b270b84f14a636067077a9b3142e982bec0393b78fd7","schema_fingerprint":"4aa3821a28b0b7c2400bc59aba4bcc0a76e971dadd19610d3ad38c768e124dc7","schema_version":"edge-lab-recorder.raw.v1","sequence":null,"source":"clob_market_ws"}
{"event_at":"2026-07-28T02:10:12.865000Z","event_fingerprint":"d48f633fdfc2cacc231c0d9d9f1286dce85fe22551de708fe755d0d0e7929c0d","payload":{"connection_id":"5d29200f65794d4d9ab6ef271f045a9b","event_at":"2026-07-28T02:10:12.865000Z","event_type":"price_change","frame_hash":"ba9dd003d00588985983030ddaf911608a5485e93d694e2e4cd8b09c19290794","frame_index":0,"kind":"data","monotonic_ns":306595955766041,"payload":{"event_type":"price_change","market":"0xda6f0e0e93fc8469e0159a166028d017bddbc162b86f66bac90391379603d962","price_changes":[{"asset_id":"20893381255801015515826997628594359667013752732428989472914000440642900266717","best_ask":"0.74","best_bid":"0.73","hash":"f1974fcce3b92a667131bd6c0a2734d1f6ae3ee8","price":"0.71","side":"BUY","size":"101.1"},{"asset_id":"39272994714739463168905443499424551362424437245880253267329605556587274644733","best_ask":"0.27","best_bid":"0.26","hash":"1276b9a020bac57d15a3ea53bd3542b1bcb2caf0","price":"0.29","side":"SELL","size":"101.1"}],"timestamp":"1785204612865"},"payload_hash":"c02742278d0f5dca3c3c068756ef7caea46c373781151b29c3c25ce64991f70e","raw_frame":"{\"market\":\"0xda6f0e0e93fc8469e0159a166028d017bddbc162b86f66bac90391379603d962\", \"price_changes\":[{\"asset_id\":\"20893381255801015515826997628594359667013752732428989472914000440642900266717\", \"price\":\"0.71\", \"size\":\"101.1\", \"side\":\"BUY\", \"hash\":\"f1974fcce3b92a667131bd6c0a2734d1f6ae3ee8\", \"best_bid\":\"0.73\", \"best_ask\":\"0.74\"}, {\"asset_id\":\"39272994714739463168905443499424551362424437245880253267329605556587274644733\", \"price\":\"0.29\", \"size\":\"101.1\", \"side\":\"SELL\", \"hash\":\"1276b9a020bac57d15a3ea53bd3542b1bcb2caf0\", \"best_bid\":\"0.26\", \"best_ask\":\"0.27\"}], \"timestamp\":\"1785204612865\", \"event_type\":\"price_change\"}","received_at":"2026-07-28T02:10:12.946640Z","schema_version":"clob-market-ws.price_change.v1","sequence":null,"server_hash":null,"server_timestamp":"1785204612865","session_id":"d2757dd6dad94f3b9fe67e8dbf1adc37","source":"clob_market_ws"},"received_at":"2026-07-28T02:10:12.946640Z","record_id":"2cec989eb5295add77170e31cb9215b5d3e441194fd09265b708f1979237f422","schema_fingerprint":"4aa3821a28b0b7c2400bc59aba4bcc0a76e971dadd19610d3ad38c768e124dc7","schema_version":"edge-lab-recorder.raw.v1","sequence":null,"source":"clob_market_ws"}
{"event_at":"2026-07-28T02:10:12.871000Z","event_fingerprint":"48cacd148028a216b5890d0d4a04ded617d716be5a45a4871043e07139fdd01f","payload":{"connection_id":"5d29200f65794d4d9ab6ef271f045a9b","event_at":"2026-07-28T02:10:12.871000Z","event_type":"price_change","frame_hash":"4f5bc1a97aca5357c26c9473a1b4186a788dfa98211d84e3cf27c0be3a74f278","frame_index":0,"kind":"data","monotonic_ns":306595961173583,"payload":{"event_type":"price_change","market":"0xda6f0e0e93fc8469e0159a166028d017bddbc162b86f66bac90391379603d962","price_changes":[{"asset_id":"39272994714739463168905443499424551362424437245880253267329605556587274644733","best_ask":"0.27","best_bid":"0.26","hash":"3967ab99c9b543a3047aaf1e4ca8364ed4715fc7","price":"0.29","side":"SELL","size":"113.59"},{"asset_id":"20893381255801015515826997628594359667013752732428989472914000440642900266717","best_ask":"0.74","best_bid":"0.73","hash":"c0a67504532b7abd3538a94b391b517c530e969d","price":"0.71","side":"BUY","size":"113.59"}],"timestamp":"1785204612871"},"payload_hash":"64e8d9c81aa560fc21941915e711533ea9e0950303fda4a71e94db9404fdd620","raw_frame":"{\"market\":\"0xda6f0e0e93fc8469e0159a166028d017bddbc162b86f66bac90391379603d962\", \"price_changes\":[{\"asset_id\":\"39272994714739463168905443499424551362424437245880253267329605556587274644733\", \"price\":\"0.29\", \"size\":\"113.59\", \"side\":\"SELL\", \"hash\":\"3967ab99c9b543a3047aaf1e4ca8364ed4715fc7\", \"best_bid\":\"0.26\", \"best_ask\":\"0.27\"}, {\"asset_id\":\"20893381255801015515826997628594359667013752732428989472914000440642900266717\", \"price\":\"0.71\", \"size\":\"113.59\", \"side\":\"BUY\", \"hash\":\"c0a67504532b7abd3538a94b391b517c530e969d\", \"best_bid\":\"0.73\", \"best_ask\":\"0.74\"}], \"timestamp\":\"1785204612871\", \"event_type\":\"price_change\"}","received_at":"2026-07-28T02:10:12.952048Z","schema_version":"clob-market-ws.price_change.v1","sequence":null,"server_hash":null,"server_timestamp":"1785204612871","session_id":"d2757dd6dad94f3b9fe67e8dbf1adc37","source":"clob_market_ws"},"received_at":"2026-07-28T02:10:12.952048Z","record_id":"e33a37a7b1f5cabd28b623da0c170d275a4a969e11729ed6d36306e3c305d206","schema_fingerprint":"4aa3821a28b0b7c2400bc59aba4bcc0a76e971dadd19610d3ad38c768e124dc7","schema_version":"edge-lab-recorder.raw.v1","sequence":null,"source":"clob_market_ws"}
{"event_at":"2026-07-28T02:10:12.901000Z","event_fingerprint":"37e96103cb5bd14cd59f389ddf8be019b57f10b4ba13a26b4262c6388c0c289e","payload":{"connection_id":"5d29200f65794d4d9ab6ef271f045a9b","event_at":"2026-07-28T02:10:12.901000Z","event_type":"price_change","frame_hash":"275720c093840d73372ecd57c1b1480699d5b1c56489a59b4bc0226001c11bae","frame_index":0,"kind":"data","monotonic_ns":306595966113458,"payload":{"event_type":"price_change","market":"0xda6f0e0e93fc8469e0159a166028d017bddbc162b86f66bac90391379603d962","price_changes":[{"asset_id":"20893381255801015515826997628594359667013752732428989472914000440642900266717","best_ask":"0.74","best_bid":"0.73","hash":"7a55659c6dc3c831282a44b43a270e13331cbb4e","price":"0.74","side":"SELL","size":"22"},{"asset_id":"39272994714739463168905443499424551362424437245880253267329605556587274644733","best_ask":"0.27","best_bid":"0.26","hash":"1100ddab5bda5fed1209a10161ea8b9cbc48b328","price":"0.26","side":"BUY","size":"22"}],"timestamp":"1785204612901"},"payload_hash":"8c89a96ab98f588eb2140d7b99c49dccd46456020315af06c55696e37ddf599a","raw_frame":"{\"market\":\"0xda6f0e0e93fc8469e0159a166028d017bddbc162b86f66bac90391379603d962\", \"price_changes\":[{\"asset_id\":\"20893381255801015515826997628594359667013752732428989472914000440642900266717\", \"price\":\"0.74\", \"size\":\"22\", \"side\":\"SELL\", \"hash\":\"7a55659c6dc3c831282a44b43a270e13331cbb4e\", \"best_bid\":\"0.73\", \"best_ask\":\"0.74\"}, {\"asset_id\":\"39272994714739463168905443499424551362424437245880253267329605556587274644733\", \"price\":\"0.26\", \"size\":\"22\", \"side\":\"BUY\", \"hash\":\"1100ddab5bda5fed1209a10161ea8b9cbc48b328\", \"best_bid\":\"0.26\", \"best_ask\":\"0.27\"}], \"timestamp\":\"1785204612901\", \"event_type\":\"price_change\"}","received_at":"2026-07-28T02:10:12.956989Z","schema_version":"clob-market-ws.price_change.v1","sequence":null,"server_hash":null,"server_timestamp":"1785204612901","session_id":"d2757dd6dad94f3b9fe67e8dbf1adc37","source":"clob_market_ws"},"received_at":"2026-07-28T02:10:12.956989Z","record_id":"160bd9490bbad7c5f7eeb5be5638b8952e38b60d0b407f37448ef0e3f007ed30","schema_fingerprint":"4aa3821a28b0b7c2400bc59aba4bcc0a76e971dadd19610d3ad38c768e124dc7","schema_version":"edge-lab-recorder.raw.v1","sequence":null,"source":"clob_market_ws"}
{"event_at":"2026-07-28T02:10:12.911000Z","event_fingerprint":"ee6e0c4e485b80e48e2c73eb66a0a59c648baec46bc3a806cddd523b1e828b44","payload":{"connection_id":"5d29200f65794d4d9ab6ef271f045a9b","event_at":"2026-07-28T02:10:12.911000Z","event_type":"price_change","frame_hash":"7130d5c9bb76ca0120b2919587fc9895bc20bf9e9c6403db8462bcce28c16b32","frame_index":0,"kind":"data","monotonic_ns":306595978046541,"payload":{"event_type":"price_change","market":"0xda6f0e0e93fc8469e0159a166028d017bddbc162b86f66bac90391379603d962","price_changes":[{"asset_id":"20893381255801015515826997628594359667013752732428989472914000440642900266717","best_ask":"0.74","best_bid":"0.73","hash":"7a422b110260fd38d3f8d92e7fc99e6af2a8d94e","price":"0.66","side":"BUY","size":"181"},{"asset_id":"39272994714739463168905443499424551362424437245880253267329605556587274644733","best_ask":"0.27","best_bid":"0.26","hash":"54652be8ae86cced626f62c2efcf22fbd4bc79e1","price":"0.34","side":"SELL","size":"181"}],"timestamp":"1785204612911"},"payload_hash":"e372599027323586e0d4f4f2c31efc257a7980739cbe294f06de90fc9d823dbc","raw_frame":"{\"market\":\"0xda6f0e0e93fc8469e0159a166028d017bddbc162b86f66bac90391379603d962\", \"price_changes\":[{\"asset_id\":\"20893381255801015515826997628594359667013752732428989472914000440642900266717\", \"price\":\"0.66\", \"size\":\"181\", \"side\":\"BUY\", \"hash\":\"7a422b110260fd38d3f8d92e7fc99e6af2a8d94e\", \"best_bid\":\"0.73\", \"best_ask\":\"0.74\"}, {\"asset_id\":\"39272994714739463168905443499424551362424437245880253267329605556587274644733\", \"price\":\"0.34\", \"size\":\"181\", \"side\":\"SELL\", \"hash\":\"54652be8ae86cced626f62c2efcf22fbd4bc79e1\", \"best_bid\":\"0.26\", \"best_ask\":\"0.27\"}], \"timestamp\":\"1785204612911\", \"event_type\":\"price_change\"}","received_at":"2026-07-28T02:10:12.968923Z","schema_version":"clob-market-ws.price_change.v1","sequence":null,"server_hash":null,"server_timestamp":"1785204612911","session_id":"d2757dd6dad94f3b9fe67e8dbf1adc37","source":"clob_market_ws"},"received_at":"2026-07-28T02:10:12.968923Z","record_id":"0e780c711627649a4d5f85c055303084cdcd7a0e15313a391387c1dab96c659f","schema_fingerprint":"4aa3821a28b0b7c2400bc59aba4bcc0a76e971dadd19610d3ad38c768e124dc7","schema_version":"edge-lab-recorder.raw.v1","sequence":null,"source":"clob_market_ws"}
{"event_at":"2026-07-28T02:10:12.911000Z","event_fingerprint":"7d63a8328031c2fc7eccccc1644b9fedd1c6e9dcaf34946ec75d16b537a2feb2","payload":{"connection_id":"5d29200f65794d4d9ab6ef271f045a9b","event_at":"2026-07-28T02:10:12.911000Z","event_type":"price_change","frame_hash":"8774ee413c3ac9e5693c00623553b6c160589374de48cae805e1dad9c85981d0","frame_index":0,"kind":"data","monotonic_ns":306595985250875,"payload":{"event_type":"price_change","market":"0xda6f0e0e93fc8469e0159a166028d017bddbc162b86f66bac90391379603d962","price_changes":[{"asset_id":"20893381255801015515826997628594359667013752732428989472914000440642900266717","best_ask":"0.74","best_bid":"0.73","hash":"09d6f6fd6bd46366b50b43251833d0c557ae6542","price":"0.7","side":"BUY","size":"127.83"},{"asset_id":"39272994714739463168905443499424551362424437245880253267329605556587274644733","best_ask":"0.27","best_bid":"0.26","hash":"a121c23ce3b77966cf38621c2dd38515ddf4ccb5","price":"0.3","side":"SELL","size":"127.83"}],"timestamp":"1785204612911"},"payload_hash":"408abd353216ca537f41f0c49915263c0bf358a38909c8b219161e0700d30524","raw_frame":"{\"market\":\"0xda6f0e0e93fc8469e0159a166028d017bddbc162b86f66bac90391379603d962\", \"price_changes\":[{\"asset_id\":\"20893381255801015515826997628594359667013752732428989472914000440642900266717\", \"price\":\"0.7\", \"size\":\"127.83\", \"side\":\"BUY\", \"hash\":\"09d6f6fd6bd46366b50b43251833d0c557ae6542\", \"best_bid\":\"0.73\", \"best_ask\":\"0.74\"}, {\"asset_id\":\"39272994714739463168905443499424551362424437245880253267329605556587274644733\", \"price\":\"0.3\", \"size\":\"127.83\", \"side\":\"SELL\", \"hash\":\"a121c23ce3b77966cf38621c2dd38515ddf4ccb5\", \"best_bid\":\"0.26\", \"best_ask\":\"0.27\"}], \"timestamp\":\"1785204612911\", \"event_type\":\"price_change\"}","received_at":"2026-07-28T02:10:12.976126Z","schema_version":"clob-market-ws.price_change.v1","sequence":null,"server_hash":null,"server_timestamp":"1785204612911","session_id":"d2757dd6dad94f3b9fe67e8dbf1adc37","source":"clob_market_ws"},"received_at":"2026-07-28T02:10:12.976126Z","record_id":"8b26a9361ab853d18fe441ca086500ad15b6b905b42485bf63dc0748033e9800","schema_fingerprint":"4aa3821a28b0b7c2400bc59aba4bcc0a76e971dadd19610d3ad38c768e124dc7","schema_version":"edge-lab-recorder.raw.v1","sequence":null,"source":"clob_market_ws"}
{"event_at":"2026-07-28T02:10:12.912000Z","event_fingerprint":"2c7e8e51ed24d067fb957bcef3830109ff9cb260e09ff999fbe0b20891e38373","payload":{"connection_id":"5d29200f65794d4d9ab6ef271f045a9b","event_at":"2026-07-28T02:10:12.912000Z","event_type":"price_change","frame_hash":"a50b60ffb0917d80bb66f89782b3e992116cea4f916b18313444c025531b9f47","frame_index":0,"kind":"data","monotonic_ns":306596001193625,"payload":{"event_type":"price_change","market":"0xda6f0e0e93fc8469e0159a166028d017bddbc162b86f66bac90391379603d962","price_changes":[{"asset_id":"20893381255801015515826997628594359667013752732428989472914000440642900266717","best_ask":"0.74","best_bid":"0.73","hash":"c765934d23e96183401f784c7827c51a8b1211d4","price":"0.01","side":"BUY","size":"5682.02"},{"asset_id":"39272994714739463168905443499424551362424437245880253267329605556587274644733","best_ask":"0.27","best_bid":"0.26","hash":"44cac02e0dd02abcd93098bb45240132b1f70bbf","price":"0.99","side":"SELL","size":"5682.02"}],"timestamp":"1785204612912"},"payload_hash":"a448876417d75857199a90edfdcee77c72e3ff83da34a5f9772e28d9d1e5c1f3","raw_frame":"{\"market\":\"0xda6f0e0e93fc8469e0159a166028d017bddbc162b86f66bac90391379603d962\", \"price_changes\":[{\"asset_id\":\"20893381255801015515826997628594359667013752732428989472914000440642900266717\", \"price\":\"0.01\", \"size\":\"5682.02\", \"side\":\"BUY\", \"hash\":\"c765934d23e96183401f784c7827c51a8b1211d4\", \"best_bid\":\"0.73\", \"best_ask\":\"0.74\"}, {\"asset_id\":\"39272994714739463168905443499424551362424437245880253267329605556587274644733\", \"price\":\"0.99\", \"size\":\"5682.02\", \"side\":\"SELL\", \"hash\":\"44cac02e0dd02abcd93098bb45240132b1f70bbf\", \"best_bid\":\"0.26\", \"best_ask\":\"0.27\"}], \"timestamp\":\"1785204612912\", \"event_type\":\"price_change\"}","received_at":"2026-07-28T02:10:12.992063Z","schema_version":"clob-market-ws.price_change.v1","sequence":null,"server_hash":null,"server_timestamp":"1785204612912","session_id":"d2757dd6dad94f3b9fe67e8dbf1adc37","source":"clob_market_ws"},"received_at":"2026-07-28T02:10:12.992063Z","record_id":"27fffd88b78dbea5b1a5494748a5743930b1ebce0406ffa7ee7ee300f3530fdf","schema_fingerprint":"4aa3821a28b0b7c2400bc59aba4bcc0a76e971dadd19610d3ad38c768e124dc7","schema_version":"edge-lab-recorder.raw.v1","sequence":null,"source":"clob_market_ws"}
{"event_at":"2026-07-28T02:10:12.925000Z","event_fingerprint":"e3f4aae20eeef46a643bc0bca75cf970ff28097d95a0ad97614e391093672f8e","payload":{"connection_id":"5d29200f65794d4d9ab6ef271f045a9b","event_at":"2026-07-28T02:10:12.925000Z","event_type":"price_change","frame_hash":"60273a7173fbb519735c93b8e94e01969434075122bf515127cdff00f20bfb02","frame_index":0,"kind":"data","monotonic_ns":306596006298916,"payload":{"event_type":"price_change","market":"0xda6f0e0e93fc8469e0159a166028d017bddbc162b86f66bac90391379603d962","price_changes":[{"asset_id":"20893381255801015515826997628594359667013752732428989472914000440642900266717","best_ask":"0.74","best_bid":"0.73","hash":"0407fe18fa7bfa6078a53c5540ba08632a410668","price":"0.01","side":"BUY","size":"5687.02"},{"asset_id":"39272994714739463168905443499424551362424437245880253267329605556587274644733","best_ask":"0.27","best_bid":"0.26","hash":"b9cc548f558dd3b215df182a0f3719deaed0d668","price":"0.99","side":"SELL","size":"5687.02"}],"timestamp":"1785204612925"},"payload_hash":"5b1d19ca23afa6c9640264744e8228952ca18ffb8ddb130b7f33ef138a7848a6","raw_frame":"{\"market\":\"0xda6f0e0e93fc8469e0159a166028d017bddbc162b86f66bac90391379603d962\", \"price_changes\":[{\"asset_id\":\"20893381255801015515826997628594359667013752732428989472914000440642900266717\", \"price\":\"0.01\", \"size\":\"5687.02\", \"side\":\"BUY\", \"hash\":\"0407fe18fa7bfa6078a53c5540ba08632a410668\", \"best_bid\":\"0.73\", \"best_ask\":\"0.74\"}, {\"asset_id\":\"39272994714739463168905443499424551362424437245880253267329605556587274644733\", \"price\":\"0.99\", \"size\":\"5687.02\", \"side\":\"SELL\", \"hash\":\"b9cc548f558dd3b215df182a0f3719deaed0d668\", \"best_bid\":\"0.26\", \"best_ask\":\"0.27\"}], \"timestamp\":\"1785204612925\", \"event_type\":\"price_change\"}","received_at":"2026-07-28T02:10:12.997175Z","schema_version":"clob-market-ws.price_change.v1","sequence":null,"server_hash":null,"server_timestamp":"1785204612925","session_id":"d2757dd6dad94f3b9fe67e8dbf1adc37","source":"clob_market_ws"},"received_at":"2026-07-28T02:10:12.997175Z","record_id":"94d1e3e5ff0422f0253fbe939b5a66de93a09d8534b00e4e3c7a3e49f5f7d240","schema_fingerprint":"4aa3821a28b0b7c2400bc59aba4bcc0a76e971dadd19610d3ad38c768e124dc7","schema_version":"edge-lab-recorder.raw.v1","sequence":null,"source":"clob_market_ws"}
{"event_at":"2026-07-28T02:10:12.929000Z","event_fingerprint":"74d80df1f413fd7c00828d87a216a29defd3452a973804f85e626284d2003fab","payload":{"connection_id":"5d29200f65794d4d9ab6ef271f045a9b","event_at":"2026-07-28T02:10:12.929000Z","event_type":"price_change","frame_hash":"44a887c12d3321b8ef007d2a8c8f664521967c237e14a0eda84987763130ba85","frame_index":0,"kind":"data","monotonic_ns":306596011750791,"payload":{"event_type":"price_change","market":"0xda6f0e0e93fc8469e0159a166028d017bddbc162b86f66bac90391379603d962","price_changes":[{"asset_id":"20893381255801015515826997628594359667013752732428989472914000440642900266717","best_ask":"0.74","best_bid":"0.73","hash":"081d79725c696ab118fba044b31adb11f270263d","price":"0.01","side":"BUY","size":"5682.02"},{"asset_id":"39272994714739463168905443499424551362424437245880253267329605556587274644733","best_ask":"0.27","best_bid":"0.26","hash":"fb16e0940e74df2f63541d8c34bfec1487e8c6ec","price":"0.99","side":"SELL","size":"5682.02"}],"timestamp":"1785204612929"},"payload_hash":"e1e10ea6f077c18079417ffc0f7695201ec716401741f5c4ffdffa58a9a2b608","raw_frame":"{\"market\":\"0xda6f0e0e93fc8469e0159a166028d017bddbc162b86f66bac90391379603d962\", \"price_changes\":[{\"asset_id\":\"20893381255801015515826997628594359667013752732428989472914000440642900266717\", \"price\":\"0.01\", \"size\":\"5682.02\", \"side\":\"BUY\", \"hash\":\"081d79725c696ab118fba044b31adb11f270263d\", \"best_bid\":\"0.73\", \"best_ask\":\"0.74\"}, {\"asset_id\":\"39272994714739463168905443499424551362424437245880253267329605556587274644733\", \"price\":\"0.99\", \"size\":\"5682.02\", \"side\":\"SELL\", \"hash\":\"fb16e0940e74df2f63541d8c34bfec1487e8c6ec\", \"best_bid\":\"0.26\", \"best_ask\":\"0.27\"}], \"timestamp\":\"1785204612929\", \"event_type\":\"price_change\"}","received_at":"2026-07-28T02:10:13.002627Z","schema_version":"clob-market-ws.price_change.v1","sequence":null,"server_hash":null,"server_timestamp":"1785204612929","session_id":"d2757dd6dad94f3b9fe67e8dbf1adc37","source":"clob_market_ws"},"received_at":"2026-07-28T02:10:13.002627Z","record_id":"0ca6911f22d782b691a6145335d9288ac656c94d28241d4988478fba7fade0be","schema_fingerprint":"4aa3821a28b0b7c2400bc59aba4bcc0a76e971dadd19610d3ad38c768e124dc7","schema_version":"edge-lab-recorder.raw.v1","sequence":null,"source":"clob_market_ws"}
{"event_at":"2026-07-28T02:10:12.939000Z","event_fingerprint":"f8b17821ea1c6eec4e9f9c53a9ddb7b1a7c121686d241a9c06f2bf76ce60b668","payload":{"connection_id":"5d29200f65794d4d9ab6ef271f045a9b","event_at":"2026-07-28T02:10:12.939000Z","event_type":"price_change","frame_hash":"09b6fbfc7b0553f863cd7f15fe2736a11050234153de6ddd9c94cdef4a875a3c","frame_index":0,"kind":"data","monotonic_ns":306596017233625,"payload":{"event_type":"price_change","market":"0xda6f0e0e93fc8469e0159a166028d017bddbc162b86f66bac90391379603d962","price_changes":[{"asset_id":"20893381255801015515826997628594359667013752732428989472914000440642900266717","best_ask":"0.74","best_bid":"0.73","hash":"a8389ec7b5046a6e49d57bdb3ab73e36a975dfbe","price":"0.67","side":"BUY","size":"220.26"},{"asset_id":"39272994714739463168905443499424551362424437245880253267329605556587274644733","best_ask":"0.27","best_bid":"0.26","hash":"a2c0caf38793febaafc23034c136620ae9b7332c","price":"0.33","side":"SELL","size":"220.26"}],"timestamp":"1785204612939"},"payload_hash":"a081167303452f56b50ef384d3886a95ac00cc63b16ae2c0d9eaf845d2386e8a","raw_frame":"{\"market\":\"0xda6f0e0e93fc8469e0159a166028d017bddbc162b86f66bac90391379603d962\", \"price_changes\":[{\"asset_id\":\"20893381255801015515826997628594359667013752732428989472914000440642900266717\", \"price\":\"0.67\", \"size\":\"220.26\", \"side\":\"BUY\", \"hash\":\"a8389ec7b5046a6e49d57bdb3ab73e36a975dfbe\", \"best_bid\":\"0.73\", \"best_ask\":\"0.74\"}, {\"asset_id\":\"39272994714739463168905443499424551362424437245880253267329605556587274644733\", \"price\":\"0.33\", \"size\":\"220.26\", \"side\":\"SELL\", \"hash\":\"a2c0caf38793febaafc23034c136620ae9b7332c\", \"best_bid\":\"0.26\", \"best_ask\":\"0.27\"}], \"timestamp\":\"1785204612939\", \"event_type\":\"price_change\"}","received_at":"2026-07-28T02:10:13.008108Z","schema_version":"clob-market-ws.price_change.v1","sequence":null,"server_hash":null,"server_timestamp":"1785204612939","session_id":"d2757dd6dad94f3b9fe67e8dbf1adc37","source":"clob_market_ws"},"received_at":"2026-07-28T02:10:13.008108Z","record_id":"63c2d0157a77935ff81165f0eb61635bf9b72296ad644b9f40ac0eb44a21eaca","schema_fingerprint":"4aa3821a28b0b7c2400bc59aba4bcc0a76e971dadd19610d3ad38c768e124dc7","schema_version":"edge-lab-recorder.raw.v1","sequence":null,"source":"clob_market_ws"}
