{"event_at":"2026-07-28T02:07:49.342000Z","event_fingerprint":"6094f4862bbc2baca9ee5c3d35e9ca473e92418a9fe661a06c42ccac85d03446","payload":{"connection_id":"5d29200f65794d4d9ab6ef271f045a9b","event_at":"2026-07-28T02:07:49.342000Z","event_type":"price_change","frame_hash":"075ec69015cb5d67e448d72e722234bdace6ee3fdda5f0640ffc6ac8322cbbd8","frame_index":0,"kind":"data","monotonic_ns":306452522826750,"payload":{"event_type":"price_change","market":"0xda6f0e0e93fc8469e0159a166028d017bddbc162b86f66bac90391379603d962","price_changes":[{"asset_id":"39272994714739463168905443499424551362424437245880253267329605556587274644733","best_ask":"0.46","best_bid":"0.45","hash":"2f3ebc6ac38855e78bdf683be4ca166def279ba3","price":"0.43","side":"BUY","size":"91"},{"asset_id":"20893381255801015515826997628594359667013752732428989472914000440642900266717","best_ask":"0.55","best_bid":"0.54","hash":"d76d749e8949bc8328dafa622db7573159c5ec26","price":"0.57","side":"SELL","size":"91"}],"timestamp":"1785204469342"},"payload_hash":"f2214c66df0704344cfd4feb3b288fda8120701931df71c2aee1867dcf5086ab","raw_frame":"{\"market\":\"0xda6f0e0e93fc8469e0159a166028d017bddbc162b86f66bac90391379603d962\", \"price_changes\":[{\"asset_id\":\"39272994714739463168905443499424551362424437245880253267329605556587274644733\", \"price\":\"0.43\", \"size\":\"91\", \"side\":\"BUY\", \"hash\":\"2f3ebc6ac38855e78bdf683be4ca166def279ba3\", \"best_bid\":\"0.45\", \"best_ask\":\"0.46\"}, {\"asset_id\":\"20893381255801015515826997628594359667013752732428989472914000440642900266717\", \"price\":\"0.57\", \"size\":\"91\", \"side\":\"SELL\", \"hash\":\"d76d749e8949bc8328dafa622db7573159c5ec26\", \"best_bid\":\"0.54\", \"best_ask\":\"0.55\"}], \"timestamp\":\"1785204469342\", \"event_type\":\"price_change\"}","received_at":"2026-07-28T02:07:49.515125Z","schema_version":"clob-market-ws.price_change.v1","sequence":null,"server_hash":null,"server_timestamp":"1785204469342","session_id":"d2757dd6dad94f3b9fe67e8dbf1adc37","source":"clob_market_ws"},"received_at":"2026-07-28T02:07:49.515125Z","record_id":"706ea2b602bd93843f3655dbd0421264d27bd5c2c003a9631f15a871d415d52f","schema_fingerprint":"4aa3821a28b0b7c2400bc59aba4bcc0a76e971dadd19610d3ad38c768e124dc7","schema_version":"edge-lab-recorder.raw.v1","sequence":null,"source":"clob_market_ws"}
{"event_at":"2026-07-28T02:07:49.342000Z","event_fingerprint":"d1f530a5557063876a65b1afb98bc89a0f5f5ddb0f7d999829a96888aff9f86d","payload":{"connection_id":"5d29200f65794d4d9ab6ef271f045a9b","event_at":"2026-07-28T02:07:49.342000Z","event_type":"price_change","frame_hash":"05e74ec10b7f6c43e458b06582e2050c1d071df31a92aeceba583960320a502c","frame_index":0,"kind":"data","monotonic_ns":306452536197708,"payload":{"event_type":"price_change","market":"0xda6f0e0e93fc8469e0159a166028d017bddbc162b86f66bac90391379603d962","price_changes":[{"asset_id":"20893381255801015515826997628594359667013752732428989472914000440642900266717","best_ask":"0.55","best_bid":"0.54","hash":"51886a84650777f6bb8bf1da552041d252930906","price":"0.4","side":"BUY","size":"111.5"},{"asset_id":"39272994714739463168905443499424551362424437245880253267329605556587274644733","best_ask":"0.46","best_bid":"0.45","hash":"54a0069277af9b26d7a41350cc4a3dda545133d7","price":"0.6","side":"SELL","size":"111.5"}],"timestamp":"1785204469342"},"payload_hash":"f1962edca90c1ebd9fa0681c5a7dbe1e17489ec0fc14f48507ba062828feff89","raw_frame":"{\"market\":\"0xda6f0e0e93fc8469e0159a166028d017bddbc162b86f66bac90391379603d962\", \"price_changes\":[{\"asset_id\":\"20893381255801015515826997628594359667013752732428989472914000440642900266717\", \"price\":\"0.4\", \"size\":\"111.5\", \"side\":\"BUY\", \"hash\":\"51886a84650777f6bb8bf1da552041d252930906\", \"best_bid\":\"0.54\", \"best_ask\":\"0.55\"}, {\"asset_id\":\"39272994714739463168905443499424551362424437245880253267329605556587274644733\", \"price\":\"0.6\", \"size\":\"111.5\", \"side\":\"SELL\", \"hash\":\"54a0069277af9b26d7a41350cc4a3dda545133d7\", \"best_bid\":\"0.45\", \"best_ask\":\"0.46\"}], \"timestamp\":\"1785204469342\", \"event_type\":\"price_change\"}","received_at":"2026-07-28T02:07:49.528497Z","schema_version":"clob-market-ws.price_change.v1","sequence":null,"server_hash":null,"server_timestamp":"1785204469342","session_id":"d2757dd6dad94f3b9fe67e8dbf1adc37","source":"clob_market_ws"},"received_at":"2026-07-28T02:07:49.528497Z","record_id":"3c485592553af60bcdac0c8557c08b606a836ab1fa7485621b8826803858c2ba","schema_fingerprint":"4aa3821a28b0b7c2400bc59aba4bcc0a76e971dadd19610d3ad38c768e124dc7","schema_version":"edge-lab-recorder.raw.v1","sequence":null,"source":"clob_market_ws"}
{"event_at":"2026-07-28T02:07:49.342000Z","event_fingerprint":"76a3caff50020b659142c85cbf37bd1b89f4dfecaa9b57bb3bfb19bacd93d4a2","payload":{"connection_id":"5d29200f65794d4d9ab6ef271f045a9b","event_at":"2026-07-28T02:07:49.342000Z","event_type":"price_change","frame_hash":"2ce5c709a0a5de48e380d488e354f171fd19326bab85d15577a6e882398b5b95","frame_index":0,"kind":"data","monotonic_ns":306452542726708,"payload":{"event_type":"price_change","market":"0xda6f0e0e93fc8469e0159a166028d017bddbc162b86f66bac90391379603d962","price_changes":[{"asset_id":"20893381255801015515826997628594359667013752732428989472914000440642900266717","best_ask":"0.55","best_bid":"0.54","hash":"0cf5a55be2414eef67862a078efa9f7158f52e97","price":"0.53","side":"BUY","size":"41.6"},{"asset_id":"39272994714739463168905443499424551362424437245880253267329605556587274644733","best_ask":"0.46","best_bid":"0.45","hash":"a933bc51f0b030b28542fc9dd00f368cbaa09ddc","price":"0.47","side":"SELL","size":"41.6"}],"timestamp":"1785204469342"},"payload_hash":"8f8a4ac02a1ffa569dd05d21495f06d1259cbd4cd051ba8c36539aed3aa31dc8","raw_frame":"{\"market\":\"0xda6f0e0e93fc8469e0159a166028d017bddbc162b86f66bac90391379603d962\", \"price_changes\":[{\"asset_id\":\"20893381255801015515826997628594359667013752732428989472914000440642900266717\", \"price\":\"0.53\", \"size\":\"41.6\", \"side\":\"BUY\", \"hash\":\"0cf5a55be2414eef67862a078efa9f7158f52e97\", \"best_bid\":\"0.54\", \"best_ask\":\"0.55\"}, {\"asset_id\":\"39272994714739463168905443499424551362424437245880253267329605556587274644733\", \"price\":\"0.47\", \"size\":\"41.6\", \"side\":\"SELL\", \"hash\":\"a933bc51f0b030b28542fc9dd00f368cbaa09ddc\", \"best_bid\":\"0.45\", \"best_ask\":\"0.46\"}], \"timestamp\":\"1785204469342\", \"event_type\":\"price_change\"}","received_at":"2026-07-28T02:07:49.535025Z","schema_version":"clob-market-ws.price_change.v1","sequence":null,"server_hash":null,"server_timestamp":"1785204469342","session_id":"d2757dd6dad94f3b9fe67e8dbf1adc37","source":"clob_market_ws"},"received_at":"2026-07-28T02:07:49.535025Z","record_id":"9e228e0064352702cf185db34d52d3221c089de6a8e50343863052e4665dceb4","schema_fingerprint":"4aa3821a28b0b7c2400bc59aba4bcc0a76e971dadd19610d3ad38c768e124dc7","schema_version":"edge-lab-recorder.raw.v1","sequence":null,"source":"clob_market_ws"}
{"event_at":"2026-07-28T02:07:49.343000Z","event_fingerprint":"1a6825d2c2aee44a23d8de16f35841d7a91445c2013e5f9d8645749922dbdadf","payload":{"connection_id":"5d29200f65794d4d9ab6ef271f045a9b","event_at":"2026-07-28T02:07:49.343000Z","event_type":"price_change","frame_hash":"995368adadccbc0e05cdf5318548788c9cd8ab895ecb3eebafe7c22d84e260d5","frame_index":0,"kind":"data","monotonic_ns":306452548734291,"payload":{"event_type":"price_change","market":"0xda6f0e0e93fc8469e0159a166028d017bddbc162b86f66bac90391379603d962","price_changes":[{"asset_id":"20893381255801015515826997628594359667013752732428989472914000440642900266717","best_ask":"0.55","best_bid":"0.54","hash":"9a2542aa0993139f23c5a8b07cfcbed7dea86911","price":"0.45","side":"BUY","size":"88"},{"asset_id":"39272994714739463168905443499424551362424437245880253267329605556587274644733","best_ask":"0.46","best_bid":"0.45","hash":"40c79a2ce4fa96df54ff4106e815558e25236d34","price":"0.55","side":"SELL","size":"88"}],"timestamp":"1785204469343"},"payload_hash":"2315affee09c018760c844c999aa9f33e5d833267464f3d61625439af1e0c2eb","raw_frame":"{\"market\":\"0xda6f0e0e93fc8469e0159a166028d017bddbc162b86f66bac90391379603d962\", \"price_changes\":[{\"asset_id\":\"20893381255801015515826997628594359667013752732428989472914000440642900266717\", \"price\":\"0.45\", \"size\":\"88\", \"side\":\"BUY\", \"hash\":\"9a2542aa0993139f23c5a8b07cfcbed7dea86911\", \"best_bid\":\"0.54\", \"best_ask\":\"0.55\"}, {\"asset_id\":\"39272994714739463168905443499424551362424437245880253267329605556587274644733\", \"price\":\"0.55\", \"size\":\"88\", \"side\":\"SELL\", \"hash\":\"40c79a2ce4fa96df54ff4106e815558e25236d34\", \"best_bid\":\"0.45\", \"best_ask\":\"0.46\"}], \"timestamp\":\"1785204469343\", \"event_type\":\"price_change\"}","received_at":"2026-07-28T02:07:49.541034Z","schema_version":"clob-market-ws.price_change.v1","sequence":null,"server_hash":null,"server_timestamp":"1785204469343","session_id":"d2757dd6dad94f3b9fe67e8dbf1adc37","source":"clob_market_ws"},"received_at":"2026-07-28T02:07:49.541034Z","record_id":"bd1fd3490725c95a9e97061737db673a1dc1b37844b2d926b7f44bab4ba91f9a","schema_fingerprint":"4aa3821a28b0b7c2400bc59aba4bcc0a76e971dadd19610d3ad38c768e124dc7","schema_version":"edge-lab-recorder.raw.v1","sequence":null,"source":"clob_market_ws"}
{"event_at":"2026-07-28T02:07:49.344000Z","event_fingerprint":"387a08a00df5f03c5e42aab79a9839c7c29a50fc851cb275fba95aa6df46aff3","payload":{"connection_id":"5d29200f65794d4d9ab6ef271f045a9b","event_at":"2026-07-28T02:07:49.344000Z","event_type":"price_change","frame_hash":"e07d07040bc91bf86f3bb7bb14e62ce609bbf7f42bccacb996051272278b262e","frame_index":0,"kind":"data","monotonic_ns":306452555789791,"payload":{"event_type":"price_change","market":"0xda6f0e0e93fc8469e0159a166028d017bddbc162b86f66bac90391379603d962","price_changes":[{"asset_id":"20893381255801015515826997628594359667013752732428989472914000440642900266717","best_ask":"0.55","best_bid":"0.54","hash":"bdb52c67735707af6ba3a024173ddb936fa6a3f8","price":"0.41","side":"BUY","size":"77.4"},{"asset_id":"39272994714739463168905443499424551362424437245880253267329605556587274644733","best_ask":"0.46","best_bid":"0.45","hash":"26d3d25f5bdb3ffd23d96794216998f13b994d8d","price":"0.59","side":"SELL","size":"77.4"}],"timestamp":"1785204469344"},"payload_hash":"51305f30159df3c40348601ded9d65d062865051243a687dc98d81154be2afca","raw_frame":"{\"market\":\"0xda6f0e0e93fc8469e0159a166028d017bddbc162b86f66bac90391379603d962\", \"price_changes\":[{\"asset_id\":\"20893381255801015515826997628594359667013752732428989472914000440642900266717\", \"price\":\"0.41\", \"size\":\"77.4\", \"side\":\"BUY\", \"hash\":\"bdb52c67735707af6ba3a024173ddb936fa6a3f8\", \"best_bid\":\"0.54\", \"best_ask\":\"0.55\"}, {\"asset_id\":\"39272994714739463168905443499424551362424437245880253267329605556587274644733\", \"price\":\"0.59\", \"size\":\"77.4\", \"side\":\"SELL\", \"hash\":\"26d3d25f5bdb3ffd23d96794216998f13b994d8d\", \"best_bid\":\"0.45\", \"best_ask\":\"0.46\"}], \"timestamp\":\"1785204469344\", \"event_type\":\"price_change\"}","received_at":"2026-07-28T02:07:49.548087Z","schema_version":"clob-market-ws.price_change.v1","sequence":null,"server_hash":null,"server_timestamp":"1785204469344","session_id":"d2757dd6dad94f3b9fe67e8dbf1adc37","source":"clob_market_ws"},"received_at":"2026-07-28T02:07:49.548087Z","record_id":"f4feec94b530be401ce74669b4c717206b44aeb8ed8c1a41c4be863c6f5b062e","schema_fingerprint":"4aa3821a28b0b7c2400bc59aba4bcc0a76e971dadd19610d3ad38c768e124dc7","schema_version":"edge-lab-recorder.raw.v1","sequence":null,"source":"clob_market_ws"}
{"event_at":"2026-07-28T02:07:49.344000Z","event_fingerprint":"0ba6a234c1e7c78d49149b42c35c1be7a9b1842bba2f71807cc5a0616cd84654","payload":{"connection_id":"5d29200f65794d4d9ab6ef271f045a9b","event_at":"2026-07-28T02:07:49.344000Z","event_type":"price_change","frame_hash":"5719fe7ba3162d75a657bc4e36d45cb38a8ee52247252a16f221d046190fabdf","frame_index":0,"kind":"data","monotonic_ns":306452560135916,"payload":{"event_type":"price_change","market":"0xda6f0e0e93fc8469e0159a166028d017bddbc162b86f66bac90391379603d962","price_changes":[{"asset_id":"20893381255801015515826997628594359667013752732428989472914000440642900266717","best_ask":"0.55","best_bid":"0.54","hash":"21cfc8b146ece3a430e35bd08dec70261d3d02db","price":"0.45","side":"BUY","size":"118"},{"asset_id":"39272994714739463168905443499424551362424437245880253267329605556587274644733","best_ask":"0.46","best_bid":"0.45","hash":"501c496768d589c25011fee858f000ae66bbf562","price":"0.55","side":"SELL","size":"118"}],"timestamp":"1785204469344"},"payload_hash":"175ff6ddbdb9071855f82cd575b9288b393cd62a107db10cdfd715fd266c1964","raw_frame":"{\"market\":\"0xda6f0e0e93fc8469e0159a166028d017bddbc162b86f66bac90391379603d962\", \"price_changes\":[{\"asset_id\":\"20893381255801015515826997628594359667013752732428989472914000440642900266717\", \"price\":\"0.45\", \"size\":\"118\", \"side\":\"BUY\", \"hash\":\"21cfc8b146ece3a430e35bd08dec70261d3d02db\", \"best_bid\":\"0.54\", \"best_ask\":\"0.55\"}, {\"asset_id\":\"39272994714739463168905443499424551362424437245880253267329605556587274644733\", \"price\":\"0.55\", \"size\":\"118\", \"side\":\"SELL\", \"hash\":\"501c496768d589c25011fee858f000ae66bbf562\", \"best_bid\":\"0.45\", \"best_ask\":\"0.46\"}], \"timestamp\":\"1785204469344\", \"event_type\":\"price_change\"}","received_at":"2026-07-28T02:07:49.552434Z","schema_version":"clob-market-ws.price_change.v1","sequence":null,"server_hash":null,"server_timestamp":"1785204469344","session_id":"d2757dd6dad94f3b9fe67e8dbf1adc37","source":"clob_market_ws"},"received_at":"2026-07-28T02:07:49.552434Z","record_id":"fe0a19412ab0656b58bc7a40738b0b5e759d6c49ba6ba76a54294f1d5358e90c","schema_fingerprint":"4aa3821a28b0b7c2400bc59aba4bcc0a76e971dadd19610d3ad38c768e124dc7","schema_version":"edge-lab-recorder.raw.v1","sequence":null,"source":"clob_market_ws"}
{"event_at":"2026-07-28T02:07:49.345000Z","event_fingerprint":"6d6626d49ad17fc96558c65ffa6efb00ff84eb47feb96ea843646ba4481a4f92","payload":{"connection_id":"5d29200f65794d4d9ab6ef271f045a9b","event_at":"2026-07-28T02:07:49.345000Z","event_type":"price_change","frame_hash":"df0c6320fa5385d3b43ce233ec435df78aa2d8068039bcc3a807a91b39597d67","frame_index":0,"kind":"data","monotonic_ns":306452564014916,"payload":{"event_type":"price_change","market":"0xda6f0e0e93fc8469e0159a166028d017bddbc162b86f66bac90391379603d962","price_changes":[{"asset_id":"20893381255801015515826997628594359667013752732428989472914000440642900266717","best_ask":"0.55","best_bid":"0.54","hash":"d42a7510a8c4ad79d3a76c839c87e3e511e5af1d","price":"0.53","side":"BUY","size":"67.6"},{"asset_id":"39272994714739463168905443499424551362424437245880253267329605556587274644733","best_ask":"0.46","best_bid":"0.45","hash":"b7844a979c2063a4b2161917b5543b7dabc635cc","price":"0.47","side":"SELL","size":"67.6"}],"timestamp":"1785204469345"},"payload_hash":"5359a23f676cca120062cbf8074eed1d46261fdd5180909fc155e961b14f1245","raw_frame":"{\"market\":\"0xda6f0e0e93fc8469e0159a166028d017bddbc162b86f66bac90391379603d962\", \"price_changes\":[{\"asset_id\":\"20893381255801015515826997628594359667013752732428989472914000440642900266717\", \"price\":\"0.53\", \"size\":\"67.6\", \"side\":\"BUY\", \"hash\":\"d42a7510a8c4ad79d3a76c839c87e3e511e5af1d\", \"best_bid\":\"0.54\", \"best_ask\":\"0.55\"}, {\"asset_id\":\"39272994714739463168905443499424551362424437245880253267329605556587274644733\", \"price\":\"0.47\", \"size\":\"67.6\", \"side\":\"SELL\", \"hash\":\"b7844a979c2063a4b2161917b5543b7dabc635cc\", \"best_bid\":\"0.45\", \"best_ask\":\"0.46\"}], \"timestamp\":\"1785204469345\", \"event_type\":\"price_change\"}","received_at":"2026-07-28T02:07:49.556313Z","schema_version":"clob-market-ws.price_change.v1","sequence":null,"server_hash":null,"server_timestamp":"1785204469345","session_id":"d2757dd6dad94f3b9fe67e8dbf1adc37","source":"clob_market_ws"},"received_at":"2026-07-28T02:07:49.556313Z","record_id":"3bb085db9ed8cd5c3996aed8f046020f68ec4be72da4174a393354b9c54dc601","schema_fingerprint":"4aa3821a28b0b7c2400bc59aba4bcc0a76e971dadd19610d3ad38c768e124dc7","schema_version":"edge-lab-recorder.raw.v1","sequence":null,"source":"clob_market_ws"}
{"event_at":"2026-07-28T02:07:49.346000Z","event_fingerprint":"cdac4e12dae5383093e208b6802efe1ba750ed8cab561261847c76e94d34b544","payload":{"connection_id":"5d29200f65794d4d9ab6ef271f045a9b","event_at":"2026-07-28T02:07:49.346000Z","event_type":"price_change","frame_hash":"04e903a45abbbf32992a32b739ed80d66322ae88b4e443a597e34b957ac23702","frame_index":0,"kind":"data","monotonic_ns":306452567894708,"payload":{"event_type":"price_change","market":"0xda6f0e0e93fc8469e0159a166028d017bddbc162b86f66bac90391379603d962","price_changes":[{"asset_id":"39272994714739463168905443499424551362424437245880253267329605556587274644733","best_ask":"0.46","best_bid":"0.45","hash":"01b55428bbf5194ac1fcbe0771ef0dd0dcc68dcb","price":"0.27","side":"BUY","size":"80.2"},{"asset_id":"20893381255801015515826997628594359667013752732428989472914000440642900266717","best_ask":"0.55","best_bid":"0.54","hash":"44ed9db0d5cda7d4301323b8f91db4f405114b61","price":"0.73","side":"SELL","size":"80.2"}],"timestamp":"1785204469346"},"payload_hash":"66cd0bdb107f88ddd200fe6434ed862f47b9a77a7ddefbc4ef9c5a50ffb47d33","raw_frame":"{\"market\":\"0xda6f0e0e93fc8469e0159a166028d017bddbc162b86f66bac90391379603d962\", \"price_changes\":[{\"asset_id\":\"39272994714739463168905443499424551362424437245880253267329605556587274644733\", \"price\":\"0.27\", \"size\":\"80.2\", \"side\":\"BUY\", \"hash\":\"01b55428bbf5194ac1fcbe0771ef0dd0dcc68dcb\", \"best_bid\":\"0.45\", \"best_ask\":\"0.46\"}, {\"asset_id\":\"20893381255801015515826997628594359667013752732428989472914000440642900266717\", \"price\":\"0.73\", \"size\":\"80.2\", \"side\":\"SELL\", \"hash\":\"44ed9db0d5cda7d4301323b8f91db4f405114b61\", \"best_bid\":\"0.54\", \"best_ask\":\"0.55\"}], \"timestamp\":\"1785204469346\", \"event_type\":\"price_change\"}","received_at":"2026-07-28T02:07:49.560194Z","schema_version":"clob-market-ws.price_change.v1","sequence":null,"server_hash":null,"server_timestamp":"1785204469346","session_id":"d2757dd6dad94f3b9fe67e8dbf1adc37","source":"clob_market_ws"},"received_at":"2026-07-28T02:07:49.560194Z","record_id":"f08214948997d8ff0d9ba61f4b7d21a53f6d65559c647870dfcaca9564407028","schema_fingerprint":"4aa3821a28b0b7c2400bc59aba4bcc0a76e971dadd19610d3ad38c768e124dc7","schema_version":"edge-lab-recorder.raw.v1","sequence":null,"source":"clob_market_ws"}
{"event_at":"2026-07-28T02:07:49.348000Z","event_fingerprint":"d610f396cee1888526b3dacf836c10444c4a295879db7c80e868f29ea9581971","payload":{"connection_id":"5d29200f65794d4d9ab6ef271f045a9b","event_at":"2026-07-28T02:07:49.348000Z","event_type":"price_change","frame_hash":"a978b55953f0545c52fa7f30233c053ee952de57a55a07624862b99d742d460b","frame_index":0,"kind":"data","monotonic_ns":306452572292583,"payload":{"event_type":"price_change","market":"0xda6f0e0e93fc8469e0159a166028d017bddbc162b86f66bac90391379603d962","price_changes":[{"asset_id":"39272994714739463168905443499424551362424437245880253267329605556587274644733","best_ask":"0.46","best_bid":"0.45","hash":"8efcc60bcf9bb48436bb6af34060bef38c737683","price":"0.44","side":"BUY","size":"51"},{"asset_id":"20893381255801015515826997628594359667013752732428989472914000440642900266717","best_ask":"0.55","best_bid":"0.54","hash":"753ac5b2869c671da8076b7f9cd2cb94faa5d71a","price":"0.56","side":"SELL","size":"51"}],"timestamp":"1785204469348"},"payload_hash":"6535d9b0c11e4c42e0d899a805b4c5b27b6da3076b211cf1e50bcafddf36b2ca","raw_frame":"{\"market\":\"0xda6f0e0e93fc8469e0159a166028d017bddbc162b86f66bac90391379603d962\", \"price_changes\":[{\"asset_id\":\"39272994714739463168905443499424551362424437245880253267329605556587274644733\", \"price\":\"0.44\", \"size\":\"51\", \"side\":\"BUY\", \"hash\":\"8efcc60bcf9bb48436bb6af34060bef38c737683\", \"best_bid\":\"0.45\", \"best_ask\":\"0.46\"}, {\"asset_id\":\"20893381255801015515826997628594359667013752732428989472914000440642900266717\", \"price\":\"0.56\", \"size\":\"51\", \"side\":\"SELL\", \"hash\":\"753ac5b2869c671da8076b7f9cd2cb94faa5d71a\", \"best_bid\":\"0.54\", \"best_ask\":\"0.55\"}], \"timestamp\":\"1785204469348\", \"event_type\":\"price_change\"}","received_at":"2026-07-28T02:07:49.564591Z","schema_version":"clob-market-ws.price_change.v1","sequence":null,"server_hash":null,"server_timestamp":"1785204469348","session_id":"d2757dd6dad94f3b9fe67e8dbf1adc37","source":"clob_market_ws"},"received_at":"2026-07-28T02:07:49.564591Z","record_id":"59efcf1580a9b0f19fa5901ffa815e0da49c5a6c5de65f4c24725300b00c0862","schema_fingerprint":"4aa3821a28b0b7c2400bc59aba4bcc0a76e971dadd19610d3ad38c768e124dc7","schema_version":"edge-lab-recorder.raw.v1","sequence":null,"source":"clob_market_ws"}
{"event_at":"2026-07-28T02:07:49.350000Z","event_fingerprint":"c81cb30555bda32589eebc2b68afb88acb64937d7eeb971693c47bfd30c36dd4","payload":{"connection_id":"5d29200f65794d4d9ab6ef271f045a9b","event_at":"2026-07-28T02:07:49.350000Z","event_type":"price_change","frame_hash":"4a7784b2fcca1dddde1a6344085108ed0372a6f395f940aadc482e6ef1635007","frame_index":0,"kind":"data","monotonic_ns":306452576203625,"payload":{"event_type":"price_change","market":"0xda6f0e0e93fc8469e0159a166028d017bddbc162b86f66bac90391379603d962","price_changes":[{"asset_id":"20893381255801015515826997628594359667013752732428989472914000440642900266717","best_ask":"0.55","best_bid":"0.54","hash":"27639d96be0b61bd74ad009219bf821cfbe19292","price":"0.53","side":"BUY","size":"101.6"},{"asset_id":"39272994714739463168905443499424551362424437245880253267329605556587274644733","best_ask":"0.46","best_bid":"0.45","hash":"03a103835f5ad054b8c2f7fc632b943f7b3b8fcf","price":"0.47","side":"SELL","size":"101.6"}],"timestamp":"1785204469350"},"payload_hash":"144c537b3971062bd3ae4d216b10233ff0d9f3e9e65c06fd134a2be295b05cff","raw_frame":"{\"market\":\"0xda6f0e0e93fc8469e0159a166028d017bddbc162b86f66bac90391379603d962\", \"price_changes\":[{\"asset_id\":\"20893381255801015515826997628594359667013752732428989472914000440642900266717\", \"price\":\"0.53\", \"size\":\"101.6\", \"side\":\"BUY\", \"hash\":\"27639d96be0b61bd74ad009219bf821cfbe19292\", \"best_bid\":\"0.54\", \"best_ask\":\"0.55\"}, {\"asset_id\":\"39272994714739463168905443499424551362424437245880253267329605556587274644733\", \"price\":\"0.47\", \"size\":\"101.6\", \"side\":\"SELL\", \"hash\":\"03a103835f5ad054b8c2f7fc632b943f7b3b8fcf\", \"best_bid\":\"0.45\", \"best_ask\":\"0.46\"}], \"timestamp\":\"1785204469350\", \"event_type\":\"price_change\"}","received_at":"2026-07-28T02:07:49.568503Z","schema_version":"clob-market-ws.price_change.v1","sequence":null,"server_hash":null,"server_timestamp":"1785204469350","session_id":"d2757dd6dad94f3b9fe67e8dbf1adc37","source":"clob_market_ws"},"received_at":"2026-07-28T02:07:49.568503Z","record_id":"69f177eef17c0069a63580101467fe65acac8d2e72310d0ff416c53a7a93591b","schema_fingerprint":"4aa3821a28b0b7c2400bc59aba4bcc0a76e971dadd19610d3ad38c768e124dc7","schema_version":"edge-lab-recorder.raw.v1","sequence":null,"source":"clob_market_ws"}
{"event_at":"2026-07-28T02:07:49.350000Z","event_fingerprint":"d32168193832470003369d05ca6877ee46b9e800c927180c39876d1b63d168a8","payload":{"connection_id":"5d29200f65794d4d9ab6ef271f045a9b","event_at":"2026-07-28T02:07:49.350000Z","event_type":"price_change","frame_hash":"519de41982205290e576bd366e77918095ac1ff41ef0ee8ffb66ebb292ee57e4","frame_index":0,"kind":"data","monotonic_ns":306452580052375,"payload":{"event_type":"price_change","market":"0xda6f0e0e93fc8469e0159a166028d017bddbc162b86f66bac90391379603d962","price_changes":[{"asset_id":"20893381255801015515826997628594359667013752732428989472914000440642900266717","best_ask":"0.55","best_bid":"0.54","hash":"620f0ed23f6c14b12097810d45dcdf12c3d0983e","price":"0.54","side":"BUY","size":"44"},{"asset_id":"39272994714739463168905443499424551362424437245880253267329605556587274644733","best_ask":"0.46","best_bid":"0.45","hash":"9f38d3a9fe22abe1167402709ad7116b40339ee1","price":"0.46","side":"SELL","size":"44"}],"timestamp":"1785204469350"},"payload_hash":"a7162d3583bac032b7954a1515596fdd3abc1ec863a2e5ff42ccc1fc6ee96522","raw_frame":"{\"market\":\"0xda6f0e0e93fc8469e0159a166028d017bddbc162b86f66bac90391379603d962\", \"price_changes\":[{\"asset_id\":\"20893381255801015515826997628594359667013752732428989472914000440642900266717\", \"price\":\"0.54\", \"size\":\"44\", \"side\":\"BUY\", \"hash\":\"620f0ed23f6c14b12097810d45dcdf12c3d0983e\", \"best_bid\":\"0.54\", \"best_ask\":\"0.55\"}, {\"asset_id\":\"39272994714739463168905443499424551362424437245880253267329605556587274644733\", \"price\":\"0.46\", \"size\":\"44\", \"side\":\"SELL\", \"hash\":\"9f38d3a9fe22abe1167402709ad7116b40339ee1\", \"best_bid\":\"0.45\", \"best_ask\":\"0.46\"}], \"timestamp\":\"1785204469350\", \"event_type\":\"price_change\"}","received_at":"2026-07-28T02:07:49.572351Z","schema_version":"clob-market-ws.price_change.v1","sequence":null,"server_hash":null,"server_timestamp":"1785204469350","session_id":"d2757dd6dad94f3b9fe67e8dbf1adc37","source":"clob_market_ws"},"received_at":"2026-07-28T02:07:49.572351Z","record_id":"1ca3629be0ad0f763faf71235f55fe5367d1b6cb3dca93fc07fb6681d7ab0475","schema_fingerprint":"4aa3821a28b0b7c2400bc59aba4bcc0a76e971dadd19610d3ad38c768e124dc7","schema_version":"edge-lab-recorder.raw.v1","sequence":null,"source":"clob_market_ws"}
{"event_at":"2026-07-28T02:07:49.352000Z","event_fingerprint":"98714cf0e56aeb513a7adaa9f3172e658496b5539cb2c27620079b2cf6baff0e","payload":{"connection_id":"5d29200f65794d4d9ab6ef271f045a9b","event_at":"2026-07-28T02:07:49.352000Z","event_type":"price_change","frame_hash":"84b59528b45797ee91d3d6924989c28fd87328afdbb3c03dc847fdfa5946bc4f","frame_index":0,"kind":"data","monotonic_ns":306452583177583,"payload":{"event_type":"price_change","market":"0xda6f0e0e93fc8469e0159a166028d017bddbc162b86f66bac90391379603d962","price_changes":[{"asset_id":"39272994714739463168905443499424551362424437245880253267329605556587274644733","best_ask":"0.46","best_bid":"0.45","hash":"7800a9a1e103f4af69b8cd693aaf31647a14c6d8","price":"0.45","side":"BUY","size":"32.6"},{"asset_id":"20893381255801015515826997628594359667013752732428989472914000440642900266717","best_ask":"0.55","best_bid":"0.54","hash":"6eb92d49e650bfa5fcbf946a5547728d9beb41b1","price":"0.55","side":"SELL","size":"32.6"}],"timestamp":"1785204469352"},"payload_hash":"790897c56039cf5bda9f3d75363ad819e503c90d7e0ccb8ced29ebf95749130f","raw_frame":"{\"market\":\"0xda6f0e0e93fc8469e0159a166028d017bddbc162b86f66bac90391379603d962\", \"price_changes\":[{\"asset_id\":\"39272994714739463168905443499424551362424437245880253267329605556587274644733\", \"price\":\"0.45\", \"size\":\"32.6\", \"side\":\"BUY\", \"hash\":\"7800a9a1e103f4af69b8cd693aaf31647a14c6d8\", \"best_bid\":\"0.45\", \"best_ask\":\"0.46\"}, {\"asset_id\":\"20893381255801015515826997628594359667013752732428989472914000440642900266717\", \"price\":\"0.55\", \"size\":\"32.6\", \"side\":\"SELL\", \"hash\":\"6eb92d49e650bfa5fcbf946a5547728d9beb41b1\", \"best_bid\":\"0.54\", \"best_ask\":\"0.55\"}], \"timestamp\":\"1785204469352\", \"event_type\":\"price_change\"}","received_at":"2026-07-28T02:07:49.575474Z","schema_version":"clob-market-ws.price_change.v1","sequence":null,"server_hash":null,"server_timestamp":"1785204469352","session_id":"d2757dd6dad94f3b9fe67e8dbf1adc37","source":"clob_market_ws"},"received_at":"2026-07-28T02:07:49.575474Z","record_id":"66f483ff9c063dac270e7bbde4e8afa9652a6d9cc2666e4dcc78e893374d21b8","schema_fingerprint":"4aa3821a28b0b7c2400bc59aba4bcc0a76e971dadd19610d3ad38c768e124dc7","schema_version":"edge-lab-recorder.raw.v1","sequence":null,"source":"clob_market_ws"}
{"event_at":"2026-07-28T02:07:49.353000Z","event_fingerprint":"ed2c2e54b865f6474c9ab33b27e9064286f80c4b552c1f738466ed5c9e9aa198","payload":{"connection_id":"5d29200f65794d4d9ab6ef271f045a9b","event_at":"2026-07-28T02:07:49.353000Z","event_type":"price_change","frame_hash":"221baa901a02881e481997b022603a295215becb556629d00ed3dd2638ff930c","frame_index":0,"kind":"data","monotonic_ns":306452587569500,"payload":{"event_type":"price_change","market":"0xda6f0e0e93fc8469e0159a166028d017bddbc162b86f66bac90391379603d962","price_changes":[{"asset_id":"39272994714739463168905443499424551362424437245880253267329605556587274644733","best_ask":"0.46","best_bid":"0.45","hash":"63b0f262f98753ea21734d935871cb5120545a3b","price":"0.42","side":"BUY","size":"86"},{"asset_id":"20893381255801015515826997628594359667013752732428989472914000440642900266717","best_ask":"0.55","best_bid":"0.54","hash":"464e43e66beea14caf4a92333051b7221b727017","price":"0.58","side":"SELL","size":"86"}],"timestamp":"1785204469353"},"payload_hash":"d3d7e99c9520643e8fc957b064f131763b77358415aee6d533b67183ab1c5bd8","raw_frame":"{\"market\":\"0xda6f0e0e93fc8469e0159a166028d017bddbc162b86f66bac90391379603d962\", \"price_changes\":[{\"asset_id\":\"39272994714739463168905443499424551362424437245880253267329605556587274644733\", \"price\":\"0.42\", \"size\":\"86\", \"side\":\"BUY\", \"hash\":\"63b0f262f98753ea21734d935871cb5120545a3b\", \"best_bid\":\"0.45\", \"best_ask\":\"0.46\"}, {\"asset_id\":\"20893381255801015515826997628594359667013752732428989472914000440642900266717\", \"price\":\"0.58\", \"size\":\"86\", \"side\":\"SELL\", \"hash\":\"464e43e66beea14caf4a92333051b7221b727017\", \"best_bid\":\"0.54\", \"best_ask\":\"0.55\"}], \"timestamp\":\"1785204469353\", \"event_type\":\"price_change\"}","received_at":"2026-07-28T02:07:49.579866Z","schema_version":"clob-market-ws.price_change.v1","sequence":null,"server_hash":null,"server_timestamp":"1785204469353","session_id":"d2757dd6dad94f3b9fe67e8dbf1adc37","source":"clob_market_ws"},"received_at":"2026-07-28T02:07:49.579866Z","record_id":"64701ee949e9f8d18e36a9b30313cded469c83708c0f8ff8fde58732461c7283","schema_fingerprint":"4aa3821a28b0b7c2400bc59aba4bcc0a76e971dadd19610d3ad38c768e124dc7","schema_version":"edge-lab-recorder.raw.v1","sequence":null,"source":"clob_market_ws"}
{"event_at":"2026-07-28T02:07:49.354000Z","event_fingerprint":"f290b83162a7cefd9276109b4372cbb83e5d2efc57a0f3e021259b9e06857f02","payload":{"connection_id":"5d29200f65794d4d9ab6ef271f045a9b","event_at":"2026-07-28T02:07:49.354000Z","event_type":"price_change","frame_hash":"29cf2b440fd3cd167294b96b949c7b5b09d163306d34972f23372701594fae7e","frame_index":0,"kind":"data","monotonic_ns":306452591440625,"payload":{"event_type":"price_change","market":"0xda6f0e0e93fc8469e0159a166028d017bddbc162b86f66bac90391379603d962","price_changes":[{"asset_id":"20893381255801015515826997628594359667013752732428989472914000440642900266717","best_ask":"0.55","best_bid":"0.54","hash":"06ffee71153e4efce22ab3d965ae9661ee8a8ec1","price":"0.45","side":"BUY","size":"148"},{"asset_id":"39272994714739463168905443499424551362424437245880253267329605556587274644733","best_ask":"0.46","best_bid":"0.45","hash":"36b255a306969b25c6728c6217a39f7c3ea6c3a5","price":"0.55","side":"SELL","size":"148"}],"timestamp":"1785204469354"},"payload_hash":"920baa95626d615291fc66b12f233ad8a4614672bfe71ca5c41cb87cd46ba888","raw_frame":"{\"market\":\"0xda6f0e0e93fc8469e0159a166028d017bddbc162b86f66bac90391379603d962\", \"price_changes\":[{\"asset_id\":\"20893381255801015515826997628594359667013752732428989472914000440642900266717\", \"price\":\"0.45\", \"size\":\"148\", \"side\":\"BUY\", \"hash\":\"06ffee71153e4efce22ab3d965ae9661ee8a8ec1\", \"best_bid\":\"0.54\", \"best_ask\":\"0.55\"}, {\"asset_id\":\"39272994714739463168905443499424551362424437245880253267329605556587274644733\", \"price\":\"0.55\", \"size\":\"148\", \"side\":\"SELL\", \"hash\":\"36b255a306969b25c6728c6217a39f7c3ea6c3a5\", \"best_bid\":\"0.45\", \"best_ask\":\"0.46\"}], \"timestamp\":\"1785204469354\", \"event_type\":\"price_change\"}","received_at":"2026-07-28T02:07:49.583739Z","schema_version":"clob-market-ws.price_change.v1","sequence":null,"server_hash":null,"server_timestamp":"1785204469354","session_id":"d2757dd6dad94f3b9fe67e8dbf1adc37","source":"clob_market_ws"},"received_at":"2026-07-28T02:07:49.583739Z","record_id":"46c8600b1abdc592d7c84dbe3f00f873216da2969be32bb4e254e73fc3a18311","schema_fingerprint":"4aa3821a28b0b7c2400bc59aba4bcc0a76e971dadd19610d3ad38c768e124dc7","schema_version":"edge-lab-recorder.raw.v1","sequence":null,"source":"clob_market_ws"}
{"event_at":"2026-07-28T02:07:49.355000Z","event_fingerprint":"05e1ed5ed17f5a25ade2a51a5a898fe2e318f4ec0e49115a06e3f3d75dc881d4","payload":{"connection_id":"5d29200f65794d4d9ab6ef271f045a9b","event_at":"2026-07-28T02:07:49.355000Z","event_type":"price_change","frame_hash":"341876a8d9b9bfbebb0694c9807ce41a8771bbf817e5a84f64489dea086ad22b","frame_index":0,"kind":"data","monotonic_ns":306452595437666,"payload":{"event_type":"price_change","market":"0xda6f0e0e93fc8469e0159a166028d017bddbc162b86f66bac90391379603d962","price_changes":[{"asset_id":"20893381255801015515826997628594359667013752732428989472914000440642900266717","best_ask":"0.55","best_bid":"0.54","hash":"f9a5bc632a63d64fe37d88868523638b4732257b","price":"0.52","side":"BUY","size":"183.2"},{"asset_id":"39272994714739463168905443499424551362424437245880253267329605556587274644733","best_ask":"0.46","best_bid":"0.45","hash":"ce04b405203f5f266fcd101a9471be46e2cba791","price":"0.48","side":"SELL","size":"183.2"}],"timestamp":"1785204469355"},"payload_hash":"b0247ea42990bc64799f49a0a4715971add1ea23350e3c69f85738947d676af8","raw_frame":"{\"market\":\"0xda6f0e0e93fc8469e0159a166028d017bddbc162b86f66bac90391379603d962\", \"price_changes\":[{\"asset_id\":\"20893381255801015515826997628594359667013752732428989472914000440642900266717\", \"price\":\"0.52\", \"size\":\"183.2\", \"side\":\"BUY\", \"hash\":\"f9a5bc632a63d64fe37d88868523638b4732257b\", \"best_bid\":\"0.54\", \"best_ask\":\"0.55\"}, {\"asset_id\":\"39272994714739463168905443499424551362424437245880253267329605556587274644733\", \"price\":\"0.48\", \"size\":\"183.2\", \"side\":\"SELL\", \"hash\":\"ce04b405203f5f266fcd101a9471be46e2cba791\", \"best_bid\":\"0.45\", \"best_ask\":\"0.46\"}], \"timestamp\":\"1785204469355\", \"event_type\":\"price_change\"}","received_at":"2026-07-28T02:07:49.587736Z","schema_version":"clob-market-ws.price_change.v1","sequence":null,"server_hash":null,"server_timestamp":"1785204469355","session_id":"d2757dd6dad94f3b9fe67e8dbf1adc37","source":"clob_market_ws"},"received_at":"2026-07-28T02:07:49.587736Z","record_id":"105d470b749377a4196a5f969d96d083b6a12138e0b4506617f37e0511aa18c0","schema_fingerprint":"4aa3821a28b0b7c2400bc59aba4bcc0a76e971dadd19610d3ad38c768e124dc7","schema_version":"edge-lab-recorder.raw.v1","sequence":null,"source":"clob_market_ws"}
{"event_at":"2026-07-28T02:07:49.356000Z","event_fingerprint":"bf18fd96594291aade3d2c0df3980ebed2ee7530f07d9a6c92251bbf35115bec","payload":{"connection_id":"5d29200f65794d4d9ab6ef271f045a9b","event_at":"2026-07-28T02:07:49.356000Z","event_type":"price_change","frame_hash":"14170516ea54fdaf98aaf5ecc2cac05e46235ca81c91f9ee74f7b7c802a00b48","frame_index":0,"kind":"data","monotonic_ns":306452599798916,"payload":{"event_type":"price_change","market":"0xda6f0e0e93fc8469e0159a166028d017bddbc162b86f66bac90391379603d962","price_changes":[{"asset_id":"20893381255801015515826997628594359667013752732428989472914000440642900266717","best_ask":"0.55","best_bid":"0.54","hash":"5393215c2fd546d88a69bb50a2c294f6e7dcd9f7","price":"0.53","side":"BUY","size":"106.6"},{"asset_id":"39272994714739463168905443499424551362424437245880253267329605556587274644733","best_ask":"0.46","best_bid":"0.45","hash":"c796cbd0c1a9faef1bc2e9d31543687992fbee00","price":"0.47","side":"SELL","size":"106.6"}],"timestamp":"1785204469356"},"payload_hash":"8f3675bfe8aced9a90e92f966afed41fc948c25f420f093f08269258120ddaff","raw_frame":"{\"market\":\"0xda6f0e0e93fc8469e0159a166028d017bddbc162b86f66bac90391379603d962\", \"price_changes\":[{\"asset_id\":\"20893381255801015515826997628594359667013752732428989472914000440642900266717\", \"price\":\"0.53\", \"size\":\"106.6\", \"side\":\"BUY\", \"hash\":\"5393215c2fd546d88a69bb50a2c294f6e7dcd9f7\", \"best_bid\":\"0.54\", \"best_ask\":\"0.55\"}, {\"asset_id\":\"39272994714739463168905443499424551362424437245880253267329605556587274644733\", \"price\":\"0.47\", \"size\":\"106.6\", \"side\":\"SELL\", \"hash\":\"c796cbd0c1a9faef1bc2e9d31543687992fbee00\", \"best_bid\":\"0.45\", \"best_ask\":\"0.46\"}], \"timestamp\":\"1785204469356\", \"event_type\":\"price_change\"}","received_at":"2026-07-28T02:07:49.592097Z","schema_version":"clob-market-ws.price_change.v1","sequence":null,"server_hash":null,"server_timestamp":"1785204469356","session_id":"d2757dd6dad94f3b9fe67e8dbf1adc37","source":"clob_market_ws"},"received_at":"2026-07-28T02:07:49.592097Z","record_id":"22d60497fed929834af49947861dfe5f4a561db05a78fd73572b731454d8808e","schema_fingerprint":"4aa3821a28b0b7c2400bc59aba4bcc0a76e971dadd19610d3ad38c768e124dc7","schema_version":"edge-lab-recorder.raw.v1","sequence":null,"source":"clob_market_ws"}
{"event_at":"2026-07-28T02:07:49.356000Z","event_fingerprint":"3b86a65b34937e295b2bae01e318188c6f859f8f3bb9d973d6c76b7a1007ae3c","payload":{"connection_id":"5d29200f65794d4d9ab6ef271f045a9b","event_at":"2026-07-28T02:07:49.356000Z","event_type":"price_change","frame_hash":"e67e4065b22558e383f00d4960fc679c6b0348a9abfa71bcfae23c7b1538a953","frame_index":0,"kind":"data","monotonic_ns":306452602817625,"payload":{"event_type":"price_change","market":"0xda6f0e0e93fc8469e0159a166028d017bddbc162b86f66bac90391379603d962","price_changes":[{"asset_id":"39272994714739463168905443499424551362424437245880253267329605556587274644733","best_ask":"0.46","best_bid":"0.45","hash":"56ba09f79a90ffd785f240127558a1cce967e4ce","price":"0.45","side":"BUY","size":"12.6"},{"asset_id":"20893381255801015515826997628594359667013752732428989472914000440642900266717","best_ask":"0.55","best_bid":"0.54","hash":"7721e9e445ba83e97aa6eba38bbc49f8c7ebb364","price":"0.55","side":"SELL","size":"12.6"}],"timestamp":"1785204469356"},"payload_hash":"db96dcb9bf1d4c46c0305defce6b368f18304bc490c1544e38081b6f1a341e3e","raw_frame":"{\"market\":\"0xda6f0e0e93fc8469e0159a166028d017bddbc162b86f66bac90391379603d962\", \"price_changes\":[{\"asset_id\":\"39272994714739463168905443499424551362424437245880253267329605556587274644733\", \"price\":\"0.45\", \"size\":\"12.6\", \"side\":\"BUY\", \"hash\":\"56ba09f79a90ffd785f240127558a1cce967e4ce\", \"best_bid\":\"0.45\", \"best_ask\":\"0.46\"}, {\"asset_id\":\"20893381255801015515826997628594359667013752732428989472914000440642900266717\", \"price\":\"0.55\", \"size\":\"12.6\", \"side\":\"SELL\", \"hash\":\"7721e9e445ba83e97aa6eba38bbc49f8c7ebb364\", \"best_bid\":\"0.54\", \"best_ask\":\"0.55\"}], \"timestamp\":\"1785204469356\", \"event_type\":\"price_change\"}","received_at":"2026-07-28T02:07:49.595116Z","schema_version":"clob-market-ws.price_change.v1","sequence":null,"server_hash":null,"server_timestamp":"1785204469356","session_id":"d2757dd6dad94f3b9fe67e8dbf1adc37","source":"clob_market_ws"},"received_at":"2026-07-28T02:07:49.595116Z","record_id":"8c64d69c0bcc1267561fd8c61c5a64ddf3934f8fb99c0643ee6c15ddae206b06","schema_fingerprint":"4aa3821a28b0b7c2400bc59aba4bcc0a76e971dadd19610d3ad38c768e124dc7","schema_version":"edge-lab-recorder.raw.v1","sequence":null,"source":"clob_market_ws"}
{"event_at":"2026-07-28T02:07:49.357000Z","event_fingerprint":"e4b0887669b9bf5467554d931a24b16f0a32a8059f9235a6448f55db57f80cf1","payload":{"connection_id":"5d29200f65794d4d9ab6ef271f045a9b","event_at":"2026-07-28T02:07:49.357000Z","event_type":"price_change","frame_hash":"e98bc2edc298ab633b57270c50b38a9aa773b4dc5a6fcb056ee9db979772a14d","frame_index":0,"kind":"data","monotonic_ns":306452606715166,"payload":{"event_type":"price_change","market":"0xda6f0e0e93fc8469e0159a166028d017bddbc162b86f66bac90391379603d962","price_changes":[{"asset_id":"39272994714739463168905443499424551362424437245880253267329605556587274644733","best_ask":"0.46","best_bid":"0.45","hash":"5faa7ca21d4dc840f33b3199dd00a235f8956308","price":"0.44","side":"BUY","size":"75"},{"asset_id":"20893381255801015515826997628594359667013752732428989472914000440642900266717","best_ask":"0.55","best_bid":"0.54","hash":"eb7c16b9e9dad231a0985106ae9569cf56fe7ac1","price":"0.56","side":"SELL","size":"75"}],"timestamp":"1785204469357"},"payload_hash":"b244f31355c5f7d1dfc34a25d1ac988719402e5a7fd9abff328f723adb069a9d","raw_frame":"{\"market\":\"0xda6f0e0e93fc8469e0159a166028d017bddbc162b86f66bac90391379603d962\", \"price_changes\":[{\"asset_id\":\"39272994714739463168905443499424551362424437245880253267329605556587274644733\", \"price\":\"0.44\", \"size\":\"75\", \"side\":\"BUY\", \"hash\":\"5faa7ca21d4dc840f33b3199dd00a235f8956308\", \"best_bid\":\"0.45\", \"best_ask\":\"0.46\"}, {\"asset_id\":\"20893381255801015515826997628594359667013752732428989472914000440642900266717\", \"price\":\"0.56\", \"size\":\"75\", \"side\":\"SELL\", \"hash\":\"eb7c16b9e9dad231a0985106ae9569cf56fe7ac1\", \"best_bid\":\"0.54\", \"best_ask\":\"0.55\"}], \"timestamp\":\"1785204469357\", \"event_type\":\"price_change\"}","received_at":"2026-07-28T02:07:49.599014Z","schema_version":"clob-market-ws.price_change.v1","sequence":null,"server_hash":null,"server_timestamp":"1785204469357","session_id":"d2757dd6dad94f3b9fe67e8dbf1adc37","source":"clob_market_ws"},"received_at":"2026-07-28T02:07:49.599014Z","record_id":"8a380c782dca5608c5f8de7ee08f0462de62d37ce24ee64c26b19893a2cdf25a","schema_fingerprint":"4aa3821a28b0b7c2400bc59aba4bcc0a76e971dadd19610d3ad38c768e124dc7","schema_version":"edge-lab-recorder.raw.v1","sequence":null,"source":"clob_market_ws"}
{"event_at":"2026-07-28T02:07:49.358000Z","event_fingerprint":"a364530cd3c4c67aa49c0e09d66c943f89f7918fb93f7be74d77a6701a4e5ef2","payload":{"connection_id":"5d29200f65794d4d9ab6ef271f045a9b","event_at":"2026-07-28T02:07:49.358000Z","event_type":"price_change","frame_hash":"551dc43526ba685f3ad4364017369eb680e26962a41798f73dc11b44516539a1","frame_index":0,"kind":"data","monotonic_ns":306452610180791,"payload":{"event_type":"price_change","market":"0xda6f0e0e93fc8469e0159a166028d017bddbc162b86f66bac90391379603d962","price_changes":[{"asset_id":"20893381255801015515826997628594359667013752732428989472914000440642900266717","best_ask":"0.55","best_bid":"0.54","hash":"43a5cbbd2ccbe946a8711e63a472478489ae6668","price":"0.53","side":"BUY","size":"140.6"},{"asset_id":"39272994714739463168905443499424551362424437245880253267329605556587274644733","best_ask":"0.46","best_bid":"0.45","hash":"7042b5a4704fd8b354e66d6e4e8b424cdf1a554c","price":"0.47","side":"SELL","size":"140.6"}],"timestamp":"1785204469358"},"payload_hash":"4a9c5f0363537a21c73403a3d13ebbeaea9118eee11af68e7c39f401d50a8050","raw_frame":"{\"market\":\"0xda6f0e0e93fc8469e0159a166028d017bddbc162b86f66bac90391379603d962\", \"price_changes\":[{\"asset_id\":\"20893381255801015515826997628594359667013752732428989472914000440642900266717\", \"price\":\"0.53\", \"size\":\"140.6\", \"side\":\"BUY\", \"hash\":\"43a5cbbd2ccbe946a8711e63a472478489ae6668\", \"best_bid\":\"0.54\", \"best_ask\":\"0.55\"}, {\"asset_id\":\"39272994714739463168905443499424551362424437245880253267329605556587274644733\", \"price\":\"0.47\", \"size\":\"140.6\", \"side\":\"SELL\", \"hash\":\"7042b5a4704fd8b354e66d6e4e8b424cdf1a554c\", \"best_bid\":\"0.45\", \"best_ask\":\"0.46\"}], \"timestamp\":\"1785204469358\", \"event_type\":\"price_change\"}","received_at":"2026-07-28T02:07:49.602479Z","schema_version":"clob-market-ws.price_change.v1","sequence":null,"server_hash":null,"server_timestamp":"1785204469358","session_id":"d2757dd6dad94f3b9fe67e8dbf1adc37","source":"clob_market_ws"},"received_at":"2026-07-28T02:07:49.602479Z","record_id":"46a8d0be94b0b4b54bfd642bf65f44a85b6b265f94ce5180ed0b6f40ffd6a89d","schema_fingerprint":"4aa3821a28b0b7c2400bc59aba4bcc0a76e971dadd19610d3ad38c768e124dc7","schema_version":"edge-lab-recorder.raw.v1","sequence":null,"source":"clob_market_ws"}
{"event_at":"2026-07-28T02:07:49.358000Z","event_fingerprint":"3d9558eeb58002d8d23a7ec15f5bd9b77c18ce37005350d0e10d66b8a2c4c76f","payload":{"connection_id":"5d29200f65794d4d9ab6ef271f045a9b","event_at":"2026-07-28T02:07:49.358000Z","event_type":"price_change","frame_hash":"b516722b7db53df16e08810fed764aed8edc8b4123e970526744484752d126af","frame_index":0,"kind":"data","monotonic_ns":306452614094708,"payload":{"event_type":"price_change","market":"0xda6f0e0e93fc8469e0159a166028d017bddbc162b86f66bac90391379603d962","price_changes":[{"asset_id":"20893381255801015515826997628594359667013752732428989472914000440642900266717","best_ask":"0.55","best_bid":"0.54","hash":"ac47367213d6eed069a750865663c0b64837c8e9","price":"0.4","side":"BUY","size":"106.5"},{"asset_id":"39272994714739463168905443499424551362424437245880253267329605556587274644733","best_ask":"0.46","best_bid":"0.45","hash":"a3f1f81295aaf72f98c9b2eb5dd13777a8a8363a","price":"0.6","side":"SELL","size":"106.5"}],"timestamp":"1785204469358"},"payload_hash":"fbf52d21445d6a379bec151e0bf1acdd9e25bb82dd301d466913638c8f9b805c","raw_frame":"{\"market\":\"0xda6f0e0e93fc8469e0159a166028d017bddbc162b86f66bac90391379603d962\", \"price_changes\":[{\"asset_id\":\"20893381255801015515826997628594359667013752732428989472914000440642900266717\", \"price\":\"0.4\", \"size\":\"106.5\", \"side\":\"BUY\", \"hash\":\"ac47367213d6eed069a750865663c0b64837c8e9\", \"best_bid\":\"0.54\", \"best_ask\":\"0.55\"}, {\"asset_id\":\"39272994714739463168905443499424551362424437245880253267329605556587274644733\", \"price\":\"0.6\", \"size\":\"106.5\", \"side\":\"SELL\", \"hash\":\"a3f1f81295aaf72f98c9b2eb5dd13777a8a8363a\", \"best_bid\":\"0.45\", \"best_ask\":\"0.46\"}], \"timestamp\":\"1785204469358\", \"event_type\":\"price_change\"}","received_at":"2026-07-28T02:07:49.606393Z","schema_version":"clob-market-ws.price_change.v1","sequence":null,"server_hash":null,"server_timestamp":"1785204469358","session_id":"d2757dd6dad94f3b9fe67e8dbf1adc37","source":"clob_market_ws"},"received_at":"2026-07-28T02:07:49.606393Z","record_id":"570c065a3604648cebe406936bb7069c71a622c42f96cc2cc592e3c3d0fd310e","schema_fingerprint":"4aa3821a28b0b7c2400bc59aba4bcc0a76e971dadd19610d3ad38c768e124dc7","schema_version":"edge-lab-recorder.raw.v1","sequence":null,"source":"clob_market_ws"}
{"event_at":"2026-07-28T02:07:49.358000Z","event_fingerprint":"7433b0d523caf71e14e6d468cc79cd41d203373b2829bcc20325765e39ab96cb","payload":{"connection_id":"5d29200f65794d4d9ab6ef271f045a9b","event_at":"2026-07-28T02:07:49.358000Z","event_type":"price_change","frame_hash":"fa3931f7e39c42ed51b3efde6faf5019dedb016465a8bf4cd26277dc0128ac72","frame_index":0,"kind":"data","monotonic_ns":306452625558875,"payload":{"event_type":"price_change","market":"0xda6f0e0e93fc8469e0159a166028d017bddbc162b86f66bac90391379603d962","price_changes":[{"asset_id":"20893381255801015515826997628594359667013752732428989472914000440642900266717","best_ask":"0.55","best_bid":"0.54","hash":"44fa8fc3d075b315549ec7a0f3ca679d1eb919d3","price":"0.53","side":"BUY","size":"159.6"},{"asset_id":"39272994714739463168905443499424551362424437245880253267329605556587274644733","best_ask":"0.46","best_bid":"0.45","hash":"53566283809b3ce998115f24377a54fc55dd03d9","price":"0.47","side":"SELL","size":"159.6"}],"timestamp":"1785204469358"},"payload_hash":"dbb44b9702b1fe911a517781d9ef165e04f34be0bc80d955df17b0616f77cb2e","raw_frame":"{\"market\":\"0xda6f0e0e93fc8469e0159a166028d017bddbc162b86f66bac90391379603d962\", \"price_changes\":[{\"asset_id\":\"20893381255801015515826997628594359667013752732428989472914000440642900266717\", \"price\":\"0.53\", \"size\":\"159.6\", \"side\":\"BUY\", \"hash\":\"44fa8fc3d075b315549ec7a0f3ca679d1eb919d3\", \"best_bid\":\"0.54\", \"best_ask\":\"0.55\"}, {\"asset_id\":\"39272994714739463168905443499424551362424437245880253267329605556587274644733\", \"price\":\"0.47\", \"size\":\"159.6\", \"side\":\"SELL\", \"hash\":\"53566283809b3ce998115f24377a54fc55dd03d9\", \"best_bid\":\"0.45\", \"best_ask\":\"0.46\"}], \"timestamp\":\"1785204469358\", \"event_type\":\"price_change\"}","received_at":"2026-07-28T02:07:49.617857Z","schema_version":"clob-market-ws.price_change.v1","sequence":null,"server_hash":null,"server_timestamp":"1785204469358","session_id":"d2757dd6dad94f3b9fe67e8dbf1adc37","source":"clob_market_ws"},"received_at":"2026-07-28T02:07:49.617857Z","record_id":"235a77c02809d4b38792d9c77ab57f3ec2825390fea73f7f60231cef89467297","schema_fingerprint":"4aa3821a28b0b7c2400bc59aba4bcc0a76e971dadd19610d3ad38c768e124dc7","schema_version":"edge-lab-recorder.raw.v1","sequence":null,"source":"clob_market_ws"}
{"event_at":"2026-07-28T02:07:49.359000Z","event_fingerprint":"fe5e3e7a68583e8fb36306754b53bb1e3f4e4ea1035dfd2a30f74359e0e54853","payload":{"connection_id":"5d29200f65794d4d9ab6ef271f045a9b","event_at":"2026-07-28T02:07:49.359000Z","event_type":"price_change","frame_hash":"f0bf4adf6773753e92a771024c300fc93cc21181fd6966015318b8c55583d078","frame_index":0,"kind":"data","monotonic_ns":306452644380208,"payload":{"event_type":"price_change","market":"0xda6f0e0e93fc8469e0159a166028d017bddbc162b86f66bac90391379603d962","price_changes":[{"asset_id":"20893381255801015515826997628594359667013752732428989472914000440642900266717","best_ask":"0.55","best_bid":"0.54","hash":"0cda4fc35210f57399cb78474112b96026001e87","price":"0.4","side":"BUY","size":"101.5"},{"asset_id":"39272994714739463168905443499424551362424437245880253267329605556587274644733","best_ask":"0.46","best_bid":"0.45","hash":"e2bca3588a7585245bc79174a0b5cf343d30af06","price":"0.6","side":"SELL","size":"101.5"}],"timestamp":"1785204469359"},"payload_hash":"ca7f08b7ecda0af48b294a631929fc45f1b5c016c4554137da45dfab9007dec5","raw_frame":"{\"market\":\"0xda6f0e0e93fc8469e0159a166028d017bddbc162b86f66bac90391379603d962\", \"price_changes\":[{\"asset_id\":\"20893381255801015515826997628594359667013752732428989472914000440642900266717\", \"price\":\"0.4\", \"size\":\"101.5\", \"side\":\"BUY\", \"hash\":\"0cda4fc35210f57399cb78474112b96026001e87\", \"best_bid\":\"0.54\", \"best_ask\":\"0.55\"}, {\"asset_id\":\"39272994714739463168905443499424551362424437245880253267329605556587274644733\", \"price\":\"0.6\", \"size\":\"101.5\", \"side\":\"SELL\", \"hash\":\"e2bca3588a7585245bc79174a0b5cf343d30af06\", \"best_bid\":\"0.45\", \"best_ask\":\"0.46\"}], \"timestamp\":\"1785204469359\", \"event_type\":\"price_change\"}","received_at":"2026-07-28T02:07:49.636676Z","schema_version":"clob-market-ws.price_change.v1","sequence":null,"server_hash":null,"server_timestamp":"1785204469359","session_id":"d2757dd6dad94f3b9fe67e8dbf1adc37","source":"clob_market_ws"},"received_at":"2026-07-28T02:07:49.636676Z","record_id":"d13a936ca35045228395dca15389cbf50c72440b3db056d39156c6c5b384977e","schema_fingerprint":"4aa3821a28b0b7c2400bc59aba4bcc0a76e971dadd19610d3ad38c768e124dc7","schema_version":"edge-lab-recorder.raw.v1","sequence":null,"source":"clob_market_ws"}
{"event_at":"2026-07-28T02:07:49.359000Z","event_fingerprint":"8418f755557c726c2835691d7eb1b04a42fc4de2909a42521e845987b98a0d33","payload":{"connection_id":"5d29200f65794d4d9ab6ef271f045a9b","event_at":"2026-07-28T02:07:49.359000Z","event_type":"price_change","frame_hash":"571cb155caf002ba8492bc67bf1de940140cdfa377b352f84ece6bb7b9eafb67","frame_index":0,"kind":"data","monotonic_ns":306452652640458,"payload":{"event_type":"price_change","market":"0xda6f0e0e93fc8469e0159a166028d017bddbc162b86f66bac90391379603d962","price_changes":[{"asset_id":"20893381255801015515826997628594359667013752732428989472914000440642900266717","best_ask":"0.55","best_bid":"0.54","hash":"60489a264abe2eb2b2e652c81dc70dca83f270f6","price":"0.53","side":"BUY","size":"193.6"},{"asset_id":"39272994714739463168905443499424551362424437245880253267329605556587274644733","best_ask":"0.46","best_bid":"0.45","hash":"a65401e5e72a9871bb0017e11de58df89b7f7467","price":"0.47","side":"SELL","size":"193.6"}],"timestamp":"1785204469359"},"payload_hash":"43c111feb6b433987f84161a62dffb0866d97cecb294535f909e67d6ad349547","raw_frame":"{\"market\":\"0xda6f0e0e93fc8469e0159a166028d017bddbc162b86f66bac90391379603d962\", \"price_changes\":[{\"asset_id\":\"20893381255801015515826997628594359667013752732428989472914000440642900266717\", \"price\":\"0.53\", \"size\":\"193.6\", \"side\":\"BUY\", \"hash\":\"60489a264abe2eb2b2e652c81dc70dca83f270f6\", \"best_bid\":\"0.54\", \"best_ask\":\"0.55\"}, {\"asset_id\":\"39272994714739463168905443499424551362424437245880253267329605556587274644733\", \"price\":\"0.47\", \"size\":\"193.6\", \"side\":\"SELL\", \"hash\":\"a65401e5e72a9871bb0017e11de58df89b7f7467\", \"best_bid\":\"0.45\", \"best_ask\":\"0.46\"}], \"timestamp\":\"1785204469359\", \"event_type\":\"price_change\"}","received_at":"2026-07-28T02:07:49.644938Z","schema_version":"clob-market-ws.price_change.v1","sequence":null,"server_hash":null,"server_timestamp":"1785204469359","session_id":"d2757dd6dad94f3b9fe67e8dbf1adc37","source":"clob_market_ws"},"received_at":"2026-07-28T02:07:49.644938Z","record_id":"04b132f3461feb8ad02ae27d6786149341f2a71061c4f5b5373a10bb7dc6776c","schema_fingerprint":"4aa3821a28b0b7c2400bc59aba4bcc0a76e971dadd19610d3ad38c768e124dc7","schema_version":"edge-lab-recorder.raw.v1","sequence":null,"source":"clob_market_ws"}
{"event_at":"2026-07-28T02:07:49.360000Z","event_fingerprint":"44099993810511996d268da859bcf2ccdbb4957ad215eb0c72a2c406c4ce2163","payload":{"connection_id":"5d29200f65794d4d9ab6ef271f045a9b","event_at":"2026-07-28T02:07:49.360000Z","event_type":"price_change","frame_hash":"763cdc89cb2c03e7fe277b3d6984cf421f8e929768627877995e5eca28a30161","frame_index":0,"kind":"data","monotonic_ns":306452655023208,"payload":{"event_type":"price_change","market":"0xda6f0e0e93fc8469e0159a166028d017bddbc162b86f66bac90391379603d962","price_changes":[{"asset_id":"20893381255801015515826997628594359667013752732428989472914000440642900266717","best_ask":"0.55","best_bid":"0.54","hash":"95f73360872187b1a2f13de0e9efc96a4380bf4c","price":"0.43","side":"BUY","size":"112.2"},{"asset_id":"39272994714739463168905443499424551362424437245880253267329605556587274644733","best_ask":"0.46","best_bid":"0.45","hash":"2939250e9b5768ba129bfb366aff8e1bbaa9a5e1","price":"0.57","side":"SELL","size":"112.2"}],"timestamp":"1785204469360"},"payload_hash":"f2a2a9ee8bbd526ea42247ceb2cebea13a6b8295b418f410d158df14a425328c","raw_frame":"{\"market\":\"0xda6f0e0e93fc8469e0159a166028d017bddbc162b86f66bac90391379603d962\", \"price_changes\":[{\"asset_id\":\"20893381255801015515826997628594359667013752732428989472914000440642900266717\", \"price\":\"0.43\", \"size\":\"112.2\", \"side\":\"BUY\", \"hash\":\"95f73360872187b1a2f13de0e9efc96a4380bf4c\", \"best_bid\":\"0.54\", \"best_ask\":\"0.55\"}, {\"asset_id\":\"39272994714739463168905443499424551362424437245880253267329605556587274644733\", \"price\":\"0.57\", \"size\":\"112.2\", \"side\":\"SELL\", \"hash\":\"2939250e9b5768ba129bfb366aff8e1bbaa9a5e1\", \"best_bid\":\"0.45\", \"best_ask\":\"0.46\"}], \"timestamp\":\"1785204469360\", \"event_type\":\"price_change\"}","received_at":"2026-07-28T02:07:49.647321Z","schema_version":"clob-market-ws.price_change.v1","sequence":null,"server_hash":null,"server_timestamp":"1785204469360","session_id":"d2757dd6dad94f3b9fe67e8dbf1adc37","source":"clob_market_ws"},"received_at":"2026-07-28T02:07:49.647321Z","record_id":"77353eca136939c69d418359b8b36fa73c6bd0d2cd4632d0d2a8599745769034","schema_fingerprint":"4aa3821a28b0b7c2400bc59aba4bcc0a76e971dadd19610d3ad38c768e124dc7","schema_version":"edge-lab-recorder.raw.v1","sequence":null,"source":"clob_market_ws"}
{"event_at":"2026-07-28T02:07:49.362000Z","event_fingerprint":"1ebad8ea2fbb5a3e1fa857c80ff71da8d343925f20bd60796d3e94103ad7c8e3","payload":{"connection_id":"5d29200f65794d4d9ab6ef271f045a9b","event_at":"2026-07-28T02:07:49.362000Z","event_type":"price_change","frame_hash":"00f95815828441af9212639635c8f07f03dc056edb0173aeb2392e8d0ed0b221","frame_index":0,"kind":"data","monotonic_ns":306452660107833,"payload":{"event_type":"price_change","market":"0xda6f0e0e93fc8469e0159a166028d017bddbc162b86f66bac90391379603d962","price_changes":[{"asset_id":"39272994714739463168905443499424551362424437245880253267329605556587274644733","best_ask":"0.46","best_bid":"0.45","hash":"75a347cab637a976cfd95afb7daeaa68d655296a","price":"0.41","side":"BUY","size":"56"},{"asset_id":"20893381255801015515826997628594359667013752732428989472914000440642900266717","best_ask":"0.55","best_bid":"0.54","hash":"6a9852359c72b0d77df2b5c2746d36ada120f2ae","price":"0.59","side":"SELL","size":"56"}],"timestamp":"1785204469362"},"payload_hash":"cf2bf6babc1bf99d1557add7c1a15eaea76401eec6ed7f9c9ad32a78ecb9b7c4","raw_frame":"{\"market\":\"0xda6f0e0e93fc8469e0159a166028d017bddbc162b86f66bac90391379603d962\", \"price_changes\":[{\"asset_id\":\"39272994714739463168905443499424551362424437245880253267329605556587274644733\", \"price\":\"0.41\", \"size\":\"56\", \"side\":\"BUY\", \"hash\":\"75a347cab637a976cfd95afb7daeaa68d655296a\", \"best_bid\":\"0.45\", \"best_ask\":\"0.46\"}, {\"asset_id\":\"20893381255801015515826997628594359667013752732428989472914000440642900266717\", \"price\":\"0.59\", \"size\":\"56\", \"side\":\"SELL\", \"hash\":\"6a9852359c72b0d77df2b5c2746d36ada120f2ae\", \"best_bid\":\"0.54\", \"best_ask\":\"0.55\"}], \"timestamp\":\"1785204469362\", \"event_type\":\"price_change\"}","received_at":"2026-07-28T02:07:49.652403Z","schema_version":"clob-market-ws.price_change.v1","sequence":null,"server_hash":null,"server_timestamp":"1785204469362","session_id":"d2757dd6dad94f3b9fe67e8dbf1adc37","source":"clob_market_ws"},"received_at":"2026-07-28T02:07:49.652403Z","record_id":"f2d6ee1d1326e4b5d607434c7b5f7670d5a935837ea3f8b79665c2e0ff66a33f","schema_fingerprint":"4aa3821a28b0b7c2400bc59aba4bcc0a76e971dadd19610d3ad38c768e124dc7","schema_version":"edge-lab-recorder.raw.v1","sequence":null,"source":"clob_market_ws"}
{"event_at":"2026-07-28T02:07:49.362000Z","event_fingerprint":"cb713f65e32a68230d726cecc203cc731f7d5d3b3de99dcfa9f566cc27e99b96","payload":{"connection_id":"5d29200f65794d4d9ab6ef271f045a9b","event_at":"2026-07-28T02:07:49.362000Z","event_type":"price_change","frame_hash":"660353f67bc28b0a9ca0ed0cc1e3427cb3943bb1ed925a5686a88afc897c70b0","frame_index":0,"kind":"data","monotonic_ns":306452665415375,"payload":{"event_type":"price_change","market":"0xda6f0e0e93fc8469e0159a166028d017bddbc162b86f66bac90391379603d962","price_changes":[{"asset_id":"39272994714739463168905443499424551362424437245880253267329605556587274644733","best_ask":"0.46","best_bid":"0.45","hash":"75a347cab637a976cfd95afb7daeaa68d655296a","price":"0.4","side":"BUY","size":"182"},{"asset_id":"20893381255801015515826997628594359667013752732428989472914000440642900266717","best_ask":"0.55","best_bid":"0.54","hash":"6a9852359c72b0d77df2b5c2746d36ada120f2ae","price":"0.6","side":"SELL","size":"182"}],"timestamp":"1785204469362"},"payload_hash":"babbac0863b50515a1ba5a141fc458cb90722dea51ec7517b134ebf85a6c5f36","raw_frame":"{\"market\":\"0xda6f0e0e93fc8469e0159a166028d017bddbc162b86f66bac90391379603d962\", \"price_changes\":[{\"asset_id\":\"39272994714739463168905443499424551362424437245880253267329605556587274644733\", \"price\":\"0.4\", \"size\":\"182\", \"side\":\"BUY\", \"hash\":\"75a347cab637a976cfd95afb7daeaa68d655296a\", \"best_bid\":\"0.45\", \"best_ask\":\"0.46\"}, {\"asset_id\":\"20893381255801015515826997628594359667013752732428989472914000440642900266717\", \"price\":\"0.6\", \"size\":\"182\", \"side\":\"SELL\", \"hash\":\"6a9852359c72b0d77df2b5c2746d36ada120f2ae\", \"best_bid\":\"0.54\", \"best_ask\":\"0.55\"}], \"timestamp\":\"1785204469362\", \"event_type\":\"price_change\"}","received_at":"2026-07-28T02:07:49.657712Z","schema_version":"clob-market-ws.price_change.v1","sequence":null,"server_hash":null,"server_timestamp":"1785204469362","session_id":"d2757dd6dad94f3b9fe67e8dbf1adc37","source":"clob_market_ws"},"received_at":"2026-07-28T02:07:49.657712Z","record_id":"34e94121fa4c0781e8fc92ff09c4459fa29e1ac46483da9464a68e667293dc2a","schema_fingerprint":"4aa3821a28b0b7c2400bc59aba4bcc0a76e971dadd19610d3ad38c768e124dc7","schema_version":"edge-lab-recorder.raw.v1","sequence":null,"source":"clob_market_ws"}
{"event_at":"2026-07-28T02:07:49.362000Z","event_fingerprint":"4ed40b84c80fc6d00631258e741264f022ee841c13f4a937767b79ec5b4ec2ec","payload":{"connection_id":"5d29200f65794d4d9ab6ef271f045a9b","event_at":"2026-07-28T02:07:49.362000Z","event_type":"price_change","frame_hash":"1115eef2c40555d34ea87c74bf3018e44ed973a5885ea7a963320ac9cb8a7f89","frame_index":0,"kind":"data","monotonic_ns":306452669697333,"payload":{"event_type":"price_change","market":"0xda6f0e0e93fc8469e0159a166028d017bddbc162b86f66bac90391379603d962","price_changes":[{"asset_id":"20893381255801015515826997628594359667013752732428989472914000440642900266717","best_ask":"0.55","best_bid":"0.54","hash":"357e224474c9053862a0083359070fc48e220214","price":"0.43","side":"BUY","size":"117.2"},{"asset_id":"39272994714739463168905443499424551362424437245880253267329605556587274644733","best_ask":"0.46","best_bid":"0.45","hash":"ab70f074297b78e1ff5f2718977488c0c1f43b07","price":"0.57","side":"SELL","size":"117.2"}],"timestamp":"1785204469362"},"payload_hash":"03a5ac8b02e443a310eba8a03253810c0d24660979bb710ed5bc6e2cc18b20b0","raw_frame":"{\"market\":\"0xda6f0e0e93fc8469e0159a166028d017bddbc162b86f66bac90391379603d962\", \"price_changes\":[{\"asset_id\":\"20893381255801015515826997628594359667013752732428989472914000440642900266717\", \"price\":\"0.43\", \"size\":\"117.2\", \"side\":\"BUY\", \"hash\":\"357e224474c9053862a0083359070fc48e220214\", \"best_bid\":\"0.54\", \"best_ask\":\"0.55\"}, {\"asset_id\":\"39272994714739463168905443499424551362424437245880253267329605556587274644733\", \"price\":\"0.57\", \"size\":\"117.2\", \"side\":\"SELL\", \"hash\":\"ab70f074297b78e1ff5f2718977488c0c1f43b07\", \"best_bid\":\"0.45\", \"best_ask\":\"0.46\"}], \"timestamp\":\"1785204469362\", \"event_type\":\"price_change\"}","received_at":"2026-07-28T02:07:49.661995Z","schema_version":"clob-market-ws.price_change.v1","sequence":null,"server_hash":null,"server_timestamp":"1785204469362","session_id":"d2757dd6dad94f3b9fe67e8dbf1adc37","source":"clob_market_ws"},"received_at":"2026-07-28T02:07:49.661995Z","record_id":"7e6e25fba1dc8fdf4232727a0b7dc7de4103d809bbc304b59951117a5f8c1528","schema_fingerprint":"4aa3821a28b0b7c2400bc59aba4bcc0a76e971dadd19610d3ad38c768e124dc7","schema_version":"edge-lab-recorder.raw.v1","sequence":null,"source":"clob_market_ws"}
{"event_at":"2026-07-28T02:07:49.363000Z","event_fingerprint":"837e2f52a78634acae38ff1d29ffaad1b9af8710caaa646d8ae32889226e3ac3","payload":{"connection_id":"5d29200f65794d4d9ab6ef271f045a9b","event_at":"2026-07-28T02:07:49.363000Z","event_type":"price_change","frame_hash":"2089362340c0335058b2f41049d79dddb8febc0f55a9578819da24a21661d1cc","frame_index":0,"kind":"data","monotonic_ns":306452674150500,"payload":{"event_type":"price_change","market":"0xda6f0e0e93fc8469e0159a166028d017bddbc162b86f66bac90391379603d962","price_changes":[{"asset_id":"39272994714739463168905443499424551362424437245880253267329605556587274644733","best_ask":"0.46","best_bid":"0.45","hash":"8f1540aca6f08686093c9630536355f1ca410ba5","price":"0.34","side":"BUY","size":"50"},{"asset_id":"20893381255801015515826997628594359667013752732428989472914000440642900266717","best_ask":"0.55","best_bid":"0.54","hash":"eed01d2e63f41f5bb96e20755e4fe516dd270dd8","price":"0.66","side":"SELL","size":"50"}],"timestamp":"1785204469363"},"payload_hash":"42c3b275885e65c4e20265c9d20db4914bb00c697876605103b08e6607cce5a5","raw_frame":"{\"market\":\"0xda6f0e0e93fc8469e0159a166028d017bddbc162b86f66bac90391379603d962\", \"price_changes\":[{\"asset_id\":\"39272994714739463168905443499424551362424437245880253267329605556587274644733\", \"price\":\"0.34\", \"size\":\"50\", \"side\":\"BUY\", \"hash\":\"8f1540aca6f08686093c9630536355f1ca410ba5\", \"best_bid\":\"0.45\", \"best_ask\":\"0.46\"}, {\"asset_id\":\"20893381255801015515826997628594359667013752732428989472914000440642900266717\", \"price\":\"0.66\", \"size\":\"50\", \"side\":\"SELL\", \"hash\":\"eed01d2e63f41f5bb96e20755e4fe516dd270dd8\", \"best_bid\":\"0.54\", \"best_ask\":\"0.55\"}], \"timestamp\":\"1785204469363\", \"event_type\":\"price_change\"}","received_at":"2026-07-28T02:07:49.666448Z","schema_version":"clob-market-ws.price_change.v1","sequence":null,"server_hash":null,"server_timestamp":"1785204469363","session_id":"d2757dd6dad94f3b9fe67e8dbf1adc37","source":"clob_market_ws"},"received_at":"2026-07-28T02:07:49.666448Z","record_id":"83b6604b75941639f2fb7f78948a0f56a07f12dd902acb6e91529e04587a5432","schema_fingerprint":"4aa3821a28b0b7c2400bc59aba4bcc0a76e971dadd19610d3ad38c768e124dc7","schema_version":"edge-lab-recorder.raw.v1","sequence":null,"source":"clob_market_ws"}
{"event_at":"2026-07-28T02:07:49.364000Z","event_fingerprint":"9fa426cbf3adce9590033d30675e1275c5ac35257fd57e59b198dfbb967bb106","payload":{"connection_id":"5d29200f65794d4d9ab6ef271f045a9b","event_at":"2026-07-28T02:07:49.364000Z","event_type":"price_change","frame_hash":"8c55c68a3394e2c62e7b98a4653b81835ca430b40977f9ae73d53aea78954f0d","frame_index":0,"kind":"data","monotonic_ns":306452677285416,"payload":{"event_type":"price_change","market":"0xda6f0e0e93fc8469e0159a166028d017bddbc162b86f66bac90391379603d962","price_changes":[{"asset_id":"20893381255801015515826997628594359667013752732428989472914000440642900266717","best_ask":"0.55","best_bid":"0.54","hash":"9538ef3a010bc5fce64d62869b091db2717395f3","price":"0.49","side":"BUY","size":"122.2"},{"asset_id":"39272994714739463168905443499424551362424437245880253267329605556587274644733","best_ask":"0.46","best_bid":"0.45","hash":"b6296be480cd2bb93adc9bca377927d0c31d345e","price":"0.51","side":"SELL","size":"122.2"}],"timestamp":"1785204469364"},"payload_hash":"1c1940f903d74292c016b28abf1093a567404bdf2406dffe70fce9f835af0ef3","raw_frame":"{\"market\":\"0xda6f0e0e93fc8469e0159a166028d017bddbc162b86f66bac90391379603d962\", \"price_changes\":[{\"asset_id\":\"20893381255801015515826997628594359667013752732428989472914000440642900266717\", \"price\":\"0.49\", \"size\":\"122.2\", \"side\":\"BUY\", \"hash\":\"9538ef3a010bc5fce64d62869b091db2717395f3\", \"best_bid\":\"0.54\", \"best_ask\":\"0.55\"}, {\"asset_id\":\"39272994714739463168905443499424551362424437245880253267329605556587274644733\", \"price\":\"0.51\", \"size\":\"122.2\", \"side\":\"SELL\", \"hash\":\"b6296be480cd2bb93adc9bca377927d0c31d345e\", \"best_bid\":\"0.45\", \"best_ask\":\"0.46\"}], \"timestamp\":\"1785204469364\", \"event_type\":\"price_change\"}","received_at":"2026-07-28T02:07:49.669581Z","schema_version":"clob-market-ws.price_change.v1","sequence":null,"server_hash":null,"server_timestamp":"1785204469364","session_id":"d2757dd6dad94f3b9fe67e8dbf1adc37","source":"clob_market_ws"},"received_at":"2026-07-28T02:07:49.669581Z","record_id":"9c75352e5a61407767e3a853cc70a8eace7c152abf32e3d886b00d731cf4b35d","schema_fingerprint":"4aa3821a28b0b7c2400bc59aba4bcc0a76e971dadd19610d3ad38c768e124dc7","schema_version":"edge-lab-recorder.raw.v1","sequence":null,"source":"clob_market_ws"}
{"event_at":"2026-07-28T02:07:49.365000Z","event_fingerprint":"1ad7699effa5b6a9456a562cdca8e44c93699e826e1093409b72ca83180e265e","payload":{"connection_id":"5d29200f65794d4d9ab6ef271f045a9b","event_at":"2026-07-28T02:07:49.365000Z","event_type":"price_change","frame_hash":"ec16688255cf9e743c295bf658198fce3d5e8997b28efe953395f58551f2138e","frame_index":0,"kind":"data","monotonic_ns":306452681628250,"payload":{"event_type":"price_change","market":"0xda6f0e0e93fc8469e0159a166028d017bddbc162b86f66bac90391379603d962","price_changes":[{"asset_id":"20893381255801015515826997628594359667013752732428989472914000440642900266717","best_ask":"0.55","best_bid":"0.54","hash":"e0888777d955ebe1c99791286be27433238508fc","price":"0.41","side":"BUY","size":"72.4"},{"asset_id":"39272994714739463168905443499424551362424437245880253267329605556587274644733","best_ask":"0.46","best_bid":"0.45","hash":"80709cdbffddf31f3942469f1dbbcea2d18a77e5","price":"0.59","side":"SELL","size":"72.4"}],"timestamp":"1785204469365"},"payload_hash":"f032fe8462942baf888805ab95869560cb91042fe609ef238468fb041406e2f0","raw_frame":"{\"market\":\"0xda6f0e0e93fc8469e0159a166028d017bddbc162b86f66bac90391379603d962\", \"price_changes\":[{\"asset_id\":\"20893381255801015515826997628594359667013752732428989472914000440642900266717\", \"price\":\"0.41\", \"size\":\"72.4\", \"side\":\"BUY\", \"hash\":\"e0888777d955ebe1c99791286be27433238508fc\", \"best_bid\":\"0.54\", \"best_ask\":\"0.55\"}, {\"asset_id\":\"39272994714739463168905443499424551362424437245880253267329605556587274644733\", \"price\":\"0.59\", \"size\":\"72.4\", \"side\":\"SELL\", \"hash\":\"80709cdbffddf31f3942469f1dbbcea2d18a77e5\", \"best_bid\":\"0.45\", \"best_ask\":\"0.46\"}], \"timestamp\":\"1785204469365\", \"event_type\":\"price_change\"}","received_at":"2026-07-28T02:07:49.673926Z","schema_version":"clob-market-ws.price_change.v1","sequence":null,"server_hash":null,"server_timestamp":"1785204469365","session_id":"d2757dd6dad94f3b9fe67e8dbf1adc37","source":"clob_market_ws"},"received_at":"2026-07-28T02:07:49.673926Z","record_id":"0ce5d2146b04f4b3d880b53e6ec09c19c0e25a04245fb69532a04c08ed10d7fe","schema_fingerprint":"4aa3821a28b0b7c2400bc59aba4bcc0a76e971dadd19610d3ad38c768e124dc7","schema_version":"edge-lab-recorder.raw.v1","sequence":null,"source":"clob_market_ws"}
{"event_at":"2026-07-28T02:07:49.365000Z","event_fingerprint":"7a3babe6bf8f207bee104afacc947a28e0d1837ce3e200bf13a017ae41636870","payload":{"connection_id":"5d29200f65794d4d9ab6ef271f045a9b","event_at":"2026-07-28T02:07:49.365000Z","event_type":"price_change","frame_hash":"89df6f088db77f12d471940f95cb3d36085b522cc15f1131602a0629d67b5400","frame_index":0,"kind":"data","monotonic_ns":306452685893791,"payload":{"event_type":"price_change","market":"0xda6f0e0e93fc8469e0159a166028d017bddbc162b86f66bac90391379603d962","price_changes":[{"asset_id":"20893381255801015515826997628594359667013752732428989472914000440642900266717","best_ask":"0.55","best_bid":"0.54","hash":"4bdf588635224192e03e9032edb9a35dc6a7922c","price":"0.44","side":"BUY","size":"114.2"},{"asset_id":"39272994714739463168905443499424551362424437245880253267329605556587274644733","best_ask":"0.46","best_bid":"0.45","hash":"0ca95c05c7402d6457be018ad163ebd8c09ea6d0","price":"0.56","side":"SELL","size":"114.2"}],"timestamp":"1785204469365"},"payload_hash":"5d4b386f0ae02b80e30975976f40364b602149564457c8938d2f8a98c259f39e","raw_frame":"{\"market\":\"0xda6f0e0e93fc8469e0159a166028d017bddbc162b86f66bac90391379603d962\", \"price_changes\":[{\"asset_id\":\"20893381255801015515826997628594359667013752732428989472914000440642900266717\", \"price\":\"0.44\", \"size\":\"114.2\", \"side\":\"BUY\", \"hash\":\"4bdf588635224192e03e9032edb9a35dc6a7922c\", \"best_bid\":\"0.54\", \"best_ask\":\"0.55\"}, {\"asset_id\":\"39272994714739463168905443499424551362424437245880253267329605556587274644733\", \"price\":\"0.56\", \"size\":\"114.2\", \"side\":\"SELL\", \"hash\":\"0ca95c05c7402d6457be018ad163ebd8c09ea6d0\", \"best_bid\":\"0.45\", \"best_ask\":\"0.46\"}], \"timestamp\":\"1785204469365\", \"event_type\":\"price_change\"}","received_at":"2026-07-28T02:07:49.678193Z","schema_version":"clob-market-ws.price_change.v1","sequence":null,"server_hash":null,"server_timestamp":"1785204469365","session_id":"d2757dd6dad94f3b9fe67e8dbf1adc37","source":"clob_market_ws"},"received_at":"2026-07-28T02:07:49.678193Z","record_id":"07d810ecc96d57cf0163d28f5f3dad87aada1971d84bd47b656e685654b7ca29","schema_fingerprint":"4aa3821a28b0b7c2400bc59aba4bcc0a76e971dadd19610d3ad38c768e124dc7","schema_version":"edge-lab-recorder.raw.v1","sequence":null,"source":"clob_market_ws"}
{"event_at":"2026-07-28T02:07:49.366000Z","event_fingerprint":"ec39c1b968cda2e46f1d9bdad45b3f023524746782ccf4eb79c89086a6332974","payload":{"connection_id":"5d29200f65794d4d9ab6ef271f045a9b","event_at":"2026-07-28T02:07:49.366000Z","event_type":"price_change","frame_hash":"adb01232e2c92f18d43039307848627bcf853fcbdff9f8a7620e0277043c0871","frame_index":0,"kind":"data","monotonic_ns":306452689749708,"payload":{"event_type":"price_change","market":"0xda6f0e0e93fc8469e0159a166028d017bddbc162b86f66bac90391379603d962","price_changes":[{"asset_id":"20893381255801015515826997628594359667013752732428989472914000440642900266717","best_ask":"0.55","best_bid":"0.54","hash":"9558e0bac68ac690df33b3455fd0710cdaf805b2","price":"0.53","side":"BUY","size":"208.6"},{"asset_id":"39272994714739463168905443499424551362424437245880253267329605556587274644733","best_ask":"0.46","best_bid":"0.45","hash":"fae61c422bab0cc820599ba0b7f70564a404be0b","price":"0.47","side":"SELL","size":"208.6"}],"timestamp":"1785204469366"},"payload_hash":"8c9398d9ed8c449668252e3858432c07ed95c011dcb4d85277d107c60e1edf58","raw_frame":"{\"market\":\"0xda6f0e0e93fc8469e0159a166028d017bddbc162b86f66bac90391379603d962\", \"price_changes\":[{\"asset_id\":\"20893381255801015515826997628594359667013752732428989472914000440642900266717\", \"price\":\"0.53\", \"size\":\"208.6\", \"side\":\"BUY\", \"hash\":\"9558e0bac68ac690df33b3455fd0710cdaf805b2\", \"best_bid\":\"0.54\", \"best_ask\":\"0.55\"}, {\"asset_id\":\"39272994714739463168905443499424551362424437245880253267329605556587274644733\", \"price\":\"0.47\", \"size\":\"208.6\", \"side\":\"SELL\", \"hash\":\"fae61c422bab0cc820599ba0b7f70564a404be0b\", \"best_bid\":\"0.45\", \"best_ask\":\"0.46\"}], \"timestamp\":\"1785204469366\", \"event_type\":\"price_change\"}","received_at":"2026-07-28T02:07:49.682047Z","schema_version":"clob-market-ws.price_change.v1","sequence":null,"server_hash":null,"server_timestamp":"1785204469366","session_id":"d2757dd6dad94f3b9fe67e8dbf1adc37","source":"clob_market_ws"},"received_at":"2026-07-28T02:07:49.682047Z","record_id":"93d11d69ae850c4b2265293513bfc69fc79613b545c63974dcb283c36354ecf8","schema_fingerprint":"4aa3821a28b0b7c2400bc59aba4bcc0a76e971dadd19610d3ad38c768e124dc7","schema_version":"edge-lab-recorder.raw.v1","sequence":null,"source":"clob_market_ws"}
{"event_at":"2026-07-28T02:07:49.367000Z","event_fingerprint":"ab50d70db48ecbab741fe28e4ae1e42c821fa06fe6c28e256a3a79ea081a6bfc","payload":{"connection_id":"5d29200f65794d4d9ab6ef271f045a9b","event_at":"2026-07-28T02:07:49.367000Z","event_type":"price_change","frame_hash":"bd5d506d76b0ce929b38d5c9dcd1110046be37be7792ad7bbe8492c65b34df3b","frame_index":0,"kind":"data","monotonic_ns":306452693897291,"payload":{"event_type":"price_change","market":"0xda6f0e0e93fc8469e0159a166028d017bddbc162b86f66bac90391379603d962","price_changes":[{"asset_id":"20893381255801015515826997628594359667013752732428989472914000440642900266717","best_ask":"0.55","best_bid":"0.54","hash":"3268d0b2c56e5e06e0f9e1be40a7502fb0481a1c","price":"0.51","side":"BUY","size":"107.6"},{"asset_id":"39272994714739463168905443499424551362424437245880253267329605556587274644733","best_ask":"0.46","best_bid":"0.45","hash":"534797c3e1f4a5f74de6308db4e193ee29e8aec7","price":"0.49","side":"SELL","size":"107.6"}],"timestamp":"1785204469367"},"payload_hash":"615d4a4cce50db7a41e84ea3f9286be67718897715086390cfa5729349e5eb79","raw_frame":"{\"market\":\"0xda6f0e0e93fc8469e0159a166028d017bddbc162b86f66bac90391379603d962\", \"price_changes\":[{\"asset_id\":\"20893381255801015515826997628594359667013752732428989472914000440642900266717\", \"price\":\"0.51\", \"size\":\"107.6\", \"side\":\"BUY\", \"hash\":\"3268d0b2c56e5e06e0f9e1be40a7502fb0481a1c\", \"best_bid\":\"0.54\", \"best_ask\":\"0.55\"}, {\"asset_id\":\"39272994714739463168905443499424551362424437245880253267329605556587274644733\", \"price\":\"0.49\", \"size\":\"107.6\", \"side\":\"SELL\", \"hash\":\"534797c3e1f4a5f74de6308db4e193ee29e8aec7\", \"best_bid\":\"0.45\", \"best_ask\":\"0.46\"}], \"timestamp\":\"1785204469367\", \"event_type\":\"price_change\"}","received_at":"2026-07-28T02:07:49.686195Z","schema_version":"clob-market-ws.price_change.v1","sequence":null,"server_hash":null,"server_timestamp":"1785204469367","session_id":"d2757dd6dad94f3b9fe67e8dbf1adc37","source":"clob_market_ws"},"received_at":"2026-07-28T02:07:49.686195Z","record_id":"3f49b4f93666c6a941b077e01e21a2e2c26e4263dedf438439eaebbf215785ef","schema_fingerprint":"4aa3821a28b0b7c2400bc59aba4bcc0a76e971dadd19610d3ad38c768e124dc7","schema_version":"edge-lab-recorder.raw.v1","sequence":null,"source":"clob_market_ws"}
{"event_at":"2026-07-28T02:07:49.368000Z","event_fingerprint":"c1aabe8b66901854925cff127e308664098f12e58cc1891b520727fb29d40cfc","payload":{"connection_id":"5d29200f65794d4d9ab6ef271f045a9b","event_at":"2026-07-28T02:07:49.368000Z","event_type":"price_change","frame_hash":"71253d3b83d501bdebdababc176e4b78446482a3a1a52ef4b1911cb0d775feb9","frame_index":0,"kind":"data","monotonic_ns":306452698247125,"payload":{"event_type":"price_change","market":"0xda6f0e0e93fc8469e0159a166028d017bddbc162b86f66bac90391379603d962","price_changes":[{"asset_id":"39272994714739463168905443499424551362424437245880253267329605556587274644733","best_ask":"0.46","best_bid":"0.45","hash":"e3c16f55399d6130c740b81d5fb999ff331b7cf2","price":"0.37","side":"BUY","size":"104"},{"asset_id":"20893381255801015515826997628594359667013752732428989472914000440642900266717","best_ask":"0.55","best_bid":"0.54","hash":"8010a54a546a61b13ed76028baa8e6dafa2985f2","price":"0.63","side":"SELL","size":"104"}],"timestamp":"1785204469368"},"payload_hash":"652f881db563693e0c1b8ff6935cb1763bb3c810f5a0a0c1b1c60cc2bcd1206d","raw_frame":"{\"market\":\"0xda6f0e0e93fc8469e0159a166028d017bddbc162b86f66bac90391379603d962\", \"price_changes\":[{\"asset_id\":\"39272994714739463168905443499424551362424437245880253267329605556587274644733\", \"price\":\"0.37\", \"size\":\"104\", \"side\":\"BUY\", \"hash\":\"e3c16f55399d6130c740b81d5fb999ff331b7cf2\", \"best_bid\":\"0.45\", \"best_ask\":\"0.46\"}, {\"asset_id\":\"20893381255801015515826997628594359667013752732428989472914000440642900266717\", \"price\":\"0.63\", \"size\":\"104\", \"side\":\"SELL\", \"hash\":\"8010a54a546a61b13ed76028baa8e6dafa2985f2\", \"best_bid\":\"0.54\", \"best_ask\":\"0.55\"}], \"timestamp\":\"1785204469368\", \"event_type\":\"price_change\"}","received_at":"2026-07-28T02:07:49.690545Z","schema_version":"clob-market-ws.price_change.v1","sequence":null,"server_hash":null,"server_timestamp":"1785204469368","session_id":"d2757dd6dad94f3b9fe67e8dbf1adc37","source":"clob_market_ws"},"received_at":"2026-07-28T02:07:49.690545Z","record_id":"07787453c178cce4d0793e161d4a55f2c5fa58e76b115afbd478a75221c4be39","schema_fingerprint":"4aa3821a28b0b7c2400bc59aba4bcc0a76e971dadd19610d3ad38c768e124dc7","schema_version":"edge-lab-recorder.raw.v1","sequence":null,"source":"clob_market_ws"}
{"event_at":"2026-07-28T02:07:49.369000Z","event_fingerprint":"3d8d1ed34fcdc35917eb4dd4a27331098b7d437bd87073a0a5ee7c0f4d0f0169","payload":{"connection_id":"5d29200f65794d4d9ab6ef271f045a9b","event_at":"2026-07-28T02:07:49.369000Z","event_type":"price_change","frame_hash":"1026bb7fec7acd54b1a7feaac13d17553bd220369a1da130e00bd0aa7d0d30f4","frame_index":0,"kind":"data","monotonic_ns":306452702528708,"payload":{"event_type":"price_change","market":"0xda6f0e0e93fc8469e0159a166028d017bddbc162b86f66bac90391379603d962","price_changes":[{"asset_id":"20893381255801015515826997628594359667013752732428989472914000440642900266717","best_ask":"0.55","best_bid":"0.54","hash":"2dea1a862d7da00ffc4efb670371c3413857d144","price":"0.42","side":"BUY","size":"129.3"},{"asset_id":"39272994714739463168905443499424551362424437245880253267329605556587274644733","best_ask":"0.46","best_bid":"0.45","hash":"f4ae706adae593a28a075db7c6da5c3cc0ea2efd","price":"0.58","side":"SELL","size":"129.3"}],"timestamp":"1785204469369"},"payload_hash":"d4e4d9eee954229715a32e61b6595ee7ee69d629bf8fdb13a380892f51a2d7d5","raw_frame":"{\"market\":\"0xda6f0e0e93fc8469e0159a166028d017bddbc162b86f66bac90391379603d962\", \"price_changes\":[{\"asset_id\":\"20893381255801015515826997628594359667013752732428989472914000440642900266717\", \"price\":\"0.42\", \"size\":\"129.3\", \"side\":\"BUY\", \"hash\":\"2dea1a862d7da00ffc4efb670371c3413857d144\", \"best_bid\":\"0.54\", \"best_ask\":\"0.55\"}, {\"asset_id\":\"39272994714739463168905443499424551362424437245880253267329605556587274644733\", \"price\":\"0.58\", \"size\":\"129.3\", \"side\":\"SELL\", \"hash\":\"f4ae706adae593a28a075db7c6da5c3cc0ea2efd\", \"best_bid\":\"0.45\", \"best_ask\":\"0.46\"}], \"timestamp\":\"1785204469369\", \"event_type\":\"price_change\"}","received_at":"2026-07-28T02:07:49.694826Z","schema_version":"clob-market-ws.price_change.v1","sequence":null,"server_hash":null,"server_timestamp":"1785204469369","session_id":"d2757dd6dad94f3b9fe67e8dbf1adc37","source":"clob_market_ws"},"received_at":"2026-07-28T02:07:49.694826Z","record_id":"723b3415837fccf273c7231f22657f779d9d72a6b9c96a368524eaa166307223","schema_fingerprint":"4aa3821a28b0b7c2400bc59aba4bcc0a76e971dadd19610d3ad38c768e124dc7","schema_version":"edge-lab-recorder.raw.v1","sequence":null,"source":"clob_market_ws"}
{"event_at":"2026-07-28T02:07:49.369000Z","event_fingerprint":"8bbe2a4fbb8fcfc0c4cfab54dc256b93fc89775e4b25b339809d7b9e3ae41e03","payload":{"connection_id":"5d29200f65794d4d9ab6ef271f045a9b","event_at":"2026-07-28T02:07:49.369000Z","event_type":"price_change","frame_hash":"32ad196278ec93a294a98686f0952e439d00a740e61a3cd9c0acc2f39689286f","frame_index":0,"kind":"data","monotonic_ns":306452706850916,"payload":{"event_type":"price_change","market":"0xda6f0e0e93fc8469e0159a166028d017bddbc162b86f66bac90391379603d962","price_changes":[{"asset_id":"39272994714739463168905443499424551362424437245880253267329605556587274644733","best_ask":"0.46","best_bid":"0.45","hash":"feb8e184f5f5b73308a238c8303b856b09d82bc6","price":"0.31","side":"BUY","size":"50"},{"asset_id":"20893381255801015515826997628594359667013752732428989472914000440642900266717","best_ask":"0.55","best_bid":"0.54","hash":"53444fc9396fb259334afec549f4415bdc71bd6a","price":"0.69","side":"SELL","size":"50"}],"timestamp":"1785204469369"},"payload_hash":"3fd40dbd7e7a83937843036b0882d744c1439a6641d01dee7c8125bfe5ae1c19","raw_frame":"{\"market\":\"0xda6f0e0e93fc8469e0159a166028d017bddbc162b86f66bac90391379603d962\", \"price_changes\":[{\"asset_id\":\"39272994714739463168905443499424551362424437245880253267329605556587274644733\", \"price\":\"0.31\", \"size\":\"50\", \"side\":\"BUY\", \"hash\":\"feb8e184f5f5b73308a238c8303b856b09d82bc6\", \"best_bid\":\"0.45\", \"best_ask\":\"0.46\"}, {\"asset_id\":\"20893381255801015515826997628594359667013752732428989472914000440642900266717\", \"price\":\"0.69\", \"size\":\"50\", \"side\":\"SELL\", \"hash\":\"53444fc9396fb259334afec549f4415bdc71bd6a\", \"best_bid\":\"0.54\", \"best_ask\":\"0.55\"}], \"timestamp\":\"1785204469369\", \"event_type\":\"price_change\"}","received_at":"2026-07-28T02:07:49.699148Z","schema_version":"clob-market-ws.price_change.v1","sequence":null,"server_hash":null,"server_timestamp":"1785204469369","session_id":"d2757dd6dad94f3b9fe67e8dbf1adc37","source":"clob_market_ws"},"received_at":"2026-07-28T02:07:49.699148Z","record_id":"338715b785867fec59bf2834158dc0bdf0e4820a1af50a7d7208e006e6a2ec83","schema_fingerprint":"4aa3821a28b0b7c2400bc59aba4bcc0a76e971dadd19610d3ad38c768e124dc7","schema_version":"edge-lab-recorder.raw.v1","sequence":null,"source":"clob_market_ws"}
{"event_at":"2026-07-28T02:07:49.369000Z","event_fingerprint":"a3b8caa0cc1a1d23b9b2f929cac3822626dc4270fbe142bbd2535de6e2a0771c","payload":{"connection_id":"5d29200f65794d4d9ab6ef271f045a9b","event_at":"2026-07-28T02:07:49.369000Z","event_type":"price_change","frame_hash":"ee16c25523f51d9a9cb2c4dfd5467cf3b29d9a1e9a95595fb702ecfa300e08f6","frame_index":0,"kind":"data","monotonic_ns":306452711303083,"payload":{"event_type":"price_change","market":"0xda6f0e0e93fc8469e0159a166028d017bddbc162b86f66bac90391379603d962","price_changes":[{"asset_id":"39272994714739463168905443499424551362424437245880253267329605556587274644733","best_ask":"0.46","best_bid":"0.45","hash":"d9d61271161996226b09f977f579babdff05d2b8","price":"0.45","side":"BUY","size":"25.2"},{"asset_id":"20893381255801015515826997628594359667013752732428989472914000440642900266717","best_ask":"0.55","best_bid":"0.54","hash":"07a5ab0a2f290192bd52518d9a84566681bf45f8","price":"0.55","side":"SELL","size":"25.2"}],"timestamp":"1785204469369"},"payload_hash":"918ff4aff5d3c02d411a9da17b09ef35e1b79391f0783977df3f354d811b19af","raw_frame":"{\"market\":\"0xda6f0e0e93fc8469e0159a166028d017bddbc162b86f66bac90391379603d962\", \"price_changes\":[{\"asset_id\":\"39272994714739463168905443499424551362424437245880253267329605556587274644733\", \"price\":\"0.45\", \"size\":\"25.2\", \"side\":\"BUY\", \"hash\":\"d9d61271161996226b09f977f579babdff05d2b8\", \"best_bid\":\"0.45\", \"best_ask\":\"0.46\"}, {\"asset_id\":\"20893381255801015515826997628594359667013752732428989472914000440642900266717\", \"price\":\"0.55\", \"size\":\"25.2\", \"side\":\"SELL\", \"hash\":\"07a5ab0a2f290192bd52518d9a84566681bf45f8\", \"best_bid\":\"0.54\", \"best_ask\":\"0.55\"}], \"timestamp\":\"1785204469369\", \"event_type\":\"price_change\"}","received_at":"2026-07-28T02:07:49.703600Z","schema_version":"clob-market-ws.price_change.v1","sequence":null,"server_hash":null,"server_timestamp":"1785204469369","session_id":"d2757dd6dad94f3b9fe67e8dbf1adc37","source":"clob_market_ws"},"received_at":"2026-07-28T02:07:49.703600Z","record_id":"cf0bc707f0bddb41595c92c1e58a1e55c6b290737aef8bd8727ceaae8ef6331d","schema_fingerprint":"4aa3821a28b0b7c2400bc59aba4bcc0a76e971dadd19610d3ad38c768e124dc7","schema_version":"edge-lab-recorder.raw.v1","sequence":null,"source":"clob_market_ws"}
{"event_at":"2026-07-28T02:07:49.370000Z","event_fingerprint":"f193de0d6f8169cee8bcf5e1318a2626f8be8e952fb00a8db4ec69a8db02781a","payload":{"connection_id":"5d29200f65794d4d9ab6ef271f045a9b","event_at":"2026-07-28T02:07:49.370000Z","event_type":"price_change","frame_hash":"1b34b2d2e8094968027a3f90bd9b13b08621e0ababf3c1c7fef7debc1971d06f","frame_index":0,"kind":"data","monotonic_ns":306452715737583,"payload":{"event_type":"price_change","market":"0xda6f0e0e93fc8469e0159a166028d017bddbc162b86f66bac90391379603d962","price_changes":[{"asset_id":"20893381255801015515826997628594359667013752732428989472914000440642900266717","best_ask":"0.55","best_bid":"0.54","hash":"b75ad41f25c8d0dc409c6dee98ec2851064f447b","price":"0.47","side":"BUY","size":"129"},{"asset_id":"39272994714739463168905443499424551362424437245880253267329605556587274644733","best_ask":"0.46","best_bid":"0.45","hash":"a9d34e75447c04816ead84e9800465644283a556","price":"0.53","side":"SELL","size":"129"}],"timestamp":"1785204469370"},"payload_hash":"813639588c90a72ad02487edaecf903ecde6e9eeb00e358f454dc1949e8a2a6e","raw_frame":"{\"market\":\"0xda6f0e0e93fc8469e0159a166028d017bddbc162b86f66bac90391379603d962\", \"price_changes\":[{\"asset_id\":\"20893381255801015515826997628594359667013752732428989472914000440642900266717\", \"price\":\"0.47\", \"size\":\"129\", \"side\":\"BUY\", \"hash\":\"b75ad41f25c8d0dc409c6dee98ec2851064f447b\", \"best_bid\":\"0.54\", \"best_ask\":\"0.55\"}, {\"asset_id\":\"39272994714739463168905443499424551362424437245880253267329605556587274644733\", \"price\":\"0.53\", \"size\":\"129\", \"side\":\"SELL\", \"hash\":\"a9d34e75447c04816ead84e9800465644283a556\", \"best_bid\":\"0.45\", \"best_ask\":\"0.46\"}], \"timestamp\":\"1785204469370\", \"event_type\":\"price_change\"}","received_at":"2026-07-28T02:07:49.708035Z","schema_version":"clob-market-ws.price_change.v1","sequence":null,"server_hash":null,"server_timestamp":"1785204469370","session_id":"d2757dd6dad94f3b9fe67e8dbf1adc37","source":"clob_market_ws"},"received_at":"2026-07-28T02:07:49.708035Z","record_id":"a906defd898fa7a5f3c2d2229731b10d91326c8ed0c6686c6200f3174ce4b022","schema_fingerprint":"4aa3821a28b0b7c2400bc59aba4bcc0a76e971dadd19610d3ad38c768e124dc7","schema_version":"edge-lab-recorder.raw.v1","sequence":null,"source":"clob_market_ws"}
{"event_at":"2026-07-28T02:07:49.371000Z","event_fingerprint":"6f66ce41b61ba6ae4ec7e5282294a47d5388429964319a621ee4f0be56f9ac7b","payload":{"connection_id":"5d29200f65794d4d9ab6ef271f045a9b","event_at":"2026-07-28T02:07:49.371000Z","event_type":"price_change","frame_hash":"b3f590f7380e2ca9c4708d9293e77bc0b23162bb7e0a3a815632fa097bc90548","frame_index":0,"kind":"data","monotonic_ns":306452720048041,"payload":{"event_type":"price_change","market":"0xda6f0e0e93fc8469e0159a166028d017bddbc162b86f66bac90391379603d962","price_changes":[{"asset_id":"39272994714739463168905443499424551362424437245880253267329605556587274644733","best_ask":"0.46","best_bid":"0.45","hash":"871fad6a19d4d195c605b7ce796654cb0eef9e68","price":"0.39","side":"BUY","size":"79"},{"asset_id":"20893381255801015515826997628594359667013752732428989472914000440642900266717","best_ask":"0.55","best_bid":"0.54","hash":"86c1f886f678294be338936e3aa01464a5f5b635","price":"0.61","side":"SELL","size":"79"}],"timestamp":"1785204469371"},"payload_hash":"e3f843e0c0e481293f12a09f1afdf4cc1fa29cf6dc274616d601ae05a5b74b84","raw_frame":"{\"market\":\"0xda6f0e0e93fc8469e0159a166028d017bddbc162b86f66bac90391379603d962\", \"price_changes\":[{\"asset_id\":\"39272994714739463168905443499424551362424437245880253267329605556587274644733\", \"price\":\"0.39\", \"size\":\"79\", \"side\":\"BUY\", \"hash\":\"871fad6a19d4d195c605b7ce796654cb0eef9e68\", \"best_bid\":\"0.45\", \"best_ask\":\"0.46\"}, {\"asset_id\":\"20893381255801015515826997628594359667013752732428989472914000440642900266717\", \"price\":\"0.61\", \"size\":\"79\", \"side\":\"SELL\", \"hash\":\"86c1f886f678294be338936e3aa01464a5f5b635\", \"best_bid\":\"0.54\", \"best_ask\":\"0.55\"}], \"timestamp\":\"1785204469371\", \"event_type\":\"price_change\"}","received_at":"2026-07-28T02:07:49.712345Z","schema_version":"clob-market-ws.price_change.v1","sequence":null,"server_hash":null,"server_timestamp":"1785204469371","session_id":"d2757dd6dad94f3b9fe67e8dbf1adc37","source":"clob_market_ws"},"received_at":"2026-07-28T02:07:49.712345Z","record_id":"b74a2181c82e8af50c551ca3186045a9aa4d1b37d3b1a0b18b3c0e037b76fb7b","schema_fingerprint":"4aa3821a28b0b7c2400bc59aba4bcc0a76e971dadd19610d3ad38c768e124dc7","schema_version":"edge-lab-recorder.raw.v1","sequence":null,"source":"clob_market_ws"}
{"event_at":"2026-07-28T02:07:49.371000Z","event_fingerprint":"3c6350dd097453377bc45b26ab74c201e5f38c92dfc66095e1fb6100a20b9fd0","payload":{"connection_id":"5d29200f65794d4d9ab6ef271f045a9b","event_at":"2026-07-28T02:07:49.371000Z","event_type":"price_change","frame_hash":"21fcf75915fbafa2259e88a986262e0634b5f7d7893b808603a6e17175bb20df","frame_index":0,"kind":"data","monotonic_ns":306452724415500,"payload":{"event_type":"price_change","market":"0xda6f0e0e93fc8469e0159a166028d017bddbc162b86f66bac90391379603d962","price_changes":[{"asset_id":"39272994714739463168905443499424551362424437245880253267329605556587274644733","best_ask":"0.46","best_bid":"0.45","hash":"871fad6a19d4d195c605b7ce796654cb0eef9e68","price":"0.38","side":"BUY","size":"49"},{"asset_id":"20893381255801015515826997628594359667013752732428989472914000440642900266717","best_ask":"0.55","best_bid":"0.54","hash":"86c1f886f678294be338936e3aa01464a5f5b635","price":"0.62","side":"SELL","size":"49"}],"timestamp":"1785204469371"},"payload_hash":"844ee477e1a687819167e41f21fd3735ac0c27b4dc4f52b3f18ea323683ab78e","raw_frame":"{\"market\":\"0xda6f0e0e93fc8469e0159a166028d017bddbc162b86f66bac90391379603d962\", \"price_changes\":[{\"asset_id\":\"39272994714739463168905443499424551362424437245880253267329605556587274644733\", \"price\":\"0.38\", \"size\":\"49\", \"side\":\"BUY\", \"hash\":\"871fad6a19d4d195c605b7ce796654cb0eef9e68\", \"best_bid\":\"0.45\", \"best_ask\":\"0.46\"}, {\"asset_id\":\"20893381255801015515826997628594359667013752732428989472914000440642900266717\", \"price\":\"0.62\", \"size\":\"49\", \"side\":\"SELL\", \"hash\":\"86c1f886f678294be338936e3aa01464a5f5b635\", \"best_bid\":\"0.54\", \"best_ask\":\"0.55\"}], \"timestamp\":\"1785204469371\", \"event_type\":\"price_change\"}","received_at":"2026-07-28T02:07:49.716713Z","schema_version":"clob-market-ws.price_change.v1","sequence":null,"server_hash":null,"server_timestamp":"1785204469371","session_id":"d2757dd6dad94f3b9fe67e8dbf1adc37","source":"clob_market_ws"},"received_at":"2026-07-28T02:07:49.716713Z","record_id":"2ac8328b6bd07767562e606453e5d25d8bec752befbda6883166ade918bb3f72","schema_fingerprint":"4aa3821a28b0b7c2400bc59aba4bcc0a76e971dadd19610d3ad38c768e124dc7","schema_version":"edge-lab-recorder.raw.v1","sequence":null,"source":"clob_market_ws"}
{"event_at":"2026-07-28T02:07:49.371000Z","event_fingerprint":"3dfe530a339ecd63aacaf5e0dc841bcae7f5d16110f7c1949a43a3194365da50","payload":{"connection_id":"5d29200f65794d4d9ab6ef271f045a9b","event_at":"2026-07-28T02:07:49.371000Z","event_type":"price_change","frame_hash":"b2438eed5101995bcbd48f499c754f06b2d86f43cb5209334df1cf3bd228ecce","frame_index":0,"kind":"data","monotonic_ns":306452728817583,"payload":{"event_type":"price_change","market":"0xda6f0e0e93fc8469e0159a166028d017bddbc162b86f66bac90391379603d962","price_changes":[{"asset_id":"20893381255801015515826997628594359667013752732428989472914000440642900266717","best_ask":"0.55","best_bid":"0.54","hash":"a6af1badbb162b7aa986f509e9569e328e619e27","price":"0.43","side":"BUY","size":"157.2"},{"asset_id":"39272994714739463168905443499424551362424437245880253267329605556587274644733","best_ask":"0.46","best_bid":"0.45","hash":"1068e766e7c6ddcd875804f786fd04e8e922d020","price":"0.57","side":"SELL","size":"157.2"}],"timestamp":"1785204469371"},"payload_hash":"f77817a92169384cd5df08a577e9a13c3f6b7d8587c52449c705586a519cc113","raw_frame":"{\"market\":\"0xda6f0e0e93fc8469e0159a166028d017bddbc162b86f66bac90391379603d962\", \"price_changes\":[{\"asset_id\":\"20893381255801015515826997628594359667013752732428989472914000440642900266717\", \"price\":\"0.43\", \"size\":\"157.2\", \"side\":\"BUY\", \"hash\":\"a6af1badbb162b7aa986f509e9569e328e619e27\", \"best_bid\":\"0.54\", \"best_ask\":\"0.55\"}, {\"asset_id\":\"39272994714739463168905443499424551362424437245880253267329605556587274644733\", \"price\":\"0.57\", \"size\":\"157.2\", \"side\":\"SELL\", \"hash\":\"1068e766e7c6ddcd875804f786fd04e8e922d020\", \"best_bid\":\"0.45\", \"best_ask\":\"0.46\"}], \"timestamp\":\"1785204469371\", \"event_type\":\"price_change\"}","received_at":"2026-07-28T02:07:49.721114Z","schema_version":"clob-market-ws.price_change.v1","sequence":null,"server_hash":null,"server_timestamp":"1785204469371","session_id":"d2757dd6dad94f3b9fe67e8dbf1adc37","source":"clob_market_ws"},"received_at":"2026-07-28T02:07:49.721114Z","record_id":"7cb8dd14fad45ac196a46e1a166e8cbb35b6d311a0ea1b9d7a2d4a8526fc5a05","schema_fingerprint":"4aa3821a28b0b7c2400bc59aba4bcc0a76e971dadd19610d3ad38c768e124dc7","schema_version":"edge-lab-recorder.raw.v1","sequence":null,"source":"clob_market_ws"}
{"event_at":"2026-07-28T02:07:49.372000Z","event_fingerprint":"7b16278f7b557bbc8bf4cfad3b70a09a6d515f2bdea717ebebd1732dbf5a7d2b","payload":{"connection_id":"5d29200f65794d4d9ab6ef271f045a9b","event_at":"2026-07-28T02:07:49.372000Z","event_type":"price_change","frame_hash":"2b5b56d7df6f607cdbbf875e73960fce76701a80914f50fb2fcf715d391ea5ee","frame_index":0,"kind":"data","monotonic_ns":306452737871958,"payload":{"event_type":"price_change","market":"0xda6f0e0e93fc8469e0159a166028d017bddbc162b86f66bac90391379603d962","price_changes":[{"asset_id":"20893381255801015515826997628594359667013752732428989472914000440642900266717","best_ask":"0.55","best_bid":"0.54","hash":"379763cd048852838755ad6d4664c0d1bc1fac9d","price":"0.41","side":"BUY","size":"67.4"},{"asset_id":"39272994714739463168905443499424551362424437245880253267329605556587274644733","best_ask":"0.46","best_bid":"0.45","hash":"90bdd72f190560aeb37514cf0bbbba120f5bf12d","price":"0.59","side":"SELL","size":"67.4"}],"timestamp":"1785204469372"},"payload_hash":"9f8430fb7abddcc2c1714aed6fb5442197a43fcb91bfa69ade898ad4ede24fde","raw_frame":"{\"market\":\"0xda6f0e0e93fc8469e0159a166028d017bddbc162b86f66bac90391379603d962\", \"price_changes\":[{\"asset_id\":\"20893381255801015515826997628594359667013752732428989472914000440642900266717\", \"price\":\"0.41\", \"size\":\"67.4\", \"side\":\"BUY\", \"hash\":\"379763cd048852838755ad6d4664c0d1bc1fac9d\", \"best_bid\":\"0.54\", \"best_ask\":\"0.55\"}, {\"asset_id\":\"39272994714739463168905443499424551362424437245880253267329605556587274644733\", \"price\":\"0.59\", \"size\":\"67.4\", \"side\":\"SELL\", \"hash\":\"90bdd72f190560aeb37514cf0bbbba120f5bf12d\", \"best_bid\":\"0.45\", \"best_ask\":\"0.46\"}], \"timestamp\":\"1785204469372\", \"event_type\":\"price_change\"}","received_at":"2026-07-28T02:07:49.730170Z","schema_version":"clob-market-ws.price_change.v1","sequence":null,"server_hash":null,"server_timestamp":"1785204469372","session_id":"d2757dd6dad94f3b9fe67e8dbf1adc37","source":"clob_market_ws"},"received_at":"2026-07-28T02:07:49.730170Z","record_id":"14c22d9a755119e440082892852e152dee835be47e8e640428c759c773408a11","schema_fingerprint":"4aa3821a28b0b7c2400bc59aba4bcc0a76e971dadd19610d3ad38c768e124dc7","schema_version":"edge-lab-recorder.raw.v1","sequence":null,"source":"clob_market_ws"}
{"event_at":"2026-07-28T02:07:49.373000Z","event_fingerprint":"93a8e2ea0224047ef0de8a9223ec7a2e938e1fd05e54d96076fca08a26ec5358","payload":{"connection_id":"5d29200f65794d4d9ab6ef271f045a9b","event_at":"2026-07-28T02:07:49.373000Z","event_type":"price_change","frame_hash":"01c703cbf9351afe7b69cba81887415cc2180d4ee6930545b96ddb41bbea08e0","frame_index":0,"kind":"data","monotonic_ns":306452743251958,"payload":{"event_type":"price_change","market":"0xda6f0e0e93fc8469e0159a166028d017bddbc162b86f66bac90391379603d962","price_changes":[{"asset_id":"20893381255801015515826997628594359667013752732428989472914000440642900266717","best_ask":"0.55","best_bid":"0.54","hash":"156ab57153163ea843742ab1f485827521d892b2","price":"0.43","side":"BUY","size":"164.7"},{"asset_id":"39272994714739463168905443499424551362424437245880253267329605556587274644733","best_ask":"0.46","best_bid":"0.45","hash":"f8c743c70fb069f27de384dcace2f730b9cad3b3","price":"0.57","side":"SELL","size":"164.7"}],"timestamp":"1785204469373"},"payload_hash":"771a1210985fe23aff7c3f624a32a7a0d6e5e38bf704cc2b2968277c84f482ef","raw_frame":"{\"market\":\"0xda6f0e0e93fc8469e0159a166028d017bddbc162b86f66bac90391379603d962\", \"price_changes\":[{\"asset_id\":\"20893381255801015515826997628594359667013752732428989472914000440642900266717\", \"price\":\"0.43\", \"size\":\"164.7\", \"side\":\"BUY\", \"hash\":\"156ab57153163ea843742ab1f485827521d892b2\", \"best_bid\":\"0.54\", \"best_ask\":\"0.55\"}, {\"asset_id\":\"39272994714739463168905443499424551362424437245880253267329605556587274644733\", \"price\":\"0.57\", \"size\":\"164.7\", \"side\":\"SELL\", \"hash\":\"f8c743c70fb069f27de384dcace2f730b9cad3b3\", \"best_bid\":\"0.45\", \"best_ask\":\"0.46\"}], \"timestamp\":\"1785204469373\", \"event_type\":\"price_change\"}","received_at":"2026-07-28T02:07:49.735547Z","schema_version":"clob-market-ws.price_change.v1","sequence":null,"server_hash":null,"server_timestamp":"1785204469373","session_id":"d2757dd6dad94f3b9fe67e8dbf1adc37","source":"clob_market_ws"},"received_at":"2026-07-28T02:07:49.735547Z","record_id":"5b6dc4b9b9ef7629557af21b0e7e7f6cb9e377ce9802bb1958033e412c6d4221","schema_fingerprint":"4aa3821a28b0b7c2400bc59aba4bcc0a76e971dadd19610d3ad38c768e124dc7","schema_version":"edge-lab-recorder.raw.v1","sequence":null,"source":"clob_market_ws"}
{"event_at":"2026-07-28T02:07:49.374000Z","event_fingerprint":"dc07572fab8e0ac2438e57f3ccc5ba3d7bc4f14c4282387310924a538ab6ee57","payload":{"connection_id":"5d29200f65794d4d9ab6ef271f045a9b","event_at":"2026-07-28T02:07:49.374000Z","event_type":"price_change","frame_hash":"a04bfcbd2c14c4f5752cd2a564c529fb6156405be9df44fe26382d124a6d1573","frame_index":0,"kind":"data","monotonic_ns":306452755261916,"payload":{"event_type":"price_change","market":"0xda6f0e0e93fc8469e0159a166028d017bddbc162b86f66bac90391379603d962","price_changes":[{"asset_id":"20893381255801015515826997628594359667013752732428989472914000440642900266717","best_ask":"0.55","best_bid":"0.54","hash":"4c56911fcdad3407c3d3f4d748033e598c8ce0df","price":"0.48","side":"BUY","size":"158.2"},{"asset_id":"39272994714739463168905443499424551362424437245880253267329605556587274644733","best_ask":"0.46","best_bid":"0.45","hash":"64997506cb63be0484ecf21f0accaf507deb11cf","price":"0.52","side":"SELL","size":"158.2"}],"timestamp":"1785204469374"},"payload_hash":"3f3e100d6fafbae93eddb163a009e44ee0a269728db269eae399274cfc699619","raw_frame":"{\"market\":\"0xda6f0e0e93fc8469e0159a166028d017bddbc162b86f66bac90391379603d962\", \"price_changes\":[{\"asset_id\":\"20893381255801015515826997628594359667013752732428989472914000440642900266717\", \"price\":\"0.48\", \"size\":\"158.2\", \"side\":\"BUY\", \"hash\":\"4c56911fcdad3407c3d3f4d748033e598c8ce0df\", \"best_bid\":\"0.54\", \"best_ask\":\"0.55\"}, {\"asset_id\":\"39272994714739463168905443499424551362424437245880253267329605556587274644733\", \"price\":\"0.52\", \"size\":\"158.2\", \"side\":\"SELL\", \"hash\":\"64997506cb63be0484ecf21f0accaf507deb11cf\", \"best_bid\":\"0.45\", \"best_ask\":\"0.46\"}], \"timestamp\":\"1785204469374\", \"event_type\":\"price_change\"}","received_at":"2026-07-28T02:07:49.747558Z","schema_version":"clob-market-ws.price_change.v1","sequence":null,"server_hash":null,"server_timestamp":"1785204469374","session_id":"d2757dd6dad94f3b9fe67e8dbf1adc37","source":"clob_market_ws"},"received_at":"2026-07-28T02:07:49.747558Z","record_id":"b1581bf7a13869bed3c51fdde6206c0878ea8d0cb26fb752080f168903b03995","schema_fingerprint":"4aa3821a28b0b7c2400bc59aba4bcc0a76e971dadd19610d3ad38c768e124dc7","schema_version":"edge-lab-recorder.raw.v1","sequence":null,"source":"clob_market_ws"}
{"event_at":"2026-07-28T02:07:49.375000Z","event_fingerprint":"f09e54b5d884ba6ca9a49ba841bb6e80dafe8bec8dcbc452e078e9568034d2e8","payload":{"connection_id":"5d29200f65794d4d9ab6ef271f045a9b","event_at":"2026-07-28T02:07:49.375000Z","event_type":"price_change","frame_hash":"6d75fec0bf05eb12bbbfcbe52cc9973b961d1ceb50146c139a3973290d9aab4f","frame_index":0,"kind":"data","monotonic_ns":306452759508166,"payload":{"event_type":"price_change","market":"0xda6f0e0e93fc8469e0159a166028d017bddbc162b86f66bac90391379603d962","price_changes":[{"asset_id":"39272994714739463168905443499424551362424437245880253267329605556587274644733","best_ask":"0.46","best_bid":"0.45","hash":"8bece4c82ebcbad04b7c6830b2d63cd7694e7ab6","price":"0.44","side":"BUY","size":"68"},{"asset_id":"20893381255801015515826997628594359667013752732428989472914000440642900266717","best_ask":"0.55","best_bid":"0.54","hash":"90bf1107c4828f71b94d43ee9b72b278b0e55455","price":"0.56","side":"SELL","size":"68"}],"timestamp":"1785204469375"},"payload_hash":"6b40ac94125e343a36e05c696ca10c7d85ce42c24dd258741249bf46f954c0b4","raw_frame":"{\"market\":\"0xda6f0e0e93fc8469e0159a166028d017bddbc162b86f66bac90391379603d962\", \"price_changes\":[{\"asset_id\":\"39272994714739463168905443499424551362424437245880253267329605556587274644733\", \"price\":\"0.44\", \"size\":\"68\", \"side\":\"BUY\", \"hash\":\"8bece4c82ebcbad04b7c6830b2d63cd7694e7ab6\", \"best_bid\":\"0.45\", \"best_ask\":\"0.46\"}, {\"asset_id\":\"20893381255801015515826997628594359667013752732428989472914000440642900266717\", \"price\":\"0.56\", \"size\":\"68\", \"side\":\"SELL\", \"hash\":\"90bf1107c4828f71b94d43ee9b72b278b0e55455\", \"best_bid\":\"0.54\", \"best_ask\":\"0.55\"}], \"timestamp\":\"1785204469375\", \"event_type\":\"price_change\"}","received_at":"2026-07-28T02:07:49.751805Z","schema_version":"clob-market-ws.price_change.v1","sequence":null,"server_hash":null,"server_timestamp":"1785204469375","session_id":"d2757dd6dad94f3b9fe67e8dbf1adc37","source":"clob_market_ws"},"received_at":"2026-07-28T02:07:49.751805Z","record_id":"d28f4835b8d51987cf6e911b79e954c87c66a75547e07d8e337d3c3eaea4a5c2","schema_fingerprint":"4aa3821a28b0b7c2400bc59aba4bcc0a76e971dadd19610d3ad38c768e124dc7","schema_version":"edge-lab-recorder.raw.v1","sequence":null,"source":"clob_market_ws"}
{"event_at":"2026-07-28T02:07:49.375000Z","event_fingerprint":"4420be0cb4082326f7cc281dbf086f54d7f933ef4e06c469274154d4bcc7faff","payload":{"connection_id":"5d29200f65794d4d9ab6ef271f045a9b","event_at":"2026-07-28T02:07:49.375000Z","event_type":"price_change","frame_hash":"95235d7dfabff57c0cae2b447b2161269339fe3070e0cb3f06f0e872696add7e","frame_index":0,"kind":"data","monotonic_ns":306452763801250,"payload":{"event_type":"price_change","market":"0xda6f0e0e93fc8469e0159a166028d017bddbc162b86f66bac90391379603d962","price_changes":[{"asset_id":"20893381255801015515826997628594359667013752732428989472914000440642900266717","best_ask":"0.55","best_bid":"0.54","hash":"a0d4a7106697bef7ca895f73e8f7b797337cb201","price":"0.45","side":"BUY","size":"192"},{"asset_id":"39272994714739463168905443499424551362424437245880253267329605556587274644733","best_ask":"0.46","best_bid":"0.45","hash":"db6cbb0459a38faaca28fd5a980b884d40eb6b26","price":"0.55","side":"SELL","size":"192"}],"timestamp":"1785204469375"},"payload_hash":"436d03c5882edcfb65f205d299388db677c41245009a02c654c2cac2a990f352","raw_frame":"{\"market\":\"0xda6f0e0e93fc8469e0159a166028d017bddbc162b86f66bac90391379603d962\", \"price_changes\":[{\"asset_id\":\"20893381255801015515826997628594359667013752732428989472914000440642900266717\", \"price\":\"0.45\", \"size\":\"192\", \"side\":\"BUY\", \"hash\":\"a0d4a7106697bef7ca895f73e8f7b797337cb201\", \"best_bid\":\"0.54\", \"best_ask\":\"0.55\"}, {\"asset_id\":\"39272994714739463168905443499424551362424437245880253267329605556587274644733\", \"price\":\"0.55\", \"size\":\"192\", \"side\":\"SELL\", \"hash\":\"db6cbb0459a38faaca28fd5a980b884d40eb6b26\", \"best_bid\":\"0.45\", \"best_ask\":\"0.46\"}], \"timestamp\":\"1785204469375\", \"event_type\":\"price_change\"}","received_at":"2026-07-28T02:07:49.756099Z","schema_version":"clob-market-ws.price_change.v1","sequence":null,"server_hash":null,"server_timestamp":"1785204469375","session_id":"d2757dd6dad94f3b9fe67e8dbf1adc37","source":"clob_market_ws"},"received_at":"2026-07-28T02:07:49.756099Z","record_id":"453fbe0081883fa455b391e352f48cef22f1839c49f95b7c0abee982a4f05a66","schema_fingerprint":"4aa3821a28b0b7c2400bc59aba4bcc0a76e971dadd19610d3ad38c768e124dc7","schema_version":"edge-lab-recorder.raw.v1","sequence":null,"source":"clob_market_ws"}
{"event_at":"2026-07-28T02:07:49.376000Z","event_fingerprint":"3bbce232047459a7e79ffc67115bfc6ac6fb308d3242e8f3b43b078626c90bcd","payload":{"connection_id":"5d29200f65794d4d9ab6ef271f045a9b","event_at":"2026-07-28T02:07:49.376000Z","event_type":"price_change","frame_hash":"1ad42e64aa129c0b1f187689922562f3a8427231ce4c76f099d2755f935f415f","frame_index":0,"kind":"data","monotonic_ns":306452768133458,"payload":{"event_type":"price_change","market":"0xda6f0e0e93fc8469e0159a166028d017bddbc162b86f66bac90391379603d962","price_changes":[{"asset_id":"20893381255801015515826997628594359667013752732428989472914000440642900266717","best_ask":"0.55","best_bid":"0.54","hash":"64ad9a885c0a6d7eabbbfb9a67d9ebcf0bde43ee","price":"0.43","side":"BUY","size":"211.7"},{"asset_id":"39272994714739463168905443499424551362424437245880253267329605556587274644733","best_ask":"0.46","best_bid":"0.45","hash":"867a9082255e64b57f0360fcb709b5784c169524","price":"0.57","side":"SELL","size":"211.7"}],"timestamp":"1785204469376"},"payload_hash":"55e83092a16a907ea62315641e556dc1c27aaa3341e491f96e96c5244832e039","raw_frame":"{\"market\":\"0xda6f0e0e93fc8469e0159a166028d017bddbc162b86f66bac90391379603d962\", \"price_changes\":[{\"asset_id\":\"20893381255801015515826997628594359667013752732428989472914000440642900266717\", \"price\":\"0.43\", \"size\":\"211.7\", \"side\":\"BUY\", \"hash\":\"64ad9a885c0a6d7eabbbfb9a67d9ebcf0bde43ee\", \"best_bid\":\"0.54\", \"best_ask\":\"0.55\"}, {\"asset_id\":\"39272994714739463168905443499424551362424437245880253267329605556587274644733\", \"price\":\"0.57\", \"size\":\"211.7\", \"side\":\"SELL\", \"hash\":\"867a9082255e64b57f0360fcb709b5784c169524\", \"best_bid\":\"0.45\", \"best_ask\":\"0.46\"}], \"timestamp\":\"1785204469376\", \"event_type\":\"price_change\"}","received_at":"2026-07-28T02:07:49.760431Z","schema_version":"clob-market-ws.price_change.v1","sequence":null,"server_hash":null,"server_timestamp":"1785204469376","session_id":"d2757dd6dad94f3b9fe67e8dbf1adc37","source":"clob_market_ws"},"received_at":"2026-07-28T02:07:49.760431Z","record_id":"546ea9129b9d3895127e4de17a08522f5cc67a333779583dd07715340a515382","schema_fingerprint":"4aa3821a28b0b7c2400bc59aba4bcc0a76e971dadd19610d3ad38c768e124dc7","schema_version":"edge-lab-recorder.raw.v1","sequence":null,"source":"clob_market_ws"}
{"event_at":"2026-07-28T02:07:49.376000Z","event_fingerprint":"ebbddef6f32c198e915c5142410ca5f03a4d25b3462e79d4527e43e227e183ab","payload":{"connection_id":"5d29200f65794d4d9ab6ef271f045a9b","event_at":"2026-07-28T02:07:49.376000Z","event_type":"price_change","frame_hash":"625191979dd1d64fe4fcf53bf0dff9f2fb12158a22bd7afe6b4cf791c90f597b","frame_index":0,"kind":"data","monotonic_ns":306452772429333,"payload":{"event_type":"price_change","market":"0xda6f0e0e93fc8469e0159a166028d017bddbc162b86f66bac90391379603d962","price_changes":[{"asset_id":"20893381255801015515826997628594359667013752732428989472914000440642900266717","best_ask":"0.55","best_bid":"0.54","hash":"ec1d5041ca2a6feb6e05b3dda8e5daeef1ce5284","price":"0.46","side":"BUY","size":"126"},{"asset_id":"39272994714739463168905443499424551362424437245880253267329605556587274644733","best_ask":"0.46","best_bid":"0.45","hash":"cb3ddcd19e653db6075ec7b0adf698460117bf04","price":"0.54","side":"SELL","size":"126"}],"timestamp":"1785204469376"},"payload_hash":"e6ea116444d18805c899f300dac4bd7ebaccdf9fadc947394d1b3b6df518c124","raw_frame":"{\"market\":\"0xda6f0e0e93fc8469e0159a166028d017bddbc162b86f66bac90391379603d962\", \"price_changes\":[{\"asset_id\":\"20893381255801015515826997628594359667013752732428989472914000440642900266717\", \"price\":\"0.46\", \"size\":\"126\", \"side\":\"BUY\", \"hash\":\"ec1d5041ca2a6feb6e05b3dda8e5daeef1ce5284\", \"best_bid\":\"0.54\", \"best_ask\":\"0.55\"}, {\"asset_id\":\"39272994714739463168905443499424551362424437245880253267329605556587274644733\", \"price\":\"0.54\", \"size\":\"126\", \"side\":\"SELL\", \"hash\":\"cb3ddcd19e653db6075ec7b0adf698460117bf04\", \"best_bid\":\"0.45\", \"best_ask\":\"0.46\"}], \"timestamp\":\"1785204469376\", \"event_type\":\"price_change\"}","received_at":"2026-07-28T02:07:49.764727Z","schema_version":"clob-market-ws.price_change.v1","sequence":null,"server_hash":null,"server_timestamp":"1785204469376","session_id":"d2757dd6dad94f3b9fe67e8dbf1adc37","source":"clob_market_ws"},"received_at":"2026-07-28T02:07:49.764727Z","record_id":"64eff51ed0e4a8140e169e679a9035c1df8164a02cc69f07390c5c6e64415285","schema_fingerprint":"4aa3821a28b0b7c2400bc59aba4bcc0a76e971dadd19610d3ad38c768e124dc7","schema_version":"edge-lab-recorder.raw.v1","sequence":null,"source":"clob_market_ws"}
{"event_at":"2026-07-28T02:07:49.377000Z","event_fingerprint":"f63764538a1c097d93caeaddcb395b2ed18a54c85f2138d264b8fb8fe37c20ea","payload":{"connection_id":"5d29200f65794d4d9ab6ef271f045a9b","event_at":"2026-07-28T02:07:49.377000Z","event_type":"price_change","frame_hash":"bcfa86561adb84533f9bc4f651126ca4f972c1825077e92def7eec6e1c801d91","frame_index":0,"kind":"data","monotonic_ns":306452776678458,"payload":{"event_type":"price_change","market":"0xda6f0e0e93fc8469e0159a166028d017bddbc162b86f66bac90391379603d962","price_changes":[{"asset_id":"39272994714739463168905443499424551362424437245880253267329605556587274644733","best_ask":"0.46","best_bid":"0.45","hash":"9e4cc2ac7d8f03b8701d8e1ad76e163398a2d333","price":"0.44","side":"BUY","size":"44"},{"asset_id":"20893381255801015515826997628594359667013752732428989472914000440642900266717","best_ask":"0.55","best_bid":"0.54","hash":"25c86da44e4d278ec25696344de03bfccb48e76f","price":"0.56","side":"SELL","size":"44"}],"timestamp":"1785204469377"},"payload_hash":"cd993eff5a8aa2e61362e6d3cf59c5e210ace70686bb7631d1f4429ba139f4a1","raw_frame":"{\"market\":\"0xda6f0e0e93fc8469e0159a166028d017bddbc162b86f66bac90391379603d962\", \"price_changes\":[{\"asset_id\":\"39272994714739463168905443499424551362424437245880253267329605556587274644733\", \"price\":\"0.44\", \"size\":\"44\", \"side\":\"BUY\", \"hash\":\"9e4cc2ac7d8f03b8701d8e1ad76e163398a2d333\", \"best_bid\":\"0.45\", \"best_ask\":\"0.46\"}, {\"asset_id\":\"20893381255801015515826997628594359667013752732428989472914000440642900266717\", \"price\":\"0.56\", \"size\":\"44\", \"side\":\"SELL\", \"hash\":\"25c86da44e4d278ec25696344de03bfccb48e76f\", \"best_bid\":\"0.54\", \"best_ask\":\"0.55\"}], \"timestamp\":\"1785204469377\", \"event_type\":\"price_change\"}","received_at":"2026-07-28T02:07:49.768976Z","schema_version":"clob-market-ws.price_change.v1","sequence":null,"server_hash":null,"server_timestamp":"1785204469377","session_id":"d2757dd6dad94f3b9fe67e8dbf1adc37","source":"clob_market_ws"},"received_at":"2026-07-28T02:07:49.768976Z","record_id":"ca9eb6d16a0aa3af7b21bd6858ab84b15b6f2fa0d87d7fc5fb8cd08316076a1e","schema_fingerprint":"4aa3821a28b0b7c2400bc59aba4bcc0a76e971dadd19610d3ad38c768e124dc7","schema_version":"edge-lab-recorder.raw.v1","sequence":null,"source":"clob_market_ws"}
{"event_at":"2026-07-28T02:07:49.378000Z","event_fingerprint":"05c3822533dc3f76c4fae32f52a68b44d04ec283c52b765ff63205d23062ff9e","payload":{"connection_id":"5d29200f65794d4d9ab6ef271f045a9b","event_at":"2026-07-28T02:07:49.378000Z","event_type":"price_change","frame_hash":"226bf1cb18f4c56a66094dd56ae29a3f94fb518f68a901d8a4d187599d4d557b","frame_index":0,"kind":"data","monotonic_ns":306452782130875,"payload":{"event_type":"price_change","market":"0xda6f0e0e93fc8469e0159a166028d017bddbc162b86f66bac90391379603d962","price_changes":[{"asset_id":"20893381255801015515826997628594359667013752732428989472914000440642900266717","best_ask":"0.55","best_bid":"0.54","hash":"a4b0ab8328f2dd0eddf491c66cbf1c99d62b757a","price":"0.5","side":"BUY","size":"123.6"},{"asset_id":"39272994714739463168905443499424551362424437245880253267329605556587274644733","best_ask":"0.46","best_bid":"0.45","hash":"f6dd5fc3b9a8ac365542c447d6889f00d25d59e1","price":"0.5","side":"SELL","size":"123.6"}],"timestamp":"1785204469378"},"payload_hash":"4324847363108f54fe7066e9d0b83faea7b025daffbcec6bb8816f5185205d0d","raw_frame":"{\"market\":\"0xda6f0e0e93fc8469e0159a166028d017bddbc162b86f66bac90391379603d962\", \"price_changes\":[{\"asset_id\":\"20893381255801015515826997628594359667013752732428989472914000440642900266717\", \"price\":\"0.5\", \"size\":\"123.6\", \"side\":\"BUY\", \"hash\":\"a4b0ab8328f2dd0eddf491c66cbf1c99d62b757a\", \"best_bid\":\"0.54\", \"best_ask\":\"0.55\"}, {\"asset_id\":\"39272994714739463168905443499424551362424437245880253267329605556587274644733\", \"price\":\"0.5\", \"size\":\"123.6\", \"side\":\"SELL\", \"hash\":\"f6dd5fc3b9a8ac365542c447d6889f00d25d59e1\", \"best_bid\":\"0.45\", \"best_ask\":\"0.46\"}], \"timestamp\":\"1785204469378\", \"event_type\":\"price_change\"}","received_at":"2026-07-28T02:07:49.774428Z","schema_version":"clob-market-ws.price_change.v1","sequence":null,"server_hash":null,"server_timestamp":"1785204469378","session_id":"d2757dd6dad94f3b9fe67e8dbf1adc37","source":"clob_market_ws"},"received_at":"2026-07-28T02:07:49.774428Z","record_id":"3f66c9082bb14ce81b4237f2241af7d00dcc18a64c3e4234e1e0151477447888","schema_fingerprint":"4aa3821a28b0b7c2400bc59aba4bcc0a76e971dadd19610d3ad38c768e124dc7","schema_version":"edge-lab-recorder.raw.v1","sequence":null,"source":"clob_market_ws"}
{"event_at":"2026-07-28T02:07:49.379000Z","event_fingerprint":"9eb2fecb31b23be29ca2a2ee90fce993644f145ee7bbe68a9029d0af65840656","payload":{"connection_id":"5d29200f65794d4d9ab6ef271f045a9b","event_at":"2026-07-28T02:07:49.379000Z","event_type":"price_change","frame_hash":"15f5e11a699a82190f49c5aba17a78cd9b17645edd563e63d1080794e6fa0156","frame_index":0,"kind":"data","monotonic_ns":306452786716833,"payload":{"event_type":"price_change","market":"0xda6f0e0e93fc8469e0159a166028d017bddbc162b86f66bac90391379603d962","price_changes":[{"asset_id":"39272994714739463168905443499424551362424437245880253267329605556587274644733","best_ask":"0.46","best_bid":"0.45","hash":"318846fd2ad63534de94c1b1927fc8671f0c9a9e","price":"0.3","side":"BUY","size":"458.33"},{"asset_id":"20893381255801015515826997628594359667013752732428989472914000440642900266717","best_ask":"0.55","best_bid":"0.54","hash":"59b907e3cb68e38a5350ce0a7d33dd6740aaa5dc","price":"0.7","side":"SELL","size":"458.33"}],"timestamp":"1785204469379"},"payload_hash":"1f96748cc28179960df6f551c9b64333b6ba275fc09b0e3e4accdf4a7a90547f","raw_frame":"{\"market\":\"0xda6f0e0e93fc8469e0159a166028d017bddbc162b86f66bac90391379603d962\", \"price_changes\":[{\"asset_id\":\"39272994714739463168905443499424551362424437245880253267329605556587274644733\", \"price\":\"0.3\", \"size\":\"458.33\", \"side\":\"BUY\", \"hash\":\"318846fd2ad63534de94c1b1927fc8671f0c9a9e\", \"best_bid\":\"0.45\", \"best_ask\":\"0.46\"}, {\"asset_id\":\"20893381255801015515826997628594359667013752732428989472914000440642900266717\", \"price\":\"0.7\", \"size\":\"458.33\", \"side\":\"SELL\", \"hash\":\"59b907e3cb68e38a5350ce0a7d33dd6740aaa5dc\", \"best_bid\":\"0.54\", \"best_ask\":\"0.55\"}], \"timestamp\":\"1785204469379\", \"event_type\":\"price_change\"}","received_at":"2026-07-28T02:07:49.779012Z","schema_version":"clob-market-ws.price_change.v1","sequence":null,"server_hash":null,"server_timestamp":"1785204469379","session_id":"d2757dd6dad94f3b9fe67e8dbf1adc37","source":"clob_market_ws"},"received_at":"2026-07-28T02:07:49.779012Z","record_id":"c9c30d217ed5bdba3599e0110a2afb5284e600b6ef96edce20ad951aacae107b","schema_fingerprint":"4aa3821a28b0b7c2400bc59aba4bcc0a76e971dadd19610d3ad38c768e124dc7","schema_version":"edge-lab-recorder.raw.v1","sequence":null,"source":"clob_market_ws"}
{"event_at":"2026-07-28T02:07:49.380000Z","event_fingerprint":"de9ce419ff3fdb6d670c0d6ad2b3abacf9c971c67b37c065ea8d27bddee87dca","payload":{"connection_id":"5d29200f65794d4d9ab6ef271f045a9b","event_at":"2026-07-28T02:07:49.380000Z","event_type":"price_change","frame_hash":"f027cd78595a2a59fb9589123b8a0105822f79a3f847b90c3b36fed8804ff29e","frame_index":0,"kind":"data","monotonic_ns":306452791388750,"payload":{"event_type":"price_change","market":"0xda6f0e0e93fc8469e0159a166028d017bddbc162b86f66bac90391379603d962","price_changes":[{"asset_id":"20893381255801015515826997628594359667013752732428989472914000440642900266717","best_ask":"0.55","best_bid":"0.54","hash":"535f923a1f9b4d84453ad48af480ddfeb0d34754","price":"0.49","side":"BUY","size":"133.2"},{"asset_id":"39272994714739463168905443499424551362424437245880253267329605556587274644733","best_ask":"0.46","best_bid":"0.45","hash":"db62a2951b9eeb2ed0451d00589f29fb7dc600ba","price":"0.51","side":"SELL","size":"133.2"}],"timestamp":"1785204469380"},"payload_hash":"d867710684cd2130be81934235884e54155735dfabd4c8866aec03f8ddfd09a9","raw_frame":"{\"market\":\"0xda6f0e0e93fc8469e0159a166028d017bddbc162b86f66bac90391379603d962\", \"price_changes\":[{\"asset_id\":\"20893381255801015515826997628594359667013752732428989472914000440642900266717\", \"price\":\"0.49\", \"size\":\"133.2\", \"side\":\"BUY\", \"hash\":\"535f923a1f9b4d84453ad48af480ddfeb0d34754\", \"best_bid\":\"0.54\", \"best_ask\":\"0.55\"}, {\"asset_id\":\"39272994714739463168905443499424551362424437245880253267329605556587274644733\", \"price\":\"0.51\", \"size\":\"133.2\", \"side\":\"SELL\", \"hash\":\"db62a2951b9eeb2ed0451d00589f29fb7dc600ba\", \"best_bid\":\"0.45\", \"best_ask\":\"0.46\"}], \"timestamp\":\"1785204469380\", \"event_type\":\"price_change\"}","received_at":"2026-07-28T02:07:49.783684Z","schema_version":"clob-market-ws.price_change.v1","sequence":null,"server_hash":null,"server_timestamp":"1785204469380","session_id":"d2757dd6dad94f3b9fe67e8dbf1adc37","source":"clob_market_ws"},"received_at":"2026-07-28T02:07:49.783684Z","record_id":"3daf0a125dd7f2953c31d903c81ae960db90eb4c9f6105dfc4b9d4141ada71f0","schema_fingerprint":"4aa3821a28b0b7c2400bc59aba4bcc0a76e971dadd19610d3ad38c768e124dc7","schema_version":"edge-lab-recorder.raw.v1","sequence":null,"source":"clob_market_ws"}
{"event_at":"2026-07-28T02:07:49.380000Z","event_fingerprint":"1e22dd6752719ba12481f16eb622b3dac4de023a86a6d70c54231a7af4e0124c","payload":{"connection_id":"5d29200f65794d4d9ab6ef271f045a9b","event_at":"2026-07-28T02:07:49.380000Z","event_type":"price_change","frame_hash":"1682fc17cad78db19237f2c17d547fa76dc29306a55698c0b567019a52b305bf","frame_index":0,"kind":"data","monotonic_ns":306452796859916,"payload":{"event_type":"price_change","market":"0xda6f0e0e93fc8469e0159a166028d017bddbc162b86f66bac90391379603d962","price_changes":[{"asset_id":"20893381255801015515826997628594359667013752732428989472914000440642900266717","best_ask":"0.55","best_bid":"0.54","hash":"7ad7fda68cb8136072c591dd5d1c5de76ea8b438","price":"0.53","side":"BUY","size":"182.6"},{"asset_id":"39272994714739463168905443499424551362424437245880253267329605556587274644733","best_ask":"0.46","best_bid":"0.45","hash":"bd6c7f6bf13672aab2e59b39088f5cf8b04b7e7c","price":"0.47","side":"SELL","size":"182.6"}],"timestamp":"1785204469380"},"payload_hash":"fbc4ca84d2d9b229ba52c668367bac6439f57b2a014aed713670e09adc3fde0d","raw_frame":"{\"market\":\"0xda6f0e0e93fc8469e0159a166028d017bddbc162b86f66bac90391379603d962\", \"price_changes\":[{\"asset_id\":\"20893381255801015515826997628594359667013752732428989472914000440642900266717\", \"price\":\"0.53\", \"size\":\"182.6\", \"side\":\"BUY\", \"hash\":\"7ad7fda68cb8136072c591dd5d1c5de76ea8b438\", \"best_bid\":\"0.54\", \"best_ask\":\"0.55\"}, {\"asset_id\":\"39272994714739463168905443499424551362424437245880253267329605556587274644733\", \"price\":\"0.47\", \"size\":\"182.6\", \"side\":\"SELL\", \"hash\":\"bd6c7f6bf13672aab2e59b39088f5cf8b04b7e7c\", \"best_bid\":\"0.45\", \"best_ask\":\"0.46\"}], \"timestamp\":\"1785204469380\", \"event_type\":\"price_change\"}","received_at":"2026-07-28T02:07:49.789157Z","schema_version":"clob-market-ws.price_change.v1","sequence":null,"server_hash":null,"server_timestamp":"1785204469380","session_id":"d2757dd6dad94f3b9fe67e8dbf1adc37","source":"clob_market_ws"},"received_at":"2026-07-28T02:07:49.789157Z","record_id":"f48b2d4d9699ae7e7a961330f230ec66a8e6acafdf271d82b273cde586ccf8eb","schema_fingerprint":"4aa3821a28b0b7c2400bc59aba4bcc0a76e971dadd19610d3ad38c768e124dc7","schema_version":"edge-lab-recorder.raw.v1","sequence":null,"source":"clob_market_ws"}
{"event_at":"2026-07-28T02:07:49.381000Z","event_fingerprint":"43a800b610f0b7ff4065dd2448939a8b3203b58acf163071780de01f34f6c448","payload":{"connection_id":"5d29200f65794d4d9ab6ef271f045a9b","event_at":"2026-07-28T02:07:49.381000Z","event_type":"price_change","frame_hash":"0d2fea24d25d288c068c04042c0377dbae50366d2e925af6997b5d8be5b37f24","frame_index":0,"kind":"data","monotonic_ns":306452802011291,"payload":{"event_type":"price_change","market":"0xda6f0e0e93fc8469e0159a166028d017bddbc162b86f66bac90391379603d962","price_changes":[{"asset_id":"39272994714739463168905443499424551362424437245880253267329605556587274644733","best_ask":"0.46","best_bid":"0.45","hash":"b6c300f2d1e88632955c4c0806c12bf7aeb2e9bc","price":"0.43","side":"BUY","size":"115"},{"asset_id":"20893381255801015515826997628594359667013752732428989472914000440642900266717","best_ask":"0.55","best_bid":"0.54","hash":"78df58afab20422d05c93ecb4ed263af09a3dc45","price":"0.57","side":"SELL","size":"115"}],"timestamp":"1785204469381"},"payload_hash":"052dbe85a5302dcf35789d9947fabaa2be5cd92b0ca86a543fd9f6613f277b88","raw_frame":"{\"market\":\"0xda6f0e0e93fc8469e0159a166028d017bddbc162b86f66bac90391379603d962\", \"price_changes\":[{\"asset_id\":\"39272994714739463168905443499424551362424437245880253267329605556587274644733\", \"price\":\"0.43\", \"size\":\"115\", \"side\":\"BUY\", \"hash\":\"b6c300f2d1e88632955c4c0806c12bf7aeb2e9bc\", \"best_bid\":\"0.45\", \"best_ask\":\"0.46\"}, {\"asset_id\":\"20893381255801015515826997628594359667013752732428989472914000440642900266717\", \"price\":\"0.57\", \"size\":\"115\", \"side\":\"SELL\", \"hash\":\"78df58afab20422d05c93ecb4ed263af09a3dc45\", \"best_bid\":\"0.54\", \"best_ask\":\"0.55\"}], \"timestamp\":\"1785204469381\", \"event_type\":\"price_change\"}","received_at":"2026-07-28T02:07:49.794307Z","schema_version":"clob-market-ws.price_change.v1","sequence":null,"server_hash":null,"server_timestamp":"1785204469381","session_id":"d2757dd6dad94f3b9fe67e8dbf1adc37","source":"clob_market_ws"},"received_at":"2026-07-28T02:07:49.794307Z","record_id":"46d73aecf8f7c411d51725bb9dd4097849cdc8f13037a9c037f9b0e497d0ee1e","schema_fingerprint":"4aa3821a28b0b7c2400bc59aba4bcc0a76e971dadd19610d3ad38c768e124dc7","schema_version":"edge-lab-recorder.raw.v1","sequence":null,"source":"clob_market_ws"}
{"event_at":"2026-07-28T02:07:49.382000Z","event_fingerprint":"d06316da5ac2a3572b2cb4cf7523e7b5bf3d2be8e130fbd406857ec8f2050bf6","payload":{"connection_id":"5d29200f65794d4d9ab6ef271f045a9b","event_at":"2026-07-28T02:07:49.382000Z","event_type":"price_change","frame_hash":"56716e3ed02827d582dca8d57d69604945d92400ec2600bdca2c88c650753806","frame_index":0,"kind":"data","monotonic_ns":306452806494291,"payload":{"event_type":"price_change","market":"0xda6f0e0e93fc8469e0159a166028d017bddbc162b86f66bac90391379603d962","price_changes":[{"asset_id":"20893381255801015515826997628594359667013752732428989472914000440642900266717","best_ask":"0.55","best_bid":"0.54","hash":"2a7f7376ce52e5e6522c712870487d864125329e","price":"0.53","side":"BUY","size":"148.6"},{"asset_id":"39272994714739463168905443499424551362424437245880253267329605556587274644733","best_ask":"0.46","best_bid":"0.45","hash":"643cf40262e3651bec62bd6ea243b7a4cf83eb10","price":"0.47","side":"SELL","size":"148.6"}],"timestamp":"1785204469382"},"payload_hash":"e1c79101b2551866baedc40bd5605a18934a42ff333c497bafef1865c54f02e5","raw_frame":"{\"market\":\"0xda6f0e0e93fc8469e0159a166028d017bddbc162b86f66bac90391379603d962\", \"price_changes\":[{\"asset_id\":\"20893381255801015515826997628594359667013752732428989472914000440642900266717\", \"price\":\"0.53\", \"size\":\"148.6\", \"side\":\"BUY\", \"hash\":\"2a7f7376ce52e5e6522c712870487d864125329e\", \"best_bid\":\"0.54\", \"best_ask\":\"0.55\"}, {\"asset_id\":\"39272994714739463168905443499424551362424437245880253267329605556587274644733\", \"price\":\"0.47\", \"size\":\"148.6\", \"side\":\"SELL\", \"hash\":\"643cf40262e3651bec62bd6ea243b7a4cf83eb10\", \"best_bid\":\"0.45\", \"best_ask\":\"0.46\"}], \"timestamp\":\"1785204469382\", \"event_type\":\"price_change\"}","received_at":"2026-07-28T02:07:49.798791Z","schema_version":"clob-market-ws.price_change.v1","sequence":null,"server_hash":null,"server_timestamp":"1785204469382","session_id":"d2757dd6dad94f3b9fe67e8dbf1adc37","source":"clob_market_ws"},"received_at":"2026-07-28T02:07:49.798791Z","record_id":"cada2334c08b219d341d98412b711a843d988eedb0f9c4a5c898c6593d7f2e29","schema_fingerprint":"4aa3821a28b0b7c2400bc59aba4bcc0a76e971dadd19610d3ad38c768e124dc7","schema_version":"edge-lab-recorder.raw.v1","sequence":null,"source":"clob_market_ws"}
{"event_at":"2026-07-28T02:07:49.383000Z","event_fingerprint":"41e25fb92183025bede2da829a8381917b4caa632064a491c4a38045cfd99661","payload":{"connection_id":"5d29200f65794d4d9ab6ef271f045a9b","event_at":"2026-07-28T02:07:49.383000Z","event_type":"price_change","frame_hash":"4fb7ed7f6a90379e2c82337b2221ce8748ea304db3b3dfd23090fb141ee78d1c","frame_index":0,"kind":"data","monotonic_ns":306452810885458,"payload":{"event_type":"price_change","market":"0xda6f0e0e93fc8469e0159a166028d017bddbc162b86f66bac90391379603d962","price_changes":[{"asset_id":"20893381255801015515826997628594359667013752732428989472914000440642900266717","best_ask":"0.55","best_bid":"0.54","hash":"ad96d656e94490f3389cc012eaf8af8f9ec5f46b","price":"0.47","side":"BUY","size":"114"},{"asset_id":"39272994714739463168905443499424551362424437245880253267329605556587274644733","best_ask":"0.46","best_bid":"0.45","hash":"c10a35dde4ffd6fed048698bf7f3d40c26a88b1d","price":"0.53","side":"SELL","size":"114"}],"timestamp":"1785204469383"},"payload_hash":"baafd3c73774335420cf30ebae8672e2078cdd76d4b07702c621b8fa3ac7e7c8","raw_frame":"{\"market\":\"0xda6f0e0e93fc8469e0159a166028d017bddbc162b86f66bac90391379603d962\", \"price_changes\":[{\"asset_id\":\"20893381255801015515826997628594359667013752732428989472914000440642900266717\", \"price\":\"0.47\", \"size\":\"114\", \"side\":\"BUY\", \"hash\":\"ad96d656e94490f3389cc012eaf8af8f9ec5f46b\", \"best_bid\":\"0.54\", \"best_ask\":\"0.55\"}, {\"asset_id\":\"39272994714739463168905443499424551362424437245880253267329605556587274644733\", \"price\":\"0.53\", \"size\":\"114\", \"side\":\"SELL\", \"hash\":\"c10a35dde4ffd6fed048698bf7f3d40c26a88b1d\", \"best_bid\":\"0.45\", \"best_ask\":\"0.46\"}], \"timestamp\":\"1785204469383\", \"event_type\":\"price_change\"}","received_at":"2026-07-28T02:07:49.803182Z","schema_version":"clob-market-ws.price_change.v1","sequence":null,"server_hash":null,"server_timestamp":"1785204469383","session_id":"d2757dd6dad94f3b9fe67e8dbf1adc37","source":"clob_market_ws"},"received_at":"2026-07-28T02:07:49.803182Z","record_id":"202adda2be652c0d8b113e232bbec8ec7f493ddc183855334d22cd2646b8cc17","schema_fingerprint":"4aa3821a28b0b7c2400bc59aba4bcc0a76e971dadd19610d3ad38c768e124dc7","schema_version":"edge-lab-recorder.raw.v1","sequence":null,"source":"clob_market_ws"}
{"event_at":"2026-07-28T02:07:49.384000Z","event_fingerprint":"3e2c672087639c2f6ccb4085f7c09aac4af235bc479f765fc23eccca662aa504","payload":{"connection_id":"5d29200f65794d4d9ab6ef271f045a9b","event_at":"2026-07-28T02:07:49.384000Z","event_type":"price_change","frame_hash":"47aa55a83a6cb3dc6f8575ea2d789b0522b2d9e04490621c697569e610a40abe","frame_index":0,"kind":"data","monotonic_ns":306452815840500,"payload":{"event_type":"price_change","market":"0xda6f0e0e93fc8469e0159a166028d017bddbc162b86f66bac90391379603d962","price_changes":[{"asset_id":"20893381255801015515826997628594359667013752732428989472914000440642900266717","best_ask":"0.55","best_bid":"0.54","hash":"abd288b65f8481dce0131af37c0df484bb03ef2f","price":"0.48","side":"BUY","size":"145.6"},{"asset_id":"39272994714739463168905443499424551362424437245880253267329605556587274644733","best_ask":"0.46","best_bid":"0.45","hash":"5b01c616dacd4e71cff4b1ca8e99772a87ac482a","price":"0.52","side":"SELL","size":"145.6"}],"timestamp":"1785204469384"},"payload_hash":"5d71607944060258f02fc7ce97ea4a9b27f0f2187c28ddbdc2f62ec46103023e","raw_frame":"{\"market\":\"0xda6f0e0e93fc8469e0159a166028d017bddbc162b86f66bac90391379603d962\", \"price_changes\":[{\"asset_id\":\"20893381255801015515826997628594359667013752732428989472914000440642900266717\", \"price\":\"0.48\", \"size\":\"145.6\", \"side\":\"BUY\", \"hash\":\"abd288b65f8481dce0131af37c0df484bb03ef2f\", \"best_bid\":\"0.54\", \"best_ask\":\"0.55\"}, {\"asset_id\":\"39272994714739463168905443499424551362424437245880253267329605556587274644733\", \"price\":\"0.52\", \"size\":\"145.6\", \"side\":\"SELL\", \"hash\":\"5b01c616dacd4e71cff4b1ca8e99772a87ac482a\", \"best_bid\":\"0.45\", \"best_ask\":\"0.46\"}], \"timestamp\":\"1785204469384\", \"event_type\":\"price_change\"}","received_at":"2026-07-28T02:07:49.808137Z","schema_version":"clob-market-ws.price_change.v1","sequence":null,"server_hash":null,"server_timestamp":"1785204469384","session_id":"d2757dd6dad94f3b9fe67e8dbf1adc37","source":"clob_market_ws"},"received_at":"2026-07-28T02:07:49.808137Z","record_id":"2b5120b43ac301ce1e989307194da09d74b905583fa09ffdc3a7e447371a58b2","schema_fingerprint":"4aa3821a28b0b7c2400bc59aba4bcc0a76e971dadd19610d3ad38c768e124dc7","schema_version":"edge-lab-recorder.raw.v1","sequence":null,"source":"clob_market_ws"}
{"event_at":"2026-07-28T02:07:49.384000Z","event_fingerprint":"c72b4838c92865268eab1fd759df245ace9c320d97b82a710bff6bdc08c2a402","payload":{"connection_id":"5d29200f65794d4d9ab6ef271f045a9b","event_at":"2026-07-28T02:07:49.384000Z","event_type":"price_change","frame_hash":"2e6946ce7c43d7f9697f13c88701161a790a55fad6cd0ac4fa149355beff4cf7","frame_index":0,"kind":"data","monotonic_ns":306452820475750,"payload":{"event_type":"price_change","market":"0xda6f0e0e93fc8469e0159a166028d017bddbc162b86f66bac90391379603d962","price_changes":[{"asset_id":"39272994714739463168905443499424551362424437245880253267329605556587274644733","best_ask":"0.46","best_bid":"0.45","hash":"e235a988e66374cd197dc50ce43cac298edba116","price":"0.43","side":"BUY","size":"90"},{"asset_id":"20893381255801015515826997628594359667013752732428989472914000440642900266717","best_ask":"0.55","best_bid":"0.54","hash":"f2d3731c46f825ccc9bd81ff41ac9cce8cfe492e","price":"0.57","side":"SELL","size":"90"}],"timestamp":"1785204469384"},"payload_hash":"c04c8ab6b1e11b3d390b584857f00d5950b62466d4889449b8ab6b8f070cbc9e","raw_frame":"{\"market\":\"0xda6f0e0e93fc8469e0159a166028d017bddbc162b86f66bac90391379603d962\", \"price_changes\":[{\"asset_id\":\"39272994714739463168905443499424551362424437245880253267329605556587274644733\", \"price\":\"0.43\", \"size\":\"90\", \"side\":\"BUY\", \"hash\":\"e235a988e66374cd197dc50ce43cac298edba116\", \"best_bid\":\"0.45\", \"best_ask\":\"0.46\"}, {\"asset_id\":\"20893381255801015515826997628594359667013752732428989472914000440642900266717\", \"price\":\"0.57\", \"size\":\"90\", \"side\":\"SELL\", \"hash\":\"f2d3731c46f825ccc9bd81ff41ac9cce8cfe492e\", \"best_bid\":\"0.54\", \"best_ask\":\"0.55\"}], \"timestamp\":\"1785204469384\", \"event_type\":\"price_change\"}","received_at":"2026-07-28T02:07:49.812772Z","schema_version":"clob-market-ws.price_change.v1","sequence":null,"server_hash":null,"server_timestamp":"1785204469384","session_id":"d2757dd6dad94f3b9fe67e8dbf1adc37","source":"clob_market_ws"},"received_at":"2026-07-28T02:07:49.812772Z","record_id":"9d6ca8450920005a95e01cafeefacebb6f13336a549b033d36cf82221139d761","schema_fingerprint":"4aa3821a28b0b7c2400bc59aba4bcc0a76e971dadd19610d3ad38c768e124dc7","schema_version":"edge-lab-recorder.raw.v1","sequence":null,"source":"clob_market_ws"}
{"event_at":"2026-07-28T02:07:49.384000Z","event_fingerprint":"e07166459292313d4ce1ea2d2366c21b1eafefbaf01bc29e355d7ecf3c0ee224","payload":{"connection_id":"5d29200f65794d4d9ab6ef271f045a9b","event_at":"2026-07-28T02:07:49.384000Z","event_type":"price_change","frame_hash":"896fd19ab78f3b5f6013587e0901fa18d988670ab174482536dddb30bd9de9d8","frame_index":0,"kind":"data","monotonic_ns":306452824431916,"payload":{"event_type":"price_change","market":"0xda6f0e0e93fc8469e0159a166028d017bddbc162b86f66bac90391379603d962","price_changes":[{"asset_id":"20893381255801015515826997628594359667013752732428989472914000440642900266717","best_ask":"0.55","best_bid":"0.54","hash":"3eb0c13d46553d16fa4556d374f43eb7a97a6c2e","price":"0.52","side":"BUY","size":"171.2"},{"asset_id":"39272994714739463168905443499424551362424437245880253267329605556587274644733","best_ask":"0.46","best_bid":"0.45","hash":"e18135f352a0292fa7ddfb0fa9196411654847c0","price":"0.48","side":"SELL","size":"171.2"}],"timestamp":"1785204469384"},"payload_hash":"2421ef53761c1785d102a566bf0e4b8ef94ce01bb2ad918350a31cb9fbe00005","raw_frame":"{\"market\":\"0xda6f0e0e93fc8469e0159a166028d017bddbc162b86f66bac90391379603d962\", \"price_changes\":[{\"asset_id\":\"20893381255801015515826997628594359667013752732428989472914000440642900266717\", \"price\":\"0.52\", \"size\":\"171.2\", \"side\":\"BUY\", \"hash\":\"3eb0c13d46553d16fa4556d374f43eb7a97a6c2e\", \"best_bid\":\"0.54\", \"best_ask\":\"0.55\"}, {\"asset_id\":\"39272994714739463168905443499424551362424437245880253267329605556587274644733\", \"price\":\"0.48\", \"size\":\"171.2\", \"side\":\"SELL\", \"hash\":\"e18135f352a0292fa7ddfb0fa9196411654847c0\", \"best_bid\":\"0.45\", \"best_ask\":\"0.46\"}], \"timestamp\":\"1785204469384\", \"event_type\":\"price_change\"}","received_at":"2026-07-28T02:07:49.816728Z","schema_version":"clob-market-ws.price_change.v1","sequence":null,"server_hash":null,"server_timestamp":"1785204469384","session_id":"d2757dd6dad94f3b9fe67e8dbf1adc37","source":"clob_market_ws"},"received_at":"2026-07-28T02:07:49.816728Z","record_id":"f9661dd865aafae1a7d85c37d63a3bd930c399bcaea065541aa618ef3869287f","schema_fingerprint":"4aa3821a28b0b7c2400bc59aba4bcc0a76e971dadd19610d3ad38c768e124dc7","schema_version":"edge-lab-recorder.raw.v1","sequence":null,"source":"clob_market_ws"}
{"event_at":"2026-07-28T02:07:49.385000Z","event_fingerprint":"c87a3957acb77a60831a18dc6143f27a5f5f6044d447c59c3b1c0fa543eaf2fb","payload":{"connection_id":"5d29200f65794d4d9ab6ef271f045a9b","event_at":"2026-07-28T02:07:49.385000Z","event_type":"price_change","frame_hash":"9fbd3225b58208380cfaa842494b06e947258588f6bb2d417676eff1ed47238b","frame_index":0,"kind":"data","monotonic_ns":306452828496791,"payload":{"event_type":"price_change","market":"0xda6f0e0e93fc8469e0159a166028d017bddbc162b86f66bac90391379603d962","price_changes":[{"asset_id":"20893381255801015515826997628594359667013752732428989472914000440642900266717","best_ask":"0.55","best_bid":"0.54","hash":"29e23a12ada5a504b4947d27ae570f7d15b9aeb7","price":"0.53","side":"BUY","size":"143.6"},{"asset_id":"39272994714739463168905443499424551362424437245880253267329605556587274644733","best_ask":"0.46","best_bid":"0.45","hash":"cb9364122f64f70c91981d7ad671ece105a21909","price":"0.47","side":"SELL","size":"143.6"}],"timestamp":"1785204469385"},"payload_hash":"b2744c83dfc951de34c84d5a3faf656fc625ba33f805868b618e408bbaa548ba","raw_frame":"{\"market\":\"0xda6f0e0e93fc8469e0159a166028d017bddbc162b86f66bac90391379603d962\", \"price_changes\":[{\"asset_id\":\"20893381255801015515826997628594359667013752732428989472914000440642900266717\", \"price\":\"0.53\", \"size\":\"143.6\", \"side\":\"BUY\", \"hash\":\"29e23a12ada5a504b4947d27ae570f7d15b9aeb7\", \"best_bid\":\"0.54\", \"best_ask\":\"0.55\"}, {\"asset_id\":\"39272994714739463168905443499424551362424437245880253267329605556587274644733\", \"price\":\"0.47\", \"size\":\"143.6\", \"side\":\"SELL\", \"hash\":\"cb9364122f64f70c91981d7ad671ece105a21909\", \"best_bid\":\"0.45\", \"best_ask\":\"0.46\"}], \"timestamp\":\"1785204469385\", \"event_type\":\"price_change\"}","received_at":"2026-07-28T02:07:49.820792Z","schema_version":"clob-market-ws.price_change.v1","sequence":null,"server_hash":null,"server_timestamp":"1785204469385","session_id":"d2757dd6dad94f3b9fe67e8dbf1adc37","source":"clob_market_ws"},"received_at":"2026-07-28T02:07:49.820792Z","record_id":"5b50e24d784bedffe0b10e7b98bc928f67c8c6dac1973d4a2cfd001edbfe25ea","schema_fingerprint":"4aa3821a28b0b7c2400bc59aba4bcc0a76e971dadd19610d3ad38c768e124dc7","schema_version":"edge-lab-recorder.raw.v1","sequence":null,"source":"clob_market_ws"}
{"event_at":"2026-07-28T02:07:49.385000Z","event_fingerprint":"81025fcf0403c9aed9f88bc86a0903f0081beb108cce94e92a75589216d566c0","payload":{"connection_id":"5d29200f65794d4d9ab6ef271f045a9b","event_at":"2026-07-28T02:07:49.385000Z","event_type":"price_change","frame_hash":"c1de58384790b5aae6ee998f6920daa01c3c9c905ba8fe3a118620e2a9f42bd3","frame_index":0,"kind":"data","monotonic_ns":306452833162333,"payload":{"event_type":"price_change","market":"0xda6f0e0e93fc8469e0159a166028d017bddbc162b86f66bac90391379603d962","price_changes":[{"asset_id":"20893381255801015515826997628594359667013752732428989472914000440642900266717","best_ask":"0.55","best_bid":"0.54","hash":"ed09b56a4d8f44e93871652911eab7b5cbb72172","price":"0.48","side":"BUY","size":"133"},{"asset_id":"39272994714739463168905443499424551362424437245880253267329605556587274644733","best_ask":"0.46","best_bid":"0.45","hash":"fb8073281fc0208ad630e39d9ec1fa1a4a2e06c0","price":"0.52","side":"SELL","size":"133"}],"timestamp":"1785204469385"},"payload_hash":"ea573307127e2f9935655994ab51e9bba48975bf628cf4ac3eac65c33ae03125","raw_frame":"{\"market\":\"0xda6f0e0e93fc8469e0159a166028d017bddbc162b86f66bac90391379603d962\", \"price_changes\":[{\"asset_id\":\"20893381255801015515826997628594359667013752732428989472914000440642900266717\", \"price\":\"0.48\", \"size\":\"133\", \"side\":\"BUY\", \"hash\":\"ed09b56a4d8f44e93871652911eab7b5cbb72172\", \"best_bid\":\"0.54\", \"best_ask\":\"0.55\"}, {\"asset_id\":\"39272994714739463168905443499424551362424437245880253267329605556587274644733\", \"price\":\"0.52\", \"size\":\"133\", \"side\":\"SELL\", \"hash\":\"fb8073281fc0208ad630e39d9ec1fa1a4a2e06c0\", \"best_bid\":\"0.45\", \"best_ask\":\"0.46\"}], \"timestamp\":\"1785204469385\", \"event_type\":\"price_change\"}","received_at":"2026-07-28T02:07:49.825458Z","schema_version":"clob-market-ws.price_change.v1","sequence":null,"server_hash":null,"server_timestamp":"1785204469385","session_id":"d2757dd6dad94f3b9fe67e8dbf1adc37","source":"clob_market_ws"},"received_at":"2026-07-28T02:07:49.825458Z","record_id":"291f8c7dd0c1752eb340509572cba1eaa43f8534fa1630fe1adf04789aa5a4fa","schema_fingerprint":"4aa3821a28b0b7c2400bc59aba4bcc0a76e971dadd19610d3ad38c768e124dc7","schema_version":"edge-lab-recorder.raw.v1","sequence":null,"source":"clob_market_ws"}
{"event_at":"2026-07-28T02:07:49.385000Z","event_fingerprint":"9cdb3070b3e538a50321129c467de2458b194d1a2fef8c3a75e524b981da1626","payload":{"connection_id":"5d29200f65794d4d9ab6ef271f045a9b","event_at":"2026-07-28T02:07:49.385000Z","event_type":"price_change","frame_hash":"2232c6ca1396744317e2b513c52cbad6621cf54252e50862fc5fcb63537f7a63","frame_index":0,"kind":"data","monotonic_ns":306452839549333,"payload":{"event_type":"price_change","market":"0xda6f0e0e93fc8469e0159a166028d017bddbc162b86f66bac90391379603d962","price_changes":[{"asset_id":"20893381255801015515826997628594359667013752732428989472914000440642900266717","best_ask":"0.55","best_bid":"0.54","hash":"81a708d05f648dcae01f083a4a8d649f6a0f6f4a","price":"0.53","side":"BUY","size":"109.6"},{"asset_id":"39272994714739463168905443499424551362424437245880253267329605556587274644733","best_ask":"0.46","best_bid":"0.45","hash":"a743a847ef8302bff38c2472ce485f80b300f584","price":"0.47","side":"SELL","size":"109.6"}],"timestamp":"1785204469385"},"payload_hash":"9e29f599da4a23c1d6b98e043724b2b4a2190ba578c19d15ad7f87f970ebfdc2","raw_frame":"{\"market\":\"0xda6f0e0e93fc8469e0159a166028d017bddbc162b86f66bac90391379603d962\", \"price_changes\":[{\"asset_id\":\"20893381255801015515826997628594359667013752732428989472914000440642900266717\", \"price\":\"0.53\", \"size\":\"109.6\", \"side\":\"BUY\", \"hash\":\"81a708d05f648dcae01f083a4a8d649f6a0f6f4a\", \"best_bid\":\"0.54\", \"best_ask\":\"0.55\"}, {\"asset_id\":\"39272994714739463168905443499424551362424437245880253267329605556587274644733\", \"price\":\"0.47\", \"size\":\"109.6\", \"side\":\"SELL\", \"hash\":\"a743a847ef8302bff38c2472ce485f80b300f584\", \"best_bid\":\"0.45\", \"best_ask\":\"0.46\"}], \"timestamp\":\"1785204469385\", \"event_type\":\"price_change\"}","received_at":"2026-07-28T02:07:49.831845Z","schema_version":"clob-market-ws.price_change.v1","sequence":null,"server_hash":null,"server_timestamp":"1785204469385","session_id":"d2757dd6dad94f3b9fe67e8dbf1adc37","source":"clob_market_ws"},"received_at":"2026-07-28T02:07:49.831845Z","record_id":"6c1b57e86d07918a8eea4fe34e66fa5bfd143985b1676a79a616db30497458f6","schema_fingerprint":"4aa3821a28b0b7c2400bc59aba4bcc0a76e971dadd19610d3ad38c768e124dc7","schema_version":"edge-lab-recorder.raw.v1","sequence":null,"source":"clob_market_ws"}
{"event_at":"2026-07-28T02:07:49.386000Z","event_fingerprint":"e2deb44aa3ebafb1dc8e754912da72da41e70194efbfdd1c6707593fc39ef9d0","payload":{"connection_id":"5d29200f65794d4d9ab6ef271f045a9b","event_at":"2026-07-28T02:07:49.386000Z","event_type":"price_change","frame_hash":"8044acd24c99132b1529a85fa2dbdf63bf6365191c80fe7dd3c593f2acd70c89","frame_index":0,"kind":"data","monotonic_ns":306452843140583,"payload":{"event_type":"price_change","market":"0xda6f0e0e93fc8469e0159a166028d017bddbc162b86f66bac90391379603d962","price_changes":[{"asset_id":"20893381255801015515826997628594359667013752732428989472914000440642900266717","best_ask":"0.55","best_bid":"0.54","hash":"564dd21781ba7de88aa82f2b0e09758853a804d4","price":"0.52","side":"BUY","size":"186.2"},{"asset_id":"39272994714739463168905443499424551362424437245880253267329605556587274644733","best_ask":"0.46","best_bid":"0.45","hash":"0acb87860b86b43259509a19bd370f8f7c337585","price":"0.48","side":"SELL","size":"186.2"}],"timestamp":"1785204469386"},"payload_hash":"d248a5c20126e79ab7fb810e9b7771c46c11767fd2f6528ebacc80de959b0086","raw_frame":"{\"market\":\"0xda6f0e0e93fc8469e0159a166028d017bddbc162b86f66bac90391379603d962\", \"price_changes\":[{\"asset_id\":\"20893381255801015515826997628594359667013752732428989472914000440642900266717\", \"price\":\"0.52\", \"size\":\"186.2\", \"side\":\"BUY\", \"hash\":\"564dd21781ba7de88aa82f2b0e09758853a804d4\", \"best_bid\":\"0.54\", \"best_ask\":\"0.55\"}, {\"asset_id\":\"39272994714739463168905443499424551362424437245880253267329605556587274644733\", \"price\":\"0.48\", \"size\":\"186.2\", \"side\":\"SELL\", \"hash\":\"0acb87860b86b43259509a19bd370f8f7c337585\", \"best_bid\":\"0.45\", \"best_ask\":\"0.46\"}], \"timestamp\":\"1785204469386\", \"event_type\":\"price_change\"}","received_at":"2026-07-28T02:07:49.835437Z","schema_version":"clob-market-ws.price_change.v1","sequence":null,"server_hash":null,"server_timestamp":"1785204469386","session_id":"d2757dd6dad94f3b9fe67e8dbf1adc37","source":"clob_market_ws"},"received_at":"2026-07-28T02:07:49.835437Z","record_id":"2fbc627e54e3e17ca1e511857f888455f3174ff22bdb5c4fcf0532277826c846","schema_fingerprint":"4aa3821a28b0b7c2400bc59aba4bcc0a76e971dadd19610d3ad38c768e124dc7","schema_version":"edge-lab-recorder.raw.v1","sequence":null,"source":"clob_market_ws"}
{"event_at":"2026-07-28T02:07:49.388000Z","event_fingerprint":"21416c52041941b7b694975ec7d07bd7dcd916ce1a71ba11a15b1f7c1616ef24","payload":{"connection_id":"5d29200f65794d4d9ab6ef271f045a9b","event_at":"2026-07-28T02:07:49.388000Z","event_type":"price_change","frame_hash":"bcd193d0205679edb3cb491049a4ae4c64630638dfeba0d9f1d2460b18fee5dc","frame_index":0,"kind":"data","monotonic_ns":306452848408708,"payload":{"event_type":"price_change","market":"0xda6f0e0e93fc8469e0159a166028d017bddbc162b86f66bac90391379603d962","price_changes":[{"asset_id":"20893381255801015515826997628594359667013752732428989472914000440642900266717","best_ask":"0.55","best_bid":"0.54","hash":"533f853e01cae9cb1caa8ada3ccc0dd6999d5ebb","price":"0.53","side":"BUY","size":"90.6"},{"asset_id":"39272994714739463168905443499424551362424437245880253267329605556587274644733","best_ask":"0.46","best_bid":"0.45","hash":"cddc334c41747d91ef33636608612e957f420943","price":"0.47","side":"SELL","size":"90.6"}],"timestamp":"1785204469388"},"payload_hash":"1672e01f9d42f8d7805607eff46ba5ac87ec2bb561fbcf3868819a0fa753d8aa","raw_frame":"{\"market\":\"0xda6f0e0e93fc8469e0159a166028d017bddbc162b86f66bac90391379603d962\", \"price_changes\":[{\"asset_id\":\"20893381255801015515826997628594359667013752732428989472914000440642900266717\", \"price\":\"0.53\", \"size\":\"90.6\", \"side\":\"BUY\", \"hash\":\"533f853e01cae9cb1caa8ada3ccc0dd6999d5ebb\", \"best_bid\":\"0.54\", \"best_ask\":\"0.55\"}, {\"asset_id\":\"39272994714739463168905443499424551362424437245880253267329605556587274644733\", \"price\":\"0.47\", \"size\":\"90.6\", \"side\":\"SELL\", \"hash\":\"cddc334c41747d91ef33636608612e957f420943\", \"best_bid\":\"0.45\", \"best_ask\":\"0.46\"}], \"timestamp\":\"1785204469388\", \"event_type\":\"price_change\"}","received_at":"2026-07-28T02:07:49.840705Z","schema_version":"clob-market-ws.price_change.v1","sequence":null,"server_hash":null,"server_timestamp":"1785204469388","session_id":"d2757dd6dad94f3b9fe67e8dbf1adc37","source":"clob_market_ws"},"received_at":"2026-07-28T02:07:49.840705Z","record_id":"2baf894154875039ec93f5311e7c01e8656cdf99e2174c92c9a51ee8db147c27","schema_fingerprint":"4aa3821a28b0b7c2400bc59aba4bcc0a76e971dadd19610d3ad38c768e124dc7","schema_version":"edge-lab-recorder.raw.v1","sequence":null,"source":"clob_market_ws"}
{"event_at":"2026-07-28T02:07:49.389000Z","event_fingerprint":"99a6fefb4f84e7626c50770c9564c5b1ce297784917afabb1ebc9e40a48c3650","payload":{"connection_id":"5d29200f65794d4d9ab6ef271f045a9b","event_at":"2026-07-28T02:07:49.389000Z","event_type":"price_change","frame_hash":"93963819f11e7e30271ecd6e3b7806ce21d769c3cbaff9dc71c84fe4042cea73","frame_index":0,"kind":"data","monotonic_ns":306452853451458,"payload":{"event_type":"price_change","market":"0xda6f0e0e93fc8469e0159a166028d017bddbc162b86f66bac90391379603d962","price_changes":[{"asset_id":"39272994714739463168905443499424551362424437245880253267329605556587274644733","best_ask":"0.46","best_bid":"0.45","hash":"731993e583fb8a2746e572a3cb0d95b5f0f6c000","price":"0.44","side":"BUY","size":"56.6"},{"asset_id":"20893381255801015515826997628594359667013752732428989472914000440642900266717","best_ask":"0.55","best_bid":"0.54","hash":"3bfdd3ad1dd9c93c48edf2ca77237567dcf53c38","price":"0.56","side":"SELL","size":"56.6"}],"timestamp":"1785204469389"},"payload_hash":"85b3c5626b944ea922acb64d11a7e8fd4f5c9ef19ac5ea69f476983c377c7465","raw_frame":"{\"market\":\"0xda6f0e0e93fc8469e0159a166028d017bddbc162b86f66bac90391379603d962\", \"price_changes\":[{\"asset_id\":\"39272994714739463168905443499424551362424437245880253267329605556587274644733\", \"price\":\"0.44\", \"size\":\"56.6\", \"side\":\"BUY\", \"hash\":\"731993e583fb8a2746e572a3cb0d95b5f0f6c000\", \"best_bid\":\"0.45\", \"best_ask\":\"0.46\"}, {\"asset_id\":\"20893381255801015515826997628594359667013752732428989472914000440642900266717\", \"price\":\"0.56\", \"size\":\"56.6\", \"side\":\"SELL\", \"hash\":\"3bfdd3ad1dd9c93c48edf2ca77237567dcf53c38\", \"best_bid\":\"0.54\", \"best_ask\":\"0.55\"}], \"timestamp\":\"1785204469389\", \"event_type\":\"price_change\"}","received_at":"2026-07-28T02:07:49.845748Z","schema_version":"clob-market-ws.price_change.v1","sequence":null,"server_hash":null,"server_timestamp":"1785204469389","session_id":"d2757dd6dad94f3b9fe67e8dbf1adc37","source":"clob_market_ws"},"received_at":"2026-07-28T02:07:49.845748Z","record_id":"366b256da42d7802fabb6051a778ef69b7710839bdef1dcc34a7f0150938e0e1","schema_fingerprint":"4aa3821a28b0b7c2400bc59aba4bcc0a76e971dadd19610d3ad38c768e124dc7","schema_version":"edge-lab-recorder.raw.v1","sequence":null,"source":"clob_market_ws"}
{"event_at":"2026-07-28T02:07:49.390000Z","event_fingerprint":"cf6f2b1221a9c009b3d2c452716949c4ee1c7f91607541ebd9ea84348feacfa1","payload":{"connection_id":"5d29200f65794d4d9ab6ef271f045a9b","event_at":"2026-07-28T02:07:49.390000Z","event_type":"price_change","frame_hash":"ec655b2a25fbab75764a3ad3c325b95e28a69c1f7cda392840711c93061b3368","frame_index":0,"kind":"data","monotonic_ns":306452862040625,"payload":{"event_type":"price_change","market":"0xda6f0e0e93fc8469e0159a166028d017bddbc162b86f66bac90391379603d962","price_changes":[{"asset_id":"20893381255801015515826997628594359667013752732428989472914000440642900266717","best_ask":"0.55","best_bid":"0.54","hash":"444757fae47bfe83b6e4ccda8eee98172fe48f5f","price":"0.53","side":"BUY","size":"103.2"},{"asset_id":"39272994714739463168905443499424551362424437245880253267329605556587274644733","best_ask":"0.46","best_bid":"0.45","hash":"a2b856d26f27c0c55547e6db37598a0096b0dbc3","price":"0.47","side":"SELL","size":"103.2"}],"timestamp":"1785204469390"},"payload_hash":"7c660b8b5a0ad5aed2119e544cb21e9d98d4d60faf5be8f3c8def23940624be1","raw_frame":"{\"market\":\"0xda6f0e0e93fc8469e0159a166028d017bddbc162b86f66bac90391379603d962\", \"price_changes\":[{\"asset_id\":\"20893381255801015515826997628594359667013752732428989472914000440642900266717\", \"price\":\"0.53\", \"size\":\"103.2\", \"side\":\"BUY\", \"hash\":\"444757fae47bfe83b6e4ccda8eee98172fe48f5f\", \"best_bid\":\"0.54\", \"best_ask\":\"0.55\"}, {\"asset_id\":\"39272994714739463168905443499424551362424437245880253267329605556587274644733\", \"price\":\"0.47\", \"size\":\"103.2\", \"side\":\"SELL\", \"hash\":\"a2b856d26f27c0c55547e6db37598a0096b0dbc3\", \"best_bid\":\"0.45\", \"best_ask\":\"0.46\"}], \"timestamp\":\"1785204469390\", \"event_type\":\"price_change\"}","received_at":"2026-07-28T02:07:49.854336Z","schema_version":"clob-market-ws.price_change.v1","sequence":null,"server_hash":null,"server_timestamp":"1785204469390","session_id":"d2757dd6dad94f3b9fe67e8dbf1adc37","source":"clob_market_ws"},"received_at":"2026-07-28T02:07:49.854336Z","record_id":"9758dbf60880807f2c4b62ddcd586a2a33b7108004d6dcba56ef1ad9c34f737e","schema_fingerprint":"4aa3821a28b0b7c2400bc59aba4bcc0a76e971dadd19610d3ad38c768e124dc7","schema_version":"edge-lab-recorder.raw.v1","sequence":null,"source":"clob_market_ws"}
{"event_at":"2026-07-28T02:07:49.392000Z","event_fingerprint":"5066f2be8da362daa093353e6431a7b8d1adb03ff85396790a24fc5cbc6408ce","payload":{"connection_id":"5d29200f65794d4d9ab6ef271f045a9b","event_at":"2026-07-28T02:07:49.392000Z","event_type":"price_change","frame_hash":"d76205b5bc70533215192ac1928658dfd87904932547ba1123a0fe2168d38446","frame_index":0,"kind":"data","monotonic_ns":306452868263375,"payload":{"event_type":"price_change","market":"0xda6f0e0e93fc8469e0159a166028d017bddbc162b86f66bac90391379603d962","price_changes":[{"asset_id":"39272994714739463168905443499424551362424437245880253267329605556587274644733","best_ask":"0.46","best_bid":"0.45","hash":"06d9d69ed0be9163b43a2039c6fe636329f03c8f","price":"0.45","side":"BUY","size":"12.6"},{"asset_id":"20893381255801015515826997628594359667013752732428989472914000440642900266717","best_ask":"0.55","best_bid":"0.54","hash":"f3b490143e798188ce9c773c84978291655ee91f","price":"0.55","side":"SELL","size":"12.6"}],"timestamp":"1785204469392"},"payload_hash":"efa91ddfb959e5835cd2779db2127fd11def8b5785cfe7a21122c5ad8ee0b6b9","raw_frame":"{\"market\":\"0xda6f0e0e93fc8469e0159a166028d017bddbc162b86f66bac90391379603d962\", \"price_changes\":[{\"asset_id\":\"39272994714739463168905443499424551362424437245880253267329605556587274644733\", \"price\":\"0.45\", \"size\":\"12.6\", \"side\":\"BUY\", \"hash\":\"06d9d69ed0be9163b43a2039c6fe636329f03c8f\", \"best_bid\":\"0.45\", \"best_ask\":\"0.46\"}, {\"asset_id\":\"20893381255801015515826997628594359667013752732428989472914000440642900266717\", \"price\":\"0.55\", \"size\":\"12.6\", \"side\":\"SELL\", \"hash\":\"f3b490143e798188ce9c773c84978291655ee91f\", \"best_bid\":\"0.54\", \"best_ask\":\"0.55\"}], \"timestamp\":\"1785204469392\", \"event_type\":\"price_change\"}","received_at":"2026-07-28T02:07:49.860560Z","schema_version":"clob-market-ws.price_change.v1","sequence":null,"server_hash":null,"server_timestamp":"1785204469392","session_id":"d2757dd6dad94f3b9fe67e8dbf1adc37","source":"clob_market_ws"},"received_at":"2026-07-28T02:07:49.860560Z","record_id":"d190c6fe0f871a7e435e3ac556cae769248913274243c28c10f6e88eb0a863b6","schema_fingerprint":"4aa3821a28b0b7c2400bc59aba4bcc0a76e971dadd19610d3ad38c768e124dc7","schema_version":"edge-lab-recorder.raw.v1","sequence":null,"source":"clob_market_ws"}
{"event_at":"2026-07-28T02:07:49.393000Z","event_fingerprint":"c70e60876e94bd7f7fc523622fa879eb1fc356c444d29c33d771b83a83637013","payload":{"connection_id":"5d29200f65794d4d9ab6ef271f045a9b","event_at":"2026-07-28T02:07:49.393000Z","event_type":"price_change","frame_hash":"a558e32f435b396f7e8df8755a7315268fc11ecac11488d6cbd025c9424f2c15","frame_index":0,"kind":"data","monotonic_ns":306452872457500,"payload":{"event_type":"price_change","market":"0xda6f0e0e93fc8469e0159a166028d017bddbc162b86f66bac90391379603d962","price_changes":[{"asset_id":"20893381255801015515826997628594359667013752732428989472914000440642900266717","best_ask":"0.55","best_bid":"0.54","hash":"9bf1f5f7926ac77dcf03ad66ce3a7054f94316be","price":"0.04","side":"BUY","size":"667.09"},{"asset_id":"39272994714739463168905443499424551362424437245880253267329605556587274644733","best_ask":"0.46","best_bid":"0.45","hash":"e963c269f83491cfa0f53486e7d92c7916896e01","price":"0.96","side":"SELL","size":"667.09"}],"timestamp":"1785204469393"},"payload_hash":"c88d49eb272ef385b974eb32f63446bcf649242fe68c0507b7a19eb70b7b116d","raw_frame":"{\"market\":\"0xda6f0e0e93fc8469e0159a166028d017bddbc162b86f66bac90391379603d962\", \"price_changes\":[{\"asset_id\":\"20893381255801015515826997628594359667013752732428989472914000440642900266717\", \"price\":\"0.04\", \"size\":\"667.09\", \"side\":\"BUY\", \"hash\":\"9bf1f5f7926ac77dcf03ad66ce3a7054f94316be\", \"best_bid\":\"0.54\", \"best_ask\":\"0.55\"}, {\"asset_id\":\"39272994714739463168905443499424551362424437245880253267329605556587274644733\", \"price\":\"0.96\", \"size\":\"667.09\", \"side\":\"SELL\", \"hash\":\"e963c269f83491cfa0f53486e7d92c7916896e01\", \"best_bid\":\"0.45\", \"best_ask\":\"0.46\"}], \"timestamp\":\"1785204469393\", \"event_type\":\"price_change\"}","received_at":"2026-07-28T02:07:49.864753Z","schema_version":"clob-market-ws.price_change.v1","sequence":null,"server_hash":null,"server_timestamp":"1785204469393","session_id":"d2757dd6dad94f3b9fe67e8dbf1adc37","source":"clob_market_ws"},"received_at":"2026-07-28T02:07:49.864753Z","record_id":"afdd0021b37493f960603c0e7a455b42c8cbfc7815b8e45dd0fa6dba25c3ff30","schema_fingerprint":"4aa3821a28b0b7c2400bc59aba4bcc0a76e971dadd19610d3ad38c768e124dc7","schema_version":"edge-lab-recorder.raw.v1","sequence":null,"source":"clob_market_ws"}
{"event_at":"2026-07-28T02:07:49.393000Z","event_fingerprint":"bcd4988e45bbb422aa7132989c944409d81a94c65b08513796d76c2f5c981f82","payload":{"connection_id":"5d29200f65794d4d9ab6ef271f045a9b","event_at":"2026-07-28T02:07:49.393000Z","event_type":"best_bid_ask","frame_hash":"862bf371132b398da4c845c51c888b61f75f0e9c6cabc03f64d2ab2e75a1c5ed","frame_index":0,"kind":"data","monotonic_ns":306452877126916,"payload":{"asset_id":"20893381255801015515826997628594359667013752732428989472914000440642900266717","best_ask":"0.56","best_bid":"0.54","event_type":"best_bid_ask","market":"0xda6f0e0e93fc8469e0159a166028d017bddbc162b86f66bac90391379603d962","spread":"0.02","timestamp":"1785204469393"},"payload_hash":"770d94aec412cdcea57f730702854ebd22c7c4aa6d7d29528cb969ae16871795","raw_frame":"{\"market\":\"0xda6f0e0e93fc8469e0159a166028d017bddbc162b86f66bac90391379603d962\", \"asset_id\":\"20893381255801015515826997628594359667013752732428989472914000440642900266717\", \"best_bid\":\"0.54\", \"best_ask\":\"0.56\", \"spread\":\"0.02\", \"timestamp\":\"1785204469393\", \"event_type\":\"best_bid_ask\"}","received_at":"2026-07-28T02:07:49.869423Z","schema_version":"clob-market-ws.best_bid_ask.v1","sequence":null,"server_hash":null,"server_timestamp":"1785204469393","session_id":"d2757dd6dad94f3b9fe67e8dbf1adc37","source":"clob_market_ws"},"received_at":"2026-07-28T02:07:49.869423Z","record_id":"91df021e8e02fbd6b77a04bc6626cf90cc2505f914ef8df46f65759dcc9efbe2","schema_fingerprint":"8488399f31b0337811b13b266be932db7062827c2470b78bd8e9e99bab51d17d","schema_version":"edge-lab-recorder.raw.v1","sequence":null,"source":"clob_market_ws"}
{"event_at":"2026-07-28T02:07:49.393000Z","event_fingerprint":"7d6f1e1b3944c9832375833701c6df72a65fa40063e30bf3b9fba9a717717f60","payload":{"connection_id":"5d29200f65794d4d9ab6ef271f045a9b","event_at":"2026-07-28T02:07:49.393000Z","event_type":"best_bid_ask","frame_hash":"ad1373c6d67cef66dbef2fb62b31ef9a8ab7c9e6f68019d06ccd34c5d057b95d","frame_index":0,"kind":"data","monotonic_ns":306452881446000,"payload":{"asset_id":"39272994714739463168905443499424551362424437245880253267329605556587274644733","best_ask":"0.46","best_bid":"0.44","event_type":"best_bid_ask","market":"0xda6f0e0e93fc8469e0159a166028d017bddbc162b86f66bac90391379603d962","spread":"0.02","timestamp":"1785204469393"},"payload_hash":"58106bb99994a7bb7c4d3edc3d8f30571e7c3ba164b0bf65e8c74dfb971f1fa7","raw_frame":"{\"market\":\"0xda6f0e0e93fc8469e0159a166028d017bddbc162b86f66bac90391379603d962\", \"asset_id\":\"39272994714739463168905443499424551362424437245880253267329605556587274644733\", \"best_bid\":\"0.44\", \"best_ask\":\"0.46\", \"spread\":\"0.02\", \"timestamp\":\"1785204469393\", \"event_type\":\"best_bid_ask\"}","received_at":"2026-07-28T02:07:49.873742Z","schema_version":"clob-market-ws.best_bid_ask.v1","sequence":null,"server_hash":null,"server_timestamp":"1785204469393","session_id":"d2757dd6dad94f3b9fe67e8dbf1adc37","source":"clob_market_ws"},"received_at":"2026-07-28T02:07:49.873742Z","record_id":"a284b26455d0efa49086764f59c71544a79407ecec71e21a523b99d5d6ecce6a","schema_fingerprint":"8488399f31b0337811b13b266be932db7062827c2470b78bd8e9e99bab51d17d","schema_version":"edge-lab-recorder.raw.v1","sequence":null,"source":"clob_market_ws"}
{"event_at":"2026-07-28T02:07:49.393000Z","event_fingerprint":"2cb159a4ca1ea0b7e4805df0882cef90523ce1ed64ae610e8cbb7a6794445855","payload":{"connection_id":"5d29200f65794d4d9ab6ef271f045a9b","event_at":"2026-07-28T02:07:49.393000Z","event_type":"price_change","frame_hash":"401227851f8223a0cdf23f62b922eb5b3e239581f6d3d90b0778dafc268fc341","frame_index":0,"kind":"data","monotonic_ns":306452888207750,"payload":{"event_type":"price_change","market":"0xda6f0e0e93fc8469e0159a166028d017bddbc162b86f66bac90391379603d962","price_changes":[{"asset_id":"39272994714739463168905443499424551362424437245880253267329605556587274644733","best_ask":"0.46","best_bid":"0.44","hash":"c9e81f904e1222252e5acdad58386a7f75929c0b","price":"0.45","side":"BUY","size":"0"},{"asset_id":"20893381255801015515826997628594359667013752732428989472914000440642900266717","best_ask":"0.56","best_bid":"0.54","hash":"b7a4b164bb45aa71c604efa5dceb972d72b7d93b","price":"0.55","side":"SELL","size":"0"}],"timestamp":"1785204469393"},"payload_hash":"9bda9e4b55ce833a2fa91afe586baf4100888a95c9ba8dabd542db372d450fcc","raw_frame":"{\"market\":\"0xda6f0e0e93fc8469e0159a166028d017bddbc162b86f66bac90391379603d962\", \"price_changes\":[{\"asset_id\":\"39272994714739463168905443499424551362424437245880253267329605556587274644733\", \"price\":\"0.45\", \"size\":\"0\", \"side\":\"BUY\", \"hash\":\"c9e81f904e1222252e5acdad58386a7f75929c0b\", \"best_bid\":\"0.44\", \"best_ask\":\"0.46\"}, {\"asset_id\":\"20893381255801015515826997628594359667013752732428989472914000440642900266717\", \"price\":\"0.55\", \"size\":\"0\", \"side\":\"SELL\", \"hash\":\"b7a4b164bb45aa71c604efa5dceb972d72b7d93b\", \"best_bid\":\"0.54\", \"best_ask\":\"0.56\"}], \"timestamp\":\"1785204469393\", \"event_type\":\"price_change\"}","received_at":"2026-07-28T02:07:49.880503Z","schema_version":"clob-market-ws.price_change.v1","sequence":null,"server_hash":null,"server_timestamp":"1785204469393","session_id":"d2757dd6dad94f3b9fe67e8dbf1adc37","source":"clob_market_ws"},"received_at":"2026-07-28T02:07:49.880503Z","record_id":"9ced4c1c58a07a56d0cb205c3e0971bd3cc736524faef79b25ffa2804ffb4fe7","schema_fingerprint":"4aa3821a28b0b7c2400bc59aba4bcc0a76e971dadd19610d3ad38c768e124dc7","schema_version":"edge-lab-recorder.raw.v1","sequence":null,"source":"clob_market_ws"}
{"event_at":"2026-07-28T02:07:49.394000Z","event_fingerprint":"1ace093e2ffe14dc7aebeb3539f16fb9e912d0465054fd814f11bd42da2b1f33","payload":{"connection_id":"5d29200f65794d4d9ab6ef271f045a9b","event_at":"2026-07-28T02:07:49.394000Z","event_type":"price_change","frame_hash":"bbaa679c30d399c3481da055ac372e07552be201d64616f27930215b58195965","frame_index":0,"kind":"data","monotonic_ns":306452894090500,"payload":{"event_type":"price_change","market":"0xda6f0e0e93fc8469e0159a166028d017bddbc162b86f66bac90391379603d962","price_changes":[{"asset_id":"20893381255801015515826997628594359667013752732428989472914000440642900266717","best_ask":"0.56","best_bid":"0.54","hash":"ea300d6403ff42398b381c8c503141a41c293045","price":"0.42","side":"BUY","size":"124.3"},{"asset_id":"39272994714739463168905443499424551362424437245880253267329605556587274644733","best_ask":"0.46","best_bid":"0.44","hash":"071707b769629cfde4474a5ac1461bbbac5b0620","price":"0.58","side":"SELL","size":"124.3"}],"timestamp":"1785204469394"},"payload_hash":"0f5ea6ff912728da39cc6ecc13680f4964c9f47733982866eff53322e9f5e3f8","raw_frame":"{\"market\":\"0xda6f0e0e93fc8469e0159a166028d017bddbc162b86f66bac90391379603d962\", \"price_changes\":[{\"asset_id\":\"20893381255801015515826997628594359667013752732428989472914000440642900266717\", \"price\":\"0.42\", \"size\":\"124.3\", \"side\":\"BUY\", \"hash\":\"ea300d6403ff42398b381c8c503141a41c293045\", \"best_bid\":\"0.54\", \"best_ask\":\"0.56\"}, {\"asset_id\":\"39272994714739463168905443499424551362424437245880253267329605556587274644733\", \"price\":\"0.58\", \"size\":\"124.3\", \"side\":\"SELL\", \"hash\":\"071707b769629cfde4474a5ac1461bbbac5b0620\", \"best_bid\":\"0.44\", \"best_ask\":\"0.46\"}], \"timestamp\":\"1785204469394\", \"event_type\":\"price_change\"}","received_at":"2026-07-28T02:07:49.886385Z","schema_version":"clob-market-ws.price_change.v1","sequence":null,"server_hash":null,"server_timestamp":"1785204469394","session_id":"d2757dd6dad94f3b9fe67e8dbf1adc37","source":"clob_market_ws"},"received_at":"2026-07-28T02:07:49.886385Z","record_id":"d9d1e3d13920d07f788821540c0ad344cb108a50eb7601b557038276946a1960","schema_fingerprint":"4aa3821a28b0b7c2400bc59aba4bcc0a76e971dadd19610d3ad38c768e124dc7","schema_version":"edge-lab-recorder.raw.v1","sequence":null,"source":"clob_market_ws"}
{"event_at":"2026-07-28T02:07:49.396000Z","event_fingerprint":"0114c505dc8a6f5bc5aad0bf2c31967fdaffe1668eac3ffbb4d114456d534b6d","payload":{"connection_id":"5d29200f65794d4d9ab6ef271f045a9b","event_at":"2026-07-28T02:07:49.396000Z","event_type":"price_change","frame_hash":"60292b3d93a8478cdf1475fef4cde90e2099144bc1fa261a18d4a7f3af354114","frame_index":0,"kind":"data","monotonic_ns":306452899850916,"payload":{"event_type":"price_change","market":"0xda6f0e0e93fc8469e0159a166028d017bddbc162b86f66bac90391379603d962","price_changes":[{"asset_id":"39272994714739463168905443499424551362424437245880253267329605556587274644733","best_ask":"0.46","best_bid":"0.44","hash":"1f1731ce69209844803b5d0b645e7038c66c3562","price":"0.27","side":"BUY","size":"95.2"},{"asset_id":"20893381255801015515826997628594359667013752732428989472914000440642900266717","best_ask":"0.56","best_bid":"0.54","hash":"660ea59199d6787ed5c9d811969332980d28bbf2","price":"0.73","side":"SELL","size":"95.2"}],"timestamp":"1785204469396"},"payload_hash":"875723d810974dad8c173abc2ba8e5ef6a549f82096be0bc52cc0f98c4978b0c","raw_frame":"{\"market\":\"0xda6f0e0e93fc8469e0159a166028d017bddbc162b86f66bac90391379603d962\", \"price_changes\":[{\"asset_id\":\"39272994714739463168905443499424551362424437245880253267329605556587274644733\", \"price\":\"0.27\", \"size\":\"95.2\", \"side\":\"BUY\", \"hash\":\"1f1731ce69209844803b5d0b645e7038c66c3562\", \"best_bid\":\"0.44\", \"best_ask\":\"0.46\"}, {\"asset_id\":\"20893381255801015515826997628594359667013752732428989472914000440642900266717\", \"price\":\"0.73\", \"size\":\"95.2\", \"side\":\"SELL\", \"hash\":\"660ea59199d6787ed5c9d811969332980d28bbf2\", \"best_bid\":\"0.54\", \"best_ask\":\"0.56\"}], \"timestamp\":\"1785204469396\", \"event_type\":\"price_change\"}","received_at":"2026-07-28T02:07:49.892146Z","schema_version":"clob-market-ws.price_change.v1","sequence":null,"server_hash":null,"server_timestamp":"1785204469396","session_id":"d2757dd6dad94f3b9fe67e8dbf1adc37","source":"clob_market_ws"},"received_at":"2026-07-28T02:07:49.892146Z","record_id":"e2e00e8f83d0d5180c07c6389b86c0f9f092c24ea49da900724d2d1d2a5521c7","schema_fingerprint":"4aa3821a28b0b7c2400bc59aba4bcc0a76e971dadd19610d3ad38c768e124dc7","schema_version":"edge-lab-recorder.raw.v1","sequence":null,"source":"clob_market_ws"}
{"event_at":"2026-07-28T02:07:49.397000Z","event_fingerprint":"ebf35827307ae5564e5246d173a7d83cb3a0ad382f9746531780c5db5417c4d7","payload":{"connection_id":"5d29200f65794d4d9ab6ef271f045a9b","event_at":"2026-07-28T02:07:49.397000Z","event_type":"price_change","frame_hash":"3b933c7289c543d82f58915081dfc3f69b35fe61e1957c03cb8c9c5dabd27b57","frame_index":0,"kind":"data","monotonic_ns":306452905551166,"payload":{"event_type":"price_change","market":"0xda6f0e0e93fc8469e0159a166028d017bddbc162b86f66bac90391379603d962","price_changes":[{"asset_id":"20893381255801015515826997628594359667013752732428989472914000440642900266717","best_ask":"0.56","best_bid":"0.54","hash":"e3ab0c1f75e3df7e753badb51ba4e7e69ff88288","price":"0.45","side":"BUY","size":"204.1"},{"asset_id":"39272994714739463168905443499424551362424437245880253267329605556587274644733","best_ask":"0.46","best_bid":"0.44","hash":"46d2be679017f0e6e12e568d7757e2e425c5f8a9","price":"0.55","side":"SELL","size":"204.1"}],"timestamp":"1785204469397"},"payload_hash":"bdab615ff2a6b31367be689b8faa7c91cacdf155adb0d3fd0732cd06e0222d5b","raw_frame":"{\"market\":\"0xda6f0e0e93fc8469e0159a166028d017bddbc162b86f66bac90391379603d962\", \"price_changes\":[{\"asset_id\":\"20893381255801015515826997628594359667013752732428989472914000440642900266717\", \"price\":\"0.45\", \"size\":\"204.1\", \"side\":\"BUY\", \"hash\":\"e3ab0c1f75e3df7e753badb51ba4e7e69ff88288\", \"best_bid\":\"0.54\", \"best_ask\":\"0.56\"}, {\"asset_id\":\"39272994714739463168905443499424551362424437245880253267329605556587274644733\", \"price\":\"0.55\", \"size\":\"204.1\", \"side\":\"SELL\", \"hash\":\"46d2be679017f0e6e12e568d7757e2e425c5f8a9\", \"best_bid\":\"0.44\", \"best_ask\":\"0.46\"}], \"timestamp\":\"1785204469397\", \"event_type\":\"price_change\"}","received_at":"2026-07-28T02:07:49.897847Z","schema_version":"clob-market-ws.price_change.v1","sequence":null,"server_hash":null,"server_timestamp":"1785204469397","session_id":"d2757dd6dad94f3b9fe67e8dbf1adc37","source":"clob_market_ws"},"received_at":"2026-07-28T02:07:49.897847Z","record_id":"e5072dea0b830e6daa725a0806e653ad32a20cdc7c4b328ae8173dd427a87af3","schema_fingerprint":"4aa3821a28b0b7c2400bc59aba4bcc0a76e971dadd19610d3ad38c768e124dc7","schema_version":"edge-lab-recorder.raw.v1","sequence":null,"source":"clob_market_ws"}
{"event_at":"2026-07-28T02:07:49.398000Z","event_fingerprint":"84a9a4617c7d8b0e2d5d1b0805c737edb0bd9635ad18efef263831072c45fa5b","payload":{"connection_id":"5d29200f65794d4d9ab6ef271f045a9b","event_at":"2026-07-28T02:07:49.398000Z","event_type":"price_change","frame_hash":"d9e3fca0080a65c61416f902097380394af58d502e012fb3a5baa5a30aef5c73","frame_index":0,"kind":"data","monotonic_ns":306452911737291,"payload":{"event_type":"price_change","market":"0xda6f0e0e93fc8469e0159a166028d017bddbc162b86f66bac90391379603d962","price_changes":[{"asset_id":"20893381255801015515826997628594359667013752732428989472914000440642900266717","best_ask":"0.56","best_bid":"0.54","hash":"5e39d62fd625bbb55c276aeaf082a2a78fe03349","price":"0.52","side":"BUY","size":"169.2"},{"asset_id":"39272994714739463168905443499424551362424437245880253267329605556587274644733","best_ask":"0.46","best_bid":"0.44","hash":"e5d98fa8a57518a42679d9dccc17909476c424f8","price":"0.48","side":"SELL","size":"169.2"}],"timestamp":"1785204469398"},"payload_hash":"cdcabae8e0775c9dab967eb87749a843670632582d96d16a9a6c57a70af6398d","raw_frame":"{\"market\":\"0xda6f0e0e93fc8469e0159a166028d017bddbc162b86f66bac90391379603d962\", \"price_changes\":[{\"asset_id\":\"20893381255801015515826997628594359667013752732428989472914000440642900266717\", \"price\":\"0.52\", \"size\":\"169.2\", \"side\":\"BUY\", \"hash\":\"5e39d62fd625bbb55c276aeaf082a2a78fe03349\", \"best_bid\":\"0.54\", \"best_ask\":\"0.56\"}, {\"asset_id\":\"39272994714739463168905443499424551362424437245880253267329605556587274644733\", \"price\":\"0.48\", \"size\":\"169.2\", \"side\":\"SELL\", \"hash\":\"e5d98fa8a57518a42679d9dccc17909476c424f8\", \"best_bid\":\"0.44\", \"best_ask\":\"0.46\"}], \"timestamp\":\"1785204469398\", \"event_type\":\"price_change\"}","received_at":"2026-07-28T02:07:49.904033Z","schema_version":"clob-market-ws.price_change.v1","sequence":null,"server_hash":null,"server_timestamp":"1785204469398","session_id":"d2757dd6dad94f3b9fe67e8dbf1adc37","source":"clob_market_ws"},"received_at":"2026-07-28T02:07:49.904033Z","record_id":"19abff0ed0c386469ea7d6f74a9098228932565d626de46e11f465cf8bfa9f64","schema_fingerprint":"4aa3821a28b0b7c2400bc59aba4bcc0a76e971dadd19610d3ad38c768e124dc7","schema_version":"edge-lab-recorder.raw.v1","sequence":null,"source":"clob_market_ws"}
{"event_at":"2026-07-28T02:07:49.398000Z","event_fingerprint":"75ad080418bd6facb71b5a63d52733c779bcda886c153cc1101ff39f84af2770","payload":{"connection_id":"5d29200f65794d4d9ab6ef271f045a9b","event_at":"2026-07-28T02:07:49.398000Z","event_type":"price_change","frame_hash":"c63a86fd0423959c27e80f86f2482da7df19f472177daee17f2b3c92546bbb2a","frame_index":0,"kind":"data","monotonic_ns":306452918186458,"payload":{"event_type":"price_change","market":"0xda6f0e0e93fc8469e0159a166028d017bddbc162b86f66bac90391379603d962","price_changes":[{"asset_id":"20893381255801015515826997628594359667013752732428989472914000440642900266717","best_ask":"0.56","best_bid":"0.54","hash":"dbdd6d1da6c407f24bd6468acc6bf8fd0d0d8d0b","price":"0.53","side":"BUY","size":"69.2"},{"asset_id":"39272994714739463168905443499424551362424437245880253267329605556587274644733","best_ask":"0.46","best_bid":"0.44","hash":"6618b299d2022ca5f1a59def647b342fb00f4b45","price":"0.47","side":"SELL","size":"69.2"}],"timestamp":"1785204469398"},"payload_hash":"ad2b6bcdce73c173d0b91862e2ee4247a1e54a846ff49e45e4d37f5754003072","raw_frame":"{\"market\":\"0xda6f0e0e93fc8469e0159a166028d017bddbc162b86f66bac90391379603d962\", \"price_changes\":[{\"asset_id\":\"20893381255801015515826997628594359667013752732428989472914000440642900266717\", \"price\":\"0.53\", \"size\":\"69.2\", \"side\":\"BUY\", \"hash\":\"dbdd6d1da6c407f24bd6468acc6bf8fd0d0d8d0b\", \"best_bid\":\"0.54\", \"best_ask\":\"0.56\"}, {\"asset_id\":\"39272994714739463168905443499424551362424437245880253267329605556587274644733\", \"price\":\"0.47\", \"size\":\"69.2\", \"side\":\"SELL\", \"hash\":\"6618b299d2022ca5f1a59def647b342fb00f4b45\", \"best_bid\":\"0.44\", \"best_ask\":\"0.46\"}], \"timestamp\":\"1785204469398\", \"event_type\":\"price_change\"}","received_at":"2026-07-28T02:07:49.910481Z","schema_version":"clob-market-ws.price_change.v1","sequence":null,"server_hash":null,"server_timestamp":"1785204469398","session_id":"d2757dd6dad94f3b9fe67e8dbf1adc37","source":"clob_market_ws"},"received_at":"2026-07-28T02:07:49.910481Z","record_id":"4cdbff83d9f2682f593530cd66c219562e0a87505a7846d71e62e3fe33f69162","schema_fingerprint":"4aa3821a28b0b7c2400bc59aba4bcc0a76e971dadd19610d3ad38c768e124dc7","schema_version":"edge-lab-recorder.raw.v1","sequence":null,"source":"clob_market_ws"}
{"event_at":"2026-07-28T02:07:49.399000Z","event_fingerprint":"450052e75ce814b1afc8d339c18d9dea1b3e09cafea9d9b55201a6d78e0a2e8b","payload":{"connection_id":"5d29200f65794d4d9ab6ef271f045a9b","event_at":"2026-07-28T02:07:49.399000Z","event_type":"price_change","frame_hash":"a44e6953a5a04b5eef9df692bfd0e450d0ceef3bf2d8cc8ae9a214ebde9ea69c","frame_index":0,"kind":"data","monotonic_ns":306452922094375,"payload":{"event_type":"price_change","market":"0xda6f0e0e93fc8469e0159a166028d017bddbc162b86f66bac90391379603d962","price_changes":[{"asset_id":"20893381255801015515826997628594359667013752732428989472914000440642900266717","best_ask":"0.56","best_bid":"0.54","hash":"9b1121346bf120daf73f01b6ab1a61de72349a0d","price":"0.44","side":"BUY","size":"119.2"},{"asset_id":"39272994714739463168905443499424551362424437245880253267329605556587274644733","best_ask":"0.46","best_bid":"0.44","hash":"3c81d483c21b59ca58b1599bd4bb804c5870d612","price":"0.56","side":"SELL","size":"119.2"}],"timestamp":"1785204469399"},"payload_hash":"7deda53a9fd5ecd547d97560083b6adb21fd0a940918f1be2e21c9d26968ceab","raw_frame":"{\"market\":\"0xda6f0e0e93fc8469e0159a166028d017bddbc162b86f66bac90391379603d962\", \"price_changes\":[{\"asset_id\":\"20893381255801015515826997628594359667013752732428989472914000440642900266717\", \"price\":\"0.44\", \"size\":\"119.2\", \"side\":\"BUY\", \"hash\":\"9b1121346bf120daf73f01b6ab1a61de72349a0d\", \"best_bid\":\"0.54\", \"best_ask\":\"0.56\"}, {\"asset_id\":\"39272994714739463168905443499424551362424437245880253267329605556587274644733\", \"price\":\"0.56\", \"size\":\"119.2\", \"side\":\"SELL\", \"hash\":\"3c81d483c21b59ca58b1599bd4bb804c5870d612\", \"best_bid\":\"0.44\", \"best_ask\":\"0.46\"}], \"timestamp\":\"1785204469399\", \"event_type\":\"price_change\"}","received_at":"2026-07-28T02:07:49.914390Z","schema_version":"clob-market-ws.price_change.v1","sequence":null,"server_hash":null,"server_timestamp":"1785204469399","session_id":"d2757dd6dad94f3b9fe67e8dbf1adc37","source":"clob_market_ws"},"received_at":"2026-07-28T02:07:49.914390Z","record_id":"088dae8eb954f030a27f20ec1ecf2661b745ae92cbdab2aee69d01ab88279388","schema_fingerprint":"4aa3821a28b0b7c2400bc59aba4bcc0a76e971dadd19610d3ad38c768e124dc7","schema_version":"edge-lab-recorder.raw.v1","sequence":null,"source":"clob_market_ws"}
{"event_at":"2026-07-28T02:07:49.400000Z","event_fingerprint":"77a65ac155cd9bde17308def177146532c52146dc7bdd168e1b9af2983ccfeac","payload":{"connection_id":"5d29200f65794d4d9ab6ef271f045a9b","event_at":"2026-07-28T02:07:49.400000Z","event_type":"price_change","frame_hash":"3e0ddf1aa063b93a9323cbd6f29085074dd1f7d374f2dd7b4a2ceb7d588dc512","frame_index":0,"kind":"data","monotonic_ns":306452926350083,"payload":{"event_type":"price_change","market":"0xda6f0e0e93fc8469e0159a166028d017bddbc162b86f66bac90391379603d962","price_changes":[{"asset_id":"39272994714739463168905443499424551362424437245880253267329605556587274644733","best_ask":"0.46","best_bid":"0.44","hash":"b1ded48b4caa1e6ad104e6525c10ec4307cc8d65","price":"0.42","side":"BUY","size":"76"},{"asset_id":"20893381255801015515826997628594359667013752732428989472914000440642900266717","best_ask":"0.56","best_bid":"0.54","hash":"838d45dabe149c13f5798101bec40622313138d8","price":"0.58","side":"SELL","size":"76"}],"timestamp":"1785204469400"},"payload_hash":"3a23447bed31e74a9e5274b43af60b9d4e3ecf9a4a61b80d93cde20e50405966","raw_frame":"{\"market\":\"0xda6f0e0e93fc8469e0159a166028d017bddbc162b86f66bac90391379603d962\", \"price_changes\":[{\"asset_id\":\"39272994714739463168905443499424551362424437245880253267329605556587274644733\", \"price\":\"0.42\", \"size\":\"76\", \"side\":\"BUY\", \"hash\":\"b1ded48b4caa1e6ad104e6525c10ec4307cc8d65\", \"best_bid\":\"0.44\", \"best_ask\":\"0.46\"}, {\"asset_id\":\"20893381255801015515826997628594359667013752732428989472914000440642900266717\", \"price\":\"0.58\", \"size\":\"76\", \"side\":\"SELL\", \"hash\":\"838d45dabe149c13f5798101bec40622313138d8\", \"best_bid\":\"0.54\", \"best_ask\":\"0.56\"}], \"timestamp\":\"1785204469400\", \"event_type\":\"price_change\"}","received_at":"2026-07-28T02:07:49.918644Z","schema_version":"clob-market-ws.price_change.v1","sequence":null,"server_hash":null,"server_timestamp":"1785204469400","session_id":"d2757dd6dad94f3b9fe67e8dbf1adc37","source":"clob_market_ws"},"received_at":"2026-07-28T02:07:49.918644Z","record_id":"7b3ad5bd1b40b9b80798ab04a122a298c5f29cbba01a32ad8851602cd9def68a","schema_fingerprint":"4aa3821a28b0b7c2400bc59aba4bcc0a76e971dadd19610d3ad38c768e124dc7","schema_version":"edge-lab-recorder.raw.v1","sequence":null,"source":"clob_market_ws"}
{"event_at":"2026-07-28T02:07:49.401000Z","event_fingerprint":"a78a025c10770d291d94a2ecccd56c291b2c4768cf07689215b546270f302e1d","payload":{"connection_id":"5d29200f65794d4d9ab6ef271f045a9b","event_at":"2026-07-28T02:07:49.401000Z","event_type":"price_change","frame_hash":"8cf5e345925c342be7899d90e4c206e54959dd2d05d88f9f6033d2fdfa4bf6ce","frame_index":0,"kind":"data","monotonic_ns":306452930812916,"payload":{"event_type":"price_change","market":"0xda6f0e0e93fc8469e0159a166028d017bddbc162b86f66bac90391379603d962","price_changes":[{"asset_id":"20893381255801015515826997628594359667013752732428989472914000440642900266717","best_ask":"0.56","best_bid":"0.54","hash":"f39964e2adacfd074b4b4f932d4859e7121e6c36","price":"0.54","side":"BUY","size":"56.6"},{"asset_id":"39272994714739463168905443499424551362424437245880253267329605556587274644733","best_ask":"0.46","best_bid":"0.44","hash":"526d54d659d1afbcb0a8f4d107e391487abb62e3","price":"0.46","side":"SELL","size":"56.6"}],"timestamp":"1785204469401"},"payload_hash":"3781c2e3d1999b0d1ce6cc536da13cc0a2b5923f922b63468e9cae409fad4b43","raw_frame":"{\"market\":\"0xda6f0e0e93fc8469e0159a166028d017bddbc162b86f66bac90391379603d962\", \"price_changes\":[{\"asset_id\":\"20893381255801015515826997628594359667013752732428989472914000440642900266717\", \"price\":\"0.54\", \"size\":\"56.6\", \"side\":\"BUY\", \"hash\":\"f39964e2adacfd074b4b4f932d4859e7121e6c36\", \"best_bid\":\"0.54\", \"best_ask\":\"0.56\"}, {\"asset_id\":\"39272994714739463168905443499424551362424437245880253267329605556587274644733\", \"price\":\"0.46\", \"size\":\"56.6\", \"side\":\"SELL\", \"hash\":\"526d54d659d1afbcb0a8f4d107e391487abb62e3\", \"best_bid\":\"0.44\", \"best_ask\":\"0.46\"}], \"timestamp\":\"1785204469401\", \"event_type\":\"price_change\"}","received_at":"2026-07-28T02:07:49.923109Z","schema_version":"clob-market-ws.price_change.v1","sequence":null,"server_hash":null,"server_timestamp":"1785204469401","session_id":"d2757dd6dad94f3b9fe67e8dbf1adc37","source":"clob_market_ws"},"received_at":"2026-07-28T02:07:49.923109Z","record_id":"47819d1aeccb4ad8e27bc48725317fb2d7f34d421f4723b0f779bc7d921cc3a1","schema_fingerprint":"4aa3821a28b0b7c2400bc59aba4bcc0a76e971dadd19610d3ad38c768e124dc7","schema_version":"edge-lab-recorder.raw.v1","sequence":null,"source":"clob_market_ws"}
{"event_at":"2026-07-28T02:07:49.401000Z","event_fingerprint":"ddbadf57216c89d6964fe7f45eed530d70cee14994affbb74d9dfcfcccc65a4a","payload":{"connection_id":"5d29200f65794d4d9ab6ef271f045a9b","event_at":"2026-07-28T02:07:49.401000Z","event_type":"price_change","frame_hash":"4887c793d1d96638405a32401b0eae44529779217cc03a615a9c60866832d55b","frame_index":0,"kind":"data","monotonic_ns":306452934538791,"payload":{"event_type":"price_change","market":"0xda6f0e0e93fc8469e0159a166028d017bddbc162b86f66bac90391379603d962","price_changes":[{"asset_id":"20893381255801015515826997628594359667013752732428989472914000440642900266717","best_ask":"0.56","best_bid":"0.54","hash":"c9e93fa8e32a5c83f51ea612b061721b6bde549c","price":"0.45","side":"BUY","size":"209.1"},{"asset_id":"39272994714739463168905443499424551362424437245880253267329605556587274644733","best_ask":"0.46","best_bid":"0.44","hash":"a6a5535eda07afa1e5a3e045a0b9d4f1c3c2eb56","price":"0.55","side":"SELL","size":"209.1"}],"timestamp":"1785204469401"},"payload_hash":"a3e6af418470c6dde919e082ea5b43b968f38d79258ad520c788d4cc78a4aa00","raw_frame":"{\"market\":\"0xda6f0e0e93fc8469e0159a166028d017bddbc162b86f66bac90391379603d962\", \"price_changes\":[{\"asset_id\":\"20893381255801015515826997628594359667013752732428989472914000440642900266717\", \"price\":\"0.45\", \"size\":\"209.1\", \"side\":\"BUY\", \"hash\":\"c9e93fa8e32a5c83f51ea612b061721b6bde549c\", \"best_bid\":\"0.54\", \"best_ask\":\"0.56\"}, {\"asset_id\":\"39272994714739463168905443499424551362424437245880253267329605556587274644733\", \"price\":\"0.55\", \"size\":\"209.1\", \"side\":\"SELL\", \"hash\":\"a6a5535eda07afa1e5a3e045a0b9d4f1c3c2eb56\", \"best_bid\":\"0.44\", \"best_ask\":\"0.46\"}], \"timestamp\":\"1785204469401\", \"event_type\":\"price_change\"}","received_at":"2026-07-28T02:07:49.926834Z","schema_version":"clob-market-ws.price_change.v1","sequence":null,"server_hash":null,"server_timestamp":"1785204469401","session_id":"d2757dd6dad94f3b9fe67e8dbf1adc37","source":"clob_market_ws"},"received_at":"2026-07-28T02:07:49.926834Z","record_id":"1c377eaf27b13e23c16276e92f51e08a88a03100e65c817c793a451f86f62386","schema_fingerprint":"4aa3821a28b0b7c2400bc59aba4bcc0a76e971dadd19610d3ad38c768e124dc7","schema_version":"edge-lab-recorder.raw.v1","sequence":null,"source":"clob_market_ws"}
{"event_at":"2026-07-28T02:07:49.403000Z","event_fingerprint":"9673fa32ed0293f4e92f18280ad6bbe4288a09ab5fbac466dc1397cf32aac0e9","payload":{"connection_id":"5d29200f65794d4d9ab6ef271f045a9b","event_at":"2026-07-28T02:07:49.403000Z","event_type":"best_bid_ask","frame_hash":"0b0ba12623671750df0fbe3ddbdcab63aa902b7dad4fdd2dcc6793856fa1e3e0","frame_index":0,"kind":"data","monotonic_ns":306452941426875,"payload":{"asset_id":"20893381255801015515826997628594359667013752732428989472914000440642900266717","best_ask":"0.56","best_bid":"0.55","event_type":"best_bid_ask","market":"0xda6f0e0e93fc8469e0159a166028d017bddbc162b86f66bac90391379603d962","spread":"0.01","timestamp":"1785204469403"},"payload_hash":"9d8b1c238bc9e3a921e82c8ef5d565e5e008b0b03e9c5309363523b1942a54bc","raw_frame":"{\"market\":\"0xda6f0e0e93fc8469e0159a166028d017bddbc162b86f66bac90391379603d962\", \"asset_id\":\"20893381255801015515826997628594359667013752732428989472914000440642900266717\", \"best_bid\":\"0.55\", \"best_ask\":\"0.56\", \"spread\":\"0.01\", \"timestamp\":\"1785204469403\", \"event_type\":\"best_bid_ask\"}","received_at":"2026-07-28T02:07:49.933723Z","schema_version":"clob-market-ws.best_bid_ask.v1","sequence":null,"server_hash":null,"server_timestamp":"1785204469403","session_id":"d2757dd6dad94f3b9fe67e8dbf1adc37","source":"clob_market_ws"},"received_at":"2026-07-28T02:07:49.933723Z","record_id":"ca87b59e4d70cb642152559f5420c44a58d601e55dfa4fce94a29a2752b0a748","schema_fingerprint":"8488399f31b0337811b13b266be932db7062827c2470b78bd8e9e99bab51d17d","schema_version":"edge-lab-recorder.raw.v1","sequence":null,"source":"clob_market_ws"}
{"event_at":"2026-07-28T02:07:49.403000Z","event_fingerprint":"1a4c5072ea8aaf674ca64c3d435d4eb1e2586fbe43d592fa355d65301252971b","payload":{"connection_id":"5d29200f65794d4d9ab6ef271f045a9b","event_at":"2026-07-28T02:07:49.403000Z","event_type":"best_bid_ask","frame_hash":"a543fe31676ea35ecd64d994993cfe5481deac0f83374d321d7412a8622620ea","frame_index":0,"kind":"data","monotonic_ns":306452945395083,"payload":{"asset_id":"39272994714739463168905443499424551362424437245880253267329605556587274644733","best_ask":"0.45","best_bid":"0.44","event_type":"best_bid_ask","market":"0xda6f0e0e93fc8469e0159a166028d017bddbc162b86f66bac90391379603d962","spread":"0.01","timestamp":"1785204469403"},"payload_hash":"ea43df8bb025881e8dc1c3fd79554bde6de135e3c9357fabc9b76a1354d5e47b","raw_frame":"{\"market\":\"0xda6f0e0e93fc8469e0159a166028d017bddbc162b86f66bac90391379603d962\", \"asset_id\":\"39272994714739463168905443499424551362424437245880253267329605556587274644733\", \"best_bid\":\"0.44\", \"best_ask\":\"0.45\", \"spread\":\"0.01\", \"timestamp\":\"1785204469403\", \"event_type\":\"best_bid_ask\"}","received_at":"2026-07-28T02:07:49.937691Z","schema_version":"clob-market-ws.best_bid_ask.v1","sequence":null,"server_hash":null,"server_timestamp":"1785204469403","session_id":"d2757dd6dad94f3b9fe67e8dbf1adc37","source":"clob_market_ws"},"received_at":"2026-07-28T02:07:49.937691Z","record_id":"fd9a179ed93db8df4391741ecf8c12d3703fcb842b94b6dbb33e1a4f469f662e","schema_fingerprint":"8488399f31b0337811b13b266be932db7062827c2470b78bd8e9e99bab51d17d","schema_version":"edge-lab-recorder.raw.v1","sequence":null,"source":"clob_market_ws"}
{"event_at":"2026-07-28T02:07:49.403000Z","event_fingerprint":"193af97257c844a99f7c59b1f5eca4f1d5949c85f10232d85fb794724b3af25e","payload":{"connection_id":"5d29200f65794d4d9ab6ef271f045a9b","event_at":"2026-07-28T02:07:49.403000Z","event_type":"price_change","frame_hash":"9e2d159f9bc96a02d779f3e22d2e8601996e6b8b1842106361ac47433f4ce8de","frame_index":0,"kind":"data","monotonic_ns":306452948621458,"payload":{"event_type":"price_change","market":"0xda6f0e0e93fc8469e0159a166028d017bddbc162b86f66bac90391379603d962","price_changes":[{"asset_id":"20893381255801015515826997628594359667013752732428989472914000440642900266717","best_ask":"0.56","best_bid":"0.55","hash":"118d058595f1df67fe0a4c85929a159e95484dc3","price":"0.55","side":"BUY","size":"29"},{"asset_id":"39272994714739463168905443499424551362424437245880253267329605556587274644733","best_ask":"0.45","best_bid":"0.44","hash":"34db2f35d3eab45ae5328f35fb00a8c911f925a9","price":"0.45","side":"SELL","size":"29"}],"timestamp":"1785204469403"},"payload_hash":"53aae6094ef5247dad9404f5630489caf1e5b803b671911458643a51147ee975","raw_frame":"{\"market\":\"0xda6f0e0e93fc8469e0159a166028d017bddbc162b86f66bac90391379603d962\", \"price_changes\":[{\"asset_id\":\"20893381255801015515826997628594359667013752732428989472914000440642900266717\", \"price\":\"0.55\", \"size\":\"29\", \"side\":\"BUY\", \"hash\":\"118d058595f1df67fe0a4c85929a159e95484dc3\", \"best_bid\":\"0.55\", \"best_ask\":\"0.56\"}, {\"asset_id\":\"39272994714739463168905443499424551362424437245880253267329605556587274644733\", \"price\":\"0.45\", \"size\":\"29\", \"side\":\"SELL\", \"hash\":\"34db2f35d3eab45ae5328f35fb00a8c911f925a9\", \"best_bid\":\"0.44\", \"best_ask\":\"0.45\"}], \"timestamp\":\"1785204469403\", \"event_type\":\"price_change\"}","received_at":"2026-07-28T02:07:49.940916Z","schema_version":"clob-market-ws.price_change.v1","sequence":null,"server_hash":null,"server_timestamp":"1785204469403","session_id":"d2757dd6dad94f3b9fe67e8dbf1adc37","source":"clob_market_ws"},"received_at":"2026-07-28T02:07:49.940916Z","record_id":"2c4f26e9e916470339c2918915b0b1615396d68340ac9ec0d9e91a4bd6e17587","schema_fingerprint":"4aa3821a28b0b7c2400bc59aba4bcc0a76e971dadd19610d3ad38c768e124dc7","schema_version":"edge-lab-recorder.raw.v1","sequence":null,"source":"clob_market_ws"}
{"event_at":"2026-07-28T02:07:49.403000Z","event_fingerprint":"18c363ba110cc73920860260e2299e5de8ed087c9f3f024a1338eaab0d664237","payload":{"connection_id":"5d29200f65794d4d9ab6ef271f045a9b","event_at":"2026-07-28T02:07:49.403000Z","event_type":"price_change","frame_hash":"7b1133f721fd544f5171639e4d178fdd5731f1136300e541390a32952af1f1b2","frame_index":0,"kind":"data","monotonic_ns":306452955237833,"payload":{"event_type":"price_change","market":"0xda6f0e0e93fc8469e0159a166028d017bddbc162b86f66bac90391379603d962","price_changes":[{"asset_id":"20893381255801015515826997628594359667013752732428989472914000440642900266717","best_ask":"0.56","best_bid":"0.55","hash":"536956345ebed84c410b40b0bf76dab693605057","price":"0.54","side":"BUY","size":"65.9"},{"asset_id":"39272994714739463168905443499424551362424437245880253267329605556587274644733","best_ask":"0.45","best_bid":"0.44","hash":"e66960322907748e0ad0618a9be5f8b0c75f367a","price":"0.46","side":"SELL","size":"65.9"}],"timestamp":"1785204469403"},"payload_hash":"018959052b75beea8420f7e71fb76b1ccf3f18eabeba6910f12ceabf18ba7621","raw_frame":"{\"market\":\"0xda6f0e0e93fc8469e0159a166028d017bddbc162b86f66bac90391379603d962\", \"price_changes\":[{\"asset_id\":\"20893381255801015515826997628594359667013752732428989472914000440642900266717\", \"price\":\"0.54\", \"size\":\"65.9\", \"side\":\"BUY\", \"hash\":\"536956345ebed84c410b40b0bf76dab693605057\", \"best_bid\":\"0.55\", \"best_ask\":\"0.56\"}, {\"asset_id\":\"39272994714739463168905443499424551362424437245880253267329605556587274644733\", \"price\":\"0.46\", \"size\":\"65.9\", \"side\":\"SELL\", \"hash\":\"e66960322907748e0ad0618a9be5f8b0c75f367a\", \"best_bid\":\"0.44\", \"best_ask\":\"0.45\"}], \"timestamp\":\"1785204469403\", \"event_type\":\"price_change\"}","received_at":"2026-07-28T02:07:49.947534Z","schema_version":"clob-market-ws.price_change.v1","sequence":null,"server_hash":null,"server_timestamp":"1785204469403","session_id":"d2757dd6dad94f3b9fe67e8dbf1adc37","source":"clob_market_ws"},"received_at":"2026-07-28T02:07:49.947534Z","record_id":"30e6d20fd0fbbb40f0554be6a5ce82ffaacb5003f5564327edefe51fd526c8aa","schema_fingerprint":"4aa3821a28b0b7c2400bc59aba4bcc0a76e971dadd19610d3ad38c768e124dc7","schema_version":"edge-lab-recorder.raw.v1","sequence":null,"source":"clob_market_ws"}
{"event_at":"2026-07-28T02:07:49.405000Z","event_fingerprint":"62186e77b7d5414043f505adda98e1665e97be9953e0fdac1faa791c6fd87fb0","payload":{"connection_id":"5d29200f65794d4d9ab6ef271f045a9b","event_at":"2026-07-28T02:07:49.405000Z","event_type":"price_change","frame_hash":"e35ae20d5986e0538fc01caab4b4b6d707d3a97e74e550769e90648084f8e061","frame_index":0,"kind":"data","monotonic_ns":306452965104291,"payload":{"event_type":"price_change","market":"0xda6f0e0e93fc8469e0159a166028d017bddbc162b86f66bac90391379603d962","price_changes":[{"asset_id":"20893381255801015515826997628594359667013752732428989472914000440642900266717","best_ask":"0.56","best_bid":"0.55","hash":"92ad0aa97c1d48e97639b3d4d94d97b3e985aa2a","price":"0.55","side":"BUY","size":"44"},{"asset_id":"39272994714739463168905443499424551362424437245880253267329605556587274644733","best_ask":"0.45","best_bid":"0.44","hash":"0ff14e0dfa4e1012e081bcf282ecf9563d1cd8cc","price":"0.45","side":"SELL","size":"44"}],"timestamp":"1785204469405"},"payload_hash":"675aab3e8738fee05ae23492ffde48464acf1e3066d3356bdcf1adee4626a4b9","raw_frame":"{\"market\":\"0xda6f0e0e93fc8469e0159a166028d017bddbc162b86f66bac90391379603d962\", \"price_changes\":[{\"asset_id\":\"20893381255801015515826997628594359667013752732428989472914000440642900266717\", \"price\":\"0.55\", \"size\":\"44\", \"side\":\"BUY\", \"hash\":\"92ad0aa97c1d48e97639b3d4d94d97b3e985aa2a\", \"best_bid\":\"0.55\", \"best_ask\":\"0.56\"}, {\"asset_id\":\"39272994714739463168905443499424551362424437245880253267329605556587274644733\", \"price\":\"0.45\", \"size\":\"44\", \"side\":\"SELL\", \"hash\":\"0ff14e0dfa4e1012e081bcf282ecf9563d1cd8cc\", \"best_bid\":\"0.44\", \"best_ask\":\"0.45\"}], \"timestamp\":\"1785204469405\", \"event_type\":\"price_change\"}","received_at":"2026-07-28T02:07:49.957398Z","schema_version":"clob-market-ws.price_change.v1","sequence":null,"server_hash":null,"server_timestamp":"1785204469405","session_id":"d2757dd6dad94f3b9fe67e8dbf1adc37","source":"clob_market_ws"},"received_at":"2026-07-28T02:07:49.957398Z","record_id":"213f14bf488bfe7334d9045b6f5f7b090760ed54670521170bd3baaab6e7bcb3","schema_fingerprint":"4aa3821a28b0b7c2400bc59aba4bcc0a76e971dadd19610d3ad38c768e124dc7","schema_version":"edge-lab-recorder.raw.v1","sequence":null,"source":"clob_market_ws"}
{"event_at":"2026-07-28T02:07:49.406000Z","event_fingerprint":"e63cf1769946f54da77c22c713ea5701d0b6a75cc5fcd2349976a562db1bc4ad","payload":{"connection_id":"5d29200f65794d4d9ab6ef271f045a9b","event_at":"2026-07-28T02:07:49.406000Z","event_type":"price_change","frame_hash":"0dcfcd50c312e9e43b7eea66b77113deb9c4f632543aebcd26ddd9ba821f3f41","frame_index":0,"kind":"data","monotonic_ns":306452969752166,"payload":{"event_type":"price_change","market":"0xda6f0e0e93fc8469e0159a166028d017bddbc162b86f66bac90391379603d962","price_changes":[{"asset_id":"20893381255801015515826997628594359667013752732428989472914000440642900266717","best_ask":"0.56","best_bid":"0.55","hash":"428b41fce03e1ebfcea6d29f13203fe2433b7298","price":"0.49","side":"BUY","size":"121.2"},{"asset_id":"39272994714739463168905443499424551362424437245880253267329605556587274644733","best_ask":"0.45","best_bid":"0.44","hash":"36394cb132942605b26e53c3ff101e65beebf92f","price":"0.51","side":"SELL","size":"121.2"}],"timestamp":"1785204469406"},"payload_hash":"ebea79380abf6549a3979e2bed952f66ac72ddf8dff624b7fb843527640c5a31","raw_frame":"{\"market\":\"0xda6f0e0e93fc8469e0159a166028d017bddbc162b86f66bac90391379603d962\", \"price_changes\":[{\"asset_id\":\"20893381255801015515826997628594359667013752732428989472914000440642900266717\", \"price\":\"0.49\", \"size\":\"121.2\", \"side\":\"BUY\", \"hash\":\"428b41fce03e1ebfcea6d29f13203fe2433b7298\", \"best_bid\":\"0.55\", \"best_ask\":\"0.56\"}, {\"asset_id\":\"39272994714739463168905443499424551362424437245880253267329605556587274644733\", \"price\":\"0.51\", \"size\":\"121.2\", \"side\":\"SELL\", \"hash\":\"36394cb132942605b26e53c3ff101e65beebf92f\", \"best_bid\":\"0.44\", \"best_ask\":\"0.45\"}], \"timestamp\":\"1785204469406\", \"event_type\":\"price_change\"}","received_at":"2026-07-28T02:07:49.962047Z","schema_version":"clob-market-ws.price_change.v1","sequence":null,"server_hash":null,"server_timestamp":"1785204469406","session_id":"d2757dd6dad94f3b9fe67e8dbf1adc37","source":"clob_market_ws"},"received_at":"2026-07-28T02:07:49.962047Z","record_id":"df30d554c635b2b7937eea08e36b14569681f20f415be4dbb963e8970bba1283","schema_fingerprint":"4aa3821a28b0b7c2400bc59aba4bcc0a76e971dadd19610d3ad38c768e124dc7","schema_version":"edge-lab-recorder.raw.v1","sequence":null,"source":"clob_market_ws"}
{"event_at":"2026-07-28T02:07:49.406000Z","event_fingerprint":"2f8e9a1832465d15b84839dd4e28b8ef215ccbc4990c9b1f8a8f8b9b8effeb03","payload":{"connection_id":"5d29200f65794d4d9ab6ef271f045a9b","event_at":"2026-07-28T02:07:49.406000Z","event_type":"price_change","frame_hash":"17f6473190dba4557602704bd68ee1cc99d26893f5571b996aa7f86defedd0fb","frame_index":0,"kind":"data","monotonic_ns":306452974401541,"payload":{"event_type":"price_change","market":"0xda6f0e0e93fc8469e0159a166028d017bddbc162b86f66bac90391379603d962","price_changes":[{"asset_id":"39272994714739463168905443499424551362424437245880253267329605556587274644733","best_ask":"0.45","best_bid":"0.44","hash":"a89daf73143da6bda5acb2116bc50f8d9433ab7b","price":"0.35","side":"BUY","size":"79"},{"asset_id":"20893381255801015515826997628594359667013752732428989472914000440642900266717","best_ask":"0.56","best_bid":"0.55","hash":"d7be65c5a7158f5ae4450acafc70754cd03821a9","price":"0.65","side":"SELL","size":"79"}],"timestamp":"1785204469406"},"payload_hash":"d10764bd950b27f7559e1ecc3afb0b64939ce4b88585f70e1a93298315da0f76","raw_frame":"{\"market\":\"0xda6f0e0e93fc8469e0159a166028d017bddbc162b86f66bac90391379603d962\", \"price_changes\":[{\"asset_id\":\"39272994714739463168905443499424551362424437245880253267329605556587274644733\", \"price\":\"0.35\", \"size\":\"79\", \"side\":\"BUY\", \"hash\":\"a89daf73143da6bda5acb2116bc50f8d9433ab7b\", \"best_bid\":\"0.44\", \"best_ask\":\"0.45\"}, {\"asset_id\":\"20893381255801015515826997628594359667013752732428989472914000440642900266717\", \"price\":\"0.65\", \"size\":\"79\", \"side\":\"SELL\", \"hash\":\"d7be65c5a7158f5ae4450acafc70754cd03821a9\", \"best_bid\":\"0.55\", \"best_ask\":\"0.56\"}], \"timestamp\":\"1785204469406\", \"event_type\":\"price_change\"}","received_at":"2026-07-28T02:07:49.966696Z","schema_version":"clob-market-ws.price_change.v1","sequence":null,"server_hash":null,"server_timestamp":"1785204469406","session_id":"d2757dd6dad94f3b9fe67e8dbf1adc37","source":"clob_market_ws"},"received_at":"2026-07-28T02:07:49.966696Z","record_id":"3cab826f159dadb4c21b4fedc45a7b6efa700507be8e596dde203dff21e48cf9","schema_fingerprint":"4aa3821a28b0b7c2400bc59aba4bcc0a76e971dadd19610d3ad38c768e124dc7","schema_version":"edge-lab-recorder.raw.v1","sequence":null,"source":"clob_market_ws"}
