{"event_at":"2026-07-28T02:08:52.894000Z","event_fingerprint":"fd9e5534533ac6dd940e2340d7df00b511c673a96eb88e0e047adbe776a3fd1a","payload":{"connection_id":"5d29200f65794d4d9ab6ef271f045a9b","event_at":"2026-07-28T02:08:52.894000Z","event_type":"price_change","frame_hash":"129c134cd2278eff2d624d41cee9d6f5793cc1e9008d2b7e4591064c038f1ae2","frame_index":0,"kind":"data","monotonic_ns":306516520168041,"payload":{"event_type":"price_change","market":"0xda6f0e0e93fc8469e0159a166028d017bddbc162b86f66bac90391379603d962","price_changes":[{"asset_id":"20893381255801015515826997628594359667013752732428989472914000440642900266717","best_ask":"0.57","best_bid":"0.56","hash":"9bbba1ee415b48589f85d5c83aed5ad7f8ccc7a7","price":"0.56","side":"BUY","size":"69.2"},{"asset_id":"39272994714739463168905443499424551362424437245880253267329605556587274644733","best_ask":"0.44","best_bid":"0.43","hash":"a57c9df815d0932c1c538b20ba3b7cae8c363ab9","price":"0.44","side":"SELL","size":"69.2"}],"timestamp":"1785204532894"},"payload_hash":"0542d6772d2f23b06bcb42ba0799289fd4c53792f238044807eb7acbd2528dad","raw_frame":"{\"market\":\"0xda6f0e0e93fc8469e0159a166028d017bddbc162b86f66bac90391379603d962\", \"price_changes\":[{\"asset_id\":\"20893381255801015515826997628594359667013752732428989472914000440642900266717\", \"price\":\"0.56\", \"size\":\"69.2\", \"side\":\"BUY\", \"hash\":\"9bbba1ee415b48589f85d5c83aed5ad7f8ccc7a7\", \"best_bid\":\"0.56\", \"best_ask\":\"0.57\"}, {\"asset_id\":\"39272994714739463168905443499424551362424437245880253267329605556587274644733\", \"price\":\"0.44\", \"size\":\"69.2\", \"side\":\"SELL\", \"hash\":\"a57c9df815d0932c1c538b20ba3b7cae8c363ab9\", \"best_bid\":\"0.43\", \"best_ask\":\"0.44\"}], \"timestamp\":\"1785204532894\", \"event_type\":\"price_change\"}","received_at":"2026-07-28T02:08:53.511830Z","schema_version":"clob-market-ws.price_change.v1","sequence":null,"server_hash":null,"server_timestamp":"1785204532894","session_id":"d2757dd6dad94f3b9fe67e8dbf1adc37","source":"clob_market_ws"},"received_at":"2026-07-28T02:08:53.511830Z","record_id":"3aded7510b9edb407fe5d57d7acfd02f5fb1b16f0de7e289cb5ef191c82a3683","schema_fingerprint":"4aa3821a28b0b7c2400bc59aba4bcc0a76e971dadd19610d3ad38c768e124dc7","schema_version":"edge-lab-recorder.raw.v1","sequence":null,"source":"clob_market_ws"}
{"event_at":"2026-07-28T02:08:52.897000Z","event_fingerprint":"2c65a2c3e285c0454a9cf5bbf86c8318798e0f8898b958005f6b30fada1ccdab","payload":{"connection_id":"5d29200f65794d4d9ab6ef271f045a9b","event_at":"2026-07-28T02:08:52.897000Z","event_type":"price_change","frame_hash":"badb9337d9fed3c13948531ad4283027a1e75f81c19fa67289db3ded0cb7eb23","frame_index":0,"kind":"data","monotonic_ns":306516533654166,"payload":{"event_type":"price_change","market":"0xda6f0e0e93fc8469e0159a166028d017bddbc162b86f66bac90391379603d962","price_changes":[{"asset_id":"39272994714739463168905443499424551362424437245880253267329605556587274644733","best_ask":"0.44","best_bid":"0.43","hash":"fe4c166719b16400f73ac2af7a388a96eeb022b7","price":"0.35","side":"BUY","size":"161"},{"asset_id":"20893381255801015515826997628594359667013752732428989472914000440642900266717","best_ask":"0.57","best_bid":"0.56","hash":"b1500fcfd19211ad8542a17ba68106b3640f6bb3","price":"0.65","side":"SELL","size":"161"}],"timestamp":"1785204532897"},"payload_hash":"7d991c145f3668ebd51964fd9c6f66ff7e4174bbcfb73f8f969a918473961732","raw_frame":"{\"market\":\"0xda6f0e0e93fc8469e0159a166028d017bddbc162b86f66bac90391379603d962\", \"price_changes\":[{\"asset_id\":\"39272994714739463168905443499424551362424437245880253267329605556587274644733\", \"price\":\"0.35\", \"size\":\"161\", \"side\":\"BUY\", \"hash\":\"fe4c166719b16400f73ac2af7a388a96eeb022b7\", \"best_bid\":\"0.43\", \"best_ask\":\"0.44\"}, {\"asset_id\":\"20893381255801015515826997628594359667013752732428989472914000440642900266717\", \"price\":\"0.65\", \"size\":\"161\", \"side\":\"SELL\", \"hash\":\"b1500fcfd19211ad8542a17ba68106b3640f6bb3\", \"best_bid\":\"0.56\", \"best_ask\":\"0.57\"}], \"timestamp\":\"1785204532897\", \"event_type\":\"price_change\"}","received_at":"2026-07-28T02:08:53.525318Z","schema_version":"clob-market-ws.price_change.v1","sequence":null,"server_hash":null,"server_timestamp":"1785204532897","session_id":"d2757dd6dad94f3b9fe67e8dbf1adc37","source":"clob_market_ws"},"received_at":"2026-07-28T02:08:53.525318Z","record_id":"022e7e17cbe26b0ad3fa52bcae2008394a221a528493c2cb8cf766f06c9f5ed4","schema_fingerprint":"4aa3821a28b0b7c2400bc59aba4bcc0a76e971dadd19610d3ad38c768e124dc7","schema_version":"edge-lab-recorder.raw.v1","sequence":null,"source":"clob_market_ws"}
{"event_at":"2026-07-28T02:08:52.898000Z","event_fingerprint":"e2f1edd74c4f699a55f8bdd92d720961060dd5acbaa8b836b27ab9909ef6fb21","payload":{"connection_id":"5d29200f65794d4d9ab6ef271f045a9b","event_at":"2026-07-28T02:08:52.898000Z","event_type":"price_change","frame_hash":"904f7299f0536efc7225598da5eb105709b97cc77abd9791b3412506b67909c9","frame_index":0,"kind":"data","monotonic_ns":306516536714333,"payload":{"event_type":"price_change","market":"0xda6f0e0e93fc8469e0159a166028d017bddbc162b86f66bac90391379603d962","price_changes":[{"asset_id":"20893381255801015515826997628594359667013752732428989472914000440642900266717","best_ask":"0.57","best_bid":"0.56","hash":"f6f9982bffdb7af178346f5d97fc4f2cdf50b5d2","price":"0.55","side":"BUY","size":"59"},{"asset_id":"39272994714739463168905443499424551362424437245880253267329605556587274644733","best_ask":"0.44","best_bid":"0.43","hash":"720527e8ee951b7632ddb4402696b78d0f150fd9","price":"0.45","side":"SELL","size":"59"}],"timestamp":"1785204532898"},"payload_hash":"87e388be623cd060bb8556f70a172473f8ac8c9b3c3e8adbdb78bea81a02b910","raw_frame":"{\"market\":\"0xda6f0e0e93fc8469e0159a166028d017bddbc162b86f66bac90391379603d962\", \"price_changes\":[{\"asset_id\":\"20893381255801015515826997628594359667013752732428989472914000440642900266717\", \"price\":\"0.55\", \"size\":\"59\", \"side\":\"BUY\", \"hash\":\"f6f9982bffdb7af178346f5d97fc4f2cdf50b5d2\", \"best_bid\":\"0.56\", \"best_ask\":\"0.57\"}, {\"asset_id\":\"39272994714739463168905443499424551362424437245880253267329605556587274644733\", \"price\":\"0.45\", \"size\":\"59\", \"side\":\"SELL\", \"hash\":\"720527e8ee951b7632ddb4402696b78d0f150fd9\", \"best_bid\":\"0.43\", \"best_ask\":\"0.44\"}], \"timestamp\":\"1785204532898\", \"event_type\":\"price_change\"}","received_at":"2026-07-28T02:08:53.528378Z","schema_version":"clob-market-ws.price_change.v1","sequence":null,"server_hash":null,"server_timestamp":"1785204532898","session_id":"d2757dd6dad94f3b9fe67e8dbf1adc37","source":"clob_market_ws"},"received_at":"2026-07-28T02:08:53.528378Z","record_id":"8eb5df55f3cf7196119af0a9b269bdf332caedae07fdb688e9481a6d06ace5e0","schema_fingerprint":"4aa3821a28b0b7c2400bc59aba4bcc0a76e971dadd19610d3ad38c768e124dc7","schema_version":"edge-lab-recorder.raw.v1","sequence":null,"source":"clob_market_ws"}
{"event_at":"2026-07-28T02:08:52.899000Z","event_fingerprint":"78a317e781a3908b4d6db11fadf9d12e3c16cd97b83e88abf87ce3cc5cda3187","payload":{"connection_id":"5d29200f65794d4d9ab6ef271f045a9b","event_at":"2026-07-28T02:08:52.899000Z","event_type":"price_change","frame_hash":"cfee1c99856b525aa8b6d1e532a4c55dca36849d2bd4a2b30ccb2779e30da949","frame_index":0,"kind":"data","monotonic_ns":306516540453416,"payload":{"event_type":"price_change","market":"0xda6f0e0e93fc8469e0159a166028d017bddbc162b86f66bac90391379603d962","price_changes":[{"asset_id":"20893381255801015515826997628594359667013752732428989472914000440642900266717","best_ask":"0.57","best_bid":"0.56","hash":"0891bf205a4a17433470e9dab12e34eec5ce0fb3","price":"0.46","side":"BUY","size":"293.09"},{"asset_id":"39272994714739463168905443499424551362424437245880253267329605556587274644733","best_ask":"0.44","best_bid":"0.43","hash":"ce423916f769e3122974a2a2f0ce2c954bdb0c2b","price":"0.54","side":"SELL","size":"293.09"}],"timestamp":"1785204532899"},"payload_hash":"ace432005b6ceb96136f05538a27271b6226acc403ff6ba22af48b44e371b8a7","raw_frame":"{\"market\":\"0xda6f0e0e93fc8469e0159a166028d017bddbc162b86f66bac90391379603d962\", \"price_changes\":[{\"asset_id\":\"20893381255801015515826997628594359667013752732428989472914000440642900266717\", \"price\":\"0.46\", \"size\":\"293.09\", \"side\":\"BUY\", \"hash\":\"0891bf205a4a17433470e9dab12e34eec5ce0fb3\", \"best_bid\":\"0.56\", \"best_ask\":\"0.57\"}, {\"asset_id\":\"39272994714739463168905443499424551362424437245880253267329605556587274644733\", \"price\":\"0.54\", \"size\":\"293.09\", \"side\":\"SELL\", \"hash\":\"ce423916f769e3122974a2a2f0ce2c954bdb0c2b\", \"best_bid\":\"0.43\", \"best_ask\":\"0.44\"}], \"timestamp\":\"1785204532899\", \"event_type\":\"price_change\"}","received_at":"2026-07-28T02:08:53.532119Z","schema_version":"clob-market-ws.price_change.v1","sequence":null,"server_hash":null,"server_timestamp":"1785204532899","session_id":"d2757dd6dad94f3b9fe67e8dbf1adc37","source":"clob_market_ws"},"received_at":"2026-07-28T02:08:53.532119Z","record_id":"7e9ff67c48f95499901f9b4f9bf5c3641e6183645c671e91e42ed8b745d64570","schema_fingerprint":"4aa3821a28b0b7c2400bc59aba4bcc0a76e971dadd19610d3ad38c768e124dc7","schema_version":"edge-lab-recorder.raw.v1","sequence":null,"source":"clob_market_ws"}
{"event_at":"2026-07-28T02:08:52.900000Z","event_fingerprint":"02595e7b68749e35a1b19bfbbb37f7aeb49c6e9050730c137b21ae4e171830ba","payload":{"connection_id":"5d29200f65794d4d9ab6ef271f045a9b","event_at":"2026-07-28T02:08:52.900000Z","event_type":"price_change","frame_hash":"ec9de46b0e2627ef896183000bc3597a1cc40097b00af519531c6eeb85e62c8c","frame_index":0,"kind":"data","monotonic_ns":306516542814041,"payload":{"event_type":"price_change","market":"0xda6f0e0e93fc8469e0159a166028d017bddbc162b86f66bac90391379603d962","price_changes":[{"asset_id":"39272994714739463168905443499424551362424437245880253267329605556587274644733","best_ask":"0.44","best_bid":"0.43","hash":"0717eba919ca2b31afdb76ee9ac134e4a9a93c17","price":"0.42","side":"BUY","size":"59"},{"asset_id":"20893381255801015515826997628594359667013752732428989472914000440642900266717","best_ask":"0.57","best_bid":"0.56","hash":"bca3ead5f48d0e048e987eb9dc9b4c06dbc11aad","price":"0.58","side":"SELL","size":"59"}],"timestamp":"1785204532900"},"payload_hash":"56ff78583b63b630d4622a0be33c73f9be3bbba36a7d9192c778dfe9ed1993d4","raw_frame":"{\"market\":\"0xda6f0e0e93fc8469e0159a166028d017bddbc162b86f66bac90391379603d962\", \"price_changes\":[{\"asset_id\":\"39272994714739463168905443499424551362424437245880253267329605556587274644733\", \"price\":\"0.42\", \"size\":\"59\", \"side\":\"BUY\", \"hash\":\"0717eba919ca2b31afdb76ee9ac134e4a9a93c17\", \"best_bid\":\"0.43\", \"best_ask\":\"0.44\"}, {\"asset_id\":\"20893381255801015515826997628594359667013752732428989472914000440642900266717\", \"price\":\"0.58\", \"size\":\"59\", \"side\":\"SELL\", \"hash\":\"bca3ead5f48d0e048e987eb9dc9b4c06dbc11aad\", \"best_bid\":\"0.56\", \"best_ask\":\"0.57\"}], \"timestamp\":\"1785204532900\", \"event_type\":\"price_change\"}","received_at":"2026-07-28T02:08:53.534476Z","schema_version":"clob-market-ws.price_change.v1","sequence":null,"server_hash":null,"server_timestamp":"1785204532900","session_id":"d2757dd6dad94f3b9fe67e8dbf1adc37","source":"clob_market_ws"},"received_at":"2026-07-28T02:08:53.534476Z","record_id":"e37a4e978dcc4a1a46547573f0b8d4cd5d5bf4cc004dcd63268e35476ff58310","schema_fingerprint":"4aa3821a28b0b7c2400bc59aba4bcc0a76e971dadd19610d3ad38c768e124dc7","schema_version":"edge-lab-recorder.raw.v1","sequence":null,"source":"clob_market_ws"}
{"event_at":"2026-07-28T02:08:52.901000Z","event_fingerprint":"cbd18825245ee75e60cdcef908b9af02639678bda53984bdeb15509bb267e107","payload":{"connection_id":"5d29200f65794d4d9ab6ef271f045a9b","event_at":"2026-07-28T02:08:52.901000Z","event_type":"price_change","frame_hash":"0db98d993722de0049d1c1818ddabfbea1efd155cd517cc12db2a0777260134f","frame_index":0,"kind":"data","monotonic_ns":306516545745583,"payload":{"event_type":"price_change","market":"0xda6f0e0e93fc8469e0159a166028d017bddbc162b86f66bac90391379603d962","price_changes":[{"asset_id":"39272994714739463168905443499424551362424437245880253267329605556587274644733","best_ask":"0.44","best_bid":"0.43","hash":"d3e978fc0275af4489fb56f32ef0afcce38c1c5e","price":"0.42","side":"BUY","size":"54"},{"asset_id":"20893381255801015515826997628594359667013752732428989472914000440642900266717","best_ask":"0.57","best_bid":"0.56","hash":"50b1a5fdcd2bfbb1ed4ae35ddbe281e92b10dcb9","price":"0.58","side":"SELL","size":"54"}],"timestamp":"1785204532901"},"payload_hash":"e8f2fc0573b99b32a96441937b0297bb5b365f067ec5cf94bdb3546edb9ac6eb","raw_frame":"{\"market\":\"0xda6f0e0e93fc8469e0159a166028d017bddbc162b86f66bac90391379603d962\", \"price_changes\":[{\"asset_id\":\"39272994714739463168905443499424551362424437245880253267329605556587274644733\", \"price\":\"0.42\", \"size\":\"54\", \"side\":\"BUY\", \"hash\":\"d3e978fc0275af4489fb56f32ef0afcce38c1c5e\", \"best_bid\":\"0.43\", \"best_ask\":\"0.44\"}, {\"asset_id\":\"20893381255801015515826997628594359667013752732428989472914000440642900266717\", \"price\":\"0.58\", \"size\":\"54\", \"side\":\"SELL\", \"hash\":\"50b1a5fdcd2bfbb1ed4ae35ddbe281e92b10dcb9\", \"best_bid\":\"0.56\", \"best_ask\":\"0.57\"}], \"timestamp\":\"1785204532901\", \"event_type\":\"price_change\"}","received_at":"2026-07-28T02:08:53.537408Z","schema_version":"clob-market-ws.price_change.v1","sequence":null,"server_hash":null,"server_timestamp":"1785204532901","session_id":"d2757dd6dad94f3b9fe67e8dbf1adc37","source":"clob_market_ws"},"received_at":"2026-07-28T02:08:53.537408Z","record_id":"c72514a1c8465479a2bcd7ee26a3dcd6db33e0f8166434a17b046381efdbf60a","schema_fingerprint":"4aa3821a28b0b7c2400bc59aba4bcc0a76e971dadd19610d3ad38c768e124dc7","schema_version":"edge-lab-recorder.raw.v1","sequence":null,"source":"clob_market_ws"}
{"event_at":"2026-07-28T02:08:52.901000Z","event_fingerprint":"13e526081c7e8b8c04442409c5ee70cdc545b1b07d252649e243cdaf9fb0bbb8","payload":{"connection_id":"5d29200f65794d4d9ab6ef271f045a9b","event_at":"2026-07-28T02:08:52.901000Z","event_type":"price_change","frame_hash":"56d528a732573cc8292695f125e34d325990a9de447bc254ca7257311db69019","frame_index":0,"kind":"data","monotonic_ns":306516550267250,"payload":{"event_type":"price_change","market":"0xda6f0e0e93fc8469e0159a166028d017bddbc162b86f66bac90391379603d962","price_changes":[{"asset_id":"39272994714739463168905443499424551362424437245880253267329605556587274644733","best_ask":"0.44","best_bid":"0.43","hash":"c57d960191fd5e35a471751488eacdf4cf171487","price":"0.41","side":"BUY","size":"120.99"},{"asset_id":"20893381255801015515826997628594359667013752732428989472914000440642900266717","best_ask":"0.57","best_bid":"0.56","hash":"9b04b5f91baaba268b4e7a0284dac23a02e0f511","price":"0.59","side":"SELL","size":"120.99"}],"timestamp":"1785204532901"},"payload_hash":"dcbc30c51849083d0fc018a9046f6f872b5479361fd05b8bb8d19c6829fa8bc1","raw_frame":"{\"market\":\"0xda6f0e0e93fc8469e0159a166028d017bddbc162b86f66bac90391379603d962\", \"price_changes\":[{\"asset_id\":\"39272994714739463168905443499424551362424437245880253267329605556587274644733\", \"price\":\"0.41\", \"size\":\"120.99\", \"side\":\"BUY\", \"hash\":\"c57d960191fd5e35a471751488eacdf4cf171487\", \"best_bid\":\"0.43\", \"best_ask\":\"0.44\"}, {\"asset_id\":\"20893381255801015515826997628594359667013752732428989472914000440642900266717\", \"price\":\"0.59\", \"size\":\"120.99\", \"side\":\"SELL\", \"hash\":\"9b04b5f91baaba268b4e7a0284dac23a02e0f511\", \"best_bid\":\"0.56\", \"best_ask\":\"0.57\"}], \"timestamp\":\"1785204532901\", \"event_type\":\"price_change\"}","received_at":"2026-07-28T02:08:53.541932Z","schema_version":"clob-market-ws.price_change.v1","sequence":null,"server_hash":null,"server_timestamp":"1785204532901","session_id":"d2757dd6dad94f3b9fe67e8dbf1adc37","source":"clob_market_ws"},"received_at":"2026-07-28T02:08:53.541932Z","record_id":"47537a33ce2c78dbc8c164df53565ee92edababe4f662026b00abbc1cc05241e","schema_fingerprint":"4aa3821a28b0b7c2400bc59aba4bcc0a76e971dadd19610d3ad38c768e124dc7","schema_version":"edge-lab-recorder.raw.v1","sequence":null,"source":"clob_market_ws"}
{"event_at":"2026-07-28T02:08:52.901000Z","event_fingerprint":"aed1f59aeb0b07749b7447c91c7dc6b8cbc6cd51a59923fcccd0312c1aef3219","payload":{"connection_id":"5d29200f65794d4d9ab6ef271f045a9b","event_at":"2026-07-28T02:08:52.901000Z","event_type":"price_change","frame_hash":"f28a476595ecdaf5297fdd862ab2657300178eafa88fdb03a866c6000b06245a","frame_index":0,"kind":"data","monotonic_ns":306516555074625,"payload":{"event_type":"price_change","market":"0xda6f0e0e93fc8469e0159a166028d017bddbc162b86f66bac90391379603d962","price_changes":[{"asset_id":"39272994714739463168905443499424551362424437245880253267329605556587274644733","best_ask":"0.44","best_bid":"0.43","hash":"c57d960191fd5e35a471751488eacdf4cf171487","price":"0.42","side":"BUY","size":"49"},{"asset_id":"20893381255801015515826997628594359667013752732428989472914000440642900266717","best_ask":"0.57","best_bid":"0.56","hash":"9b04b5f91baaba268b4e7a0284dac23a02e0f511","price":"0.58","side":"SELL","size":"49"}],"timestamp":"1785204532901"},"payload_hash":"3098e600af3bf38d2424104ccf9fb20f3ffbe20cc42d0d0ba0279a2e6c581af3","raw_frame":"{\"market\":\"0xda6f0e0e93fc8469e0159a166028d017bddbc162b86f66bac90391379603d962\", \"price_changes\":[{\"asset_id\":\"39272994714739463168905443499424551362424437245880253267329605556587274644733\", \"price\":\"0.42\", \"size\":\"49\", \"side\":\"BUY\", \"hash\":\"c57d960191fd5e35a471751488eacdf4cf171487\", \"best_bid\":\"0.43\", \"best_ask\":\"0.44\"}, {\"asset_id\":\"20893381255801015515826997628594359667013752732428989472914000440642900266717\", \"price\":\"0.58\", \"size\":\"49\", \"side\":\"SELL\", \"hash\":\"9b04b5f91baaba268b4e7a0284dac23a02e0f511\", \"best_bid\":\"0.56\", \"best_ask\":\"0.57\"}], \"timestamp\":\"1785204532901\", \"event_type\":\"price_change\"}","received_at":"2026-07-28T02:08:53.546737Z","schema_version":"clob-market-ws.price_change.v1","sequence":null,"server_hash":null,"server_timestamp":"1785204532901","session_id":"d2757dd6dad94f3b9fe67e8dbf1adc37","source":"clob_market_ws"},"received_at":"2026-07-28T02:08:53.546737Z","record_id":"7ba6387efe689792145429d7ce278ec0a7b239e7cfb18329982a4a12bb2aca0b","schema_fingerprint":"4aa3821a28b0b7c2400bc59aba4bcc0a76e971dadd19610d3ad38c768e124dc7","schema_version":"edge-lab-recorder.raw.v1","sequence":null,"source":"clob_market_ws"}
{"event_at":"2026-07-28T02:08:52.903000Z","event_fingerprint":"5eb884af39aaf8bdbc4d7a1408e0408c4eb80f2cc11a3b715e11113a215ebb3d","payload":{"connection_id":"5d29200f65794d4d9ab6ef271f045a9b","event_at":"2026-07-28T02:08:52.903000Z","event_type":"price_change","frame_hash":"3f284778fd70d11681a65c14db9f23f62491fe57ef6dc0ee441b57f3aac86e94","frame_index":0,"kind":"data","monotonic_ns":306516558107458,"payload":{"event_type":"price_change","market":"0xda6f0e0e93fc8469e0159a166028d017bddbc162b86f66bac90391379603d962","price_changes":[{"asset_id":"20893381255801015515826997628594359667013752732428989472914000440642900266717","best_ask":"0.57","best_bid":"0.56","hash":"2d0a234640e6656de9b12e50e49cd859cc6f52b1","price":"0.46","side":"BUY","size":"253.09"},{"asset_id":"39272994714739463168905443499424551362424437245880253267329605556587274644733","best_ask":"0.44","best_bid":"0.43","hash":"5b9713bacb5a24c4c7f414b66fd54c15f60eaa04","price":"0.54","side":"SELL","size":"253.09"}],"timestamp":"1785204532903"},"payload_hash":"ed152514c8fec9b55e406eaf368dad94b223287f6393f57ff821efe322005e25","raw_frame":"{\"market\":\"0xda6f0e0e93fc8469e0159a166028d017bddbc162b86f66bac90391379603d962\", \"price_changes\":[{\"asset_id\":\"20893381255801015515826997628594359667013752732428989472914000440642900266717\", \"price\":\"0.46\", \"size\":\"253.09\", \"side\":\"BUY\", \"hash\":\"2d0a234640e6656de9b12e50e49cd859cc6f52b1\", \"best_bid\":\"0.56\", \"best_ask\":\"0.57\"}, {\"asset_id\":\"39272994714739463168905443499424551362424437245880253267329605556587274644733\", \"price\":\"0.54\", \"size\":\"253.09\", \"side\":\"SELL\", \"hash\":\"5b9713bacb5a24c4c7f414b66fd54c15f60eaa04\", \"best_bid\":\"0.43\", \"best_ask\":\"0.44\"}], \"timestamp\":\"1785204532903\", \"event_type\":\"price_change\"}","received_at":"2026-07-28T02:08:53.549771Z","schema_version":"clob-market-ws.price_change.v1","sequence":null,"server_hash":null,"server_timestamp":"1785204532903","session_id":"d2757dd6dad94f3b9fe67e8dbf1adc37","source":"clob_market_ws"},"received_at":"2026-07-28T02:08:53.549771Z","record_id":"59a3cc6059fc91b44cbdc5e8157515835b0d89f5f7a92ecaf0e894e784d37f8b","schema_fingerprint":"4aa3821a28b0b7c2400bc59aba4bcc0a76e971dadd19610d3ad38c768e124dc7","schema_version":"edge-lab-recorder.raw.v1","sequence":null,"source":"clob_market_ws"}
{"event_at":"2026-07-28T02:08:52.903000Z","event_fingerprint":"27d5a6c1b79d9f506f2afa0e0cd340433302273aeb28c5650153e297891882f4","payload":{"connection_id":"5d29200f65794d4d9ab6ef271f045a9b","event_at":"2026-07-28T02:08:52.903000Z","event_type":"price_change","frame_hash":"0922a0119878f2c8b78302046c6186170f7e299074a2f270f07fab2f5027ea1f","frame_index":0,"kind":"data","monotonic_ns":306516562547875,"payload":{"event_type":"price_change","market":"0xda6f0e0e93fc8469e0159a166028d017bddbc162b86f66bac90391379603d962","price_changes":[{"asset_id":"39272994714739463168905443499424551362424437245880253267329605556587274644733","best_ask":"0.44","best_bid":"0.43","hash":"d03c08163c4cdb0e328208774fd7dfefa31c7524","price":"0.25","side":"BUY","size":"210"},{"asset_id":"20893381255801015515826997628594359667013752732428989472914000440642900266717","best_ask":"0.57","best_bid":"0.56","hash":"d5853fc475ed5ed8d3baf8cba25fb99d7a7e25cd","price":"0.75","side":"SELL","size":"210"}],"timestamp":"1785204532903"},"payload_hash":"d685c2116386ce7d9a55add48388174b89fc01d89ab6358b18ebbbce95a7372c","raw_frame":"{\"market\":\"0xda6f0e0e93fc8469e0159a166028d017bddbc162b86f66bac90391379603d962\", \"price_changes\":[{\"asset_id\":\"39272994714739463168905443499424551362424437245880253267329605556587274644733\", \"price\":\"0.25\", \"size\":\"210\", \"side\":\"BUY\", \"hash\":\"d03c08163c4cdb0e328208774fd7dfefa31c7524\", \"best_bid\":\"0.43\", \"best_ask\":\"0.44\"}, {\"asset_id\":\"20893381255801015515826997628594359667013752732428989472914000440642900266717\", \"price\":\"0.75\", \"size\":\"210\", \"side\":\"SELL\", \"hash\":\"d5853fc475ed5ed8d3baf8cba25fb99d7a7e25cd\", \"best_bid\":\"0.56\", \"best_ask\":\"0.57\"}], \"timestamp\":\"1785204532903\", \"event_type\":\"price_change\"}","received_at":"2026-07-28T02:08:53.554206Z","schema_version":"clob-market-ws.price_change.v1","sequence":null,"server_hash":null,"server_timestamp":"1785204532903","session_id":"d2757dd6dad94f3b9fe67e8dbf1adc37","source":"clob_market_ws"},"received_at":"2026-07-28T02:08:53.554206Z","record_id":"b58e78e781e16db2eaf2049851e5829f94ac627239de165d1f977038eb8ca412","schema_fingerprint":"4aa3821a28b0b7c2400bc59aba4bcc0a76e971dadd19610d3ad38c768e124dc7","schema_version":"edge-lab-recorder.raw.v1","sequence":null,"source":"clob_market_ws"}
{"event_at":"2026-07-28T02:08:52.903000Z","event_fingerprint":"230728e04b8bd2d89b633b15085ebce73c85e2b251d0f383ffa5485065520be1","payload":{"connection_id":"5d29200f65794d4d9ab6ef271f045a9b","event_at":"2026-07-28T02:08:52.903000Z","event_type":"price_change","frame_hash":"7db602a9f93fb8cec3d161e0efad5526d9baad21d01e13863ae5b42bfc17410a","frame_index":0,"kind":"data","monotonic_ns":306516565518291,"payload":{"event_type":"price_change","market":"0xda6f0e0e93fc8469e0159a166028d017bddbc162b86f66bac90391379603d962","price_changes":[{"asset_id":"39272994714739463168905443499424551362424437245880253267329605556587274644733","best_ask":"0.44","best_bid":"0.43","hash":"7986bd57d0304ecbc70a49ea73912e884c354217","price":"0.43","side":"BUY","size":"57"},{"asset_id":"20893381255801015515826997628594359667013752732428989472914000440642900266717","best_ask":"0.57","best_bid":"0.56","hash":"49a66ea5c42d4817bbfc8ad2643e96586ee10707","price":"0.57","side":"SELL","size":"57"}],"timestamp":"1785204532903"},"payload_hash":"f6712400605d733ee070ff9658c5602149dfca81e59edeb8480727c116bf1b16","raw_frame":"{\"market\":\"0xda6f0e0e93fc8469e0159a166028d017bddbc162b86f66bac90391379603d962\", \"price_changes\":[{\"asset_id\":\"39272994714739463168905443499424551362424437245880253267329605556587274644733\", \"price\":\"0.43\", \"size\":\"57\", \"side\":\"BUY\", \"hash\":\"7986bd57d0304ecbc70a49ea73912e884c354217\", \"best_bid\":\"0.43\", \"best_ask\":\"0.44\"}, {\"asset_id\":\"20893381255801015515826997628594359667013752732428989472914000440642900266717\", \"price\":\"0.57\", \"size\":\"57\", \"side\":\"SELL\", \"hash\":\"49a66ea5c42d4817bbfc8ad2643e96586ee10707\", \"best_bid\":\"0.56\", \"best_ask\":\"0.57\"}], \"timestamp\":\"1785204532903\", \"event_type\":\"price_change\"}","received_at":"2026-07-28T02:08:53.557182Z","schema_version":"clob-market-ws.price_change.v1","sequence":null,"server_hash":null,"server_timestamp":"1785204532903","session_id":"d2757dd6dad94f3b9fe67e8dbf1adc37","source":"clob_market_ws"},"received_at":"2026-07-28T02:08:53.557182Z","record_id":"5295d5468dc85e60f034ac1f03147863e586e2b44fa3606ed75e5ca097a6ed81","schema_fingerprint":"4aa3821a28b0b7c2400bc59aba4bcc0a76e971dadd19610d3ad38c768e124dc7","schema_version":"edge-lab-recorder.raw.v1","sequence":null,"source":"clob_market_ws"}
{"event_at":"2026-07-28T02:08:52.905000Z","event_fingerprint":"1d72ce48b4361c93466f67156cbf98b1ee62787792cc119cff5347863bcabc0a","payload":{"connection_id":"5d29200f65794d4d9ab6ef271f045a9b","event_at":"2026-07-28T02:08:52.905000Z","event_type":"price_change","frame_hash":"5737d2a4e585fd16a170baaa2e96d8d25e24b342084269694dae7d1a68c122f2","frame_index":0,"kind":"data","monotonic_ns":306516568462416,"payload":{"event_type":"price_change","market":"0xda6f0e0e93fc8469e0159a166028d017bddbc162b86f66bac90391379603d962","price_changes":[{"asset_id":"20893381255801015515826997628594359667013752732428989472914000440642900266717","best_ask":"0.57","best_bid":"0.56","hash":"c14d6f0836a9ebb6d353a5932bf49278e8e4177b","price":"0.45","side":"BUY","size":"239.1"},{"asset_id":"39272994714739463168905443499424551362424437245880253267329605556587274644733","best_ask":"0.44","best_bid":"0.43","hash":"591f651261b12b4fa76b10eb31491a1aee82cd5e","price":"0.55","side":"SELL","size":"239.1"}],"timestamp":"1785204532905"},"payload_hash":"98256bebcf68c205ae304c3c5870119ff578f86b2db03ee5a5e270d8dd04577f","raw_frame":"{\"market\":\"0xda6f0e0e93fc8469e0159a166028d017bddbc162b86f66bac90391379603d962\", \"price_changes\":[{\"asset_id\":\"20893381255801015515826997628594359667013752732428989472914000440642900266717\", \"price\":\"0.45\", \"size\":\"239.1\", \"side\":\"BUY\", \"hash\":\"c14d6f0836a9ebb6d353a5932bf49278e8e4177b\", \"best_bid\":\"0.56\", \"best_ask\":\"0.57\"}, {\"asset_id\":\"39272994714739463168905443499424551362424437245880253267329605556587274644733\", \"price\":\"0.55\", \"size\":\"239.1\", \"side\":\"SELL\", \"hash\":\"591f651261b12b4fa76b10eb31491a1aee82cd5e\", \"best_bid\":\"0.43\", \"best_ask\":\"0.44\"}], \"timestamp\":\"1785204532905\", \"event_type\":\"price_change\"}","received_at":"2026-07-28T02:08:53.560125Z","schema_version":"clob-market-ws.price_change.v1","sequence":null,"server_hash":null,"server_timestamp":"1785204532905","session_id":"d2757dd6dad94f3b9fe67e8dbf1adc37","source":"clob_market_ws"},"received_at":"2026-07-28T02:08:53.560125Z","record_id":"6bd07a4a800b46c53cf6ff7854aed3770c3b5b7aba5c3a62203307581b5cdbe8","schema_fingerprint":"4aa3821a28b0b7c2400bc59aba4bcc0a76e971dadd19610d3ad38c768e124dc7","schema_version":"edge-lab-recorder.raw.v1","sequence":null,"source":"clob_market_ws"}
{"event_at":"2026-07-28T02:08:52.906000Z","event_fingerprint":"0791a902bd290fa17a90e9dc4b8834457402ee349c8390d3267dd50cf5fccf84","payload":{"connection_id":"5d29200f65794d4d9ab6ef271f045a9b","event_at":"2026-07-28T02:08:52.906000Z","event_type":"price_change","frame_hash":"1c317fe138a22406b2859ef2f0dd2f9f98dec09bc5440f9d23f797ac9bf5ff9d","frame_index":0,"kind":"data","monotonic_ns":306516571463875,"payload":{"event_type":"price_change","market":"0xda6f0e0e93fc8469e0159a166028d017bddbc162b86f66bac90391379603d962","price_changes":[{"asset_id":"39272994714739463168905443499424551362424437245880253267329605556587274644733","best_ask":"0.44","best_bid":"0.43","hash":"4274a7ec911a025ee971a328f0624bd809dcc527","price":"0.43","side":"BUY","size":"62"},{"asset_id":"20893381255801015515826997628594359667013752732428989472914000440642900266717","best_ask":"0.57","best_bid":"0.56","hash":"ad2ebf93f97f33c34cb9973f5a40ce994e84ddb6","price":"0.57","side":"SELL","size":"62"}],"timestamp":"1785204532906"},"payload_hash":"74ab9d2486df58c4ad5bbb486c38a7df5a98a2230389b8536bf771214057467c","raw_frame":"{\"market\":\"0xda6f0e0e93fc8469e0159a166028d017bddbc162b86f66bac90391379603d962\", \"price_changes\":[{\"asset_id\":\"39272994714739463168905443499424551362424437245880253267329605556587274644733\", \"price\":\"0.43\", \"size\":\"62\", \"side\":\"BUY\", \"hash\":\"4274a7ec911a025ee971a328f0624bd809dcc527\", \"best_bid\":\"0.43\", \"best_ask\":\"0.44\"}, {\"asset_id\":\"20893381255801015515826997628594359667013752732428989472914000440642900266717\", \"price\":\"0.57\", \"size\":\"62\", \"side\":\"SELL\", \"hash\":\"ad2ebf93f97f33c34cb9973f5a40ce994e84ddb6\", \"best_bid\":\"0.56\", \"best_ask\":\"0.57\"}], \"timestamp\":\"1785204532906\", \"event_type\":\"price_change\"}","received_at":"2026-07-28T02:08:53.563128Z","schema_version":"clob-market-ws.price_change.v1","sequence":null,"server_hash":null,"server_timestamp":"1785204532906","session_id":"d2757dd6dad94f3b9fe67e8dbf1adc37","source":"clob_market_ws"},"received_at":"2026-07-28T02:08:53.563128Z","record_id":"c988ee1cc2ee674a7de8f69fd7db4b3b692d84027684f9113cae9fa532c0a698","schema_fingerprint":"4aa3821a28b0b7c2400bc59aba4bcc0a76e971dadd19610d3ad38c768e124dc7","schema_version":"edge-lab-recorder.raw.v1","sequence":null,"source":"clob_market_ws"}
{"event_at":"2026-07-28T02:08:52.910000Z","event_fingerprint":"0eb03ff9e0e15a345b62ab8171f4880d8969d526caa8165155d2fc345fda0bbe","payload":{"connection_id":"5d29200f65794d4d9ab6ef271f045a9b","event_at":"2026-07-28T02:08:52.910000Z","event_type":"price_change","frame_hash":"1a81564e4f309852003b3ff5db0db61060787ebad0d515d231f384d6bba19fa1","frame_index":0,"kind":"data","monotonic_ns":306516574469666,"payload":{"event_type":"price_change","market":"0xda6f0e0e93fc8469e0159a166028d017bddbc162b86f66bac90391379603d962","price_changes":[{"asset_id":"20893381255801015515826997628594359667013752732428989472914000440642900266717","best_ask":"0.57","best_bid":"0.56","hash":"cd7340412b77a16f0bde43033da6cc6c92a2fe0b","price":"0.35","side":"BUY","size":"177.43"},{"asset_id":"39272994714739463168905443499424551362424437245880253267329605556587274644733","best_ask":"0.44","best_bid":"0.43","hash":"bd4ce2ad475c9bac45ed14c69449627b55a3628f","price":"0.65","side":"SELL","size":"177.43"}],"timestamp":"1785204532910"},"payload_hash":"edd2587c57290e81075286cd688c7dce2538e906d5970c0c56790979e008f2bd","raw_frame":"{\"market\":\"0xda6f0e0e93fc8469e0159a166028d017bddbc162b86f66bac90391379603d962\", \"price_changes\":[{\"asset_id\":\"20893381255801015515826997628594359667013752732428989472914000440642900266717\", \"price\":\"0.35\", \"size\":\"177.43\", \"side\":\"BUY\", \"hash\":\"cd7340412b77a16f0bde43033da6cc6c92a2fe0b\", \"best_bid\":\"0.56\", \"best_ask\":\"0.57\"}, {\"asset_id\":\"39272994714739463168905443499424551362424437245880253267329605556587274644733\", \"price\":\"0.65\", \"size\":\"177.43\", \"side\":\"SELL\", \"hash\":\"bd4ce2ad475c9bac45ed14c69449627b55a3628f\", \"best_bid\":\"0.43\", \"best_ask\":\"0.44\"}], \"timestamp\":\"1785204532910\", \"event_type\":\"price_change\"}","received_at":"2026-07-28T02:08:53.566133Z","schema_version":"clob-market-ws.price_change.v1","sequence":null,"server_hash":null,"server_timestamp":"1785204532910","session_id":"d2757dd6dad94f3b9fe67e8dbf1adc37","source":"clob_market_ws"},"received_at":"2026-07-28T02:08:53.566133Z","record_id":"05f89905ddecff1bf6ff1781f82f87a1f9115270ac62b46e939f722be6ae0675","schema_fingerprint":"4aa3821a28b0b7c2400bc59aba4bcc0a76e971dadd19610d3ad38c768e124dc7","schema_version":"edge-lab-recorder.raw.v1","sequence":null,"source":"clob_market_ws"}
