{"event_at":"2026-07-28T02:10:43.567000Z","event_fingerprint":"e1cd2e4782a5e04a9dc8dccb94d2ead3874b692a5e57df8c085e259d58e4c3ba","payload":{"connection_id":"5d29200f65794d4d9ab6ef271f045a9b","event_at":"2026-07-28T02:10:43.567000Z","event_type":"price_change","frame_hash":"7fa2f0e058dae8a8fb0a513e8131c19051716f6704027ef0db75b26b873b92fb","frame_index":0,"kind":"data","monotonic_ns":306632805803416,"payload":{"event_type":"price_change","market":"0xda6f0e0e93fc8469e0159a166028d017bddbc162b86f66bac90391379603d962","price_changes":[{"asset_id":"39272994714739463168905443499424551362424437245880253267329605556587274644733","best_ask":"0.24","best_bid":"0.23","hash":"bda92ae81df2531f28ab3b0203f7c4d7994c55e2","price":"0.21","side":"BUY","size":"75.2"},{"asset_id":"20893381255801015515826997628594359667013752732428989472914000440642900266717","best_ask":"0.77","best_bid":"0.76","hash":"1daf5deb5c928602ebed69e3db49e583525fc25f","price":"0.79","side":"SELL","size":"75.2"}],"timestamp":"1785204643567"},"payload_hash":"5ed47ef503076ab20fd559f5a1862da89c7d3d09ac3031f5ee44933992e37655","raw_frame":"{\"market\":\"0xda6f0e0e93fc8469e0159a166028d017bddbc162b86f66bac90391379603d962\", \"price_changes\":[{\"asset_id\":\"39272994714739463168905443499424551362424437245880253267329605556587274644733\", \"price\":\"0.21\", \"size\":\"75.2\", \"side\":\"BUY\", \"hash\":\"bda92ae81df2531f28ab3b0203f7c4d7994c55e2\", \"best_bid\":\"0.23\", \"best_ask\":\"0.24\"}, {\"asset_id\":\"20893381255801015515826997628594359667013752732428989472914000440642900266717\", \"price\":\"0.79\", \"size\":\"75.2\", \"side\":\"SELL\", \"hash\":\"1daf5deb5c928602ebed69e3db49e583525fc25f\", \"best_bid\":\"0.76\", \"best_ask\":\"0.77\"}], \"timestamp\":\"1785204643567\", \"event_type\":\"price_change\"}","received_at":"2026-07-28T02:10:49.796314Z","schema_version":"clob-market-ws.price_change.v1","sequence":null,"server_hash":null,"server_timestamp":"1785204643567","session_id":"d2757dd6dad94f3b9fe67e8dbf1adc37","source":"clob_market_ws"},"received_at":"2026-07-28T02:10:49.796314Z","record_id":"9e1fb7c88e7695e74759c2de917f89106893fb2f62958be5a10acfb3f4a1fb46","schema_fingerprint":"4aa3821a28b0b7c2400bc59aba4bcc0a76e971dadd19610d3ad38c768e124dc7","schema_version":"edge-lab-recorder.raw.v1","sequence":null,"source":"clob_market_ws"}
{"event_at":"2026-07-28T02:10:43.567000Z","event_fingerprint":"dbaa6e511dda548c2cd70b82f4a105619d3b414f5f4e5f41d6c600974ad27f86","payload":{"connection_id":"5d29200f65794d4d9ab6ef271f045a9b","event_at":"2026-07-28T02:10:43.567000Z","event_type":"price_change","frame_hash":"a480a41bb3faf3dfd2b8bd2ea93a534db357c0e4ca99c95a431274dc48875e9a","frame_index":0,"kind":"data","monotonic_ns":306632815732750,"payload":{"event_type":"price_change","market":"0xda6f0e0e93fc8469e0159a166028d017bddbc162b86f66bac90391379603d962","price_changes":[{"asset_id":"39272994714739463168905443499424551362424437245880253267329605556587274644733","best_ask":"0.24","best_bid":"0.23","hash":"868450d2272b37780e7ec36d31242ea049e311d5","price":"0.22","side":"BUY","size":"32.6"},{"asset_id":"20893381255801015515826997628594359667013752732428989472914000440642900266717","best_ask":"0.77","best_bid":"0.76","hash":"4d74b33b1e2ae6686e0763929c331e83bb331dce","price":"0.78","side":"SELL","size":"32.6"}],"timestamp":"1785204643567"},"payload_hash":"1a1d9dae195412b44f3a5fd7423dacf33c32aa88138fe4a06bb8348772d6e85b","raw_frame":"{\"market\":\"0xda6f0e0e93fc8469e0159a166028d017bddbc162b86f66bac90391379603d962\", \"price_changes\":[{\"asset_id\":\"39272994714739463168905443499424551362424437245880253267329605556587274644733\", \"price\":\"0.22\", \"size\":\"32.6\", \"side\":\"BUY\", \"hash\":\"868450d2272b37780e7ec36d31242ea049e311d5\", \"best_bid\":\"0.23\", \"best_ask\":\"0.24\"}, {\"asset_id\":\"20893381255801015515826997628594359667013752732428989472914000440642900266717\", \"price\":\"0.78\", \"size\":\"32.6\", \"side\":\"SELL\", \"hash\":\"4d74b33b1e2ae6686e0763929c331e83bb331dce\", \"best_bid\":\"0.76\", \"best_ask\":\"0.77\"}], \"timestamp\":\"1785204643567\", \"event_type\":\"price_change\"}","received_at":"2026-07-28T02:10:49.806245Z","schema_version":"clob-market-ws.price_change.v1","sequence":null,"server_hash":null,"server_timestamp":"1785204643567","session_id":"d2757dd6dad94f3b9fe67e8dbf1adc37","source":"clob_market_ws"},"received_at":"2026-07-28T02:10:49.806245Z","record_id":"edf1f90ad441b2ff2be6b08e254a3e9dcb656ee07a4a42a48858b5647f921811","schema_fingerprint":"4aa3821a28b0b7c2400bc59aba4bcc0a76e971dadd19610d3ad38c768e124dc7","schema_version":"edge-lab-recorder.raw.v1","sequence":null,"source":"clob_market_ws"}
{"event_at":"2026-07-28T02:10:43.570000Z","event_fingerprint":"0369e0d8489197e9a547da8d8cfa2d2053a6ca6ae715c2e61f91e04bfe758cbd","payload":{"connection_id":"5d29200f65794d4d9ab6ef271f045a9b","event_at":"2026-07-28T02:10:43.570000Z","event_type":"price_change","frame_hash":"b6bfb77c1cf05a8aa9e2efd283361402d3a37996753361c6d1102e2fb0c20a37","frame_index":0,"kind":"data","monotonic_ns":306632820078958,"payload":{"event_type":"price_change","market":"0xda6f0e0e93fc8469e0159a166028d017bddbc162b86f66bac90391379603d962","price_changes":[{"asset_id":"20893381255801015515826997628594359667013752732428989472914000440642900266717","best_ask":"0.77","best_bid":"0.76","hash":"0656acd445551c77d23511840d38d8a6f03acfd5","price":"0.75","side":"BUY","size":"35"},{"asset_id":"39272994714739463168905443499424551362424437245880253267329605556587274644733","best_ask":"0.24","best_bid":"0.23","hash":"6392c6cdb4e2d7a94085c4f5a9ee3e18a8f44ed3","price":"0.25","side":"SELL","size":"35"}],"timestamp":"1785204643570"},"payload_hash":"628e4ba33cb9f783ab864f23f48a9077e5fa9cac6cbab0fa81c85efadda6bff6","raw_frame":"{\"market\":\"0xda6f0e0e93fc8469e0159a166028d017bddbc162b86f66bac90391379603d962\", \"price_changes\":[{\"asset_id\":\"20893381255801015515826997628594359667013752732428989472914000440642900266717\", \"price\":\"0.75\", \"size\":\"35\", \"side\":\"BUY\", \"hash\":\"0656acd445551c77d23511840d38d8a6f03acfd5\", \"best_bid\":\"0.76\", \"best_ask\":\"0.77\"}, {\"asset_id\":\"39272994714739463168905443499424551362424437245880253267329605556587274644733\", \"price\":\"0.25\", \"size\":\"35\", \"side\":\"SELL\", \"hash\":\"6392c6cdb4e2d7a94085c4f5a9ee3e18a8f44ed3\", \"best_bid\":\"0.23\", \"best_ask\":\"0.24\"}], \"timestamp\":\"1785204643570\", \"event_type\":\"price_change\"}","received_at":"2026-07-28T02:10:49.810590Z","schema_version":"clob-market-ws.price_change.v1","sequence":null,"server_hash":null,"server_timestamp":"1785204643570","session_id":"d2757dd6dad94f3b9fe67e8dbf1adc37","source":"clob_market_ws"},"received_at":"2026-07-28T02:10:49.810590Z","record_id":"59a3e6c2bbb62190d75b13a23cd82fe76ba416b4f10f7de2df7db4a0d0e8580f","schema_fingerprint":"4aa3821a28b0b7c2400bc59aba4bcc0a76e971dadd19610d3ad38c768e124dc7","schema_version":"edge-lab-recorder.raw.v1","sequence":null,"source":"clob_market_ws"}
{"event_at":"2026-07-28T02:10:43.571000Z","event_fingerprint":"e3481b3b41ad1887b033b0ba4076a6330df76d8653203c1655cb88c9bd9b92c5","payload":{"connection_id":"5d29200f65794d4d9ab6ef271f045a9b","event_at":"2026-07-28T02:10:43.571000Z","event_type":"price_change","frame_hash":"0456ad7948468e5fd7e057230c7ba1d5af168ceecc25bae148665963c6771437","frame_index":0,"kind":"data","monotonic_ns":306632824657916,"payload":{"event_type":"price_change","market":"0xda6f0e0e93fc8469e0159a166028d017bddbc162b86f66bac90391379603d962","price_changes":[{"asset_id":"20893381255801015515826997628594359667013752732428989472914000440642900266717","best_ask":"0.77","best_bid":"0.76","hash":"41a85b532b11dfa139fe505b3ecf045d2f813d25","price":"0.76","side":"BUY","size":"41.6"},{"asset_id":"39272994714739463168905443499424551362424437245880253267329605556587274644733","best_ask":"0.24","best_bid":"0.23","hash":"75dccd0c5eedc78760c90a8c57fc9909f959caca","price":"0.24","side":"SELL","size":"41.6"}],"timestamp":"1785204643571"},"payload_hash":"c4ccc1f23c17d7b801f7f63b0210dbce46a8bd2bcfc8b08300f694612f9c8e47","raw_frame":"{\"market\":\"0xda6f0e0e93fc8469e0159a166028d017bddbc162b86f66bac90391379603d962\", \"price_changes\":[{\"asset_id\":\"20893381255801015515826997628594359667013752732428989472914000440642900266717\", \"price\":\"0.76\", \"size\":\"41.6\", \"side\":\"BUY\", \"hash\":\"41a85b532b11dfa139fe505b3ecf045d2f813d25\", \"best_bid\":\"0.76\", \"best_ask\":\"0.77\"}, {\"asset_id\":\"39272994714739463168905443499424551362424437245880253267329605556587274644733\", \"price\":\"0.24\", \"size\":\"41.6\", \"side\":\"SELL\", \"hash\":\"75dccd0c5eedc78760c90a8c57fc9909f959caca\", \"best_bid\":\"0.23\", \"best_ask\":\"0.24\"}], \"timestamp\":\"1785204643571\", \"event_type\":\"price_change\"}","received_at":"2026-07-28T02:10:49.815170Z","schema_version":"clob-market-ws.price_change.v1","sequence":null,"server_hash":null,"server_timestamp":"1785204643571","session_id":"d2757dd6dad94f3b9fe67e8dbf1adc37","source":"clob_market_ws"},"received_at":"2026-07-28T02:10:49.815170Z","record_id":"b200bf33bd4f17aacefb3fb6a3a769b639940debee7a2f1796f8dfc7f0a172db","schema_fingerprint":"4aa3821a28b0b7c2400bc59aba4bcc0a76e971dadd19610d3ad38c768e124dc7","schema_version":"edge-lab-recorder.raw.v1","sequence":null,"source":"clob_market_ws"}
{"event_at":"2026-07-28T02:10:43.572000Z","event_fingerprint":"47d2bd7cbb828572eb91c5677898c49f0455dc40e6d38b519373599d1c37f375","payload":{"connection_id":"5d29200f65794d4d9ab6ef271f045a9b","event_at":"2026-07-28T02:10:43.572000Z","event_type":"price_change","frame_hash":"dc24a5b13a1b5f338f14bc9f89a22627d8e01c0bb7f6315c5a2499d28163824a","frame_index":0,"kind":"data","monotonic_ns":306632828437625,"payload":{"event_type":"price_change","market":"0xda6f0e0e93fc8469e0159a166028d017bddbc162b86f66bac90391379603d962","price_changes":[{"asset_id":"20893381255801015515826997628594359667013752732428989472914000440642900266717","best_ask":"0.77","best_bid":"0.76","hash":"195052aee1b8e58697473caf7a26c11fc126239f","price":"0.75","side":"BUY","size":"47.6"},{"asset_id":"39272994714739463168905443499424551362424437245880253267329605556587274644733","best_ask":"0.24","best_bid":"0.23","hash":"f1d91e4f46866ec918b4e9b47fe5afea7d00e3d3","price":"0.25","side":"SELL","size":"47.6"}],"timestamp":"1785204643572"},"payload_hash":"d9a556da7f37937841e67fa855fbe2d57efb64c12f9da14420a8e55a8c9b5f73","raw_frame":"{\"market\":\"0xda6f0e0e93fc8469e0159a166028d017bddbc162b86f66bac90391379603d962\", \"price_changes\":[{\"asset_id\":\"20893381255801015515826997628594359667013752732428989472914000440642900266717\", \"price\":\"0.75\", \"size\":\"47.6\", \"side\":\"BUY\", \"hash\":\"195052aee1b8e58697473caf7a26c11fc126239f\", \"best_bid\":\"0.76\", \"best_ask\":\"0.77\"}, {\"asset_id\":\"39272994714739463168905443499424551362424437245880253267329605556587274644733\", \"price\":\"0.25\", \"size\":\"47.6\", \"side\":\"SELL\", \"hash\":\"f1d91e4f46866ec918b4e9b47fe5afea7d00e3d3\", \"best_bid\":\"0.23\", \"best_ask\":\"0.24\"}], \"timestamp\":\"1785204643572\", \"event_type\":\"price_change\"}","received_at":"2026-07-28T02:10:49.818948Z","schema_version":"clob-market-ws.price_change.v1","sequence":null,"server_hash":null,"server_timestamp":"1785204643572","session_id":"d2757dd6dad94f3b9fe67e8dbf1adc37","source":"clob_market_ws"},"received_at":"2026-07-28T02:10:49.818948Z","record_id":"da46faa4b1232b08b344100fbb0bec206a7307107ec1e3a66b47966d6f9bbecc","schema_fingerprint":"4aa3821a28b0b7c2400bc59aba4bcc0a76e971dadd19610d3ad38c768e124dc7","schema_version":"edge-lab-recorder.raw.v1","sequence":null,"source":"clob_market_ws"}
{"event_at":"2026-07-28T02:10:43.573000Z","event_fingerprint":"8e73f55f22b09a8853ccd8df0dc1e32973edf0d19bd791782e415bf9ca21db7a","payload":{"connection_id":"5d29200f65794d4d9ab6ef271f045a9b","event_at":"2026-07-28T02:10:43.573000Z","event_type":"price_change","frame_hash":"41bbfd9a196e7227235d70894898f3ed184212ef4116fc40d74dcc9de7bf8e47","frame_index":0,"kind":"data","monotonic_ns":306632833758958,"payload":{"event_type":"price_change","market":"0xda6f0e0e93fc8469e0159a166028d017bddbc162b86f66bac90391379603d962","price_changes":[{"asset_id":"39272994714739463168905443499424551362424437245880253267329605556587274644733","best_ask":"0.24","best_bid":"0.23","hash":"6f64c1df9d6b1e866793cecc9eefd46e35a29589","price":"0.22","side":"BUY","size":"45.2"},{"asset_id":"20893381255801015515826997628594359667013752732428989472914000440642900266717","best_ask":"0.77","best_bid":"0.76","hash":"5892f932b1e54086a0735fbd333151f3707b6204","price":"0.78","side":"SELL","size":"45.2"}],"timestamp":"1785204643573"},"payload_hash":"2673b9f5d8c7865123319beb4d71e56ceda267b0a8ca4484ebdabfa50f9daeba","raw_frame":"{\"market\":\"0xda6f0e0e93fc8469e0159a166028d017bddbc162b86f66bac90391379603d962\", \"price_changes\":[{\"asset_id\":\"39272994714739463168905443499424551362424437245880253267329605556587274644733\", \"price\":\"0.22\", \"size\":\"45.2\", \"side\":\"BUY\", \"hash\":\"6f64c1df9d6b1e866793cecc9eefd46e35a29589\", \"best_bid\":\"0.23\", \"best_ask\":\"0.24\"}, {\"asset_id\":\"20893381255801015515826997628594359667013752732428989472914000440642900266717\", \"price\":\"0.78\", \"size\":\"45.2\", \"side\":\"SELL\", \"hash\":\"5892f932b1e54086a0735fbd333151f3707b6204\", \"best_bid\":\"0.76\", \"best_ask\":\"0.77\"}], \"timestamp\":\"1785204643573\", \"event_type\":\"price_change\"}","received_at":"2026-07-28T02:10:49.824271Z","schema_version":"clob-market-ws.price_change.v1","sequence":null,"server_hash":null,"server_timestamp":"1785204643573","session_id":"d2757dd6dad94f3b9fe67e8dbf1adc37","source":"clob_market_ws"},"received_at":"2026-07-28T02:10:49.824271Z","record_id":"5aeb9ebe3a6b3f03221bc38a11b7c7bb390747214d08018d90a534ae6a49d5e9","schema_fingerprint":"4aa3821a28b0b7c2400bc59aba4bcc0a76e971dadd19610d3ad38c768e124dc7","schema_version":"edge-lab-recorder.raw.v1","sequence":null,"source":"clob_market_ws"}
{"event_at":"2026-07-28T02:10:43.576000Z","event_fingerprint":"85557b584a1dd5ae781da14549b217daac579650852d40bfa950c80cd0d9fd45","payload":{"connection_id":"5d29200f65794d4d9ab6ef271f045a9b","event_at":"2026-07-28T02:10:43.576000Z","event_type":"price_change","frame_hash":"38e24541d08bee7c1b5d209b4f32f9bb69484ca9623ad0280daed69279e045f9","frame_index":0,"kind":"data","monotonic_ns":306632837403000,"payload":{"event_type":"price_change","market":"0xda6f0e0e93fc8469e0159a166028d017bddbc162b86f66bac90391379603d962","price_changes":[{"asset_id":"20893381255801015515826997628594359667013752732428989472914000440642900266717","best_ask":"0.77","best_bid":"0.76","hash":"5b07bbff0b1837580f94a2fc340e33bd48073b99","price":"0.74","side":"BUY","size":"50"},{"asset_id":"39272994714739463168905443499424551362424437245880253267329605556587274644733","best_ask":"0.24","best_bid":"0.23","hash":"d22f3ec491a9c22f7d9697a027fc8756a1a38fe2","price":"0.26","side":"SELL","size":"50"}],"timestamp":"1785204643576"},"payload_hash":"8d51eacc3a71a693b58aff49aa0449a6845da7aad5f9983131ca9a13d83d80a9","raw_frame":"{\"market\":\"0xda6f0e0e93fc8469e0159a166028d017bddbc162b86f66bac90391379603d962\", \"price_changes\":[{\"asset_id\":\"20893381255801015515826997628594359667013752732428989472914000440642900266717\", \"price\":\"0.74\", \"size\":\"50\", \"side\":\"BUY\", \"hash\":\"5b07bbff0b1837580f94a2fc340e33bd48073b99\", \"best_bid\":\"0.76\", \"best_ask\":\"0.77\"}, {\"asset_id\":\"39272994714739463168905443499424551362424437245880253267329605556587274644733\", \"price\":\"0.26\", \"size\":\"50\", \"side\":\"SELL\", \"hash\":\"d22f3ec491a9c22f7d9697a027fc8756a1a38fe2\", \"best_bid\":\"0.23\", \"best_ask\":\"0.24\"}], \"timestamp\":\"1785204643576\", \"event_type\":\"price_change\"}","received_at":"2026-07-28T02:10:49.827914Z","schema_version":"clob-market-ws.price_change.v1","sequence":null,"server_hash":null,"server_timestamp":"1785204643576","session_id":"d2757dd6dad94f3b9fe67e8dbf1adc37","source":"clob_market_ws"},"received_at":"2026-07-28T02:10:49.827914Z","record_id":"8b062e77bf04e07e7508a3d0129cdf6dc9f021ffe073802a57fa35771d1822cf","schema_fingerprint":"4aa3821a28b0b7c2400bc59aba4bcc0a76e971dadd19610d3ad38c768e124dc7","schema_version":"edge-lab-recorder.raw.v1","sequence":null,"source":"clob_market_ws"}
{"event_at":"2026-07-28T02:10:43.577000Z","event_fingerprint":"abb0875c7f7b2446a1b381036ae3e80755d2e87547765f97ac6028aaf333df95","payload":{"connection_id":"5d29200f65794d4d9ab6ef271f045a9b","event_at":"2026-07-28T02:10:43.577000Z","event_type":"price_change","frame_hash":"1962678a6ce14b5a07f7d1ecb2016e1bc6ca2b1d722bb7c9ad80ec470a8bff2f","frame_index":0,"kind":"data","monotonic_ns":306632841193541,"payload":{"event_type":"price_change","market":"0xda6f0e0e93fc8469e0159a166028d017bddbc162b86f66bac90391379603d962","price_changes":[{"asset_id":"20893381255801015515826997628594359667013752732428989472914000440642900266717","best_ask":"0.77","best_bid":"0.76","hash":"7fff224b935b139a635825d2cf4bfef8c8a8f1b5","price":"0.75","side":"BUY","size":"62.6"},{"asset_id":"39272994714739463168905443499424551362424437245880253267329605556587274644733","best_ask":"0.24","best_bid":"0.23","hash":"9e0b8efba8838fda7be28dee94de20ff93b7190b","price":"0.25","side":"SELL","size":"62.6"}],"timestamp":"1785204643577"},"payload_hash":"0e4ba989152e5e78751b68228d6151496006550affcb3d2bf5368a054760d5a0","raw_frame":"{\"market\":\"0xda6f0e0e93fc8469e0159a166028d017bddbc162b86f66bac90391379603d962\", \"price_changes\":[{\"asset_id\":\"20893381255801015515826997628594359667013752732428989472914000440642900266717\", \"price\":\"0.75\", \"size\":\"62.6\", \"side\":\"BUY\", \"hash\":\"7fff224b935b139a635825d2cf4bfef8c8a8f1b5\", \"best_bid\":\"0.76\", \"best_ask\":\"0.77\"}, {\"asset_id\":\"39272994714739463168905443499424551362424437245880253267329605556587274644733\", \"price\":\"0.25\", \"size\":\"62.6\", \"side\":\"SELL\", \"hash\":\"9e0b8efba8838fda7be28dee94de20ff93b7190b\", \"best_bid\":\"0.23\", \"best_ask\":\"0.24\"}], \"timestamp\":\"1785204643577\", \"event_type\":\"price_change\"}","received_at":"2026-07-28T02:10:49.831701Z","schema_version":"clob-market-ws.price_change.v1","sequence":null,"server_hash":null,"server_timestamp":"1785204643577","session_id":"d2757dd6dad94f3b9fe67e8dbf1adc37","source":"clob_market_ws"},"received_at":"2026-07-28T02:10:49.831701Z","record_id":"316adc8b781ce6f92359cccbdf023b36992df6281fce445693cef76d2d3bd1a4","schema_fingerprint":"4aa3821a28b0b7c2400bc59aba4bcc0a76e971dadd19610d3ad38c768e124dc7","schema_version":"edge-lab-recorder.raw.v1","sequence":null,"source":"clob_market_ws"}
{"event_at":"2026-07-28T02:10:43.578000Z","event_fingerprint":"dec8336c50394e8039df05e8cb5dcdf25252ca83ab2560375aa92dd876e1d26b","payload":{"connection_id":"5d29200f65794d4d9ab6ef271f045a9b","event_at":"2026-07-28T02:10:43.578000Z","event_type":"price_change","frame_hash":"4634dda68a7f381c0f065de9c42be7d29e67b7bcc410b15203eaa7043abd8cfc","frame_index":0,"kind":"data","monotonic_ns":306632845074250,"payload":{"event_type":"price_change","market":"0xda6f0e0e93fc8469e0159a166028d017bddbc162b86f66bac90391379603d962","price_changes":[{"asset_id":"39272994714739463168905443499424551362424437245880253267329605556587274644733","best_ask":"0.24","best_bid":"0.23","hash":"6dc9d1a662c217f2dcf97ff02803ecc30cd29de2","price":"0.22","side":"BUY","size":"32.6"},{"asset_id":"20893381255801015515826997628594359667013752732428989472914000440642900266717","best_ask":"0.77","best_bid":"0.76","hash":"e581709bd5bafff480317610470a7e6e257d3db3","price":"0.78","side":"SELL","size":"32.6"}],"timestamp":"1785204643578"},"payload_hash":"e69296f706ecdb90d51fcea1238e7e1e6d8fad6feade9968f3199a96870b503a","raw_frame":"{\"market\":\"0xda6f0e0e93fc8469e0159a166028d017bddbc162b86f66bac90391379603d962\", \"price_changes\":[{\"asset_id\":\"39272994714739463168905443499424551362424437245880253267329605556587274644733\", \"price\":\"0.22\", \"size\":\"32.6\", \"side\":\"BUY\", \"hash\":\"6dc9d1a662c217f2dcf97ff02803ecc30cd29de2\", \"best_bid\":\"0.23\", \"best_ask\":\"0.24\"}, {\"asset_id\":\"20893381255801015515826997628594359667013752732428989472914000440642900266717\", \"price\":\"0.78\", \"size\":\"32.6\", \"side\":\"SELL\", \"hash\":\"e581709bd5bafff480317610470a7e6e257d3db3\", \"best_bid\":\"0.76\", \"best_ask\":\"0.77\"}], \"timestamp\":\"1785204643578\", \"event_type\":\"price_change\"}","received_at":"2026-07-28T02:10:49.835584Z","schema_version":"clob-market-ws.price_change.v1","sequence":null,"server_hash":null,"server_timestamp":"1785204643578","session_id":"d2757dd6dad94f3b9fe67e8dbf1adc37","source":"clob_market_ws"},"received_at":"2026-07-28T02:10:49.835584Z","record_id":"c0eb8b2e55c719792840603e4723c671a68b0943d089d785e236dd58afecbd27","schema_fingerprint":"4aa3821a28b0b7c2400bc59aba4bcc0a76e971dadd19610d3ad38c768e124dc7","schema_version":"edge-lab-recorder.raw.v1","sequence":null,"source":"clob_market_ws"}
{"event_at":"2026-07-28T02:10:43.581000Z","event_fingerprint":"ad59e0e35046d74cb81d052dd637179a0ed02077ab02d4fcca6fcc9eecd3828e","payload":{"connection_id":"5d29200f65794d4d9ab6ef271f045a9b","event_at":"2026-07-28T02:10:43.581000Z","event_type":"price_change","frame_hash":"ffde655fc7504d5d01fed9b6a31b4510163d64baae2f179fff6bae83f7fb350e","frame_index":0,"kind":"data","monotonic_ns":306632849320458,"payload":{"event_type":"price_change","market":"0xda6f0e0e93fc8469e0159a166028d017bddbc162b86f66bac90391379603d962","price_changes":[{"asset_id":"20893381255801015515826997628594359667013752732428989472914000440642900266717","best_ask":"0.77","best_bid":"0.76","hash":"7d81e8136217a7beb69486f9c6848df6ca39ffbf","price":"0.04","side":"BUY","size":"662.09"},{"asset_id":"39272994714739463168905443499424551362424437245880253267329605556587274644733","best_ask":"0.24","best_bid":"0.23","hash":"1cbe81630d718ae464a35415ed01ad4518b7c3c7","price":"0.96","side":"SELL","size":"662.09"}],"timestamp":"1785204643581"},"payload_hash":"8cf7f765723816a0fa9602fd01a379c55410bb01d82ca98c4a390341c679d905","raw_frame":"{\"market\":\"0xda6f0e0e93fc8469e0159a166028d017bddbc162b86f66bac90391379603d962\", \"price_changes\":[{\"asset_id\":\"20893381255801015515826997628594359667013752732428989472914000440642900266717\", \"price\":\"0.04\", \"size\":\"662.09\", \"side\":\"BUY\", \"hash\":\"7d81e8136217a7beb69486f9c6848df6ca39ffbf\", \"best_bid\":\"0.76\", \"best_ask\":\"0.77\"}, {\"asset_id\":\"39272994714739463168905443499424551362424437245880253267329605556587274644733\", \"price\":\"0.96\", \"size\":\"662.09\", \"side\":\"SELL\", \"hash\":\"1cbe81630d718ae464a35415ed01ad4518b7c3c7\", \"best_bid\":\"0.23\", \"best_ask\":\"0.24\"}], \"timestamp\":\"1785204643581\", \"event_type\":\"price_change\"}","received_at":"2026-07-28T02:10:49.839831Z","schema_version":"clob-market-ws.price_change.v1","sequence":null,"server_hash":null,"server_timestamp":"1785204643581","session_id":"d2757dd6dad94f3b9fe67e8dbf1adc37","source":"clob_market_ws"},"received_at":"2026-07-28T02:10:49.839831Z","record_id":"0a229420fbd119863f734a818b426d2db30c20c8e765978cb648d5c00fd8525d","schema_fingerprint":"4aa3821a28b0b7c2400bc59aba4bcc0a76e971dadd19610d3ad38c768e124dc7","schema_version":"edge-lab-recorder.raw.v1","sequence":null,"source":"clob_market_ws"}
{"event_at":"2026-07-28T02:10:43.593000Z","event_fingerprint":"554727acf1e7fe8d101975c169716a35b8fb174e797a496575046f98518337e5","payload":{"connection_id":"5d29200f65794d4d9ab6ef271f045a9b","event_at":"2026-07-28T02:10:43.593000Z","event_type":"price_change","frame_hash":"4cae3171eb678cef17c2de2d08b3559abb0427c25dd58cd95ac5f7a64c83c981","frame_index":0,"kind":"data","monotonic_ns":306632853679916,"payload":{"event_type":"price_change","market":"0xda6f0e0e93fc8469e0159a166028d017bddbc162b86f66bac90391379603d962","price_changes":[{"asset_id":"39272994714739463168905443499424551362424437245880253267329605556587274644733","best_ask":"0.24","best_bid":"0.23","hash":"d7978a3b1e465425955de171570946b7e17095dc","price":"0.22","side":"BUY","size":"20"},{"asset_id":"20893381255801015515826997628594359667013752732428989472914000440642900266717","best_ask":"0.77","best_bid":"0.76","hash":"cab35bb0254cb3ab38ab4994e6b29bf9b3ac12c0","price":"0.78","side":"SELL","size":"20"}],"timestamp":"1785204643593"},"payload_hash":"2e42914f1365a9aa5518c7e785f82e887f09908e459b7cd293cf32698e01a0e7","raw_frame":"{\"market\":\"0xda6f0e0e93fc8469e0159a166028d017bddbc162b86f66bac90391379603d962\", \"price_changes\":[{\"asset_id\":\"39272994714739463168905443499424551362424437245880253267329605556587274644733\", \"price\":\"0.22\", \"size\":\"20\", \"side\":\"BUY\", \"hash\":\"d7978a3b1e465425955de171570946b7e17095dc\", \"best_bid\":\"0.23\", \"best_ask\":\"0.24\"}, {\"asset_id\":\"20893381255801015515826997628594359667013752732428989472914000440642900266717\", \"price\":\"0.78\", \"size\":\"20\", \"side\":\"SELL\", \"hash\":\"cab35bb0254cb3ab38ab4994e6b29bf9b3ac12c0\", \"best_bid\":\"0.76\", \"best_ask\":\"0.77\"}], \"timestamp\":\"1785204643593\", \"event_type\":\"price_change\"}","received_at":"2026-07-28T02:10:49.844190Z","schema_version":"clob-market-ws.price_change.v1","sequence":null,"server_hash":null,"server_timestamp":"1785204643593","session_id":"d2757dd6dad94f3b9fe67e8dbf1adc37","source":"clob_market_ws"},"received_at":"2026-07-28T02:10:49.844190Z","record_id":"3adb464a24338aef42473ebcfeb5fe1efd7ec90c387ecfdd37c7f890fe456d9f","schema_fingerprint":"4aa3821a28b0b7c2400bc59aba4bcc0a76e971dadd19610d3ad38c768e124dc7","schema_version":"edge-lab-recorder.raw.v1","sequence":null,"source":"clob_market_ws"}
{"event_at":"2026-07-28T02:10:43.599000Z","event_fingerprint":"595fde6fba439ff19f704e16dafed9cb66f6afbfa66ea87d9d226477e14b28a9","payload":{"connection_id":"5d29200f65794d4d9ab6ef271f045a9b","event_at":"2026-07-28T02:10:43.599000Z","event_type":"price_change","frame_hash":"84e76160091ae641ecf515cc13ece72717aeb1f893e1fc4554e416ce20555ca8","frame_index":0,"kind":"data","monotonic_ns":306632858009875,"payload":{"event_type":"price_change","market":"0xda6f0e0e93fc8469e0159a166028d017bddbc162b86f66bac90391379603d962","price_changes":[{"asset_id":"20893381255801015515826997628594359667013752732428989472914000440642900266717","best_ask":"0.77","best_bid":"0.76","hash":"618c7444b6a4a43d069d753f0671e9860c8c3037","price":"0.71","side":"BUY","size":"74.07"},{"asset_id":"39272994714739463168905443499424551362424437245880253267329605556587274644733","best_ask":"0.24","best_bid":"0.23","hash":"e730327b06c123a467349a00d2738eb3306a85b4","price":"0.29","side":"SELL","size":"74.07"}],"timestamp":"1785204643599"},"payload_hash":"eed676d960c385ab20b2452d2c0946a3cc2dc2c4719325cddc8673ba490a0c57","raw_frame":"{\"market\":\"0xda6f0e0e93fc8469e0159a166028d017bddbc162b86f66bac90391379603d962\", \"price_changes\":[{\"asset_id\":\"20893381255801015515826997628594359667013752732428989472914000440642900266717\", \"price\":\"0.71\", \"size\":\"74.07\", \"side\":\"BUY\", \"hash\":\"618c7444b6a4a43d069d753f0671e9860c8c3037\", \"best_bid\":\"0.76\", \"best_ask\":\"0.77\"}, {\"asset_id\":\"39272994714739463168905443499424551362424437245880253267329605556587274644733\", \"price\":\"0.29\", \"size\":\"74.07\", \"side\":\"SELL\", \"hash\":\"e730327b06c123a467349a00d2738eb3306a85b4\", \"best_bid\":\"0.23\", \"best_ask\":\"0.24\"}], \"timestamp\":\"1785204643599\", \"event_type\":\"price_change\"}","received_at":"2026-07-28T02:10:49.848521Z","schema_version":"clob-market-ws.price_change.v1","sequence":null,"server_hash":null,"server_timestamp":"1785204643599","session_id":"d2757dd6dad94f3b9fe67e8dbf1adc37","source":"clob_market_ws"},"received_at":"2026-07-28T02:10:49.848521Z","record_id":"68db1eabfb8f4ce40623db95841fd3323435e890a9fa401ea0a10cb0ecd1e211","schema_fingerprint":"4aa3821a28b0b7c2400bc59aba4bcc0a76e971dadd19610d3ad38c768e124dc7","schema_version":"edge-lab-recorder.raw.v1","sequence":null,"source":"clob_market_ws"}
{"event_at":"2026-07-28T02:10:43.621000Z","event_fingerprint":"8cef4387f46c9ffbda75db484de859200f3227fb418f1c68f85087c913bf855b","payload":{"connection_id":"5d29200f65794d4d9ab6ef271f045a9b","event_at":"2026-07-28T02:10:43.621000Z","event_type":"price_change","frame_hash":"ed672497d55b44a3ee5555fc067abbb2cc3996a67ad369531a27fa7cca9ac629","frame_index":0,"kind":"data","monotonic_ns":306632862368458,"payload":{"event_type":"price_change","market":"0xda6f0e0e93fc8469e0159a166028d017bddbc162b86f66bac90391379603d962","price_changes":[{"asset_id":"39272994714739463168905443499424551362424437245880253267329605556587274644733","best_ask":"0.24","best_bid":"0.23","hash":"ef5e8fd60eded127ad4be47d0cdda3f26700bbd6","price":"0.22","side":"BUY","size":"15"},{"asset_id":"20893381255801015515826997628594359667013752732428989472914000440642900266717","best_ask":"0.77","best_bid":"0.76","hash":"4d50ff5e82b1dee10053b140f4ff4981b29cfb95","price":"0.78","side":"SELL","size":"15"}],"timestamp":"1785204643621"},"payload_hash":"bce470998c5e16e09bdd4499ae4cdedf50af14496d30173630934f74b8d8246f","raw_frame":"{\"market\":\"0xda6f0e0e93fc8469e0159a166028d017bddbc162b86f66bac90391379603d962\", \"price_changes\":[{\"asset_id\":\"39272994714739463168905443499424551362424437245880253267329605556587274644733\", \"price\":\"0.22\", \"size\":\"15\", \"side\":\"BUY\", \"hash\":\"ef5e8fd60eded127ad4be47d0cdda3f26700bbd6\", \"best_bid\":\"0.23\", \"best_ask\":\"0.24\"}, {\"asset_id\":\"20893381255801015515826997628594359667013752732428989472914000440642900266717\", \"price\":\"0.78\", \"size\":\"15\", \"side\":\"SELL\", \"hash\":\"4d50ff5e82b1dee10053b140f4ff4981b29cfb95\", \"best_bid\":\"0.76\", \"best_ask\":\"0.77\"}], \"timestamp\":\"1785204643621\", \"event_type\":\"price_change\"}","received_at":"2026-07-28T02:10:49.852879Z","schema_version":"clob-market-ws.price_change.v1","sequence":null,"server_hash":null,"server_timestamp":"1785204643621","session_id":"d2757dd6dad94f3b9fe67e8dbf1adc37","source":"clob_market_ws"},"received_at":"2026-07-28T02:10:49.852879Z","record_id":"b9468f1f9fe83ebe2e0d0a5809ada0bd669cf4cdff07aba73b7528aadda1dc44","schema_fingerprint":"4aa3821a28b0b7c2400bc59aba4bcc0a76e971dadd19610d3ad38c768e124dc7","schema_version":"edge-lab-recorder.raw.v1","sequence":null,"source":"clob_market_ws"}
{"event_at":"2026-07-28T02:10:43.621000Z","event_fingerprint":"53809a4f9704b7e345b8ec57801c24bf528488816999ff523a238f8fd7662f6e","payload":{"connection_id":"5d29200f65794d4d9ab6ef271f045a9b","event_at":"2026-07-28T02:10:43.621000Z","event_type":"price_change","frame_hash":"ebaa2464361d4a94a973a289feaa4eb33e843acd21d244af768fa1fe8e5e5919","frame_index":0,"kind":"data","monotonic_ns":306632866683500,"payload":{"event_type":"price_change","market":"0xda6f0e0e93fc8469e0159a166028d017bddbc162b86f66bac90391379603d962","price_changes":[{"asset_id":"39272994714739463168905443499424551362424437245880253267329605556587274644733","best_ask":"0.24","best_bid":"0.23","hash":"ef5e8fd60eded127ad4be47d0cdda3f26700bbd6","price":"0.23","side":"BUY","size":"36"},{"asset_id":"20893381255801015515826997628594359667013752732428989472914000440642900266717","best_ask":"0.77","best_bid":"0.76","hash":"4d50ff5e82b1dee10053b140f4ff4981b29cfb95","price":"0.77","side":"SELL","size":"36"}],"timestamp":"1785204643621"},"payload_hash":"6ad559c4be66bb6537b7340b65480906d1720cd1bd09e67b44a8c7eaa9b70790","raw_frame":"{\"market\":\"0xda6f0e0e93fc8469e0159a166028d017bddbc162b86f66bac90391379603d962\", \"price_changes\":[{\"asset_id\":\"39272994714739463168905443499424551362424437245880253267329605556587274644733\", \"price\":\"0.23\", \"size\":\"36\", \"side\":\"BUY\", \"hash\":\"ef5e8fd60eded127ad4be47d0cdda3f26700bbd6\", \"best_bid\":\"0.23\", \"best_ask\":\"0.24\"}, {\"asset_id\":\"20893381255801015515826997628594359667013752732428989472914000440642900266717\", \"price\":\"0.77\", \"size\":\"36\", \"side\":\"SELL\", \"hash\":\"4d50ff5e82b1dee10053b140f4ff4981b29cfb95\", \"best_bid\":\"0.76\", \"best_ask\":\"0.77\"}], \"timestamp\":\"1785204643621\", \"event_type\":\"price_change\"}","received_at":"2026-07-28T02:10:49.857194Z","schema_version":"clob-market-ws.price_change.v1","sequence":null,"server_hash":null,"server_timestamp":"1785204643621","session_id":"d2757dd6dad94f3b9fe67e8dbf1adc37","source":"clob_market_ws"},"received_at":"2026-07-28T02:10:49.857194Z","record_id":"b395a2829c07f439514950dfd493a5451eda1a6477a57eac37b70638f60a436a","schema_fingerprint":"4aa3821a28b0b7c2400bc59aba4bcc0a76e971dadd19610d3ad38c768e124dc7","schema_version":"edge-lab-recorder.raw.v1","sequence":null,"source":"clob_market_ws"}
{"event_at":"2026-07-28T02:10:43.622000Z","event_fingerprint":"e955455160b843d40335603377dffd2ff5d1b02a1386fe3dee93d5075be10d72","payload":{"connection_id":"5d29200f65794d4d9ab6ef271f045a9b","event_at":"2026-07-28T02:10:43.622000Z","event_type":"price_change","frame_hash":"db3cb45b084f04f82b2df5c4d478f2f147d84be72e203643a2f46975956f88d0","frame_index":0,"kind":"data","monotonic_ns":306632870646250,"payload":{"event_type":"price_change","market":"0xda6f0e0e93fc8469e0159a166028d017bddbc162b86f66bac90391379603d962","price_changes":[{"asset_id":"39272994714739463168905443499424551362424437245880253267329605556587274644733","best_ask":"0.24","best_bid":"0.23","hash":"22bb82d3893d8101846cd46ef5da74a6f191d2ec","price":"0.22","side":"BUY","size":"10"},{"asset_id":"20893381255801015515826997628594359667013752732428989472914000440642900266717","best_ask":"0.77","best_bid":"0.76","hash":"a92d403aef78d7197669b4a05868c5562a19bf8e","price":"0.78","side":"SELL","size":"10"}],"timestamp":"1785204643622"},"payload_hash":"3c07ece5ddf2b952dc857e7a91b9994673072f75f722b6b5c7b2a0b754802b62","raw_frame":"{\"market\":\"0xda6f0e0e93fc8469e0159a166028d017bddbc162b86f66bac90391379603d962\", \"price_changes\":[{\"asset_id\":\"39272994714739463168905443499424551362424437245880253267329605556587274644733\", \"price\":\"0.22\", \"size\":\"10\", \"side\":\"BUY\", \"hash\":\"22bb82d3893d8101846cd46ef5da74a6f191d2ec\", \"best_bid\":\"0.23\", \"best_ask\":\"0.24\"}, {\"asset_id\":\"20893381255801015515826997628594359667013752732428989472914000440642900266717\", \"price\":\"0.78\", \"size\":\"10\", \"side\":\"SELL\", \"hash\":\"a92d403aef78d7197669b4a05868c5562a19bf8e\", \"best_bid\":\"0.76\", \"best_ask\":\"0.77\"}], \"timestamp\":\"1785204643622\", \"event_type\":\"price_change\"}","received_at":"2026-07-28T02:10:49.861157Z","schema_version":"clob-market-ws.price_change.v1","sequence":null,"server_hash":null,"server_timestamp":"1785204643622","session_id":"d2757dd6dad94f3b9fe67e8dbf1adc37","source":"clob_market_ws"},"received_at":"2026-07-28T02:10:49.861157Z","record_id":"385ccfdfe1d0ba12d4b607a122de95ef106302b0241bfd6c2924d07ef1123939","schema_fingerprint":"4aa3821a28b0b7c2400bc59aba4bcc0a76e971dadd19610d3ad38c768e124dc7","schema_version":"edge-lab-recorder.raw.v1","sequence":null,"source":"clob_market_ws"}
{"event_at":"2026-07-28T02:10:43.622000Z","event_fingerprint":"f42da1b348a96f434ae01ab367ecf672f21da975f3ddb9ce7131f7e7f38ef2f3","payload":{"connection_id":"5d29200f65794d4d9ab6ef271f045a9b","event_at":"2026-07-28T02:10:43.622000Z","event_type":"price_change","frame_hash":"56f880ec6f75b759f552eb7b435a0e91e9d536881ab212827534836e72832c36","frame_index":0,"kind":"data","monotonic_ns":306632874998541,"payload":{"event_type":"price_change","market":"0xda6f0e0e93fc8469e0159a166028d017bddbc162b86f66bac90391379603d962","price_changes":[{"asset_id":"39272994714739463168905443499424551362424437245880253267329605556587274644733","best_ask":"0.24","best_bid":"0.23","hash":"22bb82d3893d8101846cd46ef5da74a6f191d2ec","price":"0.23","side":"BUY","size":"31"},{"asset_id":"20893381255801015515826997628594359667013752732428989472914000440642900266717","best_ask":"0.77","best_bid":"0.76","hash":"a92d403aef78d7197669b4a05868c5562a19bf8e","price":"0.77","side":"SELL","size":"31"}],"timestamp":"1785204643622"},"payload_hash":"5d546278d6a0dac56ea31bb4d8f5985004c2598fc2fd165d248628dbd7dda7ab","raw_frame":"{\"market\":\"0xda6f0e0e93fc8469e0159a166028d017bddbc162b86f66bac90391379603d962\", \"price_changes\":[{\"asset_id\":\"39272994714739463168905443499424551362424437245880253267329605556587274644733\", \"price\":\"0.23\", \"size\":\"31\", \"side\":\"BUY\", \"hash\":\"22bb82d3893d8101846cd46ef5da74a6f191d2ec\", \"best_bid\":\"0.23\", \"best_ask\":\"0.24\"}, {\"asset_id\":\"20893381255801015515826997628594359667013752732428989472914000440642900266717\", \"price\":\"0.77\", \"size\":\"31\", \"side\":\"SELL\", \"hash\":\"a92d403aef78d7197669b4a05868c5562a19bf8e\", \"best_bid\":\"0.76\", \"best_ask\":\"0.77\"}], \"timestamp\":\"1785204643622\", \"event_type\":\"price_change\"}","received_at":"2026-07-28T02:10:49.865509Z","schema_version":"clob-market-ws.price_change.v1","sequence":null,"server_hash":null,"server_timestamp":"1785204643622","session_id":"d2757dd6dad94f3b9fe67e8dbf1adc37","source":"clob_market_ws"},"received_at":"2026-07-28T02:10:49.865509Z","record_id":"f5b05a2f29329e27a128cec69c9e24fdd134d4021e2be81a0f03bcbb2cfaf24a","schema_fingerprint":"4aa3821a28b0b7c2400bc59aba4bcc0a76e971dadd19610d3ad38c768e124dc7","schema_version":"edge-lab-recorder.raw.v1","sequence":null,"source":"clob_market_ws"}
{"event_at":"2026-07-28T02:10:43.622000Z","event_fingerprint":"7dfaf7c8cc0c4310c758a20b6701cca9548ca45884fb115f456fb0a9581b1d1d","payload":{"connection_id":"5d29200f65794d4d9ab6ef271f045a9b","event_at":"2026-07-28T02:10:43.622000Z","event_type":"price_change","frame_hash":"1cbaa8c3f6b30ede381297514fa17497eccaeece9052478a6da3404566086557","frame_index":0,"kind":"data","monotonic_ns":306632877842458,"payload":{"event_type":"price_change","market":"0xda6f0e0e93fc8469e0159a166028d017bddbc162b86f66bac90391379603d962","price_changes":[{"asset_id":"39272994714739463168905443499424551362424437245880253267329605556587274644733","best_ask":"0.24","best_bid":"0.23","hash":"88d25910d5f3bfdfab16477164a2c28931293ae7","price":"0.21","side":"BUY","size":"100.2"},{"asset_id":"20893381255801015515826997628594359667013752732428989472914000440642900266717","best_ask":"0.77","best_bid":"0.76","hash":"66f9bdd7706aef99869999c07139751488eaff84","price":"0.79","side":"SELL","size":"100.2"}],"timestamp":"1785204643622"},"payload_hash":"d954310fd0ac47118b9d9a862ec169c5be0ff1b9acce2a3f6a47b8f7b00d459d","raw_frame":"{\"market\":\"0xda6f0e0e93fc8469e0159a166028d017bddbc162b86f66bac90391379603d962\", \"price_changes\":[{\"asset_id\":\"39272994714739463168905443499424551362424437245880253267329605556587274644733\", \"price\":\"0.21\", \"size\":\"100.2\", \"side\":\"BUY\", \"hash\":\"88d25910d5f3bfdfab16477164a2c28931293ae7\", \"best_bid\":\"0.23\", \"best_ask\":\"0.24\"}, {\"asset_id\":\"20893381255801015515826997628594359667013752732428989472914000440642900266717\", \"price\":\"0.79\", \"size\":\"100.2\", \"side\":\"SELL\", \"hash\":\"66f9bdd7706aef99869999c07139751488eaff84\", \"best_bid\":\"0.76\", \"best_ask\":\"0.77\"}], \"timestamp\":\"1785204643622\", \"event_type\":\"price_change\"}","received_at":"2026-07-28T02:10:49.868353Z","schema_version":"clob-market-ws.price_change.v1","sequence":null,"server_hash":null,"server_timestamp":"1785204643622","session_id":"d2757dd6dad94f3b9fe67e8dbf1adc37","source":"clob_market_ws"},"received_at":"2026-07-28T02:10:49.868353Z","record_id":"eb81645ef17105f5f30688e50f3bb00c4ba94dbd89f6c781229cfb63e7ab073d","schema_fingerprint":"4aa3821a28b0b7c2400bc59aba4bcc0a76e971dadd19610d3ad38c768e124dc7","schema_version":"edge-lab-recorder.raw.v1","sequence":null,"source":"clob_market_ws"}
