{"event_at":"2026-07-28T02:02:13.942000Z","event_fingerprint":"0ae0da778e0601a7678c6140e7c9175fb155fecb60f23b6502bfbd32dbb4d9d8","payload":{"connection_id":"5d29200f65794d4d9ab6ef271f045a9b","event_at":"2026-07-28T02:02:13.942000Z","event_type":"price_change","frame_hash":"821d434c7c8329f663d91fa821b81b42e6d2103888fec50c361154372fa1181d","frame_index":0,"kind":"data","monotonic_ns":306118336791125,"payload":{"event_type":"price_change","market":"0xda6f0e0e93fc8469e0159a166028d017bddbc162b86f66bac90391379603d962","price_changes":[{"asset_id":"39272994714739463168905443499424551362424437245880253267329605556587274644733","best_ask":"0.58","best_bid":"0.57","hash":"42a828ba132a7101012cfa44cb7d71254d379e70","price":"0.02","side":"BUY","size":"733.1"},{"asset_id":"20893381255801015515826997628594359667013752732428989472914000440642900266717","best_ask":"0.43","best_bid":"0.42","hash":"6abc66fa348c8d779770700f4ec0db555fcf1228","price":"0.98","side":"SELL","size":"733.1"}],"timestamp":"1785204133942"},"payload_hash":"569279133d641d04c1fa171c5414d870687f19260bd07f1e62f1cf5c14f94b18","raw_frame":"{\"market\":\"0xda6f0e0e93fc8469e0159a166028d017bddbc162b86f66bac90391379603d962\", \"price_changes\":[{\"asset_id\":\"39272994714739463168905443499424551362424437245880253267329605556587274644733\", \"price\":\"0.02\", \"size\":\"733.1\", \"side\":\"BUY\", \"hash\":\"42a828ba132a7101012cfa44cb7d71254d379e70\", \"best_bid\":\"0.57\", \"best_ask\":\"0.58\"}, {\"asset_id\":\"20893381255801015515826997628594359667013752732428989472914000440642900266717\", \"price\":\"0.98\", \"size\":\"733.1\", \"side\":\"SELL\", \"hash\":\"6abc66fa348c8d779770700f4ec0db555fcf1228\", \"best_bid\":\"0.42\", \"best_ask\":\"0.43\"}], \"timestamp\":\"1785204133942\", \"event_type\":\"price_change\"}","received_at":"2026-07-28T02:02:15.332400Z","schema_version":"clob-market-ws.price_change.v1","sequence":null,"server_hash":null,"server_timestamp":"1785204133942","session_id":"d2757dd6dad94f3b9fe67e8dbf1adc37","source":"clob_market_ws"},"received_at":"2026-07-28T02:02:15.332400Z","record_id":"ed00bea7794c33beda1746d5c4377c958206884ecd33abd9904f41ed53acadf4","schema_fingerprint":"4aa3821a28b0b7c2400bc59aba4bcc0a76e971dadd19610d3ad38c768e124dc7","schema_version":"edge-lab-recorder.raw.v1","sequence":null,"source":"clob_market_ws"}
{"event_at":"2026-07-28T02:02:14.019000Z","event_fingerprint":"9da8139ebbf6a6af006caee2124e40125c5d8a74fc514c003ba34cc02279d513","payload":{"connection_id":"5d29200f65794d4d9ab6ef271f045a9b","event_at":"2026-07-28T02:02:14.019000Z","event_type":"price_change","frame_hash":"5d625b52b965240f7ce8be0d638fb520ffcddc990b93025efea4625579d68097","frame_index":0,"kind":"data","monotonic_ns":306118348178125,"payload":{"event_type":"price_change","market":"0xda6f0e0e93fc8469e0159a166028d017bddbc162b86f66bac90391379603d962","price_changes":[{"asset_id":"20893381255801015515826997628594359667013752732428989472914000440642900266717","best_ask":"0.43","best_bid":"0.42","hash":"697113b65064293345bb0bff6311c25539980953","price":"0.01","side":"BUY","size":"7888.02"},{"asset_id":"39272994714739463168905443499424551362424437245880253267329605556587274644733","best_ask":"0.58","best_bid":"0.57","hash":"47e497fe89a7fa91ce96315d020ae5a90b144b9d","price":"0.99","side":"SELL","size":"7888.02"}],"timestamp":"1785204134019"},"payload_hash":"d5b7163508f612165a9ce692ff38f7370dae4d73b2b7e7f11367b7761a9e8caf","raw_frame":"{\"market\":\"0xda6f0e0e93fc8469e0159a166028d017bddbc162b86f66bac90391379603d962\", \"price_changes\":[{\"asset_id\":\"20893381255801015515826997628594359667013752732428989472914000440642900266717\", \"price\":\"0.01\", \"size\":\"7888.02\", \"side\":\"BUY\", \"hash\":\"697113b65064293345bb0bff6311c25539980953\", \"best_bid\":\"0.42\", \"best_ask\":\"0.43\"}, {\"asset_id\":\"39272994714739463168905443499424551362424437245880253267329605556587274644733\", \"price\":\"0.99\", \"size\":\"7888.02\", \"side\":\"SELL\", \"hash\":\"47e497fe89a7fa91ce96315d020ae5a90b144b9d\", \"best_bid\":\"0.57\", \"best_ask\":\"0.58\"}], \"timestamp\":\"1785204134019\", \"event_type\":\"price_change\"}","received_at":"2026-07-28T02:02:15.343789Z","schema_version":"clob-market-ws.price_change.v1","sequence":null,"server_hash":null,"server_timestamp":"1785204134019","session_id":"d2757dd6dad94f3b9fe67e8dbf1adc37","source":"clob_market_ws"},"received_at":"2026-07-28T02:02:15.343789Z","record_id":"ab7aaefe1e4590fb014ea1ea71baf25181a07e28eb723a88e11d1154e7b14964","schema_fingerprint":"4aa3821a28b0b7c2400bc59aba4bcc0a76e971dadd19610d3ad38c768e124dc7","schema_version":"edge-lab-recorder.raw.v1","sequence":null,"source":"clob_market_ws"}
{"event_at":"2026-07-28T02:02:14.029000Z","event_fingerprint":"0119fb10d5858ccae14b554b99d666239f5654a512a4922141e40eb25a54d577","payload":{"connection_id":"5d29200f65794d4d9ab6ef271f045a9b","event_at":"2026-07-28T02:02:14.029000Z","event_type":"price_change","frame_hash":"4d868062b31c0c3e95f2c62a5a7129a35ecba909b527d3dbc92616ea3c087552","frame_index":0,"kind":"data","monotonic_ns":306118353089583,"payload":{"event_type":"price_change","market":"0xda6f0e0e93fc8469e0159a166028d017bddbc162b86f66bac90391379603d962","price_changes":[{"asset_id":"20893381255801015515826997628594359667013752732428989472914000440642900266717","best_ask":"0.43","best_bid":"0.42","hash":"b03ee7209e00e62d835de42ad9b969acabb85be6","price":"0.01","side":"BUY","size":"7893.02"},{"asset_id":"39272994714739463168905443499424551362424437245880253267329605556587274644733","best_ask":"0.58","best_bid":"0.57","hash":"184633d8f136015a357da8648c3c01c258010de8","price":"0.99","side":"SELL","size":"7893.02"}],"timestamp":"1785204134029"},"payload_hash":"bbe7b0d934960317d4b222c650dd0d3f5be48a9ea14b647b9119c87bd2c9870e","raw_frame":"{\"market\":\"0xda6f0e0e93fc8469e0159a166028d017bddbc162b86f66bac90391379603d962\", \"price_changes\":[{\"asset_id\":\"20893381255801015515826997628594359667013752732428989472914000440642900266717\", \"price\":\"0.01\", \"size\":\"7893.02\", \"side\":\"BUY\", \"hash\":\"b03ee7209e00e62d835de42ad9b969acabb85be6\", \"best_bid\":\"0.42\", \"best_ask\":\"0.43\"}, {\"asset_id\":\"39272994714739463168905443499424551362424437245880253267329605556587274644733\", \"price\":\"0.99\", \"size\":\"7893.02\", \"side\":\"SELL\", \"hash\":\"184633d8f136015a357da8648c3c01c258010de8\", \"best_bid\":\"0.57\", \"best_ask\":\"0.58\"}], \"timestamp\":\"1785204134029\", \"event_type\":\"price_change\"}","received_at":"2026-07-28T02:02:15.348699Z","schema_version":"clob-market-ws.price_change.v1","sequence":null,"server_hash":null,"server_timestamp":"1785204134029","session_id":"d2757dd6dad94f3b9fe67e8dbf1adc37","source":"clob_market_ws"},"received_at":"2026-07-28T02:02:15.348699Z","record_id":"47158bbec5d23f408666f91ec8096cdd747ffe69bb9d262add6ec33c000150a1","schema_fingerprint":"4aa3821a28b0b7c2400bc59aba4bcc0a76e971dadd19610d3ad38c768e124dc7","schema_version":"edge-lab-recorder.raw.v1","sequence":null,"source":"clob_market_ws"}
{"event_at":"2026-07-28T02:02:14.042000Z","event_fingerprint":"26545d9a18359581cbc224ce1b0dc83f73cb05cb176620f75fafa83a2b8f9ddd","payload":{"connection_id":"5d29200f65794d4d9ab6ef271f045a9b","event_at":"2026-07-28T02:02:14.042000Z","event_type":"price_change","frame_hash":"3d97cceaaafeeda4d00d282bd01a894bc40778eb02c9d2db1b051704d7a90689","frame_index":0,"kind":"data","monotonic_ns":306118358268208,"payload":{"event_type":"price_change","market":"0xda6f0e0e93fc8469e0159a166028d017bddbc162b86f66bac90391379603d962","price_changes":[{"asset_id":"39272994714739463168905443499424551362424437245880253267329605556587274644733","best_ask":"0.58","best_bid":"0.57","hash":"9a6ad3faa1759f46d03be41ee6f0f13d1eed19a0","price":"0.02","side":"BUY","size":"738.1"},{"asset_id":"20893381255801015515826997628594359667013752732428989472914000440642900266717","best_ask":"0.43","best_bid":"0.42","hash":"f0ced43734eb61ff9ec72b9dcc0495d65a7a78ea","price":"0.98","side":"SELL","size":"738.1"}],"timestamp":"1785204134042"},"payload_hash":"3d1a2de6c1ed791028f83bfa02f9f3d889ae677f931b8a0afbc8ff7d15cef44f","raw_frame":"{\"market\":\"0xda6f0e0e93fc8469e0159a166028d017bddbc162b86f66bac90391379603d962\", \"price_changes\":[{\"asset_id\":\"39272994714739463168905443499424551362424437245880253267329605556587274644733\", \"price\":\"0.02\", \"size\":\"738.1\", \"side\":\"BUY\", \"hash\":\"9a6ad3faa1759f46d03be41ee6f0f13d1eed19a0\", \"best_bid\":\"0.57\", \"best_ask\":\"0.58\"}, {\"asset_id\":\"20893381255801015515826997628594359667013752732428989472914000440642900266717\", \"price\":\"0.98\", \"size\":\"738.1\", \"side\":\"SELL\", \"hash\":\"f0ced43734eb61ff9ec72b9dcc0495d65a7a78ea\", \"best_bid\":\"0.42\", \"best_ask\":\"0.43\"}], \"timestamp\":\"1785204134042\", \"event_type\":\"price_change\"}","received_at":"2026-07-28T02:02:15.353878Z","schema_version":"clob-market-ws.price_change.v1","sequence":null,"server_hash":null,"server_timestamp":"1785204134042","session_id":"d2757dd6dad94f3b9fe67e8dbf1adc37","source":"clob_market_ws"},"received_at":"2026-07-28T02:02:15.353878Z","record_id":"9fb9e3b46e9ebd7e3119b9f7c91a09418d213c91988b7412e9648f13d8b95721","schema_fingerprint":"4aa3821a28b0b7c2400bc59aba4bcc0a76e971dadd19610d3ad38c768e124dc7","schema_version":"edge-lab-recorder.raw.v1","sequence":null,"source":"clob_market_ws"}
{"event_at":"2026-07-28T02:02:14.055000Z","event_fingerprint":"48b3af9514a7d3f4609ac7acf00d2f0441c5eb13a315b5f15c27e04e1e9ac984","payload":{"connection_id":"5d29200f65794d4d9ab6ef271f045a9b","event_at":"2026-07-28T02:02:14.055000Z","event_type":"price_change","frame_hash":"f9701af4f90faa6cd2536b277e787ef6d161a505b7b2d1679fa15d0a35aa5f56","frame_index":0,"kind":"data","monotonic_ns":306118368156833,"payload":{"event_type":"price_change","market":"0xda6f0e0e93fc8469e0159a166028d017bddbc162b86f66bac90391379603d962","price_changes":[{"asset_id":"20893381255801015515826997628594359667013752732428989472914000440642900266717","best_ask":"0.43","best_bid":"0.42","hash":"4daf6eabe0f57bf5f592b31d4064f479f5340458","price":"0.01","side":"BUY","size":"7888.02"},{"asset_id":"39272994714739463168905443499424551362424437245880253267329605556587274644733","best_ask":"0.58","best_bid":"0.57","hash":"d64075aecf5cb8d7c28ffc0ed47750dc179971b7","price":"0.99","side":"SELL","size":"7888.02"}],"timestamp":"1785204134055"},"payload_hash":"10775c3923fea2bd0575f3f5999de71a21fccefa035b3ad1ba8c13c78b6b5762","raw_frame":"{\"market\":\"0xda6f0e0e93fc8469e0159a166028d017bddbc162b86f66bac90391379603d962\", \"price_changes\":[{\"asset_id\":\"20893381255801015515826997628594359667013752732428989472914000440642900266717\", \"price\":\"0.01\", \"size\":\"7888.02\", \"side\":\"BUY\", \"hash\":\"4daf6eabe0f57bf5f592b31d4064f479f5340458\", \"best_bid\":\"0.42\", \"best_ask\":\"0.43\"}, {\"asset_id\":\"39272994714739463168905443499424551362424437245880253267329605556587274644733\", \"price\":\"0.99\", \"size\":\"7888.02\", \"side\":\"SELL\", \"hash\":\"d64075aecf5cb8d7c28ffc0ed47750dc179971b7\", \"best_bid\":\"0.57\", \"best_ask\":\"0.58\"}], \"timestamp\":\"1785204134055\", \"event_type\":\"price_change\"}","received_at":"2026-07-28T02:02:15.363765Z","schema_version":"clob-market-ws.price_change.v1","sequence":null,"server_hash":null,"server_timestamp":"1785204134055","session_id":"d2757dd6dad94f3b9fe67e8dbf1adc37","source":"clob_market_ws"},"received_at":"2026-07-28T02:02:15.363765Z","record_id":"9ee41b567b312f7413360798bed0ae4c94504c4f9fe22fddcf43603b6dca62d9","schema_fingerprint":"4aa3821a28b0b7c2400bc59aba4bcc0a76e971dadd19610d3ad38c768e124dc7","schema_version":"edge-lab-recorder.raw.v1","sequence":null,"source":"clob_market_ws"}
{"event_at":"2026-07-28T02:02:14.058000Z","event_fingerprint":"03354eeec821daa8ce5d2e5e9205bb82ebad9f418e83376e3e08d1c496cc2441","payload":{"connection_id":"5d29200f65794d4d9ab6ef271f045a9b","event_at":"2026-07-28T02:02:14.058000Z","event_type":"price_change","frame_hash":"315cdad3012d85af47e33ffa7c7be4b2519419ff0545131515704fd1e40e4bb2","frame_index":0,"kind":"data","monotonic_ns":306118376715833,"payload":{"event_type":"price_change","market":"0xda6f0e0e93fc8469e0159a166028d017bddbc162b86f66bac90391379603d962","price_changes":[{"asset_id":"20893381255801015515826997628594359667013752732428989472914000440642900266717","best_ask":"0.43","best_bid":"0.42","hash":"1a332e089ee9d8f7a597d3bc3e2aed234beb809a","price":"0.01","side":"BUY","size":"7883.02"},{"asset_id":"39272994714739463168905443499424551362424437245880253267329605556587274644733","best_ask":"0.58","best_bid":"0.57","hash":"dcad21b44497cedf559e61a7a70dde20c5d47d57","price":"0.99","side":"SELL","size":"7883.02"}],"timestamp":"1785204134058"},"payload_hash":"6f69642d52d29606c70ba3e5943f67d6a474d6a709c09e2659cb93a9f52c5cec","raw_frame":"{\"market\":\"0xda6f0e0e93fc8469e0159a166028d017bddbc162b86f66bac90391379603d962\", \"price_changes\":[{\"asset_id\":\"20893381255801015515826997628594359667013752732428989472914000440642900266717\", \"price\":\"0.01\", \"size\":\"7883.02\", \"side\":\"BUY\", \"hash\":\"1a332e089ee9d8f7a597d3bc3e2aed234beb809a\", \"best_bid\":\"0.42\", \"best_ask\":\"0.43\"}, {\"asset_id\":\"39272994714739463168905443499424551362424437245880253267329605556587274644733\", \"price\":\"0.99\", \"size\":\"7883.02\", \"side\":\"SELL\", \"hash\":\"dcad21b44497cedf559e61a7a70dde20c5d47d57\", \"best_bid\":\"0.57\", \"best_ask\":\"0.58\"}], \"timestamp\":\"1785204134058\", \"event_type\":\"price_change\"}","received_at":"2026-07-28T02:02:15.372321Z","schema_version":"clob-market-ws.price_change.v1","sequence":null,"server_hash":null,"server_timestamp":"1785204134058","session_id":"d2757dd6dad94f3b9fe67e8dbf1adc37","source":"clob_market_ws"},"received_at":"2026-07-28T02:02:15.372321Z","record_id":"98c65528976aa3a66998bcc1477a75a114f95aadaaf803fbdeb30e380f5d95f9","schema_fingerprint":"4aa3821a28b0b7c2400bc59aba4bcc0a76e971dadd19610d3ad38c768e124dc7","schema_version":"edge-lab-recorder.raw.v1","sequence":null,"source":"clob_market_ws"}
{"event_at":"2026-07-28T02:02:14.158000Z","event_fingerprint":"465ba3da1bf97a50c8280d8aee67c95ee1e510f6b73d234d37994fae6f0acfd3","payload":{"connection_id":"5d29200f65794d4d9ab6ef271f045a9b","event_at":"2026-07-28T02:02:14.158000Z","event_type":"price_change","frame_hash":"2e494e8473227882e1795c647221aa332b2c707171ed4aac37d64271f3a5cd9c","frame_index":0,"kind":"data","monotonic_ns":306118381401291,"payload":{"event_type":"price_change","market":"0xda6f0e0e93fc8469e0159a166028d017bddbc162b86f66bac90391379603d962","price_changes":[{"asset_id":"39272994714739463168905443499424551362424437245880253267329605556587274644733","best_ask":"0.58","best_bid":"0.57","hash":"a29129787a978559ce77056983de48c3811eb31b","price":"0.49","side":"BUY","size":"225"},{"asset_id":"20893381255801015515826997628594359667013752732428989472914000440642900266717","best_ask":"0.43","best_bid":"0.42","hash":"96420d7b0d274ea7db16bb4392390942c10d48e2","price":"0.51","side":"SELL","size":"225"}],"timestamp":"1785204134158"},"payload_hash":"6227f459cd822230af963a90d9b20fe92537c715e3078d5d42d1fdb5a155faea","raw_frame":"{\"market\":\"0xda6f0e0e93fc8469e0159a166028d017bddbc162b86f66bac90391379603d962\", \"price_changes\":[{\"asset_id\":\"39272994714739463168905443499424551362424437245880253267329605556587274644733\", \"price\":\"0.49\", \"size\":\"225\", \"side\":\"BUY\", \"hash\":\"a29129787a978559ce77056983de48c3811eb31b\", \"best_bid\":\"0.57\", \"best_ask\":\"0.58\"}, {\"asset_id\":\"20893381255801015515826997628594359667013752732428989472914000440642900266717\", \"price\":\"0.51\", \"size\":\"225\", \"side\":\"SELL\", \"hash\":\"96420d7b0d274ea7db16bb4392390942c10d48e2\", \"best_bid\":\"0.42\", \"best_ask\":\"0.43\"}], \"timestamp\":\"1785204134158\", \"event_type\":\"price_change\"}","received_at":"2026-07-28T02:02:15.377015Z","schema_version":"clob-market-ws.price_change.v1","sequence":null,"server_hash":null,"server_timestamp":"1785204134158","session_id":"d2757dd6dad94f3b9fe67e8dbf1adc37","source":"clob_market_ws"},"received_at":"2026-07-28T02:02:15.377015Z","record_id":"fee1583aa91854cd9bc1aea7458012df167c1b1c846b38ee0134cf63433e75aa","schema_fingerprint":"4aa3821a28b0b7c2400bc59aba4bcc0a76e971dadd19610d3ad38c768e124dc7","schema_version":"edge-lab-recorder.raw.v1","sequence":null,"source":"clob_market_ws"}
{"event_at":"2026-07-28T02:02:14.159000Z","event_fingerprint":"794399abc512509ce71f24f5ee90ca172aec592b0a3d45c3fc2036fee56ab4f2","payload":{"connection_id":"5d29200f65794d4d9ab6ef271f045a9b","event_at":"2026-07-28T02:02:14.159000Z","event_type":"price_change","frame_hash":"3063201af875a186870415b8784aadcba5d9a30ce653f7d7b50732cf8c164368","frame_index":0,"kind":"data","monotonic_ns":306118384718041,"payload":{"event_type":"price_change","market":"0xda6f0e0e93fc8469e0159a166028d017bddbc162b86f66bac90391379603d962","price_changes":[{"asset_id":"39272994714739463168905443499424551362424437245880253267329605556587274644733","best_ask":"0.58","best_bid":"0.57","hash":"8fde1475c203cc30bebbf7e84329c9752a49a9a1","price":"0.49","side":"BUY","size":"195"},{"asset_id":"20893381255801015515826997628594359667013752732428989472914000440642900266717","best_ask":"0.43","best_bid":"0.42","hash":"21cb877b0e83b5eb4708f0a3c51bd9a6f578b895","price":"0.51","side":"SELL","size":"195"}],"timestamp":"1785204134159"},"payload_hash":"a690b5361f51ce99124e4695cfdbf400087b504106cc3855ad64f04e4ea2e83d","raw_frame":"{\"market\":\"0xda6f0e0e93fc8469e0159a166028d017bddbc162b86f66bac90391379603d962\", \"price_changes\":[{\"asset_id\":\"39272994714739463168905443499424551362424437245880253267329605556587274644733\", \"price\":\"0.49\", \"size\":\"195\", \"side\":\"BUY\", \"hash\":\"8fde1475c203cc30bebbf7e84329c9752a49a9a1\", \"best_bid\":\"0.57\", \"best_ask\":\"0.58\"}, {\"asset_id\":\"20893381255801015515826997628594359667013752732428989472914000440642900266717\", \"price\":\"0.51\", \"size\":\"195\", \"side\":\"SELL\", \"hash\":\"21cb877b0e83b5eb4708f0a3c51bd9a6f578b895\", \"best_bid\":\"0.42\", \"best_ask\":\"0.43\"}], \"timestamp\":\"1785204134159\", \"event_type\":\"price_change\"}","received_at":"2026-07-28T02:02:15.380331Z","schema_version":"clob-market-ws.price_change.v1","sequence":null,"server_hash":null,"server_timestamp":"1785204134159","session_id":"d2757dd6dad94f3b9fe67e8dbf1adc37","source":"clob_market_ws"},"received_at":"2026-07-28T02:02:15.380331Z","record_id":"b9daaf449b8a2fe34a76ff37fbd15afd4000d71719598e629e39f845e328ba95","schema_fingerprint":"4aa3821a28b0b7c2400bc59aba4bcc0a76e971dadd19610d3ad38c768e124dc7","schema_version":"edge-lab-recorder.raw.v1","sequence":null,"source":"clob_market_ws"}
{"event_at":"2026-07-28T02:02:14.160000Z","event_fingerprint":"5acd16a015594052e3fb75268dbd61879f2c210a3483262b022d169243def09e","payload":{"connection_id":"5d29200f65794d4d9ab6ef271f045a9b","event_at":"2026-07-28T02:02:14.160000Z","event_type":"price_change","frame_hash":"9effb2a1d2b1be4e3389687f1eb36ff64bb5f6b65dcf813354b4f1fb9262a95f","frame_index":0,"kind":"data","monotonic_ns":306118387622625,"payload":{"event_type":"price_change","market":"0xda6f0e0e93fc8469e0159a166028d017bddbc162b86f66bac90391379603d962","price_changes":[{"asset_id":"39272994714739463168905443499424551362424437245880253267329605556587274644733","best_ask":"0.58","best_bid":"0.57","hash":"ad4618f7f9178560ec0658cd929b8b8f7676d1f6","price":"0.58","side":"SELL","size":"135.2"},{"asset_id":"20893381255801015515826997628594359667013752732428989472914000440642900266717","best_ask":"0.43","best_bid":"0.42","hash":"843febba0dd3fb7d85d6693e498dc6ae4cd9667a","price":"0.42","side":"BUY","size":"135.2"}],"timestamp":"1785204134160"},"payload_hash":"376a1c2f87add67a5bc89e59d22c9f571895be11c2764eae5394504f26f6b9df","raw_frame":"{\"market\":\"0xda6f0e0e93fc8469e0159a166028d017bddbc162b86f66bac90391379603d962\", \"price_changes\":[{\"asset_id\":\"39272994714739463168905443499424551362424437245880253267329605556587274644733\", \"price\":\"0.58\", \"size\":\"135.2\", \"side\":\"SELL\", \"hash\":\"ad4618f7f9178560ec0658cd929b8b8f7676d1f6\", \"best_bid\":\"0.57\", \"best_ask\":\"0.58\"}, {\"asset_id\":\"20893381255801015515826997628594359667013752732428989472914000440642900266717\", \"price\":\"0.42\", \"size\":\"135.2\", \"side\":\"BUY\", \"hash\":\"843febba0dd3fb7d85d6693e498dc6ae4cd9667a\", \"best_bid\":\"0.42\", \"best_ask\":\"0.43\"}], \"timestamp\":\"1785204134160\", \"event_type\":\"price_change\"}","received_at":"2026-07-28T02:02:15.383237Z","schema_version":"clob-market-ws.price_change.v1","sequence":null,"server_hash":null,"server_timestamp":"1785204134160","session_id":"d2757dd6dad94f3b9fe67e8dbf1adc37","source":"clob_market_ws"},"received_at":"2026-07-28T02:02:15.383237Z","record_id":"8e6b1a52983563e93edf2a4f3dd0f863c1bb821c4ec8d47dff00e079b700455b","schema_fingerprint":"4aa3821a28b0b7c2400bc59aba4bcc0a76e971dadd19610d3ad38c768e124dc7","schema_version":"edge-lab-recorder.raw.v1","sequence":null,"source":"clob_market_ws"}
{"event_at":"2026-07-28T02:02:14.161000Z","event_fingerprint":"eb61a16aebbedb237d98932b73214ac19bd455c6f0a25bc50ab281038d77f9b3","payload":{"connection_id":"5d29200f65794d4d9ab6ef271f045a9b","event_at":"2026-07-28T02:02:14.161000Z","event_type":"price_change","frame_hash":"89842066fc58d35c73a400c4bd7f6d33c67125830fd6dce8bad3a0692680512d","frame_index":0,"kind":"data","monotonic_ns":306118389671750,"payload":{"event_type":"price_change","market":"0xda6f0e0e93fc8469e0159a166028d017bddbc162b86f66bac90391379603d962","price_changes":[{"asset_id":"39272994714739463168905443499424551362424437245880253267329605556587274644733","best_ask":"0.58","best_bid":"0.57","hash":"d6910ba376b2e5b9f77dd2f0eebf1558714fa638","price":"0.5","side":"BUY","size":"200"},{"asset_id":"20893381255801015515826997628594359667013752732428989472914000440642900266717","best_ask":"0.43","best_bid":"0.42","hash":"437d909d60b1ad4ed5c3363367d72e473235527e","price":"0.5","side":"SELL","size":"200"}],"timestamp":"1785204134161"},"payload_hash":"4817ef6693b1511b1eba0da7d2e5dadac4cdf779e598506732686dff7929b5e4","raw_frame":"{\"market\":\"0xda6f0e0e93fc8469e0159a166028d017bddbc162b86f66bac90391379603d962\", \"price_changes\":[{\"asset_id\":\"39272994714739463168905443499424551362424437245880253267329605556587274644733\", \"price\":\"0.5\", \"size\":\"200\", \"side\":\"BUY\", \"hash\":\"d6910ba376b2e5b9f77dd2f0eebf1558714fa638\", \"best_bid\":\"0.57\", \"best_ask\":\"0.58\"}, {\"asset_id\":\"20893381255801015515826997628594359667013752732428989472914000440642900266717\", \"price\":\"0.5\", \"size\":\"200\", \"side\":\"SELL\", \"hash\":\"437d909d60b1ad4ed5c3363367d72e473235527e\", \"best_bid\":\"0.42\", \"best_ask\":\"0.43\"}], \"timestamp\":\"1785204134161\", \"event_type\":\"price_change\"}","received_at":"2026-07-28T02:02:15.385287Z","schema_version":"clob-market-ws.price_change.v1","sequence":null,"server_hash":null,"server_timestamp":"1785204134161","session_id":"d2757dd6dad94f3b9fe67e8dbf1adc37","source":"clob_market_ws"},"received_at":"2026-07-28T02:02:15.385287Z","record_id":"a45ac48ecefaf12b00e00b80a60c4c9daf3294602cbcbcfb67b6c1ce853d8bf6","schema_fingerprint":"4aa3821a28b0b7c2400bc59aba4bcc0a76e971dadd19610d3ad38c768e124dc7","schema_version":"edge-lab-recorder.raw.v1","sequence":null,"source":"clob_market_ws"}
