{"event_at":"2026-07-28T02:05:23.332000Z","event_fingerprint":"fa24cd596104219e1e8ded1ca935ca46d1ad317c01ccd7f35dbe57ad8e1cc1da","payload":{"connection_id":"5d29200f65794d4d9ab6ef271f045a9b","event_at":"2026-07-28T02:05:23.332000Z","event_type":"price_change","frame_hash":"428da752b981a67d9d037b7be8507928f0a8f6882e50de42f480a2f5ccdda8b3","frame_index":0,"kind":"data","monotonic_ns":306314978297791,"payload":{"event_type":"price_change","market":"0xda6f0e0e93fc8469e0159a166028d017bddbc162b86f66bac90391379603d962","price_changes":[{"asset_id":"39272994714739463168905443499424551362424437245880253267329605556587274644733","best_ask":"0.74","best_bid":"0.73","hash":"5cda88b8f48b758b8a6d9bcb67ea9d6cce03fc24","price":"0.01","side":"BUY","size":"5858.02"},{"asset_id":"20893381255801015515826997628594359667013752732428989472914000440642900266717","best_ask":"0.27","best_bid":"0.26","hash":"6e20d57aec1a21a304cd964304e9656b730296a4","price":"0.99","side":"SELL","size":"5858.02"}],"timestamp":"1785204323332"},"payload_hash":"f271e16fc00b4876de6fa9c3f7c2e16743af2df35af55daa3234755fcb1a56f9","raw_frame":"{\"market\":\"0xda6f0e0e93fc8469e0159a166028d017bddbc162b86f66bac90391379603d962\", \"price_changes\":[{\"asset_id\":\"39272994714739463168905443499424551362424437245880253267329605556587274644733\", \"price\":\"0.01\", \"size\":\"5858.02\", \"side\":\"BUY\", \"hash\":\"5cda88b8f48b758b8a6d9bcb67ea9d6cce03fc24\", \"best_bid\":\"0.73\", \"best_ask\":\"0.74\"}, {\"asset_id\":\"20893381255801015515826997628594359667013752732428989472914000440642900266717\", \"price\":\"0.99\", \"size\":\"5858.02\", \"side\":\"SELL\", \"hash\":\"6e20d57aec1a21a304cd964304e9656b730296a4\", \"best_bid\":\"0.26\", \"best_ask\":\"0.27\"}], \"timestamp\":\"1785204323332\", \"event_type\":\"price_change\"}","received_at":"2026-07-28T02:05:31.971960Z","schema_version":"clob-market-ws.price_change.v1","sequence":null,"server_hash":null,"server_timestamp":"1785204323332","session_id":"d2757dd6dad94f3b9fe67e8dbf1adc37","source":"clob_market_ws"},"received_at":"2026-07-28T02:05:31.971960Z","record_id":"9491db75d16eb248461f5d9edb622eda7cb9faf1de8b604b6c1c3001b097b67a","schema_fingerprint":"4aa3821a28b0b7c2400bc59aba4bcc0a76e971dadd19610d3ad38c768e124dc7","schema_version":"edge-lab-recorder.raw.v1","sequence":null,"source":"clob_market_ws"}
{"event_at":"2026-07-28T02:05:23.358000Z","event_fingerprint":"36cf8a530785a757270ffe94afd8579b987e1d4a21bae58627e8768dda7daae7","payload":{"connection_id":"5d29200f65794d4d9ab6ef271f045a9b","event_at":"2026-07-28T02:05:23.358000Z","event_type":"price_change","frame_hash":"5bae7881ed296dd27672ebc689f8eefd46eb1b7707ef1e65b144448f9acb22be","frame_index":0,"kind":"data","monotonic_ns":306314987002541,"payload":{"event_type":"price_change","market":"0xda6f0e0e93fc8469e0159a166028d017bddbc162b86f66bac90391379603d962","price_changes":[{"asset_id":"39272994714739463168905443499424551362424437245880253267329605556587274644733","best_ask":"0.74","best_bid":"0.73","hash":"0eaf5ea61b720bc4e741e77249ac0f99c2a42d14","price":"0.02","side":"BUY","size":"688.1"},{"asset_id":"20893381255801015515826997628594359667013752732428989472914000440642900266717","best_ask":"0.27","best_bid":"0.26","hash":"4fa1e9e77dd218697dc40098159417280129d9b6","price":"0.98","side":"SELL","size":"688.1"}],"timestamp":"1785204323358"},"payload_hash":"89c92d450026899544a5919ae72cdc22423fcd29f0019af626029b81be0308ab","raw_frame":"{\"market\":\"0xda6f0e0e93fc8469e0159a166028d017bddbc162b86f66bac90391379603d962\", \"price_changes\":[{\"asset_id\":\"39272994714739463168905443499424551362424437245880253267329605556587274644733\", \"price\":\"0.02\", \"size\":\"688.1\", \"side\":\"BUY\", \"hash\":\"0eaf5ea61b720bc4e741e77249ac0f99c2a42d14\", \"best_bid\":\"0.73\", \"best_ask\":\"0.74\"}, {\"asset_id\":\"20893381255801015515826997628594359667013752732428989472914000440642900266717\", \"price\":\"0.98\", \"size\":\"688.1\", \"side\":\"SELL\", \"hash\":\"4fa1e9e77dd218697dc40098159417280129d9b6\", \"best_bid\":\"0.26\", \"best_ask\":\"0.27\"}], \"timestamp\":\"1785204323358\", \"event_type\":\"price_change\"}","received_at":"2026-07-28T02:05:31.980665Z","schema_version":"clob-market-ws.price_change.v1","sequence":null,"server_hash":null,"server_timestamp":"1785204323358","session_id":"d2757dd6dad94f3b9fe67e8dbf1adc37","source":"clob_market_ws"},"received_at":"2026-07-28T02:05:31.980665Z","record_id":"232a012794a296bd4dd34b2fa2adfe0895576e2e73bc813c0c6fceb22c1419ca","schema_fingerprint":"4aa3821a28b0b7c2400bc59aba4bcc0a76e971dadd19610d3ad38c768e124dc7","schema_version":"edge-lab-recorder.raw.v1","sequence":null,"source":"clob_market_ws"}
{"event_at":"2026-07-28T02:05:23.359000Z","event_fingerprint":"42496e75fb788c33053fbf531dfc21484603d132bb90da4d155138ddd4e2bb88","payload":{"connection_id":"5d29200f65794d4d9ab6ef271f045a9b","event_at":"2026-07-28T02:05:23.359000Z","event_type":"price_change","frame_hash":"85923501c10a59e911daf5b927649d8cc9cf928bd76407a11322424bfd35b7a1","frame_index":0,"kind":"data","monotonic_ns":306314992126041,"payload":{"event_type":"price_change","market":"0xda6f0e0e93fc8469e0159a166028d017bddbc162b86f66bac90391379603d962","price_changes":[{"asset_id":"39272994714739463168905443499424551362424437245880253267329605556587274644733","best_ask":"0.74","best_bid":"0.73","hash":"fc109129e7fd14d9812669a4acde729bd1292ad0","price":"0.01","side":"BUY","size":"5853.02"},{"asset_id":"20893381255801015515826997628594359667013752732428989472914000440642900266717","best_ask":"0.27","best_bid":"0.26","hash":"6d80ea2a459dcc14d14848b76f4b18fb0c3dfbed","price":"0.99","side":"SELL","size":"5853.02"}],"timestamp":"1785204323359"},"payload_hash":"c9c063dc7cc88c6a92318871cfade000853d59e038f1df281cec4e6288e4c060","raw_frame":"{\"market\":\"0xda6f0e0e93fc8469e0159a166028d017bddbc162b86f66bac90391379603d962\", \"price_changes\":[{\"asset_id\":\"39272994714739463168905443499424551362424437245880253267329605556587274644733\", \"price\":\"0.01\", \"size\":\"5853.02\", \"side\":\"BUY\", \"hash\":\"fc109129e7fd14d9812669a4acde729bd1292ad0\", \"best_bid\":\"0.73\", \"best_ask\":\"0.74\"}, {\"asset_id\":\"20893381255801015515826997628594359667013752732428989472914000440642900266717\", \"price\":\"0.99\", \"size\":\"5853.02\", \"side\":\"SELL\", \"hash\":\"6d80ea2a459dcc14d14848b76f4b18fb0c3dfbed\", \"best_bid\":\"0.26\", \"best_ask\":\"0.27\"}], \"timestamp\":\"1785204323359\", \"event_type\":\"price_change\"}","received_at":"2026-07-28T02:05:31.985789Z","schema_version":"clob-market-ws.price_change.v1","sequence":null,"server_hash":null,"server_timestamp":"1785204323359","session_id":"d2757dd6dad94f3b9fe67e8dbf1adc37","source":"clob_market_ws"},"received_at":"2026-07-28T02:05:31.985789Z","record_id":"be87990cb18198b07053d1bd4c4ac60a93989b4fa47619fbc56f0a2254b788bc","schema_fingerprint":"4aa3821a28b0b7c2400bc59aba4bcc0a76e971dadd19610d3ad38c768e124dc7","schema_version":"edge-lab-recorder.raw.v1","sequence":null,"source":"clob_market_ws"}
{"event_at":"2026-07-28T02:05:23.432000Z","event_fingerprint":"277f311661a486718148c788c652c72edd41c943fb589f7b44882763b9a1839c","payload":{"connection_id":"5d29200f65794d4d9ab6ef271f045a9b","event_at":"2026-07-28T02:05:23.432000Z","event_type":"price_change","frame_hash":"2ec09bd449e56cbcd10697b720f821c2eae85a71932f9780e2618ff7810ba0b3","frame_index":0,"kind":"data","monotonic_ns":306314996331375,"payload":{"event_type":"price_change","market":"0xda6f0e0e93fc8469e0159a166028d017bddbc162b86f66bac90391379603d962","price_changes":[{"asset_id":"39272994714739463168905443499424551362424437245880253267329605556587274644733","best_ask":"0.74","best_bid":"0.73","hash":"54d8942b287789eb6390fd22c2ddf933481290ae","price":"0.73","side":"BUY","size":"24.98"},{"asset_id":"20893381255801015515826997628594359667013752732428989472914000440642900266717","best_ask":"0.27","best_bid":"0.26","hash":"39f40b738596391f1a5bd33cf163baa8701fd90b","price":"0.27","side":"SELL","size":"24.98"}],"timestamp":"1785204323432"},"payload_hash":"c6e9af955d82a3642369cb88e65c8886613318ca129bf0492f3fcf3f7748f7b7","raw_frame":"{\"market\":\"0xda6f0e0e93fc8469e0159a166028d017bddbc162b86f66bac90391379603d962\", \"price_changes\":[{\"asset_id\":\"39272994714739463168905443499424551362424437245880253267329605556587274644733\", \"price\":\"0.73\", \"size\":\"24.98\", \"side\":\"BUY\", \"hash\":\"54d8942b287789eb6390fd22c2ddf933481290ae\", \"best_bid\":\"0.73\", \"best_ask\":\"0.74\"}, {\"asset_id\":\"20893381255801015515826997628594359667013752732428989472914000440642900266717\", \"price\":\"0.27\", \"size\":\"24.98\", \"side\":\"SELL\", \"hash\":\"39f40b738596391f1a5bd33cf163baa8701fd90b\", \"best_bid\":\"0.26\", \"best_ask\":\"0.27\"}], \"timestamp\":\"1785204323432\", \"event_type\":\"price_change\"}","received_at":"2026-07-28T02:05:31.989994Z","schema_version":"clob-market-ws.price_change.v1","sequence":null,"server_hash":null,"server_timestamp":"1785204323432","session_id":"d2757dd6dad94f3b9fe67e8dbf1adc37","source":"clob_market_ws"},"received_at":"2026-07-28T02:05:31.989994Z","record_id":"ae03669edff305e96a4018bc113e9f2c8408a6b8d8ae3df663e99971f3879cfd","schema_fingerprint":"4aa3821a28b0b7c2400bc59aba4bcc0a76e971dadd19610d3ad38c768e124dc7","schema_version":"edge-lab-recorder.raw.v1","sequence":null,"source":"clob_market_ws"}
{"event_at":"2026-07-28T02:05:23.436000Z","event_fingerprint":"764868efcb6c10a438b1c5ccadc191253f9bb425dfb8aad3cf063a5f503b6554","payload":{"connection_id":"5d29200f65794d4d9ab6ef271f045a9b","event_at":"2026-07-28T02:05:23.436000Z","event_type":"price_change","frame_hash":"28858b5181d02239c24a7a639741bd0fcd1381f2dd65dd2ea93a4e54dba908fe","frame_index":0,"kind":"data","monotonic_ns":306315000662416,"payload":{"event_type":"price_change","market":"0xda6f0e0e93fc8469e0159a166028d017bddbc162b86f66bac90391379603d962","price_changes":[{"asset_id":"20893381255801015515826997628594359667013752732428989472914000440642900266717","best_ask":"0.27","best_bid":"0.26","hash":"92edeadef74a370320963ec873048531bbe1f592","price":"0.24","side":"BUY","size":"79.6"},{"asset_id":"39272994714739463168905443499424551362424437245880253267329605556587274644733","best_ask":"0.74","best_bid":"0.73","hash":"bda170817f06fc5aa1ecd79f3d5033c29b63b416","price":"0.76","side":"SELL","size":"79.6"}],"timestamp":"1785204323436"},"payload_hash":"57b155875eccaab907cf339d9fe764c0acaff490135a0701932da2d972ed3a60","raw_frame":"{\"market\":\"0xda6f0e0e93fc8469e0159a166028d017bddbc162b86f66bac90391379603d962\", \"price_changes\":[{\"asset_id\":\"20893381255801015515826997628594359667013752732428989472914000440642900266717\", \"price\":\"0.24\", \"size\":\"79.6\", \"side\":\"BUY\", \"hash\":\"92edeadef74a370320963ec873048531bbe1f592\", \"best_bid\":\"0.26\", \"best_ask\":\"0.27\"}, {\"asset_id\":\"39272994714739463168905443499424551362424437245880253267329605556587274644733\", \"price\":\"0.76\", \"size\":\"79.6\", \"side\":\"SELL\", \"hash\":\"bda170817f06fc5aa1ecd79f3d5033c29b63b416\", \"best_bid\":\"0.73\", \"best_ask\":\"0.74\"}], \"timestamp\":\"1785204323436\", \"event_type\":\"price_change\"}","received_at":"2026-07-28T02:05:31.994325Z","schema_version":"clob-market-ws.price_change.v1","sequence":null,"server_hash":null,"server_timestamp":"1785204323436","session_id":"d2757dd6dad94f3b9fe67e8dbf1adc37","source":"clob_market_ws"},"received_at":"2026-07-28T02:05:31.994325Z","record_id":"c115482c7bf5d9658b8160bc52dba2b5f16f0d3e657480283d4eb556e7c4ba42","schema_fingerprint":"4aa3821a28b0b7c2400bc59aba4bcc0a76e971dadd19610d3ad38c768e124dc7","schema_version":"edge-lab-recorder.raw.v1","sequence":null,"source":"clob_market_ws"}
{"event_at":"2026-07-28T02:05:23.453000Z","event_fingerprint":"95212ccbd6c6e879ea3bf7e4110068b732d4eea4b749aab245d1be72837f7712","payload":{"connection_id":"5d29200f65794d4d9ab6ef271f045a9b","event_at":"2026-07-28T02:05:23.453000Z","event_type":"price_change","frame_hash":"a542023b54110d9e206fe763bc8917730abdb85a81b15e06a97ca042b83585af","frame_index":0,"kind":"data","monotonic_ns":306315005048875,"payload":{"event_type":"price_change","market":"0xda6f0e0e93fc8469e0159a166028d017bddbc162b86f66bac90391379603d962","price_changes":[{"asset_id":"39272994714739463168905443499424551362424437245880253267329605556587274644733","best_ask":"0.74","best_bid":"0.73","hash":"7d1dd5cd075a06a98bb77a8e26185365beb55c85","price":"0.72","side":"BUY","size":"79.2"},{"asset_id":"20893381255801015515826997628594359667013752732428989472914000440642900266717","best_ask":"0.27","best_bid":"0.26","hash":"57eff4c4673c9234a11bc0a3ceac39304e604420","price":"0.28","side":"SELL","size":"79.2"}],"timestamp":"1785204323453"},"payload_hash":"3c560914e4e33a4da1ef8feabb1be478740fe4c2144f2b29f6b0569fb4e686a3","raw_frame":"{\"market\":\"0xda6f0e0e93fc8469e0159a166028d017bddbc162b86f66bac90391379603d962\", \"price_changes\":[{\"asset_id\":\"39272994714739463168905443499424551362424437245880253267329605556587274644733\", \"price\":\"0.72\", \"size\":\"79.2\", \"side\":\"BUY\", \"hash\":\"7d1dd5cd075a06a98bb77a8e26185365beb55c85\", \"best_bid\":\"0.73\", \"best_ask\":\"0.74\"}, {\"asset_id\":\"20893381255801015515826997628594359667013752732428989472914000440642900266717\", \"price\":\"0.28\", \"size\":\"79.2\", \"side\":\"SELL\", \"hash\":\"57eff4c4673c9234a11bc0a3ceac39304e604420\", \"best_bid\":\"0.26\", \"best_ask\":\"0.27\"}], \"timestamp\":\"1785204323453\", \"event_type\":\"price_change\"}","received_at":"2026-07-28T02:05:31.998703Z","schema_version":"clob-market-ws.price_change.v1","sequence":null,"server_hash":null,"server_timestamp":"1785204323453","session_id":"d2757dd6dad94f3b9fe67e8dbf1adc37","source":"clob_market_ws"},"received_at":"2026-07-28T02:05:31.998703Z","record_id":"04e05e8e4938c29bbe2ee24785a990f94876ff1ae242f7330c46a5465211bd1f","schema_fingerprint":"4aa3821a28b0b7c2400bc59aba4bcc0a76e971dadd19610d3ad38c768e124dc7","schema_version":"edge-lab-recorder.raw.v1","sequence":null,"source":"clob_market_ws"}
{"event_at":"2026-07-28T02:05:23.457000Z","event_fingerprint":"842dfa1c5fe9c453dfb80e090756e3f1be87a6630324dbd64ae9730f9e79e963","payload":{"connection_id":"5d29200f65794d4d9ab6ef271f045a9b","event_at":"2026-07-28T02:05:23.457000Z","event_type":"price_change","frame_hash":"075639dbf5b5b5b75a63951ffe25f80f5487d718cf33e872fc35617b7dfa851b","frame_index":0,"kind":"data","monotonic_ns":306315009411375,"payload":{"event_type":"price_change","market":"0xda6f0e0e93fc8469e0159a166028d017bddbc162b86f66bac90391379603d962","price_changes":[{"asset_id":"20893381255801015515826997628594359667013752732428989472914000440642900266717","best_ask":"0.27","best_bid":"0.26","hash":"9e7c9db7dc3b0070de958c015b7bec2e3a2c5bc8","price":"0.25","side":"BUY","size":"119.2"},{"asset_id":"39272994714739463168905443499424551362424437245880253267329605556587274644733","best_ask":"0.74","best_bid":"0.73","hash":"8f94b4db4daf8f89054b3eb7353466ed64c3f8a2","price":"0.75","side":"SELL","size":"119.2"}],"timestamp":"1785204323457"},"payload_hash":"398e65c4e4ab6baeec09e31df2c4e9a506e2ca3e3d3676ea3f0a76ee14b763ca","raw_frame":"{\"market\":\"0xda6f0e0e93fc8469e0159a166028d017bddbc162b86f66bac90391379603d962\", \"price_changes\":[{\"asset_id\":\"20893381255801015515826997628594359667013752732428989472914000440642900266717\", \"price\":\"0.25\", \"size\":\"119.2\", \"side\":\"BUY\", \"hash\":\"9e7c9db7dc3b0070de958c015b7bec2e3a2c5bc8\", \"best_bid\":\"0.26\", \"best_ask\":\"0.27\"}, {\"asset_id\":\"39272994714739463168905443499424551362424437245880253267329605556587274644733\", \"price\":\"0.75\", \"size\":\"119.2\", \"side\":\"SELL\", \"hash\":\"8f94b4db4daf8f89054b3eb7353466ed64c3f8a2\", \"best_bid\":\"0.73\", \"best_ask\":\"0.74\"}], \"timestamp\":\"1785204323457\", \"event_type\":\"price_change\"}","received_at":"2026-07-28T02:05:32.003071Z","schema_version":"clob-market-ws.price_change.v1","sequence":null,"server_hash":null,"server_timestamp":"1785204323457","session_id":"d2757dd6dad94f3b9fe67e8dbf1adc37","source":"clob_market_ws"},"received_at":"2026-07-28T02:05:32.003071Z","record_id":"cf42f90b5014a95a322cb6c005b67e5f8779bf387a9397d80328cdc3208d637d","schema_fingerprint":"4aa3821a28b0b7c2400bc59aba4bcc0a76e971dadd19610d3ad38c768e124dc7","schema_version":"edge-lab-recorder.raw.v1","sequence":null,"source":"clob_market_ws"}
{"event_at":"2026-07-28T02:05:23.458000Z","event_fingerprint":"85b90fc05b35d334ff6f65ad73f98e817a72b946753de54968aabffa818b06d3","payload":{"connection_id":"5d29200f65794d4d9ab6ef271f045a9b","event_at":"2026-07-28T02:05:23.458000Z","event_type":"price_change","frame_hash":"ab85f0e23e77342290ac209798c2d27b24e5fe55a62c51a2467d83b335cb2e22","frame_index":0,"kind":"data","monotonic_ns":306315013905041,"payload":{"event_type":"price_change","market":"0xda6f0e0e93fc8469e0159a166028d017bddbc162b86f66bac90391379603d962","price_changes":[{"asset_id":"39272994714739463168905443499424551362424437245880253267329605556587274644733","best_ask":"0.74","best_bid":"0.73","hash":"9cea8edfaddea2177105591c157ce0942394fc11","price":"0.02","side":"BUY","size":"683.1"},{"asset_id":"20893381255801015515826997628594359667013752732428989472914000440642900266717","best_ask":"0.27","best_bid":"0.26","hash":"c377a10ebe2b3099326e79cab2073be25ad5ab32","price":"0.98","side":"SELL","size":"683.1"}],"timestamp":"1785204323458"},"payload_hash":"392f34731053e498a406c3a948405655b0021d412c63f907f09eb129a5ead141","raw_frame":"{\"market\":\"0xda6f0e0e93fc8469e0159a166028d017bddbc162b86f66bac90391379603d962\", \"price_changes\":[{\"asset_id\":\"39272994714739463168905443499424551362424437245880253267329605556587274644733\", \"price\":\"0.02\", \"size\":\"683.1\", \"side\":\"BUY\", \"hash\":\"9cea8edfaddea2177105591c157ce0942394fc11\", \"best_bid\":\"0.73\", \"best_ask\":\"0.74\"}, {\"asset_id\":\"20893381255801015515826997628594359667013752732428989472914000440642900266717\", \"price\":\"0.98\", \"size\":\"683.1\", \"side\":\"SELL\", \"hash\":\"c377a10ebe2b3099326e79cab2073be25ad5ab32\", \"best_bid\":\"0.26\", \"best_ask\":\"0.27\"}], \"timestamp\":\"1785204323458\", \"event_type\":\"price_change\"}","received_at":"2026-07-28T02:05:32.007568Z","schema_version":"clob-market-ws.price_change.v1","sequence":null,"server_hash":null,"server_timestamp":"1785204323458","session_id":"d2757dd6dad94f3b9fe67e8dbf1adc37","source":"clob_market_ws"},"received_at":"2026-07-28T02:05:32.007568Z","record_id":"6569b8ff8a4538ffbc63171f1745bf7c35077ca6cd595ed34906c20f5afde9e1","schema_fingerprint":"4aa3821a28b0b7c2400bc59aba4bcc0a76e971dadd19610d3ad38c768e124dc7","schema_version":"edge-lab-recorder.raw.v1","sequence":null,"source":"clob_market_ws"}
{"event_at":"2026-07-28T02:05:23.521000Z","event_fingerprint":"5d059b7880caa3842d51af0aa1210247d08ceea5971965e5c666f8b139e13933","payload":{"connection_id":"5d29200f65794d4d9ab6ef271f045a9b","event_at":"2026-07-28T02:05:23.521000Z","event_type":"price_change","frame_hash":"79715f09a8d43f3226c5b069b1fa3547fc7284edad5e198a866cbb5efa00b121","frame_index":0,"kind":"data","monotonic_ns":306315018328333,"payload":{"event_type":"price_change","market":"0xda6f0e0e93fc8469e0159a166028d017bddbc162b86f66bac90391379603d962","price_changes":[{"asset_id":"39272994714739463168905443499424551362424437245880253267329605556587274644733","best_ask":"0.74","best_bid":"0.73","hash":"da66a826ad5a0ae657625686099c9f94a05b16e3","price":"0.65","side":"BUY","size":"169"},{"asset_id":"20893381255801015515826997628594359667013752732428989472914000440642900266717","best_ask":"0.27","best_bid":"0.26","hash":"dfac53997c02f617f2f49141b2dcd8f4175a26dd","price":"0.35","side":"SELL","size":"169"}],"timestamp":"1785204323521"},"payload_hash":"71e5e7d948ac48d131ecf75a0e87405c7502377187b31aaead543fe65e6a2086","raw_frame":"{\"market\":\"0xda6f0e0e93fc8469e0159a166028d017bddbc162b86f66bac90391379603d962\", \"price_changes\":[{\"asset_id\":\"39272994714739463168905443499424551362424437245880253267329605556587274644733\", \"price\":\"0.65\", \"size\":\"169\", \"side\":\"BUY\", \"hash\":\"da66a826ad5a0ae657625686099c9f94a05b16e3\", \"best_bid\":\"0.73\", \"best_ask\":\"0.74\"}, {\"asset_id\":\"20893381255801015515826997628594359667013752732428989472914000440642900266717\", \"price\":\"0.35\", \"size\":\"169\", \"side\":\"SELL\", \"hash\":\"dfac53997c02f617f2f49141b2dcd8f4175a26dd\", \"best_bid\":\"0.26\", \"best_ask\":\"0.27\"}], \"timestamp\":\"1785204323521\", \"event_type\":\"price_change\"}","received_at":"2026-07-28T02:05:32.011990Z","schema_version":"clob-market-ws.price_change.v1","sequence":null,"server_hash":null,"server_timestamp":"1785204323521","session_id":"d2757dd6dad94f3b9fe67e8dbf1adc37","source":"clob_market_ws"},"received_at":"2026-07-28T02:05:32.011990Z","record_id":"5f6c35f08c2add99a1d563b8621610d39ffe66e30e0b4536718d0ac94056624a","schema_fingerprint":"4aa3821a28b0b7c2400bc59aba4bcc0a76e971dadd19610d3ad38c768e124dc7","schema_version":"edge-lab-recorder.raw.v1","sequence":null,"source":"clob_market_ws"}
{"event_at":"2026-07-28T02:05:23.522000Z","event_fingerprint":"fa8d749f1d9687a92b10910e132cbea9821cd9db0daaef07311d386f98f711ae","payload":{"connection_id":"5d29200f65794d4d9ab6ef271f045a9b","event_at":"2026-07-28T02:05:23.522000Z","event_type":"price_change","frame_hash":"f82b4f2ac4fa92ac58c246e934cd1e34c0d1173921b977dd2d222d9945a7bb70","frame_index":0,"kind":"data","monotonic_ns":306315022712500,"payload":{"event_type":"price_change","market":"0xda6f0e0e93fc8469e0159a166028d017bddbc162b86f66bac90391379603d962","price_changes":[{"asset_id":"39272994714739463168905443499424551362424437245880253267329605556587274644733","best_ask":"0.74","best_bid":"0.73","hash":"5ff6730695602b5d3413d6f2a868fcd1b72afe07","price":"0.56","side":"BUY","size":"181.18"},{"asset_id":"20893381255801015515826997628594359667013752732428989472914000440642900266717","best_ask":"0.27","best_bid":"0.26","hash":"811fa62d082ac58ba76523485a24c8bb3d7ba454","price":"0.44","side":"SELL","size":"181.18"}],"timestamp":"1785204323522"},"payload_hash":"0200c090a23567b4a559741fca7134ab6ef3f4c0b996e08cf0afddff8354778e","raw_frame":"{\"market\":\"0xda6f0e0e93fc8469e0159a166028d017bddbc162b86f66bac90391379603d962\", \"price_changes\":[{\"asset_id\":\"39272994714739463168905443499424551362424437245880253267329605556587274644733\", \"price\":\"0.56\", \"size\":\"181.18\", \"side\":\"BUY\", \"hash\":\"5ff6730695602b5d3413d6f2a868fcd1b72afe07\", \"best_bid\":\"0.73\", \"best_ask\":\"0.74\"}, {\"asset_id\":\"20893381255801015515826997628594359667013752732428989472914000440642900266717\", \"price\":\"0.44\", \"size\":\"181.18\", \"side\":\"SELL\", \"hash\":\"811fa62d082ac58ba76523485a24c8bb3d7ba454\", \"best_bid\":\"0.26\", \"best_ask\":\"0.27\"}], \"timestamp\":\"1785204323522\", \"event_type\":\"price_change\"}","received_at":"2026-07-28T02:05:32.016375Z","schema_version":"clob-market-ws.price_change.v1","sequence":null,"server_hash":null,"server_timestamp":"1785204323522","session_id":"d2757dd6dad94f3b9fe67e8dbf1adc37","source":"clob_market_ws"},"received_at":"2026-07-28T02:05:32.016375Z","record_id":"04aea644353222ad169530fea48b54e0164b8beb9e8aee2492ca71c366548857","schema_fingerprint":"4aa3821a28b0b7c2400bc59aba4bcc0a76e971dadd19610d3ad38c768e124dc7","schema_version":"edge-lab-recorder.raw.v1","sequence":null,"source":"clob_market_ws"}
{"event_at":"2026-07-28T02:05:23.545000Z","event_fingerprint":"fc774623b1226f477dae5de29ea94235a1eafdeec030a3b442c8f3fe369cfb1c","payload":{"connection_id":"5d29200f65794d4d9ab6ef271f045a9b","event_at":"2026-07-28T02:05:23.545000Z","event_type":"price_change","frame_hash":"fefabe1e73f317ea3db20d5e9cd9e7d5e0ac8b16e8a86316036740ae192ceaf6","frame_index":0,"kind":"data","monotonic_ns":306315026984250,"payload":{"event_type":"price_change","market":"0xda6f0e0e93fc8469e0159a166028d017bddbc162b86f66bac90391379603d962","price_changes":[{"asset_id":"39272994714739463168905443499424551362424437245880253267329605556587274644733","best_ask":"0.74","best_bid":"0.73","hash":"8b628a2b471705c889327d7bc51792914e58a859","price":"0.04","side":"BUY","size":"593.09"},{"asset_id":"20893381255801015515826997628594359667013752732428989472914000440642900266717","best_ask":"0.27","best_bid":"0.26","hash":"dc39f7b49013e91324327f61300f61973ce69b64","price":"0.96","side":"SELL","size":"593.09"}],"timestamp":"1785204323545"},"payload_hash":"b49ccffa19ad1f264ede181b3d827c2641440f659022e82b451c842ec5e60780","raw_frame":"{\"market\":\"0xda6f0e0e93fc8469e0159a166028d017bddbc162b86f66bac90391379603d962\", \"price_changes\":[{\"asset_id\":\"39272994714739463168905443499424551362424437245880253267329605556587274644733\", \"price\":\"0.04\", \"size\":\"593.09\", \"side\":\"BUY\", \"hash\":\"8b628a2b471705c889327d7bc51792914e58a859\", \"best_bid\":\"0.73\", \"best_ask\":\"0.74\"}, {\"asset_id\":\"20893381255801015515826997628594359667013752732428989472914000440642900266717\", \"price\":\"0.96\", \"size\":\"593.09\", \"side\":\"SELL\", \"hash\":\"dc39f7b49013e91324327f61300f61973ce69b64\", \"best_bid\":\"0.26\", \"best_ask\":\"0.27\"}], \"timestamp\":\"1785204323545\", \"event_type\":\"price_change\"}","received_at":"2026-07-28T02:05:32.020647Z","schema_version":"clob-market-ws.price_change.v1","sequence":null,"server_hash":null,"server_timestamp":"1785204323545","session_id":"d2757dd6dad94f3b9fe67e8dbf1adc37","source":"clob_market_ws"},"received_at":"2026-07-28T02:05:32.020647Z","record_id":"7b4fa6d402d4407cbcdbae51b012db124539cbe852e466c8f5afc60bbf02c54d","schema_fingerprint":"4aa3821a28b0b7c2400bc59aba4bcc0a76e971dadd19610d3ad38c768e124dc7","schema_version":"edge-lab-recorder.raw.v1","sequence":null,"source":"clob_market_ws"}
{"event_at":"2026-07-28T02:05:23.676000Z","event_fingerprint":"d3f3a8517c24faeb433b61afd965321945f4da8d93f25295077f11ed506bf54a","payload":{"connection_id":"5d29200f65794d4d9ab6ef271f045a9b","event_at":"2026-07-28T02:05:23.676000Z","event_type":"price_change","frame_hash":"8b03c247dd7256dcec0f37aab146bde1c7d570036bc737a5f70a5df429f9963b","frame_index":0,"kind":"data","monotonic_ns":306315031304833,"payload":{"event_type":"price_change","market":"0xda6f0e0e93fc8469e0159a166028d017bddbc162b86f66bac90391379603d962","price_changes":[{"asset_id":"20893381255801015515826997628594359667013752732428989472914000440642900266717","best_ask":"0.27","best_bid":"0.26","hash":"1c731dd17856c98532bbba3137cd85a6bd1afb1c","price":"0.27","side":"SELL","size":"19.98"},{"asset_id":"39272994714739463168905443499424551362424437245880253267329605556587274644733","best_ask":"0.74","best_bid":"0.73","hash":"4b97cf09698c82adf4485b0160ffc60d08645052","price":"0.73","side":"BUY","size":"19.98"}],"timestamp":"1785204323676"},"payload_hash":"e9a6475009b517baa521df91d2d12e6d432bc95ed44725a45f64f9ede3fe3857","raw_frame":"{\"market\":\"0xda6f0e0e93fc8469e0159a166028d017bddbc162b86f66bac90391379603d962\", \"price_changes\":[{\"asset_id\":\"20893381255801015515826997628594359667013752732428989472914000440642900266717\", \"price\":\"0.27\", \"size\":\"19.98\", \"side\":\"SELL\", \"hash\":\"1c731dd17856c98532bbba3137cd85a6bd1afb1c\", \"best_bid\":\"0.26\", \"best_ask\":\"0.27\"}, {\"asset_id\":\"39272994714739463168905443499424551362424437245880253267329605556587274644733\", \"price\":\"0.73\", \"size\":\"19.98\", \"side\":\"BUY\", \"hash\":\"4b97cf09698c82adf4485b0160ffc60d08645052\", \"best_bid\":\"0.73\", \"best_ask\":\"0.74\"}], \"timestamp\":\"1785204323676\", \"event_type\":\"price_change\"}","received_at":"2026-07-28T02:05:32.024967Z","schema_version":"clob-market-ws.price_change.v1","sequence":null,"server_hash":null,"server_timestamp":"1785204323676","session_id":"d2757dd6dad94f3b9fe67e8dbf1adc37","source":"clob_market_ws"},"received_at":"2026-07-28T02:05:32.024967Z","record_id":"f0318e3942253066a4b1d0f6b55018ecf71fc5f43fdb93f7ac43a16becb81902","schema_fingerprint":"4aa3821a28b0b7c2400bc59aba4bcc0a76e971dadd19610d3ad38c768e124dc7","schema_version":"edge-lab-recorder.raw.v1","sequence":null,"source":"clob_market_ws"}
{"event_at":"2026-07-28T02:05:23.686000Z","event_fingerprint":"650e96312f0b7ef53b1e7ca240fc51294bf24394f0d3f04c04e6c258443232f5","payload":{"connection_id":"5d29200f65794d4d9ab6ef271f045a9b","event_at":"2026-07-28T02:05:23.686000Z","event_type":"price_change","frame_hash":"7b64b99c2e8421f701f98d5a18b5d207793c787f098de8f55af55eea8c7c2607","frame_index":0,"kind":"data","monotonic_ns":306315036453458,"payload":{"event_type":"price_change","market":"0xda6f0e0e93fc8469e0159a166028d017bddbc162b86f66bac90391379603d962","price_changes":[{"asset_id":"20893381255801015515826997628594359667013752732428989472914000440642900266717","best_ask":"0.27","best_bid":"0.26","hash":"36f86b84d410d21ae95e3024a5464df1d36dd49a","price":"0.2","side":"BUY","size":"219.53"},{"asset_id":"39272994714739463168905443499424551362424437245880253267329605556587274644733","best_ask":"0.74","best_bid":"0.73","hash":"f311ce35001e9e91192b2f3681c61e76653b5082","price":"0.8","side":"SELL","size":"219.53"}],"timestamp":"1785204323686"},"payload_hash":"3a2e0854ebc23ed79e9b87f1412dd9449dc1f7422578e808b0a6131d27839c7d","raw_frame":"{\"market\":\"0xda6f0e0e93fc8469e0159a166028d017bddbc162b86f66bac90391379603d962\", \"price_changes\":[{\"asset_id\":\"20893381255801015515826997628594359667013752732428989472914000440642900266717\", \"price\":\"0.2\", \"size\":\"219.53\", \"side\":\"BUY\", \"hash\":\"36f86b84d410d21ae95e3024a5464df1d36dd49a\", \"best_bid\":\"0.26\", \"best_ask\":\"0.27\"}, {\"asset_id\":\"39272994714739463168905443499424551362424437245880253267329605556587274644733\", \"price\":\"0.8\", \"size\":\"219.53\", \"side\":\"SELL\", \"hash\":\"f311ce35001e9e91192b2f3681c61e76653b5082\", \"best_bid\":\"0.73\", \"best_ask\":\"0.74\"}], \"timestamp\":\"1785204323686\", \"event_type\":\"price_change\"}","received_at":"2026-07-28T02:05:32.030116Z","schema_version":"clob-market-ws.price_change.v1","sequence":null,"server_hash":null,"server_timestamp":"1785204323686","session_id":"d2757dd6dad94f3b9fe67e8dbf1adc37","source":"clob_market_ws"},"received_at":"2026-07-28T02:05:32.030116Z","record_id":"ca931a5dcd139012f86a92209ebedd5e8741145d28e1718d45a32263d04f185a","schema_fingerprint":"4aa3821a28b0b7c2400bc59aba4bcc0a76e971dadd19610d3ad38c768e124dc7","schema_version":"edge-lab-recorder.raw.v1","sequence":null,"source":"clob_market_ws"}
{"event_at":"2026-07-28T02:05:23.699000Z","event_fingerprint":"a2b411b83c8a373961248c94e87d7d1f6ffd58cb2338a6ca0360a58a306885d9","payload":{"connection_id":"5d29200f65794d4d9ab6ef271f045a9b","event_at":"2026-07-28T02:05:23.699000Z","event_type":"price_change","frame_hash":"b5edc9a337e2b93ced29d7d8a175e110554de0e2d0de3e0995854d8d6b4a6f96","frame_index":0,"kind":"data","monotonic_ns":306315040708166,"payload":{"event_type":"price_change","market":"0xda6f0e0e93fc8469e0159a166028d017bddbc162b86f66bac90391379603d962","price_changes":[{"asset_id":"39272994714739463168905443499424551362424437245880253267329605556587274644733","best_ask":"0.74","best_bid":"0.73","hash":"618eff4aa0697482d796f32195db1c898b8f928a","price":"0.04","side":"BUY","size":"588.09"},{"asset_id":"20893381255801015515826997628594359667013752732428989472914000440642900266717","best_ask":"0.27","best_bid":"0.26","hash":"9490493e79a4d948fb8d76c9c339e8edf558b75e","price":"0.96","side":"SELL","size":"588.09"}],"timestamp":"1785204323699"},"payload_hash":"6cf0ef22c7a0f91784c7ea1c9352f0d0acd48b417d3a65c20a4d554633a82a89","raw_frame":"{\"market\":\"0xda6f0e0e93fc8469e0159a166028d017bddbc162b86f66bac90391379603d962\", \"price_changes\":[{\"asset_id\":\"39272994714739463168905443499424551362424437245880253267329605556587274644733\", \"price\":\"0.04\", \"size\":\"588.09\", \"side\":\"BUY\", \"hash\":\"618eff4aa0697482d796f32195db1c898b8f928a\", \"best_bid\":\"0.73\", \"best_ask\":\"0.74\"}, {\"asset_id\":\"20893381255801015515826997628594359667013752732428989472914000440642900266717\", \"price\":\"0.96\", \"size\":\"588.09\", \"side\":\"SELL\", \"hash\":\"9490493e79a4d948fb8d76c9c339e8edf558b75e\", \"best_bid\":\"0.26\", \"best_ask\":\"0.27\"}], \"timestamp\":\"1785204323699\", \"event_type\":\"price_change\"}","received_at":"2026-07-28T02:05:32.034371Z","schema_version":"clob-market-ws.price_change.v1","sequence":null,"server_hash":null,"server_timestamp":"1785204323699","session_id":"d2757dd6dad94f3b9fe67e8dbf1adc37","source":"clob_market_ws"},"received_at":"2026-07-28T02:05:32.034371Z","record_id":"e4421edbefa175bd8577ba2d1d0e7097fae165b3f953638f4869b7feec7bac33","schema_fingerprint":"4aa3821a28b0b7c2400bc59aba4bcc0a76e971dadd19610d3ad38c768e124dc7","schema_version":"edge-lab-recorder.raw.v1","sequence":null,"source":"clob_market_ws"}
