{"event_at":"2026-07-28T02:05:23.714000Z","event_fingerprint":"d10fa3465d8ab4db1a9f83b8ccdb78502876e5d31f253d9c2a772c909a9565af","payload":{"connection_id":"5d29200f65794d4d9ab6ef271f045a9b","event_at":"2026-07-28T02:05:23.714000Z","event_type":"price_change","frame_hash":"5fdbeed8b9ea1561f63b8d6cca91d4fb746a4dcbbce944520dbc5500130de260","frame_index":0,"kind":"data","monotonic_ns":306315076211000,"payload":{"event_type":"price_change","market":"0xda6f0e0e93fc8469e0159a166028d017bddbc162b86f66bac90391379603d962","price_changes":[{"asset_id":"39272994714739463168905443499424551362424437245880253267329605556587274644733","best_ask":"0.74","best_bid":"0.73","hash":"8d4a693bbbb12868b1f014fe77ccffdd321ed635","price":"0.01","side":"BUY","size":"5858.02"},{"asset_id":"20893381255801015515826997628594359667013752732428989472914000440642900266717","best_ask":"0.27","best_bid":"0.26","hash":"670095b71e6d7ac57842b69c7e35b57a2be25db7","price":"0.99","side":"SELL","size":"5858.02"}],"timestamp":"1785204323714"},"payload_hash":"77dd90c3308768408d82cd92a15c7c2a1b0a93a48ccf24cd242bb03e2503e7e6","raw_frame":"{\"market\":\"0xda6f0e0e93fc8469e0159a166028d017bddbc162b86f66bac90391379603d962\", \"price_changes\":[{\"asset_id\":\"39272994714739463168905443499424551362424437245880253267329605556587274644733\", \"price\":\"0.01\", \"size\":\"5858.02\", \"side\":\"BUY\", \"hash\":\"8d4a693bbbb12868b1f014fe77ccffdd321ed635\", \"best_bid\":\"0.73\", \"best_ask\":\"0.74\"}, {\"asset_id\":\"20893381255801015515826997628594359667013752732428989472914000440642900266717\", \"price\":\"0.99\", \"size\":\"5858.02\", \"side\":\"SELL\", \"hash\":\"670095b71e6d7ac57842b69c7e35b57a2be25db7\", \"best_bid\":\"0.26\", \"best_ask\":\"0.27\"}], \"timestamp\":\"1785204323714\", \"event_type\":\"price_change\"}","received_at":"2026-07-28T02:05:32.069873Z","schema_version":"clob-market-ws.price_change.v1","sequence":null,"server_hash":null,"server_timestamp":"1785204323714","session_id":"d2757dd6dad94f3b9fe67e8dbf1adc37","source":"clob_market_ws"},"received_at":"2026-07-28T02:05:32.069873Z","record_id":"f187d4dfbf27ff0e032068fa67209f310f830466f134e3597df5daf08f41755f","schema_fingerprint":"4aa3821a28b0b7c2400bc59aba4bcc0a76e971dadd19610d3ad38c768e124dc7","schema_version":"edge-lab-recorder.raw.v1","sequence":null,"source":"clob_market_ws"}
{"event_at":"2026-07-28T02:05:23.732000Z","event_fingerprint":"a73bd29abc52775adbdebdd77b414dd1a5782caa19c57fb3be49461597b038ad","payload":{"connection_id":"5d29200f65794d4d9ab6ef271f045a9b","event_at":"2026-07-28T02:05:23.732000Z","event_type":"price_change","frame_hash":"fc6abdd1fab5d9f49a53eb1ef1f507b329a9d7b0f9af1160df3560be43df7d56","frame_index":0,"kind":"data","monotonic_ns":306315089030250,"payload":{"event_type":"price_change","market":"0xda6f0e0e93fc8469e0159a166028d017bddbc162b86f66bac90391379603d962","price_changes":[{"asset_id":"39272994714739463168905443499424551362424437245880253267329605556587274644733","best_ask":"0.74","best_bid":"0.73","hash":"4c66ffd40179c0abefde0b6d75a6a31c31ecebf0","price":"0.01","side":"BUY","size":"5853.02"},{"asset_id":"20893381255801015515826997628594359667013752732428989472914000440642900266717","best_ask":"0.27","best_bid":"0.26","hash":"bc4cf84a415a53bc29bb6e39fbdcc37ee1f1f4ba","price":"0.99","side":"SELL","size":"5853.02"}],"timestamp":"1785204323732"},"payload_hash":"45c1ad104ae13b42cc2d7d26b10cff9fcfd45815231c8840e9e1bdcddfef3a43","raw_frame":"{\"market\":\"0xda6f0e0e93fc8469e0159a166028d017bddbc162b86f66bac90391379603d962\", \"price_changes\":[{\"asset_id\":\"39272994714739463168905443499424551362424437245880253267329605556587274644733\", \"price\":\"0.01\", \"size\":\"5853.02\", \"side\":\"BUY\", \"hash\":\"4c66ffd40179c0abefde0b6d75a6a31c31ecebf0\", \"best_bid\":\"0.73\", \"best_ask\":\"0.74\"}, {\"asset_id\":\"20893381255801015515826997628594359667013752732428989472914000440642900266717\", \"price\":\"0.99\", \"size\":\"5853.02\", \"side\":\"SELL\", \"hash\":\"bc4cf84a415a53bc29bb6e39fbdcc37ee1f1f4ba\", \"best_bid\":\"0.26\", \"best_ask\":\"0.27\"}], \"timestamp\":\"1785204323732\", \"event_type\":\"price_change\"}","received_at":"2026-07-28T02:05:32.082692Z","schema_version":"clob-market-ws.price_change.v1","sequence":null,"server_hash":null,"server_timestamp":"1785204323732","session_id":"d2757dd6dad94f3b9fe67e8dbf1adc37","source":"clob_market_ws"},"received_at":"2026-07-28T02:05:32.082692Z","record_id":"429bfec3ca1ec786ae841e59a6ba9c1f8f0d287b51cba962d5ea1f2aed8ae85a","schema_fingerprint":"4aa3821a28b0b7c2400bc59aba4bcc0a76e971dadd19610d3ad38c768e124dc7","schema_version":"edge-lab-recorder.raw.v1","sequence":null,"source":"clob_market_ws"}
{"event_at":"2026-07-28T02:05:23.753000Z","event_fingerprint":"2c65527c41f443601a3defd8fcc72d53d36a132c7a4347b653f90f2250112507","payload":{"connection_id":"5d29200f65794d4d9ab6ef271f045a9b","event_at":"2026-07-28T02:05:23.753000Z","event_type":"price_change","frame_hash":"da6a1a704e66969780babff47630173e95a926207f038edea8ffe8d4444f6312","frame_index":0,"kind":"data","monotonic_ns":306315093509458,"payload":{"event_type":"price_change","market":"0xda6f0e0e93fc8469e0159a166028d017bddbc162b86f66bac90391379603d962","price_changes":[{"asset_id":"20893381255801015515826997628594359667013752732428989472914000440642900266717","best_ask":"0.27","best_bid":"0.26","hash":"7d476ab1f5aec37c50d684bdecfaf731b77fb1fc","price":"0.21","side":"BUY","size":"105.18"},{"asset_id":"39272994714739463168905443499424551362424437245880253267329605556587274644733","best_ask":"0.74","best_bid":"0.73","hash":"2ea641d6d3b055ebb6c02b1b8340e97d9fcb2f8a","price":"0.79","side":"SELL","size":"105.18"}],"timestamp":"1785204323753"},"payload_hash":"58c7dc79f8259e80b6ce3897f2088e73eb0b9796bc861c980cbb275e0f783b8c","raw_frame":"{\"market\":\"0xda6f0e0e93fc8469e0159a166028d017bddbc162b86f66bac90391379603d962\", \"price_changes\":[{\"asset_id\":\"20893381255801015515826997628594359667013752732428989472914000440642900266717\", \"price\":\"0.21\", \"size\":\"105.18\", \"side\":\"BUY\", \"hash\":\"7d476ab1f5aec37c50d684bdecfaf731b77fb1fc\", \"best_bid\":\"0.26\", \"best_ask\":\"0.27\"}, {\"asset_id\":\"39272994714739463168905443499424551362424437245880253267329605556587274644733\", \"price\":\"0.79\", \"size\":\"105.18\", \"side\":\"SELL\", \"hash\":\"2ea641d6d3b055ebb6c02b1b8340e97d9fcb2f8a\", \"best_bid\":\"0.73\", \"best_ask\":\"0.74\"}], \"timestamp\":\"1785204323753\", \"event_type\":\"price_change\"}","received_at":"2026-07-28T02:05:32.087171Z","schema_version":"clob-market-ws.price_change.v1","sequence":null,"server_hash":null,"server_timestamp":"1785204323753","session_id":"d2757dd6dad94f3b9fe67e8dbf1adc37","source":"clob_market_ws"},"received_at":"2026-07-28T02:05:32.087171Z","record_id":"4e578187e5c3be3540a12876f586b2f764077fedec3fcbec68318aef74a8d617","schema_fingerprint":"4aa3821a28b0b7c2400bc59aba4bcc0a76e971dadd19610d3ad38c768e124dc7","schema_version":"edge-lab-recorder.raw.v1","sequence":null,"source":"clob_market_ws"}
{"event_at":"2026-07-28T02:05:23.778000Z","event_fingerprint":"a7c5e594326d82ea78d360cf8a53abb48342a22fff00f466aece22095f36f116","payload":{"connection_id":"5d29200f65794d4d9ab6ef271f045a9b","event_at":"2026-07-28T02:05:23.778000Z","event_type":"price_change","frame_hash":"b20d30a20e9c778275e2a7bdc2a344f73f948798b66ea09e347a5c5b80b52ac0","frame_index":0,"kind":"data","monotonic_ns":306315097963708,"payload":{"event_type":"price_change","market":"0xda6f0e0e93fc8469e0159a166028d017bddbc162b86f66bac90391379603d962","price_changes":[{"asset_id":"39272994714739463168905443499424551362424437245880253267329605556587274644733","best_ask":"0.74","best_bid":"0.73","hash":"86b67763d5fd8ee761012e2f51612e179b278a5d","price":"0.04","side":"BUY","size":"593.09"},{"asset_id":"20893381255801015515826997628594359667013752732428989472914000440642900266717","best_ask":"0.27","best_bid":"0.26","hash":"4630370a9f86a6914b1e1cf49b642d3d4fd960a1","price":"0.96","side":"SELL","size":"593.09"}],"timestamp":"1785204323778"},"payload_hash":"624b34c6a4d4280bb772114f6c9b5cb0d149ecb0b5599a8b469da23f314efba5","raw_frame":"{\"market\":\"0xda6f0e0e93fc8469e0159a166028d017bddbc162b86f66bac90391379603d962\", \"price_changes\":[{\"asset_id\":\"39272994714739463168905443499424551362424437245880253267329605556587274644733\", \"price\":\"0.04\", \"size\":\"593.09\", \"side\":\"BUY\", \"hash\":\"86b67763d5fd8ee761012e2f51612e179b278a5d\", \"best_bid\":\"0.73\", \"best_ask\":\"0.74\"}, {\"asset_id\":\"20893381255801015515826997628594359667013752732428989472914000440642900266717\", \"price\":\"0.96\", \"size\":\"593.09\", \"side\":\"SELL\", \"hash\":\"4630370a9f86a6914b1e1cf49b642d3d4fd960a1\", \"best_bid\":\"0.26\", \"best_ask\":\"0.27\"}], \"timestamp\":\"1785204323778\", \"event_type\":\"price_change\"}","received_at":"2026-07-28T02:05:32.091625Z","schema_version":"clob-market-ws.price_change.v1","sequence":null,"server_hash":null,"server_timestamp":"1785204323778","session_id":"d2757dd6dad94f3b9fe67e8dbf1adc37","source":"clob_market_ws"},"received_at":"2026-07-28T02:05:32.091625Z","record_id":"de24b51c9297fe3b97b340dc2145148a202ea871d72182d124989a71a4aba589","schema_fingerprint":"4aa3821a28b0b7c2400bc59aba4bcc0a76e971dadd19610d3ad38c768e124dc7","schema_version":"edge-lab-recorder.raw.v1","sequence":null,"source":"clob_market_ws"}
{"event_at":"2026-07-28T02:05:23.831000Z","event_fingerprint":"75712edfd2f73bec69a444c64dd4d9ea1820476f71a761467868c344bac82b7f","payload":{"connection_id":"5d29200f65794d4d9ab6ef271f045a9b","event_at":"2026-07-28T02:05:23.831000Z","event_type":"price_change","frame_hash":"2351c94175e7757e098ce9d62ccb234a72e3bc2174d5829ede824eb716c31dad","frame_index":0,"kind":"data","monotonic_ns":306315102194458,"payload":{"event_type":"price_change","market":"0xda6f0e0e93fc8469e0159a166028d017bddbc162b86f66bac90391379603d962","price_changes":[{"asset_id":"39272994714739463168905443499424551362424437245880253267329605556587274644733","best_ask":"0.74","best_bid":"0.73","hash":"4982b1bcf6fef3a03667cd2d12bc705131e84be2","price":"0.01","side":"BUY","size":"5858.02"},{"asset_id":"20893381255801015515826997628594359667013752732428989472914000440642900266717","best_ask":"0.27","best_bid":"0.26","hash":"cf709c975fe264b9778d1e5d38d0d13a25e1f6e6","price":"0.99","side":"SELL","size":"5858.02"}],"timestamp":"1785204323831"},"payload_hash":"640d81c5b574b7db3d6e4585ae6dcabae6d046b59c568912d48ebe47c144e37c","raw_frame":"{\"market\":\"0xda6f0e0e93fc8469e0159a166028d017bddbc162b86f66bac90391379603d962\", \"price_changes\":[{\"asset_id\":\"39272994714739463168905443499424551362424437245880253267329605556587274644733\", \"price\":\"0.01\", \"size\":\"5858.02\", \"side\":\"BUY\", \"hash\":\"4982b1bcf6fef3a03667cd2d12bc705131e84be2\", \"best_bid\":\"0.73\", \"best_ask\":\"0.74\"}, {\"asset_id\":\"20893381255801015515826997628594359667013752732428989472914000440642900266717\", \"price\":\"0.99\", \"size\":\"5858.02\", \"side\":\"SELL\", \"hash\":\"cf709c975fe264b9778d1e5d38d0d13a25e1f6e6\", \"best_bid\":\"0.26\", \"best_ask\":\"0.27\"}], \"timestamp\":\"1785204323831\", \"event_type\":\"price_change\"}","received_at":"2026-07-28T02:05:32.095856Z","schema_version":"clob-market-ws.price_change.v1","sequence":null,"server_hash":null,"server_timestamp":"1785204323831","session_id":"d2757dd6dad94f3b9fe67e8dbf1adc37","source":"clob_market_ws"},"received_at":"2026-07-28T02:05:32.095856Z","record_id":"e825096ba2a3e160d057a59c752783aa85b54b69f8ad33b4ec155a63212f580b","schema_fingerprint":"4aa3821a28b0b7c2400bc59aba4bcc0a76e971dadd19610d3ad38c768e124dc7","schema_version":"edge-lab-recorder.raw.v1","sequence":null,"source":"clob_market_ws"}
{"event_at":"2026-07-28T02:05:23.859000Z","event_fingerprint":"77afcb1c6b4f8fa9d39427465a5213d8ebc37019af6b9e22303df2b8984f4daa","payload":{"connection_id":"5d29200f65794d4d9ab6ef271f045a9b","event_at":"2026-07-28T02:05:23.859000Z","event_type":"price_change","frame_hash":"6afd81b7dbcdeca4bc5cfadf1cac47609ff9f0f4b5fc65125ca3ae2015aaf547","frame_index":0,"kind":"data","monotonic_ns":306315106521208,"payload":{"event_type":"price_change","market":"0xda6f0e0e93fc8469e0159a166028d017bddbc162b86f66bac90391379603d962","price_changes":[{"asset_id":"39272994714739463168905443499424551362424437245880253267329605556587274644733","best_ask":"0.74","best_bid":"0.73","hash":"0667453e19a65da2f2fe837c70ea14092d847008","price":"0.04","side":"BUY","size":"588.09"},{"asset_id":"20893381255801015515826997628594359667013752732428989472914000440642900266717","best_ask":"0.27","best_bid":"0.26","hash":"f4d21b1f2fcf755920dc02f743b17d5c4a07a518","price":"0.96","side":"SELL","size":"588.09"}],"timestamp":"1785204323859"},"payload_hash":"88a3bc9c023a0f9fd74ae33b4bff6915388b5df82127d3b92c1094761c574bc9","raw_frame":"{\"market\":\"0xda6f0e0e93fc8469e0159a166028d017bddbc162b86f66bac90391379603d962\", \"price_changes\":[{\"asset_id\":\"39272994714739463168905443499424551362424437245880253267329605556587274644733\", \"price\":\"0.04\", \"size\":\"588.09\", \"side\":\"BUY\", \"hash\":\"0667453e19a65da2f2fe837c70ea14092d847008\", \"best_bid\":\"0.73\", \"best_ask\":\"0.74\"}, {\"asset_id\":\"20893381255801015515826997628594359667013752732428989472914000440642900266717\", \"price\":\"0.96\", \"size\":\"588.09\", \"side\":\"SELL\", \"hash\":\"f4d21b1f2fcf755920dc02f743b17d5c4a07a518\", \"best_bid\":\"0.26\", \"best_ask\":\"0.27\"}], \"timestamp\":\"1785204323859\", \"event_type\":\"price_change\"}","received_at":"2026-07-28T02:05:32.100183Z","schema_version":"clob-market-ws.price_change.v1","sequence":null,"server_hash":null,"server_timestamp":"1785204323859","session_id":"d2757dd6dad94f3b9fe67e8dbf1adc37","source":"clob_market_ws"},"received_at":"2026-07-28T02:05:32.100183Z","record_id":"26d4f6fc6e3a1c4604359d80a2a65687848c056b8ab84c7fa02017db7652dc95","schema_fingerprint":"4aa3821a28b0b7c2400bc59aba4bcc0a76e971dadd19610d3ad38c768e124dc7","schema_version":"edge-lab-recorder.raw.v1","sequence":null,"source":"clob_market_ws"}
{"event_at":"2026-07-28T02:05:23.860000Z","event_fingerprint":"c9f316b5d5d571022572814ce13bb00591d053f3e8473aa451ef396da11cf5eb","payload":{"connection_id":"5d29200f65794d4d9ab6ef271f045a9b","event_at":"2026-07-28T02:05:23.860000Z","event_type":"price_change","frame_hash":"b9b36f44a3eff48902c917e893737c446bb34ca839cc0ddecb337de8b7433039","frame_index":0,"kind":"data","monotonic_ns":306315110868958,"payload":{"event_type":"price_change","market":"0xda6f0e0e93fc8469e0159a166028d017bddbc162b86f66bac90391379603d962","price_changes":[{"asset_id":"39272994714739463168905443499424551362424437245880253267329605556587274644733","best_ask":"0.74","best_bid":"0.73","hash":"44d17d720a5a341d310c44d080491c31856b2564","price":"0.01","side":"BUY","size":"5853.02"},{"asset_id":"20893381255801015515826997628594359667013752732428989472914000440642900266717","best_ask":"0.27","best_bid":"0.26","hash":"c545235e1b6d11461c0c616c6b8105ae9d6d4937","price":"0.99","side":"SELL","size":"5853.02"}],"timestamp":"1785204323860"},"payload_hash":"6c7640804a91d8f7361368502dbd14df5a428bd68a8a78741b960c9698200c8c","raw_frame":"{\"market\":\"0xda6f0e0e93fc8469e0159a166028d017bddbc162b86f66bac90391379603d962\", \"price_changes\":[{\"asset_id\":\"39272994714739463168905443499424551362424437245880253267329605556587274644733\", \"price\":\"0.01\", \"size\":\"5853.02\", \"side\":\"BUY\", \"hash\":\"44d17d720a5a341d310c44d080491c31856b2564\", \"best_bid\":\"0.73\", \"best_ask\":\"0.74\"}, {\"asset_id\":\"20893381255801015515826997628594359667013752732428989472914000440642900266717\", \"price\":\"0.99\", \"size\":\"5853.02\", \"side\":\"SELL\", \"hash\":\"c545235e1b6d11461c0c616c6b8105ae9d6d4937\", \"best_bid\":\"0.26\", \"best_ask\":\"0.27\"}], \"timestamp\":\"1785204323860\", \"event_type\":\"price_change\"}","received_at":"2026-07-28T02:05:32.104531Z","schema_version":"clob-market-ws.price_change.v1","sequence":null,"server_hash":null,"server_timestamp":"1785204323860","session_id":"d2757dd6dad94f3b9fe67e8dbf1adc37","source":"clob_market_ws"},"received_at":"2026-07-28T02:05:32.104531Z","record_id":"3e341f7b7dac60705e0eaa4d47ecd6c6b0e835500fd165cb01f26aec94e0b62b","schema_fingerprint":"4aa3821a28b0b7c2400bc59aba4bcc0a76e971dadd19610d3ad38c768e124dc7","schema_version":"edge-lab-recorder.raw.v1","sequence":null,"source":"clob_market_ws"}
{"event_at":"2026-07-28T02:05:23.886000Z","event_fingerprint":"9e8c7cc393c6980c42f9bab853babdb9dc51902a6ac46acf594b7f04aaae9601","payload":{"connection_id":"5d29200f65794d4d9ab6ef271f045a9b","event_at":"2026-07-28T02:05:23.886000Z","event_type":"price_change","frame_hash":"a376520045c01a0c6617b74230b377f9d6abfc34956927c6e1a25b80a281e8d5","frame_index":0,"kind":"data","monotonic_ns":306315115017166,"payload":{"event_type":"price_change","market":"0xda6f0e0e93fc8469e0159a166028d017bddbc162b86f66bac90391379603d962","price_changes":[{"asset_id":"20893381255801015515826997628594359667013752732428989472914000440642900266717","best_ask":"0.27","best_bid":"0.26","hash":"c534fd535b0ca59b7148d305ba9591cbb16d376f","price":"0.14","side":"BUY","size":"183.9"},{"asset_id":"39272994714739463168905443499424551362424437245880253267329605556587274644733","best_ask":"0.74","best_bid":"0.73","hash":"6cb40d5a9ccf68e4d8aa3e56fb1d82cd042a54e0","price":"0.86","side":"SELL","size":"183.9"}],"timestamp":"1785204323886"},"payload_hash":"b3eb78d0a76c7ecd45b07762efcaa4e4e6ea3705988f97f1d23ea4a3c335e7bc","raw_frame":"{\"market\":\"0xda6f0e0e93fc8469e0159a166028d017bddbc162b86f66bac90391379603d962\", \"price_changes\":[{\"asset_id\":\"20893381255801015515826997628594359667013752732428989472914000440642900266717\", \"price\":\"0.14\", \"size\":\"183.9\", \"side\":\"BUY\", \"hash\":\"c534fd535b0ca59b7148d305ba9591cbb16d376f\", \"best_bid\":\"0.26\", \"best_ask\":\"0.27\"}, {\"asset_id\":\"39272994714739463168905443499424551362424437245880253267329605556587274644733\", \"price\":\"0.86\", \"size\":\"183.9\", \"side\":\"SELL\", \"hash\":\"6cb40d5a9ccf68e4d8aa3e56fb1d82cd042a54e0\", \"best_bid\":\"0.73\", \"best_ask\":\"0.74\"}], \"timestamp\":\"1785204323886\", \"event_type\":\"price_change\"}","received_at":"2026-07-28T02:05:32.108679Z","schema_version":"clob-market-ws.price_change.v1","sequence":null,"server_hash":null,"server_timestamp":"1785204323886","session_id":"d2757dd6dad94f3b9fe67e8dbf1adc37","source":"clob_market_ws"},"received_at":"2026-07-28T02:05:32.108679Z","record_id":"ce4d39158075fb4bc4262f444517c620c3a75455ed36f4458dd395db08f20bf7","schema_fingerprint":"4aa3821a28b0b7c2400bc59aba4bcc0a76e971dadd19610d3ad38c768e124dc7","schema_version":"edge-lab-recorder.raw.v1","sequence":null,"source":"clob_market_ws"}
{"event_at":"2026-07-28T02:05:23.919000Z","event_fingerprint":"ce3b3c24c31fe6de6e87ebf5911901b5fd7da50f6c1b7b032f5e9b3e89e5ac5a","payload":{"connection_id":"5d29200f65794d4d9ab6ef271f045a9b","event_at":"2026-07-28T02:05:23.919000Z","event_type":"price_change","frame_hash":"be452dcbd5e70a2bf00ffef56dccd2e91a4773047095631f2857072a75b01f43","frame_index":0,"kind":"data","monotonic_ns":306315119001375,"payload":{"event_type":"price_change","market":"0xda6f0e0e93fc8469e0159a166028d017bddbc162b86f66bac90391379603d962","price_changes":[{"asset_id":"20893381255801015515826997628594359667013752732428989472914000440642900266717","best_ask":"0.27","best_bid":"0.26","hash":"aa33c38a7e4bb233c0787d00ed63a9e6bbb99da1","price":"0.13","side":"BUY","size":"224"},{"asset_id":"39272994714739463168905443499424551362424437245880253267329605556587274644733","best_ask":"0.74","best_bid":"0.73","hash":"b60618a18d7cb828f615dfaaf1b1376c4c19749d","price":"0.87","side":"SELL","size":"224"}],"timestamp":"1785204323919"},"payload_hash":"8a2dfa29f3f159046c6be5fc0dec1f9fcff94f46bdd15ce47b251496d7d770c8","raw_frame":"{\"market\":\"0xda6f0e0e93fc8469e0159a166028d017bddbc162b86f66bac90391379603d962\", \"price_changes\":[{\"asset_id\":\"20893381255801015515826997628594359667013752732428989472914000440642900266717\", \"price\":\"0.13\", \"size\":\"224\", \"side\":\"BUY\", \"hash\":\"aa33c38a7e4bb233c0787d00ed63a9e6bbb99da1\", \"best_bid\":\"0.26\", \"best_ask\":\"0.27\"}, {\"asset_id\":\"39272994714739463168905443499424551362424437245880253267329605556587274644733\", \"price\":\"0.87\", \"size\":\"224\", \"side\":\"SELL\", \"hash\":\"b60618a18d7cb828f615dfaaf1b1376c4c19749d\", \"best_bid\":\"0.73\", \"best_ask\":\"0.74\"}], \"timestamp\":\"1785204323919\", \"event_type\":\"price_change\"}","received_at":"2026-07-28T02:05:32.112663Z","schema_version":"clob-market-ws.price_change.v1","sequence":null,"server_hash":null,"server_timestamp":"1785204323919","session_id":"d2757dd6dad94f3b9fe67e8dbf1adc37","source":"clob_market_ws"},"received_at":"2026-07-28T02:05:32.112663Z","record_id":"018ed487b39a0e4c503bdf2dd8c21ad3d9a2dd11267815dab8bedd36a7423285","schema_fingerprint":"4aa3821a28b0b7c2400bc59aba4bcc0a76e971dadd19610d3ad38c768e124dc7","schema_version":"edge-lab-recorder.raw.v1","sequence":null,"source":"clob_market_ws"}
{"event_at":"2026-07-28T02:05:23.933000Z","event_fingerprint":"8c5a1518fba48dfb5aa09be686c56aed5f13a896e1ee652a40aeefdfdf5ef24f","payload":{"connection_id":"5d29200f65794d4d9ab6ef271f045a9b","event_at":"2026-07-28T02:05:23.933000Z","event_type":"price_change","frame_hash":"77e4d9b24cdc8feead636e42622aab32268314bea6c4a548ebf575bba3cce19d","frame_index":0,"kind":"data","monotonic_ns":306315122831625,"payload":{"event_type":"price_change","market":"0xda6f0e0e93fc8469e0159a166028d017bddbc162b86f66bac90391379603d962","price_changes":[{"asset_id":"39272994714739463168905443499424551362424437245880253267329605556587274644733","best_ask":"0.74","best_bid":"0.73","hash":"2cda61c5f6075bbc65b3521ca122bbf87bbc9e2c","price":"0.72","side":"BUY","size":"54.2"},{"asset_id":"20893381255801015515826997628594359667013752732428989472914000440642900266717","best_ask":"0.27","best_bid":"0.26","hash":"d49151bb6eba0f4c11c6e5f4bb60c28adc767aa7","price":"0.28","side":"SELL","size":"54.2"}],"timestamp":"1785204323933"},"payload_hash":"c68fb370ceec14dd261952185133933a7eac4302a8c301e1f32860d6d38dc02b","raw_frame":"{\"market\":\"0xda6f0e0e93fc8469e0159a166028d017bddbc162b86f66bac90391379603d962\", \"price_changes\":[{\"asset_id\":\"39272994714739463168905443499424551362424437245880253267329605556587274644733\", \"price\":\"0.72\", \"size\":\"54.2\", \"side\":\"BUY\", \"hash\":\"2cda61c5f6075bbc65b3521ca122bbf87bbc9e2c\", \"best_bid\":\"0.73\", \"best_ask\":\"0.74\"}, {\"asset_id\":\"20893381255801015515826997628594359667013752732428989472914000440642900266717\", \"price\":\"0.28\", \"size\":\"54.2\", \"side\":\"SELL\", \"hash\":\"d49151bb6eba0f4c11c6e5f4bb60c28adc767aa7\", \"best_bid\":\"0.26\", \"best_ask\":\"0.27\"}], \"timestamp\":\"1785204323933\", \"event_type\":\"price_change\"}","received_at":"2026-07-28T02:05:32.116493Z","schema_version":"clob-market-ws.price_change.v1","sequence":null,"server_hash":null,"server_timestamp":"1785204323933","session_id":"d2757dd6dad94f3b9fe67e8dbf1adc37","source":"clob_market_ws"},"received_at":"2026-07-28T02:05:32.116493Z","record_id":"21be11bf1d9d00618851f2a2ae645bbe4f9732ac2914d3f5207700f57d62afe1","schema_fingerprint":"4aa3821a28b0b7c2400bc59aba4bcc0a76e971dadd19610d3ad38c768e124dc7","schema_version":"edge-lab-recorder.raw.v1","sequence":null,"source":"clob_market_ws"}
{"event_at":"2026-07-28T02:05:23.935000Z","event_fingerprint":"4869c096e82433b9245bd888a63b097abf31f9d2d41f65ff47fb022dac600431","payload":{"connection_id":"5d29200f65794d4d9ab6ef271f045a9b","event_at":"2026-07-28T02:05:23.935000Z","event_type":"price_change","frame_hash":"84ac305506b7a78663512a649b472df68964b02eed49ee3905c86073ad9db3d2","frame_index":0,"kind":"data","monotonic_ns":306315127124791,"payload":{"event_type":"price_change","market":"0xda6f0e0e93fc8469e0159a166028d017bddbc162b86f66bac90391379603d962","price_changes":[{"asset_id":"20893381255801015515826997628594359667013752732428989472914000440642900266717","best_ask":"0.27","best_bid":"0.26","hash":"2bea96e014844ba11a7c279ff3b179f4c6ae7445","price":"0.25","side":"BUY","size":"94.2"},{"asset_id":"39272994714739463168905443499424551362424437245880253267329605556587274644733","best_ask":"0.74","best_bid":"0.73","hash":"e24a83b02c49f5224df15436ea7958a4f9464e2c","price":"0.75","side":"SELL","size":"94.2"}],"timestamp":"1785204323935"},"payload_hash":"7cde3dcd5aebd339929ca9886caf94db14e835fe7e354c542b18e13ce17dacd1","raw_frame":"{\"market\":\"0xda6f0e0e93fc8469e0159a166028d017bddbc162b86f66bac90391379603d962\", \"price_changes\":[{\"asset_id\":\"20893381255801015515826997628594359667013752732428989472914000440642900266717\", \"price\":\"0.25\", \"size\":\"94.2\", \"side\":\"BUY\", \"hash\":\"2bea96e014844ba11a7c279ff3b179f4c6ae7445\", \"best_bid\":\"0.26\", \"best_ask\":\"0.27\"}, {\"asset_id\":\"39272994714739463168905443499424551362424437245880253267329605556587274644733\", \"price\":\"0.75\", \"size\":\"94.2\", \"side\":\"SELL\", \"hash\":\"e24a83b02c49f5224df15436ea7958a4f9464e2c\", \"best_bid\":\"0.73\", \"best_ask\":\"0.74\"}], \"timestamp\":\"1785204323935\", \"event_type\":\"price_change\"}","received_at":"2026-07-28T02:05:32.120786Z","schema_version":"clob-market-ws.price_change.v1","sequence":null,"server_hash":null,"server_timestamp":"1785204323935","session_id":"d2757dd6dad94f3b9fe67e8dbf1adc37","source":"clob_market_ws"},"received_at":"2026-07-28T02:05:32.120786Z","record_id":"6459f03e565a73717ff381ae994ab9e9a047141ada808b64d942d3aa15088d74","schema_fingerprint":"4aa3821a28b0b7c2400bc59aba4bcc0a76e971dadd19610d3ad38c768e124dc7","schema_version":"edge-lab-recorder.raw.v1","sequence":null,"source":"clob_market_ws"}
{"event_at":"2026-07-28T02:05:23.944000Z","event_fingerprint":"7ffb46486e0c4206e376f1c39d6a7b8b43aa3a59aee0a1033b6725f927bf57f1","payload":{"connection_id":"5d29200f65794d4d9ab6ef271f045a9b","event_at":"2026-07-28T02:05:23.944000Z","event_type":"price_change","frame_hash":"0eaa02d933ac5d241db63b35b49ff1930504584c600411b4f2d4a185294bdbc6","frame_index":0,"kind":"data","monotonic_ns":306315131447291,"payload":{"event_type":"price_change","market":"0xda6f0e0e93fc8469e0159a166028d017bddbc162b86f66bac90391379603d962","price_changes":[{"asset_id":"39272994714739463168905443499424551362424437245880253267329605556587274644733","best_ask":"0.74","best_bid":"0.73","hash":"e2171deb7f597d139b210f3978263e0d4eabe4d4","price":"0.01","side":"BUY","size":"5858.02"},{"asset_id":"20893381255801015515826997628594359667013752732428989472914000440642900266717","best_ask":"0.27","best_bid":"0.26","hash":"45165f725905f83299fa07a10f27a17fe1ad0985","price":"0.99","side":"SELL","size":"5858.02"}],"timestamp":"1785204323944"},"payload_hash":"4a14cce6090ee10ad1770cd0879380d1e601c06c32aee2abb9fe0d4349532c39","raw_frame":"{\"market\":\"0xda6f0e0e93fc8469e0159a166028d017bddbc162b86f66bac90391379603d962\", \"price_changes\":[{\"asset_id\":\"39272994714739463168905443499424551362424437245880253267329605556587274644733\", \"price\":\"0.01\", \"size\":\"5858.02\", \"side\":\"BUY\", \"hash\":\"e2171deb7f597d139b210f3978263e0d4eabe4d4\", \"best_bid\":\"0.73\", \"best_ask\":\"0.74\"}, {\"asset_id\":\"20893381255801015515826997628594359667013752732428989472914000440642900266717\", \"price\":\"0.99\", \"size\":\"5858.02\", \"side\":\"SELL\", \"hash\":\"45165f725905f83299fa07a10f27a17fe1ad0985\", \"best_bid\":\"0.26\", \"best_ask\":\"0.27\"}], \"timestamp\":\"1785204323944\", \"event_type\":\"price_change\"}","received_at":"2026-07-28T02:05:32.125109Z","schema_version":"clob-market-ws.price_change.v1","sequence":null,"server_hash":null,"server_timestamp":"1785204323944","session_id":"d2757dd6dad94f3b9fe67e8dbf1adc37","source":"clob_market_ws"},"received_at":"2026-07-28T02:05:32.125109Z","record_id":"5d4516b70772d7c903e25838b14684d13f12963ddbdb26cabb22ca6271a9b2f9","schema_fingerprint":"4aa3821a28b0b7c2400bc59aba4bcc0a76e971dadd19610d3ad38c768e124dc7","schema_version":"edge-lab-recorder.raw.v1","sequence":null,"source":"clob_market_ws"}
{"event_at":"2026-07-28T02:05:23.953000Z","event_fingerprint":"874630ee9a414c426a77b874c92521dac6950c1909e17cec7a297515598e5677","payload":{"connection_id":"5d29200f65794d4d9ab6ef271f045a9b","event_at":"2026-07-28T02:05:23.953000Z","event_type":"price_change","frame_hash":"3a2f4be2eceddcf6c01d11088fe639a2bee5c66dba37d70ed6613221970aef1d","frame_index":0,"kind":"data","monotonic_ns":306315136018875,"payload":{"event_type":"price_change","market":"0xda6f0e0e93fc8469e0159a166028d017bddbc162b86f66bac90391379603d962","price_changes":[{"asset_id":"20893381255801015515826997628594359667013752732428989472914000440642900266717","best_ask":"0.27","best_bid":"0.26","hash":"069708508dd6adce34b4ae7fa565bb3e3dc9b57e","price":"0.27","side":"SELL","size":"24.98"},{"asset_id":"39272994714739463168905443499424551362424437245880253267329605556587274644733","best_ask":"0.74","best_bid":"0.73","hash":"3e97114bb1d561f0f5b980b41a19b2177e1b2c5e","price":"0.73","side":"BUY","size":"24.98"}],"timestamp":"1785204323953"},"payload_hash":"7de20fd28f793a91e2805bd9bea4afa246e112616dac252b9f46294849f4bcd2","raw_frame":"{\"market\":\"0xda6f0e0e93fc8469e0159a166028d017bddbc162b86f66bac90391379603d962\", \"price_changes\":[{\"asset_id\":\"20893381255801015515826997628594359667013752732428989472914000440642900266717\", \"price\":\"0.27\", \"size\":\"24.98\", \"side\":\"SELL\", \"hash\":\"069708508dd6adce34b4ae7fa565bb3e3dc9b57e\", \"best_bid\":\"0.26\", \"best_ask\":\"0.27\"}, {\"asset_id\":\"39272994714739463168905443499424551362424437245880253267329605556587274644733\", \"price\":\"0.73\", \"size\":\"24.98\", \"side\":\"BUY\", \"hash\":\"3e97114bb1d561f0f5b980b41a19b2177e1b2c5e\", \"best_bid\":\"0.73\", \"best_ask\":\"0.74\"}], \"timestamp\":\"1785204323953\", \"event_type\":\"price_change\"}","received_at":"2026-07-28T02:05:32.129681Z","schema_version":"clob-market-ws.price_change.v1","sequence":null,"server_hash":null,"server_timestamp":"1785204323953","session_id":"d2757dd6dad94f3b9fe67e8dbf1adc37","source":"clob_market_ws"},"received_at":"2026-07-28T02:05:32.129681Z","record_id":"c2b53e27f2f9e73b94baf82fc8bbe713f679eda097d6958338f5ce66a3e96953","schema_fingerprint":"4aa3821a28b0b7c2400bc59aba4bcc0a76e971dadd19610d3ad38c768e124dc7","schema_version":"edge-lab-recorder.raw.v1","sequence":null,"source":"clob_market_ws"}
{"event_at":"2026-07-28T02:05:23.957000Z","event_fingerprint":"4c4968107454b7e66892bbea1b3fa51af38603035c8cd6a09a47449a30a12eac","payload":{"connection_id":"5d29200f65794d4d9ab6ef271f045a9b","event_at":"2026-07-28T02:05:23.957000Z","event_type":"price_change","frame_hash":"a349d00b25aa85dac9c87a4f9070804b896a66e188878f2f5474c10761c89c17","frame_index":0,"kind":"data","monotonic_ns":306315140915208,"payload":{"event_type":"price_change","market":"0xda6f0e0e93fc8469e0159a166028d017bddbc162b86f66bac90391379603d962","price_changes":[{"asset_id":"39272994714739463168905443499424551362424437245880253267329605556587274644733","best_ask":"0.74","best_bid":"0.73","hash":"e64df5630ea92aa9d0dee770e994fbd5399067c9","price":"0.73","side":"BUY","size":"49.98"},{"asset_id":"20893381255801015515826997628594359667013752732428989472914000440642900266717","best_ask":"0.27","best_bid":"0.26","hash":"b32466ceaab9cc271b67c473af80693b9c8ae2ba","price":"0.27","side":"SELL","size":"49.98"}],"timestamp":"1785204323957"},"payload_hash":"c4c0dd6e7ea93d38470e14303a2a8a986ad065a464cfbb5d60a4b6dddbe526b8","raw_frame":"{\"market\":\"0xda6f0e0e93fc8469e0159a166028d017bddbc162b86f66bac90391379603d962\", \"price_changes\":[{\"asset_id\":\"39272994714739463168905443499424551362424437245880253267329605556587274644733\", \"price\":\"0.73\", \"size\":\"49.98\", \"side\":\"BUY\", \"hash\":\"e64df5630ea92aa9d0dee770e994fbd5399067c9\", \"best_bid\":\"0.73\", \"best_ask\":\"0.74\"}, {\"asset_id\":\"20893381255801015515826997628594359667013752732428989472914000440642900266717\", \"price\":\"0.27\", \"size\":\"49.98\", \"side\":\"SELL\", \"hash\":\"b32466ceaab9cc271b67c473af80693b9c8ae2ba\", \"best_bid\":\"0.26\", \"best_ask\":\"0.27\"}], \"timestamp\":\"1785204323957\", \"event_type\":\"price_change\"}","received_at":"2026-07-28T02:05:32.134577Z","schema_version":"clob-market-ws.price_change.v1","sequence":null,"server_hash":null,"server_timestamp":"1785204323957","session_id":"d2757dd6dad94f3b9fe67e8dbf1adc37","source":"clob_market_ws"},"received_at":"2026-07-28T02:05:32.134577Z","record_id":"297e371792912127dfa926298c20301605b8021d2deec99099ebc14e083fd02e","schema_fingerprint":"4aa3821a28b0b7c2400bc59aba4bcc0a76e971dadd19610d3ad38c768e124dc7","schema_version":"edge-lab-recorder.raw.v1","sequence":null,"source":"clob_market_ws"}
{"event_at":"2026-07-28T02:05:23.960000Z","event_fingerprint":"21ad097575d4df780172dc5302e8bcc6dc0f16ff37eb27bb437549ae7611ccd8","payload":{"connection_id":"5d29200f65794d4d9ab6ef271f045a9b","event_at":"2026-07-28T02:05:23.960000Z","event_type":"price_change","frame_hash":"8cef8e1bff65a442db38b19de2e5a028a923b616465f1caa87581e3fcb1bbcb7","frame_index":0,"kind":"data","monotonic_ns":306315145242625,"payload":{"event_type":"price_change","market":"0xda6f0e0e93fc8469e0159a166028d017bddbc162b86f66bac90391379603d962","price_changes":[{"asset_id":"20893381255801015515826997628594359667013752732428989472914000440642900266717","best_ask":"0.27","best_bid":"0.26","hash":"505cb13fa4d90e7b297fc86eb706b577490d61fa","price":"0.24","side":"BUY","size":"104.6"},{"asset_id":"39272994714739463168905443499424551362424437245880253267329605556587274644733","best_ask":"0.74","best_bid":"0.73","hash":"3273d0ebd373dc63f9f1d3f70c7a8c5b3af233b0","price":"0.76","side":"SELL","size":"104.6"}],"timestamp":"1785204323960"},"payload_hash":"cdcfe5bef8c10a9d0be825195bece37e307cc351b2d754f04c4e3bf82a3077b7","raw_frame":"{\"market\":\"0xda6f0e0e93fc8469e0159a166028d017bddbc162b86f66bac90391379603d962\", \"price_changes\":[{\"asset_id\":\"20893381255801015515826997628594359667013752732428989472914000440642900266717\", \"price\":\"0.24\", \"size\":\"104.6\", \"side\":\"BUY\", \"hash\":\"505cb13fa4d90e7b297fc86eb706b577490d61fa\", \"best_bid\":\"0.26\", \"best_ask\":\"0.27\"}, {\"asset_id\":\"39272994714739463168905443499424551362424437245880253267329605556587274644733\", \"price\":\"0.76\", \"size\":\"104.6\", \"side\":\"SELL\", \"hash\":\"3273d0ebd373dc63f9f1d3f70c7a8c5b3af233b0\", \"best_bid\":\"0.73\", \"best_ask\":\"0.74\"}], \"timestamp\":\"1785204323960\", \"event_type\":\"price_change\"}","received_at":"2026-07-28T02:05:32.138903Z","schema_version":"clob-market-ws.price_change.v1","sequence":null,"server_hash":null,"server_timestamp":"1785204323960","session_id":"d2757dd6dad94f3b9fe67e8dbf1adc37","source":"clob_market_ws"},"received_at":"2026-07-28T02:05:32.138903Z","record_id":"f4a00061463a194183a0d1081b99a695bc0035a3d4b832fc3189932f2d492146","schema_fingerprint":"4aa3821a28b0b7c2400bc59aba4bcc0a76e971dadd19610d3ad38c768e124dc7","schema_version":"edge-lab-recorder.raw.v1","sequence":null,"source":"clob_market_ws"}
{"event_at":"2026-07-28T02:05:23.994000Z","event_fingerprint":"c499595c0ee6ddb60bab36337a27a52291ce0835d652f4d5b1b4f54312d7a920","payload":{"connection_id":"5d29200f65794d4d9ab6ef271f045a9b","event_at":"2026-07-28T02:05:23.994000Z","event_type":"price_change","frame_hash":"74a05e22e5ce284c1dd9854f0bbda049e9b2c1ada542bde07f189bd4e7921a4a","frame_index":0,"kind":"data","monotonic_ns":306315149564166,"payload":{"event_type":"price_change","market":"0xda6f0e0e93fc8469e0159a166028d017bddbc162b86f66bac90391379603d962","price_changes":[{"asset_id":"39272994714739463168905443499424551362424437245880253267329605556587274644733","best_ask":"0.74","best_bid":"0.73","hash":"027892345e18733ed49bfb2d1432c0bcd2b3b8b4","price":"0.56","side":"BUY","size":"166.18"},{"asset_id":"20893381255801015515826997628594359667013752732428989472914000440642900266717","best_ask":"0.27","best_bid":"0.26","hash":"2c71333e0cfbdf1de4d1404af6d12b7669dd6e8e","price":"0.44","side":"SELL","size":"166.18"}],"timestamp":"1785204323994"},"payload_hash":"dc53c3b51784d72b374b26004a6a31f3462b82b8b1e022dd5e4aaaa4e642f59c","raw_frame":"{\"market\":\"0xda6f0e0e93fc8469e0159a166028d017bddbc162b86f66bac90391379603d962\", \"price_changes\":[{\"asset_id\":\"39272994714739463168905443499424551362424437245880253267329605556587274644733\", \"price\":\"0.56\", \"size\":\"166.18\", \"side\":\"BUY\", \"hash\":\"027892345e18733ed49bfb2d1432c0bcd2b3b8b4\", \"best_bid\":\"0.73\", \"best_ask\":\"0.74\"}, {\"asset_id\":\"20893381255801015515826997628594359667013752732428989472914000440642900266717\", \"price\":\"0.44\", \"size\":\"166.18\", \"side\":\"SELL\", \"hash\":\"2c71333e0cfbdf1de4d1404af6d12b7669dd6e8e\", \"best_bid\":\"0.26\", \"best_ask\":\"0.27\"}], \"timestamp\":\"1785204323994\", \"event_type\":\"price_change\"}","received_at":"2026-07-28T02:05:32.143226Z","schema_version":"clob-market-ws.price_change.v1","sequence":null,"server_hash":null,"server_timestamp":"1785204323994","session_id":"d2757dd6dad94f3b9fe67e8dbf1adc37","source":"clob_market_ws"},"received_at":"2026-07-28T02:05:32.143226Z","record_id":"c96deef760ffc840273ad23834bbbbd2e066b7138c80bd7a2a0692cad0f86c25","schema_fingerprint":"4aa3821a28b0b7c2400bc59aba4bcc0a76e971dadd19610d3ad38c768e124dc7","schema_version":"edge-lab-recorder.raw.v1","sequence":null,"source":"clob_market_ws"}
{"event_at":"2026-07-28T02:05:24.018000Z","event_fingerprint":"f0ae62eb153a2f4bf22e4d3a11469683dd7dd1e682c09d49635ffa1fb1725551","payload":{"connection_id":"5d29200f65794d4d9ab6ef271f045a9b","event_at":"2026-07-28T02:05:24.018000Z","event_type":"price_change","frame_hash":"0dc35e35bd68d443a67782ca094838ecdb33693f07c619ac970df9ac3c441078","frame_index":0,"kind":"data","monotonic_ns":306315153784875,"payload":{"event_type":"price_change","market":"0xda6f0e0e93fc8469e0159a166028d017bddbc162b86f66bac90391379603d962","price_changes":[{"asset_id":"39272994714739463168905443499424551362424437245880253267329605556587274644733","best_ask":"0.74","best_bid":"0.73","hash":"7b3eeda2e7246c0e13baf7b1792b869402e9ac97","price":"0.01","side":"BUY","size":"5853.02"},{"asset_id":"20893381255801015515826997628594359667013752732428989472914000440642900266717","best_ask":"0.27","best_bid":"0.26","hash":"b54d4ff03d0b6b41144dcf1e96a9fcbdfbf99f8e","price":"0.99","side":"SELL","size":"5853.02"}],"timestamp":"1785204324018"},"payload_hash":"158c7dd759a0dc25cfc340cf8e32da2e33bfaebffeb3dd3334b3ed1b15ceb539","raw_frame":"{\"market\":\"0xda6f0e0e93fc8469e0159a166028d017bddbc162b86f66bac90391379603d962\", \"price_changes\":[{\"asset_id\":\"39272994714739463168905443499424551362424437245880253267329605556587274644733\", \"price\":\"0.01\", \"size\":\"5853.02\", \"side\":\"BUY\", \"hash\":\"7b3eeda2e7246c0e13baf7b1792b869402e9ac97\", \"best_bid\":\"0.73\", \"best_ask\":\"0.74\"}, {\"asset_id\":\"20893381255801015515826997628594359667013752732428989472914000440642900266717\", \"price\":\"0.99\", \"size\":\"5853.02\", \"side\":\"SELL\", \"hash\":\"b54d4ff03d0b6b41144dcf1e96a9fcbdfbf99f8e\", \"best_bid\":\"0.26\", \"best_ask\":\"0.27\"}], \"timestamp\":\"1785204324018\", \"event_type\":\"price_change\"}","received_at":"2026-07-28T02:05:32.147447Z","schema_version":"clob-market-ws.price_change.v1","sequence":null,"server_hash":null,"server_timestamp":"1785204324018","session_id":"d2757dd6dad94f3b9fe67e8dbf1adc37","source":"clob_market_ws"},"received_at":"2026-07-28T02:05:32.147447Z","record_id":"b3cd3b13ed0e512203561293181b1fd68984ed9da9226a4072be7b228d303c2d","schema_fingerprint":"4aa3821a28b0b7c2400bc59aba4bcc0a76e971dadd19610d3ad38c768e124dc7","schema_version":"edge-lab-recorder.raw.v1","sequence":null,"source":"clob_market_ws"}
{"event_at":"2026-07-28T02:05:24.023000Z","event_fingerprint":"37ddb6f863d49c96398957cc5946be981be0cd4a360d9a130623a74362be83ed","payload":{"connection_id":"5d29200f65794d4d9ab6ef271f045a9b","event_at":"2026-07-28T02:05:24.023000Z","event_type":"price_change","frame_hash":"aeec303b32f4964fe01eeece07276e37ecd20c752410a7998aea8a0a8d5afe9d","frame_index":0,"kind":"data","monotonic_ns":306315158963333,"payload":{"event_type":"price_change","market":"0xda6f0e0e93fc8469e0159a166028d017bddbc162b86f66bac90391379603d962","price_changes":[{"asset_id":"39272994714739463168905443499424551362424437245880253267329605556587274644733","best_ask":"0.74","best_bid":"0.73","hash":"02a8576080e2f0450bc8727037f3beb234c5d799","price":"0.66","side":"BUY","size":"246"},{"asset_id":"20893381255801015515826997628594359667013752732428989472914000440642900266717","best_ask":"0.27","best_bid":"0.26","hash":"49d2ed03d86a2a65a231eca9981963059271c860","price":"0.34","side":"SELL","size":"246"}],"timestamp":"1785204324023"},"payload_hash":"9863c92a64e9f0d9fe8fe391142ba6e57695e9c1b45f43e0a40501a940468b1c","raw_frame":"{\"market\":\"0xda6f0e0e93fc8469e0159a166028d017bddbc162b86f66bac90391379603d962\", \"price_changes\":[{\"asset_id\":\"39272994714739463168905443499424551362424437245880253267329605556587274644733\", \"price\":\"0.66\", \"size\":\"246\", \"side\":\"BUY\", \"hash\":\"02a8576080e2f0450bc8727037f3beb234c5d799\", \"best_bid\":\"0.73\", \"best_ask\":\"0.74\"}, {\"asset_id\":\"20893381255801015515826997628594359667013752732428989472914000440642900266717\", \"price\":\"0.34\", \"size\":\"246\", \"side\":\"SELL\", \"hash\":\"49d2ed03d86a2a65a231eca9981963059271c860\", \"best_bid\":\"0.26\", \"best_ask\":\"0.27\"}], \"timestamp\":\"1785204324023\", \"event_type\":\"price_change\"}","received_at":"2026-07-28T02:05:32.152624Z","schema_version":"clob-market-ws.price_change.v1","sequence":null,"server_hash":null,"server_timestamp":"1785204324023","session_id":"d2757dd6dad94f3b9fe67e8dbf1adc37","source":"clob_market_ws"},"received_at":"2026-07-28T02:05:32.152624Z","record_id":"97b9d73ba4668fe315b9988f3478d78aa10d9b913ac727d94cf4e3113d0e1bed","schema_fingerprint":"4aa3821a28b0b7c2400bc59aba4bcc0a76e971dadd19610d3ad38c768e124dc7","schema_version":"edge-lab-recorder.raw.v1","sequence":null,"source":"clob_market_ws"}
{"event_at":"2026-07-28T02:05:24.024000Z","event_fingerprint":"3f371e29ccd2abd625118f1b87c3c54ec11b088af694bfd71f79895b8cb382e1","payload":{"connection_id":"5d29200f65794d4d9ab6ef271f045a9b","event_at":"2026-07-28T02:05:24.024000Z","event_type":"price_change","frame_hash":"8496eeb4f755a400b744ca92ad26d5fc1e3edd3179e7511d20f546d53318e1d8","frame_index":0,"kind":"data","monotonic_ns":306315162905750,"payload":{"event_type":"price_change","market":"0xda6f0e0e93fc8469e0159a166028d017bddbc162b86f66bac90391379603d962","price_changes":[{"asset_id":"20893381255801015515826997628594359667013752732428989472914000440642900266717","best_ask":"0.27","best_bid":"0.26","hash":"97dc7c79285b21af7ff6f0f6df721898f6ac790c","price":"0.01","side":"BUY","size":"5917.02"},{"asset_id":"39272994714739463168905443499424551362424437245880253267329605556587274644733","best_ask":"0.74","best_bid":"0.73","hash":"e0e9adb34a96d5c513536542e000f73167492db9","price":"0.99","side":"SELL","size":"5917.02"}],"timestamp":"1785204324024"},"payload_hash":"f4298629a662b1dfc9f8ecc4a4e237d1ad20a9d21c9d7c57513dcb19a4357897","raw_frame":"{\"market\":\"0xda6f0e0e93fc8469e0159a166028d017bddbc162b86f66bac90391379603d962\", \"price_changes\":[{\"asset_id\":\"20893381255801015515826997628594359667013752732428989472914000440642900266717\", \"price\":\"0.01\", \"size\":\"5917.02\", \"side\":\"BUY\", \"hash\":\"97dc7c79285b21af7ff6f0f6df721898f6ac790c\", \"best_bid\":\"0.26\", \"best_ask\":\"0.27\"}, {\"asset_id\":\"39272994714739463168905443499424551362424437245880253267329605556587274644733\", \"price\":\"0.99\", \"size\":\"5917.02\", \"side\":\"SELL\", \"hash\":\"e0e9adb34a96d5c513536542e000f73167492db9\", \"best_bid\":\"0.73\", \"best_ask\":\"0.74\"}], \"timestamp\":\"1785204324024\", \"event_type\":\"price_change\"}","received_at":"2026-07-28T02:05:32.156567Z","schema_version":"clob-market-ws.price_change.v1","sequence":null,"server_hash":null,"server_timestamp":"1785204324024","session_id":"d2757dd6dad94f3b9fe67e8dbf1adc37","source":"clob_market_ws"},"received_at":"2026-07-28T02:05:32.156567Z","record_id":"22644b54726728f341a5aa5a0995716473a3d882148f4a7774945d30438577f7","schema_fingerprint":"4aa3821a28b0b7c2400bc59aba4bcc0a76e971dadd19610d3ad38c768e124dc7","schema_version":"edge-lab-recorder.raw.v1","sequence":null,"source":"clob_market_ws"}
{"event_at":"2026-07-28T02:05:24.025000Z","event_fingerprint":"ad144c5a3df4f7857d19a3967c80624307962675b70144770637528af6e3cdab","payload":{"connection_id":"5d29200f65794d4d9ab6ef271f045a9b","event_at":"2026-07-28T02:05:24.025000Z","event_type":"price_change","frame_hash":"1dc4336de68766404e1abc55b15d88466ebda5525e3d6ec51d0dd7b17441c778","frame_index":0,"kind":"data","monotonic_ns":306315166669750,"payload":{"event_type":"price_change","market":"0xda6f0e0e93fc8469e0159a166028d017bddbc162b86f66bac90391379603d962","price_changes":[{"asset_id":"20893381255801015515826997628594359667013752732428989472914000440642900266717","best_ask":"0.27","best_bid":"0.26","hash":"0bb6aab99da2fc05951453162f38575c03448d3c","price":"0.01","side":"BUY","size":"5922.02"},{"asset_id":"39272994714739463168905443499424551362424437245880253267329605556587274644733","best_ask":"0.74","best_bid":"0.73","hash":"077490cd9d035fa6b0ad3a164ddcc1cfe05a4dc7","price":"0.99","side":"SELL","size":"5922.02"}],"timestamp":"1785204324025"},"payload_hash":"f4ba5d8dbf2ac9becf28842c8c4ebcdcdb80d6765214f3cce18a08b435f31702","raw_frame":"{\"market\":\"0xda6f0e0e93fc8469e0159a166028d017bddbc162b86f66bac90391379603d962\", \"price_changes\":[{\"asset_id\":\"20893381255801015515826997628594359667013752732428989472914000440642900266717\", \"price\":\"0.01\", \"size\":\"5922.02\", \"side\":\"BUY\", \"hash\":\"0bb6aab99da2fc05951453162f38575c03448d3c\", \"best_bid\":\"0.26\", \"best_ask\":\"0.27\"}, {\"asset_id\":\"39272994714739463168905443499424551362424437245880253267329605556587274644733\", \"price\":\"0.99\", \"size\":\"5922.02\", \"side\":\"SELL\", \"hash\":\"077490cd9d035fa6b0ad3a164ddcc1cfe05a4dc7\", \"best_bid\":\"0.73\", \"best_ask\":\"0.74\"}], \"timestamp\":\"1785204324025\", \"event_type\":\"price_change\"}","received_at":"2026-07-28T02:05:32.160330Z","schema_version":"clob-market-ws.price_change.v1","sequence":null,"server_hash":null,"server_timestamp":"1785204324025","session_id":"d2757dd6dad94f3b9fe67e8dbf1adc37","source":"clob_market_ws"},"received_at":"2026-07-28T02:05:32.160330Z","record_id":"117a3880894a5c9fcae54198f3e29f81172d0068a0baedbebfea506eac318dcf","schema_fingerprint":"4aa3821a28b0b7c2400bc59aba4bcc0a76e971dadd19610d3ad38c768e124dc7","schema_version":"edge-lab-recorder.raw.v1","sequence":null,"source":"clob_market_ws"}
{"event_at":"2026-07-28T02:05:24.036000Z","event_fingerprint":"cc2c300efd2a74b4c48ebb711ac8b0a9ba65c5924e762de3be47fcd3dc8b49fe","payload":{"connection_id":"5d29200f65794d4d9ab6ef271f045a9b","event_at":"2026-07-28T02:05:24.036000Z","event_type":"price_change","frame_hash":"7bf135c32103c8a2a685f8d2b13d1ac48e5e5b0677ddce20c10c61094c9d0467","frame_index":0,"kind":"data","monotonic_ns":306315170870333,"payload":{"event_type":"price_change","market":"0xda6f0e0e93fc8469e0159a166028d017bddbc162b86f66bac90391379603d962","price_changes":[{"asset_id":"39272994714739463168905443499424551362424437245880253267329605556587274644733","best_ask":"0.74","best_bid":"0.73","hash":"08aaba1e9f3090a053b673f48f3e74f0dbdf2bd7","price":"0.73","side":"BUY","size":"24.98"},{"asset_id":"20893381255801015515826997628594359667013752732428989472914000440642900266717","best_ask":"0.27","best_bid":"0.26","hash":"23c6a160f5c8e3c97eeef5b3239727f0414b82a0","price":"0.27","side":"SELL","size":"24.98"}],"timestamp":"1785204324036"},"payload_hash":"fdfab4dabb38e70a4913d43333539dd4066bf6e4e5f39fd5d7169a5fee2c77aa","raw_frame":"{\"market\":\"0xda6f0e0e93fc8469e0159a166028d017bddbc162b86f66bac90391379603d962\", \"price_changes\":[{\"asset_id\":\"39272994714739463168905443499424551362424437245880253267329605556587274644733\", \"price\":\"0.73\", \"size\":\"24.98\", \"side\":\"BUY\", \"hash\":\"08aaba1e9f3090a053b673f48f3e74f0dbdf2bd7\", \"best_bid\":\"0.73\", \"best_ask\":\"0.74\"}, {\"asset_id\":\"20893381255801015515826997628594359667013752732428989472914000440642900266717\", \"price\":\"0.27\", \"size\":\"24.98\", \"side\":\"SELL\", \"hash\":\"23c6a160f5c8e3c97eeef5b3239727f0414b82a0\", \"best_bid\":\"0.26\", \"best_ask\":\"0.27\"}], \"timestamp\":\"1785204324036\", \"event_type\":\"price_change\"}","received_at":"2026-07-28T02:05:32.164532Z","schema_version":"clob-market-ws.price_change.v1","sequence":null,"server_hash":null,"server_timestamp":"1785204324036","session_id":"d2757dd6dad94f3b9fe67e8dbf1adc37","source":"clob_market_ws"},"received_at":"2026-07-28T02:05:32.164532Z","record_id":"9b837a09330779d91cdf9b99711bd5a6d4582817449e79824d85c30c6e0a2cca","schema_fingerprint":"4aa3821a28b0b7c2400bc59aba4bcc0a76e971dadd19610d3ad38c768e124dc7","schema_version":"edge-lab-recorder.raw.v1","sequence":null,"source":"clob_market_ws"}
{"event_at":"2026-07-28T02:05:24.039000Z","event_fingerprint":"c90badbdb1865c25d61009c927236a2daa08b3216f7a58efd104697f964ada40","payload":{"connection_id":"5d29200f65794d4d9ab6ef271f045a9b","event_at":"2026-07-28T02:05:24.039000Z","event_type":"price_change","frame_hash":"a41b0e3668720a6e0d2d726f8c4fe7a9d68b279d87e835f009de1594c66512be","frame_index":0,"kind":"data","monotonic_ns":306315175193291,"payload":{"event_type":"price_change","market":"0xda6f0e0e93fc8469e0159a166028d017bddbc162b86f66bac90391379603d962","price_changes":[{"asset_id":"20893381255801015515826997628594359667013752732428989472914000440642900266717","best_ask":"0.27","best_bid":"0.26","hash":"0bcbed3ff6dff3b0160f0b4d82a4d3e6f9a4bd1d","price":"0.24","side":"BUY","size":"79.6"},{"asset_id":"39272994714739463168905443499424551362424437245880253267329605556587274644733","best_ask":"0.74","best_bid":"0.73","hash":"0fa0e0a15d6a67968601a50a6f1085659302e8ac","price":"0.76","side":"SELL","size":"79.6"}],"timestamp":"1785204324039"},"payload_hash":"10d78cda60ed5c20c84263c0f02458a8fd1c35efeecc64d54ec801618beb53ca","raw_frame":"{\"market\":\"0xda6f0e0e93fc8469e0159a166028d017bddbc162b86f66bac90391379603d962\", \"price_changes\":[{\"asset_id\":\"20893381255801015515826997628594359667013752732428989472914000440642900266717\", \"price\":\"0.24\", \"size\":\"79.6\", \"side\":\"BUY\", \"hash\":\"0bcbed3ff6dff3b0160f0b4d82a4d3e6f9a4bd1d\", \"best_bid\":\"0.26\", \"best_ask\":\"0.27\"}, {\"asset_id\":\"39272994714739463168905443499424551362424437245880253267329605556587274644733\", \"price\":\"0.76\", \"size\":\"79.6\", \"side\":\"SELL\", \"hash\":\"0fa0e0a15d6a67968601a50a6f1085659302e8ac\", \"best_bid\":\"0.73\", \"best_ask\":\"0.74\"}], \"timestamp\":\"1785204324039\", \"event_type\":\"price_change\"}","received_at":"2026-07-28T02:05:32.168854Z","schema_version":"clob-market-ws.price_change.v1","sequence":null,"server_hash":null,"server_timestamp":"1785204324039","session_id":"d2757dd6dad94f3b9fe67e8dbf1adc37","source":"clob_market_ws"},"received_at":"2026-07-28T02:05:32.168854Z","record_id":"ab97cc3857da94f4a48db7228ffdec7d18ce716eeb1a82d940e110a13cd4625a","schema_fingerprint":"4aa3821a28b0b7c2400bc59aba4bcc0a76e971dadd19610d3ad38c768e124dc7","schema_version":"edge-lab-recorder.raw.v1","sequence":null,"source":"clob_market_ws"}
{"event_at":"2026-07-28T02:05:24.048000Z","event_fingerprint":"2cdf4ded273d2ea42af0e773aa6eb40c47cd6d69be8166b7f971a9c256cb2d71","payload":{"connection_id":"5d29200f65794d4d9ab6ef271f045a9b","event_at":"2026-07-28T02:05:24.048000Z","event_type":"price_change","frame_hash":"327d3cb482a8de5e7ef8c8be4e30b079db3bc5eedda627bea87831b49a450408","frame_index":0,"kind":"data","monotonic_ns":306315179499083,"payload":{"event_type":"price_change","market":"0xda6f0e0e93fc8469e0159a166028d017bddbc162b86f66bac90391379603d962","price_changes":[{"asset_id":"20893381255801015515826997628594359667013752732428989472914000440642900266717","best_ask":"0.27","best_bid":"0.26","hash":"7d5c1baab4652a079bbbd4b1e45e525863ff4737","price":"0.01","side":"BUY","size":"5917.02"},{"asset_id":"39272994714739463168905443499424551362424437245880253267329605556587274644733","best_ask":"0.74","best_bid":"0.73","hash":"ef0c5a10110ba4644bfafc75083425d90e7928df","price":"0.99","side":"SELL","size":"5917.02"}],"timestamp":"1785204324048"},"payload_hash":"a18e2a4d6a92fb246172ce67d99b4b8e61a9389965c9f9302209079371cb15a8","raw_frame":"{\"market\":\"0xda6f0e0e93fc8469e0159a166028d017bddbc162b86f66bac90391379603d962\", \"price_changes\":[{\"asset_id\":\"20893381255801015515826997628594359667013752732428989472914000440642900266717\", \"price\":\"0.01\", \"size\":\"5917.02\", \"side\":\"BUY\", \"hash\":\"7d5c1baab4652a079bbbd4b1e45e525863ff4737\", \"best_bid\":\"0.26\", \"best_ask\":\"0.27\"}, {\"asset_id\":\"39272994714739463168905443499424551362424437245880253267329605556587274644733\", \"price\":\"0.99\", \"size\":\"5917.02\", \"side\":\"SELL\", \"hash\":\"ef0c5a10110ba4644bfafc75083425d90e7928df\", \"best_bid\":\"0.73\", \"best_ask\":\"0.74\"}], \"timestamp\":\"1785204324048\", \"event_type\":\"price_change\"}","received_at":"2026-07-28T02:05:32.173158Z","schema_version":"clob-market-ws.price_change.v1","sequence":null,"server_hash":null,"server_timestamp":"1785204324048","session_id":"d2757dd6dad94f3b9fe67e8dbf1adc37","source":"clob_market_ws"},"received_at":"2026-07-28T02:05:32.173158Z","record_id":"a14240185408a3338f0d16ece4fe2f8b7f57b077f172c20faa579720f44653df","schema_fingerprint":"4aa3821a28b0b7c2400bc59aba4bcc0a76e971dadd19610d3ad38c768e124dc7","schema_version":"edge-lab-recorder.raw.v1","sequence":null,"source":"clob_market_ws"}
{"event_at":"2026-07-28T02:05:24.113000Z","event_fingerprint":"b2ef103e502eb0de03a8c23b687f0d75476ee704ff08199db5f7656eca6d9183","payload":{"connection_id":"5d29200f65794d4d9ab6ef271f045a9b","event_at":"2026-07-28T02:05:24.113000Z","event_type":"price_change","frame_hash":"bd27e2d3a71d492a18e194857964f9082bb63b23abfef3a60b0027c3f61b53ac","frame_index":0,"kind":"data","monotonic_ns":306315183756875,"payload":{"event_type":"price_change","market":"0xda6f0e0e93fc8469e0159a166028d017bddbc162b86f66bac90391379603d962","price_changes":[{"asset_id":"39272994714739463168905443499424551362424437245880253267329605556587274644733","best_ask":"0.74","best_bid":"0.73","hash":"562167f0096cc4e318ec76eb36b01ca17362406e","price":"0.01","side":"BUY","size":"5858.02"},{"asset_id":"20893381255801015515826997628594359667013752732428989472914000440642900266717","best_ask":"0.27","best_bid":"0.26","hash":"c7fb4c6259755795c54996c7acd952c8c1a14338","price":"0.99","side":"SELL","size":"5858.02"}],"timestamp":"1785204324113"},"payload_hash":"c509f157ba7bc4ff45e719a54e6165fb03aa7d527e1fd50d8dd33443f48a4740","raw_frame":"{\"market\":\"0xda6f0e0e93fc8469e0159a166028d017bddbc162b86f66bac90391379603d962\", \"price_changes\":[{\"asset_id\":\"39272994714739463168905443499424551362424437245880253267329605556587274644733\", \"price\":\"0.01\", \"size\":\"5858.02\", \"side\":\"BUY\", \"hash\":\"562167f0096cc4e318ec76eb36b01ca17362406e\", \"best_bid\":\"0.73\", \"best_ask\":\"0.74\"}, {\"asset_id\":\"20893381255801015515826997628594359667013752732428989472914000440642900266717\", \"price\":\"0.99\", \"size\":\"5858.02\", \"side\":\"SELL\", \"hash\":\"c7fb4c6259755795c54996c7acd952c8c1a14338\", \"best_bid\":\"0.26\", \"best_ask\":\"0.27\"}], \"timestamp\":\"1785204324113\", \"event_type\":\"price_change\"}","received_at":"2026-07-28T02:05:32.177418Z","schema_version":"clob-market-ws.price_change.v1","sequence":null,"server_hash":null,"server_timestamp":"1785204324113","session_id":"d2757dd6dad94f3b9fe67e8dbf1adc37","source":"clob_market_ws"},"received_at":"2026-07-28T02:05:32.177418Z","record_id":"efd574bebbaf492c911fa64c704c1ee79f02503f331ae67ebc8dff304970fc3c","schema_fingerprint":"4aa3821a28b0b7c2400bc59aba4bcc0a76e971dadd19610d3ad38c768e124dc7","schema_version":"edge-lab-recorder.raw.v1","sequence":null,"source":"clob_market_ws"}
{"event_at":"2026-07-28T02:05:24.115000Z","event_fingerprint":"7debf115788022f29d652b40b4c4ddb177a9f286b3a50c97a0891ec52fd29eef","payload":{"connection_id":"5d29200f65794d4d9ab6ef271f045a9b","event_at":"2026-07-28T02:05:24.115000Z","event_type":"price_change","frame_hash":"c7e302a65b1931b900eb6591b406c0c261284b80180b3be2b817e80e741a1199","frame_index":0,"kind":"data","monotonic_ns":306315187962166,"payload":{"event_type":"price_change","market":"0xda6f0e0e93fc8469e0159a166028d017bddbc162b86f66bac90391379603d962","price_changes":[{"asset_id":"20893381255801015515826997628594359667013752732428989472914000440642900266717","best_ask":"0.27","best_bid":"0.26","hash":"9cc0ac1925a86587b4b29ad05a5ebd01622b55f1","price":"0.01","side":"BUY","size":"5912.02"},{"asset_id":"39272994714739463168905443499424551362424437245880253267329605556587274644733","best_ask":"0.74","best_bid":"0.73","hash":"9c63ede84d7f2ef46098aa9468a25fb1a4ed4712","price":"0.99","side":"SELL","size":"5912.02"}],"timestamp":"1785204324115"},"payload_hash":"885b37321714dda68a10a058d9d55b794cdf95d196b1e166ddbda87ed7b11acd","raw_frame":"{\"market\":\"0xda6f0e0e93fc8469e0159a166028d017bddbc162b86f66bac90391379603d962\", \"price_changes\":[{\"asset_id\":\"20893381255801015515826997628594359667013752732428989472914000440642900266717\", \"price\":\"0.01\", \"size\":\"5912.02\", \"side\":\"BUY\", \"hash\":\"9cc0ac1925a86587b4b29ad05a5ebd01622b55f1\", \"best_bid\":\"0.26\", \"best_ask\":\"0.27\"}, {\"asset_id\":\"39272994714739463168905443499424551362424437245880253267329605556587274644733\", \"price\":\"0.99\", \"size\":\"5912.02\", \"side\":\"SELL\", \"hash\":\"9c63ede84d7f2ef46098aa9468a25fb1a4ed4712\", \"best_bid\":\"0.73\", \"best_ask\":\"0.74\"}], \"timestamp\":\"1785204324115\", \"event_type\":\"price_change\"}","received_at":"2026-07-28T02:05:32.181623Z","schema_version":"clob-market-ws.price_change.v1","sequence":null,"server_hash":null,"server_timestamp":"1785204324115","session_id":"d2757dd6dad94f3b9fe67e8dbf1adc37","source":"clob_market_ws"},"received_at":"2026-07-28T02:05:32.181623Z","record_id":"fa7ce84a1ff38dc5d5bc02811ddaea2c51856d61fc80f61c4ad88ad7e2c04e22","schema_fingerprint":"4aa3821a28b0b7c2400bc59aba4bcc0a76e971dadd19610d3ad38c768e124dc7","schema_version":"edge-lab-recorder.raw.v1","sequence":null,"source":"clob_market_ws"}
{"event_at":"2026-07-28T02:05:24.131000Z","event_fingerprint":"82e50a73cbee69db25b4794527004312b443b68dc3fa5e6fb70d5ae6f1c68158","payload":{"connection_id":"5d29200f65794d4d9ab6ef271f045a9b","event_at":"2026-07-28T02:05:24.131000Z","event_type":"price_change","frame_hash":"8f05c8b375f9241f5304e5eb65c377be023460a927142ac0da7b5159f3ef77fa","frame_index":0,"kind":"data","monotonic_ns":306315192233875,"payload":{"event_type":"price_change","market":"0xda6f0e0e93fc8469e0159a166028d017bddbc162b86f66bac90391379603d962","price_changes":[{"asset_id":"39272994714739463168905443499424551362424437245880253267329605556587274644733","best_ask":"0.74","best_bid":"0.73","hash":"2c74107d9ec0db73a6d892acf7d473e1e2aea92e","price":"0.01","side":"BUY","size":"5853.02"},{"asset_id":"20893381255801015515826997628594359667013752732428989472914000440642900266717","best_ask":"0.27","best_bid":"0.26","hash":"56143c44d3fe2746ce855563dd7ec7d9661fa9bc","price":"0.99","side":"SELL","size":"5853.02"}],"timestamp":"1785204324131"},"payload_hash":"9ebc5dd1c7ffbed9876446d66bd42eac1f004749e9cc4abf9addb56d34105626","raw_frame":"{\"market\":\"0xda6f0e0e93fc8469e0159a166028d017bddbc162b86f66bac90391379603d962\", \"price_changes\":[{\"asset_id\":\"39272994714739463168905443499424551362424437245880253267329605556587274644733\", \"price\":\"0.01\", \"size\":\"5853.02\", \"side\":\"BUY\", \"hash\":\"2c74107d9ec0db73a6d892acf7d473e1e2aea92e\", \"best_bid\":\"0.73\", \"best_ask\":\"0.74\"}, {\"asset_id\":\"20893381255801015515826997628594359667013752732428989472914000440642900266717\", \"price\":\"0.99\", \"size\":\"5853.02\", \"side\":\"SELL\", \"hash\":\"56143c44d3fe2746ce855563dd7ec7d9661fa9bc\", \"best_bid\":\"0.26\", \"best_ask\":\"0.27\"}], \"timestamp\":\"1785204324131\", \"event_type\":\"price_change\"}","received_at":"2026-07-28T02:05:32.185894Z","schema_version":"clob-market-ws.price_change.v1","sequence":null,"server_hash":null,"server_timestamp":"1785204324131","session_id":"d2757dd6dad94f3b9fe67e8dbf1adc37","source":"clob_market_ws"},"received_at":"2026-07-28T02:05:32.185894Z","record_id":"c1214ef67b147f0c79027578fca27e69c78fb1cffca35c8f8074ba1e6fae402a","schema_fingerprint":"4aa3821a28b0b7c2400bc59aba4bcc0a76e971dadd19610d3ad38c768e124dc7","schema_version":"edge-lab-recorder.raw.v1","sequence":null,"source":"clob_market_ws"}
{"event_at":"2026-07-28T02:05:24.139000Z","event_fingerprint":"e437feac5de18fbb53e7ad6a4afa7269625de7aaaac2df5ffb8dee2abd4c2460","payload":{"connection_id":"5d29200f65794d4d9ab6ef271f045a9b","event_at":"2026-07-28T02:05:24.139000Z","event_type":"price_change","frame_hash":"de12acc19b04de6583cc0df0c1f22c1952b52da1cdf5c72778b9d9f9826a855e","frame_index":0,"kind":"data","monotonic_ns":306315196415208,"payload":{"event_type":"price_change","market":"0xda6f0e0e93fc8469e0159a166028d017bddbc162b86f66bac90391379603d962","price_changes":[{"asset_id":"20893381255801015515826997628594359667013752732428989472914000440642900266717","best_ask":"0.27","best_bid":"0.26","hash":"2077a1f7a76081fe6c75283cc25099218e9e8d7a","price":"0.25","side":"BUY","size":"119.2"},{"asset_id":"39272994714739463168905443499424551362424437245880253267329605556587274644733","best_ask":"0.74","best_bid":"0.73","hash":"8c9f21b80d77bbbc977bca1eaaa78b380211219d","price":"0.75","side":"SELL","size":"119.2"}],"timestamp":"1785204324139"},"payload_hash":"90c96c3734fd875a810c6d19d69bd93d874475a19e7959bd5eb5bd90e7edd7db","raw_frame":"{\"market\":\"0xda6f0e0e93fc8469e0159a166028d017bddbc162b86f66bac90391379603d962\", \"price_changes\":[{\"asset_id\":\"20893381255801015515826997628594359667013752732428989472914000440642900266717\", \"price\":\"0.25\", \"size\":\"119.2\", \"side\":\"BUY\", \"hash\":\"2077a1f7a76081fe6c75283cc25099218e9e8d7a\", \"best_bid\":\"0.26\", \"best_ask\":\"0.27\"}, {\"asset_id\":\"39272994714739463168905443499424551362424437245880253267329605556587274644733\", \"price\":\"0.75\", \"size\":\"119.2\", \"side\":\"SELL\", \"hash\":\"8c9f21b80d77bbbc977bca1eaaa78b380211219d\", \"best_bid\":\"0.73\", \"best_ask\":\"0.74\"}], \"timestamp\":\"1785204324139\", \"event_type\":\"price_change\"}","received_at":"2026-07-28T02:05:32.190075Z","schema_version":"clob-market-ws.price_change.v1","sequence":null,"server_hash":null,"server_timestamp":"1785204324139","session_id":"d2757dd6dad94f3b9fe67e8dbf1adc37","source":"clob_market_ws"},"received_at":"2026-07-28T02:05:32.190075Z","record_id":"67f61e65e305387bbf4d9b3ec5befd9599ade2d5cd0d26580238737dc2937024","schema_fingerprint":"4aa3821a28b0b7c2400bc59aba4bcc0a76e971dadd19610d3ad38c768e124dc7","schema_version":"edge-lab-recorder.raw.v1","sequence":null,"source":"clob_market_ws"}
{"event_at":"2026-07-28T02:05:24.139000Z","event_fingerprint":"5c850e891f04491fa5fa73b63cefe65cd3209c9db0da52c88ccfdeb706b8f976","payload":{"connection_id":"5d29200f65794d4d9ab6ef271f045a9b","event_at":"2026-07-28T02:05:24.139000Z","event_type":"price_change","frame_hash":"89a45d77df5901654638269a3f8c3a9b0b56a90e143f0238bac3649ea182f5e6","frame_index":0,"kind":"data","monotonic_ns":306315200580000,"payload":{"event_type":"price_change","market":"0xda6f0e0e93fc8469e0159a166028d017bddbc162b86f66bac90391379603d962","price_changes":[{"asset_id":"39272994714739463168905443499424551362424437245880253267329605556587274644733","best_ask":"0.74","best_bid":"0.73","hash":"238ae2fb29078fb147fdf164073b41d4a61d9079","price":"0.04","side":"BUY","size":"593.09"},{"asset_id":"20893381255801015515826997628594359667013752732428989472914000440642900266717","best_ask":"0.27","best_bid":"0.26","hash":"9a7fc9e9fef9f6872d21ecd534b1ae5e84ea7ed0","price":"0.96","side":"SELL","size":"593.09"}],"timestamp":"1785204324139"},"payload_hash":"3cc4ae5f007e2d226afc1101ab495210c350e750edf7f796c4b119b277c8140a","raw_frame":"{\"market\":\"0xda6f0e0e93fc8469e0159a166028d017bddbc162b86f66bac90391379603d962\", \"price_changes\":[{\"asset_id\":\"39272994714739463168905443499424551362424437245880253267329605556587274644733\", \"price\":\"0.04\", \"size\":\"593.09\", \"side\":\"BUY\", \"hash\":\"238ae2fb29078fb147fdf164073b41d4a61d9079\", \"best_bid\":\"0.73\", \"best_ask\":\"0.74\"}, {\"asset_id\":\"20893381255801015515826997628594359667013752732428989472914000440642900266717\", \"price\":\"0.96\", \"size\":\"593.09\", \"side\":\"SELL\", \"hash\":\"9a7fc9e9fef9f6872d21ecd534b1ae5e84ea7ed0\", \"best_bid\":\"0.26\", \"best_ask\":\"0.27\"}], \"timestamp\":\"1785204324139\", \"event_type\":\"price_change\"}","received_at":"2026-07-28T02:05:32.194240Z","schema_version":"clob-market-ws.price_change.v1","sequence":null,"server_hash":null,"server_timestamp":"1785204324139","session_id":"d2757dd6dad94f3b9fe67e8dbf1adc37","source":"clob_market_ws"},"received_at":"2026-07-28T02:05:32.194240Z","record_id":"2792cbb39cf99fa2f9b0d50bab950a69e25ab3b7dd6fb2fd8d97fe72436fe49d","schema_fingerprint":"4aa3821a28b0b7c2400bc59aba4bcc0a76e971dadd19610d3ad38c768e124dc7","schema_version":"edge-lab-recorder.raw.v1","sequence":null,"source":"clob_market_ws"}
{"event_at":"2026-07-28T02:05:24.141000Z","event_fingerprint":"8b9725a19bc2d3236ca5abce91a8ba11c3e47142cf5df5930c2dcdcf19943624","payload":{"connection_id":"5d29200f65794d4d9ab6ef271f045a9b","event_at":"2026-07-28T02:05:24.141000Z","event_type":"price_change","frame_hash":"e1155ca7274c02feff222f9c47c04a65ba8d5560e577b7b32dc3b1a413239ad5","frame_index":0,"kind":"data","monotonic_ns":306315204840625,"payload":{"event_type":"price_change","market":"0xda6f0e0e93fc8469e0159a166028d017bddbc162b86f66bac90391379603d962","price_changes":[{"asset_id":"39272994714739463168905443499424551362424437245880253267329605556587274644733","best_ask":"0.74","best_bid":"0.73","hash":"4e4597160de3672566f187e4f64c2732184d0074","price":"0.72","side":"BUY","size":"79.2"},{"asset_id":"20893381255801015515826997628594359667013752732428989472914000440642900266717","best_ask":"0.27","best_bid":"0.26","hash":"ee04eef2999358fb41f84dd2c82000ea80aa8150","price":"0.28","side":"SELL","size":"79.2"}],"timestamp":"1785204324141"},"payload_hash":"2a0d1e7d4cf3e38b4fdcabe72549ee7a4fb9113e10ffd3b5e6aa50efd57db2dd","raw_frame":"{\"market\":\"0xda6f0e0e93fc8469e0159a166028d017bddbc162b86f66bac90391379603d962\", \"price_changes\":[{\"asset_id\":\"39272994714739463168905443499424551362424437245880253267329605556587274644733\", \"price\":\"0.72\", \"size\":\"79.2\", \"side\":\"BUY\", \"hash\":\"4e4597160de3672566f187e4f64c2732184d0074\", \"best_bid\":\"0.73\", \"best_ask\":\"0.74\"}, {\"asset_id\":\"20893381255801015515826997628594359667013752732428989472914000440642900266717\", \"price\":\"0.28\", \"size\":\"79.2\", \"side\":\"SELL\", \"hash\":\"ee04eef2999358fb41f84dd2c82000ea80aa8150\", \"best_bid\":\"0.26\", \"best_ask\":\"0.27\"}], \"timestamp\":\"1785204324141\", \"event_type\":\"price_change\"}","received_at":"2026-07-28T02:05:32.198500Z","schema_version":"clob-market-ws.price_change.v1","sequence":null,"server_hash":null,"server_timestamp":"1785204324141","session_id":"d2757dd6dad94f3b9fe67e8dbf1adc37","source":"clob_market_ws"},"received_at":"2026-07-28T02:05:32.198500Z","record_id":"71a9bd62f33a7e0dddc94aee15f6ef5872ff4cf2f69ec4a0f49423bc062750ca","schema_fingerprint":"4aa3821a28b0b7c2400bc59aba4bcc0a76e971dadd19610d3ad38c768e124dc7","schema_version":"edge-lab-recorder.raw.v1","sequence":null,"source":"clob_market_ws"}
{"event_at":"2026-07-28T02:05:24.153000Z","event_fingerprint":"e33861cf9185b5a82829ea16897a53fe71c794e52d9cc658900e745d9fe67127","payload":{"connection_id":"5d29200f65794d4d9ab6ef271f045a9b","event_at":"2026-07-28T02:05:24.153000Z","event_type":"price_change","frame_hash":"88767cf4371d08f66cc5446d9d6ade4e9706a5c14f1237f3ad74a3785dcb63e4","frame_index":0,"kind":"data","monotonic_ns":306315209005625,"payload":{"event_type":"price_change","market":"0xda6f0e0e93fc8469e0159a166028d017bddbc162b86f66bac90391379603d962","price_changes":[{"asset_id":"39272994714739463168905443499424551362424437245880253267329605556587274644733","best_ask":"0.74","best_bid":"0.73","hash":"054970e43e93fa2d070bf362fb857d3711bed65f","price":"0.63","side":"BUY","size":"199"},{"asset_id":"20893381255801015515826997628594359667013752732428989472914000440642900266717","best_ask":"0.27","best_bid":"0.26","hash":"9f6fc1ae14e1c81c2e56337d947be57fe58b327b","price":"0.37","side":"SELL","size":"199"}],"timestamp":"1785204324153"},"payload_hash":"0eb13786d8660eced1cc9a3324afbd3058a448577df364e97967e13c865eac05","raw_frame":"{\"market\":\"0xda6f0e0e93fc8469e0159a166028d017bddbc162b86f66bac90391379603d962\", \"price_changes\":[{\"asset_id\":\"39272994714739463168905443499424551362424437245880253267329605556587274644733\", \"price\":\"0.63\", \"size\":\"199\", \"side\":\"BUY\", \"hash\":\"054970e43e93fa2d070bf362fb857d3711bed65f\", \"best_bid\":\"0.73\", \"best_ask\":\"0.74\"}, {\"asset_id\":\"20893381255801015515826997628594359667013752732428989472914000440642900266717\", \"price\":\"0.37\", \"size\":\"199\", \"side\":\"SELL\", \"hash\":\"9f6fc1ae14e1c81c2e56337d947be57fe58b327b\", \"best_bid\":\"0.26\", \"best_ask\":\"0.27\"}], \"timestamp\":\"1785204324153\", \"event_type\":\"price_change\"}","received_at":"2026-07-28T02:05:32.202667Z","schema_version":"clob-market-ws.price_change.v1","sequence":null,"server_hash":null,"server_timestamp":"1785204324153","session_id":"d2757dd6dad94f3b9fe67e8dbf1adc37","source":"clob_market_ws"},"received_at":"2026-07-28T02:05:32.202667Z","record_id":"732ef37f77b1fcafce1dcdc00bedb3667e427b925ba2a07fd29adc75153c4fe5","schema_fingerprint":"4aa3821a28b0b7c2400bc59aba4bcc0a76e971dadd19610d3ad38c768e124dc7","schema_version":"edge-lab-recorder.raw.v1","sequence":null,"source":"clob_market_ws"}
{"event_at":"2026-07-28T02:05:24.183000Z","event_fingerprint":"3c5477ae4da27a5ca5efa821454cd8b55b1f4d50763620fb878a1fbab36501f3","payload":{"connection_id":"5d29200f65794d4d9ab6ef271f045a9b","event_at":"2026-07-28T02:05:24.183000Z","event_type":"price_change","frame_hash":"054925654224f126e908076edd8ac05b37ce9866554fe17dd0e4ab7fa48e2dd1","frame_index":0,"kind":"data","monotonic_ns":306315211866708,"payload":{"event_type":"price_change","market":"0xda6f0e0e93fc8469e0159a166028d017bddbc162b86f66bac90391379603d962","price_changes":[{"asset_id":"39272994714739463168905443499424551362424437245880253267329605556587274644733","best_ask":"0.74","best_bid":"0.73","hash":"702a65416d254b2ab9b9ba435c65f72ab46a5b72","price":"0.64","side":"BUY","size":"227.5"},{"asset_id":"20893381255801015515826997628594359667013752732428989472914000440642900266717","best_ask":"0.27","best_bid":"0.26","hash":"82b7dbf67acef13575ef75068998d5af2bdee435","price":"0.36","side":"SELL","size":"227.5"}],"timestamp":"1785204324183"},"payload_hash":"3e4cd081437f9e03af76f82440737aaf9e41d75a7762da9dd85922eabfb7b386","raw_frame":"{\"market\":\"0xda6f0e0e93fc8469e0159a166028d017bddbc162b86f66bac90391379603d962\", \"price_changes\":[{\"asset_id\":\"39272994714739463168905443499424551362424437245880253267329605556587274644733\", \"price\":\"0.64\", \"size\":\"227.5\", \"side\":\"BUY\", \"hash\":\"702a65416d254b2ab9b9ba435c65f72ab46a5b72\", \"best_bid\":\"0.73\", \"best_ask\":\"0.74\"}, {\"asset_id\":\"20893381255801015515826997628594359667013752732428989472914000440642900266717\", \"price\":\"0.36\", \"size\":\"227.5\", \"side\":\"SELL\", \"hash\":\"82b7dbf67acef13575ef75068998d5af2bdee435\", \"best_bid\":\"0.26\", \"best_ask\":\"0.27\"}], \"timestamp\":\"1785204324183\", \"event_type\":\"price_change\"}","received_at":"2026-07-28T02:05:32.205526Z","schema_version":"clob-market-ws.price_change.v1","sequence":null,"server_hash":null,"server_timestamp":"1785204324183","session_id":"d2757dd6dad94f3b9fe67e8dbf1adc37","source":"clob_market_ws"},"received_at":"2026-07-28T02:05:32.205526Z","record_id":"351147edde23ef73b9fd95ce978d8891afd2217f1599c40dc7af0650eb4be9ff","schema_fingerprint":"4aa3821a28b0b7c2400bc59aba4bcc0a76e971dadd19610d3ad38c768e124dc7","schema_version":"edge-lab-recorder.raw.v1","sequence":null,"source":"clob_market_ws"}
{"event_at":"2026-07-28T02:05:24.209000Z","event_fingerprint":"66489e85385226381c8fb1da0cd0d70c7a0a936cd84d1d9addbda14659bcf19e","payload":{"connection_id":"5d29200f65794d4d9ab6ef271f045a9b","event_at":"2026-07-28T02:05:24.209000Z","event_type":"price_change","frame_hash":"466b9699cece00c180756cdc85f8aff4fb30f58f529a7f2ec6eca4dd2ce276fe","frame_index":0,"kind":"data","monotonic_ns":306315216120625,"payload":{"event_type":"price_change","market":"0xda6f0e0e93fc8469e0159a166028d017bddbc162b86f66bac90391379603d962","price_changes":[{"asset_id":"39272994714739463168905443499424551362424437245880253267329605556587274644733","best_ask":"0.74","best_bid":"0.73","hash":"6491de225c72c11504a60a49346593bd349f2fab","price":"0.04","side":"BUY","size":"588.09"},{"asset_id":"20893381255801015515826997628594359667013752732428989472914000440642900266717","best_ask":"0.27","best_bid":"0.26","hash":"9b3118c762f4a8d34bdaa30d630f533bf9778a41","price":"0.96","side":"SELL","size":"588.09"}],"timestamp":"1785204324209"},"payload_hash":"56951fa7d74a0c973a608f53ee47a2baa9933665b5a610bba203c407968f8cc6","raw_frame":"{\"market\":\"0xda6f0e0e93fc8469e0159a166028d017bddbc162b86f66bac90391379603d962\", \"price_changes\":[{\"asset_id\":\"39272994714739463168905443499424551362424437245880253267329605556587274644733\", \"price\":\"0.04\", \"size\":\"588.09\", \"side\":\"BUY\", \"hash\":\"6491de225c72c11504a60a49346593bd349f2fab\", \"best_bid\":\"0.73\", \"best_ask\":\"0.74\"}, {\"asset_id\":\"20893381255801015515826997628594359667013752732428989472914000440642900266717\", \"price\":\"0.96\", \"size\":\"588.09\", \"side\":\"SELL\", \"hash\":\"9b3118c762f4a8d34bdaa30d630f533bf9778a41\", \"best_bid\":\"0.26\", \"best_ask\":\"0.27\"}], \"timestamp\":\"1785204324209\", \"event_type\":\"price_change\"}","received_at":"2026-07-28T02:05:32.209781Z","schema_version":"clob-market-ws.price_change.v1","sequence":null,"server_hash":null,"server_timestamp":"1785204324209","session_id":"d2757dd6dad94f3b9fe67e8dbf1adc37","source":"clob_market_ws"},"received_at":"2026-07-28T02:05:32.209781Z","record_id":"3047f4c57d15191fa309aa85ad3b7a7c1504c7f322671d7237fcd26e7c56d6d5","schema_fingerprint":"4aa3821a28b0b7c2400bc59aba4bcc0a76e971dadd19610d3ad38c768e124dc7","schema_version":"edge-lab-recorder.raw.v1","sequence":null,"source":"clob_market_ws"}
{"event_at":"2026-07-28T02:05:24.285000Z","event_fingerprint":"a124ad4801ecc8ac57f49ea7be89e29777425e6c15e09cc8e3a7541b0aa7e08f","payload":{"connection_id":"5d29200f65794d4d9ab6ef271f045a9b","event_at":"2026-07-28T02:05:24.285000Z","event_type":"price_change","frame_hash":"c7ddba2aa81ec56a51f5ae173f0c213613be483e93f25850e0855c8372776ef2","frame_index":0,"kind":"data","monotonic_ns":306315218968458,"payload":{"event_type":"price_change","market":"0xda6f0e0e93fc8469e0159a166028d017bddbc162b86f66bac90391379603d962","price_changes":[{"asset_id":"39272994714739463168905443499424551362424437245880253267329605556587274644733","best_ask":"0.74","best_bid":"0.73","hash":"80bd7f7a02f6d01727f056315afcf711070829a8","price":"0.7","side":"BUY","size":"87.5"},{"asset_id":"20893381255801015515826997628594359667013752732428989472914000440642900266717","best_ask":"0.27","best_bid":"0.26","hash":"265cd765e3acd526cb25fea648f7f50d66a34e47","price":"0.3","side":"SELL","size":"87.5"}],"timestamp":"1785204324285"},"payload_hash":"127b7bbd28b8e6c729c630659a99b2f7c97bc4f4e9922e83cd8d5deed26c17e2","raw_frame":"{\"market\":\"0xda6f0e0e93fc8469e0159a166028d017bddbc162b86f66bac90391379603d962\", \"price_changes\":[{\"asset_id\":\"39272994714739463168905443499424551362424437245880253267329605556587274644733\", \"price\":\"0.7\", \"size\":\"87.5\", \"side\":\"BUY\", \"hash\":\"80bd7f7a02f6d01727f056315afcf711070829a8\", \"best_bid\":\"0.73\", \"best_ask\":\"0.74\"}, {\"asset_id\":\"20893381255801015515826997628594359667013752732428989472914000440642900266717\", \"price\":\"0.3\", \"size\":\"87.5\", \"side\":\"SELL\", \"hash\":\"265cd765e3acd526cb25fea648f7f50d66a34e47\", \"best_bid\":\"0.26\", \"best_ask\":\"0.27\"}], \"timestamp\":\"1785204324285\", \"event_type\":\"price_change\"}","received_at":"2026-07-28T02:05:32.212628Z","schema_version":"clob-market-ws.price_change.v1","sequence":null,"server_hash":null,"server_timestamp":"1785204324285","session_id":"d2757dd6dad94f3b9fe67e8dbf1adc37","source":"clob_market_ws"},"received_at":"2026-07-28T02:05:32.212628Z","record_id":"9ada5f9ea523ea49aafd73dc9020ddcf24116f2e692a5058b6c3d8713438b124","schema_fingerprint":"4aa3821a28b0b7c2400bc59aba4bcc0a76e971dadd19610d3ad38c768e124dc7","schema_version":"edge-lab-recorder.raw.v1","sequence":null,"source":"clob_market_ws"}
{"event_at":"2026-07-28T02:05:24.286000Z","event_fingerprint":"5c998b61c2adab5fe7cc7ce8c7abf2b8ca087e9d98061a9bfa9e3a1fcf09cf3c","payload":{"connection_id":"5d29200f65794d4d9ab6ef271f045a9b","event_at":"2026-07-28T02:05:24.286000Z","event_type":"price_change","frame_hash":"d50f55a9065f95260b1d7c992b33c38ac77e5a5824cf649be40af6f9862f0d6f","frame_index":0,"kind":"data","monotonic_ns":306315223245083,"payload":{"event_type":"price_change","market":"0xda6f0e0e93fc8469e0159a166028d017bddbc162b86f66bac90391379603d962","price_changes":[{"asset_id":"39272994714739463168905443499424551362424437245880253267329605556587274644733","best_ask":"0.74","best_bid":"0.73","hash":"bce227a291944170f2f59ec93ed986284bd56950","price":"0.71","side":"BUY","size":"97.57"},{"asset_id":"20893381255801015515826997628594359667013752732428989472914000440642900266717","best_ask":"0.27","best_bid":"0.26","hash":"d7a4a87fa9786409fab7a6791c35a36e44e104e3","price":"0.29","side":"SELL","size":"97.57"}],"timestamp":"1785204324286"},"payload_hash":"9f170b0fcedbfee0d08b8a6e1e2324e318e4d958ec8a4842e3a0f915bb6f5f3b","raw_frame":"{\"market\":\"0xda6f0e0e93fc8469e0159a166028d017bddbc162b86f66bac90391379603d962\", \"price_changes\":[{\"asset_id\":\"39272994714739463168905443499424551362424437245880253267329605556587274644733\", \"price\":\"0.71\", \"size\":\"97.57\", \"side\":\"BUY\", \"hash\":\"bce227a291944170f2f59ec93ed986284bd56950\", \"best_bid\":\"0.73\", \"best_ask\":\"0.74\"}, {\"asset_id\":\"20893381255801015515826997628594359667013752732428989472914000440642900266717\", \"price\":\"0.29\", \"size\":\"97.57\", \"side\":\"SELL\", \"hash\":\"d7a4a87fa9786409fab7a6791c35a36e44e104e3\", \"best_bid\":\"0.26\", \"best_ask\":\"0.27\"}], \"timestamp\":\"1785204324286\", \"event_type\":\"price_change\"}","received_at":"2026-07-28T02:05:32.216905Z","schema_version":"clob-market-ws.price_change.v1","sequence":null,"server_hash":null,"server_timestamp":"1785204324286","session_id":"d2757dd6dad94f3b9fe67e8dbf1adc37","source":"clob_market_ws"},"received_at":"2026-07-28T02:05:32.216905Z","record_id":"1fe138017c02ba9f221c52a96b8e6144861d9aee0b047dc7cec76f2ea7ff6b84","schema_fingerprint":"4aa3821a28b0b7c2400bc59aba4bcc0a76e971dadd19610d3ad38c768e124dc7","schema_version":"edge-lab-recorder.raw.v1","sequence":null,"source":"clob_market_ws"}
{"event_at":"2026-07-28T02:05:24.287000Z","event_fingerprint":"80afa997cdcad6ded61ce3690731ff60fe0e037c0bd14515b94b0ea8010284ae","payload":{"connection_id":"5d29200f65794d4d9ab6ef271f045a9b","event_at":"2026-07-28T02:05:24.287000Z","event_type":"price_change","frame_hash":"2973036e679f3c4902d3c964270c8a5eb96d209a7e5aff39b1fbe02fe77abe38","frame_index":0,"kind":"data","monotonic_ns":306315227488583,"payload":{"event_type":"price_change","market":"0xda6f0e0e93fc8469e0159a166028d017bddbc162b86f66bac90391379603d962","price_changes":[{"asset_id":"39272994714739463168905443499424551362424437245880253267329605556587274644733","best_ask":"0.74","best_bid":"0.73","hash":"dafbbd6235872e341ed5438ba1a03bb502661b80","price":"0.69","side":"BUY","size":"116.13"},{"asset_id":"20893381255801015515826997628594359667013752732428989472914000440642900266717","best_ask":"0.27","best_bid":"0.26","hash":"6b283feaddeff3fde531511c6fb09edc3a85c449","price":"0.31","side":"SELL","size":"116.13"}],"timestamp":"1785204324287"},"payload_hash":"269660c8ca991ac9ec0d88eacc7358940520751afdef1b339e5a3847b72b85e1","raw_frame":"{\"market\":\"0xda6f0e0e93fc8469e0159a166028d017bddbc162b86f66bac90391379603d962\", \"price_changes\":[{\"asset_id\":\"39272994714739463168905443499424551362424437245880253267329605556587274644733\", \"price\":\"0.69\", \"size\":\"116.13\", \"side\":\"BUY\", \"hash\":\"dafbbd6235872e341ed5438ba1a03bb502661b80\", \"best_bid\":\"0.73\", \"best_ask\":\"0.74\"}, {\"asset_id\":\"20893381255801015515826997628594359667013752732428989472914000440642900266717\", \"price\":\"0.31\", \"size\":\"116.13\", \"side\":\"SELL\", \"hash\":\"6b283feaddeff3fde531511c6fb09edc3a85c449\", \"best_bid\":\"0.26\", \"best_ask\":\"0.27\"}], \"timestamp\":\"1785204324287\", \"event_type\":\"price_change\"}","received_at":"2026-07-28T02:05:32.221149Z","schema_version":"clob-market-ws.price_change.v1","sequence":null,"server_hash":null,"server_timestamp":"1785204324287","session_id":"d2757dd6dad94f3b9fe67e8dbf1adc37","source":"clob_market_ws"},"received_at":"2026-07-28T02:05:32.221149Z","record_id":"6376bd96b93b26f7d6cea6c951a16487608f05398396fc5497ec9aac7b378795","schema_fingerprint":"4aa3821a28b0b7c2400bc59aba4bcc0a76e971dadd19610d3ad38c768e124dc7","schema_version":"edge-lab-recorder.raw.v1","sequence":null,"source":"clob_market_ws"}
{"event_at":"2026-07-28T02:05:24.313000Z","event_fingerprint":"13609067e73999828d0f152c376431cee717a611c2dad3c60ba6a4285d82dc43","payload":{"connection_id":"5d29200f65794d4d9ab6ef271f045a9b","event_at":"2026-07-28T02:05:24.313000Z","event_type":"price_change","frame_hash":"e0994b88b7a74c22c32a770289775670e513e578b4238ebc09424fd4d44bcf21","frame_index":0,"kind":"data","monotonic_ns":306315231752125,"payload":{"event_type":"price_change","market":"0xda6f0e0e93fc8469e0159a166028d017bddbc162b86f66bac90391379603d962","price_changes":[{"asset_id":"39272994714739463168905443499424551362424437245880253267329605556587274644733","best_ask":"0.74","best_bid":"0.73","hash":"2136510af007e5d8e8bd58f097d774caad1c2571","price":"0.01","side":"BUY","size":"5858.02"},{"asset_id":"20893381255801015515826997628594359667013752732428989472914000440642900266717","best_ask":"0.27","best_bid":"0.26","hash":"a121aee6e58ad074f9f3c1f50bdde94a86fb0cf8","price":"0.99","side":"SELL","size":"5858.02"}],"timestamp":"1785204324313"},"payload_hash":"c8cb29755ffe5ed29bd601d23647f3385d12ed0cf120e2e2d18e19ca6347c5e2","raw_frame":"{\"market\":\"0xda6f0e0e93fc8469e0159a166028d017bddbc162b86f66bac90391379603d962\", \"price_changes\":[{\"asset_id\":\"39272994714739463168905443499424551362424437245880253267329605556587274644733\", \"price\":\"0.01\", \"size\":\"5858.02\", \"side\":\"BUY\", \"hash\":\"2136510af007e5d8e8bd58f097d774caad1c2571\", \"best_bid\":\"0.73\", \"best_ask\":\"0.74\"}, {\"asset_id\":\"20893381255801015515826997628594359667013752732428989472914000440642900266717\", \"price\":\"0.99\", \"size\":\"5858.02\", \"side\":\"SELL\", \"hash\":\"a121aee6e58ad074f9f3c1f50bdde94a86fb0cf8\", \"best_bid\":\"0.26\", \"best_ask\":\"0.27\"}], \"timestamp\":\"1785204324313\", \"event_type\":\"price_change\"}","received_at":"2026-07-28T02:05:32.225413Z","schema_version":"clob-market-ws.price_change.v1","sequence":null,"server_hash":null,"server_timestamp":"1785204324313","session_id":"d2757dd6dad94f3b9fe67e8dbf1adc37","source":"clob_market_ws"},"received_at":"2026-07-28T02:05:32.225413Z","record_id":"5c87cc22b1ed507ee5bad18ad24409ab0434a5ead0fc37c33029379e258b17d7","schema_fingerprint":"4aa3821a28b0b7c2400bc59aba4bcc0a76e971dadd19610d3ad38c768e124dc7","schema_version":"edge-lab-recorder.raw.v1","sequence":null,"source":"clob_market_ws"}
{"event_at":"2026-07-28T02:05:24.314000Z","event_fingerprint":"f54417361a9bad94ef4f39fbc4aa194e76ff1eb828f8c4d78a49d24d32a3226d","payload":{"connection_id":"5d29200f65794d4d9ab6ef271f045a9b","event_at":"2026-07-28T02:05:24.314000Z","event_type":"price_change","frame_hash":"9c280ae0c5aefb0ba0ba7ef5a1e880a2207f52148bf859531004a3ab37ac27bb","frame_index":0,"kind":"data","monotonic_ns":306315236099916,"payload":{"event_type":"price_change","market":"0xda6f0e0e93fc8469e0159a166028d017bddbc162b86f66bac90391379603d962","price_changes":[{"asset_id":"39272994714739463168905443499424551362424437245880253267329605556587274644733","best_ask":"0.74","best_bid":"0.73","hash":"2f8ede31890c1ae3274e1ba4ca6429de0b3a1f9f","price":"0.64","side":"BUY","size":"220"},{"asset_id":"20893381255801015515826997628594359667013752732428989472914000440642900266717","best_ask":"0.27","best_bid":"0.26","hash":"dfa1ba96f3fdcae36e626518049fc5031b4e4af0","price":"0.36","side":"SELL","size":"220"}],"timestamp":"1785204324314"},"payload_hash":"84d843a0ede3146a73d31abc9c571e71ee580f150caa7f7d32a7f2862b0a6341","raw_frame":"{\"market\":\"0xda6f0e0e93fc8469e0159a166028d017bddbc162b86f66bac90391379603d962\", \"price_changes\":[{\"asset_id\":\"39272994714739463168905443499424551362424437245880253267329605556587274644733\", \"price\":\"0.64\", \"size\":\"220\", \"side\":\"BUY\", \"hash\":\"2f8ede31890c1ae3274e1ba4ca6429de0b3a1f9f\", \"best_bid\":\"0.73\", \"best_ask\":\"0.74\"}, {\"asset_id\":\"20893381255801015515826997628594359667013752732428989472914000440642900266717\", \"price\":\"0.36\", \"size\":\"220\", \"side\":\"SELL\", \"hash\":\"dfa1ba96f3fdcae36e626518049fc5031b4e4af0\", \"best_bid\":\"0.26\", \"best_ask\":\"0.27\"}], \"timestamp\":\"1785204324314\", \"event_type\":\"price_change\"}","received_at":"2026-07-28T02:05:32.229760Z","schema_version":"clob-market-ws.price_change.v1","sequence":null,"server_hash":null,"server_timestamp":"1785204324314","session_id":"d2757dd6dad94f3b9fe67e8dbf1adc37","source":"clob_market_ws"},"received_at":"2026-07-28T02:05:32.229760Z","record_id":"b3e472ebf5e21c589e9d479ed447913efd2e5643239213f5ebfce6cf8c745843","schema_fingerprint":"4aa3821a28b0b7c2400bc59aba4bcc0a76e971dadd19610d3ad38c768e124dc7","schema_version":"edge-lab-recorder.raw.v1","sequence":null,"source":"clob_market_ws"}
{"event_at":"2026-07-28T02:05:24.324000Z","event_fingerprint":"f123c6312b7a10cc39a2f5948f4b1e617e3f4d526b96be092b4602a9c57d84c6","payload":{"connection_id":"5d29200f65794d4d9ab6ef271f045a9b","event_at":"2026-07-28T02:05:24.324000Z","event_type":"price_change","frame_hash":"d2aa44532cadd8acd3c4866dcb6abc810a167ab006891e0dd68e83a81a706440","frame_index":0,"kind":"data","monotonic_ns":306315238979750,"payload":{"event_type":"price_change","market":"0xda6f0e0e93fc8469e0159a166028d017bddbc162b86f66bac90391379603d962","price_changes":[{"asset_id":"39272994714739463168905443499424551362424437245880253267329605556587274644733","best_ask":"0.74","best_bid":"0.73","hash":"b8ffd6b3587a97df30a1f84843771e1c894796d0","price":"0.01","side":"BUY","size":"5863.02"},{"asset_id":"20893381255801015515826997628594359667013752732428989472914000440642900266717","best_ask":"0.27","best_bid":"0.26","hash":"a17f6cb44ae2dab312277ce9447901461a8bc34c","price":"0.99","side":"SELL","size":"5863.02"}],"timestamp":"1785204324324"},"payload_hash":"37336aac873df1afa2a72db627465914ee77733fe22aeb7f598f3a3b101ae28e","raw_frame":"{\"market\":\"0xda6f0e0e93fc8469e0159a166028d017bddbc162b86f66bac90391379603d962\", \"price_changes\":[{\"asset_id\":\"39272994714739463168905443499424551362424437245880253267329605556587274644733\", \"price\":\"0.01\", \"size\":\"5863.02\", \"side\":\"BUY\", \"hash\":\"b8ffd6b3587a97df30a1f84843771e1c894796d0\", \"best_bid\":\"0.73\", \"best_ask\":\"0.74\"}, {\"asset_id\":\"20893381255801015515826997628594359667013752732428989472914000440642900266717\", \"price\":\"0.99\", \"size\":\"5863.02\", \"side\":\"SELL\", \"hash\":\"a17f6cb44ae2dab312277ce9447901461a8bc34c\", \"best_bid\":\"0.26\", \"best_ask\":\"0.27\"}], \"timestamp\":\"1785204324324\", \"event_type\":\"price_change\"}","received_at":"2026-07-28T02:05:32.232640Z","schema_version":"clob-market-ws.price_change.v1","sequence":null,"server_hash":null,"server_timestamp":"1785204324324","session_id":"d2757dd6dad94f3b9fe67e8dbf1adc37","source":"clob_market_ws"},"received_at":"2026-07-28T02:05:32.232640Z","record_id":"ae4fca6fb7d067170130531a08818aa56f0110130501600977c6d0f93174ea75","schema_fingerprint":"4aa3821a28b0b7c2400bc59aba4bcc0a76e971dadd19610d3ad38c768e124dc7","schema_version":"edge-lab-recorder.raw.v1","sequence":null,"source":"clob_market_ws"}
{"event_at":"2026-07-28T02:05:24.336000Z","event_fingerprint":"f513aa194709565aa3e0046a07839044f6f875a82b712ee705daeb87f98fc2b6","payload":{"connection_id":"5d29200f65794d4d9ab6ef271f045a9b","event_at":"2026-07-28T02:05:24.336000Z","event_type":"price_change","frame_hash":"c103fa731628117da0a874bbd47414b4ed30995493922a04bef7bc8a3fb5c6e1","frame_index":0,"kind":"data","monotonic_ns":306315243398708,"payload":{"event_type":"price_change","market":"0xda6f0e0e93fc8469e0159a166028d017bddbc162b86f66bac90391379603d962","price_changes":[{"asset_id":"39272994714739463168905443499424551362424437245880253267329605556587274644733","best_ask":"0.74","best_bid":"0.73","hash":"655b69976f9464f512cb6679a0e662266cc04d77","price":"0.72","side":"BUY","size":"54.2"},{"asset_id":"20893381255801015515826997628594359667013752732428989472914000440642900266717","best_ask":"0.27","best_bid":"0.26","hash":"28fb12e3a901c85dff750d919dba502a2fd6e1cc","price":"0.28","side":"SELL","size":"54.2"}],"timestamp":"1785204324336"},"payload_hash":"6fa62236c5ad776a30b5dce4e8e8c5e2b4e7ec3209e706b8b22977d01f374990","raw_frame":"{\"market\":\"0xda6f0e0e93fc8469e0159a166028d017bddbc162b86f66bac90391379603d962\", \"price_changes\":[{\"asset_id\":\"39272994714739463168905443499424551362424437245880253267329605556587274644733\", \"price\":\"0.72\", \"size\":\"54.2\", \"side\":\"BUY\", \"hash\":\"655b69976f9464f512cb6679a0e662266cc04d77\", \"best_bid\":\"0.73\", \"best_ask\":\"0.74\"}, {\"asset_id\":\"20893381255801015515826997628594359667013752732428989472914000440642900266717\", \"price\":\"0.28\", \"size\":\"54.2\", \"side\":\"SELL\", \"hash\":\"28fb12e3a901c85dff750d919dba502a2fd6e1cc\", \"best_bid\":\"0.26\", \"best_ask\":\"0.27\"}], \"timestamp\":\"1785204324336\", \"event_type\":\"price_change\"}","received_at":"2026-07-28T02:05:32.237057Z","schema_version":"clob-market-ws.price_change.v1","sequence":null,"server_hash":null,"server_timestamp":"1785204324336","session_id":"d2757dd6dad94f3b9fe67e8dbf1adc37","source":"clob_market_ws"},"received_at":"2026-07-28T02:05:32.237057Z","record_id":"6069535a497fbc6f5b828efd0e72c22deafc9c7fbfe3498cc67ae7c30a8ce4d8","schema_fingerprint":"4aa3821a28b0b7c2400bc59aba4bcc0a76e971dadd19610d3ad38c768e124dc7","schema_version":"edge-lab-recorder.raw.v1","sequence":null,"source":"clob_market_ws"}
{"event_at":"2026-07-28T02:05:24.347000Z","event_fingerprint":"423a5ece35e101aff16b0096f79a077646f61b9ce81d311260c7d30af86ddc8d","payload":{"connection_id":"5d29200f65794d4d9ab6ef271f045a9b","event_at":"2026-07-28T02:05:24.347000Z","event_type":"price_change","frame_hash":"bbd59bdfe0c971cf2045621da98eca51d8aad4b9e4f12e3d98c89104d626fba1","frame_index":0,"kind":"data","monotonic_ns":306315247111500,"payload":{"event_type":"price_change","market":"0xda6f0e0e93fc8469e0159a166028d017bddbc162b86f66bac90391379603d962","price_changes":[{"asset_id":"39272994714739463168905443499424551362424437245880253267329605556587274644733","best_ask":"0.74","best_bid":"0.73","hash":"deb804e48814eb0372104eb868920aaebfa1f4c6","price":"0.63","side":"BUY","size":"206.5"},{"asset_id":"20893381255801015515826997628594359667013752732428989472914000440642900266717","best_ask":"0.27","best_bid":"0.26","hash":"c9cd89e12d0f116161ff50c332d02220a066b3ce","price":"0.37","side":"SELL","size":"206.5"}],"timestamp":"1785204324347"},"payload_hash":"43c027a08d63a1b0ce56816a45ea58953f12712e723488d68d6e9f502f7dfc53","raw_frame":"{\"market\":\"0xda6f0e0e93fc8469e0159a166028d017bddbc162b86f66bac90391379603d962\", \"price_changes\":[{\"asset_id\":\"39272994714739463168905443499424551362424437245880253267329605556587274644733\", \"price\":\"0.63\", \"size\":\"206.5\", \"side\":\"BUY\", \"hash\":\"deb804e48814eb0372104eb868920aaebfa1f4c6\", \"best_bid\":\"0.73\", \"best_ask\":\"0.74\"}, {\"asset_id\":\"20893381255801015515826997628594359667013752732428989472914000440642900266717\", \"price\":\"0.37\", \"size\":\"206.5\", \"side\":\"SELL\", \"hash\":\"c9cd89e12d0f116161ff50c332d02220a066b3ce\", \"best_bid\":\"0.26\", \"best_ask\":\"0.27\"}], \"timestamp\":\"1785204324347\", \"event_type\":\"price_change\"}","received_at":"2026-07-28T02:05:32.240772Z","schema_version":"clob-market-ws.price_change.v1","sequence":null,"server_hash":null,"server_timestamp":"1785204324347","session_id":"d2757dd6dad94f3b9fe67e8dbf1adc37","source":"clob_market_ws"},"received_at":"2026-07-28T02:05:32.240772Z","record_id":"7eb1e3ef97f35b83ad29c8879264c6fdb1bfa8bca21115530406facff90c5963","schema_fingerprint":"4aa3821a28b0b7c2400bc59aba4bcc0a76e971dadd19610d3ad38c768e124dc7","schema_version":"edge-lab-recorder.raw.v1","sequence":null,"source":"clob_market_ws"}
{"event_at":"2026-07-28T02:05:24.352000Z","event_fingerprint":"64cd11e74eee185bf18d52dba82c1441dd08c2856adc3f7d4c1af6686d2c552a","payload":{"connection_id":"5d29200f65794d4d9ab6ef271f045a9b","event_at":"2026-07-28T02:05:24.352000Z","event_type":"price_change","frame_hash":"8e3623272e45b07ce2b9d389cfad79c9bb163924c14397d7fc5ca55fbd93dcd7","frame_index":0,"kind":"data","monotonic_ns":306315251246875,"payload":{"event_type":"price_change","market":"0xda6f0e0e93fc8469e0159a166028d017bddbc162b86f66bac90391379603d962","price_changes":[{"asset_id":"39272994714739463168905443499424551362424437245880253267329605556587274644733","best_ask":"0.74","best_bid":"0.73","hash":"9aa33cc3b72875e38985ce11ed29e2bdb9e472ea","price":"0.01","side":"BUY","size":"5858.02"},{"asset_id":"20893381255801015515826997628594359667013752732428989472914000440642900266717","best_ask":"0.27","best_bid":"0.26","hash":"cbea135a406bab943bcb7e39fc5fd4ef3fa7f33c","price":"0.99","side":"SELL","size":"5858.02"}],"timestamp":"1785204324352"},"payload_hash":"f39b683b745bac7668229faeb3803e495c038fcb4ae8b2ae9c0419fd88a60f96","raw_frame":"{\"market\":\"0xda6f0e0e93fc8469e0159a166028d017bddbc162b86f66bac90391379603d962\", \"price_changes\":[{\"asset_id\":\"39272994714739463168905443499424551362424437245880253267329605556587274644733\", \"price\":\"0.01\", \"size\":\"5858.02\", \"side\":\"BUY\", \"hash\":\"9aa33cc3b72875e38985ce11ed29e2bdb9e472ea\", \"best_bid\":\"0.73\", \"best_ask\":\"0.74\"}, {\"asset_id\":\"20893381255801015515826997628594359667013752732428989472914000440642900266717\", \"price\":\"0.99\", \"size\":\"5858.02\", \"side\":\"SELL\", \"hash\":\"cbea135a406bab943bcb7e39fc5fd4ef3fa7f33c\", \"best_bid\":\"0.26\", \"best_ask\":\"0.27\"}], \"timestamp\":\"1785204324352\", \"event_type\":\"price_change\"}","received_at":"2026-07-28T02:05:32.244908Z","schema_version":"clob-market-ws.price_change.v1","sequence":null,"server_hash":null,"server_timestamp":"1785204324352","session_id":"d2757dd6dad94f3b9fe67e8dbf1adc37","source":"clob_market_ws"},"received_at":"2026-07-28T02:05:32.244908Z","record_id":"7b03400bb59b580d11b61958001a3aea7811e230f675ed0c2dce83ca4528a3c1","schema_fingerprint":"4aa3821a28b0b7c2400bc59aba4bcc0a76e971dadd19610d3ad38c768e124dc7","schema_version":"edge-lab-recorder.raw.v1","sequence":null,"source":"clob_market_ws"}
{"event_at":"2026-07-28T02:05:24.357000Z","event_fingerprint":"9a48592d056bfe448ad18406f41330d4f43125e454adb2c684fa351c2f3363ef","payload":{"connection_id":"5d29200f65794d4d9ab6ef271f045a9b","event_at":"2026-07-28T02:05:24.357000Z","event_type":"price_change","frame_hash":"aaefe77e165a2e2c6ebbb733c25fb9e61b42f5d62042a40b166a1b1e7446465d","frame_index":0,"kind":"data","monotonic_ns":306315255480166,"payload":{"event_type":"price_change","market":"0xda6f0e0e93fc8469e0159a166028d017bddbc162b86f66bac90391379603d962","price_changes":[{"asset_id":"39272994714739463168905443499424551362424437245880253267329605556587274644733","best_ask":"0.74","best_bid":"0.73","hash":"049a1112ac45dd6c5abce76aab8ce4ae63430826","price":"0.71","side":"BUY","size":"122.57"},{"asset_id":"20893381255801015515826997628594359667013752732428989472914000440642900266717","best_ask":"0.27","best_bid":"0.26","hash":"a7ac94efb50a42988a2187923bd87d1e412479ed","price":"0.29","side":"SELL","size":"122.57"}],"timestamp":"1785204324357"},"payload_hash":"54b1d8b57784a63ad5696bc3630a1cf34db445ef843d1ebf47d49908bce83d4b","raw_frame":"{\"market\":\"0xda6f0e0e93fc8469e0159a166028d017bddbc162b86f66bac90391379603d962\", \"price_changes\":[{\"asset_id\":\"39272994714739463168905443499424551362424437245880253267329605556587274644733\", \"price\":\"0.71\", \"size\":\"122.57\", \"side\":\"BUY\", \"hash\":\"049a1112ac45dd6c5abce76aab8ce4ae63430826\", \"best_bid\":\"0.73\", \"best_ask\":\"0.74\"}, {\"asset_id\":\"20893381255801015515826997628594359667013752732428989472914000440642900266717\", \"price\":\"0.29\", \"size\":\"122.57\", \"side\":\"SELL\", \"hash\":\"a7ac94efb50a42988a2187923bd87d1e412479ed\", \"best_bid\":\"0.26\", \"best_ask\":\"0.27\"}], \"timestamp\":\"1785204324357\", \"event_type\":\"price_change\"}","received_at":"2026-07-28T02:05:32.249141Z","schema_version":"clob-market-ws.price_change.v1","sequence":null,"server_hash":null,"server_timestamp":"1785204324357","session_id":"d2757dd6dad94f3b9fe67e8dbf1adc37","source":"clob_market_ws"},"received_at":"2026-07-28T02:05:32.249141Z","record_id":"bd238350b9db1a86e4e9f626e1131ba076b64f4a2e7bc88ed90c5b6c6c04f0ca","schema_fingerprint":"4aa3821a28b0b7c2400bc59aba4bcc0a76e971dadd19610d3ad38c768e124dc7","schema_version":"edge-lab-recorder.raw.v1","sequence":null,"source":"clob_market_ws"}
{"event_at":"2026-07-28T02:05:24.362000Z","event_fingerprint":"8f90b466e77728003a21cfcd505bfbedfeb7d708031cae6141370f76320750cd","payload":{"connection_id":"5d29200f65794d4d9ab6ef271f045a9b","event_at":"2026-07-28T02:05:24.362000Z","event_type":"price_change","frame_hash":"39f3be7f22aaa87c935524211f89ba269b036d7ba4c8b5d40bda12774e144215","frame_index":0,"kind":"data","monotonic_ns":306315259681916,"payload":{"event_type":"price_change","market":"0xda6f0e0e93fc8469e0159a166028d017bddbc162b86f66bac90391379603d962","price_changes":[{"asset_id":"39272994714739463168905443499424551362424437245880253267329605556587274644733","best_ask":"0.74","best_bid":"0.73","hash":"d717a7a1d150188c29e3539948fe117c9f8759b4","price":"0.01","side":"BUY","size":"5853.02"},{"asset_id":"20893381255801015515826997628594359667013752732428989472914000440642900266717","best_ask":"0.27","best_bid":"0.26","hash":"e9508a6bb65d0edd0ce449e10eb30f242555a093","price":"0.99","side":"SELL","size":"5853.02"}],"timestamp":"1785204324362"},"payload_hash":"ec8f980684730d4cdf989be0c58463e7b085a75a84020a0352576e4a3339d211","raw_frame":"{\"market\":\"0xda6f0e0e93fc8469e0159a166028d017bddbc162b86f66bac90391379603d962\", \"price_changes\":[{\"asset_id\":\"39272994714739463168905443499424551362424437245880253267329605556587274644733\", \"price\":\"0.01\", \"size\":\"5853.02\", \"side\":\"BUY\", \"hash\":\"d717a7a1d150188c29e3539948fe117c9f8759b4\", \"best_bid\":\"0.73\", \"best_ask\":\"0.74\"}, {\"asset_id\":\"20893381255801015515826997628594359667013752732428989472914000440642900266717\", \"price\":\"0.99\", \"size\":\"5853.02\", \"side\":\"SELL\", \"hash\":\"e9508a6bb65d0edd0ce449e10eb30f242555a093\", \"best_bid\":\"0.26\", \"best_ask\":\"0.27\"}], \"timestamp\":\"1785204324362\", \"event_type\":\"price_change\"}","received_at":"2026-07-28T02:05:32.253343Z","schema_version":"clob-market-ws.price_change.v1","sequence":null,"server_hash":null,"server_timestamp":"1785204324362","session_id":"d2757dd6dad94f3b9fe67e8dbf1adc37","source":"clob_market_ws"},"received_at":"2026-07-28T02:05:32.253343Z","record_id":"cc6c37430ad6b6ce649dd19fd2c27349e4ce9c16f353bba6a75f40c730b88841","schema_fingerprint":"4aa3821a28b0b7c2400bc59aba4bcc0a76e971dadd19610d3ad38c768e124dc7","schema_version":"edge-lab-recorder.raw.v1","sequence":null,"source":"clob_market_ws"}
{"event_at":"2026-07-28T02:05:24.386000Z","event_fingerprint":"67a319eda9353d72aa3bd7d366f0d27de35bee607043e21bbfd648c9205d37f8","payload":{"connection_id":"5d29200f65794d4d9ab6ef271f045a9b","event_at":"2026-07-28T02:05:24.386000Z","event_type":"price_change","frame_hash":"cea7652200ed3a0f90e3b208fbe73265f8ab82ab4b7b9eb9d2f7ddc80e08dba9","frame_index":0,"kind":"data","monotonic_ns":306315263898291,"payload":{"event_type":"price_change","market":"0xda6f0e0e93fc8469e0159a166028d017bddbc162b86f66bac90391379603d962","price_changes":[{"asset_id":"39272994714739463168905443499424551362424437245880253267329605556587274644733","best_ask":"0.74","best_bid":"0.73","hash":"e18bc52201da1f6d887716245093ddfcf5e1e333","price":"0.66","side":"BUY","size":"231"},{"asset_id":"20893381255801015515826997628594359667013752732428989472914000440642900266717","best_ask":"0.27","best_bid":"0.26","hash":"ddbe0b6d8c19b99ebd18062a069b1bd9fea0af25","price":"0.34","side":"SELL","size":"231"}],"timestamp":"1785204324386"},"payload_hash":"34a64e59a402e865d4f86179a2a75ecc423a598c5960adcb9c29dad50e95d0dc","raw_frame":"{\"market\":\"0xda6f0e0e93fc8469e0159a166028d017bddbc162b86f66bac90391379603d962\", \"price_changes\":[{\"asset_id\":\"39272994714739463168905443499424551362424437245880253267329605556587274644733\", \"price\":\"0.66\", \"size\":\"231\", \"side\":\"BUY\", \"hash\":\"e18bc52201da1f6d887716245093ddfcf5e1e333\", \"best_bid\":\"0.73\", \"best_ask\":\"0.74\"}, {\"asset_id\":\"20893381255801015515826997628594359667013752732428989472914000440642900266717\", \"price\":\"0.34\", \"size\":\"231\", \"side\":\"SELL\", \"hash\":\"ddbe0b6d8c19b99ebd18062a069b1bd9fea0af25\", \"best_bid\":\"0.26\", \"best_ask\":\"0.27\"}], \"timestamp\":\"1785204324386\", \"event_type\":\"price_change\"}","received_at":"2026-07-28T02:05:32.257559Z","schema_version":"clob-market-ws.price_change.v1","sequence":null,"server_hash":null,"server_timestamp":"1785204324386","session_id":"d2757dd6dad94f3b9fe67e8dbf1adc37","source":"clob_market_ws"},"received_at":"2026-07-28T02:05:32.257559Z","record_id":"92705db45fad0351dba69d0b05b8109bf850fad9babb7fcf0ad0e3cfbb4a2dcd","schema_fingerprint":"4aa3821a28b0b7c2400bc59aba4bcc0a76e971dadd19610d3ad38c768e124dc7","schema_version":"edge-lab-recorder.raw.v1","sequence":null,"source":"clob_market_ws"}
{"event_at":"2026-07-28T02:05:24.419000Z","event_fingerprint":"2ada1fe1a2b9ca13cbda38445780ffa7edf294da16a062e3098db3f560f30881","payload":{"connection_id":"5d29200f65794d4d9ab6ef271f045a9b","event_at":"2026-07-28T02:05:24.419000Z","event_type":"price_change","frame_hash":"c46fe2a5fedfe506192514c1811f28ef66c3e89abb9ee2ec1682f76ec7e716fe","frame_index":0,"kind":"data","monotonic_ns":306315268137166,"payload":{"event_type":"price_change","market":"0xda6f0e0e93fc8469e0159a166028d017bddbc162b86f66bac90391379603d962","price_changes":[{"asset_id":"39272994714739463168905443499424551362424437245880253267329605556587274644733","best_ask":"0.74","best_bid":"0.73","hash":"5deb08a4868e8c37ca797239d6266934b8ecb1ac","price":"0.56","side":"BUY","size":"181.18"},{"asset_id":"20893381255801015515826997628594359667013752732428989472914000440642900266717","best_ask":"0.27","best_bid":"0.26","hash":"fcb6b2914736e653d95a29b8719521d81b3233ef","price":"0.44","side":"SELL","size":"181.18"}],"timestamp":"1785204324419"},"payload_hash":"9c1765d17f90a89dbdc7e6567f840895676fe98a9bdb609ffa8783196eaa3263","raw_frame":"{\"market\":\"0xda6f0e0e93fc8469e0159a166028d017bddbc162b86f66bac90391379603d962\", \"price_changes\":[{\"asset_id\":\"39272994714739463168905443499424551362424437245880253267329605556587274644733\", \"price\":\"0.56\", \"size\":\"181.18\", \"side\":\"BUY\", \"hash\":\"5deb08a4868e8c37ca797239d6266934b8ecb1ac\", \"best_bid\":\"0.73\", \"best_ask\":\"0.74\"}, {\"asset_id\":\"20893381255801015515826997628594359667013752732428989472914000440642900266717\", \"price\":\"0.44\", \"size\":\"181.18\", \"side\":\"SELL\", \"hash\":\"fcb6b2914736e653d95a29b8719521d81b3233ef\", \"best_bid\":\"0.26\", \"best_ask\":\"0.27\"}], \"timestamp\":\"1785204324419\", \"event_type\":\"price_change\"}","received_at":"2026-07-28T02:05:32.261798Z","schema_version":"clob-market-ws.price_change.v1","sequence":null,"server_hash":null,"server_timestamp":"1785204324419","session_id":"d2757dd6dad94f3b9fe67e8dbf1adc37","source":"clob_market_ws"},"received_at":"2026-07-28T02:05:32.261798Z","record_id":"725bcebc22550932c1f81b7a718b8e91cd680fb799fdd5096a2912c88aa01e48","schema_fingerprint":"4aa3821a28b0b7c2400bc59aba4bcc0a76e971dadd19610d3ad38c768e124dc7","schema_version":"edge-lab-recorder.raw.v1","sequence":null,"source":"clob_market_ws"}
{"event_at":"2026-07-28T02:05:24.446000Z","event_fingerprint":"ef5c16b486dc69bddb205753183e81c3316bcb4503fc36697e2d7872317a11a2","payload":{"connection_id":"5d29200f65794d4d9ab6ef271f045a9b","event_at":"2026-07-28T02:05:24.446000Z","event_type":"price_change","frame_hash":"12d871cf638001f4d93d115a242ba3ab088d77d29427a1dc5b258f96446a9b2d","frame_index":0,"kind":"data","monotonic_ns":306315272318000,"payload":{"event_type":"price_change","market":"0xda6f0e0e93fc8469e0159a166028d017bddbc162b86f66bac90391379603d962","price_changes":[{"asset_id":"39272994714739463168905443499424551362424437245880253267329605556587274644733","best_ask":"0.74","best_bid":"0.73","hash":"e0c99687ef9c725fae2092e41ac476e6441684e7","price":"0.03","side":"BUY","size":"648.1"},{"asset_id":"20893381255801015515826997628594359667013752732428989472914000440642900266717","best_ask":"0.27","best_bid":"0.26","hash":"b1ca25ec0ea1922864bf46665c636629f12e46e3","price":"0.97","side":"SELL","size":"648.1"}],"timestamp":"1785204324446"},"payload_hash":"4ea1445359c621c17e0ce43d7996ab19621b1ffb61570e9dcacba06f829b6b1e","raw_frame":"{\"market\":\"0xda6f0e0e93fc8469e0159a166028d017bddbc162b86f66bac90391379603d962\", \"price_changes\":[{\"asset_id\":\"39272994714739463168905443499424551362424437245880253267329605556587274644733\", \"price\":\"0.03\", \"size\":\"648.1\", \"side\":\"BUY\", \"hash\":\"e0c99687ef9c725fae2092e41ac476e6441684e7\", \"best_bid\":\"0.73\", \"best_ask\":\"0.74\"}, {\"asset_id\":\"20893381255801015515826997628594359667013752732428989472914000440642900266717\", \"price\":\"0.97\", \"size\":\"648.1\", \"side\":\"SELL\", \"hash\":\"b1ca25ec0ea1922864bf46665c636629f12e46e3\", \"best_bid\":\"0.26\", \"best_ask\":\"0.27\"}], \"timestamp\":\"1785204324446\", \"event_type\":\"price_change\"}","received_at":"2026-07-28T02:05:32.265979Z","schema_version":"clob-market-ws.price_change.v1","sequence":null,"server_hash":null,"server_timestamp":"1785204324446","session_id":"d2757dd6dad94f3b9fe67e8dbf1adc37","source":"clob_market_ws"},"received_at":"2026-07-28T02:05:32.265979Z","record_id":"d07e4c2d22f7801af72c137b8758fc832c4485b568f022ae8d5ad61948167806","schema_fingerprint":"4aa3821a28b0b7c2400bc59aba4bcc0a76e971dadd19610d3ad38c768e124dc7","schema_version":"edge-lab-recorder.raw.v1","sequence":null,"source":"clob_market_ws"}
{"event_at":"2026-07-28T02:05:24.494000Z","event_fingerprint":"58985b0bcf879f98b92bff8e46194b6c55b0ef5eed731e7f9773d309ae8753ef","payload":{"connection_id":"5d29200f65794d4d9ab6ef271f045a9b","event_at":"2026-07-28T02:05:24.494000Z","event_type":"price_change","frame_hash":"60ae1015f3745d3cf6ed1dbaa6c5fe724aa328031e6daa63c1ba0010dc925f9b","frame_index":0,"kind":"data","monotonic_ns":306315276574916,"payload":{"event_type":"price_change","market":"0xda6f0e0e93fc8469e0159a166028d017bddbc162b86f66bac90391379603d962","price_changes":[{"asset_id":"39272994714739463168905443499424551362424437245880253267329605556587274644733","best_ask":"0.74","best_bid":"0.73","hash":"855a5faca0f56afd47c3302d9b3866cf235b1f4f","price":"0.56","side":"BUY","size":"166.18"},{"asset_id":"20893381255801015515826997628594359667013752732428989472914000440642900266717","best_ask":"0.27","best_bid":"0.26","hash":"abefbe6d57ac65b0d3b7a2a26182b36aa5dc7782","price":"0.44","side":"SELL","size":"166.18"}],"timestamp":"1785204324494"},"payload_hash":"c7d1d15fcc500223dddd2c5422a4e89e5fbce014dc7c43e28e8fd9f32440daef","raw_frame":"{\"market\":\"0xda6f0e0e93fc8469e0159a166028d017bddbc162b86f66bac90391379603d962\", \"price_changes\":[{\"asset_id\":\"39272994714739463168905443499424551362424437245880253267329605556587274644733\", \"price\":\"0.56\", \"size\":\"166.18\", \"side\":\"BUY\", \"hash\":\"855a5faca0f56afd47c3302d9b3866cf235b1f4f\", \"best_bid\":\"0.73\", \"best_ask\":\"0.74\"}, {\"asset_id\":\"20893381255801015515826997628594359667013752732428989472914000440642900266717\", \"price\":\"0.44\", \"size\":\"166.18\", \"side\":\"SELL\", \"hash\":\"abefbe6d57ac65b0d3b7a2a26182b36aa5dc7782\", \"best_bid\":\"0.26\", \"best_ask\":\"0.27\"}], \"timestamp\":\"1785204324494\", \"event_type\":\"price_change\"}","received_at":"2026-07-28T02:05:32.270235Z","schema_version":"clob-market-ws.price_change.v1","sequence":null,"server_hash":null,"server_timestamp":"1785204324494","session_id":"d2757dd6dad94f3b9fe67e8dbf1adc37","source":"clob_market_ws"},"received_at":"2026-07-28T02:05:32.270235Z","record_id":"7edefab1136d2c9d62cd4bbb9d46b95c3354ef02f0dde76ee736667f9ba77fd5","schema_fingerprint":"4aa3821a28b0b7c2400bc59aba4bcc0a76e971dadd19610d3ad38c768e124dc7","schema_version":"edge-lab-recorder.raw.v1","sequence":null,"source":"clob_market_ws"}
{"event_at":"2026-07-28T02:05:24.511000Z","event_fingerprint":"723f8421ce6f9a50901f518dbf615fc3be1519c8102c091ca1b38f0d6986cce0","payload":{"connection_id":"5d29200f65794d4d9ab6ef271f045a9b","event_at":"2026-07-28T02:05:24.511000Z","event_type":"price_change","frame_hash":"c391d40921797077512f3100b70ad85a80d9e654753bcc245dd3a151141ebbba","frame_index":0,"kind":"data","monotonic_ns":306315280810166,"payload":{"event_type":"price_change","market":"0xda6f0e0e93fc8469e0159a166028d017bddbc162b86f66bac90391379603d962","price_changes":[{"asset_id":"39272994714739463168905443499424551362424437245880253267329605556587274644733","best_ask":"0.74","best_bid":"0.73","hash":"09fe5b860576e1754ccd2682f7a76a641e761105","price":"0.01","side":"BUY","size":"5858.02"},{"asset_id":"20893381255801015515826997628594359667013752732428989472914000440642900266717","best_ask":"0.27","best_bid":"0.26","hash":"340558e392511b401abcfe2648ee220cb1be942a","price":"0.99","side":"SELL","size":"5858.02"}],"timestamp":"1785204324511"},"payload_hash":"f1f68b66decded68262be6462e1a6a818f0c4d2ee4c826fdf048fbd657e6e460","raw_frame":"{\"market\":\"0xda6f0e0e93fc8469e0159a166028d017bddbc162b86f66bac90391379603d962\", \"price_changes\":[{\"asset_id\":\"39272994714739463168905443499424551362424437245880253267329605556587274644733\", \"price\":\"0.01\", \"size\":\"5858.02\", \"side\":\"BUY\", \"hash\":\"09fe5b860576e1754ccd2682f7a76a641e761105\", \"best_bid\":\"0.73\", \"best_ask\":\"0.74\"}, {\"asset_id\":\"20893381255801015515826997628594359667013752732428989472914000440642900266717\", \"price\":\"0.99\", \"size\":\"5858.02\", \"side\":\"SELL\", \"hash\":\"340558e392511b401abcfe2648ee220cb1be942a\", \"best_bid\":\"0.26\", \"best_ask\":\"0.27\"}], \"timestamp\":\"1785204324511\", \"event_type\":\"price_change\"}","received_at":"2026-07-28T02:05:32.274471Z","schema_version":"clob-market-ws.price_change.v1","sequence":null,"server_hash":null,"server_timestamp":"1785204324511","session_id":"d2757dd6dad94f3b9fe67e8dbf1adc37","source":"clob_market_ws"},"received_at":"2026-07-28T02:05:32.274471Z","record_id":"c82ec3d910c044107aafa0becaecadae0b1f1f2c20132574642f89ba3dac77b3","schema_fingerprint":"4aa3821a28b0b7c2400bc59aba4bcc0a76e971dadd19610d3ad38c768e124dc7","schema_version":"edge-lab-recorder.raw.v1","sequence":null,"source":"clob_market_ws"}
{"event_at":"2026-07-28T02:05:24.518000Z","event_fingerprint":"8cffbee538cdd6cee1bfebf21b98f6bf4baafb9a96d11348ad2376113559fc2f","payload":{"connection_id":"5d29200f65794d4d9ab6ef271f045a9b","event_at":"2026-07-28T02:05:24.518000Z","event_type":"price_change","frame_hash":"e5ad4c18a217db64a1e2a7a4bef88a133ebdfcaf4cdf8f8584264d704008fbaa","frame_index":0,"kind":"data","monotonic_ns":306315284401625,"payload":{"event_type":"price_change","market":"0xda6f0e0e93fc8469e0159a166028d017bddbc162b86f66bac90391379603d962","price_changes":[{"asset_id":"39272994714739463168905443499424551362424437245880253267329605556587274644733","best_ask":"0.74","best_bid":"0.73","hash":"de957c201e65a44fc09ca503e8de22ebf090af43","price":"0.03","side":"BUY","size":"643.1"},{"asset_id":"20893381255801015515826997628594359667013752732428989472914000440642900266717","best_ask":"0.27","best_bid":"0.26","hash":"c074c103e564dfe62b98c4ab13c038fe8b850d70","price":"0.97","side":"SELL","size":"643.1"}],"timestamp":"1785204324518"},"payload_hash":"2f5af1be19b28dc66a5d611c6624f2d8e3e2d32aad5d2ce475aa91077138a2d3","raw_frame":"{\"market\":\"0xda6f0e0e93fc8469e0159a166028d017bddbc162b86f66bac90391379603d962\", \"price_changes\":[{\"asset_id\":\"39272994714739463168905443499424551362424437245880253267329605556587274644733\", \"price\":\"0.03\", \"size\":\"643.1\", \"side\":\"BUY\", \"hash\":\"de957c201e65a44fc09ca503e8de22ebf090af43\", \"best_bid\":\"0.73\", \"best_ask\":\"0.74\"}, {\"asset_id\":\"20893381255801015515826997628594359667013752732428989472914000440642900266717\", \"price\":\"0.97\", \"size\":\"643.1\", \"side\":\"SELL\", \"hash\":\"c074c103e564dfe62b98c4ab13c038fe8b850d70\", \"best_bid\":\"0.26\", \"best_ask\":\"0.27\"}], \"timestamp\":\"1785204324518\", \"event_type\":\"price_change\"}","received_at":"2026-07-28T02:05:32.278062Z","schema_version":"clob-market-ws.price_change.v1","sequence":null,"server_hash":null,"server_timestamp":"1785204324518","session_id":"d2757dd6dad94f3b9fe67e8dbf1adc37","source":"clob_market_ws"},"received_at":"2026-07-28T02:05:32.278062Z","record_id":"f63cc065274539c11ebf0813462c8454c8756ba34f03b00ac008c5ae0a807d5e","schema_fingerprint":"4aa3821a28b0b7c2400bc59aba4bcc0a76e971dadd19610d3ad38c768e124dc7","schema_version":"edge-lab-recorder.raw.v1","sequence":null,"source":"clob_market_ws"}
{"event_at":"2026-07-28T02:05:24.521000Z","event_fingerprint":"ee80fd0fd989145ebac60ac22730cfd07f40aedc3b3e82781805b5bb86dc56d4","payload":{"connection_id":"5d29200f65794d4d9ab6ef271f045a9b","event_at":"2026-07-28T02:05:24.521000Z","event_type":"price_change","frame_hash":"f1228cc0015914085baf31f136656606b6b446944b976ed4809015032d2ca949","frame_index":0,"kind":"data","monotonic_ns":306315288414666,"payload":{"event_type":"price_change","market":"0xda6f0e0e93fc8469e0159a166028d017bddbc162b86f66bac90391379603d962","price_changes":[{"asset_id":"39272994714739463168905443499424551362424437245880253267329605556587274644733","best_ask":"0.74","best_bid":"0.73","hash":"2102c54dbf64158b2f17cd048edbcb599c80fab6","price":"0.66","side":"BUY","size":"246"},{"asset_id":"20893381255801015515826997628594359667013752732428989472914000440642900266717","best_ask":"0.27","best_bid":"0.26","hash":"d1fb6ba05b5063ec47012b1bf95a9b80000f2db7","price":"0.34","side":"SELL","size":"246"}],"timestamp":"1785204324521"},"payload_hash":"da49497b6a24377cef9f2e00ee4e2c5b830b0bf51f8c7923a62f47d1137d7b52","raw_frame":"{\"market\":\"0xda6f0e0e93fc8469e0159a166028d017bddbc162b86f66bac90391379603d962\", \"price_changes\":[{\"asset_id\":\"39272994714739463168905443499424551362424437245880253267329605556587274644733\", \"price\":\"0.66\", \"size\":\"246\", \"side\":\"BUY\", \"hash\":\"2102c54dbf64158b2f17cd048edbcb599c80fab6\", \"best_bid\":\"0.73\", \"best_ask\":\"0.74\"}, {\"asset_id\":\"20893381255801015515826997628594359667013752732428989472914000440642900266717\", \"price\":\"0.34\", \"size\":\"246\", \"side\":\"SELL\", \"hash\":\"d1fb6ba05b5063ec47012b1bf95a9b80000f2db7\", \"best_bid\":\"0.26\", \"best_ask\":\"0.27\"}], \"timestamp\":\"1785204324521\", \"event_type\":\"price_change\"}","received_at":"2026-07-28T02:05:32.282072Z","schema_version":"clob-market-ws.price_change.v1","sequence":null,"server_hash":null,"server_timestamp":"1785204324521","session_id":"d2757dd6dad94f3b9fe67e8dbf1adc37","source":"clob_market_ws"},"received_at":"2026-07-28T02:05:32.282072Z","record_id":"4ac2b2e441845bc68798d9feeb5cfb7b8263e6a0fe51d55cb448c12c8751b0df","schema_fingerprint":"4aa3821a28b0b7c2400bc59aba4bcc0a76e971dadd19610d3ad38c768e124dc7","schema_version":"edge-lab-recorder.raw.v1","sequence":null,"source":"clob_market_ws"}
{"event_at":"2026-07-28T02:05:24.533000Z","event_fingerprint":"3d42798257c64feb84f150874a0c25468fac33014dc0323a794f3d55397f6cf5","payload":{"connection_id":"5d29200f65794d4d9ab6ef271f045a9b","event_at":"2026-07-28T02:05:24.533000Z","event_type":"price_change","frame_hash":"bcf90113681c376e9ac54a5ef5cc2f8962767d8a46c02f6e512824b86127cd97","frame_index":0,"kind":"data","monotonic_ns":306315291668416,"payload":{"event_type":"price_change","market":"0xda6f0e0e93fc8469e0159a166028d017bddbc162b86f66bac90391379603d962","price_changes":[{"asset_id":"39272994714739463168905443499424551362424437245880253267329605556587274644733","best_ask":"0.74","best_bid":"0.73","hash":"3f8ef3868642b47dc999c1cfc25a6e86c8272985","price":"0.01","side":"BUY","size":"5853.02"},{"asset_id":"20893381255801015515826997628594359667013752732428989472914000440642900266717","best_ask":"0.27","best_bid":"0.26","hash":"6df4fbdfb1cb13bdedf2ff986bc3bf2a023db8b9","price":"0.99","side":"SELL","size":"5853.02"}],"timestamp":"1785204324533"},"payload_hash":"a32286cf62628d7a42ba48c488e44ad045cf1b3dcc80c443b26616d78b0ecde7","raw_frame":"{\"market\":\"0xda6f0e0e93fc8469e0159a166028d017bddbc162b86f66bac90391379603d962\", \"price_changes\":[{\"asset_id\":\"39272994714739463168905443499424551362424437245880253267329605556587274644733\", \"price\":\"0.01\", \"size\":\"5853.02\", \"side\":\"BUY\", \"hash\":\"3f8ef3868642b47dc999c1cfc25a6e86c8272985\", \"best_bid\":\"0.73\", \"best_ask\":\"0.74\"}, {\"asset_id\":\"20893381255801015515826997628594359667013752732428989472914000440642900266717\", \"price\":\"0.99\", \"size\":\"5853.02\", \"side\":\"SELL\", \"hash\":\"6df4fbdfb1cb13bdedf2ff986bc3bf2a023db8b9\", \"best_bid\":\"0.26\", \"best_ask\":\"0.27\"}], \"timestamp\":\"1785204324533\", \"event_type\":\"price_change\"}","received_at":"2026-07-28T02:05:32.285328Z","schema_version":"clob-market-ws.price_change.v1","sequence":null,"server_hash":null,"server_timestamp":"1785204324533","session_id":"d2757dd6dad94f3b9fe67e8dbf1adc37","source":"clob_market_ws"},"received_at":"2026-07-28T02:05:32.285328Z","record_id":"a7c9a513be4162aa8e71d3eccb60bdde01303f45009d29043eb023165eb17e0c","schema_fingerprint":"4aa3821a28b0b7c2400bc59aba4bcc0a76e971dadd19610d3ad38c768e124dc7","schema_version":"edge-lab-recorder.raw.v1","sequence":null,"source":"clob_market_ws"}
{"event_at":"2026-07-28T02:05:24.655000Z","event_fingerprint":"3179899ada2c567e7daa3ac26ecc1f00594df9cd3338cf190f666228418fc1d3","payload":{"connection_id":"5d29200f65794d4d9ab6ef271f045a9b","event_at":"2026-07-28T02:05:24.655000Z","event_type":"price_change","frame_hash":"0f0ce4dd8537e24589ae03cbcbe2918eab776e000ade36d8016075e666d09a83","frame_index":0,"kind":"data","monotonic_ns":306315294469791,"payload":{"event_type":"price_change","market":"0xda6f0e0e93fc8469e0159a166028d017bddbc162b86f66bac90391379603d962","price_changes":[{"asset_id":"39272994714739463168905443499424551362424437245880253267329605556587274644733","best_ask":"0.74","best_bid":"0.73","hash":"35c78b79c287db555ffd4e56cc61504f8c126acb","price":"0.66","side":"BUY","size":"231"},{"asset_id":"20893381255801015515826997628594359667013752732428989472914000440642900266717","best_ask":"0.27","best_bid":"0.26","hash":"ab293056c59d4db0d822c388841d13d124c27c38","price":"0.34","side":"SELL","size":"231"}],"timestamp":"1785204324655"},"payload_hash":"c1b03718784615228e08df41f0d8eda32fbb064b25b6d30b2a2b258b96cfb3b2","raw_frame":"{\"market\":\"0xda6f0e0e93fc8469e0159a166028d017bddbc162b86f66bac90391379603d962\", \"price_changes\":[{\"asset_id\":\"39272994714739463168905443499424551362424437245880253267329605556587274644733\", \"price\":\"0.66\", \"size\":\"231\", \"side\":\"BUY\", \"hash\":\"35c78b79c287db555ffd4e56cc61504f8c126acb\", \"best_bid\":\"0.73\", \"best_ask\":\"0.74\"}, {\"asset_id\":\"20893381255801015515826997628594359667013752732428989472914000440642900266717\", \"price\":\"0.34\", \"size\":\"231\", \"side\":\"SELL\", \"hash\":\"ab293056c59d4db0d822c388841d13d124c27c38\", \"best_bid\":\"0.26\", \"best_ask\":\"0.27\"}], \"timestamp\":\"1785204324655\", \"event_type\":\"price_change\"}","received_at":"2026-07-28T02:05:32.288130Z","schema_version":"clob-market-ws.price_change.v1","sequence":null,"server_hash":null,"server_timestamp":"1785204324655","session_id":"d2757dd6dad94f3b9fe67e8dbf1adc37","source":"clob_market_ws"},"received_at":"2026-07-28T02:05:32.288130Z","record_id":"1582227994c73d87f49bbdcd0044a9d0cb157e59dd75ec6f6034ce49b92d9d8f","schema_fingerprint":"4aa3821a28b0b7c2400bc59aba4bcc0a76e971dadd19610d3ad38c768e124dc7","schema_version":"edge-lab-recorder.raw.v1","sequence":null,"source":"clob_market_ws"}
{"event_at":"2026-07-28T02:05:24.680000Z","event_fingerprint":"514019b0e4048b09871cab23677f6b6518ffad94b1eb22ddf2ed37cc314b5d76","payload":{"connection_id":"5d29200f65794d4d9ab6ef271f045a9b","event_at":"2026-07-28T02:05:24.680000Z","event_type":"price_change","frame_hash":"d48bbc5a82587d6c04ea5c9b6d5fe1fc8c9761331b4345c3cce7f65ac6cd2276","frame_index":0,"kind":"data","monotonic_ns":306315298714083,"payload":{"event_type":"price_change","market":"0xda6f0e0e93fc8469e0159a166028d017bddbc162b86f66bac90391379603d962","price_changes":[{"asset_id":"39272994714739463168905443499424551362424437245880253267329605556587274644733","best_ask":"0.74","best_bid":"0.73","hash":"b4f9f08b5bf1410cef90aaa621bc8ad6b094a71c","price":"0.04","side":"BUY","size":"593.09"},{"asset_id":"20893381255801015515826997628594359667013752732428989472914000440642900266717","best_ask":"0.27","best_bid":"0.26","hash":"1696c787bfaa1b30896349dc449408f6b564c21e","price":"0.96","side":"SELL","size":"593.09"}],"timestamp":"1785204324680"},"payload_hash":"6fc7670f6f0dafec77706eb0b7b274d2a28159901c7c2638b30e3ca81bf914fd","raw_frame":"{\"market\":\"0xda6f0e0e93fc8469e0159a166028d017bddbc162b86f66bac90391379603d962\", \"price_changes\":[{\"asset_id\":\"39272994714739463168905443499424551362424437245880253267329605556587274644733\", \"price\":\"0.04\", \"size\":\"593.09\", \"side\":\"BUY\", \"hash\":\"b4f9f08b5bf1410cef90aaa621bc8ad6b094a71c\", \"best_bid\":\"0.73\", \"best_ask\":\"0.74\"}, {\"asset_id\":\"20893381255801015515826997628594359667013752732428989472914000440642900266717\", \"price\":\"0.96\", \"size\":\"593.09\", \"side\":\"SELL\", \"hash\":\"1696c787bfaa1b30896349dc449408f6b564c21e\", \"best_bid\":\"0.26\", \"best_ask\":\"0.27\"}], \"timestamp\":\"1785204324680\", \"event_type\":\"price_change\"}","received_at":"2026-07-28T02:05:32.292374Z","schema_version":"clob-market-ws.price_change.v1","sequence":null,"server_hash":null,"server_timestamp":"1785204324680","session_id":"d2757dd6dad94f3b9fe67e8dbf1adc37","source":"clob_market_ws"},"received_at":"2026-07-28T02:05:32.292374Z","record_id":"d2c50f5d8bb2e1bf3918e504f151ed01bc57572e2c5e2c33175096ced2d2a150","schema_fingerprint":"4aa3821a28b0b7c2400bc59aba4bcc0a76e971dadd19610d3ad38c768e124dc7","schema_version":"edge-lab-recorder.raw.v1","sequence":null,"source":"clob_market_ws"}
{"event_at":"2026-07-28T02:05:24.734000Z","event_fingerprint":"aa86d9421e0bcc39058f579856807edc42adb29f44701671a29f05c2807b47a1","payload":{"connection_id":"5d29200f65794d4d9ab6ef271f045a9b","event_at":"2026-07-28T02:05:24.734000Z","event_type":"price_change","frame_hash":"d066747cb7d08300af79de510aae5c9ae64d7044467da858511133e7b343efe1","frame_index":0,"kind":"data","monotonic_ns":306315301524041,"payload":{"event_type":"price_change","market":"0xda6f0e0e93fc8469e0159a166028d017bddbc162b86f66bac90391379603d962","price_changes":[{"asset_id":"20893381255801015515826997628594359667013752732428989472914000440642900266717","best_ask":"0.27","best_bid":"0.26","hash":"b2315bf0663a79410fdd43b1cd9110dde1941d21","price":"0.25","side":"BUY","size":"94.2"},{"asset_id":"39272994714739463168905443499424551362424437245880253267329605556587274644733","best_ask":"0.74","best_bid":"0.73","hash":"2d605826876ae88d1666a37058e4c8cd552a75f3","price":"0.75","side":"SELL","size":"94.2"}],"timestamp":"1785204324734"},"payload_hash":"fa540b99bc09990a8edaa2985bc1669654886e2abe66759f067a2e0b6c7f2447","raw_frame":"{\"market\":\"0xda6f0e0e93fc8469e0159a166028d017bddbc162b86f66bac90391379603d962\", \"price_changes\":[{\"asset_id\":\"20893381255801015515826997628594359667013752732428989472914000440642900266717\", \"price\":\"0.25\", \"size\":\"94.2\", \"side\":\"BUY\", \"hash\":\"b2315bf0663a79410fdd43b1cd9110dde1941d21\", \"best_bid\":\"0.26\", \"best_ask\":\"0.27\"}, {\"asset_id\":\"39272994714739463168905443499424551362424437245880253267329605556587274644733\", \"price\":\"0.75\", \"size\":\"94.2\", \"side\":\"SELL\", \"hash\":\"2d605826876ae88d1666a37058e4c8cd552a75f3\", \"best_bid\":\"0.73\", \"best_ask\":\"0.74\"}], \"timestamp\":\"1785204324734\", \"event_type\":\"price_change\"}","received_at":"2026-07-28T02:05:32.295184Z","schema_version":"clob-market-ws.price_change.v1","sequence":null,"server_hash":null,"server_timestamp":"1785204324734","session_id":"d2757dd6dad94f3b9fe67e8dbf1adc37","source":"clob_market_ws"},"received_at":"2026-07-28T02:05:32.295184Z","record_id":"a20d2d80f488d43d24a278ccf99dc324dd205f3b823c4ee4de504ea472184710","schema_fingerprint":"4aa3821a28b0b7c2400bc59aba4bcc0a76e971dadd19610d3ad38c768e124dc7","schema_version":"edge-lab-recorder.raw.v1","sequence":null,"source":"clob_market_ws"}
{"event_at":"2026-07-28T02:05:24.753000Z","event_fingerprint":"432b9a5c8a4967b367a6106d3f29b2b7bafe6b40e6319d6e9f929ace88062cb5","payload":{"connection_id":"5d29200f65794d4d9ab6ef271f045a9b","event_at":"2026-07-28T02:05:24.753000Z","event_type":"price_change","frame_hash":"75fabac7c2452eba05645ab86b9e79c7c78d31253ba4950335c31e57e0ecf161","frame_index":0,"kind":"data","monotonic_ns":306315305842083,"payload":{"event_type":"price_change","market":"0xda6f0e0e93fc8469e0159a166028d017bddbc162b86f66bac90391379603d962","price_changes":[{"asset_id":"20893381255801015515826997628594359667013752732428989472914000440642900266717","best_ask":"0.27","best_bid":"0.26","hash":"9d0bcacc87b709444cbae3aac9dee88fe616248b","price":"0.19","side":"BUY","size":"298.5"},{"asset_id":"39272994714739463168905443499424551362424437245880253267329605556587274644733","best_ask":"0.74","best_bid":"0.73","hash":"12bd54fcd47d448a4b14c1b3c2dd6953df5d1917","price":"0.81","side":"SELL","size":"298.5"}],"timestamp":"1785204324753"},"payload_hash":"ea284248a786b566c2917365b9e4f51eaa3dd0daa29fe3799a09cde090b7dcfd","raw_frame":"{\"market\":\"0xda6f0e0e93fc8469e0159a166028d017bddbc162b86f66bac90391379603d962\", \"price_changes\":[{\"asset_id\":\"20893381255801015515826997628594359667013752732428989472914000440642900266717\", \"price\":\"0.19\", \"size\":\"298.5\", \"side\":\"BUY\", \"hash\":\"9d0bcacc87b709444cbae3aac9dee88fe616248b\", \"best_bid\":\"0.26\", \"best_ask\":\"0.27\"}, {\"asset_id\":\"39272994714739463168905443499424551362424437245880253267329605556587274644733\", \"price\":\"0.81\", \"size\":\"298.5\", \"side\":\"SELL\", \"hash\":\"12bd54fcd47d448a4b14c1b3c2dd6953df5d1917\", \"best_bid\":\"0.73\", \"best_ask\":\"0.74\"}], \"timestamp\":\"1785204324753\", \"event_type\":\"price_change\"}","received_at":"2026-07-28T02:05:32.299502Z","schema_version":"clob-market-ws.price_change.v1","sequence":null,"server_hash":null,"server_timestamp":"1785204324753","session_id":"d2757dd6dad94f3b9fe67e8dbf1adc37","source":"clob_market_ws"},"received_at":"2026-07-28T02:05:32.299502Z","record_id":"f7eb2882a047abda76f9d86fa0b9a23f61c60583acef49aa1dce84913b6c23e3","schema_fingerprint":"4aa3821a28b0b7c2400bc59aba4bcc0a76e971dadd19610d3ad38c768e124dc7","schema_version":"edge-lab-recorder.raw.v1","sequence":null,"source":"clob_market_ws"}
{"event_at":"2026-07-28T02:05:24.753000Z","event_fingerprint":"0f56677e2bcdbcc3b759f02de28c6794d99f6aecdb477681158acaf6bac369d2","payload":{"connection_id":"5d29200f65794d4d9ab6ef271f045a9b","event_at":"2026-07-28T02:05:24.753000Z","event_type":"price_change","frame_hash":"555fc3c8c4aa1e60f3f95e1312cf2144a6a9a8ed62a13b98b41fd72c3cb9c269","frame_index":0,"kind":"data","monotonic_ns":306315308707500,"payload":{"event_type":"price_change","market":"0xda6f0e0e93fc8469e0159a166028d017bddbc162b86f66bac90391379603d962","price_changes":[{"asset_id":"20893381255801015515826997628594359667013752732428989472914000440642900266717","best_ask":"0.27","best_bid":"0.26","hash":"e2fe7502736e75f4fc938d36c3a3be1d5df76f4b","price":"0.19","side":"BUY","size":"268.5"},{"asset_id":"39272994714739463168905443499424551362424437245880253267329605556587274644733","best_ask":"0.74","best_bid":"0.73","hash":"23f72b2a71e7acaae758ff8cca8bd25d8c7121e8","price":"0.81","side":"SELL","size":"268.5"}],"timestamp":"1785204324753"},"payload_hash":"df30f441e83c18c578f779330a9eebdb208a27113ea557ccce402691d6475442","raw_frame":"{\"market\":\"0xda6f0e0e93fc8469e0159a166028d017bddbc162b86f66bac90391379603d962\", \"price_changes\":[{\"asset_id\":\"20893381255801015515826997628594359667013752732428989472914000440642900266717\", \"price\":\"0.19\", \"size\":\"268.5\", \"side\":\"BUY\", \"hash\":\"e2fe7502736e75f4fc938d36c3a3be1d5df76f4b\", \"best_bid\":\"0.26\", \"best_ask\":\"0.27\"}, {\"asset_id\":\"39272994714739463168905443499424551362424437245880253267329605556587274644733\", \"price\":\"0.81\", \"size\":\"268.5\", \"side\":\"SELL\", \"hash\":\"23f72b2a71e7acaae758ff8cca8bd25d8c7121e8\", \"best_bid\":\"0.73\", \"best_ask\":\"0.74\"}], \"timestamp\":\"1785204324753\", \"event_type\":\"price_change\"}","received_at":"2026-07-28T02:05:32.302367Z","schema_version":"clob-market-ws.price_change.v1","sequence":null,"server_hash":null,"server_timestamp":"1785204324753","session_id":"d2757dd6dad94f3b9fe67e8dbf1adc37","source":"clob_market_ws"},"received_at":"2026-07-28T02:05:32.302367Z","record_id":"d9026933cd9f70575ad42d4cab8d8e15de552a21539c00b5b965bec40b116172","schema_fingerprint":"4aa3821a28b0b7c2400bc59aba4bcc0a76e971dadd19610d3ad38c768e124dc7","schema_version":"edge-lab-recorder.raw.v1","sequence":null,"source":"clob_market_ws"}
{"event_at":"2026-07-28T02:05:24.753000Z","event_fingerprint":"fb0c80c98aeb7ef64307d40e43b51a21bbec0779638fe9cd09847dd5a1720f69","payload":{"connection_id":"5d29200f65794d4d9ab6ef271f045a9b","event_at":"2026-07-28T02:05:24.753000Z","event_type":"price_change","frame_hash":"914b0fb3f0667e292c24626dd34a5bfcb13d281fd9289927dba9cb30b24197e7","frame_index":0,"kind":"data","monotonic_ns":306315312913041,"payload":{"event_type":"price_change","market":"0xda6f0e0e93fc8469e0159a166028d017bddbc162b86f66bac90391379603d962","price_changes":[{"asset_id":"20893381255801015515826997628594359667013752732428989472914000440642900266717","best_ask":"0.27","best_bid":"0.26","hash":"c07f9de1b41ed070345f7bafc726060deecf2e99","price":"0.19","side":"BUY","size":"238.5"},{"asset_id":"39272994714739463168905443499424551362424437245880253267329605556587274644733","best_ask":"0.74","best_bid":"0.73","hash":"463ca2bd59d43129c92bbe24c8b366ac38cefa08","price":"0.81","side":"SELL","size":"238.5"}],"timestamp":"1785204324753"},"payload_hash":"eefa72d42c5592eac6ae505951bc7f425492d15e28cde053369dbdebd411c961","raw_frame":"{\"market\":\"0xda6f0e0e93fc8469e0159a166028d017bddbc162b86f66bac90391379603d962\", \"price_changes\":[{\"asset_id\":\"20893381255801015515826997628594359667013752732428989472914000440642900266717\", \"price\":\"0.19\", \"size\":\"238.5\", \"side\":\"BUY\", \"hash\":\"c07f9de1b41ed070345f7bafc726060deecf2e99\", \"best_bid\":\"0.26\", \"best_ask\":\"0.27\"}, {\"asset_id\":\"39272994714739463168905443499424551362424437245880253267329605556587274644733\", \"price\":\"0.81\", \"size\":\"238.5\", \"side\":\"SELL\", \"hash\":\"463ca2bd59d43129c92bbe24c8b366ac38cefa08\", \"best_bid\":\"0.73\", \"best_ask\":\"0.74\"}], \"timestamp\":\"1785204324753\", \"event_type\":\"price_change\"}","received_at":"2026-07-28T02:05:32.306572Z","schema_version":"clob-market-ws.price_change.v1","sequence":null,"server_hash":null,"server_timestamp":"1785204324753","session_id":"d2757dd6dad94f3b9fe67e8dbf1adc37","source":"clob_market_ws"},"received_at":"2026-07-28T02:05:32.306572Z","record_id":"08938828eb7a29012a5e66e0c60b0872472f8b2f2783da95f711880796943ef3","schema_fingerprint":"4aa3821a28b0b7c2400bc59aba4bcc0a76e971dadd19610d3ad38c768e124dc7","schema_version":"edge-lab-recorder.raw.v1","sequence":null,"source":"clob_market_ws"}
{"event_at":"2026-07-28T02:05:24.755000Z","event_fingerprint":"d243a5ac3b6b5d08294cc623cc1d83f3fc31467df9e0e40c5b23b7559e0c5a20","payload":{"connection_id":"5d29200f65794d4d9ab6ef271f045a9b","event_at":"2026-07-28T02:05:24.755000Z","event_type":"price_change","frame_hash":"0f37b8d78519f6ee8615266d3ad696201eb86e1e9b1a7143b3115e1e3340ecb3","frame_index":0,"kind":"data","monotonic_ns":306315317180958,"payload":{"event_type":"price_change","market":"0xda6f0e0e93fc8469e0159a166028d017bddbc162b86f66bac90391379603d962","price_changes":[{"asset_id":"20893381255801015515826997628594359667013752732428989472914000440642900266717","best_ask":"0.27","best_bid":"0.26","hash":"774b58af682606bc9ae0f9c71714759c9b6085d0","price":"0.26","side":"BUY","size":"52.6"},{"asset_id":"39272994714739463168905443499424551362424437245880253267329605556587274644733","best_ask":"0.74","best_bid":"0.73","hash":"dc579a3d914e0f4f7602f95eef40a419c9b1fc2c","price":"0.74","side":"SELL","size":"52.6"}],"timestamp":"1785204324755"},"payload_hash":"9ebba875039a9e7842b1cb5ffac2053e267f07e150df15a4c0cd79de7e061cfb","raw_frame":"{\"market\":\"0xda6f0e0e93fc8469e0159a166028d017bddbc162b86f66bac90391379603d962\", \"price_changes\":[{\"asset_id\":\"20893381255801015515826997628594359667013752732428989472914000440642900266717\", \"price\":\"0.26\", \"size\":\"52.6\", \"side\":\"BUY\", \"hash\":\"774b58af682606bc9ae0f9c71714759c9b6085d0\", \"best_bid\":\"0.26\", \"best_ask\":\"0.27\"}, {\"asset_id\":\"39272994714739463168905443499424551362424437245880253267329605556587274644733\", \"price\":\"0.74\", \"size\":\"52.6\", \"side\":\"SELL\", \"hash\":\"dc579a3d914e0f4f7602f95eef40a419c9b1fc2c\", \"best_bid\":\"0.73\", \"best_ask\":\"0.74\"}], \"timestamp\":\"1785204324755\", \"event_type\":\"price_change\"}","received_at":"2026-07-28T02:05:32.310841Z","schema_version":"clob-market-ws.price_change.v1","sequence":null,"server_hash":null,"server_timestamp":"1785204324755","session_id":"d2757dd6dad94f3b9fe67e8dbf1adc37","source":"clob_market_ws"},"received_at":"2026-07-28T02:05:32.310841Z","record_id":"fbbdb7c89cb4dfa8fd8b75301c0e986f2000bdb583dabcb74737bcdb68bc63e2","schema_fingerprint":"4aa3821a28b0b7c2400bc59aba4bcc0a76e971dadd19610d3ad38c768e124dc7","schema_version":"edge-lab-recorder.raw.v1","sequence":null,"source":"clob_market_ws"}
{"event_at":"2026-07-28T02:05:24.756000Z","event_fingerprint":"063285d99413c3f5ecc1b85c120022146f0d1547713dc105a071bc862a0a2fca","payload":{"connection_id":"5d29200f65794d4d9ab6ef271f045a9b","event_at":"2026-07-28T02:05:24.756000Z","event_type":"price_change","frame_hash":"64654ef8095cf0995636956219e485b56f26f46bb3056f3a839ee834141e8e09","frame_index":0,"kind":"data","monotonic_ns":306315321417250,"payload":{"event_type":"price_change","market":"0xda6f0e0e93fc8469e0159a166028d017bddbc162b86f66bac90391379603d962","price_changes":[{"asset_id":"39272994714739463168905443499424551362424437245880253267329605556587274644733","best_ask":"0.74","best_bid":"0.73","hash":"b2c1ea7bb4f65698187614ad678a3f14feeb2821","price":"0.65","side":"BUY","size":"154"},{"asset_id":"20893381255801015515826997628594359667013752732428989472914000440642900266717","best_ask":"0.27","best_bid":"0.26","hash":"caa5a0c50b552c0d8eeda3ab95ca96f89d642983","price":"0.35","side":"SELL","size":"154"}],"timestamp":"1785204324756"},"payload_hash":"2881b43e3c4989cf0dc2c0be566f7fa235aabf9e10227f39bc624d990afd0b84","raw_frame":"{\"market\":\"0xda6f0e0e93fc8469e0159a166028d017bddbc162b86f66bac90391379603d962\", \"price_changes\":[{\"asset_id\":\"39272994714739463168905443499424551362424437245880253267329605556587274644733\", \"price\":\"0.65\", \"size\":\"154\", \"side\":\"BUY\", \"hash\":\"b2c1ea7bb4f65698187614ad678a3f14feeb2821\", \"best_bid\":\"0.73\", \"best_ask\":\"0.74\"}, {\"asset_id\":\"20893381255801015515826997628594359667013752732428989472914000440642900266717\", \"price\":\"0.35\", \"size\":\"154\", \"side\":\"SELL\", \"hash\":\"caa5a0c50b552c0d8eeda3ab95ca96f89d642983\", \"best_bid\":\"0.26\", \"best_ask\":\"0.27\"}], \"timestamp\":\"1785204324756\", \"event_type\":\"price_change\"}","received_at":"2026-07-28T02:05:32.315077Z","schema_version":"clob-market-ws.price_change.v1","sequence":null,"server_hash":null,"server_timestamp":"1785204324756","session_id":"d2757dd6dad94f3b9fe67e8dbf1adc37","source":"clob_market_ws"},"received_at":"2026-07-28T02:05:32.315077Z","record_id":"2e2609937cc51ae103604edddba06719670f3386eaf417d6a7f00c250b66bca9","schema_fingerprint":"4aa3821a28b0b7c2400bc59aba4bcc0a76e971dadd19610d3ad38c768e124dc7","schema_version":"edge-lab-recorder.raw.v1","sequence":null,"source":"clob_market_ws"}
{"event_at":"2026-07-28T02:05:24.758000Z","event_fingerprint":"2553aa58cd544395b817a25e6dafd15810a6837ac9931976db59a468e6c75570","payload":{"connection_id":"5d29200f65794d4d9ab6ef271f045a9b","event_at":"2026-07-28T02:05:24.758000Z","event_type":"price_change","frame_hash":"4f7ec482be71c58947f8ff6643a438484cedf99b7da4e59f9de21ac6d75ddef5","frame_index":0,"kind":"data","monotonic_ns":306315325644500,"payload":{"event_type":"price_change","market":"0xda6f0e0e93fc8469e0159a166028d017bddbc162b86f66bac90391379603d962","price_changes":[{"asset_id":"39272994714739463168905443499424551362424437245880253267329605556587274644733","best_ask":"0.74","best_bid":"0.73","hash":"7785c19b42e0524cd21d8768e9b874a4744ffae5","price":"0.68","side":"BUY","size":"259.35"},{"asset_id":"20893381255801015515826997628594359667013752732428989472914000440642900266717","best_ask":"0.27","best_bid":"0.26","hash":"57e546178335c6d35f803aaae9d953f62a4b3f82","price":"0.32","side":"SELL","size":"259.35"}],"timestamp":"1785204324758"},"payload_hash":"f9145652a40612d3a804b2b4012cfb3b070203371115ed25291d7d894e6d5bfa","raw_frame":"{\"market\":\"0xda6f0e0e93fc8469e0159a166028d017bddbc162b86f66bac90391379603d962\", \"price_changes\":[{\"asset_id\":\"39272994714739463168905443499424551362424437245880253267329605556587274644733\", \"price\":\"0.68\", \"size\":\"259.35\", \"side\":\"BUY\", \"hash\":\"7785c19b42e0524cd21d8768e9b874a4744ffae5\", \"best_bid\":\"0.73\", \"best_ask\":\"0.74\"}, {\"asset_id\":\"20893381255801015515826997628594359667013752732428989472914000440642900266717\", \"price\":\"0.32\", \"size\":\"259.35\", \"side\":\"SELL\", \"hash\":\"57e546178335c6d35f803aaae9d953f62a4b3f82\", \"best_bid\":\"0.26\", \"best_ask\":\"0.27\"}], \"timestamp\":\"1785204324758\", \"event_type\":\"price_change\"}","received_at":"2026-07-28T02:05:32.319304Z","schema_version":"clob-market-ws.price_change.v1","sequence":null,"server_hash":null,"server_timestamp":"1785204324758","session_id":"d2757dd6dad94f3b9fe67e8dbf1adc37","source":"clob_market_ws"},"received_at":"2026-07-28T02:05:32.319304Z","record_id":"b3df44cff633a249b8e616c2e670e9cada61e52bc74a5227f2e99b5c3fc5621d","schema_fingerprint":"4aa3821a28b0b7c2400bc59aba4bcc0a76e971dadd19610d3ad38c768e124dc7","schema_version":"edge-lab-recorder.raw.v1","sequence":null,"source":"clob_market_ws"}
{"event_at":"2026-07-28T02:05:24.758000Z","event_fingerprint":"54053b1925804cc3204fb75a2bfc07ab25f43a8c3cf39bde9b422d6e43b51996","payload":{"connection_id":"5d29200f65794d4d9ab6ef271f045a9b","event_at":"2026-07-28T02:05:24.758000Z","event_type":"price_change","frame_hash":"bb8ffb8b119ea9bae2ab73d778c92bb793106e017b356847af4b9b74ab9cf194","frame_index":0,"kind":"data","monotonic_ns":306315329940000,"payload":{"event_type":"price_change","market":"0xda6f0e0e93fc8469e0159a166028d017bddbc162b86f66bac90391379603d962","price_changes":[{"asset_id":"39272994714739463168905443499424551362424437245880253267329605556587274644733","best_ask":"0.74","best_bid":"0.73","hash":"d0745c4922b83c4123d2a0b9db5fc784d1c71d09","price":"0.04","side":"BUY","size":"588.09"},{"asset_id":"20893381255801015515826997628594359667013752732428989472914000440642900266717","best_ask":"0.27","best_bid":"0.26","hash":"4fa2f4ccfea104087a0453267431448062f207fa","price":"0.96","side":"SELL","size":"588.09"}],"timestamp":"1785204324758"},"payload_hash":"81479ad2dd2783cc36875fe6c6ffc3a45103da89daffa2bec3d0d427975ecf5e","raw_frame":"{\"market\":\"0xda6f0e0e93fc8469e0159a166028d017bddbc162b86f66bac90391379603d962\", \"price_changes\":[{\"asset_id\":\"39272994714739463168905443499424551362424437245880253267329605556587274644733\", \"price\":\"0.04\", \"size\":\"588.09\", \"side\":\"BUY\", \"hash\":\"d0745c4922b83c4123d2a0b9db5fc784d1c71d09\", \"best_bid\":\"0.73\", \"best_ask\":\"0.74\"}, {\"asset_id\":\"20893381255801015515826997628594359667013752732428989472914000440642900266717\", \"price\":\"0.96\", \"size\":\"588.09\", \"side\":\"SELL\", \"hash\":\"4fa2f4ccfea104087a0453267431448062f207fa\", \"best_bid\":\"0.26\", \"best_ask\":\"0.27\"}], \"timestamp\":\"1785204324758\", \"event_type\":\"price_change\"}","received_at":"2026-07-28T02:05:32.323599Z","schema_version":"clob-market-ws.price_change.v1","sequence":null,"server_hash":null,"server_timestamp":"1785204324758","session_id":"d2757dd6dad94f3b9fe67e8dbf1adc37","source":"clob_market_ws"},"received_at":"2026-07-28T02:05:32.323599Z","record_id":"cfbd0eb7b4a00ab2a63584eba0f01b221d8249c1e2ec0eef541de15252652eb2","schema_fingerprint":"4aa3821a28b0b7c2400bc59aba4bcc0a76e971dadd19610d3ad38c768e124dc7","schema_version":"edge-lab-recorder.raw.v1","sequence":null,"source":"clob_market_ws"}
{"event_at":"2026-07-28T02:05:24.763000Z","event_fingerprint":"c52122f0bfbc8b1f8c5cc3e4ef56a1dcce9b638ad4d605c6f7a07aaff2217d94","payload":{"connection_id":"5d29200f65794d4d9ab6ef271f045a9b","event_at":"2026-07-28T02:05:24.763000Z","event_type":"price_change","frame_hash":"e5e1dd9495b3536a2d4ec8168a4a8ae898df621ceda91574db632e3c01f79da5","frame_index":0,"kind":"data","monotonic_ns":306315334171333,"payload":{"event_type":"price_change","market":"0xda6f0e0e93fc8469e0159a166028d017bddbc162b86f66bac90391379603d962","price_changes":[{"asset_id":"39272994714739463168905443499424551362424437245880253267329605556587274644733","best_ask":"0.74","best_bid":"0.73","hash":"5326560cf9e7d15f3f9c178855b30ed3a4d330ec","price":"0.72","side":"BUY","size":"41.6"},{"asset_id":"20893381255801015515826997628594359667013752732428989472914000440642900266717","best_ask":"0.27","best_bid":"0.26","hash":"78b18d0fa507f149b71c9d6c4e3afd2cb7eb663c","price":"0.28","side":"SELL","size":"41.6"}],"timestamp":"1785204324763"},"payload_hash":"a2522bde2a56888ff87f22318a5cfe81a0bcf2d6773ec5c4f8f602138b47c2f6","raw_frame":"{\"market\":\"0xda6f0e0e93fc8469e0159a166028d017bddbc162b86f66bac90391379603d962\", \"price_changes\":[{\"asset_id\":\"39272994714739463168905443499424551362424437245880253267329605556587274644733\", \"price\":\"0.72\", \"size\":\"41.6\", \"side\":\"BUY\", \"hash\":\"5326560cf9e7d15f3f9c178855b30ed3a4d330ec\", \"best_bid\":\"0.73\", \"best_ask\":\"0.74\"}, {\"asset_id\":\"20893381255801015515826997628594359667013752732428989472914000440642900266717\", \"price\":\"0.28\", \"size\":\"41.6\", \"side\":\"SELL\", \"hash\":\"78b18d0fa507f149b71c9d6c4e3afd2cb7eb663c\", \"best_bid\":\"0.26\", \"best_ask\":\"0.27\"}], \"timestamp\":\"1785204324763\", \"event_type\":\"price_change\"}","received_at":"2026-07-28T02:05:32.327831Z","schema_version":"clob-market-ws.price_change.v1","sequence":null,"server_hash":null,"server_timestamp":"1785204324763","session_id":"d2757dd6dad94f3b9fe67e8dbf1adc37","source":"clob_market_ws"},"received_at":"2026-07-28T02:05:32.327831Z","record_id":"ae0e4d4c7abc19f4b1c15fe344c3124f8e7738766dc83fe89ba5a9713de3b962","schema_fingerprint":"4aa3821a28b0b7c2400bc59aba4bcc0a76e971dadd19610d3ad38c768e124dc7","schema_version":"edge-lab-recorder.raw.v1","sequence":null,"source":"clob_market_ws"}
{"event_at":"2026-07-28T02:05:24.763000Z","event_fingerprint":"1c7ec941c03994896033f166b5b32ee96ae208d2033be232f66d8ca49841842e","payload":{"connection_id":"5d29200f65794d4d9ab6ef271f045a9b","event_at":"2026-07-28T02:05:24.763000Z","event_type":"price_change","frame_hash":"b1cd5504aa5c40d2c04e61eeb419344b7b5d0ec9db3e0d82f5b84e029458e805","frame_index":0,"kind":"data","monotonic_ns":306315344154916,"payload":{"event_type":"price_change","market":"0xda6f0e0e93fc8469e0159a166028d017bddbc162b86f66bac90391379603d962","price_changes":[{"asset_id":"39272994714739463168905443499424551362424437245880253267329605556587274644733","best_ask":"0.74","best_bid":"0.73","hash":"56071ed8caba5204ed1757f411967f94438313b9","price":"0.72","side":"BUY","size":"29"},{"asset_id":"20893381255801015515826997628594359667013752732428989472914000440642900266717","best_ask":"0.27","best_bid":"0.26","hash":"1a9c4fac70f9f6c0c0f28145ca3e6ff395d03af2","price":"0.28","side":"SELL","size":"29"}],"timestamp":"1785204324763"},"payload_hash":"07df6347c40cf65edcfe815e004885be3fb9f33ebcf0b6cc2504df3c0a53db60","raw_frame":"{\"market\":\"0xda6f0e0e93fc8469e0159a166028d017bddbc162b86f66bac90391379603d962\", \"price_changes\":[{\"asset_id\":\"39272994714739463168905443499424551362424437245880253267329605556587274644733\", \"price\":\"0.72\", \"size\":\"29\", \"side\":\"BUY\", \"hash\":\"56071ed8caba5204ed1757f411967f94438313b9\", \"best_bid\":\"0.73\", \"best_ask\":\"0.74\"}, {\"asset_id\":\"20893381255801015515826997628594359667013752732428989472914000440642900266717\", \"price\":\"0.28\", \"size\":\"29\", \"side\":\"SELL\", \"hash\":\"1a9c4fac70f9f6c0c0f28145ca3e6ff395d03af2\", \"best_bid\":\"0.26\", \"best_ask\":\"0.27\"}], \"timestamp\":\"1785204324763\", \"event_type\":\"price_change\"}","received_at":"2026-07-28T02:05:32.337811Z","schema_version":"clob-market-ws.price_change.v1","sequence":null,"server_hash":null,"server_timestamp":"1785204324763","session_id":"d2757dd6dad94f3b9fe67e8dbf1adc37","source":"clob_market_ws"},"received_at":"2026-07-28T02:05:32.337811Z","record_id":"bbdac3caceea1b48b3f080b6362cab0e01f2242c5bffeeb35272a721abb3f206","schema_fingerprint":"4aa3821a28b0b7c2400bc59aba4bcc0a76e971dadd19610d3ad38c768e124dc7","schema_version":"edge-lab-recorder.raw.v1","sequence":null,"source":"clob_market_ws"}
{"event_at":"2026-07-28T02:05:24.780000Z","event_fingerprint":"3354bd134a0beb8cc07361bb86ded032d1b396ed306534432fa3c0ea6af39beb","payload":{"connection_id":"5d29200f65794d4d9ab6ef271f045a9b","event_at":"2026-07-28T02:05:24.780000Z","event_type":"price_change","frame_hash":"c5f8a59e383cec7432cf758e843fcfca04525a8d2659dfb1efa306b447ff1560","frame_index":0,"kind":"data","monotonic_ns":306315348503375,"payload":{"event_type":"price_change","market":"0xda6f0e0e93fc8469e0159a166028d017bddbc162b86f66bac90391379603d962","price_changes":[{"asset_id":"20893381255801015515826997628594359667013752732428989472914000440642900266717","best_ask":"0.27","best_bid":"0.26","hash":"bc62aa7eff056eb9eba290f07a4cce2410ab063c","price":"0.2","side":"BUY","size":"249.53"},{"asset_id":"39272994714739463168905443499424551362424437245880253267329605556587274644733","best_ask":"0.74","best_bid":"0.73","hash":"b907840bc329da290c4dc68681041e3ec96ee05e","price":"0.8","side":"SELL","size":"249.53"}],"timestamp":"1785204324780"},"payload_hash":"90530a98f5d0e1cee270d9f6a8d424caba7e925afcbff4e157add333760ceece","raw_frame":"{\"market\":\"0xda6f0e0e93fc8469e0159a166028d017bddbc162b86f66bac90391379603d962\", \"price_changes\":[{\"asset_id\":\"20893381255801015515826997628594359667013752732428989472914000440642900266717\", \"price\":\"0.2\", \"size\":\"249.53\", \"side\":\"BUY\", \"hash\":\"bc62aa7eff056eb9eba290f07a4cce2410ab063c\", \"best_bid\":\"0.26\", \"best_ask\":\"0.27\"}, {\"asset_id\":\"39272994714739463168905443499424551362424437245880253267329605556587274644733\", \"price\":\"0.8\", \"size\":\"249.53\", \"side\":\"SELL\", \"hash\":\"b907840bc329da290c4dc68681041e3ec96ee05e\", \"best_bid\":\"0.73\", \"best_ask\":\"0.74\"}], \"timestamp\":\"1785204324780\", \"event_type\":\"price_change\"}","received_at":"2026-07-28T02:05:32.342164Z","schema_version":"clob-market-ws.price_change.v1","sequence":null,"server_hash":null,"server_timestamp":"1785204324780","session_id":"d2757dd6dad94f3b9fe67e8dbf1adc37","source":"clob_market_ws"},"received_at":"2026-07-28T02:05:32.342164Z","record_id":"aa56395a46363e5eea9d0d094a7ac672177f05305b3119a53cfb1758c03d61ac","schema_fingerprint":"4aa3821a28b0b7c2400bc59aba4bcc0a76e971dadd19610d3ad38c768e124dc7","schema_version":"edge-lab-recorder.raw.v1","sequence":null,"source":"clob_market_ws"}
{"event_at":"2026-07-28T02:05:24.781000Z","event_fingerprint":"dd62e5d51fd3b2acd39d7150c4eb401a77fabaf5c85c4299840cb57e1393e408","payload":{"connection_id":"5d29200f65794d4d9ab6ef271f045a9b","event_at":"2026-07-28T02:05:24.781000Z","event_type":"price_change","frame_hash":"8b54b86e1276706213f83cd2702913d675d521215c08e3ed90f55922e896cf6b","frame_index":0,"kind":"data","monotonic_ns":306315352275041,"payload":{"event_type":"price_change","market":"0xda6f0e0e93fc8469e0159a166028d017bddbc162b86f66bac90391379603d962","price_changes":[{"asset_id":"20893381255801015515826997628594359667013752732428989472914000440642900266717","best_ask":"0.27","best_bid":"0.26","hash":"b473006ffd55663dadf053115cfb70ad733eb466","price":"0.27","side":"SELL","size":"19.98"},{"asset_id":"39272994714739463168905443499424551362424437245880253267329605556587274644733","best_ask":"0.74","best_bid":"0.73","hash":"04ca4c9c7fa9da2fcaa1dba1766e5f9b93a0c28d","price":"0.73","side":"BUY","size":"19.98"}],"timestamp":"1785204324781"},"payload_hash":"22b215b294694d81479f86811fe538de412250589d5e42605f24df2bdbca569c","raw_frame":"{\"market\":\"0xda6f0e0e93fc8469e0159a166028d017bddbc162b86f66bac90391379603d962\", \"price_changes\":[{\"asset_id\":\"20893381255801015515826997628594359667013752732428989472914000440642900266717\", \"price\":\"0.27\", \"size\":\"19.98\", \"side\":\"SELL\", \"hash\":\"b473006ffd55663dadf053115cfb70ad733eb466\", \"best_bid\":\"0.26\", \"best_ask\":\"0.27\"}, {\"asset_id\":\"39272994714739463168905443499424551362424437245880253267329605556587274644733\", \"price\":\"0.73\", \"size\":\"19.98\", \"side\":\"BUY\", \"hash\":\"04ca4c9c7fa9da2fcaa1dba1766e5f9b93a0c28d\", \"best_bid\":\"0.73\", \"best_ask\":\"0.74\"}], \"timestamp\":\"1785204324781\", \"event_type\":\"price_change\"}","received_at":"2026-07-28T02:05:32.345936Z","schema_version":"clob-market-ws.price_change.v1","sequence":null,"server_hash":null,"server_timestamp":"1785204324781","session_id":"d2757dd6dad94f3b9fe67e8dbf1adc37","source":"clob_market_ws"},"received_at":"2026-07-28T02:05:32.345936Z","record_id":"97633af139ccd95807d280d2b418fe99abb002829587cc041dd8c958451664aa","schema_fingerprint":"4aa3821a28b0b7c2400bc59aba4bcc0a76e971dadd19610d3ad38c768e124dc7","schema_version":"edge-lab-recorder.raw.v1","sequence":null,"source":"clob_market_ws"}
{"event_at":"2026-07-28T02:05:24.781000Z","event_fingerprint":"ffdaa5db2a797515c043ef4e25c32beef5e2c4eb636e71bb77de914ee25acec2","payload":{"connection_id":"5d29200f65794d4d9ab6ef271f045a9b","event_at":"2026-07-28T02:05:24.781000Z","event_type":"price_change","frame_hash":"059a513644ce3a184bfce4abeabd8de8028632534b557b3e086a4b5fbbb1e622","frame_index":0,"kind":"data","monotonic_ns":306315356494750,"payload":{"event_type":"price_change","market":"0xda6f0e0e93fc8469e0159a166028d017bddbc162b86f66bac90391379603d962","price_changes":[{"asset_id":"39272994714739463168905443499424551362424437245880253267329605556587274644733","best_ask":"0.74","best_bid":"0.73","hash":"432ca93f473380222df15bdec07e5ed666add82c","price":"0.73","side":"BUY","size":"14.98"},{"asset_id":"20893381255801015515826997628594359667013752732428989472914000440642900266717","best_ask":"0.27","best_bid":"0.26","hash":"3fe6f011f1600288b377d21f745b3f08e026c752","price":"0.27","side":"SELL","size":"14.98"}],"timestamp":"1785204324781"},"payload_hash":"54e7463edf8c620a51d3fe19df22eb4080a3d9362909965b08a456cd09ab40c2","raw_frame":"{\"market\":\"0xda6f0e0e93fc8469e0159a166028d017bddbc162b86f66bac90391379603d962\", \"price_changes\":[{\"asset_id\":\"39272994714739463168905443499424551362424437245880253267329605556587274644733\", \"price\":\"0.73\", \"size\":\"14.98\", \"side\":\"BUY\", \"hash\":\"432ca93f473380222df15bdec07e5ed666add82c\", \"best_bid\":\"0.73\", \"best_ask\":\"0.74\"}, {\"asset_id\":\"20893381255801015515826997628594359667013752732428989472914000440642900266717\", \"price\":\"0.27\", \"size\":\"14.98\", \"side\":\"SELL\", \"hash\":\"3fe6f011f1600288b377d21f745b3f08e026c752\", \"best_bid\":\"0.26\", \"best_ask\":\"0.27\"}], \"timestamp\":\"1785204324781\", \"event_type\":\"price_change\"}","received_at":"2026-07-28T02:05:32.350152Z","schema_version":"clob-market-ws.price_change.v1","sequence":null,"server_hash":null,"server_timestamp":"1785204324781","session_id":"d2757dd6dad94f3b9fe67e8dbf1adc37","source":"clob_market_ws"},"received_at":"2026-07-28T02:05:32.350152Z","record_id":"971ee22adcfaefc3892df8eed34e084d76cd794b1b5548dc5c8de517139c2b08","schema_fingerprint":"4aa3821a28b0b7c2400bc59aba4bcc0a76e971dadd19610d3ad38c768e124dc7","schema_version":"edge-lab-recorder.raw.v1","sequence":null,"source":"clob_market_ws"}
{"event_at":"2026-07-28T02:05:24.783000Z","event_fingerprint":"5d90281d835c2803b19a2a58f2cf70072a6ea45e1ca923abe072063dbfe954da","payload":{"connection_id":"5d29200f65794d4d9ab6ef271f045a9b","event_at":"2026-07-28T02:05:24.783000Z","event_type":"price_change","frame_hash":"c9863607b7d3481770efcc1dbc1dd6c22fc5fe4bf19b38af4f9e10610c4f9a0a","frame_index":0,"kind":"data","monotonic_ns":306315360949000,"payload":{"event_type":"price_change","market":"0xda6f0e0e93fc8469e0159a166028d017bddbc162b86f66bac90391379603d962","price_changes":[{"asset_id":"20893381255801015515826997628594359667013752732428989472914000440642900266717","best_ask":"0.27","best_bid":"0.26","hash":"3f9d756e197afb7b79727a6b0bd1740c34f60242","price":"0.2","side":"BUY","size":"279.53"},{"asset_id":"39272994714739463168905443499424551362424437245880253267329605556587274644733","best_ask":"0.74","best_bid":"0.73","hash":"c4f5707accf7d65abe320b571c482276d29986bd","price":"0.8","side":"SELL","size":"279.53"}],"timestamp":"1785204324783"},"payload_hash":"cd52cc49a064ac1452d58e9af35e0658ae0e601e43d26e5e05a3ea9e4c654d1a","raw_frame":"{\"market\":\"0xda6f0e0e93fc8469e0159a166028d017bddbc162b86f66bac90391379603d962\", \"price_changes\":[{\"asset_id\":\"20893381255801015515826997628594359667013752732428989472914000440642900266717\", \"price\":\"0.2\", \"size\":\"279.53\", \"side\":\"BUY\", \"hash\":\"3f9d756e197afb7b79727a6b0bd1740c34f60242\", \"best_bid\":\"0.26\", \"best_ask\":\"0.27\"}, {\"asset_id\":\"39272994714739463168905443499424551362424437245880253267329605556587274644733\", \"price\":\"0.8\", \"size\":\"279.53\", \"side\":\"SELL\", \"hash\":\"c4f5707accf7d65abe320b571c482276d29986bd\", \"best_bid\":\"0.73\", \"best_ask\":\"0.74\"}], \"timestamp\":\"1785204324783\", \"event_type\":\"price_change\"}","received_at":"2026-07-28T02:05:32.354607Z","schema_version":"clob-market-ws.price_change.v1","sequence":null,"server_hash":null,"server_timestamp":"1785204324783","session_id":"d2757dd6dad94f3b9fe67e8dbf1adc37","source":"clob_market_ws"},"received_at":"2026-07-28T02:05:32.354607Z","record_id":"6a1fa0886f9cfedcace2ae71440cd9e1fc001874aaee891ccfbb67efc4c2154d","schema_fingerprint":"4aa3821a28b0b7c2400bc59aba4bcc0a76e971dadd19610d3ad38c768e124dc7","schema_version":"edge-lab-recorder.raw.v1","sequence":null,"source":"clob_market_ws"}
{"event_at":"2026-07-28T02:05:24.786000Z","event_fingerprint":"b4a9da6238de6fa27f7a12055581f6706cfc460ce45659982de47e84325097e0","payload":{"connection_id":"5d29200f65794d4d9ab6ef271f045a9b","event_at":"2026-07-28T02:05:24.786000Z","event_type":"price_change","frame_hash":"c486b1e939eeecaed25d348744dd9b707ce692640ea93683472d401ed23d4d04","frame_index":0,"kind":"data","monotonic_ns":306315365194958,"payload":{"event_type":"price_change","market":"0xda6f0e0e93fc8469e0159a166028d017bddbc162b86f66bac90391379603d962","price_changes":[{"asset_id":"20893381255801015515826997628594359667013752732428989472914000440642900266717","best_ask":"0.27","best_bid":"0.26","hash":"3ac62782a4a55f72918ee24186acb85b6f1dc123","price":"0.11","side":"BUY","size":"187.6"},{"asset_id":"39272994714739463168905443499424551362424437245880253267329605556587274644733","best_ask":"0.74","best_bid":"0.73","hash":"54972a2172f1905d4a5dda980de53f34d1e08625","price":"0.89","side":"SELL","size":"187.6"}],"timestamp":"1785204324786"},"payload_hash":"84262790fe5e6c7409c5fcc894b9427f687172169d0a8deab3344380c48ade8e","raw_frame":"{\"market\":\"0xda6f0e0e93fc8469e0159a166028d017bddbc162b86f66bac90391379603d962\", \"price_changes\":[{\"asset_id\":\"20893381255801015515826997628594359667013752732428989472914000440642900266717\", \"price\":\"0.11\", \"size\":\"187.6\", \"side\":\"BUY\", \"hash\":\"3ac62782a4a55f72918ee24186acb85b6f1dc123\", \"best_bid\":\"0.26\", \"best_ask\":\"0.27\"}, {\"asset_id\":\"39272994714739463168905443499424551362424437245880253267329605556587274644733\", \"price\":\"0.89\", \"size\":\"187.6\", \"side\":\"SELL\", \"hash\":\"54972a2172f1905d4a5dda980de53f34d1e08625\", \"best_bid\":\"0.73\", \"best_ask\":\"0.74\"}], \"timestamp\":\"1785204324786\", \"event_type\":\"price_change\"}","received_at":"2026-07-28T02:05:32.358853Z","schema_version":"clob-market-ws.price_change.v1","sequence":null,"server_hash":null,"server_timestamp":"1785204324786","session_id":"d2757dd6dad94f3b9fe67e8dbf1adc37","source":"clob_market_ws"},"received_at":"2026-07-28T02:05:32.358853Z","record_id":"933f34c321ae07d1900f717ca0e9bae9cdff28a0b7c70464b7ecbd1f70b8dcca","schema_fingerprint":"4aa3821a28b0b7c2400bc59aba4bcc0a76e971dadd19610d3ad38c768e124dc7","schema_version":"edge-lab-recorder.raw.v1","sequence":null,"source":"clob_market_ws"}
{"event_at":"2026-07-28T02:05:24.787000Z","event_fingerprint":"6d920ae80dc2b3302127eace0e8a1aebe10163717235bfd4f9673b0ffb886bd2","payload":{"connection_id":"5d29200f65794d4d9ab6ef271f045a9b","event_at":"2026-07-28T02:05:24.787000Z","event_type":"price_change","frame_hash":"007694ab52d6842176c0defe26810164df26835fb91db12e4240cb4ecd08c444","frame_index":0,"kind":"data","monotonic_ns":306315369452583,"payload":{"event_type":"price_change","market":"0xda6f0e0e93fc8469e0159a166028d017bddbc162b86f66bac90391379603d962","price_changes":[{"asset_id":"39272994714739463168905443499424551362424437245880253267329605556587274644733","best_ask":"0.74","best_bid":"0.73","hash":"e87c0912bdf506af73519506dd27323b19864907","price":"0.67","side":"BUY","size":"160"},{"asset_id":"20893381255801015515826997628594359667013752732428989472914000440642900266717","best_ask":"0.27","best_bid":"0.26","hash":"34948bcf62db76d2056106b51a76e0a8b7ca9f54","price":"0.33","side":"SELL","size":"160"}],"timestamp":"1785204324787"},"payload_hash":"9cebd96c032e9d3c4b42db0fcd979bb76d56e6101c28af7c618705d739ff153e","raw_frame":"{\"market\":\"0xda6f0e0e93fc8469e0159a166028d017bddbc162b86f66bac90391379603d962\", \"price_changes\":[{\"asset_id\":\"39272994714739463168905443499424551362424437245880253267329605556587274644733\", \"price\":\"0.67\", \"size\":\"160\", \"side\":\"BUY\", \"hash\":\"e87c0912bdf506af73519506dd27323b19864907\", \"best_bid\":\"0.73\", \"best_ask\":\"0.74\"}, {\"asset_id\":\"20893381255801015515826997628594359667013752732428989472914000440642900266717\", \"price\":\"0.33\", \"size\":\"160\", \"side\":\"SELL\", \"hash\":\"34948bcf62db76d2056106b51a76e0a8b7ca9f54\", \"best_bid\":\"0.26\", \"best_ask\":\"0.27\"}], \"timestamp\":\"1785204324787\", \"event_type\":\"price_change\"}","received_at":"2026-07-28T02:05:32.363112Z","schema_version":"clob-market-ws.price_change.v1","sequence":null,"server_hash":null,"server_timestamp":"1785204324787","session_id":"d2757dd6dad94f3b9fe67e8dbf1adc37","source":"clob_market_ws"},"received_at":"2026-07-28T02:05:32.363112Z","record_id":"0b3ce9109ce7c7b84decab344069065586a42c6f3307d1de4864cb0b6d934d45","schema_fingerprint":"4aa3821a28b0b7c2400bc59aba4bcc0a76e971dadd19610d3ad38c768e124dc7","schema_version":"edge-lab-recorder.raw.v1","sequence":null,"source":"clob_market_ws"}
{"event_at":"2026-07-28T02:05:24.788000Z","event_fingerprint":"4bc0aef4acd0d8fd9e573c6cbf7ecc15b6f5a354d3c204d0f3342f0448bec466","payload":{"connection_id":"5d29200f65794d4d9ab6ef271f045a9b","event_at":"2026-07-28T02:05:24.788000Z","event_type":"price_change","frame_hash":"0d5285789ed115c184d4851447cd7ca708dab28487f80bd98040db44e0f6f222","frame_index":0,"kind":"data","monotonic_ns":306315374103833,"payload":{"event_type":"price_change","market":"0xda6f0e0e93fc8469e0159a166028d017bddbc162b86f66bac90391379603d962","price_changes":[{"asset_id":"39272994714739463168905443499424551362424437245880253267329605556587274644733","best_ask":"0.74","best_bid":"0.73","hash":"586730594aec9d9ebe5055871dd34838b0019c93","price":"0.71","side":"BUY","size":"108.6"},{"asset_id":"20893381255801015515826997628594359667013752732428989472914000440642900266717","best_ask":"0.27","best_bid":"0.26","hash":"fb15567a577d251bac2b92c010433c1af7ff1e11","price":"0.29","side":"SELL","size":"108.6"}],"timestamp":"1785204324788"},"payload_hash":"5906491f9e726ba771ec5e53b01ef43fb1e1fc10ce587fa740755b950cf2eb97","raw_frame":"{\"market\":\"0xda6f0e0e93fc8469e0159a166028d017bddbc162b86f66bac90391379603d962\", \"price_changes\":[{\"asset_id\":\"39272994714739463168905443499424551362424437245880253267329605556587274644733\", \"price\":\"0.71\", \"size\":\"108.6\", \"side\":\"BUY\", \"hash\":\"586730594aec9d9ebe5055871dd34838b0019c93\", \"best_bid\":\"0.73\", \"best_ask\":\"0.74\"}, {\"asset_id\":\"20893381255801015515826997628594359667013752732428989472914000440642900266717\", \"price\":\"0.29\", \"size\":\"108.6\", \"side\":\"SELL\", \"hash\":\"fb15567a577d251bac2b92c010433c1af7ff1e11\", \"best_bid\":\"0.26\", \"best_ask\":\"0.27\"}], \"timestamp\":\"1785204324788\", \"event_type\":\"price_change\"}","received_at":"2026-07-28T02:05:32.367762Z","schema_version":"clob-market-ws.price_change.v1","sequence":null,"server_hash":null,"server_timestamp":"1785204324788","session_id":"d2757dd6dad94f3b9fe67e8dbf1adc37","source":"clob_market_ws"},"received_at":"2026-07-28T02:05:32.367762Z","record_id":"5ae94f1300aff34b38fcaff71dbdbfa8d131322dab0ceb3e55f3ccbb51cd4632","schema_fingerprint":"4aa3821a28b0b7c2400bc59aba4bcc0a76e971dadd19610d3ad38c768e124dc7","schema_version":"edge-lab-recorder.raw.v1","sequence":null,"source":"clob_market_ws"}
{"event_at":"2026-07-28T02:05:24.789000Z","event_fingerprint":"9a92327c777baf2031b171e5c6967b38392f01f8ba384c7d519107d43c81f6dd","payload":{"connection_id":"5d29200f65794d4d9ab6ef271f045a9b","event_at":"2026-07-28T02:05:24.789000Z","event_type":"price_change","frame_hash":"75840055b93e3c6b55fa632a3b12d2e53f21627734f81325ab5ca9f58bfec555","frame_index":0,"kind":"data","monotonic_ns":306315378399000,"payload":{"event_type":"price_change","market":"0xda6f0e0e93fc8469e0159a166028d017bddbc162b86f66bac90391379603d962","price_changes":[{"asset_id":"20893381255801015515826997628594359667013752732428989472914000440642900266717","best_ask":"0.27","best_bid":"0.26","hash":"b90152c6ab625ab2eff3f344a4be48c457df5d62","price":"0.18","side":"BUY","size":"178.3"},{"asset_id":"39272994714739463168905443499424551362424437245880253267329605556587274644733","best_ask":"0.74","best_bid":"0.73","hash":"061141bc1490fe228e32f75d82fcfb4140f7fe6a","price":"0.82","side":"SELL","size":"178.3"}],"timestamp":"1785204324789"},"payload_hash":"e2992c7249b5271cba2d78590a9f474beed6204b54afc74b761cfaf667015f6b","raw_frame":"{\"market\":\"0xda6f0e0e93fc8469e0159a166028d017bddbc162b86f66bac90391379603d962\", \"price_changes\":[{\"asset_id\":\"20893381255801015515826997628594359667013752732428989472914000440642900266717\", \"price\":\"0.18\", \"size\":\"178.3\", \"side\":\"BUY\", \"hash\":\"b90152c6ab625ab2eff3f344a4be48c457df5d62\", \"best_bid\":\"0.26\", \"best_ask\":\"0.27\"}, {\"asset_id\":\"39272994714739463168905443499424551362424437245880253267329605556587274644733\", \"price\":\"0.82\", \"size\":\"178.3\", \"side\":\"SELL\", \"hash\":\"061141bc1490fe228e32f75d82fcfb4140f7fe6a\", \"best_bid\":\"0.73\", \"best_ask\":\"0.74\"}], \"timestamp\":\"1785204324789\", \"event_type\":\"price_change\"}","received_at":"2026-07-28T02:05:32.372057Z","schema_version":"clob-market-ws.price_change.v1","sequence":null,"server_hash":null,"server_timestamp":"1785204324789","session_id":"d2757dd6dad94f3b9fe67e8dbf1adc37","source":"clob_market_ws"},"received_at":"2026-07-28T02:05:32.372057Z","record_id":"c2e1850124f21a73d4925e1a88c592bad467d4411e00dcbd85cb8bfb6bfdd6bd","schema_fingerprint":"4aa3821a28b0b7c2400bc59aba4bcc0a76e971dadd19610d3ad38c768e124dc7","schema_version":"edge-lab-recorder.raw.v1","sequence":null,"source":"clob_market_ws"}
{"event_at":"2026-07-28T02:05:24.790000Z","event_fingerprint":"db10e56eec3f55984f26c721f356feba0cb2229e2bc464590c0f591f8ff24cb8","payload":{"connection_id":"5d29200f65794d4d9ab6ef271f045a9b","event_at":"2026-07-28T02:05:24.790000Z","event_type":"price_change","frame_hash":"1f7b17c77a005e72d2d8b15dc59f6dd7b71f1cec6191a4b0277eebaeedc94190","frame_index":0,"kind":"data","monotonic_ns":306315382727166,"payload":{"event_type":"price_change","market":"0xda6f0e0e93fc8469e0159a166028d017bddbc162b86f66bac90391379603d962","price_changes":[{"asset_id":"20893381255801015515826997628594359667013752732428989472914000440642900266717","best_ask":"0.27","best_bid":"0.26","hash":"1f3deef60d600ca354193815e7289df94e2791d5","price":"0.2","side":"BUY","size":"309.53"},{"asset_id":"39272994714739463168905443499424551362424437245880253267329605556587274644733","best_ask":"0.74","best_bid":"0.73","hash":"8ca69aac7d011760f966b076903ae8101d83020c","price":"0.8","side":"SELL","size":"309.53"}],"timestamp":"1785204324790"},"payload_hash":"7b63fc34789ed128af0c3d9b4736de8354b4fe0825d11b9b214dcc0a94d22a29","raw_frame":"{\"market\":\"0xda6f0e0e93fc8469e0159a166028d017bddbc162b86f66bac90391379603d962\", \"price_changes\":[{\"asset_id\":\"20893381255801015515826997628594359667013752732428989472914000440642900266717\", \"price\":\"0.2\", \"size\":\"309.53\", \"side\":\"BUY\", \"hash\":\"1f3deef60d600ca354193815e7289df94e2791d5\", \"best_bid\":\"0.26\", \"best_ask\":\"0.27\"}, {\"asset_id\":\"39272994714739463168905443499424551362424437245880253267329605556587274644733\", \"price\":\"0.8\", \"size\":\"309.53\", \"side\":\"SELL\", \"hash\":\"8ca69aac7d011760f966b076903ae8101d83020c\", \"best_bid\":\"0.73\", \"best_ask\":\"0.74\"}], \"timestamp\":\"1785204324790\", \"event_type\":\"price_change\"}","received_at":"2026-07-28T02:05:32.376385Z","schema_version":"clob-market-ws.price_change.v1","sequence":null,"server_hash":null,"server_timestamp":"1785204324790","session_id":"d2757dd6dad94f3b9fe67e8dbf1adc37","source":"clob_market_ws"},"received_at":"2026-07-28T02:05:32.376385Z","record_id":"ece75c43fd4a13b05789338ebc5db035d28af11e9d3b61b601cf3eb653171efb","schema_fingerprint":"4aa3821a28b0b7c2400bc59aba4bcc0a76e971dadd19610d3ad38c768e124dc7","schema_version":"edge-lab-recorder.raw.v1","sequence":null,"source":"clob_market_ws"}
{"event_at":"2026-07-28T02:05:24.792000Z","event_fingerprint":"d6246537f0529c9f514fcb95d5f351b5979d93e8d568d2823071db4fbbb4041b","payload":{"connection_id":"5d29200f65794d4d9ab6ef271f045a9b","event_at":"2026-07-28T02:05:24.792000Z","event_type":"price_change","frame_hash":"bf4ab2ef5cbb6b7af481dbdf8e12d826da2c17002c5e46cf8817e52163de3434","frame_index":0,"kind":"data","monotonic_ns":306315387229166,"payload":{"event_type":"price_change","market":"0xda6f0e0e93fc8469e0159a166028d017bddbc162b86f66bac90391379603d962","price_changes":[{"asset_id":"39272994714739463168905443499424551362424437245880253267329605556587274644733","best_ask":"0.74","best_bid":"0.73","hash":"83029c4eb548ed1b0dd8cead34dbb4a03defd9b9","price":"0.72","side":"BUY","size":"35"},{"asset_id":"20893381255801015515826997628594359667013752732428989472914000440642900266717","best_ask":"0.27","best_bid":"0.26","hash":"f57dcb8d948b65748cee1163a63ef4f26bf0fbd3","price":"0.28","side":"SELL","size":"35"}],"timestamp":"1785204324792"},"payload_hash":"18a9fad24e25f800b6d9105a7226d5eda053b6b4cbff3e3dae28e89570c6cb34","raw_frame":"{\"market\":\"0xda6f0e0e93fc8469e0159a166028d017bddbc162b86f66bac90391379603d962\", \"price_changes\":[{\"asset_id\":\"39272994714739463168905443499424551362424437245880253267329605556587274644733\", \"price\":\"0.72\", \"size\":\"35\", \"side\":\"BUY\", \"hash\":\"83029c4eb548ed1b0dd8cead34dbb4a03defd9b9\", \"best_bid\":\"0.73\", \"best_ask\":\"0.74\"}, {\"asset_id\":\"20893381255801015515826997628594359667013752732428989472914000440642900266717\", \"price\":\"0.28\", \"size\":\"35\", \"side\":\"SELL\", \"hash\":\"f57dcb8d948b65748cee1163a63ef4f26bf0fbd3\", \"best_bid\":\"0.26\", \"best_ask\":\"0.27\"}], \"timestamp\":\"1785204324792\", \"event_type\":\"price_change\"}","received_at":"2026-07-28T02:05:32.380888Z","schema_version":"clob-market-ws.price_change.v1","sequence":null,"server_hash":null,"server_timestamp":"1785204324792","session_id":"d2757dd6dad94f3b9fe67e8dbf1adc37","source":"clob_market_ws"},"received_at":"2026-07-28T02:05:32.380888Z","record_id":"7c6562164893d08bead520f0c90de4098c0ef1516e2e6a31e31624b3169d4b32","schema_fingerprint":"4aa3821a28b0b7c2400bc59aba4bcc0a76e971dadd19610d3ad38c768e124dc7","schema_version":"edge-lab-recorder.raw.v1","sequence":null,"source":"clob_market_ws"}
{"event_at":"2026-07-28T02:05:24.793000Z","event_fingerprint":"e973db1991c3e4d11bd5a9361f648145e72beac668b2311cff6dd0e67c44aebf","payload":{"connection_id":"5d29200f65794d4d9ab6ef271f045a9b","event_at":"2026-07-28T02:05:24.793000Z","event_type":"price_change","frame_hash":"fdb9f7d03d536e1fce716c477474c7a63702e95c35ab1c58adafeca961ed39c7","frame_index":0,"kind":"data","monotonic_ns":306315391544416,"payload":{"event_type":"price_change","market":"0xda6f0e0e93fc8469e0159a166028d017bddbc162b86f66bac90391379603d962","price_changes":[{"asset_id":"20893381255801015515826997628594359667013752732428989472914000440642900266717","best_ask":"0.27","best_bid":"0.26","hash":"dd7427b48e31fa69aaabd49d45e03535fbc442a8","price":"0.21","side":"BUY","size":"112.18"},{"asset_id":"39272994714739463168905443499424551362424437245880253267329605556587274644733","best_ask":"0.74","best_bid":"0.73","hash":"bda2076f51f779bbc6aeb1909e24bd075e27f7a3","price":"0.79","side":"SELL","size":"112.18"}],"timestamp":"1785204324793"},"payload_hash":"a7dc685cac620a776852a06bc6c08931b8f6309edd9d5a60225eeb880b328293","raw_frame":"{\"market\":\"0xda6f0e0e93fc8469e0159a166028d017bddbc162b86f66bac90391379603d962\", \"price_changes\":[{\"asset_id\":\"20893381255801015515826997628594359667013752732428989472914000440642900266717\", \"price\":\"0.21\", \"size\":\"112.18\", \"side\":\"BUY\", \"hash\":\"dd7427b48e31fa69aaabd49d45e03535fbc442a8\", \"best_bid\":\"0.26\", \"best_ask\":\"0.27\"}, {\"asset_id\":\"39272994714739463168905443499424551362424437245880253267329605556587274644733\", \"price\":\"0.79\", \"size\":\"112.18\", \"side\":\"SELL\", \"hash\":\"bda2076f51f779bbc6aeb1909e24bd075e27f7a3\", \"best_bid\":\"0.73\", \"best_ask\":\"0.74\"}], \"timestamp\":\"1785204324793\", \"event_type\":\"price_change\"}","received_at":"2026-07-28T02:05:32.385203Z","schema_version":"clob-market-ws.price_change.v1","sequence":null,"server_hash":null,"server_timestamp":"1785204324793","session_id":"d2757dd6dad94f3b9fe67e8dbf1adc37","source":"clob_market_ws"},"received_at":"2026-07-28T02:05:32.385203Z","record_id":"458da0dc14f91465319dfd7345189b6c3d74ef20a4a65ed72b586c1addbc72f5","schema_fingerprint":"4aa3821a28b0b7c2400bc59aba4bcc0a76e971dadd19610d3ad38c768e124dc7","schema_version":"edge-lab-recorder.raw.v1","sequence":null,"source":"clob_market_ws"}
{"event_at":"2026-07-28T02:05:24.803000Z","event_fingerprint":"51e9ccff6389db1c3fab4933f2e4ef96ccfa13bc66b370142a648af3314c9c98","payload":{"connection_id":"5d29200f65794d4d9ab6ef271f045a9b","event_at":"2026-07-28T02:05:24.803000Z","event_type":"price_change","frame_hash":"90464955964af28fefd75015d9916d04c7189a035373a848830cd297f03d4d16","frame_index":0,"kind":"data","monotonic_ns":306315394503750,"payload":{"event_type":"price_change","market":"0xda6f0e0e93fc8469e0159a166028d017bddbc162b86f66bac90391379603d962","price_changes":[{"asset_id":"20893381255801015515826997628594359667013752732428989472914000440642900266717","best_ask":"0.27","best_bid":"0.26","hash":"f20c518c1ad2a1d8ea0fa922b22f3ec9b12e131d","price":"0.2","side":"BUY","size":"291.8"},{"asset_id":"39272994714739463168905443499424551362424437245880253267329605556587274644733","best_ask":"0.74","best_bid":"0.73","hash":"ec42770c523b7c8a75629cd063b2320198f5fda9","price":"0.8","side":"SELL","size":"291.8"}],"timestamp":"1785204324803"},"payload_hash":"2e44f58a12fd63b4f8e18d0fb702cd100d44a0eab0027beb91f065b01eec5bb9","raw_frame":"{\"market\":\"0xda6f0e0e93fc8469e0159a166028d017bddbc162b86f66bac90391379603d962\", \"price_changes\":[{\"asset_id\":\"20893381255801015515826997628594359667013752732428989472914000440642900266717\", \"price\":\"0.2\", \"size\":\"291.8\", \"side\":\"BUY\", \"hash\":\"f20c518c1ad2a1d8ea0fa922b22f3ec9b12e131d\", \"best_bid\":\"0.26\", \"best_ask\":\"0.27\"}, {\"asset_id\":\"39272994714739463168905443499424551362424437245880253267329605556587274644733\", \"price\":\"0.8\", \"size\":\"291.8\", \"side\":\"SELL\", \"hash\":\"ec42770c523b7c8a75629cd063b2320198f5fda9\", \"best_bid\":\"0.73\", \"best_ask\":\"0.74\"}], \"timestamp\":\"1785204324803\", \"event_type\":\"price_change\"}","received_at":"2026-07-28T02:05:32.388162Z","schema_version":"clob-market-ws.price_change.v1","sequence":null,"server_hash":null,"server_timestamp":"1785204324803","session_id":"d2757dd6dad94f3b9fe67e8dbf1adc37","source":"clob_market_ws"},"received_at":"2026-07-28T02:05:32.388162Z","record_id":"cd07dc44377a3b534a15479ba3d9897ee31ed9bf350c5ab158ac9fb1b995f464","schema_fingerprint":"4aa3821a28b0b7c2400bc59aba4bcc0a76e971dadd19610d3ad38c768e124dc7","schema_version":"edge-lab-recorder.raw.v1","sequence":null,"source":"clob_market_ws"}
{"event_at":"2026-07-28T02:05:24.806000Z","event_fingerprint":"124d1ea27a817c83357fd4ce023a13bd32a843f261ddf6c4f1b49c6d2961ed01","payload":{"connection_id":"5d29200f65794d4d9ab6ef271f045a9b","event_at":"2026-07-28T02:05:24.806000Z","event_type":"price_change","frame_hash":"396807f8ef47e86a8fe6cbc012203fc662b09cd0ae47d8dade30a6a0143b193b","frame_index":0,"kind":"data","monotonic_ns":306315398921125,"payload":{"event_type":"price_change","market":"0xda6f0e0e93fc8469e0159a166028d017bddbc162b86f66bac90391379603d962","price_changes":[{"asset_id":"20893381255801015515826997628594359667013752732428989472914000440642900266717","best_ask":"0.27","best_bid":"0.26","hash":"d175c0b27e31a78352bfc8f3991df8dca3fdba22","price":"0.21","side":"BUY","size":"130.28"},{"asset_id":"39272994714739463168905443499424551362424437245880253267329605556587274644733","best_ask":"0.74","best_bid":"0.73","hash":"188cadb61794baec3143b2358cc058e3cf861e11","price":"0.79","side":"SELL","size":"130.28"}],"timestamp":"1785204324806"},"payload_hash":"7aca9121d29184bd95ac9e9be0137b762d38e9dcf23e7aae0973f476b4c49385","raw_frame":"{\"market\":\"0xda6f0e0e93fc8469e0159a166028d017bddbc162b86f66bac90391379603d962\", \"price_changes\":[{\"asset_id\":\"20893381255801015515826997628594359667013752732428989472914000440642900266717\", \"price\":\"0.21\", \"size\":\"130.28\", \"side\":\"BUY\", \"hash\":\"d175c0b27e31a78352bfc8f3991df8dca3fdba22\", \"best_bid\":\"0.26\", \"best_ask\":\"0.27\"}, {\"asset_id\":\"39272994714739463168905443499424551362424437245880253267329605556587274644733\", \"price\":\"0.79\", \"size\":\"130.28\", \"side\":\"SELL\", \"hash\":\"188cadb61794baec3143b2358cc058e3cf861e11\", \"best_bid\":\"0.73\", \"best_ask\":\"0.74\"}], \"timestamp\":\"1785204324806\", \"event_type\":\"price_change\"}","received_at":"2026-07-28T02:05:32.392578Z","schema_version":"clob-market-ws.price_change.v1","sequence":null,"server_hash":null,"server_timestamp":"1785204324806","session_id":"d2757dd6dad94f3b9fe67e8dbf1adc37","source":"clob_market_ws"},"received_at":"2026-07-28T02:05:32.392578Z","record_id":"b6bd8e2b2867f6121ddc92dbaa4d4e08cbd377658e1d50271c7b49d5f9e5fc3f","schema_fingerprint":"4aa3821a28b0b7c2400bc59aba4bcc0a76e971dadd19610d3ad38c768e124dc7","schema_version":"edge-lab-recorder.raw.v1","sequence":null,"source":"clob_market_ws"}
{"event_at":"2026-07-28T02:05:24.810000Z","event_fingerprint":"9803872ad69bd25ab26923536d8f648fef38c71a010edce5248d3e66fdaaaa52","payload":{"connection_id":"5d29200f65794d4d9ab6ef271f045a9b","event_at":"2026-07-28T02:05:24.810000Z","event_type":"price_change","frame_hash":"4d5a22fd0c8ea5aaac645da6ddc232092a2cec284ff1776909d580fc5f9af408","frame_index":0,"kind":"data","monotonic_ns":306315403352375,"payload":{"event_type":"price_change","market":"0xda6f0e0e93fc8469e0159a166028d017bddbc162b86f66bac90391379603d962","price_changes":[{"asset_id":"39272994714739463168905443499424551362424437245880253267329605556587274644733","best_ask":"0.74","best_bid":"0.73","hash":"e3f96ffbdcdcd142f762ec63dcad0d7689caaf67","price":"0.67","side":"BUY","size":"173.22"},{"asset_id":"20893381255801015515826997628594359667013752732428989472914000440642900266717","best_ask":"0.27","best_bid":"0.26","hash":"2e55f5bd0ab4f0d8202fd55740e921e2c069ce31","price":"0.33","side":"SELL","size":"173.22"}],"timestamp":"1785204324810"},"payload_hash":"73536f249158a4dfb6ab4108d3fb13e8c25f88f059ac4751aef004754437d6d8","raw_frame":"{\"market\":\"0xda6f0e0e93fc8469e0159a166028d017bddbc162b86f66bac90391379603d962\", \"price_changes\":[{\"asset_id\":\"39272994714739463168905443499424551362424437245880253267329605556587274644733\", \"price\":\"0.67\", \"size\":\"173.22\", \"side\":\"BUY\", \"hash\":\"e3f96ffbdcdcd142f762ec63dcad0d7689caaf67\", \"best_bid\":\"0.73\", \"best_ask\":\"0.74\"}, {\"asset_id\":\"20893381255801015515826997628594359667013752732428989472914000440642900266717\", \"price\":\"0.33\", \"size\":\"173.22\", \"side\":\"SELL\", \"hash\":\"2e55f5bd0ab4f0d8202fd55740e921e2c069ce31\", \"best_bid\":\"0.26\", \"best_ask\":\"0.27\"}], \"timestamp\":\"1785204324810\", \"event_type\":\"price_change\"}","received_at":"2026-07-28T02:05:32.397011Z","schema_version":"clob-market-ws.price_change.v1","sequence":null,"server_hash":null,"server_timestamp":"1785204324810","session_id":"d2757dd6dad94f3b9fe67e8dbf1adc37","source":"clob_market_ws"},"received_at":"2026-07-28T02:05:32.397011Z","record_id":"511d6dac58544d88b9813f376341ba04288528f52e90526fefd699b22e4cac6d","schema_fingerprint":"4aa3821a28b0b7c2400bc59aba4bcc0a76e971dadd19610d3ad38c768e124dc7","schema_version":"edge-lab-recorder.raw.v1","sequence":null,"source":"clob_market_ws"}
{"event_at":"2026-07-28T02:05:24.811000Z","event_fingerprint":"2c8d82144ab9ddfc54d073fe4cd6ee0810b2481265fe62c64143b0fffae45082","payload":{"connection_id":"5d29200f65794d4d9ab6ef271f045a9b","event_at":"2026-07-28T02:05:24.811000Z","event_type":"price_change","frame_hash":"2e9a42cbe9ae06476fd97728891a34847a4cbad09ad652dcdb030ee7de86b9f5","frame_index":0,"kind":"data","monotonic_ns":306315407383166,"payload":{"event_type":"price_change","market":"0xda6f0e0e93fc8469e0159a166028d017bddbc162b86f66bac90391379603d962","price_changes":[{"asset_id":"20893381255801015515826997628594359667013752732428989472914000440642900266717","best_ask":"0.27","best_bid":"0.26","hash":"66d5140675a1ce2bec996c5cb3a3166d1736f3ee","price":"0.13","side":"BUY","size":"419"},{"asset_id":"39272994714739463168905443499424551362424437245880253267329605556587274644733","best_ask":"0.74","best_bid":"0.73","hash":"bd35afbfad4332ad7fbd7614da75472c920d3f5f","price":"0.87","side":"SELL","size":"419"}],"timestamp":"1785204324811"},"payload_hash":"5cec7b7ecc9bae0ffaf1ece90489e358c9ee7c49f99bb4673e0274f54a0f926c","raw_frame":"{\"market\":\"0xda6f0e0e93fc8469e0159a166028d017bddbc162b86f66bac90391379603d962\", \"price_changes\":[{\"asset_id\":\"20893381255801015515826997628594359667013752732428989472914000440642900266717\", \"price\":\"0.13\", \"size\":\"419\", \"side\":\"BUY\", \"hash\":\"66d5140675a1ce2bec996c5cb3a3166d1736f3ee\", \"best_bid\":\"0.26\", \"best_ask\":\"0.27\"}, {\"asset_id\":\"39272994714739463168905443499424551362424437245880253267329605556587274644733\", \"price\":\"0.87\", \"size\":\"419\", \"side\":\"SELL\", \"hash\":\"bd35afbfad4332ad7fbd7614da75472c920d3f5f\", \"best_bid\":\"0.73\", \"best_ask\":\"0.74\"}], \"timestamp\":\"1785204324811\", \"event_type\":\"price_change\"}","received_at":"2026-07-28T02:05:32.401039Z","schema_version":"clob-market-ws.price_change.v1","sequence":null,"server_hash":null,"server_timestamp":"1785204324811","session_id":"d2757dd6dad94f3b9fe67e8dbf1adc37","source":"clob_market_ws"},"received_at":"2026-07-28T02:05:32.401039Z","record_id":"2d92e916188f9fa5aa039f20641938824f413ecc7c8266ec08e67eb290e986c0","schema_fingerprint":"4aa3821a28b0b7c2400bc59aba4bcc0a76e971dadd19610d3ad38c768e124dc7","schema_version":"edge-lab-recorder.raw.v1","sequence":null,"source":"clob_market_ws"}
{"event_at":"2026-07-28T02:05:24.812000Z","event_fingerprint":"c1785cc0fac05cd599bf27fc6894e707748b156cc7ea4df59ed4538d841d0764","payload":{"connection_id":"5d29200f65794d4d9ab6ef271f045a9b","event_at":"2026-07-28T02:05:24.812000Z","event_type":"price_change","frame_hash":"ce219d9cfc1a72a97951b8c0816bbc06ad5e28883b1a5aff0ed5e31965209c1c","frame_index":0,"kind":"data","monotonic_ns":306315410840541,"payload":{"event_type":"price_change","market":"0xda6f0e0e93fc8469e0159a166028d017bddbc162b86f66bac90391379603d962","price_changes":[{"asset_id":"39272994714739463168905443499424551362424437245880253267329605556587274644733","best_ask":"0.74","best_bid":"0.73","hash":"3e865b4ebaf9bf0ff3d352d2ff4cddaf1f8e084e","price":"0.57","side":"BUY","size":"162.2"},{"asset_id":"20893381255801015515826997628594359667013752732428989472914000440642900266717","best_ask":"0.27","best_bid":"0.26","hash":"9ef5a6d22042e6baca7640ebc6c8ccad58863b30","price":"0.43","side":"SELL","size":"162.2"}],"timestamp":"1785204324812"},"payload_hash":"65d072527d728f5a12534c56bbe27d202a6c2359f352ecd8e14c912c61e3f4ae","raw_frame":"{\"market\":\"0xda6f0e0e93fc8469e0159a166028d017bddbc162b86f66bac90391379603d962\", \"price_changes\":[{\"asset_id\":\"39272994714739463168905443499424551362424437245880253267329605556587274644733\", \"price\":\"0.57\", \"size\":\"162.2\", \"side\":\"BUY\", \"hash\":\"3e865b4ebaf9bf0ff3d352d2ff4cddaf1f8e084e\", \"best_bid\":\"0.73\", \"best_ask\":\"0.74\"}, {\"asset_id\":\"20893381255801015515826997628594359667013752732428989472914000440642900266717\", \"price\":\"0.43\", \"size\":\"162.2\", \"side\":\"SELL\", \"hash\":\"9ef5a6d22042e6baca7640ebc6c8ccad58863b30\", \"best_bid\":\"0.26\", \"best_ask\":\"0.27\"}], \"timestamp\":\"1785204324812\", \"event_type\":\"price_change\"}","received_at":"2026-07-28T02:05:32.404500Z","schema_version":"clob-market-ws.price_change.v1","sequence":null,"server_hash":null,"server_timestamp":"1785204324812","session_id":"d2757dd6dad94f3b9fe67e8dbf1adc37","source":"clob_market_ws"},"received_at":"2026-07-28T02:05:32.404500Z","record_id":"81b2504ef094bb9ac640bfbb23b9e76ac2c86162d512f00ca37acb73471ec6bd","schema_fingerprint":"4aa3821a28b0b7c2400bc59aba4bcc0a76e971dadd19610d3ad38c768e124dc7","schema_version":"edge-lab-recorder.raw.v1","sequence":null,"source":"clob_market_ws"}
{"event_at":"2026-07-28T02:05:24.812000Z","event_fingerprint":"8c94129ba8e70a719172e3842792de5ba6b03f85c7db0650d084e5f1d7d9820c","payload":{"connection_id":"5d29200f65794d4d9ab6ef271f045a9b","event_at":"2026-07-28T02:05:24.812000Z","event_type":"price_change","frame_hash":"f31c109fc331f90016ab5f196bafa7ec6930f8b3f0341cc2d7a0066a6ecc20b1","frame_index":0,"kind":"data","monotonic_ns":306315415733916,"payload":{"event_type":"price_change","market":"0xda6f0e0e93fc8469e0159a166028d017bddbc162b86f66bac90391379603d962","price_changes":[{"asset_id":"20893381255801015515826997628594359667013752732428989472914000440642900266717","best_ask":"0.27","best_bid":"0.26","hash":"81a15eb4ef7ffb093649c5368c9e1357e8dc3810","price":"0.24","side":"BUY","size":"95.66"},{"asset_id":"39272994714739463168905443499424551362424437245880253267329605556587274644733","best_ask":"0.74","best_bid":"0.73","hash":"1977f81ec025f3bda4fe9063ac6d79de0d5f5717","price":"0.76","side":"SELL","size":"95.66"}],"timestamp":"1785204324812"},"payload_hash":"29886f2bfd63274dacdd559a81bfbee4364c75401ce0c87816b141d121b072d9","raw_frame":"{\"market\":\"0xda6f0e0e93fc8469e0159a166028d017bddbc162b86f66bac90391379603d962\", \"price_changes\":[{\"asset_id\":\"20893381255801015515826997628594359667013752732428989472914000440642900266717\", \"price\":\"0.24\", \"size\":\"95.66\", \"side\":\"BUY\", \"hash\":\"81a15eb4ef7ffb093649c5368c9e1357e8dc3810\", \"best_bid\":\"0.26\", \"best_ask\":\"0.27\"}, {\"asset_id\":\"39272994714739463168905443499424551362424437245880253267329605556587274644733\", \"price\":\"0.76\", \"size\":\"95.66\", \"side\":\"SELL\", \"hash\":\"1977f81ec025f3bda4fe9063ac6d79de0d5f5717\", \"best_bid\":\"0.73\", \"best_ask\":\"0.74\"}], \"timestamp\":\"1785204324812\", \"event_type\":\"price_change\"}","received_at":"2026-07-28T02:05:32.409391Z","schema_version":"clob-market-ws.price_change.v1","sequence":null,"server_hash":null,"server_timestamp":"1785204324812","session_id":"d2757dd6dad94f3b9fe67e8dbf1adc37","source":"clob_market_ws"},"received_at":"2026-07-28T02:05:32.409391Z","record_id":"ce0fab05a6ff15a2227aee1bfcae1f008fc6059eb0430f717e9f4b1440213127","schema_fingerprint":"4aa3821a28b0b7c2400bc59aba4bcc0a76e971dadd19610d3ad38c768e124dc7","schema_version":"edge-lab-recorder.raw.v1","sequence":null,"source":"clob_market_ws"}
{"event_at":"2026-07-28T02:05:24.816000Z","event_fingerprint":"02af4a21c4592bacc6261501604d33a0148388882be97196ca3d131e96b8376e","payload":{"connection_id":"5d29200f65794d4d9ab6ef271f045a9b","event_at":"2026-07-28T02:05:24.816000Z","event_type":"price_change","frame_hash":"e68411757fb42d3e7b3ae0a1cc5f128144ca16f183237a2581617b5f56bb1bc6","frame_index":0,"kind":"data","monotonic_ns":306315420057416,"payload":{"event_type":"price_change","market":"0xda6f0e0e93fc8469e0159a166028d017bddbc162b86f66bac90391379603d962","price_changes":[{"asset_id":"20893381255801015515826997628594359667013752732428989472914000440642900266717","best_ask":"0.27","best_bid":"0.26","hash":"eb185023e9d61e90bd906a9005f6d624587f888c","price":"0.2","side":"BUY","size":"281.8"},{"asset_id":"39272994714739463168905443499424551362424437245880253267329605556587274644733","best_ask":"0.74","best_bid":"0.73","hash":"bb9c8dd95e1926c1a127ad3781e8b958c6d25090","price":"0.8","side":"SELL","size":"281.8"}],"timestamp":"1785204324816"},"payload_hash":"a90e0dc0839c0846b5f09c63a20a70842e6a53693447b0566fe5a0950785ae4c","raw_frame":"{\"market\":\"0xda6f0e0e93fc8469e0159a166028d017bddbc162b86f66bac90391379603d962\", \"price_changes\":[{\"asset_id\":\"20893381255801015515826997628594359667013752732428989472914000440642900266717\", \"price\":\"0.2\", \"size\":\"281.8\", \"side\":\"BUY\", \"hash\":\"eb185023e9d61e90bd906a9005f6d624587f888c\", \"best_bid\":\"0.26\", \"best_ask\":\"0.27\"}, {\"asset_id\":\"39272994714739463168905443499424551362424437245880253267329605556587274644733\", \"price\":\"0.8\", \"size\":\"281.8\", \"side\":\"SELL\", \"hash\":\"bb9c8dd95e1926c1a127ad3781e8b958c6d25090\", \"best_bid\":\"0.73\", \"best_ask\":\"0.74\"}], \"timestamp\":\"1785204324816\", \"event_type\":\"price_change\"}","received_at":"2026-07-28T02:05:32.413716Z","schema_version":"clob-market-ws.price_change.v1","sequence":null,"server_hash":null,"server_timestamp":"1785204324816","session_id":"d2757dd6dad94f3b9fe67e8dbf1adc37","source":"clob_market_ws"},"received_at":"2026-07-28T02:05:32.413716Z","record_id":"bcbb4d8f705ee0e6bf47176c48842feda9f01e937caefea427798d1f6a491e7a","schema_fingerprint":"4aa3821a28b0b7c2400bc59aba4bcc0a76e971dadd19610d3ad38c768e124dc7","schema_version":"edge-lab-recorder.raw.v1","sequence":null,"source":"clob_market_ws"}
{"event_at":"2026-07-28T02:05:24.816000Z","event_fingerprint":"efc00f353deac9f1c7ee097919bc7529bb7c0e8ed2b9b1b5789af032001575c1","payload":{"connection_id":"5d29200f65794d4d9ab6ef271f045a9b","event_at":"2026-07-28T02:05:24.816000Z","event_type":"price_change","frame_hash":"d7a1246629c88053745822eec9bfc163a9420c2bcd71c031fe196e9c5b44a9c4","frame_index":0,"kind":"data","monotonic_ns":306315424355500,"payload":{"event_type":"price_change","market":"0xda6f0e0e93fc8469e0159a166028d017bddbc162b86f66bac90391379603d962","price_changes":[{"asset_id":"39272994714739463168905443499424551362424437245880253267329605556587274644733","best_ask":"0.74","best_bid":"0.73","hash":"e13835d92eb9e2c02271eb119b4ad0901a442239","price":"0.7","side":"BUY","size":"73.6"},{"asset_id":"20893381255801015515826997628594359667013752732428989472914000440642900266717","best_ask":"0.27","best_bid":"0.26","hash":"b060ef1d2bf89bb831688651be40b1ea3936b0d7","price":"0.3","side":"SELL","size":"73.6"}],"timestamp":"1785204324816"},"payload_hash":"89a56467eada63b64ca9321a9829c7a86107795d8c1ca032f76a29e72809e4c6","raw_frame":"{\"market\":\"0xda6f0e0e93fc8469e0159a166028d017bddbc162b86f66bac90391379603d962\", \"price_changes\":[{\"asset_id\":\"39272994714739463168905443499424551362424437245880253267329605556587274644733\", \"price\":\"0.7\", \"size\":\"73.6\", \"side\":\"BUY\", \"hash\":\"e13835d92eb9e2c02271eb119b4ad0901a442239\", \"best_bid\":\"0.73\", \"best_ask\":\"0.74\"}, {\"asset_id\":\"20893381255801015515826997628594359667013752732428989472914000440642900266717\", \"price\":\"0.3\", \"size\":\"73.6\", \"side\":\"SELL\", \"hash\":\"b060ef1d2bf89bb831688651be40b1ea3936b0d7\", \"best_bid\":\"0.26\", \"best_ask\":\"0.27\"}], \"timestamp\":\"1785204324816\", \"event_type\":\"price_change\"}","received_at":"2026-07-28T02:05:32.418015Z","schema_version":"clob-market-ws.price_change.v1","sequence":null,"server_hash":null,"server_timestamp":"1785204324816","session_id":"d2757dd6dad94f3b9fe67e8dbf1adc37","source":"clob_market_ws"},"received_at":"2026-07-28T02:05:32.418015Z","record_id":"0e8a43a00ada4d6fb2502f985af2019307804d2928d4f3362bf1e05313908c66","schema_fingerprint":"4aa3821a28b0b7c2400bc59aba4bcc0a76e971dadd19610d3ad38c768e124dc7","schema_version":"edge-lab-recorder.raw.v1","sequence":null,"source":"clob_market_ws"}
{"event_at":"2026-07-28T02:05:24.817000Z","event_fingerprint":"b9c7a5d40ba559d08492fa2fd6c2295b837429103d897aa144b783f84b4032cc","payload":{"connection_id":"5d29200f65794d4d9ab6ef271f045a9b","event_at":"2026-07-28T02:05:24.817000Z","event_type":"price_change","frame_hash":"f84576197afa5564922f41d847b35ce5e5e74cbf0c40690e6fc67e17d283e7f8","frame_index":0,"kind":"data","monotonic_ns":306315428771375,"payload":{"event_type":"price_change","market":"0xda6f0e0e93fc8469e0159a166028d017bddbc162b86f66bac90391379603d962","price_changes":[{"asset_id":"39272994714739463168905443499424551362424437245880253267329605556587274644733","best_ask":"0.74","best_bid":"0.73","hash":"fca5491db0eb8d046062ba8e431ce8ef64f609c3","price":"0.73","side":"BUY","size":"4.98"},{"asset_id":"20893381255801015515826997628594359667013752732428989472914000440642900266717","best_ask":"0.27","best_bid":"0.26","hash":"7ce57b21e3747dbd77e9aafaebe57dc249250667","price":"0.27","side":"SELL","size":"4.98"}],"timestamp":"1785204324817"},"payload_hash":"79f4edc1cc0d27478541c3ab6dcb06bac0682380fdaa199d37e456b836b0ed80","raw_frame":"{\"market\":\"0xda6f0e0e93fc8469e0159a166028d017bddbc162b86f66bac90391379603d962\", \"price_changes\":[{\"asset_id\":\"39272994714739463168905443499424551362424437245880253267329605556587274644733\", \"price\":\"0.73\", \"size\":\"4.98\", \"side\":\"BUY\", \"hash\":\"fca5491db0eb8d046062ba8e431ce8ef64f609c3\", \"best_bid\":\"0.73\", \"best_ask\":\"0.74\"}, {\"asset_id\":\"20893381255801015515826997628594359667013752732428989472914000440642900266717\", \"price\":\"0.27\", \"size\":\"4.98\", \"side\":\"SELL\", \"hash\":\"7ce57b21e3747dbd77e9aafaebe57dc249250667\", \"best_bid\":\"0.26\", \"best_ask\":\"0.27\"}], \"timestamp\":\"1785204324817\", \"event_type\":\"price_change\"}","received_at":"2026-07-28T02:05:32.422429Z","schema_version":"clob-market-ws.price_change.v1","sequence":null,"server_hash":null,"server_timestamp":"1785204324817","session_id":"d2757dd6dad94f3b9fe67e8dbf1adc37","source":"clob_market_ws"},"received_at":"2026-07-28T02:05:32.422429Z","record_id":"ba2a3e9cfa0a4d884348a743882ede3c284a1e11e68dac270b22683fc065f8d9","schema_fingerprint":"4aa3821a28b0b7c2400bc59aba4bcc0a76e971dadd19610d3ad38c768e124dc7","schema_version":"edge-lab-recorder.raw.v1","sequence":null,"source":"clob_market_ws"}
{"event_at":"2026-07-28T02:05:24.837000Z","event_fingerprint":"257fe3c37b092d7af8aace8978c352aa92072f023cc1b033843aa59f9c6eb28d","payload":{"connection_id":"5d29200f65794d4d9ab6ef271f045a9b","event_at":"2026-07-28T02:05:24.837000Z","event_type":"price_change","frame_hash":"b7c86c465ecfceb6951288683f5b1ca436b86a48f27feee6e1e683979130c511","frame_index":0,"kind":"data","monotonic_ns":306315433009958,"payload":{"event_type":"price_change","market":"0xda6f0e0e93fc8469e0159a166028d017bddbc162b86f66bac90391379603d962","price_changes":[{"asset_id":"39272994714739463168905443499424551362424437245880253267329605556587274644733","best_ask":"0.74","best_bid":"0.73","hash":"2ca34b2ce68f7656712c22efe77b6e4a71e0c6a6","price":"0.04","side":"BUY","size":"593.09"},{"asset_id":"20893381255801015515826997628594359667013752732428989472914000440642900266717","best_ask":"0.27","best_bid":"0.26","hash":"1f27347ce7fcd6e97d1edce55550da1fdd3f36ae","price":"0.96","side":"SELL","size":"593.09"}],"timestamp":"1785204324837"},"payload_hash":"68d0f9a580584e2e128320c21b3a3f8c49e7f322b1b6b76cc847977c906298af","raw_frame":"{\"market\":\"0xda6f0e0e93fc8469e0159a166028d017bddbc162b86f66bac90391379603d962\", \"price_changes\":[{\"asset_id\":\"39272994714739463168905443499424551362424437245880253267329605556587274644733\", \"price\":\"0.04\", \"size\":\"593.09\", \"side\":\"BUY\", \"hash\":\"2ca34b2ce68f7656712c22efe77b6e4a71e0c6a6\", \"best_bid\":\"0.73\", \"best_ask\":\"0.74\"}, {\"asset_id\":\"20893381255801015515826997628594359667013752732428989472914000440642900266717\", \"price\":\"0.96\", \"size\":\"593.09\", \"side\":\"SELL\", \"hash\":\"1f27347ce7fcd6e97d1edce55550da1fdd3f36ae\", \"best_bid\":\"0.26\", \"best_ask\":\"0.27\"}], \"timestamp\":\"1785204324837\", \"event_type\":\"price_change\"}","received_at":"2026-07-28T02:05:32.426669Z","schema_version":"clob-market-ws.price_change.v1","sequence":null,"server_hash":null,"server_timestamp":"1785204324837","session_id":"d2757dd6dad94f3b9fe67e8dbf1adc37","source":"clob_market_ws"},"received_at":"2026-07-28T02:05:32.426669Z","record_id":"d747bc75648a2f506b1362726f59b66f4ecd786a1007b4dfafffcd0d5af025dd","schema_fingerprint":"4aa3821a28b0b7c2400bc59aba4bcc0a76e971dadd19610d3ad38c768e124dc7","schema_version":"edge-lab-recorder.raw.v1","sequence":null,"source":"clob_market_ws"}
{"event_at":"2026-07-28T02:05:24.838000Z","event_fingerprint":"a219f2ad02d48e76a5476ec89c0cd3652cd1f56381dca99e097d059b264ff434","payload":{"connection_id":"5d29200f65794d4d9ab6ef271f045a9b","event_at":"2026-07-28T02:05:24.838000Z","event_type":"price_change","frame_hash":"9d46c6a64fb13d88d78aa6a4c77d6d5c926362b5fbf0fce5a15d059adc58edef","frame_index":0,"kind":"data","monotonic_ns":306315437259916,"payload":{"event_type":"price_change","market":"0xda6f0e0e93fc8469e0159a166028d017bddbc162b86f66bac90391379603d962","price_changes":[{"asset_id":"20893381255801015515826997628594359667013752732428989472914000440642900266717","best_ask":"0.27","best_bid":"0.26","hash":"6107aa5d1274b1442080f4e7511ab018191a26d9","price":"0.13","side":"BUY","size":"411.5"},{"asset_id":"39272994714739463168905443499424551362424437245880253267329605556587274644733","best_ask":"0.74","best_bid":"0.73","hash":"f16fea5c24732bc3fb62ca5ab491dc4df0917b59","price":"0.87","side":"SELL","size":"411.5"}],"timestamp":"1785204324838"},"payload_hash":"18d58c34420f23b830021054865b88f02419f947506ef96cfe49e72282891287","raw_frame":"{\"market\":\"0xda6f0e0e93fc8469e0159a166028d017bddbc162b86f66bac90391379603d962\", \"price_changes\":[{\"asset_id\":\"20893381255801015515826997628594359667013752732428989472914000440642900266717\", \"price\":\"0.13\", \"size\":\"411.5\", \"side\":\"BUY\", \"hash\":\"6107aa5d1274b1442080f4e7511ab018191a26d9\", \"best_bid\":\"0.26\", \"best_ask\":\"0.27\"}, {\"asset_id\":\"39272994714739463168905443499424551362424437245880253267329605556587274644733\", \"price\":\"0.87\", \"size\":\"411.5\", \"side\":\"SELL\", \"hash\":\"f16fea5c24732bc3fb62ca5ab491dc4df0917b59\", \"best_bid\":\"0.73\", \"best_ask\":\"0.74\"}], \"timestamp\":\"1785204324838\", \"event_type\":\"price_change\"}","received_at":"2026-07-28T02:05:32.430919Z","schema_version":"clob-market-ws.price_change.v1","sequence":null,"server_hash":null,"server_timestamp":"1785204324838","session_id":"d2757dd6dad94f3b9fe67e8dbf1adc37","source":"clob_market_ws"},"received_at":"2026-07-28T02:05:32.430919Z","record_id":"fe38b495f7dbc465dc9702a4b1dc7fb797270715c55fcbff39362a6da9ed1353","schema_fingerprint":"4aa3821a28b0b7c2400bc59aba4bcc0a76e971dadd19610d3ad38c768e124dc7","schema_version":"edge-lab-recorder.raw.v1","sequence":null,"source":"clob_market_ws"}
