{"event_at":"2026-07-28T02:00:30.694000Z","event_fingerprint":"02c0f1064e089315b50d2978667bfca3ae280bc49c68451150843c8d7f13d333","payload":{"connection_id":"5d29200f65794d4d9ab6ef271f045a9b","event_at":"2026-07-28T02:00:30.694000Z","event_type":"price_change","frame_hash":"8ab324ab3fb187cbb05037fbbb3e9b99188b340aff11c570c16670fc47a8cf77","frame_index":0,"kind":"data","monotonic_ns":306015916758291,"payload":{"event_type":"price_change","market":"0xda6f0e0e93fc8469e0159a166028d017bddbc162b86f66bac90391379603d962","price_changes":[{"asset_id":"39272994714739463168905443499424551362424437245880253267329605556587274644733","best_ask":"0.52","best_bid":"0.51","hash":"d50d64e78989ecdd182476a1ab1c6684888c9a31","price":"0.49","side":"BUY","size":"141.61"},{"asset_id":"20893381255801015515826997628594359667013752732428989472914000440642900266717","best_ask":"0.49","best_bid":"0.48","hash":"88c6467269b1d055737051871754a5d9bac01ad3","price":"0.51","side":"SELL","size":"141.61"}],"timestamp":"1785204030694"},"payload_hash":"5c292eafcefca255126f675d9f8a38d701887f12a6616b7507c509754b8a9646","raw_frame":"{\"market\":\"0xda6f0e0e93fc8469e0159a166028d017bddbc162b86f66bac90391379603d962\", \"price_changes\":[{\"asset_id\":\"39272994714739463168905443499424551362424437245880253267329605556587274644733\", \"price\":\"0.49\", \"size\":\"141.61\", \"side\":\"BUY\", \"hash\":\"d50d64e78989ecdd182476a1ab1c6684888c9a31\", \"best_bid\":\"0.51\", \"best_ask\":\"0.52\"}, {\"asset_id\":\"20893381255801015515826997628594359667013752732428989472914000440642900266717\", \"price\":\"0.51\", \"size\":\"141.61\", \"side\":\"SELL\", \"hash\":\"88c6467269b1d055737051871754a5d9bac01ad3\", \"best_bid\":\"0.48\", \"best_ask\":\"0.49\"}], \"timestamp\":\"1785204030694\", \"event_type\":\"price_change\"}","received_at":"2026-07-28T02:00:32.911146Z","schema_version":"clob-market-ws.price_change.v1","sequence":null,"server_hash":null,"server_timestamp":"1785204030694","session_id":"d2757dd6dad94f3b9fe67e8dbf1adc37","source":"clob_market_ws"},"received_at":"2026-07-28T02:00:32.911146Z","record_id":"3da2037067eadcde6124450c1968c07c5da1e4ab05ae6073f6d913cf89b59d95","schema_fingerprint":"4aa3821a28b0b7c2400bc59aba4bcc0a76e971dadd19610d3ad38c768e124dc7","schema_version":"edge-lab-recorder.raw.v1","sequence":null,"source":"clob_market_ws"}
{"event_at":"2026-07-28T02:00:30.713000Z","event_fingerprint":"c8518b2cecc3a7469c1a1fe932ed5e2ba6c04dc9f79d01fda166be13044f1fde","payload":{"connection_id":"5d29200f65794d4d9ab6ef271f045a9b","event_at":"2026-07-28T02:00:30.713000Z","event_type":"price_change","frame_hash":"894d011e86d7e35e999792f9429ed663ee11625d2ea6f43e60a9625e1aff2269","frame_index":0,"kind":"data","monotonic_ns":306015930466166,"payload":{"event_type":"price_change","market":"0xda6f0e0e93fc8469e0159a166028d017bddbc162b86f66bac90391379603d962","price_changes":[{"asset_id":"39272994714739463168905443499424551362424437245880253267329605556587274644733","best_ask":"0.52","best_bid":"0.51","hash":"b2f84f89ce483c5d742297543c7c1f688de5482c","price":"0.01","side":"BUY","size":"7858.02"},{"asset_id":"20893381255801015515826997628594359667013752732428989472914000440642900266717","best_ask":"0.49","best_bid":"0.48","hash":"bce5e2902dc07a082e3ad24b4987a170abd541e6","price":"0.99","side":"SELL","size":"7858.02"}],"timestamp":"1785204030713"},"payload_hash":"9c64d81c088bd915464fa4e120da32a22326e06f32c1524810cff02b01c37af8","raw_frame":"{\"market\":\"0xda6f0e0e93fc8469e0159a166028d017bddbc162b86f66bac90391379603d962\", \"price_changes\":[{\"asset_id\":\"39272994714739463168905443499424551362424437245880253267329605556587274644733\", \"price\":\"0.01\", \"size\":\"7858.02\", \"side\":\"BUY\", \"hash\":\"b2f84f89ce483c5d742297543c7c1f688de5482c\", \"best_bid\":\"0.51\", \"best_ask\":\"0.52\"}, {\"asset_id\":\"20893381255801015515826997628594359667013752732428989472914000440642900266717\", \"price\":\"0.99\", \"size\":\"7858.02\", \"side\":\"SELL\", \"hash\":\"bce5e2902dc07a082e3ad24b4987a170abd541e6\", \"best_bid\":\"0.48\", \"best_ask\":\"0.49\"}], \"timestamp\":\"1785204030713\", \"event_type\":\"price_change\"}","received_at":"2026-07-28T02:00:32.924855Z","schema_version":"clob-market-ws.price_change.v1","sequence":null,"server_hash":null,"server_timestamp":"1785204030713","session_id":"d2757dd6dad94f3b9fe67e8dbf1adc37","source":"clob_market_ws"},"received_at":"2026-07-28T02:00:32.924855Z","record_id":"674d720b546d46ca05ebd20529b43e39fd7722c30551235a63288be5db80a8ec","schema_fingerprint":"4aa3821a28b0b7c2400bc59aba4bcc0a76e971dadd19610d3ad38c768e124dc7","schema_version":"edge-lab-recorder.raw.v1","sequence":null,"source":"clob_market_ws"}
{"event_at":"2026-07-28T02:00:30.714000Z","event_fingerprint":"797d7f1d43ccbbb90e0a03be0c3bb314621d820c7ffb47ebe442b3c59c4665ca","payload":{"connection_id":"5d29200f65794d4d9ab6ef271f045a9b","event_at":"2026-07-28T02:00:30.714000Z","event_type":"price_change","frame_hash":"858f81ceb146d9cdea2e9bcfa7c2d755ab2fb00abf2952b4d3a835f45ba2633d","frame_index":0,"kind":"data","monotonic_ns":306015934873833,"payload":{"event_type":"price_change","market":"0xda6f0e0e93fc8469e0159a166028d017bddbc162b86f66bac90391379603d962","price_changes":[{"asset_id":"39272994714739463168905443499424551362424437245880253267329605556587274644733","best_ask":"0.52","best_bid":"0.51","hash":"d9756bca2da9a814ae4b25c9159fdc2507453d93","price":"0.03","side":"BUY","size":"1196.43"},{"asset_id":"20893381255801015515826997628594359667013752732428989472914000440642900266717","best_ask":"0.49","best_bid":"0.48","hash":"fd20b4e9255adb4e4c4c8157b56153dac5ee35cf","price":"0.97","side":"SELL","size":"1196.43"}],"timestamp":"1785204030714"},"payload_hash":"acc75030112f596d096ef16dbe5b0da65b206a533fb430df4cace90213e4052c","raw_frame":"{\"market\":\"0xda6f0e0e93fc8469e0159a166028d017bddbc162b86f66bac90391379603d962\", \"price_changes\":[{\"asset_id\":\"39272994714739463168905443499424551362424437245880253267329605556587274644733\", \"price\":\"0.03\", \"size\":\"1196.43\", \"side\":\"BUY\", \"hash\":\"d9756bca2da9a814ae4b25c9159fdc2507453d93\", \"best_bid\":\"0.51\", \"best_ask\":\"0.52\"}, {\"asset_id\":\"20893381255801015515826997628594359667013752732428989472914000440642900266717\", \"price\":\"0.97\", \"size\":\"1196.43\", \"side\":\"SELL\", \"hash\":\"fd20b4e9255adb4e4c4c8157b56153dac5ee35cf\", \"best_bid\":\"0.48\", \"best_ask\":\"0.49\"}], \"timestamp\":\"1785204030714\", \"event_type\":\"price_change\"}","received_at":"2026-07-28T02:00:32.929264Z","schema_version":"clob-market-ws.price_change.v1","sequence":null,"server_hash":null,"server_timestamp":"1785204030714","session_id":"d2757dd6dad94f3b9fe67e8dbf1adc37","source":"clob_market_ws"},"received_at":"2026-07-28T02:00:32.929264Z","record_id":"d1e944f4dfea6be502e007d8fe3189a481b686f132c19848e1e1af68a0a66550","schema_fingerprint":"4aa3821a28b0b7c2400bc59aba4bcc0a76e971dadd19610d3ad38c768e124dc7","schema_version":"edge-lab-recorder.raw.v1","sequence":null,"source":"clob_market_ws"}
{"event_at":"2026-07-28T02:00:30.715000Z","event_fingerprint":"9d6b5f876419bdfbe294e4ed437534c08929e85bd9e60307a0ca88718d302cff","payload":{"connection_id":"5d29200f65794d4d9ab6ef271f045a9b","event_at":"2026-07-28T02:00:30.715000Z","event_type":"price_change","frame_hash":"8376a09824aa42f20796b416cf9517fce90b6ee6da8456c95bee121b2d07a9df","frame_index":0,"kind":"data","monotonic_ns":306015940541208,"payload":{"event_type":"price_change","market":"0xda6f0e0e93fc8469e0159a166028d017bddbc162b86f66bac90391379603d962","price_changes":[{"asset_id":"39272994714739463168905443499424551362424437245880253267329605556587274644733","best_ask":"0.52","best_bid":"0.51","hash":"916d37d83da68a86aa17d5033f7e28dd6a0f9799","price":"0.01","side":"BUY","size":"7863.02"},{"asset_id":"20893381255801015515826997628594359667013752732428989472914000440642900266717","best_ask":"0.49","best_bid":"0.48","hash":"53fe418b7a073d3f70cbf83af5688f64431f01b3","price":"0.99","side":"SELL","size":"7863.02"}],"timestamp":"1785204030715"},"payload_hash":"7a32631c6fe6cdcd00d031ce412532229b1ced82d898959547d91886bffdcae5","raw_frame":"{\"market\":\"0xda6f0e0e93fc8469e0159a166028d017bddbc162b86f66bac90391379603d962\", \"price_changes\":[{\"asset_id\":\"39272994714739463168905443499424551362424437245880253267329605556587274644733\", \"price\":\"0.01\", \"size\":\"7863.02\", \"side\":\"BUY\", \"hash\":\"916d37d83da68a86aa17d5033f7e28dd6a0f9799\", \"best_bid\":\"0.51\", \"best_ask\":\"0.52\"}, {\"asset_id\":\"20893381255801015515826997628594359667013752732428989472914000440642900266717\", \"price\":\"0.99\", \"size\":\"7863.02\", \"side\":\"SELL\", \"hash\":\"53fe418b7a073d3f70cbf83af5688f64431f01b3\", \"best_bid\":\"0.48\", \"best_ask\":\"0.49\"}], \"timestamp\":\"1785204030715\", \"event_type\":\"price_change\"}","received_at":"2026-07-28T02:00:32.934932Z","schema_version":"clob-market-ws.price_change.v1","sequence":null,"server_hash":null,"server_timestamp":"1785204030715","session_id":"d2757dd6dad94f3b9fe67e8dbf1adc37","source":"clob_market_ws"},"received_at":"2026-07-28T02:00:32.934932Z","record_id":"377e44f32d95b0d8f40d3a34ffeca88587da3da7ce777c2947c0eee3d9b60622","schema_fingerprint":"4aa3821a28b0b7c2400bc59aba4bcc0a76e971dadd19610d3ad38c768e124dc7","schema_version":"edge-lab-recorder.raw.v1","sequence":null,"source":"clob_market_ws"}
{"event_at":"2026-07-28T02:00:30.735000Z","event_fingerprint":"142fa3898949fb8d402d64dab47c2222cad8a4b3dc8401b05149b6c09cde126e","payload":{"connection_id":"5d29200f65794d4d9ab6ef271f045a9b","event_at":"2026-07-28T02:00:30.735000Z","event_type":"price_change","frame_hash":"00506c63a41d78468dfe33297306a872f20fcef4045e032f0acbada9bc8f190f","frame_index":0,"kind":"data","monotonic_ns":306015946771625,"payload":{"event_type":"price_change","market":"0xda6f0e0e93fc8469e0159a166028d017bddbc162b86f66bac90391379603d962","price_changes":[{"asset_id":"39272994714739463168905443499424551362424437245880253267329605556587274644733","best_ask":"0.52","best_bid":"0.51","hash":"c92af3c104692e59256508686bd9c1d6b42165e3","price":"0.01","side":"BUY","size":"7858.02"},{"asset_id":"20893381255801015515826997628594359667013752732428989472914000440642900266717","best_ask":"0.49","best_bid":"0.48","hash":"7b2b5fefd3d27da5069c3f659debf2e035b1371a","price":"0.99","side":"SELL","size":"7858.02"}],"timestamp":"1785204030735"},"payload_hash":"bd03a38960eb7610131f0d0508419c11b93994c69c3ea939cbf2ef0f764cc1e7","raw_frame":"{\"market\":\"0xda6f0e0e93fc8469e0159a166028d017bddbc162b86f66bac90391379603d962\", \"price_changes\":[{\"asset_id\":\"39272994714739463168905443499424551362424437245880253267329605556587274644733\", \"price\":\"0.01\", \"size\":\"7858.02\", \"side\":\"BUY\", \"hash\":\"c92af3c104692e59256508686bd9c1d6b42165e3\", \"best_bid\":\"0.51\", \"best_ask\":\"0.52\"}, {\"asset_id\":\"20893381255801015515826997628594359667013752732428989472914000440642900266717\", \"price\":\"0.99\", \"size\":\"7858.02\", \"side\":\"SELL\", \"hash\":\"7b2b5fefd3d27da5069c3f659debf2e035b1371a\", \"best_bid\":\"0.48\", \"best_ask\":\"0.49\"}], \"timestamp\":\"1785204030735\", \"event_type\":\"price_change\"}","received_at":"2026-07-28T02:00:32.941164Z","schema_version":"clob-market-ws.price_change.v1","sequence":null,"server_hash":null,"server_timestamp":"1785204030735","session_id":"d2757dd6dad94f3b9fe67e8dbf1adc37","source":"clob_market_ws"},"received_at":"2026-07-28T02:00:32.941164Z","record_id":"e983206cf4e6f91fef9a230dc9f2dafffb396300db544c53847933a8c043282a","schema_fingerprint":"4aa3821a28b0b7c2400bc59aba4bcc0a76e971dadd19610d3ad38c768e124dc7","schema_version":"edge-lab-recorder.raw.v1","sequence":null,"source":"clob_market_ws"}
{"event_at":"2026-07-28T02:00:30.736000Z","event_fingerprint":"7ae212c4d4c24a8415a303e14850f4a85b59f75a9d0f8ad1100713570ab83cce","payload":{"connection_id":"5d29200f65794d4d9ab6ef271f045a9b","event_at":"2026-07-28T02:00:30.736000Z","event_type":"price_change","frame_hash":"2bb3691c76e79ec681057a8d387e89e37ce800dc7c25e1f529c72f8c22f54630","frame_index":0,"kind":"data","monotonic_ns":306015951696541,"payload":{"event_type":"price_change","market":"0xda6f0e0e93fc8469e0159a166028d017bddbc162b86f66bac90391379603d962","price_changes":[{"asset_id":"39272994714739463168905443499424551362424437245880253267329605556587274644733","best_ask":"0.52","best_bid":"0.51","hash":"02fde27cbc656f4a69e120c0e0890449b24f4b19","price":"0.43","side":"BUY","size":"122"},{"asset_id":"20893381255801015515826997628594359667013752732428989472914000440642900266717","best_ask":"0.49","best_bid":"0.48","hash":"89675a25ee8a56ddef5bf86645d1c7f140d566be","price":"0.57","side":"SELL","size":"122"}],"timestamp":"1785204030736"},"payload_hash":"e1c7244353a6436c4e45a0359d4c973334d95e0eb7066f8352ef3e44866e915b","raw_frame":"{\"market\":\"0xda6f0e0e93fc8469e0159a166028d017bddbc162b86f66bac90391379603d962\", \"price_changes\":[{\"asset_id\":\"39272994714739463168905443499424551362424437245880253267329605556587274644733\", \"price\":\"0.43\", \"size\":\"122\", \"side\":\"BUY\", \"hash\":\"02fde27cbc656f4a69e120c0e0890449b24f4b19\", \"best_bid\":\"0.51\", \"best_ask\":\"0.52\"}, {\"asset_id\":\"20893381255801015515826997628594359667013752732428989472914000440642900266717\", \"price\":\"0.57\", \"size\":\"122\", \"side\":\"SELL\", \"hash\":\"89675a25ee8a56ddef5bf86645d1c7f140d566be\", \"best_bid\":\"0.48\", \"best_ask\":\"0.49\"}], \"timestamp\":\"1785204030736\", \"event_type\":\"price_change\"}","received_at":"2026-07-28T02:00:32.946089Z","schema_version":"clob-market-ws.price_change.v1","sequence":null,"server_hash":null,"server_timestamp":"1785204030736","session_id":"d2757dd6dad94f3b9fe67e8dbf1adc37","source":"clob_market_ws"},"received_at":"2026-07-28T02:00:32.946089Z","record_id":"569758173c9836e4b2c60739b35c02c99380c9e20b1c4a22fbca402b622fdde8","schema_fingerprint":"4aa3821a28b0b7c2400bc59aba4bcc0a76e971dadd19610d3ad38c768e124dc7","schema_version":"edge-lab-recorder.raw.v1","sequence":null,"source":"clob_market_ws"}
{"event_at":"2026-07-28T02:00:30.739000Z","event_fingerprint":"53fc0f3eb78618dc64b0bca0dc48ae9439370eb03629984ccd7f5b2762ed807e","payload":{"connection_id":"5d29200f65794d4d9ab6ef271f045a9b","event_at":"2026-07-28T02:00:30.739000Z","event_type":"price_change","frame_hash":"2837bca4e42627d77607adb82cd3acddfcc9de6071fb06acbf6d89ee3bdc23ef","frame_index":0,"kind":"data","monotonic_ns":306015957943708,"payload":{"event_type":"price_change","market":"0xda6f0e0e93fc8469e0159a166028d017bddbc162b86f66bac90391379603d962","price_changes":[{"asset_id":"39272994714739463168905443499424551362424437245880253267329605556587274644733","best_ask":"0.52","best_bid":"0.51","hash":"30448eb541d5bfa197650d003783695bd14026ea","price":"0.01","side":"BUY","size":"7853.02"},{"asset_id":"20893381255801015515826997628594359667013752732428989472914000440642900266717","best_ask":"0.49","best_bid":"0.48","hash":"b7c3da100937fc6ac30a1a0faf3fded52ded7029","price":"0.99","side":"SELL","size":"7853.02"}],"timestamp":"1785204030739"},"payload_hash":"34cca54ba5a3f3765776f3f22d0359cce0f7e5deeb6cba3020dd0fa270b014b9","raw_frame":"{\"market\":\"0xda6f0e0e93fc8469e0159a166028d017bddbc162b86f66bac90391379603d962\", \"price_changes\":[{\"asset_id\":\"39272994714739463168905443499424551362424437245880253267329605556587274644733\", \"price\":\"0.01\", \"size\":\"7853.02\", \"side\":\"BUY\", \"hash\":\"30448eb541d5bfa197650d003783695bd14026ea\", \"best_bid\":\"0.51\", \"best_ask\":\"0.52\"}, {\"asset_id\":\"20893381255801015515826997628594359667013752732428989472914000440642900266717\", \"price\":\"0.99\", \"size\":\"7853.02\", \"side\":\"SELL\", \"hash\":\"b7c3da100937fc6ac30a1a0faf3fded52ded7029\", \"best_bid\":\"0.48\", \"best_ask\":\"0.49\"}], \"timestamp\":\"1785204030739\", \"event_type\":\"price_change\"}","received_at":"2026-07-28T02:00:32.952338Z","schema_version":"clob-market-ws.price_change.v1","sequence":null,"server_hash":null,"server_timestamp":"1785204030739","session_id":"d2757dd6dad94f3b9fe67e8dbf1adc37","source":"clob_market_ws"},"received_at":"2026-07-28T02:00:32.952338Z","record_id":"651ad0ddbf9565044af796edc2536f0a0f4f2d2fbfcace7775b9875d2bfcfd5e","schema_fingerprint":"4aa3821a28b0b7c2400bc59aba4bcc0a76e971dadd19610d3ad38c768e124dc7","schema_version":"edge-lab-recorder.raw.v1","sequence":null,"source":"clob_market_ws"}
{"event_at":"2026-07-28T02:00:30.780000Z","event_fingerprint":"0dcd99af253c922e1aa5f48ed046302375ab75fc284d448a847836387b8f7e50","payload":{"connection_id":"5d29200f65794d4d9ab6ef271f045a9b","event_at":"2026-07-28T02:00:30.780000Z","event_type":"price_change","frame_hash":"11d3cc2e90a78e2b9ee5ad4db9e9a6b149e5efbd665b76969a2b96145fb0cf9a","frame_index":0,"kind":"data","monotonic_ns":306015962912750,"payload":{"event_type":"price_change","market":"0xda6f0e0e93fc8469e0159a166028d017bddbc162b86f66bac90391379603d962","price_changes":[{"asset_id":"39272994714739463168905443499424551362424437245880253267329605556587274644733","best_ask":"0.52","best_bid":"0.51","hash":"f62745289400bc2f565b8fee2086181800237bc4","price":"0.44","side":"BUY","size":"195"},{"asset_id":"20893381255801015515826997628594359667013752732428989472914000440642900266717","best_ask":"0.49","best_bid":"0.48","hash":"9df16177a74797f3ead1d9204911ec9902ec4c0c","price":"0.56","side":"SELL","size":"195"}],"timestamp":"1785204030780"},"payload_hash":"4a4b7dcd8c43ada46dba0c1c4e45374f34b1d34152a41b2818d97518af0c2873","raw_frame":"{\"market\":\"0xda6f0e0e93fc8469e0159a166028d017bddbc162b86f66bac90391379603d962\", \"price_changes\":[{\"asset_id\":\"39272994714739463168905443499424551362424437245880253267329605556587274644733\", \"price\":\"0.44\", \"size\":\"195\", \"side\":\"BUY\", \"hash\":\"f62745289400bc2f565b8fee2086181800237bc4\", \"best_bid\":\"0.51\", \"best_ask\":\"0.52\"}, {\"asset_id\":\"20893381255801015515826997628594359667013752732428989472914000440642900266717\", \"price\":\"0.56\", \"size\":\"195\", \"side\":\"SELL\", \"hash\":\"9df16177a74797f3ead1d9204911ec9902ec4c0c\", \"best_bid\":\"0.48\", \"best_ask\":\"0.49\"}], \"timestamp\":\"1785204030780\", \"event_type\":\"price_change\"}","received_at":"2026-07-28T02:00:32.957305Z","schema_version":"clob-market-ws.price_change.v1","sequence":null,"server_hash":null,"server_timestamp":"1785204030780","session_id":"d2757dd6dad94f3b9fe67e8dbf1adc37","source":"clob_market_ws"},"received_at":"2026-07-28T02:00:32.957305Z","record_id":"957c095517329d96a1113e380ff5386aa5c4badf19e68aef2779cd4f277ddfd4","schema_fingerprint":"4aa3821a28b0b7c2400bc59aba4bcc0a76e971dadd19610d3ad38c768e124dc7","schema_version":"edge-lab-recorder.raw.v1","sequence":null,"source":"clob_market_ws"}
{"event_at":"2026-07-28T02:00:30.800000Z","event_fingerprint":"b70e9c47480785d8d5ffd522b5c888b0efd28ea66d2339406eb8b5bfaf5b4f04","payload":{"connection_id":"5d29200f65794d4d9ab6ef271f045a9b","event_at":"2026-07-28T02:00:30.800000Z","event_type":"price_change","frame_hash":"4f42db0ec1384909b72f0c9c7d334a922a3a6e7e33033a5cea74c3e9b27ec56d","frame_index":0,"kind":"data","monotonic_ns":306015969375208,"payload":{"event_type":"price_change","market":"0xda6f0e0e93fc8469e0159a166028d017bddbc162b86f66bac90391379603d962","price_changes":[{"asset_id":"39272994714739463168905443499424551362424437245880253267329605556587274644733","best_ask":"0.52","best_bid":"0.51","hash":"09aa7c9f9b105261ef629b87cbd96b243081a446","price":"0.45","side":"BUY","size":"153"},{"asset_id":"20893381255801015515826997628594359667013752732428989472914000440642900266717","best_ask":"0.49","best_bid":"0.48","hash":"ef2fc4b5e54f24710776f39bd3fa9bc53b761a56","price":"0.55","side":"SELL","size":"153"}],"timestamp":"1785204030800"},"payload_hash":"1551d452294be9fd2d892e07a971b599909f040da06b43d5e0b7d122bf2a1902","raw_frame":"{\"market\":\"0xda6f0e0e93fc8469e0159a166028d017bddbc162b86f66bac90391379603d962\", \"price_changes\":[{\"asset_id\":\"39272994714739463168905443499424551362424437245880253267329605556587274644733\", \"price\":\"0.45\", \"size\":\"153\", \"side\":\"BUY\", \"hash\":\"09aa7c9f9b105261ef629b87cbd96b243081a446\", \"best_bid\":\"0.51\", \"best_ask\":\"0.52\"}, {\"asset_id\":\"20893381255801015515826997628594359667013752732428989472914000440642900266717\", \"price\":\"0.55\", \"size\":\"153\", \"side\":\"SELL\", \"hash\":\"ef2fc4b5e54f24710776f39bd3fa9bc53b761a56\", \"best_bid\":\"0.48\", \"best_ask\":\"0.49\"}], \"timestamp\":\"1785204030800\", \"event_type\":\"price_change\"}","received_at":"2026-07-28T02:00:32.963771Z","schema_version":"clob-market-ws.price_change.v1","sequence":null,"server_hash":null,"server_timestamp":"1785204030800","session_id":"d2757dd6dad94f3b9fe67e8dbf1adc37","source":"clob_market_ws"},"received_at":"2026-07-28T02:00:32.963771Z","record_id":"082b24fe83f98e1a2b9a9dd74af894b8f522b8345ce170147225bdcd686d9581","schema_fingerprint":"4aa3821a28b0b7c2400bc59aba4bcc0a76e971dadd19610d3ad38c768e124dc7","schema_version":"edge-lab-recorder.raw.v1","sequence":null,"source":"clob_market_ws"}
{"event_at":"2026-07-28T02:00:30.801000Z","event_fingerprint":"183cdc9270d1e0c56535a54ab0bf593982a3c53bac53b98d8361e157bd069b05","payload":{"connection_id":"5d29200f65794d4d9ab6ef271f045a9b","event_at":"2026-07-28T02:00:30.801000Z","event_type":"price_change","frame_hash":"2b718641379572e1754d0b658484d52ff9fb837352f05f6e36ca404ba2fa1778","frame_index":0,"kind":"data","monotonic_ns":306015972930916,"payload":{"event_type":"price_change","market":"0xda6f0e0e93fc8469e0159a166028d017bddbc162b86f66bac90391379603d962","price_changes":[{"asset_id":"39272994714739463168905443499424551362424437245880253267329605556587274644733","best_ask":"0.52","best_bid":"0.51","hash":"a5da87d48dfaf6b736a85c8a90a2ee3c9882b3d0","price":"0.46","side":"BUY","size":"98"},{"asset_id":"20893381255801015515826997628594359667013752732428989472914000440642900266717","best_ask":"0.49","best_bid":"0.48","hash":"d100bdfd7f8a119fc6a4f694ef645fd813e40df4","price":"0.54","side":"SELL","size":"98"}],"timestamp":"1785204030801"},"payload_hash":"bd9bae0f5c9251a576626d0c488f228cd014afd4f31bcefbafd2c1fcfbf79c3b","raw_frame":"{\"market\":\"0xda6f0e0e93fc8469e0159a166028d017bddbc162b86f66bac90391379603d962\", \"price_changes\":[{\"asset_id\":\"39272994714739463168905443499424551362424437245880253267329605556587274644733\", \"price\":\"0.46\", \"size\":\"98\", \"side\":\"BUY\", \"hash\":\"a5da87d48dfaf6b736a85c8a90a2ee3c9882b3d0\", \"best_bid\":\"0.51\", \"best_ask\":\"0.52\"}, {\"asset_id\":\"20893381255801015515826997628594359667013752732428989472914000440642900266717\", \"price\":\"0.54\", \"size\":\"98\", \"side\":\"SELL\", \"hash\":\"d100bdfd7f8a119fc6a4f694ef645fd813e40df4\", \"best_bid\":\"0.48\", \"best_ask\":\"0.49\"}], \"timestamp\":\"1785204030801\", \"event_type\":\"price_change\"}","received_at":"2026-07-28T02:00:32.967327Z","schema_version":"clob-market-ws.price_change.v1","sequence":null,"server_hash":null,"server_timestamp":"1785204030801","session_id":"d2757dd6dad94f3b9fe67e8dbf1adc37","source":"clob_market_ws"},"received_at":"2026-07-28T02:00:32.967327Z","record_id":"b000b2e371a46ebf80c05f7bcfdc3fc1d98683e51c1d3b8128a165d96dcf0188","schema_fingerprint":"4aa3821a28b0b7c2400bc59aba4bcc0a76e971dadd19610d3ad38c768e124dc7","schema_version":"edge-lab-recorder.raw.v1","sequence":null,"source":"clob_market_ws"}
{"event_at":"2026-07-28T02:00:30.803000Z","event_fingerprint":"12f4913129a2c43c28a201012ea1a5bacb817cd60f8d7e0b2a5b463327a6b93b","payload":{"connection_id":"5d29200f65794d4d9ab6ef271f045a9b","event_at":"2026-07-28T02:00:30.803000Z","event_type":"price_change","frame_hash":"e8a1d34814e646c72e57a067672c9cf9f866df55af5526f7bab0ae4cdfe48f9b","frame_index":0,"kind":"data","monotonic_ns":306015977995250,"payload":{"event_type":"price_change","market":"0xda6f0e0e93fc8469e0159a166028d017bddbc162b86f66bac90391379603d962","price_changes":[{"asset_id":"39272994714739463168905443499424551362424437245880253267329605556587274644733","best_ask":"0.52","best_bid":"0.51","hash":"584041ff1001de86e835bfdf5ce4a74ec97b4477","price":"0.44","side":"BUY","size":"200"},{"asset_id":"20893381255801015515826997628594359667013752732428989472914000440642900266717","best_ask":"0.49","best_bid":"0.48","hash":"27e108649347e81b97ced562da235469eb349ea2","price":"0.56","side":"SELL","size":"200"}],"timestamp":"1785204030803"},"payload_hash":"fa3f6ea22ceab8169c95891ec1dae03d0b136b4f4230875617f4f1e4b8ccc995","raw_frame":"{\"market\":\"0xda6f0e0e93fc8469e0159a166028d017bddbc162b86f66bac90391379603d962\", \"price_changes\":[{\"asset_id\":\"39272994714739463168905443499424551362424437245880253267329605556587274644733\", \"price\":\"0.44\", \"size\":\"200\", \"side\":\"BUY\", \"hash\":\"584041ff1001de86e835bfdf5ce4a74ec97b4477\", \"best_bid\":\"0.51\", \"best_ask\":\"0.52\"}, {\"asset_id\":\"20893381255801015515826997628594359667013752732428989472914000440642900266717\", \"price\":\"0.56\", \"size\":\"200\", \"side\":\"SELL\", \"hash\":\"27e108649347e81b97ced562da235469eb349ea2\", \"best_bid\":\"0.48\", \"best_ask\":\"0.49\"}], \"timestamp\":\"1785204030803\", \"event_type\":\"price_change\"}","received_at":"2026-07-28T02:00:32.972392Z","schema_version":"clob-market-ws.price_change.v1","sequence":null,"server_hash":null,"server_timestamp":"1785204030803","session_id":"d2757dd6dad94f3b9fe67e8dbf1adc37","source":"clob_market_ws"},"received_at":"2026-07-28T02:00:32.972392Z","record_id":"73a60c54ff85cbfbd85c5287242dc08bf612ee16892c60576af469b7fd089c98","schema_fingerprint":"4aa3821a28b0b7c2400bc59aba4bcc0a76e971dadd19610d3ad38c768e124dc7","schema_version":"edge-lab-recorder.raw.v1","sequence":null,"source":"clob_market_ws"}
{"event_at":"2026-07-28T02:00:30.809000Z","event_fingerprint":"16e23be7eb1ff16fc961a328d6bb662b42df69ae7fd55c615608914c591e2386","payload":{"connection_id":"5d29200f65794d4d9ab6ef271f045a9b","event_at":"2026-07-28T02:00:30.809000Z","event_type":"price_change","frame_hash":"c7974a04a79732e480e7999895706a0642a950eb8063c6a403494bf1a8e8ba2c","frame_index":0,"kind":"data","monotonic_ns":306015983169750,"payload":{"event_type":"price_change","market":"0xda6f0e0e93fc8469e0159a166028d017bddbc162b86f66bac90391379603d962","price_changes":[{"asset_id":"39272994714739463168905443499424551362424437245880253267329605556587274644733","best_ask":"0.52","best_bid":"0.51","hash":"0e2b851f3561bc4002e4b65275927bbeebb60a5f","price":"0.46","side":"BUY","size":"103"},{"asset_id":"20893381255801015515826997628594359667013752732428989472914000440642900266717","best_ask":"0.49","best_bid":"0.48","hash":"68c187bb91954a8958868852031fc77dca5eebaa","price":"0.54","side":"SELL","size":"103"}],"timestamp":"1785204030809"},"payload_hash":"de410565f60e6cfee8dcc5e4cfbd6481a9c5c127c6ef25d4880a9d3d4d6b6e67","raw_frame":"{\"market\":\"0xda6f0e0e93fc8469e0159a166028d017bddbc162b86f66bac90391379603d962\", \"price_changes\":[{\"asset_id\":\"39272994714739463168905443499424551362424437245880253267329605556587274644733\", \"price\":\"0.46\", \"size\":\"103\", \"side\":\"BUY\", \"hash\":\"0e2b851f3561bc4002e4b65275927bbeebb60a5f\", \"best_bid\":\"0.51\", \"best_ask\":\"0.52\"}, {\"asset_id\":\"20893381255801015515826997628594359667013752732428989472914000440642900266717\", \"price\":\"0.54\", \"size\":\"103\", \"side\":\"SELL\", \"hash\":\"68c187bb91954a8958868852031fc77dca5eebaa\", \"best_bid\":\"0.48\", \"best_ask\":\"0.49\"}], \"timestamp\":\"1785204030809\", \"event_type\":\"price_change\"}","received_at":"2026-07-28T02:00:32.977567Z","schema_version":"clob-market-ws.price_change.v1","sequence":null,"server_hash":null,"server_timestamp":"1785204030809","session_id":"d2757dd6dad94f3b9fe67e8dbf1adc37","source":"clob_market_ws"},"received_at":"2026-07-28T02:00:32.977567Z","record_id":"8a0450eab8a08f4daa0f903521105522e195cf878d0de6ca6c6eca5e85c63f34","schema_fingerprint":"4aa3821a28b0b7c2400bc59aba4bcc0a76e971dadd19610d3ad38c768e124dc7","schema_version":"edge-lab-recorder.raw.v1","sequence":null,"source":"clob_market_ws"}
{"event_at":"2026-07-28T02:00:30.810000Z","event_fingerprint":"7b7ca8bb29067b10c38e4ad40fcae7645f1a57f0269bad2edbad8097d1108193","payload":{"connection_id":"5d29200f65794d4d9ab6ef271f045a9b","event_at":"2026-07-28T02:00:30.810000Z","event_type":"price_change","frame_hash":"81df9ea51bd05d84f04856d759c9cb3da587b127902b8ec4ee5ea846d3adb3e4","frame_index":0,"kind":"data","monotonic_ns":306015989509416,"payload":{"event_type":"price_change","market":"0xda6f0e0e93fc8469e0159a166028d017bddbc162b86f66bac90391379603d962","price_changes":[{"asset_id":"39272994714739463168905443499424551362424437245880253267329605556587274644733","best_ask":"0.52","best_bid":"0.51","hash":"9b94cdbcad68c36cc956a7c90493a27735e81039","price":"0.01","side":"BUY","size":"7858.02"},{"asset_id":"20893381255801015515826997628594359667013752732428989472914000440642900266717","best_ask":"0.49","best_bid":"0.48","hash":"78c4aac55585d2812f2f3ba40bf97708d847e20c","price":"0.99","side":"SELL","size":"7858.02"}],"timestamp":"1785204030810"},"payload_hash":"32ab7db48f4e1b0c7713db41cd8d66165a1e0f9ed97e9894707aa3f2167f8376","raw_frame":"{\"market\":\"0xda6f0e0e93fc8469e0159a166028d017bddbc162b86f66bac90391379603d962\", \"price_changes\":[{\"asset_id\":\"39272994714739463168905443499424551362424437245880253267329605556587274644733\", \"price\":\"0.01\", \"size\":\"7858.02\", \"side\":\"BUY\", \"hash\":\"9b94cdbcad68c36cc956a7c90493a27735e81039\", \"best_bid\":\"0.51\", \"best_ask\":\"0.52\"}, {\"asset_id\":\"20893381255801015515826997628594359667013752732428989472914000440642900266717\", \"price\":\"0.99\", \"size\":\"7858.02\", \"side\":\"SELL\", \"hash\":\"78c4aac55585d2812f2f3ba40bf97708d847e20c\", \"best_bid\":\"0.48\", \"best_ask\":\"0.49\"}], \"timestamp\":\"1785204030810\", \"event_type\":\"price_change\"}","received_at":"2026-07-28T02:00:32.983904Z","schema_version":"clob-market-ws.price_change.v1","sequence":null,"server_hash":null,"server_timestamp":"1785204030810","session_id":"d2757dd6dad94f3b9fe67e8dbf1adc37","source":"clob_market_ws"},"received_at":"2026-07-28T02:00:32.983904Z","record_id":"d48fe5c5cce93a21e05d221ca66023431bdef202cbab6f7b56ef56b5e24fbb82","schema_fingerprint":"4aa3821a28b0b7c2400bc59aba4bcc0a76e971dadd19610d3ad38c768e124dc7","schema_version":"edge-lab-recorder.raw.v1","sequence":null,"source":"clob_market_ws"}
{"event_at":"2026-07-28T02:00:30.815000Z","event_fingerprint":"95392d661d8b3a5e3584364d6c929f39e7172baf5f535925f1c3d2f6f871b97f","payload":{"connection_id":"5d29200f65794d4d9ab6ef271f045a9b","event_at":"2026-07-28T02:00:30.815000Z","event_type":"price_change","frame_hash":"f8d1998c1ad2459c896c859ed147afdf38a956bc26708f9b8d8c52f11c497ef9","frame_index":0,"kind":"data","monotonic_ns":306016001005541,"payload":{"event_type":"price_change","market":"0xda6f0e0e93fc8469e0159a166028d017bddbc162b86f66bac90391379603d962","price_changes":[{"asset_id":"39272994714739463168905443499424551362424437245880253267329605556587274644733","best_ask":"0.52","best_bid":"0.51","hash":"ee557c4ac1d8a71f6f80136ad7d0a5509d309420","price":"0.48","side":"BUY","size":"150"},{"asset_id":"20893381255801015515826997628594359667013752732428989472914000440642900266717","best_ask":"0.49","best_bid":"0.48","hash":"781ea64a5f7370fba4a0e8151b3b50bcb3d0fb11","price":"0.52","side":"SELL","size":"150"}],"timestamp":"1785204030815"},"payload_hash":"e0bf470fe32056ab48dd47b4af3acd0237b0d8a0de28c181b5ec9617e8e5c7a4","raw_frame":"{\"market\":\"0xda6f0e0e93fc8469e0159a166028d017bddbc162b86f66bac90391379603d962\", \"price_changes\":[{\"asset_id\":\"39272994714739463168905443499424551362424437245880253267329605556587274644733\", \"price\":\"0.48\", \"size\":\"150\", \"side\":\"BUY\", \"hash\":\"ee557c4ac1d8a71f6f80136ad7d0a5509d309420\", \"best_bid\":\"0.51\", \"best_ask\":\"0.52\"}, {\"asset_id\":\"20893381255801015515826997628594359667013752732428989472914000440642900266717\", \"price\":\"0.52\", \"size\":\"150\", \"side\":\"SELL\", \"hash\":\"781ea64a5f7370fba4a0e8151b3b50bcb3d0fb11\", \"best_bid\":\"0.48\", \"best_ask\":\"0.49\"}], \"timestamp\":\"1785204030815\", \"event_type\":\"price_change\"}","received_at":"2026-07-28T02:00:32.995403Z","schema_version":"clob-market-ws.price_change.v1","sequence":null,"server_hash":null,"server_timestamp":"1785204030815","session_id":"d2757dd6dad94f3b9fe67e8dbf1adc37","source":"clob_market_ws"},"received_at":"2026-07-28T02:00:32.995403Z","record_id":"05888cefaa002c91fad38570835bef94f75621c304be14ef13c7cb69ff1206b6","schema_fingerprint":"4aa3821a28b0b7c2400bc59aba4bcc0a76e971dadd19610d3ad38c768e124dc7","schema_version":"edge-lab-recorder.raw.v1","sequence":null,"source":"clob_market_ws"}
{"event_at":"2026-07-28T02:00:30.828000Z","event_fingerprint":"9dc5e0abfa9b888bf0fbeef1d7717219f8404fcb0a1b38d639cc78393e02292b","payload":{"connection_id":"5d29200f65794d4d9ab6ef271f045a9b","event_at":"2026-07-28T02:00:30.828000Z","event_type":"price_change","frame_hash":"173b84f134658dbe3c869e02297c77c2097c58192f607a476b1655df43ff9d97","frame_index":0,"kind":"data","monotonic_ns":306016006781791,"payload":{"event_type":"price_change","market":"0xda6f0e0e93fc8469e0159a166028d017bddbc162b86f66bac90391379603d962","price_changes":[{"asset_id":"20893381255801015515826997628594359667013752732428989472914000440642900266717","best_ask":"0.49","best_bid":"0.48","hash":"0b9355bb5c99224a4683fcd9abb6d4407c2f58b9","price":"0.48","side":"BUY","size":"10"},{"asset_id":"39272994714739463168905443499424551362424437245880253267329605556587274644733","best_ask":"0.52","best_bid":"0.51","hash":"9468d55a5353dbe6c49ee0eb5eccec47e190fd34","price":"0.52","side":"SELL","size":"10"}],"timestamp":"1785204030828"},"payload_hash":"7992d1c145fa9846266779e895672b64a9d919e0fe3f12ecf8c9de190d11731a","raw_frame":"{\"market\":\"0xda6f0e0e93fc8469e0159a166028d017bddbc162b86f66bac90391379603d962\", \"price_changes\":[{\"asset_id\":\"20893381255801015515826997628594359667013752732428989472914000440642900266717\", \"price\":\"0.48\", \"size\":\"10\", \"side\":\"BUY\", \"hash\":\"0b9355bb5c99224a4683fcd9abb6d4407c2f58b9\", \"best_bid\":\"0.48\", \"best_ask\":\"0.49\"}, {\"asset_id\":\"39272994714739463168905443499424551362424437245880253267329605556587274644733\", \"price\":\"0.52\", \"size\":\"10\", \"side\":\"SELL\", \"hash\":\"9468d55a5353dbe6c49ee0eb5eccec47e190fd34\", \"best_bid\":\"0.51\", \"best_ask\":\"0.52\"}], \"timestamp\":\"1785204030828\", \"event_type\":\"price_change\"}","received_at":"2026-07-28T02:00:33.001181Z","schema_version":"clob-market-ws.price_change.v1","sequence":null,"server_hash":null,"server_timestamp":"1785204030828","session_id":"d2757dd6dad94f3b9fe67e8dbf1adc37","source":"clob_market_ws"},"received_at":"2026-07-28T02:00:33.001181Z","record_id":"2c5ceceaac7da3703e28d9b7b8bc095084dff41702b4aad847def056f51fa824","schema_fingerprint":"4aa3821a28b0b7c2400bc59aba4bcc0a76e971dadd19610d3ad38c768e124dc7","schema_version":"edge-lab-recorder.raw.v1","sequence":null,"source":"clob_market_ws"}
{"event_at":"2026-07-28T02:00:30.829000Z","event_fingerprint":"31a62fd14382a2a83756d97d032579dd0a61ce599931a400fbe6f157a50832b6","payload":{"connection_id":"5d29200f65794d4d9ab6ef271f045a9b","event_at":"2026-07-28T02:00:30.829000Z","event_type":"price_change","frame_hash":"3c2901bf8f07991d5bc30c1301d827bb404098b70dffbd7b068eb72232bc0d6f","frame_index":0,"kind":"data","monotonic_ns":306016011040000,"payload":{"event_type":"price_change","market":"0xda6f0e0e93fc8469e0159a166028d017bddbc162b86f66bac90391379603d962","price_changes":[{"asset_id":"39272994714739463168905443499424551362424437245880253267329605556587274644733","best_ask":"0.52","best_bid":"0.51","hash":"1f545548f8274eb4751ee1aa4abd27ac02942a2a","price":"0.43","side":"BUY","size":"112"},{"asset_id":"20893381255801015515826997628594359667013752732428989472914000440642900266717","best_ask":"0.49","best_bid":"0.48","hash":"4e41f841974288b8390a226aa146fa72e3b9f7ba","price":"0.57","side":"SELL","size":"112"}],"timestamp":"1785204030829"},"payload_hash":"520d60bbb2d0cf9a543dbdbeff59773c8cee67aa48cb1c09a8ccb1ba74ddd785","raw_frame":"{\"market\":\"0xda6f0e0e93fc8469e0159a166028d017bddbc162b86f66bac90391379603d962\", \"price_changes\":[{\"asset_id\":\"39272994714739463168905443499424551362424437245880253267329605556587274644733\", \"price\":\"0.43\", \"size\":\"112\", \"side\":\"BUY\", \"hash\":\"1f545548f8274eb4751ee1aa4abd27ac02942a2a\", \"best_bid\":\"0.51\", \"best_ask\":\"0.52\"}, {\"asset_id\":\"20893381255801015515826997628594359667013752732428989472914000440642900266717\", \"price\":\"0.57\", \"size\":\"112\", \"side\":\"SELL\", \"hash\":\"4e41f841974288b8390a226aa146fa72e3b9f7ba\", \"best_bid\":\"0.48\", \"best_ask\":\"0.49\"}], \"timestamp\":\"1785204030829\", \"event_type\":\"price_change\"}","received_at":"2026-07-28T02:00:33.005441Z","schema_version":"clob-market-ws.price_change.v1","sequence":null,"server_hash":null,"server_timestamp":"1785204030829","session_id":"d2757dd6dad94f3b9fe67e8dbf1adc37","source":"clob_market_ws"},"received_at":"2026-07-28T02:00:33.005441Z","record_id":"b9beb213ac3f6cbfbf5e5f53ee32dfc9cc7581180cca90d6dc615829b5443905","schema_fingerprint":"4aa3821a28b0b7c2400bc59aba4bcc0a76e971dadd19610d3ad38c768e124dc7","schema_version":"edge-lab-recorder.raw.v1","sequence":null,"source":"clob_market_ws"}
{"event_at":"2026-07-28T02:00:30.832000Z","event_fingerprint":"bc2abbe9f4beb0e65f29085d5758a260a06516ecff11c297db8b6dfed4962c92","payload":{"connection_id":"5d29200f65794d4d9ab6ef271f045a9b","event_at":"2026-07-28T02:00:30.832000Z","event_type":"price_change","frame_hash":"8f057b457c5061b62886fb4fcdeea982a0f628d1af586045822d6ab1441a142d","frame_index":0,"kind":"data","monotonic_ns":306016016039166,"payload":{"event_type":"price_change","market":"0xda6f0e0e93fc8469e0159a166028d017bddbc162b86f66bac90391379603d962","price_changes":[{"asset_id":"20893381255801015515826997628594359667013752732428989472914000440642900266717","best_ask":"0.49","best_bid":"0.48","hash":"06b1dc7b1c77523adc8deb1ccbad8b4557781dfb","price":"0.44","side":"BUY","size":"231"},{"asset_id":"39272994714739463168905443499424551362424437245880253267329605556587274644733","best_ask":"0.52","best_bid":"0.51","hash":"1651f6d4dcd7082fe12441f9b0804efcf4be7b90","price":"0.56","side":"SELL","size":"231"}],"timestamp":"1785204030832"},"payload_hash":"b3abf449c305e618354fc51c65b9257efe6cdf6b0201c350cf403db57067b28d","raw_frame":"{\"market\":\"0xda6f0e0e93fc8469e0159a166028d017bddbc162b86f66bac90391379603d962\", \"price_changes\":[{\"asset_id\":\"20893381255801015515826997628594359667013752732428989472914000440642900266717\", \"price\":\"0.44\", \"size\":\"231\", \"side\":\"BUY\", \"hash\":\"06b1dc7b1c77523adc8deb1ccbad8b4557781dfb\", \"best_bid\":\"0.48\", \"best_ask\":\"0.49\"}, {\"asset_id\":\"39272994714739463168905443499424551362424437245880253267329605556587274644733\", \"price\":\"0.56\", \"size\":\"231\", \"side\":\"SELL\", \"hash\":\"1651f6d4dcd7082fe12441f9b0804efcf4be7b90\", \"best_bid\":\"0.51\", \"best_ask\":\"0.52\"}], \"timestamp\":\"1785204030832\", \"event_type\":\"price_change\"}","received_at":"2026-07-28T02:00:33.010441Z","schema_version":"clob-market-ws.price_change.v1","sequence":null,"server_hash":null,"server_timestamp":"1785204030832","session_id":"d2757dd6dad94f3b9fe67e8dbf1adc37","source":"clob_market_ws"},"received_at":"2026-07-28T02:00:33.010441Z","record_id":"0c58345bb8beec543b5e6c43e967466d6306e919f5c9522698fc097703f135f6","schema_fingerprint":"4aa3821a28b0b7c2400bc59aba4bcc0a76e971dadd19610d3ad38c768e124dc7","schema_version":"edge-lab-recorder.raw.v1","sequence":null,"source":"clob_market_ws"}
{"event_at":"2026-07-28T02:00:30.832000Z","event_fingerprint":"d98302ef43d41ab858288b213a546283df96be9baa0f910c8879ccfcaf767e76","payload":{"connection_id":"5d29200f65794d4d9ab6ef271f045a9b","event_at":"2026-07-28T02:00:30.832000Z","event_type":"price_change","frame_hash":"df39478108dbc11aa917ad7bcfe7707b3e60fef03c5ddb9b11990f46976b6e73","frame_index":0,"kind":"data","monotonic_ns":306016025356250,"payload":{"event_type":"price_change","market":"0xda6f0e0e93fc8469e0159a166028d017bddbc162b86f66bac90391379603d962","price_changes":[{"asset_id":"39272994714739463168905443499424551362424437245880253267329605556587274644733","best_ask":"0.52","best_bid":"0.51","hash":"1651f6d4dcd7082fe12441f9b0804efcf4be7b90","price":"0.47","side":"BUY","size":"126.6"},{"asset_id":"20893381255801015515826997628594359667013752732428989472914000440642900266717","best_ask":"0.49","best_bid":"0.48","hash":"06b1dc7b1c77523adc8deb1ccbad8b4557781dfb","price":"0.53","side":"SELL","size":"126.6"}],"timestamp":"1785204030832"},"payload_hash":"4efa6d51b9e8e0356e587caa50af156e33bdb8d58b1c5366666c508e54f31e1e","raw_frame":"{\"market\":\"0xda6f0e0e93fc8469e0159a166028d017bddbc162b86f66bac90391379603d962\", \"price_changes\":[{\"asset_id\":\"39272994714739463168905443499424551362424437245880253267329605556587274644733\", \"price\":\"0.47\", \"size\":\"126.6\", \"side\":\"BUY\", \"hash\":\"1651f6d4dcd7082fe12441f9b0804efcf4be7b90\", \"best_bid\":\"0.51\", \"best_ask\":\"0.52\"}, {\"asset_id\":\"20893381255801015515826997628594359667013752732428989472914000440642900266717\", \"price\":\"0.53\", \"size\":\"126.6\", \"side\":\"SELL\", \"hash\":\"06b1dc7b1c77523adc8deb1ccbad8b4557781dfb\", \"best_bid\":\"0.48\", \"best_ask\":\"0.49\"}], \"timestamp\":\"1785204030832\", \"event_type\":\"price_change\"}","received_at":"2026-07-28T02:00:33.019758Z","schema_version":"clob-market-ws.price_change.v1","sequence":null,"server_hash":null,"server_timestamp":"1785204030832","session_id":"d2757dd6dad94f3b9fe67e8dbf1adc37","source":"clob_market_ws"},"received_at":"2026-07-28T02:00:33.019758Z","record_id":"9f88627e7d494436f265e8e882b76ceace5e2fc6ae82b438bc5bd036001c0047","schema_fingerprint":"4aa3821a28b0b7c2400bc59aba4bcc0a76e971dadd19610d3ad38c768e124dc7","schema_version":"edge-lab-recorder.raw.v1","sequence":null,"source":"clob_market_ws"}
{"event_at":"2026-07-28T02:00:30.839000Z","event_fingerprint":"e64661d2159336400d451f5e8e87562b03de4f6be01cf82eb00198c425b727c9","payload":{"connection_id":"5d29200f65794d4d9ab6ef271f045a9b","event_at":"2026-07-28T02:00:30.839000Z","event_type":"price_change","frame_hash":"db576789d29d8c1a177621cf1c9f88abccbf49e00bd0f86898769f6be580c981","frame_index":0,"kind":"data","monotonic_ns":306016036471250,"payload":{"event_type":"price_change","market":"0xda6f0e0e93fc8469e0159a166028d017bddbc162b86f66bac90391379603d962","price_changes":[{"asset_id":"20893381255801015515826997628594359667013752732428989472914000440642900266717","best_ask":"0.49","best_bid":"0.48","hash":"a06ebd3e320040bd4915fdd50c332f3cac6d4af4","price":"0.4","side":"BUY","size":"260.45"},{"asset_id":"39272994714739463168905443499424551362424437245880253267329605556587274644733","best_ask":"0.52","best_bid":"0.51","hash":"6344d66cf10d046f7468d210cf1611c0fa54f359","price":"0.6","side":"SELL","size":"260.45"}],"timestamp":"1785204030839"},"payload_hash":"c6768703ed38ad26ed95e0da0ba4a7bde00aa2aeba3e95722c702919ee8ee928","raw_frame":"{\"market\":\"0xda6f0e0e93fc8469e0159a166028d017bddbc162b86f66bac90391379603d962\", \"price_changes\":[{\"asset_id\":\"20893381255801015515826997628594359667013752732428989472914000440642900266717\", \"price\":\"0.4\", \"size\":\"260.45\", \"side\":\"BUY\", \"hash\":\"a06ebd3e320040bd4915fdd50c332f3cac6d4af4\", \"best_bid\":\"0.48\", \"best_ask\":\"0.49\"}, {\"asset_id\":\"39272994714739463168905443499424551362424437245880253267329605556587274644733\", \"price\":\"0.6\", \"size\":\"260.45\", \"side\":\"SELL\", \"hash\":\"6344d66cf10d046f7468d210cf1611c0fa54f359\", \"best_bid\":\"0.51\", \"best_ask\":\"0.52\"}], \"timestamp\":\"1785204030839\", \"event_type\":\"price_change\"}","received_at":"2026-07-28T02:00:33.030876Z","schema_version":"clob-market-ws.price_change.v1","sequence":null,"server_hash":null,"server_timestamp":"1785204030839","session_id":"d2757dd6dad94f3b9fe67e8dbf1adc37","source":"clob_market_ws"},"received_at":"2026-07-28T02:00:33.030876Z","record_id":"ae8218de718b3225501434d37dab9ab7662b9aa353d911b8b7ae5d2f97d6ecab","schema_fingerprint":"4aa3821a28b0b7c2400bc59aba4bcc0a76e971dadd19610d3ad38c768e124dc7","schema_version":"edge-lab-recorder.raw.v1","sequence":null,"source":"clob_market_ws"}
{"event_at":"2026-07-28T02:00:30.840000Z","event_fingerprint":"c75bbcfe8aa30e38d285baf382ae539be91dd679c32abbb68f2d6c18e4841372","payload":{"connection_id":"5d29200f65794d4d9ab6ef271f045a9b","event_at":"2026-07-28T02:00:30.840000Z","event_type":"price_change","frame_hash":"821e887ebbd164290c9cb2c2685a747b1f63ff12e761c4cb045316ae3ba5f638","frame_index":0,"kind":"data","monotonic_ns":306016050057333,"payload":{"event_type":"price_change","market":"0xda6f0e0e93fc8469e0159a166028d017bddbc162b86f66bac90391379603d962","price_changes":[{"asset_id":"39272994714739463168905443499424551362424437245880253267329605556587274644733","best_ask":"0.52","best_bid":"0.51","hash":"0f10ce87d3e5445f39660dd6c8ecc7bda6107afd","price":"0.51","side":"BUY","size":"97.2"},{"asset_id":"20893381255801015515826997628594359667013752732428989472914000440642900266717","best_ask":"0.49","best_bid":"0.48","hash":"54ecf8764b6bc1899535927541d9ac1a3be7022e","price":"0.49","side":"SELL","size":"97.2"}],"timestamp":"1785204030840"},"payload_hash":"1e627220f73e9d476b0b2042494611cd0054d16565026d5c2cf1bc633e18ba7d","raw_frame":"{\"market\":\"0xda6f0e0e93fc8469e0159a166028d017bddbc162b86f66bac90391379603d962\", \"price_changes\":[{\"asset_id\":\"39272994714739463168905443499424551362424437245880253267329605556587274644733\", \"price\":\"0.51\", \"size\":\"97.2\", \"side\":\"BUY\", \"hash\":\"0f10ce87d3e5445f39660dd6c8ecc7bda6107afd\", \"best_bid\":\"0.51\", \"best_ask\":\"0.52\"}, {\"asset_id\":\"20893381255801015515826997628594359667013752732428989472914000440642900266717\", \"price\":\"0.49\", \"size\":\"97.2\", \"side\":\"SELL\", \"hash\":\"54ecf8764b6bc1899535927541d9ac1a3be7022e\", \"best_bid\":\"0.48\", \"best_ask\":\"0.49\"}], \"timestamp\":\"1785204030840\", \"event_type\":\"price_change\"}","received_at":"2026-07-28T02:00:33.044463Z","schema_version":"clob-market-ws.price_change.v1","sequence":null,"server_hash":null,"server_timestamp":"1785204030840","session_id":"d2757dd6dad94f3b9fe67e8dbf1adc37","source":"clob_market_ws"},"received_at":"2026-07-28T02:00:33.044463Z","record_id":"aa8c810a5c9fab560882a2ad0183088320e037fa87d81f990ac7b11c46575b88","schema_fingerprint":"4aa3821a28b0b7c2400bc59aba4bcc0a76e971dadd19610d3ad38c768e124dc7","schema_version":"edge-lab-recorder.raw.v1","sequence":null,"source":"clob_market_ws"}
{"event_at":"2026-07-28T02:00:30.862000Z","event_fingerprint":"8b0f59a84d2429a4690158eecc0b27dd7df5d8df7db27f0157bf826f4f5c7396","payload":{"connection_id":"5d29200f65794d4d9ab6ef271f045a9b","event_at":"2026-07-28T02:00:30.862000Z","event_type":"price_change","frame_hash":"9ccbf12ba55e30859cafc4cc3454fd7153b312b1b758405c908cbe374d68bab0","frame_index":0,"kind":"data","monotonic_ns":306016053775000,"payload":{"event_type":"price_change","market":"0xda6f0e0e93fc8469e0159a166028d017bddbc162b86f66bac90391379603d962","price_changes":[{"asset_id":"39272994714739463168905443499424551362424437245880253267329605556587274644733","best_ask":"0.52","best_bid":"0.51","hash":"170b0a97c0f33a2e273a3a0fab07469678d86543","price":"0.05","side":"BUY","size":"773.2"},{"asset_id":"20893381255801015515826997628594359667013752732428989472914000440642900266717","best_ask":"0.49","best_bid":"0.48","hash":"46047c2a0c416ae7282fc24569d1a7110d06179c","price":"0.95","side":"SELL","size":"773.2"}],"timestamp":"1785204030862"},"payload_hash":"e6cdbf39e67c4c69eac492224676facd0a881803d9b28a8847bcd176279ad035","raw_frame":"{\"market\":\"0xda6f0e0e93fc8469e0159a166028d017bddbc162b86f66bac90391379603d962\", \"price_changes\":[{\"asset_id\":\"39272994714739463168905443499424551362424437245880253267329605556587274644733\", \"price\":\"0.05\", \"size\":\"773.2\", \"side\":\"BUY\", \"hash\":\"170b0a97c0f33a2e273a3a0fab07469678d86543\", \"best_bid\":\"0.51\", \"best_ask\":\"0.52\"}, {\"asset_id\":\"20893381255801015515826997628594359667013752732428989472914000440642900266717\", \"price\":\"0.95\", \"size\":\"773.2\", \"side\":\"SELL\", \"hash\":\"46047c2a0c416ae7282fc24569d1a7110d06179c\", \"best_bid\":\"0.48\", \"best_ask\":\"0.49\"}], \"timestamp\":\"1785204030862\", \"event_type\":\"price_change\"}","received_at":"2026-07-28T02:00:33.048182Z","schema_version":"clob-market-ws.price_change.v1","sequence":null,"server_hash":null,"server_timestamp":"1785204030862","session_id":"d2757dd6dad94f3b9fe67e8dbf1adc37","source":"clob_market_ws"},"received_at":"2026-07-28T02:00:33.048182Z","record_id":"407fc1633efb8bb5b5df5636770ce6d5f15467c0a8c8322d58dc34540ba8640f","schema_fingerprint":"4aa3821a28b0b7c2400bc59aba4bcc0a76e971dadd19610d3ad38c768e124dc7","schema_version":"edge-lab-recorder.raw.v1","sequence":null,"source":"clob_market_ws"}
{"event_at":"2026-07-28T02:00:30.863000Z","event_fingerprint":"91b9d5a2732c2904e30bd773855742149ebb02d549f91d0dac5a1900d8fac518","payload":{"connection_id":"5d29200f65794d4d9ab6ef271f045a9b","event_at":"2026-07-28T02:00:30.863000Z","event_type":"price_change","frame_hash":"a9da5fc6faf0ead4ffb3b5f4d3e67ca570e14e32ac0733cc68089bd2f4eba32a","frame_index":0,"kind":"data","monotonic_ns":306016060213250,"payload":{"event_type":"price_change","market":"0xda6f0e0e93fc8469e0159a166028d017bddbc162b86f66bac90391379603d962","price_changes":[{"asset_id":"39272994714739463168905443499424551362424437245880253267329605556587274644733","best_ask":"0.52","best_bid":"0.51","hash":"a510cb28623b3b38fc6d8a0f8fa8d4c1d780a287","price":"0.01","side":"BUY","size":"7853.02"},{"asset_id":"20893381255801015515826997628594359667013752732428989472914000440642900266717","best_ask":"0.49","best_bid":"0.48","hash":"3186a9f11f3fcbd437628bcbc9b6d20b4106cc12","price":"0.99","side":"SELL","size":"7853.02"}],"timestamp":"1785204030863"},"payload_hash":"2f0077bd49a35c5829a0219cbd759f78de2ca3a400356881b82a8ed5ab8de1a7","raw_frame":"{\"market\":\"0xda6f0e0e93fc8469e0159a166028d017bddbc162b86f66bac90391379603d962\", \"price_changes\":[{\"asset_id\":\"39272994714739463168905443499424551362424437245880253267329605556587274644733\", \"price\":\"0.01\", \"size\":\"7853.02\", \"side\":\"BUY\", \"hash\":\"a510cb28623b3b38fc6d8a0f8fa8d4c1d780a287\", \"best_bid\":\"0.51\", \"best_ask\":\"0.52\"}, {\"asset_id\":\"20893381255801015515826997628594359667013752732428989472914000440642900266717\", \"price\":\"0.99\", \"size\":\"7853.02\", \"side\":\"SELL\", \"hash\":\"3186a9f11f3fcbd437628bcbc9b6d20b4106cc12\", \"best_bid\":\"0.48\", \"best_ask\":\"0.49\"}], \"timestamp\":\"1785204030863\", \"event_type\":\"price_change\"}","received_at":"2026-07-28T02:00:33.054620Z","schema_version":"clob-market-ws.price_change.v1","sequence":null,"server_hash":null,"server_timestamp":"1785204030863","session_id":"d2757dd6dad94f3b9fe67e8dbf1adc37","source":"clob_market_ws"},"received_at":"2026-07-28T02:00:33.054620Z","record_id":"83458364c871d1027b6689a9994e3c64bf4118c54d3a8152ca464cbcd0661083","schema_fingerprint":"4aa3821a28b0b7c2400bc59aba4bcc0a76e971dadd19610d3ad38c768e124dc7","schema_version":"edge-lab-recorder.raw.v1","sequence":null,"source":"clob_market_ws"}
{"event_at":"2026-07-28T02:00:30.949000Z","event_fingerprint":"0c512ccb838e5a7eb355f0e2cb41e76c9bb4ec29bf2479a5cd8d8cde63536c5c","payload":{"connection_id":"5d29200f65794d4d9ab6ef271f045a9b","event_at":"2026-07-28T02:00:30.949000Z","event_type":"price_change","frame_hash":"9beba0bef08966bca4ba2875283404a54ce7cd399f03e883f0465a53cdac130c","frame_index":0,"kind":"data","monotonic_ns":306016068925708,"payload":{"event_type":"price_change","market":"0xda6f0e0e93fc8469e0159a166028d017bddbc162b86f66bac90391379603d962","price_changes":[{"asset_id":"39272994714739463168905443499424551362424437245880253267329605556587274644733","best_ask":"0.52","best_bid":"0.51","hash":"cc5771406255d7573a62d141600a5c26321f1335","price":"0.46","side":"BUY","size":"98"},{"asset_id":"20893381255801015515826997628594359667013752732428989472914000440642900266717","best_ask":"0.49","best_bid":"0.48","hash":"b241a281a89453f499e5adf793d34705669f09ca","price":"0.54","side":"SELL","size":"98"}],"timestamp":"1785204030949"},"payload_hash":"79b0ccbc5ff8b1f7f5d6bdd39cd9993e2e626c53a516e3602c6051102002121d","raw_frame":"{\"market\":\"0xda6f0e0e93fc8469e0159a166028d017bddbc162b86f66bac90391379603d962\", \"price_changes\":[{\"asset_id\":\"39272994714739463168905443499424551362424437245880253267329605556587274644733\", \"price\":\"0.46\", \"size\":\"98\", \"side\":\"BUY\", \"hash\":\"cc5771406255d7573a62d141600a5c26321f1335\", \"best_bid\":\"0.51\", \"best_ask\":\"0.52\"}, {\"asset_id\":\"20893381255801015515826997628594359667013752732428989472914000440642900266717\", \"price\":\"0.54\", \"size\":\"98\", \"side\":\"SELL\", \"hash\":\"b241a281a89453f499e5adf793d34705669f09ca\", \"best_bid\":\"0.48\", \"best_ask\":\"0.49\"}], \"timestamp\":\"1785204030949\", \"event_type\":\"price_change\"}","received_at":"2026-07-28T02:00:33.063334Z","schema_version":"clob-market-ws.price_change.v1","sequence":null,"server_hash":null,"server_timestamp":"1785204030949","session_id":"d2757dd6dad94f3b9fe67e8dbf1adc37","source":"clob_market_ws"},"received_at":"2026-07-28T02:00:33.063334Z","record_id":"9b4ebaf32be871449b04263888da5ef1b53a602e7fa8d9821acad100941a2391","schema_fingerprint":"4aa3821a28b0b7c2400bc59aba4bcc0a76e971dadd19610d3ad38c768e124dc7","schema_version":"edge-lab-recorder.raw.v1","sequence":null,"source":"clob_market_ws"}
{"event_at":"2026-07-28T02:00:30.990000Z","event_fingerprint":"ea4279dda9ecdaaf46901cac4bef6ffdd20c85268e586c73573cba0c90f6399e","payload":{"connection_id":"5d29200f65794d4d9ab6ef271f045a9b","event_at":"2026-07-28T02:00:30.990000Z","event_type":"price_change","frame_hash":"7490d351b68ac122caaf07d43a1152e5be74b2d29082226ddb1856aab352cba9","frame_index":0,"kind":"data","monotonic_ns":306016074653750,"payload":{"event_type":"price_change","market":"0xda6f0e0e93fc8469e0159a166028d017bddbc162b86f66bac90391379603d962","price_changes":[{"asset_id":"20893381255801015515826997628594359667013752732428989472914000440642900266717","best_ask":"0.49","best_bid":"0.48","hash":"f043b7e7a92eb2a73af945438fb47a5e04451156","price":"0.48","side":"BUY","size":"5"},{"asset_id":"39272994714739463168905443499424551362424437245880253267329605556587274644733","best_ask":"0.52","best_bid":"0.51","hash":"aa04f11940b799d3c9d701ce28edec4fa883f9d6","price":"0.52","side":"SELL","size":"5"}],"timestamp":"1785204030990"},"payload_hash":"c01850ad745cca0c7076aca6a9808d291308a3fdb21c920a79a08da39f190f9a","raw_frame":"{\"market\":\"0xda6f0e0e93fc8469e0159a166028d017bddbc162b86f66bac90391379603d962\", \"price_changes\":[{\"asset_id\":\"20893381255801015515826997628594359667013752732428989472914000440642900266717\", \"price\":\"0.48\", \"size\":\"5\", \"side\":\"BUY\", \"hash\":\"f043b7e7a92eb2a73af945438fb47a5e04451156\", \"best_bid\":\"0.48\", \"best_ask\":\"0.49\"}, {\"asset_id\":\"39272994714739463168905443499424551362424437245880253267329605556587274644733\", \"price\":\"0.52\", \"size\":\"5\", \"side\":\"SELL\", \"hash\":\"aa04f11940b799d3c9d701ce28edec4fa883f9d6\", \"best_bid\":\"0.51\", \"best_ask\":\"0.52\"}], \"timestamp\":\"1785204030990\", \"event_type\":\"price_change\"}","received_at":"2026-07-28T02:00:33.069062Z","schema_version":"clob-market-ws.price_change.v1","sequence":null,"server_hash":null,"server_timestamp":"1785204030990","session_id":"d2757dd6dad94f3b9fe67e8dbf1adc37","source":"clob_market_ws"},"received_at":"2026-07-28T02:00:33.069062Z","record_id":"458173aea1fbed8613e28ccd8105f627957ed9a3880248bc12c41dbe4c1454a7","schema_fingerprint":"4aa3821a28b0b7c2400bc59aba4bcc0a76e971dadd19610d3ad38c768e124dc7","schema_version":"edge-lab-recorder.raw.v1","sequence":null,"source":"clob_market_ws"}
{"event_at":"2026-07-28T02:00:30.991000Z","event_fingerprint":"8aaa63457a6220dfa33f20726eba2d9df35b89c7749e440c13c0712e8e9ac164","payload":{"connection_id":"5d29200f65794d4d9ab6ef271f045a9b","event_at":"2026-07-28T02:00:30.991000Z","event_type":"best_bid_ask","frame_hash":"430c7273f3fb729c16783ae0ce90a12bd4451b06780f4903b5c6230274799396","frame_index":0,"kind":"data","monotonic_ns":306016078936583,"payload":{"asset_id":"20893381255801015515826997628594359667013752732428989472914000440642900266717","best_ask":"0.49","best_bid":"0.47","event_type":"best_bid_ask","market":"0xda6f0e0e93fc8469e0159a166028d017bddbc162b86f66bac90391379603d962","spread":"0.02","timestamp":"1785204030991"},"payload_hash":"2190a2cd7405fafcd81f62f95828f18ae5577944dfd3487957c63fa732e68111","raw_frame":"{\"market\":\"0xda6f0e0e93fc8469e0159a166028d017bddbc162b86f66bac90391379603d962\", \"asset_id\":\"20893381255801015515826997628594359667013752732428989472914000440642900266717\", \"best_bid\":\"0.47\", \"best_ask\":\"0.49\", \"spread\":\"0.02\", \"timestamp\":\"1785204030991\", \"event_type\":\"best_bid_ask\"}","received_at":"2026-07-28T02:00:33.073347Z","schema_version":"clob-market-ws.best_bid_ask.v1","sequence":null,"server_hash":null,"server_timestamp":"1785204030991","session_id":"d2757dd6dad94f3b9fe67e8dbf1adc37","source":"clob_market_ws"},"received_at":"2026-07-28T02:00:33.073347Z","record_id":"45cd2797e395266900df7e4b2f915d611cb9df0c16922558d0313d1460269b2a","schema_fingerprint":"8488399f31b0337811b13b266be932db7062827c2470b78bd8e9e99bab51d17d","schema_version":"edge-lab-recorder.raw.v1","sequence":null,"source":"clob_market_ws"}
{"event_at":"2026-07-28T02:00:30.991000Z","event_fingerprint":"dcd9af3fa7b92584258b45f56921e4e7e3e1997cadbb4d84014ae38a701774d0","payload":{"connection_id":"5d29200f65794d4d9ab6ef271f045a9b","event_at":"2026-07-28T02:00:30.991000Z","event_type":"best_bid_ask","frame_hash":"b2f8b9200cd314484d8ab4b26c3ee98686f3b34084b633152f40f4761daa43f4","frame_index":0,"kind":"data","monotonic_ns":306016082889458,"payload":{"asset_id":"39272994714739463168905443499424551362424437245880253267329605556587274644733","best_ask":"0.53","best_bid":"0.51","event_type":"best_bid_ask","market":"0xda6f0e0e93fc8469e0159a166028d017bddbc162b86f66bac90391379603d962","spread":"0.02","timestamp":"1785204030991"},"payload_hash":"192c3ce587085b47f02321cb74026cc0d4874210e4b8981b2d49d2d7f6b9cc2f","raw_frame":"{\"market\":\"0xda6f0e0e93fc8469e0159a166028d017bddbc162b86f66bac90391379603d962\", \"asset_id\":\"39272994714739463168905443499424551362424437245880253267329605556587274644733\", \"best_bid\":\"0.51\", \"best_ask\":\"0.53\", \"spread\":\"0.02\", \"timestamp\":\"1785204030991\", \"event_type\":\"best_bid_ask\"}","received_at":"2026-07-28T02:00:33.077299Z","schema_version":"clob-market-ws.best_bid_ask.v1","sequence":null,"server_hash":null,"server_timestamp":"1785204030991","session_id":"d2757dd6dad94f3b9fe67e8dbf1adc37","source":"clob_market_ws"},"received_at":"2026-07-28T02:00:33.077299Z","record_id":"9ff3f0754a11caf22feaae8e0a8e91645eeffa0239e0725e2bf5daa893d17c0b","schema_fingerprint":"8488399f31b0337811b13b266be932db7062827c2470b78bd8e9e99bab51d17d","schema_version":"edge-lab-recorder.raw.v1","sequence":null,"source":"clob_market_ws"}
{"event_at":"2026-07-28T02:00:30.991000Z","event_fingerprint":"cd96250ed96b76813dc335ff3b37c1f25a5fd80b5f2ecb737e4e6a87e5e58f01","payload":{"connection_id":"5d29200f65794d4d9ab6ef271f045a9b","event_at":"2026-07-28T02:00:30.991000Z","event_type":"price_change","frame_hash":"c21518fbcba2404cf2402eb3e9f2dfe291a82d1b8286a613457731305b976220","frame_index":0,"kind":"data","monotonic_ns":306016088121875,"payload":{"event_type":"price_change","market":"0xda6f0e0e93fc8469e0159a166028d017bddbc162b86f66bac90391379603d962","price_changes":[{"asset_id":"39272994714739463168905443499424551362424437245880253267329605556587274644733","best_ask":"0.53","best_bid":"0.51","hash":"4fa111aa529bb17119dde9a2a2b5de8de79180af","price":"0.52","side":"SELL","size":"0"},{"asset_id":"20893381255801015515826997628594359667013752732428989472914000440642900266717","best_ask":"0.49","best_bid":"0.47","hash":"9805ebbc834aa963e55101d9c8f6e08c91d39362","price":"0.48","side":"BUY","size":"0"}],"timestamp":"1785204030991"},"payload_hash":"f08950408ac1e46190c9d495660a8d3add793486055e00bcefc1ebcfc9d40f4d","raw_frame":"{\"market\":\"0xda6f0e0e93fc8469e0159a166028d017bddbc162b86f66bac90391379603d962\", \"price_changes\":[{\"asset_id\":\"39272994714739463168905443499424551362424437245880253267329605556587274644733\", \"price\":\"0.52\", \"size\":\"0\", \"side\":\"SELL\", \"hash\":\"4fa111aa529bb17119dde9a2a2b5de8de79180af\", \"best_bid\":\"0.51\", \"best_ask\":\"0.53\"}, {\"asset_id\":\"20893381255801015515826997628594359667013752732428989472914000440642900266717\", \"price\":\"0.48\", \"size\":\"0\", \"side\":\"BUY\", \"hash\":\"9805ebbc834aa963e55101d9c8f6e08c91d39362\", \"best_bid\":\"0.47\", \"best_ask\":\"0.49\"}], \"timestamp\":\"1785204030991\", \"event_type\":\"price_change\"}","received_at":"2026-07-28T02:00:33.082533Z","schema_version":"clob-market-ws.price_change.v1","sequence":null,"server_hash":null,"server_timestamp":"1785204030991","session_id":"d2757dd6dad94f3b9fe67e8dbf1adc37","source":"clob_market_ws"},"received_at":"2026-07-28T02:00:33.082533Z","record_id":"80ab0a3d7534326a3aa0041a1fc39c26d86f963ef07799563a4e6056af1df83b","schema_fingerprint":"4aa3821a28b0b7c2400bc59aba4bcc0a76e971dadd19610d3ad38c768e124dc7","schema_version":"edge-lab-recorder.raw.v1","sequence":null,"source":"clob_market_ws"}
{"event_at":"2026-07-28T02:00:31.016000Z","event_fingerprint":"fe11a6cb81189bfa69cb7792810f234f3b90f1aa8b32309087779ee87c283c55","payload":{"connection_id":"5d29200f65794d4d9ab6ef271f045a9b","event_at":"2026-07-28T02:00:31.016000Z","event_type":"price_change","frame_hash":"9f5cd81537b4b77bee87381dc751622da13e34d3aaad42249269f2d4701f137d","frame_index":0,"kind":"data","monotonic_ns":306016095799458,"payload":{"event_type":"price_change","market":"0xda6f0e0e93fc8469e0159a166028d017bddbc162b86f66bac90391379603d962","price_changes":[{"asset_id":"20893381255801015515826997628594359667013752732428989472914000440642900266717","best_ask":"0.49","best_bid":"0.47","hash":"c2e89e45bd77b489071a9d864b4dfd7a721bd606","price":"0.44","side":"BUY","size":"221"},{"asset_id":"39272994714739463168905443499424551362424437245880253267329605556587274644733","best_ask":"0.53","best_bid":"0.51","hash":"f1f08be7d05c93334d7ad2d6413e8d779e242fd5","price":"0.56","side":"SELL","size":"221"}],"timestamp":"1785204031016"},"payload_hash":"9fa4c11744548a715e7bd0df473284eecc7afb73ce7813ffe10065d255efe02d","raw_frame":"{\"market\":\"0xda6f0e0e93fc8469e0159a166028d017bddbc162b86f66bac90391379603d962\", \"price_changes\":[{\"asset_id\":\"20893381255801015515826997628594359667013752732428989472914000440642900266717\", \"price\":\"0.44\", \"size\":\"221\", \"side\":\"BUY\", \"hash\":\"c2e89e45bd77b489071a9d864b4dfd7a721bd606\", \"best_bid\":\"0.47\", \"best_ask\":\"0.49\"}, {\"asset_id\":\"39272994714739463168905443499424551362424437245880253267329605556587274644733\", \"price\":\"0.56\", \"size\":\"221\", \"side\":\"SELL\", \"hash\":\"f1f08be7d05c93334d7ad2d6413e8d779e242fd5\", \"best_bid\":\"0.51\", \"best_ask\":\"0.53\"}], \"timestamp\":\"1785204031016\", \"event_type\":\"price_change\"}","received_at":"2026-07-28T02:00:33.090210Z","schema_version":"clob-market-ws.price_change.v1","sequence":null,"server_hash":null,"server_timestamp":"1785204031016","session_id":"d2757dd6dad94f3b9fe67e8dbf1adc37","source":"clob_market_ws"},"received_at":"2026-07-28T02:00:33.090210Z","record_id":"63bd73c30f30fb2e11a0b6d294866064491a16649e1d142bdaed43cc287baf54","schema_fingerprint":"4aa3821a28b0b7c2400bc59aba4bcc0a76e971dadd19610d3ad38c768e124dc7","schema_version":"edge-lab-recorder.raw.v1","sequence":null,"source":"clob_market_ws"}
{"event_at":"2026-07-28T02:00:31.018000Z","event_fingerprint":"cb36b7263ecad0e963a71d0b5fd30ae49ccd11db3fe57900342b7dde74a97feb","payload":{"connection_id":"5d29200f65794d4d9ab6ef271f045a9b","event_at":"2026-07-28T02:00:31.018000Z","event_type":"best_bid_ask","frame_hash":"a297eb4b569c82915dfe64b447a8a6e850892fc9a0d75da7202a009c2831867f","frame_index":0,"kind":"data","monotonic_ns":306016101888333,"payload":{"asset_id":"20893381255801015515826997628594359667013752732428989472914000440642900266717","best_ask":"0.49","best_bid":"0.48","event_type":"best_bid_ask","market":"0xda6f0e0e93fc8469e0159a166028d017bddbc162b86f66bac90391379603d962","spread":"0.01","timestamp":"1785204031018"},"payload_hash":"fa7080ae69f0528f8ce5eee81b50e2d4adea95256e344029cb45180dc1683869","raw_frame":"{\"market\":\"0xda6f0e0e93fc8469e0159a166028d017bddbc162b86f66bac90391379603d962\", \"asset_id\":\"20893381255801015515826997628594359667013752732428989472914000440642900266717\", \"best_bid\":\"0.48\", \"best_ask\":\"0.49\", \"spread\":\"0.01\", \"timestamp\":\"1785204031018\", \"event_type\":\"best_bid_ask\"}","received_at":"2026-07-28T02:00:33.096302Z","schema_version":"clob-market-ws.best_bid_ask.v1","sequence":null,"server_hash":null,"server_timestamp":"1785204031018","session_id":"d2757dd6dad94f3b9fe67e8dbf1adc37","source":"clob_market_ws"},"received_at":"2026-07-28T02:00:33.096302Z","record_id":"a87ce676c76e431cf3f1aa4aa3e19b45afd32925fb7005264160c286486bb8d8","schema_fingerprint":"8488399f31b0337811b13b266be932db7062827c2470b78bd8e9e99bab51d17d","schema_version":"edge-lab-recorder.raw.v1","sequence":null,"source":"clob_market_ws"}
{"event_at":"2026-07-28T02:00:31.018000Z","event_fingerprint":"75b6fa9804cb8b80c4753100013c0ac9092a28e0e02bbf501ecaada7b817749b","payload":{"connection_id":"5d29200f65794d4d9ab6ef271f045a9b","event_at":"2026-07-28T02:00:31.018000Z","event_type":"best_bid_ask","frame_hash":"b5f44797b98d51391b0398e521f5664bff9a7b283852f6b9916614ad2790c680","frame_index":0,"kind":"data","monotonic_ns":306016105914250,"payload":{"asset_id":"39272994714739463168905443499424551362424437245880253267329605556587274644733","best_ask":"0.52","best_bid":"0.51","event_type":"best_bid_ask","market":"0xda6f0e0e93fc8469e0159a166028d017bddbc162b86f66bac90391379603d962","spread":"0.01","timestamp":"1785204031018"},"payload_hash":"230a8f80c8ef314a3c66ee590d5aadee082c528be0745eba8146af8fe7c30c02","raw_frame":"{\"market\":\"0xda6f0e0e93fc8469e0159a166028d017bddbc162b86f66bac90391379603d962\", \"asset_id\":\"39272994714739463168905443499424551362424437245880253267329605556587274644733\", \"best_bid\":\"0.51\", \"best_ask\":\"0.52\", \"spread\":\"0.01\", \"timestamp\":\"1785204031018\", \"event_type\":\"best_bid_ask\"}","received_at":"2026-07-28T02:00:33.100328Z","schema_version":"clob-market-ws.best_bid_ask.v1","sequence":null,"server_hash":null,"server_timestamp":"1785204031018","session_id":"d2757dd6dad94f3b9fe67e8dbf1adc37","source":"clob_market_ws"},"received_at":"2026-07-28T02:00:33.100328Z","record_id":"60158deba3eeaeb2222da13344feffa34036583c95354f095c2ea11df2a4bd3b","schema_fingerprint":"8488399f31b0337811b13b266be932db7062827c2470b78bd8e9e99bab51d17d","schema_version":"edge-lab-recorder.raw.v1","sequence":null,"source":"clob_market_ws"}
{"event_at":"2026-07-28T02:00:31.018000Z","event_fingerprint":"329720e2c8205d0065fb9b6f95f9f1492efad3677b3c6a325d0db31d340f091c","payload":{"connection_id":"5d29200f65794d4d9ab6ef271f045a9b","event_at":"2026-07-28T02:00:31.018000Z","event_type":"price_change","frame_hash":"7ae9550009f5b90d285a83ea17e1c046731764b8659f98e41519914355b3c53a","frame_index":0,"kind":"data","monotonic_ns":306016111755000,"payload":{"event_type":"price_change","market":"0xda6f0e0e93fc8469e0159a166028d017bddbc162b86f66bac90391379603d962","price_changes":[{"asset_id":"20893381255801015515826997628594359667013752732428989472914000440642900266717","best_ask":"0.49","best_bid":"0.48","hash":"9ce4d54c7e3e8fdedde37f715246c0ff75edf7fc","price":"0.48","side":"BUY","size":"5"},{"asset_id":"39272994714739463168905443499424551362424437245880253267329605556587274644733","best_ask":"0.52","best_bid":"0.51","hash":"91717cf522bd88089759d50b135801ded0429483","price":"0.52","side":"SELL","size":"5"}],"timestamp":"1785204031018"},"payload_hash":"09ea91f56af4db36c7b8e2235b073a4813b2e648cbf81662d50d8f0429d494f9","raw_frame":"{\"market\":\"0xda6f0e0e93fc8469e0159a166028d017bddbc162b86f66bac90391379603d962\", \"price_changes\":[{\"asset_id\":\"20893381255801015515826997628594359667013752732428989472914000440642900266717\", \"price\":\"0.48\", \"size\":\"5\", \"side\":\"BUY\", \"hash\":\"9ce4d54c7e3e8fdedde37f715246c0ff75edf7fc\", \"best_bid\":\"0.48\", \"best_ask\":\"0.49\"}, {\"asset_id\":\"39272994714739463168905443499424551362424437245880253267329605556587274644733\", \"price\":\"0.52\", \"size\":\"5\", \"side\":\"SELL\", \"hash\":\"91717cf522bd88089759d50b135801ded0429483\", \"best_bid\":\"0.51\", \"best_ask\":\"0.52\"}], \"timestamp\":\"1785204031018\", \"event_type\":\"price_change\"}","received_at":"2026-07-28T02:00:33.106169Z","schema_version":"clob-market-ws.price_change.v1","sequence":null,"server_hash":null,"server_timestamp":"1785204031018","session_id":"d2757dd6dad94f3b9fe67e8dbf1adc37","source":"clob_market_ws"},"received_at":"2026-07-28T02:00:33.106169Z","record_id":"4700571b88c2d1de6c8d1f95213937d8b380bec4ea1954ef879f20067220dc67","schema_fingerprint":"4aa3821a28b0b7c2400bc59aba4bcc0a76e971dadd19610d3ad38c768e124dc7","schema_version":"edge-lab-recorder.raw.v1","sequence":null,"source":"clob_market_ws"}
{"event_at":"2026-07-28T02:00:31.019000Z","event_fingerprint":"7d050942ec631e2b7a6eba3348eb99ca3c1f16bcec5895fb64b8e42ce274cd4d","payload":{"connection_id":"5d29200f65794d4d9ab6ef271f045a9b","event_at":"2026-07-28T02:00:31.019000Z","event_type":"price_change","frame_hash":"6b6a42a97cf9bec5c9e25092120ef9634a9c314460f9f715cec0bc3499adc301","frame_index":0,"kind":"data","monotonic_ns":306016117321250,"payload":{"event_type":"price_change","market":"0xda6f0e0e93fc8469e0159a166028d017bddbc162b86f66bac90391379603d962","price_changes":[{"asset_id":"39272994714739463168905443499424551362424437245880253267329605556587274644733","best_ask":"0.52","best_bid":"0.51","hash":"a0264c6123c3beba7a225baf0bc9d973a3d5b57d","price":"0.52","side":"SELL","size":"10"},{"asset_id":"20893381255801015515826997628594359667013752732428989472914000440642900266717","best_ask":"0.49","best_bid":"0.48","hash":"6e3d2de94c1e8a4fbea2853b507af486ff1ee98c","price":"0.48","side":"BUY","size":"10"}],"timestamp":"1785204031019"},"payload_hash":"f604d527787ea46b5162ccb738b61328a66ac1e0ae7210e76ea5670c1915fde5","raw_frame":"{\"market\":\"0xda6f0e0e93fc8469e0159a166028d017bddbc162b86f66bac90391379603d962\", \"price_changes\":[{\"asset_id\":\"39272994714739463168905443499424551362424437245880253267329605556587274644733\", \"price\":\"0.52\", \"size\":\"10\", \"side\":\"SELL\", \"hash\":\"a0264c6123c3beba7a225baf0bc9d973a3d5b57d\", \"best_bid\":\"0.51\", \"best_ask\":\"0.52\"}, {\"asset_id\":\"20893381255801015515826997628594359667013752732428989472914000440642900266717\", \"price\":\"0.48\", \"size\":\"10\", \"side\":\"BUY\", \"hash\":\"6e3d2de94c1e8a4fbea2853b507af486ff1ee98c\", \"best_bid\":\"0.48\", \"best_ask\":\"0.49\"}], \"timestamp\":\"1785204031019\", \"event_type\":\"price_change\"}","received_at":"2026-07-28T02:00:33.111736Z","schema_version":"clob-market-ws.price_change.v1","sequence":null,"server_hash":null,"server_timestamp":"1785204031019","session_id":"d2757dd6dad94f3b9fe67e8dbf1adc37","source":"clob_market_ws"},"received_at":"2026-07-28T02:00:33.111736Z","record_id":"f3d02aae174352975df970baa730a595f204b166a84b4e65ee54703440a67663","schema_fingerprint":"4aa3821a28b0b7c2400bc59aba4bcc0a76e971dadd19610d3ad38c768e124dc7","schema_version":"edge-lab-recorder.raw.v1","sequence":null,"source":"clob_market_ws"}
{"event_at":"2026-07-28T02:00:31.020000Z","event_fingerprint":"41289d624a84047c54e12607a4eb6b53666175981db036c48486e97ddd440bca","payload":{"connection_id":"5d29200f65794d4d9ab6ef271f045a9b","event_at":"2026-07-28T02:00:31.020000Z","event_type":"price_change","frame_hash":"3e4d6e6472ee818297cae816ce43374b01947ea27e3bb0183df82becfeb3633f","frame_index":0,"kind":"data","monotonic_ns":306016122992916,"payload":{"event_type":"price_change","market":"0xda6f0e0e93fc8469e0159a166028d017bddbc162b86f66bac90391379603d962","price_changes":[{"asset_id":"39272994714739463168905443499424551362424437245880253267329605556587274644733","best_ask":"0.52","best_bid":"0.51","hash":"32293c1de3070ebd05969cd1d8587cfb900480a9","price":"0.03","side":"BUY","size":"1201.43"},{"asset_id":"20893381255801015515826997628594359667013752732428989472914000440642900266717","best_ask":"0.49","best_bid":"0.48","hash":"00c66f707966c9a87ad25a4571c8931f7040c615","price":"0.97","side":"SELL","size":"1201.43"}],"timestamp":"1785204031020"},"payload_hash":"0d098599195dfc02f57810da7e1bc09bb6c4cd5ae0f086b2c14ffd13fd7a160f","raw_frame":"{\"market\":\"0xda6f0e0e93fc8469e0159a166028d017bddbc162b86f66bac90391379603d962\", \"price_changes\":[{\"asset_id\":\"39272994714739463168905443499424551362424437245880253267329605556587274644733\", \"price\":\"0.03\", \"size\":\"1201.43\", \"side\":\"BUY\", \"hash\":\"32293c1de3070ebd05969cd1d8587cfb900480a9\", \"best_bid\":\"0.51\", \"best_ask\":\"0.52\"}, {\"asset_id\":\"20893381255801015515826997628594359667013752732428989472914000440642900266717\", \"price\":\"0.97\", \"size\":\"1201.43\", \"side\":\"SELL\", \"hash\":\"00c66f707966c9a87ad25a4571c8931f7040c615\", \"best_bid\":\"0.48\", \"best_ask\":\"0.49\"}], \"timestamp\":\"1785204031020\", \"event_type\":\"price_change\"}","received_at":"2026-07-28T02:00:33.117409Z","schema_version":"clob-market-ws.price_change.v1","sequence":null,"server_hash":null,"server_timestamp":"1785204031020","session_id":"d2757dd6dad94f3b9fe67e8dbf1adc37","source":"clob_market_ws"},"received_at":"2026-07-28T02:00:33.117409Z","record_id":"de6293d08123e906e14a8914112d999268163563a732fb3518f455772a1eb8db","schema_fingerprint":"4aa3821a28b0b7c2400bc59aba4bcc0a76e971dadd19610d3ad38c768e124dc7","schema_version":"edge-lab-recorder.raw.v1","sequence":null,"source":"clob_market_ws"}
{"event_at":"2026-07-28T02:00:31.022000Z","event_fingerprint":"5448b776ab165ef158191fe7880f960d1dbe627bec56946265fbebea7c9e7f22","payload":{"connection_id":"5d29200f65794d4d9ab6ef271f045a9b","event_at":"2026-07-28T02:00:31.022000Z","event_type":"price_change","frame_hash":"f6deaca8246741a1a516087b72b94b409e46f39eb00be4955af36ff559cd5059","frame_index":0,"kind":"data","monotonic_ns":306016129548875,"payload":{"event_type":"price_change","market":"0xda6f0e0e93fc8469e0159a166028d017bddbc162b86f66bac90391379603d962","price_changes":[{"asset_id":"20893381255801015515826997628594359667013752732428989472914000440642900266717","best_ask":"0.49","best_bid":"0.48","hash":"149787f25b9a09f567acc2572c8b018743c17eba","price":"0.01","side":"BUY","size":"7888.02"},{"asset_id":"39272994714739463168905443499424551362424437245880253267329605556587274644733","best_ask":"0.52","best_bid":"0.51","hash":"8c10cbb4a799ca8cbad779f3f1a9cfd59a71cfb8","price":"0.99","side":"SELL","size":"7888.02"}],"timestamp":"1785204031022"},"payload_hash":"5279a7f998b3ef846816e5a15dc395cbff4170615e12698712c969cba56b718d","raw_frame":"{\"market\":\"0xda6f0e0e93fc8469e0159a166028d017bddbc162b86f66bac90391379603d962\", \"price_changes\":[{\"asset_id\":\"20893381255801015515826997628594359667013752732428989472914000440642900266717\", \"price\":\"0.01\", \"size\":\"7888.02\", \"side\":\"BUY\", \"hash\":\"149787f25b9a09f567acc2572c8b018743c17eba\", \"best_bid\":\"0.48\", \"best_ask\":\"0.49\"}, {\"asset_id\":\"39272994714739463168905443499424551362424437245880253267329605556587274644733\", \"price\":\"0.99\", \"size\":\"7888.02\", \"side\":\"SELL\", \"hash\":\"8c10cbb4a799ca8cbad779f3f1a9cfd59a71cfb8\", \"best_bid\":\"0.51\", \"best_ask\":\"0.52\"}], \"timestamp\":\"1785204031022\", \"event_type\":\"price_change\"}","received_at":"2026-07-28T02:00:33.123965Z","schema_version":"clob-market-ws.price_change.v1","sequence":null,"server_hash":null,"server_timestamp":"1785204031022","session_id":"d2757dd6dad94f3b9fe67e8dbf1adc37","source":"clob_market_ws"},"received_at":"2026-07-28T02:00:33.123965Z","record_id":"c1891d55f407f0f9baf58f340d5edc0e9395d6f4d90f9f73e0aed5e48924f179","schema_fingerprint":"4aa3821a28b0b7c2400bc59aba4bcc0a76e971dadd19610d3ad38c768e124dc7","schema_version":"edge-lab-recorder.raw.v1","sequence":null,"source":"clob_market_ws"}
{"event_at":"2026-07-28T02:00:31.037000Z","event_fingerprint":"47e641c12f2536f60c445887ef632aae3a38c839d69677140e26587cfb3d1f30","payload":{"connection_id":"5d29200f65794d4d9ab6ef271f045a9b","event_at":"2026-07-28T02:00:31.037000Z","event_type":"price_change","frame_hash":"d95f363b28616202527d4a04ba7e8f0e4356a58c3bb19021274d41a945eb7ac3","frame_index":0,"kind":"data","monotonic_ns":306016134536583,"payload":{"event_type":"price_change","market":"0xda6f0e0e93fc8469e0159a166028d017bddbc162b86f66bac90391379603d962","price_changes":[{"asset_id":"20893381255801015515826997628594359667013752732428989472914000440642900266717","best_ask":"0.49","best_bid":"0.48","hash":"3bc70f373c88d76997b6ff2c26342ef59a21f494","price":"0.48","side":"BUY","size":"5"},{"asset_id":"39272994714739463168905443499424551362424437245880253267329605556587274644733","best_ask":"0.52","best_bid":"0.51","hash":"048f4c064f05e80b9b7bd0b62d45ba7344c5fa09","price":"0.52","side":"SELL","size":"5"}],"timestamp":"1785204031037"},"payload_hash":"a6f7a95b6ec99aac1159488ab23ed8487e2aae8e28d28029eb207c971e68fed9","raw_frame":"{\"market\":\"0xda6f0e0e93fc8469e0159a166028d017bddbc162b86f66bac90391379603d962\", \"price_changes\":[{\"asset_id\":\"20893381255801015515826997628594359667013752732428989472914000440642900266717\", \"price\":\"0.48\", \"size\":\"5\", \"side\":\"BUY\", \"hash\":\"3bc70f373c88d76997b6ff2c26342ef59a21f494\", \"best_bid\":\"0.48\", \"best_ask\":\"0.49\"}, {\"asset_id\":\"39272994714739463168905443499424551362424437245880253267329605556587274644733\", \"price\":\"0.52\", \"size\":\"5\", \"side\":\"SELL\", \"hash\":\"048f4c064f05e80b9b7bd0b62d45ba7344c5fa09\", \"best_bid\":\"0.51\", \"best_ask\":\"0.52\"}], \"timestamp\":\"1785204031037\", \"event_type\":\"price_change\"}","received_at":"2026-07-28T02:00:33.128954Z","schema_version":"clob-market-ws.price_change.v1","sequence":null,"server_hash":null,"server_timestamp":"1785204031037","session_id":"d2757dd6dad94f3b9fe67e8dbf1adc37","source":"clob_market_ws"},"received_at":"2026-07-28T02:00:33.128954Z","record_id":"ca784884a3f586809b44f6c095923ada1233b220ea5a390300e87809c6f2f5b4","schema_fingerprint":"4aa3821a28b0b7c2400bc59aba4bcc0a76e971dadd19610d3ad38c768e124dc7","schema_version":"edge-lab-recorder.raw.v1","sequence":null,"source":"clob_market_ws"}
{"event_at":"2026-07-28T02:00:31.038000Z","event_fingerprint":"2e4a9005f37b534b97bac2241bcfcaddbe510e3361dc1f32110d7f316a6e2e31","payload":{"connection_id":"5d29200f65794d4d9ab6ef271f045a9b","event_at":"2026-07-28T02:00:31.038000Z","event_type":"best_bid_ask","frame_hash":"a2dd3c3b0d1f05461da6d2acf711a829e7c89d8b7ad0deb6ca978387b42f89c2","frame_index":0,"kind":"data","monotonic_ns":306016140155125,"payload":{"asset_id":"20893381255801015515826997628594359667013752732428989472914000440642900266717","best_ask":"0.49","best_bid":"0.47","event_type":"best_bid_ask","market":"0xda6f0e0e93fc8469e0159a166028d017bddbc162b86f66bac90391379603d962","spread":"0.02","timestamp":"1785204031038"},"payload_hash":"929a9629e2f40fec57bad9e4b51f6571d1e8f0a2bc55a1ffe9d717d49380fd3f","raw_frame":"{\"market\":\"0xda6f0e0e93fc8469e0159a166028d017bddbc162b86f66bac90391379603d962\", \"asset_id\":\"20893381255801015515826997628594359667013752732428989472914000440642900266717\", \"best_bid\":\"0.47\", \"best_ask\":\"0.49\", \"spread\":\"0.02\", \"timestamp\":\"1785204031038\", \"event_type\":\"best_bid_ask\"}","received_at":"2026-07-28T02:00:33.134573Z","schema_version":"clob-market-ws.best_bid_ask.v1","sequence":null,"server_hash":null,"server_timestamp":"1785204031038","session_id":"d2757dd6dad94f3b9fe67e8dbf1adc37","source":"clob_market_ws"},"received_at":"2026-07-28T02:00:33.134573Z","record_id":"8c176281cf16538e75c525c7aec358e566c8b82076f3a4f41be95039c8fd6f0b","schema_fingerprint":"8488399f31b0337811b13b266be932db7062827c2470b78bd8e9e99bab51d17d","schema_version":"edge-lab-recorder.raw.v1","sequence":null,"source":"clob_market_ws"}
{"event_at":"2026-07-28T02:00:31.038000Z","event_fingerprint":"891e07db333793bc7003fb2158783aa78c4eb0ab917bbc26c58aaf0103c22926","payload":{"connection_id":"5d29200f65794d4d9ab6ef271f045a9b","event_at":"2026-07-28T02:00:31.038000Z","event_type":"best_bid_ask","frame_hash":"22521c7e483af7b7f3fdf319b75aba93153afce776be53a7ce43e465b9ce7096","frame_index":0,"kind":"data","monotonic_ns":306016145150833,"payload":{"asset_id":"39272994714739463168905443499424551362424437245880253267329605556587274644733","best_ask":"0.53","best_bid":"0.51","event_type":"best_bid_ask","market":"0xda6f0e0e93fc8469e0159a166028d017bddbc162b86f66bac90391379603d962","spread":"0.02","timestamp":"1785204031038"},"payload_hash":"51aa27c2a54cd529778542776e054b83d7773fd323abd95cba4415b396f969af","raw_frame":"{\"market\":\"0xda6f0e0e93fc8469e0159a166028d017bddbc162b86f66bac90391379603d962\", \"asset_id\":\"39272994714739463168905443499424551362424437245880253267329605556587274644733\", \"best_bid\":\"0.51\", \"best_ask\":\"0.53\", \"spread\":\"0.02\", \"timestamp\":\"1785204031038\", \"event_type\":\"best_bid_ask\"}","received_at":"2026-07-28T02:00:33.139570Z","schema_version":"clob-market-ws.best_bid_ask.v1","sequence":null,"server_hash":null,"server_timestamp":"1785204031038","session_id":"d2757dd6dad94f3b9fe67e8dbf1adc37","source":"clob_market_ws"},"received_at":"2026-07-28T02:00:33.139570Z","record_id":"cfd0510ebb2df93327e894aa730eaa01351b97e7bf91499f85d087d6ded2bb6e","schema_fingerprint":"8488399f31b0337811b13b266be932db7062827c2470b78bd8e9e99bab51d17d","schema_version":"edge-lab-recorder.raw.v1","sequence":null,"source":"clob_market_ws"}
{"event_at":"2026-07-28T02:00:31.038000Z","event_fingerprint":"aa7eda39d47e1fc13ce1d918b3d8893e5dd88562279c2ade2cd0a20f6d4da292","payload":{"connection_id":"5d29200f65794d4d9ab6ef271f045a9b","event_at":"2026-07-28T02:00:31.038000Z","event_type":"price_change","frame_hash":"e0e84bca0ed1b95be5f81cd78bba9eb3e044ab617dfea0daf51d7fa11d04a67c","frame_index":0,"kind":"data","monotonic_ns":306016149817250,"payload":{"event_type":"price_change","market":"0xda6f0e0e93fc8469e0159a166028d017bddbc162b86f66bac90391379603d962","price_changes":[{"asset_id":"39272994714739463168905443499424551362424437245880253267329605556587274644733","best_ask":"0.53","best_bid":"0.51","hash":"68031012149d1c0858c7af4afbdd31c312b8b6e4","price":"0.52","side":"SELL","size":"0"},{"asset_id":"20893381255801015515826997628594359667013752732428989472914000440642900266717","best_ask":"0.49","best_bid":"0.47","hash":"ebf687994646a3c3a5bfe4b7cd324ffcdb05a8df","price":"0.48","side":"BUY","size":"0"}],"timestamp":"1785204031038"},"payload_hash":"59bd008ebbd5cdffaf86cb62007e88b5dace5634e955571836fb3665413560eb","raw_frame":"{\"market\":\"0xda6f0e0e93fc8469e0159a166028d017bddbc162b86f66bac90391379603d962\", \"price_changes\":[{\"asset_id\":\"39272994714739463168905443499424551362424437245880253267329605556587274644733\", \"price\":\"0.52\", \"size\":\"0\", \"side\":\"SELL\", \"hash\":\"68031012149d1c0858c7af4afbdd31c312b8b6e4\", \"best_bid\":\"0.51\", \"best_ask\":\"0.53\"}, {\"asset_id\":\"20893381255801015515826997628594359667013752732428989472914000440642900266717\", \"price\":\"0.48\", \"size\":\"0\", \"side\":\"BUY\", \"hash\":\"ebf687994646a3c3a5bfe4b7cd324ffcdb05a8df\", \"best_bid\":\"0.47\", \"best_ask\":\"0.49\"}], \"timestamp\":\"1785204031038\", \"event_type\":\"price_change\"}","received_at":"2026-07-28T02:00:33.144237Z","schema_version":"clob-market-ws.price_change.v1","sequence":null,"server_hash":null,"server_timestamp":"1785204031038","session_id":"d2757dd6dad94f3b9fe67e8dbf1adc37","source":"clob_market_ws"},"received_at":"2026-07-28T02:00:33.144237Z","record_id":"83a7c58135a469985988f334b96e76c8cb047541c3af1fc28996083d3b32ade1","schema_fingerprint":"4aa3821a28b0b7c2400bc59aba4bcc0a76e971dadd19610d3ad38c768e124dc7","schema_version":"edge-lab-recorder.raw.v1","sequence":null,"source":"clob_market_ws"}
{"event_at":"2026-07-28T02:00:31.046000Z","event_fingerprint":"7487efdadebc9a453e8d9bada0d9f24bee13a26dfae21d9ebdac41a3bdedcacb","payload":{"connection_id":"5d29200f65794d4d9ab6ef271f045a9b","event_at":"2026-07-28T02:00:31.046000Z","event_type":"price_change","frame_hash":"b56aac35724c1b6a5af0ad2f7434795c80d2d47f54f4dfc30279563b769addfb","frame_index":0,"kind":"data","monotonic_ns":306016156813375,"payload":{"event_type":"price_change","market":"0xda6f0e0e93fc8469e0159a166028d017bddbc162b86f66bac90391379603d962","price_changes":[{"asset_id":"39272994714739463168905443499424551362424437245880253267329605556587274644733","best_ask":"0.53","best_bid":"0.51","hash":"61babf909fd60bf705befb65f3b305b90f335164","price":"0.03","side":"BUY","size":"1196.43"},{"asset_id":"20893381255801015515826997628594359667013752732428989472914000440642900266717","best_ask":"0.49","best_bid":"0.47","hash":"5c2563367035819759e98497bf66c360c18b741e","price":"0.97","side":"SELL","size":"1196.43"}],"timestamp":"1785204031046"},"payload_hash":"aedd73c1ba0df1ca75e934fc58342e1918d86ee9140189a69e47ceb377c882fa","raw_frame":"{\"market\":\"0xda6f0e0e93fc8469e0159a166028d017bddbc162b86f66bac90391379603d962\", \"price_changes\":[{\"asset_id\":\"39272994714739463168905443499424551362424437245880253267329605556587274644733\", \"price\":\"0.03\", \"size\":\"1196.43\", \"side\":\"BUY\", \"hash\":\"61babf909fd60bf705befb65f3b305b90f335164\", \"best_bid\":\"0.51\", \"best_ask\":\"0.53\"}, {\"asset_id\":\"20893381255801015515826997628594359667013752732428989472914000440642900266717\", \"price\":\"0.97\", \"size\":\"1196.43\", \"side\":\"SELL\", \"hash\":\"5c2563367035819759e98497bf66c360c18b741e\", \"best_bid\":\"0.47\", \"best_ask\":\"0.49\"}], \"timestamp\":\"1785204031046\", \"event_type\":\"price_change\"}","received_at":"2026-07-28T02:00:33.151234Z","schema_version":"clob-market-ws.price_change.v1","sequence":null,"server_hash":null,"server_timestamp":"1785204031046","session_id":"d2757dd6dad94f3b9fe67e8dbf1adc37","source":"clob_market_ws"},"received_at":"2026-07-28T02:00:33.151234Z","record_id":"6598364d5bac8fb48b320cd53d719ff5a362db4946634c2108c204fc0df28118","schema_fingerprint":"4aa3821a28b0b7c2400bc59aba4bcc0a76e971dadd19610d3ad38c768e124dc7","schema_version":"edge-lab-recorder.raw.v1","sequence":null,"source":"clob_market_ws"}
{"event_at":"2026-07-28T02:00:31.046000Z","event_fingerprint":"d31d1f39f12ccef495fe79593734180d78fa50a86d6b4a848edbce2160d1c6d8","payload":{"connection_id":"5d29200f65794d4d9ab6ef271f045a9b","event_at":"2026-07-28T02:00:31.046000Z","event_type":"price_change","frame_hash":"14cd2872ff0e866902e174d03e4daf5f23e6a6a3dbb17af933d47058dfc9920f","frame_index":0,"kind":"data","monotonic_ns":306016162733875,"payload":{"event_type":"price_change","market":"0xda6f0e0e93fc8469e0159a166028d017bddbc162b86f66bac90391379603d962","price_changes":[{"asset_id":"39272994714739463168905443499424551362424437245880253267329605556587274644733","best_ask":"0.53","best_bid":"0.51","hash":"57339065b6c21ab28e8023969a37a2c6aed88eee","price":"0.51","side":"BUY","size":"102.2"},{"asset_id":"20893381255801015515826997628594359667013752732428989472914000440642900266717","best_ask":"0.49","best_bid":"0.47","hash":"98870bf1e8be7ea839c341777c522dba9139cc6e","price":"0.49","side":"SELL","size":"102.2"}],"timestamp":"1785204031046"},"payload_hash":"5d6109ade73a1e82640a6105df4f58fb8cfe2a7748c7f83ae4035daaeea5616c","raw_frame":"{\"market\":\"0xda6f0e0e93fc8469e0159a166028d017bddbc162b86f66bac90391379603d962\", \"price_changes\":[{\"asset_id\":\"39272994714739463168905443499424551362424437245880253267329605556587274644733\", \"price\":\"0.51\", \"size\":\"102.2\", \"side\":\"BUY\", \"hash\":\"57339065b6c21ab28e8023969a37a2c6aed88eee\", \"best_bid\":\"0.51\", \"best_ask\":\"0.53\"}, {\"asset_id\":\"20893381255801015515826997628594359667013752732428989472914000440642900266717\", \"price\":\"0.49\", \"size\":\"102.2\", \"side\":\"SELL\", \"hash\":\"98870bf1e8be7ea839c341777c522dba9139cc6e\", \"best_bid\":\"0.47\", \"best_ask\":\"0.49\"}], \"timestamp\":\"1785204031046\", \"event_type\":\"price_change\"}","received_at":"2026-07-28T02:00:33.157155Z","schema_version":"clob-market-ws.price_change.v1","sequence":null,"server_hash":null,"server_timestamp":"1785204031046","session_id":"d2757dd6dad94f3b9fe67e8dbf1adc37","source":"clob_market_ws"},"received_at":"2026-07-28T02:00:33.157155Z","record_id":"d35b39670989c954f8749345363b45b01a61af5d9c3e314d195254cffd6b4848","schema_fingerprint":"4aa3821a28b0b7c2400bc59aba4bcc0a76e971dadd19610d3ad38c768e124dc7","schema_version":"edge-lab-recorder.raw.v1","sequence":null,"source":"clob_market_ws"}
{"event_at":"2026-07-28T02:00:31.052000Z","event_fingerprint":"1ffd6b2837eeb4c9cac56c37e625ee07509d54e5fb61cb02f5c177d7009386ed","payload":{"connection_id":"5d29200f65794d4d9ab6ef271f045a9b","event_at":"2026-07-28T02:00:31.052000Z","event_type":"price_change","frame_hash":"673e03560321caa121208bc88db0751ccd068e41465746a8088473d6c2dfea73","frame_index":0,"kind":"data","monotonic_ns":306016167779916,"payload":{"event_type":"price_change","market":"0xda6f0e0e93fc8469e0159a166028d017bddbc162b86f66bac90391379603d962","price_changes":[{"asset_id":"20893381255801015515826997628594359667013752732428989472914000440642900266717","best_ask":"0.49","best_bid":"0.47","hash":"14e7a9cb8f6fc6bc9f87b94ace12f4e93200a78b","price":"0.01","side":"BUY","size":"7883.02"},{"asset_id":"39272994714739463168905443499424551362424437245880253267329605556587274644733","best_ask":"0.53","best_bid":"0.51","hash":"5a0c8e9350b153e78653c2100799b2d7501a20bb","price":"0.99","side":"SELL","size":"7883.02"}],"timestamp":"1785204031052"},"payload_hash":"951481f8ad1e5e3701425e5a540690701c4d96d101207fc86f2159cc183ec273","raw_frame":"{\"market\":\"0xda6f0e0e93fc8469e0159a166028d017bddbc162b86f66bac90391379603d962\", \"price_changes\":[{\"asset_id\":\"20893381255801015515826997628594359667013752732428989472914000440642900266717\", \"price\":\"0.01\", \"size\":\"7883.02\", \"side\":\"BUY\", \"hash\":\"14e7a9cb8f6fc6bc9f87b94ace12f4e93200a78b\", \"best_bid\":\"0.47\", \"best_ask\":\"0.49\"}, {\"asset_id\":\"39272994714739463168905443499424551362424437245880253267329605556587274644733\", \"price\":\"0.99\", \"size\":\"7883.02\", \"side\":\"SELL\", \"hash\":\"5a0c8e9350b153e78653c2100799b2d7501a20bb\", \"best_bid\":\"0.51\", \"best_ask\":\"0.53\"}], \"timestamp\":\"1785204031052\", \"event_type\":\"price_change\"}","received_at":"2026-07-28T02:00:33.162199Z","schema_version":"clob-market-ws.price_change.v1","sequence":null,"server_hash":null,"server_timestamp":"1785204031052","session_id":"d2757dd6dad94f3b9fe67e8dbf1adc37","source":"clob_market_ws"},"received_at":"2026-07-28T02:00:33.162199Z","record_id":"a0223d650fd8f4e3673b37775404e775cae84dfbca2e53dda3905e155186baaf","schema_fingerprint":"4aa3821a28b0b7c2400bc59aba4bcc0a76e971dadd19610d3ad38c768e124dc7","schema_version":"edge-lab-recorder.raw.v1","sequence":null,"source":"clob_market_ws"}
{"event_at":"2026-07-28T02:00:31.069000Z","event_fingerprint":"ed6545c4252a99f0f4def016c9497bea09db4d2785aa7143d105c3c5aba73569","payload":{"connection_id":"5d29200f65794d4d9ab6ef271f045a9b","event_at":"2026-07-28T02:00:31.069000Z","event_type":"best_bid_ask","frame_hash":"6b1890d60a01b1ce1ef50d520b22005db68a38e4838fd513b558dc4b11992148","frame_index":0,"kind":"data","monotonic_ns":306016171987166,"payload":{"asset_id":"20893381255801015515826997628594359667013752732428989472914000440642900266717","best_ask":"0.49","best_bid":"0.48","event_type":"best_bid_ask","market":"0xda6f0e0e93fc8469e0159a166028d017bddbc162b86f66bac90391379603d962","spread":"0.01","timestamp":"1785204031069"},"payload_hash":"105540d70ed2a224fa6759cdd16dd6faa6151ff0398b6210bc96a2a01ea03b80","raw_frame":"{\"market\":\"0xda6f0e0e93fc8469e0159a166028d017bddbc162b86f66bac90391379603d962\", \"asset_id\":\"20893381255801015515826997628594359667013752732428989472914000440642900266717\", \"best_bid\":\"0.48\", \"best_ask\":\"0.49\", \"spread\":\"0.01\", \"timestamp\":\"1785204031069\", \"event_type\":\"best_bid_ask\"}","received_at":"2026-07-28T02:00:33.166410Z","schema_version":"clob-market-ws.best_bid_ask.v1","sequence":null,"server_hash":null,"server_timestamp":"1785204031069","session_id":"d2757dd6dad94f3b9fe67e8dbf1adc37","source":"clob_market_ws"},"received_at":"2026-07-28T02:00:33.166410Z","record_id":"27c2e6c07aec900e3f009cb1a8d9b59dea91a8e2e645b275591c3b633a5ba4bb","schema_fingerprint":"8488399f31b0337811b13b266be932db7062827c2470b78bd8e9e99bab51d17d","schema_version":"edge-lab-recorder.raw.v1","sequence":null,"source":"clob_market_ws"}
{"event_at":"2026-07-28T02:00:31.069000Z","event_fingerprint":"b3cb2fb150b7d779885623ec9f1984ab542619183666996215e9fc0485c998eb","payload":{"connection_id":"5d29200f65794d4d9ab6ef271f045a9b","event_at":"2026-07-28T02:00:31.069000Z","event_type":"best_bid_ask","frame_hash":"74f655ea703e1a0f359297bd5061d673743cced3aa0040fe23f1e87da4dcaac0","frame_index":0,"kind":"data","monotonic_ns":306016175165333,"payload":{"asset_id":"39272994714739463168905443499424551362424437245880253267329605556587274644733","best_ask":"0.52","best_bid":"0.51","event_type":"best_bid_ask","market":"0xda6f0e0e93fc8469e0159a166028d017bddbc162b86f66bac90391379603d962","spread":"0.01","timestamp":"1785204031069"},"payload_hash":"6ff65a9c54df6e3e43c5bc08e0b02ea7ef01f424ecc41b76ff86406f3d67500a","raw_frame":"{\"market\":\"0xda6f0e0e93fc8469e0159a166028d017bddbc162b86f66bac90391379603d962\", \"asset_id\":\"39272994714739463168905443499424551362424437245880253267329605556587274644733\", \"best_bid\":\"0.51\", \"best_ask\":\"0.52\", \"spread\":\"0.01\", \"timestamp\":\"1785204031069\", \"event_type\":\"best_bid_ask\"}","received_at":"2026-07-28T02:00:33.169588Z","schema_version":"clob-market-ws.best_bid_ask.v1","sequence":null,"server_hash":null,"server_timestamp":"1785204031069","session_id":"d2757dd6dad94f3b9fe67e8dbf1adc37","source":"clob_market_ws"},"received_at":"2026-07-28T02:00:33.169588Z","record_id":"dd8c006ba69f937819d3361cdb8b7df2936eea8624063bed98ad33ed74fa148c","schema_fingerprint":"8488399f31b0337811b13b266be932db7062827c2470b78bd8e9e99bab51d17d","schema_version":"edge-lab-recorder.raw.v1","sequence":null,"source":"clob_market_ws"}
{"event_at":"2026-07-28T02:00:31.069000Z","event_fingerprint":"65acf449afbaf5c83ef8d70d0c5e82968f9dd1a9e42f5b313e4b5389d9927886","payload":{"connection_id":"5d29200f65794d4d9ab6ef271f045a9b","event_at":"2026-07-28T02:00:31.069000Z","event_type":"price_change","frame_hash":"ead898e1c4490e505f81d716e73e4f1d566581ac920314a72f51e0dcbbd0988f","frame_index":0,"kind":"data","monotonic_ns":306016179030166,"payload":{"event_type":"price_change","market":"0xda6f0e0e93fc8469e0159a166028d017bddbc162b86f66bac90391379603d962","price_changes":[{"asset_id":"39272994714739463168905443499424551362424437245880253267329605556587274644733","best_ask":"0.52","best_bid":"0.51","hash":"a42dc4a64d0e62be7e7ed24a319b32503e45702c","price":"0.52","side":"SELL","size":"5"},{"asset_id":"20893381255801015515826997628594359667013752732428989472914000440642900266717","best_ask":"0.49","best_bid":"0.48","hash":"862fe02d5e5e3502f090690b5a628bb527cc1300","price":"0.48","side":"BUY","size":"5"}],"timestamp":"1785204031069"},"payload_hash":"e44b0c9fb397c87f73bcc2ab27b5f0cf2e54df5f6090a51e6d3515b8bf3e3579","raw_frame":"{\"market\":\"0xda6f0e0e93fc8469e0159a166028d017bddbc162b86f66bac90391379603d962\", \"price_changes\":[{\"asset_id\":\"39272994714739463168905443499424551362424437245880253267329605556587274644733\", \"price\":\"0.52\", \"size\":\"5\", \"side\":\"SELL\", \"hash\":\"a42dc4a64d0e62be7e7ed24a319b32503e45702c\", \"best_bid\":\"0.51\", \"best_ask\":\"0.52\"}, {\"asset_id\":\"20893381255801015515826997628594359667013752732428989472914000440642900266717\", \"price\":\"0.48\", \"size\":\"5\", \"side\":\"BUY\", \"hash\":\"862fe02d5e5e3502f090690b5a628bb527cc1300\", \"best_bid\":\"0.48\", \"best_ask\":\"0.49\"}], \"timestamp\":\"1785204031069\", \"event_type\":\"price_change\"}","received_at":"2026-07-28T02:00:33.173454Z","schema_version":"clob-market-ws.price_change.v1","sequence":null,"server_hash":null,"server_timestamp":"1785204031069","session_id":"d2757dd6dad94f3b9fe67e8dbf1adc37","source":"clob_market_ws"},"received_at":"2026-07-28T02:00:33.173454Z","record_id":"ff090a4b6c0c9bb5907f11978e44078ef91d008a51ed24382bd197b71e8b99fd","schema_fingerprint":"4aa3821a28b0b7c2400bc59aba4bcc0a76e971dadd19610d3ad38c768e124dc7","schema_version":"edge-lab-recorder.raw.v1","sequence":null,"source":"clob_market_ws"}
{"event_at":"2026-07-28T02:00:31.070000Z","event_fingerprint":"7deadc0df90f8a1d5ee6678bb5eee7d65257c77428f899e64e89ff6f719d9ee3","payload":{"connection_id":"5d29200f65794d4d9ab6ef271f045a9b","event_at":"2026-07-28T02:00:31.070000Z","event_type":"price_change","frame_hash":"8a319f627cf229e7d1a4233b4eecb9133c5f1dc8908217f1872d9c1ff8f22292","frame_index":0,"kind":"data","monotonic_ns":306016183828958,"payload":{"event_type":"price_change","market":"0xda6f0e0e93fc8469e0159a166028d017bddbc162b86f66bac90391379603d962","price_changes":[{"asset_id":"39272994714739463168905443499424551362424437245880253267329605556587274644733","best_ask":"0.52","best_bid":"0.51","hash":"be98992ef23c19ac3d2a6386e4924c3e4d42e3b8","price":"0.46","side":"BUY","size":"103"},{"asset_id":"20893381255801015515826997628594359667013752732428989472914000440642900266717","best_ask":"0.49","best_bid":"0.48","hash":"467964ebd805fc54d9139e969d7e9d709a72f688","price":"0.54","side":"SELL","size":"103"}],"timestamp":"1785204031070"},"payload_hash":"2cc1da18fddfaadd7a97acf7fcf80ca6768586b8957a2419c4d22e85103ff53d","raw_frame":"{\"market\":\"0xda6f0e0e93fc8469e0159a166028d017bddbc162b86f66bac90391379603d962\", \"price_changes\":[{\"asset_id\":\"39272994714739463168905443499424551362424437245880253267329605556587274644733\", \"price\":\"0.46\", \"size\":\"103\", \"side\":\"BUY\", \"hash\":\"be98992ef23c19ac3d2a6386e4924c3e4d42e3b8\", \"best_bid\":\"0.51\", \"best_ask\":\"0.52\"}, {\"asset_id\":\"20893381255801015515826997628594359667013752732428989472914000440642900266717\", \"price\":\"0.54\", \"size\":\"103\", \"side\":\"SELL\", \"hash\":\"467964ebd805fc54d9139e969d7e9d709a72f688\", \"best_bid\":\"0.48\", \"best_ask\":\"0.49\"}], \"timestamp\":\"1785204031070\", \"event_type\":\"price_change\"}","received_at":"2026-07-28T02:00:33.178254Z","schema_version":"clob-market-ws.price_change.v1","sequence":null,"server_hash":null,"server_timestamp":"1785204031070","session_id":"d2757dd6dad94f3b9fe67e8dbf1adc37","source":"clob_market_ws"},"received_at":"2026-07-28T02:00:33.178254Z","record_id":"2348bc1748f14bf4b1761abcb96d8c262feaf355843c4f3653bd7ae6db61eb85","schema_fingerprint":"4aa3821a28b0b7c2400bc59aba4bcc0a76e971dadd19610d3ad38c768e124dc7","schema_version":"edge-lab-recorder.raw.v1","sequence":null,"source":"clob_market_ws"}
{"event_at":"2026-07-28T02:00:31.071000Z","event_fingerprint":"e3be83a7bfa18996a6b76f39e20ecd81fb120568c925f7d8613fc3c05d587544","payload":{"connection_id":"5d29200f65794d4d9ab6ef271f045a9b","event_at":"2026-07-28T02:00:31.071000Z","event_type":"price_change","frame_hash":"0b1779a363cb728f913db52fa2de1e95ff05b7f2bb4b2e26a44baf716470bbe9","frame_index":0,"kind":"data","monotonic_ns":306016189425916,"payload":{"event_type":"price_change","market":"0xda6f0e0e93fc8469e0159a166028d017bddbc162b86f66bac90391379603d962","price_changes":[{"asset_id":"20893381255801015515826997628594359667013752732428989472914000440642900266717","best_ask":"0.49","best_bid":"0.48","hash":"586f9ec9b21947d931dadfb163ee626be99d750e","price":"0.48","side":"BUY","size":"10"},{"asset_id":"39272994714739463168905443499424551362424437245880253267329605556587274644733","best_ask":"0.52","best_bid":"0.51","hash":"3505d4c6d687793d74d3fd6428ab056648100c33","price":"0.52","side":"SELL","size":"10"}],"timestamp":"1785204031071"},"payload_hash":"ddaceaffab74d83d1594bc0ff68d4abc357a45c49eac483b05927fd97ff8d736","raw_frame":"{\"market\":\"0xda6f0e0e93fc8469e0159a166028d017bddbc162b86f66bac90391379603d962\", \"price_changes\":[{\"asset_id\":\"20893381255801015515826997628594359667013752732428989472914000440642900266717\", \"price\":\"0.48\", \"size\":\"10\", \"side\":\"BUY\", \"hash\":\"586f9ec9b21947d931dadfb163ee626be99d750e\", \"best_bid\":\"0.48\", \"best_ask\":\"0.49\"}, {\"asset_id\":\"39272994714739463168905443499424551362424437245880253267329605556587274644733\", \"price\":\"0.52\", \"size\":\"10\", \"side\":\"SELL\", \"hash\":\"3505d4c6d687793d74d3fd6428ab056648100c33\", \"best_bid\":\"0.51\", \"best_ask\":\"0.52\"}], \"timestamp\":\"1785204031071\", \"event_type\":\"price_change\"}","received_at":"2026-07-28T02:00:33.183849Z","schema_version":"clob-market-ws.price_change.v1","sequence":null,"server_hash":null,"server_timestamp":"1785204031071","session_id":"d2757dd6dad94f3b9fe67e8dbf1adc37","source":"clob_market_ws"},"received_at":"2026-07-28T02:00:33.183849Z","record_id":"f9ecb3f07fd2d1744a58492941fb7685b76041ce5fc5dd3e92d7edf54abb4d72","schema_fingerprint":"4aa3821a28b0b7c2400bc59aba4bcc0a76e971dadd19610d3ad38c768e124dc7","schema_version":"edge-lab-recorder.raw.v1","sequence":null,"source":"clob_market_ws"}
{"event_at":"2026-07-28T02:00:31.074000Z","event_fingerprint":"ecffaf16a79e32ab04461b88c966dea38aca481c495ccbea742e111e7467390e","payload":{"connection_id":"5d29200f65794d4d9ab6ef271f045a9b","event_at":"2026-07-28T02:00:31.074000Z","event_type":"price_change","frame_hash":"731403bf692a065336a9821c324a87265d06b105f27e11b2c470f3b75e514aec","frame_index":0,"kind":"data","monotonic_ns":306016195222750,"payload":{"event_type":"price_change","market":"0xda6f0e0e93fc8469e0159a166028d017bddbc162b86f66bac90391379603d962","price_changes":[{"asset_id":"20893381255801015515826997628594359667013752732428989472914000440642900266717","best_ask":"0.49","best_bid":"0.48","hash":"4171a2802861a1eb76445d5638370431c3431e90","price":"0.48","side":"BUY","size":"15"},{"asset_id":"39272994714739463168905443499424551362424437245880253267329605556587274644733","best_ask":"0.52","best_bid":"0.51","hash":"a4427039519a076d01a539e846d4761cfa1d1974","price":"0.52","side":"SELL","size":"15"}],"timestamp":"1785204031074"},"payload_hash":"469efdebeadcc6d2a4c1309a72cd26f2fa10ad9c089d7041e72c90d91401bb08","raw_frame":"{\"market\":\"0xda6f0e0e93fc8469e0159a166028d017bddbc162b86f66bac90391379603d962\", \"price_changes\":[{\"asset_id\":\"20893381255801015515826997628594359667013752732428989472914000440642900266717\", \"price\":\"0.48\", \"size\":\"15\", \"side\":\"BUY\", \"hash\":\"4171a2802861a1eb76445d5638370431c3431e90\", \"best_bid\":\"0.48\", \"best_ask\":\"0.49\"}, {\"asset_id\":\"39272994714739463168905443499424551362424437245880253267329605556587274644733\", \"price\":\"0.52\", \"size\":\"15\", \"side\":\"SELL\", \"hash\":\"a4427039519a076d01a539e846d4761cfa1d1974\", \"best_bid\":\"0.51\", \"best_ask\":\"0.52\"}], \"timestamp\":\"1785204031074\", \"event_type\":\"price_change\"}","received_at":"2026-07-28T02:00:33.189648Z","schema_version":"clob-market-ws.price_change.v1","sequence":null,"server_hash":null,"server_timestamp":"1785204031074","session_id":"d2757dd6dad94f3b9fe67e8dbf1adc37","source":"clob_market_ws"},"received_at":"2026-07-28T02:00:33.189648Z","record_id":"528778c276310acd0bd2dfa9ac804221ea1de477628ef2588c43e0b9a93ce257","schema_fingerprint":"4aa3821a28b0b7c2400bc59aba4bcc0a76e971dadd19610d3ad38c768e124dc7","schema_version":"edge-lab-recorder.raw.v1","sequence":null,"source":"clob_market_ws"}
{"event_at":"2026-07-28T02:00:31.086000Z","event_fingerprint":"741fdd144cbbd691880779cb5237f14b1f80392523f9c0ffc015c052a911aaed","payload":{"connection_id":"5d29200f65794d4d9ab6ef271f045a9b","event_at":"2026-07-28T02:00:31.086000Z","event_type":"price_change","frame_hash":"d980f676f25cc8cf6cdc135d08a84c57c56aa4e4097f32141a69d4f730ef50b1","frame_index":0,"kind":"data","monotonic_ns":306016201744166,"payload":{"event_type":"price_change","market":"0xda6f0e0e93fc8469e0159a166028d017bddbc162b86f66bac90391379603d962","price_changes":[{"asset_id":"20893381255801015515826997628594359667013752732428989472914000440642900266717","best_ask":"0.49","best_bid":"0.48","hash":"3259fac5cd22391a6cccc91d5e675cdd5521ac45","price":"0.48","side":"BUY","size":"10"},{"asset_id":"39272994714739463168905443499424551362424437245880253267329605556587274644733","best_ask":"0.52","best_bid":"0.51","hash":"db3caf41bd432540477bda7073b0c22795d10ccd","price":"0.52","side":"SELL","size":"10"}],"timestamp":"1785204031086"},"payload_hash":"39f0e2b65face58d41920722299d0522db008d3d66a8cc4b6448a6c170972c1e","raw_frame":"{\"market\":\"0xda6f0e0e93fc8469e0159a166028d017bddbc162b86f66bac90391379603d962\", \"price_changes\":[{\"asset_id\":\"20893381255801015515826997628594359667013752732428989472914000440642900266717\", \"price\":\"0.48\", \"size\":\"10\", \"side\":\"BUY\", \"hash\":\"3259fac5cd22391a6cccc91d5e675cdd5521ac45\", \"best_bid\":\"0.48\", \"best_ask\":\"0.49\"}, {\"asset_id\":\"39272994714739463168905443499424551362424437245880253267329605556587274644733\", \"price\":\"0.52\", \"size\":\"10\", \"side\":\"SELL\", \"hash\":\"db3caf41bd432540477bda7073b0c22795d10ccd\", \"best_bid\":\"0.51\", \"best_ask\":\"0.52\"}], \"timestamp\":\"1785204031086\", \"event_type\":\"price_change\"}","received_at":"2026-07-28T02:00:33.196171Z","schema_version":"clob-market-ws.price_change.v1","sequence":null,"server_hash":null,"server_timestamp":"1785204031086","session_id":"d2757dd6dad94f3b9fe67e8dbf1adc37","source":"clob_market_ws"},"received_at":"2026-07-28T02:00:33.196171Z","record_id":"8df3d4c1afd2b0bff4f671844594cc07f43bfa08c279c2b6441c083d36a42cdb","schema_fingerprint":"4aa3821a28b0b7c2400bc59aba4bcc0a76e971dadd19610d3ad38c768e124dc7","schema_version":"edge-lab-recorder.raw.v1","sequence":null,"source":"clob_market_ws"}
{"event_at":"2026-07-28T02:00:31.087000Z","event_fingerprint":"2a3c5d6372fdb8e92ed35cea69ba88b41099d597d70974c97d3f932177c1fad0","payload":{"connection_id":"5d29200f65794d4d9ab6ef271f045a9b","event_at":"2026-07-28T02:00:31.087000Z","event_type":"price_change","frame_hash":"1ea480718532190b167e296f9844e3cf3bdb39c16c55a2685629d8e0594109d3","frame_index":0,"kind":"data","monotonic_ns":306016206840916,"payload":{"event_type":"price_change","market":"0xda6f0e0e93fc8469e0159a166028d017bddbc162b86f66bac90391379603d962","price_changes":[{"asset_id":"39272994714739463168905443499424551362424437245880253267329605556587274644733","best_ask":"0.52","best_bid":"0.51","hash":"149f119575352e2c80914737c6b5a4ebaec76660","price":"0.52","side":"SELL","size":"5"},{"asset_id":"20893381255801015515826997628594359667013752732428989472914000440642900266717","best_ask":"0.49","best_bid":"0.48","hash":"e662055b3c8caec1e41899621631e37f131c0c08","price":"0.48","side":"BUY","size":"5"}],"timestamp":"1785204031087"},"payload_hash":"fd72cef6a4e784d5e4393fadf39d4f2a2956e0e65319451b2b602e121e0518db","raw_frame":"{\"market\":\"0xda6f0e0e93fc8469e0159a166028d017bddbc162b86f66bac90391379603d962\", \"price_changes\":[{\"asset_id\":\"39272994714739463168905443499424551362424437245880253267329605556587274644733\", \"price\":\"0.52\", \"size\":\"5\", \"side\":\"SELL\", \"hash\":\"149f119575352e2c80914737c6b5a4ebaec76660\", \"best_bid\":\"0.51\", \"best_ask\":\"0.52\"}, {\"asset_id\":\"20893381255801015515826997628594359667013752732428989472914000440642900266717\", \"price\":\"0.48\", \"size\":\"5\", \"side\":\"BUY\", \"hash\":\"e662055b3c8caec1e41899621631e37f131c0c08\", \"best_bid\":\"0.48\", \"best_ask\":\"0.49\"}], \"timestamp\":\"1785204031087\", \"event_type\":\"price_change\"}","received_at":"2026-07-28T02:00:33.201269Z","schema_version":"clob-market-ws.price_change.v1","sequence":null,"server_hash":null,"server_timestamp":"1785204031087","session_id":"d2757dd6dad94f3b9fe67e8dbf1adc37","source":"clob_market_ws"},"received_at":"2026-07-28T02:00:33.201269Z","record_id":"3412ffed90fdae70c5e220b2e31022e2892d54917ea5812ff6c260a7460141f4","schema_fingerprint":"4aa3821a28b0b7c2400bc59aba4bcc0a76e971dadd19610d3ad38c768e124dc7","schema_version":"edge-lab-recorder.raw.v1","sequence":null,"source":"clob_market_ws"}
{"event_at":"2026-07-28T02:00:31.091000Z","event_fingerprint":"a8960b598e5a1c3225a14faa98610fe77c08f070a23a8f7de340c3c46771d39c","payload":{"connection_id":"5d29200f65794d4d9ab6ef271f045a9b","event_at":"2026-07-28T02:00:31.091000Z","event_type":"price_change","frame_hash":"03bb25e854969a7edb209de27cb94823e9d731fb9dcf221794dcbbb890346107","frame_index":0,"kind":"data","monotonic_ns":306016212243458,"payload":{"event_type":"price_change","market":"0xda6f0e0e93fc8469e0159a166028d017bddbc162b86f66bac90391379603d962","price_changes":[{"asset_id":"39272994714739463168905443499424551362424437245880253267329605556587274644733","best_ask":"0.52","best_bid":"0.51","hash":"cb40ab3cf0a39a36ab8fb1f476e8542cafc245a2","price":"0.51","side":"BUY","size":"107.2"},{"asset_id":"20893381255801015515826997628594359667013752732428989472914000440642900266717","best_ask":"0.49","best_bid":"0.48","hash":"576216c046d2e415aee84e2d4bc72e238c026ffc","price":"0.49","side":"SELL","size":"107.2"}],"timestamp":"1785204031091"},"payload_hash":"176f04f11244ce265218f0ed794aab7f1d6d622a75b5a4ed1b20b32f64fb9f0a","raw_frame":"{\"market\":\"0xda6f0e0e93fc8469e0159a166028d017bddbc162b86f66bac90391379603d962\", \"price_changes\":[{\"asset_id\":\"39272994714739463168905443499424551362424437245880253267329605556587274644733\", \"price\":\"0.51\", \"size\":\"107.2\", \"side\":\"BUY\", \"hash\":\"cb40ab3cf0a39a36ab8fb1f476e8542cafc245a2\", \"best_bid\":\"0.51\", \"best_ask\":\"0.52\"}, {\"asset_id\":\"20893381255801015515826997628594359667013752732428989472914000440642900266717\", \"price\":\"0.49\", \"size\":\"107.2\", \"side\":\"SELL\", \"hash\":\"576216c046d2e415aee84e2d4bc72e238c026ffc\", \"best_bid\":\"0.48\", \"best_ask\":\"0.49\"}], \"timestamp\":\"1785204031091\", \"event_type\":\"price_change\"}","received_at":"2026-07-28T02:00:33.206672Z","schema_version":"clob-market-ws.price_change.v1","sequence":null,"server_hash":null,"server_timestamp":"1785204031091","session_id":"d2757dd6dad94f3b9fe67e8dbf1adc37","source":"clob_market_ws"},"received_at":"2026-07-28T02:00:33.206672Z","record_id":"813d64d8deb9c6bfbc97cb86f4b56072eb0f240745424b0d977302428d85dd1c","schema_fingerprint":"4aa3821a28b0b7c2400bc59aba4bcc0a76e971dadd19610d3ad38c768e124dc7","schema_version":"edge-lab-recorder.raw.v1","sequence":null,"source":"clob_market_ws"}
{"event_at":"2026-07-28T02:00:31.094000Z","event_fingerprint":"8526421714382188a19e66c1c89e17d239898bc048fce859934465c89e832b00","payload":{"connection_id":"5d29200f65794d4d9ab6ef271f045a9b","event_at":"2026-07-28T02:00:31.094000Z","event_type":"best_bid_ask","frame_hash":"9b870e7b8465d8f1acf098e4c79d8e24595af7e4bfbd1cca11a158571bbfdb80","frame_index":0,"kind":"data","monotonic_ns":306016218666416,"payload":{"asset_id":"20893381255801015515826997628594359667013752732428989472914000440642900266717","best_ask":"0.49","best_bid":"0.47","event_type":"best_bid_ask","market":"0xda6f0e0e93fc8469e0159a166028d017bddbc162b86f66bac90391379603d962","spread":"0.02","timestamp":"1785204031094"},"payload_hash":"11b68e58c4b4ace8302d6feecc85e05b2ac0165a650925038f28320ba56fdb57","raw_frame":"{\"market\":\"0xda6f0e0e93fc8469e0159a166028d017bddbc162b86f66bac90391379603d962\", \"asset_id\":\"20893381255801015515826997628594359667013752732428989472914000440642900266717\", \"best_bid\":\"0.47\", \"best_ask\":\"0.49\", \"spread\":\"0.02\", \"timestamp\":\"1785204031094\", \"event_type\":\"best_bid_ask\"}","received_at":"2026-07-28T02:00:33.213095Z","schema_version":"clob-market-ws.best_bid_ask.v1","sequence":null,"server_hash":null,"server_timestamp":"1785204031094","session_id":"d2757dd6dad94f3b9fe67e8dbf1adc37","source":"clob_market_ws"},"received_at":"2026-07-28T02:00:33.213095Z","record_id":"84831e0e4176be89f44ee1483fd8628a7ddc1e129d7472a15999d0378bd65b7e","schema_fingerprint":"8488399f31b0337811b13b266be932db7062827c2470b78bd8e9e99bab51d17d","schema_version":"edge-lab-recorder.raw.v1","sequence":null,"source":"clob_market_ws"}
{"event_at":"2026-07-28T02:00:31.094000Z","event_fingerprint":"091c5347350cc9b93d6478c495bf6b98713175ace5d96aa2d61d37efdeab714a","payload":{"connection_id":"5d29200f65794d4d9ab6ef271f045a9b","event_at":"2026-07-28T02:00:31.094000Z","event_type":"best_bid_ask","frame_hash":"2c066a1fe1f05b75f0a76e9466b00f8f147b7cad94ded4ab5426a7c97d635982","frame_index":0,"kind":"data","monotonic_ns":306016222902375,"payload":{"asset_id":"39272994714739463168905443499424551362424437245880253267329605556587274644733","best_ask":"0.53","best_bid":"0.51","event_type":"best_bid_ask","market":"0xda6f0e0e93fc8469e0159a166028d017bddbc162b86f66bac90391379603d962","spread":"0.02","timestamp":"1785204031094"},"payload_hash":"e17f6aa352764e982130371a925345c5df442dd123807733afa7370bafb966cb","raw_frame":"{\"market\":\"0xda6f0e0e93fc8469e0159a166028d017bddbc162b86f66bac90391379603d962\", \"asset_id\":\"39272994714739463168905443499424551362424437245880253267329605556587274644733\", \"best_bid\":\"0.51\", \"best_ask\":\"0.53\", \"spread\":\"0.02\", \"timestamp\":\"1785204031094\", \"event_type\":\"best_bid_ask\"}","received_at":"2026-07-28T02:00:33.217332Z","schema_version":"clob-market-ws.best_bid_ask.v1","sequence":null,"server_hash":null,"server_timestamp":"1785204031094","session_id":"d2757dd6dad94f3b9fe67e8dbf1adc37","source":"clob_market_ws"},"received_at":"2026-07-28T02:00:33.217332Z","record_id":"7d9423c1728ca811b4cf22d78f64c312d006c276543227c046d7f200b8c4c3cb","schema_fingerprint":"8488399f31b0337811b13b266be932db7062827c2470b78bd8e9e99bab51d17d","schema_version":"edge-lab-recorder.raw.v1","sequence":null,"source":"clob_market_ws"}
{"event_at":"2026-07-28T02:00:31.093000Z","event_fingerprint":"b62042ec7b6a5e0b1e64517d1acf42597de93494a02fa9d0b529eda01222dc1c","payload":{"connection_id":"5d29200f65794d4d9ab6ef271f045a9b","event_at":"2026-07-28T02:00:31.093000Z","event_type":"price_change","frame_hash":"26dde3611e364a910bb42eba1e6a6d99ae6853731484934e457978131de6c4e8","frame_index":0,"kind":"data","monotonic_ns":306016236076250,"payload":{"event_type":"price_change","market":"0xda6f0e0e93fc8469e0159a166028d017bddbc162b86f66bac90391379603d962","price_changes":[{"asset_id":"20893381255801015515826997628594359667013752732428989472914000440642900266717","best_ask":"0.49","best_bid":"0.47","hash":"c9c03d066724ed09f1ee719da5cad3642fd949f9","price":"0.48","side":"BUY","size":"0"},{"asset_id":"39272994714739463168905443499424551362424437245880253267329605556587274644733","best_ask":"0.53","best_bid":"0.51","hash":"ff6be9792e2c86403eb8339322ba48e41aa9e574","price":"0.52","side":"SELL","size":"0"}],"timestamp":"1785204031093"},"payload_hash":"05dbeb2478b4398dfbbc87983f303a851091ec00e2cc51f1b235f5fba6f1aa42","raw_frame":"{\"market\":\"0xda6f0e0e93fc8469e0159a166028d017bddbc162b86f66bac90391379603d962\", \"price_changes\":[{\"asset_id\":\"20893381255801015515826997628594359667013752732428989472914000440642900266717\", \"price\":\"0.48\", \"size\":\"0\", \"side\":\"BUY\", \"hash\":\"c9c03d066724ed09f1ee719da5cad3642fd949f9\", \"best_bid\":\"0.47\", \"best_ask\":\"0.49\"}, {\"asset_id\":\"39272994714739463168905443499424551362424437245880253267329605556587274644733\", \"price\":\"0.52\", \"size\":\"0\", \"side\":\"SELL\", \"hash\":\"ff6be9792e2c86403eb8339322ba48e41aa9e574\", \"best_bid\":\"0.51\", \"best_ask\":\"0.53\"}], \"timestamp\":\"1785204031093\", \"event_type\":\"price_change\"}","received_at":"2026-07-28T02:00:33.230505Z","schema_version":"clob-market-ws.price_change.v1","sequence":null,"server_hash":null,"server_timestamp":"1785204031093","session_id":"d2757dd6dad94f3b9fe67e8dbf1adc37","source":"clob_market_ws"},"received_at":"2026-07-28T02:00:33.230505Z","record_id":"47c76f95097baadef40b323fc3bbe7467220de582a1343a7e2cb33adf36469d1","schema_fingerprint":"4aa3821a28b0b7c2400bc59aba4bcc0a76e971dadd19610d3ad38c768e124dc7","schema_version":"edge-lab-recorder.raw.v1","sequence":null,"source":"clob_market_ws"}
{"event_at":"2026-07-28T02:00:31.113000Z","event_fingerprint":"5e3ae527db5b1342c88273211fa9028e30f579ff4e5a34ac41c8f390e1f62fbb","payload":{"connection_id":"5d29200f65794d4d9ab6ef271f045a9b","event_at":"2026-07-28T02:00:31.113000Z","event_type":"price_change","frame_hash":"a98137bd50b8d9d8329261e19830c52e80292ed838822fc273983a3117f18334","frame_index":0,"kind":"data","monotonic_ns":306016242079000,"payload":{"event_type":"price_change","market":"0xda6f0e0e93fc8469e0159a166028d017bddbc162b86f66bac90391379603d962","price_changes":[{"asset_id":"20893381255801015515826997628594359667013752732428989472914000440642900266717","best_ask":"0.49","best_bid":"0.47","hash":"6ce0516835a6a5ee7fee27c5623593488a22a679","price":"0.03","side":"BUY","size":"1033.1"},{"asset_id":"39272994714739463168905443499424551362424437245880253267329605556587274644733","best_ask":"0.53","best_bid":"0.51","hash":"29fe872ce399acfa0ef9fefe662653cedaf797e8","price":"0.97","side":"SELL","size":"1033.1"}],"timestamp":"1785204031113"},"payload_hash":"426b7f3a8dde502f712e4350a3bba14ce845411cca157bd05b27c43efa723fef","raw_frame":"{\"market\":\"0xda6f0e0e93fc8469e0159a166028d017bddbc162b86f66bac90391379603d962\", \"price_changes\":[{\"asset_id\":\"20893381255801015515826997628594359667013752732428989472914000440642900266717\", \"price\":\"0.03\", \"size\":\"1033.1\", \"side\":\"BUY\", \"hash\":\"6ce0516835a6a5ee7fee27c5623593488a22a679\", \"best_bid\":\"0.47\", \"best_ask\":\"0.49\"}, {\"asset_id\":\"39272994714739463168905443499424551362424437245880253267329605556587274644733\", \"price\":\"0.97\", \"size\":\"1033.1\", \"side\":\"SELL\", \"hash\":\"29fe872ce399acfa0ef9fefe662653cedaf797e8\", \"best_bid\":\"0.51\", \"best_ask\":\"0.53\"}], \"timestamp\":\"1785204031113\", \"event_type\":\"price_change\"}","received_at":"2026-07-28T02:00:33.236508Z","schema_version":"clob-market-ws.price_change.v1","sequence":null,"server_hash":null,"server_timestamp":"1785204031113","session_id":"d2757dd6dad94f3b9fe67e8dbf1adc37","source":"clob_market_ws"},"received_at":"2026-07-28T02:00:33.236508Z","record_id":"901c7fc70d3bdda1c0b866a0da9a2adaa9ebbe9834f92eebe3a6abc27de84122","schema_fingerprint":"4aa3821a28b0b7c2400bc59aba4bcc0a76e971dadd19610d3ad38c768e124dc7","schema_version":"edge-lab-recorder.raw.v1","sequence":null,"source":"clob_market_ws"}
{"event_at":"2026-07-28T02:00:31.115000Z","event_fingerprint":"afe7b1958d245af51cd03fb822a1066a9d861919e8db6bf5dfa1caa408142736","payload":{"connection_id":"5d29200f65794d4d9ab6ef271f045a9b","event_at":"2026-07-28T02:00:31.115000Z","event_type":"price_change","frame_hash":"77aaf36a1c1cff31d7aa39a07e6ef4794ade5725956e498fdce1077423057898","frame_index":0,"kind":"data","monotonic_ns":306016255637625,"payload":{"event_type":"price_change","market":"0xda6f0e0e93fc8469e0159a166028d017bddbc162b86f66bac90391379603d962","price_changes":[{"asset_id":"39272994714739463168905443499424551362424437245880253267329605556587274644733","best_ask":"0.53","best_bid":"0.51","hash":"c154f304743a1d864081bbef1b9759689ea6fefc","price":"0.01","side":"BUY","size":"7858.02"},{"asset_id":"20893381255801015515826997628594359667013752732428989472914000440642900266717","best_ask":"0.49","best_bid":"0.47","hash":"ea9c140b89336294e9b0090ef0e1c34382484ba0","price":"0.99","side":"SELL","size":"7858.02"}],"timestamp":"1785204031115"},"payload_hash":"82902e50ef46b000d0ad66ed5a4d7642c3266426ef4291629efcafe2aac49c51","raw_frame":"{\"market\":\"0xda6f0e0e93fc8469e0159a166028d017bddbc162b86f66bac90391379603d962\", \"price_changes\":[{\"asset_id\":\"39272994714739463168905443499424551362424437245880253267329605556587274644733\", \"price\":\"0.01\", \"size\":\"7858.02\", \"side\":\"BUY\", \"hash\":\"c154f304743a1d864081bbef1b9759689ea6fefc\", \"best_bid\":\"0.51\", \"best_ask\":\"0.53\"}, {\"asset_id\":\"20893381255801015515826997628594359667013752732428989472914000440642900266717\", \"price\":\"0.99\", \"size\":\"7858.02\", \"side\":\"SELL\", \"hash\":\"ea9c140b89336294e9b0090ef0e1c34382484ba0\", \"best_bid\":\"0.47\", \"best_ask\":\"0.49\"}], \"timestamp\":\"1785204031115\", \"event_type\":\"price_change\"}","received_at":"2026-07-28T02:00:33.250067Z","schema_version":"clob-market-ws.price_change.v1","sequence":null,"server_hash":null,"server_timestamp":"1785204031115","session_id":"d2757dd6dad94f3b9fe67e8dbf1adc37","source":"clob_market_ws"},"received_at":"2026-07-28T02:00:33.250067Z","record_id":"d9c7d44c9e699a5e8f4e62f4003cbf24759378e9bf39aede8555da9dfa9bee82","schema_fingerprint":"4aa3821a28b0b7c2400bc59aba4bcc0a76e971dadd19610d3ad38c768e124dc7","schema_version":"edge-lab-recorder.raw.v1","sequence":null,"source":"clob_market_ws"}
{"event_at":"2026-07-28T02:00:31.119000Z","event_fingerprint":"8a3d93efa9f487296c516de97b5f49f1ca05265b5fa2b7f9f955232aa61ee83d","payload":{"connection_id":"5d29200f65794d4d9ab6ef271f045a9b","event_at":"2026-07-28T02:00:31.119000Z","event_type":"best_bid_ask","frame_hash":"2e2b24cc3fb92bae9c7f0026c9bd3a023eee7e99a5ac7904778d221267d06f96","frame_index":0,"kind":"data","monotonic_ns":306016264662375,"payload":{"asset_id":"20893381255801015515826997628594359667013752732428989472914000440642900266717","best_ask":"0.49","best_bid":"0.48","event_type":"best_bid_ask","market":"0xda6f0e0e93fc8469e0159a166028d017bddbc162b86f66bac90391379603d962","spread":"0.01","timestamp":"1785204031119"},"payload_hash":"87c83fc12ff7db5a33d07024557eefc55e6bcc85818e8248317328b00b4c4946","raw_frame":"{\"market\":\"0xda6f0e0e93fc8469e0159a166028d017bddbc162b86f66bac90391379603d962\", \"asset_id\":\"20893381255801015515826997628594359667013752732428989472914000440642900266717\", \"best_bid\":\"0.48\", \"best_ask\":\"0.49\", \"spread\":\"0.01\", \"timestamp\":\"1785204031119\", \"event_type\":\"best_bid_ask\"}","received_at":"2026-07-28T02:00:33.259095Z","schema_version":"clob-market-ws.best_bid_ask.v1","sequence":null,"server_hash":null,"server_timestamp":"1785204031119","session_id":"d2757dd6dad94f3b9fe67e8dbf1adc37","source":"clob_market_ws"},"received_at":"2026-07-28T02:00:33.259095Z","record_id":"0bd71862d88cd1f8ddfa6538bb3463f387f7b87796ba22a067be4b02449914a2","schema_fingerprint":"8488399f31b0337811b13b266be932db7062827c2470b78bd8e9e99bab51d17d","schema_version":"edge-lab-recorder.raw.v1","sequence":null,"source":"clob_market_ws"}
{"event_at":"2026-07-28T02:00:31.119000Z","event_fingerprint":"832aedfedfd975096a1cb22dc8c2b2d988c7766ec4c0ae35e98256a63b624320","payload":{"connection_id":"5d29200f65794d4d9ab6ef271f045a9b","event_at":"2026-07-28T02:00:31.119000Z","event_type":"best_bid_ask","frame_hash":"59cb43558ee57a11aaa5c1bd0e67496e47eebaacc24adf150afd18e7b6b4f722","frame_index":0,"kind":"data","monotonic_ns":306016271230958,"payload":{"asset_id":"39272994714739463168905443499424551362424437245880253267329605556587274644733","best_ask":"0.52","best_bid":"0.51","event_type":"best_bid_ask","market":"0xda6f0e0e93fc8469e0159a166028d017bddbc162b86f66bac90391379603d962","spread":"0.01","timestamp":"1785204031119"},"payload_hash":"11d0c6bbf267ba2c2080af1eae4da3a1d0781b1afec15f8e73ae3177ffb1ea8c","raw_frame":"{\"market\":\"0xda6f0e0e93fc8469e0159a166028d017bddbc162b86f66bac90391379603d962\", \"asset_id\":\"39272994714739463168905443499424551362424437245880253267329605556587274644733\", \"best_bid\":\"0.51\", \"best_ask\":\"0.52\", \"spread\":\"0.01\", \"timestamp\":\"1785204031119\", \"event_type\":\"best_bid_ask\"}","received_at":"2026-07-28T02:00:33.265666Z","schema_version":"clob-market-ws.best_bid_ask.v1","sequence":null,"server_hash":null,"server_timestamp":"1785204031119","session_id":"d2757dd6dad94f3b9fe67e8dbf1adc37","source":"clob_market_ws"},"received_at":"2026-07-28T02:00:33.265666Z","record_id":"c70d66da81c0f3e2783a4e7aca7356a5365dca783acb2bb47fad2586b81175c2","schema_fingerprint":"8488399f31b0337811b13b266be932db7062827c2470b78bd8e9e99bab51d17d","schema_version":"edge-lab-recorder.raw.v1","sequence":null,"source":"clob_market_ws"}
{"event_at":"2026-07-28T02:00:31.119000Z","event_fingerprint":"4c862b5c8b231c6f78316d35634869183e921e1f05a9c0448a229fbce391db63","payload":{"connection_id":"5d29200f65794d4d9ab6ef271f045a9b","event_at":"2026-07-28T02:00:31.119000Z","event_type":"price_change","frame_hash":"3a866858efc2d4ab3868ae3606c336794308aeff1d7183a07eb3ea2a6b335bd0","frame_index":0,"kind":"data","monotonic_ns":306016275886333,"payload":{"event_type":"price_change","market":"0xda6f0e0e93fc8469e0159a166028d017bddbc162b86f66bac90391379603d962","price_changes":[{"asset_id":"20893381255801015515826997628594359667013752732428989472914000440642900266717","best_ask":"0.49","best_bid":"0.48","hash":"ffd2103feed080f3d5d7d79d24f000a1cb83554e","price":"0.48","side":"BUY","size":"6"},{"asset_id":"39272994714739463168905443499424551362424437245880253267329605556587274644733","best_ask":"0.52","best_bid":"0.51","hash":"b2c64a5d07f616dbb57973997a689b0f84c25554","price":"0.52","side":"SELL","size":"6"}],"timestamp":"1785204031119"},"payload_hash":"c62385c46ee72a21d0c274753884853fab550238165eb1d7cfb2901a4527f012","raw_frame":"{\"market\":\"0xda6f0e0e93fc8469e0159a166028d017bddbc162b86f66bac90391379603d962\", \"price_changes\":[{\"asset_id\":\"20893381255801015515826997628594359667013752732428989472914000440642900266717\", \"price\":\"0.48\", \"size\":\"6\", \"side\":\"BUY\", \"hash\":\"ffd2103feed080f3d5d7d79d24f000a1cb83554e\", \"best_bid\":\"0.48\", \"best_ask\":\"0.49\"}, {\"asset_id\":\"39272994714739463168905443499424551362424437245880253267329605556587274644733\", \"price\":\"0.52\", \"size\":\"6\", \"side\":\"SELL\", \"hash\":\"b2c64a5d07f616dbb57973997a689b0f84c25554\", \"best_bid\":\"0.51\", \"best_ask\":\"0.52\"}], \"timestamp\":\"1785204031119\", \"event_type\":\"price_change\"}","received_at":"2026-07-28T02:00:33.270322Z","schema_version":"clob-market-ws.price_change.v1","sequence":null,"server_hash":null,"server_timestamp":"1785204031119","session_id":"d2757dd6dad94f3b9fe67e8dbf1adc37","source":"clob_market_ws"},"received_at":"2026-07-28T02:00:33.270322Z","record_id":"083c3c7a73456c8783ff15cdde3b5f7a9eebc9854977848d10459b3a4c405330","schema_fingerprint":"4aa3821a28b0b7c2400bc59aba4bcc0a76e971dadd19610d3ad38c768e124dc7","schema_version":"edge-lab-recorder.raw.v1","sequence":null,"source":"clob_market_ws"}
{"event_at":"2026-07-28T02:00:31.122000Z","event_fingerprint":"da46dfd466dd49eeea4f19da2709e2e069f11e395b4c0a500b9ddd0802ff692a","payload":{"connection_id":"5d29200f65794d4d9ab6ef271f045a9b","event_at":"2026-07-28T02:00:31.122000Z","event_type":"price_change","frame_hash":"2116d74ad28a517b56b3ccca1a172b4b74d55b4ce81b131da16bd5a091aec9a7","frame_index":0,"kind":"data","monotonic_ns":306016282311333,"payload":{"event_type":"price_change","market":"0xda6f0e0e93fc8469e0159a166028d017bddbc162b86f66bac90391379603d962","price_changes":[{"asset_id":"20893381255801015515826997628594359667013752732428989472914000440642900266717","best_ask":"0.49","best_bid":"0.48","hash":"066c8c13eb543ef359bed6ed5c51354a7aa56589","price":"0.48","side":"BUY","size":"11"},{"asset_id":"39272994714739463168905443499424551362424437245880253267329605556587274644733","best_ask":"0.52","best_bid":"0.51","hash":"b0d120e643681fc41865829875534a99b7439a5e","price":"0.52","side":"SELL","size":"11"}],"timestamp":"1785204031122"},"payload_hash":"2f2f07b345c16147efd00c7344d2da30dbb01813d6b4cca9465ddf353d182254","raw_frame":"{\"market\":\"0xda6f0e0e93fc8469e0159a166028d017bddbc162b86f66bac90391379603d962\", \"price_changes\":[{\"asset_id\":\"20893381255801015515826997628594359667013752732428989472914000440642900266717\", \"price\":\"0.48\", \"size\":\"11\", \"side\":\"BUY\", \"hash\":\"066c8c13eb543ef359bed6ed5c51354a7aa56589\", \"best_bid\":\"0.48\", \"best_ask\":\"0.49\"}, {\"asset_id\":\"39272994714739463168905443499424551362424437245880253267329605556587274644733\", \"price\":\"0.52\", \"size\":\"11\", \"side\":\"SELL\", \"hash\":\"b0d120e643681fc41865829875534a99b7439a5e\", \"best_bid\":\"0.51\", \"best_ask\":\"0.52\"}], \"timestamp\":\"1785204031122\", \"event_type\":\"price_change\"}","received_at":"2026-07-28T02:00:33.276749Z","schema_version":"clob-market-ws.price_change.v1","sequence":null,"server_hash":null,"server_timestamp":"1785204031122","session_id":"d2757dd6dad94f3b9fe67e8dbf1adc37","source":"clob_market_ws"},"received_at":"2026-07-28T02:00:33.276749Z","record_id":"2dc9abd99d314b9f60f9ec45a7a602c7ec9d6758910cf2e04c1aa56eb5b65f8e","schema_fingerprint":"4aa3821a28b0b7c2400bc59aba4bcc0a76e971dadd19610d3ad38c768e124dc7","schema_version":"edge-lab-recorder.raw.v1","sequence":null,"source":"clob_market_ws"}
{"event_at":"2026-07-28T02:00:31.132000Z","event_fingerprint":"8245c75e80cab2475a5aa1c9a2dd561fd1a304813e43827369aabd18a5f2f1c1","payload":{"connection_id":"5d29200f65794d4d9ab6ef271f045a9b","event_at":"2026-07-28T02:00:31.132000Z","event_type":"price_change","frame_hash":"db526a50c07a97a863437b1e39d11829e88a6ccab05af11b9a7d1d334e777049","frame_index":0,"kind":"data","monotonic_ns":306016287502500,"payload":{"event_type":"price_change","market":"0xda6f0e0e93fc8469e0159a166028d017bddbc162b86f66bac90391379603d962","price_changes":[{"asset_id":"39272994714739463168905443499424551362424437245880253267329605556587274644733","best_ask":"0.52","best_bid":"0.51","hash":"f67400216153f426644a9263d1262dd3da716432","price":"0.52","side":"SELL","size":"17"},{"asset_id":"20893381255801015515826997628594359667013752732428989472914000440642900266717","best_ask":"0.49","best_bid":"0.48","hash":"6e71b229b83e6ac4d9aa02c4d32dcbb25d435281","price":"0.48","side":"BUY","size":"17"}],"timestamp":"1785204031132"},"payload_hash":"1dccf0388e3db9f1c9e63a3183a37527f5b5cadd5d09cdfc8e0221524078f6da","raw_frame":"{\"market\":\"0xda6f0e0e93fc8469e0159a166028d017bddbc162b86f66bac90391379603d962\", \"price_changes\":[{\"asset_id\":\"39272994714739463168905443499424551362424437245880253267329605556587274644733\", \"price\":\"0.52\", \"size\":\"17\", \"side\":\"SELL\", \"hash\":\"f67400216153f426644a9263d1262dd3da716432\", \"best_bid\":\"0.51\", \"best_ask\":\"0.52\"}, {\"asset_id\":\"20893381255801015515826997628594359667013752732428989472914000440642900266717\", \"price\":\"0.48\", \"size\":\"17\", \"side\":\"BUY\", \"hash\":\"6e71b229b83e6ac4d9aa02c4d32dcbb25d435281\", \"best_bid\":\"0.48\", \"best_ask\":\"0.49\"}], \"timestamp\":\"1785204031132\", \"event_type\":\"price_change\"}","received_at":"2026-07-28T02:00:33.281940Z","schema_version":"clob-market-ws.price_change.v1","sequence":null,"server_hash":null,"server_timestamp":"1785204031132","session_id":"d2757dd6dad94f3b9fe67e8dbf1adc37","source":"clob_market_ws"},"received_at":"2026-07-28T02:00:33.281940Z","record_id":"259590be30e4e8ed5bbab269b93c9fe4ec4d085a4d856e8f29936a1057b05840","schema_fingerprint":"4aa3821a28b0b7c2400bc59aba4bcc0a76e971dadd19610d3ad38c768e124dc7","schema_version":"edge-lab-recorder.raw.v1","sequence":null,"source":"clob_market_ws"}
{"event_at":"2026-07-28T02:00:31.134000Z","event_fingerprint":"ff4f42167c6e0d3b612693db019d4450f3b04bc1072b40e2fb56171a91a515de","payload":{"connection_id":"5d29200f65794d4d9ab6ef271f045a9b","event_at":"2026-07-28T02:00:31.134000Z","event_type":"price_change","frame_hash":"55bde1a03a386da0da74940ad7e51b6deae06dcad5ab7a2492497569c8b813b1","frame_index":0,"kind":"data","monotonic_ns":306016294021291,"payload":{"event_type":"price_change","market":"0xda6f0e0e93fc8469e0159a166028d017bddbc162b86f66bac90391379603d962","price_changes":[{"asset_id":"39272994714739463168905443499424551362424437245880253267329605556587274644733","best_ask":"0.52","best_bid":"0.51","hash":"859c1aae926c11557fe94e5356fb059334b20c25","price":"0.46","side":"BUY","size":"98"},{"asset_id":"20893381255801015515826997628594359667013752732428989472914000440642900266717","best_ask":"0.49","best_bid":"0.48","hash":"abb2f35029b4caa661c462fd2df5dbea31c1d05d","price":"0.54","side":"SELL","size":"98"}],"timestamp":"1785204031134"},"payload_hash":"edfb263e894c1be1540663442581a96c0a37a19f1fba10c9d7857c21f9279c7f","raw_frame":"{\"market\":\"0xda6f0e0e93fc8469e0159a166028d017bddbc162b86f66bac90391379603d962\", \"price_changes\":[{\"asset_id\":\"39272994714739463168905443499424551362424437245880253267329605556587274644733\", \"price\":\"0.46\", \"size\":\"98\", \"side\":\"BUY\", \"hash\":\"859c1aae926c11557fe94e5356fb059334b20c25\", \"best_bid\":\"0.51\", \"best_ask\":\"0.52\"}, {\"asset_id\":\"20893381255801015515826997628594359667013752732428989472914000440642900266717\", \"price\":\"0.54\", \"size\":\"98\", \"side\":\"SELL\", \"hash\":\"abb2f35029b4caa661c462fd2df5dbea31c1d05d\", \"best_bid\":\"0.48\", \"best_ask\":\"0.49\"}], \"timestamp\":\"1785204031134\", \"event_type\":\"price_change\"}","received_at":"2026-07-28T02:00:33.288460Z","schema_version":"clob-market-ws.price_change.v1","sequence":null,"server_hash":null,"server_timestamp":"1785204031134","session_id":"d2757dd6dad94f3b9fe67e8dbf1adc37","source":"clob_market_ws"},"received_at":"2026-07-28T02:00:33.288460Z","record_id":"7ce9418b37d22d878285644087b942428b3213dbdce0742b28498f42ba38658b","schema_fingerprint":"4aa3821a28b0b7c2400bc59aba4bcc0a76e971dadd19610d3ad38c768e124dc7","schema_version":"edge-lab-recorder.raw.v1","sequence":null,"source":"clob_market_ws"}
{"event_at":"2026-07-28T02:00:31.136000Z","event_fingerprint":"e3aeb65684d639c565c3a74d9ae036ef7394093b76a374ccdd2738cb3f143439","payload":{"connection_id":"5d29200f65794d4d9ab6ef271f045a9b","event_at":"2026-07-28T02:00:31.136000Z","event_type":"price_change","frame_hash":"d458671b62109076c6acea076135508c19ccb7528e447b8c34970f32790434ed","frame_index":0,"kind":"data","monotonic_ns":306016302516875,"payload":{"event_type":"price_change","market":"0xda6f0e0e93fc8469e0159a166028d017bddbc162b86f66bac90391379603d962","price_changes":[{"asset_id":"20893381255801015515826997628594359667013752732428989472914000440642900266717","best_ask":"0.49","best_bid":"0.48","hash":"5dc1258eefc93904f875a07146f39e8ff2ac00a9","price":"0.48","side":"BUY","size":"11"},{"asset_id":"39272994714739463168905443499424551362424437245880253267329605556587274644733","best_ask":"0.52","best_bid":"0.51","hash":"e71dc1ede0ad104e5e56a0eeb6b9827e4a74d074","price":"0.52","side":"SELL","size":"11"}],"timestamp":"1785204031136"},"payload_hash":"c4761c63386f99ed1b5978a8966b7d44df80d9e97e292123c013ef7cde3459ef","raw_frame":"{\"market\":\"0xda6f0e0e93fc8469e0159a166028d017bddbc162b86f66bac90391379603d962\", \"price_changes\":[{\"asset_id\":\"20893381255801015515826997628594359667013752732428989472914000440642900266717\", \"price\":\"0.48\", \"size\":\"11\", \"side\":\"BUY\", \"hash\":\"5dc1258eefc93904f875a07146f39e8ff2ac00a9\", \"best_bid\":\"0.48\", \"best_ask\":\"0.49\"}, {\"asset_id\":\"39272994714739463168905443499424551362424437245880253267329605556587274644733\", \"price\":\"0.52\", \"size\":\"11\", \"side\":\"SELL\", \"hash\":\"e71dc1ede0ad104e5e56a0eeb6b9827e4a74d074\", \"best_bid\":\"0.51\", \"best_ask\":\"0.52\"}], \"timestamp\":\"1785204031136\", \"event_type\":\"price_change\"}","received_at":"2026-07-28T02:00:33.296958Z","schema_version":"clob-market-ws.price_change.v1","sequence":null,"server_hash":null,"server_timestamp":"1785204031136","session_id":"d2757dd6dad94f3b9fe67e8dbf1adc37","source":"clob_market_ws"},"received_at":"2026-07-28T02:00:33.296958Z","record_id":"d45164dbebd4196897372b8f6eff31372f7db58cbf8c48ede9dc171e1736fbdf","schema_fingerprint":"4aa3821a28b0b7c2400bc59aba4bcc0a76e971dadd19610d3ad38c768e124dc7","schema_version":"edge-lab-recorder.raw.v1","sequence":null,"source":"clob_market_ws"}
{"event_at":"2026-07-28T02:00:31.138000Z","event_fingerprint":"ae5edbe7d2df8dee5eaf128eaf74030df8a1b0f63e2578d2410a85c994fc04b8","payload":{"connection_id":"5d29200f65794d4d9ab6ef271f045a9b","event_at":"2026-07-28T02:00:31.138000Z","event_type":"price_change","frame_hash":"69b4cff25946fbc6fc602b462958237d85a4d44b6da98cee6f238cca5e8f668f","frame_index":0,"kind":"data","monotonic_ns":306016308291750,"payload":{"event_type":"price_change","market":"0xda6f0e0e93fc8469e0159a166028d017bddbc162b86f66bac90391379603d962","price_changes":[{"asset_id":"20893381255801015515826997628594359667013752732428989472914000440642900266717","best_ask":"0.49","best_bid":"0.48","hash":"817cf527a9a48f6431a648eed8138e8613e4d770","price":"0.48","side":"BUY","size":"6"},{"asset_id":"39272994714739463168905443499424551362424437245880253267329605556587274644733","best_ask":"0.52","best_bid":"0.51","hash":"fc90627d7dcad57589df504129d1e5bfe8dbbcf6","price":"0.52","side":"SELL","size":"6"}],"timestamp":"1785204031138"},"payload_hash":"be9499984310cdbe1243019eb6dc4dd93fdbfeb0724264f886cf403423981d5d","raw_frame":"{\"market\":\"0xda6f0e0e93fc8469e0159a166028d017bddbc162b86f66bac90391379603d962\", \"price_changes\":[{\"asset_id\":\"20893381255801015515826997628594359667013752732428989472914000440642900266717\", \"price\":\"0.48\", \"size\":\"6\", \"side\":\"BUY\", \"hash\":\"817cf527a9a48f6431a648eed8138e8613e4d770\", \"best_bid\":\"0.48\", \"best_ask\":\"0.49\"}, {\"asset_id\":\"39272994714739463168905443499424551362424437245880253267329605556587274644733\", \"price\":\"0.52\", \"size\":\"6\", \"side\":\"SELL\", \"hash\":\"fc90627d7dcad57589df504129d1e5bfe8dbbcf6\", \"best_bid\":\"0.51\", \"best_ask\":\"0.52\"}], \"timestamp\":\"1785204031138\", \"event_type\":\"price_change\"}","received_at":"2026-07-28T02:00:33.302733Z","schema_version":"clob-market-ws.price_change.v1","sequence":null,"server_hash":null,"server_timestamp":"1785204031138","session_id":"d2757dd6dad94f3b9fe67e8dbf1adc37","source":"clob_market_ws"},"received_at":"2026-07-28T02:00:33.302733Z","record_id":"2c509ad7dd09634a6ee9dc6f513e85c4ebe0a6f0f8e8ad2dc96ffa69e5c5a172","schema_fingerprint":"4aa3821a28b0b7c2400bc59aba4bcc0a76e971dadd19610d3ad38c768e124dc7","schema_version":"edge-lab-recorder.raw.v1","sequence":null,"source":"clob_market_ws"}
{"event_at":"2026-07-28T02:00:31.139000Z","event_fingerprint":"a16ccbeb3b3e6c01ff5b668785db4685f8d483fa4d8d47c8fa39cdd3c6857957","payload":{"connection_id":"5d29200f65794d4d9ab6ef271f045a9b","event_at":"2026-07-28T02:00:31.139000Z","event_type":"price_change","frame_hash":"d826c451ddc1f6a77842f453592b16f4f532ea937bb617b4e572b02848a62a4d","frame_index":0,"kind":"data","monotonic_ns":306016315487458,"payload":{"event_type":"price_change","market":"0xda6f0e0e93fc8469e0159a166028d017bddbc162b86f66bac90391379603d962","price_changes":[{"asset_id":"39272994714739463168905443499424551362424437245880253267329605556587274644733","best_ask":"0.52","best_bid":"0.51","hash":"2b7acefc0bdb803f587521fe34c8bb670d920d77","price":"0.01","side":"BUY","size":"7853.02"},{"asset_id":"20893381255801015515826997628594359667013752732428989472914000440642900266717","best_ask":"0.49","best_bid":"0.48","hash":"37cd494b395e5c74aa7b17acef1afa6f37ae198b","price":"0.99","side":"SELL","size":"7853.02"}],"timestamp":"1785204031139"},"payload_hash":"310c17a646fbd0c9c008df16ec517a4c6714dc4bfe261552ba45e769a2d71dcb","raw_frame":"{\"market\":\"0xda6f0e0e93fc8469e0159a166028d017bddbc162b86f66bac90391379603d962\", \"price_changes\":[{\"asset_id\":\"39272994714739463168905443499424551362424437245880253267329605556587274644733\", \"price\":\"0.01\", \"size\":\"7853.02\", \"side\":\"BUY\", \"hash\":\"2b7acefc0bdb803f587521fe34c8bb670d920d77\", \"best_bid\":\"0.51\", \"best_ask\":\"0.52\"}, {\"asset_id\":\"20893381255801015515826997628594359667013752732428989472914000440642900266717\", \"price\":\"0.99\", \"size\":\"7853.02\", \"side\":\"SELL\", \"hash\":\"37cd494b395e5c74aa7b17acef1afa6f37ae198b\", \"best_bid\":\"0.48\", \"best_ask\":\"0.49\"}], \"timestamp\":\"1785204031139\", \"event_type\":\"price_change\"}","received_at":"2026-07-28T02:00:33.309929Z","schema_version":"clob-market-ws.price_change.v1","sequence":null,"server_hash":null,"server_timestamp":"1785204031139","session_id":"d2757dd6dad94f3b9fe67e8dbf1adc37","source":"clob_market_ws"},"received_at":"2026-07-28T02:00:33.309929Z","record_id":"9df8aca4651130b2c42f0817133b10d9e83675c9b480056fc5d68fcdb0c92b5c","schema_fingerprint":"4aa3821a28b0b7c2400bc59aba4bcc0a76e971dadd19610d3ad38c768e124dc7","schema_version":"edge-lab-recorder.raw.v1","sequence":null,"source":"clob_market_ws"}
{"event_at":"2026-07-28T02:00:31.143000Z","event_fingerprint":"758f83bfae7948e2843058833ab76701c81b3e1b211519043e0aeac38d9a5ae1","payload":{"connection_id":"5d29200f65794d4d9ab6ef271f045a9b","event_at":"2026-07-28T02:00:31.143000Z","event_type":"price_change","frame_hash":"6edf78d8d43cdc0d465a083c0261fb4c17524c893c0d38c63836351c7667f441","frame_index":0,"kind":"data","monotonic_ns":306016322125041,"payload":{"event_type":"price_change","market":"0xda6f0e0e93fc8469e0159a166028d017bddbc162b86f66bac90391379603d962","price_changes":[{"asset_id":"39272994714739463168905443499424551362424437245880253267329605556587274644733","best_ask":"0.52","best_bid":"0.51","hash":"647114afbbd76aa870ffd021c9f20b7baaafa50e","price":"0.03","side":"BUY","size":"1201.43"},{"asset_id":"20893381255801015515826997628594359667013752732428989472914000440642900266717","best_ask":"0.49","best_bid":"0.48","hash":"ac1c858a917e7dcf5ba54c8e53e90a051cc6d3b1","price":"0.97","side":"SELL","size":"1201.43"}],"timestamp":"1785204031143"},"payload_hash":"88b06c23abae176bc92b6ed4e48beeee4ef87531dc9f016adf6662a2dab23083","raw_frame":"{\"market\":\"0xda6f0e0e93fc8469e0159a166028d017bddbc162b86f66bac90391379603d962\", \"price_changes\":[{\"asset_id\":\"39272994714739463168905443499424551362424437245880253267329605556587274644733\", \"price\":\"0.03\", \"size\":\"1201.43\", \"side\":\"BUY\", \"hash\":\"647114afbbd76aa870ffd021c9f20b7baaafa50e\", \"best_bid\":\"0.51\", \"best_ask\":\"0.52\"}, {\"asset_id\":\"20893381255801015515826997628594359667013752732428989472914000440642900266717\", \"price\":\"0.97\", \"size\":\"1201.43\", \"side\":\"SELL\", \"hash\":\"ac1c858a917e7dcf5ba54c8e53e90a051cc6d3b1\", \"best_bid\":\"0.48\", \"best_ask\":\"0.49\"}], \"timestamp\":\"1785204031143\", \"event_type\":\"price_change\"}","received_at":"2026-07-28T02:00:33.316569Z","schema_version":"clob-market-ws.price_change.v1","sequence":null,"server_hash":null,"server_timestamp":"1785204031143","session_id":"d2757dd6dad94f3b9fe67e8dbf1adc37","source":"clob_market_ws"},"received_at":"2026-07-28T02:00:33.316569Z","record_id":"854d02b9c54d7c518bede8d7bd3caf32d0a6af898cf3286f3e9169152cf238b6","schema_fingerprint":"4aa3821a28b0b7c2400bc59aba4bcc0a76e971dadd19610d3ad38c768e124dc7","schema_version":"edge-lab-recorder.raw.v1","sequence":null,"source":"clob_market_ws"}
{"event_at":"2026-07-28T02:00:31.144000Z","event_fingerprint":"71c4c18bbef4cf8b49a30c3edeb8be457baa54e3f3d182bcfc54eaca7479333e","payload":{"connection_id":"5d29200f65794d4d9ab6ef271f045a9b","event_at":"2026-07-28T02:00:31.144000Z","event_type":"best_bid_ask","frame_hash":"8cadef941ce405ecea61f5bdf6321ed9fdc330499216aad3fe172ade73ef8e96","frame_index":0,"kind":"data","monotonic_ns":306016327513791,"payload":{"asset_id":"20893381255801015515826997628594359667013752732428989472914000440642900266717","best_ask":"0.49","best_bid":"0.47","event_type":"best_bid_ask","market":"0xda6f0e0e93fc8469e0159a166028d017bddbc162b86f66bac90391379603d962","spread":"0.02","timestamp":"1785204031144"},"payload_hash":"d924e7bd344773c69ee6fa9aaad3b6a7c331912e271ed79ac3753eb75a158063","raw_frame":"{\"market\":\"0xda6f0e0e93fc8469e0159a166028d017bddbc162b86f66bac90391379603d962\", \"asset_id\":\"20893381255801015515826997628594359667013752732428989472914000440642900266717\", \"best_bid\":\"0.47\", \"best_ask\":\"0.49\", \"spread\":\"0.02\", \"timestamp\":\"1785204031144\", \"event_type\":\"best_bid_ask\"}","received_at":"2026-07-28T02:00:33.321958Z","schema_version":"clob-market-ws.best_bid_ask.v1","sequence":null,"server_hash":null,"server_timestamp":"1785204031144","session_id":"d2757dd6dad94f3b9fe67e8dbf1adc37","source":"clob_market_ws"},"received_at":"2026-07-28T02:00:33.321958Z","record_id":"edb0277b49217b2d24cd4ca9ff31574383cfe1fc7ba969ceb643a7b31cb11525","schema_fingerprint":"8488399f31b0337811b13b266be932db7062827c2470b78bd8e9e99bab51d17d","schema_version":"edge-lab-recorder.raw.v1","sequence":null,"source":"clob_market_ws"}
{"event_at":"2026-07-28T02:00:31.144000Z","event_fingerprint":"0a2a96a86b308df24bd17d712f6baa2ed9ff744eac128c40f638a17867d6d400","payload":{"connection_id":"5d29200f65794d4d9ab6ef271f045a9b","event_at":"2026-07-28T02:00:31.144000Z","event_type":"best_bid_ask","frame_hash":"3d266b21f63b92fdea426d75f667c86813a36b0eabf85c4b790de5f1748766b6","frame_index":0,"kind":"data","monotonic_ns":306016332016083,"payload":{"asset_id":"39272994714739463168905443499424551362424437245880253267329605556587274644733","best_ask":"0.53","best_bid":"0.51","event_type":"best_bid_ask","market":"0xda6f0e0e93fc8469e0159a166028d017bddbc162b86f66bac90391379603d962","spread":"0.02","timestamp":"1785204031144"},"payload_hash":"b368b64441d9615c3ffd2ae303a60283c9c04cc8b0ac78907e0bd09ea8d1e68d","raw_frame":"{\"market\":\"0xda6f0e0e93fc8469e0159a166028d017bddbc162b86f66bac90391379603d962\", \"asset_id\":\"39272994714739463168905443499424551362424437245880253267329605556587274644733\", \"best_bid\":\"0.51\", \"best_ask\":\"0.53\", \"spread\":\"0.02\", \"timestamp\":\"1785204031144\", \"event_type\":\"best_bid_ask\"}","received_at":"2026-07-28T02:00:33.326460Z","schema_version":"clob-market-ws.best_bid_ask.v1","sequence":null,"server_hash":null,"server_timestamp":"1785204031144","session_id":"d2757dd6dad94f3b9fe67e8dbf1adc37","source":"clob_market_ws"},"received_at":"2026-07-28T02:00:33.326460Z","record_id":"4103c13c752b0b39df160f1c6912108bbdf716ef5d3ae956db138b84fb7f2431","schema_fingerprint":"8488399f31b0337811b13b266be932db7062827c2470b78bd8e9e99bab51d17d","schema_version":"edge-lab-recorder.raw.v1","sequence":null,"source":"clob_market_ws"}
{"event_at":"2026-07-28T02:00:31.144000Z","event_fingerprint":"51eb44ad96da69b3eabaccdefb39ca6c57ca5c84e8ab9a9f6526b1c62d81a83e","payload":{"connection_id":"5d29200f65794d4d9ab6ef271f045a9b","event_at":"2026-07-28T02:00:31.144000Z","event_type":"price_change","frame_hash":"022fb2761f9a67942f3d5caee218ba209e6b501c5cda0087c4a4f02807f2f1ee","frame_index":0,"kind":"data","monotonic_ns":306016336102583,"payload":{"event_type":"price_change","market":"0xda6f0e0e93fc8469e0159a166028d017bddbc162b86f66bac90391379603d962","price_changes":[{"asset_id":"39272994714739463168905443499424551362424437245880253267329605556587274644733","best_ask":"0.53","best_bid":"0.51","hash":"8d4b320594419bf760b8d2c8434b50c111d900c1","price":"0.52","side":"SELL","size":"0"},{"asset_id":"20893381255801015515826997628594359667013752732428989472914000440642900266717","best_ask":"0.49","best_bid":"0.47","hash":"cc89982eadb04d957a2e8c94a73040cddc7245c9","price":"0.48","side":"BUY","size":"0"}],"timestamp":"1785204031144"},"payload_hash":"5cca35dd38107ba74e6ce11ce523bfb3e71ee3087c8555e7964f7be829ec3666","raw_frame":"{\"market\":\"0xda6f0e0e93fc8469e0159a166028d017bddbc162b86f66bac90391379603d962\", \"price_changes\":[{\"asset_id\":\"39272994714739463168905443499424551362424437245880253267329605556587274644733\", \"price\":\"0.52\", \"size\":\"0\", \"side\":\"SELL\", \"hash\":\"8d4b320594419bf760b8d2c8434b50c111d900c1\", \"best_bid\":\"0.51\", \"best_ask\":\"0.53\"}, {\"asset_id\":\"20893381255801015515826997628594359667013752732428989472914000440642900266717\", \"price\":\"0.48\", \"size\":\"0\", \"side\":\"BUY\", \"hash\":\"cc89982eadb04d957a2e8c94a73040cddc7245c9\", \"best_bid\":\"0.47\", \"best_ask\":\"0.49\"}], \"timestamp\":\"1785204031144\", \"event_type\":\"price_change\"}","received_at":"2026-07-28T02:00:33.330547Z","schema_version":"clob-market-ws.price_change.v1","sequence":null,"server_hash":null,"server_timestamp":"1785204031144","session_id":"d2757dd6dad94f3b9fe67e8dbf1adc37","source":"clob_market_ws"},"received_at":"2026-07-28T02:00:33.330547Z","record_id":"60a6636f184b3aaebebf0a5e7c31a8044a832404b7481eb6f4a73722e48b3ebb","schema_fingerprint":"4aa3821a28b0b7c2400bc59aba4bcc0a76e971dadd19610d3ad38c768e124dc7","schema_version":"edge-lab-recorder.raw.v1","sequence":null,"source":"clob_market_ws"}
{"event_at":"2026-07-28T02:00:31.158000Z","event_fingerprint":"b3f0e20837808dafe4489e85ef7e5cf6b63cd0861d3f16c543446cbde340723d","payload":{"connection_id":"5d29200f65794d4d9ab6ef271f045a9b","event_at":"2026-07-28T02:00:31.158000Z","event_type":"price_change","frame_hash":"82158befaa514cd2ccb64c25e04936721ba803df96a5fe8ac2d9c021a1cb442e","frame_index":0,"kind":"data","monotonic_ns":306016341493083,"payload":{"event_type":"price_change","market":"0xda6f0e0e93fc8469e0159a166028d017bddbc162b86f66bac90391379603d962","price_changes":[{"asset_id":"39272994714739463168905443499424551362424437245880253267329605556587274644733","best_ask":"0.53","best_bid":"0.51","hash":"e2ebd0c2ce29be9e3fad9bc419a7d2fcfe37da8f","price":"0.47","side":"BUY","size":"120.6"},{"asset_id":"20893381255801015515826997628594359667013752732428989472914000440642900266717","best_ask":"0.49","best_bid":"0.47","hash":"5b3e5284f665c94ea5a23786156867d5fa19ef6d","price":"0.53","side":"SELL","size":"120.6"}],"timestamp":"1785204031158"},"payload_hash":"d49d3abb72bb2f616f5c9a1d1788b3507fc8b2e54f42fd6e493cd71e4ffe9c38","raw_frame":"{\"market\":\"0xda6f0e0e93fc8469e0159a166028d017bddbc162b86f66bac90391379603d962\", \"price_changes\":[{\"asset_id\":\"39272994714739463168905443499424551362424437245880253267329605556587274644733\", \"price\":\"0.47\", \"size\":\"120.6\", \"side\":\"BUY\", \"hash\":\"e2ebd0c2ce29be9e3fad9bc419a7d2fcfe37da8f\", \"best_bid\":\"0.51\", \"best_ask\":\"0.53\"}, {\"asset_id\":\"20893381255801015515826997628594359667013752732428989472914000440642900266717\", \"price\":\"0.53\", \"size\":\"120.6\", \"side\":\"SELL\", \"hash\":\"5b3e5284f665c94ea5a23786156867d5fa19ef6d\", \"best_bid\":\"0.47\", \"best_ask\":\"0.49\"}], \"timestamp\":\"1785204031158\", \"event_type\":\"price_change\"}","received_at":"2026-07-28T02:00:33.335936Z","schema_version":"clob-market-ws.price_change.v1","sequence":null,"server_hash":null,"server_timestamp":"1785204031158","session_id":"d2757dd6dad94f3b9fe67e8dbf1adc37","source":"clob_market_ws"},"received_at":"2026-07-28T02:00:33.335936Z","record_id":"62c1a6ef08febd68b6f993b80d9b39a133695ae293f3fb626e2c58fb357832bd","schema_fingerprint":"4aa3821a28b0b7c2400bc59aba4bcc0a76e971dadd19610d3ad38c768e124dc7","schema_version":"edge-lab-recorder.raw.v1","sequence":null,"source":"clob_market_ws"}
{"event_at":"2026-07-28T02:00:31.159000Z","event_fingerprint":"e13eb1f53d4075b0c03a1236ea161b65659eb74714b4174d5d5044cf74f73d1c","payload":{"connection_id":"5d29200f65794d4d9ab6ef271f045a9b","event_at":"2026-07-28T02:00:31.159000Z","event_type":"price_change","frame_hash":"ed3a9f09b38170d5fb87383cc9e3a7e6e49836beaa001b6911f4361a4386720a","frame_index":0,"kind":"data","monotonic_ns":306016347537166,"payload":{"event_type":"price_change","market":"0xda6f0e0e93fc8469e0159a166028d017bddbc162b86f66bac90391379603d962","price_changes":[{"asset_id":"20893381255801015515826997628594359667013752732428989472914000440642900266717","best_ask":"0.49","best_bid":"0.47","hash":"d15334ca58b890d4a7399fdc0660e119f235f7cf","price":"0.46","side":"BUY","size":"104.6"},{"asset_id":"39272994714739463168905443499424551362424437245880253267329605556587274644733","best_ask":"0.53","best_bid":"0.51","hash":"3bd7b2c32dc3a001629eb71071020dbec886d875","price":"0.54","side":"SELL","size":"104.6"}],"timestamp":"1785204031159"},"payload_hash":"f38e16c20e7c77eea5416aff7da8e3d17d21bdb6fdddcfb10623f71df6fd32d7","raw_frame":"{\"market\":\"0xda6f0e0e93fc8469e0159a166028d017bddbc162b86f66bac90391379603d962\", \"price_changes\":[{\"asset_id\":\"20893381255801015515826997628594359667013752732428989472914000440642900266717\", \"price\":\"0.46\", \"size\":\"104.6\", \"side\":\"BUY\", \"hash\":\"d15334ca58b890d4a7399fdc0660e119f235f7cf\", \"best_bid\":\"0.47\", \"best_ask\":\"0.49\"}, {\"asset_id\":\"39272994714739463168905443499424551362424437245880253267329605556587274644733\", \"price\":\"0.54\", \"size\":\"104.6\", \"side\":\"SELL\", \"hash\":\"3bd7b2c32dc3a001629eb71071020dbec886d875\", \"best_bid\":\"0.51\", \"best_ask\":\"0.53\"}], \"timestamp\":\"1785204031159\", \"event_type\":\"price_change\"}","received_at":"2026-07-28T02:00:33.341983Z","schema_version":"clob-market-ws.price_change.v1","sequence":null,"server_hash":null,"server_timestamp":"1785204031159","session_id":"d2757dd6dad94f3b9fe67e8dbf1adc37","source":"clob_market_ws"},"received_at":"2026-07-28T02:00:33.341983Z","record_id":"ba3d9a68b278418d208dbb36747dffc8fd95786ea845b9b998742d86b694c3a5","schema_fingerprint":"4aa3821a28b0b7c2400bc59aba4bcc0a76e971dadd19610d3ad38c768e124dc7","schema_version":"edge-lab-recorder.raw.v1","sequence":null,"source":"clob_market_ws"}
{"event_at":"2026-07-28T02:00:31.168000Z","event_fingerprint":"452cad9102f4481587c8c7b9406b3899cf38b8e3b43e332aa9b6c7d039fda1c0","payload":{"connection_id":"5d29200f65794d4d9ab6ef271f045a9b","event_at":"2026-07-28T02:00:31.168000Z","event_type":"best_bid_ask","frame_hash":"70204efd14fbf75a2bed79ba72ec1838e4646d469b8f7ebcbb0af57a5dcb8579","frame_index":0,"kind":"data","monotonic_ns":306016352545125,"payload":{"asset_id":"20893381255801015515826997628594359667013752732428989472914000440642900266717","best_ask":"0.49","best_bid":"0.48","event_type":"best_bid_ask","market":"0xda6f0e0e93fc8469e0159a166028d017bddbc162b86f66bac90391379603d962","spread":"0.01","timestamp":"1785204031168"},"payload_hash":"ea4d5bafe5b84dd10d8d8b49d943543d28c41feea0440a23ab4f350cf4efeaea","raw_frame":"{\"market\":\"0xda6f0e0e93fc8469e0159a166028d017bddbc162b86f66bac90391379603d962\", \"asset_id\":\"20893381255801015515826997628594359667013752732428989472914000440642900266717\", \"best_bid\":\"0.48\", \"best_ask\":\"0.49\", \"spread\":\"0.01\", \"timestamp\":\"1785204031168\", \"event_type\":\"best_bid_ask\"}","received_at":"2026-07-28T02:00:33.346992Z","schema_version":"clob-market-ws.best_bid_ask.v1","sequence":null,"server_hash":null,"server_timestamp":"1785204031168","session_id":"d2757dd6dad94f3b9fe67e8dbf1adc37","source":"clob_market_ws"},"received_at":"2026-07-28T02:00:33.346992Z","record_id":"a0428f57dd5684de6c263f6b8528e8de428e97f4c33f87b988282a8d81eafcd4","schema_fingerprint":"8488399f31b0337811b13b266be932db7062827c2470b78bd8e9e99bab51d17d","schema_version":"edge-lab-recorder.raw.v1","sequence":null,"source":"clob_market_ws"}
{"event_at":"2026-07-28T02:00:31.168000Z","event_fingerprint":"2ed21ab3df71ae2868cc3154c7436edd32a34b5dc1b0e3b1847ee0c36c0e4fd4","payload":{"connection_id":"5d29200f65794d4d9ab6ef271f045a9b","event_at":"2026-07-28T02:00:31.168000Z","event_type":"best_bid_ask","frame_hash":"f1240f4da20a8e795fb42bf93e23d2afd6b0cec52983d5130671b17d19e694db","frame_index":0,"kind":"data","monotonic_ns":306016356476500,"payload":{"asset_id":"39272994714739463168905443499424551362424437245880253267329605556587274644733","best_ask":"0.52","best_bid":"0.51","event_type":"best_bid_ask","market":"0xda6f0e0e93fc8469e0159a166028d017bddbc162b86f66bac90391379603d962","spread":"0.01","timestamp":"1785204031168"},"payload_hash":"96f340bf20969b5df1abb0fb14a44e34d6c1d560bd23de6ec5f10d5e660e1360","raw_frame":"{\"market\":\"0xda6f0e0e93fc8469e0159a166028d017bddbc162b86f66bac90391379603d962\", \"asset_id\":\"39272994714739463168905443499424551362424437245880253267329605556587274644733\", \"best_bid\":\"0.51\", \"best_ask\":\"0.52\", \"spread\":\"0.01\", \"timestamp\":\"1785204031168\", \"event_type\":\"best_bid_ask\"}","received_at":"2026-07-28T02:00:33.350924Z","schema_version":"clob-market-ws.best_bid_ask.v1","sequence":null,"server_hash":null,"server_timestamp":"1785204031168","session_id":"d2757dd6dad94f3b9fe67e8dbf1adc37","source":"clob_market_ws"},"received_at":"2026-07-28T02:00:33.350924Z","record_id":"188463a0a3fc6e591daeea62231aca82b551953b0c42e1b5095b85f813400ed1","schema_fingerprint":"8488399f31b0337811b13b266be932db7062827c2470b78bd8e9e99bab51d17d","schema_version":"edge-lab-recorder.raw.v1","sequence":null,"source":"clob_market_ws"}
{"event_at":"2026-07-28T02:00:31.168000Z","event_fingerprint":"ee8217dd2edf7f19a245d29ca9df5c962c07ee1e2e116d180a7c7edb09bcaf11","payload":{"connection_id":"5d29200f65794d4d9ab6ef271f045a9b","event_at":"2026-07-28T02:00:31.168000Z","event_type":"price_change","frame_hash":"542f03df22a6e0656f650e1d75812b906a1850ac2aeb7403f04317358651a134","frame_index":0,"kind":"data","monotonic_ns":306016361575333,"payload":{"event_type":"price_change","market":"0xda6f0e0e93fc8469e0159a166028d017bddbc162b86f66bac90391379603d962","price_changes":[{"asset_id":"20893381255801015515826997628594359667013752732428989472914000440642900266717","best_ask":"0.49","best_bid":"0.48","hash":"e3c11dcdd5b27d1ea38d04496f616c3c460517ab","price":"0.48","side":"BUY","size":"5"},{"asset_id":"39272994714739463168905443499424551362424437245880253267329605556587274644733","best_ask":"0.52","best_bid":"0.51","hash":"90aa64b536922bdb406a05cbd1ab28c6d289c46f","price":"0.52","side":"SELL","size":"5"}],"timestamp":"1785204031168"},"payload_hash":"ead1c9a3f324e240c0abb02e5e9778a1c0181ca8399fc782f7997b49822c67dc","raw_frame":"{\"market\":\"0xda6f0e0e93fc8469e0159a166028d017bddbc162b86f66bac90391379603d962\", \"price_changes\":[{\"asset_id\":\"20893381255801015515826997628594359667013752732428989472914000440642900266717\", \"price\":\"0.48\", \"size\":\"5\", \"side\":\"BUY\", \"hash\":\"e3c11dcdd5b27d1ea38d04496f616c3c460517ab\", \"best_bid\":\"0.48\", \"best_ask\":\"0.49\"}, {\"asset_id\":\"39272994714739463168905443499424551362424437245880253267329605556587274644733\", \"price\":\"0.52\", \"size\":\"5\", \"side\":\"SELL\", \"hash\":\"90aa64b536922bdb406a05cbd1ab28c6d289c46f\", \"best_bid\":\"0.51\", \"best_ask\":\"0.52\"}], \"timestamp\":\"1785204031168\", \"event_type\":\"price_change\"}","received_at":"2026-07-28T02:00:33.356024Z","schema_version":"clob-market-ws.price_change.v1","sequence":null,"server_hash":null,"server_timestamp":"1785204031168","session_id":"d2757dd6dad94f3b9fe67e8dbf1adc37","source":"clob_market_ws"},"received_at":"2026-07-28T02:00:33.356024Z","record_id":"c3316cd2d614a477c0b4c3e9cdafeab24ddf425213992677ccf6282e10093dfd","schema_fingerprint":"4aa3821a28b0b7c2400bc59aba4bcc0a76e971dadd19610d3ad38c768e124dc7","schema_version":"edge-lab-recorder.raw.v1","sequence":null,"source":"clob_market_ws"}
{"event_at":"2026-07-28T02:00:31.169000Z","event_fingerprint":"ca3124659396a0ab5067f347800cdeebccb6971c37b2c0a101d6f8ec5b90b596","payload":{"connection_id":"5d29200f65794d4d9ab6ef271f045a9b","event_at":"2026-07-28T02:00:31.169000Z","event_type":"price_change","frame_hash":"c4c115ee128c9ac0948070696397e751ee5844319343134797585a9a27368d79","frame_index":0,"kind":"data","monotonic_ns":306016364973208,"payload":{"event_type":"price_change","market":"0xda6f0e0e93fc8469e0159a166028d017bddbc162b86f66bac90391379603d962","price_changes":[{"asset_id":"20893381255801015515826997628594359667013752732428989472914000440642900266717","best_ask":"0.49","best_bid":"0.48","hash":"ac0363d7a3a4309b79055788548ca4d2ae83c163","price":"0.47","side":"BUY","size":"90.06"},{"asset_id":"39272994714739463168905443499424551362424437245880253267329605556587274644733","best_ask":"0.52","best_bid":"0.51","hash":"2bb3e48f9506006373acad9475e22e0f02c9ad0d","price":"0.53","side":"SELL","size":"90.06"}],"timestamp":"1785204031169"},"payload_hash":"5d16b19bf9af06e44a40f66fc43f6212377f1e12f03a7bc1fb0552eac4a9a83c","raw_frame":"{\"market\":\"0xda6f0e0e93fc8469e0159a166028d017bddbc162b86f66bac90391379603d962\", \"price_changes\":[{\"asset_id\":\"20893381255801015515826997628594359667013752732428989472914000440642900266717\", \"price\":\"0.47\", \"size\":\"90.06\", \"side\":\"BUY\", \"hash\":\"ac0363d7a3a4309b79055788548ca4d2ae83c163\", \"best_bid\":\"0.48\", \"best_ask\":\"0.49\"}, {\"asset_id\":\"39272994714739463168905443499424551362424437245880253267329605556587274644733\", \"price\":\"0.53\", \"size\":\"90.06\", \"side\":\"SELL\", \"hash\":\"2bb3e48f9506006373acad9475e22e0f02c9ad0d\", \"best_bid\":\"0.51\", \"best_ask\":\"0.52\"}], \"timestamp\":\"1785204031169\", \"event_type\":\"price_change\"}","received_at":"2026-07-28T02:00:33.359422Z","schema_version":"clob-market-ws.price_change.v1","sequence":null,"server_hash":null,"server_timestamp":"1785204031169","session_id":"d2757dd6dad94f3b9fe67e8dbf1adc37","source":"clob_market_ws"},"received_at":"2026-07-28T02:00:33.359422Z","record_id":"8066f118683ebdc466b780b487631cfa3e14c11640715a41f739b0752eca15a5","schema_fingerprint":"4aa3821a28b0b7c2400bc59aba4bcc0a76e971dadd19610d3ad38c768e124dc7","schema_version":"edge-lab-recorder.raw.v1","sequence":null,"source":"clob_market_ws"}
{"event_at":"2026-07-28T02:00:31.170000Z","event_fingerprint":"9cfcbfb121803d2a9a94365d5bffbaa81dfc794732f4bea9932680a2e1cb74a5","payload":{"connection_id":"5d29200f65794d4d9ab6ef271f045a9b","event_at":"2026-07-28T02:00:31.170000Z","event_type":"price_change","frame_hash":"bcdd5d6af70e35f1ba9c60fa6c89a21d30448baa4ea10c57ad2e687cb6e5e699","frame_index":0,"kind":"data","monotonic_ns":306016369371833,"payload":{"event_type":"price_change","market":"0xda6f0e0e93fc8469e0159a166028d017bddbc162b86f66bac90391379603d962","price_changes":[{"asset_id":"20893381255801015515826997628594359667013752732428989472914000440642900266717","best_ask":"0.49","best_bid":"0.48","hash":"0f10e089ea292ae19727d07eb712ffd8b9d44a7b","price":"0.48","side":"BUY","size":"11"},{"asset_id":"39272994714739463168905443499424551362424437245880253267329605556587274644733","best_ask":"0.52","best_bid":"0.51","hash":"ec5c9ebd004548a57388842fc4a59244593cefd4","price":"0.52","side":"SELL","size":"11"}],"timestamp":"1785204031170"},"payload_hash":"6c0d899a1bf240611ba3b469ff809371d57897d3b8a33fba944727c1d89b5ee2","raw_frame":"{\"market\":\"0xda6f0e0e93fc8469e0159a166028d017bddbc162b86f66bac90391379603d962\", \"price_changes\":[{\"asset_id\":\"20893381255801015515826997628594359667013752732428989472914000440642900266717\", \"price\":\"0.48\", \"size\":\"11\", \"side\":\"BUY\", \"hash\":\"0f10e089ea292ae19727d07eb712ffd8b9d44a7b\", \"best_bid\":\"0.48\", \"best_ask\":\"0.49\"}, {\"asset_id\":\"39272994714739463168905443499424551362424437245880253267329605556587274644733\", \"price\":\"0.52\", \"size\":\"11\", \"side\":\"SELL\", \"hash\":\"ec5c9ebd004548a57388842fc4a59244593cefd4\", \"best_bid\":\"0.51\", \"best_ask\":\"0.52\"}], \"timestamp\":\"1785204031170\", \"event_type\":\"price_change\"}","received_at":"2026-07-28T02:00:33.363821Z","schema_version":"clob-market-ws.price_change.v1","sequence":null,"server_hash":null,"server_timestamp":"1785204031170","session_id":"d2757dd6dad94f3b9fe67e8dbf1adc37","source":"clob_market_ws"},"received_at":"2026-07-28T02:00:33.363821Z","record_id":"b991ea295b09e5ea42c346ea41e61730e4ac632c914fa42d13daf5b1b9118bae","schema_fingerprint":"4aa3821a28b0b7c2400bc59aba4bcc0a76e971dadd19610d3ad38c768e124dc7","schema_version":"edge-lab-recorder.raw.v1","sequence":null,"source":"clob_market_ws"}
{"event_at":"2026-07-28T02:00:31.174000Z","event_fingerprint":"afe6664a6bcb5a823cfe211bcdf4b4f8ee68d26df68526a35ac79f304fedffdd","payload":{"connection_id":"5d29200f65794d4d9ab6ef271f045a9b","event_at":"2026-07-28T02:00:31.174000Z","event_type":"price_change","frame_hash":"86fb99dd790fba23648966b3d13ad03d36b53fbca4de9e150fdd57dfbc49ee83","frame_index":0,"kind":"data","monotonic_ns":306016379121833,"payload":{"event_type":"price_change","market":"0xda6f0e0e93fc8469e0159a166028d017bddbc162b86f66bac90391379603d962","price_changes":[{"asset_id":"39272994714739463168905443499424551362424437245880253267329605556587274644733","best_ask":"0.52","best_bid":"0.51","hash":"3bbd0e0967c113d9fae661bd1d64849315418774","price":"0.47","side":"BUY","size":"105.6"},{"asset_id":"20893381255801015515826997628594359667013752732428989472914000440642900266717","best_ask":"0.49","best_bid":"0.48","hash":"477bb797c8141a4980c8a1c99ea5c7ab1604790f","price":"0.53","side":"SELL","size":"105.6"}],"timestamp":"1785204031174"},"payload_hash":"f06b3662bd871a7b635207413e7e5b61d1e378943950bed003cd3e0af9e69b4b","raw_frame":"{\"market\":\"0xda6f0e0e93fc8469e0159a166028d017bddbc162b86f66bac90391379603d962\", \"price_changes\":[{\"asset_id\":\"39272994714739463168905443499424551362424437245880253267329605556587274644733\", \"price\":\"0.47\", \"size\":\"105.6\", \"side\":\"BUY\", \"hash\":\"3bbd0e0967c113d9fae661bd1d64849315418774\", \"best_bid\":\"0.51\", \"best_ask\":\"0.52\"}, {\"asset_id\":\"20893381255801015515826997628594359667013752732428989472914000440642900266717\", \"price\":\"0.53\", \"size\":\"105.6\", \"side\":\"SELL\", \"hash\":\"477bb797c8141a4980c8a1c99ea5c7ab1604790f\", \"best_bid\":\"0.48\", \"best_ask\":\"0.49\"}], \"timestamp\":\"1785204031174\", \"event_type\":\"price_change\"}","received_at":"2026-07-28T02:00:33.373572Z","schema_version":"clob-market-ws.price_change.v1","sequence":null,"server_hash":null,"server_timestamp":"1785204031174","session_id":"d2757dd6dad94f3b9fe67e8dbf1adc37","source":"clob_market_ws"},"received_at":"2026-07-28T02:00:33.373572Z","record_id":"b06007b215ff932e04a4cfe51cb3e799c9905d589095a45acdc3a8bfd9dc0972","schema_fingerprint":"4aa3821a28b0b7c2400bc59aba4bcc0a76e971dadd19610d3ad38c768e124dc7","schema_version":"edge-lab-recorder.raw.v1","sequence":null,"source":"clob_market_ws"}
{"event_at":"2026-07-28T02:00:31.181000Z","event_fingerprint":"eb006fe159e22d6e335c6e8e2ee9bca7a0d74110d57b0f2122de0c5b6318b749","payload":{"connection_id":"5d29200f65794d4d9ab6ef271f045a9b","event_at":"2026-07-28T02:00:31.181000Z","event_type":"price_change","frame_hash":"c7ba486546e65b1e8dc964e6373dc67a14bffdd14a96a9387fc98378ff11fe29","frame_index":0,"kind":"data","monotonic_ns":306016387930666,"payload":{"event_type":"price_change","market":"0xda6f0e0e93fc8469e0159a166028d017bddbc162b86f66bac90391379603d962","price_changes":[{"asset_id":"39272994714739463168905443499424551362424437245880253267329605556587274644733","best_ask":"0.52","best_bid":"0.51","hash":"6ede24e8347e3f5053f887833c656c9f63d34ad0","price":"0.42","side":"BUY","size":"137"},{"asset_id":"20893381255801015515826997628594359667013752732428989472914000440642900266717","best_ask":"0.49","best_bid":"0.48","hash":"aa545053259fb55ab4e7c1669817004be19224b1","price":"0.58","side":"SELL","size":"137"}],"timestamp":"1785204031181"},"payload_hash":"2694d3aea9f0af145c5f27132fbf89a9ecd7d4152c166123de3b3af0f109669b","raw_frame":"{\"market\":\"0xda6f0e0e93fc8469e0159a166028d017bddbc162b86f66bac90391379603d962\", \"price_changes\":[{\"asset_id\":\"39272994714739463168905443499424551362424437245880253267329605556587274644733\", \"price\":\"0.42\", \"size\":\"137\", \"side\":\"BUY\", \"hash\":\"6ede24e8347e3f5053f887833c656c9f63d34ad0\", \"best_bid\":\"0.51\", \"best_ask\":\"0.52\"}, {\"asset_id\":\"20893381255801015515826997628594359667013752732428989472914000440642900266717\", \"price\":\"0.58\", \"size\":\"137\", \"side\":\"SELL\", \"hash\":\"aa545053259fb55ab4e7c1669817004be19224b1\", \"best_bid\":\"0.48\", \"best_ask\":\"0.49\"}], \"timestamp\":\"1785204031181\", \"event_type\":\"price_change\"}","received_at":"2026-07-28T02:00:33.382382Z","schema_version":"clob-market-ws.price_change.v1","sequence":null,"server_hash":null,"server_timestamp":"1785204031181","session_id":"d2757dd6dad94f3b9fe67e8dbf1adc37","source":"clob_market_ws"},"received_at":"2026-07-28T02:00:33.382382Z","record_id":"da7d421faa1a5e25d0919689a36058d5503283ec77610c58a72e742eccc32e1f","schema_fingerprint":"4aa3821a28b0b7c2400bc59aba4bcc0a76e971dadd19610d3ad38c768e124dc7","schema_version":"edge-lab-recorder.raw.v1","sequence":null,"source":"clob_market_ws"}
{"event_at":"2026-07-28T02:00:31.182000Z","event_fingerprint":"50da4fe745861a8417b35dd186977275a1fa1d598341f7c16b3193c43f571319","payload":{"connection_id":"5d29200f65794d4d9ab6ef271f045a9b","event_at":"2026-07-28T02:00:31.182000Z","event_type":"price_change","frame_hash":"abcb502fe9285b653220ab58ff618368e4d8985810eba7dde40e20f3b674e4be","frame_index":0,"kind":"data","monotonic_ns":306016397381833,"payload":{"event_type":"price_change","market":"0xda6f0e0e93fc8469e0159a166028d017bddbc162b86f66bac90391379603d962","price_changes":[{"asset_id":"39272994714739463168905443499424551362424437245880253267329605556587274644733","best_ask":"0.52","best_bid":"0.51","hash":"440b25a1f4985d3ff074903f6ac0bad5d4f22139","price":"0.52","side":"SELL","size":"17"},{"asset_id":"20893381255801015515826997628594359667013752732428989472914000440642900266717","best_ask":"0.49","best_bid":"0.48","hash":"a567dcad776f819f377af626bd7b39f66a9b6694","price":"0.48","side":"BUY","size":"17"}],"timestamp":"1785204031182"},"payload_hash":"8739a33acc29db07e02826fcb7a2f19d20a833423ac4d7698249b30534112fab","raw_frame":"{\"market\":\"0xda6f0e0e93fc8469e0159a166028d017bddbc162b86f66bac90391379603d962\", \"price_changes\":[{\"asset_id\":\"39272994714739463168905443499424551362424437245880253267329605556587274644733\", \"price\":\"0.52\", \"size\":\"17\", \"side\":\"SELL\", \"hash\":\"440b25a1f4985d3ff074903f6ac0bad5d4f22139\", \"best_bid\":\"0.51\", \"best_ask\":\"0.52\"}, {\"asset_id\":\"20893381255801015515826997628594359667013752732428989472914000440642900266717\", \"price\":\"0.48\", \"size\":\"17\", \"side\":\"BUY\", \"hash\":\"a567dcad776f819f377af626bd7b39f66a9b6694\", \"best_bid\":\"0.48\", \"best_ask\":\"0.49\"}], \"timestamp\":\"1785204031182\", \"event_type\":\"price_change\"}","received_at":"2026-07-28T02:00:33.391835Z","schema_version":"clob-market-ws.price_change.v1","sequence":null,"server_hash":null,"server_timestamp":"1785204031182","session_id":"d2757dd6dad94f3b9fe67e8dbf1adc37","source":"clob_market_ws"},"received_at":"2026-07-28T02:00:33.391835Z","record_id":"6fcf8210669f30ca9cff811d0f24bfc471addfb1ce23a5dba09946b36d9b60b6","schema_fingerprint":"4aa3821a28b0b7c2400bc59aba4bcc0a76e971dadd19610d3ad38c768e124dc7","schema_version":"edge-lab-recorder.raw.v1","sequence":null,"source":"clob_market_ws"}
{"event_at":"2026-07-28T02:00:31.185000Z","event_fingerprint":"28e5b30a6ff2987bbe323bf5b9fe2f56806100c44eb11f34a4f19801b6f2294e","payload":{"connection_id":"5d29200f65794d4d9ab6ef271f045a9b","event_at":"2026-07-28T02:00:31.185000Z","event_type":"price_change","frame_hash":"fa13516aebcf5728b5ef4ca901146f631dfa313b9d4e29e116a47f5be811596a","frame_index":0,"kind":"data","monotonic_ns":306016404540916,"payload":{"event_type":"price_change","market":"0xda6f0e0e93fc8469e0159a166028d017bddbc162b86f66bac90391379603d962","price_changes":[{"asset_id":"20893381255801015515826997628594359667013752732428989472914000440642900266717","best_ask":"0.49","best_bid":"0.48","hash":"deceb9f9aaa88e65813842fed698a0952e6345b9","price":"0.48","side":"BUY","size":"12"},{"asset_id":"39272994714739463168905443499424551362424437245880253267329605556587274644733","best_ask":"0.52","best_bid":"0.51","hash":"7b2255c3d5f28f73eefdbdad89d11aa736fa53a6","price":"0.52","side":"SELL","size":"12"}],"timestamp":"1785204031185"},"payload_hash":"3f961c5c53ea74cb4aa07dad785d22d3803b671eea195d4696da6ac4a8dbbe2b","raw_frame":"{\"market\":\"0xda6f0e0e93fc8469e0159a166028d017bddbc162b86f66bac90391379603d962\", \"price_changes\":[{\"asset_id\":\"20893381255801015515826997628594359667013752732428989472914000440642900266717\", \"price\":\"0.48\", \"size\":\"12\", \"side\":\"BUY\", \"hash\":\"deceb9f9aaa88e65813842fed698a0952e6345b9\", \"best_bid\":\"0.48\", \"best_ask\":\"0.49\"}, {\"asset_id\":\"39272994714739463168905443499424551362424437245880253267329605556587274644733\", \"price\":\"0.52\", \"size\":\"12\", \"side\":\"SELL\", \"hash\":\"7b2255c3d5f28f73eefdbdad89d11aa736fa53a6\", \"best_bid\":\"0.51\", \"best_ask\":\"0.52\"}], \"timestamp\":\"1785204031185\", \"event_type\":\"price_change\"}","received_at":"2026-07-28T02:00:33.398993Z","schema_version":"clob-market-ws.price_change.v1","sequence":null,"server_hash":null,"server_timestamp":"1785204031185","session_id":"d2757dd6dad94f3b9fe67e8dbf1adc37","source":"clob_market_ws"},"received_at":"2026-07-28T02:00:33.398993Z","record_id":"0b0664ec0f4ca62d641053b4cda0c21f58d5c82d8afb593cbe9bca4444365eb1","schema_fingerprint":"4aa3821a28b0b7c2400bc59aba4bcc0a76e971dadd19610d3ad38c768e124dc7","schema_version":"edge-lab-recorder.raw.v1","sequence":null,"source":"clob_market_ws"}
{"event_at":"2026-07-28T02:00:31.187000Z","event_fingerprint":"2fa3190cc5d7456edb2e8698511f7d02d75f3201c29bf46be41674e0c5886612","payload":{"connection_id":"5d29200f65794d4d9ab6ef271f045a9b","event_at":"2026-07-28T02:00:31.187000Z","event_type":"price_change","frame_hash":"cfaab88bab8b051e3e719b32c40fbc8ee070f6180278f85ec47b3acec57fe786","frame_index":0,"kind":"data","monotonic_ns":306016409056750,"payload":{"event_type":"price_change","market":"0xda6f0e0e93fc8469e0159a166028d017bddbc162b86f66bac90391379603d962","price_changes":[{"asset_id":"20893381255801015515826997628594359667013752732428989472914000440642900266717","best_ask":"0.49","best_bid":"0.48","hash":"027c748c94bedf953c5069cf65133cc994b56ac7","price":"0.48","side":"BUY","size":"6"},{"asset_id":"39272994714739463168905443499424551362424437245880253267329605556587274644733","best_ask":"0.52","best_bid":"0.51","hash":"6441510194386107a484647f97949ca7a5582121","price":"0.52","side":"SELL","size":"6"}],"timestamp":"1785204031187"},"payload_hash":"15f337b406b2087426ec1e32f5d1822d22f02f74788812091b9250abef491011","raw_frame":"{\"market\":\"0xda6f0e0e93fc8469e0159a166028d017bddbc162b86f66bac90391379603d962\", \"price_changes\":[{\"asset_id\":\"20893381255801015515826997628594359667013752732428989472914000440642900266717\", \"price\":\"0.48\", \"size\":\"6\", \"side\":\"BUY\", \"hash\":\"027c748c94bedf953c5069cf65133cc994b56ac7\", \"best_bid\":\"0.48\", \"best_ask\":\"0.49\"}, {\"asset_id\":\"39272994714739463168905443499424551362424437245880253267329605556587274644733\", \"price\":\"0.52\", \"size\":\"6\", \"side\":\"SELL\", \"hash\":\"6441510194386107a484647f97949ca7a5582121\", \"best_bid\":\"0.51\", \"best_ask\":\"0.52\"}], \"timestamp\":\"1785204031187\", \"event_type\":\"price_change\"}","received_at":"2026-07-28T02:00:33.403512Z","schema_version":"clob-market-ws.price_change.v1","sequence":null,"server_hash":null,"server_timestamp":"1785204031187","session_id":"d2757dd6dad94f3b9fe67e8dbf1adc37","source":"clob_market_ws"},"received_at":"2026-07-28T02:00:33.403512Z","record_id":"56f31fdba0c5ed21e3eb531db8506523f8277862d3e3da7061c05c6e9a32004f","schema_fingerprint":"4aa3821a28b0b7c2400bc59aba4bcc0a76e971dadd19610d3ad38c768e124dc7","schema_version":"edge-lab-recorder.raw.v1","sequence":null,"source":"clob_market_ws"}
{"event_at":"2026-07-28T02:00:31.187000Z","event_fingerprint":"d4063418c189b6c46d6142de593c0acba6983ffac467ff910026d07e6531d388","payload":{"connection_id":"5d29200f65794d4d9ab6ef271f045a9b","event_at":"2026-07-28T02:00:31.187000Z","event_type":"best_bid_ask","frame_hash":"8e51b3fd5f430b7aa58d395d4fb4904cb613530d0a93142714df3d715599a047","frame_index":0,"kind":"data","monotonic_ns":306016414930583,"payload":{"asset_id":"20893381255801015515826997628594359667013752732428989472914000440642900266717","best_ask":"0.49","best_bid":"0.47","event_type":"best_bid_ask","market":"0xda6f0e0e93fc8469e0159a166028d017bddbc162b86f66bac90391379603d962","spread":"0.02","timestamp":"1785204031187"},"payload_hash":"1f50ef3755779fba0b8be1b60c3962308b74430bcd3b1b1929a3a65cf8ebea78","raw_frame":"{\"market\":\"0xda6f0e0e93fc8469e0159a166028d017bddbc162b86f66bac90391379603d962\", \"asset_id\":\"20893381255801015515826997628594359667013752732428989472914000440642900266717\", \"best_bid\":\"0.47\", \"best_ask\":\"0.49\", \"spread\":\"0.02\", \"timestamp\":\"1785204031187\", \"event_type\":\"best_bid_ask\"}","received_at":"2026-07-28T02:00:33.409386Z","schema_version":"clob-market-ws.best_bid_ask.v1","sequence":null,"server_hash":null,"server_timestamp":"1785204031187","session_id":"d2757dd6dad94f3b9fe67e8dbf1adc37","source":"clob_market_ws"},"received_at":"2026-07-28T02:00:33.409386Z","record_id":"6a27b07ad1e4825bc07fd3942d3d8c748afa98ca3c0a126b3557f18575f959eb","schema_fingerprint":"8488399f31b0337811b13b266be932db7062827c2470b78bd8e9e99bab51d17d","schema_version":"edge-lab-recorder.raw.v1","sequence":null,"source":"clob_market_ws"}
{"event_at":"2026-07-28T02:00:31.187000Z","event_fingerprint":"3bccc7ee6b2eaeac37c2a1b1f376f0b8487037e1655be23aa0eb37882d1f1957","payload":{"connection_id":"5d29200f65794d4d9ab6ef271f045a9b","event_at":"2026-07-28T02:00:31.187000Z","event_type":"best_bid_ask","frame_hash":"42c75d89e9b2dfca49d3959dd485a4f245fbca2feb1044289b545a0723f6d4b8","frame_index":0,"kind":"data","monotonic_ns":306016420312291,"payload":{"asset_id":"39272994714739463168905443499424551362424437245880253267329605556587274644733","best_ask":"0.53","best_bid":"0.51","event_type":"best_bid_ask","market":"0xda6f0e0e93fc8469e0159a166028d017bddbc162b86f66bac90391379603d962","spread":"0.02","timestamp":"1785204031187"},"payload_hash":"a02aaa61ec74e3f449563569df0f3078ca040d580f6f70e605334d9ef9dd8ae8","raw_frame":"{\"market\":\"0xda6f0e0e93fc8469e0159a166028d017bddbc162b86f66bac90391379603d962\", \"asset_id\":\"39272994714739463168905443499424551362424437245880253267329605556587274644733\", \"best_bid\":\"0.51\", \"best_ask\":\"0.53\", \"spread\":\"0.02\", \"timestamp\":\"1785204031187\", \"event_type\":\"best_bid_ask\"}","received_at":"2026-07-28T02:00:33.414768Z","schema_version":"clob-market-ws.best_bid_ask.v1","sequence":null,"server_hash":null,"server_timestamp":"1785204031187","session_id":"d2757dd6dad94f3b9fe67e8dbf1adc37","source":"clob_market_ws"},"received_at":"2026-07-28T02:00:33.414768Z","record_id":"5d9f1018487eeb9c83e0fff810db88addf314b37340ac7cea0dc699ae8c22ff2","schema_fingerprint":"8488399f31b0337811b13b266be932db7062827c2470b78bd8e9e99bab51d17d","schema_version":"edge-lab-recorder.raw.v1","sequence":null,"source":"clob_market_ws"}
{"event_at":"2026-07-28T02:00:31.187000Z","event_fingerprint":"f6fa834d4d28ccb1de22021b1ecfc2c179b35c4e98f6aaf25b982e770b326807","payload":{"connection_id":"5d29200f65794d4d9ab6ef271f045a9b","event_at":"2026-07-28T02:00:31.187000Z","event_type":"price_change","frame_hash":"66fce6bd1ecd6b9c32e90e380410fad7f4a9d0739f043290dcd88703c9eb443a","frame_index":0,"kind":"data","monotonic_ns":306016425642250,"payload":{"event_type":"price_change","market":"0xda6f0e0e93fc8469e0159a166028d017bddbc162b86f66bac90391379603d962","price_changes":[{"asset_id":"39272994714739463168905443499424551362424437245880253267329605556587274644733","best_ask":"0.53","best_bid":"0.51","hash":"72cf8c87751d4f330db442742c81c6d914e320f2","price":"0.52","side":"SELL","size":"0"},{"asset_id":"20893381255801015515826997628594359667013752732428989472914000440642900266717","best_ask":"0.49","best_bid":"0.47","hash":"63e61a70693d045ebb44bc008053a8bf48135a5e","price":"0.48","side":"BUY","size":"0"}],"timestamp":"1785204031187"},"payload_hash":"5b6404ccbbcb0c0795793200bd0c7e85e05df43c0c90c5f80d5dd699fa507e26","raw_frame":"{\"market\":\"0xda6f0e0e93fc8469e0159a166028d017bddbc162b86f66bac90391379603d962\", \"price_changes\":[{\"asset_id\":\"39272994714739463168905443499424551362424437245880253267329605556587274644733\", \"price\":\"0.52\", \"size\":\"0\", \"side\":\"SELL\", \"hash\":\"72cf8c87751d4f330db442742c81c6d914e320f2\", \"best_bid\":\"0.51\", \"best_ask\":\"0.53\"}, {\"asset_id\":\"20893381255801015515826997628594359667013752732428989472914000440642900266717\", \"price\":\"0.48\", \"size\":\"0\", \"side\":\"BUY\", \"hash\":\"63e61a70693d045ebb44bc008053a8bf48135a5e\", \"best_bid\":\"0.47\", \"best_ask\":\"0.49\"}], \"timestamp\":\"1785204031187\", \"event_type\":\"price_change\"}","received_at":"2026-07-28T02:00:33.420098Z","schema_version":"clob-market-ws.price_change.v1","sequence":null,"server_hash":null,"server_timestamp":"1785204031187","session_id":"d2757dd6dad94f3b9fe67e8dbf1adc37","source":"clob_market_ws"},"received_at":"2026-07-28T02:00:33.420098Z","record_id":"66a3ab3cf0d97c61996b7f36943eae368a7f962a5e7725fc7f4a42c20cf3af86","schema_fingerprint":"4aa3821a28b0b7c2400bc59aba4bcc0a76e971dadd19610d3ad38c768e124dc7","schema_version":"edge-lab-recorder.raw.v1","sequence":null,"source":"clob_market_ws"}
{"event_at":"2026-07-28T02:00:31.196000Z","event_fingerprint":"59d1110439c3586cf2e6a911a7f9adad714bce19cf3fe675bcfa63f2bb7fee87","payload":{"connection_id":"5d29200f65794d4d9ab6ef271f045a9b","event_at":"2026-07-28T02:00:31.196000Z","event_type":"price_change","frame_hash":"8ff17554fec36dfc706cb735df51403d73006479538bc265b2e4465b857c3b14","frame_index":0,"kind":"data","monotonic_ns":306016431389958,"payload":{"event_type":"price_change","market":"0xda6f0e0e93fc8469e0159a166028d017bddbc162b86f66bac90391379603d962","price_changes":[{"asset_id":"39272994714739463168905443499424551362424437245880253267329605556587274644733","best_ask":"0.53","best_bid":"0.51","hash":"2b2442360ca14a598b8b78318a863b0e3f8a8d10","price":"0.03","side":"BUY","size":"1196.43"},{"asset_id":"20893381255801015515826997628594359667013752732428989472914000440642900266717","best_ask":"0.49","best_bid":"0.47","hash":"96d3630d2564fb6b8a8cb23e33d4616ff7d93f39","price":"0.97","side":"SELL","size":"1196.43"}],"timestamp":"1785204031196"},"payload_hash":"6540d8d4ac8e9c83881955c87e9632aa2d15b77ff0a38a581e3eee81048d66bb","raw_frame":"{\"market\":\"0xda6f0e0e93fc8469e0159a166028d017bddbc162b86f66bac90391379603d962\", \"price_changes\":[{\"asset_id\":\"39272994714739463168905443499424551362424437245880253267329605556587274644733\", \"price\":\"0.03\", \"size\":\"1196.43\", \"side\":\"BUY\", \"hash\":\"2b2442360ca14a598b8b78318a863b0e3f8a8d10\", \"best_bid\":\"0.51\", \"best_ask\":\"0.53\"}, {\"asset_id\":\"20893381255801015515826997628594359667013752732428989472914000440642900266717\", \"price\":\"0.97\", \"size\":\"1196.43\", \"side\":\"SELL\", \"hash\":\"96d3630d2564fb6b8a8cb23e33d4616ff7d93f39\", \"best_bid\":\"0.47\", \"best_ask\":\"0.49\"}], \"timestamp\":\"1785204031196\", \"event_type\":\"price_change\"}","received_at":"2026-07-28T02:00:33.425847Z","schema_version":"clob-market-ws.price_change.v1","sequence":null,"server_hash":null,"server_timestamp":"1785204031196","session_id":"d2757dd6dad94f3b9fe67e8dbf1adc37","source":"clob_market_ws"},"received_at":"2026-07-28T02:00:33.425847Z","record_id":"cc46ba4f37ee3656d93abb9d56358c536637d8d8bd3296730fa861ece78ced1e","schema_fingerprint":"4aa3821a28b0b7c2400bc59aba4bcc0a76e971dadd19610d3ad38c768e124dc7","schema_version":"edge-lab-recorder.raw.v1","sequence":null,"source":"clob_market_ws"}
{"event_at":"2026-07-28T02:00:31.203000Z","event_fingerprint":"834efdd7e8b19c02e45ed8a65c73a1c112390af611ad2f41b0c9fe71d49ea796","payload":{"connection_id":"5d29200f65794d4d9ab6ef271f045a9b","event_at":"2026-07-28T02:00:31.203000Z","event_type":"best_bid_ask","frame_hash":"2924cd43bd6d670fbd6deb1e775b8c04acfdb57b8035f345f93e2e3eaabdb0d5","frame_index":0,"kind":"data","monotonic_ns":306016437286708,"payload":{"asset_id":"20893381255801015515826997628594359667013752732428989472914000440642900266717","best_ask":"0.48","best_bid":"0.47","event_type":"best_bid_ask","market":"0xda6f0e0e93fc8469e0159a166028d017bddbc162b86f66bac90391379603d962","spread":"0.01","timestamp":"1785204031203"},"payload_hash":"8c48e083eb08ab0e2fd82f8b2dcfd45021a3932cde678204966b21b3c673b3d8","raw_frame":"{\"market\":\"0xda6f0e0e93fc8469e0159a166028d017bddbc162b86f66bac90391379603d962\", \"asset_id\":\"20893381255801015515826997628594359667013752732428989472914000440642900266717\", \"best_bid\":\"0.47\", \"best_ask\":\"0.48\", \"spread\":\"0.01\", \"timestamp\":\"1785204031203\", \"event_type\":\"best_bid_ask\"}","received_at":"2026-07-28T02:00:33.431742Z","schema_version":"clob-market-ws.best_bid_ask.v1","sequence":null,"server_hash":null,"server_timestamp":"1785204031203","session_id":"d2757dd6dad94f3b9fe67e8dbf1adc37","source":"clob_market_ws"},"received_at":"2026-07-28T02:00:33.431742Z","record_id":"d7738a986cf62ab184fbead2dc019727388f24808870002287e5b5d586a88866","schema_fingerprint":"8488399f31b0337811b13b266be932db7062827c2470b78bd8e9e99bab51d17d","schema_version":"edge-lab-recorder.raw.v1","sequence":null,"source":"clob_market_ws"}
{"event_at":"2026-07-28T02:00:31.203000Z","event_fingerprint":"38926c4fcea48f4c95eebd32cfe33ef6380629bdc16ab10e45a7c5e40f3e1a0a","payload":{"connection_id":"5d29200f65794d4d9ab6ef271f045a9b","event_at":"2026-07-28T02:00:31.203000Z","event_type":"best_bid_ask","frame_hash":"657403e650e972601226e24dbc27b70c0e5094e00b6b26efa89d32a71f27667b","frame_index":0,"kind":"data","monotonic_ns":306016441401833,"payload":{"asset_id":"39272994714739463168905443499424551362424437245880253267329605556587274644733","best_ask":"0.53","best_bid":"0.52","event_type":"best_bid_ask","market":"0xda6f0e0e93fc8469e0159a166028d017bddbc162b86f66bac90391379603d962","spread":"0.01","timestamp":"1785204031203"},"payload_hash":"4b91bfc979b719b8df92b361a01daf4c5def7561183c7206e3148233be3c7731","raw_frame":"{\"market\":\"0xda6f0e0e93fc8469e0159a166028d017bddbc162b86f66bac90391379603d962\", \"asset_id\":\"39272994714739463168905443499424551362424437245880253267329605556587274644733\", \"best_bid\":\"0.52\", \"best_ask\":\"0.53\", \"spread\":\"0.01\", \"timestamp\":\"1785204031203\", \"event_type\":\"best_bid_ask\"}","received_at":"2026-07-28T02:00:33.435860Z","schema_version":"clob-market-ws.best_bid_ask.v1","sequence":null,"server_hash":null,"server_timestamp":"1785204031203","session_id":"d2757dd6dad94f3b9fe67e8dbf1adc37","source":"clob_market_ws"},"received_at":"2026-07-28T02:00:33.435860Z","record_id":"e194dfe15bf692137d0718299137c3de8a8aa328f0dfff27fcccf576e5c50abe","schema_fingerprint":"8488399f31b0337811b13b266be932db7062827c2470b78bd8e9e99bab51d17d","schema_version":"edge-lab-recorder.raw.v1","sequence":null,"source":"clob_market_ws"}
{"event_at":"2026-07-28T02:00:31.203000Z","event_fingerprint":"4b62e482a0359c870c00c4e97bc1eb437501b8ab2b79628d444e772ae1c1611d","payload":{"connection_id":"5d29200f65794d4d9ab6ef271f045a9b","event_at":"2026-07-28T02:00:31.203000Z","event_type":"price_change","frame_hash":"7e6ad4c49697987d3d8328832fcfae227499a817988e5080c884ddf9b19f14b9","frame_index":0,"kind":"data","monotonic_ns":306016445565000,"payload":{"event_type":"price_change","market":"0xda6f0e0e93fc8469e0159a166028d017bddbc162b86f66bac90391379603d962","price_changes":[{"asset_id":"39272994714739463168905443499424551362424437245880253267329605556587274644733","best_ask":"0.53","best_bid":"0.52","hash":"a70c23896f46fd7aa5d3cc5c57cae2f82457e82e","price":"0.52","side":"BUY","size":"15"},{"asset_id":"20893381255801015515826997628594359667013752732428989472914000440642900266717","best_ask":"0.48","best_bid":"0.47","hash":"3c0544e80070b602262e11300d73e411b2c89096","price":"0.48","side":"SELL","size":"15"}],"timestamp":"1785204031203"},"payload_hash":"b1981f16b84777862bcef8312e7727b96c18f5928b33b6dc66bdb480154e4f3e","raw_frame":"{\"market\":\"0xda6f0e0e93fc8469e0159a166028d017bddbc162b86f66bac90391379603d962\", \"price_changes\":[{\"asset_id\":\"39272994714739463168905443499424551362424437245880253267329605556587274644733\", \"price\":\"0.52\", \"size\":\"15\", \"side\":\"BUY\", \"hash\":\"a70c23896f46fd7aa5d3cc5c57cae2f82457e82e\", \"best_bid\":\"0.52\", \"best_ask\":\"0.53\"}, {\"asset_id\":\"20893381255801015515826997628594359667013752732428989472914000440642900266717\", \"price\":\"0.48\", \"size\":\"15\", \"side\":\"SELL\", \"hash\":\"3c0544e80070b602262e11300d73e411b2c89096\", \"best_bid\":\"0.47\", \"best_ask\":\"0.48\"}], \"timestamp\":\"1785204031203\", \"event_type\":\"price_change\"}","received_at":"2026-07-28T02:00:33.440025Z","schema_version":"clob-market-ws.price_change.v1","sequence":null,"server_hash":null,"server_timestamp":"1785204031203","session_id":"d2757dd6dad94f3b9fe67e8dbf1adc37","source":"clob_market_ws"},"received_at":"2026-07-28T02:00:33.440025Z","record_id":"4d7a7e6e6c878f58e922ef75aaff2d0d029109291746ec2ffedc81f38088ecee","schema_fingerprint":"4aa3821a28b0b7c2400bc59aba4bcc0a76e971dadd19610d3ad38c768e124dc7","schema_version":"edge-lab-recorder.raw.v1","sequence":null,"source":"clob_market_ws"}
