{"event_at":"2026-07-26T03:22:34.271000Z","event_fingerprint":"8b49b7e895b66b796ee513de8159175939b1810a21bbceeea109406d148a2fa8","payload":{"connection_id":"f3be8c5f87ba4c71b8e5c26aee143178","event_at":"2026-07-26T03:22:34.271000Z","event_type":"new_market","frame_hash":"bf09f302dbf9c1db71ef7f11b9ebf9bc9c9c1aeedb18066957e4b1094ecbc598","frame_index":0,"kind":"data","monotonic_ns":138137882322708,"payload":{"active":false,"assets_ids":["22843378481037496345854892657275113292040395605788348915016157051620778145987","37073152382410194532210940846873373514320855516666721986320645560837280084554"],"clob_token_ids":["22843378481037496345854892657275113292040395605788348915016157051620778145987","37073152382410194532210940846873373514320855516666721986320645560837280084554"],"condition_id":"0x2f7e6912c5aedbac1067007966fb98f1887b3c92c1e218b6db1de92cd058cc82","description":"This market will resolve to \"Up\" if the Dogecoin price at the end of the time range specified in the title is greater than or equal to the price at the beginning of that range. Otherwise, it will resolve to \"Down\".\nThe resolution source for this market is information from Chainlink, specifically the DOGE/USD data stream available at https://data.chain.link/streams/doge-usd.\nPlease note that this market is about the price according to Chainlink data stream DOGE/USD, not according to other sources or spot markets.","event_message":{"description":"This market will resolve to \"Up\" if the Dogecoin price at the end of the time range specified in the title is greater than or equal to the price at the beginning of that range. Otherwise, it will resolve to \"Down\".\nThe resolution source for this market is information from Chainlink, specifically the DOGE/USD data stream available at https://data.chain.link/streams/doge-usd.\nPlease note that this market is about the price according to Chainlink data stream DOGE/USD, not according to other sources or spot markets.","id":"750041","slug":"doge-updown-15m-1785122100","ticker":"doge-updown-15m-1785122100","title":"Dogecoin Up or Down - July 26, 11:15PM-11:30PM ET"},"event_type":"new_market","fee_schedule":{"exponent":"1","rate":"0.07","rebate_rate":"0.2","taker_only":true},"fees_enabled":true,"game_start_time":"","group_item_title":"","id":"3107510","line":"","market":"0x2f7e6912c5aedbac1067007966fb98f1887b3c92c1e218b6db1de92cd058cc82","order_price_min_tick_size":"0.01","outcomes":["Up","Down"],"question":"Dogecoin Up or Down - July 26, 11:15PM-11:30PM ET","slug":"doge-updown-15m-1785122100","sports_market_type":"","tags":[],"taker_base_fee":"1000","timestamp":"1785036154271"},"payload_hash":"d3245b4078264f77f862fbe2f5583519147a5f00f225336c7a9fd79dea1d3702","raw_frame":"{\"id\":\"3107510\", \"question\":\"Dogecoin Up or Down - July 26, 11:15PM-11:30PM ET\", \"market\":\"0x2f7e6912c5aedbac1067007966fb98f1887b3c92c1e218b6db1de92cd058cc82\", \"slug\":\"doge-updown-15m-1785122100\", \"description\":\"This market will resolve to \\\"Up\\\" if the Dogecoin price at the end of the time range specified in the title is greater than or equal to the price at the beginning of that range. Otherwise, it will resolve to \\\"Down\\\".\\nThe resolution source for this market is information from Chainlink, specifically the DOGE/USD data stream available at https://data.chain.link/streams/doge-usd.\\nPlease note that this market is about the price according to Chainlink data stream DOGE/USD, not according to other sources or spot markets.\", \"assets_ids\":[\"22843378481037496345854892657275113292040395605788348915016157051620778145987\", \"37073152382410194532210940846873373514320855516666721986320645560837280084554\"], \"outcomes\":[\"Up\", \"Down\"], \"event_message\":{\"id\":\"750041\", \"ticker\":\"doge-updown-15m-1785122100\", \"slug\":\"doge-updown-15m-1785122100\", \"title\":\"Dogecoin Up or Down - July 26, 11:15PM-11:30PM ET\", \"description\":\"This market will resolve to \\\"Up\\\" if the Dogecoin price at the end of the time range specified in the title is greater than or equal to the price at the beginning of that range. Otherwise, it will resolve to \\\"Down\\\".\\nThe resolution source for this market is information from Chainlink, specifically the DOGE/USD data stream available at https://data.chain.link/streams/doge-usd.\\nPlease note that this market is about the price according to Chainlink data stream DOGE/USD, not according to other sources or spot markets.\"}, \"timestamp\":\"1785036154271\", \"event_type\":\"new_market\", \"tags\":[], \"condition_id\":\"0x2f7e6912c5aedbac1067007966fb98f1887b3c92c1e218b6db1de92cd058cc82\", \"active\":false, \"clob_token_ids\":[\"22843378481037496345854892657275113292040395605788348915016157051620778145987\", \"37073152382410194532210940846873373514320855516666721986320645560837280084554\"], \"sports_market_type\":\"\", \"line\":\"\", \"game_start_time\":\"\", \"order_price_min_tick_size\":\"0.01\", \"group_item_title\":\"\", \"taker_base_fee\":\"1000\", \"fees_enabled\":true, \"fee_schedule\":{\"exponent\":\"1\", \"rate\":\"0.07\", \"taker_only\":true, \"rebate_rate\":\"0.2\"}}","received_at":"2026-07-26T03:22:34.331941Z","schema_version":"clob-market-ws.new_market.v1","sequence":null,"server_hash":null,"server_timestamp":"1785036154271","session_id":"c31a343fa9584b66bec39f9faee0e3a0","source":"clob_market_ws"},"received_at":"2026-07-26T03:22:34.331941Z","record_id":"1b54dc8884436e8beeb667c449e762b8e582f8c4e0ef27b212bc3478a579d65e","schema_fingerprint":"6639a822a7b79cfa4c3fc0044066e4f66ba8611f5bf361772bd6902a2319b82d","schema_version":"edge-lab-recorder.raw.v1","sequence":null,"source":"clob_market_ws"}
{"event_at":null,"event_fingerprint":"a83a6774883ae9356ed95c4b5b22bbb60e3d4bcae38e5d525ba35e05616d6fc5","payload":{"connection_id":"f3be8c5f87ba4c71b8e5c26aee143178","detail":{"interval_seconds":10.0,"message":"PING"},"event_type":"heartbeat","kind":"lifecycle","monotonic_ns":138138150421583,"received_at":"2026-07-26T03:22:34.600046Z","schema_version":"edge-lab-recorder.lifecycle.v1","session_id":"c31a343fa9584b66bec39f9faee0e3a0","source":"clob_market_ws"},"received_at":"2026-07-26T03:22:34.600046Z","record_id":"f2391bef978e5b3a6142796a9a68869bb2d0e8f9de968dc857a322466132b3c3","schema_fingerprint":"cb8aa3aa4cb168a4b724fd9077bee6ecfb9bc586c57cfdf0ab89f00d82045e3c","schema_version":"edge-lab-recorder.raw.v1","sequence":null,"source":"clob_market_ws"}
{"event_at":null,"event_fingerprint":"9a34923a3306bb457b85641de571b3653749fcf5ff535c59c622bb204e8ce759","payload":{"connection_id":"f3be8c5f87ba4c71b8e5c26aee143178","event_type":"heartbeat_ack","frame_hash":"95784973cc639977bff93619700168505cb8f7855e44fa643d34622a43706c87","kind":"lifecycle","monotonic_ns":138138354557416,"raw_frame":"PONG","received_at":"2026-07-26T03:22:34.804170Z","schema_version":"edge-lab-recorder.heartbeat-ack.v1","session_id":"c31a343fa9584b66bec39f9faee0e3a0","source":"clob_market_ws"},"received_at":"2026-07-26T03:22:34.804170Z","record_id":"fa5f1d49641d5e0918510ada8e981524340a5c0ae17276225923449c0ca66008","schema_fingerprint":"c14ee1aab3ca674ee738e5268877b544d74c41ad3c427cedc09236467dc68ba1","schema_version":"edge-lab-recorder.raw.v1","sequence":null,"source":"clob_market_ws"}
{"event_at":"2026-07-26T03:22:35.020000Z","event_fingerprint":"8a07f5970b0265a1ea9588c7f65262eab7ce34443a5f1f944dafa6e1e5a2c6ce","payload":{"connection_id":"f3be8c5f87ba4c71b8e5c26aee143178","event_at":"2026-07-26T03:22:35.020000Z","event_type":"new_market","frame_hash":"6a80995459ba8393590976502d3927f2e3f260218d8e9405a4d6125e43720dfb","frame_index":0,"kind":"data","monotonic_ns":138138629552125,"payload":{"active":false,"assets_ids":["24254094493625419915756280046002869097156693848522361803041977572204227262166","41448400836309843603620980831210604935021861034693225347475867885462478926555"],"clob_token_ids":["24254094493625419915756280046002869097156693848522361803041977572204227262166","41448400836309843603620980831210604935021861034693225347475867885462478926555"],"condition_id":"0x717c0e8ccd4d5c7040185188fbae28be901ca589a11a94b1b38ca36a79eccfeb","description":"This market will resolve to \"Up\" if the Ethereum price at the end of the time range specified in the title is greater than or equal to the price at the beginning of that range. Otherwise, it will resolve to \"Down\".\nThe resolution source for this market is information from Chainlink, specifically the ETH/USD data stream available at https://data.chain.link/streams/eth-usd.\nPlease note that this market is about the price according to Chainlink data stream ETH/USD, not according to other sources or spot markets.","event_message":{"description":"This market will resolve to \"Up\" if the Ethereum price at the end of the time range specified in the title is greater than or equal to the price at the beginning of that range. Otherwise, it will resolve to \"Down\".\nThe resolution source for this market is information from Chainlink, specifically the ETH/USD data stream available at https://data.chain.link/streams/eth-usd.\nPlease note that this market is about the price according to Chainlink data stream ETH/USD, not according to other sources or spot markets.","id":"750035","slug":"eth-updown-15m-1785122100","ticker":"eth-updown-15m-1785122100","title":"Ethereum Up or Down - July 26, 11:15PM-11:30PM ET"},"event_type":"new_market","fee_schedule":{"exponent":"1","rate":"0.07","rebate_rate":"0.2","taker_only":true},"fees_enabled":true,"game_start_time":"","group_item_title":"","id":"3107504","line":"","market":"0x717c0e8ccd4d5c7040185188fbae28be901ca589a11a94b1b38ca36a79eccfeb","order_price_min_tick_size":"0.01","outcomes":["Up","Down"],"question":"Ethereum Up or Down - July 26, 11:15PM-11:30PM ET","slug":"eth-updown-15m-1785122100","sports_market_type":"","tags":[],"taker_base_fee":"1000","timestamp":"1785036155020"},"payload_hash":"97ebfabf5ddc5702c5b6f16dc49501772ebff02c9ec44ee0a40d9ea4924f6a54","raw_frame":"{\"id\":\"3107504\", \"question\":\"Ethereum Up or Down - July 26, 11:15PM-11:30PM ET\", \"market\":\"0x717c0e8ccd4d5c7040185188fbae28be901ca589a11a94b1b38ca36a79eccfeb\", \"slug\":\"eth-updown-15m-1785122100\", \"description\":\"This market will resolve to \\\"Up\\\" if the Ethereum price at the end of the time range specified in the title is greater than or equal to the price at the beginning of that range. Otherwise, it will resolve to \\\"Down\\\".\\nThe resolution source for this market is information from Chainlink, specifically the ETH/USD data stream available at https://data.chain.link/streams/eth-usd.\\nPlease note that this market is about the price according to Chainlink data stream ETH/USD, not according to other sources or spot markets.\", \"assets_ids\":[\"24254094493625419915756280046002869097156693848522361803041977572204227262166\", \"41448400836309843603620980831210604935021861034693225347475867885462478926555\"], \"outcomes\":[\"Up\", \"Down\"], \"event_message\":{\"id\":\"750035\", \"ticker\":\"eth-updown-15m-1785122100\", \"slug\":\"eth-updown-15m-1785122100\", \"title\":\"Ethereum Up or Down - July 26, 11:15PM-11:30PM ET\", \"description\":\"This market will resolve to \\\"Up\\\" if the Ethereum price at the end of the time range specified in the title is greater than or equal to the price at the beginning of that range. Otherwise, it will resolve to \\\"Down\\\".\\nThe resolution source for this market is information from Chainlink, specifically the ETH/USD data stream available at https://data.chain.link/streams/eth-usd.\\nPlease note that this market is about the price according to Chainlink data stream ETH/USD, not according to other sources or spot markets.\"}, \"timestamp\":\"1785036155020\", \"event_type\":\"new_market\", \"tags\":[], \"condition_id\":\"0x717c0e8ccd4d5c7040185188fbae28be901ca589a11a94b1b38ca36a79eccfeb\", \"active\":false, \"clob_token_ids\":[\"24254094493625419915756280046002869097156693848522361803041977572204227262166\", \"41448400836309843603620980831210604935021861034693225347475867885462478926555\"], \"sports_market_type\":\"\", \"line\":\"\", \"game_start_time\":\"\", \"order_price_min_tick_size\":\"0.01\", \"group_item_title\":\"\", \"taker_base_fee\":\"1000\", \"fees_enabled\":true, \"fee_schedule\":{\"exponent\":\"1\", \"rate\":\"0.07\", \"taker_only\":true, \"rebate_rate\":\"0.2\"}}","received_at":"2026-07-26T03:22:35.079179Z","schema_version":"clob-market-ws.new_market.v1","sequence":null,"server_hash":null,"server_timestamp":"1785036155020","session_id":"c31a343fa9584b66bec39f9faee0e3a0","source":"clob_market_ws"},"received_at":"2026-07-26T03:22:35.079179Z","record_id":"95fd6ca5658e189e1f4563bb64eb4886b54d3e9182926b8f68b381938d4b5068","schema_fingerprint":"6639a822a7b79cfa4c3fc0044066e4f66ba8611f5bf361772bd6902a2319b82d","schema_version":"edge-lab-recorder.raw.v1","sequence":null,"source":"clob_market_ws"}
{"event_at":"2026-07-26T03:22:35.299000Z","event_fingerprint":"25bdc3ae042f06d7dc1293bba5461e47eb715b190e72c59f69938c8d68fcf764","payload":{"connection_id":"f3be8c5f87ba4c71b8e5c26aee143178","event_at":"2026-07-26T03:22:35.299000Z","event_type":"new_market","frame_hash":"d4fb71efccdf5445fd182cf22a021e7e9ef5d6d026cd436cacc6434d36c62a56","frame_index":0,"kind":"data","monotonic_ns":138139511773500,"payload":{"active":false,"assets_ids":["60373647525130822526641315965826531999228021003348624596999043127698656309309","46705735166752777606859389962839352896428131799823376314716441665769491551413"],"clob_token_ids":["60373647525130822526641315965826531999228021003348624596999043127698656309309","46705735166752777606859389962839352896428131799823376314716441665769491551413"],"condition_id":"0xbcd3cc4fe370f92f5d5bd07454d1a39e95a58194b31363aa1a2ff347ef3b36da","description":"This market will resolve to \"Up\" if the Bitcoin price at the end of the time range specified in the title is greater than or equal to the price at the beginning of that range. Otherwise, it will resolve to \"Down\".\nThe resolution source for this market is information from Chainlink, specifically the BTC/USD data stream available at https://data.chain.link/streams/btc-usd.\nPlease note that this market is about the price according to Chainlink data stream BTC/USD, not according to other sources or spot markets.","event_message":{"description":"This market will resolve to \"Up\" if the Bitcoin price at the end of the time range specified in the title is greater than or equal to the price at the beginning of that range. Otherwise, it will resolve to \"Down\".\nThe resolution source for this market is information from Chainlink, specifically the BTC/USD data stream available at https://data.chain.link/streams/btc-usd.\nPlease note that this market is about the price according to Chainlink data stream BTC/USD, not according to other sources or spot markets.","id":"750040","slug":"btc-updown-5m-1785122100","ticker":"btc-updown-5m-1785122100","title":"Bitcoin Up or Down - July 26, 11:15PM-11:20PM ET"},"event_type":"new_market","fee_schedule":{"exponent":"1","rate":"0.07","rebate_rate":"0.2","taker_only":true},"fees_enabled":true,"game_start_time":"","group_item_title":"","id":"3107508","line":"","market":"0xbcd3cc4fe370f92f5d5bd07454d1a39e95a58194b31363aa1a2ff347ef3b36da","order_price_min_tick_size":"0.01","outcomes":["Up","Down"],"question":"Bitcoin Up or Down - July 26, 11:15PM-11:20PM ET","slug":"btc-updown-5m-1785122100","sports_market_type":"","tags":[],"taker_base_fee":"1000","timestamp":"1785036155299"},"payload_hash":"a7d044323421a9e64121d5fd10765ab9eb0d425d715405596f5dbdc4d198fdaf","raw_frame":"{\"id\":\"3107508\", \"question\":\"Bitcoin Up or Down - July 26, 11:15PM-11:20PM ET\", \"market\":\"0xbcd3cc4fe370f92f5d5bd07454d1a39e95a58194b31363aa1a2ff347ef3b36da\", \"slug\":\"btc-updown-5m-1785122100\", \"description\":\"This market will resolve to \\\"Up\\\" if the Bitcoin price at the end of the time range specified in the title is greater than or equal to the price at the beginning of that range. Otherwise, it will resolve to \\\"Down\\\".\\nThe resolution source for this market is information from Chainlink, specifically the BTC/USD data stream available at https://data.chain.link/streams/btc-usd.\\nPlease note that this market is about the price according to Chainlink data stream BTC/USD, not according to other sources or spot markets.\", \"assets_ids\":[\"60373647525130822526641315965826531999228021003348624596999043127698656309309\", \"46705735166752777606859389962839352896428131799823376314716441665769491551413\"], \"outcomes\":[\"Up\", \"Down\"], \"event_message\":{\"id\":\"750040\", \"ticker\":\"btc-updown-5m-1785122100\", \"slug\":\"btc-updown-5m-1785122100\", \"title\":\"Bitcoin Up or Down - July 26, 11:15PM-11:20PM ET\", \"description\":\"This market will resolve to \\\"Up\\\" if the Bitcoin price at the end of the time range specified in the title is greater than or equal to the price at the beginning of that range. Otherwise, it will resolve to \\\"Down\\\".\\nThe resolution source for this market is information from Chainlink, specifically the BTC/USD data stream available at https://data.chain.link/streams/btc-usd.\\nPlease note that this market is about the price according to Chainlink data stream BTC/USD, not according to other sources or spot markets.\"}, \"timestamp\":\"1785036155299\", \"event_type\":\"new_market\", \"tags\":[], \"condition_id\":\"0xbcd3cc4fe370f92f5d5bd07454d1a39e95a58194b31363aa1a2ff347ef3b36da\", \"active\":false, \"clob_token_ids\":[\"60373647525130822526641315965826531999228021003348624596999043127698656309309\", \"46705735166752777606859389962839352896428131799823376314716441665769491551413\"], \"sports_market_type\":\"\", \"line\":\"\", \"game_start_time\":\"\", \"order_price_min_tick_size\":\"0.01\", \"group_item_title\":\"\", \"taker_base_fee\":\"1000\", \"fees_enabled\":true, \"fee_schedule\":{\"exponent\":\"1\", \"rate\":\"0.07\", \"taker_only\":true, \"rebate_rate\":\"0.2\"}}","received_at":"2026-07-26T03:22:35.961407Z","schema_version":"clob-market-ws.new_market.v1","sequence":null,"server_hash":null,"server_timestamp":"1785036155299","session_id":"c31a343fa9584b66bec39f9faee0e3a0","source":"clob_market_ws"},"received_at":"2026-07-26T03:22:35.961407Z","record_id":"42087caaacf9b898ed3fbc161d9c898d0693230b51f16ca05e98ab4cf42cb1f0","schema_fingerprint":"6639a822a7b79cfa4c3fc0044066e4f66ba8611f5bf361772bd6902a2319b82d","schema_version":"edge-lab-recorder.raw.v1","sequence":null,"source":"clob_market_ws"}
{"event_at":"2026-07-26T03:22:36.959000Z","event_fingerprint":"2e1150ff48a383c3978c9727798f22864ef2e8d6117f95feb500453a94d15f2a","payload":{"connection_id":"f3be8c5f87ba4c71b8e5c26aee143178","event_at":"2026-07-26T03:22:36.959000Z","event_type":"price_change","frame_hash":"f77b5bb9dca31392708f9577b31c320b21190b31fa4f4e5275d02dcc1b45a440","frame_index":0,"kind":"data","monotonic_ns":138140564731791,"payload":{"event_type":"price_change","market":"0xd34d11638850161b49d343af579b355a91a40625a1cb324b89da0ec34316ce0d","price_changes":[{"asset_id":"72412292208263882620567760335223208281592684887840447866591915373071557986157","best_ask":"0.001","best_bid":"0","hash":"01a9301d4342f97bc34718f5bd305b426df10e0b","price":"0.001","side":"SELL","size":"2654.01"},{"asset_id":"23304427590407806052073703058430344447294483314513948492296568658168726366081","best_ask":"1","best_bid":"0.999","hash":"dd5c5f6b1a69f014ec848f54181f155abe0780c7","price":"0.999","side":"BUY","size":"2654.01"}],"timestamp":"1785036156959"},"payload_hash":"b6319601c02000e001a83b0c6a9646bc04d3b64ded6acc74c469c6300a753a61","raw_frame":"{\"market\":\"0xd34d11638850161b49d343af579b355a91a40625a1cb324b89da0ec34316ce0d\", \"price_changes\":[{\"asset_id\":\"72412292208263882620567760335223208281592684887840447866591915373071557986157\", \"price\":\"0.001\", \"size\":\"2654.01\", \"side\":\"SELL\", \"hash\":\"01a9301d4342f97bc34718f5bd305b426df10e0b\", \"best_bid\":\"0\", \"best_ask\":\"0.001\"}, {\"asset_id\":\"23304427590407806052073703058430344447294483314513948492296568658168726366081\", \"price\":\"0.999\", \"size\":\"2654.01\", \"side\":\"BUY\", \"hash\":\"dd5c5f6b1a69f014ec848f54181f155abe0780c7\", \"best_bid\":\"0.999\", \"best_ask\":\"1\"}], \"timestamp\":\"1785036156959\", \"event_type\":\"price_change\"}","received_at":"2026-07-26T03:22:37.014383Z","schema_version":"clob-market-ws.price_change.v1","sequence":null,"server_hash":null,"server_timestamp":"1785036156959","session_id":"c31a343fa9584b66bec39f9faee0e3a0","source":"clob_market_ws"},"received_at":"2026-07-26T03:22:37.014383Z","record_id":"359e5b8b19ec198fd19773c22a96c6277883fe2b1c9d6a553144c4c0ff2f0f01","schema_fingerprint":"4aa3821a28b0b7c2400bc59aba4bcc0a76e971dadd19610d3ad38c768e124dc7","schema_version":"edge-lab-recorder.raw.v1","sequence":null,"source":"clob_market_ws"}
{"event_at":"2026-07-26T03:22:36.961000Z","event_fingerprint":"717d20f0d3d856b805475d17add2cdd583910ebdda9ea3a0c8a2b1a8713175df","payload":{"connection_id":"f3be8c5f87ba4c71b8e5c26aee143178","event_at":"2026-07-26T03:22:36.961000Z","event_type":"price_change","frame_hash":"efe7f032d81ccdc36214aa3afae10d370df682f936334c32cac6629acd53fb55","frame_index":0,"kind":"data","monotonic_ns":138140567138083,"payload":{"event_type":"price_change","market":"0x4f38d51fa4a5a6ee7bef3839663f1ba6781f805620a00656a1ac78971ff65f94","price_changes":[{"asset_id":"60846176734025071834155023520866063850736009438184221594765130197435585627848","best_ask":"0.001","best_bid":"0","hash":"ba9d4b50a527cf2904d60e5f8e78e9f08c582588","price":"0.001","side":"SELL","size":"2823.92"},{"asset_id":"44664371028109261969095768944878691828121031685263777021740408906309606948679","best_ask":"1","best_bid":"0.999","hash":"a43c197237246f90b7f114b617f1818b0d08ac1c","price":"0.999","side":"BUY","size":"2823.92"}],"timestamp":"1785036156961"},"payload_hash":"0254d576c28934776d78cb6519987d2826ab4bca8a7870158598664dfd6f8113","raw_frame":"{\"market\":\"0x4f38d51fa4a5a6ee7bef3839663f1ba6781f805620a00656a1ac78971ff65f94\", \"price_changes\":[{\"asset_id\":\"60846176734025071834155023520866063850736009438184221594765130197435585627848\", \"price\":\"0.001\", \"size\":\"2823.92\", \"side\":\"SELL\", \"hash\":\"ba9d4b50a527cf2904d60e5f8e78e9f08c582588\", \"best_bid\":\"0\", \"best_ask\":\"0.001\"}, {\"asset_id\":\"44664371028109261969095768944878691828121031685263777021740408906309606948679\", \"price\":\"0.999\", \"size\":\"2823.92\", \"side\":\"BUY\", \"hash\":\"a43c197237246f90b7f114b617f1818b0d08ac1c\", \"best_bid\":\"0.999\", \"best_ask\":\"1\"}], \"timestamp\":\"1785036156961\", \"event_type\":\"price_change\"}","received_at":"2026-07-26T03:22:37.016795Z","schema_version":"clob-market-ws.price_change.v1","sequence":null,"server_hash":null,"server_timestamp":"1785036156961","session_id":"c31a343fa9584b66bec39f9faee0e3a0","source":"clob_market_ws"},"received_at":"2026-07-26T03:22:37.016795Z","record_id":"3f6717abf67991899f88a670fbf9c619e0569e7b864ddff7b1d38b5eef62f810","schema_fingerprint":"4aa3821a28b0b7c2400bc59aba4bcc0a76e971dadd19610d3ad38c768e124dc7","schema_version":"edge-lab-recorder.raw.v1","sequence":null,"source":"clob_market_ws"}
{"event_at":"2026-07-26T03:22:36.960000Z","event_fingerprint":"9a589a4043deab209457071073b4af3a952f74c5e58ed588bfb4548ef2ede68c","payload":{"connection_id":"f3be8c5f87ba4c71b8e5c26aee143178","event_at":"2026-07-26T03:22:36.960000Z","event_type":"price_change","frame_hash":"155ffadaa1356522caf5a51f4b95f88bb086fb936fdf6dfbf57ced34bd384430","frame_index":0,"kind":"data","monotonic_ns":138140569705791,"payload":{"event_type":"price_change","market":"0x8c323abb1ede2f2619000d6a23ac35b5168d91d791d7f66b1ca85c76e0067cb2","price_changes":[{"asset_id":"99984412512137939403884906462112387899264398613764835397028075776778837165349","best_ask":"0.001","best_bid":"0","hash":"dd651aeaf08e29517dec23469898461c85f5a00a","price":"0.001","side":"SELL","size":"2624.01"},{"asset_id":"21528271602641370669107334886285049226470476823971040418410401833791672433390","best_ask":"1","best_bid":"0.999","hash":"0df093bef808cfba4f7dc482161ffe8db44dfd7f","price":"0.999","side":"BUY","size":"2624.01"}],"timestamp":"1785036156960"},"payload_hash":"4307ee2dac1e62bc892fea8fb06f1e891879c238985259239425a7941022e9f4","raw_frame":"{\"market\":\"0x8c323abb1ede2f2619000d6a23ac35b5168d91d791d7f66b1ca85c76e0067cb2\", \"price_changes\":[{\"asset_id\":\"99984412512137939403884906462112387899264398613764835397028075776778837165349\", \"price\":\"0.001\", \"size\":\"2624.01\", \"side\":\"SELL\", \"hash\":\"dd651aeaf08e29517dec23469898461c85f5a00a\", \"best_bid\":\"0\", \"best_ask\":\"0.001\"}, {\"asset_id\":\"21528271602641370669107334886285049226470476823971040418410401833791672433390\", \"price\":\"0.999\", \"size\":\"2624.01\", \"side\":\"BUY\", \"hash\":\"0df093bef808cfba4f7dc482161ffe8db44dfd7f\", \"best_bid\":\"0.999\", \"best_ask\":\"1\"}], \"timestamp\":\"1785036156960\", \"event_type\":\"price_change\"}","received_at":"2026-07-26T03:22:37.019368Z","schema_version":"clob-market-ws.price_change.v1","sequence":null,"server_hash":null,"server_timestamp":"1785036156960","session_id":"c31a343fa9584b66bec39f9faee0e3a0","source":"clob_market_ws"},"received_at":"2026-07-26T03:22:37.019368Z","record_id":"0bd4b005ab578595cfce988be406935c0c1d0627f080ae69e408a3de219d5e75","schema_fingerprint":"4aa3821a28b0b7c2400bc59aba4bcc0a76e971dadd19610d3ad38c768e124dc7","schema_version":"edge-lab-recorder.raw.v1","sequence":null,"source":"clob_market_ws"}
{"event_at":"2026-07-26T03:22:36.962000Z","event_fingerprint":"c15cec2f3f46318820ab562cf02b78cbc4962ad32c6b507f87080a90f7141c59","payload":{"connection_id":"f3be8c5f87ba4c71b8e5c26aee143178","event_at":"2026-07-26T03:22:36.962000Z","event_type":"price_change","frame_hash":"6d967016f5261a45e9ae757951cb071906185e2497dece95209b63ff1b40f7b4","frame_index":0,"kind":"data","monotonic_ns":138140572010125,"payload":{"event_type":"price_change","market":"0xf5c1ad6b533e31b7156c48d12276744433a7dd1829938850a73717cea9d53821","price_changes":[{"asset_id":"34600602296599885071917717676988207363957952958012665255891266571657806817559","best_ask":"0.001","best_bid":"0","hash":"1780f4289d59eaba1710c9fc9a1f70d7cad0276e","price":"0.001","side":"SELL","size":"24767.16"},{"asset_id":"17984242239730438865135655538589475203118151844342180615256685234465965850727","best_ask":"1","best_bid":"0.999","hash":"db5aa9b25318d0f094640a49c195f18be33653af","price":"0.999","side":"BUY","size":"24767.16"}],"timestamp":"1785036156962"},"payload_hash":"a5fe82f04d27d041c3c318f671db4e17d94d6d31a9be772bb0a0472a7c6fe028","raw_frame":"{\"market\":\"0xf5c1ad6b533e31b7156c48d12276744433a7dd1829938850a73717cea9d53821\", \"price_changes\":[{\"asset_id\":\"34600602296599885071917717676988207363957952958012665255891266571657806817559\", \"price\":\"0.001\", \"size\":\"24767.16\", \"side\":\"SELL\", \"hash\":\"1780f4289d59eaba1710c9fc9a1f70d7cad0276e\", \"best_bid\":\"0\", \"best_ask\":\"0.001\"}, {\"asset_id\":\"17984242239730438865135655538589475203118151844342180615256685234465965850727\", \"price\":\"0.999\", \"size\":\"24767.16\", \"side\":\"BUY\", \"hash\":\"db5aa9b25318d0f094640a49c195f18be33653af\", \"best_bid\":\"0.999\", \"best_ask\":\"1\"}], \"timestamp\":\"1785036156962\", \"event_type\":\"price_change\"}","received_at":"2026-07-26T03:22:37.021667Z","schema_version":"clob-market-ws.price_change.v1","sequence":null,"server_hash":null,"server_timestamp":"1785036156962","session_id":"c31a343fa9584b66bec39f9faee0e3a0","source":"clob_market_ws"},"received_at":"2026-07-26T03:22:37.021667Z","record_id":"2b8b941dd4d0697d3a599775a373e42568e97dc2e0dc142abee82e9bbdd97d79","schema_fingerprint":"4aa3821a28b0b7c2400bc59aba4bcc0a76e971dadd19610d3ad38c768e124dc7","schema_version":"edge-lab-recorder.raw.v1","sequence":null,"source":"clob_market_ws"}
{"event_at":"2026-07-26T03:22:36.960000Z","event_fingerprint":"c39c9f55bc8e884d0acf4e698a958381e45f00a82f59a6072d29c27783c6932f","payload":{"connection_id":"f3be8c5f87ba4c71b8e5c26aee143178","event_at":"2026-07-26T03:22:36.960000Z","event_type":"price_change","frame_hash":"2ad70a9b092683088fc5700368c6ec374a6430d858e830ef85f46379e83db339","frame_index":0,"kind":"data","monotonic_ns":138140766851666,"payload":{"event_type":"price_change","market":"0x529e20dbcafea98019b83fb73d95438060842c1755b5da85f84dd470bcf4b6e7","price_changes":[{"asset_id":"8751464955595067927363468221457794220960058706401173909132456942616242167659","best_ask":"0.001","best_bid":"0","hash":"285eb579223060939b9b6c7d10b80f2f99e40e4f","price":"0.001","side":"SELL","size":"2774.31"},{"asset_id":"59690684605978199241259738837409754535439173706362879570036366520913988351920","best_ask":"1","best_bid":"0.999","hash":"b96a37fb29278e94f92732eddb2439ccdeac4622","price":"0.999","side":"BUY","size":"2774.31"}],"timestamp":"1785036156960"},"payload_hash":"6c667698a5eb29bbadd513fe4779b358f5aee95c642b1fc1678131bf333a36e8","raw_frame":"{\"market\":\"0x529e20dbcafea98019b83fb73d95438060842c1755b5da85f84dd470bcf4b6e7\", \"price_changes\":[{\"asset_id\":\"8751464955595067927363468221457794220960058706401173909132456942616242167659\", \"price\":\"0.001\", \"size\":\"2774.31\", \"side\":\"SELL\", \"hash\":\"285eb579223060939b9b6c7d10b80f2f99e40e4f\", \"best_bid\":\"0\", \"best_ask\":\"0.001\"}, {\"asset_id\":\"59690684605978199241259738837409754535439173706362879570036366520913988351920\", \"price\":\"0.999\", \"size\":\"2774.31\", \"side\":\"BUY\", \"hash\":\"b96a37fb29278e94f92732eddb2439ccdeac4622\", \"best_bid\":\"0.999\", \"best_ask\":\"1\"}], \"timestamp\":\"1785036156960\", \"event_type\":\"price_change\"}","received_at":"2026-07-26T03:22:37.216507Z","schema_version":"clob-market-ws.price_change.v1","sequence":null,"server_hash":null,"server_timestamp":"1785036156960","session_id":"c31a343fa9584b66bec39f9faee0e3a0","source":"clob_market_ws"},"received_at":"2026-07-26T03:22:37.216507Z","record_id":"3055c6c4037f34e7cb5dcf1ef47122c452344ec2c2f27dcfd3d5fa8da342e034","schema_fingerprint":"4aa3821a28b0b7c2400bc59aba4bcc0a76e971dadd19610d3ad38c768e124dc7","schema_version":"edge-lab-recorder.raw.v1","sequence":null,"source":"clob_market_ws"}
{"event_at":"2026-07-26T03:22:36.976000Z","event_fingerprint":"1f09cf2ca5cdb8f1301a0b927d1f82933b1a2e4eea652f0aa06cf46cb4cfbe99","payload":{"connection_id":"f3be8c5f87ba4c71b8e5c26aee143178","event_at":"2026-07-26T03:22:36.976000Z","event_type":"price_change","frame_hash":"1c412dcf115756f413470d5fbec650723074766f5eee24246e6819e809d762e6","frame_index":0,"kind":"data","monotonic_ns":138140768945750,"payload":{"event_type":"price_change","market":"0x9c381c628d4d7f50c84fe33ed2e6034c9e95a38fe2bbaf0839e0045ed6ebb00a","price_changes":[{"asset_id":"65498980163493839080617380002950766616985632732897237936946030803559673024127","best_ask":"0.001","best_bid":"0","hash":"1b4ce29e773948e45b88958a231a96c84bd11504","price":"0.001","side":"SELL","size":"2624.01"},{"asset_id":"54242839679678573772031723750101159478558866523031929268633860829634800562410","best_ask":"1","best_bid":"0.999","hash":"cc35d00c80020c8f9d66b962e1dc0f59ff25aa40","price":"0.999","side":"BUY","size":"2624.01"}],"timestamp":"1785036156976"},"payload_hash":"b02dbdae469388b6cb2a2b05ab49a777a7572d48dc6fb9d8d87ea8668b3edaa0","raw_frame":"{\"market\":\"0x9c381c628d4d7f50c84fe33ed2e6034c9e95a38fe2bbaf0839e0045ed6ebb00a\", \"price_changes\":[{\"asset_id\":\"65498980163493839080617380002950766616985632732897237936946030803559673024127\", \"price\":\"0.001\", \"size\":\"2624.01\", \"side\":\"SELL\", \"hash\":\"1b4ce29e773948e45b88958a231a96c84bd11504\", \"best_bid\":\"0\", \"best_ask\":\"0.001\"}, {\"asset_id\":\"54242839679678573772031723750101159478558866523031929268633860829634800562410\", \"price\":\"0.999\", \"size\":\"2624.01\", \"side\":\"BUY\", \"hash\":\"cc35d00c80020c8f9d66b962e1dc0f59ff25aa40\", \"best_bid\":\"0.999\", \"best_ask\":\"1\"}], \"timestamp\":\"1785036156976\", \"event_type\":\"price_change\"}","received_at":"2026-07-26T03:22:37.218601Z","schema_version":"clob-market-ws.price_change.v1","sequence":null,"server_hash":null,"server_timestamp":"1785036156976","session_id":"c31a343fa9584b66bec39f9faee0e3a0","source":"clob_market_ws"},"received_at":"2026-07-26T03:22:37.218601Z","record_id":"18236a371a70c5fa9f69d70afa9e5ae71a4bc2bddaed13c357f0f0ad5b15bc9d","schema_fingerprint":"4aa3821a28b0b7c2400bc59aba4bcc0a76e971dadd19610d3ad38c768e124dc7","schema_version":"edge-lab-recorder.raw.v1","sequence":null,"source":"clob_market_ws"}
{"event_at":"2026-07-26T03:22:37.342000Z","event_fingerprint":"d664dd3605ab865afc29dbe42da406d128610d4236c4afe7ccb6bd57f3017aff","payload":{"connection_id":"f3be8c5f87ba4c71b8e5c26aee143178","event_at":"2026-07-26T03:22:37.342000Z","event_type":"new_market","frame_hash":"dfc354fbfcd5299be5257676ae35fc7a06911e5135cb249661cfdd2abccf3b5c","frame_index":0,"kind":"data","monotonic_ns":138141672035416,"payload":{"active":false,"assets_ids":["113729330036902978514446144398782190159212105514752250700660164132369063099299","72438770148707946248977225635624039045643536659223307082824500507141805677098"],"clob_token_ids":["113729330036902978514446144398782190159212105514752250700660164132369063099299","72438770148707946248977225635624039045643536659223307082824500507141805677098"],"condition_id":"0xe03c4a08a3af1b251ef8061fb79f586280900cc25b6395f4ca81ef42befbc641","description":"This market will resolve to \"Up\" if the XRP price at the end of the time range specified in the title is greater than or equal to the price at the beginning of that range. Otherwise, it will resolve to \"Down\".\nThe resolution source for this market is information from Chainlink, specifically the XRP/USD data stream available at https://data.chain.link/streams/xrp-usd.\nPlease note that this market is about the price according to Chainlink data stream XRP/USD, not according to other sources or spot markets.","event_message":{"description":"This market will resolve to \"Up\" if the XRP price at the end of the time range specified in the title is greater than or equal to the price at the beginning of that range. Otherwise, it will resolve to \"Down\".\nThe resolution source for this market is information from Chainlink, specifically the XRP/USD data stream available at https://data.chain.link/streams/xrp-usd.\nPlease note that this market is about the price according to Chainlink data stream XRP/USD, not according to other sources or spot markets.","id":"750038","slug":"xrp-updown-15m-1785122100","ticker":"xrp-updown-15m-1785122100","title":"XRP Up or Down - July 26, 11:15PM-11:30PM ET"},"event_type":"new_market","fee_schedule":{"exponent":"1","rate":"0.07","rebate_rate":"0.2","taker_only":true},"fees_enabled":true,"game_start_time":"","group_item_title":"","id":"3107505","line":"","market":"0xe03c4a08a3af1b251ef8061fb79f586280900cc25b6395f4ca81ef42befbc641","order_price_min_tick_size":"0.01","outcomes":["Up","Down"],"question":"XRP Up or Down - July 26, 11:15PM-11:30PM ET","slug":"xrp-updown-15m-1785122100","sports_market_type":"","tags":[],"taker_base_fee":"1000","timestamp":"1785036157342"},"payload_hash":"f884c3801600b14b6241a9f2303196fdf63a5d2e83204b13be3ebe2c2eca578e","raw_frame":"{\"id\":\"3107505\", \"question\":\"XRP Up or Down - July 26, 11:15PM-11:30PM ET\", \"market\":\"0xe03c4a08a3af1b251ef8061fb79f586280900cc25b6395f4ca81ef42befbc641\", \"slug\":\"xrp-updown-15m-1785122100\", \"description\":\"This market will resolve to \\\"Up\\\" if the XRP price at the end of the time range specified in the title is greater than or equal to the price at the beginning of that range. Otherwise, it will resolve to \\\"Down\\\".\\nThe resolution source for this market is information from Chainlink, specifically the XRP/USD data stream available at https://data.chain.link/streams/xrp-usd.\\nPlease note that this market is about the price according to Chainlink data stream XRP/USD, not according to other sources or spot markets.\", \"assets_ids\":[\"113729330036902978514446144398782190159212105514752250700660164132369063099299\", \"72438770148707946248977225635624039045643536659223307082824500507141805677098\"], \"outcomes\":[\"Up\", \"Down\"], \"event_message\":{\"id\":\"750038\", \"ticker\":\"xrp-updown-15m-1785122100\", \"slug\":\"xrp-updown-15m-1785122100\", \"title\":\"XRP Up or Down - July 26, 11:15PM-11:30PM ET\", \"description\":\"This market will resolve to \\\"Up\\\" if the XRP price at the end of the time range specified in the title is greater than or equal to the price at the beginning of that range. Otherwise, it will resolve to \\\"Down\\\".\\nThe resolution source for this market is information from Chainlink, specifically the XRP/USD data stream available at https://data.chain.link/streams/xrp-usd.\\nPlease note that this market is about the price according to Chainlink data stream XRP/USD, not according to other sources or spot markets.\"}, \"timestamp\":\"1785036157342\", \"event_type\":\"new_market\", \"tags\":[], \"condition_id\":\"0xe03c4a08a3af1b251ef8061fb79f586280900cc25b6395f4ca81ef42befbc641\", \"active\":false, \"clob_token_ids\":[\"113729330036902978514446144398782190159212105514752250700660164132369063099299\", \"72438770148707946248977225635624039045643536659223307082824500507141805677098\"], \"sports_market_type\":\"\", \"line\":\"\", \"game_start_time\":\"\", \"order_price_min_tick_size\":\"0.01\", \"group_item_title\":\"\", \"taker_base_fee\":\"1000\", \"fees_enabled\":true, \"fee_schedule\":{\"exponent\":\"1\", \"rate\":\"0.07\", \"taker_only\":true, \"rebate_rate\":\"0.2\"}}","received_at":"2026-07-26T03:22:38.121700Z","schema_version":"clob-market-ws.new_market.v1","sequence":null,"server_hash":null,"server_timestamp":"1785036157342","session_id":"c31a343fa9584b66bec39f9faee0e3a0","source":"clob_market_ws"},"received_at":"2026-07-26T03:22:38.121700Z","record_id":"0c82c514201ab251e8459dbc615aac7b4ceb20ff61e62082f3109fd21c83e42f","schema_fingerprint":"6639a822a7b79cfa4c3fc0044066e4f66ba8611f5bf361772bd6902a2319b82d","schema_version":"edge-lab-recorder.raw.v1","sequence":null,"source":"clob_market_ws"}
{"event_at":"2026-07-26T03:22:37.872000Z","event_fingerprint":"5cd25f1a20265f676d68a61ebd978f6fdb962dd10d19f57f59981898d948b822","payload":{"connection_id":"f3be8c5f87ba4c71b8e5c26aee143178","event_at":"2026-07-26T03:22:37.872000Z","event_type":"price_change","frame_hash":"aaaac2d5e800cf2fc9ac8dccccb7ddbf733f3df90028d188974cae41359f6af5","frame_index":0,"kind":"data","monotonic_ns":138141674585000,"payload":{"event_type":"price_change","market":"0x529e20dbcafea98019b83fb73d95438060842c1755b5da85f84dd470bcf4b6e7","price_changes":[{"asset_id":"8751464955595067927363468221457794220960058706401173909132456942616242167659","best_ask":"0.001","best_bid":"0","hash":"c72f516d16165875c006771c431aabe89cbc14ca","price":"0.001","side":"SELL","size":"3338.12"},{"asset_id":"59690684605978199241259738837409754535439173706362879570036366520913988351920","best_ask":"1","best_bid":"0.999","hash":"b776ac6f31016da296351f31ba880d171c83c281","price":"0.999","side":"BUY","size":"3338.12"}],"timestamp":"1785036157872"},"payload_hash":"7b06f83c6f08e24b4af74cff8d6a0ddbff6edd643a6c79600f680f04a89c83f0","raw_frame":"{\"market\":\"0x529e20dbcafea98019b83fb73d95438060842c1755b5da85f84dd470bcf4b6e7\", \"price_changes\":[{\"asset_id\":\"8751464955595067927363468221457794220960058706401173909132456942616242167659\", \"price\":\"0.001\", \"size\":\"3338.12\", \"side\":\"SELL\", \"hash\":\"c72f516d16165875c006771c431aabe89cbc14ca\", \"best_bid\":\"0\", \"best_ask\":\"0.001\"}, {\"asset_id\":\"59690684605978199241259738837409754535439173706362879570036366520913988351920\", \"price\":\"0.999\", \"size\":\"3338.12\", \"side\":\"BUY\", \"hash\":\"b776ac6f31016da296351f31ba880d171c83c281\", \"best_bid\":\"0.999\", \"best_ask\":\"1\"}], \"timestamp\":\"1785036157872\", \"event_type\":\"price_change\"}","received_at":"2026-07-26T03:22:38.124264Z","schema_version":"clob-market-ws.price_change.v1","sequence":null,"server_hash":null,"server_timestamp":"1785036157872","session_id":"c31a343fa9584b66bec39f9faee0e3a0","source":"clob_market_ws"},"received_at":"2026-07-26T03:22:38.124264Z","record_id":"26459374146ee610ce78c9a52a8c9a412ddf6bf45d020c80e80d2b3dcd4ec21b","schema_fingerprint":"4aa3821a28b0b7c2400bc59aba4bcc0a76e971dadd19610d3ad38c768e124dc7","schema_version":"edge-lab-recorder.raw.v1","sequence":null,"source":"clob_market_ws"}
{"event_at":"2026-07-26T03:22:37.872000Z","event_fingerprint":"ad295a550617210570b28b73670455f4897a387d6a71947983863b1e43cd2b16","payload":{"connection_id":"f3be8c5f87ba4c71b8e5c26aee143178","event_at":"2026-07-26T03:22:37.872000Z","event_type":"price_change","frame_hash":"66a9fbd1f2fbf8adf6365bddf1d46b8f930414b1d5b773d2446e345b90f23ea4","frame_index":0,"kind":"data","monotonic_ns":138141676346458,"payload":{"event_type":"price_change","market":"0x8c323abb1ede2f2619000d6a23ac35b5168d91d791d7f66b1ca85c76e0067cb2","price_changes":[{"asset_id":"99984412512137939403884906462112387899264398613764835397028075776778837165349","best_ask":"0.001","best_bid":"0","hash":"729799ae3f0ba26bd0b9a9a4fe68fb881083b384","price":"0.001","side":"SELL","size":"3156.82"},{"asset_id":"21528271602641370669107334886285049226470476823971040418410401833791672433390","best_ask":"1","best_bid":"0.999","hash":"d88fff78aa30ec6e71bed21c06206a6ebc78af85","price":"0.999","side":"BUY","size":"3156.82"}],"timestamp":"1785036157872"},"payload_hash":"214a8739f499bc9b201e4f71b6529ffd964444397e9915642905d2ae661052b5","raw_frame":"{\"market\":\"0x8c323abb1ede2f2619000d6a23ac35b5168d91d791d7f66b1ca85c76e0067cb2\", \"price_changes\":[{\"asset_id\":\"99984412512137939403884906462112387899264398613764835397028075776778837165349\", \"price\":\"0.001\", \"size\":\"3156.82\", \"side\":\"SELL\", \"hash\":\"729799ae3f0ba26bd0b9a9a4fe68fb881083b384\", \"best_bid\":\"0\", \"best_ask\":\"0.001\"}, {\"asset_id\":\"21528271602641370669107334886285049226470476823971040418410401833791672433390\", \"price\":\"0.999\", \"size\":\"3156.82\", \"side\":\"BUY\", \"hash\":\"d88fff78aa30ec6e71bed21c06206a6ebc78af85\", \"best_bid\":\"0.999\", \"best_ask\":\"1\"}], \"timestamp\":\"1785036157872\", \"event_type\":\"price_change\"}","received_at":"2026-07-26T03:22:38.126025Z","schema_version":"clob-market-ws.price_change.v1","sequence":null,"server_hash":null,"server_timestamp":"1785036157872","session_id":"c31a343fa9584b66bec39f9faee0e3a0","source":"clob_market_ws"},"received_at":"2026-07-26T03:22:38.126025Z","record_id":"af8952a2e36463e65b20e4f2cf47dcdc3be31daaff0dd2137f0431147718d7f3","schema_fingerprint":"4aa3821a28b0b7c2400bc59aba4bcc0a76e971dadd19610d3ad38c768e124dc7","schema_version":"edge-lab-recorder.raw.v1","sequence":null,"source":"clob_market_ws"}
{"event_at":"2026-07-26T03:22:37.873000Z","event_fingerprint":"cf63bee7855aef132a18138eb4142bbae02484425a2d1493e39652ab2874e29e","payload":{"connection_id":"f3be8c5f87ba4c71b8e5c26aee143178","event_at":"2026-07-26T03:22:37.873000Z","event_type":"price_change","frame_hash":"fea2fd4f989c926ff455fe3e83e47c47a34d58ffa7a0abc0beef933050a83280","frame_index":0,"kind":"data","monotonic_ns":138141678017916,"payload":{"event_type":"price_change","market":"0xf5c1ad6b533e31b7156c48d12276744433a7dd1829938850a73717cea9d53821","price_changes":[{"asset_id":"34600602296599885071917717676988207363957952958012665255891266571657806817559","best_ask":"0.001","best_bid":"0","hash":"c25d51cabb7b50926b63b72c08fba2a8cee02573","price":"0.001","side":"SELL","size":"24858.24"},{"asset_id":"17984242239730438865135655538589475203118151844342180615256685234465965850727","best_ask":"1","best_bid":"0.999","hash":"04826e5797923eca28f3a13dcb978d7d9f74109d","price":"0.999","side":"BUY","size":"24858.24"}],"timestamp":"1785036157873"},"payload_hash":"72d9e3364bafc3505db872834a2eb396c4e56fdd5ef681b8565b1f644ffaa8c5","raw_frame":"{\"market\":\"0xf5c1ad6b533e31b7156c48d12276744433a7dd1829938850a73717cea9d53821\", \"price_changes\":[{\"asset_id\":\"34600602296599885071917717676988207363957952958012665255891266571657806817559\", \"price\":\"0.001\", \"size\":\"24858.24\", \"side\":\"SELL\", \"hash\":\"c25d51cabb7b50926b63b72c08fba2a8cee02573\", \"best_bid\":\"0\", \"best_ask\":\"0.001\"}, {\"asset_id\":\"17984242239730438865135655538589475203118151844342180615256685234465965850727\", \"price\":\"0.999\", \"size\":\"24858.24\", \"side\":\"BUY\", \"hash\":\"04826e5797923eca28f3a13dcb978d7d9f74109d\", \"best_bid\":\"0.999\", \"best_ask\":\"1\"}], \"timestamp\":\"1785036157873\", \"event_type\":\"price_change\"}","received_at":"2026-07-26T03:22:38.127692Z","schema_version":"clob-market-ws.price_change.v1","sequence":null,"server_hash":null,"server_timestamp":"1785036157873","session_id":"c31a343fa9584b66bec39f9faee0e3a0","source":"clob_market_ws"},"received_at":"2026-07-26T03:22:38.127692Z","record_id":"d60b06b2eccb5d08279177598c824e2d6e23cd6d4d278a6143deb870aba95313","schema_fingerprint":"4aa3821a28b0b7c2400bc59aba4bcc0a76e971dadd19610d3ad38c768e124dc7","schema_version":"edge-lab-recorder.raw.v1","sequence":null,"source":"clob_market_ws"}
{"event_at":"2026-07-26T03:22:37.876000Z","event_fingerprint":"ec38ee5a9dcd99ff1152f5468a59215d420c79c1a05c9f831c56dff69f773599","payload":{"connection_id":"f3be8c5f87ba4c71b8e5c26aee143178","event_at":"2026-07-26T03:22:37.876000Z","event_type":"price_change","frame_hash":"652580903ddca2d5401f66296f07fcb9dad436c258da2e610250372c831bea00","frame_index":0,"kind":"data","monotonic_ns":138141679765958,"payload":{"event_type":"price_change","market":"0x9c381c628d4d7f50c84fe33ed2e6034c9e95a38fe2bbaf0839e0045ed6ebb00a","price_changes":[{"asset_id":"65498980163493839080617380002950766616985632732897237936946030803559673024127","best_ask":"0.001","best_bid":"0","hash":"d97f7db9faa87b472a9f48bf9dd7845f21acee78","price":"0.001","side":"SELL","size":"3148.22"},{"asset_id":"54242839679678573772031723750101159478558866523031929268633860829634800562410","best_ask":"1","best_bid":"0.999","hash":"c2504bb2522900c016b07577d38eb402ab56c9e3","price":"0.999","side":"BUY","size":"3148.22"}],"timestamp":"1785036157876"},"payload_hash":"e12e27ec2ef2775feb2b8e713b8f95abf73bdb4a373b6a0d6a411fd5304bfe97","raw_frame":"{\"market\":\"0x9c381c628d4d7f50c84fe33ed2e6034c9e95a38fe2bbaf0839e0045ed6ebb00a\", \"price_changes\":[{\"asset_id\":\"65498980163493839080617380002950766616985632732897237936946030803559673024127\", \"price\":\"0.001\", \"size\":\"3148.22\", \"side\":\"SELL\", \"hash\":\"d97f7db9faa87b472a9f48bf9dd7845f21acee78\", \"best_bid\":\"0\", \"best_ask\":\"0.001\"}, {\"asset_id\":\"54242839679678573772031723750101159478558866523031929268633860829634800562410\", \"price\":\"0.999\", \"size\":\"3148.22\", \"side\":\"BUY\", \"hash\":\"c2504bb2522900c016b07577d38eb402ab56c9e3\", \"best_bid\":\"0.999\", \"best_ask\":\"1\"}], \"timestamp\":\"1785036157876\", \"event_type\":\"price_change\"}","received_at":"2026-07-26T03:22:38.129444Z","schema_version":"clob-market-ws.price_change.v1","sequence":null,"server_hash":null,"server_timestamp":"1785036157876","session_id":"c31a343fa9584b66bec39f9faee0e3a0","source":"clob_market_ws"},"received_at":"2026-07-26T03:22:38.129444Z","record_id":"d34d4549fbc122bae14d08445185682b968b705652474c925cd2d4834608136d","schema_fingerprint":"4aa3821a28b0b7c2400bc59aba4bcc0a76e971dadd19610d3ad38c768e124dc7","schema_version":"edge-lab-recorder.raw.v1","sequence":null,"source":"clob_market_ws"}
{"event_at":"2026-07-26T03:22:37.876000Z","event_fingerprint":"bd0d3012d4daa393d43e1b69dd0e75337689409032d680705b55981c2cd0bae5","payload":{"connection_id":"f3be8c5f87ba4c71b8e5c26aee143178","event_at":"2026-07-26T03:22:37.876000Z","event_type":"price_change","frame_hash":"519ca6fa6910c998780b34fd8f105743d6f658a1282e059f14e90d22abc46067","frame_index":0,"kind":"data","monotonic_ns":138141863436041,"payload":{"event_type":"price_change","market":"0x4f38d51fa4a5a6ee7bef3839663f1ba6781f805620a00656a1ac78971ff65f94","price_changes":[{"asset_id":"60846176734025071834155023520866063850736009438184221594765130197435585627848","best_ask":"0.001","best_bid":"0","hash":"cc90cf7aaf6e7bd4e754987f111b85232a5a9b42","price":"0.001","side":"SELL","size":"2895"},{"asset_id":"44664371028109261969095768944878691828121031685263777021740408906309606948679","best_ask":"1","best_bid":"0.999","hash":"a47b802c01aed8bd1ae563c1682d8e462acb7bff","price":"0.999","side":"BUY","size":"2895"}],"timestamp":"1785036157876"},"payload_hash":"b47a91b09771688628b7748cbe03ab1a6c7e98a0a1e595ab78503365ef2eddec","raw_frame":"{\"market\":\"0x4f38d51fa4a5a6ee7bef3839663f1ba6781f805620a00656a1ac78971ff65f94\", \"price_changes\":[{\"asset_id\":\"60846176734025071834155023520866063850736009438184221594765130197435585627848\", \"price\":\"0.001\", \"size\":\"2895\", \"side\":\"SELL\", \"hash\":\"cc90cf7aaf6e7bd4e754987f111b85232a5a9b42\", \"best_bid\":\"0\", \"best_ask\":\"0.001\"}, {\"asset_id\":\"44664371028109261969095768944878691828121031685263777021740408906309606948679\", \"price\":\"0.999\", \"size\":\"2895\", \"side\":\"BUY\", \"hash\":\"a47b802c01aed8bd1ae563c1682d8e462acb7bff\", \"best_bid\":\"0.999\", \"best_ask\":\"1\"}], \"timestamp\":\"1785036157876\", \"event_type\":\"price_change\"}","received_at":"2026-07-26T03:22:38.313114Z","schema_version":"clob-market-ws.price_change.v1","sequence":null,"server_hash":null,"server_timestamp":"1785036157876","session_id":"c31a343fa9584b66bec39f9faee0e3a0","source":"clob_market_ws"},"received_at":"2026-07-26T03:22:38.313114Z","record_id":"26705c16a7aaf385ff2d643bc414e93963f049b9a92cb8632344353aa07d5960","schema_fingerprint":"4aa3821a28b0b7c2400bc59aba4bcc0a76e971dadd19610d3ad38c768e124dc7","schema_version":"edge-lab-recorder.raw.v1","sequence":null,"source":"clob_market_ws"}
{"event_at":"2026-07-26T03:22:37.884000Z","event_fingerprint":"54c98ee7740b5db24d082f987347de427e7b73473ef575ba08e16041a79d5b5c","payload":{"connection_id":"f3be8c5f87ba4c71b8e5c26aee143178","event_at":"2026-07-26T03:22:37.884000Z","event_type":"price_change","frame_hash":"44235205c766136d587e9751cb19b9e8960e99e71a94e377578f0f11613de3d5","frame_index":0,"kind":"data","monotonic_ns":138141865100750,"payload":{"event_type":"price_change","market":"0xd34d11638850161b49d343af579b355a91a40625a1cb324b89da0ec34316ce0d","price_changes":[{"asset_id":"72412292208263882620567760335223208281592684887840447866591915373071557986157","best_ask":"0.001","best_bid":"0","hash":"2c5b7889bb5ff72d0895a7fd16f07341561c78da","price":"0.001","side":"SELL","size":"2966.04"},{"asset_id":"23304427590407806052073703058430344447294483314513948492296568658168726366081","best_ask":"1","best_bid":"0.999","hash":"94907ea54ed6d59006ce700e1a20f8058e3735b8","price":"0.999","side":"BUY","size":"2966.04"}],"timestamp":"1785036157884"},"payload_hash":"a13bdb7b68e762ed77eed5808324784ca5cf4f663cbbe4f311d315dfa5062628","raw_frame":"{\"market\":\"0xd34d11638850161b49d343af579b355a91a40625a1cb324b89da0ec34316ce0d\", \"price_changes\":[{\"asset_id\":\"72412292208263882620567760335223208281592684887840447866591915373071557986157\", \"price\":\"0.001\", \"size\":\"2966.04\", \"side\":\"SELL\", \"hash\":\"2c5b7889bb5ff72d0895a7fd16f07341561c78da\", \"best_bid\":\"0\", \"best_ask\":\"0.001\"}, {\"asset_id\":\"23304427590407806052073703058430344447294483314513948492296568658168726366081\", \"price\":\"0.999\", \"size\":\"2966.04\", \"side\":\"BUY\", \"hash\":\"94907ea54ed6d59006ce700e1a20f8058e3735b8\", \"best_bid\":\"0.999\", \"best_ask\":\"1\"}], \"timestamp\":\"1785036157884\", \"event_type\":\"price_change\"}","received_at":"2026-07-26T03:22:38.314781Z","schema_version":"clob-market-ws.price_change.v1","sequence":null,"server_hash":null,"server_timestamp":"1785036157884","session_id":"c31a343fa9584b66bec39f9faee0e3a0","source":"clob_market_ws"},"received_at":"2026-07-26T03:22:38.314781Z","record_id":"eef2f351e0146412e4a220bd4002c209fd373fc1da6c211a214f71d39453eaa2","schema_fingerprint":"4aa3821a28b0b7c2400bc59aba4bcc0a76e971dadd19610d3ad38c768e124dc7","schema_version":"edge-lab-recorder.raw.v1","sequence":null,"source":"clob_market_ws"}
{"event_at":"2026-07-26T03:22:38.345000Z","event_fingerprint":"675c29bc572c15198031993a5fa3accb97de81da1878389041953f0de2f8a659","payload":{"connection_id":"f3be8c5f87ba4c71b8e5c26aee143178","event_at":"2026-07-26T03:22:38.345000Z","event_type":"new_market","frame_hash":"bb77fc03be00425f4a0a8a75a38c3133297686192b46f50bb1db4f475385a56d","frame_index":0,"kind":"data","monotonic_ns":138141953417500,"payload":{"active":false,"assets_ids":["86478617187130767750772526398665480924547781772919055519322857513067246965249","71464619313477852878097140511976793321796276149654430113941029342645840757701"],"clob_token_ids":["86478617187130767750772526398665480924547781772919055519322857513067246965249","71464619313477852878097140511976793321796276149654430113941029342645840757701"],"condition_id":"0x058d8120ed558a572c5f630e9c90c7219bd048d0da7cd2784cca31bd85998a93","description":"This market will resolve to \"Up\" if the Hyperliquid price at the end of the time range specified in the title is greater than or equal to the price at the beginning of that range. Otherwise, it will resolve to \"Down\".\nThe resolution source for this market is information from Chainlink, specifically the HYPE/USD data stream available at https://data.chain.link/streams/hype-usd.\nPlease note that this market is about the price according to Chainlink data stream HYPE/USD, not according to other sources or spot markets.","event_message":{"description":"This market will resolve to \"Up\" if the Hyperliquid price at the end of the time range specified in the title is greater than or equal to the price at the beginning of that range. Otherwise, it will resolve to \"Down\".\nThe resolution source for this market is information from Chainlink, specifically the HYPE/USD data stream available at https://data.chain.link/streams/hype-usd.\nPlease note that this market is about the price according to Chainlink data stream HYPE/USD, not according to other sources or spot markets.","id":"750047","slug":"hype-updown-15m-1785122100","ticker":"hype-updown-15m-1785122100","title":"Hyperliquid Up or Down - July 26, 11:15PM-11:30PM ET"},"event_type":"new_market","fee_schedule":{"exponent":"1","rate":"0.07","rebate_rate":"0.2","taker_only":true},"fees_enabled":true,"game_start_time":"","group_item_title":"","id":"3107516","line":"","market":"0x058d8120ed558a572c5f630e9c90c7219bd048d0da7cd2784cca31bd85998a93","order_price_min_tick_size":"0.01","outcomes":["Up","Down"],"question":"Hyperliquid Up or Down - July 26, 11:15PM-11:30PM ET","slug":"hype-updown-15m-1785122100","sports_market_type":"","tags":[],"taker_base_fee":"1000","timestamp":"1785036158345"},"payload_hash":"174406925d69d4a30c73dd51233ad150b4628c7a22f704afb01490c9554d94d1","raw_frame":"{\"id\":\"3107516\", \"question\":\"Hyperliquid Up or Down - July 26, 11:15PM-11:30PM ET\", \"market\":\"0x058d8120ed558a572c5f630e9c90c7219bd048d0da7cd2784cca31bd85998a93\", \"slug\":\"hype-updown-15m-1785122100\", \"description\":\"This market will resolve to \\\"Up\\\" if the Hyperliquid price at the end of the time range specified in the title is greater than or equal to the price at the beginning of that range. Otherwise, it will resolve to \\\"Down\\\".\\nThe resolution source for this market is information from Chainlink, specifically the HYPE/USD data stream available at https://data.chain.link/streams/hype-usd.\\nPlease note that this market is about the price according to Chainlink data stream HYPE/USD, not according to other sources or spot markets.\", \"assets_ids\":[\"86478617187130767750772526398665480924547781772919055519322857513067246965249\", \"71464619313477852878097140511976793321796276149654430113941029342645840757701\"], \"outcomes\":[\"Up\", \"Down\"], \"event_message\":{\"id\":\"750047\", \"ticker\":\"hype-updown-15m-1785122100\", \"slug\":\"hype-updown-15m-1785122100\", \"title\":\"Hyperliquid Up or Down - July 26, 11:15PM-11:30PM ET\", \"description\":\"This market will resolve to \\\"Up\\\" if the Hyperliquid price at the end of the time range specified in the title is greater than or equal to the price at the beginning of that range. Otherwise, it will resolve to \\\"Down\\\".\\nThe resolution source for this market is information from Chainlink, specifically the HYPE/USD data stream available at https://data.chain.link/streams/hype-usd.\\nPlease note that this market is about the price according to Chainlink data stream HYPE/USD, not according to other sources or spot markets.\"}, \"timestamp\":\"1785036158345\", \"event_type\":\"new_market\", \"tags\":[], \"condition_id\":\"0x058d8120ed558a572c5f630e9c90c7219bd048d0da7cd2784cca31bd85998a93\", \"active\":false, \"clob_token_ids\":[\"86478617187130767750772526398665480924547781772919055519322857513067246965249\", \"71464619313477852878097140511976793321796276149654430113941029342645840757701\"], \"sports_market_type\":\"\", \"line\":\"\", \"game_start_time\":\"\", \"order_price_min_tick_size\":\"0.01\", \"group_item_title\":\"\", \"taker_base_fee\":\"1000\", \"fees_enabled\":true, \"fee_schedule\":{\"exponent\":\"1\", \"rate\":\"0.07\", \"taker_only\":true, \"rebate_rate\":\"0.2\"}}","received_at":"2026-07-26T03:22:38.403098Z","schema_version":"clob-market-ws.new_market.v1","sequence":null,"server_hash":null,"server_timestamp":"1785036158345","session_id":"c31a343fa9584b66bec39f9faee0e3a0","source":"clob_market_ws"},"received_at":"2026-07-26T03:22:38.403098Z","record_id":"a4ddf3ff8bf28215f7c295c05a59613047d1ac2364c9532ad0a8057c2cde4b14","schema_fingerprint":"6639a822a7b79cfa4c3fc0044066e4f66ba8611f5bf361772bd6902a2319b82d","schema_version":"edge-lab-recorder.raw.v1","sequence":null,"source":"clob_market_ws"}
{"event_at":"2026-07-26T03:22:40.395000Z","event_fingerprint":"fedcb25204baa148b19dc3a88b0d85eec25242cd97ac0eb517c7c37d1bf8fbd0","payload":{"connection_id":"f3be8c5f87ba4c71b8e5c26aee143178","event_at":"2026-07-26T03:22:40.395000Z","event_type":"new_market","frame_hash":"9a99a35c1d133f83b5fc4f8a00a1247411734f3fee3db2de5bb47d2669867f2c","frame_index":0,"kind":"data","monotonic_ns":138144597708375,"payload":{"active":false,"assets_ids":["107479364671810586595256469525045884559568203293998757778355148931210358499662","15855399819962109582138117738667675904449024733137890923311514908772503950059"],"clob_token_ids":["107479364671810586595256469525045884559568203293998757778355148931210358499662","15855399819962109582138117738667675904449024733137890923311514908772503950059"],"condition_id":"0xc5d737b0b039e38d5c2ebbf580feefcb4b164f61902aa06b481e2f032ec5ccf2","description":"This market will resolve to \"Up\" if the Bitcoin price at the end of the time range specified in the title is greater than or equal to the price at the beginning of that range. Otherwise, it will resolve to \"Down\".\nThe resolution source for this market is information from Chainlink, specifically the BTC/USD data stream available at https://data.chain.link/streams/btc-usd.\nPlease note that this market is about the price according to Chainlink data stream BTC/USD, not according to other sources or spot markets.","event_message":{"description":"This market will resolve to \"Up\" if the Bitcoin price at the end of the time range specified in the title is greater than or equal to the price at the beginning of that range. Otherwise, it will resolve to \"Down\".\nThe resolution source for this market is information from Chainlink, specifically the BTC/USD data stream available at https://data.chain.link/streams/btc-usd.\nPlease note that this market is about the price according to Chainlink data stream BTC/USD, not according to other sources or spot markets.","id":"750044","slug":"btc-updown-15m-1785122100","ticker":"btc-updown-15m-1785122100","title":"Bitcoin Up or Down - July 26, 11:15PM-11:30PM ET"},"event_type":"new_market","fee_schedule":{"exponent":"1","rate":"0.07","rebate_rate":"0.2","taker_only":true},"fees_enabled":true,"game_start_time":"","group_item_title":"","id":"3107513","line":"","market":"0xc5d737b0b039e38d5c2ebbf580feefcb4b164f61902aa06b481e2f032ec5ccf2","order_price_min_tick_size":"0.01","outcomes":["Up","Down"],"question":"Bitcoin Up or Down - July 26, 11:15PM-11:30PM ET","slug":"btc-updown-15m-1785122100","sports_market_type":"","tags":[],"taker_base_fee":"1000","timestamp":"1785036160395"},"payload_hash":"c79b7646ed5abf46d67dd8fae048319d24405fd9f6a855af0b745828f27e217d","raw_frame":"{\"id\":\"3107513\", \"question\":\"Bitcoin Up or Down - July 26, 11:15PM-11:30PM ET\", \"market\":\"0xc5d737b0b039e38d5c2ebbf580feefcb4b164f61902aa06b481e2f032ec5ccf2\", \"slug\":\"btc-updown-15m-1785122100\", \"description\":\"This market will resolve to \\\"Up\\\" if the Bitcoin price at the end of the time range specified in the title is greater than or equal to the price at the beginning of that range. Otherwise, it will resolve to \\\"Down\\\".\\nThe resolution source for this market is information from Chainlink, specifically the BTC/USD data stream available at https://data.chain.link/streams/btc-usd.\\nPlease note that this market is about the price according to Chainlink data stream BTC/USD, not according to other sources or spot markets.\", \"assets_ids\":[\"107479364671810586595256469525045884559568203293998757778355148931210358499662\", \"15855399819962109582138117738667675904449024733137890923311514908772503950059\"], \"outcomes\":[\"Up\", \"Down\"], \"event_message\":{\"id\":\"750044\", \"ticker\":\"btc-updown-15m-1785122100\", \"slug\":\"btc-updown-15m-1785122100\", \"title\":\"Bitcoin Up or Down - July 26, 11:15PM-11:30PM ET\", \"description\":\"This market will resolve to \\\"Up\\\" if the Bitcoin price at the end of the time range specified in the title is greater than or equal to the price at the beginning of that range. Otherwise, it will resolve to \\\"Down\\\".\\nThe resolution source for this market is information from Chainlink, specifically the BTC/USD data stream available at https://data.chain.link/streams/btc-usd.\\nPlease note that this market is about the price according to Chainlink data stream BTC/USD, not according to other sources or spot markets.\"}, \"timestamp\":\"1785036160395\", \"event_type\":\"new_market\", \"tags\":[], \"condition_id\":\"0xc5d737b0b039e38d5c2ebbf580feefcb4b164f61902aa06b481e2f032ec5ccf2\", \"active\":false, \"clob_token_ids\":[\"107479364671810586595256469525045884559568203293998757778355148931210358499662\", \"15855399819962109582138117738667675904449024733137890923311514908772503950059\"], \"sports_market_type\":\"\", \"line\":\"\", \"game_start_time\":\"\", \"order_price_min_tick_size\":\"0.01\", \"group_item_title\":\"\", \"taker_base_fee\":\"1000\", \"fees_enabled\":true, \"fee_schedule\":{\"exponent\":\"1\", \"rate\":\"0.07\", \"taker_only\":true, \"rebate_rate\":\"0.2\"}}","received_at":"2026-07-26T03:22:41.047416Z","schema_version":"clob-market-ws.new_market.v1","sequence":null,"server_hash":null,"server_timestamp":"1785036160395","session_id":"c31a343fa9584b66bec39f9faee0e3a0","source":"clob_market_ws"},"received_at":"2026-07-26T03:22:41.047416Z","record_id":"5684c7f425252ea1a8d2c8d8f7043a54481a4fcef8b60d492c3e86d714c532e2","schema_fingerprint":"6639a822a7b79cfa4c3fc0044066e4f66ba8611f5bf361772bd6902a2319b82d","schema_version":"edge-lab-recorder.raw.v1","sequence":null,"source":"clob_market_ws"}
{"event_at":"2026-07-26T03:22:41.194000Z","event_fingerprint":"3b7198b57088c016879606642b22ed34be756c7d963ca14ab68aec1a0f05a049","payload":{"connection_id":"f3be8c5f87ba4c71b8e5c26aee143178","event_at":"2026-07-26T03:22:41.194000Z","event_type":"new_market","frame_hash":"2b181a9ed95eb50dfb0a9273cd14b7989fa023f24767f2ad706a1d17ca08181f","frame_index":0,"kind":"data","monotonic_ns":138144802862500,"payload":{"active":false,"assets_ids":["10545181108115067217748918920686871631125728567655678553415552190195257275629","88391116468970999563631743417827097999348684436582270448340599248248635653890"],"clob_token_ids":["10545181108115067217748918920686871631125728567655678553415552190195257275629","88391116468970999563631743417827097999348684436582270448340599248248635653890"],"condition_id":"0xe990873b821f72f2f8fc4651d9543cecf6c59dcbea42d2daf6a3a1b2c845c2fd","description":"This market will resolve to \"Up\" if the Solana price at the end of the time range specified in the title is greater than or equal to the price at the beginning of that range. Otherwise, it will resolve to \"Down\".\nThe resolution source for this market is information from Chainlink, specifically the SOL/USD data stream available at https://data.chain.link/streams/sol-usd.\nPlease note that this market is about the price according to Chainlink data stream SOL/USD, not according to other sources or spot markets.","event_message":{"description":"This market will resolve to \"Up\" if the Solana price at the end of the time range specified in the title is greater than or equal to the price at the beginning of that range. Otherwise, it will resolve to \"Down\".\nThe resolution source for this market is information from Chainlink, specifically the SOL/USD data stream available at https://data.chain.link/streams/sol-usd.\nPlease note that this market is about the price according to Chainlink data stream SOL/USD, not according to other sources or spot markets.","id":"750046","slug":"sol-updown-5m-1785122100","ticker":"sol-updown-5m-1785122100","title":"Solana Up or Down - July 26, 11:15PM-11:20PM ET"},"event_type":"new_market","fee_schedule":{"exponent":"1","rate":"0.07","rebate_rate":"0.2","taker_only":true},"fees_enabled":true,"game_start_time":"","group_item_title":"","id":"3107515","line":"","market":"0xe990873b821f72f2f8fc4651d9543cecf6c59dcbea42d2daf6a3a1b2c845c2fd","order_price_min_tick_size":"0.01","outcomes":["Up","Down"],"question":"Solana Up or Down - July 26, 11:15PM-11:20PM ET","slug":"sol-updown-5m-1785122100","sports_market_type":"","tags":[],"taker_base_fee":"1000","timestamp":"1785036161194"},"payload_hash":"42c2f6453e8083a61eb5ae50262da7098a9868b9f43d59ee95955a0bc62cffc4","raw_frame":"{\"id\":\"3107515\", \"question\":\"Solana Up or Down - July 26, 11:15PM-11:20PM ET\", \"market\":\"0xe990873b821f72f2f8fc4651d9543cecf6c59dcbea42d2daf6a3a1b2c845c2fd\", \"slug\":\"sol-updown-5m-1785122100\", \"description\":\"This market will resolve to \\\"Up\\\" if the Solana price at the end of the time range specified in the title is greater than or equal to the price at the beginning of that range. Otherwise, it will resolve to \\\"Down\\\".\\nThe resolution source for this market is information from Chainlink, specifically the SOL/USD data stream available at https://data.chain.link/streams/sol-usd.\\nPlease note that this market is about the price according to Chainlink data stream SOL/USD, not according to other sources or spot markets.\", \"assets_ids\":[\"10545181108115067217748918920686871631125728567655678553415552190195257275629\", \"88391116468970999563631743417827097999348684436582270448340599248248635653890\"], \"outcomes\":[\"Up\", \"Down\"], \"event_message\":{\"id\":\"750046\", \"ticker\":\"sol-updown-5m-1785122100\", \"slug\":\"sol-updown-5m-1785122100\", \"title\":\"Solana Up or Down - July 26, 11:15PM-11:20PM ET\", \"description\":\"This market will resolve to \\\"Up\\\" if the Solana price at the end of the time range specified in the title is greater than or equal to the price at the beginning of that range. Otherwise, it will resolve to \\\"Down\\\".\\nThe resolution source for this market is information from Chainlink, specifically the SOL/USD data stream available at https://data.chain.link/streams/sol-usd.\\nPlease note that this market is about the price according to Chainlink data stream SOL/USD, not according to other sources or spot markets.\"}, \"timestamp\":\"1785036161194\", \"event_type\":\"new_market\", \"tags\":[], \"condition_id\":\"0xe990873b821f72f2f8fc4651d9543cecf6c59dcbea42d2daf6a3a1b2c845c2fd\", \"active\":false, \"clob_token_ids\":[\"10545181108115067217748918920686871631125728567655678553415552190195257275629\", \"88391116468970999563631743417827097999348684436582270448340599248248635653890\"], \"sports_market_type\":\"\", \"line\":\"\", \"game_start_time\":\"\", \"order_price_min_tick_size\":\"0.01\", \"group_item_title\":\"\", \"taker_base_fee\":\"1000\", \"fees_enabled\":true, \"fee_schedule\":{\"exponent\":\"1\", \"rate\":\"0.07\", \"taker_only\":true, \"rebate_rate\":\"0.2\"}}","received_at":"2026-07-26T03:22:41.252580Z","schema_version":"clob-market-ws.new_market.v1","sequence":null,"server_hash":null,"server_timestamp":"1785036161194","session_id":"c31a343fa9584b66bec39f9faee0e3a0","source":"clob_market_ws"},"received_at":"2026-07-26T03:22:41.252580Z","record_id":"5a8189876b3b7fc717a0cc36def3ff6ad8ae7c75f89b8cb603b2408bc67671c9","schema_fingerprint":"6639a822a7b79cfa4c3fc0044066e4f66ba8611f5bf361772bd6902a2319b82d","schema_version":"edge-lab-recorder.raw.v1","sequence":null,"source":"clob_market_ws"}
{"event_at":"2026-07-26T03:22:41.446000Z","event_fingerprint":"047cda1ee7541318fc4547c6bd9c87e7e2a9c30f2f44bb6839407611ca125a8c","payload":{"connection_id":"f3be8c5f87ba4c71b8e5c26aee143178","event_at":"2026-07-26T03:22:41.446000Z","event_type":"price_change","frame_hash":"0a1b8bc6da16be65f6758e6c6d18e11be4b633bfd8c3d45e496779251000a7eb","frame_index":0,"kind":"data","monotonic_ns":138145157998458,"payload":{"event_type":"price_change","market":"0x37b4e66ed76a1ae459bf10d847a67f8b177df9e948837bb216db7f0ddeeb0a8f","price_changes":[{"asset_id":"108872501708701256232360833975340759490903762166970350300622728710669503400981","best_ask":"1","best_bid":"0.999","hash":"4da914c4212ff563d08d8a3168c4496969298b36","price":"0.03","side":"BUY","size":"169.59"},{"asset_id":"9589024508471284927421067800380793227060508852978748836190721804896525288035","best_ask":"0.001","best_bid":"0","hash":"b1183ff3f797d8128bea36d2d17951c7d214498a","price":"0.97","side":"SELL","size":"169.59"}],"timestamp":"1785036161446"},"payload_hash":"cc440d39a1e888236a09d394a5964b6b9d5a5659f20eb6829e1d526d816a501e","raw_frame":"{\"market\":\"0x37b4e66ed76a1ae459bf10d847a67f8b177df9e948837bb216db7f0ddeeb0a8f\", \"price_changes\":[{\"asset_id\":\"108872501708701256232360833975340759490903762166970350300622728710669503400981\", \"price\":\"0.03\", \"size\":\"169.59\", \"side\":\"BUY\", \"hash\":\"4da914c4212ff563d08d8a3168c4496969298b36\", \"best_bid\":\"0.999\", \"best_ask\":\"1\"}, {\"asset_id\":\"9589024508471284927421067800380793227060508852978748836190721804896525288035\", \"price\":\"0.97\", \"size\":\"169.59\", \"side\":\"SELL\", \"hash\":\"b1183ff3f797d8128bea36d2d17951c7d214498a\", \"best_bid\":\"0\", \"best_ask\":\"0.001\"}], \"timestamp\":\"1785036161446\", \"event_type\":\"price_change\"}","received_at":"2026-07-26T03:22:41.607722Z","schema_version":"clob-market-ws.price_change.v1","sequence":null,"server_hash":null,"server_timestamp":"1785036161446","session_id":"c31a343fa9584b66bec39f9faee0e3a0","source":"clob_market_ws"},"received_at":"2026-07-26T03:22:41.607722Z","record_id":"23015de6388ccdaa59345860e89ee9645de1274be67a96c5efd630dea76a82e3","schema_fingerprint":"4aa3821a28b0b7c2400bc59aba4bcc0a76e971dadd19610d3ad38c768e124dc7","schema_version":"edge-lab-recorder.raw.v1","sequence":null,"source":"clob_market_ws"}
{"event_at":"2026-07-26T03:22:42.208000Z","event_fingerprint":"054075dc88c36a2c7dbaaf346f6db42c6be1f1c85c0ce49936f5d1192fc21089","payload":{"connection_id":"f3be8c5f87ba4c71b8e5c26aee143178","event_at":"2026-07-26T03:22:42.208000Z","event_type":"new_market","frame_hash":"d6d9a75db43968f8fa0dc3ef427ce83bc3b4c46759c829884a9ca10c30a89592","frame_index":0,"kind":"data","monotonic_ns":138145824312458,"payload":{"active":false,"assets_ids":["9398744479045632945902348379219470401635487985796972870753656039205331233377","312636423596320462935684688734931092836837619038220513932930123351005089733"],"clob_token_ids":["9398744479045632945902348379219470401635487985796972870753656039205331233377","312636423596320462935684688734931092836837619038220513932930123351005089733"],"condition_id":"0xa886ccb591a134da49a30fb19f18a976aec1c7291a7bcbc66ed051d0baf795b3","description":"This market will resolve to \"Up\" if the Hyperliquid price at the end of the time range specified in the title is greater than or equal to the price at the beginning of that range. Otherwise, it will resolve to \"Down\".\nThe resolution source for this market is information from Chainlink, specifically the HYPE/USD data stream available at https://data.chain.link/streams/hype-usd.\nPlease note that this market is about the price according to Chainlink data stream HYPE/USD, not according to other sources or spot markets.","event_message":{"description":"This market will resolve to \"Up\" if the Hyperliquid price at the end of the time range specified in the title is greater than or equal to the price at the beginning of that range. Otherwise, it will resolve to \"Down\".\nThe resolution source for this market is information from Chainlink, specifically the HYPE/USD data stream available at https://data.chain.link/streams/hype-usd.\nPlease note that this market is about the price according to Chainlink data stream HYPE/USD, not according to other sources or spot markets.","id":"750043","slug":"hype-updown-5m-1785122100","ticker":"hype-updown-5m-1785122100","title":"Hyperliquid Up or Down - July 26, 11:15PM-11:20PM ET"},"event_type":"new_market","fee_schedule":{"exponent":"1","rate":"0.07","rebate_rate":"0.2","taker_only":true},"fees_enabled":true,"game_start_time":"","group_item_title":"","id":"3107512","line":"","market":"0xa886ccb591a134da49a30fb19f18a976aec1c7291a7bcbc66ed051d0baf795b3","order_price_min_tick_size":"0.01","outcomes":["Up","Down"],"question":"Hyperliquid Up or Down - July 26, 11:15PM-11:20PM ET","slug":"hype-updown-5m-1785122100","sports_market_type":"","tags":[],"taker_base_fee":"1000","timestamp":"1785036162208"},"payload_hash":"4b2346a62ee15aa8157143ae8adc5049bad782f7c047c9e75ac9241961f97c4c","raw_frame":"{\"id\":\"3107512\", \"question\":\"Hyperliquid Up or Down - July 26, 11:15PM-11:20PM ET\", \"market\":\"0xa886ccb591a134da49a30fb19f18a976aec1c7291a7bcbc66ed051d0baf795b3\", \"slug\":\"hype-updown-5m-1785122100\", \"description\":\"This market will resolve to \\\"Up\\\" if the Hyperliquid price at the end of the time range specified in the title is greater than or equal to the price at the beginning of that range. Otherwise, it will resolve to \\\"Down\\\".\\nThe resolution source for this market is information from Chainlink, specifically the HYPE/USD data stream available at https://data.chain.link/streams/hype-usd.\\nPlease note that this market is about the price according to Chainlink data stream HYPE/USD, not according to other sources or spot markets.\", \"assets_ids\":[\"9398744479045632945902348379219470401635487985796972870753656039205331233377\", \"312636423596320462935684688734931092836837619038220513932930123351005089733\"], \"outcomes\":[\"Up\", \"Down\"], \"event_message\":{\"id\":\"750043\", \"ticker\":\"hype-updown-5m-1785122100\", \"slug\":\"hype-updown-5m-1785122100\", \"title\":\"Hyperliquid Up or Down - July 26, 11:15PM-11:20PM ET\", \"description\":\"This market will resolve to \\\"Up\\\" if the Hyperliquid price at the end of the time range specified in the title is greater than or equal to the price at the beginning of that range. Otherwise, it will resolve to \\\"Down\\\".\\nThe resolution source for this market is information from Chainlink, specifically the HYPE/USD data stream available at https://data.chain.link/streams/hype-usd.\\nPlease note that this market is about the price according to Chainlink data stream HYPE/USD, not according to other sources or spot markets.\"}, \"timestamp\":\"1785036162208\", \"event_type\":\"new_market\", \"tags\":[], \"condition_id\":\"0xa886ccb591a134da49a30fb19f18a976aec1c7291a7bcbc66ed051d0baf795b3\", \"active\":false, \"clob_token_ids\":[\"9398744479045632945902348379219470401635487985796972870753656039205331233377\", \"312636423596320462935684688734931092836837619038220513932930123351005089733\"], \"sports_market_type\":\"\", \"line\":\"\", \"game_start_time\":\"\", \"order_price_min_tick_size\":\"0.01\", \"group_item_title\":\"\", \"taker_base_fee\":\"1000\", \"fees_enabled\":true, \"fee_schedule\":{\"exponent\":\"1\", \"rate\":\"0.07\", \"taker_only\":true, \"rebate_rate\":\"0.2\"}}","received_at":"2026-07-26T03:22:42.274045Z","schema_version":"clob-market-ws.new_market.v1","sequence":null,"server_hash":null,"server_timestamp":"1785036162208","session_id":"c31a343fa9584b66bec39f9faee0e3a0","source":"clob_market_ws"},"received_at":"2026-07-26T03:22:42.274045Z","record_id":"5a496bf2e0e05506f8f20b4165861fc1b0e497f8574a591443b0bf5924aa9f64","schema_fingerprint":"6639a822a7b79cfa4c3fc0044066e4f66ba8611f5bf361772bd6902a2319b82d","schema_version":"edge-lab-recorder.raw.v1","sequence":null,"source":"clob_market_ws"}
{"event_at":"2026-07-26T03:22:43.000000Z","event_fingerprint":"891625c4954807693de0b282382e790cf9b693138530613e6b94812883b8c9c0","payload":{"connection_id":"f3be8c5f87ba4c71b8e5c26aee143178","event_at":"2026-07-26T03:22:43.000000Z","event_type":"price_change","frame_hash":"574801605082546e00134f17023fe060b207ebe34c25b4c65e2fdc41ddc85ab1","frame_index":0,"kind":"data","monotonic_ns":138146606043791,"payload":{"event_type":"price_change","market":"0x4f38d51fa4a5a6ee7bef3839663f1ba6781f805620a00656a1ac78971ff65f94","price_changes":[{"asset_id":"44664371028109261969095768944878691828121031685263777021740408906309606948679","best_ask":"1","best_bid":"0.999","hash":"8edc834ee1a7b171dbb5dced884d1489bc8b4150","price":"0.001","side":"BUY","size":"123.56"},{"asset_id":"60846176734025071834155023520866063850736009438184221594765130197435585627848","best_ask":"0.001","best_bid":"0","hash":"9d1f7c162f9bcd9631b8fe279854e50f3337f3bf","price":"0.999","side":"SELL","size":"123.56"}],"timestamp":"1785036163000"},"payload_hash":"5cb85776ecf6da7cb7d70343ab86d5a2163a371cc8b6fc9dcb2276e649e2d859","raw_frame":"{\"market\":\"0x4f38d51fa4a5a6ee7bef3839663f1ba6781f805620a00656a1ac78971ff65f94\", \"price_changes\":[{\"asset_id\":\"44664371028109261969095768944878691828121031685263777021740408906309606948679\", \"price\":\"0.001\", \"size\":\"123.56\", \"side\":\"BUY\", \"hash\":\"8edc834ee1a7b171dbb5dced884d1489bc8b4150\", \"best_bid\":\"0.999\", \"best_ask\":\"1\"}, {\"asset_id\":\"60846176734025071834155023520866063850736009438184221594765130197435585627848\", \"price\":\"0.999\", \"size\":\"123.56\", \"side\":\"SELL\", \"hash\":\"9d1f7c162f9bcd9631b8fe279854e50f3337f3bf\", \"best_bid\":\"0\", \"best_ask\":\"0.001\"}], \"timestamp\":\"1785036163000\", \"event_type\":\"price_change\"}","received_at":"2026-07-26T03:22:43.055784Z","schema_version":"clob-market-ws.price_change.v1","sequence":null,"server_hash":null,"server_timestamp":"1785036163000","session_id":"c31a343fa9584b66bec39f9faee0e3a0","source":"clob_market_ws"},"received_at":"2026-07-26T03:22:43.055784Z","record_id":"e3ac42bb13885a4a539f6a6f2ff82c66571d2b874875d54c8256771dc4ad50eb","schema_fingerprint":"4aa3821a28b0b7c2400bc59aba4bcc0a76e971dadd19610d3ad38c768e124dc7","schema_version":"edge-lab-recorder.raw.v1","sequence":null,"source":"clob_market_ws"}
{"event_at":"2026-07-26T03:22:43.005000Z","event_fingerprint":"70f0c8194b886669d9eef2a84455fa03f4f3effa8c28fb01ad9a53eeef9a40ce","payload":{"connection_id":"f3be8c5f87ba4c71b8e5c26aee143178","event_at":"2026-07-26T03:22:43.005000Z","event_type":"price_change","frame_hash":"fd1cb6df7a9d6aee8a41f94417d5d0be1921d4fcb43011acc93bf52ea6ac671e","frame_index":0,"kind":"data","monotonic_ns":138146611930083,"payload":{"event_type":"price_change","market":"0x8c323abb1ede2f2619000d6a23ac35b5168d91d791d7f66b1ca85c76e0067cb2","price_changes":[{"asset_id":"21528271602641370669107334886285049226470476823971040418410401833791672433390","best_ask":"1","best_bid":"0.999","hash":"528057dc424bcde74e14acf90ac31ad59ddbfb68","price":"0.025","side":"BUY","size":"30"},{"asset_id":"99984412512137939403884906462112387899264398613764835397028075776778837165349","best_ask":"0.001","best_bid":"0","hash":"f314f451a7eab1197cf94dc43c805bb74b7caf81","price":"0.975","side":"SELL","size":"30"}],"timestamp":"1785036163005"},"payload_hash":"39ecaf285fb0ccf9b505af2f73df8f20ee22c9fcdc54abb3fddeab8d7312c098","raw_frame":"{\"market\":\"0x8c323abb1ede2f2619000d6a23ac35b5168d91d791d7f66b1ca85c76e0067cb2\", \"price_changes\":[{\"asset_id\":\"21528271602641370669107334886285049226470476823971040418410401833791672433390\", \"price\":\"0.025\", \"size\":\"30\", \"side\":\"BUY\", \"hash\":\"528057dc424bcde74e14acf90ac31ad59ddbfb68\", \"best_bid\":\"0.999\", \"best_ask\":\"1\"}, {\"asset_id\":\"99984412512137939403884906462112387899264398613764835397028075776778837165349\", \"price\":\"0.975\", \"size\":\"30\", \"side\":\"SELL\", \"hash\":\"f314f451a7eab1197cf94dc43c805bb74b7caf81\", \"best_bid\":\"0\", \"best_ask\":\"0.001\"}], \"timestamp\":\"1785036163005\", \"event_type\":\"price_change\"}","received_at":"2026-07-26T03:22:43.061675Z","schema_version":"clob-market-ws.price_change.v1","sequence":null,"server_hash":null,"server_timestamp":"1785036163005","session_id":"c31a343fa9584b66bec39f9faee0e3a0","source":"clob_market_ws"},"received_at":"2026-07-26T03:22:43.061675Z","record_id":"f80bf7ff3119091a6501e612e2284bf58662e05bb2eab9628517e012b58a77c2","schema_fingerprint":"4aa3821a28b0b7c2400bc59aba4bcc0a76e971dadd19610d3ad38c768e124dc7","schema_version":"edge-lab-recorder.raw.v1","sequence":null,"source":"clob_market_ws"}
{"event_at":"2026-07-26T03:22:43.001000Z","event_fingerprint":"736a63b2b7f24da2ae6a90210a0196d68f3e52a0e315a287073b3c00e95b98dc","payload":{"connection_id":"f3be8c5f87ba4c71b8e5c26aee143178","event_at":"2026-07-26T03:22:43.001000Z","event_type":"price_change","frame_hash":"f13329e79a46bfbaed6ed1e0f3837d325b402bc9d10aaecb8f6e75cb0992babe","frame_index":0,"kind":"data","monotonic_ns":138146620832458,"payload":{"event_type":"price_change","market":"0x4f38d51fa4a5a6ee7bef3839663f1ba6781f805620a00656a1ac78971ff65f94","price_changes":[{"asset_id":"44664371028109261969095768944878691828121031685263777021740408906309606948679","best_ask":"1","best_bid":"0.999","hash":"e0b7e8f8940267713f974f808d326ade2d4f1957","price":"0.025","side":"BUY","size":"30"},{"asset_id":"60846176734025071834155023520866063850736009438184221594765130197435585627848","best_ask":"0.001","best_bid":"0","hash":"2a0ac19a864abed5987bdcc20ba74a0f5310838d","price":"0.975","side":"SELL","size":"30"}],"timestamp":"1785036163001"},"payload_hash":"7b040aff3a99ef76618c050e3274ea2c43be6abbd33d391f36a8504ddc480027","raw_frame":"{\"market\":\"0x4f38d51fa4a5a6ee7bef3839663f1ba6781f805620a00656a1ac78971ff65f94\", \"price_changes\":[{\"asset_id\":\"44664371028109261969095768944878691828121031685263777021740408906309606948679\", \"price\":\"0.025\", \"size\":\"30\", \"side\":\"BUY\", \"hash\":\"e0b7e8f8940267713f974f808d326ade2d4f1957\", \"best_bid\":\"0.999\", \"best_ask\":\"1\"}, {\"asset_id\":\"60846176734025071834155023520866063850736009438184221594765130197435585627848\", \"price\":\"0.975\", \"size\":\"30\", \"side\":\"SELL\", \"hash\":\"2a0ac19a864abed5987bdcc20ba74a0f5310838d\", \"best_bid\":\"0\", \"best_ask\":\"0.001\"}], \"timestamp\":\"1785036163001\", \"event_type\":\"price_change\"}","received_at":"2026-07-26T03:22:43.070577Z","schema_version":"clob-market-ws.price_change.v1","sequence":null,"server_hash":null,"server_timestamp":"1785036163001","session_id":"c31a343fa9584b66bec39f9faee0e3a0","source":"clob_market_ws"},"received_at":"2026-07-26T03:22:43.070577Z","record_id":"48028d3f058131596e1e1f5ef92a01fbee7d30021bc20f6aa672a6465861f12f","schema_fingerprint":"4aa3821a28b0b7c2400bc59aba4bcc0a76e971dadd19610d3ad38c768e124dc7","schema_version":"edge-lab-recorder.raw.v1","sequence":null,"source":"clob_market_ws"}
{"event_at":"2026-07-26T03:22:43.005000Z","event_fingerprint":"d7a81301d860fa7b32812df6cf4f12e2853a8e2492771befa01fb730fa1242c0","payload":{"connection_id":"f3be8c5f87ba4c71b8e5c26aee143178","event_at":"2026-07-26T03:22:43.005000Z","event_type":"price_change","frame_hash":"060a9b8cbfd6edfba22979afe2b48ace7b1a3d38ecd3e221dba27fda735789cb","frame_index":0,"kind":"data","monotonic_ns":138146798717875,"payload":{"event_type":"price_change","market":"0x8c323abb1ede2f2619000d6a23ac35b5168d91d791d7f66b1ca85c76e0067cb2","price_changes":[{"asset_id":"21528271602641370669107334886285049226470476823971040418410401833791672433390","best_ask":"1","best_bid":"0.999","hash":"528057dc424bcde74e14acf90ac31ad59ddbfb68","price":"0.061","side":"BUY","size":"0"},{"asset_id":"99984412512137939403884906462112387899264398613764835397028075776778837165349","best_ask":"0.001","best_bid":"0","hash":"f314f451a7eab1197cf94dc43c805bb74b7caf81","price":"0.939","side":"SELL","size":"0"}],"timestamp":"1785036163005"},"payload_hash":"33c17c056159f1a2454305f926d37fcd46253b38fe0f37a7a6352060f76b4175","raw_frame":"{\"market\":\"0x8c323abb1ede2f2619000d6a23ac35b5168d91d791d7f66b1ca85c76e0067cb2\", \"price_changes\":[{\"asset_id\":\"21528271602641370669107334886285049226470476823971040418410401833791672433390\", \"price\":\"0.061\", \"size\":\"0\", \"side\":\"BUY\", \"hash\":\"528057dc424bcde74e14acf90ac31ad59ddbfb68\", \"best_bid\":\"0.999\", \"best_ask\":\"1\"}, {\"asset_id\":\"99984412512137939403884906462112387899264398613764835397028075776778837165349\", \"price\":\"0.939\", \"size\":\"0\", \"side\":\"SELL\", \"hash\":\"f314f451a7eab1197cf94dc43c805bb74b7caf81\", \"best_bid\":\"0\", \"best_ask\":\"0.001\"}], \"timestamp\":\"1785036163005\", \"event_type\":\"price_change\"}","received_at":"2026-07-26T03:22:43.248465Z","schema_version":"clob-market-ws.price_change.v1","sequence":null,"server_hash":null,"server_timestamp":"1785036163005","session_id":"c31a343fa9584b66bec39f9faee0e3a0","source":"clob_market_ws"},"received_at":"2026-07-26T03:22:43.248465Z","record_id":"18522176d758fcd7f2cce9a35f13a6866a17e8d4a0c4f40c9d6aace3f5fd11b3","schema_fingerprint":"4aa3821a28b0b7c2400bc59aba4bcc0a76e971dadd19610d3ad38c768e124dc7","schema_version":"edge-lab-recorder.raw.v1","sequence":null,"source":"clob_market_ws"}
{"event_at":"2026-07-26T03:22:43.038000Z","event_fingerprint":"a34e2ce0ba9c340a8a46b9dc8a19bf3cc27bb2992fa7253be617bf7287e10bad","payload":{"connection_id":"f3be8c5f87ba4c71b8e5c26aee143178","event_at":"2026-07-26T03:22:43.038000Z","event_type":"price_change","frame_hash":"620a65ce8524bef74486136effec5b366b8caa90922f6394cb0676576ab9d717","frame_index":0,"kind":"data","monotonic_ns":138146800469708,"payload":{"event_type":"price_change","market":"0x4f38d51fa4a5a6ee7bef3839663f1ba6781f805620a00656a1ac78971ff65f94","price_changes":[{"asset_id":"44664371028109261969095768944878691828121031685263777021740408906309606948679","best_ask":"1","best_bid":"0.999","hash":"1e85bd6a09b3b3b0a8ffb71e84dca4040a329921","price":"0.011","side":"BUY","size":"0"},{"asset_id":"60846176734025071834155023520866063850736009438184221594765130197435585627848","best_ask":"0.001","best_bid":"0","hash":"7ff985579d67efaa42e17733e468042fa51b233f","price":"0.989","side":"SELL","size":"0"}],"timestamp":"1785036163038"},"payload_hash":"f0d4012a7ca05e1819ac5a67aa10c23f1c63d34c6f57ba631d25815dcb4e40c4","raw_frame":"{\"market\":\"0x4f38d51fa4a5a6ee7bef3839663f1ba6781f805620a00656a1ac78971ff65f94\", \"price_changes\":[{\"asset_id\":\"44664371028109261969095768944878691828121031685263777021740408906309606948679\", \"price\":\"0.011\", \"size\":\"0\", \"side\":\"BUY\", \"hash\":\"1e85bd6a09b3b3b0a8ffb71e84dca4040a329921\", \"best_bid\":\"0.999\", \"best_ask\":\"1\"}, {\"asset_id\":\"60846176734025071834155023520866063850736009438184221594765130197435585627848\", \"price\":\"0.989\", \"size\":\"0\", \"side\":\"SELL\", \"hash\":\"7ff985579d67efaa42e17733e468042fa51b233f\", \"best_bid\":\"0\", \"best_ask\":\"0.001\"}], \"timestamp\":\"1785036163038\", \"event_type\":\"price_change\"}","received_at":"2026-07-26T03:22:43.250219Z","schema_version":"clob-market-ws.price_change.v1","sequence":null,"server_hash":null,"server_timestamp":"1785036163038","session_id":"c31a343fa9584b66bec39f9faee0e3a0","source":"clob_market_ws"},"received_at":"2026-07-26T03:22:43.250219Z","record_id":"a32e5a8cbe70b96dba3d05803f63b05e8d78dbb81a7d5b2f30a6c98d6b1e1e3e","schema_fingerprint":"4aa3821a28b0b7c2400bc59aba4bcc0a76e971dadd19610d3ad38c768e124dc7","schema_version":"edge-lab-recorder.raw.v1","sequence":null,"source":"clob_market_ws"}
{"event_at":"2026-07-26T03:22:43.047000Z","event_fingerprint":"729c512e4e2db2d6ba9788eee17a0940633f65fa30b1716211098df7d256677c","payload":{"connection_id":"f3be8c5f87ba4c71b8e5c26aee143178","event_at":"2026-07-26T03:22:43.047000Z","event_type":"price_change","frame_hash":"17574749597b98829f4b83d68779fac8c08fc3c0d89993475b41e7794abfda9a","frame_index":0,"kind":"data","monotonic_ns":138146803097333,"payload":{"event_type":"price_change","market":"0x8c323abb1ede2f2619000d6a23ac35b5168d91d791d7f66b1ca85c76e0067cb2","price_changes":[{"asset_id":"21528271602641370669107334886285049226470476823971040418410401833791672433390","best_ask":"1","best_bid":"0.999","hash":"83b45345f10a5a70ce160d7f2833e09ffb7d471a","price":"0.011","side":"BUY","size":"0"},{"asset_id":"99984412512137939403884906462112387899264398613764835397028075776778837165349","best_ask":"0.001","best_bid":"0","hash":"83708dc73926638505cc5f4e1ad66b990f02fde6","price":"0.989","side":"SELL","size":"0"}],"timestamp":"1785036163047"},"payload_hash":"e05e6d438c1e06f9db96b4939a2062930074a1a39faff7d4aa5a877418f37512","raw_frame":"{\"market\":\"0x8c323abb1ede2f2619000d6a23ac35b5168d91d791d7f66b1ca85c76e0067cb2\", \"price_changes\":[{\"asset_id\":\"21528271602641370669107334886285049226470476823971040418410401833791672433390\", \"price\":\"0.011\", \"size\":\"0\", \"side\":\"BUY\", \"hash\":\"83b45345f10a5a70ce160d7f2833e09ffb7d471a\", \"best_bid\":\"0.999\", \"best_ask\":\"1\"}, {\"asset_id\":\"99984412512137939403884906462112387899264398613764835397028075776778837165349\", \"price\":\"0.989\", \"size\":\"0\", \"side\":\"SELL\", \"hash\":\"83708dc73926638505cc5f4e1ad66b990f02fde6\", \"best_bid\":\"0\", \"best_ask\":\"0.001\"}], \"timestamp\":\"1785036163047\", \"event_type\":\"price_change\"}","received_at":"2026-07-26T03:22:43.252850Z","schema_version":"clob-market-ws.price_change.v1","sequence":null,"server_hash":null,"server_timestamp":"1785036163047","session_id":"c31a343fa9584b66bec39f9faee0e3a0","source":"clob_market_ws"},"received_at":"2026-07-26T03:22:43.252850Z","record_id":"a10e1036d132264ecbcd435ba8809dda496be953ea2c9602c095721d4149fa6b","schema_fingerprint":"4aa3821a28b0b7c2400bc59aba4bcc0a76e971dadd19610d3ad38c768e124dc7","schema_version":"edge-lab-recorder.raw.v1","sequence":null,"source":"clob_market_ws"}
{"event_at":"2026-07-26T03:22:43.066000Z","event_fingerprint":"0eecf10197710615f318472d9a5e0836c02337f1449ba42b4c0b2f023fc3a148","payload":{"connection_id":"f3be8c5f87ba4c71b8e5c26aee143178","event_at":"2026-07-26T03:22:43.066000Z","event_type":"price_change","frame_hash":"d61822eea3c1e832eb166abd26bc58095127cae447452a3df5d02b79c46a3761","frame_index":0,"kind":"data","monotonic_ns":138146804647291,"payload":{"event_type":"price_change","market":"0x4f38d51fa4a5a6ee7bef3839663f1ba6781f805620a00656a1ac78971ff65f94","price_changes":[{"asset_id":"44664371028109261969095768944878691828121031685263777021740408906309606948679","best_ask":"1","best_bid":"0.999","hash":"a19436396c70a474fc9fe76ef51571b6025cfcb9","price":"0.061","side":"BUY","size":"0"},{"asset_id":"60846176734025071834155023520866063850736009438184221594765130197435585627848","best_ask":"0.001","best_bid":"0","hash":"f0f7fc750d46dfe59a82febe4798083bc710e00a","price":"0.939","side":"SELL","size":"0"}],"timestamp":"1785036163066"},"payload_hash":"a120aa6eecca31c33cbc6788707f0f3a604d6678e94c21ce8526628405eb036c","raw_frame":"{\"market\":\"0x4f38d51fa4a5a6ee7bef3839663f1ba6781f805620a00656a1ac78971ff65f94\", \"price_changes\":[{\"asset_id\":\"44664371028109261969095768944878691828121031685263777021740408906309606948679\", \"price\":\"0.061\", \"size\":\"0\", \"side\":\"BUY\", \"hash\":\"a19436396c70a474fc9fe76ef51571b6025cfcb9\", \"best_bid\":\"0.999\", \"best_ask\":\"1\"}, {\"asset_id\":\"60846176734025071834155023520866063850736009438184221594765130197435585627848\", \"price\":\"0.939\", \"size\":\"0\", \"side\":\"SELL\", \"hash\":\"f0f7fc750d46dfe59a82febe4798083bc710e00a\", \"best_bid\":\"0\", \"best_ask\":\"0.001\"}], \"timestamp\":\"1785036163066\", \"event_type\":\"price_change\"}","received_at":"2026-07-26T03:22:43.254402Z","schema_version":"clob-market-ws.price_change.v1","sequence":null,"server_hash":null,"server_timestamp":"1785036163066","session_id":"c31a343fa9584b66bec39f9faee0e3a0","source":"clob_market_ws"},"received_at":"2026-07-26T03:22:43.254402Z","record_id":"a3f03873ec0e1d38818f29934c97a76c5d9bb1130ebd25d4321779c1d088e3ac","schema_fingerprint":"4aa3821a28b0b7c2400bc59aba4bcc0a76e971dadd19610d3ad38c768e124dc7","schema_version":"edge-lab-recorder.raw.v1","sequence":null,"source":"clob_market_ws"}
{"event_at":null,"event_fingerprint":"31889ca91b9e4f55713d1583779c21426489dc4bc99311d3a7f9326dc79975a3","payload":{"connection_id":"f3be8c5f87ba4c71b8e5c26aee143178","detail":{"interval_seconds":10.0,"message":"PING"},"event_type":"heartbeat","kind":"lifecycle","monotonic_ns":138148153408666,"received_at":"2026-07-26T03:22:44.603168Z","schema_version":"edge-lab-recorder.lifecycle.v1","session_id":"c31a343fa9584b66bec39f9faee0e3a0","source":"clob_market_ws"},"received_at":"2026-07-26T03:22:44.603168Z","record_id":"3f9892560d23e5e988182782d2c1ac42fcdcf6895f74dfa9923ca9a79291be13","schema_fingerprint":"cb8aa3aa4cb168a4b724fd9077bee6ecfb9bc586c57cfdf0ab89f00d82045e3c","schema_version":"edge-lab-recorder.raw.v1","sequence":null,"source":"clob_market_ws"}
{"event_at":null,"event_fingerprint":"96b1c298a9819e43b7af4c34b1779f163f6f6aeff6f3e72a059c00f392275996","payload":{"connection_id":"f3be8c5f87ba4c71b8e5c26aee143178","event_type":"heartbeat_ack","frame_hash":"95784973cc639977bff93619700168505cb8f7855e44fa643d34622a43706c87","kind":"lifecycle","monotonic_ns":138148355876208,"raw_frame":"PONG","received_at":"2026-07-26T03:22:44.805637Z","schema_version":"edge-lab-recorder.heartbeat-ack.v1","session_id":"c31a343fa9584b66bec39f9faee0e3a0","source":"clob_market_ws"},"received_at":"2026-07-26T03:22:44.805637Z","record_id":"4e0062db507e968037c4cd83b69bb6187e89631b5e6317a76463ac46d82142e2","schema_fingerprint":"c14ee1aab3ca674ee738e5268877b544d74c41ad3c427cedc09236467dc68ba1","schema_version":"edge-lab-recorder.raw.v1","sequence":null,"source":"clob_market_ws"}
{"event_at":"2026-07-26T03:22:53.946000Z","event_fingerprint":"fdb6c3e758e45a7bc131246bb4b7b098e162a87c8a00a064ba7cf58d666f0f10","payload":{"connection_id":"f3be8c5f87ba4c71b8e5c26aee143178","event_at":"2026-07-26T03:22:53.946000Z","event_type":"price_change","frame_hash":"a8fb6e2a0705bbef7e557e126e2082715e35e670b302142334dd8912bbbd6ca0","frame_index":0,"kind":"data","monotonic_ns":138157562307041,"payload":{"event_type":"price_change","market":"0xf5c1ad6b533e31b7156c48d12276744433a7dd1829938850a73717cea9d53821","price_changes":[{"asset_id":"34600602296599885071917717676988207363957952958012665255891266571657806817559","best_ask":"0.001","best_bid":"0","hash":"55a2b94e3922bc280bf55ff01a5b983d142aee31","price":"0.001","side":"SELL","size":"24767.16"},{"asset_id":"17984242239730438865135655538589475203118151844342180615256685234465965850727","best_ask":"1","best_bid":"0.999","hash":"1ea8b8948aff2a52aec58df3efd069e003e0fa21","price":"0.999","side":"BUY","size":"24767.16"}],"timestamp":"1785036173946"},"payload_hash":"4446fb660bea761a43af997972c7b4b062949cae4f3bfb5b4555a11bcbdc8906","raw_frame":"{\"market\":\"0xf5c1ad6b533e31b7156c48d12276744433a7dd1829938850a73717cea9d53821\", \"price_changes\":[{\"asset_id\":\"34600602296599885071917717676988207363957952958012665255891266571657806817559\", \"price\":\"0.001\", \"size\":\"24767.16\", \"side\":\"SELL\", \"hash\":\"55a2b94e3922bc280bf55ff01a5b983d142aee31\", \"best_bid\":\"0\", \"best_ask\":\"0.001\"}, {\"asset_id\":\"17984242239730438865135655538589475203118151844342180615256685234465965850727\", \"price\":\"0.999\", \"size\":\"24767.16\", \"side\":\"BUY\", \"hash\":\"1ea8b8948aff2a52aec58df3efd069e003e0fa21\", \"best_bid\":\"0.999\", \"best_ask\":\"1\"}], \"timestamp\":\"1785036173946\", \"event_type\":\"price_change\"}","received_at":"2026-07-26T03:22:54.012211Z","schema_version":"clob-market-ws.price_change.v1","sequence":null,"server_hash":null,"server_timestamp":"1785036173946","session_id":"c31a343fa9584b66bec39f9faee0e3a0","source":"clob_market_ws"},"received_at":"2026-07-26T03:22:54.012211Z","record_id":"81af54219cc68f281c0b1c29ccc11378c05d90358dcf656a3ae77d60873c91e3","schema_fingerprint":"4aa3821a28b0b7c2400bc59aba4bcc0a76e971dadd19610d3ad38c768e124dc7","schema_version":"edge-lab-recorder.raw.v1","sequence":null,"source":"clob_market_ws"}
{"event_at":"2026-07-26T03:22:53.945000Z","event_fingerprint":"288cb3688230ef3f59b21686a5bb14368ddfda6c6f22812a58dec7e7add4e485","payload":{"connection_id":"f3be8c5f87ba4c71b8e5c26aee143178","event_at":"2026-07-26T03:22:53.945000Z","event_type":"price_change","frame_hash":"972f795a9790aef1843f8e4fb037837be532a11a9d5952cd802cef198d20a0e8","frame_index":0,"kind":"data","monotonic_ns":138157563246625,"payload":{"event_type":"price_change","market":"0x4f38d51fa4a5a6ee7bef3839663f1ba6781f805620a00656a1ac78971ff65f94","price_changes":[{"asset_id":"60846176734025071834155023520866063850736009438184221594765130197435585627848","best_ask":"0.001","best_bid":"0","hash":"9a464e1ade6fa13161f1dd09234415fcfe7e0a3b","price":"0.001","side":"SELL","size":"2823.92"},{"asset_id":"44664371028109261969095768944878691828121031685263777021740408906309606948679","best_ask":"1","best_bid":"0.999","hash":"fcc03b10ce93647084ef0949660e19107d13ed78","price":"0.999","side":"BUY","size":"2823.92"}],"timestamp":"1785036173945"},"payload_hash":"70acc83ba38feda715865aa71b74d5b9bb1b9c40bf9dbe556c6ca9d7b34c8239","raw_frame":"{\"market\":\"0x4f38d51fa4a5a6ee7bef3839663f1ba6781f805620a00656a1ac78971ff65f94\", \"price_changes\":[{\"asset_id\":\"60846176734025071834155023520866063850736009438184221594765130197435585627848\", \"price\":\"0.001\", \"size\":\"2823.92\", \"side\":\"SELL\", \"hash\":\"9a464e1ade6fa13161f1dd09234415fcfe7e0a3b\", \"best_bid\":\"0\", \"best_ask\":\"0.001\"}, {\"asset_id\":\"44664371028109261969095768944878691828121031685263777021740408906309606948679\", \"price\":\"0.999\", \"size\":\"2823.92\", \"side\":\"BUY\", \"hash\":\"fcc03b10ce93647084ef0949660e19107d13ed78\", \"best_bid\":\"0.999\", \"best_ask\":\"1\"}], \"timestamp\":\"1785036173945\", \"event_type\":\"price_change\"}","received_at":"2026-07-26T03:22:54.013149Z","schema_version":"clob-market-ws.price_change.v1","sequence":null,"server_hash":null,"server_timestamp":"1785036173945","session_id":"c31a343fa9584b66bec39f9faee0e3a0","source":"clob_market_ws"},"received_at":"2026-07-26T03:22:54.013149Z","record_id":"5281c0a6451ddb7b6d677ee592199612817cba6b795bf6bc129a56d5fac2128a","schema_fingerprint":"4aa3821a28b0b7c2400bc59aba4bcc0a76e971dadd19610d3ad38c768e124dc7","schema_version":"edge-lab-recorder.raw.v1","sequence":null,"source":"clob_market_ws"}
{"event_at":"2026-07-26T03:22:53.949000Z","event_fingerprint":"fc3a35eea9baa1706c22393fc70300fbeef0cd5661cb049cd2fdbef0dcffde76","payload":{"connection_id":"f3be8c5f87ba4c71b8e5c26aee143178","event_at":"2026-07-26T03:22:53.949000Z","event_type":"price_change","frame_hash":"0be0f9500fa545aedd2c4f1c37934c7e19ea6fca7689f5ad537b84e24a393771","frame_index":0,"kind":"data","monotonic_ns":138157571145041,"payload":{"event_type":"price_change","market":"0xd34d11638850161b49d343af579b355a91a40625a1cb324b89da0ec34316ce0d","price_changes":[{"asset_id":"72412292208263882620567760335223208281592684887840447866591915373071557986157","best_ask":"0.001","best_bid":"0","hash":"6c3e738802230104c5f147af70866f4cb30956bb","price":"0.001","side":"SELL","size":"2654.01"},{"asset_id":"23304427590407806052073703058430344447294483314513948492296568658168726366081","best_ask":"1","best_bid":"0.999","hash":"081a0a6679d636f370225169b7b910a173bc891b","price":"0.999","side":"BUY","size":"2654.01"}],"timestamp":"1785036173949"},"payload_hash":"6c2aeaf916001fa8816e383c78d38b75455048427858497fb15d5aeac2a6fa10","raw_frame":"{\"market\":\"0xd34d11638850161b49d343af579b355a91a40625a1cb324b89da0ec34316ce0d\", \"price_changes\":[{\"asset_id\":\"72412292208263882620567760335223208281592684887840447866591915373071557986157\", \"price\":\"0.001\", \"size\":\"2654.01\", \"side\":\"SELL\", \"hash\":\"6c3e738802230104c5f147af70866f4cb30956bb\", \"best_bid\":\"0\", \"best_ask\":\"0.001\"}, {\"asset_id\":\"23304427590407806052073703058430344447294483314513948492296568658168726366081\", \"price\":\"0.999\", \"size\":\"2654.01\", \"side\":\"BUY\", \"hash\":\"081a0a6679d636f370225169b7b910a173bc891b\", \"best_bid\":\"0.999\", \"best_ask\":\"1\"}], \"timestamp\":\"1785036173949\", \"event_type\":\"price_change\"}","received_at":"2026-07-26T03:22:54.021052Z","schema_version":"clob-market-ws.price_change.v1","sequence":null,"server_hash":null,"server_timestamp":"1785036173949","session_id":"c31a343fa9584b66bec39f9faee0e3a0","source":"clob_market_ws"},"received_at":"2026-07-26T03:22:54.021052Z","record_id":"cc6d1c66e53777837fcf10452d6ac5f2d068dc42ddee1f8d34b550849ce1b62b","schema_fingerprint":"4aa3821a28b0b7c2400bc59aba4bcc0a76e971dadd19610d3ad38c768e124dc7","schema_version":"edge-lab-recorder.raw.v1","sequence":null,"source":"clob_market_ws"}
{"event_at":"2026-07-26T03:22:53.950000Z","event_fingerprint":"67e2879456b685a4cdc0f3d58cd20163af2d5f7bbd50fc3b8a0b6c9c24b7a991","payload":{"connection_id":"f3be8c5f87ba4c71b8e5c26aee143178","event_at":"2026-07-26T03:22:53.950000Z","event_type":"price_change","frame_hash":"5c953fec96b7650609d32429f32eac9b9bb801bdc2e17f472270b160925d78fe","frame_index":0,"kind":"data","monotonic_ns":138157571866500,"payload":{"event_type":"price_change","market":"0x9c381c628d4d7f50c84fe33ed2e6034c9e95a38fe2bbaf0839e0045ed6ebb00a","price_changes":[{"asset_id":"65498980163493839080617380002950766616985632732897237936946030803559673024127","best_ask":"0.001","best_bid":"0","hash":"94ded39af35379eaa44a45bb61703c4fd5423666","price":"0.001","side":"SELL","size":"2624.01"},{"asset_id":"54242839679678573772031723750101159478558866523031929268633860829634800562410","best_ask":"1","best_bid":"0.999","hash":"20d37b4c1953ef033a5afe4d9709642fc71af290","price":"0.999","side":"BUY","size":"2624.01"}],"timestamp":"1785036173950"},"payload_hash":"d220238bde6fd4b15f4439d54e50ab3f8db08c569b30050bdbd011522d68f706","raw_frame":"{\"market\":\"0x9c381c628d4d7f50c84fe33ed2e6034c9e95a38fe2bbaf0839e0045ed6ebb00a\", \"price_changes\":[{\"asset_id\":\"65498980163493839080617380002950766616985632732897237936946030803559673024127\", \"price\":\"0.001\", \"size\":\"2624.01\", \"side\":\"SELL\", \"hash\":\"94ded39af35379eaa44a45bb61703c4fd5423666\", \"best_bid\":\"0\", \"best_ask\":\"0.001\"}, {\"asset_id\":\"54242839679678573772031723750101159478558866523031929268633860829634800562410\", \"price\":\"0.999\", \"size\":\"2624.01\", \"side\":\"BUY\", \"hash\":\"20d37b4c1953ef033a5afe4d9709642fc71af290\", \"best_bid\":\"0.999\", \"best_ask\":\"1\"}], \"timestamp\":\"1785036173950\", \"event_type\":\"price_change\"}","received_at":"2026-07-26T03:22:54.021778Z","schema_version":"clob-market-ws.price_change.v1","sequence":null,"server_hash":null,"server_timestamp":"1785036173950","session_id":"c31a343fa9584b66bec39f9faee0e3a0","source":"clob_market_ws"},"received_at":"2026-07-26T03:22:54.021778Z","record_id":"59bea9bf7e3df7bd0c0c934ca7c1d160d82117b64c7fd25393a0eba9d2fb5f94","schema_fingerprint":"4aa3821a28b0b7c2400bc59aba4bcc0a76e971dadd19610d3ad38c768e124dc7","schema_version":"edge-lab-recorder.raw.v1","sequence":null,"source":"clob_market_ws"}
{"event_at":"2026-07-26T03:22:53.969000Z","event_fingerprint":"7923e411c961744d0c611b09de6c218270267a49901c6564ca4e9276e8ff9a6b","payload":{"connection_id":"f3be8c5f87ba4c71b8e5c26aee143178","event_at":"2026-07-26T03:22:53.969000Z","event_type":"price_change","frame_hash":"f033cd373c7788db785782b8237ed81ef9dd0edd46eafb55a5076f3d9b4ae96b","frame_index":0,"kind":"data","monotonic_ns":138157629746375,"payload":{"event_type":"price_change","market":"0x37b4e66ed76a1ae459bf10d847a67f8b177df9e948837bb216db7f0ddeeb0a8f","price_changes":[{"asset_id":"108872501708701256232360833975340759490903762166970350300622728710669503400981","best_ask":"1","best_bid":"0.999","hash":"3f044815ee5cc6c697f4cd17633f780de10e0d8c","price":"0.03","side":"BUY","size":"69.59"},{"asset_id":"9589024508471284927421067800380793227060508852978748836190721804896525288035","best_ask":"0.001","best_bid":"0","hash":"b21c770da14990f23dd5397fabe635c15ba1f9ee","price":"0.97","side":"SELL","size":"69.59"}],"timestamp":"1785036173969"},"payload_hash":"046d9ac44848733778e1db90894e43e6b7ee27d35e7ba5c78fe96e5b8c51ff12","raw_frame":"{\"market\":\"0x37b4e66ed76a1ae459bf10d847a67f8b177df9e948837bb216db7f0ddeeb0a8f\", \"price_changes\":[{\"asset_id\":\"108872501708701256232360833975340759490903762166970350300622728710669503400981\", \"price\":\"0.03\", \"size\":\"69.59\", \"side\":\"BUY\", \"hash\":\"3f044815ee5cc6c697f4cd17633f780de10e0d8c\", \"best_bid\":\"0.999\", \"best_ask\":\"1\"}, {\"asset_id\":\"9589024508471284927421067800380793227060508852978748836190721804896525288035\", \"price\":\"0.97\", \"size\":\"69.59\", \"side\":\"SELL\", \"hash\":\"b21c770da14990f23dd5397fabe635c15ba1f9ee\", \"best_bid\":\"0\", \"best_ask\":\"0.001\"}], \"timestamp\":\"1785036173969\", \"event_type\":\"price_change\"}","received_at":"2026-07-26T03:22:54.079658Z","schema_version":"clob-market-ws.price_change.v1","sequence":null,"server_hash":null,"server_timestamp":"1785036173969","session_id":"c31a343fa9584b66bec39f9faee0e3a0","source":"clob_market_ws"},"received_at":"2026-07-26T03:22:54.079658Z","record_id":"2a06e5bf22b232e767bc1798eaa464b4cf7cdfd16253e4301df0a0d9c38c00cc","schema_fingerprint":"4aa3821a28b0b7c2400bc59aba4bcc0a76e971dadd19610d3ad38c768e124dc7","schema_version":"edge-lab-recorder.raw.v1","sequence":null,"source":"clob_market_ws"}
{"event_at":"2026-07-26T03:22:54.371000Z","event_fingerprint":"93edf3ff52b001f9d90cf4c3f5b4ff2fd4d26c8c30caede48fff0722e8232643","payload":{"connection_id":"f3be8c5f87ba4c71b8e5c26aee143178","event_at":"2026-07-26T03:22:54.371000Z","event_type":"price_change","frame_hash":"f0238848e2018e1a2bf21b521c88d729b134e472d7a9508a97390af566803316","frame_index":0,"kind":"data","monotonic_ns":138157976625916,"payload":{"event_type":"price_change","market":"0xd34d11638850161b49d343af579b355a91a40625a1cb324b89da0ec34316ce0d","price_changes":[{"asset_id":"72412292208263882620567760335223208281592684887840447866591915373071557986157","best_ask":"0.001","best_bid":"0","hash":"2da92a02c65cc05e00c53722a106922bb3cfc20c","price":"0.001","side":"SELL","size":"2966.04"},{"asset_id":"23304427590407806052073703058430344447294483314513948492296568658168726366081","best_ask":"1","best_bid":"0.999","hash":"88f406d89d139dfdf617994a04a6f050591ce85e","price":"0.999","side":"BUY","size":"2966.04"}],"timestamp":"1785036174371"},"payload_hash":"cc1dfa857e49cb9995d5c3a959efd81dddb285d42f92b793b7a272ba7ceeb90c","raw_frame":"{\"market\":\"0xd34d11638850161b49d343af579b355a91a40625a1cb324b89da0ec34316ce0d\", \"price_changes\":[{\"asset_id\":\"72412292208263882620567760335223208281592684887840447866591915373071557986157\", \"price\":\"0.001\", \"size\":\"2966.04\", \"side\":\"SELL\", \"hash\":\"2da92a02c65cc05e00c53722a106922bb3cfc20c\", \"best_bid\":\"0\", \"best_ask\":\"0.001\"}, {\"asset_id\":\"23304427590407806052073703058430344447294483314513948492296568658168726366081\", \"price\":\"0.999\", \"size\":\"2966.04\", \"side\":\"BUY\", \"hash\":\"88f406d89d139dfdf617994a04a6f050591ce85e\", \"best_bid\":\"0.999\", \"best_ask\":\"1\"}], \"timestamp\":\"1785036174371\", \"event_type\":\"price_change\"}","received_at":"2026-07-26T03:22:54.426520Z","schema_version":"clob-market-ws.price_change.v1","sequence":null,"server_hash":null,"server_timestamp":"1785036174371","session_id":"c31a343fa9584b66bec39f9faee0e3a0","source":"clob_market_ws"},"received_at":"2026-07-26T03:22:54.426520Z","record_id":"6282046a626539d2b994cc38ec80f093b86b8d195eefe327d6c855ff79db3209","schema_fingerprint":"4aa3821a28b0b7c2400bc59aba4bcc0a76e971dadd19610d3ad38c768e124dc7","schema_version":"edge-lab-recorder.raw.v1","sequence":null,"source":"clob_market_ws"}
{"event_at":"2026-07-26T03:22:54.371000Z","event_fingerprint":"64aa54c38b52c16fe217c7e9bfcfa2a7e21cc78cbd566ce18624644f28257bc7","payload":{"connection_id":"f3be8c5f87ba4c71b8e5c26aee143178","event_at":"2026-07-26T03:22:54.371000Z","event_type":"price_change","frame_hash":"f85ee1c1d3f9052160318a43a8411b11dc08ceb9c1e186056b8651a6c6ce9431","frame_index":0,"kind":"data","monotonic_ns":138157978616291,"payload":{"event_type":"price_change","market":"0x4f38d51fa4a5a6ee7bef3839663f1ba6781f805620a00656a1ac78971ff65f94","price_changes":[{"asset_id":"60846176734025071834155023520866063850736009438184221594765130197435585627848","best_ask":"0.001","best_bid":"0","hash":"56bc46baf2a47780251a439093b128708ca89c64","price":"0.001","side":"SELL","size":"2895"},{"asset_id":"44664371028109261969095768944878691828121031685263777021740408906309606948679","best_ask":"1","best_bid":"0.999","hash":"3b72078dec3bdedf5ab26f95444c4714fcd14302","price":"0.999","side":"BUY","size":"2895"}],"timestamp":"1785036174371"},"payload_hash":"3344025e719efeb7e0f8ec16355018a22c2c6dd5e5a4a12feb602c94060b10d5","raw_frame":"{\"market\":\"0x4f38d51fa4a5a6ee7bef3839663f1ba6781f805620a00656a1ac78971ff65f94\", \"price_changes\":[{\"asset_id\":\"60846176734025071834155023520866063850736009438184221594765130197435585627848\", \"price\":\"0.001\", \"size\":\"2895\", \"side\":\"SELL\", \"hash\":\"56bc46baf2a47780251a439093b128708ca89c64\", \"best_bid\":\"0\", \"best_ask\":\"0.001\"}, {\"asset_id\":\"44664371028109261969095768944878691828121031685263777021740408906309606948679\", \"price\":\"0.999\", \"size\":\"2895\", \"side\":\"BUY\", \"hash\":\"3b72078dec3bdedf5ab26f95444c4714fcd14302\", \"best_bid\":\"0.999\", \"best_ask\":\"1\"}], \"timestamp\":\"1785036174371\", \"event_type\":\"price_change\"}","received_at":"2026-07-26T03:22:54.428525Z","schema_version":"clob-market-ws.price_change.v1","sequence":null,"server_hash":null,"server_timestamp":"1785036174371","session_id":"c31a343fa9584b66bec39f9faee0e3a0","source":"clob_market_ws"},"received_at":"2026-07-26T03:22:54.428525Z","record_id":"1fde2be2a40cf63714446e51775099b17c9b23cc762ca76dd1bf7fdf09ec910b","schema_fingerprint":"4aa3821a28b0b7c2400bc59aba4bcc0a76e971dadd19610d3ad38c768e124dc7","schema_version":"edge-lab-recorder.raw.v1","sequence":null,"source":"clob_market_ws"}
{"event_at":"2026-07-26T03:22:54.371000Z","event_fingerprint":"509d6d9114bd2c0816f4b4a7dd92e24e677c5086b3713cf8ba872a7ae780a9b8","payload":{"connection_id":"f3be8c5f87ba4c71b8e5c26aee143178","event_at":"2026-07-26T03:22:54.371000Z","event_type":"price_change","frame_hash":"51da767332ba9c8bfba34d3abb9753087747256c4228e0020c9e5512e120c8db","frame_index":0,"kind":"data","monotonic_ns":138157980347250,"payload":{"event_type":"price_change","market":"0x9c381c628d4d7f50c84fe33ed2e6034c9e95a38fe2bbaf0839e0045ed6ebb00a","price_changes":[{"asset_id":"65498980163493839080617380002950766616985632732897237936946030803559673024127","best_ask":"0.001","best_bid":"0","hash":"5da54c467891d07304db653703691a5dac7d4bb1","price":"0.001","side":"SELL","size":"3148.22"},{"asset_id":"54242839679678573772031723750101159478558866523031929268633860829634800562410","best_ask":"1","best_bid":"0.999","hash":"b8a8273f43c94995c137f48fdc055ffa85549698","price":"0.999","side":"BUY","size":"3148.22"}],"timestamp":"1785036174371"},"payload_hash":"bdccfc7729450e366012989cee2b33de19cb0da5fd682ab6d92b0ad19b07fc3b","raw_frame":"{\"market\":\"0x9c381c628d4d7f50c84fe33ed2e6034c9e95a38fe2bbaf0839e0045ed6ebb00a\", \"price_changes\":[{\"asset_id\":\"65498980163493839080617380002950766616985632732897237936946030803559673024127\", \"price\":\"0.001\", \"size\":\"3148.22\", \"side\":\"SELL\", \"hash\":\"5da54c467891d07304db653703691a5dac7d4bb1\", \"best_bid\":\"0\", \"best_ask\":\"0.001\"}, {\"asset_id\":\"54242839679678573772031723750101159478558866523031929268633860829634800562410\", \"price\":\"0.999\", \"size\":\"3148.22\", \"side\":\"BUY\", \"hash\":\"b8a8273f43c94995c137f48fdc055ffa85549698\", \"best_bid\":\"0.999\", \"best_ask\":\"1\"}], \"timestamp\":\"1785036174371\", \"event_type\":\"price_change\"}","received_at":"2026-07-26T03:22:54.430262Z","schema_version":"clob-market-ws.price_change.v1","sequence":null,"server_hash":null,"server_timestamp":"1785036174371","session_id":"c31a343fa9584b66bec39f9faee0e3a0","source":"clob_market_ws"},"received_at":"2026-07-26T03:22:54.430262Z","record_id":"78ed5a34a5c42d91a5501cca2099d561b374cc1f33daf2a108a5a8d5c38a6736","schema_fingerprint":"4aa3821a28b0b7c2400bc59aba4bcc0a76e971dadd19610d3ad38c768e124dc7","schema_version":"edge-lab-recorder.raw.v1","sequence":null,"source":"clob_market_ws"}
{"event_at":"2026-07-26T03:22:54.371000Z","event_fingerprint":"73f60b4c40612bb1f76347e98558c5596505c84f6d03b5e7c74c5a56a46cc1e7","payload":{"connection_id":"f3be8c5f87ba4c71b8e5c26aee143178","event_at":"2026-07-26T03:22:54.371000Z","event_type":"price_change","frame_hash":"9b7b4c9dc8b81056903c437ba6239219120652e1a7b4ac9445d6eace6c992354","frame_index":0,"kind":"data","monotonic_ns":138157981851166,"payload":{"event_type":"price_change","market":"0xf5c1ad6b533e31b7156c48d12276744433a7dd1829938850a73717cea9d53821","price_changes":[{"asset_id":"34600602296599885071917717676988207363957952958012665255891266571657806817559","best_ask":"0.001","best_bid":"0","hash":"ab686939bf315d7f60d1d87e952363482e148d7c","price":"0.001","side":"SELL","size":"24858.24"},{"asset_id":"17984242239730438865135655538589475203118151844342180615256685234465965850727","best_ask":"1","best_bid":"0.999","hash":"914dc6f55f697ff0596e2add3b5006c14d5861b8","price":"0.999","side":"BUY","size":"24858.24"}],"timestamp":"1785036174371"},"payload_hash":"51f9249e9f5177275d0b8ad61e5cb26c90368db01b8965f0c7a08bf43b29eeed","raw_frame":"{\"market\":\"0xf5c1ad6b533e31b7156c48d12276744433a7dd1829938850a73717cea9d53821\", \"price_changes\":[{\"asset_id\":\"34600602296599885071917717676988207363957952958012665255891266571657806817559\", \"price\":\"0.001\", \"size\":\"24858.24\", \"side\":\"SELL\", \"hash\":\"ab686939bf315d7f60d1d87e952363482e148d7c\", \"best_bid\":\"0\", \"best_ask\":\"0.001\"}, {\"asset_id\":\"17984242239730438865135655538589475203118151844342180615256685234465965850727\", \"price\":\"0.999\", \"size\":\"24858.24\", \"side\":\"BUY\", \"hash\":\"914dc6f55f697ff0596e2add3b5006c14d5861b8\", \"best_bid\":\"0.999\", \"best_ask\":\"1\"}], \"timestamp\":\"1785036174371\", \"event_type\":\"price_change\"}","received_at":"2026-07-26T03:22:54.431769Z","schema_version":"clob-market-ws.price_change.v1","sequence":null,"server_hash":null,"server_timestamp":"1785036174371","session_id":"c31a343fa9584b66bec39f9faee0e3a0","source":"clob_market_ws"},"received_at":"2026-07-26T03:22:54.431769Z","record_id":"149767fad09719a4e1c8b8a6d401243bb29d9274e2a5112d49da3a4482f0e993","schema_fingerprint":"4aa3821a28b0b7c2400bc59aba4bcc0a76e971dadd19610d3ad38c768e124dc7","schema_version":"edge-lab-recorder.raw.v1","sequence":null,"source":"clob_market_ws"}
{"event_at":null,"event_fingerprint":"1cc6e25e55280a0812e9cab2e4d7be19ecbcdb54f021433bb6f7e591ad038865","payload":{"connection_id":"f3be8c5f87ba4c71b8e5c26aee143178","detail":{"interval_seconds":10.0,"message":"PING"},"event_type":"heartbeat","kind":"lifecycle","monotonic_ns":138158156019125,"received_at":"2026-07-26T03:22:54.605926Z","schema_version":"edge-lab-recorder.lifecycle.v1","session_id":"c31a343fa9584b66bec39f9faee0e3a0","source":"clob_market_ws"},"received_at":"2026-07-26T03:22:54.605926Z","record_id":"fe8879a5c55219016302bcb5410cf8e3bd770bfee41ac0a8bcef2dea11d6390a","schema_fingerprint":"cb8aa3aa4cb168a4b724fd9077bee6ecfb9bc586c57cfdf0ab89f00d82045e3c","schema_version":"edge-lab-recorder.raw.v1","sequence":null,"source":"clob_market_ws"}
{"event_at":null,"event_fingerprint":"e4c2078d327ba3fb15e7a52bb2a5b9a7ceb9ce98623f61741e1a1bcc26b2081d","payload":{"connection_id":"f3be8c5f87ba4c71b8e5c26aee143178","event_type":"heartbeat_ack","frame_hash":"95784973cc639977bff93619700168505cb8f7855e44fa643d34622a43706c87","kind":"lifecycle","monotonic_ns":138158363791875,"raw_frame":"PONG","received_at":"2026-07-26T03:22:54.813704Z","schema_version":"edge-lab-recorder.heartbeat-ack.v1","session_id":"c31a343fa9584b66bec39f9faee0e3a0","source":"clob_market_ws"},"received_at":"2026-07-26T03:22:54.813704Z","record_id":"4f7c1cf9c2622ee6c0ad492c245c3aae7f5ac219190466caa485571d863af504","schema_fingerprint":"c14ee1aab3ca674ee738e5268877b544d74c41ad3c427cedc09236467dc68ba1","schema_version":"edge-lab-recorder.raw.v1","sequence":null,"source":"clob_market_ws"}
{"event_at":"2026-07-26T03:22:59.630000Z","event_fingerprint":"a124cac75e02f4177dc0922e2f3f79ae6b2f7fb51e700f6cd7d0a859457b72bd","payload":{"connection_id":"f3be8c5f87ba4c71b8e5c26aee143178","event_at":"2026-07-26T03:22:59.630000Z","event_type":"price_change","frame_hash":"cb3cfc03eaa4611bfe4094e5587baada4be5bb79324cb466d526c09a17bbb1e0","frame_index":0,"kind":"data","monotonic_ns":138163237066166,"payload":{"event_type":"price_change","market":"0x37b4e66ed76a1ae459bf10d847a67f8b177df9e948837bb216db7f0ddeeb0a8f","price_changes":[{"asset_id":"108872501708701256232360833975340759490903762166970350300622728710669503400981","best_ask":"1","best_bid":"0.999","hash":"d5225fd7cb02a25a93c08eda9570ce03cac605f3","price":"0.03","side":"BUY","size":"169.59"},{"asset_id":"9589024508471284927421067800380793227060508852978748836190721804896525288035","best_ask":"0.001","best_bid":"0","hash":"08108f312428f42a6d0e2970a7256be80687de97","price":"0.97","side":"SELL","size":"169.59"}],"timestamp":"1785036179630"},"payload_hash":"04b4dfecf2a5137351c442f55c1c35f6ebb2ce8d08066343b9143c62446af22c","raw_frame":"{\"market\":\"0x37b4e66ed76a1ae459bf10d847a67f8b177df9e948837bb216db7f0ddeeb0a8f\", \"price_changes\":[{\"asset_id\":\"108872501708701256232360833975340759490903762166970350300622728710669503400981\", \"price\":\"0.03\", \"size\":\"169.59\", \"side\":\"BUY\", \"hash\":\"d5225fd7cb02a25a93c08eda9570ce03cac605f3\", \"best_bid\":\"0.999\", \"best_ask\":\"1\"}, {\"asset_id\":\"9589024508471284927421067800380793227060508852978748836190721804896525288035\", \"price\":\"0.97\", \"size\":\"169.59\", \"side\":\"SELL\", \"hash\":\"08108f312428f42a6d0e2970a7256be80687de97\", \"best_bid\":\"0\", \"best_ask\":\"0.001\"}], \"timestamp\":\"1785036179630\", \"event_type\":\"price_change\"}","received_at":"2026-07-26T03:22:59.687033Z","schema_version":"clob-market-ws.price_change.v1","sequence":null,"server_hash":null,"server_timestamp":"1785036179630","session_id":"c31a343fa9584b66bec39f9faee0e3a0","source":"clob_market_ws"},"received_at":"2026-07-26T03:22:59.687033Z","record_id":"15fb3d858a549a866b605ddf0ca4045560509f305d63b4ef7b9c238e4a98a777","schema_fingerprint":"4aa3821a28b0b7c2400bc59aba4bcc0a76e971dadd19610d3ad38c768e124dc7","schema_version":"edge-lab-recorder.raw.v1","sequence":null,"source":"clob_market_ws"}
{"event_at":"2026-07-26T03:23:01.598000Z","event_fingerprint":"c2c2295b33ab55fab597b806d4fd6657e6cee15c5dbc143479bbb7acf91a2665","payload":{"connection_id":"f3be8c5f87ba4c71b8e5c26aee143178","event_at":"2026-07-26T03:23:01.598000Z","event_type":"price_change","frame_hash":"3bcd122e046fc6efeef229cfc89aec01fb082069e172f150a1bea97556030037","frame_index":0,"kind":"data","monotonic_ns":138165206201250,"payload":{"event_type":"price_change","market":"0x9c381c628d4d7f50c84fe33ed2e6034c9e95a38fe2bbaf0839e0045ed6ebb00a","price_changes":[{"asset_id":"65498980163493839080617380002950766616985632732897237936946030803559673024127","best_ask":"0.001","best_bid":"0","hash":"531843845bbf753430bb24689730fa4506fc34ce","price":"0.001","side":"SELL","size":"2624.01"},{"asset_id":"54242839679678573772031723750101159478558866523031929268633860829634800562410","best_ask":"1","best_bid":"0.999","hash":"08c5c8dedc8b053edf93c46bf1162373edede19a","price":"0.999","side":"BUY","size":"2624.01"}],"timestamp":"1785036181598"},"payload_hash":"ac1638505afbfc61dcd82489a608a35acd649e681da459d8a16b1e2e2b390c97","raw_frame":"{\"market\":\"0x9c381c628d4d7f50c84fe33ed2e6034c9e95a38fe2bbaf0839e0045ed6ebb00a\", \"price_changes\":[{\"asset_id\":\"65498980163493839080617380002950766616985632732897237936946030803559673024127\", \"price\":\"0.001\", \"size\":\"2624.01\", \"side\":\"SELL\", \"hash\":\"531843845bbf753430bb24689730fa4506fc34ce\", \"best_bid\":\"0\", \"best_ask\":\"0.001\"}, {\"asset_id\":\"54242839679678573772031723750101159478558866523031929268633860829634800562410\", \"price\":\"0.999\", \"size\":\"2624.01\", \"side\":\"BUY\", \"hash\":\"08c5c8dedc8b053edf93c46bf1162373edede19a\", \"best_bid\":\"0.999\", \"best_ask\":\"1\"}], \"timestamp\":\"1785036181598\", \"event_type\":\"price_change\"}","received_at":"2026-07-26T03:23:01.656208Z","schema_version":"clob-market-ws.price_change.v1","sequence":null,"server_hash":null,"server_timestamp":"1785036181598","session_id":"c31a343fa9584b66bec39f9faee0e3a0","source":"clob_market_ws"},"received_at":"2026-07-26T03:23:01.656208Z","record_id":"addde212e17161e8e3887095ac552b42983d7524c5459c798a797e13d5aed7b2","schema_fingerprint":"4aa3821a28b0b7c2400bc59aba4bcc0a76e971dadd19610d3ad38c768e124dc7","schema_version":"edge-lab-recorder.raw.v1","sequence":null,"source":"clob_market_ws"}
{"event_at":"2026-07-26T03:23:01.598000Z","event_fingerprint":"e83deb72b44026ad47084b0460f5a60813fe4402265d262cab549a237c9e65b5","payload":{"connection_id":"f3be8c5f87ba4c71b8e5c26aee143178","event_at":"2026-07-26T03:23:01.598000Z","event_type":"price_change","frame_hash":"f424090a5caa73496b30b798891b5b9b121df794b263a726bb51275829d27fc9","frame_index":0,"kind":"data","monotonic_ns":138165207272625,"payload":{"event_type":"price_change","market":"0xd34d11638850161b49d343af579b355a91a40625a1cb324b89da0ec34316ce0d","price_changes":[{"asset_id":"72412292208263882620567760335223208281592684887840447866591915373071557986157","best_ask":"0.001","best_bid":"0","hash":"3c5e623131440f4ac3b084aae0a712eb723cb79c","price":"0.001","side":"SELL","size":"2654.01"},{"asset_id":"23304427590407806052073703058430344447294483314513948492296568658168726366081","best_ask":"1","best_bid":"0.999","hash":"0c8cb35302154ca31dc9051c19d0426b8d547ffd","price":"0.999","side":"BUY","size":"2654.01"}],"timestamp":"1785036181598"},"payload_hash":"d39d961cca9855073a78ece1c5466daad2947fa6b2df84a92a7190dbe224d867","raw_frame":"{\"market\":\"0xd34d11638850161b49d343af579b355a91a40625a1cb324b89da0ec34316ce0d\", \"price_changes\":[{\"asset_id\":\"72412292208263882620567760335223208281592684887840447866591915373071557986157\", \"price\":\"0.001\", \"size\":\"2654.01\", \"side\":\"SELL\", \"hash\":\"3c5e623131440f4ac3b084aae0a712eb723cb79c\", \"best_bid\":\"0\", \"best_ask\":\"0.001\"}, {\"asset_id\":\"23304427590407806052073703058430344447294483314513948492296568658168726366081\", \"price\":\"0.999\", \"size\":\"2654.01\", \"side\":\"BUY\", \"hash\":\"0c8cb35302154ca31dc9051c19d0426b8d547ffd\", \"best_bid\":\"0.999\", \"best_ask\":\"1\"}], \"timestamp\":\"1785036181598\", \"event_type\":\"price_change\"}","received_at":"2026-07-26T03:23:01.657298Z","schema_version":"clob-market-ws.price_change.v1","sequence":null,"server_hash":null,"server_timestamp":"1785036181598","session_id":"c31a343fa9584b66bec39f9faee0e3a0","source":"clob_market_ws"},"received_at":"2026-07-26T03:23:01.657298Z","record_id":"b88be1e3b39213124733246da554f3a707f0aae21e165576d0356668bd222262","schema_fingerprint":"4aa3821a28b0b7c2400bc59aba4bcc0a76e971dadd19610d3ad38c768e124dc7","schema_version":"edge-lab-recorder.raw.v1","sequence":null,"source":"clob_market_ws"}
{"event_at":"2026-07-26T03:23:01.598000Z","event_fingerprint":"286c14692c9572e7c378bc0af25eb48faae8900b26c088fdad28a7b7892faa19","payload":{"connection_id":"f3be8c5f87ba4c71b8e5c26aee143178","event_at":"2026-07-26T03:23:01.598000Z","event_type":"price_change","frame_hash":"2f580513800898835c1a2da526ca7a196212acc938aacbe37818d31b9d0ab8a6","frame_index":0,"kind":"data","monotonic_ns":138165207985583,"payload":{"event_type":"price_change","market":"0x4f38d51fa4a5a6ee7bef3839663f1ba6781f805620a00656a1ac78971ff65f94","price_changes":[{"asset_id":"60846176734025071834155023520866063850736009438184221594765130197435585627848","best_ask":"0.001","best_bid":"0","hash":"62cdeec93a63af8ab7ea0c564f496070e49bbd54","price":"0.001","side":"SELL","size":"2823.92"},{"asset_id":"44664371028109261969095768944878691828121031685263777021740408906309606948679","best_ask":"1","best_bid":"0.999","hash":"30a4b2466b308501381a5cc4061ffda2d15ba8b1","price":"0.999","side":"BUY","size":"2823.92"}],"timestamp":"1785036181598"},"payload_hash":"cb045b9c4aede0eb80658bf2e40737c453da13072ecabc3a0c8f82726c1c19b0","raw_frame":"{\"market\":\"0x4f38d51fa4a5a6ee7bef3839663f1ba6781f805620a00656a1ac78971ff65f94\", \"price_changes\":[{\"asset_id\":\"60846176734025071834155023520866063850736009438184221594765130197435585627848\", \"price\":\"0.001\", \"size\":\"2823.92\", \"side\":\"SELL\", \"hash\":\"62cdeec93a63af8ab7ea0c564f496070e49bbd54\", \"best_bid\":\"0\", \"best_ask\":\"0.001\"}, {\"asset_id\":\"44664371028109261969095768944878691828121031685263777021740408906309606948679\", \"price\":\"0.999\", \"size\":\"2823.92\", \"side\":\"BUY\", \"hash\":\"30a4b2466b308501381a5cc4061ffda2d15ba8b1\", \"best_bid\":\"0.999\", \"best_ask\":\"1\"}], \"timestamp\":\"1785036181598\", \"event_type\":\"price_change\"}","received_at":"2026-07-26T03:23:01.658011Z","schema_version":"clob-market-ws.price_change.v1","sequence":null,"server_hash":null,"server_timestamp":"1785036181598","session_id":"c31a343fa9584b66bec39f9faee0e3a0","source":"clob_market_ws"},"received_at":"2026-07-26T03:23:01.658011Z","record_id":"e0a645639d74441cf57a4d1c6b50ce34d32316a76f154fb5ef867bc9d4d74f90","schema_fingerprint":"4aa3821a28b0b7c2400bc59aba4bcc0a76e971dadd19610d3ad38c768e124dc7","schema_version":"edge-lab-recorder.raw.v1","sequence":null,"source":"clob_market_ws"}
{"event_at":"2026-07-26T03:23:01.600000Z","event_fingerprint":"5107efbb366df0d327e02161895e33301dc11fe821cc9fd17838dafd7413c4af","payload":{"connection_id":"f3be8c5f87ba4c71b8e5c26aee143178","event_at":"2026-07-26T03:23:01.600000Z","event_type":"price_change","frame_hash":"407a0bd0f48d5d4c434d1562eef3ec145a83ee0fdd6715219b71251f6d2252fd","frame_index":0,"kind":"data","monotonic_ns":138165215687875,"payload":{"event_type":"price_change","market":"0x8c323abb1ede2f2619000d6a23ac35b5168d91d791d7f66b1ca85c76e0067cb2","price_changes":[{"asset_id":"99984412512137939403884906462112387899264398613764835397028075776778837165349","best_ask":"0.001","best_bid":"0","hash":"aaa0bc69c39fe987c78fb39ef01cc191d5cdfacd","price":"0.001","side":"SELL","size":"2624.01"},{"asset_id":"21528271602641370669107334886285049226470476823971040418410401833791672433390","best_ask":"1","best_bid":"0.999","hash":"4d14077a3474deefb536d911adf2380acb5e8367","price":"0.999","side":"BUY","size":"2624.01"}],"timestamp":"1785036181600"},"payload_hash":"304f5aa3497d0e8666776dbc0aa6d5c712a3932d47f6267c549db828a6975435","raw_frame":"{\"market\":\"0x8c323abb1ede2f2619000d6a23ac35b5168d91d791d7f66b1ca85c76e0067cb2\", \"price_changes\":[{\"asset_id\":\"99984412512137939403884906462112387899264398613764835397028075776778837165349\", \"price\":\"0.001\", \"size\":\"2624.01\", \"side\":\"SELL\", \"hash\":\"aaa0bc69c39fe987c78fb39ef01cc191d5cdfacd\", \"best_bid\":\"0\", \"best_ask\":\"0.001\"}, {\"asset_id\":\"21528271602641370669107334886285049226470476823971040418410401833791672433390\", \"price\":\"0.999\", \"size\":\"2624.01\", \"side\":\"BUY\", \"hash\":\"4d14077a3474deefb536d911adf2380acb5e8367\", \"best_bid\":\"0.999\", \"best_ask\":\"1\"}], \"timestamp\":\"1785036181600\", \"event_type\":\"price_change\"}","received_at":"2026-07-26T03:23:01.665708Z","schema_version":"clob-market-ws.price_change.v1","sequence":null,"server_hash":null,"server_timestamp":"1785036181600","session_id":"c31a343fa9584b66bec39f9faee0e3a0","source":"clob_market_ws"},"received_at":"2026-07-26T03:23:01.665708Z","record_id":"499228f6a54d4c547deeeaa75f541290f2226cc83645152ddad1e0b481b4fd60","schema_fingerprint":"4aa3821a28b0b7c2400bc59aba4bcc0a76e971dadd19610d3ad38c768e124dc7","schema_version":"edge-lab-recorder.raw.v1","sequence":null,"source":"clob_market_ws"}
{"event_at":"2026-07-26T03:23:01.600000Z","event_fingerprint":"439a4e9341ab6ebd03a47dd40de4c0d148f9c0a4d13ef6a697b744486f882b0a","payload":{"connection_id":"f3be8c5f87ba4c71b8e5c26aee143178","event_at":"2026-07-26T03:23:01.600000Z","event_type":"price_change","frame_hash":"5a4cbe66c4366222331aae26093f700dedd47e1b08c374ec7b217596e245d8f7","frame_index":0,"kind":"data","monotonic_ns":138165217362416,"payload":{"event_type":"price_change","market":"0x529e20dbcafea98019b83fb73d95438060842c1755b5da85f84dd470bcf4b6e7","price_changes":[{"asset_id":"8751464955595067927363468221457794220960058706401173909132456942616242167659","best_ask":"0.001","best_bid":"0","hash":"21250203842e99903d54857e946375eca20fbf81","price":"0.001","side":"SELL","size":"2774.31"},{"asset_id":"59690684605978199241259738837409754535439173706362879570036366520913988351920","best_ask":"1","best_bid":"0.999","hash":"56e58fb7d1b904038b179baeb29a236774dbe5c3","price":"0.999","side":"BUY","size":"2774.31"}],"timestamp":"1785036181600"},"payload_hash":"257af07bf1daf429d9d2562ab8d6d27d412c53ed1816f57fbbfea61ec1aefe94","raw_frame":"{\"market\":\"0x529e20dbcafea98019b83fb73d95438060842c1755b5da85f84dd470bcf4b6e7\", \"price_changes\":[{\"asset_id\":\"8751464955595067927363468221457794220960058706401173909132456942616242167659\", \"price\":\"0.001\", \"size\":\"2774.31\", \"side\":\"SELL\", \"hash\":\"21250203842e99903d54857e946375eca20fbf81\", \"best_bid\":\"0\", \"best_ask\":\"0.001\"}, {\"asset_id\":\"59690684605978199241259738837409754535439173706362879570036366520913988351920\", \"price\":\"0.999\", \"size\":\"2774.31\", \"side\":\"BUY\", \"hash\":\"56e58fb7d1b904038b179baeb29a236774dbe5c3\", \"best_bid\":\"0.999\", \"best_ask\":\"1\"}], \"timestamp\":\"1785036181600\", \"event_type\":\"price_change\"}","received_at":"2026-07-26T03:23:01.667383Z","schema_version":"clob-market-ws.price_change.v1","sequence":null,"server_hash":null,"server_timestamp":"1785036181600","session_id":"c31a343fa9584b66bec39f9faee0e3a0","source":"clob_market_ws"},"received_at":"2026-07-26T03:23:01.667383Z","record_id":"a6c28506d4d67d91387a4907edc590be37dbe445e16d26e4b3aa5041a72d40b6","schema_fingerprint":"4aa3821a28b0b7c2400bc59aba4bcc0a76e971dadd19610d3ad38c768e124dc7","schema_version":"edge-lab-recorder.raw.v1","sequence":null,"source":"clob_market_ws"}
{"event_at":"2026-07-26T03:23:01.600000Z","event_fingerprint":"c5614470809a661b7853d34d8d4c8f9983be6dddbb6b7e131d93eaac4a352d77","payload":{"connection_id":"f3be8c5f87ba4c71b8e5c26aee143178","event_at":"2026-07-26T03:23:01.600000Z","event_type":"price_change","frame_hash":"479be540575de461fac8bdcb82c2af655fd55b87d978a94edbb4a8672f72dd67","frame_index":0,"kind":"data","monotonic_ns":138165398605500,"payload":{"event_type":"price_change","market":"0xf5c1ad6b533e31b7156c48d12276744433a7dd1829938850a73717cea9d53821","price_changes":[{"asset_id":"34600602296599885071917717676988207363957952958012665255891266571657806817559","best_ask":"0.001","best_bid":"0","hash":"c94944e9534d4280014bdf966ac895aa30683206","price":"0.001","side":"SELL","size":"24767.16"},{"asset_id":"17984242239730438865135655538589475203118151844342180615256685234465965850727","best_ask":"1","best_bid":"0.999","hash":"3ef17de5fb0d20695854f685a381bb732f844a93","price":"0.999","side":"BUY","size":"24767.16"}],"timestamp":"1785036181600"},"payload_hash":"a0b714e50103662123aebf23262b0b6a6b2b8ad27bfb93287033c3ebbbcc6cff","raw_frame":"{\"market\":\"0xf5c1ad6b533e31b7156c48d12276744433a7dd1829938850a73717cea9d53821\", \"price_changes\":[{\"asset_id\":\"34600602296599885071917717676988207363957952958012665255891266571657806817559\", \"price\":\"0.001\", \"size\":\"24767.16\", \"side\":\"SELL\", \"hash\":\"c94944e9534d4280014bdf966ac895aa30683206\", \"best_bid\":\"0\", \"best_ask\":\"0.001\"}, {\"asset_id\":\"17984242239730438865135655538589475203118151844342180615256685234465965850727\", \"price\":\"0.999\", \"size\":\"24767.16\", \"side\":\"BUY\", \"hash\":\"3ef17de5fb0d20695854f685a381bb732f844a93\", \"best_bid\":\"0.999\", \"best_ask\":\"1\"}], \"timestamp\":\"1785036181600\", \"event_type\":\"price_change\"}","received_at":"2026-07-26T03:23:01.848612Z","schema_version":"clob-market-ws.price_change.v1","sequence":null,"server_hash":null,"server_timestamp":"1785036181600","session_id":"c31a343fa9584b66bec39f9faee0e3a0","source":"clob_market_ws"},"received_at":"2026-07-26T03:23:01.848612Z","record_id":"15b2ab239501735723e4ebe303a09ef3dca36048953364c26c2b8da2aa855992","schema_fingerprint":"4aa3821a28b0b7c2400bc59aba4bcc0a76e971dadd19610d3ad38c768e124dc7","schema_version":"edge-lab-recorder.raw.v1","sequence":null,"source":"clob_market_ws"}
{"event_at":"2026-07-26T03:23:01.613000Z","event_fingerprint":"ce3a2a3afe5bf47800cb69bcf2dfef089046fb50ceb2ffb08a84fd083a492967","payload":{"connection_id":"f3be8c5f87ba4c71b8e5c26aee143178","event_at":"2026-07-26T03:23:01.613000Z","event_type":"price_change","frame_hash":"ab28e781b17b5d25cf3e6481f432089bcd0b5f8b0074ac388d3919061f6b135e","frame_index":0,"kind":"data","monotonic_ns":138165400764708,"payload":{"event_type":"price_change","market":"0x37b4e66ed76a1ae459bf10d847a67f8b177df9e948837bb216db7f0ddeeb0a8f","price_changes":[{"asset_id":"108872501708701256232360833975340759490903762166970350300622728710669503400981","best_ask":"1","best_bid":"0.999","hash":"f9d7ed63c651430b94838bd3d36a5d113bc01f5b","price":"0.03","side":"BUY","size":"69.59"},{"asset_id":"9589024508471284927421067800380793227060508852978748836190721804896525288035","best_ask":"0.001","best_bid":"0","hash":"f49b4086f5fc0fc27ff65b4f841fa3266e33941b","price":"0.97","side":"SELL","size":"69.59"}],"timestamp":"1785036181613"},"payload_hash":"39cc177eeb0502071dd1eec76fe6c914f28d5dbc0768fb834b23775415b40644","raw_frame":"{\"market\":\"0x37b4e66ed76a1ae459bf10d847a67f8b177df9e948837bb216db7f0ddeeb0a8f\", \"price_changes\":[{\"asset_id\":\"108872501708701256232360833975340759490903762166970350300622728710669503400981\", \"price\":\"0.03\", \"size\":\"69.59\", \"side\":\"BUY\", \"hash\":\"f9d7ed63c651430b94838bd3d36a5d113bc01f5b\", \"best_bid\":\"0.999\", \"best_ask\":\"1\"}, {\"asset_id\":\"9589024508471284927421067800380793227060508852978748836190721804896525288035\", \"price\":\"0.97\", \"size\":\"69.59\", \"side\":\"SELL\", \"hash\":\"f49b4086f5fc0fc27ff65b4f841fa3266e33941b\", \"best_bid\":\"0\", \"best_ask\":\"0.001\"}], \"timestamp\":\"1785036181613\", \"event_type\":\"price_change\"}","received_at":"2026-07-26T03:23:01.850790Z","schema_version":"clob-market-ws.price_change.v1","sequence":null,"server_hash":null,"server_timestamp":"1785036181613","session_id":"c31a343fa9584b66bec39f9faee0e3a0","source":"clob_market_ws"},"received_at":"2026-07-26T03:23:01.850790Z","record_id":"de4eb17127bd3398d196368a7326a57c3cf8f25f4a00c0cc21e838e0a34aecd9","schema_fingerprint":"4aa3821a28b0b7c2400bc59aba4bcc0a76e971dadd19610d3ad38c768e124dc7","schema_version":"edge-lab-recorder.raw.v1","sequence":null,"source":"clob_market_ws"}
{"event_at":null,"event_fingerprint":"f2d8afb0659196e39239052d51509dd7ca9dfc4d70da93c12e77eeda24b3f0cc","payload":{"connection_id":"f3be8c5f87ba4c71b8e5c26aee143178","detail":{"interval_seconds":10.0,"message":"PING"},"event_type":"heartbeat","kind":"lifecycle","monotonic_ns":138168158746416,"received_at":"2026-07-26T03:23:04.608799Z","schema_version":"edge-lab-recorder.lifecycle.v1","session_id":"c31a343fa9584b66bec39f9faee0e3a0","source":"clob_market_ws"},"received_at":"2026-07-26T03:23:04.608799Z","record_id":"bf01aaf889e03208a1d022c1bd4f07e91a17f218045d3066b17426f1934197b8","schema_fingerprint":"cb8aa3aa4cb168a4b724fd9077bee6ecfb9bc586c57cfdf0ab89f00d82045e3c","schema_version":"edge-lab-recorder.raw.v1","sequence":null,"source":"clob_market_ws"}
{"event_at":null,"event_fingerprint":"3b286129d092a6a37ef036eab716b6d92f29958a452a799f2411e0ab83e78c49","payload":{"connection_id":"f3be8c5f87ba4c71b8e5c26aee143178","event_type":"heartbeat_ack","frame_hash":"95784973cc639977bff93619700168505cb8f7855e44fa643d34622a43706c87","kind":"lifecycle","monotonic_ns":138168363884041,"raw_frame":"PONG","received_at":"2026-07-26T03:23:04.813943Z","schema_version":"edge-lab-recorder.heartbeat-ack.v1","session_id":"c31a343fa9584b66bec39f9faee0e3a0","source":"clob_market_ws"},"received_at":"2026-07-26T03:23:04.813943Z","record_id":"85ac7536223b21107b2e1171f7dbe9bffd32a8bdc5468dbdd4378486fdeb72d2","schema_fingerprint":"c14ee1aab3ca674ee738e5268877b544d74c41ad3c427cedc09236467dc68ba1","schema_version":"edge-lab-recorder.raw.v1","sequence":null,"source":"clob_market_ws"}
{"event_at":"2026-07-26T03:23:05.942000Z","event_fingerprint":"e69d536834a7d181b22ea2cdd844330bb4d2be2be65bebb02824119119669cef","payload":{"connection_id":"f3be8c5f87ba4c71b8e5c26aee143178","event_at":"2026-07-26T03:23:05.942000Z","event_type":"price_change","frame_hash":"b7c6dcc2141a05d53ccbd4f3789ebb993d0aa4fb05caf07dd2e8266272dc4817","frame_index":0,"kind":"data","monotonic_ns":138169548257916,"payload":{"event_type":"price_change","market":"0x4ece6ea8e71e48e1a06bc1f3afae28b8cf1f4c02da84e063e897ee2934579fb7","price_changes":[{"asset_id":"42849131213114758080260198350962549519803211945339841540212854265574993410571","best_ask":"1","best_bid":"0.999","hash":"1aa9518bc13ed45053986e6dd14289f454471f87","price":"0.001","side":"BUY","size":"132.63"},{"asset_id":"54181442874099068684888188755958127023688250733698219741890813802447465352698","best_ask":"0.001","best_bid":"0","hash":"e1dc5a972d8260c7db6cb7b6ce949c79bd548276","price":"0.999","side":"SELL","size":"132.63"}],"timestamp":"1785036185942"},"payload_hash":"f1e11d76d7e674cc0b35b9b9ee0164e37f18ab2a24e3857a0792c8d9b83246c8","raw_frame":"{\"market\":\"0x4ece6ea8e71e48e1a06bc1f3afae28b8cf1f4c02da84e063e897ee2934579fb7\", \"price_changes\":[{\"asset_id\":\"42849131213114758080260198350962549519803211945339841540212854265574993410571\", \"price\":\"0.001\", \"size\":\"132.63\", \"side\":\"BUY\", \"hash\":\"1aa9518bc13ed45053986e6dd14289f454471f87\", \"best_bid\":\"0.999\", \"best_ask\":\"1\"}, {\"asset_id\":\"54181442874099068684888188755958127023688250733698219741890813802447465352698\", \"price\":\"0.999\", \"size\":\"132.63\", \"side\":\"SELL\", \"hash\":\"e1dc5a972d8260c7db6cb7b6ce949c79bd548276\", \"best_bid\":\"0\", \"best_ask\":\"0.001\"}], \"timestamp\":\"1785036185942\", \"event_type\":\"price_change\"}","received_at":"2026-07-26T03:23:05.998330Z","schema_version":"clob-market-ws.price_change.v1","sequence":null,"server_hash":null,"server_timestamp":"1785036185942","session_id":"c31a343fa9584b66bec39f9faee0e3a0","source":"clob_market_ws"},"received_at":"2026-07-26T03:23:05.998330Z","record_id":"7cf13b3978b21e601479b7930965e511a0442dfd62a2e797908694f7d0e1b005","schema_fingerprint":"4aa3821a28b0b7c2400bc59aba4bcc0a76e971dadd19610d3ad38c768e124dc7","schema_version":"edge-lab-recorder.raw.v1","sequence":null,"source":"clob_market_ws"}
{"event_at":"2026-07-26T03:23:05.943000Z","event_fingerprint":"ee3349381fc55b491f4304da620184f81868aa4f70ace3bceb7bea500a141cf3","payload":{"connection_id":"f3be8c5f87ba4c71b8e5c26aee143178","event_at":"2026-07-26T03:23:05.943000Z","event_type":"price_change","frame_hash":"95a3ebee57db648fca553f87bce861d8340db5a0e48d406426461fc3266d9820","frame_index":0,"kind":"data","monotonic_ns":138169550483875,"payload":{"event_type":"price_change","market":"0x4ece6ea8e71e48e1a06bc1f3afae28b8cf1f4c02da84e063e897ee2934579fb7","price_changes":[{"asset_id":"42849131213114758080260198350962549519803211945339841540212854265574993410571","best_ask":"1","best_bid":"0.999","hash":"fe4635d5ea43cb7fb055e7541b0aa10cc52d3697","price":"0.003","side":"BUY","size":"17.47"},{"asset_id":"54181442874099068684888188755958127023688250733698219741890813802447465352698","best_ask":"0.001","best_bid":"0","hash":"ccd7984cd13f38c9ea90f4ba17d87e2ff07e5d5e","price":"0.997","side":"SELL","size":"17.47"}],"timestamp":"1785036185943"},"payload_hash":"d2a983f568dcec3ac95f6367f23eb81ca11f90c704ea9285495e6d2852e9860d","raw_frame":"{\"market\":\"0x4ece6ea8e71e48e1a06bc1f3afae28b8cf1f4c02da84e063e897ee2934579fb7\", \"price_changes\":[{\"asset_id\":\"42849131213114758080260198350962549519803211945339841540212854265574993410571\", \"price\":\"0.003\", \"size\":\"17.47\", \"side\":\"BUY\", \"hash\":\"fe4635d5ea43cb7fb055e7541b0aa10cc52d3697\", \"best_bid\":\"0.999\", \"best_ask\":\"1\"}, {\"asset_id\":\"54181442874099068684888188755958127023688250733698219741890813802447465352698\", \"price\":\"0.997\", \"size\":\"17.47\", \"side\":\"SELL\", \"hash\":\"ccd7984cd13f38c9ea90f4ba17d87e2ff07e5d5e\", \"best_bid\":\"0\", \"best_ask\":\"0.001\"}], \"timestamp\":\"1785036185943\", \"event_type\":\"price_change\"}","received_at":"2026-07-26T03:23:06.000566Z","schema_version":"clob-market-ws.price_change.v1","sequence":null,"server_hash":null,"server_timestamp":"1785036185943","session_id":"c31a343fa9584b66bec39f9faee0e3a0","source":"clob_market_ws"},"received_at":"2026-07-26T03:23:06.000566Z","record_id":"ef383d1cd97137cc203034821b29c91bc2b56f9ba4aef5dfd32b8fbeddb3fe06","schema_fingerprint":"4aa3821a28b0b7c2400bc59aba4bcc0a76e971dadd19610d3ad38c768e124dc7","schema_version":"edge-lab-recorder.raw.v1","sequence":null,"source":"clob_market_ws"}
{"event_at":"2026-07-26T03:23:05.944000Z","event_fingerprint":"39db8e58bb811217621bc053c28c24e8f265795281762f689d2a6a27266a0487","payload":{"connection_id":"f3be8c5f87ba4c71b8e5c26aee143178","event_at":"2026-07-26T03:23:05.944000Z","event_type":"price_change","frame_hash":"8905756ed5d7a766aa929f9e674d11b69b57dc3b502974594cbd5302bb07b599","frame_index":0,"kind":"data","monotonic_ns":138169552228833,"payload":{"event_type":"price_change","market":"0x4ece6ea8e71e48e1a06bc1f3afae28b8cf1f4c02da84e063e897ee2934579fb7","price_changes":[{"asset_id":"42849131213114758080260198350962549519803211945339841540212854265574993410571","best_ask":"1","best_bid":"0.999","hash":"e1f4a9db62a9c55c4f4bbead666eec9ae965d879","price":"0.061","side":"BUY","size":"5.42"},{"asset_id":"54181442874099068684888188755958127023688250733698219741890813802447465352698","best_ask":"0.001","best_bid":"0","hash":"aab1ed897ae43595c78d64393c2e368159477701","price":"0.939","side":"SELL","size":"5.42"}],"timestamp":"1785036185944"},"payload_hash":"2810c68d07690ddb466b3f28a2eabb41bda2c29337a888f757e802008af3f8b1","raw_frame":"{\"market\":\"0x4ece6ea8e71e48e1a06bc1f3afae28b8cf1f4c02da84e063e897ee2934579fb7\", \"price_changes\":[{\"asset_id\":\"42849131213114758080260198350962549519803211945339841540212854265574993410571\", \"price\":\"0.061\", \"size\":\"5.42\", \"side\":\"BUY\", \"hash\":\"e1f4a9db62a9c55c4f4bbead666eec9ae965d879\", \"best_bid\":\"0.999\", \"best_ask\":\"1\"}, {\"asset_id\":\"54181442874099068684888188755958127023688250733698219741890813802447465352698\", \"price\":\"0.939\", \"size\":\"5.42\", \"side\":\"SELL\", \"hash\":\"aab1ed897ae43595c78d64393c2e368159477701\", \"best_bid\":\"0\", \"best_ask\":\"0.001\"}], \"timestamp\":\"1785036185944\", \"event_type\":\"price_change\"}","received_at":"2026-07-26T03:23:06.002312Z","schema_version":"clob-market-ws.price_change.v1","sequence":null,"server_hash":null,"server_timestamp":"1785036185944","session_id":"c31a343fa9584b66bec39f9faee0e3a0","source":"clob_market_ws"},"received_at":"2026-07-26T03:23:06.002312Z","record_id":"a2394de95a47971eaa1e4ec4ce9aa483360719e5a5d4d6ba2ae40fc07a0c5d94","schema_fingerprint":"4aa3821a28b0b7c2400bc59aba4bcc0a76e971dadd19610d3ad38c768e124dc7","schema_version":"edge-lab-recorder.raw.v1","sequence":null,"source":"clob_market_ws"}
{"event_at":"2026-07-26T03:23:05.945000Z","event_fingerprint":"8e5d1922659dc77a818eb31f99676081cc0e9953834429629826ba845ec7259d","payload":{"connection_id":"f3be8c5f87ba4c71b8e5c26aee143178","event_at":"2026-07-26T03:23:05.945000Z","event_type":"price_change","frame_hash":"86bac97159f3f75fb9dac21edbba1fa2061e47e624ac54c1264ef2bc4152aa40","frame_index":0,"kind":"data","monotonic_ns":138169553758291,"payload":{"event_type":"price_change","market":"0x4ece6ea8e71e48e1a06bc1f3afae28b8cf1f4c02da84e063e897ee2934579fb7","price_changes":[{"asset_id":"42849131213114758080260198350962549519803211945339841540212854265574993410571","best_ask":"1","best_bid":"0.999","hash":"f601bba346823022fe71ab937cf03a0afd8bc8da","price":"0.181","side":"BUY","size":"5.53"},{"asset_id":"54181442874099068684888188755958127023688250733698219741890813802447465352698","best_ask":"0.001","best_bid":"0","hash":"aeccf512c4cf814a7757947a696344f7bbfc0eba","price":"0.819","side":"SELL","size":"5.53"}],"timestamp":"1785036185945"},"payload_hash":"d9f97dcd93eeb2cb2343b6511a6ea418ad30247f5d92d62fc6257517c7ab669e","raw_frame":"{\"market\":\"0x4ece6ea8e71e48e1a06bc1f3afae28b8cf1f4c02da84e063e897ee2934579fb7\", \"price_changes\":[{\"asset_id\":\"42849131213114758080260198350962549519803211945339841540212854265574993410571\", \"price\":\"0.181\", \"size\":\"5.53\", \"side\":\"BUY\", \"hash\":\"f601bba346823022fe71ab937cf03a0afd8bc8da\", \"best_bid\":\"0.999\", \"best_ask\":\"1\"}, {\"asset_id\":\"54181442874099068684888188755958127023688250733698219741890813802447465352698\", \"price\":\"0.819\", \"size\":\"5.53\", \"side\":\"SELL\", \"hash\":\"aeccf512c4cf814a7757947a696344f7bbfc0eba\", \"best_bid\":\"0\", \"best_ask\":\"0.001\"}], \"timestamp\":\"1785036185945\", \"event_type\":\"price_change\"}","received_at":"2026-07-26T03:23:06.003844Z","schema_version":"clob-market-ws.price_change.v1","sequence":null,"server_hash":null,"server_timestamp":"1785036185945","session_id":"c31a343fa9584b66bec39f9faee0e3a0","source":"clob_market_ws"},"received_at":"2026-07-26T03:23:06.003844Z","record_id":"358861c356d1bd6b0294de35652b5ecb722ca7a9b98d56f7fa983d38471bb060","schema_fingerprint":"4aa3821a28b0b7c2400bc59aba4bcc0a76e971dadd19610d3ad38c768e124dc7","schema_version":"edge-lab-recorder.raw.v1","sequence":null,"source":"clob_market_ws"}
{"event_at":"2026-07-26T03:23:05.945000Z","event_fingerprint":"4401f77ced6baad2763cc6e70bbaf4d991d6d6ba3ac11c8b9eff8c94c2bd4cad","payload":{"connection_id":"f3be8c5f87ba4c71b8e5c26aee143178","event_at":"2026-07-26T03:23:05.945000Z","event_type":"price_change","frame_hash":"e90f6730b210f886dbe1ed725280dc53a3ea9cb6cf0e4f840b5ceb2144428ac7","frame_index":0,"kind":"data","monotonic_ns":138169555246541,"payload":{"event_type":"price_change","market":"0x4ece6ea8e71e48e1a06bc1f3afae28b8cf1f4c02da84e063e897ee2934579fb7","price_changes":[{"asset_id":"42849131213114758080260198350962549519803211945339841540212854265574993410571","best_ask":"1","best_bid":"0.999","hash":"6a388ce7d14692d29da8dc556b6685d150bfff4a","price":"0.025","side":"BUY","size":"5.26"},{"asset_id":"54181442874099068684888188755958127023688250733698219741890813802447465352698","best_ask":"0.001","best_bid":"0","hash":"85109d4fcdfbc7dc8aaf5b3b08c0a55aea96bb06","price":"0.975","side":"SELL","size":"5.26"}],"timestamp":"1785036185945"},"payload_hash":"a36255666956e5e8e5902f4563cabec58944b21efff340689b882446b252b946","raw_frame":"{\"market\":\"0x4ece6ea8e71e48e1a06bc1f3afae28b8cf1f4c02da84e063e897ee2934579fb7\", \"price_changes\":[{\"asset_id\":\"42849131213114758080260198350962549519803211945339841540212854265574993410571\", \"price\":\"0.025\", \"size\":\"5.26\", \"side\":\"BUY\", \"hash\":\"6a388ce7d14692d29da8dc556b6685d150bfff4a\", \"best_bid\":\"0.999\", \"best_ask\":\"1\"}, {\"asset_id\":\"54181442874099068684888188755958127023688250733698219741890813802447465352698\", \"price\":\"0.975\", \"size\":\"5.26\", \"side\":\"SELL\", \"hash\":\"85109d4fcdfbc7dc8aaf5b3b08c0a55aea96bb06\", \"best_bid\":\"0\", \"best_ask\":\"0.001\"}], \"timestamp\":\"1785036185945\", \"event_type\":\"price_change\"}","received_at":"2026-07-26T03:23:06.005327Z","schema_version":"clob-market-ws.price_change.v1","sequence":null,"server_hash":null,"server_timestamp":"1785036185945","session_id":"c31a343fa9584b66bec39f9faee0e3a0","source":"clob_market_ws"},"received_at":"2026-07-26T03:23:06.005327Z","record_id":"6e8da01f517f991ab75049970bb5380c0fdd248c2fd1bcea72df682c4b0ce9db","schema_fingerprint":"4aa3821a28b0b7c2400bc59aba4bcc0a76e971dadd19610d3ad38c768e124dc7","schema_version":"edge-lab-recorder.raw.v1","sequence":null,"source":"clob_market_ws"}
