{"event_at":"2026-07-27T03:25:52.735000Z","event_fingerprint":"63d6e3c7c0fb51a5d9788f9afa72989008d0417af25feea85e6eb3fa679f395a","payload":{"connection_id":"c7dc2e4762f849c6b6f9306b6518dcab","event_at":"2026-07-27T03:25:52.735000Z","event_type":"price_change","frame_hash":"13f9437fb833f627923d7eafde92735b8b93266807d4e59d8e05c8f99646341d","frame_index":0,"kind":"data","monotonic_ns":224736039597458,"payload":{"event_type":"price_change","market":"0x717c0e8ccd4d5c7040185188fbae28be901ca589a11a94b1b38ca36a79eccfeb","price_changes":[{"asset_id":"24254094493625419915756280046002869097156693848522361803041977572204227262166","best_ask":"0.86","best_bid":"0.85","hash":"5fd1d6900a9d5defbd703c82aaba1eaed9cc72a8","price":"0.95","side":"SELL","size":"804.2"},{"asset_id":"41448400836309843603620980831210604935021861034693225347475867885462478926555","best_ask":"0.15","best_bid":"0.14","hash":"a2f1a37dff28282ad53d0c24fd140a46f6703b3d","price":"0.05","side":"BUY","size":"804.2"}],"timestamp":"1785122752735"},"payload_hash":"70f71eb02c5fa133ff1d407df8886a5b0996aa063aad63e62aa87826a33b721e","raw_frame":"{\"market\":\"0x717c0e8ccd4d5c7040185188fbae28be901ca589a11a94b1b38ca36a79eccfeb\", \"price_changes\":[{\"asset_id\":\"24254094493625419915756280046002869097156693848522361803041977572204227262166\", \"price\":\"0.95\", \"size\":\"804.2\", \"side\":\"SELL\", \"hash\":\"5fd1d6900a9d5defbd703c82aaba1eaed9cc72a8\", \"best_bid\":\"0.85\", \"best_ask\":\"0.86\"}, {\"asset_id\":\"41448400836309843603620980831210604935021861034693225347475867885462478926555\", \"price\":\"0.05\", \"size\":\"804.2\", \"side\":\"BUY\", \"hash\":\"a2f1a37dff28282ad53d0c24fd140a46f6703b3d\", \"best_bid\":\"0.14\", \"best_ask\":\"0.15\"}], \"timestamp\":\"1785122752735\", \"event_type\":\"price_change\"}","received_at":"2026-07-27T03:25:52.679967Z","schema_version":"clob-market-ws.price_change.v1","sequence":null,"server_hash":null,"server_timestamp":"1785122752735","session_id":"dd162b8dca5f43ff811d304e69a06123","source":"clob_market_ws"},"received_at":"2026-07-27T03:25:52.679967Z","record_id":"5c31842e71684f0753d26d6b604fccfc362792da990352f2541031475b1a402d","schema_fingerprint":"4aa3821a28b0b7c2400bc59aba4bcc0a76e971dadd19610d3ad38c768e124dc7","schema_version":"edge-lab-recorder.raw.v1","sequence":null,"source":"clob_market_ws"}
{"event_at":"2026-07-27T03:25:52.743000Z","event_fingerprint":"06754b1fbf8c243bebf65952dd8bfe707b48c73dfdfc091525f88dccc3d53dbe","payload":{"connection_id":"c7dc2e4762f849c6b6f9306b6518dcab","event_at":"2026-07-27T03:25:52.743000Z","event_type":"price_change","frame_hash":"86022c5f21860bc19fda9727d8d7893c0b0a441820c8d779ff415c15ba4f0825","frame_index":0,"kind":"data","monotonic_ns":224736051030833,"payload":{"event_type":"price_change","market":"0x717c0e8ccd4d5c7040185188fbae28be901ca589a11a94b1b38ca36a79eccfeb","price_changes":[{"asset_id":"41448400836309843603620980831210604935021861034693225347475867885462478926555","best_ask":"0.15","best_bid":"0.14","hash":"125f41f546cc10db57f8bebf1afab728285c5c83","price":"0.16","side":"SELL","size":"25.51"},{"asset_id":"24254094493625419915756280046002869097156693848522361803041977572204227262166","best_ask":"0.86","best_bid":"0.85","hash":"53f3b12a6f31c0bf705eb8f2fc1badc3ee03ee85","price":"0.84","side":"BUY","size":"25.51"}],"timestamp":"1785122752743"},"payload_hash":"dc4eeb62b33b898cb090b3c159d1484e471009291924f61fe754248b24fff168","raw_frame":"{\"market\":\"0x717c0e8ccd4d5c7040185188fbae28be901ca589a11a94b1b38ca36a79eccfeb\", \"price_changes\":[{\"asset_id\":\"41448400836309843603620980831210604935021861034693225347475867885462478926555\", \"price\":\"0.16\", \"size\":\"25.51\", \"side\":\"SELL\", \"hash\":\"125f41f546cc10db57f8bebf1afab728285c5c83\", \"best_bid\":\"0.14\", \"best_ask\":\"0.15\"}, {\"asset_id\":\"24254094493625419915756280046002869097156693848522361803041977572204227262166\", \"price\":\"0.84\", \"size\":\"25.51\", \"side\":\"BUY\", \"hash\":\"53f3b12a6f31c0bf705eb8f2fc1badc3ee03ee85\", \"best_bid\":\"0.85\", \"best_ask\":\"0.86\"}], \"timestamp\":\"1785122752743\", \"event_type\":\"price_change\"}","received_at":"2026-07-27T03:25:52.691400Z","schema_version":"clob-market-ws.price_change.v1","sequence":null,"server_hash":null,"server_timestamp":"1785122752743","session_id":"dd162b8dca5f43ff811d304e69a06123","source":"clob_market_ws"},"received_at":"2026-07-27T03:25:52.691400Z","record_id":"cc3254273c8ddaa5a4fec524369d181fe6e093f63988f90265f5d3aaf4d5f3a2","schema_fingerprint":"4aa3821a28b0b7c2400bc59aba4bcc0a76e971dadd19610d3ad38c768e124dc7","schema_version":"edge-lab-recorder.raw.v1","sequence":null,"source":"clob_market_ws"}
{"event_at":"2026-07-27T03:25:52.755000Z","event_fingerprint":"97a6eabc06695d298dbf15024b26f1fdc974102437a61179f07a7fb0b5942b86","payload":{"connection_id":"c7dc2e4762f849c6b6f9306b6518dcab","event_at":"2026-07-27T03:25:52.755000Z","event_type":"price_change","frame_hash":"13d135daeaca076002893312a3df7afa7412d3b43fc69350d6d7440e4822af82","frame_index":0,"kind":"data","monotonic_ns":224736054929375,"payload":{"event_type":"price_change","market":"0x717c0e8ccd4d5c7040185188fbae28be901ca589a11a94b1b38ca36a79eccfeb","price_changes":[{"asset_id":"24254094493625419915756280046002869097156693848522361803041977572204227262166","best_ask":"0.86","best_bid":"0.85","hash":"53bfff7cb227962ec6b2a10364d4c2be92c73838","price":"0.85","side":"BUY","size":"401"},{"asset_id":"41448400836309843603620980831210604935021861034693225347475867885462478926555","best_ask":"0.15","best_bid":"0.14","hash":"f3ba3a303437fff35b4d55c0018ee3ed1590e00a","price":"0.15","side":"SELL","size":"401"}],"timestamp":"1785122752755"},"payload_hash":"c2150f2a907105e4cca1764cd44de2a3652e0b15984f41b472b1248af1297590","raw_frame":"{\"market\":\"0x717c0e8ccd4d5c7040185188fbae28be901ca589a11a94b1b38ca36a79eccfeb\", \"price_changes\":[{\"asset_id\":\"24254094493625419915756280046002869097156693848522361803041977572204227262166\", \"price\":\"0.85\", \"size\":\"401\", \"side\":\"BUY\", \"hash\":\"53bfff7cb227962ec6b2a10364d4c2be92c73838\", \"best_bid\":\"0.85\", \"best_ask\":\"0.86\"}, {\"asset_id\":\"41448400836309843603620980831210604935021861034693225347475867885462478926555\", \"price\":\"0.15\", \"size\":\"401\", \"side\":\"SELL\", \"hash\":\"f3ba3a303437fff35b4d55c0018ee3ed1590e00a\", \"best_bid\":\"0.14\", \"best_ask\":\"0.15\"}], \"timestamp\":\"1785122752755\", \"event_type\":\"price_change\"}","received_at":"2026-07-27T03:25:52.695299Z","schema_version":"clob-market-ws.price_change.v1","sequence":null,"server_hash":null,"server_timestamp":"1785122752755","session_id":"dd162b8dca5f43ff811d304e69a06123","source":"clob_market_ws"},"received_at":"2026-07-27T03:25:52.695299Z","record_id":"b50fbbfcf1e90dee6bceeb2bad00e04834a7d0b270933229806be83f81adecd1","schema_fingerprint":"4aa3821a28b0b7c2400bc59aba4bcc0a76e971dadd19610d3ad38c768e124dc7","schema_version":"edge-lab-recorder.raw.v1","sequence":null,"source":"clob_market_ws"}
{"event_at":"2026-07-27T03:25:52.759000Z","event_fingerprint":"8b2248bf71278d9ef3ba7ac9dc4e6b05e39346ebf9e356c4ca2163b954c818c4","payload":{"connection_id":"c7dc2e4762f849c6b6f9306b6518dcab","event_at":"2026-07-27T03:25:52.759000Z","event_type":"price_change","frame_hash":"67fb629a603f60a3f5bbba1a06474e954904036dd23e5300781794512f1bf759","frame_index":0,"kind":"data","monotonic_ns":224736059165625,"payload":{"event_type":"price_change","market":"0x717c0e8ccd4d5c7040185188fbae28be901ca589a11a94b1b38ca36a79eccfeb","price_changes":[{"asset_id":"24254094493625419915756280046002869097156693848522361803041977572204227262166","best_ask":"0.86","best_bid":"0.85","hash":"0e5f2d72ba43caae7a4f3b224a1745532fa7c006","price":"0.02","side":"BUY","size":"683.1"},{"asset_id":"41448400836309843603620980831210604935021861034693225347475867885462478926555","best_ask":"0.15","best_bid":"0.14","hash":"2bc87adf5b897503033bc79e988db9ef099483ec","price":"0.98","side":"SELL","size":"683.1"}],"timestamp":"1785122752759"},"payload_hash":"79d5aa9da5ef8c6bed30006cc9328a8e3af6d6c07930534e9ab4a34d944cc3bf","raw_frame":"{\"market\":\"0x717c0e8ccd4d5c7040185188fbae28be901ca589a11a94b1b38ca36a79eccfeb\", \"price_changes\":[{\"asset_id\":\"24254094493625419915756280046002869097156693848522361803041977572204227262166\", \"price\":\"0.02\", \"size\":\"683.1\", \"side\":\"BUY\", \"hash\":\"0e5f2d72ba43caae7a4f3b224a1745532fa7c006\", \"best_bid\":\"0.85\", \"best_ask\":\"0.86\"}, {\"asset_id\":\"41448400836309843603620980831210604935021861034693225347475867885462478926555\", \"price\":\"0.98\", \"size\":\"683.1\", \"side\":\"SELL\", \"hash\":\"2bc87adf5b897503033bc79e988db9ef099483ec\", \"best_bid\":\"0.14\", \"best_ask\":\"0.15\"}], \"timestamp\":\"1785122752759\", \"event_type\":\"price_change\"}","received_at":"2026-07-27T03:25:52.699535Z","schema_version":"clob-market-ws.price_change.v1","sequence":null,"server_hash":null,"server_timestamp":"1785122752759","session_id":"dd162b8dca5f43ff811d304e69a06123","source":"clob_market_ws"},"received_at":"2026-07-27T03:25:52.699535Z","record_id":"6f9c604ae11c101b379f5ca64b12eae54ebdde684c3998cb3d25daea50a4420a","schema_fingerprint":"4aa3821a28b0b7c2400bc59aba4bcc0a76e971dadd19610d3ad38c768e124dc7","schema_version":"edge-lab-recorder.raw.v1","sequence":null,"source":"clob_market_ws"}
{"event_at":"2026-07-27T03:25:52.767000Z","event_fingerprint":"f502ad1a885a9b8f0c8a35ff7f814f552eb12c819e97bc440f31cd5d5634f0c3","payload":{"connection_id":"c7dc2e4762f849c6b6f9306b6518dcab","event_at":"2026-07-27T03:25:52.767000Z","event_type":"price_change","frame_hash":"04856f6b8edf218ccf607a6662b289ff822491991039897dec6b984712b6cf17","frame_index":0,"kind":"data","monotonic_ns":224736065228958,"payload":{"event_type":"price_change","market":"0x717c0e8ccd4d5c7040185188fbae28be901ca589a11a94b1b38ca36a79eccfeb","price_changes":[{"asset_id":"41448400836309843603620980831210604935021861034693225347475867885462478926555","best_ask":"0.15","best_bid":"0.14","hash":"4fcdda6b9717cc993f16273f0a92910f4e217803","price":"0.15","side":"SELL","size":"426"},{"asset_id":"24254094493625419915756280046002869097156693848522361803041977572204227262166","best_ask":"0.86","best_bid":"0.85","hash":"09edc9519b23f5718d944831efe862ac36e9b27e","price":"0.85","side":"BUY","size":"426"}],"timestamp":"1785122752767"},"payload_hash":"687e03863db0a83dc6d035fd7c2b9f9a811ec5683c8cf59d14c8cf9838dcbd82","raw_frame":"{\"market\":\"0x717c0e8ccd4d5c7040185188fbae28be901ca589a11a94b1b38ca36a79eccfeb\", \"price_changes\":[{\"asset_id\":\"41448400836309843603620980831210604935021861034693225347475867885462478926555\", \"price\":\"0.15\", \"size\":\"426\", \"side\":\"SELL\", \"hash\":\"4fcdda6b9717cc993f16273f0a92910f4e217803\", \"best_bid\":\"0.14\", \"best_ask\":\"0.15\"}, {\"asset_id\":\"24254094493625419915756280046002869097156693848522361803041977572204227262166\", \"price\":\"0.85\", \"size\":\"426\", \"side\":\"BUY\", \"hash\":\"09edc9519b23f5718d944831efe862ac36e9b27e\", \"best_bid\":\"0.85\", \"best_ask\":\"0.86\"}], \"timestamp\":\"1785122752767\", \"event_type\":\"price_change\"}","received_at":"2026-07-27T03:25:52.705596Z","schema_version":"clob-market-ws.price_change.v1","sequence":null,"server_hash":null,"server_timestamp":"1785122752767","session_id":"dd162b8dca5f43ff811d304e69a06123","source":"clob_market_ws"},"received_at":"2026-07-27T03:25:52.705596Z","record_id":"d40ad55cc6d5b747da018e4c665cb829bf1c122fe667503e3f3268059848845c","schema_fingerprint":"4aa3821a28b0b7c2400bc59aba4bcc0a76e971dadd19610d3ad38c768e124dc7","schema_version":"edge-lab-recorder.raw.v1","sequence":null,"source":"clob_market_ws"}
{"event_at":"2026-07-27T03:25:52.783000Z","event_fingerprint":"c228f3acf70128e821b3e72399347decb401353596f1c359e7e7ca5ad1ebb8f2","payload":{"connection_id":"c7dc2e4762f849c6b6f9306b6518dcab","event_at":"2026-07-27T03:25:52.783000Z","event_type":"price_change","frame_hash":"fece3e9c453f936b0560af588d151c6f8d69a586a5af4d66ea80f424aedaf2ec","frame_index":0,"kind":"data","monotonic_ns":224736069429541,"payload":{"event_type":"price_change","market":"0x717c0e8ccd4d5c7040185188fbae28be901ca589a11a94b1b38ca36a79eccfeb","price_changes":[{"asset_id":"41448400836309843603620980831210604935021861034693225347475867885462478926555","best_ask":"0.15","best_bid":"0.14","hash":"44906d78240a064fe283bbef8cde17834fee0a14","price":"0.17","side":"SELL","size":"44.96"},{"asset_id":"24254094493625419915756280046002869097156693848522361803041977572204227262166","best_ask":"0.86","best_bid":"0.85","hash":"41f75f10823c48f30fcf9dd177b075493b908adf","price":"0.83","side":"BUY","size":"44.96"}],"timestamp":"1785122752783"},"payload_hash":"aac3171e69e93e42def0a35028c5f233ee775a45701a3b1079e84e9a9134ca69","raw_frame":"{\"market\":\"0x717c0e8ccd4d5c7040185188fbae28be901ca589a11a94b1b38ca36a79eccfeb\", \"price_changes\":[{\"asset_id\":\"41448400836309843603620980831210604935021861034693225347475867885462478926555\", \"price\":\"0.17\", \"size\":\"44.96\", \"side\":\"SELL\", \"hash\":\"44906d78240a064fe283bbef8cde17834fee0a14\", \"best_bid\":\"0.14\", \"best_ask\":\"0.15\"}, {\"asset_id\":\"24254094493625419915756280046002869097156693848522361803041977572204227262166\", \"price\":\"0.83\", \"size\":\"44.96\", \"side\":\"BUY\", \"hash\":\"41f75f10823c48f30fcf9dd177b075493b908adf\", \"best_bid\":\"0.85\", \"best_ask\":\"0.86\"}], \"timestamp\":\"1785122752783\", \"event_type\":\"price_change\"}","received_at":"2026-07-27T03:25:52.709798Z","schema_version":"clob-market-ws.price_change.v1","sequence":null,"server_hash":null,"server_timestamp":"1785122752783","session_id":"dd162b8dca5f43ff811d304e69a06123","source":"clob_market_ws"},"received_at":"2026-07-27T03:25:52.709798Z","record_id":"45d4de3703cc56e9f9fe6a11e74c8fee53941d93915939aa6e57d224036940b0","schema_fingerprint":"4aa3821a28b0b7c2400bc59aba4bcc0a76e971dadd19610d3ad38c768e124dc7","schema_version":"edge-lab-recorder.raw.v1","sequence":null,"source":"clob_market_ws"}
{"event_at":"2026-07-27T03:25:52.849000Z","event_fingerprint":"a383b9ca2600472f087e642b838929389039d8b54a3b680380834b6705a622be","payload":{"connection_id":"c7dc2e4762f849c6b6f9306b6518dcab","event_at":"2026-07-27T03:25:52.849000Z","event_type":"price_change","frame_hash":"da224e1785005b982314b21ca050942aa59b65f52a0512a37472559654ab35fa","frame_index":0,"kind":"data","monotonic_ns":224736083384041,"payload":{"event_type":"price_change","market":"0x717c0e8ccd4d5c7040185188fbae28be901ca589a11a94b1b38ca36a79eccfeb","price_changes":[{"asset_id":"24254094493625419915756280046002869097156693848522361803041977572204227262166","best_ask":"0.86","best_bid":"0.85","hash":"ff7f58d1795765369d3d0b963054a7e9d1186df8","price":"0.01","side":"BUY","size":"5458.02"},{"asset_id":"41448400836309843603620980831210604935021861034693225347475867885462478926555","best_ask":"0.15","best_bid":"0.14","hash":"22dcae90940a8eed22b73f93648bac7ba545a73b","price":"0.99","side":"SELL","size":"5458.02"}],"timestamp":"1785122752849"},"payload_hash":"9c433b48e82dbb92082a64585dacf8553e0815b2812c4398d6916111375fee15","raw_frame":"{\"market\":\"0x717c0e8ccd4d5c7040185188fbae28be901ca589a11a94b1b38ca36a79eccfeb\", \"price_changes\":[{\"asset_id\":\"24254094493625419915756280046002869097156693848522361803041977572204227262166\", \"price\":\"0.01\", \"size\":\"5458.02\", \"side\":\"BUY\", \"hash\":\"ff7f58d1795765369d3d0b963054a7e9d1186df8\", \"best_bid\":\"0.85\", \"best_ask\":\"0.86\"}, {\"asset_id\":\"41448400836309843603620980831210604935021861034693225347475867885462478926555\", \"price\":\"0.99\", \"size\":\"5458.02\", \"side\":\"SELL\", \"hash\":\"22dcae90940a8eed22b73f93648bac7ba545a73b\", \"best_bid\":\"0.14\", \"best_ask\":\"0.15\"}], \"timestamp\":\"1785122752849\", \"event_type\":\"price_change\"}","received_at":"2026-07-27T03:25:52.723750Z","schema_version":"clob-market-ws.price_change.v1","sequence":null,"server_hash":null,"server_timestamp":"1785122752849","session_id":"dd162b8dca5f43ff811d304e69a06123","source":"clob_market_ws"},"received_at":"2026-07-27T03:25:52.723750Z","record_id":"69af1bda9ad596185bef404dbd01397e92b89b57d58e7a874320bb9a5bd56c69","schema_fingerprint":"4aa3821a28b0b7c2400bc59aba4bcc0a76e971dadd19610d3ad38c768e124dc7","schema_version":"edge-lab-recorder.raw.v1","sequence":null,"source":"clob_market_ws"}
{"event_at":"2026-07-27T03:25:52.853000Z","event_fingerprint":"c8cab7eb3ffb4ce1090847c47d80c4093c9c3b7272e8e21c270db7887715c607","payload":{"connection_id":"c7dc2e4762f849c6b6f9306b6518dcab","event_at":"2026-07-27T03:25:52.853000Z","event_type":"price_change","frame_hash":"1e17534fb245c0c1cea9e87fe193523135683bc971631d35ff48c66564e000a4","frame_index":0,"kind":"data","monotonic_ns":224736087859458,"payload":{"event_type":"price_change","market":"0x717c0e8ccd4d5c7040185188fbae28be901ca589a11a94b1b38ca36a79eccfeb","price_changes":[{"asset_id":"24254094493625419915756280046002869097156693848522361803041977572204227262166","best_ask":"0.86","best_bid":"0.85","hash":"f86ea281249498e85a782d14b975db55c1f340eb","price":"0.85","side":"BUY","size":"330"},{"asset_id":"41448400836309843603620980831210604935021861034693225347475867885462478926555","best_ask":"0.15","best_bid":"0.14","hash":"ab4f9c87259bacb245c46b390f34ea282034a163","price":"0.15","side":"SELL","size":"330"}],"timestamp":"1785122752853"},"payload_hash":"43e0701c8bd4fa640aca8beaa10406f6f65d117196649960b8a3e698f5d96a74","raw_frame":"{\"market\":\"0x717c0e8ccd4d5c7040185188fbae28be901ca589a11a94b1b38ca36a79eccfeb\", \"price_changes\":[{\"asset_id\":\"24254094493625419915756280046002869097156693848522361803041977572204227262166\", \"price\":\"0.85\", \"size\":\"330\", \"side\":\"BUY\", \"hash\":\"f86ea281249498e85a782d14b975db55c1f340eb\", \"best_bid\":\"0.85\", \"best_ask\":\"0.86\"}, {\"asset_id\":\"41448400836309843603620980831210604935021861034693225347475867885462478926555\", \"price\":\"0.15\", \"size\":\"330\", \"side\":\"SELL\", \"hash\":\"ab4f9c87259bacb245c46b390f34ea282034a163\", \"best_bid\":\"0.14\", \"best_ask\":\"0.15\"}], \"timestamp\":\"1785122752853\", \"event_type\":\"price_change\"}","received_at":"2026-07-27T03:25:52.728227Z","schema_version":"clob-market-ws.price_change.v1","sequence":null,"server_hash":null,"server_timestamp":"1785122752853","session_id":"dd162b8dca5f43ff811d304e69a06123","source":"clob_market_ws"},"received_at":"2026-07-27T03:25:52.728227Z","record_id":"92123cfc30c00e2bec3d2b1dbb69523cbdf8ebed8921be6f96ea0948a0726d3c","schema_fingerprint":"4aa3821a28b0b7c2400bc59aba4bcc0a76e971dadd19610d3ad38c768e124dc7","schema_version":"edge-lab-recorder.raw.v1","sequence":null,"source":"clob_market_ws"}
{"event_at":"2026-07-27T03:25:52.869000Z","event_fingerprint":"7c26a1cebdbe6566fc0b85cf2259ea278b20e2c6f2ef7bd4d2101aacefdfa96c","payload":{"connection_id":"c7dc2e4762f849c6b6f9306b6518dcab","event_at":"2026-07-27T03:25:52.869000Z","event_type":"price_change","frame_hash":"03136ee5fcfabcad4a97f09289801c5976b4faa0650bbe30f17559f738a0520e","frame_index":0,"kind":"data","monotonic_ns":224736103987000,"payload":{"event_type":"price_change","market":"0x717c0e8ccd4d5c7040185188fbae28be901ca589a11a94b1b38ca36a79eccfeb","price_changes":[{"asset_id":"24254094493625419915756280046002869097156693848522361803041977572204227262166","best_ask":"0.86","best_bid":"0.85","hash":"b9d790bc12fb1451c619323efea14d24de4ddfa6","price":"0.01","side":"BUY","size":"5453.02"},{"asset_id":"41448400836309843603620980831210604935021861034693225347475867885462478926555","best_ask":"0.15","best_bid":"0.14","hash":"5627c4ef0308b07816393a4f149d4538d55f0489","price":"0.99","side":"SELL","size":"5453.02"}],"timestamp":"1785122752869"},"payload_hash":"945188607cc4cda6dbfa38cf920eeec984d7a13c7dae0d71fd0be2594e105897","raw_frame":"{\"market\":\"0x717c0e8ccd4d5c7040185188fbae28be901ca589a11a94b1b38ca36a79eccfeb\", \"price_changes\":[{\"asset_id\":\"24254094493625419915756280046002869097156693848522361803041977572204227262166\", \"price\":\"0.01\", \"size\":\"5453.02\", \"side\":\"BUY\", \"hash\":\"b9d790bc12fb1451c619323efea14d24de4ddfa6\", \"best_bid\":\"0.85\", \"best_ask\":\"0.86\"}, {\"asset_id\":\"41448400836309843603620980831210604935021861034693225347475867885462478926555\", \"price\":\"0.99\", \"size\":\"5453.02\", \"side\":\"SELL\", \"hash\":\"5627c4ef0308b07816393a4f149d4538d55f0489\", \"best_bid\":\"0.14\", \"best_ask\":\"0.15\"}], \"timestamp\":\"1785122752869\", \"event_type\":\"price_change\"}","received_at":"2026-07-27T03:25:52.744355Z","schema_version":"clob-market-ws.price_change.v1","sequence":null,"server_hash":null,"server_timestamp":"1785122752869","session_id":"dd162b8dca5f43ff811d304e69a06123","source":"clob_market_ws"},"received_at":"2026-07-27T03:25:52.744355Z","record_id":"b28df2ecbbeb8933664acf8bd66b9c1526c151a9fc031efa5c73c194f32d8ba7","schema_fingerprint":"4aa3821a28b0b7c2400bc59aba4bcc0a76e971dadd19610d3ad38c768e124dc7","schema_version":"edge-lab-recorder.raw.v1","sequence":null,"source":"clob_market_ws"}
{"event_at":"2026-07-27T03:25:52.876000Z","event_fingerprint":"571fcd5651938c72a82d42d46e0b6ec0a9fef26c1160cab0958b7f1b56a27695","payload":{"connection_id":"c7dc2e4762f849c6b6f9306b6518dcab","event_at":"2026-07-27T03:25:52.876000Z","event_type":"price_change","frame_hash":"d25bce467ab1a1d6b9c8408624c0f6af343bdbf25427ec639773b64bb79b1beb","frame_index":0,"kind":"data","monotonic_ns":224736111549875,"payload":{"event_type":"price_change","market":"0x717c0e8ccd4d5c7040185188fbae28be901ca589a11a94b1b38ca36a79eccfeb","price_changes":[{"asset_id":"24254094493625419915756280046002869097156693848522361803041977572204227262166","best_ask":"0.86","best_bid":"0.85","hash":"2b346369aa383792ba6c7495901a48aafeceb615","price":"0.01","side":"BUY","size":"5458.02"},{"asset_id":"41448400836309843603620980831210604935021861034693225347475867885462478926555","best_ask":"0.15","best_bid":"0.14","hash":"02e9bf3546b752f3d67fe9544df09ad05f07548b","price":"0.99","side":"SELL","size":"5458.02"}],"timestamp":"1785122752876"},"payload_hash":"93bc377c93847f45f3dfe060157276e4330a809ccd8348d617faec6dfc906a7c","raw_frame":"{\"market\":\"0x717c0e8ccd4d5c7040185188fbae28be901ca589a11a94b1b38ca36a79eccfeb\", \"price_changes\":[{\"asset_id\":\"24254094493625419915756280046002869097156693848522361803041977572204227262166\", \"price\":\"0.01\", \"size\":\"5458.02\", \"side\":\"BUY\", \"hash\":\"2b346369aa383792ba6c7495901a48aafeceb615\", \"best_bid\":\"0.85\", \"best_ask\":\"0.86\"}, {\"asset_id\":\"41448400836309843603620980831210604935021861034693225347475867885462478926555\", \"price\":\"0.99\", \"size\":\"5458.02\", \"side\":\"SELL\", \"hash\":\"02e9bf3546b752f3d67fe9544df09ad05f07548b\", \"best_bid\":\"0.14\", \"best_ask\":\"0.15\"}], \"timestamp\":\"1785122752876\", \"event_type\":\"price_change\"}","received_at":"2026-07-27T03:25:52.751917Z","schema_version":"clob-market-ws.price_change.v1","sequence":null,"server_hash":null,"server_timestamp":"1785122752876","session_id":"dd162b8dca5f43ff811d304e69a06123","source":"clob_market_ws"},"received_at":"2026-07-27T03:25:52.751917Z","record_id":"1b8ce85909a47d25e18d66871973785fe73908ec46f510bf5f1953efbe1e5437","schema_fingerprint":"4aa3821a28b0b7c2400bc59aba4bcc0a76e971dadd19610d3ad38c768e124dc7","schema_version":"edge-lab-recorder.raw.v1","sequence":null,"source":"clob_market_ws"}
{"event_at":"2026-07-27T03:25:52.879000Z","event_fingerprint":"9526603786840abf9db0487ae76d034109e7ee651cc7af1665545f3b01b38203","payload":{"connection_id":"c7dc2e4762f849c6b6f9306b6518dcab","event_at":"2026-07-27T03:25:52.879000Z","event_type":"price_change","frame_hash":"124ec4ed164aaa4808e982af0017ac39dc569a5ed6508801ddb9c25ecc0b6be7","frame_index":0,"kind":"data","monotonic_ns":224736115202000,"payload":{"event_type":"price_change","market":"0x717c0e8ccd4d5c7040185188fbae28be901ca589a11a94b1b38ca36a79eccfeb","price_changes":[{"asset_id":"41448400836309843603620980831210604935021861034693225347475867885462478926555","best_ask":"0.15","best_bid":"0.14","hash":"a666a81ea12e1199ddf798c64fa08802e51ff753","price":"0.17","side":"SELL","size":"38.91"},{"asset_id":"24254094493625419915756280046002869097156693848522361803041977572204227262166","best_ask":"0.86","best_bid":"0.85","hash":"8bf13dff493e264bad40846f7cf47f8d4de82dbe","price":"0.83","side":"BUY","size":"38.91"}],"timestamp":"1785122752879"},"payload_hash":"3d62130b9775c34a550ca5f1395c76799afbedb6911cf8bde75c174f700b570e","raw_frame":"{\"market\":\"0x717c0e8ccd4d5c7040185188fbae28be901ca589a11a94b1b38ca36a79eccfeb\", \"price_changes\":[{\"asset_id\":\"41448400836309843603620980831210604935021861034693225347475867885462478926555\", \"price\":\"0.17\", \"size\":\"38.91\", \"side\":\"SELL\", \"hash\":\"a666a81ea12e1199ddf798c64fa08802e51ff753\", \"best_bid\":\"0.14\", \"best_ask\":\"0.15\"}, {\"asset_id\":\"24254094493625419915756280046002869097156693848522361803041977572204227262166\", \"price\":\"0.83\", \"size\":\"38.91\", \"side\":\"BUY\", \"hash\":\"8bf13dff493e264bad40846f7cf47f8d4de82dbe\", \"best_bid\":\"0.85\", \"best_ask\":\"0.86\"}], \"timestamp\":\"1785122752879\", \"event_type\":\"price_change\"}","received_at":"2026-07-27T03:25:52.755570Z","schema_version":"clob-market-ws.price_change.v1","sequence":null,"server_hash":null,"server_timestamp":"1785122752879","session_id":"dd162b8dca5f43ff811d304e69a06123","source":"clob_market_ws"},"received_at":"2026-07-27T03:25:52.755570Z","record_id":"34706fc3aad34da6a826f518e84a746fdbafd8db68a5611551ad8e0cfe67cc59","schema_fingerprint":"4aa3821a28b0b7c2400bc59aba4bcc0a76e971dadd19610d3ad38c768e124dc7","schema_version":"edge-lab-recorder.raw.v1","sequence":null,"source":"clob_market_ws"}
{"event_at":"2026-07-27T03:25:52.887000Z","event_fingerprint":"c16cff372fd4d766ab1e836c73fc43fc2f2d694594f792a9316a242c28a9e3e7","payload":{"connection_id":"c7dc2e4762f849c6b6f9306b6518dcab","event_at":"2026-07-27T03:25:52.887000Z","event_type":"price_change","frame_hash":"3574710362808fcdad44ee7426fc2318a64acd4dfdee22815e19f9b65b472829","frame_index":0,"kind":"data","monotonic_ns":224736123170291,"payload":{"event_type":"price_change","market":"0x717c0e8ccd4d5c7040185188fbae28be901ca589a11a94b1b38ca36a79eccfeb","price_changes":[{"asset_id":"24254094493625419915756280046002869097156693848522361803041977572204227262166","best_ask":"0.86","best_bid":"0.85","hash":"d5edbb9fab713980b746cb3d9c95d9ee4513e6c7","price":"0.86","side":"SELL","size":"12.58"},{"asset_id":"41448400836309843603620980831210604935021861034693225347475867885462478926555","best_ask":"0.15","best_bid":"0.14","hash":"877e24ab63c7911355f621d3d045e8f4dc6387f2","price":"0.14","side":"BUY","size":"12.58"}],"timestamp":"1785122752887"},"payload_hash":"533312074f0b3204cb54582bf06fec5ac55ac84bdfbe83296d32353872de7911","raw_frame":"{\"market\":\"0x717c0e8ccd4d5c7040185188fbae28be901ca589a11a94b1b38ca36a79eccfeb\", \"price_changes\":[{\"asset_id\":\"24254094493625419915756280046002869097156693848522361803041977572204227262166\", \"price\":\"0.86\", \"size\":\"12.58\", \"side\":\"SELL\", \"hash\":\"d5edbb9fab713980b746cb3d9c95d9ee4513e6c7\", \"best_bid\":\"0.85\", \"best_ask\":\"0.86\"}, {\"asset_id\":\"41448400836309843603620980831210604935021861034693225347475867885462478926555\", \"price\":\"0.14\", \"size\":\"12.58\", \"side\":\"BUY\", \"hash\":\"877e24ab63c7911355f621d3d045e8f4dc6387f2\", \"best_bid\":\"0.14\", \"best_ask\":\"0.15\"}], \"timestamp\":\"1785122752887\", \"event_type\":\"price_change\"}","received_at":"2026-07-27T03:25:52.763538Z","schema_version":"clob-market-ws.price_change.v1","sequence":null,"server_hash":null,"server_timestamp":"1785122752887","session_id":"dd162b8dca5f43ff811d304e69a06123","source":"clob_market_ws"},"received_at":"2026-07-27T03:25:52.763538Z","record_id":"aec0271201574893410dbbd49090c87b6a2a5f1205d6215961613b1dc18495ff","schema_fingerprint":"4aa3821a28b0b7c2400bc59aba4bcc0a76e971dadd19610d3ad38c768e124dc7","schema_version":"edge-lab-recorder.raw.v1","sequence":null,"source":"clob_market_ws"}
{"event_at":"2026-07-27T03:25:52.931000Z","event_fingerprint":"f0a832c6760383e29d3276104a8e521fc0039bba5576a859f40aa284dd47e91e","payload":{"connection_id":"c7dc2e4762f849c6b6f9306b6518dcab","event_at":"2026-07-27T03:25:52.931000Z","event_type":"price_change","frame_hash":"83f9da03ed87d0ed1230c28749e6df45b7db03172700756fbe73affbe83c2f6a","frame_index":0,"kind":"data","monotonic_ns":224736167448958,"payload":{"event_type":"price_change","market":"0x717c0e8ccd4d5c7040185188fbae28be901ca589a11a94b1b38ca36a79eccfeb","price_changes":[{"asset_id":"24254094493625419915756280046002869097156693848522361803041977572204227262166","best_ask":"0.86","best_bid":"0.85","hash":"50684c992713800493309b3e3a4d8706b5ce48d2","price":"0.85","side":"BUY","size":"305"},{"asset_id":"41448400836309843603620980831210604935021861034693225347475867885462478926555","best_ask":"0.15","best_bid":"0.14","hash":"33ee1ef0a50b33dcd21dad94a48f553fe72c50ec","price":"0.15","side":"SELL","size":"305"}],"timestamp":"1785122752931"},"payload_hash":"aadcf707cbc7c6b6dfcb5ad749b5ba36967274ec834a1c7c145d0c4e548dd28b","raw_frame":"{\"market\":\"0x717c0e8ccd4d5c7040185188fbae28be901ca589a11a94b1b38ca36a79eccfeb\", \"price_changes\":[{\"asset_id\":\"24254094493625419915756280046002869097156693848522361803041977572204227262166\", \"price\":\"0.85\", \"size\":\"305\", \"side\":\"BUY\", \"hash\":\"50684c992713800493309b3e3a4d8706b5ce48d2\", \"best_bid\":\"0.85\", \"best_ask\":\"0.86\"}, {\"asset_id\":\"41448400836309843603620980831210604935021861034693225347475867885462478926555\", \"price\":\"0.15\", \"size\":\"305\", \"side\":\"SELL\", \"hash\":\"33ee1ef0a50b33dcd21dad94a48f553fe72c50ec\", \"best_bid\":\"0.14\", \"best_ask\":\"0.15\"}], \"timestamp\":\"1785122752931\", \"event_type\":\"price_change\"}","received_at":"2026-07-27T03:25:52.807815Z","schema_version":"clob-market-ws.price_change.v1","sequence":null,"server_hash":null,"server_timestamp":"1785122752931","session_id":"dd162b8dca5f43ff811d304e69a06123","source":"clob_market_ws"},"received_at":"2026-07-27T03:25:52.807815Z","record_id":"757c4effe602ce48a4efa47cd297580f3cca2d7e634a2590827789a4e00242e4","schema_fingerprint":"4aa3821a28b0b7c2400bc59aba4bcc0a76e971dadd19610d3ad38c768e124dc7","schema_version":"edge-lab-recorder.raw.v1","sequence":null,"source":"clob_market_ws"}
{"event_at":"2026-07-27T03:25:52.933000Z","event_fingerprint":"c3364482cb960e1888aedd604eb171f85e07c61ffd4b796ed0d26626a4ff3c16","payload":{"connection_id":"c7dc2e4762f849c6b6f9306b6518dcab","event_at":"2026-07-27T03:25:52.933000Z","event_type":"price_change","frame_hash":"17a3075bde4dda35734b8e5f625a0c0b9f4afc38d96e08527e372e4b9d92a865","frame_index":0,"kind":"data","monotonic_ns":224736171846833,"payload":{"event_type":"price_change","market":"0x717c0e8ccd4d5c7040185188fbae28be901ca589a11a94b1b38ca36a79eccfeb","price_changes":[{"asset_id":"41448400836309843603620980831210604935021861034693225347475867885462478926555","best_ask":"0.15","best_bid":"0.14","hash":"5ca05156fcf3100908fcd5e754deb96a6462879b","price":"0.15","side":"SELL","size":"280"},{"asset_id":"24254094493625419915756280046002869097156693848522361803041977572204227262166","best_ask":"0.86","best_bid":"0.85","hash":"db27f71686f5f82b5559d5d825204e9e7dad7176","price":"0.85","side":"BUY","size":"280"}],"timestamp":"1785122752933"},"payload_hash":"93d36c29f5b493aa3929ad7797d326473c86adaae9fcacc6e9e486249cdc3d7a","raw_frame":"{\"market\":\"0x717c0e8ccd4d5c7040185188fbae28be901ca589a11a94b1b38ca36a79eccfeb\", \"price_changes\":[{\"asset_id\":\"41448400836309843603620980831210604935021861034693225347475867885462478926555\", \"price\":\"0.15\", \"size\":\"280\", \"side\":\"SELL\", \"hash\":\"5ca05156fcf3100908fcd5e754deb96a6462879b\", \"best_bid\":\"0.14\", \"best_ask\":\"0.15\"}, {\"asset_id\":\"24254094493625419915756280046002869097156693848522361803041977572204227262166\", \"price\":\"0.85\", \"size\":\"280\", \"side\":\"BUY\", \"hash\":\"db27f71686f5f82b5559d5d825204e9e7dad7176\", \"best_bid\":\"0.85\", \"best_ask\":\"0.86\"}], \"timestamp\":\"1785122752933\", \"event_type\":\"price_change\"}","received_at":"2026-07-27T03:25:52.812214Z","schema_version":"clob-market-ws.price_change.v1","sequence":null,"server_hash":null,"server_timestamp":"1785122752933","session_id":"dd162b8dca5f43ff811d304e69a06123","source":"clob_market_ws"},"received_at":"2026-07-27T03:25:52.812214Z","record_id":"8116cea1d6994e064f17f983279ef2afadec9a75da3c170492d5e6fe9f239b47","schema_fingerprint":"4aa3821a28b0b7c2400bc59aba4bcc0a76e971dadd19610d3ad38c768e124dc7","schema_version":"edge-lab-recorder.raw.v1","sequence":null,"source":"clob_market_ws"}
{"event_at":"2026-07-27T03:25:52.954000Z","event_fingerprint":"e601d4a3a0c31150fe07e5397a705916e713bef7d52377e67ef98914c43cb31c","payload":{"connection_id":"c7dc2e4762f849c6b6f9306b6518dcab","event_at":"2026-07-27T03:25:52.954000Z","event_type":"price_change","frame_hash":"bef234fe1fe447f62f0e961eb2d6506c144040d8abd6f5aed6b1a8ccc569bdff","frame_index":0,"kind":"data","monotonic_ns":224736190640125,"payload":{"event_type":"price_change","market":"0x717c0e8ccd4d5c7040185188fbae28be901ca589a11a94b1b38ca36a79eccfeb","price_changes":[{"asset_id":"24254094493625419915756280046002869097156693848522361803041977572204227262166","best_ask":"0.86","best_bid":"0.85","hash":"38247091cbc654f25f089b19fb529ca62924e716","price":"0.84","side":"BUY","size":"50.51"},{"asset_id":"41448400836309843603620980831210604935021861034693225347475867885462478926555","best_ask":"0.15","best_bid":"0.14","hash":"f600a7e1a06c87fa0061496bcb649ef7ad9e71dc","price":"0.16","side":"SELL","size":"50.51"}],"timestamp":"1785122752954"},"payload_hash":"72c041f0844bf641f670a70995f2033a8be0be8f831f4c9f2769c07e065f9ab2","raw_frame":"{\"market\":\"0x717c0e8ccd4d5c7040185188fbae28be901ca589a11a94b1b38ca36a79eccfeb\", \"price_changes\":[{\"asset_id\":\"24254094493625419915756280046002869097156693848522361803041977572204227262166\", \"price\":\"0.84\", \"size\":\"50.51\", \"side\":\"BUY\", \"hash\":\"38247091cbc654f25f089b19fb529ca62924e716\", \"best_bid\":\"0.85\", \"best_ask\":\"0.86\"}, {\"asset_id\":\"41448400836309843603620980831210604935021861034693225347475867885462478926555\", \"price\":\"0.16\", \"size\":\"50.51\", \"side\":\"SELL\", \"hash\":\"f600a7e1a06c87fa0061496bcb649ef7ad9e71dc\", \"best_bid\":\"0.14\", \"best_ask\":\"0.15\"}], \"timestamp\":\"1785122752954\", \"event_type\":\"price_change\"}","received_at":"2026-07-27T03:25:52.831007Z","schema_version":"clob-market-ws.price_change.v1","sequence":null,"server_hash":null,"server_timestamp":"1785122752954","session_id":"dd162b8dca5f43ff811d304e69a06123","source":"clob_market_ws"},"received_at":"2026-07-27T03:25:52.831007Z","record_id":"6d4b379376daf8ea0689595e593f02651cfb7a527bff7c2953b304977214bfb8","schema_fingerprint":"4aa3821a28b0b7c2400bc59aba4bcc0a76e971dadd19610d3ad38c768e124dc7","schema_version":"edge-lab-recorder.raw.v1","sequence":null,"source":"clob_market_ws"}
{"event_at":"2026-07-27T03:25:52.956000Z","event_fingerprint":"f523d2ed13119494dfe266755c856718b877ba4059bd03f2af28956cfe9d77fa","payload":{"connection_id":"c7dc2e4762f849c6b6f9306b6518dcab","event_at":"2026-07-27T03:25:52.956000Z","event_type":"price_change","frame_hash":"9edfc78ff22fa2c3118d6aaf6defe567a40155bfa484b2120e58856fe2ddd5d5","frame_index":0,"kind":"data","monotonic_ns":224736195343250,"payload":{"event_type":"price_change","market":"0x717c0e8ccd4d5c7040185188fbae28be901ca589a11a94b1b38ca36a79eccfeb","price_changes":[{"asset_id":"41448400836309843603620980831210604935021861034693225347475867885462478926555","best_ask":"0.15","best_bid":"0.14","hash":"69294ba1ee038eefb344956a08e66d5822ada2e5","price":"0.16","side":"SELL","size":"75.51"},{"asset_id":"24254094493625419915756280046002869097156693848522361803041977572204227262166","best_ask":"0.86","best_bid":"0.85","hash":"40dd32a51b17532a078ca6c623989fb6722ce191","price":"0.84","side":"BUY","size":"75.51"}],"timestamp":"1785122752956"},"payload_hash":"55c4d53a58b4c14cb7f73603c219e1467d2d0050d0cfacabb7c4faaeb473dca6","raw_frame":"{\"market\":\"0x717c0e8ccd4d5c7040185188fbae28be901ca589a11a94b1b38ca36a79eccfeb\", \"price_changes\":[{\"asset_id\":\"41448400836309843603620980831210604935021861034693225347475867885462478926555\", \"price\":\"0.16\", \"size\":\"75.51\", \"side\":\"SELL\", \"hash\":\"69294ba1ee038eefb344956a08e66d5822ada2e5\", \"best_bid\":\"0.14\", \"best_ask\":\"0.15\"}, {\"asset_id\":\"24254094493625419915756280046002869097156693848522361803041977572204227262166\", \"price\":\"0.84\", \"size\":\"75.51\", \"side\":\"BUY\", \"hash\":\"40dd32a51b17532a078ca6c623989fb6722ce191\", \"best_bid\":\"0.85\", \"best_ask\":\"0.86\"}], \"timestamp\":\"1785122752956\", \"event_type\":\"price_change\"}","received_at":"2026-07-27T03:25:52.835710Z","schema_version":"clob-market-ws.price_change.v1","sequence":null,"server_hash":null,"server_timestamp":"1785122752956","session_id":"dd162b8dca5f43ff811d304e69a06123","source":"clob_market_ws"},"received_at":"2026-07-27T03:25:52.835710Z","record_id":"e378468605f052f4cd0f2449e7d1469d931f244756d88baea918706e9afd9bff","schema_fingerprint":"4aa3821a28b0b7c2400bc59aba4bcc0a76e971dadd19610d3ad38c768e124dc7","schema_version":"edge-lab-recorder.raw.v1","sequence":null,"source":"clob_market_ws"}
