{"event_at":"2026-07-27T03:22:25.598000Z","event_fingerprint":"4884451a4b33c2c9d2a867a950ab659287cb9990aed5e582a3cc85d708fc952d","payload":{"connection_id":"c7dc2e4762f849c6b6f9306b6518dcab","event_at":"2026-07-27T03:22:25.598000Z","event_type":"price_change","frame_hash":"a7fbe7af6406bfb1ca6a0e8e4f99546347dc6fb4bf88db4b877b082ac0864646","frame_index":0,"kind":"data","monotonic_ns":224528830277166,"payload":{"event_type":"price_change","market":"0x717c0e8ccd4d5c7040185188fbae28be901ca589a11a94b1b38ca36a79eccfeb","price_changes":[{"asset_id":"41448400836309843603620980831210604935021861034693225347475867885462478926555","best_ask":"0.56","best_bid":"0.55","hash":"275aa4c630a7d67585bde7ab7e01ac1caf8086bd","price":"0.04","side":"BUY","size":"583.09"},{"asset_id":"24254094493625419915756280046002869097156693848522361803041977572204227262166","best_ask":"0.45","best_bid":"0.44","hash":"2283c195608a96e460953304169d2d93f00c661a","price":"0.96","side":"SELL","size":"583.09"}],"timestamp":"1785122545598"},"payload_hash":"3c44c79b3459c0c2329ae8359af2740a6dad6a8fb7b0d2b4a5f253e838d08214","raw_frame":"{\"market\":\"0x717c0e8ccd4d5c7040185188fbae28be901ca589a11a94b1b38ca36a79eccfeb\", \"price_changes\":[{\"asset_id\":\"41448400836309843603620980831210604935021861034693225347475867885462478926555\", \"price\":\"0.04\", \"size\":\"583.09\", \"side\":\"BUY\", \"hash\":\"275aa4c630a7d67585bde7ab7e01ac1caf8086bd\", \"best_bid\":\"0.55\", \"best_ask\":\"0.56\"}, {\"asset_id\":\"24254094493625419915756280046002869097156693848522361803041977572204227262166\", \"price\":\"0.96\", \"size\":\"583.09\", \"side\":\"SELL\", \"hash\":\"2283c195608a96e460953304169d2d93f00c661a\", \"best_bid\":\"0.44\", \"best_ask\":\"0.45\"}], \"timestamp\":\"1785122545598\", \"event_type\":\"price_change\"}","received_at":"2026-07-27T03:22:25.474107Z","schema_version":"clob-market-ws.price_change.v1","sequence":null,"server_hash":null,"server_timestamp":"1785122545598","session_id":"dd162b8dca5f43ff811d304e69a06123","source":"clob_market_ws"},"received_at":"2026-07-27T03:22:25.474107Z","record_id":"7877fbbdc9d4ceee65c3e450db6add8427bf8579188228af2249b9e44220ac98","schema_fingerprint":"4aa3821a28b0b7c2400bc59aba4bcc0a76e971dadd19610d3ad38c768e124dc7","schema_version":"edge-lab-recorder.raw.v1","sequence":null,"source":"clob_market_ws"}
{"event_at":"2026-07-27T03:22:25.719000Z","event_fingerprint":"9b4a28f45c56545550438350b3667c11853777aaa3eb810b8fa67560fe3ff56b","payload":{"connection_id":"c7dc2e4762f849c6b6f9306b6518dcab","event_at":"2026-07-27T03:22:25.719000Z","event_type":"price_change","frame_hash":"5a6affe19bcb2ca24be42bba72d49372098aba60cc7380c269a011bececba605","frame_index":0,"kind":"data","monotonic_ns":224528952788500,"payload":{"event_type":"price_change","market":"0x717c0e8ccd4d5c7040185188fbae28be901ca589a11a94b1b38ca36a79eccfeb","price_changes":[{"asset_id":"41448400836309843603620980831210604935021861034693225347475867885462478926555","best_ask":"0.56","best_bid":"0.55","hash":"c1f8abaa35a82f1ba347bd88232965c1bc6b6c6e","price":"0.04","side":"BUY","size":"578.09"},{"asset_id":"24254094493625419915756280046002869097156693848522361803041977572204227262166","best_ask":"0.45","best_bid":"0.44","hash":"ab8f4a80b36ffe9752712895aba32fdc02763ddf","price":"0.96","side":"SELL","size":"578.09"}],"timestamp":"1785122545719"},"payload_hash":"a3ca743a0a113f36b76ebf55a757756e32b7d5447cb845ea6a414d6c0d51a6fc","raw_frame":"{\"market\":\"0x717c0e8ccd4d5c7040185188fbae28be901ca589a11a94b1b38ca36a79eccfeb\", \"price_changes\":[{\"asset_id\":\"41448400836309843603620980831210604935021861034693225347475867885462478926555\", \"price\":\"0.04\", \"size\":\"578.09\", \"side\":\"BUY\", \"hash\":\"c1f8abaa35a82f1ba347bd88232965c1bc6b6c6e\", \"best_bid\":\"0.55\", \"best_ask\":\"0.56\"}, {\"asset_id\":\"24254094493625419915756280046002869097156693848522361803041977572204227262166\", \"price\":\"0.96\", \"size\":\"578.09\", \"side\":\"SELL\", \"hash\":\"ab8f4a80b36ffe9752712895aba32fdc02763ddf\", \"best_bid\":\"0.44\", \"best_ask\":\"0.45\"}], \"timestamp\":\"1785122545719\", \"event_type\":\"price_change\"}","received_at":"2026-07-27T03:22:25.596613Z","schema_version":"clob-market-ws.price_change.v1","sequence":null,"server_hash":null,"server_timestamp":"1785122545719","session_id":"dd162b8dca5f43ff811d304e69a06123","source":"clob_market_ws"},"received_at":"2026-07-27T03:22:25.596613Z","record_id":"80cd09fc71150951ea8742b1301cc0eb8815c65a33b852676011a209aeef0a61","schema_fingerprint":"4aa3821a28b0b7c2400bc59aba4bcc0a76e971dadd19610d3ad38c768e124dc7","schema_version":"edge-lab-recorder.raw.v1","sequence":null,"source":"clob_market_ws"}
{"event_at":"2026-07-27T03:22:25.818000Z","event_fingerprint":"2f57dd518d1a5deba615a273d574da43d01855c72c17dbc8f68521249cb91ab8","payload":{"connection_id":"c7dc2e4762f849c6b6f9306b6518dcab","event_at":"2026-07-27T03:22:25.818000Z","event_type":"price_change","frame_hash":"01ab3739e1ad55ecf6f633613124e7a1e35a85103bef8ebc3c4fbfd887f86953","frame_index":0,"kind":"data","monotonic_ns":224529052210791,"payload":{"event_type":"price_change","market":"0x717c0e8ccd4d5c7040185188fbae28be901ca589a11a94b1b38ca36a79eccfeb","price_changes":[{"asset_id":"41448400836309843603620980831210604935021861034693225347475867885462478926555","best_ask":"0.56","best_bid":"0.55","hash":"cba3be5e29eb5a3baecb3485bc911041b28f56ff","price":"0.01","side":"BUY","size":"5458.02"},{"asset_id":"24254094493625419915756280046002869097156693848522361803041977572204227262166","best_ask":"0.45","best_bid":"0.44","hash":"d58efb8c71c7b3d0d1500c5191d1b0108105ba58","price":"0.99","side":"SELL","size":"5458.02"}],"timestamp":"1785122545818"},"payload_hash":"53f8aa927e6a74ff416a2a702333050a13d20a72c9cd9e8f3e0f31081e99cc9d","raw_frame":"{\"market\":\"0x717c0e8ccd4d5c7040185188fbae28be901ca589a11a94b1b38ca36a79eccfeb\", \"price_changes\":[{\"asset_id\":\"41448400836309843603620980831210604935021861034693225347475867885462478926555\", \"price\":\"0.01\", \"size\":\"5458.02\", \"side\":\"BUY\", \"hash\":\"cba3be5e29eb5a3baecb3485bc911041b28f56ff\", \"best_bid\":\"0.55\", \"best_ask\":\"0.56\"}, {\"asset_id\":\"24254094493625419915756280046002869097156693848522361803041977572204227262166\", \"price\":\"0.99\", \"size\":\"5458.02\", \"side\":\"SELL\", \"hash\":\"d58efb8c71c7b3d0d1500c5191d1b0108105ba58\", \"best_bid\":\"0.44\", \"best_ask\":\"0.45\"}], \"timestamp\":\"1785122545818\", \"event_type\":\"price_change\"}","received_at":"2026-07-27T03:22:25.696036Z","schema_version":"clob-market-ws.price_change.v1","sequence":null,"server_hash":null,"server_timestamp":"1785122545818","session_id":"dd162b8dca5f43ff811d304e69a06123","source":"clob_market_ws"},"received_at":"2026-07-27T03:22:25.696036Z","record_id":"2dc71aacdb60192ac289faecf271b568634e377cb5b7166ee55b949e4caefe9f","schema_fingerprint":"4aa3821a28b0b7c2400bc59aba4bcc0a76e971dadd19610d3ad38c768e124dc7","schema_version":"edge-lab-recorder.raw.v1","sequence":null,"source":"clob_market_ws"}
{"event_at":"2026-07-27T03:22:25.847000Z","event_fingerprint":"b5d1606f6bfd46608c9be7140c04a0da72149d01f6e0360e2f9695486e40c38b","payload":{"connection_id":"c7dc2e4762f849c6b6f9306b6518dcab","event_at":"2026-07-27T03:22:25.847000Z","event_type":"price_change","frame_hash":"cdf97e33a72752c1b3bebc6e4b07ef8ec10f10c55ee19d7f7d1543050eb895ac","frame_index":0,"kind":"data","monotonic_ns":224529082385583,"payload":{"event_type":"price_change","market":"0x717c0e8ccd4d5c7040185188fbae28be901ca589a11a94b1b38ca36a79eccfeb","price_changes":[{"asset_id":"24254094493625419915756280046002869097156693848522361803041977572204227262166","best_ask":"0.45","best_bid":"0.44","hash":"aeda1b2df2de7fbed108c792187f20f5452f3520","price":"0.42","side":"BUY","size":"275"},{"asset_id":"41448400836309843603620980831210604935021861034693225347475867885462478926555","best_ask":"0.56","best_bid":"0.55","hash":"c4cfc15f2332988c7acd1a17f03f237a0fe426f2","price":"0.58","side":"SELL","size":"275"}],"timestamp":"1785122545847"},"payload_hash":"78447b774fbd5de99f04ed4a7d3111f56702fa5de83b2daef4863c2abe8d05dc","raw_frame":"{\"market\":\"0x717c0e8ccd4d5c7040185188fbae28be901ca589a11a94b1b38ca36a79eccfeb\", \"price_changes\":[{\"asset_id\":\"24254094493625419915756280046002869097156693848522361803041977572204227262166\", \"price\":\"0.42\", \"size\":\"275\", \"side\":\"BUY\", \"hash\":\"aeda1b2df2de7fbed108c792187f20f5452f3520\", \"best_bid\":\"0.44\", \"best_ask\":\"0.45\"}, {\"asset_id\":\"41448400836309843603620980831210604935021861034693225347475867885462478926555\", \"price\":\"0.58\", \"size\":\"275\", \"side\":\"SELL\", \"hash\":\"c4cfc15f2332988c7acd1a17f03f237a0fe426f2\", \"best_bid\":\"0.55\", \"best_ask\":\"0.56\"}], \"timestamp\":\"1785122545847\", \"event_type\":\"price_change\"}","received_at":"2026-07-27T03:22:25.726208Z","schema_version":"clob-market-ws.price_change.v1","sequence":null,"server_hash":null,"server_timestamp":"1785122545847","session_id":"dd162b8dca5f43ff811d304e69a06123","source":"clob_market_ws"},"received_at":"2026-07-27T03:22:25.726208Z","record_id":"dae5c271bc6ba69f5e6a873a5e3c5a4ac69a6b9549871e71a5081d05aeb4d3af","schema_fingerprint":"4aa3821a28b0b7c2400bc59aba4bcc0a76e971dadd19610d3ad38c768e124dc7","schema_version":"edge-lab-recorder.raw.v1","sequence":null,"source":"clob_market_ws"}
{"event_at":"2026-07-27T03:22:25.858000Z","event_fingerprint":"b5b2ff99d68bbe9f7fc1a947f18d51dc51c494a62727de6955830eb2abac26f5","payload":{"connection_id":"c7dc2e4762f849c6b6f9306b6518dcab","event_at":"2026-07-27T03:22:25.858000Z","event_type":"price_change","frame_hash":"1eb7d2dbcdf54567ed9f7ef1a1e72d06c547ccf89ef76cb3b451a27c31a3b423","frame_index":0,"kind":"data","monotonic_ns":224529090855166,"payload":{"event_type":"price_change","market":"0x717c0e8ccd4d5c7040185188fbae28be901ca589a11a94b1b38ca36a79eccfeb","price_changes":[{"asset_id":"41448400836309843603620980831210604935021861034693225347475867885462478926555","best_ask":"0.56","best_bid":"0.55","hash":"e71f5561c371b7912f7dfd31bb32b6a790064e67","price":"0.01","side":"BUY","size":"5463.02"},{"asset_id":"24254094493625419915756280046002869097156693848522361803041977572204227262166","best_ask":"0.45","best_bid":"0.44","hash":"63ab1e987eed823400c806c1e19f7a682937680f","price":"0.99","side":"SELL","size":"5463.02"}],"timestamp":"1785122545858"},"payload_hash":"354eb94cee433435ceca07612badba6bb9daafd3171f43fadc5bf0e3e775a1a8","raw_frame":"{\"market\":\"0x717c0e8ccd4d5c7040185188fbae28be901ca589a11a94b1b38ca36a79eccfeb\", \"price_changes\":[{\"asset_id\":\"41448400836309843603620980831210604935021861034693225347475867885462478926555\", \"price\":\"0.01\", \"size\":\"5463.02\", \"side\":\"BUY\", \"hash\":\"e71f5561c371b7912f7dfd31bb32b6a790064e67\", \"best_bid\":\"0.55\", \"best_ask\":\"0.56\"}, {\"asset_id\":\"24254094493625419915756280046002869097156693848522361803041977572204227262166\", \"price\":\"0.99\", \"size\":\"5463.02\", \"side\":\"SELL\", \"hash\":\"63ab1e987eed823400c806c1e19f7a682937680f\", \"best_bid\":\"0.44\", \"best_ask\":\"0.45\"}], \"timestamp\":\"1785122545858\", \"event_type\":\"price_change\"}","received_at":"2026-07-27T03:22:25.734680Z","schema_version":"clob-market-ws.price_change.v1","sequence":null,"server_hash":null,"server_timestamp":"1785122545858","session_id":"dd162b8dca5f43ff811d304e69a06123","source":"clob_market_ws"},"received_at":"2026-07-27T03:22:25.734680Z","record_id":"d35085206dbafd099aa6535eba2baee56ac9b37bfc23dd286dc42b3d34e3fa0e","schema_fingerprint":"4aa3821a28b0b7c2400bc59aba4bcc0a76e971dadd19610d3ad38c768e124dc7","schema_version":"edge-lab-recorder.raw.v1","sequence":null,"source":"clob_market_ws"}
{"event_at":"2026-07-27T03:22:25.873000Z","event_fingerprint":"0f2921b1aa414b970302c79ca3bde5739c7869072d563fd9d7ded6ab99e31ca7","payload":{"connection_id":"c7dc2e4762f849c6b6f9306b6518dcab","event_at":"2026-07-27T03:22:25.873000Z","event_type":"price_change","frame_hash":"f5e165e4dbd25964927f49a582e13386ebbfbc723edeaf7e2061663dd520f0ed","frame_index":0,"kind":"data","monotonic_ns":224529106627916,"payload":{"event_type":"price_change","market":"0x717c0e8ccd4d5c7040185188fbae28be901ca589a11a94b1b38ca36a79eccfeb","price_changes":[{"asset_id":"41448400836309843603620980831210604935021861034693225347475867885462478926555","best_ask":"0.56","best_bid":"0.55","hash":"7ca581de966c09bdc840345ba6a4061401f868a0","price":"0.01","side":"BUY","size":"5458.02"},{"asset_id":"24254094493625419915756280046002869097156693848522361803041977572204227262166","best_ask":"0.45","best_bid":"0.44","hash":"0bb7ec9a8d7d1ed6fa7eb7fce772388ee8786a29","price":"0.99","side":"SELL","size":"5458.02"}],"timestamp":"1785122545873"},"payload_hash":"ddfe48ecb36459e1453d5d497b94e6ca7d809df2e1f94906b5fae4b96a9b2c3a","raw_frame":"{\"market\":\"0x717c0e8ccd4d5c7040185188fbae28be901ca589a11a94b1b38ca36a79eccfeb\", \"price_changes\":[{\"asset_id\":\"41448400836309843603620980831210604935021861034693225347475867885462478926555\", \"price\":\"0.01\", \"size\":\"5458.02\", \"side\":\"BUY\", \"hash\":\"7ca581de966c09bdc840345ba6a4061401f868a0\", \"best_bid\":\"0.55\", \"best_ask\":\"0.56\"}, {\"asset_id\":\"24254094493625419915756280046002869097156693848522361803041977572204227262166\", \"price\":\"0.99\", \"size\":\"5458.02\", \"side\":\"SELL\", \"hash\":\"0bb7ec9a8d7d1ed6fa7eb7fce772388ee8786a29\", \"best_bid\":\"0.44\", \"best_ask\":\"0.45\"}], \"timestamp\":\"1785122545873\", \"event_type\":\"price_change\"}","received_at":"2026-07-27T03:22:25.750452Z","schema_version":"clob-market-ws.price_change.v1","sequence":null,"server_hash":null,"server_timestamp":"1785122545873","session_id":"dd162b8dca5f43ff811d304e69a06123","source":"clob_market_ws"},"received_at":"2026-07-27T03:22:25.750452Z","record_id":"fe2d30d9df910558fdf4ff8f6e0600955373deeab02ed9054ea4269257f76de3","schema_fingerprint":"4aa3821a28b0b7c2400bc59aba4bcc0a76e971dadd19610d3ad38c768e124dc7","schema_version":"edge-lab-recorder.raw.v1","sequence":null,"source":"clob_market_ws"}
{"event_at":"2026-07-27T03:22:25.881000Z","event_fingerprint":"818ca709d3cf5979bc3415e8f6148e8c38edf73f1b7612696deff48814e71682","payload":{"connection_id":"c7dc2e4762f849c6b6f9306b6518dcab","event_at":"2026-07-27T03:22:25.881000Z","event_type":"price_change","frame_hash":"420f680a81666ab1e0da07e57afec9f2f18caa31754de967b4c0b4da1a2024db","frame_index":0,"kind":"data","monotonic_ns":224529113675375,"payload":{"event_type":"price_change","market":"0x717c0e8ccd4d5c7040185188fbae28be901ca589a11a94b1b38ca36a79eccfeb","price_changes":[{"asset_id":"41448400836309843603620980831210604935021861034693225347475867885462478926555","best_ask":"0.56","best_bid":"0.55","hash":"393c0a0155c8ee0e85e7fcab086d712aedcb819f","price":"0.01","side":"BUY","size":"5453.02"},{"asset_id":"24254094493625419915756280046002869097156693848522361803041977572204227262166","best_ask":"0.45","best_bid":"0.44","hash":"27c8178c25f606509c3f808ca1035e0c02c9cddd","price":"0.99","side":"SELL","size":"5453.02"}],"timestamp":"1785122545881"},"payload_hash":"66dcb50b3cd5e81c0e59bd91b677eabb3b5e5f0f6ec55cb64e3d43ab632455da","raw_frame":"{\"market\":\"0x717c0e8ccd4d5c7040185188fbae28be901ca589a11a94b1b38ca36a79eccfeb\", \"price_changes\":[{\"asset_id\":\"41448400836309843603620980831210604935021861034693225347475867885462478926555\", \"price\":\"0.01\", \"size\":\"5453.02\", \"side\":\"BUY\", \"hash\":\"393c0a0155c8ee0e85e7fcab086d712aedcb819f\", \"best_bid\":\"0.55\", \"best_ask\":\"0.56\"}, {\"asset_id\":\"24254094493625419915756280046002869097156693848522361803041977572204227262166\", \"price\":\"0.99\", \"size\":\"5453.02\", \"side\":\"SELL\", \"hash\":\"27c8178c25f606509c3f808ca1035e0c02c9cddd\", \"best_bid\":\"0.44\", \"best_ask\":\"0.45\"}], \"timestamp\":\"1785122545881\", \"event_type\":\"price_change\"}","received_at":"2026-07-27T03:22:25.757499Z","schema_version":"clob-market-ws.price_change.v1","sequence":null,"server_hash":null,"server_timestamp":"1785122545881","session_id":"dd162b8dca5f43ff811d304e69a06123","source":"clob_market_ws"},"received_at":"2026-07-27T03:22:25.757499Z","record_id":"d76cbb1b2912c7c1b5fb9886734d3a59e96d1df3c38236ca80255448b8e2cdf0","schema_fingerprint":"4aa3821a28b0b7c2400bc59aba4bcc0a76e971dadd19610d3ad38c768e124dc7","schema_version":"edge-lab-recorder.raw.v1","sequence":null,"source":"clob_market_ws"}
{"event_at":"2026-07-27T03:22:25.881000Z","event_fingerprint":"bfa82806538e54ee8cf2b107103852a4d6846ad4e1d806a893bf629faf88bca0","payload":{"connection_id":"c7dc2e4762f849c6b6f9306b6518dcab","event_at":"2026-07-27T03:22:25.881000Z","event_type":"price_change","frame_hash":"96161c16fb4ce471ad2397e919f781af9624f1ad5fa1efc4eb365782940e998f","frame_index":0,"kind":"data","monotonic_ns":224529115276291,"payload":{"event_type":"price_change","market":"0x717c0e8ccd4d5c7040185188fbae28be901ca589a11a94b1b38ca36a79eccfeb","price_changes":[{"asset_id":"24254094493625419915756280046002869097156693848522361803041977572204227262166","best_ask":"0.45","best_bid":"0.44","hash":"fd081e5439c4b0218ec10e50cefe7bf1c5ea4cd7","price":"0.3","side":"BUY","size":"20.3"},{"asset_id":"41448400836309843603620980831210604935021861034693225347475867885462478926555","best_ask":"0.56","best_bid":"0.55","hash":"13e3b8b104ca695f5bd4226dfdb0b8d240e5ae12","price":"0.7","side":"SELL","size":"20.3"}],"timestamp":"1785122545881"},"payload_hash":"684ed770ad6977ad639edc0719c85726a275e6dc26b72d0ce5dd90d3b578d5cf","raw_frame":"{\"market\":\"0x717c0e8ccd4d5c7040185188fbae28be901ca589a11a94b1b38ca36a79eccfeb\", \"price_changes\":[{\"asset_id\":\"24254094493625419915756280046002869097156693848522361803041977572204227262166\", \"price\":\"0.3\", \"size\":\"20.3\", \"side\":\"BUY\", \"hash\":\"fd081e5439c4b0218ec10e50cefe7bf1c5ea4cd7\", \"best_bid\":\"0.44\", \"best_ask\":\"0.45\"}, {\"asset_id\":\"41448400836309843603620980831210604935021861034693225347475867885462478926555\", \"price\":\"0.7\", \"size\":\"20.3\", \"side\":\"SELL\", \"hash\":\"13e3b8b104ca695f5bd4226dfdb0b8d240e5ae12\", \"best_bid\":\"0.55\", \"best_ask\":\"0.56\"}], \"timestamp\":\"1785122545881\", \"event_type\":\"price_change\"}","received_at":"2026-07-27T03:22:25.759101Z","schema_version":"clob-market-ws.price_change.v1","sequence":null,"server_hash":null,"server_timestamp":"1785122545881","session_id":"dd162b8dca5f43ff811d304e69a06123","source":"clob_market_ws"},"received_at":"2026-07-27T03:22:25.759101Z","record_id":"2d0e883895303ad456f3ed6a8cf29511cee0ce8ea4179bfd74e2abc650d8322d","schema_fingerprint":"4aa3821a28b0b7c2400bc59aba4bcc0a76e971dadd19610d3ad38c768e124dc7","schema_version":"edge-lab-recorder.raw.v1","sequence":null,"source":"clob_market_ws"}
{"event_at":"2026-07-27T03:22:25.918000Z","event_fingerprint":"b74c158e2fcb3ab2bebb82bacb2876c449b90d978d66ef6d1291429696b2bc90","payload":{"connection_id":"c7dc2e4762f849c6b6f9306b6518dcab","event_at":"2026-07-27T03:22:25.918000Z","event_type":"price_change","frame_hash":"781d5d10183be6cf7a7fb40361a052bafbc05c9505cf9877e0518bf13a0b5efa","frame_index":0,"kind":"data","monotonic_ns":224529152376333,"payload":{"event_type":"price_change","market":"0x717c0e8ccd4d5c7040185188fbae28be901ca589a11a94b1b38ca36a79eccfeb","price_changes":[{"asset_id":"41448400836309843603620980831210604935021861034693225347475867885462478926555","best_ask":"0.56","best_bid":"0.55","hash":"c260e4cc1587567d13608b9ee0c6d6386798da76","price":"0.01","side":"BUY","size":"5458.02"},{"asset_id":"24254094493625419915756280046002869097156693848522361803041977572204227262166","best_ask":"0.45","best_bid":"0.44","hash":"eb2d92513c7355bf4d9f87d4411fb61bfe0980eb","price":"0.99","side":"SELL","size":"5458.02"}],"timestamp":"1785122545918"},"payload_hash":"3171ad96fe21796565f7d6dbcbaf1c2f6f7bbfebd1cc33f5c5334f94382e8266","raw_frame":"{\"market\":\"0x717c0e8ccd4d5c7040185188fbae28be901ca589a11a94b1b38ca36a79eccfeb\", \"price_changes\":[{\"asset_id\":\"41448400836309843603620980831210604935021861034693225347475867885462478926555\", \"price\":\"0.01\", \"size\":\"5458.02\", \"side\":\"BUY\", \"hash\":\"c260e4cc1587567d13608b9ee0c6d6386798da76\", \"best_bid\":\"0.55\", \"best_ask\":\"0.56\"}, {\"asset_id\":\"24254094493625419915756280046002869097156693848522361803041977572204227262166\", \"price\":\"0.99\", \"size\":\"5458.02\", \"side\":\"SELL\", \"hash\":\"eb2d92513c7355bf4d9f87d4411fb61bfe0980eb\", \"best_bid\":\"0.44\", \"best_ask\":\"0.45\"}], \"timestamp\":\"1785122545918\", \"event_type\":\"price_change\"}","received_at":"2026-07-27T03:22:25.796206Z","schema_version":"clob-market-ws.price_change.v1","sequence":null,"server_hash":null,"server_timestamp":"1785122545918","session_id":"dd162b8dca5f43ff811d304e69a06123","source":"clob_market_ws"},"received_at":"2026-07-27T03:22:25.796206Z","record_id":"ffe5a0fa52d1efc0633a5e2c23b13ccdc3604081d6b243178084b7096ad1c197","schema_fingerprint":"4aa3821a28b0b7c2400bc59aba4bcc0a76e971dadd19610d3ad38c768e124dc7","schema_version":"edge-lab-recorder.raw.v1","sequence":null,"source":"clob_market_ws"}
{"event_at":"2026-07-27T03:22:25.940000Z","event_fingerprint":"7177cc6b3548d9fa613007c716f12430e5993d3e24531d56f792723de84fbd67","payload":{"connection_id":"c7dc2e4762f849c6b6f9306b6518dcab","event_at":"2026-07-27T03:22:25.940000Z","event_type":"price_change","frame_hash":"bd9d3f60e8fd4e9703c8b5503eb04620abe8153eda12b659c27f91e4093113b5","frame_index":0,"kind":"data","monotonic_ns":224529179297583,"payload":{"event_type":"price_change","market":"0x717c0e8ccd4d5c7040185188fbae28be901ca589a11a94b1b38ca36a79eccfeb","price_changes":[{"asset_id":"41448400836309843603620980831210604935021861034693225347475867885462478926555","best_ask":"0.56","best_bid":"0.55","hash":"2e34d58f887031a1802602b532ff0f1a3f8dadfb","price":"0.01","side":"BUY","size":"5453.02"},{"asset_id":"24254094493625419915756280046002869097156693848522361803041977572204227262166","best_ask":"0.45","best_bid":"0.44","hash":"c83d843a65c19c0bdba6ae8b94b24ad6092ce982","price":"0.99","side":"SELL","size":"5453.02"}],"timestamp":"1785122545940"},"payload_hash":"704e8ef2ee7c7fe3c02924e6084fa991bb7bfc3ee0002666952f3bc83a326e63","raw_frame":"{\"market\":\"0x717c0e8ccd4d5c7040185188fbae28be901ca589a11a94b1b38ca36a79eccfeb\", \"price_changes\":[{\"asset_id\":\"41448400836309843603620980831210604935021861034693225347475867885462478926555\", \"price\":\"0.01\", \"size\":\"5453.02\", \"side\":\"BUY\", \"hash\":\"2e34d58f887031a1802602b532ff0f1a3f8dadfb\", \"best_bid\":\"0.55\", \"best_ask\":\"0.56\"}, {\"asset_id\":\"24254094493625419915756280046002869097156693848522361803041977572204227262166\", \"price\":\"0.99\", \"size\":\"5453.02\", \"side\":\"SELL\", \"hash\":\"c83d843a65c19c0bdba6ae8b94b24ad6092ce982\", \"best_bid\":\"0.44\", \"best_ask\":\"0.45\"}], \"timestamp\":\"1785122545940\", \"event_type\":\"price_change\"}","received_at":"2026-07-27T03:22:25.823121Z","schema_version":"clob-market-ws.price_change.v1","sequence":null,"server_hash":null,"server_timestamp":"1785122545940","session_id":"dd162b8dca5f43ff811d304e69a06123","source":"clob_market_ws"},"received_at":"2026-07-27T03:22:25.823121Z","record_id":"718e99e3ee6c943562cf47d933691786355f54d4a2e7d6c255afc4233862c387","schema_fingerprint":"4aa3821a28b0b7c2400bc59aba4bcc0a76e971dadd19610d3ad38c768e124dc7","schema_version":"edge-lab-recorder.raw.v1","sequence":null,"source":"clob_market_ws"}
{"event_at":"2026-07-27T03:22:25.967000Z","event_fingerprint":"e70f8c9ad2755307ff428d9b836affdd56c1cc2f6dc12b4ac41cb064ecffcf7a","payload":{"connection_id":"c7dc2e4762f849c6b6f9306b6518dcab","event_at":"2026-07-27T03:22:25.967000Z","event_type":"price_change","frame_hash":"8211ad922f64f1dc9e03fea4b8836d4d97128e1ac3a29b187e4905d08535aab2","frame_index":0,"kind":"data","monotonic_ns":224529202203416,"payload":{"event_type":"price_change","market":"0x717c0e8ccd4d5c7040185188fbae28be901ca589a11a94b1b38ca36a79eccfeb","price_changes":[{"asset_id":"41448400836309843603620980831210604935021861034693225347475867885462478926555","best_ask":"0.56","best_bid":"0.55","hash":"0fa07e0531da9b6191e5c466fc9176e9703ed92a","price":"0.01","side":"BUY","size":"5458.02"},{"asset_id":"24254094493625419915756280046002869097156693848522361803041977572204227262166","best_ask":"0.45","best_bid":"0.44","hash":"0227c5115bca88e6d52aa96a6b5b21e763427e4c","price":"0.99","side":"SELL","size":"5458.02"}],"timestamp":"1785122545967"},"payload_hash":"cdc0dc38b6d63d532db115205e11b2fc81a5d9e7a79a1c2c0f9858499126487e","raw_frame":"{\"market\":\"0x717c0e8ccd4d5c7040185188fbae28be901ca589a11a94b1b38ca36a79eccfeb\", \"price_changes\":[{\"asset_id\":\"41448400836309843603620980831210604935021861034693225347475867885462478926555\", \"price\":\"0.01\", \"size\":\"5458.02\", \"side\":\"BUY\", \"hash\":\"0fa07e0531da9b6191e5c466fc9176e9703ed92a\", \"best_bid\":\"0.55\", \"best_ask\":\"0.56\"}, {\"asset_id\":\"24254094493625419915756280046002869097156693848522361803041977572204227262166\", \"price\":\"0.99\", \"size\":\"5458.02\", \"side\":\"SELL\", \"hash\":\"0227c5115bca88e6d52aa96a6b5b21e763427e4c\", \"best_bid\":\"0.44\", \"best_ask\":\"0.45\"}], \"timestamp\":\"1785122545967\", \"event_type\":\"price_change\"}","received_at":"2026-07-27T03:22:25.846029Z","schema_version":"clob-market-ws.price_change.v1","sequence":null,"server_hash":null,"server_timestamp":"1785122545967","session_id":"dd162b8dca5f43ff811d304e69a06123","source":"clob_market_ws"},"received_at":"2026-07-27T03:22:25.846029Z","record_id":"b0cd74e17d251c99b0ca8f7989d2ddda01879c905ead3c3484b9b537b646ecf4","schema_fingerprint":"4aa3821a28b0b7c2400bc59aba4bcc0a76e971dadd19610d3ad38c768e124dc7","schema_version":"edge-lab-recorder.raw.v1","sequence":null,"source":"clob_market_ws"}
{"event_at":"2026-07-27T03:22:26.010000Z","event_fingerprint":"b14e6f2621c333a77b399a0d56e9f5849825887650b8a7c6eef6da77581ca2e5","payload":{"connection_id":"c7dc2e4762f849c6b6f9306b6518dcab","event_at":"2026-07-27T03:22:26.010000Z","event_type":"price_change","frame_hash":"6674dcc69fcf060ab0549bfe01dd3dc2e4ab68c6419cb589e83072a687cef0a5","frame_index":0,"kind":"data","monotonic_ns":224529246403291,"payload":{"event_type":"price_change","market":"0x717c0e8ccd4d5c7040185188fbae28be901ca589a11a94b1b38ca36a79eccfeb","price_changes":[{"asset_id":"41448400836309843603620980831210604935021861034693225347475867885462478926555","best_ask":"0.56","best_bid":"0.55","hash":"19430186e7954185ce3f2b51dcc087a26fa891e6","price":"0.46","side":"BUY","size":"13"},{"asset_id":"24254094493625419915756280046002869097156693848522361803041977572204227262166","best_ask":"0.45","best_bid":"0.44","hash":"98c90dd5c549d96b647012201bf266e0825e2ff1","price":"0.54","side":"SELL","size":"13"}],"timestamp":"1785122546010"},"payload_hash":"307d84c22435ab7ae828b2dae5122fec3c4df816e0b5cbaaf16abcf051d27b89","raw_frame":"{\"market\":\"0x717c0e8ccd4d5c7040185188fbae28be901ca589a11a94b1b38ca36a79eccfeb\", \"price_changes\":[{\"asset_id\":\"41448400836309843603620980831210604935021861034693225347475867885462478926555\", \"price\":\"0.46\", \"size\":\"13\", \"side\":\"BUY\", \"hash\":\"19430186e7954185ce3f2b51dcc087a26fa891e6\", \"best_bid\":\"0.55\", \"best_ask\":\"0.56\"}, {\"asset_id\":\"24254094493625419915756280046002869097156693848522361803041977572204227262166\", \"price\":\"0.54\", \"size\":\"13\", \"side\":\"SELL\", \"hash\":\"98c90dd5c549d96b647012201bf266e0825e2ff1\", \"best_bid\":\"0.44\", \"best_ask\":\"0.45\"}], \"timestamp\":\"1785122546010\", \"event_type\":\"price_change\"}","received_at":"2026-07-27T03:22:25.890226Z","schema_version":"clob-market-ws.price_change.v1","sequence":null,"server_hash":null,"server_timestamp":"1785122546010","session_id":"dd162b8dca5f43ff811d304e69a06123","source":"clob_market_ws"},"received_at":"2026-07-27T03:22:25.890226Z","record_id":"1d287392d5ea2d6bbb0a75de3e1553cb50270e8b4a4f8ad0fac11dd394542e98","schema_fingerprint":"4aa3821a28b0b7c2400bc59aba4bcc0a76e971dadd19610d3ad38c768e124dc7","schema_version":"edge-lab-recorder.raw.v1","sequence":null,"source":"clob_market_ws"}
{"event_at":"2026-07-27T03:22:26.018000Z","event_fingerprint":"0a84aa5d782dce20795102289b516d304979a04bf794f8529e99aff134310f6f","payload":{"connection_id":"c7dc2e4762f849c6b6f9306b6518dcab","event_at":"2026-07-27T03:22:26.018000Z","event_type":"price_change","frame_hash":"df8cf333c76e0c704a924661bad01bbd7d7d81318b99ff5400779ea879af9577","frame_index":0,"kind":"data","monotonic_ns":224529253877291,"payload":{"event_type":"price_change","market":"0x717c0e8ccd4d5c7040185188fbae28be901ca589a11a94b1b38ca36a79eccfeb","price_changes":[{"asset_id":"41448400836309843603620980831210604935021861034693225347475867885462478926555","best_ask":"0.56","best_bid":"0.55","hash":"ac0210f0d75061d22710ba7c7598291017c8b032","price":"0.01","side":"BUY","size":"5453.02"},{"asset_id":"24254094493625419915756280046002869097156693848522361803041977572204227262166","best_ask":"0.45","best_bid":"0.44","hash":"c9975d1b0141d18217fe7eb7b4374cc7398365a7","price":"0.99","side":"SELL","size":"5453.02"}],"timestamp":"1785122546018"},"payload_hash":"0ae1d817f9636fec3480293c5ecc3b6cdcdc428b0c8ac87fbe16a2347bdb8862","raw_frame":"{\"market\":\"0x717c0e8ccd4d5c7040185188fbae28be901ca589a11a94b1b38ca36a79eccfeb\", \"price_changes\":[{\"asset_id\":\"41448400836309843603620980831210604935021861034693225347475867885462478926555\", \"price\":\"0.01\", \"size\":\"5453.02\", \"side\":\"BUY\", \"hash\":\"ac0210f0d75061d22710ba7c7598291017c8b032\", \"best_bid\":\"0.55\", \"best_ask\":\"0.56\"}, {\"asset_id\":\"24254094493625419915756280046002869097156693848522361803041977572204227262166\", \"price\":\"0.99\", \"size\":\"5453.02\", \"side\":\"SELL\", \"hash\":\"c9975d1b0141d18217fe7eb7b4374cc7398365a7\", \"best_bid\":\"0.44\", \"best_ask\":\"0.45\"}], \"timestamp\":\"1785122546018\", \"event_type\":\"price_change\"}","received_at":"2026-07-27T03:22:25.897702Z","schema_version":"clob-market-ws.price_change.v1","sequence":null,"server_hash":null,"server_timestamp":"1785122546018","session_id":"dd162b8dca5f43ff811d304e69a06123","source":"clob_market_ws"},"received_at":"2026-07-27T03:22:25.897702Z","record_id":"5928407b8ae25a8a219684ae097e3fa3bf079dcf56456307cfc6a4fff8123a0a","schema_fingerprint":"4aa3821a28b0b7c2400bc59aba4bcc0a76e971dadd19610d3ad38c768e124dc7","schema_version":"edge-lab-recorder.raw.v1","sequence":null,"source":"clob_market_ws"}
{"event_at":"2026-07-27T03:22:26.022000Z","event_fingerprint":"a6a6feb747d8586549981c99862b48eb75a7b767760dcf219c9341348e5db2ba","payload":{"connection_id":"c7dc2e4762f849c6b6f9306b6518dcab","event_at":"2026-07-27T03:22:26.022000Z","event_type":"price_change","frame_hash":"f8d35d772fb40cc29ab674ceb576d12da9eaf0f8080daa85b14b7cd1f8ae52c0","frame_index":0,"kind":"data","monotonic_ns":224529257163125,"payload":{"event_type":"price_change","market":"0x717c0e8ccd4d5c7040185188fbae28be901ca589a11a94b1b38ca36a79eccfeb","price_changes":[{"asset_id":"24254094493625419915756280046002869097156693848522361803041977572204227262166","best_ask":"0.45","best_bid":"0.44","hash":"6d6569daab1747262ce9382d2ad9402dfd7f7aab","price":"0.01","side":"BUY","size":"5458.02"},{"asset_id":"41448400836309843603620980831210604935021861034693225347475867885462478926555","best_ask":"0.56","best_bid":"0.55","hash":"db84132121b668e250dd3ce409308f28cf9bbe0b","price":"0.99","side":"SELL","size":"5458.02"}],"timestamp":"1785122546022"},"payload_hash":"421f6b61d357f200c9476c5f519fd646294c76c364fc8572bbe5beaab5609fc9","raw_frame":"{\"market\":\"0x717c0e8ccd4d5c7040185188fbae28be901ca589a11a94b1b38ca36a79eccfeb\", \"price_changes\":[{\"asset_id\":\"24254094493625419915756280046002869097156693848522361803041977572204227262166\", \"price\":\"0.01\", \"size\":\"5458.02\", \"side\":\"BUY\", \"hash\":\"6d6569daab1747262ce9382d2ad9402dfd7f7aab\", \"best_bid\":\"0.44\", \"best_ask\":\"0.45\"}, {\"asset_id\":\"41448400836309843603620980831210604935021861034693225347475867885462478926555\", \"price\":\"0.99\", \"size\":\"5458.02\", \"side\":\"SELL\", \"hash\":\"db84132121b668e250dd3ce409308f28cf9bbe0b\", \"best_bid\":\"0.55\", \"best_ask\":\"0.56\"}], \"timestamp\":\"1785122546022\", \"event_type\":\"price_change\"}","received_at":"2026-07-27T03:22:25.900988Z","schema_version":"clob-market-ws.price_change.v1","sequence":null,"server_hash":null,"server_timestamp":"1785122546022","session_id":"dd162b8dca5f43ff811d304e69a06123","source":"clob_market_ws"},"received_at":"2026-07-27T03:22:25.900988Z","record_id":"a089cbb93897c8a99246b1941986420fed8b94a224abb825e027403c18e2d330","schema_fingerprint":"4aa3821a28b0b7c2400bc59aba4bcc0a76e971dadd19610d3ad38c768e124dc7","schema_version":"edge-lab-recorder.raw.v1","sequence":null,"source":"clob_market_ws"}
{"event_at":"2026-07-27T03:22:26.022000Z","event_fingerprint":"c912489425b197e4fe07ee3d2c4445d8b97710a4659bd43c813985ef18c2307b","payload":{"connection_id":"c7dc2e4762f849c6b6f9306b6518dcab","event_at":"2026-07-27T03:22:26.022000Z","event_type":"price_change","frame_hash":"6e92a3776a72199c0af47247a3c232aa084d8d4817272ae3a761ecead1e5a730","frame_index":0,"kind":"data","monotonic_ns":224529260308791,"payload":{"event_type":"price_change","market":"0x717c0e8ccd4d5c7040185188fbae28be901ca589a11a94b1b38ca36a79eccfeb","price_changes":[{"asset_id":"24254094493625419915756280046002869097156693848522361803041977572204227262166","best_ask":"0.45","best_bid":"0.44","hash":"a032976000cf429ddfe9d4dafeddbb1faf02bddb","price":"0.01","side":"BUY","size":"5463.02"},{"asset_id":"41448400836309843603620980831210604935021861034693225347475867885462478926555","best_ask":"0.56","best_bid":"0.55","hash":"9fa1bd5af563118e130e4d535e60b6ce939604c0","price":"0.99","side":"SELL","size":"5463.02"}],"timestamp":"1785122546022"},"payload_hash":"d0f3fcc2d6a67c498b16ef87b6471680b77c532b02c7c164a1235e35dd2a3509","raw_frame":"{\"market\":\"0x717c0e8ccd4d5c7040185188fbae28be901ca589a11a94b1b38ca36a79eccfeb\", \"price_changes\":[{\"asset_id\":\"24254094493625419915756280046002869097156693848522361803041977572204227262166\", \"price\":\"0.01\", \"size\":\"5463.02\", \"side\":\"BUY\", \"hash\":\"a032976000cf429ddfe9d4dafeddbb1faf02bddb\", \"best_bid\":\"0.44\", \"best_ask\":\"0.45\"}, {\"asset_id\":\"41448400836309843603620980831210604935021861034693225347475867885462478926555\", \"price\":\"0.99\", \"size\":\"5463.02\", \"side\":\"SELL\", \"hash\":\"9fa1bd5af563118e130e4d535e60b6ce939604c0\", \"best_bid\":\"0.55\", \"best_ask\":\"0.56\"}], \"timestamp\":\"1785122546022\", \"event_type\":\"price_change\"}","received_at":"2026-07-27T03:22:25.904133Z","schema_version":"clob-market-ws.price_change.v1","sequence":null,"server_hash":null,"server_timestamp":"1785122546022","session_id":"dd162b8dca5f43ff811d304e69a06123","source":"clob_market_ws"},"received_at":"2026-07-27T03:22:25.904133Z","record_id":"ed176aa64709533dcf2b607a7f0c58b0111b9d19d36ab791d135c4af63a4bd2c","schema_fingerprint":"4aa3821a28b0b7c2400bc59aba4bcc0a76e971dadd19610d3ad38c768e124dc7","schema_version":"edge-lab-recorder.raw.v1","sequence":null,"source":"clob_market_ws"}
{"event_at":"2026-07-27T03:22:26.045000Z","event_fingerprint":"9fa0e63e0218135e9edd0870dce453785e35d713b9ba4790efa4100461d892b7","payload":{"connection_id":"c7dc2e4762f849c6b6f9306b6518dcab","event_at":"2026-07-27T03:22:26.045000Z","event_type":"price_change","frame_hash":"ed5bca3cae4c00be14888d66539719ef65e82ee279c79f2336f587adcaa6c8bb","frame_index":0,"kind":"data","monotonic_ns":224529278207625,"payload":{"event_type":"price_change","market":"0x717c0e8ccd4d5c7040185188fbae28be901ca589a11a94b1b38ca36a79eccfeb","price_changes":[{"asset_id":"24254094493625419915756280046002869097156693848522361803041977572204227262166","best_ask":"0.45","best_bid":"0.44","hash":"c754ef84be39825bc8e47a6e71b1a78afd96f394","price":"0.01","side":"BUY","size":"5458.02"},{"asset_id":"41448400836309843603620980831210604935021861034693225347475867885462478926555","best_ask":"0.56","best_bid":"0.55","hash":"cc89b3e5c8e818ab3ccb5f38a816e9d8232c65ac","price":"0.99","side":"SELL","size":"5458.02"}],"timestamp":"1785122546045"},"payload_hash":"057e116d41cbfb503ba8feeb625d4c0305d78d4c9df2ef7e785766e7dad4404f","raw_frame":"{\"market\":\"0x717c0e8ccd4d5c7040185188fbae28be901ca589a11a94b1b38ca36a79eccfeb\", \"price_changes\":[{\"asset_id\":\"24254094493625419915756280046002869097156693848522361803041977572204227262166\", \"price\":\"0.01\", \"size\":\"5458.02\", \"side\":\"BUY\", \"hash\":\"c754ef84be39825bc8e47a6e71b1a78afd96f394\", \"best_bid\":\"0.44\", \"best_ask\":\"0.45\"}, {\"asset_id\":\"41448400836309843603620980831210604935021861034693225347475867885462478926555\", \"price\":\"0.99\", \"size\":\"5458.02\", \"side\":\"SELL\", \"hash\":\"cc89b3e5c8e818ab3ccb5f38a816e9d8232c65ac\", \"best_bid\":\"0.55\", \"best_ask\":\"0.56\"}], \"timestamp\":\"1785122546045\", \"event_type\":\"price_change\"}","received_at":"2026-07-27T03:22:25.922030Z","schema_version":"clob-market-ws.price_change.v1","sequence":null,"server_hash":null,"server_timestamp":"1785122546045","session_id":"dd162b8dca5f43ff811d304e69a06123","source":"clob_market_ws"},"received_at":"2026-07-27T03:22:25.922030Z","record_id":"1888a363c87f94bccc56481b36af22022dbb5a3cb42eab3c8c74dd5755b7143e","schema_fingerprint":"4aa3821a28b0b7c2400bc59aba4bcc0a76e971dadd19610d3ad38c768e124dc7","schema_version":"edge-lab-recorder.raw.v1","sequence":null,"source":"clob_market_ws"}
{"event_at":"2026-07-27T03:22:26.054000Z","event_fingerprint":"8d108a8a96cbdbc8de1ea50e4a81eaa7e604e6cc10ce9693a7c5e66f5ab81f17","payload":{"connection_id":"c7dc2e4762f849c6b6f9306b6518dcab","event_at":"2026-07-27T03:22:26.054000Z","event_type":"price_change","frame_hash":"3fddcaeeeb56066a8a7e6cc5761fb37e2f6fb7770a5c7b5c4ccf533197bdd005","frame_index":0,"kind":"data","monotonic_ns":224529289711583,"payload":{"event_type":"price_change","market":"0x717c0e8ccd4d5c7040185188fbae28be901ca589a11a94b1b38ca36a79eccfeb","price_changes":[{"asset_id":"41448400836309843603620980831210604935021861034693225347475867885462478926555","best_ask":"0.56","best_bid":"0.55","hash":"fa7b328c535f6b0a01d023f0b0803c93a37d61f5","price":"0.43","side":"BUY","size":"117.2"},{"asset_id":"24254094493625419915756280046002869097156693848522361803041977572204227262166","best_ask":"0.45","best_bid":"0.44","hash":"789ac2918378be4d2860ceed02e97627084876bf","price":"0.57","side":"SELL","size":"117.2"}],"timestamp":"1785122546054"},"payload_hash":"a54fa598b7ab57627e2c0a8f152602beed2e9400f82e3b75d1c347145c858bd5","raw_frame":"{\"market\":\"0x717c0e8ccd4d5c7040185188fbae28be901ca589a11a94b1b38ca36a79eccfeb\", \"price_changes\":[{\"asset_id\":\"41448400836309843603620980831210604935021861034693225347475867885462478926555\", \"price\":\"0.43\", \"size\":\"117.2\", \"side\":\"BUY\", \"hash\":\"fa7b328c535f6b0a01d023f0b0803c93a37d61f5\", \"best_bid\":\"0.55\", \"best_ask\":\"0.56\"}, {\"asset_id\":\"24254094493625419915756280046002869097156693848522361803041977572204227262166\", \"price\":\"0.57\", \"size\":\"117.2\", \"side\":\"SELL\", \"hash\":\"789ac2918378be4d2860ceed02e97627084876bf\", \"best_bid\":\"0.44\", \"best_ask\":\"0.45\"}], \"timestamp\":\"1785122546054\", \"event_type\":\"price_change\"}","received_at":"2026-07-27T03:22:25.933535Z","schema_version":"clob-market-ws.price_change.v1","sequence":null,"server_hash":null,"server_timestamp":"1785122546054","session_id":"dd162b8dca5f43ff811d304e69a06123","source":"clob_market_ws"},"received_at":"2026-07-27T03:22:25.933535Z","record_id":"d8b5d4aa1acfd8621ab12718206248b46c296d852201de0d3d00df65ff4c4ec0","schema_fingerprint":"4aa3821a28b0b7c2400bc59aba4bcc0a76e971dadd19610d3ad38c768e124dc7","schema_version":"edge-lab-recorder.raw.v1","sequence":null,"source":"clob_market_ws"}
{"event_at":"2026-07-27T03:22:26.058000Z","event_fingerprint":"29b92c38293a16727524977e5b6dadbbc1dcfd167e6ae9ea679d5231aa2593ed","payload":{"connection_id":"c7dc2e4762f849c6b6f9306b6518dcab","event_at":"2026-07-27T03:22:26.058000Z","event_type":"price_change","frame_hash":"50c185eed846d4a26b9826a78961fea2827d6f89e38479a25a0fa15a8b982b54","frame_index":0,"kind":"data","monotonic_ns":224529292824416,"payload":{"event_type":"price_change","market":"0x717c0e8ccd4d5c7040185188fbae28be901ca589a11a94b1b38ca36a79eccfeb","price_changes":[{"asset_id":"24254094493625419915756280046002869097156693848522361803041977572204227262166","best_ask":"0.45","best_bid":"0.44","hash":"fffcfa1e99e71d396757d8e67bcdedcef5a05baa","price":"0.4","side":"BUY","size":"10"},{"asset_id":"41448400836309843603620980831210604935021861034693225347475867885462478926555","best_ask":"0.56","best_bid":"0.55","hash":"d1aa9df1bc839b1f84f1ec047c0b3acbf6f09248","price":"0.6","side":"SELL","size":"10"}],"timestamp":"1785122546058"},"payload_hash":"ce7a2488e955c9c0291701bfe5f80ad7501a1159945159de6944b4466de87ba8","raw_frame":"{\"market\":\"0x717c0e8ccd4d5c7040185188fbae28be901ca589a11a94b1b38ca36a79eccfeb\", \"price_changes\":[{\"asset_id\":\"24254094493625419915756280046002869097156693848522361803041977572204227262166\", \"price\":\"0.4\", \"size\":\"10\", \"side\":\"BUY\", \"hash\":\"fffcfa1e99e71d396757d8e67bcdedcef5a05baa\", \"best_bid\":\"0.44\", \"best_ask\":\"0.45\"}, {\"asset_id\":\"41448400836309843603620980831210604935021861034693225347475867885462478926555\", \"price\":\"0.6\", \"size\":\"10\", \"side\":\"SELL\", \"hash\":\"d1aa9df1bc839b1f84f1ec047c0b3acbf6f09248\", \"best_bid\":\"0.55\", \"best_ask\":\"0.56\"}], \"timestamp\":\"1785122546058\", \"event_type\":\"price_change\"}","received_at":"2026-07-27T03:22:25.936648Z","schema_version":"clob-market-ws.price_change.v1","sequence":null,"server_hash":null,"server_timestamp":"1785122546058","session_id":"dd162b8dca5f43ff811d304e69a06123","source":"clob_market_ws"},"received_at":"2026-07-27T03:22:25.936648Z","record_id":"42f404ed6a9ebaacb7eca8aa0bfddeadf0c1327f891139b9f88e6631b3da1915","schema_fingerprint":"4aa3821a28b0b7c2400bc59aba4bcc0a76e971dadd19610d3ad38c768e124dc7","schema_version":"edge-lab-recorder.raw.v1","sequence":null,"source":"clob_market_ws"}
{"event_at":"2026-07-27T03:22:26.060000Z","event_fingerprint":"67450bdc1cfa3511458669a9097987c9beaa6f7ba77c67e64445be2104a81467","payload":{"connection_id":"c7dc2e4762f849c6b6f9306b6518dcab","event_at":"2026-07-27T03:22:26.060000Z","event_type":"price_change","frame_hash":"1cc93ec166f98936843db63f63050b3f5c2c0f039b718d3ed9ee1779fa05989a","frame_index":0,"kind":"data","monotonic_ns":224529294725083,"payload":{"event_type":"price_change","market":"0x717c0e8ccd4d5c7040185188fbae28be901ca589a11a94b1b38ca36a79eccfeb","price_changes":[{"asset_id":"24254094493625419915756280046002869097156693848522361803041977572204227262166","best_ask":"0.45","best_bid":"0.44","hash":"2a73df8d08c34a55e53a3ca01161fb14892aa291","price":"0.42","side":"BUY","size":"270"},{"asset_id":"41448400836309843603620980831210604935021861034693225347475867885462478926555","best_ask":"0.56","best_bid":"0.55","hash":"6e211d46af58e69204d7914973c5f7cd04d2a614","price":"0.58","side":"SELL","size":"270"}],"timestamp":"1785122546060"},"payload_hash":"a00d9398dd946b0f5ba0de55cbd41605c1d56fb59ec541e6c6ffe726d48e2dbe","raw_frame":"{\"market\":\"0x717c0e8ccd4d5c7040185188fbae28be901ca589a11a94b1b38ca36a79eccfeb\", \"price_changes\":[{\"asset_id\":\"24254094493625419915756280046002869097156693848522361803041977572204227262166\", \"price\":\"0.42\", \"size\":\"270\", \"side\":\"BUY\", \"hash\":\"2a73df8d08c34a55e53a3ca01161fb14892aa291\", \"best_bid\":\"0.44\", \"best_ask\":\"0.45\"}, {\"asset_id\":\"41448400836309843603620980831210604935021861034693225347475867885462478926555\", \"price\":\"0.58\", \"size\":\"270\", \"side\":\"SELL\", \"hash\":\"6e211d46af58e69204d7914973c5f7cd04d2a614\", \"best_bid\":\"0.55\", \"best_ask\":\"0.56\"}], \"timestamp\":\"1785122546060\", \"event_type\":\"price_change\"}","received_at":"2026-07-27T03:22:25.938547Z","schema_version":"clob-market-ws.price_change.v1","sequence":null,"server_hash":null,"server_timestamp":"1785122546060","session_id":"dd162b8dca5f43ff811d304e69a06123","source":"clob_market_ws"},"received_at":"2026-07-27T03:22:25.938547Z","record_id":"00993fcd38afdce58264acaf11ecd4b278376979660e40a06f54148d69f843a6","schema_fingerprint":"4aa3821a28b0b7c2400bc59aba4bcc0a76e971dadd19610d3ad38c768e124dc7","schema_version":"edge-lab-recorder.raw.v1","sequence":null,"source":"clob_market_ws"}
{"event_at":"2026-07-27T03:22:26.060000Z","event_fingerprint":"d5ed061294af27ba885a0318196be9782408bf53f37a16a637d3e7f15c5b30ff","payload":{"connection_id":"c7dc2e4762f849c6b6f9306b6518dcab","event_at":"2026-07-27T03:22:26.060000Z","event_type":"price_change","frame_hash":"0d0c0be86bdf6904c839755f3ab213d7d8e84e77327e7fc015c9bf398dba6e60","frame_index":0,"kind":"data","monotonic_ns":224529297727208,"payload":{"event_type":"price_change","market":"0x717c0e8ccd4d5c7040185188fbae28be901ca589a11a94b1b38ca36a79eccfeb","price_changes":[{"asset_id":"41448400836309843603620980831210604935021861034693225347475867885462478926555","best_ask":"0.56","best_bid":"0.55","hash":"8ba2b0c506d7aa3dda7130028d33961da4bc58b4","price":"0.44","side":"BUY","size":"235"},{"asset_id":"24254094493625419915756280046002869097156693848522361803041977572204227262166","best_ask":"0.45","best_bid":"0.44","hash":"f0d8e184a21704d2bb22a5521d48c5160c10fb46","price":"0.56","side":"SELL","size":"235"}],"timestamp":"1785122546060"},"payload_hash":"2f6c8f74c07aa3dde01377369fdff6cce56e14293330b1610adfb8da90164d58","raw_frame":"{\"market\":\"0x717c0e8ccd4d5c7040185188fbae28be901ca589a11a94b1b38ca36a79eccfeb\", \"price_changes\":[{\"asset_id\":\"41448400836309843603620980831210604935021861034693225347475867885462478926555\", \"price\":\"0.44\", \"size\":\"235\", \"side\":\"BUY\", \"hash\":\"8ba2b0c506d7aa3dda7130028d33961da4bc58b4\", \"best_bid\":\"0.55\", \"best_ask\":\"0.56\"}, {\"asset_id\":\"24254094493625419915756280046002869097156693848522361803041977572204227262166\", \"price\":\"0.56\", \"size\":\"235\", \"side\":\"SELL\", \"hash\":\"f0d8e184a21704d2bb22a5521d48c5160c10fb46\", \"best_bid\":\"0.44\", \"best_ask\":\"0.45\"}], \"timestamp\":\"1785122546060\", \"event_type\":\"price_change\"}","received_at":"2026-07-27T03:22:25.941551Z","schema_version":"clob-market-ws.price_change.v1","sequence":null,"server_hash":null,"server_timestamp":"1785122546060","session_id":"dd162b8dca5f43ff811d304e69a06123","source":"clob_market_ws"},"received_at":"2026-07-27T03:22:25.941551Z","record_id":"def51b8b780ffaa6633982c57baec74c59a9863c3e8afd63c1a81857c67d148c","schema_fingerprint":"4aa3821a28b0b7c2400bc59aba4bcc0a76e971dadd19610d3ad38c768e124dc7","schema_version":"edge-lab-recorder.raw.v1","sequence":null,"source":"clob_market_ws"}
{"event_at":"2026-07-27T03:22:26.063000Z","event_fingerprint":"ad6c8859f349f6f09e917f1d4026586ccf40ea05690156492e56f262c5aadf50","payload":{"connection_id":"c7dc2e4762f849c6b6f9306b6518dcab","event_at":"2026-07-27T03:22:26.063000Z","event_type":"price_change","frame_hash":"3f241d1e7bb044a285f773a0f0ac1febf7e7d81b1cba1d6ca8f8bbac69751f82","frame_index":0,"kind":"data","monotonic_ns":224529299311541,"payload":{"event_type":"price_change","market":"0x717c0e8ccd4d5c7040185188fbae28be901ca589a11a94b1b38ca36a79eccfeb","price_changes":[{"asset_id":"41448400836309843603620980831210604935021861034693225347475867885462478926555","best_ask":"0.56","best_bid":"0.55","hash":"ad1f19b8a01d81022dff969117592a10e53c4f31","price":"0.45","side":"BUY","size":"115"},{"asset_id":"24254094493625419915756280046002869097156693848522361803041977572204227262166","best_ask":"0.45","best_bid":"0.44","hash":"fa85407d4643d80418e64f1d918cc6ba97b47ec1","price":"0.55","side":"SELL","size":"115"}],"timestamp":"1785122546063"},"payload_hash":"38fdaae962645dcbf40f9fc24ba3f0bd6c7d47497096614219945161725ce95a","raw_frame":"{\"market\":\"0x717c0e8ccd4d5c7040185188fbae28be901ca589a11a94b1b38ca36a79eccfeb\", \"price_changes\":[{\"asset_id\":\"41448400836309843603620980831210604935021861034693225347475867885462478926555\", \"price\":\"0.45\", \"size\":\"115\", \"side\":\"BUY\", \"hash\":\"ad1f19b8a01d81022dff969117592a10e53c4f31\", \"best_bid\":\"0.55\", \"best_ask\":\"0.56\"}, {\"asset_id\":\"24254094493625419915756280046002869097156693848522361803041977572204227262166\", \"price\":\"0.55\", \"size\":\"115\", \"side\":\"SELL\", \"hash\":\"fa85407d4643d80418e64f1d918cc6ba97b47ec1\", \"best_bid\":\"0.44\", \"best_ask\":\"0.45\"}], \"timestamp\":\"1785122546063\", \"event_type\":\"price_change\"}","received_at":"2026-07-27T03:22:25.943134Z","schema_version":"clob-market-ws.price_change.v1","sequence":null,"server_hash":null,"server_timestamp":"1785122546063","session_id":"dd162b8dca5f43ff811d304e69a06123","source":"clob_market_ws"},"received_at":"2026-07-27T03:22:25.943134Z","record_id":"aa7846881d3f4e9f6e78a5bea319d1c0b77f7041a09e2962f8283b3d23e9b430","schema_fingerprint":"4aa3821a28b0b7c2400bc59aba4bcc0a76e971dadd19610d3ad38c768e124dc7","schema_version":"edge-lab-recorder.raw.v1","sequence":null,"source":"clob_market_ws"}
{"event_at":"2026-07-27T03:22:26.116000Z","event_fingerprint":"a56e5693459c4b6722a322ab58b078425eb7e27541079fb3196154ee16c1745a","payload":{"connection_id":"c7dc2e4762f849c6b6f9306b6518dcab","event_at":"2026-07-27T03:22:26.116000Z","event_type":"price_change","frame_hash":"b09f55ef1cedf7b521ea524a16842a3d455e25f7aea0af31d78e69945df9ae4b","frame_index":0,"kind":"data","monotonic_ns":224529365899416,"payload":{"event_type":"price_change","market":"0x717c0e8ccd4d5c7040185188fbae28be901ca589a11a94b1b38ca36a79eccfeb","price_changes":[{"asset_id":"41448400836309843603620980831210604935021861034693225347475867885462478926555","best_ask":"0.56","best_bid":"0.55","hash":"8e94dbfa95c5ec03a325edffd697b9039999c2bc","price":"0.04","side":"BUY","size":"583.09"},{"asset_id":"24254094493625419915756280046002869097156693848522361803041977572204227262166","best_ask":"0.45","best_bid":"0.44","hash":"e21b50ddeb5a6d8dca1f2525730883ec5b095cda","price":"0.96","side":"SELL","size":"583.09"}],"timestamp":"1785122546116"},"payload_hash":"cd146150ce5e0d854b4e46e6b6f48083235eb5a8996b86431b7791f0fca1682c","raw_frame":"{\"market\":\"0x717c0e8ccd4d5c7040185188fbae28be901ca589a11a94b1b38ca36a79eccfeb\", \"price_changes\":[{\"asset_id\":\"41448400836309843603620980831210604935021861034693225347475867885462478926555\", \"price\":\"0.04\", \"size\":\"583.09\", \"side\":\"BUY\", \"hash\":\"8e94dbfa95c5ec03a325edffd697b9039999c2bc\", \"best_bid\":\"0.55\", \"best_ask\":\"0.56\"}, {\"asset_id\":\"24254094493625419915756280046002869097156693848522361803041977572204227262166\", \"price\":\"0.96\", \"size\":\"583.09\", \"side\":\"SELL\", \"hash\":\"e21b50ddeb5a6d8dca1f2525730883ec5b095cda\", \"best_bid\":\"0.44\", \"best_ask\":\"0.45\"}], \"timestamp\":\"1785122546116\", \"event_type\":\"price_change\"}","received_at":"2026-07-27T03:22:26.009721Z","schema_version":"clob-market-ws.price_change.v1","sequence":null,"server_hash":null,"server_timestamp":"1785122546116","session_id":"dd162b8dca5f43ff811d304e69a06123","source":"clob_market_ws"},"received_at":"2026-07-27T03:22:26.009721Z","record_id":"13d7513b5f6b9be3ac21f790a308645c347bef72728f6016690dfaab9618ba31","schema_fingerprint":"4aa3821a28b0b7c2400bc59aba4bcc0a76e971dadd19610d3ad38c768e124dc7","schema_version":"edge-lab-recorder.raw.v1","sequence":null,"source":"clob_market_ws"}
{"event_at":"2026-07-27T03:22:26.140000Z","event_fingerprint":"ff17098687ffb3b0f0979cf13e8c24ad89779a12d7c0fff55da5ac6d9bc4e6dc","payload":{"connection_id":"c7dc2e4762f849c6b6f9306b6518dcab","event_at":"2026-07-27T03:22:26.140000Z","event_type":"price_change","frame_hash":"4385155560709ce4d7feaa21a89267e9be375c645d5bff5485ebebc4a4af5f85","frame_index":0,"kind":"data","monotonic_ns":224529373089875,"payload":{"event_type":"price_change","market":"0x717c0e8ccd4d5c7040185188fbae28be901ca589a11a94b1b38ca36a79eccfeb","price_changes":[{"asset_id":"24254094493625419915756280046002869097156693848522361803041977572204227262166","best_ask":"0.45","best_bid":"0.44","hash":"c0a57a60f8b531e82b1dd513151d95c481fa658b","price":"0.01","side":"BUY","size":"5453.02"},{"asset_id":"41448400836309843603620980831210604935021861034693225347475867885462478926555","best_ask":"0.56","best_bid":"0.55","hash":"8789cb1cddc89da095e531521bc86c194d21f123","price":"0.99","side":"SELL","size":"5453.02"}],"timestamp":"1785122546140"},"payload_hash":"5d0b72c87d0b41a6ab8dd3e97f526820eb6e81eaa8a1dc302e7cbc5e599479f3","raw_frame":"{\"market\":\"0x717c0e8ccd4d5c7040185188fbae28be901ca589a11a94b1b38ca36a79eccfeb\", \"price_changes\":[{\"asset_id\":\"24254094493625419915756280046002869097156693848522361803041977572204227262166\", \"price\":\"0.01\", \"size\":\"5453.02\", \"side\":\"BUY\", \"hash\":\"c0a57a60f8b531e82b1dd513151d95c481fa658b\", \"best_bid\":\"0.44\", \"best_ask\":\"0.45\"}, {\"asset_id\":\"41448400836309843603620980831210604935021861034693225347475867885462478926555\", \"price\":\"0.99\", \"size\":\"5453.02\", \"side\":\"SELL\", \"hash\":\"8789cb1cddc89da095e531521bc86c194d21f123\", \"best_bid\":\"0.55\", \"best_ask\":\"0.56\"}], \"timestamp\":\"1785122546140\", \"event_type\":\"price_change\"}","received_at":"2026-07-27T03:22:26.016913Z","schema_version":"clob-market-ws.price_change.v1","sequence":null,"server_hash":null,"server_timestamp":"1785122546140","session_id":"dd162b8dca5f43ff811d304e69a06123","source":"clob_market_ws"},"received_at":"2026-07-27T03:22:26.016913Z","record_id":"803e12c9124cfac3aecc89dd53fb6ebbcd62380c8efebeb3629178044aaf2292","schema_fingerprint":"4aa3821a28b0b7c2400bc59aba4bcc0a76e971dadd19610d3ad38c768e124dc7","schema_version":"edge-lab-recorder.raw.v1","sequence":null,"source":"clob_market_ws"}
{"event_at":"2026-07-27T03:22:26.167000Z","event_fingerprint":"66406d295bbeef6197d37daa482a6b1c406201d097e8c93e5f665c1e40b7aef7","payload":{"connection_id":"c7dc2e4762f849c6b6f9306b6518dcab","event_at":"2026-07-27T03:22:26.167000Z","event_type":"price_change","frame_hash":"2a8157568140b80f2c160826daf516cb3235a36dc793259b10dd7899d4e21f92","frame_index":0,"kind":"data","monotonic_ns":224529401688208,"payload":{"event_type":"price_change","market":"0x717c0e8ccd4d5c7040185188fbae28be901ca589a11a94b1b38ca36a79eccfeb","price_changes":[{"asset_id":"41448400836309843603620980831210604935021861034693225347475867885462478926555","best_ask":"0.56","best_bid":"0.55","hash":"fc99bba571308c5c46f07124d79350109707c8ea","price":"0.45","side":"BUY","size":"110"},{"asset_id":"24254094493625419915756280046002869097156693848522361803041977572204227262166","best_ask":"0.45","best_bid":"0.44","hash":"a511fe4d818048b1ae362b00a4f296d343ece344","price":"0.55","side":"SELL","size":"110"}],"timestamp":"1785122546167"},"payload_hash":"e0821569f61f72aa508a31b195830cbe8276354ba940233c73c78a748974e65b","raw_frame":"{\"market\":\"0x717c0e8ccd4d5c7040185188fbae28be901ca589a11a94b1b38ca36a79eccfeb\", \"price_changes\":[{\"asset_id\":\"41448400836309843603620980831210604935021861034693225347475867885462478926555\", \"price\":\"0.45\", \"size\":\"110\", \"side\":\"BUY\", \"hash\":\"fc99bba571308c5c46f07124d79350109707c8ea\", \"best_bid\":\"0.55\", \"best_ask\":\"0.56\"}, {\"asset_id\":\"24254094493625419915756280046002869097156693848522361803041977572204227262166\", \"price\":\"0.55\", \"size\":\"110\", \"side\":\"SELL\", \"hash\":\"a511fe4d818048b1ae362b00a4f296d343ece344\", \"best_bid\":\"0.44\", \"best_ask\":\"0.45\"}], \"timestamp\":\"1785122546167\", \"event_type\":\"price_change\"}","received_at":"2026-07-27T03:22:26.045500Z","schema_version":"clob-market-ws.price_change.v1","sequence":null,"server_hash":null,"server_timestamp":"1785122546167","session_id":"dd162b8dca5f43ff811d304e69a06123","source":"clob_market_ws"},"received_at":"2026-07-27T03:22:26.045500Z","record_id":"549dbf9e8fcd14fc8df183cad7fc8931f58321cfe994e02de45a5e90f90684f6","schema_fingerprint":"4aa3821a28b0b7c2400bc59aba4bcc0a76e971dadd19610d3ad38c768e124dc7","schema_version":"edge-lab-recorder.raw.v1","sequence":null,"source":"clob_market_ws"}
{"event_at":"2026-07-27T03:22:26.170000Z","event_fingerprint":"e1443eeba648ee15d91e478e27ab9147a5abc2511d6d4c5983b6917b2af60317","payload":{"connection_id":"c7dc2e4762f849c6b6f9306b6518dcab","event_at":"2026-07-27T03:22:26.170000Z","event_type":"price_change","frame_hash":"e478bb890cf9e88c3520ff99598d34c3fafb35fac2a93e022e0f87b0b604111f","frame_index":0,"kind":"data","monotonic_ns":224529404956958,"payload":{"event_type":"price_change","market":"0x717c0e8ccd4d5c7040185188fbae28be901ca589a11a94b1b38ca36a79eccfeb","price_changes":[{"asset_id":"24254094493625419915756280046002869097156693848522361803041977572204227262166","best_ask":"0.45","best_bid":"0.44","hash":"132cfb2a890b400f88d9a8060080f99cdcecee7a","price":"0.4","side":"BUY","size":"15"},{"asset_id":"41448400836309843603620980831210604935021861034693225347475867885462478926555","best_ask":"0.56","best_bid":"0.55","hash":"dbb75d7ec576ab47c97ed075f224a2d43868f5b9","price":"0.6","side":"SELL","size":"15"}],"timestamp":"1785122546170"},"payload_hash":"53910df560c0398ec055bedb0e3a6a3fdd5f9020cbc1a7fef4d91311d1a4afea","raw_frame":"{\"market\":\"0x717c0e8ccd4d5c7040185188fbae28be901ca589a11a94b1b38ca36a79eccfeb\", \"price_changes\":[{\"asset_id\":\"24254094493625419915756280046002869097156693848522361803041977572204227262166\", \"price\":\"0.4\", \"size\":\"15\", \"side\":\"BUY\", \"hash\":\"132cfb2a890b400f88d9a8060080f99cdcecee7a\", \"best_bid\":\"0.44\", \"best_ask\":\"0.45\"}, {\"asset_id\":\"41448400836309843603620980831210604935021861034693225347475867885462478926555\", \"price\":\"0.6\", \"size\":\"15\", \"side\":\"SELL\", \"hash\":\"dbb75d7ec576ab47c97ed075f224a2d43868f5b9\", \"best_bid\":\"0.55\", \"best_ask\":\"0.56\"}], \"timestamp\":\"1785122546170\", \"event_type\":\"price_change\"}","received_at":"2026-07-27T03:22:26.048777Z","schema_version":"clob-market-ws.price_change.v1","sequence":null,"server_hash":null,"server_timestamp":"1785122546170","session_id":"dd162b8dca5f43ff811d304e69a06123","source":"clob_market_ws"},"received_at":"2026-07-27T03:22:26.048777Z","record_id":"c90ad8a320daca0c350c4d0951b95cdd21e486d049a24e15cc4af2c379e6d9b8","schema_fingerprint":"4aa3821a28b0b7c2400bc59aba4bcc0a76e971dadd19610d3ad38c768e124dc7","schema_version":"edge-lab-recorder.raw.v1","sequence":null,"source":"clob_market_ws"}
{"event_at":"2026-07-27T03:22:26.172000Z","event_fingerprint":"574632eac4cd6768856ad4b89d243e12c33b227b98a922888ce68b5d1f450611","payload":{"connection_id":"c7dc2e4762f849c6b6f9306b6518dcab","event_at":"2026-07-27T03:22:26.172000Z","event_type":"price_change","frame_hash":"7295bb642a6f4a33e3df09f473ade82ffc3948b5a8b7af473b9c2e36a173b705","frame_index":0,"kind":"data","monotonic_ns":224529406596583,"payload":{"event_type":"price_change","market":"0x717c0e8ccd4d5c7040185188fbae28be901ca589a11a94b1b38ca36a79eccfeb","price_changes":[{"asset_id":"41448400836309843603620980831210604935021861034693225347475867885462478926555","best_ask":"0.56","best_bid":"0.55","hash":"bf722f66e0257dbeb8ecb4ece5127f24dd42de8a","price":"0.44","side":"BUY","size":"244"},{"asset_id":"24254094493625419915756280046002869097156693848522361803041977572204227262166","best_ask":"0.45","best_bid":"0.44","hash":"929b0b6dc09efa9bebad28fce19cb35f6963a031","price":"0.56","side":"SELL","size":"244"}],"timestamp":"1785122546172"},"payload_hash":"371c294590eb6df1eaec837df41dc72c68db4bb71256b43eea1240bc2d647160","raw_frame":"{\"market\":\"0x717c0e8ccd4d5c7040185188fbae28be901ca589a11a94b1b38ca36a79eccfeb\", \"price_changes\":[{\"asset_id\":\"41448400836309843603620980831210604935021861034693225347475867885462478926555\", \"price\":\"0.44\", \"size\":\"244\", \"side\":\"BUY\", \"hash\":\"bf722f66e0257dbeb8ecb4ece5127f24dd42de8a\", \"best_bid\":\"0.55\", \"best_ask\":\"0.56\"}, {\"asset_id\":\"24254094493625419915756280046002869097156693848522361803041977572204227262166\", \"price\":\"0.56\", \"size\":\"244\", \"side\":\"SELL\", \"hash\":\"929b0b6dc09efa9bebad28fce19cb35f6963a031\", \"best_bid\":\"0.44\", \"best_ask\":\"0.45\"}], \"timestamp\":\"1785122546172\", \"event_type\":\"price_change\"}","received_at":"2026-07-27T03:22:26.050417Z","schema_version":"clob-market-ws.price_change.v1","sequence":null,"server_hash":null,"server_timestamp":"1785122546172","session_id":"dd162b8dca5f43ff811d304e69a06123","source":"clob_market_ws"},"received_at":"2026-07-27T03:22:26.050417Z","record_id":"7b38f5eb6169bad8c414c38c3e089af64c9d14610c339375afb9de7ce2654e67","schema_fingerprint":"4aa3821a28b0b7c2400bc59aba4bcc0a76e971dadd19610d3ad38c768e124dc7","schema_version":"edge-lab-recorder.raw.v1","sequence":null,"source":"clob_market_ws"}
{"event_at":"2026-07-27T03:22:26.196000Z","event_fingerprint":"b1a44c4757bcc996c3af759674bb8bd2001ae73f3cd6c3d868c71e36613b69e9","payload":{"connection_id":"c7dc2e4762f849c6b6f9306b6518dcab","event_at":"2026-07-27T03:22:26.196000Z","event_type":"price_change","frame_hash":"94fcc23009ecafd95c4f149a9a958d5f32235721773b87e6e616d7e679984dc3","frame_index":0,"kind":"data","monotonic_ns":224529428551208,"payload":{"event_type":"price_change","market":"0x717c0e8ccd4d5c7040185188fbae28be901ca589a11a94b1b38ca36a79eccfeb","price_changes":[{"asset_id":"41448400836309843603620980831210604935021861034693225347475867885462478926555","best_ask":"0.56","best_bid":"0.55","hash":"d20a8d45c72b19e4e6758a26e1f542a2b301ded2","price":"0.04","side":"BUY","size":"578.09"},{"asset_id":"24254094493625419915756280046002869097156693848522361803041977572204227262166","best_ask":"0.45","best_bid":"0.44","hash":"063215990c416fe1551990cd1711fb907c6594f1","price":"0.96","side":"SELL","size":"578.09"}],"timestamp":"1785122546196"},"payload_hash":"a1a90d50693f02be6721f7c15d51b580031aaede517fcd5594bf12b578e8df88","raw_frame":"{\"market\":\"0x717c0e8ccd4d5c7040185188fbae28be901ca589a11a94b1b38ca36a79eccfeb\", \"price_changes\":[{\"asset_id\":\"41448400836309843603620980831210604935021861034693225347475867885462478926555\", \"price\":\"0.04\", \"size\":\"578.09\", \"side\":\"BUY\", \"hash\":\"d20a8d45c72b19e4e6758a26e1f542a2b301ded2\", \"best_bid\":\"0.55\", \"best_ask\":\"0.56\"}, {\"asset_id\":\"24254094493625419915756280046002869097156693848522361803041977572204227262166\", \"price\":\"0.96\", \"size\":\"578.09\", \"side\":\"SELL\", \"hash\":\"063215990c416fe1551990cd1711fb907c6594f1\", \"best_bid\":\"0.44\", \"best_ask\":\"0.45\"}], \"timestamp\":\"1785122546196\", \"event_type\":\"price_change\"}","received_at":"2026-07-27T03:22:26.072366Z","schema_version":"clob-market-ws.price_change.v1","sequence":null,"server_hash":null,"server_timestamp":"1785122546196","session_id":"dd162b8dca5f43ff811d304e69a06123","source":"clob_market_ws"},"received_at":"2026-07-27T03:22:26.072366Z","record_id":"63a811c24ade91df98303f2a04a481f774ccbd06a4aa3d52e7f6583ce6da904f","schema_fingerprint":"4aa3821a28b0b7c2400bc59aba4bcc0a76e971dadd19610d3ad38c768e124dc7","schema_version":"edge-lab-recorder.raw.v1","sequence":null,"source":"clob_market_ws"}
{"event_at":"2026-07-27T03:22:26.256000Z","event_fingerprint":"e4d740f4c91564b4686c683d54f38882918c1b57b982b754249113c79018de8c","payload":{"connection_id":"c7dc2e4762f849c6b6f9306b6518dcab","event_at":"2026-07-27T03:22:26.256000Z","event_type":"price_change","frame_hash":"f6608610fd6688c0689081c16f178b3c9eecc2f875c66750b8339123413571d8","frame_index":0,"kind":"data","monotonic_ns":224529488862833,"payload":{"event_type":"price_change","market":"0x717c0e8ccd4d5c7040185188fbae28be901ca589a11a94b1b38ca36a79eccfeb","price_changes":[{"asset_id":"41448400836309843603620980831210604935021861034693225347475867885462478926555","best_ask":"0.56","best_bid":"0.55","hash":"1627acd78f47470fc9aecd854818c422f69a2d7e","price":"0.01","side":"BUY","size":"5458.02"},{"asset_id":"24254094493625419915756280046002869097156693848522361803041977572204227262166","best_ask":"0.45","best_bid":"0.44","hash":"0f5c7e482bb4515e3de5aac3cde5d486d3cee06e","price":"0.99","side":"SELL","size":"5458.02"}],"timestamp":"1785122546256"},"payload_hash":"0eef57954602bd2fc785a8405910d2dbd719c7b31272fdaebd59ae8af4db6aef","raw_frame":"{\"market\":\"0x717c0e8ccd4d5c7040185188fbae28be901ca589a11a94b1b38ca36a79eccfeb\", \"price_changes\":[{\"asset_id\":\"41448400836309843603620980831210604935021861034693225347475867885462478926555\", \"price\":\"0.01\", \"size\":\"5458.02\", \"side\":\"BUY\", \"hash\":\"1627acd78f47470fc9aecd854818c422f69a2d7e\", \"best_bid\":\"0.55\", \"best_ask\":\"0.56\"}, {\"asset_id\":\"24254094493625419915756280046002869097156693848522361803041977572204227262166\", \"price\":\"0.99\", \"size\":\"5458.02\", \"side\":\"SELL\", \"hash\":\"0f5c7e482bb4515e3de5aac3cde5d486d3cee06e\", \"best_bid\":\"0.44\", \"best_ask\":\"0.45\"}], \"timestamp\":\"1785122546256\", \"event_type\":\"price_change\"}","received_at":"2026-07-27T03:22:26.132682Z","schema_version":"clob-market-ws.price_change.v1","sequence":null,"server_hash":null,"server_timestamp":"1785122546256","session_id":"dd162b8dca5f43ff811d304e69a06123","source":"clob_market_ws"},"received_at":"2026-07-27T03:22:26.132682Z","record_id":"af2f1e593db77f3fb27aa940e03d1b8fa481cf41a0fe6fa53a4f1fa5f12c85b1","schema_fingerprint":"4aa3821a28b0b7c2400bc59aba4bcc0a76e971dadd19610d3ad38c768e124dc7","schema_version":"edge-lab-recorder.raw.v1","sequence":null,"source":"clob_market_ws"}
{"event_at":"2026-07-27T03:22:26.264000Z","event_fingerprint":"78ef4aa1e22ad0a60acf47ba98332c367c532af21e0ab0c2c18cdc6f9bdda093","payload":{"connection_id":"c7dc2e4762f849c6b6f9306b6518dcab","event_at":"2026-07-27T03:22:26.264000Z","event_type":"price_change","frame_hash":"7ccbe2ff7b309100fb630dc0e186ed394b424fce3af099628f33af8b087d99fe","frame_index":0,"kind":"data","monotonic_ns":224529499707000,"payload":{"event_type":"price_change","market":"0x717c0e8ccd4d5c7040185188fbae28be901ca589a11a94b1b38ca36a79eccfeb","price_changes":[{"asset_id":"24254094493625419915756280046002869097156693848522361803041977572204227262166","best_ask":"0.45","best_bid":"0.44","hash":"c78293129e8a7cc69fe5a55c04641cf72403f37e","price":"0.37","side":"BUY","size":"207"},{"asset_id":"41448400836309843603620980831210604935021861034693225347475867885462478926555","best_ask":"0.56","best_bid":"0.55","hash":"6f8856b6d8d85719fb75998adccfce63ae11af75","price":"0.63","side":"SELL","size":"207"}],"timestamp":"1785122546264"},"payload_hash":"f939b621de431ffac0d2fe6a656ba332db242afbafdf1b55b333425df00024d5","raw_frame":"{\"market\":\"0x717c0e8ccd4d5c7040185188fbae28be901ca589a11a94b1b38ca36a79eccfeb\", \"price_changes\":[{\"asset_id\":\"24254094493625419915756280046002869097156693848522361803041977572204227262166\", \"price\":\"0.37\", \"size\":\"207\", \"side\":\"BUY\", \"hash\":\"c78293129e8a7cc69fe5a55c04641cf72403f37e\", \"best_bid\":\"0.44\", \"best_ask\":\"0.45\"}, {\"asset_id\":\"41448400836309843603620980831210604935021861034693225347475867885462478926555\", \"price\":\"0.63\", \"size\":\"207\", \"side\":\"SELL\", \"hash\":\"6f8856b6d8d85719fb75998adccfce63ae11af75\", \"best_bid\":\"0.55\", \"best_ask\":\"0.56\"}], \"timestamp\":\"1785122546264\", \"event_type\":\"price_change\"}","received_at":"2026-07-27T03:22:26.143527Z","schema_version":"clob-market-ws.price_change.v1","sequence":null,"server_hash":null,"server_timestamp":"1785122546264","session_id":"dd162b8dca5f43ff811d304e69a06123","source":"clob_market_ws"},"received_at":"2026-07-27T03:22:26.143527Z","record_id":"49938a8706b51334428a3fd9e91a83d6e9c734a83e81b5fe735bff91507f32bd","schema_fingerprint":"4aa3821a28b0b7c2400bc59aba4bcc0a76e971dadd19610d3ad38c768e124dc7","schema_version":"edge-lab-recorder.raw.v1","sequence":null,"source":"clob_market_ws"}
{"event_at":"2026-07-27T03:22:26.266000Z","event_fingerprint":"c1660b38ac91b65fa3cf73047b5a6b88d6d8f50940812afcb2f6140bf271bb58","payload":{"connection_id":"c7dc2e4762f849c6b6f9306b6518dcab","event_at":"2026-07-27T03:22:26.266000Z","event_type":"price_change","frame_hash":"8d7053bcd197ba778caf554c07c4ab228a5a38b256ddd41d2f9c2caa489cb031","frame_index":0,"kind":"data","monotonic_ns":224529502878541,"payload":{"event_type":"price_change","market":"0x717c0e8ccd4d5c7040185188fbae28be901ca589a11a94b1b38ca36a79eccfeb","price_changes":[{"asset_id":"24254094493625419915756280046002869097156693848522361803041977572204227262166","best_ask":"0.45","best_bid":"0.44","hash":"c24b67f9c542158de4fa7bee6decbc543c66881a","price":"0.4","side":"BUY","size":"10"},{"asset_id":"41448400836309843603620980831210604935021861034693225347475867885462478926555","best_ask":"0.56","best_bid":"0.55","hash":"dc1e7338adb8b17bdf910d4c666f968c72b8f5a1","price":"0.6","side":"SELL","size":"10"}],"timestamp":"1785122546266"},"payload_hash":"9d8fa058f4d271843aa30e64693695be894771f637c678597de35334d7912821","raw_frame":"{\"market\":\"0x717c0e8ccd4d5c7040185188fbae28be901ca589a11a94b1b38ca36a79eccfeb\", \"price_changes\":[{\"asset_id\":\"24254094493625419915756280046002869097156693848522361803041977572204227262166\", \"price\":\"0.4\", \"size\":\"10\", \"side\":\"BUY\", \"hash\":\"c24b67f9c542158de4fa7bee6decbc543c66881a\", \"best_bid\":\"0.44\", \"best_ask\":\"0.45\"}, {\"asset_id\":\"41448400836309843603620980831210604935021861034693225347475867885462478926555\", \"price\":\"0.6\", \"size\":\"10\", \"side\":\"SELL\", \"hash\":\"dc1e7338adb8b17bdf910d4c666f968c72b8f5a1\", \"best_bid\":\"0.55\", \"best_ask\":\"0.56\"}], \"timestamp\":\"1785122546266\", \"event_type\":\"price_change\"}","received_at":"2026-07-27T03:22:26.146698Z","schema_version":"clob-market-ws.price_change.v1","sequence":null,"server_hash":null,"server_timestamp":"1785122546266","session_id":"dd162b8dca5f43ff811d304e69a06123","source":"clob_market_ws"},"received_at":"2026-07-27T03:22:26.146698Z","record_id":"5b3f6bc22c84aaf145c2260644949666f18e12c5d2a30d82ef74fd20652851e1","schema_fingerprint":"4aa3821a28b0b7c2400bc59aba4bcc0a76e971dadd19610d3ad38c768e124dc7","schema_version":"edge-lab-recorder.raw.v1","sequence":null,"source":"clob_market_ws"}
{"event_at":"2026-07-27T03:22:26.273000Z","event_fingerprint":"65faf8c7d95013bfd279524718f813d416dc2275280a429df018baf00f7507e4","payload":{"connection_id":"c7dc2e4762f849c6b6f9306b6518dcab","event_at":"2026-07-27T03:22:26.273000Z","event_type":"price_change","frame_hash":"d7d850145f1f3dff4d103cc2be434c0ea2a03e68433b7703d5ff05b330703ce5","frame_index":0,"kind":"data","monotonic_ns":224529507792250,"payload":{"event_type":"price_change","market":"0x717c0e8ccd4d5c7040185188fbae28be901ca589a11a94b1b38ca36a79eccfeb","price_changes":[{"asset_id":"41448400836309843603620980831210604935021861034693225347475867885462478926555","best_ask":"0.56","best_bid":"0.55","hash":"15a33a7330ea4d5f5c84ddb20b2856e27d83a713","price":"0.63","side":"SELL","size":"195"},{"asset_id":"24254094493625419915756280046002869097156693848522361803041977572204227262166","best_ask":"0.45","best_bid":"0.44","hash":"1568a684876b326308cc78f0c42476ceca082b0d","price":"0.37","side":"BUY","size":"195"}],"timestamp":"1785122546273"},"payload_hash":"670ba66369358ae5b50a55d9ab02414086c953b9df2baa30601d7045eae7d9c2","raw_frame":"{\"market\":\"0x717c0e8ccd4d5c7040185188fbae28be901ca589a11a94b1b38ca36a79eccfeb\", \"price_changes\":[{\"asset_id\":\"41448400836309843603620980831210604935021861034693225347475867885462478926555\", \"price\":\"0.63\", \"size\":\"195\", \"side\":\"SELL\", \"hash\":\"15a33a7330ea4d5f5c84ddb20b2856e27d83a713\", \"best_bid\":\"0.55\", \"best_ask\":\"0.56\"}, {\"asset_id\":\"24254094493625419915756280046002869097156693848522361803041977572204227262166\", \"price\":\"0.37\", \"size\":\"195\", \"side\":\"BUY\", \"hash\":\"1568a684876b326308cc78f0c42476ceca082b0d\", \"best_bid\":\"0.44\", \"best_ask\":\"0.45\"}], \"timestamp\":\"1785122546273\", \"event_type\":\"price_change\"}","received_at":"2026-07-27T03:22:26.151611Z","schema_version":"clob-market-ws.price_change.v1","sequence":null,"server_hash":null,"server_timestamp":"1785122546273","session_id":"dd162b8dca5f43ff811d304e69a06123","source":"clob_market_ws"},"received_at":"2026-07-27T03:22:26.151611Z","record_id":"d61998816c1cc8dbeca67f1b8cfa4f03376cf5658a80c1b6d31d470897d55b77","schema_fingerprint":"4aa3821a28b0b7c2400bc59aba4bcc0a76e971dadd19610d3ad38c768e124dc7","schema_version":"edge-lab-recorder.raw.v1","sequence":null,"source":"clob_market_ws"}
{"event_at":"2026-07-27T03:22:26.278000Z","event_fingerprint":"540cab6538aa376516f6828e14ab42cd5200c42257c4da87f18b499d150cef5a","payload":{"connection_id":"c7dc2e4762f849c6b6f9306b6518dcab","event_at":"2026-07-27T03:22:26.278000Z","event_type":"price_change","frame_hash":"c9593cc73616d6c68067f9b0f647f219bff7c6915b653ac624400cd164afd243","frame_index":0,"kind":"data","monotonic_ns":224529513009125,"payload":{"event_type":"price_change","market":"0x717c0e8ccd4d5c7040185188fbae28be901ca589a11a94b1b38ca36a79eccfeb","price_changes":[{"asset_id":"41448400836309843603620980831210604935021861034693225347475867885462478926555","best_ask":"0.56","best_bid":"0.55","hash":"e43f579764b6c8eaf1756a9bc8db75228d28db70","price":"0.01","side":"BUY","size":"5453.02"},{"asset_id":"24254094493625419915756280046002869097156693848522361803041977572204227262166","best_ask":"0.45","best_bid":"0.44","hash":"2b049a9ec7bb5fe3bdc7bd01e30a4f82318c6195","price":"0.99","side":"SELL","size":"5453.02"}],"timestamp":"1785122546278"},"payload_hash":"a17f6a93ce3340a9e01556d20287bb036eb77871ac7640e1ef89aea2ea4596ab","raw_frame":"{\"market\":\"0x717c0e8ccd4d5c7040185188fbae28be901ca589a11a94b1b38ca36a79eccfeb\", \"price_changes\":[{\"asset_id\":\"41448400836309843603620980831210604935021861034693225347475867885462478926555\", \"price\":\"0.01\", \"size\":\"5453.02\", \"side\":\"BUY\", \"hash\":\"e43f579764b6c8eaf1756a9bc8db75228d28db70\", \"best_bid\":\"0.55\", \"best_ask\":\"0.56\"}, {\"asset_id\":\"24254094493625419915756280046002869097156693848522361803041977572204227262166\", \"price\":\"0.99\", \"size\":\"5453.02\", \"side\":\"SELL\", \"hash\":\"2b049a9ec7bb5fe3bdc7bd01e30a4f82318c6195\", \"best_bid\":\"0.44\", \"best_ask\":\"0.45\"}], \"timestamp\":\"1785122546278\", \"event_type\":\"price_change\"}","received_at":"2026-07-27T03:22:26.156828Z","schema_version":"clob-market-ws.price_change.v1","sequence":null,"server_hash":null,"server_timestamp":"1785122546278","session_id":"dd162b8dca5f43ff811d304e69a06123","source":"clob_market_ws"},"received_at":"2026-07-27T03:22:26.156828Z","record_id":"23361673b56d4fcf2c7b91f415f23f610a9674524f0ce1a5740dcd2be821f689","schema_fingerprint":"4aa3821a28b0b7c2400bc59aba4bcc0a76e971dadd19610d3ad38c768e124dc7","schema_version":"edge-lab-recorder.raw.v1","sequence":null,"source":"clob_market_ws"}
{"event_at":"2026-07-27T03:22:26.285000Z","event_fingerprint":"dbbca6dfa51eaab5d525597d4cd47613d4e84758e94e4ed3ffbfb58a259cb069","payload":{"connection_id":"c7dc2e4762f849c6b6f9306b6518dcab","event_at":"2026-07-27T03:22:26.285000Z","event_type":"price_change","frame_hash":"9db28a1ea61eb6afe7f8fbf740210f69c2ccb1e925e7f505d089b7c0ef738b10","frame_index":0,"kind":"data","monotonic_ns":224529522327083,"payload":{"event_type":"price_change","market":"0x717c0e8ccd4d5c7040185188fbae28be901ca589a11a94b1b38ca36a79eccfeb","price_changes":[{"asset_id":"41448400836309843603620980831210604935021861034693225347475867885462478926555","best_ask":"0.56","best_bid":"0.55","hash":"8fd59679e685e155c2d8bb1647782254736e1421","price":"0.03","side":"BUY","size":"618.1"},{"asset_id":"24254094493625419915756280046002869097156693848522361803041977572204227262166","best_ask":"0.45","best_bid":"0.44","hash":"36b5a034129b1f174126cf782ce3d3b480fad31a","price":"0.97","side":"SELL","size":"618.1"}],"timestamp":"1785122546285"},"payload_hash":"f7c58d9c3aa786468198f7a96e0048270f57d3af0676d165beea54ea2674e39b","raw_frame":"{\"market\":\"0x717c0e8ccd4d5c7040185188fbae28be901ca589a11a94b1b38ca36a79eccfeb\", \"price_changes\":[{\"asset_id\":\"41448400836309843603620980831210604935021861034693225347475867885462478926555\", \"price\":\"0.03\", \"size\":\"618.1\", \"side\":\"BUY\", \"hash\":\"8fd59679e685e155c2d8bb1647782254736e1421\", \"best_bid\":\"0.55\", \"best_ask\":\"0.56\"}, {\"asset_id\":\"24254094493625419915756280046002869097156693848522361803041977572204227262166\", \"price\":\"0.97\", \"size\":\"618.1\", \"side\":\"SELL\", \"hash\":\"36b5a034129b1f174126cf782ce3d3b480fad31a\", \"best_bid\":\"0.44\", \"best_ask\":\"0.45\"}], \"timestamp\":\"1785122546285\", \"event_type\":\"price_change\"}","received_at":"2026-07-27T03:22:26.166147Z","schema_version":"clob-market-ws.price_change.v1","sequence":null,"server_hash":null,"server_timestamp":"1785122546285","session_id":"dd162b8dca5f43ff811d304e69a06123","source":"clob_market_ws"},"received_at":"2026-07-27T03:22:26.166147Z","record_id":"b3070a76b9cc5dad64a40133ca760d39488bc2db3479b97356e5fbb6a384585c","schema_fingerprint":"4aa3821a28b0b7c2400bc59aba4bcc0a76e971dadd19610d3ad38c768e124dc7","schema_version":"edge-lab-recorder.raw.v1","sequence":null,"source":"clob_market_ws"}
{"event_at":"2026-07-27T03:22:26.290000Z","event_fingerprint":"9e08043ed74c4895d969f02e0a5a015d9137d3ae6e761026c13fc21dd69ac4aa","payload":{"connection_id":"c7dc2e4762f849c6b6f9306b6518dcab","event_at":"2026-07-27T03:22:26.290000Z","event_type":"price_change","frame_hash":"904794cbc5efd6a43b92ee70b032b6a9d7966272434eb02c5cea89480834d53e","frame_index":0,"kind":"data","monotonic_ns":224529525654916,"payload":{"event_type":"price_change","market":"0x717c0e8ccd4d5c7040185188fbae28be901ca589a11a94b1b38ca36a79eccfeb","price_changes":[{"asset_id":"24254094493625419915756280046002869097156693848522361803041977572204227262166","best_ask":"0.45","best_bid":"0.44","hash":"e257ca0d3819b30eb7dd15dc400325a131e3d850","price":"0.38","side":"BUY","size":"40"},{"asset_id":"41448400836309843603620980831210604935021861034693225347475867885462478926555","best_ask":"0.56","best_bid":"0.55","hash":"090df63155af8cdf6716538b8290e042511eed0b","price":"0.62","side":"SELL","size":"40"}],"timestamp":"1785122546290"},"payload_hash":"c2f086857ba4ba53d54998f2b0a1631ac4b6feb5ac80a4e7aa351c79da9337d3","raw_frame":"{\"market\":\"0x717c0e8ccd4d5c7040185188fbae28be901ca589a11a94b1b38ca36a79eccfeb\", \"price_changes\":[{\"asset_id\":\"24254094493625419915756280046002869097156693848522361803041977572204227262166\", \"price\":\"0.38\", \"size\":\"40\", \"side\":\"BUY\", \"hash\":\"e257ca0d3819b30eb7dd15dc400325a131e3d850\", \"best_bid\":\"0.44\", \"best_ask\":\"0.45\"}, {\"asset_id\":\"41448400836309843603620980831210604935021861034693225347475867885462478926555\", \"price\":\"0.62\", \"size\":\"40\", \"side\":\"SELL\", \"hash\":\"090df63155af8cdf6716538b8290e042511eed0b\", \"best_bid\":\"0.55\", \"best_ask\":\"0.56\"}], \"timestamp\":\"1785122546290\", \"event_type\":\"price_change\"}","received_at":"2026-07-27T03:22:26.169474Z","schema_version":"clob-market-ws.price_change.v1","sequence":null,"server_hash":null,"server_timestamp":"1785122546290","session_id":"dd162b8dca5f43ff811d304e69a06123","source":"clob_market_ws"},"received_at":"2026-07-27T03:22:26.169474Z","record_id":"50f81a4258022a71384c512134ef0ce5f27588070eb6f8b8253243f3006a1b61","schema_fingerprint":"4aa3821a28b0b7c2400bc59aba4bcc0a76e971dadd19610d3ad38c768e124dc7","schema_version":"edge-lab-recorder.raw.v1","sequence":null,"source":"clob_market_ws"}
{"event_at":"2026-07-27T03:22:26.297000Z","event_fingerprint":"2ba9ff2a9d7f818c89585b9cc4e804c4b8cd4b9449f0173728e75b3a29deb3ec","payload":{"connection_id":"c7dc2e4762f849c6b6f9306b6518dcab","event_at":"2026-07-27T03:22:26.297000Z","event_type":"price_change","frame_hash":"51b2190f2644c01ad490d781a1f5e4710cbdbd0ec1befb649046113d38be75a3","frame_index":0,"kind":"data","monotonic_ns":224529530443458,"payload":{"event_type":"price_change","market":"0x717c0e8ccd4d5c7040185188fbae28be901ca589a11a94b1b38ca36a79eccfeb","price_changes":[{"asset_id":"41448400836309843603620980831210604935021861034693225347475867885462478926555","best_ask":"0.56","best_bid":"0.55","hash":"8114d5c97e33d84edcf3da22755a05495d316d93","price":"0.62","side":"SELL","size":"52.5"},{"asset_id":"24254094493625419915756280046002869097156693848522361803041977572204227262166","best_ask":"0.45","best_bid":"0.44","hash":"fe2adfb42a814effff4578d90d4f88ef2aa8fd76","price":"0.38","side":"BUY","size":"52.5"}],"timestamp":"1785122546297"},"payload_hash":"a09b6d2e3008ff0fbc12c04e49c91e5d16693fc200282e64193b28516fdaa239","raw_frame":"{\"market\":\"0x717c0e8ccd4d5c7040185188fbae28be901ca589a11a94b1b38ca36a79eccfeb\", \"price_changes\":[{\"asset_id\":\"41448400836309843603620980831210604935021861034693225347475867885462478926555\", \"price\":\"0.62\", \"size\":\"52.5\", \"side\":\"SELL\", \"hash\":\"8114d5c97e33d84edcf3da22755a05495d316d93\", \"best_bid\":\"0.55\", \"best_ask\":\"0.56\"}, {\"asset_id\":\"24254094493625419915756280046002869097156693848522361803041977572204227262166\", \"price\":\"0.38\", \"size\":\"52.5\", \"side\":\"BUY\", \"hash\":\"fe2adfb42a814effff4578d90d4f88ef2aa8fd76\", \"best_bid\":\"0.44\", \"best_ask\":\"0.45\"}], \"timestamp\":\"1785122546297\", \"event_type\":\"price_change\"}","received_at":"2026-07-27T03:22:26.174261Z","schema_version":"clob-market-ws.price_change.v1","sequence":null,"server_hash":null,"server_timestamp":"1785122546297","session_id":"dd162b8dca5f43ff811d304e69a06123","source":"clob_market_ws"},"received_at":"2026-07-27T03:22:26.174261Z","record_id":"99a8f84cddab48a2485ba67bc843292cfbd39aa8b23805e35d62e03001b9e77b","schema_fingerprint":"4aa3821a28b0b7c2400bc59aba4bcc0a76e971dadd19610d3ad38c768e124dc7","schema_version":"edge-lab-recorder.raw.v1","sequence":null,"source":"clob_market_ws"}
{"event_at":"2026-07-27T03:22:26.364000Z","event_fingerprint":"502fb763c45f0794adc566d3c14d2d869a2e0b277fc0749b0dd433aa90af04ef","payload":{"connection_id":"c7dc2e4762f849c6b6f9306b6518dcab","event_at":"2026-07-27T03:22:26.364000Z","event_type":"price_change","frame_hash":"125bb84f51223faebd866dd3e88d68652931ae548e1da423ead76b55b0bbd21a","frame_index":0,"kind":"data","monotonic_ns":224529598708208,"payload":{"event_type":"price_change","market":"0x717c0e8ccd4d5c7040185188fbae28be901ca589a11a94b1b38ca36a79eccfeb","price_changes":[{"asset_id":"41448400836309843603620980831210604935021861034693225347475867885462478926555","best_ask":"0.56","best_bid":"0.55","hash":"e8edfb245c1861635b69fde0cd9b552130f640d3","price":"0.62","side":"SELL","size":"40"},{"asset_id":"24254094493625419915756280046002869097156693848522361803041977572204227262166","best_ask":"0.45","best_bid":"0.44","hash":"1596275164788f091b610e790057cd9d23cabd19","price":"0.38","side":"BUY","size":"40"}],"timestamp":"1785122546364"},"payload_hash":"566bdc90e0fae44f677b851f4fb8e4021b0e72a47fead55fb83012dd77dace61","raw_frame":"{\"market\":\"0x717c0e8ccd4d5c7040185188fbae28be901ca589a11a94b1b38ca36a79eccfeb\", \"price_changes\":[{\"asset_id\":\"41448400836309843603620980831210604935021861034693225347475867885462478926555\", \"price\":\"0.62\", \"size\":\"40\", \"side\":\"SELL\", \"hash\":\"e8edfb245c1861635b69fde0cd9b552130f640d3\", \"best_bid\":\"0.55\", \"best_ask\":\"0.56\"}, {\"asset_id\":\"24254094493625419915756280046002869097156693848522361803041977572204227262166\", \"price\":\"0.38\", \"size\":\"40\", \"side\":\"BUY\", \"hash\":\"1596275164788f091b610e790057cd9d23cabd19\", \"best_bid\":\"0.44\", \"best_ask\":\"0.45\"}], \"timestamp\":\"1785122546364\", \"event_type\":\"price_change\"}","received_at":"2026-07-27T03:22:26.242525Z","schema_version":"clob-market-ws.price_change.v1","sequence":null,"server_hash":null,"server_timestamp":"1785122546364","session_id":"dd162b8dca5f43ff811d304e69a06123","source":"clob_market_ws"},"received_at":"2026-07-27T03:22:26.242525Z","record_id":"ad37243c62d44869e9f239d6bd68420c5226b9a5a51cfbc0ae197f7eccaedaae","schema_fingerprint":"4aa3821a28b0b7c2400bc59aba4bcc0a76e971dadd19610d3ad38c768e124dc7","schema_version":"edge-lab-recorder.raw.v1","sequence":null,"source":"clob_market_ws"}
{"event_at":"2026-07-27T03:22:26.367000Z","event_fingerprint":"a2a59526269eadc593dc57dd8dd8975510443fcd5bd3b4d56b70b2a585bbb348","payload":{"connection_id":"c7dc2e4762f849c6b6f9306b6518dcab","event_at":"2026-07-27T03:22:26.367000Z","event_type":"price_change","frame_hash":"db104f630888d825a1e1f0060526ca01b049128d9b27e11f064c27cc234f9508","frame_index":0,"kind":"data","monotonic_ns":224529604905541,"payload":{"event_type":"price_change","market":"0x717c0e8ccd4d5c7040185188fbae28be901ca589a11a94b1b38ca36a79eccfeb","price_changes":[{"asset_id":"24254094493625419915756280046002869097156693848522361803041977572204227262166","best_ask":"0.45","best_bid":"0.44","hash":"bcb269d9cea1b5c8285e36d852014ff379d6b740","price":"0.38","side":"BUY","size":"15"},{"asset_id":"41448400836309843603620980831210604935021861034693225347475867885462478926555","best_ask":"0.56","best_bid":"0.55","hash":"5becfa031cb391757e7f088fc9a91486169c2bbe","price":"0.62","side":"SELL","size":"15"}],"timestamp":"1785122546367"},"payload_hash":"a2af34e961a427e0f889818c0d05012d74bfad34698198e8937bbb0b5be74e52","raw_frame":"{\"market\":\"0x717c0e8ccd4d5c7040185188fbae28be901ca589a11a94b1b38ca36a79eccfeb\", \"price_changes\":[{\"asset_id\":\"24254094493625419915756280046002869097156693848522361803041977572204227262166\", \"price\":\"0.38\", \"size\":\"15\", \"side\":\"BUY\", \"hash\":\"bcb269d9cea1b5c8285e36d852014ff379d6b740\", \"best_bid\":\"0.44\", \"best_ask\":\"0.45\"}, {\"asset_id\":\"41448400836309843603620980831210604935021861034693225347475867885462478926555\", \"price\":\"0.62\", \"size\":\"15\", \"side\":\"SELL\", \"hash\":\"5becfa031cb391757e7f088fc9a91486169c2bbe\", \"best_bid\":\"0.55\", \"best_ask\":\"0.56\"}], \"timestamp\":\"1785122546367\", \"event_type\":\"price_change\"}","received_at":"2026-07-27T03:22:26.248725Z","schema_version":"clob-market-ws.price_change.v1","sequence":null,"server_hash":null,"server_timestamp":"1785122546367","session_id":"dd162b8dca5f43ff811d304e69a06123","source":"clob_market_ws"},"received_at":"2026-07-27T03:22:26.248725Z","record_id":"2681bc2799545139cc50b358a222719ad0823fa85b35807c6e29210b9bb6f2df","schema_fingerprint":"4aa3821a28b0b7c2400bc59aba4bcc0a76e971dadd19610d3ad38c768e124dc7","schema_version":"edge-lab-recorder.raw.v1","sequence":null,"source":"clob_market_ws"}
{"event_at":"2026-07-27T03:22:26.378000Z","event_fingerprint":"64c057101a49369897690e6ab09da6c204300e4276fd122adf234091bcb423ad","payload":{"connection_id":"c7dc2e4762f849c6b6f9306b6518dcab","event_at":"2026-07-27T03:22:26.378000Z","event_type":"price_change","frame_hash":"67f64c78edd9286b19b9c0fbae170a00f8a04dc1c1e905ad613454adfa228845","frame_index":0,"kind":"data","monotonic_ns":224529613400500,"payload":{"event_type":"price_change","market":"0x717c0e8ccd4d5c7040185188fbae28be901ca589a11a94b1b38ca36a79eccfeb","price_changes":[{"asset_id":"24254094493625419915756280046002869097156693848522361803041977572204227262166","best_ask":"0.45","best_bid":"0.44","hash":"ad3ec255741a26d32da3266c6b0b604f8b075958","price":"0.4","side":"BUY","size":"15"},{"asset_id":"41448400836309843603620980831210604935021861034693225347475867885462478926555","best_ask":"0.56","best_bid":"0.55","hash":"bbad4124b257ac5cf391f973f615bcdfb19cea2e","price":"0.6","side":"SELL","size":"15"}],"timestamp":"1785122546378"},"payload_hash":"c9a3c16d9c35d4e923ac2e46bc556080753185b6123d216a4e1dd64b320d46ec","raw_frame":"{\"market\":\"0x717c0e8ccd4d5c7040185188fbae28be901ca589a11a94b1b38ca36a79eccfeb\", \"price_changes\":[{\"asset_id\":\"24254094493625419915756280046002869097156693848522361803041977572204227262166\", \"price\":\"0.4\", \"size\":\"15\", \"side\":\"BUY\", \"hash\":\"ad3ec255741a26d32da3266c6b0b604f8b075958\", \"best_bid\":\"0.44\", \"best_ask\":\"0.45\"}, {\"asset_id\":\"41448400836309843603620980831210604935021861034693225347475867885462478926555\", \"price\":\"0.6\", \"size\":\"15\", \"side\":\"SELL\", \"hash\":\"bbad4124b257ac5cf391f973f615bcdfb19cea2e\", \"best_bid\":\"0.55\", \"best_ask\":\"0.56\"}], \"timestamp\":\"1785122546378\", \"event_type\":\"price_change\"}","received_at":"2026-07-27T03:22:26.257219Z","schema_version":"clob-market-ws.price_change.v1","sequence":null,"server_hash":null,"server_timestamp":"1785122546378","session_id":"dd162b8dca5f43ff811d304e69a06123","source":"clob_market_ws"},"received_at":"2026-07-27T03:22:26.257219Z","record_id":"d15303384340469a50a91223d0fb0671603f95dfaf18c5f9704d33a2844ee013","schema_fingerprint":"4aa3821a28b0b7c2400bc59aba4bcc0a76e971dadd19610d3ad38c768e124dc7","schema_version":"edge-lab-recorder.raw.v1","sequence":null,"source":"clob_market_ws"}
{"event_at":"2026-07-27T03:22:26.379000Z","event_fingerprint":"8a668f27805a8ef2f91704559e9b212b5d33b970707d8f79fd5fd2969d87cbef","payload":{"connection_id":"c7dc2e4762f849c6b6f9306b6518dcab","event_at":"2026-07-27T03:22:26.379000Z","event_type":"price_change","frame_hash":"0ad274ff40e1952a4fa949fc2a6dc576cdbd0680ad5d22a662b44befc0ff2aa4","frame_index":0,"kind":"data","monotonic_ns":224529615850541,"payload":{"event_type":"price_change","market":"0x717c0e8ccd4d5c7040185188fbae28be901ca589a11a94b1b38ca36a79eccfeb","price_changes":[{"asset_id":"41448400836309843603620980831210604935021861034693225347475867885462478926555","best_ask":"0.56","best_bid":"0.55","hash":"b6935056c3c605fac22dd6388cb2d4ae06a80b5b","price":"0.45","side":"BUY","size":"115"},{"asset_id":"24254094493625419915756280046002869097156693848522361803041977572204227262166","best_ask":"0.45","best_bid":"0.44","hash":"48788da9d0119cc57b2d7f007676d93e27524821","price":"0.55","side":"SELL","size":"115"}],"timestamp":"1785122546379"},"payload_hash":"28b06927708e1c30ea1702e89625f99fa5e279bb6bf7014f204797b621c1fac7","raw_frame":"{\"market\":\"0x717c0e8ccd4d5c7040185188fbae28be901ca589a11a94b1b38ca36a79eccfeb\", \"price_changes\":[{\"asset_id\":\"41448400836309843603620980831210604935021861034693225347475867885462478926555\", \"price\":\"0.45\", \"size\":\"115\", \"side\":\"BUY\", \"hash\":\"b6935056c3c605fac22dd6388cb2d4ae06a80b5b\", \"best_bid\":\"0.55\", \"best_ask\":\"0.56\"}, {\"asset_id\":\"24254094493625419915756280046002869097156693848522361803041977572204227262166\", \"price\":\"0.55\", \"size\":\"115\", \"side\":\"SELL\", \"hash\":\"48788da9d0119cc57b2d7f007676d93e27524821\", \"best_bid\":\"0.44\", \"best_ask\":\"0.45\"}], \"timestamp\":\"1785122546379\", \"event_type\":\"price_change\"}","received_at":"2026-07-27T03:22:26.259670Z","schema_version":"clob-market-ws.price_change.v1","sequence":null,"server_hash":null,"server_timestamp":"1785122546379","session_id":"dd162b8dca5f43ff811d304e69a06123","source":"clob_market_ws"},"received_at":"2026-07-27T03:22:26.259670Z","record_id":"df4220556683ea6508b9f88b821433dca3649197282bfec5949a894c2a28d214","schema_fingerprint":"4aa3821a28b0b7c2400bc59aba4bcc0a76e971dadd19610d3ad38c768e124dc7","schema_version":"edge-lab-recorder.raw.v1","sequence":null,"source":"clob_market_ws"}
{"event_at":"2026-07-27T03:22:26.381000Z","event_fingerprint":"8722ce7ea9c844b649007f805cf3662c982bec41798bfe67c92cd6436dbbc7ec","payload":{"connection_id":"c7dc2e4762f849c6b6f9306b6518dcab","event_at":"2026-07-27T03:22:26.381000Z","event_type":"price_change","frame_hash":"332cc6e74c1d405af6870f19f0f209e55e86d7fad16ddb713f47e1f29b71ed24","frame_index":0,"kind":"data","monotonic_ns":224529618813125,"payload":{"event_type":"price_change","market":"0x717c0e8ccd4d5c7040185188fbae28be901ca589a11a94b1b38ca36a79eccfeb","price_changes":[{"asset_id":"41448400836309843603620980831210604935021861034693225347475867885462478926555","best_ask":"0.56","best_bid":"0.55","hash":"3824289e7c7583a1e8f3a45eb75f4a0b85332355","price":"0.43","side":"BUY","size":"125.2"},{"asset_id":"24254094493625419915756280046002869097156693848522361803041977572204227262166","best_ask":"0.45","best_bid":"0.44","hash":"29a39cb88f3865fa494e358946b6046367064da9","price":"0.57","side":"SELL","size":"125.2"}],"timestamp":"1785122546381"},"payload_hash":"620b92ad37975cfd2d848d89cd660b894d0e9fc75507279473e34b46f6ec4eb0","raw_frame":"{\"market\":\"0x717c0e8ccd4d5c7040185188fbae28be901ca589a11a94b1b38ca36a79eccfeb\", \"price_changes\":[{\"asset_id\":\"41448400836309843603620980831210604935021861034693225347475867885462478926555\", \"price\":\"0.43\", \"size\":\"125.2\", \"side\":\"BUY\", \"hash\":\"3824289e7c7583a1e8f3a45eb75f4a0b85332355\", \"best_bid\":\"0.55\", \"best_ask\":\"0.56\"}, {\"asset_id\":\"24254094493625419915756280046002869097156693848522361803041977572204227262166\", \"price\":\"0.57\", \"size\":\"125.2\", \"side\":\"SELL\", \"hash\":\"29a39cb88f3865fa494e358946b6046367064da9\", \"best_bid\":\"0.44\", \"best_ask\":\"0.45\"}], \"timestamp\":\"1785122546381\", \"event_type\":\"price_change\"}","received_at":"2026-07-27T03:22:26.262632Z","schema_version":"clob-market-ws.price_change.v1","sequence":null,"server_hash":null,"server_timestamp":"1785122546381","session_id":"dd162b8dca5f43ff811d304e69a06123","source":"clob_market_ws"},"received_at":"2026-07-27T03:22:26.262632Z","record_id":"733a3e9839470f860bd4bc8a3fa01778211f98eda2a8fbb3245b0b94ef1a7333","schema_fingerprint":"4aa3821a28b0b7c2400bc59aba4bcc0a76e971dadd19610d3ad38c768e124dc7","schema_version":"edge-lab-recorder.raw.v1","sequence":null,"source":"clob_market_ws"}
{"event_at":"2026-07-27T03:22:26.383000Z","event_fingerprint":"2043007bf78f71fa4e25301bf6bd63f3dd8e27646400c3a5ef9c6920d6e13e6c","payload":{"connection_id":"c7dc2e4762f849c6b6f9306b6518dcab","event_at":"2026-07-27T03:22:26.383000Z","event_type":"price_change","frame_hash":"8cbec6bd0256cfde83e60118acaf4249cf32b684c3b040193498d9d430382d70","frame_index":0,"kind":"data","monotonic_ns":224529621873500,"payload":{"event_type":"price_change","market":"0x717c0e8ccd4d5c7040185188fbae28be901ca589a11a94b1b38ca36a79eccfeb","price_changes":[{"asset_id":"41448400836309843603620980831210604935021861034693225347475867885462478926555","best_ask":"0.56","best_bid":"0.55","hash":"af49c848754eb2b304566dbda56118b8d6446359","price":"0.44","side":"BUY","size":"235"},{"asset_id":"24254094493625419915756280046002869097156693848522361803041977572204227262166","best_ask":"0.45","best_bid":"0.44","hash":"55099176b21b34087191f6e0c186728cd4a1013c","price":"0.56","side":"SELL","size":"235"}],"timestamp":"1785122546383"},"payload_hash":"6f001b53dcdd1b73f3838c8f309c3d896166d4a150e5830cbc08a20e671c2d84","raw_frame":"{\"market\":\"0x717c0e8ccd4d5c7040185188fbae28be901ca589a11a94b1b38ca36a79eccfeb\", \"price_changes\":[{\"asset_id\":\"41448400836309843603620980831210604935021861034693225347475867885462478926555\", \"price\":\"0.44\", \"size\":\"235\", \"side\":\"BUY\", \"hash\":\"af49c848754eb2b304566dbda56118b8d6446359\", \"best_bid\":\"0.55\", \"best_ask\":\"0.56\"}, {\"asset_id\":\"24254094493625419915756280046002869097156693848522361803041977572204227262166\", \"price\":\"0.56\", \"size\":\"235\", \"side\":\"SELL\", \"hash\":\"55099176b21b34087191f6e0c186728cd4a1013c\", \"best_bid\":\"0.44\", \"best_ask\":\"0.45\"}], \"timestamp\":\"1785122546383\", \"event_type\":\"price_change\"}","received_at":"2026-07-27T03:22:26.265693Z","schema_version":"clob-market-ws.price_change.v1","sequence":null,"server_hash":null,"server_timestamp":"1785122546383","session_id":"dd162b8dca5f43ff811d304e69a06123","source":"clob_market_ws"},"received_at":"2026-07-27T03:22:26.265693Z","record_id":"8035c13fb0f841a6c950990a59b5faecde9e54cd88f8d4e7355d97571d494e8c","schema_fingerprint":"4aa3821a28b0b7c2400bc59aba4bcc0a76e971dadd19610d3ad38c768e124dc7","schema_version":"edge-lab-recorder.raw.v1","sequence":null,"source":"clob_market_ws"}
{"event_at":"2026-07-27T03:22:26.389000Z","event_fingerprint":"4376ed8bb5fde72e963a22f84f4e261c5e4172647dfaf5fc95b069dfdeaa86df","payload":{"connection_id":"c7dc2e4762f849c6b6f9306b6518dcab","event_at":"2026-07-27T03:22:26.389000Z","event_type":"price_change","frame_hash":"b1e6fe70130f0391fb0ee0ed437ec6f31a66f1be8dfdfc5ab040dd71da83731e","frame_index":0,"kind":"data","monotonic_ns":224529625289875,"payload":{"event_type":"price_change","market":"0x717c0e8ccd4d5c7040185188fbae28be901ca589a11a94b1b38ca36a79eccfeb","price_changes":[{"asset_id":"41448400836309843603620980831210604935021861034693225347475867885462478926555","best_ask":"0.56","best_bid":"0.55","hash":"7b28422c8651b27fea7e347cb7ff52cbfdcbdb50","price":"0.03","side":"BUY","size":"613.1"},{"asset_id":"24254094493625419915756280046002869097156693848522361803041977572204227262166","best_ask":"0.45","best_bid":"0.44","hash":"e11a160e8d37769721b71a3becfbb674cbb03953","price":"0.97","side":"SELL","size":"613.1"}],"timestamp":"1785122546389"},"payload_hash":"82bc7fe816e3c40ce6975acd00931710a0ec03c6ffbb3a468d5ee9425ed0734e","raw_frame":"{\"market\":\"0x717c0e8ccd4d5c7040185188fbae28be901ca589a11a94b1b38ca36a79eccfeb\", \"price_changes\":[{\"asset_id\":\"41448400836309843603620980831210604935021861034693225347475867885462478926555\", \"price\":\"0.03\", \"size\":\"613.1\", \"side\":\"BUY\", \"hash\":\"7b28422c8651b27fea7e347cb7ff52cbfdcbdb50\", \"best_bid\":\"0.55\", \"best_ask\":\"0.56\"}, {\"asset_id\":\"24254094493625419915756280046002869097156693848522361803041977572204227262166\", \"price\":\"0.97\", \"size\":\"613.1\", \"side\":\"SELL\", \"hash\":\"e11a160e8d37769721b71a3becfbb674cbb03953\", \"best_bid\":\"0.44\", \"best_ask\":\"0.45\"}], \"timestamp\":\"1785122546389\", \"event_type\":\"price_change\"}","received_at":"2026-07-27T03:22:26.269107Z","schema_version":"clob-market-ws.price_change.v1","sequence":null,"server_hash":null,"server_timestamp":"1785122546389","session_id":"dd162b8dca5f43ff811d304e69a06123","source":"clob_market_ws"},"received_at":"2026-07-27T03:22:26.269107Z","record_id":"228f0389ec1e4e119a05ea971e05f1a5ae5fa24396846184a1773a13d8e35d49","schema_fingerprint":"4aa3821a28b0b7c2400bc59aba4bcc0a76e971dadd19610d3ad38c768e124dc7","schema_version":"edge-lab-recorder.raw.v1","sequence":null,"source":"clob_market_ws"}
{"event_at":"2026-07-27T03:22:26.399000Z","event_fingerprint":"e873a642a1200dfda0f6b79122b6b4585c3079f6a4bfd8566b33d1cd5675b678","payload":{"connection_id":"c7dc2e4762f849c6b6f9306b6518dcab","event_at":"2026-07-27T03:22:26.399000Z","event_type":"price_change","frame_hash":"7bf97f78e167a7f348ed43da18bbdfa49ce49dc5219b04018b85ef9410e3181c","frame_index":0,"kind":"data","monotonic_ns":224529632901000,"payload":{"event_type":"price_change","market":"0x717c0e8ccd4d5c7040185188fbae28be901ca589a11a94b1b38ca36a79eccfeb","price_changes":[{"asset_id":"41448400836309843603620980831210604935021861034693225347475867885462478926555","best_ask":"0.56","best_bid":"0.55","hash":"ac2e558385faff1fedd00808ef536a59068f5504","price":"0.48","side":"BUY","size":"106.5"},{"asset_id":"24254094493625419915756280046002869097156693848522361803041977572204227262166","best_ask":"0.45","best_bid":"0.44","hash":"b2958a523d0b15d913afab66790c7828d541807d","price":"0.52","side":"SELL","size":"106.5"}],"timestamp":"1785122546399"},"payload_hash":"409170382f413dc097f3ad4aefbb2de698dc9bb7e40857d65eab42ec0ae6859a","raw_frame":"{\"market\":\"0x717c0e8ccd4d5c7040185188fbae28be901ca589a11a94b1b38ca36a79eccfeb\", \"price_changes\":[{\"asset_id\":\"41448400836309843603620980831210604935021861034693225347475867885462478926555\", \"price\":\"0.48\", \"size\":\"106.5\", \"side\":\"BUY\", \"hash\":\"ac2e558385faff1fedd00808ef536a59068f5504\", \"best_bid\":\"0.55\", \"best_ask\":\"0.56\"}, {\"asset_id\":\"24254094493625419915756280046002869097156693848522361803041977572204227262166\", \"price\":\"0.52\", \"size\":\"106.5\", \"side\":\"SELL\", \"hash\":\"b2958a523d0b15d913afab66790c7828d541807d\", \"best_bid\":\"0.44\", \"best_ask\":\"0.45\"}], \"timestamp\":\"1785122546399\", \"event_type\":\"price_change\"}","received_at":"2026-07-27T03:22:26.276719Z","schema_version":"clob-market-ws.price_change.v1","sequence":null,"server_hash":null,"server_timestamp":"1785122546399","session_id":"dd162b8dca5f43ff811d304e69a06123","source":"clob_market_ws"},"received_at":"2026-07-27T03:22:26.276719Z","record_id":"31264d6849a460721b891133b095fc658682af86c21b05b3c2d0e883421bf54f","schema_fingerprint":"4aa3821a28b0b7c2400bc59aba4bcc0a76e971dadd19610d3ad38c768e124dc7","schema_version":"edge-lab-recorder.raw.v1","sequence":null,"source":"clob_market_ws"}
{"event_at":"2026-07-27T03:22:26.405000Z","event_fingerprint":"cf28f65d5fd7143ef4b5fb77fc06bf6534ef08705505623105dbcb00ad8295e4","payload":{"connection_id":"c7dc2e4762f849c6b6f9306b6518dcab","event_at":"2026-07-27T03:22:26.405000Z","event_type":"price_change","frame_hash":"e5408c30860ffdcaccf416b0698687ac225766f12bff7a840f426f1251ab0ed3","frame_index":0,"kind":"data","monotonic_ns":224529640283916,"payload":{"event_type":"price_change","market":"0x717c0e8ccd4d5c7040185188fbae28be901ca589a11a94b1b38ca36a79eccfeb","price_changes":[{"asset_id":"41448400836309843603620980831210604935021861034693225347475867885462478926555","best_ask":"0.56","best_bid":"0.55","hash":"4243a131d99c527d5185632fb855198b8d3f8c41","price":"0.52","side":"BUY","size":"21.6"},{"asset_id":"24254094493625419915756280046002869097156693848522361803041977572204227262166","best_ask":"0.45","best_bid":"0.44","hash":"8831a52642dbf6e23b58c9041c5df627679645a0","price":"0.48","side":"SELL","size":"21.6"}],"timestamp":"1785122546405"},"payload_hash":"746e92107f58d00b0ca32670965b26ab20792c72d394ba8614cfd3c6beb5b45b","raw_frame":"{\"market\":\"0x717c0e8ccd4d5c7040185188fbae28be901ca589a11a94b1b38ca36a79eccfeb\", \"price_changes\":[{\"asset_id\":\"41448400836309843603620980831210604935021861034693225347475867885462478926555\", \"price\":\"0.52\", \"size\":\"21.6\", \"side\":\"BUY\", \"hash\":\"4243a131d99c527d5185632fb855198b8d3f8c41\", \"best_bid\":\"0.55\", \"best_ask\":\"0.56\"}, {\"asset_id\":\"24254094493625419915756280046002869097156693848522361803041977572204227262166\", \"price\":\"0.48\", \"size\":\"21.6\", \"side\":\"SELL\", \"hash\":\"8831a52642dbf6e23b58c9041c5df627679645a0\", \"best_bid\":\"0.44\", \"best_ask\":\"0.45\"}], \"timestamp\":\"1785122546405\", \"event_type\":\"price_change\"}","received_at":"2026-07-27T03:22:26.284100Z","schema_version":"clob-market-ws.price_change.v1","sequence":null,"server_hash":null,"server_timestamp":"1785122546405","session_id":"dd162b8dca5f43ff811d304e69a06123","source":"clob_market_ws"},"received_at":"2026-07-27T03:22:26.284100Z","record_id":"9f8d8f67b20dd5a31912941204324378dd19451cd436d3c75f9b07fba8490948","schema_fingerprint":"4aa3821a28b0b7c2400bc59aba4bcc0a76e971dadd19610d3ad38c768e124dc7","schema_version":"edge-lab-recorder.raw.v1","sequence":null,"source":"clob_market_ws"}
{"event_at":"2026-07-27T03:22:26.414000Z","event_fingerprint":"144c44a98cc99eeb14e715b2a644ee579ece5c2d29fbbd5ae4230327419c9fe7","payload":{"connection_id":"c7dc2e4762f849c6b6f9306b6518dcab","event_at":"2026-07-27T03:22:26.414000Z","event_type":"price_change","frame_hash":"390bd82483254721187800389c4aaf3563d2959c737dbff7ddfe6d51f47780bf","frame_index":0,"kind":"data","monotonic_ns":224529649478125,"payload":{"event_type":"price_change","market":"0x717c0e8ccd4d5c7040185188fbae28be901ca589a11a94b1b38ca36a79eccfeb","price_changes":[{"asset_id":"41448400836309843603620980831210604935021861034693225347475867885462478926555","best_ask":"0.56","best_bid":"0.55","hash":"09e2345b2620260805752c18347daaa1e5683f34","price":"0.01","side":"BUY","size":"5458.02"},{"asset_id":"24254094493625419915756280046002869097156693848522361803041977572204227262166","best_ask":"0.45","best_bid":"0.44","hash":"f7bdf4042c70eb4925aa24814cd1b386c53829af","price":"0.99","side":"SELL","size":"5458.02"}],"timestamp":"1785122546414"},"payload_hash":"971fd33b0d1480c10f2f0aaf075e3c35c66dbf14da59058eab669843f8bea0ec","raw_frame":"{\"market\":\"0x717c0e8ccd4d5c7040185188fbae28be901ca589a11a94b1b38ca36a79eccfeb\", \"price_changes\":[{\"asset_id\":\"41448400836309843603620980831210604935021861034693225347475867885462478926555\", \"price\":\"0.01\", \"size\":\"5458.02\", \"side\":\"BUY\", \"hash\":\"09e2345b2620260805752c18347daaa1e5683f34\", \"best_bid\":\"0.55\", \"best_ask\":\"0.56\"}, {\"asset_id\":\"24254094493625419915756280046002869097156693848522361803041977572204227262166\", \"price\":\"0.99\", \"size\":\"5458.02\", \"side\":\"SELL\", \"hash\":\"f7bdf4042c70eb4925aa24814cd1b386c53829af\", \"best_bid\":\"0.44\", \"best_ask\":\"0.45\"}], \"timestamp\":\"1785122546414\", \"event_type\":\"price_change\"}","received_at":"2026-07-27T03:22:26.293295Z","schema_version":"clob-market-ws.price_change.v1","sequence":null,"server_hash":null,"server_timestamp":"1785122546414","session_id":"dd162b8dca5f43ff811d304e69a06123","source":"clob_market_ws"},"received_at":"2026-07-27T03:22:26.293295Z","record_id":"830303b518c2d92bd4425dab3c313edc70218063a6bbdb8457af1dd041e6faac","schema_fingerprint":"4aa3821a28b0b7c2400bc59aba4bcc0a76e971dadd19610d3ad38c768e124dc7","schema_version":"edge-lab-recorder.raw.v1","sequence":null,"source":"clob_market_ws"}
{"event_at":"2026-07-27T03:22:26.439000Z","event_fingerprint":"cdc1b93121afd1fe0f774158d4cfc32e2d18f47c34dc8cbc04c317ba6efb8703","payload":{"connection_id":"c7dc2e4762f849c6b6f9306b6518dcab","event_at":"2026-07-27T03:22:26.439000Z","event_type":"price_change","frame_hash":"c3f92a335ce0feaf86059cf100f676a52aa4efb31b2a995926aaa2f8feef2e7f","frame_index":0,"kind":"data","monotonic_ns":224529673115875,"payload":{"event_type":"price_change","market":"0x717c0e8ccd4d5c7040185188fbae28be901ca589a11a94b1b38ca36a79eccfeb","price_changes":[{"asset_id":"24254094493625419915756280046002869097156693848522361803041977572204227262166","best_ask":"0.45","best_bid":"0.44","hash":"765222fa23efa5c9b95c8e36e8a0995b55a246bc","price":"0.45","side":"SELL","size":"52"},{"asset_id":"41448400836309843603620980831210604935021861034693225347475867885462478926555","best_ask":"0.56","best_bid":"0.55","hash":"a5d641ea5565b657305080066345c0e48673d822","price":"0.55","side":"BUY","size":"52"}],"timestamp":"1785122546439"},"payload_hash":"a0862a99c1d6527d46b3e1fafc61c96331cc5f0ff68c10130c7475cb79e29601","raw_frame":"{\"market\":\"0x717c0e8ccd4d5c7040185188fbae28be901ca589a11a94b1b38ca36a79eccfeb\", \"price_changes\":[{\"asset_id\":\"24254094493625419915756280046002869097156693848522361803041977572204227262166\", \"price\":\"0.45\", \"size\":\"52\", \"side\":\"SELL\", \"hash\":\"765222fa23efa5c9b95c8e36e8a0995b55a246bc\", \"best_bid\":\"0.44\", \"best_ask\":\"0.45\"}, {\"asset_id\":\"41448400836309843603620980831210604935021861034693225347475867885462478926555\", \"price\":\"0.55\", \"size\":\"52\", \"side\":\"BUY\", \"hash\":\"a5d641ea5565b657305080066345c0e48673d822\", \"best_bid\":\"0.55\", \"best_ask\":\"0.56\"}], \"timestamp\":\"1785122546439\", \"event_type\":\"price_change\"}","received_at":"2026-07-27T03:22:26.316932Z","schema_version":"clob-market-ws.price_change.v1","sequence":null,"server_hash":null,"server_timestamp":"1785122546439","session_id":"dd162b8dca5f43ff811d304e69a06123","source":"clob_market_ws"},"received_at":"2026-07-27T03:22:26.316932Z","record_id":"efb307941935622333a47348bc3b3056f357f790cccb89a5b97ff6850bce132f","schema_fingerprint":"4aa3821a28b0b7c2400bc59aba4bcc0a76e971dadd19610d3ad38c768e124dc7","schema_version":"edge-lab-recorder.raw.v1","sequence":null,"source":"clob_market_ws"}
{"event_at":"2026-07-27T03:22:26.459000Z","event_fingerprint":"c27feffbe06c430062ce4f1c42e5cc0f727e7e6be5ecde91957053398d191461","payload":{"connection_id":"c7dc2e4762f849c6b6f9306b6518dcab","event_at":"2026-07-27T03:22:26.459000Z","event_type":"price_change","frame_hash":"60dc25e06a157695ad11bc2f08499b5614a40f5af11d684fbb005e7d42ace2cc","frame_index":0,"kind":"data","monotonic_ns":224529695394291,"payload":{"event_type":"price_change","market":"0x717c0e8ccd4d5c7040185188fbae28be901ca589a11a94b1b38ca36a79eccfeb","price_changes":[{"asset_id":"41448400836309843603620980831210604935021861034693225347475867885462478926555","best_ask":"0.56","best_bid":"0.55","hash":"052329affb6de9a803369d78ee8fa55ed764ba7c","price":"0.01","side":"BUY","size":"5453.02"},{"asset_id":"24254094493625419915756280046002869097156693848522361803041977572204227262166","best_ask":"0.45","best_bid":"0.44","hash":"c79447645ec6a90b0bf3717c9b3037c5c8651e2b","price":"0.99","side":"SELL","size":"5453.02"}],"timestamp":"1785122546459"},"payload_hash":"ad50d8d84a28a29ef93045fb0cabbdb2f1536cdbe8f7bc9c7b73f6defd533000","raw_frame":"{\"market\":\"0x717c0e8ccd4d5c7040185188fbae28be901ca589a11a94b1b38ca36a79eccfeb\", \"price_changes\":[{\"asset_id\":\"41448400836309843603620980831210604935021861034693225347475867885462478926555\", \"price\":\"0.01\", \"size\":\"5453.02\", \"side\":\"BUY\", \"hash\":\"052329affb6de9a803369d78ee8fa55ed764ba7c\", \"best_bid\":\"0.55\", \"best_ask\":\"0.56\"}, {\"asset_id\":\"24254094493625419915756280046002869097156693848522361803041977572204227262166\", \"price\":\"0.99\", \"size\":\"5453.02\", \"side\":\"SELL\", \"hash\":\"c79447645ec6a90b0bf3717c9b3037c5c8651e2b\", \"best_bid\":\"0.44\", \"best_ask\":\"0.45\"}], \"timestamp\":\"1785122546459\", \"event_type\":\"price_change\"}","received_at":"2026-07-27T03:22:26.339206Z","schema_version":"clob-market-ws.price_change.v1","sequence":null,"server_hash":null,"server_timestamp":"1785122546459","session_id":"dd162b8dca5f43ff811d304e69a06123","source":"clob_market_ws"},"received_at":"2026-07-27T03:22:26.339206Z","record_id":"f1471d51404d9ecc743e2ba3e1b324e960c5aac8ab9b1100a5d31d7a3344cfa1","schema_fingerprint":"4aa3821a28b0b7c2400bc59aba4bcc0a76e971dadd19610d3ad38c768e124dc7","schema_version":"edge-lab-recorder.raw.v1","sequence":null,"source":"clob_market_ws"}
{"event_at":"2026-07-27T03:22:26.461000Z","event_fingerprint":"18c7de5f53596740416013ddb8269e28f441b18caa2f3d09c1b06b484eef9c88","payload":{"connection_id":"c7dc2e4762f849c6b6f9306b6518dcab","event_at":"2026-07-27T03:22:26.461000Z","event_type":"price_change","frame_hash":"316717fd75eb590e19e1bc60d9ddbf6dc8872071b28fd75dece3965fdb1b6885","frame_index":0,"kind":"data","monotonic_ns":224529697062166,"payload":{"event_type":"price_change","market":"0x717c0e8ccd4d5c7040185188fbae28be901ca589a11a94b1b38ca36a79eccfeb","price_changes":[{"asset_id":"24254094493625419915756280046002869097156693848522361803041977572204227262166","best_ask":"0.45","best_bid":"0.44","hash":"1f90ba8a75fef9b7a30b80a06576b47ff19b65ce","price":"0.3","side":"BUY","size":"120.3"},{"asset_id":"41448400836309843603620980831210604935021861034693225347475867885462478926555","best_ask":"0.56","best_bid":"0.55","hash":"31793f82b3be370292e9d08083a72c99850c65b4","price":"0.7","side":"SELL","size":"120.3"}],"timestamp":"1785122546461"},"payload_hash":"fdbde6515e0cb605bf835dcb088b9a2435139f022fe51477c553100707025f44","raw_frame":"{\"market\":\"0x717c0e8ccd4d5c7040185188fbae28be901ca589a11a94b1b38ca36a79eccfeb\", \"price_changes\":[{\"asset_id\":\"24254094493625419915756280046002869097156693848522361803041977572204227262166\", \"price\":\"0.3\", \"size\":\"120.3\", \"side\":\"BUY\", \"hash\":\"1f90ba8a75fef9b7a30b80a06576b47ff19b65ce\", \"best_bid\":\"0.44\", \"best_ask\":\"0.45\"}, {\"asset_id\":\"41448400836309843603620980831210604935021861034693225347475867885462478926555\", \"price\":\"0.7\", \"size\":\"120.3\", \"side\":\"SELL\", \"hash\":\"31793f82b3be370292e9d08083a72c99850c65b4\", \"best_bid\":\"0.55\", \"best_ask\":\"0.56\"}], \"timestamp\":\"1785122546461\", \"event_type\":\"price_change\"}","received_at":"2026-07-27T03:22:26.340877Z","schema_version":"clob-market-ws.price_change.v1","sequence":null,"server_hash":null,"server_timestamp":"1785122546461","session_id":"dd162b8dca5f43ff811d304e69a06123","source":"clob_market_ws"},"received_at":"2026-07-27T03:22:26.340877Z","record_id":"4ad59b81c0e307220d61e369191c4c0bfa16ca2a9646abfead908ed937f97438","schema_fingerprint":"4aa3821a28b0b7c2400bc59aba4bcc0a76e971dadd19610d3ad38c768e124dc7","schema_version":"edge-lab-recorder.raw.v1","sequence":null,"source":"clob_market_ws"}
{"event_at":"2026-07-27T03:22:26.466000Z","event_fingerprint":"8aac30158a89572e818546d1934c8abee43163021cb3cb202a55ceeff815f2e5","payload":{"connection_id":"c7dc2e4762f849c6b6f9306b6518dcab","event_at":"2026-07-27T03:22:26.466000Z","event_type":"price_change","frame_hash":"0a7eb29db6416ef82f19a46b48a57e2c32b94bb8f24cf9673c71be1496f6bdad","frame_index":0,"kind":"data","monotonic_ns":224529700720750,"payload":{"event_type":"price_change","market":"0x717c0e8ccd4d5c7040185188fbae28be901ca589a11a94b1b38ca36a79eccfeb","price_changes":[{"asset_id":"41448400836309843603620980831210604935021861034693225347475867885462478926555","best_ask":"0.56","best_bid":"0.55","hash":"52d6d18eafd09709c19fdade4918380f09279893","price":"0.02","side":"BUY","size":"688.1"},{"asset_id":"24254094493625419915756280046002869097156693848522361803041977572204227262166","best_ask":"0.45","best_bid":"0.44","hash":"28fedda57e99f7451ff2c3b427af94222dcbdb02","price":"0.98","side":"SELL","size":"688.1"}],"timestamp":"1785122546466"},"payload_hash":"c184deb042b21eadd22e8fcd1ba8b83b9446af2c76741cdf0eabc877c12255b6","raw_frame":"{\"market\":\"0x717c0e8ccd4d5c7040185188fbae28be901ca589a11a94b1b38ca36a79eccfeb\", \"price_changes\":[{\"asset_id\":\"41448400836309843603620980831210604935021861034693225347475867885462478926555\", \"price\":\"0.02\", \"size\":\"688.1\", \"side\":\"BUY\", \"hash\":\"52d6d18eafd09709c19fdade4918380f09279893\", \"best_bid\":\"0.55\", \"best_ask\":\"0.56\"}, {\"asset_id\":\"24254094493625419915756280046002869097156693848522361803041977572204227262166\", \"price\":\"0.98\", \"size\":\"688.1\", \"side\":\"SELL\", \"hash\":\"28fedda57e99f7451ff2c3b427af94222dcbdb02\", \"best_bid\":\"0.44\", \"best_ask\":\"0.45\"}], \"timestamp\":\"1785122546466\", \"event_type\":\"price_change\"}","received_at":"2026-07-27T03:22:26.344535Z","schema_version":"clob-market-ws.price_change.v1","sequence":null,"server_hash":null,"server_timestamp":"1785122546466","session_id":"dd162b8dca5f43ff811d304e69a06123","source":"clob_market_ws"},"received_at":"2026-07-27T03:22:26.344535Z","record_id":"17f1967e24de2ccd611f59e9818ad01632daf66a216ab2bbe11fe5ae4c1f09b1","schema_fingerprint":"4aa3821a28b0b7c2400bc59aba4bcc0a76e971dadd19610d3ad38c768e124dc7","schema_version":"edge-lab-recorder.raw.v1","sequence":null,"source":"clob_market_ws"}
{"event_at":"2026-07-27T03:22:26.470000Z","event_fingerprint":"de6f598ea5113a09466efeb9efd8685238c03291f4cdda4fd7d804a27056be79","payload":{"connection_id":"c7dc2e4762f849c6b6f9306b6518dcab","event_at":"2026-07-27T03:22:26.470000Z","event_type":"price_change","frame_hash":"ea5bfd85809b008394cda0fb25a5527d2c295628068cd9619eed82da0295203b","frame_index":0,"kind":"data","monotonic_ns":224529705552708,"payload":{"event_type":"price_change","market":"0x717c0e8ccd4d5c7040185188fbae28be901ca589a11a94b1b38ca36a79eccfeb","price_changes":[{"asset_id":"41448400836309843603620980831210604935021861034693225347475867885462478926555","best_ask":"0.56","best_bid":"0.55","hash":"3fb3bfce4cbed023ea18a6688afb3989beb8ce1c","price":"0.63","side":"SELL","size":"207"},{"asset_id":"24254094493625419915756280046002869097156693848522361803041977572204227262166","best_ask":"0.45","best_bid":"0.44","hash":"843d6ec96f3d0d5a2280afe2a69dedb7b0bf0230","price":"0.37","side":"BUY","size":"207"}],"timestamp":"1785122546470"},"payload_hash":"deef645cd74e3ccff78bb7af95a4ee7e8a8c18700a3c8225ee5bd144020dc6f5","raw_frame":"{\"market\":\"0x717c0e8ccd4d5c7040185188fbae28be901ca589a11a94b1b38ca36a79eccfeb\", \"price_changes\":[{\"asset_id\":\"41448400836309843603620980831210604935021861034693225347475867885462478926555\", \"price\":\"0.63\", \"size\":\"207\", \"side\":\"SELL\", \"hash\":\"3fb3bfce4cbed023ea18a6688afb3989beb8ce1c\", \"best_bid\":\"0.55\", \"best_ask\":\"0.56\"}, {\"asset_id\":\"24254094493625419915756280046002869097156693848522361803041977572204227262166\", \"price\":\"0.37\", \"size\":\"207\", \"side\":\"BUY\", \"hash\":\"843d6ec96f3d0d5a2280afe2a69dedb7b0bf0230\", \"best_bid\":\"0.44\", \"best_ask\":\"0.45\"}], \"timestamp\":\"1785122546470\", \"event_type\":\"price_change\"}","received_at":"2026-07-27T03:22:26.349370Z","schema_version":"clob-market-ws.price_change.v1","sequence":null,"server_hash":null,"server_timestamp":"1785122546470","session_id":"dd162b8dca5f43ff811d304e69a06123","source":"clob_market_ws"},"received_at":"2026-07-27T03:22:26.349370Z","record_id":"89c213593782ec05e8f92a75fef9c0ae056c5c2b8eb45e217f911a0619ef9bad","schema_fingerprint":"4aa3821a28b0b7c2400bc59aba4bcc0a76e971dadd19610d3ad38c768e124dc7","schema_version":"edge-lab-recorder.raw.v1","sequence":null,"source":"clob_market_ws"}
{"event_at":"2026-07-27T03:22:26.479000Z","event_fingerprint":"9b242b3c81846d7da530faf441b523ebd9a15ef30b3c7e314c6c18065497076c","payload":{"connection_id":"c7dc2e4762f849c6b6f9306b6518dcab","event_at":"2026-07-27T03:22:26.479000Z","event_type":"price_change","frame_hash":"7703c75c6478b98cb4c8823800c83ae8fc34084117e4da006ac9c80a39ee74f2","frame_index":0,"kind":"data","monotonic_ns":224529713118916,"payload":{"event_type":"price_change","market":"0x717c0e8ccd4d5c7040185188fbae28be901ca589a11a94b1b38ca36a79eccfeb","price_changes":[{"asset_id":"24254094493625419915756280046002869097156693848522361803041977572204227262166","best_ask":"0.45","best_bid":"0.44","hash":"f1e5111f52ad8aefd9ef40b43e4b42f6fdae7825","price":"0.42","side":"BUY","size":"275"},{"asset_id":"41448400836309843603620980831210604935021861034693225347475867885462478926555","best_ask":"0.56","best_bid":"0.55","hash":"e1931a31a6907d5c6704c9732a485bd166a0904a","price":"0.58","side":"SELL","size":"275"}],"timestamp":"1785122546479"},"payload_hash":"fb43cdb9a0b72fb3c9b0cb6e6ab0535b524d0046bae100d870a655c185c5beee","raw_frame":"{\"market\":\"0x717c0e8ccd4d5c7040185188fbae28be901ca589a11a94b1b38ca36a79eccfeb\", \"price_changes\":[{\"asset_id\":\"24254094493625419915756280046002869097156693848522361803041977572204227262166\", \"price\":\"0.42\", \"size\":\"275\", \"side\":\"BUY\", \"hash\":\"f1e5111f52ad8aefd9ef40b43e4b42f6fdae7825\", \"best_bid\":\"0.44\", \"best_ask\":\"0.45\"}, {\"asset_id\":\"41448400836309843603620980831210604935021861034693225347475867885462478926555\", \"price\":\"0.58\", \"size\":\"275\", \"side\":\"SELL\", \"hash\":\"e1931a31a6907d5c6704c9732a485bd166a0904a\", \"best_bid\":\"0.55\", \"best_ask\":\"0.56\"}], \"timestamp\":\"1785122546479\", \"event_type\":\"price_change\"}","received_at":"2026-07-27T03:22:26.356931Z","schema_version":"clob-market-ws.price_change.v1","sequence":null,"server_hash":null,"server_timestamp":"1785122546479","session_id":"dd162b8dca5f43ff811d304e69a06123","source":"clob_market_ws"},"received_at":"2026-07-27T03:22:26.356931Z","record_id":"d76dd43936cba9555174c9677e08c5a502fb32ee024877bb140af2454d54f7b7","schema_fingerprint":"4aa3821a28b0b7c2400bc59aba4bcc0a76e971dadd19610d3ad38c768e124dc7","schema_version":"edge-lab-recorder.raw.v1","sequence":null,"source":"clob_market_ws"}
{"event_at":"2026-07-27T03:22:26.483000Z","event_fingerprint":"0e77eef548ce32195cef40c2231b85bf4608810796cc72ca83644d9735207841","payload":{"connection_id":"c7dc2e4762f849c6b6f9306b6518dcab","event_at":"2026-07-27T03:22:26.483000Z","event_type":"price_change","frame_hash":"71cce5dbd66a89fecdeabc0d7feae2c6dcdc2f75b754363aece3aec83e05f699","frame_index":0,"kind":"data","monotonic_ns":224529717455166,"payload":{"event_type":"price_change","market":"0x717c0e8ccd4d5c7040185188fbae28be901ca589a11a94b1b38ca36a79eccfeb","price_changes":[{"asset_id":"24254094493625419915756280046002869097156693848522361803041977572204227262166","best_ask":"0.45","best_bid":"0.44","hash":"1d6593d2fa04b23e98ae978d84f58db2538cff52","price":"0.37","side":"BUY","size":"232"},{"asset_id":"41448400836309843603620980831210604935021861034693225347475867885462478926555","best_ask":"0.56","best_bid":"0.55","hash":"ccdc3467924a84d2d2cc8510162169515c31f42d","price":"0.63","side":"SELL","size":"232"}],"timestamp":"1785122546483"},"payload_hash":"99db4b07f899fa6cf9b85976773b092005f49e802ae195409bd1009ac0fc1af2","raw_frame":"{\"market\":\"0x717c0e8ccd4d5c7040185188fbae28be901ca589a11a94b1b38ca36a79eccfeb\", \"price_changes\":[{\"asset_id\":\"24254094493625419915756280046002869097156693848522361803041977572204227262166\", \"price\":\"0.37\", \"size\":\"232\", \"side\":\"BUY\", \"hash\":\"1d6593d2fa04b23e98ae978d84f58db2538cff52\", \"best_bid\":\"0.44\", \"best_ask\":\"0.45\"}, {\"asset_id\":\"41448400836309843603620980831210604935021861034693225347475867885462478926555\", \"price\":\"0.63\", \"size\":\"232\", \"side\":\"SELL\", \"hash\":\"ccdc3467924a84d2d2cc8510162169515c31f42d\", \"best_bid\":\"0.55\", \"best_ask\":\"0.56\"}], \"timestamp\":\"1785122546483\", \"event_type\":\"price_change\"}","received_at":"2026-07-27T03:22:26.361273Z","schema_version":"clob-market-ws.price_change.v1","sequence":null,"server_hash":null,"server_timestamp":"1785122546483","session_id":"dd162b8dca5f43ff811d304e69a06123","source":"clob_market_ws"},"received_at":"2026-07-27T03:22:26.361273Z","record_id":"6c860e562a8f5ca044602c5597bd484d293dce826510dd8a219f7f10bf66f112","schema_fingerprint":"4aa3821a28b0b7c2400bc59aba4bcc0a76e971dadd19610d3ad38c768e124dc7","schema_version":"edge-lab-recorder.raw.v1","sequence":null,"source":"clob_market_ws"}
{"event_at":"2026-07-27T03:22:26.518000Z","event_fingerprint":"c4ad9d356e7c1397692ea3e21bf7168323fa7fd4b5c6855c1a6b06778e93c3dd","payload":{"connection_id":"c7dc2e4762f849c6b6f9306b6518dcab","event_at":"2026-07-27T03:22:26.518000Z","event_type":"price_change","frame_hash":"2f55641a528cf34179fc22f106ef64e4a540046f66e707d3ea1eb38813dd5b07","frame_index":0,"kind":"data","monotonic_ns":224529751957791,"payload":{"event_type":"price_change","market":"0x717c0e8ccd4d5c7040185188fbae28be901ca589a11a94b1b38ca36a79eccfeb","price_changes":[{"asset_id":"41448400836309843603620980831210604935021861034693225347475867885462478926555","best_ask":"0.56","best_bid":"0.55","hash":"a916719be4f41b1f05b58aa16ca2ea9074f7aa59","price":"0.02","side":"BUY","size":"683.1"},{"asset_id":"24254094493625419915756280046002869097156693848522361803041977572204227262166","best_ask":"0.45","best_bid":"0.44","hash":"998eaf8ff2e31d086bfe7ddd629abfefa78380d0","price":"0.98","side":"SELL","size":"683.1"}],"timestamp":"1785122546518"},"payload_hash":"47657c05ea145aee5e01d7c35de730d2f22a8d14ee0d027ae697dd47fab2ca2a","raw_frame":"{\"market\":\"0x717c0e8ccd4d5c7040185188fbae28be901ca589a11a94b1b38ca36a79eccfeb\", \"price_changes\":[{\"asset_id\":\"41448400836309843603620980831210604935021861034693225347475867885462478926555\", \"price\":\"0.02\", \"size\":\"683.1\", \"side\":\"BUY\", \"hash\":\"a916719be4f41b1f05b58aa16ca2ea9074f7aa59\", \"best_bid\":\"0.55\", \"best_ask\":\"0.56\"}, {\"asset_id\":\"24254094493625419915756280046002869097156693848522361803041977572204227262166\", \"price\":\"0.98\", \"size\":\"683.1\", \"side\":\"SELL\", \"hash\":\"998eaf8ff2e31d086bfe7ddd629abfefa78380d0\", \"best_bid\":\"0.44\", \"best_ask\":\"0.45\"}], \"timestamp\":\"1785122546518\", \"event_type\":\"price_change\"}","received_at":"2026-07-27T03:22:26.395772Z","schema_version":"clob-market-ws.price_change.v1","sequence":null,"server_hash":null,"server_timestamp":"1785122546518","session_id":"dd162b8dca5f43ff811d304e69a06123","source":"clob_market_ws"},"received_at":"2026-07-27T03:22:26.395772Z","record_id":"0d8c24efd4af19c31841a3aa12380d7941a06a64dae5ee91a17173303b2fa57b","schema_fingerprint":"4aa3821a28b0b7c2400bc59aba4bcc0a76e971dadd19610d3ad38c768e124dc7","schema_version":"edge-lab-recorder.raw.v1","sequence":null,"source":"clob_market_ws"}
{"event_at":"2026-07-27T03:22:26.620000Z","event_fingerprint":"34a15e179c03bc15abe9a21d9445b79f39b12163e50ddb0769e3abd16f95c832","payload":{"connection_id":"c7dc2e4762f849c6b6f9306b6518dcab","event_at":"2026-07-27T03:22:26.620000Z","event_type":"price_change","frame_hash":"ad43b5888577ddac9133e246266f2e2be50b212ea861a1231c47ede5173958ba","frame_index":0,"kind":"data","monotonic_ns":224529854256083,"payload":{"event_type":"price_change","market":"0x717c0e8ccd4d5c7040185188fbae28be901ca589a11a94b1b38ca36a79eccfeb","price_changes":[{"asset_id":"41448400836309843603620980831210604935021861034693225347475867885462478926555","best_ask":"0.56","best_bid":"0.55","hash":"69056f36bd58bd729a5c4b14b313733e0b30e1e2","price":"0.03","side":"BUY","size":"618.1"},{"asset_id":"24254094493625419915756280046002869097156693848522361803041977572204227262166","best_ask":"0.45","best_bid":"0.44","hash":"4dc36703e6e415f2e275fbedcf6baadbf765cfdc","price":"0.97","side":"SELL","size":"618.1"}],"timestamp":"1785122546620"},"payload_hash":"10389c4ad32442219e7aa54b0c56ca53914c2024edcd0e146351de02c2f20ee9","raw_frame":"{\"market\":\"0x717c0e8ccd4d5c7040185188fbae28be901ca589a11a94b1b38ca36a79eccfeb\", \"price_changes\":[{\"asset_id\":\"41448400836309843603620980831210604935021861034693225347475867885462478926555\", \"price\":\"0.03\", \"size\":\"618.1\", \"side\":\"BUY\", \"hash\":\"69056f36bd58bd729a5c4b14b313733e0b30e1e2\", \"best_bid\":\"0.55\", \"best_ask\":\"0.56\"}, {\"asset_id\":\"24254094493625419915756280046002869097156693848522361803041977572204227262166\", \"price\":\"0.97\", \"size\":\"618.1\", \"side\":\"SELL\", \"hash\":\"4dc36703e6e415f2e275fbedcf6baadbf765cfdc\", \"best_bid\":\"0.44\", \"best_ask\":\"0.45\"}], \"timestamp\":\"1785122546620\", \"event_type\":\"price_change\"}","received_at":"2026-07-27T03:22:26.498069Z","schema_version":"clob-market-ws.price_change.v1","sequence":null,"server_hash":null,"server_timestamp":"1785122546620","session_id":"dd162b8dca5f43ff811d304e69a06123","source":"clob_market_ws"},"received_at":"2026-07-27T03:22:26.498069Z","record_id":"fee935b605c9dd6fd9e5327851da7a2dfdad8dc54bd897ed9cbe46bcaa85d234","schema_fingerprint":"4aa3821a28b0b7c2400bc59aba4bcc0a76e971dadd19610d3ad38c768e124dc7","schema_version":"edge-lab-recorder.raw.v1","sequence":null,"source":"clob_market_ws"}
{"event_at":"2026-07-27T03:22:26.622000Z","event_fingerprint":"8d44de52da5911b9c6ef29f8552eec3f2b3fbe4c61a6714975fad3c1595dfaf6","payload":{"connection_id":"c7dc2e4762f849c6b6f9306b6518dcab","event_at":"2026-07-27T03:22:26.622000Z","event_type":"price_change","frame_hash":"ca4ae92bc4d0ea099642bed13217063767da5002017d90ed57c134d8fcbd1410","frame_index":0,"kind":"data","monotonic_ns":224529856643583,"payload":{"event_type":"price_change","market":"0x717c0e8ccd4d5c7040185188fbae28be901ca589a11a94b1b38ca36a79eccfeb","price_changes":[{"asset_id":"24254094493625419915756280046002869097156693848522361803041977572204227262166","best_ask":"0.45","best_bid":"0.44","hash":"9b3baff8431441fb4ddf721de9b1d7aaaf89560a","price":"0.4","side":"BUY","size":"10"},{"asset_id":"41448400836309843603620980831210604935021861034693225347475867885462478926555","best_ask":"0.56","best_bid":"0.55","hash":"667de60e441856e947d490f639139cae65b8f67f","price":"0.6","side":"SELL","size":"10"}],"timestamp":"1785122546622"},"payload_hash":"5709ef9ed5b5a900874794080699cd0bf2a72ea94d65cabd45cdaf15b0a14e81","raw_frame":"{\"market\":\"0x717c0e8ccd4d5c7040185188fbae28be901ca589a11a94b1b38ca36a79eccfeb\", \"price_changes\":[{\"asset_id\":\"24254094493625419915756280046002869097156693848522361803041977572204227262166\", \"price\":\"0.4\", \"size\":\"10\", \"side\":\"BUY\", \"hash\":\"9b3baff8431441fb4ddf721de9b1d7aaaf89560a\", \"best_bid\":\"0.44\", \"best_ask\":\"0.45\"}, {\"asset_id\":\"41448400836309843603620980831210604935021861034693225347475867885462478926555\", \"price\":\"0.6\", \"size\":\"10\", \"side\":\"SELL\", \"hash\":\"667de60e441856e947d490f639139cae65b8f67f\", \"best_bid\":\"0.55\", \"best_ask\":\"0.56\"}], \"timestamp\":\"1785122546622\", \"event_type\":\"price_change\"}","received_at":"2026-07-27T03:22:26.500456Z","schema_version":"clob-market-ws.price_change.v1","sequence":null,"server_hash":null,"server_timestamp":"1785122546622","session_id":"dd162b8dca5f43ff811d304e69a06123","source":"clob_market_ws"},"received_at":"2026-07-27T03:22:26.500456Z","record_id":"46ba6e71422c5ebc59d4e69e81974c5a9fbe3885b3847cc70710f6b5a9c1c379","schema_fingerprint":"4aa3821a28b0b7c2400bc59aba4bcc0a76e971dadd19610d3ad38c768e124dc7","schema_version":"edge-lab-recorder.raw.v1","sequence":null,"source":"clob_market_ws"}
{"event_at":"2026-07-27T03:22:26.622000Z","event_fingerprint":"324a7b2441a6421df558fe238b7f2888668c09d1767dcc485987e0730a812453","payload":{"connection_id":"c7dc2e4762f849c6b6f9306b6518dcab","event_at":"2026-07-27T03:22:26.622000Z","event_type":"price_change","frame_hash":"179baed328fd2448b14deec4a83a8a0dba312a9dd6ad6994c811c268c2dd1e8a","frame_index":0,"kind":"data","monotonic_ns":224529858306750,"payload":{"event_type":"price_change","market":"0x717c0e8ccd4d5c7040185188fbae28be901ca589a11a94b1b38ca36a79eccfeb","price_changes":[{"asset_id":"24254094493625419915756280046002869097156693848522361803041977572204227262166","best_ask":"0.45","best_bid":"0.44","hash":"6621ef4b71c6d9ac4044e224032bca40231a682f","price":"0.42","side":"BUY","size":"270"},{"asset_id":"41448400836309843603620980831210604935021861034693225347475867885462478926555","best_ask":"0.56","best_bid":"0.55","hash":"62ec9fe957870584888249758182bff2935a08ed","price":"0.58","side":"SELL","size":"270"}],"timestamp":"1785122546622"},"payload_hash":"620369aeb1dbfd6dc8f5f2f1488d95783edadf123a733a43d35faff5159a5e7f","raw_frame":"{\"market\":\"0x717c0e8ccd4d5c7040185188fbae28be901ca589a11a94b1b38ca36a79eccfeb\", \"price_changes\":[{\"asset_id\":\"24254094493625419915756280046002869097156693848522361803041977572204227262166\", \"price\":\"0.42\", \"size\":\"270\", \"side\":\"BUY\", \"hash\":\"6621ef4b71c6d9ac4044e224032bca40231a682f\", \"best_bid\":\"0.44\", \"best_ask\":\"0.45\"}, {\"asset_id\":\"41448400836309843603620980831210604935021861034693225347475867885462478926555\", \"price\":\"0.58\", \"size\":\"270\", \"side\":\"SELL\", \"hash\":\"62ec9fe957870584888249758182bff2935a08ed\", \"best_bid\":\"0.55\", \"best_ask\":\"0.56\"}], \"timestamp\":\"1785122546622\", \"event_type\":\"price_change\"}","received_at":"2026-07-27T03:22:26.502120Z","schema_version":"clob-market-ws.price_change.v1","sequence":null,"server_hash":null,"server_timestamp":"1785122546622","session_id":"dd162b8dca5f43ff811d304e69a06123","source":"clob_market_ws"},"received_at":"2026-07-27T03:22:26.502120Z","record_id":"0a101f5da0a0e91d4b2161b2b494869546537d0151a95ff4fde72e8b5601541a","schema_fingerprint":"4aa3821a28b0b7c2400bc59aba4bcc0a76e971dadd19610d3ad38c768e124dc7","schema_version":"edge-lab-recorder.raw.v1","sequence":null,"source":"clob_market_ws"}
{"event_at":"2026-07-27T03:22:26.624000Z","event_fingerprint":"59df9bb37755336a4586bc0683de3f2823d7f5ffe5d87c26a23ba7ddda0ce574","payload":{"connection_id":"c7dc2e4762f849c6b6f9306b6518dcab","event_at":"2026-07-27T03:22:26.624000Z","event_type":"price_change","frame_hash":"0a53c6452b2f97eaefe2d71f6f804a6d6b761ece78e0b5045b9a88f57b030f38","frame_index":0,"kind":"data","monotonic_ns":224529859952625,"payload":{"event_type":"price_change","market":"0x717c0e8ccd4d5c7040185188fbae28be901ca589a11a94b1b38ca36a79eccfeb","price_changes":[{"asset_id":"41448400836309843603620980831210604935021861034693225347475867885462478926555","best_ask":"0.56","best_bid":"0.55","hash":"38986f76867144c7d4031bf7528bf40f59568757","price":"0.45","side":"BUY","size":"110"},{"asset_id":"24254094493625419915756280046002869097156693848522361803041977572204227262166","best_ask":"0.45","best_bid":"0.44","hash":"60b365809245335e2b323ac0a2e89f5133560e86","price":"0.55","side":"SELL","size":"110"}],"timestamp":"1785122546624"},"payload_hash":"e94ecc2bb27787add1cccba9fc9779c47074fd933c784641ac926a47d108483c","raw_frame":"{\"market\":\"0x717c0e8ccd4d5c7040185188fbae28be901ca589a11a94b1b38ca36a79eccfeb\", \"price_changes\":[{\"asset_id\":\"41448400836309843603620980831210604935021861034693225347475867885462478926555\", \"price\":\"0.45\", \"size\":\"110\", \"side\":\"BUY\", \"hash\":\"38986f76867144c7d4031bf7528bf40f59568757\", \"best_bid\":\"0.55\", \"best_ask\":\"0.56\"}, {\"asset_id\":\"24254094493625419915756280046002869097156693848522361803041977572204227262166\", \"price\":\"0.55\", \"size\":\"110\", \"side\":\"SELL\", \"hash\":\"60b365809245335e2b323ac0a2e89f5133560e86\", \"best_bid\":\"0.44\", \"best_ask\":\"0.45\"}], \"timestamp\":\"1785122546624\", \"event_type\":\"price_change\"}","received_at":"2026-07-27T03:22:26.503765Z","schema_version":"clob-market-ws.price_change.v1","sequence":null,"server_hash":null,"server_timestamp":"1785122546624","session_id":"dd162b8dca5f43ff811d304e69a06123","source":"clob_market_ws"},"received_at":"2026-07-27T03:22:26.503765Z","record_id":"63602909853fa6b33bb1cce5c3e07a509ec7b3f3cedfe89db221efa49b3fc4fd","schema_fingerprint":"4aa3821a28b0b7c2400bc59aba4bcc0a76e971dadd19610d3ad38c768e124dc7","schema_version":"edge-lab-recorder.raw.v1","sequence":null,"source":"clob_market_ws"}
{"event_at":"2026-07-27T03:22:26.629000Z","event_fingerprint":"80a21b0d21f9b47304921c1b6cc3523066e90540e76e063d70bb5bb02fe0ce6e","payload":{"connection_id":"c7dc2e4762f849c6b6f9306b6518dcab","event_at":"2026-07-27T03:22:26.629000Z","event_type":"price_change","frame_hash":"9156251adfe7d6cb617a176f3a95c8cbe8749b29015796876d1962f2525b17b8","frame_index":0,"kind":"data","monotonic_ns":224529864657833,"payload":{"event_type":"price_change","market":"0x717c0e8ccd4d5c7040185188fbae28be901ca589a11a94b1b38ca36a79eccfeb","price_changes":[{"asset_id":"41448400836309843603620980831210604935021861034693225347475867885462478926555","best_ask":"0.56","best_bid":"0.55","hash":"7b56af7093b0aebbd1aaaef080341db49ac3c9bc","price":"0.44","side":"BUY","size":"243"},{"asset_id":"24254094493625419915756280046002869097156693848522361803041977572204227262166","best_ask":"0.45","best_bid":"0.44","hash":"c74c76537e2700d0078ab0fbc3d37f6583d50f80","price":"0.56","side":"SELL","size":"243"}],"timestamp":"1785122546629"},"payload_hash":"6a76a4b4bf18c91df6192d0e5800c11898e6018caf60cda55657ac27d5861288","raw_frame":"{\"market\":\"0x717c0e8ccd4d5c7040185188fbae28be901ca589a11a94b1b38ca36a79eccfeb\", \"price_changes\":[{\"asset_id\":\"41448400836309843603620980831210604935021861034693225347475867885462478926555\", \"price\":\"0.44\", \"size\":\"243\", \"side\":\"BUY\", \"hash\":\"7b56af7093b0aebbd1aaaef080341db49ac3c9bc\", \"best_bid\":\"0.55\", \"best_ask\":\"0.56\"}, {\"asset_id\":\"24254094493625419915756280046002869097156693848522361803041977572204227262166\", \"price\":\"0.56\", \"size\":\"243\", \"side\":\"SELL\", \"hash\":\"c74c76537e2700d0078ab0fbc3d37f6583d50f80\", \"best_bid\":\"0.44\", \"best_ask\":\"0.45\"}], \"timestamp\":\"1785122546629\", \"event_type\":\"price_change\"}","received_at":"2026-07-27T03:22:26.508471Z","schema_version":"clob-market-ws.price_change.v1","sequence":null,"server_hash":null,"server_timestamp":"1785122546629","session_id":"dd162b8dca5f43ff811d304e69a06123","source":"clob_market_ws"},"received_at":"2026-07-27T03:22:26.508471Z","record_id":"d75d24e6ce2bc3cf45fd37627af71eb154a13af8acfdbe6c9862a2769bfabd29","schema_fingerprint":"4aa3821a28b0b7c2400bc59aba4bcc0a76e971dadd19610d3ad38c768e124dc7","schema_version":"edge-lab-recorder.raw.v1","sequence":null,"source":"clob_market_ws"}
{"event_at":"2026-07-27T03:22:26.654000Z","event_fingerprint":"e20ac1bb5bf3f6b18f2d211d14130addadb9040b7c7276de7f30018674c86d22","payload":{"connection_id":"c7dc2e4762f849c6b6f9306b6518dcab","event_at":"2026-07-27T03:22:26.654000Z","event_type":"price_change","frame_hash":"b1404533ac13aa6573d6017728b53446fd9adf3fc1a859733e3baf5e5594c8ae","frame_index":0,"kind":"data","monotonic_ns":224529890637916,"payload":{"event_type":"price_change","market":"0x717c0e8ccd4d5c7040185188fbae28be901ca589a11a94b1b38ca36a79eccfeb","price_changes":[{"asset_id":"41448400836309843603620980831210604935021861034693225347475867885462478926555","best_ask":"0.56","best_bid":"0.55","hash":"17f15393e29d4c324262d274a1c71d800ff28d07","price":"0.01","side":"BUY","size":"5458.02"},{"asset_id":"24254094493625419915756280046002869097156693848522361803041977572204227262166","best_ask":"0.45","best_bid":"0.44","hash":"e39ec4f4843340d758dc7d00f05aed2e573b98e8","price":"0.99","side":"SELL","size":"5458.02"}],"timestamp":"1785122546654"},"payload_hash":"2b1d573dc6d71878976f8a6b83dbb9a06f4e07037dc7dccfae45102e65880fdc","raw_frame":"{\"market\":\"0x717c0e8ccd4d5c7040185188fbae28be901ca589a11a94b1b38ca36a79eccfeb\", \"price_changes\":[{\"asset_id\":\"41448400836309843603620980831210604935021861034693225347475867885462478926555\", \"price\":\"0.01\", \"size\":\"5458.02\", \"side\":\"BUY\", \"hash\":\"17f15393e29d4c324262d274a1c71d800ff28d07\", \"best_bid\":\"0.55\", \"best_ask\":\"0.56\"}, {\"asset_id\":\"24254094493625419915756280046002869097156693848522361803041977572204227262166\", \"price\":\"0.99\", \"size\":\"5458.02\", \"side\":\"SELL\", \"hash\":\"e39ec4f4843340d758dc7d00f05aed2e573b98e8\", \"best_bid\":\"0.44\", \"best_ask\":\"0.45\"}], \"timestamp\":\"1785122546654\", \"event_type\":\"price_change\"}","received_at":"2026-07-27T03:22:26.534452Z","schema_version":"clob-market-ws.price_change.v1","sequence":null,"server_hash":null,"server_timestamp":"1785122546654","session_id":"dd162b8dca5f43ff811d304e69a06123","source":"clob_market_ws"},"received_at":"2026-07-27T03:22:26.534452Z","record_id":"3c7a66e9d6ce0dff74dc14f47f219f2f8c5616650e1a6eb2efaf2bc88f5fde8c","schema_fingerprint":"4aa3821a28b0b7c2400bc59aba4bcc0a76e971dadd19610d3ad38c768e124dc7","schema_version":"edge-lab-recorder.raw.v1","sequence":null,"source":"clob_market_ws"}
{"event_at":"2026-07-27T03:22:26.679000Z","event_fingerprint":"f2bd9c3e4b78f54890c657bee0495763aa26f26d7c6ed43852b6651091e14e5b","payload":{"connection_id":"c7dc2e4762f849c6b6f9306b6518dcab","event_at":"2026-07-27T03:22:26.679000Z","event_type":"price_change","frame_hash":"906f5ea5c34176d7e87a7a1547776e14de2c1ae79655b7d07e398d47533ec90d","frame_index":0,"kind":"data","monotonic_ns":224529920941916,"payload":{"event_type":"price_change","market":"0x717c0e8ccd4d5c7040185188fbae28be901ca589a11a94b1b38ca36a79eccfeb","price_changes":[{"asset_id":"41448400836309843603620980831210604935021861034693225347475867885462478926555","best_ask":"0.56","best_bid":"0.55","hash":"3ba9d797a72fcce72c739121670c31fe1aed70aa","price":"0.01","side":"BUY","size":"5453.02"},{"asset_id":"24254094493625419915756280046002869097156693848522361803041977572204227262166","best_ask":"0.45","best_bid":"0.44","hash":"841f1c7e13aa14fcb8be20f4f48a2cdc03ca55e4","price":"0.99","side":"SELL","size":"5453.02"}],"timestamp":"1785122546679"},"payload_hash":"95216c9459f934b004c8bae7000737c0cfa3a4a9c20ed35ceb829969b4d2cd67","raw_frame":"{\"market\":\"0x717c0e8ccd4d5c7040185188fbae28be901ca589a11a94b1b38ca36a79eccfeb\", \"price_changes\":[{\"asset_id\":\"41448400836309843603620980831210604935021861034693225347475867885462478926555\", \"price\":\"0.01\", \"size\":\"5453.02\", \"side\":\"BUY\", \"hash\":\"3ba9d797a72fcce72c739121670c31fe1aed70aa\", \"best_bid\":\"0.55\", \"best_ask\":\"0.56\"}, {\"asset_id\":\"24254094493625419915756280046002869097156693848522361803041977572204227262166\", \"price\":\"0.99\", \"size\":\"5453.02\", \"side\":\"SELL\", \"hash\":\"841f1c7e13aa14fcb8be20f4f48a2cdc03ca55e4\", \"best_bid\":\"0.44\", \"best_ask\":\"0.45\"}], \"timestamp\":\"1785122546679\", \"event_type\":\"price_change\"}","received_at":"2026-07-27T03:22:26.564752Z","schema_version":"clob-market-ws.price_change.v1","sequence":null,"server_hash":null,"server_timestamp":"1785122546679","session_id":"dd162b8dca5f43ff811d304e69a06123","source":"clob_market_ws"},"received_at":"2026-07-27T03:22:26.564752Z","record_id":"fb3fe19ca41d4e7278eae5985c9d4e4fdbbfec84793a6c31c7a2ce579c68e9c4","schema_fingerprint":"4aa3821a28b0b7c2400bc59aba4bcc0a76e971dadd19610d3ad38c768e124dc7","schema_version":"edge-lab-recorder.raw.v1","sequence":null,"source":"clob_market_ws"}
{"event_at":"2026-07-27T03:22:26.696000Z","event_fingerprint":"eb2e217216a18917c511eb7dd2788faa074689e27e08a5bb6ea28d09c6ad596c","payload":{"connection_id":"c7dc2e4762f849c6b6f9306b6518dcab","event_at":"2026-07-27T03:22:26.696000Z","event_type":"price_change","frame_hash":"ac434617d1de9aaa949bc20aa731710cfc7444966179194094da175dab886c67","frame_index":0,"kind":"data","monotonic_ns":224529930286458,"payload":{"event_type":"price_change","market":"0x717c0e8ccd4d5c7040185188fbae28be901ca589a11a94b1b38ca36a79eccfeb","price_changes":[{"asset_id":"41448400836309843603620980831210604935021861034693225347475867885462478926555","best_ask":"0.56","best_bid":"0.55","hash":"67b072d17dcd1f9d8f7f85dd1480ab043e002fb5","price":"0.03","side":"BUY","size":"613.1"},{"asset_id":"24254094493625419915756280046002869097156693848522361803041977572204227262166","best_ask":"0.45","best_bid":"0.44","hash":"369f82e10a4ac786e0bcc3ad2a36b86afb7aa9ee","price":"0.97","side":"SELL","size":"613.1"}],"timestamp":"1785122546696"},"payload_hash":"70019b89302faf8ecf70613358d0ec7b2f8c70c0605b9b075a0206cac6ea3960","raw_frame":"{\"market\":\"0x717c0e8ccd4d5c7040185188fbae28be901ca589a11a94b1b38ca36a79eccfeb\", \"price_changes\":[{\"asset_id\":\"41448400836309843603620980831210604935021861034693225347475867885462478926555\", \"price\":\"0.03\", \"size\":\"613.1\", \"side\":\"BUY\", \"hash\":\"67b072d17dcd1f9d8f7f85dd1480ab043e002fb5\", \"best_bid\":\"0.55\", \"best_ask\":\"0.56\"}, {\"asset_id\":\"24254094493625419915756280046002869097156693848522361803041977572204227262166\", \"price\":\"0.97\", \"size\":\"613.1\", \"side\":\"SELL\", \"hash\":\"369f82e10a4ac786e0bcc3ad2a36b86afb7aa9ee\", \"best_bid\":\"0.44\", \"best_ask\":\"0.45\"}], \"timestamp\":\"1785122546696\", \"event_type\":\"price_change\"}","received_at":"2026-07-27T03:22:26.574096Z","schema_version":"clob-market-ws.price_change.v1","sequence":null,"server_hash":null,"server_timestamp":"1785122546696","session_id":"dd162b8dca5f43ff811d304e69a06123","source":"clob_market_ws"},"received_at":"2026-07-27T03:22:26.574096Z","record_id":"92ae770757b9f3233c49a9e43ffbad329a8e36b3d44040a0edfb6c348a4f85e8","schema_fingerprint":"4aa3821a28b0b7c2400bc59aba4bcc0a76e971dadd19610d3ad38c768e124dc7","schema_version":"edge-lab-recorder.raw.v1","sequence":null,"source":"clob_market_ws"}
{"event_at":"2026-07-27T03:22:26.764000Z","event_fingerprint":"90a9d56b933ae03d8323d735561a1fbf0915e76d616bcad269ba7d2a51e7b991","payload":{"connection_id":"c7dc2e4762f849c6b6f9306b6518dcab","event_at":"2026-07-27T03:22:26.764000Z","event_type":"price_change","frame_hash":"ea6afc68f4155d765fa9816848af2fcb1be0b530b0262e229032f4578d2dc533","frame_index":0,"kind":"data","monotonic_ns":224529998907875,"payload":{"event_type":"price_change","market":"0x717c0e8ccd4d5c7040185188fbae28be901ca589a11a94b1b38ca36a79eccfeb","price_changes":[{"asset_id":"41448400836309843603620980831210604935021861034693225347475867885462478926555","best_ask":"0.56","best_bid":"0.55","hash":"ca0bc4b737742cab3e433fcd0ec6f337a2a2876c","price":"0.43","side":"BUY","size":"117.2"},{"asset_id":"24254094493625419915756280046002869097156693848522361803041977572204227262166","best_ask":"0.45","best_bid":"0.44","hash":"c6c7af6166ada485204990c69f29ccff4826b5fc","price":"0.57","side":"SELL","size":"117.2"}],"timestamp":"1785122546764"},"payload_hash":"a7819a40cdedafcda480970c817f19cd3d5ba431be4c652ddf4d555d82f28b22","raw_frame":"{\"market\":\"0x717c0e8ccd4d5c7040185188fbae28be901ca589a11a94b1b38ca36a79eccfeb\", \"price_changes\":[{\"asset_id\":\"41448400836309843603620980831210604935021861034693225347475867885462478926555\", \"price\":\"0.43\", \"size\":\"117.2\", \"side\":\"BUY\", \"hash\":\"ca0bc4b737742cab3e433fcd0ec6f337a2a2876c\", \"best_bid\":\"0.55\", \"best_ask\":\"0.56\"}, {\"asset_id\":\"24254094493625419915756280046002869097156693848522361803041977572204227262166\", \"price\":\"0.57\", \"size\":\"117.2\", \"side\":\"SELL\", \"hash\":\"c6c7af6166ada485204990c69f29ccff4826b5fc\", \"best_bid\":\"0.44\", \"best_ask\":\"0.45\"}], \"timestamp\":\"1785122546764\", \"event_type\":\"price_change\"}","received_at":"2026-07-27T03:22:26.642715Z","schema_version":"clob-market-ws.price_change.v1","sequence":null,"server_hash":null,"server_timestamp":"1785122546764","session_id":"dd162b8dca5f43ff811d304e69a06123","source":"clob_market_ws"},"received_at":"2026-07-27T03:22:26.642715Z","record_id":"bdb3451c9ca8d9446d188628f45ffb45272946a681e75406a2f2ae43249a4b17","schema_fingerprint":"4aa3821a28b0b7c2400bc59aba4bcc0a76e971dadd19610d3ad38c768e124dc7","schema_version":"edge-lab-recorder.raw.v1","sequence":null,"source":"clob_market_ws"}
{"event_at":"2026-07-27T03:22:26.770000Z","event_fingerprint":"6e6deecdbafeb0b461ba91d44672f59f7e628f83f51c75f059ccdc4304203f8c","payload":{"connection_id":"c7dc2e4762f849c6b6f9306b6518dcab","event_at":"2026-07-27T03:22:26.770000Z","event_type":"price_change","frame_hash":"b69cdfa8179e790f57aa978bdca1485a5f868bc962256e50a344d93eb5c154ff","frame_index":0,"kind":"data","monotonic_ns":224530004757958,"payload":{"event_type":"price_change","market":"0x717c0e8ccd4d5c7040185188fbae28be901ca589a11a94b1b38ca36a79eccfeb","price_changes":[{"asset_id":"24254094493625419915756280046002869097156693848522361803041977572204227262166","best_ask":"0.45","best_bid":"0.44","hash":"55e2a359eff819c961b5d1c92e9f2dc3c56ffe4a","price":"0.4","side":"BUY","size":"15"},{"asset_id":"41448400836309843603620980831210604935021861034693225347475867885462478926555","best_ask":"0.56","best_bid":"0.55","hash":"7ec55afa560f79828ec0f4751b0530bafb00f59a","price":"0.6","side":"SELL","size":"15"}],"timestamp":"1785122546770"},"payload_hash":"f6479413b7166fcf0c4cb617222827827c1ef1fbe6fa25cc236c0c098b1a6e3c","raw_frame":"{\"market\":\"0x717c0e8ccd4d5c7040185188fbae28be901ca589a11a94b1b38ca36a79eccfeb\", \"price_changes\":[{\"asset_id\":\"24254094493625419915756280046002869097156693848522361803041977572204227262166\", \"price\":\"0.4\", \"size\":\"15\", \"side\":\"BUY\", \"hash\":\"55e2a359eff819c961b5d1c92e9f2dc3c56ffe4a\", \"best_bid\":\"0.44\", \"best_ask\":\"0.45\"}, {\"asset_id\":\"41448400836309843603620980831210604935021861034693225347475867885462478926555\", \"price\":\"0.6\", \"size\":\"15\", \"side\":\"SELL\", \"hash\":\"7ec55afa560f79828ec0f4751b0530bafb00f59a\", \"best_bid\":\"0.55\", \"best_ask\":\"0.56\"}], \"timestamp\":\"1785122546770\", \"event_type\":\"price_change\"}","received_at":"2026-07-27T03:22:26.648568Z","schema_version":"clob-market-ws.price_change.v1","sequence":null,"server_hash":null,"server_timestamp":"1785122546770","session_id":"dd162b8dca5f43ff811d304e69a06123","source":"clob_market_ws"},"received_at":"2026-07-27T03:22:26.648568Z","record_id":"5ad28b917ded56fd0590d6779c469eb7c6ed51f8e782b79fceaf8320c3171160","schema_fingerprint":"4aa3821a28b0b7c2400bc59aba4bcc0a76e971dadd19610d3ad38c768e124dc7","schema_version":"edge-lab-recorder.raw.v1","sequence":null,"source":"clob_market_ws"}
{"event_at":"2026-07-27T03:22:26.790000Z","event_fingerprint":"aafda28a88bb1a19818c7c4cd77a9a234a34de2139f6d5cd84847cfceb23115a","payload":{"connection_id":"c7dc2e4762f849c6b6f9306b6518dcab","event_at":"2026-07-27T03:22:26.790000Z","event_type":"price_change","frame_hash":"40b7b0a43a8cdb48d684949d224c281266656b31c75bb1312a61361c8128f77e","frame_index":0,"kind":"data","monotonic_ns":224530024413916,"payload":{"event_type":"price_change","market":"0x717c0e8ccd4d5c7040185188fbae28be901ca589a11a94b1b38ca36a79eccfeb","price_changes":[{"asset_id":"41448400836309843603620980831210604935021861034693225347475867885462478926555","best_ask":"0.56","best_bid":"0.55","hash":"9e29fd6de5a0cc4da88b6a870adc095448986dad","price":"0.03","side":"BUY","size":"618.1"},{"asset_id":"24254094493625419915756280046002869097156693848522361803041977572204227262166","best_ask":"0.45","best_bid":"0.44","hash":"f3733f3410709866211cb4f6a4df299b6ac61590","price":"0.97","side":"SELL","size":"618.1"}],"timestamp":"1785122546790"},"payload_hash":"e2bdf0d0a3e950baf1006278f3c440388099cf493011ea4745aaee3956301520","raw_frame":"{\"market\":\"0x717c0e8ccd4d5c7040185188fbae28be901ca589a11a94b1b38ca36a79eccfeb\", \"price_changes\":[{\"asset_id\":\"41448400836309843603620980831210604935021861034693225347475867885462478926555\", \"price\":\"0.03\", \"size\":\"618.1\", \"side\":\"BUY\", \"hash\":\"9e29fd6de5a0cc4da88b6a870adc095448986dad\", \"best_bid\":\"0.55\", \"best_ask\":\"0.56\"}, {\"asset_id\":\"24254094493625419915756280046002869097156693848522361803041977572204227262166\", \"price\":\"0.97\", \"size\":\"618.1\", \"side\":\"SELL\", \"hash\":\"f3733f3410709866211cb4f6a4df299b6ac61590\", \"best_bid\":\"0.44\", \"best_ask\":\"0.45\"}], \"timestamp\":\"1785122546790\", \"event_type\":\"price_change\"}","received_at":"2026-07-27T03:22:26.668224Z","schema_version":"clob-market-ws.price_change.v1","sequence":null,"server_hash":null,"server_timestamp":"1785122546790","session_id":"dd162b8dca5f43ff811d304e69a06123","source":"clob_market_ws"},"received_at":"2026-07-27T03:22:26.668224Z","record_id":"640eb6dc9d514befa94ef3abb6cb80e75b998adda7f35b3db5dda17debf4bcad","schema_fingerprint":"4aa3821a28b0b7c2400bc59aba4bcc0a76e971dadd19610d3ad38c768e124dc7","schema_version":"edge-lab-recorder.raw.v1","sequence":null,"source":"clob_market_ws"}
{"event_at":"2026-07-27T03:22:26.919000Z","event_fingerprint":"30adb065c860d6636f0244385e1094f7dea3ad5889019f95c2670f80271d8fb5","payload":{"connection_id":"c7dc2e4762f849c6b6f9306b6518dcab","event_at":"2026-07-27T03:22:26.919000Z","event_type":"price_change","frame_hash":"258a4309d0fbcd9e66205a4d6cc16a5e10535e501210460ec71a265b26477d6f","frame_index":0,"kind":"data","monotonic_ns":224530153753666,"payload":{"event_type":"price_change","market":"0x717c0e8ccd4d5c7040185188fbae28be901ca589a11a94b1b38ca36a79eccfeb","price_changes":[{"asset_id":"41448400836309843603620980831210604935021861034693225347475867885462478926555","best_ask":"0.56","best_bid":"0.55","hash":"051f120625481e62a2b2f96936c5a2f693461b5a","price":"0.01","side":"BUY","size":"5458.02"},{"asset_id":"24254094493625419915756280046002869097156693848522361803041977572204227262166","best_ask":"0.45","best_bid":"0.44","hash":"0fbea28194648995d74c54897f0d861475b5ee23","price":"0.99","side":"SELL","size":"5458.02"}],"timestamp":"1785122546919"},"payload_hash":"df5a6b92b7ff0eccff5fca3984fd87a9ed6f3d74ba26d7f35da08c9e8cac090f","raw_frame":"{\"market\":\"0x717c0e8ccd4d5c7040185188fbae28be901ca589a11a94b1b38ca36a79eccfeb\", \"price_changes\":[{\"asset_id\":\"41448400836309843603620980831210604935021861034693225347475867885462478926555\", \"price\":\"0.01\", \"size\":\"5458.02\", \"side\":\"BUY\", \"hash\":\"051f120625481e62a2b2f96936c5a2f693461b5a\", \"best_bid\":\"0.55\", \"best_ask\":\"0.56\"}, {\"asset_id\":\"24254094493625419915756280046002869097156693848522361803041977572204227262166\", \"price\":\"0.99\", \"size\":\"5458.02\", \"side\":\"SELL\", \"hash\":\"0fbea28194648995d74c54897f0d861475b5ee23\", \"best_bid\":\"0.44\", \"best_ask\":\"0.45\"}], \"timestamp\":\"1785122546919\", \"event_type\":\"price_change\"}","received_at":"2026-07-27T03:22:26.797562Z","schema_version":"clob-market-ws.price_change.v1","sequence":null,"server_hash":null,"server_timestamp":"1785122546919","session_id":"dd162b8dca5f43ff811d304e69a06123","source":"clob_market_ws"},"received_at":"2026-07-27T03:22:26.797562Z","record_id":"75353293d572ac89ed6d27678fa4ac37c6064c5b7fa0ebbb9e4df5e178863317","schema_fingerprint":"4aa3821a28b0b7c2400bc59aba4bcc0a76e971dadd19610d3ad38c768e124dc7","schema_version":"edge-lab-recorder.raw.v1","sequence":null,"source":"clob_market_ws"}
{"event_at":"2026-07-27T03:22:26.924000Z","event_fingerprint":"e5a4de24b362fb953563490b9a8fbb6e2b7ef75288f26c11ec360345baac861c","payload":{"connection_id":"c7dc2e4762f849c6b6f9306b6518dcab","event_at":"2026-07-27T03:22:26.924000Z","event_type":"price_change","frame_hash":"cde5fff2c4749e71b2ce49d0a7013cb4bd9834d086c19d5a56c0bfc4cc104449","frame_index":0,"kind":"data","monotonic_ns":224530158828000,"payload":{"event_type":"price_change","market":"0x717c0e8ccd4d5c7040185188fbae28be901ca589a11a94b1b38ca36a79eccfeb","price_changes":[{"asset_id":"41448400836309843603620980831210604935021861034693225347475867885462478926555","best_ask":"0.56","best_bid":"0.55","hash":"bbde2a0836dcbb3260d433fe81497d80e4412af4","price":"0.03","side":"BUY","size":"613.1"},{"asset_id":"24254094493625419915756280046002869097156693848522361803041977572204227262166","best_ask":"0.45","best_bid":"0.44","hash":"a609fa2d12c413aff49dc58d77a143c994a875b0","price":"0.97","side":"SELL","size":"613.1"}],"timestamp":"1785122546924"},"payload_hash":"ef3ff678ce0c6b8ff63eaa6460ceabf13404e8f473251672c459585493b5da6f","raw_frame":"{\"market\":\"0x717c0e8ccd4d5c7040185188fbae28be901ca589a11a94b1b38ca36a79eccfeb\", \"price_changes\":[{\"asset_id\":\"41448400836309843603620980831210604935021861034693225347475867885462478926555\", \"price\":\"0.03\", \"size\":\"613.1\", \"side\":\"BUY\", \"hash\":\"bbde2a0836dcbb3260d433fe81497d80e4412af4\", \"best_bid\":\"0.55\", \"best_ask\":\"0.56\"}, {\"asset_id\":\"24254094493625419915756280046002869097156693848522361803041977572204227262166\", \"price\":\"0.97\", \"size\":\"613.1\", \"side\":\"SELL\", \"hash\":\"a609fa2d12c413aff49dc58d77a143c994a875b0\", \"best_bid\":\"0.44\", \"best_ask\":\"0.45\"}], \"timestamp\":\"1785122546924\", \"event_type\":\"price_change\"}","received_at":"2026-07-27T03:22:26.802636Z","schema_version":"clob-market-ws.price_change.v1","sequence":null,"server_hash":null,"server_timestamp":"1785122546924","session_id":"dd162b8dca5f43ff811d304e69a06123","source":"clob_market_ws"},"received_at":"2026-07-27T03:22:26.802636Z","record_id":"32263ec49d614f55bfc2d92216a3be88059d0cda54d534fc15973906cc923557","schema_fingerprint":"4aa3821a28b0b7c2400bc59aba4bcc0a76e971dadd19610d3ad38c768e124dc7","schema_version":"edge-lab-recorder.raw.v1","sequence":null,"source":"clob_market_ws"}
{"event_at":"2026-07-27T03:22:26.939000Z","event_fingerprint":"394c6928c77eb357bbc87abfbc9ffd50345258f5843322b557b0552a9cee08d8","payload":{"connection_id":"c7dc2e4762f849c6b6f9306b6518dcab","event_at":"2026-07-27T03:22:26.939000Z","event_type":"price_change","frame_hash":"45157872f2633cb0d7adc0f96a4b61fc9b032f6ef2fbd5c247fcdadf1dab973d","frame_index":0,"kind":"data","monotonic_ns":224530174769708,"payload":{"event_type":"price_change","market":"0x717c0e8ccd4d5c7040185188fbae28be901ca589a11a94b1b38ca36a79eccfeb","price_changes":[{"asset_id":"41448400836309843603620980831210604935021861034693225347475867885462478926555","best_ask":"0.56","best_bid":"0.55","hash":"934ee43f562ea768630cb9c0546c771b5d30636d","price":"0.01","side":"BUY","size":"5453.02"},{"asset_id":"24254094493625419915756280046002869097156693848522361803041977572204227262166","best_ask":"0.45","best_bid":"0.44","hash":"3d1b39989d9b60a23b49a2757e753ed704762fe4","price":"0.99","side":"SELL","size":"5453.02"}],"timestamp":"1785122546939"},"payload_hash":"65d9ff7ec3c2693648576977b93a348252ff4011e39bd1656a215060bb01b3cc","raw_frame":"{\"market\":\"0x717c0e8ccd4d5c7040185188fbae28be901ca589a11a94b1b38ca36a79eccfeb\", \"price_changes\":[{\"asset_id\":\"41448400836309843603620980831210604935021861034693225347475867885462478926555\", \"price\":\"0.01\", \"size\":\"5453.02\", \"side\":\"BUY\", \"hash\":\"934ee43f562ea768630cb9c0546c771b5d30636d\", \"best_bid\":\"0.55\", \"best_ask\":\"0.56\"}, {\"asset_id\":\"24254094493625419915756280046002869097156693848522361803041977572204227262166\", \"price\":\"0.99\", \"size\":\"5453.02\", \"side\":\"SELL\", \"hash\":\"3d1b39989d9b60a23b49a2757e753ed704762fe4\", \"best_bid\":\"0.44\", \"best_ask\":\"0.45\"}], \"timestamp\":\"1785122546939\", \"event_type\":\"price_change\"}","received_at":"2026-07-27T03:22:26.818578Z","schema_version":"clob-market-ws.price_change.v1","sequence":null,"server_hash":null,"server_timestamp":"1785122546939","session_id":"dd162b8dca5f43ff811d304e69a06123","source":"clob_market_ws"},"received_at":"2026-07-27T03:22:26.818578Z","record_id":"d3fcfc4842a37d297a2276c213ea331969561b63edb40ad5e39b552c0248f348","schema_fingerprint":"4aa3821a28b0b7c2400bc59aba4bcc0a76e971dadd19610d3ad38c768e124dc7","schema_version":"edge-lab-recorder.raw.v1","sequence":null,"source":"clob_market_ws"}
{"event_at":"2026-07-27T03:22:26.939000Z","event_fingerprint":"37f7a15cbe4475fb17fa477427fcae26d0524821b8432cacf16bf4006ed69770","payload":{"connection_id":"c7dc2e4762f849c6b6f9306b6518dcab","event_at":"2026-07-27T03:22:26.939000Z","event_type":"price_change","frame_hash":"9fcb4469b520bfb79de89876e656ed341fd9ee7088f3fa7c0b64c9f093d8e69d","frame_index":0,"kind":"data","monotonic_ns":224530178049791,"payload":{"event_type":"price_change","market":"0x717c0e8ccd4d5c7040185188fbae28be901ca589a11a94b1b38ca36a79eccfeb","price_changes":[{"asset_id":"41448400836309843603620980831210604935021861034693225347475867885462478926555","best_ask":"0.56","best_bid":"0.55","hash":"b599236e94e05b96e61b6a69faf5da796e798386","price":"0.44","side":"BUY","size":"235"},{"asset_id":"24254094493625419915756280046002869097156693848522361803041977572204227262166","best_ask":"0.45","best_bid":"0.44","hash":"5130acc26c3bdd3715f479072920a934b582dd6b","price":"0.56","side":"SELL","size":"235"}],"timestamp":"1785122546939"},"payload_hash":"6ba17fb37d8a67a985eb591101bc27f10956eda5b156f83b0f597d315d65d550","raw_frame":"{\"market\":\"0x717c0e8ccd4d5c7040185188fbae28be901ca589a11a94b1b38ca36a79eccfeb\", \"price_changes\":[{\"asset_id\":\"41448400836309843603620980831210604935021861034693225347475867885462478926555\", \"price\":\"0.44\", \"size\":\"235\", \"side\":\"BUY\", \"hash\":\"b599236e94e05b96e61b6a69faf5da796e798386\", \"best_bid\":\"0.55\", \"best_ask\":\"0.56\"}, {\"asset_id\":\"24254094493625419915756280046002869097156693848522361803041977572204227262166\", \"price\":\"0.56\", \"size\":\"235\", \"side\":\"SELL\", \"hash\":\"5130acc26c3bdd3715f479072920a934b582dd6b\", \"best_bid\":\"0.44\", \"best_ask\":\"0.45\"}], \"timestamp\":\"1785122546939\", \"event_type\":\"price_change\"}","received_at":"2026-07-27T03:22:26.821855Z","schema_version":"clob-market-ws.price_change.v1","sequence":null,"server_hash":null,"server_timestamp":"1785122546939","session_id":"dd162b8dca5f43ff811d304e69a06123","source":"clob_market_ws"},"received_at":"2026-07-27T03:22:26.821855Z","record_id":"18cde8a3f41bf2d1e4c66a0ebdfd753171759cd0050a33d65076ec8ef73cddbf","schema_fingerprint":"4aa3821a28b0b7c2400bc59aba4bcc0a76e971dadd19610d3ad38c768e124dc7","schema_version":"edge-lab-recorder.raw.v1","sequence":null,"source":"clob_market_ws"}
{"event_at":"2026-07-27T03:22:26.943000Z","event_fingerprint":"83b3ebc39cb2985036fe69e1e341ce9689d1b90d857348c60717c4186d30fbeb","payload":{"connection_id":"c7dc2e4762f849c6b6f9306b6518dcab","event_at":"2026-07-27T03:22:26.943000Z","event_type":"price_change","frame_hash":"efede7abde82fbba86366e1c263a8313058eb948d33ce92ef0e0e10911d75649","frame_index":0,"kind":"data","monotonic_ns":224530179865833,"payload":{"event_type":"price_change","market":"0x717c0e8ccd4d5c7040185188fbae28be901ca589a11a94b1b38ca36a79eccfeb","price_changes":[{"asset_id":"41448400836309843603620980831210604935021861034693225347475867885462478926555","best_ask":"0.56","best_bid":"0.55","hash":"69cb015b424ba4b7acf158d3c3b9508c416a8005","price":"0.45","side":"BUY","size":"115"},{"asset_id":"24254094493625419915756280046002869097156693848522361803041977572204227262166","best_ask":"0.45","best_bid":"0.44","hash":"ea78aef053facefd3ce9f69d119dabddc02cffca","price":"0.55","side":"SELL","size":"115"}],"timestamp":"1785122546943"},"payload_hash":"cd2b366289c1dabaf4ab04093fb4e71435815197bd4f6dea39fdf31c52f73423","raw_frame":"{\"market\":\"0x717c0e8ccd4d5c7040185188fbae28be901ca589a11a94b1b38ca36a79eccfeb\", \"price_changes\":[{\"asset_id\":\"41448400836309843603620980831210604935021861034693225347475867885462478926555\", \"price\":\"0.45\", \"size\":\"115\", \"side\":\"BUY\", \"hash\":\"69cb015b424ba4b7acf158d3c3b9508c416a8005\", \"best_bid\":\"0.55\", \"best_ask\":\"0.56\"}, {\"asset_id\":\"24254094493625419915756280046002869097156693848522361803041977572204227262166\", \"price\":\"0.55\", \"size\":\"115\", \"side\":\"SELL\", \"hash\":\"ea78aef053facefd3ce9f69d119dabddc02cffca\", \"best_bid\":\"0.44\", \"best_ask\":\"0.45\"}], \"timestamp\":\"1785122546943\", \"event_type\":\"price_change\"}","received_at":"2026-07-27T03:22:26.823674Z","schema_version":"clob-market-ws.price_change.v1","sequence":null,"server_hash":null,"server_timestamp":"1785122546943","session_id":"dd162b8dca5f43ff811d304e69a06123","source":"clob_market_ws"},"received_at":"2026-07-27T03:22:26.823674Z","record_id":"8834938b408469bc123b20a80cf8985adfb0fa131fbdf71f5f0b6dbf17d78ecb","schema_fingerprint":"4aa3821a28b0b7c2400bc59aba4bcc0a76e971dadd19610d3ad38c768e124dc7","schema_version":"edge-lab-recorder.raw.v1","sequence":null,"source":"clob_market_ws"}
{"event_at":"2026-07-27T03:22:26.945000Z","event_fingerprint":"390fdaedb954030fe665841c32908e1966ae0725d258b6ce16a37e1cb9ed2b4c","payload":{"connection_id":"c7dc2e4762f849c6b6f9306b6518dcab","event_at":"2026-07-27T03:22:26.945000Z","event_type":"price_change","frame_hash":"d9a019764ee1e1964f3b1c65a798b0cb48723fe87a18f2c23ccaf3eb6a9224f1","frame_index":0,"kind":"data","monotonic_ns":224530181457500,"payload":{"event_type":"price_change","market":"0x717c0e8ccd4d5c7040185188fbae28be901ca589a11a94b1b38ca36a79eccfeb","price_changes":[{"asset_id":"41448400836309843603620980831210604935021861034693225347475867885462478926555","best_ask":"0.56","best_bid":"0.55","hash":"25abd296310958f45c6649a2f67cf77d3dd0cfd3","price":"0.43","side":"BUY","size":"126.2"},{"asset_id":"24254094493625419915756280046002869097156693848522361803041977572204227262166","best_ask":"0.45","best_bid":"0.44","hash":"2b7e2e14929eb338c3716eb4a971a09d55f5ddf9","price":"0.57","side":"SELL","size":"126.2"}],"timestamp":"1785122546945"},"payload_hash":"95d1ee4c5a067f6f3db0e3013060b991e32d3b1d0d70baea0c58a9f95091b66e","raw_frame":"{\"market\":\"0x717c0e8ccd4d5c7040185188fbae28be901ca589a11a94b1b38ca36a79eccfeb\", \"price_changes\":[{\"asset_id\":\"41448400836309843603620980831210604935021861034693225347475867885462478926555\", \"price\":\"0.43\", \"size\":\"126.2\", \"side\":\"BUY\", \"hash\":\"25abd296310958f45c6649a2f67cf77d3dd0cfd3\", \"best_bid\":\"0.55\", \"best_ask\":\"0.56\"}, {\"asset_id\":\"24254094493625419915756280046002869097156693848522361803041977572204227262166\", \"price\":\"0.57\", \"size\":\"126.2\", \"side\":\"SELL\", \"hash\":\"2b7e2e14929eb338c3716eb4a971a09d55f5ddf9\", \"best_bid\":\"0.44\", \"best_ask\":\"0.45\"}], \"timestamp\":\"1785122546945\", \"event_type\":\"price_change\"}","received_at":"2026-07-27T03:22:26.825267Z","schema_version":"clob-market-ws.price_change.v1","sequence":null,"server_hash":null,"server_timestamp":"1785122546945","session_id":"dd162b8dca5f43ff811d304e69a06123","source":"clob_market_ws"},"received_at":"2026-07-27T03:22:26.825267Z","record_id":"00f3bf8e37ab366dd6e55b5da964dc2843e0c59bfbd11288c8f3dce790e485a0","schema_fingerprint":"4aa3821a28b0b7c2400bc59aba4bcc0a76e971dadd19610d3ad38c768e124dc7","schema_version":"edge-lab-recorder.raw.v1","sequence":null,"source":"clob_market_ws"}
{"event_at":"2026-07-27T03:22:27.002000Z","event_fingerprint":"730a87145b37ef8ca913b16478807fbd1688a3b26ce0035ea79a18567f223e29","payload":{"connection_id":"c7dc2e4762f849c6b6f9306b6518dcab","event_at":"2026-07-27T03:22:27.002000Z","event_type":"price_change","frame_hash":"56c81ac441d39ab2aeb9c0ee2e79c3dfd0585e32916064dce60e3fccca77a9df","frame_index":0,"kind":"data","monotonic_ns":224530236467333,"payload":{"event_type":"price_change","market":"0x717c0e8ccd4d5c7040185188fbae28be901ca589a11a94b1b38ca36a79eccfeb","price_changes":[{"asset_id":"24254094493625419915756280046002869097156693848522361803041977572204227262166","best_ask":"0.45","best_bid":"0.44","hash":"71bc7e3fca87c7d4a3151c9a4342385fd8022914","price":"0.36","side":"BUY","size":"105"},{"asset_id":"41448400836309843603620980831210604935021861034693225347475867885462478926555","best_ask":"0.56","best_bid":"0.55","hash":"1c5b9c3370373c6e89c4a7256fff38e684fac1f5","price":"0.64","side":"SELL","size":"105"}],"timestamp":"1785122547002"},"payload_hash":"6b09a1eb5038fab5d8d6cf196591816e16b0cbb64bece64d48a955eb895a0273","raw_frame":"{\"market\":\"0x717c0e8ccd4d5c7040185188fbae28be901ca589a11a94b1b38ca36a79eccfeb\", \"price_changes\":[{\"asset_id\":\"24254094493625419915756280046002869097156693848522361803041977572204227262166\", \"price\":\"0.36\", \"size\":\"105\", \"side\":\"BUY\", \"hash\":\"71bc7e3fca87c7d4a3151c9a4342385fd8022914\", \"best_bid\":\"0.44\", \"best_ask\":\"0.45\"}, {\"asset_id\":\"41448400836309843603620980831210604935021861034693225347475867885462478926555\", \"price\":\"0.64\", \"size\":\"105\", \"side\":\"SELL\", \"hash\":\"1c5b9c3370373c6e89c4a7256fff38e684fac1f5\", \"best_bid\":\"0.55\", \"best_ask\":\"0.56\"}], \"timestamp\":\"1785122547002\", \"event_type\":\"price_change\"}","received_at":"2026-07-27T03:22:26.880270Z","schema_version":"clob-market-ws.price_change.v1","sequence":null,"server_hash":null,"server_timestamp":"1785122547002","session_id":"dd162b8dca5f43ff811d304e69a06123","source":"clob_market_ws"},"received_at":"2026-07-27T03:22:26.880270Z","record_id":"0dfdd94cf524d9958d9b74eacfc1caff223e4bc6473ca44a584d9dd13731c9fb","schema_fingerprint":"4aa3821a28b0b7c2400bc59aba4bcc0a76e971dadd19610d3ad38c768e124dc7","schema_version":"edge-lab-recorder.raw.v1","sequence":null,"source":"clob_market_ws"}
{"event_at":"2026-07-27T03:22:27.017000Z","event_fingerprint":"bfc318fcca356ba336d05970521e0a15705f4345f1f751f032581a663ed54ad2","payload":{"connection_id":"c7dc2e4762f849c6b6f9306b6518dcab","event_at":"2026-07-27T03:22:27.017000Z","event_type":"price_change","frame_hash":"11ae1d3d81b2ed4b8c7f84b15603ab1f064a704e864a2926f7de281d947fd181","frame_index":0,"kind":"data","monotonic_ns":224530249991958,"payload":{"event_type":"price_change","market":"0x717c0e8ccd4d5c7040185188fbae28be901ca589a11a94b1b38ca36a79eccfeb","price_changes":[{"asset_id":"41448400836309843603620980831210604935021861034693225347475867885462478926555","best_ask":"0.56","best_bid":"0.55","hash":"4da94aea24995102fbfd0dbf72eccc6b22d17dfd","price":"0.01","side":"BUY","size":"5458.02"},{"asset_id":"24254094493625419915756280046002869097156693848522361803041977572204227262166","best_ask":"0.45","best_bid":"0.44","hash":"78944302e21c6ba4fad8196b48e0d24ac6fff2b4","price":"0.99","side":"SELL","size":"5458.02"}],"timestamp":"1785122547017"},"payload_hash":"c116e79c0ee4d52fa73c601f0266bd1dd53155ceeb72603c1021b3f5d4795894","raw_frame":"{\"market\":\"0x717c0e8ccd4d5c7040185188fbae28be901ca589a11a94b1b38ca36a79eccfeb\", \"price_changes\":[{\"asset_id\":\"41448400836309843603620980831210604935021861034693225347475867885462478926555\", \"price\":\"0.01\", \"size\":\"5458.02\", \"side\":\"BUY\", \"hash\":\"4da94aea24995102fbfd0dbf72eccc6b22d17dfd\", \"best_bid\":\"0.55\", \"best_ask\":\"0.56\"}, {\"asset_id\":\"24254094493625419915756280046002869097156693848522361803041977572204227262166\", \"price\":\"0.99\", \"size\":\"5458.02\", \"side\":\"SELL\", \"hash\":\"78944302e21c6ba4fad8196b48e0d24ac6fff2b4\", \"best_bid\":\"0.44\", \"best_ask\":\"0.45\"}], \"timestamp\":\"1785122547017\", \"event_type\":\"price_change\"}","received_at":"2026-07-27T03:22:26.893798Z","schema_version":"clob-market-ws.price_change.v1","sequence":null,"server_hash":null,"server_timestamp":"1785122547017","session_id":"dd162b8dca5f43ff811d304e69a06123","source":"clob_market_ws"},"received_at":"2026-07-27T03:22:26.893798Z","record_id":"c30e36666d640fe674bc3f27c607842776eb2da727d7612843d0e3ff1e408212","schema_fingerprint":"4aa3821a28b0b7c2400bc59aba4bcc0a76e971dadd19610d3ad38c768e124dc7","schema_version":"edge-lab-recorder.raw.v1","sequence":null,"source":"clob_market_ws"}
{"event_at":"2026-07-27T03:22:27.018000Z","event_fingerprint":"007108a06311197217a6764866cbcc8260b1c5986bb3c9e5440250af59d1b78d","payload":{"connection_id":"c7dc2e4762f849c6b6f9306b6518dcab","event_at":"2026-07-27T03:22:27.018000Z","event_type":"price_change","frame_hash":"7c48ca512104302d6874ed84b3ec68cf8af76842ec44740984bf2338fdcc6842","frame_index":0,"kind":"data","monotonic_ns":224530253125416,"payload":{"event_type":"price_change","market":"0x717c0e8ccd4d5c7040185188fbae28be901ca589a11a94b1b38ca36a79eccfeb","price_changes":[{"asset_id":"24254094493625419915756280046002869097156693848522361803041977572204227262166","best_ask":"0.45","best_bid":"0.44","hash":"ec1d684527c9f066b9aa1018ff6e5675c7c2ffb1","price":"0.01","side":"BUY","size":"5458.02"},{"asset_id":"41448400836309843603620980831210604935021861034693225347475867885462478926555","best_ask":"0.56","best_bid":"0.55","hash":"362ff6311b55f5ad1b35cc63681b67afc1f20cdf","price":"0.99","side":"SELL","size":"5458.02"}],"timestamp":"1785122547018"},"payload_hash":"df764d5cc04cd055dd68c93cf9ef13d4bc434056d933422f032f3a3c1be6a148","raw_frame":"{\"market\":\"0x717c0e8ccd4d5c7040185188fbae28be901ca589a11a94b1b38ca36a79eccfeb\", \"price_changes\":[{\"asset_id\":\"24254094493625419915756280046002869097156693848522361803041977572204227262166\", \"price\":\"0.01\", \"size\":\"5458.02\", \"side\":\"BUY\", \"hash\":\"ec1d684527c9f066b9aa1018ff6e5675c7c2ffb1\", \"best_bid\":\"0.44\", \"best_ask\":\"0.45\"}, {\"asset_id\":\"41448400836309843603620980831210604935021861034693225347475867885462478926555\", \"price\":\"0.99\", \"size\":\"5458.02\", \"side\":\"SELL\", \"hash\":\"362ff6311b55f5ad1b35cc63681b67afc1f20cdf\", \"best_bid\":\"0.55\", \"best_ask\":\"0.56\"}], \"timestamp\":\"1785122547018\", \"event_type\":\"price_change\"}","received_at":"2026-07-27T03:22:26.896933Z","schema_version":"clob-market-ws.price_change.v1","sequence":null,"server_hash":null,"server_timestamp":"1785122547018","session_id":"dd162b8dca5f43ff811d304e69a06123","source":"clob_market_ws"},"received_at":"2026-07-27T03:22:26.896933Z","record_id":"2913ab49df1fdb855e5d109a5d7f15f8585b0564053e5e81be308b04e0397b93","schema_fingerprint":"4aa3821a28b0b7c2400bc59aba4bcc0a76e971dadd19610d3ad38c768e124dc7","schema_version":"edge-lab-recorder.raw.v1","sequence":null,"source":"clob_market_ws"}
{"event_at":"2026-07-27T03:22:27.025000Z","event_fingerprint":"4d3aa6cccd92d07e4aeb3607506094a8ddb92293a596145de4186d101d9e3b5e","payload":{"connection_id":"c7dc2e4762f849c6b6f9306b6518dcab","event_at":"2026-07-27T03:22:27.025000Z","event_type":"price_change","frame_hash":"edaed49eadbb81f14a66620ff50b9b0a11210d706dfe919f47886f8d8398eaac","frame_index":0,"kind":"data","monotonic_ns":224530259033291,"payload":{"event_type":"price_change","market":"0x717c0e8ccd4d5c7040185188fbae28be901ca589a11a94b1b38ca36a79eccfeb","price_changes":[{"asset_id":"24254094493625419915756280046002869097156693848522361803041977572204227262166","best_ask":"0.45","best_bid":"0.44","hash":"2e5625f3acf48da1e9d4e917691d33ac9f4cca04","price":"0.32","side":"BUY","size":"133.41"},{"asset_id":"41448400836309843603620980831210604935021861034693225347475867885462478926555","best_ask":"0.56","best_bid":"0.55","hash":"d57068877b6e2aa6b657fb9393ee54047f3081a9","price":"0.68","side":"SELL","size":"133.41"}],"timestamp":"1785122547025"},"payload_hash":"2d479fcebcafa5ba9449b9e1dfc1799cba13624a7423e16e2bfae2dce5691941","raw_frame":"{\"market\":\"0x717c0e8ccd4d5c7040185188fbae28be901ca589a11a94b1b38ca36a79eccfeb\", \"price_changes\":[{\"asset_id\":\"24254094493625419915756280046002869097156693848522361803041977572204227262166\", \"price\":\"0.32\", \"size\":\"133.41\", \"side\":\"BUY\", \"hash\":\"2e5625f3acf48da1e9d4e917691d33ac9f4cca04\", \"best_bid\":\"0.44\", \"best_ask\":\"0.45\"}, {\"asset_id\":\"41448400836309843603620980831210604935021861034693225347475867885462478926555\", \"price\":\"0.68\", \"size\":\"133.41\", \"side\":\"SELL\", \"hash\":\"d57068877b6e2aa6b657fb9393ee54047f3081a9\", \"best_bid\":\"0.55\", \"best_ask\":\"0.56\"}], \"timestamp\":\"1785122547025\", \"event_type\":\"price_change\"}","received_at":"2026-07-27T03:22:26.902840Z","schema_version":"clob-market-ws.price_change.v1","sequence":null,"server_hash":null,"server_timestamp":"1785122547025","session_id":"dd162b8dca5f43ff811d304e69a06123","source":"clob_market_ws"},"received_at":"2026-07-27T03:22:26.902840Z","record_id":"69498237bef0d2fb760c328bd20008d897e8e5c09fc10ecd05687500d8c90c06","schema_fingerprint":"4aa3821a28b0b7c2400bc59aba4bcc0a76e971dadd19610d3ad38c768e124dc7","schema_version":"edge-lab-recorder.raw.v1","sequence":null,"source":"clob_market_ws"}
{"event_at":"2026-07-27T03:22:27.028000Z","event_fingerprint":"ac5847efe6a61fcc823797b9da5ecb8e7e26dd7048c01d8a8caf4b3b5a264317","payload":{"connection_id":"c7dc2e4762f849c6b6f9306b6518dcab","event_at":"2026-07-27T03:22:27.028000Z","event_type":"price_change","frame_hash":"d2935f782cb52511c74a3e73a5ea04112391f39a9f0854aacbf47d549e5c1078","frame_index":0,"kind":"data","monotonic_ns":224530261872291,"payload":{"event_type":"price_change","market":"0x717c0e8ccd4d5c7040185188fbae28be901ca589a11a94b1b38ca36a79eccfeb","price_changes":[{"asset_id":"24254094493625419915756280046002869097156693848522361803041977572204227262166","best_ask":"0.45","best_bid":"0.44","hash":"9292d54539e445434b9ccbbf42ea03cbf837611a","price":"0.01","side":"BUY","size":"5463.02"},{"asset_id":"41448400836309843603620980831210604935021861034693225347475867885462478926555","best_ask":"0.56","best_bid":"0.55","hash":"0ed149bf01d62b8d2189ff982f501bc435865f88","price":"0.99","side":"SELL","size":"5463.02"}],"timestamp":"1785122547028"},"payload_hash":"5f7f50a26f0ae3a482226a14717a3fc2a086ca5dab8e2ddc88c0f6b1dfea7022","raw_frame":"{\"market\":\"0x717c0e8ccd4d5c7040185188fbae28be901ca589a11a94b1b38ca36a79eccfeb\", \"price_changes\":[{\"asset_id\":\"24254094493625419915756280046002869097156693848522361803041977572204227262166\", \"price\":\"0.01\", \"size\":\"5463.02\", \"side\":\"BUY\", \"hash\":\"9292d54539e445434b9ccbbf42ea03cbf837611a\", \"best_bid\":\"0.44\", \"best_ask\":\"0.45\"}, {\"asset_id\":\"41448400836309843603620980831210604935021861034693225347475867885462478926555\", \"price\":\"0.99\", \"size\":\"5463.02\", \"side\":\"SELL\", \"hash\":\"0ed149bf01d62b8d2189ff982f501bc435865f88\", \"best_bid\":\"0.55\", \"best_ask\":\"0.56\"}], \"timestamp\":\"1785122547028\", \"event_type\":\"price_change\"}","received_at":"2026-07-27T03:22:26.905679Z","schema_version":"clob-market-ws.price_change.v1","sequence":null,"server_hash":null,"server_timestamp":"1785122547028","session_id":"dd162b8dca5f43ff811d304e69a06123","source":"clob_market_ws"},"received_at":"2026-07-27T03:22:26.905679Z","record_id":"111d030d3ca830e806363404cd2b93a1897504060d6e4dbf1ebc013f7da71295","schema_fingerprint":"4aa3821a28b0b7c2400bc59aba4bcc0a76e971dadd19610d3ad38c768e124dc7","schema_version":"edge-lab-recorder.raw.v1","sequence":null,"source":"clob_market_ws"}
{"event_at":"2026-07-27T03:22:27.038000Z","event_fingerprint":"ea1846984138a6251ced644884468001a3fc0118b4a5de68f1c466bd313f9d8e","payload":{"connection_id":"c7dc2e4762f849c6b6f9306b6518dcab","event_at":"2026-07-27T03:22:27.038000Z","event_type":"price_change","frame_hash":"e79ffc88801f185063c015ed13550f83afe3506b9c10a04b42982062623ad0e5","frame_index":0,"kind":"data","monotonic_ns":224530272023833,"payload":{"event_type":"price_change","market":"0x717c0e8ccd4d5c7040185188fbae28be901ca589a11a94b1b38ca36a79eccfeb","price_changes":[{"asset_id":"24254094493625419915756280046002869097156693848522361803041977572204227262166","best_ask":"0.45","best_bid":"0.44","hash":"00f95b727318c5c7ae5f248a4f07f0e5f7d55afb","price":"0.01","side":"BUY","size":"5458.02"},{"asset_id":"41448400836309843603620980831210604935021861034693225347475867885462478926555","best_ask":"0.56","best_bid":"0.55","hash":"6e6eba0af82f1634570490cb619a08fe14a4cb79","price":"0.99","side":"SELL","size":"5458.02"}],"timestamp":"1785122547038"},"payload_hash":"56a888e8dd7ff869b63455d11b530af6178979423d477664594b7d385b38da0d","raw_frame":"{\"market\":\"0x717c0e8ccd4d5c7040185188fbae28be901ca589a11a94b1b38ca36a79eccfeb\", \"price_changes\":[{\"asset_id\":\"24254094493625419915756280046002869097156693848522361803041977572204227262166\", \"price\":\"0.01\", \"size\":\"5458.02\", \"side\":\"BUY\", \"hash\":\"00f95b727318c5c7ae5f248a4f07f0e5f7d55afb\", \"best_bid\":\"0.44\", \"best_ask\":\"0.45\"}, {\"asset_id\":\"41448400836309843603620980831210604935021861034693225347475867885462478926555\", \"price\":\"0.99\", \"size\":\"5458.02\", \"side\":\"SELL\", \"hash\":\"6e6eba0af82f1634570490cb619a08fe14a4cb79\", \"best_bid\":\"0.55\", \"best_ask\":\"0.56\"}], \"timestamp\":\"1785122547038\", \"event_type\":\"price_change\"}","received_at":"2026-07-27T03:22:26.915828Z","schema_version":"clob-market-ws.price_change.v1","sequence":null,"server_hash":null,"server_timestamp":"1785122547038","session_id":"dd162b8dca5f43ff811d304e69a06123","source":"clob_market_ws"},"received_at":"2026-07-27T03:22:26.915828Z","record_id":"7ca773f2edf70b38ec3fce7784f9f319e557c7e046df276e53ca88267a87ddf5","schema_fingerprint":"4aa3821a28b0b7c2400bc59aba4bcc0a76e971dadd19610d3ad38c768e124dc7","schema_version":"edge-lab-recorder.raw.v1","sequence":null,"source":"clob_market_ws"}
{"event_at":"2026-07-27T03:22:27.050000Z","event_fingerprint":"af8f048d3fcc251973b2c10714b3af441b45fbaf5c26f02afc8daa259bc082de","payload":{"connection_id":"c7dc2e4762f849c6b6f9306b6518dcab","event_at":"2026-07-27T03:22:27.050000Z","event_type":"price_change","frame_hash":"39bf68cf836d932549d26e6f6b746071bb584709ad0d7889167044272b167f67","frame_index":0,"kind":"data","monotonic_ns":224530282473708,"payload":{"event_type":"price_change","market":"0x717c0e8ccd4d5c7040185188fbae28be901ca589a11a94b1b38ca36a79eccfeb","price_changes":[{"asset_id":"24254094493625419915756280046002869097156693848522361803041977572204227262166","best_ask":"0.45","best_bid":"0.44","hash":"640d3b3bdbfa3f8c6953ed4a8fcf2ed450538d9a","price":"0.01","side":"BUY","size":"5453.02"},{"asset_id":"41448400836309843603620980831210604935021861034693225347475867885462478926555","best_ask":"0.56","best_bid":"0.55","hash":"6123cb34bcb58bc6d5f05e7d8a37bee773966679","price":"0.99","side":"SELL","size":"5453.02"}],"timestamp":"1785122547050"},"payload_hash":"0f9b07237c014f81c25419e531ba4b75e171c1fa562459dff13368ec6018f48b","raw_frame":"{\"market\":\"0x717c0e8ccd4d5c7040185188fbae28be901ca589a11a94b1b38ca36a79eccfeb\", \"price_changes\":[{\"asset_id\":\"24254094493625419915756280046002869097156693848522361803041977572204227262166\", \"price\":\"0.01\", \"size\":\"5453.02\", \"side\":\"BUY\", \"hash\":\"640d3b3bdbfa3f8c6953ed4a8fcf2ed450538d9a\", \"best_bid\":\"0.44\", \"best_ask\":\"0.45\"}, {\"asset_id\":\"41448400836309843603620980831210604935021861034693225347475867885462478926555\", \"price\":\"0.99\", \"size\":\"5453.02\", \"side\":\"SELL\", \"hash\":\"6123cb34bcb58bc6d5f05e7d8a37bee773966679\", \"best_bid\":\"0.55\", \"best_ask\":\"0.56\"}], \"timestamp\":\"1785122547050\", \"event_type\":\"price_change\"}","received_at":"2026-07-27T03:22:26.926274Z","schema_version":"clob-market-ws.price_change.v1","sequence":null,"server_hash":null,"server_timestamp":"1785122547050","session_id":"dd162b8dca5f43ff811d304e69a06123","source":"clob_market_ws"},"received_at":"2026-07-27T03:22:26.926274Z","record_id":"6d60b052e36b45b72302dea6341b59f721fed22b0d067b30fb252ee9167339b9","schema_fingerprint":"4aa3821a28b0b7c2400bc59aba4bcc0a76e971dadd19610d3ad38c768e124dc7","schema_version":"edge-lab-recorder.raw.v1","sequence":null,"source":"clob_market_ws"}
{"event_at":"2026-07-27T03:22:27.053000Z","event_fingerprint":"b5628a4def5906d223c3074715c82e049c5aa8c1f153c5217e2e047c94a844b8","payload":{"connection_id":"c7dc2e4762f849c6b6f9306b6518dcab","event_at":"2026-07-27T03:22:27.053000Z","event_type":"price_change","frame_hash":"fc83fb65dbf901dc4c75966f3043278719d82c10a20e86351e55c779356fd669","frame_index":0,"kind":"data","monotonic_ns":224530287266583,"payload":{"event_type":"price_change","market":"0x717c0e8ccd4d5c7040185188fbae28be901ca589a11a94b1b38ca36a79eccfeb","price_changes":[{"asset_id":"41448400836309843603620980831210604935021861034693225347475867885462478926555","best_ask":"0.56","best_bid":"0.55","hash":"fda87942c5d096a55a6d2787b195c717cbc51ce5","price":"0.01","side":"BUY","size":"5463.02"},{"asset_id":"24254094493625419915756280046002869097156693848522361803041977572204227262166","best_ask":"0.45","best_bid":"0.44","hash":"2a3b8222743e234b44b1cba612781bcf5f57ca03","price":"0.99","side":"SELL","size":"5463.02"}],"timestamp":"1785122547053"},"payload_hash":"b1f1294648a78b24aeb9a680a3074ec608041a3793b59c65aadafa6562da67dd","raw_frame":"{\"market\":\"0x717c0e8ccd4d5c7040185188fbae28be901ca589a11a94b1b38ca36a79eccfeb\", \"price_changes\":[{\"asset_id\":\"41448400836309843603620980831210604935021861034693225347475867885462478926555\", \"price\":\"0.01\", \"size\":\"5463.02\", \"side\":\"BUY\", \"hash\":\"fda87942c5d096a55a6d2787b195c717cbc51ce5\", \"best_bid\":\"0.55\", \"best_ask\":\"0.56\"}, {\"asset_id\":\"24254094493625419915756280046002869097156693848522361803041977572204227262166\", \"price\":\"0.99\", \"size\":\"5463.02\", \"side\":\"SELL\", \"hash\":\"2a3b8222743e234b44b1cba612781bcf5f57ca03\", \"best_bid\":\"0.44\", \"best_ask\":\"0.45\"}], \"timestamp\":\"1785122547053\", \"event_type\":\"price_change\"}","received_at":"2026-07-27T03:22:26.931073Z","schema_version":"clob-market-ws.price_change.v1","sequence":null,"server_hash":null,"server_timestamp":"1785122547053","session_id":"dd162b8dca5f43ff811d304e69a06123","source":"clob_market_ws"},"received_at":"2026-07-27T03:22:26.931073Z","record_id":"44312e1e5052d72b84e642fcda3973e6ba72a93b922c9647e68ad42091d5f655","schema_fingerprint":"4aa3821a28b0b7c2400bc59aba4bcc0a76e971dadd19610d3ad38c768e124dc7","schema_version":"edge-lab-recorder.raw.v1","sequence":null,"source":"clob_market_ws"}
{"event_at":"2026-07-27T03:22:27.059000Z","event_fingerprint":"6732b26dbab52e3afd483777d2f602c988d11cc598ce739c27246885d93d9b10","payload":{"connection_id":"c7dc2e4762f849c6b6f9306b6518dcab","event_at":"2026-07-27T03:22:27.059000Z","event_type":"price_change","frame_hash":"9353193cf03c49cb78c7218e1d28e5314b83cbf2fd80418d70bcf75b7ab7262f","frame_index":0,"kind":"data","monotonic_ns":224530293784083,"payload":{"event_type":"price_change","market":"0x717c0e8ccd4d5c7040185188fbae28be901ca589a11a94b1b38ca36a79eccfeb","price_changes":[{"asset_id":"41448400836309843603620980831210604935021861034693225347475867885462478926555","best_ask":"0.56","best_bid":"0.55","hash":"7a4426985e0cfd8a9e40489f3984e249a6a6b95d","price":"0.45","side":"BUY","size":"110"},{"asset_id":"24254094493625419915756280046002869097156693848522361803041977572204227262166","best_ask":"0.45","best_bid":"0.44","hash":"90d45b3af456f60bcc43a9a96ed844c524dd5656","price":"0.55","side":"SELL","size":"110"}],"timestamp":"1785122547059"},"payload_hash":"2e0ba98289cff9a9cf7cc0e0e74fe82afcfef189942e51d6070c574b0b3d02ed","raw_frame":"{\"market\":\"0x717c0e8ccd4d5c7040185188fbae28be901ca589a11a94b1b38ca36a79eccfeb\", \"price_changes\":[{\"asset_id\":\"41448400836309843603620980831210604935021861034693225347475867885462478926555\", \"price\":\"0.45\", \"size\":\"110\", \"side\":\"BUY\", \"hash\":\"7a4426985e0cfd8a9e40489f3984e249a6a6b95d\", \"best_bid\":\"0.55\", \"best_ask\":\"0.56\"}, {\"asset_id\":\"24254094493625419915756280046002869097156693848522361803041977572204227262166\", \"price\":\"0.55\", \"size\":\"110\", \"side\":\"SELL\", \"hash\":\"90d45b3af456f60bcc43a9a96ed844c524dd5656\", \"best_bid\":\"0.44\", \"best_ask\":\"0.45\"}], \"timestamp\":\"1785122547059\", \"event_type\":\"price_change\"}","received_at":"2026-07-27T03:22:26.937589Z","schema_version":"clob-market-ws.price_change.v1","sequence":null,"server_hash":null,"server_timestamp":"1785122547059","session_id":"dd162b8dca5f43ff811d304e69a06123","source":"clob_market_ws"},"received_at":"2026-07-27T03:22:26.937589Z","record_id":"c8908c99ffecff8dcd9e84754bd62060db40bdc098e338068d34b4321bbd4021","schema_fingerprint":"4aa3821a28b0b7c2400bc59aba4bcc0a76e971dadd19610d3ad38c768e124dc7","schema_version":"edge-lab-recorder.raw.v1","sequence":null,"source":"clob_market_ws"}
{"event_at":"2026-07-27T03:22:27.064000Z","event_fingerprint":"fcc6d0b95496db2b421b7334fe9555e8aea6c69781c7e273b57b2a474aa10db4","payload":{"connection_id":"c7dc2e4762f849c6b6f9306b6518dcab","event_at":"2026-07-27T03:22:27.064000Z","event_type":"price_change","frame_hash":"fb60ce037dd1cc1f71fe4d748528bda30d07835e59c70fa72fe5f03dcb04013f","frame_index":0,"kind":"data","monotonic_ns":224530298779958,"payload":{"event_type":"price_change","market":"0x717c0e8ccd4d5c7040185188fbae28be901ca589a11a94b1b38ca36a79eccfeb","price_changes":[{"asset_id":"41448400836309843603620980831210604935021861034693225347475867885462478926555","best_ask":"0.56","best_bid":"0.55","hash":"ac6b721d17e57ec5e1a37a252217dfbca4b8863f","price":"0.44","side":"BUY","size":"243"},{"asset_id":"24254094493625419915756280046002869097156693848522361803041977572204227262166","best_ask":"0.45","best_bid":"0.44","hash":"6fb445aa89b613c10b1adb996f9414e19bee8a2e","price":"0.56","side":"SELL","size":"243"}],"timestamp":"1785122547064"},"payload_hash":"0bda4b965ff4988277fa558277d89a17aee4f77b4f630599bcc6e28e56d26020","raw_frame":"{\"market\":\"0x717c0e8ccd4d5c7040185188fbae28be901ca589a11a94b1b38ca36a79eccfeb\", \"price_changes\":[{\"asset_id\":\"41448400836309843603620980831210604935021861034693225347475867885462478926555\", \"price\":\"0.44\", \"size\":\"243\", \"side\":\"BUY\", \"hash\":\"ac6b721d17e57ec5e1a37a252217dfbca4b8863f\", \"best_bid\":\"0.55\", \"best_ask\":\"0.56\"}, {\"asset_id\":\"24254094493625419915756280046002869097156693848522361803041977572204227262166\", \"price\":\"0.56\", \"size\":\"243\", \"side\":\"SELL\", \"hash\":\"6fb445aa89b613c10b1adb996f9414e19bee8a2e\", \"best_bid\":\"0.44\", \"best_ask\":\"0.45\"}], \"timestamp\":\"1785122547064\", \"event_type\":\"price_change\"}","received_at":"2026-07-27T03:22:26.942585Z","schema_version":"clob-market-ws.price_change.v1","sequence":null,"server_hash":null,"server_timestamp":"1785122547064","session_id":"dd162b8dca5f43ff811d304e69a06123","source":"clob_market_ws"},"received_at":"2026-07-27T03:22:26.942585Z","record_id":"5010808ff1ec7cd0aab644bb2a67ba0e5f472f369f65e0a3c91484aab612e220","schema_fingerprint":"4aa3821a28b0b7c2400bc59aba4bcc0a76e971dadd19610d3ad38c768e124dc7","schema_version":"edge-lab-recorder.raw.v1","sequence":null,"source":"clob_market_ws"}
{"event_at":"2026-07-27T03:22:27.065000Z","event_fingerprint":"3b2a0b52c0420b3c5e8101342e8ccaa61664ca52e890564d8a5e00c8ccb6a044","payload":{"connection_id":"c7dc2e4762f849c6b6f9306b6518dcab","event_at":"2026-07-27T03:22:27.065000Z","event_type":"price_change","frame_hash":"8d3788d5d1fad697f20f2e867a7b5f911e1341aa7cdb3d3338cf67f4da5992f0","frame_index":0,"kind":"data","monotonic_ns":224530300320916,"payload":{"event_type":"price_change","market":"0x717c0e8ccd4d5c7040185188fbae28be901ca589a11a94b1b38ca36a79eccfeb","price_changes":[{"asset_id":"41448400836309843603620980831210604935021861034693225347475867885462478926555","best_ask":"0.56","best_bid":"0.55","hash":"269aeff90526385657e74389e1c9a524ab375a00","price":"0.63","side":"SELL","size":"220"},{"asset_id":"24254094493625419915756280046002869097156693848522361803041977572204227262166","best_ask":"0.45","best_bid":"0.44","hash":"ecb905136bb66a098ac36bf961d0096f3e2dda91","price":"0.37","side":"BUY","size":"220"}],"timestamp":"1785122547065"},"payload_hash":"e0ee43aca3cabfccfc2a81d02f7069e2fd234b04bcccacb4756a432e276fb615","raw_frame":"{\"market\":\"0x717c0e8ccd4d5c7040185188fbae28be901ca589a11a94b1b38ca36a79eccfeb\", \"price_changes\":[{\"asset_id\":\"41448400836309843603620980831210604935021861034693225347475867885462478926555\", \"price\":\"0.63\", \"size\":\"220\", \"side\":\"SELL\", \"hash\":\"269aeff90526385657e74389e1c9a524ab375a00\", \"best_bid\":\"0.55\", \"best_ask\":\"0.56\"}, {\"asset_id\":\"24254094493625419915756280046002869097156693848522361803041977572204227262166\", \"price\":\"0.37\", \"size\":\"220\", \"side\":\"BUY\", \"hash\":\"ecb905136bb66a098ac36bf961d0096f3e2dda91\", \"best_bid\":\"0.44\", \"best_ask\":\"0.45\"}], \"timestamp\":\"1785122547065\", \"event_type\":\"price_change\"}","received_at":"2026-07-27T03:22:26.944127Z","schema_version":"clob-market-ws.price_change.v1","sequence":null,"server_hash":null,"server_timestamp":"1785122547065","session_id":"dd162b8dca5f43ff811d304e69a06123","source":"clob_market_ws"},"received_at":"2026-07-27T03:22:26.944127Z","record_id":"6e931732f311a8684d7e5d6d5b71f1f07fb5d2288d88c8e95abe270a01e3c7d5","schema_fingerprint":"4aa3821a28b0b7c2400bc59aba4bcc0a76e971dadd19610d3ad38c768e124dc7","schema_version":"edge-lab-recorder.raw.v1","sequence":null,"source":"clob_market_ws"}
{"event_at":"2026-07-27T03:22:27.067000Z","event_fingerprint":"c7c312d4638a0dd88ed425f13d532783599787ae197470a2355dbd7f00aa8dec","payload":{"connection_id":"c7dc2e4762f849c6b6f9306b6518dcab","event_at":"2026-07-27T03:22:27.067000Z","event_type":"price_change","frame_hash":"2857ccb146e993ab98d06f96267f1d85bca1097ea7e6dc7265564de96441eb9b","frame_index":0,"kind":"data","monotonic_ns":224530301921958,"payload":{"event_type":"price_change","market":"0x717c0e8ccd4d5c7040185188fbae28be901ca589a11a94b1b38ca36a79eccfeb","price_changes":[{"asset_id":"24254094493625419915756280046002869097156693848522361803041977572204227262166","best_ask":"0.45","best_bid":"0.44","hash":"5242424abea6a2d9b5db207ddd49fb950726980b","price":"0.37","side":"BUY","size":"195"},{"asset_id":"41448400836309843603620980831210604935021861034693225347475867885462478926555","best_ask":"0.56","best_bid":"0.55","hash":"a1b0fb108e7da5542dc09ea40aa79ad1f41c96dd","price":"0.63","side":"SELL","size":"195"}],"timestamp":"1785122547067"},"payload_hash":"138396453cbf975c8c04d084608316482c443ad03cd9277c4834580ad994b91b","raw_frame":"{\"market\":\"0x717c0e8ccd4d5c7040185188fbae28be901ca589a11a94b1b38ca36a79eccfeb\", \"price_changes\":[{\"asset_id\":\"24254094493625419915756280046002869097156693848522361803041977572204227262166\", \"price\":\"0.37\", \"size\":\"195\", \"side\":\"BUY\", \"hash\":\"5242424abea6a2d9b5db207ddd49fb950726980b\", \"best_bid\":\"0.44\", \"best_ask\":\"0.45\"}, {\"asset_id\":\"41448400836309843603620980831210604935021861034693225347475867885462478926555\", \"price\":\"0.63\", \"size\":\"195\", \"side\":\"SELL\", \"hash\":\"a1b0fb108e7da5542dc09ea40aa79ad1f41c96dd\", \"best_bid\":\"0.55\", \"best_ask\":\"0.56\"}], \"timestamp\":\"1785122547067\", \"event_type\":\"price_change\"}","received_at":"2026-07-27T03:22:26.945729Z","schema_version":"clob-market-ws.price_change.v1","sequence":null,"server_hash":null,"server_timestamp":"1785122547067","session_id":"dd162b8dca5f43ff811d304e69a06123","source":"clob_market_ws"},"received_at":"2026-07-27T03:22:26.945729Z","record_id":"c7f3a84d616ede64d2fbc606f6418f5f395c2603d48c5e10de05704bf38a92dc","schema_fingerprint":"4aa3821a28b0b7c2400bc59aba4bcc0a76e971dadd19610d3ad38c768e124dc7","schema_version":"edge-lab-recorder.raw.v1","sequence":null,"source":"clob_market_ws"}
{"event_at":"2026-07-27T03:22:27.078000Z","event_fingerprint":"b4a62f0f2e2562a47166cd1b5ca8ac607cf643b6cf0a136f5ba0dc7fdf5367d9","payload":{"connection_id":"c7dc2e4762f849c6b6f9306b6518dcab","event_at":"2026-07-27T03:22:27.078000Z","event_type":"price_change","frame_hash":"1df24ebe79f4b09c127225a81a0fe1b2c4444d5c6eab93d0447b0dc97f34a787","frame_index":0,"kind":"data","monotonic_ns":224530312818333,"payload":{"event_type":"price_change","market":"0x717c0e8ccd4d5c7040185188fbae28be901ca589a11a94b1b38ca36a79eccfeb","price_changes":[{"asset_id":"41448400836309843603620980831210604935021861034693225347475867885462478926555","best_ask":"0.56","best_bid":"0.55","hash":"a142c47cf1e7fa9d4e37d777214ccd3edf39a198","price":"0.01","side":"BUY","size":"5458.02"},{"asset_id":"24254094493625419915756280046002869097156693848522361803041977572204227262166","best_ask":"0.45","best_bid":"0.44","hash":"5b94bf179440e26433cd9c5df8bc126e53a7af7f","price":"0.99","side":"SELL","size":"5458.02"}],"timestamp":"1785122547078"},"payload_hash":"73a5de7854f547c121e584f3e69181767f92d9b57c4d70004b71ec0697862db1","raw_frame":"{\"market\":\"0x717c0e8ccd4d5c7040185188fbae28be901ca589a11a94b1b38ca36a79eccfeb\", \"price_changes\":[{\"asset_id\":\"41448400836309843603620980831210604935021861034693225347475867885462478926555\", \"price\":\"0.01\", \"size\":\"5458.02\", \"side\":\"BUY\", \"hash\":\"a142c47cf1e7fa9d4e37d777214ccd3edf39a198\", \"best_bid\":\"0.55\", \"best_ask\":\"0.56\"}, {\"asset_id\":\"24254094493625419915756280046002869097156693848522361803041977572204227262166\", \"price\":\"0.99\", \"size\":\"5458.02\", \"side\":\"SELL\", \"hash\":\"5b94bf179440e26433cd9c5df8bc126e53a7af7f\", \"best_bid\":\"0.44\", \"best_ask\":\"0.45\"}], \"timestamp\":\"1785122547078\", \"event_type\":\"price_change\"}","received_at":"2026-07-27T03:22:26.956623Z","schema_version":"clob-market-ws.price_change.v1","sequence":null,"server_hash":null,"server_timestamp":"1785122547078","session_id":"dd162b8dca5f43ff811d304e69a06123","source":"clob_market_ws"},"received_at":"2026-07-27T03:22:26.956623Z","record_id":"9d1469d84c1acb566e4e4a7c9edb6eed6d651cec2e1f310a7f480e9ddf643e01","schema_fingerprint":"4aa3821a28b0b7c2400bc59aba4bcc0a76e971dadd19610d3ad38c768e124dc7","schema_version":"edge-lab-recorder.raw.v1","sequence":null,"source":"clob_market_ws"}
{"event_at":"2026-07-27T03:22:27.079000Z","event_fingerprint":"e6e0cb01108a74388cc4e1ca1f3ca935894beadaa12f6000245bbf6ddec76ec4","payload":{"connection_id":"c7dc2e4762f849c6b6f9306b6518dcab","event_at":"2026-07-27T03:22:27.079000Z","event_type":"price_change","frame_hash":"1af7182a3e32e2e3925147ec4edc160a2daa31b1e351417be8ede7e6be5d0be5","frame_index":0,"kind":"data","monotonic_ns":224530320805125,"payload":{"event_type":"price_change","market":"0x717c0e8ccd4d5c7040185188fbae28be901ca589a11a94b1b38ca36a79eccfeb","price_changes":[{"asset_id":"41448400836309843603620980831210604935021861034693225347475867885462478926555","best_ask":"0.56","best_bid":"0.55","hash":"51f31ddd625ebe5a1b5c543d64f76ebc2c928148","price":"0.01","side":"BUY","size":"5453.02"},{"asset_id":"24254094493625419915756280046002869097156693848522361803041977572204227262166","best_ask":"0.45","best_bid":"0.44","hash":"84f522bb779b6fb00753fbdeecf37c3d1506b352","price":"0.99","side":"SELL","size":"5453.02"}],"timestamp":"1785122547079"},"payload_hash":"bf30595010b54f1f25e2ef71a3146215113d3023c620b3de05caa824a4b869d4","raw_frame":"{\"market\":\"0x717c0e8ccd4d5c7040185188fbae28be901ca589a11a94b1b38ca36a79eccfeb\", \"price_changes\":[{\"asset_id\":\"41448400836309843603620980831210604935021861034693225347475867885462478926555\", \"price\":\"0.01\", \"size\":\"5453.02\", \"side\":\"BUY\", \"hash\":\"51f31ddd625ebe5a1b5c543d64f76ebc2c928148\", \"best_bid\":\"0.55\", \"best_ask\":\"0.56\"}, {\"asset_id\":\"24254094493625419915756280046002869097156693848522361803041977572204227262166\", \"price\":\"0.99\", \"size\":\"5453.02\", \"side\":\"SELL\", \"hash\":\"84f522bb779b6fb00753fbdeecf37c3d1506b352\", \"best_bid\":\"0.44\", \"best_ask\":\"0.45\"}], \"timestamp\":\"1785122547079\", \"event_type\":\"price_change\"}","received_at":"2026-07-27T03:22:26.964612Z","schema_version":"clob-market-ws.price_change.v1","sequence":null,"server_hash":null,"server_timestamp":"1785122547079","session_id":"dd162b8dca5f43ff811d304e69a06123","source":"clob_market_ws"},"received_at":"2026-07-27T03:22:26.964612Z","record_id":"0e6416e448fe350368c0b619e15286a8d6d7e295edf2cdca3dd945cf8c5f2c24","schema_fingerprint":"4aa3821a28b0b7c2400bc59aba4bcc0a76e971dadd19610d3ad38c768e124dc7","schema_version":"edge-lab-recorder.raw.v1","sequence":null,"source":"clob_market_ws"}
{"event_at":"2026-07-27T03:22:27.087000Z","event_fingerprint":"113cf61ee725ca43f1eb28d36d33e7aa5eb9d3fade2c513e44707d66b368f229","payload":{"connection_id":"c7dc2e4762f849c6b6f9306b6518dcab","event_at":"2026-07-27T03:22:27.087000Z","event_type":"price_change","frame_hash":"1b361f0556c4eac76ed1f16c70a5df46e2786196b1441ee72aa4726d33d5f70b","frame_index":0,"kind":"data","monotonic_ns":224530325396916,"payload":{"event_type":"price_change","market":"0x717c0e8ccd4d5c7040185188fbae28be901ca589a11a94b1b38ca36a79eccfeb","price_changes":[{"asset_id":"24254094493625419915756280046002869097156693848522361803041977572204227262166","best_ask":"0.45","best_bid":"0.44","hash":"080ee4aecbae492e096de2353a33fa714ac8043f","price":"0.38","side":"BUY","size":"40"},{"asset_id":"41448400836309843603620980831210604935021861034693225347475867885462478926555","best_ask":"0.56","best_bid":"0.55","hash":"39caeb1b9701058c167d42d2e78312c8fecb57a6","price":"0.62","side":"SELL","size":"40"}],"timestamp":"1785122547087"},"payload_hash":"99b563630d3c592d9134afba107ca3258f9250c3e030cd4edaff4d86efe0a58f","raw_frame":"{\"market\":\"0x717c0e8ccd4d5c7040185188fbae28be901ca589a11a94b1b38ca36a79eccfeb\", \"price_changes\":[{\"asset_id\":\"24254094493625419915756280046002869097156693848522361803041977572204227262166\", \"price\":\"0.38\", \"size\":\"40\", \"side\":\"BUY\", \"hash\":\"080ee4aecbae492e096de2353a33fa714ac8043f\", \"best_bid\":\"0.44\", \"best_ask\":\"0.45\"}, {\"asset_id\":\"41448400836309843603620980831210604935021861034693225347475867885462478926555\", \"price\":\"0.62\", \"size\":\"40\", \"side\":\"SELL\", \"hash\":\"39caeb1b9701058c167d42d2e78312c8fecb57a6\", \"best_bid\":\"0.55\", \"best_ask\":\"0.56\"}], \"timestamp\":\"1785122547087\", \"event_type\":\"price_change\"}","received_at":"2026-07-27T03:22:26.969203Z","schema_version":"clob-market-ws.price_change.v1","sequence":null,"server_hash":null,"server_timestamp":"1785122547087","session_id":"dd162b8dca5f43ff811d304e69a06123","source":"clob_market_ws"},"received_at":"2026-07-27T03:22:26.969203Z","record_id":"10ca7cae5e3dd4e4bdea33d7b2c86774a69fbbcab258fb1d3991cb48d0a93b68","schema_fingerprint":"4aa3821a28b0b7c2400bc59aba4bcc0a76e971dadd19610d3ad38c768e124dc7","schema_version":"edge-lab-recorder.raw.v1","sequence":null,"source":"clob_market_ws"}
