{"event_at":"2026-07-27T03:30:01.221000Z","event_fingerprint":"6b3c7316db560454ec65914e1a6de02dade0219b28ebcbe52939720f31503aee","payload":{"connection_id":"c7dc2e4762f849c6b6f9306b6518dcab","event_at":"2026-07-27T03:30:01.221000Z","event_type":"price_change","frame_hash":"b6e8c5481da4ec59daa240a1889b48c4a8da3d7211175f8747bb6ea0e833ca60","frame_index":0,"kind":"data","monotonic_ns":224985146680291,"payload":{"event_type":"price_change","market":"0x717c0e8ccd4d5c7040185188fbae28be901ca589a11a94b1b38ca36a79eccfeb","price_changes":[{"asset_id":"24254094493625419915756280046002869097156693848522361803041977572204227262166","best_ask":"1","best_bid":"0.99","hash":"c9e2411563b03625a925c8bf63c7d701162e0839","price":"0.99","side":"BUY","size":"240702"},{"asset_id":"41448400836309843603620980831210604935021861034693225347475867885462478926555","best_ask":"0.01","best_bid":"0","hash":"dba548d1f25f3d895c393a870aef4e8e50771446","price":"0.01","side":"SELL","size":"240702"}],"timestamp":"1785123001221"},"payload_hash":"2a8a801dcc098c0e4dbcd02f74baba3edf4d21126120c503636c390619cf8c67","raw_frame":"{\"market\":\"0x717c0e8ccd4d5c7040185188fbae28be901ca589a11a94b1b38ca36a79eccfeb\", \"price_changes\":[{\"asset_id\":\"24254094493625419915756280046002869097156693848522361803041977572204227262166\", \"price\":\"0.99\", \"size\":\"240702\", \"side\":\"BUY\", \"hash\":\"c9e2411563b03625a925c8bf63c7d701162e0839\", \"best_bid\":\"0.99\", \"best_ask\":\"1\"}, {\"asset_id\":\"41448400836309843603620980831210604935021861034693225347475867885462478926555\", \"price\":\"0.01\", \"size\":\"240702\", \"side\":\"SELL\", \"hash\":\"dba548d1f25f3d895c393a870aef4e8e50771446\", \"best_bid\":\"0\", \"best_ask\":\"0.01\"}], \"timestamp\":\"1785123001221\", \"event_type\":\"price_change\"}","received_at":"2026-07-27T03:30:01.782887Z","schema_version":"clob-market-ws.price_change.v1","sequence":null,"server_hash":null,"server_timestamp":"1785123001221","session_id":"dd162b8dca5f43ff811d304e69a06123","source":"clob_market_ws"},"received_at":"2026-07-27T03:30:01.782887Z","record_id":"9fc3e0c72d93c9ee00388214833cdfe53bdd509d51fdc1722e85ec8e771cd7ae","schema_fingerprint":"4aa3821a28b0b7c2400bc59aba4bcc0a76e971dadd19610d3ad38c768e124dc7","schema_version":"edge-lab-recorder.raw.v1","sequence":null,"source":"clob_market_ws"}
{"event_at":"2026-07-27T03:30:01.222000Z","event_fingerprint":"9c3c08e1565fd94bea8b2fe940f8fb360811a9103987d4728ffde675a2229c0b","payload":{"connection_id":"c7dc2e4762f849c6b6f9306b6518dcab","event_at":"2026-07-27T03:30:01.222000Z","event_type":"price_change","frame_hash":"a8e6eb7d680e71fb70bfe22828846661a927f374d3dcbeabc3a46e7f0cadc75b","frame_index":0,"kind":"data","monotonic_ns":224985166057625,"payload":{"event_type":"price_change","market":"0x717c0e8ccd4d5c7040185188fbae28be901ca589a11a94b1b38ca36a79eccfeb","price_changes":[{"asset_id":"24254094493625419915756280046002869097156693848522361803041977572204227262166","best_ask":"1","best_bid":"0.99","hash":"4bf1c2c72d1507e4d75bf707528b694b31212d6a","price":"0.99","side":"BUY","size":"246062"},{"asset_id":"41448400836309843603620980831210604935021861034693225347475867885462478926555","best_ask":"0.01","best_bid":"0","hash":"8faaf8661707497ffaeac02ac368510c2d235bd3","price":"0.01","side":"SELL","size":"246062"}],"timestamp":"1785123001222"},"payload_hash":"50df9a6388c98440effab1f227bea2a443a0612a37d8a1d625a4091f10e24286","raw_frame":"{\"market\":\"0x717c0e8ccd4d5c7040185188fbae28be901ca589a11a94b1b38ca36a79eccfeb\", \"price_changes\":[{\"asset_id\":\"24254094493625419915756280046002869097156693848522361803041977572204227262166\", \"price\":\"0.99\", \"size\":\"246062\", \"side\":\"BUY\", \"hash\":\"4bf1c2c72d1507e4d75bf707528b694b31212d6a\", \"best_bid\":\"0.99\", \"best_ask\":\"1\"}, {\"asset_id\":\"41448400836309843603620980831210604935021861034693225347475867885462478926555\", \"price\":\"0.01\", \"size\":\"246062\", \"side\":\"SELL\", \"hash\":\"8faaf8661707497ffaeac02ac368510c2d235bd3\", \"best_bid\":\"0\", \"best_ask\":\"0.01\"}], \"timestamp\":\"1785123001222\", \"event_type\":\"price_change\"}","received_at":"2026-07-27T03:30:01.802261Z","schema_version":"clob-market-ws.price_change.v1","sequence":null,"server_hash":null,"server_timestamp":"1785123001222","session_id":"dd162b8dca5f43ff811d304e69a06123","source":"clob_market_ws"},"received_at":"2026-07-27T03:30:01.802261Z","record_id":"4dae05b9e9698233a08e67fc433a1bde221dfb342d237de2c1e1e9d2990d8d3d","schema_fingerprint":"4aa3821a28b0b7c2400bc59aba4bcc0a76e971dadd19610d3ad38c768e124dc7","schema_version":"edge-lab-recorder.raw.v1","sequence":null,"source":"clob_market_ws"}
{"event_at":"2026-07-27T03:30:01.223000Z","event_fingerprint":"b91f9947f2f7b7e1d527117694484d0c5b1737d5d6e3c614872b1f707a198a6c","payload":{"connection_id":"c7dc2e4762f849c6b6f9306b6518dcab","event_at":"2026-07-27T03:30:01.223000Z","event_type":"price_change","frame_hash":"a6f5fadc5b33894e21c75ce7e65681bf711cee3f9467bd4cf1408a52bc123338","frame_index":0,"kind":"data","monotonic_ns":224985174676791,"payload":{"event_type":"price_change","market":"0x717c0e8ccd4d5c7040185188fbae28be901ca589a11a94b1b38ca36a79eccfeb","price_changes":[{"asset_id":"24254094493625419915756280046002869097156693848522361803041977572204227262166","best_ask":"1","best_bid":"0.99","hash":"b57bbd4ead850560192872ee76a1004f9f3bab7e","price":"0.99","side":"BUY","size":"251501"},{"asset_id":"41448400836309843603620980831210604935021861034693225347475867885462478926555","best_ask":"0.01","best_bid":"0","hash":"6f3d434aec048129237ae9cc53f4d052faad5f64","price":"0.01","side":"SELL","size":"251501"}],"timestamp":"1785123001223"},"payload_hash":"24ae5eac0a0249fd2d816cdefc6773f91f4614095dad71e236592019fd9c6112","raw_frame":"{\"market\":\"0x717c0e8ccd4d5c7040185188fbae28be901ca589a11a94b1b38ca36a79eccfeb\", \"price_changes\":[{\"asset_id\":\"24254094493625419915756280046002869097156693848522361803041977572204227262166\", \"price\":\"0.99\", \"size\":\"251501\", \"side\":\"BUY\", \"hash\":\"b57bbd4ead850560192872ee76a1004f9f3bab7e\", \"best_bid\":\"0.99\", \"best_ask\":\"1\"}, {\"asset_id\":\"41448400836309843603620980831210604935021861034693225347475867885462478926555\", \"price\":\"0.01\", \"size\":\"251501\", \"side\":\"SELL\", \"hash\":\"6f3d434aec048129237ae9cc53f4d052faad5f64\", \"best_bid\":\"0\", \"best_ask\":\"0.01\"}], \"timestamp\":\"1785123001223\", \"event_type\":\"price_change\"}","received_at":"2026-07-27T03:30:01.810881Z","schema_version":"clob-market-ws.price_change.v1","sequence":null,"server_hash":null,"server_timestamp":"1785123001223","session_id":"dd162b8dca5f43ff811d304e69a06123","source":"clob_market_ws"},"received_at":"2026-07-27T03:30:01.810881Z","record_id":"7f6ae74c763426963913a0936481a5541a638e2b72bc1cead270f8caf993bddd","schema_fingerprint":"4aa3821a28b0b7c2400bc59aba4bcc0a76e971dadd19610d3ad38c768e124dc7","schema_version":"edge-lab-recorder.raw.v1","sequence":null,"source":"clob_market_ws"}
{"event_at":"2026-07-27T03:30:01.223000Z","event_fingerprint":"3bd7a880d9cb74c139615e3ba389a72a285938ee89d9ea9c312032c794d2ff61","payload":{"connection_id":"c7dc2e4762f849c6b6f9306b6518dcab","event_at":"2026-07-27T03:30:01.223000Z","event_type":"price_change","frame_hash":"798d28b4e651ca87cd11ed23cc90650b47e864badffa516185bdac88744fbb56","frame_index":0,"kind":"data","monotonic_ns":224985186535750,"payload":{"event_type":"price_change","market":"0x717c0e8ccd4d5c7040185188fbae28be901ca589a11a94b1b38ca36a79eccfeb","price_changes":[{"asset_id":"24254094493625419915756280046002869097156693848522361803041977572204227262166","best_ask":"1","best_bid":"0.99","hash":"c5c496850406a5b2311fb74405e18cc6025153ee","price":"0.99","side":"BUY","size":"256721"},{"asset_id":"41448400836309843603620980831210604935021861034693225347475867885462478926555","best_ask":"0.01","best_bid":"0","hash":"79cfaa6ceec95159bb7efa7b4c9303df3a79311f","price":"0.01","side":"SELL","size":"256721"}],"timestamp":"1785123001223"},"payload_hash":"fdcbafd6c5d0badccbc169e31fc14795209650394a05d17f7b59d03d99ebc795","raw_frame":"{\"market\":\"0x717c0e8ccd4d5c7040185188fbae28be901ca589a11a94b1b38ca36a79eccfeb\", \"price_changes\":[{\"asset_id\":\"24254094493625419915756280046002869097156693848522361803041977572204227262166\", \"price\":\"0.99\", \"size\":\"256721\", \"side\":\"BUY\", \"hash\":\"c5c496850406a5b2311fb74405e18cc6025153ee\", \"best_bid\":\"0.99\", \"best_ask\":\"1\"}, {\"asset_id\":\"41448400836309843603620980831210604935021861034693225347475867885462478926555\", \"price\":\"0.01\", \"size\":\"256721\", \"side\":\"SELL\", \"hash\":\"79cfaa6ceec95159bb7efa7b4c9303df3a79311f\", \"best_bid\":\"0\", \"best_ask\":\"0.01\"}], \"timestamp\":\"1785123001223\", \"event_type\":\"price_change\"}","received_at":"2026-07-27T03:30:01.822739Z","schema_version":"clob-market-ws.price_change.v1","sequence":null,"server_hash":null,"server_timestamp":"1785123001223","session_id":"dd162b8dca5f43ff811d304e69a06123","source":"clob_market_ws"},"received_at":"2026-07-27T03:30:01.822739Z","record_id":"ba3eb42c9d026e6c60a39b6c8acdb8f22ca7295e125c7b6806698b19a1376708","schema_fingerprint":"4aa3821a28b0b7c2400bc59aba4bcc0a76e971dadd19610d3ad38c768e124dc7","schema_version":"edge-lab-recorder.raw.v1","sequence":null,"source":"clob_market_ws"}
{"event_at":"2026-07-27T03:30:01.224000Z","event_fingerprint":"56d33a26ee4410239c426cbf21ab44131ad03cb9cd37a56e991948ce538b8654","payload":{"connection_id":"c7dc2e4762f849c6b6f9306b6518dcab","event_at":"2026-07-27T03:30:01.224000Z","event_type":"price_change","frame_hash":"246e217c92d1842861383c556ce61cf094cc2df58f29f4854e444190d38df8e2","frame_index":0,"kind":"data","monotonic_ns":224985197614541,"payload":{"event_type":"price_change","market":"0x717c0e8ccd4d5c7040185188fbae28be901ca589a11a94b1b38ca36a79eccfeb","price_changes":[{"asset_id":"24254094493625419915756280046002869097156693848522361803041977572204227262166","best_ask":"1","best_bid":"0.99","hash":"60f4448fff8208741d5ff818826fd2e5bd2f6c87","price":"0.98","side":"BUY","size":"190.3"},{"asset_id":"41448400836309843603620980831210604935021861034693225347475867885462478926555","best_ask":"0.01","best_bid":"0","hash":"0c934cb39a582ef89e9fbde100b4f23e5573b9f2","price":"0.02","side":"SELL","size":"190.3"}],"timestamp":"1785123001224"},"payload_hash":"6f46f48afec462ae90271048cbc0f6483087f70b7be9d882a985595e8510dbb7","raw_frame":"{\"market\":\"0x717c0e8ccd4d5c7040185188fbae28be901ca589a11a94b1b38ca36a79eccfeb\", \"price_changes\":[{\"asset_id\":\"24254094493625419915756280046002869097156693848522361803041977572204227262166\", \"price\":\"0.98\", \"size\":\"190.3\", \"side\":\"BUY\", \"hash\":\"60f4448fff8208741d5ff818826fd2e5bd2f6c87\", \"best_bid\":\"0.99\", \"best_ask\":\"1\"}, {\"asset_id\":\"41448400836309843603620980831210604935021861034693225347475867885462478926555\", \"price\":\"0.02\", \"size\":\"190.3\", \"side\":\"SELL\", \"hash\":\"0c934cb39a582ef89e9fbde100b4f23e5573b9f2\", \"best_bid\":\"0\", \"best_ask\":\"0.01\"}], \"timestamp\":\"1785123001224\", \"event_type\":\"price_change\"}","received_at":"2026-07-27T03:30:01.833820Z","schema_version":"clob-market-ws.price_change.v1","sequence":null,"server_hash":null,"server_timestamp":"1785123001224","session_id":"dd162b8dca5f43ff811d304e69a06123","source":"clob_market_ws"},"received_at":"2026-07-27T03:30:01.833820Z","record_id":"32a67c7b4840ddf6ef5ac5a10aa4548a3fc39af936137091e19e104076c5e0a6","schema_fingerprint":"4aa3821a28b0b7c2400bc59aba4bcc0a76e971dadd19610d3ad38c768e124dc7","schema_version":"edge-lab-recorder.raw.v1","sequence":null,"source":"clob_market_ws"}
{"event_at":"2026-07-27T03:30:01.225000Z","event_fingerprint":"b35a172499122c8088687ba27561c1500c68bc24f275486c0f04844556e208fd","payload":{"connection_id":"c7dc2e4762f849c6b6f9306b6518dcab","event_at":"2026-07-27T03:30:01.225000Z","event_type":"price_change","frame_hash":"d269f9cfd2f193c2717819a51966634a21f8e5feb83124e0ef24fc86746a5a6d","frame_index":0,"kind":"data","monotonic_ns":224985210617083,"payload":{"event_type":"price_change","market":"0x717c0e8ccd4d5c7040185188fbae28be901ca589a11a94b1b38ca36a79eccfeb","price_changes":[{"asset_id":"24254094493625419915756280046002869097156693848522361803041977572204227262166","best_ask":"1","best_bid":"0.99","hash":"0043acaaade1863add8d1b0ce852ae0fc81434ab","price":"0.99","side":"BUY","size":"262010"},{"asset_id":"41448400836309843603620980831210604935021861034693225347475867885462478926555","best_ask":"0.01","best_bid":"0","hash":"ced53bc9ef31a10408026ec5bce84c6dc59a95da","price":"0.01","side":"SELL","size":"262010"}],"timestamp":"1785123001225"},"payload_hash":"7865424d9b7c0484a2330b37fa207954178a7b8d48cd4e92f5a1470d874201ee","raw_frame":"{\"market\":\"0x717c0e8ccd4d5c7040185188fbae28be901ca589a11a94b1b38ca36a79eccfeb\", \"price_changes\":[{\"asset_id\":\"24254094493625419915756280046002869097156693848522361803041977572204227262166\", \"price\":\"0.99\", \"size\":\"262010\", \"side\":\"BUY\", \"hash\":\"0043acaaade1863add8d1b0ce852ae0fc81434ab\", \"best_bid\":\"0.99\", \"best_ask\":\"1\"}, {\"asset_id\":\"41448400836309843603620980831210604935021861034693225347475867885462478926555\", \"price\":\"0.01\", \"size\":\"262010\", \"side\":\"SELL\", \"hash\":\"ced53bc9ef31a10408026ec5bce84c6dc59a95da\", \"best_bid\":\"0\", \"best_ask\":\"0.01\"}], \"timestamp\":\"1785123001225\", \"event_type\":\"price_change\"}","received_at":"2026-07-27T03:30:01.846822Z","schema_version":"clob-market-ws.price_change.v1","sequence":null,"server_hash":null,"server_timestamp":"1785123001225","session_id":"dd162b8dca5f43ff811d304e69a06123","source":"clob_market_ws"},"received_at":"2026-07-27T03:30:01.846822Z","record_id":"3d740a0798c34212a4fd566dda0388abe32eaadcdf9690d525885260c4073724","schema_fingerprint":"4aa3821a28b0b7c2400bc59aba4bcc0a76e971dadd19610d3ad38c768e124dc7","schema_version":"edge-lab-recorder.raw.v1","sequence":null,"source":"clob_market_ws"}
{"event_at":"2026-07-27T03:30:01.226000Z","event_fingerprint":"ac3db9f4e6d10f4d57effb9761dcf754c6403981d869b9dd34e9c35192627bc0","payload":{"connection_id":"c7dc2e4762f849c6b6f9306b6518dcab","event_at":"2026-07-27T03:30:01.226000Z","event_type":"price_change","frame_hash":"52ff5a57c1c9f86ef70603c92b89aa4e67334e44173f69dc52a8d967c08ce6f3","frame_index":0,"kind":"data","monotonic_ns":224985242849541,"payload":{"event_type":"price_change","market":"0x717c0e8ccd4d5c7040185188fbae28be901ca589a11a94b1b38ca36a79eccfeb","price_changes":[{"asset_id":"24254094493625419915756280046002869097156693848522361803041977572204227262166","best_ask":"1","best_bid":"0.99","hash":"235a7146f5be19cde08dda76d784498870fac988","price":"0.99","side":"BUY","size":"267423"},{"asset_id":"41448400836309843603620980831210604935021861034693225347475867885462478926555","best_ask":"0.01","best_bid":"0","hash":"1496656af4da1c3273e68ed33de000d6446c72db","price":"0.01","side":"SELL","size":"267423"}],"timestamp":"1785123001226"},"payload_hash":"34c4f5e8b5f153ea7d62a3b3407fc9dbabd9cf4a505017bf851724505b3f8097","raw_frame":"{\"market\":\"0x717c0e8ccd4d5c7040185188fbae28be901ca589a11a94b1b38ca36a79eccfeb\", \"price_changes\":[{\"asset_id\":\"24254094493625419915756280046002869097156693848522361803041977572204227262166\", \"price\":\"0.99\", \"size\":\"267423\", \"side\":\"BUY\", \"hash\":\"235a7146f5be19cde08dda76d784498870fac988\", \"best_bid\":\"0.99\", \"best_ask\":\"1\"}, {\"asset_id\":\"41448400836309843603620980831210604935021861034693225347475867885462478926555\", \"price\":\"0.01\", \"size\":\"267423\", \"side\":\"SELL\", \"hash\":\"1496656af4da1c3273e68ed33de000d6446c72db\", \"best_bid\":\"0\", \"best_ask\":\"0.01\"}], \"timestamp\":\"1785123001226\", \"event_type\":\"price_change\"}","received_at":"2026-07-27T03:30:01.879054Z","schema_version":"clob-market-ws.price_change.v1","sequence":null,"server_hash":null,"server_timestamp":"1785123001226","session_id":"dd162b8dca5f43ff811d304e69a06123","source":"clob_market_ws"},"received_at":"2026-07-27T03:30:01.879054Z","record_id":"04319348dc95bc764b378a555b3aa9d4d8b664abc49a55504b9450280cbe5168","schema_fingerprint":"4aa3821a28b0b7c2400bc59aba4bcc0a76e971dadd19610d3ad38c768e124dc7","schema_version":"edge-lab-recorder.raw.v1","sequence":null,"source":"clob_market_ws"}
{"event_at":"2026-07-27T03:30:01.229000Z","event_fingerprint":"82810de79a12aa1132552c52451f8fa445a7a8d051db5cc785ec3fefb89a8277","payload":{"connection_id":"c7dc2e4762f849c6b6f9306b6518dcab","event_at":"2026-07-27T03:30:01.229000Z","event_type":"price_change","frame_hash":"96c7080c187a9ea21a4a9019ed1538cbf59a6ea237c09544f2720e068fa59467","frame_index":0,"kind":"data","monotonic_ns":224985254371500,"payload":{"event_type":"price_change","market":"0x717c0e8ccd4d5c7040185188fbae28be901ca589a11a94b1b38ca36a79eccfeb","price_changes":[{"asset_id":"24254094493625419915756280046002869097156693848522361803041977572204227262166","best_ask":"1","best_bid":"0.99","hash":"f49a8fa971b0d9d077083746637f3356dcb2960d","price":"0.99","side":"BUY","size":"267474"},{"asset_id":"41448400836309843603620980831210604935021861034693225347475867885462478926555","best_ask":"0.01","best_bid":"0","hash":"c5296e1f2caf0bea267fa980d82d0e8dfe110bea","price":"0.01","side":"SELL","size":"267474"}],"timestamp":"1785123001229"},"payload_hash":"51b7cea21ca8f9dec2a3284194c5bdb04e20c2feda2259dcc5a0c3652e4b8aa5","raw_frame":"{\"market\":\"0x717c0e8ccd4d5c7040185188fbae28be901ca589a11a94b1b38ca36a79eccfeb\", \"price_changes\":[{\"asset_id\":\"24254094493625419915756280046002869097156693848522361803041977572204227262166\", \"price\":\"0.99\", \"size\":\"267474\", \"side\":\"BUY\", \"hash\":\"f49a8fa971b0d9d077083746637f3356dcb2960d\", \"best_bid\":\"0.99\", \"best_ask\":\"1\"}, {\"asset_id\":\"41448400836309843603620980831210604935021861034693225347475867885462478926555\", \"price\":\"0.01\", \"size\":\"267474\", \"side\":\"SELL\", \"hash\":\"c5296e1f2caf0bea267fa980d82d0e8dfe110bea\", \"best_bid\":\"0\", \"best_ask\":\"0.01\"}], \"timestamp\":\"1785123001229\", \"event_type\":\"price_change\"}","received_at":"2026-07-27T03:30:01.890577Z","schema_version":"clob-market-ws.price_change.v1","sequence":null,"server_hash":null,"server_timestamp":"1785123001229","session_id":"dd162b8dca5f43ff811d304e69a06123","source":"clob_market_ws"},"received_at":"2026-07-27T03:30:01.890577Z","record_id":"49312de5d8fc7b6f2959296574c60795567bdedf8f077375865035cdbdde092b","schema_fingerprint":"4aa3821a28b0b7c2400bc59aba4bcc0a76e971dadd19610d3ad38c768e124dc7","schema_version":"edge-lab-recorder.raw.v1","sequence":null,"source":"clob_market_ws"}
{"event_at":"2026-07-27T03:30:01.231000Z","event_fingerprint":"e6b4c3f36d8e3faf577401014d499863b6955161c15e55a09af55c41f7004b6b","payload":{"connection_id":"c7dc2e4762f849c6b6f9306b6518dcab","event_at":"2026-07-27T03:30:01.231000Z","event_type":"price_change","frame_hash":"d820100d9cb50c27d0681b0e75206c71da3d8324747bff92bb59c88cf99ef96f","frame_index":0,"kind":"data","monotonic_ns":224985266793291,"payload":{"event_type":"price_change","market":"0x717c0e8ccd4d5c7040185188fbae28be901ca589a11a94b1b38ca36a79eccfeb","price_changes":[{"asset_id":"24254094493625419915756280046002869097156693848522361803041977572204227262166","best_ask":"1","best_bid":"0.99","hash":"5920ef96803f814595ebf759e8fcae40b01e2c49","price":"0.99","side":"BUY","size":"267531"},{"asset_id":"41448400836309843603620980831210604935021861034693225347475867885462478926555","best_ask":"0.01","best_bid":"0","hash":"2dda33853f1a1e714dabef7e898c3f96d23c141d","price":"0.01","side":"SELL","size":"267531"}],"timestamp":"1785123001231"},"payload_hash":"10c32889f89c4ff36f1e062f743226e041db2c4890bac1a1019b4a7a0c6659d2","raw_frame":"{\"market\":\"0x717c0e8ccd4d5c7040185188fbae28be901ca589a11a94b1b38ca36a79eccfeb\", \"price_changes\":[{\"asset_id\":\"24254094493625419915756280046002869097156693848522361803041977572204227262166\", \"price\":\"0.99\", \"size\":\"267531\", \"side\":\"BUY\", \"hash\":\"5920ef96803f814595ebf759e8fcae40b01e2c49\", \"best_bid\":\"0.99\", \"best_ask\":\"1\"}, {\"asset_id\":\"41448400836309843603620980831210604935021861034693225347475867885462478926555\", \"price\":\"0.01\", \"size\":\"267531\", \"side\":\"SELL\", \"hash\":\"2dda33853f1a1e714dabef7e898c3f96d23c141d\", \"best_bid\":\"0\", \"best_ask\":\"0.01\"}], \"timestamp\":\"1785123001231\", \"event_type\":\"price_change\"}","received_at":"2026-07-27T03:30:01.902998Z","schema_version":"clob-market-ws.price_change.v1","sequence":null,"server_hash":null,"server_timestamp":"1785123001231","session_id":"dd162b8dca5f43ff811d304e69a06123","source":"clob_market_ws"},"received_at":"2026-07-27T03:30:01.902998Z","record_id":"a501e9922b51fed6655bf0fb52a2ae66db7efd672b6c0112c64c41acd7b995b5","schema_fingerprint":"4aa3821a28b0b7c2400bc59aba4bcc0a76e971dadd19610d3ad38c768e124dc7","schema_version":"edge-lab-recorder.raw.v1","sequence":null,"source":"clob_market_ws"}
{"event_at":"2026-07-27T03:30:01.232000Z","event_fingerprint":"200f9014e18615247b0302cc3b2e955dc51131822d79f5752f95b26e18bffd0e","payload":{"connection_id":"c7dc2e4762f849c6b6f9306b6518dcab","event_at":"2026-07-27T03:30:01.232000Z","event_type":"price_change","frame_hash":"e46453a5617ace44ae526bae0d52dee130c8527b763eb75b9c6df39c4d3e5ebd","frame_index":0,"kind":"data","monotonic_ns":224985274394125,"payload":{"event_type":"price_change","market":"0x717c0e8ccd4d5c7040185188fbae28be901ca589a11a94b1b38ca36a79eccfeb","price_changes":[{"asset_id":"24254094493625419915756280046002869097156693848522361803041977572204227262166","best_ask":"1","best_bid":"0.99","hash":"935879c7eb3148a1f5b311b3d35f765886a57cc3","price":"0.99","side":"BUY","size":"267556"},{"asset_id":"41448400836309843603620980831210604935021861034693225347475867885462478926555","best_ask":"0.01","best_bid":"0","hash":"4309f61fcbc9954231e02400f5a99f919dbe247c","price":"0.01","side":"SELL","size":"267556"}],"timestamp":"1785123001232"},"payload_hash":"61de440f645a87d1ebb00828ba38e4b8a9f47ed49b7e047db86697ef133f56bc","raw_frame":"{\"market\":\"0x717c0e8ccd4d5c7040185188fbae28be901ca589a11a94b1b38ca36a79eccfeb\", \"price_changes\":[{\"asset_id\":\"24254094493625419915756280046002869097156693848522361803041977572204227262166\", \"price\":\"0.99\", \"size\":\"267556\", \"side\":\"BUY\", \"hash\":\"935879c7eb3148a1f5b311b3d35f765886a57cc3\", \"best_bid\":\"0.99\", \"best_ask\":\"1\"}, {\"asset_id\":\"41448400836309843603620980831210604935021861034693225347475867885462478926555\", \"price\":\"0.01\", \"size\":\"267556\", \"side\":\"SELL\", \"hash\":\"4309f61fcbc9954231e02400f5a99f919dbe247c\", \"best_bid\":\"0\", \"best_ask\":\"0.01\"}], \"timestamp\":\"1785123001232\", \"event_type\":\"price_change\"}","received_at":"2026-07-27T03:30:01.910597Z","schema_version":"clob-market-ws.price_change.v1","sequence":null,"server_hash":null,"server_timestamp":"1785123001232","session_id":"dd162b8dca5f43ff811d304e69a06123","source":"clob_market_ws"},"received_at":"2026-07-27T03:30:01.910597Z","record_id":"4e58e7c9e70d0c8ce8942b30744854dd7483226dabd050654babac9aaf4dbdb5","schema_fingerprint":"4aa3821a28b0b7c2400bc59aba4bcc0a76e971dadd19610d3ad38c768e124dc7","schema_version":"edge-lab-recorder.raw.v1","sequence":null,"source":"clob_market_ws"}
{"event_at":"2026-07-27T03:30:01.233000Z","event_fingerprint":"b86a256ed45c7311ca4d7d424d4f0ec3a27bb53ed5512efd80470685aec85847","payload":{"connection_id":"c7dc2e4762f849c6b6f9306b6518dcab","event_at":"2026-07-27T03:30:01.233000Z","event_type":"price_change","frame_hash":"b697d9322da73dfe8f4c3c1093423b7dbbfff432e0d05729a533cf319e4fc480","frame_index":0,"kind":"data","monotonic_ns":224985282787208,"payload":{"event_type":"price_change","market":"0x717c0e8ccd4d5c7040185188fbae28be901ca589a11a94b1b38ca36a79eccfeb","price_changes":[{"asset_id":"24254094493625419915756280046002869097156693848522361803041977572204227262166","best_ask":"1","best_bid":"0.99","hash":"8676b6048a76e32d23677c74a88cd7dbd767b579","price":"0.96","side":"BUY","size":"199"},{"asset_id":"41448400836309843603620980831210604935021861034693225347475867885462478926555","best_ask":"0.01","best_bid":"0","hash":"bb7257b56ed8521ed57270471d23632d84d0432c","price":"0.04","side":"SELL","size":"199"}],"timestamp":"1785123001233"},"payload_hash":"fcfa2dfaf56909a0bb8495ab96cab841df2aca2a84956d6d753e859d583f0576","raw_frame":"{\"market\":\"0x717c0e8ccd4d5c7040185188fbae28be901ca589a11a94b1b38ca36a79eccfeb\", \"price_changes\":[{\"asset_id\":\"24254094493625419915756280046002869097156693848522361803041977572204227262166\", \"price\":\"0.96\", \"size\":\"199\", \"side\":\"BUY\", \"hash\":\"8676b6048a76e32d23677c74a88cd7dbd767b579\", \"best_bid\":\"0.99\", \"best_ask\":\"1\"}, {\"asset_id\":\"41448400836309843603620980831210604935021861034693225347475867885462478926555\", \"price\":\"0.04\", \"size\":\"199\", \"side\":\"SELL\", \"hash\":\"bb7257b56ed8521ed57270471d23632d84d0432c\", \"best_bid\":\"0\", \"best_ask\":\"0.01\"}], \"timestamp\":\"1785123001233\", \"event_type\":\"price_change\"}","received_at":"2026-07-27T03:30:01.918989Z","schema_version":"clob-market-ws.price_change.v1","sequence":null,"server_hash":null,"server_timestamp":"1785123001233","session_id":"dd162b8dca5f43ff811d304e69a06123","source":"clob_market_ws"},"received_at":"2026-07-27T03:30:01.918989Z","record_id":"504862f35e5e6f45bbf01cfcfca85cf16ac3bd8e1c8138596eb53d3e86e8d015","schema_fingerprint":"4aa3821a28b0b7c2400bc59aba4bcc0a76e971dadd19610d3ad38c768e124dc7","schema_version":"edge-lab-recorder.raw.v1","sequence":null,"source":"clob_market_ws"}
{"event_at":"2026-07-27T03:30:01.234000Z","event_fingerprint":"49d370298615644af9a6db8195b1aa55193f4779c4679b35553cb453da443c34","payload":{"connection_id":"c7dc2e4762f849c6b6f9306b6518dcab","event_at":"2026-07-27T03:30:01.234000Z","event_type":"price_change","frame_hash":"977edc9fe58337203d5862933be4e02251b487ca9551e8cdd064f8a9c060116b","frame_index":0,"kind":"data","monotonic_ns":224985304057000,"payload":{"event_type":"price_change","market":"0x717c0e8ccd4d5c7040185188fbae28be901ca589a11a94b1b38ca36a79eccfeb","price_changes":[{"asset_id":"24254094493625419915756280046002869097156693848522361803041977572204227262166","best_ask":"1","best_bid":"0.99","hash":"c0afb823191e6e9009b8c3f29a3126fd69089b81","price":"0.97","side":"BUY","size":"196"},{"asset_id":"41448400836309843603620980831210604935021861034693225347475867885462478926555","best_ask":"0.01","best_bid":"0","hash":"56d579998128818e7933360bee41deb6786da14b","price":"0.03","side":"SELL","size":"196"}],"timestamp":"1785123001234"},"payload_hash":"96b6ff7cdaf7907d4d3a6dba4cce61a8f1d7468aaa8f94b5dbd55974038d016d","raw_frame":"{\"market\":\"0x717c0e8ccd4d5c7040185188fbae28be901ca589a11a94b1b38ca36a79eccfeb\", \"price_changes\":[{\"asset_id\":\"24254094493625419915756280046002869097156693848522361803041977572204227262166\", \"price\":\"0.97\", \"size\":\"196\", \"side\":\"BUY\", \"hash\":\"c0afb823191e6e9009b8c3f29a3126fd69089b81\", \"best_bid\":\"0.99\", \"best_ask\":\"1\"}, {\"asset_id\":\"41448400836309843603620980831210604935021861034693225347475867885462478926555\", \"price\":\"0.03\", \"size\":\"196\", \"side\":\"SELL\", \"hash\":\"56d579998128818e7933360bee41deb6786da14b\", \"best_bid\":\"0\", \"best_ask\":\"0.01\"}], \"timestamp\":\"1785123001234\", \"event_type\":\"price_change\"}","received_at":"2026-07-27T03:30:01.940261Z","schema_version":"clob-market-ws.price_change.v1","sequence":null,"server_hash":null,"server_timestamp":"1785123001234","session_id":"dd162b8dca5f43ff811d304e69a06123","source":"clob_market_ws"},"received_at":"2026-07-27T03:30:01.940261Z","record_id":"ad54934de8bb4dc4d2aabbbe3908f10aa467857e48e3c215b2deaccc77aa5827","schema_fingerprint":"4aa3821a28b0b7c2400bc59aba4bcc0a76e971dadd19610d3ad38c768e124dc7","schema_version":"edge-lab-recorder.raw.v1","sequence":null,"source":"clob_market_ws"}
{"event_at":"2026-07-27T03:30:01.235000Z","event_fingerprint":"aeb4a468fb197b8cbb099447a7fcc250169b70e99d2d0a24e5b6a1e8dc3bbe8a","payload":{"connection_id":"c7dc2e4762f849c6b6f9306b6518dcab","event_at":"2026-07-27T03:30:01.235000Z","event_type":"price_change","frame_hash":"2ced696193fbb32fa41fe9e9b058fde90f17caab4e685590fd9c66e956bf69de","frame_index":0,"kind":"data","monotonic_ns":224985313832625,"payload":{"event_type":"price_change","market":"0x717c0e8ccd4d5c7040185188fbae28be901ca589a11a94b1b38ca36a79eccfeb","price_changes":[{"asset_id":"24254094493625419915756280046002869097156693848522361803041977572204227262166","best_ask":"1","best_bid":"0.99","hash":"c88890150579896175dcc6d006eb3a5d621545e7","price":"0.98","side":"BUY","size":"215.3"},{"asset_id":"41448400836309843603620980831210604935021861034693225347475867885462478926555","best_ask":"0.01","best_bid":"0","hash":"4d4c806887577ccc1968b2d9c35a09097b93d4b9","price":"0.02","side":"SELL","size":"215.3"}],"timestamp":"1785123001235"},"payload_hash":"5b8339f7714d0b96fe3adadc17fe08a33e4dc7a512a8ecbe5fe5ba91c90b5205","raw_frame":"{\"market\":\"0x717c0e8ccd4d5c7040185188fbae28be901ca589a11a94b1b38ca36a79eccfeb\", \"price_changes\":[{\"asset_id\":\"24254094493625419915756280046002869097156693848522361803041977572204227262166\", \"price\":\"0.98\", \"size\":\"215.3\", \"side\":\"BUY\", \"hash\":\"c88890150579896175dcc6d006eb3a5d621545e7\", \"best_bid\":\"0.99\", \"best_ask\":\"1\"}, {\"asset_id\":\"41448400836309843603620980831210604935021861034693225347475867885462478926555\", \"price\":\"0.02\", \"size\":\"215.3\", \"side\":\"SELL\", \"hash\":\"4d4c806887577ccc1968b2d9c35a09097b93d4b9\", \"best_bid\":\"0\", \"best_ask\":\"0.01\"}], \"timestamp\":\"1785123001235\", \"event_type\":\"price_change\"}","received_at":"2026-07-27T03:30:01.950034Z","schema_version":"clob-market-ws.price_change.v1","sequence":null,"server_hash":null,"server_timestamp":"1785123001235","session_id":"dd162b8dca5f43ff811d304e69a06123","source":"clob_market_ws"},"received_at":"2026-07-27T03:30:01.950034Z","record_id":"ac049d80532f2604f31a436c106dafb37cd5536adb18cff8bac60caf8c882551","schema_fingerprint":"4aa3821a28b0b7c2400bc59aba4bcc0a76e971dadd19610d3ad38c768e124dc7","schema_version":"edge-lab-recorder.raw.v1","sequence":null,"source":"clob_market_ws"}
{"event_at":"2026-07-27T03:30:01.240000Z","event_fingerprint":"78e0f6ce0fde35d10a13b732247ffb27ed786a6032bf3edc201aea2c31f65c90","payload":{"connection_id":"c7dc2e4762f849c6b6f9306b6518dcab","event_at":"2026-07-27T03:30:01.240000Z","event_type":"price_change","frame_hash":"51eb134d665a9683a6b7e8709cbbd6d5fc780adfb221e595d00e9b9d44e56047","frame_index":0,"kind":"data","monotonic_ns":224985329687333,"payload":{"event_type":"price_change","market":"0x717c0e8ccd4d5c7040185188fbae28be901ca589a11a94b1b38ca36a79eccfeb","price_changes":[{"asset_id":"24254094493625419915756280046002869097156693848522361803041977572204227262166","best_ask":"1","best_bid":"0.99","hash":"06e1f23e07631e073ee489970379fd8c5b34646c","price":"0.99","side":"BUY","size":"267929"},{"asset_id":"41448400836309843603620980831210604935021861034693225347475867885462478926555","best_ask":"0.01","best_bid":"0","hash":"d88be6b65c83c89a7b3b62e9ad7d0d34e960e10a","price":"0.01","side":"SELL","size":"267929"}],"timestamp":"1785123001240"},"payload_hash":"b11f3e82acfd317c1a609599f6a7d95b85d079ffe408c1574231655a77874ae0","raw_frame":"{\"market\":\"0x717c0e8ccd4d5c7040185188fbae28be901ca589a11a94b1b38ca36a79eccfeb\", \"price_changes\":[{\"asset_id\":\"24254094493625419915756280046002869097156693848522361803041977572204227262166\", \"price\":\"0.99\", \"size\":\"267929\", \"side\":\"BUY\", \"hash\":\"06e1f23e07631e073ee489970379fd8c5b34646c\", \"best_bid\":\"0.99\", \"best_ask\":\"1\"}, {\"asset_id\":\"41448400836309843603620980831210604935021861034693225347475867885462478926555\", \"price\":\"0.01\", \"size\":\"267929\", \"side\":\"SELL\", \"hash\":\"d88be6b65c83c89a7b3b62e9ad7d0d34e960e10a\", \"best_bid\":\"0\", \"best_ask\":\"0.01\"}], \"timestamp\":\"1785123001240\", \"event_type\":\"price_change\"}","received_at":"2026-07-27T03:30:01.965890Z","schema_version":"clob-market-ws.price_change.v1","sequence":null,"server_hash":null,"server_timestamp":"1785123001240","session_id":"dd162b8dca5f43ff811d304e69a06123","source":"clob_market_ws"},"received_at":"2026-07-27T03:30:01.965890Z","record_id":"af5982ff2ae9b39055e3d7d2f848a21b93e661fb9db2fa44c7529acf413adbe4","schema_fingerprint":"4aa3821a28b0b7c2400bc59aba4bcc0a76e971dadd19610d3ad38c768e124dc7","schema_version":"edge-lab-recorder.raw.v1","sequence":null,"source":"clob_market_ws"}
