{"event_at":null,"event_fingerprint":"935d758d3b44ba6e84c5d1148609d9b8f7c7df907cfb8fb5723c69eb516e867a","payload":{"connection_id":"c7dc2e4762f849c6b6f9306b6518dcab","detail":{"interval_seconds":10.0,"message":"PING"},"event_type":"heartbeat","kind":"lifecycle","monotonic_ns":224627647459375,"received_at":"2026-07-27T03:24:04.289638Z","schema_version":"edge-lab-recorder.lifecycle.v1","session_id":"dd162b8dca5f43ff811d304e69a06123","source":"clob_market_ws"},"received_at":"2026-07-27T03:24:04.289638Z","record_id":"65977afb8263029854d18e7aff1f57ea3e27067c04fbba546ff7616a9d8febea","schema_fingerprint":"cb8aa3aa4cb168a4b724fd9077bee6ecfb9bc586c57cfdf0ab89f00d82045e3c","schema_version":"edge-lab-recorder.raw.v1","sequence":null,"source":"clob_market_ws"}
{"event_at":"2026-07-27T03:24:02.113000Z","event_fingerprint":"21aee3efe7b329c8f10433562e3aa04f182c6df8261f0810f2819d9259566996","payload":{"connection_id":"c7dc2e4762f849c6b6f9306b6518dcab","event_at":"2026-07-27T03:24:02.113000Z","event_type":"price_change","frame_hash":"31a925d3a16ada2a190a1d3d83508efb56226392c353de785309a2d79c40c088","frame_index":0,"kind":"data","monotonic_ns":224627650281250,"payload":{"event_type":"price_change","market":"0x717c0e8ccd4d5c7040185188fbae28be901ca589a11a94b1b38ca36a79eccfeb","price_changes":[{"asset_id":"24254094493625419915756280046002869097156693848522361803041977572204227262166","best_ask":"0.64","best_bid":"0.63","hash":"9ae45ec3e7e0ca1598b8c0507bda1a8be9dcfd24","price":"0.63","side":"BUY","size":"8"},{"asset_id":"41448400836309843603620980831210604935021861034693225347475867885462478926555","best_ask":"0.37","best_bid":"0.36","hash":"9331a066b4a9a3df537ad29665bb8594e7be603a","price":"0.37","side":"SELL","size":"8"}],"timestamp":"1785122642113"},"payload_hash":"9939b00a3fccc75a9746c1c2013b7188c519dc312e216b510f9fa5c44defde15","raw_frame":"{\"market\":\"0x717c0e8ccd4d5c7040185188fbae28be901ca589a11a94b1b38ca36a79eccfeb\", \"price_changes\":[{\"asset_id\":\"24254094493625419915756280046002869097156693848522361803041977572204227262166\", \"price\":\"0.63\", \"size\":\"8\", \"side\":\"BUY\", \"hash\":\"9ae45ec3e7e0ca1598b8c0507bda1a8be9dcfd24\", \"best_bid\":\"0.63\", \"best_ask\":\"0.64\"}, {\"asset_id\":\"41448400836309843603620980831210604935021861034693225347475867885462478926555\", \"price\":\"0.37\", \"size\":\"8\", \"side\":\"SELL\", \"hash\":\"9331a066b4a9a3df537ad29665bb8594e7be603a\", \"best_bid\":\"0.36\", \"best_ask\":\"0.37\"}], \"timestamp\":\"1785122642113\", \"event_type\":\"price_change\"}","received_at":"2026-07-27T03:24:04.292462Z","schema_version":"clob-market-ws.price_change.v1","sequence":null,"server_hash":null,"server_timestamp":"1785122642113","session_id":"dd162b8dca5f43ff811d304e69a06123","source":"clob_market_ws"},"received_at":"2026-07-27T03:24:04.292462Z","record_id":"26e7758ac492d7369589026e91b5a2cb35e0d3bac03d83f590fa3ae1d520ccd2","schema_fingerprint":"4aa3821a28b0b7c2400bc59aba4bcc0a76e971dadd19610d3ad38c768e124dc7","schema_version":"edge-lab-recorder.raw.v1","sequence":null,"source":"clob_market_ws"}
{"event_at":"2026-07-27T03:24:02.124000Z","event_fingerprint":"140b1eed790c6b7761c63d463e86d9bc9706a2d64ede2cc4986b2a38d95dc26d","payload":{"connection_id":"c7dc2e4762f849c6b6f9306b6518dcab","event_at":"2026-07-27T03:24:02.124000Z","event_type":"price_change","frame_hash":"317e0b65fb30b28c4aafa199c8bb2d8bcf5f965381d1bc861023eb268f6da7b0","frame_index":0,"kind":"data","monotonic_ns":224627656696375,"payload":{"event_type":"price_change","market":"0x717c0e8ccd4d5c7040185188fbae28be901ca589a11a94b1b38ca36a79eccfeb","price_changes":[{"asset_id":"24254094493625419915756280046002869097156693848522361803041977572204227262166","best_ask":"0.64","best_bid":"0.63","hash":"456b249ba521ff352eeeab7a0cb2625af2d69392","price":"0.04","side":"BUY","size":"578.09"},{"asset_id":"41448400836309843603620980831210604935021861034693225347475867885462478926555","best_ask":"0.37","best_bid":"0.36","hash":"88d13e76e384f69b735588a520a7cca5d291a453","price":"0.96","side":"SELL","size":"578.09"}],"timestamp":"1785122642124"},"payload_hash":"d19649916c81fc66432656b563ac6343f277d8238818d505fe7c0063456d1b3c","raw_frame":"{\"market\":\"0x717c0e8ccd4d5c7040185188fbae28be901ca589a11a94b1b38ca36a79eccfeb\", \"price_changes\":[{\"asset_id\":\"24254094493625419915756280046002869097156693848522361803041977572204227262166\", \"price\":\"0.04\", \"size\":\"578.09\", \"side\":\"BUY\", \"hash\":\"456b249ba521ff352eeeab7a0cb2625af2d69392\", \"best_bid\":\"0.63\", \"best_ask\":\"0.64\"}, {\"asset_id\":\"41448400836309843603620980831210604935021861034693225347475867885462478926555\", \"price\":\"0.96\", \"size\":\"578.09\", \"side\":\"SELL\", \"hash\":\"88d13e76e384f69b735588a520a7cca5d291a453\", \"best_bid\":\"0.36\", \"best_ask\":\"0.37\"}], \"timestamp\":\"1785122642124\", \"event_type\":\"price_change\"}","received_at":"2026-07-27T03:24:04.298877Z","schema_version":"clob-market-ws.price_change.v1","sequence":null,"server_hash":null,"server_timestamp":"1785122642124","session_id":"dd162b8dca5f43ff811d304e69a06123","source":"clob_market_ws"},"received_at":"2026-07-27T03:24:04.298877Z","record_id":"160789ba12306a62cd02ec3543b9f3a96264626791bccbbecf2456ce4e9903e7","schema_fingerprint":"4aa3821a28b0b7c2400bc59aba4bcc0a76e971dadd19610d3ad38c768e124dc7","schema_version":"edge-lab-recorder.raw.v1","sequence":null,"source":"clob_market_ws"}
{"event_at":"2026-07-27T03:24:02.126000Z","event_fingerprint":"e0cbedc638a84c8fdc2499260b6241bca680213b673a43de5286a1e57acba339","payload":{"connection_id":"c7dc2e4762f849c6b6f9306b6518dcab","event_at":"2026-07-27T03:24:02.126000Z","event_type":"price_change","frame_hash":"1dac54b8381cc56bd401a09f7e4ff46571d945abd739b8d5ce9e653e375774b1","frame_index":0,"kind":"data","monotonic_ns":224627660571041,"payload":{"event_type":"price_change","market":"0x717c0e8ccd4d5c7040185188fbae28be901ca589a11a94b1b38ca36a79eccfeb","price_changes":[{"asset_id":"41448400836309843603620980831210604935021861034693225347475867885462478926555","best_ask":"0.37","best_bid":"0.36","hash":"18dfa9369f355c705e0d17eccc6cfdcd41da1595","price":"0.17","side":"BUY","size":"364.89"},{"asset_id":"24254094493625419915756280046002869097156693848522361803041977572204227262166","best_ask":"0.64","best_bid":"0.63","hash":"c68677eac88c01d3eb9b1ae854eb8bf7bdb0daff","price":"0.83","side":"SELL","size":"364.89"}],"timestamp":"1785122642126"},"payload_hash":"ea0f9c07f5d81ff0701f722f415c56ae8db1c2069ed7c0c4e2d0dc2dbbd722a3","raw_frame":"{\"market\":\"0x717c0e8ccd4d5c7040185188fbae28be901ca589a11a94b1b38ca36a79eccfeb\", \"price_changes\":[{\"asset_id\":\"41448400836309843603620980831210604935021861034693225347475867885462478926555\", \"price\":\"0.17\", \"size\":\"364.89\", \"side\":\"BUY\", \"hash\":\"18dfa9369f355c705e0d17eccc6cfdcd41da1595\", \"best_bid\":\"0.36\", \"best_ask\":\"0.37\"}, {\"asset_id\":\"24254094493625419915756280046002869097156693848522361803041977572204227262166\", \"price\":\"0.83\", \"size\":\"364.89\", \"side\":\"SELL\", \"hash\":\"c68677eac88c01d3eb9b1ae854eb8bf7bdb0daff\", \"best_bid\":\"0.63\", \"best_ask\":\"0.64\"}], \"timestamp\":\"1785122642126\", \"event_type\":\"price_change\"}","received_at":"2026-07-27T03:24:04.302748Z","schema_version":"clob-market-ws.price_change.v1","sequence":null,"server_hash":null,"server_timestamp":"1785122642126","session_id":"dd162b8dca5f43ff811d304e69a06123","source":"clob_market_ws"},"received_at":"2026-07-27T03:24:04.302748Z","record_id":"3d5db1bea1cc1b0c9f490870f3fd2dbc3b49391f3d996eeb9e14bfbba5e467d8","schema_fingerprint":"4aa3821a28b0b7c2400bc59aba4bcc0a76e971dadd19610d3ad38c768e124dc7","schema_version":"edge-lab-recorder.raw.v1","sequence":null,"source":"clob_market_ws"}
{"event_at":"2026-07-27T03:24:02.126000Z","event_fingerprint":"69e4c6daad16fd40daa65e8e4c6a3eacff4c18f24471a100ab3e7155126aec4a","payload":{"connection_id":"c7dc2e4762f849c6b6f9306b6518dcab","event_at":"2026-07-27T03:24:02.126000Z","event_type":"price_change","frame_hash":"12d83de77e634f947826da2673be1105acf24bf31abffe8dd886c285fa2bcf12","frame_index":0,"kind":"data","monotonic_ns":224627663680500,"payload":{"event_type":"price_change","market":"0x717c0e8ccd4d5c7040185188fbae28be901ca589a11a94b1b38ca36a79eccfeb","price_changes":[{"asset_id":"41448400836309843603620980831210604935021861034693225347475867885462478926555","best_ask":"0.37","best_bid":"0.36","hash":"d0e91f441b254066c7a5ac955d77ba7b7ccfd9d7","price":"0.36","side":"BUY","size":"303.33"},{"asset_id":"24254094493625419915756280046002869097156693848522361803041977572204227262166","best_ask":"0.64","best_bid":"0.63","hash":"f0d4b489dc302e5065318bafa7b73ed0c4ddf3a2","price":"0.64","side":"SELL","size":"303.33"}],"timestamp":"1785122642126"},"payload_hash":"8b058ae84cabcff47464a962506232477fedfbcd613c40950524b03ae3782db3","raw_frame":"{\"market\":\"0x717c0e8ccd4d5c7040185188fbae28be901ca589a11a94b1b38ca36a79eccfeb\", \"price_changes\":[{\"asset_id\":\"41448400836309843603620980831210604935021861034693225347475867885462478926555\", \"price\":\"0.36\", \"size\":\"303.33\", \"side\":\"BUY\", \"hash\":\"d0e91f441b254066c7a5ac955d77ba7b7ccfd9d7\", \"best_bid\":\"0.36\", \"best_ask\":\"0.37\"}, {\"asset_id\":\"24254094493625419915756280046002869097156693848522361803041977572204227262166\", \"price\":\"0.64\", \"size\":\"303.33\", \"side\":\"SELL\", \"hash\":\"f0d4b489dc302e5065318bafa7b73ed0c4ddf3a2\", \"best_bid\":\"0.63\", \"best_ask\":\"0.64\"}], \"timestamp\":\"1785122642126\", \"event_type\":\"price_change\"}","received_at":"2026-07-27T03:24:04.305858Z","schema_version":"clob-market-ws.price_change.v1","sequence":null,"server_hash":null,"server_timestamp":"1785122642126","session_id":"dd162b8dca5f43ff811d304e69a06123","source":"clob_market_ws"},"received_at":"2026-07-27T03:24:04.305858Z","record_id":"c86925d48bcb77822c883c93f283d6670c6c3bb658ad24700055f37fc2c7b975","schema_fingerprint":"4aa3821a28b0b7c2400bc59aba4bcc0a76e971dadd19610d3ad38c768e124dc7","schema_version":"edge-lab-recorder.raw.v1","sequence":null,"source":"clob_market_ws"}
{"event_at":"2026-07-27T03:24:02.127000Z","event_fingerprint":"c5a9318953965a507c067a6aa37cef98cca1d3b54b21442c1ecd44bc18d05545","payload":{"connection_id":"c7dc2e4762f849c6b6f9306b6518dcab","event_at":"2026-07-27T03:24:02.127000Z","event_type":"price_change","frame_hash":"4762c13c5de6104bec448bc6aeacbf6d294966a52ed94f34cf1757d8bbb0e6da","frame_index":0,"kind":"data","monotonic_ns":224627666625083,"payload":{"event_type":"price_change","market":"0x717c0e8ccd4d5c7040185188fbae28be901ca589a11a94b1b38ca36a79eccfeb","price_changes":[{"asset_id":"41448400836309843603620980831210604935021861034693225347475867885462478926555","best_ask":"0.37","best_bid":"0.36","hash":"6fc64552f0d6d8028cd1e49f1c176a40fc0920a8","price":"0.36","side":"BUY","size":"293.33"},{"asset_id":"24254094493625419915756280046002869097156693848522361803041977572204227262166","best_ask":"0.64","best_bid":"0.63","hash":"c8595e9b5b6af8ea1fde8eda075511b3e6a0f7df","price":"0.64","side":"SELL","size":"293.33"}],"timestamp":"1785122642127"},"payload_hash":"281b405b22799b5841155a3c447c36ce6c0714e1a6da83a92ac31e8ed5f4d198","raw_frame":"{\"market\":\"0x717c0e8ccd4d5c7040185188fbae28be901ca589a11a94b1b38ca36a79eccfeb\", \"price_changes\":[{\"asset_id\":\"41448400836309843603620980831210604935021861034693225347475867885462478926555\", \"price\":\"0.36\", \"size\":\"293.33\", \"side\":\"BUY\", \"hash\":\"6fc64552f0d6d8028cd1e49f1c176a40fc0920a8\", \"best_bid\":\"0.36\", \"best_ask\":\"0.37\"}, {\"asset_id\":\"24254094493625419915756280046002869097156693848522361803041977572204227262166\", \"price\":\"0.64\", \"size\":\"293.33\", \"side\":\"SELL\", \"hash\":\"c8595e9b5b6af8ea1fde8eda075511b3e6a0f7df\", \"best_bid\":\"0.63\", \"best_ask\":\"0.64\"}], \"timestamp\":\"1785122642127\", \"event_type\":\"price_change\"}","received_at":"2026-07-27T03:24:04.308805Z","schema_version":"clob-market-ws.price_change.v1","sequence":null,"server_hash":null,"server_timestamp":"1785122642127","session_id":"dd162b8dca5f43ff811d304e69a06123","source":"clob_market_ws"},"received_at":"2026-07-27T03:24:04.308805Z","record_id":"08250a961132faa1fac7592ad1e4b985d331a6e3ef16d1b8f5f8488eaaff6016","schema_fingerprint":"4aa3821a28b0b7c2400bc59aba4bcc0a76e971dadd19610d3ad38c768e124dc7","schema_version":"edge-lab-recorder.raw.v1","sequence":null,"source":"clob_market_ws"}
{"event_at":"2026-07-27T03:24:02.127000Z","event_fingerprint":"777d70de9f64e3835ca49717e970dd40ccb7b7f8dc205e0ba09db7fe84486de7","payload":{"connection_id":"c7dc2e4762f849c6b6f9306b6518dcab","event_at":"2026-07-27T03:24:02.127000Z","event_type":"price_change","frame_hash":"5625c7bbc3e3758bb5801a0f6b4b7f65b5164a61ae2f124ea8777d100579b607","frame_index":0,"kind":"data","monotonic_ns":224627669578583,"payload":{"event_type":"price_change","market":"0x717c0e8ccd4d5c7040185188fbae28be901ca589a11a94b1b38ca36a79eccfeb","price_changes":[{"asset_id":"24254094493625419915756280046002869097156693848522361803041977572204227262166","best_ask":"0.64","best_bid":"0.63","hash":"b683620a3d3a42b3996bb408afd09a9f6c16a4cc","price":"0.64","side":"SELL","size":"287.33"},{"asset_id":"41448400836309843603620980831210604935021861034693225347475867885462478926555","best_ask":"0.37","best_bid":"0.36","hash":"63bda4e156b3943f9e7be037c57b842261831a18","price":"0.36","side":"BUY","size":"287.33"}],"timestamp":"1785122642127"},"payload_hash":"de16ffe116db61578d05bf14035b6c6567516356543ddc53ab6658472136a012","raw_frame":"{\"market\":\"0x717c0e8ccd4d5c7040185188fbae28be901ca589a11a94b1b38ca36a79eccfeb\", \"price_changes\":[{\"asset_id\":\"24254094493625419915756280046002869097156693848522361803041977572204227262166\", \"price\":\"0.64\", \"size\":\"287.33\", \"side\":\"SELL\", \"hash\":\"b683620a3d3a42b3996bb408afd09a9f6c16a4cc\", \"best_bid\":\"0.63\", \"best_ask\":\"0.64\"}, {\"asset_id\":\"41448400836309843603620980831210604935021861034693225347475867885462478926555\", \"price\":\"0.36\", \"size\":\"287.33\", \"side\":\"BUY\", \"hash\":\"63bda4e156b3943f9e7be037c57b842261831a18\", \"best_bid\":\"0.36\", \"best_ask\":\"0.37\"}], \"timestamp\":\"1785122642127\", \"event_type\":\"price_change\"}","received_at":"2026-07-27T03:24:04.311759Z","schema_version":"clob-market-ws.price_change.v1","sequence":null,"server_hash":null,"server_timestamp":"1785122642127","session_id":"dd162b8dca5f43ff811d304e69a06123","source":"clob_market_ws"},"received_at":"2026-07-27T03:24:04.311759Z","record_id":"5d1819dc715d09d49a296e13668e2ff6b55372d75bd68c320cdf872dfd9acd63","schema_fingerprint":"4aa3821a28b0b7c2400bc59aba4bcc0a76e971dadd19610d3ad38c768e124dc7","schema_version":"edge-lab-recorder.raw.v1","sequence":null,"source":"clob_market_ws"}
{"event_at":"2026-07-27T03:24:02.132000Z","event_fingerprint":"0f41da35311d26c7baf28f95d5656e2b82f43d5f4c44d4e489a1b6cb61a29d67","payload":{"connection_id":"c7dc2e4762f849c6b6f9306b6518dcab","event_at":"2026-07-27T03:24:02.132000Z","event_type":"price_change","frame_hash":"a06c6f7e92c8b7a19f7a4f9ea971e645a4190cf1d0d38075438558a20818a48f","frame_index":0,"kind":"data","monotonic_ns":224627672472083,"payload":{"event_type":"price_change","market":"0x717c0e8ccd4d5c7040185188fbae28be901ca589a11a94b1b38ca36a79eccfeb","price_changes":[{"asset_id":"24254094493625419915756280046002869097156693848522361803041977572204227262166","best_ask":"0.64","best_bid":"0.63","hash":"d34cdd04de7bc0fb38631512a5b1ac6127925a25","price":"0.36","side":"BUY","size":"110.59"},{"asset_id":"41448400836309843603620980831210604935021861034693225347475867885462478926555","best_ask":"0.37","best_bid":"0.36","hash":"ed43d4dfeb2069b760c15a32600757c99cf0c575","price":"0.64","side":"SELL","size":"110.59"}],"timestamp":"1785122642132"},"payload_hash":"4de3f4f78060e7f0c88ad8220bd82fcdf9c8c754358c4b8689187ae0199e5f9d","raw_frame":"{\"market\":\"0x717c0e8ccd4d5c7040185188fbae28be901ca589a11a94b1b38ca36a79eccfeb\", \"price_changes\":[{\"asset_id\":\"24254094493625419915756280046002869097156693848522361803041977572204227262166\", \"price\":\"0.36\", \"size\":\"110.59\", \"side\":\"BUY\", \"hash\":\"d34cdd04de7bc0fb38631512a5b1ac6127925a25\", \"best_bid\":\"0.63\", \"best_ask\":\"0.64\"}, {\"asset_id\":\"41448400836309843603620980831210604935021861034693225347475867885462478926555\", \"price\":\"0.64\", \"size\":\"110.59\", \"side\":\"SELL\", \"hash\":\"ed43d4dfeb2069b760c15a32600757c99cf0c575\", \"best_bid\":\"0.36\", \"best_ask\":\"0.37\"}], \"timestamp\":\"1785122642132\", \"event_type\":\"price_change\"}","received_at":"2026-07-27T03:24:04.314652Z","schema_version":"clob-market-ws.price_change.v1","sequence":null,"server_hash":null,"server_timestamp":"1785122642132","session_id":"dd162b8dca5f43ff811d304e69a06123","source":"clob_market_ws"},"received_at":"2026-07-27T03:24:04.314652Z","record_id":"fa07c57541dc9e6c724928c9e37268ad597bd52f2ff9c50fbc5a309d7d0235f0","schema_fingerprint":"4aa3821a28b0b7c2400bc59aba4bcc0a76e971dadd19610d3ad38c768e124dc7","schema_version":"edge-lab-recorder.raw.v1","sequence":null,"source":"clob_market_ws"}
{"event_at":"2026-07-27T03:24:02.137000Z","event_fingerprint":"e45b5b46aba984ba830818f083f1dca77f40e5167c75e2ce5c638ca2904a98c3","payload":{"connection_id":"c7dc2e4762f849c6b6f9306b6518dcab","event_at":"2026-07-27T03:24:02.137000Z","event_type":"price_change","frame_hash":"93ae5db44cad1afdebf19da546cf0de44de04b1fb6c74666ff160cd7bca48cdd","frame_index":0,"kind":"data","monotonic_ns":224627675379000,"payload":{"event_type":"price_change","market":"0x717c0e8ccd4d5c7040185188fbae28be901ca589a11a94b1b38ca36a79eccfeb","price_changes":[{"asset_id":"41448400836309843603620980831210604935021861034693225347475867885462478926555","best_ask":"0.37","best_bid":"0.36","hash":"5d8af57d136f0507d02228d97043273d000b5ab7","price":"0.23","side":"BUY","size":"29"},{"asset_id":"24254094493625419915756280046002869097156693848522361803041977572204227262166","best_ask":"0.64","best_bid":"0.63","hash":"a31cdd625625f7f8eaef39df4be276d7718d5749","price":"0.77","side":"SELL","size":"29"}],"timestamp":"1785122642137"},"payload_hash":"b511ce43857096ca7b7c8f3fbad894299dc36cf0d9d2f22f0b53063793930f84","raw_frame":"{\"market\":\"0x717c0e8ccd4d5c7040185188fbae28be901ca589a11a94b1b38ca36a79eccfeb\", \"price_changes\":[{\"asset_id\":\"41448400836309843603620980831210604935021861034693225347475867885462478926555\", \"price\":\"0.23\", \"size\":\"29\", \"side\":\"BUY\", \"hash\":\"5d8af57d136f0507d02228d97043273d000b5ab7\", \"best_bid\":\"0.36\", \"best_ask\":\"0.37\"}, {\"asset_id\":\"24254094493625419915756280046002869097156693848522361803041977572204227262166\", \"price\":\"0.77\", \"size\":\"29\", \"side\":\"SELL\", \"hash\":\"a31cdd625625f7f8eaef39df4be276d7718d5749\", \"best_bid\":\"0.63\", \"best_ask\":\"0.64\"}], \"timestamp\":\"1785122642137\", \"event_type\":\"price_change\"}","received_at":"2026-07-27T03:24:04.317557Z","schema_version":"clob-market-ws.price_change.v1","sequence":null,"server_hash":null,"server_timestamp":"1785122642137","session_id":"dd162b8dca5f43ff811d304e69a06123","source":"clob_market_ws"},"received_at":"2026-07-27T03:24:04.317557Z","record_id":"36bdc8399c4dd7cdaa7a20e704460f6250b282033b12f977946990db2037a43c","schema_fingerprint":"4aa3821a28b0b7c2400bc59aba4bcc0a76e971dadd19610d3ad38c768e124dc7","schema_version":"edge-lab-recorder.raw.v1","sequence":null,"source":"clob_market_ws"}
{"event_at":"2026-07-27T03:24:02.139000Z","event_fingerprint":"2238c785c0e113b57f3e2f1ee20a40ad04344c3b161fd90300c3969df7a82590","payload":{"connection_id":"c7dc2e4762f849c6b6f9306b6518dcab","event_at":"2026-07-27T03:24:02.139000Z","event_type":"price_change","frame_hash":"e81864bdd147cc5ecc08858193c608a64ac00c36b94a5851c11bf4af65e0399b","frame_index":0,"kind":"data","monotonic_ns":224627678712000,"payload":{"event_type":"price_change","market":"0x717c0e8ccd4d5c7040185188fbae28be901ca589a11a94b1b38ca36a79eccfeb","price_changes":[{"asset_id":"24254094493625419915756280046002869097156693848522361803041977572204227262166","best_ask":"0.64","best_bid":"0.63","hash":"798dd63f865e22b9963f897831c8f5ed409c1543","price":"0.62","side":"BUY","size":"39.4"},{"asset_id":"41448400836309843603620980831210604935021861034693225347475867885462478926555","best_ask":"0.37","best_bid":"0.36","hash":"a38b86fa65edf864324a37b69e0ec3a3211ebb78","price":"0.38","side":"SELL","size":"39.4"}],"timestamp":"1785122642139"},"payload_hash":"372f3ce0bfc61ddda3b7a16eafbecdf0da820999f7e9c1d5aeaad16eb0c6202f","raw_frame":"{\"market\":\"0x717c0e8ccd4d5c7040185188fbae28be901ca589a11a94b1b38ca36a79eccfeb\", \"price_changes\":[{\"asset_id\":\"24254094493625419915756280046002869097156693848522361803041977572204227262166\", \"price\":\"0.62\", \"size\":\"39.4\", \"side\":\"BUY\", \"hash\":\"798dd63f865e22b9963f897831c8f5ed409c1543\", \"best_bid\":\"0.63\", \"best_ask\":\"0.64\"}, {\"asset_id\":\"41448400836309843603620980831210604935021861034693225347475867885462478926555\", \"price\":\"0.38\", \"size\":\"39.4\", \"side\":\"SELL\", \"hash\":\"a38b86fa65edf864324a37b69e0ec3a3211ebb78\", \"best_bid\":\"0.36\", \"best_ask\":\"0.37\"}], \"timestamp\":\"1785122642139\", \"event_type\":\"price_change\"}","received_at":"2026-07-27T03:24:04.320891Z","schema_version":"clob-market-ws.price_change.v1","sequence":null,"server_hash":null,"server_timestamp":"1785122642139","session_id":"dd162b8dca5f43ff811d304e69a06123","source":"clob_market_ws"},"received_at":"2026-07-27T03:24:04.320891Z","record_id":"3345fa37cd2abc2e422f7c59333e525fc36a37021cbb7b9493a73d4ca6e77e35","schema_fingerprint":"4aa3821a28b0b7c2400bc59aba4bcc0a76e971dadd19610d3ad38c768e124dc7","schema_version":"edge-lab-recorder.raw.v1","sequence":null,"source":"clob_market_ws"}
{"event_at":"2026-07-27T03:24:02.143000Z","event_fingerprint":"abd1edb007d2cfcccb4d04b3c5472f6defc6cae3a52055f248bc3cf32e385260","payload":{"connection_id":"c7dc2e4762f849c6b6f9306b6518dcab","event_at":"2026-07-27T03:24:02.143000Z","event_type":"price_change","frame_hash":"3a74a0fa783ca34812dcd7a0ed488354d1431da3686b09d3b9a3ab224a9f87cb","frame_index":0,"kind":"data","monotonic_ns":224627680687791,"payload":{"event_type":"price_change","market":"0x717c0e8ccd4d5c7040185188fbae28be901ca589a11a94b1b38ca36a79eccfeb","price_changes":[{"asset_id":"24254094493625419915756280046002869097156693848522361803041977572204227262166","best_ask":"0.64","best_bid":"0.63","hash":"457552f08bb273a09df2783b20e94b5076fd149a","price":"0.56","side":"BUY","size":"114"},{"asset_id":"41448400836309843603620980831210604935021861034693225347475867885462478926555","best_ask":"0.37","best_bid":"0.36","hash":"1acf239d69f0e1d930332f7e1de8a097819271e9","price":"0.44","side":"SELL","size":"114"}],"timestamp":"1785122642143"},"payload_hash":"2adadc2ce36481c511f1c387d06a3b25fff51443bc7873a7ba01fb2d71528a10","raw_frame":"{\"market\":\"0x717c0e8ccd4d5c7040185188fbae28be901ca589a11a94b1b38ca36a79eccfeb\", \"price_changes\":[{\"asset_id\":\"24254094493625419915756280046002869097156693848522361803041977572204227262166\", \"price\":\"0.56\", \"size\":\"114\", \"side\":\"BUY\", \"hash\":\"457552f08bb273a09df2783b20e94b5076fd149a\", \"best_bid\":\"0.63\", \"best_ask\":\"0.64\"}, {\"asset_id\":\"41448400836309843603620980831210604935021861034693225347475867885462478926555\", \"price\":\"0.44\", \"size\":\"114\", \"side\":\"SELL\", \"hash\":\"1acf239d69f0e1d930332f7e1de8a097819271e9\", \"best_bid\":\"0.36\", \"best_ask\":\"0.37\"}], \"timestamp\":\"1785122642143\", \"event_type\":\"price_change\"}","received_at":"2026-07-27T03:24:04.322868Z","schema_version":"clob-market-ws.price_change.v1","sequence":null,"server_hash":null,"server_timestamp":"1785122642143","session_id":"dd162b8dca5f43ff811d304e69a06123","source":"clob_market_ws"},"received_at":"2026-07-27T03:24:04.322868Z","record_id":"c6f3b539a2fd52089399981acfc0a4e8ab975c2b75e6f8e2ab0b335d4ad677ad","schema_fingerprint":"4aa3821a28b0b7c2400bc59aba4bcc0a76e971dadd19610d3ad38c768e124dc7","schema_version":"edge-lab-recorder.raw.v1","sequence":null,"source":"clob_market_ws"}
{"event_at":"2026-07-27T03:24:02.143000Z","event_fingerprint":"9787e04235501926af9799766a38071c7963c5c4f9fb07c5ab790f739d835575","payload":{"connection_id":"c7dc2e4762f849c6b6f9306b6518dcab","event_at":"2026-07-27T03:24:02.143000Z","event_type":"price_change","frame_hash":"aea74c68a5c483ee71456f8b6904e79fef5a6958bdc5e17fcbf668b0834f6f07","frame_index":0,"kind":"data","monotonic_ns":224627683693083,"payload":{"event_type":"price_change","market":"0x717c0e8ccd4d5c7040185188fbae28be901ca589a11a94b1b38ca36a79eccfeb","price_changes":[{"asset_id":"41448400836309843603620980831210604935021861034693225347475867885462478926555","best_ask":"0.37","best_bid":"0.36","hash":"1acf239d69f0e1d930332f7e1de8a097819271e9","price":"0.35","side":"BUY","size":"27.68"},{"asset_id":"24254094493625419915756280046002869097156693848522361803041977572204227262166","best_ask":"0.64","best_bid":"0.63","hash":"457552f08bb273a09df2783b20e94b5076fd149a","price":"0.65","side":"SELL","size":"27.68"}],"timestamp":"1785122642143"},"payload_hash":"64cf1020d6ed05f72ece1dbd3c3096fb0d15a909f920201c4553670f2746832b","raw_frame":"{\"market\":\"0x717c0e8ccd4d5c7040185188fbae28be901ca589a11a94b1b38ca36a79eccfeb\", \"price_changes\":[{\"asset_id\":\"41448400836309843603620980831210604935021861034693225347475867885462478926555\", \"price\":\"0.35\", \"size\":\"27.68\", \"side\":\"BUY\", \"hash\":\"1acf239d69f0e1d930332f7e1de8a097819271e9\", \"best_bid\":\"0.36\", \"best_ask\":\"0.37\"}, {\"asset_id\":\"24254094493625419915756280046002869097156693848522361803041977572204227262166\", \"price\":\"0.65\", \"size\":\"27.68\", \"side\":\"SELL\", \"hash\":\"457552f08bb273a09df2783b20e94b5076fd149a\", \"best_bid\":\"0.63\", \"best_ask\":\"0.64\"}], \"timestamp\":\"1785122642143\", \"event_type\":\"price_change\"}","received_at":"2026-07-27T03:24:04.325873Z","schema_version":"clob-market-ws.price_change.v1","sequence":null,"server_hash":null,"server_timestamp":"1785122642143","session_id":"dd162b8dca5f43ff811d304e69a06123","source":"clob_market_ws"},"received_at":"2026-07-27T03:24:04.325873Z","record_id":"0eaf9886a1df3194aa6a94afa5e5c8b7d2fce803bd92002afebac4dd1cfb0c37","schema_fingerprint":"4aa3821a28b0b7c2400bc59aba4bcc0a76e971dadd19610d3ad38c768e124dc7","schema_version":"edge-lab-recorder.raw.v1","sequence":null,"source":"clob_market_ws"}
{"event_at":"2026-07-27T03:24:02.149000Z","event_fingerprint":"f4bc47a95c0bdf719bb88a321db972639d4cc50037c49e4e9315db563e4ff91b","payload":{"connection_id":"c7dc2e4762f849c6b6f9306b6518dcab","event_at":"2026-07-27T03:24:02.149000Z","event_type":"price_change","frame_hash":"95805ce685fc46ec1ebdd50f911bf810d423794ff73fe0069839b308d378295f","frame_index":0,"kind":"data","monotonic_ns":224627686900291,"payload":{"event_type":"price_change","market":"0x717c0e8ccd4d5c7040185188fbae28be901ca589a11a94b1b38ca36a79eccfeb","price_changes":[{"asset_id":"41448400836309843603620980831210604935021861034693225347475867885462478926555","best_ask":"0.37","best_bid":"0.36","hash":"6f60f893d23bfbcb06f9fc0f24afaa985c933cd3","price":"0.24","side":"BUY","size":"35"},{"asset_id":"24254094493625419915756280046002869097156693848522361803041977572204227262166","best_ask":"0.64","best_bid":"0.63","hash":"3d4ea69cb227ecf9e52369844690d09c7cdbcff2","price":"0.76","side":"SELL","size":"35"}],"timestamp":"1785122642149"},"payload_hash":"7449e03c9327746d6e51315cc7d632a54eda0f23269b62bd8dd2c5590a653982","raw_frame":"{\"market\":\"0x717c0e8ccd4d5c7040185188fbae28be901ca589a11a94b1b38ca36a79eccfeb\", \"price_changes\":[{\"asset_id\":\"41448400836309843603620980831210604935021861034693225347475867885462478926555\", \"price\":\"0.24\", \"size\":\"35\", \"side\":\"BUY\", \"hash\":\"6f60f893d23bfbcb06f9fc0f24afaa985c933cd3\", \"best_bid\":\"0.36\", \"best_ask\":\"0.37\"}, {\"asset_id\":\"24254094493625419915756280046002869097156693848522361803041977572204227262166\", \"price\":\"0.76\", \"size\":\"35\", \"side\":\"SELL\", \"hash\":\"3d4ea69cb227ecf9e52369844690d09c7cdbcff2\", \"best_bid\":\"0.63\", \"best_ask\":\"0.64\"}], \"timestamp\":\"1785122642149\", \"event_type\":\"price_change\"}","received_at":"2026-07-27T03:24:04.329080Z","schema_version":"clob-market-ws.price_change.v1","sequence":null,"server_hash":null,"server_timestamp":"1785122642149","session_id":"dd162b8dca5f43ff811d304e69a06123","source":"clob_market_ws"},"received_at":"2026-07-27T03:24:04.329080Z","record_id":"7efa5cca71eedb1e6d23e48fa59d1ae7cceaa41a243c97ff1b54889172aa193e","schema_fingerprint":"4aa3821a28b0b7c2400bc59aba4bcc0a76e971dadd19610d3ad38c768e124dc7","schema_version":"edge-lab-recorder.raw.v1","sequence":null,"source":"clob_market_ws"}
{"event_at":"2026-07-27T03:24:02.150000Z","event_fingerprint":"0157f0c40595f9a344910b3a3c8b77717b032add7332fe7da50ff8af834e0b5a","payload":{"connection_id":"c7dc2e4762f849c6b6f9306b6518dcab","event_at":"2026-07-27T03:24:02.150000Z","event_type":"price_change","frame_hash":"f570fd83adff8ed836019a3d304a6cc43ebc8cdf4684348e9900828d92dab576","frame_index":0,"kind":"data","monotonic_ns":224627689867458,"payload":{"event_type":"price_change","market":"0x717c0e8ccd4d5c7040185188fbae28be901ca589a11a94b1b38ca36a79eccfeb","price_changes":[{"asset_id":"41448400836309843603620980831210604935021861034693225347475867885462478926555","best_ask":"0.37","best_bid":"0.36","hash":"786f1e260c0d2eaaba28f62b712051909f381e93","price":"0.36","side":"BUY","size":"297.33"},{"asset_id":"24254094493625419915756280046002869097156693848522361803041977572204227262166","best_ask":"0.64","best_bid":"0.63","hash":"e40fa427ad6a77fcbc4a0bf651e8549b9cfd396b","price":"0.64","side":"SELL","size":"297.33"}],"timestamp":"1785122642150"},"payload_hash":"8b5518ce5f69b78c6d631bbbcde3ef0887c9dff9684d745f4eaf3a9ce97a10b4","raw_frame":"{\"market\":\"0x717c0e8ccd4d5c7040185188fbae28be901ca589a11a94b1b38ca36a79eccfeb\", \"price_changes\":[{\"asset_id\":\"41448400836309843603620980831210604935021861034693225347475867885462478926555\", \"price\":\"0.36\", \"size\":\"297.33\", \"side\":\"BUY\", \"hash\":\"786f1e260c0d2eaaba28f62b712051909f381e93\", \"best_bid\":\"0.36\", \"best_ask\":\"0.37\"}, {\"asset_id\":\"24254094493625419915756280046002869097156693848522361803041977572204227262166\", \"price\":\"0.64\", \"size\":\"297.33\", \"side\":\"SELL\", \"hash\":\"e40fa427ad6a77fcbc4a0bf651e8549b9cfd396b\", \"best_bid\":\"0.63\", \"best_ask\":\"0.64\"}], \"timestamp\":\"1785122642150\", \"event_type\":\"price_change\"}","received_at":"2026-07-27T03:24:04.332046Z","schema_version":"clob-market-ws.price_change.v1","sequence":null,"server_hash":null,"server_timestamp":"1785122642150","session_id":"dd162b8dca5f43ff811d304e69a06123","source":"clob_market_ws"},"received_at":"2026-07-27T03:24:04.332046Z","record_id":"0aab8c00bae804d31e3ff3ad02c7cec31b6cb84431eb9832cb5d08a39d92b3f6","schema_fingerprint":"4aa3821a28b0b7c2400bc59aba4bcc0a76e971dadd19610d3ad38c768e124dc7","schema_version":"edge-lab-recorder.raw.v1","sequence":null,"source":"clob_market_ws"}
{"event_at":"2026-07-27T03:24:02.155000Z","event_fingerprint":"1aa978085831d122c56a2ca58a2a5543bf1d9f03fc33375592d9d019647185c0","payload":{"connection_id":"c7dc2e4762f849c6b6f9306b6518dcab","event_at":"2026-07-27T03:24:02.155000Z","event_type":"price_change","frame_hash":"e072f7826e67af4f615f2d293a766e80fc865ac62fb032ccad9fab283ffc4b26","frame_index":0,"kind":"data","monotonic_ns":224627692769416,"payload":{"event_type":"price_change","market":"0x717c0e8ccd4d5c7040185188fbae28be901ca589a11a94b1b38ca36a79eccfeb","price_changes":[{"asset_id":"24254094493625419915756280046002869097156693848522361803041977572204227262166","best_ask":"0.64","best_bid":"0.63","hash":"f7b75d3e0bc26dc53d522a983df9a31cbb74dbf6","price":"0.64","side":"SELL","size":"302.33"},{"asset_id":"41448400836309843603620980831210604935021861034693225347475867885462478926555","best_ask":"0.37","best_bid":"0.36","hash":"e6b0fb4811f5313adf2d88e108c2b48f3888de8c","price":"0.36","side":"BUY","size":"302.33"}],"timestamp":"1785122642155"},"payload_hash":"e97c95e891571efc92c92730156ba7fe8e3c46f74ed739c30d0b303fb5d6e38d","raw_frame":"{\"market\":\"0x717c0e8ccd4d5c7040185188fbae28be901ca589a11a94b1b38ca36a79eccfeb\", \"price_changes\":[{\"asset_id\":\"24254094493625419915756280046002869097156693848522361803041977572204227262166\", \"price\":\"0.64\", \"size\":\"302.33\", \"side\":\"SELL\", \"hash\":\"f7b75d3e0bc26dc53d522a983df9a31cbb74dbf6\", \"best_bid\":\"0.63\", \"best_ask\":\"0.64\"}, {\"asset_id\":\"41448400836309843603620980831210604935021861034693225347475867885462478926555\", \"price\":\"0.36\", \"size\":\"302.33\", \"side\":\"BUY\", \"hash\":\"e6b0fb4811f5313adf2d88e108c2b48f3888de8c\", \"best_bid\":\"0.36\", \"best_ask\":\"0.37\"}], \"timestamp\":\"1785122642155\", \"event_type\":\"price_change\"}","received_at":"2026-07-27T03:24:04.334948Z","schema_version":"clob-market-ws.price_change.v1","sequence":null,"server_hash":null,"server_timestamp":"1785122642155","session_id":"dd162b8dca5f43ff811d304e69a06123","source":"clob_market_ws"},"received_at":"2026-07-27T03:24:04.334948Z","record_id":"44b3fac9f3d45840c6b5818c74acd1c98fdd4b172445dffa5a7cd1313232a604","schema_fingerprint":"4aa3821a28b0b7c2400bc59aba4bcc0a76e971dadd19610d3ad38c768e124dc7","schema_version":"edge-lab-recorder.raw.v1","sequence":null,"source":"clob_market_ws"}
{"event_at":"2026-07-27T03:24:02.156000Z","event_fingerprint":"8f006ca6ac9b603aa490f83936a771e371a073699ce20441fe666aa92a0cef34","payload":{"connection_id":"c7dc2e4762f849c6b6f9306b6518dcab","event_at":"2026-07-27T03:24:02.156000Z","event_type":"price_change","frame_hash":"4d61e44cf515fd0c00e84d48171dc4d63519e29ba1a950728fb58fdee63074a6","frame_index":0,"kind":"data","monotonic_ns":224627696130125,"payload":{"event_type":"price_change","market":"0x717c0e8ccd4d5c7040185188fbae28be901ca589a11a94b1b38ca36a79eccfeb","price_changes":[{"asset_id":"41448400836309843603620980831210604935021861034693225347475867885462478926555","best_ask":"0.37","best_bid":"0.36","hash":"6864fa86f2abffe7e8fa16df009c3e9a56ece9cd","price":"0.36","side":"BUY","size":"307.33"},{"asset_id":"24254094493625419915756280046002869097156693848522361803041977572204227262166","best_ask":"0.64","best_bid":"0.63","hash":"635ad3484798b67ca02c197083549e15553fef7c","price":"0.64","side":"SELL","size":"307.33"}],"timestamp":"1785122642156"},"payload_hash":"c7a22496c57f6b34efdd5e27d3945feb698ae96da68537c38f97c1237e5e9ada","raw_frame":"{\"market\":\"0x717c0e8ccd4d5c7040185188fbae28be901ca589a11a94b1b38ca36a79eccfeb\", \"price_changes\":[{\"asset_id\":\"41448400836309843603620980831210604935021861034693225347475867885462478926555\", \"price\":\"0.36\", \"size\":\"307.33\", \"side\":\"BUY\", \"hash\":\"6864fa86f2abffe7e8fa16df009c3e9a56ece9cd\", \"best_bid\":\"0.36\", \"best_ask\":\"0.37\"}, {\"asset_id\":\"24254094493625419915756280046002869097156693848522361803041977572204227262166\", \"price\":\"0.64\", \"size\":\"307.33\", \"side\":\"SELL\", \"hash\":\"635ad3484798b67ca02c197083549e15553fef7c\", \"best_bid\":\"0.63\", \"best_ask\":\"0.64\"}], \"timestamp\":\"1785122642156\", \"event_type\":\"price_change\"}","received_at":"2026-07-27T03:24:04.338310Z","schema_version":"clob-market-ws.price_change.v1","sequence":null,"server_hash":null,"server_timestamp":"1785122642156","session_id":"dd162b8dca5f43ff811d304e69a06123","source":"clob_market_ws"},"received_at":"2026-07-27T03:24:04.338310Z","record_id":"5241d7e515a0c6dc0d3185770b56efc69d4219ffe4c639223d759bb5078abadc","schema_fingerprint":"4aa3821a28b0b7c2400bc59aba4bcc0a76e971dadd19610d3ad38c768e124dc7","schema_version":"edge-lab-recorder.raw.v1","sequence":null,"source":"clob_market_ws"}
{"event_at":"2026-07-27T03:24:02.162000Z","event_fingerprint":"f7fc7443e62bc05341c862901b03a4f630641823f018119a96f79f1fa2bc68c7","payload":{"connection_id":"c7dc2e4762f849c6b6f9306b6518dcab","event_at":"2026-07-27T03:24:02.162000Z","event_type":"price_change","frame_hash":"0bfaac0a3026baa7a3574fc4151e0f0dd3c6687c2babda20d199f8175b622bdf","frame_index":0,"kind":"data","monotonic_ns":224627699003833,"payload":{"event_type":"price_change","market":"0x717c0e8ccd4d5c7040185188fbae28be901ca589a11a94b1b38ca36a79eccfeb","price_changes":[{"asset_id":"41448400836309843603620980831210604935021861034693225347475867885462478926555","best_ask":"0.37","best_bid":"0.36","hash":"487a20e40cd52b62d08ee6516be01751f80db594","price":"0.28","side":"BUY","size":"135.59"},{"asset_id":"24254094493625419915756280046002869097156693848522361803041977572204227262166","best_ask":"0.64","best_bid":"0.63","hash":"4531523f118f8acc7fc7107758cd2757964a8b7f","price":"0.72","side":"SELL","size":"135.59"}],"timestamp":"1785122642162"},"payload_hash":"37eb6affb03d6961afb2d1611527a058a70b711c0f3d39bba4c7ee5e64eac533","raw_frame":"{\"market\":\"0x717c0e8ccd4d5c7040185188fbae28be901ca589a11a94b1b38ca36a79eccfeb\", \"price_changes\":[{\"asset_id\":\"41448400836309843603620980831210604935021861034693225347475867885462478926555\", \"price\":\"0.28\", \"size\":\"135.59\", \"side\":\"BUY\", \"hash\":\"487a20e40cd52b62d08ee6516be01751f80db594\", \"best_bid\":\"0.36\", \"best_ask\":\"0.37\"}, {\"asset_id\":\"24254094493625419915756280046002869097156693848522361803041977572204227262166\", \"price\":\"0.72\", \"size\":\"135.59\", \"side\":\"SELL\", \"hash\":\"4531523f118f8acc7fc7107758cd2757964a8b7f\", \"best_bid\":\"0.63\", \"best_ask\":\"0.64\"}], \"timestamp\":\"1785122642162\", \"event_type\":\"price_change\"}","received_at":"2026-07-27T03:24:04.341184Z","schema_version":"clob-market-ws.price_change.v1","sequence":null,"server_hash":null,"server_timestamp":"1785122642162","session_id":"dd162b8dca5f43ff811d304e69a06123","source":"clob_market_ws"},"received_at":"2026-07-27T03:24:04.341184Z","record_id":"3af226852c91512bd202c8f62bd43d729fe8f34e630351a7e316b1de8c882ef1","schema_fingerprint":"4aa3821a28b0b7c2400bc59aba4bcc0a76e971dadd19610d3ad38c768e124dc7","schema_version":"edge-lab-recorder.raw.v1","sequence":null,"source":"clob_market_ws"}
{"event_at":"2026-07-27T03:24:02.172000Z","event_fingerprint":"8371768114a7108dbef657306edc01df76c95a49c196cb1eaba816c7c7eaab59","payload":{"connection_id":"c7dc2e4762f849c6b6f9306b6518dcab","event_at":"2026-07-27T03:24:02.172000Z","event_type":"price_change","frame_hash":"5e700e044b1a3b8e4651922205582c8d2872e28d6e37d500fc16d4a3c0badb03","frame_index":0,"kind":"data","monotonic_ns":224627701541291,"payload":{"event_type":"price_change","market":"0x717c0e8ccd4d5c7040185188fbae28be901ca589a11a94b1b38ca36a79eccfeb","price_changes":[{"asset_id":"24254094493625419915756280046002869097156693848522361803041977572204227262166","best_ask":"0.64","best_bid":"0.63","hash":"550ee73f02900f8e916e6dc9fcca6fdeb50d1c24","price":"0.57","side":"BUY","size":"43"},{"asset_id":"41448400836309843603620980831210604935021861034693225347475867885462478926555","best_ask":"0.37","best_bid":"0.36","hash":"f6b77aeab5e5db97392a1085ea15e9b062ca0352","price":"0.43","side":"SELL","size":"43"}],"timestamp":"1785122642172"},"payload_hash":"c1b2b64ee2e9f6d010b38c6bf8852ae9bd8e6d0b43219f9aa4d277225a0c7d57","raw_frame":"{\"market\":\"0x717c0e8ccd4d5c7040185188fbae28be901ca589a11a94b1b38ca36a79eccfeb\", \"price_changes\":[{\"asset_id\":\"24254094493625419915756280046002869097156693848522361803041977572204227262166\", \"price\":\"0.57\", \"size\":\"43\", \"side\":\"BUY\", \"hash\":\"550ee73f02900f8e916e6dc9fcca6fdeb50d1c24\", \"best_bid\":\"0.63\", \"best_ask\":\"0.64\"}, {\"asset_id\":\"41448400836309843603620980831210604935021861034693225347475867885462478926555\", \"price\":\"0.43\", \"size\":\"43\", \"side\":\"SELL\", \"hash\":\"f6b77aeab5e5db97392a1085ea15e9b062ca0352\", \"best_bid\":\"0.36\", \"best_ask\":\"0.37\"}], \"timestamp\":\"1785122642172\", \"event_type\":\"price_change\"}","received_at":"2026-07-27T03:24:04.343721Z","schema_version":"clob-market-ws.price_change.v1","sequence":null,"server_hash":null,"server_timestamp":"1785122642172","session_id":"dd162b8dca5f43ff811d304e69a06123","source":"clob_market_ws"},"received_at":"2026-07-27T03:24:04.343721Z","record_id":"6cbc10c22a5100977381d0c16ed030b5754ed3396c8a5412aacc12e5c230641c","schema_fingerprint":"4aa3821a28b0b7c2400bc59aba4bcc0a76e971dadd19610d3ad38c768e124dc7","schema_version":"edge-lab-recorder.raw.v1","sequence":null,"source":"clob_market_ws"}
{"event_at":"2026-07-27T03:24:02.172000Z","event_fingerprint":"959e7ea0a4685b9ae2a63118322075719b4b153c808eb031fa971682171e83b8","payload":{"connection_id":"c7dc2e4762f849c6b6f9306b6518dcab","event_at":"2026-07-27T03:24:02.172000Z","event_type":"price_change","frame_hash":"dc4a846e6001e6bd54041f54016d3b1824f1cf7fff2ecd8d0896c26115f3e928","frame_index":0,"kind":"data","monotonic_ns":224627704706041,"payload":{"event_type":"price_change","market":"0x717c0e8ccd4d5c7040185188fbae28be901ca589a11a94b1b38ca36a79eccfeb","price_changes":[{"asset_id":"41448400836309843603620980831210604935021861034693225347475867885462478926555","best_ask":"0.37","best_bid":"0.36","hash":"12f71e19b793302599f6b263137008fe3eee05b3","price":"0.34","side":"BUY","size":"28.6"},{"asset_id":"24254094493625419915756280046002869097156693848522361803041977572204227262166","best_ask":"0.64","best_bid":"0.63","hash":"6edfa9af10149051059a25fb7bd9d80db51c4329","price":"0.66","side":"SELL","size":"28.6"}],"timestamp":"1785122642172"},"payload_hash":"79a28ec15759e362d47bb9276540a935ac8c5a42e19d90f49c08e9376c95cb8d","raw_frame":"{\"market\":\"0x717c0e8ccd4d5c7040185188fbae28be901ca589a11a94b1b38ca36a79eccfeb\", \"price_changes\":[{\"asset_id\":\"41448400836309843603620980831210604935021861034693225347475867885462478926555\", \"price\":\"0.34\", \"size\":\"28.6\", \"side\":\"BUY\", \"hash\":\"12f71e19b793302599f6b263137008fe3eee05b3\", \"best_bid\":\"0.36\", \"best_ask\":\"0.37\"}, {\"asset_id\":\"24254094493625419915756280046002869097156693848522361803041977572204227262166\", \"price\":\"0.66\", \"size\":\"28.6\", \"side\":\"SELL\", \"hash\":\"6edfa9af10149051059a25fb7bd9d80db51c4329\", \"best_bid\":\"0.63\", \"best_ask\":\"0.64\"}], \"timestamp\":\"1785122642172\", \"event_type\":\"price_change\"}","received_at":"2026-07-27T03:24:04.346885Z","schema_version":"clob-market-ws.price_change.v1","sequence":null,"server_hash":null,"server_timestamp":"1785122642172","session_id":"dd162b8dca5f43ff811d304e69a06123","source":"clob_market_ws"},"received_at":"2026-07-27T03:24:04.346885Z","record_id":"28cb5830be74f8ba2b0bfa4f8afcab61a2918c19dff32da393633b869b60b031","schema_fingerprint":"4aa3821a28b0b7c2400bc59aba4bcc0a76e971dadd19610d3ad38c768e124dc7","schema_version":"edge-lab-recorder.raw.v1","sequence":null,"source":"clob_market_ws"}
{"event_at":"2026-07-27T03:24:02.180000Z","event_fingerprint":"fb79490bd47f1e4a5e25f8bbd97a792b1b1205787179a90ae63e04e0a6861b38","payload":{"connection_id":"c7dc2e4762f849c6b6f9306b6518dcab","event_at":"2026-07-27T03:24:02.180000Z","event_type":"price_change","frame_hash":"5d6e277e5e5d0f3ec24642b2d9960bbea94973c102a745681936092bd61c2133","frame_index":0,"kind":"data","monotonic_ns":224627707685250,"payload":{"event_type":"price_change","market":"0x717c0e8ccd4d5c7040185188fbae28be901ca589a11a94b1b38ca36a79eccfeb","price_changes":[{"asset_id":"41448400836309843603620980831210604935021861034693225347475867885462478926555","best_ask":"0.37","best_bid":"0.36","hash":"0100063986699c86cfc98ddc2f4609039503485e","price":"0.35","side":"BUY","size":"22.14"},{"asset_id":"24254094493625419915756280046002869097156693848522361803041977572204227262166","best_ask":"0.64","best_bid":"0.63","hash":"c06a8287041f630ff293208912e46229165628ca","price":"0.65","side":"SELL","size":"22.14"}],"timestamp":"1785122642180"},"payload_hash":"36b899ab336056b4dc0fe7afd0800e5a81c2df298b670786e8577deeebb624c0","raw_frame":"{\"market\":\"0x717c0e8ccd4d5c7040185188fbae28be901ca589a11a94b1b38ca36a79eccfeb\", \"price_changes\":[{\"asset_id\":\"41448400836309843603620980831210604935021861034693225347475867885462478926555\", \"price\":\"0.35\", \"size\":\"22.14\", \"side\":\"BUY\", \"hash\":\"0100063986699c86cfc98ddc2f4609039503485e\", \"best_bid\":\"0.36\", \"best_ask\":\"0.37\"}, {\"asset_id\":\"24254094493625419915756280046002869097156693848522361803041977572204227262166\", \"price\":\"0.65\", \"size\":\"22.14\", \"side\":\"SELL\", \"hash\":\"c06a8287041f630ff293208912e46229165628ca\", \"best_bid\":\"0.63\", \"best_ask\":\"0.64\"}], \"timestamp\":\"1785122642180\", \"event_type\":\"price_change\"}","received_at":"2026-07-27T03:24:04.349864Z","schema_version":"clob-market-ws.price_change.v1","sequence":null,"server_hash":null,"server_timestamp":"1785122642180","session_id":"dd162b8dca5f43ff811d304e69a06123","source":"clob_market_ws"},"received_at":"2026-07-27T03:24:04.349864Z","record_id":"dd84f3a0d5a0c8d2876a23d0a9d79bbc8430b50df5868befc99a189c3a39d2f6","schema_fingerprint":"4aa3821a28b0b7c2400bc59aba4bcc0a76e971dadd19610d3ad38c768e124dc7","schema_version":"edge-lab-recorder.raw.v1","sequence":null,"source":"clob_market_ws"}
{"event_at":"2026-07-27T03:24:02.180000Z","event_fingerprint":"d70be062ad468d5dfc740ede657c2320da92eaab35b26f6d7237c11cbe5941a4","payload":{"connection_id":"c7dc2e4762f849c6b6f9306b6518dcab","event_at":"2026-07-27T03:24:02.180000Z","event_type":"price_change","frame_hash":"4bb4bd2ace2cf75533fdc1cc7b633ae58c22e860e2ffdb2c7dbf6b4d8df0dc51","frame_index":0,"kind":"data","monotonic_ns":224627710860875,"payload":{"event_type":"price_change","market":"0x717c0e8ccd4d5c7040185188fbae28be901ca589a11a94b1b38ca36a79eccfeb","price_changes":[{"asset_id":"41448400836309843603620980831210604935021861034693225347475867885462478926555","best_ask":"0.37","best_bid":"0.36","hash":"0100063986699c86cfc98ddc2f4609039503485e","price":"0.36","side":"BUY","size":"301.79"},{"asset_id":"24254094493625419915756280046002869097156693848522361803041977572204227262166","best_ask":"0.64","best_bid":"0.63","hash":"c06a8287041f630ff293208912e46229165628ca","price":"0.64","side":"SELL","size":"301.79"}],"timestamp":"1785122642180"},"payload_hash":"63f8099e4ad6bf8119d450f36a75389f8877e20b0fc2f010cd1fc6a7ebbadd79","raw_frame":"{\"market\":\"0x717c0e8ccd4d5c7040185188fbae28be901ca589a11a94b1b38ca36a79eccfeb\", \"price_changes\":[{\"asset_id\":\"41448400836309843603620980831210604935021861034693225347475867885462478926555\", \"price\":\"0.36\", \"size\":\"301.79\", \"side\":\"BUY\", \"hash\":\"0100063986699c86cfc98ddc2f4609039503485e\", \"best_bid\":\"0.36\", \"best_ask\":\"0.37\"}, {\"asset_id\":\"24254094493625419915756280046002869097156693848522361803041977572204227262166\", \"price\":\"0.64\", \"size\":\"301.79\", \"side\":\"SELL\", \"hash\":\"c06a8287041f630ff293208912e46229165628ca\", \"best_bid\":\"0.63\", \"best_ask\":\"0.64\"}], \"timestamp\":\"1785122642180\", \"event_type\":\"price_change\"}","received_at":"2026-07-27T03:24:04.353034Z","schema_version":"clob-market-ws.price_change.v1","sequence":null,"server_hash":null,"server_timestamp":"1785122642180","session_id":"dd162b8dca5f43ff811d304e69a06123","source":"clob_market_ws"},"received_at":"2026-07-27T03:24:04.353034Z","record_id":"a2a75a43d7c06ee34a457f6c5eb848901146f16bc47f223a73e169565c881cde","schema_fingerprint":"4aa3821a28b0b7c2400bc59aba4bcc0a76e971dadd19610d3ad38c768e124dc7","schema_version":"edge-lab-recorder.raw.v1","sequence":null,"source":"clob_market_ws"}
{"event_at":"2026-07-27T03:24:02.181000Z","event_fingerprint":"b9c9f2040091e62427410720f2dcda3efa8343f90ebfe550a8477ae1ef4f3254","payload":{"connection_id":"c7dc2e4762f849c6b6f9306b6518dcab","event_at":"2026-07-27T03:24:02.181000Z","event_type":"price_change","frame_hash":"6b52b52a1b5d750f87c1963aa7134968d65c8de87711b61f343400d73fe89ae8","frame_index":0,"kind":"data","monotonic_ns":224627713521500,"payload":{"event_type":"price_change","market":"0x717c0e8ccd4d5c7040185188fbae28be901ca589a11a94b1b38ca36a79eccfeb","price_changes":[{"asset_id":"41448400836309843603620980831210604935021861034693225347475867885462478926555","best_ask":"0.37","best_bid":"0.36","hash":"5454ff5c29fb4c3406c1f3e86b22a0b1380c5b96","price":"0.35","side":"BUY","size":"16.6"},{"asset_id":"24254094493625419915756280046002869097156693848522361803041977572204227262166","best_ask":"0.64","best_bid":"0.63","hash":"a975f2c3b2991978aa6eaf3695424696f156dae1","price":"0.65","side":"SELL","size":"16.6"}],"timestamp":"1785122642181"},"payload_hash":"5d072b4a766360688c5fe532b5f891fb16028fb41d0ad46f247c27307f30f1dc","raw_frame":"{\"market\":\"0x717c0e8ccd4d5c7040185188fbae28be901ca589a11a94b1b38ca36a79eccfeb\", \"price_changes\":[{\"asset_id\":\"41448400836309843603620980831210604935021861034693225347475867885462478926555\", \"price\":\"0.35\", \"size\":\"16.6\", \"side\":\"BUY\", \"hash\":\"5454ff5c29fb4c3406c1f3e86b22a0b1380c5b96\", \"best_bid\":\"0.36\", \"best_ask\":\"0.37\"}, {\"asset_id\":\"24254094493625419915756280046002869097156693848522361803041977572204227262166\", \"price\":\"0.65\", \"size\":\"16.6\", \"side\":\"SELL\", \"hash\":\"a975f2c3b2991978aa6eaf3695424696f156dae1\", \"best_bid\":\"0.63\", \"best_ask\":\"0.64\"}], \"timestamp\":\"1785122642181\", \"event_type\":\"price_change\"}","received_at":"2026-07-27T03:24:04.355699Z","schema_version":"clob-market-ws.price_change.v1","sequence":null,"server_hash":null,"server_timestamp":"1785122642181","session_id":"dd162b8dca5f43ff811d304e69a06123","source":"clob_market_ws"},"received_at":"2026-07-27T03:24:04.355699Z","record_id":"6325353ecb94c52d1c3bb9ccb9ecf56a015ef12b4c8d925defb2b597ccc7c802","schema_fingerprint":"4aa3821a28b0b7c2400bc59aba4bcc0a76e971dadd19610d3ad38c768e124dc7","schema_version":"edge-lab-recorder.raw.v1","sequence":null,"source":"clob_market_ws"}
{"event_at":"2026-07-27T03:24:02.181000Z","event_fingerprint":"c3b046568977c54a145d539afce4710691e6caf2bb6cf07b1062c1a7c4a98833","payload":{"connection_id":"c7dc2e4762f849c6b6f9306b6518dcab","event_at":"2026-07-27T03:24:02.181000Z","event_type":"price_change","frame_hash":"5b82eaaac89f58e1165f66aa4e5fe6fa282d9fa599527b4f2cf325690cfcb789","frame_index":0,"kind":"data","monotonic_ns":224627715814583,"payload":{"event_type":"price_change","market":"0x717c0e8ccd4d5c7040185188fbae28be901ca589a11a94b1b38ca36a79eccfeb","price_changes":[{"asset_id":"41448400836309843603620980831210604935021861034693225347475867885462478926555","best_ask":"0.37","best_bid":"0.36","hash":"5454ff5c29fb4c3406c1f3e86b22a0b1380c5b96","price":"0.36","side":"BUY","size":"296.25"},{"asset_id":"24254094493625419915756280046002869097156693848522361803041977572204227262166","best_ask":"0.64","best_bid":"0.63","hash":"a975f2c3b2991978aa6eaf3695424696f156dae1","price":"0.64","side":"SELL","size":"296.25"}],"timestamp":"1785122642181"},"payload_hash":"79de4b7357589bf6f996c895b9ca49627413d6f77827b15fe3e40e408b6f2e2e","raw_frame":"{\"market\":\"0x717c0e8ccd4d5c7040185188fbae28be901ca589a11a94b1b38ca36a79eccfeb\", \"price_changes\":[{\"asset_id\":\"41448400836309843603620980831210604935021861034693225347475867885462478926555\", \"price\":\"0.36\", \"size\":\"296.25\", \"side\":\"BUY\", \"hash\":\"5454ff5c29fb4c3406c1f3e86b22a0b1380c5b96\", \"best_bid\":\"0.36\", \"best_ask\":\"0.37\"}, {\"asset_id\":\"24254094493625419915756280046002869097156693848522361803041977572204227262166\", \"price\":\"0.64\", \"size\":\"296.25\", \"side\":\"SELL\", \"hash\":\"a975f2c3b2991978aa6eaf3695424696f156dae1\", \"best_bid\":\"0.63\", \"best_ask\":\"0.64\"}], \"timestamp\":\"1785122642181\", \"event_type\":\"price_change\"}","received_at":"2026-07-27T03:24:04.357996Z","schema_version":"clob-market-ws.price_change.v1","sequence":null,"server_hash":null,"server_timestamp":"1785122642181","session_id":"dd162b8dca5f43ff811d304e69a06123","source":"clob_market_ws"},"received_at":"2026-07-27T03:24:04.357996Z","record_id":"bfa8126ec284f878ec31090924e34c6bb3501db037fa20a89e8ebba831c2e555","schema_fingerprint":"4aa3821a28b0b7c2400bc59aba4bcc0a76e971dadd19610d3ad38c768e124dc7","schema_version":"edge-lab-recorder.raw.v1","sequence":null,"source":"clob_market_ws"}
{"event_at":"2026-07-27T03:24:02.200000Z","event_fingerprint":"b0c98d64f01ca201352480ee29701c133150fcc5541b38254dd842a4061d1b4c","payload":{"connection_id":"c7dc2e4762f849c6b6f9306b6518dcab","event_at":"2026-07-27T03:24:02.200000Z","event_type":"price_change","frame_hash":"3112799a52cd438c32157702b6e8e2e4198ac1669c7f6de5400e36bb74cf58d8","frame_index":0,"kind":"data","monotonic_ns":224627717982958,"payload":{"event_type":"price_change","market":"0x717c0e8ccd4d5c7040185188fbae28be901ca589a11a94b1b38ca36a79eccfeb","price_changes":[{"asset_id":"24254094493625419915756280046002869097156693848522361803041977572204227262166","best_ask":"0.64","best_bid":"0.63","hash":"3b6eb369348d439d167d75f185b196703dfe82a6","price":"0.56","side":"BUY","size":"123"},{"asset_id":"41448400836309843603620980831210604935021861034693225347475867885462478926555","best_ask":"0.37","best_bid":"0.36","hash":"d1e423c383d1ec1cc90b065a56cec459a1593275","price":"0.44","side":"SELL","size":"123"}],"timestamp":"1785122642200"},"payload_hash":"84db7f4602c3f4968f6f3b836f4f6ac8877fa0b43062be7dbba3f37e0913817d","raw_frame":"{\"market\":\"0x717c0e8ccd4d5c7040185188fbae28be901ca589a11a94b1b38ca36a79eccfeb\", \"price_changes\":[{\"asset_id\":\"24254094493625419915756280046002869097156693848522361803041977572204227262166\", \"price\":\"0.56\", \"size\":\"123\", \"side\":\"BUY\", \"hash\":\"3b6eb369348d439d167d75f185b196703dfe82a6\", \"best_bid\":\"0.63\", \"best_ask\":\"0.64\"}, {\"asset_id\":\"41448400836309843603620980831210604935021861034693225347475867885462478926555\", \"price\":\"0.44\", \"size\":\"123\", \"side\":\"SELL\", \"hash\":\"d1e423c383d1ec1cc90b065a56cec459a1593275\", \"best_bid\":\"0.36\", \"best_ask\":\"0.37\"}], \"timestamp\":\"1785122642200\", \"event_type\":\"price_change\"}","received_at":"2026-07-27T03:24:04.360161Z","schema_version":"clob-market-ws.price_change.v1","sequence":null,"server_hash":null,"server_timestamp":"1785122642200","session_id":"dd162b8dca5f43ff811d304e69a06123","source":"clob_market_ws"},"received_at":"2026-07-27T03:24:04.360161Z","record_id":"54dd977fb036f3c2c35390c2dc2654a89422a035d948bd498bd2ab4f7e2f3ff3","schema_fingerprint":"4aa3821a28b0b7c2400bc59aba4bcc0a76e971dadd19610d3ad38c768e124dc7","schema_version":"edge-lab-recorder.raw.v1","sequence":null,"source":"clob_market_ws"}
{"event_at":"2026-07-27T03:24:02.205000Z","event_fingerprint":"d913923e32d85c075b4c2421d938f9f0b9fcc971b1d422099dfaa64971dc9e37","payload":{"connection_id":"c7dc2e4762f849c6b6f9306b6518dcab","event_at":"2026-07-27T03:24:02.205000Z","event_type":"price_change","frame_hash":"23ca0056975e05e1d75d7ce806528a612a1ed2ef7388c98524bfcecc8da564f7","frame_index":0,"kind":"data","monotonic_ns":224627720271916,"payload":{"event_type":"price_change","market":"0x717c0e8ccd4d5c7040185188fbae28be901ca589a11a94b1b38ca36a79eccfeb","price_changes":[{"asset_id":"24254094493625419915756280046002869097156693848522361803041977572204227262166","best_ask":"0.64","best_bid":"0.63","hash":"10a6283ca0457a10b22e6953852197ad9ceb95ca","price":"0.03","side":"BUY","size":"618.1"},{"asset_id":"41448400836309843603620980831210604935021861034693225347475867885462478926555","best_ask":"0.37","best_bid":"0.36","hash":"99ba24f7fa1ec0d66dd2e4955c620a937c7d0cb3","price":"0.97","side":"SELL","size":"618.1"}],"timestamp":"1785122642205"},"payload_hash":"190fd037c13d151296db469d4853e8989fd295076ec78f1846d8446c77f8947d","raw_frame":"{\"market\":\"0x717c0e8ccd4d5c7040185188fbae28be901ca589a11a94b1b38ca36a79eccfeb\", \"price_changes\":[{\"asset_id\":\"24254094493625419915756280046002869097156693848522361803041977572204227262166\", \"price\":\"0.03\", \"size\":\"618.1\", \"side\":\"BUY\", \"hash\":\"10a6283ca0457a10b22e6953852197ad9ceb95ca\", \"best_bid\":\"0.63\", \"best_ask\":\"0.64\"}, {\"asset_id\":\"41448400836309843603620980831210604935021861034693225347475867885462478926555\", \"price\":\"0.97\", \"size\":\"618.1\", \"side\":\"SELL\", \"hash\":\"99ba24f7fa1ec0d66dd2e4955c620a937c7d0cb3\", \"best_bid\":\"0.36\", \"best_ask\":\"0.37\"}], \"timestamp\":\"1785122642205\", \"event_type\":\"price_change\"}","received_at":"2026-07-27T03:24:04.362451Z","schema_version":"clob-market-ws.price_change.v1","sequence":null,"server_hash":null,"server_timestamp":"1785122642205","session_id":"dd162b8dca5f43ff811d304e69a06123","source":"clob_market_ws"},"received_at":"2026-07-27T03:24:04.362451Z","record_id":"412bc774f458a6bc2b71d92db47d90093d53ab44044b47d9b2ac7686bfb3b213","schema_fingerprint":"4aa3821a28b0b7c2400bc59aba4bcc0a76e971dadd19610d3ad38c768e124dc7","schema_version":"edge-lab-recorder.raw.v1","sequence":null,"source":"clob_market_ws"}
{"event_at":"2026-07-27T03:24:02.158000Z","event_fingerprint":"40375fe4494e6a45c5f26949fe62b093ccdb2bcad3e321505133f83fc12f6db6","payload":{"connection_id":"c7dc2e4762f849c6b6f9306b6518dcab","event_at":"2026-07-27T03:24:02.158000Z","event_type":"last_trade_price","frame_hash":"35303b70e87247571bcb69253d313040494ca5b25fccc6eaa0765df152523521","frame_index":0,"kind":"data","monotonic_ns":224627723170250,"payload":{"asset_id":"24254094493625419915756280046002869097156693848522361803041977572204227262166","event_type":"last_trade_price","fee_rate_bps":"0","market":"0x717c0e8ccd4d5c7040185188fbae28be901ca589a11a94b1b38ca36a79eccfeb","price":"0.63","side":"SELL","size":"0.02","timestamp":"1785122642158","transaction_hash":"0x1b3024f46a6821012212a1684ee8c5f6c4fae8f05bcc4448cc094fff66485fb5"},"payload_hash":"5ef786503e2cbc34ea49bdaca54a245a519f64134cefe29517461b5ec2c5b6e4","raw_frame":"{\"market\":\"0x717c0e8ccd4d5c7040185188fbae28be901ca589a11a94b1b38ca36a79eccfeb\", \"asset_id\":\"24254094493625419915756280046002869097156693848522361803041977572204227262166\", \"price\":\"0.63\", \"size\":\"0.02\", \"fee_rate_bps\":\"0\", \"side\":\"SELL\", \"timestamp\":\"1785122642158\", \"event_type\":\"last_trade_price\", \"transaction_hash\":\"0x1b3024f46a6821012212a1684ee8c5f6c4fae8f05bcc4448cc094fff66485fb5\"}","received_at":"2026-07-27T03:24:04.365350Z","schema_version":"clob-market-ws.last_trade_price.v1","sequence":null,"server_hash":null,"server_timestamp":"1785122642158","session_id":"dd162b8dca5f43ff811d304e69a06123","source":"clob_market_ws"},"received_at":"2026-07-27T03:24:04.365350Z","record_id":"1b1961cf2395661ffa58ad64a812819a678962e06f34a77d07372142b7ca2e0b","schema_fingerprint":"95ad9be75a4b695cd99991e12b2592bc7346f3f5388a82d0000ba65bc0d9fd0a","schema_version":"edge-lab-recorder.raw.v1","sequence":null,"source":"clob_market_ws"}
{"event_at":"2026-07-27T03:24:02.211000Z","event_fingerprint":"14dc8d267375ba210e4f3168ee1a24e07e565ee55bcb9153a5e13eb32d6ace21","payload":{"connection_id":"c7dc2e4762f849c6b6f9306b6518dcab","event_at":"2026-07-27T03:24:02.211000Z","event_type":"price_change","frame_hash":"0ee592198afd647cb2c385f41d4f477b946d0ed537b726d63ea29da3d872ae9d","frame_index":0,"kind":"data","monotonic_ns":224627725753416,"payload":{"event_type":"price_change","market":"0x717c0e8ccd4d5c7040185188fbae28be901ca589a11a94b1b38ca36a79eccfeb","price_changes":[{"asset_id":"24254094493625419915756280046002869097156693848522361803041977572204227262166","best_ask":"0.64","best_bid":"0.63","hash":"a202fc3ceb7109c8865daf738bae44b6cf729f07","price":"0.57","side":"BUY","size":"34"},{"asset_id":"41448400836309843603620980831210604935021861034693225347475867885462478926555","best_ask":"0.37","best_bid":"0.36","hash":"9d39e42b3434b34282a37675fad9640a180c4919","price":"0.43","side":"SELL","size":"34"}],"timestamp":"1785122642211"},"payload_hash":"a0ad17558064415f69197146a2ec765865320d2b0608548c900a669ca7070a13","raw_frame":"{\"market\":\"0x717c0e8ccd4d5c7040185188fbae28be901ca589a11a94b1b38ca36a79eccfeb\", \"price_changes\":[{\"asset_id\":\"24254094493625419915756280046002869097156693848522361803041977572204227262166\", \"price\":\"0.57\", \"size\":\"34\", \"side\":\"BUY\", \"hash\":\"a202fc3ceb7109c8865daf738bae44b6cf729f07\", \"best_bid\":\"0.63\", \"best_ask\":\"0.64\"}, {\"asset_id\":\"41448400836309843603620980831210604935021861034693225347475867885462478926555\", \"price\":\"0.43\", \"size\":\"34\", \"side\":\"SELL\", \"hash\":\"9d39e42b3434b34282a37675fad9640a180c4919\", \"best_bid\":\"0.36\", \"best_ask\":\"0.37\"}], \"timestamp\":\"1785122642211\", \"event_type\":\"price_change\"}","received_at":"2026-07-27T03:24:04.367934Z","schema_version":"clob-market-ws.price_change.v1","sequence":null,"server_hash":null,"server_timestamp":"1785122642211","session_id":"dd162b8dca5f43ff811d304e69a06123","source":"clob_market_ws"},"received_at":"2026-07-27T03:24:04.367934Z","record_id":"7206dfa04b4367d3d5b1619e60f652612e55c149e4530170de843ad1b14ef9b6","schema_fingerprint":"4aa3821a28b0b7c2400bc59aba4bcc0a76e971dadd19610d3ad38c768e124dc7","schema_version":"edge-lab-recorder.raw.v1","sequence":null,"source":"clob_market_ws"}
{"event_at":"2026-07-27T03:24:02.214000Z","event_fingerprint":"6835dcb61d96bfe82a2b7a8ded341fc51bea8f841d9730737d55b94396a4a807","payload":{"connection_id":"c7dc2e4762f849c6b6f9306b6518dcab","event_at":"2026-07-27T03:24:02.214000Z","event_type":"price_change","frame_hash":"ff17a8fcc5956462a8f60cebdd8bf2b2bcbd6adee9018e62fe84688848875f6a","frame_index":0,"kind":"data","monotonic_ns":224627728811958,"payload":{"event_type":"price_change","market":"0x717c0e8ccd4d5c7040185188fbae28be901ca589a11a94b1b38ca36a79eccfeb","price_changes":[{"asset_id":"24254094493625419915756280046002869097156693848522361803041977572204227262166","best_ask":"0.64","best_bid":"0.63","hash":"86ac22b14a3d71ed9570ac8946dbf7a40cc3ba3d","price":"0.51","side":"BUY","size":"17"},{"asset_id":"41448400836309843603620980831210604935021861034693225347475867885462478926555","best_ask":"0.37","best_bid":"0.36","hash":"c051f277c84da2c1e9879bd8e0829d88dfd3aed5","price":"0.49","side":"SELL","size":"17"}],"timestamp":"1785122642214"},"payload_hash":"407f96963d4591b79948a3f189b7b776600f964601f987cdd901b76768e3bdd6","raw_frame":"{\"market\":\"0x717c0e8ccd4d5c7040185188fbae28be901ca589a11a94b1b38ca36a79eccfeb\", \"price_changes\":[{\"asset_id\":\"24254094493625419915756280046002869097156693848522361803041977572204227262166\", \"price\":\"0.51\", \"size\":\"17\", \"side\":\"BUY\", \"hash\":\"86ac22b14a3d71ed9570ac8946dbf7a40cc3ba3d\", \"best_bid\":\"0.63\", \"best_ask\":\"0.64\"}, {\"asset_id\":\"41448400836309843603620980831210604935021861034693225347475867885462478926555\", \"price\":\"0.49\", \"size\":\"17\", \"side\":\"SELL\", \"hash\":\"c051f277c84da2c1e9879bd8e0829d88dfd3aed5\", \"best_bid\":\"0.36\", \"best_ask\":\"0.37\"}], \"timestamp\":\"1785122642214\", \"event_type\":\"price_change\"}","received_at":"2026-07-27T03:24:04.370990Z","schema_version":"clob-market-ws.price_change.v1","sequence":null,"server_hash":null,"server_timestamp":"1785122642214","session_id":"dd162b8dca5f43ff811d304e69a06123","source":"clob_market_ws"},"received_at":"2026-07-27T03:24:04.370990Z","record_id":"a1eb4cb6857eab600cbc7ad6769892cc32cabe752ef329bdadca403f3a9f4d27","schema_fingerprint":"4aa3821a28b0b7c2400bc59aba4bcc0a76e971dadd19610d3ad38c768e124dc7","schema_version":"edge-lab-recorder.raw.v1","sequence":null,"source":"clob_market_ws"}
{"event_at":"2026-07-27T03:24:02.214000Z","event_fingerprint":"e543a5a3427b5b97da299db927227dc4c99a9f9985e2e111020f59fb7343c1a1","payload":{"connection_id":"c7dc2e4762f849c6b6f9306b6518dcab","event_at":"2026-07-27T03:24:02.214000Z","event_type":"price_change","frame_hash":"0356193bceeb95c05070ea853bca9fffe8d541056012c611b286c7b105b4f692","frame_index":0,"kind":"data","monotonic_ns":224627731778708,"payload":{"event_type":"price_change","market":"0x717c0e8ccd4d5c7040185188fbae28be901ca589a11a94b1b38ca36a79eccfeb","price_changes":[{"asset_id":"24254094493625419915756280046002869097156693848522361803041977572204227262166","best_ask":"0.64","best_bid":"0.63","hash":"86ac22b14a3d71ed9570ac8946dbf7a40cc3ba3d","price":"0.5","side":"BUY","size":"117"},{"asset_id":"41448400836309843603620980831210604935021861034693225347475867885462478926555","best_ask":"0.37","best_bid":"0.36","hash":"c051f277c84da2c1e9879bd8e0829d88dfd3aed5","price":"0.5","side":"SELL","size":"117"}],"timestamp":"1785122642214"},"payload_hash":"749c599c1a7419603e8ff68b9bf09cd498a95697b683fecfb47510aa6495e556","raw_frame":"{\"market\":\"0x717c0e8ccd4d5c7040185188fbae28be901ca589a11a94b1b38ca36a79eccfeb\", \"price_changes\":[{\"asset_id\":\"24254094493625419915756280046002869097156693848522361803041977572204227262166\", \"price\":\"0.5\", \"size\":\"117\", \"side\":\"BUY\", \"hash\":\"86ac22b14a3d71ed9570ac8946dbf7a40cc3ba3d\", \"best_bid\":\"0.63\", \"best_ask\":\"0.64\"}, {\"asset_id\":\"41448400836309843603620980831210604935021861034693225347475867885462478926555\", \"price\":\"0.5\", \"size\":\"117\", \"side\":\"SELL\", \"hash\":\"c051f277c84da2c1e9879bd8e0829d88dfd3aed5\", \"best_bid\":\"0.36\", \"best_ask\":\"0.37\"}], \"timestamp\":\"1785122642214\", \"event_type\":\"price_change\"}","received_at":"2026-07-27T03:24:04.373957Z","schema_version":"clob-market-ws.price_change.v1","sequence":null,"server_hash":null,"server_timestamp":"1785122642214","session_id":"dd162b8dca5f43ff811d304e69a06123","source":"clob_market_ws"},"received_at":"2026-07-27T03:24:04.373957Z","record_id":"e3bab94ad665eb4446336b7f033adcec82a9b265a6033a88befa902ccc6625db","schema_fingerprint":"4aa3821a28b0b7c2400bc59aba4bcc0a76e971dadd19610d3ad38c768e124dc7","schema_version":"edge-lab-recorder.raw.v1","sequence":null,"source":"clob_market_ws"}
{"event_at":"2026-07-27T03:24:02.214000Z","event_fingerprint":"8df80900e04904ad30436d94103e81d93837c12b9a95764a38230faf2f1cbddd","payload":{"connection_id":"c7dc2e4762f849c6b6f9306b6518dcab","event_at":"2026-07-27T03:24:02.214000Z","event_type":"price_change","frame_hash":"35eac84ed8933eb6175a6305a1235750cdefe0db3547299ff12105140f7f94ff","frame_index":0,"kind":"data","monotonic_ns":224627734726833,"payload":{"event_type":"price_change","market":"0x717c0e8ccd4d5c7040185188fbae28be901ca589a11a94b1b38ca36a79eccfeb","price_changes":[{"asset_id":"41448400836309843603620980831210604935021861034693225347475867885462478926555","best_ask":"0.37","best_bid":"0.36","hash":"c051f277c84da2c1e9879bd8e0829d88dfd3aed5","price":"0.29","side":"BUY","size":"7"},{"asset_id":"24254094493625419915756280046002869097156693848522361803041977572204227262166","best_ask":"0.64","best_bid":"0.63","hash":"86ac22b14a3d71ed9570ac8946dbf7a40cc3ba3d","price":"0.71","side":"SELL","size":"7"}],"timestamp":"1785122642214"},"payload_hash":"550b24481ee0b28c2c9cc6678c4950f80db95cc5995955d6e4b009e6c19e44cc","raw_frame":"{\"market\":\"0x717c0e8ccd4d5c7040185188fbae28be901ca589a11a94b1b38ca36a79eccfeb\", \"price_changes\":[{\"asset_id\":\"41448400836309843603620980831210604935021861034693225347475867885462478926555\", \"price\":\"0.29\", \"size\":\"7\", \"side\":\"BUY\", \"hash\":\"c051f277c84da2c1e9879bd8e0829d88dfd3aed5\", \"best_bid\":\"0.36\", \"best_ask\":\"0.37\"}, {\"asset_id\":\"24254094493625419915756280046002869097156693848522361803041977572204227262166\", \"price\":\"0.71\", \"size\":\"7\", \"side\":\"SELL\", \"hash\":\"86ac22b14a3d71ed9570ac8946dbf7a40cc3ba3d\", \"best_bid\":\"0.63\", \"best_ask\":\"0.64\"}], \"timestamp\":\"1785122642214\", \"event_type\":\"price_change\"}","received_at":"2026-07-27T03:24:04.376906Z","schema_version":"clob-market-ws.price_change.v1","sequence":null,"server_hash":null,"server_timestamp":"1785122642214","session_id":"dd162b8dca5f43ff811d304e69a06123","source":"clob_market_ws"},"received_at":"2026-07-27T03:24:04.376906Z","record_id":"ecbc573479b066a8ec49e660e525e6ab2d315023c057d1089173f75f83173412","schema_fingerprint":"4aa3821a28b0b7c2400bc59aba4bcc0a76e971dadd19610d3ad38c768e124dc7","schema_version":"edge-lab-recorder.raw.v1","sequence":null,"source":"clob_market_ws"}
{"event_at":"2026-07-27T03:24:02.226000Z","event_fingerprint":"b6a43f4a14d5f98e71a76900606a99eb7749d7e1f0c65b4752c03f5b18ba7301","payload":{"connection_id":"c7dc2e4762f849c6b6f9306b6518dcab","event_at":"2026-07-27T03:24:02.226000Z","event_type":"price_change","frame_hash":"d458be2adf9bc245ce28f9a015922efb6e6d9348ea81d9586892d256d28ce608","frame_index":0,"kind":"data","monotonic_ns":224627737604500,"payload":{"event_type":"price_change","market":"0x717c0e8ccd4d5c7040185188fbae28be901ca589a11a94b1b38ca36a79eccfeb","price_changes":[{"asset_id":"24254094493625419915756280046002869097156693848522361803041977572204227262166","best_ask":"0.64","best_bid":"0.63","hash":"1ec273167b18e8daea6d3c056f4eae62daa193b6","price":"0.55","side":"BUY","size":"126.07"},{"asset_id":"41448400836309843603620980831210604935021861034693225347475867885462478926555","best_ask":"0.37","best_bid":"0.36","hash":"28bfee216cde5adce94afdf167d48d7d124ff551","price":"0.45","side":"SELL","size":"126.07"}],"timestamp":"1785122642226"},"payload_hash":"4da09161835840dc4af042a114680a7ec203916d2cb31ea626a24ce3e1286b3b","raw_frame":"{\"market\":\"0x717c0e8ccd4d5c7040185188fbae28be901ca589a11a94b1b38ca36a79eccfeb\", \"price_changes\":[{\"asset_id\":\"24254094493625419915756280046002869097156693848522361803041977572204227262166\", \"price\":\"0.55\", \"size\":\"126.07\", \"side\":\"BUY\", \"hash\":\"1ec273167b18e8daea6d3c056f4eae62daa193b6\", \"best_bid\":\"0.63\", \"best_ask\":\"0.64\"}, {\"asset_id\":\"41448400836309843603620980831210604935021861034693225347475867885462478926555\", \"price\":\"0.45\", \"size\":\"126.07\", \"side\":\"SELL\", \"hash\":\"28bfee216cde5adce94afdf167d48d7d124ff551\", \"best_bid\":\"0.36\", \"best_ask\":\"0.37\"}], \"timestamp\":\"1785122642226\", \"event_type\":\"price_change\"}","received_at":"2026-07-27T03:24:04.379784Z","schema_version":"clob-market-ws.price_change.v1","sequence":null,"server_hash":null,"server_timestamp":"1785122642226","session_id":"dd162b8dca5f43ff811d304e69a06123","source":"clob_market_ws"},"received_at":"2026-07-27T03:24:04.379784Z","record_id":"6511ac7dcf105e6ef0a6b75aae6767b40d68e1e3f83daf1ec1da688aa459268e","schema_fingerprint":"4aa3821a28b0b7c2400bc59aba4bcc0a76e971dadd19610d3ad38c768e124dc7","schema_version":"edge-lab-recorder.raw.v1","sequence":null,"source":"clob_market_ws"}
{"event_at":"2026-07-27T03:24:02.227000Z","event_fingerprint":"fee99d871c829e47c2e8f86dee32a1fdbea07b75c5d2e63c08348011d59bcd68","payload":{"connection_id":"c7dc2e4762f849c6b6f9306b6518dcab","event_at":"2026-07-27T03:24:02.227000Z","event_type":"price_change","frame_hash":"40a45638b940c29e62c69489a22c8019537be2857b25b72d8db4227a318f7541","frame_index":0,"kind":"data","monotonic_ns":224627740554958,"payload":{"event_type":"price_change","market":"0x717c0e8ccd4d5c7040185188fbae28be901ca589a11a94b1b38ca36a79eccfeb","price_changes":[{"asset_id":"41448400836309843603620980831210604935021861034693225347475867885462478926555","best_ask":"0.37","best_bid":"0.36","hash":"08bbcde2cd29d006bb1f4c60ed49e73ea1bb07de","price":"0.34","side":"BUY","size":"41.88"},{"asset_id":"24254094493625419915756280046002869097156693848522361803041977572204227262166","best_ask":"0.64","best_bid":"0.63","hash":"e7c5ef895e77aaca4ae832d641c8fa9d35f6db19","price":"0.66","side":"SELL","size":"41.88"}],"timestamp":"1785122642227"},"payload_hash":"0146df8146abedb5464cfd828ee00a1be9cfcebadcc7857e1a5afc17cc5dead9","raw_frame":"{\"market\":\"0x717c0e8ccd4d5c7040185188fbae28be901ca589a11a94b1b38ca36a79eccfeb\", \"price_changes\":[{\"asset_id\":\"41448400836309843603620980831210604935021861034693225347475867885462478926555\", \"price\":\"0.34\", \"size\":\"41.88\", \"side\":\"BUY\", \"hash\":\"08bbcde2cd29d006bb1f4c60ed49e73ea1bb07de\", \"best_bid\":\"0.36\", \"best_ask\":\"0.37\"}, {\"asset_id\":\"24254094493625419915756280046002869097156693848522361803041977572204227262166\", \"price\":\"0.66\", \"size\":\"41.88\", \"side\":\"SELL\", \"hash\":\"e7c5ef895e77aaca4ae832d641c8fa9d35f6db19\", \"best_bid\":\"0.63\", \"best_ask\":\"0.64\"}], \"timestamp\":\"1785122642227\", \"event_type\":\"price_change\"}","received_at":"2026-07-27T03:24:04.382734Z","schema_version":"clob-market-ws.price_change.v1","sequence":null,"server_hash":null,"server_timestamp":"1785122642227","session_id":"dd162b8dca5f43ff811d304e69a06123","source":"clob_market_ws"},"received_at":"2026-07-27T03:24:04.382734Z","record_id":"efb277dd40f2a6437860d9b5f53e17adb14b1267e4108006e20aac50ce89ae37","schema_fingerprint":"4aa3821a28b0b7c2400bc59aba4bcc0a76e971dadd19610d3ad38c768e124dc7","schema_version":"edge-lab-recorder.raw.v1","sequence":null,"source":"clob_market_ws"}
{"event_at":"2026-07-27T03:24:02.228000Z","event_fingerprint":"f652c79b540a10574a6f11c62cdee7e97fcb8fa21dbc734bf6260fe05995e4b3","payload":{"connection_id":"c7dc2e4762f849c6b6f9306b6518dcab","event_at":"2026-07-27T03:24:02.228000Z","event_type":"price_change","frame_hash":"0e0c73c985c905584cd25c19a220e808d5c63bd98782d302aac14b787a0d56ae","frame_index":0,"kind":"data","monotonic_ns":224627743831375,"payload":{"event_type":"price_change","market":"0x717c0e8ccd4d5c7040185188fbae28be901ca589a11a94b1b38ca36a79eccfeb","price_changes":[{"asset_id":"24254094493625419915756280046002869097156693848522361803041977572204227262166","best_ask":"0.64","best_bid":"0.63","hash":"66c9500351f150264a0042d3828360271190c8d9","price":"0.54","side":"BUY","size":"216.04"},{"asset_id":"41448400836309843603620980831210604935021861034693225347475867885462478926555","best_ask":"0.37","best_bid":"0.36","hash":"6fd8a16f069fb0e5e5a4da542481d0e3fd80dc32","price":"0.46","side":"SELL","size":"216.04"}],"timestamp":"1785122642228"},"payload_hash":"76dc38a1bf1f66b27f2a039824baa29959a38499e144da6a2d700e60693fb51e","raw_frame":"{\"market\":\"0x717c0e8ccd4d5c7040185188fbae28be901ca589a11a94b1b38ca36a79eccfeb\", \"price_changes\":[{\"asset_id\":\"24254094493625419915756280046002869097156693848522361803041977572204227262166\", \"price\":\"0.54\", \"size\":\"216.04\", \"side\":\"BUY\", \"hash\":\"66c9500351f150264a0042d3828360271190c8d9\", \"best_bid\":\"0.63\", \"best_ask\":\"0.64\"}, {\"asset_id\":\"41448400836309843603620980831210604935021861034693225347475867885462478926555\", \"price\":\"0.46\", \"size\":\"216.04\", \"side\":\"SELL\", \"hash\":\"6fd8a16f069fb0e5e5a4da542481d0e3fd80dc32\", \"best_bid\":\"0.36\", \"best_ask\":\"0.37\"}], \"timestamp\":\"1785122642228\", \"event_type\":\"price_change\"}","received_at":"2026-07-27T03:24:04.386010Z","schema_version":"clob-market-ws.price_change.v1","sequence":null,"server_hash":null,"server_timestamp":"1785122642228","session_id":"dd162b8dca5f43ff811d304e69a06123","source":"clob_market_ws"},"received_at":"2026-07-27T03:24:04.386010Z","record_id":"a07fada17be54b40ca9aa037997002865287908635dc794a63f7bf75fbef28aa","schema_fingerprint":"4aa3821a28b0b7c2400bc59aba4bcc0a76e971dadd19610d3ad38c768e124dc7","schema_version":"edge-lab-recorder.raw.v1","sequence":null,"source":"clob_market_ws"}
{"event_at":"2026-07-27T03:24:02.255000Z","event_fingerprint":"02772b5fb5038e9fba8c32f5ef4d02103be782d13f761229afa583dbbfa267fc","payload":{"connection_id":"c7dc2e4762f849c6b6f9306b6518dcab","event_at":"2026-07-27T03:24:02.255000Z","event_type":"price_change","frame_hash":"da898033502842f151ae1f4fa3c4b7d5505bde8f36592d1cbe7465718f5de4c2","frame_index":0,"kind":"data","monotonic_ns":224627746748666,"payload":{"event_type":"price_change","market":"0x717c0e8ccd4d5c7040185188fbae28be901ca589a11a94b1b38ca36a79eccfeb","price_changes":[{"asset_id":"24254094493625419915756280046002869097156693848522361803041977572204227262166","best_ask":"0.64","best_bid":"0.63","hash":"eb0c3bbed3b2dd5603dfee0aa4068e7072f6ac4d","price":"0.01","side":"BUY","size":"5458.02"},{"asset_id":"41448400836309843603620980831210604935021861034693225347475867885462478926555","best_ask":"0.37","best_bid":"0.36","hash":"d3257f5b14938590ba4e87511681e65495aab0b8","price":"0.99","side":"SELL","size":"5458.02"}],"timestamp":"1785122642255"},"payload_hash":"7b1064b090862a56107194ae8367b3bfd08d28e02b539ffb3478820029f58c72","raw_frame":"{\"market\":\"0x717c0e8ccd4d5c7040185188fbae28be901ca589a11a94b1b38ca36a79eccfeb\", \"price_changes\":[{\"asset_id\":\"24254094493625419915756280046002869097156693848522361803041977572204227262166\", \"price\":\"0.01\", \"size\":\"5458.02\", \"side\":\"BUY\", \"hash\":\"eb0c3bbed3b2dd5603dfee0aa4068e7072f6ac4d\", \"best_bid\":\"0.63\", \"best_ask\":\"0.64\"}, {\"asset_id\":\"41448400836309843603620980831210604935021861034693225347475867885462478926555\", \"price\":\"0.99\", \"size\":\"5458.02\", \"side\":\"SELL\", \"hash\":\"d3257f5b14938590ba4e87511681e65495aab0b8\", \"best_bid\":\"0.36\", \"best_ask\":\"0.37\"}], \"timestamp\":\"1785122642255\", \"event_type\":\"price_change\"}","received_at":"2026-07-27T03:24:04.388926Z","schema_version":"clob-market-ws.price_change.v1","sequence":null,"server_hash":null,"server_timestamp":"1785122642255","session_id":"dd162b8dca5f43ff811d304e69a06123","source":"clob_market_ws"},"received_at":"2026-07-27T03:24:04.388926Z","record_id":"4679cca1e0160818fce9346e5834bb19a0775809e9b19fc152136d10a1ada785","schema_fingerprint":"4aa3821a28b0b7c2400bc59aba4bcc0a76e971dadd19610d3ad38c768e124dc7","schema_version":"edge-lab-recorder.raw.v1","sequence":null,"source":"clob_market_ws"}
{"event_at":"2026-07-27T03:24:02.255000Z","event_fingerprint":"26ee624ab343e22dc1cb08e8b7ff698c1e336b33b9683d6923a3d15e81d33500","payload":{"connection_id":"c7dc2e4762f849c6b6f9306b6518dcab","event_at":"2026-07-27T03:24:02.255000Z","event_type":"price_change","frame_hash":"eba6ef2a5ff946d98d82109086618e7afcd3e12f10718da49ea4fee1046641af","frame_index":0,"kind":"data","monotonic_ns":224627749927250,"payload":{"event_type":"price_change","market":"0x717c0e8ccd4d5c7040185188fbae28be901ca589a11a94b1b38ca36a79eccfeb","price_changes":[{"asset_id":"24254094493625419915756280046002869097156693848522361803041977572204227262166","best_ask":"0.64","best_bid":"0.63","hash":"b3eeab0d1054425c90861576955fa07a63f9c2e3","price":"0.36","side":"BUY","size":"203.18"},{"asset_id":"41448400836309843603620980831210604935021861034693225347475867885462478926555","best_ask":"0.37","best_bid":"0.36","hash":"10278a06328003da8410d0d72c156f16700825df","price":"0.64","side":"SELL","size":"203.18"}],"timestamp":"1785122642255"},"payload_hash":"16675f0ec7fa9089cea3eba17268d41649f1fda9aaf3d0bc236a46d87ba5d689","raw_frame":"{\"market\":\"0x717c0e8ccd4d5c7040185188fbae28be901ca589a11a94b1b38ca36a79eccfeb\", \"price_changes\":[{\"asset_id\":\"24254094493625419915756280046002869097156693848522361803041977572204227262166\", \"price\":\"0.36\", \"size\":\"203.18\", \"side\":\"BUY\", \"hash\":\"b3eeab0d1054425c90861576955fa07a63f9c2e3\", \"best_bid\":\"0.63\", \"best_ask\":\"0.64\"}, {\"asset_id\":\"41448400836309843603620980831210604935021861034693225347475867885462478926555\", \"price\":\"0.64\", \"size\":\"203.18\", \"side\":\"SELL\", \"hash\":\"10278a06328003da8410d0d72c156f16700825df\", \"best_bid\":\"0.36\", \"best_ask\":\"0.37\"}], \"timestamp\":\"1785122642255\", \"event_type\":\"price_change\"}","received_at":"2026-07-27T03:24:04.392106Z","schema_version":"clob-market-ws.price_change.v1","sequence":null,"server_hash":null,"server_timestamp":"1785122642255","session_id":"dd162b8dca5f43ff811d304e69a06123","source":"clob_market_ws"},"received_at":"2026-07-27T03:24:04.392106Z","record_id":"5f14a90ebfe4f823af45ccf362f84c49e96725f25113e6c58baede3dda9080d2","schema_fingerprint":"4aa3821a28b0b7c2400bc59aba4bcc0a76e971dadd19610d3ad38c768e124dc7","schema_version":"edge-lab-recorder.raw.v1","sequence":null,"source":"clob_market_ws"}
{"event_at":"2026-07-27T03:24:02.256000Z","event_fingerprint":"7478da82831a8992665ad3dfa9e550fb4389b778dc6d13aa4d8a859ab7dd6484","payload":{"connection_id":"c7dc2e4762f849c6b6f9306b6518dcab","event_at":"2026-07-27T03:24:02.256000Z","event_type":"price_change","frame_hash":"4b24a6c934b37361a6b9cba779db8e64d5cf33e5b325bca3b74de4317abf5c51","frame_index":0,"kind":"data","monotonic_ns":224627752951750,"payload":{"event_type":"price_change","market":"0x717c0e8ccd4d5c7040185188fbae28be901ca589a11a94b1b38ca36a79eccfeb","price_changes":[{"asset_id":"24254094493625419915756280046002869097156693848522361803041977572204227262166","best_ask":"0.64","best_bid":"0.63","hash":"052adf200351177b47d448988e1c3a7b27144440","price":"0.67","side":"SELL","size":"29.05"},{"asset_id":"41448400836309843603620980831210604935021861034693225347475867885462478926555","best_ask":"0.37","best_bid":"0.36","hash":"6a9cb27f2604e7ea57ea6c419387184620959e30","price":"0.33","side":"BUY","size":"29.05"}],"timestamp":"1785122642256"},"payload_hash":"cf708eca0c7dd1fc7478b38c8459c786971ea8cfbc30f91826365284515519fa","raw_frame":"{\"market\":\"0x717c0e8ccd4d5c7040185188fbae28be901ca589a11a94b1b38ca36a79eccfeb\", \"price_changes\":[{\"asset_id\":\"24254094493625419915756280046002869097156693848522361803041977572204227262166\", \"price\":\"0.67\", \"size\":\"29.05\", \"side\":\"SELL\", \"hash\":\"052adf200351177b47d448988e1c3a7b27144440\", \"best_bid\":\"0.63\", \"best_ask\":\"0.64\"}, {\"asset_id\":\"41448400836309843603620980831210604935021861034693225347475867885462478926555\", \"price\":\"0.33\", \"size\":\"29.05\", \"side\":\"BUY\", \"hash\":\"6a9cb27f2604e7ea57ea6c419387184620959e30\", \"best_bid\":\"0.36\", \"best_ask\":\"0.37\"}], \"timestamp\":\"1785122642256\", \"event_type\":\"price_change\"}","received_at":"2026-07-27T03:24:04.395130Z","schema_version":"clob-market-ws.price_change.v1","sequence":null,"server_hash":null,"server_timestamp":"1785122642256","session_id":"dd162b8dca5f43ff811d304e69a06123","source":"clob_market_ws"},"received_at":"2026-07-27T03:24:04.395130Z","record_id":"1d62de047de5194f091877a42b8b92e6caee6dd52ccbc11cdeda1b078e889270","schema_fingerprint":"4aa3821a28b0b7c2400bc59aba4bcc0a76e971dadd19610d3ad38c768e124dc7","schema_version":"edge-lab-recorder.raw.v1","sequence":null,"source":"clob_market_ws"}
{"event_at":"2026-07-27T03:24:02.258000Z","event_fingerprint":"c273562cd6a9a389321796232963dd9d81d6852ca4338b7c650ee8a75f6abfaf","payload":{"connection_id":"c7dc2e4762f849c6b6f9306b6518dcab","event_at":"2026-07-27T03:24:02.258000Z","event_type":"price_change","frame_hash":"01f5dac88778e1704b4212590b3054a6c50fabf014e782b10eb816d9f35aa9c3","frame_index":0,"kind":"data","monotonic_ns":224627756057250,"payload":{"event_type":"price_change","market":"0x717c0e8ccd4d5c7040185188fbae28be901ca589a11a94b1b38ca36a79eccfeb","price_changes":[{"asset_id":"24254094493625419915756280046002869097156693848522361803041977572204227262166","best_ask":"0.64","best_bid":"0.63","hash":"3f45e759f29dc0a5ffd1efb78bf9569431f08f5e","price":"0.65","side":"SELL","size":"9.6"},{"asset_id":"41448400836309843603620980831210604935021861034693225347475867885462478926555","best_ask":"0.37","best_bid":"0.36","hash":"c7c3aa3a376bcaf7ec646dac07b43e044ea16f4c","price":"0.35","side":"BUY","size":"9.6"}],"timestamp":"1785122642258"},"payload_hash":"6ab2b1f27f90e504c02ac4478abb6990a387cbd03749941a2218b9fe2c7c2187","raw_frame":"{\"market\":\"0x717c0e8ccd4d5c7040185188fbae28be901ca589a11a94b1b38ca36a79eccfeb\", \"price_changes\":[{\"asset_id\":\"24254094493625419915756280046002869097156693848522361803041977572204227262166\", \"price\":\"0.65\", \"size\":\"9.6\", \"side\":\"SELL\", \"hash\":\"3f45e759f29dc0a5ffd1efb78bf9569431f08f5e\", \"best_bid\":\"0.63\", \"best_ask\":\"0.64\"}, {\"asset_id\":\"41448400836309843603620980831210604935021861034693225347475867885462478926555\", \"price\":\"0.35\", \"size\":\"9.6\", \"side\":\"BUY\", \"hash\":\"c7c3aa3a376bcaf7ec646dac07b43e044ea16f4c\", \"best_bid\":\"0.36\", \"best_ask\":\"0.37\"}], \"timestamp\":\"1785122642258\", \"event_type\":\"price_change\"}","received_at":"2026-07-27T03:24:04.398232Z","schema_version":"clob-market-ws.price_change.v1","sequence":null,"server_hash":null,"server_timestamp":"1785122642258","session_id":"dd162b8dca5f43ff811d304e69a06123","source":"clob_market_ws"},"received_at":"2026-07-27T03:24:04.398232Z","record_id":"809c93b885f3e7865a83faa9e683b3b56d50e3015db1682aee09651322f5ccfd","schema_fingerprint":"4aa3821a28b0b7c2400bc59aba4bcc0a76e971dadd19610d3ad38c768e124dc7","schema_version":"edge-lab-recorder.raw.v1","sequence":null,"source":"clob_market_ws"}
{"event_at":"2026-07-27T03:24:02.259000Z","event_fingerprint":"fe23f836db27c64199b9b58b62fd47152e33f4e899747aa006af767134147982","payload":{"connection_id":"c7dc2e4762f849c6b6f9306b6518dcab","event_at":"2026-07-27T03:24:02.259000Z","event_type":"price_change","frame_hash":"c68f3011879c0305aa068a0c7b1813f7e168c86e8156bdf8eedf54ed39f5746c","frame_index":0,"kind":"data","monotonic_ns":224627759571250,"payload":{"event_type":"price_change","market":"0x717c0e8ccd4d5c7040185188fbae28be901ca589a11a94b1b38ca36a79eccfeb","price_changes":[{"asset_id":"24254094493625419915756280046002869097156693848522361803041977572204227262166","best_ask":"0.64","best_bid":"0.63","hash":"d14f2324cdbdde8e000a90937ac0e3886d8c500c","price":"0.6","side":"BUY","size":"116"},{"asset_id":"41448400836309843603620980831210604935021861034693225347475867885462478926555","best_ask":"0.37","best_bid":"0.36","hash":"968243b812c9bf7bf7830c32da73de1fbc97a18e","price":"0.4","side":"SELL","size":"116"}],"timestamp":"1785122642259"},"payload_hash":"654490463195470bcd8a5757efc812a7813117de67be8344d082ef15ca30d838","raw_frame":"{\"market\":\"0x717c0e8ccd4d5c7040185188fbae28be901ca589a11a94b1b38ca36a79eccfeb\", \"price_changes\":[{\"asset_id\":\"24254094493625419915756280046002869097156693848522361803041977572204227262166\", \"price\":\"0.6\", \"size\":\"116\", \"side\":\"BUY\", \"hash\":\"d14f2324cdbdde8e000a90937ac0e3886d8c500c\", \"best_bid\":\"0.63\", \"best_ask\":\"0.64\"}, {\"asset_id\":\"41448400836309843603620980831210604935021861034693225347475867885462478926555\", \"price\":\"0.4\", \"size\":\"116\", \"side\":\"SELL\", \"hash\":\"968243b812c9bf7bf7830c32da73de1fbc97a18e\", \"best_bid\":\"0.36\", \"best_ask\":\"0.37\"}], \"timestamp\":\"1785122642259\", \"event_type\":\"price_change\"}","received_at":"2026-07-27T03:24:04.401744Z","schema_version":"clob-market-ws.price_change.v1","sequence":null,"server_hash":null,"server_timestamp":"1785122642259","session_id":"dd162b8dca5f43ff811d304e69a06123","source":"clob_market_ws"},"received_at":"2026-07-27T03:24:04.401744Z","record_id":"d1db2a656de1f99609cd5983389d745f5eefb14f5fdbfa26aa514588bd97f04a","schema_fingerprint":"4aa3821a28b0b7c2400bc59aba4bcc0a76e971dadd19610d3ad38c768e124dc7","schema_version":"edge-lab-recorder.raw.v1","sequence":null,"source":"clob_market_ws"}
{"event_at":"2026-07-27T03:24:02.265000Z","event_fingerprint":"17339db4a8294886066ff4d909eb210b87951abe463807688a230309c27c506d","payload":{"connection_id":"c7dc2e4762f849c6b6f9306b6518dcab","event_at":"2026-07-27T03:24:02.265000Z","event_type":"price_change","frame_hash":"1872349cb1850528d8648bfb95686ab4dc537163c366957344784883ce57974b","frame_index":0,"kind":"data","monotonic_ns":224627762894666,"payload":{"event_type":"price_change","market":"0x717c0e8ccd4d5c7040185188fbae28be901ca589a11a94b1b38ca36a79eccfeb","price_changes":[{"asset_id":"24254094493625419915756280046002869097156693848522361803041977572204227262166","best_ask":"0.64","best_bid":"0.63","hash":"81e23fe17ad44b5e608e8cdcd7aaa0b0176a7b6a","price":"0.61","side":"BUY","size":"109"},{"asset_id":"41448400836309843603620980831210604935021861034693225347475867885462478926555","best_ask":"0.37","best_bid":"0.36","hash":"d4caa844ff9773b42e5b9e4973eb82dfe2c622b0","price":"0.39","side":"SELL","size":"109"}],"timestamp":"1785122642265"},"payload_hash":"529a3775ad0fa8c6fb0ff14b0a74682f4e4f6e21c9f524f7e7da3c068f61bd18","raw_frame":"{\"market\":\"0x717c0e8ccd4d5c7040185188fbae28be901ca589a11a94b1b38ca36a79eccfeb\", \"price_changes\":[{\"asset_id\":\"24254094493625419915756280046002869097156693848522361803041977572204227262166\", \"price\":\"0.61\", \"size\":\"109\", \"side\":\"BUY\", \"hash\":\"81e23fe17ad44b5e608e8cdcd7aaa0b0176a7b6a\", \"best_bid\":\"0.63\", \"best_ask\":\"0.64\"}, {\"asset_id\":\"41448400836309843603620980831210604935021861034693225347475867885462478926555\", \"price\":\"0.39\", \"size\":\"109\", \"side\":\"SELL\", \"hash\":\"d4caa844ff9773b42e5b9e4973eb82dfe2c622b0\", \"best_bid\":\"0.36\", \"best_ask\":\"0.37\"}], \"timestamp\":\"1785122642265\", \"event_type\":\"price_change\"}","received_at":"2026-07-27T03:24:04.405072Z","schema_version":"clob-market-ws.price_change.v1","sequence":null,"server_hash":null,"server_timestamp":"1785122642265","session_id":"dd162b8dca5f43ff811d304e69a06123","source":"clob_market_ws"},"received_at":"2026-07-27T03:24:04.405072Z","record_id":"c869848d28ed033d285e9d263a9131f5774b3bb7b59b06856146b84619713af5","schema_fingerprint":"4aa3821a28b0b7c2400bc59aba4bcc0a76e971dadd19610d3ad38c768e124dc7","schema_version":"edge-lab-recorder.raw.v1","sequence":null,"source":"clob_market_ws"}
{"event_at":"2026-07-27T03:24:02.268000Z","event_fingerprint":"e7b791df3f5d9d41ca6ee30dab55c1f6a232a4bc28858b97c342f089cc7c05e8","payload":{"connection_id":"c7dc2e4762f849c6b6f9306b6518dcab","event_at":"2026-07-27T03:24:02.268000Z","event_type":"price_change","frame_hash":"76ca7d6bad35261e9cc831ca11ddf6a47534030dcc9a2a64c08a304a19593779","frame_index":0,"kind":"data","monotonic_ns":224627765891750,"payload":{"event_type":"price_change","market":"0x717c0e8ccd4d5c7040185188fbae28be901ca589a11a94b1b38ca36a79eccfeb","price_changes":[{"asset_id":"24254094493625419915756280046002869097156693848522361803041977572204227262166","best_ask":"0.64","best_bid":"0.63","hash":"bb1460cc610a3c0a81650b6b4d9081609d7faf44","price":"0.6","side":"BUY","size":"20"},{"asset_id":"41448400836309843603620980831210604935021861034693225347475867885462478926555","best_ask":"0.37","best_bid":"0.36","hash":"0d32a5df3ceba5a06a8e7cbde14b6def1388a132","price":"0.4","side":"SELL","size":"20"}],"timestamp":"1785122642268"},"payload_hash":"870a035582ccb0355cc7da482a409766f935a57c269d8247e7d5a2f7c358b400","raw_frame":"{\"market\":\"0x717c0e8ccd4d5c7040185188fbae28be901ca589a11a94b1b38ca36a79eccfeb\", \"price_changes\":[{\"asset_id\":\"24254094493625419915756280046002869097156693848522361803041977572204227262166\", \"price\":\"0.6\", \"size\":\"20\", \"side\":\"BUY\", \"hash\":\"bb1460cc610a3c0a81650b6b4d9081609d7faf44\", \"best_bid\":\"0.63\", \"best_ask\":\"0.64\"}, {\"asset_id\":\"41448400836309843603620980831210604935021861034693225347475867885462478926555\", \"price\":\"0.4\", \"size\":\"20\", \"side\":\"SELL\", \"hash\":\"0d32a5df3ceba5a06a8e7cbde14b6def1388a132\", \"best_bid\":\"0.36\", \"best_ask\":\"0.37\"}], \"timestamp\":\"1785122642268\", \"event_type\":\"price_change\"}","received_at":"2026-07-27T03:24:04.408070Z","schema_version":"clob-market-ws.price_change.v1","sequence":null,"server_hash":null,"server_timestamp":"1785122642268","session_id":"dd162b8dca5f43ff811d304e69a06123","source":"clob_market_ws"},"received_at":"2026-07-27T03:24:04.408070Z","record_id":"4d18d5487a2314b784c8229dc41d41e5b06e85885c58114f310b458a1ac4cb7c","schema_fingerprint":"4aa3821a28b0b7c2400bc59aba4bcc0a76e971dadd19610d3ad38c768e124dc7","schema_version":"edge-lab-recorder.raw.v1","sequence":null,"source":"clob_market_ws"}
{"event_at":"2026-07-27T03:24:02.275000Z","event_fingerprint":"c28c4af6cf11078a255ce94d224e09fc7b1a793e322d60aa2b14ef03a7896235","payload":{"connection_id":"c7dc2e4762f849c6b6f9306b6518dcab","event_at":"2026-07-27T03:24:02.275000Z","event_type":"price_change","frame_hash":"bd46c988ad250c3ba8af3e56070bebdc95d80322d2100ad049dbedfcf1e48b86","frame_index":0,"kind":"data","monotonic_ns":224627768235791,"payload":{"event_type":"price_change","market":"0x717c0e8ccd4d5c7040185188fbae28be901ca589a11a94b1b38ca36a79eccfeb","price_changes":[{"asset_id":"24254094493625419915756280046002869097156693848522361803041977572204227262166","best_ask":"0.64","best_bid":"0.63","hash":"d6d12ba7ebb6e4a92d72ff009bc8a84ebcf40fd7","price":"0.36","side":"BUY","size":"110.59"},{"asset_id":"41448400836309843603620980831210604935021861034693225347475867885462478926555","best_ask":"0.37","best_bid":"0.36","hash":"161ce3e9b138a535074092a8d16d70c1b803250a","price":"0.64","side":"SELL","size":"110.59"}],"timestamp":"1785122642275"},"payload_hash":"dcf4008a09f7cbbc076d21cdd5d6e7eb60ed3b19e63b6ff61014682158ac5ca8","raw_frame":"{\"market\":\"0x717c0e8ccd4d5c7040185188fbae28be901ca589a11a94b1b38ca36a79eccfeb\", \"price_changes\":[{\"asset_id\":\"24254094493625419915756280046002869097156693848522361803041977572204227262166\", \"price\":\"0.36\", \"size\":\"110.59\", \"side\":\"BUY\", \"hash\":\"d6d12ba7ebb6e4a92d72ff009bc8a84ebcf40fd7\", \"best_bid\":\"0.63\", \"best_ask\":\"0.64\"}, {\"asset_id\":\"41448400836309843603620980831210604935021861034693225347475867885462478926555\", \"price\":\"0.64\", \"size\":\"110.59\", \"side\":\"SELL\", \"hash\":\"161ce3e9b138a535074092a8d16d70c1b803250a\", \"best_bid\":\"0.36\", \"best_ask\":\"0.37\"}], \"timestamp\":\"1785122642275\", \"event_type\":\"price_change\"}","received_at":"2026-07-27T03:24:04.410415Z","schema_version":"clob-market-ws.price_change.v1","sequence":null,"server_hash":null,"server_timestamp":"1785122642275","session_id":"dd162b8dca5f43ff811d304e69a06123","source":"clob_market_ws"},"received_at":"2026-07-27T03:24:04.410415Z","record_id":"e53ad3b682965b8ccd47a5069cbe0dc3f6fa576031fc88577d39149705b0f0d7","schema_fingerprint":"4aa3821a28b0b7c2400bc59aba4bcc0a76e971dadd19610d3ad38c768e124dc7","schema_version":"edge-lab-recorder.raw.v1","sequence":null,"source":"clob_market_ws"}
{"event_at":"2026-07-27T03:24:02.280000Z","event_fingerprint":"65a48cc956de4d9fe2387879eb4630afc64c7e9c990e4f127250e41d6c611de8","payload":{"connection_id":"c7dc2e4762f849c6b6f9306b6518dcab","event_at":"2026-07-27T03:24:02.280000Z","event_type":"price_change","frame_hash":"8a878b43ae9b10ab3b1d22f17bdd61b0e22f69478b346ecc3cade579a3b8b9c0","frame_index":0,"kind":"data","monotonic_ns":224627770966041,"payload":{"event_type":"price_change","market":"0x717c0e8ccd4d5c7040185188fbae28be901ca589a11a94b1b38ca36a79eccfeb","price_changes":[{"asset_id":"24254094493625419915756280046002869097156693848522361803041977572204227262166","best_ask":"0.64","best_bid":"0.63","hash":"3d8827bb7dbc9eecdcde568e1bef14aac58ba4ea","price":"0.36","side":"BUY","size":"18"},{"asset_id":"41448400836309843603620980831210604935021861034693225347475867885462478926555","best_ask":"0.37","best_bid":"0.36","hash":"1e8d4473d557733f707af4f8c3ef0d5c3aae2a89","price":"0.64","side":"SELL","size":"18"}],"timestamp":"1785122642280"},"payload_hash":"ad82732a2a95566b7b9627a4d55ac555db9b55c2b4b4bdf91f8f03acc028b3e6","raw_frame":"{\"market\":\"0x717c0e8ccd4d5c7040185188fbae28be901ca589a11a94b1b38ca36a79eccfeb\", \"price_changes\":[{\"asset_id\":\"24254094493625419915756280046002869097156693848522361803041977572204227262166\", \"price\":\"0.36\", \"size\":\"18\", \"side\":\"BUY\", \"hash\":\"3d8827bb7dbc9eecdcde568e1bef14aac58ba4ea\", \"best_bid\":\"0.63\", \"best_ask\":\"0.64\"}, {\"asset_id\":\"41448400836309843603620980831210604935021861034693225347475867885462478926555\", \"price\":\"0.64\", \"size\":\"18\", \"side\":\"SELL\", \"hash\":\"1e8d4473d557733f707af4f8c3ef0d5c3aae2a89\", \"best_bid\":\"0.36\", \"best_ask\":\"0.37\"}], \"timestamp\":\"1785122642280\", \"event_type\":\"price_change\"}","received_at":"2026-07-27T03:24:04.413144Z","schema_version":"clob-market-ws.price_change.v1","sequence":null,"server_hash":null,"server_timestamp":"1785122642280","session_id":"dd162b8dca5f43ff811d304e69a06123","source":"clob_market_ws"},"received_at":"2026-07-27T03:24:04.413144Z","record_id":"ca2c78db03620cb575eb73a4a7b614b41481aeb24d029ddac2f87f191e20960f","schema_fingerprint":"4aa3821a28b0b7c2400bc59aba4bcc0a76e971dadd19610d3ad38c768e124dc7","schema_version":"edge-lab-recorder.raw.v1","sequence":null,"source":"clob_market_ws"}
{"event_at":"2026-07-27T03:24:02.281000Z","event_fingerprint":"d5d2cc90e84619a5a6fd93c9ddc26643f971f14a9c9d0b8fb3cbad5b9654bf6a","payload":{"connection_id":"c7dc2e4762f849c6b6f9306b6518dcab","event_at":"2026-07-27T03:24:02.281000Z","event_type":"price_change","frame_hash":"32368121e2a5973acaee15368670dc82eafbeb13f96fb7e0fad508f7ca3cf94a","frame_index":0,"kind":"data","monotonic_ns":224627774033000,"payload":{"event_type":"price_change","market":"0x717c0e8ccd4d5c7040185188fbae28be901ca589a11a94b1b38ca36a79eccfeb","price_changes":[{"asset_id":"24254094493625419915756280046002869097156693848522361803041977572204227262166","best_ask":"0.64","best_bid":"0.63","hash":"775565d1a31a68bde6e3c51498e5198e64034aa7","price":"0.01","side":"BUY","size":"5453.02"},{"asset_id":"41448400836309843603620980831210604935021861034693225347475867885462478926555","best_ask":"0.37","best_bid":"0.36","hash":"77e69dfb33760764c4f78ae7145d8c9f00704cd9","price":"0.99","side":"SELL","size":"5453.02"}],"timestamp":"1785122642281"},"payload_hash":"f5b8292a3531be8ce79bb29d2e45650edfe74768e1041847c845f3f357dd51ac","raw_frame":"{\"market\":\"0x717c0e8ccd4d5c7040185188fbae28be901ca589a11a94b1b38ca36a79eccfeb\", \"price_changes\":[{\"asset_id\":\"24254094493625419915756280046002869097156693848522361803041977572204227262166\", \"price\":\"0.01\", \"size\":\"5453.02\", \"side\":\"BUY\", \"hash\":\"775565d1a31a68bde6e3c51498e5198e64034aa7\", \"best_bid\":\"0.63\", \"best_ask\":\"0.64\"}, {\"asset_id\":\"41448400836309843603620980831210604935021861034693225347475867885462478926555\", \"price\":\"0.99\", \"size\":\"5453.02\", \"side\":\"SELL\", \"hash\":\"77e69dfb33760764c4f78ae7145d8c9f00704cd9\", \"best_bid\":\"0.36\", \"best_ask\":\"0.37\"}], \"timestamp\":\"1785122642281\", \"event_type\":\"price_change\"}","received_at":"2026-07-27T03:24:04.416212Z","schema_version":"clob-market-ws.price_change.v1","sequence":null,"server_hash":null,"server_timestamp":"1785122642281","session_id":"dd162b8dca5f43ff811d304e69a06123","source":"clob_market_ws"},"received_at":"2026-07-27T03:24:04.416212Z","record_id":"24aade6bd5ab81f85a03ae9851f6ed59154aa5fd42ad8dd5f203d5125ed05751","schema_fingerprint":"4aa3821a28b0b7c2400bc59aba4bcc0a76e971dadd19610d3ad38c768e124dc7","schema_version":"edge-lab-recorder.raw.v1","sequence":null,"source":"clob_market_ws"}
{"event_at":"2026-07-27T03:24:02.282000Z","event_fingerprint":"a354f36676ce00025f193e839581f8fdd637b7c0a4430d033ba2a52c48933767","payload":{"connection_id":"c7dc2e4762f849c6b6f9306b6518dcab","event_at":"2026-07-27T03:24:02.282000Z","event_type":"price_change","frame_hash":"39aa684ab0d5942d818d06cde168cc72b5a7cd3ea686e6678d6d9aa7d2c1dfeb","frame_index":0,"kind":"data","monotonic_ns":224627776325500,"payload":{"event_type":"price_change","market":"0x717c0e8ccd4d5c7040185188fbae28be901ca589a11a94b1b38ca36a79eccfeb","price_changes":[{"asset_id":"24254094493625419915756280046002869097156693848522361803041977572204227262166","best_ask":"0.64","best_bid":"0.63","hash":"20e5f3df0d3646cdafd89cea2641c54254965d77","price":"0.03","side":"BUY","size":"613.1"},{"asset_id":"41448400836309843603620980831210604935021861034693225347475867885462478926555","best_ask":"0.37","best_bid":"0.36","hash":"e47b23b5fc4fcd075951432f3333cb24569dd1e0","price":"0.97","side":"SELL","size":"613.1"}],"timestamp":"1785122642282"},"payload_hash":"b57c6ef8de6ac5abbc07ab5643cbe055b7f36fb78cef38a9352df19aebab3aa7","raw_frame":"{\"market\":\"0x717c0e8ccd4d5c7040185188fbae28be901ca589a11a94b1b38ca36a79eccfeb\", \"price_changes\":[{\"asset_id\":\"24254094493625419915756280046002869097156693848522361803041977572204227262166\", \"price\":\"0.03\", \"size\":\"613.1\", \"side\":\"BUY\", \"hash\":\"20e5f3df0d3646cdafd89cea2641c54254965d77\", \"best_bid\":\"0.63\", \"best_ask\":\"0.64\"}, {\"asset_id\":\"41448400836309843603620980831210604935021861034693225347475867885462478926555\", \"price\":\"0.97\", \"size\":\"613.1\", \"side\":\"SELL\", \"hash\":\"e47b23b5fc4fcd075951432f3333cb24569dd1e0\", \"best_bid\":\"0.36\", \"best_ask\":\"0.37\"}], \"timestamp\":\"1785122642282\", \"event_type\":\"price_change\"}","received_at":"2026-07-27T03:24:04.418503Z","schema_version":"clob-market-ws.price_change.v1","sequence":null,"server_hash":null,"server_timestamp":"1785122642282","session_id":"dd162b8dca5f43ff811d304e69a06123","source":"clob_market_ws"},"received_at":"2026-07-27T03:24:04.418503Z","record_id":"ea7b81e1f30ada7cee272ba46932c2aa8a3c01b450dd05cd16e479f71298ca88","schema_fingerprint":"4aa3821a28b0b7c2400bc59aba4bcc0a76e971dadd19610d3ad38c768e124dc7","schema_version":"edge-lab-recorder.raw.v1","sequence":null,"source":"clob_market_ws"}
{"event_at":"2026-07-27T03:24:02.338000Z","event_fingerprint":"1e752fe6261ae27a36e734d7faab471a08b3f1da35cc6056e08154f1a3c0d23b","payload":{"connection_id":"c7dc2e4762f849c6b6f9306b6518dcab","event_at":"2026-07-27T03:24:02.338000Z","event_type":"price_change","frame_hash":"fe34418b8c78cf4e7a260c1919207e936ac19ca2c09258b9a06826fc9e429a21","frame_index":0,"kind":"data","monotonic_ns":224627779486041,"payload":{"event_type":"price_change","market":"0x717c0e8ccd4d5c7040185188fbae28be901ca589a11a94b1b38ca36a79eccfeb","price_changes":[{"asset_id":"24254094493625419915756280046002869097156693848522361803041977572204227262166","best_ask":"0.64","best_bid":"0.63","hash":"f450d6a174e1f808c3ffa2a7898028b402eef9c5","price":"0.6","side":"BUY","size":"290"},{"asset_id":"41448400836309843603620980831210604935021861034693225347475867885462478926555","best_ask":"0.37","best_bid":"0.36","hash":"fe655e8807d4fa5cdbf3388c070b59f628a8ffa9","price":"0.4","side":"SELL","size":"290"}],"timestamp":"1785122642338"},"payload_hash":"dfccc8de481ea1789bd14388c6d498a7894742962e201947bdc2bc4f2b4d49c9","raw_frame":"{\"market\":\"0x717c0e8ccd4d5c7040185188fbae28be901ca589a11a94b1b38ca36a79eccfeb\", \"price_changes\":[{\"asset_id\":\"24254094493625419915756280046002869097156693848522361803041977572204227262166\", \"price\":\"0.6\", \"size\":\"290\", \"side\":\"BUY\", \"hash\":\"f450d6a174e1f808c3ffa2a7898028b402eef9c5\", \"best_bid\":\"0.63\", \"best_ask\":\"0.64\"}, {\"asset_id\":\"41448400836309843603620980831210604935021861034693225347475867885462478926555\", \"price\":\"0.4\", \"size\":\"290\", \"side\":\"SELL\", \"hash\":\"fe655e8807d4fa5cdbf3388c070b59f628a8ffa9\", \"best_bid\":\"0.36\", \"best_ask\":\"0.37\"}], \"timestamp\":\"1785122642338\", \"event_type\":\"price_change\"}","received_at":"2026-07-27T03:24:04.421664Z","schema_version":"clob-market-ws.price_change.v1","sequence":null,"server_hash":null,"server_timestamp":"1785122642338","session_id":"dd162b8dca5f43ff811d304e69a06123","source":"clob_market_ws"},"received_at":"2026-07-27T03:24:04.421664Z","record_id":"bda1a5442d601f36fc161cb79a714e9f75954ba12c2c4a8098585ace97c65ca9","schema_fingerprint":"4aa3821a28b0b7c2400bc59aba4bcc0a76e971dadd19610d3ad38c768e124dc7","schema_version":"edge-lab-recorder.raw.v1","sequence":null,"source":"clob_market_ws"}
{"event_at":"2026-07-27T03:24:02.345000Z","event_fingerprint":"81e10760b39c27d2096a150887736a2ed399b2b79361ee0ab40f9407667d874a","payload":{"connection_id":"c7dc2e4762f849c6b6f9306b6518dcab","event_at":"2026-07-27T03:24:02.345000Z","event_type":"price_change","frame_hash":"e17fe441445667b8b08f0bda133990e4aec84787bd049939233a6b4360a31c00","frame_index":0,"kind":"data","monotonic_ns":224627783090041,"payload":{"event_type":"price_change","market":"0x717c0e8ccd4d5c7040185188fbae28be901ca589a11a94b1b38ca36a79eccfeb","price_changes":[{"asset_id":"41448400836309843603620980831210604935021861034693225347475867885462478926555","best_ask":"0.37","best_bid":"0.36","hash":"bea7301bcfa78b4d6c84039ee0e886eed946c369","price":"0.23","side":"BUY","size":"45.89"},{"asset_id":"24254094493625419915756280046002869097156693848522361803041977572204227262166","best_ask":"0.64","best_bid":"0.63","hash":"7d121674e3b0e428494666ca02bbfd5421f61dbb","price":"0.77","side":"SELL","size":"45.89"}],"timestamp":"1785122642345"},"payload_hash":"a4efc5bc4a760e0ec4743670a5f525f55470199f324d6214a5e904ba53588831","raw_frame":"{\"market\":\"0x717c0e8ccd4d5c7040185188fbae28be901ca589a11a94b1b38ca36a79eccfeb\", \"price_changes\":[{\"asset_id\":\"41448400836309843603620980831210604935021861034693225347475867885462478926555\", \"price\":\"0.23\", \"size\":\"45.89\", \"side\":\"BUY\", \"hash\":\"bea7301bcfa78b4d6c84039ee0e886eed946c369\", \"best_bid\":\"0.36\", \"best_ask\":\"0.37\"}, {\"asset_id\":\"24254094493625419915756280046002869097156693848522361803041977572204227262166\", \"price\":\"0.77\", \"size\":\"45.89\", \"side\":\"SELL\", \"hash\":\"7d121674e3b0e428494666ca02bbfd5421f61dbb\", \"best_bid\":\"0.63\", \"best_ask\":\"0.64\"}], \"timestamp\":\"1785122642345\", \"event_type\":\"price_change\"}","received_at":"2026-07-27T03:24:04.425266Z","schema_version":"clob-market-ws.price_change.v1","sequence":null,"server_hash":null,"server_timestamp":"1785122642345","session_id":"dd162b8dca5f43ff811d304e69a06123","source":"clob_market_ws"},"received_at":"2026-07-27T03:24:04.425266Z","record_id":"18fbc35a823a860c3fef51c18257a7d686747f15bb9ae76524f7e02d30c6c99d","schema_fingerprint":"4aa3821a28b0b7c2400bc59aba4bcc0a76e971dadd19610d3ad38c768e124dc7","schema_version":"edge-lab-recorder.raw.v1","sequence":null,"source":"clob_market_ws"}
{"event_at":"2026-07-27T03:24:02.360000Z","event_fingerprint":"de9889c09ef7b40f502bb7843b34a675a6de6068dd9f78072fae47944bb3c2b8","payload":{"connection_id":"c7dc2e4762f849c6b6f9306b6518dcab","event_at":"2026-07-27T03:24:02.360000Z","event_type":"price_change","frame_hash":"a95259d9a96dc90081ee028f469d7aa29aa7f57bd62e97ae0bf110fafc0048fd","frame_index":0,"kind":"data","monotonic_ns":224627786086416,"payload":{"event_type":"price_change","market":"0x717c0e8ccd4d5c7040185188fbae28be901ca589a11a94b1b38ca36a79eccfeb","price_changes":[{"asset_id":"41448400836309843603620980831210604935021861034693225347475867885462478926555","best_ask":"0.37","best_bid":"0.36","hash":"37f43486e1580ccde1e2b48dc77a8487c97bfbdc","price":"0.33","side":"BUY","size":"23.46"},{"asset_id":"24254094493625419915756280046002869097156693848522361803041977572204227262166","best_ask":"0.64","best_bid":"0.63","hash":"6a1c98256641bae73ed93bdeb3cb122391558c4c","price":"0.67","side":"SELL","size":"23.46"}],"timestamp":"1785122642360"},"payload_hash":"d9f99aa90a87008504735b681ea5d5800e9dce5543e643da82c989390fd5d9bb","raw_frame":"{\"market\":\"0x717c0e8ccd4d5c7040185188fbae28be901ca589a11a94b1b38ca36a79eccfeb\", \"price_changes\":[{\"asset_id\":\"41448400836309843603620980831210604935021861034693225347475867885462478926555\", \"price\":\"0.33\", \"size\":\"23.46\", \"side\":\"BUY\", \"hash\":\"37f43486e1580ccde1e2b48dc77a8487c97bfbdc\", \"best_bid\":\"0.36\", \"best_ask\":\"0.37\"}, {\"asset_id\":\"24254094493625419915756280046002869097156693848522361803041977572204227262166\", \"price\":\"0.67\", \"size\":\"23.46\", \"side\":\"SELL\", \"hash\":\"6a1c98256641bae73ed93bdeb3cb122391558c4c\", \"best_bid\":\"0.63\", \"best_ask\":\"0.64\"}], \"timestamp\":\"1785122642360\", \"event_type\":\"price_change\"}","received_at":"2026-07-27T03:24:04.428264Z","schema_version":"clob-market-ws.price_change.v1","sequence":null,"server_hash":null,"server_timestamp":"1785122642360","session_id":"dd162b8dca5f43ff811d304e69a06123","source":"clob_market_ws"},"received_at":"2026-07-27T03:24:04.428264Z","record_id":"da5de75e63a7dad41d3573788733bf544b6ce02735dcc5699418bd5bd9731509","schema_fingerprint":"4aa3821a28b0b7c2400bc59aba4bcc0a76e971dadd19610d3ad38c768e124dc7","schema_version":"edge-lab-recorder.raw.v1","sequence":null,"source":"clob_market_ws"}
{"event_at":"2026-07-27T03:24:02.362000Z","event_fingerprint":"62f1d7171c0b492e0e7982e6ee79244d6a6498cbfc1ae88635928aab73e3c577","payload":{"connection_id":"c7dc2e4762f849c6b6f9306b6518dcab","event_at":"2026-07-27T03:24:02.362000Z","event_type":"price_change","frame_hash":"388c1f47572616f5dbe0a032d211cb463a3c0868f43827437d6b845dac56b750","frame_index":0,"kind":"data","monotonic_ns":224627789074625,"payload":{"event_type":"price_change","market":"0x717c0e8ccd4d5c7040185188fbae28be901ca589a11a94b1b38ca36a79eccfeb","price_changes":[{"asset_id":"41448400836309843603620980831210604935021861034693225347475867885462478926555","best_ask":"0.37","best_bid":"0.36","hash":"60bcd56df1ed84323ca4647c6f8c9c8005fc5824","price":"0.36","side":"BUY","size":"291.25"},{"asset_id":"24254094493625419915756280046002869097156693848522361803041977572204227262166","best_ask":"0.64","best_bid":"0.63","hash":"6a24e2abbe316a7808b303e010f47b85de90d5e3","price":"0.64","side":"SELL","size":"291.25"}],"timestamp":"1785122642362"},"payload_hash":"41d7e0752caf9f8872c28d694b64afa5bb18e347a656d542a5421194efb9c392","raw_frame":"{\"market\":\"0x717c0e8ccd4d5c7040185188fbae28be901ca589a11a94b1b38ca36a79eccfeb\", \"price_changes\":[{\"asset_id\":\"41448400836309843603620980831210604935021861034693225347475867885462478926555\", \"price\":\"0.36\", \"size\":\"291.25\", \"side\":\"BUY\", \"hash\":\"60bcd56df1ed84323ca4647c6f8c9c8005fc5824\", \"best_bid\":\"0.36\", \"best_ask\":\"0.37\"}, {\"asset_id\":\"24254094493625419915756280046002869097156693848522361803041977572204227262166\", \"price\":\"0.64\", \"size\":\"291.25\", \"side\":\"SELL\", \"hash\":\"6a24e2abbe316a7808b303e010f47b85de90d5e3\", \"best_bid\":\"0.63\", \"best_ask\":\"0.64\"}], \"timestamp\":\"1785122642362\", \"event_type\":\"price_change\"}","received_at":"2026-07-27T03:24:04.431253Z","schema_version":"clob-market-ws.price_change.v1","sequence":null,"server_hash":null,"server_timestamp":"1785122642362","session_id":"dd162b8dca5f43ff811d304e69a06123","source":"clob_market_ws"},"received_at":"2026-07-27T03:24:04.431253Z","record_id":"b11f0101720daa83870f84e8e0d511b446b70dd0c2cc0a42f8e3b54e58cbf3f2","schema_fingerprint":"4aa3821a28b0b7c2400bc59aba4bcc0a76e971dadd19610d3ad38c768e124dc7","schema_version":"edge-lab-recorder.raw.v1","sequence":null,"source":"clob_market_ws"}
{"event_at":"2026-07-27T03:24:02.363000Z","event_fingerprint":"dd83da011287e0e9de02790704ed42ffedcf0467f443965d9f23f33b531a8cd7","payload":{"connection_id":"c7dc2e4762f849c6b6f9306b6518dcab","event_at":"2026-07-27T03:24:02.363000Z","event_type":"price_change","frame_hash":"439c99989a370f24efca7f4fd6a8668e6265d463927a412f63f5135617785662","frame_index":0,"kind":"data","monotonic_ns":224627792193083,"payload":{"event_type":"price_change","market":"0x717c0e8ccd4d5c7040185188fbae28be901ca589a11a94b1b38ca36a79eccfeb","price_changes":[{"asset_id":"24254094493625419915756280046002869097156693848522361803041977572204227262166","best_ask":"0.64","best_bid":"0.63","hash":"71ce747c9664fd90ba8db2d956f302d04154e193","price":"0.64","side":"SELL","size":"286.25"},{"asset_id":"41448400836309843603620980831210604935021861034693225347475867885462478926555","best_ask":"0.37","best_bid":"0.36","hash":"65214ee683d5bbcd072f7568fe1e6e19650daf80","price":"0.36","side":"BUY","size":"286.25"}],"timestamp":"1785122642363"},"payload_hash":"ca4298a430aa371dc78ae3b1fce2017045c6a01417f3f4ee1cf4093081e48ae6","raw_frame":"{\"market\":\"0x717c0e8ccd4d5c7040185188fbae28be901ca589a11a94b1b38ca36a79eccfeb\", \"price_changes\":[{\"asset_id\":\"24254094493625419915756280046002869097156693848522361803041977572204227262166\", \"price\":\"0.64\", \"size\":\"286.25\", \"side\":\"SELL\", \"hash\":\"71ce747c9664fd90ba8db2d956f302d04154e193\", \"best_bid\":\"0.63\", \"best_ask\":\"0.64\"}, {\"asset_id\":\"41448400836309843603620980831210604935021861034693225347475867885462478926555\", \"price\":\"0.36\", \"size\":\"286.25\", \"side\":\"BUY\", \"hash\":\"65214ee683d5bbcd072f7568fe1e6e19650daf80\", \"best_bid\":\"0.36\", \"best_ask\":\"0.37\"}], \"timestamp\":\"1785122642363\", \"event_type\":\"price_change\"}","received_at":"2026-07-27T03:24:04.434371Z","schema_version":"clob-market-ws.price_change.v1","sequence":null,"server_hash":null,"server_timestamp":"1785122642363","session_id":"dd162b8dca5f43ff811d304e69a06123","source":"clob_market_ws"},"received_at":"2026-07-27T03:24:04.434371Z","record_id":"625b30e7becb9741939c543c2ceedd095be25e92dcaef6b0cff35b3da5a6c5d3","schema_fingerprint":"4aa3821a28b0b7c2400bc59aba4bcc0a76e971dadd19610d3ad38c768e124dc7","schema_version":"edge-lab-recorder.raw.v1","sequence":null,"source":"clob_market_ws"}
{"event_at":"2026-07-27T03:24:02.363000Z","event_fingerprint":"2d6efa4c0491730991d1ca0d64a6db051aae07b2bcd98318abaa79993958ff5f","payload":{"connection_id":"c7dc2e4762f849c6b6f9306b6518dcab","event_at":"2026-07-27T03:24:02.363000Z","event_type":"price_change","frame_hash":"0ba92cb80799aeebc8fca6232cb378d1376bb381d124840e8c540809db6b1b8e","frame_index":0,"kind":"data","monotonic_ns":224627795506291,"payload":{"event_type":"price_change","market":"0x717c0e8ccd4d5c7040185188fbae28be901ca589a11a94b1b38ca36a79eccfeb","price_changes":[{"asset_id":"24254094493625419915756280046002869097156693848522361803041977572204227262166","best_ask":"0.64","best_bid":"0.63","hash":"5dc2f4215d311be591fb0aec90d773bb4f91b76f","price":"0.67","side":"SELL","size":"29.46"},{"asset_id":"41448400836309843603620980831210604935021861034693225347475867885462478926555","best_ask":"0.37","best_bid":"0.36","hash":"3cd5bbffc8c57abde36f3f934a423e8b6340da2c","price":"0.33","side":"BUY","size":"29.46"}],"timestamp":"1785122642363"},"payload_hash":"408d7d9dd65a9144d4966394f3df73c21ee7628080e3878958030fc7fb9b59e9","raw_frame":"{\"market\":\"0x717c0e8ccd4d5c7040185188fbae28be901ca589a11a94b1b38ca36a79eccfeb\", \"price_changes\":[{\"asset_id\":\"24254094493625419915756280046002869097156693848522361803041977572204227262166\", \"price\":\"0.67\", \"size\":\"29.46\", \"side\":\"SELL\", \"hash\":\"5dc2f4215d311be591fb0aec90d773bb4f91b76f\", \"best_bid\":\"0.63\", \"best_ask\":\"0.64\"}, {\"asset_id\":\"41448400836309843603620980831210604935021861034693225347475867885462478926555\", \"price\":\"0.33\", \"size\":\"29.46\", \"side\":\"BUY\", \"hash\":\"3cd5bbffc8c57abde36f3f934a423e8b6340da2c\", \"best_bid\":\"0.36\", \"best_ask\":\"0.37\"}], \"timestamp\":\"1785122642363\", \"event_type\":\"price_change\"}","received_at":"2026-07-27T03:24:04.437684Z","schema_version":"clob-market-ws.price_change.v1","sequence":null,"server_hash":null,"server_timestamp":"1785122642363","session_id":"dd162b8dca5f43ff811d304e69a06123","source":"clob_market_ws"},"received_at":"2026-07-27T03:24:04.437684Z","record_id":"c2047cfd55e2d41f2057d51c7524912840d69358c615e498f39ee00364411f4e","schema_fingerprint":"4aa3821a28b0b7c2400bc59aba4bcc0a76e971dadd19610d3ad38c768e124dc7","schema_version":"edge-lab-recorder.raw.v1","sequence":null,"source":"clob_market_ws"}
{"event_at":"2026-07-27T03:24:02.366000Z","event_fingerprint":"8c4052bf9feb4d447df66d5e80d452a77702a4f4e6f87eb7c8807a9b94f29333","payload":{"connection_id":"c7dc2e4762f849c6b6f9306b6518dcab","event_at":"2026-07-27T03:24:02.366000Z","event_type":"price_change","frame_hash":"e860906960a05cf7b627fdaa681a8fd423b59a1dbf0cbb11dbf36bd2e269cf52","frame_index":0,"kind":"data","monotonic_ns":224627798572125,"payload":{"event_type":"price_change","market":"0x717c0e8ccd4d5c7040185188fbae28be901ca589a11a94b1b38ca36a79eccfeb","price_changes":[{"asset_id":"24254094493625419915756280046002869097156693848522361803041977572204227262166","best_ask":"0.64","best_bid":"0.63","hash":"85457a6193c4ac48e1eabf77a75a475a9817e282","price":"0.02","side":"BUY","size":"688.1"},{"asset_id":"41448400836309843603620980831210604935021861034693225347475867885462478926555","best_ask":"0.37","best_bid":"0.36","hash":"bab201508f816f8bbd862e987e19f2583c7bc6fd","price":"0.98","side":"SELL","size":"688.1"}],"timestamp":"1785122642366"},"payload_hash":"4cc1aa9db8211fb6c6c5c36441a4feb3c0a585dab2108976269cab4bd201be45","raw_frame":"{\"market\":\"0x717c0e8ccd4d5c7040185188fbae28be901ca589a11a94b1b38ca36a79eccfeb\", \"price_changes\":[{\"asset_id\":\"24254094493625419915756280046002869097156693848522361803041977572204227262166\", \"price\":\"0.02\", \"size\":\"688.1\", \"side\":\"BUY\", \"hash\":\"85457a6193c4ac48e1eabf77a75a475a9817e282\", \"best_bid\":\"0.63\", \"best_ask\":\"0.64\"}, {\"asset_id\":\"41448400836309843603620980831210604935021861034693225347475867885462478926555\", \"price\":\"0.98\", \"size\":\"688.1\", \"side\":\"SELL\", \"hash\":\"bab201508f816f8bbd862e987e19f2583c7bc6fd\", \"best_bid\":\"0.36\", \"best_ask\":\"0.37\"}], \"timestamp\":\"1785122642366\", \"event_type\":\"price_change\"}","received_at":"2026-07-27T03:24:04.440750Z","schema_version":"clob-market-ws.price_change.v1","sequence":null,"server_hash":null,"server_timestamp":"1785122642366","session_id":"dd162b8dca5f43ff811d304e69a06123","source":"clob_market_ws"},"received_at":"2026-07-27T03:24:04.440750Z","record_id":"c9b8d9c58adc9c2e993e84ac1edd9abb48f718383bbed95700dfa83759e5aefe","schema_fingerprint":"4aa3821a28b0b7c2400bc59aba4bcc0a76e971dadd19610d3ad38c768e124dc7","schema_version":"edge-lab-recorder.raw.v1","sequence":null,"source":"clob_market_ws"}
{"event_at":"2026-07-27T03:24:02.380000Z","event_fingerprint":"5ec35166d24b025996c1ee2eb440bde1442c3bfa9787d8c17fa952634a629970","payload":{"connection_id":"c7dc2e4762f849c6b6f9306b6518dcab","event_at":"2026-07-27T03:24:02.380000Z","event_type":"price_change","frame_hash":"839b078338c1199da95e49006956fa73817c17dd5ea6e03b09d7fba66852ecb3","frame_index":0,"kind":"data","monotonic_ns":224627801491541,"payload":{"event_type":"price_change","market":"0x717c0e8ccd4d5c7040185188fbae28be901ca589a11a94b1b38ca36a79eccfeb","price_changes":[{"asset_id":"24254094493625419915756280046002869097156693848522361803041977572204227262166","best_ask":"0.64","best_bid":"0.63","hash":"d087df5d05c233ea5c31b137d1d387204ac48f1c","price":"0.42","side":"BUY","size":"96.66"},{"asset_id":"41448400836309843603620980831210604935021861034693225347475867885462478926555","best_ask":"0.37","best_bid":"0.36","hash":"da4ed3685f470f14beab493aecd967912cd4deba","price":"0.58","side":"SELL","size":"96.66"}],"timestamp":"1785122642380"},"payload_hash":"e004ec3c6a4bdca78110f922bce189c5522381a1a95a445bb99ec0bdabaad5ff","raw_frame":"{\"market\":\"0x717c0e8ccd4d5c7040185188fbae28be901ca589a11a94b1b38ca36a79eccfeb\", \"price_changes\":[{\"asset_id\":\"24254094493625419915756280046002869097156693848522361803041977572204227262166\", \"price\":\"0.42\", \"size\":\"96.66\", \"side\":\"BUY\", \"hash\":\"d087df5d05c233ea5c31b137d1d387204ac48f1c\", \"best_bid\":\"0.63\", \"best_ask\":\"0.64\"}, {\"asset_id\":\"41448400836309843603620980831210604935021861034693225347475867885462478926555\", \"price\":\"0.58\", \"size\":\"96.66\", \"side\":\"SELL\", \"hash\":\"da4ed3685f470f14beab493aecd967912cd4deba\", \"best_bid\":\"0.36\", \"best_ask\":\"0.37\"}], \"timestamp\":\"1785122642380\", \"event_type\":\"price_change\"}","received_at":"2026-07-27T03:24:04.443666Z","schema_version":"clob-market-ws.price_change.v1","sequence":null,"server_hash":null,"server_timestamp":"1785122642380","session_id":"dd162b8dca5f43ff811d304e69a06123","source":"clob_market_ws"},"received_at":"2026-07-27T03:24:04.443666Z","record_id":"87c454dea0ef3dfcf301e204e3d3a4e49dfb9810b6f3a5f9ffd0d1231834c1ee","schema_fingerprint":"4aa3821a28b0b7c2400bc59aba4bcc0a76e971dadd19610d3ad38c768e124dc7","schema_version":"edge-lab-recorder.raw.v1","sequence":null,"source":"clob_market_ws"}
{"event_at":"2026-07-27T03:24:02.417000Z","event_fingerprint":"61b88f645a65d62791362056ffddd8de30765fcdb40a4f5d8b0dc4ffb1c541d0","payload":{"connection_id":"c7dc2e4762f849c6b6f9306b6518dcab","event_at":"2026-07-27T03:24:02.417000Z","event_type":"price_change","frame_hash":"fe29a46177286bf4e2252821fed8ecc442370b0d47eb984e278c28a33a80198f","frame_index":0,"kind":"data","monotonic_ns":224627804600625,"payload":{"event_type":"price_change","market":"0x717c0e8ccd4d5c7040185188fbae28be901ca589a11a94b1b38ca36a79eccfeb","price_changes":[{"asset_id":"24254094493625419915756280046002869097156693848522361803041977572204227262166","best_ask":"0.64","best_bid":"0.63","hash":"cb55a7644fc414abb11b5f1bdedacd06795daab0","price":"0.02","side":"BUY","size":"683.1"},{"asset_id":"41448400836309843603620980831210604935021861034693225347475867885462478926555","best_ask":"0.37","best_bid":"0.36","hash":"ecd6deb362ee639f6bf2d3bf89ea9dbd9b449c0f","price":"0.98","side":"SELL","size":"683.1"}],"timestamp":"1785122642417"},"payload_hash":"2829007b1373b7b421273cd1e9a603899f9a536eacf780d6248daec19d7f8d35","raw_frame":"{\"market\":\"0x717c0e8ccd4d5c7040185188fbae28be901ca589a11a94b1b38ca36a79eccfeb\", \"price_changes\":[{\"asset_id\":\"24254094493625419915756280046002869097156693848522361803041977572204227262166\", \"price\":\"0.02\", \"size\":\"683.1\", \"side\":\"BUY\", \"hash\":\"cb55a7644fc414abb11b5f1bdedacd06795daab0\", \"best_bid\":\"0.63\", \"best_ask\":\"0.64\"}, {\"asset_id\":\"41448400836309843603620980831210604935021861034693225347475867885462478926555\", \"price\":\"0.98\", \"size\":\"683.1\", \"side\":\"SELL\", \"hash\":\"ecd6deb362ee639f6bf2d3bf89ea9dbd9b449c0f\", \"best_bid\":\"0.36\", \"best_ask\":\"0.37\"}], \"timestamp\":\"1785122642417\", \"event_type\":\"price_change\"}","received_at":"2026-07-27T03:24:04.446776Z","schema_version":"clob-market-ws.price_change.v1","sequence":null,"server_hash":null,"server_timestamp":"1785122642417","session_id":"dd162b8dca5f43ff811d304e69a06123","source":"clob_market_ws"},"received_at":"2026-07-27T03:24:04.446776Z","record_id":"b494e4269a0d1a795b8c9784d75443521456db570f8c71a311432cb197c97c78","schema_fingerprint":"4aa3821a28b0b7c2400bc59aba4bcc0a76e971dadd19610d3ad38c768e124dc7","schema_version":"edge-lab-recorder.raw.v1","sequence":null,"source":"clob_market_ws"}
{"event_at":"2026-07-27T03:24:02.448000Z","event_fingerprint":"d6b9db87842f5401b419f30fa7210943a0d535fcf96caa36211700f9a9365b2e","payload":{"connection_id":"c7dc2e4762f849c6b6f9306b6518dcab","event_at":"2026-07-27T03:24:02.448000Z","event_type":"price_change","frame_hash":"a116ad9863ee950ec7045cc7b7b1ca81aad3d1c5470d24eaca476236066a3f36","frame_index":0,"kind":"data","monotonic_ns":224627806710958,"payload":{"event_type":"price_change","market":"0x717c0e8ccd4d5c7040185188fbae28be901ca589a11a94b1b38ca36a79eccfeb","price_changes":[{"asset_id":"41448400836309843603620980831210604935021861034693225347475867885462478926555","best_ask":"0.37","best_bid":"0.36","hash":"e25a72137db7b50167f38ff2e0f2e4a624266d3d","price":"0.34","side":"BUY","size":"31.88"},{"asset_id":"24254094493625419915756280046002869097156693848522361803041977572204227262166","best_ask":"0.64","best_bid":"0.63","hash":"63bb76ab56dbec87ebd7bfc112e365e49045436c","price":"0.66","side":"SELL","size":"31.88"}],"timestamp":"1785122642448"},"payload_hash":"904e1ee15ce56100e54d890a7368bdde5ea903b38002a0ec4a3634bc048a4696","raw_frame":"{\"market\":\"0x717c0e8ccd4d5c7040185188fbae28be901ca589a11a94b1b38ca36a79eccfeb\", \"price_changes\":[{\"asset_id\":\"41448400836309843603620980831210604935021861034693225347475867885462478926555\", \"price\":\"0.34\", \"size\":\"31.88\", \"side\":\"BUY\", \"hash\":\"e25a72137db7b50167f38ff2e0f2e4a624266d3d\", \"best_bid\":\"0.36\", \"best_ask\":\"0.37\"}, {\"asset_id\":\"24254094493625419915756280046002869097156693848522361803041977572204227262166\", \"price\":\"0.66\", \"size\":\"31.88\", \"side\":\"SELL\", \"hash\":\"63bb76ab56dbec87ebd7bfc112e365e49045436c\", \"best_bid\":\"0.63\", \"best_ask\":\"0.64\"}], \"timestamp\":\"1785122642448\", \"event_type\":\"price_change\"}","received_at":"2026-07-27T03:24:04.448889Z","schema_version":"clob-market-ws.price_change.v1","sequence":null,"server_hash":null,"server_timestamp":"1785122642448","session_id":"dd162b8dca5f43ff811d304e69a06123","source":"clob_market_ws"},"received_at":"2026-07-27T03:24:04.448889Z","record_id":"165ebf83eb6474f69ca8b2bab1d041f7a64406c19aa42c7f21dbbd03786e87ec","schema_fingerprint":"4aa3821a28b0b7c2400bc59aba4bcc0a76e971dadd19610d3ad38c768e124dc7","schema_version":"edge-lab-recorder.raw.v1","sequence":null,"source":"clob_market_ws"}
{"event_at":"2026-07-27T03:24:02.448000Z","event_fingerprint":"cb3b8f301f005713bdb1a382f6a1b37bb4536e6cfa84155798fa0b08e5117ba6","payload":{"connection_id":"c7dc2e4762f849c6b6f9306b6518dcab","event_at":"2026-07-27T03:24:02.448000Z","event_type":"price_change","frame_hash":"b097330bba13ca47c0c510047cda9c52ed39c5febaf0954134d1450936174002","frame_index":0,"kind":"data","monotonic_ns":224627809638333,"payload":{"event_type":"price_change","market":"0x717c0e8ccd4d5c7040185188fbae28be901ca589a11a94b1b38ca36a79eccfeb","price_changes":[{"asset_id":"24254094493625419915756280046002869097156693848522361803041977572204227262166","best_ask":"0.64","best_bid":"0.63","hash":"63bb76ab56dbec87ebd7bfc112e365e49045436c","price":"0.57","side":"BUY","size":"24"},{"asset_id":"41448400836309843603620980831210604935021861034693225347475867885462478926555","best_ask":"0.37","best_bid":"0.36","hash":"e25a72137db7b50167f38ff2e0f2e4a624266d3d","price":"0.43","side":"SELL","size":"24"}],"timestamp":"1785122642448"},"payload_hash":"9a539074fd723298938ab3df9556d1d3e1cd16ee48674bdac6cf92e16279e536","raw_frame":"{\"market\":\"0x717c0e8ccd4d5c7040185188fbae28be901ca589a11a94b1b38ca36a79eccfeb\", \"price_changes\":[{\"asset_id\":\"24254094493625419915756280046002869097156693848522361803041977572204227262166\", \"price\":\"0.57\", \"size\":\"24\", \"side\":\"BUY\", \"hash\":\"63bb76ab56dbec87ebd7bfc112e365e49045436c\", \"best_bid\":\"0.63\", \"best_ask\":\"0.64\"}, {\"asset_id\":\"41448400836309843603620980831210604935021861034693225347475867885462478926555\", \"price\":\"0.43\", \"size\":\"24\", \"side\":\"SELL\", \"hash\":\"e25a72137db7b50167f38ff2e0f2e4a624266d3d\", \"best_bid\":\"0.36\", \"best_ask\":\"0.37\"}], \"timestamp\":\"1785122642448\", \"event_type\":\"price_change\"}","received_at":"2026-07-27T03:24:04.451815Z","schema_version":"clob-market-ws.price_change.v1","sequence":null,"server_hash":null,"server_timestamp":"1785122642448","session_id":"dd162b8dca5f43ff811d304e69a06123","source":"clob_market_ws"},"received_at":"2026-07-27T03:24:04.451815Z","record_id":"df81d1ecd91a212d84a89f78de0d62b3b4e4bf0dc090f471a487afec98c6e862","schema_fingerprint":"4aa3821a28b0b7c2400bc59aba4bcc0a76e971dadd19610d3ad38c768e124dc7","schema_version":"edge-lab-recorder.raw.v1","sequence":null,"source":"clob_market_ws"}
{"event_at":"2026-07-27T03:24:02.469000Z","event_fingerprint":"5dd75fe6a015fb98df245391a9a112356e85ceb135e79c54e86710bd5117a29b","payload":{"connection_id":"c7dc2e4762f849c6b6f9306b6518dcab","event_at":"2026-07-27T03:24:02.469000Z","event_type":"price_change","frame_hash":"88eec578963c23adf508631c8fdd2ca9e439f374c85d779c33f1b7c3d44f3d49","frame_index":0,"kind":"data","monotonic_ns":224627812793875,"payload":{"event_type":"price_change","market":"0x717c0e8ccd4d5c7040185188fbae28be901ca589a11a94b1b38ca36a79eccfeb","price_changes":[{"asset_id":"24254094493625419915756280046002869097156693848522361803041977572204227262166","best_ask":"0.64","best_bid":"0.63","hash":"6b588a9369ce974d8c08e65bc2fdd9767ec70133","price":"0.01","side":"BUY","size":"5458.02"},{"asset_id":"41448400836309843603620980831210604935021861034693225347475867885462478926555","best_ask":"0.37","best_bid":"0.36","hash":"00e504108f161afb29c8fadaa51e74ca798a6d5f","price":"0.99","side":"SELL","size":"5458.02"}],"timestamp":"1785122642469"},"payload_hash":"5768b1973853b7148c9ae3b3686e6a188169cd1935cda3b432dcea4848216853","raw_frame":"{\"market\":\"0x717c0e8ccd4d5c7040185188fbae28be901ca589a11a94b1b38ca36a79eccfeb\", \"price_changes\":[{\"asset_id\":\"24254094493625419915756280046002869097156693848522361803041977572204227262166\", \"price\":\"0.01\", \"size\":\"5458.02\", \"side\":\"BUY\", \"hash\":\"6b588a9369ce974d8c08e65bc2fdd9767ec70133\", \"best_bid\":\"0.63\", \"best_ask\":\"0.64\"}, {\"asset_id\":\"41448400836309843603620980831210604935021861034693225347475867885462478926555\", \"price\":\"0.99\", \"size\":\"5458.02\", \"side\":\"SELL\", \"hash\":\"00e504108f161afb29c8fadaa51e74ca798a6d5f\", \"best_bid\":\"0.36\", \"best_ask\":\"0.37\"}], \"timestamp\":\"1785122642469\", \"event_type\":\"price_change\"}","received_at":"2026-07-27T03:24:04.454969Z","schema_version":"clob-market-ws.price_change.v1","sequence":null,"server_hash":null,"server_timestamp":"1785122642469","session_id":"dd162b8dca5f43ff811d304e69a06123","source":"clob_market_ws"},"received_at":"2026-07-27T03:24:04.454969Z","record_id":"336711288609c98c42456dd6329d639834745dd4ba3c17501d68d7b1790335ee","schema_fingerprint":"4aa3821a28b0b7c2400bc59aba4bcc0a76e971dadd19610d3ad38c768e124dc7","schema_version":"edge-lab-recorder.raw.v1","sequence":null,"source":"clob_market_ws"}
{"event_at":"2026-07-27T03:24:02.477000Z","event_fingerprint":"65793c7e8cd017dbe00fe1e8274bb77b0c46488fefce8c2b1b45384603975570","payload":{"connection_id":"c7dc2e4762f849c6b6f9306b6518dcab","event_at":"2026-07-27T03:24:02.477000Z","event_type":"price_change","frame_hash":"588721c324a09df879ba3c1e49cb6b4d96e78b46ca32c9c88262157843fc82e2","frame_index":0,"kind":"data","monotonic_ns":224627815754041,"payload":{"event_type":"price_change","market":"0x717c0e8ccd4d5c7040185188fbae28be901ca589a11a94b1b38ca36a79eccfeb","price_changes":[{"asset_id":"41448400836309843603620980831210604935021861034693225347475867885462478926555","best_ask":"0.37","best_bid":"0.36","hash":"05181b1b8d0ce4252e534d96f24c246d09b813b8","price":"0.33","side":"BUY","size":"39.46"},{"asset_id":"24254094493625419915756280046002869097156693848522361803041977572204227262166","best_ask":"0.64","best_bid":"0.63","hash":"ef955af2c3a13bf1932582c7525abdb9ef9c946b","price":"0.67","side":"SELL","size":"39.46"}],"timestamp":"1785122642477"},"payload_hash":"aa9b3c343edc0d0f6faeb1b649c030886390ba952f3d7d8e161f80048aaa5cab","raw_frame":"{\"market\":\"0x717c0e8ccd4d5c7040185188fbae28be901ca589a11a94b1b38ca36a79eccfeb\", \"price_changes\":[{\"asset_id\":\"41448400836309843603620980831210604935021861034693225347475867885462478926555\", \"price\":\"0.33\", \"size\":\"39.46\", \"side\":\"BUY\", \"hash\":\"05181b1b8d0ce4252e534d96f24c246d09b813b8\", \"best_bid\":\"0.36\", \"best_ask\":\"0.37\"}, {\"asset_id\":\"24254094493625419915756280046002869097156693848522361803041977572204227262166\", \"price\":\"0.67\", \"size\":\"39.46\", \"side\":\"SELL\", \"hash\":\"ef955af2c3a13bf1932582c7525abdb9ef9c946b\", \"best_bid\":\"0.63\", \"best_ask\":\"0.64\"}], \"timestamp\":\"1785122642477\", \"event_type\":\"price_change\"}","received_at":"2026-07-27T03:24:04.457931Z","schema_version":"clob-market-ws.price_change.v1","sequence":null,"server_hash":null,"server_timestamp":"1785122642477","session_id":"dd162b8dca5f43ff811d304e69a06123","source":"clob_market_ws"},"received_at":"2026-07-27T03:24:04.457931Z","record_id":"8ca5056ad2f348b885bebab278d509e614f0ed32bd09ee41d2878c1c4cb589c0","schema_fingerprint":"4aa3821a28b0b7c2400bc59aba4bcc0a76e971dadd19610d3ad38c768e124dc7","schema_version":"edge-lab-recorder.raw.v1","sequence":null,"source":"clob_market_ws"}
{"event_at":"2026-07-27T03:24:02.480000Z","event_fingerprint":"08f1142c80321aa8cd46429efdf6c90b233970c49bd6a89ee5c1b5338f6d769f","payload":{"connection_id":"c7dc2e4762f849c6b6f9306b6518dcab","event_at":"2026-07-27T03:24:02.480000Z","event_type":"price_change","frame_hash":"bc2f8f2bdb7ada4585ff9e49a3fcecd843b4bdfeaf9f48f61b0685b3a277e05c","frame_index":0,"kind":"data","monotonic_ns":224627818654625,"payload":{"event_type":"price_change","market":"0x717c0e8ccd4d5c7040185188fbae28be901ca589a11a94b1b38ca36a79eccfeb","price_changes":[{"asset_id":"24254094493625419915756280046002869097156693848522361803041977572204227262166","best_ask":"0.64","best_bid":"0.63","hash":"73f4f716bbdca38be2e08f998261bfdf00746e1e","price":"0.58","side":"BUY","size":"29"},{"asset_id":"41448400836309843603620980831210604935021861034693225347475867885462478926555","best_ask":"0.37","best_bid":"0.36","hash":"8212ad355892ae1fd340d5627187db7d00c49943","price":"0.42","side":"SELL","size":"29"}],"timestamp":"1785122642480"},"payload_hash":"05ce7288a2e3782f78b1b86aa22104d23ffd7ba66b846d24a5fceaebc77dd6df","raw_frame":"{\"market\":\"0x717c0e8ccd4d5c7040185188fbae28be901ca589a11a94b1b38ca36a79eccfeb\", \"price_changes\":[{\"asset_id\":\"24254094493625419915756280046002869097156693848522361803041977572204227262166\", \"price\":\"0.58\", \"size\":\"29\", \"side\":\"BUY\", \"hash\":\"73f4f716bbdca38be2e08f998261bfdf00746e1e\", \"best_bid\":\"0.63\", \"best_ask\":\"0.64\"}, {\"asset_id\":\"41448400836309843603620980831210604935021861034693225347475867885462478926555\", \"price\":\"0.42\", \"size\":\"29\", \"side\":\"SELL\", \"hash\":\"8212ad355892ae1fd340d5627187db7d00c49943\", \"best_bid\":\"0.36\", \"best_ask\":\"0.37\"}], \"timestamp\":\"1785122642480\", \"event_type\":\"price_change\"}","received_at":"2026-07-27T03:24:04.460832Z","schema_version":"clob-market-ws.price_change.v1","sequence":null,"server_hash":null,"server_timestamp":"1785122642480","session_id":"dd162b8dca5f43ff811d304e69a06123","source":"clob_market_ws"},"received_at":"2026-07-27T03:24:04.460832Z","record_id":"041fbdd24916124222c6fa05404b7305f5a686d5b9a8dcecf206de0923a52ce6","schema_fingerprint":"4aa3821a28b0b7c2400bc59aba4bcc0a76e971dadd19610d3ad38c768e124dc7","schema_version":"edge-lab-recorder.raw.v1","sequence":null,"source":"clob_market_ws"}
{"event_at":"2026-07-27T03:24:02.490000Z","event_fingerprint":"2dc561eca261b496068f3ef921834a168eed40879e51122040cf591f4c389fb0","payload":{"connection_id":"c7dc2e4762f849c6b6f9306b6518dcab","event_at":"2026-07-27T03:24:02.490000Z","event_type":"price_change","frame_hash":"450201fcf66fbb7f468ba46520df62405ee2f94a64c36818e2fd4b9d246e4ea7","frame_index":0,"kind":"data","monotonic_ns":224627821693833,"payload":{"event_type":"price_change","market":"0x717c0e8ccd4d5c7040185188fbae28be901ca589a11a94b1b38ca36a79eccfeb","price_changes":[{"asset_id":"24254094493625419915756280046002869097156693848522361803041977572204227262166","best_ask":"0.64","best_bid":"0.63","hash":"60fc1ba3454f9f5458aa7accd854596a44434507","price":"0.01","side":"BUY","size":"5453.02"},{"asset_id":"41448400836309843603620980831210604935021861034693225347475867885462478926555","best_ask":"0.37","best_bid":"0.36","hash":"86ca0cbffb622b6086e9ad32e19823967800a754","price":"0.99","side":"SELL","size":"5453.02"}],"timestamp":"1785122642490"},"payload_hash":"283d9b20c813acc19697635437452ce592324ffd68459b5b5990dad6afda7a1a","raw_frame":"{\"market\":\"0x717c0e8ccd4d5c7040185188fbae28be901ca589a11a94b1b38ca36a79eccfeb\", \"price_changes\":[{\"asset_id\":\"24254094493625419915756280046002869097156693848522361803041977572204227262166\", \"price\":\"0.01\", \"size\":\"5453.02\", \"side\":\"BUY\", \"hash\":\"60fc1ba3454f9f5458aa7accd854596a44434507\", \"best_bid\":\"0.63\", \"best_ask\":\"0.64\"}, {\"asset_id\":\"41448400836309843603620980831210604935021861034693225347475867885462478926555\", \"price\":\"0.99\", \"size\":\"5453.02\", \"side\":\"SELL\", \"hash\":\"86ca0cbffb622b6086e9ad32e19823967800a754\", \"best_bid\":\"0.36\", \"best_ask\":\"0.37\"}], \"timestamp\":\"1785122642490\", \"event_type\":\"price_change\"}","received_at":"2026-07-27T03:24:04.463871Z","schema_version":"clob-market-ws.price_change.v1","sequence":null,"server_hash":null,"server_timestamp":"1785122642490","session_id":"dd162b8dca5f43ff811d304e69a06123","source":"clob_market_ws"},"received_at":"2026-07-27T03:24:04.463871Z","record_id":"8553f36fef515abee42a37fff4c5e9e6750992b267424ea0c3004ddf150c85b9","schema_fingerprint":"4aa3821a28b0b7c2400bc59aba4bcc0a76e971dadd19610d3ad38c768e124dc7","schema_version":"edge-lab-recorder.raw.v1","sequence":null,"source":"clob_market_ws"}
{"event_at":"2026-07-27T03:24:02.501000Z","event_fingerprint":"8ee63660679c782170076ce76c921a4b3105e540bf68672f7f4d36df3e8c84bb","payload":{"connection_id":"c7dc2e4762f849c6b6f9306b6518dcab","event_at":"2026-07-27T03:24:02.501000Z","event_type":"price_change","frame_hash":"594b76e9e659ae16cbaeabcaf27b582aff1bb4d7a4cf36a2d938629d270a276b","frame_index":0,"kind":"data","monotonic_ns":224627824529083,"payload":{"event_type":"price_change","market":"0x717c0e8ccd4d5c7040185188fbae28be901ca589a11a94b1b38ca36a79eccfeb","price_changes":[{"asset_id":"24254094493625419915756280046002869097156693848522361803041977572204227262166","best_ask":"0.64","best_bid":"0.63","hash":"b1d2aeb723ef21f2066fdde533b8fc17ff89bf3d","price":"0.03","side":"BUY","size":"618.1"},{"asset_id":"41448400836309843603620980831210604935021861034693225347475867885462478926555","best_ask":"0.37","best_bid":"0.36","hash":"88e5462a0310c5a27d8c55f9157814f774253c73","price":"0.97","side":"SELL","size":"618.1"}],"timestamp":"1785122642501"},"payload_hash":"6818c2e5b036340d3d1045f86ccfe015d22215c77ca3591236813a3829a13811","raw_frame":"{\"market\":\"0x717c0e8ccd4d5c7040185188fbae28be901ca589a11a94b1b38ca36a79eccfeb\", \"price_changes\":[{\"asset_id\":\"24254094493625419915756280046002869097156693848522361803041977572204227262166\", \"price\":\"0.03\", \"size\":\"618.1\", \"side\":\"BUY\", \"hash\":\"b1d2aeb723ef21f2066fdde533b8fc17ff89bf3d\", \"best_bid\":\"0.63\", \"best_ask\":\"0.64\"}, {\"asset_id\":\"41448400836309843603620980831210604935021861034693225347475867885462478926555\", \"price\":\"0.97\", \"size\":\"618.1\", \"side\":\"SELL\", \"hash\":\"88e5462a0310c5a27d8c55f9157814f774253c73\", \"best_bid\":\"0.36\", \"best_ask\":\"0.37\"}], \"timestamp\":\"1785122642501\", \"event_type\":\"price_change\"}","received_at":"2026-07-27T03:24:04.466705Z","schema_version":"clob-market-ws.price_change.v1","sequence":null,"server_hash":null,"server_timestamp":"1785122642501","session_id":"dd162b8dca5f43ff811d304e69a06123","source":"clob_market_ws"},"received_at":"2026-07-27T03:24:04.466705Z","record_id":"084432a5cd5b31921915f54bbef62a45d500c18c870ffa54b8b92a7105ee2086","schema_fingerprint":"4aa3821a28b0b7c2400bc59aba4bcc0a76e971dadd19610d3ad38c768e124dc7","schema_version":"edge-lab-recorder.raw.v1","sequence":null,"source":"clob_market_ws"}
{"event_at":"2026-07-27T03:24:02.504000Z","event_fingerprint":"b6c3850a216c7072bec28fec66aa0fc76c068a1b3c9f6c5fb7975c284608a47b","payload":{"connection_id":"c7dc2e4762f849c6b6f9306b6518dcab","event_at":"2026-07-27T03:24:02.504000Z","event_type":"price_change","frame_hash":"b18e5b66d6416cebb5345a1e9d64ee75f84b5186a0f8c69432ad5644aec8415d","frame_index":0,"kind":"data","monotonic_ns":224627827846250,"payload":{"event_type":"price_change","market":"0x717c0e8ccd4d5c7040185188fbae28be901ca589a11a94b1b38ca36a79eccfeb","price_changes":[{"asset_id":"24254094493625419915756280046002869097156693848522361803041977572204227262166","best_ask":"0.64","best_bid":"0.63","hash":"b3e52665914d1090f7405f5790cfef22f439f5a4","price":"0.42","side":"BUY","size":"176.02"},{"asset_id":"41448400836309843603620980831210604935021861034693225347475867885462478926555","best_ask":"0.37","best_bid":"0.36","hash":"f70d1a485e4a83b30c69036e524edec65d5def0d","price":"0.58","side":"SELL","size":"176.02"}],"timestamp":"1785122642504"},"payload_hash":"6d6df6eea5798a559823903d32f615f929a745d7645ec247373b524a4b889630","raw_frame":"{\"market\":\"0x717c0e8ccd4d5c7040185188fbae28be901ca589a11a94b1b38ca36a79eccfeb\", \"price_changes\":[{\"asset_id\":\"24254094493625419915756280046002869097156693848522361803041977572204227262166\", \"price\":\"0.42\", \"size\":\"176.02\", \"side\":\"BUY\", \"hash\":\"b3e52665914d1090f7405f5790cfef22f439f5a4\", \"best_bid\":\"0.63\", \"best_ask\":\"0.64\"}, {\"asset_id\":\"41448400836309843603620980831210604935021861034693225347475867885462478926555\", \"price\":\"0.58\", \"size\":\"176.02\", \"side\":\"SELL\", \"hash\":\"f70d1a485e4a83b30c69036e524edec65d5def0d\", \"best_bid\":\"0.36\", \"best_ask\":\"0.37\"}], \"timestamp\":\"1785122642504\", \"event_type\":\"price_change\"}","received_at":"2026-07-27T03:24:04.470020Z","schema_version":"clob-market-ws.price_change.v1","sequence":null,"server_hash":null,"server_timestamp":"1785122642504","session_id":"dd162b8dca5f43ff811d304e69a06123","source":"clob_market_ws"},"received_at":"2026-07-27T03:24:04.470020Z","record_id":"287a4623125c9e9d5ea82566323558280b1954851d178ff88e3ba8a4be0d9ae9","schema_fingerprint":"4aa3821a28b0b7c2400bc59aba4bcc0a76e971dadd19610d3ad38c768e124dc7","schema_version":"edge-lab-recorder.raw.v1","sequence":null,"source":"clob_market_ws"}
{"event_at":"2026-07-27T03:24:02.569000Z","event_fingerprint":"de9c772e30bb9bba5d718483b464e899796f63353a5c3219ec94a9f1710c634a","payload":{"connection_id":"c7dc2e4762f849c6b6f9306b6518dcab","event_at":"2026-07-27T03:24:02.569000Z","event_type":"price_change","frame_hash":"9d8bcc572212652270e7bc114c60287fd56cfc63c9a54943c250055dbe4de236","frame_index":0,"kind":"data","monotonic_ns":224627830361791,"payload":{"event_type":"price_change","market":"0x717c0e8ccd4d5c7040185188fbae28be901ca589a11a94b1b38ca36a79eccfeb","price_changes":[{"asset_id":"24254094493625419915756280046002869097156693848522361803041977572204227262166","best_ask":"0.64","best_bid":"0.63","hash":"0bb5e9d2b22996fb582fc9216ea035b568303e9d","price":"0.6","side":"BUY","size":"283"},{"asset_id":"41448400836309843603620980831210604935021861034693225347475867885462478926555","best_ask":"0.37","best_bid":"0.36","hash":"18ad47711f3a72ff8fd2effdacd94ef38baa57db","price":"0.4","side":"SELL","size":"283"}],"timestamp":"1785122642569"},"payload_hash":"62911ff303c4c9500240e31bac7408e92b6eb9ea7490d278650caa22c1ba6336","raw_frame":"{\"market\":\"0x717c0e8ccd4d5c7040185188fbae28be901ca589a11a94b1b38ca36a79eccfeb\", \"price_changes\":[{\"asset_id\":\"24254094493625419915756280046002869097156693848522361803041977572204227262166\", \"price\":\"0.6\", \"size\":\"283\", \"side\":\"BUY\", \"hash\":\"0bb5e9d2b22996fb582fc9216ea035b568303e9d\", \"best_bid\":\"0.63\", \"best_ask\":\"0.64\"}, {\"asset_id\":\"41448400836309843603620980831210604935021861034693225347475867885462478926555\", \"price\":\"0.4\", \"size\":\"283\", \"side\":\"SELL\", \"hash\":\"18ad47711f3a72ff8fd2effdacd94ef38baa57db\", \"best_bid\":\"0.36\", \"best_ask\":\"0.37\"}], \"timestamp\":\"1785122642569\", \"event_type\":\"price_change\"}","received_at":"2026-07-27T03:24:04.472544Z","schema_version":"clob-market-ws.price_change.v1","sequence":null,"server_hash":null,"server_timestamp":"1785122642569","session_id":"dd162b8dca5f43ff811d304e69a06123","source":"clob_market_ws"},"received_at":"2026-07-27T03:24:04.472544Z","record_id":"d2d10aa91c683eb6a0df1a037501ef64bc54070403a4a2f531fdf91c54e4b63b","schema_fingerprint":"4aa3821a28b0b7c2400bc59aba4bcc0a76e971dadd19610d3ad38c768e124dc7","schema_version":"edge-lab-recorder.raw.v1","sequence":null,"source":"clob_market_ws"}
{"event_at":"2026-07-27T03:24:02.570000Z","event_fingerprint":"a9a639b0a6430f6f047ff0a04eaca127d2d24606c76ac27553614fcd89d66fe5","payload":{"connection_id":"c7dc2e4762f849c6b6f9306b6518dcab","event_at":"2026-07-27T03:24:02.570000Z","event_type":"price_change","frame_hash":"7ec1538183cf33322bc03828bc33f57c862bf9f4a7662571ce0063ad8c972be3","frame_index":0,"kind":"data","monotonic_ns":224627831463416,"payload":{"event_type":"price_change","market":"0x717c0e8ccd4d5c7040185188fbae28be901ca589a11a94b1b38ca36a79eccfeb","price_changes":[{"asset_id":"24254094493625419915756280046002869097156693848522361803041977572204227262166","best_ask":"0.64","best_bid":"0.63","hash":"0dbbc1014a5fb8cf0af9d6a87c1ed0a2b4e414d5","price":"0.58","side":"BUY","size":"24"},{"asset_id":"41448400836309843603620980831210604935021861034693225347475867885462478926555","best_ask":"0.37","best_bid":"0.36","hash":"a64ebfc2d664b1b6df22000774767553afeb27dc","price":"0.42","side":"SELL","size":"24"}],"timestamp":"1785122642570"},"payload_hash":"297a3de0b0302b4735766f2a99bf7ce0f0c67e690acd0fa3146edd8a954a7e81","raw_frame":"{\"market\":\"0x717c0e8ccd4d5c7040185188fbae28be901ca589a11a94b1b38ca36a79eccfeb\", \"price_changes\":[{\"asset_id\":\"24254094493625419915756280046002869097156693848522361803041977572204227262166\", \"price\":\"0.58\", \"size\":\"24\", \"side\":\"BUY\", \"hash\":\"0dbbc1014a5fb8cf0af9d6a87c1ed0a2b4e414d5\", \"best_bid\":\"0.63\", \"best_ask\":\"0.64\"}, {\"asset_id\":\"41448400836309843603620980831210604935021861034693225347475867885462478926555\", \"price\":\"0.42\", \"size\":\"24\", \"side\":\"SELL\", \"hash\":\"a64ebfc2d664b1b6df22000774767553afeb27dc\", \"best_bid\":\"0.36\", \"best_ask\":\"0.37\"}], \"timestamp\":\"1785122642570\", \"event_type\":\"price_change\"}","received_at":"2026-07-27T03:24:04.473646Z","schema_version":"clob-market-ws.price_change.v1","sequence":null,"server_hash":null,"server_timestamp":"1785122642570","session_id":"dd162b8dca5f43ff811d304e69a06123","source":"clob_market_ws"},"received_at":"2026-07-27T03:24:04.473646Z","record_id":"15f4fcc5f60d291662c94d09e548105d3ad9ea77ead0c101cd7c719f7ffbe82f","schema_fingerprint":"4aa3821a28b0b7c2400bc59aba4bcc0a76e971dadd19610d3ad38c768e124dc7","schema_version":"edge-lab-recorder.raw.v1","sequence":null,"source":"clob_market_ws"}
{"event_at":"2026-07-27T03:24:02.574000Z","event_fingerprint":"ccd5291d9b34c1202786b140e97805d98b6d37a5de18cf9dc82f21a3fd1aafcc","payload":{"connection_id":"c7dc2e4762f849c6b6f9306b6518dcab","event_at":"2026-07-27T03:24:02.574000Z","event_type":"price_change","frame_hash":"fb730513130ee8f22d12cf7ed07f5837b38c48977fe139b47d9e15dae15731d8","frame_index":0,"kind":"data","monotonic_ns":224627832331875,"payload":{"event_type":"price_change","market":"0x717c0e8ccd4d5c7040185188fbae28be901ca589a11a94b1b38ca36a79eccfeb","price_changes":[{"asset_id":"24254094493625419915756280046002869097156693848522361803041977572204227262166","best_ask":"0.64","best_bid":"0.63","hash":"a5dd7fd0e1409f5485bb9bf8e697f2522e314a77","price":"0.57","side":"BUY","size":"33"},{"asset_id":"41448400836309843603620980831210604935021861034693225347475867885462478926555","best_ask":"0.37","best_bid":"0.36","hash":"c7e4a795fdef7788962237ffd1ff84e2682ff6df","price":"0.43","side":"SELL","size":"33"}],"timestamp":"1785122642574"},"payload_hash":"385834f51c63ec398f2e22f1a997ee0869c4c98b8323265538c7fe7e4d9ad3eb","raw_frame":"{\"market\":\"0x717c0e8ccd4d5c7040185188fbae28be901ca589a11a94b1b38ca36a79eccfeb\", \"price_changes\":[{\"asset_id\":\"24254094493625419915756280046002869097156693848522361803041977572204227262166\", \"price\":\"0.57\", \"size\":\"33\", \"side\":\"BUY\", \"hash\":\"a5dd7fd0e1409f5485bb9bf8e697f2522e314a77\", \"best_bid\":\"0.63\", \"best_ask\":\"0.64\"}, {\"asset_id\":\"41448400836309843603620980831210604935021861034693225347475867885462478926555\", \"price\":\"0.43\", \"size\":\"33\", \"side\":\"SELL\", \"hash\":\"c7e4a795fdef7788962237ffd1ff84e2682ff6df\", \"best_bid\":\"0.36\", \"best_ask\":\"0.37\"}], \"timestamp\":\"1785122642574\", \"event_type\":\"price_change\"}","received_at":"2026-07-27T03:24:04.474515Z","schema_version":"clob-market-ws.price_change.v1","sequence":null,"server_hash":null,"server_timestamp":"1785122642574","session_id":"dd162b8dca5f43ff811d304e69a06123","source":"clob_market_ws"},"received_at":"2026-07-27T03:24:04.474515Z","record_id":"95331428be8bd8caa2b3f6b2e8cea4da0db5dd46fbbcfa63e2652fa056a3a97c","schema_fingerprint":"4aa3821a28b0b7c2400bc59aba4bcc0a76e971dadd19610d3ad38c768e124dc7","schema_version":"edge-lab-recorder.raw.v1","sequence":null,"source":"clob_market_ws"}
{"event_at":"2026-07-27T03:24:02.594000Z","event_fingerprint":"6fa529ce96afb53b1c00a5f1cc6fa4a81ff2139f302de0ef0aba259e44d2720a","payload":{"connection_id":"c7dc2e4762f849c6b6f9306b6518dcab","event_at":"2026-07-27T03:24:02.594000Z","event_type":"price_change","frame_hash":"372a77c09f54f4bd63e103e287de4cb0d81cffacbb3e2ae642c89b6d21fec919","frame_index":0,"kind":"data","monotonic_ns":224627833406916,"payload":{"event_type":"price_change","market":"0x717c0e8ccd4d5c7040185188fbae28be901ca589a11a94b1b38ca36a79eccfeb","price_changes":[{"asset_id":"24254094493625419915756280046002869097156693848522361803041977572204227262166","best_ask":"0.64","best_bid":"0.63","hash":"2bca74c89b71178cc680525c3ff2a4f2baa284ae","price":"0.03","side":"BUY","size":"613.1"},{"asset_id":"41448400836309843603620980831210604935021861034693225347475867885462478926555","best_ask":"0.37","best_bid":"0.36","hash":"eb7d6e53760da2760bb8442a6483cf2e6e164485","price":"0.97","side":"SELL","size":"613.1"}],"timestamp":"1785122642594"},"payload_hash":"89e4453733bc5d408d2fa47f404075303f8219467369a018fb6ef9b3a7dd58b5","raw_frame":"{\"market\":\"0x717c0e8ccd4d5c7040185188fbae28be901ca589a11a94b1b38ca36a79eccfeb\", \"price_changes\":[{\"asset_id\":\"24254094493625419915756280046002869097156693848522361803041977572204227262166\", \"price\":\"0.03\", \"size\":\"613.1\", \"side\":\"BUY\", \"hash\":\"2bca74c89b71178cc680525c3ff2a4f2baa284ae\", \"best_bid\":\"0.63\", \"best_ask\":\"0.64\"}, {\"asset_id\":\"41448400836309843603620980831210604935021861034693225347475867885462478926555\", \"price\":\"0.97\", \"size\":\"613.1\", \"side\":\"SELL\", \"hash\":\"eb7d6e53760da2760bb8442a6483cf2e6e164485\", \"best_bid\":\"0.36\", \"best_ask\":\"0.37\"}], \"timestamp\":\"1785122642594\", \"event_type\":\"price_change\"}","received_at":"2026-07-27T03:24:04.475590Z","schema_version":"clob-market-ws.price_change.v1","sequence":null,"server_hash":null,"server_timestamp":"1785122642594","session_id":"dd162b8dca5f43ff811d304e69a06123","source":"clob_market_ws"},"received_at":"2026-07-27T03:24:04.475590Z","record_id":"52fb26f58bcb6f6b443da7aaf9a7c2d414eb7f14006d31b6ecfc50d7d2ec8af6","schema_fingerprint":"4aa3821a28b0b7c2400bc59aba4bcc0a76e971dadd19610d3ad38c768e124dc7","schema_version":"edge-lab-recorder.raw.v1","sequence":null,"source":"clob_market_ws"}
{"event_at":"2026-07-27T03:24:02.606000Z","event_fingerprint":"96cb48a0f95e183d48dc521a271150741fcee25e138c0619f91be7d30ff4707f","payload":{"connection_id":"c7dc2e4762f849c6b6f9306b6518dcab","event_at":"2026-07-27T03:24:02.606000Z","event_type":"price_change","frame_hash":"1c956363f43ccdb48fc46ff6ea3e2f50aa41d058d3f1a88227abb816bc1ed421","frame_index":0,"kind":"data","monotonic_ns":224627834521666,"payload":{"event_type":"price_change","market":"0x717c0e8ccd4d5c7040185188fbae28be901ca589a11a94b1b38ca36a79eccfeb","price_changes":[{"asset_id":"41448400836309843603620980831210604935021861034693225347475867885462478926555","best_ask":"0.37","best_bid":"0.36","hash":"6f99862c4a37c08aef49b816776472f451bad2eb","price":"0.24","side":"BUY","size":"51.39"},{"asset_id":"24254094493625419915756280046002869097156693848522361803041977572204227262166","best_ask":"0.64","best_bid":"0.63","hash":"ca2d46ca6c2a2aaa89b91876dface67fff9ccf23","price":"0.76","side":"SELL","size":"51.39"}],"timestamp":"1785122642606"},"payload_hash":"ea80486c7fa73024ac4f5e2c8437930209599f0ad8ad6552afe38dba2d5fcef8","raw_frame":"{\"market\":\"0x717c0e8ccd4d5c7040185188fbae28be901ca589a11a94b1b38ca36a79eccfeb\", \"price_changes\":[{\"asset_id\":\"41448400836309843603620980831210604935021861034693225347475867885462478926555\", \"price\":\"0.24\", \"size\":\"51.39\", \"side\":\"BUY\", \"hash\":\"6f99862c4a37c08aef49b816776472f451bad2eb\", \"best_bid\":\"0.36\", \"best_ask\":\"0.37\"}, {\"asset_id\":\"24254094493625419915756280046002869097156693848522361803041977572204227262166\", \"price\":\"0.76\", \"size\":\"51.39\", \"side\":\"SELL\", \"hash\":\"ca2d46ca6c2a2aaa89b91876dface67fff9ccf23\", \"best_bid\":\"0.63\", \"best_ask\":\"0.64\"}], \"timestamp\":\"1785122642606\", \"event_type\":\"price_change\"}","received_at":"2026-07-27T03:24:04.476705Z","schema_version":"clob-market-ws.price_change.v1","sequence":null,"server_hash":null,"server_timestamp":"1785122642606","session_id":"dd162b8dca5f43ff811d304e69a06123","source":"clob_market_ws"},"received_at":"2026-07-27T03:24:04.476705Z","record_id":"7888cdb261ad8699360468370d57badfb7e6eb133e5532ac86ca289be9c0e81e","schema_fingerprint":"4aa3821a28b0b7c2400bc59aba4bcc0a76e971dadd19610d3ad38c768e124dc7","schema_version":"edge-lab-recorder.raw.v1","sequence":null,"source":"clob_market_ws"}
{"event_at":"2026-07-27T03:24:02.613000Z","event_fingerprint":"f197de56d3a38a59c8333748676dfb7d1fca0fdcf3affe8cd6c12e29223c02b9","payload":{"connection_id":"c7dc2e4762f849c6b6f9306b6518dcab","event_at":"2026-07-27T03:24:02.613000Z","event_type":"price_change","frame_hash":"790fbe0d2fc1a1964b383b89744d793dfec82c694a2870dad4430708597b2d0a","frame_index":0,"kind":"data","monotonic_ns":224627835897916,"payload":{"event_type":"price_change","market":"0x717c0e8ccd4d5c7040185188fbae28be901ca589a11a94b1b38ca36a79eccfeb","price_changes":[{"asset_id":"41448400836309843603620980831210604935021861034693225347475867885462478926555","best_ask":"0.37","best_bid":"0.36","hash":"faf1c758888809ee686c262e7279d22a8b1e1904","price":"0.28","side":"BUY","size":"235.59"},{"asset_id":"24254094493625419915756280046002869097156693848522361803041977572204227262166","best_ask":"0.64","best_bid":"0.63","hash":"6f431a445fba8f7c2a987a27774ec74b22a6f82e","price":"0.72","side":"SELL","size":"235.59"}],"timestamp":"1785122642613"},"payload_hash":"ce0e6d09cc80c9d50f7eeec5c32772f723f36879f6c8f8a61f034f7c3c9a5e2f","raw_frame":"{\"market\":\"0x717c0e8ccd4d5c7040185188fbae28be901ca589a11a94b1b38ca36a79eccfeb\", \"price_changes\":[{\"asset_id\":\"41448400836309843603620980831210604935021861034693225347475867885462478926555\", \"price\":\"0.28\", \"size\":\"235.59\", \"side\":\"BUY\", \"hash\":\"faf1c758888809ee686c262e7279d22a8b1e1904\", \"best_bid\":\"0.36\", \"best_ask\":\"0.37\"}, {\"asset_id\":\"24254094493625419915756280046002869097156693848522361803041977572204227262166\", \"price\":\"0.72\", \"size\":\"235.59\", \"side\":\"SELL\", \"hash\":\"6f431a445fba8f7c2a987a27774ec74b22a6f82e\", \"best_bid\":\"0.63\", \"best_ask\":\"0.64\"}], \"timestamp\":\"1785122642613\", \"event_type\":\"price_change\"}","received_at":"2026-07-27T03:24:04.478081Z","schema_version":"clob-market-ws.price_change.v1","sequence":null,"server_hash":null,"server_timestamp":"1785122642613","session_id":"dd162b8dca5f43ff811d304e69a06123","source":"clob_market_ws"},"received_at":"2026-07-27T03:24:04.478081Z","record_id":"78ec60be8008a8130fe35e284d448c3802937ce98ed95b0fab7c6c1f573c4e59","schema_fingerprint":"4aa3821a28b0b7c2400bc59aba4bcc0a76e971dadd19610d3ad38c768e124dc7","schema_version":"edge-lab-recorder.raw.v1","sequence":null,"source":"clob_market_ws"}
{"event_at":"2026-07-27T03:24:02.628000Z","event_fingerprint":"494825b0e5345fc1b7fd0236981852a9c97cdeabf5e27c73f6958063997c8dbc","payload":{"connection_id":"c7dc2e4762f849c6b6f9306b6518dcab","event_at":"2026-07-27T03:24:02.628000Z","event_type":"price_change","frame_hash":"7879d18af0e35a8bd85740393f437f2001eecf6033fcda454d58ef998980b3d3","frame_index":0,"kind":"data","monotonic_ns":224627836981666,"payload":{"event_type":"price_change","market":"0x717c0e8ccd4d5c7040185188fbae28be901ca589a11a94b1b38ca36a79eccfeb","price_changes":[{"asset_id":"24254094493625419915756280046002869097156693848522361803041977572204227262166","best_ask":"0.64","best_bid":"0.63","hash":"46c57f07fae8d67c5e3337259b24193aedb97522","price":"0.42","side":"BUY","size":"255.38"},{"asset_id":"41448400836309843603620980831210604935021861034693225347475867885462478926555","best_ask":"0.37","best_bid":"0.36","hash":"c5844a5dd8b03eec10527a5082af1e046cc4fb23","price":"0.58","side":"SELL","size":"255.38"}],"timestamp":"1785122642628"},"payload_hash":"cf8d9ef7da7b354253ae1acaa62b39aea82d79abcad3acf458f78682bd45f8e6","raw_frame":"{\"market\":\"0x717c0e8ccd4d5c7040185188fbae28be901ca589a11a94b1b38ca36a79eccfeb\", \"price_changes\":[{\"asset_id\":\"24254094493625419915756280046002869097156693848522361803041977572204227262166\", \"price\":\"0.42\", \"size\":\"255.38\", \"side\":\"BUY\", \"hash\":\"46c57f07fae8d67c5e3337259b24193aedb97522\", \"best_bid\":\"0.63\", \"best_ask\":\"0.64\"}, {\"asset_id\":\"41448400836309843603620980831210604935021861034693225347475867885462478926555\", \"price\":\"0.58\", \"size\":\"255.38\", \"side\":\"SELL\", \"hash\":\"c5844a5dd8b03eec10527a5082af1e046cc4fb23\", \"best_bid\":\"0.36\", \"best_ask\":\"0.37\"}], \"timestamp\":\"1785122642628\", \"event_type\":\"price_change\"}","received_at":"2026-07-27T03:24:04.479165Z","schema_version":"clob-market-ws.price_change.v1","sequence":null,"server_hash":null,"server_timestamp":"1785122642628","session_id":"dd162b8dca5f43ff811d304e69a06123","source":"clob_market_ws"},"received_at":"2026-07-27T03:24:04.479165Z","record_id":"57cf24d715f1d0f2bcf1d4c6ade3a1dfddced9cdea0edbb60e4e795c67b9bf03","schema_fingerprint":"4aa3821a28b0b7c2400bc59aba4bcc0a76e971dadd19610d3ad38c768e124dc7","schema_version":"edge-lab-recorder.raw.v1","sequence":null,"source":"clob_market_ws"}
{"event_at":"2026-07-27T03:24:02.637000Z","event_fingerprint":"cdc1bb59529d9b61c7d8df7faf73eebc58343bfc0500022dda8d521006b4fa8f","payload":{"connection_id":"c7dc2e4762f849c6b6f9306b6518dcab","event_at":"2026-07-27T03:24:02.637000Z","event_type":"price_change","frame_hash":"f769705558f07dd94478ea05c6b46cafb0872ecae6708a1c77cd3677f36d1030","frame_index":0,"kind":"data","monotonic_ns":224627838036625,"payload":{"event_type":"price_change","market":"0x717c0e8ccd4d5c7040185188fbae28be901ca589a11a94b1b38ca36a79eccfeb","price_changes":[{"asset_id":"41448400836309843603620980831210604935021861034693225347475867885462478926555","best_ask":"0.37","best_bid":"0.36","hash":"82d644b11a63eea6fec67aea88f3a6c4162f7ae3","price":"0.25","side":"BUY","size":"27"},{"asset_id":"24254094493625419915756280046002869097156693848522361803041977572204227262166","best_ask":"0.64","best_bid":"0.63","hash":"9170beacef5cff77da563fff5966c37dd2c18798","price":"0.75","side":"SELL","size":"27"}],"timestamp":"1785122642637"},"payload_hash":"2e0bca2e7af1f8ca867c3bb256ff3cec1b6cc7bbd0e1bb3cb3bf58a204c0946b","raw_frame":"{\"market\":\"0x717c0e8ccd4d5c7040185188fbae28be901ca589a11a94b1b38ca36a79eccfeb\", \"price_changes\":[{\"asset_id\":\"41448400836309843603620980831210604935021861034693225347475867885462478926555\", \"price\":\"0.25\", \"size\":\"27\", \"side\":\"BUY\", \"hash\":\"82d644b11a63eea6fec67aea88f3a6c4162f7ae3\", \"best_bid\":\"0.36\", \"best_ask\":\"0.37\"}, {\"asset_id\":\"24254094493625419915756280046002869097156693848522361803041977572204227262166\", \"price\":\"0.75\", \"size\":\"27\", \"side\":\"SELL\", \"hash\":\"9170beacef5cff77da563fff5966c37dd2c18798\", \"best_bid\":\"0.63\", \"best_ask\":\"0.64\"}], \"timestamp\":\"1785122642637\", \"event_type\":\"price_change\"}","received_at":"2026-07-27T03:24:04.480220Z","schema_version":"clob-market-ws.price_change.v1","sequence":null,"server_hash":null,"server_timestamp":"1785122642637","session_id":"dd162b8dca5f43ff811d304e69a06123","source":"clob_market_ws"},"received_at":"2026-07-27T03:24:04.480220Z","record_id":"cf7d208a9a825adf7dc7b04b939f95953007e36eb967c13c1c65d59ba11b45ca","schema_fingerprint":"4aa3821a28b0b7c2400bc59aba4bcc0a76e971dadd19610d3ad38c768e124dc7","schema_version":"edge-lab-recorder.raw.v1","sequence":null,"source":"clob_market_ws"}
{"event_at":"2026-07-27T03:24:02.659000Z","event_fingerprint":"f5657c600ad8c8affaf63e5b67038606f4acf0b6c01b9de93232de0cfe2a27dc","payload":{"connection_id":"c7dc2e4762f849c6b6f9306b6518dcab","event_at":"2026-07-27T03:24:02.659000Z","event_type":"price_change","frame_hash":"db131a61863679f116c2102b43527cd88e525a2cf55ae2c68d5d953ba89ab790","frame_index":0,"kind":"data","monotonic_ns":224627839059625,"payload":{"event_type":"price_change","market":"0x717c0e8ccd4d5c7040185188fbae28be901ca589a11a94b1b38ca36a79eccfeb","price_changes":[{"asset_id":"24254094493625419915756280046002869097156693848522361803041977572204227262166","best_ask":"0.64","best_bid":"0.63","hash":"6509eb6a5056ca46201b86776a162254707188aa","price":"0.01","side":"BUY","size":"5458.02"},{"asset_id":"41448400836309843603620980831210604935021861034693225347475867885462478926555","best_ask":"0.37","best_bid":"0.36","hash":"a0dcc46411e4e014642e4c646f00d4b9b57494ab","price":"0.99","side":"SELL","size":"5458.02"}],"timestamp":"1785122642659"},"payload_hash":"a66551ce0a131680238efb07e4fa059fac8565639d48f915fed2af2927dc7f1c","raw_frame":"{\"market\":\"0x717c0e8ccd4d5c7040185188fbae28be901ca589a11a94b1b38ca36a79eccfeb\", \"price_changes\":[{\"asset_id\":\"24254094493625419915756280046002869097156693848522361803041977572204227262166\", \"price\":\"0.01\", \"size\":\"5458.02\", \"side\":\"BUY\", \"hash\":\"6509eb6a5056ca46201b86776a162254707188aa\", \"best_bid\":\"0.63\", \"best_ask\":\"0.64\"}, {\"asset_id\":\"41448400836309843603620980831210604935021861034693225347475867885462478926555\", \"price\":\"0.99\", \"size\":\"5458.02\", \"side\":\"SELL\", \"hash\":\"a0dcc46411e4e014642e4c646f00d4b9b57494ab\", \"best_bid\":\"0.36\", \"best_ask\":\"0.37\"}], \"timestamp\":\"1785122642659\", \"event_type\":\"price_change\"}","received_at":"2026-07-27T03:24:04.481242Z","schema_version":"clob-market-ws.price_change.v1","sequence":null,"server_hash":null,"server_timestamp":"1785122642659","session_id":"dd162b8dca5f43ff811d304e69a06123","source":"clob_market_ws"},"received_at":"2026-07-27T03:24:04.481242Z","record_id":"c91ad52da593054b92cdaa80d0eb1bd687eda13fe211c75e084c77ba2c8faba1","schema_fingerprint":"4aa3821a28b0b7c2400bc59aba4bcc0a76e971dadd19610d3ad38c768e124dc7","schema_version":"edge-lab-recorder.raw.v1","sequence":null,"source":"clob_market_ws"}
{"event_at":"2026-07-27T03:24:02.684000Z","event_fingerprint":"7d425cfae646b4cdc27b6b3f7a530d7e2a70b2c699956ddcdaff22c76d6b1396","payload":{"connection_id":"c7dc2e4762f849c6b6f9306b6518dcab","event_at":"2026-07-27T03:24:02.684000Z","event_type":"price_change","frame_hash":"cc5a3c7c5c23d2a2f91a23e3f5a5700ac2abc97fd26ee1fcf7d966a660ae655d","frame_index":0,"kind":"data","monotonic_ns":224627840007416,"payload":{"event_type":"price_change","market":"0x717c0e8ccd4d5c7040185188fbae28be901ca589a11a94b1b38ca36a79eccfeb","price_changes":[{"asset_id":"24254094493625419915756280046002869097156693848522361803041977572204227262166","best_ask":"0.64","best_bid":"0.63","hash":"4164ca5eddb26842a52e936744de4e3d2d6b127a","price":"0.01","side":"BUY","size":"5453.02"},{"asset_id":"41448400836309843603620980831210604935021861034693225347475867885462478926555","best_ask":"0.37","best_bid":"0.36","hash":"971793834da08eab2ae98020fd2472ba6ca1355b","price":"0.99","side":"SELL","size":"5453.02"}],"timestamp":"1785122642684"},"payload_hash":"af9b7aab4bd06564f9ad2e4cac7dda894566a26fb98432cd49a3dbb1eb717427","raw_frame":"{\"market\":\"0x717c0e8ccd4d5c7040185188fbae28be901ca589a11a94b1b38ca36a79eccfeb\", \"price_changes\":[{\"asset_id\":\"24254094493625419915756280046002869097156693848522361803041977572204227262166\", \"price\":\"0.01\", \"size\":\"5453.02\", \"side\":\"BUY\", \"hash\":\"4164ca5eddb26842a52e936744de4e3d2d6b127a\", \"best_bid\":\"0.63\", \"best_ask\":\"0.64\"}, {\"asset_id\":\"41448400836309843603620980831210604935021861034693225347475867885462478926555\", \"price\":\"0.99\", \"size\":\"5453.02\", \"side\":\"SELL\", \"hash\":\"971793834da08eab2ae98020fd2472ba6ca1355b\", \"best_bid\":\"0.36\", \"best_ask\":\"0.37\"}], \"timestamp\":\"1785122642684\", \"event_type\":\"price_change\"}","received_at":"2026-07-27T03:24:04.482191Z","schema_version":"clob-market-ws.price_change.v1","sequence":null,"server_hash":null,"server_timestamp":"1785122642684","session_id":"dd162b8dca5f43ff811d304e69a06123","source":"clob_market_ws"},"received_at":"2026-07-27T03:24:04.482191Z","record_id":"ce251ffcc41bc359fac77c6c51d21c06c21a655c45971f43d31f99721a6c4be6","schema_fingerprint":"4aa3821a28b0b7c2400bc59aba4bcc0a76e971dadd19610d3ad38c768e124dc7","schema_version":"edge-lab-recorder.raw.v1","sequence":null,"source":"clob_market_ws"}
{"event_at":"2026-07-27T03:24:02.685000Z","event_fingerprint":"da25e715e2ef14127d132503a39577a0d51cd7a0a213e7b845e6d2a05019ab5a","payload":{"connection_id":"c7dc2e4762f849c6b6f9306b6518dcab","event_at":"2026-07-27T03:24:02.685000Z","event_type":"price_change","frame_hash":"60567d381b15012d2439f5387bfd66fcae54c1d5102f554251656ff73db9f022","frame_index":0,"kind":"data","monotonic_ns":224627840946666,"payload":{"event_type":"price_change","market":"0x717c0e8ccd4d5c7040185188fbae28be901ca589a11a94b1b38ca36a79eccfeb","price_changes":[{"asset_id":"24254094493625419915756280046002869097156693848522361803041977572204227262166","best_ask":"0.64","best_bid":"0.63","hash":"b8a4003eacaa172a5c99371da1be61c4074e9379","price":"0.6","side":"BUY","size":"291"},{"asset_id":"41448400836309843603620980831210604935021861034693225347475867885462478926555","best_ask":"0.37","best_bid":"0.36","hash":"622a3f36a5419dcb982ac8688c50082fdf4b14c9","price":"0.4","side":"SELL","size":"291"}],"timestamp":"1785122642685"},"payload_hash":"fb0a4c154f779c7d8567367ff665c667d78c050a3189c4a85c8ebf242334e413","raw_frame":"{\"market\":\"0x717c0e8ccd4d5c7040185188fbae28be901ca589a11a94b1b38ca36a79eccfeb\", \"price_changes\":[{\"asset_id\":\"24254094493625419915756280046002869097156693848522361803041977572204227262166\", \"price\":\"0.6\", \"size\":\"291\", \"side\":\"BUY\", \"hash\":\"b8a4003eacaa172a5c99371da1be61c4074e9379\", \"best_bid\":\"0.63\", \"best_ask\":\"0.64\"}, {\"asset_id\":\"41448400836309843603620980831210604935021861034693225347475867885462478926555\", \"price\":\"0.4\", \"size\":\"291\", \"side\":\"SELL\", \"hash\":\"622a3f36a5419dcb982ac8688c50082fdf4b14c9\", \"best_bid\":\"0.36\", \"best_ask\":\"0.37\"}], \"timestamp\":\"1785122642685\", \"event_type\":\"price_change\"}","received_at":"2026-07-27T03:24:04.483130Z","schema_version":"clob-market-ws.price_change.v1","sequence":null,"server_hash":null,"server_timestamp":"1785122642685","session_id":"dd162b8dca5f43ff811d304e69a06123","source":"clob_market_ws"},"received_at":"2026-07-27T03:24:04.483130Z","record_id":"d422bb8240d4b34fb0626389bf54e470e3abd8d32658483412c2f893cc4fb276","schema_fingerprint":"4aa3821a28b0b7c2400bc59aba4bcc0a76e971dadd19610d3ad38c768e124dc7","schema_version":"edge-lab-recorder.raw.v1","sequence":null,"source":"clob_market_ws"}
{"event_at":"2026-07-27T03:24:02.687000Z","event_fingerprint":"dadb8540be8ebbaba475f53b125d2025c37c2d8c50d1e5182732e28b690920d4","payload":{"connection_id":"c7dc2e4762f849c6b6f9306b6518dcab","event_at":"2026-07-27T03:24:02.687000Z","event_type":"price_change","frame_hash":"f6024eb7010aee01de86e784c48a092c51a8d4c9230d094f6c5fd510ea397b61","frame_index":0,"kind":"data","monotonic_ns":224627843297125,"payload":{"event_type":"price_change","market":"0x717c0e8ccd4d5c7040185188fbae28be901ca589a11a94b1b38ca36a79eccfeb","price_changes":[{"asset_id":"24254094493625419915756280046002869097156693848522361803041977572204227262166","best_ask":"0.64","best_bid":"0.63","hash":"015c29b0ee0cb97c5a4f96fe657d55e421a1f46b","price":"0.58","side":"BUY","size":"29"},{"asset_id":"41448400836309843603620980831210604935021861034693225347475867885462478926555","best_ask":"0.37","best_bid":"0.36","hash":"2d815a38981f4a0ed877c895bc8f8f14b528a1df","price":"0.42","side":"SELL","size":"29"}],"timestamp":"1785122642687"},"payload_hash":"198e5c46ace54548780e1052ae0cff5171610d2f82c53451e3233678e7bb2deb","raw_frame":"{\"market\":\"0x717c0e8ccd4d5c7040185188fbae28be901ca589a11a94b1b38ca36a79eccfeb\", \"price_changes\":[{\"asset_id\":\"24254094493625419915756280046002869097156693848522361803041977572204227262166\", \"price\":\"0.58\", \"size\":\"29\", \"side\":\"BUY\", \"hash\":\"015c29b0ee0cb97c5a4f96fe657d55e421a1f46b\", \"best_bid\":\"0.63\", \"best_ask\":\"0.64\"}, {\"asset_id\":\"41448400836309843603620980831210604935021861034693225347475867885462478926555\", \"price\":\"0.42\", \"size\":\"29\", \"side\":\"SELL\", \"hash\":\"2d815a38981f4a0ed877c895bc8f8f14b528a1df\", \"best_bid\":\"0.36\", \"best_ask\":\"0.37\"}], \"timestamp\":\"1785122642687\", \"event_type\":\"price_change\"}","received_at":"2026-07-27T03:24:04.485480Z","schema_version":"clob-market-ws.price_change.v1","sequence":null,"server_hash":null,"server_timestamp":"1785122642687","session_id":"dd162b8dca5f43ff811d304e69a06123","source":"clob_market_ws"},"received_at":"2026-07-27T03:24:04.485480Z","record_id":"79dc28158395b14b94a290ca06e881367619fe7153e155f1b34a996c574d6769","schema_fingerprint":"4aa3821a28b0b7c2400bc59aba4bcc0a76e971dadd19610d3ad38c768e124dc7","schema_version":"edge-lab-recorder.raw.v1","sequence":null,"source":"clob_market_ws"}
{"event_at":"2026-07-27T03:24:02.693000Z","event_fingerprint":"c7a1fbf59bdfac275453fdb70d3ee59b22c9e23c949c689c7388f43ecdb23365","payload":{"connection_id":"c7dc2e4762f849c6b6f9306b6518dcab","event_at":"2026-07-27T03:24:02.693000Z","event_type":"price_change","frame_hash":"08e8a71742560b423ef94e968b4be33c9f7b46bad76de042b4e5481a37f2d066","frame_index":0,"kind":"data","monotonic_ns":224627844790583,"payload":{"event_type":"price_change","market":"0x717c0e8ccd4d5c7040185188fbae28be901ca589a11a94b1b38ca36a79eccfeb","price_changes":[{"asset_id":"41448400836309843603620980831210604935021861034693225347475867885462478926555","best_ask":"0.37","best_bid":"0.36","hash":"5afc7e51e2d02d3043810f7c4f495f7d6a349521","price":"0.27","side":"BUY","size":"126"},{"asset_id":"24254094493625419915756280046002869097156693848522361803041977572204227262166","best_ask":"0.64","best_bid":"0.63","hash":"4cecdd024fc6d1a715fd36f8dc72f3659dd03d80","price":"0.73","side":"SELL","size":"126"}],"timestamp":"1785122642693"},"payload_hash":"a4b2df4f870139ff66edc2b63905d428e0c801aa3c2169cf847bd89bd0657ea9","raw_frame":"{\"market\":\"0x717c0e8ccd4d5c7040185188fbae28be901ca589a11a94b1b38ca36a79eccfeb\", \"price_changes\":[{\"asset_id\":\"41448400836309843603620980831210604935021861034693225347475867885462478926555\", \"price\":\"0.27\", \"size\":\"126\", \"side\":\"BUY\", \"hash\":\"5afc7e51e2d02d3043810f7c4f495f7d6a349521\", \"best_bid\":\"0.36\", \"best_ask\":\"0.37\"}, {\"asset_id\":\"24254094493625419915756280046002869097156693848522361803041977572204227262166\", \"price\":\"0.73\", \"size\":\"126\", \"side\":\"SELL\", \"hash\":\"4cecdd024fc6d1a715fd36f8dc72f3659dd03d80\", \"best_bid\":\"0.63\", \"best_ask\":\"0.64\"}], \"timestamp\":\"1785122642693\", \"event_type\":\"price_change\"}","received_at":"2026-07-27T03:24:04.486968Z","schema_version":"clob-market-ws.price_change.v1","sequence":null,"server_hash":null,"server_timestamp":"1785122642693","session_id":"dd162b8dca5f43ff811d304e69a06123","source":"clob_market_ws"},"received_at":"2026-07-27T03:24:04.486968Z","record_id":"b9aa5eab0d1147e0a3156ac6fcc8f6d31b75582cd6adbd552b470a79e960633a","schema_fingerprint":"4aa3821a28b0b7c2400bc59aba4bcc0a76e971dadd19610d3ad38c768e124dc7","schema_version":"edge-lab-recorder.raw.v1","sequence":null,"source":"clob_market_ws"}
{"event_at":"2026-07-27T03:24:02.695000Z","event_fingerprint":"237f61fbfb161105e1ab465ee4115b570e6ae9b28320c4efe3e61dd2815a88ce","payload":{"connection_id":"c7dc2e4762f849c6b6f9306b6518dcab","event_at":"2026-07-27T03:24:02.695000Z","event_type":"price_change","frame_hash":"adf907aea854d15fffdbb3df494ace42626cc7bac6dfd07da1df010a0ca5d8fa","frame_index":0,"kind":"data","monotonic_ns":224627847723041,"payload":{"event_type":"price_change","market":"0x717c0e8ccd4d5c7040185188fbae28be901ca589a11a94b1b38ca36a79eccfeb","price_changes":[{"asset_id":"24254094493625419915756280046002869097156693848522361803041977572204227262166","best_ask":"0.64","best_bid":"0.63","hash":"8744832f83427dc2c8aca5e8f1f068a80b5353d8","price":"0.04","side":"BUY","size":"583.09"},{"asset_id":"41448400836309843603620980831210604935021861034693225347475867885462478926555","best_ask":"0.37","best_bid":"0.36","hash":"d498839de6741fa67fd1731ad152f29adedf1b58","price":"0.96","side":"SELL","size":"583.09"}],"timestamp":"1785122642695"},"payload_hash":"c3480e199a3c6172c8ffefffcecbda3ab493f6a9d06d1a678b35e171cc254258","raw_frame":"{\"market\":\"0x717c0e8ccd4d5c7040185188fbae28be901ca589a11a94b1b38ca36a79eccfeb\", \"price_changes\":[{\"asset_id\":\"24254094493625419915756280046002869097156693848522361803041977572204227262166\", \"price\":\"0.04\", \"size\":\"583.09\", \"side\":\"BUY\", \"hash\":\"8744832f83427dc2c8aca5e8f1f068a80b5353d8\", \"best_bid\":\"0.63\", \"best_ask\":\"0.64\"}, {\"asset_id\":\"41448400836309843603620980831210604935021861034693225347475867885462478926555\", \"price\":\"0.96\", \"size\":\"583.09\", \"side\":\"SELL\", \"hash\":\"d498839de6741fa67fd1731ad152f29adedf1b58\", \"best_bid\":\"0.36\", \"best_ask\":\"0.37\"}], \"timestamp\":\"1785122642695\", \"event_type\":\"price_change\"}","received_at":"2026-07-27T03:24:04.489901Z","schema_version":"clob-market-ws.price_change.v1","sequence":null,"server_hash":null,"server_timestamp":"1785122642695","session_id":"dd162b8dca5f43ff811d304e69a06123","source":"clob_market_ws"},"received_at":"2026-07-27T03:24:04.489901Z","record_id":"dcb0df1564e82879ba508e1bbf0631b6701b0074c5ef2405170918ec16ad256f","schema_fingerprint":"4aa3821a28b0b7c2400bc59aba4bcc0a76e971dadd19610d3ad38c768e124dc7","schema_version":"edge-lab-recorder.raw.v1","sequence":null,"source":"clob_market_ws"}
{"event_at":"2026-07-27T03:24:02.820000Z","event_fingerprint":"2657ddeeba73f26eeb61b41990242aad4b78d5957570ea04cb0fb63507080ce9","payload":{"connection_id":"c7dc2e4762f849c6b6f9306b6518dcab","event_at":"2026-07-27T03:24:02.820000Z","event_type":"price_change","frame_hash":"922c8caf8c50dedeeb8caa5ba4ddaf4a84698267f2814124eae4a1f81aabe2da","frame_index":0,"kind":"data","monotonic_ns":224627850726916,"payload":{"event_type":"price_change","market":"0x717c0e8ccd4d5c7040185188fbae28be901ca589a11a94b1b38ca36a79eccfeb","price_changes":[{"asset_id":"24254094493625419915756280046002869097156693848522361803041977572204227262166","best_ask":"0.64","best_bid":"0.63","hash":"b59c06d729785b80992d7d55edd400a405438e65","price":"0.04","side":"BUY","size":"578.09"},{"asset_id":"41448400836309843603620980831210604935021861034693225347475867885462478926555","best_ask":"0.37","best_bid":"0.36","hash":"4ef10929affd6f3daaf662e57fb9536cb6d7a24e","price":"0.96","side":"SELL","size":"578.09"}],"timestamp":"1785122642820"},"payload_hash":"3b4a905c3bd25a7f3eb344f58d61a7a55757e01faa271b9e5b2075418583bcd8","raw_frame":"{\"market\":\"0x717c0e8ccd4d5c7040185188fbae28be901ca589a11a94b1b38ca36a79eccfeb\", \"price_changes\":[{\"asset_id\":\"24254094493625419915756280046002869097156693848522361803041977572204227262166\", \"price\":\"0.04\", \"size\":\"578.09\", \"side\":\"BUY\", \"hash\":\"b59c06d729785b80992d7d55edd400a405438e65\", \"best_bid\":\"0.63\", \"best_ask\":\"0.64\"}, {\"asset_id\":\"41448400836309843603620980831210604935021861034693225347475867885462478926555\", \"price\":\"0.96\", \"size\":\"578.09\", \"side\":\"SELL\", \"hash\":\"4ef10929affd6f3daaf662e57fb9536cb6d7a24e\", \"best_bid\":\"0.36\", \"best_ask\":\"0.37\"}], \"timestamp\":\"1785122642820\", \"event_type\":\"price_change\"}","received_at":"2026-07-27T03:24:04.492902Z","schema_version":"clob-market-ws.price_change.v1","sequence":null,"server_hash":null,"server_timestamp":"1785122642820","session_id":"dd162b8dca5f43ff811d304e69a06123","source":"clob_market_ws"},"received_at":"2026-07-27T03:24:04.492902Z","record_id":"05bd1ba4475c6e313b20464d84a5477238eca9041fe2eb4e29797eaa97700dda","schema_fingerprint":"4aa3821a28b0b7c2400bc59aba4bcc0a76e971dadd19610d3ad38c768e124dc7","schema_version":"edge-lab-recorder.raw.v1","sequence":null,"source":"clob_market_ws"}
{"event_at":"2026-07-27T03:24:02.838000Z","event_fingerprint":"cbad799a53af54430b831ff1279d106ced55166a104301d89ea2b65f970fc719","payload":{"connection_id":"c7dc2e4762f849c6b6f9306b6518dcab","event_at":"2026-07-27T03:24:02.838000Z","event_type":"price_change","frame_hash":"bb985f962b70816476e16149c181ab8a3d3105c77ecc43c7acd52a804e250828","frame_index":0,"kind":"data","monotonic_ns":224627853628875,"payload":{"event_type":"price_change","market":"0x717c0e8ccd4d5c7040185188fbae28be901ca589a11a94b1b38ca36a79eccfeb","price_changes":[{"asset_id":"41448400836309843603620980831210604935021861034693225347475867885462478926555","best_ask":"0.37","best_bid":"0.36","hash":"3921c512777d282c3c48c0fd25b50dcffd8880f4","price":"0.24","side":"BUY","size":"56.39"},{"asset_id":"24254094493625419915756280046002869097156693848522361803041977572204227262166","best_ask":"0.64","best_bid":"0.63","hash":"b97e3f3d65e80672874b828e695023e707bc7cc0","price":"0.76","side":"SELL","size":"56.39"}],"timestamp":"1785122642838"},"payload_hash":"550f12cf8c9034058633dcc456fd1272d31dd1d0b80856c9d7fe85dffe55c7fe","raw_frame":"{\"market\":\"0x717c0e8ccd4d5c7040185188fbae28be901ca589a11a94b1b38ca36a79eccfeb\", \"price_changes\":[{\"asset_id\":\"41448400836309843603620980831210604935021861034693225347475867885462478926555\", \"price\":\"0.24\", \"size\":\"56.39\", \"side\":\"BUY\", \"hash\":\"3921c512777d282c3c48c0fd25b50dcffd8880f4\", \"best_bid\":\"0.36\", \"best_ask\":\"0.37\"}, {\"asset_id\":\"24254094493625419915756280046002869097156693848522361803041977572204227262166\", \"price\":\"0.76\", \"size\":\"56.39\", \"side\":\"SELL\", \"hash\":\"b97e3f3d65e80672874b828e695023e707bc7cc0\", \"best_bid\":\"0.63\", \"best_ask\":\"0.64\"}], \"timestamp\":\"1785122642838\", \"event_type\":\"price_change\"}","received_at":"2026-07-27T03:24:04.495805Z","schema_version":"clob-market-ws.price_change.v1","sequence":null,"server_hash":null,"server_timestamp":"1785122642838","session_id":"dd162b8dca5f43ff811d304e69a06123","source":"clob_market_ws"},"received_at":"2026-07-27T03:24:04.495805Z","record_id":"37c6ab5a625f10f4f76b6e91c1f70d07aa6ca7b2290e925cb2e51ed42bed6bdf","schema_fingerprint":"4aa3821a28b0b7c2400bc59aba4bcc0a76e971dadd19610d3ad38c768e124dc7","schema_version":"edge-lab-recorder.raw.v1","sequence":null,"source":"clob_market_ws"}
{"event_at":"2026-07-27T03:24:02.917000Z","event_fingerprint":"5d7ad6ce57356bf1c2f1f1006d82c10bf9a8833c259b5a375239f1944b484dcb","payload":{"connection_id":"c7dc2e4762f849c6b6f9306b6518dcab","event_at":"2026-07-27T03:24:02.917000Z","event_type":"price_change","frame_hash":"43765ca77a2748744f7a8507320eef453990467c0035e5ad882ae097dfd84a5a","frame_index":0,"kind":"data","monotonic_ns":224627855873500,"payload":{"event_type":"price_change","market":"0x717c0e8ccd4d5c7040185188fbae28be901ca589a11a94b1b38ca36a79eccfeb","price_changes":[{"asset_id":"24254094493625419915756280046002869097156693848522361803041977572204227262166","best_ask":"0.64","best_bid":"0.63","hash":"d7725995b1e5fc1a8de389143a01d6504c59d3b5","price":"0.04","side":"BUY","size":"583.09"},{"asset_id":"41448400836309843603620980831210604935021861034693225347475867885462478926555","best_ask":"0.37","best_bid":"0.36","hash":"c7a7fb90e1f980dc99eab6b9648183ffae858395","price":"0.96","side":"SELL","size":"583.09"}],"timestamp":"1785122642917"},"payload_hash":"bd24b3cff4d75ab070fd617bca46ac0abfd95664bfc35893fca8fab8785bae52","raw_frame":"{\"market\":\"0x717c0e8ccd4d5c7040185188fbae28be901ca589a11a94b1b38ca36a79eccfeb\", \"price_changes\":[{\"asset_id\":\"24254094493625419915756280046002869097156693848522361803041977572204227262166\", \"price\":\"0.04\", \"size\":\"583.09\", \"side\":\"BUY\", \"hash\":\"d7725995b1e5fc1a8de389143a01d6504c59d3b5\", \"best_bid\":\"0.63\", \"best_ask\":\"0.64\"}, {\"asset_id\":\"41448400836309843603620980831210604935021861034693225347475867885462478926555\", \"price\":\"0.96\", \"size\":\"583.09\", \"side\":\"SELL\", \"hash\":\"c7a7fb90e1f980dc99eab6b9648183ffae858395\", \"best_bid\":\"0.36\", \"best_ask\":\"0.37\"}], \"timestamp\":\"1785122642917\", \"event_type\":\"price_change\"}","received_at":"2026-07-27T03:24:04.498051Z","schema_version":"clob-market-ws.price_change.v1","sequence":null,"server_hash":null,"server_timestamp":"1785122642917","session_id":"dd162b8dca5f43ff811d304e69a06123","source":"clob_market_ws"},"received_at":"2026-07-27T03:24:04.498051Z","record_id":"a94b1c31b26e28aed9e6dce7a7b5e9f6d97d24f284361b8c4b47482156300d5f","schema_fingerprint":"4aa3821a28b0b7c2400bc59aba4bcc0a76e971dadd19610d3ad38c768e124dc7","schema_version":"edge-lab-recorder.raw.v1","sequence":null,"source":"clob_market_ws"}
{"event_at":"2026-07-27T03:24:02.946000Z","event_fingerprint":"6b8a5132b24a34a2b89a51e0c5d0435716084c9a40fd696cf89a72345c66f68d","payload":{"connection_id":"c7dc2e4762f849c6b6f9306b6518dcab","event_at":"2026-07-27T03:24:02.946000Z","event_type":"price_change","frame_hash":"5bb567b902d8609fa12a5cc663f6b2b7e4d313cd8aa24af790ffcf69c8bb16ed","frame_index":0,"kind":"data","monotonic_ns":224627858884875,"payload":{"event_type":"price_change","market":"0x717c0e8ccd4d5c7040185188fbae28be901ca589a11a94b1b38ca36a79eccfeb","price_changes":[{"asset_id":"24254094493625419915756280046002869097156693848522361803041977572204227262166","best_ask":"0.64","best_bid":"0.63","hash":"03de46677320ea4098029cfb5a80e8dc68d162d0","price":"0.42","side":"BUY","size":"176.02"},{"asset_id":"41448400836309843603620980831210604935021861034693225347475867885462478926555","best_ask":"0.37","best_bid":"0.36","hash":"6e1a5087cf69aea285cd61c6de872c75645f8213","price":"0.58","side":"SELL","size":"176.02"}],"timestamp":"1785122642946"},"payload_hash":"1ea5179ae2824294ea8a74f8af36c38b4552247779c68b887e6130c108650128","raw_frame":"{\"market\":\"0x717c0e8ccd4d5c7040185188fbae28be901ca589a11a94b1b38ca36a79eccfeb\", \"price_changes\":[{\"asset_id\":\"24254094493625419915756280046002869097156693848522361803041977572204227262166\", \"price\":\"0.42\", \"size\":\"176.02\", \"side\":\"BUY\", \"hash\":\"03de46677320ea4098029cfb5a80e8dc68d162d0\", \"best_bid\":\"0.63\", \"best_ask\":\"0.64\"}, {\"asset_id\":\"41448400836309843603620980831210604935021861034693225347475867885462478926555\", \"price\":\"0.58\", \"size\":\"176.02\", \"side\":\"SELL\", \"hash\":\"6e1a5087cf69aea285cd61c6de872c75645f8213\", \"best_bid\":\"0.36\", \"best_ask\":\"0.37\"}], \"timestamp\":\"1785122642946\", \"event_type\":\"price_change\"}","received_at":"2026-07-27T03:24:04.501061Z","schema_version":"clob-market-ws.price_change.v1","sequence":null,"server_hash":null,"server_timestamp":"1785122642946","session_id":"dd162b8dca5f43ff811d304e69a06123","source":"clob_market_ws"},"received_at":"2026-07-27T03:24:04.501061Z","record_id":"be91075f36fc082ff21e270f9281322a9a60716a49bb05542ab349b96e0e1c83","schema_fingerprint":"4aa3821a28b0b7c2400bc59aba4bcc0a76e971dadd19610d3ad38c768e124dc7","schema_version":"edge-lab-recorder.raw.v1","sequence":null,"source":"clob_market_ws"}
{"event_at":"2026-07-27T03:24:02.947000Z","event_fingerprint":"d2c77006e2664461164b1f6a74c95e3c0bf4f9f1ae24f57a3162ec652a5f42bd","payload":{"connection_id":"c7dc2e4762f849c6b6f9306b6518dcab","event_at":"2026-07-27T03:24:02.947000Z","event_type":"price_change","frame_hash":"aee6d3b11109e609de155dcfac19f22d0fc5de6f4ded35fbce5090fa249d2c60","frame_index":0,"kind":"data","monotonic_ns":224627860513416,"payload":{"event_type":"price_change","market":"0x717c0e8ccd4d5c7040185188fbae28be901ca589a11a94b1b38ca36a79eccfeb","price_changes":[{"asset_id":"24254094493625419915756280046002869097156693848522361803041977572204227262166","best_ask":"0.64","best_bid":"0.63","hash":"31e256bfc51a3dcdfa1c27df9167917534084bd7","price":"0.42","side":"BUY","size":"96.66"},{"asset_id":"41448400836309843603620980831210604935021861034693225347475867885462478926555","best_ask":"0.37","best_bid":"0.36","hash":"66ab5fd413a485e781728fae04d47614cdd833a6","price":"0.58","side":"SELL","size":"96.66"}],"timestamp":"1785122642947"},"payload_hash":"9e8bcb7a1a11de417be10264b3c6d59b8c06bcf769d9c87c0948345c7067e64b","raw_frame":"{\"market\":\"0x717c0e8ccd4d5c7040185188fbae28be901ca589a11a94b1b38ca36a79eccfeb\", \"price_changes\":[{\"asset_id\":\"24254094493625419915756280046002869097156693848522361803041977572204227262166\", \"price\":\"0.42\", \"size\":\"96.66\", \"side\":\"BUY\", \"hash\":\"31e256bfc51a3dcdfa1c27df9167917534084bd7\", \"best_bid\":\"0.63\", \"best_ask\":\"0.64\"}, {\"asset_id\":\"41448400836309843603620980831210604935021861034693225347475867885462478926555\", \"price\":\"0.58\", \"size\":\"96.66\", \"side\":\"SELL\", \"hash\":\"66ab5fd413a485e781728fae04d47614cdd833a6\", \"best_bid\":\"0.36\", \"best_ask\":\"0.37\"}], \"timestamp\":\"1785122642947\", \"event_type\":\"price_change\"}","received_at":"2026-07-27T03:24:04.502690Z","schema_version":"clob-market-ws.price_change.v1","sequence":null,"server_hash":null,"server_timestamp":"1785122642947","session_id":"dd162b8dca5f43ff811d304e69a06123","source":"clob_market_ws"},"received_at":"2026-07-27T03:24:04.502690Z","record_id":"00eaeb88142d081b978cd466cbc762b9987468a1c8216c0f38c52879c4b9928e","schema_fingerprint":"4aa3821a28b0b7c2400bc59aba4bcc0a76e971dadd19610d3ad38c768e124dc7","schema_version":"edge-lab-recorder.raw.v1","sequence":null,"source":"clob_market_ws"}
{"event_at":"2026-07-27T03:24:02.947000Z","event_fingerprint":"fdb3f39b3cccab7d108b1ccaeb767240a10905c42e8019c6487b3a8f53f557be","payload":{"connection_id":"c7dc2e4762f849c6b6f9306b6518dcab","event_at":"2026-07-27T03:24:02.947000Z","event_type":"price_change","frame_hash":"a1d90582d73e5315fd3071846e157b976dbe906aa0577ce5206bcfb7ac331850","frame_index":0,"kind":"data","monotonic_ns":224627863419375,"payload":{"event_type":"price_change","market":"0x717c0e8ccd4d5c7040185188fbae28be901ca589a11a94b1b38ca36a79eccfeb","price_changes":[{"asset_id":"24254094493625419915756280046002869097156693848522361803041977572204227262166","best_ask":"0.64","best_bid":"0.63","hash":"95d6a6bf224df7c8a4d52d7b9a530dc117a98914","price":"0.42","side":"BUY","size":"17.3"},{"asset_id":"41448400836309843603620980831210604935021861034693225347475867885462478926555","best_ask":"0.37","best_bid":"0.36","hash":"039df2e7d3db7fd54aa256829026848b5e7825e5","price":"0.58","side":"SELL","size":"17.3"}],"timestamp":"1785122642947"},"payload_hash":"253d58f3f8dbd48dd7efff1342ac1d9a50cb2082908c97fe5aca9fae42884b07","raw_frame":"{\"market\":\"0x717c0e8ccd4d5c7040185188fbae28be901ca589a11a94b1b38ca36a79eccfeb\", \"price_changes\":[{\"asset_id\":\"24254094493625419915756280046002869097156693848522361803041977572204227262166\", \"price\":\"0.42\", \"size\":\"17.3\", \"side\":\"BUY\", \"hash\":\"95d6a6bf224df7c8a4d52d7b9a530dc117a98914\", \"best_bid\":\"0.63\", \"best_ask\":\"0.64\"}, {\"asset_id\":\"41448400836309843603620980831210604935021861034693225347475867885462478926555\", \"price\":\"0.58\", \"size\":\"17.3\", \"side\":\"SELL\", \"hash\":\"039df2e7d3db7fd54aa256829026848b5e7825e5\", \"best_bid\":\"0.36\", \"best_ask\":\"0.37\"}], \"timestamp\":\"1785122642947\", \"event_type\":\"price_change\"}","received_at":"2026-07-27T03:24:04.505597Z","schema_version":"clob-market-ws.price_change.v1","sequence":null,"server_hash":null,"server_timestamp":"1785122642947","session_id":"dd162b8dca5f43ff811d304e69a06123","source":"clob_market_ws"},"received_at":"2026-07-27T03:24:04.505597Z","record_id":"7a50bfdf9b22a5dd9c31ae1e7cce2fa3813da0fecb8e3ef6277b0da94ba4db5f","schema_fingerprint":"4aa3821a28b0b7c2400bc59aba4bcc0a76e971dadd19610d3ad38c768e124dc7","schema_version":"edge-lab-recorder.raw.v1","sequence":null,"source":"clob_market_ws"}
{"event_at":"2026-07-27T03:24:02.954000Z","event_fingerprint":"48a71eec72befa04806d8e48ec43ee789c77b9c946d85389b198549fa4a5722b","payload":{"connection_id":"c7dc2e4762f849c6b6f9306b6518dcab","event_at":"2026-07-27T03:24:02.954000Z","event_type":"price_change","frame_hash":"cae55537090ba09e27b21b2621211fb0248b2d551190feadcf77629588deb510","frame_index":0,"kind":"data","monotonic_ns":224627866423458,"payload":{"event_type":"price_change","market":"0x717c0e8ccd4d5c7040185188fbae28be901ca589a11a94b1b38ca36a79eccfeb","price_changes":[{"asset_id":"24254094493625419915756280046002869097156693848522361803041977572204227262166","best_ask":"0.64","best_bid":"0.63","hash":"6106c1f922557d3dc1af0423c8f09ce36286daca","price":"0.01","side":"BUY","size":"5458.02"},{"asset_id":"41448400836309843603620980831210604935021861034693225347475867885462478926555","best_ask":"0.37","best_bid":"0.36","hash":"01d2a5ba3aaab6bae5a72caeb61b2d4a867f21bc","price":"0.99","side":"SELL","size":"5458.02"}],"timestamp":"1785122642954"},"payload_hash":"b39d3cdd42436eb759426464ac63297eb430affafdb19ec91f2763880f475691","raw_frame":"{\"market\":\"0x717c0e8ccd4d5c7040185188fbae28be901ca589a11a94b1b38ca36a79eccfeb\", \"price_changes\":[{\"asset_id\":\"24254094493625419915756280046002869097156693848522361803041977572204227262166\", \"price\":\"0.01\", \"size\":\"5458.02\", \"side\":\"BUY\", \"hash\":\"6106c1f922557d3dc1af0423c8f09ce36286daca\", \"best_bid\":\"0.63\", \"best_ask\":\"0.64\"}, {\"asset_id\":\"41448400836309843603620980831210604935021861034693225347475867885462478926555\", \"price\":\"0.99\", \"size\":\"5458.02\", \"side\":\"SELL\", \"hash\":\"01d2a5ba3aaab6bae5a72caeb61b2d4a867f21bc\", \"best_bid\":\"0.36\", \"best_ask\":\"0.37\"}], \"timestamp\":\"1785122642954\", \"event_type\":\"price_change\"}","received_at":"2026-07-27T03:24:04.508597Z","schema_version":"clob-market-ws.price_change.v1","sequence":null,"server_hash":null,"server_timestamp":"1785122642954","session_id":"dd162b8dca5f43ff811d304e69a06123","source":"clob_market_ws"},"received_at":"2026-07-27T03:24:04.508597Z","record_id":"63182ff02a2cd54d2969e2e8f7338cbb6514e4439afa6cf7e2552ecf6b4b9506","schema_fingerprint":"4aa3821a28b0b7c2400bc59aba4bcc0a76e971dadd19610d3ad38c768e124dc7","schema_version":"edge-lab-recorder.raw.v1","sequence":null,"source":"clob_market_ws"}
{"event_at":"2026-07-27T03:24:02.968000Z","event_fingerprint":"7ced2a816af8ce75ebb0bb32eb6e12cc2008ac06cdd72081fa5470a84291fa83","payload":{"connection_id":"c7dc2e4762f849c6b6f9306b6518dcab","event_at":"2026-07-27T03:24:02.968000Z","event_type":"price_change","frame_hash":"9735133dbdfc0059a59b85ed9e748456961f2fa8b55fa28ad9fb286f033e400b","frame_index":0,"kind":"data","monotonic_ns":224627869367000,"payload":{"event_type":"price_change","market":"0x717c0e8ccd4d5c7040185188fbae28be901ca589a11a94b1b38ca36a79eccfeb","price_changes":[{"asset_id":"24254094493625419915756280046002869097156693848522361803041977572204227262166","best_ask":"0.64","best_bid":"0.63","hash":"d6be726259cd6f850558deaf86a574511c224f8c","price":"0.04","side":"BUY","size":"578.09"},{"asset_id":"41448400836309843603620980831210604935021861034693225347475867885462478926555","best_ask":"0.37","best_bid":"0.36","hash":"2b520a9e660b05df5906c7a3ed59f9a905437412","price":"0.96","side":"SELL","size":"578.09"}],"timestamp":"1785122642968"},"payload_hash":"8098a0464c287ad6806436c91af87a1561c16fd0ccaac52ecda4c5a520e99398","raw_frame":"{\"market\":\"0x717c0e8ccd4d5c7040185188fbae28be901ca589a11a94b1b38ca36a79eccfeb\", \"price_changes\":[{\"asset_id\":\"24254094493625419915756280046002869097156693848522361803041977572204227262166\", \"price\":\"0.04\", \"size\":\"578.09\", \"side\":\"BUY\", \"hash\":\"d6be726259cd6f850558deaf86a574511c224f8c\", \"best_bid\":\"0.63\", \"best_ask\":\"0.64\"}, {\"asset_id\":\"41448400836309843603620980831210604935021861034693225347475867885462478926555\", \"price\":\"0.96\", \"size\":\"578.09\", \"side\":\"SELL\", \"hash\":\"2b520a9e660b05df5906c7a3ed59f9a905437412\", \"best_bid\":\"0.36\", \"best_ask\":\"0.37\"}], \"timestamp\":\"1785122642968\", \"event_type\":\"price_change\"}","received_at":"2026-07-27T03:24:04.511540Z","schema_version":"clob-market-ws.price_change.v1","sequence":null,"server_hash":null,"server_timestamp":"1785122642968","session_id":"dd162b8dca5f43ff811d304e69a06123","source":"clob_market_ws"},"received_at":"2026-07-27T03:24:04.511540Z","record_id":"f470f84bd01d1beb9918862329d45ea45ca90b7b1204656775867b9253ea4847","schema_fingerprint":"4aa3821a28b0b7c2400bc59aba4bcc0a76e971dadd19610d3ad38c768e124dc7","schema_version":"edge-lab-recorder.raw.v1","sequence":null,"source":"clob_market_ws"}
{"event_at":"2026-07-27T03:24:02.973000Z","event_fingerprint":"0c573ba81c477ff82de0d7b4cd3a7c1c5bbcd8f275334a2e814d70a60a435bf8","payload":{"connection_id":"c7dc2e4762f849c6b6f9306b6518dcab","event_at":"2026-07-27T03:24:02.973000Z","event_type":"price_change","frame_hash":"8572c1c2ce3de0f28c86544ed9b86cda42bf0b226991343a81a5ec57fdf30591","frame_index":0,"kind":"data","monotonic_ns":224627872202166,"payload":{"event_type":"price_change","market":"0x717c0e8ccd4d5c7040185188fbae28be901ca589a11a94b1b38ca36a79eccfeb","price_changes":[{"asset_id":"24254094493625419915756280046002869097156693848522361803041977572204227262166","best_ask":"0.64","best_bid":"0.63","hash":"11e442e415a59d1a84bb2c360d4d6c6aaff9d452","price":"0.43","side":"BUY","size":"94.71"},{"asset_id":"41448400836309843603620980831210604935021861034693225347475867885462478926555","best_ask":"0.37","best_bid":"0.36","hash":"ce0950df15b50e6810ee1965a8b1d367286bc286","price":"0.57","side":"SELL","size":"94.71"}],"timestamp":"1785122642973"},"payload_hash":"cb5d7c5c0dc4c1849590bd02a11b4baba7ee0f3af42a49514feffb798d346f3a","raw_frame":"{\"market\":\"0x717c0e8ccd4d5c7040185188fbae28be901ca589a11a94b1b38ca36a79eccfeb\", \"price_changes\":[{\"asset_id\":\"24254094493625419915756280046002869097156693848522361803041977572204227262166\", \"price\":\"0.43\", \"size\":\"94.71\", \"side\":\"BUY\", \"hash\":\"11e442e415a59d1a84bb2c360d4d6c6aaff9d452\", \"best_bid\":\"0.63\", \"best_ask\":\"0.64\"}, {\"asset_id\":\"41448400836309843603620980831210604935021861034693225347475867885462478926555\", \"price\":\"0.57\", \"size\":\"94.71\", \"side\":\"SELL\", \"hash\":\"ce0950df15b50e6810ee1965a8b1d367286bc286\", \"best_bid\":\"0.36\", \"best_ask\":\"0.37\"}], \"timestamp\":\"1785122642973\", \"event_type\":\"price_change\"}","received_at":"2026-07-27T03:24:04.514377Z","schema_version":"clob-market-ws.price_change.v1","sequence":null,"server_hash":null,"server_timestamp":"1785122642973","session_id":"dd162b8dca5f43ff811d304e69a06123","source":"clob_market_ws"},"received_at":"2026-07-27T03:24:04.514377Z","record_id":"d700e0e87b7ba6cc288d5190f32ff2811c5ad7eee9b1168a131cdc88e3d1ff0c","schema_fingerprint":"4aa3821a28b0b7c2400bc59aba4bcc0a76e971dadd19610d3ad38c768e124dc7","schema_version":"edge-lab-recorder.raw.v1","sequence":null,"source":"clob_market_ws"}
{"event_at":"2026-07-27T03:24:02.984000Z","event_fingerprint":"e57ed7e1ba1d7f56a828d9f5dc663a149f46428c3abf7e133c6f699e3ecd0209","payload":{"connection_id":"c7dc2e4762f849c6b6f9306b6518dcab","event_at":"2026-07-27T03:24:02.984000Z","event_type":"price_change","frame_hash":"9ffb752b26518491785c33002c1cfdc2dc96eb29dfd129b33eb76a201142dc71","frame_index":0,"kind":"data","monotonic_ns":224627875199916,"payload":{"event_type":"price_change","market":"0x717c0e8ccd4d5c7040185188fbae28be901ca589a11a94b1b38ca36a79eccfeb","price_changes":[{"asset_id":"24254094493625419915756280046002869097156693848522361803041977572204227262166","best_ask":"0.64","best_bid":"0.63","hash":"1661a3ecf1ec76cc8339917f4cf8b9a62f9fdf69","price":"0.01","side":"BUY","size":"5453.02"},{"asset_id":"41448400836309843603620980831210604935021861034693225347475867885462478926555","best_ask":"0.37","best_bid":"0.36","hash":"902329121129b05ca60d18cd3a26bddae5032182","price":"0.99","side":"SELL","size":"5453.02"}],"timestamp":"1785122642984"},"payload_hash":"49787fd62a7d8545c240b37a559eeb0590ace15288cd994e3e1fb649a1c1260b","raw_frame":"{\"market\":\"0x717c0e8ccd4d5c7040185188fbae28be901ca589a11a94b1b38ca36a79eccfeb\", \"price_changes\":[{\"asset_id\":\"24254094493625419915756280046002869097156693848522361803041977572204227262166\", \"price\":\"0.01\", \"size\":\"5453.02\", \"side\":\"BUY\", \"hash\":\"1661a3ecf1ec76cc8339917f4cf8b9a62f9fdf69\", \"best_bid\":\"0.63\", \"best_ask\":\"0.64\"}, {\"asset_id\":\"41448400836309843603620980831210604935021861034693225347475867885462478926555\", \"price\":\"0.99\", \"size\":\"5453.02\", \"side\":\"SELL\", \"hash\":\"902329121129b05ca60d18cd3a26bddae5032182\", \"best_bid\":\"0.36\", \"best_ask\":\"0.37\"}], \"timestamp\":\"1785122642984\", \"event_type\":\"price_change\"}","received_at":"2026-07-27T03:24:04.517375Z","schema_version":"clob-market-ws.price_change.v1","sequence":null,"server_hash":null,"server_timestamp":"1785122642984","session_id":"dd162b8dca5f43ff811d304e69a06123","source":"clob_market_ws"},"received_at":"2026-07-27T03:24:04.517375Z","record_id":"247d4efb831aa8e77d2a391e0b84e4092d228cfdd4bfdfe483ce116f3d066309","schema_fingerprint":"4aa3821a28b0b7c2400bc59aba4bcc0a76e971dadd19610d3ad38c768e124dc7","schema_version":"edge-lab-recorder.raw.v1","sequence":null,"source":"clob_market_ws"}
{"event_at":"2026-07-27T03:24:03.011000Z","event_fingerprint":"1073710d61d0e5613b459067acb5373a635947717af158fa3dc21d8bfb51ba93","payload":{"connection_id":"c7dc2e4762f849c6b6f9306b6518dcab","event_at":"2026-07-27T03:24:03.011000Z","event_type":"price_change","frame_hash":"74bb7134e4fe49b9b097fa1c33407c82ca664bd81bd30a38ae6f62e599933540","frame_index":0,"kind":"data","monotonic_ns":224627877103458,"payload":{"event_type":"price_change","market":"0x717c0e8ccd4d5c7040185188fbae28be901ca589a11a94b1b38ca36a79eccfeb","price_changes":[{"asset_id":"24254094493625419915756280046002869097156693848522361803041977572204227262166","best_ask":"0.64","best_bid":"0.63","hash":"94d1355783549565df8af8b9d040b638e6c663f8","price":"0.65","side":"SELL","size":"15.6"},{"asset_id":"41448400836309843603620980831210604935021861034693225347475867885462478926555","best_ask":"0.37","best_bid":"0.36","hash":"977283abaadd318a8d61d37069b01db45c1b0ed4","price":"0.35","side":"BUY","size":"15.6"}],"timestamp":"1785122643011"},"payload_hash":"d5a371dd18f14d0a1349f70afc70ef5cc48549ad848b78af021ec6b16e4e4d33","raw_frame":"{\"market\":\"0x717c0e8ccd4d5c7040185188fbae28be901ca589a11a94b1b38ca36a79eccfeb\", \"price_changes\":[{\"asset_id\":\"24254094493625419915756280046002869097156693848522361803041977572204227262166\", \"price\":\"0.65\", \"size\":\"15.6\", \"side\":\"SELL\", \"hash\":\"94d1355783549565df8af8b9d040b638e6c663f8\", \"best_bid\":\"0.63\", \"best_ask\":\"0.64\"}, {\"asset_id\":\"41448400836309843603620980831210604935021861034693225347475867885462478926555\", \"price\":\"0.35\", \"size\":\"15.6\", \"side\":\"BUY\", \"hash\":\"977283abaadd318a8d61d37069b01db45c1b0ed4\", \"best_bid\":\"0.36\", \"best_ask\":\"0.37\"}], \"timestamp\":\"1785122643011\", \"event_type\":\"price_change\"}","received_at":"2026-07-27T03:24:04.519286Z","schema_version":"clob-market-ws.price_change.v1","sequence":null,"server_hash":null,"server_timestamp":"1785122643011","session_id":"dd162b8dca5f43ff811d304e69a06123","source":"clob_market_ws"},"received_at":"2026-07-27T03:24:04.519286Z","record_id":"7986f2e60cfbea328f60b06d0b216cbec28d00b3bfb408db74381ca02c6c3508","schema_fingerprint":"4aa3821a28b0b7c2400bc59aba4bcc0a76e971dadd19610d3ad38c768e124dc7","schema_version":"edge-lab-recorder.raw.v1","sequence":null,"source":"clob_market_ws"}
