{"event_at":"2026-07-27T03:25:15.243000Z","event_fingerprint":"3faddbc9363bef742ab4fae0b4ef82bad547bcfe293cc77705e245124ebd45c8","payload":{"connection_id":"c7dc2e4762f849c6b6f9306b6518dcab","event_at":"2026-07-27T03:25:15.243000Z","event_type":"price_change","frame_hash":"256251a76d8c5d66b549adff0cb7643e6105ea57753707c89fdc2e674fddfa74","frame_index":0,"kind":"data","monotonic_ns":224700240858125,"payload":{"event_type":"price_change","market":"0x717c0e8ccd4d5c7040185188fbae28be901ca589a11a94b1b38ca36a79eccfeb","price_changes":[{"asset_id":"41448400836309843603620980831210604935021861034693225347475867885462478926555","best_ask":"0.36","best_bid":"0.35","hash":"27263c4093485364879af212ec71885cb527fc1c","price":"0.34","side":"BUY","size":"5.21"},{"asset_id":"24254094493625419915756280046002869097156693848522361803041977572204227262166","best_ask":"0.65","best_bid":"0.64","hash":"802bac8e0bbf202dddb1214d7029ba2513c822ec","price":"0.66","side":"SELL","size":"5.21"}],"timestamp":"1785122715243"},"payload_hash":"aeae8e4addddfeea15cb06cb892ceecd4dbb1d175d0d9feab0f16ec57c37b1ab","raw_frame":"{\"market\":\"0x717c0e8ccd4d5c7040185188fbae28be901ca589a11a94b1b38ca36a79eccfeb\", \"price_changes\":[{\"asset_id\":\"41448400836309843603620980831210604935021861034693225347475867885462478926555\", \"price\":\"0.34\", \"size\":\"5.21\", \"side\":\"BUY\", \"hash\":\"27263c4093485364879af212ec71885cb527fc1c\", \"best_bid\":\"0.35\", \"best_ask\":\"0.36\"}, {\"asset_id\":\"24254094493625419915756280046002869097156693848522361803041977572204227262166\", \"price\":\"0.66\", \"size\":\"5.21\", \"side\":\"SELL\", \"hash\":\"802bac8e0bbf202dddb1214d7029ba2513c822ec\", \"best_bid\":\"0.64\", \"best_ask\":\"0.65\"}], \"timestamp\":\"1785122715243\", \"event_type\":\"price_change\"}","received_at":"2026-07-27T03:25:16.881826Z","schema_version":"clob-market-ws.price_change.v1","sequence":null,"server_hash":null,"server_timestamp":"1785122715243","session_id":"dd162b8dca5f43ff811d304e69a06123","source":"clob_market_ws"},"received_at":"2026-07-27T03:25:16.881826Z","record_id":"2668dc5b663970742f80bcb70b474880fe5a05fef38a91c721163a184fa29410","schema_fingerprint":"4aa3821a28b0b7c2400bc59aba4bcc0a76e971dadd19610d3ad38c768e124dc7","schema_version":"edge-lab-recorder.raw.v1","sequence":null,"source":"clob_market_ws"}
{"event_at":"2026-07-27T03:25:15.255000Z","event_fingerprint":"708b30a7050fb28c196e55518a18e81a69bd3795af372150e475716b8402a2fa","payload":{"connection_id":"c7dc2e4762f849c6b6f9306b6518dcab","event_at":"2026-07-27T03:25:15.255000Z","event_type":"price_change","frame_hash":"ba22dbd5ecc6ff06c6bbb3b755f4247a4ceb123ed67ac294d1a2be62c60bdf8f","frame_index":0,"kind":"data","monotonic_ns":224700252853125,"payload":{"event_type":"price_change","market":"0x717c0e8ccd4d5c7040185188fbae28be901ca589a11a94b1b38ca36a79eccfeb","price_changes":[{"asset_id":"24254094493625419915756280046002869097156693848522361803041977572204227262166","best_ask":"0.65","best_bid":"0.64","hash":"b19ed9136c183dd44aea1ae449d0f50df076cda0","price":"0.01","side":"BUY","size":"5458.02"},{"asset_id":"41448400836309843603620980831210604935021861034693225347475867885462478926555","best_ask":"0.36","best_bid":"0.35","hash":"20611279328fea315c130788320db3d6213b4659","price":"0.99","side":"SELL","size":"5458.02"}],"timestamp":"1785122715255"},"payload_hash":"87f8380cc2a1dadc2d3b5a37e676fd4a6679e353b690d038bb0ee32e2b86ebe0","raw_frame":"{\"market\":\"0x717c0e8ccd4d5c7040185188fbae28be901ca589a11a94b1b38ca36a79eccfeb\", \"price_changes\":[{\"asset_id\":\"24254094493625419915756280046002869097156693848522361803041977572204227262166\", \"price\":\"0.01\", \"size\":\"5458.02\", \"side\":\"BUY\", \"hash\":\"b19ed9136c183dd44aea1ae449d0f50df076cda0\", \"best_bid\":\"0.64\", \"best_ask\":\"0.65\"}, {\"asset_id\":\"41448400836309843603620980831210604935021861034693225347475867885462478926555\", \"price\":\"0.99\", \"size\":\"5458.02\", \"side\":\"SELL\", \"hash\":\"20611279328fea315c130788320db3d6213b4659\", \"best_bid\":\"0.35\", \"best_ask\":\"0.36\"}], \"timestamp\":\"1785122715255\", \"event_type\":\"price_change\"}","received_at":"2026-07-27T03:25:16.893820Z","schema_version":"clob-market-ws.price_change.v1","sequence":null,"server_hash":null,"server_timestamp":"1785122715255","session_id":"dd162b8dca5f43ff811d304e69a06123","source":"clob_market_ws"},"received_at":"2026-07-27T03:25:16.893820Z","record_id":"562102e62c9ec1693a51d62960eec78889d125e4bd8b36a6ce581918b57661f3","schema_fingerprint":"4aa3821a28b0b7c2400bc59aba4bcc0a76e971dadd19610d3ad38c768e124dc7","schema_version":"edge-lab-recorder.raw.v1","sequence":null,"source":"clob_market_ws"}
{"event_at":"2026-07-27T03:25:15.259000Z","event_fingerprint":"5896f2c579f36ea26f308d2f626148ad0c25e6620e271b21a1553c0e36ee3179","payload":{"connection_id":"c7dc2e4762f849c6b6f9306b6518dcab","event_at":"2026-07-27T03:25:15.259000Z","event_type":"price_change","frame_hash":"259ff43b5a026fd0cff541d2fc230cd8442839f7c0b5e97575da6d1280e033dd","frame_index":0,"kind":"data","monotonic_ns":224700257552625,"payload":{"event_type":"price_change","market":"0x717c0e8ccd4d5c7040185188fbae28be901ca589a11a94b1b38ca36a79eccfeb","price_changes":[{"asset_id":"41448400836309843603620980831210604935021861034693225347475867885462478926555","best_ask":"0.36","best_bid":"0.35","hash":"97382b5f5f49cec8ba1b4217e54489ad4170b13c","price":"0.32","side":"BUY","size":"338.21"},{"asset_id":"24254094493625419915756280046002869097156693848522361803041977572204227262166","best_ask":"0.65","best_bid":"0.64","hash":"33076eb536fb9c2d3ae1f3173bf357a0c1328c4a","price":"0.68","side":"SELL","size":"338.21"}],"timestamp":"1785122715259"},"payload_hash":"360b915acdc27778f67cf2d3131e3069d06399c15193dce8794e8a0b876e6668","raw_frame":"{\"market\":\"0x717c0e8ccd4d5c7040185188fbae28be901ca589a11a94b1b38ca36a79eccfeb\", \"price_changes\":[{\"asset_id\":\"41448400836309843603620980831210604935021861034693225347475867885462478926555\", \"price\":\"0.32\", \"size\":\"338.21\", \"side\":\"BUY\", \"hash\":\"97382b5f5f49cec8ba1b4217e54489ad4170b13c\", \"best_bid\":\"0.35\", \"best_ask\":\"0.36\"}, {\"asset_id\":\"24254094493625419915756280046002869097156693848522361803041977572204227262166\", \"price\":\"0.68\", \"size\":\"338.21\", \"side\":\"SELL\", \"hash\":\"33076eb536fb9c2d3ae1f3173bf357a0c1328c4a\", \"best_bid\":\"0.64\", \"best_ask\":\"0.65\"}], \"timestamp\":\"1785122715259\", \"event_type\":\"price_change\"}","received_at":"2026-07-27T03:25:16.898519Z","schema_version":"clob-market-ws.price_change.v1","sequence":null,"server_hash":null,"server_timestamp":"1785122715259","session_id":"dd162b8dca5f43ff811d304e69a06123","source":"clob_market_ws"},"received_at":"2026-07-27T03:25:16.898519Z","record_id":"a9da7f6ae03b814a1e5ed53b9c2974104094cbac06f74639c54a8308ef92ad52","schema_fingerprint":"4aa3821a28b0b7c2400bc59aba4bcc0a76e971dadd19610d3ad38c768e124dc7","schema_version":"edge-lab-recorder.raw.v1","sequence":null,"source":"clob_market_ws"}
{"event_at":"2026-07-27T03:25:15.260000Z","event_fingerprint":"f4b2186e0144d4e0fd12146fe734b7ae250157d07c279f9cdb321ce1a6907648","payload":{"connection_id":"c7dc2e4762f849c6b6f9306b6518dcab","event_at":"2026-07-27T03:25:15.260000Z","event_type":"price_change","frame_hash":"c9b4790a9609aee0386fe79d763e335eb87c77a3e6ecf20ad427398927d7aa72","frame_index":0,"kind":"data","monotonic_ns":224700261240250,"payload":{"event_type":"price_change","market":"0x717c0e8ccd4d5c7040185188fbae28be901ca589a11a94b1b38ca36a79eccfeb","price_changes":[{"asset_id":"24254094493625419915756280046002869097156693848522361803041977572204227262166","best_ask":"0.65","best_bid":"0.64","hash":"04bbd0121da551022d06237c4afda921f7f22d19","price":"0.63","side":"BUY","size":"106"},{"asset_id":"41448400836309843603620980831210604935021861034693225347475867885462478926555","best_ask":"0.36","best_bid":"0.35","hash":"628b31de9abe534c6b1f9b93744d88300bc7a5ee","price":"0.37","side":"SELL","size":"106"}],"timestamp":"1785122715260"},"payload_hash":"adbcde41510de2389750dc6c753a883907d5eb8244221a788791cfaac9714117","raw_frame":"{\"market\":\"0x717c0e8ccd4d5c7040185188fbae28be901ca589a11a94b1b38ca36a79eccfeb\", \"price_changes\":[{\"asset_id\":\"24254094493625419915756280046002869097156693848522361803041977572204227262166\", \"price\":\"0.63\", \"size\":\"106\", \"side\":\"BUY\", \"hash\":\"04bbd0121da551022d06237c4afda921f7f22d19\", \"best_bid\":\"0.64\", \"best_ask\":\"0.65\"}, {\"asset_id\":\"41448400836309843603620980831210604935021861034693225347475867885462478926555\", \"price\":\"0.37\", \"size\":\"106\", \"side\":\"SELL\", \"hash\":\"628b31de9abe534c6b1f9b93744d88300bc7a5ee\", \"best_bid\":\"0.35\", \"best_ask\":\"0.36\"}], \"timestamp\":\"1785122715260\", \"event_type\":\"price_change\"}","received_at":"2026-07-27T03:25:16.902206Z","schema_version":"clob-market-ws.price_change.v1","sequence":null,"server_hash":null,"server_timestamp":"1785122715260","session_id":"dd162b8dca5f43ff811d304e69a06123","source":"clob_market_ws"},"received_at":"2026-07-27T03:25:16.902206Z","record_id":"855223013d34921d23c993f1e637bef1a6adaa51169d72ec9faf563f7f2be911","schema_fingerprint":"4aa3821a28b0b7c2400bc59aba4bcc0a76e971dadd19610d3ad38c768e124dc7","schema_version":"edge-lab-recorder.raw.v1","sequence":null,"source":"clob_market_ws"}
{"event_at":"2026-07-27T03:25:15.265000Z","event_fingerprint":"8feddd3b77b5f4c782cc58da7c31645b524a17c31a8b562aa6fe223252c1333e","payload":{"connection_id":"c7dc2e4762f849c6b6f9306b6518dcab","event_at":"2026-07-27T03:25:15.265000Z","event_type":"price_change","frame_hash":"1931afdb6d5fe6bd5a933fde988c6bf882c61ff85ab7cd52986bd76d3cf0744a","frame_index":0,"kind":"data","monotonic_ns":224700265747791,"payload":{"event_type":"price_change","market":"0x717c0e8ccd4d5c7040185188fbae28be901ca589a11a94b1b38ca36a79eccfeb","price_changes":[{"asset_id":"24254094493625419915756280046002869097156693848522361803041977572204227262166","best_ask":"0.65","best_bid":"0.64","hash":"2f93f1f60ba4d7a8b67f92473b1fe7215f544dde","price":"0.64","side":"BUY","size":"334"},{"asset_id":"41448400836309843603620980831210604935021861034693225347475867885462478926555","best_ask":"0.36","best_bid":"0.35","hash":"c822d36a63a9e09bdac9cda406b6d173461fe02d","price":"0.36","side":"SELL","size":"334"}],"timestamp":"1785122715265"},"payload_hash":"e58bf303cedab6db825f1c7daa2795aefe01d3c8121a9090ab25f5e6b2367cfb","raw_frame":"{\"market\":\"0x717c0e8ccd4d5c7040185188fbae28be901ca589a11a94b1b38ca36a79eccfeb\", \"price_changes\":[{\"asset_id\":\"24254094493625419915756280046002869097156693848522361803041977572204227262166\", \"price\":\"0.64\", \"size\":\"334\", \"side\":\"BUY\", \"hash\":\"2f93f1f60ba4d7a8b67f92473b1fe7215f544dde\", \"best_bid\":\"0.64\", \"best_ask\":\"0.65\"}, {\"asset_id\":\"41448400836309843603620980831210604935021861034693225347475867885462478926555\", \"price\":\"0.36\", \"size\":\"334\", \"side\":\"SELL\", \"hash\":\"c822d36a63a9e09bdac9cda406b6d173461fe02d\", \"best_bid\":\"0.35\", \"best_ask\":\"0.36\"}], \"timestamp\":\"1785122715265\", \"event_type\":\"price_change\"}","received_at":"2026-07-27T03:25:16.906715Z","schema_version":"clob-market-ws.price_change.v1","sequence":null,"server_hash":null,"server_timestamp":"1785122715265","session_id":"dd162b8dca5f43ff811d304e69a06123","source":"clob_market_ws"},"received_at":"2026-07-27T03:25:16.906715Z","record_id":"134ffcb7ba1ac44762cfe04361aeb1c5fce75de532533c3fe10ab3f903e74113","schema_fingerprint":"4aa3821a28b0b7c2400bc59aba4bcc0a76e971dadd19610d3ad38c768e124dc7","schema_version":"edge-lab-recorder.raw.v1","sequence":null,"source":"clob_market_ws"}
{"event_at":"2026-07-27T03:25:15.278000Z","event_fingerprint":"6bf0c63a27c993dcfe6675061ac2c221de019d04f8f544cf1eeee3187a880207","payload":{"connection_id":"c7dc2e4762f849c6b6f9306b6518dcab","event_at":"2026-07-27T03:25:15.278000Z","event_type":"price_change","frame_hash":"ea67439c2566ab95b8ad5c5a1a657470fd225a46ebd87b95bbc8fe973ec02549","frame_index":0,"kind":"data","monotonic_ns":224700269643208,"payload":{"event_type":"price_change","market":"0x717c0e8ccd4d5c7040185188fbae28be901ca589a11a94b1b38ca36a79eccfeb","price_changes":[{"asset_id":"24254094493625419915756280046002869097156693848522361803041977572204227262166","best_ask":"0.65","best_bid":"0.64","hash":"f15746197b6fa5579b86494d79b10d7314daa675","price":"0.01","side":"BUY","size":"5453.02"},{"asset_id":"41448400836309843603620980831210604935021861034693225347475867885462478926555","best_ask":"0.36","best_bid":"0.35","hash":"a9ab564b8e566217c192a07c8e97620a89e7d1e3","price":"0.99","side":"SELL","size":"5453.02"}],"timestamp":"1785122715278"},"payload_hash":"7a93ab7ef394bbd560445ff989b4c131ffe52957a4682365b4b2387851a4470f","raw_frame":"{\"market\":\"0x717c0e8ccd4d5c7040185188fbae28be901ca589a11a94b1b38ca36a79eccfeb\", \"price_changes\":[{\"asset_id\":\"24254094493625419915756280046002869097156693848522361803041977572204227262166\", \"price\":\"0.01\", \"size\":\"5453.02\", \"side\":\"BUY\", \"hash\":\"f15746197b6fa5579b86494d79b10d7314daa675\", \"best_bid\":\"0.64\", \"best_ask\":\"0.65\"}, {\"asset_id\":\"41448400836309843603620980831210604935021861034693225347475867885462478926555\", \"price\":\"0.99\", \"size\":\"5453.02\", \"side\":\"SELL\", \"hash\":\"a9ab564b8e566217c192a07c8e97620a89e7d1e3\", \"best_bid\":\"0.35\", \"best_ask\":\"0.36\"}], \"timestamp\":\"1785122715278\", \"event_type\":\"price_change\"}","received_at":"2026-07-27T03:25:16.910610Z","schema_version":"clob-market-ws.price_change.v1","sequence":null,"server_hash":null,"server_timestamp":"1785122715278","session_id":"dd162b8dca5f43ff811d304e69a06123","source":"clob_market_ws"},"received_at":"2026-07-27T03:25:16.910610Z","record_id":"857d25ded7684464e5045fe2481c9c600263e205bcc670bdddba630e99143bef","schema_fingerprint":"4aa3821a28b0b7c2400bc59aba4bcc0a76e971dadd19610d3ad38c768e124dc7","schema_version":"edge-lab-recorder.raw.v1","sequence":null,"source":"clob_market_ws"}
{"event_at":"2026-07-27T03:25:15.301000Z","event_fingerprint":"9829c8ac1c228ce38ddf0419975e2a78e74dcf7f46b8250ec2e569f93fac94af","payload":{"connection_id":"c7dc2e4762f849c6b6f9306b6518dcab","event_at":"2026-07-27T03:25:15.301000Z","event_type":"price_change","frame_hash":"732b8c9a4e8a23d1907998430f5e57414efb8f628d345512a14d35eead381d68","frame_index":0,"kind":"data","monotonic_ns":224700274567583,"payload":{"event_type":"price_change","market":"0x717c0e8ccd4d5c7040185188fbae28be901ca589a11a94b1b38ca36a79eccfeb","price_changes":[{"asset_id":"24254094493625419915756280046002869097156693848522361803041977572204227262166","best_ask":"0.65","best_bid":"0.64","hash":"e5c1210daf7c1f19bcb65fa663788e1965c78d8a","price":"0.04","side":"BUY","size":"583.09"},{"asset_id":"41448400836309843603620980831210604935021861034693225347475867885462478926555","best_ask":"0.36","best_bid":"0.35","hash":"fc464d06a9c65762dbf1f042dc50f7526470636d","price":"0.96","side":"SELL","size":"583.09"}],"timestamp":"1785122715301"},"payload_hash":"59050fcf6417a75805cb8e995dd113cce422715649fab9ef8a19450aa4881a36","raw_frame":"{\"market\":\"0x717c0e8ccd4d5c7040185188fbae28be901ca589a11a94b1b38ca36a79eccfeb\", \"price_changes\":[{\"asset_id\":\"24254094493625419915756280046002869097156693848522361803041977572204227262166\", \"price\":\"0.04\", \"size\":\"583.09\", \"side\":\"BUY\", \"hash\":\"e5c1210daf7c1f19bcb65fa663788e1965c78d8a\", \"best_bid\":\"0.64\", \"best_ask\":\"0.65\"}, {\"asset_id\":\"41448400836309843603620980831210604935021861034693225347475867885462478926555\", \"price\":\"0.96\", \"size\":\"583.09\", \"side\":\"SELL\", \"hash\":\"fc464d06a9c65762dbf1f042dc50f7526470636d\", \"best_bid\":\"0.35\", \"best_ask\":\"0.36\"}], \"timestamp\":\"1785122715301\", \"event_type\":\"price_change\"}","received_at":"2026-07-27T03:25:16.915535Z","schema_version":"clob-market-ws.price_change.v1","sequence":null,"server_hash":null,"server_timestamp":"1785122715301","session_id":"dd162b8dca5f43ff811d304e69a06123","source":"clob_market_ws"},"received_at":"2026-07-27T03:25:16.915535Z","record_id":"ee60379e10aa66a3471079ce9e37ca5866a03f59e8f4f296cb939188aa2dd461","schema_fingerprint":"4aa3821a28b0b7c2400bc59aba4bcc0a76e971dadd19610d3ad38c768e124dc7","schema_version":"edge-lab-recorder.raw.v1","sequence":null,"source":"clob_market_ws"}
{"event_at":"2026-07-27T03:25:15.328000Z","event_fingerprint":"44f1d22cc94e6e9eef7d9d9dadc7d29dd7f327911bb4fbb4f230c24dcbe27268","payload":{"connection_id":"c7dc2e4762f849c6b6f9306b6518dcab","event_at":"2026-07-27T03:25:15.328000Z","event_type":"price_change","frame_hash":"40bbfa4b3b0ebe4f0102ceab432cc68b63a3b73d1442c5c574d1a5524efc2027","frame_index":0,"kind":"data","monotonic_ns":224700279169750,"payload":{"event_type":"price_change","market":"0x717c0e8ccd4d5c7040185188fbae28be901ca589a11a94b1b38ca36a79eccfeb","price_changes":[{"asset_id":"41448400836309843603620980831210604935021861034693225347475867885462478926555","best_ask":"0.36","best_bid":"0.35","hash":"8b3ea65f8bc158a66a94664a1e22b8bcb74e1cd5","price":"0.39","side":"SELL","size":"57.08"},{"asset_id":"24254094493625419915756280046002869097156693848522361803041977572204227262166","best_ask":"0.65","best_bid":"0.64","hash":"08239c97d7ef7159af021e17c8b65d44c573f249","price":"0.61","side":"BUY","size":"57.08"}],"timestamp":"1785122715328"},"payload_hash":"c60cb76d353cbf966725ec963c3ef42b2dd189cc651f230633db8cc5eb62f831","raw_frame":"{\"market\":\"0x717c0e8ccd4d5c7040185188fbae28be901ca589a11a94b1b38ca36a79eccfeb\", \"price_changes\":[{\"asset_id\":\"41448400836309843603620980831210604935021861034693225347475867885462478926555\", \"price\":\"0.39\", \"size\":\"57.08\", \"side\":\"SELL\", \"hash\":\"8b3ea65f8bc158a66a94664a1e22b8bcb74e1cd5\", \"best_bid\":\"0.35\", \"best_ask\":\"0.36\"}, {\"asset_id\":\"24254094493625419915756280046002869097156693848522361803041977572204227262166\", \"price\":\"0.61\", \"size\":\"57.08\", \"side\":\"BUY\", \"hash\":\"08239c97d7ef7159af021e17c8b65d44c573f249\", \"best_bid\":\"0.64\", \"best_ask\":\"0.65\"}], \"timestamp\":\"1785122715328\", \"event_type\":\"price_change\"}","received_at":"2026-07-27T03:25:16.920137Z","schema_version":"clob-market-ws.price_change.v1","sequence":null,"server_hash":null,"server_timestamp":"1785122715328","session_id":"dd162b8dca5f43ff811d304e69a06123","source":"clob_market_ws"},"received_at":"2026-07-27T03:25:16.920137Z","record_id":"e6fe1f4c8963d58c74f12e6315e2e1d32ba89ab887472bf10c9df1ad16ef7eda","schema_fingerprint":"4aa3821a28b0b7c2400bc59aba4bcc0a76e971dadd19610d3ad38c768e124dc7","schema_version":"edge-lab-recorder.raw.v1","sequence":null,"source":"clob_market_ws"}
{"event_at":"2026-07-27T03:25:15.330000Z","event_fingerprint":"6c36083b3e0d99224a6926d5b66a7508d9fa082814b1ef032e16d7351a4e9d53","payload":{"connection_id":"c7dc2e4762f849c6b6f9306b6518dcab","event_at":"2026-07-27T03:25:15.330000Z","event_type":"price_change","frame_hash":"5236108d48a251799c050260c9a898d3a397efa5ea57a501db4a63a238056075","frame_index":0,"kind":"data","monotonic_ns":224700283854541,"payload":{"event_type":"price_change","market":"0x717c0e8ccd4d5c7040185188fbae28be901ca589a11a94b1b38ca36a79eccfeb","price_changes":[{"asset_id":"24254094493625419915756280046002869097156693848522361803041977572204227262166","best_ask":"0.65","best_bid":"0.64","hash":"a0790308be5c248b232e82df97c7b7506007c1eb","price":"0.61","side":"BUY","size":"82.08"},{"asset_id":"41448400836309843603620980831210604935021861034693225347475867885462478926555","best_ask":"0.36","best_bid":"0.35","hash":"72b1418628b601af78d08e77572d23c80ac7b77b","price":"0.39","side":"SELL","size":"82.08"}],"timestamp":"1785122715330"},"payload_hash":"f24f9596219b1e6d89c682e4369b66776e1e1fee183ca793674b8adb5d9e9bba","raw_frame":"{\"market\":\"0x717c0e8ccd4d5c7040185188fbae28be901ca589a11a94b1b38ca36a79eccfeb\", \"price_changes\":[{\"asset_id\":\"24254094493625419915756280046002869097156693848522361803041977572204227262166\", \"price\":\"0.61\", \"size\":\"82.08\", \"side\":\"BUY\", \"hash\":\"a0790308be5c248b232e82df97c7b7506007c1eb\", \"best_bid\":\"0.64\", \"best_ask\":\"0.65\"}, {\"asset_id\":\"41448400836309843603620980831210604935021861034693225347475867885462478926555\", \"price\":\"0.39\", \"size\":\"82.08\", \"side\":\"SELL\", \"hash\":\"72b1418628b601af78d08e77572d23c80ac7b77b\", \"best_bid\":\"0.35\", \"best_ask\":\"0.36\"}], \"timestamp\":\"1785122715330\", \"event_type\":\"price_change\"}","received_at":"2026-07-27T03:25:16.924818Z","schema_version":"clob-market-ws.price_change.v1","sequence":null,"server_hash":null,"server_timestamp":"1785122715330","session_id":"dd162b8dca5f43ff811d304e69a06123","source":"clob_market_ws"},"received_at":"2026-07-27T03:25:16.924818Z","record_id":"257feee4c3427960b1731e6762da89cacd89b006ec8bde3d045d55b568ac89ef","schema_fingerprint":"4aa3821a28b0b7c2400bc59aba4bcc0a76e971dadd19610d3ad38c768e124dc7","schema_version":"edge-lab-recorder.raw.v1","sequence":null,"source":"clob_market_ws"}
{"event_at":"2026-07-27T03:25:15.335000Z","event_fingerprint":"e7dc256a22a2f5937f407bb6fac4ac1316b357ef54335f203490e499dc2078bc","payload":{"connection_id":"c7dc2e4762f849c6b6f9306b6518dcab","event_at":"2026-07-27T03:25:15.335000Z","event_type":"price_change","frame_hash":"b1a0fa08569c247ad2f03a03921be7d6f6fda4db0d2ee05e7b716dbe8ee8f0aa","frame_index":0,"kind":"data","monotonic_ns":224700296622000,"payload":{"event_type":"price_change","market":"0x717c0e8ccd4d5c7040185188fbae28be901ca589a11a94b1b38ca36a79eccfeb","price_changes":[{"asset_id":"41448400836309843603620980831210604935021861034693225347475867885462478926555","best_ask":"0.36","best_bid":"0.35","hash":"5cc14d7456a973d5c70805efc676575bbfc2afa1","price":"0.41","side":"SELL","size":"38.84"},{"asset_id":"24254094493625419915756280046002869097156693848522361803041977572204227262166","best_ask":"0.65","best_bid":"0.64","hash":"767adcd0e1ee0c06e56a8d62a893de99da9e4105","price":"0.59","side":"BUY","size":"38.84"}],"timestamp":"1785122715335"},"payload_hash":"4fced8253fa305f1cdf95ff30d5829d9a8478e4b2384afb1e41973bb2166becf","raw_frame":"{\"market\":\"0x717c0e8ccd4d5c7040185188fbae28be901ca589a11a94b1b38ca36a79eccfeb\", \"price_changes\":[{\"asset_id\":\"41448400836309843603620980831210604935021861034693225347475867885462478926555\", \"price\":\"0.41\", \"size\":\"38.84\", \"side\":\"SELL\", \"hash\":\"5cc14d7456a973d5c70805efc676575bbfc2afa1\", \"best_bid\":\"0.35\", \"best_ask\":\"0.36\"}, {\"asset_id\":\"24254094493625419915756280046002869097156693848522361803041977572204227262166\", \"price\":\"0.59\", \"size\":\"38.84\", \"side\":\"BUY\", \"hash\":\"767adcd0e1ee0c06e56a8d62a893de99da9e4105\", \"best_bid\":\"0.64\", \"best_ask\":\"0.65\"}], \"timestamp\":\"1785122715335\", \"event_type\":\"price_change\"}","received_at":"2026-07-27T03:25:16.937589Z","schema_version":"clob-market-ws.price_change.v1","sequence":null,"server_hash":null,"server_timestamp":"1785122715335","session_id":"dd162b8dca5f43ff811d304e69a06123","source":"clob_market_ws"},"received_at":"2026-07-27T03:25:16.937589Z","record_id":"a76e7a69fd45adf305f3f84d353ae3d17a8919286610bf98e9f9f26f8cbc426a","schema_fingerprint":"4aa3821a28b0b7c2400bc59aba4bcc0a76e971dadd19610d3ad38c768e124dc7","schema_version":"edge-lab-recorder.raw.v1","sequence":null,"source":"clob_market_ws"}
{"event_at":"2026-07-27T03:25:15.335000Z","event_fingerprint":"a2fc67e16363512b499a1ccda5c71e8a910d9538b353f888571601a3497e07f9","payload":{"connection_id":"c7dc2e4762f849c6b6f9306b6518dcab","event_at":"2026-07-27T03:25:15.335000Z","event_type":"price_change","frame_hash":"b643cc5d1d28a97cd63bfdbe48384eb77e8b7acff7f376a49ae8a374c048fd0b","frame_index":0,"kind":"data","monotonic_ns":224700304916583,"payload":{"event_type":"price_change","market":"0x717c0e8ccd4d5c7040185188fbae28be901ca589a11a94b1b38ca36a79eccfeb","price_changes":[{"asset_id":"24254094493625419915756280046002869097156693848522361803041977572204227262166","best_ask":"0.65","best_bid":"0.64","hash":"48c4c61f3ae9ab88a9b588f3f8ce1a09fd365f08","price":"0.59","side":"BUY","size":"31.9"},{"asset_id":"41448400836309843603620980831210604935021861034693225347475867885462478926555","best_ask":"0.36","best_bid":"0.35","hash":"69f5f2c234528c300af4a0b2c5c652dc398ad453","price":"0.41","side":"SELL","size":"31.9"}],"timestamp":"1785122715335"},"payload_hash":"b0996122ee142461f5336f60276232733c48d9e82658efdecea5db4762d19f07","raw_frame":"{\"market\":\"0x717c0e8ccd4d5c7040185188fbae28be901ca589a11a94b1b38ca36a79eccfeb\", \"price_changes\":[{\"asset_id\":\"24254094493625419915756280046002869097156693848522361803041977572204227262166\", \"price\":\"0.59\", \"size\":\"31.9\", \"side\":\"BUY\", \"hash\":\"48c4c61f3ae9ab88a9b588f3f8ce1a09fd365f08\", \"best_bid\":\"0.64\", \"best_ask\":\"0.65\"}, {\"asset_id\":\"41448400836309843603620980831210604935021861034693225347475867885462478926555\", \"price\":\"0.41\", \"size\":\"31.9\", \"side\":\"SELL\", \"hash\":\"69f5f2c234528c300af4a0b2c5c652dc398ad453\", \"best_bid\":\"0.35\", \"best_ask\":\"0.36\"}], \"timestamp\":\"1785122715335\", \"event_type\":\"price_change\"}","received_at":"2026-07-27T03:25:16.945882Z","schema_version":"clob-market-ws.price_change.v1","sequence":null,"server_hash":null,"server_timestamp":"1785122715335","session_id":"dd162b8dca5f43ff811d304e69a06123","source":"clob_market_ws"},"received_at":"2026-07-27T03:25:16.945882Z","record_id":"a2c40dec0f0f3f947f429ff9ee4859f43bd933d45bb3f61ace732eba0c550acc","schema_fingerprint":"4aa3821a28b0b7c2400bc59aba4bcc0a76e971dadd19610d3ad38c768e124dc7","schema_version":"edge-lab-recorder.raw.v1","sequence":null,"source":"clob_market_ws"}
