{"event_at":"2026-07-27T03:27:42.719000Z","event_fingerprint":"9dfdf535a52e2e6c61e785516b7dffd3efe0754deb1d682924f0f81c32655801","payload":{"connection_id":"c7dc2e4762f849c6b6f9306b6518dcab","event_at":"2026-07-27T03:27:42.719000Z","event_type":"price_change","frame_hash":"9eccb5919e4d7c8670f3205101dfdcfa7a8b3c6657736690ebdad6005763fc7b","frame_index":0,"kind":"data","monotonic_ns":224845994604750,"payload":{"event_type":"price_change","market":"0x717c0e8ccd4d5c7040185188fbae28be901ca589a11a94b1b38ca36a79eccfeb","price_changes":[{"asset_id":"24254094493625419915756280046002869097156693848522361803041977572204227262166","best_ask":"0.92","best_bid":"0.91","hash":"3289c53b5a2cefac84f8d37e2946b765a2f74829","price":"0.02","side":"BUY","size":"530"},{"asset_id":"41448400836309843603620980831210604935021861034693225347475867885462478926555","best_ask":"0.09","best_bid":"0.08","hash":"81e7c8d0cd2e4c0f0fdf77de26456502dda2c52e","price":"0.98","side":"SELL","size":"530"}],"timestamp":"1785122862719"},"payload_hash":"b3d635977251f61b014f37d7803c8f7734a81b17804dcb0b73b07d5cd59f580a","raw_frame":"{\"market\":\"0x717c0e8ccd4d5c7040185188fbae28be901ca589a11a94b1b38ca36a79eccfeb\", \"price_changes\":[{\"asset_id\":\"24254094493625419915756280046002869097156693848522361803041977572204227262166\", \"price\":\"0.02\", \"size\":\"530\", \"side\":\"BUY\", \"hash\":\"3289c53b5a2cefac84f8d37e2946b765a2f74829\", \"best_bid\":\"0.91\", \"best_ask\":\"0.92\"}, {\"asset_id\":\"41448400836309843603620980831210604935021861034693225347475867885462478926555\", \"price\":\"0.98\", \"size\":\"530\", \"side\":\"SELL\", \"hash\":\"81e7c8d0cd2e4c0f0fdf77de26456502dda2c52e\", \"best_bid\":\"0.08\", \"best_ask\":\"0.09\"}], \"timestamp\":\"1785122862719\", \"event_type\":\"price_change\"}","received_at":"2026-07-27T03:27:42.633135Z","schema_version":"clob-market-ws.price_change.v1","sequence":null,"server_hash":null,"server_timestamp":"1785122862719","session_id":"dd162b8dca5f43ff811d304e69a06123","source":"clob_market_ws"},"received_at":"2026-07-27T03:27:42.633135Z","record_id":"a2e80267d1f5dbc7250d87cb6aa0d0b92265b7fdafdd1c31024292a38d5150cf","schema_fingerprint":"4aa3821a28b0b7c2400bc59aba4bcc0a76e971dadd19610d3ad38c768e124dc7","schema_version":"edge-lab-recorder.raw.v1","sequence":null,"source":"clob_market_ws"}
{"event_at":"2026-07-27T03:27:42.771000Z","event_fingerprint":"9eade410f8cf45f92328d6cac243daedd775abe140d2883fee78665e10d80442","payload":{"connection_id":"c7dc2e4762f849c6b6f9306b6518dcab","event_at":"2026-07-27T03:27:42.771000Z","event_type":"price_change","frame_hash":"8e98f6515f55bdd34c1c3992fc3ba85fc60ce3688e509aabe280bea5b694a2e3","frame_index":0,"kind":"data","monotonic_ns":224846005867291,"payload":{"event_type":"price_change","market":"0x717c0e8ccd4d5c7040185188fbae28be901ca589a11a94b1b38ca36a79eccfeb","price_changes":[{"asset_id":"41448400836309843603620980831210604935021861034693225347475867885462478926555","best_ask":"0.09","best_bid":"0.08","hash":"41cc7712198bf7dcae5a9705d867b3bb3d905769","price":"0.12","side":"SELL","size":"344.55"},{"asset_id":"24254094493625419915756280046002869097156693848522361803041977572204227262166","best_ask":"0.92","best_bid":"0.91","hash":"4bf6be3f60d85331ceda7691d03b493dcacacead","price":"0.88","side":"BUY","size":"344.55"}],"timestamp":"1785122862771"},"payload_hash":"f21bacfc0ad0e2c464f8cddfa1c7ef91032dfba058a3009804240a6633a0766c","raw_frame":"{\"market\":\"0x717c0e8ccd4d5c7040185188fbae28be901ca589a11a94b1b38ca36a79eccfeb\", \"price_changes\":[{\"asset_id\":\"41448400836309843603620980831210604935021861034693225347475867885462478926555\", \"price\":\"0.12\", \"size\":\"344.55\", \"side\":\"SELL\", \"hash\":\"41cc7712198bf7dcae5a9705d867b3bb3d905769\", \"best_bid\":\"0.08\", \"best_ask\":\"0.09\"}, {\"asset_id\":\"24254094493625419915756280046002869097156693848522361803041977572204227262166\", \"price\":\"0.88\", \"size\":\"344.55\", \"side\":\"BUY\", \"hash\":\"4bf6be3f60d85331ceda7691d03b493dcacacead\", \"best_bid\":\"0.91\", \"best_ask\":\"0.92\"}], \"timestamp\":\"1785122862771\", \"event_type\":\"price_change\"}","received_at":"2026-07-27T03:27:42.644398Z","schema_version":"clob-market-ws.price_change.v1","sequence":null,"server_hash":null,"server_timestamp":"1785122862771","session_id":"dd162b8dca5f43ff811d304e69a06123","source":"clob_market_ws"},"received_at":"2026-07-27T03:27:42.644398Z","record_id":"22d9d144f5a46a371dcfa197025a802484587f81a0abf109e4ec7b2dddb3b241","schema_fingerprint":"4aa3821a28b0b7c2400bc59aba4bcc0a76e971dadd19610d3ad38c768e124dc7","schema_version":"edge-lab-recorder.raw.v1","sequence":null,"source":"clob_market_ws"}
{"event_at":"2026-07-27T03:27:42.799000Z","event_fingerprint":"55da4d290dd717290c5b4a81de351a03a31068c4254e5fdc1563540e2548ef36","payload":{"connection_id":"c7dc2e4762f849c6b6f9306b6518dcab","event_at":"2026-07-27T03:27:42.799000Z","event_type":"price_change","frame_hash":"5d85124ffc19387e70018ad2c9cb4a03f5f7c811a1f3f918301033493548dacf","frame_index":0,"kind":"data","monotonic_ns":224846032684166,"payload":{"event_type":"price_change","market":"0x717c0e8ccd4d5c7040185188fbae28be901ca589a11a94b1b38ca36a79eccfeb","price_changes":[{"asset_id":"24254094493625419915756280046002869097156693848522361803041977572204227262166","best_ask":"0.92","best_bid":"0.91","hash":"e428fb3cba495e6f94ad92d3f8237ca2aba70da5","price":"0.01","side":"BUY","size":"5155.02"},{"asset_id":"41448400836309843603620980831210604935021861034693225347475867885462478926555","best_ask":"0.09","best_bid":"0.08","hash":"d5c4c70f07e40d4a4313cdf55e0091ab92887b89","price":"0.99","side":"SELL","size":"5155.02"}],"timestamp":"1785122862799"},"payload_hash":"ea05e2a40a2e3eb5765be7f3321aae3e2611dd331d74ff29ece21b00c014c35a","raw_frame":"{\"market\":\"0x717c0e8ccd4d5c7040185188fbae28be901ca589a11a94b1b38ca36a79eccfeb\", \"price_changes\":[{\"asset_id\":\"24254094493625419915756280046002869097156693848522361803041977572204227262166\", \"price\":\"0.01\", \"size\":\"5155.02\", \"side\":\"BUY\", \"hash\":\"e428fb3cba495e6f94ad92d3f8237ca2aba70da5\", \"best_bid\":\"0.91\", \"best_ask\":\"0.92\"}, {\"asset_id\":\"41448400836309843603620980831210604935021861034693225347475867885462478926555\", \"price\":\"0.99\", \"size\":\"5155.02\", \"side\":\"SELL\", \"hash\":\"d5c4c70f07e40d4a4313cdf55e0091ab92887b89\", \"best_bid\":\"0.08\", \"best_ask\":\"0.09\"}], \"timestamp\":\"1785122862799\", \"event_type\":\"price_change\"}","received_at":"2026-07-27T03:27:42.671213Z","schema_version":"clob-market-ws.price_change.v1","sequence":null,"server_hash":null,"server_timestamp":"1785122862799","session_id":"dd162b8dca5f43ff811d304e69a06123","source":"clob_market_ws"},"received_at":"2026-07-27T03:27:42.671213Z","record_id":"b8eb156cf1ed540d4d78b37cc29ff86419f494322d09e840fcb70255f52be30a","schema_fingerprint":"4aa3821a28b0b7c2400bc59aba4bcc0a76e971dadd19610d3ad38c768e124dc7","schema_version":"edge-lab-recorder.raw.v1","sequence":null,"source":"clob_market_ws"}
{"event_at":"2026-07-27T03:27:42.850000Z","event_fingerprint":"005723c36112ccda88eeacfedee4414a4edd367cb3b1c75b9c22abf42b18168a","payload":{"connection_id":"c7dc2e4762f849c6b6f9306b6518dcab","event_at":"2026-07-27T03:27:42.850000Z","event_type":"price_change","frame_hash":"f4be92427265e00a2f9f345b845d863772be1ca5eaecdee948d1dd8e6ac7a1e6","frame_index":0,"kind":"data","monotonic_ns":224846088530625,"payload":{"event_type":"price_change","market":"0x717c0e8ccd4d5c7040185188fbae28be901ca589a11a94b1b38ca36a79eccfeb","price_changes":[{"asset_id":"24254094493625419915756280046002869097156693848522361803041977572204227262166","best_ask":"0.92","best_bid":"0.91","hash":"6bdf856eb02937d265c6f5f2e8c685b255c4f414","price":"0.01","side":"BUY","size":"5160.02"},{"asset_id":"41448400836309843603620980831210604935021861034693225347475867885462478926555","best_ask":"0.09","best_bid":"0.08","hash":"154e1bfbf0795a5092168c88d50a302520e9c232","price":"0.99","side":"SELL","size":"5160.02"}],"timestamp":"1785122862850"},"payload_hash":"9ce9fe105dd2b1779cdcb99dad2923d11a7fe181b691bdfa39f3ca08a2b1d414","raw_frame":"{\"market\":\"0x717c0e8ccd4d5c7040185188fbae28be901ca589a11a94b1b38ca36a79eccfeb\", \"price_changes\":[{\"asset_id\":\"24254094493625419915756280046002869097156693848522361803041977572204227262166\", \"price\":\"0.01\", \"size\":\"5160.02\", \"side\":\"BUY\", \"hash\":\"6bdf856eb02937d265c6f5f2e8c685b255c4f414\", \"best_bid\":\"0.91\", \"best_ask\":\"0.92\"}, {\"asset_id\":\"41448400836309843603620980831210604935021861034693225347475867885462478926555\", \"price\":\"0.99\", \"size\":\"5160.02\", \"side\":\"SELL\", \"hash\":\"154e1bfbf0795a5092168c88d50a302520e9c232\", \"best_bid\":\"0.08\", \"best_ask\":\"0.09\"}], \"timestamp\":\"1785122862850\", \"event_type\":\"price_change\"}","received_at":"2026-07-27T03:27:42.727056Z","schema_version":"clob-market-ws.price_change.v1","sequence":null,"server_hash":null,"server_timestamp":"1785122862850","session_id":"dd162b8dca5f43ff811d304e69a06123","source":"clob_market_ws"},"received_at":"2026-07-27T03:27:42.727056Z","record_id":"c212277790f8f4b4e29dfc1163564323abd34c7034d457723dea0729b5ae8fe0","schema_fingerprint":"4aa3821a28b0b7c2400bc59aba4bcc0a76e971dadd19610d3ad38c768e124dc7","schema_version":"edge-lab-recorder.raw.v1","sequence":null,"source":"clob_market_ws"}
{"event_at":"2026-07-27T03:27:42.871000Z","event_fingerprint":"61a5ff9da8125885cc6198942b250749d08d43f07fcfa2563ac4b68c47100477","payload":{"connection_id":"c7dc2e4762f849c6b6f9306b6518dcab","event_at":"2026-07-27T03:27:42.871000Z","event_type":"price_change","frame_hash":"4d4bf1bcf5b72e95764484d3f69501d041004a12b6ef3602152e5625e7f6a34b","frame_index":0,"kind":"data","monotonic_ns":224846122197625,"payload":{"event_type":"price_change","market":"0x717c0e8ccd4d5c7040185188fbae28be901ca589a11a94b1b38ca36a79eccfeb","price_changes":[{"asset_id":"24254094493625419915756280046002869097156693848522361803041977572204227262166","best_ask":"0.92","best_bid":"0.91","hash":"ed8c3cd3f65850f8b257ca859cf0dda6b2905b22","price":"0.01","side":"BUY","size":"5155.02"},{"asset_id":"41448400836309843603620980831210604935021861034693225347475867885462478926555","best_ask":"0.09","best_bid":"0.08","hash":"cbc624a404a8bc166363b8e690e852d7e5669094","price":"0.99","side":"SELL","size":"5155.02"}],"timestamp":"1785122862871"},"payload_hash":"8aa4c56fec3ba8dba8d847b1dc5d0d891a76cff98fefa2bbff265a4485acfe05","raw_frame":"{\"market\":\"0x717c0e8ccd4d5c7040185188fbae28be901ca589a11a94b1b38ca36a79eccfeb\", \"price_changes\":[{\"asset_id\":\"24254094493625419915756280046002869097156693848522361803041977572204227262166\", \"price\":\"0.01\", \"size\":\"5155.02\", \"side\":\"BUY\", \"hash\":\"ed8c3cd3f65850f8b257ca859cf0dda6b2905b22\", \"best_bid\":\"0.91\", \"best_ask\":\"0.92\"}, {\"asset_id\":\"41448400836309843603620980831210604935021861034693225347475867885462478926555\", \"price\":\"0.99\", \"size\":\"5155.02\", \"side\":\"SELL\", \"hash\":\"cbc624a404a8bc166363b8e690e852d7e5669094\", \"best_bid\":\"0.08\", \"best_ask\":\"0.09\"}], \"timestamp\":\"1785122862871\", \"event_type\":\"price_change\"}","received_at":"2026-07-27T03:27:42.760723Z","schema_version":"clob-market-ws.price_change.v1","sequence":null,"server_hash":null,"server_timestamp":"1785122862871","session_id":"dd162b8dca5f43ff811d304e69a06123","source":"clob_market_ws"},"received_at":"2026-07-27T03:27:42.760723Z","record_id":"504868b56bc73f522cea1a53f1f91a84533e10fb57209d2005eb0cec09477c86","schema_fingerprint":"4aa3821a28b0b7c2400bc59aba4bcc0a76e971dadd19610d3ad38c768e124dc7","schema_version":"edge-lab-recorder.raw.v1","sequence":null,"source":"clob_market_ws"}
{"event_at":"2026-07-27T03:27:42.875000Z","event_fingerprint":"aeca551746ae24f3c55ba2d9df6ae5dbfcd1a41b9303c34d8c41201ef774691b","payload":{"connection_id":"c7dc2e4762f849c6b6f9306b6518dcab","event_at":"2026-07-27T03:27:42.875000Z","event_type":"price_change","frame_hash":"e2cd258234a503a5682af4f031e9b36e55d906682023bd23f88a7725f5b48319","frame_index":0,"kind":"data","monotonic_ns":224846127344250,"payload":{"event_type":"price_change","market":"0x717c0e8ccd4d5c7040185188fbae28be901ca589a11a94b1b38ca36a79eccfeb","price_changes":[{"asset_id":"24254094493625419915756280046002869097156693848522361803041977572204227262166","best_ask":"0.92","best_bid":"0.91","hash":"ba48bebf8e7edf33f5484bbe0bf82245178464e9","price":"0.01","side":"BUY","size":"5150.02"},{"asset_id":"41448400836309843603620980831210604935021861034693225347475867885462478926555","best_ask":"0.09","best_bid":"0.08","hash":"12912b478fa2ebd2a897309b9d1ff8b9343bb83f","price":"0.99","side":"SELL","size":"5150.02"}],"timestamp":"1785122862875"},"payload_hash":"9d3712cd01e86d82b2405450987f5c67d7794b8c3a2de49524e6c05664299b80","raw_frame":"{\"market\":\"0x717c0e8ccd4d5c7040185188fbae28be901ca589a11a94b1b38ca36a79eccfeb\", \"price_changes\":[{\"asset_id\":\"24254094493625419915756280046002869097156693848522361803041977572204227262166\", \"price\":\"0.01\", \"size\":\"5150.02\", \"side\":\"BUY\", \"hash\":\"ba48bebf8e7edf33f5484bbe0bf82245178464e9\", \"best_bid\":\"0.91\", \"best_ask\":\"0.92\"}, {\"asset_id\":\"41448400836309843603620980831210604935021861034693225347475867885462478926555\", \"price\":\"0.99\", \"size\":\"5150.02\", \"side\":\"SELL\", \"hash\":\"12912b478fa2ebd2a897309b9d1ff8b9343bb83f\", \"best_bid\":\"0.08\", \"best_ask\":\"0.09\"}], \"timestamp\":\"1785122862875\", \"event_type\":\"price_change\"}","received_at":"2026-07-27T03:27:42.765872Z","schema_version":"clob-market-ws.price_change.v1","sequence":null,"server_hash":null,"server_timestamp":"1785122862875","session_id":"dd162b8dca5f43ff811d304e69a06123","source":"clob_market_ws"},"received_at":"2026-07-27T03:27:42.765872Z","record_id":"59f68ed61841816fe3d5703d6de6e9c4e6a68409521bd43824d6c51173f8457b","schema_fingerprint":"4aa3821a28b0b7c2400bc59aba4bcc0a76e971dadd19610d3ad38c768e124dc7","schema_version":"edge-lab-recorder.raw.v1","sequence":null,"source":"clob_market_ws"}
{"event_at":"2026-07-27T03:27:42.918000Z","event_fingerprint":"630ab8ff701941853b043802a5e4d11dadb089bbeab04ee0d514c88d24be544a","payload":{"connection_id":"c7dc2e4762f849c6b6f9306b6518dcab","event_at":"2026-07-27T03:27:42.918000Z","event_type":"price_change","frame_hash":"b5d80635c1971c4beb4d56bdda6396da485629c82f1db8d89b1b8462e31c8719","frame_index":0,"kind":"data","monotonic_ns":224846150916458,"payload":{"event_type":"price_change","market":"0x717c0e8ccd4d5c7040185188fbae28be901ca589a11a94b1b38ca36a79eccfeb","price_changes":[{"asset_id":"41448400836309843603620980831210604935021861034693225347475867885462478926555","best_ask":"0.09","best_bid":"0.08","hash":"9c5e7521ca6ac2ff6136dd497e764925e0f59087","price":"0.12","side":"SELL","size":"338.5"},{"asset_id":"24254094493625419915756280046002869097156693848522361803041977572204227262166","best_ask":"0.92","best_bid":"0.91","hash":"4a96b72b17f6ba7fcc7b8ce0c188c7d84638f672","price":"0.88","side":"BUY","size":"338.5"}],"timestamp":"1785122862918"},"payload_hash":"453f65601e893c1f764db0041ce513e0060b90452da5f3d0c5b17da75a7fa4ba","raw_frame":"{\"market\":\"0x717c0e8ccd4d5c7040185188fbae28be901ca589a11a94b1b38ca36a79eccfeb\", \"price_changes\":[{\"asset_id\":\"41448400836309843603620980831210604935021861034693225347475867885462478926555\", \"price\":\"0.12\", \"size\":\"338.5\", \"side\":\"SELL\", \"hash\":\"9c5e7521ca6ac2ff6136dd497e764925e0f59087\", \"best_bid\":\"0.08\", \"best_ask\":\"0.09\"}, {\"asset_id\":\"24254094493625419915756280046002869097156693848522361803041977572204227262166\", \"price\":\"0.88\", \"size\":\"338.5\", \"side\":\"BUY\", \"hash\":\"4a96b72b17f6ba7fcc7b8ce0c188c7d84638f672\", \"best_bid\":\"0.91\", \"best_ask\":\"0.92\"}], \"timestamp\":\"1785122862918\", \"event_type\":\"price_change\"}","received_at":"2026-07-27T03:27:42.789445Z","schema_version":"clob-market-ws.price_change.v1","sequence":null,"server_hash":null,"server_timestamp":"1785122862918","session_id":"dd162b8dca5f43ff811d304e69a06123","source":"clob_market_ws"},"received_at":"2026-07-27T03:27:42.789445Z","record_id":"f9151fa47e998366b08a60fc317ad6272582f1b3df7e2897db7df59c91500986","schema_fingerprint":"4aa3821a28b0b7c2400bc59aba4bcc0a76e971dadd19610d3ad38c768e124dc7","schema_version":"edge-lab-recorder.raw.v1","sequence":null,"source":"clob_market_ws"}
{"event_at":"2026-07-27T03:27:43.018000Z","event_fingerprint":"1dc0b65f3e873f9607eba99f3e4de59ad291188c48e32e9072daa624c59f966b","payload":{"connection_id":"c7dc2e4762f849c6b6f9306b6518dcab","event_at":"2026-07-27T03:27:43.018000Z","event_type":"price_change","frame_hash":"20772a1f20b5669f72f8804da86d3505a24ed0b4e2c780b6e2b533c4176827df","frame_index":0,"kind":"data","monotonic_ns":224846265729583,"payload":{"event_type":"price_change","market":"0x717c0e8ccd4d5c7040185188fbae28be901ca589a11a94b1b38ca36a79eccfeb","price_changes":[{"asset_id":"24254094493625419915756280046002869097156693848522361803041977572204227262166","best_ask":"0.92","best_bid":"0.91","hash":"328d9fc97e8944f015a055f9ee881bbec208d85f","price":"0.03","side":"BUY","size":"515"},{"asset_id":"41448400836309843603620980831210604935021861034693225347475867885462478926555","best_ask":"0.09","best_bid":"0.08","hash":"d03b70aa2a83b1c67d1a978a89a144434c52c2ef","price":"0.97","side":"SELL","size":"515"}],"timestamp":"1785122863018"},"payload_hash":"b0af8563aac367fe0c7e181ba756c30aafd3993b16a4dbf8501fe382e4ad1371","raw_frame":"{\"market\":\"0x717c0e8ccd4d5c7040185188fbae28be901ca589a11a94b1b38ca36a79eccfeb\", \"price_changes\":[{\"asset_id\":\"24254094493625419915756280046002869097156693848522361803041977572204227262166\", \"price\":\"0.03\", \"size\":\"515\", \"side\":\"BUY\", \"hash\":\"328d9fc97e8944f015a055f9ee881bbec208d85f\", \"best_bid\":\"0.91\", \"best_ask\":\"0.92\"}, {\"asset_id\":\"41448400836309843603620980831210604935021861034693225347475867885462478926555\", \"price\":\"0.97\", \"size\":\"515\", \"side\":\"SELL\", \"hash\":\"d03b70aa2a83b1c67d1a978a89a144434c52c2ef\", \"best_bid\":\"0.08\", \"best_ask\":\"0.09\"}], \"timestamp\":\"1785122863018\", \"event_type\":\"price_change\"}","received_at":"2026-07-27T03:27:42.904253Z","schema_version":"clob-market-ws.price_change.v1","sequence":null,"server_hash":null,"server_timestamp":"1785122863018","session_id":"dd162b8dca5f43ff811d304e69a06123","source":"clob_market_ws"},"received_at":"2026-07-27T03:27:42.904253Z","record_id":"bace99d3c1b8cf6d618e9423cf979267b893bf7563a1ead16973f94d502e23fb","schema_fingerprint":"4aa3821a28b0b7c2400bc59aba4bcc0a76e971dadd19610d3ad38c768e124dc7","schema_version":"edge-lab-recorder.raw.v1","sequence":null,"source":"clob_market_ws"}
{"event_at":"2026-07-27T03:27:43.025000Z","event_fingerprint":"12e8ccc47c43b211f298e1bf3d531ba860e42e8ca09d9ca2552cbb7c3f450704","payload":{"connection_id":"c7dc2e4762f849c6b6f9306b6518dcab","event_at":"2026-07-27T03:27:43.025000Z","event_type":"price_change","frame_hash":"8ec1fa3da8b3585b26abe806ffffde0be719b42be86a85bd09ff05b65474cd96","frame_index":0,"kind":"data","monotonic_ns":224846271220125,"payload":{"event_type":"price_change","market":"0x717c0e8ccd4d5c7040185188fbae28be901ca589a11a94b1b38ca36a79eccfeb","price_changes":[{"asset_id":"41448400836309843603620980831210604935021861034693225347475867885462478926555","best_ask":"0.09","best_bid":"0.08","hash":"827d6ee73d48f9912ed209625552c653c84ebfe4","price":"0.01","side":"BUY","size":"5245.02"},{"asset_id":"24254094493625419915756280046002869097156693848522361803041977572204227262166","best_ask":"0.92","best_bid":"0.91","hash":"9fc2dbecca5c6cef988380c8e4b90b2644eda324","price":"0.99","side":"SELL","size":"5245.02"}],"timestamp":"1785122863025"},"payload_hash":"7115888b1fdfa714d41507362db0c42fdfa42f4fcf019553a91fa57201cfd720","raw_frame":"{\"market\":\"0x717c0e8ccd4d5c7040185188fbae28be901ca589a11a94b1b38ca36a79eccfeb\", \"price_changes\":[{\"asset_id\":\"41448400836309843603620980831210604935021861034693225347475867885462478926555\", \"price\":\"0.01\", \"size\":\"5245.02\", \"side\":\"BUY\", \"hash\":\"827d6ee73d48f9912ed209625552c653c84ebfe4\", \"best_bid\":\"0.08\", \"best_ask\":\"0.09\"}, {\"asset_id\":\"24254094493625419915756280046002869097156693848522361803041977572204227262166\", \"price\":\"0.99\", \"size\":\"5245.02\", \"side\":\"SELL\", \"hash\":\"9fc2dbecca5c6cef988380c8e4b90b2644eda324\", \"best_bid\":\"0.91\", \"best_ask\":\"0.92\"}], \"timestamp\":\"1785122863025\", \"event_type\":\"price_change\"}","received_at":"2026-07-27T03:27:42.909747Z","schema_version":"clob-market-ws.price_change.v1","sequence":null,"server_hash":null,"server_timestamp":"1785122863025","session_id":"dd162b8dca5f43ff811d304e69a06123","source":"clob_market_ws"},"received_at":"2026-07-27T03:27:42.909747Z","record_id":"fcd0187050ff4ebccfc46f0dd0d99875074e9559de69fc931ef50dd6c0bc0924","schema_fingerprint":"4aa3821a28b0b7c2400bc59aba4bcc0a76e971dadd19610d3ad38c768e124dc7","schema_version":"edge-lab-recorder.raw.v1","sequence":null,"source":"clob_market_ws"}
{"event_at":"2026-07-27T03:27:43.026000Z","event_fingerprint":"1a1b7feb94fe71fc1b1f5b2149616a90c5789de4f55bac987a6df64914fec1f9","payload":{"connection_id":"c7dc2e4762f849c6b6f9306b6518dcab","event_at":"2026-07-27T03:27:43.026000Z","event_type":"price_change","frame_hash":"d8067333d94616ec4a02e34f1bbd6f3d08c672fa21f2bcaa9e80b85890a988b2","frame_index":0,"kind":"data","monotonic_ns":224846275365958,"payload":{"event_type":"price_change","market":"0x717c0e8ccd4d5c7040185188fbae28be901ca589a11a94b1b38ca36a79eccfeb","price_changes":[{"asset_id":"41448400836309843603620980831210604935021861034693225347475867885462478926555","best_ask":"0.09","best_bid":"0.08","hash":"1b90b4939383526ce05c2387c4017cae689c2bc3","price":"0.01","side":"BUY","size":"5250.02"},{"asset_id":"24254094493625419915756280046002869097156693848522361803041977572204227262166","best_ask":"0.92","best_bid":"0.91","hash":"25995001a0c65ded46185985698e1b975b200fc4","price":"0.99","side":"SELL","size":"5250.02"}],"timestamp":"1785122863026"},"payload_hash":"f3f13a3603d037d6d85e3e5b1999d5ce559dd60e823a50ebac2225afbcc5a4e1","raw_frame":"{\"market\":\"0x717c0e8ccd4d5c7040185188fbae28be901ca589a11a94b1b38ca36a79eccfeb\", \"price_changes\":[{\"asset_id\":\"41448400836309843603620980831210604935021861034693225347475867885462478926555\", \"price\":\"0.01\", \"size\":\"5250.02\", \"side\":\"BUY\", \"hash\":\"1b90b4939383526ce05c2387c4017cae689c2bc3\", \"best_bid\":\"0.08\", \"best_ask\":\"0.09\"}, {\"asset_id\":\"24254094493625419915756280046002869097156693848522361803041977572204227262166\", \"price\":\"0.99\", \"size\":\"5250.02\", \"side\":\"SELL\", \"hash\":\"25995001a0c65ded46185985698e1b975b200fc4\", \"best_bid\":\"0.91\", \"best_ask\":\"0.92\"}], \"timestamp\":\"1785122863026\", \"event_type\":\"price_change\"}","received_at":"2026-07-27T03:27:42.913886Z","schema_version":"clob-market-ws.price_change.v1","sequence":null,"server_hash":null,"server_timestamp":"1785122863026","session_id":"dd162b8dca5f43ff811d304e69a06123","source":"clob_market_ws"},"received_at":"2026-07-27T03:27:42.913886Z","record_id":"2de0425bfacabddcb04d1188f5db14a2c02ab37a22f92b67de4aeb1f257d9e27","schema_fingerprint":"4aa3821a28b0b7c2400bc59aba4bcc0a76e971dadd19610d3ad38c768e124dc7","schema_version":"edge-lab-recorder.raw.v1","sequence":null,"source":"clob_market_ws"}
{"event_at":"2026-07-27T03:27:43.046000Z","event_fingerprint":"4671de6cfaafd620a44b3022ee55fea508e2be2c8d923aad6cd78f8a24da68f2","payload":{"connection_id":"c7dc2e4762f849c6b6f9306b6518dcab","event_at":"2026-07-27T03:27:43.046000Z","event_type":"price_change","frame_hash":"e355bcf2f56dd2a858d9f2994df71bb6731e29b5c4ca4afd30bdefb01479aad4","frame_index":0,"kind":"data","monotonic_ns":224846280696875,"payload":{"event_type":"price_change","market":"0x717c0e8ccd4d5c7040185188fbae28be901ca589a11a94b1b38ca36a79eccfeb","price_changes":[{"asset_id":"41448400836309843603620980831210604935021861034693225347475867885462478926555","best_ask":"0.09","best_bid":"0.08","hash":"07fa0b5501106029d4a065968f228ca3acbccf34","price":"0.01","side":"BUY","size":"5245.02"},{"asset_id":"24254094493625419915756280046002869097156693848522361803041977572204227262166","best_ask":"0.92","best_bid":"0.91","hash":"74d47e32db9c4527dc533c751d39623180fc4d8d","price":"0.99","side":"SELL","size":"5245.02"}],"timestamp":"1785122863046"},"payload_hash":"3f12c97a5f1f3b026f0fc48d81210e9f0068a02f84343c7c1dc5f6a4085bc4f9","raw_frame":"{\"market\":\"0x717c0e8ccd4d5c7040185188fbae28be901ca589a11a94b1b38ca36a79eccfeb\", \"price_changes\":[{\"asset_id\":\"41448400836309843603620980831210604935021861034693225347475867885462478926555\", \"price\":\"0.01\", \"size\":\"5245.02\", \"side\":\"BUY\", \"hash\":\"07fa0b5501106029d4a065968f228ca3acbccf34\", \"best_bid\":\"0.08\", \"best_ask\":\"0.09\"}, {\"asset_id\":\"24254094493625419915756280046002869097156693848522361803041977572204227262166\", \"price\":\"0.99\", \"size\":\"5245.02\", \"side\":\"SELL\", \"hash\":\"74d47e32db9c4527dc533c751d39623180fc4d8d\", \"best_bid\":\"0.91\", \"best_ask\":\"0.92\"}], \"timestamp\":\"1785122863046\", \"event_type\":\"price_change\"}","received_at":"2026-07-27T03:27:42.919221Z","schema_version":"clob-market-ws.price_change.v1","sequence":null,"server_hash":null,"server_timestamp":"1785122863046","session_id":"dd162b8dca5f43ff811d304e69a06123","source":"clob_market_ws"},"received_at":"2026-07-27T03:27:42.919221Z","record_id":"4e67b2054eeb136924c5c30273787470fffe85e4436c72e3a511198097ddb858","schema_fingerprint":"4aa3821a28b0b7c2400bc59aba4bcc0a76e971dadd19610d3ad38c768e124dc7","schema_version":"edge-lab-recorder.raw.v1","sequence":null,"source":"clob_market_ws"}
{"event_at":"2026-07-27T03:27:43.070000Z","event_fingerprint":"8f2941a0d07a06d13e99ad5654185823a002f9e5655c5c07c78f25aac6456a55","payload":{"connection_id":"c7dc2e4762f849c6b6f9306b6518dcab","event_at":"2026-07-27T03:27:43.070000Z","event_type":"price_change","frame_hash":"6061c7a86998f2a19d43c32f34eeb69c8791b7ec31fee8a9ce7aa1cb96efd532","frame_index":0,"kind":"data","monotonic_ns":224846325627833,"payload":{"event_type":"price_change","market":"0x717c0e8ccd4d5c7040185188fbae28be901ca589a11a94b1b38ca36a79eccfeb","price_changes":[{"asset_id":"24254094493625419915756280046002869097156693848522361803041977572204227262166","best_ask":"0.92","best_bid":"0.91","hash":"70ba0731c3d898ef0d86aa8993f5838807c3561d","price":"0.03","side":"BUY","size":"510"},{"asset_id":"41448400836309843603620980831210604935021861034693225347475867885462478926555","best_ask":"0.09","best_bid":"0.08","hash":"b4b11491580a472ba58d931e7e73f855c52df113","price":"0.97","side":"SELL","size":"510"}],"timestamp":"1785122863070"},"payload_hash":"2c4cd74f27aaaa7aa27850d272d20653e848c2929ebebc603e744c94ebbcd37f","raw_frame":"{\"market\":\"0x717c0e8ccd4d5c7040185188fbae28be901ca589a11a94b1b38ca36a79eccfeb\", \"price_changes\":[{\"asset_id\":\"24254094493625419915756280046002869097156693848522361803041977572204227262166\", \"price\":\"0.03\", \"size\":\"510\", \"side\":\"BUY\", \"hash\":\"70ba0731c3d898ef0d86aa8993f5838807c3561d\", \"best_bid\":\"0.91\", \"best_ask\":\"0.92\"}, {\"asset_id\":\"41448400836309843603620980831210604935021861034693225347475867885462478926555\", \"price\":\"0.97\", \"size\":\"510\", \"side\":\"SELL\", \"hash\":\"b4b11491580a472ba58d931e7e73f855c52df113\", \"best_bid\":\"0.08\", \"best_ask\":\"0.09\"}], \"timestamp\":\"1785122863070\", \"event_type\":\"price_change\"}","received_at":"2026-07-27T03:27:42.964152Z","schema_version":"clob-market-ws.price_change.v1","sequence":null,"server_hash":null,"server_timestamp":"1785122863070","session_id":"dd162b8dca5f43ff811d304e69a06123","source":"clob_market_ws"},"received_at":"2026-07-27T03:27:42.964152Z","record_id":"5ff75ec3bdbc4037f34dbf883ee1c6c047fe759f3868dc874640f0b6854b9b45","schema_fingerprint":"4aa3821a28b0b7c2400bc59aba4bcc0a76e971dadd19610d3ad38c768e124dc7","schema_version":"edge-lab-recorder.raw.v1","sequence":null,"source":"clob_market_ws"}
{"event_at":"2026-07-27T03:27:43.081000Z","event_fingerprint":"204a316df12a42a7ea5215704747a03f25dbc894cc807f0258094c71dbdfd1ff","payload":{"connection_id":"c7dc2e4762f849c6b6f9306b6518dcab","event_at":"2026-07-27T03:27:43.081000Z","event_type":"price_change","frame_hash":"9ac08d29875ed437e7ec3f9c8f6fb33fe67d44275318c11b5a9e2cce8fc43f52","frame_index":0,"kind":"data","monotonic_ns":224846330405375,"payload":{"event_type":"price_change","market":"0x717c0e8ccd4d5c7040185188fbae28be901ca589a11a94b1b38ca36a79eccfeb","price_changes":[{"asset_id":"24254094493625419915756280046002869097156693848522361803041977572204227262166","best_ask":"0.92","best_bid":"0.91","hash":"7772117cdeb14289a7b5c64a82ee1ef40b252327","price":"0.01","side":"BUY","size":"5155.02"},{"asset_id":"41448400836309843603620980831210604935021861034693225347475867885462478926555","best_ask":"0.09","best_bid":"0.08","hash":"b0236b8d6abfe6a57169e12bfe2544cb351413f6","price":"0.99","side":"SELL","size":"5155.02"}],"timestamp":"1785122863081"},"payload_hash":"719658e4262a91bc1aab8ca9da0c0433d2ad35be1643778075307a463107318a","raw_frame":"{\"market\":\"0x717c0e8ccd4d5c7040185188fbae28be901ca589a11a94b1b38ca36a79eccfeb\", \"price_changes\":[{\"asset_id\":\"24254094493625419915756280046002869097156693848522361803041977572204227262166\", \"price\":\"0.01\", \"size\":\"5155.02\", \"side\":\"BUY\", \"hash\":\"7772117cdeb14289a7b5c64a82ee1ef40b252327\", \"best_bid\":\"0.91\", \"best_ask\":\"0.92\"}, {\"asset_id\":\"41448400836309843603620980831210604935021861034693225347475867885462478926555\", \"price\":\"0.99\", \"size\":\"5155.02\", \"side\":\"SELL\", \"hash\":\"b0236b8d6abfe6a57169e12bfe2544cb351413f6\", \"best_bid\":\"0.08\", \"best_ask\":\"0.09\"}], \"timestamp\":\"1785122863081\", \"event_type\":\"price_change\"}","received_at":"2026-07-27T03:27:42.968931Z","schema_version":"clob-market-ws.price_change.v1","sequence":null,"server_hash":null,"server_timestamp":"1785122863081","session_id":"dd162b8dca5f43ff811d304e69a06123","source":"clob_market_ws"},"received_at":"2026-07-27T03:27:42.968931Z","record_id":"2370a777d04c4adc63d83b774d79c036693b4836145133dbe4304b0f8c4cad44","schema_fingerprint":"4aa3821a28b0b7c2400bc59aba4bcc0a76e971dadd19610d3ad38c768e124dc7","schema_version":"edge-lab-recorder.raw.v1","sequence":null,"source":"clob_market_ws"}
{"event_at":"2026-07-27T03:27:43.102000Z","event_fingerprint":"c3c9dd0270dbe2dd09fadf8412dc8c7234a1ae584f7ffcac73d2f0d77755e83a","payload":{"connection_id":"c7dc2e4762f849c6b6f9306b6518dcab","event_at":"2026-07-27T03:27:43.102000Z","event_type":"price_change","frame_hash":"f80ba30a6aa56aef0c98680b4661b17e48482c61d87fa39d006323cfcacc4d2a","frame_index":0,"kind":"data","monotonic_ns":224846338432958,"payload":{"event_type":"price_change","market":"0x717c0e8ccd4d5c7040185188fbae28be901ca589a11a94b1b38ca36a79eccfeb","price_changes":[{"asset_id":"24254094493625419915756280046002869097156693848522361803041977572204227262166","best_ask":"0.92","best_bid":"0.91","hash":"35096e46591ea17f86bde28734a76bd41d076b19","price":"0.01","side":"BUY","size":"5150.02"},{"asset_id":"41448400836309843603620980831210604935021861034693225347475867885462478926555","best_ask":"0.09","best_bid":"0.08","hash":"861017090ff2510b906a05c4fb768ca6a1f6fc8e","price":"0.99","side":"SELL","size":"5150.02"}],"timestamp":"1785122863102"},"payload_hash":"1d1f5793d056ded42da98b216be457de3b8cf51475bdcf12b9f429705a7817a8","raw_frame":"{\"market\":\"0x717c0e8ccd4d5c7040185188fbae28be901ca589a11a94b1b38ca36a79eccfeb\", \"price_changes\":[{\"asset_id\":\"24254094493625419915756280046002869097156693848522361803041977572204227262166\", \"price\":\"0.01\", \"size\":\"5150.02\", \"side\":\"BUY\", \"hash\":\"35096e46591ea17f86bde28734a76bd41d076b19\", \"best_bid\":\"0.91\", \"best_ask\":\"0.92\"}, {\"asset_id\":\"41448400836309843603620980831210604935021861034693225347475867885462478926555\", \"price\":\"0.99\", \"size\":\"5150.02\", \"side\":\"SELL\", \"hash\":\"861017090ff2510b906a05c4fb768ca6a1f6fc8e\", \"best_bid\":\"0.08\", \"best_ask\":\"0.09\"}], \"timestamp\":\"1785122863102\", \"event_type\":\"price_change\"}","received_at":"2026-07-27T03:27:42.976959Z","schema_version":"clob-market-ws.price_change.v1","sequence":null,"server_hash":null,"server_timestamp":"1785122863102","session_id":"dd162b8dca5f43ff811d304e69a06123","source":"clob_market_ws"},"received_at":"2026-07-27T03:27:42.976959Z","record_id":"ad03d1d77350947903df1e0c46761c5c49b35c5aa4ec0ebe17d0138b25324493","schema_fingerprint":"4aa3821a28b0b7c2400bc59aba4bcc0a76e971dadd19610d3ad38c768e124dc7","schema_version":"edge-lab-recorder.raw.v1","sequence":null,"source":"clob_market_ws"}
{"event_at":"2026-07-27T03:27:43.115000Z","event_fingerprint":"4f84a112669e67c31dd662962642974e1192a9a9ef249bccf36daced6677e445","payload":{"connection_id":"c7dc2e4762f849c6b6f9306b6518dcab","event_at":"2026-07-27T03:27:43.115000Z","event_type":"price_change","frame_hash":"1270c4b0e2af608e9ecbd85032441480887117c1f862a520e124413d9d50ad3f","frame_index":0,"kind":"data","monotonic_ns":224846365618750,"payload":{"event_type":"price_change","market":"0x717c0e8ccd4d5c7040185188fbae28be901ca589a11a94b1b38ca36a79eccfeb","price_changes":[{"asset_id":"24254094493625419915756280046002869097156693848522361803041977572204227262166","best_ask":"0.92","best_bid":"0.91","hash":"d30f9cb7c47b60a664cef68540e657d0670a8b68","price":"0.85","side":"BUY","size":"110"},{"asset_id":"41448400836309843603620980831210604935021861034693225347475867885462478926555","best_ask":"0.09","best_bid":"0.08","hash":"39dc34ded504c638d869aff8f19c7f2ae9f75746","price":"0.15","side":"SELL","size":"110"}],"timestamp":"1785122863115"},"payload_hash":"4457c6fccd5c93aaa88288056eeece7360fc70d50618bbd1f07b2dc615a85c6a","raw_frame":"{\"market\":\"0x717c0e8ccd4d5c7040185188fbae28be901ca589a11a94b1b38ca36a79eccfeb\", \"price_changes\":[{\"asset_id\":\"24254094493625419915756280046002869097156693848522361803041977572204227262166\", \"price\":\"0.85\", \"size\":\"110\", \"side\":\"BUY\", \"hash\":\"d30f9cb7c47b60a664cef68540e657d0670a8b68\", \"best_bid\":\"0.91\", \"best_ask\":\"0.92\"}, {\"asset_id\":\"41448400836309843603620980831210604935021861034693225347475867885462478926555\", \"price\":\"0.15\", \"size\":\"110\", \"side\":\"SELL\", \"hash\":\"39dc34ded504c638d869aff8f19c7f2ae9f75746\", \"best_bid\":\"0.08\", \"best_ask\":\"0.09\"}], \"timestamp\":\"1785122863115\", \"event_type\":\"price_change\"}","received_at":"2026-07-27T03:27:43.004139Z","schema_version":"clob-market-ws.price_change.v1","sequence":null,"server_hash":null,"server_timestamp":"1785122863115","session_id":"dd162b8dca5f43ff811d304e69a06123","source":"clob_market_ws"},"received_at":"2026-07-27T03:27:43.004139Z","record_id":"35e23f6d7753f882d7e44509ae0a0be38602184fbe117543544ff62594c68e02","schema_fingerprint":"4aa3821a28b0b7c2400bc59aba4bcc0a76e971dadd19610d3ad38c768e124dc7","schema_version":"edge-lab-recorder.raw.v1","sequence":null,"source":"clob_market_ws"}
{"event_at":"2026-07-27T03:27:43.115000Z","event_fingerprint":"1e6109334eb6b48c06ecf9721453c8aa4bc4441f4113187b76eae2c4db9a94bb","payload":{"connection_id":"c7dc2e4762f849c6b6f9306b6518dcab","event_at":"2026-07-27T03:27:43.115000Z","event_type":"price_change","frame_hash":"09ade34292a8e8987f569ffce18aa5a43f3d51e41131efa038b07500b134ac80","frame_index":0,"kind":"data","monotonic_ns":224846370567916,"payload":{"event_type":"price_change","market":"0x717c0e8ccd4d5c7040185188fbae28be901ca589a11a94b1b38ca36a79eccfeb","price_changes":[{"asset_id":"41448400836309843603620980831210604935021861034693225347475867885462478926555","best_ask":"0.09","best_bid":"0.08","hash":"39dc34ded504c638d869aff8f19c7f2ae9f75746","price":"0.06","side":"BUY","size":"44.22"},{"asset_id":"24254094493625419915756280046002869097156693848522361803041977572204227262166","best_ask":"0.92","best_bid":"0.91","hash":"d30f9cb7c47b60a664cef68540e657d0670a8b68","price":"0.94","side":"SELL","size":"44.22"}],"timestamp":"1785122863115"},"payload_hash":"bf935475785ca75b1d4a9c6c53c96fb5d531dc604b71c100cf7054e17601ac42","raw_frame":"{\"market\":\"0x717c0e8ccd4d5c7040185188fbae28be901ca589a11a94b1b38ca36a79eccfeb\", \"price_changes\":[{\"asset_id\":\"41448400836309843603620980831210604935021861034693225347475867885462478926555\", \"price\":\"0.06\", \"size\":\"44.22\", \"side\":\"BUY\", \"hash\":\"39dc34ded504c638d869aff8f19c7f2ae9f75746\", \"best_bid\":\"0.08\", \"best_ask\":\"0.09\"}, {\"asset_id\":\"24254094493625419915756280046002869097156693848522361803041977572204227262166\", \"price\":\"0.94\", \"size\":\"44.22\", \"side\":\"SELL\", \"hash\":\"d30f9cb7c47b60a664cef68540e657d0670a8b68\", \"best_bid\":\"0.91\", \"best_ask\":\"0.92\"}], \"timestamp\":\"1785122863115\", \"event_type\":\"price_change\"}","received_at":"2026-07-27T03:27:43.009090Z","schema_version":"clob-market-ws.price_change.v1","sequence":null,"server_hash":null,"server_timestamp":"1785122863115","session_id":"dd162b8dca5f43ff811d304e69a06123","source":"clob_market_ws"},"received_at":"2026-07-27T03:27:43.009090Z","record_id":"0fe40122b1964b2fe3afa5ea635068714aaecff9cec009f867dbafe68a352db4","schema_fingerprint":"4aa3821a28b0b7c2400bc59aba4bcc0a76e971dadd19610d3ad38c768e124dc7","schema_version":"edge-lab-recorder.raw.v1","sequence":null,"source":"clob_market_ws"}
