{"event_at":"2026-07-27T03:25:15.353000Z","event_fingerprint":"bf771386bc100c6d788e1af1401bb9d3a9db25f71df32c693adfc429ac2d7c85","payload":{"connection_id":"c7dc2e4762f849c6b6f9306b6518dcab","event_at":"2026-07-27T03:25:15.353000Z","event_type":"price_change","frame_hash":"93b5e684e7c31f41d783087160e1165dc532f9b90899bfa62aa3a0f25ddba077","frame_index":0,"kind":"data","monotonic_ns":224700364170041,"payload":{"event_type":"price_change","market":"0x717c0e8ccd4d5c7040185188fbae28be901ca589a11a94b1b38ca36a79eccfeb","price_changes":[{"asset_id":"24254094493625419915756280046002869097156693848522361803041977572204227262166","best_ask":"0.65","best_bid":"0.64","hash":"532b660c1bc0c32044901cba3a98d599a76465a6","price":"0.04","side":"BUY","size":"578.09"},{"asset_id":"41448400836309843603620980831210604935021861034693225347475867885462478926555","best_ask":"0.36","best_bid":"0.35","hash":"4319b55ecdf8f52eebf23cb17e966d7a9ac6de30","price":"0.96","side":"SELL","size":"578.09"}],"timestamp":"1785122715353"},"payload_hash":"fc799854e9896ccf327138b4587bd11c45b93b7634693e0f63bbce52a3288b09","raw_frame":"{\"market\":\"0x717c0e8ccd4d5c7040185188fbae28be901ca589a11a94b1b38ca36a79eccfeb\", \"price_changes\":[{\"asset_id\":\"24254094493625419915756280046002869097156693848522361803041977572204227262166\", \"price\":\"0.04\", \"size\":\"578.09\", \"side\":\"BUY\", \"hash\":\"532b660c1bc0c32044901cba3a98d599a76465a6\", \"best_bid\":\"0.64\", \"best_ask\":\"0.65\"}, {\"asset_id\":\"41448400836309843603620980831210604935021861034693225347475867885462478926555\", \"price\":\"0.96\", \"size\":\"578.09\", \"side\":\"SELL\", \"hash\":\"4319b55ecdf8f52eebf23cb17e966d7a9ac6de30\", \"best_bid\":\"0.35\", \"best_ask\":\"0.36\"}], \"timestamp\":\"1785122715353\", \"event_type\":\"price_change\"}","received_at":"2026-07-27T03:25:17.005135Z","schema_version":"clob-market-ws.price_change.v1","sequence":null,"server_hash":null,"server_timestamp":"1785122715353","session_id":"dd162b8dca5f43ff811d304e69a06123","source":"clob_market_ws"},"received_at":"2026-07-27T03:25:17.005135Z","record_id":"f0231a106759473705c0e8696daa8614e62140998cda52f40ec0b08988a0ac62","schema_fingerprint":"4aa3821a28b0b7c2400bc59aba4bcc0a76e971dadd19610d3ad38c768e124dc7","schema_version":"edge-lab-recorder.raw.v1","sequence":null,"source":"clob_market_ws"}
{"event_at":"2026-07-27T03:25:15.454000Z","event_fingerprint":"e3d366eb4289328781672bf2bbf703034c2ff5a4e24c8ffcba2ab456752bee0f","payload":{"connection_id":"c7dc2e4762f849c6b6f9306b6518dcab","event_at":"2026-07-27T03:25:15.454000Z","event_type":"price_change","frame_hash":"a68a3c8ea54ae97c55e1d968d70975c42e3a6968e4a331d8c55caeff1e1ab76e","frame_index":0,"kind":"data","monotonic_ns":224700378427333,"payload":{"event_type":"price_change","market":"0x717c0e8ccd4d5c7040185188fbae28be901ca589a11a94b1b38ca36a79eccfeb","price_changes":[{"asset_id":"41448400836309843603620980831210604935021861034693225347475867885462478926555","best_ask":"0.36","best_bid":"0.35","hash":"319ad4b9a070f7d77365107b9f2f18666e244f1c","price":"0.42","side":"SELL","size":"11.05"},{"asset_id":"24254094493625419915756280046002869097156693848522361803041977572204227262166","best_ask":"0.65","best_bid":"0.64","hash":"ab974cf15ce41b0245f058593f50e26b32056187","price":"0.58","side":"BUY","size":"11.05"}],"timestamp":"1785122715454"},"payload_hash":"a70028ab3bc9576ee08cda6dc77bc0786c0771ea7df647b30eaa037386062145","raw_frame":"{\"market\":\"0x717c0e8ccd4d5c7040185188fbae28be901ca589a11a94b1b38ca36a79eccfeb\", \"price_changes\":[{\"asset_id\":\"41448400836309843603620980831210604935021861034693225347475867885462478926555\", \"price\":\"0.42\", \"size\":\"11.05\", \"side\":\"SELL\", \"hash\":\"319ad4b9a070f7d77365107b9f2f18666e244f1c\", \"best_bid\":\"0.35\", \"best_ask\":\"0.36\"}, {\"asset_id\":\"24254094493625419915756280046002869097156693848522361803041977572204227262166\", \"price\":\"0.58\", \"size\":\"11.05\", \"side\":\"BUY\", \"hash\":\"ab974cf15ce41b0245f058593f50e26b32056187\", \"best_bid\":\"0.64\", \"best_ask\":\"0.65\"}], \"timestamp\":\"1785122715454\", \"event_type\":\"price_change\"}","received_at":"2026-07-27T03:25:17.019393Z","schema_version":"clob-market-ws.price_change.v1","sequence":null,"server_hash":null,"server_timestamp":"1785122715454","session_id":"dd162b8dca5f43ff811d304e69a06123","source":"clob_market_ws"},"received_at":"2026-07-27T03:25:17.019393Z","record_id":"d1fcea95c5727425f88a47b1a7bc0c565234d016e4f02e6bad5411dd10036e60","schema_fingerprint":"4aa3821a28b0b7c2400bc59aba4bcc0a76e971dadd19610d3ad38c768e124dc7","schema_version":"edge-lab-recorder.raw.v1","sequence":null,"source":"clob_market_ws"}
{"event_at":"2026-07-27T03:25:15.477000Z","event_fingerprint":"b8473b1768ab4984afa630b4b20b9e7c6daa8d443e00efb909050d636a234333","payload":{"connection_id":"c7dc2e4762f849c6b6f9306b6518dcab","event_at":"2026-07-27T03:25:15.477000Z","event_type":"price_change","frame_hash":"6ae65035171bfeaf7442ee61a6ebc7727be25f7660cee8fd4e9d401dd6035794","frame_index":0,"kind":"data","monotonic_ns":224700384932916,"payload":{"event_type":"price_change","market":"0x717c0e8ccd4d5c7040185188fbae28be901ca589a11a94b1b38ca36a79eccfeb","price_changes":[{"asset_id":"24254094493625419915756280046002869097156693848522361803041977572204227262166","best_ask":"0.65","best_bid":"0.64","hash":"b793d4258135f6b271bcf3be252feefe8cfa21e6","price":"0.03","side":"BUY","size":"618.1"},{"asset_id":"41448400836309843603620980831210604935021861034693225347475867885462478926555","best_ask":"0.36","best_bid":"0.35","hash":"676616f21fb733a2b3515957be028da9e4132e9f","price":"0.97","side":"SELL","size":"618.1"}],"timestamp":"1785122715477"},"payload_hash":"dda1f50d93a8840ab59df1161738fda35d2a6a55d26969c2243d8218350f050c","raw_frame":"{\"market\":\"0x717c0e8ccd4d5c7040185188fbae28be901ca589a11a94b1b38ca36a79eccfeb\", \"price_changes\":[{\"asset_id\":\"24254094493625419915756280046002869097156693848522361803041977572204227262166\", \"price\":\"0.03\", \"size\":\"618.1\", \"side\":\"BUY\", \"hash\":\"b793d4258135f6b271bcf3be252feefe8cfa21e6\", \"best_bid\":\"0.64\", \"best_ask\":\"0.65\"}, {\"asset_id\":\"41448400836309843603620980831210604935021861034693225347475867885462478926555\", \"price\":\"0.97\", \"size\":\"618.1\", \"side\":\"SELL\", \"hash\":\"676616f21fb733a2b3515957be028da9e4132e9f\", \"best_bid\":\"0.35\", \"best_ask\":\"0.36\"}], \"timestamp\":\"1785122715477\", \"event_type\":\"price_change\"}","received_at":"2026-07-27T03:25:17.025898Z","schema_version":"clob-market-ws.price_change.v1","sequence":null,"server_hash":null,"server_timestamp":"1785122715477","session_id":"dd162b8dca5f43ff811d304e69a06123","source":"clob_market_ws"},"received_at":"2026-07-27T03:25:17.025898Z","record_id":"58476b31a199ac8e22a59eca0f087f55da31908d66cad53513126e4434f46b93","schema_fingerprint":"4aa3821a28b0b7c2400bc59aba4bcc0a76e971dadd19610d3ad38c768e124dc7","schema_version":"edge-lab-recorder.raw.v1","sequence":null,"source":"clob_market_ws"}
{"event_at":"2026-07-27T03:25:15.485000Z","event_fingerprint":"5e638d953b20ca8720da1697b4fbb4e9499c15c5a4fef17e3a1e588a27f8323e","payload":{"connection_id":"c7dc2e4762f849c6b6f9306b6518dcab","event_at":"2026-07-27T03:25:15.485000Z","event_type":"price_change","frame_hash":"2534d3a88dff384990b4f52835e1ec7dcd4824123dbb98d5d49e79ef2cdc3334","frame_index":0,"kind":"data","monotonic_ns":224700392400833,"payload":{"event_type":"price_change","market":"0x717c0e8ccd4d5c7040185188fbae28be901ca589a11a94b1b38ca36a79eccfeb","price_changes":[{"asset_id":"24254094493625419915756280046002869097156693848522361803041977572204227262166","best_ask":"0.65","best_bid":"0.64","hash":"c5f1be8513ce946a5c66ce434bd4cfc40a05cefd","price":"0.01","side":"BUY","size":"5458.02"},{"asset_id":"41448400836309843603620980831210604935021861034693225347475867885462478926555","best_ask":"0.36","best_bid":"0.35","hash":"6153c1bd343b179a7dd8c6d5d99815bd78314d71","price":"0.99","side":"SELL","size":"5458.02"}],"timestamp":"1785122715485"},"payload_hash":"b5e4d9867bfacdf0aa83a9ab5431367fb1e7c01268615f2d145af7815c807e60","raw_frame":"{\"market\":\"0x717c0e8ccd4d5c7040185188fbae28be901ca589a11a94b1b38ca36a79eccfeb\", \"price_changes\":[{\"asset_id\":\"24254094493625419915756280046002869097156693848522361803041977572204227262166\", \"price\":\"0.01\", \"size\":\"5458.02\", \"side\":\"BUY\", \"hash\":\"c5f1be8513ce946a5c66ce434bd4cfc40a05cefd\", \"best_bid\":\"0.64\", \"best_ask\":\"0.65\"}, {\"asset_id\":\"41448400836309843603620980831210604935021861034693225347475867885462478926555\", \"price\":\"0.99\", \"size\":\"5458.02\", \"side\":\"SELL\", \"hash\":\"6153c1bd343b179a7dd8c6d5d99815bd78314d71\", \"best_bid\":\"0.35\", \"best_ask\":\"0.36\"}], \"timestamp\":\"1785122715485\", \"event_type\":\"price_change\"}","received_at":"2026-07-27T03:25:17.033363Z","schema_version":"clob-market-ws.price_change.v1","sequence":null,"server_hash":null,"server_timestamp":"1785122715485","session_id":"dd162b8dca5f43ff811d304e69a06123","source":"clob_market_ws"},"received_at":"2026-07-27T03:25:17.033363Z","record_id":"70f325f1d07f4f0c6a4d526664fc48cb9fe06e068472eab236024f3aae8f4a0e","schema_fingerprint":"4aa3821a28b0b7c2400bc59aba4bcc0a76e971dadd19610d3ad38c768e124dc7","schema_version":"edge-lab-recorder.raw.v1","sequence":null,"source":"clob_market_ws"}
{"event_at":"2026-07-27T03:25:15.511000Z","event_fingerprint":"88260a09c58f47216f0b2700c4c10e24671de7eff2bea01eb542a0a5d72aaa55","payload":{"connection_id":"c7dc2e4762f849c6b6f9306b6518dcab","event_at":"2026-07-27T03:25:15.511000Z","event_type":"price_change","frame_hash":"fc0839f9482b4ddf5f742e9697fb9ae1b13b003e3998ff97875aafe0f29fb3fd","frame_index":0,"kind":"data","monotonic_ns":224700396761541,"payload":{"event_type":"price_change","market":"0x717c0e8ccd4d5c7040185188fbae28be901ca589a11a94b1b38ca36a79eccfeb","price_changes":[{"asset_id":"24254094493625419915756280046002869097156693848522361803041977572204227262166","best_ask":"0.65","best_bid":"0.64","hash":"7499fe6438d4fb074de33eea80022b95b8fccab6","price":"0.01","side":"BUY","size":"5453.02"},{"asset_id":"41448400836309843603620980831210604935021861034693225347475867885462478926555","best_ask":"0.36","best_bid":"0.35","hash":"d80d9bb68052aaeb9e3d0037c115af7f1f387221","price":"0.99","side":"SELL","size":"5453.02"}],"timestamp":"1785122715511"},"payload_hash":"f335e9706d0249ae3cfcdd6274dda731b72eef7184586a859fe14fa715cedbd6","raw_frame":"{\"market\":\"0x717c0e8ccd4d5c7040185188fbae28be901ca589a11a94b1b38ca36a79eccfeb\", \"price_changes\":[{\"asset_id\":\"24254094493625419915756280046002869097156693848522361803041977572204227262166\", \"price\":\"0.01\", \"size\":\"5453.02\", \"side\":\"BUY\", \"hash\":\"7499fe6438d4fb074de33eea80022b95b8fccab6\", \"best_bid\":\"0.64\", \"best_ask\":\"0.65\"}, {\"asset_id\":\"41448400836309843603620980831210604935021861034693225347475867885462478926555\", \"price\":\"0.99\", \"size\":\"5453.02\", \"side\":\"SELL\", \"hash\":\"d80d9bb68052aaeb9e3d0037c115af7f1f387221\", \"best_bid\":\"0.35\", \"best_ask\":\"0.36\"}], \"timestamp\":\"1785122715511\", \"event_type\":\"price_change\"}","received_at":"2026-07-27T03:25:17.037727Z","schema_version":"clob-market-ws.price_change.v1","sequence":null,"server_hash":null,"server_timestamp":"1785122715511","session_id":"dd162b8dca5f43ff811d304e69a06123","source":"clob_market_ws"},"received_at":"2026-07-27T03:25:17.037727Z","record_id":"537a166d22d90321fa41f3499d1d50bab746d4263df33380ee3c31a46d581fe7","schema_fingerprint":"4aa3821a28b0b7c2400bc59aba4bcc0a76e971dadd19610d3ad38c768e124dc7","schema_version":"edge-lab-recorder.raw.v1","sequence":null,"source":"clob_market_ws"}
{"event_at":"2026-07-27T03:25:15.535000Z","event_fingerprint":"d73972673cd168a24472bf14a1dd9b5cf9dd89b66138d95e4eef82e4f2d51deb","payload":{"connection_id":"c7dc2e4762f849c6b6f9306b6518dcab","event_at":"2026-07-27T03:25:15.535000Z","event_type":"price_change","frame_hash":"df84966de85038afda749c338456cb4ef000977430fb14bf8ea2ec0ace48e975","frame_index":0,"kind":"data","monotonic_ns":224700403168416,"payload":{"event_type":"price_change","market":"0x717c0e8ccd4d5c7040185188fbae28be901ca589a11a94b1b38ca36a79eccfeb","price_changes":[{"asset_id":"24254094493625419915756280046002869097156693848522361803041977572204227262166","best_ask":"0.65","best_bid":"0.64","hash":"2118dd4fc05e4d480ca3edb898c0ff813cfbe7f6","price":"0.03","side":"BUY","size":"613.1"},{"asset_id":"41448400836309843603620980831210604935021861034693225347475867885462478926555","best_ask":"0.36","best_bid":"0.35","hash":"c7a9ca0712b2d18c019527bc309f3259004e4332","price":"0.97","side":"SELL","size":"613.1"}],"timestamp":"1785122715535"},"payload_hash":"773b25e7489e3a3333fdff4b6a763ac0d9f752b6f5eeeb735e4709537ce538dd","raw_frame":"{\"market\":\"0x717c0e8ccd4d5c7040185188fbae28be901ca589a11a94b1b38ca36a79eccfeb\", \"price_changes\":[{\"asset_id\":\"24254094493625419915756280046002869097156693848522361803041977572204227262166\", \"price\":\"0.03\", \"size\":\"613.1\", \"side\":\"BUY\", \"hash\":\"2118dd4fc05e4d480ca3edb898c0ff813cfbe7f6\", \"best_bid\":\"0.64\", \"best_ask\":\"0.65\"}, {\"asset_id\":\"41448400836309843603620980831210604935021861034693225347475867885462478926555\", \"price\":\"0.97\", \"size\":\"613.1\", \"side\":\"SELL\", \"hash\":\"c7a9ca0712b2d18c019527bc309f3259004e4332\", \"best_bid\":\"0.35\", \"best_ask\":\"0.36\"}], \"timestamp\":\"1785122715535\", \"event_type\":\"price_change\"}","received_at":"2026-07-27T03:25:17.044133Z","schema_version":"clob-market-ws.price_change.v1","sequence":null,"server_hash":null,"server_timestamp":"1785122715535","session_id":"dd162b8dca5f43ff811d304e69a06123","source":"clob_market_ws"},"received_at":"2026-07-27T03:25:17.044133Z","record_id":"117e2fdd3f11757aacc8fe39fa4f71870ccb868c2a6a28e1cf203de8c280f2bf","schema_fingerprint":"4aa3821a28b0b7c2400bc59aba4bcc0a76e971dadd19610d3ad38c768e124dc7","schema_version":"edge-lab-recorder.raw.v1","sequence":null,"source":"clob_market_ws"}
{"event_at":"2026-07-27T03:25:15.563000Z","event_fingerprint":"19c54ad3e7489175ae582c3fbf52279dac8efee0114a4ed4b4c153d4651aa9df","payload":{"connection_id":"c7dc2e4762f849c6b6f9306b6518dcab","event_at":"2026-07-27T03:25:15.563000Z","event_type":"price_change","frame_hash":"05286a1f4c0266667b590696a8604d67a70e9bc095e552528f04c25a51387eb3","frame_index":0,"kind":"data","monotonic_ns":224700407726666,"payload":{"event_type":"price_change","market":"0x717c0e8ccd4d5c7040185188fbae28be901ca589a11a94b1b38ca36a79eccfeb","price_changes":[{"asset_id":"41448400836309843603620980831210604935021861034693225347475867885462478926555","best_ask":"0.36","best_bid":"0.35","hash":"665dc97d23880a462faa42ec4d8971803321c9e8","price":"0.42","side":"SELL","size":"5"},{"asset_id":"24254094493625419915756280046002869097156693848522361803041977572204227262166","best_ask":"0.65","best_bid":"0.64","hash":"b162e18265d4b34b7df32adc07b06b8b5cb3ddb4","price":"0.58","side":"BUY","size":"5"}],"timestamp":"1785122715563"},"payload_hash":"0b4052cea220ca3e9f0958159d5241ed40eb66d38d2004e63bd87d795b27542d","raw_frame":"{\"market\":\"0x717c0e8ccd4d5c7040185188fbae28be901ca589a11a94b1b38ca36a79eccfeb\", \"price_changes\":[{\"asset_id\":\"41448400836309843603620980831210604935021861034693225347475867885462478926555\", \"price\":\"0.42\", \"size\":\"5\", \"side\":\"SELL\", \"hash\":\"665dc97d23880a462faa42ec4d8971803321c9e8\", \"best_bid\":\"0.35\", \"best_ask\":\"0.36\"}, {\"asset_id\":\"24254094493625419915756280046002869097156693848522361803041977572204227262166\", \"price\":\"0.58\", \"size\":\"5\", \"side\":\"BUY\", \"hash\":\"b162e18265d4b34b7df32adc07b06b8b5cb3ddb4\", \"best_bid\":\"0.64\", \"best_ask\":\"0.65\"}], \"timestamp\":\"1785122715563\", \"event_type\":\"price_change\"}","received_at":"2026-07-27T03:25:17.048693Z","schema_version":"clob-market-ws.price_change.v1","sequence":null,"server_hash":null,"server_timestamp":"1785122715563","session_id":"dd162b8dca5f43ff811d304e69a06123","source":"clob_market_ws"},"received_at":"2026-07-27T03:25:17.048693Z","record_id":"1c49f54069ca92313bf3bcd7b0e5f727a5395958ce87f3f84d5b40ab795eaafe","schema_fingerprint":"4aa3821a28b0b7c2400bc59aba4bcc0a76e971dadd19610d3ad38c768e124dc7","schema_version":"edge-lab-recorder.raw.v1","sequence":null,"source":"clob_market_ws"}
{"event_at":"2026-07-27T03:25:15.566000Z","event_fingerprint":"f54fdcd5d21166902fe912b12c58e37902753020d28b85caec058541f50aaadb","payload":{"connection_id":"c7dc2e4762f849c6b6f9306b6518dcab","event_at":"2026-07-27T03:25:15.566000Z","event_type":"price_change","frame_hash":"20510c04f996610384d54b2674fb921c29db06d28c69fcf050f6c2a48dd33e4c","frame_index":0,"kind":"data","monotonic_ns":224700412868541,"payload":{"event_type":"price_change","market":"0x717c0e8ccd4d5c7040185188fbae28be901ca589a11a94b1b38ca36a79eccfeb","price_changes":[{"asset_id":"24254094493625419915756280046002869097156693848522361803041977572204227262166","best_ask":"0.65","best_bid":"0.64","hash":"4734559f3f1309f035ecb120920d8aa1a1fd0159","price":"0.59","side":"BUY","size":"36.9"},{"asset_id":"41448400836309843603620980831210604935021861034693225347475867885462478926555","best_ask":"0.36","best_bid":"0.35","hash":"b30b556aaedbc5dc5c1bd6e621205509a018be5f","price":"0.41","side":"SELL","size":"36.9"}],"timestamp":"1785122715566"},"payload_hash":"97e168bb3aa90e59b1be4302d8220a73464d70db8c411273d4cc377504032796","raw_frame":"{\"market\":\"0x717c0e8ccd4d5c7040185188fbae28be901ca589a11a94b1b38ca36a79eccfeb\", \"price_changes\":[{\"asset_id\":\"24254094493625419915756280046002869097156693848522361803041977572204227262166\", \"price\":\"0.59\", \"size\":\"36.9\", \"side\":\"BUY\", \"hash\":\"4734559f3f1309f035ecb120920d8aa1a1fd0159\", \"best_bid\":\"0.64\", \"best_ask\":\"0.65\"}, {\"asset_id\":\"41448400836309843603620980831210604935021861034693225347475867885462478926555\", \"price\":\"0.41\", \"size\":\"36.9\", \"side\":\"SELL\", \"hash\":\"b30b556aaedbc5dc5c1bd6e621205509a018be5f\", \"best_bid\":\"0.35\", \"best_ask\":\"0.36\"}], \"timestamp\":\"1785122715566\", \"event_type\":\"price_change\"}","received_at":"2026-07-27T03:25:17.053833Z","schema_version":"clob-market-ws.price_change.v1","sequence":null,"server_hash":null,"server_timestamp":"1785122715566","session_id":"dd162b8dca5f43ff811d304e69a06123","source":"clob_market_ws"},"received_at":"2026-07-27T03:25:17.053833Z","record_id":"073b3bdafa97b46ba1b08ffd9df24b4584f4a1fda738cd7e742428736acac091","schema_fingerprint":"4aa3821a28b0b7c2400bc59aba4bcc0a76e971dadd19610d3ad38c768e124dc7","schema_version":"edge-lab-recorder.raw.v1","sequence":null,"source":"clob_market_ws"}
{"event_at":"2026-07-27T03:25:15.571000Z","event_fingerprint":"f3aa219efae2a963fefddf052a1f756208cda0d2b9d4863c99fc58bf7bf79d9f","payload":{"connection_id":"c7dc2e4762f849c6b6f9306b6518dcab","event_at":"2026-07-27T03:25:15.571000Z","event_type":"price_change","frame_hash":"5c9cc18d0bc551818286e62553afe4fa94b902407df37bc4ef70db897602202f","frame_index":0,"kind":"data","monotonic_ns":224700418839500,"payload":{"event_type":"price_change","market":"0x717c0e8ccd4d5c7040185188fbae28be901ca589a11a94b1b38ca36a79eccfeb","price_changes":[{"asset_id":"24254094493625419915756280046002869097156693848522361803041977572204227262166","best_ask":"0.65","best_bid":"0.64","hash":"a73e7f9c3a500ee530d316ef01b965299366a5e3","price":"0.57","side":"BUY","size":"0"},{"asset_id":"41448400836309843603620980831210604935021861034693225347475867885462478926555","best_ask":"0.36","best_bid":"0.35","hash":"335596af08dd1871cde48a6c6d186cace0b1fe29","price":"0.43","side":"SELL","size":"0"}],"timestamp":"1785122715571"},"payload_hash":"4259d53dd35dc9bcad957f7b5be7b79031ed24399967c612f436d13ab0a04550","raw_frame":"{\"market\":\"0x717c0e8ccd4d5c7040185188fbae28be901ca589a11a94b1b38ca36a79eccfeb\", \"price_changes\":[{\"asset_id\":\"24254094493625419915756280046002869097156693848522361803041977572204227262166\", \"price\":\"0.57\", \"size\":\"0\", \"side\":\"BUY\", \"hash\":\"a73e7f9c3a500ee530d316ef01b965299366a5e3\", \"best_bid\":\"0.64\", \"best_ask\":\"0.65\"}, {\"asset_id\":\"41448400836309843603620980831210604935021861034693225347475867885462478926555\", \"price\":\"0.43\", \"size\":\"0\", \"side\":\"SELL\", \"hash\":\"335596af08dd1871cde48a6c6d186cace0b1fe29\", \"best_bid\":\"0.35\", \"best_ask\":\"0.36\"}], \"timestamp\":\"1785122715571\", \"event_type\":\"price_change\"}","received_at":"2026-07-27T03:25:17.059803Z","schema_version":"clob-market-ws.price_change.v1","sequence":null,"server_hash":null,"server_timestamp":"1785122715571","session_id":"dd162b8dca5f43ff811d304e69a06123","source":"clob_market_ws"},"received_at":"2026-07-27T03:25:17.059803Z","record_id":"1ffabb6fdf04e7ac6e177e393aa7797075f36bb9f99e95af6f1172a3ad06a052","schema_fingerprint":"4aa3821a28b0b7c2400bc59aba4bcc0a76e971dadd19610d3ad38c768e124dc7","schema_version":"edge-lab-recorder.raw.v1","sequence":null,"source":"clob_market_ws"}
{"event_at":"2026-07-27T03:25:15.612000Z","event_fingerprint":"1c7c6ee5ea77dbdb7e90a39f637aeb96bbd07a33e88c9671ff5cac55b3a41190","payload":{"connection_id":"c7dc2e4762f849c6b6f9306b6518dcab","event_at":"2026-07-27T03:25:15.612000Z","event_type":"price_change","frame_hash":"a2fd300cfeceaca59ccb8b4901904885922799811a7758df70fae9b300585876","frame_index":0,"kind":"data","monotonic_ns":224700422737208,"payload":{"event_type":"price_change","market":"0x717c0e8ccd4d5c7040185188fbae28be901ca589a11a94b1b38ca36a79eccfeb","price_changes":[{"asset_id":"41448400836309843603620980831210604935021861034693225347475867885462478926555","best_ask":"0.36","best_bid":"0.35","hash":"a62533c4b0671206308ac2045fdddf0b923d045e","price":"0.33","side":"BUY","size":"128.21"},{"asset_id":"24254094493625419915756280046002869097156693848522361803041977572204227262166","best_ask":"0.65","best_bid":"0.64","hash":"a33350aea56732e5e5781ea5e55150eeb4b4c5b7","price":"0.67","side":"SELL","size":"128.21"}],"timestamp":"1785122715612"},"payload_hash":"dcaed1ac29363cf5ac195067ff3476067c085f8aab7494428abd5254e368ae78","raw_frame":"{\"market\":\"0x717c0e8ccd4d5c7040185188fbae28be901ca589a11a94b1b38ca36a79eccfeb\", \"price_changes\":[{\"asset_id\":\"41448400836309843603620980831210604935021861034693225347475867885462478926555\", \"price\":\"0.33\", \"size\":\"128.21\", \"side\":\"BUY\", \"hash\":\"a62533c4b0671206308ac2045fdddf0b923d045e\", \"best_bid\":\"0.35\", \"best_ask\":\"0.36\"}, {\"asset_id\":\"24254094493625419915756280046002869097156693848522361803041977572204227262166\", \"price\":\"0.67\", \"size\":\"128.21\", \"side\":\"SELL\", \"hash\":\"a33350aea56732e5e5781ea5e55150eeb4b4c5b7\", \"best_bid\":\"0.64\", \"best_ask\":\"0.65\"}], \"timestamp\":\"1785122715612\", \"event_type\":\"price_change\"}","received_at":"2026-07-27T03:25:17.063702Z","schema_version":"clob-market-ws.price_change.v1","sequence":null,"server_hash":null,"server_timestamp":"1785122715612","session_id":"dd162b8dca5f43ff811d304e69a06123","source":"clob_market_ws"},"received_at":"2026-07-27T03:25:17.063702Z","record_id":"72d6c70330763db3e7e100883b479c42917106d061ab3fdba8290a5a84526ca0","schema_fingerprint":"4aa3821a28b0b7c2400bc59aba4bcc0a76e971dadd19610d3ad38c768e124dc7","schema_version":"edge-lab-recorder.raw.v1","sequence":null,"source":"clob_market_ws"}
{"event_at":"2026-07-27T03:25:15.618000Z","event_fingerprint":"e3446a7ddde141eda5f4e8fe455d5befe129fe258cde20e16eae62d0d9ee4765","payload":{"connection_id":"c7dc2e4762f849c6b6f9306b6518dcab","event_at":"2026-07-27T03:25:15.618000Z","event_type":"price_change","frame_hash":"fe41422ac27a916224c4ee914d30605ab45cde5ee240d7ad81ed318c9bf93485","frame_index":0,"kind":"data","monotonic_ns":224700428955958,"payload":{"event_type":"price_change","market":"0x717c0e8ccd4d5c7040185188fbae28be901ca589a11a94b1b38ca36a79eccfeb","price_changes":[{"asset_id":"24254094493625419915756280046002869097156693848522361803041977572204227262166","best_ask":"0.65","best_bid":"0.64","hash":"64d3d8f06b695b7752c0119534643fb42c87543d","price":"0.02","side":"BUY","size":"688.1"},{"asset_id":"41448400836309843603620980831210604935021861034693225347475867885462478926555","best_ask":"0.36","best_bid":"0.35","hash":"8e7cb9d31fc850e5f72fd871b547dc880027c966","price":"0.98","side":"SELL","size":"688.1"}],"timestamp":"1785122715618"},"payload_hash":"f7e96e1eda487a30b27aaf13ba04619cf2846a16f06164fc5d39872ccc84d765","raw_frame":"{\"market\":\"0x717c0e8ccd4d5c7040185188fbae28be901ca589a11a94b1b38ca36a79eccfeb\", \"price_changes\":[{\"asset_id\":\"24254094493625419915756280046002869097156693848522361803041977572204227262166\", \"price\":\"0.02\", \"size\":\"688.1\", \"side\":\"BUY\", \"hash\":\"64d3d8f06b695b7752c0119534643fb42c87543d\", \"best_bid\":\"0.64\", \"best_ask\":\"0.65\"}, {\"asset_id\":\"41448400836309843603620980831210604935021861034693225347475867885462478926555\", \"price\":\"0.98\", \"size\":\"688.1\", \"side\":\"SELL\", \"hash\":\"8e7cb9d31fc850e5f72fd871b547dc880027c966\", \"best_bid\":\"0.35\", \"best_ask\":\"0.36\"}], \"timestamp\":\"1785122715618\", \"event_type\":\"price_change\"}","received_at":"2026-07-27T03:25:17.069917Z","schema_version":"clob-market-ws.price_change.v1","sequence":null,"server_hash":null,"server_timestamp":"1785122715618","session_id":"dd162b8dca5f43ff811d304e69a06123","source":"clob_market_ws"},"received_at":"2026-07-27T03:25:17.069917Z","record_id":"16fa8c8919a518b9353e1cc8805981b67c4085763844e30e002d60b8c4c9431a","schema_fingerprint":"4aa3821a28b0b7c2400bc59aba4bcc0a76e971dadd19610d3ad38c768e124dc7","schema_version":"edge-lab-recorder.raw.v1","sequence":null,"source":"clob_market_ws"}
{"event_at":"2026-07-27T03:25:15.627000Z","event_fingerprint":"0b47a4ee5e6459892cd4c1e20320be9666dcde135683704be4a88aef115fe46b","payload":{"connection_id":"c7dc2e4762f849c6b6f9306b6518dcab","event_at":"2026-07-27T03:25:15.627000Z","event_type":"price_change","frame_hash":"e2654948e585117511ea4ba23189c131be90cee9905cb5d94bde60baa52467d3","frame_index":0,"kind":"data","monotonic_ns":224700437526000,"payload":{"event_type":"price_change","market":"0x717c0e8ccd4d5c7040185188fbae28be901ca589a11a94b1b38ca36a79eccfeb","price_changes":[{"asset_id":"24254094493625419915756280046002869097156693848522361803041977572204227262166","best_ask":"0.65","best_bid":"0.64","hash":"624d10cf201fb6ff1a20c3583d1baee4ab0ceda7","price":"0.61","side":"BUY","size":"57.08"},{"asset_id":"41448400836309843603620980831210604935021861034693225347475867885462478926555","best_ask":"0.36","best_bid":"0.35","hash":"ba111877ce831c5d0885c8cdb59e64fce2c90518","price":"0.39","side":"SELL","size":"57.08"}],"timestamp":"1785122715627"},"payload_hash":"a1ffd79ac5152155e655e37fbf320d394e0c78185fa2731f5959b4bd2e2b1f1a","raw_frame":"{\"market\":\"0x717c0e8ccd4d5c7040185188fbae28be901ca589a11a94b1b38ca36a79eccfeb\", \"price_changes\":[{\"asset_id\":\"24254094493625419915756280046002869097156693848522361803041977572204227262166\", \"price\":\"0.61\", \"size\":\"57.08\", \"side\":\"BUY\", \"hash\":\"624d10cf201fb6ff1a20c3583d1baee4ab0ceda7\", \"best_bid\":\"0.64\", \"best_ask\":\"0.65\"}, {\"asset_id\":\"41448400836309843603620980831210604935021861034693225347475867885462478926555\", \"price\":\"0.39\", \"size\":\"57.08\", \"side\":\"SELL\", \"hash\":\"ba111877ce831c5d0885c8cdb59e64fce2c90518\", \"best_bid\":\"0.35\", \"best_ask\":\"0.36\"}], \"timestamp\":\"1785122715627\", \"event_type\":\"price_change\"}","received_at":"2026-07-27T03:25:17.078490Z","schema_version":"clob-market-ws.price_change.v1","sequence":null,"server_hash":null,"server_timestamp":"1785122715627","session_id":"dd162b8dca5f43ff811d304e69a06123","source":"clob_market_ws"},"received_at":"2026-07-27T03:25:17.078490Z","record_id":"087f9abfd7caebbf94c2f52034bedb29e35599d7061820361006af32d116011e","schema_fingerprint":"4aa3821a28b0b7c2400bc59aba4bcc0a76e971dadd19610d3ad38c768e124dc7","schema_version":"edge-lab-recorder.raw.v1","sequence":null,"source":"clob_market_ws"}
{"event_at":"2026-07-27T03:25:15.628000Z","event_fingerprint":"3c2ef7fcce1655bff8c0bf741a47b38bcd83efc697b801fdb5d009e27038b9a4","payload":{"connection_id":"c7dc2e4762f849c6b6f9306b6518dcab","event_at":"2026-07-27T03:25:15.628000Z","event_type":"price_change","frame_hash":"56863ff344fdb9553a85cfa3b8c0b1f47a2281ac6b18111b69d5ec2071eb23a1","frame_index":0,"kind":"data","monotonic_ns":224700444770125,"payload":{"event_type":"price_change","market":"0x717c0e8ccd4d5c7040185188fbae28be901ca589a11a94b1b38ca36a79eccfeb","price_changes":[{"asset_id":"41448400836309843603620980831210604935021861034693225347475867885462478926555","best_ask":"0.36","best_bid":"0.35","hash":"fb9c7a362f3b1b4f6957136a749f0e59cceffe63","price":"0.39","side":"SELL","size":"32.08"},{"asset_id":"24254094493625419915756280046002869097156693848522361803041977572204227262166","best_ask":"0.65","best_bid":"0.64","hash":"7fb216d95b29f50cde3379fe31e9cfed07c173ca","price":"0.61","side":"BUY","size":"32.08"}],"timestamp":"1785122715628"},"payload_hash":"703b9a7fc87941bb5978ed043cc9e35c9a94cb13af21ae56cd457468e404467e","raw_frame":"{\"market\":\"0x717c0e8ccd4d5c7040185188fbae28be901ca589a11a94b1b38ca36a79eccfeb\", \"price_changes\":[{\"asset_id\":\"41448400836309843603620980831210604935021861034693225347475867885462478926555\", \"price\":\"0.39\", \"size\":\"32.08\", \"side\":\"SELL\", \"hash\":\"fb9c7a362f3b1b4f6957136a749f0e59cceffe63\", \"best_bid\":\"0.35\", \"best_ask\":\"0.36\"}, {\"asset_id\":\"24254094493625419915756280046002869097156693848522361803041977572204227262166\", \"price\":\"0.61\", \"size\":\"32.08\", \"side\":\"BUY\", \"hash\":\"7fb216d95b29f50cde3379fe31e9cfed07c173ca\", \"best_bid\":\"0.64\", \"best_ask\":\"0.65\"}], \"timestamp\":\"1785122715628\", \"event_type\":\"price_change\"}","received_at":"2026-07-27T03:25:17.085731Z","schema_version":"clob-market-ws.price_change.v1","sequence":null,"server_hash":null,"server_timestamp":"1785122715628","session_id":"dd162b8dca5f43ff811d304e69a06123","source":"clob_market_ws"},"received_at":"2026-07-27T03:25:17.085731Z","record_id":"a66eeae4423f3fd2b7eb2300bc9b0fba731307e89e43c4a4e64e94ea447c772e","schema_fingerprint":"4aa3821a28b0b7c2400bc59aba4bcc0a76e971dadd19610d3ad38c768e124dc7","schema_version":"edge-lab-recorder.raw.v1","sequence":null,"source":"clob_market_ws"}
{"event_at":"2026-07-27T03:25:15.629000Z","event_fingerprint":"c3a828960d3b8e3d4dd4257d86e915bf4cd2958dff6646e295ab394535221959","payload":{"connection_id":"c7dc2e4762f849c6b6f9306b6518dcab","event_at":"2026-07-27T03:25:15.629000Z","event_type":"price_change","frame_hash":"1ead2bc83f420f5759a4169468544fbea068bd64a1465c02545a02f9bfbee0d8","frame_index":0,"kind":"data","monotonic_ns":224700449931125,"payload":{"event_type":"price_change","market":"0x717c0e8ccd4d5c7040185188fbae28be901ca589a11a94b1b38ca36a79eccfeb","price_changes":[{"asset_id":"41448400836309843603620980831210604935021861034693225347475867885462478926555","best_ask":"0.36","best_bid":"0.35","hash":"d2395347bd6f610a3cb7f24a323cf059c01dcb02","price":"0.32","side":"BUY","size":"68.21"},{"asset_id":"24254094493625419915756280046002869097156693848522361803041977572204227262166","best_ask":"0.65","best_bid":"0.64","hash":"6122fceabda75c9ab6dfbf97249acf3068f1223a","price":"0.68","side":"SELL","size":"68.21"}],"timestamp":"1785122715629"},"payload_hash":"45ea6a381c29c88977a5e4ca45fc2be40ccc413c4243d0932452c819c9226949","raw_frame":"{\"market\":\"0x717c0e8ccd4d5c7040185188fbae28be901ca589a11a94b1b38ca36a79eccfeb\", \"price_changes\":[{\"asset_id\":\"41448400836309843603620980831210604935021861034693225347475867885462478926555\", \"price\":\"0.32\", \"size\":\"68.21\", \"side\":\"BUY\", \"hash\":\"d2395347bd6f610a3cb7f24a323cf059c01dcb02\", \"best_bid\":\"0.35\", \"best_ask\":\"0.36\"}, {\"asset_id\":\"24254094493625419915756280046002869097156693848522361803041977572204227262166\", \"price\":\"0.68\", \"size\":\"68.21\", \"side\":\"SELL\", \"hash\":\"6122fceabda75c9ab6dfbf97249acf3068f1223a\", \"best_bid\":\"0.64\", \"best_ask\":\"0.65\"}], \"timestamp\":\"1785122715629\", \"event_type\":\"price_change\"}","received_at":"2026-07-27T03:25:17.090874Z","schema_version":"clob-market-ws.price_change.v1","sequence":null,"server_hash":null,"server_timestamp":"1785122715629","session_id":"dd162b8dca5f43ff811d304e69a06123","source":"clob_market_ws"},"received_at":"2026-07-27T03:25:17.090874Z","record_id":"eb8b0d7463ffaff33bc0aeb844a196a2d5eb2a9d4ab37e1ba3c508fba93074b3","schema_fingerprint":"4aa3821a28b0b7c2400bc59aba4bcc0a76e971dadd19610d3ad38c768e124dc7","schema_version":"edge-lab-recorder.raw.v1","sequence":null,"source":"clob_market_ws"}
{"event_at":"2026-07-27T03:25:15.631000Z","event_fingerprint":"a6de1f30532e3922633d96a5188bc14f4daff7ee320a85084158744ae08e0dc1","payload":{"connection_id":"c7dc2e4762f849c6b6f9306b6518dcab","event_at":"2026-07-27T03:25:15.631000Z","event_type":"price_change","frame_hash":"41dcce463830135ea8318848aa512ca6bf21156dba707e0418522ce4b2310966","frame_index":0,"kind":"data","monotonic_ns":224700456757166,"payload":{"event_type":"price_change","market":"0x717c0e8ccd4d5c7040185188fbae28be901ca589a11a94b1b38ca36a79eccfeb","price_changes":[{"asset_id":"41448400836309843603620980831210604935021861034693225347475867885462478926555","best_ask":"0.36","best_bid":"0.35","hash":"e7c294f910796c10ddf05d890cc8f8d3ad77665d","price":"0.31","side":"BUY","size":"293.21"},{"asset_id":"24254094493625419915756280046002869097156693848522361803041977572204227262166","best_ask":"0.65","best_bid":"0.64","hash":"b16c4841b8f5cfdc28a948cf06d2aa95f01c03fa","price":"0.69","side":"SELL","size":"293.21"}],"timestamp":"1785122715631"},"payload_hash":"309dd752c2a5eca5aea1f46b3891f992b04ca13c37f377ad2e1a1025dadcc6be","raw_frame":"{\"market\":\"0x717c0e8ccd4d5c7040185188fbae28be901ca589a11a94b1b38ca36a79eccfeb\", \"price_changes\":[{\"asset_id\":\"41448400836309843603620980831210604935021861034693225347475867885462478926555\", \"price\":\"0.31\", \"size\":\"293.21\", \"side\":\"BUY\", \"hash\":\"e7c294f910796c10ddf05d890cc8f8d3ad77665d\", \"best_bid\":\"0.35\", \"best_ask\":\"0.36\"}, {\"asset_id\":\"24254094493625419915756280046002869097156693848522361803041977572204227262166\", \"price\":\"0.69\", \"size\":\"293.21\", \"side\":\"SELL\", \"hash\":\"b16c4841b8f5cfdc28a948cf06d2aa95f01c03fa\", \"best_bid\":\"0.64\", \"best_ask\":\"0.65\"}], \"timestamp\":\"1785122715631\", \"event_type\":\"price_change\"}","received_at":"2026-07-27T03:25:17.097722Z","schema_version":"clob-market-ws.price_change.v1","sequence":null,"server_hash":null,"server_timestamp":"1785122715631","session_id":"dd162b8dca5f43ff811d304e69a06123","source":"clob_market_ws"},"received_at":"2026-07-27T03:25:17.097722Z","record_id":"0b9349ad4359b7baa815665707672b9af6a88f8f581f82a5b761df563e0974ac","schema_fingerprint":"4aa3821a28b0b7c2400bc59aba4bcc0a76e971dadd19610d3ad38c768e124dc7","schema_version":"edge-lab-recorder.raw.v1","sequence":null,"source":"clob_market_ws"}
{"event_at":"2026-07-27T03:25:15.633000Z","event_fingerprint":"cc89012385444a5cbd92660ac58d74ae15e01551c918e8cd1129448f93d32c3d","payload":{"connection_id":"c7dc2e4762f849c6b6f9306b6518dcab","event_at":"2026-07-27T03:25:15.633000Z","event_type":"price_change","frame_hash":"81656fcd00e917f78faf2c03b64ba4238053cbd31c7c1bb1d58a4092313847ae","frame_index":0,"kind":"data","monotonic_ns":224700462280333,"payload":{"event_type":"price_change","market":"0x717c0e8ccd4d5c7040185188fbae28be901ca589a11a94b1b38ca36a79eccfeb","price_changes":[{"asset_id":"24254094493625419915756280046002869097156693848522361803041977572204227262166","best_ask":"0.65","best_bid":"0.64","hash":"1b5f3b76124ad515ba88b329732a69831fca3f7e","price":"0.8","side":"SELL","size":"251.8"},{"asset_id":"41448400836309843603620980831210604935021861034693225347475867885462478926555","best_ask":"0.36","best_bid":"0.35","hash":"52e7b997a9b00070a7eb002c2cf10f1dcdf79465","price":"0.2","side":"BUY","size":"251.8"}],"timestamp":"1785122715633"},"payload_hash":"e3e3600762b9bc4a1d2d4db42ebf6f622f4bd59e5bd21f247c42cd5dbcba883d","raw_frame":"{\"market\":\"0x717c0e8ccd4d5c7040185188fbae28be901ca589a11a94b1b38ca36a79eccfeb\", \"price_changes\":[{\"asset_id\":\"24254094493625419915756280046002869097156693848522361803041977572204227262166\", \"price\":\"0.8\", \"size\":\"251.8\", \"side\":\"SELL\", \"hash\":\"1b5f3b76124ad515ba88b329732a69831fca3f7e\", \"best_bid\":\"0.64\", \"best_ask\":\"0.65\"}, {\"asset_id\":\"41448400836309843603620980831210604935021861034693225347475867885462478926555\", \"price\":\"0.2\", \"size\":\"251.8\", \"side\":\"BUY\", \"hash\":\"52e7b997a9b00070a7eb002c2cf10f1dcdf79465\", \"best_bid\":\"0.35\", \"best_ask\":\"0.36\"}], \"timestamp\":\"1785122715633\", \"event_type\":\"price_change\"}","received_at":"2026-07-27T03:25:17.103244Z","schema_version":"clob-market-ws.price_change.v1","sequence":null,"server_hash":null,"server_timestamp":"1785122715633","session_id":"dd162b8dca5f43ff811d304e69a06123","source":"clob_market_ws"},"received_at":"2026-07-27T03:25:17.103244Z","record_id":"d681be6bd947db6b84febb2aff8432885d7f649e10ae92394c82d3f5772f02ee","schema_fingerprint":"4aa3821a28b0b7c2400bc59aba4bcc0a76e971dadd19610d3ad38c768e124dc7","schema_version":"edge-lab-recorder.raw.v1","sequence":null,"source":"clob_market_ws"}
{"event_at":"2026-07-27T03:25:15.634000Z","event_fingerprint":"74255aa5eaa1e9d59f3ba6e8adc4a5a54ddd40313a87135dbea7f4e1e7055653","payload":{"connection_id":"c7dc2e4762f849c6b6f9306b6518dcab","event_at":"2026-07-27T03:25:15.634000Z","event_type":"price_change","frame_hash":"f894ea22df339fcbcbd054c968cbc6d3570d8e48696a5d0a1083956bf75b1ca4","frame_index":0,"kind":"data","monotonic_ns":224700470128375,"payload":{"event_type":"price_change","market":"0x717c0e8ccd4d5c7040185188fbae28be901ca589a11a94b1b38ca36a79eccfeb","price_changes":[{"asset_id":"24254094493625419915756280046002869097156693848522361803041977572204227262166","best_ask":"0.65","best_bid":"0.64","hash":"c6bd5570f1c8cd1375147a8e8e74c1bdfcba5a2a","price":"0.63","side":"BUY","size":"10"},{"asset_id":"41448400836309843603620980831210604935021861034693225347475867885462478926555","best_ask":"0.36","best_bid":"0.35","hash":"e00c75ff690d370e2b5c148ad2c593ff6eaba590","price":"0.37","side":"SELL","size":"10"}],"timestamp":"1785122715634"},"payload_hash":"0337a70bc306a7d041d6b407d0f52512d338505f2e4f1e7864ff12ca690e2d94","raw_frame":"{\"market\":\"0x717c0e8ccd4d5c7040185188fbae28be901ca589a11a94b1b38ca36a79eccfeb\", \"price_changes\":[{\"asset_id\":\"24254094493625419915756280046002869097156693848522361803041977572204227262166\", \"price\":\"0.63\", \"size\":\"10\", \"side\":\"BUY\", \"hash\":\"c6bd5570f1c8cd1375147a8e8e74c1bdfcba5a2a\", \"best_bid\":\"0.64\", \"best_ask\":\"0.65\"}, {\"asset_id\":\"41448400836309843603620980831210604935021861034693225347475867885462478926555\", \"price\":\"0.37\", \"size\":\"10\", \"side\":\"SELL\", \"hash\":\"e00c75ff690d370e2b5c148ad2c593ff6eaba590\", \"best_bid\":\"0.35\", \"best_ask\":\"0.36\"}], \"timestamp\":\"1785122715634\", \"event_type\":\"price_change\"}","received_at":"2026-07-27T03:25:17.111093Z","schema_version":"clob-market-ws.price_change.v1","sequence":null,"server_hash":null,"server_timestamp":"1785122715634","session_id":"dd162b8dca5f43ff811d304e69a06123","source":"clob_market_ws"},"received_at":"2026-07-27T03:25:17.111093Z","record_id":"beaed400b38f083d23fd8534ba70eb6ba9906ea596f40cb9f65e5d74483e49a4","schema_fingerprint":"4aa3821a28b0b7c2400bc59aba4bcc0a76e971dadd19610d3ad38c768e124dc7","schema_version":"edge-lab-recorder.raw.v1","sequence":null,"source":"clob_market_ws"}
{"event_at":"2026-07-27T03:25:15.645000Z","event_fingerprint":"da7004449742daac0a0fe009f4c0ebf7da30beea59ac8d4d99a419275965be8b","payload":{"connection_id":"c7dc2e4762f849c6b6f9306b6518dcab","event_at":"2026-07-27T03:25:15.645000Z","event_type":"price_change","frame_hash":"04c36ad1c4e9b3bb7cdbd1dc5a9614c05a19fe28742cc350ec7fd2874949116f","frame_index":0,"kind":"data","monotonic_ns":224700478210458,"payload":{"event_type":"price_change","market":"0x717c0e8ccd4d5c7040185188fbae28be901ca589a11a94b1b38ca36a79eccfeb","price_changes":[{"asset_id":"41448400836309843603620980831210604935021861034693225347475867885462478926555","best_ask":"0.36","best_bid":"0.35","hash":"e4341caee7b60478dd7a761dc36c1c9f07a39842","price":"0.31","side":"BUY","size":"283.21"},{"asset_id":"24254094493625419915756280046002869097156693848522361803041977572204227262166","best_ask":"0.65","best_bid":"0.64","hash":"186f73fbd8f230b49492efeadb91602ee4479f26","price":"0.69","side":"SELL","size":"283.21"}],"timestamp":"1785122715645"},"payload_hash":"84e9bc7c9139583a16d88abe309b7ecb0e8dc40d5087f313ed8e4fc11365f3e6","raw_frame":"{\"market\":\"0x717c0e8ccd4d5c7040185188fbae28be901ca589a11a94b1b38ca36a79eccfeb\", \"price_changes\":[{\"asset_id\":\"41448400836309843603620980831210604935021861034693225347475867885462478926555\", \"price\":\"0.31\", \"size\":\"283.21\", \"side\":\"BUY\", \"hash\":\"e4341caee7b60478dd7a761dc36c1c9f07a39842\", \"best_bid\":\"0.35\", \"best_ask\":\"0.36\"}, {\"asset_id\":\"24254094493625419915756280046002869097156693848522361803041977572204227262166\", \"price\":\"0.69\", \"size\":\"283.21\", \"side\":\"SELL\", \"hash\":\"186f73fbd8f230b49492efeadb91602ee4479f26\", \"best_bid\":\"0.64\", \"best_ask\":\"0.65\"}], \"timestamp\":\"1785122715645\", \"event_type\":\"price_change\"}","received_at":"2026-07-27T03:25:17.119174Z","schema_version":"clob-market-ws.price_change.v1","sequence":null,"server_hash":null,"server_timestamp":"1785122715645","session_id":"dd162b8dca5f43ff811d304e69a06123","source":"clob_market_ws"},"received_at":"2026-07-27T03:25:17.119174Z","record_id":"efc91da24009f4d96ca6aa480ba84c073bb8775c12a9255e1b5298c36502c85f","schema_fingerprint":"4aa3821a28b0b7c2400bc59aba4bcc0a76e971dadd19610d3ad38c768e124dc7","schema_version":"edge-lab-recorder.raw.v1","sequence":null,"source":"clob_market_ws"}
{"event_at":"2026-07-27T03:25:15.645000Z","event_fingerprint":"a3026568a562cfd7d28c19cb1d5b34666aae5dfbd4136b36f2763d447e3879f4","payload":{"connection_id":"c7dc2e4762f849c6b6f9306b6518dcab","event_at":"2026-07-27T03:25:15.645000Z","event_type":"price_change","frame_hash":"2fe132fd4e0074bae519c5a18862d18c3cd761f4b8e676302adb15b12a743888","frame_index":0,"kind":"data","monotonic_ns":224700484151416,"payload":{"event_type":"price_change","market":"0x717c0e8ccd4d5c7040185188fbae28be901ca589a11a94b1b38ca36a79eccfeb","price_changes":[{"asset_id":"24254094493625419915756280046002869097156693848522361803041977572204227262166","best_ask":"0.65","best_bid":"0.64","hash":"186f73fbd8f230b49492efeadb91602ee4479f26","price":"0.59","side":"BUY","size":"26.9"},{"asset_id":"41448400836309843603620980831210604935021861034693225347475867885462478926555","best_ask":"0.36","best_bid":"0.35","hash":"e4341caee7b60478dd7a761dc36c1c9f07a39842","price":"0.41","side":"SELL","size":"26.9"}],"timestamp":"1785122715645"},"payload_hash":"0c7e4b034e5965eb4d89f9ae0bc083ffc31f6e47910d1a7da4a0e1d7c417f45b","raw_frame":"{\"market\":\"0x717c0e8ccd4d5c7040185188fbae28be901ca589a11a94b1b38ca36a79eccfeb\", \"price_changes\":[{\"asset_id\":\"24254094493625419915756280046002869097156693848522361803041977572204227262166\", \"price\":\"0.59\", \"size\":\"26.9\", \"side\":\"BUY\", \"hash\":\"186f73fbd8f230b49492efeadb91602ee4479f26\", \"best_bid\":\"0.64\", \"best_ask\":\"0.65\"}, {\"asset_id\":\"41448400836309843603620980831210604935021861034693225347475867885462478926555\", \"price\":\"0.41\", \"size\":\"26.9\", \"side\":\"SELL\", \"hash\":\"e4341caee7b60478dd7a761dc36c1c9f07a39842\", \"best_bid\":\"0.35\", \"best_ask\":\"0.36\"}], \"timestamp\":\"1785122715645\", \"event_type\":\"price_change\"}","received_at":"2026-07-27T03:25:17.125113Z","schema_version":"clob-market-ws.price_change.v1","sequence":null,"server_hash":null,"server_timestamp":"1785122715645","session_id":"dd162b8dca5f43ff811d304e69a06123","source":"clob_market_ws"},"received_at":"2026-07-27T03:25:17.125113Z","record_id":"8828174d28c766529698ccfdf8f3eb0e60c53ebd06835e782fa019d9c7ed3d29","schema_fingerprint":"4aa3821a28b0b7c2400bc59aba4bcc0a76e971dadd19610d3ad38c768e124dc7","schema_version":"edge-lab-recorder.raw.v1","sequence":null,"source":"clob_market_ws"}
{"event_at":"2026-07-27T03:25:15.650000Z","event_fingerprint":"ae9aa1be9fbf02620cf28074ce34f404b56b45eae929ce321da6f19541316bab","payload":{"connection_id":"c7dc2e4762f849c6b6f9306b6518dcab","event_at":"2026-07-27T03:25:15.650000Z","event_type":"price_change","frame_hash":"f5ac45a282b1fa6723542f4646682f9e6d9c4e116d98a9034d24117db4c44829","frame_index":0,"kind":"data","monotonic_ns":224700489882083,"payload":{"event_type":"price_change","market":"0x717c0e8ccd4d5c7040185188fbae28be901ca589a11a94b1b38ca36a79eccfeb","price_changes":[{"asset_id":"41448400836309843603620980831210604935021861034693225347475867885462478926555","best_ask":"0.36","best_bid":"0.35","hash":"f1fd0caac2e4f0a9f4acce748266a91780351c54","price":"0.38","side":"SELL","size":"37.51"},{"asset_id":"24254094493625419915756280046002869097156693848522361803041977572204227262166","best_ask":"0.65","best_bid":"0.64","hash":"2f31c03711c5f9b71890f41b9bb936bad14a1d0b","price":"0.62","side":"BUY","size":"37.51"}],"timestamp":"1785122715650"},"payload_hash":"f7880150adc4325f0b599f4548e0421ce76cc39c97e7a8b769f24817d099dec4","raw_frame":"{\"market\":\"0x717c0e8ccd4d5c7040185188fbae28be901ca589a11a94b1b38ca36a79eccfeb\", \"price_changes\":[{\"asset_id\":\"41448400836309843603620980831210604935021861034693225347475867885462478926555\", \"price\":\"0.38\", \"size\":\"37.51\", \"side\":\"SELL\", \"hash\":\"f1fd0caac2e4f0a9f4acce748266a91780351c54\", \"best_bid\":\"0.35\", \"best_ask\":\"0.36\"}, {\"asset_id\":\"24254094493625419915756280046002869097156693848522361803041977572204227262166\", \"price\":\"0.62\", \"size\":\"37.51\", \"side\":\"BUY\", \"hash\":\"2f31c03711c5f9b71890f41b9bb936bad14a1d0b\", \"best_bid\":\"0.64\", \"best_ask\":\"0.65\"}], \"timestamp\":\"1785122715650\", \"event_type\":\"price_change\"}","received_at":"2026-07-27T03:25:17.130845Z","schema_version":"clob-market-ws.price_change.v1","sequence":null,"server_hash":null,"server_timestamp":"1785122715650","session_id":"dd162b8dca5f43ff811d304e69a06123","source":"clob_market_ws"},"received_at":"2026-07-27T03:25:17.130845Z","record_id":"c23ef1ab4a6af5cd159c7fd425e70ae7c4d57fd6174d9c965e8ce3ae79af1299","schema_fingerprint":"4aa3821a28b0b7c2400bc59aba4bcc0a76e971dadd19610d3ad38c768e124dc7","schema_version":"edge-lab-recorder.raw.v1","sequence":null,"source":"clob_market_ws"}
{"event_at":"2026-07-27T03:25:15.655000Z","event_fingerprint":"c78ebadf6d7428ec59b6b5dbada64a1d84486599916d9e7df15db7cc3dc7f6e2","payload":{"connection_id":"c7dc2e4762f849c6b6f9306b6518dcab","event_at":"2026-07-27T03:25:15.655000Z","event_type":"price_change","frame_hash":"54a8f89c16cab0ad4e70f7cba2538f1cbdd4654c24418b31dd444449739cb35f","frame_index":0,"kind":"data","monotonic_ns":224700496876166,"payload":{"event_type":"price_change","market":"0x717c0e8ccd4d5c7040185188fbae28be901ca589a11a94b1b38ca36a79eccfeb","price_changes":[{"asset_id":"24254094493625419915756280046002869097156693848522361803041977572204227262166","best_ask":"0.65","best_bid":"0.64","hash":"189acd1e804c6f58c71e9e9543857c4cd878dc94","price":"0.01","side":"BUY","size":"5458.02"},{"asset_id":"41448400836309843603620980831210604935021861034693225347475867885462478926555","best_ask":"0.36","best_bid":"0.35","hash":"c5c381016eebeac6f5f13f2c91432882af19ee73","price":"0.99","side":"SELL","size":"5458.02"}],"timestamp":"1785122715655"},"payload_hash":"5f3b0ca4bfb0a88b37812a0f2a98b8ad879e73797f7a02728e4214a132f898f4","raw_frame":"{\"market\":\"0x717c0e8ccd4d5c7040185188fbae28be901ca589a11a94b1b38ca36a79eccfeb\", \"price_changes\":[{\"asset_id\":\"24254094493625419915756280046002869097156693848522361803041977572204227262166\", \"price\":\"0.01\", \"size\":\"5458.02\", \"side\":\"BUY\", \"hash\":\"189acd1e804c6f58c71e9e9543857c4cd878dc94\", \"best_bid\":\"0.64\", \"best_ask\":\"0.65\"}, {\"asset_id\":\"41448400836309843603620980831210604935021861034693225347475867885462478926555\", \"price\":\"0.99\", \"size\":\"5458.02\", \"side\":\"SELL\", \"hash\":\"c5c381016eebeac6f5f13f2c91432882af19ee73\", \"best_bid\":\"0.35\", \"best_ask\":\"0.36\"}], \"timestamp\":\"1785122715655\", \"event_type\":\"price_change\"}","received_at":"2026-07-27T03:25:17.137838Z","schema_version":"clob-market-ws.price_change.v1","sequence":null,"server_hash":null,"server_timestamp":"1785122715655","session_id":"dd162b8dca5f43ff811d304e69a06123","source":"clob_market_ws"},"received_at":"2026-07-27T03:25:17.137838Z","record_id":"b6e2cb0ca0f7747583c481269da7660e1c558f35b36fbadbd5b3f289d2a06a17","schema_fingerprint":"4aa3821a28b0b7c2400bc59aba4bcc0a76e971dadd19610d3ad38c768e124dc7","schema_version":"edge-lab-recorder.raw.v1","sequence":null,"source":"clob_market_ws"}
{"event_at":"2026-07-27T03:25:15.656000Z","event_fingerprint":"9610a0873fde4cd4eb1067ab4ac3abb1b6b5fda9b922998311501f0034d15376","payload":{"connection_id":"c7dc2e4762f849c6b6f9306b6518dcab","event_at":"2026-07-27T03:25:15.656000Z","event_type":"price_change","frame_hash":"bc9ff7445af39ad809ec5fab4320549a80173ce93daebabf05c692d605d84045","frame_index":0,"kind":"data","monotonic_ns":224700502575416,"payload":{"event_type":"price_change","market":"0x717c0e8ccd4d5c7040185188fbae28be901ca589a11a94b1b38ca36a79eccfeb","price_changes":[{"asset_id":"24254094493625419915756280046002869097156693848522361803041977572204227262166","best_ask":"0.65","best_bid":"0.64","hash":"b5bb3384c1aa8a395ed4d5ca029a026865d1adae","price":"0.62","side":"BUY","size":"62.51"},{"asset_id":"41448400836309843603620980831210604935021861034693225347475867885462478926555","best_ask":"0.36","best_bid":"0.35","hash":"9f269e3262b8cfa94ada969e09e3068e82b40b89","price":"0.38","side":"SELL","size":"62.51"}],"timestamp":"1785122715656"},"payload_hash":"2d4581dd444275c65b573da6b70d3a4be2b81e7d7c7dfcc3ab4ce0fccdef2fc7","raw_frame":"{\"market\":\"0x717c0e8ccd4d5c7040185188fbae28be901ca589a11a94b1b38ca36a79eccfeb\", \"price_changes\":[{\"asset_id\":\"24254094493625419915756280046002869097156693848522361803041977572204227262166\", \"price\":\"0.62\", \"size\":\"62.51\", \"side\":\"BUY\", \"hash\":\"b5bb3384c1aa8a395ed4d5ca029a026865d1adae\", \"best_bid\":\"0.64\", \"best_ask\":\"0.65\"}, {\"asset_id\":\"41448400836309843603620980831210604935021861034693225347475867885462478926555\", \"price\":\"0.38\", \"size\":\"62.51\", \"side\":\"SELL\", \"hash\":\"9f269e3262b8cfa94ada969e09e3068e82b40b89\", \"best_bid\":\"0.35\", \"best_ask\":\"0.36\"}], \"timestamp\":\"1785122715656\", \"event_type\":\"price_change\"}","received_at":"2026-07-27T03:25:17.143538Z","schema_version":"clob-market-ws.price_change.v1","sequence":null,"server_hash":null,"server_timestamp":"1785122715656","session_id":"dd162b8dca5f43ff811d304e69a06123","source":"clob_market_ws"},"received_at":"2026-07-27T03:25:17.143538Z","record_id":"96ee05d84f1fed298c719b6bc0ce4d8935ebbf409d4b04c850b597b194e3b425","schema_fingerprint":"4aa3821a28b0b7c2400bc59aba4bcc0a76e971dadd19610d3ad38c768e124dc7","schema_version":"edge-lab-recorder.raw.v1","sequence":null,"source":"clob_market_ws"}
{"event_at":"2026-07-27T03:25:15.663000Z","event_fingerprint":"74c9356f1fe6d1dcf792888a66e8ae53c7fbc8cd40d6effbd577ee6720297b0f","payload":{"connection_id":"c7dc2e4762f849c6b6f9306b6518dcab","event_at":"2026-07-27T03:25:15.663000Z","event_type":"price_change","frame_hash":"8c3002a9273b7ea206de8232c0732402d3d3931d4f713de25a8626cb66551eb2","frame_index":0,"kind":"data","monotonic_ns":224700518134583,"payload":{"event_type":"price_change","market":"0x717c0e8ccd4d5c7040185188fbae28be901ca589a11a94b1b38ca36a79eccfeb","price_changes":[{"asset_id":"24254094493625419915756280046002869097156693848522361803041977572204227262166","best_ask":"0.65","best_bid":"0.64","hash":"4435b7abd9ebdc141d4d3b06707edb2a5062c38e","price":"0.81","side":"SELL","size":"584.79"},{"asset_id":"41448400836309843603620980831210604935021861034693225347475867885462478926555","best_ask":"0.36","best_bid":"0.35","hash":"d63bcb17b9421fbc0b61bd2cf5ca99d5d58c9bd1","price":"0.19","side":"BUY","size":"584.79"}],"timestamp":"1785122715663"},"payload_hash":"331dce6eb8d6d14479132da72d456d4c64d97c9da281db879ef23b14274c3864","raw_frame":"{\"market\":\"0x717c0e8ccd4d5c7040185188fbae28be901ca589a11a94b1b38ca36a79eccfeb\", \"price_changes\":[{\"asset_id\":\"24254094493625419915756280046002869097156693848522361803041977572204227262166\", \"price\":\"0.81\", \"size\":\"584.79\", \"side\":\"SELL\", \"hash\":\"4435b7abd9ebdc141d4d3b06707edb2a5062c38e\", \"best_bid\":\"0.64\", \"best_ask\":\"0.65\"}, {\"asset_id\":\"41448400836309843603620980831210604935021861034693225347475867885462478926555\", \"price\":\"0.19\", \"size\":\"584.79\", \"side\":\"BUY\", \"hash\":\"d63bcb17b9421fbc0b61bd2cf5ca99d5d58c9bd1\", \"best_bid\":\"0.35\", \"best_ask\":\"0.36\"}], \"timestamp\":\"1785122715663\", \"event_type\":\"price_change\"}","received_at":"2026-07-27T03:25:17.159097Z","schema_version":"clob-market-ws.price_change.v1","sequence":null,"server_hash":null,"server_timestamp":"1785122715663","session_id":"dd162b8dca5f43ff811d304e69a06123","source":"clob_market_ws"},"received_at":"2026-07-27T03:25:17.159097Z","record_id":"192a303021c5e2465abf2a8dac41ac55954cd354e5bfaf5196f3e403d140842c","schema_fingerprint":"4aa3821a28b0b7c2400bc59aba4bcc0a76e971dadd19610d3ad38c768e124dc7","schema_version":"edge-lab-recorder.raw.v1","sequence":null,"source":"clob_market_ws"}
{"event_at":"2026-07-27T03:25:15.665000Z","event_fingerprint":"58e5f413f501be01d895b63723478726eb54916387038279db00e9ce2e9d19f5","payload":{"connection_id":"c7dc2e4762f849c6b6f9306b6518dcab","event_at":"2026-07-27T03:25:15.665000Z","event_type":"price_change","frame_hash":"721c29b6c8dad6526f89231551cc0904441a9e51b03d4142eb29b5ded036ad32","frame_index":0,"kind":"data","monotonic_ns":224700534602708,"payload":{"event_type":"price_change","market":"0x717c0e8ccd4d5c7040185188fbae28be901ca589a11a94b1b38ca36a79eccfeb","price_changes":[{"asset_id":"24254094493625419915756280046002869097156693848522361803041977572204227262166","best_ask":"0.65","best_bid":"0.64","hash":"90c99425100dc39336d768d9990e3efc23b5d4e5","price":"0.59","side":"BUY","size":"21.9"},{"asset_id":"41448400836309843603620980831210604935021861034693225347475867885462478926555","best_ask":"0.36","best_bid":"0.35","hash":"25af5a09db228bf336c3742d59fa1cf58949cde2","price":"0.41","side":"SELL","size":"21.9"}],"timestamp":"1785122715665"},"payload_hash":"9dca9418e8ece878a0f5347a3c557d92e4d0773697711cda36a7776352d44a56","raw_frame":"{\"market\":\"0x717c0e8ccd4d5c7040185188fbae28be901ca589a11a94b1b38ca36a79eccfeb\", \"price_changes\":[{\"asset_id\":\"24254094493625419915756280046002869097156693848522361803041977572204227262166\", \"price\":\"0.59\", \"size\":\"21.9\", \"side\":\"BUY\", \"hash\":\"90c99425100dc39336d768d9990e3efc23b5d4e5\", \"best_bid\":\"0.64\", \"best_ask\":\"0.65\"}, {\"asset_id\":\"41448400836309843603620980831210604935021861034693225347475867885462478926555\", \"price\":\"0.41\", \"size\":\"21.9\", \"side\":\"SELL\", \"hash\":\"25af5a09db228bf336c3742d59fa1cf58949cde2\", \"best_bid\":\"0.35\", \"best_ask\":\"0.36\"}], \"timestamp\":\"1785122715665\", \"event_type\":\"price_change\"}","received_at":"2026-07-27T03:25:17.175565Z","schema_version":"clob-market-ws.price_change.v1","sequence":null,"server_hash":null,"server_timestamp":"1785122715665","session_id":"dd162b8dca5f43ff811d304e69a06123","source":"clob_market_ws"},"received_at":"2026-07-27T03:25:17.175565Z","record_id":"ed10c046229a699ef180b8d63227df276f3375454e70b6f9bb1b1f81d6b34393","schema_fingerprint":"4aa3821a28b0b7c2400bc59aba4bcc0a76e971dadd19610d3ad38c768e124dc7","schema_version":"edge-lab-recorder.raw.v1","sequence":null,"source":"clob_market_ws"}
{"event_at":"2026-07-27T03:25:15.670000Z","event_fingerprint":"1fb1920c39d348d70b1711a4a683f777de7d38b12b23bd3314e2777f6cf6f6df","payload":{"connection_id":"c7dc2e4762f849c6b6f9306b6518dcab","event_at":"2026-07-27T03:25:15.670000Z","event_type":"price_change","frame_hash":"04bacd0d43d987433222f58e9d3e71961ad55d9a6226d21661c9717d7cc18151","frame_index":0,"kind":"data","monotonic_ns":224700541680125,"payload":{"event_type":"price_change","market":"0x717c0e8ccd4d5c7040185188fbae28be901ca589a11a94b1b38ca36a79eccfeb","price_changes":[{"asset_id":"24254094493625419915756280046002869097156693848522361803041977572204227262166","best_ask":"0.65","best_bid":"0.64","hash":"8f596891c641341e33ff586f6b3d69aa16c1e8b3","price":"0.6","side":"BUY","size":"31.96"},{"asset_id":"41448400836309843603620980831210604935021861034693225347475867885462478926555","best_ask":"0.36","best_bid":"0.35","hash":"d6450cfcc530cc28c21617213f36368b86981f01","price":"0.4","side":"SELL","size":"31.96"}],"timestamp":"1785122715670"},"payload_hash":"9b392378786dd062d5e4a402edd3d551013013a36d9dcee68001ea281d0f66c7","raw_frame":"{\"market\":\"0x717c0e8ccd4d5c7040185188fbae28be901ca589a11a94b1b38ca36a79eccfeb\", \"price_changes\":[{\"asset_id\":\"24254094493625419915756280046002869097156693848522361803041977572204227262166\", \"price\":\"0.6\", \"size\":\"31.96\", \"side\":\"BUY\", \"hash\":\"8f596891c641341e33ff586f6b3d69aa16c1e8b3\", \"best_bid\":\"0.64\", \"best_ask\":\"0.65\"}, {\"asset_id\":\"41448400836309843603620980831210604935021861034693225347475867885462478926555\", \"price\":\"0.4\", \"size\":\"31.96\", \"side\":\"SELL\", \"hash\":\"d6450cfcc530cc28c21617213f36368b86981f01\", \"best_bid\":\"0.35\", \"best_ask\":\"0.36\"}], \"timestamp\":\"1785122715670\", \"event_type\":\"price_change\"}","received_at":"2026-07-27T03:25:17.182642Z","schema_version":"clob-market-ws.price_change.v1","sequence":null,"server_hash":null,"server_timestamp":"1785122715670","session_id":"dd162b8dca5f43ff811d304e69a06123","source":"clob_market_ws"},"received_at":"2026-07-27T03:25:17.182642Z","record_id":"9abb41a97a63265010976ac319a1800ac050884efd5bb715b8f242d1d4eb3e6a","schema_fingerprint":"4aa3821a28b0b7c2400bc59aba4bcc0a76e971dadd19610d3ad38c768e124dc7","schema_version":"edge-lab-recorder.raw.v1","sequence":null,"source":"clob_market_ws"}
{"event_at":"2026-07-27T03:25:15.671000Z","event_fingerprint":"26f8dc0fea9737f209d1e341af33555448fb295ba50a909b7d26d92f9ca2422c","payload":{"connection_id":"c7dc2e4762f849c6b6f9306b6518dcab","event_at":"2026-07-27T03:25:15.671000Z","event_type":"price_change","frame_hash":"b9d38ec7c10ab6409514ed912286dedeeef1f2c3ee6f85397abbe4a4e6190ba3","frame_index":0,"kind":"data","monotonic_ns":224700551758916,"payload":{"event_type":"price_change","market":"0x717c0e8ccd4d5c7040185188fbae28be901ca589a11a94b1b38ca36a79eccfeb","price_changes":[{"asset_id":"24254094493625419915756280046002869097156693848522361803041977572204227262166","best_ask":"0.65","best_bid":"0.64","hash":"06648ed32f3f71fb6e37c70645d22ad4000e28dc","price":"0.02","side":"BUY","size":"683.1"},{"asset_id":"41448400836309843603620980831210604935021861034693225347475867885462478926555","best_ask":"0.36","best_bid":"0.35","hash":"5a9522f540a20a4068a846c2cbc1e500b88b807f","price":"0.98","side":"SELL","size":"683.1"}],"timestamp":"1785122715671"},"payload_hash":"340cf3befdbca7a14d8161dd09bd49af1e108e5bc3066129ebe9f219313c666a","raw_frame":"{\"market\":\"0x717c0e8ccd4d5c7040185188fbae28be901ca589a11a94b1b38ca36a79eccfeb\", \"price_changes\":[{\"asset_id\":\"24254094493625419915756280046002869097156693848522361803041977572204227262166\", \"price\":\"0.02\", \"size\":\"683.1\", \"side\":\"BUY\", \"hash\":\"06648ed32f3f71fb6e37c70645d22ad4000e28dc\", \"best_bid\":\"0.64\", \"best_ask\":\"0.65\"}, {\"asset_id\":\"41448400836309843603620980831210604935021861034693225347475867885462478926555\", \"price\":\"0.98\", \"size\":\"683.1\", \"side\":\"SELL\", \"hash\":\"5a9522f540a20a4068a846c2cbc1e500b88b807f\", \"best_bid\":\"0.35\", \"best_ask\":\"0.36\"}], \"timestamp\":\"1785122715671\", \"event_type\":\"price_change\"}","received_at":"2026-07-27T03:25:17.192725Z","schema_version":"clob-market-ws.price_change.v1","sequence":null,"server_hash":null,"server_timestamp":"1785122715671","session_id":"dd162b8dca5f43ff811d304e69a06123","source":"clob_market_ws"},"received_at":"2026-07-27T03:25:17.192725Z","record_id":"28b035282c1a94b25003c163adf32acf5b5349878c795b2d4682c217f3d35914","schema_fingerprint":"4aa3821a28b0b7c2400bc59aba4bcc0a76e971dadd19610d3ad38c768e124dc7","schema_version":"edge-lab-recorder.raw.v1","sequence":null,"source":"clob_market_ws"}
{"event_at":"2026-07-27T03:25:15.671000Z","event_fingerprint":"16a91a83600c056396bb813a821bacedd13d24238fd93d81c5bff907e61c1788","payload":{"connection_id":"c7dc2e4762f849c6b6f9306b6518dcab","event_at":"2026-07-27T03:25:15.671000Z","event_type":"price_change","frame_hash":"c2547d633ca0c2816551f4e699978a960311c21b71e1d46a4cbac909870c26df","frame_index":0,"kind":"data","monotonic_ns":224700555852791,"payload":{"event_type":"price_change","market":"0x717c0e8ccd4d5c7040185188fbae28be901ca589a11a94b1b38ca36a79eccfeb","price_changes":[{"asset_id":"41448400836309843603620980831210604935021861034693225347475867885462478926555","best_ask":"0.36","best_bid":"0.35","hash":"fd4072077a34a0a7a6455e5dab68e33e88f37513","price":"0.3","side":"BUY","size":"22"},{"asset_id":"24254094493625419915756280046002869097156693848522361803041977572204227262166","best_ask":"0.65","best_bid":"0.64","hash":"da13b7cef954eaa852f5da66bb52dca6f2ed4a84","price":"0.7","side":"SELL","size":"22"}],"timestamp":"1785122715671"},"payload_hash":"7bec66b1b1dc675b0019a1ad1831b3176bacafc33e85b9981f0cf8a880f9091b","raw_frame":"{\"market\":\"0x717c0e8ccd4d5c7040185188fbae28be901ca589a11a94b1b38ca36a79eccfeb\", \"price_changes\":[{\"asset_id\":\"41448400836309843603620980831210604935021861034693225347475867885462478926555\", \"price\":\"0.3\", \"size\":\"22\", \"side\":\"BUY\", \"hash\":\"fd4072077a34a0a7a6455e5dab68e33e88f37513\", \"best_bid\":\"0.35\", \"best_ask\":\"0.36\"}, {\"asset_id\":\"24254094493625419915756280046002869097156693848522361803041977572204227262166\", \"price\":\"0.7\", \"size\":\"22\", \"side\":\"SELL\", \"hash\":\"da13b7cef954eaa852f5da66bb52dca6f2ed4a84\", \"best_bid\":\"0.64\", \"best_ask\":\"0.65\"}], \"timestamp\":\"1785122715671\", \"event_type\":\"price_change\"}","received_at":"2026-07-27T03:25:17.196819Z","schema_version":"clob-market-ws.price_change.v1","sequence":null,"server_hash":null,"server_timestamp":"1785122715671","session_id":"dd162b8dca5f43ff811d304e69a06123","source":"clob_market_ws"},"received_at":"2026-07-27T03:25:17.196819Z","record_id":"4024949aaaee390c7c11ee844aa9cb2d056a9e0ec6d6ed00a0642365918c7cf4","schema_fingerprint":"4aa3821a28b0b7c2400bc59aba4bcc0a76e971dadd19610d3ad38c768e124dc7","schema_version":"edge-lab-recorder.raw.v1","sequence":null,"source":"clob_market_ws"}
{"event_at":"2026-07-27T03:25:15.673000Z","event_fingerprint":"b89d9fd429e5184d3a5f97dfd18047878f98c3d2b5324dbe9947c55a1ae47291","payload":{"connection_id":"c7dc2e4762f849c6b6f9306b6518dcab","event_at":"2026-07-27T03:25:15.673000Z","event_type":"price_change","frame_hash":"9b6ebd0fad4737ebb86c7a42f2dd6895af911e62b52044060be91b41de47d3ef","frame_index":0,"kind":"data","monotonic_ns":224700560892958,"payload":{"event_type":"price_change","market":"0x717c0e8ccd4d5c7040185188fbae28be901ca589a11a94b1b38ca36a79eccfeb","price_changes":[{"asset_id":"24254094493625419915756280046002869097156693848522361803041977572204227262166","best_ask":"0.65","best_bid":"0.64","hash":"93894cf1e6d2d0a851e1e969d579b2a8842d1f73","price":"0.57","side":"BUY","size":"5"},{"asset_id":"41448400836309843603620980831210604935021861034693225347475867885462478926555","best_ask":"0.36","best_bid":"0.35","hash":"e91a612f5fd52a2f79091a1857b30fd7f6a9d8bb","price":"0.43","side":"SELL","size":"5"}],"timestamp":"1785122715673"},"payload_hash":"15bee4368cc89ff9bc6c5bc3bd3d7ca9d643337677560f71b6cfc1a7fb57acb4","raw_frame":"{\"market\":\"0x717c0e8ccd4d5c7040185188fbae28be901ca589a11a94b1b38ca36a79eccfeb\", \"price_changes\":[{\"asset_id\":\"24254094493625419915756280046002869097156693848522361803041977572204227262166\", \"price\":\"0.57\", \"size\":\"5\", \"side\":\"BUY\", \"hash\":\"93894cf1e6d2d0a851e1e969d579b2a8842d1f73\", \"best_bid\":\"0.64\", \"best_ask\":\"0.65\"}, {\"asset_id\":\"41448400836309843603620980831210604935021861034693225347475867885462478926555\", \"price\":\"0.43\", \"size\":\"5\", \"side\":\"SELL\", \"hash\":\"e91a612f5fd52a2f79091a1857b30fd7f6a9d8bb\", \"best_bid\":\"0.35\", \"best_ask\":\"0.36\"}], \"timestamp\":\"1785122715673\", \"event_type\":\"price_change\"}","received_at":"2026-07-27T03:25:17.201859Z","schema_version":"clob-market-ws.price_change.v1","sequence":null,"server_hash":null,"server_timestamp":"1785122715673","session_id":"dd162b8dca5f43ff811d304e69a06123","source":"clob_market_ws"},"received_at":"2026-07-27T03:25:17.201859Z","record_id":"c6313e748b66cb4a0a9b37463787c84899a01ea0cac49b6e08596fb99eace465","schema_fingerprint":"4aa3821a28b0b7c2400bc59aba4bcc0a76e971dadd19610d3ad38c768e124dc7","schema_version":"edge-lab-recorder.raw.v1","sequence":null,"source":"clob_market_ws"}
{"event_at":"2026-07-27T03:25:15.675000Z","event_fingerprint":"2580f263e40364777e37aaff67cc642eb2ad7bfed8a5abb2453062317b6317e8","payload":{"connection_id":"c7dc2e4762f849c6b6f9306b6518dcab","event_at":"2026-07-27T03:25:15.675000Z","event_type":"price_change","frame_hash":"53465781a7acd883c635632411bf2d543d9751880b6c730906a9d0f529a3e003","frame_index":0,"kind":"data","monotonic_ns":224700562847000,"payload":{"event_type":"price_change","market":"0x717c0e8ccd4d5c7040185188fbae28be901ca589a11a94b1b38ca36a79eccfeb","price_changes":[{"asset_id":"41448400836309843603620980831210604935021861034693225347475867885462478926555","best_ask":"0.36","best_bid":"0.35","hash":"8a7ae6fd513f607a84a1f3c31f743b56ad16e7ba","price":"0.41","side":"SELL","size":"26.9"},{"asset_id":"24254094493625419915756280046002869097156693848522361803041977572204227262166","best_ask":"0.65","best_bid":"0.64","hash":"26afe826653a9a54e1e8b3a673a97737fb781652","price":"0.59","side":"BUY","size":"26.9"}],"timestamp":"1785122715675"},"payload_hash":"3f9d620997f960f6db20a563e6e4639ccdc3b41c86b2436fe5838fc20dd92045","raw_frame":"{\"market\":\"0x717c0e8ccd4d5c7040185188fbae28be901ca589a11a94b1b38ca36a79eccfeb\", \"price_changes\":[{\"asset_id\":\"41448400836309843603620980831210604935021861034693225347475867885462478926555\", \"price\":\"0.41\", \"size\":\"26.9\", \"side\":\"SELL\", \"hash\":\"8a7ae6fd513f607a84a1f3c31f743b56ad16e7ba\", \"best_bid\":\"0.35\", \"best_ask\":\"0.36\"}, {\"asset_id\":\"24254094493625419915756280046002869097156693848522361803041977572204227262166\", \"price\":\"0.59\", \"size\":\"26.9\", \"side\":\"BUY\", \"hash\":\"26afe826653a9a54e1e8b3a673a97737fb781652\", \"best_bid\":\"0.64\", \"best_ask\":\"0.65\"}], \"timestamp\":\"1785122715675\", \"event_type\":\"price_change\"}","received_at":"2026-07-27T03:25:17.203811Z","schema_version":"clob-market-ws.price_change.v1","sequence":null,"server_hash":null,"server_timestamp":"1785122715675","session_id":"dd162b8dca5f43ff811d304e69a06123","source":"clob_market_ws"},"received_at":"2026-07-27T03:25:17.203811Z","record_id":"a7fa408fa65fda3d895b6ec062c0a823efff6fb80c72391ebc842f4fc86f9176","schema_fingerprint":"4aa3821a28b0b7c2400bc59aba4bcc0a76e971dadd19610d3ad38c768e124dc7","schema_version":"edge-lab-recorder.raw.v1","sequence":null,"source":"clob_market_ws"}
{"event_at":"2026-07-27T03:25:15.680000Z","event_fingerprint":"f20e9ffa24bfea236997e72951efeb2c6b44553457c6f3aab208cd11705174b3","payload":{"connection_id":"c7dc2e4762f849c6b6f9306b6518dcab","event_at":"2026-07-27T03:25:15.680000Z","event_type":"price_change","frame_hash":"92fd4a534a3f692e31202df477f9ef4e7a808470e9b33db078b6ee804f617680","frame_index":0,"kind":"data","monotonic_ns":224700565487625,"payload":{"event_type":"price_change","market":"0x717c0e8ccd4d5c7040185188fbae28be901ca589a11a94b1b38ca36a79eccfeb","price_changes":[{"asset_id":"24254094493625419915756280046002869097156693848522361803041977572204227262166","best_ask":"0.65","best_bid":"0.64","hash":"29bc0f4c62d931dc88128014b6f4924fc8eaa2ac","price":"0.01","side":"BUY","size":"5453.02"},{"asset_id":"41448400836309843603620980831210604935021861034693225347475867885462478926555","best_ask":"0.36","best_bid":"0.35","hash":"3c26fe136411d15697548faa849d17aa548b9f29","price":"0.99","side":"SELL","size":"5453.02"}],"timestamp":"1785122715680"},"payload_hash":"475d2697ef65e1df264bc47d3af0343967dfd9cf5edaa941b075af4c1c0000c1","raw_frame":"{\"market\":\"0x717c0e8ccd4d5c7040185188fbae28be901ca589a11a94b1b38ca36a79eccfeb\", \"price_changes\":[{\"asset_id\":\"24254094493625419915756280046002869097156693848522361803041977572204227262166\", \"price\":\"0.01\", \"size\":\"5453.02\", \"side\":\"BUY\", \"hash\":\"29bc0f4c62d931dc88128014b6f4924fc8eaa2ac\", \"best_bid\":\"0.64\", \"best_ask\":\"0.65\"}, {\"asset_id\":\"41448400836309843603620980831210604935021861034693225347475867885462478926555\", \"price\":\"0.99\", \"size\":\"5453.02\", \"side\":\"SELL\", \"hash\":\"3c26fe136411d15697548faa849d17aa548b9f29\", \"best_bid\":\"0.35\", \"best_ask\":\"0.36\"}], \"timestamp\":\"1785122715680\", \"event_type\":\"price_change\"}","received_at":"2026-07-27T03:25:17.206453Z","schema_version":"clob-market-ws.price_change.v1","sequence":null,"server_hash":null,"server_timestamp":"1785122715680","session_id":"dd162b8dca5f43ff811d304e69a06123","source":"clob_market_ws"},"received_at":"2026-07-27T03:25:17.206453Z","record_id":"0c91027c30a85e9e85582c0a479cef86ea5abd28d32a4d737437cb3d521074f8","schema_fingerprint":"4aa3821a28b0b7c2400bc59aba4bcc0a76e971dadd19610d3ad38c768e124dc7","schema_version":"edge-lab-recorder.raw.v1","sequence":null,"source":"clob_market_ws"}
{"event_at":"2026-07-27T03:25:15.817000Z","event_fingerprint":"71cd78fc12b3a94422772ea0e943bc90687cc2a00e55df63c5e005dd8f87278d","payload":{"connection_id":"c7dc2e4762f849c6b6f9306b6518dcab","event_at":"2026-07-27T03:25:15.817000Z","event_type":"price_change","frame_hash":"2e02522cb863c08702fd5ce2b3a3aace5acfb9b4a3d01c8808a610d411363e67","frame_index":0,"kind":"data","monotonic_ns":224700568641125,"payload":{"event_type":"price_change","market":"0x717c0e8ccd4d5c7040185188fbae28be901ca589a11a94b1b38ca36a79eccfeb","price_changes":[{"asset_id":"24254094493625419915756280046002869097156693848522361803041977572204227262166","best_ask":"0.65","best_bid":"0.64","hash":"cdadfa6b398072693f3d19d80136b2668b5c1451","price":"0.03","side":"BUY","size":"618.1"},{"asset_id":"41448400836309843603620980831210604935021861034693225347475867885462478926555","best_ask":"0.36","best_bid":"0.35","hash":"937be263bd4a69d969d0ef0fd525f870d7a6f1e2","price":"0.97","side":"SELL","size":"618.1"}],"timestamp":"1785122715817"},"payload_hash":"df014246226b73b2a022fd718663ea3bcacc8f5fe68f0b29df33f903408d3026","raw_frame":"{\"market\":\"0x717c0e8ccd4d5c7040185188fbae28be901ca589a11a94b1b38ca36a79eccfeb\", \"price_changes\":[{\"asset_id\":\"24254094493625419915756280046002869097156693848522361803041977572204227262166\", \"price\":\"0.03\", \"size\":\"618.1\", \"side\":\"BUY\", \"hash\":\"cdadfa6b398072693f3d19d80136b2668b5c1451\", \"best_bid\":\"0.64\", \"best_ask\":\"0.65\"}, {\"asset_id\":\"41448400836309843603620980831210604935021861034693225347475867885462478926555\", \"price\":\"0.97\", \"size\":\"618.1\", \"side\":\"SELL\", \"hash\":\"937be263bd4a69d969d0ef0fd525f870d7a6f1e2\", \"best_bid\":\"0.35\", \"best_ask\":\"0.36\"}], \"timestamp\":\"1785122715817\", \"event_type\":\"price_change\"}","received_at":"2026-07-27T03:25:17.209604Z","schema_version":"clob-market-ws.price_change.v1","sequence":null,"server_hash":null,"server_timestamp":"1785122715817","session_id":"dd162b8dca5f43ff811d304e69a06123","source":"clob_market_ws"},"received_at":"2026-07-27T03:25:17.209604Z","record_id":"5f03f7ce50d0448640f2b1afac80c7cc05971f224f928dd7d8c9ff1a39392a8d","schema_fingerprint":"4aa3821a28b0b7c2400bc59aba4bcc0a76e971dadd19610d3ad38c768e124dc7","schema_version":"edge-lab-recorder.raw.v1","sequence":null,"source":"clob_market_ws"}
{"event_at":"2026-07-27T03:25:15.919000Z","event_fingerprint":"530bea0f5884f15c60e50f6692582fecb508ba9ef15e58adb8ca2939c3c5ab88","payload":{"connection_id":"c7dc2e4762f849c6b6f9306b6518dcab","event_at":"2026-07-27T03:25:15.919000Z","event_type":"price_change","frame_hash":"706fb57bfc1f04dd6728ad810e3f352cb5fd868417fb51781e26c4f3fa9fd6d2","frame_index":0,"kind":"data","monotonic_ns":224700573724125,"payload":{"event_type":"price_change","market":"0x717c0e8ccd4d5c7040185188fbae28be901ca589a11a94b1b38ca36a79eccfeb","price_changes":[{"asset_id":"24254094493625419915756280046002869097156693848522361803041977572204227262166","best_ask":"0.65","best_bid":"0.64","hash":"5d8bc1c2b3b6f0c5df0b8f5384e8eef835b75d3c","price":"0.03","side":"BUY","size":"613.1"},{"asset_id":"41448400836309843603620980831210604935021861034693225347475867885462478926555","best_ask":"0.36","best_bid":"0.35","hash":"0d2d40473a8a0b91af85bb4772157c3a7ca879f5","price":"0.97","side":"SELL","size":"613.1"}],"timestamp":"1785122715919"},"payload_hash":"a1b8d45464675502435a3f96c47a6e0c6b16f003882c381825cb386ebe328a9b","raw_frame":"{\"market\":\"0x717c0e8ccd4d5c7040185188fbae28be901ca589a11a94b1b38ca36a79eccfeb\", \"price_changes\":[{\"asset_id\":\"24254094493625419915756280046002869097156693848522361803041977572204227262166\", \"price\":\"0.03\", \"size\":\"613.1\", \"side\":\"BUY\", \"hash\":\"5d8bc1c2b3b6f0c5df0b8f5384e8eef835b75d3c\", \"best_bid\":\"0.64\", \"best_ask\":\"0.65\"}, {\"asset_id\":\"41448400836309843603620980831210604935021861034693225347475867885462478926555\", \"price\":\"0.97\", \"size\":\"613.1\", \"side\":\"SELL\", \"hash\":\"0d2d40473a8a0b91af85bb4772157c3a7ca879f5\", \"best_bid\":\"0.35\", \"best_ask\":\"0.36\"}], \"timestamp\":\"1785122715919\", \"event_type\":\"price_change\"}","received_at":"2026-07-27T03:25:17.214686Z","schema_version":"clob-market-ws.price_change.v1","sequence":null,"server_hash":null,"server_timestamp":"1785122715919","session_id":"dd162b8dca5f43ff811d304e69a06123","source":"clob_market_ws"},"received_at":"2026-07-27T03:25:17.214686Z","record_id":"6480dabea10f42584802978a1db620248517a66bf4ec89fc6cab48b0fa12c3ea","schema_fingerprint":"4aa3821a28b0b7c2400bc59aba4bcc0a76e971dadd19610d3ad38c768e124dc7","schema_version":"edge-lab-recorder.raw.v1","sequence":null,"source":"clob_market_ws"}
{"event_at":"2026-07-27T03:25:15.928000Z","event_fingerprint":"92703852cc196564a9fabec76ad6e31a1684cfc28cc531b8ffbec79af0ed3de1","payload":{"connection_id":"c7dc2e4762f849c6b6f9306b6518dcab","event_at":"2026-07-27T03:25:15.928000Z","event_type":"best_bid_ask","frame_hash":"88eceec65ebdbb774f0168ec22702c6c62f68b2399a88d8663df9720ee73aadd","frame_index":0,"kind":"data","monotonic_ns":224700580711791,"payload":{"asset_id":"24254094493625419915756280046002869097156693848522361803041977572204227262166","best_ask":"0.65","best_bid":"0.64","event_type":"best_bid_ask","market":"0x717c0e8ccd4d5c7040185188fbae28be901ca589a11a94b1b38ca36a79eccfeb","spread":"0.01","timestamp":"1785122715928"},"payload_hash":"28aa88a3553111d43924582a8764aea2abeda01f2758d0f7a741c009688bb383","raw_frame":"{\"market\":\"0x717c0e8ccd4d5c7040185188fbae28be901ca589a11a94b1b38ca36a79eccfeb\", \"asset_id\":\"24254094493625419915756280046002869097156693848522361803041977572204227262166\", \"best_bid\":\"0.64\", \"best_ask\":\"0.65\", \"spread\":\"0.01\", \"timestamp\":\"1785122715928\", \"event_type\":\"best_bid_ask\"}","received_at":"2026-07-27T03:25:17.221671Z","schema_version":"clob-market-ws.best_bid_ask.v1","sequence":null,"server_hash":null,"server_timestamp":"1785122715928","session_id":"dd162b8dca5f43ff811d304e69a06123","source":"clob_market_ws"},"received_at":"2026-07-27T03:25:17.221671Z","record_id":"5af8d3c3446ee94d0468f08ba8b9f7f24d4644f9a428ff632bc6d9e6d424f07c","schema_fingerprint":"8488399f31b0337811b13b266be932db7062827c2470b78bd8e9e99bab51d17d","schema_version":"edge-lab-recorder.raw.v1","sequence":null,"source":"clob_market_ws"}
{"event_at":"2026-07-27T03:25:15.928000Z","event_fingerprint":"c9775f264af020627f26bc89c95da65f8fc75546cddefbc120fe337d26791f2e","payload":{"connection_id":"c7dc2e4762f849c6b6f9306b6518dcab","event_at":"2026-07-27T03:25:15.928000Z","event_type":"best_bid_ask","frame_hash":"c367443ab8c9cb48ee0728279c4ade88ccc99a23041aa17b1f98889a685e0d44","frame_index":0,"kind":"data","monotonic_ns":224700590263333,"payload":{"asset_id":"41448400836309843603620980831210604935021861034693225347475867885462478926555","best_ask":"0.36","best_bid":"0.35","event_type":"best_bid_ask","market":"0x717c0e8ccd4d5c7040185188fbae28be901ca589a11a94b1b38ca36a79eccfeb","spread":"0.01","timestamp":"1785122715928"},"payload_hash":"e56f3a91f730c4302804d0595bd1ad116fee839a16a38e129cecbcb6d6305e74","raw_frame":"{\"market\":\"0x717c0e8ccd4d5c7040185188fbae28be901ca589a11a94b1b38ca36a79eccfeb\", \"asset_id\":\"41448400836309843603620980831210604935021861034693225347475867885462478926555\", \"best_bid\":\"0.35\", \"best_ask\":\"0.36\", \"spread\":\"0.01\", \"timestamp\":\"1785122715928\", \"event_type\":\"best_bid_ask\"}","received_at":"2026-07-27T03:25:17.231226Z","schema_version":"clob-market-ws.best_bid_ask.v1","sequence":null,"server_hash":null,"server_timestamp":"1785122715928","session_id":"dd162b8dca5f43ff811d304e69a06123","source":"clob_market_ws"},"received_at":"2026-07-27T03:25:17.231226Z","record_id":"69051d398751253233479f32f11f0853ce46a10889d15557725b34724b1a1e1c","schema_fingerprint":"8488399f31b0337811b13b266be932db7062827c2470b78bd8e9e99bab51d17d","schema_version":"edge-lab-recorder.raw.v1","sequence":null,"source":"clob_market_ws"}
{"event_at":"2026-07-27T03:25:15.928000Z","event_fingerprint":"1926d6303955fbe8ff5d1661d9e57265413d054267b1efe3970e94333b5ac01d","payload":{"connection_id":"c7dc2e4762f849c6b6f9306b6518dcab","event_at":"2026-07-27T03:25:15.928000Z","event_type":"price_change","frame_hash":"7220f1de5477cfc99ca3ef51b453ecf48f489caa8cb9b70cbc5270e53c4e5c60","frame_index":0,"kind":"data","monotonic_ns":224700601824958,"payload":{"event_type":"price_change","market":"0x717c0e8ccd4d5c7040185188fbae28be901ca589a11a94b1b38ca36a79eccfeb","price_changes":[{"asset_id":"41448400836309843603620980831210604935021861034693225347475867885462478926555","best_ask":"0.36","best_bid":"0.35","hash":"73967519ec0ed511d7de85aec12b4f7b6e637664","price":"0.35","side":"BUY","size":"21.09"},{"asset_id":"24254094493625419915756280046002869097156693848522361803041977572204227262166","best_ask":"0.65","best_bid":"0.64","hash":"022ba31ba7b33d25a3213587cceab7aaaf9f0ec1","price":"0.65","side":"SELL","size":"21.09"}],"timestamp":"1785122715928"},"payload_hash":"329c330a6da7fb1e8e08f8afa3c6d7c20aceeb4f44d92bc964b4c506757be0e7","raw_frame":"{\"market\":\"0x717c0e8ccd4d5c7040185188fbae28be901ca589a11a94b1b38ca36a79eccfeb\", \"price_changes\":[{\"asset_id\":\"41448400836309843603620980831210604935021861034693225347475867885462478926555\", \"price\":\"0.35\", \"size\":\"21.09\", \"side\":\"BUY\", \"hash\":\"73967519ec0ed511d7de85aec12b4f7b6e637664\", \"best_bid\":\"0.35\", \"best_ask\":\"0.36\"}, {\"asset_id\":\"24254094493625419915756280046002869097156693848522361803041977572204227262166\", \"price\":\"0.65\", \"size\":\"21.09\", \"side\":\"SELL\", \"hash\":\"022ba31ba7b33d25a3213587cceab7aaaf9f0ec1\", \"best_bid\":\"0.64\", \"best_ask\":\"0.65\"}], \"timestamp\":\"1785122715928\", \"event_type\":\"price_change\"}","received_at":"2026-07-27T03:25:17.242784Z","schema_version":"clob-market-ws.price_change.v1","sequence":null,"server_hash":null,"server_timestamp":"1785122715928","session_id":"dd162b8dca5f43ff811d304e69a06123","source":"clob_market_ws"},"received_at":"2026-07-27T03:25:17.242784Z","record_id":"75c563cd3f56ec5bdad5204aab8841b337bf96e7d1739594f3b679528f35c988","schema_fingerprint":"4aa3821a28b0b7c2400bc59aba4bcc0a76e971dadd19610d3ad38c768e124dc7","schema_version":"edge-lab-recorder.raw.v1","sequence":null,"source":"clob_market_ws"}
{"event_at":"2026-07-27T03:25:15.928000Z","event_fingerprint":"21127f1fe5bb96fcd23732c179e511b9dc9755d1ee1ee24be367f792148163c3","payload":{"connection_id":"c7dc2e4762f849c6b6f9306b6518dcab","event_at":"2026-07-27T03:25:15.928000Z","event_type":"book","frame_hash":"67f30c110414c960743e99396c706ac380ac11e4b24a275cc16c479cf77b17d7","frame_index":0,"kind":"data","monotonic_ns":224700609309125,"payload":{"asks":[{"price":"0.99","size":"5453.02"},{"price":"0.98","size":"673.1"},{"price":"0.97","size":"746.43"},{"price":"0.96","size":"578.09"},{"price":"0.95","size":"594.2"},{"price":"0.94","size":"575.2"},{"price":"0.93","size":"565.1"},{"price":"0.92","size":"557.79"},{"price":"0.91","size":"51.6"},{"price":"0.9","size":"47.29"},{"price":"0.89","size":"43.6"},{"price":"0.88","size":"40.4"},{"price":"0.87","size":"37.5"},{"price":"0.86","size":"34.9"},{"price":"0.85","size":"33.5"},{"price":"0.84","size":"31.3"},{"price":"0.83","size":"30.3"},{"price":"0.82","size":"56.3"},{"price":"0.81","size":"584.79"},{"price":"0.8","size":"251.8"},{"price":"0.79","size":"150.1"},{"price":"0.78","size":"155.07"},{"price":"0.77","size":"162"},{"price":"0.76","size":"166.46"},{"price":"0.75","size":"158.46"},{"price":"0.74","size":"230.16"},{"price":"0.73","size":"125"},{"price":"0.72","size":"124"},{"price":"0.71","size":"22"},{"price":"0.7","size":"22"},{"price":"0.69","size":"283.21"},{"price":"0.68","size":"68.21"},{"price":"0.67","size":"128.21"},{"price":"0.66","size":"5.21"},{"price":"0.65","size":"21.09"}],"asset_id":"24254094493625419915756280046002869097156693848522361803041977572204227262166","bids":[{"price":"0.01","size":"5453.02"},{"price":"0.02","size":"683.1"},{"price":"0.03","size":"613.1"},{"price":"0.04","size":"578.09"},{"price":"0.05","size":"668.2"},{"price":"0.06","size":"553.2"},{"price":"0.07","size":"546.1"},{"price":"0.08","size":"540.79"},{"price":"0.09","size":"536.6"},{"price":"0.1","size":"33.29"},{"price":"0.11","size":"30.6"},{"price":"0.12","size":"28.4"},{"price":"0.13","size":"26.5"},{"price":"0.14","size":"32.04"},{"price":"0.15","size":"23.5"},{"price":"0.16","size":"22.3"},{"price":"0.17","size":"21.3"},{"price":"0.18","size":"20.3"},{"price":"0.19","size":"19.5"},{"price":"0.2","size":"26.8"},{"price":"0.21","size":"26.1"},{"price":"0.22","size":"24.5"},{"price":"0.23","size":"23.89"},{"price":"0.24","size":"23.39"},{"price":"0.25","size":"23"},{"price":"0.26","size":"21.6"},{"price":"0.27","size":"21.2"},{"price":"0.28","size":"20.9"},{"price":"0.29","size":"20.6"},{"price":"0.3","size":"20.3"},{"price":"0.31","size":"36.07"},{"price":"0.32","size":"19.8"},{"price":"0.33","size":"31.6"},{"price":"0.34","size":"19.4"},{"price":"0.35","size":"18.2"},{"price":"0.36","size":"18"},{"price":"0.37","size":"17.9"},{"price":"0.38","size":"320.83"},{"price":"0.39","size":"17.6"},{"price":"0.4","size":"17.5"},{"price":"0.41","size":"17.4"},{"price":"0.42","size":"25.3"},{"price":"0.43","size":"24.14"},{"price":"0.44","size":"122.2"},{"price":"0.45","size":"122.1"},{"price":"0.46","size":"122.1"},{"price":"0.47","size":"127"},{"price":"0.48","size":"122"},{"price":"0.49","size":"212"},{"price":"0.5","size":"117"},{"price":"0.51","size":"122"},{"price":"0.52","size":"5"},{"price":"0.53","size":"115"},{"price":"0.54","size":"111"},{"price":"0.55","size":"245"},{"price":"0.56","size":"13"},{"price":"0.57","size":"5"},{"price":"0.58","size":"5"},{"price":"0.59","size":"26.9"},{"price":"0.6","size":"31.96"},{"price":"0.61","size":"32.08"},{"price":"0.62","size":"62.51"},{"price":"0.63","size":"10"},{"price":"0.64","size":"334"}],"event_type":"book","hash":"022ba31ba7b33d25a3213587cceab7aaaf9f0ec1","market":"0x717c0e8ccd4d5c7040185188fbae28be901ca589a11a94b1b38ca36a79eccfeb","timestamp":"1785122715928"},"payload_hash":"0fd81378e0d2c60164dd8524ecc3dbbc66e50b3303737fb6974234f9f63e327b","raw_frame":"{\"market\":\"0x717c0e8ccd4d5c7040185188fbae28be901ca589a11a94b1b38ca36a79eccfeb\", \"asset_id\":\"24254094493625419915756280046002869097156693848522361803041977572204227262166\", \"bids\":[{\"price\":\"0.01\", \"size\":\"5453.02\"}, {\"price\":\"0.02\", \"size\":\"683.1\"}, {\"price\":\"0.03\", \"size\":\"613.1\"}, {\"price\":\"0.04\", \"size\":\"578.09\"}, {\"price\":\"0.05\", \"size\":\"668.2\"}, {\"price\":\"0.06\", \"size\":\"553.2\"}, {\"price\":\"0.07\", \"size\":\"546.1\"}, {\"price\":\"0.08\", \"size\":\"540.79\"}, {\"price\":\"0.09\", \"size\":\"536.6\"}, {\"price\":\"0.1\", \"size\":\"33.29\"}, {\"price\":\"0.11\", \"size\":\"30.6\"}, {\"price\":\"0.12\", \"size\":\"28.4\"}, {\"price\":\"0.13\", \"size\":\"26.5\"}, {\"price\":\"0.14\", \"size\":\"32.04\"}, {\"price\":\"0.15\", \"size\":\"23.5\"}, {\"price\":\"0.16\", \"size\":\"22.3\"}, {\"price\":\"0.17\", \"size\":\"21.3\"}, {\"price\":\"0.18\", \"size\":\"20.3\"}, {\"price\":\"0.19\", \"size\":\"19.5\"}, {\"price\":\"0.2\", \"size\":\"26.8\"}, {\"price\":\"0.21\", \"size\":\"26.1\"}, {\"price\":\"0.22\", \"size\":\"24.5\"}, {\"price\":\"0.23\", \"size\":\"23.89\"}, {\"price\":\"0.24\", \"size\":\"23.39\"}, {\"price\":\"0.25\", \"size\":\"23\"}, {\"price\":\"0.26\", \"size\":\"21.6\"}, {\"price\":\"0.27\", \"size\":\"21.2\"}, {\"price\":\"0.28\", \"size\":\"20.9\"}, {\"price\":\"0.29\", \"size\":\"20.6\"}, {\"price\":\"0.3\", \"size\":\"20.3\"}, {\"price\":\"0.31\", \"size\":\"36.07\"}, {\"price\":\"0.32\", \"size\":\"19.8\"}, {\"price\":\"0.33\", \"size\":\"31.6\"}, {\"price\":\"0.34\", \"size\":\"19.4\"}, {\"price\":\"0.35\", \"size\":\"18.2\"}, {\"price\":\"0.36\", \"size\":\"18\"}, {\"price\":\"0.37\", \"size\":\"17.9\"}, {\"price\":\"0.38\", \"size\":\"320.83\"}, {\"price\":\"0.39\", \"size\":\"17.6\"}, {\"price\":\"0.4\", \"size\":\"17.5\"}, {\"price\":\"0.41\", \"size\":\"17.4\"}, {\"price\":\"0.42\", \"size\":\"25.3\"}, {\"price\":\"0.43\", \"size\":\"24.14\"}, {\"price\":\"0.44\", \"size\":\"122.2\"}, {\"price\":\"0.45\", \"size\":\"122.1\"}, {\"price\":\"0.46\", \"size\":\"122.1\"}, {\"price\":\"0.47\", \"size\":\"127\"}, {\"price\":\"0.48\", \"size\":\"122\"}, {\"price\":\"0.49\", \"size\":\"212\"}, {\"price\":\"0.5\", \"size\":\"117\"}, {\"price\":\"0.51\", \"size\":\"122\"}, {\"price\":\"0.52\", \"size\":\"5\"}, {\"price\":\"0.53\", \"size\":\"115\"}, {\"price\":\"0.54\", \"size\":\"111\"}, {\"price\":\"0.55\", \"size\":\"245\"}, {\"price\":\"0.56\", \"size\":\"13\"}, {\"price\":\"0.57\", \"size\":\"5\"}, {\"price\":\"0.58\", \"size\":\"5\"}, {\"price\":\"0.59\", \"size\":\"26.9\"}, {\"price\":\"0.6\", \"size\":\"31.96\"}, {\"price\":\"0.61\", \"size\":\"32.08\"}, {\"price\":\"0.62\", \"size\":\"62.51\"}, {\"price\":\"0.63\", \"size\":\"10\"}, {\"price\":\"0.64\", \"size\":\"334\"}], \"asks\":[{\"price\":\"0.99\", \"size\":\"5453.02\"}, {\"price\":\"0.98\", \"size\":\"673.1\"}, {\"price\":\"0.97\", \"size\":\"746.43\"}, {\"price\":\"0.96\", \"size\":\"578.09\"}, {\"price\":\"0.95\", \"size\":\"594.2\"}, {\"price\":\"0.94\", \"size\":\"575.2\"}, {\"price\":\"0.93\", \"size\":\"565.1\"}, {\"price\":\"0.92\", \"size\":\"557.79\"}, {\"price\":\"0.91\", \"size\":\"51.6\"}, {\"price\":\"0.9\", \"size\":\"47.29\"}, {\"price\":\"0.89\", \"size\":\"43.6\"}, {\"price\":\"0.88\", \"size\":\"40.4\"}, {\"price\":\"0.87\", \"size\":\"37.5\"}, {\"price\":\"0.86\", \"size\":\"34.9\"}, {\"price\":\"0.85\", \"size\":\"33.5\"}, {\"price\":\"0.84\", \"size\":\"31.3\"}, {\"price\":\"0.83\", \"size\":\"30.3\"}, {\"price\":\"0.82\", \"size\":\"56.3\"}, {\"price\":\"0.81\", \"size\":\"584.79\"}, {\"price\":\"0.8\", \"size\":\"251.8\"}, {\"price\":\"0.79\", \"size\":\"150.1\"}, {\"price\":\"0.78\", \"size\":\"155.07\"}, {\"price\":\"0.77\", \"size\":\"162\"}, {\"price\":\"0.76\", \"size\":\"166.46\"}, {\"price\":\"0.75\", \"size\":\"158.46\"}, {\"price\":\"0.74\", \"size\":\"230.16\"}, {\"price\":\"0.73\", \"size\":\"125\"}, {\"price\":\"0.72\", \"size\":\"124\"}, {\"price\":\"0.71\", \"size\":\"22\"}, {\"price\":\"0.7\", \"size\":\"22\"}, {\"price\":\"0.69\", \"size\":\"283.21\"}, {\"price\":\"0.68\", \"size\":\"68.21\"}, {\"price\":\"0.67\", \"size\":\"128.21\"}, {\"price\":\"0.66\", \"size\":\"5.21\"}, {\"price\":\"0.65\", \"size\":\"21.09\"}], \"hash\":\"022ba31ba7b33d25a3213587cceab7aaaf9f0ec1\", \"timestamp\":\"1785122715928\", \"event_type\":\"book\"}","received_at":"2026-07-27T03:25:17.250270Z","schema_version":"clob-market-ws.book.v1","sequence":null,"server_hash":"022ba31ba7b33d25a3213587cceab7aaaf9f0ec1","server_timestamp":"1785122715928","session_id":"dd162b8dca5f43ff811d304e69a06123","source":"clob_market_ws"},"received_at":"2026-07-27T03:25:17.250270Z","record_id":"2f7f3625b818ce2c2ad69d7b81362bb5e3cbb5b09044a1c22a80b413ae9c40a7","schema_fingerprint":"dc2caa1c89c6a7426e2e07ff925910cd4d0a8a223a515d4092d91d6d127aacb6","schema_version":"edge-lab-recorder.raw.v1","sequence":null,"source":"clob_market_ws"}
{"event_at":"2026-07-27T03:25:15.928000Z","event_fingerprint":"3d249a05ddd049ddd0f8c58a270979dfc4af692036c94dc6eccfe26586dac398","payload":{"connection_id":"c7dc2e4762f849c6b6f9306b6518dcab","event_at":"2026-07-27T03:25:15.928000Z","event_type":"book","frame_hash":"cbd25b293ef086e78af4081cafa3e1ae3fc1b1bd0913bb9b7dd07cba6bc93425","frame_index":0,"kind":"data","monotonic_ns":224700626333291,"payload":{"asks":[{"price":"0.99","size":"5453.02"},{"price":"0.98","size":"683.1"},{"price":"0.97","size":"613.1"},{"price":"0.96","size":"578.09"},{"price":"0.95","size":"668.2"},{"price":"0.94","size":"553.2"},{"price":"0.93","size":"546.1"},{"price":"0.92","size":"540.79"},{"price":"0.91","size":"536.6"},{"price":"0.9","size":"33.29"},{"price":"0.89","size":"30.6"},{"price":"0.88","size":"28.4"},{"price":"0.87","size":"26.5"},{"price":"0.86","size":"32.04"},{"price":"0.85","size":"23.5"},{"price":"0.84","size":"22.3"},{"price":"0.83","size":"21.3"},{"price":"0.82","size":"20.3"},{"price":"0.81","size":"19.5"},{"price":"0.8","size":"26.8"},{"price":"0.79","size":"26.1"},{"price":"0.78","size":"24.5"},{"price":"0.77","size":"23.89"},{"price":"0.76","size":"23.39"},{"price":"0.75","size":"23"},{"price":"0.74","size":"21.6"},{"price":"0.73","size":"21.2"},{"price":"0.72","size":"20.9"},{"price":"0.71","size":"20.6"},{"price":"0.7","size":"20.3"},{"price":"0.69","size":"36.07"},{"price":"0.68","size":"19.8"},{"price":"0.67","size":"31.6"},{"price":"0.66","size":"19.4"},{"price":"0.65","size":"18.2"},{"price":"0.64","size":"18"},{"price":"0.63","size":"17.9"},{"price":"0.62","size":"320.83"},{"price":"0.61","size":"17.6"},{"price":"0.6","size":"17.5"},{"price":"0.59","size":"17.4"},{"price":"0.58","size":"25.3"},{"price":"0.57","size":"24.14"},{"price":"0.56","size":"122.2"},{"price":"0.55","size":"122.1"},{"price":"0.54","size":"122.1"},{"price":"0.53","size":"127"},{"price":"0.52","size":"122"},{"price":"0.51","size":"212"},{"price":"0.5","size":"117"},{"price":"0.49","size":"122"},{"price":"0.48","size":"5"},{"price":"0.47","size":"115"},{"price":"0.46","size":"111"},{"price":"0.45","size":"245"},{"price":"0.44","size":"13"},{"price":"0.43","size":"5"},{"price":"0.42","size":"5"},{"price":"0.41","size":"26.9"},{"price":"0.4","size":"31.96"},{"price":"0.39","size":"32.08"},{"price":"0.38","size":"62.51"},{"price":"0.37","size":"10"},{"price":"0.36","size":"334"}],"asset_id":"41448400836309843603620980831210604935021861034693225347475867885462478926555","bids":[{"price":"0.01","size":"5453.02"},{"price":"0.02","size":"673.1"},{"price":"0.03","size":"746.43"},{"price":"0.04","size":"578.09"},{"price":"0.05","size":"594.2"},{"price":"0.06","size":"575.2"},{"price":"0.07","size":"565.1"},{"price":"0.08","size":"557.79"},{"price":"0.09","size":"51.6"},{"price":"0.1","size":"47.29"},{"price":"0.11","size":"43.6"},{"price":"0.12","size":"40.4"},{"price":"0.13","size":"37.5"},{"price":"0.14","size":"34.9"},{"price":"0.15","size":"33.5"},{"price":"0.16","size":"31.3"},{"price":"0.17","size":"30.3"},{"price":"0.18","size":"56.3"},{"price":"0.19","size":"584.79"},{"price":"0.2","size":"251.8"},{"price":"0.21","size":"150.1"},{"price":"0.22","size":"155.07"},{"price":"0.23","size":"162"},{"price":"0.24","size":"166.46"},{"price":"0.25","size":"158.46"},{"price":"0.26","size":"230.16"},{"price":"0.27","size":"125"},{"price":"0.28","size":"124"},{"price":"0.29","size":"22"},{"price":"0.3","size":"22"},{"price":"0.31","size":"283.21"},{"price":"0.32","size":"68.21"},{"price":"0.33","size":"128.21"},{"price":"0.34","size":"5.21"},{"price":"0.35","size":"21.09"}],"event_type":"book","hash":"73967519ec0ed511d7de85aec12b4f7b6e637664","market":"0x717c0e8ccd4d5c7040185188fbae28be901ca589a11a94b1b38ca36a79eccfeb","timestamp":"1785122715928"},"payload_hash":"769f7bfb8f41f4b303b78569ac54007e28cd82ce3776eb412d94fbc767ff99f0","raw_frame":"{\"market\":\"0x717c0e8ccd4d5c7040185188fbae28be901ca589a11a94b1b38ca36a79eccfeb\", \"asset_id\":\"41448400836309843603620980831210604935021861034693225347475867885462478926555\", \"bids\":[{\"price\":\"0.01\", \"size\":\"5453.02\"}, {\"price\":\"0.02\", \"size\":\"673.1\"}, {\"price\":\"0.03\", \"size\":\"746.43\"}, {\"price\":\"0.04\", \"size\":\"578.09\"}, {\"price\":\"0.05\", \"size\":\"594.2\"}, {\"price\":\"0.06\", \"size\":\"575.2\"}, {\"price\":\"0.07\", \"size\":\"565.1\"}, {\"price\":\"0.08\", \"size\":\"557.79\"}, {\"price\":\"0.09\", \"size\":\"51.6\"}, {\"price\":\"0.1\", \"size\":\"47.29\"}, {\"price\":\"0.11\", \"size\":\"43.6\"}, {\"price\":\"0.12\", \"size\":\"40.4\"}, {\"price\":\"0.13\", \"size\":\"37.5\"}, {\"price\":\"0.14\", \"size\":\"34.9\"}, {\"price\":\"0.15\", \"size\":\"33.5\"}, {\"price\":\"0.16\", \"size\":\"31.3\"}, {\"price\":\"0.17\", \"size\":\"30.3\"}, {\"price\":\"0.18\", \"size\":\"56.3\"}, {\"price\":\"0.19\", \"size\":\"584.79\"}, {\"price\":\"0.2\", \"size\":\"251.8\"}, {\"price\":\"0.21\", \"size\":\"150.1\"}, {\"price\":\"0.22\", \"size\":\"155.07\"}, {\"price\":\"0.23\", \"size\":\"162\"}, {\"price\":\"0.24\", \"size\":\"166.46\"}, {\"price\":\"0.25\", \"size\":\"158.46\"}, {\"price\":\"0.26\", \"size\":\"230.16\"}, {\"price\":\"0.27\", \"size\":\"125\"}, {\"price\":\"0.28\", \"size\":\"124\"}, {\"price\":\"0.29\", \"size\":\"22\"}, {\"price\":\"0.3\", \"size\":\"22\"}, {\"price\":\"0.31\", \"size\":\"283.21\"}, {\"price\":\"0.32\", \"size\":\"68.21\"}, {\"price\":\"0.33\", \"size\":\"128.21\"}, {\"price\":\"0.34\", \"size\":\"5.21\"}, {\"price\":\"0.35\", \"size\":\"21.09\"}], \"asks\":[{\"price\":\"0.99\", \"size\":\"5453.02\"}, {\"price\":\"0.98\", \"size\":\"683.1\"}, {\"price\":\"0.97\", \"size\":\"613.1\"}, {\"price\":\"0.96\", \"size\":\"578.09\"}, {\"price\":\"0.95\", \"size\":\"668.2\"}, {\"price\":\"0.94\", \"size\":\"553.2\"}, {\"price\":\"0.93\", \"size\":\"546.1\"}, {\"price\":\"0.92\", \"size\":\"540.79\"}, {\"price\":\"0.91\", \"size\":\"536.6\"}, {\"price\":\"0.9\", \"size\":\"33.29\"}, {\"price\":\"0.89\", \"size\":\"30.6\"}, {\"price\":\"0.88\", \"size\":\"28.4\"}, {\"price\":\"0.87\", \"size\":\"26.5\"}, {\"price\":\"0.86\", \"size\":\"32.04\"}, {\"price\":\"0.85\", \"size\":\"23.5\"}, {\"price\":\"0.84\", \"size\":\"22.3\"}, {\"price\":\"0.83\", \"size\":\"21.3\"}, {\"price\":\"0.82\", \"size\":\"20.3\"}, {\"price\":\"0.81\", \"size\":\"19.5\"}, {\"price\":\"0.8\", \"size\":\"26.8\"}, {\"price\":\"0.79\", \"size\":\"26.1\"}, {\"price\":\"0.78\", \"size\":\"24.5\"}, {\"price\":\"0.77\", \"size\":\"23.89\"}, {\"price\":\"0.76\", \"size\":\"23.39\"}, {\"price\":\"0.75\", \"size\":\"23\"}, {\"price\":\"0.74\", \"size\":\"21.6\"}, {\"price\":\"0.73\", \"size\":\"21.2\"}, {\"price\":\"0.72\", \"size\":\"20.9\"}, {\"price\":\"0.71\", \"size\":\"20.6\"}, {\"price\":\"0.7\", \"size\":\"20.3\"}, {\"price\":\"0.69\", \"size\":\"36.07\"}, {\"price\":\"0.68\", \"size\":\"19.8\"}, {\"price\":\"0.67\", \"size\":\"31.6\"}, {\"price\":\"0.66\", \"size\":\"19.4\"}, {\"price\":\"0.65\", \"size\":\"18.2\"}, {\"price\":\"0.64\", \"size\":\"18\"}, {\"price\":\"0.63\", \"size\":\"17.9\"}, {\"price\":\"0.62\", \"size\":\"320.83\"}, {\"price\":\"0.61\", \"size\":\"17.6\"}, {\"price\":\"0.6\", \"size\":\"17.5\"}, {\"price\":\"0.59\", \"size\":\"17.4\"}, {\"price\":\"0.58\", \"size\":\"25.3\"}, {\"price\":\"0.57\", \"size\":\"24.14\"}, {\"price\":\"0.56\", \"size\":\"122.2\"}, {\"price\":\"0.55\", \"size\":\"122.1\"}, {\"price\":\"0.54\", \"size\":\"122.1\"}, {\"price\":\"0.53\", \"size\":\"127\"}, {\"price\":\"0.52\", \"size\":\"122\"}, {\"price\":\"0.51\", \"size\":\"212\"}, {\"price\":\"0.5\", \"size\":\"117\"}, {\"price\":\"0.49\", \"size\":\"122\"}, {\"price\":\"0.48\", \"size\":\"5\"}, {\"price\":\"0.47\", \"size\":\"115\"}, {\"price\":\"0.46\", \"size\":\"111\"}, {\"price\":\"0.45\", \"size\":\"245\"}, {\"price\":\"0.44\", \"size\":\"13\"}, {\"price\":\"0.43\", \"size\":\"5\"}, {\"price\":\"0.42\", \"size\":\"5\"}, {\"price\":\"0.41\", \"size\":\"26.9\"}, {\"price\":\"0.4\", \"size\":\"31.96\"}, {\"price\":\"0.39\", \"size\":\"32.08\"}, {\"price\":\"0.38\", \"size\":\"62.51\"}, {\"price\":\"0.37\", \"size\":\"10\"}, {\"price\":\"0.36\", \"size\":\"334\"}], \"hash\":\"73967519ec0ed511d7de85aec12b4f7b6e637664\", \"timestamp\":\"1785122715928\", \"event_type\":\"book\"}","received_at":"2026-07-27T03:25:17.267294Z","schema_version":"clob-market-ws.book.v1","sequence":null,"server_hash":"73967519ec0ed511d7de85aec12b4f7b6e637664","server_timestamp":"1785122715928","session_id":"dd162b8dca5f43ff811d304e69a06123","source":"clob_market_ws"},"received_at":"2026-07-27T03:25:17.267294Z","record_id":"ece1ec9b581f4d17934565eda07514a23806e3fa1c844152e880bdd65e9016d9","schema_fingerprint":"dc2caa1c89c6a7426e2e07ff925910cd4d0a8a223a515d4092d91d6d127aacb6","schema_version":"edge-lab-recorder.raw.v1","sequence":null,"source":"clob_market_ws"}
{"event_at":"2026-07-27T03:25:15.932000Z","event_fingerprint":"30d5d992c6f2f515180bf67b70e5dff29e63112d4ad6f62fefcc9f18450234fb","payload":{"connection_id":"c7dc2e4762f849c6b6f9306b6518dcab","event_at":"2026-07-27T03:25:15.932000Z","event_type":"price_change","frame_hash":"01f4946c551fa2224526e49cd4d664690fb6882505073cd35e533d935059d31c","frame_index":0,"kind":"data","monotonic_ns":224700652638250,"payload":{"event_type":"price_change","market":"0x717c0e8ccd4d5c7040185188fbae28be901ca589a11a94b1b38ca36a79eccfeb","price_changes":[{"asset_id":"41448400836309843603620980831210604935021861034693225347475867885462478926555","best_ask":"0.36","best_bid":"0.35","hash":"8891bcfd4b628fd6aa0222d5ddf557ecd28d03e3","price":"0.31","side":"BUY","size":"13.21"},{"asset_id":"24254094493625419915756280046002869097156693848522361803041977572204227262166","best_ask":"0.65","best_bid":"0.64","hash":"e9330911048ddf9dbdb3288d9fa8a993bf7f8e22","price":"0.69","side":"SELL","size":"13.21"}],"timestamp":"1785122715932"},"payload_hash":"68c71cc6f22121ffcd1d1e390991d11974ac1e7834bbb578785de2b63aa65d05","raw_frame":"{\"market\":\"0x717c0e8ccd4d5c7040185188fbae28be901ca589a11a94b1b38ca36a79eccfeb\", \"price_changes\":[{\"asset_id\":\"41448400836309843603620980831210604935021861034693225347475867885462478926555\", \"price\":\"0.31\", \"size\":\"13.21\", \"side\":\"BUY\", \"hash\":\"8891bcfd4b628fd6aa0222d5ddf557ecd28d03e3\", \"best_bid\":\"0.35\", \"best_ask\":\"0.36\"}, {\"asset_id\":\"24254094493625419915756280046002869097156693848522361803041977572204227262166\", \"price\":\"0.69\", \"size\":\"13.21\", \"side\":\"SELL\", \"hash\":\"e9330911048ddf9dbdb3288d9fa8a993bf7f8e22\", \"best_bid\":\"0.64\", \"best_ask\":\"0.65\"}], \"timestamp\":\"1785122715932\", \"event_type\":\"price_change\"}","received_at":"2026-07-27T03:25:17.293598Z","schema_version":"clob-market-ws.price_change.v1","sequence":null,"server_hash":null,"server_timestamp":"1785122715932","session_id":"dd162b8dca5f43ff811d304e69a06123","source":"clob_market_ws"},"received_at":"2026-07-27T03:25:17.293598Z","record_id":"fcf7425d1bac795a1a747eca496b454dedecfa9f1f13a60092241b1183b113f8","schema_fingerprint":"4aa3821a28b0b7c2400bc59aba4bcc0a76e971dadd19610d3ad38c768e124dc7","schema_version":"edge-lab-recorder.raw.v1","sequence":null,"source":"clob_market_ws"}
{"event_at":"2026-07-27T03:25:15.933000Z","event_fingerprint":"7654d80075580f40c86e839b4bdca271e6fff46764b775b1c6c1de389138c9eb","payload":{"connection_id":"c7dc2e4762f849c6b6f9306b6518dcab","event_at":"2026-07-27T03:25:15.933000Z","event_type":"price_change","frame_hash":"b4308da8ab8fd7ea42f1cf101959740f1c0725a318ecf2ae46bf1d43f574680a","frame_index":0,"kind":"data","monotonic_ns":224700665221833,"payload":{"event_type":"price_change","market":"0x717c0e8ccd4d5c7040185188fbae28be901ca589a11a94b1b38ca36a79eccfeb","price_changes":[{"asset_id":"41448400836309843603620980831210604935021861034693225347475867885462478926555","best_ask":"0.36","best_bid":"0.35","hash":"3849eb185713a467542f73a05e4e620d9d343ca6","price":"0.32","side":"BUY","size":"338.21"},{"asset_id":"24254094493625419915756280046002869097156693848522361803041977572204227262166","best_ask":"0.65","best_bid":"0.64","hash":"1ef118f7ca7ae25b578b0fdd44eb711beaea9309","price":"0.68","side":"SELL","size":"338.21"}],"timestamp":"1785122715933"},"payload_hash":"86cd057d4eab4b4d79f5cf5e921d6dd1a713595580d934b5874bb873464b47a8","raw_frame":"{\"market\":\"0x717c0e8ccd4d5c7040185188fbae28be901ca589a11a94b1b38ca36a79eccfeb\", \"price_changes\":[{\"asset_id\":\"41448400836309843603620980831210604935021861034693225347475867885462478926555\", \"price\":\"0.32\", \"size\":\"338.21\", \"side\":\"BUY\", \"hash\":\"3849eb185713a467542f73a05e4e620d9d343ca6\", \"best_bid\":\"0.35\", \"best_ask\":\"0.36\"}, {\"asset_id\":\"24254094493625419915756280046002869097156693848522361803041977572204227262166\", \"price\":\"0.68\", \"size\":\"338.21\", \"side\":\"SELL\", \"hash\":\"1ef118f7ca7ae25b578b0fdd44eb711beaea9309\", \"best_bid\":\"0.64\", \"best_ask\":\"0.65\"}], \"timestamp\":\"1785122715933\", \"event_type\":\"price_change\"}","received_at":"2026-07-27T03:25:17.306180Z","schema_version":"clob-market-ws.price_change.v1","sequence":null,"server_hash":null,"server_timestamp":"1785122715933","session_id":"dd162b8dca5f43ff811d304e69a06123","source":"clob_market_ws"},"received_at":"2026-07-27T03:25:17.306180Z","record_id":"dd875afd6ae974aa8b3547fd6787c73f8ce3b3be311def111ced5d630c01d7d7","schema_fingerprint":"4aa3821a28b0b7c2400bc59aba4bcc0a76e971dadd19610d3ad38c768e124dc7","schema_version":"edge-lab-recorder.raw.v1","sequence":null,"source":"clob_market_ws"}
{"event_at":"2026-07-27T03:25:15.938000Z","event_fingerprint":"5d3bab7e6e8236a39ed482324f8508258c13c6b0ff3f17d60a3bf41840045bf8","payload":{"connection_id":"c7dc2e4762f849c6b6f9306b6518dcab","event_at":"2026-07-27T03:25:15.938000Z","event_type":"price_change","frame_hash":"7c388b658648c9c77a6ea257e745494660abee9b1095b98689a9f6bee56b27c7","frame_index":0,"kind":"data","monotonic_ns":224700672048916,"payload":{"event_type":"price_change","market":"0x717c0e8ccd4d5c7040185188fbae28be901ca589a11a94b1b38ca36a79eccfeb","price_changes":[{"asset_id":"24254094493625419915756280046002869097156693848522361803041977572204227262166","best_ask":"0.65","best_bid":"0.64","hash":"a2693a28930df4dc885bfd7964bce7cbe928c540","price":"0.63","side":"BUY","size":"106"},{"asset_id":"41448400836309843603620980831210604935021861034693225347475867885462478926555","best_ask":"0.36","best_bid":"0.35","hash":"5bae6c266643acb7f0ac2e76210a7135f1ae4441","price":"0.37","side":"SELL","size":"106"}],"timestamp":"1785122715938"},"payload_hash":"5503004ed944978dd1d5b7d88d213938c2a395da67058743a5a064a4e69ba41e","raw_frame":"{\"market\":\"0x717c0e8ccd4d5c7040185188fbae28be901ca589a11a94b1b38ca36a79eccfeb\", \"price_changes\":[{\"asset_id\":\"24254094493625419915756280046002869097156693848522361803041977572204227262166\", \"price\":\"0.63\", \"size\":\"106\", \"side\":\"BUY\", \"hash\":\"a2693a28930df4dc885bfd7964bce7cbe928c540\", \"best_bid\":\"0.64\", \"best_ask\":\"0.65\"}, {\"asset_id\":\"41448400836309843603620980831210604935021861034693225347475867885462478926555\", \"price\":\"0.37\", \"size\":\"106\", \"side\":\"SELL\", \"hash\":\"5bae6c266643acb7f0ac2e76210a7135f1ae4441\", \"best_bid\":\"0.35\", \"best_ask\":\"0.36\"}], \"timestamp\":\"1785122715938\", \"event_type\":\"price_change\"}","received_at":"2026-07-27T03:25:17.313009Z","schema_version":"clob-market-ws.price_change.v1","sequence":null,"server_hash":null,"server_timestamp":"1785122715938","session_id":"dd162b8dca5f43ff811d304e69a06123","source":"clob_market_ws"},"received_at":"2026-07-27T03:25:17.313009Z","record_id":"7214abfd111b5f0922d0379ee0b7e805680a34d835d3fd57a8a8c6aa75a1e963","schema_fingerprint":"4aa3821a28b0b7c2400bc59aba4bcc0a76e971dadd19610d3ad38c768e124dc7","schema_version":"edge-lab-recorder.raw.v1","sequence":null,"source":"clob_market_ws"}
{"event_at":"2026-07-27T03:25:15.947000Z","event_fingerprint":"680b37666bd10359afbcbe815bbafe5496d6aea662039192d433bfc879f4b96f","payload":{"connection_id":"c7dc2e4762f849c6b6f9306b6518dcab","event_at":"2026-07-27T03:25:15.947000Z","event_type":"price_change","frame_hash":"026587bafca10673a1b1fef1f62199d15a6762f0d308ae55c249cd15e9d17fcc","frame_index":0,"kind":"data","monotonic_ns":224700678181125,"payload":{"event_type":"price_change","market":"0x717c0e8ccd4d5c7040185188fbae28be901ca589a11a94b1b38ca36a79eccfeb","price_changes":[{"asset_id":"41448400836309843603620980831210604935021861034693225347475867885462478926555","best_ask":"0.36","best_bid":"0.35","hash":"5fb72bb35f26f5d39043780dab5ecf3381961b44","price":"0.33","side":"BUY","size":"32.21"},{"asset_id":"24254094493625419915756280046002869097156693848522361803041977572204227262166","best_ask":"0.65","best_bid":"0.64","hash":"754b413f7920111fab735b790ebf3c481f207d0f","price":"0.67","side":"SELL","size":"32.21"}],"timestamp":"1785122715947"},"payload_hash":"e0a61f3ddc6ea1c3a4681050283fa37dc8247bb3298e154178756b881b9226c6","raw_frame":"{\"market\":\"0x717c0e8ccd4d5c7040185188fbae28be901ca589a11a94b1b38ca36a79eccfeb\", \"price_changes\":[{\"asset_id\":\"41448400836309843603620980831210604935021861034693225347475867885462478926555\", \"price\":\"0.33\", \"size\":\"32.21\", \"side\":\"BUY\", \"hash\":\"5fb72bb35f26f5d39043780dab5ecf3381961b44\", \"best_bid\":\"0.35\", \"best_ask\":\"0.36\"}, {\"asset_id\":\"24254094493625419915756280046002869097156693848522361803041977572204227262166\", \"price\":\"0.67\", \"size\":\"32.21\", \"side\":\"SELL\", \"hash\":\"754b413f7920111fab735b790ebf3c481f207d0f\", \"best_bid\":\"0.64\", \"best_ask\":\"0.65\"}], \"timestamp\":\"1785122715947\", \"event_type\":\"price_change\"}","received_at":"2026-07-27T03:25:17.319138Z","schema_version":"clob-market-ws.price_change.v1","sequence":null,"server_hash":null,"server_timestamp":"1785122715947","session_id":"dd162b8dca5f43ff811d304e69a06123","source":"clob_market_ws"},"received_at":"2026-07-27T03:25:17.319138Z","record_id":"6df97384468e6ef609c638871a620086972b208deb11049967144063b73f7750","schema_fingerprint":"4aa3821a28b0b7c2400bc59aba4bcc0a76e971dadd19610d3ad38c768e124dc7","schema_version":"edge-lab-recorder.raw.v1","sequence":null,"source":"clob_market_ws"}
{"event_at":"2026-07-27T03:25:15.947000Z","event_fingerprint":"75299646783ed04edf7e8539a1895fc5110ad2f1d3bcd24bc43a8ef729c2df9d","payload":{"connection_id":"c7dc2e4762f849c6b6f9306b6518dcab","event_at":"2026-07-27T03:25:15.947000Z","event_type":"price_change","frame_hash":"bad1e23ad5de8e164cc7f4013ff3689406a7681a6d5f4fc199ac5be7c7e847b5","frame_index":0,"kind":"data","monotonic_ns":224700683764250,"payload":{"event_type":"price_change","market":"0x717c0e8ccd4d5c7040185188fbae28be901ca589a11a94b1b38ca36a79eccfeb","price_changes":[{"asset_id":"24254094493625419915756280046002869097156693848522361803041977572204227262166","best_ask":"0.65","best_bid":"0.64","hash":"9b6bc1c10cf855f07cddfa90ce091bc0f7484eca","price":"0.6","side":"BUY","size":"21.96"},{"asset_id":"41448400836309843603620980831210604935021861034693225347475867885462478926555","best_ask":"0.36","best_bid":"0.35","hash":"fbe1e6477452c2e016c61aa68b7cbb70d9420744","price":"0.4","side":"SELL","size":"21.96"}],"timestamp":"1785122715947"},"payload_hash":"244f3a891d8e8fa2c6eaa9bf7891cc23867f9d4004140919e2a7b6ef4664112b","raw_frame":"{\"market\":\"0x717c0e8ccd4d5c7040185188fbae28be901ca589a11a94b1b38ca36a79eccfeb\", \"price_changes\":[{\"asset_id\":\"24254094493625419915756280046002869097156693848522361803041977572204227262166\", \"price\":\"0.6\", \"size\":\"21.96\", \"side\":\"BUY\", \"hash\":\"9b6bc1c10cf855f07cddfa90ce091bc0f7484eca\", \"best_bid\":\"0.64\", \"best_ask\":\"0.65\"}, {\"asset_id\":\"41448400836309843603620980831210604935021861034693225347475867885462478926555\", \"price\":\"0.4\", \"size\":\"21.96\", \"side\":\"SELL\", \"hash\":\"fbe1e6477452c2e016c61aa68b7cbb70d9420744\", \"best_bid\":\"0.35\", \"best_ask\":\"0.36\"}], \"timestamp\":\"1785122715947\", \"event_type\":\"price_change\"}","received_at":"2026-07-27T03:25:17.324724Z","schema_version":"clob-market-ws.price_change.v1","sequence":null,"server_hash":null,"server_timestamp":"1785122715947","session_id":"dd162b8dca5f43ff811d304e69a06123","source":"clob_market_ws"},"received_at":"2026-07-27T03:25:17.324724Z","record_id":"f8fa61e7746a5ad39d40cd1203eaf4e4f1d2e7ad63c7d731d0be2a1584ea8e9a","schema_fingerprint":"4aa3821a28b0b7c2400bc59aba4bcc0a76e971dadd19610d3ad38c768e124dc7","schema_version":"edge-lab-recorder.raw.v1","sequence":null,"source":"clob_market_ws"}
{"event_at":"2026-07-27T03:25:15.947000Z","event_fingerprint":"45c389c4097d24bd6d0012108ce11a2cde47591a35c71ece2213c28c78641825","payload":{"connection_id":"c7dc2e4762f849c6b6f9306b6518dcab","event_at":"2026-07-27T03:25:15.947000Z","event_type":"price_change","frame_hash":"55f4fc46fc1de34e5703223a5eab020f6b8c9ba7cd2c79c3163d118befd6e8cc","frame_index":0,"kind":"data","monotonic_ns":224700689046166,"payload":{"event_type":"price_change","market":"0x717c0e8ccd4d5c7040185188fbae28be901ca589a11a94b1b38ca36a79eccfeb","price_changes":[{"asset_id":"41448400836309843603620980831210604935021861034693225347475867885462478926555","best_ask":"0.36","best_bid":"0.35","hash":"fbe1e6477452c2e016c61aa68b7cbb70d9420744","price":"0.3","side":"BUY","size":"12"},{"asset_id":"24254094493625419915756280046002869097156693848522361803041977572204227262166","best_ask":"0.65","best_bid":"0.64","hash":"9b6bc1c10cf855f07cddfa90ce091bc0f7484eca","price":"0.7","side":"SELL","size":"12"}],"timestamp":"1785122715947"},"payload_hash":"cdf09e48720f0734d3c5e12ac3b6b658b36dbdae32b80ec432f42c03c035ea3d","raw_frame":"{\"market\":\"0x717c0e8ccd4d5c7040185188fbae28be901ca589a11a94b1b38ca36a79eccfeb\", \"price_changes\":[{\"asset_id\":\"41448400836309843603620980831210604935021861034693225347475867885462478926555\", \"price\":\"0.3\", \"size\":\"12\", \"side\":\"BUY\", \"hash\":\"fbe1e6477452c2e016c61aa68b7cbb70d9420744\", \"best_bid\":\"0.35\", \"best_ask\":\"0.36\"}, {\"asset_id\":\"24254094493625419915756280046002869097156693848522361803041977572204227262166\", \"price\":\"0.7\", \"size\":\"12\", \"side\":\"SELL\", \"hash\":\"9b6bc1c10cf855f07cddfa90ce091bc0f7484eca\", \"best_bid\":\"0.64\", \"best_ask\":\"0.65\"}], \"timestamp\":\"1785122715947\", \"event_type\":\"price_change\"}","received_at":"2026-07-27T03:25:17.330007Z","schema_version":"clob-market-ws.price_change.v1","sequence":null,"server_hash":null,"server_timestamp":"1785122715947","session_id":"dd162b8dca5f43ff811d304e69a06123","source":"clob_market_ws"},"received_at":"2026-07-27T03:25:17.330007Z","record_id":"0b6d33bdb0ae6b54639df3dc948ad34f4e18b74c0d793693dfeb39f2d8328fe5","schema_fingerprint":"4aa3821a28b0b7c2400bc59aba4bcc0a76e971dadd19610d3ad38c768e124dc7","schema_version":"edge-lab-recorder.raw.v1","sequence":null,"source":"clob_market_ws"}
{"event_at":"2026-07-27T03:25:15.965000Z","event_fingerprint":"1c16c868138091ed4b3fc96c14110f9000fbf8859b4364fb25a22eb96009cc6a","payload":{"connection_id":"c7dc2e4762f849c6b6f9306b6518dcab","event_at":"2026-07-27T03:25:15.965000Z","event_type":"price_change","frame_hash":"f85698c4a04d86183fc96a9b5250491ae67cf1715628bbcd71c43353ca29c897","frame_index":0,"kind":"data","monotonic_ns":224700693486083,"payload":{"event_type":"price_change","market":"0x717c0e8ccd4d5c7040185188fbae28be901ca589a11a94b1b38ca36a79eccfeb","price_changes":[{"asset_id":"24254094493625419915756280046002869097156693848522361803041977572204227262166","best_ask":"0.65","best_bid":"0.64","hash":"0807f3d6695e25a478ed76233e9e0d4c6ba33ad1","price":"0.01","side":"BUY","size":"5458.02"},{"asset_id":"41448400836309843603620980831210604935021861034693225347475867885462478926555","best_ask":"0.36","best_bid":"0.35","hash":"4d2fe614050cecb6724a9fcd3980fd85ef4bfc30","price":"0.99","side":"SELL","size":"5458.02"}],"timestamp":"1785122715965"},"payload_hash":"f87e97d401f059785d01977c8709cd9a94d21e0989b6e6d1264f9a73ec02fa31","raw_frame":"{\"market\":\"0x717c0e8ccd4d5c7040185188fbae28be901ca589a11a94b1b38ca36a79eccfeb\", \"price_changes\":[{\"asset_id\":\"24254094493625419915756280046002869097156693848522361803041977572204227262166\", \"price\":\"0.01\", \"size\":\"5458.02\", \"side\":\"BUY\", \"hash\":\"0807f3d6695e25a478ed76233e9e0d4c6ba33ad1\", \"best_bid\":\"0.64\", \"best_ask\":\"0.65\"}, {\"asset_id\":\"41448400836309843603620980831210604935021861034693225347475867885462478926555\", \"price\":\"0.99\", \"size\":\"5458.02\", \"side\":\"SELL\", \"hash\":\"4d2fe614050cecb6724a9fcd3980fd85ef4bfc30\", \"best_bid\":\"0.35\", \"best_ask\":\"0.36\"}], \"timestamp\":\"1785122715965\", \"event_type\":\"price_change\"}","received_at":"2026-07-27T03:25:17.334447Z","schema_version":"clob-market-ws.price_change.v1","sequence":null,"server_hash":null,"server_timestamp":"1785122715965","session_id":"dd162b8dca5f43ff811d304e69a06123","source":"clob_market_ws"},"received_at":"2026-07-27T03:25:17.334447Z","record_id":"a199322f940a20d67479be887e4574226ab98e79d4831c52efe65fc894a27655","schema_fingerprint":"4aa3821a28b0b7c2400bc59aba4bcc0a76e971dadd19610d3ad38c768e124dc7","schema_version":"edge-lab-recorder.raw.v1","sequence":null,"source":"clob_market_ws"}
{"event_at":"2026-07-27T03:25:15.973000Z","event_fingerprint":"2af1ee579cf4cd229fbe0bdaf85080299745f09c0987501342531894dfa2775d","payload":{"connection_id":"c7dc2e4762f849c6b6f9306b6518dcab","event_at":"2026-07-27T03:25:15.973000Z","event_type":"price_change","frame_hash":"62ea1de276d83712a977a84367b58ca62b50f974ce4986df9423f722fd69a977","frame_index":0,"kind":"data","monotonic_ns":224700699520333,"payload":{"event_type":"price_change","market":"0x717c0e8ccd4d5c7040185188fbae28be901ca589a11a94b1b38ca36a79eccfeb","price_changes":[{"asset_id":"41448400836309843603620980831210604935021861034693225347475867885462478926555","best_ask":"0.36","best_bid":"0.35","hash":"ba58d75bb2da4e98e88e9da556cb7ba9bf7ab902","price":"0.31","side":"BUY","size":"23.21"},{"asset_id":"24254094493625419915756280046002869097156693848522361803041977572204227262166","best_ask":"0.65","best_bid":"0.64","hash":"9cd05d68250fd97760c86b6c8e4945cb699c7de5","price":"0.69","side":"SELL","size":"23.21"}],"timestamp":"1785122715973"},"payload_hash":"6540907143f29f13dc1ab31faff43753d3e48db4b79ffe19b1f5f20a1677533c","raw_frame":"{\"market\":\"0x717c0e8ccd4d5c7040185188fbae28be901ca589a11a94b1b38ca36a79eccfeb\", \"price_changes\":[{\"asset_id\":\"41448400836309843603620980831210604935021861034693225347475867885462478926555\", \"price\":\"0.31\", \"size\":\"23.21\", \"side\":\"BUY\", \"hash\":\"ba58d75bb2da4e98e88e9da556cb7ba9bf7ab902\", \"best_bid\":\"0.35\", \"best_ask\":\"0.36\"}, {\"asset_id\":\"24254094493625419915756280046002869097156693848522361803041977572204227262166\", \"price\":\"0.69\", \"size\":\"23.21\", \"side\":\"SELL\", \"hash\":\"9cd05d68250fd97760c86b6c8e4945cb699c7de5\", \"best_bid\":\"0.64\", \"best_ask\":\"0.65\"}], \"timestamp\":\"1785122715973\", \"event_type\":\"price_change\"}","received_at":"2026-07-27T03:25:17.340481Z","schema_version":"clob-market-ws.price_change.v1","sequence":null,"server_hash":null,"server_timestamp":"1785122715973","session_id":"dd162b8dca5f43ff811d304e69a06123","source":"clob_market_ws"},"received_at":"2026-07-27T03:25:17.340481Z","record_id":"514e47372001144c78dc6187516fdbfefc66264d6bfa703aeedd5c0d0b255f16","schema_fingerprint":"4aa3821a28b0b7c2400bc59aba4bcc0a76e971dadd19610d3ad38c768e124dc7","schema_version":"edge-lab-recorder.raw.v1","sequence":null,"source":"clob_market_ws"}
{"event_at":"2026-07-27T03:25:15.975000Z","event_fingerprint":"fe62a445fd34f4629172a110894c10cf615c93da3df9ffb215898832ede64f76","payload":{"connection_id":"c7dc2e4762f849c6b6f9306b6518dcab","event_at":"2026-07-27T03:25:15.975000Z","event_type":"price_change","frame_hash":"0a7ab827a18b17473f5608a3daf9f9969e6d67874959c16d3933a7fe609f3bc7","frame_index":0,"kind":"data","monotonic_ns":224700704739916,"payload":{"event_type":"price_change","market":"0x717c0e8ccd4d5c7040185188fbae28be901ca589a11a94b1b38ca36a79eccfeb","price_changes":[{"asset_id":"24254094493625419915756280046002869097156693848522361803041977572204227262166","best_ask":"0.65","best_bid":"0.64","hash":"9ef812ba6a033a674835b11273f63ebb63d65505","price":"0.59","side":"BUY","size":"36.9"},{"asset_id":"41448400836309843603620980831210604935021861034693225347475867885462478926555","best_ask":"0.36","best_bid":"0.35","hash":"e45086464aefd679c4ac07591b75656d3441b285","price":"0.41","side":"SELL","size":"36.9"}],"timestamp":"1785122715975"},"payload_hash":"a310dbcc30960cc4d1618381e24474998fc279662ce8d1c3100066e799d6d43b","raw_frame":"{\"market\":\"0x717c0e8ccd4d5c7040185188fbae28be901ca589a11a94b1b38ca36a79eccfeb\", \"price_changes\":[{\"asset_id\":\"24254094493625419915756280046002869097156693848522361803041977572204227262166\", \"price\":\"0.59\", \"size\":\"36.9\", \"side\":\"BUY\", \"hash\":\"9ef812ba6a033a674835b11273f63ebb63d65505\", \"best_bid\":\"0.64\", \"best_ask\":\"0.65\"}, {\"asset_id\":\"41448400836309843603620980831210604935021861034693225347475867885462478926555\", \"price\":\"0.41\", \"size\":\"36.9\", \"side\":\"SELL\", \"hash\":\"e45086464aefd679c4ac07591b75656d3441b285\", \"best_bid\":\"0.35\", \"best_ask\":\"0.36\"}], \"timestamp\":\"1785122715975\", \"event_type\":\"price_change\"}","received_at":"2026-07-27T03:25:17.345698Z","schema_version":"clob-market-ws.price_change.v1","sequence":null,"server_hash":null,"server_timestamp":"1785122715975","session_id":"dd162b8dca5f43ff811d304e69a06123","source":"clob_market_ws"},"received_at":"2026-07-27T03:25:17.345698Z","record_id":"abff8392e7eebb62b391b6a411c76b65a801670503a084a99992ae3f6db09da6","schema_fingerprint":"4aa3821a28b0b7c2400bc59aba4bcc0a76e971dadd19610d3ad38c768e124dc7","schema_version":"edge-lab-recorder.raw.v1","sequence":null,"source":"clob_market_ws"}
{"event_at":"2026-07-27T03:25:15.984000Z","event_fingerprint":"595f2fe638222bd56b71fe86936717b5f818709c6ded213767f63a3843b7a1c9","payload":{"connection_id":"c7dc2e4762f849c6b6f9306b6518dcab","event_at":"2026-07-27T03:25:15.984000Z","event_type":"price_change","frame_hash":"1cb146107adad7e23bf993e4e2abbbe94fef0fd979d31ac3737ffa966e0c5c09","frame_index":0,"kind":"data","monotonic_ns":224700709874083,"payload":{"event_type":"price_change","market":"0x717c0e8ccd4d5c7040185188fbae28be901ca589a11a94b1b38ca36a79eccfeb","price_changes":[{"asset_id":"24254094493625419915756280046002869097156693848522361803041977572204227262166","best_ask":"0.65","best_bid":"0.64","hash":"deeedd40145e5c589b2a58b9ba8af829b073db59","price":"0.01","side":"BUY","size":"5453.02"},{"asset_id":"41448400836309843603620980831210604935021861034693225347475867885462478926555","best_ask":"0.36","best_bid":"0.35","hash":"fe0e1a896655c788be2cf6e65dfd6f5057a07d7c","price":"0.99","side":"SELL","size":"5453.02"}],"timestamp":"1785122715984"},"payload_hash":"8a912ac94d5eabee09e186e3360aea72f6ac7a141c1bca68015bc600ce46f372","raw_frame":"{\"market\":\"0x717c0e8ccd4d5c7040185188fbae28be901ca589a11a94b1b38ca36a79eccfeb\", \"price_changes\":[{\"asset_id\":\"24254094493625419915756280046002869097156693848522361803041977572204227262166\", \"price\":\"0.01\", \"size\":\"5453.02\", \"side\":\"BUY\", \"hash\":\"deeedd40145e5c589b2a58b9ba8af829b073db59\", \"best_bid\":\"0.64\", \"best_ask\":\"0.65\"}, {\"asset_id\":\"41448400836309843603620980831210604935021861034693225347475867885462478926555\", \"price\":\"0.99\", \"size\":\"5453.02\", \"side\":\"SELL\", \"hash\":\"fe0e1a896655c788be2cf6e65dfd6f5057a07d7c\", \"best_bid\":\"0.35\", \"best_ask\":\"0.36\"}], \"timestamp\":\"1785122715984\", \"event_type\":\"price_change\"}","received_at":"2026-07-27T03:25:17.350833Z","schema_version":"clob-market-ws.price_change.v1","sequence":null,"server_hash":null,"server_timestamp":"1785122715984","session_id":"dd162b8dca5f43ff811d304e69a06123","source":"clob_market_ws"},"received_at":"2026-07-27T03:25:17.350833Z","record_id":"55c7de2a77e224d74c958abba5d889c6ed3308dcb0bba9a7710fd2c6c1fc56c7","schema_fingerprint":"4aa3821a28b0b7c2400bc59aba4bcc0a76e971dadd19610d3ad38c768e124dc7","schema_version":"edge-lab-recorder.raw.v1","sequence":null,"source":"clob_market_ws"}
{"event_at":"2026-07-27T03:25:16.003000Z","event_fingerprint":"8ee8674a974f59f7cbcbe5c9c0354a1c9281046cd5809e3933fb837b078c6fc9","payload":{"connection_id":"c7dc2e4762f849c6b6f9306b6518dcab","event_at":"2026-07-27T03:25:16.003000Z","event_type":"price_change","frame_hash":"985bfad69b74ef63694acfa20ec51a9a26f45a1ea9b36a5b305c5daf64f8a553","frame_index":0,"kind":"data","monotonic_ns":224700719515166,"payload":{"event_type":"price_change","market":"0x717c0e8ccd4d5c7040185188fbae28be901ca589a11a94b1b38ca36a79eccfeb","price_changes":[{"asset_id":"24254094493625419915756280046002869097156693848522361803041977572204227262166","best_ask":"0.65","best_bid":"0.64","hash":"380b1f2ae37493b0bf3285dc9d001d1b9276dd74","price":"0.01","side":"BUY","size":"5458.02"},{"asset_id":"41448400836309843603620980831210604935021861034693225347475867885462478926555","best_ask":"0.36","best_bid":"0.35","hash":"ef86c8cb9a5bc020da67e07d826c2e868a912c67","price":"0.99","side":"SELL","size":"5458.02"}],"timestamp":"1785122716003"},"payload_hash":"7275d900774cad0b392f08b5323f1e315d327a3a3c77981339aa6906e9bac3c4","raw_frame":"{\"market\":\"0x717c0e8ccd4d5c7040185188fbae28be901ca589a11a94b1b38ca36a79eccfeb\", \"price_changes\":[{\"asset_id\":\"24254094493625419915756280046002869097156693848522361803041977572204227262166\", \"price\":\"0.01\", \"size\":\"5458.02\", \"side\":\"BUY\", \"hash\":\"380b1f2ae37493b0bf3285dc9d001d1b9276dd74\", \"best_bid\":\"0.64\", \"best_ask\":\"0.65\"}, {\"asset_id\":\"41448400836309843603620980831210604935021861034693225347475867885462478926555\", \"price\":\"0.99\", \"size\":\"5458.02\", \"side\":\"SELL\", \"hash\":\"ef86c8cb9a5bc020da67e07d826c2e868a912c67\", \"best_bid\":\"0.35\", \"best_ask\":\"0.36\"}], \"timestamp\":\"1785122716003\", \"event_type\":\"price_change\"}","received_at":"2026-07-27T03:25:17.360475Z","schema_version":"clob-market-ws.price_change.v1","sequence":null,"server_hash":null,"server_timestamp":"1785122716003","session_id":"dd162b8dca5f43ff811d304e69a06123","source":"clob_market_ws"},"received_at":"2026-07-27T03:25:17.360475Z","record_id":"963125a37acb08a0eba8d88ac1db7680f044a2c3465407a6ca8aa1430b99f43c","schema_fingerprint":"4aa3821a28b0b7c2400bc59aba4bcc0a76e971dadd19610d3ad38c768e124dc7","schema_version":"edge-lab-recorder.raw.v1","sequence":null,"source":"clob_market_ws"}
{"event_at":"2026-07-27T03:25:15.999000Z","event_fingerprint":"d119e079572aa682a9bff1aaf2f1efd25c41baf6e587bad59ed3f23f2937027a","payload":{"connection_id":"c7dc2e4762f849c6b6f9306b6518dcab","event_at":"2026-07-27T03:25:15.999000Z","event_type":"last_trade_price","frame_hash":"5557ab11035cc1476a781feda38029cc22f01a4f40a4e815ed349209e0630e8c","frame_index":0,"kind":"data","monotonic_ns":224700723965291,"payload":{"asset_id":"24254094493625419915756280046002869097156693848522361803041977572204227262166","event_type":"last_trade_price","fee_rate_bps":"0","market":"0x717c0e8ccd4d5c7040185188fbae28be901ca589a11a94b1b38ca36a79eccfeb","price":"0.65","side":"BUY","size":"10.307691","timestamp":"1785122715999","transaction_hash":"0x6ec37a4a31817e8f7f83640c82a076b86bbc1b08dad6ff6c150cdee27b48e784"},"payload_hash":"8e9aa8248716eea5b311b27970741372be59e2d3381bb532cd92b0013d39d122","raw_frame":"{\"market\":\"0x717c0e8ccd4d5c7040185188fbae28be901ca589a11a94b1b38ca36a79eccfeb\", \"asset_id\":\"24254094493625419915756280046002869097156693848522361803041977572204227262166\", \"price\":\"0.65\", \"size\":\"10.307691\", \"fee_rate_bps\":\"0\", \"side\":\"BUY\", \"timestamp\":\"1785122715999\", \"event_type\":\"last_trade_price\", \"transaction_hash\":\"0x6ec37a4a31817e8f7f83640c82a076b86bbc1b08dad6ff6c150cdee27b48e784\"}","received_at":"2026-07-27T03:25:17.364925Z","schema_version":"clob-market-ws.last_trade_price.v1","sequence":null,"server_hash":null,"server_timestamp":"1785122715999","session_id":"dd162b8dca5f43ff811d304e69a06123","source":"clob_market_ws"},"received_at":"2026-07-27T03:25:17.364925Z","record_id":"83b916b76071529e59000ee1e458dae903d346f9fde8c15ad6fd6f29fa3c8fc8","schema_fingerprint":"95ad9be75a4b695cd99991e12b2592bc7346f3f5388a82d0000ba65bc0d9fd0a","schema_version":"edge-lab-recorder.raw.v1","sequence":null,"source":"clob_market_ws"}
{"event_at":"2026-07-27T03:25:16.024000Z","event_fingerprint":"d6f04cae3e637bf9bf149d1322fee0ac7c91c339a96a21fee385edda5a58a1cf","payload":{"connection_id":"c7dc2e4762f849c6b6f9306b6518dcab","event_at":"2026-07-27T03:25:16.024000Z","event_type":"price_change","frame_hash":"b7421c4773dc12d8d3dc6349626c7a741b2901217515a54f4e34d45b19cb997b","frame_index":0,"kind":"data","monotonic_ns":224700729041291,"payload":{"event_type":"price_change","market":"0x717c0e8ccd4d5c7040185188fbae28be901ca589a11a94b1b38ca36a79eccfeb","price_changes":[{"asset_id":"24254094493625419915756280046002869097156693848522361803041977572204227262166","best_ask":"0.65","best_bid":"0.64","hash":"8d730c8b85114ee5210450164bae73a2375c393f","price":"0.62","side":"BUY","size":"37.51"},{"asset_id":"41448400836309843603620980831210604935021861034693225347475867885462478926555","best_ask":"0.36","best_bid":"0.35","hash":"aa440c48f7b90ff293390ba6cc8c93fa8db2b2e0","price":"0.38","side":"SELL","size":"37.51"}],"timestamp":"1785122716024"},"payload_hash":"40d0cdec5bdd2b50345e12b3438c26520e6ec84651ce271f5d3ff3a2a9a98191","raw_frame":"{\"market\":\"0x717c0e8ccd4d5c7040185188fbae28be901ca589a11a94b1b38ca36a79eccfeb\", \"price_changes\":[{\"asset_id\":\"24254094493625419915756280046002869097156693848522361803041977572204227262166\", \"price\":\"0.62\", \"size\":\"37.51\", \"side\":\"BUY\", \"hash\":\"8d730c8b85114ee5210450164bae73a2375c393f\", \"best_bid\":\"0.64\", \"best_ask\":\"0.65\"}, {\"asset_id\":\"41448400836309843603620980831210604935021861034693225347475867885462478926555\", \"price\":\"0.38\", \"size\":\"37.51\", \"side\":\"SELL\", \"hash\":\"aa440c48f7b90ff293390ba6cc8c93fa8db2b2e0\", \"best_bid\":\"0.35\", \"best_ask\":\"0.36\"}], \"timestamp\":\"1785122716024\", \"event_type\":\"price_change\"}","received_at":"2026-07-27T03:25:17.369999Z","schema_version":"clob-market-ws.price_change.v1","sequence":null,"server_hash":null,"server_timestamp":"1785122716024","session_id":"dd162b8dca5f43ff811d304e69a06123","source":"clob_market_ws"},"received_at":"2026-07-27T03:25:17.369999Z","record_id":"460c3d53400b138fe3b8044550e1fc755a15446b259d953c04d5fae1e0be668c","schema_fingerprint":"4aa3821a28b0b7c2400bc59aba4bcc0a76e971dadd19610d3ad38c768e124dc7","schema_version":"edge-lab-recorder.raw.v1","sequence":null,"source":"clob_market_ws"}
{"event_at":"2026-07-27T03:25:16.025000Z","event_fingerprint":"c3a067ced09c3135e589ef2ca0f4e438bf2d8283dc71e89ef74aacff8f0d6e90","payload":{"connection_id":"c7dc2e4762f849c6b6f9306b6518dcab","event_at":"2026-07-27T03:25:16.025000Z","event_type":"price_change","frame_hash":"ce885317dabc220a74a81e77c373468b0523e3cc72f20961b0a7f0701bb8dc10","frame_index":0,"kind":"data","monotonic_ns":224700734768500,"payload":{"event_type":"price_change","market":"0x717c0e8ccd4d5c7040185188fbae28be901ca589a11a94b1b38ca36a79eccfeb","price_changes":[{"asset_id":"41448400836309843603620980831210604935021861034693225347475867885462478926555","best_ask":"0.36","best_bid":"0.35","hash":"63f7445cacf380b7ec5f174930343d4fd91108ed","price":"0.38","side":"SELL","size":"12.51"},{"asset_id":"24254094493625419915756280046002869097156693848522361803041977572204227262166","best_ask":"0.65","best_bid":"0.64","hash":"0b5296ebc1313feb004ecc32935c801e7d50c142","price":"0.62","side":"BUY","size":"12.51"}],"timestamp":"1785122716025"},"payload_hash":"4629c6d90a13f1fd53f09d93d632aa2b62b8c04db133aec02b8626db184102fa","raw_frame":"{\"market\":\"0x717c0e8ccd4d5c7040185188fbae28be901ca589a11a94b1b38ca36a79eccfeb\", \"price_changes\":[{\"asset_id\":\"41448400836309843603620980831210604935021861034693225347475867885462478926555\", \"price\":\"0.38\", \"size\":\"12.51\", \"side\":\"SELL\", \"hash\":\"63f7445cacf380b7ec5f174930343d4fd91108ed\", \"best_bid\":\"0.35\", \"best_ask\":\"0.36\"}, {\"asset_id\":\"24254094493625419915756280046002869097156693848522361803041977572204227262166\", \"price\":\"0.62\", \"size\":\"12.51\", \"side\":\"BUY\", \"hash\":\"0b5296ebc1313feb004ecc32935c801e7d50c142\", \"best_bid\":\"0.64\", \"best_ask\":\"0.65\"}], \"timestamp\":\"1785122716025\", \"event_type\":\"price_change\"}","received_at":"2026-07-27T03:25:17.375727Z","schema_version":"clob-market-ws.price_change.v1","sequence":null,"server_hash":null,"server_timestamp":"1785122716025","session_id":"dd162b8dca5f43ff811d304e69a06123","source":"clob_market_ws"},"received_at":"2026-07-27T03:25:17.375727Z","record_id":"f5ad750bc5fa03a4da254035d6e0e75a322372b9529b8bc483444040cbc91f80","schema_fingerprint":"4aa3821a28b0b7c2400bc59aba4bcc0a76e971dadd19610d3ad38c768e124dc7","schema_version":"edge-lab-recorder.raw.v1","sequence":null,"source":"clob_market_ws"}
{"event_at":"2026-07-27T03:25:16.027000Z","event_fingerprint":"b00ce0008d3041e6cf95d5325ad47c5fdb701e7b094caffd279c360ea1ab2e78","payload":{"connection_id":"c7dc2e4762f849c6b6f9306b6518dcab","event_at":"2026-07-27T03:25:16.027000Z","event_type":"price_change","frame_hash":"bd9b084199c47b896a3ccb5299ba895375190285203f4739651587a83669ab00","frame_index":0,"kind":"data","monotonic_ns":224700743376583,"payload":{"event_type":"price_change","market":"0x717c0e8ccd4d5c7040185188fbae28be901ca589a11a94b1b38ca36a79eccfeb","price_changes":[{"asset_id":"41448400836309843603620980831210604935021861034693225347475867885462478926555","best_ask":"0.36","best_bid":"0.35","hash":"9a9ce3e849a291f0f1513309bd363abe4a3918da","price":"0.01","side":"BUY","size":"5458.02"},{"asset_id":"24254094493625419915756280046002869097156693848522361803041977572204227262166","best_ask":"0.65","best_bid":"0.64","hash":"adebb62828cadf1134f17f90dd32b1fba1545050","price":"0.99","side":"SELL","size":"5458.02"}],"timestamp":"1785122716027"},"payload_hash":"15f3eb5dd2452e8fe05a8a91b9f0ef107b819ea7a8412d7a9f5dc0c6c7cf943b","raw_frame":"{\"market\":\"0x717c0e8ccd4d5c7040185188fbae28be901ca589a11a94b1b38ca36a79eccfeb\", \"price_changes\":[{\"asset_id\":\"41448400836309843603620980831210604935021861034693225347475867885462478926555\", \"price\":\"0.01\", \"size\":\"5458.02\", \"side\":\"BUY\", \"hash\":\"9a9ce3e849a291f0f1513309bd363abe4a3918da\", \"best_bid\":\"0.35\", \"best_ask\":\"0.36\"}, {\"asset_id\":\"24254094493625419915756280046002869097156693848522361803041977572204227262166\", \"price\":\"0.99\", \"size\":\"5458.02\", \"side\":\"SELL\", \"hash\":\"adebb62828cadf1134f17f90dd32b1fba1545050\", \"best_bid\":\"0.64\", \"best_ask\":\"0.65\"}], \"timestamp\":\"1785122716027\", \"event_type\":\"price_change\"}","received_at":"2026-07-27T03:25:17.384335Z","schema_version":"clob-market-ws.price_change.v1","sequence":null,"server_hash":null,"server_timestamp":"1785122716027","session_id":"dd162b8dca5f43ff811d304e69a06123","source":"clob_market_ws"},"received_at":"2026-07-27T03:25:17.384335Z","record_id":"f66d35a81baa38d393212291b82e73d9cae5d77eb77e8ddf3aa6d36ce331c5d7","schema_fingerprint":"4aa3821a28b0b7c2400bc59aba4bcc0a76e971dadd19610d3ad38c768e124dc7","schema_version":"edge-lab-recorder.raw.v1","sequence":null,"source":"clob_market_ws"}
{"event_at":"2026-07-27T03:25:16.034000Z","event_fingerprint":"8038ee710757391a078b876bb796a17555e413f34e01adbe3b4089bb1753baef","payload":{"connection_id":"c7dc2e4762f849c6b6f9306b6518dcab","event_at":"2026-07-27T03:25:16.034000Z","event_type":"price_change","frame_hash":"c07dcfff974a3a0d653def390ae929299ffc67b898cdf91c99c8c618c208f522","frame_index":0,"kind":"data","monotonic_ns":224700751244416,"payload":{"event_type":"price_change","market":"0x717c0e8ccd4d5c7040185188fbae28be901ca589a11a94b1b38ca36a79eccfeb","price_changes":[{"asset_id":"41448400836309843603620980831210604935021861034693225347475867885462478926555","best_ask":"0.36","best_bid":"0.35","hash":"3dd8a42d020dabcac65f2cf7fe146c959e1732e8","price":"0.35","side":"BUY","size":"30.69"},{"asset_id":"24254094493625419915756280046002869097156693848522361803041977572204227262166","best_ask":"0.65","best_bid":"0.64","hash":"f4dbf054d533e152a1870dc48807d724b8c6a197","price":"0.65","side":"SELL","size":"30.69"}],"timestamp":"1785122716034"},"payload_hash":"be5d7946aea0f767fb1d3b899bb0584bcaa6c0dfc73a3203bcd3ed01e67d9ab8","raw_frame":"{\"market\":\"0x717c0e8ccd4d5c7040185188fbae28be901ca589a11a94b1b38ca36a79eccfeb\", \"price_changes\":[{\"asset_id\":\"41448400836309843603620980831210604935021861034693225347475867885462478926555\", \"price\":\"0.35\", \"size\":\"30.69\", \"side\":\"BUY\", \"hash\":\"3dd8a42d020dabcac65f2cf7fe146c959e1732e8\", \"best_bid\":\"0.35\", \"best_ask\":\"0.36\"}, {\"asset_id\":\"24254094493625419915756280046002869097156693848522361803041977572204227262166\", \"price\":\"0.65\", \"size\":\"30.69\", \"side\":\"SELL\", \"hash\":\"f4dbf054d533e152a1870dc48807d724b8c6a197\", \"best_bid\":\"0.64\", \"best_ask\":\"0.65\"}], \"timestamp\":\"1785122716034\", \"event_type\":\"price_change\"}","received_at":"2026-07-27T03:25:17.392201Z","schema_version":"clob-market-ws.price_change.v1","sequence":null,"server_hash":null,"server_timestamp":"1785122716034","session_id":"dd162b8dca5f43ff811d304e69a06123","source":"clob_market_ws"},"received_at":"2026-07-27T03:25:17.392201Z","record_id":"0feb0de2832f2c897cc979cb219562360decec94c7a556785f429c6a381caa93","schema_fingerprint":"4aa3821a28b0b7c2400bc59aba4bcc0a76e971dadd19610d3ad38c768e124dc7","schema_version":"edge-lab-recorder.raw.v1","sequence":null,"source":"clob_market_ws"}
{"event_at":"2026-07-27T03:25:16.046000Z","event_fingerprint":"7054c95db399ffb77b402a73bdc3cfa3e9a7cce6fd83f35ed7ddedd555b11fd7","payload":{"connection_id":"c7dc2e4762f849c6b6f9306b6518dcab","event_at":"2026-07-27T03:25:16.046000Z","event_type":"price_change","frame_hash":"8e51f81689f2d972b601647e0933c7a9470817bf8b4c7bd26141d5e5179cdbc2","frame_index":0,"kind":"data","monotonic_ns":224700756686000,"payload":{"event_type":"price_change","market":"0x717c0e8ccd4d5c7040185188fbae28be901ca589a11a94b1b38ca36a79eccfeb","price_changes":[{"asset_id":"41448400836309843603620980831210604935021861034693225347475867885462478926555","best_ask":"0.36","best_bid":"0.35","hash":"44809a6086d533b584c8f8da2090fd5596404a62","price":"0.39","side":"SELL","size":"57.08"},{"asset_id":"24254094493625419915756280046002869097156693848522361803041977572204227262166","best_ask":"0.65","best_bid":"0.64","hash":"d487890e9dd08e61f3a2a92de12a2ee87e54aa65","price":"0.61","side":"BUY","size":"57.08"}],"timestamp":"1785122716046"},"payload_hash":"118032bdde5846acadd26b3a2b23cafe7218846e99ce129e3c4900ccf2e5714f","raw_frame":"{\"market\":\"0x717c0e8ccd4d5c7040185188fbae28be901ca589a11a94b1b38ca36a79eccfeb\", \"price_changes\":[{\"asset_id\":\"41448400836309843603620980831210604935021861034693225347475867885462478926555\", \"price\":\"0.39\", \"size\":\"57.08\", \"side\":\"SELL\", \"hash\":\"44809a6086d533b584c8f8da2090fd5596404a62\", \"best_bid\":\"0.35\", \"best_ask\":\"0.36\"}, {\"asset_id\":\"24254094493625419915756280046002869097156693848522361803041977572204227262166\", \"price\":\"0.61\", \"size\":\"57.08\", \"side\":\"BUY\", \"hash\":\"d487890e9dd08e61f3a2a92de12a2ee87e54aa65\", \"best_bid\":\"0.64\", \"best_ask\":\"0.65\"}], \"timestamp\":\"1785122716046\", \"event_type\":\"price_change\"}","received_at":"2026-07-27T03:25:17.397646Z","schema_version":"clob-market-ws.price_change.v1","sequence":null,"server_hash":null,"server_timestamp":"1785122716046","session_id":"dd162b8dca5f43ff811d304e69a06123","source":"clob_market_ws"},"received_at":"2026-07-27T03:25:17.397646Z","record_id":"9fb4ce2f6e89a6cc99c7e4fde0883fc87027877f3e14efa91369ddb8935b4811","schema_fingerprint":"4aa3821a28b0b7c2400bc59aba4bcc0a76e971dadd19610d3ad38c768e124dc7","schema_version":"edge-lab-recorder.raw.v1","sequence":null,"source":"clob_market_ws"}
{"event_at":"2026-07-27T03:25:16.049000Z","event_fingerprint":"ea1439296e2d832b3186abad2311280218470d6953bff551e3a008aea47fcd30","payload":{"connection_id":"c7dc2e4762f849c6b6f9306b6518dcab","event_at":"2026-07-27T03:25:16.049000Z","event_type":"price_change","frame_hash":"c75cf03aa7bd64cd667984dad781524519cfe066753cee4dce4c472fa90e3c52","frame_index":0,"kind":"data","monotonic_ns":224700760742166,"payload":{"event_type":"price_change","market":"0x717c0e8ccd4d5c7040185188fbae28be901ca589a11a94b1b38ca36a79eccfeb","price_changes":[{"asset_id":"24254094493625419915756280046002869097156693848522361803041977572204227262166","best_ask":"0.65","best_bid":"0.64","hash":"39984a9ca7c2997a41d4c549dcdb0c892d08f88e","price":"0.61","side":"BUY","size":"82.08"},{"asset_id":"41448400836309843603620980831210604935021861034693225347475867885462478926555","best_ask":"0.36","best_bid":"0.35","hash":"04c5e7ecfb4fb3a2320b501e5bc0c49256494038","price":"0.39","side":"SELL","size":"82.08"}],"timestamp":"1785122716049"},"payload_hash":"73571020c043c1292c89c08951568c64ade1b9b0378c1ccc481fafa860e62b43","raw_frame":"{\"market\":\"0x717c0e8ccd4d5c7040185188fbae28be901ca589a11a94b1b38ca36a79eccfeb\", \"price_changes\":[{\"asset_id\":\"24254094493625419915756280046002869097156693848522361803041977572204227262166\", \"price\":\"0.61\", \"size\":\"82.08\", \"side\":\"BUY\", \"hash\":\"39984a9ca7c2997a41d4c549dcdb0c892d08f88e\", \"best_bid\":\"0.64\", \"best_ask\":\"0.65\"}, {\"asset_id\":\"41448400836309843603620980831210604935021861034693225347475867885462478926555\", \"price\":\"0.39\", \"size\":\"82.08\", \"side\":\"SELL\", \"hash\":\"04c5e7ecfb4fb3a2320b501e5bc0c49256494038\", \"best_bid\":\"0.35\", \"best_ask\":\"0.36\"}], \"timestamp\":\"1785122716049\", \"event_type\":\"price_change\"}","received_at":"2026-07-27T03:25:17.401698Z","schema_version":"clob-market-ws.price_change.v1","sequence":null,"server_hash":null,"server_timestamp":"1785122716049","session_id":"dd162b8dca5f43ff811d304e69a06123","source":"clob_market_ws"},"received_at":"2026-07-27T03:25:17.401698Z","record_id":"e6ac86a76181b1fb74fed4f0a9e70001bdd3cc1690a770de960db4782ecc9783","schema_fingerprint":"4aa3821a28b0b7c2400bc59aba4bcc0a76e971dadd19610d3ad38c768e124dc7","schema_version":"edge-lab-recorder.raw.v1","sequence":null,"source":"clob_market_ws"}
{"event_at":"2026-07-27T03:25:16.051000Z","event_fingerprint":"cdcf047701fe0a8a8c510bdfe34f2eb46f005f184e83ed9e4cc587d40cd0e3a4","payload":{"connection_id":"c7dc2e4762f849c6b6f9306b6518dcab","event_at":"2026-07-27T03:25:16.051000Z","event_type":"price_change","frame_hash":"c6667a27c1436b133f356cc720ba436db6d0977f9909632da9f1f968d4a0feb6","frame_index":0,"kind":"data","monotonic_ns":224700766795833,"payload":{"event_type":"price_change","market":"0x717c0e8ccd4d5c7040185188fbae28be901ca589a11a94b1b38ca36a79eccfeb","price_changes":[{"asset_id":"24254094493625419915756280046002869097156693848522361803041977572204227262166","best_ask":"0.65","best_bid":"0.64","hash":"5a1aa9c3563bd6c01c5332d0ae2c313a12f9fe77","price":"0.01","side":"BUY","size":"5453.02"},{"asset_id":"41448400836309843603620980831210604935021861034693225347475867885462478926555","best_ask":"0.36","best_bid":"0.35","hash":"831c17bb4d6dca0b020408c78278ce7c6930bb98","price":"0.99","side":"SELL","size":"5453.02"}],"timestamp":"1785122716051"},"payload_hash":"5fc5fad9c7620c968c6890fee85fee49001c84f5d6e2d02f202ff5be8bc01846","raw_frame":"{\"market\":\"0x717c0e8ccd4d5c7040185188fbae28be901ca589a11a94b1b38ca36a79eccfeb\", \"price_changes\":[{\"asset_id\":\"24254094493625419915756280046002869097156693848522361803041977572204227262166\", \"price\":\"0.01\", \"size\":\"5453.02\", \"side\":\"BUY\", \"hash\":\"5a1aa9c3563bd6c01c5332d0ae2c313a12f9fe77\", \"best_bid\":\"0.64\", \"best_ask\":\"0.65\"}, {\"asset_id\":\"41448400836309843603620980831210604935021861034693225347475867885462478926555\", \"price\":\"0.99\", \"size\":\"5453.02\", \"side\":\"SELL\", \"hash\":\"831c17bb4d6dca0b020408c78278ce7c6930bb98\", \"best_bid\":\"0.35\", \"best_ask\":\"0.36\"}], \"timestamp\":\"1785122716051\", \"event_type\":\"price_change\"}","received_at":"2026-07-27T03:25:17.407754Z","schema_version":"clob-market-ws.price_change.v1","sequence":null,"server_hash":null,"server_timestamp":"1785122716051","session_id":"dd162b8dca5f43ff811d304e69a06123","source":"clob_market_ws"},"received_at":"2026-07-27T03:25:17.407754Z","record_id":"decf8796258653f2645829597a2c669cae9f74b1372cfdba55bf62bcc3262ccf","schema_fingerprint":"4aa3821a28b0b7c2400bc59aba4bcc0a76e971dadd19610d3ad38c768e124dc7","schema_version":"edge-lab-recorder.raw.v1","sequence":null,"source":"clob_market_ws"}
{"event_at":"2026-07-27T03:25:16.053000Z","event_fingerprint":"7def1c5c14eecba63f9c867600999d9edb359afdf86a3c364ed9b35ce2ff43e5","payload":{"connection_id":"c7dc2e4762f849c6b6f9306b6518dcab","event_at":"2026-07-27T03:25:16.053000Z","event_type":"price_change","frame_hash":"cd6d5f3a9d61411f5ffaa16f9643527ae604cb40a82f9661417f79f248d3a9e0","frame_index":0,"kind":"data","monotonic_ns":224700774196750,"payload":{"event_type":"price_change","market":"0x717c0e8ccd4d5c7040185188fbae28be901ca589a11a94b1b38ca36a79eccfeb","price_changes":[{"asset_id":"41448400836309843603620980831210604935021861034693225347475867885462478926555","best_ask":"0.36","best_bid":"0.35","hash":"9f37eea88c04e25deffac5d1ae63e73518e3431f","price":"0.01","side":"BUY","size":"5453.02"},{"asset_id":"24254094493625419915756280046002869097156693848522361803041977572204227262166","best_ask":"0.65","best_bid":"0.64","hash":"95c2a386d1ccae24a36a4635e276bc0d2f9d1d8d","price":"0.99","side":"SELL","size":"5453.02"}],"timestamp":"1785122716053"},"payload_hash":"f760021f273a392ae201e171350dffd3898b3ee5970f1ca315769a9052218b07","raw_frame":"{\"market\":\"0x717c0e8ccd4d5c7040185188fbae28be901ca589a11a94b1b38ca36a79eccfeb\", \"price_changes\":[{\"asset_id\":\"41448400836309843603620980831210604935021861034693225347475867885462478926555\", \"price\":\"0.01\", \"size\":\"5453.02\", \"side\":\"BUY\", \"hash\":\"9f37eea88c04e25deffac5d1ae63e73518e3431f\", \"best_bid\":\"0.35\", \"best_ask\":\"0.36\"}, {\"asset_id\":\"24254094493625419915756280046002869097156693848522361803041977572204227262166\", \"price\":\"0.99\", \"size\":\"5453.02\", \"side\":\"SELL\", \"hash\":\"95c2a386d1ccae24a36a4635e276bc0d2f9d1d8d\", \"best_bid\":\"0.64\", \"best_ask\":\"0.65\"}], \"timestamp\":\"1785122716053\", \"event_type\":\"price_change\"}","received_at":"2026-07-27T03:25:17.415153Z","schema_version":"clob-market-ws.price_change.v1","sequence":null,"server_hash":null,"server_timestamp":"1785122716053","session_id":"dd162b8dca5f43ff811d304e69a06123","source":"clob_market_ws"},"received_at":"2026-07-27T03:25:17.415153Z","record_id":"bf52dbba7ea579b1d336aae8a8e265aa44ffdc9bf94d5881e3eb5d30abfa5509","schema_fingerprint":"4aa3821a28b0b7c2400bc59aba4bcc0a76e971dadd19610d3ad38c768e124dc7","schema_version":"edge-lab-recorder.raw.v1","sequence":null,"source":"clob_market_ws"}
{"event_at":"2026-07-27T03:25:16.057000Z","event_fingerprint":"161425e4ee57cb74ae74d7af6cd2e42cba997497d131968dc0dfdd15c5382f77","payload":{"connection_id":"c7dc2e4762f849c6b6f9306b6518dcab","event_at":"2026-07-27T03:25:16.057000Z","event_type":"price_change","frame_hash":"d163102556ad086d92790ee038c47f6c8c6b173dab344ab991eac20500e68abc","frame_index":0,"kind":"data","monotonic_ns":224700780297500,"payload":{"event_type":"price_change","market":"0x717c0e8ccd4d5c7040185188fbae28be901ca589a11a94b1b38ca36a79eccfeb","price_changes":[{"asset_id":"24254094493625419915756280046002869097156693848522361803041977572204227262166","best_ask":"0.65","best_bid":"0.64","hash":"173d81a353eb713d231682026f1110d59844e49c","price":"0.01","side":"BUY","size":"5458.02"},{"asset_id":"41448400836309843603620980831210604935021861034693225347475867885462478926555","best_ask":"0.36","best_bid":"0.35","hash":"cfc737895d65c599cb8bd0edc022aae994f8ec64","price":"0.99","side":"SELL","size":"5458.02"}],"timestamp":"1785122716057"},"payload_hash":"aa32d6bb10fb33dd6f714fb3607a76ebda90376b56d9f500908ab51ba0f06d07","raw_frame":"{\"market\":\"0x717c0e8ccd4d5c7040185188fbae28be901ca589a11a94b1b38ca36a79eccfeb\", \"price_changes\":[{\"asset_id\":\"24254094493625419915756280046002869097156693848522361803041977572204227262166\", \"price\":\"0.01\", \"size\":\"5458.02\", \"side\":\"BUY\", \"hash\":\"173d81a353eb713d231682026f1110d59844e49c\", \"best_bid\":\"0.64\", \"best_ask\":\"0.65\"}, {\"asset_id\":\"41448400836309843603620980831210604935021861034693225347475867885462478926555\", \"price\":\"0.99\", \"size\":\"5458.02\", \"side\":\"SELL\", \"hash\":\"cfc737895d65c599cb8bd0edc022aae994f8ec64\", \"best_bid\":\"0.35\", \"best_ask\":\"0.36\"}], \"timestamp\":\"1785122716057\", \"event_type\":\"price_change\"}","received_at":"2026-07-27T03:25:17.421255Z","schema_version":"clob-market-ws.price_change.v1","sequence":null,"server_hash":null,"server_timestamp":"1785122716057","session_id":"dd162b8dca5f43ff811d304e69a06123","source":"clob_market_ws"},"received_at":"2026-07-27T03:25:17.421255Z","record_id":"6d1b9474da879386a38d310ea585b62b116b7343c2c4beb6e2263c8296399ca7","schema_fingerprint":"4aa3821a28b0b7c2400bc59aba4bcc0a76e971dadd19610d3ad38c768e124dc7","schema_version":"edge-lab-recorder.raw.v1","sequence":null,"source":"clob_market_ws"}
{"event_at":"2026-07-27T03:25:16.079000Z","event_fingerprint":"991e1f5553e62cfccc6317aa9c36b081f52187e410b9103a1d3778866fccbe35","payload":{"connection_id":"c7dc2e4762f849c6b6f9306b6518dcab","event_at":"2026-07-27T03:25:16.079000Z","event_type":"price_change","frame_hash":"b15476af38837c61fe471fe2eb8ac017b0f0e355a5590e837e8c213c93fa373a","frame_index":0,"kind":"data","monotonic_ns":224700786193333,"payload":{"event_type":"price_change","market":"0x717c0e8ccd4d5c7040185188fbae28be901ca589a11a94b1b38ca36a79eccfeb","price_changes":[{"asset_id":"24254094493625419915756280046002869097156693848522361803041977572204227262166","best_ask":"0.65","best_bid":"0.64","hash":"eafdb55eebb9588a577693d2e03f60f306c5aa75","price":"0.01","side":"BUY","size":"5453.02"},{"asset_id":"41448400836309843603620980831210604935021861034693225347475867885462478926555","best_ask":"0.36","best_bid":"0.35","hash":"9d0e83c97ab25753ad0c401096af4ad4b1ebe12a","price":"0.99","side":"SELL","size":"5453.02"}],"timestamp":"1785122716079"},"payload_hash":"ed126e3879c41d79e2c1fa1446fd50477f65bec3f7b313c6fdbdcf1e3cf4025b","raw_frame":"{\"market\":\"0x717c0e8ccd4d5c7040185188fbae28be901ca589a11a94b1b38ca36a79eccfeb\", \"price_changes\":[{\"asset_id\":\"24254094493625419915756280046002869097156693848522361803041977572204227262166\", \"price\":\"0.01\", \"size\":\"5453.02\", \"side\":\"BUY\", \"hash\":\"eafdb55eebb9588a577693d2e03f60f306c5aa75\", \"best_bid\":\"0.64\", \"best_ask\":\"0.65\"}, {\"asset_id\":\"41448400836309843603620980831210604935021861034693225347475867885462478926555\", \"price\":\"0.99\", \"size\":\"5453.02\", \"side\":\"SELL\", \"hash\":\"9d0e83c97ab25753ad0c401096af4ad4b1ebe12a\", \"best_bid\":\"0.35\", \"best_ask\":\"0.36\"}], \"timestamp\":\"1785122716079\", \"event_type\":\"price_change\"}","received_at":"2026-07-27T03:25:17.427152Z","schema_version":"clob-market-ws.price_change.v1","sequence":null,"server_hash":null,"server_timestamp":"1785122716079","session_id":"dd162b8dca5f43ff811d304e69a06123","source":"clob_market_ws"},"received_at":"2026-07-27T03:25:17.427152Z","record_id":"337dbe5b9e12b0424ca7a994de2181ea678141ee800259b02ffd48fd2ee9cd66","schema_fingerprint":"4aa3821a28b0b7c2400bc59aba4bcc0a76e971dadd19610d3ad38c768e124dc7","schema_version":"edge-lab-recorder.raw.v1","sequence":null,"source":"clob_market_ws"}
{"event_at":"2026-07-27T03:25:16.125000Z","event_fingerprint":"65afd45af63a5c1f34b7b9ee6e3b4b46fb0da848227f4e8b6aa6066f24851e67","payload":{"connection_id":"c7dc2e4762f849c6b6f9306b6518dcab","event_at":"2026-07-27T03:25:16.125000Z","event_type":"price_change","frame_hash":"d61379ab5f0e94e88435b9674a8d8ee233b91713dd2d22599ff6e947c0734c67","frame_index":0,"kind":"data","monotonic_ns":224700790673000,"payload":{"event_type":"price_change","market":"0x717c0e8ccd4d5c7040185188fbae28be901ca589a11a94b1b38ca36a79eccfeb","price_changes":[{"asset_id":"41448400836309843603620980831210604935021861034693225347475867885462478926555","best_ask":"0.36","best_bid":"0.35","hash":"b7ca5136c3dab3f0d042b2658ff5260c36587779","price":"0.33","side":"BUY","size":"128.21"},{"asset_id":"24254094493625419915756280046002869097156693848522361803041977572204227262166","best_ask":"0.65","best_bid":"0.64","hash":"9bec718b897ad36f30548371818529b5c12d004c","price":"0.67","side":"SELL","size":"128.21"}],"timestamp":"1785122716125"},"payload_hash":"fe0090cdd08f19b866edf6cedaf8b62865cb7092e35689d93f9be6c787d658b3","raw_frame":"{\"market\":\"0x717c0e8ccd4d5c7040185188fbae28be901ca589a11a94b1b38ca36a79eccfeb\", \"price_changes\":[{\"asset_id\":\"41448400836309843603620980831210604935021861034693225347475867885462478926555\", \"price\":\"0.33\", \"size\":\"128.21\", \"side\":\"BUY\", \"hash\":\"b7ca5136c3dab3f0d042b2658ff5260c36587779\", \"best_bid\":\"0.35\", \"best_ask\":\"0.36\"}, {\"asset_id\":\"24254094493625419915756280046002869097156693848522361803041977572204227262166\", \"price\":\"0.67\", \"size\":\"128.21\", \"side\":\"SELL\", \"hash\":\"9bec718b897ad36f30548371818529b5c12d004c\", \"best_bid\":\"0.64\", \"best_ask\":\"0.65\"}], \"timestamp\":\"1785122716125\", \"event_type\":\"price_change\"}","received_at":"2026-07-27T03:25:17.431633Z","schema_version":"clob-market-ws.price_change.v1","sequence":null,"server_hash":null,"server_timestamp":"1785122716125","session_id":"dd162b8dca5f43ff811d304e69a06123","source":"clob_market_ws"},"received_at":"2026-07-27T03:25:17.431633Z","record_id":"7687bf5abd559ed678c772c0553b25020f398d193b63ea8745f27e6fa05209a9","schema_fingerprint":"4aa3821a28b0b7c2400bc59aba4bcc0a76e971dadd19610d3ad38c768e124dc7","schema_version":"edge-lab-recorder.raw.v1","sequence":null,"source":"clob_market_ws"}
{"event_at":"2026-07-27T03:25:16.154000Z","event_fingerprint":"1db599b92e457c443f174190f534462268f7c06f49629095128b9267cedd07c4","payload":{"connection_id":"c7dc2e4762f849c6b6f9306b6518dcab","event_at":"2026-07-27T03:25:16.154000Z","event_type":"price_change","frame_hash":"e6a3170619e0db157519e64bcc4fbb93642a863cdb9a81a2000608f790ab4868","frame_index":0,"kind":"data","monotonic_ns":224700794960208,"payload":{"event_type":"price_change","market":"0x717c0e8ccd4d5c7040185188fbae28be901ca589a11a94b1b38ca36a79eccfeb","price_changes":[{"asset_id":"24254094493625419915756280046002869097156693848522361803041977572204227262166","best_ask":"0.65","best_bid":"0.64","hash":"04a5c6fc018951f046f0f659e2cd2d85f7d34525","price":"0.03","side":"BUY","size":"618.1"},{"asset_id":"41448400836309843603620980831210604935021861034693225347475867885462478926555","best_ask":"0.36","best_bid":"0.35","hash":"2c29f8034dbe0debaf6d7381c2b9af436d8250fa","price":"0.97","side":"SELL","size":"618.1"}],"timestamp":"1785122716154"},"payload_hash":"5f94615401acea4f248acc7f69d61ff5abc08ec833bdbeba4fcf53ae7a1987bd","raw_frame":"{\"market\":\"0x717c0e8ccd4d5c7040185188fbae28be901ca589a11a94b1b38ca36a79eccfeb\", \"price_changes\":[{\"asset_id\":\"24254094493625419915756280046002869097156693848522361803041977572204227262166\", \"price\":\"0.03\", \"size\":\"618.1\", \"side\":\"BUY\", \"hash\":\"04a5c6fc018951f046f0f659e2cd2d85f7d34525\", \"best_bid\":\"0.64\", \"best_ask\":\"0.65\"}, {\"asset_id\":\"41448400836309843603620980831210604935021861034693225347475867885462478926555\", \"price\":\"0.97\", \"size\":\"618.1\", \"side\":\"SELL\", \"hash\":\"2c29f8034dbe0debaf6d7381c2b9af436d8250fa\", \"best_bid\":\"0.35\", \"best_ask\":\"0.36\"}], \"timestamp\":\"1785122716154\", \"event_type\":\"price_change\"}","received_at":"2026-07-27T03:25:17.435918Z","schema_version":"clob-market-ws.price_change.v1","sequence":null,"server_hash":null,"server_timestamp":"1785122716154","session_id":"dd162b8dca5f43ff811d304e69a06123","source":"clob_market_ws"},"received_at":"2026-07-27T03:25:17.435918Z","record_id":"1ff14e1c99bfe7a22ff72599e705622930e4bd5c5c6dd04c9c1d825358722646","schema_fingerprint":"4aa3821a28b0b7c2400bc59aba4bcc0a76e971dadd19610d3ad38c768e124dc7","schema_version":"edge-lab-recorder.raw.v1","sequence":null,"source":"clob_market_ws"}
{"event_at":"2026-07-27T03:25:16.219000Z","event_fingerprint":"1202eac6306a6d07c04ee2929ffbe241970a1e4e850e9fdca9b8910896b04c0b","payload":{"connection_id":"c7dc2e4762f849c6b6f9306b6518dcab","event_at":"2026-07-27T03:25:16.219000Z","event_type":"price_change","frame_hash":"fde47bb91a2092e446677d10e9ff64c8fb0f97b774f2c3198dffbf724e80f683","frame_index":0,"kind":"data","monotonic_ns":224700802492333,"payload":{"event_type":"price_change","market":"0x717c0e8ccd4d5c7040185188fbae28be901ca589a11a94b1b38ca36a79eccfeb","price_changes":[{"asset_id":"24254094493625419915756280046002869097156693848522361803041977572204227262166","best_ask":"0.65","best_bid":"0.64","hash":"27f9b774d0e608f2cbdff2211ebd0f9abdc6562b","price":"0.03","side":"BUY","size":"613.1"},{"asset_id":"41448400836309843603620980831210604935021861034693225347475867885462478926555","best_ask":"0.36","best_bid":"0.35","hash":"166a3aeb319c052e0390740224d5650bc18d1519","price":"0.97","side":"SELL","size":"613.1"}],"timestamp":"1785122716219"},"payload_hash":"7e16fa3103a589a0a285f9da01df45e55c6580bc35afef2b34ac3429d4b361a9","raw_frame":"{\"market\":\"0x717c0e8ccd4d5c7040185188fbae28be901ca589a11a94b1b38ca36a79eccfeb\", \"price_changes\":[{\"asset_id\":\"24254094493625419915756280046002869097156693848522361803041977572204227262166\", \"price\":\"0.03\", \"size\":\"613.1\", \"side\":\"BUY\", \"hash\":\"27f9b774d0e608f2cbdff2211ebd0f9abdc6562b\", \"best_bid\":\"0.64\", \"best_ask\":\"0.65\"}, {\"asset_id\":\"41448400836309843603620980831210604935021861034693225347475867885462478926555\", \"price\":\"0.97\", \"size\":\"613.1\", \"side\":\"SELL\", \"hash\":\"166a3aeb319c052e0390740224d5650bc18d1519\", \"best_bid\":\"0.35\", \"best_ask\":\"0.36\"}], \"timestamp\":\"1785122716219\", \"event_type\":\"price_change\"}","received_at":"2026-07-27T03:25:17.443450Z","schema_version":"clob-market-ws.price_change.v1","sequence":null,"server_hash":null,"server_timestamp":"1785122716219","session_id":"dd162b8dca5f43ff811d304e69a06123","source":"clob_market_ws"},"received_at":"2026-07-27T03:25:17.443450Z","record_id":"d75a39c4139edc38bc3993eb123939b159784fff678b63d9dec401b758a24b4e","schema_fingerprint":"4aa3821a28b0b7c2400bc59aba4bcc0a76e971dadd19610d3ad38c768e124dc7","schema_version":"edge-lab-recorder.raw.v1","sequence":null,"source":"clob_market_ws"}
{"event_at":"2026-07-27T03:25:16.255000Z","event_fingerprint":"5e393f7b6146242e413c3fd6335238759533041e7361cdfe42c663150c531441","payload":{"connection_id":"c7dc2e4762f849c6b6f9306b6518dcab","event_at":"2026-07-27T03:25:16.255000Z","event_type":"price_change","frame_hash":"8a6e129e5bd10c080aeb7c67273613724c0324283aa273a0c90bc7a51688c734","frame_index":0,"kind":"data","monotonic_ns":224700807947500,"payload":{"event_type":"price_change","market":"0x717c0e8ccd4d5c7040185188fbae28be901ca589a11a94b1b38ca36a79eccfeb","price_changes":[{"asset_id":"41448400836309843603620980831210604935021861034693225347475867885462478926555","best_ask":"0.36","best_bid":"0.35","hash":"094add5553bf1ad7c19cc0cc932f8e8d6524d949","price":"0.31","side":"BUY","size":"13.21"},{"asset_id":"24254094493625419915756280046002869097156693848522361803041977572204227262166","best_ask":"0.65","best_bid":"0.64","hash":"7b120ea17e1373de27dd456077b4fe4aa385724c","price":"0.69","side":"SELL","size":"13.21"}],"timestamp":"1785122716255"},"payload_hash":"f9819fb5c5a8107a1407e369407f9a7b03b586739bc25e4905b8ba2969847031","raw_frame":"{\"market\":\"0x717c0e8ccd4d5c7040185188fbae28be901ca589a11a94b1b38ca36a79eccfeb\", \"price_changes\":[{\"asset_id\":\"41448400836309843603620980831210604935021861034693225347475867885462478926555\", \"price\":\"0.31\", \"size\":\"13.21\", \"side\":\"BUY\", \"hash\":\"094add5553bf1ad7c19cc0cc932f8e8d6524d949\", \"best_bid\":\"0.35\", \"best_ask\":\"0.36\"}, {\"asset_id\":\"24254094493625419915756280046002869097156693848522361803041977572204227262166\", \"price\":\"0.69\", \"size\":\"13.21\", \"side\":\"SELL\", \"hash\":\"7b120ea17e1373de27dd456077b4fe4aa385724c\", \"best_bid\":\"0.64\", \"best_ask\":\"0.65\"}], \"timestamp\":\"1785122716255\", \"event_type\":\"price_change\"}","received_at":"2026-07-27T03:25:17.448901Z","schema_version":"clob-market-ws.price_change.v1","sequence":null,"server_hash":null,"server_timestamp":"1785122716255","session_id":"dd162b8dca5f43ff811d304e69a06123","source":"clob_market_ws"},"received_at":"2026-07-27T03:25:17.448901Z","record_id":"b1883c9522bb3b5ba29e62e04c7c0b6f9ea6e684639d32d0b78871ac7315a1d1","schema_fingerprint":"4aa3821a28b0b7c2400bc59aba4bcc0a76e971dadd19610d3ad38c768e124dc7","schema_version":"edge-lab-recorder.raw.v1","sequence":null,"source":"clob_market_ws"}
{"event_at":"2026-07-27T03:25:16.255000Z","event_fingerprint":"703ecd27b6d793ca786a98aeb2a82cef4a91b0f5bb6521a8343d9dc6e44140cc","payload":{"connection_id":"c7dc2e4762f849c6b6f9306b6518dcab","event_at":"2026-07-27T03:25:16.255000Z","event_type":"price_change","frame_hash":"909ebfe21e7792af827adaae495f9571eb211273fba66ae405b7d24e373ed357","frame_index":0,"kind":"data","monotonic_ns":224700814573833,"payload":{"event_type":"price_change","market":"0x717c0e8ccd4d5c7040185188fbae28be901ca589a11a94b1b38ca36a79eccfeb","price_changes":[{"asset_id":"24254094493625419915756280046002869097156693848522361803041977572204227262166","best_ask":"0.65","best_bid":"0.64","hash":"7b120ea17e1373de27dd456077b4fe4aa385724c","price":"0.59","side":"BUY","size":"26.9"},{"asset_id":"41448400836309843603620980831210604935021861034693225347475867885462478926555","best_ask":"0.36","best_bid":"0.35","hash":"094add5553bf1ad7c19cc0cc932f8e8d6524d949","price":"0.41","side":"SELL","size":"26.9"}],"timestamp":"1785122716255"},"payload_hash":"6389d54b85c1427404cf436eedc6b01baab4a2db3acf42fa434bbf3973714b11","raw_frame":"{\"market\":\"0x717c0e8ccd4d5c7040185188fbae28be901ca589a11a94b1b38ca36a79eccfeb\", \"price_changes\":[{\"asset_id\":\"24254094493625419915756280046002869097156693848522361803041977572204227262166\", \"price\":\"0.59\", \"size\":\"26.9\", \"side\":\"BUY\", \"hash\":\"7b120ea17e1373de27dd456077b4fe4aa385724c\", \"best_bid\":\"0.64\", \"best_ask\":\"0.65\"}, {\"asset_id\":\"41448400836309843603620980831210604935021861034693225347475867885462478926555\", \"price\":\"0.41\", \"size\":\"26.9\", \"side\":\"SELL\", \"hash\":\"094add5553bf1ad7c19cc0cc932f8e8d6524d949\", \"best_bid\":\"0.35\", \"best_ask\":\"0.36\"}], \"timestamp\":\"1785122716255\", \"event_type\":\"price_change\"}","received_at":"2026-07-27T03:25:17.455530Z","schema_version":"clob-market-ws.price_change.v1","sequence":null,"server_hash":null,"server_timestamp":"1785122716255","session_id":"dd162b8dca5f43ff811d304e69a06123","source":"clob_market_ws"},"received_at":"2026-07-27T03:25:17.455530Z","record_id":"52138e8b437b635dec6c78eb269b45fc4ea2a45b756aa63f8a16141f39d4923e","schema_fingerprint":"4aa3821a28b0b7c2400bc59aba4bcc0a76e971dadd19610d3ad38c768e124dc7","schema_version":"edge-lab-recorder.raw.v1","sequence":null,"source":"clob_market_ws"}
{"event_at":"2026-07-27T03:25:16.282000Z","event_fingerprint":"5686d7bcc49f93e10d98b50dcad05c63916d89d2775cb7c03661830679d034b9","payload":{"connection_id":"c7dc2e4762f849c6b6f9306b6518dcab","event_at":"2026-07-27T03:25:16.282000Z","event_type":"price_change","frame_hash":"035036419d8e65164ae144dc8d7b9645687021bf02cf9106a6acf26aab8bb7d2","frame_index":0,"kind":"data","monotonic_ns":224700819631875,"payload":{"event_type":"price_change","market":"0x717c0e8ccd4d5c7040185188fbae28be901ca589a11a94b1b38ca36a79eccfeb","price_changes":[{"asset_id":"41448400836309843603620980831210604935021861034693225347475867885462478926555","best_ask":"0.36","best_bid":"0.35","hash":"3c60a2897b4bfcd239e7f45c5eb2d533f5306253","price":"0.3","side":"BUY","size":"22"},{"asset_id":"24254094493625419915756280046002869097156693848522361803041977572204227262166","best_ask":"0.65","best_bid":"0.64","hash":"c5b8fa35a4f4bbfea8be5adcd705d6e9e234847c","price":"0.7","side":"SELL","size":"22"}],"timestamp":"1785122716282"},"payload_hash":"92893ad758bae24239ce490103f5918b7b937ba66aebecfb3ee6d5f0c38850d1","raw_frame":"{\"market\":\"0x717c0e8ccd4d5c7040185188fbae28be901ca589a11a94b1b38ca36a79eccfeb\", \"price_changes\":[{\"asset_id\":\"41448400836309843603620980831210604935021861034693225347475867885462478926555\", \"price\":\"0.3\", \"size\":\"22\", \"side\":\"BUY\", \"hash\":\"3c60a2897b4bfcd239e7f45c5eb2d533f5306253\", \"best_bid\":\"0.35\", \"best_ask\":\"0.36\"}, {\"asset_id\":\"24254094493625419915756280046002869097156693848522361803041977572204227262166\", \"price\":\"0.7\", \"size\":\"22\", \"side\":\"SELL\", \"hash\":\"c5b8fa35a4f4bbfea8be5adcd705d6e9e234847c\", \"best_bid\":\"0.64\", \"best_ask\":\"0.65\"}], \"timestamp\":\"1785122716282\", \"event_type\":\"price_change\"}","received_at":"2026-07-27T03:25:17.460590Z","schema_version":"clob-market-ws.price_change.v1","sequence":null,"server_hash":null,"server_timestamp":"1785122716282","session_id":"dd162b8dca5f43ff811d304e69a06123","source":"clob_market_ws"},"received_at":"2026-07-27T03:25:17.460590Z","record_id":"2e58c5cf71c1ce4a12b5bc02bd2e0502271debfa36405ff43a1392f8e69bf644","schema_fingerprint":"4aa3821a28b0b7c2400bc59aba4bcc0a76e971dadd19610d3ad38c768e124dc7","schema_version":"edge-lab-recorder.raw.v1","sequence":null,"source":"clob_market_ws"}
{"event_at":"2026-07-27T03:25:16.283000Z","event_fingerprint":"bccf9242407f803c98da8707106e37a4b095eec80d3ca5f3091a77f098c06e27","payload":{"connection_id":"c7dc2e4762f849c6b6f9306b6518dcab","event_at":"2026-07-27T03:25:16.283000Z","event_type":"price_change","frame_hash":"996f250eaf485f3cfd035476e2abb480512b464c5caffa8573f6398e913266b6","frame_index":0,"kind":"data","monotonic_ns":224700826368041,"payload":{"event_type":"price_change","market":"0x717c0e8ccd4d5c7040185188fbae28be901ca589a11a94b1b38ca36a79eccfeb","price_changes":[{"asset_id":"24254094493625419915756280046002869097156693848522361803041977572204227262166","best_ask":"0.65","best_bid":"0.64","hash":"b8eb2ba62847602ec904219707ac922f01f6ea16","price":"0.6","side":"BUY","size":"31.96"},{"asset_id":"41448400836309843603620980831210604935021861034693225347475867885462478926555","best_ask":"0.36","best_bid":"0.35","hash":"fe1fa718b33d8cc96cf3cf394cdeb45699c2839c","price":"0.4","side":"SELL","size":"31.96"}],"timestamp":"1785122716283"},"payload_hash":"962ecab10e6f92030899cc67bff412e0ac0ce10ffcfbb910de7aabd419d657b3","raw_frame":"{\"market\":\"0x717c0e8ccd4d5c7040185188fbae28be901ca589a11a94b1b38ca36a79eccfeb\", \"price_changes\":[{\"asset_id\":\"24254094493625419915756280046002869097156693848522361803041977572204227262166\", \"price\":\"0.6\", \"size\":\"31.96\", \"side\":\"BUY\", \"hash\":\"b8eb2ba62847602ec904219707ac922f01f6ea16\", \"best_bid\":\"0.64\", \"best_ask\":\"0.65\"}, {\"asset_id\":\"41448400836309843603620980831210604935021861034693225347475867885462478926555\", \"price\":\"0.4\", \"size\":\"31.96\", \"side\":\"SELL\", \"hash\":\"fe1fa718b33d8cc96cf3cf394cdeb45699c2839c\", \"best_bid\":\"0.35\", \"best_ask\":\"0.36\"}], \"timestamp\":\"1785122716283\", \"event_type\":\"price_change\"}","received_at":"2026-07-27T03:25:17.467325Z","schema_version":"clob-market-ws.price_change.v1","sequence":null,"server_hash":null,"server_timestamp":"1785122716283","session_id":"dd162b8dca5f43ff811d304e69a06123","source":"clob_market_ws"},"received_at":"2026-07-27T03:25:17.467325Z","record_id":"8907125e47df40798fed663565dfda25fac0b4b3fba0d6afdb6cb5f96aeebe4e","schema_fingerprint":"4aa3821a28b0b7c2400bc59aba4bcc0a76e971dadd19610d3ad38c768e124dc7","schema_version":"edge-lab-recorder.raw.v1","sequence":null,"source":"clob_market_ws"}
{"event_at":"2026-07-27T03:25:16.306000Z","event_fingerprint":"c5bca099523990cc0ffdfd6f9fa317ec927b7e24ef08d3ecec9039da04286050","payload":{"connection_id":"c7dc2e4762f849c6b6f9306b6518dcab","event_at":"2026-07-27T03:25:16.306000Z","event_type":"price_change","frame_hash":"3f1eaf90bf30809a7c7a16ad10cc9f19f191b0fab0c11936d841c49d5b01affc","frame_index":0,"kind":"data","monotonic_ns":224700832029666,"payload":{"event_type":"price_change","market":"0x717c0e8ccd4d5c7040185188fbae28be901ca589a11a94b1b38ca36a79eccfeb","price_changes":[{"asset_id":"24254094493625419915756280046002869097156693848522361803041977572204227262166","best_ask":"0.65","best_bid":"0.64","hash":"e66191c01d38dc4114559875ca76c9bcaedf8647","price":"0.03","side":"BUY","size":"618.1"},{"asset_id":"41448400836309843603620980831210604935021861034693225347475867885462478926555","best_ask":"0.36","best_bid":"0.35","hash":"32ddc20b6838ea7f4e26653c59db229143daff2f","price":"0.97","side":"SELL","size":"618.1"}],"timestamp":"1785122716306"},"payload_hash":"c47fc8096e6a5d9bed8a6b08f309032d105ef7729e2667bea24ed14b42a64ef5","raw_frame":"{\"market\":\"0x717c0e8ccd4d5c7040185188fbae28be901ca589a11a94b1b38ca36a79eccfeb\", \"price_changes\":[{\"asset_id\":\"24254094493625419915756280046002869097156693848522361803041977572204227262166\", \"price\":\"0.03\", \"size\":\"618.1\", \"side\":\"BUY\", \"hash\":\"e66191c01d38dc4114559875ca76c9bcaedf8647\", \"best_bid\":\"0.64\", \"best_ask\":\"0.65\"}, {\"asset_id\":\"41448400836309843603620980831210604935021861034693225347475867885462478926555\", \"price\":\"0.97\", \"size\":\"618.1\", \"side\":\"SELL\", \"hash\":\"32ddc20b6838ea7f4e26653c59db229143daff2f\", \"best_bid\":\"0.35\", \"best_ask\":\"0.36\"}], \"timestamp\":\"1785122716306\", \"event_type\":\"price_change\"}","received_at":"2026-07-27T03:25:17.472987Z","schema_version":"clob-market-ws.price_change.v1","sequence":null,"server_hash":null,"server_timestamp":"1785122716306","session_id":"dd162b8dca5f43ff811d304e69a06123","source":"clob_market_ws"},"received_at":"2026-07-27T03:25:17.472987Z","record_id":"424a130d8eb3164512f2b3432b725d67a4fe37a9e5b6f0df2fcd968901dc068b","schema_fingerprint":"4aa3821a28b0b7c2400bc59aba4bcc0a76e971dadd19610d3ad38c768e124dc7","schema_version":"edge-lab-recorder.raw.v1","sequence":null,"source":"clob_market_ws"}
{"event_at":"2026-07-27T03:25:16.332000Z","event_fingerprint":"3fd13974ff5888265c2938fbcf1fd9d8f40fc969c85b1eae6d3dfb8049edd0fd","payload":{"connection_id":"c7dc2e4762f849c6b6f9306b6518dcab","event_at":"2026-07-27T03:25:16.332000Z","event_type":"best_bid_ask","frame_hash":"c28d26204001ed3af0528eab0b1d21c00a1da91e002cbebc4debe15dc68c0297","frame_index":0,"kind":"data","monotonic_ns":224700839426375,"payload":{"asset_id":"24254094493625419915756280046002869097156693848522361803041977572204227262166","best_ask":"0.65","best_bid":"0.64","event_type":"best_bid_ask","market":"0x717c0e8ccd4d5c7040185188fbae28be901ca589a11a94b1b38ca36a79eccfeb","spread":"0.01","timestamp":"1785122716332"},"payload_hash":"c9036f471465c8287ac3ae4728dea0835e50ef1b02b7134ae6265e7dfdb012eb","raw_frame":"{\"market\":\"0x717c0e8ccd4d5c7040185188fbae28be901ca589a11a94b1b38ca36a79eccfeb\", \"asset_id\":\"24254094493625419915756280046002869097156693848522361803041977572204227262166\", \"best_bid\":\"0.64\", \"best_ask\":\"0.65\", \"spread\":\"0.01\", \"timestamp\":\"1785122716332\", \"event_type\":\"best_bid_ask\"}","received_at":"2026-07-27T03:25:17.480385Z","schema_version":"clob-market-ws.best_bid_ask.v1","sequence":null,"server_hash":null,"server_timestamp":"1785122716332","session_id":"dd162b8dca5f43ff811d304e69a06123","source":"clob_market_ws"},"received_at":"2026-07-27T03:25:17.480385Z","record_id":"8fd4a4b6307484fec04ad9378d8963c79cf9dffab4fdd229143edbdc7b64041e","schema_fingerprint":"8488399f31b0337811b13b266be932db7062827c2470b78bd8e9e99bab51d17d","schema_version":"edge-lab-recorder.raw.v1","sequence":null,"source":"clob_market_ws"}
{"event_at":"2026-07-27T03:25:16.332000Z","event_fingerprint":"01dca4d96e67576700ab0fa83c62a0b1d20262f6a2a480663b13425c257310f0","payload":{"connection_id":"c7dc2e4762f849c6b6f9306b6518dcab","event_at":"2026-07-27T03:25:16.332000Z","event_type":"best_bid_ask","frame_hash":"774b276295abc112b218f58100fb973a444d49b7449b2c40d4c8222a5ef43ed5","frame_index":0,"kind":"data","monotonic_ns":224700844700791,"payload":{"asset_id":"41448400836309843603620980831210604935021861034693225347475867885462478926555","best_ask":"0.36","best_bid":"0.35","event_type":"best_bid_ask","market":"0x717c0e8ccd4d5c7040185188fbae28be901ca589a11a94b1b38ca36a79eccfeb","spread":"0.01","timestamp":"1785122716332"},"payload_hash":"c61d31d51d0710c6861d2d42d69c61d908e1cafada8037393db33933ef2d2d02","raw_frame":"{\"market\":\"0x717c0e8ccd4d5c7040185188fbae28be901ca589a11a94b1b38ca36a79eccfeb\", \"asset_id\":\"41448400836309843603620980831210604935021861034693225347475867885462478926555\", \"best_bid\":\"0.35\", \"best_ask\":\"0.36\", \"spread\":\"0.01\", \"timestamp\":\"1785122716332\", \"event_type\":\"best_bid_ask\"}","received_at":"2026-07-27T03:25:17.485657Z","schema_version":"clob-market-ws.best_bid_ask.v1","sequence":null,"server_hash":null,"server_timestamp":"1785122716332","session_id":"dd162b8dca5f43ff811d304e69a06123","source":"clob_market_ws"},"received_at":"2026-07-27T03:25:17.485657Z","record_id":"19232c2b1db75cb06828589a059601215a9dae27b58bee8829bbb410820b5f82","schema_fingerprint":"8488399f31b0337811b13b266be932db7062827c2470b78bd8e9e99bab51d17d","schema_version":"edge-lab-recorder.raw.v1","sequence":null,"source":"clob_market_ws"}
{"event_at":"2026-07-27T03:25:16.332000Z","event_fingerprint":"f94cd6a974aaa242b1528b24ebbfc804f2308f80fd41816242aa064a5f7002f7","payload":{"connection_id":"c7dc2e4762f849c6b6f9306b6518dcab","event_at":"2026-07-27T03:25:16.332000Z","event_type":"price_change","frame_hash":"a09365c977de5501645cd51dd394dcc37af4ffb4db55b5d9b685f30989392ce6","frame_index":0,"kind":"data","monotonic_ns":224700852966791,"payload":{"event_type":"price_change","market":"0x717c0e8ccd4d5c7040185188fbae28be901ca589a11a94b1b38ca36a79eccfeb","price_changes":[{"asset_id":"41448400836309843603620980831210604935021861034693225347475867885462478926555","best_ask":"0.36","best_bid":"0.35","hash":"630eccde8f95520d07ea438b5df2401be2ca94e7","price":"0.36","side":"SELL","size":"325.66"},{"asset_id":"24254094493625419915756280046002869097156693848522361803041977572204227262166","best_ask":"0.65","best_bid":"0.64","hash":"1a87bd1e42c993b4b0b08d2cbadeaf01d80eac63","price":"0.64","side":"BUY","size":"325.66"}],"timestamp":"1785122716332"},"payload_hash":"5765b5448d865ad0ced1345791d36189f2efeb1fe03284f56c70e659fe14b181","raw_frame":"{\"market\":\"0x717c0e8ccd4d5c7040185188fbae28be901ca589a11a94b1b38ca36a79eccfeb\", \"price_changes\":[{\"asset_id\":\"41448400836309843603620980831210604935021861034693225347475867885462478926555\", \"price\":\"0.36\", \"size\":\"325.66\", \"side\":\"SELL\", \"hash\":\"630eccde8f95520d07ea438b5df2401be2ca94e7\", \"best_bid\":\"0.35\", \"best_ask\":\"0.36\"}, {\"asset_id\":\"24254094493625419915756280046002869097156693848522361803041977572204227262166\", \"price\":\"0.64\", \"size\":\"325.66\", \"side\":\"BUY\", \"hash\":\"1a87bd1e42c993b4b0b08d2cbadeaf01d80eac63\", \"best_bid\":\"0.64\", \"best_ask\":\"0.65\"}], \"timestamp\":\"1785122716332\", \"event_type\":\"price_change\"}","received_at":"2026-07-27T03:25:17.493923Z","schema_version":"clob-market-ws.price_change.v1","sequence":null,"server_hash":null,"server_timestamp":"1785122716332","session_id":"dd162b8dca5f43ff811d304e69a06123","source":"clob_market_ws"},"received_at":"2026-07-27T03:25:17.493923Z","record_id":"cb8c80bea351f3ab13574cedc3d08d65a22ac18a19fe49bfabb81bb186451e35","schema_fingerprint":"4aa3821a28b0b7c2400bc59aba4bcc0a76e971dadd19610d3ad38c768e124dc7","schema_version":"edge-lab-recorder.raw.v1","sequence":null,"source":"clob_market_ws"}
