{"event_at":"2026-07-27T03:18:34.087000Z","event_fingerprint":"0f7016fa02580fe113f575d51d5307a3d0487967e8df799092962bbaf24e4bc3","payload":{"connection_id":"c7dc2e4762f849c6b6f9306b6518dcab","event_at":"2026-07-27T03:18:34.087000Z","event_type":"price_change","frame_hash":"0dd3734fab93321c4f0d45fa137b29d38593751a8a4b93de7b1aebdc25f3e677","frame_index":0,"kind":"data","monotonic_ns":224297330999291,"payload":{"event_type":"price_change","market":"0x717c0e8ccd4d5c7040185188fbae28be901ca589a11a94b1b38ca36a79eccfeb","price_changes":[{"asset_id":"41448400836309843603620980831210604935021861034693225347475867885462478926555","best_ask":"0.49","best_bid":"0.48","hash":"afae8c1106975fb48e89dbe6a1d81aeebf64fb54","price":"0.28","side":"BUY","size":"241.84"},{"asset_id":"24254094493625419915756280046002869097156693848522361803041977572204227262166","best_ask":"0.52","best_bid":"0.51","hash":"04bc8b30c03b279ff122c589bcb22db7c161e332","price":"0.72","side":"SELL","size":"241.84"}],"timestamp":"1785122314087"},"payload_hash":"53437e8d50eaa003633c6095c644396b6ed920d83794e9d7f261a0f7712249b2","raw_frame":"{\"market\":\"0x717c0e8ccd4d5c7040185188fbae28be901ca589a11a94b1b38ca36a79eccfeb\", \"price_changes\":[{\"asset_id\":\"41448400836309843603620980831210604935021861034693225347475867885462478926555\", \"price\":\"0.28\", \"size\":\"241.84\", \"side\":\"BUY\", \"hash\":\"afae8c1106975fb48e89dbe6a1d81aeebf64fb54\", \"best_bid\":\"0.48\", \"best_ask\":\"0.49\"}, {\"asset_id\":\"24254094493625419915756280046002869097156693848522361803041977572204227262166\", \"price\":\"0.72\", \"size\":\"241.84\", \"side\":\"SELL\", \"hash\":\"04bc8b30c03b279ff122c589bcb22db7c161e332\", \"best_bid\":\"0.51\", \"best_ask\":\"0.52\"}], \"timestamp\":\"1785122314087\", \"event_type\":\"price_change\"}","received_at":"2026-07-27T03:18:33.994337Z","schema_version":"clob-market-ws.price_change.v1","sequence":null,"server_hash":null,"server_timestamp":"1785122314087","session_id":"dd162b8dca5f43ff811d304e69a06123","source":"clob_market_ws"},"received_at":"2026-07-27T03:18:33.994337Z","record_id":"3d5f19ecaf76f3509da9c6b1e32d221552f32bdcb08643a207759d3db5546e5d","schema_fingerprint":"4aa3821a28b0b7c2400bc59aba4bcc0a76e971dadd19610d3ad38c768e124dc7","schema_version":"edge-lab-recorder.raw.v1","sequence":null,"source":"clob_market_ws"}
{"event_at":"2026-07-27T03:18:34.087000Z","event_fingerprint":"61d2dc0fae1ee43cbbe3ede69c7e9be85fedc068b46de955d2062a38919e0e04","payload":{"connection_id":"c7dc2e4762f849c6b6f9306b6518dcab","event_at":"2026-07-27T03:18:34.087000Z","event_type":"price_change","frame_hash":"668a34f475a4472525dfa031fb366070c2a0bef3aeaa850d33c246e6711e1f2e","frame_index":0,"kind":"data","monotonic_ns":224297333014791,"payload":{"event_type":"price_change","market":"0x717c0e8ccd4d5c7040185188fbae28be901ca589a11a94b1b38ca36a79eccfeb","price_changes":[{"asset_id":"41448400836309843603620980831210604935021861034693225347475867885462478926555","best_ask":"0.49","best_bid":"0.48","hash":"e8c33dfb20bd16ec8b867fc88d8671ef56cb0d3e","price":"0.28","side":"BUY","size":"126.9"},{"asset_id":"24254094493625419915756280046002869097156693848522361803041977572204227262166","best_ask":"0.52","best_bid":"0.51","hash":"80f1e9cd908eebb3b5f6db178f46316519b2b900","price":"0.72","side":"SELL","size":"126.9"}],"timestamp":"1785122314087"},"payload_hash":"268c96f5a4e8eeabc4e1f02a17b1a6782beaca049c9a23fc8d10af1a5e0a5015","raw_frame":"{\"market\":\"0x717c0e8ccd4d5c7040185188fbae28be901ca589a11a94b1b38ca36a79eccfeb\", \"price_changes\":[{\"asset_id\":\"41448400836309843603620980831210604935021861034693225347475867885462478926555\", \"price\":\"0.28\", \"size\":\"126.9\", \"side\":\"BUY\", \"hash\":\"e8c33dfb20bd16ec8b867fc88d8671ef56cb0d3e\", \"best_bid\":\"0.48\", \"best_ask\":\"0.49\"}, {\"asset_id\":\"24254094493625419915756280046002869097156693848522361803041977572204227262166\", \"price\":\"0.72\", \"size\":\"126.9\", \"side\":\"SELL\", \"hash\":\"80f1e9cd908eebb3b5f6db178f46316519b2b900\", \"best_bid\":\"0.51\", \"best_ask\":\"0.52\"}], \"timestamp\":\"1785122314087\", \"event_type\":\"price_change\"}","received_at":"2026-07-27T03:18:33.996347Z","schema_version":"clob-market-ws.price_change.v1","sequence":null,"server_hash":null,"server_timestamp":"1785122314087","session_id":"dd162b8dca5f43ff811d304e69a06123","source":"clob_market_ws"},"received_at":"2026-07-27T03:18:33.996347Z","record_id":"ee8076a3205414028d8b3c336c386e6fc4a237859f190066be8f597d2392ff1c","schema_fingerprint":"4aa3821a28b0b7c2400bc59aba4bcc0a76e971dadd19610d3ad38c768e124dc7","schema_version":"edge-lab-recorder.raw.v1","sequence":null,"source":"clob_market_ws"}
{"event_at":"2026-07-27T03:18:34.091000Z","event_fingerprint":"09d7695496b476ab74f58d59a36654e3a0dce7488257be797b3c1f40bce5a6a4","payload":{"connection_id":"c7dc2e4762f849c6b6f9306b6518dcab","event_at":"2026-07-27T03:18:34.091000Z","event_type":"price_change","frame_hash":"30ef85e6502868e0200e346fb3039dd1531d880f356ba070d3a4872408a2cfe8","frame_index":0,"kind":"data","monotonic_ns":224297334609541,"payload":{"event_type":"price_change","market":"0x717c0e8ccd4d5c7040185188fbae28be901ca589a11a94b1b38ca36a79eccfeb","price_changes":[{"asset_id":"24254094493625419915756280046002869097156693848522361803041977572204227262166","best_ask":"0.52","best_bid":"0.51","hash":"35a06fd013a3dda2d6b0683dee666f45dd7de3b9","price":"0.36","side":"BUY","size":"118"},{"asset_id":"41448400836309843603620980831210604935021861034693225347475867885462478926555","best_ask":"0.49","best_bid":"0.48","hash":"4cc4a37322384718d399b69def673f65939ccdc4","price":"0.64","side":"SELL","size":"118"}],"timestamp":"1785122314091"},"payload_hash":"91ec821f96ae0bb16543090e8784306680132d63c05475d51705d7711076d05b","raw_frame":"{\"market\":\"0x717c0e8ccd4d5c7040185188fbae28be901ca589a11a94b1b38ca36a79eccfeb\", \"price_changes\":[{\"asset_id\":\"24254094493625419915756280046002869097156693848522361803041977572204227262166\", \"price\":\"0.36\", \"size\":\"118\", \"side\":\"BUY\", \"hash\":\"35a06fd013a3dda2d6b0683dee666f45dd7de3b9\", \"best_bid\":\"0.51\", \"best_ask\":\"0.52\"}, {\"asset_id\":\"41448400836309843603620980831210604935021861034693225347475867885462478926555\", \"price\":\"0.64\", \"size\":\"118\", \"side\":\"SELL\", \"hash\":\"4cc4a37322384718d399b69def673f65939ccdc4\", \"best_bid\":\"0.48\", \"best_ask\":\"0.49\"}], \"timestamp\":\"1785122314091\", \"event_type\":\"price_change\"}","received_at":"2026-07-27T03:18:33.997946Z","schema_version":"clob-market-ws.price_change.v1","sequence":null,"server_hash":null,"server_timestamp":"1785122314091","session_id":"dd162b8dca5f43ff811d304e69a06123","source":"clob_market_ws"},"received_at":"2026-07-27T03:18:33.997946Z","record_id":"bcd32f9a9fb9a3d21e6123e4b3b19cf8f2d1737bdd973277d2bdbfbcb834fe98","schema_fingerprint":"4aa3821a28b0b7c2400bc59aba4bcc0a76e971dadd19610d3ad38c768e124dc7","schema_version":"edge-lab-recorder.raw.v1","sequence":null,"source":"clob_market_ws"}
{"event_at":"2026-07-27T03:18:34.093000Z","event_fingerprint":"3c48e4da4aff62836584fb79272b61b068247eb2e16b74bf0c0c39a5bf8fa2a3","payload":{"connection_id":"c7dc2e4762f849c6b6f9306b6518dcab","event_at":"2026-07-27T03:18:34.093000Z","event_type":"price_change","frame_hash":"db0d785cd9a85ea07670a276ee71fc4bfd60a8feff466f5d1c39fde798cb2111","frame_index":0,"kind":"data","monotonic_ns":224297336089625,"payload":{"event_type":"price_change","market":"0x717c0e8ccd4d5c7040185188fbae28be901ca589a11a94b1b38ca36a79eccfeb","price_changes":[{"asset_id":"41448400836309843603620980831210604935021861034693225347475867885462478926555","best_ask":"0.49","best_bid":"0.48","hash":"457d539d264e43f8d5026a8e5764dac19ea0ea93","price":"0.01","side":"BUY","size":"7703.02"},{"asset_id":"24254094493625419915756280046002869097156693848522361803041977572204227262166","best_ask":"0.52","best_bid":"0.51","hash":"1a9d1f8a217185d4b240d7814e6d5de4d755ba5b","price":"0.99","side":"SELL","size":"7703.02"}],"timestamp":"1785122314093"},"payload_hash":"7f6395f807fe2fb26036311dbae28af7429e183d486604d97ed785bca6bd1623","raw_frame":"{\"market\":\"0x717c0e8ccd4d5c7040185188fbae28be901ca589a11a94b1b38ca36a79eccfeb\", \"price_changes\":[{\"asset_id\":\"41448400836309843603620980831210604935021861034693225347475867885462478926555\", \"price\":\"0.01\", \"size\":\"7703.02\", \"side\":\"BUY\", \"hash\":\"457d539d264e43f8d5026a8e5764dac19ea0ea93\", \"best_bid\":\"0.48\", \"best_ask\":\"0.49\"}, {\"asset_id\":\"24254094493625419915756280046002869097156693848522361803041977572204227262166\", \"price\":\"0.99\", \"size\":\"7703.02\", \"side\":\"SELL\", \"hash\":\"1a9d1f8a217185d4b240d7814e6d5de4d755ba5b\", \"best_bid\":\"0.51\", \"best_ask\":\"0.52\"}], \"timestamp\":\"1785122314093\", \"event_type\":\"price_change\"}","received_at":"2026-07-27T03:18:33.999426Z","schema_version":"clob-market-ws.price_change.v1","sequence":null,"server_hash":null,"server_timestamp":"1785122314093","session_id":"dd162b8dca5f43ff811d304e69a06123","source":"clob_market_ws"},"received_at":"2026-07-27T03:18:33.999426Z","record_id":"692e53e6149686ca45aa2ebb3a8a40da65281742bff6fbd9f3f515a07d8d5011","schema_fingerprint":"4aa3821a28b0b7c2400bc59aba4bcc0a76e971dadd19610d3ad38c768e124dc7","schema_version":"edge-lab-recorder.raw.v1","sequence":null,"source":"clob_market_ws"}
{"event_at":"2026-07-27T03:18:34.185000Z","event_fingerprint":"ef93f7a051f47a91c920b274c69fbfbff7cd44fe3e4863330ac8cf7d9ddf0bea","payload":{"connection_id":"c7dc2e4762f849c6b6f9306b6518dcab","event_at":"2026-07-27T03:18:34.185000Z","event_type":"price_change","frame_hash":"e15d41d5f2b88ad23ca068ecc20322ef19b7f869e76dc780833dd78dd24335c5","frame_index":0,"kind":"data","monotonic_ns":224297419710833,"payload":{"event_type":"price_change","market":"0x717c0e8ccd4d5c7040185188fbae28be901ca589a11a94b1b38ca36a79eccfeb","price_changes":[{"asset_id":"41448400836309843603620980831210604935021861034693225347475867885462478926555","best_ask":"0.49","best_bid":"0.48","hash":"ac5fbea1037d07bbcc15975b02bd3726ab60405d","price":"0.44","side":"BUY","size":"14.6"},{"asset_id":"24254094493625419915756280046002869097156693848522361803041977572204227262166","best_ask":"0.52","best_bid":"0.51","hash":"8fcf3eb57a2ecb142b8072cd9ec40cfb101ad967","price":"0.56","side":"SELL","size":"14.6"}],"timestamp":"1785122314185"},"payload_hash":"57089ee2feca1237f524788d58eeed01da2e1709b425d1715ec4e4f1f3854d52","raw_frame":"{\"market\":\"0x717c0e8ccd4d5c7040185188fbae28be901ca589a11a94b1b38ca36a79eccfeb\", \"price_changes\":[{\"asset_id\":\"41448400836309843603620980831210604935021861034693225347475867885462478926555\", \"price\":\"0.44\", \"size\":\"14.6\", \"side\":\"BUY\", \"hash\":\"ac5fbea1037d07bbcc15975b02bd3726ab60405d\", \"best_bid\":\"0.48\", \"best_ask\":\"0.49\"}, {\"asset_id\":\"24254094493625419915756280046002869097156693848522361803041977572204227262166\", \"price\":\"0.56\", \"size\":\"14.6\", \"side\":\"SELL\", \"hash\":\"8fcf3eb57a2ecb142b8072cd9ec40cfb101ad967\", \"best_bid\":\"0.51\", \"best_ask\":\"0.52\"}], \"timestamp\":\"1785122314185\", \"event_type\":\"price_change\"}","received_at":"2026-07-27T03:18:34.083046Z","schema_version":"clob-market-ws.price_change.v1","sequence":null,"server_hash":null,"server_timestamp":"1785122314185","session_id":"dd162b8dca5f43ff811d304e69a06123","source":"clob_market_ws"},"received_at":"2026-07-27T03:18:34.083046Z","record_id":"7197f729e3ac09ddbb129b0265e66e30c0f4d3f56e6521a8306ab1b0ca87afe7","schema_fingerprint":"4aa3821a28b0b7c2400bc59aba4bcc0a76e971dadd19610d3ad38c768e124dc7","schema_version":"edge-lab-recorder.raw.v1","sequence":null,"source":"clob_market_ws"}
{"event_at":"2026-07-27T03:18:34.185000Z","event_fingerprint":"c03d6066462fdb49e2cae339fcbe472a015f72b1382662f75eecda6c6686a098","payload":{"connection_id":"c7dc2e4762f849c6b6f9306b6518dcab","event_at":"2026-07-27T03:18:34.185000Z","event_type":"price_change","frame_hash":"e4c69ce043c1d29b2a8168334603d4a0917a4931252d62025a8612aa0109c029","frame_index":0,"kind":"data","monotonic_ns":224297420630041,"payload":{"event_type":"price_change","market":"0x717c0e8ccd4d5c7040185188fbae28be901ca589a11a94b1b38ca36a79eccfeb","price_changes":[{"asset_id":"24254094493625419915756280046002869097156693848522361803041977572204227262166","best_ask":"0.52","best_bid":"0.51","hash":"8fcf3eb57a2ecb142b8072cd9ec40cfb101ad967","price":"0.5","side":"BUY","size":"63.22"},{"asset_id":"41448400836309843603620980831210604935021861034693225347475867885462478926555","best_ask":"0.49","best_bid":"0.48","hash":"ac5fbea1037d07bbcc15975b02bd3726ab60405d","price":"0.5","side":"SELL","size":"63.22"}],"timestamp":"1785122314185"},"payload_hash":"5ad5a2886c597c93242c5b68f976920d118d04aeafef30aa0254417725044aa8","raw_frame":"{\"market\":\"0x717c0e8ccd4d5c7040185188fbae28be901ca589a11a94b1b38ca36a79eccfeb\", \"price_changes\":[{\"asset_id\":\"24254094493625419915756280046002869097156693848522361803041977572204227262166\", \"price\":\"0.5\", \"size\":\"63.22\", \"side\":\"BUY\", \"hash\":\"8fcf3eb57a2ecb142b8072cd9ec40cfb101ad967\", \"best_bid\":\"0.51\", \"best_ask\":\"0.52\"}, {\"asset_id\":\"41448400836309843603620980831210604935021861034693225347475867885462478926555\", \"price\":\"0.5\", \"size\":\"63.22\", \"side\":\"SELL\", \"hash\":\"ac5fbea1037d07bbcc15975b02bd3726ab60405d\", \"best_bid\":\"0.48\", \"best_ask\":\"0.49\"}], \"timestamp\":\"1785122314185\", \"event_type\":\"price_change\"}","received_at":"2026-07-27T03:18:34.083968Z","schema_version":"clob-market-ws.price_change.v1","sequence":null,"server_hash":null,"server_timestamp":"1785122314185","session_id":"dd162b8dca5f43ff811d304e69a06123","source":"clob_market_ws"},"received_at":"2026-07-27T03:18:34.083968Z","record_id":"755d4d7afe5c69b24727d3d42875d1c0c53be4f5d91a5fec9e3cd75a30d61057","schema_fingerprint":"4aa3821a28b0b7c2400bc59aba4bcc0a76e971dadd19610d3ad38c768e124dc7","schema_version":"edge-lab-recorder.raw.v1","sequence":null,"source":"clob_market_ws"}
{"event_at":"2026-07-27T03:18:34.196000Z","event_fingerprint":"7303100d6208643ca23aa87e259f4d2ac9fde623e0cc709e8cc0044ca4217173","payload":{"connection_id":"c7dc2e4762f849c6b6f9306b6518dcab","event_at":"2026-07-27T03:18:34.196000Z","event_type":"price_change","frame_hash":"c862fdf317d1fa84e5be70f70abebf0235705805ffbf3d2ddc8936628078ddbc","frame_index":0,"kind":"data","monotonic_ns":224297432555583,"payload":{"event_type":"price_change","market":"0x717c0e8ccd4d5c7040185188fbae28be901ca589a11a94b1b38ca36a79eccfeb","price_changes":[{"asset_id":"24254094493625419915756280046002869097156693848522361803041977572204227262166","best_ask":"0.52","best_bid":"0.51","hash":"7fda631da7db140a09f9a073b2e035bd43465730","price":"0.49","side":"BUY","size":"108.24"},{"asset_id":"41448400836309843603620980831210604935021861034693225347475867885462478926555","best_ask":"0.49","best_bid":"0.48","hash":"ac0f1037c83c57e71bb9ed730fa0626dc5a86d10","price":"0.51","side":"SELL","size":"108.24"}],"timestamp":"1785122314196"},"payload_hash":"39dad06c50bbbb8b5eab829f4a44694276c2c2ee52747ff36ade836690dee525","raw_frame":"{\"market\":\"0x717c0e8ccd4d5c7040185188fbae28be901ca589a11a94b1b38ca36a79eccfeb\", \"price_changes\":[{\"asset_id\":\"24254094493625419915756280046002869097156693848522361803041977572204227262166\", \"price\":\"0.49\", \"size\":\"108.24\", \"side\":\"BUY\", \"hash\":\"7fda631da7db140a09f9a073b2e035bd43465730\", \"best_bid\":\"0.51\", \"best_ask\":\"0.52\"}, {\"asset_id\":\"41448400836309843603620980831210604935021861034693225347475867885462478926555\", \"price\":\"0.51\", \"size\":\"108.24\", \"side\":\"SELL\", \"hash\":\"ac0f1037c83c57e71bb9ed730fa0626dc5a86d10\", \"best_bid\":\"0.48\", \"best_ask\":\"0.49\"}], \"timestamp\":\"1785122314196\", \"event_type\":\"price_change\"}","received_at":"2026-07-27T03:18:34.095886Z","schema_version":"clob-market-ws.price_change.v1","sequence":null,"server_hash":null,"server_timestamp":"1785122314196","session_id":"dd162b8dca5f43ff811d304e69a06123","source":"clob_market_ws"},"received_at":"2026-07-27T03:18:34.095886Z","record_id":"5fdb920a9a6d96fefa6434d76eee33a67124bf54fe8dc726e6931993d49d284c","schema_fingerprint":"4aa3821a28b0b7c2400bc59aba4bcc0a76e971dadd19610d3ad38c768e124dc7","schema_version":"edge-lab-recorder.raw.v1","sequence":null,"source":"clob_market_ws"}
{"event_at":"2026-07-27T03:18:34.198000Z","event_fingerprint":"34f66dc43b26472684358298b7adf47a6560c4e8934425af359c8640c83cabd5","payload":{"connection_id":"c7dc2e4762f849c6b6f9306b6518dcab","event_at":"2026-07-27T03:18:34.198000Z","event_type":"price_change","frame_hash":"c63fa5e8db889ec798af28a6b1101607df56b3adabc36f273dd4ee8cc0a84e01","frame_index":0,"kind":"data","monotonic_ns":224297434137250,"payload":{"event_type":"price_change","market":"0x717c0e8ccd4d5c7040185188fbae28be901ca589a11a94b1b38ca36a79eccfeb","price_changes":[{"asset_id":"24254094493625419915756280046002869097156693848522361803041977572204227262166","best_ask":"0.52","best_bid":"0.51","hash":"27069fb243d62cceaef79da103fb4647cbce8154","price":"0.47","side":"BUY","size":"12.06"},{"asset_id":"41448400836309843603620980831210604935021861034693225347475867885462478926555","best_ask":"0.49","best_bid":"0.48","hash":"caefb492f544c8eaac9a586466d530002b460bb8","price":"0.53","side":"SELL","size":"12.06"}],"timestamp":"1785122314198"},"payload_hash":"dbf1438afeee448368fb02569020b719a8aa539b4fda39f9dc05b7b82fa9c049","raw_frame":"{\"market\":\"0x717c0e8ccd4d5c7040185188fbae28be901ca589a11a94b1b38ca36a79eccfeb\", \"price_changes\":[{\"asset_id\":\"24254094493625419915756280046002869097156693848522361803041977572204227262166\", \"price\":\"0.47\", \"size\":\"12.06\", \"side\":\"BUY\", \"hash\":\"27069fb243d62cceaef79da103fb4647cbce8154\", \"best_bid\":\"0.51\", \"best_ask\":\"0.52\"}, {\"asset_id\":\"41448400836309843603620980831210604935021861034693225347475867885462478926555\", \"price\":\"0.53\", \"size\":\"12.06\", \"side\":\"SELL\", \"hash\":\"caefb492f544c8eaac9a586466d530002b460bb8\", \"best_bid\":\"0.48\", \"best_ask\":\"0.49\"}], \"timestamp\":\"1785122314198\", \"event_type\":\"price_change\"}","received_at":"2026-07-27T03:18:34.097470Z","schema_version":"clob-market-ws.price_change.v1","sequence":null,"server_hash":null,"server_timestamp":"1785122314198","session_id":"dd162b8dca5f43ff811d304e69a06123","source":"clob_market_ws"},"received_at":"2026-07-27T03:18:34.097470Z","record_id":"50ff679c116a9e90f1468f7db2767f44d30ad8fb26b3c2cd795d283352ef20e3","schema_fingerprint":"4aa3821a28b0b7c2400bc59aba4bcc0a76e971dadd19610d3ad38c768e124dc7","schema_version":"edge-lab-recorder.raw.v1","sequence":null,"source":"clob_market_ws"}
{"event_at":"2026-07-27T03:18:34.199000Z","event_fingerprint":"a4fcc70c3648774337158b2393e85d74b59058ef2a1a2de25f77acf460520b62","payload":{"connection_id":"c7dc2e4762f849c6b6f9306b6518dcab","event_at":"2026-07-27T03:18:34.199000Z","event_type":"price_change","frame_hash":"4c4022967bf92870285e32a94074b0ad29ff77c8cf983b1b7f01823de18c4ccd","frame_index":0,"kind":"data","monotonic_ns":224297435711125,"payload":{"event_type":"price_change","market":"0x717c0e8ccd4d5c7040185188fbae28be901ca589a11a94b1b38ca36a79eccfeb","price_changes":[{"asset_id":"24254094493625419915756280046002869097156693848522361803041977572204227262166","best_ask":"0.52","best_bid":"0.51","hash":"4621dd40084cc4fa448ef4be64f438be1a883bb9","price":"0.5","side":"BUY","size":"72.22"},{"asset_id":"41448400836309843603620980831210604935021861034693225347475867885462478926555","best_ask":"0.49","best_bid":"0.48","hash":"afd1ff733048084b8d42786e378ed9aebe7972ab","price":"0.5","side":"SELL","size":"72.22"}],"timestamp":"1785122314199"},"payload_hash":"1d9e93c4daa77b607e66aac3cfd964bcb05739d99755903749a0ccb03fba16bf","raw_frame":"{\"market\":\"0x717c0e8ccd4d5c7040185188fbae28be901ca589a11a94b1b38ca36a79eccfeb\", \"price_changes\":[{\"asset_id\":\"24254094493625419915756280046002869097156693848522361803041977572204227262166\", \"price\":\"0.5\", \"size\":\"72.22\", \"side\":\"BUY\", \"hash\":\"4621dd40084cc4fa448ef4be64f438be1a883bb9\", \"best_bid\":\"0.51\", \"best_ask\":\"0.52\"}, {\"asset_id\":\"41448400836309843603620980831210604935021861034693225347475867885462478926555\", \"price\":\"0.5\", \"size\":\"72.22\", \"side\":\"SELL\", \"hash\":\"afd1ff733048084b8d42786e378ed9aebe7972ab\", \"best_bid\":\"0.48\", \"best_ask\":\"0.49\"}], \"timestamp\":\"1785122314199\", \"event_type\":\"price_change\"}","received_at":"2026-07-27T03:18:34.099043Z","schema_version":"clob-market-ws.price_change.v1","sequence":null,"server_hash":null,"server_timestamp":"1785122314199","session_id":"dd162b8dca5f43ff811d304e69a06123","source":"clob_market_ws"},"received_at":"2026-07-27T03:18:34.099043Z","record_id":"6f667e53645bb39604a5a5df17f5d97a4a1de212d9a78b49c7b0f013713c2acc","schema_fingerprint":"4aa3821a28b0b7c2400bc59aba4bcc0a76e971dadd19610d3ad38c768e124dc7","schema_version":"edge-lab-recorder.raw.v1","sequence":null,"source":"clob_market_ws"}
{"event_at":"2026-07-27T03:18:34.200000Z","event_fingerprint":"2ceeed24e5885012f333104c4cc2a4713ea0e26a99a08fd74a813451e50e8dbd","payload":{"connection_id":"c7dc2e4762f849c6b6f9306b6518dcab","event_at":"2026-07-27T03:18:34.200000Z","event_type":"price_change","frame_hash":"5fdccc8a9c181336d59c18e460e614da0fd5c167ab8130b54d26dd14498f4a06","frame_index":0,"kind":"data","monotonic_ns":224297437431958,"payload":{"event_type":"price_change","market":"0x717c0e8ccd4d5c7040185188fbae28be901ca589a11a94b1b38ca36a79eccfeb","price_changes":[{"asset_id":"24254094493625419915756280046002869097156693848522361803041977572204227262166","best_ask":"0.52","best_bid":"0.51","hash":"7a9e3b99dcb258994155dcc5f663e72ea7d5e11d","price":"0.48","side":"BUY","size":"287.01"},{"asset_id":"41448400836309843603620980831210604935021861034693225347475867885462478926555","best_ask":"0.49","best_bid":"0.48","hash":"dcb1cf6c6a10f4ccb13ecbd7d9306342fc06e5e7","price":"0.52","side":"SELL","size":"287.01"}],"timestamp":"1785122314200"},"payload_hash":"593204dbe35c5b3d7470a6cf6757b505340fff5478880d4bc46bb4066bb1ced6","raw_frame":"{\"market\":\"0x717c0e8ccd4d5c7040185188fbae28be901ca589a11a94b1b38ca36a79eccfeb\", \"price_changes\":[{\"asset_id\":\"24254094493625419915756280046002869097156693848522361803041977572204227262166\", \"price\":\"0.48\", \"size\":\"287.01\", \"side\":\"BUY\", \"hash\":\"7a9e3b99dcb258994155dcc5f663e72ea7d5e11d\", \"best_bid\":\"0.51\", \"best_ask\":\"0.52\"}, {\"asset_id\":\"41448400836309843603620980831210604935021861034693225347475867885462478926555\", \"price\":\"0.52\", \"size\":\"287.01\", \"side\":\"SELL\", \"hash\":\"dcb1cf6c6a10f4ccb13ecbd7d9306342fc06e5e7\", \"best_bid\":\"0.48\", \"best_ask\":\"0.49\"}], \"timestamp\":\"1785122314200\", \"event_type\":\"price_change\"}","received_at":"2026-07-27T03:18:34.100766Z","schema_version":"clob-market-ws.price_change.v1","sequence":null,"server_hash":null,"server_timestamp":"1785122314200","session_id":"dd162b8dca5f43ff811d304e69a06123","source":"clob_market_ws"},"received_at":"2026-07-27T03:18:34.100766Z","record_id":"68b551f0249453a42432fee3986b4b4982033dbd1c399cc0bf14c94ca597e219","schema_fingerprint":"4aa3821a28b0b7c2400bc59aba4bcc0a76e971dadd19610d3ad38c768e124dc7","schema_version":"edge-lab-recorder.raw.v1","sequence":null,"source":"clob_market_ws"}
{"event_at":"2026-07-27T03:18:34.201000Z","event_fingerprint":"7055cf9a6ae9e3e5629a902c6cf98876ea0403c4bfdcfe21d0c296b2b13c0989","payload":{"connection_id":"c7dc2e4762f849c6b6f9306b6518dcab","event_at":"2026-07-27T03:18:34.201000Z","event_type":"price_change","frame_hash":"088ff144fcc1ec83ba3f5fbf861503b4d2a278441b68f882800f640ef4a36a69","frame_index":0,"kind":"data","monotonic_ns":224297438943708,"payload":{"event_type":"price_change","market":"0x717c0e8ccd4d5c7040185188fbae28be901ca589a11a94b1b38ca36a79eccfeb","price_changes":[{"asset_id":"24254094493625419915756280046002869097156693848522361803041977572204227262166","best_ask":"0.52","best_bid":"0.51","hash":"1e91a625cef2b7119dc4190e2f3946ce4c8ca66a","price":"0.46","side":"BUY","size":"121"},{"asset_id":"41448400836309843603620980831210604935021861034693225347475867885462478926555","best_ask":"0.49","best_bid":"0.48","hash":"c27ed6f42c13991dd7fe860f2507a6ddae6730fa","price":"0.54","side":"SELL","size":"121"}],"timestamp":"1785122314201"},"payload_hash":"a6e9350268626b4e0b4d41a1968a88cee140fe6d0fe14e1696f378b706c9c1dc","raw_frame":"{\"market\":\"0x717c0e8ccd4d5c7040185188fbae28be901ca589a11a94b1b38ca36a79eccfeb\", \"price_changes\":[{\"asset_id\":\"24254094493625419915756280046002869097156693848522361803041977572204227262166\", \"price\":\"0.46\", \"size\":\"121\", \"side\":\"BUY\", \"hash\":\"1e91a625cef2b7119dc4190e2f3946ce4c8ca66a\", \"best_bid\":\"0.51\", \"best_ask\":\"0.52\"}, {\"asset_id\":\"41448400836309843603620980831210604935021861034693225347475867885462478926555\", \"price\":\"0.54\", \"size\":\"121\", \"side\":\"SELL\", \"hash\":\"c27ed6f42c13991dd7fe860f2507a6ddae6730fa\", \"best_bid\":\"0.48\", \"best_ask\":\"0.49\"}], \"timestamp\":\"1785122314201\", \"event_type\":\"price_change\"}","received_at":"2026-07-27T03:18:34.102278Z","schema_version":"clob-market-ws.price_change.v1","sequence":null,"server_hash":null,"server_timestamp":"1785122314201","session_id":"dd162b8dca5f43ff811d304e69a06123","source":"clob_market_ws"},"received_at":"2026-07-27T03:18:34.102278Z","record_id":"8c908a57a74414deb3efc7e347099c56aca4f804e00d2f6cffffd7667a850269","schema_fingerprint":"4aa3821a28b0b7c2400bc59aba4bcc0a76e971dadd19610d3ad38c768e124dc7","schema_version":"edge-lab-recorder.raw.v1","sequence":null,"source":"clob_market_ws"}
{"event_at":"2026-07-27T03:18:34.210000Z","event_fingerprint":"a92c512d13196e165feccac5f64550fc2d300b392f2a01020ddc504dad1ce1a1","payload":{"connection_id":"c7dc2e4762f849c6b6f9306b6518dcab","event_at":"2026-07-27T03:18:34.210000Z","event_type":"price_change","frame_hash":"3e70043ca5ff100d8593f4fbcfe8521cc916a39f0552ae57ae6c71d86fced0f9","frame_index":0,"kind":"data","monotonic_ns":224297445138458,"payload":{"event_type":"price_change","market":"0x717c0e8ccd4d5c7040185188fbae28be901ca589a11a94b1b38ca36a79eccfeb","price_changes":[{"asset_id":"24254094493625419915756280046002869097156693848522361803041977572204227262166","best_ask":"0.52","best_bid":"0.51","hash":"80db6484d26a735445888001d6674f3f6cfa7921","price":"0.03","side":"BUY","size":"618.1"},{"asset_id":"41448400836309843603620980831210604935021861034693225347475867885462478926555","best_ask":"0.49","best_bid":"0.48","hash":"5a982fd23f48faad7d0a325415166e643b2ccb39","price":"0.97","side":"SELL","size":"618.1"}],"timestamp":"1785122314210"},"payload_hash":"4e4c62c47f321efed4822838b58ee2825d1cf7c478bb0d043a32a9c41d922601","raw_frame":"{\"market\":\"0x717c0e8ccd4d5c7040185188fbae28be901ca589a11a94b1b38ca36a79eccfeb\", \"price_changes\":[{\"asset_id\":\"24254094493625419915756280046002869097156693848522361803041977572204227262166\", \"price\":\"0.03\", \"size\":\"618.1\", \"side\":\"BUY\", \"hash\":\"80db6484d26a735445888001d6674f3f6cfa7921\", \"best_bid\":\"0.51\", \"best_ask\":\"0.52\"}, {\"asset_id\":\"41448400836309843603620980831210604935021861034693225347475867885462478926555\", \"price\":\"0.97\", \"size\":\"618.1\", \"side\":\"SELL\", \"hash\":\"5a982fd23f48faad7d0a325415166e643b2ccb39\", \"best_bid\":\"0.48\", \"best_ask\":\"0.49\"}], \"timestamp\":\"1785122314210\", \"event_type\":\"price_change\"}","received_at":"2026-07-27T03:18:34.108469Z","schema_version":"clob-market-ws.price_change.v1","sequence":null,"server_hash":null,"server_timestamp":"1785122314210","session_id":"dd162b8dca5f43ff811d304e69a06123","source":"clob_market_ws"},"received_at":"2026-07-27T03:18:34.108469Z","record_id":"30677048cf96c1bd3aabdbb8dfdfc458eb54dc63c5616762e9ec11a66e8092f8","schema_fingerprint":"4aa3821a28b0b7c2400bc59aba4bcc0a76e971dadd19610d3ad38c768e124dc7","schema_version":"edge-lab-recorder.raw.v1","sequence":null,"source":"clob_market_ws"}
{"event_at":"2026-07-27T03:18:34.214000Z","event_fingerprint":"849f913c09c73b2515703de9e100ee1c01cbf7cf4d030206c0f27693410beb43","payload":{"connection_id":"c7dc2e4762f849c6b6f9306b6518dcab","event_at":"2026-07-27T03:18:34.214000Z","event_type":"price_change","frame_hash":"ce36812953a9744d91ed3f9a64cd1c14f367abce9b2cd86ac162d0fe88e61e34","frame_index":0,"kind":"data","monotonic_ns":224297449017958,"payload":{"event_type":"price_change","market":"0x717c0e8ccd4d5c7040185188fbae28be901ca589a11a94b1b38ca36a79eccfeb","price_changes":[{"asset_id":"24254094493625419915756280046002869097156693848522361803041977572204227262166","best_ask":"0.52","best_bid":"0.51","hash":"c00de11d8edd774d1c24ad65a74c12d2af52699a","price":"0.51","side":"BUY","size":"66.34"},{"asset_id":"41448400836309843603620980831210604935021861034693225347475867885462478926555","best_ask":"0.49","best_bid":"0.48","hash":"956369888fc412a91da4455e7c4b6baa8f01c8e1","price":"0.49","side":"SELL","size":"66.34"}],"timestamp":"1785122314214"},"payload_hash":"49b93471bffe2cfadbcd919e63be1948899f6494fb61c71d44080947580c8271","raw_frame":"{\"market\":\"0x717c0e8ccd4d5c7040185188fbae28be901ca589a11a94b1b38ca36a79eccfeb\", \"price_changes\":[{\"asset_id\":\"24254094493625419915756280046002869097156693848522361803041977572204227262166\", \"price\":\"0.51\", \"size\":\"66.34\", \"side\":\"BUY\", \"hash\":\"c00de11d8edd774d1c24ad65a74c12d2af52699a\", \"best_bid\":\"0.51\", \"best_ask\":\"0.52\"}, {\"asset_id\":\"41448400836309843603620980831210604935021861034693225347475867885462478926555\", \"price\":\"0.49\", \"size\":\"66.34\", \"side\":\"SELL\", \"hash\":\"956369888fc412a91da4455e7c4b6baa8f01c8e1\", \"best_bid\":\"0.48\", \"best_ask\":\"0.49\"}], \"timestamp\":\"1785122314214\", \"event_type\":\"price_change\"}","received_at":"2026-07-27T03:18:34.112350Z","schema_version":"clob-market-ws.price_change.v1","sequence":null,"server_hash":null,"server_timestamp":"1785122314214","session_id":"dd162b8dca5f43ff811d304e69a06123","source":"clob_market_ws"},"received_at":"2026-07-27T03:18:34.112350Z","record_id":"1cf1320197ca0b71c5551397c767ef17a04c22a359519390e0bc48b028d34da3","schema_fingerprint":"4aa3821a28b0b7c2400bc59aba4bcc0a76e971dadd19610d3ad38c768e124dc7","schema_version":"edge-lab-recorder.raw.v1","sequence":null,"source":"clob_market_ws"}
{"event_at":"2026-07-27T03:18:34.215000Z","event_fingerprint":"0988b34a71fbf71b63a2e14cb25e6312bd44e7ac4d0296cf158762e347d938b5","payload":{"connection_id":"c7dc2e4762f849c6b6f9306b6518dcab","event_at":"2026-07-27T03:18:34.215000Z","event_type":"price_change","frame_hash":"a0f1a80882e5d363d66fc349a93efeea8082cffd5ba3495959ce8acd7ac8479d","frame_index":0,"kind":"data","monotonic_ns":224297451339416,"payload":{"event_type":"price_change","market":"0x717c0e8ccd4d5c7040185188fbae28be901ca589a11a94b1b38ca36a79eccfeb","price_changes":[{"asset_id":"41448400836309843603620980831210604935021861034693225347475867885462478926555","best_ask":"0.49","best_bid":"0.48","hash":"1df786192264d88b3da08aa180ceb7cdf68945e2","price":"0.43","side":"BUY","size":"53.65"},{"asset_id":"24254094493625419915756280046002869097156693848522361803041977572204227262166","best_ask":"0.52","best_bid":"0.51","hash":"bb986788bd0c1116047748fe310b973e11212854","price":"0.57","side":"SELL","size":"53.65"}],"timestamp":"1785122314215"},"payload_hash":"fbd5fad162147cf5939019016a99145f4f863a6312639df6e1ffb85a1eaacdc3","raw_frame":"{\"market\":\"0x717c0e8ccd4d5c7040185188fbae28be901ca589a11a94b1b38ca36a79eccfeb\", \"price_changes\":[{\"asset_id\":\"41448400836309843603620980831210604935021861034693225347475867885462478926555\", \"price\":\"0.43\", \"size\":\"53.65\", \"side\":\"BUY\", \"hash\":\"1df786192264d88b3da08aa180ceb7cdf68945e2\", \"best_bid\":\"0.48\", \"best_ask\":\"0.49\"}, {\"asset_id\":\"24254094493625419915756280046002869097156693848522361803041977572204227262166\", \"price\":\"0.57\", \"size\":\"53.65\", \"side\":\"SELL\", \"hash\":\"bb986788bd0c1116047748fe310b973e11212854\", \"best_bid\":\"0.51\", \"best_ask\":\"0.52\"}], \"timestamp\":\"1785122314215\", \"event_type\":\"price_change\"}","received_at":"2026-07-27T03:18:34.114674Z","schema_version":"clob-market-ws.price_change.v1","sequence":null,"server_hash":null,"server_timestamp":"1785122314215","session_id":"dd162b8dca5f43ff811d304e69a06123","source":"clob_market_ws"},"received_at":"2026-07-27T03:18:34.114674Z","record_id":"87af8e01b72357b7d7363f70411285e07d568d08d92bb4cb3ee6b1551d76b0c0","schema_fingerprint":"4aa3821a28b0b7c2400bc59aba4bcc0a76e971dadd19610d3ad38c768e124dc7","schema_version":"edge-lab-recorder.raw.v1","sequence":null,"source":"clob_market_ws"}
{"event_at":"2026-07-27T03:18:34.319000Z","event_fingerprint":"ec2f7f5a45fb619972b3fe549ef338644c45448f9e9174c62e5923977a86ee51","payload":{"connection_id":"c7dc2e4762f849c6b6f9306b6518dcab","event_at":"2026-07-27T03:18:34.319000Z","event_type":"price_change","frame_hash":"1d29559f7bcfea853647402e2df6a2ba163dd3dfb4989d87be2091534f0563ca","frame_index":0,"kind":"data","monotonic_ns":224297553103375,"payload":{"event_type":"price_change","market":"0x717c0e8ccd4d5c7040185188fbae28be901ca589a11a94b1b38ca36a79eccfeb","price_changes":[{"asset_id":"24254094493625419915756280046002869097156693848522361803041977572204227262166","best_ask":"0.52","best_bid":"0.51","hash":"fa22c65082ec2295d9c3a9d42ff9da19af0a40c8","price":"0.03","side":"BUY","size":"613.1"},{"asset_id":"41448400836309843603620980831210604935021861034693225347475867885462478926555","best_ask":"0.49","best_bid":"0.48","hash":"ece3f119524d138e29bd9575c5047bc16be28626","price":"0.97","side":"SELL","size":"613.1"}],"timestamp":"1785122314319"},"payload_hash":"a4c2f3942b564ea21f8d3c9ee87e5920ef43577465c552301e427d68574a37fd","raw_frame":"{\"market\":\"0x717c0e8ccd4d5c7040185188fbae28be901ca589a11a94b1b38ca36a79eccfeb\", \"price_changes\":[{\"asset_id\":\"24254094493625419915756280046002869097156693848522361803041977572204227262166\", \"price\":\"0.03\", \"size\":\"613.1\", \"side\":\"BUY\", \"hash\":\"fa22c65082ec2295d9c3a9d42ff9da19af0a40c8\", \"best_bid\":\"0.51\", \"best_ask\":\"0.52\"}, {\"asset_id\":\"41448400836309843603620980831210604935021861034693225347475867885462478926555\", \"price\":\"0.97\", \"size\":\"613.1\", \"side\":\"SELL\", \"hash\":\"ece3f119524d138e29bd9575c5047bc16be28626\", \"best_bid\":\"0.48\", \"best_ask\":\"0.49\"}], \"timestamp\":\"1785122314319\", \"event_type\":\"price_change\"}","received_at":"2026-07-27T03:18:34.216434Z","schema_version":"clob-market-ws.price_change.v1","sequence":null,"server_hash":null,"server_timestamp":"1785122314319","session_id":"dd162b8dca5f43ff811d304e69a06123","source":"clob_market_ws"},"received_at":"2026-07-27T03:18:34.216434Z","record_id":"69aaf9f0eb7c91d4948b021a8cfacd9be5c9992e762f04d0735c87ecaeeb7733","schema_fingerprint":"4aa3821a28b0b7c2400bc59aba4bcc0a76e971dadd19610d3ad38c768e124dc7","schema_version":"edge-lab-recorder.raw.v1","sequence":null,"source":"clob_market_ws"}
{"event_at":"2026-07-27T03:18:34.332000Z","event_fingerprint":"7f95514021f84e4f3bfb9d4a9bca3817c853e677c24e9272280302217233c87a","payload":{"connection_id":"c7dc2e4762f849c6b6f9306b6518dcab","event_at":"2026-07-27T03:18:34.332000Z","event_type":"price_change","frame_hash":"67d846a67c155fd4dfe45bebc4d0436a889bb605893ca9aee8c26dbf9f9a3ae2","frame_index":0,"kind":"data","monotonic_ns":224297567407958,"payload":{"event_type":"price_change","market":"0x717c0e8ccd4d5c7040185188fbae28be901ca589a11a94b1b38ca36a79eccfeb","price_changes":[{"asset_id":"41448400836309843603620980831210604935021861034693225347475867885462478926555","best_ask":"0.49","best_bid":"0.48","hash":"700a89a336e4372aa4e368bd7b3239c6908d951e","price":"0.31","side":"BUY","size":"131"},{"asset_id":"24254094493625419915756280046002869097156693848522361803041977572204227262166","best_ask":"0.52","best_bid":"0.51","hash":"9ebeb4895058916f4835137e7dd83d5d7510710c","price":"0.69","side":"SELL","size":"131"}],"timestamp":"1785122314332"},"payload_hash":"79ae3369560fe5d69045bb1773f9749e9f2131a063fb396cccd9937ff1df1b42","raw_frame":"{\"market\":\"0x717c0e8ccd4d5c7040185188fbae28be901ca589a11a94b1b38ca36a79eccfeb\", \"price_changes\":[{\"asset_id\":\"41448400836309843603620980831210604935021861034693225347475867885462478926555\", \"price\":\"0.31\", \"size\":\"131\", \"side\":\"BUY\", \"hash\":\"700a89a336e4372aa4e368bd7b3239c6908d951e\", \"best_bid\":\"0.48\", \"best_ask\":\"0.49\"}, {\"asset_id\":\"24254094493625419915756280046002869097156693848522361803041977572204227262166\", \"price\":\"0.69\", \"size\":\"131\", \"side\":\"SELL\", \"hash\":\"9ebeb4895058916f4835137e7dd83d5d7510710c\", \"best_bid\":\"0.51\", \"best_ask\":\"0.52\"}], \"timestamp\":\"1785122314332\", \"event_type\":\"price_change\"}","received_at":"2026-07-27T03:18:34.230738Z","schema_version":"clob-market-ws.price_change.v1","sequence":null,"server_hash":null,"server_timestamp":"1785122314332","session_id":"dd162b8dca5f43ff811d304e69a06123","source":"clob_market_ws"},"received_at":"2026-07-27T03:18:34.230738Z","record_id":"da1d25cd3f05f896668a195edf81687551964cb976b6a3099cc05d8f3f4f4b84","schema_fingerprint":"4aa3821a28b0b7c2400bc59aba4bcc0a76e971dadd19610d3ad38c768e124dc7","schema_version":"edge-lab-recorder.raw.v1","sequence":null,"source":"clob_market_ws"}
{"event_at":"2026-07-27T03:18:34.333000Z","event_fingerprint":"5cdcd49062add9aa3df7a5c82f162bf9d6061d0b7e56956760d63015160d1f8e","payload":{"connection_id":"c7dc2e4762f849c6b6f9306b6518dcab","event_at":"2026-07-27T03:18:34.333000Z","event_type":"price_change","frame_hash":"dd66ac85d7c37b3f97a35796fbc4dc076ef9705b3e3d0916681ae2ceee079f8e","frame_index":0,"kind":"data","monotonic_ns":224297568950250,"payload":{"event_type":"price_change","market":"0x717c0e8ccd4d5c7040185188fbae28be901ca589a11a94b1b38ca36a79eccfeb","price_changes":[{"asset_id":"24254094493625419915756280046002869097156693848522361803041977572204227262166","best_ask":"0.52","best_bid":"0.51","hash":"430f609f38bc6b0394dade6fd341d1345db46028","price":"0.01","side":"BUY","size":"7713.02"},{"asset_id":"41448400836309843603620980831210604935021861034693225347475867885462478926555","best_ask":"0.49","best_bid":"0.48","hash":"015bdd8527c748e7753d42ca73e7ea5fb382e973","price":"0.99","side":"SELL","size":"7713.02"}],"timestamp":"1785122314333"},"payload_hash":"ea116303175aa51ed81cc119d0d4607d99a6870ef58020bc328dc8d8e38cb4a6","raw_frame":"{\"market\":\"0x717c0e8ccd4d5c7040185188fbae28be901ca589a11a94b1b38ca36a79eccfeb\", \"price_changes\":[{\"asset_id\":\"24254094493625419915756280046002869097156693848522361803041977572204227262166\", \"price\":\"0.01\", \"size\":\"7713.02\", \"side\":\"BUY\", \"hash\":\"430f609f38bc6b0394dade6fd341d1345db46028\", \"best_bid\":\"0.51\", \"best_ask\":\"0.52\"}, {\"asset_id\":\"41448400836309843603620980831210604935021861034693225347475867885462478926555\", \"price\":\"0.99\", \"size\":\"7713.02\", \"side\":\"SELL\", \"hash\":\"015bdd8527c748e7753d42ca73e7ea5fb382e973\", \"best_bid\":\"0.48\", \"best_ask\":\"0.49\"}], \"timestamp\":\"1785122314333\", \"event_type\":\"price_change\"}","received_at":"2026-07-27T03:18:34.232282Z","schema_version":"clob-market-ws.price_change.v1","sequence":null,"server_hash":null,"server_timestamp":"1785122314333","session_id":"dd162b8dca5f43ff811d304e69a06123","source":"clob_market_ws"},"received_at":"2026-07-27T03:18:34.232282Z","record_id":"0a77b045737b5c0e8b6817337e11142bfbaa2796a24b74540d94e5a4a4b8d68a","schema_fingerprint":"4aa3821a28b0b7c2400bc59aba4bcc0a76e971dadd19610d3ad38c768e124dc7","schema_version":"edge-lab-recorder.raw.v1","sequence":null,"source":"clob_market_ws"}
{"event_at":"2026-07-27T03:18:34.336000Z","event_fingerprint":"2709d11237de9fd2b94ffd9c7d2a7d2718a2d57cc57a441afb7c4e0fd57692c2","payload":{"connection_id":"c7dc2e4762f849c6b6f9306b6518dcab","event_at":"2026-07-27T03:18:34.336000Z","event_type":"price_change","frame_hash":"6ae0a2a5bb4d6a85d864c878332ce5cdce19d37d65fe94160fc13a2c710975e1","frame_index":0,"kind":"data","monotonic_ns":224297572078583,"payload":{"event_type":"price_change","market":"0x717c0e8ccd4d5c7040185188fbae28be901ca589a11a94b1b38ca36a79eccfeb","price_changes":[{"asset_id":"24254094493625419915756280046002869097156693848522361803041977572204227262166","best_ask":"0.52","best_bid":"0.51","hash":"4d14ac636a2eef22b7dfae2b4a84d25932fa01f1","price":"0.69","side":"SELL","size":"126"},{"asset_id":"41448400836309843603620980831210604935021861034693225347475867885462478926555","best_ask":"0.49","best_bid":"0.48","hash":"42a252202ab60741dacffcd18f8ea6527f5bc45f","price":"0.31","side":"BUY","size":"126"}],"timestamp":"1785122314336"},"payload_hash":"5dc11484374f1415471e7aa7ed2206db91d135168a914fda2777515bc10e02c2","raw_frame":"{\"market\":\"0x717c0e8ccd4d5c7040185188fbae28be901ca589a11a94b1b38ca36a79eccfeb\", \"price_changes\":[{\"asset_id\":\"24254094493625419915756280046002869097156693848522361803041977572204227262166\", \"price\":\"0.69\", \"size\":\"126\", \"side\":\"SELL\", \"hash\":\"4d14ac636a2eef22b7dfae2b4a84d25932fa01f1\", \"best_bid\":\"0.51\", \"best_ask\":\"0.52\"}, {\"asset_id\":\"41448400836309843603620980831210604935021861034693225347475867885462478926555\", \"price\":\"0.31\", \"size\":\"126\", \"side\":\"BUY\", \"hash\":\"42a252202ab60741dacffcd18f8ea6527f5bc45f\", \"best_bid\":\"0.48\", \"best_ask\":\"0.49\"}], \"timestamp\":\"1785122314336\", \"event_type\":\"price_change\"}","received_at":"2026-07-27T03:18:34.235411Z","schema_version":"clob-market-ws.price_change.v1","sequence":null,"server_hash":null,"server_timestamp":"1785122314336","session_id":"dd162b8dca5f43ff811d304e69a06123","source":"clob_market_ws"},"received_at":"2026-07-27T03:18:34.235411Z","record_id":"449dbd67d0134b769b790975c55b532e3b025a0db71095f973f1d1c4c0aaf672","schema_fingerprint":"4aa3821a28b0b7c2400bc59aba4bcc0a76e971dadd19610d3ad38c768e124dc7","schema_version":"edge-lab-recorder.raw.v1","sequence":null,"source":"clob_market_ws"}
{"event_at":"2026-07-27T03:18:34.357000Z","event_fingerprint":"123010779724004375e51f21463874a61672c5d6c0c492bcaedf5fc9f2e624ef","payload":{"connection_id":"c7dc2e4762f849c6b6f9306b6518dcab","event_at":"2026-07-27T03:18:34.357000Z","event_type":"price_change","frame_hash":"d02c43d31e539227aa58795280e403bc28c024102ef7ed1082cb2b3fa8418b21","frame_index":0,"kind":"data","monotonic_ns":224297593112041,"payload":{"event_type":"price_change","market":"0x717c0e8ccd4d5c7040185188fbae28be901ca589a11a94b1b38ca36a79eccfeb","price_changes":[{"asset_id":"24254094493625419915756280046002869097156693848522361803041977572204227262166","best_ask":"0.52","best_bid":"0.51","hash":"ba7d9f2c8f7408a74581d595d7e7d99346aed511","price":"0.01","side":"BUY","size":"7708.02"},{"asset_id":"41448400836309843603620980831210604935021861034693225347475867885462478926555","best_ask":"0.49","best_bid":"0.48","hash":"dd50671b7657ce781112dbcdf7509b5d84add01f","price":"0.99","side":"SELL","size":"7708.02"}],"timestamp":"1785122314357"},"payload_hash":"3d11e0a9835e2e754794bbfbfed7fa410b69f869cceff5876a2ee2bc25e4bc52","raw_frame":"{\"market\":\"0x717c0e8ccd4d5c7040185188fbae28be901ca589a11a94b1b38ca36a79eccfeb\", \"price_changes\":[{\"asset_id\":\"24254094493625419915756280046002869097156693848522361803041977572204227262166\", \"price\":\"0.01\", \"size\":\"7708.02\", \"side\":\"BUY\", \"hash\":\"ba7d9f2c8f7408a74581d595d7e7d99346aed511\", \"best_bid\":\"0.51\", \"best_ask\":\"0.52\"}, {\"asset_id\":\"41448400836309843603620980831210604935021861034693225347475867885462478926555\", \"price\":\"0.99\", \"size\":\"7708.02\", \"side\":\"SELL\", \"hash\":\"dd50671b7657ce781112dbcdf7509b5d84add01f\", \"best_bid\":\"0.48\", \"best_ask\":\"0.49\"}], \"timestamp\":\"1785122314357\", \"event_type\":\"price_change\"}","received_at":"2026-07-27T03:18:34.256441Z","schema_version":"clob-market-ws.price_change.v1","sequence":null,"server_hash":null,"server_timestamp":"1785122314357","session_id":"dd162b8dca5f43ff811d304e69a06123","source":"clob_market_ws"},"received_at":"2026-07-27T03:18:34.256441Z","record_id":"53287584f9b21ec798c831ade862230bb0305c5f4b060eb6cd3f20f2c9bbfa96","schema_fingerprint":"4aa3821a28b0b7c2400bc59aba4bcc0a76e971dadd19610d3ad38c768e124dc7","schema_version":"edge-lab-recorder.raw.v1","sequence":null,"source":"clob_market_ws"}
{"event_at":"2026-07-27T03:18:34.362000Z","event_fingerprint":"eaecd1575f69afaea5042db3f4c231b6e4c6ddbb57f6a8fede4a96434805a8a0","payload":{"connection_id":"c7dc2e4762f849c6b6f9306b6518dcab","event_at":"2026-07-27T03:18:34.362000Z","event_type":"price_change","frame_hash":"9d517a34d0e97273275069f1e3787d8e732491b3c0ba448491276beecc542d81","frame_index":0,"kind":"data","monotonic_ns":224297597158583,"payload":{"event_type":"price_change","market":"0x717c0e8ccd4d5c7040185188fbae28be901ca589a11a94b1b38ca36a79eccfeb","price_changes":[{"asset_id":"41448400836309843603620980831210604935021861034693225347475867885462478926555","best_ask":"0.49","best_bid":"0.48","hash":"68efdf0008c198b42cf8dd803e4a604be253d7cf","price":"0.3","side":"BUY","size":"131.3"},{"asset_id":"24254094493625419915756280046002869097156693848522361803041977572204227262166","best_ask":"0.52","best_bid":"0.51","hash":"8334925edaaf0cc7f2663bcedbf89899a663efc5","price":"0.7","side":"SELL","size":"131.3"}],"timestamp":"1785122314362"},"payload_hash":"0f6a5ccbd107be444d0c057af29614954063f97ebe079e2b196aa66203cfa7ac","raw_frame":"{\"market\":\"0x717c0e8ccd4d5c7040185188fbae28be901ca589a11a94b1b38ca36a79eccfeb\", \"price_changes\":[{\"asset_id\":\"41448400836309843603620980831210604935021861034693225347475867885462478926555\", \"price\":\"0.3\", \"size\":\"131.3\", \"side\":\"BUY\", \"hash\":\"68efdf0008c198b42cf8dd803e4a604be253d7cf\", \"best_bid\":\"0.48\", \"best_ask\":\"0.49\"}, {\"asset_id\":\"24254094493625419915756280046002869097156693848522361803041977572204227262166\", \"price\":\"0.7\", \"size\":\"131.3\", \"side\":\"SELL\", \"hash\":\"8334925edaaf0cc7f2663bcedbf89899a663efc5\", \"best_bid\":\"0.51\", \"best_ask\":\"0.52\"}], \"timestamp\":\"1785122314362\", \"event_type\":\"price_change\"}","received_at":"2026-07-27T03:18:34.260489Z","schema_version":"clob-market-ws.price_change.v1","sequence":null,"server_hash":null,"server_timestamp":"1785122314362","session_id":"dd162b8dca5f43ff811d304e69a06123","source":"clob_market_ws"},"received_at":"2026-07-27T03:18:34.260489Z","record_id":"f84b2ef78757e9e2b38e10b662f6455cbefc4afdab7cf533cd94802eb0c8c4a0","schema_fingerprint":"4aa3821a28b0b7c2400bc59aba4bcc0a76e971dadd19610d3ad38c768e124dc7","schema_version":"edge-lab-recorder.raw.v1","sequence":null,"source":"clob_market_ws"}
{"event_at":"2026-07-27T03:18:34.367000Z","event_fingerprint":"4ee34ee86d3b16f6fad314d6ca3e97f819093d9b0a1291c7294ee1afa569e1c9","payload":{"connection_id":"c7dc2e4762f849c6b6f9306b6518dcab","event_at":"2026-07-27T03:18:34.367000Z","event_type":"price_change","frame_hash":"b6add930ef5a83c2d0e8292a571bf91deef7a4bd4a8dd5de7fe9495adcb67a56","frame_index":0,"kind":"data","monotonic_ns":224297601376916,"payload":{"event_type":"price_change","market":"0x717c0e8ccd4d5c7040185188fbae28be901ca589a11a94b1b38ca36a79eccfeb","price_changes":[{"asset_id":"24254094493625419915756280046002869097156693848522361803041977572204227262166","best_ask":"0.52","best_bid":"0.51","hash":"3be10df16b85e6aa169d49b32bc6654627ec2c24","price":"0.46","side":"BUY","size":"115"},{"asset_id":"41448400836309843603620980831210604935021861034693225347475867885462478926555","best_ask":"0.49","best_bid":"0.48","hash":"3a1c2846d1b2c654195a216ddce5f943a34fb78d","price":"0.54","side":"SELL","size":"115"}],"timestamp":"1785122314367"},"payload_hash":"c56aa1070e093063e2492c58951b5e8680cf39b1ad64b62cf2cd656b4071813d","raw_frame":"{\"market\":\"0x717c0e8ccd4d5c7040185188fbae28be901ca589a11a94b1b38ca36a79eccfeb\", \"price_changes\":[{\"asset_id\":\"24254094493625419915756280046002869097156693848522361803041977572204227262166\", \"price\":\"0.46\", \"size\":\"115\", \"side\":\"BUY\", \"hash\":\"3be10df16b85e6aa169d49b32bc6654627ec2c24\", \"best_bid\":\"0.51\", \"best_ask\":\"0.52\"}, {\"asset_id\":\"41448400836309843603620980831210604935021861034693225347475867885462478926555\", \"price\":\"0.54\", \"size\":\"115\", \"side\":\"SELL\", \"hash\":\"3a1c2846d1b2c654195a216ddce5f943a34fb78d\", \"best_bid\":\"0.48\", \"best_ask\":\"0.49\"}], \"timestamp\":\"1785122314367\", \"event_type\":\"price_change\"}","received_at":"2026-07-27T03:18:34.264707Z","schema_version":"clob-market-ws.price_change.v1","sequence":null,"server_hash":null,"server_timestamp":"1785122314367","session_id":"dd162b8dca5f43ff811d304e69a06123","source":"clob_market_ws"},"received_at":"2026-07-27T03:18:34.264707Z","record_id":"148bde64d8d33d704918eba0986c5f754674d7bfcb6b58ddb2b541e491dc6370","schema_fingerprint":"4aa3821a28b0b7c2400bc59aba4bcc0a76e971dadd19610d3ad38c768e124dc7","schema_version":"edge-lab-recorder.raw.v1","sequence":null,"source":"clob_market_ws"}
{"event_at":"2026-07-27T03:18:34.369000Z","event_fingerprint":"cc4fec749a24dd87568bd9c6ca5686cf0ec864ff4551b8932dab87c4453ed36a","payload":{"connection_id":"c7dc2e4762f849c6b6f9306b6518dcab","event_at":"2026-07-27T03:18:34.369000Z","event_type":"price_change","frame_hash":"de9e8d71b6b2984ca506e0af6b8e359c6cca6242cadde0d9980e46d1d1b529e0","frame_index":0,"kind":"data","monotonic_ns":224297605693583,"payload":{"event_type":"price_change","market":"0x717c0e8ccd4d5c7040185188fbae28be901ca589a11a94b1b38ca36a79eccfeb","price_changes":[{"asset_id":"24254094493625419915756280046002869097156693848522361803041977572204227262166","best_ask":"0.52","best_bid":"0.51","hash":"44f33320e71bd4c8e81ac288e8adcd411983e342","price":"0.5","side":"BUY","size":"63.22"},{"asset_id":"41448400836309843603620980831210604935021861034693225347475867885462478926555","best_ask":"0.49","best_bid":"0.48","hash":"9b5b7dea0c706081077dd8f69fb91dce6e84f559","price":"0.5","side":"SELL","size":"63.22"}],"timestamp":"1785122314369"},"payload_hash":"d4f4c47acbb81464cbb1493a0af17ce81e070a74fb905d753afca5a9ad89cb65","raw_frame":"{\"market\":\"0x717c0e8ccd4d5c7040185188fbae28be901ca589a11a94b1b38ca36a79eccfeb\", \"price_changes\":[{\"asset_id\":\"24254094493625419915756280046002869097156693848522361803041977572204227262166\", \"price\":\"0.5\", \"size\":\"63.22\", \"side\":\"BUY\", \"hash\":\"44f33320e71bd4c8e81ac288e8adcd411983e342\", \"best_bid\":\"0.51\", \"best_ask\":\"0.52\"}, {\"asset_id\":\"41448400836309843603620980831210604935021861034693225347475867885462478926555\", \"price\":\"0.5\", \"size\":\"63.22\", \"side\":\"SELL\", \"hash\":\"9b5b7dea0c706081077dd8f69fb91dce6e84f559\", \"best_bid\":\"0.48\", \"best_ask\":\"0.49\"}], \"timestamp\":\"1785122314369\", \"event_type\":\"price_change\"}","received_at":"2026-07-27T03:18:34.269025Z","schema_version":"clob-market-ws.price_change.v1","sequence":null,"server_hash":null,"server_timestamp":"1785122314369","session_id":"dd162b8dca5f43ff811d304e69a06123","source":"clob_market_ws"},"received_at":"2026-07-27T03:18:34.269025Z","record_id":"033813f85bc26fb7ced196a44c681e9080af89a9a4d1de16facd6976895f682f","schema_fingerprint":"4aa3821a28b0b7c2400bc59aba4bcc0a76e971dadd19610d3ad38c768e124dc7","schema_version":"edge-lab-recorder.raw.v1","sequence":null,"source":"clob_market_ws"}
{"event_at":"2026-07-27T03:18:34.370000Z","event_fingerprint":"f2263d821c37637ce22f67d31a8b59672956c6e32c8964e51e061b08e90495bd","payload":{"connection_id":"c7dc2e4762f849c6b6f9306b6518dcab","event_at":"2026-07-27T03:18:34.370000Z","event_type":"price_change","frame_hash":"3507b84d3f84c33917065a80ffed3517a4cd28e1a3412e10de985e45a2677e80","frame_index":0,"kind":"data","monotonic_ns":224297607207625,"payload":{"event_type":"price_change","market":"0x717c0e8ccd4d5c7040185188fbae28be901ca589a11a94b1b38ca36a79eccfeb","price_changes":[{"asset_id":"24254094493625419915756280046002869097156693848522361803041977572204227262166","best_ask":"0.52","best_bid":"0.51","hash":"7074652498407fc38f7a6a263ceb589e37724a4d","price":"0.48","side":"BUY","size":"282.01"},{"asset_id":"41448400836309843603620980831210604935021861034693225347475867885462478926555","best_ask":"0.49","best_bid":"0.48","hash":"2a397c275fa844e1002ea6f76ee341febf072b17","price":"0.52","side":"SELL","size":"282.01"}],"timestamp":"1785122314370"},"payload_hash":"7724ee9031b8b22fe3a243ee6ee839e7749eb77fc6b5281922f20b064e45b6a1","raw_frame":"{\"market\":\"0x717c0e8ccd4d5c7040185188fbae28be901ca589a11a94b1b38ca36a79eccfeb\", \"price_changes\":[{\"asset_id\":\"24254094493625419915756280046002869097156693848522361803041977572204227262166\", \"price\":\"0.48\", \"size\":\"282.01\", \"side\":\"BUY\", \"hash\":\"7074652498407fc38f7a6a263ceb589e37724a4d\", \"best_bid\":\"0.51\", \"best_ask\":\"0.52\"}, {\"asset_id\":\"41448400836309843603620980831210604935021861034693225347475867885462478926555\", \"price\":\"0.52\", \"size\":\"282.01\", \"side\":\"SELL\", \"hash\":\"2a397c275fa844e1002ea6f76ee341febf072b17\", \"best_bid\":\"0.48\", \"best_ask\":\"0.49\"}], \"timestamp\":\"1785122314370\", \"event_type\":\"price_change\"}","received_at":"2026-07-27T03:18:34.270539Z","schema_version":"clob-market-ws.price_change.v1","sequence":null,"server_hash":null,"server_timestamp":"1785122314370","session_id":"dd162b8dca5f43ff811d304e69a06123","source":"clob_market_ws"},"received_at":"2026-07-27T03:18:34.270539Z","record_id":"070d1e95bae508330f8b1a135b19cfd9412705d310e1980664192b6c4ec4b8ca","schema_fingerprint":"4aa3821a28b0b7c2400bc59aba4bcc0a76e971dadd19610d3ad38c768e124dc7","schema_version":"edge-lab-recorder.raw.v1","sequence":null,"source":"clob_market_ws"}
{"event_at":"2026-07-27T03:18:34.370000Z","event_fingerprint":"286756af6adaf1471175335c654b405f3ca8354244f718027a813a9fe9096a1a","payload":{"connection_id":"c7dc2e4762f849c6b6f9306b6518dcab","event_at":"2026-07-27T03:18:34.370000Z","event_type":"price_change","frame_hash":"df9d2d61d77aac502d8fdbcf6f626d7e1c5a640e110fbad6d5815d5f50aad1f9","frame_index":0,"kind":"data","monotonic_ns":224297608887875,"payload":{"event_type":"price_change","market":"0x717c0e8ccd4d5c7040185188fbae28be901ca589a11a94b1b38ca36a79eccfeb","price_changes":[{"asset_id":"24254094493625419915756280046002869097156693848522361803041977572204227262166","best_ask":"0.52","best_bid":"0.51","hash":"5e5774029e089357673b798515af187d1c2026a4","price":"0.49","side":"BUY","size":"120.24"},{"asset_id":"41448400836309843603620980831210604935021861034693225347475867885462478926555","best_ask":"0.49","best_bid":"0.48","hash":"8866bc32ea389a8409943db409174d9caaa6a313","price":"0.51","side":"SELL","size":"120.24"}],"timestamp":"1785122314370"},"payload_hash":"95a12d50ac7a81bc47cc514584c72e26ed4b9e2af81655a05f7564c268be30dc","raw_frame":"{\"market\":\"0x717c0e8ccd4d5c7040185188fbae28be901ca589a11a94b1b38ca36a79eccfeb\", \"price_changes\":[{\"asset_id\":\"24254094493625419915756280046002869097156693848522361803041977572204227262166\", \"price\":\"0.49\", \"size\":\"120.24\", \"side\":\"BUY\", \"hash\":\"5e5774029e089357673b798515af187d1c2026a4\", \"best_bid\":\"0.51\", \"best_ask\":\"0.52\"}, {\"asset_id\":\"41448400836309843603620980831210604935021861034693225347475867885462478926555\", \"price\":\"0.51\", \"size\":\"120.24\", \"side\":\"SELL\", \"hash\":\"8866bc32ea389a8409943db409174d9caaa6a313\", \"best_bid\":\"0.48\", \"best_ask\":\"0.49\"}], \"timestamp\":\"1785122314370\", \"event_type\":\"price_change\"}","received_at":"2026-07-27T03:18:34.272219Z","schema_version":"clob-market-ws.price_change.v1","sequence":null,"server_hash":null,"server_timestamp":"1785122314370","session_id":"dd162b8dca5f43ff811d304e69a06123","source":"clob_market_ws"},"received_at":"2026-07-27T03:18:34.272219Z","record_id":"cfd53eeab1938a982b083d682ca48cbf0dc4740e4d7bff43812db178d7699d00","schema_fingerprint":"4aa3821a28b0b7c2400bc59aba4bcc0a76e971dadd19610d3ad38c768e124dc7","schema_version":"edge-lab-recorder.raw.v1","sequence":null,"source":"clob_market_ws"}
{"event_at":"2026-07-27T03:18:34.372000Z","event_fingerprint":"704aaac6cf4dc5a9a8e2a19af52d5fb5cb240ec6aeafd10964514c0b2660c955","payload":{"connection_id":"c7dc2e4762f849c6b6f9306b6518dcab","event_at":"2026-07-27T03:18:34.372000Z","event_type":"price_change","frame_hash":"dfcfaa3668a694ebe2d1a7d8c7393cf9bb699c80a14762144fa5c96debdb1677","frame_index":0,"kind":"data","monotonic_ns":224297610383208,"payload":{"event_type":"price_change","market":"0x717c0e8ccd4d5c7040185188fbae28be901ca589a11a94b1b38ca36a79eccfeb","price_changes":[{"asset_id":"24254094493625419915756280046002869097156693848522361803041977572204227262166","best_ask":"0.52","best_bid":"0.51","hash":"4fc88fd5f674731a5099bba5436e004b6b554238","price":"0.47","side":"BUY","size":"17.06"},{"asset_id":"41448400836309843603620980831210604935021861034693225347475867885462478926555","best_ask":"0.49","best_bid":"0.48","hash":"606e26061a60fb3793dfcab12acefc1beeb99fe7","price":"0.53","side":"SELL","size":"17.06"}],"timestamp":"1785122314372"},"payload_hash":"0a9be5df4dee77f300015e63cd56c569240099b3fc562b3ed210109894f533c4","raw_frame":"{\"market\":\"0x717c0e8ccd4d5c7040185188fbae28be901ca589a11a94b1b38ca36a79eccfeb\", \"price_changes\":[{\"asset_id\":\"24254094493625419915756280046002869097156693848522361803041977572204227262166\", \"price\":\"0.47\", \"size\":\"17.06\", \"side\":\"BUY\", \"hash\":\"4fc88fd5f674731a5099bba5436e004b6b554238\", \"best_bid\":\"0.51\", \"best_ask\":\"0.52\"}, {\"asset_id\":\"41448400836309843603620980831210604935021861034693225347475867885462478926555\", \"price\":\"0.53\", \"size\":\"17.06\", \"side\":\"SELL\", \"hash\":\"606e26061a60fb3793dfcab12acefc1beeb99fe7\", \"best_bid\":\"0.48\", \"best_ask\":\"0.49\"}], \"timestamp\":\"1785122314372\", \"event_type\":\"price_change\"}","received_at":"2026-07-27T03:18:34.273715Z","schema_version":"clob-market-ws.price_change.v1","sequence":null,"server_hash":null,"server_timestamp":"1785122314372","session_id":"dd162b8dca5f43ff811d304e69a06123","source":"clob_market_ws"},"received_at":"2026-07-27T03:18:34.273715Z","record_id":"0274b16dffa1218796c6d885104522f4f6c3b6d833bbc114040749822f98111c","schema_fingerprint":"4aa3821a28b0b7c2400bc59aba4bcc0a76e971dadd19610d3ad38c768e124dc7","schema_version":"edge-lab-recorder.raw.v1","sequence":null,"source":"clob_market_ws"}
{"event_at":"2026-07-27T03:18:34.395000Z","event_fingerprint":"9e03ddec7a0c4bbcdbac94ab5ca6bda57c58caf7d3fe5e2d1f24b56315623d78","payload":{"connection_id":"c7dc2e4762f849c6b6f9306b6518dcab","event_at":"2026-07-27T03:18:34.395000Z","event_type":"price_change","frame_hash":"5df8cb577b6d132549ff7de56cdb9cafce1b55a857876a55d4e0a1f6499bf07c","frame_index":0,"kind":"data","monotonic_ns":224297629802375,"payload":{"event_type":"price_change","market":"0x717c0e8ccd4d5c7040185188fbae28be901ca589a11a94b1b38ca36a79eccfeb","price_changes":[{"asset_id":"24254094493625419915756280046002869097156693848522361803041977572204227262166","best_ask":"0.52","best_bid":"0.51","hash":"ea8ef94564b16655c36141b03f3f1762bdc2afc8","price":"0.02","side":"BUY","size":"738.1"},{"asset_id":"41448400836309843603620980831210604935021861034693225347475867885462478926555","best_ask":"0.49","best_bid":"0.48","hash":"132a2c67777bf761c991cc747ead8a24870d7729","price":"0.98","side":"SELL","size":"738.1"}],"timestamp":"1785122314395"},"payload_hash":"15c9b7e46a2ac82f534fa5575173f9db7be7351c006c25b07a5d515c14d2067d","raw_frame":"{\"market\":\"0x717c0e8ccd4d5c7040185188fbae28be901ca589a11a94b1b38ca36a79eccfeb\", \"price_changes\":[{\"asset_id\":\"24254094493625419915756280046002869097156693848522361803041977572204227262166\", \"price\":\"0.02\", \"size\":\"738.1\", \"side\":\"BUY\", \"hash\":\"ea8ef94564b16655c36141b03f3f1762bdc2afc8\", \"best_bid\":\"0.51\", \"best_ask\":\"0.52\"}, {\"asset_id\":\"41448400836309843603620980831210604935021861034693225347475867885462478926555\", \"price\":\"0.98\", \"size\":\"738.1\", \"side\":\"SELL\", \"hash\":\"132a2c67777bf761c991cc747ead8a24870d7729\", \"best_bid\":\"0.48\", \"best_ask\":\"0.49\"}], \"timestamp\":\"1785122314395\", \"event_type\":\"price_change\"}","received_at":"2026-07-27T03:18:34.293129Z","schema_version":"clob-market-ws.price_change.v1","sequence":null,"server_hash":null,"server_timestamp":"1785122314395","session_id":"dd162b8dca5f43ff811d304e69a06123","source":"clob_market_ws"},"received_at":"2026-07-27T03:18:34.293129Z","record_id":"2643ce05dfbf4269772b5e0bc60d108f08d28c0f97b8017f90f0bff2323fc3d9","schema_fingerprint":"4aa3821a28b0b7c2400bc59aba4bcc0a76e971dadd19610d3ad38c768e124dc7","schema_version":"edge-lab-recorder.raw.v1","sequence":null,"source":"clob_market_ws"}
{"event_at":"2026-07-27T03:18:34.434000Z","event_fingerprint":"c600d0470c1ed9bb1de2bf39d766b62c5b882547298ed7d35c2d1577a3eec3de","payload":{"connection_id":"c7dc2e4762f849c6b6f9306b6518dcab","event_at":"2026-07-27T03:18:34.434000Z","event_type":"price_change","frame_hash":"5f8591bf83095f5c0fe8e23a601760a3f47915033c607c08e5f4500635ae3f07","frame_index":0,"kind":"data","monotonic_ns":224297670420666,"payload":{"event_type":"price_change","market":"0x717c0e8ccd4d5c7040185188fbae28be901ca589a11a94b1b38ca36a79eccfeb","price_changes":[{"asset_id":"24254094493625419915756280046002869097156693848522361803041977572204227262166","best_ask":"0.52","best_bid":"0.51","hash":"7427b57722ca37134ed1172914625238ede077cc","price":"0.47","side":"BUY","size":"5"},{"asset_id":"41448400836309843603620980831210604935021861034693225347475867885462478926555","best_ask":"0.49","best_bid":"0.48","hash":"1c3eca97cdcb1ed2e6342858737132538fd403bc","price":"0.53","side":"SELL","size":"5"}],"timestamp":"1785122314434"},"payload_hash":"235bcad1e33bd843d963566b5991a211f0512c8b77c9d700847ab3f54c9d4613","raw_frame":"{\"market\":\"0x717c0e8ccd4d5c7040185188fbae28be901ca589a11a94b1b38ca36a79eccfeb\", \"price_changes\":[{\"asset_id\":\"24254094493625419915756280046002869097156693848522361803041977572204227262166\", \"price\":\"0.47\", \"size\":\"5\", \"side\":\"BUY\", \"hash\":\"7427b57722ca37134ed1172914625238ede077cc\", \"best_bid\":\"0.51\", \"best_ask\":\"0.52\"}, {\"asset_id\":\"41448400836309843603620980831210604935021861034693225347475867885462478926555\", \"price\":\"0.53\", \"size\":\"5\", \"side\":\"SELL\", \"hash\":\"1c3eca97cdcb1ed2e6342858737132538fd403bc\", \"best_bid\":\"0.48\", \"best_ask\":\"0.49\"}], \"timestamp\":\"1785122314434\", \"event_type\":\"price_change\"}","received_at":"2026-07-27T03:18:34.333747Z","schema_version":"clob-market-ws.price_change.v1","sequence":null,"server_hash":null,"server_timestamp":"1785122314434","session_id":"dd162b8dca5f43ff811d304e69a06123","source":"clob_market_ws"},"received_at":"2026-07-27T03:18:34.333747Z","record_id":"e982ad83da926260213dead1b6ecf99f3eaef112db9e9fcafd529fa2fae54c95","schema_fingerprint":"4aa3821a28b0b7c2400bc59aba4bcc0a76e971dadd19610d3ad38c768e124dc7","schema_version":"edge-lab-recorder.raw.v1","sequence":null,"source":"clob_market_ws"}
{"event_at":"2026-07-27T03:18:34.434000Z","event_fingerprint":"8e06030cc79c68e89a51832067adf488adde30219f2a2eb44aae2118d074518e","payload":{"connection_id":"c7dc2e4762f849c6b6f9306b6518dcab","event_at":"2026-07-27T03:18:34.434000Z","event_type":"price_change","frame_hash":"88c80fdd2a6881d4da6d82c80efe06996737fdbd676550aed898b78a4e489e1b","frame_index":0,"kind":"data","monotonic_ns":224297673600625,"payload":{"event_type":"price_change","market":"0x717c0e8ccd4d5c7040185188fbae28be901ca589a11a94b1b38ca36a79eccfeb","price_changes":[{"asset_id":"41448400836309843603620980831210604935021861034693225347475867885462478926555","best_ask":"0.49","best_bid":"0.48","hash":"1c3eca97cdcb1ed2e6342858737132538fd403bc","price":"0.43","side":"BUY","size":"41.4"},{"asset_id":"24254094493625419915756280046002869097156693848522361803041977572204227262166","best_ask":"0.52","best_bid":"0.51","hash":"7427b57722ca37134ed1172914625238ede077cc","price":"0.57","side":"SELL","size":"41.4"}],"timestamp":"1785122314434"},"payload_hash":"bcaa97e64d556fc13d83bfafa29df9e96a6b12412ec1929e464806e3e6e0b22c","raw_frame":"{\"market\":\"0x717c0e8ccd4d5c7040185188fbae28be901ca589a11a94b1b38ca36a79eccfeb\", \"price_changes\":[{\"asset_id\":\"41448400836309843603620980831210604935021861034693225347475867885462478926555\", \"price\":\"0.43\", \"size\":\"41.4\", \"side\":\"BUY\", \"hash\":\"1c3eca97cdcb1ed2e6342858737132538fd403bc\", \"best_bid\":\"0.48\", \"best_ask\":\"0.49\"}, {\"asset_id\":\"24254094493625419915756280046002869097156693848522361803041977572204227262166\", \"price\":\"0.57\", \"size\":\"41.4\", \"side\":\"SELL\", \"hash\":\"7427b57722ca37134ed1172914625238ede077cc\", \"best_bid\":\"0.51\", \"best_ask\":\"0.52\"}], \"timestamp\":\"1785122314434\", \"event_type\":\"price_change\"}","received_at":"2026-07-27T03:18:34.336931Z","schema_version":"clob-market-ws.price_change.v1","sequence":null,"server_hash":null,"server_timestamp":"1785122314434","session_id":"dd162b8dca5f43ff811d304e69a06123","source":"clob_market_ws"},"received_at":"2026-07-27T03:18:34.336931Z","record_id":"c68bde3333681996cc18f321508748d0ea0f6fb4fb31db38e47bacab0bcdafe6","schema_fingerprint":"4aa3821a28b0b7c2400bc59aba4bcc0a76e971dadd19610d3ad38c768e124dc7","schema_version":"edge-lab-recorder.raw.v1","sequence":null,"source":"clob_market_ws"}
{"event_at":"2026-07-27T03:18:34.439000Z","event_fingerprint":"c499685b658e6152c34518ddbf7915d83f4891ee6cc5c406cf70b0c6cdd65e02","payload":{"connection_id":"c7dc2e4762f849c6b6f9306b6518dcab","event_at":"2026-07-27T03:18:34.439000Z","event_type":"price_change","frame_hash":"f907a67574459757f9ab6315b35faa78cfedfeec32090415db6bb75cc39f8a5e","frame_index":0,"kind":"data","monotonic_ns":224297675237291,"payload":{"event_type":"price_change","market":"0x717c0e8ccd4d5c7040185188fbae28be901ca589a11a94b1b38ca36a79eccfeb","price_changes":[{"asset_id":"24254094493625419915756280046002869097156693848522361803041977572204227262166","best_ask":"0.52","best_bid":"0.51","hash":"b0ef817555cee390c25863a1216bffc9520ca311","price":"0.51","side":"BUY","size":"78.34"},{"asset_id":"41448400836309843603620980831210604935021861034693225347475867885462478926555","best_ask":"0.49","best_bid":"0.48","hash":"fa59e1611a2bdbd70c634efe1d0290d040f99bfb","price":"0.49","side":"SELL","size":"78.34"}],"timestamp":"1785122314439"},"payload_hash":"6be25ec51124fa1dbc82e75fa8e859ecf1ed3631362683e0773b6c37d82b4a45","raw_frame":"{\"market\":\"0x717c0e8ccd4d5c7040185188fbae28be901ca589a11a94b1b38ca36a79eccfeb\", \"price_changes\":[{\"asset_id\":\"24254094493625419915756280046002869097156693848522361803041977572204227262166\", \"price\":\"0.51\", \"size\":\"78.34\", \"side\":\"BUY\", \"hash\":\"b0ef817555cee390c25863a1216bffc9520ca311\", \"best_bid\":\"0.51\", \"best_ask\":\"0.52\"}, {\"asset_id\":\"41448400836309843603620980831210604935021861034693225347475867885462478926555\", \"price\":\"0.49\", \"size\":\"78.34\", \"side\":\"SELL\", \"hash\":\"fa59e1611a2bdbd70c634efe1d0290d040f99bfb\", \"best_bid\":\"0.48\", \"best_ask\":\"0.49\"}], \"timestamp\":\"1785122314439\", \"event_type\":\"price_change\"}","received_at":"2026-07-27T03:18:34.338568Z","schema_version":"clob-market-ws.price_change.v1","sequence":null,"server_hash":null,"server_timestamp":"1785122314439","session_id":"dd162b8dca5f43ff811d304e69a06123","source":"clob_market_ws"},"received_at":"2026-07-27T03:18:34.338568Z","record_id":"9bab1081f351d68fffa4ed891d3e31ca14b4de5ff53a584372dcc5e0c151ae8e","schema_fingerprint":"4aa3821a28b0b7c2400bc59aba4bcc0a76e971dadd19610d3ad38c768e124dc7","schema_version":"edge-lab-recorder.raw.v1","sequence":null,"source":"clob_market_ws"}
{"event_at":"2026-07-27T03:18:34.440000Z","event_fingerprint":"6fbb1b66ec13912c8df34daf11f4e8140b9753086ebbb894cdfe60e83447cf6e","payload":{"connection_id":"c7dc2e4762f849c6b6f9306b6518dcab","event_at":"2026-07-27T03:18:34.440000Z","event_type":"price_change","frame_hash":"0b33f4304bf67b13874199e8fac20777cb4a540c857fa4d76c15f48baaa9d15c","frame_index":0,"kind":"data","monotonic_ns":224297676872833,"payload":{"event_type":"price_change","market":"0x717c0e8ccd4d5c7040185188fbae28be901ca589a11a94b1b38ca36a79eccfeb","price_changes":[{"asset_id":"41448400836309843603620980831210604935021861034693225347475867885462478926555","best_ask":"0.49","best_bid":"0.48","hash":"d62becfbc1750743737f3454e1fec5f286bc0dc2","price":"0.39","side":"BUY","size":"28.51"},{"asset_id":"24254094493625419915756280046002869097156693848522361803041977572204227262166","best_ask":"0.52","best_bid":"0.51","hash":"3d61f804531437e57ef163be7d0507461d66a38e","price":"0.61","side":"SELL","size":"28.51"}],"timestamp":"1785122314440"},"payload_hash":"a841f13aac02a5d9f705d9de882a1201a4f3ba237d6d83d2257afd3ab1ddc545","raw_frame":"{\"market\":\"0x717c0e8ccd4d5c7040185188fbae28be901ca589a11a94b1b38ca36a79eccfeb\", \"price_changes\":[{\"asset_id\":\"41448400836309843603620980831210604935021861034693225347475867885462478926555\", \"price\":\"0.39\", \"size\":\"28.51\", \"side\":\"BUY\", \"hash\":\"d62becfbc1750743737f3454e1fec5f286bc0dc2\", \"best_bid\":\"0.48\", \"best_ask\":\"0.49\"}, {\"asset_id\":\"24254094493625419915756280046002869097156693848522361803041977572204227262166\", \"price\":\"0.61\", \"size\":\"28.51\", \"side\":\"SELL\", \"hash\":\"3d61f804531437e57ef163be7d0507461d66a38e\", \"best_bid\":\"0.51\", \"best_ask\":\"0.52\"}], \"timestamp\":\"1785122314440\", \"event_type\":\"price_change\"}","received_at":"2026-07-27T03:18:34.340204Z","schema_version":"clob-market-ws.price_change.v1","sequence":null,"server_hash":null,"server_timestamp":"1785122314440","session_id":"dd162b8dca5f43ff811d304e69a06123","source":"clob_market_ws"},"received_at":"2026-07-27T03:18:34.340204Z","record_id":"be8f3d333839cd88e06d0f1c19a409a94e016089eb44fd8ecba41c8c1f10f6f8","schema_fingerprint":"4aa3821a28b0b7c2400bc59aba4bcc0a76e971dadd19610d3ad38c768e124dc7","schema_version":"edge-lab-recorder.raw.v1","sequence":null,"source":"clob_market_ws"}
{"event_at":"2026-07-27T03:18:34.450000Z","event_fingerprint":"ef43eeb2580b3205222d08a23c807c0cfe72e612d1714c8416430a221e40a65e","payload":{"connection_id":"c7dc2e4762f849c6b6f9306b6518dcab","event_at":"2026-07-27T03:18:34.450000Z","event_type":"price_change","frame_hash":"b39b374d14f46ad5662c4cbc09c9b2be066a8ef329e2f100d30c466d93526967","frame_index":0,"kind":"data","monotonic_ns":224297685428875,"payload":{"event_type":"price_change","market":"0x717c0e8ccd4d5c7040185188fbae28be901ca589a11a94b1b38ca36a79eccfeb","price_changes":[{"asset_id":"24254094493625419915756280046002869097156693848522361803041977572204227262166","best_ask":"0.52","best_bid":"0.51","hash":"142f91f2dc785621034b860c7730215cebad404c","price":"0.01","side":"BUY","size":"7713.02"},{"asset_id":"41448400836309843603620980831210604935021861034693225347475867885462478926555","best_ask":"0.49","best_bid":"0.48","hash":"40fa36a7f0b337081330e40247fd0c31e9ed7aee","price":"0.99","side":"SELL","size":"7713.02"}],"timestamp":"1785122314450"},"payload_hash":"d6f927b1365ed519645543806388c0f46354d5bdfc63e830e283a0352da9e02f","raw_frame":"{\"market\":\"0x717c0e8ccd4d5c7040185188fbae28be901ca589a11a94b1b38ca36a79eccfeb\", \"price_changes\":[{\"asset_id\":\"24254094493625419915756280046002869097156693848522361803041977572204227262166\", \"price\":\"0.01\", \"size\":\"7713.02\", \"side\":\"BUY\", \"hash\":\"142f91f2dc785621034b860c7730215cebad404c\", \"best_bid\":\"0.51\", \"best_ask\":\"0.52\"}, {\"asset_id\":\"41448400836309843603620980831210604935021861034693225347475867885462478926555\", \"price\":\"0.99\", \"size\":\"7713.02\", \"side\":\"SELL\", \"hash\":\"40fa36a7f0b337081330e40247fd0c31e9ed7aee\", \"best_bid\":\"0.48\", \"best_ask\":\"0.49\"}], \"timestamp\":\"1785122314450\", \"event_type\":\"price_change\"}","received_at":"2026-07-27T03:18:34.348758Z","schema_version":"clob-market-ws.price_change.v1","sequence":null,"server_hash":null,"server_timestamp":"1785122314450","session_id":"dd162b8dca5f43ff811d304e69a06123","source":"clob_market_ws"},"received_at":"2026-07-27T03:18:34.348758Z","record_id":"e71236b4d228c1d8973b428e3b55e3a55f956d1ccd05a8ac12bc7d028b88dbca","schema_fingerprint":"4aa3821a28b0b7c2400bc59aba4bcc0a76e971dadd19610d3ad38c768e124dc7","schema_version":"edge-lab-recorder.raw.v1","sequence":null,"source":"clob_market_ws"}
{"event_at":"2026-07-27T03:18:34.458000Z","event_fingerprint":"aaa8511026a117b139ba24fb673079341fffdf303695fc4701e9601934f96ca6","payload":{"connection_id":"c7dc2e4762f849c6b6f9306b6518dcab","event_at":"2026-07-27T03:18:34.458000Z","event_type":"price_change","frame_hash":"656f54626315757976fbeb1d98902d5feb27872744714b30e4ef42d81650a07f","frame_index":0,"kind":"data","monotonic_ns":224297697592000,"payload":{"event_type":"price_change","market":"0x717c0e8ccd4d5c7040185188fbae28be901ca589a11a94b1b38ca36a79eccfeb","price_changes":[{"asset_id":"24254094493625419915756280046002869097156693848522361803041977572204227262166","best_ask":"0.52","best_bid":"0.51","hash":"6b18808b0a2f6d13905c0432180f54d335d5ce6e","price":"0.02","side":"BUY","size":"733.1"},{"asset_id":"41448400836309843603620980831210604935021861034693225347475867885462478926555","best_ask":"0.49","best_bid":"0.48","hash":"abe4867e0c44ea88d03111781c44f6b81cc579bd","price":"0.98","side":"SELL","size":"733.1"}],"timestamp":"1785122314458"},"payload_hash":"21b96d4e4132c5426fc58f0d9be2713ea31bf5f3c13f9831d588a6c38ab1b57c","raw_frame":"{\"market\":\"0x717c0e8ccd4d5c7040185188fbae28be901ca589a11a94b1b38ca36a79eccfeb\", \"price_changes\":[{\"asset_id\":\"24254094493625419915756280046002869097156693848522361803041977572204227262166\", \"price\":\"0.02\", \"size\":\"733.1\", \"side\":\"BUY\", \"hash\":\"6b18808b0a2f6d13905c0432180f54d335d5ce6e\", \"best_bid\":\"0.51\", \"best_ask\":\"0.52\"}, {\"asset_id\":\"41448400836309843603620980831210604935021861034693225347475867885462478926555\", \"price\":\"0.98\", \"size\":\"733.1\", \"side\":\"SELL\", \"hash\":\"abe4867e0c44ea88d03111781c44f6b81cc579bd\", \"best_bid\":\"0.48\", \"best_ask\":\"0.49\"}], \"timestamp\":\"1785122314458\", \"event_type\":\"price_change\"}","received_at":"2026-07-27T03:18:34.360922Z","schema_version":"clob-market-ws.price_change.v1","sequence":null,"server_hash":null,"server_timestamp":"1785122314458","session_id":"dd162b8dca5f43ff811d304e69a06123","source":"clob_market_ws"},"received_at":"2026-07-27T03:18:34.360922Z","record_id":"0926534f6c872a3d721170f442bf5db6487ccedaf7cc2de5accba3283dd6f0b9","schema_fingerprint":"4aa3821a28b0b7c2400bc59aba4bcc0a76e971dadd19610d3ad38c768e124dc7","schema_version":"edge-lab-recorder.raw.v1","sequence":null,"source":"clob_market_ws"}
{"event_at":"2026-07-27T03:18:34.470000Z","event_fingerprint":"127359d108e080648b8acaa32a697109d94a2f739c8901f4ef3ffbba64d8e139","payload":{"connection_id":"c7dc2e4762f849c6b6f9306b6518dcab","event_at":"2026-07-27T03:18:34.470000Z","event_type":"price_change","frame_hash":"f0888cafc52636927217c39dbfc1cc9735103a4333fae23a1a00b577aa4d3611","frame_index":0,"kind":"data","monotonic_ns":224297707730875,"payload":{"event_type":"price_change","market":"0x717c0e8ccd4d5c7040185188fbae28be901ca589a11a94b1b38ca36a79eccfeb","price_changes":[{"asset_id":"24254094493625419915756280046002869097156693848522361803041977572204227262166","best_ask":"0.52","best_bid":"0.51","hash":"05a8b2b6776d946cd92380b3dbe5592ed0ed40e2","price":"0.01","side":"BUY","size":"7708.02"},{"asset_id":"41448400836309843603620980831210604935021861034693225347475867885462478926555","best_ask":"0.49","best_bid":"0.48","hash":"bb4135dfe4bbc2fa39cecf6c46e6e35b17d02802","price":"0.99","side":"SELL","size":"7708.02"}],"timestamp":"1785122314470"},"payload_hash":"bda0e0aecd7737773f3135a46e85fc075e26fd2bdd85e5f62c888d1170e0c2f8","raw_frame":"{\"market\":\"0x717c0e8ccd4d5c7040185188fbae28be901ca589a11a94b1b38ca36a79eccfeb\", \"price_changes\":[{\"asset_id\":\"24254094493625419915756280046002869097156693848522361803041977572204227262166\", \"price\":\"0.01\", \"size\":\"7708.02\", \"side\":\"BUY\", \"hash\":\"05a8b2b6776d946cd92380b3dbe5592ed0ed40e2\", \"best_bid\":\"0.51\", \"best_ask\":\"0.52\"}, {\"asset_id\":\"41448400836309843603620980831210604935021861034693225347475867885462478926555\", \"price\":\"0.99\", \"size\":\"7708.02\", \"side\":\"SELL\", \"hash\":\"bb4135dfe4bbc2fa39cecf6c46e6e35b17d02802\", \"best_bid\":\"0.48\", \"best_ask\":\"0.49\"}], \"timestamp\":\"1785122314470\", \"event_type\":\"price_change\"}","received_at":"2026-07-27T03:18:34.371061Z","schema_version":"clob-market-ws.price_change.v1","sequence":null,"server_hash":null,"server_timestamp":"1785122314470","session_id":"dd162b8dca5f43ff811d304e69a06123","source":"clob_market_ws"},"received_at":"2026-07-27T03:18:34.371061Z","record_id":"3d76cd404b7110389b5b7b51062439bb7ce31bfe633bd39f9659812ec9ccc3d1","schema_fingerprint":"4aa3821a28b0b7c2400bc59aba4bcc0a76e971dadd19610d3ad38c768e124dc7","schema_version":"edge-lab-recorder.raw.v1","sequence":null,"source":"clob_market_ws"}
{"event_at":"2026-07-27T03:18:34.595000Z","event_fingerprint":"d3d5d2432ca35bf6044e100844f75a16a28b47088ee0eb78f94187c203233662","payload":{"connection_id":"c7dc2e4762f849c6b6f9306b6518dcab","event_at":"2026-07-27T03:18:34.595000Z","event_type":"price_change","frame_hash":"5cc9f06596aed4f29e37de2ed0d7b42476a3e2933569c82bf3bffe6385704030","frame_index":0,"kind":"data","monotonic_ns":224297830552416,"payload":{"event_type":"price_change","market":"0x717c0e8ccd4d5c7040185188fbae28be901ca589a11a94b1b38ca36a79eccfeb","price_changes":[{"asset_id":"24254094493625419915756280046002869097156693848522361803041977572204227262166","best_ask":"0.52","best_bid":"0.51","hash":"06fd35d8559b45745c0d470cbf9f66a125d98093","price":"0.51","side":"BUY","size":"68.34"},{"asset_id":"41448400836309843603620980831210604935021861034693225347475867885462478926555","best_ask":"0.49","best_bid":"0.48","hash":"143e0f368658c0068ce7762ec4323a028eaa1d51","price":"0.49","side":"SELL","size":"68.34"}],"timestamp":"1785122314595"},"payload_hash":"f16cd5501bb4a5991dadd5a501b57b19ed22930e72f52a9a672bc1ba5adb4321","raw_frame":"{\"market\":\"0x717c0e8ccd4d5c7040185188fbae28be901ca589a11a94b1b38ca36a79eccfeb\", \"price_changes\":[{\"asset_id\":\"24254094493625419915756280046002869097156693848522361803041977572204227262166\", \"price\":\"0.51\", \"size\":\"68.34\", \"side\":\"BUY\", \"hash\":\"06fd35d8559b45745c0d470cbf9f66a125d98093\", \"best_bid\":\"0.51\", \"best_ask\":\"0.52\"}, {\"asset_id\":\"41448400836309843603620980831210604935021861034693225347475867885462478926555\", \"price\":\"0.49\", \"size\":\"68.34\", \"side\":\"SELL\", \"hash\":\"143e0f368658c0068ce7762ec4323a028eaa1d51\", \"best_bid\":\"0.48\", \"best_ask\":\"0.49\"}], \"timestamp\":\"1785122314595\", \"event_type\":\"price_change\"}","received_at":"2026-07-27T03:18:34.493879Z","schema_version":"clob-market-ws.price_change.v1","sequence":null,"server_hash":null,"server_timestamp":"1785122314595","session_id":"dd162b8dca5f43ff811d304e69a06123","source":"clob_market_ws"},"received_at":"2026-07-27T03:18:34.493879Z","record_id":"5df725831ce72c22878911dec83e45acef3ffc8ee97f66bac52dd4a11c7e7001","schema_fingerprint":"4aa3821a28b0b7c2400bc59aba4bcc0a76e971dadd19610d3ad38c768e124dc7","schema_version":"edge-lab-recorder.raw.v1","sequence":null,"source":"clob_market_ws"}
{"event_at":"2026-07-27T03:18:34.616000Z","event_fingerprint":"d06f1e2f6a441805b74c4db8eb506d4872e99eaf5c3a22d55c354e0a8c9fdc99","payload":{"connection_id":"c7dc2e4762f849c6b6f9306b6518dcab","event_at":"2026-07-27T03:18:34.616000Z","event_type":"price_change","frame_hash":"5eba9ec3f95aa0bbf955c97a2f35210ff445325d0d99bb9696253d120fd71de5","frame_index":0,"kind":"data","monotonic_ns":224297850704333,"payload":{"event_type":"price_change","market":"0x717c0e8ccd4d5c7040185188fbae28be901ca589a11a94b1b38ca36a79eccfeb","price_changes":[{"asset_id":"24254094493625419915756280046002869097156693848522361803041977572204227262166","best_ask":"0.52","best_bid":"0.51","hash":"3e59d5e28881c5c27df6a585407a23b0799239f2","price":"0.03","side":"BUY","size":"618.1"},{"asset_id":"41448400836309843603620980831210604935021861034693225347475867885462478926555","best_ask":"0.49","best_bid":"0.48","hash":"6ba55a66c999deb45963cd1f56cf8b2f9f6b2a51","price":"0.97","side":"SELL","size":"618.1"}],"timestamp":"1785122314616"},"payload_hash":"3ca6b16a9e10af6a89577bc4173115ef7fe0233c79f4e3f07aafef88de3dcedd","raw_frame":"{\"market\":\"0x717c0e8ccd4d5c7040185188fbae28be901ca589a11a94b1b38ca36a79eccfeb\", \"price_changes\":[{\"asset_id\":\"24254094493625419915756280046002869097156693848522361803041977572204227262166\", \"price\":\"0.03\", \"size\":\"618.1\", \"side\":\"BUY\", \"hash\":\"3e59d5e28881c5c27df6a585407a23b0799239f2\", \"best_bid\":\"0.51\", \"best_ask\":\"0.52\"}, {\"asset_id\":\"41448400836309843603620980831210604935021861034693225347475867885462478926555\", \"price\":\"0.97\", \"size\":\"618.1\", \"side\":\"SELL\", \"hash\":\"6ba55a66c999deb45963cd1f56cf8b2f9f6b2a51\", \"best_bid\":\"0.48\", \"best_ask\":\"0.49\"}], \"timestamp\":\"1785122314616\", \"event_type\":\"price_change\"}","received_at":"2026-07-27T03:18:34.514029Z","schema_version":"clob-market-ws.price_change.v1","sequence":null,"server_hash":null,"server_timestamp":"1785122314616","session_id":"dd162b8dca5f43ff811d304e69a06123","source":"clob_market_ws"},"received_at":"2026-07-27T03:18:34.514029Z","record_id":"17fd9bb1a7cb38b06b01978a970b8f8c5c031b572846a0e76f6766a855d2d80d","schema_fingerprint":"4aa3821a28b0b7c2400bc59aba4bcc0a76e971dadd19610d3ad38c768e124dc7","schema_version":"edge-lab-recorder.raw.v1","sequence":null,"source":"clob_market_ws"}
{"event_at":"2026-07-27T03:18:34.622000Z","event_fingerprint":"11146dbe3c7ad0924f8b857e41392f5df63ae06722c4201341ea199fc0bc6db1","payload":{"connection_id":"c7dc2e4762f849c6b6f9306b6518dcab","event_at":"2026-07-27T03:18:34.622000Z","event_type":"price_change","frame_hash":"5f6a48185427fe4c5d54dd07d8025703cf352dcaed48d4b373dbeccf01c3f8fd","frame_index":0,"kind":"data","monotonic_ns":224297856591791,"payload":{"event_type":"price_change","market":"0x717c0e8ccd4d5c7040185188fbae28be901ca589a11a94b1b38ca36a79eccfeb","price_changes":[{"asset_id":"24254094493625419915756280046002869097156693848522361803041977572204227262166","best_ask":"0.52","best_bid":"0.51","hash":"21866489034e4ea5e536485659e7529c2e43db81","price":"0.5","side":"BUY","size":"73.22"},{"asset_id":"41448400836309843603620980831210604935021861034693225347475867885462478926555","best_ask":"0.49","best_bid":"0.48","hash":"748b823ab0821d0265d14e1364d52e45e0d14bd6","price":"0.5","side":"SELL","size":"73.22"}],"timestamp":"1785122314622"},"payload_hash":"8f76eaf0b814471ce563c1150244a199d6b3d1bc6d88f5362cd724caf166fb4d","raw_frame":"{\"market\":\"0x717c0e8ccd4d5c7040185188fbae28be901ca589a11a94b1b38ca36a79eccfeb\", \"price_changes\":[{\"asset_id\":\"24254094493625419915756280046002869097156693848522361803041977572204227262166\", \"price\":\"0.5\", \"size\":\"73.22\", \"side\":\"BUY\", \"hash\":\"21866489034e4ea5e536485659e7529c2e43db81\", \"best_bid\":\"0.51\", \"best_ask\":\"0.52\"}, {\"asset_id\":\"41448400836309843603620980831210604935021861034693225347475867885462478926555\", \"price\":\"0.5\", \"size\":\"73.22\", \"side\":\"SELL\", \"hash\":\"748b823ab0821d0265d14e1364d52e45e0d14bd6\", \"best_bid\":\"0.48\", \"best_ask\":\"0.49\"}], \"timestamp\":\"1785122314622\", \"event_type\":\"price_change\"}","received_at":"2026-07-27T03:18:34.519919Z","schema_version":"clob-market-ws.price_change.v1","sequence":null,"server_hash":null,"server_timestamp":"1785122314622","session_id":"dd162b8dca5f43ff811d304e69a06123","source":"clob_market_ws"},"received_at":"2026-07-27T03:18:34.519919Z","record_id":"a38d1e09f94312b178be917589e481ece1eaf0f4b3c31ca36b6333554fc01a7b","schema_fingerprint":"4aa3821a28b0b7c2400bc59aba4bcc0a76e971dadd19610d3ad38c768e124dc7","schema_version":"edge-lab-recorder.raw.v1","sequence":null,"source":"clob_market_ws"}
{"event_at":"2026-07-27T03:18:34.663000Z","event_fingerprint":"6d059bc0a7263acb99f2e5f319d6002d94894b78e1c9835d5a20fe641d7f491a","payload":{"connection_id":"c7dc2e4762f849c6b6f9306b6518dcab","event_at":"2026-07-27T03:18:34.663000Z","event_type":"price_change","frame_hash":"6dde869c60f5c1e8337d5df197cd21725e1403970f307ed3a91c28819952a139","frame_index":0,"kind":"data","monotonic_ns":224297898139375,"payload":{"event_type":"price_change","market":"0x717c0e8ccd4d5c7040185188fbae28be901ca589a11a94b1b38ca36a79eccfeb","price_changes":[{"asset_id":"24254094493625419915756280046002869097156693848522361803041977572204227262166","best_ask":"0.52","best_bid":"0.51","hash":"226e68bdec2f397b688711fc63724eb8bd5801aa","price":"0.47","side":"BUY","size":"0"},{"asset_id":"41448400836309843603620980831210604935021861034693225347475867885462478926555","best_ask":"0.49","best_bid":"0.48","hash":"888547e464099f52cbe44550b6026cb8bd26c7fd","price":"0.53","side":"SELL","size":"0"}],"timestamp":"1785122314663"},"payload_hash":"209eececee5903bbcd6772b058c91d114f22f75400b0d6d91c9a1702553a0fe2","raw_frame":"{\"market\":\"0x717c0e8ccd4d5c7040185188fbae28be901ca589a11a94b1b38ca36a79eccfeb\", \"price_changes\":[{\"asset_id\":\"24254094493625419915756280046002869097156693848522361803041977572204227262166\", \"price\":\"0.47\", \"size\":\"0\", \"side\":\"BUY\", \"hash\":\"226e68bdec2f397b688711fc63724eb8bd5801aa\", \"best_bid\":\"0.51\", \"best_ask\":\"0.52\"}, {\"asset_id\":\"41448400836309843603620980831210604935021861034693225347475867885462478926555\", \"price\":\"0.53\", \"size\":\"0\", \"side\":\"SELL\", \"hash\":\"888547e464099f52cbe44550b6026cb8bd26c7fd\", \"best_bid\":\"0.48\", \"best_ask\":\"0.49\"}], \"timestamp\":\"1785122314663\", \"event_type\":\"price_change\"}","received_at":"2026-07-27T03:18:34.561466Z","schema_version":"clob-market-ws.price_change.v1","sequence":null,"server_hash":null,"server_timestamp":"1785122314663","session_id":"dd162b8dca5f43ff811d304e69a06123","source":"clob_market_ws"},"received_at":"2026-07-27T03:18:34.561466Z","record_id":"874266ab407550461d7c8bf576f72ac4f44ea4d9bd149975c4152870b7b77c40","schema_fingerprint":"4aa3821a28b0b7c2400bc59aba4bcc0a76e971dadd19610d3ad38c768e124dc7","schema_version":"edge-lab-recorder.raw.v1","sequence":null,"source":"clob_market_ws"}
{"event_at":"2026-07-27T03:18:34.663000Z","event_fingerprint":"a542e3d2e1cf0f64c9eed978ad13da91eb7fb2e948f5b6c6aff51db3a260241b","payload":{"connection_id":"c7dc2e4762f849c6b6f9306b6518dcab","event_at":"2026-07-27T03:18:34.663000Z","event_type":"price_change","frame_hash":"891468480952287d13cceecce30c4fc6a3718b99137cd4ddef98c083a977a2a7","frame_index":0,"kind":"data","monotonic_ns":224297899740208,"payload":{"event_type":"price_change","market":"0x717c0e8ccd4d5c7040185188fbae28be901ca589a11a94b1b38ca36a79eccfeb","price_changes":[{"asset_id":"24254094493625419915756280046002869097156693848522361803041977572204227262166","best_ask":"0.52","best_bid":"0.51","hash":"74ae30ca5096685c3cbcca8fe2803e109dbfb975","price":"0.49","side":"BUY","size":"108.24"},{"asset_id":"41448400836309843603620980831210604935021861034693225347475867885462478926555","best_ask":"0.49","best_bid":"0.48","hash":"f48a1c7227657e00b8e44faf911a3d7aa72c3b8f","price":"0.51","side":"SELL","size":"108.24"}],"timestamp":"1785122314663"},"payload_hash":"2455872a521cddd1f319cb79b17a2e642a9720825a6f6eb9edabc45f4cb3c7ed","raw_frame":"{\"market\":\"0x717c0e8ccd4d5c7040185188fbae28be901ca589a11a94b1b38ca36a79eccfeb\", \"price_changes\":[{\"asset_id\":\"24254094493625419915756280046002869097156693848522361803041977572204227262166\", \"price\":\"0.49\", \"size\":\"108.24\", \"side\":\"BUY\", \"hash\":\"74ae30ca5096685c3cbcca8fe2803e109dbfb975\", \"best_bid\":\"0.51\", \"best_ask\":\"0.52\"}, {\"asset_id\":\"41448400836309843603620980831210604935021861034693225347475867885462478926555\", \"price\":\"0.51\", \"size\":\"108.24\", \"side\":\"SELL\", \"hash\":\"f48a1c7227657e00b8e44faf911a3d7aa72c3b8f\", \"best_bid\":\"0.48\", \"best_ask\":\"0.49\"}], \"timestamp\":\"1785122314663\", \"event_type\":\"price_change\"}","received_at":"2026-07-27T03:18:34.563068Z","schema_version":"clob-market-ws.price_change.v1","sequence":null,"server_hash":null,"server_timestamp":"1785122314663","session_id":"dd162b8dca5f43ff811d304e69a06123","source":"clob_market_ws"},"received_at":"2026-07-27T03:18:34.563068Z","record_id":"b8ddcdf5ba5f3cd9f19755819dcbf7b4597842a797238d2544b2c61b20e1fffa","schema_fingerprint":"4aa3821a28b0b7c2400bc59aba4bcc0a76e971dadd19610d3ad38c768e124dc7","schema_version":"edge-lab-recorder.raw.v1","sequence":null,"source":"clob_market_ws"}
{"event_at":"2026-07-27T03:18:34.666000Z","event_fingerprint":"7efdfb430920921c9bdf32f1488cda79c62a707b4ff7f7b1001c51b1762d332a","payload":{"connection_id":"c7dc2e4762f849c6b6f9306b6518dcab","event_at":"2026-07-27T03:18:34.666000Z","event_type":"price_change","frame_hash":"f57bda3f53b0aa73f775b1f115b907605793c7a381771e39abbbf4ff98034078","frame_index":0,"kind":"data","monotonic_ns":224297901446750,"payload":{"event_type":"price_change","market":"0x717c0e8ccd4d5c7040185188fbae28be901ca589a11a94b1b38ca36a79eccfeb","price_changes":[{"asset_id":"24254094493625419915756280046002869097156693848522361803041977572204227262166","best_ask":"0.52","best_bid":"0.51","hash":"6af2775952fac2f5b708681f8b17a46d700b5bfe","price":"0.48","side":"BUY","size":"287.01"},{"asset_id":"41448400836309843603620980831210604935021861034693225347475867885462478926555","best_ask":"0.49","best_bid":"0.48","hash":"73793656ebfb4f77abfc368f263f0dedd1c3a108","price":"0.52","side":"SELL","size":"287.01"}],"timestamp":"1785122314666"},"payload_hash":"c92e266374d2dea42d9ae7d7e8455dc7883aac7b66522e78085e05d3ee332d9d","raw_frame":"{\"market\":\"0x717c0e8ccd4d5c7040185188fbae28be901ca589a11a94b1b38ca36a79eccfeb\", \"price_changes\":[{\"asset_id\":\"24254094493625419915756280046002869097156693848522361803041977572204227262166\", \"price\":\"0.48\", \"size\":\"287.01\", \"side\":\"BUY\", \"hash\":\"6af2775952fac2f5b708681f8b17a46d700b5bfe\", \"best_bid\":\"0.51\", \"best_ask\":\"0.52\"}, {\"asset_id\":\"41448400836309843603620980831210604935021861034693225347475867885462478926555\", \"price\":\"0.52\", \"size\":\"287.01\", \"side\":\"SELL\", \"hash\":\"73793656ebfb4f77abfc368f263f0dedd1c3a108\", \"best_bid\":\"0.48\", \"best_ask\":\"0.49\"}], \"timestamp\":\"1785122314666\", \"event_type\":\"price_change\"}","received_at":"2026-07-27T03:18:34.564774Z","schema_version":"clob-market-ws.price_change.v1","sequence":null,"server_hash":null,"server_timestamp":"1785122314666","session_id":"dd162b8dca5f43ff811d304e69a06123","source":"clob_market_ws"},"received_at":"2026-07-27T03:18:34.564774Z","record_id":"0cb6d2bb01a88da9aef10ba1f5750f4c7242c65ede2731c3c0a7cb7f51f8b35b","schema_fingerprint":"4aa3821a28b0b7c2400bc59aba4bcc0a76e971dadd19610d3ad38c768e124dc7","schema_version":"edge-lab-recorder.raw.v1","sequence":null,"source":"clob_market_ws"}
{"event_at":"2026-07-27T03:18:34.666000Z","event_fingerprint":"1503a99fa483623af7cf45ce5180d4ae49599e52a86220d29fb3d71cbfb18d8b","payload":{"connection_id":"c7dc2e4762f849c6b6f9306b6518dcab","event_at":"2026-07-27T03:18:34.666000Z","event_type":"price_change","frame_hash":"9b036f51f1b0df272916e690b106da47ba79e8699819a0dee595aacb6ebdf245","frame_index":0,"kind":"data","monotonic_ns":224297903073916,"payload":{"event_type":"price_change","market":"0x717c0e8ccd4d5c7040185188fbae28be901ca589a11a94b1b38ca36a79eccfeb","price_changes":[{"asset_id":"24254094493625419915756280046002869097156693848522361803041977572204227262166","best_ask":"0.52","best_bid":"0.51","hash":"661d09f1ec5dcb8f8d1e1a61fd1ab4ef6211f30e","price":"0.5","side":"BUY","size":"82.22"},{"asset_id":"41448400836309843603620980831210604935021861034693225347475867885462478926555","best_ask":"0.49","best_bid":"0.48","hash":"02b7368f49e28b535bc110ea180cbb359cbd5fdb","price":"0.5","side":"SELL","size":"82.22"}],"timestamp":"1785122314666"},"payload_hash":"5d4c776b2ec3b6c2500da3df074d8c2437207ccb9300f920d96a5abb26f69caa","raw_frame":"{\"market\":\"0x717c0e8ccd4d5c7040185188fbae28be901ca589a11a94b1b38ca36a79eccfeb\", \"price_changes\":[{\"asset_id\":\"24254094493625419915756280046002869097156693848522361803041977572204227262166\", \"price\":\"0.5\", \"size\":\"82.22\", \"side\":\"BUY\", \"hash\":\"661d09f1ec5dcb8f8d1e1a61fd1ab4ef6211f30e\", \"best_bid\":\"0.51\", \"best_ask\":\"0.52\"}, {\"asset_id\":\"41448400836309843603620980831210604935021861034693225347475867885462478926555\", \"price\":\"0.5\", \"size\":\"82.22\", \"side\":\"SELL\", \"hash\":\"02b7368f49e28b535bc110ea180cbb359cbd5fdb\", \"best_bid\":\"0.48\", \"best_ask\":\"0.49\"}], \"timestamp\":\"1785122314666\", \"event_type\":\"price_change\"}","received_at":"2026-07-27T03:18:34.566402Z","schema_version":"clob-market-ws.price_change.v1","sequence":null,"server_hash":null,"server_timestamp":"1785122314666","session_id":"dd162b8dca5f43ff811d304e69a06123","source":"clob_market_ws"},"received_at":"2026-07-27T03:18:34.566402Z","record_id":"a5862d771d9f4af65d00904b73d0cb087efdba9e21fda558aca82e498279f8b1","schema_fingerprint":"4aa3821a28b0b7c2400bc59aba4bcc0a76e971dadd19610d3ad38c768e124dc7","schema_version":"edge-lab-recorder.raw.v1","sequence":null,"source":"clob_market_ws"}
{"event_at":"2026-07-27T03:18:34.667000Z","event_fingerprint":"671d305b0e1313a141430b4f169478b0aad6902c79f731a64956a9fb6106072e","payload":{"connection_id":"c7dc2e4762f849c6b6f9306b6518dcab","event_at":"2026-07-27T03:18:34.667000Z","event_type":"price_change","frame_hash":"8afbf6eb06ece0209d0dd66fd93cb8605378833f7a2ce6b588e38e5d74336786","frame_index":0,"kind":"data","monotonic_ns":224297904403375,"payload":{"event_type":"price_change","market":"0x717c0e8ccd4d5c7040185188fbae28be901ca589a11a94b1b38ca36a79eccfeb","price_changes":[{"asset_id":"24254094493625419915756280046002869097156693848522361803041977572204227262166","best_ask":"0.52","best_bid":"0.51","hash":"150856689ce6e772b9a3f350ecf307e0b761609e","price":"0.46","side":"BUY","size":"121"},{"asset_id":"41448400836309843603620980831210604935021861034693225347475867885462478926555","best_ask":"0.49","best_bid":"0.48","hash":"36542302e7ac980f42f8e6656c84285c5431ffa2","price":"0.54","side":"SELL","size":"121"}],"timestamp":"1785122314667"},"payload_hash":"c98fc8e9cb647ccce60277ca3995535763f02fafe5625d5816a52f36219882e9","raw_frame":"{\"market\":\"0x717c0e8ccd4d5c7040185188fbae28be901ca589a11a94b1b38ca36a79eccfeb\", \"price_changes\":[{\"asset_id\":\"24254094493625419915756280046002869097156693848522361803041977572204227262166\", \"price\":\"0.46\", \"size\":\"121\", \"side\":\"BUY\", \"hash\":\"150856689ce6e772b9a3f350ecf307e0b761609e\", \"best_bid\":\"0.51\", \"best_ask\":\"0.52\"}, {\"asset_id\":\"41448400836309843603620980831210604935021861034693225347475867885462478926555\", \"price\":\"0.54\", \"size\":\"121\", \"side\":\"SELL\", \"hash\":\"36542302e7ac980f42f8e6656c84285c5431ffa2\", \"best_bid\":\"0.48\", \"best_ask\":\"0.49\"}], \"timestamp\":\"1785122314667\", \"event_type\":\"price_change\"}","received_at":"2026-07-27T03:18:34.567732Z","schema_version":"clob-market-ws.price_change.v1","sequence":null,"server_hash":null,"server_timestamp":"1785122314667","session_id":"dd162b8dca5f43ff811d304e69a06123","source":"clob_market_ws"},"received_at":"2026-07-27T03:18:34.567732Z","record_id":"d13608a648efc20b2d446b2edeaeeb380c2619f3839272fddab83c4fcee26021","schema_fingerprint":"4aa3821a28b0b7c2400bc59aba4bcc0a76e971dadd19610d3ad38c768e124dc7","schema_version":"edge-lab-recorder.raw.v1","sequence":null,"source":"clob_market_ws"}
{"event_at":"2026-07-27T03:18:34.688000Z","event_fingerprint":"19584d1b9709dcd10c06cb278e1a9977952c917942220d3ee357df8636c81fad","payload":{"connection_id":"c7dc2e4762f849c6b6f9306b6518dcab","event_at":"2026-07-27T03:18:34.688000Z","event_type":"price_change","frame_hash":"d0298046268bd5934d5492566e18c9cf8411265fc91a62e7d879f764fc83b84d","frame_index":0,"kind":"data","monotonic_ns":224297922646750,"payload":{"event_type":"price_change","market":"0x717c0e8ccd4d5c7040185188fbae28be901ca589a11a94b1b38ca36a79eccfeb","price_changes":[{"asset_id":"24254094493625419915756280046002869097156693848522361803041977572204227262166","best_ask":"0.52","best_bid":"0.51","hash":"adb7963862bef1a4c153f22f0c44ed3db8b92112","price":"0.03","side":"BUY","size":"613.1"},{"asset_id":"41448400836309843603620980831210604935021861034693225347475867885462478926555","best_ask":"0.49","best_bid":"0.48","hash":"7946ac31d3f50b22c6e6cea7070d189d4c100dd3","price":"0.97","side":"SELL","size":"613.1"}],"timestamp":"1785122314688"},"payload_hash":"2fd35341563a4413ada7c61174926d18a4208b6cdf1eb0714a09c4a42e6e3b99","raw_frame":"{\"market\":\"0x717c0e8ccd4d5c7040185188fbae28be901ca589a11a94b1b38ca36a79eccfeb\", \"price_changes\":[{\"asset_id\":\"24254094493625419915756280046002869097156693848522361803041977572204227262166\", \"price\":\"0.03\", \"size\":\"613.1\", \"side\":\"BUY\", \"hash\":\"adb7963862bef1a4c153f22f0c44ed3db8b92112\", \"best_bid\":\"0.51\", \"best_ask\":\"0.52\"}, {\"asset_id\":\"41448400836309843603620980831210604935021861034693225347475867885462478926555\", \"price\":\"0.97\", \"size\":\"613.1\", \"side\":\"SELL\", \"hash\":\"7946ac31d3f50b22c6e6cea7070d189d4c100dd3\", \"best_bid\":\"0.48\", \"best_ask\":\"0.49\"}], \"timestamp\":\"1785122314688\", \"event_type\":\"price_change\"}","received_at":"2026-07-27T03:18:34.585977Z","schema_version":"clob-market-ws.price_change.v1","sequence":null,"server_hash":null,"server_timestamp":"1785122314688","session_id":"dd162b8dca5f43ff811d304e69a06123","source":"clob_market_ws"},"received_at":"2026-07-27T03:18:34.585977Z","record_id":"c3ccc335d3f8bb6e21fcb9482264ace9a56c8f367e3809ee7d03601d5f59fb02","schema_fingerprint":"4aa3821a28b0b7c2400bc59aba4bcc0a76e971dadd19610d3ad38c768e124dc7","schema_version":"edge-lab-recorder.raw.v1","sequence":null,"source":"clob_market_ws"}
{"event_at":"2026-07-27T03:18:34.817000Z","event_fingerprint":"cf2821815eb5ea098f3cc76f6104ea2e4acfc2aa7b9d08c0f7b52e44c5571b8e","payload":{"connection_id":"c7dc2e4762f849c6b6f9306b6518dcab","event_at":"2026-07-27T03:18:34.817000Z","event_type":"price_change","frame_hash":"cb3cd89775a3e235b4fdd88ff78ab6b9b0a8f3944ffb1bd6822e5dba0e08e660","frame_index":0,"kind":"data","monotonic_ns":224298052462916,"payload":{"event_type":"price_change","market":"0x717c0e8ccd4d5c7040185188fbae28be901ca589a11a94b1b38ca36a79eccfeb","price_changes":[{"asset_id":"24254094493625419915756280046002869097156693848522361803041977572204227262166","best_ask":"0.52","best_bid":"0.51","hash":"ab04ee6ab502f38024168509dec5073eb2d93e97","price":"0.04","side":"BUY","size":"633.09"},{"asset_id":"41448400836309843603620980831210604935021861034693225347475867885462478926555","best_ask":"0.49","best_bid":"0.48","hash":"15eb08b21d9b51383214cc5751417162f7cbd411","price":"0.96","side":"SELL","size":"633.09"}],"timestamp":"1785122314817"},"payload_hash":"c233f69d7e1fe44d391430e2dbb1f122c3cc829c3a371f91906ea9325f6853e6","raw_frame":"{\"market\":\"0x717c0e8ccd4d5c7040185188fbae28be901ca589a11a94b1b38ca36a79eccfeb\", \"price_changes\":[{\"asset_id\":\"24254094493625419915756280046002869097156693848522361803041977572204227262166\", \"price\":\"0.04\", \"size\":\"633.09\", \"side\":\"BUY\", \"hash\":\"ab04ee6ab502f38024168509dec5073eb2d93e97\", \"best_bid\":\"0.51\", \"best_ask\":\"0.52\"}, {\"asset_id\":\"41448400836309843603620980831210604935021861034693225347475867885462478926555\", \"price\":\"0.96\", \"size\":\"633.09\", \"side\":\"SELL\", \"hash\":\"15eb08b21d9b51383214cc5751417162f7cbd411\", \"best_bid\":\"0.48\", \"best_ask\":\"0.49\"}], \"timestamp\":\"1785122314817\", \"event_type\":\"price_change\"}","received_at":"2026-07-27T03:18:34.715785Z","schema_version":"clob-market-ws.price_change.v1","sequence":null,"server_hash":null,"server_timestamp":"1785122314817","session_id":"dd162b8dca5f43ff811d304e69a06123","source":"clob_market_ws"},"received_at":"2026-07-27T03:18:34.715785Z","record_id":"aa0b0f819b4bc8955d14dca2612d8753c5c2c667bca9cb8d6d6305eecf92cb7a","schema_fingerprint":"4aa3821a28b0b7c2400bc59aba4bcc0a76e971dadd19610d3ad38c768e124dc7","schema_version":"edge-lab-recorder.raw.v1","sequence":null,"source":"clob_market_ws"}
{"event_at":"2026-07-27T03:18:34.833000Z","event_fingerprint":"6c14e0e9fbac25089b4127b43c94f1b21f4776163386e2efb6c098ffad12fb84","payload":{"connection_id":"c7dc2e4762f849c6b6f9306b6518dcab","event_at":"2026-07-27T03:18:34.833000Z","event_type":"price_change","frame_hash":"27679900cfe621b1761b1bd5382e57959e68f475edd62ff7d3c69a145cea78b7","frame_index":0,"kind":"data","monotonic_ns":224298069310958,"payload":{"event_type":"price_change","market":"0x717c0e8ccd4d5c7040185188fbae28be901ca589a11a94b1b38ca36a79eccfeb","price_changes":[{"asset_id":"24254094493625419915756280046002869097156693848522361803041977572204227262166","best_ask":"0.52","best_bid":"0.51","hash":"7f9b4a015e67e248016cc5b770c1aac5e7f3f617","price":"0.01","side":"BUY","size":"7713.02"},{"asset_id":"41448400836309843603620980831210604935021861034693225347475867885462478926555","best_ask":"0.49","best_bid":"0.48","hash":"bb54243d22c53970ed4497e605139d7c517c697a","price":"0.99","side":"SELL","size":"7713.02"}],"timestamp":"1785122314833"},"payload_hash":"0c23ccd2458671d08ac7d9184b8a31c0ed54046dc00cf26527c01312dfb009f7","raw_frame":"{\"market\":\"0x717c0e8ccd4d5c7040185188fbae28be901ca589a11a94b1b38ca36a79eccfeb\", \"price_changes\":[{\"asset_id\":\"24254094493625419915756280046002869097156693848522361803041977572204227262166\", \"price\":\"0.01\", \"size\":\"7713.02\", \"side\":\"BUY\", \"hash\":\"7f9b4a015e67e248016cc5b770c1aac5e7f3f617\", \"best_bid\":\"0.51\", \"best_ask\":\"0.52\"}, {\"asset_id\":\"41448400836309843603620980831210604935021861034693225347475867885462478926555\", \"price\":\"0.99\", \"size\":\"7713.02\", \"side\":\"SELL\", \"hash\":\"bb54243d22c53970ed4497e605139d7c517c697a\", \"best_bid\":\"0.48\", \"best_ask\":\"0.49\"}], \"timestamp\":\"1785122314833\", \"event_type\":\"price_change\"}","received_at":"2026-07-27T03:18:34.732634Z","schema_version":"clob-market-ws.price_change.v1","sequence":null,"server_hash":null,"server_timestamp":"1785122314833","session_id":"dd162b8dca5f43ff811d304e69a06123","source":"clob_market_ws"},"received_at":"2026-07-27T03:18:34.732634Z","record_id":"46b35c4bf4e9d938c5baf7c5d2ccb7eb64e360fb4fa35f728d65bd2f68c033f4","schema_fingerprint":"4aa3821a28b0b7c2400bc59aba4bcc0a76e971dadd19610d3ad38c768e124dc7","schema_version":"edge-lab-recorder.raw.v1","sequence":null,"source":"clob_market_ws"}
{"event_at":"2026-07-27T03:18:34.849000Z","event_fingerprint":"7a77b3c4a095becdafe8052e5719ca37889bf4a635e034532faa36ceea061577","payload":{"connection_id":"c7dc2e4762f849c6b6f9306b6518dcab","event_at":"2026-07-27T03:18:34.849000Z","event_type":"price_change","frame_hash":"0d1ac1f822ae3f2c330b05de40dabc0401df6ec6b6c8014e67ee189ef056d099","frame_index":0,"kind":"data","monotonic_ns":224298086450666,"payload":{"event_type":"price_change","market":"0x717c0e8ccd4d5c7040185188fbae28be901ca589a11a94b1b38ca36a79eccfeb","price_changes":[{"asset_id":"24254094493625419915756280046002869097156693848522361803041977572204227262166","best_ask":"0.52","best_bid":"0.51","hash":"f74773861bb5647be15d46f36164e7965de586ef","price":"0.01","side":"BUY","size":"7718.02"},{"asset_id":"41448400836309843603620980831210604935021861034693225347475867885462478926555","best_ask":"0.49","best_bid":"0.48","hash":"16d42da6331a61f84be45d20652dce42b6ec83ca","price":"0.99","side":"SELL","size":"7718.02"}],"timestamp":"1785122314849"},"payload_hash":"3978821b8344764461d899089c6ea2be26dd4ffde02588b08dd384d27201810b","raw_frame":"{\"market\":\"0x717c0e8ccd4d5c7040185188fbae28be901ca589a11a94b1b38ca36a79eccfeb\", \"price_changes\":[{\"asset_id\":\"24254094493625419915756280046002869097156693848522361803041977572204227262166\", \"price\":\"0.01\", \"size\":\"7718.02\", \"side\":\"BUY\", \"hash\":\"f74773861bb5647be15d46f36164e7965de586ef\", \"best_bid\":\"0.51\", \"best_ask\":\"0.52\"}, {\"asset_id\":\"41448400836309843603620980831210604935021861034693225347475867885462478926555\", \"price\":\"0.99\", \"size\":\"7718.02\", \"side\":\"SELL\", \"hash\":\"16d42da6331a61f84be45d20652dce42b6ec83ca\", \"best_bid\":\"0.48\", \"best_ask\":\"0.49\"}], \"timestamp\":\"1785122314849\", \"event_type\":\"price_change\"}","received_at":"2026-07-27T03:18:34.749772Z","schema_version":"clob-market-ws.price_change.v1","sequence":null,"server_hash":null,"server_timestamp":"1785122314849","session_id":"dd162b8dca5f43ff811d304e69a06123","source":"clob_market_ws"},"received_at":"2026-07-27T03:18:34.749772Z","record_id":"80eba5384796ddccf5eb3cce23ccde1e35b9b872ebb9ea3db61bb8d0440f89ff","schema_fingerprint":"4aa3821a28b0b7c2400bc59aba4bcc0a76e971dadd19610d3ad38c768e124dc7","schema_version":"edge-lab-recorder.raw.v1","sequence":null,"source":"clob_market_ws"}
{"event_at":"2026-07-27T03:18:34.855000Z","event_fingerprint":"1a932ed64b630f3ac88b7e10a11a726bce6f552df616d70e336936c74f66dc75","payload":{"connection_id":"c7dc2e4762f849c6b6f9306b6518dcab","event_at":"2026-07-27T03:18:34.855000Z","event_type":"price_change","frame_hash":"4537bca7cf0fd855ee1694b3f63205c32464b7cd532aea1b2c4ee0e933f20ed4","frame_index":0,"kind":"data","monotonic_ns":224298092900583,"payload":{"event_type":"price_change","market":"0x717c0e8ccd4d5c7040185188fbae28be901ca589a11a94b1b38ca36a79eccfeb","price_changes":[{"asset_id":"24254094493625419915756280046002869097156693848522361803041977572204227262166","best_ask":"0.52","best_bid":"0.51","hash":"b97011d55f52aaba90a0a61d0351050ca27e00d9","price":"0.01","side":"BUY","size":"7713.02"},{"asset_id":"41448400836309843603620980831210604935021861034693225347475867885462478926555","best_ask":"0.49","best_bid":"0.48","hash":"0587f85eed1644bb6a83b95341b0558ad55f74b7","price":"0.99","side":"SELL","size":"7713.02"}],"timestamp":"1785122314855"},"payload_hash":"b608260cafdae9f1cb5d018674ffa31bac9c96f5723b9b1f66dacf454759094b","raw_frame":"{\"market\":\"0x717c0e8ccd4d5c7040185188fbae28be901ca589a11a94b1b38ca36a79eccfeb\", \"price_changes\":[{\"asset_id\":\"24254094493625419915756280046002869097156693848522361803041977572204227262166\", \"price\":\"0.01\", \"size\":\"7713.02\", \"side\":\"BUY\", \"hash\":\"b97011d55f52aaba90a0a61d0351050ca27e00d9\", \"best_bid\":\"0.51\", \"best_ask\":\"0.52\"}, {\"asset_id\":\"41448400836309843603620980831210604935021861034693225347475867885462478926555\", \"price\":\"0.99\", \"size\":\"7713.02\", \"side\":\"SELL\", \"hash\":\"0587f85eed1644bb6a83b95341b0558ad55f74b7\", \"best_bid\":\"0.48\", \"best_ask\":\"0.49\"}], \"timestamp\":\"1785122314855\", \"event_type\":\"price_change\"}","received_at":"2026-07-27T03:18:34.756224Z","schema_version":"clob-market-ws.price_change.v1","sequence":null,"server_hash":null,"server_timestamp":"1785122314855","session_id":"dd162b8dca5f43ff811d304e69a06123","source":"clob_market_ws"},"received_at":"2026-07-27T03:18:34.756224Z","record_id":"da7c12a586a580c19814a539cc90e13cb3a35993d439aa819db65bd3c7c20ccd","schema_fingerprint":"4aa3821a28b0b7c2400bc59aba4bcc0a76e971dadd19610d3ad38c768e124dc7","schema_version":"edge-lab-recorder.raw.v1","sequence":null,"source":"clob_market_ws"}
{"event_at":"2026-07-27T03:18:34.869000Z","event_fingerprint":"df3c0eef6b2ddc0e020eed985b62b8bafd2eb1e25bb3fec1032ba6d4536ba911","payload":{"connection_id":"c7dc2e4762f849c6b6f9306b6518dcab","event_at":"2026-07-27T03:18:34.869000Z","event_type":"price_change","frame_hash":"2f0c98aec57f9e6b36f44b9f18e713b4f76831438bd5204eedb63f03e297922b","frame_index":0,"kind":"data","monotonic_ns":224298103249916,"payload":{"event_type":"price_change","market":"0x717c0e8ccd4d5c7040185188fbae28be901ca589a11a94b1b38ca36a79eccfeb","price_changes":[{"asset_id":"24254094493625419915756280046002869097156693848522361803041977572204227262166","best_ask":"0.52","best_bid":"0.51","hash":"f0232c82ed2b09196702f0750ff4e72c37170bc8","price":"0.01","side":"BUY","size":"7708.02"},{"asset_id":"41448400836309843603620980831210604935021861034693225347475867885462478926555","best_ask":"0.49","best_bid":"0.48","hash":"5cc7d1e4e826d1f7c87df039bd9f8ad42beef5f3","price":"0.99","side":"SELL","size":"7708.02"}],"timestamp":"1785122314869"},"payload_hash":"18cbc1c8507e83d4c0bff5943d6634047ddd9dff4b756410bc9fc4a19a2e41c8","raw_frame":"{\"market\":\"0x717c0e8ccd4d5c7040185188fbae28be901ca589a11a94b1b38ca36a79eccfeb\", \"price_changes\":[{\"asset_id\":\"24254094493625419915756280046002869097156693848522361803041977572204227262166\", \"price\":\"0.01\", \"size\":\"7708.02\", \"side\":\"BUY\", \"hash\":\"f0232c82ed2b09196702f0750ff4e72c37170bc8\", \"best_bid\":\"0.51\", \"best_ask\":\"0.52\"}, {\"asset_id\":\"41448400836309843603620980831210604935021861034693225347475867885462478926555\", \"price\":\"0.99\", \"size\":\"7708.02\", \"side\":\"SELL\", \"hash\":\"5cc7d1e4e826d1f7c87df039bd9f8ad42beef5f3\", \"best_bid\":\"0.48\", \"best_ask\":\"0.49\"}], \"timestamp\":\"1785122314869\", \"event_type\":\"price_change\"}","received_at":"2026-07-27T03:18:34.766569Z","schema_version":"clob-market-ws.price_change.v1","sequence":null,"server_hash":null,"server_timestamp":"1785122314869","session_id":"dd162b8dca5f43ff811d304e69a06123","source":"clob_market_ws"},"received_at":"2026-07-27T03:18:34.766569Z","record_id":"c1f5d658269053a0484e0e69226391467f2bd4a723cd0e873073626ba6eec097","schema_fingerprint":"4aa3821a28b0b7c2400bc59aba4bcc0a76e971dadd19610d3ad38c768e124dc7","schema_version":"edge-lab-recorder.raw.v1","sequence":null,"source":"clob_market_ws"}
{"event_at":"2026-07-27T03:18:34.877000Z","event_fingerprint":"b074f59fe5be9a6cf832a21e78cea2aa187872bb6842e032c87a5ba6631edc27","payload":{"connection_id":"c7dc2e4762f849c6b6f9306b6518dcab","event_at":"2026-07-27T03:18:34.877000Z","event_type":"price_change","frame_hash":"e96c05e078d2b6f88be992b0f9f9e24a957742cd4fdc2ed81d47c48fa4fcc896","frame_index":0,"kind":"data","monotonic_ns":224298112437166,"payload":{"event_type":"price_change","market":"0x717c0e8ccd4d5c7040185188fbae28be901ca589a11a94b1b38ca36a79eccfeb","price_changes":[{"asset_id":"24254094493625419915756280046002869097156693848522361803041977572204227262166","best_ask":"0.52","best_bid":"0.51","hash":"ed2c08284bbc3956bc04f73b08e13861f140cee5","price":"0.04","side":"BUY","size":"628.09"},{"asset_id":"41448400836309843603620980831210604935021861034693225347475867885462478926555","best_ask":"0.49","best_bid":"0.48","hash":"a49ecbeecc81b4e954fdafb301c2ffb168264a43","price":"0.96","side":"SELL","size":"628.09"}],"timestamp":"1785122314877"},"payload_hash":"f2405d695c40e90928a81b850d42e9831e9f0ab99bb1d07e013151f652cbb2e5","raw_frame":"{\"market\":\"0x717c0e8ccd4d5c7040185188fbae28be901ca589a11a94b1b38ca36a79eccfeb\", \"price_changes\":[{\"asset_id\":\"24254094493625419915756280046002869097156693848522361803041977572204227262166\", \"price\":\"0.04\", \"size\":\"628.09\", \"side\":\"BUY\", \"hash\":\"ed2c08284bbc3956bc04f73b08e13861f140cee5\", \"best_bid\":\"0.51\", \"best_ask\":\"0.52\"}, {\"asset_id\":\"41448400836309843603620980831210604935021861034693225347475867885462478926555\", \"price\":\"0.96\", \"size\":\"628.09\", \"side\":\"SELL\", \"hash\":\"a49ecbeecc81b4e954fdafb301c2ffb168264a43\", \"best_bid\":\"0.48\", \"best_ask\":\"0.49\"}], \"timestamp\":\"1785122314877\", \"event_type\":\"price_change\"}","received_at":"2026-07-27T03:18:34.775766Z","schema_version":"clob-market-ws.price_change.v1","sequence":null,"server_hash":null,"server_timestamp":"1785122314877","session_id":"dd162b8dca5f43ff811d304e69a06123","source":"clob_market_ws"},"received_at":"2026-07-27T03:18:34.775766Z","record_id":"fad93bd7f17a546163b5804e356759301a4d24915cc8c5f5f39823db1c329074","schema_fingerprint":"4aa3821a28b0b7c2400bc59aba4bcc0a76e971dadd19610d3ad38c768e124dc7","schema_version":"edge-lab-recorder.raw.v1","sequence":null,"source":"clob_market_ws"}
{"event_at":"2026-07-27T03:18:34.900000Z","event_fingerprint":"c59b706c29dea8a4be8e83c8a57fac49c8892c714edb43df00953e02248b6d52","payload":{"connection_id":"c7dc2e4762f849c6b6f9306b6518dcab","event_at":"2026-07-27T03:18:34.900000Z","event_type":"price_change","frame_hash":"63cc62eb8c9640847d4a006e766a45eb506e0fc740efe894f784de737ca83abc","frame_index":0,"kind":"data","monotonic_ns":224298134302791,"payload":{"event_type":"price_change","market":"0x717c0e8ccd4d5c7040185188fbae28be901ca589a11a94b1b38ca36a79eccfeb","price_changes":[{"asset_id":"24254094493625419915756280046002869097156693848522361803041977572204227262166","best_ask":"0.52","best_bid":"0.51","hash":"7b2fae212888c157525ff3a0af3880690353a8f4","price":"0.5","side":"BUY","size":"72.22"},{"asset_id":"41448400836309843603620980831210604935021861034693225347475867885462478926555","best_ask":"0.49","best_bid":"0.48","hash":"dde1b754760113e373d9b5f4f50e2ea792f8c6f2","price":"0.5","side":"SELL","size":"72.22"}],"timestamp":"1785122314900"},"payload_hash":"c1430e2b933feb07c1ad7a028c3df2214786b73d3b6b7349c9fadeb08640bfd0","raw_frame":"{\"market\":\"0x717c0e8ccd4d5c7040185188fbae28be901ca589a11a94b1b38ca36a79eccfeb\", \"price_changes\":[{\"asset_id\":\"24254094493625419915756280046002869097156693848522361803041977572204227262166\", \"price\":\"0.5\", \"size\":\"72.22\", \"side\":\"BUY\", \"hash\":\"7b2fae212888c157525ff3a0af3880690353a8f4\", \"best_bid\":\"0.51\", \"best_ask\":\"0.52\"}, {\"asset_id\":\"41448400836309843603620980831210604935021861034693225347475867885462478926555\", \"price\":\"0.5\", \"size\":\"72.22\", \"side\":\"SELL\", \"hash\":\"dde1b754760113e373d9b5f4f50e2ea792f8c6f2\", \"best_bid\":\"0.48\", \"best_ask\":\"0.49\"}], \"timestamp\":\"1785122314900\", \"event_type\":\"price_change\"}","received_at":"2026-07-27T03:18:34.797633Z","schema_version":"clob-market-ws.price_change.v1","sequence":null,"server_hash":null,"server_timestamp":"1785122314900","session_id":"dd162b8dca5f43ff811d304e69a06123","source":"clob_market_ws"},"received_at":"2026-07-27T03:18:34.797633Z","record_id":"8e188d87eb9cfc84deb5ae7ae6de6c809d15b19c03242e3a70c1a81d1a05da7e","schema_fingerprint":"4aa3821a28b0b7c2400bc59aba4bcc0a76e971dadd19610d3ad38c768e124dc7","schema_version":"edge-lab-recorder.raw.v1","sequence":null,"source":"clob_market_ws"}
{"event_at":"2026-07-27T03:18:34.926000Z","event_fingerprint":"523c977caec77bb8d14d7b0a4165b5c6e9116561be5353567ab0bf56b6af20c4","payload":{"connection_id":"c7dc2e4762f849c6b6f9306b6518dcab","event_at":"2026-07-27T03:18:34.926000Z","event_type":"price_change","frame_hash":"d26678b55badb1f5fbcb416a0d8fadb57e5a88b963e802cca6c42fe0ffaf4e24","frame_index":0,"kind":"data","monotonic_ns":224298170401875,"payload":{"event_type":"price_change","market":"0x717c0e8ccd4d5c7040185188fbae28be901ca589a11a94b1b38ca36a79eccfeb","price_changes":[{"asset_id":"24254094493625419915756280046002869097156693848522361803041977572204227262166","best_ask":"0.52","best_bid":"0.51","hash":"984d58bab89def5f847249de6b68725dbcbd4ca5","price":"0.51","side":"BUY","size":"78.34"},{"asset_id":"41448400836309843603620980831210604935021861034693225347475867885462478926555","best_ask":"0.49","best_bid":"0.48","hash":"1148c471c0b1afa44431dc8d37a2b126e7ec693d","price":"0.49","side":"SELL","size":"78.34"}],"timestamp":"1785122314926"},"payload_hash":"e7387b293eb622ba7a9924181d2c953bdd7260f7e968b79b87023fa5aa28d57f","raw_frame":"{\"market\":\"0x717c0e8ccd4d5c7040185188fbae28be901ca589a11a94b1b38ca36a79eccfeb\", \"price_changes\":[{\"asset_id\":\"24254094493625419915756280046002869097156693848522361803041977572204227262166\", \"price\":\"0.51\", \"size\":\"78.34\", \"side\":\"BUY\", \"hash\":\"984d58bab89def5f847249de6b68725dbcbd4ca5\", \"best_bid\":\"0.51\", \"best_ask\":\"0.52\"}, {\"asset_id\":\"41448400836309843603620980831210604935021861034693225347475867885462478926555\", \"price\":\"0.49\", \"size\":\"78.34\", \"side\":\"SELL\", \"hash\":\"1148c471c0b1afa44431dc8d37a2b126e7ec693d\", \"best_bid\":\"0.48\", \"best_ask\":\"0.49\"}], \"timestamp\":\"1785122314926\", \"event_type\":\"price_change\"}","received_at":"2026-07-27T03:18:34.833720Z","schema_version":"clob-market-ws.price_change.v1","sequence":null,"server_hash":null,"server_timestamp":"1785122314926","session_id":"dd162b8dca5f43ff811d304e69a06123","source":"clob_market_ws"},"received_at":"2026-07-27T03:18:34.833720Z","record_id":"72a166bec520fb4f2300091151aeb24601319b61e2e2c4a513e23cd72f67874a","schema_fingerprint":"4aa3821a28b0b7c2400bc59aba4bcc0a76e971dadd19610d3ad38c768e124dc7","schema_version":"edge-lab-recorder.raw.v1","sequence":null,"source":"clob_market_ws"}
{"event_at":"2026-07-27T03:18:35.005000Z","event_fingerprint":"c5e3453705423d6eee98c78b7e8f6dadf66c6032b31cf7da9a605a68a3062d94","payload":{"connection_id":"c7dc2e4762f849c6b6f9306b6518dcab","event_at":"2026-07-27T03:18:35.005000Z","event_type":"price_change","frame_hash":"d42c6a420a5fd67e59b05869d1eb40fdc257cb39782f2e9ffb9f28a762bab7b5","frame_index":0,"kind":"data","monotonic_ns":224298243834958,"payload":{"event_type":"price_change","market":"0x717c0e8ccd4d5c7040185188fbae28be901ca589a11a94b1b38ca36a79eccfeb","price_changes":[{"asset_id":"24254094493625419915756280046002869097156693848522361803041977572204227262166","best_ask":"0.52","best_bid":"0.51","hash":"ca7533c6b65dc1674bb2e7bc08a72869d9cdfa42","price":"0.49","side":"BUY","size":"378.24"},{"asset_id":"41448400836309843603620980831210604935021861034693225347475867885462478926555","best_ask":"0.49","best_bid":"0.48","hash":"bbf1fbd994f7d50da83818f7a430def9c38e0278","price":"0.51","side":"SELL","size":"378.24"}],"timestamp":"1785122315005"},"payload_hash":"59d45987a7997ddc34317c7dfea7cebfec397107819be65561545cd290f373ec","raw_frame":"{\"market\":\"0x717c0e8ccd4d5c7040185188fbae28be901ca589a11a94b1b38ca36a79eccfeb\", \"price_changes\":[{\"asset_id\":\"24254094493625419915756280046002869097156693848522361803041977572204227262166\", \"price\":\"0.49\", \"size\":\"378.24\", \"side\":\"BUY\", \"hash\":\"ca7533c6b65dc1674bb2e7bc08a72869d9cdfa42\", \"best_bid\":\"0.51\", \"best_ask\":\"0.52\"}, {\"asset_id\":\"41448400836309843603620980831210604935021861034693225347475867885462478926555\", \"price\":\"0.51\", \"size\":\"378.24\", \"side\":\"SELL\", \"hash\":\"bbf1fbd994f7d50da83818f7a430def9c38e0278\", \"best_bid\":\"0.48\", \"best_ask\":\"0.49\"}], \"timestamp\":\"1785122315005\", \"event_type\":\"price_change\"}","received_at":"2026-07-27T03:18:34.907160Z","schema_version":"clob-market-ws.price_change.v1","sequence":null,"server_hash":null,"server_timestamp":"1785122315005","session_id":"dd162b8dca5f43ff811d304e69a06123","source":"clob_market_ws"},"received_at":"2026-07-27T03:18:34.907160Z","record_id":"134e25aca9f764231a02619d023208368ddcdb281b54819ab31d3cecee041d33","schema_fingerprint":"4aa3821a28b0b7c2400bc59aba4bcc0a76e971dadd19610d3ad38c768e124dc7","schema_version":"edge-lab-recorder.raw.v1","sequence":null,"source":"clob_market_ws"}
{"event_at":"2026-07-27T03:18:35.005000Z","event_fingerprint":"8754078c5c5b913c84d31787491b323c5e68183d9276bbe72b42d1067d43bf98","payload":{"connection_id":"c7dc2e4762f849c6b6f9306b6518dcab","event_at":"2026-07-27T03:18:35.005000Z","event_type":"price_change","frame_hash":"985c80c664416a8f1fd55f78cf919c9b59228b5700d11a0100d5811a35afaa33","frame_index":0,"kind":"data","monotonic_ns":224298244876250,"payload":{"event_type":"price_change","market":"0x717c0e8ccd4d5c7040185188fbae28be901ca589a11a94b1b38ca36a79eccfeb","price_changes":[{"asset_id":"41448400836309843603620980831210604935021861034693225347475867885462478926555","best_ask":"0.49","best_bid":"0.48","hash":"027733067552885db17323a7f58d13ec08e5e333","price":"0.37","side":"BUY","size":"183.9"},{"asset_id":"24254094493625419915756280046002869097156693848522361803041977572204227262166","best_ask":"0.52","best_bid":"0.51","hash":"8284d2902fc0aabbf59b9720feacc6b14ae3cd39","price":"0.63","side":"SELL","size":"183.9"}],"timestamp":"1785122315005"},"payload_hash":"3338d5227b844f22aa65f99ce5e49b68e0fcf50757daa90a4d26111b8443461c","raw_frame":"{\"market\":\"0x717c0e8ccd4d5c7040185188fbae28be901ca589a11a94b1b38ca36a79eccfeb\", \"price_changes\":[{\"asset_id\":\"41448400836309843603620980831210604935021861034693225347475867885462478926555\", \"price\":\"0.37\", \"size\":\"183.9\", \"side\":\"BUY\", \"hash\":\"027733067552885db17323a7f58d13ec08e5e333\", \"best_bid\":\"0.48\", \"best_ask\":\"0.49\"}, {\"asset_id\":\"24254094493625419915756280046002869097156693848522361803041977572204227262166\", \"price\":\"0.63\", \"size\":\"183.9\", \"side\":\"SELL\", \"hash\":\"8284d2902fc0aabbf59b9720feacc6b14ae3cd39\", \"best_bid\":\"0.51\", \"best_ask\":\"0.52\"}], \"timestamp\":\"1785122315005\", \"event_type\":\"price_change\"}","received_at":"2026-07-27T03:18:34.908202Z","schema_version":"clob-market-ws.price_change.v1","sequence":null,"server_hash":null,"server_timestamp":"1785122315005","session_id":"dd162b8dca5f43ff811d304e69a06123","source":"clob_market_ws"},"received_at":"2026-07-27T03:18:34.908202Z","record_id":"3d9bdfb62a8019eba4f25895e158c0fe0748d359fe0c61bc1724217baf3f164a","schema_fingerprint":"4aa3821a28b0b7c2400bc59aba4bcc0a76e971dadd19610d3ad38c768e124dc7","schema_version":"edge-lab-recorder.raw.v1","sequence":null,"source":"clob_market_ws"}
{"event_at":"2026-07-27T03:18:35.006000Z","event_fingerprint":"c3609660a49d09510d6051212159e99fc37cf7bb5ee117292a6d3b7fb316d630","payload":{"connection_id":"c7dc2e4762f849c6b6f9306b6518dcab","event_at":"2026-07-27T03:18:35.006000Z","event_type":"price_change","frame_hash":"23b609ecf8a7a46a2c73a92e0352c041c99b4c890d430b5f83fb97277fdd9a0c","frame_index":0,"kind":"data","monotonic_ns":224298245511541,"payload":{"event_type":"price_change","market":"0x717c0e8ccd4d5c7040185188fbae28be901ca589a11a94b1b38ca36a79eccfeb","price_changes":[{"asset_id":"41448400836309843603620980831210604935021861034693225347475867885462478926555","best_ask":"0.49","best_bid":"0.48","hash":"4318070134b3195e98ecf1e36e894fee4d670706","price":"0.37","side":"BUY","size":"153.9"},{"asset_id":"24254094493625419915756280046002869097156693848522361803041977572204227262166","best_ask":"0.52","best_bid":"0.51","hash":"60d12b6068213e009d669873367952daff559a63","price":"0.63","side":"SELL","size":"153.9"}],"timestamp":"1785122315006"},"payload_hash":"d82a4fe7f2aef345fdf425125c8e3ba3890e9fcabe206b7776b56b0e0c15b7b8","raw_frame":"{\"market\":\"0x717c0e8ccd4d5c7040185188fbae28be901ca589a11a94b1b38ca36a79eccfeb\", \"price_changes\":[{\"asset_id\":\"41448400836309843603620980831210604935021861034693225347475867885462478926555\", \"price\":\"0.37\", \"size\":\"153.9\", \"side\":\"BUY\", \"hash\":\"4318070134b3195e98ecf1e36e894fee4d670706\", \"best_bid\":\"0.48\", \"best_ask\":\"0.49\"}, {\"asset_id\":\"24254094493625419915756280046002869097156693848522361803041977572204227262166\", \"price\":\"0.63\", \"size\":\"153.9\", \"side\":\"SELL\", \"hash\":\"60d12b6068213e009d669873367952daff559a63\", \"best_bid\":\"0.51\", \"best_ask\":\"0.52\"}], \"timestamp\":\"1785122315006\", \"event_type\":\"price_change\"}","received_at":"2026-07-27T03:18:34.908841Z","schema_version":"clob-market-ws.price_change.v1","sequence":null,"server_hash":null,"server_timestamp":"1785122315006","session_id":"dd162b8dca5f43ff811d304e69a06123","source":"clob_market_ws"},"received_at":"2026-07-27T03:18:34.908841Z","record_id":"de9a95800253ad1259d6cc9ee03eaf478c5419b44da29759a640a291e0f98cd4","schema_fingerprint":"4aa3821a28b0b7c2400bc59aba4bcc0a76e971dadd19610d3ad38c768e124dc7","schema_version":"edge-lab-recorder.raw.v1","sequence":null,"source":"clob_market_ws"}
{"event_at":"2026-07-27T03:18:35.007000Z","event_fingerprint":"c9b1c61ac4a316c35aafb538a0add8e5fa4d360c77f78b889f84020e6f1db2f4","payload":{"connection_id":"c7dc2e4762f849c6b6f9306b6518dcab","event_at":"2026-07-27T03:18:35.007000Z","event_type":"price_change","frame_hash":"72e237213b6d398c0dcd5b87b9bb797ec50b6a48d65bd3e6c88dc4ca64758ba4","frame_index":0,"kind":"data","monotonic_ns":224298247334166,"payload":{"event_type":"price_change","market":"0x717c0e8ccd4d5c7040185188fbae28be901ca589a11a94b1b38ca36a79eccfeb","price_changes":[{"asset_id":"24254094493625419915756280046002869097156693848522361803041977572204227262166","best_ask":"0.52","best_bid":"0.51","hash":"ca9d72064822c6f93c1ca9769db79c1fd3369ebd","price":"0.48","side":"BUY","size":"17.01"},{"asset_id":"41448400836309843603620980831210604935021861034693225347475867885462478926555","best_ask":"0.49","best_bid":"0.48","hash":"8947bbe03d99f074a26d3c504dd40b5ec4beadb6","price":"0.52","side":"SELL","size":"17.01"}],"timestamp":"1785122315007"},"payload_hash":"08eef81449323cc36546a047c038714749e0d23f9f80c62e9062248d47a4604f","raw_frame":"{\"market\":\"0x717c0e8ccd4d5c7040185188fbae28be901ca589a11a94b1b38ca36a79eccfeb\", \"price_changes\":[{\"asset_id\":\"24254094493625419915756280046002869097156693848522361803041977572204227262166\", \"price\":\"0.48\", \"size\":\"17.01\", \"side\":\"BUY\", \"hash\":\"ca9d72064822c6f93c1ca9769db79c1fd3369ebd\", \"best_bid\":\"0.51\", \"best_ask\":\"0.52\"}, {\"asset_id\":\"41448400836309843603620980831210604935021861034693225347475867885462478926555\", \"price\":\"0.52\", \"size\":\"17.01\", \"side\":\"SELL\", \"hash\":\"8947bbe03d99f074a26d3c504dd40b5ec4beadb6\", \"best_bid\":\"0.48\", \"best_ask\":\"0.49\"}], \"timestamp\":\"1785122315007\", \"event_type\":\"price_change\"}","received_at":"2026-07-27T03:18:34.910660Z","schema_version":"clob-market-ws.price_change.v1","sequence":null,"server_hash":null,"server_timestamp":"1785122315007","session_id":"dd162b8dca5f43ff811d304e69a06123","source":"clob_market_ws"},"received_at":"2026-07-27T03:18:34.910660Z","record_id":"8b2bf058460d909f55c38753a63bf1bd21357c7a420261d005c9335be41692d7","schema_fingerprint":"4aa3821a28b0b7c2400bc59aba4bcc0a76e971dadd19610d3ad38c768e124dc7","schema_version":"edge-lab-recorder.raw.v1","sequence":null,"source":"clob_market_ws"}
{"event_at":"2026-07-27T03:18:35.007000Z","event_fingerprint":"01fcd31ca55543846863a3c3099d6451c4b831934cf3d6140474156911fe2ee3","payload":{"connection_id":"c7dc2e4762f849c6b6f9306b6518dcab","event_at":"2026-07-27T03:18:35.007000Z","event_type":"price_change","frame_hash":"2676a04657d1917defd53afdfd3a7508fb6ac266b53e36991ea1d39bf0a46885","frame_index":0,"kind":"data","monotonic_ns":224298249509375,"payload":{"event_type":"price_change","market":"0x717c0e8ccd4d5c7040185188fbae28be901ca589a11a94b1b38ca36a79eccfeb","price_changes":[{"asset_id":"41448400836309843603620980831210604935021861034693225347475867885462478926555","best_ask":"0.49","best_bid":"0.48","hash":"811956432194419092e57a500b0a64ad901c3bc0","price":"0.37","side":"BUY","size":"123.9"},{"asset_id":"24254094493625419915756280046002869097156693848522361803041977572204227262166","best_ask":"0.52","best_bid":"0.51","hash":"bf76dda08b51c264fd690a2389c5ad5a84370e0a","price":"0.63","side":"SELL","size":"123.9"}],"timestamp":"1785122315007"},"payload_hash":"2599467d44f24f240e81c778ae16cfdbb2e311fa26be1afcb8049f0262acf835","raw_frame":"{\"market\":\"0x717c0e8ccd4d5c7040185188fbae28be901ca589a11a94b1b38ca36a79eccfeb\", \"price_changes\":[{\"asset_id\":\"41448400836309843603620980831210604935021861034693225347475867885462478926555\", \"price\":\"0.37\", \"size\":\"123.9\", \"side\":\"BUY\", \"hash\":\"811956432194419092e57a500b0a64ad901c3bc0\", \"best_bid\":\"0.48\", \"best_ask\":\"0.49\"}, {\"asset_id\":\"24254094493625419915756280046002869097156693848522361803041977572204227262166\", \"price\":\"0.63\", \"size\":\"123.9\", \"side\":\"SELL\", \"hash\":\"bf76dda08b51c264fd690a2389c5ad5a84370e0a\", \"best_bid\":\"0.51\", \"best_ask\":\"0.52\"}], \"timestamp\":\"1785122315007\", \"event_type\":\"price_change\"}","received_at":"2026-07-27T03:18:34.912836Z","schema_version":"clob-market-ws.price_change.v1","sequence":null,"server_hash":null,"server_timestamp":"1785122315007","session_id":"dd162b8dca5f43ff811d304e69a06123","source":"clob_market_ws"},"received_at":"2026-07-27T03:18:34.912836Z","record_id":"8ef51c0bcf9e245e539bb54b61441465e77a6b46714763ba6b3468e1b4418a8c","schema_fingerprint":"4aa3821a28b0b7c2400bc59aba4bcc0a76e971dadd19610d3ad38c768e124dc7","schema_version":"edge-lab-recorder.raw.v1","sequence":null,"source":"clob_market_ws"}
{"event_at":"2026-07-27T03:18:35.008000Z","event_fingerprint":"c0ff9b753fe9b0c95ee7d21ea0e4192437dcdd1d739b882c54524def59dfdee5","payload":{"connection_id":"c7dc2e4762f849c6b6f9306b6518dcab","event_at":"2026-07-27T03:18:35.008000Z","event_type":"price_change","frame_hash":"5e1dd95f02b61b24c24530e3963e2407223cc555b225afdafd9a7c0d9c41e604","frame_index":0,"kind":"data","monotonic_ns":224298251406500,"payload":{"event_type":"price_change","market":"0x717c0e8ccd4d5c7040185188fbae28be901ca589a11a94b1b38ca36a79eccfeb","price_changes":[{"asset_id":"41448400836309843603620980831210604935021861034693225347475867885462478926555","best_ask":"0.49","best_bid":"0.48","hash":"c0d7da7a33cd2855d2b081abfef28b1348467975","price":"0.43","side":"BUY","size":"31.4"},{"asset_id":"24254094493625419915756280046002869097156693848522361803041977572204227262166","best_ask":"0.52","best_bid":"0.51","hash":"9363dd6243b5040f127acee6ed62bfd03e547113","price":"0.57","side":"SELL","size":"31.4"}],"timestamp":"1785122315008"},"payload_hash":"501d796483938984c8fcc80010065369e3e00e4cb77c11b10dd4d2cabdc2c70f","raw_frame":"{\"market\":\"0x717c0e8ccd4d5c7040185188fbae28be901ca589a11a94b1b38ca36a79eccfeb\", \"price_changes\":[{\"asset_id\":\"41448400836309843603620980831210604935021861034693225347475867885462478926555\", \"price\":\"0.43\", \"size\":\"31.4\", \"side\":\"BUY\", \"hash\":\"c0d7da7a33cd2855d2b081abfef28b1348467975\", \"best_bid\":\"0.48\", \"best_ask\":\"0.49\"}, {\"asset_id\":\"24254094493625419915756280046002869097156693848522361803041977572204227262166\", \"price\":\"0.57\", \"size\":\"31.4\", \"side\":\"SELL\", \"hash\":\"9363dd6243b5040f127acee6ed62bfd03e547113\", \"best_bid\":\"0.51\", \"best_ask\":\"0.52\"}], \"timestamp\":\"1785122315008\", \"event_type\":\"price_change\"}","received_at":"2026-07-27T03:18:34.914731Z","schema_version":"clob-market-ws.price_change.v1","sequence":null,"server_hash":null,"server_timestamp":"1785122315008","session_id":"dd162b8dca5f43ff811d304e69a06123","source":"clob_market_ws"},"received_at":"2026-07-27T03:18:34.914731Z","record_id":"c98328c113aeda0f65d1ec4e4bbc2cc4371373393a14d757d879637d295c8103","schema_fingerprint":"4aa3821a28b0b7c2400bc59aba4bcc0a76e971dadd19610d3ad38c768e124dc7","schema_version":"edge-lab-recorder.raw.v1","sequence":null,"source":"clob_market_ws"}
{"event_at":"2026-07-27T03:18:35.010000Z","event_fingerprint":"3d16569aa55048baeef6c5d895565066dd87a8256a6ad537dedaeb949824c98c","payload":{"connection_id":"c7dc2e4762f849c6b6f9306b6518dcab","event_at":"2026-07-27T03:18:35.010000Z","event_type":"price_change","frame_hash":"f991361612d8c71218e5d619404f5f8718a7581ce63d6ee5d6a9c2a018ea0da8","frame_index":0,"kind":"data","monotonic_ns":224298253386708,"payload":{"event_type":"price_change","market":"0x717c0e8ccd4d5c7040185188fbae28be901ca589a11a94b1b38ca36a79eccfeb","price_changes":[{"asset_id":"41448400836309843603620980831210604935021861034693225347475867885462478926555","best_ask":"0.49","best_bid":"0.48","hash":"c77678a2b1f5cb441f369023c8fddb16fdf53633","price":"0.46","side":"BUY","size":"14.6"},{"asset_id":"24254094493625419915756280046002869097156693848522361803041977572204227262166","best_ask":"0.52","best_bid":"0.51","hash":"560cde609becdb120ac45a9d751cce57fb4b29c5","price":"0.54","side":"SELL","size":"14.6"}],"timestamp":"1785122315010"},"payload_hash":"fb03ff3880650183cbf09da9f21fb827c98d8062f7430e6643cb328c164644aa","raw_frame":"{\"market\":\"0x717c0e8ccd4d5c7040185188fbae28be901ca589a11a94b1b38ca36a79eccfeb\", \"price_changes\":[{\"asset_id\":\"41448400836309843603620980831210604935021861034693225347475867885462478926555\", \"price\":\"0.46\", \"size\":\"14.6\", \"side\":\"BUY\", \"hash\":\"c77678a2b1f5cb441f369023c8fddb16fdf53633\", \"best_bid\":\"0.48\", \"best_ask\":\"0.49\"}, {\"asset_id\":\"24254094493625419915756280046002869097156693848522361803041977572204227262166\", \"price\":\"0.54\", \"size\":\"14.6\", \"side\":\"SELL\", \"hash\":\"560cde609becdb120ac45a9d751cce57fb4b29c5\", \"best_bid\":\"0.51\", \"best_ask\":\"0.52\"}], \"timestamp\":\"1785122315010\", \"event_type\":\"price_change\"}","received_at":"2026-07-27T03:18:34.916712Z","schema_version":"clob-market-ws.price_change.v1","sequence":null,"server_hash":null,"server_timestamp":"1785122315010","session_id":"dd162b8dca5f43ff811d304e69a06123","source":"clob_market_ws"},"received_at":"2026-07-27T03:18:34.916712Z","record_id":"97421903db8a97124846fd008389a6c16830f18451033832dfd03d68cd156d5c","schema_fingerprint":"4aa3821a28b0b7c2400bc59aba4bcc0a76e971dadd19610d3ad38c768e124dc7","schema_version":"edge-lab-recorder.raw.v1","sequence":null,"source":"clob_market_ws"}
{"event_at":"2026-07-27T03:18:35.012000Z","event_fingerprint":"a628d16f09eae331b6e1efa4850753dc129f1850bda62950be825f5e9c7fbc5c","payload":{"connection_id":"c7dc2e4762f849c6b6f9306b6518dcab","event_at":"2026-07-27T03:18:35.012000Z","event_type":"price_change","frame_hash":"10b50b01e1acf7e0ceab321fb38275d05a9fd87627e597b4f48b1d9a9132ff5b","frame_index":0,"kind":"data","monotonic_ns":224298255524291,"payload":{"event_type":"price_change","market":"0x717c0e8ccd4d5c7040185188fbae28be901ca589a11a94b1b38ca36a79eccfeb","price_changes":[{"asset_id":"41448400836309843603620980831210604935021861034693225347475867885462478926555","best_ask":"0.49","best_bid":"0.48","hash":"44c2be22e6832e79888f3a888c7dd3a2ddbc74ab","price":"0.46","side":"BUY","size":"5"},{"asset_id":"24254094493625419915756280046002869097156693848522361803041977572204227262166","best_ask":"0.52","best_bid":"0.51","hash":"d41f49a09ffc5ad440f8cb220da207acd1f2d4d3","price":"0.54","side":"SELL","size":"5"}],"timestamp":"1785122315012"},"payload_hash":"23d5d4dbc6f190672e182c9749d658380481e27c99743b12860ea9e1d8cff8b7","raw_frame":"{\"market\":\"0x717c0e8ccd4d5c7040185188fbae28be901ca589a11a94b1b38ca36a79eccfeb\", \"price_changes\":[{\"asset_id\":\"41448400836309843603620980831210604935021861034693225347475867885462478926555\", \"price\":\"0.46\", \"size\":\"5\", \"side\":\"BUY\", \"hash\":\"44c2be22e6832e79888f3a888c7dd3a2ddbc74ab\", \"best_bid\":\"0.48\", \"best_ask\":\"0.49\"}, {\"asset_id\":\"24254094493625419915756280046002869097156693848522361803041977572204227262166\", \"price\":\"0.54\", \"size\":\"5\", \"side\":\"SELL\", \"hash\":\"d41f49a09ffc5ad440f8cb220da207acd1f2d4d3\", \"best_bid\":\"0.51\", \"best_ask\":\"0.52\"}], \"timestamp\":\"1785122315012\", \"event_type\":\"price_change\"}","received_at":"2026-07-27T03:18:34.918850Z","schema_version":"clob-market-ws.price_change.v1","sequence":null,"server_hash":null,"server_timestamp":"1785122315012","session_id":"dd162b8dca5f43ff811d304e69a06123","source":"clob_market_ws"},"received_at":"2026-07-27T03:18:34.918850Z","record_id":"3d4c5b5040a013efb20d99f0de8f5a234d42ff34a01c60e8b34a24845ad23d44","schema_fingerprint":"4aa3821a28b0b7c2400bc59aba4bcc0a76e971dadd19610d3ad38c768e124dc7","schema_version":"edge-lab-recorder.raw.v1","sequence":null,"source":"clob_market_ws"}
{"event_at":"2026-07-27T03:18:35.013000Z","event_fingerprint":"a6edf51b8381b568afe8dbc64cc2464b06445f1dad89c76b29b9710056b3f8e2","payload":{"connection_id":"c7dc2e4762f849c6b6f9306b6518dcab","event_at":"2026-07-27T03:18:35.013000Z","event_type":"price_change","frame_hash":"4798224b625454b652eccd1bfcc6ecf652e6dfacb1b7f45649d6c04bf67e121f","frame_index":0,"kind":"data","monotonic_ns":224298257473541,"payload":{"event_type":"price_change","market":"0x717c0e8ccd4d5c7040185188fbae28be901ca589a11a94b1b38ca36a79eccfeb","price_changes":[{"asset_id":"24254094493625419915756280046002869097156693848522361803041977572204227262166","best_ask":"0.52","best_bid":"0.51","hash":"ae94a2999ef5fcbea851f160e0482d342dee1fae","price":"0.51","side":"BUY","size":"174.34"},{"asset_id":"41448400836309843603620980831210604935021861034693225347475867885462478926555","best_ask":"0.49","best_bid":"0.48","hash":"7c7887b33f1306339a093b51e58ed3a714b63976","price":"0.49","side":"SELL","size":"174.34"}],"timestamp":"1785122315013"},"payload_hash":"4ce1aeed217db04174f63f3ef11280e55f3fb28af9860e2b186a1e94a98ea1c4","raw_frame":"{\"market\":\"0x717c0e8ccd4d5c7040185188fbae28be901ca589a11a94b1b38ca36a79eccfeb\", \"price_changes\":[{\"asset_id\":\"24254094493625419915756280046002869097156693848522361803041977572204227262166\", \"price\":\"0.51\", \"size\":\"174.34\", \"side\":\"BUY\", \"hash\":\"ae94a2999ef5fcbea851f160e0482d342dee1fae\", \"best_bid\":\"0.51\", \"best_ask\":\"0.52\"}, {\"asset_id\":\"41448400836309843603620980831210604935021861034693225347475867885462478926555\", \"price\":\"0.49\", \"size\":\"174.34\", \"side\":\"SELL\", \"hash\":\"7c7887b33f1306339a093b51e58ed3a714b63976\", \"best_bid\":\"0.48\", \"best_ask\":\"0.49\"}], \"timestamp\":\"1785122315013\", \"event_type\":\"price_change\"}","received_at":"2026-07-27T03:18:34.920800Z","schema_version":"clob-market-ws.price_change.v1","sequence":null,"server_hash":null,"server_timestamp":"1785122315013","session_id":"dd162b8dca5f43ff811d304e69a06123","source":"clob_market_ws"},"received_at":"2026-07-27T03:18:34.920800Z","record_id":"d7b8b686e72e50b8d3bfff00af7c44dea337c09a8b10f5d43cf1b748d3227112","schema_fingerprint":"4aa3821a28b0b7c2400bc59aba4bcc0a76e971dadd19610d3ad38c768e124dc7","schema_version":"edge-lab-recorder.raw.v1","sequence":null,"source":"clob_market_ws"}
{"event_at":"2026-07-27T03:18:35.014000Z","event_fingerprint":"a55bc96a372d582980112f3dcf25b3c76f5af941fced36ece89246da4d2c8bdf","payload":{"connection_id":"c7dc2e4762f849c6b6f9306b6518dcab","event_at":"2026-07-27T03:18:35.014000Z","event_type":"price_change","frame_hash":"bff024190b383d7a2e122dc7dc7c90a4c50e7dced1e1339fd6881d5ce4073bc9","frame_index":0,"kind":"data","monotonic_ns":224298258969958,"payload":{"event_type":"price_change","market":"0x717c0e8ccd4d5c7040185188fbae28be901ca589a11a94b1b38ca36a79eccfeb","price_changes":[{"asset_id":"41448400836309843603620980831210604935021861034693225347475867885462478926555","best_ask":"0.49","best_bid":"0.48","hash":"901cc95028360407bb72c69dd81e1f9a37e508ce","price":"0.47","side":"BUY","size":"0"},{"asset_id":"24254094493625419915756280046002869097156693848522361803041977572204227262166","best_ask":"0.52","best_bid":"0.51","hash":"286400b3d04913fa1c3530c02f2a2e2469ca9aa0","price":"0.53","side":"SELL","size":"0"}],"timestamp":"1785122315014"},"payload_hash":"8bb389e4723526b3cc01c7e3e45c1da531048e7b8a90c96c0bb9b8ca6a77a2fb","raw_frame":"{\"market\":\"0x717c0e8ccd4d5c7040185188fbae28be901ca589a11a94b1b38ca36a79eccfeb\", \"price_changes\":[{\"asset_id\":\"41448400836309843603620980831210604935021861034693225347475867885462478926555\", \"price\":\"0.47\", \"size\":\"0\", \"side\":\"BUY\", \"hash\":\"901cc95028360407bb72c69dd81e1f9a37e508ce\", \"best_bid\":\"0.48\", \"best_ask\":\"0.49\"}, {\"asset_id\":\"24254094493625419915756280046002869097156693848522361803041977572204227262166\", \"price\":\"0.53\", \"size\":\"0\", \"side\":\"SELL\", \"hash\":\"286400b3d04913fa1c3530c02f2a2e2469ca9aa0\", \"best_bid\":\"0.51\", \"best_ask\":\"0.52\"}], \"timestamp\":\"1785122315014\", \"event_type\":\"price_change\"}","received_at":"2026-07-27T03:18:34.922297Z","schema_version":"clob-market-ws.price_change.v1","sequence":null,"server_hash":null,"server_timestamp":"1785122315014","session_id":"dd162b8dca5f43ff811d304e69a06123","source":"clob_market_ws"},"received_at":"2026-07-27T03:18:34.922297Z","record_id":"d14d6cb6ebb31239f115424e92b84d5256a516980c4771e1adfa33d2f692d858","schema_fingerprint":"4aa3821a28b0b7c2400bc59aba4bcc0a76e971dadd19610d3ad38c768e124dc7","schema_version":"edge-lab-recorder.raw.v1","sequence":null,"source":"clob_market_ws"}
{"event_at":"2026-07-27T03:18:35.014000Z","event_fingerprint":"c44055b64996e2fce7b5fb096c2712dd78608eebad2c47e892dc16bc3b856f84","payload":{"connection_id":"c7dc2e4762f849c6b6f9306b6518dcab","event_at":"2026-07-27T03:18:35.014000Z","event_type":"price_change","frame_hash":"0fb32095a2e1833ee8348ad640b2850068ca136bf24c247b85b509ab110c195e","frame_index":0,"kind":"data","monotonic_ns":224298261190166,"payload":{"event_type":"price_change","market":"0x717c0e8ccd4d5c7040185188fbae28be901ca589a11a94b1b38ca36a79eccfeb","price_changes":[{"asset_id":"24254094493625419915756280046002869097156693848522361803041977572204227262166","best_ask":"0.52","best_bid":"0.51","hash":"286400b3d04913fa1c3530c02f2a2e2469ca9aa0","price":"0.49","side":"BUY","size":"282.24"},{"asset_id":"41448400836309843603620980831210604935021861034693225347475867885462478926555","best_ask":"0.49","best_bid":"0.48","hash":"901cc95028360407bb72c69dd81e1f9a37e508ce","price":"0.51","side":"SELL","size":"282.24"}],"timestamp":"1785122315014"},"payload_hash":"e40ae014e8f5483a6f51678da29a151376b29afc2752e5e2ee50195f94b86d93","raw_frame":"{\"market\":\"0x717c0e8ccd4d5c7040185188fbae28be901ca589a11a94b1b38ca36a79eccfeb\", \"price_changes\":[{\"asset_id\":\"24254094493625419915756280046002869097156693848522361803041977572204227262166\", \"price\":\"0.49\", \"size\":\"282.24\", \"side\":\"BUY\", \"hash\":\"286400b3d04913fa1c3530c02f2a2e2469ca9aa0\", \"best_bid\":\"0.51\", \"best_ask\":\"0.52\"}, {\"asset_id\":\"41448400836309843603620980831210604935021861034693225347475867885462478926555\", \"price\":\"0.51\", \"size\":\"282.24\", \"side\":\"SELL\", \"hash\":\"901cc95028360407bb72c69dd81e1f9a37e508ce\", \"best_bid\":\"0.48\", \"best_ask\":\"0.49\"}], \"timestamp\":\"1785122315014\", \"event_type\":\"price_change\"}","received_at":"2026-07-27T03:18:34.924515Z","schema_version":"clob-market-ws.price_change.v1","sequence":null,"server_hash":null,"server_timestamp":"1785122315014","session_id":"dd162b8dca5f43ff811d304e69a06123","source":"clob_market_ws"},"received_at":"2026-07-27T03:18:34.924515Z","record_id":"6df5e5218e2266ad390edae5c3415181ce9f0c0d1a9dfb386c5c830b1f4ca713","schema_fingerprint":"4aa3821a28b0b7c2400bc59aba4bcc0a76e971dadd19610d3ad38c768e124dc7","schema_version":"edge-lab-recorder.raw.v1","sequence":null,"source":"clob_market_ws"}
{"event_at":"2026-07-27T03:18:35.015000Z","event_fingerprint":"7bc5a68a4e03872d3be89dced29d494651a71ed6d07b9314de1098680ad653bb","payload":{"connection_id":"c7dc2e4762f849c6b6f9306b6518dcab","event_at":"2026-07-27T03:18:35.015000Z","event_type":"best_bid_ask","frame_hash":"99f603917a0f4fde7a196a1cdcafc4881469a34cedd0508e205e3273aa1dfe60","frame_index":0,"kind":"data","monotonic_ns":224298263764875,"payload":{"asset_id":"24254094493625419915756280046002869097156693848522361803041977572204227262166","best_ask":"0.54","best_bid":"0.51","event_type":"best_bid_ask","market":"0x717c0e8ccd4d5c7040185188fbae28be901ca589a11a94b1b38ca36a79eccfeb","spread":"0.03","timestamp":"1785122315015"},"payload_hash":"9df45f10438914547c55a0cb9186e2c45dc44633e5dc171a1c4d122240c9c69c","raw_frame":"{\"market\":\"0x717c0e8ccd4d5c7040185188fbae28be901ca589a11a94b1b38ca36a79eccfeb\", \"asset_id\":\"24254094493625419915756280046002869097156693848522361803041977572204227262166\", \"best_bid\":\"0.51\", \"best_ask\":\"0.54\", \"spread\":\"0.03\", \"timestamp\":\"1785122315015\", \"event_type\":\"best_bid_ask\"}","received_at":"2026-07-27T03:18:34.927091Z","schema_version":"clob-market-ws.best_bid_ask.v1","sequence":null,"server_hash":null,"server_timestamp":"1785122315015","session_id":"dd162b8dca5f43ff811d304e69a06123","source":"clob_market_ws"},"received_at":"2026-07-27T03:18:34.927091Z","record_id":"920ef6c51a76df088948ac276ee1720d5b7291fa144d8f263bd1b16ad55449a0","schema_fingerprint":"8488399f31b0337811b13b266be932db7062827c2470b78bd8e9e99bab51d17d","schema_version":"edge-lab-recorder.raw.v1","sequence":null,"source":"clob_market_ws"}
{"event_at":"2026-07-27T03:18:35.015000Z","event_fingerprint":"8fddd6b48fb6819b3cefdc93630d2e386896d7c89844030d927c9ddec15ba502","payload":{"connection_id":"c7dc2e4762f849c6b6f9306b6518dcab","event_at":"2026-07-27T03:18:35.015000Z","event_type":"best_bid_ask","frame_hash":"a92e1bef6ea9fb867f9ea06fd4327b5d5b3054dcab885735f7664234bd2823ba","frame_index":0,"kind":"data","monotonic_ns":224298265431500,"payload":{"asset_id":"41448400836309843603620980831210604935021861034693225347475867885462478926555","best_ask":"0.49","best_bid":"0.46","event_type":"best_bid_ask","market":"0x717c0e8ccd4d5c7040185188fbae28be901ca589a11a94b1b38ca36a79eccfeb","spread":"0.03","timestamp":"1785122315015"},"payload_hash":"6b5994f933ecef608300c03441ff2b0e22abdd62be3dae10de44b75ff4b04b56","raw_frame":"{\"market\":\"0x717c0e8ccd4d5c7040185188fbae28be901ca589a11a94b1b38ca36a79eccfeb\", \"asset_id\":\"41448400836309843603620980831210604935021861034693225347475867885462478926555\", \"best_bid\":\"0.46\", \"best_ask\":\"0.49\", \"spread\":\"0.03\", \"timestamp\":\"1785122315015\", \"event_type\":\"best_bid_ask\"}","received_at":"2026-07-27T03:18:34.928758Z","schema_version":"clob-market-ws.best_bid_ask.v1","sequence":null,"server_hash":null,"server_timestamp":"1785122315015","session_id":"dd162b8dca5f43ff811d304e69a06123","source":"clob_market_ws"},"received_at":"2026-07-27T03:18:34.928758Z","record_id":"5de687b26497c57e5a5aefc734536af62e0f554bb1dd8080670598b098a7150e","schema_fingerprint":"8488399f31b0337811b13b266be932db7062827c2470b78bd8e9e99bab51d17d","schema_version":"edge-lab-recorder.raw.v1","sequence":null,"source":"clob_market_ws"}
{"event_at":"2026-07-27T03:18:35.015000Z","event_fingerprint":"b03948e99cabd08977e7d0833419ca1021c393700d5937c2b7b3f90336a605ed","payload":{"connection_id":"c7dc2e4762f849c6b6f9306b6518dcab","event_at":"2026-07-27T03:18:35.015000Z","event_type":"price_change","frame_hash":"9df96ddf1a28088f632a1ac307d4db2862115818e75572f0488c1ca06418b0ad","frame_index":0,"kind":"data","monotonic_ns":224298267192375,"payload":{"event_type":"price_change","market":"0x717c0e8ccd4d5c7040185188fbae28be901ca589a11a94b1b38ca36a79eccfeb","price_changes":[{"asset_id":"41448400836309843603620980831210604935021861034693225347475867885462478926555","best_ask":"0.49","best_bid":"0.46","hash":"90cec1d26b89286741925b9de9fa4f2a08dfb915","price":"0.48","side":"BUY","size":"0"},{"asset_id":"24254094493625419915756280046002869097156693848522361803041977572204227262166","best_ask":"0.54","best_bid":"0.51","hash":"e93db3fd1a48f4efd369bdd5031ae8383f50b608","price":"0.52","side":"SELL","size":"0"}],"timestamp":"1785122315015"},"payload_hash":"c289be08b3f6bdc439cdda603134436d85a85d3d926c9d91dbf6a2a7b99e6df2","raw_frame":"{\"market\":\"0x717c0e8ccd4d5c7040185188fbae28be901ca589a11a94b1b38ca36a79eccfeb\", \"price_changes\":[{\"asset_id\":\"41448400836309843603620980831210604935021861034693225347475867885462478926555\", \"price\":\"0.48\", \"size\":\"0\", \"side\":\"BUY\", \"hash\":\"90cec1d26b89286741925b9de9fa4f2a08dfb915\", \"best_bid\":\"0.46\", \"best_ask\":\"0.49\"}, {\"asset_id\":\"24254094493625419915756280046002869097156693848522361803041977572204227262166\", \"price\":\"0.52\", \"size\":\"0\", \"side\":\"SELL\", \"hash\":\"e93db3fd1a48f4efd369bdd5031ae8383f50b608\", \"best_bid\":\"0.51\", \"best_ask\":\"0.54\"}], \"timestamp\":\"1785122315015\", \"event_type\":\"price_change\"}","received_at":"2026-07-27T03:18:34.930519Z","schema_version":"clob-market-ws.price_change.v1","sequence":null,"server_hash":null,"server_timestamp":"1785122315015","session_id":"dd162b8dca5f43ff811d304e69a06123","source":"clob_market_ws"},"received_at":"2026-07-27T03:18:34.930519Z","record_id":"3140f1f7a267b524d8ea8ce98e1783e61f6b2384ae0fd5e6ded92fdf23e47af5","schema_fingerprint":"4aa3821a28b0b7c2400bc59aba4bcc0a76e971dadd19610d3ad38c768e124dc7","schema_version":"edge-lab-recorder.raw.v1","sequence":null,"source":"clob_market_ws"}
{"event_at":"2026-07-27T03:18:35.019000Z","event_fingerprint":"796af6628b5c12a24076a3e15c39ccfdaac09216cef366018e7ad2dd28260034","payload":{"connection_id":"c7dc2e4762f849c6b6f9306b6518dcab","event_at":"2026-07-27T03:18:35.019000Z","event_type":"price_change","frame_hash":"4031b9aa349596448b3ea97bdf0eb735acf7f1827ce2079517075520f58fae8a","frame_index":0,"kind":"data","monotonic_ns":224298269049458,"payload":{"event_type":"price_change","market":"0x717c0e8ccd4d5c7040185188fbae28be901ca589a11a94b1b38ca36a79eccfeb","price_changes":[{"asset_id":"24254094493625419915756280046002869097156693848522361803041977572204227262166","best_ask":"0.54","best_bid":"0.51","hash":"b23744d795f8d67eeebb5a4b56488fa8fd9e838d","price":"0.02","side":"BUY","size":"738.1"},{"asset_id":"41448400836309843603620980831210604935021861034693225347475867885462478926555","best_ask":"0.49","best_bid":"0.46","hash":"e548f5b28d956761ecadb41def77222044c47022","price":"0.98","side":"SELL","size":"738.1"}],"timestamp":"1785122315019"},"payload_hash":"bf472921fafd42df30897ab69cae5f6d2c1f18c20c03cd457aa1e88637a84e5f","raw_frame":"{\"market\":\"0x717c0e8ccd4d5c7040185188fbae28be901ca589a11a94b1b38ca36a79eccfeb\", \"price_changes\":[{\"asset_id\":\"24254094493625419915756280046002869097156693848522361803041977572204227262166\", \"price\":\"0.02\", \"size\":\"738.1\", \"side\":\"BUY\", \"hash\":\"b23744d795f8d67eeebb5a4b56488fa8fd9e838d\", \"best_bid\":\"0.51\", \"best_ask\":\"0.54\"}, {\"asset_id\":\"41448400836309843603620980831210604935021861034693225347475867885462478926555\", \"price\":\"0.98\", \"size\":\"738.1\", \"side\":\"SELL\", \"hash\":\"e548f5b28d956761ecadb41def77222044c47022\", \"best_bid\":\"0.46\", \"best_ask\":\"0.49\"}], \"timestamp\":\"1785122315019\", \"event_type\":\"price_change\"}","received_at":"2026-07-27T03:18:34.932376Z","schema_version":"clob-market-ws.price_change.v1","sequence":null,"server_hash":null,"server_timestamp":"1785122315019","session_id":"dd162b8dca5f43ff811d304e69a06123","source":"clob_market_ws"},"received_at":"2026-07-27T03:18:34.932376Z","record_id":"8c8b3ebe4ba084058f4b57a8f0b503295e92a86f971b8bf08c4effcdc87e3d73","schema_fingerprint":"4aa3821a28b0b7c2400bc59aba4bcc0a76e971dadd19610d3ad38c768e124dc7","schema_version":"edge-lab-recorder.raw.v1","sequence":null,"source":"clob_market_ws"}
{"event_at":"2026-07-27T03:18:35.020000Z","event_fingerprint":"13187b9779192330ff93ae34de5ea26acfca9162e7b95b086c088a0bbac88a50","payload":{"connection_id":"c7dc2e4762f849c6b6f9306b6518dcab","event_at":"2026-07-27T03:18:35.020000Z","event_type":"price_change","frame_hash":"1c4006d7198545a359aaf96bed641f2cbada1fa55e8b8866e6d73b8911ad427a","frame_index":0,"kind":"data","monotonic_ns":224298270650958,"payload":{"event_type":"price_change","market":"0x717c0e8ccd4d5c7040185188fbae28be901ca589a11a94b1b38ca36a79eccfeb","price_changes":[{"asset_id":"41448400836309843603620980831210604935021861034693225347475867885462478926555","best_ask":"0.49","best_bid":"0.46","hash":"5ec76aff325ff5c3d60500033134dec2d8646c1d","price":"0.01","side":"BUY","size":"7708.02"},{"asset_id":"24254094493625419915756280046002869097156693848522361803041977572204227262166","best_ask":"0.54","best_bid":"0.51","hash":"5230937b38d9ed8d57cead768cda14e89a5bdba5","price":"0.99","side":"SELL","size":"7708.02"}],"timestamp":"1785122315020"},"payload_hash":"a13a3b94b5c2a24da46dabbb94c02f5a747714994acf1ea6224070ebc5f29001","raw_frame":"{\"market\":\"0x717c0e8ccd4d5c7040185188fbae28be901ca589a11a94b1b38ca36a79eccfeb\", \"price_changes\":[{\"asset_id\":\"41448400836309843603620980831210604935021861034693225347475867885462478926555\", \"price\":\"0.01\", \"size\":\"7708.02\", \"side\":\"BUY\", \"hash\":\"5ec76aff325ff5c3d60500033134dec2d8646c1d\", \"best_bid\":\"0.46\", \"best_ask\":\"0.49\"}, {\"asset_id\":\"24254094493625419915756280046002869097156693848522361803041977572204227262166\", \"price\":\"0.99\", \"size\":\"7708.02\", \"side\":\"SELL\", \"hash\":\"5230937b38d9ed8d57cead768cda14e89a5bdba5\", \"best_bid\":\"0.51\", \"best_ask\":\"0.54\"}], \"timestamp\":\"1785122315020\", \"event_type\":\"price_change\"}","received_at":"2026-07-27T03:18:34.933977Z","schema_version":"clob-market-ws.price_change.v1","sequence":null,"server_hash":null,"server_timestamp":"1785122315020","session_id":"dd162b8dca5f43ff811d304e69a06123","source":"clob_market_ws"},"received_at":"2026-07-27T03:18:34.933977Z","record_id":"928ec2f3140f21b62480586b457ceea1461aec21e4fe9f6e720f581eba47e8e1","schema_fingerprint":"4aa3821a28b0b7c2400bc59aba4bcc0a76e971dadd19610d3ad38c768e124dc7","schema_version":"edge-lab-recorder.raw.v1","sequence":null,"source":"clob_market_ws"}
{"event_at":"2026-07-27T03:18:35.021000Z","event_fingerprint":"0a0d12cbdc5438bf14bc2900ee07ecaf7799f252a7f885c6bc4889b271aca677","payload":{"connection_id":"c7dc2e4762f849c6b6f9306b6518dcab","event_at":"2026-07-27T03:18:35.021000Z","event_type":"price_change","frame_hash":"c898dc0717ede543ed364ecbf17621afbe50307676064475075523c0eda80ef2","frame_index":0,"kind":"data","monotonic_ns":224298272779958,"payload":{"event_type":"price_change","market":"0x717c0e8ccd4d5c7040185188fbae28be901ca589a11a94b1b38ca36a79eccfeb","price_changes":[{"asset_id":"41448400836309843603620980831210604935021861034693225347475867885462478926555","best_ask":"0.49","best_bid":"0.46","hash":"7c142fd61c9b2ef4c540d707cd0ea3c659310a87","price":"0.01","side":"BUY","size":"7713.02"},{"asset_id":"24254094493625419915756280046002869097156693848522361803041977572204227262166","best_ask":"0.54","best_bid":"0.51","hash":"8943352490dc8f41cd9af14895b69044452b33c8","price":"0.99","side":"SELL","size":"7713.02"}],"timestamp":"1785122315021"},"payload_hash":"dfe446977f000760d6e43ec1d1af354e21d1487942517f39187ac20a53ba7925","raw_frame":"{\"market\":\"0x717c0e8ccd4d5c7040185188fbae28be901ca589a11a94b1b38ca36a79eccfeb\", \"price_changes\":[{\"asset_id\":\"41448400836309843603620980831210604935021861034693225347475867885462478926555\", \"price\":\"0.01\", \"size\":\"7713.02\", \"side\":\"BUY\", \"hash\":\"7c142fd61c9b2ef4c540d707cd0ea3c659310a87\", \"best_bid\":\"0.46\", \"best_ask\":\"0.49\"}, {\"asset_id\":\"24254094493625419915756280046002869097156693848522361803041977572204227262166\", \"price\":\"0.99\", \"size\":\"7713.02\", \"side\":\"SELL\", \"hash\":\"8943352490dc8f41cd9af14895b69044452b33c8\", \"best_bid\":\"0.51\", \"best_ask\":\"0.54\"}], \"timestamp\":\"1785122315021\", \"event_type\":\"price_change\"}","received_at":"2026-07-27T03:18:34.936105Z","schema_version":"clob-market-ws.price_change.v1","sequence":null,"server_hash":null,"server_timestamp":"1785122315021","session_id":"dd162b8dca5f43ff811d304e69a06123","source":"clob_market_ws"},"received_at":"2026-07-27T03:18:34.936105Z","record_id":"29de7bbc3a847584bd58141b449b0ff8d5c5e432161ab165b3dc66976e0fc8bf","schema_fingerprint":"4aa3821a28b0b7c2400bc59aba4bcc0a76e971dadd19610d3ad38c768e124dc7","schema_version":"edge-lab-recorder.raw.v1","sequence":null,"source":"clob_market_ws"}
{"event_at":"2026-07-27T03:18:35.031000Z","event_fingerprint":"ae705f4e852eae06912a3d9ffae3bd43c4e1646d282247b91915fb8409c45588","payload":{"connection_id":"c7dc2e4762f849c6b6f9306b6518dcab","event_at":"2026-07-27T03:18:35.031000Z","event_type":"price_change","frame_hash":"60c16ee1a7c767f300f3da6bc2c1940ccdc1731a58e50a1e06974f47f36859cd","frame_index":0,"kind":"data","monotonic_ns":224298275272541,"payload":{"event_type":"price_change","market":"0x717c0e8ccd4d5c7040185188fbae28be901ca589a11a94b1b38ca36a79eccfeb","price_changes":[{"asset_id":"24254094493625419915756280046002869097156693848522361803041977572204227262166","best_ask":"0.54","best_bid":"0.51","hash":"85f709c0cf426bc3e92d4f1fab9b17435b024177","price":"0.51","side":"BUY","size":"169.34"},{"asset_id":"41448400836309843603620980831210604935021861034693225347475867885462478926555","best_ask":"0.49","best_bid":"0.46","hash":"c035000e737618fd1fdbd0e36e9032d5658b3a0f","price":"0.49","side":"SELL","size":"169.34"}],"timestamp":"1785122315031"},"payload_hash":"a74cb838a045e495bba884255210f54982dbbb9b242960ab24219f1b9decb9ba","raw_frame":"{\"market\":\"0x717c0e8ccd4d5c7040185188fbae28be901ca589a11a94b1b38ca36a79eccfeb\", \"price_changes\":[{\"asset_id\":\"24254094493625419915756280046002869097156693848522361803041977572204227262166\", \"price\":\"0.51\", \"size\":\"169.34\", \"side\":\"BUY\", \"hash\":\"85f709c0cf426bc3e92d4f1fab9b17435b024177\", \"best_bid\":\"0.51\", \"best_ask\":\"0.54\"}, {\"asset_id\":\"41448400836309843603620980831210604935021861034693225347475867885462478926555\", \"price\":\"0.49\", \"size\":\"169.34\", \"side\":\"SELL\", \"hash\":\"c035000e737618fd1fdbd0e36e9032d5658b3a0f\", \"best_bid\":\"0.46\", \"best_ask\":\"0.49\"}], \"timestamp\":\"1785122315031\", \"event_type\":\"price_change\"}","received_at":"2026-07-27T03:18:34.938597Z","schema_version":"clob-market-ws.price_change.v1","sequence":null,"server_hash":null,"server_timestamp":"1785122315031","session_id":"dd162b8dca5f43ff811d304e69a06123","source":"clob_market_ws"},"received_at":"2026-07-27T03:18:34.938597Z","record_id":"fae679b6892b9d8a688233566d9559e1e86e28639fe0288586120ef8b280de73","schema_fingerprint":"4aa3821a28b0b7c2400bc59aba4bcc0a76e971dadd19610d3ad38c768e124dc7","schema_version":"edge-lab-recorder.raw.v1","sequence":null,"source":"clob_market_ws"}
{"event_at":"2026-07-27T03:18:35.033000Z","event_fingerprint":"5f5fab15d415f9cf80acae19cbdcb949a45995526bfb79290ea1f8f71b292937","payload":{"connection_id":"c7dc2e4762f849c6b6f9306b6518dcab","event_at":"2026-07-27T03:18:35.033000Z","event_type":"price_change","frame_hash":"1a30ad1b16665ca4ebd56ed9c703c31097d41d8d288c5bfc945b1f38d9eec843","frame_index":0,"kind":"data","monotonic_ns":224298277415708,"payload":{"event_type":"price_change","market":"0x717c0e8ccd4d5c7040185188fbae28be901ca589a11a94b1b38ca36a79eccfeb","price_changes":[{"asset_id":"41448400836309843603620980831210604935021861034693225347475867885462478926555","best_ask":"0.49","best_bid":"0.46","hash":"109be7b9d99652917345f51b4320e16b79456dc2","price":"0.45","side":"BUY","size":"56.4"},{"asset_id":"24254094493625419915756280046002869097156693848522361803041977572204227262166","best_ask":"0.54","best_bid":"0.51","hash":"b5de3d68b91e4e04641675be1ce5f1f39bc0d5e9","price":"0.55","side":"SELL","size":"56.4"}],"timestamp":"1785122315033"},"payload_hash":"a55e680f0ca47c71598e0dc5ac1792648efe0ae23c480e6cbdf2759ff9611d3b","raw_frame":"{\"market\":\"0x717c0e8ccd4d5c7040185188fbae28be901ca589a11a94b1b38ca36a79eccfeb\", \"price_changes\":[{\"asset_id\":\"41448400836309843603620980831210604935021861034693225347475867885462478926555\", \"price\":\"0.45\", \"size\":\"56.4\", \"side\":\"BUY\", \"hash\":\"109be7b9d99652917345f51b4320e16b79456dc2\", \"best_bid\":\"0.46\", \"best_ask\":\"0.49\"}, {\"asset_id\":\"24254094493625419915756280046002869097156693848522361803041977572204227262166\", \"price\":\"0.55\", \"size\":\"56.4\", \"side\":\"SELL\", \"hash\":\"b5de3d68b91e4e04641675be1ce5f1f39bc0d5e9\", \"best_bid\":\"0.51\", \"best_ask\":\"0.54\"}], \"timestamp\":\"1785122315033\", \"event_type\":\"price_change\"}","received_at":"2026-07-27T03:18:34.940742Z","schema_version":"clob-market-ws.price_change.v1","sequence":null,"server_hash":null,"server_timestamp":"1785122315033","session_id":"dd162b8dca5f43ff811d304e69a06123","source":"clob_market_ws"},"received_at":"2026-07-27T03:18:34.940742Z","record_id":"6a4f75503d7d1d6506f6b4f7d5221b5e6d9f25f98b9d10bc816fd89d225a7744","schema_fingerprint":"4aa3821a28b0b7c2400bc59aba4bcc0a76e971dadd19610d3ad38c768e124dc7","schema_version":"edge-lab-recorder.raw.v1","sequence":null,"source":"clob_market_ws"}
{"event_at":"2026-07-27T03:18:35.033000Z","event_fingerprint":"adc1908aa6cbb1d5dfb4917a52f88eba09b3e5c9a6a757024c7b6c127503a313","payload":{"connection_id":"c7dc2e4762f849c6b6f9306b6518dcab","event_at":"2026-07-27T03:18:35.033000Z","event_type":"price_change","frame_hash":"2570db4ad9e42246d7b2cfd2da5990f7d21df39771e2ebcf7c612a918b641da0","frame_index":0,"kind":"data","monotonic_ns":224298279116125,"payload":{"event_type":"price_change","market":"0x717c0e8ccd4d5c7040185188fbae28be901ca589a11a94b1b38ca36a79eccfeb","price_changes":[{"asset_id":"24254094493625419915756280046002869097156693848522361803041977572204227262166","best_ask":"0.54","best_bid":"0.51","hash":"548bf36d6023835c4104cb63911323d9d8d8992e","price":"0.36","side":"BUY","size":"210.59"},{"asset_id":"41448400836309843603620980831210604935021861034693225347475867885462478926555","best_ask":"0.49","best_bid":"0.46","hash":"340b4eef57e1ab7eb1cbf7f42fc5e07b61e1b04f","price":"0.64","side":"SELL","size":"210.59"}],"timestamp":"1785122315033"},"payload_hash":"143735517c1a662f2e2415974dea40934feff884b4590dd93b1febe392aa9845","raw_frame":"{\"market\":\"0x717c0e8ccd4d5c7040185188fbae28be901ca589a11a94b1b38ca36a79eccfeb\", \"price_changes\":[{\"asset_id\":\"24254094493625419915756280046002869097156693848522361803041977572204227262166\", \"price\":\"0.36\", \"size\":\"210.59\", \"side\":\"BUY\", \"hash\":\"548bf36d6023835c4104cb63911323d9d8d8992e\", \"best_bid\":\"0.51\", \"best_ask\":\"0.54\"}, {\"asset_id\":\"41448400836309843603620980831210604935021861034693225347475867885462478926555\", \"price\":\"0.64\", \"size\":\"210.59\", \"side\":\"SELL\", \"hash\":\"340b4eef57e1ab7eb1cbf7f42fc5e07b61e1b04f\", \"best_bid\":\"0.46\", \"best_ask\":\"0.49\"}], \"timestamp\":\"1785122315033\", \"event_type\":\"price_change\"}","received_at":"2026-07-27T03:18:34.942442Z","schema_version":"clob-market-ws.price_change.v1","sequence":null,"server_hash":null,"server_timestamp":"1785122315033","session_id":"dd162b8dca5f43ff811d304e69a06123","source":"clob_market_ws"},"received_at":"2026-07-27T03:18:34.942442Z","record_id":"61cfb5be8800af535490d64d8e1dee9a3121c3ff82a8a3364117348912c01459","schema_fingerprint":"4aa3821a28b0b7c2400bc59aba4bcc0a76e971dadd19610d3ad38c768e124dc7","schema_version":"edge-lab-recorder.raw.v1","sequence":null,"source":"clob_market_ws"}
{"event_at":"2026-07-27T03:18:35.034000Z","event_fingerprint":"f77064c999cb7c1f94c4bb57dfe40e7a0bd5069aa37908e812367c254c007934","payload":{"connection_id":"c7dc2e4762f849c6b6f9306b6518dcab","event_at":"2026-07-27T03:18:35.034000Z","event_type":"price_change","frame_hash":"252256f1b1797bc078c7604272e9ef9f885609c8bdfcdda92a2ea38b58a6f466","frame_index":0,"kind":"data","monotonic_ns":224298281586666,"payload":{"event_type":"price_change","market":"0x717c0e8ccd4d5c7040185188fbae28be901ca589a11a94b1b38ca36a79eccfeb","price_changes":[{"asset_id":"24254094493625419915756280046002869097156693848522361803041977572204227262166","best_ask":"0.54","best_bid":"0.51","hash":"4d7984e50d79fbee1cdd052956a994bc21852048","price":"0.51","side":"BUY","size":"164.34"},{"asset_id":"41448400836309843603620980831210604935021861034693225347475867885462478926555","best_ask":"0.49","best_bid":"0.46","hash":"cd49c1d5275dd3faef19e9c808b107d822b54caa","price":"0.49","side":"SELL","size":"164.34"}],"timestamp":"1785122315034"},"payload_hash":"4b95ab980bc5585e697a84adf27c97ff0ee20228eb7b15711852d3cec5b338bc","raw_frame":"{\"market\":\"0x717c0e8ccd4d5c7040185188fbae28be901ca589a11a94b1b38ca36a79eccfeb\", \"price_changes\":[{\"asset_id\":\"24254094493625419915756280046002869097156693848522361803041977572204227262166\", \"price\":\"0.51\", \"size\":\"164.34\", \"side\":\"BUY\", \"hash\":\"4d7984e50d79fbee1cdd052956a994bc21852048\", \"best_bid\":\"0.51\", \"best_ask\":\"0.54\"}, {\"asset_id\":\"41448400836309843603620980831210604935021861034693225347475867885462478926555\", \"price\":\"0.49\", \"size\":\"164.34\", \"side\":\"SELL\", \"hash\":\"cd49c1d5275dd3faef19e9c808b107d822b54caa\", \"best_bid\":\"0.46\", \"best_ask\":\"0.49\"}], \"timestamp\":\"1785122315034\", \"event_type\":\"price_change\"}","received_at":"2026-07-27T03:18:34.944911Z","schema_version":"clob-market-ws.price_change.v1","sequence":null,"server_hash":null,"server_timestamp":"1785122315034","session_id":"dd162b8dca5f43ff811d304e69a06123","source":"clob_market_ws"},"received_at":"2026-07-27T03:18:34.944911Z","record_id":"d796f5fdc24bea01e0b28d88feeca720288458833f02ed33ba6e1df68687f206","schema_fingerprint":"4aa3821a28b0b7c2400bc59aba4bcc0a76e971dadd19610d3ad38c768e124dc7","schema_version":"edge-lab-recorder.raw.v1","sequence":null,"source":"clob_market_ws"}
{"event_at":"2026-07-27T03:18:35.035000Z","event_fingerprint":"1ad2de5abd496286d6bf2d7ef088a76dfeb6a5e29f332eaf2348cab4c251ef4f","payload":{"connection_id":"c7dc2e4762f849c6b6f9306b6518dcab","event_at":"2026-07-27T03:18:35.035000Z","event_type":"best_bid_ask","frame_hash":"056908c33f5b8ffbc12781851e73d56a4d04d260d569cbf17272d451176e5705","frame_index":0,"kind":"data","monotonic_ns":224298283626666,"payload":{"asset_id":"24254094493625419915756280046002869097156693848522361803041977572204227262166","best_ask":"0.54","best_bid":"0.52","event_type":"best_bid_ask","market":"0x717c0e8ccd4d5c7040185188fbae28be901ca589a11a94b1b38ca36a79eccfeb","spread":"0.02","timestamp":"1785122315035"},"payload_hash":"66ebfd488a265b2f2021491676d6df8227a5c5ea49312d065568640ae53fccea","raw_frame":"{\"market\":\"0x717c0e8ccd4d5c7040185188fbae28be901ca589a11a94b1b38ca36a79eccfeb\", \"asset_id\":\"24254094493625419915756280046002869097156693848522361803041977572204227262166\", \"best_bid\":\"0.52\", \"best_ask\":\"0.54\", \"spread\":\"0.02\", \"timestamp\":\"1785122315035\", \"event_type\":\"best_bid_ask\"}","received_at":"2026-07-27T03:18:34.946949Z","schema_version":"clob-market-ws.best_bid_ask.v1","sequence":null,"server_hash":null,"server_timestamp":"1785122315035","session_id":"dd162b8dca5f43ff811d304e69a06123","source":"clob_market_ws"},"received_at":"2026-07-27T03:18:34.946949Z","record_id":"a79a7c3b4a4addbeb81fbfda7680304ada12bb5a2791de2cd291ca7f6245e21d","schema_fingerprint":"8488399f31b0337811b13b266be932db7062827c2470b78bd8e9e99bab51d17d","schema_version":"edge-lab-recorder.raw.v1","sequence":null,"source":"clob_market_ws"}
{"event_at":"2026-07-27T03:18:35.035000Z","event_fingerprint":"fe227de5dd809866804be959371c8d48eb9b56d76339973a9678392209fa143c","payload":{"connection_id":"c7dc2e4762f849c6b6f9306b6518dcab","event_at":"2026-07-27T03:18:35.035000Z","event_type":"best_bid_ask","frame_hash":"f4ff40ee0a13407551d29d0bd7f60342c605e8aa44c8631009badafd9da7da2f","frame_index":0,"kind":"data","monotonic_ns":224298284811666,"payload":{"asset_id":"41448400836309843603620980831210604935021861034693225347475867885462478926555","best_ask":"0.48","best_bid":"0.46","event_type":"best_bid_ask","market":"0x717c0e8ccd4d5c7040185188fbae28be901ca589a11a94b1b38ca36a79eccfeb","spread":"0.02","timestamp":"1785122315035"},"payload_hash":"b9320bef4f89d33700f9464b582ba352c03e9f920cb8041a0ed05cd89745c855","raw_frame":"{\"market\":\"0x717c0e8ccd4d5c7040185188fbae28be901ca589a11a94b1b38ca36a79eccfeb\", \"asset_id\":\"41448400836309843603620980831210604935021861034693225347475867885462478926555\", \"best_bid\":\"0.46\", \"best_ask\":\"0.48\", \"spread\":\"0.02\", \"timestamp\":\"1785122315035\", \"event_type\":\"best_bid_ask\"}","received_at":"2026-07-27T03:18:34.948138Z","schema_version":"clob-market-ws.best_bid_ask.v1","sequence":null,"server_hash":null,"server_timestamp":"1785122315035","session_id":"dd162b8dca5f43ff811d304e69a06123","source":"clob_market_ws"},"received_at":"2026-07-27T03:18:34.948138Z","record_id":"e835d97c9089c7c0e4c560eed8e3f14053934df17f063762359e1792ab97c1b3","schema_fingerprint":"8488399f31b0337811b13b266be932db7062827c2470b78bd8e9e99bab51d17d","schema_version":"edge-lab-recorder.raw.v1","sequence":null,"source":"clob_market_ws"}
{"event_at":"2026-07-27T03:18:35.035000Z","event_fingerprint":"e7055be00122ba2d2d543b183dac037b97a8104659343d835fce8c0910dca0af","payload":{"connection_id":"c7dc2e4762f849c6b6f9306b6518dcab","event_at":"2026-07-27T03:18:35.035000Z","event_type":"price_change","frame_hash":"b14f129b469342eedd14c920ffce3cc8b5169dd44595a106a2c377b7c5820dba","frame_index":0,"kind":"data","monotonic_ns":224298286939916,"payload":{"event_type":"price_change","market":"0x717c0e8ccd4d5c7040185188fbae28be901ca589a11a94b1b38ca36a79eccfeb","price_changes":[{"asset_id":"24254094493625419915756280046002869097156693848522361803041977572204227262166","best_ask":"0.54","best_bid":"0.52","hash":"855ac2d4037367f07482125bc3b05832ce8e694f","price":"0.52","side":"BUY","size":"34"},{"asset_id":"41448400836309843603620980831210604935021861034693225347475867885462478926555","best_ask":"0.48","best_bid":"0.46","hash":"d21e89c17ee571fb662e012e75a4226338337114","price":"0.48","side":"SELL","size":"34"}],"timestamp":"1785122315035"},"payload_hash":"4b0dc5751e8c294cc788c9ef00336a033a50dc9a81306d302e7915f1c3ab6fb9","raw_frame":"{\"market\":\"0x717c0e8ccd4d5c7040185188fbae28be901ca589a11a94b1b38ca36a79eccfeb\", \"price_changes\":[{\"asset_id\":\"24254094493625419915756280046002869097156693848522361803041977572204227262166\", \"price\":\"0.52\", \"size\":\"34\", \"side\":\"BUY\", \"hash\":\"855ac2d4037367f07482125bc3b05832ce8e694f\", \"best_bid\":\"0.52\", \"best_ask\":\"0.54\"}, {\"asset_id\":\"41448400836309843603620980831210604935021861034693225347475867885462478926555\", \"price\":\"0.48\", \"size\":\"34\", \"side\":\"SELL\", \"hash\":\"d21e89c17ee571fb662e012e75a4226338337114\", \"best_bid\":\"0.46\", \"best_ask\":\"0.48\"}], \"timestamp\":\"1785122315035\", \"event_type\":\"price_change\"}","received_at":"2026-07-27T03:18:34.950264Z","schema_version":"clob-market-ws.price_change.v1","sequence":null,"server_hash":null,"server_timestamp":"1785122315035","session_id":"dd162b8dca5f43ff811d304e69a06123","source":"clob_market_ws"},"received_at":"2026-07-27T03:18:34.950264Z","record_id":"ad5b9a1f7683a23c64d66565128a031c382a9b529e7bdacc254328c5abb3ef8f","schema_fingerprint":"4aa3821a28b0b7c2400bc59aba4bcc0a76e971dadd19610d3ad38c768e124dc7","schema_version":"edge-lab-recorder.raw.v1","sequence":null,"source":"clob_market_ws"}
{"event_at":"2026-07-27T03:18:35.037000Z","event_fingerprint":"efb6c159d70332fcc1e033543fb90fca650b9992b88eb6e981f63646a75c1a62","payload":{"connection_id":"c7dc2e4762f849c6b6f9306b6518dcab","event_at":"2026-07-27T03:18:35.037000Z","event_type":"price_change","frame_hash":"f87f3c7f3a116cf34f3df6f24e2c8752d50bdd75c790bb1df690c3ef6e0587b0","frame_index":0,"kind":"data","monotonic_ns":224298289739250,"payload":{"event_type":"price_change","market":"0x717c0e8ccd4d5c7040185188fbae28be901ca589a11a94b1b38ca36a79eccfeb","price_changes":[{"asset_id":"41448400836309843603620980831210604935021861034693225347475867885462478926555","best_ask":"0.48","best_bid":"0.46","hash":"ec990b2c979c2d26fad6f52e7189ab05b5bd383f","price":"0.42","side":"BUY","size":"27.32"},{"asset_id":"24254094493625419915756280046002869097156693848522361803041977572204227262166","best_ask":"0.54","best_bid":"0.52","hash":"4da039cdc750c04ee1cd9f02798ce42bd24468a2","price":"0.58","side":"SELL","size":"27.32"}],"timestamp":"1785122315037"},"payload_hash":"7c71c7fe8e62a489304b87dde6dcf0dffa68b527a0949da916a45dc283be4b9a","raw_frame":"{\"market\":\"0x717c0e8ccd4d5c7040185188fbae28be901ca589a11a94b1b38ca36a79eccfeb\", \"price_changes\":[{\"asset_id\":\"41448400836309843603620980831210604935021861034693225347475867885462478926555\", \"price\":\"0.42\", \"size\":\"27.32\", \"side\":\"BUY\", \"hash\":\"ec990b2c979c2d26fad6f52e7189ab05b5bd383f\", \"best_bid\":\"0.46\", \"best_ask\":\"0.48\"}, {\"asset_id\":\"24254094493625419915756280046002869097156693848522361803041977572204227262166\", \"price\":\"0.58\", \"size\":\"27.32\", \"side\":\"SELL\", \"hash\":\"4da039cdc750c04ee1cd9f02798ce42bd24468a2\", \"best_bid\":\"0.52\", \"best_ask\":\"0.54\"}], \"timestamp\":\"1785122315037\", \"event_type\":\"price_change\"}","received_at":"2026-07-27T03:18:34.953066Z","schema_version":"clob-market-ws.price_change.v1","sequence":null,"server_hash":null,"server_timestamp":"1785122315037","session_id":"dd162b8dca5f43ff811d304e69a06123","source":"clob_market_ws"},"received_at":"2026-07-27T03:18:34.953066Z","record_id":"78469770f7ab29c0870a551e82d9e89646fd70c57cb1b6767bf6a220acf77292","schema_fingerprint":"4aa3821a28b0b7c2400bc59aba4bcc0a76e971dadd19610d3ad38c768e124dc7","schema_version":"edge-lab-recorder.raw.v1","sequence":null,"source":"clob_market_ws"}
{"event_at":"2026-07-27T03:18:35.038000Z","event_fingerprint":"b5605ec65f2ed6c88dea63ac8e1725f6895f05321290afd67542dbb24699ff20","payload":{"connection_id":"c7dc2e4762f849c6b6f9306b6518dcab","event_at":"2026-07-27T03:18:35.038000Z","event_type":"price_change","frame_hash":"916de956bf2b417579179d81e908defa90f0225e854c9e1c2044797b4095c621","frame_index":0,"kind":"data","monotonic_ns":224298292055500,"payload":{"event_type":"price_change","market":"0x717c0e8ccd4d5c7040185188fbae28be901ca589a11a94b1b38ca36a79eccfeb","price_changes":[{"asset_id":"24254094493625419915756280046002869097156693848522361803041977572204227262166","best_ask":"0.54","best_bid":"0.52","hash":"bfd928ae69330b360b60f83408660b86fe9e3394","price":"0.51","side":"BUY","size":"154.4"},{"asset_id":"41448400836309843603620980831210604935021861034693225347475867885462478926555","best_ask":"0.48","best_bid":"0.46","hash":"098674deb423cb4a644d5f52862a1866fb87c435","price":"0.49","side":"SELL","size":"154.4"}],"timestamp":"1785122315038"},"payload_hash":"7785c4f0422638bd64ccf05a38064da45a15afa59b3e216010fc1736055b3810","raw_frame":"{\"market\":\"0x717c0e8ccd4d5c7040185188fbae28be901ca589a11a94b1b38ca36a79eccfeb\", \"price_changes\":[{\"asset_id\":\"24254094493625419915756280046002869097156693848522361803041977572204227262166\", \"price\":\"0.51\", \"size\":\"154.4\", \"side\":\"BUY\", \"hash\":\"bfd928ae69330b360b60f83408660b86fe9e3394\", \"best_bid\":\"0.52\", \"best_ask\":\"0.54\"}, {\"asset_id\":\"41448400836309843603620980831210604935021861034693225347475867885462478926555\", \"price\":\"0.49\", \"size\":\"154.4\", \"side\":\"SELL\", \"hash\":\"098674deb423cb4a644d5f52862a1866fb87c435\", \"best_bid\":\"0.46\", \"best_ask\":\"0.48\"}], \"timestamp\":\"1785122315038\", \"event_type\":\"price_change\"}","received_at":"2026-07-27T03:18:34.955382Z","schema_version":"clob-market-ws.price_change.v1","sequence":null,"server_hash":null,"server_timestamp":"1785122315038","session_id":"dd162b8dca5f43ff811d304e69a06123","source":"clob_market_ws"},"received_at":"2026-07-27T03:18:34.955382Z","record_id":"50a03928e1c3d5f5789bb58e02289b858f01969d0fd0f2e8578fa6f5057ea83b","schema_fingerprint":"4aa3821a28b0b7c2400bc59aba4bcc0a76e971dadd19610d3ad38c768e124dc7","schema_version":"edge-lab-recorder.raw.v1","sequence":null,"source":"clob_market_ws"}
{"event_at":"2026-07-27T03:18:35.038000Z","event_fingerprint":"64baf039cb44ed7959d9f8c6150fe6a12a08161ea2939538ee07090087413bca","payload":{"connection_id":"c7dc2e4762f849c6b6f9306b6518dcab","event_at":"2026-07-27T03:18:35.038000Z","event_type":"price_change","frame_hash":"d21280d3f3327230e154cd61d2e6197e366e830c69ab383af5bc8f1c990e361e","frame_index":0,"kind":"data","monotonic_ns":224298293907250,"payload":{"event_type":"price_change","market":"0x717c0e8ccd4d5c7040185188fbae28be901ca589a11a94b1b38ca36a79eccfeb","price_changes":[{"asset_id":"24254094493625419915756280046002869097156693848522361803041977572204227262166","best_ask":"0.54","best_bid":"0.52","hash":"7215f5b7da52c3874f9939623951dc8ac443fa05","price":"0.52","side":"BUY","size":"39"},{"asset_id":"41448400836309843603620980831210604935021861034693225347475867885462478926555","best_ask":"0.48","best_bid":"0.46","hash":"daa00dbac2d8816ffbf378dece250da7a2929ea9","price":"0.48","side":"SELL","size":"39"}],"timestamp":"1785122315038"},"payload_hash":"6a04c3faed281468f7d677a48826a1949732dd59954b877cee6c85b442ebd025","raw_frame":"{\"market\":\"0x717c0e8ccd4d5c7040185188fbae28be901ca589a11a94b1b38ca36a79eccfeb\", \"price_changes\":[{\"asset_id\":\"24254094493625419915756280046002869097156693848522361803041977572204227262166\", \"price\":\"0.52\", \"size\":\"39\", \"side\":\"BUY\", \"hash\":\"7215f5b7da52c3874f9939623951dc8ac443fa05\", \"best_bid\":\"0.52\", \"best_ask\":\"0.54\"}, {\"asset_id\":\"41448400836309843603620980831210604935021861034693225347475867885462478926555\", \"price\":\"0.48\", \"size\":\"39\", \"side\":\"SELL\", \"hash\":\"daa00dbac2d8816ffbf378dece250da7a2929ea9\", \"best_bid\":\"0.46\", \"best_ask\":\"0.48\"}], \"timestamp\":\"1785122315038\", \"event_type\":\"price_change\"}","received_at":"2026-07-27T03:18:34.957232Z","schema_version":"clob-market-ws.price_change.v1","sequence":null,"server_hash":null,"server_timestamp":"1785122315038","session_id":"dd162b8dca5f43ff811d304e69a06123","source":"clob_market_ws"},"received_at":"2026-07-27T03:18:34.957232Z","record_id":"463cfff4f7e9173ab18594e17f6c20042c06699c174e47663ee45b14706ed03b","schema_fingerprint":"4aa3821a28b0b7c2400bc59aba4bcc0a76e971dadd19610d3ad38c768e124dc7","schema_version":"edge-lab-recorder.raw.v1","sequence":null,"source":"clob_market_ws"}
{"event_at":"2026-07-27T03:18:35.039000Z","event_fingerprint":"583bc4d4d325d8c7572efc306445a0ad08520ec3d6987129e40fca1d27395e66","payload":{"connection_id":"c7dc2e4762f849c6b6f9306b6518dcab","event_at":"2026-07-27T03:18:35.039000Z","event_type":"price_change","frame_hash":"9a2a64e4582072149ba88a5bd68e6b8eb472d5b0b1214a9366d4a334e5893ffa","frame_index":0,"kind":"data","monotonic_ns":224298295260125,"payload":{"event_type":"price_change","market":"0x717c0e8ccd4d5c7040185188fbae28be901ca589a11a94b1b38ca36a79eccfeb","price_changes":[{"asset_id":"41448400836309843603620980831210604935021861034693225347475867885462478926555","best_ask":"0.48","best_bid":"0.46","hash":"8bcf193c0ddbce563830e81b920cdc2809f32f14","price":"0.39","side":"BUY","size":"22.51"},{"asset_id":"24254094493625419915756280046002869097156693848522361803041977572204227262166","best_ask":"0.54","best_bid":"0.52","hash":"e34052b87eaba7a0e5b60101c2a14ff5d7edbf87","price":"0.61","side":"SELL","size":"22.51"}],"timestamp":"1785122315039"},"payload_hash":"23d3d6d789995c1116338569b1f84b9860725e18aae48eb8632ace2802817a49","raw_frame":"{\"market\":\"0x717c0e8ccd4d5c7040185188fbae28be901ca589a11a94b1b38ca36a79eccfeb\", \"price_changes\":[{\"asset_id\":\"41448400836309843603620980831210604935021861034693225347475867885462478926555\", \"price\":\"0.39\", \"size\":\"22.51\", \"side\":\"BUY\", \"hash\":\"8bcf193c0ddbce563830e81b920cdc2809f32f14\", \"best_bid\":\"0.46\", \"best_ask\":\"0.48\"}, {\"asset_id\":\"24254094493625419915756280046002869097156693848522361803041977572204227262166\", \"price\":\"0.61\", \"size\":\"22.51\", \"side\":\"SELL\", \"hash\":\"e34052b87eaba7a0e5b60101c2a14ff5d7edbf87\", \"best_bid\":\"0.52\", \"best_ask\":\"0.54\"}], \"timestamp\":\"1785122315039\", \"event_type\":\"price_change\"}","received_at":"2026-07-27T03:18:34.958589Z","schema_version":"clob-market-ws.price_change.v1","sequence":null,"server_hash":null,"server_timestamp":"1785122315039","session_id":"dd162b8dca5f43ff811d304e69a06123","source":"clob_market_ws"},"received_at":"2026-07-27T03:18:34.958589Z","record_id":"c3e806087dd92b6c941a8ef1d8300a9c6acd3e1561064582f24946426096d7b6","schema_fingerprint":"4aa3821a28b0b7c2400bc59aba4bcc0a76e971dadd19610d3ad38c768e124dc7","schema_version":"edge-lab-recorder.raw.v1","sequence":null,"source":"clob_market_ws"}
{"event_at":"2026-07-27T03:18:35.039000Z","event_fingerprint":"86857318835ca59e24110a3a692c1f22b483dd01e6c54f1223ad373fa6d9c1e1","payload":{"connection_id":"c7dc2e4762f849c6b6f9306b6518dcab","event_at":"2026-07-27T03:18:35.039000Z","event_type":"price_change","frame_hash":"6f60036633d4c7948829bc9222d18a177ea8a122d573a40b6dfc4efcc5adae4b","frame_index":0,"kind":"data","monotonic_ns":224298296991041,"payload":{"event_type":"price_change","market":"0x717c0e8ccd4d5c7040185188fbae28be901ca589a11a94b1b38ca36a79eccfeb","price_changes":[{"asset_id":"41448400836309843603620980831210604935021861034693225347475867885462478926555","best_ask":"0.48","best_bid":"0.46","hash":"8333bae03ef8da45e469001fb865c357b282270a","price":"0.49","side":"SELL","size":"149.4"},{"asset_id":"24254094493625419915756280046002869097156693848522361803041977572204227262166","best_ask":"0.54","best_bid":"0.52","hash":"382fad3f4729811604409c13112bd90882fd49bb","price":"0.51","side":"BUY","size":"149.4"}],"timestamp":"1785122315039"},"payload_hash":"4fd4ccac2890244d54d7719c250d4c93955192ab8b64a4953d707bf0377c24b8","raw_frame":"{\"market\":\"0x717c0e8ccd4d5c7040185188fbae28be901ca589a11a94b1b38ca36a79eccfeb\", \"price_changes\":[{\"asset_id\":\"41448400836309843603620980831210604935021861034693225347475867885462478926555\", \"price\":\"0.49\", \"size\":\"149.4\", \"side\":\"SELL\", \"hash\":\"8333bae03ef8da45e469001fb865c357b282270a\", \"best_bid\":\"0.46\", \"best_ask\":\"0.48\"}, {\"asset_id\":\"24254094493625419915756280046002869097156693848522361803041977572204227262166\", \"price\":\"0.51\", \"size\":\"149.4\", \"side\":\"BUY\", \"hash\":\"382fad3f4729811604409c13112bd90882fd49bb\", \"best_bid\":\"0.52\", \"best_ask\":\"0.54\"}], \"timestamp\":\"1785122315039\", \"event_type\":\"price_change\"}","received_at":"2026-07-27T03:18:34.960316Z","schema_version":"clob-market-ws.price_change.v1","sequence":null,"server_hash":null,"server_timestamp":"1785122315039","session_id":"dd162b8dca5f43ff811d304e69a06123","source":"clob_market_ws"},"received_at":"2026-07-27T03:18:34.960316Z","record_id":"7c378686bc1ed558a937305176990b3d3fe76068e707b21eabdd8e74863da93b","schema_fingerprint":"4aa3821a28b0b7c2400bc59aba4bcc0a76e971dadd19610d3ad38c768e124dc7","schema_version":"edge-lab-recorder.raw.v1","sequence":null,"source":"clob_market_ws"}
{"event_at":"2026-07-27T03:18:35.040000Z","event_fingerprint":"bd9b9bdbd4fdf8ebae44058ff47f12989da76e33a67662926c199024e7ba7b76","payload":{"connection_id":"c7dc2e4762f849c6b6f9306b6518dcab","event_at":"2026-07-27T03:18:35.040000Z","event_type":"price_change","frame_hash":"7b7bb742c9460ced6b10375379f77176e65cd1b6a37229308c3e2b3816cd21cb","frame_index":0,"kind":"data","monotonic_ns":224298298986000,"payload":{"event_type":"price_change","market":"0x717c0e8ccd4d5c7040185188fbae28be901ca589a11a94b1b38ca36a79eccfeb","price_changes":[{"asset_id":"41448400836309843603620980831210604935021861034693225347475867885462478926555","best_ask":"0.48","best_bid":"0.46","hash":"27bc05390d16277c73e9430279a4183374a6ca47","price":"0.28","side":"BUY","size":"245.94"},{"asset_id":"24254094493625419915756280046002869097156693848522361803041977572204227262166","best_ask":"0.54","best_bid":"0.52","hash":"4f89d1523eae1537e71aed692b6e1ac96a8cb2dc","price":"0.72","side":"SELL","size":"245.94"}],"timestamp":"1785122315040"},"payload_hash":"338bdca64bd609fbafbd6d66e08bbba42f92d827fb50d4628c8b74aa6a466278","raw_frame":"{\"market\":\"0x717c0e8ccd4d5c7040185188fbae28be901ca589a11a94b1b38ca36a79eccfeb\", \"price_changes\":[{\"asset_id\":\"41448400836309843603620980831210604935021861034693225347475867885462478926555\", \"price\":\"0.28\", \"size\":\"245.94\", \"side\":\"BUY\", \"hash\":\"27bc05390d16277c73e9430279a4183374a6ca47\", \"best_bid\":\"0.46\", \"best_ask\":\"0.48\"}, {\"asset_id\":\"24254094493625419915756280046002869097156693848522361803041977572204227262166\", \"price\":\"0.72\", \"size\":\"245.94\", \"side\":\"SELL\", \"hash\":\"4f89d1523eae1537e71aed692b6e1ac96a8cb2dc\", \"best_bid\":\"0.52\", \"best_ask\":\"0.54\"}], \"timestamp\":\"1785122315040\", \"event_type\":\"price_change\"}","received_at":"2026-07-27T03:18:34.962312Z","schema_version":"clob-market-ws.price_change.v1","sequence":null,"server_hash":null,"server_timestamp":"1785122315040","session_id":"dd162b8dca5f43ff811d304e69a06123","source":"clob_market_ws"},"received_at":"2026-07-27T03:18:34.962312Z","record_id":"09f53975f1e8e8980ee44b6fc33566deb99ef44eae89609b987f8aa1e1b4e850","schema_fingerprint":"4aa3821a28b0b7c2400bc59aba4bcc0a76e971dadd19610d3ad38c768e124dc7","schema_version":"edge-lab-recorder.raw.v1","sequence":null,"source":"clob_market_ws"}
{"event_at":"2026-07-27T03:18:35.040000Z","event_fingerprint":"549f855656cd3babef6cfc25490ae739290c309c8977a9847f9d547677d2d934","payload":{"connection_id":"c7dc2e4762f849c6b6f9306b6518dcab","event_at":"2026-07-27T03:18:35.040000Z","event_type":"price_change","frame_hash":"627e31746409ea5151b497ede0926cce1ae04ab76d85ff6af2ecd10ebdd5ffd6","frame_index":0,"kind":"data","monotonic_ns":224298300996291,"payload":{"event_type":"price_change","market":"0x717c0e8ccd4d5c7040185188fbae28be901ca589a11a94b1b38ca36a79eccfeb","price_changes":[{"asset_id":"41448400836309843603620980831210604935021861034693225347475867885462478926555","best_ask":"0.48","best_bid":"0.46","hash":"16fdc38d471cac0bd01df80f7ecf2efe15841b1e","price":"0.43","side":"BUY","size":"26.4"},{"asset_id":"24254094493625419915756280046002869097156693848522361803041977572204227262166","best_ask":"0.54","best_bid":"0.52","hash":"5265c327e686f4ca658607f068cec67dabc8d164","price":"0.57","side":"SELL","size":"26.4"}],"timestamp":"1785122315040"},"payload_hash":"00ece3a74881695e090effa222b3401fe323dd94b34bdccd6e915093b0680331","raw_frame":"{\"market\":\"0x717c0e8ccd4d5c7040185188fbae28be901ca589a11a94b1b38ca36a79eccfeb\", \"price_changes\":[{\"asset_id\":\"41448400836309843603620980831210604935021861034693225347475867885462478926555\", \"price\":\"0.43\", \"size\":\"26.4\", \"side\":\"BUY\", \"hash\":\"16fdc38d471cac0bd01df80f7ecf2efe15841b1e\", \"best_bid\":\"0.46\", \"best_ask\":\"0.48\"}, {\"asset_id\":\"24254094493625419915756280046002869097156693848522361803041977572204227262166\", \"price\":\"0.57\", \"size\":\"26.4\", \"side\":\"SELL\", \"hash\":\"5265c327e686f4ca658607f068cec67dabc8d164\", \"best_bid\":\"0.52\", \"best_ask\":\"0.54\"}], \"timestamp\":\"1785122315040\", \"event_type\":\"price_change\"}","received_at":"2026-07-27T03:18:34.964321Z","schema_version":"clob-market-ws.price_change.v1","sequence":null,"server_hash":null,"server_timestamp":"1785122315040","session_id":"dd162b8dca5f43ff811d304e69a06123","source":"clob_market_ws"},"received_at":"2026-07-27T03:18:34.964321Z","record_id":"a39e62d3d507433220615ce8776097845e8455c1ba5612255a2c20def432d2aa","schema_fingerprint":"4aa3821a28b0b7c2400bc59aba4bcc0a76e971dadd19610d3ad38c768e124dc7","schema_version":"edge-lab-recorder.raw.v1","sequence":null,"source":"clob_market_ws"}
{"event_at":"2026-07-27T03:18:35.042000Z","event_fingerprint":"740c06e6398eb08caead88c1ee890009644f1478a7cbab7601cfffa817d0f156","payload":{"connection_id":"c7dc2e4762f849c6b6f9306b6518dcab","event_at":"2026-07-27T03:18:35.042000Z","event_type":"price_change","frame_hash":"c6dec1661cf6932aa15fdd0987fa000435efbc0134e2b058380eb00aa93d711b","frame_index":0,"kind":"data","monotonic_ns":224298302914083,"payload":{"event_type":"price_change","market":"0x717c0e8ccd4d5c7040185188fbae28be901ca589a11a94b1b38ca36a79eccfeb","price_changes":[{"asset_id":"24254094493625419915756280046002869097156693848522361803041977572204227262166","best_ask":"0.54","best_bid":"0.52","hash":"e790001eea232e46b8769502b144c25c1f89191d","price":"0.52","side":"BUY","size":"48.6"},{"asset_id":"41448400836309843603620980831210604935021861034693225347475867885462478926555","best_ask":"0.48","best_bid":"0.46","hash":"d3dd9b99f5a161b58d0639554a40008e356381a8","price":"0.48","side":"SELL","size":"48.6"}],"timestamp":"1785122315042"},"payload_hash":"26fc4cdc560ee0943ef2f65dd9f8bdf7341ce19dbfeb51b1b567c36e711123ac","raw_frame":"{\"market\":\"0x717c0e8ccd4d5c7040185188fbae28be901ca589a11a94b1b38ca36a79eccfeb\", \"price_changes\":[{\"asset_id\":\"24254094493625419915756280046002869097156693848522361803041977572204227262166\", \"price\":\"0.52\", \"size\":\"48.6\", \"side\":\"BUY\", \"hash\":\"e790001eea232e46b8769502b144c25c1f89191d\", \"best_bid\":\"0.52\", \"best_ask\":\"0.54\"}, {\"asset_id\":\"41448400836309843603620980831210604935021861034693225347475867885462478926555\", \"price\":\"0.48\", \"size\":\"48.6\", \"side\":\"SELL\", \"hash\":\"d3dd9b99f5a161b58d0639554a40008e356381a8\", \"best_bid\":\"0.46\", \"best_ask\":\"0.48\"}], \"timestamp\":\"1785122315042\", \"event_type\":\"price_change\"}","received_at":"2026-07-27T03:18:34.966239Z","schema_version":"clob-market-ws.price_change.v1","sequence":null,"server_hash":null,"server_timestamp":"1785122315042","session_id":"dd162b8dca5f43ff811d304e69a06123","source":"clob_market_ws"},"received_at":"2026-07-27T03:18:34.966239Z","record_id":"9ba243eaa2ee1ff8ca00fbe583a80f7a0cc8b3f652b8e0a14091f68c7e13ad03","schema_fingerprint":"4aa3821a28b0b7c2400bc59aba4bcc0a76e971dadd19610d3ad38c768e124dc7","schema_version":"edge-lab-recorder.raw.v1","sequence":null,"source":"clob_market_ws"}
{"event_at":"2026-07-27T03:18:35.043000Z","event_fingerprint":"4e0e276e358d4d2760f2a1a2dd8aa41e3a3ed9acde3370ab9e6519b855c6c62f","payload":{"connection_id":"c7dc2e4762f849c6b6f9306b6518dcab","event_at":"2026-07-27T03:18:35.043000Z","event_type":"price_change","frame_hash":"0393b68b73f5dbf5de0bc5dcdcd88e93896f7687ee19ccbfe942aa9745933894","frame_index":0,"kind":"data","monotonic_ns":224298304853541,"payload":{"event_type":"price_change","market":"0x717c0e8ccd4d5c7040185188fbae28be901ca589a11a94b1b38ca36a79eccfeb","price_changes":[{"asset_id":"41448400836309843603620980831210604935021861034693225347475867885462478926555","best_ask":"0.48","best_bid":"0.46","hash":"ea3cba740dc8ba8826b7f231b8bb376199e9cf2e","price":"0.49","side":"SELL","size":"144.4"},{"asset_id":"24254094493625419915756280046002869097156693848522361803041977572204227262166","best_ask":"0.54","best_bid":"0.52","hash":"91d0c8d4c5f17e210fbcce666f5f50f86c71a8c5","price":"0.51","side":"BUY","size":"144.4"}],"timestamp":"1785122315043"},"payload_hash":"f1e4ae69256c1189725315b6171f2505e5ec72b9e3351ab1deeb451babbf6bb6","raw_frame":"{\"market\":\"0x717c0e8ccd4d5c7040185188fbae28be901ca589a11a94b1b38ca36a79eccfeb\", \"price_changes\":[{\"asset_id\":\"41448400836309843603620980831210604935021861034693225347475867885462478926555\", \"price\":\"0.49\", \"size\":\"144.4\", \"side\":\"SELL\", \"hash\":\"ea3cba740dc8ba8826b7f231b8bb376199e9cf2e\", \"best_bid\":\"0.46\", \"best_ask\":\"0.48\"}, {\"asset_id\":\"24254094493625419915756280046002869097156693848522361803041977572204227262166\", \"price\":\"0.51\", \"size\":\"144.4\", \"side\":\"BUY\", \"hash\":\"91d0c8d4c5f17e210fbcce666f5f50f86c71a8c5\", \"best_bid\":\"0.52\", \"best_ask\":\"0.54\"}], \"timestamp\":\"1785122315043\", \"event_type\":\"price_change\"}","received_at":"2026-07-27T03:18:34.968179Z","schema_version":"clob-market-ws.price_change.v1","sequence":null,"server_hash":null,"server_timestamp":"1785122315043","session_id":"dd162b8dca5f43ff811d304e69a06123","source":"clob_market_ws"},"received_at":"2026-07-27T03:18:34.968179Z","record_id":"bbf2ff2929e661d55ca9fc9fe103d3a922e523110b6ae0343d5e19071dfee91b","schema_fingerprint":"4aa3821a28b0b7c2400bc59aba4bcc0a76e971dadd19610d3ad38c768e124dc7","schema_version":"edge-lab-recorder.raw.v1","sequence":null,"source":"clob_market_ws"}
{"event_at":"2026-07-27T03:18:35.046000Z","event_fingerprint":"62f0008c7db1c1982048132e6f11e49df63e23abd6af4aa84f60763034f95c22","payload":{"connection_id":"c7dc2e4762f849c6b6f9306b6518dcab","event_at":"2026-07-27T03:18:35.046000Z","event_type":"price_change","frame_hash":"287b32b334e91da01e38a9aebbaa3aa351859f73d24c0b666220a86aa714eaf1","frame_index":0,"kind":"data","monotonic_ns":224298306656958,"payload":{"event_type":"price_change","market":"0x717c0e8ccd4d5c7040185188fbae28be901ca589a11a94b1b38ca36a79eccfeb","price_changes":[{"asset_id":"41448400836309843603620980831210604935021861034693225347475867885462478926555","best_ask":"0.48","best_bid":"0.46","hash":"3ccdfc6f8f85ed927d24a40b97c151c61956a7cb","price":"0.41","side":"BUY","size":"112.4"},{"asset_id":"24254094493625419915756280046002869097156693848522361803041977572204227262166","best_ask":"0.54","best_bid":"0.52","hash":"39f440787e687f3b631be2f02c378ef34d05933a","price":"0.59","side":"SELL","size":"112.4"}],"timestamp":"1785122315046"},"payload_hash":"0a238492ef2d8159121436599e25c491d7cf4f35d349b1a35e5133ef25897651","raw_frame":"{\"market\":\"0x717c0e8ccd4d5c7040185188fbae28be901ca589a11a94b1b38ca36a79eccfeb\", \"price_changes\":[{\"asset_id\":\"41448400836309843603620980831210604935021861034693225347475867885462478926555\", \"price\":\"0.41\", \"size\":\"112.4\", \"side\":\"BUY\", \"hash\":\"3ccdfc6f8f85ed927d24a40b97c151c61956a7cb\", \"best_bid\":\"0.46\", \"best_ask\":\"0.48\"}, {\"asset_id\":\"24254094493625419915756280046002869097156693848522361803041977572204227262166\", \"price\":\"0.59\", \"size\":\"112.4\", \"side\":\"SELL\", \"hash\":\"39f440787e687f3b631be2f02c378ef34d05933a\", \"best_bid\":\"0.52\", \"best_ask\":\"0.54\"}], \"timestamp\":\"1785122315046\", \"event_type\":\"price_change\"}","received_at":"2026-07-27T03:18:34.969983Z","schema_version":"clob-market-ws.price_change.v1","sequence":null,"server_hash":null,"server_timestamp":"1785122315046","session_id":"dd162b8dca5f43ff811d304e69a06123","source":"clob_market_ws"},"received_at":"2026-07-27T03:18:34.969983Z","record_id":"400046ffded47cd88d7ba349b56f483f29020b5c5d59ad94e57c3571cb3be7f8","schema_fingerprint":"4aa3821a28b0b7c2400bc59aba4bcc0a76e971dadd19610d3ad38c768e124dc7","schema_version":"edge-lab-recorder.raw.v1","sequence":null,"source":"clob_market_ws"}
{"event_at":"2026-07-27T03:18:35.046000Z","event_fingerprint":"ed1041b460612d562d404b4518e009795ecaecf998ff1ef5f87371a76189d60c","payload":{"connection_id":"c7dc2e4762f849c6b6f9306b6518dcab","event_at":"2026-07-27T03:18:35.046000Z","event_type":"best_bid_ask","frame_hash":"5c4994e5886022f8bc724e92a408637eec2c3a44732460344deea213854ad58d","frame_index":0,"kind":"data","monotonic_ns":224298308633458,"payload":{"asset_id":"24254094493625419915756280046002869097156693848522361803041977572204227262166","best_ask":"0.54","best_bid":"0.53","event_type":"best_bid_ask","market":"0x717c0e8ccd4d5c7040185188fbae28be901ca589a11a94b1b38ca36a79eccfeb","spread":"0.01","timestamp":"1785122315046"},"payload_hash":"c0c7667900d1744fbda18eedb2a6c57ae1788c01ece92f64f1f1dda7260efc33","raw_frame":"{\"market\":\"0x717c0e8ccd4d5c7040185188fbae28be901ca589a11a94b1b38ca36a79eccfeb\", \"asset_id\":\"24254094493625419915756280046002869097156693848522361803041977572204227262166\", \"best_bid\":\"0.53\", \"best_ask\":\"0.54\", \"spread\":\"0.01\", \"timestamp\":\"1785122315046\", \"event_type\":\"best_bid_ask\"}","received_at":"2026-07-27T03:18:34.971959Z","schema_version":"clob-market-ws.best_bid_ask.v1","sequence":null,"server_hash":null,"server_timestamp":"1785122315046","session_id":"dd162b8dca5f43ff811d304e69a06123","source":"clob_market_ws"},"received_at":"2026-07-27T03:18:34.971959Z","record_id":"95ff14a351de0b5d64554020bf4f16fadd33866278174df2b0ac065ac46e82dd","schema_fingerprint":"8488399f31b0337811b13b266be932db7062827c2470b78bd8e9e99bab51d17d","schema_version":"edge-lab-recorder.raw.v1","sequence":null,"source":"clob_market_ws"}
{"event_at":"2026-07-27T03:18:35.046000Z","event_fingerprint":"daecb8c56dde4baa883406222b3beabe269b76130c7c9032d205bffd25675ea1","payload":{"connection_id":"c7dc2e4762f849c6b6f9306b6518dcab","event_at":"2026-07-27T03:18:35.046000Z","event_type":"best_bid_ask","frame_hash":"6b7898ad66cfea115f85c4b74d1dc418fd99d947dd88df922adb70f29235c863","frame_index":0,"kind":"data","monotonic_ns":224298309867958,"payload":{"asset_id":"41448400836309843603620980831210604935021861034693225347475867885462478926555","best_ask":"0.47","best_bid":"0.46","event_type":"best_bid_ask","market":"0x717c0e8ccd4d5c7040185188fbae28be901ca589a11a94b1b38ca36a79eccfeb","spread":"0.01","timestamp":"1785122315046"},"payload_hash":"fc21685ae37b6e3e616629900a0ae20e65a9f7f7eee88c978499e7cb6ca80b11","raw_frame":"{\"market\":\"0x717c0e8ccd4d5c7040185188fbae28be901ca589a11a94b1b38ca36a79eccfeb\", \"asset_id\":\"41448400836309843603620980831210604935021861034693225347475867885462478926555\", \"best_bid\":\"0.46\", \"best_ask\":\"0.47\", \"spread\":\"0.01\", \"timestamp\":\"1785122315046\", \"event_type\":\"best_bid_ask\"}","received_at":"2026-07-27T03:18:34.973194Z","schema_version":"clob-market-ws.best_bid_ask.v1","sequence":null,"server_hash":null,"server_timestamp":"1785122315046","session_id":"dd162b8dca5f43ff811d304e69a06123","source":"clob_market_ws"},"received_at":"2026-07-27T03:18:34.973194Z","record_id":"e5caa8569dfcd5fc9e9b1a2c796beb8402a58d332a70c15c43738e808e59741f","schema_fingerprint":"8488399f31b0337811b13b266be932db7062827c2470b78bd8e9e99bab51d17d","schema_version":"edge-lab-recorder.raw.v1","sequence":null,"source":"clob_market_ws"}
{"event_at":"2026-07-27T03:18:35.046000Z","event_fingerprint":"1cc8c77a1dc6e3ac38997ce6dda31df74784c1ca180342c2518b2a087f35a49a","payload":{"connection_id":"c7dc2e4762f849c6b6f9306b6518dcab","event_at":"2026-07-27T03:18:35.046000Z","event_type":"price_change","frame_hash":"6ecc839b924a2c794638990af16d3335297eb966b26f396c337d185b07666530","frame_index":0,"kind":"data","monotonic_ns":224298311502416,"payload":{"event_type":"price_change","market":"0x717c0e8ccd4d5c7040185188fbae28be901ca589a11a94b1b38ca36a79eccfeb","price_changes":[{"asset_id":"24254094493625419915756280046002869097156693848522361803041977572204227262166","best_ask":"0.54","best_bid":"0.53","hash":"be09995b078fdf2f70cc9b7f96670181f60ee69b","price":"0.53","side":"BUY","size":"5"},{"asset_id":"41448400836309843603620980831210604935021861034693225347475867885462478926555","best_ask":"0.47","best_bid":"0.46","hash":"bc65966b313d0824e3bc5da7e052210b5a96d15c","price":"0.47","side":"SELL","size":"5"}],"timestamp":"1785122315046"},"payload_hash":"1e3830018a769aaccc4cc621d6966b26bb46e4787356c7d6b47e3e519eccdc17","raw_frame":"{\"market\":\"0x717c0e8ccd4d5c7040185188fbae28be901ca589a11a94b1b38ca36a79eccfeb\", \"price_changes\":[{\"asset_id\":\"24254094493625419915756280046002869097156693848522361803041977572204227262166\", \"price\":\"0.53\", \"size\":\"5\", \"side\":\"BUY\", \"hash\":\"be09995b078fdf2f70cc9b7f96670181f60ee69b\", \"best_bid\":\"0.53\", \"best_ask\":\"0.54\"}, {\"asset_id\":\"41448400836309843603620980831210604935021861034693225347475867885462478926555\", \"price\":\"0.47\", \"size\":\"5\", \"side\":\"SELL\", \"hash\":\"bc65966b313d0824e3bc5da7e052210b5a96d15c\", \"best_bid\":\"0.46\", \"best_ask\":\"0.47\"}], \"timestamp\":\"1785122315046\", \"event_type\":\"price_change\"}","received_at":"2026-07-27T03:18:34.974829Z","schema_version":"clob-market-ws.price_change.v1","sequence":null,"server_hash":null,"server_timestamp":"1785122315046","session_id":"dd162b8dca5f43ff811d304e69a06123","source":"clob_market_ws"},"received_at":"2026-07-27T03:18:34.974829Z","record_id":"082f535dcd80e0b17807d49991a39b998d2f4d95451bb98a74ccace4bc3e3adc","schema_fingerprint":"4aa3821a28b0b7c2400bc59aba4bcc0a76e971dadd19610d3ad38c768e124dc7","schema_version":"edge-lab-recorder.raw.v1","sequence":null,"source":"clob_market_ws"}
{"event_at":"2026-07-27T03:18:35.048000Z","event_fingerprint":"97386ed8981e632b2bac1b3da66288e412fbbf528568bf16aca410bae4b3af1a","payload":{"connection_id":"c7dc2e4762f849c6b6f9306b6518dcab","event_at":"2026-07-27T03:18:35.048000Z","event_type":"best_bid_ask","frame_hash":"382842bfa4ab6e6b1f51a995ed5cd9b89f1346b9a790c591e6d2886245313ecc","frame_index":0,"kind":"data","monotonic_ns":224298312601791,"payload":{"asset_id":"24254094493625419915756280046002869097156693848522361803041977572204227262166","best_ask":"0.55","best_bid":"0.53","event_type":"best_bid_ask","market":"0x717c0e8ccd4d5c7040185188fbae28be901ca589a11a94b1b38ca36a79eccfeb","spread":"0.02","timestamp":"1785122315048"},"payload_hash":"795c81fd06fa9dec617a6c2313f5a25c9ba06229fabb6b7b8aa01541635292eb","raw_frame":"{\"market\":\"0x717c0e8ccd4d5c7040185188fbae28be901ca589a11a94b1b38ca36a79eccfeb\", \"asset_id\":\"24254094493625419915756280046002869097156693848522361803041977572204227262166\", \"best_bid\":\"0.53\", \"best_ask\":\"0.55\", \"spread\":\"0.02\", \"timestamp\":\"1785122315048\", \"event_type\":\"best_bid_ask\"}","received_at":"2026-07-27T03:18:34.975931Z","schema_version":"clob-market-ws.best_bid_ask.v1","sequence":null,"server_hash":null,"server_timestamp":"1785122315048","session_id":"dd162b8dca5f43ff811d304e69a06123","source":"clob_market_ws"},"received_at":"2026-07-27T03:18:34.975931Z","record_id":"e6d39a9c3568d5b945451575cfc9ab23ff2988b641be8ab622a28f1d36022750","schema_fingerprint":"8488399f31b0337811b13b266be932db7062827c2470b78bd8e9e99bab51d17d","schema_version":"edge-lab-recorder.raw.v1","sequence":null,"source":"clob_market_ws"}
