{"event_at":"2026-07-27T03:20:01.641000Z","event_fingerprint":"8656f955f80e05f5778a0aee945c20cb55375ebcc2b2705fc50d5f822223a425","payload":{"connection_id":"c7dc2e4762f849c6b6f9306b6518dcab","event_at":"2026-07-27T03:20:01.641000Z","event_type":"price_change","frame_hash":"079713b41b66fb47db449ce52ada573b94a224c3624a727da4ce5629dee92d1f","frame_index":0,"kind":"data","monotonic_ns":224384886457416,"payload":{"event_type":"price_change","market":"0x717c0e8ccd4d5c7040185188fbae28be901ca589a11a94b1b38ca36a79eccfeb","price_changes":[{"asset_id":"24254094493625419915756280046002869097156693848522361803041977572204227262166","best_ask":"0.47","best_bid":"0.46","hash":"c90e22aee9335015367a4b29c8037399b30790f9","price":"0.4","side":"BUY","size":"45.44"},{"asset_id":"41448400836309843603620980831210604935021861034693225347475867885462478926555","best_ask":"0.54","best_bid":"0.53","hash":"2f18a87fd38376e0af83b71f131488c16713c6dc","price":"0.6","side":"SELL","size":"45.44"}],"timestamp":"1785122401641"},"payload_hash":"1ed542300b4b67d45d65e547865121c8212b55d696887db6f48f5bfef970c738","raw_frame":"{\"market\":\"0x717c0e8ccd4d5c7040185188fbae28be901ca589a11a94b1b38ca36a79eccfeb\", \"price_changes\":[{\"asset_id\":\"24254094493625419915756280046002869097156693848522361803041977572204227262166\", \"price\":\"0.4\", \"size\":\"45.44\", \"side\":\"BUY\", \"hash\":\"c90e22aee9335015367a4b29c8037399b30790f9\", \"best_bid\":\"0.46\", \"best_ask\":\"0.47\"}, {\"asset_id\":\"41448400836309843603620980831210604935021861034693225347475867885462478926555\", \"price\":\"0.6\", \"size\":\"45.44\", \"side\":\"SELL\", \"hash\":\"2f18a87fd38376e0af83b71f131488c16713c6dc\", \"best_bid\":\"0.53\", \"best_ask\":\"0.54\"}], \"timestamp\":\"1785122401641\", \"event_type\":\"price_change\"}","received_at":"2026-07-27T03:20:01.534822Z","schema_version":"clob-market-ws.price_change.v1","sequence":null,"server_hash":null,"server_timestamp":"1785122401641","session_id":"dd162b8dca5f43ff811d304e69a06123","source":"clob_market_ws"},"received_at":"2026-07-27T03:20:01.534822Z","record_id":"c7e7acb392faf71b499cef5d0e731ddf37d2b9d5ff3f6bc7c533b9b08bcc17ca","schema_fingerprint":"4aa3821a28b0b7c2400bc59aba4bcc0a76e971dadd19610d3ad38c768e124dc7","schema_version":"edge-lab-recorder.raw.v1","sequence":null,"source":"clob_market_ws"}
{"event_at":"2026-07-27T03:20:01.645000Z","event_fingerprint":"c792f81eb1db88a5376634fa1a03edb469c63937e17765e3a36a69f6475c58c3","payload":{"connection_id":"c7dc2e4762f849c6b6f9306b6518dcab","event_at":"2026-07-27T03:20:01.645000Z","event_type":"price_change","frame_hash":"99360f5b888b0aeb3a5c133d46669fade7fa712acc497e7b86d1d706c878b321","frame_index":0,"kind":"data","monotonic_ns":224384889917166,"payload":{"event_type":"price_change","market":"0x717c0e8ccd4d5c7040185188fbae28be901ca589a11a94b1b38ca36a79eccfeb","price_changes":[{"asset_id":"24254094493625419915756280046002869097156693848522361803041977572204227262166","best_ask":"0.47","best_bid":"0.46","hash":"439a880dd60716361e1d5c0d581b2b938981b646","price":"0.44","side":"BUY","size":"16"},{"asset_id":"41448400836309843603620980831210604935021861034693225347475867885462478926555","best_ask":"0.54","best_bid":"0.53","hash":"985eca3ac8ec14b5b6dd585824b13e91917875b3","price":"0.56","side":"SELL","size":"16"}],"timestamp":"1785122401645"},"payload_hash":"5909c4fe307596ca507aa24afd8b8dac02a28bd71410c30bd4a9fd2e0eb989da","raw_frame":"{\"market\":\"0x717c0e8ccd4d5c7040185188fbae28be901ca589a11a94b1b38ca36a79eccfeb\", \"price_changes\":[{\"asset_id\":\"24254094493625419915756280046002869097156693848522361803041977572204227262166\", \"price\":\"0.44\", \"size\":\"16\", \"side\":\"BUY\", \"hash\":\"439a880dd60716361e1d5c0d581b2b938981b646\", \"best_bid\":\"0.46\", \"best_ask\":\"0.47\"}, {\"asset_id\":\"41448400836309843603620980831210604935021861034693225347475867885462478926555\", \"price\":\"0.56\", \"size\":\"16\", \"side\":\"SELL\", \"hash\":\"985eca3ac8ec14b5b6dd585824b13e91917875b3\", \"best_bid\":\"0.53\", \"best_ask\":\"0.54\"}], \"timestamp\":\"1785122401645\", \"event_type\":\"price_change\"}","received_at":"2026-07-27T03:20:01.538280Z","schema_version":"clob-market-ws.price_change.v1","sequence":null,"server_hash":null,"server_timestamp":"1785122401645","session_id":"dd162b8dca5f43ff811d304e69a06123","source":"clob_market_ws"},"received_at":"2026-07-27T03:20:01.538280Z","record_id":"6de7b338d969cb1d10fa50da5bff3a90eb2f1252292f4ab62960042396e3b773","schema_fingerprint":"4aa3821a28b0b7c2400bc59aba4bcc0a76e971dadd19610d3ad38c768e124dc7","schema_version":"edge-lab-recorder.raw.v1","sequence":null,"source":"clob_market_ws"}
{"event_at":"2026-07-27T03:20:01.652000Z","event_fingerprint":"b78a6031f5ee6b39c8e9a8ce7e26a6cdf43c665add6907828a1c0c7ad44bf809","payload":{"connection_id":"c7dc2e4762f849c6b6f9306b6518dcab","event_at":"2026-07-27T03:20:01.652000Z","event_type":"price_change","frame_hash":"e2cbb2e9486d42c1164a150eda3f5282a40f58f299dfcf1b7c566fcd52ff8bce","frame_index":0,"kind":"data","monotonic_ns":224384892957333,"payload":{"event_type":"price_change","market":"0x717c0e8ccd4d5c7040185188fbae28be901ca589a11a94b1b38ca36a79eccfeb","price_changes":[{"asset_id":"41448400836309843603620980831210604935021861034693225347475867885462478926555","best_ask":"0.54","best_bid":"0.53","hash":"33a18bb73a9e6638fc0e909511ebf1cc55648045","price":"0.01","side":"BUY","size":"5708.02"},{"asset_id":"24254094493625419915756280046002869097156693848522361803041977572204227262166","best_ask":"0.47","best_bid":"0.46","hash":"c22423916d4bbba5ea97e586a9e4d6bb42bf8823","price":"0.99","side":"SELL","size":"5708.02"}],"timestamp":"1785122401652"},"payload_hash":"c3788a85c73d9fc33d4da83b2f544906ffee9fa8fade5a0dbe64d52e7b9a2423","raw_frame":"{\"market\":\"0x717c0e8ccd4d5c7040185188fbae28be901ca589a11a94b1b38ca36a79eccfeb\", \"price_changes\":[{\"asset_id\":\"41448400836309843603620980831210604935021861034693225347475867885462478926555\", \"price\":\"0.01\", \"size\":\"5708.02\", \"side\":\"BUY\", \"hash\":\"33a18bb73a9e6638fc0e909511ebf1cc55648045\", \"best_bid\":\"0.53\", \"best_ask\":\"0.54\"}, {\"asset_id\":\"24254094493625419915756280046002869097156693848522361803041977572204227262166\", \"price\":\"0.99\", \"size\":\"5708.02\", \"side\":\"SELL\", \"hash\":\"c22423916d4bbba5ea97e586a9e4d6bb42bf8823\", \"best_bid\":\"0.46\", \"best_ask\":\"0.47\"}], \"timestamp\":\"1785122401652\", \"event_type\":\"price_change\"}","received_at":"2026-07-27T03:20:01.541322Z","schema_version":"clob-market-ws.price_change.v1","sequence":null,"server_hash":null,"server_timestamp":"1785122401652","session_id":"dd162b8dca5f43ff811d304e69a06123","source":"clob_market_ws"},"received_at":"2026-07-27T03:20:01.541322Z","record_id":"3a7c161f85c4057365c69843464dd0a8892bdcfeace5da8b11937cfe164c6cf0","schema_fingerprint":"4aa3821a28b0b7c2400bc59aba4bcc0a76e971dadd19610d3ad38c768e124dc7","schema_version":"edge-lab-recorder.raw.v1","sequence":null,"source":"clob_market_ws"}
{"event_at":"2026-07-27T03:20:01.671000Z","event_fingerprint":"26162631f6b2ebe89553207679b6080e29342f4a09c72e9a111b8dfa231f29ec","payload":{"connection_id":"c7dc2e4762f849c6b6f9306b6518dcab","event_at":"2026-07-27T03:20:01.671000Z","event_type":"price_change","frame_hash":"bd7148e2a220f681d3a41622736eaf85f5c63aef63bd86c9bd39d5175c9f3267","frame_index":0,"kind":"data","monotonic_ns":224384908181791,"payload":{"event_type":"price_change","market":"0x717c0e8ccd4d5c7040185188fbae28be901ca589a11a94b1b38ca36a79eccfeb","price_changes":[{"asset_id":"41448400836309843603620980831210604935021861034693225347475867885462478926555","best_ask":"0.54","best_bid":"0.53","hash":"820fdcd15d869ab38b0458ed670d17af1305bc5d","price":"0.04","side":"BUY","size":"628.09"},{"asset_id":"24254094493625419915756280046002869097156693848522361803041977572204227262166","best_ask":"0.47","best_bid":"0.46","hash":"9ef82f079895fa4a0a2a8c1103ca8fbe15196dad","price":"0.96","side":"SELL","size":"628.09"}],"timestamp":"1785122401671"},"payload_hash":"b1952f974a2a5fe331b58c57fa4e8df6aee49f105b89b808294d2b3ff0259294","raw_frame":"{\"market\":\"0x717c0e8ccd4d5c7040185188fbae28be901ca589a11a94b1b38ca36a79eccfeb\", \"price_changes\":[{\"asset_id\":\"41448400836309843603620980831210604935021861034693225347475867885462478926555\", \"price\":\"0.04\", \"size\":\"628.09\", \"side\":\"BUY\", \"hash\":\"820fdcd15d869ab38b0458ed670d17af1305bc5d\", \"best_bid\":\"0.53\", \"best_ask\":\"0.54\"}, {\"asset_id\":\"24254094493625419915756280046002869097156693848522361803041977572204227262166\", \"price\":\"0.96\", \"size\":\"628.09\", \"side\":\"SELL\", \"hash\":\"9ef82f079895fa4a0a2a8c1103ca8fbe15196dad\", \"best_bid\":\"0.46\", \"best_ask\":\"0.47\"}], \"timestamp\":\"1785122401671\", \"event_type\":\"price_change\"}","received_at":"2026-07-27T03:20:01.556539Z","schema_version":"clob-market-ws.price_change.v1","sequence":null,"server_hash":null,"server_timestamp":"1785122401671","session_id":"dd162b8dca5f43ff811d304e69a06123","source":"clob_market_ws"},"received_at":"2026-07-27T03:20:01.556539Z","record_id":"c9e2aa409bd0005b11d3f0b4344d66c8ee6b236a7e5c60257fbd8a311146671a","schema_fingerprint":"4aa3821a28b0b7c2400bc59aba4bcc0a76e971dadd19610d3ad38c768e124dc7","schema_version":"edge-lab-recorder.raw.v1","sequence":null,"source":"clob_market_ws"}
{"event_at":"2026-07-27T03:20:01.674000Z","event_fingerprint":"2c99c26222846e7550686cca6157f0df6b742f6799bbce56c13c56a591fa95c0","payload":{"connection_id":"c7dc2e4762f849c6b6f9306b6518dcab","event_at":"2026-07-27T03:20:01.674000Z","event_type":"price_change","frame_hash":"c063193f8e7cf4a856bbb9e8c49d55fa7b5c2bf43649461bb66f9fffbbfec27d","frame_index":0,"kind":"data","monotonic_ns":224384909861291,"payload":{"event_type":"price_change","market":"0x717c0e8ccd4d5c7040185188fbae28be901ca589a11a94b1b38ca36a79eccfeb","price_changes":[{"asset_id":"41448400836309843603620980831210604935021861034693225347475867885462478926555","best_ask":"0.54","best_bid":"0.53","hash":"f1c5d9b15e23c0ab26ff0c26a9c20198497d4c58","price":"0.01","side":"BUY","size":"5703.02"},{"asset_id":"24254094493625419915756280046002869097156693848522361803041977572204227262166","best_ask":"0.47","best_bid":"0.46","hash":"73bcb71990a4e9b45826a848ef47ebc2909f41d7","price":"0.99","side":"SELL","size":"5703.02"}],"timestamp":"1785122401674"},"payload_hash":"ca925ff3741e415374f4e9719f324bc335423876b803fcef692baf9b983870ae","raw_frame":"{\"market\":\"0x717c0e8ccd4d5c7040185188fbae28be901ca589a11a94b1b38ca36a79eccfeb\", \"price_changes\":[{\"asset_id\":\"41448400836309843603620980831210604935021861034693225347475867885462478926555\", \"price\":\"0.01\", \"size\":\"5703.02\", \"side\":\"BUY\", \"hash\":\"f1c5d9b15e23c0ab26ff0c26a9c20198497d4c58\", \"best_bid\":\"0.53\", \"best_ask\":\"0.54\"}, {\"asset_id\":\"24254094493625419915756280046002869097156693848522361803041977572204227262166\", \"price\":\"0.99\", \"size\":\"5703.02\", \"side\":\"SELL\", \"hash\":\"73bcb71990a4e9b45826a848ef47ebc2909f41d7\", \"best_bid\":\"0.46\", \"best_ask\":\"0.47\"}], \"timestamp\":\"1785122401674\", \"event_type\":\"price_change\"}","received_at":"2026-07-27T03:20:01.558221Z","schema_version":"clob-market-ws.price_change.v1","sequence":null,"server_hash":null,"server_timestamp":"1785122401674","session_id":"dd162b8dca5f43ff811d304e69a06123","source":"clob_market_ws"},"received_at":"2026-07-27T03:20:01.558221Z","record_id":"c925587ea3182c5b6f7e208b50b7e459aefe9efbda2820532cd31e93b240a3cc","schema_fingerprint":"4aa3821a28b0b7c2400bc59aba4bcc0a76e971dadd19610d3ad38c768e124dc7","schema_version":"edge-lab-recorder.raw.v1","sequence":null,"source":"clob_market_ws"}
{"event_at":"2026-07-27T03:20:01.676000Z","event_fingerprint":"98872e923ff820ef7942d54536574b78a454293617ee8418ac043b14ec44ce08","payload":{"connection_id":"c7dc2e4762f849c6b6f9306b6518dcab","event_at":"2026-07-27T03:20:01.676000Z","event_type":"price_change","frame_hash":"27d3105232c9f15d373e5a9b6a00625b59aaeb7c9fd9ed43c6a5b601e6166ff6","frame_index":0,"kind":"data","monotonic_ns":224384912018875,"payload":{"event_type":"price_change","market":"0x717c0e8ccd4d5c7040185188fbae28be901ca589a11a94b1b38ca36a79eccfeb","price_changes":[{"asset_id":"24254094493625419915756280046002869097156693848522361803041977572204227262166","best_ask":"0.47","best_bid":"0.46","hash":"c6de53a512bdd900ac219d61b1d6f4f536159a5a","price":"0.34","side":"BUY","size":"119.4"},{"asset_id":"41448400836309843603620980831210604935021861034693225347475867885462478926555","best_ask":"0.54","best_bid":"0.53","hash":"f028a880ace07f11a8bd9444cb1aaec103db98a9","price":"0.66","side":"SELL","size":"119.4"}],"timestamp":"1785122401676"},"payload_hash":"c8a7ef3d9bfd18a318e16338c690da610d236325d782a74f9ec799bdc63ddc65","raw_frame":"{\"market\":\"0x717c0e8ccd4d5c7040185188fbae28be901ca589a11a94b1b38ca36a79eccfeb\", \"price_changes\":[{\"asset_id\":\"24254094493625419915756280046002869097156693848522361803041977572204227262166\", \"price\":\"0.34\", \"size\":\"119.4\", \"side\":\"BUY\", \"hash\":\"c6de53a512bdd900ac219d61b1d6f4f536159a5a\", \"best_bid\":\"0.46\", \"best_ask\":\"0.47\"}, {\"asset_id\":\"41448400836309843603620980831210604935021861034693225347475867885462478926555\", \"price\":\"0.66\", \"size\":\"119.4\", \"side\":\"SELL\", \"hash\":\"f028a880ace07f11a8bd9444cb1aaec103db98a9\", \"best_bid\":\"0.53\", \"best_ask\":\"0.54\"}], \"timestamp\":\"1785122401676\", \"event_type\":\"price_change\"}","received_at":"2026-07-27T03:20:01.560342Z","schema_version":"clob-market-ws.price_change.v1","sequence":null,"server_hash":null,"server_timestamp":"1785122401676","session_id":"dd162b8dca5f43ff811d304e69a06123","source":"clob_market_ws"},"received_at":"2026-07-27T03:20:01.560342Z","record_id":"6895508bb502820b01fbae5fa72c954021b3fccc046676f52bee48e25bbf10bd","schema_fingerprint":"4aa3821a28b0b7c2400bc59aba4bcc0a76e971dadd19610d3ad38c768e124dc7","schema_version":"edge-lab-recorder.raw.v1","sequence":null,"source":"clob_market_ws"}
{"event_at":"2026-07-27T03:20:01.677000Z","event_fingerprint":"5613cc8a5d16c298fe121a0fd5c3854d427fdca07d07c7d92ef486a314fc2a57","payload":{"connection_id":"c7dc2e4762f849c6b6f9306b6518dcab","event_at":"2026-07-27T03:20:01.677000Z","event_type":"price_change","frame_hash":"a880e30667daaf0ab2d5c5eb6a3f2861cba357c8130b50a6ff512f6266589c59","frame_index":0,"kind":"data","monotonic_ns":224384913765166,"payload":{"event_type":"price_change","market":"0x717c0e8ccd4d5c7040185188fbae28be901ca589a11a94b1b38ca36a79eccfeb","price_changes":[{"asset_id":"24254094493625419915756280046002869097156693848522361803041977572204227262166","best_ask":"0.47","best_bid":"0.46","hash":"1123f045f59e7a155f2483a415e593aaa2b54be7","price":"0.36","side":"BUY","size":"137"},{"asset_id":"41448400836309843603620980831210604935021861034693225347475867885462478926555","best_ask":"0.54","best_bid":"0.53","hash":"015a1b20c95e18ce621fe1dd37bff087fe90fbba","price":"0.64","side":"SELL","size":"137"}],"timestamp":"1785122401677"},"payload_hash":"0c7b84af029a316397b604c21ca75a513d7c1bae0101a01c4771258e96ad2224","raw_frame":"{\"market\":\"0x717c0e8ccd4d5c7040185188fbae28be901ca589a11a94b1b38ca36a79eccfeb\", \"price_changes\":[{\"asset_id\":\"24254094493625419915756280046002869097156693848522361803041977572204227262166\", \"price\":\"0.36\", \"size\":\"137\", \"side\":\"BUY\", \"hash\":\"1123f045f59e7a155f2483a415e593aaa2b54be7\", \"best_bid\":\"0.46\", \"best_ask\":\"0.47\"}, {\"asset_id\":\"41448400836309843603620980831210604935021861034693225347475867885462478926555\", \"price\":\"0.64\", \"size\":\"137\", \"side\":\"SELL\", \"hash\":\"015a1b20c95e18ce621fe1dd37bff087fe90fbba\", \"best_bid\":\"0.53\", \"best_ask\":\"0.54\"}], \"timestamp\":\"1785122401677\", \"event_type\":\"price_change\"}","received_at":"2026-07-27T03:20:01.562124Z","schema_version":"clob-market-ws.price_change.v1","sequence":null,"server_hash":null,"server_timestamp":"1785122401677","session_id":"dd162b8dca5f43ff811d304e69a06123","source":"clob_market_ws"},"received_at":"2026-07-27T03:20:01.562124Z","record_id":"34bf1b73843cad83a145d1c6cf0eeadad575fa5b62d7fb12dd965ac025f0daec","schema_fingerprint":"4aa3821a28b0b7c2400bc59aba4bcc0a76e971dadd19610d3ad38c768e124dc7","schema_version":"edge-lab-recorder.raw.v1","sequence":null,"source":"clob_market_ws"}
{"event_at":"2026-07-27T03:20:01.680000Z","event_fingerprint":"38e20cbeee5630ba2daa998423bf32c84707314760351bb17cdeae9b0a9d5d8a","payload":{"connection_id":"c7dc2e4762f849c6b6f9306b6518dcab","event_at":"2026-07-27T03:20:01.680000Z","event_type":"price_change","frame_hash":"4efb9a5a329996d3c19d6b7a7600b35f7dc4e4652034f48deb085dc804b521ea","frame_index":0,"kind":"data","monotonic_ns":224384915332666,"payload":{"event_type":"price_change","market":"0x717c0e8ccd4d5c7040185188fbae28be901ca589a11a94b1b38ca36a79eccfeb","price_changes":[{"asset_id":"24254094493625419915756280046002869097156693848522361803041977572204227262166","best_ask":"0.47","best_bid":"0.46","hash":"4d5f0516f2b4761cefc37b0d2eff06698a5d028a","price":"0.35","side":"BUY","size":"129.2"},{"asset_id":"41448400836309843603620980831210604935021861034693225347475867885462478926555","best_ask":"0.54","best_bid":"0.53","hash":"30916ee7ac725e6f120971c7c8dae34d8646718f","price":"0.65","side":"SELL","size":"129.2"}],"timestamp":"1785122401680"},"payload_hash":"6216d78620e33014483e96f9fea73107ab2d893ad1b12c4fdb0b1e1fe22f433b","raw_frame":"{\"market\":\"0x717c0e8ccd4d5c7040185188fbae28be901ca589a11a94b1b38ca36a79eccfeb\", \"price_changes\":[{\"asset_id\":\"24254094493625419915756280046002869097156693848522361803041977572204227262166\", \"price\":\"0.35\", \"size\":\"129.2\", \"side\":\"BUY\", \"hash\":\"4d5f0516f2b4761cefc37b0d2eff06698a5d028a\", \"best_bid\":\"0.46\", \"best_ask\":\"0.47\"}, {\"asset_id\":\"41448400836309843603620980831210604935021861034693225347475867885462478926555\", \"price\":\"0.65\", \"size\":\"129.2\", \"side\":\"SELL\", \"hash\":\"30916ee7ac725e6f120971c7c8dae34d8646718f\", \"best_bid\":\"0.53\", \"best_ask\":\"0.54\"}], \"timestamp\":\"1785122401680\", \"event_type\":\"price_change\"}","received_at":"2026-07-27T03:20:01.563694Z","schema_version":"clob-market-ws.price_change.v1","sequence":null,"server_hash":null,"server_timestamp":"1785122401680","session_id":"dd162b8dca5f43ff811d304e69a06123","source":"clob_market_ws"},"received_at":"2026-07-27T03:20:01.563694Z","record_id":"6050d9eccdc6eac979eb9f100cd2748ce03f2a70ef05bd39a4d9916214064113","schema_fingerprint":"4aa3821a28b0b7c2400bc59aba4bcc0a76e971dadd19610d3ad38c768e124dc7","schema_version":"edge-lab-recorder.raw.v1","sequence":null,"source":"clob_market_ws"}
{"event_at":"2026-07-27T03:20:01.680000Z","event_fingerprint":"e576818f05d4106be49ebe7e36be459cfec24739394ee49573c5c5c540bdbda1","payload":{"connection_id":"c7dc2e4762f849c6b6f9306b6518dcab","event_at":"2026-07-27T03:20:01.680000Z","event_type":"price_change","frame_hash":"9d38e46dfa7b32783956bc60f56bbf59c5ebbab49fdada4b18bb35ef9984a1ba","frame_index":0,"kind":"data","monotonic_ns":224384916980500,"payload":{"event_type":"price_change","market":"0x717c0e8ccd4d5c7040185188fbae28be901ca589a11a94b1b38ca36a79eccfeb","price_changes":[{"asset_id":"24254094493625419915756280046002869097156693848522361803041977572204227262166","best_ask":"0.47","best_bid":"0.46","hash":"98a3cca35ee8ebf69fbba6d867c439387df2ce27","price":"0.37","side":"BUY","size":"141.9"},{"asset_id":"41448400836309843603620980831210604935021861034693225347475867885462478926555","best_ask":"0.54","best_bid":"0.53","hash":"8daf0123db18a147436c734d0e835b9688d2653d","price":"0.63","side":"SELL","size":"141.9"}],"timestamp":"1785122401680"},"payload_hash":"f1def9dda5059560d3d8c84d07ca1fbd23cd313e449b339287bf5ff2425fe79a","raw_frame":"{\"market\":\"0x717c0e8ccd4d5c7040185188fbae28be901ca589a11a94b1b38ca36a79eccfeb\", \"price_changes\":[{\"asset_id\":\"24254094493625419915756280046002869097156693848522361803041977572204227262166\", \"price\":\"0.37\", \"size\":\"141.9\", \"side\":\"BUY\", \"hash\":\"98a3cca35ee8ebf69fbba6d867c439387df2ce27\", \"best_bid\":\"0.46\", \"best_ask\":\"0.47\"}, {\"asset_id\":\"41448400836309843603620980831210604935021861034693225347475867885462478926555\", \"price\":\"0.63\", \"size\":\"141.9\", \"side\":\"SELL\", \"hash\":\"8daf0123db18a147436c734d0e835b9688d2653d\", \"best_bid\":\"0.53\", \"best_ask\":\"0.54\"}], \"timestamp\":\"1785122401680\", \"event_type\":\"price_change\"}","received_at":"2026-07-27T03:20:01.565337Z","schema_version":"clob-market-ws.price_change.v1","sequence":null,"server_hash":null,"server_timestamp":"1785122401680","session_id":"dd162b8dca5f43ff811d304e69a06123","source":"clob_market_ws"},"received_at":"2026-07-27T03:20:01.565337Z","record_id":"8c289ff273e492b8d7d67b19bada2daacabbb73ff65e665ba42112242d5aafd4","schema_fingerprint":"4aa3821a28b0b7c2400bc59aba4bcc0a76e971dadd19610d3ad38c768e124dc7","schema_version":"edge-lab-recorder.raw.v1","sequence":null,"source":"clob_market_ws"}
{"event_at":"2026-07-27T03:20:01.682000Z","event_fingerprint":"671eafc58b52d7084b164bc337500acccb251a23ba2bf4b064545a4c9dc01070","payload":{"connection_id":"c7dc2e4762f849c6b6f9306b6518dcab","event_at":"2026-07-27T03:20:01.682000Z","event_type":"price_change","frame_hash":"8c7de9b91ae5eb382787684bf0f3fdf3a82abb86c9f9504c4bdbb2a3fc1c82d0","frame_index":0,"kind":"data","monotonic_ns":224384918648750,"payload":{"event_type":"price_change","market":"0x717c0e8ccd4d5c7040185188fbae28be901ca589a11a94b1b38ca36a79eccfeb","price_changes":[{"asset_id":"24254094493625419915756280046002869097156693848522361803041977572204227262166","best_ask":"0.47","best_bid":"0.46","hash":"11f7c3150068aeadf64db3e26861bc2e963bf9b6","price":"0.33","side":"BUY","size":"125.6"},{"asset_id":"41448400836309843603620980831210604935021861034693225347475867885462478926555","best_ask":"0.54","best_bid":"0.53","hash":"b16be918452b023d4d6f29b815b6a86582928ca2","price":"0.67","side":"SELL","size":"125.6"}],"timestamp":"1785122401682"},"payload_hash":"c6232c73a84c8c12486fc23ea2b86c6ccca108dff2ec04f5b3fda76f5f1d7353","raw_frame":"{\"market\":\"0x717c0e8ccd4d5c7040185188fbae28be901ca589a11a94b1b38ca36a79eccfeb\", \"price_changes\":[{\"asset_id\":\"24254094493625419915756280046002869097156693848522361803041977572204227262166\", \"price\":\"0.33\", \"size\":\"125.6\", \"side\":\"BUY\", \"hash\":\"11f7c3150068aeadf64db3e26861bc2e963bf9b6\", \"best_bid\":\"0.46\", \"best_ask\":\"0.47\"}, {\"asset_id\":\"41448400836309843603620980831210604935021861034693225347475867885462478926555\", \"price\":\"0.67\", \"size\":\"125.6\", \"side\":\"SELL\", \"hash\":\"b16be918452b023d4d6f29b815b6a86582928ca2\", \"best_bid\":\"0.53\", \"best_ask\":\"0.54\"}], \"timestamp\":\"1785122401682\", \"event_type\":\"price_change\"}","received_at":"2026-07-27T03:20:01.567008Z","schema_version":"clob-market-ws.price_change.v1","sequence":null,"server_hash":null,"server_timestamp":"1785122401682","session_id":"dd162b8dca5f43ff811d304e69a06123","source":"clob_market_ws"},"received_at":"2026-07-27T03:20:01.567008Z","record_id":"ab0a63558ac776feabe6aeab498122a6d4690fc90eef5b46494dda86c0c3c216","schema_fingerprint":"4aa3821a28b0b7c2400bc59aba4bcc0a76e971dadd19610d3ad38c768e124dc7","schema_version":"edge-lab-recorder.raw.v1","sequence":null,"source":"clob_market_ws"}
{"event_at":"2026-07-27T03:20:01.793000Z","event_fingerprint":"5bce87faa90cfcffb872d35375aab014f54ee54bb5d76dd356f5176f4bef2f04","payload":{"connection_id":"c7dc2e4762f849c6b6f9306b6518dcab","event_at":"2026-07-27T03:20:01.793000Z","event_type":"price_change","frame_hash":"4bf7a5e22071d7c1f38cba4e2d3db281e3c96f19a982bab3e00cbba23e8638f8","frame_index":0,"kind":"data","monotonic_ns":224385027613166,"payload":{"event_type":"price_change","market":"0x717c0e8ccd4d5c7040185188fbae28be901ca589a11a94b1b38ca36a79eccfeb","price_changes":[{"asset_id":"24254094493625419915756280046002869097156693848522361803041977572204227262166","best_ask":"0.47","best_bid":"0.46","hash":"da6ee49e80141b5a0153e7898327974ed090f11b","price":"0.35","side":"BUY","size":"123.2"},{"asset_id":"41448400836309843603620980831210604935021861034693225347475867885462478926555","best_ask":"0.54","best_bid":"0.53","hash":"ee273df3557f5dc4757e901ed2445c94d5e2c4ef","price":"0.65","side":"SELL","size":"123.2"}],"timestamp":"1785122401793"},"payload_hash":"d7e2335f88fa207053eed35aa35a628612a41149e0d718a829a82a3d7fe1b474","raw_frame":"{\"market\":\"0x717c0e8ccd4d5c7040185188fbae28be901ca589a11a94b1b38ca36a79eccfeb\", \"price_changes\":[{\"asset_id\":\"24254094493625419915756280046002869097156693848522361803041977572204227262166\", \"price\":\"0.35\", \"size\":\"123.2\", \"side\":\"BUY\", \"hash\":\"da6ee49e80141b5a0153e7898327974ed090f11b\", \"best_bid\":\"0.46\", \"best_ask\":\"0.47\"}, {\"asset_id\":\"41448400836309843603620980831210604935021861034693225347475867885462478926555\", \"price\":\"0.65\", \"size\":\"123.2\", \"side\":\"SELL\", \"hash\":\"ee273df3557f5dc4757e901ed2445c94d5e2c4ef\", \"best_bid\":\"0.53\", \"best_ask\":\"0.54\"}], \"timestamp\":\"1785122401793\", \"event_type\":\"price_change\"}","received_at":"2026-07-27T03:20:01.675950Z","schema_version":"clob-market-ws.price_change.v1","sequence":null,"server_hash":null,"server_timestamp":"1785122401793","session_id":"dd162b8dca5f43ff811d304e69a06123","source":"clob_market_ws"},"received_at":"2026-07-27T03:20:01.675950Z","record_id":"100ddd1950e26d6f291ec2c9d24dd56e47543737d6d3f97a4ddfb9fcd9a366e6","schema_fingerprint":"4aa3821a28b0b7c2400bc59aba4bcc0a76e971dadd19610d3ad38c768e124dc7","schema_version":"edge-lab-recorder.raw.v1","sequence":null,"source":"clob_market_ws"}
{"event_at":"2026-07-27T03:20:01.793000Z","event_fingerprint":"95aa9a3a66d743d285a4221205ae6b1ed0b4f361ee1baefacc722e62f33f89a7","payload":{"connection_id":"c7dc2e4762f849c6b6f9306b6518dcab","event_at":"2026-07-27T03:20:01.793000Z","event_type":"price_change","frame_hash":"a74a450be0dd0ac2d98cd34a24e40636a9822c16bee38b7ef14be6f35c6f7cac","frame_index":0,"kind":"data","monotonic_ns":224385029800250,"payload":{"event_type":"price_change","market":"0x717c0e8ccd4d5c7040185188fbae28be901ca589a11a94b1b38ca36a79eccfeb","price_changes":[{"asset_id":"41448400836309843603620980831210604935021861034693225347475867885462478926555","best_ask":"0.54","best_bid":"0.53","hash":"ee273df3557f5dc4757e901ed2445c94d5e2c4ef","price":"0.48","side":"BUY","size":"63.43"},{"asset_id":"24254094493625419915756280046002869097156693848522361803041977572204227262166","best_ask":"0.47","best_bid":"0.46","hash":"da6ee49e80141b5a0153e7898327974ed090f11b","price":"0.52","side":"SELL","size":"63.43"}],"timestamp":"1785122401793"},"payload_hash":"7e4611580f9770e3cd8e1737c58b19861cd982d2f03e2b1e6b950f4d2b317d39","raw_frame":"{\"market\":\"0x717c0e8ccd4d5c7040185188fbae28be901ca589a11a94b1b38ca36a79eccfeb\", \"price_changes\":[{\"asset_id\":\"41448400836309843603620980831210604935021861034693225347475867885462478926555\", \"price\":\"0.48\", \"size\":\"63.43\", \"side\":\"BUY\", \"hash\":\"ee273df3557f5dc4757e901ed2445c94d5e2c4ef\", \"best_bid\":\"0.53\", \"best_ask\":\"0.54\"}, {\"asset_id\":\"24254094493625419915756280046002869097156693848522361803041977572204227262166\", \"price\":\"0.52\", \"size\":\"63.43\", \"side\":\"SELL\", \"hash\":\"da6ee49e80141b5a0153e7898327974ed090f11b\", \"best_bid\":\"0.46\", \"best_ask\":\"0.47\"}], \"timestamp\":\"1785122401793\", \"event_type\":\"price_change\"}","received_at":"2026-07-27T03:20:01.678139Z","schema_version":"clob-market-ws.price_change.v1","sequence":null,"server_hash":null,"server_timestamp":"1785122401793","session_id":"dd162b8dca5f43ff811d304e69a06123","source":"clob_market_ws"},"received_at":"2026-07-27T03:20:01.678139Z","record_id":"1cbc075ecc0844c5b2e9c9ce5b083e9ad8881b23ba3b26beaa61b09ecdc65484","schema_fingerprint":"4aa3821a28b0b7c2400bc59aba4bcc0a76e971dadd19610d3ad38c768e124dc7","schema_version":"edge-lab-recorder.raw.v1","sequence":null,"source":"clob_market_ws"}
{"event_at":"2026-07-27T03:20:01.793000Z","event_fingerprint":"529690d450ca5a487da5c8003fb1835aa3bcf747c17d32ee2d5baaa9bf853dc2","payload":{"connection_id":"c7dc2e4762f849c6b6f9306b6518dcab","event_at":"2026-07-27T03:20:01.793000Z","event_type":"price_change","frame_hash":"d26114cb7f09c93404a28a5f7ee0471c9bb90cbc2434f5bc813018652ab58bcb","frame_index":0,"kind":"data","monotonic_ns":224385031440125,"payload":{"event_type":"price_change","market":"0x717c0e8ccd4d5c7040185188fbae28be901ca589a11a94b1b38ca36a79eccfeb","price_changes":[{"asset_id":"24254094493625419915756280046002869097156693848522361803041977572204227262166","best_ask":"0.47","best_bid":"0.46","hash":"da6ee49e80141b5a0153e7898327974ed090f11b","price":"0.33","side":"BUY","size":"119.6"},{"asset_id":"41448400836309843603620980831210604935021861034693225347475867885462478926555","best_ask":"0.54","best_bid":"0.53","hash":"ee273df3557f5dc4757e901ed2445c94d5e2c4ef","price":"0.67","side":"SELL","size":"119.6"}],"timestamp":"1785122401793"},"payload_hash":"9e2a44ab9e1a4b5e5388885607f264c29b79cfa218a4abdf9eb875274a2a2fb4","raw_frame":"{\"market\":\"0x717c0e8ccd4d5c7040185188fbae28be901ca589a11a94b1b38ca36a79eccfeb\", \"price_changes\":[{\"asset_id\":\"24254094493625419915756280046002869097156693848522361803041977572204227262166\", \"price\":\"0.33\", \"size\":\"119.6\", \"side\":\"BUY\", \"hash\":\"da6ee49e80141b5a0153e7898327974ed090f11b\", \"best_bid\":\"0.46\", \"best_ask\":\"0.47\"}, {\"asset_id\":\"41448400836309843603620980831210604935021861034693225347475867885462478926555\", \"price\":\"0.67\", \"size\":\"119.6\", \"side\":\"SELL\", \"hash\":\"ee273df3557f5dc4757e901ed2445c94d5e2c4ef\", \"best_bid\":\"0.53\", \"best_ask\":\"0.54\"}], \"timestamp\":\"1785122401793\", \"event_type\":\"price_change\"}","received_at":"2026-07-27T03:20:01.679782Z","schema_version":"clob-market-ws.price_change.v1","sequence":null,"server_hash":null,"server_timestamp":"1785122401793","session_id":"dd162b8dca5f43ff811d304e69a06123","source":"clob_market_ws"},"received_at":"2026-07-27T03:20:01.679782Z","record_id":"1bce5d51a7aceb4f5e6032ea523f09b7f35a9eb6290f4885f95591c316fcc1cf","schema_fingerprint":"4aa3821a28b0b7c2400bc59aba4bcc0a76e971dadd19610d3ad38c768e124dc7","schema_version":"edge-lab-recorder.raw.v1","sequence":null,"source":"clob_market_ws"}
{"event_at":"2026-07-27T03:20:01.793000Z","event_fingerprint":"a0b1842e5b3e7856e4d342f783c9ba76ebd23c78230460553308fcaa5a5992ec","payload":{"connection_id":"c7dc2e4762f849c6b6f9306b6518dcab","event_at":"2026-07-27T03:20:01.793000Z","event_type":"price_change","frame_hash":"286c0bdd308c8c0f5728762d4e9ffabcf6d9f360b3daa2ad820abc13bd9f3654","frame_index":0,"kind":"data","monotonic_ns":224385034844708,"payload":{"event_type":"price_change","market":"0x717c0e8ccd4d5c7040185188fbae28be901ca589a11a94b1b38ca36a79eccfeb","price_changes":[{"asset_id":"24254094493625419915756280046002869097156693848522361803041977572204227262166","best_ask":"0.47","best_bid":"0.46","hash":"da6ee49e80141b5a0153e7898327974ed090f11b","price":"0.37","side":"BUY","size":"136.9"},{"asset_id":"41448400836309843603620980831210604935021861034693225347475867885462478926555","best_ask":"0.54","best_bid":"0.53","hash":"ee273df3557f5dc4757e901ed2445c94d5e2c4ef","price":"0.63","side":"SELL","size":"136.9"}],"timestamp":"1785122401793"},"payload_hash":"8cb194388c921cd2c8eec742b47711871f38674337b4b812dbf76b06f99314ea","raw_frame":"{\"market\":\"0x717c0e8ccd4d5c7040185188fbae28be901ca589a11a94b1b38ca36a79eccfeb\", \"price_changes\":[{\"asset_id\":\"24254094493625419915756280046002869097156693848522361803041977572204227262166\", \"price\":\"0.37\", \"size\":\"136.9\", \"side\":\"BUY\", \"hash\":\"da6ee49e80141b5a0153e7898327974ed090f11b\", \"best_bid\":\"0.46\", \"best_ask\":\"0.47\"}, {\"asset_id\":\"41448400836309843603620980831210604935021861034693225347475867885462478926555\", \"price\":\"0.63\", \"size\":\"136.9\", \"side\":\"SELL\", \"hash\":\"ee273df3557f5dc4757e901ed2445c94d5e2c4ef\", \"best_bid\":\"0.53\", \"best_ask\":\"0.54\"}], \"timestamp\":\"1785122401793\", \"event_type\":\"price_change\"}","received_at":"2026-07-27T03:20:01.683187Z","schema_version":"clob-market-ws.price_change.v1","sequence":null,"server_hash":null,"server_timestamp":"1785122401793","session_id":"dd162b8dca5f43ff811d304e69a06123","source":"clob_market_ws"},"received_at":"2026-07-27T03:20:01.683187Z","record_id":"84b582b76e37abdc90ab79e7e0b725bfeeb4176af745b83ef43ad5b868e1209e","schema_fingerprint":"4aa3821a28b0b7c2400bc59aba4bcc0a76e971dadd19610d3ad38c768e124dc7","schema_version":"edge-lab-recorder.raw.v1","sequence":null,"source":"clob_market_ws"}
{"event_at":"2026-07-27T03:20:01.793000Z","event_fingerprint":"da5c02baf9faf73741911a6f8c9e6181421dee692bbff3e5dc5cb772dfb28935","payload":{"connection_id":"c7dc2e4762f849c6b6f9306b6518dcab","event_at":"2026-07-27T03:20:01.793000Z","event_type":"price_change","frame_hash":"5e5298f6479d47cdf7fe0f178dbccca3deb96b46faef10c2cd945545b9b124dd","frame_index":0,"kind":"data","monotonic_ns":224385036319625,"payload":{"event_type":"price_change","market":"0x717c0e8ccd4d5c7040185188fbae28be901ca589a11a94b1b38ca36a79eccfeb","price_changes":[{"asset_id":"41448400836309843603620980831210604935021861034693225347475867885462478926555","best_ask":"0.54","best_bid":"0.53","hash":"ee273df3557f5dc4757e901ed2445c94d5e2c4ef","price":"0.5","side":"BUY","size":"26.4"},{"asset_id":"24254094493625419915756280046002869097156693848522361803041977572204227262166","best_ask":"0.47","best_bid":"0.46","hash":"da6ee49e80141b5a0153e7898327974ed090f11b","price":"0.5","side":"SELL","size":"26.4"}],"timestamp":"1785122401793"},"payload_hash":"057150b33bdcf69433c5ecdb4e13e0eeec85d70092323dacb2a8e757278ceb03","raw_frame":"{\"market\":\"0x717c0e8ccd4d5c7040185188fbae28be901ca589a11a94b1b38ca36a79eccfeb\", \"price_changes\":[{\"asset_id\":\"41448400836309843603620980831210604935021861034693225347475867885462478926555\", \"price\":\"0.5\", \"size\":\"26.4\", \"side\":\"BUY\", \"hash\":\"ee273df3557f5dc4757e901ed2445c94d5e2c4ef\", \"best_bid\":\"0.53\", \"best_ask\":\"0.54\"}, {\"asset_id\":\"24254094493625419915756280046002869097156693848522361803041977572204227262166\", \"price\":\"0.5\", \"size\":\"26.4\", \"side\":\"SELL\", \"hash\":\"da6ee49e80141b5a0153e7898327974ed090f11b\", \"best_bid\":\"0.46\", \"best_ask\":\"0.47\"}], \"timestamp\":\"1785122401793\", \"event_type\":\"price_change\"}","received_at":"2026-07-27T03:20:01.684665Z","schema_version":"clob-market-ws.price_change.v1","sequence":null,"server_hash":null,"server_timestamp":"1785122401793","session_id":"dd162b8dca5f43ff811d304e69a06123","source":"clob_market_ws"},"received_at":"2026-07-27T03:20:01.684665Z","record_id":"2891d46b237780f404793527a250b802f9d57205c11d81b4f9ef7b608171e62e","schema_fingerprint":"4aa3821a28b0b7c2400bc59aba4bcc0a76e971dadd19610d3ad38c768e124dc7","schema_version":"edge-lab-recorder.raw.v1","sequence":null,"source":"clob_market_ws"}
{"event_at":"2026-07-27T03:20:01.793000Z","event_fingerprint":"30d29c2a7658b25bfdc0aeceb08c978700ac2837d8dd34868f352440d7ade5b2","payload":{"connection_id":"c7dc2e4762f849c6b6f9306b6518dcab","event_at":"2026-07-27T03:20:01.793000Z","event_type":"price_change","frame_hash":"5c8257084ac3d9be253bb55c430d05c21d16dce32470f56a58ebcebdaa29d8ca","frame_index":0,"kind":"data","monotonic_ns":224385037336416,"payload":{"event_type":"price_change","market":"0x717c0e8ccd4d5c7040185188fbae28be901ca589a11a94b1b38ca36a79eccfeb","price_changes":[{"asset_id":"41448400836309843603620980831210604935021861034693225347475867885462478926555","best_ask":"0.54","best_bid":"0.53","hash":"ee273df3557f5dc4757e901ed2445c94d5e2c4ef","price":"0.52","side":"BUY","size":"9.6"},{"asset_id":"24254094493625419915756280046002869097156693848522361803041977572204227262166","best_ask":"0.47","best_bid":"0.46","hash":"da6ee49e80141b5a0153e7898327974ed090f11b","price":"0.48","side":"SELL","size":"9.6"}],"timestamp":"1785122401793"},"payload_hash":"952cfa9afaec26d5113324b55e8f32855ce2660060dfe322799f851de8c79f2c","raw_frame":"{\"market\":\"0x717c0e8ccd4d5c7040185188fbae28be901ca589a11a94b1b38ca36a79eccfeb\", \"price_changes\":[{\"asset_id\":\"41448400836309843603620980831210604935021861034693225347475867885462478926555\", \"price\":\"0.52\", \"size\":\"9.6\", \"side\":\"BUY\", \"hash\":\"ee273df3557f5dc4757e901ed2445c94d5e2c4ef\", \"best_bid\":\"0.53\", \"best_ask\":\"0.54\"}, {\"asset_id\":\"24254094493625419915756280046002869097156693848522361803041977572204227262166\", \"price\":\"0.48\", \"size\":\"9.6\", \"side\":\"SELL\", \"hash\":\"da6ee49e80141b5a0153e7898327974ed090f11b\", \"best_bid\":\"0.46\", \"best_ask\":\"0.47\"}], \"timestamp\":\"1785122401793\", \"event_type\":\"price_change\"}","received_at":"2026-07-27T03:20:01.685682Z","schema_version":"clob-market-ws.price_change.v1","sequence":null,"server_hash":null,"server_timestamp":"1785122401793","session_id":"dd162b8dca5f43ff811d304e69a06123","source":"clob_market_ws"},"received_at":"2026-07-27T03:20:01.685682Z","record_id":"fbd886997fbd821984267449cead6baff9072a565985e4f028c0f6c99c94b1cd","schema_fingerprint":"4aa3821a28b0b7c2400bc59aba4bcc0a76e971dadd19610d3ad38c768e124dc7","schema_version":"edge-lab-recorder.raw.v1","sequence":null,"source":"clob_market_ws"}
{"event_at":"2026-07-27T03:20:01.794000Z","event_fingerprint":"55b037f2149c2aff3e2b323a9a28752b8ac1d51a4099788385b1f503b9114de3","payload":{"connection_id":"c7dc2e4762f849c6b6f9306b6518dcab","event_at":"2026-07-27T03:20:01.794000Z","event_type":"price_change","frame_hash":"2b1e43f569a622d08f7873805417b0d430a4834da06fe57bd80de745df9dd131","frame_index":0,"kind":"data","monotonic_ns":224385038298083,"payload":{"event_type":"price_change","market":"0x717c0e8ccd4d5c7040185188fbae28be901ca589a11a94b1b38ca36a79eccfeb","price_changes":[{"asset_id":"41448400836309843603620980831210604935021861034693225347475867885462478926555","best_ask":"0.54","best_bid":"0.53","hash":"ef0600afc6aab6a584d66c30e2cb079eabb6acc6","price":"0.49","side":"BUY","size":"41.4"},{"asset_id":"24254094493625419915756280046002869097156693848522361803041977572204227262166","best_ask":"0.47","best_bid":"0.46","hash":"c3110ced918d2011b928d6fba67bc35602e6a280","price":"0.51","side":"SELL","size":"41.4"}],"timestamp":"1785122401794"},"payload_hash":"5d56e44af0a646ad9c8a8c99af0a57f7486bc4d1d089a11c776a4d29e8e3b412","raw_frame":"{\"market\":\"0x717c0e8ccd4d5c7040185188fbae28be901ca589a11a94b1b38ca36a79eccfeb\", \"price_changes\":[{\"asset_id\":\"41448400836309843603620980831210604935021861034693225347475867885462478926555\", \"price\":\"0.49\", \"size\":\"41.4\", \"side\":\"BUY\", \"hash\":\"ef0600afc6aab6a584d66c30e2cb079eabb6acc6\", \"best_bid\":\"0.53\", \"best_ask\":\"0.54\"}, {\"asset_id\":\"24254094493625419915756280046002869097156693848522361803041977572204227262166\", \"price\":\"0.51\", \"size\":\"41.4\", \"side\":\"SELL\", \"hash\":\"c3110ced918d2011b928d6fba67bc35602e6a280\", \"best_bid\":\"0.46\", \"best_ask\":\"0.47\"}], \"timestamp\":\"1785122401794\", \"event_type\":\"price_change\"}","received_at":"2026-07-27T03:20:01.686643Z","schema_version":"clob-market-ws.price_change.v1","sequence":null,"server_hash":null,"server_timestamp":"1785122401794","session_id":"dd162b8dca5f43ff811d304e69a06123","source":"clob_market_ws"},"received_at":"2026-07-27T03:20:01.686643Z","record_id":"74ecb42d1e07bfd496f5c8fc95681b10fdab98736e3ff3d1924b99466cde4d47","schema_fingerprint":"4aa3821a28b0b7c2400bc59aba4bcc0a76e971dadd19610d3ad38c768e124dc7","schema_version":"edge-lab-recorder.raw.v1","sequence":null,"source":"clob_market_ws"}
{"event_at":"2026-07-27T03:20:01.795000Z","event_fingerprint":"0235c1c7b8039bde34f7144fc7f581645aa14930078e89771134c0476541aead","payload":{"connection_id":"c7dc2e4762f849c6b6f9306b6518dcab","event_at":"2026-07-27T03:20:01.795000Z","event_type":"price_change","frame_hash":"dcd5c2128913f0a282764cde6b89d504a8d9f878c2d4db2c782ba762853ba319","frame_index":0,"kind":"data","monotonic_ns":224385039574000,"payload":{"event_type":"price_change","market":"0x717c0e8ccd4d5c7040185188fbae28be901ca589a11a94b1b38ca36a79eccfeb","price_changes":[{"asset_id":"24254094493625419915756280046002869097156693848522361803041977572204227262166","best_ask":"0.47","best_bid":"0.46","hash":"3027fbbab90a70f0324561df0bcadde625c49cc3","price":"0.34","side":"BUY","size":"125.4"},{"asset_id":"41448400836309843603620980831210604935021861034693225347475867885462478926555","best_ask":"0.54","best_bid":"0.53","hash":"a52f15738c0c0f3923c0137aeeff4f4bbfbf31d5","price":"0.66","side":"SELL","size":"125.4"}],"timestamp":"1785122401795"},"payload_hash":"64c1fb8c499d51722c835134aae811682890811602c799ccbc40a6cb1b586803","raw_frame":"{\"market\":\"0x717c0e8ccd4d5c7040185188fbae28be901ca589a11a94b1b38ca36a79eccfeb\", \"price_changes\":[{\"asset_id\":\"24254094493625419915756280046002869097156693848522361803041977572204227262166\", \"price\":\"0.34\", \"size\":\"125.4\", \"side\":\"BUY\", \"hash\":\"3027fbbab90a70f0324561df0bcadde625c49cc3\", \"best_bid\":\"0.46\", \"best_ask\":\"0.47\"}, {\"asset_id\":\"41448400836309843603620980831210604935021861034693225347475867885462478926555\", \"price\":\"0.66\", \"size\":\"125.4\", \"side\":\"SELL\", \"hash\":\"a52f15738c0c0f3923c0137aeeff4f4bbfbf31d5\", \"best_bid\":\"0.53\", \"best_ask\":\"0.54\"}], \"timestamp\":\"1785122401795\", \"event_type\":\"price_change\"}","received_at":"2026-07-27T03:20:01.687916Z","schema_version":"clob-market-ws.price_change.v1","sequence":null,"server_hash":null,"server_timestamp":"1785122401795","session_id":"dd162b8dca5f43ff811d304e69a06123","source":"clob_market_ws"},"received_at":"2026-07-27T03:20:01.687916Z","record_id":"aa9de25579317d1e3e555a2b0e86afe5f028a76953d8d4451a0c331b6b36d246","schema_fingerprint":"4aa3821a28b0b7c2400bc59aba4bcc0a76e971dadd19610d3ad38c768e124dc7","schema_version":"edge-lab-recorder.raw.v1","sequence":null,"source":"clob_market_ws"}
{"event_at":"2026-07-27T03:20:01.795000Z","event_fingerprint":"af0d672f4f235a25e57f597897fa867770414c891502692675c03cd11e774bb9","payload":{"connection_id":"c7dc2e4762f849c6b6f9306b6518dcab","event_at":"2026-07-27T03:20:01.795000Z","event_type":"price_change","frame_hash":"a52c30a276543dd16fc33587c5a20e156127293286182190914687e42045c308","frame_index":0,"kind":"data","monotonic_ns":224385041078625,"payload":{"event_type":"price_change","market":"0x717c0e8ccd4d5c7040185188fbae28be901ca589a11a94b1b38ca36a79eccfeb","price_changes":[{"asset_id":"41448400836309843603620980831210604935021861034693225347475867885462478926555","best_ask":"0.54","best_bid":"0.53","hash":"d1ad642e54ecc2f9d2e4474573324013db9d6268","price":"0.51","side":"BUY","size":"33.6"},{"asset_id":"24254094493625419915756280046002869097156693848522361803041977572204227262166","best_ask":"0.47","best_bid":"0.46","hash":"04825efb389a77467bf69b346cc65129b8684347","price":"0.49","side":"SELL","size":"33.6"}],"timestamp":"1785122401795"},"payload_hash":"5fdd7247084622c3e8669e3b918ed10c51d464e2e114ab281a6b0531e863e584","raw_frame":"{\"market\":\"0x717c0e8ccd4d5c7040185188fbae28be901ca589a11a94b1b38ca36a79eccfeb\", \"price_changes\":[{\"asset_id\":\"41448400836309843603620980831210604935021861034693225347475867885462478926555\", \"price\":\"0.51\", \"size\":\"33.6\", \"side\":\"BUY\", \"hash\":\"d1ad642e54ecc2f9d2e4474573324013db9d6268\", \"best_bid\":\"0.53\", \"best_ask\":\"0.54\"}, {\"asset_id\":\"24254094493625419915756280046002869097156693848522361803041977572204227262166\", \"price\":\"0.49\", \"size\":\"33.6\", \"side\":\"SELL\", \"hash\":\"04825efb389a77467bf69b346cc65129b8684347\", \"best_bid\":\"0.46\", \"best_ask\":\"0.47\"}], \"timestamp\":\"1785122401795\", \"event_type\":\"price_change\"}","received_at":"2026-07-27T03:20:01.689421Z","schema_version":"clob-market-ws.price_change.v1","sequence":null,"server_hash":null,"server_timestamp":"1785122401795","session_id":"dd162b8dca5f43ff811d304e69a06123","source":"clob_market_ws"},"received_at":"2026-07-27T03:20:01.689421Z","record_id":"b97dd42764e79f10ba64f67dd488dc34fcbc75fb45a1a630eaaa45ebaa56392b","schema_fingerprint":"4aa3821a28b0b7c2400bc59aba4bcc0a76e971dadd19610d3ad38c768e124dc7","schema_version":"edge-lab-recorder.raw.v1","sequence":null,"source":"clob_market_ws"}
{"event_at":"2026-07-27T03:20:01.796000Z","event_fingerprint":"898060cf16e03402e85cdea25750b7192b4304f29e0d8530817b59a09451e4ea","payload":{"connection_id":"c7dc2e4762f849c6b6f9306b6518dcab","event_at":"2026-07-27T03:20:01.796000Z","event_type":"price_change","frame_hash":"78ae7b1058bee35cf16b14f564f6a72f9e047ddfcc75e2c30edb76785f62a4b6","frame_index":0,"kind":"data","monotonic_ns":224385045590291,"payload":{"event_type":"price_change","market":"0x717c0e8ccd4d5c7040185188fbae28be901ca589a11a94b1b38ca36a79eccfeb","price_changes":[{"asset_id":"24254094493625419915756280046002869097156693848522361803041977572204227262166","best_ask":"0.47","best_bid":"0.46","hash":"6d41476bd1789544960b31287bbdf3a828bccfd6","price":"0.36","side":"BUY","size":"145"},{"asset_id":"41448400836309843603620980831210604935021861034693225347475867885462478926555","best_ask":"0.54","best_bid":"0.53","hash":"27fea32824f4ab20403030b54d993ce8bf6fa316","price":"0.64","side":"SELL","size":"145"}],"timestamp":"1785122401796"},"payload_hash":"77337e0c0bb219a6cb88b7a229f8c01dce57654f9de74119490d777c9a7703c0","raw_frame":"{\"market\":\"0x717c0e8ccd4d5c7040185188fbae28be901ca589a11a94b1b38ca36a79eccfeb\", \"price_changes\":[{\"asset_id\":\"24254094493625419915756280046002869097156693848522361803041977572204227262166\", \"price\":\"0.36\", \"size\":\"145\", \"side\":\"BUY\", \"hash\":\"6d41476bd1789544960b31287bbdf3a828bccfd6\", \"best_bid\":\"0.46\", \"best_ask\":\"0.47\"}, {\"asset_id\":\"41448400836309843603620980831210604935021861034693225347475867885462478926555\", \"price\":\"0.64\", \"size\":\"145\", \"side\":\"SELL\", \"hash\":\"27fea32824f4ab20403030b54d993ce8bf6fa316\", \"best_bid\":\"0.53\", \"best_ask\":\"0.54\"}], \"timestamp\":\"1785122401796\", \"event_type\":\"price_change\"}","received_at":"2026-07-27T03:20:01.693927Z","schema_version":"clob-market-ws.price_change.v1","sequence":null,"server_hash":null,"server_timestamp":"1785122401796","session_id":"dd162b8dca5f43ff811d304e69a06123","source":"clob_market_ws"},"received_at":"2026-07-27T03:20:01.693927Z","record_id":"1a0934303ac61b399bae81baf9a7aad2d1ac037654d8b67a0da25bb417c97add","schema_fingerprint":"4aa3821a28b0b7c2400bc59aba4bcc0a76e971dadd19610d3ad38c768e124dc7","schema_version":"edge-lab-recorder.raw.v1","sequence":null,"source":"clob_market_ws"}
{"event_at":"2026-07-27T03:20:01.819000Z","event_fingerprint":"d36ad24f49308083a8d63904261e5407484e38ad8f6abc10a3905c0c3d26fe35","payload":{"connection_id":"c7dc2e4762f849c6b6f9306b6518dcab","event_at":"2026-07-27T03:20:01.819000Z","event_type":"price_change","frame_hash":"5c9a6a87c1fae31c95e40e3f9bf9fc38a67f5d884e0d7efbbd9d84638ddcef0d","frame_index":0,"kind":"data","monotonic_ns":224385053661541,"payload":{"event_type":"price_change","market":"0x717c0e8ccd4d5c7040185188fbae28be901ca589a11a94b1b38ca36a79eccfeb","price_changes":[{"asset_id":"41448400836309843603620980831210604935021861034693225347475867885462478926555","best_ask":"0.54","best_bid":"0.53","hash":"1d3721dcd625d845faa09ae726a90b4dfa54853e","price":"0.01","side":"BUY","size":"5708.02"},{"asset_id":"24254094493625419915756280046002869097156693848522361803041977572204227262166","best_ask":"0.47","best_bid":"0.46","hash":"777c51d0351dadc3017e06d7a276be9ef2637c57","price":"0.99","side":"SELL","size":"5708.02"}],"timestamp":"1785122401819"},"payload_hash":"0932079849cc7816f06ccff7c75f40139390195fb6891a1a5284c585b2f2d0ad","raw_frame":"{\"market\":\"0x717c0e8ccd4d5c7040185188fbae28be901ca589a11a94b1b38ca36a79eccfeb\", \"price_changes\":[{\"asset_id\":\"41448400836309843603620980831210604935021861034693225347475867885462478926555\", \"price\":\"0.01\", \"size\":\"5708.02\", \"side\":\"BUY\", \"hash\":\"1d3721dcd625d845faa09ae726a90b4dfa54853e\", \"best_bid\":\"0.53\", \"best_ask\":\"0.54\"}, {\"asset_id\":\"24254094493625419915756280046002869097156693848522361803041977572204227262166\", \"price\":\"0.99\", \"size\":\"5708.02\", \"side\":\"SELL\", \"hash\":\"777c51d0351dadc3017e06d7a276be9ef2637c57\", \"best_bid\":\"0.46\", \"best_ask\":\"0.47\"}], \"timestamp\":\"1785122401819\", \"event_type\":\"price_change\"}","received_at":"2026-07-27T03:20:01.701998Z","schema_version":"clob-market-ws.price_change.v1","sequence":null,"server_hash":null,"server_timestamp":"1785122401819","session_id":"dd162b8dca5f43ff811d304e69a06123","source":"clob_market_ws"},"received_at":"2026-07-27T03:20:01.701998Z","record_id":"88bfe6e06cdf7e3d1ad1c9f457b55d2d9d955ccff4dacb17a7369993a019934b","schema_fingerprint":"4aa3821a28b0b7c2400bc59aba4bcc0a76e971dadd19610d3ad38c768e124dc7","schema_version":"edge-lab-recorder.raw.v1","sequence":null,"source":"clob_market_ws"}
{"event_at":"2026-07-27T03:20:01.846000Z","event_fingerprint":"2d96ba7cf6cd0fac058ea1ace91a2cae9f5be74953b94c3e883b1cedf6591112","payload":{"connection_id":"c7dc2e4762f849c6b6f9306b6518dcab","event_at":"2026-07-27T03:20:01.846000Z","event_type":"price_change","frame_hash":"f64ffb7a533c29bdda8879a57097cb3290968e56b5881bad5eeb85bed8aa6faa","frame_index":0,"kind":"data","monotonic_ns":224385082215625,"payload":{"event_type":"price_change","market":"0x717c0e8ccd4d5c7040185188fbae28be901ca589a11a94b1b38ca36a79eccfeb","price_changes":[{"asset_id":"24254094493625419915756280046002869097156693848522361803041977572204227262166","best_ask":"0.47","best_bid":"0.46","hash":"4cd49d2ca078c5259adb24dd2adea75c3dd20c70","price":"0.02","side":"BUY","size":"678.1"},{"asset_id":"41448400836309843603620980831210604935021861034693225347475867885462478926555","best_ask":"0.54","best_bid":"0.53","hash":"376a8df2d6ee497ec99c8ba200e57a8f8bfb1ebb","price":"0.98","side":"SELL","size":"678.1"}],"timestamp":"1785122401846"},"payload_hash":"cda87827a24ac62487ae0594774875fbfc7c1a40b2e0af85663905e947ac1a32","raw_frame":"{\"market\":\"0x717c0e8ccd4d5c7040185188fbae28be901ca589a11a94b1b38ca36a79eccfeb\", \"price_changes\":[{\"asset_id\":\"24254094493625419915756280046002869097156693848522361803041977572204227262166\", \"price\":\"0.02\", \"size\":\"678.1\", \"side\":\"BUY\", \"hash\":\"4cd49d2ca078c5259adb24dd2adea75c3dd20c70\", \"best_bid\":\"0.46\", \"best_ask\":\"0.47\"}, {\"asset_id\":\"41448400836309843603620980831210604935021861034693225347475867885462478926555\", \"price\":\"0.98\", \"size\":\"678.1\", \"side\":\"SELL\", \"hash\":\"376a8df2d6ee497ec99c8ba200e57a8f8bfb1ebb\", \"best_bid\":\"0.53\", \"best_ask\":\"0.54\"}], \"timestamp\":\"1785122401846\", \"event_type\":\"price_change\"}","received_at":"2026-07-27T03:20:01.730549Z","schema_version":"clob-market-ws.price_change.v1","sequence":null,"server_hash":null,"server_timestamp":"1785122401846","session_id":"dd162b8dca5f43ff811d304e69a06123","source":"clob_market_ws"},"received_at":"2026-07-27T03:20:01.730549Z","record_id":"b44cfcab62dc470e0a67210e7a4c4dabf44bdef6d70f9ecd9251b6cedff6d8ba","schema_fingerprint":"4aa3821a28b0b7c2400bc59aba4bcc0a76e971dadd19610d3ad38c768e124dc7","schema_version":"edge-lab-recorder.raw.v1","sequence":null,"source":"clob_market_ws"}
{"event_at":"2026-07-27T03:20:01.850000Z","event_fingerprint":"44cccf3e5a5e8c59d8975b77c7a88280bd9423d2544f6b418b54de609841ba7a","payload":{"connection_id":"c7dc2e4762f849c6b6f9306b6518dcab","event_at":"2026-07-27T03:20:01.850000Z","event_type":"price_change","frame_hash":"3c7e413cb146ebeb2619907f3c48cc1267fdc3195d42dd81f441bf8e041ef0ea","frame_index":0,"kind":"data","monotonic_ns":224385085299625,"payload":{"event_type":"price_change","market":"0x717c0e8ccd4d5c7040185188fbae28be901ca589a11a94b1b38ca36a79eccfeb","price_changes":[{"asset_id":"41448400836309843603620980831210604935021861034693225347475867885462478926555","best_ask":"0.54","best_bid":"0.53","hash":"acfe4df06a76fe05c86ba3a50f19fb7f71334413","price":"0.01","side":"BUY","size":"5713.02"},{"asset_id":"24254094493625419915756280046002869097156693848522361803041977572204227262166","best_ask":"0.47","best_bid":"0.46","hash":"253052bdba7c5fc579196fe81721d6e984eeb371","price":"0.99","side":"SELL","size":"5713.02"}],"timestamp":"1785122401850"},"payload_hash":"28518746a5cafdcf64520002a350ec1f526dde89c9420e178ace12e8101aba14","raw_frame":"{\"market\":\"0x717c0e8ccd4d5c7040185188fbae28be901ca589a11a94b1b38ca36a79eccfeb\", \"price_changes\":[{\"asset_id\":\"41448400836309843603620980831210604935021861034693225347475867885462478926555\", \"price\":\"0.01\", \"size\":\"5713.02\", \"side\":\"BUY\", \"hash\":\"acfe4df06a76fe05c86ba3a50f19fb7f71334413\", \"best_bid\":\"0.53\", \"best_ask\":\"0.54\"}, {\"asset_id\":\"24254094493625419915756280046002869097156693848522361803041977572204227262166\", \"price\":\"0.99\", \"size\":\"5713.02\", \"side\":\"SELL\", \"hash\":\"253052bdba7c5fc579196fe81721d6e984eeb371\", \"best_bid\":\"0.46\", \"best_ask\":\"0.47\"}], \"timestamp\":\"1785122401850\", \"event_type\":\"price_change\"}","received_at":"2026-07-27T03:20:01.733633Z","schema_version":"clob-market-ws.price_change.v1","sequence":null,"server_hash":null,"server_timestamp":"1785122401850","session_id":"dd162b8dca5f43ff811d304e69a06123","source":"clob_market_ws"},"received_at":"2026-07-27T03:20:01.733633Z","record_id":"fa4582e57693bb75efb2fddfe7388dc923f3eb99bbb51aa84e3cf7a58570a789","schema_fingerprint":"4aa3821a28b0b7c2400bc59aba4bcc0a76e971dadd19610d3ad38c768e124dc7","schema_version":"edge-lab-recorder.raw.v1","sequence":null,"source":"clob_market_ws"}
{"event_at":"2026-07-27T03:20:01.870000Z","event_fingerprint":"5298ecf3ed234a8a52561102ff8debee97dd2062cf7aa66ffd36680da486d805","payload":{"connection_id":"c7dc2e4762f849c6b6f9306b6518dcab","event_at":"2026-07-27T03:20:01.870000Z","event_type":"price_change","frame_hash":"7792e9e922dacdc807e4ced8c3a9b26cb7642822a374314aee618ecee3ab99f6","frame_index":0,"kind":"data","monotonic_ns":224385105397708,"payload":{"event_type":"price_change","market":"0x717c0e8ccd4d5c7040185188fbae28be901ca589a11a94b1b38ca36a79eccfeb","price_changes":[{"asset_id":"41448400836309843603620980831210604935021861034693225347475867885462478926555","best_ask":"0.54","best_bid":"0.53","hash":"67fc493d705b1812be77fc413c43b4ff53354ce1","price":"0.01","side":"BUY","size":"5708.02"},{"asset_id":"24254094493625419915756280046002869097156693848522361803041977572204227262166","best_ask":"0.47","best_bid":"0.46","hash":"64af9e9d1c5561378fe869826f141b454e273cd5","price":"0.99","side":"SELL","size":"5708.02"}],"timestamp":"1785122401870"},"payload_hash":"61d62105159a7497eae2e4011b3275b79d7123a905bb1e1e5fc54095f43472cd","raw_frame":"{\"market\":\"0x717c0e8ccd4d5c7040185188fbae28be901ca589a11a94b1b38ca36a79eccfeb\", \"price_changes\":[{\"asset_id\":\"41448400836309843603620980831210604935021861034693225347475867885462478926555\", \"price\":\"0.01\", \"size\":\"5708.02\", \"side\":\"BUY\", \"hash\":\"67fc493d705b1812be77fc413c43b4ff53354ce1\", \"best_bid\":\"0.53\", \"best_ask\":\"0.54\"}, {\"asset_id\":\"24254094493625419915756280046002869097156693848522361803041977572204227262166\", \"price\":\"0.99\", \"size\":\"5708.02\", \"side\":\"SELL\", \"hash\":\"64af9e9d1c5561378fe869826f141b454e273cd5\", \"best_bid\":\"0.46\", \"best_ask\":\"0.47\"}], \"timestamp\":\"1785122401870\", \"event_type\":\"price_change\"}","received_at":"2026-07-27T03:20:01.753729Z","schema_version":"clob-market-ws.price_change.v1","sequence":null,"server_hash":null,"server_timestamp":"1785122401870","session_id":"dd162b8dca5f43ff811d304e69a06123","source":"clob_market_ws"},"received_at":"2026-07-27T03:20:01.753729Z","record_id":"305b980afd7c7aaaa2721dceaa1c9d26e31da1fe0d125a11d2f40671e3a99ea6","schema_fingerprint":"4aa3821a28b0b7c2400bc59aba4bcc0a76e971dadd19610d3ad38c768e124dc7","schema_version":"edge-lab-recorder.raw.v1","sequence":null,"source":"clob_market_ws"}
{"event_at":"2026-07-27T03:20:01.872000Z","event_fingerprint":"027aea56f76a3450e4ded1754be2f9b11f9551619f2dd3b8dddfb7ec85f9e18e","payload":{"connection_id":"c7dc2e4762f849c6b6f9306b6518dcab","event_at":"2026-07-27T03:20:01.872000Z","event_type":"price_change","frame_hash":"d4fefc054e554e1e421f7f4c21e34d45ee902e4b1c11704d0d03bad767ca18cb","frame_index":0,"kind":"data","monotonic_ns":224385107925916,"payload":{"event_type":"price_change","market":"0x717c0e8ccd4d5c7040185188fbae28be901ca589a11a94b1b38ca36a79eccfeb","price_changes":[{"asset_id":"41448400836309843603620980831210604935021861034693225347475867885462478926555","best_ask":"0.54","best_bid":"0.53","hash":"d529c841deced54e8ed9666079c4c30ff3aeeed2","price":"0.01","side":"BUY","size":"5703.02"},{"asset_id":"24254094493625419915756280046002869097156693848522361803041977572204227262166","best_ask":"0.47","best_bid":"0.46","hash":"edeebd92d480d43d4def582017c3dd526e9af443","price":"0.99","side":"SELL","size":"5703.02"}],"timestamp":"1785122401872"},"payload_hash":"691d91c23c3c14372943070761b0857728722b640e9a358073a9e425d39c9f1a","raw_frame":"{\"market\":\"0x717c0e8ccd4d5c7040185188fbae28be901ca589a11a94b1b38ca36a79eccfeb\", \"price_changes\":[{\"asset_id\":\"41448400836309843603620980831210604935021861034693225347475867885462478926555\", \"price\":\"0.01\", \"size\":\"5703.02\", \"side\":\"BUY\", \"hash\":\"d529c841deced54e8ed9666079c4c30ff3aeeed2\", \"best_bid\":\"0.53\", \"best_ask\":\"0.54\"}, {\"asset_id\":\"24254094493625419915756280046002869097156693848522361803041977572204227262166\", \"price\":\"0.99\", \"size\":\"5703.02\", \"side\":\"SELL\", \"hash\":\"edeebd92d480d43d4def582017c3dd526e9af443\", \"best_bid\":\"0.46\", \"best_ask\":\"0.47\"}], \"timestamp\":\"1785122401872\", \"event_type\":\"price_change\"}","received_at":"2026-07-27T03:20:01.756257Z","schema_version":"clob-market-ws.price_change.v1","sequence":null,"server_hash":null,"server_timestamp":"1785122401872","session_id":"dd162b8dca5f43ff811d304e69a06123","source":"clob_market_ws"},"received_at":"2026-07-27T03:20:01.756257Z","record_id":"11e87cd8295003963595f898edf8745116b95cd09240645f2d0ac3e0d25f5e9a","schema_fingerprint":"4aa3821a28b0b7c2400bc59aba4bcc0a76e971dadd19610d3ad38c768e124dc7","schema_version":"edge-lab-recorder.raw.v1","sequence":null,"source":"clob_market_ws"}
{"event_at":"2026-07-27T03:20:01.994000Z","event_fingerprint":"8fa1a2f5777c9984e9b4b5ddded5a04a86c40ff5459a0d4f58d2296f374f5906","payload":{"connection_id":"c7dc2e4762f849c6b6f9306b6518dcab","event_at":"2026-07-27T03:20:01.994000Z","event_type":"price_change","frame_hash":"d8519a6bc402fc6cf3b2d21e8a6f01345e3250f755102ce2270ac6c7a85c2aa1","frame_index":0,"kind":"data","monotonic_ns":224385228541583,"payload":{"event_type":"price_change","market":"0x717c0e8ccd4d5c7040185188fbae28be901ca589a11a94b1b38ca36a79eccfeb","price_changes":[{"asset_id":"41448400836309843603620980831210604935021861034693225347475867885462478926555","best_ask":"0.54","best_bid":"0.53","hash":"f0ac867316197f7252b66c45dfc14e377e561754","price":"0.49","side":"BUY","size":"36.4"},{"asset_id":"24254094493625419915756280046002869097156693848522361803041977572204227262166","best_ask":"0.47","best_bid":"0.46","hash":"ae52a572197bd47b592a5bbea5bd2743bfc8bb17","price":"0.51","side":"SELL","size":"36.4"}],"timestamp":"1785122401994"},"payload_hash":"310dca437e825dcd2020cdce5be1a660cb159cb074d5d000303f79d038d63ad3","raw_frame":"{\"market\":\"0x717c0e8ccd4d5c7040185188fbae28be901ca589a11a94b1b38ca36a79eccfeb\", \"price_changes\":[{\"asset_id\":\"41448400836309843603620980831210604935021861034693225347475867885462478926555\", \"price\":\"0.49\", \"size\":\"36.4\", \"side\":\"BUY\", \"hash\":\"f0ac867316197f7252b66c45dfc14e377e561754\", \"best_bid\":\"0.53\", \"best_ask\":\"0.54\"}, {\"asset_id\":\"24254094493625419915756280046002869097156693848522361803041977572204227262166\", \"price\":\"0.51\", \"size\":\"36.4\", \"side\":\"SELL\", \"hash\":\"ae52a572197bd47b592a5bbea5bd2743bfc8bb17\", \"best_bid\":\"0.46\", \"best_ask\":\"0.47\"}], \"timestamp\":\"1785122401994\", \"event_type\":\"price_change\"}","received_at":"2026-07-27T03:20:01.876847Z","schema_version":"clob-market-ws.price_change.v1","sequence":null,"server_hash":null,"server_timestamp":"1785122401994","session_id":"dd162b8dca5f43ff811d304e69a06123","source":"clob_market_ws"},"received_at":"2026-07-27T03:20:01.876847Z","record_id":"029426a5995a716b08272878be23bd3ff6b81b456cefa8871ea3e0d69428ac63","schema_fingerprint":"4aa3821a28b0b7c2400bc59aba4bcc0a76e971dadd19610d3ad38c768e124dc7","schema_version":"edge-lab-recorder.raw.v1","sequence":null,"source":"clob_market_ws"}
{"event_at":"2026-07-27T03:20:01.994000Z","event_fingerprint":"7eee5426a0e53cf03c6a19f68329b03b91affcad39706037e4d6da9e7e840418","payload":{"connection_id":"c7dc2e4762f849c6b6f9306b6518dcab","event_at":"2026-07-27T03:20:01.994000Z","event_type":"price_change","frame_hash":"7a38a67f842d3a949966a60efdfd6bf20d092315ca52c173e43f5e6d65493b99","frame_index":0,"kind":"data","monotonic_ns":224385230310041,"payload":{"event_type":"price_change","market":"0x717c0e8ccd4d5c7040185188fbae28be901ca589a11a94b1b38ca36a79eccfeb","price_changes":[{"asset_id":"41448400836309843603620980831210604935021861034693225347475867885462478926555","best_ask":"0.54","best_bid":"0.53","hash":"f0ac867316197f7252b66c45dfc14e377e561754","price":"0.51","side":"BUY","size":"9.6"},{"asset_id":"24254094493625419915756280046002869097156693848522361803041977572204227262166","best_ask":"0.47","best_bid":"0.46","hash":"ae52a572197bd47b592a5bbea5bd2743bfc8bb17","price":"0.49","side":"SELL","size":"9.6"}],"timestamp":"1785122401994"},"payload_hash":"f2852bd3fa68b6098fad7abc716f6c31ea8ecf4bf52e11a47ab78c3b110d7a4b","raw_frame":"{\"market\":\"0x717c0e8ccd4d5c7040185188fbae28be901ca589a11a94b1b38ca36a79eccfeb\", \"price_changes\":[{\"asset_id\":\"41448400836309843603620980831210604935021861034693225347475867885462478926555\", \"price\":\"0.51\", \"size\":\"9.6\", \"side\":\"BUY\", \"hash\":\"f0ac867316197f7252b66c45dfc14e377e561754\", \"best_bid\":\"0.53\", \"best_ask\":\"0.54\"}, {\"asset_id\":\"24254094493625419915756280046002869097156693848522361803041977572204227262166\", \"price\":\"0.49\", \"size\":\"9.6\", \"side\":\"SELL\", \"hash\":\"ae52a572197bd47b592a5bbea5bd2743bfc8bb17\", \"best_bid\":\"0.46\", \"best_ask\":\"0.47\"}], \"timestamp\":\"1785122401994\", \"event_type\":\"price_change\"}","received_at":"2026-07-27T03:20:01.878622Z","schema_version":"clob-market-ws.price_change.v1","sequence":null,"server_hash":null,"server_timestamp":"1785122401994","session_id":"dd162b8dca5f43ff811d304e69a06123","source":"clob_market_ws"},"received_at":"2026-07-27T03:20:01.878622Z","record_id":"b806c4b0532c42920162a96e35d27870ce97bdc215ec3ece045ea9975045c61c","schema_fingerprint":"4aa3821a28b0b7c2400bc59aba4bcc0a76e971dadd19610d3ad38c768e124dc7","schema_version":"edge-lab-recorder.raw.v1","sequence":null,"source":"clob_market_ws"}
{"event_at":"2026-07-27T03:20:01.998000Z","event_fingerprint":"6355a965c36d7b5f2a3556e58a6b1bf3d62b795cc6f054ef8e8d500d235440bb","payload":{"connection_id":"c7dc2e4762f849c6b6f9306b6518dcab","event_at":"2026-07-27T03:20:01.998000Z","event_type":"price_change","frame_hash":"5a63fa7fc6727731e65cfeba5bc46ef5d53b86175042d67c53c50738ef6a8ef4","frame_index":0,"kind":"data","monotonic_ns":224385232942000,"payload":{"event_type":"price_change","market":"0x717c0e8ccd4d5c7040185188fbae28be901ca589a11a94b1b38ca36a79eccfeb","price_changes":[{"asset_id":"41448400836309843603620980831210604935021861034693225347475867885462478926555","best_ask":"0.54","best_bid":"0.53","hash":"6754c3ed6396e8e7364d4b6c8ca84b5d7f50de6b","price":"0.48","side":"BUY","size":"69.43"},{"asset_id":"24254094493625419915756280046002869097156693848522361803041977572204227262166","best_ask":"0.47","best_bid":"0.46","hash":"f095c6dea608eff77a0ba8f068dbeb4a8229e59f","price":"0.52","side":"SELL","size":"69.43"}],"timestamp":"1785122401998"},"payload_hash":"48bf399535b99108372594cada9cb59b7080ec3b5d3fd6b1d4f03a1dd547ae67","raw_frame":"{\"market\":\"0x717c0e8ccd4d5c7040185188fbae28be901ca589a11a94b1b38ca36a79eccfeb\", \"price_changes\":[{\"asset_id\":\"41448400836309843603620980831210604935021861034693225347475867885462478926555\", \"price\":\"0.48\", \"size\":\"69.43\", \"side\":\"BUY\", \"hash\":\"6754c3ed6396e8e7364d4b6c8ca84b5d7f50de6b\", \"best_bid\":\"0.53\", \"best_ask\":\"0.54\"}, {\"asset_id\":\"24254094493625419915756280046002869097156693848522361803041977572204227262166\", \"price\":\"0.52\", \"size\":\"69.43\", \"side\":\"SELL\", \"hash\":\"f095c6dea608eff77a0ba8f068dbeb4a8229e59f\", \"best_bid\":\"0.46\", \"best_ask\":\"0.47\"}], \"timestamp\":\"1785122401998\", \"event_type\":\"price_change\"}","received_at":"2026-07-27T03:20:01.881255Z","schema_version":"clob-market-ws.price_change.v1","sequence":null,"server_hash":null,"server_timestamp":"1785122401998","session_id":"dd162b8dca5f43ff811d304e69a06123","source":"clob_market_ws"},"received_at":"2026-07-27T03:20:01.881255Z","record_id":"c70dbbbc5d9fddbb6e19701401700500ef19d951ba465e719d3126594c55e34f","schema_fingerprint":"4aa3821a28b0b7c2400bc59aba4bcc0a76e971dadd19610d3ad38c768e124dc7","schema_version":"edge-lab-recorder.raw.v1","sequence":null,"source":"clob_market_ws"}
{"event_at":"2026-07-27T03:20:02.000000Z","event_fingerprint":"5ec5444f86384d9cc89aa6a6e9641d37d71f0fd7cf2cc9fade3dc61bdfe6eb21","payload":{"connection_id":"c7dc2e4762f849c6b6f9306b6518dcab","event_at":"2026-07-27T03:20:02.000000Z","event_type":"price_change","frame_hash":"03520843c57f1ddeebf02767fafa7e9c41fbe95dec8ea63371a93a0b9d3489e2","frame_index":0,"kind":"data","monotonic_ns":224385235485041,"payload":{"event_type":"price_change","market":"0x717c0e8ccd4d5c7040185188fbae28be901ca589a11a94b1b38ca36a79eccfeb","price_changes":[{"asset_id":"41448400836309843603620980831210604935021861034693225347475867885462478926555","best_ask":"0.54","best_bid":"0.53","hash":"e01135c2e9cf8a076aad0c3d62b88da1ce9a8fe7","price":"0.5","side":"BUY","size":"32.4"},{"asset_id":"24254094493625419915756280046002869097156693848522361803041977572204227262166","best_ask":"0.47","best_bid":"0.46","hash":"8a0115c1aaa72c581bd28ed2cde21ebf7ed18b9a","price":"0.5","side":"SELL","size":"32.4"}],"timestamp":"1785122402000"},"payload_hash":"6675447166a15a5dd3e608ebb3fb40b2c6f3c56cbebf9a7f190de0ed1e3c2309","raw_frame":"{\"market\":\"0x717c0e8ccd4d5c7040185188fbae28be901ca589a11a94b1b38ca36a79eccfeb\", \"price_changes\":[{\"asset_id\":\"41448400836309843603620980831210604935021861034693225347475867885462478926555\", \"price\":\"0.5\", \"size\":\"32.4\", \"side\":\"BUY\", \"hash\":\"e01135c2e9cf8a076aad0c3d62b88da1ce9a8fe7\", \"best_bid\":\"0.53\", \"best_ask\":\"0.54\"}, {\"asset_id\":\"24254094493625419915756280046002869097156693848522361803041977572204227262166\", \"price\":\"0.5\", \"size\":\"32.4\", \"side\":\"SELL\", \"hash\":\"8a0115c1aaa72c581bd28ed2cde21ebf7ed18b9a\", \"best_bid\":\"0.46\", \"best_ask\":\"0.47\"}], \"timestamp\":\"1785122402000\", \"event_type\":\"price_change\"}","received_at":"2026-07-27T03:20:01.883797Z","schema_version":"clob-market-ws.price_change.v1","sequence":null,"server_hash":null,"server_timestamp":"1785122402000","session_id":"dd162b8dca5f43ff811d304e69a06123","source":"clob_market_ws"},"received_at":"2026-07-27T03:20:01.883797Z","record_id":"a6a8f06c71b7d97448579d955aeea489035918ecd95d3648d391cb704bc107c0","schema_fingerprint":"4aa3821a28b0b7c2400bc59aba4bcc0a76e971dadd19610d3ad38c768e124dc7","schema_version":"edge-lab-recorder.raw.v1","sequence":null,"source":"clob_market_ws"}
{"event_at":"2026-07-27T03:20:02.001000Z","event_fingerprint":"428810decbf552467acc9661f58a71569f41fc1b61160703c681999f2dcee990","payload":{"connection_id":"c7dc2e4762f849c6b6f9306b6518dcab","event_at":"2026-07-27T03:20:02.001000Z","event_type":"price_change","frame_hash":"c8f811f5800bd93b2e853b41be63ecd764d4333b0f0dee8ba7ae399fe9ed9e65","frame_index":0,"kind":"data","monotonic_ns":224385237124291,"payload":{"event_type":"price_change","market":"0x717c0e8ccd4d5c7040185188fbae28be901ca589a11a94b1b38ca36a79eccfeb","price_changes":[{"asset_id":"41448400836309843603620980831210604935021861034693225347475867885462478926555","best_ask":"0.54","best_bid":"0.53","hash":"3157d8acfab72e177fa875b14e4064606c387221","price":"0.52","side":"BUY","size":"30.6"},{"asset_id":"24254094493625419915756280046002869097156693848522361803041977572204227262166","best_ask":"0.47","best_bid":"0.46","hash":"f6e8f6e5258fcffbc05b559e76f38aa30bf4ac0f","price":"0.48","side":"SELL","size":"30.6"}],"timestamp":"1785122402001"},"payload_hash":"fcf21636b67cdc788869601fa28df405079a0563fa4a98b50566a3dcdeaeb902","raw_frame":"{\"market\":\"0x717c0e8ccd4d5c7040185188fbae28be901ca589a11a94b1b38ca36a79eccfeb\", \"price_changes\":[{\"asset_id\":\"41448400836309843603620980831210604935021861034693225347475867885462478926555\", \"price\":\"0.52\", \"size\":\"30.6\", \"side\":\"BUY\", \"hash\":\"3157d8acfab72e177fa875b14e4064606c387221\", \"best_bid\":\"0.53\", \"best_ask\":\"0.54\"}, {\"asset_id\":\"24254094493625419915756280046002869097156693848522361803041977572204227262166\", \"price\":\"0.48\", \"size\":\"30.6\", \"side\":\"SELL\", \"hash\":\"f6e8f6e5258fcffbc05b559e76f38aa30bf4ac0f\", \"best_bid\":\"0.46\", \"best_ask\":\"0.47\"}], \"timestamp\":\"1785122402001\", \"event_type\":\"price_change\"}","received_at":"2026-07-27T03:20:01.885437Z","schema_version":"clob-market-ws.price_change.v1","sequence":null,"server_hash":null,"server_timestamp":"1785122402001","session_id":"dd162b8dca5f43ff811d304e69a06123","source":"clob_market_ws"},"received_at":"2026-07-27T03:20:01.885437Z","record_id":"fb481b0ace82c153f8630d2fef01cbdad7379af97e555d24c73e4d095739da2b","schema_fingerprint":"4aa3821a28b0b7c2400bc59aba4bcc0a76e971dadd19610d3ad38c768e124dc7","schema_version":"edge-lab-recorder.raw.v1","sequence":null,"source":"clob_market_ws"}
{"event_at":"2026-07-27T03:20:02.018000Z","event_fingerprint":"2bf289dbec1c9d64651c79afb9a7c01ae2947c3db122ac7245bb44f91b1b74a8","payload":{"connection_id":"c7dc2e4762f849c6b6f9306b6518dcab","event_at":"2026-07-27T03:20:02.018000Z","event_type":"price_change","frame_hash":"ddbb45bc6c3e1fb96d5c9c428c749666f1f7a81b76ec335656b62e46a15c3935","frame_index":0,"kind":"data","monotonic_ns":224385252970833,"payload":{"event_type":"price_change","market":"0x717c0e8ccd4d5c7040185188fbae28be901ca589a11a94b1b38ca36a79eccfeb","price_changes":[{"asset_id":"41448400836309843603620980831210604935021861034693225347475867885462478926555","best_ask":"0.54","best_bid":"0.53","hash":"6d80c6e4a8cbd327b8f4b7ce968ec0fe64a890ac","price":"0.02","side":"BUY","size":"688.1"},{"asset_id":"24254094493625419915756280046002869097156693848522361803041977572204227262166","best_ask":"0.47","best_bid":"0.46","hash":"f19c7cdd28ceb87535d5057f969c27466b7bade6","price":"0.98","side":"SELL","size":"688.1"}],"timestamp":"1785122402018"},"payload_hash":"a251e63da9f134d27354382a1676389832378bac120c9a164bfc85132072893a","raw_frame":"{\"market\":\"0x717c0e8ccd4d5c7040185188fbae28be901ca589a11a94b1b38ca36a79eccfeb\", \"price_changes\":[{\"asset_id\":\"41448400836309843603620980831210604935021861034693225347475867885462478926555\", \"price\":\"0.02\", \"size\":\"688.1\", \"side\":\"BUY\", \"hash\":\"6d80c6e4a8cbd327b8f4b7ce968ec0fe64a890ac\", \"best_bid\":\"0.53\", \"best_ask\":\"0.54\"}, {\"asset_id\":\"24254094493625419915756280046002869097156693848522361803041977572204227262166\", \"price\":\"0.98\", \"size\":\"688.1\", \"side\":\"SELL\", \"hash\":\"f19c7cdd28ceb87535d5057f969c27466b7bade6\", \"best_bid\":\"0.46\", \"best_ask\":\"0.47\"}], \"timestamp\":\"1785122402018\", \"event_type\":\"price_change\"}","received_at":"2026-07-27T03:20:01.901279Z","schema_version":"clob-market-ws.price_change.v1","sequence":null,"server_hash":null,"server_timestamp":"1785122402018","session_id":"dd162b8dca5f43ff811d304e69a06123","source":"clob_market_ws"},"received_at":"2026-07-27T03:20:01.901279Z","record_id":"1361e7384bed23c671bba172dc61e67ddac99ef43c0d10ee09413ccf25d831d4","schema_fingerprint":"4aa3821a28b0b7c2400bc59aba4bcc0a76e971dadd19610d3ad38c768e124dc7","schema_version":"edge-lab-recorder.raw.v1","sequence":null,"source":"clob_market_ws"}
{"event_at":"2026-07-27T03:20:02.051000Z","event_fingerprint":"72cfc56173a0de667533f143e2a392bc6c563849f83d85d49ada6215e9b0fc30","payload":{"connection_id":"c7dc2e4762f849c6b6f9306b6518dcab","event_at":"2026-07-27T03:20:02.051000Z","event_type":"price_change","frame_hash":"70461100d4cc6b63e1f68432323ff96e6dc12eb239712ad7d723ab7eb3c74814","frame_index":0,"kind":"data","monotonic_ns":224385285248416,"payload":{"event_type":"price_change","market":"0x717c0e8ccd4d5c7040185188fbae28be901ca589a11a94b1b38ca36a79eccfeb","price_changes":[{"asset_id":"41448400836309843603620980831210604935021861034693225347475867885462478926555","best_ask":"0.54","best_bid":"0.53","hash":"4da284d61ce86212052c69bb7c999f08cc042abe","price":"0.01","side":"BUY","size":"5708.02"},{"asset_id":"24254094493625419915756280046002869097156693848522361803041977572204227262166","best_ask":"0.47","best_bid":"0.46","hash":"07ca509386ae6db31789f5bed6b8fb26e1941da1","price":"0.99","side":"SELL","size":"5708.02"}],"timestamp":"1785122402051"},"payload_hash":"c3bfe77f2d52d270aa5ee4af3d085443ac2ebf4909d39e3d68682e15f50411ca","raw_frame":"{\"market\":\"0x717c0e8ccd4d5c7040185188fbae28be901ca589a11a94b1b38ca36a79eccfeb\", \"price_changes\":[{\"asset_id\":\"41448400836309843603620980831210604935021861034693225347475867885462478926555\", \"price\":\"0.01\", \"size\":\"5708.02\", \"side\":\"BUY\", \"hash\":\"4da284d61ce86212052c69bb7c999f08cc042abe\", \"best_bid\":\"0.53\", \"best_ask\":\"0.54\"}, {\"asset_id\":\"24254094493625419915756280046002869097156693848522361803041977572204227262166\", \"price\":\"0.99\", \"size\":\"5708.02\", \"side\":\"SELL\", \"hash\":\"07ca509386ae6db31789f5bed6b8fb26e1941da1\", \"best_bid\":\"0.46\", \"best_ask\":\"0.47\"}], \"timestamp\":\"1785122402051\", \"event_type\":\"price_change\"}","received_at":"2026-07-27T03:20:01.933549Z","schema_version":"clob-market-ws.price_change.v1","sequence":null,"server_hash":null,"server_timestamp":"1785122402051","session_id":"dd162b8dca5f43ff811d304e69a06123","source":"clob_market_ws"},"received_at":"2026-07-27T03:20:01.933549Z","record_id":"3e12d2637407c6957540be3a0b302a426b4bde28b40f1fbf37f047926a5eef8b","schema_fingerprint":"4aa3821a28b0b7c2400bc59aba4bcc0a76e971dadd19610d3ad38c768e124dc7","schema_version":"edge-lab-recorder.raw.v1","sequence":null,"source":"clob_market_ws"}
{"event_at":"2026-07-27T03:20:02.065000Z","event_fingerprint":"18c49078f1eebd2514180a035f1be96f5771dc03b2f583a1fa60ff09524543a7","payload":{"connection_id":"c7dc2e4762f849c6b6f9306b6518dcab","event_at":"2026-07-27T03:20:02.065000Z","event_type":"price_change","frame_hash":"34038cadc12f8c0b34bcb08d8a69a4c976fea9de7b7bb0cdbbf91a8c84df8844","frame_index":0,"kind":"data","monotonic_ns":224385300728083,"payload":{"event_type":"price_change","market":"0x717c0e8ccd4d5c7040185188fbae28be901ca589a11a94b1b38ca36a79eccfeb","price_changes":[{"asset_id":"41448400836309843603620980831210604935021861034693225347475867885462478926555","best_ask":"0.54","best_bid":"0.53","hash":"847e5a6d033802e439137ed7953408eb043c9bd2","price":"0.46","side":"BUY","size":"145.58"},{"asset_id":"24254094493625419915756280046002869097156693848522361803041977572204227262166","best_ask":"0.47","best_bid":"0.46","hash":"543b368a4a552c8f93ae1472658a14a588d1055e","price":"0.54","side":"SELL","size":"145.58"}],"timestamp":"1785122402065"},"payload_hash":"78b837c6129e52a9cb8aafb583e6c595cde7d4a20482f85fa1d6508821ca5e22","raw_frame":"{\"market\":\"0x717c0e8ccd4d5c7040185188fbae28be901ca589a11a94b1b38ca36a79eccfeb\", \"price_changes\":[{\"asset_id\":\"41448400836309843603620980831210604935021861034693225347475867885462478926555\", \"price\":\"0.46\", \"size\":\"145.58\", \"side\":\"BUY\", \"hash\":\"847e5a6d033802e439137ed7953408eb043c9bd2\", \"best_bid\":\"0.53\", \"best_ask\":\"0.54\"}, {\"asset_id\":\"24254094493625419915756280046002869097156693848522361803041977572204227262166\", \"price\":\"0.54\", \"size\":\"145.58\", \"side\":\"SELL\", \"hash\":\"543b368a4a552c8f93ae1472658a14a588d1055e\", \"best_bid\":\"0.46\", \"best_ask\":\"0.47\"}], \"timestamp\":\"1785122402065\", \"event_type\":\"price_change\"}","received_at":"2026-07-27T03:20:01.949034Z","schema_version":"clob-market-ws.price_change.v1","sequence":null,"server_hash":null,"server_timestamp":"1785122402065","session_id":"dd162b8dca5f43ff811d304e69a06123","source":"clob_market_ws"},"received_at":"2026-07-27T03:20:01.949034Z","record_id":"5cf07d542df3de3348c8e3e04afc80ce395116d5c3ef6e4b4be65561acf9187b","schema_fingerprint":"4aa3821a28b0b7c2400bc59aba4bcc0a76e971dadd19610d3ad38c768e124dc7","schema_version":"edge-lab-recorder.raw.v1","sequence":null,"source":"clob_market_ws"}
{"event_at":"2026-07-27T03:20:02.074000Z","event_fingerprint":"75d5ff0c8b3f205acc4fdd1ae700467318a9e0242117de49c5b9225f8b07bb66","payload":{"connection_id":"c7dc2e4762f849c6b6f9306b6518dcab","event_at":"2026-07-27T03:20:02.074000Z","event_type":"price_change","frame_hash":"03bdb483e30d8186a722708094768e1c58ebd4f7bd502fccc50c78aebf251625","frame_index":0,"kind":"data","monotonic_ns":224385307857541,"payload":{"event_type":"price_change","market":"0x717c0e8ccd4d5c7040185188fbae28be901ca589a11a94b1b38ca36a79eccfeb","price_changes":[{"asset_id":"41448400836309843603620980831210604935021861034693225347475867885462478926555","best_ask":"0.54","best_bid":"0.53","hash":"5532055347d8c2bdaea60c019cb6d525cc774d2c","price":"0.01","side":"BUY","size":"5703.02"},{"asset_id":"24254094493625419915756280046002869097156693848522361803041977572204227262166","best_ask":"0.47","best_bid":"0.46","hash":"e5db8557d6efd0d8271d0be5a31d367472bb9176","price":"0.99","side":"SELL","size":"5703.02"}],"timestamp":"1785122402074"},"payload_hash":"f5022055f6a2a9f8fe72c83a5fd4e290dee8c4c5df1c5324f099064d170b11b7","raw_frame":"{\"market\":\"0x717c0e8ccd4d5c7040185188fbae28be901ca589a11a94b1b38ca36a79eccfeb\", \"price_changes\":[{\"asset_id\":\"41448400836309843603620980831210604935021861034693225347475867885462478926555\", \"price\":\"0.01\", \"size\":\"5703.02\", \"side\":\"BUY\", \"hash\":\"5532055347d8c2bdaea60c019cb6d525cc774d2c\", \"best_bid\":\"0.53\", \"best_ask\":\"0.54\"}, {\"asset_id\":\"24254094493625419915756280046002869097156693848522361803041977572204227262166\", \"price\":\"0.99\", \"size\":\"5703.02\", \"side\":\"SELL\", \"hash\":\"e5db8557d6efd0d8271d0be5a31d367472bb9176\", \"best_bid\":\"0.46\", \"best_ask\":\"0.47\"}], \"timestamp\":\"1785122402074\", \"event_type\":\"price_change\"}","received_at":"2026-07-27T03:20:01.956153Z","schema_version":"clob-market-ws.price_change.v1","sequence":null,"server_hash":null,"server_timestamp":"1785122402074","session_id":"dd162b8dca5f43ff811d304e69a06123","source":"clob_market_ws"},"received_at":"2026-07-27T03:20:01.956153Z","record_id":"9bcfa62845c1d2ae29874a4f92f58fca725549ac8dbac8601f116c32e026cc81","schema_fingerprint":"4aa3821a28b0b7c2400bc59aba4bcc0a76e971dadd19610d3ad38c768e124dc7","schema_version":"edge-lab-recorder.raw.v1","sequence":null,"source":"clob_market_ws"}
{"event_at":"2026-07-27T03:20:02.077000Z","event_fingerprint":"a42be888bf4b45a2a0b609a00247ae5044069ce3a379aa77b9b626e592a77f29","payload":{"connection_id":"c7dc2e4762f849c6b6f9306b6518dcab","event_at":"2026-07-27T03:20:02.077000Z","event_type":"price_change","frame_hash":"8112791fc8f3c2bd9faa3685acd9c47517f4e49f2a439a7c9288c0fdd7aae3de","frame_index":0,"kind":"data","monotonic_ns":224385310575750,"payload":{"event_type":"price_change","market":"0x717c0e8ccd4d5c7040185188fbae28be901ca589a11a94b1b38ca36a79eccfeb","price_changes":[{"asset_id":"41448400836309843603620980831210604935021861034693225347475867885462478926555","best_ask":"0.54","best_bid":"0.53","hash":"6efb4520172debb54b6f489ad71c691417692269","price":"0.02","side":"BUY","size":"683.1"},{"asset_id":"24254094493625419915756280046002869097156693848522361803041977572204227262166","best_ask":"0.47","best_bid":"0.46","hash":"669617270d063cec452e4440ef053d03e45eb4da","price":"0.98","side":"SELL","size":"683.1"}],"timestamp":"1785122402077"},"payload_hash":"38c9b65151e4306155fb7825136cdbd1b996db3438400e2d1fc732aa9aa36a76","raw_frame":"{\"market\":\"0x717c0e8ccd4d5c7040185188fbae28be901ca589a11a94b1b38ca36a79eccfeb\", \"price_changes\":[{\"asset_id\":\"41448400836309843603620980831210604935021861034693225347475867885462478926555\", \"price\":\"0.02\", \"size\":\"683.1\", \"side\":\"BUY\", \"hash\":\"6efb4520172debb54b6f489ad71c691417692269\", \"best_bid\":\"0.53\", \"best_ask\":\"0.54\"}, {\"asset_id\":\"24254094493625419915756280046002869097156693848522361803041977572204227262166\", \"price\":\"0.98\", \"size\":\"683.1\", \"side\":\"SELL\", \"hash\":\"669617270d063cec452e4440ef053d03e45eb4da\", \"best_bid\":\"0.46\", \"best_ask\":\"0.47\"}], \"timestamp\":\"1785122402077\", \"event_type\":\"price_change\"}","received_at":"2026-07-27T03:20:01.958880Z","schema_version":"clob-market-ws.price_change.v1","sequence":null,"server_hash":null,"server_timestamp":"1785122402077","session_id":"dd162b8dca5f43ff811d304e69a06123","source":"clob_market_ws"},"received_at":"2026-07-27T03:20:01.958880Z","record_id":"33ac579ac5ea01e7a88185be2d71c71ba5b1698505ab62656f2207e681181257","schema_fingerprint":"4aa3821a28b0b7c2400bc59aba4bcc0a76e971dadd19610d3ad38c768e124dc7","schema_version":"edge-lab-recorder.raw.v1","sequence":null,"source":"clob_market_ws"}
{"event_at":"2026-07-27T03:20:02.141000Z","event_fingerprint":"d2c650428bd3c05a910110fb57e232cd5e12f3c3adbf1d87a9e1df3984bf71a5","payload":{"connection_id":"c7dc2e4762f849c6b6f9306b6518dcab","event_at":"2026-07-27T03:20:02.141000Z","event_type":"price_change","frame_hash":"a619d93b4137149c1cbd11d9b9025571723adfbe0e01e13325269e3bf5e414c2","frame_index":0,"kind":"data","monotonic_ns":224385375783125,"payload":{"event_type":"price_change","market":"0x717c0e8ccd4d5c7040185188fbae28be901ca589a11a94b1b38ca36a79eccfeb","price_changes":[{"asset_id":"41448400836309843603620980831210604935021861034693225347475867885462478926555","best_ask":"0.54","best_bid":"0.53","hash":"789f267231d98dc2f2fda5a1338853046e099eb5","price":"0.52","side":"BUY","size":"9.6"},{"asset_id":"24254094493625419915756280046002869097156693848522361803041977572204227262166","best_ask":"0.47","best_bid":"0.46","hash":"5c287473748330fabedef03bb02906aec1215068","price":"0.48","side":"SELL","size":"9.6"}],"timestamp":"1785122402141"},"payload_hash":"8895f00177c5b2246d262fe7e0f4cbfaab4229bffed7ad8430e56afcec5e8c80","raw_frame":"{\"market\":\"0x717c0e8ccd4d5c7040185188fbae28be901ca589a11a94b1b38ca36a79eccfeb\", \"price_changes\":[{\"asset_id\":\"41448400836309843603620980831210604935021861034693225347475867885462478926555\", \"price\":\"0.52\", \"size\":\"9.6\", \"side\":\"BUY\", \"hash\":\"789f267231d98dc2f2fda5a1338853046e099eb5\", \"best_bid\":\"0.53\", \"best_ask\":\"0.54\"}, {\"asset_id\":\"24254094493625419915756280046002869097156693848522361803041977572204227262166\", \"price\":\"0.48\", \"size\":\"9.6\", \"side\":\"SELL\", \"hash\":\"5c287473748330fabedef03bb02906aec1215068\", \"best_bid\":\"0.46\", \"best_ask\":\"0.47\"}], \"timestamp\":\"1785122402141\", \"event_type\":\"price_change\"}","received_at":"2026-07-27T03:20:02.024074Z","schema_version":"clob-market-ws.price_change.v1","sequence":null,"server_hash":null,"server_timestamp":"1785122402141","session_id":"dd162b8dca5f43ff811d304e69a06123","source":"clob_market_ws"},"received_at":"2026-07-27T03:20:02.024074Z","record_id":"0b8345c48aff0e92fb617fa000d22d027e79035331c15909ba0b8a3c6d7c2f5d","schema_fingerprint":"4aa3821a28b0b7c2400bc59aba4bcc0a76e971dadd19610d3ad38c768e124dc7","schema_version":"edge-lab-recorder.raw.v1","sequence":null,"source":"clob_market_ws"}
{"event_at":"2026-07-27T03:20:02.141000Z","event_fingerprint":"3d96c69f15ddac75a86eaa9bb5b6b6df919bf6d5f12d48cb5c6d8de9b592101b","payload":{"connection_id":"c7dc2e4762f849c6b6f9306b6518dcab","event_at":"2026-07-27T03:20:02.141000Z","event_type":"price_change","frame_hash":"44b3879c76717af21f15442633fd6b892911046fe7e5427ea2d8d078554a23da","frame_index":0,"kind":"data","monotonic_ns":224385378648125,"payload":{"event_type":"price_change","market":"0x717c0e8ccd4d5c7040185188fbae28be901ca589a11a94b1b38ca36a79eccfeb","price_changes":[{"asset_id":"41448400836309843603620980831210604935021861034693225347475867885462478926555","best_ask":"0.54","best_bid":"0.53","hash":"789f267231d98dc2f2fda5a1338853046e099eb5","price":"0.46","side":"BUY","size":"139.58"},{"asset_id":"24254094493625419915756280046002869097156693848522361803041977572204227262166","best_ask":"0.47","best_bid":"0.46","hash":"5c287473748330fabedef03bb02906aec1215068","price":"0.54","side":"SELL","size":"139.58"}],"timestamp":"1785122402141"},"payload_hash":"f0553f5278a24f67ed622cd6fbe4fbce33a761e15db49218367dec994a07e5e4","raw_frame":"{\"market\":\"0x717c0e8ccd4d5c7040185188fbae28be901ca589a11a94b1b38ca36a79eccfeb\", \"price_changes\":[{\"asset_id\":\"41448400836309843603620980831210604935021861034693225347475867885462478926555\", \"price\":\"0.46\", \"size\":\"139.58\", \"side\":\"BUY\", \"hash\":\"789f267231d98dc2f2fda5a1338853046e099eb5\", \"best_bid\":\"0.53\", \"best_ask\":\"0.54\"}, {\"asset_id\":\"24254094493625419915756280046002869097156693848522361803041977572204227262166\", \"price\":\"0.54\", \"size\":\"139.58\", \"side\":\"SELL\", \"hash\":\"5c287473748330fabedef03bb02906aec1215068\", \"best_bid\":\"0.46\", \"best_ask\":\"0.47\"}], \"timestamp\":\"1785122402141\", \"event_type\":\"price_change\"}","received_at":"2026-07-27T03:20:02.026932Z","schema_version":"clob-market-ws.price_change.v1","sequence":null,"server_hash":null,"server_timestamp":"1785122402141","session_id":"dd162b8dca5f43ff811d304e69a06123","source":"clob_market_ws"},"received_at":"2026-07-27T03:20:02.026932Z","record_id":"524835bf270026a6993a5d43401281ffbca299183057d6c185f2abd70cd5eab6","schema_fingerprint":"4aa3821a28b0b7c2400bc59aba4bcc0a76e971dadd19610d3ad38c768e124dc7","schema_version":"edge-lab-recorder.raw.v1","sequence":null,"source":"clob_market_ws"}
{"event_at":"2026-07-27T03:20:02.141000Z","event_fingerprint":"0420f84c34eee7f3b950b671fbb98ed4613639f29259276cee2d8f858342b5f2","payload":{"connection_id":"c7dc2e4762f849c6b6f9306b6518dcab","event_at":"2026-07-27T03:20:02.141000Z","event_type":"price_change","frame_hash":"9f61d664e8286cb97fdf14c5b1f8151923ed2da6d0d8a36292bc8a8adc420b2a","frame_index":0,"kind":"data","monotonic_ns":224385380376333,"payload":{"event_type":"price_change","market":"0x717c0e8ccd4d5c7040185188fbae28be901ca589a11a94b1b38ca36a79eccfeb","price_changes":[{"asset_id":"41448400836309843603620980831210604935021861034693225347475867885462478926555","best_ask":"0.54","best_bid":"0.53","hash":"789f267231d98dc2f2fda5a1338853046e099eb5","price":"0.48","side":"BUY","size":"63.43"},{"asset_id":"24254094493625419915756280046002869097156693848522361803041977572204227262166","best_ask":"0.47","best_bid":"0.46","hash":"5c287473748330fabedef03bb02906aec1215068","price":"0.52","side":"SELL","size":"63.43"}],"timestamp":"1785122402141"},"payload_hash":"8922f57ebd01ab2a059aeb363fbbce139d3f7c5880cd618b9f550ce2123897ab","raw_frame":"{\"market\":\"0x717c0e8ccd4d5c7040185188fbae28be901ca589a11a94b1b38ca36a79eccfeb\", \"price_changes\":[{\"asset_id\":\"41448400836309843603620980831210604935021861034693225347475867885462478926555\", \"price\":\"0.48\", \"size\":\"63.43\", \"side\":\"BUY\", \"hash\":\"789f267231d98dc2f2fda5a1338853046e099eb5\", \"best_bid\":\"0.53\", \"best_ask\":\"0.54\"}, {\"asset_id\":\"24254094493625419915756280046002869097156693848522361803041977572204227262166\", \"price\":\"0.52\", \"size\":\"63.43\", \"side\":\"SELL\", \"hash\":\"5c287473748330fabedef03bb02906aec1215068\", \"best_bid\":\"0.46\", \"best_ask\":\"0.47\"}], \"timestamp\":\"1785122402141\", \"event_type\":\"price_change\"}","received_at":"2026-07-27T03:20:02.028665Z","schema_version":"clob-market-ws.price_change.v1","sequence":null,"server_hash":null,"server_timestamp":"1785122402141","session_id":"dd162b8dca5f43ff811d304e69a06123","source":"clob_market_ws"},"received_at":"2026-07-27T03:20:02.028665Z","record_id":"543d452fe3260f053b80f8ea4b79a4d543d19210bb89c89d616b16179d766541","schema_fingerprint":"4aa3821a28b0b7c2400bc59aba4bcc0a76e971dadd19610d3ad38c768e124dc7","schema_version":"edge-lab-recorder.raw.v1","sequence":null,"source":"clob_market_ws"}
{"event_at":"2026-07-27T03:20:02.141000Z","event_fingerprint":"49db575410d18075bd00a1613ae9c0051247dcd000b9e5136345bf02c8c0b8dd","payload":{"connection_id":"c7dc2e4762f849c6b6f9306b6518dcab","event_at":"2026-07-27T03:20:02.141000Z","event_type":"price_change","frame_hash":"3677a0081730d33269dad0941895e5d5ab4c67735ae0cc7dce1077da25d3ea7a","frame_index":0,"kind":"data","monotonic_ns":224385381969458,"payload":{"event_type":"price_change","market":"0x717c0e8ccd4d5c7040185188fbae28be901ca589a11a94b1b38ca36a79eccfeb","price_changes":[{"asset_id":"24254094493625419915756280046002869097156693848522361803041977572204227262166","best_ask":"0.47","best_bid":"0.46","hash":"5c287473748330fabedef03bb02906aec1215068","price":"0.34","side":"BUY","size":"119.4"},{"asset_id":"41448400836309843603620980831210604935021861034693225347475867885462478926555","best_ask":"0.54","best_bid":"0.53","hash":"789f267231d98dc2f2fda5a1338853046e099eb5","price":"0.66","side":"SELL","size":"119.4"}],"timestamp":"1785122402141"},"payload_hash":"7efb152af78d5ad129a8c2cbcde5946d877604e630c4fb4ce1eefec9134b4556","raw_frame":"{\"market\":\"0x717c0e8ccd4d5c7040185188fbae28be901ca589a11a94b1b38ca36a79eccfeb\", \"price_changes\":[{\"asset_id\":\"24254094493625419915756280046002869097156693848522361803041977572204227262166\", \"price\":\"0.34\", \"size\":\"119.4\", \"side\":\"BUY\", \"hash\":\"5c287473748330fabedef03bb02906aec1215068\", \"best_bid\":\"0.46\", \"best_ask\":\"0.47\"}, {\"asset_id\":\"41448400836309843603620980831210604935021861034693225347475867885462478926555\", \"price\":\"0.66\", \"size\":\"119.4\", \"side\":\"SELL\", \"hash\":\"789f267231d98dc2f2fda5a1338853046e099eb5\", \"best_bid\":\"0.53\", \"best_ask\":\"0.54\"}], \"timestamp\":\"1785122402141\", \"event_type\":\"price_change\"}","received_at":"2026-07-27T03:20:02.030260Z","schema_version":"clob-market-ws.price_change.v1","sequence":null,"server_hash":null,"server_timestamp":"1785122402141","session_id":"dd162b8dca5f43ff811d304e69a06123","source":"clob_market_ws"},"received_at":"2026-07-27T03:20:02.030260Z","record_id":"cdc7e9be0715be62aaafd234ab0a58fc69f44595111f13f8550ebbe09002f439","schema_fingerprint":"4aa3821a28b0b7c2400bc59aba4bcc0a76e971dadd19610d3ad38c768e124dc7","schema_version":"edge-lab-recorder.raw.v1","sequence":null,"source":"clob_market_ws"}
{"event_at":"2026-07-27T03:20:02.141000Z","event_fingerprint":"65a6f30e93d7d602828f06231feff60f280305ed4046eaddd704eb32ce2f8bb5","payload":{"connection_id":"c7dc2e4762f849c6b6f9306b6518dcab","event_at":"2026-07-27T03:20:02.141000Z","event_type":"price_change","frame_hash":"b3901f4d602e68c4048d88d2dbd5712f8fc10ac23c7e9d4226802c0378a95b19","frame_index":0,"kind":"data","monotonic_ns":224385385003541,"payload":{"event_type":"price_change","market":"0x717c0e8ccd4d5c7040185188fbae28be901ca589a11a94b1b38ca36a79eccfeb","price_changes":[{"asset_id":"24254094493625419915756280046002869097156693848522361803041977572204227262166","best_ask":"0.47","best_bid":"0.46","hash":"5c287473748330fabedef03bb02906aec1215068","price":"0.36","side":"BUY","size":"137"},{"asset_id":"41448400836309843603620980831210604935021861034693225347475867885462478926555","best_ask":"0.54","best_bid":"0.53","hash":"789f267231d98dc2f2fda5a1338853046e099eb5","price":"0.64","side":"SELL","size":"137"}],"timestamp":"1785122402141"},"payload_hash":"9f08989a5fa694e8034519963e42444a8fea880b1e2387398e13ac0ce3f23048","raw_frame":"{\"market\":\"0x717c0e8ccd4d5c7040185188fbae28be901ca589a11a94b1b38ca36a79eccfeb\", \"price_changes\":[{\"asset_id\":\"24254094493625419915756280046002869097156693848522361803041977572204227262166\", \"price\":\"0.36\", \"size\":\"137\", \"side\":\"BUY\", \"hash\":\"5c287473748330fabedef03bb02906aec1215068\", \"best_bid\":\"0.46\", \"best_ask\":\"0.47\"}, {\"asset_id\":\"41448400836309843603620980831210604935021861034693225347475867885462478926555\", \"price\":\"0.64\", \"size\":\"137\", \"side\":\"SELL\", \"hash\":\"789f267231d98dc2f2fda5a1338853046e099eb5\", \"best_bid\":\"0.53\", \"best_ask\":\"0.54\"}], \"timestamp\":\"1785122402141\", \"event_type\":\"price_change\"}","received_at":"2026-07-27T03:20:02.033294Z","schema_version":"clob-market-ws.price_change.v1","sequence":null,"server_hash":null,"server_timestamp":"1785122402141","session_id":"dd162b8dca5f43ff811d304e69a06123","source":"clob_market_ws"},"received_at":"2026-07-27T03:20:02.033294Z","record_id":"0570207a8108ed45788e05067e58ea9f3e3f94bfc6b640c6744bafb3636212dc","schema_fingerprint":"4aa3821a28b0b7c2400bc59aba4bcc0a76e971dadd19610d3ad38c768e124dc7","schema_version":"edge-lab-recorder.raw.v1","sequence":null,"source":"clob_market_ws"}
{"event_at":"2026-07-27T03:20:02.141000Z","event_fingerprint":"014317bfbec03cfe482c6feba9535b8eabcba9bd19ef9ec6b7347f68f95c58dc","payload":{"connection_id":"c7dc2e4762f849c6b6f9306b6518dcab","event_at":"2026-07-27T03:20:02.141000Z","event_type":"price_change","frame_hash":"5f6e4b3f3b8e49e0f5c42459543bf8fafb1c10f2294be9d3b9a62dff2cf228f4","frame_index":0,"kind":"data","monotonic_ns":224385386702791,"payload":{"event_type":"price_change","market":"0x717c0e8ccd4d5c7040185188fbae28be901ca589a11a94b1b38ca36a79eccfeb","price_changes":[{"asset_id":"41448400836309843603620980831210604935021861034693225347475867885462478926555","best_ask":"0.54","best_bid":"0.53","hash":"789f267231d98dc2f2fda5a1338853046e099eb5","price":"0.47","side":"BUY","size":"28.05"},{"asset_id":"24254094493625419915756280046002869097156693848522361803041977572204227262166","best_ask":"0.47","best_bid":"0.46","hash":"5c287473748330fabedef03bb02906aec1215068","price":"0.53","side":"SELL","size":"28.05"}],"timestamp":"1785122402141"},"payload_hash":"cce63675010f5357db69c9f9387dc49a690f9964992b9e1857fdbcaf0f500836","raw_frame":"{\"market\":\"0x717c0e8ccd4d5c7040185188fbae28be901ca589a11a94b1b38ca36a79eccfeb\", \"price_changes\":[{\"asset_id\":\"41448400836309843603620980831210604935021861034693225347475867885462478926555\", \"price\":\"0.47\", \"size\":\"28.05\", \"side\":\"BUY\", \"hash\":\"789f267231d98dc2f2fda5a1338853046e099eb5\", \"best_bid\":\"0.53\", \"best_ask\":\"0.54\"}, {\"asset_id\":\"24254094493625419915756280046002869097156693848522361803041977572204227262166\", \"price\":\"0.53\", \"size\":\"28.05\", \"side\":\"SELL\", \"hash\":\"5c287473748330fabedef03bb02906aec1215068\", \"best_bid\":\"0.46\", \"best_ask\":\"0.47\"}], \"timestamp\":\"1785122402141\", \"event_type\":\"price_change\"}","received_at":"2026-07-27T03:20:02.034992Z","schema_version":"clob-market-ws.price_change.v1","sequence":null,"server_hash":null,"server_timestamp":"1785122402141","session_id":"dd162b8dca5f43ff811d304e69a06123","source":"clob_market_ws"},"received_at":"2026-07-27T03:20:02.034992Z","record_id":"9dc988783d710dc8ef1d7d31c7fbfa89576f4ce7cd0dbfbcc1acb34578c6b2da","schema_fingerprint":"4aa3821a28b0b7c2400bc59aba4bcc0a76e971dadd19610d3ad38c768e124dc7","schema_version":"edge-lab-recorder.raw.v1","sequence":null,"source":"clob_market_ws"}
{"event_at":"2026-07-27T03:20:02.141000Z","event_fingerprint":"7d21afbe6a4a9b896115b7132f22c4f3c67ae3755f475575bc7fc4ae7f5d8d9f","payload":{"connection_id":"c7dc2e4762f849c6b6f9306b6518dcab","event_at":"2026-07-27T03:20:02.141000Z","event_type":"price_change","frame_hash":"d28e9869688559332da480ebd16d718ea336fd97a0a68a13c0eb5913a5257a81","frame_index":0,"kind":"data","monotonic_ns":224385388301083,"payload":{"event_type":"price_change","market":"0x717c0e8ccd4d5c7040185188fbae28be901ca589a11a94b1b38ca36a79eccfeb","price_changes":[{"asset_id":"41448400836309843603620980831210604935021861034693225347475867885462478926555","best_ask":"0.54","best_bid":"0.53","hash":"789f267231d98dc2f2fda5a1338853046e099eb5","price":"0.5","side":"BUY","size":"26.4"},{"asset_id":"24254094493625419915756280046002869097156693848522361803041977572204227262166","best_ask":"0.47","best_bid":"0.46","hash":"5c287473748330fabedef03bb02906aec1215068","price":"0.5","side":"SELL","size":"26.4"}],"timestamp":"1785122402141"},"payload_hash":"54b73de7b53a5419297ee02fca886197d1f897e75eadcf6e589bb0ee736e2589","raw_frame":"{\"market\":\"0x717c0e8ccd4d5c7040185188fbae28be901ca589a11a94b1b38ca36a79eccfeb\", \"price_changes\":[{\"asset_id\":\"41448400836309843603620980831210604935021861034693225347475867885462478926555\", \"price\":\"0.5\", \"size\":\"26.4\", \"side\":\"BUY\", \"hash\":\"789f267231d98dc2f2fda5a1338853046e099eb5\", \"best_bid\":\"0.53\", \"best_ask\":\"0.54\"}, {\"asset_id\":\"24254094493625419915756280046002869097156693848522361803041977572204227262166\", \"price\":\"0.5\", \"size\":\"26.4\", \"side\":\"SELL\", \"hash\":\"5c287473748330fabedef03bb02906aec1215068\", \"best_bid\":\"0.46\", \"best_ask\":\"0.47\"}], \"timestamp\":\"1785122402141\", \"event_type\":\"price_change\"}","received_at":"2026-07-27T03:20:02.036590Z","schema_version":"clob-market-ws.price_change.v1","sequence":null,"server_hash":null,"server_timestamp":"1785122402141","session_id":"dd162b8dca5f43ff811d304e69a06123","source":"clob_market_ws"},"received_at":"2026-07-27T03:20:02.036590Z","record_id":"4683b55a1d4481832e5a2b7e32f695140bfb2fdde421f6b4ee8b4c79a5070b45","schema_fingerprint":"4aa3821a28b0b7c2400bc59aba4bcc0a76e971dadd19610d3ad38c768e124dc7","schema_version":"edge-lab-recorder.raw.v1","sequence":null,"source":"clob_market_ws"}
{"event_at":"2026-07-27T03:20:02.141000Z","event_fingerprint":"10c194f7a5afecd0239d7c64d65bb28de68823c3d85505354164d10f80f28f69","payload":{"connection_id":"c7dc2e4762f849c6b6f9306b6518dcab","event_at":"2026-07-27T03:20:02.141000Z","event_type":"price_change","frame_hash":"895f44347e00c86c76c8b4a31679def17b3845cd0e58e912ef4604db290db9e9","frame_index":0,"kind":"data","monotonic_ns":224385389818208,"payload":{"event_type":"price_change","market":"0x717c0e8ccd4d5c7040185188fbae28be901ca589a11a94b1b38ca36a79eccfeb","price_changes":[{"asset_id":"24254094493625419915756280046002869097156693848522361803041977572204227262166","best_ask":"0.47","best_bid":"0.46","hash":"5c287473748330fabedef03bb02906aec1215068","price":"0.32","side":"BUY","size":"332.28"},{"asset_id":"41448400836309843603620980831210604935021861034693225347475867885462478926555","best_ask":"0.54","best_bid":"0.53","hash":"789f267231d98dc2f2fda5a1338853046e099eb5","price":"0.68","side":"SELL","size":"332.28"}],"timestamp":"1785122402141"},"payload_hash":"2bf18f6d6a09656dc90f40a78a96ad8c1dd2a81c13808f3d6e07aa6e93b65777","raw_frame":"{\"market\":\"0x717c0e8ccd4d5c7040185188fbae28be901ca589a11a94b1b38ca36a79eccfeb\", \"price_changes\":[{\"asset_id\":\"24254094493625419915756280046002869097156693848522361803041977572204227262166\", \"price\":\"0.32\", \"size\":\"332.28\", \"side\":\"BUY\", \"hash\":\"5c287473748330fabedef03bb02906aec1215068\", \"best_bid\":\"0.46\", \"best_ask\":\"0.47\"}, {\"asset_id\":\"41448400836309843603620980831210604935021861034693225347475867885462478926555\", \"price\":\"0.68\", \"size\":\"332.28\", \"side\":\"SELL\", \"hash\":\"789f267231d98dc2f2fda5a1338853046e099eb5\", \"best_bid\":\"0.53\", \"best_ask\":\"0.54\"}], \"timestamp\":\"1785122402141\", \"event_type\":\"price_change\"}","received_at":"2026-07-27T03:20:02.038108Z","schema_version":"clob-market-ws.price_change.v1","sequence":null,"server_hash":null,"server_timestamp":"1785122402141","session_id":"dd162b8dca5f43ff811d304e69a06123","source":"clob_market_ws"},"received_at":"2026-07-27T03:20:02.038108Z","record_id":"3b7a0112b11802c1754d8bf901e6872bd203a1aeb0e101b38b5c6dc9300f96eb","schema_fingerprint":"4aa3821a28b0b7c2400bc59aba4bcc0a76e971dadd19610d3ad38c768e124dc7","schema_version":"edge-lab-recorder.raw.v1","sequence":null,"source":"clob_market_ws"}
{"event_at":"2026-07-27T03:20:02.168000Z","event_fingerprint":"b915966753dc4637d97908a83e6a32b113a5bda3a83171ebae07eab59ef82784","payload":{"connection_id":"c7dc2e4762f849c6b6f9306b6518dcab","event_at":"2026-07-27T03:20:02.168000Z","event_type":"price_change","frame_hash":"a4af44eae14b5f4e914e0bfa575d1436cedb90d4e21c9d8b88b2d35317ba003a","frame_index":0,"kind":"data","monotonic_ns":224385404654500,"payload":{"event_type":"price_change","market":"0x717c0e8ccd4d5c7040185188fbae28be901ca589a11a94b1b38ca36a79eccfeb","price_changes":[{"asset_id":"41448400836309843603620980831210604935021861034693225347475867885462478926555","best_ask":"0.54","best_bid":"0.53","hash":"297e1c9640e2940c1b29645c4f943f1082feb1b4","price":"0.02","side":"BUY","size":"688.1"},{"asset_id":"24254094493625419915756280046002869097156693848522361803041977572204227262166","best_ask":"0.47","best_bid":"0.46","hash":"c1c1be17356c539f320262172c687777b3ca1d83","price":"0.98","side":"SELL","size":"688.1"}],"timestamp":"1785122402168"},"payload_hash":"efbd567b56547be9b10a84f53f406dd4c10cb8dd264213dd42acd02eaf844011","raw_frame":"{\"market\":\"0x717c0e8ccd4d5c7040185188fbae28be901ca589a11a94b1b38ca36a79eccfeb\", \"price_changes\":[{\"asset_id\":\"41448400836309843603620980831210604935021861034693225347475867885462478926555\", \"price\":\"0.02\", \"size\":\"688.1\", \"side\":\"BUY\", \"hash\":\"297e1c9640e2940c1b29645c4f943f1082feb1b4\", \"best_bid\":\"0.53\", \"best_ask\":\"0.54\"}, {\"asset_id\":\"24254094493625419915756280046002869097156693848522361803041977572204227262166\", \"price\":\"0.98\", \"size\":\"688.1\", \"side\":\"SELL\", \"hash\":\"c1c1be17356c539f320262172c687777b3ca1d83\", \"best_bid\":\"0.46\", \"best_ask\":\"0.47\"}], \"timestamp\":\"1785122402168\", \"event_type\":\"price_change\"}","received_at":"2026-07-27T03:20:02.052940Z","schema_version":"clob-market-ws.price_change.v1","sequence":null,"server_hash":null,"server_timestamp":"1785122402168","session_id":"dd162b8dca5f43ff811d304e69a06123","source":"clob_market_ws"},"received_at":"2026-07-27T03:20:02.052940Z","record_id":"21018d02eb6166807669068ff47bb62217ca1eb2a5798726053b63818910555a","schema_fingerprint":"4aa3821a28b0b7c2400bc59aba4bcc0a76e971dadd19610d3ad38c768e124dc7","schema_version":"edge-lab-recorder.raw.v1","sequence":null,"source":"clob_market_ws"}
{"event_at":"2026-07-27T03:20:02.192000Z","event_fingerprint":"46764bc01854c47263c37c88c0fc3994cb08d7aa7eedb8fd93ad2334ef0d685b","payload":{"connection_id":"c7dc2e4762f849c6b6f9306b6518dcab","event_at":"2026-07-27T03:20:02.192000Z","event_type":"best_bid_ask","frame_hash":"1c6888dd41c820b9e96140f4e1d97c6f9e8363b27114d4797593fff12e1b4671","frame_index":0,"kind":"data","monotonic_ns":224385426207416,"payload":{"asset_id":"24254094493625419915756280046002869097156693848522361803041977572204227262166","best_ask":"0.47","best_bid":"0.46","event_type":"best_bid_ask","market":"0x717c0e8ccd4d5c7040185188fbae28be901ca589a11a94b1b38ca36a79eccfeb","spread":"0.01","timestamp":"1785122402192"},"payload_hash":"fc98ef3b35baf5f1e9d6e4a1a63e62d3f6fccce0304b7fb5c49fa48673bdb535","raw_frame":"{\"market\":\"0x717c0e8ccd4d5c7040185188fbae28be901ca589a11a94b1b38ca36a79eccfeb\", \"asset_id\":\"24254094493625419915756280046002869097156693848522361803041977572204227262166\", \"best_bid\":\"0.46\", \"best_ask\":\"0.47\", \"spread\":\"0.01\", \"timestamp\":\"1785122402192\", \"event_type\":\"best_bid_ask\"}","received_at":"2026-07-27T03:20:02.074488Z","schema_version":"clob-market-ws.best_bid_ask.v1","sequence":null,"server_hash":null,"server_timestamp":"1785122402192","session_id":"dd162b8dca5f43ff811d304e69a06123","source":"clob_market_ws"},"received_at":"2026-07-27T03:20:02.074488Z","record_id":"e991922d8f007fdab6e1c21bd0ad7a61fcb343a680f4957788ebf24d72050aae","schema_fingerprint":"8488399f31b0337811b13b266be932db7062827c2470b78bd8e9e99bab51d17d","schema_version":"edge-lab-recorder.raw.v1","sequence":null,"source":"clob_market_ws"}
{"event_at":"2026-07-27T03:20:02.192000Z","event_fingerprint":"1d8ce666725eee36204fc7e6d12b9c2459942bb9311f600d6c79b79cccc79de1","payload":{"connection_id":"c7dc2e4762f849c6b6f9306b6518dcab","event_at":"2026-07-27T03:20:02.192000Z","event_type":"best_bid_ask","frame_hash":"5b973ac626197cf4210f30611cd78656c3eb98d4305bebc0af3e9408616095f1","frame_index":0,"kind":"data","monotonic_ns":224385427460916,"payload":{"asset_id":"41448400836309843603620980831210604935021861034693225347475867885462478926555","best_ask":"0.54","best_bid":"0.53","event_type":"best_bid_ask","market":"0x717c0e8ccd4d5c7040185188fbae28be901ca589a11a94b1b38ca36a79eccfeb","spread":"0.01","timestamp":"1785122402192"},"payload_hash":"8504b7ee628511c4423bf4a4fc172a49fd457395905ebb1d94913d4bf3a90925","raw_frame":"{\"market\":\"0x717c0e8ccd4d5c7040185188fbae28be901ca589a11a94b1b38ca36a79eccfeb\", \"asset_id\":\"41448400836309843603620980831210604935021861034693225347475867885462478926555\", \"best_bid\":\"0.53\", \"best_ask\":\"0.54\", \"spread\":\"0.01\", \"timestamp\":\"1785122402192\", \"event_type\":\"best_bid_ask\"}","received_at":"2026-07-27T03:20:02.075743Z","schema_version":"clob-market-ws.best_bid_ask.v1","sequence":null,"server_hash":null,"server_timestamp":"1785122402192","session_id":"dd162b8dca5f43ff811d304e69a06123","source":"clob_market_ws"},"received_at":"2026-07-27T03:20:02.075743Z","record_id":"11e22c6b95c4bb77301f1177483eff444358d9ebc8fae2adca4ba65885c1639e","schema_fingerprint":"8488399f31b0337811b13b266be932db7062827c2470b78bd8e9e99bab51d17d","schema_version":"edge-lab-recorder.raw.v1","sequence":null,"source":"clob_market_ws"}
{"event_at":"2026-07-27T03:20:02.192000Z","event_fingerprint":"5ea4b8c2d44feb4cb2477076f1a6061de1536c46b7fff5be21a81a164fca4dc4","payload":{"connection_id":"c7dc2e4762f849c6b6f9306b6518dcab","event_at":"2026-07-27T03:20:02.192000Z","event_type":"price_change","frame_hash":"fa299420f00ddaac40c5aba0fb31a0f98c5f6925f7263a3b7e73eaba56a30c90","frame_index":0,"kind":"data","monotonic_ns":224385428743291,"payload":{"event_type":"price_change","market":"0x717c0e8ccd4d5c7040185188fbae28be901ca589a11a94b1b38ca36a79eccfeb","price_changes":[{"asset_id":"41448400836309843603620980831210604935021861034693225347475867885462478926555","best_ask":"0.54","best_bid":"0.53","hash":"cb2b2e617450c22d85314a7fa7053d2f17ee8d72","price":"0.53","side":"BUY","size":"86.28"},{"asset_id":"24254094493625419915756280046002869097156693848522361803041977572204227262166","best_ask":"0.47","best_bid":"0.46","hash":"16830144b368fb091dc286334f7317ea0a71f147","price":"0.47","side":"SELL","size":"86.28"}],"timestamp":"1785122402192"},"payload_hash":"bb304e3cba679e831e64e38e7009e76f85d152c05e3736e31856da6dceb70513","raw_frame":"{\"market\":\"0x717c0e8ccd4d5c7040185188fbae28be901ca589a11a94b1b38ca36a79eccfeb\", \"price_changes\":[{\"asset_id\":\"41448400836309843603620980831210604935021861034693225347475867885462478926555\", \"price\":\"0.53\", \"size\":\"86.28\", \"side\":\"BUY\", \"hash\":\"cb2b2e617450c22d85314a7fa7053d2f17ee8d72\", \"best_bid\":\"0.53\", \"best_ask\":\"0.54\"}, {\"asset_id\":\"24254094493625419915756280046002869097156693848522361803041977572204227262166\", \"price\":\"0.47\", \"size\":\"86.28\", \"side\":\"SELL\", \"hash\":\"16830144b368fb091dc286334f7317ea0a71f147\", \"best_bid\":\"0.46\", \"best_ask\":\"0.47\"}], \"timestamp\":\"1785122402192\", \"event_type\":\"price_change\"}","received_at":"2026-07-27T03:20:02.077026Z","schema_version":"clob-market-ws.price_change.v1","sequence":null,"server_hash":null,"server_timestamp":"1785122402192","session_id":"dd162b8dca5f43ff811d304e69a06123","source":"clob_market_ws"},"received_at":"2026-07-27T03:20:02.077026Z","record_id":"db0aa3fa71c1ffa6f161e919bb6530a0b458674f293f1ca2490a80a3509e07ba","schema_fingerprint":"4aa3821a28b0b7c2400bc59aba4bcc0a76e971dadd19610d3ad38c768e124dc7","schema_version":"edge-lab-recorder.raw.v1","sequence":null,"source":"clob_market_ws"}
{"event_at":"2026-07-27T03:20:02.192000Z","event_fingerprint":"23d486a1c851347f2c1206a3576024c07a858da4187677bce34b92913d97a779","payload":{"connection_id":"c7dc2e4762f849c6b6f9306b6518dcab","event_at":"2026-07-27T03:20:02.192000Z","event_type":"book","frame_hash":"998f06ca58c94c1bdc218bcc20bd2a2771d8c253bf7194bb0fbb66cbc471d1c7","frame_index":0,"kind":"data","monotonic_ns":224385431739000,"payload":{"asks":[{"price":"0.99","size":"5703.02"},{"price":"0.98","size":"688.1"},{"price":"0.97","size":"613.1"},{"price":"0.96","size":"628.09"},{"price":"0.95","size":"718.2"},{"price":"0.94","size":"553.2"},{"price":"0.93","size":"546.1"},{"price":"0.92","size":"540.79"},{"price":"0.91","size":"551.6"},{"price":"0.9","size":"47.29"},{"price":"0.89","size":"43.6"},{"price":"0.88","size":"40.4"},{"price":"0.87","size":"37.5"},{"price":"0.86","size":"34.9"},{"price":"0.85","size":"33.5"},{"price":"0.84","size":"31.3"},{"price":"0.83","size":"30.3"},{"price":"0.82","size":"28.3"},{"price":"0.81","size":"27.5"},{"price":"0.8","size":"26.8"},{"price":"0.79","size":"26.1"},{"price":"0.78","size":"24.5"},{"price":"0.77","size":"23.89"},{"price":"0.76","size":"23.39"},{"price":"0.75","size":"23"},{"price":"0.74","size":"21.6"},{"price":"0.73","size":"27.79"},{"price":"0.72","size":"20.9"},{"price":"0.71","size":"20.6"},{"price":"0.7","size":"20.3"},{"price":"0.69","size":"342.56"},{"price":"0.68","size":"13.8"},{"price":"0.67","size":"19.6"},{"price":"0.66","size":"19.4"},{"price":"0.65","size":"23.2"},{"price":"0.64","size":"118"},{"price":"0.63","size":"117.9"},{"price":"0.62","size":"122.7"},{"price":"0.61","size":"5"},{"price":"0.6","size":"118"},{"price":"0.59","size":"117"},{"price":"0.58","size":"152"},{"price":"0.57","size":"117"},{"price":"0.56","size":"16"},{"price":"0.55","size":"128.12"},{"price":"0.54","size":"139.58"},{"price":"0.53","size":"28.05"},{"price":"0.52","size":"63.43"},{"price":"0.51","size":"36.4"},{"price":"0.5","size":"26.4"},{"price":"0.49","size":"9.6"},{"price":"0.48","size":"9.6"},{"price":"0.47","size":"86.28"}],"asset_id":"24254094493625419915756280046002869097156693848522361803041977572204227262166","bids":[{"price":"0.01","size":"5703.02"},{"price":"0.02","size":"678.1"},{"price":"0.03","size":"746.43"},{"price":"0.04","size":"628.09"},{"price":"0.05","size":"618.2"},{"price":"0.06","size":"553.2"},{"price":"0.07","size":"546.1"},{"price":"0.08","size":"540.79"},{"price":"0.09","size":"536.6"},{"price":"0.1","size":"33.29"},{"price":"0.11","size":"43.6"},{"price":"0.12","size":"40.4"},{"price":"0.13","size":"37.5"},{"price":"0.14","size":"34.9"},{"price":"0.15","size":"33.5"},{"price":"0.16","size":"31.3"},{"price":"0.17","size":"30.3"},{"price":"0.18","size":"28.3"},{"price":"0.19","size":"27.5"},{"price":"0.2","size":"26.8"},{"price":"0.21","size":"26.1"},{"price":"0.22","size":"24.5"},{"price":"0.23","size":"23.89"},{"price":"0.24","size":"23.39"},{"price":"0.25","size":"23"},{"price":"0.26","size":"21.6"},{"price":"0.27","size":"21.2"},{"price":"0.28","size":"20.9"},{"price":"0.29","size":"20.6"},{"price":"0.3","size":"160.3"},{"price":"0.31","size":"130"},{"price":"0.32","size":"332.28"},{"price":"0.33","size":"119.6"},{"price":"0.34","size":"119.4"},{"price":"0.35","size":"123.2"},{"price":"0.36","size":"137"},{"price":"0.37","size":"136.9"},{"price":"0.38","size":"118"},{"price":"0.39","size":"118"},{"price":"0.4","size":"45.44"},{"price":"0.41","size":"224.37"},{"price":"0.42","size":"70.29"},{"price":"0.43","size":"29.23"},{"price":"0.44","size":"16"},{"price":"0.45","size":"20.6"},{"price":"0.46","size":"21"}],"event_type":"book","hash":"16830144b368fb091dc286334f7317ea0a71f147","market":"0x717c0e8ccd4d5c7040185188fbae28be901ca589a11a94b1b38ca36a79eccfeb","timestamp":"1785122402192"},"payload_hash":"7ca4991cfaba981b0f2c664f0837384c00894b7235485d9f0d37c84d0cca0482","raw_frame":"{\"market\":\"0x717c0e8ccd4d5c7040185188fbae28be901ca589a11a94b1b38ca36a79eccfeb\", \"asset_id\":\"24254094493625419915756280046002869097156693848522361803041977572204227262166\", \"bids\":[{\"price\":\"0.01\", \"size\":\"5703.02\"}, {\"price\":\"0.02\", \"size\":\"678.1\"}, {\"price\":\"0.03\", \"size\":\"746.43\"}, {\"price\":\"0.04\", \"size\":\"628.09\"}, {\"price\":\"0.05\", \"size\":\"618.2\"}, {\"price\":\"0.06\", \"size\":\"553.2\"}, {\"price\":\"0.07\", \"size\":\"546.1\"}, {\"price\":\"0.08\", \"size\":\"540.79\"}, {\"price\":\"0.09\", \"size\":\"536.6\"}, {\"price\":\"0.1\", \"size\":\"33.29\"}, {\"price\":\"0.11\", \"size\":\"43.6\"}, {\"price\":\"0.12\", \"size\":\"40.4\"}, {\"price\":\"0.13\", \"size\":\"37.5\"}, {\"price\":\"0.14\", \"size\":\"34.9\"}, {\"price\":\"0.15\", \"size\":\"33.5\"}, {\"price\":\"0.16\", \"size\":\"31.3\"}, {\"price\":\"0.17\", \"size\":\"30.3\"}, {\"price\":\"0.18\", \"size\":\"28.3\"}, {\"price\":\"0.19\", \"size\":\"27.5\"}, {\"price\":\"0.2\", \"size\":\"26.8\"}, {\"price\":\"0.21\", \"size\":\"26.1\"}, {\"price\":\"0.22\", \"size\":\"24.5\"}, {\"price\":\"0.23\", \"size\":\"23.89\"}, {\"price\":\"0.24\", \"size\":\"23.39\"}, {\"price\":\"0.25\", \"size\":\"23\"}, {\"price\":\"0.26\", \"size\":\"21.6\"}, {\"price\":\"0.27\", \"size\":\"21.2\"}, {\"price\":\"0.28\", \"size\":\"20.9\"}, {\"price\":\"0.29\", \"size\":\"20.6\"}, {\"price\":\"0.3\", \"size\":\"160.3\"}, {\"price\":\"0.31\", \"size\":\"130\"}, {\"price\":\"0.32\", \"size\":\"332.28\"}, {\"price\":\"0.33\", \"size\":\"119.6\"}, {\"price\":\"0.34\", \"size\":\"119.4\"}, {\"price\":\"0.35\", \"size\":\"123.2\"}, {\"price\":\"0.36\", \"size\":\"137\"}, {\"price\":\"0.37\", \"size\":\"136.9\"}, {\"price\":\"0.38\", \"size\":\"118\"}, {\"price\":\"0.39\", \"size\":\"118\"}, {\"price\":\"0.4\", \"size\":\"45.44\"}, {\"price\":\"0.41\", \"size\":\"224.37\"}, {\"price\":\"0.42\", \"size\":\"70.29\"}, {\"price\":\"0.43\", \"size\":\"29.23\"}, {\"price\":\"0.44\", \"size\":\"16\"}, {\"price\":\"0.45\", \"size\":\"20.6\"}, {\"price\":\"0.46\", \"size\":\"21\"}], \"asks\":[{\"price\":\"0.99\", \"size\":\"5703.02\"}, {\"price\":\"0.98\", \"size\":\"688.1\"}, {\"price\":\"0.97\", \"size\":\"613.1\"}, {\"price\":\"0.96\", \"size\":\"628.09\"}, {\"price\":\"0.95\", \"size\":\"718.2\"}, {\"price\":\"0.94\", \"size\":\"553.2\"}, {\"price\":\"0.93\", \"size\":\"546.1\"}, {\"price\":\"0.92\", \"size\":\"540.79\"}, {\"price\":\"0.91\", \"size\":\"551.6\"}, {\"price\":\"0.9\", \"size\":\"47.29\"}, {\"price\":\"0.89\", \"size\":\"43.6\"}, {\"price\":\"0.88\", \"size\":\"40.4\"}, {\"price\":\"0.87\", \"size\":\"37.5\"}, {\"price\":\"0.86\", \"size\":\"34.9\"}, {\"price\":\"0.85\", \"size\":\"33.5\"}, {\"price\":\"0.84\", \"size\":\"31.3\"}, {\"price\":\"0.83\", \"size\":\"30.3\"}, {\"price\":\"0.82\", \"size\":\"28.3\"}, {\"price\":\"0.81\", \"size\":\"27.5\"}, {\"price\":\"0.8\", \"size\":\"26.8\"}, {\"price\":\"0.79\", \"size\":\"26.1\"}, {\"price\":\"0.78\", \"size\":\"24.5\"}, {\"price\":\"0.77\", \"size\":\"23.89\"}, {\"price\":\"0.76\", \"size\":\"23.39\"}, {\"price\":\"0.75\", \"size\":\"23\"}, {\"price\":\"0.74\", \"size\":\"21.6\"}, {\"price\":\"0.73\", \"size\":\"27.79\"}, {\"price\":\"0.72\", \"size\":\"20.9\"}, {\"price\":\"0.71\", \"size\":\"20.6\"}, {\"price\":\"0.7\", \"size\":\"20.3\"}, {\"price\":\"0.69\", \"size\":\"342.56\"}, {\"price\":\"0.68\", \"size\":\"13.8\"}, {\"price\":\"0.67\", \"size\":\"19.6\"}, {\"price\":\"0.66\", \"size\":\"19.4\"}, {\"price\":\"0.65\", \"size\":\"23.2\"}, {\"price\":\"0.64\", \"size\":\"118\"}, {\"price\":\"0.63\", \"size\":\"117.9\"}, {\"price\":\"0.62\", \"size\":\"122.7\"}, {\"price\":\"0.61\", \"size\":\"5\"}, {\"price\":\"0.6\", \"size\":\"118\"}, {\"price\":\"0.59\", \"size\":\"117\"}, {\"price\":\"0.58\", \"size\":\"152\"}, {\"price\":\"0.57\", \"size\":\"117\"}, {\"price\":\"0.56\", \"size\":\"16\"}, {\"price\":\"0.55\", \"size\":\"128.12\"}, {\"price\":\"0.54\", \"size\":\"139.58\"}, {\"price\":\"0.53\", \"size\":\"28.05\"}, {\"price\":\"0.52\", \"size\":\"63.43\"}, {\"price\":\"0.51\", \"size\":\"36.4\"}, {\"price\":\"0.5\", \"size\":\"26.4\"}, {\"price\":\"0.49\", \"size\":\"9.6\"}, {\"price\":\"0.48\", \"size\":\"9.6\"}, {\"price\":\"0.47\", \"size\":\"86.28\"}], \"hash\":\"16830144b368fb091dc286334f7317ea0a71f147\", \"timestamp\":\"1785122402192\", \"event_type\":\"book\"}","received_at":"2026-07-27T03:20:02.080020Z","schema_version":"clob-market-ws.book.v1","sequence":null,"server_hash":"16830144b368fb091dc286334f7317ea0a71f147","server_timestamp":"1785122402192","session_id":"dd162b8dca5f43ff811d304e69a06123","source":"clob_market_ws"},"received_at":"2026-07-27T03:20:02.080020Z","record_id":"6607d6841157628b99cb6c20b70034be7b8f03960ec46e81367efa8877cd1c51","schema_fingerprint":"dc2caa1c89c6a7426e2e07ff925910cd4d0a8a223a515d4092d91d6d127aacb6","schema_version":"edge-lab-recorder.raw.v1","sequence":null,"source":"clob_market_ws"}
{"event_at":"2026-07-27T03:20:02.192000Z","event_fingerprint":"70b0bef02ce34bda9a49045fec6923b72382c0f4b7ba99a5b9d41cb5d54c942a","payload":{"connection_id":"c7dc2e4762f849c6b6f9306b6518dcab","event_at":"2026-07-27T03:20:02.192000Z","event_type":"book","frame_hash":"a8865a6bebf19c1caea84a7b0ad1e241b4cf308781d739baa3e9e90825191e5a","frame_index":0,"kind":"data","monotonic_ns":224385442429708,"payload":{"asks":[{"price":"0.99","size":"5703.02"},{"price":"0.98","size":"678.1"},{"price":"0.97","size":"746.43"},{"price":"0.96","size":"628.09"},{"price":"0.95","size":"618.2"},{"price":"0.94","size":"553.2"},{"price":"0.93","size":"546.1"},{"price":"0.92","size":"540.79"},{"price":"0.91","size":"536.6"},{"price":"0.9","size":"33.29"},{"price":"0.89","size":"43.6"},{"price":"0.88","size":"40.4"},{"price":"0.87","size":"37.5"},{"price":"0.86","size":"34.9"},{"price":"0.85","size":"33.5"},{"price":"0.84","size":"31.3"},{"price":"0.83","size":"30.3"},{"price":"0.82","size":"28.3"},{"price":"0.81","size":"27.5"},{"price":"0.8","size":"26.8"},{"price":"0.79","size":"26.1"},{"price":"0.78","size":"24.5"},{"price":"0.77","size":"23.89"},{"price":"0.76","size":"23.39"},{"price":"0.75","size":"23"},{"price":"0.74","size":"21.6"},{"price":"0.73","size":"21.2"},{"price":"0.72","size":"20.9"},{"price":"0.71","size":"20.6"},{"price":"0.7","size":"160.3"},{"price":"0.69","size":"130"},{"price":"0.68","size":"332.28"},{"price":"0.67","size":"119.6"},{"price":"0.66","size":"119.4"},{"price":"0.65","size":"123.2"},{"price":"0.64","size":"137"},{"price":"0.63","size":"136.9"},{"price":"0.62","size":"118"},{"price":"0.61","size":"118"},{"price":"0.6","size":"45.44"},{"price":"0.59","size":"224.37"},{"price":"0.58","size":"70.29"},{"price":"0.57","size":"29.23"},{"price":"0.56","size":"16"},{"price":"0.55","size":"20.6"},{"price":"0.54","size":"21"}],"asset_id":"41448400836309843603620980831210604935021861034693225347475867885462478926555","bids":[{"price":"0.01","size":"5703.02"},{"price":"0.02","size":"688.1"},{"price":"0.03","size":"613.1"},{"price":"0.04","size":"628.09"},{"price":"0.05","size":"718.2"},{"price":"0.06","size":"553.2"},{"price":"0.07","size":"546.1"},{"price":"0.08","size":"540.79"},{"price":"0.09","size":"551.6"},{"price":"0.1","size":"47.29"},{"price":"0.11","size":"43.6"},{"price":"0.12","size":"40.4"},{"price":"0.13","size":"37.5"},{"price":"0.14","size":"34.9"},{"price":"0.15","size":"33.5"},{"price":"0.16","size":"31.3"},{"price":"0.17","size":"30.3"},{"price":"0.18","size":"28.3"},{"price":"0.19","size":"27.5"},{"price":"0.2","size":"26.8"},{"price":"0.21","size":"26.1"},{"price":"0.22","size":"24.5"},{"price":"0.23","size":"23.89"},{"price":"0.24","size":"23.39"},{"price":"0.25","size":"23"},{"price":"0.26","size":"21.6"},{"price":"0.27","size":"27.79"},{"price":"0.28","size":"20.9"},{"price":"0.29","size":"20.6"},{"price":"0.3","size":"20.3"},{"price":"0.31","size":"342.56"},{"price":"0.32","size":"13.8"},{"price":"0.33","size":"19.6"},{"price":"0.34","size":"19.4"},{"price":"0.35","size":"23.2"},{"price":"0.36","size":"118"},{"price":"0.37","size":"117.9"},{"price":"0.38","size":"122.7"},{"price":"0.39","size":"5"},{"price":"0.4","size":"118"},{"price":"0.41","size":"117"},{"price":"0.42","size":"152"},{"price":"0.43","size":"117"},{"price":"0.44","size":"16"},{"price":"0.45","size":"128.12"},{"price":"0.46","size":"139.58"},{"price":"0.47","size":"28.05"},{"price":"0.48","size":"63.43"},{"price":"0.49","size":"36.4"},{"price":"0.5","size":"26.4"},{"price":"0.51","size":"9.6"},{"price":"0.52","size":"9.6"},{"price":"0.53","size":"86.28"}],"event_type":"book","hash":"cb2b2e617450c22d85314a7fa7053d2f17ee8d72","market":"0x717c0e8ccd4d5c7040185188fbae28be901ca589a11a94b1b38ca36a79eccfeb","timestamp":"1785122402192"},"payload_hash":"bac547b4c23dd8216c01780e235b35ae5739d7ecc9956545083d54a8b1b1f997","raw_frame":"{\"market\":\"0x717c0e8ccd4d5c7040185188fbae28be901ca589a11a94b1b38ca36a79eccfeb\", \"asset_id\":\"41448400836309843603620980831210604935021861034693225347475867885462478926555\", \"bids\":[{\"price\":\"0.01\", \"size\":\"5703.02\"}, {\"price\":\"0.02\", \"size\":\"688.1\"}, {\"price\":\"0.03\", \"size\":\"613.1\"}, {\"price\":\"0.04\", \"size\":\"628.09\"}, {\"price\":\"0.05\", \"size\":\"718.2\"}, {\"price\":\"0.06\", \"size\":\"553.2\"}, {\"price\":\"0.07\", \"size\":\"546.1\"}, {\"price\":\"0.08\", \"size\":\"540.79\"}, {\"price\":\"0.09\", \"size\":\"551.6\"}, {\"price\":\"0.1\", \"size\":\"47.29\"}, {\"price\":\"0.11\", \"size\":\"43.6\"}, {\"price\":\"0.12\", \"size\":\"40.4\"}, {\"price\":\"0.13\", \"size\":\"37.5\"}, {\"price\":\"0.14\", \"size\":\"34.9\"}, {\"price\":\"0.15\", \"size\":\"33.5\"}, {\"price\":\"0.16\", \"size\":\"31.3\"}, {\"price\":\"0.17\", \"size\":\"30.3\"}, {\"price\":\"0.18\", \"size\":\"28.3\"}, {\"price\":\"0.19\", \"size\":\"27.5\"}, {\"price\":\"0.2\", \"size\":\"26.8\"}, {\"price\":\"0.21\", \"size\":\"26.1\"}, {\"price\":\"0.22\", \"size\":\"24.5\"}, {\"price\":\"0.23\", \"size\":\"23.89\"}, {\"price\":\"0.24\", \"size\":\"23.39\"}, {\"price\":\"0.25\", \"size\":\"23\"}, {\"price\":\"0.26\", \"size\":\"21.6\"}, {\"price\":\"0.27\", \"size\":\"27.79\"}, {\"price\":\"0.28\", \"size\":\"20.9\"}, {\"price\":\"0.29\", \"size\":\"20.6\"}, {\"price\":\"0.3\", \"size\":\"20.3\"}, {\"price\":\"0.31\", \"size\":\"342.56\"}, {\"price\":\"0.32\", \"size\":\"13.8\"}, {\"price\":\"0.33\", \"size\":\"19.6\"}, {\"price\":\"0.34\", \"size\":\"19.4\"}, {\"price\":\"0.35\", \"size\":\"23.2\"}, {\"price\":\"0.36\", \"size\":\"118\"}, {\"price\":\"0.37\", \"size\":\"117.9\"}, {\"price\":\"0.38\", \"size\":\"122.7\"}, {\"price\":\"0.39\", \"size\":\"5\"}, {\"price\":\"0.4\", \"size\":\"118\"}, {\"price\":\"0.41\", \"size\":\"117\"}, {\"price\":\"0.42\", \"size\":\"152\"}, {\"price\":\"0.43\", \"size\":\"117\"}, {\"price\":\"0.44\", \"size\":\"16\"}, {\"price\":\"0.45\", \"size\":\"128.12\"}, {\"price\":\"0.46\", \"size\":\"139.58\"}, {\"price\":\"0.47\", \"size\":\"28.05\"}, {\"price\":\"0.48\", \"size\":\"63.43\"}, {\"price\":\"0.49\", \"size\":\"36.4\"}, {\"price\":\"0.5\", \"size\":\"26.4\"}, {\"price\":\"0.51\", \"size\":\"9.6\"}, {\"price\":\"0.52\", \"size\":\"9.6\"}, {\"price\":\"0.53\", \"size\":\"86.28\"}], \"asks\":[{\"price\":\"0.99\", \"size\":\"5703.02\"}, {\"price\":\"0.98\", \"size\":\"678.1\"}, {\"price\":\"0.97\", \"size\":\"746.43\"}, {\"price\":\"0.96\", \"size\":\"628.09\"}, {\"price\":\"0.95\", \"size\":\"618.2\"}, {\"price\":\"0.94\", \"size\":\"553.2\"}, {\"price\":\"0.93\", \"size\":\"546.1\"}, {\"price\":\"0.92\", \"size\":\"540.79\"}, {\"price\":\"0.91\", \"size\":\"536.6\"}, {\"price\":\"0.9\", \"size\":\"33.29\"}, {\"price\":\"0.89\", \"size\":\"43.6\"}, {\"price\":\"0.88\", \"size\":\"40.4\"}, {\"price\":\"0.87\", \"size\":\"37.5\"}, {\"price\":\"0.86\", \"size\":\"34.9\"}, {\"price\":\"0.85\", \"size\":\"33.5\"}, {\"price\":\"0.84\", \"size\":\"31.3\"}, {\"price\":\"0.83\", \"size\":\"30.3\"}, {\"price\":\"0.82\", \"size\":\"28.3\"}, {\"price\":\"0.81\", \"size\":\"27.5\"}, {\"price\":\"0.8\", \"size\":\"26.8\"}, {\"price\":\"0.79\", \"size\":\"26.1\"}, {\"price\":\"0.78\", \"size\":\"24.5\"}, {\"price\":\"0.77\", \"size\":\"23.89\"}, {\"price\":\"0.76\", \"size\":\"23.39\"}, {\"price\":\"0.75\", \"size\":\"23\"}, {\"price\":\"0.74\", \"size\":\"21.6\"}, {\"price\":\"0.73\", \"size\":\"21.2\"}, {\"price\":\"0.72\", \"size\":\"20.9\"}, {\"price\":\"0.71\", \"size\":\"20.6\"}, {\"price\":\"0.7\", \"size\":\"160.3\"}, {\"price\":\"0.69\", \"size\":\"130\"}, {\"price\":\"0.68\", \"size\":\"332.28\"}, {\"price\":\"0.67\", \"size\":\"119.6\"}, {\"price\":\"0.66\", \"size\":\"119.4\"}, {\"price\":\"0.65\", \"size\":\"123.2\"}, {\"price\":\"0.64\", \"size\":\"137\"}, {\"price\":\"0.63\", \"size\":\"136.9\"}, {\"price\":\"0.62\", \"size\":\"118\"}, {\"price\":\"0.61\", \"size\":\"118\"}, {\"price\":\"0.6\", \"size\":\"45.44\"}, {\"price\":\"0.59\", \"size\":\"224.37\"}, {\"price\":\"0.58\", \"size\":\"70.29\"}, {\"price\":\"0.57\", \"size\":\"29.23\"}, {\"price\":\"0.56\", \"size\":\"16\"}, {\"price\":\"0.55\", \"size\":\"20.6\"}, {\"price\":\"0.54\", \"size\":\"21\"}], \"hash\":\"cb2b2e617450c22d85314a7fa7053d2f17ee8d72\", \"timestamp\":\"1785122402192\", \"event_type\":\"book\"}","received_at":"2026-07-27T03:20:02.090712Z","schema_version":"clob-market-ws.book.v1","sequence":null,"server_hash":"cb2b2e617450c22d85314a7fa7053d2f17ee8d72","server_timestamp":"1785122402192","session_id":"dd162b8dca5f43ff811d304e69a06123","source":"clob_market_ws"},"received_at":"2026-07-27T03:20:02.090712Z","record_id":"8df8bbccecf9abe1ebb51e29bf91f207721e4066b9a089f7875960132680d0a1","schema_fingerprint":"dc2caa1c89c6a7426e2e07ff925910cd4d0a8a223a515d4092d91d6d127aacb6","schema_version":"edge-lab-recorder.raw.v1","sequence":null,"source":"clob_market_ws"}
{"event_at":"2026-07-27T03:20:02.219000Z","event_fingerprint":"c65805fd9d4b61347b6317dc8ef7405c2e22715e85f16421733ec00f7f117bb4","payload":{"connection_id":"c7dc2e4762f849c6b6f9306b6518dcab","event_at":"2026-07-27T03:20:02.219000Z","event_type":"price_change","frame_hash":"1799fdfd6ecaf3f04fe5e2dd82d161a25f3943cbaf0ed44efd5de62ba1171f98","frame_index":0,"kind":"data","monotonic_ns":224385453396833,"payload":{"event_type":"price_change","market":"0x717c0e8ccd4d5c7040185188fbae28be901ca589a11a94b1b38ca36a79eccfeb","price_changes":[{"asset_id":"41448400836309843603620980831210604935021861034693225347475867885462478926555","best_ask":"0.54","best_bid":"0.53","hash":"d1acf57596601598e15054d2ec63bac6b5d87f64","price":"0.02","side":"BUY","size":"683.1"},{"asset_id":"24254094493625419915756280046002869097156693848522361803041977572204227262166","best_ask":"0.47","best_bid":"0.46","hash":"8d2d86581a2fb388fd50845d86a818923eb49727","price":"0.98","side":"SELL","size":"683.1"}],"timestamp":"1785122402219"},"payload_hash":"717633b9d485d849c763507d5ae18889eb583597766ea03ac4ee5534943e66e2","raw_frame":"{\"market\":\"0x717c0e8ccd4d5c7040185188fbae28be901ca589a11a94b1b38ca36a79eccfeb\", \"price_changes\":[{\"asset_id\":\"41448400836309843603620980831210604935021861034693225347475867885462478926555\", \"price\":\"0.02\", \"size\":\"683.1\", \"side\":\"BUY\", \"hash\":\"d1acf57596601598e15054d2ec63bac6b5d87f64\", \"best_bid\":\"0.53\", \"best_ask\":\"0.54\"}, {\"asset_id\":\"24254094493625419915756280046002869097156693848522361803041977572204227262166\", \"price\":\"0.98\", \"size\":\"683.1\", \"side\":\"SELL\", \"hash\":\"8d2d86581a2fb388fd50845d86a818923eb49727\", \"best_bid\":\"0.46\", \"best_ask\":\"0.47\"}], \"timestamp\":\"1785122402219\", \"event_type\":\"price_change\"}","received_at":"2026-07-27T03:20:02.101674Z","schema_version":"clob-market-ws.price_change.v1","sequence":null,"server_hash":null,"server_timestamp":"1785122402219","session_id":"dd162b8dca5f43ff811d304e69a06123","source":"clob_market_ws"},"received_at":"2026-07-27T03:20:02.101674Z","record_id":"1560b675c3915a61476e9a682031e9b5bb0985570a313033a225dc6fd9698069","schema_fingerprint":"4aa3821a28b0b7c2400bc59aba4bcc0a76e971dadd19610d3ad38c768e124dc7","schema_version":"edge-lab-recorder.raw.v1","sequence":null,"source":"clob_market_ws"}
{"event_at":"2026-07-27T03:20:02.281000Z","event_fingerprint":"dda400a1fe2ea2ddf4bef673b6cc308acbd78e7432b80aa4cc1a9594d0611b0c","payload":{"connection_id":"c7dc2e4762f849c6b6f9306b6518dcab","event_at":"2026-07-27T03:20:02.281000Z","event_type":"last_trade_price","frame_hash":"01c4cd4a093162854b43e3dac27df6da4fc0c4121f1d3f7294d6a85ac5e4bcf2","frame_index":0,"kind":"data","monotonic_ns":224385518414333,"payload":{"asset_id":"24254094493625419915756280046002869097156693848522361803041977572204227262166","event_type":"last_trade_price","fee_rate_bps":"0","market":"0x717c0e8ccd4d5c7040185188fbae28be901ca589a11a94b1b38ca36a79eccfeb","price":"0.47","side":"BUY","size":"4.659573","timestamp":"1785122402281","transaction_hash":"0x262f39ccef65104b334046dd22e815436e3f77d3e0c41e6a749e8cb5318872ac"},"payload_hash":"81852eb47fd0c9fe3c1fc16342109c2fb70a6e1d000b89162b95ddfb3c178b82","raw_frame":"{\"market\":\"0x717c0e8ccd4d5c7040185188fbae28be901ca589a11a94b1b38ca36a79eccfeb\", \"asset_id\":\"24254094493625419915756280046002869097156693848522361803041977572204227262166\", \"price\":\"0.47\", \"size\":\"4.659573\", \"fee_rate_bps\":\"0\", \"side\":\"BUY\", \"timestamp\":\"1785122402281\", \"event_type\":\"last_trade_price\", \"transaction_hash\":\"0x262f39ccef65104b334046dd22e815436e3f77d3e0c41e6a749e8cb5318872ac\"}","received_at":"2026-07-27T03:20:02.166680Z","schema_version":"clob-market-ws.last_trade_price.v1","sequence":null,"server_hash":null,"server_timestamp":"1785122402281","session_id":"dd162b8dca5f43ff811d304e69a06123","source":"clob_market_ws"},"received_at":"2026-07-27T03:20:02.166680Z","record_id":"c8a69d7ae7757ea12048a9155db5af1fd325e4ec98b366985d001e00c44e1275","schema_fingerprint":"95ad9be75a4b695cd99991e12b2592bc7346f3f5388a82d0000ba65bc0d9fd0a","schema_version":"edge-lab-recorder.raw.v1","sequence":null,"source":"clob_market_ws"}
{"event_at":"2026-07-27T03:20:02.310000Z","event_fingerprint":"c9c7920c3eaad0c87749d9862b6fd43373dbb76b437d9a345de50bfbed2bd7ec","payload":{"connection_id":"c7dc2e4762f849c6b6f9306b6518dcab","event_at":"2026-07-27T03:20:02.310000Z","event_type":"price_change","frame_hash":"6565d2e745c558b951dd4cc3ebbe77aa1166a6baa16154dff1c2fbb54ea85bb5","frame_index":0,"kind":"data","monotonic_ns":224385545835541,"payload":{"event_type":"price_change","market":"0x717c0e8ccd4d5c7040185188fbae28be901ca589a11a94b1b38ca36a79eccfeb","price_changes":[{"asset_id":"41448400836309843603620980831210604935021861034693225347475867885462478926555","best_ask":"0.54","best_bid":"0.53","hash":"a5f623d11600d0a637533f4b2d3f5806451427c8","price":"0.04","side":"BUY","size":"633.09"},{"asset_id":"24254094493625419915756280046002869097156693848522361803041977572204227262166","best_ask":"0.47","best_bid":"0.46","hash":"0053b64037d852b0f9c0c9cab847129d1cd2e450","price":"0.96","side":"SELL","size":"633.09"}],"timestamp":"1785122402310"},"payload_hash":"298b85517a1cf24d0e27a45e3679545b1124d2ff87ac51dddc8be00da6b99dfb","raw_frame":"{\"market\":\"0x717c0e8ccd4d5c7040185188fbae28be901ca589a11a94b1b38ca36a79eccfeb\", \"price_changes\":[{\"asset_id\":\"41448400836309843603620980831210604935021861034693225347475867885462478926555\", \"price\":\"0.04\", \"size\":\"633.09\", \"side\":\"BUY\", \"hash\":\"a5f623d11600d0a637533f4b2d3f5806451427c8\", \"best_bid\":\"0.53\", \"best_ask\":\"0.54\"}, {\"asset_id\":\"24254094493625419915756280046002869097156693848522361803041977572204227262166\", \"price\":\"0.96\", \"size\":\"633.09\", \"side\":\"SELL\", \"hash\":\"0053b64037d852b0f9c0c9cab847129d1cd2e450\", \"best_bid\":\"0.46\", \"best_ask\":\"0.47\"}], \"timestamp\":\"1785122402310\", \"event_type\":\"price_change\"}","received_at":"2026-07-27T03:20:02.194099Z","schema_version":"clob-market-ws.price_change.v1","sequence":null,"server_hash":null,"server_timestamp":"1785122402310","session_id":"dd162b8dca5f43ff811d304e69a06123","source":"clob_market_ws"},"received_at":"2026-07-27T03:20:02.194099Z","record_id":"2013d31810793f7285d704e65a4439500a0ca671dc46753859758efef8defdff","schema_fingerprint":"4aa3821a28b0b7c2400bc59aba4bcc0a76e971dadd19610d3ad38c768e124dc7","schema_version":"edge-lab-recorder.raw.v1","sequence":null,"source":"clob_market_ws"}
{"event_at":"2026-07-27T03:20:02.329000Z","event_fingerprint":"79a87d7360229b8682635295d1bfdf73b576f65e31af47f52e06acba8c22a3a2","payload":{"connection_id":"c7dc2e4762f849c6b6f9306b6518dcab","event_at":"2026-07-27T03:20:02.329000Z","event_type":"price_change","frame_hash":"437b43ad43935647dafb19c5dc75442eb67348be8802f84268295a98a292f4e7","frame_index":0,"kind":"data","monotonic_ns":224385564407333,"payload":{"event_type":"price_change","market":"0x717c0e8ccd4d5c7040185188fbae28be901ca589a11a94b1b38ca36a79eccfeb","price_changes":[{"asset_id":"41448400836309843603620980831210604935021861034693225347475867885462478926555","best_ask":"0.54","best_bid":"0.53","hash":"a94c173aebfafb419f95e97e7ddf22eec25e23b5","price":"0.04","side":"BUY","size":"583.09"},{"asset_id":"24254094493625419915756280046002869097156693848522361803041977572204227262166","best_ask":"0.47","best_bid":"0.46","hash":"7eba6346af86664843c3cdb26c709dada5c1bd35","price":"0.96","side":"SELL","size":"583.09"}],"timestamp":"1785122402329"},"payload_hash":"05b8167ce453676db6edd242756ee3bcf3a159fdb37687778e8a71e42a580b23","raw_frame":"{\"market\":\"0x717c0e8ccd4d5c7040185188fbae28be901ca589a11a94b1b38ca36a79eccfeb\", \"price_changes\":[{\"asset_id\":\"41448400836309843603620980831210604935021861034693225347475867885462478926555\", \"price\":\"0.04\", \"size\":\"583.09\", \"side\":\"BUY\", \"hash\":\"a94c173aebfafb419f95e97e7ddf22eec25e23b5\", \"best_bid\":\"0.53\", \"best_ask\":\"0.54\"}, {\"asset_id\":\"24254094493625419915756280046002869097156693848522361803041977572204227262166\", \"price\":\"0.96\", \"size\":\"583.09\", \"side\":\"SELL\", \"hash\":\"7eba6346af86664843c3cdb26c709dada5c1bd35\", \"best_bid\":\"0.46\", \"best_ask\":\"0.47\"}], \"timestamp\":\"1785122402329\", \"event_type\":\"price_change\"}","received_at":"2026-07-27T03:20:02.212669Z","schema_version":"clob-market-ws.price_change.v1","sequence":null,"server_hash":null,"server_timestamp":"1785122402329","session_id":"dd162b8dca5f43ff811d304e69a06123","source":"clob_market_ws"},"received_at":"2026-07-27T03:20:02.212669Z","record_id":"b947b739cd64402bbe5b019b183e78eda84c33f8c4fde04fc693c951e8e4098d","schema_fingerprint":"4aa3821a28b0b7c2400bc59aba4bcc0a76e971dadd19610d3ad38c768e124dc7","schema_version":"edge-lab-recorder.raw.v1","sequence":null,"source":"clob_market_ws"}
{"event_at":"2026-07-27T03:20:02.331000Z","event_fingerprint":"55366a298d9286b5b78c64b68dccc4e5c16b898617ce0d4c43f14bccf8bab955","payload":{"connection_id":"c7dc2e4762f849c6b6f9306b6518dcab","event_at":"2026-07-27T03:20:02.331000Z","event_type":"price_change","frame_hash":"bf7cee757d834c80ebe5b1baab3e765ed7195a86d1df31ac00adc7d454407515","frame_index":0,"kind":"data","monotonic_ns":224385566085625,"payload":{"event_type":"price_change","market":"0x717c0e8ccd4d5c7040185188fbae28be901ca589a11a94b1b38ca36a79eccfeb","price_changes":[{"asset_id":"41448400836309843603620980831210604935021861034693225347475867885462478926555","best_ask":"0.54","best_bid":"0.53","hash":"54855a6a23373e94991f36ef0b9c0cb597b5c8c3","price":"0.05","side":"BUY","size":"668.2"},{"asset_id":"24254094493625419915756280046002869097156693848522361803041977572204227262166","best_ask":"0.47","best_bid":"0.46","hash":"05b73077c256b475192b164fc35e59b9d03fb4ce","price":"0.95","side":"SELL","size":"668.2"}],"timestamp":"1785122402331"},"payload_hash":"e470581a90794ee38f312611d0922ff2d6d0f23413b56ed616ed89b40e0d151c","raw_frame":"{\"market\":\"0x717c0e8ccd4d5c7040185188fbae28be901ca589a11a94b1b38ca36a79eccfeb\", \"price_changes\":[{\"asset_id\":\"41448400836309843603620980831210604935021861034693225347475867885462478926555\", \"price\":\"0.05\", \"size\":\"668.2\", \"side\":\"BUY\", \"hash\":\"54855a6a23373e94991f36ef0b9c0cb597b5c8c3\", \"best_bid\":\"0.53\", \"best_ask\":\"0.54\"}, {\"asset_id\":\"24254094493625419915756280046002869097156693848522361803041977572204227262166\", \"price\":\"0.95\", \"size\":\"668.2\", \"side\":\"SELL\", \"hash\":\"05b73077c256b475192b164fc35e59b9d03fb4ce\", \"best_bid\":\"0.46\", \"best_ask\":\"0.47\"}], \"timestamp\":\"1785122402331\", \"event_type\":\"price_change\"}","received_at":"2026-07-27T03:20:02.214347Z","schema_version":"clob-market-ws.price_change.v1","sequence":null,"server_hash":null,"server_timestamp":"1785122402331","session_id":"dd162b8dca5f43ff811d304e69a06123","source":"clob_market_ws"},"received_at":"2026-07-27T03:20:02.214347Z","record_id":"027d9c51f022af403c1a97423254a872c4fc4ae08b09c66f01b2f0607325fb30","schema_fingerprint":"4aa3821a28b0b7c2400bc59aba4bcc0a76e971dadd19610d3ad38c768e124dc7","schema_version":"edge-lab-recorder.raw.v1","sequence":null,"source":"clob_market_ws"}
{"event_at":"2026-07-27T03:20:02.331000Z","event_fingerprint":"10826550ea4e49f63b870bfdae9381e7b781327be1ed1c1bce7b3905c2604def","payload":{"connection_id":"c7dc2e4762f849c6b6f9306b6518dcab","event_at":"2026-07-27T03:20:02.331000Z","event_type":"price_change","frame_hash":"120014f22c014c45219aab8c6f9185a1e0ec680fec477e879921a04090b644f8","frame_index":0,"kind":"data","monotonic_ns":224385567630416,"payload":{"event_type":"price_change","market":"0x717c0e8ccd4d5c7040185188fbae28be901ca589a11a94b1b38ca36a79eccfeb","price_changes":[{"asset_id":"24254094493625419915756280046002869097156693848522361803041977572204227262166","best_ask":"0.47","best_bid":"0.46","hash":"4cdf1cdfbc0838039b1a8b0110d680c8556a17a0","price":"0.04","side":"BUY","size":"578.09"},{"asset_id":"41448400836309843603620980831210604935021861034693225347475867885462478926555","best_ask":"0.54","best_bid":"0.53","hash":"3e169d3f6fdb60106b6b59e7b625ccfe0b611bb3","price":"0.96","side":"SELL","size":"578.09"}],"timestamp":"1785122402331"},"payload_hash":"10118c051218614e8c919cdb5a2186759dbd674d3e8ec1de09b02adf01284d4a","raw_frame":"{\"market\":\"0x717c0e8ccd4d5c7040185188fbae28be901ca589a11a94b1b38ca36a79eccfeb\", \"price_changes\":[{\"asset_id\":\"24254094493625419915756280046002869097156693848522361803041977572204227262166\", \"price\":\"0.04\", \"size\":\"578.09\", \"side\":\"BUY\", \"hash\":\"4cdf1cdfbc0838039b1a8b0110d680c8556a17a0\", \"best_bid\":\"0.46\", \"best_ask\":\"0.47\"}, {\"asset_id\":\"41448400836309843603620980831210604935021861034693225347475867885462478926555\", \"price\":\"0.96\", \"size\":\"578.09\", \"side\":\"SELL\", \"hash\":\"3e169d3f6fdb60106b6b59e7b625ccfe0b611bb3\", \"best_bid\":\"0.53\", \"best_ask\":\"0.54\"}], \"timestamp\":\"1785122402331\", \"event_type\":\"price_change\"}","received_at":"2026-07-27T03:20:02.215893Z","schema_version":"clob-market-ws.price_change.v1","sequence":null,"server_hash":null,"server_timestamp":"1785122402331","session_id":"dd162b8dca5f43ff811d304e69a06123","source":"clob_market_ws"},"received_at":"2026-07-27T03:20:02.215893Z","record_id":"c85aa94016f9784fcd8a1524061bed3d26a2a97756a3fd55eb264b78d422b82c","schema_fingerprint":"4aa3821a28b0b7c2400bc59aba4bcc0a76e971dadd19610d3ad38c768e124dc7","schema_version":"edge-lab-recorder.raw.v1","sequence":null,"source":"clob_market_ws"}
{"event_at":"2026-07-27T03:20:02.334000Z","event_fingerprint":"34eb5180b99ec92191792cd6dc4b14cfd3a21e07099cdfa9183dabab082aab92","payload":{"connection_id":"c7dc2e4762f849c6b6f9306b6518dcab","event_at":"2026-07-27T03:20:02.334000Z","event_type":"price_change","frame_hash":"5f060ad479af39413b19d2d019d767a6eebbf2f22700db8a2fb651be89d9345d","frame_index":0,"kind":"data","monotonic_ns":224385569240875,"payload":{"event_type":"price_change","market":"0x717c0e8ccd4d5c7040185188fbae28be901ca589a11a94b1b38ca36a79eccfeb","price_changes":[{"asset_id":"24254094493625419915756280046002869097156693848522361803041977572204227262166","best_ask":"0.47","best_bid":"0.46","hash":"9a78012991650852bb0f07fd5203630108b558c8","price":"0.05","side":"BUY","size":"568.2"},{"asset_id":"41448400836309843603620980831210604935021861034693225347475867885462478926555","best_ask":"0.54","best_bid":"0.53","hash":"c19dc4c0fbbfea5f96f3cb33411d86c1474fa925","price":"0.95","side":"SELL","size":"568.2"}],"timestamp":"1785122402334"},"payload_hash":"f1ee5aa821f0d2e8555d115f7bd74b1bd1433de44124964c0b59623c06dd854a","raw_frame":"{\"market\":\"0x717c0e8ccd4d5c7040185188fbae28be901ca589a11a94b1b38ca36a79eccfeb\", \"price_changes\":[{\"asset_id\":\"24254094493625419915756280046002869097156693848522361803041977572204227262166\", \"price\":\"0.05\", \"size\":\"568.2\", \"side\":\"BUY\", \"hash\":\"9a78012991650852bb0f07fd5203630108b558c8\", \"best_bid\":\"0.46\", \"best_ask\":\"0.47\"}, {\"asset_id\":\"41448400836309843603620980831210604935021861034693225347475867885462478926555\", \"price\":\"0.95\", \"size\":\"568.2\", \"side\":\"SELL\", \"hash\":\"c19dc4c0fbbfea5f96f3cb33411d86c1474fa925\", \"best_bid\":\"0.53\", \"best_ask\":\"0.54\"}], \"timestamp\":\"1785122402334\", \"event_type\":\"price_change\"}","received_at":"2026-07-27T03:20:02.217504Z","schema_version":"clob-market-ws.price_change.v1","sequence":null,"server_hash":null,"server_timestamp":"1785122402334","session_id":"dd162b8dca5f43ff811d304e69a06123","source":"clob_market_ws"},"received_at":"2026-07-27T03:20:02.217504Z","record_id":"22a4bb83d581f485f4399bf1f63b7c89014eb6bafaf0637d4423db84efa59e24","schema_fingerprint":"4aa3821a28b0b7c2400bc59aba4bcc0a76e971dadd19610d3ad38c768e124dc7","schema_version":"edge-lab-recorder.raw.v1","sequence":null,"source":"clob_market_ws"}
{"event_at":"2026-07-27T03:20:02.334000Z","event_fingerprint":"81e81dd31487363a5eb2514fc09f50719cdfd703ac400cd0228fec97dd8dc070","payload":{"connection_id":"c7dc2e4762f849c6b6f9306b6518dcab","event_at":"2026-07-27T03:20:02.334000Z","event_type":"price_change","frame_hash":"506ee981cf781f6893ff5032de4b08299448c67fd5a1093961beea0b061111d4","frame_index":0,"kind":"data","monotonic_ns":224385570728750,"payload":{"event_type":"price_change","market":"0x717c0e8ccd4d5c7040185188fbae28be901ca589a11a94b1b38ca36a79eccfeb","price_changes":[{"asset_id":"41448400836309843603620980831210604935021861034693225347475867885462478926555","best_ask":"0.54","best_bid":"0.53","hash":"1b1268dbd1ed8cf5210d90afa8616b736a907f60","price":"0.01","side":"BUY","size":"5708.02"},{"asset_id":"24254094493625419915756280046002869097156693848522361803041977572204227262166","best_ask":"0.47","best_bid":"0.46","hash":"ee27da4557988d6e933968c3709db63373c9d70e","price":"0.99","side":"SELL","size":"5708.02"}],"timestamp":"1785122402334"},"payload_hash":"ab76d56f4443a0614be9c2c2f6227fbee15c6c0cb31cea1b9158d5431ff7b5ba","raw_frame":"{\"market\":\"0x717c0e8ccd4d5c7040185188fbae28be901ca589a11a94b1b38ca36a79eccfeb\", \"price_changes\":[{\"asset_id\":\"41448400836309843603620980831210604935021861034693225347475867885462478926555\", \"price\":\"0.01\", \"size\":\"5708.02\", \"side\":\"BUY\", \"hash\":\"1b1268dbd1ed8cf5210d90afa8616b736a907f60\", \"best_bid\":\"0.53\", \"best_ask\":\"0.54\"}, {\"asset_id\":\"24254094493625419915756280046002869097156693848522361803041977572204227262166\", \"price\":\"0.99\", \"size\":\"5708.02\", \"side\":\"SELL\", \"hash\":\"ee27da4557988d6e933968c3709db63373c9d70e\", \"best_bid\":\"0.46\", \"best_ask\":\"0.47\"}], \"timestamp\":\"1785122402334\", \"event_type\":\"price_change\"}","received_at":"2026-07-27T03:20:02.218990Z","schema_version":"clob-market-ws.price_change.v1","sequence":null,"server_hash":null,"server_timestamp":"1785122402334","session_id":"dd162b8dca5f43ff811d304e69a06123","source":"clob_market_ws"},"received_at":"2026-07-27T03:20:02.218990Z","record_id":"69fdb98fba1796e11daf5f9564324f24039ed40d43fafb5663084ef0c8715aa8","schema_fingerprint":"4aa3821a28b0b7c2400bc59aba4bcc0a76e971dadd19610d3ad38c768e124dc7","schema_version":"edge-lab-recorder.raw.v1","sequence":null,"source":"clob_market_ws"}
{"event_at":"2026-07-27T03:20:02.360000Z","event_fingerprint":"8045c99c7845c813b1e021afb2577da62c87d9bcf3d9b88287b7d841def3afe7","payload":{"connection_id":"c7dc2e4762f849c6b6f9306b6518dcab","event_at":"2026-07-27T03:20:02.360000Z","event_type":"price_change","frame_hash":"01092ed1203fbc2f9e67c2f82f69fdca32f672067d0187933d9306358a59e241","frame_index":0,"kind":"data","monotonic_ns":224385596626916,"payload":{"event_type":"price_change","market":"0x717c0e8ccd4d5c7040185188fbae28be901ca589a11a94b1b38ca36a79eccfeb","price_changes":[{"asset_id":"41448400836309843603620980831210604935021861034693225347475867885462478926555","best_ask":"0.54","best_bid":"0.53","hash":"d75050b17147786f0c6258e003f55cd1e7c476aa","price":"0.04","side":"BUY","size":"578.09"},{"asset_id":"24254094493625419915756280046002869097156693848522361803041977572204227262166","best_ask":"0.47","best_bid":"0.46","hash":"0710fffbf80b52b61be637f57c80dafb63c3688d","price":"0.96","side":"SELL","size":"578.09"}],"timestamp":"1785122402360"},"payload_hash":"d19ce1707ce0015d7e9002692b9c1a8efaf56e085a29c23f926c214f6a76488b","raw_frame":"{\"market\":\"0x717c0e8ccd4d5c7040185188fbae28be901ca589a11a94b1b38ca36a79eccfeb\", \"price_changes\":[{\"asset_id\":\"41448400836309843603620980831210604935021861034693225347475867885462478926555\", \"price\":\"0.04\", \"size\":\"578.09\", \"side\":\"BUY\", \"hash\":\"d75050b17147786f0c6258e003f55cd1e7c476aa\", \"best_bid\":\"0.53\", \"best_ask\":\"0.54\"}, {\"asset_id\":\"24254094493625419915756280046002869097156693848522361803041977572204227262166\", \"price\":\"0.96\", \"size\":\"578.09\", \"side\":\"SELL\", \"hash\":\"0710fffbf80b52b61be637f57c80dafb63c3688d\", \"best_bid\":\"0.46\", \"best_ask\":\"0.47\"}], \"timestamp\":\"1785122402360\", \"event_type\":\"price_change\"}","received_at":"2026-07-27T03:20:02.244885Z","schema_version":"clob-market-ws.price_change.v1","sequence":null,"server_hash":null,"server_timestamp":"1785122402360","session_id":"dd162b8dca5f43ff811d304e69a06123","source":"clob_market_ws"},"received_at":"2026-07-27T03:20:02.244885Z","record_id":"6f032bc58d2d0aa13033a67f3995046f47c37ee791dd56f81e29d7ff879eb595","schema_fingerprint":"4aa3821a28b0b7c2400bc59aba4bcc0a76e971dadd19610d3ad38c768e124dc7","schema_version":"edge-lab-recorder.raw.v1","sequence":null,"source":"clob_market_ws"}
{"event_at":"2026-07-27T03:20:02.376000Z","event_fingerprint":"15556c13a081ab0a05d39a45737faa795c05e886a7de57543e3537ce9424df8f","payload":{"connection_id":"c7dc2e4762f849c6b6f9306b6518dcab","event_at":"2026-07-27T03:20:02.376000Z","event_type":"price_change","frame_hash":"c2815ee59f710cc1e7af0d970f1b7473af83e425fff52a8eac616fcc6a677063","frame_index":0,"kind":"data","monotonic_ns":224385613181791,"payload":{"event_type":"price_change","market":"0x717c0e8ccd4d5c7040185188fbae28be901ca589a11a94b1b38ca36a79eccfeb","price_changes":[{"asset_id":"41448400836309843603620980831210604935021861034693225347475867885462478926555","best_ask":"0.54","best_bid":"0.53","hash":"6eb50855949574c328ad4089713049500e22f84a","price":"0.01","side":"BUY","size":"5703.02"},{"asset_id":"24254094493625419915756280046002869097156693848522361803041977572204227262166","best_ask":"0.47","best_bid":"0.46","hash":"06356bb0e4b1b1d9e7a2502f1d25ab0ecd0113e9","price":"0.99","side":"SELL","size":"5703.02"}],"timestamp":"1785122402376"},"payload_hash":"1aa5f3b82881858aaac262b68f102e7ebd45b9a1104c54882644739622212639","raw_frame":"{\"market\":\"0x717c0e8ccd4d5c7040185188fbae28be901ca589a11a94b1b38ca36a79eccfeb\", \"price_changes\":[{\"asset_id\":\"41448400836309843603620980831210604935021861034693225347475867885462478926555\", \"price\":\"0.01\", \"size\":\"5703.02\", \"side\":\"BUY\", \"hash\":\"6eb50855949574c328ad4089713049500e22f84a\", \"best_bid\":\"0.53\", \"best_ask\":\"0.54\"}, {\"asset_id\":\"24254094493625419915756280046002869097156693848522361803041977572204227262166\", \"price\":\"0.99\", \"size\":\"5703.02\", \"side\":\"SELL\", \"hash\":\"06356bb0e4b1b1d9e7a2502f1d25ab0ecd0113e9\", \"best_bid\":\"0.46\", \"best_ask\":\"0.47\"}], \"timestamp\":\"1785122402376\", \"event_type\":\"price_change\"}","received_at":"2026-07-27T03:20:02.261436Z","schema_version":"clob-market-ws.price_change.v1","sequence":null,"server_hash":null,"server_timestamp":"1785122402376","session_id":"dd162b8dca5f43ff811d304e69a06123","source":"clob_market_ws"},"received_at":"2026-07-27T03:20:02.261436Z","record_id":"52a27a80957271fb89d597387e1c9bf17807b0cfeb03d5ae93e0c73588bbc98d","schema_fingerprint":"4aa3821a28b0b7c2400bc59aba4bcc0a76e971dadd19610d3ad38c768e124dc7","schema_version":"edge-lab-recorder.raw.v1","sequence":null,"source":"clob_market_ws"}
{"event_at":"2026-07-27T03:20:02.453000Z","event_fingerprint":"0e6df2c2d1206d63e89aac1d1c48081c6a0aaa32024247361d3fb73d1718087c","payload":{"connection_id":"c7dc2e4762f849c6b6f9306b6518dcab","event_at":"2026-07-27T03:20:02.453000Z","event_type":"price_change","frame_hash":"5149d47a879493e2245d006b42791edc1e476f0f37fcbb7020d7a054efde7b9d","frame_index":0,"kind":"data","monotonic_ns":224385688110291,"payload":{"event_type":"price_change","market":"0x717c0e8ccd4d5c7040185188fbae28be901ca589a11a94b1b38ca36a79eccfeb","price_changes":[{"asset_id":"41448400836309843603620980831210604935021861034693225347475867885462478926555","best_ask":"0.54","best_bid":"0.53","hash":"b2552c3b7a154499b9746ad83b3aa8818ba4f803","price":"0.01","side":"BUY","size":"5708.02"},{"asset_id":"24254094493625419915756280046002869097156693848522361803041977572204227262166","best_ask":"0.47","best_bid":"0.46","hash":"0a5254b28d15bc69ec4f7c046ea46b2dc7567b03","price":"0.99","side":"SELL","size":"5708.02"}],"timestamp":"1785122402453"},"payload_hash":"24831e1f32a144723b5bb2f2a73d53b1f95bda32dac8712e12042ba856a92764","raw_frame":"{\"market\":\"0x717c0e8ccd4d5c7040185188fbae28be901ca589a11a94b1b38ca36a79eccfeb\", \"price_changes\":[{\"asset_id\":\"41448400836309843603620980831210604935021861034693225347475867885462478926555\", \"price\":\"0.01\", \"size\":\"5708.02\", \"side\":\"BUY\", \"hash\":\"b2552c3b7a154499b9746ad83b3aa8818ba4f803\", \"best_bid\":\"0.53\", \"best_ask\":\"0.54\"}, {\"asset_id\":\"24254094493625419915756280046002869097156693848522361803041977572204227262166\", \"price\":\"0.99\", \"size\":\"5708.02\", \"side\":\"SELL\", \"hash\":\"0a5254b28d15bc69ec4f7c046ea46b2dc7567b03\", \"best_bid\":\"0.46\", \"best_ask\":\"0.47\"}], \"timestamp\":\"1785122402453\", \"event_type\":\"price_change\"}","received_at":"2026-07-27T03:20:02.336354Z","schema_version":"clob-market-ws.price_change.v1","sequence":null,"server_hash":null,"server_timestamp":"1785122402453","session_id":"dd162b8dca5f43ff811d304e69a06123","source":"clob_market_ws"},"received_at":"2026-07-27T03:20:02.336354Z","record_id":"97743b0690772158a59832d0483e96548e7456184d543891fb89a23fd1c71a5c","schema_fingerprint":"4aa3821a28b0b7c2400bc59aba4bcc0a76e971dadd19610d3ad38c768e124dc7","schema_version":"edge-lab-recorder.raw.v1","sequence":null,"source":"clob_market_ws"}
{"event_at":"2026-07-27T03:20:02.475000Z","event_fingerprint":"1c8a6226a16089ba2e7e17cc2574c9d30da492004963c27c966a02d4f3625060","payload":{"connection_id":"c7dc2e4762f849c6b6f9306b6518dcab","event_at":"2026-07-27T03:20:02.475000Z","event_type":"price_change","frame_hash":"993a445cd5543ddeeac071af0e14515c054930dc4768a1e84e941ba4762abe89","frame_index":0,"kind":"data","monotonic_ns":224385709547125,"payload":{"event_type":"price_change","market":"0x717c0e8ccd4d5c7040185188fbae28be901ca589a11a94b1b38ca36a79eccfeb","price_changes":[{"asset_id":"41448400836309843603620980831210604935021861034693225347475867885462478926555","best_ask":"0.54","best_bid":"0.53","hash":"a111088017c99191c3a427b7525eb018b70d08b5","price":"0.01","side":"BUY","size":"5703.02"},{"asset_id":"24254094493625419915756280046002869097156693848522361803041977572204227262166","best_ask":"0.47","best_bid":"0.46","hash":"99d811f46df9d5065938b8323a4b4627c1ac0337","price":"0.99","side":"SELL","size":"5703.02"}],"timestamp":"1785122402475"},"payload_hash":"74794dafdf581168932fcf8e4c537fc1a7aa4ab8fafddc45fc1fea6ddf33cb59","raw_frame":"{\"market\":\"0x717c0e8ccd4d5c7040185188fbae28be901ca589a11a94b1b38ca36a79eccfeb\", \"price_changes\":[{\"asset_id\":\"41448400836309843603620980831210604935021861034693225347475867885462478926555\", \"price\":\"0.01\", \"size\":\"5703.02\", \"side\":\"BUY\", \"hash\":\"a111088017c99191c3a427b7525eb018b70d08b5\", \"best_bid\":\"0.53\", \"best_ask\":\"0.54\"}, {\"asset_id\":\"24254094493625419915756280046002869097156693848522361803041977572204227262166\", \"price\":\"0.99\", \"size\":\"5703.02\", \"side\":\"SELL\", \"hash\":\"99d811f46df9d5065938b8323a4b4627c1ac0337\", \"best_bid\":\"0.46\", \"best_ask\":\"0.47\"}], \"timestamp\":\"1785122402475\", \"event_type\":\"price_change\"}","received_at":"2026-07-27T03:20:02.357785Z","schema_version":"clob-market-ws.price_change.v1","sequence":null,"server_hash":null,"server_timestamp":"1785122402475","session_id":"dd162b8dca5f43ff811d304e69a06123","source":"clob_market_ws"},"received_at":"2026-07-27T03:20:02.357785Z","record_id":"56161fb8433fe78476536010b66805d9aebd36fd74b5a9fc75359a5cacfdbdd8","schema_fingerprint":"4aa3821a28b0b7c2400bc59aba4bcc0a76e971dadd19610d3ad38c768e124dc7","schema_version":"edge-lab-recorder.raw.v1","sequence":null,"source":"clob_market_ws"}
{"event_at":"2026-07-27T03:20:02.480000Z","event_fingerprint":"6ee2731e25efec8b32b026c5f59a59f026adc0ed496c87c3fa2cd37a9ee52467","payload":{"connection_id":"c7dc2e4762f849c6b6f9306b6518dcab","event_at":"2026-07-27T03:20:02.480000Z","event_type":"price_change","frame_hash":"c42602e81158f527177d5155c3a2e38a35ed2bb8a5ee6ca5d018473b66c91827","frame_index":0,"kind":"data","monotonic_ns":224385718486375,"payload":{"event_type":"price_change","market":"0x717c0e8ccd4d5c7040185188fbae28be901ca589a11a94b1b38ca36a79eccfeb","price_changes":[{"asset_id":"41448400836309843603620980831210604935021861034693225347475867885462478926555","best_ask":"0.54","best_bid":"0.53","hash":"1e4a09b851e778662eeb8c76cc2bc2de36045f82","price":"0.03","side":"BUY","size":"618.1"},{"asset_id":"24254094493625419915756280046002869097156693848522361803041977572204227262166","best_ask":"0.47","best_bid":"0.46","hash":"33367792240ee9e7767ddfcc5d41bc553d94f7ef","price":"0.97","side":"SELL","size":"618.1"}],"timestamp":"1785122402480"},"payload_hash":"98f11adb5d5a6dc3902ba1c8d588fd55e196dc03c1a2ec4e26e523c64647eafa","raw_frame":"{\"market\":\"0x717c0e8ccd4d5c7040185188fbae28be901ca589a11a94b1b38ca36a79eccfeb\", \"price_changes\":[{\"asset_id\":\"41448400836309843603620980831210604935021861034693225347475867885462478926555\", \"price\":\"0.03\", \"size\":\"618.1\", \"side\":\"BUY\", \"hash\":\"1e4a09b851e778662eeb8c76cc2bc2de36045f82\", \"best_bid\":\"0.53\", \"best_ask\":\"0.54\"}, {\"asset_id\":\"24254094493625419915756280046002869097156693848522361803041977572204227262166\", \"price\":\"0.97\", \"size\":\"618.1\", \"side\":\"SELL\", \"hash\":\"33367792240ee9e7767ddfcc5d41bc553d94f7ef\", \"best_bid\":\"0.46\", \"best_ask\":\"0.47\"}], \"timestamp\":\"1785122402480\", \"event_type\":\"price_change\"}","received_at":"2026-07-27T03:20:02.366724Z","schema_version":"clob-market-ws.price_change.v1","sequence":null,"server_hash":null,"server_timestamp":"1785122402480","session_id":"dd162b8dca5f43ff811d304e69a06123","source":"clob_market_ws"},"received_at":"2026-07-27T03:20:02.366724Z","record_id":"27d0f58e8aa60c4cf5240f8d9d94041f3e75e8e9d3a9b0d8f952ed95389e0500","schema_fingerprint":"4aa3821a28b0b7c2400bc59aba4bcc0a76e971dadd19610d3ad38c768e124dc7","schema_version":"edge-lab-recorder.raw.v1","sequence":null,"source":"clob_market_ws"}
{"event_at":"2026-07-27T03:20:02.540000Z","event_fingerprint":"2fd4e569cb9b8e7aa2fd527d3ada5f4dd5b1dfe9a0b8df758c0f2eb3d14f12f2","payload":{"connection_id":"c7dc2e4762f849c6b6f9306b6518dcab","event_at":"2026-07-27T03:20:02.540000Z","event_type":"price_change","frame_hash":"455ef4967dd7f4cf7de348716c7b1c621027be188f8f49b1dcf0240e37d86360","frame_index":0,"kind":"data","monotonic_ns":224385776310500,"payload":{"event_type":"price_change","market":"0x717c0e8ccd4d5c7040185188fbae28be901ca589a11a94b1b38ca36a79eccfeb","price_changes":[{"asset_id":"24254094493625419915756280046002869097156693848522361803041977572204227262166","best_ask":"0.47","best_bid":"0.46","hash":"e4574b67ad9e8661fae02cd92dc7e2057da23ebc","price":"0.4","side":"BUY","size":"33"},{"asset_id":"41448400836309843603620980831210604935021861034693225347475867885462478926555","best_ask":"0.54","best_bid":"0.53","hash":"2f6bc6bc4648ad113e91a598a1932c7d0504f718","price":"0.6","side":"SELL","size":"33"}],"timestamp":"1785122402540"},"payload_hash":"6c80cf85b57858cfc44b31d3b7742a4e3b8e5150a8eebe63f7e2b5ab955d0ccf","raw_frame":"{\"market\":\"0x717c0e8ccd4d5c7040185188fbae28be901ca589a11a94b1b38ca36a79eccfeb\", \"price_changes\":[{\"asset_id\":\"24254094493625419915756280046002869097156693848522361803041977572204227262166\", \"price\":\"0.4\", \"size\":\"33\", \"side\":\"BUY\", \"hash\":\"e4574b67ad9e8661fae02cd92dc7e2057da23ebc\", \"best_bid\":\"0.46\", \"best_ask\":\"0.47\"}, {\"asset_id\":\"41448400836309843603620980831210604935021861034693225347475867885462478926555\", \"price\":\"0.6\", \"size\":\"33\", \"side\":\"SELL\", \"hash\":\"2f6bc6bc4648ad113e91a598a1932c7d0504f718\", \"best_bid\":\"0.53\", \"best_ask\":\"0.54\"}], \"timestamp\":\"1785122402540\", \"event_type\":\"price_change\"}","received_at":"2026-07-27T03:20:02.424539Z","schema_version":"clob-market-ws.price_change.v1","sequence":null,"server_hash":null,"server_timestamp":"1785122402540","session_id":"dd162b8dca5f43ff811d304e69a06123","source":"clob_market_ws"},"received_at":"2026-07-27T03:20:02.424539Z","record_id":"9da36ccb9b4adfb2ca9711587667b76f852be99a24bc99c7774b07cc1f1a6541","schema_fingerprint":"4aa3821a28b0b7c2400bc59aba4bcc0a76e971dadd19610d3ad38c768e124dc7","schema_version":"edge-lab-recorder.raw.v1","sequence":null,"source":"clob_market_ws"}
{"event_at":"2026-07-27T03:20:02.540000Z","event_fingerprint":"c050457db190d35c0f037de3c5ea8b09a5d9f1a2eba343dfb4e9f360348a8874","payload":{"connection_id":"c7dc2e4762f849c6b6f9306b6518dcab","event_at":"2026-07-27T03:20:02.540000Z","event_type":"price_change","frame_hash":"8e27fb74e94904a6481c193f6e7745cb25693828da71b6cafbe297908008c28e","frame_index":0,"kind":"data","monotonic_ns":224385778136000,"payload":{"event_type":"price_change","market":"0x717c0e8ccd4d5c7040185188fbae28be901ca589a11a94b1b38ca36a79eccfeb","price_changes":[{"asset_id":"41448400836309843603620980831210604935021861034693225347475867885462478926555","best_ask":"0.54","best_bid":"0.53","hash":"2f6bc6bc4648ad113e91a598a1932c7d0504f718","price":"0.48","side":"BUY","size":"51.4"},{"asset_id":"24254094493625419915756280046002869097156693848522361803041977572204227262166","best_ask":"0.47","best_bid":"0.46","hash":"e4574b67ad9e8661fae02cd92dc7e2057da23ebc","price":"0.52","side":"SELL","size":"51.4"}],"timestamp":"1785122402540"},"payload_hash":"fce402b438d6a15d497ddb4e2a14f66d28cfe8c66533d1d75af92bef37bedbab","raw_frame":"{\"market\":\"0x717c0e8ccd4d5c7040185188fbae28be901ca589a11a94b1b38ca36a79eccfeb\", \"price_changes\":[{\"asset_id\":\"41448400836309843603620980831210604935021861034693225347475867885462478926555\", \"price\":\"0.48\", \"size\":\"51.4\", \"side\":\"BUY\", \"hash\":\"2f6bc6bc4648ad113e91a598a1932c7d0504f718\", \"best_bid\":\"0.53\", \"best_ask\":\"0.54\"}, {\"asset_id\":\"24254094493625419915756280046002869097156693848522361803041977572204227262166\", \"price\":\"0.52\", \"size\":\"51.4\", \"side\":\"SELL\", \"hash\":\"e4574b67ad9e8661fae02cd92dc7e2057da23ebc\", \"best_bid\":\"0.46\", \"best_ask\":\"0.47\"}], \"timestamp\":\"1785122402540\", \"event_type\":\"price_change\"}","received_at":"2026-07-27T03:20:02.426364Z","schema_version":"clob-market-ws.price_change.v1","sequence":null,"server_hash":null,"server_timestamp":"1785122402540","session_id":"dd162b8dca5f43ff811d304e69a06123","source":"clob_market_ws"},"received_at":"2026-07-27T03:20:02.426364Z","record_id":"5db5767fd96b04c9e81e2af6d724824fecb8ad07548e35a3d1de93cf0d758ac8","schema_fingerprint":"4aa3821a28b0b7c2400bc59aba4bcc0a76e971dadd19610d3ad38c768e124dc7","schema_version":"edge-lab-recorder.raw.v1","sequence":null,"source":"clob_market_ws"}
{"event_at":"2026-07-27T03:20:02.547000Z","event_fingerprint":"cb3316bed2562a553ed68fc24b61ec2843d6e5a49c5216e56223866a2fe71e2a","payload":{"connection_id":"c7dc2e4762f849c6b6f9306b6518dcab","event_at":"2026-07-27T03:20:02.547000Z","event_type":"price_change","frame_hash":"5d86793101dfd72451db0133d491a21e14100a1b1a19aedc57b29f5f9b8d96b0","frame_index":0,"kind":"data","monotonic_ns":224385780327000,"payload":{"event_type":"price_change","market":"0x717c0e8ccd4d5c7040185188fbae28be901ca589a11a94b1b38ca36a79eccfeb","price_changes":[{"asset_id":"41448400836309843603620980831210604935021861034693225347475867885462478926555","best_ask":"0.54","best_bid":"0.53","hash":"b5b4870524967a50716b8e51fb8c7b4d419184c3","price":"0.44","side":"BUY","size":"28.16"},{"asset_id":"24254094493625419915756280046002869097156693848522361803041977572204227262166","best_ask":"0.47","best_bid":"0.46","hash":"ff85583435f777b5d4d287b5646a9d23861a2306","price":"0.56","side":"SELL","size":"28.16"}],"timestamp":"1785122402547"},"payload_hash":"2ac804420282906a4081f95a9a10d6edd4a5810058ac8bfb3fb44bbc78a77d58","raw_frame":"{\"market\":\"0x717c0e8ccd4d5c7040185188fbae28be901ca589a11a94b1b38ca36a79eccfeb\", \"price_changes\":[{\"asset_id\":\"41448400836309843603620980831210604935021861034693225347475867885462478926555\", \"price\":\"0.44\", \"size\":\"28.16\", \"side\":\"BUY\", \"hash\":\"b5b4870524967a50716b8e51fb8c7b4d419184c3\", \"best_bid\":\"0.53\", \"best_ask\":\"0.54\"}, {\"asset_id\":\"24254094493625419915756280046002869097156693848522361803041977572204227262166\", \"price\":\"0.56\", \"size\":\"28.16\", \"side\":\"SELL\", \"hash\":\"ff85583435f777b5d4d287b5646a9d23861a2306\", \"best_bid\":\"0.46\", \"best_ask\":\"0.47\"}], \"timestamp\":\"1785122402547\", \"event_type\":\"price_change\"}","received_at":"2026-07-27T03:20:02.428555Z","schema_version":"clob-market-ws.price_change.v1","sequence":null,"server_hash":null,"server_timestamp":"1785122402547","session_id":"dd162b8dca5f43ff811d304e69a06123","source":"clob_market_ws"},"received_at":"2026-07-27T03:20:02.428555Z","record_id":"6e63a3004e4c1f9ef6b9a918aaa7370b53c6b00dada72d7130a963e4afede673","schema_fingerprint":"4aa3821a28b0b7c2400bc59aba4bcc0a76e971dadd19610d3ad38c768e124dc7","schema_version":"edge-lab-recorder.raw.v1","sequence":null,"source":"clob_market_ws"}
{"event_at":"2026-07-27T03:20:02.547000Z","event_fingerprint":"10b97ff9180acc42b67f2b2a3ea97d8e26f355f86962ac4ae8cd3532b2ab64ff","payload":{"connection_id":"c7dc2e4762f849c6b6f9306b6518dcab","event_at":"2026-07-27T03:20:02.547000Z","event_type":"price_change","frame_hash":"c1ad29781e343fc07f0bf6586be32308212a4b430861e3763d426b1e7a549846","frame_index":0,"kind":"data","monotonic_ns":224385783429750,"payload":{"event_type":"price_change","market":"0x717c0e8ccd4d5c7040185188fbae28be901ca589a11a94b1b38ca36a79eccfeb","price_changes":[{"asset_id":"24254094493625419915756280046002869097156693848522361803041977572204227262166","best_ask":"0.47","best_bid":"0.46","hash":"75d2f216803defc6e2707ab37c77efcde28f70c5","price":"0.44","side":"BUY","size":"28.19"},{"asset_id":"41448400836309843603620980831210604935021861034693225347475867885462478926555","best_ask":"0.54","best_bid":"0.53","hash":"f87ef9097f1a4f94c1e0e02c3c1141a757f95669","price":"0.56","side":"SELL","size":"28.19"}],"timestamp":"1785122402547"},"payload_hash":"63d1e79438b6e22d5ddf5640c14091b80d083a3285b858f4aa18058f7db5ae1b","raw_frame":"{\"market\":\"0x717c0e8ccd4d5c7040185188fbae28be901ca589a11a94b1b38ca36a79eccfeb\", \"price_changes\":[{\"asset_id\":\"24254094493625419915756280046002869097156693848522361803041977572204227262166\", \"price\":\"0.44\", \"size\":\"28.19\", \"side\":\"BUY\", \"hash\":\"75d2f216803defc6e2707ab37c77efcde28f70c5\", \"best_bid\":\"0.46\", \"best_ask\":\"0.47\"}, {\"asset_id\":\"41448400836309843603620980831210604935021861034693225347475867885462478926555\", \"price\":\"0.56\", \"size\":\"28.19\", \"side\":\"SELL\", \"hash\":\"f87ef9097f1a4f94c1e0e02c3c1141a757f95669\", \"best_bid\":\"0.53\", \"best_ask\":\"0.54\"}], \"timestamp\":\"1785122402547\", \"event_type\":\"price_change\"}","received_at":"2026-07-27T03:20:02.431659Z","schema_version":"clob-market-ws.price_change.v1","sequence":null,"server_hash":null,"server_timestamp":"1785122402547","session_id":"dd162b8dca5f43ff811d304e69a06123","source":"clob_market_ws"},"received_at":"2026-07-27T03:20:02.431659Z","record_id":"f53426c8b2b6d51dbda66f1b2b113e263b04f65c2761dc10cfddfc32396c6f32","schema_fingerprint":"4aa3821a28b0b7c2400bc59aba4bcc0a76e971dadd19610d3ad38c768e124dc7","schema_version":"edge-lab-recorder.raw.v1","sequence":null,"source":"clob_market_ws"}
{"event_at":"2026-07-27T03:20:02.566000Z","event_fingerprint":"0ac5ae49515c995ee53bef363e08c8e97c16061483ab8d23c983185923b12cab","payload":{"connection_id":"c7dc2e4762f849c6b6f9306b6518dcab","event_at":"2026-07-27T03:20:02.566000Z","event_type":"price_change","frame_hash":"5fa578f5a5c28ffa8ffeb68042b2e0891438cbe854633f25c7faf374c70a97e6","frame_index":0,"kind":"data","monotonic_ns":224385801476083,"payload":{"event_type":"price_change","market":"0x717c0e8ccd4d5c7040185188fbae28be901ca589a11a94b1b38ca36a79eccfeb","price_changes":[{"asset_id":"41448400836309843603620980831210604935021861034693225347475867885462478926555","best_ask":"0.54","best_bid":"0.53","hash":"4ff35d5077fac8c288622c9e18444a176e79d259","price":"0.03","side":"BUY","size":"613.1"},{"asset_id":"24254094493625419915756280046002869097156693848522361803041977572204227262166","best_ask":"0.47","best_bid":"0.46","hash":"c9f947e67ba728cc9c528f0840de837f23e83ebf","price":"0.97","side":"SELL","size":"613.1"}],"timestamp":"1785122402566"},"payload_hash":"94cc81de10caf4695e17106cded3059642dce831dc4b10878f6817af1d1b24d7","raw_frame":"{\"market\":\"0x717c0e8ccd4d5c7040185188fbae28be901ca589a11a94b1b38ca36a79eccfeb\", \"price_changes\":[{\"asset_id\":\"41448400836309843603620980831210604935021861034693225347475867885462478926555\", \"price\":\"0.03\", \"size\":\"613.1\", \"side\":\"BUY\", \"hash\":\"4ff35d5077fac8c288622c9e18444a176e79d259\", \"best_bid\":\"0.53\", \"best_ask\":\"0.54\"}, {\"asset_id\":\"24254094493625419915756280046002869097156693848522361803041977572204227262166\", \"price\":\"0.97\", \"size\":\"613.1\", \"side\":\"SELL\", \"hash\":\"c9f947e67ba728cc9c528f0840de837f23e83ebf\", \"best_bid\":\"0.46\", \"best_ask\":\"0.47\"}], \"timestamp\":\"1785122402566\", \"event_type\":\"price_change\"}","received_at":"2026-07-27T03:20:02.449702Z","schema_version":"clob-market-ws.price_change.v1","sequence":null,"server_hash":null,"server_timestamp":"1785122402566","session_id":"dd162b8dca5f43ff811d304e69a06123","source":"clob_market_ws"},"received_at":"2026-07-27T03:20:02.449702Z","record_id":"67a95315373eb8f572dcf0d69597fc5079430210a8d74c1734261cdfb40aed3b","schema_fingerprint":"4aa3821a28b0b7c2400bc59aba4bcc0a76e971dadd19610d3ad38c768e124dc7","schema_version":"edge-lab-recorder.raw.v1","sequence":null,"source":"clob_market_ws"}
{"event_at":"2026-07-27T03:20:02.718000Z","event_fingerprint":"bf1544b5f09cfaa0d8d89fe08566ed7648c56d3773736a429109d68a784739dc","payload":{"connection_id":"c7dc2e4762f849c6b6f9306b6518dcab","event_at":"2026-07-27T03:20:02.718000Z","event_type":"price_change","frame_hash":"4ff3dad2875e35424ce204f4f14cbb356bccdb2744dd7551a08b544eb4e35bf3","frame_index":0,"kind":"data","monotonic_ns":224385952539625,"payload":{"event_type":"price_change","market":"0x717c0e8ccd4d5c7040185188fbae28be901ca589a11a94b1b38ca36a79eccfeb","price_changes":[{"asset_id":"41448400836309843603620980831210604935021861034693225347475867885462478926555","best_ask":"0.54","best_bid":"0.53","hash":"9006c48a0d02df399c8a84e92f1f502388f9ed14","price":"0.01","side":"BUY","size":"5708.02"},{"asset_id":"24254094493625419915756280046002869097156693848522361803041977572204227262166","best_ask":"0.47","best_bid":"0.46","hash":"43476d0479c21acaecd235f002dc79cf7bf458c1","price":"0.99","side":"SELL","size":"5708.02"}],"timestamp":"1785122402718"},"payload_hash":"2af8ce08e7f68a0b7a736b30cbc014cb80808bae51b3aa808d7190a5d2853599","raw_frame":"{\"market\":\"0x717c0e8ccd4d5c7040185188fbae28be901ca589a11a94b1b38ca36a79eccfeb\", \"price_changes\":[{\"asset_id\":\"41448400836309843603620980831210604935021861034693225347475867885462478926555\", \"price\":\"0.01\", \"size\":\"5708.02\", \"side\":\"BUY\", \"hash\":\"9006c48a0d02df399c8a84e92f1f502388f9ed14\", \"best_bid\":\"0.53\", \"best_ask\":\"0.54\"}, {\"asset_id\":\"24254094493625419915756280046002869097156693848522361803041977572204227262166\", \"price\":\"0.99\", \"size\":\"5708.02\", \"side\":\"SELL\", \"hash\":\"43476d0479c21acaecd235f002dc79cf7bf458c1\", \"best_bid\":\"0.46\", \"best_ask\":\"0.47\"}], \"timestamp\":\"1785122402718\", \"event_type\":\"price_change\"}","received_at":"2026-07-27T03:20:02.600743Z","schema_version":"clob-market-ws.price_change.v1","sequence":null,"server_hash":null,"server_timestamp":"1785122402718","session_id":"dd162b8dca5f43ff811d304e69a06123","source":"clob_market_ws"},"received_at":"2026-07-27T03:20:02.600743Z","record_id":"5a35128ca5eab9f0c5f630546e69c72a6753c641ea09a68ef48123195f5a41d7","schema_fingerprint":"4aa3821a28b0b7c2400bc59aba4bcc0a76e971dadd19610d3ad38c768e124dc7","schema_version":"edge-lab-recorder.raw.v1","sequence":null,"source":"clob_market_ws"}
{"event_at":"2026-07-27T03:20:02.824000Z","event_fingerprint":"5c5960849adb769dc95cc3a89f4bcd11091f39a16f8dcf77b06718a6e4986e20","payload":{"connection_id":"c7dc2e4762f849c6b6f9306b6518dcab","event_at":"2026-07-27T03:20:02.824000Z","event_type":"price_change","frame_hash":"0c1e5fe5d61680099717425593888143e810cb80b9afc93ac3a5c6503a581bc5","frame_index":0,"kind":"data","monotonic_ns":224386057741583,"payload":{"event_type":"price_change","market":"0x717c0e8ccd4d5c7040185188fbae28be901ca589a11a94b1b38ca36a79eccfeb","price_changes":[{"asset_id":"41448400836309843603620980831210604935021861034693225347475867885462478926555","best_ask":"0.54","best_bid":"0.53","hash":"8cda1fdfc7db354809037b3caf62d1a6b7e99bd0","price":"0.01","side":"BUY","size":"5703.02"},{"asset_id":"24254094493625419915756280046002869097156693848522361803041977572204227262166","best_ask":"0.47","best_bid":"0.46","hash":"bddd5b9bbf4867f9fbc4f5f309ff09e16cc9b854","price":"0.99","side":"SELL","size":"5703.02"}],"timestamp":"1785122402824"},"payload_hash":"cad8d18064302a8b2c47d71f881592ad64c1bde178a8c75d6bf0e8e87599b9e4","raw_frame":"{\"market\":\"0x717c0e8ccd4d5c7040185188fbae28be901ca589a11a94b1b38ca36a79eccfeb\", \"price_changes\":[{\"asset_id\":\"41448400836309843603620980831210604935021861034693225347475867885462478926555\", \"price\":\"0.01\", \"size\":\"5703.02\", \"side\":\"BUY\", \"hash\":\"8cda1fdfc7db354809037b3caf62d1a6b7e99bd0\", \"best_bid\":\"0.53\", \"best_ask\":\"0.54\"}, {\"asset_id\":\"24254094493625419915756280046002869097156693848522361803041977572204227262166\", \"price\":\"0.99\", \"size\":\"5703.02\", \"side\":\"SELL\", \"hash\":\"bddd5b9bbf4867f9fbc4f5f309ff09e16cc9b854\", \"best_bid\":\"0.46\", \"best_ask\":\"0.47\"}], \"timestamp\":\"1785122402824\", \"event_type\":\"price_change\"}","received_at":"2026-07-27T03:20:02.705929Z","schema_version":"clob-market-ws.price_change.v1","sequence":null,"server_hash":null,"server_timestamp":"1785122402824","session_id":"dd162b8dca5f43ff811d304e69a06123","source":"clob_market_ws"},"received_at":"2026-07-27T03:20:02.705929Z","record_id":"e033bba6216d7989840dba74e3d2c5d5b53786260620dda766bc8953b0e1d97d","schema_fingerprint":"4aa3821a28b0b7c2400bc59aba4bcc0a76e971dadd19610d3ad38c768e124dc7","schema_version":"edge-lab-recorder.raw.v1","sequence":null,"source":"clob_market_ws"}
{"event_at":"2026-07-27T03:20:02.854000Z","event_fingerprint":"030ad1d81c6b9618c82c1172ddcc40f4bf0d83d8eb648b3ede805d9c67cb8236","payload":{"connection_id":"c7dc2e4762f849c6b6f9306b6518dcab","event_at":"2026-07-27T03:20:02.854000Z","event_type":"price_change","frame_hash":"c7645c786264df7e5f6fb08e881923528e39afa4b059287be0457fde1e8fc0e6","frame_index":0,"kind":"data","monotonic_ns":224386090076541,"payload":{"event_type":"price_change","market":"0x717c0e8ccd4d5c7040185188fbae28be901ca589a11a94b1b38ca36a79eccfeb","price_changes":[{"asset_id":"41448400836309843603620980831210604935021861034693225347475867885462478926555","best_ask":"0.54","best_bid":"0.53","hash":"1d22522c0535fab3c51ee81957bc8735a154433e","price":"0.01","side":"BUY","size":"5708.02"},{"asset_id":"24254094493625419915756280046002869097156693848522361803041977572204227262166","best_ask":"0.47","best_bid":"0.46","hash":"22a265069618d1d28b8dc82feaa5421ee841b670","price":"0.99","side":"SELL","size":"5708.02"}],"timestamp":"1785122402854"},"payload_hash":"ca001b454c23fc4010ec10ee7051d74f21eb43f7cbed04576fb5f8b64b8fc06b","raw_frame":"{\"market\":\"0x717c0e8ccd4d5c7040185188fbae28be901ca589a11a94b1b38ca36a79eccfeb\", \"price_changes\":[{\"asset_id\":\"41448400836309843603620980831210604935021861034693225347475867885462478926555\", \"price\":\"0.01\", \"size\":\"5708.02\", \"side\":\"BUY\", \"hash\":\"1d22522c0535fab3c51ee81957bc8735a154433e\", \"best_bid\":\"0.53\", \"best_ask\":\"0.54\"}, {\"asset_id\":\"24254094493625419915756280046002869097156693848522361803041977572204227262166\", \"price\":\"0.99\", \"size\":\"5708.02\", \"side\":\"SELL\", \"hash\":\"22a265069618d1d28b8dc82feaa5421ee841b670\", \"best_bid\":\"0.46\", \"best_ask\":\"0.47\"}], \"timestamp\":\"1785122402854\", \"event_type\":\"price_change\"}","received_at":"2026-07-27T03:20:02.738263Z","schema_version":"clob-market-ws.price_change.v1","sequence":null,"server_hash":null,"server_timestamp":"1785122402854","session_id":"dd162b8dca5f43ff811d304e69a06123","source":"clob_market_ws"},"received_at":"2026-07-27T03:20:02.738263Z","record_id":"dc410c926f591d609f9850c6b4f5f7fcf6167c4f3cef4e394d0dc05d22e2752f","schema_fingerprint":"4aa3821a28b0b7c2400bc59aba4bcc0a76e971dadd19610d3ad38c768e124dc7","schema_version":"edge-lab-recorder.raw.v1","sequence":null,"source":"clob_market_ws"}
{"event_at":"2026-07-27T03:20:02.859000Z","event_fingerprint":"7a356e14f9daf3e2032c890159a0e5fbfc3d54d2273c34c23edfb1ec14567b92","payload":{"connection_id":"c7dc2e4762f849c6b6f9306b6518dcab","event_at":"2026-07-27T03:20:02.859000Z","event_type":"price_change","frame_hash":"fb4fc4f95e0932a1fa62c502fdf5ef1ef68cf943396c28611fe5d3034a82a647","frame_index":0,"kind":"data","monotonic_ns":224386094877666,"payload":{"event_type":"price_change","market":"0x717c0e8ccd4d5c7040185188fbae28be901ca589a11a94b1b38ca36a79eccfeb","price_changes":[{"asset_id":"41448400836309843603620980831210604935021861034693225347475867885462478926555","best_ask":"0.54","best_bid":"0.53","hash":"db1874e5c1c7f4cc47afd1c13bbba529430f850c","price":"0.01","side":"BUY","size":"5713.02"},{"asset_id":"24254094493625419915756280046002869097156693848522361803041977572204227262166","best_ask":"0.47","best_bid":"0.46","hash":"fa5fdfa638987d9eded2f665e9b033e82a39b1f2","price":"0.99","side":"SELL","size":"5713.02"}],"timestamp":"1785122402859"},"payload_hash":"64f2e14694c3ea52790db561cb298cf5eaecad60be70cac6876100d272fb3717","raw_frame":"{\"market\":\"0x717c0e8ccd4d5c7040185188fbae28be901ca589a11a94b1b38ca36a79eccfeb\", \"price_changes\":[{\"asset_id\":\"41448400836309843603620980831210604935021861034693225347475867885462478926555\", \"price\":\"0.01\", \"size\":\"5713.02\", \"side\":\"BUY\", \"hash\":\"db1874e5c1c7f4cc47afd1c13bbba529430f850c\", \"best_bid\":\"0.53\", \"best_ask\":\"0.54\"}, {\"asset_id\":\"24254094493625419915756280046002869097156693848522361803041977572204227262166\", \"price\":\"0.99\", \"size\":\"5713.02\", \"side\":\"SELL\", \"hash\":\"fa5fdfa638987d9eded2f665e9b033e82a39b1f2\", \"best_bid\":\"0.46\", \"best_ask\":\"0.47\"}], \"timestamp\":\"1785122402859\", \"event_type\":\"price_change\"}","received_at":"2026-07-27T03:20:02.743063Z","schema_version":"clob-market-ws.price_change.v1","sequence":null,"server_hash":null,"server_timestamp":"1785122402859","session_id":"dd162b8dca5f43ff811d304e69a06123","source":"clob_market_ws"},"received_at":"2026-07-27T03:20:02.743063Z","record_id":"601f5b57f8dc7b9b2cd083da5c4d35769bb80291313ab8eaf8435216c3b2dc83","schema_fingerprint":"4aa3821a28b0b7c2400bc59aba4bcc0a76e971dadd19610d3ad38c768e124dc7","schema_version":"edge-lab-recorder.raw.v1","sequence":null,"source":"clob_market_ws"}
{"event_at":"2026-07-27T03:20:02.877000Z","event_fingerprint":"b6ab0356e4e6a12b06a42e4e1bd998823f732e5055586711199ab328cff93780","payload":{"connection_id":"c7dc2e4762f849c6b6f9306b6518dcab","event_at":"2026-07-27T03:20:02.877000Z","event_type":"price_change","frame_hash":"22e8d084473738bacba62a8247120cb97c235c3939441dbe7ea99d5bcaf7a29b","frame_index":0,"kind":"data","monotonic_ns":224386113758916,"payload":{"event_type":"price_change","market":"0x717c0e8ccd4d5c7040185188fbae28be901ca589a11a94b1b38ca36a79eccfeb","price_changes":[{"asset_id":"41448400836309843603620980831210604935021861034693225347475867885462478926555","best_ask":"0.54","best_bid":"0.53","hash":"4115285ad0b08e6d9098666cb21edbddbf5fa675","price":"0.53","side":"BUY","size":"81.28"},{"asset_id":"24254094493625419915756280046002869097156693848522361803041977572204227262166","best_ask":"0.47","best_bid":"0.46","hash":"0278f7c0a2a46c703028a4b230876177d9da7dfd","price":"0.47","side":"SELL","size":"81.28"}],"timestamp":"1785122402877"},"payload_hash":"6f18720f1d6c29a98c34dda8684861e147e536a6fa98ba073948abe4fd2ce665","raw_frame":"{\"market\":\"0x717c0e8ccd4d5c7040185188fbae28be901ca589a11a94b1b38ca36a79eccfeb\", \"price_changes\":[{\"asset_id\":\"41448400836309843603620980831210604935021861034693225347475867885462478926555\", \"price\":\"0.53\", \"size\":\"81.28\", \"side\":\"BUY\", \"hash\":\"4115285ad0b08e6d9098666cb21edbddbf5fa675\", \"best_bid\":\"0.53\", \"best_ask\":\"0.54\"}, {\"asset_id\":\"24254094493625419915756280046002869097156693848522361803041977572204227262166\", \"price\":\"0.47\", \"size\":\"81.28\", \"side\":\"SELL\", \"hash\":\"0278f7c0a2a46c703028a4b230876177d9da7dfd\", \"best_bid\":\"0.46\", \"best_ask\":\"0.47\"}], \"timestamp\":\"1785122402877\", \"event_type\":\"price_change\"}","received_at":"2026-07-27T03:20:02.761940Z","schema_version":"clob-market-ws.price_change.v1","sequence":null,"server_hash":null,"server_timestamp":"1785122402877","session_id":"dd162b8dca5f43ff811d304e69a06123","source":"clob_market_ws"},"received_at":"2026-07-27T03:20:02.761940Z","record_id":"10cb3f90881c539100a75ff97cfc4c168d4ac6e511091c307fbd933d9dae106f","schema_fingerprint":"4aa3821a28b0b7c2400bc59aba4bcc0a76e971dadd19610d3ad38c768e124dc7","schema_version":"edge-lab-recorder.raw.v1","sequence":null,"source":"clob_market_ws"}
{"event_at":"2026-07-27T03:20:02.878000Z","event_fingerprint":"3012ed1faa668db1bc6c977fd79dc34067a11449da087e471282b298ba623a12","payload":{"connection_id":"c7dc2e4762f849c6b6f9306b6518dcab","event_at":"2026-07-27T03:20:02.878000Z","event_type":"price_change","frame_hash":"7ae1b0d1b30d49a97f8fff32d2892e2475ce84e556ab0eb64bae3a2fcbc2f59e","frame_index":0,"kind":"data","monotonic_ns":224386117111125,"payload":{"event_type":"price_change","market":"0x717c0e8ccd4d5c7040185188fbae28be901ca589a11a94b1b38ca36a79eccfeb","price_changes":[{"asset_id":"24254094493625419915756280046002869097156693848522361803041977572204227262166","best_ask":"0.47","best_bid":"0.46","hash":"17ba10d79b435e3b4814b021ead12a33efbbefa7","price":"0.47","side":"SELL","size":"69.28"},{"asset_id":"41448400836309843603620980831210604935021861034693225347475867885462478926555","best_ask":"0.54","best_bid":"0.53","hash":"2571d25730b25e444f74dd6d096fb1aedd5d95c9","price":"0.53","side":"BUY","size":"69.28"}],"timestamp":"1785122402878"},"payload_hash":"cd5c29e2c3da4b3d2544dd86a89d10b23cf410272b514e8037ade08891ac25f9","raw_frame":"{\"market\":\"0x717c0e8ccd4d5c7040185188fbae28be901ca589a11a94b1b38ca36a79eccfeb\", \"price_changes\":[{\"asset_id\":\"24254094493625419915756280046002869097156693848522361803041977572204227262166\", \"price\":\"0.47\", \"size\":\"69.28\", \"side\":\"SELL\", \"hash\":\"17ba10d79b435e3b4814b021ead12a33efbbefa7\", \"best_bid\":\"0.46\", \"best_ask\":\"0.47\"}, {\"asset_id\":\"41448400836309843603620980831210604935021861034693225347475867885462478926555\", \"price\":\"0.53\", \"size\":\"69.28\", \"side\":\"BUY\", \"hash\":\"2571d25730b25e444f74dd6d096fb1aedd5d95c9\", \"best_bid\":\"0.53\", \"best_ask\":\"0.54\"}], \"timestamp\":\"1785122402878\", \"event_type\":\"price_change\"}","received_at":"2026-07-27T03:20:02.765292Z","schema_version":"clob-market-ws.price_change.v1","sequence":null,"server_hash":null,"server_timestamp":"1785122402878","session_id":"dd162b8dca5f43ff811d304e69a06123","source":"clob_market_ws"},"received_at":"2026-07-27T03:20:02.765292Z","record_id":"25a4e688b94043e8e18af180839d5b38b1ba7020650abd6ca73b00df213c12a4","schema_fingerprint":"4aa3821a28b0b7c2400bc59aba4bcc0a76e971dadd19610d3ad38c768e124dc7","schema_version":"edge-lab-recorder.raw.v1","sequence":null,"source":"clob_market_ws"}
{"event_at":"2026-07-27T03:20:02.880000Z","event_fingerprint":"a163f816f575196746b53eabdbc1c12af975f993e81206434a9203f2374eddb5","payload":{"connection_id":"c7dc2e4762f849c6b6f9306b6518dcab","event_at":"2026-07-27T03:20:02.880000Z","event_type":"price_change","frame_hash":"6aebc8c1174ae5372e31524106554b9fdb4e1b32dbc42e65d73c53cea0b6899b","frame_index":0,"kind":"data","monotonic_ns":224386120141125,"payload":{"event_type":"price_change","market":"0x717c0e8ccd4d5c7040185188fbae28be901ca589a11a94b1b38ca36a79eccfeb","price_changes":[{"asset_id":"24254094493625419915756280046002869097156693848522361803041977572204227262166","best_ask":"0.47","best_bid":"0.46","hash":"0f1d1b67300031d520b017b4e38b021549c06f3d","price":"0.47","side":"SELL","size":"62.28"},{"asset_id":"41448400836309843603620980831210604935021861034693225347475867885462478926555","best_ask":"0.54","best_bid":"0.53","hash":"b03d396cecc8d13036277b959b7d7d23a205e6b6","price":"0.53","side":"BUY","size":"62.28"}],"timestamp":"1785122402880"},"payload_hash":"6f2e69f4d4bef129f945a7e4bf72aa1ec57bbc58d0d1aa95bf2a2f6029a39040","raw_frame":"{\"market\":\"0x717c0e8ccd4d5c7040185188fbae28be901ca589a11a94b1b38ca36a79eccfeb\", \"price_changes\":[{\"asset_id\":\"24254094493625419915756280046002869097156693848522361803041977572204227262166\", \"price\":\"0.47\", \"size\":\"62.28\", \"side\":\"SELL\", \"hash\":\"0f1d1b67300031d520b017b4e38b021549c06f3d\", \"best_bid\":\"0.46\", \"best_ask\":\"0.47\"}, {\"asset_id\":\"41448400836309843603620980831210604935021861034693225347475867885462478926555\", \"price\":\"0.53\", \"size\":\"62.28\", \"side\":\"BUY\", \"hash\":\"b03d396cecc8d13036277b959b7d7d23a205e6b6\", \"best_bid\":\"0.53\", \"best_ask\":\"0.54\"}], \"timestamp\":\"1785122402880\", \"event_type\":\"price_change\"}","received_at":"2026-07-27T03:20:02.768323Z","schema_version":"clob-market-ws.price_change.v1","sequence":null,"server_hash":null,"server_timestamp":"1785122402880","session_id":"dd162b8dca5f43ff811d304e69a06123","source":"clob_market_ws"},"received_at":"2026-07-27T03:20:02.768323Z","record_id":"8a03be564b0b439573796443155d5aa639b1c472dbfa93690771aea2ece78d48","schema_fingerprint":"4aa3821a28b0b7c2400bc59aba4bcc0a76e971dadd19610d3ad38c768e124dc7","schema_version":"edge-lab-recorder.raw.v1","sequence":null,"source":"clob_market_ws"}
{"event_at":"2026-07-27T03:20:02.880000Z","event_fingerprint":"99e1673fbcec0ee3f50cd1631ab23b88d44f1aa16bcdb8af10f0c00acb3bb3c6","payload":{"connection_id":"c7dc2e4762f849c6b6f9306b6518dcab","event_at":"2026-07-27T03:20:02.880000Z","event_type":"price_change","frame_hash":"5291a47f0ddf81223d9dbed8c8af32926010fcdecdcc618944d1ed7212ae58c6","frame_index":0,"kind":"data","monotonic_ns":224386123223541,"payload":{"event_type":"price_change","market":"0x717c0e8ccd4d5c7040185188fbae28be901ca589a11a94b1b38ca36a79eccfeb","price_changes":[{"asset_id":"41448400836309843603620980831210604935021861034693225347475867885462478926555","best_ask":"0.54","best_bid":"0.53","hash":"c9df4d8057ab083eb02ecd2f6d54791a24543253","price":"0.01","side":"BUY","size":"5708.02"},{"asset_id":"24254094493625419915756280046002869097156693848522361803041977572204227262166","best_ask":"0.47","best_bid":"0.46","hash":"5544bd20b7f34f4947275aced091bd241d609a28","price":"0.99","side":"SELL","size":"5708.02"}],"timestamp":"1785122402880"},"payload_hash":"e604433862b0fbd52fb63d2dbbddf6954ca4ebe99afcd0b69d1f19c9fe17798b","raw_frame":"{\"market\":\"0x717c0e8ccd4d5c7040185188fbae28be901ca589a11a94b1b38ca36a79eccfeb\", \"price_changes\":[{\"asset_id\":\"41448400836309843603620980831210604935021861034693225347475867885462478926555\", \"price\":\"0.01\", \"size\":\"5708.02\", \"side\":\"BUY\", \"hash\":\"c9df4d8057ab083eb02ecd2f6d54791a24543253\", \"best_bid\":\"0.53\", \"best_ask\":\"0.54\"}, {\"asset_id\":\"24254094493625419915756280046002869097156693848522361803041977572204227262166\", \"price\":\"0.99\", \"size\":\"5708.02\", \"side\":\"SELL\", \"hash\":\"5544bd20b7f34f4947275aced091bd241d609a28\", \"best_bid\":\"0.46\", \"best_ask\":\"0.47\"}], \"timestamp\":\"1785122402880\", \"event_type\":\"price_change\"}","received_at":"2026-07-27T03:20:02.771405Z","schema_version":"clob-market-ws.price_change.v1","sequence":null,"server_hash":null,"server_timestamp":"1785122402880","session_id":"dd162b8dca5f43ff811d304e69a06123","source":"clob_market_ws"},"received_at":"2026-07-27T03:20:02.771405Z","record_id":"d88c815bab4d6b4a33ebed43f98b7f40d77551bb6dbea4ac25e689677d30628d","schema_fingerprint":"4aa3821a28b0b7c2400bc59aba4bcc0a76e971dadd19610d3ad38c768e124dc7","schema_version":"edge-lab-recorder.raw.v1","sequence":null,"source":"clob_market_ws"}
{"event_at":"2026-07-27T03:20:02.883000Z","event_fingerprint":"5fb1492d42f496f1c5dc6f4a7c9dbd7f88edfbf9f057bc95ad53efe1b2bda542","payload":{"connection_id":"c7dc2e4762f849c6b6f9306b6518dcab","event_at":"2026-07-27T03:20:02.883000Z","event_type":"price_change","frame_hash":"d77dc3590a8816ba8e12f8f48d365d6e57e9d3b0e3c45cbb10aaeb8cda2e14c0","frame_index":0,"kind":"data","monotonic_ns":224386127369833,"payload":{"event_type":"price_change","market":"0x717c0e8ccd4d5c7040185188fbae28be901ca589a11a94b1b38ca36a79eccfeb","price_changes":[{"asset_id":"41448400836309843603620980831210604935021861034693225347475867885462478926555","best_ask":"0.54","best_bid":"0.53","hash":"6e8273d6629f39694eee11059794beebe0cda239","price":"0.53","side":"BUY","size":"37.28"},{"asset_id":"24254094493625419915756280046002869097156693848522361803041977572204227262166","best_ask":"0.47","best_bid":"0.46","hash":"6e29b90f9c19d75124829c89767d8f5a8ab8caf0","price":"0.47","side":"SELL","size":"37.28"}],"timestamp":"1785122402883"},"payload_hash":"659a04f1093e668505a7636d4c83b715fc0dac60325b7514b18d227ecb49b3e9","raw_frame":"{\"market\":\"0x717c0e8ccd4d5c7040185188fbae28be901ca589a11a94b1b38ca36a79eccfeb\", \"price_changes\":[{\"asset_id\":\"41448400836309843603620980831210604935021861034693225347475867885462478926555\", \"price\":\"0.53\", \"size\":\"37.28\", \"side\":\"BUY\", \"hash\":\"6e8273d6629f39694eee11059794beebe0cda239\", \"best_bid\":\"0.53\", \"best_ask\":\"0.54\"}, {\"asset_id\":\"24254094493625419915756280046002869097156693848522361803041977572204227262166\", \"price\":\"0.47\", \"size\":\"37.28\", \"side\":\"SELL\", \"hash\":\"6e29b90f9c19d75124829c89767d8f5a8ab8caf0\", \"best_bid\":\"0.46\", \"best_ask\":\"0.47\"}], \"timestamp\":\"1785122402883\", \"event_type\":\"price_change\"}","received_at":"2026-07-27T03:20:02.775542Z","schema_version":"clob-market-ws.price_change.v1","sequence":null,"server_hash":null,"server_timestamp":"1785122402883","session_id":"dd162b8dca5f43ff811d304e69a06123","source":"clob_market_ws"},"received_at":"2026-07-27T03:20:02.775542Z","record_id":"d2c9117ff59911a303f8bd4635e9c5449d59c737f4034a2217f36b8fe08b14e9","schema_fingerprint":"4aa3821a28b0b7c2400bc59aba4bcc0a76e971dadd19610d3ad38c768e124dc7","schema_version":"edge-lab-recorder.raw.v1","sequence":null,"source":"clob_market_ws"}
{"event_at":"2026-07-27T03:20:02.884000Z","event_fingerprint":"2864451368eb3fc0ce41cfb9ae9b10bd52f622b5535b15c7bbc4a6e0ba45da5a","payload":{"connection_id":"c7dc2e4762f849c6b6f9306b6518dcab","event_at":"2026-07-27T03:20:02.884000Z","event_type":"price_change","frame_hash":"8549a1c30029a62b55b949641419000fb7651527c5ffd4bf5e2e2b061b8c4d55","frame_index":0,"kind":"data","monotonic_ns":224386131203875,"payload":{"event_type":"price_change","market":"0x717c0e8ccd4d5c7040185188fbae28be901ca589a11a94b1b38ca36a79eccfeb","price_changes":[{"asset_id":"41448400836309843603620980831210604935021861034693225347475867885462478926555","best_ask":"0.54","best_bid":"0.53","hash":"98ea48a29b7c6156530c6916066c7449e17eed27","price":"0.58","side":"SELL","size":"54.29"},{"asset_id":"24254094493625419915756280046002869097156693848522361803041977572204227262166","best_ask":"0.47","best_bid":"0.46","hash":"544fc46433e19a5cde5e57f28df43668fa235189","price":"0.42","side":"BUY","size":"54.29"}],"timestamp":"1785122402884"},"payload_hash":"e5f4932714c21895bcdfa48e6f697d6e5fb32f3d2a1622f61fd360ed17feffdf","raw_frame":"{\"market\":\"0x717c0e8ccd4d5c7040185188fbae28be901ca589a11a94b1b38ca36a79eccfeb\", \"price_changes\":[{\"asset_id\":\"41448400836309843603620980831210604935021861034693225347475867885462478926555\", \"price\":\"0.58\", \"size\":\"54.29\", \"side\":\"SELL\", \"hash\":\"98ea48a29b7c6156530c6916066c7449e17eed27\", \"best_bid\":\"0.53\", \"best_ask\":\"0.54\"}, {\"asset_id\":\"24254094493625419915756280046002869097156693848522361803041977572204227262166\", \"price\":\"0.42\", \"size\":\"54.29\", \"side\":\"BUY\", \"hash\":\"544fc46433e19a5cde5e57f28df43668fa235189\", \"best_bid\":\"0.46\", \"best_ask\":\"0.47\"}], \"timestamp\":\"1785122402884\", \"event_type\":\"price_change\"}","received_at":"2026-07-27T03:20:02.779385Z","schema_version":"clob-market-ws.price_change.v1","sequence":null,"server_hash":null,"server_timestamp":"1785122402884","session_id":"dd162b8dca5f43ff811d304e69a06123","source":"clob_market_ws"},"received_at":"2026-07-27T03:20:02.779385Z","record_id":"92eff9fe521b8277ece82e7c54799e2ae24a522be2cd48da770f1351975ec10f","schema_fingerprint":"4aa3821a28b0b7c2400bc59aba4bcc0a76e971dadd19610d3ad38c768e124dc7","schema_version":"edge-lab-recorder.raw.v1","sequence":null,"source":"clob_market_ws"}
{"event_at":"2026-07-27T03:20:02.885000Z","event_fingerprint":"58a3268b7a38447cf337c0f08b5fdd2ce3676697cfbcfa8e8562f1643da17ef9","payload":{"connection_id":"c7dc2e4762f849c6b6f9306b6518dcab","event_at":"2026-07-27T03:20:02.885000Z","event_type":"price_change","frame_hash":"1c15b913e390ad21dec5c0a50a7f8931faaa95d580d354684929f7ff8b15c30d","frame_index":0,"kind":"data","monotonic_ns":224386134414375,"payload":{"event_type":"price_change","market":"0x717c0e8ccd4d5c7040185188fbae28be901ca589a11a94b1b38ca36a79eccfeb","price_changes":[{"asset_id":"41448400836309843603620980831210604935021861034693225347475867885462478926555","best_ask":"0.54","best_bid":"0.53","hash":"8cc1007e57da38197ec46196634357aff874e97a","price":"0.48","side":"BUY","size":"41.4"},{"asset_id":"24254094493625419915756280046002869097156693848522361803041977572204227262166","best_ask":"0.47","best_bid":"0.46","hash":"2f357c5f6b449c8c6640e23c56abe45ba68b2514","price":"0.52","side":"SELL","size":"41.4"}],"timestamp":"1785122402885"},"payload_hash":"5d588806da8662aa8a9e1ef483c3db20a68706729faf959af0e8166e8d978c9f","raw_frame":"{\"market\":\"0x717c0e8ccd4d5c7040185188fbae28be901ca589a11a94b1b38ca36a79eccfeb\", \"price_changes\":[{\"asset_id\":\"41448400836309843603620980831210604935021861034693225347475867885462478926555\", \"price\":\"0.48\", \"size\":\"41.4\", \"side\":\"BUY\", \"hash\":\"8cc1007e57da38197ec46196634357aff874e97a\", \"best_bid\":\"0.53\", \"best_ask\":\"0.54\"}, {\"asset_id\":\"24254094493625419915756280046002869097156693848522361803041977572204227262166\", \"price\":\"0.52\", \"size\":\"41.4\", \"side\":\"SELL\", \"hash\":\"2f357c5f6b449c8c6640e23c56abe45ba68b2514\", \"best_bid\":\"0.46\", \"best_ask\":\"0.47\"}], \"timestamp\":\"1785122402885\", \"event_type\":\"price_change\"}","received_at":"2026-07-27T03:20:02.782595Z","schema_version":"clob-market-ws.price_change.v1","sequence":null,"server_hash":null,"server_timestamp":"1785122402885","session_id":"dd162b8dca5f43ff811d304e69a06123","source":"clob_market_ws"},"received_at":"2026-07-27T03:20:02.782595Z","record_id":"c77844d1e008277d55cbb3a6896c602bb2aacb1b224207b2a074b6f271dcccec","schema_fingerprint":"4aa3821a28b0b7c2400bc59aba4bcc0a76e971dadd19610d3ad38c768e124dc7","schema_version":"edge-lab-recorder.raw.v1","sequence":null,"source":"clob_market_ws"}
{"event_at":"2026-07-27T03:20:02.885000Z","event_fingerprint":"18e627d5f6786025169fdbb6be08dac76ae3432dea05f66b52a018f53d4c0b1a","payload":{"connection_id":"c7dc2e4762f849c6b6f9306b6518dcab","event_at":"2026-07-27T03:20:02.885000Z","event_type":"price_change","frame_hash":"c44cb9098d21495f43bdefb3a2c0576d8ee7bac5b82fd176bb3bb9b4bc9dc587","frame_index":0,"kind":"data","monotonic_ns":224386137495791,"payload":{"event_type":"price_change","market":"0x717c0e8ccd4d5c7040185188fbae28be901ca589a11a94b1b38ca36a79eccfeb","price_changes":[{"asset_id":"41448400836309843603620980831210604935021861034693225347475867885462478926555","best_ask":"0.54","best_bid":"0.53","hash":"0484da9c34cfc7ca4eda0f92c371924a2ad55b80","price":"0.53","side":"BUY","size":"27.68"},{"asset_id":"24254094493625419915756280046002869097156693848522361803041977572204227262166","best_ask":"0.47","best_bid":"0.46","hash":"45f224656acc46ba0374726a5fa158f51217a13a","price":"0.47","side":"SELL","size":"27.68"}],"timestamp":"1785122402885"},"payload_hash":"0b8c0479713e5b7b6c8f8553a2376f5e68b2d7df279753d67c2ac212a2468b6a","raw_frame":"{\"market\":\"0x717c0e8ccd4d5c7040185188fbae28be901ca589a11a94b1b38ca36a79eccfeb\", \"price_changes\":[{\"asset_id\":\"41448400836309843603620980831210604935021861034693225347475867885462478926555\", \"price\":\"0.53\", \"size\":\"27.68\", \"side\":\"BUY\", \"hash\":\"0484da9c34cfc7ca4eda0f92c371924a2ad55b80\", \"best_bid\":\"0.53\", \"best_ask\":\"0.54\"}, {\"asset_id\":\"24254094493625419915756280046002869097156693848522361803041977572204227262166\", \"price\":\"0.47\", \"size\":\"27.68\", \"side\":\"SELL\", \"hash\":\"45f224656acc46ba0374726a5fa158f51217a13a\", \"best_bid\":\"0.46\", \"best_ask\":\"0.47\"}], \"timestamp\":\"1785122402885\", \"event_type\":\"price_change\"}","received_at":"2026-07-27T03:20:02.785675Z","schema_version":"clob-market-ws.price_change.v1","sequence":null,"server_hash":null,"server_timestamp":"1785122402885","session_id":"dd162b8dca5f43ff811d304e69a06123","source":"clob_market_ws"},"received_at":"2026-07-27T03:20:02.785675Z","record_id":"efaa5e7529a5e0f7dfc3efdefa83452d8049d695303cc7c69071260c1f8187bd","schema_fingerprint":"4aa3821a28b0b7c2400bc59aba4bcc0a76e971dadd19610d3ad38c768e124dc7","schema_version":"edge-lab-recorder.raw.v1","sequence":null,"source":"clob_market_ws"}
{"event_at":"2026-07-27T03:20:02.887000Z","event_fingerprint":"442412f4c0710bfdce7f3097e280069058c2f9a08b8e6959b7c36c80e2a686dd","payload":{"connection_id":"c7dc2e4762f849c6b6f9306b6518dcab","event_at":"2026-07-27T03:20:02.887000Z","event_type":"price_change","frame_hash":"b7d49f6d2f7bbd7341ce4ad136bbd33fc3983b90878d3aebe050b070cae8f934","frame_index":0,"kind":"data","monotonic_ns":224386141221916,"payload":{"event_type":"price_change","market":"0x717c0e8ccd4d5c7040185188fbae28be901ca589a11a94b1b38ca36a79eccfeb","price_changes":[{"asset_id":"41448400836309843603620980831210604935021861034693225347475867885462478926555","best_ask":"0.54","best_bid":"0.53","hash":"fc5b7706fc40910d39ae09ca3ccb69593021b781","price":"0.53","side":"BUY","size":"10.88"},{"asset_id":"24254094493625419915756280046002869097156693848522361803041977572204227262166","best_ask":"0.47","best_bid":"0.46","hash":"d3d3811796ff6eab6635d4ddac1282b06e34dbe3","price":"0.47","side":"SELL","size":"10.88"}],"timestamp":"1785122402887"},"payload_hash":"462d17550ee82cfd358037eb4cd8ee76a14c5cf9212c3816e700ef4f9179f7eb","raw_frame":"{\"market\":\"0x717c0e8ccd4d5c7040185188fbae28be901ca589a11a94b1b38ca36a79eccfeb\", \"price_changes\":[{\"asset_id\":\"41448400836309843603620980831210604935021861034693225347475867885462478926555\", \"price\":\"0.53\", \"size\":\"10.88\", \"side\":\"BUY\", \"hash\":\"fc5b7706fc40910d39ae09ca3ccb69593021b781\", \"best_bid\":\"0.53\", \"best_ask\":\"0.54\"}, {\"asset_id\":\"24254094493625419915756280046002869097156693848522361803041977572204227262166\", \"price\":\"0.47\", \"size\":\"10.88\", \"side\":\"SELL\", \"hash\":\"d3d3811796ff6eab6635d4ddac1282b06e34dbe3\", \"best_bid\":\"0.46\", \"best_ask\":\"0.47\"}], \"timestamp\":\"1785122402887\", \"event_type\":\"price_change\"}","received_at":"2026-07-27T03:20:02.789402Z","schema_version":"clob-market-ws.price_change.v1","sequence":null,"server_hash":null,"server_timestamp":"1785122402887","session_id":"dd162b8dca5f43ff811d304e69a06123","source":"clob_market_ws"},"received_at":"2026-07-27T03:20:02.789402Z","record_id":"16b547b043f0071ad0c92ea106fcded7be629cba44be62a1abdf7470bd02a3d6","schema_fingerprint":"4aa3821a28b0b7c2400bc59aba4bcc0a76e971dadd19610d3ad38c768e124dc7","schema_version":"edge-lab-recorder.raw.v1","sequence":null,"source":"clob_market_ws"}
{"event_at":"2026-07-27T03:20:02.887000Z","event_fingerprint":"d29fdddcec346fde2bcbdde439afd3cf524713fcb216c5ba7d9ae8f3cb2df3df","payload":{"connection_id":"c7dc2e4762f849c6b6f9306b6518dcab","event_at":"2026-07-27T03:20:02.887000Z","event_type":"price_change","frame_hash":"6a360aaabdcc6038a81a99a9c0dba1af22346555e6f873ba72cdc3a630165be1","frame_index":0,"kind":"data","monotonic_ns":224386145325208,"payload":{"event_type":"price_change","market":"0x717c0e8ccd4d5c7040185188fbae28be901ca589a11a94b1b38ca36a79eccfeb","price_changes":[{"asset_id":"24254094493625419915756280046002869097156693848522361803041977572204227262166","best_ask":"0.47","best_bid":"0.46","hash":"d988ed6462ce65ad2c5a29dfec84d98eb36eea3e","price":"0.46","side":"BUY","size":"30.6"},{"asset_id":"41448400836309843603620980831210604935021861034693225347475867885462478926555","best_ask":"0.54","best_bid":"0.53","hash":"f8ee5067d4482d85116dfbe7d39c2af3c53725af","price":"0.54","side":"SELL","size":"30.6"}],"timestamp":"1785122402887"},"payload_hash":"17a58f6b74fd861b025ecb4f3dacfedf2c254cd12542e0a26ae39d0de6c459da","raw_frame":"{\"market\":\"0x717c0e8ccd4d5c7040185188fbae28be901ca589a11a94b1b38ca36a79eccfeb\", \"price_changes\":[{\"asset_id\":\"24254094493625419915756280046002869097156693848522361803041977572204227262166\", \"price\":\"0.46\", \"size\":\"30.6\", \"side\":\"BUY\", \"hash\":\"d988ed6462ce65ad2c5a29dfec84d98eb36eea3e\", \"best_bid\":\"0.46\", \"best_ask\":\"0.47\"}, {\"asset_id\":\"41448400836309843603620980831210604935021861034693225347475867885462478926555\", \"price\":\"0.54\", \"size\":\"30.6\", \"side\":\"SELL\", \"hash\":\"f8ee5067d4482d85116dfbe7d39c2af3c53725af\", \"best_bid\":\"0.53\", \"best_ask\":\"0.54\"}], \"timestamp\":\"1785122402887\", \"event_type\":\"price_change\"}","received_at":"2026-07-27T03:20:02.793501Z","schema_version":"clob-market-ws.price_change.v1","sequence":null,"server_hash":null,"server_timestamp":"1785122402887","session_id":"dd162b8dca5f43ff811d304e69a06123","source":"clob_market_ws"},"received_at":"2026-07-27T03:20:02.793501Z","record_id":"7aa1a63caaa4714e855ed9183170386281c96ef4361573c3f6021b9ec9819cf1","schema_fingerprint":"4aa3821a28b0b7c2400bc59aba4bcc0a76e971dadd19610d3ad38c768e124dc7","schema_version":"edge-lab-recorder.raw.v1","sequence":null,"source":"clob_market_ws"}
