{"event_at":"2026-07-27T03:26:46.636000Z","event_fingerprint":"1c5184a242a69b26a05a22f00d3a2ffc7d7e644b74ac79fe40f4dcfd0cbce5c1","payload":{"connection_id":"c7dc2e4762f849c6b6f9306b6518dcab","event_at":"2026-07-27T03:26:46.636000Z","event_type":"price_change","frame_hash":"13a1c7f04f1a8b0be5ac566cd02b5d4455fd7511af1d08d18931c0b9d97e0417","frame_index":0,"kind":"data","monotonic_ns":224789947762791,"payload":{"event_type":"price_change","market":"0x717c0e8ccd4d5c7040185188fbae28be901ca589a11a94b1b38ca36a79eccfeb","price_changes":[{"asset_id":"24254094493625419915756280046002869097156693848522361803041977572204227262166","best_ask":"0.86","best_bid":"0.84","hash":"0ed0a2b19bf3b599ea6fdc36c49916750725cff3","price":"0.78","side":"BUY","size":"117"},{"asset_id":"41448400836309843603620980831210604935021861034693225347475867885462478926555","best_ask":"0.16","best_bid":"0.14","hash":"c605f5441ebfcee4f50e98bf27f177a79b7a4298","price":"0.22","side":"SELL","size":"117"}],"timestamp":"1785122806636"},"payload_hash":"88d39d5a57062bc93c3c023239dfa3c2fd419cc468ea4332fd8e41febefe38f6","raw_frame":"{\"market\":\"0x717c0e8ccd4d5c7040185188fbae28be901ca589a11a94b1b38ca36a79eccfeb\", \"price_changes\":[{\"asset_id\":\"24254094493625419915756280046002869097156693848522361803041977572204227262166\", \"price\":\"0.78\", \"size\":\"117\", \"side\":\"BUY\", \"hash\":\"0ed0a2b19bf3b599ea6fdc36c49916750725cff3\", \"best_bid\":\"0.84\", \"best_ask\":\"0.86\"}, {\"asset_id\":\"41448400836309843603620980831210604935021861034693225347475867885462478926555\", \"price\":\"0.22\", \"size\":\"117\", \"side\":\"SELL\", \"hash\":\"c605f5441ebfcee4f50e98bf27f177a79b7a4298\", \"best_bid\":\"0.14\", \"best_ask\":\"0.16\"}], \"timestamp\":\"1785122806636\", \"event_type\":\"price_change\"}","received_at":"2026-07-27T03:26:46.587234Z","schema_version":"clob-market-ws.price_change.v1","sequence":null,"server_hash":null,"server_timestamp":"1785122806636","session_id":"dd162b8dca5f43ff811d304e69a06123","source":"clob_market_ws"},"received_at":"2026-07-27T03:26:46.587234Z","record_id":"002efaed01658bfbc31821216bc0a6393d3a3638fcbe916d29339be5242f4151","schema_fingerprint":"4aa3821a28b0b7c2400bc59aba4bcc0a76e971dadd19610d3ad38c768e124dc7","schema_version":"edge-lab-recorder.raw.v1","sequence":null,"source":"clob_market_ws"}
{"event_at":"2026-07-27T03:26:46.639000Z","event_fingerprint":"2cd54c733a84b75ca3f6d92505372c608c98b9ded45d0fce85398cd2640381bb","payload":{"connection_id":"c7dc2e4762f849c6b6f9306b6518dcab","event_at":"2026-07-27T03:26:46.639000Z","event_type":"best_bid_ask","frame_hash":"f618cab98371fa7a1a33a88b71bedd524cd024ceff8ef37ed80bac147e0094c7","frame_index":0,"kind":"data","monotonic_ns":224789950424458,"payload":{"asset_id":"24254094493625419915756280046002869097156693848522361803041977572204227262166","best_ask":"0.85","best_bid":"0.84","event_type":"best_bid_ask","market":"0x717c0e8ccd4d5c7040185188fbae28be901ca589a11a94b1b38ca36a79eccfeb","spread":"0.01","timestamp":"1785122806639"},"payload_hash":"1d3b68803a09cb263c631ddbf3a921f44e9baa8d170a13e0b2492acbb62c47f5","raw_frame":"{\"market\":\"0x717c0e8ccd4d5c7040185188fbae28be901ca589a11a94b1b38ca36a79eccfeb\", \"asset_id\":\"24254094493625419915756280046002869097156693848522361803041977572204227262166\", \"best_bid\":\"0.84\", \"best_ask\":\"0.85\", \"spread\":\"0.01\", \"timestamp\":\"1785122806639\", \"event_type\":\"best_bid_ask\"}","received_at":"2026-07-27T03:26:46.589891Z","schema_version":"clob-market-ws.best_bid_ask.v1","sequence":null,"server_hash":null,"server_timestamp":"1785122806639","session_id":"dd162b8dca5f43ff811d304e69a06123","source":"clob_market_ws"},"received_at":"2026-07-27T03:26:46.589891Z","record_id":"8f885bc2855431e377515355a3266414de0ce2f22050c7a8b735e4e1744f3310","schema_fingerprint":"8488399f31b0337811b13b266be932db7062827c2470b78bd8e9e99bab51d17d","schema_version":"edge-lab-recorder.raw.v1","sequence":null,"source":"clob_market_ws"}
{"event_at":"2026-07-27T03:26:46.639000Z","event_fingerprint":"cfa0060c8696abdeab6880008ff6a221aa20013b403fd46710a0b241c40e40bc","payload":{"connection_id":"c7dc2e4762f849c6b6f9306b6518dcab","event_at":"2026-07-27T03:26:46.639000Z","event_type":"best_bid_ask","frame_hash":"6814f0a128f7b30b740ca9db29c579da750f9e58b3e58a62ccb56a8b453403c4","frame_index":0,"kind":"data","monotonic_ns":224789951745083,"payload":{"asset_id":"41448400836309843603620980831210604935021861034693225347475867885462478926555","best_ask":"0.16","best_bid":"0.15","event_type":"best_bid_ask","market":"0x717c0e8ccd4d5c7040185188fbae28be901ca589a11a94b1b38ca36a79eccfeb","spread":"0.01","timestamp":"1785122806639"},"payload_hash":"add21e28e07a87a9acc84cf69bb0f25611514e43dbc54a1cb29a5219701a9af3","raw_frame":"{\"market\":\"0x717c0e8ccd4d5c7040185188fbae28be901ca589a11a94b1b38ca36a79eccfeb\", \"asset_id\":\"41448400836309843603620980831210604935021861034693225347475867885462478926555\", \"best_bid\":\"0.15\", \"best_ask\":\"0.16\", \"spread\":\"0.01\", \"timestamp\":\"1785122806639\", \"event_type\":\"best_bid_ask\"}","received_at":"2026-07-27T03:26:46.591212Z","schema_version":"clob-market-ws.best_bid_ask.v1","sequence":null,"server_hash":null,"server_timestamp":"1785122806639","session_id":"dd162b8dca5f43ff811d304e69a06123","source":"clob_market_ws"},"received_at":"2026-07-27T03:26:46.591212Z","record_id":"03558ff6f6750d22698fd658ab0bd1a0768d60d6204fbaa927358edef6828dc4","schema_fingerprint":"8488399f31b0337811b13b266be932db7062827c2470b78bd8e9e99bab51d17d","schema_version":"edge-lab-recorder.raw.v1","sequence":null,"source":"clob_market_ws"}
{"event_at":"2026-07-27T03:26:46.639000Z","event_fingerprint":"9da4e02c07916a24a225c4b70833b9de7bf1c42f7f2c9ea3066b50ac8a6cdc5e","payload":{"connection_id":"c7dc2e4762f849c6b6f9306b6518dcab","event_at":"2026-07-27T03:26:46.639000Z","event_type":"price_change","frame_hash":"2cb45c62b542faf072ac30ff9f26014c0be8b9d9c25b5f5a1770f9c5bf3fa28c","frame_index":0,"kind":"data","monotonic_ns":224789957249250,"payload":{"event_type":"price_change","market":"0x717c0e8ccd4d5c7040185188fbae28be901ca589a11a94b1b38ca36a79eccfeb","price_changes":[{"asset_id":"41448400836309843603620980831210604935021861034693225347475867885462478926555","best_ask":"0.16","best_bid":"0.15","hash":"b6d3a279940cb7c554ec6e216d0535158cde53a3","price":"0.15","side":"BUY","size":"10"},{"asset_id":"24254094493625419915756280046002869097156693848522361803041977572204227262166","best_ask":"0.85","best_bid":"0.84","hash":"110e508391899f7599a4a7daca1a4f4b5c22aed3","price":"0.85","side":"SELL","size":"10"}],"timestamp":"1785122806639"},"payload_hash":"19c14627bc38c00f18bb1d739239c2b462afc76521f1f443280aba2f7d73515c","raw_frame":"{\"market\":\"0x717c0e8ccd4d5c7040185188fbae28be901ca589a11a94b1b38ca36a79eccfeb\", \"price_changes\":[{\"asset_id\":\"41448400836309843603620980831210604935021861034693225347475867885462478926555\", \"price\":\"0.15\", \"size\":\"10\", \"side\":\"BUY\", \"hash\":\"b6d3a279940cb7c554ec6e216d0535158cde53a3\", \"best_bid\":\"0.15\", \"best_ask\":\"0.16\"}, {\"asset_id\":\"24254094493625419915756280046002869097156693848522361803041977572204227262166\", \"price\":\"0.85\", \"size\":\"10\", \"side\":\"SELL\", \"hash\":\"110e508391899f7599a4a7daca1a4f4b5c22aed3\", \"best_bid\":\"0.84\", \"best_ask\":\"0.85\"}], \"timestamp\":\"1785122806639\", \"event_type\":\"price_change\"}","received_at":"2026-07-27T03:26:46.596715Z","schema_version":"clob-market-ws.price_change.v1","sequence":null,"server_hash":null,"server_timestamp":"1785122806639","session_id":"dd162b8dca5f43ff811d304e69a06123","source":"clob_market_ws"},"received_at":"2026-07-27T03:26:46.596715Z","record_id":"1ad0956f44d4f956af1a6c85190847bf7696b7b674fbed22e8014f6d2c2c7aac","schema_fingerprint":"4aa3821a28b0b7c2400bc59aba4bcc0a76e971dadd19610d3ad38c768e124dc7","schema_version":"edge-lab-recorder.raw.v1","sequence":null,"source":"clob_market_ws"}
{"event_at":"2026-07-27T03:26:46.652000Z","event_fingerprint":"8752c59f3c29cf052d27f98ed237cfafece7a37492fb195b817456a474bad157","payload":{"connection_id":"c7dc2e4762f849c6b6f9306b6518dcab","event_at":"2026-07-27T03:26:46.652000Z","event_type":"price_change","frame_hash":"291011f27cc97e070c5d66b46405f36a830308c144b73dc2900fce103d3d3d44","frame_index":0,"kind":"data","monotonic_ns":224789959484208,"payload":{"event_type":"price_change","market":"0x717c0e8ccd4d5c7040185188fbae28be901ca589a11a94b1b38ca36a79eccfeb","price_changes":[{"asset_id":"41448400836309843603620980831210604935021861034693225347475867885462478926555","best_ask":"0.16","best_bid":"0.15","hash":"51ea77e034f46aee7722f2af3a10341960bbb9ef","price":"0.08","side":"BUY","size":"555.12"},{"asset_id":"24254094493625419915756280046002869097156693848522361803041977572204227262166","best_ask":"0.85","best_bid":"0.84","hash":"0c4a8067814f0eae50e102c7a477481af9f00f02","price":"0.92","side":"SELL","size":"555.12"}],"timestamp":"1785122806652"},"payload_hash":"5fdf49e0c868d1cb71db06bf4cb1687c330799d80e3a10f241cdffe1634d4598","raw_frame":"{\"market\":\"0x717c0e8ccd4d5c7040185188fbae28be901ca589a11a94b1b38ca36a79eccfeb\", \"price_changes\":[{\"asset_id\":\"41448400836309843603620980831210604935021861034693225347475867885462478926555\", \"price\":\"0.08\", \"size\":\"555.12\", \"side\":\"BUY\", \"hash\":\"51ea77e034f46aee7722f2af3a10341960bbb9ef\", \"best_bid\":\"0.15\", \"best_ask\":\"0.16\"}, {\"asset_id\":\"24254094493625419915756280046002869097156693848522361803041977572204227262166\", \"price\":\"0.92\", \"size\":\"555.12\", \"side\":\"SELL\", \"hash\":\"0c4a8067814f0eae50e102c7a477481af9f00f02\", \"best_bid\":\"0.84\", \"best_ask\":\"0.85\"}], \"timestamp\":\"1785122806652\", \"event_type\":\"price_change\"}","received_at":"2026-07-27T03:26:46.598949Z","schema_version":"clob-market-ws.price_change.v1","sequence":null,"server_hash":null,"server_timestamp":"1785122806652","session_id":"dd162b8dca5f43ff811d304e69a06123","source":"clob_market_ws"},"received_at":"2026-07-27T03:26:46.598949Z","record_id":"e6cc8ba645a121e7a5623d5de48004f23fc21c7e1c808d60931a33e735611be5","schema_fingerprint":"4aa3821a28b0b7c2400bc59aba4bcc0a76e971dadd19610d3ad38c768e124dc7","schema_version":"edge-lab-recorder.raw.v1","sequence":null,"source":"clob_market_ws"}
{"event_at":"2026-07-27T03:26:46.652000Z","event_fingerprint":"28315f9792e0a44d090071339e1804ee125ceabba2f9ba303fe8778eb150dbe9","payload":{"connection_id":"c7dc2e4762f849c6b6f9306b6518dcab","event_at":"2026-07-27T03:26:46.652000Z","event_type":"price_change","frame_hash":"5e8437092cb6205bd3b0cf879677ebba8cec74f9944d922c814443aba1c56b86","frame_index":0,"kind":"data","monotonic_ns":224789962890500,"payload":{"event_type":"price_change","market":"0x717c0e8ccd4d5c7040185188fbae28be901ca589a11a94b1b38ca36a79eccfeb","price_changes":[{"asset_id":"24254094493625419915756280046002869097156693848522361803041977572204227262166","best_ask":"0.85","best_bid":"0.84","hash":"7b7400c2d55bd0a2d3d92df9290352451dd56b6f","price":"0.55","side":"BUY","size":"126.2"},{"asset_id":"41448400836309843603620980831210604935021861034693225347475867885462478926555","best_ask":"0.16","best_bid":"0.15","hash":"701da4f778655ce6276b4da6c61510228e71609f","price":"0.45","side":"SELL","size":"126.2"}],"timestamp":"1785122806652"},"payload_hash":"70861d28615d764422f66e7d2ea03f2b199c57c986cd68e8792739d4dc8174c7","raw_frame":"{\"market\":\"0x717c0e8ccd4d5c7040185188fbae28be901ca589a11a94b1b38ca36a79eccfeb\", \"price_changes\":[{\"asset_id\":\"24254094493625419915756280046002869097156693848522361803041977572204227262166\", \"price\":\"0.55\", \"size\":\"126.2\", \"side\":\"BUY\", \"hash\":\"7b7400c2d55bd0a2d3d92df9290352451dd56b6f\", \"best_bid\":\"0.84\", \"best_ask\":\"0.85\"}, {\"asset_id\":\"41448400836309843603620980831210604935021861034693225347475867885462478926555\", \"price\":\"0.45\", \"size\":\"126.2\", \"side\":\"SELL\", \"hash\":\"701da4f778655ce6276b4da6c61510228e71609f\", \"best_bid\":\"0.15\", \"best_ask\":\"0.16\"}], \"timestamp\":\"1785122806652\", \"event_type\":\"price_change\"}","received_at":"2026-07-27T03:26:46.602357Z","schema_version":"clob-market-ws.price_change.v1","sequence":null,"server_hash":null,"server_timestamp":"1785122806652","session_id":"dd162b8dca5f43ff811d304e69a06123","source":"clob_market_ws"},"received_at":"2026-07-27T03:26:46.602357Z","record_id":"62411135386f1d46f6e6802015f65cc2ea98d16bb035dc0d8499ef7e3087d7d7","schema_fingerprint":"4aa3821a28b0b7c2400bc59aba4bcc0a76e971dadd19610d3ad38c768e124dc7","schema_version":"edge-lab-recorder.raw.v1","sequence":null,"source":"clob_market_ws"}
{"event_at":"2026-07-27T03:26:46.652000Z","event_fingerprint":"44695af758f83b6dbf85b560e823f36e940f7c51798a6a13f34351ef30d2c650","payload":{"connection_id":"c7dc2e4762f849c6b6f9306b6518dcab","event_at":"2026-07-27T03:26:46.652000Z","event_type":"price_change","frame_hash":"92d0daf6d8df5e5edcdc32050a344bd22f15f4096b8cb5ccc5d63b3e00e47dec","frame_index":0,"kind":"data","monotonic_ns":224789966412041,"payload":{"event_type":"price_change","market":"0x717c0e8ccd4d5c7040185188fbae28be901ca589a11a94b1b38ca36a79eccfeb","price_changes":[{"asset_id":"41448400836309843603620980831210604935021861034693225347475867885462478926555","best_ask":"0.16","best_bid":"0.15","hash":"ce0e41aaeeeb4e826bb8d2ff61edc1eeaa47160e","price":"0.08","side":"BUY","size":"285.12"},{"asset_id":"24254094493625419915756280046002869097156693848522361803041977572204227262166","best_ask":"0.85","best_bid":"0.84","hash":"4acbc8dfee4f76c4644bb0edb1f3389d619981ef","price":"0.92","side":"SELL","size":"285.12"}],"timestamp":"1785122806652"},"payload_hash":"3f080219e8601b8369d061562c6ceb76a5e60d670da3bba532fb0b5068b47ccb","raw_frame":"{\"market\":\"0x717c0e8ccd4d5c7040185188fbae28be901ca589a11a94b1b38ca36a79eccfeb\", \"price_changes\":[{\"asset_id\":\"41448400836309843603620980831210604935021861034693225347475867885462478926555\", \"price\":\"0.08\", \"size\":\"285.12\", \"side\":\"BUY\", \"hash\":\"ce0e41aaeeeb4e826bb8d2ff61edc1eeaa47160e\", \"best_bid\":\"0.15\", \"best_ask\":\"0.16\"}, {\"asset_id\":\"24254094493625419915756280046002869097156693848522361803041977572204227262166\", \"price\":\"0.92\", \"size\":\"285.12\", \"side\":\"SELL\", \"hash\":\"4acbc8dfee4f76c4644bb0edb1f3389d619981ef\", \"best_bid\":\"0.84\", \"best_ask\":\"0.85\"}], \"timestamp\":\"1785122806652\", \"event_type\":\"price_change\"}","received_at":"2026-07-27T03:26:46.605871Z","schema_version":"clob-market-ws.price_change.v1","sequence":null,"server_hash":null,"server_timestamp":"1785122806652","session_id":"dd162b8dca5f43ff811d304e69a06123","source":"clob_market_ws"},"received_at":"2026-07-27T03:26:46.605871Z","record_id":"d9b1961546da1a1bcb999f38f9f4c579b1379ea8411ed340058c6e718c1e74a7","schema_fingerprint":"4aa3821a28b0b7c2400bc59aba4bcc0a76e971dadd19610d3ad38c768e124dc7","schema_version":"edge-lab-recorder.raw.v1","sequence":null,"source":"clob_market_ws"}
{"event_at":"2026-07-27T03:26:46.653000Z","event_fingerprint":"4710a2b2bcdaca3ff13ec1ebfdcc33c6916264053937172cb93973420ce60d32","payload":{"connection_id":"c7dc2e4762f849c6b6f9306b6518dcab","event_at":"2026-07-27T03:26:46.653000Z","event_type":"price_change","frame_hash":"8045ca533f181e47fe7e5677daf003e1f3d1c7a96769ed84c469f8a7ecf69e85","frame_index":0,"kind":"data","monotonic_ns":224789970403625,"payload":{"event_type":"price_change","market":"0x717c0e8ccd4d5c7040185188fbae28be901ca589a11a94b1b38ca36a79eccfeb","price_changes":[{"asset_id":"24254094493625419915756280046002869097156693848522361803041977572204227262166","best_ask":"0.85","best_bid":"0.84","hash":"af625e7de42cdef4c1bb78b2d540c1610b1a2cad","price":"0.55","side":"BUY","size":"65.6"},{"asset_id":"41448400836309843603620980831210604935021861034693225347475867885462478926555","best_ask":"0.16","best_bid":"0.15","hash":"af02fffd85c8c0ba5be37f29ef941a76af27c98e","price":"0.45","side":"SELL","size":"65.6"}],"timestamp":"1785122806653"},"payload_hash":"d2aaf8ededc9b13dbda5fa2d563fc317780fe4c42b144450ec42a7adf49781f0","raw_frame":"{\"market\":\"0x717c0e8ccd4d5c7040185188fbae28be901ca589a11a94b1b38ca36a79eccfeb\", \"price_changes\":[{\"asset_id\":\"24254094493625419915756280046002869097156693848522361803041977572204227262166\", \"price\":\"0.55\", \"size\":\"65.6\", \"side\":\"BUY\", \"hash\":\"af625e7de42cdef4c1bb78b2d540c1610b1a2cad\", \"best_bid\":\"0.84\", \"best_ask\":\"0.85\"}, {\"asset_id\":\"41448400836309843603620980831210604935021861034693225347475867885462478926555\", \"price\":\"0.45\", \"size\":\"65.6\", \"side\":\"SELL\", \"hash\":\"af02fffd85c8c0ba5be37f29ef941a76af27c98e\", \"best_bid\":\"0.15\", \"best_ask\":\"0.16\"}], \"timestamp\":\"1785122806653\", \"event_type\":\"price_change\"}","received_at":"2026-07-27T03:26:46.609869Z","schema_version":"clob-market-ws.price_change.v1","sequence":null,"server_hash":null,"server_timestamp":"1785122806653","session_id":"dd162b8dca5f43ff811d304e69a06123","source":"clob_market_ws"},"received_at":"2026-07-27T03:26:46.609869Z","record_id":"c3a2a2692263f5cc3ea1ec44cffe402535f668a6ffdc82aba9d79498a3a0053d","schema_fingerprint":"4aa3821a28b0b7c2400bc59aba4bcc0a76e971dadd19610d3ad38c768e124dc7","schema_version":"edge-lab-recorder.raw.v1","sequence":null,"source":"clob_market_ws"}
{"event_at":"2026-07-27T03:26:46.654000Z","event_fingerprint":"42e2a0483cb891ca72bcb344bf963eb85dd00f85a05b7440f4ef4b195e4967b8","payload":{"connection_id":"c7dc2e4762f849c6b6f9306b6518dcab","event_at":"2026-07-27T03:26:46.654000Z","event_type":"price_change","frame_hash":"feb0b81f267622fb42ae31bb50f99fdfdc7f1a3af04242d2020cda893845d8c9","frame_index":0,"kind":"data","monotonic_ns":224789973678416,"payload":{"event_type":"price_change","market":"0x717c0e8ccd4d5c7040185188fbae28be901ca589a11a94b1b38ca36a79eccfeb","price_changes":[{"asset_id":"24254094493625419915756280046002869097156693848522361803041977572204227262166","best_ask":"0.85","best_bid":"0.84","hash":"bc312e0e1450a3839b7221cf14d842b30ed914ad","price":"0.55","side":"BUY","size":"5"},{"asset_id":"41448400836309843603620980831210604935021861034693225347475867885462478926555","best_ask":"0.16","best_bid":"0.15","hash":"3ec7fe964577aeee09901ae5b7402d585c5ad821","price":"0.45","side":"SELL","size":"5"}],"timestamp":"1785122806654"},"payload_hash":"c2f803bd1e30effe09323840f2c2ef9a8a43bfd5259f76c775c26b8155618bc4","raw_frame":"{\"market\":\"0x717c0e8ccd4d5c7040185188fbae28be901ca589a11a94b1b38ca36a79eccfeb\", \"price_changes\":[{\"asset_id\":\"24254094493625419915756280046002869097156693848522361803041977572204227262166\", \"price\":\"0.55\", \"size\":\"5\", \"side\":\"BUY\", \"hash\":\"bc312e0e1450a3839b7221cf14d842b30ed914ad\", \"best_bid\":\"0.84\", \"best_ask\":\"0.85\"}, {\"asset_id\":\"41448400836309843603620980831210604935021861034693225347475867885462478926555\", \"price\":\"0.45\", \"size\":\"5\", \"side\":\"SELL\", \"hash\":\"3ec7fe964577aeee09901ae5b7402d585c5ad821\", \"best_bid\":\"0.15\", \"best_ask\":\"0.16\"}], \"timestamp\":\"1785122806654\", \"event_type\":\"price_change\"}","received_at":"2026-07-27T03:26:46.613144Z","schema_version":"clob-market-ws.price_change.v1","sequence":null,"server_hash":null,"server_timestamp":"1785122806654","session_id":"dd162b8dca5f43ff811d304e69a06123","source":"clob_market_ws"},"received_at":"2026-07-27T03:26:46.613144Z","record_id":"04ae4be8f77394ddd5758b2df96c1b92f67447e460b1bc2b232ca325c081d41b","schema_fingerprint":"4aa3821a28b0b7c2400bc59aba4bcc0a76e971dadd19610d3ad38c768e124dc7","schema_version":"edge-lab-recorder.raw.v1","sequence":null,"source":"clob_market_ws"}
{"event_at":"2026-07-27T03:26:46.654000Z","event_fingerprint":"8eeecadf8128bff8a2873df677a10e1e264e284e291d49a1cd9b2cc64f1a86de","payload":{"connection_id":"c7dc2e4762f849c6b6f9306b6518dcab","event_at":"2026-07-27T03:26:46.654000Z","event_type":"price_change","frame_hash":"c6a5c313050b110367226365b096a24a4db950e974065d9bafd0424b72e88855","frame_index":0,"kind":"data","monotonic_ns":224789977952916,"payload":{"event_type":"price_change","market":"0x717c0e8ccd4d5c7040185188fbae28be901ca589a11a94b1b38ca36a79eccfeb","price_changes":[{"asset_id":"41448400836309843603620980831210604935021861034693225347475867885462478926555","best_ask":"0.16","best_bid":"0.15","hash":"b9d29b11f31a8bdf7f2da3b06806ea92f7f65b8e","price":"0.07","side":"BUY","size":"757.58"},{"asset_id":"24254094493625419915756280046002869097156693848522361803041977572204227262166","best_ask":"0.85","best_bid":"0.84","hash":"77ac410ab81506a07847eebd213806cc51114580","price":"0.93","side":"SELL","size":"757.58"}],"timestamp":"1785122806654"},"payload_hash":"c40e453ff9955295ffd5ca5081f94ad78675890906162a854e462244ec029e71","raw_frame":"{\"market\":\"0x717c0e8ccd4d5c7040185188fbae28be901ca589a11a94b1b38ca36a79eccfeb\", \"price_changes\":[{\"asset_id\":\"41448400836309843603620980831210604935021861034693225347475867885462478926555\", \"price\":\"0.07\", \"size\":\"757.58\", \"side\":\"BUY\", \"hash\":\"b9d29b11f31a8bdf7f2da3b06806ea92f7f65b8e\", \"best_bid\":\"0.15\", \"best_ask\":\"0.16\"}, {\"asset_id\":\"24254094493625419915756280046002869097156693848522361803041977572204227262166\", \"price\":\"0.93\", \"size\":\"757.58\", \"side\":\"SELL\", \"hash\":\"77ac410ab81506a07847eebd213806cc51114580\", \"best_bid\":\"0.84\", \"best_ask\":\"0.85\"}], \"timestamp\":\"1785122806654\", \"event_type\":\"price_change\"}","received_at":"2026-07-27T03:26:46.617420Z","schema_version":"clob-market-ws.price_change.v1","sequence":null,"server_hash":null,"server_timestamp":"1785122806654","session_id":"dd162b8dca5f43ff811d304e69a06123","source":"clob_market_ws"},"received_at":"2026-07-27T03:26:46.617420Z","record_id":"d9476072a0bc157c231b87ba2efa301dcb238c9033f720591d29a1c9f7bb6e3f","schema_fingerprint":"4aa3821a28b0b7c2400bc59aba4bcc0a76e971dadd19610d3ad38c768e124dc7","schema_version":"edge-lab-recorder.raw.v1","sequence":null,"source":"clob_market_ws"}
{"event_at":"2026-07-27T03:26:46.662000Z","event_fingerprint":"e20fafbe750c00b4aebddbd5b711857d1e838f2db94e663df666c3453955c8cb","payload":{"connection_id":"c7dc2e4762f849c6b6f9306b6518dcab","event_at":"2026-07-27T03:26:46.662000Z","event_type":"price_change","frame_hash":"7762a907b8ee587417de965c5d1acf76e29f5569b24d06e1ccb1baabb8996548","frame_index":0,"kind":"data","monotonic_ns":224789981463000,"payload":{"event_type":"price_change","market":"0x717c0e8ccd4d5c7040185188fbae28be901ca589a11a94b1b38ca36a79eccfeb","price_changes":[{"asset_id":"24254094493625419915756280046002869097156693848522361803041977572204227262166","best_ask":"0.85","best_bid":"0.84","hash":"3e74a6aa13d6b58cc37b338b7b7aa78f859916ec","price":"0.84","side":"BUY","size":"116.53"},{"asset_id":"41448400836309843603620980831210604935021861034693225347475867885462478926555","best_ask":"0.16","best_bid":"0.15","hash":"bcd1e369b1b89152476edfc988d5e500b25d39a6","price":"0.16","side":"SELL","size":"116.53"}],"timestamp":"1785122806662"},"payload_hash":"4b23c57df143ae502ac4f83d9d5becb406c611ec0adadfe0cc7f6d527a4f77e5","raw_frame":"{\"market\":\"0x717c0e8ccd4d5c7040185188fbae28be901ca589a11a94b1b38ca36a79eccfeb\", \"price_changes\":[{\"asset_id\":\"24254094493625419915756280046002869097156693848522361803041977572204227262166\", \"price\":\"0.84\", \"size\":\"116.53\", \"side\":\"BUY\", \"hash\":\"3e74a6aa13d6b58cc37b338b7b7aa78f859916ec\", \"best_bid\":\"0.84\", \"best_ask\":\"0.85\"}, {\"asset_id\":\"41448400836309843603620980831210604935021861034693225347475867885462478926555\", \"price\":\"0.16\", \"size\":\"116.53\", \"side\":\"SELL\", \"hash\":\"bcd1e369b1b89152476edfc988d5e500b25d39a6\", \"best_bid\":\"0.15\", \"best_ask\":\"0.16\"}], \"timestamp\":\"1785122806662\", \"event_type\":\"price_change\"}","received_at":"2026-07-27T03:26:46.620928Z","schema_version":"clob-market-ws.price_change.v1","sequence":null,"server_hash":null,"server_timestamp":"1785122806662","session_id":"dd162b8dca5f43ff811d304e69a06123","source":"clob_market_ws"},"received_at":"2026-07-27T03:26:46.620928Z","record_id":"ce817cbb0e41e493a3b9d420dbb63d42abc4d086f342aa198a7fd3bcf446c3a0","schema_fingerprint":"4aa3821a28b0b7c2400bc59aba4bcc0a76e971dadd19610d3ad38c768e124dc7","schema_version":"edge-lab-recorder.raw.v1","sequence":null,"source":"clob_market_ws"}
{"event_at":"2026-07-27T03:26:46.671000Z","event_fingerprint":"3d5eb015dcf332e8c6b7da0f610640117cec86a95f216c7aa9b52ed88344dafe","payload":{"connection_id":"c7dc2e4762f849c6b6f9306b6518dcab","event_at":"2026-07-27T03:26:46.671000Z","event_type":"best_bid_ask","frame_hash":"ca2cffd9d8efcbf467037f7dcd8ca9825b7673de3b921956ea18b4700ab3ee85","frame_index":0,"kind":"data","monotonic_ns":224789985631083,"payload":{"asset_id":"24254094493625419915756280046002869097156693848522361803041977572204227262166","best_ask":"0.86","best_bid":"0.84","event_type":"best_bid_ask","market":"0x717c0e8ccd4d5c7040185188fbae28be901ca589a11a94b1b38ca36a79eccfeb","spread":"0.02","timestamp":"1785122806671"},"payload_hash":"2ee4cfe25da64ef29622c9c1eb003d088b5b8ee6bbb9ad699f62d4939b1a0092","raw_frame":"{\"market\":\"0x717c0e8ccd4d5c7040185188fbae28be901ca589a11a94b1b38ca36a79eccfeb\", \"asset_id\":\"24254094493625419915756280046002869097156693848522361803041977572204227262166\", \"best_bid\":\"0.84\", \"best_ask\":\"0.86\", \"spread\":\"0.02\", \"timestamp\":\"1785122806671\", \"event_type\":\"best_bid_ask\"}","received_at":"2026-07-27T03:26:46.625098Z","schema_version":"clob-market-ws.best_bid_ask.v1","sequence":null,"server_hash":null,"server_timestamp":"1785122806671","session_id":"dd162b8dca5f43ff811d304e69a06123","source":"clob_market_ws"},"received_at":"2026-07-27T03:26:46.625098Z","record_id":"7ad7e0d36fbe285c2ca6ca7bc92f2f28d9e645d46fb2f0d8707ff145a134046e","schema_fingerprint":"8488399f31b0337811b13b266be932db7062827c2470b78bd8e9e99bab51d17d","schema_version":"edge-lab-recorder.raw.v1","sequence":null,"source":"clob_market_ws"}
{"event_at":"2026-07-27T03:26:46.671000Z","event_fingerprint":"13ef3b619e8ea372e26fcad91f2f064ca2a5227404f36f5168ae5f729f7196bb","payload":{"connection_id":"c7dc2e4762f849c6b6f9306b6518dcab","event_at":"2026-07-27T03:26:46.671000Z","event_type":"best_bid_ask","frame_hash":"aa0d9d7cad8184917884c43a6615ac3527ad1e5c79c34130dc1ae39d1e6ad84d","frame_index":0,"kind":"data","monotonic_ns":224789986969583,"payload":{"asset_id":"41448400836309843603620980831210604935021861034693225347475867885462478926555","best_ask":"0.16","best_bid":"0.14","event_type":"best_bid_ask","market":"0x717c0e8ccd4d5c7040185188fbae28be901ca589a11a94b1b38ca36a79eccfeb","spread":"0.02","timestamp":"1785122806671"},"payload_hash":"75b92cd6f283332ff497c794348599aa27b4dff7bc9f5f0f66b32018cdf41004","raw_frame":"{\"market\":\"0x717c0e8ccd4d5c7040185188fbae28be901ca589a11a94b1b38ca36a79eccfeb\", \"asset_id\":\"41448400836309843603620980831210604935021861034693225347475867885462478926555\", \"best_bid\":\"0.14\", \"best_ask\":\"0.16\", \"spread\":\"0.02\", \"timestamp\":\"1785122806671\", \"event_type\":\"best_bid_ask\"}","received_at":"2026-07-27T03:26:46.626435Z","schema_version":"clob-market-ws.best_bid_ask.v1","sequence":null,"server_hash":null,"server_timestamp":"1785122806671","session_id":"dd162b8dca5f43ff811d304e69a06123","source":"clob_market_ws"},"received_at":"2026-07-27T03:26:46.626435Z","record_id":"7f954e6710e521a092ee42eb69fd8b86bff2f57b21ede98c28e0f21571f575d5","schema_fingerprint":"8488399f31b0337811b13b266be932db7062827c2470b78bd8e9e99bab51d17d","schema_version":"edge-lab-recorder.raw.v1","sequence":null,"source":"clob_market_ws"}
{"event_at":"2026-07-27T03:26:46.671000Z","event_fingerprint":"796918f39b63138f63cded54007167efa1bd712109c13d0ea14cadd1f450c5b6","payload":{"connection_id":"c7dc2e4762f849c6b6f9306b6518dcab","event_at":"2026-07-27T03:26:46.671000Z","event_type":"price_change","frame_hash":"cc9d435adc83537b8f5148eda85670275d021c0293bb700e426c75e8c0e95ce0","frame_index":0,"kind":"data","monotonic_ns":224789988115708,"payload":{"event_type":"price_change","market":"0x717c0e8ccd4d5c7040185188fbae28be901ca589a11a94b1b38ca36a79eccfeb","price_changes":[{"asset_id":"41448400836309843603620980831210604935021861034693225347475867885462478926555","best_ask":"0.16","best_bid":"0.14","hash":"886d89c8472cc0a56d362163dd1a503265744229","price":"0.15","side":"BUY","size":"0"},{"asset_id":"24254094493625419915756280046002869097156693848522361803041977572204227262166","best_ask":"0.86","best_bid":"0.84","hash":"71a4a66577dbcb3bc083d4cdaeb488ad5076191e","price":"0.85","side":"SELL","size":"0"}],"timestamp":"1785122806671"},"payload_hash":"8fc8af988d94115d36cf56bf1e9ee79d65b26a9f6b2fab196001f867e035d9de","raw_frame":"{\"market\":\"0x717c0e8ccd4d5c7040185188fbae28be901ca589a11a94b1b38ca36a79eccfeb\", \"price_changes\":[{\"asset_id\":\"41448400836309843603620980831210604935021861034693225347475867885462478926555\", \"price\":\"0.15\", \"size\":\"0\", \"side\":\"BUY\", \"hash\":\"886d89c8472cc0a56d362163dd1a503265744229\", \"best_bid\":\"0.14\", \"best_ask\":\"0.16\"}, {\"asset_id\":\"24254094493625419915756280046002869097156693848522361803041977572204227262166\", \"price\":\"0.85\", \"size\":\"0\", \"side\":\"SELL\", \"hash\":\"71a4a66577dbcb3bc083d4cdaeb488ad5076191e\", \"best_bid\":\"0.84\", \"best_ask\":\"0.86\"}], \"timestamp\":\"1785122806671\", \"event_type\":\"price_change\"}","received_at":"2026-07-27T03:26:46.627582Z","schema_version":"clob-market-ws.price_change.v1","sequence":null,"server_hash":null,"server_timestamp":"1785122806671","session_id":"dd162b8dca5f43ff811d304e69a06123","source":"clob_market_ws"},"received_at":"2026-07-27T03:26:46.627582Z","record_id":"a1bccf7b57d7f91ad0fb4ddcada01d28892492d520cb72fd49e4ea94189e953d","schema_fingerprint":"4aa3821a28b0b7c2400bc59aba4bcc0a76e971dadd19610d3ad38c768e124dc7","schema_version":"edge-lab-recorder.raw.v1","sequence":null,"source":"clob_market_ws"}
{"event_at":"2026-07-27T03:26:46.671000Z","event_fingerprint":"5a082b8a989f3dcd60ff1c033742c624d548d534226aafac426b91fbec4cc097","payload":{"connection_id":"c7dc2e4762f849c6b6f9306b6518dcab","event_at":"2026-07-27T03:26:46.671000Z","event_type":"price_change","frame_hash":"4f9d7162c3403ed2ded1a84c9306de49bba1cb3cb1bb88f3812bbcbae4aabfdc","frame_index":0,"kind":"data","monotonic_ns":224789991432708,"payload":{"event_type":"price_change","market":"0x717c0e8ccd4d5c7040185188fbae28be901ca589a11a94b1b38ca36a79eccfeb","price_changes":[{"asset_id":"24254094493625419915756280046002869097156693848522361803041977572204227262166","best_ask":"0.86","best_bid":"0.84","hash":"73c27d186ac39169cb6c6c8eea1102819ba3df19","price":"0.78","side":"BUY","size":"107"},{"asset_id":"41448400836309843603620980831210604935021861034693225347475867885462478926555","best_ask":"0.16","best_bid":"0.14","hash":"503939480168110ea12627e0d1f221a87d55fce1","price":"0.22","side":"SELL","size":"107"}],"timestamp":"1785122806671"},"payload_hash":"e5d842396a4185f9c53bda3c6b9ef821d45fd7278ed7298928a15e5d1ca0d318","raw_frame":"{\"market\":\"0x717c0e8ccd4d5c7040185188fbae28be901ca589a11a94b1b38ca36a79eccfeb\", \"price_changes\":[{\"asset_id\":\"24254094493625419915756280046002869097156693848522361803041977572204227262166\", \"price\":\"0.78\", \"size\":\"107\", \"side\":\"BUY\", \"hash\":\"73c27d186ac39169cb6c6c8eea1102819ba3df19\", \"best_bid\":\"0.84\", \"best_ask\":\"0.86\"}, {\"asset_id\":\"41448400836309843603620980831210604935021861034693225347475867885462478926555\", \"price\":\"0.22\", \"size\":\"107\", \"side\":\"SELL\", \"hash\":\"503939480168110ea12627e0d1f221a87d55fce1\", \"best_bid\":\"0.14\", \"best_ask\":\"0.16\"}], \"timestamp\":\"1785122806671\", \"event_type\":\"price_change\"}","received_at":"2026-07-27T03:26:46.630898Z","schema_version":"clob-market-ws.price_change.v1","sequence":null,"server_hash":null,"server_timestamp":"1785122806671","session_id":"dd162b8dca5f43ff811d304e69a06123","source":"clob_market_ws"},"received_at":"2026-07-27T03:26:46.630898Z","record_id":"11815193c3b9e6856e48a4192c9b04c26345faa49e6dea930ccbe15e21cca8d5","schema_fingerprint":"4aa3821a28b0b7c2400bc59aba4bcc0a76e971dadd19610d3ad38c768e124dc7","schema_version":"edge-lab-recorder.raw.v1","sequence":null,"source":"clob_market_ws"}
{"event_at":"2026-07-27T03:26:46.688000Z","event_fingerprint":"d04057d86dee31c4b22d64b77cf26a4968417aa70e1e69a7d96e92237949eff1","payload":{"connection_id":"c7dc2e4762f849c6b6f9306b6518dcab","event_at":"2026-07-27T03:26:46.688000Z","event_type":"price_change","frame_hash":"869ed476de54e3861a1bd242fe626301ef651bf24f745bf3eb7f8905e1dc4620","frame_index":0,"kind":"data","monotonic_ns":224789994644083,"payload":{"event_type":"price_change","market":"0x717c0e8ccd4d5c7040185188fbae28be901ca589a11a94b1b38ca36a79eccfeb","price_changes":[{"asset_id":"24254094493625419915756280046002869097156693848522361803041977572204227262166","best_ask":"0.86","best_bid":"0.84","hash":"dfb236535ff1b72557b40e948f309caaa1710e53","price":"0.84","side":"BUY","size":"111.53"},{"asset_id":"41448400836309843603620980831210604935021861034693225347475867885462478926555","best_ask":"0.16","best_bid":"0.14","hash":"d5378c64d7eee4a2eb409ef80fa3e4d2fd1df67a","price":"0.16","side":"SELL","size":"111.53"}],"timestamp":"1785122806688"},"payload_hash":"56636bdcedcc138aea088ccd4fe7a497c864423d83baacb576b8f0d522ee5065","raw_frame":"{\"market\":\"0x717c0e8ccd4d5c7040185188fbae28be901ca589a11a94b1b38ca36a79eccfeb\", \"price_changes\":[{\"asset_id\":\"24254094493625419915756280046002869097156693848522361803041977572204227262166\", \"price\":\"0.84\", \"size\":\"111.53\", \"side\":\"BUY\", \"hash\":\"dfb236535ff1b72557b40e948f309caaa1710e53\", \"best_bid\":\"0.84\", \"best_ask\":\"0.86\"}, {\"asset_id\":\"41448400836309843603620980831210604935021861034693225347475867885462478926555\", \"price\":\"0.16\", \"size\":\"111.53\", \"side\":\"SELL\", \"hash\":\"d5378c64d7eee4a2eb409ef80fa3e4d2fd1df67a\", \"best_bid\":\"0.14\", \"best_ask\":\"0.16\"}], \"timestamp\":\"1785122806688\", \"event_type\":\"price_change\"}","received_at":"2026-07-27T03:26:46.634107Z","schema_version":"clob-market-ws.price_change.v1","sequence":null,"server_hash":null,"server_timestamp":"1785122806688","session_id":"dd162b8dca5f43ff811d304e69a06123","source":"clob_market_ws"},"received_at":"2026-07-27T03:26:46.634107Z","record_id":"bb5010da3864b294bf94bee17db2b79d5b37ba0d75aeb01a9c0c0612809e5d2e","schema_fingerprint":"4aa3821a28b0b7c2400bc59aba4bcc0a76e971dadd19610d3ad38c768e124dc7","schema_version":"edge-lab-recorder.raw.v1","sequence":null,"source":"clob_market_ws"}
{"event_at":"2026-07-27T03:26:46.697000Z","event_fingerprint":"e4ee472b8b4f096a2dac610ad3423356890397b9414c5cde97cde69a94c47e9b","payload":{"connection_id":"c7dc2e4762f849c6b6f9306b6518dcab","event_at":"2026-07-27T03:26:46.697000Z","event_type":"price_change","frame_hash":"b30cece158fcfaa228cef0943625918e1eab1929a6f0c976e9a695a34406c893","frame_index":0,"kind":"data","monotonic_ns":224790017773791,"payload":{"event_type":"price_change","market":"0x717c0e8ccd4d5c7040185188fbae28be901ca589a11a94b1b38ca36a79eccfeb","price_changes":[{"asset_id":"24254094493625419915756280046002869097156693848522361803041977572204227262166","best_ask":"0.86","best_bid":"0.84","hash":"d1559f36f9e2b5542cdd577cc138984a4da936ca","price":"0.04","side":"BUY","size":"505"},{"asset_id":"41448400836309843603620980831210604935021861034693225347475867885462478926555","best_ask":"0.16","best_bid":"0.14","hash":"973494414b6974ae2edba938f7ff534324f4804c","price":"0.96","side":"SELL","size":"505"}],"timestamp":"1785122806697"},"payload_hash":"aade82a6b8ede5e709036b37cbef39cba2fc13e890b348d967fd23df1752050e","raw_frame":"{\"market\":\"0x717c0e8ccd4d5c7040185188fbae28be901ca589a11a94b1b38ca36a79eccfeb\", \"price_changes\":[{\"asset_id\":\"24254094493625419915756280046002869097156693848522361803041977572204227262166\", \"price\":\"0.04\", \"size\":\"505\", \"side\":\"BUY\", \"hash\":\"d1559f36f9e2b5542cdd577cc138984a4da936ca\", \"best_bid\":\"0.84\", \"best_ask\":\"0.86\"}, {\"asset_id\":\"41448400836309843603620980831210604935021861034693225347475867885462478926555\", \"price\":\"0.96\", \"size\":\"505\", \"side\":\"SELL\", \"hash\":\"973494414b6974ae2edba938f7ff534324f4804c\", \"best_bid\":\"0.14\", \"best_ask\":\"0.16\"}], \"timestamp\":\"1785122806697\", \"event_type\":\"price_change\"}","received_at":"2026-07-27T03:26:46.657241Z","schema_version":"clob-market-ws.price_change.v1","sequence":null,"server_hash":null,"server_timestamp":"1785122806697","session_id":"dd162b8dca5f43ff811d304e69a06123","source":"clob_market_ws"},"received_at":"2026-07-27T03:26:46.657241Z","record_id":"07d56a0331574f3f23531f95e694f47728d74d175b6b5ba440c6e100c95bb28c","schema_fingerprint":"4aa3821a28b0b7c2400bc59aba4bcc0a76e971dadd19610d3ad38c768e124dc7","schema_version":"edge-lab-recorder.raw.v1","sequence":null,"source":"clob_market_ws"}
{"event_at":"2026-07-27T03:26:46.718000Z","event_fingerprint":"370cb28d8ea4e957c3855750fe9e3c78178f6443aa3009d039508cf001ddf1d8","payload":{"connection_id":"c7dc2e4762f849c6b6f9306b6518dcab","event_at":"2026-07-27T03:26:46.718000Z","event_type":"price_change","frame_hash":"11a8f8ff0bb63d18eedb4d8f01effea01ef60c082066bf5be95d3131069c60ce","frame_index":0,"kind":"data","monotonic_ns":224790022499750,"payload":{"event_type":"price_change","market":"0x717c0e8ccd4d5c7040185188fbae28be901ca589a11a94b1b38ca36a79eccfeb","price_changes":[{"asset_id":"41448400836309843603620980831210604935021861034693225347475867885462478926555","best_ask":"0.16","best_bid":"0.14","hash":"7e386fd6da124629188eb524b3e22b5311d5572f","price":"0.18","side":"SELL","size":"73.98"},{"asset_id":"24254094493625419915756280046002869097156693848522361803041977572204227262166","best_ask":"0.86","best_bid":"0.84","hash":"b16ec7d32a9ebd60d6c8255c550b685932b831bd","price":"0.82","side":"BUY","size":"73.98"}],"timestamp":"1785122806718"},"payload_hash":"9333dcfed0dfcd9b496f6c21d52151ac43ff5b69b7c302f39fde5de4c26af96e","raw_frame":"{\"market\":\"0x717c0e8ccd4d5c7040185188fbae28be901ca589a11a94b1b38ca36a79eccfeb\", \"price_changes\":[{\"asset_id\":\"41448400836309843603620980831210604935021861034693225347475867885462478926555\", \"price\":\"0.18\", \"size\":\"73.98\", \"side\":\"SELL\", \"hash\":\"7e386fd6da124629188eb524b3e22b5311d5572f\", \"best_bid\":\"0.14\", \"best_ask\":\"0.16\"}, {\"asset_id\":\"24254094493625419915756280046002869097156693848522361803041977572204227262166\", \"price\":\"0.82\", \"size\":\"73.98\", \"side\":\"BUY\", \"hash\":\"b16ec7d32a9ebd60d6c8255c550b685932b831bd\", \"best_bid\":\"0.84\", \"best_ask\":\"0.86\"}], \"timestamp\":\"1785122806718\", \"event_type\":\"price_change\"}","received_at":"2026-07-27T03:26:46.661967Z","schema_version":"clob-market-ws.price_change.v1","sequence":null,"server_hash":null,"server_timestamp":"1785122806718","session_id":"dd162b8dca5f43ff811d304e69a06123","source":"clob_market_ws"},"received_at":"2026-07-27T03:26:46.661967Z","record_id":"9b8341ec07d404ad1d6a96355a0f6ab0000ecd463b6036d2bb805113324f89f9","schema_fingerprint":"4aa3821a28b0b7c2400bc59aba4bcc0a76e971dadd19610d3ad38c768e124dc7","schema_version":"edge-lab-recorder.raw.v1","sequence":null,"source":"clob_market_ws"}
{"event_at":"2026-07-27T03:26:46.720000Z","event_fingerprint":"54e35b2a712e4514a711f7d06c33c1986efa540d802d9db09423a85c4cee3e63","payload":{"connection_id":"c7dc2e4762f849c6b6f9306b6518dcab","event_at":"2026-07-27T03:26:46.720000Z","event_type":"price_change","frame_hash":"ca9305d4efcdf03b511039059829f120df4e99f2f3c691407f3bd65f9332b0cd","frame_index":0,"kind":"data","monotonic_ns":224790028020291,"payload":{"event_type":"price_change","market":"0x717c0e8ccd4d5c7040185188fbae28be901ca589a11a94b1b38ca36a79eccfeb","price_changes":[{"asset_id":"41448400836309843603620980831210604935021861034693225347475867885462478926555","best_ask":"0.16","best_bid":"0.14","hash":"94813a2bf3655877554f797392a6ffa26d41593b","price":"0.11","side":"BUY","size":"9.6"},{"asset_id":"24254094493625419915756280046002869097156693848522361803041977572204227262166","best_ask":"0.86","best_bid":"0.84","hash":"86fef6b498943a25be39ec4b6b7fdb2cecf4770b","price":"0.89","side":"SELL","size":"9.6"}],"timestamp":"1785122806720"},"payload_hash":"c57505874c1b099eb3909b2368f6b27e48b99079e4c17d05a2a683548846a8ab","raw_frame":"{\"market\":\"0x717c0e8ccd4d5c7040185188fbae28be901ca589a11a94b1b38ca36a79eccfeb\", \"price_changes\":[{\"asset_id\":\"41448400836309843603620980831210604935021861034693225347475867885462478926555\", \"price\":\"0.11\", \"size\":\"9.6\", \"side\":\"BUY\", \"hash\":\"94813a2bf3655877554f797392a6ffa26d41593b\", \"best_bid\":\"0.14\", \"best_ask\":\"0.16\"}, {\"asset_id\":\"24254094493625419915756280046002869097156693848522361803041977572204227262166\", \"price\":\"0.89\", \"size\":\"9.6\", \"side\":\"SELL\", \"hash\":\"86fef6b498943a25be39ec4b6b7fdb2cecf4770b\", \"best_bid\":\"0.84\", \"best_ask\":\"0.86\"}], \"timestamp\":\"1785122806720\", \"event_type\":\"price_change\"}","received_at":"2026-07-27T03:26:46.667487Z","schema_version":"clob-market-ws.price_change.v1","sequence":null,"server_hash":null,"server_timestamp":"1785122806720","session_id":"dd162b8dca5f43ff811d304e69a06123","source":"clob_market_ws"},"received_at":"2026-07-27T03:26:46.667487Z","record_id":"94c9f2b8b9a573650104fd42fef78a82cf849b141de1f0d9ab39bca8a267f6cf","schema_fingerprint":"4aa3821a28b0b7c2400bc59aba4bcc0a76e971dadd19610d3ad38c768e124dc7","schema_version":"edge-lab-recorder.raw.v1","sequence":null,"source":"clob_market_ws"}
{"event_at":"2026-07-27T03:26:46.721000Z","event_fingerprint":"a49765fd53d5e8b2b3d00a19a551da1f8f1b554ca0e039bdf5564d66224267e4","payload":{"connection_id":"c7dc2e4762f849c6b6f9306b6518dcab","event_at":"2026-07-27T03:26:46.721000Z","event_type":"price_change","frame_hash":"e8e6d76bb9157681846583bdd08052baccebd4d17cdc794eea5b40e0df5d46a4","frame_index":0,"kind":"data","monotonic_ns":224790031644500,"payload":{"event_type":"price_change","market":"0x717c0e8ccd4d5c7040185188fbae28be901ca589a11a94b1b38ca36a79eccfeb","price_changes":[{"asset_id":"24254094493625419915756280046002869097156693848522361803041977572204227262166","best_ask":"0.86","best_bid":"0.84","hash":"bf5643fde1ae766593e00b2c4c6bbb4499c463ac","price":"0.89","side":"SELL","size":"25.6"},{"asset_id":"41448400836309843603620980831210604935021861034693225347475867885462478926555","best_ask":"0.16","best_bid":"0.14","hash":"445bbfa7664e44314d4df71f8d50a154bbc9af13","price":"0.11","side":"BUY","size":"25.6"}],"timestamp":"1785122806721"},"payload_hash":"8eed016fbfe0c38dab59ba5b3dab4e06b1eb87627f8ff8b4de02ae9cb8a6f6e1","raw_frame":"{\"market\":\"0x717c0e8ccd4d5c7040185188fbae28be901ca589a11a94b1b38ca36a79eccfeb\", \"price_changes\":[{\"asset_id\":\"24254094493625419915756280046002869097156693848522361803041977572204227262166\", \"price\":\"0.89\", \"size\":\"25.6\", \"side\":\"SELL\", \"hash\":\"bf5643fde1ae766593e00b2c4c6bbb4499c463ac\", \"best_bid\":\"0.84\", \"best_ask\":\"0.86\"}, {\"asset_id\":\"41448400836309843603620980831210604935021861034693225347475867885462478926555\", \"price\":\"0.11\", \"size\":\"25.6\", \"side\":\"BUY\", \"hash\":\"445bbfa7664e44314d4df71f8d50a154bbc9af13\", \"best_bid\":\"0.14\", \"best_ask\":\"0.16\"}], \"timestamp\":\"1785122806721\", \"event_type\":\"price_change\"}","received_at":"2026-07-27T03:26:46.671111Z","schema_version":"clob-market-ws.price_change.v1","sequence":null,"server_hash":null,"server_timestamp":"1785122806721","session_id":"dd162b8dca5f43ff811d304e69a06123","source":"clob_market_ws"},"received_at":"2026-07-27T03:26:46.671111Z","record_id":"00ff1ef07a6bdf8bd73020208d1045ca78cc932dfb8ca0a12f8502a3ed78cc22","schema_fingerprint":"4aa3821a28b0b7c2400bc59aba4bcc0a76e971dadd19610d3ad38c768e124dc7","schema_version":"edge-lab-recorder.raw.v1","sequence":null,"source":"clob_market_ws"}
{"event_at":"2026-07-27T03:26:46.740000Z","event_fingerprint":"4178a9d77db613ddb4bd78b0ad5abdd49d61c3e8387901c60a97ad4e2ae6ed79","payload":{"connection_id":"c7dc2e4762f849c6b6f9306b6518dcab","event_at":"2026-07-27T03:26:46.740000Z","event_type":"best_bid_ask","frame_hash":"562047ac4b54f4f825eda2acd1bc647626eabdcd61c4d749aa75d5e72f4688e0","frame_index":0,"kind":"data","monotonic_ns":224790036973625,"payload":{"asset_id":"24254094493625419915756280046002869097156693848522361803041977572204227262166","best_ask":"0.85","best_bid":"0.84","event_type":"best_bid_ask","market":"0x717c0e8ccd4d5c7040185188fbae28be901ca589a11a94b1b38ca36a79eccfeb","spread":"0.01","timestamp":"1785122806740"},"payload_hash":"d5930625c3be34bc204e722db9e7fd6a9f625095551a481f29aa14c9b08531c9","raw_frame":"{\"market\":\"0x717c0e8ccd4d5c7040185188fbae28be901ca589a11a94b1b38ca36a79eccfeb\", \"asset_id\":\"24254094493625419915756280046002869097156693848522361803041977572204227262166\", \"best_bid\":\"0.84\", \"best_ask\":\"0.85\", \"spread\":\"0.01\", \"timestamp\":\"1785122806740\", \"event_type\":\"best_bid_ask\"}","received_at":"2026-07-27T03:26:46.676439Z","schema_version":"clob-market-ws.best_bid_ask.v1","sequence":null,"server_hash":null,"server_timestamp":"1785122806740","session_id":"dd162b8dca5f43ff811d304e69a06123","source":"clob_market_ws"},"received_at":"2026-07-27T03:26:46.676439Z","record_id":"29f1667bf97fa3c4db82f00b8e04378e6ae5aa74524cb2984bd88491d5388f5e","schema_fingerprint":"8488399f31b0337811b13b266be932db7062827c2470b78bd8e9e99bab51d17d","schema_version":"edge-lab-recorder.raw.v1","sequence":null,"source":"clob_market_ws"}
{"event_at":"2026-07-27T03:26:46.740000Z","event_fingerprint":"03d640d22f41807c866fd9c382d2a219113de6fff71b8da049e226886c448d66","payload":{"connection_id":"c7dc2e4762f849c6b6f9306b6518dcab","event_at":"2026-07-27T03:26:46.740000Z","event_type":"best_bid_ask","frame_hash":"131261b57d27569df8f6069a86aa8595b05c5eab63af4e70be678d43b41cb369","frame_index":0,"kind":"data","monotonic_ns":224790039743375,"payload":{"asset_id":"41448400836309843603620980831210604935021861034693225347475867885462478926555","best_ask":"0.16","best_bid":"0.15","event_type":"best_bid_ask","market":"0x717c0e8ccd4d5c7040185188fbae28be901ca589a11a94b1b38ca36a79eccfeb","spread":"0.01","timestamp":"1785122806740"},"payload_hash":"c0337c8bca46eb8be0a5913b30f2ed872f55d210ae854d5cf8c8fe0546f2d614","raw_frame":"{\"market\":\"0x717c0e8ccd4d5c7040185188fbae28be901ca589a11a94b1b38ca36a79eccfeb\", \"asset_id\":\"41448400836309843603620980831210604935021861034693225347475867885462478926555\", \"best_bid\":\"0.15\", \"best_ask\":\"0.16\", \"spread\":\"0.01\", \"timestamp\":\"1785122806740\", \"event_type\":\"best_bid_ask\"}","received_at":"2026-07-27T03:26:46.679209Z","schema_version":"clob-market-ws.best_bid_ask.v1","sequence":null,"server_hash":null,"server_timestamp":"1785122806740","session_id":"dd162b8dca5f43ff811d304e69a06123","source":"clob_market_ws"},"received_at":"2026-07-27T03:26:46.679209Z","record_id":"ea3221167c9134db0a154b6f5b0f175c4b6eee31b58e920e23745ece9a06bc6a","schema_fingerprint":"8488399f31b0337811b13b266be932db7062827c2470b78bd8e9e99bab51d17d","schema_version":"edge-lab-recorder.raw.v1","sequence":null,"source":"clob_market_ws"}
{"event_at":"2026-07-27T03:26:46.740000Z","event_fingerprint":"3866d1af67c6122926a1bff50e8e453f5fdb1214e67cb909acff3521b5760716","payload":{"connection_id":"c7dc2e4762f849c6b6f9306b6518dcab","event_at":"2026-07-27T03:26:46.740000Z","event_type":"price_change","frame_hash":"db319dbaa33ba6de4ae66a4e56e825bedf788fea21c0e579e3e01f7da2039687","frame_index":0,"kind":"data","monotonic_ns":224790042259791,"payload":{"event_type":"price_change","market":"0x717c0e8ccd4d5c7040185188fbae28be901ca589a11a94b1b38ca36a79eccfeb","price_changes":[{"asset_id":"41448400836309843603620980831210604935021861034693225347475867885462478926555","best_ask":"0.16","best_bid":"0.15","hash":"f5d4e4da828bc771db571976be1789cd5c550350","price":"0.15","side":"BUY","size":"10"},{"asset_id":"24254094493625419915756280046002869097156693848522361803041977572204227262166","best_ask":"0.85","best_bid":"0.84","hash":"2bca792a51f911a14e0eeda64fc3bbfe57b06f1c","price":"0.85","side":"SELL","size":"10"}],"timestamp":"1785122806740"},"payload_hash":"02ab11de95dde9b1887d8964593b04e47c5ea565e2c634a3ec1c323f15da3ec5","raw_frame":"{\"market\":\"0x717c0e8ccd4d5c7040185188fbae28be901ca589a11a94b1b38ca36a79eccfeb\", \"price_changes\":[{\"asset_id\":\"41448400836309843603620980831210604935021861034693225347475867885462478926555\", \"price\":\"0.15\", \"size\":\"10\", \"side\":\"BUY\", \"hash\":\"f5d4e4da828bc771db571976be1789cd5c550350\", \"best_bid\":\"0.15\", \"best_ask\":\"0.16\"}, {\"asset_id\":\"24254094493625419915756280046002869097156693848522361803041977572204227262166\", \"price\":\"0.85\", \"size\":\"10\", \"side\":\"SELL\", \"hash\":\"2bca792a51f911a14e0eeda64fc3bbfe57b06f1c\", \"best_bid\":\"0.84\", \"best_ask\":\"0.85\"}], \"timestamp\":\"1785122806740\", \"event_type\":\"price_change\"}","received_at":"2026-07-27T03:26:46.681723Z","schema_version":"clob-market-ws.price_change.v1","sequence":null,"server_hash":null,"server_timestamp":"1785122806740","session_id":"dd162b8dca5f43ff811d304e69a06123","source":"clob_market_ws"},"received_at":"2026-07-27T03:26:46.681723Z","record_id":"e6ee4f157898a30df7ceb84ff276f36400f8462520b83b45c6fdf23418b75e93","schema_fingerprint":"4aa3821a28b0b7c2400bc59aba4bcc0a76e971dadd19610d3ad38c768e124dc7","schema_version":"edge-lab-recorder.raw.v1","sequence":null,"source":"clob_market_ws"}
{"event_at":"2026-07-27T03:26:46.741000Z","event_fingerprint":"162e88212e1717a0fa19fcaf661eef8ed89fa24b2c3da8d8ba57edbc499eeadc","payload":{"connection_id":"c7dc2e4762f849c6b6f9306b6518dcab","event_at":"2026-07-27T03:26:46.741000Z","event_type":"price_change","frame_hash":"833fdd60dfae908fcf1924c29f735d0efdf3abf4522395c292a9b80ce70623f1","frame_index":0,"kind":"data","monotonic_ns":224790044568625,"payload":{"event_type":"price_change","market":"0x717c0e8ccd4d5c7040185188fbae28be901ca589a11a94b1b38ca36a79eccfeb","price_changes":[{"asset_id":"24254094493625419915756280046002869097156693848522361803041977572204227262166","best_ask":"0.85","best_bid":"0.84","hash":"8c2f7a5a3d94e7b9372b4d4385f1ca13f994807c","price":"0.78","side":"BUY","size":"117"},{"asset_id":"41448400836309843603620980831210604935021861034693225347475867885462478926555","best_ask":"0.16","best_bid":"0.15","hash":"d008d7012438216d967402b3b259df4a3bab4aaa","price":"0.22","side":"SELL","size":"117"}],"timestamp":"1785122806741"},"payload_hash":"9791173f856c6d349edd84cd2091425f3b6f8af496e43d937459f397d9586e83","raw_frame":"{\"market\":\"0x717c0e8ccd4d5c7040185188fbae28be901ca589a11a94b1b38ca36a79eccfeb\", \"price_changes\":[{\"asset_id\":\"24254094493625419915756280046002869097156693848522361803041977572204227262166\", \"price\":\"0.78\", \"size\":\"117\", \"side\":\"BUY\", \"hash\":\"8c2f7a5a3d94e7b9372b4d4385f1ca13f994807c\", \"best_bid\":\"0.84\", \"best_ask\":\"0.85\"}, {\"asset_id\":\"41448400836309843603620980831210604935021861034693225347475867885462478926555\", \"price\":\"0.22\", \"size\":\"117\", \"side\":\"SELL\", \"hash\":\"d008d7012438216d967402b3b259df4a3bab4aaa\", \"best_bid\":\"0.15\", \"best_ask\":\"0.16\"}], \"timestamp\":\"1785122806741\", \"event_type\":\"price_change\"}","received_at":"2026-07-27T03:26:46.684031Z","schema_version":"clob-market-ws.price_change.v1","sequence":null,"server_hash":null,"server_timestamp":"1785122806741","session_id":"dd162b8dca5f43ff811d304e69a06123","source":"clob_market_ws"},"received_at":"2026-07-27T03:26:46.684031Z","record_id":"3159e5ad4ca02ded6acba60fc9c3cb2a7a3b29f9f73aa5e8388b02e79eee1c44","schema_fingerprint":"4aa3821a28b0b7c2400bc59aba4bcc0a76e971dadd19610d3ad38c768e124dc7","schema_version":"edge-lab-recorder.raw.v1","sequence":null,"source":"clob_market_ws"}
{"event_at":"2026-07-27T03:26:46.746000Z","event_fingerprint":"c59657f5c71eaa6f6588efad0e4c03d4866b54dfa6dc3a4ad61df595c48cfc09","payload":{"connection_id":"c7dc2e4762f849c6b6f9306b6518dcab","event_at":"2026-07-27T03:26:46.746000Z","event_type":"price_change","frame_hash":"2e9bba79d17943abb2d12d0787555b18c2a302f37369a66c6d0553cbae93aaad","frame_index":0,"kind":"data","monotonic_ns":224790046405625,"payload":{"event_type":"price_change","market":"0x717c0e8ccd4d5c7040185188fbae28be901ca589a11a94b1b38ca36a79eccfeb","price_changes":[{"asset_id":"24254094493625419915756280046002869097156693848522361803041977572204227262166","best_ask":"0.85","best_bid":"0.84","hash":"723ea734de3489d4cc0c1b0ef110f403eaaa5e28","price":"0.04","side":"BUY","size":"500"},{"asset_id":"41448400836309843603620980831210604935021861034693225347475867885462478926555","best_ask":"0.16","best_bid":"0.15","hash":"810784cae7bd0650c7bcd082f4dd4edc52f38cd2","price":"0.96","side":"SELL","size":"500"}],"timestamp":"1785122806746"},"payload_hash":"0f5739d5a4884caf3a422964b6185f194e1c87accc497f1ed29c2ecd5d59cfc3","raw_frame":"{\"market\":\"0x717c0e8ccd4d5c7040185188fbae28be901ca589a11a94b1b38ca36a79eccfeb\", \"price_changes\":[{\"asset_id\":\"24254094493625419915756280046002869097156693848522361803041977572204227262166\", \"price\":\"0.04\", \"size\":\"500\", \"side\":\"BUY\", \"hash\":\"723ea734de3489d4cc0c1b0ef110f403eaaa5e28\", \"best_bid\":\"0.84\", \"best_ask\":\"0.85\"}, {\"asset_id\":\"41448400836309843603620980831210604935021861034693225347475867885462478926555\", \"price\":\"0.96\", \"size\":\"500\", \"side\":\"SELL\", \"hash\":\"810784cae7bd0650c7bcd082f4dd4edc52f38cd2\", \"best_bid\":\"0.15\", \"best_ask\":\"0.16\"}], \"timestamp\":\"1785122806746\", \"event_type\":\"price_change\"}","received_at":"2026-07-27T03:26:46.685871Z","schema_version":"clob-market-ws.price_change.v1","sequence":null,"server_hash":null,"server_timestamp":"1785122806746","session_id":"dd162b8dca5f43ff811d304e69a06123","source":"clob_market_ws"},"received_at":"2026-07-27T03:26:46.685871Z","record_id":"43510bb072bc728db30edc7891acdd7799811b0f994822086d98ddb953e90756","schema_fingerprint":"4aa3821a28b0b7c2400bc59aba4bcc0a76e971dadd19610d3ad38c768e124dc7","schema_version":"edge-lab-recorder.raw.v1","sequence":null,"source":"clob_market_ws"}
{"event_at":"2026-07-27T03:26:46.766000Z","event_fingerprint":"26001df70c9b8aff281e6b0f3a607304c0cbd14ee6fbbf4c1260a0a9e948e975","payload":{"connection_id":"c7dc2e4762f849c6b6f9306b6518dcab","event_at":"2026-07-27T03:26:46.766000Z","event_type":"price_change","frame_hash":"2aa8e58888fc41be023961e9ca6cd2a9b1235a84abb77c9f300a6ae9a50b1063","frame_index":0,"kind":"data","monotonic_ns":224790051234791,"payload":{"event_type":"price_change","market":"0x717c0e8ccd4d5c7040185188fbae28be901ca589a11a94b1b38ca36a79eccfeb","price_changes":[{"asset_id":"24254094493625419915756280046002869097156693848522361803041977572204227262166","best_ask":"0.85","best_bid":"0.84","hash":"7a6222133456220b3067fd017d999f769ad81221","price":"0.84","side":"BUY","size":"116.53"},{"asset_id":"41448400836309843603620980831210604935021861034693225347475867885462478926555","best_ask":"0.16","best_bid":"0.15","hash":"beacfeae02c99b1a9c84badcf098ebf2e609e1e9","price":"0.16","side":"SELL","size":"116.53"}],"timestamp":"1785122806766"},"payload_hash":"3d64303bd513fd6c6598016c2093477ac5ac33b1a7c45d49fccedb5694244e45","raw_frame":"{\"market\":\"0x717c0e8ccd4d5c7040185188fbae28be901ca589a11a94b1b38ca36a79eccfeb\", \"price_changes\":[{\"asset_id\":\"24254094493625419915756280046002869097156693848522361803041977572204227262166\", \"price\":\"0.84\", \"size\":\"116.53\", \"side\":\"BUY\", \"hash\":\"7a6222133456220b3067fd017d999f769ad81221\", \"best_bid\":\"0.84\", \"best_ask\":\"0.85\"}, {\"asset_id\":\"41448400836309843603620980831210604935021861034693225347475867885462478926555\", \"price\":\"0.16\", \"size\":\"116.53\", \"side\":\"SELL\", \"hash\":\"beacfeae02c99b1a9c84badcf098ebf2e609e1e9\", \"best_bid\":\"0.15\", \"best_ask\":\"0.16\"}], \"timestamp\":\"1785122806766\", \"event_type\":\"price_change\"}","received_at":"2026-07-27T03:26:46.690699Z","schema_version":"clob-market-ws.price_change.v1","sequence":null,"server_hash":null,"server_timestamp":"1785122806766","session_id":"dd162b8dca5f43ff811d304e69a06123","source":"clob_market_ws"},"received_at":"2026-07-27T03:26:46.690699Z","record_id":"6372abf695f571026109d91f56fb0ebf6805e8bec3bec722f46427f2566d7f3d","schema_fingerprint":"4aa3821a28b0b7c2400bc59aba4bcc0a76e971dadd19610d3ad38c768e124dc7","schema_version":"edge-lab-recorder.raw.v1","sequence":null,"source":"clob_market_ws"}
{"event_at":"2026-07-27T03:26:46.779000Z","event_fingerprint":"8da6e34b893508c8a2ffef7c28b8fd2f0e2975f53d364fa4f4993f5a1015ee6c","payload":{"connection_id":"c7dc2e4762f849c6b6f9306b6518dcab","event_at":"2026-07-27T03:26:46.779000Z","event_type":"best_bid_ask","frame_hash":"3b5d35af24f06cbb2dfe1781c353816b31ef7548afe6a5df8e70d444502d25fb","frame_index":0,"kind":"data","monotonic_ns":224790052842916,"payload":{"asset_id":"24254094493625419915756280046002869097156693848522361803041977572204227262166","best_ask":"0.86","best_bid":"0.84","event_type":"best_bid_ask","market":"0x717c0e8ccd4d5c7040185188fbae28be901ca589a11a94b1b38ca36a79eccfeb","spread":"0.02","timestamp":"1785122806779"},"payload_hash":"08f053b2f859f7b0fa5fdd1acfd2067a624b25189c37946b7dc914a4692f1a9f","raw_frame":"{\"market\":\"0x717c0e8ccd4d5c7040185188fbae28be901ca589a11a94b1b38ca36a79eccfeb\", \"asset_id\":\"24254094493625419915756280046002869097156693848522361803041977572204227262166\", \"best_bid\":\"0.84\", \"best_ask\":\"0.86\", \"spread\":\"0.02\", \"timestamp\":\"1785122806779\", \"event_type\":\"best_bid_ask\"}","received_at":"2026-07-27T03:26:46.692309Z","schema_version":"clob-market-ws.best_bid_ask.v1","sequence":null,"server_hash":null,"server_timestamp":"1785122806779","session_id":"dd162b8dca5f43ff811d304e69a06123","source":"clob_market_ws"},"received_at":"2026-07-27T03:26:46.692309Z","record_id":"b3c36f2a1b78934321ccffd60fa9132864297c46f499bd06d5292bce5224d407","schema_fingerprint":"8488399f31b0337811b13b266be932db7062827c2470b78bd8e9e99bab51d17d","schema_version":"edge-lab-recorder.raw.v1","sequence":null,"source":"clob_market_ws"}
{"event_at":"2026-07-27T03:26:46.779000Z","event_fingerprint":"3d9d3fa8a549c746b59dc971984917188d06edfdb6c5d32549be1729c510ec5a","payload":{"connection_id":"c7dc2e4762f849c6b6f9306b6518dcab","event_at":"2026-07-27T03:26:46.779000Z","event_type":"best_bid_ask","frame_hash":"5f95e504e71caa926d3ad22e2d317d706dc3e5c7c139bbd493c24946b6800797","frame_index":0,"kind":"data","monotonic_ns":224790054148000,"payload":{"asset_id":"41448400836309843603620980831210604935021861034693225347475867885462478926555","best_ask":"0.16","best_bid":"0.14","event_type":"best_bid_ask","market":"0x717c0e8ccd4d5c7040185188fbae28be901ca589a11a94b1b38ca36a79eccfeb","spread":"0.02","timestamp":"1785122806779"},"payload_hash":"4098b5a4e3615431eacf037acf911fa416783d1a6f2dcb74fd3e49f189d1707f","raw_frame":"{\"market\":\"0x717c0e8ccd4d5c7040185188fbae28be901ca589a11a94b1b38ca36a79eccfeb\", \"asset_id\":\"41448400836309843603620980831210604935021861034693225347475867885462478926555\", \"best_bid\":\"0.14\", \"best_ask\":\"0.16\", \"spread\":\"0.02\", \"timestamp\":\"1785122806779\", \"event_type\":\"best_bid_ask\"}","received_at":"2026-07-27T03:26:46.693615Z","schema_version":"clob-market-ws.best_bid_ask.v1","sequence":null,"server_hash":null,"server_timestamp":"1785122806779","session_id":"dd162b8dca5f43ff811d304e69a06123","source":"clob_market_ws"},"received_at":"2026-07-27T03:26:46.693615Z","record_id":"7f3bfa44bd7d48046511d2131921c55604ff4bd0ed0f6a669ca4b8b9a6f4f746","schema_fingerprint":"8488399f31b0337811b13b266be932db7062827c2470b78bd8e9e99bab51d17d","schema_version":"edge-lab-recorder.raw.v1","sequence":null,"source":"clob_market_ws"}
{"event_at":"2026-07-27T03:26:46.778000Z","event_fingerprint":"ddf9e4e9d69d061eca477b74bc7119388b000bb1d83442fd8655bf3bc417fb1c","payload":{"connection_id":"c7dc2e4762f849c6b6f9306b6518dcab","event_at":"2026-07-27T03:26:46.778000Z","event_type":"price_change","frame_hash":"fa3ccd6c9988577c976142693337cdc6cf768305921d3a22c6523ca98db2881a","frame_index":0,"kind":"data","monotonic_ns":224790055297166,"payload":{"event_type":"price_change","market":"0x717c0e8ccd4d5c7040185188fbae28be901ca589a11a94b1b38ca36a79eccfeb","price_changes":[{"asset_id":"41448400836309843603620980831210604935021861034693225347475867885462478926555","best_ask":"0.16","best_bid":"0.14","hash":"c80c7edd8167b357d0cf72c3bd7cf5c15527efa4","price":"0.15","side":"BUY","size":"0"},{"asset_id":"24254094493625419915756280046002869097156693848522361803041977572204227262166","best_ask":"0.86","best_bid":"0.84","hash":"58155a470c5e04dec450fb1e5138d4c2aa536695","price":"0.85","side":"SELL","size":"0"}],"timestamp":"1785122806778"},"payload_hash":"abe2cd846893dec15874d1d3e4c6bde28c00efd05edde9e67ea20f010f3194c2","raw_frame":"{\"market\":\"0x717c0e8ccd4d5c7040185188fbae28be901ca589a11a94b1b38ca36a79eccfeb\", \"price_changes\":[{\"asset_id\":\"41448400836309843603620980831210604935021861034693225347475867885462478926555\", \"price\":\"0.15\", \"size\":\"0\", \"side\":\"BUY\", \"hash\":\"c80c7edd8167b357d0cf72c3bd7cf5c15527efa4\", \"best_bid\":\"0.14\", \"best_ask\":\"0.16\"}, {\"asset_id\":\"24254094493625419915756280046002869097156693848522361803041977572204227262166\", \"price\":\"0.85\", \"size\":\"0\", \"side\":\"SELL\", \"hash\":\"58155a470c5e04dec450fb1e5138d4c2aa536695\", \"best_bid\":\"0.84\", \"best_ask\":\"0.86\"}], \"timestamp\":\"1785122806778\", \"event_type\":\"price_change\"}","received_at":"2026-07-27T03:26:46.694762Z","schema_version":"clob-market-ws.price_change.v1","sequence":null,"server_hash":null,"server_timestamp":"1785122806778","session_id":"dd162b8dca5f43ff811d304e69a06123","source":"clob_market_ws"},"received_at":"2026-07-27T03:26:46.694762Z","record_id":"9238f12d9c0d58a595621e7a6b49d9e8b1b98a163c0d58dfd715a4f4aa561274","schema_fingerprint":"4aa3821a28b0b7c2400bc59aba4bcc0a76e971dadd19610d3ad38c768e124dc7","schema_version":"edge-lab-recorder.raw.v1","sequence":null,"source":"clob_market_ws"}
{"event_at":"2026-07-27T03:26:46.796000Z","event_fingerprint":"0c323b2a83fa89d453130217e372e8642ffa53731c426a859161281cf20d3a5b","payload":{"connection_id":"c7dc2e4762f849c6b6f9306b6518dcab","event_at":"2026-07-27T03:26:46.796000Z","event_type":"price_change","frame_hash":"12b20c960ffceb407754539b656018decaeeef3a83b4cf7bcbf14911703ae40f","frame_index":0,"kind":"data","monotonic_ns":224790059152833,"payload":{"event_type":"price_change","market":"0x717c0e8ccd4d5c7040185188fbae28be901ca589a11a94b1b38ca36a79eccfeb","price_changes":[{"asset_id":"24254094493625419915756280046002869097156693848522361803041977572204227262166","best_ask":"0.86","best_bid":"0.84","hash":"1076ae1219e601f3ad998b4b0582405f055578a0","price":"0.84","side":"BUY","size":"111.53"},{"asset_id":"41448400836309843603620980831210604935021861034693225347475867885462478926555","best_ask":"0.16","best_bid":"0.14","hash":"b8e0d1398820a93911ee82590f169e7e1f756951","price":"0.16","side":"SELL","size":"111.53"}],"timestamp":"1785122806796"},"payload_hash":"10eb20daf38e1a453d26c256579071b01f4a78da64b08140343d7605a9cef779","raw_frame":"{\"market\":\"0x717c0e8ccd4d5c7040185188fbae28be901ca589a11a94b1b38ca36a79eccfeb\", \"price_changes\":[{\"asset_id\":\"24254094493625419915756280046002869097156693848522361803041977572204227262166\", \"price\":\"0.84\", \"size\":\"111.53\", \"side\":\"BUY\", \"hash\":\"1076ae1219e601f3ad998b4b0582405f055578a0\", \"best_bid\":\"0.84\", \"best_ask\":\"0.86\"}, {\"asset_id\":\"41448400836309843603620980831210604935021861034693225347475867885462478926555\", \"price\":\"0.16\", \"size\":\"111.53\", \"side\":\"SELL\", \"hash\":\"b8e0d1398820a93911ee82590f169e7e1f756951\", \"best_bid\":\"0.14\", \"best_ask\":\"0.16\"}], \"timestamp\":\"1785122806796\", \"event_type\":\"price_change\"}","received_at":"2026-07-27T03:26:46.698617Z","schema_version":"clob-market-ws.price_change.v1","sequence":null,"server_hash":null,"server_timestamp":"1785122806796","session_id":"dd162b8dca5f43ff811d304e69a06123","source":"clob_market_ws"},"received_at":"2026-07-27T03:26:46.698617Z","record_id":"81d85e332872c9e17f111a83371388a2d403887135de4bfec4b455d780fa2fb7","schema_fingerprint":"4aa3821a28b0b7c2400bc59aba4bcc0a76e971dadd19610d3ad38c768e124dc7","schema_version":"edge-lab-recorder.raw.v1","sequence":null,"source":"clob_market_ws"}
{"event_at":"2026-07-27T03:26:46.810000Z","event_fingerprint":"83f905a0e9add86da28cb34d970ecae4e765799ebc0520b1d48fbb966d251040","payload":{"connection_id":"c7dc2e4762f849c6b6f9306b6518dcab","event_at":"2026-07-27T03:26:46.810000Z","event_type":"price_change","frame_hash":"bdc52375dd94cff101fa0e5eede64322e1c0232e5cae14c9b999324d8853c79b","frame_index":0,"kind":"data","monotonic_ns":224790061182708,"payload":{"event_type":"price_change","market":"0x717c0e8ccd4d5c7040185188fbae28be901ca589a11a94b1b38ca36a79eccfeb","price_changes":[{"asset_id":"24254094493625419915756280046002869097156693848522361803041977572204227262166","best_ask":"0.86","best_bid":"0.84","hash":"3428f47a3aa32d304f11bf5391923d8f5cf2dcbb","price":"0.78","side":"BUY","size":"107"},{"asset_id":"41448400836309843603620980831210604935021861034693225347475867885462478926555","best_ask":"0.16","best_bid":"0.14","hash":"3e13ac1e22e11df78b3b3d27dc0eb8977f0876fc","price":"0.22","side":"SELL","size":"107"}],"timestamp":"1785122806810"},"payload_hash":"215baaf1e2a116112c82008a42f0593ff3c942087f5822a32b2a74af472e7536","raw_frame":"{\"market\":\"0x717c0e8ccd4d5c7040185188fbae28be901ca589a11a94b1b38ca36a79eccfeb\", \"price_changes\":[{\"asset_id\":\"24254094493625419915756280046002869097156693848522361803041977572204227262166\", \"price\":\"0.78\", \"size\":\"107\", \"side\":\"BUY\", \"hash\":\"3428f47a3aa32d304f11bf5391923d8f5cf2dcbb\", \"best_bid\":\"0.84\", \"best_ask\":\"0.86\"}, {\"asset_id\":\"41448400836309843603620980831210604935021861034693225347475867885462478926555\", \"price\":\"0.22\", \"size\":\"107\", \"side\":\"SELL\", \"hash\":\"3e13ac1e22e11df78b3b3d27dc0eb8977f0876fc\", \"best_bid\":\"0.14\", \"best_ask\":\"0.16\"}], \"timestamp\":\"1785122806810\", \"event_type\":\"price_change\"}","received_at":"2026-07-27T03:26:46.700648Z","schema_version":"clob-market-ws.price_change.v1","sequence":null,"server_hash":null,"server_timestamp":"1785122806810","session_id":"dd162b8dca5f43ff811d304e69a06123","source":"clob_market_ws"},"received_at":"2026-07-27T03:26:46.700648Z","record_id":"28ebb50363b3db55e273a2135635ef485faee65b76c7a47504455e0353c3e37d","schema_fingerprint":"4aa3821a28b0b7c2400bc59aba4bcc0a76e971dadd19610d3ad38c768e124dc7","schema_version":"edge-lab-recorder.raw.v1","sequence":null,"source":"clob_market_ws"}
{"event_at":"2026-07-27T03:26:46.820000Z","event_fingerprint":"25b04a4788172faf999fe2bdedb2210da5ac8c9aff9bec8db8cb0e8625207cc1","payload":{"connection_id":"c7dc2e4762f849c6b6f9306b6518dcab","event_at":"2026-07-27T03:26:46.820000Z","event_type":"price_change","frame_hash":"68f2f18be4292ad8392f577ec2fec2977bf950ac4a0b5753a727a220799772e2","frame_index":0,"kind":"data","monotonic_ns":224790062822666,"payload":{"event_type":"price_change","market":"0x717c0e8ccd4d5c7040185188fbae28be901ca589a11a94b1b38ca36a79eccfeb","price_changes":[{"asset_id":"24254094493625419915756280046002869097156693848522361803041977572204227262166","best_ask":"0.86","best_bid":"0.84","hash":"98379f205907cf331059b0666c4ef4fa6e67cd57","price":"0.03","side":"BUY","size":"515"},{"asset_id":"41448400836309843603620980831210604935021861034693225347475867885462478926555","best_ask":"0.16","best_bid":"0.14","hash":"094fe3f8065e52c657ab8ed08afc86a56910572f","price":"0.97","side":"SELL","size":"515"}],"timestamp":"1785122806820"},"payload_hash":"e1a5ad2e637fc9a255988502f40fb2fd9a35df09c8987e54a36f30c6ca1502bd","raw_frame":"{\"market\":\"0x717c0e8ccd4d5c7040185188fbae28be901ca589a11a94b1b38ca36a79eccfeb\", \"price_changes\":[{\"asset_id\":\"24254094493625419915756280046002869097156693848522361803041977572204227262166\", \"price\":\"0.03\", \"size\":\"515\", \"side\":\"BUY\", \"hash\":\"98379f205907cf331059b0666c4ef4fa6e67cd57\", \"best_bid\":\"0.84\", \"best_ask\":\"0.86\"}, {\"asset_id\":\"41448400836309843603620980831210604935021861034693225347475867885462478926555\", \"price\":\"0.97\", \"size\":\"515\", \"side\":\"SELL\", \"hash\":\"094fe3f8065e52c657ab8ed08afc86a56910572f\", \"best_bid\":\"0.14\", \"best_ask\":\"0.16\"}], \"timestamp\":\"1785122806820\", \"event_type\":\"price_change\"}","received_at":"2026-07-27T03:26:46.702287Z","schema_version":"clob-market-ws.price_change.v1","sequence":null,"server_hash":null,"server_timestamp":"1785122806820","session_id":"dd162b8dca5f43ff811d304e69a06123","source":"clob_market_ws"},"received_at":"2026-07-27T03:26:46.702287Z","record_id":"357256589aa35e4a53ac5dbacdfbf44266e235eb33513b29b24488bb74229c0e","schema_fingerprint":"4aa3821a28b0b7c2400bc59aba4bcc0a76e971dadd19610d3ad38c768e124dc7","schema_version":"edge-lab-recorder.raw.v1","sequence":null,"source":"clob_market_ws"}
{"event_at":"2026-07-27T03:26:46.841000Z","event_fingerprint":"8303e204d75450505e3122d9899c043224bc70df56fc40fd5a12333e80995c0d","payload":{"connection_id":"c7dc2e4762f849c6b6f9306b6518dcab","event_at":"2026-07-27T03:26:46.841000Z","event_type":"price_change","frame_hash":"dfea61fd1eb1d8f37b87cd7af90814b0d56a215edf0c682444e15378b7b0308c","frame_index":0,"kind":"data","monotonic_ns":224790087598125,"payload":{"event_type":"price_change","market":"0x717c0e8ccd4d5c7040185188fbae28be901ca589a11a94b1b38ca36a79eccfeb","price_changes":[{"asset_id":"24254094493625419915756280046002869097156693848522361803041977572204227262166","best_ask":"0.86","best_bid":"0.84","hash":"50a8a52c00909cc673e71daa5aebc7a039c8140c","price":"0.78","side":"BUY","size":"117"},{"asset_id":"41448400836309843603620980831210604935021861034693225347475867885462478926555","best_ask":"0.16","best_bid":"0.14","hash":"e180f6c34eec4b92742b0f1b72ffac79a7482ead","price":"0.22","side":"SELL","size":"117"}],"timestamp":"1785122806841"},"payload_hash":"a6a15062ed8e6311227fc015cd59a7779bb1d717c3e5b32100d8e7c5497a58b9","raw_frame":"{\"market\":\"0x717c0e8ccd4d5c7040185188fbae28be901ca589a11a94b1b38ca36a79eccfeb\", \"price_changes\":[{\"asset_id\":\"24254094493625419915756280046002869097156693848522361803041977572204227262166\", \"price\":\"0.78\", \"size\":\"117\", \"side\":\"BUY\", \"hash\":\"50a8a52c00909cc673e71daa5aebc7a039c8140c\", \"best_bid\":\"0.84\", \"best_ask\":\"0.86\"}, {\"asset_id\":\"41448400836309843603620980831210604935021861034693225347475867885462478926555\", \"price\":\"0.22\", \"size\":\"117\", \"side\":\"SELL\", \"hash\":\"e180f6c34eec4b92742b0f1b72ffac79a7482ead\", \"best_bid\":\"0.14\", \"best_ask\":\"0.16\"}], \"timestamp\":\"1785122806841\", \"event_type\":\"price_change\"}","received_at":"2026-07-27T03:26:46.727063Z","schema_version":"clob-market-ws.price_change.v1","sequence":null,"server_hash":null,"server_timestamp":"1785122806841","session_id":"dd162b8dca5f43ff811d304e69a06123","source":"clob_market_ws"},"received_at":"2026-07-27T03:26:46.727063Z","record_id":"7b75b47cf79e256267d5c964a3b21b7475ac88fc1e87ca2db5061953412f10fa","schema_fingerprint":"4aa3821a28b0b7c2400bc59aba4bcc0a76e971dadd19610d3ad38c768e124dc7","schema_version":"edge-lab-recorder.raw.v1","sequence":null,"source":"clob_market_ws"}
{"event_at":"2026-07-27T03:26:46.842000Z","event_fingerprint":"a8d512c7279a3aa1bfea9e8f74e577cd20ec32a12ae1484b92407ce70684c05a","payload":{"connection_id":"c7dc2e4762f849c6b6f9306b6518dcab","event_at":"2026-07-27T03:26:46.842000Z","event_type":"best_bid_ask","frame_hash":"d36a107f9397b4b79ffeb0b982357f29b1afb34d3dfddae516d67f37e9e94fdb","frame_index":0,"kind":"data","monotonic_ns":224790090607291,"payload":{"asset_id":"24254094493625419915756280046002869097156693848522361803041977572204227262166","best_ask":"0.85","best_bid":"0.84","event_type":"best_bid_ask","market":"0x717c0e8ccd4d5c7040185188fbae28be901ca589a11a94b1b38ca36a79eccfeb","spread":"0.01","timestamp":"1785122806842"},"payload_hash":"853b9db57fc8a45b800752c4f1082665aa4495f2ff505119e3b9c0d83dd5bb57","raw_frame":"{\"market\":\"0x717c0e8ccd4d5c7040185188fbae28be901ca589a11a94b1b38ca36a79eccfeb\", \"asset_id\":\"24254094493625419915756280046002869097156693848522361803041977572204227262166\", \"best_bid\":\"0.84\", \"best_ask\":\"0.85\", \"spread\":\"0.01\", \"timestamp\":\"1785122806842\", \"event_type\":\"best_bid_ask\"}","received_at":"2026-07-27T03:26:46.730070Z","schema_version":"clob-market-ws.best_bid_ask.v1","sequence":null,"server_hash":null,"server_timestamp":"1785122806842","session_id":"dd162b8dca5f43ff811d304e69a06123","source":"clob_market_ws"},"received_at":"2026-07-27T03:26:46.730070Z","record_id":"6739cee51e88e794301fb0f4c61e4b1eef48ceb8c88cd76abf8572053168fcc4","schema_fingerprint":"8488399f31b0337811b13b266be932db7062827c2470b78bd8e9e99bab51d17d","schema_version":"edge-lab-recorder.raw.v1","sequence":null,"source":"clob_market_ws"}
{"event_at":"2026-07-27T03:26:46.842000Z","event_fingerprint":"ff39a28deb4228143b275a74e5692ed4a39a7125e47056b89a9cfed73551fb30","payload":{"connection_id":"c7dc2e4762f849c6b6f9306b6518dcab","event_at":"2026-07-27T03:26:46.842000Z","event_type":"best_bid_ask","frame_hash":"ab1930f0fba5d01de446497cd111db3253cd243072c2f4cef7234dcee6b2c7ff","frame_index":0,"kind":"data","monotonic_ns":224790093962333,"payload":{"asset_id":"41448400836309843603620980831210604935021861034693225347475867885462478926555","best_ask":"0.16","best_bid":"0.15","event_type":"best_bid_ask","market":"0x717c0e8ccd4d5c7040185188fbae28be901ca589a11a94b1b38ca36a79eccfeb","spread":"0.01","timestamp":"1785122806842"},"payload_hash":"b6a533936776a0c3175e1d8df8e9b84abd7f3ae5b7e5e20685f70786598c16c9","raw_frame":"{\"market\":\"0x717c0e8ccd4d5c7040185188fbae28be901ca589a11a94b1b38ca36a79eccfeb\", \"asset_id\":\"41448400836309843603620980831210604935021861034693225347475867885462478926555\", \"best_bid\":\"0.15\", \"best_ask\":\"0.16\", \"spread\":\"0.01\", \"timestamp\":\"1785122806842\", \"event_type\":\"best_bid_ask\"}","received_at":"2026-07-27T03:26:46.733425Z","schema_version":"clob-market-ws.best_bid_ask.v1","sequence":null,"server_hash":null,"server_timestamp":"1785122806842","session_id":"dd162b8dca5f43ff811d304e69a06123","source":"clob_market_ws"},"received_at":"2026-07-27T03:26:46.733425Z","record_id":"2bd2c8b732c58fe0f094dc7d4de758dbdb9f73248d8eb984623b7837e196a4e3","schema_fingerprint":"8488399f31b0337811b13b266be932db7062827c2470b78bd8e9e99bab51d17d","schema_version":"edge-lab-recorder.raw.v1","sequence":null,"source":"clob_market_ws"}
{"event_at":"2026-07-27T03:26:46.842000Z","event_fingerprint":"eb101f1c34553c6b9f74a26f5d7fb518cb5a2c0c490f6f0be279f61268e14362","payload":{"connection_id":"c7dc2e4762f849c6b6f9306b6518dcab","event_at":"2026-07-27T03:26:46.842000Z","event_type":"price_change","frame_hash":"4670eeae07e89386775f27b615a90e214179b77b6f021eff71fe198e748efb45","frame_index":0,"kind":"data","monotonic_ns":224790095616458,"payload":{"event_type":"price_change","market":"0x717c0e8ccd4d5c7040185188fbae28be901ca589a11a94b1b38ca36a79eccfeb","price_changes":[{"asset_id":"41448400836309843603620980831210604935021861034693225347475867885462478926555","best_ask":"0.16","best_bid":"0.15","hash":"7e87cc9aeb5c46a557f678e43ed5758dec21d6bb","price":"0.15","side":"BUY","size":"10"},{"asset_id":"24254094493625419915756280046002869097156693848522361803041977572204227262166","best_ask":"0.85","best_bid":"0.84","hash":"746ea091a91bbdd1d208f93890031995333902af","price":"0.85","side":"SELL","size":"10"}],"timestamp":"1785122806842"},"payload_hash":"b3122febba26301f9576390e01c081729a298ab70a1eeadb1b7c62f739df0762","raw_frame":"{\"market\":\"0x717c0e8ccd4d5c7040185188fbae28be901ca589a11a94b1b38ca36a79eccfeb\", \"price_changes\":[{\"asset_id\":\"41448400836309843603620980831210604935021861034693225347475867885462478926555\", \"price\":\"0.15\", \"size\":\"10\", \"side\":\"BUY\", \"hash\":\"7e87cc9aeb5c46a557f678e43ed5758dec21d6bb\", \"best_bid\":\"0.15\", \"best_ask\":\"0.16\"}, {\"asset_id\":\"24254094493625419915756280046002869097156693848522361803041977572204227262166\", \"price\":\"0.85\", \"size\":\"10\", \"side\":\"SELL\", \"hash\":\"746ea091a91bbdd1d208f93890031995333902af\", \"best_bid\":\"0.84\", \"best_ask\":\"0.85\"}], \"timestamp\":\"1785122806842\", \"event_type\":\"price_change\"}","received_at":"2026-07-27T03:26:46.735080Z","schema_version":"clob-market-ws.price_change.v1","sequence":null,"server_hash":null,"server_timestamp":"1785122806842","session_id":"dd162b8dca5f43ff811d304e69a06123","source":"clob_market_ws"},"received_at":"2026-07-27T03:26:46.735080Z","record_id":"57cea8f4b8897ea751c72a09a49fbfb7e48f0915d26804157c381f34b98ac8dd","schema_fingerprint":"4aa3821a28b0b7c2400bc59aba4bcc0a76e971dadd19610d3ad38c768e124dc7","schema_version":"edge-lab-recorder.raw.v1","sequence":null,"source":"clob_market_ws"}
{"event_at":"2026-07-27T03:26:46.849000Z","event_fingerprint":"0125753d56f6cfedf7b1b1ee850b9b36156ef21fecab66d175d8778273653c3e","payload":{"connection_id":"c7dc2e4762f849c6b6f9306b6518dcab","event_at":"2026-07-27T03:26:46.849000Z","event_type":"price_change","frame_hash":"98a14a47c8f3ed6e7e0a56ef8101f0f8f71c944a601a0aba54d417a12391530b","frame_index":0,"kind":"data","monotonic_ns":224790097365250,"payload":{"event_type":"price_change","market":"0x717c0e8ccd4d5c7040185188fbae28be901ca589a11a94b1b38ca36a79eccfeb","price_changes":[{"asset_id":"24254094493625419915756280046002869097156693848522361803041977572204227262166","best_ask":"0.85","best_bid":"0.84","hash":"e70a453fe586c7f8677302d3317814962b878bf7","price":"0.01","side":"BUY","size":"5155.02"},{"asset_id":"41448400836309843603620980831210604935021861034693225347475867885462478926555","best_ask":"0.16","best_bid":"0.15","hash":"fbd95a29b1d7c79bd60146eba11bb208ac5e17c9","price":"0.99","side":"SELL","size":"5155.02"}],"timestamp":"1785122806849"},"payload_hash":"9b6c14605c5fd8ed95cdcf3dad600ad91b16a60f71ad3a027b34c4b3ef89ae76","raw_frame":"{\"market\":\"0x717c0e8ccd4d5c7040185188fbae28be901ca589a11a94b1b38ca36a79eccfeb\", \"price_changes\":[{\"asset_id\":\"24254094493625419915756280046002869097156693848522361803041977572204227262166\", \"price\":\"0.01\", \"size\":\"5155.02\", \"side\":\"BUY\", \"hash\":\"e70a453fe586c7f8677302d3317814962b878bf7\", \"best_bid\":\"0.84\", \"best_ask\":\"0.85\"}, {\"asset_id\":\"41448400836309843603620980831210604935021861034693225347475867885462478926555\", \"price\":\"0.99\", \"size\":\"5155.02\", \"side\":\"SELL\", \"hash\":\"fbd95a29b1d7c79bd60146eba11bb208ac5e17c9\", \"best_bid\":\"0.15\", \"best_ask\":\"0.16\"}], \"timestamp\":\"1785122806849\", \"event_type\":\"price_change\"}","received_at":"2026-07-27T03:26:46.736830Z","schema_version":"clob-market-ws.price_change.v1","sequence":null,"server_hash":null,"server_timestamp":"1785122806849","session_id":"dd162b8dca5f43ff811d304e69a06123","source":"clob_market_ws"},"received_at":"2026-07-27T03:26:46.736830Z","record_id":"201f752f99cffbbe5027501cce273f6c1e7e902ab8719f11f16c130353f0b655","schema_fingerprint":"4aa3821a28b0b7c2400bc59aba4bcc0a76e971dadd19610d3ad38c768e124dc7","schema_version":"edge-lab-recorder.raw.v1","sequence":null,"source":"clob_market_ws"}
{"event_at":"2026-07-27T03:26:46.860000Z","event_fingerprint":"712e07e271fbfd0199ab340633ef3ee088fbf22038eab26a4aae267e94986034","payload":{"connection_id":"c7dc2e4762f849c6b6f9306b6518dcab","event_at":"2026-07-27T03:26:46.860000Z","event_type":"price_change","frame_hash":"3c1ef39ad98e3055fe4e2daa33e27f415596da8b744094941ac08ed7f3850f6c","frame_index":0,"kind":"data","monotonic_ns":224790100528583,"payload":{"event_type":"price_change","market":"0x717c0e8ccd4d5c7040185188fbae28be901ca589a11a94b1b38ca36a79eccfeb","price_changes":[{"asset_id":"24254094493625419915756280046002869097156693848522361803041977572204227262166","best_ask":"0.85","best_bid":"0.84","hash":"3a16be5ca68600f7f0bd8174aa0568184217f97c","price":"0.89","side":"SELL","size":"9.6"},{"asset_id":"41448400836309843603620980831210604935021861034693225347475867885462478926555","best_ask":"0.16","best_bid":"0.15","hash":"cc5c71443fa7e0f77111fdc62f27fd71e13a553d","price":"0.11","side":"BUY","size":"9.6"}],"timestamp":"1785122806860"},"payload_hash":"1cae9317e3ae03fc6a81b10a86fd2e3d5eb5b06cf14b1de23912df56e91053a1","raw_frame":"{\"market\":\"0x717c0e8ccd4d5c7040185188fbae28be901ca589a11a94b1b38ca36a79eccfeb\", \"price_changes\":[{\"asset_id\":\"24254094493625419915756280046002869097156693848522361803041977572204227262166\", \"price\":\"0.89\", \"size\":\"9.6\", \"side\":\"SELL\", \"hash\":\"3a16be5ca68600f7f0bd8174aa0568184217f97c\", \"best_bid\":\"0.84\", \"best_ask\":\"0.85\"}, {\"asset_id\":\"41448400836309843603620980831210604935021861034693225347475867885462478926555\", \"price\":\"0.11\", \"size\":\"9.6\", \"side\":\"BUY\", \"hash\":\"cc5c71443fa7e0f77111fdc62f27fd71e13a553d\", \"best_bid\":\"0.15\", \"best_ask\":\"0.16\"}], \"timestamp\":\"1785122806860\", \"event_type\":\"price_change\"}","received_at":"2026-07-27T03:26:46.739994Z","schema_version":"clob-market-ws.price_change.v1","sequence":null,"server_hash":null,"server_timestamp":"1785122806860","session_id":"dd162b8dca5f43ff811d304e69a06123","source":"clob_market_ws"},"received_at":"2026-07-27T03:26:46.739994Z","record_id":"1d280ea41e273ec44ad370d276ffdfd3984ae63af9eefb38df19a133235741e7","schema_fingerprint":"4aa3821a28b0b7c2400bc59aba4bcc0a76e971dadd19610d3ad38c768e124dc7","schema_version":"edge-lab-recorder.raw.v1","sequence":null,"source":"clob_market_ws"}
{"event_at":"2026-07-27T03:26:46.866000Z","event_fingerprint":"958c1fadc7d5145a9e3bcc613dac351e86f426297937e29db6b622ee849b5ece","payload":{"connection_id":"c7dc2e4762f849c6b6f9306b6518dcab","event_at":"2026-07-27T03:26:46.866000Z","event_type":"price_change","frame_hash":"6cb55be0f78ce5d032b95290e7e57417dc99602cbe8e2137aa53ed0d06e0178d","frame_index":0,"kind":"data","monotonic_ns":224790106457125,"payload":{"event_type":"price_change","market":"0x717c0e8ccd4d5c7040185188fbae28be901ca589a11a94b1b38ca36a79eccfeb","price_changes":[{"asset_id":"41448400836309843603620980831210604935021861034693225347475867885462478926555","best_ask":"0.16","best_bid":"0.15","hash":"f59c8dbf3a40a7ed213ca064ecfe5be0fadc77dd","price":"0.18","side":"SELL","size":"80.03"},{"asset_id":"24254094493625419915756280046002869097156693848522361803041977572204227262166","best_ask":"0.85","best_bid":"0.84","hash":"d044bc8195e3af7e5aae24f63f0f6112729e6440","price":"0.82","side":"BUY","size":"80.03"}],"timestamp":"1785122806866"},"payload_hash":"a0a63b317ac7b6b3ac0ac310f43ddcfe5751e37b8a894599c0f6b1f28afda0b4","raw_frame":"{\"market\":\"0x717c0e8ccd4d5c7040185188fbae28be901ca589a11a94b1b38ca36a79eccfeb\", \"price_changes\":[{\"asset_id\":\"41448400836309843603620980831210604935021861034693225347475867885462478926555\", \"price\":\"0.18\", \"size\":\"80.03\", \"side\":\"SELL\", \"hash\":\"f59c8dbf3a40a7ed213ca064ecfe5be0fadc77dd\", \"best_bid\":\"0.15\", \"best_ask\":\"0.16\"}, {\"asset_id\":\"24254094493625419915756280046002869097156693848522361803041977572204227262166\", \"price\":\"0.82\", \"size\":\"80.03\", \"side\":\"BUY\", \"hash\":\"d044bc8195e3af7e5aae24f63f0f6112729e6440\", \"best_bid\":\"0.84\", \"best_ask\":\"0.85\"}], \"timestamp\":\"1785122806866\", \"event_type\":\"price_change\"}","received_at":"2026-07-27T03:26:46.745921Z","schema_version":"clob-market-ws.price_change.v1","sequence":null,"server_hash":null,"server_timestamp":"1785122806866","session_id":"dd162b8dca5f43ff811d304e69a06123","source":"clob_market_ws"},"received_at":"2026-07-27T03:26:46.745921Z","record_id":"75e723665bddb715e1f628ae7555cb9192cb2a73dbfb567831212e8eeca03621","schema_fingerprint":"4aa3821a28b0b7c2400bc59aba4bcc0a76e971dadd19610d3ad38c768e124dc7","schema_version":"edge-lab-recorder.raw.v1","sequence":null,"source":"clob_market_ws"}
{"event_at":"2026-07-27T03:26:46.867000Z","event_fingerprint":"cc4cf7a9a2872ccb57b1b9c37817dcbcd4b937d000cd43ec5f8c27b41a3f51ea","payload":{"connection_id":"c7dc2e4762f849c6b6f9306b6518dcab","event_at":"2026-07-27T03:26:46.867000Z","event_type":"price_change","frame_hash":"f7004242384c9fcd3c65c345535b76520eefe87cade24ea33f4423dac147fff7","frame_index":0,"kind":"data","monotonic_ns":224790108829875,"payload":{"event_type":"price_change","market":"0x717c0e8ccd4d5c7040185188fbae28be901ca589a11a94b1b38ca36a79eccfeb","price_changes":[{"asset_id":"24254094493625419915756280046002869097156693848522361803041977572204227262166","best_ask":"0.85","best_bid":"0.84","hash":"fd40f39318d17b2079897db3883c23bc47d15dd4","price":"0.01","side":"BUY","size":"5150.02"},{"asset_id":"41448400836309843603620980831210604935021861034693225347475867885462478926555","best_ask":"0.16","best_bid":"0.15","hash":"e5a6210cd24bd3d352630d00cf00dde4209403df","price":"0.99","side":"SELL","size":"5150.02"}],"timestamp":"1785122806867"},"payload_hash":"378f681d7838e8ccef7b9b096b60d2863df56652570d52879fd0bf7530ae6351","raw_frame":"{\"market\":\"0x717c0e8ccd4d5c7040185188fbae28be901ca589a11a94b1b38ca36a79eccfeb\", \"price_changes\":[{\"asset_id\":\"24254094493625419915756280046002869097156693848522361803041977572204227262166\", \"price\":\"0.01\", \"size\":\"5150.02\", \"side\":\"BUY\", \"hash\":\"fd40f39318d17b2079897db3883c23bc47d15dd4\", \"best_bid\":\"0.84\", \"best_ask\":\"0.85\"}, {\"asset_id\":\"41448400836309843603620980831210604935021861034693225347475867885462478926555\", \"price\":\"0.99\", \"size\":\"5150.02\", \"side\":\"SELL\", \"hash\":\"e5a6210cd24bd3d352630d00cf00dde4209403df\", \"best_bid\":\"0.15\", \"best_ask\":\"0.16\"}], \"timestamp\":\"1785122806867\", \"event_type\":\"price_change\"}","received_at":"2026-07-27T03:26:46.748296Z","schema_version":"clob-market-ws.price_change.v1","sequence":null,"server_hash":null,"server_timestamp":"1785122806867","session_id":"dd162b8dca5f43ff811d304e69a06123","source":"clob_market_ws"},"received_at":"2026-07-27T03:26:46.748296Z","record_id":"65c0714746975024b664dc28f27992e42f342e03dc06b8d12ace15acac9cb8d3","schema_fingerprint":"4aa3821a28b0b7c2400bc59aba4bcc0a76e971dadd19610d3ad38c768e124dc7","schema_version":"edge-lab-recorder.raw.v1","sequence":null,"source":"clob_market_ws"}
{"event_at":"2026-07-27T03:26:46.867000Z","event_fingerprint":"54194a33e898710cfa16eb44f94d3eb8de6baa7fcb216211bdd00b1f82d3ff81","payload":{"connection_id":"c7dc2e4762f849c6b6f9306b6518dcab","event_at":"2026-07-27T03:26:46.867000Z","event_type":"price_change","frame_hash":"1a73b8416ecb8c98d6c2871a921a432dba4600997dc9aa82b0a769950d1f323c","frame_index":0,"kind":"data","monotonic_ns":224790112446625,"payload":{"event_type":"price_change","market":"0x717c0e8ccd4d5c7040185188fbae28be901ca589a11a94b1b38ca36a79eccfeb","price_changes":[{"asset_id":"41448400836309843603620980831210604935021861034693225347475867885462478926555","best_ask":"0.16","best_bid":"0.15","hash":"d290288b6d535c71519076b51f09526371d9a41f","price":"0.11","side":"BUY","size":"22.8"},{"asset_id":"24254094493625419915756280046002869097156693848522361803041977572204227262166","best_ask":"0.85","best_bid":"0.84","hash":"8fac0252fc9e00141d859c152c2343c7c0ff927e","price":"0.89","side":"SELL","size":"22.8"}],"timestamp":"1785122806867"},"payload_hash":"662c490d7db48d17997cb5b8490a16895a86e12a321a12b4f9c1ef137b2ea2ac","raw_frame":"{\"market\":\"0x717c0e8ccd4d5c7040185188fbae28be901ca589a11a94b1b38ca36a79eccfeb\", \"price_changes\":[{\"asset_id\":\"41448400836309843603620980831210604935021861034693225347475867885462478926555\", \"price\":\"0.11\", \"size\":\"22.8\", \"side\":\"BUY\", \"hash\":\"d290288b6d535c71519076b51f09526371d9a41f\", \"best_bid\":\"0.15\", \"best_ask\":\"0.16\"}, {\"asset_id\":\"24254094493625419915756280046002869097156693848522361803041977572204227262166\", \"price\":\"0.89\", \"size\":\"22.8\", \"side\":\"SELL\", \"hash\":\"8fac0252fc9e00141d859c152c2343c7c0ff927e\", \"best_bid\":\"0.84\", \"best_ask\":\"0.85\"}], \"timestamp\":\"1785122806867\", \"event_type\":\"price_change\"}","received_at":"2026-07-27T03:26:46.751912Z","schema_version":"clob-market-ws.price_change.v1","sequence":null,"server_hash":null,"server_timestamp":"1785122806867","session_id":"dd162b8dca5f43ff811d304e69a06123","source":"clob_market_ws"},"received_at":"2026-07-27T03:26:46.751912Z","record_id":"51715e65393471f9fbd199a309a999d08c496dbd4089a48ad5f77d3e534584f3","schema_fingerprint":"4aa3821a28b0b7c2400bc59aba4bcc0a76e971dadd19610d3ad38c768e124dc7","schema_version":"edge-lab-recorder.raw.v1","sequence":null,"source":"clob_market_ws"}
{"event_at":"2026-07-27T03:26:46.873000Z","event_fingerprint":"2b63641b5db38d5c2e70e35d81dfccbc9c8c2ff0f2a16f63bddf3a9af0d7d254","payload":{"connection_id":"c7dc2e4762f849c6b6f9306b6518dcab","event_at":"2026-07-27T03:26:46.873000Z","event_type":"price_change","frame_hash":"cc94f9fe3de3a581a3abac74b6f52e6dbb09eed062b671f4c3f750f0d2d77021","frame_index":0,"kind":"data","monotonic_ns":224790116409416,"payload":{"event_type":"price_change","market":"0x717c0e8ccd4d5c7040185188fbae28be901ca589a11a94b1b38ca36a79eccfeb","price_changes":[{"asset_id":"24254094493625419915756280046002869097156693848522361803041977572204227262166","best_ask":"0.85","best_bid":"0.84","hash":"1c3b16264bfd99a73834bb6532ab27ae723a106f","price":"0.78","side":"BUY","size":"107"},{"asset_id":"41448400836309843603620980831210604935021861034693225347475867885462478926555","best_ask":"0.16","best_bid":"0.15","hash":"04957eaf34003c6c298b3db4c0a78a0f5ad69fdc","price":"0.22","side":"SELL","size":"107"}],"timestamp":"1785122806873"},"payload_hash":"480000d6dd601421e4a00e10dd8581b3ef8b83e9d81ae5dbf08fe1b35f657081","raw_frame":"{\"market\":\"0x717c0e8ccd4d5c7040185188fbae28be901ca589a11a94b1b38ca36a79eccfeb\", \"price_changes\":[{\"asset_id\":\"24254094493625419915756280046002869097156693848522361803041977572204227262166\", \"price\":\"0.78\", \"size\":\"107\", \"side\":\"BUY\", \"hash\":\"1c3b16264bfd99a73834bb6532ab27ae723a106f\", \"best_bid\":\"0.84\", \"best_ask\":\"0.85\"}, {\"asset_id\":\"41448400836309843603620980831210604935021861034693225347475867885462478926555\", \"price\":\"0.22\", \"size\":\"107\", \"side\":\"SELL\", \"hash\":\"04957eaf34003c6c298b3db4c0a78a0f5ad69fdc\", \"best_bid\":\"0.15\", \"best_ask\":\"0.16\"}], \"timestamp\":\"1785122806873\", \"event_type\":\"price_change\"}","received_at":"2026-07-27T03:26:46.755873Z","schema_version":"clob-market-ws.price_change.v1","sequence":null,"server_hash":null,"server_timestamp":"1785122806873","session_id":"dd162b8dca5f43ff811d304e69a06123","source":"clob_market_ws"},"received_at":"2026-07-27T03:26:46.755873Z","record_id":"44448d48392ce3aba21e58ba6be6157a822bbdd86381464d6cdde0be210ed3c9","schema_fingerprint":"4aa3821a28b0b7c2400bc59aba4bcc0a76e971dadd19610d3ad38c768e124dc7","schema_version":"edge-lab-recorder.raw.v1","sequence":null,"source":"clob_market_ws"}
{"event_at":"2026-07-27T03:26:46.873000Z","event_fingerprint":"a07a7b5026f226c5101cb5fca640b6f14b7294ce5065ad841756030153a532fc","payload":{"connection_id":"c7dc2e4762f849c6b6f9306b6518dcab","event_at":"2026-07-27T03:26:46.873000Z","event_type":"price_change","frame_hash":"f31b3b04fbfc520e64365c780d0d134bd691f46ac78dfc6731eedf887addf9c2","frame_index":0,"kind":"data","monotonic_ns":224790119539166,"payload":{"event_type":"price_change","market":"0x717c0e8ccd4d5c7040185188fbae28be901ca589a11a94b1b38ca36a79eccfeb","price_changes":[{"asset_id":"24254094493625419915756280046002869097156693848522361803041977572204227262166","best_ask":"0.85","best_bid":"0.84","hash":"c29aac9509d11e958c3f8b0370d80c3d42a0b746","price":"0.84","side":"BUY","size":"116.53"},{"asset_id":"41448400836309843603620980831210604935021861034693225347475867885462478926555","best_ask":"0.16","best_bid":"0.15","hash":"bdfb8f23963c7e858a9f011a0ec233c06021db26","price":"0.16","side":"SELL","size":"116.53"}],"timestamp":"1785122806873"},"payload_hash":"bf753bee095469408957368a0273419baae23ee7c750089dca65f4c85e1b90e4","raw_frame":"{\"market\":\"0x717c0e8ccd4d5c7040185188fbae28be901ca589a11a94b1b38ca36a79eccfeb\", \"price_changes\":[{\"asset_id\":\"24254094493625419915756280046002869097156693848522361803041977572204227262166\", \"price\":\"0.84\", \"size\":\"116.53\", \"side\":\"BUY\", \"hash\":\"c29aac9509d11e958c3f8b0370d80c3d42a0b746\", \"best_bid\":\"0.84\", \"best_ask\":\"0.85\"}, {\"asset_id\":\"41448400836309843603620980831210604935021861034693225347475867885462478926555\", \"price\":\"0.16\", \"size\":\"116.53\", \"side\":\"SELL\", \"hash\":\"bdfb8f23963c7e858a9f011a0ec233c06021db26\", \"best_bid\":\"0.15\", \"best_ask\":\"0.16\"}], \"timestamp\":\"1785122806873\", \"event_type\":\"price_change\"}","received_at":"2026-07-27T03:26:46.759005Z","schema_version":"clob-market-ws.price_change.v1","sequence":null,"server_hash":null,"server_timestamp":"1785122806873","session_id":"dd162b8dca5f43ff811d304e69a06123","source":"clob_market_ws"},"received_at":"2026-07-27T03:26:46.759005Z","record_id":"9de10df437f2df2c1c06a317bb0cb557aca8961a8bb7cfc68ee87f1bef0a80fb","schema_fingerprint":"4aa3821a28b0b7c2400bc59aba4bcc0a76e971dadd19610d3ad38c768e124dc7","schema_version":"edge-lab-recorder.raw.v1","sequence":null,"source":"clob_market_ws"}
{"event_at":"2026-07-27T03:26:46.875000Z","event_fingerprint":"3dafc372ea1ece74e9fdf39f610ffa6ca1443e2468630f71eb64792357c863c7","payload":{"connection_id":"c7dc2e4762f849c6b6f9306b6518dcab","event_at":"2026-07-27T03:26:46.875000Z","event_type":"best_bid_ask","frame_hash":"59d2896d908f2103ceb56ac34e20467de3da5cd707723aad65555e2378b9d5ef","frame_index":0,"kind":"data","monotonic_ns":224790122767666,"payload":{"asset_id":"24254094493625419915756280046002869097156693848522361803041977572204227262166","best_ask":"0.86","best_bid":"0.84","event_type":"best_bid_ask","market":"0x717c0e8ccd4d5c7040185188fbae28be901ca589a11a94b1b38ca36a79eccfeb","spread":"0.02","timestamp":"1785122806875"},"payload_hash":"65c558a5f7e86f8b57cfbf4c76ce86df5981e33d548cdfb407e2fa86adfb1606","raw_frame":"{\"market\":\"0x717c0e8ccd4d5c7040185188fbae28be901ca589a11a94b1b38ca36a79eccfeb\", \"asset_id\":\"24254094493625419915756280046002869097156693848522361803041977572204227262166\", \"best_bid\":\"0.84\", \"best_ask\":\"0.86\", \"spread\":\"0.02\", \"timestamp\":\"1785122806875\", \"event_type\":\"best_bid_ask\"}","received_at":"2026-07-27T03:26:46.762232Z","schema_version":"clob-market-ws.best_bid_ask.v1","sequence":null,"server_hash":null,"server_timestamp":"1785122806875","session_id":"dd162b8dca5f43ff811d304e69a06123","source":"clob_market_ws"},"received_at":"2026-07-27T03:26:46.762232Z","record_id":"6048aeb9fc68a0e0f329792055a44504d4468f4044c07cc151acdb0af0486db3","schema_fingerprint":"8488399f31b0337811b13b266be932db7062827c2470b78bd8e9e99bab51d17d","schema_version":"edge-lab-recorder.raw.v1","sequence":null,"source":"clob_market_ws"}
{"event_at":"2026-07-27T03:26:46.875000Z","event_fingerprint":"1cdde3b772a202b53d79d4590d40b32d3ab6b029f9af36f2c8d5474d564ae186","payload":{"connection_id":"c7dc2e4762f849c6b6f9306b6518dcab","event_at":"2026-07-27T03:26:46.875000Z","event_type":"best_bid_ask","frame_hash":"e09987c0c6f9ac907f34e111c9533b1c0adaf1dee12db20ac671744514217375","frame_index":0,"kind":"data","monotonic_ns":224790126401750,"payload":{"asset_id":"41448400836309843603620980831210604935021861034693225347475867885462478926555","best_ask":"0.16","best_bid":"0.14","event_type":"best_bid_ask","market":"0x717c0e8ccd4d5c7040185188fbae28be901ca589a11a94b1b38ca36a79eccfeb","spread":"0.02","timestamp":"1785122806875"},"payload_hash":"84f5dadae1c9b081d554a646a65098ffff220f6a7f207b476bf74bc4d38361fd","raw_frame":"{\"market\":\"0x717c0e8ccd4d5c7040185188fbae28be901ca589a11a94b1b38ca36a79eccfeb\", \"asset_id\":\"41448400836309843603620980831210604935021861034693225347475867885462478926555\", \"best_bid\":\"0.14\", \"best_ask\":\"0.16\", \"spread\":\"0.02\", \"timestamp\":\"1785122806875\", \"event_type\":\"best_bid_ask\"}","received_at":"2026-07-27T03:26:46.765863Z","schema_version":"clob-market-ws.best_bid_ask.v1","sequence":null,"server_hash":null,"server_timestamp":"1785122806875","session_id":"dd162b8dca5f43ff811d304e69a06123","source":"clob_market_ws"},"received_at":"2026-07-27T03:26:46.765863Z","record_id":"f77df7bb902677429c3b71b5dfdea69652d4ce0be837d8fa33cb978270d70ba5","schema_fingerprint":"8488399f31b0337811b13b266be932db7062827c2470b78bd8e9e99bab51d17d","schema_version":"edge-lab-recorder.raw.v1","sequence":null,"source":"clob_market_ws"}
{"event_at":"2026-07-27T03:26:46.875000Z","event_fingerprint":"24fed2a88daff81da40a6e3c8b40b90031ba54490b252ec3a8793b319441d103","payload":{"connection_id":"c7dc2e4762f849c6b6f9306b6518dcab","event_at":"2026-07-27T03:26:46.875000Z","event_type":"price_change","frame_hash":"b05c5d0ade42573e567402e5d29dd85d2dc8fa201a77d9f283fef5ccd3bdeecf","frame_index":0,"kind":"data","monotonic_ns":224790128991958,"payload":{"event_type":"price_change","market":"0x717c0e8ccd4d5c7040185188fbae28be901ca589a11a94b1b38ca36a79eccfeb","price_changes":[{"asset_id":"41448400836309843603620980831210604935021861034693225347475867885462478926555","best_ask":"0.16","best_bid":"0.14","hash":"8b5586430309e1a77547212a9463d202db58ab26","price":"0.15","side":"BUY","size":"0"},{"asset_id":"24254094493625419915756280046002869097156693848522361803041977572204227262166","best_ask":"0.86","best_bid":"0.84","hash":"cff2768f932a8f1917d936e5b4f5d3c45fa6e760","price":"0.85","side":"SELL","size":"0"}],"timestamp":"1785122806875"},"payload_hash":"8cc84c8393215d1c6ca26287a8115dbdf45831b2ed3513fce6926ed2c5b800dd","raw_frame":"{\"market\":\"0x717c0e8ccd4d5c7040185188fbae28be901ca589a11a94b1b38ca36a79eccfeb\", \"price_changes\":[{\"asset_id\":\"41448400836309843603620980831210604935021861034693225347475867885462478926555\", \"price\":\"0.15\", \"size\":\"0\", \"side\":\"BUY\", \"hash\":\"8b5586430309e1a77547212a9463d202db58ab26\", \"best_bid\":\"0.14\", \"best_ask\":\"0.16\"}, {\"asset_id\":\"24254094493625419915756280046002869097156693848522361803041977572204227262166\", \"price\":\"0.85\", \"size\":\"0\", \"side\":\"SELL\", \"hash\":\"cff2768f932a8f1917d936e5b4f5d3c45fa6e760\", \"best_bid\":\"0.84\", \"best_ask\":\"0.86\"}], \"timestamp\":\"1785122806875\", \"event_type\":\"price_change\"}","received_at":"2026-07-27T03:26:46.768456Z","schema_version":"clob-market-ws.price_change.v1","sequence":null,"server_hash":null,"server_timestamp":"1785122806875","session_id":"dd162b8dca5f43ff811d304e69a06123","source":"clob_market_ws"},"received_at":"2026-07-27T03:26:46.768456Z","record_id":"09d72a258f997f88c843f669fc31a66923882a63182c76b4d80b7c0882e95dd4","schema_fingerprint":"4aa3821a28b0b7c2400bc59aba4bcc0a76e971dadd19610d3ad38c768e124dc7","schema_version":"edge-lab-recorder.raw.v1","sequence":null,"source":"clob_market_ws"}
{"event_at":"2026-07-27T03:26:46.876000Z","event_fingerprint":"224121343592a0dc627b5770039a74070a85195956913b7234f2eb96ff08ea13","payload":{"connection_id":"c7dc2e4762f849c6b6f9306b6518dcab","event_at":"2026-07-27T03:26:46.876000Z","event_type":"price_change","frame_hash":"6bbd0521b1302037ba265f34de8001480fe92a8676f29e061ad55180b40be41a","frame_index":0,"kind":"data","monotonic_ns":224790132270125,"payload":{"event_type":"price_change","market":"0x717c0e8ccd4d5c7040185188fbae28be901ca589a11a94b1b38ca36a79eccfeb","price_changes":[{"asset_id":"24254094493625419915756280046002869097156693848522361803041977572204227262166","best_ask":"0.86","best_bid":"0.84","hash":"59d69f7f03c0b8f51f3ee216efa73ffb8d94c1f2","price":"0.03","side":"BUY","size":"510"},{"asset_id":"41448400836309843603620980831210604935021861034693225347475867885462478926555","best_ask":"0.16","best_bid":"0.14","hash":"b93a713570f5697402fba533db47a7e2d156d1e0","price":"0.97","side":"SELL","size":"510"}],"timestamp":"1785122806876"},"payload_hash":"5435cab3c7cc12b62bd6bdbe0c16980c5f338b038230cbd29f177703deac5440","raw_frame":"{\"market\":\"0x717c0e8ccd4d5c7040185188fbae28be901ca589a11a94b1b38ca36a79eccfeb\", \"price_changes\":[{\"asset_id\":\"24254094493625419915756280046002869097156693848522361803041977572204227262166\", \"price\":\"0.03\", \"size\":\"510\", \"side\":\"BUY\", \"hash\":\"59d69f7f03c0b8f51f3ee216efa73ffb8d94c1f2\", \"best_bid\":\"0.84\", \"best_ask\":\"0.86\"}, {\"asset_id\":\"41448400836309843603620980831210604935021861034693225347475867885462478926555\", \"price\":\"0.97\", \"size\":\"510\", \"side\":\"SELL\", \"hash\":\"b93a713570f5697402fba533db47a7e2d156d1e0\", \"best_bid\":\"0.14\", \"best_ask\":\"0.16\"}], \"timestamp\":\"1785122806876\", \"event_type\":\"price_change\"}","received_at":"2026-07-27T03:26:46.771733Z","schema_version":"clob-market-ws.price_change.v1","sequence":null,"server_hash":null,"server_timestamp":"1785122806876","session_id":"dd162b8dca5f43ff811d304e69a06123","source":"clob_market_ws"},"received_at":"2026-07-27T03:26:46.771733Z","record_id":"548a1d60a775a8c9022c0d703e199d7b5d2478c44d941d96f668a2673d3e8883","schema_fingerprint":"4aa3821a28b0b7c2400bc59aba4bcc0a76e971dadd19610d3ad38c768e124dc7","schema_version":"edge-lab-recorder.raw.v1","sequence":null,"source":"clob_market_ws"}
{"event_at":"2026-07-27T03:26:46.892000Z","event_fingerprint":"7515d4c6ce373e55a347ed2aa7e65287f95ea3118ad454a71ece436dd399b5f7","payload":{"connection_id":"c7dc2e4762f849c6b6f9306b6518dcab","event_at":"2026-07-27T03:26:46.892000Z","event_type":"price_change","frame_hash":"526f75835d9a574f8f872edf1aeaa8b6b805d3a79fa98971493eec9cc0b0ae03","frame_index":0,"kind":"data","monotonic_ns":224790134233166,"payload":{"event_type":"price_change","market":"0x717c0e8ccd4d5c7040185188fbae28be901ca589a11a94b1b38ca36a79eccfeb","price_changes":[{"asset_id":"24254094493625419915756280046002869097156693848522361803041977572204227262166","best_ask":"0.86","best_bid":"0.84","hash":"4f6b99a78210f972d3159c9e262012b0ee5da772","price":"0.84","side":"BUY","size":"111.53"},{"asset_id":"41448400836309843603620980831210604935021861034693225347475867885462478926555","best_ask":"0.16","best_bid":"0.14","hash":"d0cb8ad36cc0afafc583f4e533a9b4128542952a","price":"0.16","side":"SELL","size":"111.53"}],"timestamp":"1785122806892"},"payload_hash":"ff680be7415b97941549b3568230cee800affc9c5ab9a23045e6dec4ef74d90c","raw_frame":"{\"market\":\"0x717c0e8ccd4d5c7040185188fbae28be901ca589a11a94b1b38ca36a79eccfeb\", \"price_changes\":[{\"asset_id\":\"24254094493625419915756280046002869097156693848522361803041977572204227262166\", \"price\":\"0.84\", \"size\":\"111.53\", \"side\":\"BUY\", \"hash\":\"4f6b99a78210f972d3159c9e262012b0ee5da772\", \"best_bid\":\"0.84\", \"best_ask\":\"0.86\"}, {\"asset_id\":\"41448400836309843603620980831210604935021861034693225347475867885462478926555\", \"price\":\"0.16\", \"size\":\"111.53\", \"side\":\"SELL\", \"hash\":\"d0cb8ad36cc0afafc583f4e533a9b4128542952a\", \"best_bid\":\"0.14\", \"best_ask\":\"0.16\"}], \"timestamp\":\"1785122806892\", \"event_type\":\"price_change\"}","received_at":"2026-07-27T03:26:46.773697Z","schema_version":"clob-market-ws.price_change.v1","sequence":null,"server_hash":null,"server_timestamp":"1785122806892","session_id":"dd162b8dca5f43ff811d304e69a06123","source":"clob_market_ws"},"received_at":"2026-07-27T03:26:46.773697Z","record_id":"07dab97335fd9d345ab05282049195977b08f1039d2e49ad465558d651017fcd","schema_fingerprint":"4aa3821a28b0b7c2400bc59aba4bcc0a76e971dadd19610d3ad38c768e124dc7","schema_version":"edge-lab-recorder.raw.v1","sequence":null,"source":"clob_market_ws"}
{"event_at":"2026-07-27T03:26:46.942000Z","event_fingerprint":"cb65cc21d4232056536df33a9ac89c2abac9a0a8595df28a71035f20eb447a37","payload":{"connection_id":"c7dc2e4762f849c6b6f9306b6518dcab","event_at":"2026-07-27T03:26:46.942000Z","event_type":"best_bid_ask","frame_hash":"16c22980e04d1a0109c1656dcecc53b41218c98e4a9d6a647c8066be0526d480","frame_index":0,"kind":"data","monotonic_ns":224790177744666,"payload":{"asset_id":"24254094493625419915756280046002869097156693848522361803041977572204227262166","best_ask":"0.85","best_bid":"0.84","event_type":"best_bid_ask","market":"0x717c0e8ccd4d5c7040185188fbae28be901ca589a11a94b1b38ca36a79eccfeb","spread":"0.01","timestamp":"1785122806942"},"payload_hash":"d0be6466b302addac8a70063cb72deed935f84f93f39f295c8e65cb8aa897620","raw_frame":"{\"market\":\"0x717c0e8ccd4d5c7040185188fbae28be901ca589a11a94b1b38ca36a79eccfeb\", \"asset_id\":\"24254094493625419915756280046002869097156693848522361803041977572204227262166\", \"best_bid\":\"0.84\", \"best_ask\":\"0.85\", \"spread\":\"0.01\", \"timestamp\":\"1785122806942\", \"event_type\":\"best_bid_ask\"}","received_at":"2026-07-27T03:26:46.817208Z","schema_version":"clob-market-ws.best_bid_ask.v1","sequence":null,"server_hash":null,"server_timestamp":"1785122806942","session_id":"dd162b8dca5f43ff811d304e69a06123","source":"clob_market_ws"},"received_at":"2026-07-27T03:26:46.817208Z","record_id":"88a329db177d242c048be5b04caaca88f2dbdf10d8c915531e0eb37c004b6795","schema_fingerprint":"8488399f31b0337811b13b266be932db7062827c2470b78bd8e9e99bab51d17d","schema_version":"edge-lab-recorder.raw.v1","sequence":null,"source":"clob_market_ws"}
{"event_at":"2026-07-27T03:26:46.942000Z","event_fingerprint":"140f89b5cd2c674455e9172ab60337c3a86ffb61eb6f4fea019019cfb62ac04c","payload":{"connection_id":"c7dc2e4762f849c6b6f9306b6518dcab","event_at":"2026-07-27T03:26:46.942000Z","event_type":"best_bid_ask","frame_hash":"3e6762ba6720b0fa8fb900e321838478309128f4626fdc6d8a8b78f68d3ee498","frame_index":0,"kind":"data","monotonic_ns":224790182018083,"payload":{"asset_id":"41448400836309843603620980831210604935021861034693225347475867885462478926555","best_ask":"0.16","best_bid":"0.15","event_type":"best_bid_ask","market":"0x717c0e8ccd4d5c7040185188fbae28be901ca589a11a94b1b38ca36a79eccfeb","spread":"0.01","timestamp":"1785122806942"},"payload_hash":"5054ff58cc28c2991f6fa556b8b9a40bf0d6b2498640a23025ec459f2175ebff","raw_frame":"{\"market\":\"0x717c0e8ccd4d5c7040185188fbae28be901ca589a11a94b1b38ca36a79eccfeb\", \"asset_id\":\"41448400836309843603620980831210604935021861034693225347475867885462478926555\", \"best_bid\":\"0.15\", \"best_ask\":\"0.16\", \"spread\":\"0.01\", \"timestamp\":\"1785122806942\", \"event_type\":\"best_bid_ask\"}","received_at":"2026-07-27T03:26:46.821482Z","schema_version":"clob-market-ws.best_bid_ask.v1","sequence":null,"server_hash":null,"server_timestamp":"1785122806942","session_id":"dd162b8dca5f43ff811d304e69a06123","source":"clob_market_ws"},"received_at":"2026-07-27T03:26:46.821482Z","record_id":"4e371d203de36943449377a385c5faed1dd0131714daac5dfb79e8450c261503","schema_fingerprint":"8488399f31b0337811b13b266be932db7062827c2470b78bd8e9e99bab51d17d","schema_version":"edge-lab-recorder.raw.v1","sequence":null,"source":"clob_market_ws"}
{"event_at":"2026-07-27T03:26:46.942000Z","event_fingerprint":"14250eac56b3a27787c745cfb5240f8d85eecae8ddafaac2b6030760c4f10ba6","payload":{"connection_id":"c7dc2e4762f849c6b6f9306b6518dcab","event_at":"2026-07-27T03:26:46.942000Z","event_type":"price_change","frame_hash":"8bde447069c640f4bb7e79ff644dc33fcbf46fc30165cf55fdeb2e10df6216fd","frame_index":0,"kind":"data","monotonic_ns":224790186089541,"payload":{"event_type":"price_change","market":"0x717c0e8ccd4d5c7040185188fbae28be901ca589a11a94b1b38ca36a79eccfeb","price_changes":[{"asset_id":"41448400836309843603620980831210604935021861034693225347475867885462478926555","best_ask":"0.16","best_bid":"0.15","hash":"ee818a833c94137291076cfdafd28741f5d70eea","price":"0.15","side":"BUY","size":"10"},{"asset_id":"24254094493625419915756280046002869097156693848522361803041977572204227262166","best_ask":"0.85","best_bid":"0.84","hash":"22e7ada5d630b44dfefb78539ddec31af0c4ed36","price":"0.85","side":"SELL","size":"10"}],"timestamp":"1785122806942"},"payload_hash":"e6628b7ebc166346e6e482df798d948b7fb622b6315e36c61f59a64fbf3247d2","raw_frame":"{\"market\":\"0x717c0e8ccd4d5c7040185188fbae28be901ca589a11a94b1b38ca36a79eccfeb\", \"price_changes\":[{\"asset_id\":\"41448400836309843603620980831210604935021861034693225347475867885462478926555\", \"price\":\"0.15\", \"size\":\"10\", \"side\":\"BUY\", \"hash\":\"ee818a833c94137291076cfdafd28741f5d70eea\", \"best_bid\":\"0.15\", \"best_ask\":\"0.16\"}, {\"asset_id\":\"24254094493625419915756280046002869097156693848522361803041977572204227262166\", \"price\":\"0.85\", \"size\":\"10\", \"side\":\"SELL\", \"hash\":\"22e7ada5d630b44dfefb78539ddec31af0c4ed36\", \"best_bid\":\"0.84\", \"best_ask\":\"0.85\"}], \"timestamp\":\"1785122806942\", \"event_type\":\"price_change\"}","received_at":"2026-07-27T03:26:46.825554Z","schema_version":"clob-market-ws.price_change.v1","sequence":null,"server_hash":null,"server_timestamp":"1785122806942","session_id":"dd162b8dca5f43ff811d304e69a06123","source":"clob_market_ws"},"received_at":"2026-07-27T03:26:46.825554Z","record_id":"a54ad855d30fcf11be3a3c7571dd917701aa9341b0baf8bcb3375bc551f09722","schema_fingerprint":"4aa3821a28b0b7c2400bc59aba4bcc0a76e971dadd19610d3ad38c768e124dc7","schema_version":"edge-lab-recorder.raw.v1","sequence":null,"source":"clob_market_ws"}
{"event_at":"2026-07-27T03:26:46.942000Z","event_fingerprint":"64df068ae4aeda077b784792140bab17780e35ddab722b318642684cc1627d69","payload":{"connection_id":"c7dc2e4762f849c6b6f9306b6518dcab","event_at":"2026-07-27T03:26:46.942000Z","event_type":"price_change","frame_hash":"ac287499efda78c11bb197b59115f250f4ea38502597280d50940435d0da800c","frame_index":0,"kind":"data","monotonic_ns":224790190761458,"payload":{"event_type":"price_change","market":"0x717c0e8ccd4d5c7040185188fbae28be901ca589a11a94b1b38ca36a79eccfeb","price_changes":[{"asset_id":"24254094493625419915756280046002869097156693848522361803041977572204227262166","best_ask":"0.85","best_bid":"0.84","hash":"652f49b0e962cc2880ae37ac9ea495b8531c487d","price":"0.78","side":"BUY","size":"117"},{"asset_id":"41448400836309843603620980831210604935021861034693225347475867885462478926555","best_ask":"0.16","best_bid":"0.15","hash":"56deb5fd54ca6418255bfc4028f5db2fdf2972fa","price":"0.22","side":"SELL","size":"117"}],"timestamp":"1785122806942"},"payload_hash":"3792b4a757eb7519338a775133ba3e973e39e98ba15544c67a22b2c929ee7234","raw_frame":"{\"market\":\"0x717c0e8ccd4d5c7040185188fbae28be901ca589a11a94b1b38ca36a79eccfeb\", \"price_changes\":[{\"asset_id\":\"24254094493625419915756280046002869097156693848522361803041977572204227262166\", \"price\":\"0.78\", \"size\":\"117\", \"side\":\"BUY\", \"hash\":\"652f49b0e962cc2880ae37ac9ea495b8531c487d\", \"best_bid\":\"0.84\", \"best_ask\":\"0.85\"}, {\"asset_id\":\"41448400836309843603620980831210604935021861034693225347475867885462478926555\", \"price\":\"0.22\", \"size\":\"117\", \"side\":\"SELL\", \"hash\":\"56deb5fd54ca6418255bfc4028f5db2fdf2972fa\", \"best_bid\":\"0.15\", \"best_ask\":\"0.16\"}], \"timestamp\":\"1785122806942\", \"event_type\":\"price_change\"}","received_at":"2026-07-27T03:26:46.830226Z","schema_version":"clob-market-ws.price_change.v1","sequence":null,"server_hash":null,"server_timestamp":"1785122806942","session_id":"dd162b8dca5f43ff811d304e69a06123","source":"clob_market_ws"},"received_at":"2026-07-27T03:26:46.830226Z","record_id":"f26047c658d67a8b81aa45a5d9337194d85d976fa4617d55ceeaa37e2c39a0f8","schema_fingerprint":"4aa3821a28b0b7c2400bc59aba4bcc0a76e971dadd19610d3ad38c768e124dc7","schema_version":"edge-lab-recorder.raw.v1","sequence":null,"source":"clob_market_ws"}
{"event_at":"2026-07-27T03:26:46.962000Z","event_fingerprint":"db826f75e998f775a3c87737898e173cf989f819d6c52d0294d85b0ccce5312c","payload":{"connection_id":"c7dc2e4762f849c6b6f9306b6518dcab","event_at":"2026-07-27T03:26:46.962000Z","event_type":"price_change","frame_hash":"6648d40aaf186b226aafeb7c93f0e0d183979018f4ceca3d03995b84b987f373","frame_index":0,"kind":"data","monotonic_ns":224790199605375,"payload":{"event_type":"price_change","market":"0x717c0e8ccd4d5c7040185188fbae28be901ca589a11a94b1b38ca36a79eccfeb","price_changes":[{"asset_id":"41448400836309843603620980831210604935021861034693225347475867885462478926555","best_ask":"0.16","best_bid":"0.15","hash":"9e4c1f6f85bcdc6a8f7d52e595984c23f435b7a7","price":"0.18","side":"SELL","size":"73.98"},{"asset_id":"24254094493625419915756280046002869097156693848522361803041977572204227262166","best_ask":"0.85","best_bid":"0.84","hash":"8219536482ae314f4adcc7651e7190b5c0623604","price":"0.82","side":"BUY","size":"73.98"}],"timestamp":"1785122806962"},"payload_hash":"4db3a639686a3c7f09de4e7f6332cffa2cd300d6cec8366344472942616308c1","raw_frame":"{\"market\":\"0x717c0e8ccd4d5c7040185188fbae28be901ca589a11a94b1b38ca36a79eccfeb\", \"price_changes\":[{\"asset_id\":\"41448400836309843603620980831210604935021861034693225347475867885462478926555\", \"price\":\"0.18\", \"size\":\"73.98\", \"side\":\"SELL\", \"hash\":\"9e4c1f6f85bcdc6a8f7d52e595984c23f435b7a7\", \"best_bid\":\"0.15\", \"best_ask\":\"0.16\"}, {\"asset_id\":\"24254094493625419915756280046002869097156693848522361803041977572204227262166\", \"price\":\"0.82\", \"size\":\"73.98\", \"side\":\"BUY\", \"hash\":\"8219536482ae314f4adcc7651e7190b5c0623604\", \"best_bid\":\"0.84\", \"best_ask\":\"0.85\"}], \"timestamp\":\"1785122806962\", \"event_type\":\"price_change\"}","received_at":"2026-07-27T03:26:46.839066Z","schema_version":"clob-market-ws.price_change.v1","sequence":null,"server_hash":null,"server_timestamp":"1785122806962","session_id":"dd162b8dca5f43ff811d304e69a06123","source":"clob_market_ws"},"received_at":"2026-07-27T03:26:46.839066Z","record_id":"b0debe7c14b58e845659ce33753a0a5e3bef6d46849a409117fb498b39cd8cba","schema_fingerprint":"4aa3821a28b0b7c2400bc59aba4bcc0a76e971dadd19610d3ad38c768e124dc7","schema_version":"edge-lab-recorder.raw.v1","sequence":null,"source":"clob_market_ws"}
{"event_at":"2026-07-27T03:26:46.963000Z","event_fingerprint":"033075762a5e56c84aad23ee8ab37438d619b951f7f656badf04005efe65386c","payload":{"connection_id":"c7dc2e4762f849c6b6f9306b6518dcab","event_at":"2026-07-27T03:26:46.963000Z","event_type":"price_change","frame_hash":"127f6020d0bd04f634350ec29294371256afd1887c2ea764e221ad41d4c04872","frame_index":0,"kind":"data","monotonic_ns":224790203343083,"payload":{"event_type":"price_change","market":"0x717c0e8ccd4d5c7040185188fbae28be901ca589a11a94b1b38ca36a79eccfeb","price_changes":[{"asset_id":"24254094493625419915756280046002869097156693848522361803041977572204227262166","best_ask":"0.85","best_bid":"0.84","hash":"19cb554f0320e7339970fa14e1cd4ce6209c3eff","price":"0.84","side":"BUY","size":"116.53"},{"asset_id":"41448400836309843603620980831210604935021861034693225347475867885462478926555","best_ask":"0.16","best_bid":"0.15","hash":"4e17c875fb9b8b3e17fc0e80692e967512cd716f","price":"0.16","side":"SELL","size":"116.53"}],"timestamp":"1785122806963"},"payload_hash":"f7236422b807e25b3d8c92819c76192190fa5dedd039eea4ba87681141301a0d","raw_frame":"{\"market\":\"0x717c0e8ccd4d5c7040185188fbae28be901ca589a11a94b1b38ca36a79eccfeb\", \"price_changes\":[{\"asset_id\":\"24254094493625419915756280046002869097156693848522361803041977572204227262166\", \"price\":\"0.84\", \"size\":\"116.53\", \"side\":\"BUY\", \"hash\":\"19cb554f0320e7339970fa14e1cd4ce6209c3eff\", \"best_bid\":\"0.84\", \"best_ask\":\"0.85\"}, {\"asset_id\":\"41448400836309843603620980831210604935021861034693225347475867885462478926555\", \"price\":\"0.16\", \"size\":\"116.53\", \"side\":\"SELL\", \"hash\":\"4e17c875fb9b8b3e17fc0e80692e967512cd716f\", \"best_bid\":\"0.15\", \"best_ask\":\"0.16\"}], \"timestamp\":\"1785122806963\", \"event_type\":\"price_change\"}","received_at":"2026-07-27T03:26:46.842806Z","schema_version":"clob-market-ws.price_change.v1","sequence":null,"server_hash":null,"server_timestamp":"1785122806963","session_id":"dd162b8dca5f43ff811d304e69a06123","source":"clob_market_ws"},"received_at":"2026-07-27T03:26:46.842806Z","record_id":"6beca959a5e831e1d3e04fe2e9a94400f0c2cca4c3e76494da3f0971b9bf6f8e","schema_fingerprint":"4aa3821a28b0b7c2400bc59aba4bcc0a76e971dadd19610d3ad38c768e124dc7","schema_version":"edge-lab-recorder.raw.v1","sequence":null,"source":"clob_market_ws"}
{"event_at":"2026-07-27T03:26:46.966000Z","event_fingerprint":"d951962db295d373e2f0fe54c561bda79c51fd2a4aca396d4688adfd8a28d6dd","payload":{"connection_id":"c7dc2e4762f849c6b6f9306b6518dcab","event_at":"2026-07-27T03:26:46.966000Z","event_type":"price_change","frame_hash":"fa3ad2dbd364b1668ab9f7ffd4cd620deb03335ca6acf7680386e227e05af5cd","frame_index":0,"kind":"data","monotonic_ns":224790205006333,"payload":{"event_type":"price_change","market":"0x717c0e8ccd4d5c7040185188fbae28be901ca589a11a94b1b38ca36a79eccfeb","price_changes":[{"asset_id":"41448400836309843603620980831210604935021861034693225347475867885462478926555","best_ask":"0.16","best_bid":"0.15","hash":"93cafe462e0364145302e76e730b759755d82e4d","price":"0.11","side":"BUY","size":"9.6"},{"asset_id":"24254094493625419915756280046002869097156693848522361803041977572204227262166","best_ask":"0.85","best_bid":"0.84","hash":"61d87280f0b73709d4dfb011ffc2f94885792047","price":"0.89","side":"SELL","size":"9.6"}],"timestamp":"1785122806966"},"payload_hash":"19217c88a43764ccfc62ac22816b4be43649f8f2781aa78354fdecbd06ec09ed","raw_frame":"{\"market\":\"0x717c0e8ccd4d5c7040185188fbae28be901ca589a11a94b1b38ca36a79eccfeb\", \"price_changes\":[{\"asset_id\":\"41448400836309843603620980831210604935021861034693225347475867885462478926555\", \"price\":\"0.11\", \"size\":\"9.6\", \"side\":\"BUY\", \"hash\":\"93cafe462e0364145302e76e730b759755d82e4d\", \"best_bid\":\"0.15\", \"best_ask\":\"0.16\"}, {\"asset_id\":\"24254094493625419915756280046002869097156693848522361803041977572204227262166\", \"price\":\"0.89\", \"size\":\"9.6\", \"side\":\"SELL\", \"hash\":\"61d87280f0b73709d4dfb011ffc2f94885792047\", \"best_bid\":\"0.84\", \"best_ask\":\"0.85\"}], \"timestamp\":\"1785122806966\", \"event_type\":\"price_change\"}","received_at":"2026-07-27T03:26:46.844468Z","schema_version":"clob-market-ws.price_change.v1","sequence":null,"server_hash":null,"server_timestamp":"1785122806966","session_id":"dd162b8dca5f43ff811d304e69a06123","source":"clob_market_ws"},"received_at":"2026-07-27T03:26:46.844468Z","record_id":"3784fc16a05c16b9db144c1f9534dbef1a605ed635c0ce17cdaf96d304459850","schema_fingerprint":"4aa3821a28b0b7c2400bc59aba4bcc0a76e971dadd19610d3ad38c768e124dc7","schema_version":"edge-lab-recorder.raw.v1","sequence":null,"source":"clob_market_ws"}
{"event_at":"2026-07-27T03:26:46.968000Z","event_fingerprint":"be26c196a0bcb212f761e143420512f53fa568b609f55e40e5d0795de0ba0cb0","payload":{"connection_id":"c7dc2e4762f849c6b6f9306b6518dcab","event_at":"2026-07-27T03:26:46.968000Z","event_type":"price_change","frame_hash":"a9e14bc92e4ac646ecd48087303589556f79741c66bf13eb45922b17f7b7401b","frame_index":0,"kind":"data","monotonic_ns":224790206301166,"payload":{"event_type":"price_change","market":"0x717c0e8ccd4d5c7040185188fbae28be901ca589a11a94b1b38ca36a79eccfeb","price_changes":[{"asset_id":"24254094493625419915756280046002869097156693848522361803041977572204227262166","best_ask":"0.85","best_bid":"0.84","hash":"8208453780cc2ce840af07085b51e33c0cc5e684","price":"0.03","side":"BUY","size":"515"},{"asset_id":"41448400836309843603620980831210604935021861034693225347475867885462478926555","best_ask":"0.16","best_bid":"0.15","hash":"04bd2258ae2b9fbe2f8eb4286983f6f1dd3a6e4e","price":"0.97","side":"SELL","size":"515"}],"timestamp":"1785122806968"},"payload_hash":"8fc9803449189b16f2084b73d2cd5b21206c6929220914403931339a2bd373a0","raw_frame":"{\"market\":\"0x717c0e8ccd4d5c7040185188fbae28be901ca589a11a94b1b38ca36a79eccfeb\", \"price_changes\":[{\"asset_id\":\"24254094493625419915756280046002869097156693848522361803041977572204227262166\", \"price\":\"0.03\", \"size\":\"515\", \"side\":\"BUY\", \"hash\":\"8208453780cc2ce840af07085b51e33c0cc5e684\", \"best_bid\":\"0.84\", \"best_ask\":\"0.85\"}, {\"asset_id\":\"41448400836309843603620980831210604935021861034693225347475867885462478926555\", \"price\":\"0.97\", \"size\":\"515\", \"side\":\"SELL\", \"hash\":\"04bd2258ae2b9fbe2f8eb4286983f6f1dd3a6e4e\", \"best_bid\":\"0.15\", \"best_ask\":\"0.16\"}], \"timestamp\":\"1785122806968\", \"event_type\":\"price_change\"}","received_at":"2026-07-27T03:26:46.845767Z","schema_version":"clob-market-ws.price_change.v1","sequence":null,"server_hash":null,"server_timestamp":"1785122806968","session_id":"dd162b8dca5f43ff811d304e69a06123","source":"clob_market_ws"},"received_at":"2026-07-27T03:26:46.845767Z","record_id":"be822b77f3e1dfeb780765d069211b3064e056441b416dd30c0891c736861adb","schema_fingerprint":"4aa3821a28b0b7c2400bc59aba4bcc0a76e971dadd19610d3ad38c768e124dc7","schema_version":"edge-lab-recorder.raw.v1","sequence":null,"source":"clob_market_ws"}
{"event_at":"2026-07-27T03:26:46.968000Z","event_fingerprint":"96ce7143841086e01b132b5813dd8fcb1929e92afdb9e72d86472c5da87ffa64","payload":{"connection_id":"c7dc2e4762f849c6b6f9306b6518dcab","event_at":"2026-07-27T03:26:46.968000Z","event_type":"price_change","frame_hash":"57b7cbe4920c89fbd61d26308ae2a8961fbe2809d6cf1b3bc2493c2053ec331a","frame_index":0,"kind":"data","monotonic_ns":224790207291000,"payload":{"event_type":"price_change","market":"0x717c0e8ccd4d5c7040185188fbae28be901ca589a11a94b1b38ca36a79eccfeb","price_changes":[{"asset_id":"24254094493625419915756280046002869097156693848522361803041977572204227262166","best_ask":"0.85","best_bid":"0.84","hash":"1fcbd0a6f7b1d8bb8e3f6d1afd57c8e2470e7af3","price":"0.89","side":"SELL","size":"24.6"},{"asset_id":"41448400836309843603620980831210604935021861034693225347475867885462478926555","best_ask":"0.16","best_bid":"0.15","hash":"333901d4995a3f63f129e00438aa6bfd04c032b0","price":"0.11","side":"BUY","size":"24.6"}],"timestamp":"1785122806968"},"payload_hash":"a7fa0cbee9cc79e81b24a5ff9da2c4f245be6f6b8cac4488be5c963f7d924cb9","raw_frame":"{\"market\":\"0x717c0e8ccd4d5c7040185188fbae28be901ca589a11a94b1b38ca36a79eccfeb\", \"price_changes\":[{\"asset_id\":\"24254094493625419915756280046002869097156693848522361803041977572204227262166\", \"price\":\"0.89\", \"size\":\"24.6\", \"side\":\"SELL\", \"hash\":\"1fcbd0a6f7b1d8bb8e3f6d1afd57c8e2470e7af3\", \"best_bid\":\"0.84\", \"best_ask\":\"0.85\"}, {\"asset_id\":\"41448400836309843603620980831210604935021861034693225347475867885462478926555\", \"price\":\"0.11\", \"size\":\"24.6\", \"side\":\"BUY\", \"hash\":\"333901d4995a3f63f129e00438aa6bfd04c032b0\", \"best_bid\":\"0.15\", \"best_ask\":\"0.16\"}], \"timestamp\":\"1785122806968\", \"event_type\":\"price_change\"}","received_at":"2026-07-27T03:26:46.846758Z","schema_version":"clob-market-ws.price_change.v1","sequence":null,"server_hash":null,"server_timestamp":"1785122806968","session_id":"dd162b8dca5f43ff811d304e69a06123","source":"clob_market_ws"},"received_at":"2026-07-27T03:26:46.846758Z","record_id":"373510d7b122efda2cb314b1761c2959067a4928f6c48223f5c73edac9c93626","schema_fingerprint":"4aa3821a28b0b7c2400bc59aba4bcc0a76e971dadd19610d3ad38c768e124dc7","schema_version":"edge-lab-recorder.raw.v1","sequence":null,"source":"clob_market_ws"}
{"event_at":"2026-07-27T03:26:46.973000Z","event_fingerprint":"f5a2411704bdf0748b648889f6695d1d5cdc4b405f4582aa4f7df4b97c37358d","payload":{"connection_id":"c7dc2e4762f849c6b6f9306b6518dcab","event_at":"2026-07-27T03:26:46.973000Z","event_type":"price_change","frame_hash":"7dcb742be7eb5fc2b068e596959fbbad3129aa34420aa49ec403682073eb6491","frame_index":0,"kind":"data","monotonic_ns":224790208058208,"payload":{"event_type":"price_change","market":"0x717c0e8ccd4d5c7040185188fbae28be901ca589a11a94b1b38ca36a79eccfeb","price_changes":[{"asset_id":"24254094493625419915756280046002869097156693848522361803041977572204227262166","best_ask":"0.85","best_bid":"0.84","hash":"7a81188ff2072e2d480e0a6cdac894b601095cb2","price":"0.78","side":"BUY","size":"107"},{"asset_id":"41448400836309843603620980831210604935021861034693225347475867885462478926555","best_ask":"0.16","best_bid":"0.15","hash":"93dc93993cc49b63dc3c205d518c555ea9f85ee6","price":"0.22","side":"SELL","size":"107"}],"timestamp":"1785122806973"},"payload_hash":"45325a50db072d8205ed67498909c0ed691a7050e7a52fdd2ff30a00a860c942","raw_frame":"{\"market\":\"0x717c0e8ccd4d5c7040185188fbae28be901ca589a11a94b1b38ca36a79eccfeb\", \"price_changes\":[{\"asset_id\":\"24254094493625419915756280046002869097156693848522361803041977572204227262166\", \"price\":\"0.78\", \"size\":\"107\", \"side\":\"BUY\", \"hash\":\"7a81188ff2072e2d480e0a6cdac894b601095cb2\", \"best_bid\":\"0.84\", \"best_ask\":\"0.85\"}, {\"asset_id\":\"41448400836309843603620980831210604935021861034693225347475867885462478926555\", \"price\":\"0.22\", \"size\":\"107\", \"side\":\"SELL\", \"hash\":\"93dc93993cc49b63dc3c205d518c555ea9f85ee6\", \"best_bid\":\"0.15\", \"best_ask\":\"0.16\"}], \"timestamp\":\"1785122806973\", \"event_type\":\"price_change\"}","received_at":"2026-07-27T03:26:46.847526Z","schema_version":"clob-market-ws.price_change.v1","sequence":null,"server_hash":null,"server_timestamp":"1785122806973","session_id":"dd162b8dca5f43ff811d304e69a06123","source":"clob_market_ws"},"received_at":"2026-07-27T03:26:46.847526Z","record_id":"166421ab96139b50f0f5ef7230ebf2147dee9b82e23ef8d5e2c8063d067d831a","schema_fingerprint":"4aa3821a28b0b7c2400bc59aba4bcc0a76e971dadd19610d3ad38c768e124dc7","schema_version":"edge-lab-recorder.raw.v1","sequence":null,"source":"clob_market_ws"}
{"event_at":"2026-07-27T03:26:46.974000Z","event_fingerprint":"b08c9a5fa5672a1fb570f6954d4a9c6fb88277385e3c847bc96c4ae06dfc5596","payload":{"connection_id":"c7dc2e4762f849c6b6f9306b6518dcab","event_at":"2026-07-27T03:26:46.974000Z","event_type":"best_bid_ask","frame_hash":"ccc1ec8df4c797f4af88e1f64c251bc87c0e3c71ca613cd0d87ef5443e66860d","frame_index":0,"kind":"data","monotonic_ns":224790208760375,"payload":{"asset_id":"24254094493625419915756280046002869097156693848522361803041977572204227262166","best_ask":"0.86","best_bid":"0.84","event_type":"best_bid_ask","market":"0x717c0e8ccd4d5c7040185188fbae28be901ca589a11a94b1b38ca36a79eccfeb","spread":"0.02","timestamp":"1785122806974"},"payload_hash":"5bd88b86b5164870265dc83fc905180e9d224528e45a89ec8b34bec21f56c9e4","raw_frame":"{\"market\":\"0x717c0e8ccd4d5c7040185188fbae28be901ca589a11a94b1b38ca36a79eccfeb\", \"asset_id\":\"24254094493625419915756280046002869097156693848522361803041977572204227262166\", \"best_bid\":\"0.84\", \"best_ask\":\"0.86\", \"spread\":\"0.02\", \"timestamp\":\"1785122806974\", \"event_type\":\"best_bid_ask\"}","received_at":"2026-07-27T03:26:46.848229Z","schema_version":"clob-market-ws.best_bid_ask.v1","sequence":null,"server_hash":null,"server_timestamp":"1785122806974","session_id":"dd162b8dca5f43ff811d304e69a06123","source":"clob_market_ws"},"received_at":"2026-07-27T03:26:46.848229Z","record_id":"bd232c67d9c34e4b6617052e0f41c2335978fd30ad2aea029de78d2a7a5bd5c9","schema_fingerprint":"8488399f31b0337811b13b266be932db7062827c2470b78bd8e9e99bab51d17d","schema_version":"edge-lab-recorder.raw.v1","sequence":null,"source":"clob_market_ws"}
{"event_at":"2026-07-27T03:26:46.974000Z","event_fingerprint":"0ed0aff86fbc4f73578e7fcdc92b306894a0a533fb2185920aedce9979fbfa97","payload":{"connection_id":"c7dc2e4762f849c6b6f9306b6518dcab","event_at":"2026-07-27T03:26:46.974000Z","event_type":"best_bid_ask","frame_hash":"789011236683a0e567629524d0ad09e0c46c47c76bbf1c3dc1dfbdc08df39682","frame_index":0,"kind":"data","monotonic_ns":224790209352083,"payload":{"asset_id":"41448400836309843603620980831210604935021861034693225347475867885462478926555","best_ask":"0.16","best_bid":"0.14","event_type":"best_bid_ask","market":"0x717c0e8ccd4d5c7040185188fbae28be901ca589a11a94b1b38ca36a79eccfeb","spread":"0.02","timestamp":"1785122806974"},"payload_hash":"9b24d950ca61ff0986d6025cc0bf79e5523d19f32badf5ffdf09346cb6df2799","raw_frame":"{\"market\":\"0x717c0e8ccd4d5c7040185188fbae28be901ca589a11a94b1b38ca36a79eccfeb\", \"asset_id\":\"41448400836309843603620980831210604935021861034693225347475867885462478926555\", \"best_bid\":\"0.14\", \"best_ask\":\"0.16\", \"spread\":\"0.02\", \"timestamp\":\"1785122806974\", \"event_type\":\"best_bid_ask\"}","received_at":"2026-07-27T03:26:46.848818Z","schema_version":"clob-market-ws.best_bid_ask.v1","sequence":null,"server_hash":null,"server_timestamp":"1785122806974","session_id":"dd162b8dca5f43ff811d304e69a06123","source":"clob_market_ws"},"received_at":"2026-07-27T03:26:46.848818Z","record_id":"864d2796db6fdc35f7ee3ab577d604916eac420b18d4c88f38dfbc926110939a","schema_fingerprint":"8488399f31b0337811b13b266be932db7062827c2470b78bd8e9e99bab51d17d","schema_version":"edge-lab-recorder.raw.v1","sequence":null,"source":"clob_market_ws"}
{"event_at":"2026-07-27T03:26:46.974000Z","event_fingerprint":"9c9f4e4f3ee375c4b46dc49d50550fb9ec6ff3aaa70e2fa5d3241375797dc2ea","payload":{"connection_id":"c7dc2e4762f849c6b6f9306b6518dcab","event_at":"2026-07-27T03:26:46.974000Z","event_type":"price_change","frame_hash":"dbacade9782319dfcf8acc58b14032637b613fd54d1fc903707825db0b5676db","frame_index":0,"kind":"data","monotonic_ns":224790217393500,"payload":{"event_type":"price_change","market":"0x717c0e8ccd4d5c7040185188fbae28be901ca589a11a94b1b38ca36a79eccfeb","price_changes":[{"asset_id":"41448400836309843603620980831210604935021861034693225347475867885462478926555","best_ask":"0.16","best_bid":"0.14","hash":"a405fcbfcc05a84e0a2f09c94f629d7996c89487","price":"0.15","side":"BUY","size":"0"},{"asset_id":"24254094493625419915756280046002869097156693848522361803041977572204227262166","best_ask":"0.86","best_bid":"0.84","hash":"f5f409f8141e08f4c89f0e2ad385e2bd04391bc1","price":"0.85","side":"SELL","size":"0"}],"timestamp":"1785122806974"},"payload_hash":"0d6d521c4d4188033a07d6df790d4be2ce1dc1ab4020bdfe513ea2a4d07d25f6","raw_frame":"{\"market\":\"0x717c0e8ccd4d5c7040185188fbae28be901ca589a11a94b1b38ca36a79eccfeb\", \"price_changes\":[{\"asset_id\":\"41448400836309843603620980831210604935021861034693225347475867885462478926555\", \"price\":\"0.15\", \"size\":\"0\", \"side\":\"BUY\", \"hash\":\"a405fcbfcc05a84e0a2f09c94f629d7996c89487\", \"best_bid\":\"0.14\", \"best_ask\":\"0.16\"}, {\"asset_id\":\"24254094493625419915756280046002869097156693848522361803041977572204227262166\", \"price\":\"0.85\", \"size\":\"0\", \"side\":\"SELL\", \"hash\":\"f5f409f8141e08f4c89f0e2ad385e2bd04391bc1\", \"best_bid\":\"0.84\", \"best_ask\":\"0.86\"}], \"timestamp\":\"1785122806974\", \"event_type\":\"price_change\"}","received_at":"2026-07-27T03:26:46.856859Z","schema_version":"clob-market-ws.price_change.v1","sequence":null,"server_hash":null,"server_timestamp":"1785122806974","session_id":"dd162b8dca5f43ff811d304e69a06123","source":"clob_market_ws"},"received_at":"2026-07-27T03:26:46.856859Z","record_id":"83ad6475c98ce64f0ebf3626fbc3ff4e265f655e7dc91d799eeb1f471d2ba5a9","schema_fingerprint":"4aa3821a28b0b7c2400bc59aba4bcc0a76e971dadd19610d3ad38c768e124dc7","schema_version":"edge-lab-recorder.raw.v1","sequence":null,"source":"clob_market_ws"}
{"event_at":"2026-07-27T03:26:46.989000Z","event_fingerprint":"a3322689d617d27b53c9b7a56206c0e8ceaa127d6d0aa14b08c2cf9d667384a2","payload":{"connection_id":"c7dc2e4762f849c6b6f9306b6518dcab","event_at":"2026-07-27T03:26:46.989000Z","event_type":"price_change","frame_hash":"54376bcf92c6dfbefaddb06b5319e83c0aca8530057c4dcf40c810ca1ddf7a83","frame_index":0,"kind":"data","monotonic_ns":224790229808416,"payload":{"event_type":"price_change","market":"0x717c0e8ccd4d5c7040185188fbae28be901ca589a11a94b1b38ca36a79eccfeb","price_changes":[{"asset_id":"24254094493625419915756280046002869097156693848522361803041977572204227262166","best_ask":"0.86","best_bid":"0.84","hash":"b8cf8ff3785d79a5808543d40d4500a47bb330b2","price":"0.84","side":"BUY","size":"111.53"},{"asset_id":"41448400836309843603620980831210604935021861034693225347475867885462478926555","best_ask":"0.16","best_bid":"0.14","hash":"197c826016145e2a2eb6404f1a715d621cd38160","price":"0.16","side":"SELL","size":"111.53"}],"timestamp":"1785122806989"},"payload_hash":"37d15068005ad253838c0527da5fcb24caf920ab36ef20484e538848a1c58ae7","raw_frame":"{\"market\":\"0x717c0e8ccd4d5c7040185188fbae28be901ca589a11a94b1b38ca36a79eccfeb\", \"price_changes\":[{\"asset_id\":\"24254094493625419915756280046002869097156693848522361803041977572204227262166\", \"price\":\"0.84\", \"size\":\"111.53\", \"side\":\"BUY\", \"hash\":\"b8cf8ff3785d79a5808543d40d4500a47bb330b2\", \"best_bid\":\"0.84\", \"best_ask\":\"0.86\"}, {\"asset_id\":\"41448400836309843603620980831210604935021861034693225347475867885462478926555\", \"price\":\"0.16\", \"size\":\"111.53\", \"side\":\"SELL\", \"hash\":\"197c826016145e2a2eb6404f1a715d621cd38160\", \"best_bid\":\"0.14\", \"best_ask\":\"0.16\"}], \"timestamp\":\"1785122806989\", \"event_type\":\"price_change\"}","received_at":"2026-07-27T03:26:46.869266Z","schema_version":"clob-market-ws.price_change.v1","sequence":null,"server_hash":null,"server_timestamp":"1785122806989","session_id":"dd162b8dca5f43ff811d304e69a06123","source":"clob_market_ws"},"received_at":"2026-07-27T03:26:46.869266Z","record_id":"56f238b7f6f3e1384f4e5aa40c73834f00d5cfe1f9e39ba60565c59eb33ee341","schema_fingerprint":"4aa3821a28b0b7c2400bc59aba4bcc0a76e971dadd19610d3ad38c768e124dc7","schema_version":"edge-lab-recorder.raw.v1","sequence":null,"source":"clob_market_ws"}
{"event_at":"2026-07-27T03:26:47.007000Z","event_fingerprint":"044b472e89c145db951ee98679e164c4549846cd951808e21325a73649cb8875","payload":{"connection_id":"c7dc2e4762f849c6b6f9306b6518dcab","event_at":"2026-07-27T03:26:47.007000Z","event_type":"price_change","frame_hash":"95c82994c4963dc594d648716fe66d473636c209757729bdd3ecd4dda04f21ea","frame_index":0,"kind":"data","monotonic_ns":224790240753166,"payload":{"event_type":"price_change","market":"0x717c0e8ccd4d5c7040185188fbae28be901ca589a11a94b1b38ca36a79eccfeb","price_changes":[{"asset_id":"24254094493625419915756280046002869097156693848522361803041977572204227262166","best_ask":"0.86","best_bid":"0.84","hash":"f1d1f0bd1c85ebfe787105b4166681ebe976d860","price":"0.77","side":"BUY","size":"112"},{"asset_id":"41448400836309843603620980831210604935021861034693225347475867885462478926555","best_ask":"0.16","best_bid":"0.14","hash":"1ae5342b8fe78b7d61ade66dda867098ce6035aa","price":"0.23","side":"SELL","size":"112"}],"timestamp":"1785122807007"},"payload_hash":"4bca74ae9396c081618672e443008325cd4a5c8c1c1b84925d53613123caccc9","raw_frame":"{\"market\":\"0x717c0e8ccd4d5c7040185188fbae28be901ca589a11a94b1b38ca36a79eccfeb\", \"price_changes\":[{\"asset_id\":\"24254094493625419915756280046002869097156693848522361803041977572204227262166\", \"price\":\"0.77\", \"size\":\"112\", \"side\":\"BUY\", \"hash\":\"f1d1f0bd1c85ebfe787105b4166681ebe976d860\", \"best_bid\":\"0.84\", \"best_ask\":\"0.86\"}, {\"asset_id\":\"41448400836309843603620980831210604935021861034693225347475867885462478926555\", \"price\":\"0.23\", \"size\":\"112\", \"side\":\"SELL\", \"hash\":\"1ae5342b8fe78b7d61ade66dda867098ce6035aa\", \"best_bid\":\"0.14\", \"best_ask\":\"0.16\"}], \"timestamp\":\"1785122807007\", \"event_type\":\"price_change\"}","received_at":"2026-07-27T03:26:46.880214Z","schema_version":"clob-market-ws.price_change.v1","sequence":null,"server_hash":null,"server_timestamp":"1785122807007","session_id":"dd162b8dca5f43ff811d304e69a06123","source":"clob_market_ws"},"received_at":"2026-07-27T03:26:46.880214Z","record_id":"ec9315b691455a65ee18b1674b10a3877f98007c0f4df333faa32984f4d1542a","schema_fingerprint":"4aa3821a28b0b7c2400bc59aba4bcc0a76e971dadd19610d3ad38c768e124dc7","schema_version":"edge-lab-recorder.raw.v1","sequence":null,"source":"clob_market_ws"}
{"event_at":"2026-07-27T03:26:47.026000Z","event_fingerprint":"fcbdd789cc78e8df3f319de69d1dd92c23ead7108dcf876bdc7b541cda53a9f7","payload":{"connection_id":"c7dc2e4762f849c6b6f9306b6518dcab","event_at":"2026-07-27T03:26:47.026000Z","event_type":"price_change","frame_hash":"ed9c8176856a132677a6e349ff12b313494fa59d80dbb037ba79014b18a1d9d0","frame_index":0,"kind":"data","monotonic_ns":224790264159750,"payload":{"event_type":"price_change","market":"0x717c0e8ccd4d5c7040185188fbae28be901ca589a11a94b1b38ca36a79eccfeb","price_changes":[{"asset_id":"41448400836309843603620980831210604935021861034693225347475867885462478926555","best_ask":"0.16","best_bid":"0.14","hash":"c66fd902afd63013a702885aa91444e5a03a0bea","price":"0.01","side":"BUY","size":"5745.02"},{"asset_id":"24254094493625419915756280046002869097156693848522361803041977572204227262166","best_ask":"0.86","best_bid":"0.84","hash":"2f9a16fd29854fb1e10f0208573ec81a84f9b2fa","price":"0.99","side":"SELL","size":"5745.02"}],"timestamp":"1785122807026"},"payload_hash":"65b42a82aa1fba811211ee006414a4d571ae71b86b15db9b9c02d96053e8f481","raw_frame":"{\"market\":\"0x717c0e8ccd4d5c7040185188fbae28be901ca589a11a94b1b38ca36a79eccfeb\", \"price_changes\":[{\"asset_id\":\"41448400836309843603620980831210604935021861034693225347475867885462478926555\", \"price\":\"0.01\", \"size\":\"5745.02\", \"side\":\"BUY\", \"hash\":\"c66fd902afd63013a702885aa91444e5a03a0bea\", \"best_bid\":\"0.14\", \"best_ask\":\"0.16\"}, {\"asset_id\":\"24254094493625419915756280046002869097156693848522361803041977572204227262166\", \"price\":\"0.99\", \"size\":\"5745.02\", \"side\":\"SELL\", \"hash\":\"2f9a16fd29854fb1e10f0208573ec81a84f9b2fa\", \"best_bid\":\"0.84\", \"best_ask\":\"0.86\"}], \"timestamp\":\"1785122807026\", \"event_type\":\"price_change\"}","received_at":"2026-07-27T03:26:46.903623Z","schema_version":"clob-market-ws.price_change.v1","sequence":null,"server_hash":null,"server_timestamp":"1785122807026","session_id":"dd162b8dca5f43ff811d304e69a06123","source":"clob_market_ws"},"received_at":"2026-07-27T03:26:46.903623Z","record_id":"ae1653b18152071580fdd2dff7b47110a1197c95c3c87cc5ef64e5c00f98aa88","schema_fingerprint":"4aa3821a28b0b7c2400bc59aba4bcc0a76e971dadd19610d3ad38c768e124dc7","schema_version":"edge-lab-recorder.raw.v1","sequence":null,"source":"clob_market_ws"}
{"event_at":"2026-07-27T03:26:47.030000Z","event_fingerprint":"a9b9cd66eaff747935fd38eaf527e860d6ac738b2db57ab13126ce4469462a0a","payload":{"connection_id":"c7dc2e4762f849c6b6f9306b6518dcab","event_at":"2026-07-27T03:26:47.030000Z","event_type":"price_change","frame_hash":"f20fb4b38b3445ef224e0824b4bc5591811df394e5e8c0b159dee859bb197888","frame_index":0,"kind":"data","monotonic_ns":224790267259375,"payload":{"event_type":"price_change","market":"0x717c0e8ccd4d5c7040185188fbae28be901ca589a11a94b1b38ca36a79eccfeb","price_changes":[{"asset_id":"41448400836309843603620980831210604935021861034693225347475867885462478926555","best_ask":"0.16","best_bid":"0.14","hash":"75f7452c80543bfef25ae11a6183bc1e0fe4b81a","price":"0.01","side":"BUY","size":"5750.02"},{"asset_id":"24254094493625419915756280046002869097156693848522361803041977572204227262166","best_ask":"0.86","best_bid":"0.84","hash":"ad436797ab7168e2cd9296da7f6a0262b0a30969","price":"0.99","side":"SELL","size":"5750.02"}],"timestamp":"1785122807030"},"payload_hash":"67148b01e224419526bccb18a777f78b71a4ed83c833707665fc319a7a6352cf","raw_frame":"{\"market\":\"0x717c0e8ccd4d5c7040185188fbae28be901ca589a11a94b1b38ca36a79eccfeb\", \"price_changes\":[{\"asset_id\":\"41448400836309843603620980831210604935021861034693225347475867885462478926555\", \"price\":\"0.01\", \"size\":\"5750.02\", \"side\":\"BUY\", \"hash\":\"75f7452c80543bfef25ae11a6183bc1e0fe4b81a\", \"best_bid\":\"0.14\", \"best_ask\":\"0.16\"}, {\"asset_id\":\"24254094493625419915756280046002869097156693848522361803041977572204227262166\", \"price\":\"0.99\", \"size\":\"5750.02\", \"side\":\"SELL\", \"hash\":\"ad436797ab7168e2cd9296da7f6a0262b0a30969\", \"best_bid\":\"0.84\", \"best_ask\":\"0.86\"}], \"timestamp\":\"1785122807030\", \"event_type\":\"price_change\"}","received_at":"2026-07-27T03:26:46.906723Z","schema_version":"clob-market-ws.price_change.v1","sequence":null,"server_hash":null,"server_timestamp":"1785122807030","session_id":"dd162b8dca5f43ff811d304e69a06123","source":"clob_market_ws"},"received_at":"2026-07-27T03:26:46.906723Z","record_id":"c6ae69761d2b031dab5918aa2d3f75d4f300a9383e65308e7a55bd6c7b7a1198","schema_fingerprint":"4aa3821a28b0b7c2400bc59aba4bcc0a76e971dadd19610d3ad38c768e124dc7","schema_version":"edge-lab-recorder.raw.v1","sequence":null,"source":"clob_market_ws"}
{"event_at":"2026-07-27T03:26:47.031000Z","event_fingerprint":"3c6cb45d444ea1e242d178e8177ba01b9a2ee04f8e10fb2aca4c371079855c4c","payload":{"connection_id":"c7dc2e4762f849c6b6f9306b6518dcab","event_at":"2026-07-27T03:26:47.031000Z","event_type":"price_change","frame_hash":"d02147801aae36fb2f4fac7b13a8ecced8c2e9cb748b30412889ee92304312ae","frame_index":0,"kind":"data","monotonic_ns":224790269617000,"payload":{"event_type":"price_change","market":"0x717c0e8ccd4d5c7040185188fbae28be901ca589a11a94b1b38ca36a79eccfeb","price_changes":[{"asset_id":"24254094493625419915756280046002869097156693848522361803041977572204227262166","best_ask":"0.86","best_bid":"0.84","hash":"0a79ab3493d561e9bc9635d10c58ab420ed8f365","price":"0.03","side":"BUY","size":"510"},{"asset_id":"41448400836309843603620980831210604935021861034693225347475867885462478926555","best_ask":"0.16","best_bid":"0.14","hash":"1715eb314c3eee88f1c4bd1ce9aae11678717fe3","price":"0.97","side":"SELL","size":"510"}],"timestamp":"1785122807031"},"payload_hash":"ff4378c84177f5f349042172c177fabaea9e9d8bb82b7635ec35baac9dc858bd","raw_frame":"{\"market\":\"0x717c0e8ccd4d5c7040185188fbae28be901ca589a11a94b1b38ca36a79eccfeb\", \"price_changes\":[{\"asset_id\":\"24254094493625419915756280046002869097156693848522361803041977572204227262166\", \"price\":\"0.03\", \"size\":\"510\", \"side\":\"BUY\", \"hash\":\"0a79ab3493d561e9bc9635d10c58ab420ed8f365\", \"best_bid\":\"0.84\", \"best_ask\":\"0.86\"}, {\"asset_id\":\"41448400836309843603620980831210604935021861034693225347475867885462478926555\", \"price\":\"0.97\", \"size\":\"510\", \"side\":\"SELL\", \"hash\":\"1715eb314c3eee88f1c4bd1ce9aae11678717fe3\", \"best_bid\":\"0.14\", \"best_ask\":\"0.16\"}], \"timestamp\":\"1785122807031\", \"event_type\":\"price_change\"}","received_at":"2026-07-27T03:26:46.909084Z","schema_version":"clob-market-ws.price_change.v1","sequence":null,"server_hash":null,"server_timestamp":"1785122807031","session_id":"dd162b8dca5f43ff811d304e69a06123","source":"clob_market_ws"},"received_at":"2026-07-27T03:26:46.909084Z","record_id":"481e52c302aaab9af5a439119657562cadfd264330922ccffca4c5991fe7a19d","schema_fingerprint":"4aa3821a28b0b7c2400bc59aba4bcc0a76e971dadd19610d3ad38c768e124dc7","schema_version":"edge-lab-recorder.raw.v1","sequence":null,"source":"clob_market_ws"}
{"event_at":"2026-07-27T03:26:47.044000Z","event_fingerprint":"c420e902627ddf0169447bb6122e3b3ca7eb898888aa9db32dc6a40dfecfe4f8","payload":{"connection_id":"c7dc2e4762f849c6b6f9306b6518dcab","event_at":"2026-07-27T03:26:47.044000Z","event_type":"best_bid_ask","frame_hash":"33d6ae3eb9ec57b3d086f13074eaa967272ed484a5d510a898ceb61c63e46d4b","frame_index":0,"kind":"data","monotonic_ns":224790280512041,"payload":{"asset_id":"24254094493625419915756280046002869097156693848522361803041977572204227262166","best_ask":"0.85","best_bid":"0.84","event_type":"best_bid_ask","market":"0x717c0e8ccd4d5c7040185188fbae28be901ca589a11a94b1b38ca36a79eccfeb","spread":"0.01","timestamp":"1785122807044"},"payload_hash":"1195ac3169dc7f6a8f967485655ac2c4f08481ead049caea0d6b251eb52900e8","raw_frame":"{\"market\":\"0x717c0e8ccd4d5c7040185188fbae28be901ca589a11a94b1b38ca36a79eccfeb\", \"asset_id\":\"24254094493625419915756280046002869097156693848522361803041977572204227262166\", \"best_bid\":\"0.84\", \"best_ask\":\"0.85\", \"spread\":\"0.01\", \"timestamp\":\"1785122807044\", \"event_type\":\"best_bid_ask\"}","received_at":"2026-07-27T03:26:46.919974Z","schema_version":"clob-market-ws.best_bid_ask.v1","sequence":null,"server_hash":null,"server_timestamp":"1785122807044","session_id":"dd162b8dca5f43ff811d304e69a06123","source":"clob_market_ws"},"received_at":"2026-07-27T03:26:46.919974Z","record_id":"4a961881bd0fc622a8ea353ed202a13d379ec7ddbc1f5c9651376f519a9717f6","schema_fingerprint":"8488399f31b0337811b13b266be932db7062827c2470b78bd8e9e99bab51d17d","schema_version":"edge-lab-recorder.raw.v1","sequence":null,"source":"clob_market_ws"}
{"event_at":"2026-07-27T03:26:47.044000Z","event_fingerprint":"1a549e16a6b5b5071b0ae82906844bb83751a084c5b91feb29933692ce28bdef","payload":{"connection_id":"c7dc2e4762f849c6b6f9306b6518dcab","event_at":"2026-07-27T03:26:47.044000Z","event_type":"best_bid_ask","frame_hash":"5de4212ff71a7de9773637d44c785ed92f2bc0ae668f11e13369ee571e93c15a","frame_index":0,"kind":"data","monotonic_ns":224790285067333,"payload":{"asset_id":"41448400836309843603620980831210604935021861034693225347475867885462478926555","best_ask":"0.16","best_bid":"0.15","event_type":"best_bid_ask","market":"0x717c0e8ccd4d5c7040185188fbae28be901ca589a11a94b1b38ca36a79eccfeb","spread":"0.01","timestamp":"1785122807044"},"payload_hash":"f9aad2aea5458390cb790a4b5c75c7a0c7248ddf234daaa684286799efb50259","raw_frame":"{\"market\":\"0x717c0e8ccd4d5c7040185188fbae28be901ca589a11a94b1b38ca36a79eccfeb\", \"asset_id\":\"41448400836309843603620980831210604935021861034693225347475867885462478926555\", \"best_bid\":\"0.15\", \"best_ask\":\"0.16\", \"spread\":\"0.01\", \"timestamp\":\"1785122807044\", \"event_type\":\"best_bid_ask\"}","received_at":"2026-07-27T03:26:46.924534Z","schema_version":"clob-market-ws.best_bid_ask.v1","sequence":null,"server_hash":null,"server_timestamp":"1785122807044","session_id":"dd162b8dca5f43ff811d304e69a06123","source":"clob_market_ws"},"received_at":"2026-07-27T03:26:46.924534Z","record_id":"15e6e7347f03db253b3961f903fd5a37f1f404c30a34fc51e7d281aedc18ade8","schema_fingerprint":"8488399f31b0337811b13b266be932db7062827c2470b78bd8e9e99bab51d17d","schema_version":"edge-lab-recorder.raw.v1","sequence":null,"source":"clob_market_ws"}
{"event_at":"2026-07-27T03:26:47.044000Z","event_fingerprint":"2d269e90624fbd034de53e88c1dfb5350da056e1ec8861065cbcf5e5f235c72c","payload":{"connection_id":"c7dc2e4762f849c6b6f9306b6518dcab","event_at":"2026-07-27T03:26:47.044000Z","event_type":"price_change","frame_hash":"fa299dd16e52b9017460de50490c71d82e8a81ce12548d9574726d9793010e14","frame_index":0,"kind":"data","monotonic_ns":224790288544041,"payload":{"event_type":"price_change","market":"0x717c0e8ccd4d5c7040185188fbae28be901ca589a11a94b1b38ca36a79eccfeb","price_changes":[{"asset_id":"41448400836309843603620980831210604935021861034693225347475867885462478926555","best_ask":"0.16","best_bid":"0.15","hash":"4c7c4fd87b569d56d863a28dbba62e2a8b4adb7d","price":"0.15","side":"BUY","size":"10"},{"asset_id":"24254094493625419915756280046002869097156693848522361803041977572204227262166","best_ask":"0.85","best_bid":"0.84","hash":"8b9607ad4d61623d08cfe9cdf3c927dafb34cf27","price":"0.85","side":"SELL","size":"10"}],"timestamp":"1785122807044"},"payload_hash":"efe66df19e660bff9a59350cc4178287fbfadf03c8224cd16e843011b1ac178c","raw_frame":"{\"market\":\"0x717c0e8ccd4d5c7040185188fbae28be901ca589a11a94b1b38ca36a79eccfeb\", \"price_changes\":[{\"asset_id\":\"41448400836309843603620980831210604935021861034693225347475867885462478926555\", \"price\":\"0.15\", \"size\":\"10\", \"side\":\"BUY\", \"hash\":\"4c7c4fd87b569d56d863a28dbba62e2a8b4adb7d\", \"best_bid\":\"0.15\", \"best_ask\":\"0.16\"}, {\"asset_id\":\"24254094493625419915756280046002869097156693848522361803041977572204227262166\", \"price\":\"0.85\", \"size\":\"10\", \"side\":\"SELL\", \"hash\":\"8b9607ad4d61623d08cfe9cdf3c927dafb34cf27\", \"best_bid\":\"0.84\", \"best_ask\":\"0.85\"}], \"timestamp\":\"1785122807044\", \"event_type\":\"price_change\"}","received_at":"2026-07-27T03:26:46.928006Z","schema_version":"clob-market-ws.price_change.v1","sequence":null,"server_hash":null,"server_timestamp":"1785122807044","session_id":"dd162b8dca5f43ff811d304e69a06123","source":"clob_market_ws"},"received_at":"2026-07-27T03:26:46.928006Z","record_id":"a6eae5761867c4499fc206cd7f17429f2e759e7d34ef676021cc16eeff81c409","schema_fingerprint":"4aa3821a28b0b7c2400bc59aba4bcc0a76e971dadd19610d3ad38c768e124dc7","schema_version":"edge-lab-recorder.raw.v1","sequence":null,"source":"clob_market_ws"}
{"event_at":"2026-07-27T03:26:47.045000Z","event_fingerprint":"faa29c9b92706aa980a59bfe5bce231d60bae8d05de46c9272000b6899293214","payload":{"connection_id":"c7dc2e4762f849c6b6f9306b6518dcab","event_at":"2026-07-27T03:26:47.045000Z","event_type":"price_change","frame_hash":"37158ffefb4cb3357823191395945b351ed0a0d7b2e219329f5dcd4cccc8f076","frame_index":0,"kind":"data","monotonic_ns":224790292796333,"payload":{"event_type":"price_change","market":"0x717c0e8ccd4d5c7040185188fbae28be901ca589a11a94b1b38ca36a79eccfeb","price_changes":[{"asset_id":"24254094493625419915756280046002869097156693848522361803041977572204227262166","best_ask":"0.85","best_bid":"0.84","hash":"4d9daa784bb890a58c2e64094a3d50b0bdf050a6","price":"0.78","side":"BUY","size":"117"},{"asset_id":"41448400836309843603620980831210604935021861034693225347475867885462478926555","best_ask":"0.16","best_bid":"0.15","hash":"bf960657757e6939bcf3fbbc125137f9c1b0eb22","price":"0.22","side":"SELL","size":"117"}],"timestamp":"1785122807045"},"payload_hash":"77d46250905f37baf2f80bb5b8d72e9f954281402f7ccb6b9c15cc5d0e456884","raw_frame":"{\"market\":\"0x717c0e8ccd4d5c7040185188fbae28be901ca589a11a94b1b38ca36a79eccfeb\", \"price_changes\":[{\"asset_id\":\"24254094493625419915756280046002869097156693848522361803041977572204227262166\", \"price\":\"0.78\", \"size\":\"117\", \"side\":\"BUY\", \"hash\":\"4d9daa784bb890a58c2e64094a3d50b0bdf050a6\", \"best_bid\":\"0.84\", \"best_ask\":\"0.85\"}, {\"asset_id\":\"41448400836309843603620980831210604935021861034693225347475867885462478926555\", \"price\":\"0.22\", \"size\":\"117\", \"side\":\"SELL\", \"hash\":\"bf960657757e6939bcf3fbbc125137f9c1b0eb22\", \"best_bid\":\"0.15\", \"best_ask\":\"0.16\"}], \"timestamp\":\"1785122807045\", \"event_type\":\"price_change\"}","received_at":"2026-07-27T03:26:46.932258Z","schema_version":"clob-market-ws.price_change.v1","sequence":null,"server_hash":null,"server_timestamp":"1785122807045","session_id":"dd162b8dca5f43ff811d304e69a06123","source":"clob_market_ws"},"received_at":"2026-07-27T03:26:46.932258Z","record_id":"866b357174dcdc181092275e453b8b8d752662d06586fd70792d6daaf91d4eef","schema_fingerprint":"4aa3821a28b0b7c2400bc59aba4bcc0a76e971dadd19610d3ad38c768e124dc7","schema_version":"edge-lab-recorder.raw.v1","sequence":null,"source":"clob_market_ws"}
{"event_at":"2026-07-27T03:26:47.049000Z","event_fingerprint":"b4afae4d68c4c9f3f4ba3b869fc1e8f47ce2bdaa54fdd595e93c6db4ec2dfc74","payload":{"connection_id":"c7dc2e4762f849c6b6f9306b6518dcab","event_at":"2026-07-27T03:26:47.049000Z","event_type":"price_change","frame_hash":"8713705cd3e422392cf9a80bf296027fe4247e51d641359342707e45d8d56a1d","frame_index":0,"kind":"data","monotonic_ns":224790295815666,"payload":{"event_type":"price_change","market":"0x717c0e8ccd4d5c7040185188fbae28be901ca589a11a94b1b38ca36a79eccfeb","price_changes":[{"asset_id":"24254094493625419915756280046002869097156693848522361803041977572204227262166","best_ask":"0.85","best_bid":"0.84","hash":"d48c9ba15d05df8536fead94196cc57bf01a7d34","price":"0.01","side":"BUY","size":"5155.02"},{"asset_id":"41448400836309843603620980831210604935021861034693225347475867885462478926555","best_ask":"0.16","best_bid":"0.15","hash":"64e57e6ac7fd74c671fda02f90e3200306a15b6a","price":"0.99","side":"SELL","size":"5155.02"}],"timestamp":"1785122807049"},"payload_hash":"02de6af5683cee0eeb6f223017d49edf8759db76a3a6f973359663a918385b44","raw_frame":"{\"market\":\"0x717c0e8ccd4d5c7040185188fbae28be901ca589a11a94b1b38ca36a79eccfeb\", \"price_changes\":[{\"asset_id\":\"24254094493625419915756280046002869097156693848522361803041977572204227262166\", \"price\":\"0.01\", \"size\":\"5155.02\", \"side\":\"BUY\", \"hash\":\"d48c9ba15d05df8536fead94196cc57bf01a7d34\", \"best_bid\":\"0.84\", \"best_ask\":\"0.85\"}, {\"asset_id\":\"41448400836309843603620980831210604935021861034693225347475867885462478926555\", \"price\":\"0.99\", \"size\":\"5155.02\", \"side\":\"SELL\", \"hash\":\"64e57e6ac7fd74c671fda02f90e3200306a15b6a\", \"best_bid\":\"0.15\", \"best_ask\":\"0.16\"}], \"timestamp\":\"1785122807049\", \"event_type\":\"price_change\"}","received_at":"2026-07-27T03:26:46.935278Z","schema_version":"clob-market-ws.price_change.v1","sequence":null,"server_hash":null,"server_timestamp":"1785122807049","session_id":"dd162b8dca5f43ff811d304e69a06123","source":"clob_market_ws"},"received_at":"2026-07-27T03:26:46.935278Z","record_id":"104318c2f725755e66c071869aa4806d281283c8f757d1ec3a95865817a63829","schema_fingerprint":"4aa3821a28b0b7c2400bc59aba4bcc0a76e971dadd19610d3ad38c768e124dc7","schema_version":"edge-lab-recorder.raw.v1","sequence":null,"source":"clob_market_ws"}
{"event_at":"2026-07-27T03:26:47.053000Z","event_fingerprint":"c31a3ebd941a59db1256b463ff5516da3743ce92ca8e0e92f564a8a08fec410f","payload":{"connection_id":"c7dc2e4762f849c6b6f9306b6518dcab","event_at":"2026-07-27T03:26:47.053000Z","event_type":"price_change","frame_hash":"55c5883759bf57156354c9765310337f18827cb1ea242742235866e5acb942d5","frame_index":0,"kind":"data","monotonic_ns":224790298537791,"payload":{"event_type":"price_change","market":"0x717c0e8ccd4d5c7040185188fbae28be901ca589a11a94b1b38ca36a79eccfeb","price_changes":[{"asset_id":"41448400836309843603620980831210604935021861034693225347475867885462478926555","best_ask":"0.16","best_bid":"0.15","hash":"9f8e5ce322ac19b789a9814fc81f457ac57014ec","price":"0.01","side":"BUY","size":"5745.02"},{"asset_id":"24254094493625419915756280046002869097156693848522361803041977572204227262166","best_ask":"0.85","best_bid":"0.84","hash":"c564604d644b5c3c9f484f0737a9e447ce5a4a9f","price":"0.99","side":"SELL","size":"5745.02"}],"timestamp":"1785122807053"},"payload_hash":"9811c581551036b222374fe227aeee6225f694ec5fd3fe5baef1d6ad2bd0c6a8","raw_frame":"{\"market\":\"0x717c0e8ccd4d5c7040185188fbae28be901ca589a11a94b1b38ca36a79eccfeb\", \"price_changes\":[{\"asset_id\":\"41448400836309843603620980831210604935021861034693225347475867885462478926555\", \"price\":\"0.01\", \"size\":\"5745.02\", \"side\":\"BUY\", \"hash\":\"9f8e5ce322ac19b789a9814fc81f457ac57014ec\", \"best_bid\":\"0.15\", \"best_ask\":\"0.16\"}, {\"asset_id\":\"24254094493625419915756280046002869097156693848522361803041977572204227262166\", \"price\":\"0.99\", \"size\":\"5745.02\", \"side\":\"SELL\", \"hash\":\"c564604d644b5c3c9f484f0737a9e447ce5a4a9f\", \"best_bid\":\"0.84\", \"best_ask\":\"0.85\"}], \"timestamp\":\"1785122807053\", \"event_type\":\"price_change\"}","received_at":"2026-07-27T03:26:46.937999Z","schema_version":"clob-market-ws.price_change.v1","sequence":null,"server_hash":null,"server_timestamp":"1785122807053","session_id":"dd162b8dca5f43ff811d304e69a06123","source":"clob_market_ws"},"received_at":"2026-07-27T03:26:46.937999Z","record_id":"517e59a2da3d429feb88be9544c0d2ef592afcb7fe4016eb5a2e7fe5341b913e","schema_fingerprint":"4aa3821a28b0b7c2400bc59aba4bcc0a76e971dadd19610d3ad38c768e124dc7","schema_version":"edge-lab-recorder.raw.v1","sequence":null,"source":"clob_market_ws"}
{"event_at":"2026-07-27T03:26:47.064000Z","event_fingerprint":"6952cdb913b5d2d3b6e22cd927a3cfed1ea26e4d799ce976ecfc9b22edebe1d6","payload":{"connection_id":"c7dc2e4762f849c6b6f9306b6518dcab","event_at":"2026-07-27T03:26:47.064000Z","event_type":"price_change","frame_hash":"85dbe4f7dc9f0d831108a045e23c76f89a6996ea13f323d473cc072829f2f569","frame_index":0,"kind":"data","monotonic_ns":224790303311791,"payload":{"event_type":"price_change","market":"0x717c0e8ccd4d5c7040185188fbae28be901ca589a11a94b1b38ca36a79eccfeb","price_changes":[{"asset_id":"24254094493625419915756280046002869097156693848522361803041977572204227262166","best_ask":"0.85","best_bid":"0.84","hash":"8adc5721d879014166b384909281cc8e695e8991","price":"0.89","side":"SELL","size":"9.6"},{"asset_id":"41448400836309843603620980831210604935021861034693225347475867885462478926555","best_ask":"0.16","best_bid":"0.15","hash":"704bca3d47a2a4fe9e0766805161ccaa722e98fd","price":"0.11","side":"BUY","size":"9.6"}],"timestamp":"1785122807064"},"payload_hash":"200ffad63547b0dbf879af676998dc06d0c856c70711c1be2c4f7c13d696bbe4","raw_frame":"{\"market\":\"0x717c0e8ccd4d5c7040185188fbae28be901ca589a11a94b1b38ca36a79eccfeb\", \"price_changes\":[{\"asset_id\":\"24254094493625419915756280046002869097156693848522361803041977572204227262166\", \"price\":\"0.89\", \"size\":\"9.6\", \"side\":\"SELL\", \"hash\":\"8adc5721d879014166b384909281cc8e695e8991\", \"best_bid\":\"0.84\", \"best_ask\":\"0.85\"}, {\"asset_id\":\"41448400836309843603620980831210604935021861034693225347475867885462478926555\", \"price\":\"0.11\", \"size\":\"9.6\", \"side\":\"BUY\", \"hash\":\"704bca3d47a2a4fe9e0766805161ccaa722e98fd\", \"best_bid\":\"0.15\", \"best_ask\":\"0.16\"}], \"timestamp\":\"1785122807064\", \"event_type\":\"price_change\"}","received_at":"2026-07-27T03:26:46.942774Z","schema_version":"clob-market-ws.price_change.v1","sequence":null,"server_hash":null,"server_timestamp":"1785122807064","session_id":"dd162b8dca5f43ff811d304e69a06123","source":"clob_market_ws"},"received_at":"2026-07-27T03:26:46.942774Z","record_id":"84dd0b30a7e4f5391a17e41cb06dd37f44ab5a0833379b90f5db0dae84fed319","schema_fingerprint":"4aa3821a28b0b7c2400bc59aba4bcc0a76e971dadd19610d3ad38c768e124dc7","schema_version":"edge-lab-recorder.raw.v1","sequence":null,"source":"clob_market_ws"}
{"event_at":"2026-07-27T03:26:47.069000Z","event_fingerprint":"8b072f135bea5a74b1a719af08ecd75cf1face93e2770cae2e5e70808a18268e","payload":{"connection_id":"c7dc2e4762f849c6b6f9306b6518dcab","event_at":"2026-07-27T03:26:47.069000Z","event_type":"price_change","frame_hash":"b7da12cf8d30d7d3b09f9b06bc64f86e5246cf1c07903cd7dc684798a318bc87","frame_index":0,"kind":"data","monotonic_ns":224790326335625,"payload":{"event_type":"price_change","market":"0x717c0e8ccd4d5c7040185188fbae28be901ca589a11a94b1b38ca36a79eccfeb","price_changes":[{"asset_id":"24254094493625419915756280046002869097156693848522361803041977572204227262166","best_ask":"0.85","best_bid":"0.84","hash":"c784181aada60c0a8db610a627850753c11ce59e","price":"0.01","side":"BUY","size":"5150.02"},{"asset_id":"41448400836309843603620980831210604935021861034693225347475867885462478926555","best_ask":"0.16","best_bid":"0.15","hash":"83ba0c4b0758cb06cddc5cd5ca665b939623136d","price":"0.99","side":"SELL","size":"5150.02"}],"timestamp":"1785122807069"},"payload_hash":"a7b15157ea36d1aebb5c3aef6aa0390ac82e4f8468664e9bbb0a4b36b169f23b","raw_frame":"{\"market\":\"0x717c0e8ccd4d5c7040185188fbae28be901ca589a11a94b1b38ca36a79eccfeb\", \"price_changes\":[{\"asset_id\":\"24254094493625419915756280046002869097156693848522361803041977572204227262166\", \"price\":\"0.01\", \"size\":\"5150.02\", \"side\":\"BUY\", \"hash\":\"c784181aada60c0a8db610a627850753c11ce59e\", \"best_bid\":\"0.84\", \"best_ask\":\"0.85\"}, {\"asset_id\":\"41448400836309843603620980831210604935021861034693225347475867885462478926555\", \"price\":\"0.99\", \"size\":\"5150.02\", \"side\":\"SELL\", \"hash\":\"83ba0c4b0758cb06cddc5cd5ca665b939623136d\", \"best_bid\":\"0.15\", \"best_ask\":\"0.16\"}], \"timestamp\":\"1785122807069\", \"event_type\":\"price_change\"}","received_at":"2026-07-27T03:26:46.965793Z","schema_version":"clob-market-ws.price_change.v1","sequence":null,"server_hash":null,"server_timestamp":"1785122807069","session_id":"dd162b8dca5f43ff811d304e69a06123","source":"clob_market_ws"},"received_at":"2026-07-27T03:26:46.965793Z","record_id":"125535021d7dcdaffcb6bae0f082362c548a80dfd0095a54f8b377d78a1a047b","schema_fingerprint":"4aa3821a28b0b7c2400bc59aba4bcc0a76e971dadd19610d3ad38c768e124dc7","schema_version":"edge-lab-recorder.raw.v1","sequence":null,"source":"clob_market_ws"}
{"event_at":"2026-07-27T03:26:47.070000Z","event_fingerprint":"f47a6a63e3fa59586bd8d3f44ac2c50aef9210b61b5134a576791f73dbfcde22","payload":{"connection_id":"c7dc2e4762f849c6b6f9306b6518dcab","event_at":"2026-07-27T03:26:47.070000Z","event_type":"price_change","frame_hash":"df77264bb0d3462af0fa6d12ee382a2fd8063ae1d215d043a3034baf8bd7e5dd","frame_index":0,"kind":"data","monotonic_ns":224790330504625,"payload":{"event_type":"price_change","market":"0x717c0e8ccd4d5c7040185188fbae28be901ca589a11a94b1b38ca36a79eccfeb","price_changes":[{"asset_id":"24254094493625419915756280046002869097156693848522361803041977572204227262166","best_ask":"0.85","best_bid":"0.84","hash":"46044d7ea4d9703b0066bdcb5faefc67f8d094c0","price":"0.84","side":"BUY","size":"116.53"},{"asset_id":"41448400836309843603620980831210604935021861034693225347475867885462478926555","best_ask":"0.16","best_bid":"0.15","hash":"77715d606a915de0cc00beec24f649a1efcf451b","price":"0.16","side":"SELL","size":"116.53"}],"timestamp":"1785122807070"},"payload_hash":"d278fcabf9c1718df47a13690cee4136d656f6e240f1641737b627d27948d521","raw_frame":"{\"market\":\"0x717c0e8ccd4d5c7040185188fbae28be901ca589a11a94b1b38ca36a79eccfeb\", \"price_changes\":[{\"asset_id\":\"24254094493625419915756280046002869097156693848522361803041977572204227262166\", \"price\":\"0.84\", \"size\":\"116.53\", \"side\":\"BUY\", \"hash\":\"46044d7ea4d9703b0066bdcb5faefc67f8d094c0\", \"best_bid\":\"0.84\", \"best_ask\":\"0.85\"}, {\"asset_id\":\"41448400836309843603620980831210604935021861034693225347475867885462478926555\", \"price\":\"0.16\", \"size\":\"116.53\", \"side\":\"SELL\", \"hash\":\"77715d606a915de0cc00beec24f649a1efcf451b\", \"best_bid\":\"0.15\", \"best_ask\":\"0.16\"}], \"timestamp\":\"1785122807070\", \"event_type\":\"price_change\"}","received_at":"2026-07-27T03:26:46.969964Z","schema_version":"clob-market-ws.price_change.v1","sequence":null,"server_hash":null,"server_timestamp":"1785122807070","session_id":"dd162b8dca5f43ff811d304e69a06123","source":"clob_market_ws"},"received_at":"2026-07-27T03:26:46.969964Z","record_id":"89ceec9c89e32655fb2adc182e1bccbd482c321c8ed21d585a92478e3722f4fc","schema_fingerprint":"4aa3821a28b0b7c2400bc59aba4bcc0a76e971dadd19610d3ad38c768e124dc7","schema_version":"edge-lab-recorder.raw.v1","sequence":null,"source":"clob_market_ws"}
{"event_at":"2026-07-27T03:26:47.070000Z","event_fingerprint":"7705f99885f1cb6c6b7ac181f3107e91144010fb3dc9fdbf7365743db3198191","payload":{"connection_id":"c7dc2e4762f849c6b6f9306b6518dcab","event_at":"2026-07-27T03:26:47.070000Z","event_type":"price_change","frame_hash":"f5e1f9e74ba2ef420fe1a7b962cb269e8833f0261ff9d0cae56c91234a405567","frame_index":0,"kind":"data","monotonic_ns":224790335593916,"payload":{"event_type":"price_change","market":"0x717c0e8ccd4d5c7040185188fbae28be901ca589a11a94b1b38ca36a79eccfeb","price_changes":[{"asset_id":"41448400836309843603620980831210604935021861034693225347475867885462478926555","best_ask":"0.16","best_bid":"0.15","hash":"38e9455ef086a8e9775885bc9090fbfe1978e864","price":"0.18","side":"SELL","size":"80.03"},{"asset_id":"24254094493625419915756280046002869097156693848522361803041977572204227262166","best_ask":"0.85","best_bid":"0.84","hash":"2331e9e443cf482e3cb11c5f4bce97a4940e8f69","price":"0.82","side":"BUY","size":"80.03"}],"timestamp":"1785122807070"},"payload_hash":"2f88ff3c959e9b90676e383b93fa0b479215a56e999b76223427dc7949242d01","raw_frame":"{\"market\":\"0x717c0e8ccd4d5c7040185188fbae28be901ca589a11a94b1b38ca36a79eccfeb\", \"price_changes\":[{\"asset_id\":\"41448400836309843603620980831210604935021861034693225347475867885462478926555\", \"price\":\"0.18\", \"size\":\"80.03\", \"side\":\"SELL\", \"hash\":\"38e9455ef086a8e9775885bc9090fbfe1978e864\", \"best_bid\":\"0.15\", \"best_ask\":\"0.16\"}, {\"asset_id\":\"24254094493625419915756280046002869097156693848522361803041977572204227262166\", \"price\":\"0.82\", \"size\":\"80.03\", \"side\":\"BUY\", \"hash\":\"2331e9e443cf482e3cb11c5f4bce97a4940e8f69\", \"best_bid\":\"0.84\", \"best_ask\":\"0.85\"}], \"timestamp\":\"1785122807070\", \"event_type\":\"price_change\"}","received_at":"2026-07-27T03:26:46.975056Z","schema_version":"clob-market-ws.price_change.v1","sequence":null,"server_hash":null,"server_timestamp":"1785122807070","session_id":"dd162b8dca5f43ff811d304e69a06123","source":"clob_market_ws"},"received_at":"2026-07-27T03:26:46.975056Z","record_id":"c38364992b67b34c0a0fc34a7e00d06aba0ec62eaaa498597c38867274df33e2","schema_fingerprint":"4aa3821a28b0b7c2400bc59aba4bcc0a76e971dadd19610d3ad38c768e124dc7","schema_version":"edge-lab-recorder.raw.v1","sequence":null,"source":"clob_market_ws"}
{"event_at":"2026-07-27T03:26:47.071000Z","event_fingerprint":"57f94f1ca1f54120ababf9df86581c798d214e55bd7ba47c03656f8493d7bcb3","payload":{"connection_id":"c7dc2e4762f849c6b6f9306b6518dcab","event_at":"2026-07-27T03:26:47.071000Z","event_type":"price_change","frame_hash":"9b7f27505480ff0486215d851747588285a9bd1df1c2602e869622a528acd996","frame_index":0,"kind":"data","monotonic_ns":224790341185541,"payload":{"event_type":"price_change","market":"0x717c0e8ccd4d5c7040185188fbae28be901ca589a11a94b1b38ca36a79eccfeb","price_changes":[{"asset_id":"41448400836309843603620980831210604935021861034693225347475867885462478926555","best_ask":"0.16","best_bid":"0.15","hash":"63e1ff8ad0dcf4392fe0393a43f9aad4b7ce1787","price":"0.11","side":"BUY","size":"18.8"},{"asset_id":"24254094493625419915756280046002869097156693848522361803041977572204227262166","best_ask":"0.85","best_bid":"0.84","hash":"8097abdb1994c0dda27c801e191664ed016540e2","price":"0.89","side":"SELL","size":"18.8"}],"timestamp":"1785122807071"},"payload_hash":"d1d197801e20248b35b7068cfa781917761116307f27e22b6ad8f3d473841082","raw_frame":"{\"market\":\"0x717c0e8ccd4d5c7040185188fbae28be901ca589a11a94b1b38ca36a79eccfeb\", \"price_changes\":[{\"asset_id\":\"41448400836309843603620980831210604935021861034693225347475867885462478926555\", \"price\":\"0.11\", \"size\":\"18.8\", \"side\":\"BUY\", \"hash\":\"63e1ff8ad0dcf4392fe0393a43f9aad4b7ce1787\", \"best_bid\":\"0.15\", \"best_ask\":\"0.16\"}, {\"asset_id\":\"24254094493625419915756280046002869097156693848522361803041977572204227262166\", \"price\":\"0.89\", \"size\":\"18.8\", \"side\":\"SELL\", \"hash\":\"8097abdb1994c0dda27c801e191664ed016540e2\", \"best_bid\":\"0.84\", \"best_ask\":\"0.85\"}], \"timestamp\":\"1785122807071\", \"event_type\":\"price_change\"}","received_at":"2026-07-27T03:26:46.980646Z","schema_version":"clob-market-ws.price_change.v1","sequence":null,"server_hash":null,"server_timestamp":"1785122807071","session_id":"dd162b8dca5f43ff811d304e69a06123","source":"clob_market_ws"},"received_at":"2026-07-27T03:26:46.980646Z","record_id":"840c4cc7f98eb893662968985a9a917db5e0bfcddb38e55b7cb36732979331c2","schema_fingerprint":"4aa3821a28b0b7c2400bc59aba4bcc0a76e971dadd19610d3ad38c768e124dc7","schema_version":"edge-lab-recorder.raw.v1","sequence":null,"source":"clob_market_ws"}
{"event_at":"2026-07-27T03:26:47.079000Z","event_fingerprint":"04810b3120cab8514431b247fd874ed04e8f5f9d6bad7ef2fda73452a8e6e13e","payload":{"connection_id":"c7dc2e4762f849c6b6f9306b6518dcab","event_at":"2026-07-27T03:26:47.079000Z","event_type":"price_change","frame_hash":"3089c8a30b8df068659306b2b72d991c0be7957ea7ca60904d6e5795aa87ba75","frame_index":0,"kind":"data","monotonic_ns":224790343920625,"payload":{"event_type":"price_change","market":"0x717c0e8ccd4d5c7040185188fbae28be901ca589a11a94b1b38ca36a79eccfeb","price_changes":[{"asset_id":"24254094493625419915756280046002869097156693848522361803041977572204227262166","best_ask":"0.85","best_bid":"0.84","hash":"f34e6520df685bb7bf7a80bd15159101b8283937","price":"0.78","side":"BUY","size":"107"},{"asset_id":"41448400836309843603620980831210604935021861034693225347475867885462478926555","best_ask":"0.16","best_bid":"0.15","hash":"7fe2054981daf3e5618d623d10e9d9c600971815","price":"0.22","side":"SELL","size":"107"}],"timestamp":"1785122807079"},"payload_hash":"3fcd1f15735fd71bcb980c463857eb278a08e30667a633e735e061fda335d3c9","raw_frame":"{\"market\":\"0x717c0e8ccd4d5c7040185188fbae28be901ca589a11a94b1b38ca36a79eccfeb\", \"price_changes\":[{\"asset_id\":\"24254094493625419915756280046002869097156693848522361803041977572204227262166\", \"price\":\"0.78\", \"size\":\"107\", \"side\":\"BUY\", \"hash\":\"f34e6520df685bb7bf7a80bd15159101b8283937\", \"best_bid\":\"0.84\", \"best_ask\":\"0.85\"}, {\"asset_id\":\"41448400836309843603620980831210604935021861034693225347475867885462478926555\", \"price\":\"0.22\", \"size\":\"107\", \"side\":\"SELL\", \"hash\":\"7fe2054981daf3e5618d623d10e9d9c600971815\", \"best_bid\":\"0.15\", \"best_ask\":\"0.16\"}], \"timestamp\":\"1785122807079\", \"event_type\":\"price_change\"}","received_at":"2026-07-27T03:26:46.983377Z","schema_version":"clob-market-ws.price_change.v1","sequence":null,"server_hash":null,"server_timestamp":"1785122807079","session_id":"dd162b8dca5f43ff811d304e69a06123","source":"clob_market_ws"},"received_at":"2026-07-27T03:26:46.983377Z","record_id":"90916306e3a64f486aa6421383c33d19ca70aeb8308a5f85f921f9261563d5b2","schema_fingerprint":"4aa3821a28b0b7c2400bc59aba4bcc0a76e971dadd19610d3ad38c768e124dc7","schema_version":"edge-lab-recorder.raw.v1","sequence":null,"source":"clob_market_ws"}
{"event_at":"2026-07-27T03:26:47.083000Z","event_fingerprint":"f21326f5f484c3854aa0b398c2a65ff4fcad41beb1732db942fa4422b5322bad","payload":{"connection_id":"c7dc2e4762f849c6b6f9306b6518dcab","event_at":"2026-07-27T03:26:47.083000Z","event_type":"best_bid_ask","frame_hash":"9cbee0e8db6bae85e336134abd50e530c3e561bc45221d32403c685572ca018e","frame_index":0,"kind":"data","monotonic_ns":224790345842125,"payload":{"asset_id":"24254094493625419915756280046002869097156693848522361803041977572204227262166","best_ask":"0.86","best_bid":"0.84","event_type":"best_bid_ask","market":"0x717c0e8ccd4d5c7040185188fbae28be901ca589a11a94b1b38ca36a79eccfeb","spread":"0.02","timestamp":"1785122807083"},"payload_hash":"5035a7096ec76a188c6d340d3d1f5b829ae77d7f89bd7a4589d1fe0064ad0e80","raw_frame":"{\"market\":\"0x717c0e8ccd4d5c7040185188fbae28be901ca589a11a94b1b38ca36a79eccfeb\", \"asset_id\":\"24254094493625419915756280046002869097156693848522361803041977572204227262166\", \"best_bid\":\"0.84\", \"best_ask\":\"0.86\", \"spread\":\"0.02\", \"timestamp\":\"1785122807083\", \"event_type\":\"best_bid_ask\"}","received_at":"2026-07-27T03:26:46.985298Z","schema_version":"clob-market-ws.best_bid_ask.v1","sequence":null,"server_hash":null,"server_timestamp":"1785122807083","session_id":"dd162b8dca5f43ff811d304e69a06123","source":"clob_market_ws"},"received_at":"2026-07-27T03:26:46.985298Z","record_id":"359070375733c834be3a1fd0f8d3822b9f0e170138c3466bc2e63c36be176af7","schema_fingerprint":"8488399f31b0337811b13b266be932db7062827c2470b78bd8e9e99bab51d17d","schema_version":"edge-lab-recorder.raw.v1","sequence":null,"source":"clob_market_ws"}
{"event_at":"2026-07-27T03:26:47.083000Z","event_fingerprint":"7eca7c1ea28b4795918bef37d57453aa3e6e31332b45ea820647fb6d0eafbf5f","payload":{"connection_id":"c7dc2e4762f849c6b6f9306b6518dcab","event_at":"2026-07-27T03:26:47.083000Z","event_type":"best_bid_ask","frame_hash":"44b8f0884e6f59ada09f5b5926b596c021f459211b148ea3e5b3d5f001828c0c","frame_index":0,"kind":"data","monotonic_ns":224790349186041,"payload":{"asset_id":"41448400836309843603620980831210604935021861034693225347475867885462478926555","best_ask":"0.16","best_bid":"0.14","event_type":"best_bid_ask","market":"0x717c0e8ccd4d5c7040185188fbae28be901ca589a11a94b1b38ca36a79eccfeb","spread":"0.02","timestamp":"1785122807083"},"payload_hash":"2f24a3212ed6042e4c5de9c077c8a389c7d82ff709d1bd769ca59827e673f2d8","raw_frame":"{\"market\":\"0x717c0e8ccd4d5c7040185188fbae28be901ca589a11a94b1b38ca36a79eccfeb\", \"asset_id\":\"41448400836309843603620980831210604935021861034693225347475867885462478926555\", \"best_bid\":\"0.14\", \"best_ask\":\"0.16\", \"spread\":\"0.02\", \"timestamp\":\"1785122807083\", \"event_type\":\"best_bid_ask\"}","received_at":"2026-07-27T03:26:46.988645Z","schema_version":"clob-market-ws.best_bid_ask.v1","sequence":null,"server_hash":null,"server_timestamp":"1785122807083","session_id":"dd162b8dca5f43ff811d304e69a06123","source":"clob_market_ws"},"received_at":"2026-07-27T03:26:46.988645Z","record_id":"9c4695dd2817ac029e78993509aeba6d8163bd48b205c364e07272214bd532f2","schema_fingerprint":"8488399f31b0337811b13b266be932db7062827c2470b78bd8e9e99bab51d17d","schema_version":"edge-lab-recorder.raw.v1","sequence":null,"source":"clob_market_ws"}
{"event_at":"2026-07-27T03:26:47.083000Z","event_fingerprint":"f4990a8817f946277565e0dc9943dc9880939c2955bd6ea5eb6e89887cbe2e53","payload":{"connection_id":"c7dc2e4762f849c6b6f9306b6518dcab","event_at":"2026-07-27T03:26:47.083000Z","event_type":"price_change","frame_hash":"f93355349749c53dbc3df55e5e752736446a7a16e8f6ef26bd794eafc0d9533d","frame_index":0,"kind":"data","monotonic_ns":224790352159833,"payload":{"event_type":"price_change","market":"0x717c0e8ccd4d5c7040185188fbae28be901ca589a11a94b1b38ca36a79eccfeb","price_changes":[{"asset_id":"41448400836309843603620980831210604935021861034693225347475867885462478926555","best_ask":"0.16","best_bid":"0.14","hash":"b85b0f583e0f77bf3463ad45284dd619b70af29e","price":"0.15","side":"BUY","size":"0"},{"asset_id":"24254094493625419915756280046002869097156693848522361803041977572204227262166","best_ask":"0.86","best_bid":"0.84","hash":"fadd15e8641d8c11d38cc0a3cd919a346d658bb1","price":"0.85","side":"SELL","size":"0"}],"timestamp":"1785122807083"},"payload_hash":"d20b54c4ef6e1d3396a92b05b5ddce33d21c9012031de93d7602fc53b421ba45","raw_frame":"{\"market\":\"0x717c0e8ccd4d5c7040185188fbae28be901ca589a11a94b1b38ca36a79eccfeb\", \"price_changes\":[{\"asset_id\":\"41448400836309843603620980831210604935021861034693225347475867885462478926555\", \"price\":\"0.15\", \"size\":\"0\", \"side\":\"BUY\", \"hash\":\"b85b0f583e0f77bf3463ad45284dd619b70af29e\", \"best_bid\":\"0.14\", \"best_ask\":\"0.16\"}, {\"asset_id\":\"24254094493625419915756280046002869097156693848522361803041977572204227262166\", \"price\":\"0.85\", \"size\":\"0\", \"side\":\"SELL\", \"hash\":\"fadd15e8641d8c11d38cc0a3cd919a346d658bb1\", \"best_bid\":\"0.84\", \"best_ask\":\"0.86\"}], \"timestamp\":\"1785122807083\", \"event_type\":\"price_change\"}","received_at":"2026-07-27T03:26:46.991622Z","schema_version":"clob-market-ws.price_change.v1","sequence":null,"server_hash":null,"server_timestamp":"1785122807083","session_id":"dd162b8dca5f43ff811d304e69a06123","source":"clob_market_ws"},"received_at":"2026-07-27T03:26:46.991622Z","record_id":"fa6b6ffd4dd87e6542a588fe23dcf35a90b2fcd8c392ef32a9355a79732ad92b","schema_fingerprint":"4aa3821a28b0b7c2400bc59aba4bcc0a76e971dadd19610d3ad38c768e124dc7","schema_version":"edge-lab-recorder.raw.v1","sequence":null,"source":"clob_market_ws"}
{"event_at":"2026-07-27T03:26:47.093000Z","event_fingerprint":"b50a1481dc315c66589c4b5359eb954920c03ba3af1ab7e2acd504117336d128","payload":{"connection_id":"c7dc2e4762f849c6b6f9306b6518dcab","event_at":"2026-07-27T03:26:47.093000Z","event_type":"price_change","frame_hash":"9a7ae05d6351157d4fcfdb1aacaf71eafd33976d4519ce628d2847e3ef780a1c","frame_index":0,"kind":"data","monotonic_ns":224790355448083,"payload":{"event_type":"price_change","market":"0x717c0e8ccd4d5c7040185188fbae28be901ca589a11a94b1b38ca36a79eccfeb","price_changes":[{"asset_id":"24254094493625419915756280046002869097156693848522361803041977572204227262166","best_ask":"0.86","best_bid":"0.84","hash":"3e86c460a9763ed6645986b29f5be3933fcbfb54","price":"0.96","side":"SELL","size":"625"},{"asset_id":"41448400836309843603620980831210604935021861034693225347475867885462478926555","best_ask":"0.16","best_bid":"0.14","hash":"5e454c2afc7d76105c9008368395319f89f77a77","price":"0.04","side":"BUY","size":"625"}],"timestamp":"1785122807093"},"payload_hash":"de4f232fec23257d7e6c0d72c58d392a01123b87730a4247368f790889ae76dd","raw_frame":"{\"market\":\"0x717c0e8ccd4d5c7040185188fbae28be901ca589a11a94b1b38ca36a79eccfeb\", \"price_changes\":[{\"asset_id\":\"24254094493625419915756280046002869097156693848522361803041977572204227262166\", \"price\":\"0.96\", \"size\":\"625\", \"side\":\"SELL\", \"hash\":\"3e86c460a9763ed6645986b29f5be3933fcbfb54\", \"best_bid\":\"0.84\", \"best_ask\":\"0.86\"}, {\"asset_id\":\"41448400836309843603620980831210604935021861034693225347475867885462478926555\", \"price\":\"0.04\", \"size\":\"625\", \"side\":\"BUY\", \"hash\":\"5e454c2afc7d76105c9008368395319f89f77a77\", \"best_bid\":\"0.14\", \"best_ask\":\"0.16\"}], \"timestamp\":\"1785122807093\", \"event_type\":\"price_change\"}","received_at":"2026-07-27T03:26:46.994908Z","schema_version":"clob-market-ws.price_change.v1","sequence":null,"server_hash":null,"server_timestamp":"1785122807093","session_id":"dd162b8dca5f43ff811d304e69a06123","source":"clob_market_ws"},"received_at":"2026-07-27T03:26:46.994908Z","record_id":"f79e96036ae4d8ec65844bf92e28b3e177c63fd8974489967c29fd7893281db8","schema_fingerprint":"4aa3821a28b0b7c2400bc59aba4bcc0a76e971dadd19610d3ad38c768e124dc7","schema_version":"edge-lab-recorder.raw.v1","sequence":null,"source":"clob_market_ws"}
{"event_at":"2026-07-27T03:26:47.099000Z","event_fingerprint":"4e02064bfbc734899a8ccb1f0220e83749b66d556879b425ea49cbc7c486d8ae","payload":{"connection_id":"c7dc2e4762f849c6b6f9306b6518dcab","event_at":"2026-07-27T03:26:47.099000Z","event_type":"price_change","frame_hash":"167b8dd01762ea1aecf55b57d7408a0bc8e1cdbc48430e99f9878d8abaf1f689","frame_index":0,"kind":"data","monotonic_ns":224790357335916,"payload":{"event_type":"price_change","market":"0x717c0e8ccd4d5c7040185188fbae28be901ca589a11a94b1b38ca36a79eccfeb","price_changes":[{"asset_id":"24254094493625419915756280046002869097156693848522361803041977572204227262166","best_ask":"0.86","best_bid":"0.84","hash":"930334b655689a2c04fbcf85a1631a37e6b98c6f","price":"0.84","side":"BUY","size":"111.53"},{"asset_id":"41448400836309843603620980831210604935021861034693225347475867885462478926555","best_ask":"0.16","best_bid":"0.14","hash":"c08d994db4910a797514e2b03ffa687316ee296c","price":"0.16","side":"SELL","size":"111.53"}],"timestamp":"1785122807099"},"payload_hash":"5250af3bf6613cce76d3276f650ae13890469c6680697544dc4d436262954baa","raw_frame":"{\"market\":\"0x717c0e8ccd4d5c7040185188fbae28be901ca589a11a94b1b38ca36a79eccfeb\", \"price_changes\":[{\"asset_id\":\"24254094493625419915756280046002869097156693848522361803041977572204227262166\", \"price\":\"0.84\", \"size\":\"111.53\", \"side\":\"BUY\", \"hash\":\"930334b655689a2c04fbcf85a1631a37e6b98c6f\", \"best_bid\":\"0.84\", \"best_ask\":\"0.86\"}, {\"asset_id\":\"41448400836309843603620980831210604935021861034693225347475867885462478926555\", \"price\":\"0.16\", \"size\":\"111.53\", \"side\":\"SELL\", \"hash\":\"c08d994db4910a797514e2b03ffa687316ee296c\", \"best_bid\":\"0.14\", \"best_ask\":\"0.16\"}], \"timestamp\":\"1785122807099\", \"event_type\":\"price_change\"}","received_at":"2026-07-27T03:26:46.996795Z","schema_version":"clob-market-ws.price_change.v1","sequence":null,"server_hash":null,"server_timestamp":"1785122807099","session_id":"dd162b8dca5f43ff811d304e69a06123","source":"clob_market_ws"},"received_at":"2026-07-27T03:26:46.996795Z","record_id":"cfd8a7545365de680555534d293cede87750cf239473d09b350bfe102b2cac6a","schema_fingerprint":"4aa3821a28b0b7c2400bc59aba4bcc0a76e971dadd19610d3ad38c768e124dc7","schema_version":"edge-lab-recorder.raw.v1","sequence":null,"source":"clob_market_ws"}
{"event_at":"2026-07-27T03:26:47.109000Z","event_fingerprint":"52bc28445a90ade47b237f607582e7fb43aa4cba9ae2002e8c1f22047164dfb7","payload":{"connection_id":"c7dc2e4762f849c6b6f9306b6518dcab","event_at":"2026-07-27T03:26:47.109000Z","event_type":"price_change","frame_hash":"83a87cf932ecdc6714a73ceb9264adb32960d8fb05f30c5e88260e6d9215be16","frame_index":0,"kind":"data","monotonic_ns":224790361963583,"payload":{"event_type":"price_change","market":"0x717c0e8ccd4d5c7040185188fbae28be901ca589a11a94b1b38ca36a79eccfeb","price_changes":[{"asset_id":"24254094493625419915756280046002869097156693848522361803041977572204227262166","best_ask":"0.86","best_bid":"0.84","hash":"973aba35c73c6de004fe802ea769a4df632239c4","price":"0.02","side":"BUY","size":"535"},{"asset_id":"41448400836309843603620980831210604935021861034693225347475867885462478926555","best_ask":"0.16","best_bid":"0.14","hash":"7806bd4c3198fde2e4925521836b6b78df1b44fb","price":"0.98","side":"SELL","size":"535"}],"timestamp":"1785122807109"},"payload_hash":"4b672b782c879690a822c98e4e387a6f9af9b10f585206f52a53536ae8fbbb26","raw_frame":"{\"market\":\"0x717c0e8ccd4d5c7040185188fbae28be901ca589a11a94b1b38ca36a79eccfeb\", \"price_changes\":[{\"asset_id\":\"24254094493625419915756280046002869097156693848522361803041977572204227262166\", \"price\":\"0.02\", \"size\":\"535\", \"side\":\"BUY\", \"hash\":\"973aba35c73c6de004fe802ea769a4df632239c4\", \"best_bid\":\"0.84\", \"best_ask\":\"0.86\"}, {\"asset_id\":\"41448400836309843603620980831210604935021861034693225347475867885462478926555\", \"price\":\"0.98\", \"size\":\"535\", \"side\":\"SELL\", \"hash\":\"7806bd4c3198fde2e4925521836b6b78df1b44fb\", \"best_bid\":\"0.14\", \"best_ask\":\"0.16\"}], \"timestamp\":\"1785122807109\", \"event_type\":\"price_change\"}","received_at":"2026-07-27T03:26:47.001423Z","schema_version":"clob-market-ws.price_change.v1","sequence":null,"server_hash":null,"server_timestamp":"1785122807109","session_id":"dd162b8dca5f43ff811d304e69a06123","source":"clob_market_ws"},"received_at":"2026-07-27T03:26:47.001423Z","record_id":"bd2dcbd4ea211262420de83eab4c80a983637385a93b9529861b8ed66a4455e9","schema_fingerprint":"4aa3821a28b0b7c2400bc59aba4bcc0a76e971dadd19610d3ad38c768e124dc7","schema_version":"edge-lab-recorder.raw.v1","sequence":null,"source":"clob_market_ws"}
{"event_at":"2026-07-27T03:26:47.122000Z","event_fingerprint":"f8a4e293f0c3ff41ac74cbe55452c765e0498fd70de9160ef6a08e02e611b7ed","payload":{"connection_id":"c7dc2e4762f849c6b6f9306b6518dcab","event_at":"2026-07-27T03:26:47.122000Z","event_type":"price_change","frame_hash":"e58810d0c5c9d2c04039f22903026dad968908f4eb074e0bc132df1a8f985ef9","frame_index":0,"kind":"data","monotonic_ns":224790363579250,"payload":{"event_type":"price_change","market":"0x717c0e8ccd4d5c7040185188fbae28be901ca589a11a94b1b38ca36a79eccfeb","price_changes":[{"asset_id":"24254094493625419915756280046002869097156693848522361803041977572204227262166","best_ask":"0.86","best_bid":"0.84","hash":"97313699022ae850751c193a2d1fecf6587bc3d9","price":"0.97","side":"SELL","size":"782"},{"asset_id":"41448400836309843603620980831210604935021861034693225347475867885462478926555","best_ask":"0.16","best_bid":"0.14","hash":"09aa78f9c7281eb8cb25014be96e17c19c4c752a","price":"0.03","side":"BUY","size":"782"}],"timestamp":"1785122807122"},"payload_hash":"934ed620f55735c3286d914fb2ac412a9aabc1e4c208822092fbc044474fa503","raw_frame":"{\"market\":\"0x717c0e8ccd4d5c7040185188fbae28be901ca589a11a94b1b38ca36a79eccfeb\", \"price_changes\":[{\"asset_id\":\"24254094493625419915756280046002869097156693848522361803041977572204227262166\", \"price\":\"0.97\", \"size\":\"782\", \"side\":\"SELL\", \"hash\":\"97313699022ae850751c193a2d1fecf6587bc3d9\", \"best_bid\":\"0.84\", \"best_ask\":\"0.86\"}, {\"asset_id\":\"41448400836309843603620980831210604935021861034693225347475867885462478926555\", \"price\":\"0.03\", \"size\":\"782\", \"side\":\"BUY\", \"hash\":\"09aa78f9c7281eb8cb25014be96e17c19c4c752a\", \"best_bid\":\"0.14\", \"best_ask\":\"0.16\"}], \"timestamp\":\"1785122807122\", \"event_type\":\"price_change\"}","received_at":"2026-07-27T03:26:47.003040Z","schema_version":"clob-market-ws.price_change.v1","sequence":null,"server_hash":null,"server_timestamp":"1785122807122","session_id":"dd162b8dca5f43ff811d304e69a06123","source":"clob_market_ws"},"received_at":"2026-07-27T03:26:47.003040Z","record_id":"39d530b63082737c1420f932ab818849fb7790f0751aa374688e8ffb73166961","schema_fingerprint":"4aa3821a28b0b7c2400bc59aba4bcc0a76e971dadd19610d3ad38c768e124dc7","schema_version":"edge-lab-recorder.raw.v1","sequence":null,"source":"clob_market_ws"}
{"event_at":"2026-07-27T03:26:47.132000Z","event_fingerprint":"1d24b628dcf25dd1835e9130a83a86fa8612eb76dc1511643b671e11153288d3","payload":{"connection_id":"c7dc2e4762f849c6b6f9306b6518dcab","event_at":"2026-07-27T03:26:47.132000Z","event_type":"price_change","frame_hash":"4af3023e6077632b99e6e24a6023f03a06b997c88e68780ee0d6309a61b19fe7","frame_index":0,"kind":"data","monotonic_ns":224790366293500,"payload":{"event_type":"price_change","market":"0x717c0e8ccd4d5c7040185188fbae28be901ca589a11a94b1b38ca36a79eccfeb","price_changes":[{"asset_id":"41448400836309843603620980831210604935021861034693225347475867885462478926555","best_ask":"0.16","best_bid":"0.14","hash":"e8928c05de966dd87e6b82fdc5e0cf8da5b2bab6","price":"0.01","side":"BUY","size":"5740.02"},{"asset_id":"24254094493625419915756280046002869097156693848522361803041977572204227262166","best_ask":"0.86","best_bid":"0.84","hash":"db277c4f4bb0aeaefe15d2119f067e75a37f6197","price":"0.99","side":"SELL","size":"5740.02"}],"timestamp":"1785122807132"},"payload_hash":"14c0c67583c9b5ee058861bb1c55087330a11fd5785dfe31582b762956a0532c","raw_frame":"{\"market\":\"0x717c0e8ccd4d5c7040185188fbae28be901ca589a11a94b1b38ca36a79eccfeb\", \"price_changes\":[{\"asset_id\":\"41448400836309843603620980831210604935021861034693225347475867885462478926555\", \"price\":\"0.01\", \"size\":\"5740.02\", \"side\":\"BUY\", \"hash\":\"e8928c05de966dd87e6b82fdc5e0cf8da5b2bab6\", \"best_bid\":\"0.14\", \"best_ask\":\"0.16\"}, {\"asset_id\":\"24254094493625419915756280046002869097156693848522361803041977572204227262166\", \"price\":\"0.99\", \"size\":\"5740.02\", \"side\":\"SELL\", \"hash\":\"db277c4f4bb0aeaefe15d2119f067e75a37f6197\", \"best_bid\":\"0.84\", \"best_ask\":\"0.86\"}], \"timestamp\":\"1785122807132\", \"event_type\":\"price_change\"}","received_at":"2026-07-27T03:26:47.005749Z","schema_version":"clob-market-ws.price_change.v1","sequence":null,"server_hash":null,"server_timestamp":"1785122807132","session_id":"dd162b8dca5f43ff811d304e69a06123","source":"clob_market_ws"},"received_at":"2026-07-27T03:26:47.005749Z","record_id":"3a424afb1ec8a1b350369eccac06018bfc116456ac3e5bb359e3963841ee4fec","schema_fingerprint":"4aa3821a28b0b7c2400bc59aba4bcc0a76e971dadd19610d3ad38c768e124dc7","schema_version":"edge-lab-recorder.raw.v1","sequence":null,"source":"clob_market_ws"}
{"event_at":"2026-07-27T03:26:47.143000Z","event_fingerprint":"73660c74e1978e18a0394f755e6a63aceb39cf6446bccf9254776d0351a50119","payload":{"connection_id":"c7dc2e4762f849c6b6f9306b6518dcab","event_at":"2026-07-27T03:26:47.143000Z","event_type":"price_change","frame_hash":"6b69fa047ffa3026ac9f7098c4f17b21ba7ed5bbdf855b1e33e2a6f80297fe4f","frame_index":0,"kind":"data","monotonic_ns":224790390840958,"payload":{"event_type":"price_change","market":"0x717c0e8ccd4d5c7040185188fbae28be901ca589a11a94b1b38ca36a79eccfeb","price_changes":[{"asset_id":"41448400836309843603620980831210604935021861034693225347475867885462478926555","best_ask":"0.16","best_bid":"0.14","hash":"5de1ca79d63820d5c8da9c6688efdedc6cdbcdda","price":"0.14","side":"BUY","size":"289.6"},{"asset_id":"24254094493625419915756280046002869097156693848522361803041977572204227262166","best_ask":"0.86","best_bid":"0.84","hash":"6a20cca6537dd8e543235e334d08f6d6710fa19d","price":"0.86","side":"SELL","size":"289.6"}],"timestamp":"1785122807143"},"payload_hash":"e9605730c7187c0a4ef933cea480db13a9a6e55795e9412787705d3c4c4bdcd3","raw_frame":"{\"market\":\"0x717c0e8ccd4d5c7040185188fbae28be901ca589a11a94b1b38ca36a79eccfeb\", \"price_changes\":[{\"asset_id\":\"41448400836309843603620980831210604935021861034693225347475867885462478926555\", \"price\":\"0.14\", \"size\":\"289.6\", \"side\":\"BUY\", \"hash\":\"5de1ca79d63820d5c8da9c6688efdedc6cdbcdda\", \"best_bid\":\"0.14\", \"best_ask\":\"0.16\"}, {\"asset_id\":\"24254094493625419915756280046002869097156693848522361803041977572204227262166\", \"price\":\"0.86\", \"size\":\"289.6\", \"side\":\"SELL\", \"hash\":\"6a20cca6537dd8e543235e334d08f6d6710fa19d\", \"best_bid\":\"0.84\", \"best_ask\":\"0.86\"}], \"timestamp\":\"1785122807143\", \"event_type\":\"price_change\"}","received_at":"2026-07-27T03:26:47.030297Z","schema_version":"clob-market-ws.price_change.v1","sequence":null,"server_hash":null,"server_timestamp":"1785122807143","session_id":"dd162b8dca5f43ff811d304e69a06123","source":"clob_market_ws"},"received_at":"2026-07-27T03:26:47.030297Z","record_id":"5360645f5bc9c6236c90a16f25a388cc4ae76cf931497f1903b072c5a381ea65","schema_fingerprint":"4aa3821a28b0b7c2400bc59aba4bcc0a76e971dadd19610d3ad38c768e124dc7","schema_version":"edge-lab-recorder.raw.v1","sequence":null,"source":"clob_market_ws"}
{"event_at":"2026-07-27T03:26:47.146000Z","event_fingerprint":"0254f77e5aea98aa27c865cb8489d884087e13cbbc918e622692be38dbd68d3d","payload":{"connection_id":"c7dc2e4762f849c6b6f9306b6518dcab","event_at":"2026-07-27T03:26:47.146000Z","event_type":"price_change","frame_hash":"6730d97ada0350ecf688da9c1dc6074d60573d20efc81e06f2b474bed97aee7d","frame_index":0,"kind":"data","monotonic_ns":224790394318666,"payload":{"event_type":"price_change","market":"0x717c0e8ccd4d5c7040185188fbae28be901ca589a11a94b1b38ca36a79eccfeb","price_changes":[{"asset_id":"24254094493625419915756280046002869097156693848522361803041977572204227262166","best_ask":"0.86","best_bid":"0.84","hash":"cb832de900645f7f9d5c613e37f27f0eca3ff496","price":"0.84","side":"BUY","size":"121.53"},{"asset_id":"41448400836309843603620980831210604935021861034693225347475867885462478926555","best_ask":"0.16","best_bid":"0.14","hash":"821ac6f3c191742aa521b3ecd671f6c441174c79","price":"0.16","side":"SELL","size":"121.53"}],"timestamp":"1785122807146"},"payload_hash":"ebea654142fd7c5a80c9ba9775365efe89eb1a892f163db512c704c7ed06bb9d","raw_frame":"{\"market\":\"0x717c0e8ccd4d5c7040185188fbae28be901ca589a11a94b1b38ca36a79eccfeb\", \"price_changes\":[{\"asset_id\":\"24254094493625419915756280046002869097156693848522361803041977572204227262166\", \"price\":\"0.84\", \"size\":\"121.53\", \"side\":\"BUY\", \"hash\":\"cb832de900645f7f9d5c613e37f27f0eca3ff496\", \"best_bid\":\"0.84\", \"best_ask\":\"0.86\"}, {\"asset_id\":\"41448400836309843603620980831210604935021861034693225347475867885462478926555\", \"price\":\"0.16\", \"size\":\"121.53\", \"side\":\"SELL\", \"hash\":\"821ac6f3c191742aa521b3ecd671f6c441174c79\", \"best_bid\":\"0.14\", \"best_ask\":\"0.16\"}], \"timestamp\":\"1785122807146\", \"event_type\":\"price_change\"}","received_at":"2026-07-27T03:26:47.033778Z","schema_version":"clob-market-ws.price_change.v1","sequence":null,"server_hash":null,"server_timestamp":"1785122807146","session_id":"dd162b8dca5f43ff811d304e69a06123","source":"clob_market_ws"},"received_at":"2026-07-27T03:26:47.033778Z","record_id":"fa01017c71c082df25021bef8446ac6dbe1c6ce61ac3bfc3b6dd7e49968acc3d","schema_fingerprint":"4aa3821a28b0b7c2400bc59aba4bcc0a76e971dadd19610d3ad38c768e124dc7","schema_version":"edge-lab-recorder.raw.v1","sequence":null,"source":"clob_market_ws"}
{"event_at":"2026-07-27T03:26:47.161000Z","event_fingerprint":"a7c385efb74520178edcf52e9257712ab2e213bdc905751751a7e3d43147b007","payload":{"connection_id":"c7dc2e4762f849c6b6f9306b6518dcab","event_at":"2026-07-27T03:26:47.161000Z","event_type":"price_change","frame_hash":"615036a03ac20f62dab51b03cebcfaf0e68f46f89b9f4b3dc62b791df21f49ce","frame_index":0,"kind":"data","monotonic_ns":224790397914833,"payload":{"event_type":"price_change","market":"0x717c0e8ccd4d5c7040185188fbae28be901ca589a11a94b1b38ca36a79eccfeb","price_changes":[{"asset_id":"41448400836309843603620980831210604935021861034693225347475867885462478926555","best_ask":"0.16","best_bid":"0.14","hash":"01eb48c7f415a3e416b6c5b4e300d8ba71200599","price":"0.14","side":"BUY","size":"279.6"},{"asset_id":"24254094493625419915756280046002869097156693848522361803041977572204227262166","best_ask":"0.86","best_bid":"0.84","hash":"836d0f4e6b47a78108330308041934484b561576","price":"0.86","side":"SELL","size":"279.6"}],"timestamp":"1785122807161"},"payload_hash":"e53ef2a03f16c5e0e306b3ac86b16f0e64a6400cb3ed50b0a12c47586236646b","raw_frame":"{\"market\":\"0x717c0e8ccd4d5c7040185188fbae28be901ca589a11a94b1b38ca36a79eccfeb\", \"price_changes\":[{\"asset_id\":\"41448400836309843603620980831210604935021861034693225347475867885462478926555\", \"price\":\"0.14\", \"size\":\"279.6\", \"side\":\"BUY\", \"hash\":\"01eb48c7f415a3e416b6c5b4e300d8ba71200599\", \"best_bid\":\"0.14\", \"best_ask\":\"0.16\"}, {\"asset_id\":\"24254094493625419915756280046002869097156693848522361803041977572204227262166\", \"price\":\"0.86\", \"size\":\"279.6\", \"side\":\"SELL\", \"hash\":\"836d0f4e6b47a78108330308041934484b561576\", \"best_bid\":\"0.84\", \"best_ask\":\"0.86\"}], \"timestamp\":\"1785122807161\", \"event_type\":\"price_change\"}","received_at":"2026-07-27T03:26:47.037374Z","schema_version":"clob-market-ws.price_change.v1","sequence":null,"server_hash":null,"server_timestamp":"1785122807161","session_id":"dd162b8dca5f43ff811d304e69a06123","source":"clob_market_ws"},"received_at":"2026-07-27T03:26:47.037374Z","record_id":"dfaf3df7b7ba0378a9e7cdad726036938fdb2b60b06020f42f2028e3d6e73037","schema_fingerprint":"4aa3821a28b0b7c2400bc59aba4bcc0a76e971dadd19610d3ad38c768e124dc7","schema_version":"edge-lab-recorder.raw.v1","sequence":null,"source":"clob_market_ws"}
{"event_at":"2026-07-27T03:26:47.164000Z","event_fingerprint":"3932fc4a82cbb33e8b277c4100e3328c239b7a3096951c62a6895b90490bcfa3","payload":{"connection_id":"c7dc2e4762f849c6b6f9306b6518dcab","event_at":"2026-07-27T03:26:47.164000Z","event_type":"price_change","frame_hash":"f944bf4eba767ff7847acbe7bac6f8d69f1055c88ee691ce1e3cd5c16d3b9f9e","frame_index":0,"kind":"data","monotonic_ns":224790403891625,"payload":{"event_type":"price_change","market":"0x717c0e8ccd4d5c7040185188fbae28be901ca589a11a94b1b38ca36a79eccfeb","price_changes":[{"asset_id":"24254094493625419915756280046002869097156693848522361803041977572204227262166","best_ask":"0.86","best_bid":"0.84","hash":"24b903fc1979c5f6fd3d2617230ae8a8511726ef","price":"0.84","side":"BUY","size":"111.53"},{"asset_id":"41448400836309843603620980831210604935021861034693225347475867885462478926555","best_ask":"0.16","best_bid":"0.14","hash":"e2971dc9baaa362caa769b5d27b592a33509e6db","price":"0.16","side":"SELL","size":"111.53"}],"timestamp":"1785122807164"},"payload_hash":"33632f3c9eadc5382a7fb8d8d767fb9560e13d6623e1a9347cabba6ab39d6f3c","raw_frame":"{\"market\":\"0x717c0e8ccd4d5c7040185188fbae28be901ca589a11a94b1b38ca36a79eccfeb\", \"price_changes\":[{\"asset_id\":\"24254094493625419915756280046002869097156693848522361803041977572204227262166\", \"price\":\"0.84\", \"size\":\"111.53\", \"side\":\"BUY\", \"hash\":\"24b903fc1979c5f6fd3d2617230ae8a8511726ef\", \"best_bid\":\"0.84\", \"best_ask\":\"0.86\"}, {\"asset_id\":\"41448400836309843603620980831210604935021861034693225347475867885462478926555\", \"price\":\"0.16\", \"size\":\"111.53\", \"side\":\"SELL\", \"hash\":\"e2971dc9baaa362caa769b5d27b592a33509e6db\", \"best_bid\":\"0.14\", \"best_ask\":\"0.16\"}], \"timestamp\":\"1785122807164\", \"event_type\":\"price_change\"}","received_at":"2026-07-27T03:26:47.043353Z","schema_version":"clob-market-ws.price_change.v1","sequence":null,"server_hash":null,"server_timestamp":"1785122807164","session_id":"dd162b8dca5f43ff811d304e69a06123","source":"clob_market_ws"},"received_at":"2026-07-27T03:26:47.043353Z","record_id":"aa381b9c54fae1aca957ebde4fa6087a917d8992555f5bb62bef8b5133bd1bbc","schema_fingerprint":"4aa3821a28b0b7c2400bc59aba4bcc0a76e971dadd19610d3ad38c768e124dc7","schema_version":"edge-lab-recorder.raw.v1","sequence":null,"source":"clob_market_ws"}
{"event_at":"2026-07-27T03:26:47.165000Z","event_fingerprint":"5f25c6750cbbc83ed9098f83ca86bf9289bbc6aa7c8e303399dc5c1804ed3528","payload":{"connection_id":"c7dc2e4762f849c6b6f9306b6518dcab","event_at":"2026-07-27T03:26:47.165000Z","event_type":"price_change","frame_hash":"de52429b3fb874dd5fc48cb76bb8bb15c34e78300af7d80c8f7d09e51fe59f93","frame_index":0,"kind":"data","monotonic_ns":224790412298583,"payload":{"event_type":"price_change","market":"0x717c0e8ccd4d5c7040185188fbae28be901ca589a11a94b1b38ca36a79eccfeb","price_changes":[{"asset_id":"41448400836309843603620980831210604935021861034693225347475867885462478926555","best_ask":"0.16","best_bid":"0.14","hash":"18a9a27bbff8985236e66287bf63f26971de7965","price":"0.18","side":"SELL","size":"73.98"},{"asset_id":"24254094493625419915756280046002869097156693848522361803041977572204227262166","best_ask":"0.86","best_bid":"0.84","hash":"391b08059f6f52387ef28b44feb6792f0af52c81","price":"0.82","side":"BUY","size":"73.98"}],"timestamp":"1785122807165"},"payload_hash":"e4bbf0dc1ae23831c920f059c75877272e5f9621e8041b497105d0e2f768eba0","raw_frame":"{\"market\":\"0x717c0e8ccd4d5c7040185188fbae28be901ca589a11a94b1b38ca36a79eccfeb\", \"price_changes\":[{\"asset_id\":\"41448400836309843603620980831210604935021861034693225347475867885462478926555\", \"price\":\"0.18\", \"size\":\"73.98\", \"side\":\"SELL\", \"hash\":\"18a9a27bbff8985236e66287bf63f26971de7965\", \"best_bid\":\"0.14\", \"best_ask\":\"0.16\"}, {\"asset_id\":\"24254094493625419915756280046002869097156693848522361803041977572204227262166\", \"price\":\"0.82\", \"size\":\"73.98\", \"side\":\"BUY\", \"hash\":\"391b08059f6f52387ef28b44feb6792f0af52c81\", \"best_bid\":\"0.84\", \"best_ask\":\"0.86\"}], \"timestamp\":\"1785122807165\", \"event_type\":\"price_change\"}","received_at":"2026-07-27T03:26:47.051759Z","schema_version":"clob-market-ws.price_change.v1","sequence":null,"server_hash":null,"server_timestamp":"1785122807165","session_id":"dd162b8dca5f43ff811d304e69a06123","source":"clob_market_ws"},"received_at":"2026-07-27T03:26:47.051759Z","record_id":"696f3f2eda77fd5a5cf34cfb5096ad1e9fe66a0ea93675e28d42361b68cce16a","schema_fingerprint":"4aa3821a28b0b7c2400bc59aba4bcc0a76e971dadd19610d3ad38c768e124dc7","schema_version":"edge-lab-recorder.raw.v1","sequence":null,"source":"clob_market_ws"}
