{"event_at":"2026-07-27T03:10:30.000000Z","event_fingerprint":"6114c9f0fcc56b53c6c60885d2eedb9a0d46039984cb8f5a36b9cbf7ae51353e","payload":{"connection_id":"c7dc2e4762f849c6b6f9306b6518dcab","event_at":"2026-07-27T03:10:30.000000Z","event_type":"price_change","frame_hash":"38106b6d9b7b9989d0c23f24bb94189c84221c20b81294cd0e86989e4936a709","frame_index":0,"kind":"data","monotonic_ns":223813237442791,"payload":{"event_type":"price_change","market":"0x717c0e8ccd4d5c7040185188fbae28be901ca589a11a94b1b38ca36a79eccfeb","price_changes":[{"asset_id":"24254094493625419915756280046002869097156693848522361803041977572204227262166","best_ask":"0.53","best_bid":"0.52","hash":"8a36d2e4014f172f3041090f2b8bd931dc810529","price":"0.35","side":"BUY","size":"15"},{"asset_id":"41448400836309843603620980831210604935021861034693225347475867885462478926555","best_ask":"0.48","best_bid":"0.47","hash":"54fe5ba0f5bf97c9c4a066fc37a29dce723fe78e","price":"0.65","side":"SELL","size":"15"}],"timestamp":"1785121830000"},"payload_hash":"c374d80db89ad34cd8d971eae46f3faed41c57a469aa1c8910eb702c101e4202","raw_frame":"{\"market\":\"0x717c0e8ccd4d5c7040185188fbae28be901ca589a11a94b1b38ca36a79eccfeb\", \"price_changes\":[{\"asset_id\":\"24254094493625419915756280046002869097156693848522361803041977572204227262166\", \"price\":\"0.35\", \"size\":\"15\", \"side\":\"BUY\", \"hash\":\"8a36d2e4014f172f3041090f2b8bd931dc810529\", \"best_bid\":\"0.52\", \"best_ask\":\"0.53\"}, {\"asset_id\":\"41448400836309843603620980831210604935021861034693225347475867885462478926555\", \"price\":\"0.65\", \"size\":\"15\", \"side\":\"SELL\", \"hash\":\"54fe5ba0f5bf97c9c4a066fc37a29dce723fe78e\", \"best_bid\":\"0.47\", \"best_ask\":\"0.48\"}], \"timestamp\":\"1785121830000\", \"event_type\":\"price_change\"}","received_at":"2026-07-27T03:10:29.907564Z","schema_version":"clob-market-ws.price_change.v1","sequence":null,"server_hash":null,"server_timestamp":"1785121830000","session_id":"dd162b8dca5f43ff811d304e69a06123","source":"clob_market_ws"},"received_at":"2026-07-27T03:10:29.907564Z","record_id":"9a21993ce28f0f5ddd48c293924369a692d27ac3fd718168ba48db2e8bbd0c92","schema_fingerprint":"4aa3821a28b0b7c2400bc59aba4bcc0a76e971dadd19610d3ad38c768e124dc7","schema_version":"edge-lab-recorder.raw.v1","sequence":null,"source":"clob_market_ws"}
{"event_at":"2026-07-27T03:10:30.001000Z","event_fingerprint":"4c6c7e3fb3d0e18c7b4f684397c18a15a0676a90e3cc42ac1ad62f80462a51d4","payload":{"connection_id":"c7dc2e4762f849c6b6f9306b6518dcab","event_at":"2026-07-27T03:10:30.001000Z","event_type":"price_change","frame_hash":"aaad2c168950148bf0d53377ce75fb1c35352c948b9797813d6e83d03250a2f6","frame_index":0,"kind":"data","monotonic_ns":223813244462375,"payload":{"event_type":"price_change","market":"0x717c0e8ccd4d5c7040185188fbae28be901ca589a11a94b1b38ca36a79eccfeb","price_changes":[{"asset_id":"24254094493625419915756280046002869097156693848522361803041977572204227262166","best_ask":"0.53","best_bid":"0.52","hash":"8e2c4592d47f0364680620dd186a33ab8107fbd1","price":"0.35","side":"BUY","size":"15"},{"asset_id":"41448400836309843603620980831210604935021861034693225347475867885462478926555","best_ask":"0.48","best_bid":"0.47","hash":"3d98cee0e82be45b3dbf9b2c9d44b143f94c5bdd","price":"0.65","side":"SELL","size":"15"}],"timestamp":"1785121830001"},"payload_hash":"febec4478e60e248e65a5c2ec2bd9852c8363092fb8e6f0610d1834afc06f877","raw_frame":"{\"market\":\"0x717c0e8ccd4d5c7040185188fbae28be901ca589a11a94b1b38ca36a79eccfeb\", \"price_changes\":[{\"asset_id\":\"24254094493625419915756280046002869097156693848522361803041977572204227262166\", \"price\":\"0.35\", \"size\":\"15\", \"side\":\"BUY\", \"hash\":\"8e2c4592d47f0364680620dd186a33ab8107fbd1\", \"best_bid\":\"0.52\", \"best_ask\":\"0.53\"}, {\"asset_id\":\"41448400836309843603620980831210604935021861034693225347475867885462478926555\", \"price\":\"0.65\", \"size\":\"15\", \"side\":\"SELL\", \"hash\":\"3d98cee0e82be45b3dbf9b2c9d44b143f94c5bdd\", \"best_bid\":\"0.47\", \"best_ask\":\"0.48\"}], \"timestamp\":\"1785121830001\", \"event_type\":\"price_change\"}","received_at":"2026-07-27T03:10:29.914584Z","schema_version":"clob-market-ws.price_change.v1","sequence":null,"server_hash":null,"server_timestamp":"1785121830001","session_id":"dd162b8dca5f43ff811d304e69a06123","source":"clob_market_ws"},"received_at":"2026-07-27T03:10:29.914584Z","record_id":"466fbc221a4675ee7c0ebe70780a4f79cbdcb3e4964d583deb76564c20784d67","schema_fingerprint":"4aa3821a28b0b7c2400bc59aba4bcc0a76e971dadd19610d3ad38c768e124dc7","schema_version":"edge-lab-recorder.raw.v1","sequence":null,"source":"clob_market_ws"}
{"event_at":"2026-07-27T03:10:30.862000Z","event_fingerprint":"7112073c9c46b031046b0263e2d79340158886de477ef1ba025dcc788ab705fe","payload":{"connection_id":"c7dc2e4762f849c6b6f9306b6518dcab","event_at":"2026-07-27T03:10:30.862000Z","event_type":"price_change","frame_hash":"6a3a8c3cb6b219cd3dbc1797e846437ce6eff8f53ab019ab24d5b37fc4948955","frame_index":0,"kind":"data","monotonic_ns":223814100199791,"payload":{"event_type":"price_change","market":"0x717c0e8ccd4d5c7040185188fbae28be901ca589a11a94b1b38ca36a79eccfeb","price_changes":[{"asset_id":"41448400836309843603620980831210604935021861034693225347475867885462478926555","best_ask":"0.48","best_bid":"0.47","hash":"8fc462992dfed5f153411238ce00cd3ed046a010","price":"0.47","side":"BUY","size":"24.67"},{"asset_id":"24254094493625419915756280046002869097156693848522361803041977572204227262166","best_ask":"0.53","best_bid":"0.52","hash":"710cd14e7297902efffd7d23e69d7b01dc7548c0","price":"0.53","side":"SELL","size":"24.67"}],"timestamp":"1785121830862"},"payload_hash":"f847f4ade4e62dc5c583914375a6c8a409e7772c74abae1e0d7828a275c146ff","raw_frame":"{\"market\":\"0x717c0e8ccd4d5c7040185188fbae28be901ca589a11a94b1b38ca36a79eccfeb\", \"price_changes\":[{\"asset_id\":\"41448400836309843603620980831210604935021861034693225347475867885462478926555\", \"price\":\"0.47\", \"size\":\"24.67\", \"side\":\"BUY\", \"hash\":\"8fc462992dfed5f153411238ce00cd3ed046a010\", \"best_bid\":\"0.47\", \"best_ask\":\"0.48\"}, {\"asset_id\":\"24254094493625419915756280046002869097156693848522361803041977572204227262166\", \"price\":\"0.53\", \"size\":\"24.67\", \"side\":\"SELL\", \"hash\":\"710cd14e7297902efffd7d23e69d7b01dc7548c0\", \"best_bid\":\"0.52\", \"best_ask\":\"0.53\"}], \"timestamp\":\"1785121830862\", \"event_type\":\"price_change\"}","received_at":"2026-07-27T03:10:30.770309Z","schema_version":"clob-market-ws.price_change.v1","sequence":null,"server_hash":null,"server_timestamp":"1785121830862","session_id":"dd162b8dca5f43ff811d304e69a06123","source":"clob_market_ws"},"received_at":"2026-07-27T03:10:30.770309Z","record_id":"eb355dff8fab20b3183f774693346e221ecf34ebec6c01573ee56f7544757eed","schema_fingerprint":"4aa3821a28b0b7c2400bc59aba4bcc0a76e971dadd19610d3ad38c768e124dc7","schema_version":"edge-lab-recorder.raw.v1","sequence":null,"source":"clob_market_ws"}
{"event_at":"2026-07-27T03:10:31.000000Z","event_fingerprint":"7fbe8e46b2d7f2b5c6099dedc2af45488ea0101070298ad8951bf4650aa06be0","payload":{"connection_id":"c7dc2e4762f849c6b6f9306b6518dcab","event_at":"2026-07-27T03:10:31.000000Z","event_type":"price_change","frame_hash":"03aa9f0b66db3fd10bb702008ca89142ed1ccc95e4789e7131c890d3307a4ffd","frame_index":0,"kind":"data","monotonic_ns":223814236852000,"payload":{"event_type":"price_change","market":"0x717c0e8ccd4d5c7040185188fbae28be901ca589a11a94b1b38ca36a79eccfeb","price_changes":[{"asset_id":"41448400836309843603620980831210604935021861034693225347475867885462478926555","best_ask":"0.48","best_bid":"0.47","hash":"89b4bec0d7e23a7d631d4bb19744cea16f2e35d4","price":"0.35","side":"BUY","size":"15"},{"asset_id":"24254094493625419915756280046002869097156693848522361803041977572204227262166","best_ask":"0.53","best_bid":"0.52","hash":"8942dd0747094a6d0c2f0137eb6643ad2e692a05","price":"0.65","side":"SELL","size":"15"}],"timestamp":"1785121831000"},"payload_hash":"7c503a99a58213e181b097a318a918a5b15d067126150dbdd25f1e282adad2b4","raw_frame":"{\"market\":\"0x717c0e8ccd4d5c7040185188fbae28be901ca589a11a94b1b38ca36a79eccfeb\", \"price_changes\":[{\"asset_id\":\"41448400836309843603620980831210604935021861034693225347475867885462478926555\", \"price\":\"0.35\", \"size\":\"15\", \"side\":\"BUY\", \"hash\":\"89b4bec0d7e23a7d631d4bb19744cea16f2e35d4\", \"best_bid\":\"0.47\", \"best_ask\":\"0.48\"}, {\"asset_id\":\"24254094493625419915756280046002869097156693848522361803041977572204227262166\", \"price\":\"0.65\", \"size\":\"15\", \"side\":\"SELL\", \"hash\":\"8942dd0747094a6d0c2f0137eb6643ad2e692a05\", \"best_bid\":\"0.52\", \"best_ask\":\"0.53\"}], \"timestamp\":\"1785121831000\", \"event_type\":\"price_change\"}","received_at":"2026-07-27T03:10:30.906958Z","schema_version":"clob-market-ws.price_change.v1","sequence":null,"server_hash":null,"server_timestamp":"1785121831000","session_id":"dd162b8dca5f43ff811d304e69a06123","source":"clob_market_ws"},"received_at":"2026-07-27T03:10:30.906958Z","record_id":"26580f6ba3f0ab5f8f008fd54ce20225556926417c31b32f2fe442d24a74d34a","schema_fingerprint":"4aa3821a28b0b7c2400bc59aba4bcc0a76e971dadd19610d3ad38c768e124dc7","schema_version":"edge-lab-recorder.raw.v1","sequence":null,"source":"clob_market_ws"}
{"event_at":"2026-07-27T03:10:31.001000Z","event_fingerprint":"f23ff81e62c1b56dfaf0a9b3a01f379ef8129dc0cc20f913e6b70eafd63a32da","payload":{"connection_id":"c7dc2e4762f849c6b6f9306b6518dcab","event_at":"2026-07-27T03:10:31.001000Z","event_type":"price_change","frame_hash":"8e340bea9ac7784129314c4bc4c6217b79e89e0a69e6f85399ea3bf9bb4dd064","frame_index":0,"kind":"data","monotonic_ns":223814243442333,"payload":{"event_type":"price_change","market":"0x717c0e8ccd4d5c7040185188fbae28be901ca589a11a94b1b38ca36a79eccfeb","price_changes":[{"asset_id":"41448400836309843603620980831210604935021861034693225347475867885462478926555","best_ask":"0.48","best_bid":"0.47","hash":"0b5559cd7f229d00233268fb35d04699dde9119d","price":"0.35","side":"BUY","size":"15"},{"asset_id":"24254094493625419915756280046002869097156693848522361803041977572204227262166","best_ask":"0.53","best_bid":"0.52","hash":"8052132e341174c689a440345452cc00f2f40a8a","price":"0.65","side":"SELL","size":"15"}],"timestamp":"1785121831001"},"payload_hash":"d51c79b20888606f3be2d78128a306ca030dc5c3246eef8b2c7ea569823a0f5e","raw_frame":"{\"market\":\"0x717c0e8ccd4d5c7040185188fbae28be901ca589a11a94b1b38ca36a79eccfeb\", \"price_changes\":[{\"asset_id\":\"41448400836309843603620980831210604935021861034693225347475867885462478926555\", \"price\":\"0.35\", \"size\":\"15\", \"side\":\"BUY\", \"hash\":\"0b5559cd7f229d00233268fb35d04699dde9119d\", \"best_bid\":\"0.47\", \"best_ask\":\"0.48\"}, {\"asset_id\":\"24254094493625419915756280046002869097156693848522361803041977572204227262166\", \"price\":\"0.65\", \"size\":\"15\", \"side\":\"SELL\", \"hash\":\"8052132e341174c689a440345452cc00f2f40a8a\", \"best_bid\":\"0.52\", \"best_ask\":\"0.53\"}], \"timestamp\":\"1785121831001\", \"event_type\":\"price_change\"}","received_at":"2026-07-27T03:10:30.913550Z","schema_version":"clob-market-ws.price_change.v1","sequence":null,"server_hash":null,"server_timestamp":"1785121831001","session_id":"dd162b8dca5f43ff811d304e69a06123","source":"clob_market_ws"},"received_at":"2026-07-27T03:10:30.913550Z","record_id":"3dfeb0ff931e01477d3fe02a636976782eaad3aea039b98f05f9173c45cbb55e","schema_fingerprint":"4aa3821a28b0b7c2400bc59aba4bcc0a76e971dadd19610d3ad38c768e124dc7","schema_version":"edge-lab-recorder.raw.v1","sequence":null,"source":"clob_market_ws"}
{"event_at":"2026-07-27T03:10:31.615000Z","event_fingerprint":"88dab3633d154f220659a947cb1032773feeda19fe249c33311b48d86759e946","payload":{"connection_id":"c7dc2e4762f849c6b6f9306b6518dcab","event_at":"2026-07-27T03:10:31.615000Z","event_type":"price_change","frame_hash":"878c0553f70aca0efc2882c29d25dc385482ef0124c197e09c4bd91681deb014","frame_index":0,"kind":"data","monotonic_ns":223814853760875,"payload":{"event_type":"price_change","market":"0x717c0e8ccd4d5c7040185188fbae28be901ca589a11a94b1b38ca36a79eccfeb","price_changes":[{"asset_id":"41448400836309843603620980831210604935021861034693225347475867885462478926555","best_ask":"0.48","best_bid":"0.47","hash":"cadbce04e82dcb9d50c0de359e1a1e86729c0b9e","price":"0.47","side":"BUY","size":"324.67"},{"asset_id":"24254094493625419915756280046002869097156693848522361803041977572204227262166","best_ask":"0.53","best_bid":"0.52","hash":"735acb3825c7860046184b9564b26d1a64abaf27","price":"0.53","side":"SELL","size":"324.67"}],"timestamp":"1785121831615"},"payload_hash":"dece9865ac2fb3a745b03ea0a193162575bbf4ffb8889c57e01111ed6820673f","raw_frame":"{\"market\":\"0x717c0e8ccd4d5c7040185188fbae28be901ca589a11a94b1b38ca36a79eccfeb\", \"price_changes\":[{\"asset_id\":\"41448400836309843603620980831210604935021861034693225347475867885462478926555\", \"price\":\"0.47\", \"size\":\"324.67\", \"side\":\"BUY\", \"hash\":\"cadbce04e82dcb9d50c0de359e1a1e86729c0b9e\", \"best_bid\":\"0.47\", \"best_ask\":\"0.48\"}, {\"asset_id\":\"24254094493625419915756280046002869097156693848522361803041977572204227262166\", \"price\":\"0.53\", \"size\":\"324.67\", \"side\":\"SELL\", \"hash\":\"735acb3825c7860046184b9564b26d1a64abaf27\", \"best_bid\":\"0.52\", \"best_ask\":\"0.53\"}], \"timestamp\":\"1785121831615\", \"event_type\":\"price_change\"}","received_at":"2026-07-27T03:10:31.523858Z","schema_version":"clob-market-ws.price_change.v1","sequence":null,"server_hash":null,"server_timestamp":"1785121831615","session_id":"dd162b8dca5f43ff811d304e69a06123","source":"clob_market_ws"},"received_at":"2026-07-27T03:10:31.523858Z","record_id":"5ba42cf5c83f5ce7f1c30ef52c8d71f310a0a3c9484ffae42e33384c9f3c1d94","schema_fingerprint":"4aa3821a28b0b7c2400bc59aba4bcc0a76e971dadd19610d3ad38c768e124dc7","schema_version":"edge-lab-recorder.raw.v1","sequence":null,"source":"clob_market_ws"}
{"event_at":"2026-07-27T03:10:31.822000Z","event_fingerprint":"d3b4a4e71c0ce46b7992de22ecd91d048e3f4726da575ac72ebb3e71be34c159","payload":{"connection_id":"c7dc2e4762f849c6b6f9306b6518dcab","event_at":"2026-07-27T03:10:31.822000Z","event_type":"price_change","frame_hash":"8657c6ed5d40fa2d4e57049a11c8cf40db417a0e8564e36c35d7eb99014a67da","frame_index":0,"kind":"data","monotonic_ns":223815061341500,"payload":{"event_type":"price_change","market":"0x717c0e8ccd4d5c7040185188fbae28be901ca589a11a94b1b38ca36a79eccfeb","price_changes":[{"asset_id":"41448400836309843603620980831210604935021861034693225347475867885462478926555","best_ask":"0.48","best_bid":"0.47","hash":"2d8451b6c6e4fe794ff453920de0f752066be43f","price":"0.47","side":"BUY","size":"24.67"},{"asset_id":"24254094493625419915756280046002869097156693848522361803041977572204227262166","best_ask":"0.53","best_bid":"0.52","hash":"4ced80ce3556c0142cdc84cc70eca5e2b371c8f3","price":"0.53","side":"SELL","size":"24.67"}],"timestamp":"1785121831822"},"payload_hash":"ce6ac48c67b22eeb46043e082703f6f724b12d58589740dcad70d7b4d90bbaee","raw_frame":"{\"market\":\"0x717c0e8ccd4d5c7040185188fbae28be901ca589a11a94b1b38ca36a79eccfeb\", \"price_changes\":[{\"asset_id\":\"41448400836309843603620980831210604935021861034693225347475867885462478926555\", \"price\":\"0.47\", \"size\":\"24.67\", \"side\":\"BUY\", \"hash\":\"2d8451b6c6e4fe794ff453920de0f752066be43f\", \"best_bid\":\"0.47\", \"best_ask\":\"0.48\"}, {\"asset_id\":\"24254094493625419915756280046002869097156693848522361803041977572204227262166\", \"price\":\"0.53\", \"size\":\"24.67\", \"side\":\"SELL\", \"hash\":\"4ced80ce3556c0142cdc84cc70eca5e2b371c8f3\", \"best_bid\":\"0.52\", \"best_ask\":\"0.53\"}], \"timestamp\":\"1785121831822\", \"event_type\":\"price_change\"}","received_at":"2026-07-27T03:10:31.731438Z","schema_version":"clob-market-ws.price_change.v1","sequence":null,"server_hash":null,"server_timestamp":"1785121831822","session_id":"dd162b8dca5f43ff811d304e69a06123","source":"clob_market_ws"},"received_at":"2026-07-27T03:10:31.731438Z","record_id":"f01a5eaba35d5939f4cdab2bf1d5d4db63309818c8e245efb5439a9ac613d59e","schema_fingerprint":"4aa3821a28b0b7c2400bc59aba4bcc0a76e971dadd19610d3ad38c768e124dc7","schema_version":"edge-lab-recorder.raw.v1","sequence":null,"source":"clob_market_ws"}
{"event_at":"2026-07-27T03:10:31.975000Z","event_fingerprint":"f570c19adf9314c3dcb69cf209c4203c46cb8272496a5293786414cdbf8fe3e8","payload":{"connection_id":"c7dc2e4762f849c6b6f9306b6518dcab","event_at":"2026-07-27T03:10:31.975000Z","event_type":"price_change","frame_hash":"b1a63e47b8f5a8e5523985e343a71b09512625206e5cb8f448cb6d0e413c5d49","frame_index":0,"kind":"data","monotonic_ns":223815211270041,"payload":{"event_type":"price_change","market":"0x717c0e8ccd4d5c7040185188fbae28be901ca589a11a94b1b38ca36a79eccfeb","price_changes":[{"asset_id":"24254094493625419915756280046002869097156693848522361803041977572204227262166","best_ask":"0.53","best_bid":"0.52","hash":"3a52dd4c651cffb68c5102b6d690cec4b6865aee","price":"0.01","side":"BUY","size":"97907.45"},{"asset_id":"41448400836309843603620980831210604935021861034693225347475867885462478926555","best_ask":"0.48","best_bid":"0.47","hash":"900fbd3a78259254adc5b149396550b53732a8ac","price":"0.99","side":"SELL","size":"97907.45"}],"timestamp":"1785121831975"},"payload_hash":"7c643c64e26d58285d515c0256c2e31578bbe63668aba4a4eaaf93326933c896","raw_frame":"{\"market\":\"0x717c0e8ccd4d5c7040185188fbae28be901ca589a11a94b1b38ca36a79eccfeb\", \"price_changes\":[{\"asset_id\":\"24254094493625419915756280046002869097156693848522361803041977572204227262166\", \"price\":\"0.01\", \"size\":\"97907.45\", \"side\":\"BUY\", \"hash\":\"3a52dd4c651cffb68c5102b6d690cec4b6865aee\", \"best_bid\":\"0.52\", \"best_ask\":\"0.53\"}, {\"asset_id\":\"41448400836309843603620980831210604935021861034693225347475867885462478926555\", \"price\":\"0.99\", \"size\":\"97907.45\", \"side\":\"SELL\", \"hash\":\"900fbd3a78259254adc5b149396550b53732a8ac\", \"best_bid\":\"0.47\", \"best_ask\":\"0.48\"}], \"timestamp\":\"1785121831975\", \"event_type\":\"price_change\"}","received_at":"2026-07-27T03:10:31.881364Z","schema_version":"clob-market-ws.price_change.v1","sequence":null,"server_hash":null,"server_timestamp":"1785121831975","session_id":"dd162b8dca5f43ff811d304e69a06123","source":"clob_market_ws"},"received_at":"2026-07-27T03:10:31.881364Z","record_id":"41ae759db112c4a23dfd52a887272464b745d5e01769079607b5c7e136446a6b","schema_fingerprint":"4aa3821a28b0b7c2400bc59aba4bcc0a76e971dadd19610d3ad38c768e124dc7","schema_version":"edge-lab-recorder.raw.v1","sequence":null,"source":"clob_market_ws"}
{"event_at":"2026-07-27T03:10:32.000000Z","event_fingerprint":"2c8fb2b64ba5313dfcf65c92ac5243f396470647887884910f2d6192039d013e","payload":{"connection_id":"c7dc2e4762f849c6b6f9306b6518dcab","event_at":"2026-07-27T03:10:32.000000Z","event_type":"price_change","frame_hash":"b58b03785ef3a6c0af7fe101569d68ddfa9a3061c58fe312e5b8114079403195","frame_index":0,"kind":"data","monotonic_ns":223815236610500,"payload":{"event_type":"price_change","market":"0x717c0e8ccd4d5c7040185188fbae28be901ca589a11a94b1b38ca36a79eccfeb","price_changes":[{"asset_id":"24254094493625419915756280046002869097156693848522361803041977572204227262166","best_ask":"0.53","best_bid":"0.52","hash":"96a4e8f1f7d2b4a09ef346a919482478b3e240c0","price":"0.05","side":"BUY","size":"5391"},{"asset_id":"41448400836309843603620980831210604935021861034693225347475867885462478926555","best_ask":"0.48","best_bid":"0.47","hash":"9637fc518a29698e88e75bc095f357bb4b76b71c","price":"0.95","side":"SELL","size":"5391"}],"timestamp":"1785121832000"},"payload_hash":"804657e6bfd86594f18d915d55e8809da35fcfa74df747d90641e17fd797d125","raw_frame":"{\"market\":\"0x717c0e8ccd4d5c7040185188fbae28be901ca589a11a94b1b38ca36a79eccfeb\", \"price_changes\":[{\"asset_id\":\"24254094493625419915756280046002869097156693848522361803041977572204227262166\", \"price\":\"0.05\", \"size\":\"5391\", \"side\":\"BUY\", \"hash\":\"96a4e8f1f7d2b4a09ef346a919482478b3e240c0\", \"best_bid\":\"0.52\", \"best_ask\":\"0.53\"}, {\"asset_id\":\"41448400836309843603620980831210604935021861034693225347475867885462478926555\", \"price\":\"0.95\", \"size\":\"5391\", \"side\":\"SELL\", \"hash\":\"9637fc518a29698e88e75bc095f357bb4b76b71c\", \"best_bid\":\"0.47\", \"best_ask\":\"0.48\"}], \"timestamp\":\"1785121832000\", \"event_type\":\"price_change\"}","received_at":"2026-07-27T03:10:31.906704Z","schema_version":"clob-market-ws.price_change.v1","sequence":null,"server_hash":null,"server_timestamp":"1785121832000","session_id":"dd162b8dca5f43ff811d304e69a06123","source":"clob_market_ws"},"received_at":"2026-07-27T03:10:31.906704Z","record_id":"b5632396bd0643870e2bdb8ee7e2133a25e89a587bc433f5b0aba59f26b5ce9d","schema_fingerprint":"4aa3821a28b0b7c2400bc59aba4bcc0a76e971dadd19610d3ad38c768e124dc7","schema_version":"edge-lab-recorder.raw.v1","sequence":null,"source":"clob_market_ws"}
{"event_at":"2026-07-27T03:10:32.000000Z","event_fingerprint":"41585e252c04e5331bfff63e4588d740bd081bfff082eac39e2a7775f8408d8b","payload":{"connection_id":"c7dc2e4762f849c6b6f9306b6518dcab","event_at":"2026-07-27T03:10:32.000000Z","event_type":"price_change","frame_hash":"1ac3440094835424488a842250f8ab6a8cb67477c76271db80512b7adeba4e83","frame_index":0,"kind":"data","monotonic_ns":223815241049333,"payload":{"event_type":"price_change","market":"0x717c0e8ccd4d5c7040185188fbae28be901ca589a11a94b1b38ca36a79eccfeb","price_changes":[{"asset_id":"24254094493625419915756280046002869097156693848522361803041977572204227262166","best_ask":"0.53","best_bid":"0.52","hash":"96a4e8f1f7d2b4a09ef346a919482478b3e240c0","price":"0.02","side":"BUY","size":"16850"},{"asset_id":"41448400836309843603620980831210604935021861034693225347475867885462478926555","best_ask":"0.48","best_bid":"0.47","hash":"9637fc518a29698e88e75bc095f357bb4b76b71c","price":"0.98","side":"SELL","size":"16850"}],"timestamp":"1785121832000"},"payload_hash":"a28cd316210aa9cd312be4bdd42319b5d4051edff2c1c2cabf4e891138afc082","raw_frame":"{\"market\":\"0x717c0e8ccd4d5c7040185188fbae28be901ca589a11a94b1b38ca36a79eccfeb\", \"price_changes\":[{\"asset_id\":\"24254094493625419915756280046002869097156693848522361803041977572204227262166\", \"price\":\"0.02\", \"size\":\"16850\", \"side\":\"BUY\", \"hash\":\"96a4e8f1f7d2b4a09ef346a919482478b3e240c0\", \"best_bid\":\"0.52\", \"best_ask\":\"0.53\"}, {\"asset_id\":\"41448400836309843603620980831210604935021861034693225347475867885462478926555\", \"price\":\"0.98\", \"size\":\"16850\", \"side\":\"SELL\", \"hash\":\"9637fc518a29698e88e75bc095f357bb4b76b71c\", \"best_bid\":\"0.47\", \"best_ask\":\"0.48\"}], \"timestamp\":\"1785121832000\", \"event_type\":\"price_change\"}","received_at":"2026-07-27T03:10:31.911142Z","schema_version":"clob-market-ws.price_change.v1","sequence":null,"server_hash":null,"server_timestamp":"1785121832000","session_id":"dd162b8dca5f43ff811d304e69a06123","source":"clob_market_ws"},"received_at":"2026-07-27T03:10:31.911142Z","record_id":"43111b5197674cdff54bb4e276b4688189ad83f166ea6e5557d3b4a687195382","schema_fingerprint":"4aa3821a28b0b7c2400bc59aba4bcc0a76e971dadd19610d3ad38c768e124dc7","schema_version":"edge-lab-recorder.raw.v1","sequence":null,"source":"clob_market_ws"}
{"event_at":"2026-07-27T03:10:32.001000Z","event_fingerprint":"04bd9adb316d9ad9db5dd7ff89c638f1f2918f496ad18a9e1fe46f6e768e8827","payload":{"connection_id":"c7dc2e4762f849c6b6f9306b6518dcab","event_at":"2026-07-27T03:10:32.001000Z","event_type":"price_change","frame_hash":"8bf3bb9db4be1ebe70cf7599fa91a08af819e33cadbe6f7c2be844d239c94355","frame_index":0,"kind":"data","monotonic_ns":223815245902875,"payload":{"event_type":"price_change","market":"0x717c0e8ccd4d5c7040185188fbae28be901ca589a11a94b1b38ca36a79eccfeb","price_changes":[{"asset_id":"24254094493625419915756280046002869097156693848522361803041977572204227262166","best_ask":"0.53","best_bid":"0.52","hash":"423b6eaa2da7ef224a261279ecde3c75f2af4318","price":"0.01","side":"BUY","size":"97900.02"},{"asset_id":"41448400836309843603620980831210604935021861034693225347475867885462478926555","best_ask":"0.48","best_bid":"0.47","hash":"2ae841f9fbdfcaf2d7ada5a1b90b1cf4fa381e6b","price":"0.99","side":"SELL","size":"97900.02"}],"timestamp":"1785121832001"},"payload_hash":"45126cc236c467a3d5e05d3c535b80b1786580b129346f76ce1a104df9c01dee","raw_frame":"{\"market\":\"0x717c0e8ccd4d5c7040185188fbae28be901ca589a11a94b1b38ca36a79eccfeb\", \"price_changes\":[{\"asset_id\":\"24254094493625419915756280046002869097156693848522361803041977572204227262166\", \"price\":\"0.01\", \"size\":\"97900.02\", \"side\":\"BUY\", \"hash\":\"423b6eaa2da7ef224a261279ecde3c75f2af4318\", \"best_bid\":\"0.52\", \"best_ask\":\"0.53\"}, {\"asset_id\":\"41448400836309843603620980831210604935021861034693225347475867885462478926555\", \"price\":\"0.99\", \"size\":\"97900.02\", \"side\":\"SELL\", \"hash\":\"2ae841f9fbdfcaf2d7ada5a1b90b1cf4fa381e6b\", \"best_bid\":\"0.47\", \"best_ask\":\"0.48\"}], \"timestamp\":\"1785121832001\", \"event_type\":\"price_change\"}","received_at":"2026-07-27T03:10:31.915998Z","schema_version":"clob-market-ws.price_change.v1","sequence":null,"server_hash":null,"server_timestamp":"1785121832001","session_id":"dd162b8dca5f43ff811d304e69a06123","source":"clob_market_ws"},"received_at":"2026-07-27T03:10:31.915998Z","record_id":"c88f9948d4e4f06ca30bc9d6f61245d6845e866c0b8d88635fc2cf35779b9d00","schema_fingerprint":"4aa3821a28b0b7c2400bc59aba4bcc0a76e971dadd19610d3ad38c768e124dc7","schema_version":"edge-lab-recorder.raw.v1","sequence":null,"source":"clob_market_ws"}
{"event_at":"2026-07-27T03:10:32.001000Z","event_fingerprint":"48344581aa20bae66ed7a62a8d0baf6ad92420febd6cea9985a26e53a49245d9","payload":{"connection_id":"c7dc2e4762f849c6b6f9306b6518dcab","event_at":"2026-07-27T03:10:32.001000Z","event_type":"price_change","frame_hash":"c41d8ad1595c39f92a96c64dd2796d285fc697c4ffc5b576cc9a0a398253c60e","frame_index":0,"kind":"data","monotonic_ns":223815252054375,"payload":{"event_type":"price_change","market":"0x717c0e8ccd4d5c7040185188fbae28be901ca589a11a94b1b38ca36a79eccfeb","price_changes":[{"asset_id":"24254094493625419915756280046002869097156693848522361803041977572204227262166","best_ask":"0.53","best_bid":"0.52","hash":"423b6eaa2da7ef224a261279ecde3c75f2af4318","price":"0.13","side":"BUY","size":"38"},{"asset_id":"41448400836309843603620980831210604935021861034693225347475867885462478926555","best_ask":"0.48","best_bid":"0.47","hash":"2ae841f9fbdfcaf2d7ada5a1b90b1cf4fa381e6b","price":"0.87","side":"SELL","size":"38"}],"timestamp":"1785121832001"},"payload_hash":"f0fe327bc892a061544fa1063b5441ea912baf00adb5f845fc2053f9164f83b2","raw_frame":"{\"market\":\"0x717c0e8ccd4d5c7040185188fbae28be901ca589a11a94b1b38ca36a79eccfeb\", \"price_changes\":[{\"asset_id\":\"24254094493625419915756280046002869097156693848522361803041977572204227262166\", \"price\":\"0.13\", \"size\":\"38\", \"side\":\"BUY\", \"hash\":\"423b6eaa2da7ef224a261279ecde3c75f2af4318\", \"best_bid\":\"0.52\", \"best_ask\":\"0.53\"}, {\"asset_id\":\"41448400836309843603620980831210604935021861034693225347475867885462478926555\", \"price\":\"0.87\", \"size\":\"38\", \"side\":\"SELL\", \"hash\":\"2ae841f9fbdfcaf2d7ada5a1b90b1cf4fa381e6b\", \"best_bid\":\"0.47\", \"best_ask\":\"0.48\"}], \"timestamp\":\"1785121832001\", \"event_type\":\"price_change\"}","received_at":"2026-07-27T03:10:31.922150Z","schema_version":"clob-market-ws.price_change.v1","sequence":null,"server_hash":null,"server_timestamp":"1785121832001","session_id":"dd162b8dca5f43ff811d304e69a06123","source":"clob_market_ws"},"received_at":"2026-07-27T03:10:31.922150Z","record_id":"ffc24afda3dd9e7f3d70ec1b80f15ce5ea8c3fd130e144251caef30102c8f0d4","schema_fingerprint":"4aa3821a28b0b7c2400bc59aba4bcc0a76e971dadd19610d3ad38c768e124dc7","schema_version":"edge-lab-recorder.raw.v1","sequence":null,"source":"clob_market_ws"}
{"event_at":"2026-07-27T03:10:32.183000Z","event_fingerprint":"9df9f09737f5f9cf031268b7b4c0a93c5f0d69e740ca8f3298249daad0afee1e","payload":{"connection_id":"c7dc2e4762f849c6b6f9306b6518dcab","event_at":"2026-07-27T03:10:32.183000Z","event_type":"price_change","frame_hash":"a33dfdaf82d73854267d6cdd578579d8129b83e30289796908e83c0530566237","frame_index":0,"kind":"data","monotonic_ns":223815421484208,"payload":{"event_type":"price_change","market":"0x717c0e8ccd4d5c7040185188fbae28be901ca589a11a94b1b38ca36a79eccfeb","price_changes":[{"asset_id":"41448400836309843603620980831210604935021861034693225347475867885462478926555","best_ask":"0.48","best_bid":"0.47","hash":"8be9f6275ffe85613cb6478cc4e37f2b77abbbbc","price":"0.47","side":"BUY","size":"324.67"},{"asset_id":"24254094493625419915756280046002869097156693848522361803041977572204227262166","best_ask":"0.53","best_bid":"0.52","hash":"9a1013a1ff3e11ce96bd1904f71d5e430c12cb85","price":"0.53","side":"SELL","size":"324.67"}],"timestamp":"1785121832183"},"payload_hash":"f3dad5bd6bcf6d1ff9cfabb4ce97c99733fa6da2a966b7623d189b05cc017f39","raw_frame":"{\"market\":\"0x717c0e8ccd4d5c7040185188fbae28be901ca589a11a94b1b38ca36a79eccfeb\", \"price_changes\":[{\"asset_id\":\"41448400836309843603620980831210604935021861034693225347475867885462478926555\", \"price\":\"0.47\", \"size\":\"324.67\", \"side\":\"BUY\", \"hash\":\"8be9f6275ffe85613cb6478cc4e37f2b77abbbbc\", \"best_bid\":\"0.47\", \"best_ask\":\"0.48\"}, {\"asset_id\":\"24254094493625419915756280046002869097156693848522361803041977572204227262166\", \"price\":\"0.53\", \"size\":\"324.67\", \"side\":\"SELL\", \"hash\":\"9a1013a1ff3e11ce96bd1904f71d5e430c12cb85\", \"best_bid\":\"0.52\", \"best_ask\":\"0.53\"}], \"timestamp\":\"1785121832183\", \"event_type\":\"price_change\"}","received_at":"2026-07-27T03:10:32.091574Z","schema_version":"clob-market-ws.price_change.v1","sequence":null,"server_hash":null,"server_timestamp":"1785121832183","session_id":"dd162b8dca5f43ff811d304e69a06123","source":"clob_market_ws"},"received_at":"2026-07-27T03:10:32.091574Z","record_id":"0b036ccf45d3ecff5195edbc74d897c479bfda38a06f3dbbaaf0f1951fbeb8e7","schema_fingerprint":"4aa3821a28b0b7c2400bc59aba4bcc0a76e971dadd19610d3ad38c768e124dc7","schema_version":"edge-lab-recorder.raw.v1","sequence":null,"source":"clob_market_ws"}
{"event_at":"2026-07-27T03:10:32.760000Z","event_fingerprint":"7eca5ac93e68da6c9726f04123209b5093180397f62ecf2280c93e3b770aa230","payload":{"connection_id":"c7dc2e4762f849c6b6f9306b6518dcab","event_at":"2026-07-27T03:10:32.760000Z","event_type":"price_change","frame_hash":"5fcc5ff8cc7f40c3679ee5d9de87939b0c5eb89d8e31e8569c00d1cbbfe4ff14","frame_index":0,"kind":"data","monotonic_ns":223815997569958,"payload":{"event_type":"price_change","market":"0x717c0e8ccd4d5c7040185188fbae28be901ca589a11a94b1b38ca36a79eccfeb","price_changes":[{"asset_id":"24254094493625419915756280046002869097156693848522361803041977572204227262166","best_ask":"0.53","best_bid":"0.52","hash":"719b8c72487743ddaa2e3b56495d6b3525ce6a9a","price":"0.01","side":"BUY","size":"97895.02"},{"asset_id":"41448400836309843603620980831210604935021861034693225347475867885462478926555","best_ask":"0.48","best_bid":"0.47","hash":"45d786c1e6fe59a9f9bc98ba22fa159ffd285805","price":"0.99","side":"SELL","size":"97895.02"}],"timestamp":"1785121832760"},"payload_hash":"2cdf9876cbe72a20b00f75a7fda694286c9e185f2606f11782a6762f3df00e45","raw_frame":"{\"market\":\"0x717c0e8ccd4d5c7040185188fbae28be901ca589a11a94b1b38ca36a79eccfeb\", \"price_changes\":[{\"asset_id\":\"24254094493625419915756280046002869097156693848522361803041977572204227262166\", \"price\":\"0.01\", \"size\":\"97895.02\", \"side\":\"BUY\", \"hash\":\"719b8c72487743ddaa2e3b56495d6b3525ce6a9a\", \"best_bid\":\"0.52\", \"best_ask\":\"0.53\"}, {\"asset_id\":\"41448400836309843603620980831210604935021861034693225347475867885462478926555\", \"price\":\"0.99\", \"size\":\"97895.02\", \"side\":\"SELL\", \"hash\":\"45d786c1e6fe59a9f9bc98ba22fa159ffd285805\", \"best_bid\":\"0.47\", \"best_ask\":\"0.48\"}], \"timestamp\":\"1785121832760\", \"event_type\":\"price_change\"}","received_at":"2026-07-27T03:10:32.667652Z","schema_version":"clob-market-ws.price_change.v1","sequence":null,"server_hash":null,"server_timestamp":"1785121832760","session_id":"dd162b8dca5f43ff811d304e69a06123","source":"clob_market_ws"},"received_at":"2026-07-27T03:10:32.667652Z","record_id":"64e7cf53d9385fa035eb4c2ca38da22ecca76260d3149889b87c3c24e053c318","schema_fingerprint":"4aa3821a28b0b7c2400bc59aba4bcc0a76e971dadd19610d3ad38c768e124dc7","schema_version":"edge-lab-recorder.raw.v1","sequence":null,"source":"clob_market_ws"}
{"event_at":null,"event_fingerprint":"87665a1d4ef7196f94366970360d70375d5e081936b0881da69850813a6c0273","payload":{"connection_id":"c7dc2e4762f849c6b6f9306b6518dcab","detail":{"interval_seconds":10.0,"message":"PING"},"event_type":"heartbeat","kind":"lifecycle","monotonic_ns":223818104538916,"received_at":"2026-07-27T03:10:34.774589Z","schema_version":"edge-lab-recorder.lifecycle.v1","session_id":"dd162b8dca5f43ff811d304e69a06123","source":"clob_market_ws"},"received_at":"2026-07-27T03:10:34.774589Z","record_id":"94f0e08ab03ad13cb579e3df0c236c47abd204b1fc84e4d7ddeb0c1e21793226","schema_fingerprint":"cb8aa3aa4cb168a4b724fd9077bee6ecfb9bc586c57cfdf0ab89f00d82045e3c","schema_version":"edge-lab-recorder.raw.v1","sequence":null,"source":"clob_market_ws"}
{"event_at":null,"event_fingerprint":"ef0e7357a86c989aaa9cf0af652b9c832fef35be542ed0027766067b78252fde","payload":{"connection_id":"c7dc2e4762f849c6b6f9306b6518dcab","event_type":"heartbeat_ack","frame_hash":"95784973cc639977bff93619700168505cb8f7855e44fa643d34622a43706c87","kind":"lifecycle","monotonic_ns":223818307881916,"raw_frame":"PONG","received_at":"2026-07-27T03:10:34.977931Z","schema_version":"edge-lab-recorder.heartbeat-ack.v1","session_id":"dd162b8dca5f43ff811d304e69a06123","source":"clob_market_ws"},"received_at":"2026-07-27T03:10:34.977931Z","record_id":"feb8af475ae1bc5058c8a305c0204e6f571c1b29da19677a6358353202c48ac1","schema_fingerprint":"c14ee1aab3ca674ee738e5268877b544d74c41ad3c427cedc09236467dc68ba1","schema_version":"edge-lab-recorder.raw.v1","sequence":null,"source":"clob_market_ws"}
{"event_at":null,"event_fingerprint":"cc1c81e9325fcdc908c43e857fcf4ab74d37dc289265e6053d21e38159190153","payload":{"connection_id":"c7dc2e4762f849c6b6f9306b6518dcab","detail":{"interval_seconds":10.0,"message":"PING"},"event_type":"heartbeat","kind":"lifecycle","monotonic_ns":223828110093916,"received_at":"2026-07-27T03:10:44.780004Z","schema_version":"edge-lab-recorder.lifecycle.v1","session_id":"dd162b8dca5f43ff811d304e69a06123","source":"clob_market_ws"},"received_at":"2026-07-27T03:10:44.780004Z","record_id":"61772da23fbe3364f49d22f1f731093b5bccc3e0e4c46226a3ee61ba5c1364a4","schema_fingerprint":"cb8aa3aa4cb168a4b724fd9077bee6ecfb9bc586c57cfdf0ab89f00d82045e3c","schema_version":"edge-lab-recorder.raw.v1","sequence":null,"source":"clob_market_ws"}
{"event_at":null,"event_fingerprint":"b4ccb7721b23537d6bb8c7145be4ffe95627a8379e3c8ce674657c40a80522e3","payload":{"connection_id":"c7dc2e4762f849c6b6f9306b6518dcab","event_type":"heartbeat_ack","frame_hash":"95784973cc639977bff93619700168505cb8f7855e44fa643d34622a43706c87","kind":"lifecycle","monotonic_ns":223828312709041,"raw_frame":"PONG","received_at":"2026-07-27T03:10:44.982617Z","schema_version":"edge-lab-recorder.heartbeat-ack.v1","session_id":"dd162b8dca5f43ff811d304e69a06123","source":"clob_market_ws"},"received_at":"2026-07-27T03:10:44.982617Z","record_id":"1d4012819b86aafae1867307b4c7ba3b22bfdce3b1625a0115e7e95727dac8e7","schema_fingerprint":"c14ee1aab3ca674ee738e5268877b544d74c41ad3c427cedc09236467dc68ba1","schema_version":"edge-lab-recorder.raw.v1","sequence":null,"source":"clob_market_ws"}
{"event_at":"2026-07-27T03:10:50.979000Z","event_fingerprint":"b8e335585995b2f89c2ed13b6a3945940acc8db296be02d2098337b1f62c20a6","payload":{"connection_id":"c7dc2e4762f849c6b6f9306b6518dcab","event_at":"2026-07-27T03:10:50.979000Z","event_type":"price_change","frame_hash":"64a22a15792ea1ae3cd1eeda8e0026fe275d79ed109a4b0f150c52d5a8cd92b7","frame_index":0,"kind":"data","monotonic_ns":223834216710208,"payload":{"event_type":"price_change","market":"0x717c0e8ccd4d5c7040185188fbae28be901ca589a11a94b1b38ca36a79eccfeb","price_changes":[{"asset_id":"24254094493625419915756280046002869097156693848522361803041977572204227262166","best_ask":"0.53","best_bid":"0.52","hash":"4450f4701ecb059601188a6264df78d34b6f163b","price":"0.01","side":"BUY","size":"97900.02"},{"asset_id":"41448400836309843603620980831210604935021861034693225347475867885462478926555","best_ask":"0.48","best_bid":"0.47","hash":"4634490f9486636dc2d55ae0a447f32df763ed3c","price":"0.99","side":"SELL","size":"97900.02"}],"timestamp":"1785121850979"},"payload_hash":"73eec709b5a47aa684de73d214b859894bbb8a503b74d7ba38847a3024ead1ce","raw_frame":"{\"market\":\"0x717c0e8ccd4d5c7040185188fbae28be901ca589a11a94b1b38ca36a79eccfeb\", \"price_changes\":[{\"asset_id\":\"24254094493625419915756280046002869097156693848522361803041977572204227262166\", \"price\":\"0.01\", \"size\":\"97900.02\", \"side\":\"BUY\", \"hash\":\"4450f4701ecb059601188a6264df78d34b6f163b\", \"best_bid\":\"0.52\", \"best_ask\":\"0.53\"}, {\"asset_id\":\"41448400836309843603620980831210604935021861034693225347475867885462478926555\", \"price\":\"0.99\", \"size\":\"97900.02\", \"side\":\"SELL\", \"hash\":\"4634490f9486636dc2d55ae0a447f32df763ed3c\", \"best_bid\":\"0.47\", \"best_ask\":\"0.48\"}], \"timestamp\":\"1785121850979\", \"event_type\":\"price_change\"}","received_at":"2026-07-27T03:10:50.886537Z","schema_version":"clob-market-ws.price_change.v1","sequence":null,"server_hash":null,"server_timestamp":"1785121850979","session_id":"dd162b8dca5f43ff811d304e69a06123","source":"clob_market_ws"},"received_at":"2026-07-27T03:10:50.886537Z","record_id":"8e679f051f1f90cdfee4a75174d99be230495b8eb691f6625000a7869b8877cc","schema_fingerprint":"4aa3821a28b0b7c2400bc59aba4bcc0a76e971dadd19610d3ad38c768e124dc7","schema_version":"edge-lab-recorder.raw.v1","sequence":null,"source":"clob_market_ws"}
{"event_at":"2026-07-27T03:10:51.775000Z","event_fingerprint":"b793df9600866d37c53417445a3dc84d29a2b9ee183ee3aadb6ad82c4ad56ac7","payload":{"connection_id":"c7dc2e4762f849c6b6f9306b6518dcab","event_at":"2026-07-27T03:10:51.775000Z","event_type":"price_change","frame_hash":"ae5a8b9b651493357f38ddae0ff45395b93dd35b8768cdf2ef13779777950ab7","frame_index":0,"kind":"data","monotonic_ns":223835010661583,"payload":{"event_type":"price_change","market":"0x717c0e8ccd4d5c7040185188fbae28be901ca589a11a94b1b38ca36a79eccfeb","price_changes":[{"asset_id":"24254094493625419915756280046002869097156693848522361803041977572204227262166","best_ask":"0.53","best_bid":"0.52","hash":"ed2b2f8c60102f9a869c8dfb4cd493036c7e24a5","price":"0.01","side":"BUY","size":"97895.02"},{"asset_id":"41448400836309843603620980831210604935021861034693225347475867885462478926555","best_ask":"0.48","best_bid":"0.47","hash":"d5e8606926070a8c1d3c599330c860ab6f601714","price":"0.99","side":"SELL","size":"97895.02"}],"timestamp":"1785121851775"},"payload_hash":"d8755addd8107768b7d4617cd1f66c53746afedda4e5eb0ba30ea67c5d3b835e","raw_frame":"{\"market\":\"0x717c0e8ccd4d5c7040185188fbae28be901ca589a11a94b1b38ca36a79eccfeb\", \"price_changes\":[{\"asset_id\":\"24254094493625419915756280046002869097156693848522361803041977572204227262166\", \"price\":\"0.01\", \"size\":\"97895.02\", \"side\":\"BUY\", \"hash\":\"ed2b2f8c60102f9a869c8dfb4cd493036c7e24a5\", \"best_bid\":\"0.52\", \"best_ask\":\"0.53\"}, {\"asset_id\":\"41448400836309843603620980831210604935021861034693225347475867885462478926555\", \"price\":\"0.99\", \"size\":\"97895.02\", \"side\":\"SELL\", \"hash\":\"d5e8606926070a8c1d3c599330c860ab6f601714\", \"best_bid\":\"0.47\", \"best_ask\":\"0.48\"}], \"timestamp\":\"1785121851775\", \"event_type\":\"price_change\"}","received_at":"2026-07-27T03:10:51.680484Z","schema_version":"clob-market-ws.price_change.v1","sequence":null,"server_hash":null,"server_timestamp":"1785121851775","session_id":"dd162b8dca5f43ff811d304e69a06123","source":"clob_market_ws"},"received_at":"2026-07-27T03:10:51.680484Z","record_id":"ee8508510698bcf7967f214d350b80d8896106c8e5d10fac7a6d11984745bcb3","schema_fingerprint":"4aa3821a28b0b7c2400bc59aba4bcc0a76e971dadd19610d3ad38c768e124dc7","schema_version":"edge-lab-recorder.raw.v1","sequence":null,"source":"clob_market_ws"}
{"event_at":null,"event_fingerprint":"ae718fbeba6cab9f23798fdeb661bea78e211b9a179e59950bb611f4be36519f","payload":{"connection_id":"c7dc2e4762f849c6b6f9306b6518dcab","detail":{"interval_seconds":10.0,"message":"PING"},"event_type":"heartbeat","kind":"lifecycle","monotonic_ns":223838115546583,"received_at":"2026-07-27T03:10:54.785319Z","schema_version":"edge-lab-recorder.lifecycle.v1","session_id":"dd162b8dca5f43ff811d304e69a06123","source":"clob_market_ws"},"received_at":"2026-07-27T03:10:54.785319Z","record_id":"bbe412830e65ca4bc9ea352ab405d54f5452195e19399aa1132d89f6d5e947ce","schema_fingerprint":"cb8aa3aa4cb168a4b724fd9077bee6ecfb9bc586c57cfdf0ab89f00d82045e3c","schema_version":"edge-lab-recorder.raw.v1","sequence":null,"source":"clob_market_ws"}
{"event_at":null,"event_fingerprint":"c89d7482714956f06488e3f3fec2d467db6564349d4044d17acb9b8f0c123061","payload":{"connection_id":"c7dc2e4762f849c6b6f9306b6518dcab","event_type":"heartbeat_ack","frame_hash":"95784973cc639977bff93619700168505cb8f7855e44fa643d34622a43706c87","kind":"lifecycle","monotonic_ns":223838319647583,"raw_frame":"PONG","received_at":"2026-07-27T03:10:54.989417Z","schema_version":"edge-lab-recorder.heartbeat-ack.v1","session_id":"dd162b8dca5f43ff811d304e69a06123","source":"clob_market_ws"},"received_at":"2026-07-27T03:10:54.989417Z","record_id":"ed3ef45b601ed60bd35e1054aaa1e3a52f811420b8eb480416db8edf9dee8d70","schema_fingerprint":"c14ee1aab3ca674ee738e5268877b544d74c41ad3c427cedc09236467dc68ba1","schema_version":"edge-lab-recorder.raw.v1","sequence":null,"source":"clob_market_ws"}
{"event_at":"2026-07-27T03:10:59.582000Z","event_fingerprint":"65854167d84d1a402543ce44b72b43a2b2de98c25122222b57cbb4de699c059d","payload":{"connection_id":"c7dc2e4762f849c6b6f9306b6518dcab","event_at":"2026-07-27T03:10:59.582000Z","event_type":"price_change","frame_hash":"3650b8e0b6be8ef0eb62eb2919f88dab35fb927d4711283b37245062674d9ccf","frame_index":0,"kind":"data","monotonic_ns":223842819961958,"payload":{"event_type":"price_change","market":"0x717c0e8ccd4d5c7040185188fbae28be901ca589a11a94b1b38ca36a79eccfeb","price_changes":[{"asset_id":"41448400836309843603620980831210604935021861034693225347475867885462478926555","best_ask":"0.48","best_bid":"0.47","hash":"3d687087e0e9ea051aea08f407600da2e5a633ec","price":"0.45","side":"BUY","size":"215.33"},{"asset_id":"24254094493625419915756280046002869097156693848522361803041977572204227262166","best_ask":"0.53","best_bid":"0.52","hash":"4b98d5488b8ad038b126f8f6bad45c0ba60983f2","price":"0.55","side":"SELL","size":"215.33"}],"timestamp":"1785121859582"},"payload_hash":"ef05336a4a7c63c1b78b2634e505f9abbe6a9d2379fa006a43545078e22478c2","raw_frame":"{\"market\":\"0x717c0e8ccd4d5c7040185188fbae28be901ca589a11a94b1b38ca36a79eccfeb\", \"price_changes\":[{\"asset_id\":\"41448400836309843603620980831210604935021861034693225347475867885462478926555\", \"price\":\"0.45\", \"size\":\"215.33\", \"side\":\"BUY\", \"hash\":\"3d687087e0e9ea051aea08f407600da2e5a633ec\", \"best_bid\":\"0.47\", \"best_ask\":\"0.48\"}, {\"asset_id\":\"24254094493625419915756280046002869097156693848522361803041977572204227262166\", \"price\":\"0.55\", \"size\":\"215.33\", \"side\":\"SELL\", \"hash\":\"4b98d5488b8ad038b126f8f6bad45c0ba60983f2\", \"best_bid\":\"0.52\", \"best_ask\":\"0.53\"}], \"timestamp\":\"1785121859582\", \"event_type\":\"price_change\"}","received_at":"2026-07-27T03:10:59.489670Z","schema_version":"clob-market-ws.price_change.v1","sequence":null,"server_hash":null,"server_timestamp":"1785121859582","session_id":"dd162b8dca5f43ff811d304e69a06123","source":"clob_market_ws"},"received_at":"2026-07-27T03:10:59.489670Z","record_id":"6a201a601c10652027f70c1a271b422fed9cbeb2ee4ad2ca915387e6d96abdfe","schema_fingerprint":"4aa3821a28b0b7c2400bc59aba4bcc0a76e971dadd19610d3ad38c768e124dc7","schema_version":"edge-lab-recorder.raw.v1","sequence":null,"source":"clob_market_ws"}
{"event_at":"2026-07-27T03:10:59.582000Z","event_fingerprint":"45c848a612d90402d98d0718012690e865cbf6457a586d03fb403a01e6de9e92","payload":{"connection_id":"c7dc2e4762f849c6b6f9306b6518dcab","event_at":"2026-07-27T03:10:59.582000Z","event_type":"price_change","frame_hash":"725cbd2266c3ea4a788f1c31f0555affd876a3af62241ba5e9107bf2add4bc11","frame_index":0,"kind":"data","monotonic_ns":223842925885000,"payload":{"event_type":"price_change","market":"0x717c0e8ccd4d5c7040185188fbae28be901ca589a11a94b1b38ca36a79eccfeb","price_changes":[{"asset_id":"41448400836309843603620980831210604935021861034693225347475867885462478926555","best_ask":"0.48","best_bid":"0.47","hash":"3d687087e0e9ea051aea08f407600da2e5a633ec","price":"0.28","side":"BUY","size":"165"},{"asset_id":"24254094493625419915756280046002869097156693848522361803041977572204227262166","best_ask":"0.53","best_bid":"0.52","hash":"4b98d5488b8ad038b126f8f6bad45c0ba60983f2","price":"0.72","side":"SELL","size":"165"}],"timestamp":"1785121859582"},"payload_hash":"5bf4e98c15b989e657261a1bdfcf7b9db389dafb6dc4e7aba290ad9595e8da2c","raw_frame":"{\"market\":\"0x717c0e8ccd4d5c7040185188fbae28be901ca589a11a94b1b38ca36a79eccfeb\", \"price_changes\":[{\"asset_id\":\"41448400836309843603620980831210604935021861034693225347475867885462478926555\", \"price\":\"0.28\", \"size\":\"165\", \"side\":\"BUY\", \"hash\":\"3d687087e0e9ea051aea08f407600da2e5a633ec\", \"best_bid\":\"0.47\", \"best_ask\":\"0.48\"}, {\"asset_id\":\"24254094493625419915756280046002869097156693848522361803041977572204227262166\", \"price\":\"0.72\", \"size\":\"165\", \"side\":\"SELL\", \"hash\":\"4b98d5488b8ad038b126f8f6bad45c0ba60983f2\", \"best_bid\":\"0.52\", \"best_ask\":\"0.53\"}], \"timestamp\":\"1785121859582\", \"event_type\":\"price_change\"}","received_at":"2026-07-27T03:10:59.595589Z","schema_version":"clob-market-ws.price_change.v1","sequence":null,"server_hash":null,"server_timestamp":"1785121859582","session_id":"dd162b8dca5f43ff811d304e69a06123","source":"clob_market_ws"},"received_at":"2026-07-27T03:10:59.595589Z","record_id":"bdddf1923e084fb5afc63611c266fa3e8126ffca81ef74ad5c84be1db2c43b0b","schema_fingerprint":"4aa3821a28b0b7c2400bc59aba4bcc0a76e971dadd19610d3ad38c768e124dc7","schema_version":"edge-lab-recorder.raw.v1","sequence":null,"source":"clob_market_ws"}
{"event_at":"2026-07-27T03:10:59.582000Z","event_fingerprint":"773512c20979f5c05fb807a868726a5e7c00dfe788f064695a3abd6d1a03e62d","payload":{"connection_id":"c7dc2e4762f849c6b6f9306b6518dcab","event_at":"2026-07-27T03:10:59.582000Z","event_type":"price_change","frame_hash":"a7bf0fa5f239d69b5f2f4bce261942197b0e74bc4a02d2cf85109ea36e610671","frame_index":0,"kind":"data","monotonic_ns":223842928298583,"payload":{"event_type":"price_change","market":"0x717c0e8ccd4d5c7040185188fbae28be901ca589a11a94b1b38ca36a79eccfeb","price_changes":[{"asset_id":"24254094493625419915756280046002869097156693848522361803041977572204227262166","best_ask":"0.53","best_bid":"0.52","hash":"4b98d5488b8ad038b126f8f6bad45c0ba60983f2","price":"0.22","side":"BUY","size":"25"},{"asset_id":"41448400836309843603620980831210604935021861034693225347475867885462478926555","best_ask":"0.48","best_bid":"0.47","hash":"3d687087e0e9ea051aea08f407600da2e5a633ec","price":"0.78","side":"SELL","size":"25"}],"timestamp":"1785121859582"},"payload_hash":"df3d1596a03fedbc753456a23366596984346b09662cdb70c5a103fa7f604e53","raw_frame":"{\"market\":\"0x717c0e8ccd4d5c7040185188fbae28be901ca589a11a94b1b38ca36a79eccfeb\", \"price_changes\":[{\"asset_id\":\"24254094493625419915756280046002869097156693848522361803041977572204227262166\", \"price\":\"0.22\", \"size\":\"25\", \"side\":\"BUY\", \"hash\":\"4b98d5488b8ad038b126f8f6bad45c0ba60983f2\", \"best_bid\":\"0.52\", \"best_ask\":\"0.53\"}, {\"asset_id\":\"41448400836309843603620980831210604935021861034693225347475867885462478926555\", \"price\":\"0.78\", \"size\":\"25\", \"side\":\"SELL\", \"hash\":\"3d687087e0e9ea051aea08f407600da2e5a633ec\", \"best_bid\":\"0.47\", \"best_ask\":\"0.48\"}], \"timestamp\":\"1785121859582\", \"event_type\":\"price_change\"}","received_at":"2026-07-27T03:10:59.598005Z","schema_version":"clob-market-ws.price_change.v1","sequence":null,"server_hash":null,"server_timestamp":"1785121859582","session_id":"dd162b8dca5f43ff811d304e69a06123","source":"clob_market_ws"},"received_at":"2026-07-27T03:10:59.598005Z","record_id":"1c976f5d519a50a9568d69ce6eb09620db9f4958fdd8b65be2c472fd6566a77e","schema_fingerprint":"4aa3821a28b0b7c2400bc59aba4bcc0a76e971dadd19610d3ad38c768e124dc7","schema_version":"edge-lab-recorder.raw.v1","sequence":null,"source":"clob_market_ws"}
{"event_at":"2026-07-27T03:10:59.582000Z","event_fingerprint":"904c4c50fa1d8492831ca79fb1bb06b7e0302a58db8cf70380bc8f662999a616","payload":{"connection_id":"c7dc2e4762f849c6b6f9306b6518dcab","event_at":"2026-07-27T03:10:59.582000Z","event_type":"price_change","frame_hash":"435f35841e9910f46fea68161b1da617d422ca10d4c53e8c48fd288b9a3fb9ee","frame_index":0,"kind":"data","monotonic_ns":223842930643250,"payload":{"event_type":"price_change","market":"0x717c0e8ccd4d5c7040185188fbae28be901ca589a11a94b1b38ca36a79eccfeb","price_changes":[{"asset_id":"24254094493625419915756280046002869097156693848522361803041977572204227262166","best_ask":"0.53","best_bid":"0.52","hash":"4b98d5488b8ad038b126f8f6bad45c0ba60983f2","price":"0.42","side":"BUY","size":"22"},{"asset_id":"41448400836309843603620980831210604935021861034693225347475867885462478926555","best_ask":"0.48","best_bid":"0.47","hash":"3d687087e0e9ea051aea08f407600da2e5a633ec","price":"0.58","side":"SELL","size":"22"}],"timestamp":"1785121859582"},"payload_hash":"69f4a468687e8be0ad82829046e0130f024711cf0b54b5152df2cfa3e33aa59a","raw_frame":"{\"market\":\"0x717c0e8ccd4d5c7040185188fbae28be901ca589a11a94b1b38ca36a79eccfeb\", \"price_changes\":[{\"asset_id\":\"24254094493625419915756280046002869097156693848522361803041977572204227262166\", \"price\":\"0.42\", \"size\":\"22\", \"side\":\"BUY\", \"hash\":\"4b98d5488b8ad038b126f8f6bad45c0ba60983f2\", \"best_bid\":\"0.52\", \"best_ask\":\"0.53\"}, {\"asset_id\":\"41448400836309843603620980831210604935021861034693225347475867885462478926555\", \"price\":\"0.58\", \"size\":\"22\", \"side\":\"SELL\", \"hash\":\"3d687087e0e9ea051aea08f407600da2e5a633ec\", \"best_bid\":\"0.47\", \"best_ask\":\"0.48\"}], \"timestamp\":\"1785121859582\", \"event_type\":\"price_change\"}","received_at":"2026-07-27T03:10:59.600340Z","schema_version":"clob-market-ws.price_change.v1","sequence":null,"server_hash":null,"server_timestamp":"1785121859582","session_id":"dd162b8dca5f43ff811d304e69a06123","source":"clob_market_ws"},"received_at":"2026-07-27T03:10:59.600340Z","record_id":"48475a815a1db32b51c367af661f729dc4431047db8fafb40273f8efa7b77c56","schema_fingerprint":"4aa3821a28b0b7c2400bc59aba4bcc0a76e971dadd19610d3ad38c768e124dc7","schema_version":"edge-lab-recorder.raw.v1","sequence":null,"source":"clob_market_ws"}
{"event_at":"2026-07-27T03:10:59.582000Z","event_fingerprint":"3f203700ac696b3894210d93f6fb1de114e20667fde6fc123503eb31c8b0fea3","payload":{"connection_id":"c7dc2e4762f849c6b6f9306b6518dcab","event_at":"2026-07-27T03:10:59.582000Z","event_type":"price_change","frame_hash":"751f40ec3e8dd4ff0b2134bff654fa09bf807152a6be8d825e29e1657bf20e2b","frame_index":0,"kind":"data","monotonic_ns":223842933246958,"payload":{"event_type":"price_change","market":"0x717c0e8ccd4d5c7040185188fbae28be901ca589a11a94b1b38ca36a79eccfeb","price_changes":[{"asset_id":"41448400836309843603620980831210604935021861034693225347475867885462478926555","best_ask":"0.48","best_bid":"0.47","hash":"3d687087e0e9ea051aea08f407600da2e5a633ec","price":"0.47","side":"BUY","size":"319.67"},{"asset_id":"24254094493625419915756280046002869097156693848522361803041977572204227262166","best_ask":"0.53","best_bid":"0.52","hash":"4b98d5488b8ad038b126f8f6bad45c0ba60983f2","price":"0.53","side":"SELL","size":"319.67"}],"timestamp":"1785121859582"},"payload_hash":"08bfc330d62224590703c339f7097d23ec41f788cbc28f594c18f668cd184be3","raw_frame":"{\"market\":\"0x717c0e8ccd4d5c7040185188fbae28be901ca589a11a94b1b38ca36a79eccfeb\", \"price_changes\":[{\"asset_id\":\"41448400836309843603620980831210604935021861034693225347475867885462478926555\", \"price\":\"0.47\", \"size\":\"319.67\", \"side\":\"BUY\", \"hash\":\"3d687087e0e9ea051aea08f407600da2e5a633ec\", \"best_bid\":\"0.47\", \"best_ask\":\"0.48\"}, {\"asset_id\":\"24254094493625419915756280046002869097156693848522361803041977572204227262166\", \"price\":\"0.53\", \"size\":\"319.67\", \"side\":\"SELL\", \"hash\":\"4b98d5488b8ad038b126f8f6bad45c0ba60983f2\", \"best_bid\":\"0.52\", \"best_ask\":\"0.53\"}], \"timestamp\":\"1785121859582\", \"event_type\":\"price_change\"}","received_at":"2026-07-27T03:10:59.602953Z","schema_version":"clob-market-ws.price_change.v1","sequence":null,"server_hash":null,"server_timestamp":"1785121859582","session_id":"dd162b8dca5f43ff811d304e69a06123","source":"clob_market_ws"},"received_at":"2026-07-27T03:10:59.602953Z","record_id":"042bdc1789e7c961cc4b17ae5a04a09952899179fdf6aeb71f159835182fc0c2","schema_fingerprint":"4aa3821a28b0b7c2400bc59aba4bcc0a76e971dadd19610d3ad38c768e124dc7","schema_version":"edge-lab-recorder.raw.v1","sequence":null,"source":"clob_market_ws"}
{"event_at":"2026-07-27T03:10:59.582000Z","event_fingerprint":"16ff6272b7f7ff4009836b0c6422b92eaa142befc026bd5c4edb7fdcd4e29bca","payload":{"connection_id":"c7dc2e4762f849c6b6f9306b6518dcab","event_at":"2026-07-27T03:10:59.582000Z","event_type":"price_change","frame_hash":"b6f594197d8141f5849b04034bc7d258b29b68dc3891fbff162f3f8e3a32c18a","frame_index":0,"kind":"data","monotonic_ns":223842936304000,"payload":{"event_type":"price_change","market":"0x717c0e8ccd4d5c7040185188fbae28be901ca589a11a94b1b38ca36a79eccfeb","price_changes":[{"asset_id":"41448400836309843603620980831210604935021861034693225347475867885462478926555","best_ask":"0.48","best_bid":"0.47","hash":"3d687087e0e9ea051aea08f407600da2e5a633ec","price":"0.18","side":"BUY","size":"30"},{"asset_id":"24254094493625419915756280046002869097156693848522361803041977572204227262166","best_ask":"0.53","best_bid":"0.52","hash":"4b98d5488b8ad038b126f8f6bad45c0ba60983f2","price":"0.82","side":"SELL","size":"30"}],"timestamp":"1785121859582"},"payload_hash":"08aab3ab5b107ab33193dc768a383cfe4bc848643a3f3f2767e668992dde1700","raw_frame":"{\"market\":\"0x717c0e8ccd4d5c7040185188fbae28be901ca589a11a94b1b38ca36a79eccfeb\", \"price_changes\":[{\"asset_id\":\"41448400836309843603620980831210604935021861034693225347475867885462478926555\", \"price\":\"0.18\", \"size\":\"30\", \"side\":\"BUY\", \"hash\":\"3d687087e0e9ea051aea08f407600da2e5a633ec\", \"best_bid\":\"0.47\", \"best_ask\":\"0.48\"}, {\"asset_id\":\"24254094493625419915756280046002869097156693848522361803041977572204227262166\", \"price\":\"0.82\", \"size\":\"30\", \"side\":\"SELL\", \"hash\":\"4b98d5488b8ad038b126f8f6bad45c0ba60983f2\", \"best_bid\":\"0.52\", \"best_ask\":\"0.53\"}], \"timestamp\":\"1785121859582\", \"event_type\":\"price_change\"}","received_at":"2026-07-27T03:10:59.606010Z","schema_version":"clob-market-ws.price_change.v1","sequence":null,"server_hash":null,"server_timestamp":"1785121859582","session_id":"dd162b8dca5f43ff811d304e69a06123","source":"clob_market_ws"},"received_at":"2026-07-27T03:10:59.606010Z","record_id":"121d83eb21c4ee4722a4cc98b9a42c3395483dc81085713847496b430dba3465","schema_fingerprint":"4aa3821a28b0b7c2400bc59aba4bcc0a76e971dadd19610d3ad38c768e124dc7","schema_version":"edge-lab-recorder.raw.v1","sequence":null,"source":"clob_market_ws"}
{"event_at":"2026-07-27T03:10:59.582000Z","event_fingerprint":"3df251b7bf2cc23063bda255c0e210e61cfe7e890466cf7640075ef285bfe242","payload":{"connection_id":"c7dc2e4762f849c6b6f9306b6518dcab","event_at":"2026-07-27T03:10:59.582000Z","event_type":"price_change","frame_hash":"9a060e69be114bda17f090a82af550d58f085201fe06b53a9e406e20f083aaad","frame_index":0,"kind":"data","monotonic_ns":223842939267833,"payload":{"event_type":"price_change","market":"0x717c0e8ccd4d5c7040185188fbae28be901ca589a11a94b1b38ca36a79eccfeb","price_changes":[{"asset_id":"24254094493625419915756280046002869097156693848522361803041977572204227262166","best_ask":"0.53","best_bid":"0.52","hash":"4b98d5488b8ad038b126f8f6bad45c0ba60983f2","price":"0.12","side":"BUY","size":"40"},{"asset_id":"41448400836309843603620980831210604935021861034693225347475867885462478926555","best_ask":"0.48","best_bid":"0.47","hash":"3d687087e0e9ea051aea08f407600da2e5a633ec","price":"0.88","side":"SELL","size":"40"}],"timestamp":"1785121859582"},"payload_hash":"f32869f0527d519b34a0196d1c020ac41370d53851b0c8cefb5aaaed59d4ec57","raw_frame":"{\"market\":\"0x717c0e8ccd4d5c7040185188fbae28be901ca589a11a94b1b38ca36a79eccfeb\", \"price_changes\":[{\"asset_id\":\"24254094493625419915756280046002869097156693848522361803041977572204227262166\", \"price\":\"0.12\", \"size\":\"40\", \"side\":\"BUY\", \"hash\":\"4b98d5488b8ad038b126f8f6bad45c0ba60983f2\", \"best_bid\":\"0.52\", \"best_ask\":\"0.53\"}, {\"asset_id\":\"41448400836309843603620980831210604935021861034693225347475867885462478926555\", \"price\":\"0.88\", \"size\":\"40\", \"side\":\"SELL\", \"hash\":\"3d687087e0e9ea051aea08f407600da2e5a633ec\", \"best_bid\":\"0.47\", \"best_ask\":\"0.48\"}], \"timestamp\":\"1785121859582\", \"event_type\":\"price_change\"}","received_at":"2026-07-27T03:10:59.608974Z","schema_version":"clob-market-ws.price_change.v1","sequence":null,"server_hash":null,"server_timestamp":"1785121859582","session_id":"dd162b8dca5f43ff811d304e69a06123","source":"clob_market_ws"},"received_at":"2026-07-27T03:10:59.608974Z","record_id":"6596e0eef0b7f56bef30226928f5bbd5c7abf355bdc1897100a2f9160619e0e0","schema_fingerprint":"4aa3821a28b0b7c2400bc59aba4bcc0a76e971dadd19610d3ad38c768e124dc7","schema_version":"edge-lab-recorder.raw.v1","sequence":null,"source":"clob_market_ws"}
{"event_at":"2026-07-27T03:10:59.582000Z","event_fingerprint":"c3ddf2c2471afdbe9a2f33bac71ad47e48121439d578521600fd38a42d9db1f5","payload":{"connection_id":"c7dc2e4762f849c6b6f9306b6518dcab","event_at":"2026-07-27T03:10:59.582000Z","event_type":"price_change","frame_hash":"48c7e26ef37a1e134835df2a00be11a646a26f06a1132e721f0c785c0c38d15f","frame_index":0,"kind":"data","monotonic_ns":223842943790041,"payload":{"event_type":"price_change","market":"0x717c0e8ccd4d5c7040185188fbae28be901ca589a11a94b1b38ca36a79eccfeb","price_changes":[{"asset_id":"24254094493625419915756280046002869097156693848522361803041977572204227262166","best_ask":"0.53","best_bid":"0.52","hash":"4b98d5488b8ad038b126f8f6bad45c0ba60983f2","price":"0.49","side":"BUY","size":"255"},{"asset_id":"41448400836309843603620980831210604935021861034693225347475867885462478926555","best_ask":"0.48","best_bid":"0.47","hash":"3d687087e0e9ea051aea08f407600da2e5a633ec","price":"0.51","side":"SELL","size":"255"}],"timestamp":"1785121859582"},"payload_hash":"4625191bd79c2fd5cc051dcd176a1f6b8d1b32a38589f1d8e056a2e1bdac3e5d","raw_frame":"{\"market\":\"0x717c0e8ccd4d5c7040185188fbae28be901ca589a11a94b1b38ca36a79eccfeb\", \"price_changes\":[{\"asset_id\":\"24254094493625419915756280046002869097156693848522361803041977572204227262166\", \"price\":\"0.49\", \"size\":\"255\", \"side\":\"BUY\", \"hash\":\"4b98d5488b8ad038b126f8f6bad45c0ba60983f2\", \"best_bid\":\"0.52\", \"best_ask\":\"0.53\"}, {\"asset_id\":\"41448400836309843603620980831210604935021861034693225347475867885462478926555\", \"price\":\"0.51\", \"size\":\"255\", \"side\":\"SELL\", \"hash\":\"3d687087e0e9ea051aea08f407600da2e5a633ec\", \"best_bid\":\"0.47\", \"best_ask\":\"0.48\"}], \"timestamp\":\"1785121859582\", \"event_type\":\"price_change\"}","received_at":"2026-07-27T03:10:59.613489Z","schema_version":"clob-market-ws.price_change.v1","sequence":null,"server_hash":null,"server_timestamp":"1785121859582","session_id":"dd162b8dca5f43ff811d304e69a06123","source":"clob_market_ws"},"received_at":"2026-07-27T03:10:59.613489Z","record_id":"344351cf7c30ac2c1f19f12ee104f0be449389e5672139ab1ecd95258129c5ad","schema_fingerprint":"4aa3821a28b0b7c2400bc59aba4bcc0a76e971dadd19610d3ad38c768e124dc7","schema_version":"edge-lab-recorder.raw.v1","sequence":null,"source":"clob_market_ws"}
{"event_at":"2026-07-27T03:10:59.582000Z","event_fingerprint":"2805f53e2438ffae770baed032701cabacf65476934618af862df3de06455a18","payload":{"connection_id":"c7dc2e4762f849c6b6f9306b6518dcab","event_at":"2026-07-27T03:10:59.582000Z","event_type":"price_change","frame_hash":"5db41f1e128301863a4063e35b9512760b45f0c4995e1699a50b634e7478466c","frame_index":0,"kind":"data","monotonic_ns":223842948031291,"payload":{"event_type":"price_change","market":"0x717c0e8ccd4d5c7040185188fbae28be901ca589a11a94b1b38ca36a79eccfeb","price_changes":[{"asset_id":"41448400836309843603620980831210604935021861034693225347475867885462478926555","best_ask":"0.48","best_bid":"0.47","hash":"3d687087e0e9ea051aea08f407600da2e5a633ec","price":"0.38","side":"BUY","size":"265.07"},{"asset_id":"24254094493625419915756280046002869097156693848522361803041977572204227262166","best_ask":"0.53","best_bid":"0.52","hash":"4b98d5488b8ad038b126f8f6bad45c0ba60983f2","price":"0.62","side":"SELL","size":"265.07"}],"timestamp":"1785121859582"},"payload_hash":"17d7ba4a23a843303004323ccc1201a96d3e6dcf70b66b38ac640ee09f026d72","raw_frame":"{\"market\":\"0x717c0e8ccd4d5c7040185188fbae28be901ca589a11a94b1b38ca36a79eccfeb\", \"price_changes\":[{\"asset_id\":\"41448400836309843603620980831210604935021861034693225347475867885462478926555\", \"price\":\"0.38\", \"size\":\"265.07\", \"side\":\"BUY\", \"hash\":\"3d687087e0e9ea051aea08f407600da2e5a633ec\", \"best_bid\":\"0.47\", \"best_ask\":\"0.48\"}, {\"asset_id\":\"24254094493625419915756280046002869097156693848522361803041977572204227262166\", \"price\":\"0.62\", \"size\":\"265.07\", \"side\":\"SELL\", \"hash\":\"4b98d5488b8ad038b126f8f6bad45c0ba60983f2\", \"best_bid\":\"0.52\", \"best_ask\":\"0.53\"}], \"timestamp\":\"1785121859582\", \"event_type\":\"price_change\"}","received_at":"2026-07-27T03:10:59.617743Z","schema_version":"clob-market-ws.price_change.v1","sequence":null,"server_hash":null,"server_timestamp":"1785121859582","session_id":"dd162b8dca5f43ff811d304e69a06123","source":"clob_market_ws"},"received_at":"2026-07-27T03:10:59.617743Z","record_id":"debb551c27c3140b5dbddc75d770e87cab744e47c05f5bda839f7d404cd15d2c","schema_fingerprint":"4aa3821a28b0b7c2400bc59aba4bcc0a76e971dadd19610d3ad38c768e124dc7","schema_version":"edge-lab-recorder.raw.v1","sequence":null,"source":"clob_market_ws"}
{"event_at":"2026-07-27T03:10:59.582000Z","event_fingerprint":"3ced3305f4ad8b0b77d3ae8daaba5c921e5d539776b14c9c4b0fc0a8eb1bbbd0","payload":{"connection_id":"c7dc2e4762f849c6b6f9306b6518dcab","event_at":"2026-07-27T03:10:59.582000Z","event_type":"price_change","frame_hash":"f8a8621b912547041e0e84d67a7fc7e077045e6a83c3fde8964813d57e4c070c","frame_index":0,"kind":"data","monotonic_ns":223842950151208,"payload":{"event_type":"price_change","market":"0x717c0e8ccd4d5c7040185188fbae28be901ca589a11a94b1b38ca36a79eccfeb","price_changes":[{"asset_id":"24254094493625419915756280046002869097156693848522361803041977572204227262166","best_ask":"0.53","best_bid":"0.52","hash":"4b98d5488b8ad038b126f8f6bad45c0ba60983f2","price":"0.32","side":"BUY","size":"145"},{"asset_id":"41448400836309843603620980831210604935021861034693225347475867885462478926555","best_ask":"0.48","best_bid":"0.47","hash":"3d687087e0e9ea051aea08f407600da2e5a633ec","price":"0.68","side":"SELL","size":"145"}],"timestamp":"1785121859582"},"payload_hash":"b76596fd76bc487ae2bf027b07572739d3d8925880714d0f27d8da802b87e142","raw_frame":"{\"market\":\"0x717c0e8ccd4d5c7040185188fbae28be901ca589a11a94b1b38ca36a79eccfeb\", \"price_changes\":[{\"asset_id\":\"24254094493625419915756280046002869097156693848522361803041977572204227262166\", \"price\":\"0.32\", \"size\":\"145\", \"side\":\"BUY\", \"hash\":\"4b98d5488b8ad038b126f8f6bad45c0ba60983f2\", \"best_bid\":\"0.52\", \"best_ask\":\"0.53\"}, {\"asset_id\":\"41448400836309843603620980831210604935021861034693225347475867885462478926555\", \"price\":\"0.68\", \"size\":\"145\", \"side\":\"SELL\", \"hash\":\"3d687087e0e9ea051aea08f407600da2e5a633ec\", \"best_bid\":\"0.47\", \"best_ask\":\"0.48\"}], \"timestamp\":\"1785121859582\", \"event_type\":\"price_change\"}","received_at":"2026-07-27T03:10:59.619857Z","schema_version":"clob-market-ws.price_change.v1","sequence":null,"server_hash":null,"server_timestamp":"1785121859582","session_id":"dd162b8dca5f43ff811d304e69a06123","source":"clob_market_ws"},"received_at":"2026-07-27T03:10:59.619857Z","record_id":"b5596c569e01793b2a8cb4e4c1cc1be8beed96ec1ccb43217c21c9fc7540b17a","schema_fingerprint":"4aa3821a28b0b7c2400bc59aba4bcc0a76e971dadd19610d3ad38c768e124dc7","schema_version":"edge-lab-recorder.raw.v1","sequence":null,"source":"clob_market_ws"}
{"event_at":"2026-07-27T03:10:59.582000Z","event_fingerprint":"339f9807674cdf5e470899f97c72fefa9fd59482d31c69d6f4099e6b5f41a248","payload":{"connection_id":"c7dc2e4762f849c6b6f9306b6518dcab","event_at":"2026-07-27T03:10:59.582000Z","event_type":"price_change","frame_hash":"c26b6cf2521f03f81e52ec5cb62a7c59c4faa6a827a879c64da632fd9101dbe4","frame_index":0,"kind":"data","monotonic_ns":223842953221041,"payload":{"event_type":"price_change","market":"0x717c0e8ccd4d5c7040185188fbae28be901ca589a11a94b1b38ca36a79eccfeb","price_changes":[{"asset_id":"41448400836309843603620980831210604935021861034693225347475867885462478926555","best_ask":"0.48","best_bid":"0.47","hash":"3d687087e0e9ea051aea08f407600da2e5a633ec","price":"0.46","side":"BUY","size":"65.87"},{"asset_id":"24254094493625419915756280046002869097156693848522361803041977572204227262166","best_ask":"0.53","best_bid":"0.52","hash":"4b98d5488b8ad038b126f8f6bad45c0ba60983f2","price":"0.54","side":"SELL","size":"65.87"}],"timestamp":"1785121859582"},"payload_hash":"6eb656dd0afcfdead1b8e01d9619836662bb5c8405c8f43ea5e46f6db08bf335","raw_frame":"{\"market\":\"0x717c0e8ccd4d5c7040185188fbae28be901ca589a11a94b1b38ca36a79eccfeb\", \"price_changes\":[{\"asset_id\":\"41448400836309843603620980831210604935021861034693225347475867885462478926555\", \"price\":\"0.46\", \"size\":\"65.87\", \"side\":\"BUY\", \"hash\":\"3d687087e0e9ea051aea08f407600da2e5a633ec\", \"best_bid\":\"0.47\", \"best_ask\":\"0.48\"}, {\"asset_id\":\"24254094493625419915756280046002869097156693848522361803041977572204227262166\", \"price\":\"0.54\", \"size\":\"65.87\", \"side\":\"SELL\", \"hash\":\"4b98d5488b8ad038b126f8f6bad45c0ba60983f2\", \"best_bid\":\"0.52\", \"best_ask\":\"0.53\"}], \"timestamp\":\"1785121859582\", \"event_type\":\"price_change\"}","received_at":"2026-07-27T03:10:59.622926Z","schema_version":"clob-market-ws.price_change.v1","sequence":null,"server_hash":null,"server_timestamp":"1785121859582","session_id":"dd162b8dca5f43ff811d304e69a06123","source":"clob_market_ws"},"received_at":"2026-07-27T03:10:59.622926Z","record_id":"c64ca6f37636949c3b969637930101291387d08b56b96c227a7310583240f686","schema_fingerprint":"4aa3821a28b0b7c2400bc59aba4bcc0a76e971dadd19610d3ad38c768e124dc7","schema_version":"edge-lab-recorder.raw.v1","sequence":null,"source":"clob_market_ws"}
{"event_at":"2026-07-27T03:10:59.582000Z","event_fingerprint":"69a9b3f118c880eb3e535e482c8f3c3d1c13c0c9d4683f48179b297a7409fd33","payload":{"connection_id":"c7dc2e4762f849c6b6f9306b6518dcab","event_at":"2026-07-27T03:10:59.582000Z","event_type":"price_change","frame_hash":"0275c2dc94cbbcf15a695397b16c5755a2f51949ed50e7b48705f97f8465c946","frame_index":0,"kind":"data","monotonic_ns":223842957162708,"payload":{"event_type":"price_change","market":"0x717c0e8ccd4d5c7040185188fbae28be901ca589a11a94b1b38ca36a79eccfeb","price_changes":[{"asset_id":"41448400836309843603620980831210604935021861034693225347475867885462478926555","best_ask":"0.48","best_bid":"0.47","hash":"3d687087e0e9ea051aea08f407600da2e5a633ec","price":"0.08","side":"BUY","size":"646"},{"asset_id":"24254094493625419915756280046002869097156693848522361803041977572204227262166","best_ask":"0.53","best_bid":"0.52","hash":"4b98d5488b8ad038b126f8f6bad45c0ba60983f2","price":"0.92","side":"SELL","size":"646"}],"timestamp":"1785121859582"},"payload_hash":"e240dd5e29bf99d7f8705d31fa0f05e7def6072efd5ababd76650443d9590329","raw_frame":"{\"market\":\"0x717c0e8ccd4d5c7040185188fbae28be901ca589a11a94b1b38ca36a79eccfeb\", \"price_changes\":[{\"asset_id\":\"41448400836309843603620980831210604935021861034693225347475867885462478926555\", \"price\":\"0.08\", \"size\":\"646\", \"side\":\"BUY\", \"hash\":\"3d687087e0e9ea051aea08f407600da2e5a633ec\", \"best_bid\":\"0.47\", \"best_ask\":\"0.48\"}, {\"asset_id\":\"24254094493625419915756280046002869097156693848522361803041977572204227262166\", \"price\":\"0.92\", \"size\":\"646\", \"side\":\"SELL\", \"hash\":\"4b98d5488b8ad038b126f8f6bad45c0ba60983f2\", \"best_bid\":\"0.52\", \"best_ask\":\"0.53\"}], \"timestamp\":\"1785121859582\", \"event_type\":\"price_change\"}","received_at":"2026-07-27T03:10:59.626868Z","schema_version":"clob-market-ws.price_change.v1","sequence":null,"server_hash":null,"server_timestamp":"1785121859582","session_id":"dd162b8dca5f43ff811d304e69a06123","source":"clob_market_ws"},"received_at":"2026-07-27T03:10:59.626868Z","record_id":"152063f38ddd07c6fec3b0de1bf06db7cce09bbc197c8ab253aa53fdc5d85bf7","schema_fingerprint":"4aa3821a28b0b7c2400bc59aba4bcc0a76e971dadd19610d3ad38c768e124dc7","schema_version":"edge-lab-recorder.raw.v1","sequence":null,"source":"clob_market_ws"}
{"event_at":"2026-07-27T03:10:59.768000Z","event_fingerprint":"e92cfea24bce2e6f119dd70727e0f8ab7a127c73f69bcc73e81c2ef8e91fc1df","payload":{"connection_id":"c7dc2e4762f849c6b6f9306b6518dcab","event_at":"2026-07-27T03:10:59.768000Z","event_type":"price_change","frame_hash":"24d2e606394f5dc6fb1f2ea5c953fc4b9ee6ed1b0266b7d987f9e82498586b53","frame_index":0,"kind":"data","monotonic_ns":223843008806875,"payload":{"event_type":"price_change","market":"0x717c0e8ccd4d5c7040185188fbae28be901ca589a11a94b1b38ca36a79eccfeb","price_changes":[{"asset_id":"41448400836309843603620980831210604935021861034693225347475867885462478926555","best_ask":"0.48","best_bid":"0.47","hash":"ef7fa060ec3fbcf34e737448b2865e5d0933504e","price":"0.07","side":"BUY","size":"636.5"},{"asset_id":"24254094493625419915756280046002869097156693848522361803041977572204227262166","best_ask":"0.53","best_bid":"0.52","hash":"67acbd3eac1297ed9904a205d926c4a7f4111660","price":"0.93","side":"SELL","size":"636.5"}],"timestamp":"1785121859768"},"payload_hash":"c09836d5521123f5ab739a9e48993b52759ac21d2338d812f688ee1b799e8223","raw_frame":"{\"market\":\"0x717c0e8ccd4d5c7040185188fbae28be901ca589a11a94b1b38ca36a79eccfeb\", \"price_changes\":[{\"asset_id\":\"41448400836309843603620980831210604935021861034693225347475867885462478926555\", \"price\":\"0.07\", \"size\":\"636.5\", \"side\":\"BUY\", \"hash\":\"ef7fa060ec3fbcf34e737448b2865e5d0933504e\", \"best_bid\":\"0.47\", \"best_ask\":\"0.48\"}, {\"asset_id\":\"24254094493625419915756280046002869097156693848522361803041977572204227262166\", \"price\":\"0.93\", \"size\":\"636.5\", \"side\":\"SELL\", \"hash\":\"67acbd3eac1297ed9904a205d926c4a7f4111660\", \"best_bid\":\"0.52\", \"best_ask\":\"0.53\"}], \"timestamp\":\"1785121859768\", \"event_type\":\"price_change\"}","received_at":"2026-07-27T03:10:59.678511Z","schema_version":"clob-market-ws.price_change.v1","sequence":null,"server_hash":null,"server_timestamp":"1785121859768","session_id":"dd162b8dca5f43ff811d304e69a06123","source":"clob_market_ws"},"received_at":"2026-07-27T03:10:59.678511Z","record_id":"d6db2c43be72dfe48267985750a02c0d269208536913d24d9e5073dc2ccf04c1","schema_fingerprint":"4aa3821a28b0b7c2400bc59aba4bcc0a76e971dadd19610d3ad38c768e124dc7","schema_version":"edge-lab-recorder.raw.v1","sequence":null,"source":"clob_market_ws"}
{"event_at":"2026-07-27T03:10:59.768000Z","event_fingerprint":"a144bcab005bf94955395f985c1711ccef259b48be5689b40e4d6ddcf8cbd2b3","payload":{"connection_id":"c7dc2e4762f849c6b6f9306b6518dcab","event_at":"2026-07-27T03:10:59.768000Z","event_type":"price_change","frame_hash":"7f70c6c99ac735a33242cdd4b5d3df040b550a98b3de4de7055659223721b7f1","frame_index":0,"kind":"data","monotonic_ns":223843014326041,"payload":{"event_type":"price_change","market":"0x717c0e8ccd4d5c7040185188fbae28be901ca589a11a94b1b38ca36a79eccfeb","price_changes":[{"asset_id":"24254094493625419915756280046002869097156693848522361803041977572204227262166","best_ask":"0.53","best_bid":"0.52","hash":"704e84ce020e93e089de7ff54d2e3a1ec3bc8087","price":"0.43","side":"BUY","size":"182.5"},{"asset_id":"41448400836309843603620980831210604935021861034693225347475867885462478926555","best_ask":"0.48","best_bid":"0.47","hash":"0527c98de576cf7e7263a8a0cb45bab26c1bd600","price":"0.57","side":"SELL","size":"182.5"}],"timestamp":"1785121859768"},"payload_hash":"a633c4f2bf476265936b3051d9014065927945c3fb1e8e483cd6c936f5fbba30","raw_frame":"{\"market\":\"0x717c0e8ccd4d5c7040185188fbae28be901ca589a11a94b1b38ca36a79eccfeb\", \"price_changes\":[{\"asset_id\":\"24254094493625419915756280046002869097156693848522361803041977572204227262166\", \"price\":\"0.43\", \"size\":\"182.5\", \"side\":\"BUY\", \"hash\":\"704e84ce020e93e089de7ff54d2e3a1ec3bc8087\", \"best_bid\":\"0.52\", \"best_ask\":\"0.53\"}, {\"asset_id\":\"41448400836309843603620980831210604935021861034693225347475867885462478926555\", \"price\":\"0.57\", \"size\":\"182.5\", \"side\":\"SELL\", \"hash\":\"0527c98de576cf7e7263a8a0cb45bab26c1bd600\", \"best_bid\":\"0.47\", \"best_ask\":\"0.48\"}], \"timestamp\":\"1785121859768\", \"event_type\":\"price_change\"}","received_at":"2026-07-27T03:10:59.684036Z","schema_version":"clob-market-ws.price_change.v1","sequence":null,"server_hash":null,"server_timestamp":"1785121859768","session_id":"dd162b8dca5f43ff811d304e69a06123","source":"clob_market_ws"},"received_at":"2026-07-27T03:10:59.684036Z","record_id":"b6ab6d92249948b5efd18248da818a534a20d24bd072ffa25ca8827d36c301ee","schema_fingerprint":"4aa3821a28b0b7c2400bc59aba4bcc0a76e971dadd19610d3ad38c768e124dc7","schema_version":"edge-lab-recorder.raw.v1","sequence":null,"source":"clob_market_ws"}
{"event_at":"2026-07-27T03:10:59.769000Z","event_fingerprint":"037f7a746935419bdf420b55c40483b1867a2eba35d40cb88b3512cac1531c0f","payload":{"connection_id":"c7dc2e4762f849c6b6f9306b6518dcab","event_at":"2026-07-27T03:10:59.769000Z","event_type":"price_change","frame_hash":"ba8443f231e77f2583af647c39da181dd2b954ba8df56c5106a749324639923d","frame_index":0,"kind":"data","monotonic_ns":223843017134583,"payload":{"event_type":"price_change","market":"0x717c0e8ccd4d5c7040185188fbae28be901ca589a11a94b1b38ca36a79eccfeb","price_changes":[{"asset_id":"24254094493625419915756280046002869097156693848522361803041977572204227262166","best_ask":"0.53","best_bid":"0.52","hash":"5ea2eacca69dda7f4dc933da64ac937a2f22de4c","price":"0.52","side":"BUY","size":"14.61"},{"asset_id":"41448400836309843603620980831210604935021861034693225347475867885462478926555","best_ask":"0.48","best_bid":"0.47","hash":"8e0a27919a9060960f1552e3d8003215b7d320c0","price":"0.48","side":"SELL","size":"14.61"}],"timestamp":"1785121859769"},"payload_hash":"54e1853771f5a620d7bd70ab9b7d32cabc5d5ccca2729650e4aeacb8fcae2497","raw_frame":"{\"market\":\"0x717c0e8ccd4d5c7040185188fbae28be901ca589a11a94b1b38ca36a79eccfeb\", \"price_changes\":[{\"asset_id\":\"24254094493625419915756280046002869097156693848522361803041977572204227262166\", \"price\":\"0.52\", \"size\":\"14.61\", \"side\":\"BUY\", \"hash\":\"5ea2eacca69dda7f4dc933da64ac937a2f22de4c\", \"best_bid\":\"0.52\", \"best_ask\":\"0.53\"}, {\"asset_id\":\"41448400836309843603620980831210604935021861034693225347475867885462478926555\", \"price\":\"0.48\", \"size\":\"14.61\", \"side\":\"SELL\", \"hash\":\"8e0a27919a9060960f1552e3d8003215b7d320c0\", \"best_bid\":\"0.47\", \"best_ask\":\"0.48\"}], \"timestamp\":\"1785121859769\", \"event_type\":\"price_change\"}","received_at":"2026-07-27T03:10:59.686839Z","schema_version":"clob-market-ws.price_change.v1","sequence":null,"server_hash":null,"server_timestamp":"1785121859769","session_id":"dd162b8dca5f43ff811d304e69a06123","source":"clob_market_ws"},"received_at":"2026-07-27T03:10:59.686839Z","record_id":"93eed2fda581137351755eef1bd85c97a64d1aab5b5aae6529700d586f5713a5","schema_fingerprint":"4aa3821a28b0b7c2400bc59aba4bcc0a76e971dadd19610d3ad38c768e124dc7","schema_version":"edge-lab-recorder.raw.v1","sequence":null,"source":"clob_market_ws"}
{"event_at":"2026-07-27T03:10:59.770000Z","event_fingerprint":"64fb41a40582989882bcddd60fc9fb0db70851f101a91be263b11310a63ad25c","payload":{"connection_id":"c7dc2e4762f849c6b6f9306b6518dcab","event_at":"2026-07-27T03:10:59.770000Z","event_type":"price_change","frame_hash":"e49f47cd304cd53b1482a832c9539608554fd380363063673d815347234a28e7","frame_index":0,"kind":"data","monotonic_ns":223843021007291,"payload":{"event_type":"price_change","market":"0x717c0e8ccd4d5c7040185188fbae28be901ca589a11a94b1b38ca36a79eccfeb","price_changes":[{"asset_id":"41448400836309843603620980831210604935021861034693225347475867885462478926555","best_ask":"0.48","best_bid":"0.47","hash":"104edef2fdfb5f32c40e7b9e6fa938fc156aadc3","price":"0.37","side":"BUY","size":"194.12"},{"asset_id":"24254094493625419915756280046002869097156693848522361803041977572204227262166","best_ask":"0.53","best_bid":"0.52","hash":"af677de4a581524de1946b3ccc6132a92bae10cd","price":"0.63","side":"SELL","size":"194.12"}],"timestamp":"1785121859770"},"payload_hash":"ea3e90d1567fee4bde82e0e16885e363bbbe640bbd8a8d717be8f5f9eaf2967d","raw_frame":"{\"market\":\"0x717c0e8ccd4d5c7040185188fbae28be901ca589a11a94b1b38ca36a79eccfeb\", \"price_changes\":[{\"asset_id\":\"41448400836309843603620980831210604935021861034693225347475867885462478926555\", \"price\":\"0.37\", \"size\":\"194.12\", \"side\":\"BUY\", \"hash\":\"104edef2fdfb5f32c40e7b9e6fa938fc156aadc3\", \"best_bid\":\"0.47\", \"best_ask\":\"0.48\"}, {\"asset_id\":\"24254094493625419915756280046002869097156693848522361803041977572204227262166\", \"price\":\"0.63\", \"size\":\"194.12\", \"side\":\"SELL\", \"hash\":\"af677de4a581524de1946b3ccc6132a92bae10cd\", \"best_bid\":\"0.52\", \"best_ask\":\"0.53\"}], \"timestamp\":\"1785121859770\", \"event_type\":\"price_change\"}","received_at":"2026-07-27T03:10:59.690713Z","schema_version":"clob-market-ws.price_change.v1","sequence":null,"server_hash":null,"server_timestamp":"1785121859770","session_id":"dd162b8dca5f43ff811d304e69a06123","source":"clob_market_ws"},"received_at":"2026-07-27T03:10:59.690713Z","record_id":"a34afc63561d4f0143de997d08bc0db96f19a2b26424cbe0b67fa7b986963576","schema_fingerprint":"4aa3821a28b0b7c2400bc59aba4bcc0a76e971dadd19610d3ad38c768e124dc7","schema_version":"edge-lab-recorder.raw.v1","sequence":null,"source":"clob_market_ws"}
{"event_at":"2026-07-27T03:10:59.771000Z","event_fingerprint":"4f55a6e5062829db26e6bfa0031ea437c9d76389f52b7193abaa009ae41ba668","payload":{"connection_id":"c7dc2e4762f849c6b6f9306b6518dcab","event_at":"2026-07-27T03:10:59.771000Z","event_type":"price_change","frame_hash":"467e763453316533e513f7f52f63669271cc02a17d7114883fafeed8aad3562a","frame_index":0,"kind":"data","monotonic_ns":223843024884833,"payload":{"event_type":"price_change","market":"0x717c0e8ccd4d5c7040185188fbae28be901ca589a11a94b1b38ca36a79eccfeb","price_changes":[{"asset_id":"41448400836309843603620980831210604935021861034693225347475867885462478926555","best_ask":"0.48","best_bid":"0.47","hash":"a452ca0fa401e78a1cd18ba564b7b08320111450","price":"0.45","side":"BUY","size":"225.33"},{"asset_id":"24254094493625419915756280046002869097156693848522361803041977572204227262166","best_ask":"0.53","best_bid":"0.52","hash":"332d240fd7f4ad4d1c080ff831bbddbdd9352d9a","price":"0.55","side":"SELL","size":"225.33"}],"timestamp":"1785121859771"},"payload_hash":"9f4467ddf2f5322a7bac3e4f280760f56cb461c423f27068ac36429b629cd7e0","raw_frame":"{\"market\":\"0x717c0e8ccd4d5c7040185188fbae28be901ca589a11a94b1b38ca36a79eccfeb\", \"price_changes\":[{\"asset_id\":\"41448400836309843603620980831210604935021861034693225347475867885462478926555\", \"price\":\"0.45\", \"size\":\"225.33\", \"side\":\"BUY\", \"hash\":\"a452ca0fa401e78a1cd18ba564b7b08320111450\", \"best_bid\":\"0.47\", \"best_ask\":\"0.48\"}, {\"asset_id\":\"24254094493625419915756280046002869097156693848522361803041977572204227262166\", \"price\":\"0.55\", \"size\":\"225.33\", \"side\":\"SELL\", \"hash\":\"332d240fd7f4ad4d1c080ff831bbddbdd9352d9a\", \"best_bid\":\"0.52\", \"best_ask\":\"0.53\"}], \"timestamp\":\"1785121859771\", \"event_type\":\"price_change\"}","received_at":"2026-07-27T03:10:59.694582Z","schema_version":"clob-market-ws.price_change.v1","sequence":null,"server_hash":null,"server_timestamp":"1785121859771","session_id":"dd162b8dca5f43ff811d304e69a06123","source":"clob_market_ws"},"received_at":"2026-07-27T03:10:59.694582Z","record_id":"2b5384d334615bb33a4197052d10ed87b96aff6f85b19eb73a1845ddd8e21abf","schema_fingerprint":"4aa3821a28b0b7c2400bc59aba4bcc0a76e971dadd19610d3ad38c768e124dc7","schema_version":"edge-lab-recorder.raw.v1","sequence":null,"source":"clob_market_ws"}
{"event_at":"2026-07-27T03:10:59.771000Z","event_fingerprint":"3c29b9ff9d550b94a267a48e3f83f015e289b6b4f151c0b1db6e7cbc29206a1d","payload":{"connection_id":"c7dc2e4762f849c6b6f9306b6518dcab","event_at":"2026-07-27T03:10:59.771000Z","event_type":"price_change","frame_hash":"c7074a7da937fdfadc9978b153c7bd2ddec6045de21f44806e9e761028c4c4cf","frame_index":0,"kind":"data","monotonic_ns":223843026596458,"payload":{"event_type":"price_change","market":"0x717c0e8ccd4d5c7040185188fbae28be901ca589a11a94b1b38ca36a79eccfeb","price_changes":[{"asset_id":"41448400836309843603620980831210604935021861034693225347475867885462478926555","best_ask":"0.48","best_bid":"0.47","hash":"6f0c2e00cd59b67c2a11eb6ea976a44561df09ab","price":"0.27","side":"BUY","size":"97.5"},{"asset_id":"24254094493625419915756280046002869097156693848522361803041977572204227262166","best_ask":"0.53","best_bid":"0.52","hash":"a751f929f9170b11255672a7d644a5ad7e97d858","price":"0.73","side":"SELL","size":"97.5"}],"timestamp":"1785121859771"},"payload_hash":"3a11cbe288917d9e5c00584c0e44f05801eb4e945c8940e8007e4b3d549d6250","raw_frame":"{\"market\":\"0x717c0e8ccd4d5c7040185188fbae28be901ca589a11a94b1b38ca36a79eccfeb\", \"price_changes\":[{\"asset_id\":\"41448400836309843603620980831210604935021861034693225347475867885462478926555\", \"price\":\"0.27\", \"size\":\"97.5\", \"side\":\"BUY\", \"hash\":\"6f0c2e00cd59b67c2a11eb6ea976a44561df09ab\", \"best_bid\":\"0.47\", \"best_ask\":\"0.48\"}, {\"asset_id\":\"24254094493625419915756280046002869097156693848522361803041977572204227262166\", \"price\":\"0.73\", \"size\":\"97.5\", \"side\":\"SELL\", \"hash\":\"a751f929f9170b11255672a7d644a5ad7e97d858\", \"best_bid\":\"0.52\", \"best_ask\":\"0.53\"}], \"timestamp\":\"1785121859771\", \"event_type\":\"price_change\"}","received_at":"2026-07-27T03:10:59.696301Z","schema_version":"clob-market-ws.price_change.v1","sequence":null,"server_hash":null,"server_timestamp":"1785121859771","session_id":"dd162b8dca5f43ff811d304e69a06123","source":"clob_market_ws"},"received_at":"2026-07-27T03:10:59.696301Z","record_id":"ce1c5714b4eab53a04d0cc7a12e0e94967999612d608447211f9083b55f1dcb4","schema_fingerprint":"4aa3821a28b0b7c2400bc59aba4bcc0a76e971dadd19610d3ad38c768e124dc7","schema_version":"edge-lab-recorder.raw.v1","sequence":null,"source":"clob_market_ws"}
{"event_at":"2026-07-27T03:10:59.772000Z","event_fingerprint":"949745b4ef349332cef86b7f823ab342e07a5b84b3b2159d5d5f87d9c3bb9039","payload":{"connection_id":"c7dc2e4762f849c6b6f9306b6518dcab","event_at":"2026-07-27T03:10:59.772000Z","event_type":"price_change","frame_hash":"3cadcdc7cd4a1166119b895fe04f9cdac4dabc9738f938026a89aa4de03c8c10","frame_index":0,"kind":"data","monotonic_ns":223843028102708,"payload":{"event_type":"price_change","market":"0x717c0e8ccd4d5c7040185188fbae28be901ca589a11a94b1b38ca36a79eccfeb","price_changes":[{"asset_id":"24254094493625419915756280046002869097156693848522361803041977572204227262166","best_ask":"0.53","best_bid":"0.52","hash":"1ebb195aa0ab68d42a43d646875cd7ce4bbc8f1e","price":"0.33","side":"BUY","size":"503.5"},{"asset_id":"41448400836309843603620980831210604935021861034693225347475867885462478926555","best_ask":"0.48","best_bid":"0.47","hash":"6652f47f50d694b10c2c9eb4e8dbe5af04dcb2c0","price":"0.67","side":"SELL","size":"503.5"}],"timestamp":"1785121859772"},"payload_hash":"08402a16e718196aa01cd4b040c6a54369ff216b2d0d937074b5f15840ef973a","raw_frame":"{\"market\":\"0x717c0e8ccd4d5c7040185188fbae28be901ca589a11a94b1b38ca36a79eccfeb\", \"price_changes\":[{\"asset_id\":\"24254094493625419915756280046002869097156693848522361803041977572204227262166\", \"price\":\"0.33\", \"size\":\"503.5\", \"side\":\"BUY\", \"hash\":\"1ebb195aa0ab68d42a43d646875cd7ce4bbc8f1e\", \"best_bid\":\"0.52\", \"best_ask\":\"0.53\"}, {\"asset_id\":\"41448400836309843603620980831210604935021861034693225347475867885462478926555\", \"price\":\"0.67\", \"size\":\"503.5\", \"side\":\"SELL\", \"hash\":\"6652f47f50d694b10c2c9eb4e8dbe5af04dcb2c0\", \"best_bid\":\"0.47\", \"best_ask\":\"0.48\"}], \"timestamp\":\"1785121859772\", \"event_type\":\"price_change\"}","received_at":"2026-07-27T03:10:59.697806Z","schema_version":"clob-market-ws.price_change.v1","sequence":null,"server_hash":null,"server_timestamp":"1785121859772","session_id":"dd162b8dca5f43ff811d304e69a06123","source":"clob_market_ws"},"received_at":"2026-07-27T03:10:59.697806Z","record_id":"857e96de8f1ccaf024f686cd5cc39d9f0866bf934dcca805f3708d4f96215284","schema_fingerprint":"4aa3821a28b0b7c2400bc59aba4bcc0a76e971dadd19610d3ad38c768e124dc7","schema_version":"edge-lab-recorder.raw.v1","sequence":null,"source":"clob_market_ws"}
{"event_at":"2026-07-27T03:10:59.773000Z","event_fingerprint":"9dc35115e7e163bef84b257522c1665eb41d2b3e31451dc443859c893f864e4c","payload":{"connection_id":"c7dc2e4762f849c6b6f9306b6518dcab","event_at":"2026-07-27T03:10:59.773000Z","event_type":"price_change","frame_hash":"924331d1d28f24f7e6006edcab900e54e0b4918ec59391eaf3d316bf19063f82","frame_index":0,"kind":"data","monotonic_ns":223843029723625,"payload":{"event_type":"price_change","market":"0x717c0e8ccd4d5c7040185188fbae28be901ca589a11a94b1b38ca36a79eccfeb","price_changes":[{"asset_id":"24254094493625419915756280046002869097156693848522361803041977572204227262166","best_ask":"0.53","best_bid":"0.52","hash":"b1fa8fe5da4b61944e4a00764c676b6511696ea6","price":"0.5","side":"BUY","size":"270"},{"asset_id":"41448400836309843603620980831210604935021861034693225347475867885462478926555","best_ask":"0.48","best_bid":"0.47","hash":"b86cd2a1ab3b0b73e94dbdeea9008c584df0bdf6","price":"0.5","side":"SELL","size":"270"}],"timestamp":"1785121859773"},"payload_hash":"6775a0da927b4bb9719ada02b7edaa97b16a4617a009d375101f9f8177bb7c4c","raw_frame":"{\"market\":\"0x717c0e8ccd4d5c7040185188fbae28be901ca589a11a94b1b38ca36a79eccfeb\", \"price_changes\":[{\"asset_id\":\"24254094493625419915756280046002869097156693848522361803041977572204227262166\", \"price\":\"0.5\", \"size\":\"270\", \"side\":\"BUY\", \"hash\":\"b1fa8fe5da4b61944e4a00764c676b6511696ea6\", \"best_bid\":\"0.52\", \"best_ask\":\"0.53\"}, {\"asset_id\":\"41448400836309843603620980831210604935021861034693225347475867885462478926555\", \"price\":\"0.5\", \"size\":\"270\", \"side\":\"SELL\", \"hash\":\"b86cd2a1ab3b0b73e94dbdeea9008c584df0bdf6\", \"best_bid\":\"0.47\", \"best_ask\":\"0.48\"}], \"timestamp\":\"1785121859773\", \"event_type\":\"price_change\"}","received_at":"2026-07-27T03:10:59.699427Z","schema_version":"clob-market-ws.price_change.v1","sequence":null,"server_hash":null,"server_timestamp":"1785121859773","session_id":"dd162b8dca5f43ff811d304e69a06123","source":"clob_market_ws"},"received_at":"2026-07-27T03:10:59.699427Z","record_id":"714b1660e5bd2cc60f71e406f1fc22f32f36e8a5deacbf7f1d05fc83195e7472","schema_fingerprint":"4aa3821a28b0b7c2400bc59aba4bcc0a76e971dadd19610d3ad38c768e124dc7","schema_version":"edge-lab-recorder.raw.v1","sequence":null,"source":"clob_market_ws"}
{"event_at":"2026-07-27T03:10:59.773000Z","event_fingerprint":"f6a606940faaad24057b00ae42c5f282cb3cd2581e28ade9a244533d26ec895f","payload":{"connection_id":"c7dc2e4762f849c6b6f9306b6518dcab","event_at":"2026-07-27T03:10:59.773000Z","event_type":"price_change","frame_hash":"910a4afb61337a92e9867d61e744ef1a5cdb2695efec044f6afbd0400d68c437","frame_index":0,"kind":"data","monotonic_ns":223843030981041,"payload":{"event_type":"price_change","market":"0x717c0e8ccd4d5c7040185188fbae28be901ca589a11a94b1b38ca36a79eccfeb","price_changes":[{"asset_id":"41448400836309843603620980831210604935021861034693225347475867885462478926555","best_ask":"0.48","best_bid":"0.47","hash":"64b88cdc81b4db625a02c9116417896c38412de5","price":"0.17","side":"BUY","size":"103.5"},{"asset_id":"24254094493625419915756280046002869097156693848522361803041977572204227262166","best_ask":"0.53","best_bid":"0.52","hash":"1965ee8ffe5a8323e3d7e5714b7a62f2a46cc583","price":"0.83","side":"SELL","size":"103.5"}],"timestamp":"1785121859773"},"payload_hash":"05f2063b70104cb7a615ed01d774f4c880c2b9666769e6acd7f5bc12721387b3","raw_frame":"{\"market\":\"0x717c0e8ccd4d5c7040185188fbae28be901ca589a11a94b1b38ca36a79eccfeb\", \"price_changes\":[{\"asset_id\":\"41448400836309843603620980831210604935021861034693225347475867885462478926555\", \"price\":\"0.17\", \"size\":\"103.5\", \"side\":\"BUY\", \"hash\":\"64b88cdc81b4db625a02c9116417896c38412de5\", \"best_bid\":\"0.47\", \"best_ask\":\"0.48\"}, {\"asset_id\":\"24254094493625419915756280046002869097156693848522361803041977572204227262166\", \"price\":\"0.83\", \"size\":\"103.5\", \"side\":\"SELL\", \"hash\":\"1965ee8ffe5a8323e3d7e5714b7a62f2a46cc583\", \"best_bid\":\"0.52\", \"best_ask\":\"0.53\"}], \"timestamp\":\"1785121859773\", \"event_type\":\"price_change\"}","received_at":"2026-07-27T03:10:59.700691Z","schema_version":"clob-market-ws.price_change.v1","sequence":null,"server_hash":null,"server_timestamp":"1785121859773","session_id":"dd162b8dca5f43ff811d304e69a06123","source":"clob_market_ws"},"received_at":"2026-07-27T03:10:59.700691Z","record_id":"6d50187dea86e0f134c6ef146d2eb896572a17b3313b23be88b984a60ec5793a","schema_fingerprint":"4aa3821a28b0b7c2400bc59aba4bcc0a76e971dadd19610d3ad38c768e124dc7","schema_version":"edge-lab-recorder.raw.v1","sequence":null,"source":"clob_market_ws"}
{"event_at":"2026-07-27T03:10:59.774000Z","event_fingerprint":"4a47be2ed3e3132e5d8ca9c0c923c6d09ef46235b0e76510c708cd60e16c81dc","payload":{"connection_id":"c7dc2e4762f849c6b6f9306b6518dcab","event_at":"2026-07-27T03:10:59.774000Z","event_type":"price_change","frame_hash":"57731cac072dcdcf15548409e27f3fbe9227235e703832e8b20afa4df535cd04","frame_index":0,"kind":"data","monotonic_ns":223843031527083,"payload":{"event_type":"price_change","market":"0x717c0e8ccd4d5c7040185188fbae28be901ca589a11a94b1b38ca36a79eccfeb","price_changes":[{"asset_id":"41448400836309843603620980831210604935021861034693225347475867885462478926555","best_ask":"0.48","best_bid":"0.47","hash":"0acd19c4d36441555a68a93f132ab190a4c01fd5","price":"0.46","side":"BUY","size":"70.87"},{"asset_id":"24254094493625419915756280046002869097156693848522361803041977572204227262166","best_ask":"0.53","best_bid":"0.52","hash":"280de9c31cf9f7312e755fa40185d8be51187b38","price":"0.54","side":"SELL","size":"70.87"}],"timestamp":"1785121859774"},"payload_hash":"8dc29402b6324606b432b5f865145463f1f0aca3f26a2a1aab882312a822dd29","raw_frame":"{\"market\":\"0x717c0e8ccd4d5c7040185188fbae28be901ca589a11a94b1b38ca36a79eccfeb\", \"price_changes\":[{\"asset_id\":\"41448400836309843603620980831210604935021861034693225347475867885462478926555\", \"price\":\"0.46\", \"size\":\"70.87\", \"side\":\"BUY\", \"hash\":\"0acd19c4d36441555a68a93f132ab190a4c01fd5\", \"best_bid\":\"0.47\", \"best_ask\":\"0.48\"}, {\"asset_id\":\"24254094493625419915756280046002869097156693848522361803041977572204227262166\", \"price\":\"0.54\", \"size\":\"70.87\", \"side\":\"SELL\", \"hash\":\"280de9c31cf9f7312e755fa40185d8be51187b38\", \"best_bid\":\"0.52\", \"best_ask\":\"0.53\"}], \"timestamp\":\"1785121859774\", \"event_type\":\"price_change\"}","received_at":"2026-07-27T03:10:59.701234Z","schema_version":"clob-market-ws.price_change.v1","sequence":null,"server_hash":null,"server_timestamp":"1785121859774","session_id":"dd162b8dca5f43ff811d304e69a06123","source":"clob_market_ws"},"received_at":"2026-07-27T03:10:59.701234Z","record_id":"b22c7ebc14c8754a6df63b2093af55a38172c4aa936f5f2d8c326db01c2d54f4","schema_fingerprint":"4aa3821a28b0b7c2400bc59aba4bcc0a76e971dadd19610d3ad38c768e124dc7","schema_version":"edge-lab-recorder.raw.v1","sequence":null,"source":"clob_market_ws"}
{"event_at":"2026-07-27T03:10:59.775000Z","event_fingerprint":"6115785b1d0795804cdb3944923d4b2861617ddd5d812e6c23fb71fbe994b422","payload":{"connection_id":"c7dc2e4762f849c6b6f9306b6518dcab","event_at":"2026-07-27T03:10:59.775000Z","event_type":"price_change","frame_hash":"2ca1f2abcc5a313eb9c52e9f9bf54014a46aafc05e6ec6f7ca6f26b69bd64374","frame_index":0,"kind":"data","monotonic_ns":223843034835208,"payload":{"event_type":"price_change","market":"0x717c0e8ccd4d5c7040185188fbae28be901ca589a11a94b1b38ca36a79eccfeb","price_changes":[{"asset_id":"24254094493625419915756280046002869097156693848522361803041977572204227262166","best_ask":"0.53","best_bid":"0.52","hash":"cc30d311194a22c5cbd900bf06f1923894836ba8","price":"0.51","side":"BUY","size":"180"},{"asset_id":"41448400836309843603620980831210604935021861034693225347475867885462478926555","best_ask":"0.48","best_bid":"0.47","hash":"e14e604f17c467e8a7e98b28ee82579222e81037","price":"0.49","side":"SELL","size":"180"}],"timestamp":"1785121859775"},"payload_hash":"4bdd0e42ef978a155ff533dbe13a0ea76a199bcebd9721de37cf91bb75b24409","raw_frame":"{\"market\":\"0x717c0e8ccd4d5c7040185188fbae28be901ca589a11a94b1b38ca36a79eccfeb\", \"price_changes\":[{\"asset_id\":\"24254094493625419915756280046002869097156693848522361803041977572204227262166\", \"price\":\"0.51\", \"size\":\"180\", \"side\":\"BUY\", \"hash\":\"cc30d311194a22c5cbd900bf06f1923894836ba8\", \"best_bid\":\"0.52\", \"best_ask\":\"0.53\"}, {\"asset_id\":\"41448400836309843603620980831210604935021861034693225347475867885462478926555\", \"price\":\"0.49\", \"size\":\"180\", \"side\":\"SELL\", \"hash\":\"e14e604f17c467e8a7e98b28ee82579222e81037\", \"best_bid\":\"0.47\", \"best_ask\":\"0.48\"}], \"timestamp\":\"1785121859775\", \"event_type\":\"price_change\"}","received_at":"2026-07-27T03:10:59.704538Z","schema_version":"clob-market-ws.price_change.v1","sequence":null,"server_hash":null,"server_timestamp":"1785121859775","session_id":"dd162b8dca5f43ff811d304e69a06123","source":"clob_market_ws"},"received_at":"2026-07-27T03:10:59.704538Z","record_id":"749f8288b61d047488df6a5fb6b3beba12f5004fa13fc037a7f545765374aa3d","schema_fingerprint":"4aa3821a28b0b7c2400bc59aba4bcc0a76e971dadd19610d3ad38c768e124dc7","schema_version":"edge-lab-recorder.raw.v1","sequence":null,"source":"clob_market_ws"}
{"event_at":"2026-07-27T03:10:59.776000Z","event_fingerprint":"f6d988221a1ecabf5e07b2a29bab4aa52371685a9dd23d50573cc74dd4fcbbb2","payload":{"connection_id":"c7dc2e4762f849c6b6f9306b6518dcab","event_at":"2026-07-27T03:10:59.776000Z","event_type":"price_change","frame_hash":"65decacaab0da85af3659007551db650400edbf872f88460bc8616dd64c6f337","frame_index":0,"kind":"data","monotonic_ns":223843036706500,"payload":{"event_type":"price_change","market":"0x717c0e8ccd4d5c7040185188fbae28be901ca589a11a94b1b38ca36a79eccfeb","price_changes":[{"asset_id":"24254094493625419915756280046002869097156693848522361803041977572204227262166","best_ask":"0.53","best_bid":"0.52","hash":"9aa8e1d1986dc3b8bbeaaec7abd129063f2cb538","price":"0.13","side":"BUY","size":"110.5"},{"asset_id":"41448400836309843603620980831210604935021861034693225347475867885462478926555","best_ask":"0.48","best_bid":"0.47","hash":"5a2f38068f95d31531293dbec47db9f209f161bb","price":"0.87","side":"SELL","size":"110.5"}],"timestamp":"1785121859776"},"payload_hash":"760a8fa7c21c00f8ac6717bbdce5a10aa5f0afd8bc1ab9f2016bf9ddddd9e583","raw_frame":"{\"market\":\"0x717c0e8ccd4d5c7040185188fbae28be901ca589a11a94b1b38ca36a79eccfeb\", \"price_changes\":[{\"asset_id\":\"24254094493625419915756280046002869097156693848522361803041977572204227262166\", \"price\":\"0.13\", \"size\":\"110.5\", \"side\":\"BUY\", \"hash\":\"9aa8e1d1986dc3b8bbeaaec7abd129063f2cb538\", \"best_bid\":\"0.52\", \"best_ask\":\"0.53\"}, {\"asset_id\":\"41448400836309843603620980831210604935021861034693225347475867885462478926555\", \"price\":\"0.87\", \"size\":\"110.5\", \"side\":\"SELL\", \"hash\":\"5a2f38068f95d31531293dbec47db9f209f161bb\", \"best_bid\":\"0.47\", \"best_ask\":\"0.48\"}], \"timestamp\":\"1785121859776\", \"event_type\":\"price_change\"}","received_at":"2026-07-27T03:10:59.706410Z","schema_version":"clob-market-ws.price_change.v1","sequence":null,"server_hash":null,"server_timestamp":"1785121859776","session_id":"dd162b8dca5f43ff811d304e69a06123","source":"clob_market_ws"},"received_at":"2026-07-27T03:10:59.706410Z","record_id":"ceaab959ffef8e8e309364692481e928c0eb18b80cf41edd4ca34f230121feb6","schema_fingerprint":"4aa3821a28b0b7c2400bc59aba4bcc0a76e971dadd19610d3ad38c768e124dc7","schema_version":"edge-lab-recorder.raw.v1","sequence":null,"source":"clob_market_ws"}
{"event_at":"2026-07-27T03:10:59.777000Z","event_fingerprint":"a57dfa2b3add5a2e713eade239c79209efc8eb3de27b46c5b1b2a6d18f68eb56","payload":{"connection_id":"c7dc2e4762f849c6b6f9306b6518dcab","event_at":"2026-07-27T03:10:59.777000Z","event_type":"price_change","frame_hash":"f945fc86d5ebdc5986a4ba8b47af3373b7ef1f45a82e70e2ac277f3e0f55a1eb","frame_index":0,"kind":"data","monotonic_ns":223843044212416,"payload":{"event_type":"price_change","market":"0x717c0e8ccd4d5c7040185188fbae28be901ca589a11a94b1b38ca36a79eccfeb","price_changes":[{"asset_id":"41448400836309843603620980831210604935021861034693225347475867885462478926555","best_ask":"0.48","best_bid":"0.47","hash":"f5c08e0c83a4c989665b8014a15f50635493b9f3","price":"0.44","side":"BUY","size":"500.68"},{"asset_id":"24254094493625419915756280046002869097156693848522361803041977572204227262166","best_ask":"0.53","best_bid":"0.52","hash":"347aa812ed8a6fe0708184b23934957668d63276","price":"0.56","side":"SELL","size":"500.68"}],"timestamp":"1785121859777"},"payload_hash":"c6a1d30e0375f8b028261fcf7c72e378a6ac4e279d573fd9769892207324595e","raw_frame":"{\"market\":\"0x717c0e8ccd4d5c7040185188fbae28be901ca589a11a94b1b38ca36a79eccfeb\", \"price_changes\":[{\"asset_id\":\"41448400836309843603620980831210604935021861034693225347475867885462478926555\", \"price\":\"0.44\", \"size\":\"500.68\", \"side\":\"BUY\", \"hash\":\"f5c08e0c83a4c989665b8014a15f50635493b9f3\", \"best_bid\":\"0.47\", \"best_ask\":\"0.48\"}, {\"asset_id\":\"24254094493625419915756280046002869097156693848522361803041977572204227262166\", \"price\":\"0.56\", \"size\":\"500.68\", \"side\":\"SELL\", \"hash\":\"347aa812ed8a6fe0708184b23934957668d63276\", \"best_bid\":\"0.52\", \"best_ask\":\"0.53\"}], \"timestamp\":\"1785121859777\", \"event_type\":\"price_change\"}","received_at":"2026-07-27T03:10:59.713916Z","schema_version":"clob-market-ws.price_change.v1","sequence":null,"server_hash":null,"server_timestamp":"1785121859777","session_id":"dd162b8dca5f43ff811d304e69a06123","source":"clob_market_ws"},"received_at":"2026-07-27T03:10:59.713916Z","record_id":"8747b805276d96c5235c92c3032fcd8f13b23a2980ab103da3321c00f2e84275","schema_fingerprint":"4aa3821a28b0b7c2400bc59aba4bcc0a76e971dadd19610d3ad38c768e124dc7","schema_version":"edge-lab-recorder.raw.v1","sequence":null,"source":"clob_market_ws"}
{"event_at":"2026-07-27T03:10:59.777000Z","event_fingerprint":"0a6be40f1106e1df9a188fbb70f58290c4c0eb9b5ea8696bf60065a46abb26b8","payload":{"connection_id":"c7dc2e4762f849c6b6f9306b6518dcab","event_at":"2026-07-27T03:10:59.777000Z","event_type":"price_change","frame_hash":"a1ba18ff1466b4b6e23454045606b444778a797b97d0894cdf6da4e92ccf2529","frame_index":0,"kind":"data","monotonic_ns":223843048297583,"payload":{"event_type":"price_change","market":"0x717c0e8ccd4d5c7040185188fbae28be901ca589a11a94b1b38ca36a79eccfeb","price_changes":[{"asset_id":"24254094493625419915756280046002869097156693848522361803041977572204227262166","best_ask":"0.53","best_bid":"0.52","hash":"dacc5345402e590e682bf7d75304175ea948e417","price":"0.23","side":"BUY","size":"97.5"},{"asset_id":"41448400836309843603620980831210604935021861034693225347475867885462478926555","best_ask":"0.48","best_bid":"0.47","hash":"60ec7910c1d5eb1a6442d0a25a821f2bc5445e12","price":"0.77","side":"SELL","size":"97.5"}],"timestamp":"1785121859777"},"payload_hash":"9d69e8e2928b1af05e74642647c6b8c64fbdb1b098f47ce8ae75a2908e47a8ed","raw_frame":"{\"market\":\"0x717c0e8ccd4d5c7040185188fbae28be901ca589a11a94b1b38ca36a79eccfeb\", \"price_changes\":[{\"asset_id\":\"24254094493625419915756280046002869097156693848522361803041977572204227262166\", \"price\":\"0.23\", \"size\":\"97.5\", \"side\":\"BUY\", \"hash\":\"dacc5345402e590e682bf7d75304175ea948e417\", \"best_bid\":\"0.52\", \"best_ask\":\"0.53\"}, {\"asset_id\":\"41448400836309843603620980831210604935021861034693225347475867885462478926555\", \"price\":\"0.77\", \"size\":\"97.5\", \"side\":\"SELL\", \"hash\":\"60ec7910c1d5eb1a6442d0a25a821f2bc5445e12\", \"best_bid\":\"0.47\", \"best_ask\":\"0.48\"}], \"timestamp\":\"1785121859777\", \"event_type\":\"price_change\"}","received_at":"2026-07-27T03:10:59.718008Z","schema_version":"clob-market-ws.price_change.v1","sequence":null,"server_hash":null,"server_timestamp":"1785121859777","session_id":"dd162b8dca5f43ff811d304e69a06123","source":"clob_market_ws"},"received_at":"2026-07-27T03:10:59.718008Z","record_id":"b53c786e44e1f91384e061f8cc9f6f880c146d6e8113f7ab1af707e4b53996f4","schema_fingerprint":"4aa3821a28b0b7c2400bc59aba4bcc0a76e971dadd19610d3ad38c768e124dc7","schema_version":"edge-lab-recorder.raw.v1","sequence":null,"source":"clob_market_ws"}
{"event_at":"2026-07-27T03:10:59.797000Z","event_fingerprint":"7f80e75d87b5b6bf675eee94f8f35d0498dedc75bb12076c496ad0fbd3a38217","payload":{"connection_id":"c7dc2e4762f849c6b6f9306b6518dcab","event_at":"2026-07-27T03:10:59.797000Z","event_type":"price_change","frame_hash":"9beda8eac791c7cf9c2ce2a8c1bae19621aaf05de9d923f192cb6ec062eaf6c2","frame_index":0,"kind":"data","monotonic_ns":223843051960083,"payload":{"event_type":"price_change","market":"0x717c0e8ccd4d5c7040185188fbae28be901ca589a11a94b1b38ca36a79eccfeb","price_changes":[{"asset_id":"41448400836309843603620980831210604935021861034693225347475867885462478926555","best_ask":"0.48","best_bid":"0.47","hash":"706c2a9c107b27b351cea9cca0befe484069842d","price":"0.45","side":"BUY","size":"125.33"},{"asset_id":"24254094493625419915756280046002869097156693848522361803041977572204227262166","best_ask":"0.53","best_bid":"0.52","hash":"9000763faf1809da0a6da9696dfaa743a5dfede5","price":"0.55","side":"SELL","size":"125.33"}],"timestamp":"1785121859797"},"payload_hash":"fc2cf1d26daff4449050c0c8bde7c768608721c6425af10818a0c1abf9dc788f","raw_frame":"{\"market\":\"0x717c0e8ccd4d5c7040185188fbae28be901ca589a11a94b1b38ca36a79eccfeb\", \"price_changes\":[{\"asset_id\":\"41448400836309843603620980831210604935021861034693225347475867885462478926555\", \"price\":\"0.45\", \"size\":\"125.33\", \"side\":\"BUY\", \"hash\":\"706c2a9c107b27b351cea9cca0befe484069842d\", \"best_bid\":\"0.47\", \"best_ask\":\"0.48\"}, {\"asset_id\":\"24254094493625419915756280046002869097156693848522361803041977572204227262166\", \"price\":\"0.55\", \"size\":\"125.33\", \"side\":\"SELL\", \"hash\":\"9000763faf1809da0a6da9696dfaa743a5dfede5\", \"best_bid\":\"0.52\", \"best_ask\":\"0.53\"}], \"timestamp\":\"1785121859797\", \"event_type\":\"price_change\"}","received_at":"2026-07-27T03:10:59.721664Z","schema_version":"clob-market-ws.price_change.v1","sequence":null,"server_hash":null,"server_timestamp":"1785121859797","session_id":"dd162b8dca5f43ff811d304e69a06123","source":"clob_market_ws"},"received_at":"2026-07-27T03:10:59.721664Z","record_id":"2df238c9fae6ed1ba081b978fa5871e3924340594c0b89c01d2cf7304136c2e9","schema_fingerprint":"4aa3821a28b0b7c2400bc59aba4bcc0a76e971dadd19610d3ad38c768e124dc7","schema_version":"edge-lab-recorder.raw.v1","sequence":null,"source":"clob_market_ws"}
{"event_at":"2026-07-27T03:10:59.799000Z","event_fingerprint":"dfe70aab6633d671d4480d3000c796a2e5b932a7ab93e191f6fcee67d5120df4","payload":{"connection_id":"c7dc2e4762f849c6b6f9306b6518dcab","event_at":"2026-07-27T03:10:59.799000Z","event_type":"price_change","frame_hash":"17330a5ed9ee4b9d9aa2fa35b3aa728539880a6087b80fbb08757edd51d5cb1a","frame_index":0,"kind":"data","monotonic_ns":223843053681000,"payload":{"event_type":"price_change","market":"0x717c0e8ccd4d5c7040185188fbae28be901ca589a11a94b1b38ca36a79eccfeb","price_changes":[{"asset_id":"41448400836309843603620980831210604935021861034693225347475867885462478926555","best_ask":"0.48","best_bid":"0.47","hash":"5e420c51b51770989ab724df40336c2eb7434aaf","price":"0.45","side":"BUY","size":"25.33"},{"asset_id":"24254094493625419915756280046002869097156693848522361803041977572204227262166","best_ask":"0.53","best_bid":"0.52","hash":"8a0dbbcefb103be23f3e50efa65185edc8f01d55","price":"0.55","side":"SELL","size":"25.33"}],"timestamp":"1785121859799"},"payload_hash":"f15c0474055ccbec1082316bab88d7da875a55f9c9a3bd14da5d25228b6405b4","raw_frame":"{\"market\":\"0x717c0e8ccd4d5c7040185188fbae28be901ca589a11a94b1b38ca36a79eccfeb\", \"price_changes\":[{\"asset_id\":\"41448400836309843603620980831210604935021861034693225347475867885462478926555\", \"price\":\"0.45\", \"size\":\"25.33\", \"side\":\"BUY\", \"hash\":\"5e420c51b51770989ab724df40336c2eb7434aaf\", \"best_bid\":\"0.47\", \"best_ask\":\"0.48\"}, {\"asset_id\":\"24254094493625419915756280046002869097156693848522361803041977572204227262166\", \"price\":\"0.55\", \"size\":\"25.33\", \"side\":\"SELL\", \"hash\":\"8a0dbbcefb103be23f3e50efa65185edc8f01d55\", \"best_bid\":\"0.52\", \"best_ask\":\"0.53\"}], \"timestamp\":\"1785121859799\", \"event_type\":\"price_change\"}","received_at":"2026-07-27T03:10:59.723385Z","schema_version":"clob-market-ws.price_change.v1","sequence":null,"server_hash":null,"server_timestamp":"1785121859799","session_id":"dd162b8dca5f43ff811d304e69a06123","source":"clob_market_ws"},"received_at":"2026-07-27T03:10:59.723385Z","record_id":"d096cf5b52f4afdd5e09d45503820e55e1c1f2d36a011c0be68b53544174605f","schema_fingerprint":"4aa3821a28b0b7c2400bc59aba4bcc0a76e971dadd19610d3ad38c768e124dc7","schema_version":"edge-lab-recorder.raw.v1","sequence":null,"source":"clob_market_ws"}
{"event_at":"2026-07-27T03:10:59.846000Z","event_fingerprint":"9b3cbecbd8091f7cc183492f5baf176435f7cf97fae694c49fd7bcc7ce974585","payload":{"connection_id":"c7dc2e4762f849c6b6f9306b6518dcab","event_at":"2026-07-27T03:10:59.846000Z","event_type":"price_change","frame_hash":"5315ab20799469c35542041ba5d3b70a36c861eb55ed3660101068e4f624c55c","frame_index":0,"kind":"data","monotonic_ns":223843081441666,"payload":{"event_type":"price_change","market":"0x717c0e8ccd4d5c7040185188fbae28be901ca589a11a94b1b38ca36a79eccfeb","price_changes":[{"asset_id":"41448400836309843603620980831210604935021861034693225347475867885462478926555","best_ask":"0.48","best_bid":"0.47","hash":"25ae008f63a3254c4e2b48cb744f560b100e456c","price":"0.42","side":"BUY","size":"223"},{"asset_id":"24254094493625419915756280046002869097156693848522361803041977572204227262166","best_ask":"0.53","best_bid":"0.52","hash":"1d5774d4057e16add03eb49a122d197a3450366a","price":"0.58","side":"SELL","size":"223"}],"timestamp":"1785121859846"},"payload_hash":"0336e71e785e9f4764ae546761fa9c3f4d5110c5292c4bbe152c8362c850573c","raw_frame":"{\"market\":\"0x717c0e8ccd4d5c7040185188fbae28be901ca589a11a94b1b38ca36a79eccfeb\", \"price_changes\":[{\"asset_id\":\"41448400836309843603620980831210604935021861034693225347475867885462478926555\", \"price\":\"0.42\", \"size\":\"223\", \"side\":\"BUY\", \"hash\":\"25ae008f63a3254c4e2b48cb744f560b100e456c\", \"best_bid\":\"0.47\", \"best_ask\":\"0.48\"}, {\"asset_id\":\"24254094493625419915756280046002869097156693848522361803041977572204227262166\", \"price\":\"0.58\", \"size\":\"223\", \"side\":\"SELL\", \"hash\":\"1d5774d4057e16add03eb49a122d197a3450366a\", \"best_bid\":\"0.52\", \"best_ask\":\"0.53\"}], \"timestamp\":\"1785121859846\", \"event_type\":\"price_change\"}","received_at":"2026-07-27T03:10:59.751137Z","schema_version":"clob-market-ws.price_change.v1","sequence":null,"server_hash":null,"server_timestamp":"1785121859846","session_id":"dd162b8dca5f43ff811d304e69a06123","source":"clob_market_ws"},"received_at":"2026-07-27T03:10:59.751137Z","record_id":"383a6270cb8ac498dc6483230b9fa67104ddbefb9a42d9877815f07c89f592b1","schema_fingerprint":"4aa3821a28b0b7c2400bc59aba4bcc0a76e971dadd19610d3ad38c768e124dc7","schema_version":"edge-lab-recorder.raw.v1","sequence":null,"source":"clob_market_ws"}
{"event_at":"2026-07-27T03:10:59.847000Z","event_fingerprint":"d9d53e272c06d21f5fdcecea7b33c47a53fde227664bf9dab5ba7ce4f65a904d","payload":{"connection_id":"c7dc2e4762f849c6b6f9306b6518dcab","event_at":"2026-07-27T03:10:59.847000Z","event_type":"price_change","frame_hash":"f73081b11bbb211a6574d4c431aad90e930bde8dffc0a370c7251b301d445abf","frame_index":0,"kind":"data","monotonic_ns":223843083844000,"payload":{"event_type":"price_change","market":"0x717c0e8ccd4d5c7040185188fbae28be901ca589a11a94b1b38ca36a79eccfeb","price_changes":[{"asset_id":"41448400836309843603620980831210604935021861034693225347475867885462478926555","best_ask":"0.48","best_bid":"0.47","hash":"15e2b0746cb0f44bb8e89352a47342dcbb1d54c3","price":"0.42","side":"BUY","size":"228"},{"asset_id":"24254094493625419915756280046002869097156693848522361803041977572204227262166","best_ask":"0.53","best_bid":"0.52","hash":"29f8a4bbc310a819f0ecad6d5e3857c6ad42ff72","price":"0.58","side":"SELL","size":"228"}],"timestamp":"1785121859847"},"payload_hash":"189188647aed0962e5120cb3dead23856f6a79df9522427506a450249d609f17","raw_frame":"{\"market\":\"0x717c0e8ccd4d5c7040185188fbae28be901ca589a11a94b1b38ca36a79eccfeb\", \"price_changes\":[{\"asset_id\":\"41448400836309843603620980831210604935021861034693225347475867885462478926555\", \"price\":\"0.42\", \"size\":\"228\", \"side\":\"BUY\", \"hash\":\"15e2b0746cb0f44bb8e89352a47342dcbb1d54c3\", \"best_bid\":\"0.47\", \"best_ask\":\"0.48\"}, {\"asset_id\":\"24254094493625419915756280046002869097156693848522361803041977572204227262166\", \"price\":\"0.58\", \"size\":\"228\", \"side\":\"SELL\", \"hash\":\"29f8a4bbc310a819f0ecad6d5e3857c6ad42ff72\", \"best_bid\":\"0.52\", \"best_ask\":\"0.53\"}], \"timestamp\":\"1785121859847\", \"event_type\":\"price_change\"}","received_at":"2026-07-27T03:10:59.753547Z","schema_version":"clob-market-ws.price_change.v1","sequence":null,"server_hash":null,"server_timestamp":"1785121859847","session_id":"dd162b8dca5f43ff811d304e69a06123","source":"clob_market_ws"},"received_at":"2026-07-27T03:10:59.753547Z","record_id":"7eff75f078fa989eb3e86a0a9d1c96f5ddcd5e74102d62574bdd1b20baa296c8","schema_fingerprint":"4aa3821a28b0b7c2400bc59aba4bcc0a76e971dadd19610d3ad38c768e124dc7","schema_version":"edge-lab-recorder.raw.v1","sequence":null,"source":"clob_market_ws"}
{"event_at":"2026-07-27T03:10:59.848000Z","event_fingerprint":"6ee52594f142740419d3e6a232b601fb8dd05d08c2d04c914fc4dea6f92f0b36","payload":{"connection_id":"c7dc2e4762f849c6b6f9306b6518dcab","event_at":"2026-07-27T03:10:59.848000Z","event_type":"price_change","frame_hash":"5f3fe845083f7ffda225b8e57516be02589219b6b4e4370f37fd0dfcaeaf5181","frame_index":0,"kind":"data","monotonic_ns":223843086888958,"payload":{"event_type":"price_change","market":"0x717c0e8ccd4d5c7040185188fbae28be901ca589a11a94b1b38ca36a79eccfeb","price_changes":[{"asset_id":"41448400836309843603620980831210604935021861034693225347475867885462478926555","best_ask":"0.48","best_bid":"0.47","hash":"f56696c545e510adcaf032f3bf07eba7a7ef42df","price":"0.42","side":"BUY","size":"233"},{"asset_id":"24254094493625419915756280046002869097156693848522361803041977572204227262166","best_ask":"0.53","best_bid":"0.52","hash":"eace943cb65801afa9a0b4a4156e532e58772be9","price":"0.58","side":"SELL","size":"233"}],"timestamp":"1785121859848"},"payload_hash":"c7995aa88b6b82669d143c4acfb4900658d76ac0048e0e75b922889e4a6b9c6a","raw_frame":"{\"market\":\"0x717c0e8ccd4d5c7040185188fbae28be901ca589a11a94b1b38ca36a79eccfeb\", \"price_changes\":[{\"asset_id\":\"41448400836309843603620980831210604935021861034693225347475867885462478926555\", \"price\":\"0.42\", \"size\":\"233\", \"side\":\"BUY\", \"hash\":\"f56696c545e510adcaf032f3bf07eba7a7ef42df\", \"best_bid\":\"0.47\", \"best_ask\":\"0.48\"}, {\"asset_id\":\"24254094493625419915756280046002869097156693848522361803041977572204227262166\", \"price\":\"0.58\", \"size\":\"233\", \"side\":\"SELL\", \"hash\":\"eace943cb65801afa9a0b4a4156e532e58772be9\", \"best_bid\":\"0.52\", \"best_ask\":\"0.53\"}], \"timestamp\":\"1785121859848\", \"event_type\":\"price_change\"}","received_at":"2026-07-27T03:10:59.756591Z","schema_version":"clob-market-ws.price_change.v1","sequence":null,"server_hash":null,"server_timestamp":"1785121859848","session_id":"dd162b8dca5f43ff811d304e69a06123","source":"clob_market_ws"},"received_at":"2026-07-27T03:10:59.756591Z","record_id":"4a4cf5b910ee1edbe0459a5b6ba82b4404bc223a476c3b7a59c6ed113c372898","schema_fingerprint":"4aa3821a28b0b7c2400bc59aba4bcc0a76e971dadd19610d3ad38c768e124dc7","schema_version":"edge-lab-recorder.raw.v1","sequence":null,"source":"clob_market_ws"}
{"event_at":"2026-07-27T03:10:59.849000Z","event_fingerprint":"cf432a989352bbb8c4e5b6b7c78a124b7c0c646354a88806aa5959cc6ca0e9e1","payload":{"connection_id":"c7dc2e4762f849c6b6f9306b6518dcab","event_at":"2026-07-27T03:10:59.849000Z","event_type":"price_change","frame_hash":"d955f9cc4a9d87121265b7c6f3d2c2900e6636ece85e773bddbb3c0268a23e0a","frame_index":0,"kind":"data","monotonic_ns":223843088496666,"payload":{"event_type":"price_change","market":"0x717c0e8ccd4d5c7040185188fbae28be901ca589a11a94b1b38ca36a79eccfeb","price_changes":[{"asset_id":"41448400836309843603620980831210604935021861034693225347475867885462478926555","best_ask":"0.48","best_bid":"0.47","hash":"3d46a4dccaf3e2b2d5d32a87fdce1ca99b5db293","price":"0.42","side":"BUY","size":"238"},{"asset_id":"24254094493625419915756280046002869097156693848522361803041977572204227262166","best_ask":"0.53","best_bid":"0.52","hash":"cd77dcc58cc312acbe9eba61b31fbd5368ce38aa","price":"0.58","side":"SELL","size":"238"}],"timestamp":"1785121859849"},"payload_hash":"a13ad6b1060dd0412e7f3e26b006a6770c5a52539b1fbd88da07df3f2d225a02","raw_frame":"{\"market\":\"0x717c0e8ccd4d5c7040185188fbae28be901ca589a11a94b1b38ca36a79eccfeb\", \"price_changes\":[{\"asset_id\":\"41448400836309843603620980831210604935021861034693225347475867885462478926555\", \"price\":\"0.42\", \"size\":\"238\", \"side\":\"BUY\", \"hash\":\"3d46a4dccaf3e2b2d5d32a87fdce1ca99b5db293\", \"best_bid\":\"0.47\", \"best_ask\":\"0.48\"}, {\"asset_id\":\"24254094493625419915756280046002869097156693848522361803041977572204227262166\", \"price\":\"0.58\", \"size\":\"238\", \"side\":\"SELL\", \"hash\":\"cd77dcc58cc312acbe9eba61b31fbd5368ce38aa\", \"best_bid\":\"0.52\", \"best_ask\":\"0.53\"}], \"timestamp\":\"1785121859849\", \"event_type\":\"price_change\"}","received_at":"2026-07-27T03:10:59.758199Z","schema_version":"clob-market-ws.price_change.v1","sequence":null,"server_hash":null,"server_timestamp":"1785121859849","session_id":"dd162b8dca5f43ff811d304e69a06123","source":"clob_market_ws"},"received_at":"2026-07-27T03:10:59.758199Z","record_id":"f4c157826b75147aa05fa2ea763033df702f87dd6646180fb38349ff50db648c","schema_fingerprint":"4aa3821a28b0b7c2400bc59aba4bcc0a76e971dadd19610d3ad38c768e124dc7","schema_version":"edge-lab-recorder.raw.v1","sequence":null,"source":"clob_market_ws"}
{"event_at":"2026-07-27T03:10:59.850000Z","event_fingerprint":"c3d47699e0ca7f45a7b7fc217ea00640db496c6640bfb8d189268b3f5a608993","payload":{"connection_id":"c7dc2e4762f849c6b6f9306b6518dcab","event_at":"2026-07-27T03:10:59.850000Z","event_type":"price_change","frame_hash":"ec3d5468e4b7185c1c259c6dbb970a54241d625258d82df3ffeb2736c19956f4","frame_index":0,"kind":"data","monotonic_ns":223843091550583,"payload":{"event_type":"price_change","market":"0x717c0e8ccd4d5c7040185188fbae28be901ca589a11a94b1b38ca36a79eccfeb","price_changes":[{"asset_id":"41448400836309843603620980831210604935021861034693225347475867885462478926555","best_ask":"0.48","best_bid":"0.47","hash":"47ae3025446d3ee18627272c9ffe991f4aa4d5f9","price":"0.42","side":"BUY","size":"243"},{"asset_id":"24254094493625419915756280046002869097156693848522361803041977572204227262166","best_ask":"0.53","best_bid":"0.52","hash":"0432d379cd351a33cbbef3aa9d5c7ff9f17e4e37","price":"0.58","side":"SELL","size":"243"}],"timestamp":"1785121859850"},"payload_hash":"09bbd4b876b9f6a468af4cc7816b638db9b0ddc59cd0607f568ae56d7ffd6901","raw_frame":"{\"market\":\"0x717c0e8ccd4d5c7040185188fbae28be901ca589a11a94b1b38ca36a79eccfeb\", \"price_changes\":[{\"asset_id\":\"41448400836309843603620980831210604935021861034693225347475867885462478926555\", \"price\":\"0.42\", \"size\":\"243\", \"side\":\"BUY\", \"hash\":\"47ae3025446d3ee18627272c9ffe991f4aa4d5f9\", \"best_bid\":\"0.47\", \"best_ask\":\"0.48\"}, {\"asset_id\":\"24254094493625419915756280046002869097156693848522361803041977572204227262166\", \"price\":\"0.58\", \"size\":\"243\", \"side\":\"SELL\", \"hash\":\"0432d379cd351a33cbbef3aa9d5c7ff9f17e4e37\", \"best_bid\":\"0.52\", \"best_ask\":\"0.53\"}], \"timestamp\":\"1785121859850\", \"event_type\":\"price_change\"}","received_at":"2026-07-27T03:10:59.761252Z","schema_version":"clob-market-ws.price_change.v1","sequence":null,"server_hash":null,"server_timestamp":"1785121859850","session_id":"dd162b8dca5f43ff811d304e69a06123","source":"clob_market_ws"},"received_at":"2026-07-27T03:10:59.761252Z","record_id":"07185fe988a3847a8728f507e344e4f6520468939fbce79322d51cf6ab9e238e","schema_fingerprint":"4aa3821a28b0b7c2400bc59aba4bcc0a76e971dadd19610d3ad38c768e124dc7","schema_version":"edge-lab-recorder.raw.v1","sequence":null,"source":"clob_market_ws"}
{"event_at":"2026-07-27T03:10:59.850000Z","event_fingerprint":"4c14601cde3bfe15ab4812c539ac1358d16003da4a3c175569f182a5c5890aa4","payload":{"connection_id":"c7dc2e4762f849c6b6f9306b6518dcab","event_at":"2026-07-27T03:10:59.850000Z","event_type":"price_change","frame_hash":"eb030a967853451691379d82398ee60b4ba22b8fea9b0be203ba06d75c91c03e","frame_index":0,"kind":"data","monotonic_ns":223843093227791,"payload":{"event_type":"price_change","market":"0x717c0e8ccd4d5c7040185188fbae28be901ca589a11a94b1b38ca36a79eccfeb","price_changes":[{"asset_id":"41448400836309843603620980831210604935021861034693225347475867885462478926555","best_ask":"0.48","best_bid":"0.47","hash":"e3cbe484be7eb06aa26d89a34c0a4ae50bb10376","price":"0.42","side":"BUY","size":"248"},{"asset_id":"24254094493625419915756280046002869097156693848522361803041977572204227262166","best_ask":"0.53","best_bid":"0.52","hash":"a0705f9cdde9ca707c95de22710f3cb8de65917f","price":"0.58","side":"SELL","size":"248"}],"timestamp":"1785121859850"},"payload_hash":"f9324265d387df53c7b244e43b1d210bbe8b984cc1e5b1fbcee5f43cdba9dd18","raw_frame":"{\"market\":\"0x717c0e8ccd4d5c7040185188fbae28be901ca589a11a94b1b38ca36a79eccfeb\", \"price_changes\":[{\"asset_id\":\"41448400836309843603620980831210604935021861034693225347475867885462478926555\", \"price\":\"0.42\", \"size\":\"248\", \"side\":\"BUY\", \"hash\":\"e3cbe484be7eb06aa26d89a34c0a4ae50bb10376\", \"best_bid\":\"0.47\", \"best_ask\":\"0.48\"}, {\"asset_id\":\"24254094493625419915756280046002869097156693848522361803041977572204227262166\", \"price\":\"0.58\", \"size\":\"248\", \"side\":\"SELL\", \"hash\":\"a0705f9cdde9ca707c95de22710f3cb8de65917f\", \"best_bid\":\"0.52\", \"best_ask\":\"0.53\"}], \"timestamp\":\"1785121859850\", \"event_type\":\"price_change\"}","received_at":"2026-07-27T03:10:59.762931Z","schema_version":"clob-market-ws.price_change.v1","sequence":null,"server_hash":null,"server_timestamp":"1785121859850","session_id":"dd162b8dca5f43ff811d304e69a06123","source":"clob_market_ws"},"received_at":"2026-07-27T03:10:59.762931Z","record_id":"6cfb9b612e73a176efbd63051b7f810286a2bdda66e2191a6b456c6d9fb5819a","schema_fingerprint":"4aa3821a28b0b7c2400bc59aba4bcc0a76e971dadd19610d3ad38c768e124dc7","schema_version":"edge-lab-recorder.raw.v1","sequence":null,"source":"clob_market_ws"}
{"event_at":"2026-07-27T03:10:59.851000Z","event_fingerprint":"253df08a7f80c6897bb027ab7398f068e8a5bfe9d114f011cef4b534d1c4bda3","payload":{"connection_id":"c7dc2e4762f849c6b6f9306b6518dcab","event_at":"2026-07-27T03:10:59.851000Z","event_type":"price_change","frame_hash":"f3c8e02f80af3e695caabb3c0ecf7cc14bc74d57c82c43cfd08c3ef6a37ff53a","frame_index":0,"kind":"data","monotonic_ns":223843192769916,"payload":{"event_type":"price_change","market":"0x717c0e8ccd4d5c7040185188fbae28be901ca589a11a94b1b38ca36a79eccfeb","price_changes":[{"asset_id":"41448400836309843603620980831210604935021861034693225347475867885462478926555","best_ask":"0.48","best_bid":"0.47","hash":"c0e28fdaa868a08366be8239605cdd0a6db6dba6","price":"0.42","side":"BUY","size":"253"},{"asset_id":"24254094493625419915756280046002869097156693848522361803041977572204227262166","best_ask":"0.53","best_bid":"0.52","hash":"d7763423b9d92bab0f7d38a510d615c5340f42f6","price":"0.58","side":"SELL","size":"253"}],"timestamp":"1785121859851"},"payload_hash":"b4191c6668019aecd5717a84d736be1ca6962a56c00324068cf18bc193b31538","raw_frame":"{\"market\":\"0x717c0e8ccd4d5c7040185188fbae28be901ca589a11a94b1b38ca36a79eccfeb\", \"price_changes\":[{\"asset_id\":\"41448400836309843603620980831210604935021861034693225347475867885462478926555\", \"price\":\"0.42\", \"size\":\"253\", \"side\":\"BUY\", \"hash\":\"c0e28fdaa868a08366be8239605cdd0a6db6dba6\", \"best_bid\":\"0.47\", \"best_ask\":\"0.48\"}, {\"asset_id\":\"24254094493625419915756280046002869097156693848522361803041977572204227262166\", \"price\":\"0.58\", \"size\":\"253\", \"side\":\"SELL\", \"hash\":\"d7763423b9d92bab0f7d38a510d615c5340f42f6\", \"best_bid\":\"0.52\", \"best_ask\":\"0.53\"}], \"timestamp\":\"1785121859851\", \"event_type\":\"price_change\"}","received_at":"2026-07-27T03:10:59.862471Z","schema_version":"clob-market-ws.price_change.v1","sequence":null,"server_hash":null,"server_timestamp":"1785121859851","session_id":"dd162b8dca5f43ff811d304e69a06123","source":"clob_market_ws"},"received_at":"2026-07-27T03:10:59.862471Z","record_id":"4881670bf93bb7979e8a45adfd6c95c76fb1431e2635c97e7c76c0b821cf24d9","schema_fingerprint":"4aa3821a28b0b7c2400bc59aba4bcc0a76e971dadd19610d3ad38c768e124dc7","schema_version":"edge-lab-recorder.raw.v1","sequence":null,"source":"clob_market_ws"}
{"event_at":"2026-07-27T03:10:59.852000Z","event_fingerprint":"6d831d53c69cff0d84d95ba57edcad8c5c93c93ee6cc1d9f6d581ba346847b63","payload":{"connection_id":"c7dc2e4762f849c6b6f9306b6518dcab","event_at":"2026-07-27T03:10:59.852000Z","event_type":"price_change","frame_hash":"63190692c1b6c5a2812cfb021bf81e3b400448561d26e9eabb623b84a5c5e6c5","frame_index":0,"kind":"data","monotonic_ns":223843194289541,"payload":{"event_type":"price_change","market":"0x717c0e8ccd4d5c7040185188fbae28be901ca589a11a94b1b38ca36a79eccfeb","price_changes":[{"asset_id":"41448400836309843603620980831210604935021861034693225347475867885462478926555","best_ask":"0.48","best_bid":"0.47","hash":"2387e963f52d3e74d2d5efce690aac44622c475c","price":"0.42","side":"BUY","size":"258"},{"asset_id":"24254094493625419915756280046002869097156693848522361803041977572204227262166","best_ask":"0.53","best_bid":"0.52","hash":"f6c8a6eb7ed4974b209c017b8dbfd2d23f693f61","price":"0.58","side":"SELL","size":"258"}],"timestamp":"1785121859852"},"payload_hash":"91129edf9543dfc72ca7c8f93bc09ace4028be20beb71568cefbf37dd589e398","raw_frame":"{\"market\":\"0x717c0e8ccd4d5c7040185188fbae28be901ca589a11a94b1b38ca36a79eccfeb\", \"price_changes\":[{\"asset_id\":\"41448400836309843603620980831210604935021861034693225347475867885462478926555\", \"price\":\"0.42\", \"size\":\"258\", \"side\":\"BUY\", \"hash\":\"2387e963f52d3e74d2d5efce690aac44622c475c\", \"best_bid\":\"0.47\", \"best_ask\":\"0.48\"}, {\"asset_id\":\"24254094493625419915756280046002869097156693848522361803041977572204227262166\", \"price\":\"0.58\", \"size\":\"258\", \"side\":\"SELL\", \"hash\":\"f6c8a6eb7ed4974b209c017b8dbfd2d23f693f61\", \"best_bid\":\"0.52\", \"best_ask\":\"0.53\"}], \"timestamp\":\"1785121859852\", \"event_type\":\"price_change\"}","received_at":"2026-07-27T03:10:59.863990Z","schema_version":"clob-market-ws.price_change.v1","sequence":null,"server_hash":null,"server_timestamp":"1785121859852","session_id":"dd162b8dca5f43ff811d304e69a06123","source":"clob_market_ws"},"received_at":"2026-07-27T03:10:59.863990Z","record_id":"6badbc65e6c3f2d179340179264f114cd28e88fab181b5ef352cd77c2b7a8456","schema_fingerprint":"4aa3821a28b0b7c2400bc59aba4bcc0a76e971dadd19610d3ad38c768e124dc7","schema_version":"edge-lab-recorder.raw.v1","sequence":null,"source":"clob_market_ws"}
{"event_at":"2026-07-27T03:10:59.852000Z","event_fingerprint":"086b37302191b170d5dade730f9b891c0924c683894361d3c6b5692e47d5b893","payload":{"connection_id":"c7dc2e4762f849c6b6f9306b6518dcab","event_at":"2026-07-27T03:10:59.852000Z","event_type":"price_change","frame_hash":"01ffb42b3476d6c080f4e341fcc5e81f210b37be743ee6477a5437bb636095ac","frame_index":0,"kind":"data","monotonic_ns":223843196004625,"payload":{"event_type":"price_change","market":"0x717c0e8ccd4d5c7040185188fbae28be901ca589a11a94b1b38ca36a79eccfeb","price_changes":[{"asset_id":"41448400836309843603620980831210604935021861034693225347475867885462478926555","best_ask":"0.48","best_bid":"0.47","hash":"226aa0d7a5ca1b84be78f16ae45f982b4e19d353","price":"0.42","side":"BUY","size":"263"},{"asset_id":"24254094493625419915756280046002869097156693848522361803041977572204227262166","best_ask":"0.53","best_bid":"0.52","hash":"8ec621c8323534afe6ff17708913be5963a377b6","price":"0.58","side":"SELL","size":"263"}],"timestamp":"1785121859852"},"payload_hash":"df1e1203e4d6922eb650c7f455365b595204a79436bd2909ed98bb58fcbe1802","raw_frame":"{\"market\":\"0x717c0e8ccd4d5c7040185188fbae28be901ca589a11a94b1b38ca36a79eccfeb\", \"price_changes\":[{\"asset_id\":\"41448400836309843603620980831210604935021861034693225347475867885462478926555\", \"price\":\"0.42\", \"size\":\"263\", \"side\":\"BUY\", \"hash\":\"226aa0d7a5ca1b84be78f16ae45f982b4e19d353\", \"best_bid\":\"0.47\", \"best_ask\":\"0.48\"}, {\"asset_id\":\"24254094493625419915756280046002869097156693848522361803041977572204227262166\", \"price\":\"0.58\", \"size\":\"263\", \"side\":\"SELL\", \"hash\":\"8ec621c8323534afe6ff17708913be5963a377b6\", \"best_bid\":\"0.52\", \"best_ask\":\"0.53\"}], \"timestamp\":\"1785121859852\", \"event_type\":\"price_change\"}","received_at":"2026-07-27T03:10:59.865705Z","schema_version":"clob-market-ws.price_change.v1","sequence":null,"server_hash":null,"server_timestamp":"1785121859852","session_id":"dd162b8dca5f43ff811d304e69a06123","source":"clob_market_ws"},"received_at":"2026-07-27T03:10:59.865705Z","record_id":"21f86e2c63681a385a5b063534cfdef260e7ca2722eea6adb6b88c060155dc34","schema_fingerprint":"4aa3821a28b0b7c2400bc59aba4bcc0a76e971dadd19610d3ad38c768e124dc7","schema_version":"edge-lab-recorder.raw.v1","sequence":null,"source":"clob_market_ws"}
{"event_at":"2026-07-27T03:10:59.853000Z","event_fingerprint":"c951942e84594b9e665cb6fdcbcc586ab85e9b0d3c229ad0f2ff336fa3c593e0","payload":{"connection_id":"c7dc2e4762f849c6b6f9306b6518dcab","event_at":"2026-07-27T03:10:59.853000Z","event_type":"price_change","frame_hash":"6b936a0b42baafde218e13169c2e41b14be7e2318d7a5f727314d8568084c691","frame_index":0,"kind":"data","monotonic_ns":223843197542041,"payload":{"event_type":"price_change","market":"0x717c0e8ccd4d5c7040185188fbae28be901ca589a11a94b1b38ca36a79eccfeb","price_changes":[{"asset_id":"41448400836309843603620980831210604935021861034693225347475867885462478926555","best_ask":"0.48","best_bid":"0.47","hash":"bd1ee25a8f718d77bd4f50e168d5d029d9bb9a69","price":"0.42","side":"BUY","size":"268"},{"asset_id":"24254094493625419915756280046002869097156693848522361803041977572204227262166","best_ask":"0.53","best_bid":"0.52","hash":"09df4f969f98b08d134a4aef9e5ee326ab65a7d5","price":"0.58","side":"SELL","size":"268"}],"timestamp":"1785121859853"},"payload_hash":"36ce581dbb6adcea184b6c474afb889c976c4b47419ce453e0685252b7e64a35","raw_frame":"{\"market\":\"0x717c0e8ccd4d5c7040185188fbae28be901ca589a11a94b1b38ca36a79eccfeb\", \"price_changes\":[{\"asset_id\":\"41448400836309843603620980831210604935021861034693225347475867885462478926555\", \"price\":\"0.42\", \"size\":\"268\", \"side\":\"BUY\", \"hash\":\"bd1ee25a8f718d77bd4f50e168d5d029d9bb9a69\", \"best_bid\":\"0.47\", \"best_ask\":\"0.48\"}, {\"asset_id\":\"24254094493625419915756280046002869097156693848522361803041977572204227262166\", \"price\":\"0.58\", \"size\":\"268\", \"side\":\"SELL\", \"hash\":\"09df4f969f98b08d134a4aef9e5ee326ab65a7d5\", \"best_bid\":\"0.52\", \"best_ask\":\"0.53\"}], \"timestamp\":\"1785121859853\", \"event_type\":\"price_change\"}","received_at":"2026-07-27T03:10:59.867250Z","schema_version":"clob-market-ws.price_change.v1","sequence":null,"server_hash":null,"server_timestamp":"1785121859853","session_id":"dd162b8dca5f43ff811d304e69a06123","source":"clob_market_ws"},"received_at":"2026-07-27T03:10:59.867250Z","record_id":"edb2f9db0e7695c0edb4a756ad61f4fc4b6e84d8b79dc6bcc12f3da56afa47ef","schema_fingerprint":"4aa3821a28b0b7c2400bc59aba4bcc0a76e971dadd19610d3ad38c768e124dc7","schema_version":"edge-lab-recorder.raw.v1","sequence":null,"source":"clob_market_ws"}
{"event_at":"2026-07-27T03:10:59.875000Z","event_fingerprint":"ebef93eff74a885498987c2b8acd43812809d5b69214589bc23ac01d522acf5d","payload":{"connection_id":"c7dc2e4762f849c6b6f9306b6518dcab","event_at":"2026-07-27T03:10:59.875000Z","event_type":"price_change","frame_hash":"2f0eb65cc88abc2903a3b9069edccfd4f7f51aba81bd7cd971600c9cb12ec418","frame_index":0,"kind":"data","monotonic_ns":223843198067958,"payload":{"event_type":"price_change","market":"0x717c0e8ccd4d5c7040185188fbae28be901ca589a11a94b1b38ca36a79eccfeb","price_changes":[{"asset_id":"41448400836309843603620980831210604935021861034693225347475867885462478926555","best_ask":"0.48","best_bid":"0.47","hash":"1954008155af49bb8d6f5335a5710b5c97843ee8","price":"0.42","side":"BUY","size":"273"},{"asset_id":"24254094493625419915756280046002869097156693848522361803041977572204227262166","best_ask":"0.53","best_bid":"0.52","hash":"91ba45f133251e688f6c9b9649145ea6d8bb4d2d","price":"0.58","side":"SELL","size":"273"}],"timestamp":"1785121859875"},"payload_hash":"a3f157cc4d3f7448c236cb7b24aa4c5cdfb4ce1b26fe25a1c8854e3502ec64fd","raw_frame":"{\"market\":\"0x717c0e8ccd4d5c7040185188fbae28be901ca589a11a94b1b38ca36a79eccfeb\", \"price_changes\":[{\"asset_id\":\"41448400836309843603620980831210604935021861034693225347475867885462478926555\", \"price\":\"0.42\", \"size\":\"273\", \"side\":\"BUY\", \"hash\":\"1954008155af49bb8d6f5335a5710b5c97843ee8\", \"best_bid\":\"0.47\", \"best_ask\":\"0.48\"}, {\"asset_id\":\"24254094493625419915756280046002869097156693848522361803041977572204227262166\", \"price\":\"0.58\", \"size\":\"273\", \"side\":\"SELL\", \"hash\":\"91ba45f133251e688f6c9b9649145ea6d8bb4d2d\", \"best_bid\":\"0.52\", \"best_ask\":\"0.53\"}], \"timestamp\":\"1785121859875\", \"event_type\":\"price_change\"}","received_at":"2026-07-27T03:10:59.867775Z","schema_version":"clob-market-ws.price_change.v1","sequence":null,"server_hash":null,"server_timestamp":"1785121859875","session_id":"dd162b8dca5f43ff811d304e69a06123","source":"clob_market_ws"},"received_at":"2026-07-27T03:10:59.867775Z","record_id":"9f92ba208b629decc5f77b16713346013caa7a9c3836d36ad8eecf62f8ed9377","schema_fingerprint":"4aa3821a28b0b7c2400bc59aba4bcc0a76e971dadd19610d3ad38c768e124dc7","schema_version":"edge-lab-recorder.raw.v1","sequence":null,"source":"clob_market_ws"}
{"event_at":"2026-07-27T03:10:59.875000Z","event_fingerprint":"4d89639c0af590010db209a65c96d459bd0db1c918cf4f5e44ea23a30c394724","payload":{"connection_id":"c7dc2e4762f849c6b6f9306b6518dcab","event_at":"2026-07-27T03:10:59.875000Z","event_type":"price_change","frame_hash":"5044d222c43b32eeadc63980b3bc3ff16b5b4c89dfcf5e3a8dacaf34b8ecc59d","frame_index":0,"kind":"data","monotonic_ns":223843199527291,"payload":{"event_type":"price_change","market":"0x717c0e8ccd4d5c7040185188fbae28be901ca589a11a94b1b38ca36a79eccfeb","price_changes":[{"asset_id":"41448400836309843603620980831210604935021861034693225347475867885462478926555","best_ask":"0.48","best_bid":"0.47","hash":"881ab5ccb8717c64e38caf351cbce2c066561c87","price":"0.42","side":"BUY","size":"278"},{"asset_id":"24254094493625419915756280046002869097156693848522361803041977572204227262166","best_ask":"0.53","best_bid":"0.52","hash":"81ce1ff85fc4079beb4ab68322c0da0e69678332","price":"0.58","side":"SELL","size":"278"}],"timestamp":"1785121859875"},"payload_hash":"8b5794c45d9d7aef16fe535f405e7b9f7e5949a4fe777cb2245d95f51484523d","raw_frame":"{\"market\":\"0x717c0e8ccd4d5c7040185188fbae28be901ca589a11a94b1b38ca36a79eccfeb\", \"price_changes\":[{\"asset_id\":\"41448400836309843603620980831210604935021861034693225347475867885462478926555\", \"price\":\"0.42\", \"size\":\"278\", \"side\":\"BUY\", \"hash\":\"881ab5ccb8717c64e38caf351cbce2c066561c87\", \"best_bid\":\"0.47\", \"best_ask\":\"0.48\"}, {\"asset_id\":\"24254094493625419915756280046002869097156693848522361803041977572204227262166\", \"price\":\"0.58\", \"size\":\"278\", \"side\":\"SELL\", \"hash\":\"81ce1ff85fc4079beb4ab68322c0da0e69678332\", \"best_bid\":\"0.52\", \"best_ask\":\"0.53\"}], \"timestamp\":\"1785121859875\", \"event_type\":\"price_change\"}","received_at":"2026-07-27T03:10:59.869228Z","schema_version":"clob-market-ws.price_change.v1","sequence":null,"server_hash":null,"server_timestamp":"1785121859875","session_id":"dd162b8dca5f43ff811d304e69a06123","source":"clob_market_ws"},"received_at":"2026-07-27T03:10:59.869228Z","record_id":"2a3a224f4d073ff249e9633d152ef5c2be2b6ef85a8854a1a003e0c397e3d114","schema_fingerprint":"4aa3821a28b0b7c2400bc59aba4bcc0a76e971dadd19610d3ad38c768e124dc7","schema_version":"edge-lab-recorder.raw.v1","sequence":null,"source":"clob_market_ws"}
{"event_at":"2026-07-27T03:10:59.876000Z","event_fingerprint":"44bac5362ef3bfe263147fe82e307ea4193cf8df1cd79d2c0cb8c04c73801cb0","payload":{"connection_id":"c7dc2e4762f849c6b6f9306b6518dcab","event_at":"2026-07-27T03:10:59.876000Z","event_type":"price_change","frame_hash":"cb7d9295e84ac1621add99be1f2990bcb192a5753a96bde19901f4ad0a8d8592","frame_index":0,"kind":"data","monotonic_ns":223843202513750,"payload":{"event_type":"price_change","market":"0x717c0e8ccd4d5c7040185188fbae28be901ca589a11a94b1b38ca36a79eccfeb","price_changes":[{"asset_id":"41448400836309843603620980831210604935021861034693225347475867885462478926555","best_ask":"0.48","best_bid":"0.47","hash":"fbaaa19b538dfbbb6330e51ba822b63c99401457","price":"0.42","side":"BUY","size":"283"},{"asset_id":"24254094493625419915756280046002869097156693848522361803041977572204227262166","best_ask":"0.53","best_bid":"0.52","hash":"e113990fc163b6a99f286680deec71459c5f17a5","price":"0.58","side":"SELL","size":"283"}],"timestamp":"1785121859876"},"payload_hash":"5431ca187a46086e5b2b777a3c803147caf5ce212d87aec1cfcd41faa26a0b6e","raw_frame":"{\"market\":\"0x717c0e8ccd4d5c7040185188fbae28be901ca589a11a94b1b38ca36a79eccfeb\", \"price_changes\":[{\"asset_id\":\"41448400836309843603620980831210604935021861034693225347475867885462478926555\", \"price\":\"0.42\", \"size\":\"283\", \"side\":\"BUY\", \"hash\":\"fbaaa19b538dfbbb6330e51ba822b63c99401457\", \"best_bid\":\"0.47\", \"best_ask\":\"0.48\"}, {\"asset_id\":\"24254094493625419915756280046002869097156693848522361803041977572204227262166\", \"price\":\"0.58\", \"size\":\"283\", \"side\":\"SELL\", \"hash\":\"e113990fc163b6a99f286680deec71459c5f17a5\", \"best_bid\":\"0.52\", \"best_ask\":\"0.53\"}], \"timestamp\":\"1785121859876\", \"event_type\":\"price_change\"}","received_at":"2026-07-27T03:10:59.872215Z","schema_version":"clob-market-ws.price_change.v1","sequence":null,"server_hash":null,"server_timestamp":"1785121859876","session_id":"dd162b8dca5f43ff811d304e69a06123","source":"clob_market_ws"},"received_at":"2026-07-27T03:10:59.872215Z","record_id":"488f8b02936c13f706c0d8a6ced17733daac9e95deedea7c37a0c41e47d578f7","schema_fingerprint":"4aa3821a28b0b7c2400bc59aba4bcc0a76e971dadd19610d3ad38c768e124dc7","schema_version":"edge-lab-recorder.raw.v1","sequence":null,"source":"clob_market_ws"}
{"event_at":"2026-07-27T03:10:59.877000Z","event_fingerprint":"19e454c8643de9cccad068e16bbaed2f68fd320dc3f73020a3a89c05597102c5","payload":{"connection_id":"c7dc2e4762f849c6b6f9306b6518dcab","event_at":"2026-07-27T03:10:59.877000Z","event_type":"price_change","frame_hash":"e881e2acfa1f647ea0ea5d969519802509328da799515a7e0ba4ea2bbb0b8a33","frame_index":0,"kind":"data","monotonic_ns":223843204124916,"payload":{"event_type":"price_change","market":"0x717c0e8ccd4d5c7040185188fbae28be901ca589a11a94b1b38ca36a79eccfeb","price_changes":[{"asset_id":"41448400836309843603620980831210604935021861034693225347475867885462478926555","best_ask":"0.48","best_bid":"0.47","hash":"4e412b43800d499348c9cc2cd80f1a35536f8c04","price":"0.42","side":"BUY","size":"288"},{"asset_id":"24254094493625419915756280046002869097156693848522361803041977572204227262166","best_ask":"0.53","best_bid":"0.52","hash":"af250a6a06862d98bec238e5b93c2e5bd9793070","price":"0.58","side":"SELL","size":"288"}],"timestamp":"1785121859877"},"payload_hash":"53203723c3d6304f81d651d2ad30e8c45ada22130359578560af7c65c4e5c97d","raw_frame":"{\"market\":\"0x717c0e8ccd4d5c7040185188fbae28be901ca589a11a94b1b38ca36a79eccfeb\", \"price_changes\":[{\"asset_id\":\"41448400836309843603620980831210604935021861034693225347475867885462478926555\", \"price\":\"0.42\", \"size\":\"288\", \"side\":\"BUY\", \"hash\":\"4e412b43800d499348c9cc2cd80f1a35536f8c04\", \"best_bid\":\"0.47\", \"best_ask\":\"0.48\"}, {\"asset_id\":\"24254094493625419915756280046002869097156693848522361803041977572204227262166\", \"price\":\"0.58\", \"size\":\"288\", \"side\":\"SELL\", \"hash\":\"af250a6a06862d98bec238e5b93c2e5bd9793070\", \"best_bid\":\"0.52\", \"best_ask\":\"0.53\"}], \"timestamp\":\"1785121859877\", \"event_type\":\"price_change\"}","received_at":"2026-07-27T03:10:59.873826Z","schema_version":"clob-market-ws.price_change.v1","sequence":null,"server_hash":null,"server_timestamp":"1785121859877","session_id":"dd162b8dca5f43ff811d304e69a06123","source":"clob_market_ws"},"received_at":"2026-07-27T03:10:59.873826Z","record_id":"5b2db77cfc263f73cee366a97f262cbf5fae81f6428537b4181692fd9f28190a","schema_fingerprint":"4aa3821a28b0b7c2400bc59aba4bcc0a76e971dadd19610d3ad38c768e124dc7","schema_version":"edge-lab-recorder.raw.v1","sequence":null,"source":"clob_market_ws"}
{"event_at":"2026-07-27T03:10:59.878000Z","event_fingerprint":"e93331653363b207328d2e2633dd449790514a4b845f5ceee2df003dec19b615","payload":{"connection_id":"c7dc2e4762f849c6b6f9306b6518dcab","event_at":"2026-07-27T03:10:59.878000Z","event_type":"price_change","frame_hash":"fa96d9eec627e6efbbc2f55ee713accca69fdd7dacf62f8cc5add49fdc66d8de","frame_index":0,"kind":"data","monotonic_ns":223843205677750,"payload":{"event_type":"price_change","market":"0x717c0e8ccd4d5c7040185188fbae28be901ca589a11a94b1b38ca36a79eccfeb","price_changes":[{"asset_id":"41448400836309843603620980831210604935021861034693225347475867885462478926555","best_ask":"0.48","best_bid":"0.47","hash":"cce839f64d56dc69552f9aaa18ab87cd029990a3","price":"0.42","side":"BUY","size":"293"},{"asset_id":"24254094493625419915756280046002869097156693848522361803041977572204227262166","best_ask":"0.53","best_bid":"0.52","hash":"ff35c0170fb880e8d10f9d6233e63395d9b47f5b","price":"0.58","side":"SELL","size":"293"}],"timestamp":"1785121859878"},"payload_hash":"42928599ec2366ba9ebcbb119287986cbb9fafdbe3e4dc41d8d4bbbdcc3a4e41","raw_frame":"{\"market\":\"0x717c0e8ccd4d5c7040185188fbae28be901ca589a11a94b1b38ca36a79eccfeb\", \"price_changes\":[{\"asset_id\":\"41448400836309843603620980831210604935021861034693225347475867885462478926555\", \"price\":\"0.42\", \"size\":\"293\", \"side\":\"BUY\", \"hash\":\"cce839f64d56dc69552f9aaa18ab87cd029990a3\", \"best_bid\":\"0.47\", \"best_ask\":\"0.48\"}, {\"asset_id\":\"24254094493625419915756280046002869097156693848522361803041977572204227262166\", \"price\":\"0.58\", \"size\":\"293\", \"side\":\"SELL\", \"hash\":\"ff35c0170fb880e8d10f9d6233e63395d9b47f5b\", \"best_bid\":\"0.52\", \"best_ask\":\"0.53\"}], \"timestamp\":\"1785121859878\", \"event_type\":\"price_change\"}","received_at":"2026-07-27T03:10:59.875379Z","schema_version":"clob-market-ws.price_change.v1","sequence":null,"server_hash":null,"server_timestamp":"1785121859878","session_id":"dd162b8dca5f43ff811d304e69a06123","source":"clob_market_ws"},"received_at":"2026-07-27T03:10:59.875379Z","record_id":"67be6f60b48f26c52258d4c9ab2fbc7782b49d59dd513829d645c7bcbb79888d","schema_fingerprint":"4aa3821a28b0b7c2400bc59aba4bcc0a76e971dadd19610d3ad38c768e124dc7","schema_version":"edge-lab-recorder.raw.v1","sequence":null,"source":"clob_market_ws"}
{"event_at":"2026-07-27T03:10:59.879000Z","event_fingerprint":"90047f21f79e35d12174125ff64e100835a538a0add20908e74e61358b7c3caa","payload":{"connection_id":"c7dc2e4762f849c6b6f9306b6518dcab","event_at":"2026-07-27T03:10:59.879000Z","event_type":"price_change","frame_hash":"14364e27b579d398ee61cd8f45f544a5123672b6948249adc020bd39eda09f0e","frame_index":0,"kind":"data","monotonic_ns":223843207206583,"payload":{"event_type":"price_change","market":"0x717c0e8ccd4d5c7040185188fbae28be901ca589a11a94b1b38ca36a79eccfeb","price_changes":[{"asset_id":"41448400836309843603620980831210604935021861034693225347475867885462478926555","best_ask":"0.48","best_bid":"0.47","hash":"467f5577b9d17ba03d7e6b88873850b446513633","price":"0.42","side":"BUY","size":"298"},{"asset_id":"24254094493625419915756280046002869097156693848522361803041977572204227262166","best_ask":"0.53","best_bid":"0.52","hash":"dd766b68d84c681044e8e960146be296a18fed04","price":"0.58","side":"SELL","size":"298"}],"timestamp":"1785121859879"},"payload_hash":"570c9115d3b75b9aaf1c5972ee6e6fa252d7e6a544faac8cdff21dc022d393ca","raw_frame":"{\"market\":\"0x717c0e8ccd4d5c7040185188fbae28be901ca589a11a94b1b38ca36a79eccfeb\", \"price_changes\":[{\"asset_id\":\"41448400836309843603620980831210604935021861034693225347475867885462478926555\", \"price\":\"0.42\", \"size\":\"298\", \"side\":\"BUY\", \"hash\":\"467f5577b9d17ba03d7e6b88873850b446513633\", \"best_bid\":\"0.47\", \"best_ask\":\"0.48\"}, {\"asset_id\":\"24254094493625419915756280046002869097156693848522361803041977572204227262166\", \"price\":\"0.58\", \"size\":\"298\", \"side\":\"SELL\", \"hash\":\"dd766b68d84c681044e8e960146be296a18fed04\", \"best_bid\":\"0.52\", \"best_ask\":\"0.53\"}], \"timestamp\":\"1785121859879\", \"event_type\":\"price_change\"}","received_at":"2026-07-27T03:10:59.876908Z","schema_version":"clob-market-ws.price_change.v1","sequence":null,"server_hash":null,"server_timestamp":"1785121859879","session_id":"dd162b8dca5f43ff811d304e69a06123","source":"clob_market_ws"},"received_at":"2026-07-27T03:10:59.876908Z","record_id":"d4d3c47e1295bfe8997ef0eac9295ab08a8beeeecde7718980fab3e2a3beb82a","schema_fingerprint":"4aa3821a28b0b7c2400bc59aba4bcc0a76e971dadd19610d3ad38c768e124dc7","schema_version":"edge-lab-recorder.raw.v1","sequence":null,"source":"clob_market_ws"}
{"event_at":"2026-07-27T03:10:59.880000Z","event_fingerprint":"84f81985fdfc2d7b8d95a78bb3b9ae5a8133991ee7f864d6472d62cbbb9b0200","payload":{"connection_id":"c7dc2e4762f849c6b6f9306b6518dcab","event_at":"2026-07-27T03:10:59.880000Z","event_type":"price_change","frame_hash":"f76d0eca516de2814a9d841de058593b1722cfc9f339b1d962866e5411935f3a","frame_index":0,"kind":"data","monotonic_ns":223843210224958,"payload":{"event_type":"price_change","market":"0x717c0e8ccd4d5c7040185188fbae28be901ca589a11a94b1b38ca36a79eccfeb","price_changes":[{"asset_id":"41448400836309843603620980831210604935021861034693225347475867885462478926555","best_ask":"0.48","best_bid":"0.47","hash":"e98ebd7bfb5b50176685350107e2ff7fb0fa23e4","price":"0.42","side":"BUY","size":"303"},{"asset_id":"24254094493625419915756280046002869097156693848522361803041977572204227262166","best_ask":"0.53","best_bid":"0.52","hash":"4f619fbbc939bec4f45ad4373578800d96f8bb81","price":"0.58","side":"SELL","size":"303"}],"timestamp":"1785121859880"},"payload_hash":"8977d9cf940edaef158bdb7c9df3bded289151e8125f81af032fd48f2fa7107a","raw_frame":"{\"market\":\"0x717c0e8ccd4d5c7040185188fbae28be901ca589a11a94b1b38ca36a79eccfeb\", \"price_changes\":[{\"asset_id\":\"41448400836309843603620980831210604935021861034693225347475867885462478926555\", \"price\":\"0.42\", \"size\":\"303\", \"side\":\"BUY\", \"hash\":\"e98ebd7bfb5b50176685350107e2ff7fb0fa23e4\", \"best_bid\":\"0.47\", \"best_ask\":\"0.48\"}, {\"asset_id\":\"24254094493625419915756280046002869097156693848522361803041977572204227262166\", \"price\":\"0.58\", \"size\":\"303\", \"side\":\"SELL\", \"hash\":\"4f619fbbc939bec4f45ad4373578800d96f8bb81\", \"best_bid\":\"0.52\", \"best_ask\":\"0.53\"}], \"timestamp\":\"1785121859880\", \"event_type\":\"price_change\"}","received_at":"2026-07-27T03:10:59.879924Z","schema_version":"clob-market-ws.price_change.v1","sequence":null,"server_hash":null,"server_timestamp":"1785121859880","session_id":"dd162b8dca5f43ff811d304e69a06123","source":"clob_market_ws"},"received_at":"2026-07-27T03:10:59.879924Z","record_id":"25747518ea4f097bf2a95d218c58fa8a36bcb130be388736903d9a06e9ae9423","schema_fingerprint":"4aa3821a28b0b7c2400bc59aba4bcc0a76e971dadd19610d3ad38c768e124dc7","schema_version":"edge-lab-recorder.raw.v1","sequence":null,"source":"clob_market_ws"}
{"event_at":"2026-07-27T03:10:59.880000Z","event_fingerprint":"ea2f45b344e52a9d99ecfee38f55e165a7794d9e80cccd8266c8e1e8adbc4369","payload":{"connection_id":"c7dc2e4762f849c6b6f9306b6518dcab","event_at":"2026-07-27T03:10:59.880000Z","event_type":"price_change","frame_hash":"cc34372602251f552881eea569452af8db79a9b895fa2c228f64be4da548f0bf","frame_index":0,"kind":"data","monotonic_ns":223843214171041,"payload":{"event_type":"price_change","market":"0x717c0e8ccd4d5c7040185188fbae28be901ca589a11a94b1b38ca36a79eccfeb","price_changes":[{"asset_id":"41448400836309843603620980831210604935021861034693225347475867885462478926555","best_ask":"0.48","best_bid":"0.47","hash":"a408e082df6a2294b72d98c493062191d37ed669","price":"0.42","side":"BUY","size":"308"},{"asset_id":"24254094493625419915756280046002869097156693848522361803041977572204227262166","best_ask":"0.53","best_bid":"0.52","hash":"494b3db02213bea31d783f123aff5c2d61c2dee8","price":"0.58","side":"SELL","size":"308"}],"timestamp":"1785121859880"},"payload_hash":"005dfeac1145257bb9ade9f22e09a2c5d58946167838b3f62f05875455184c79","raw_frame":"{\"market\":\"0x717c0e8ccd4d5c7040185188fbae28be901ca589a11a94b1b38ca36a79eccfeb\", \"price_changes\":[{\"asset_id\":\"41448400836309843603620980831210604935021861034693225347475867885462478926555\", \"price\":\"0.42\", \"size\":\"308\", \"side\":\"BUY\", \"hash\":\"a408e082df6a2294b72d98c493062191d37ed669\", \"best_bid\":\"0.47\", \"best_ask\":\"0.48\"}, {\"asset_id\":\"24254094493625419915756280046002869097156693848522361803041977572204227262166\", \"price\":\"0.58\", \"size\":\"308\", \"side\":\"SELL\", \"hash\":\"494b3db02213bea31d783f123aff5c2d61c2dee8\", \"best_bid\":\"0.52\", \"best_ask\":\"0.53\"}], \"timestamp\":\"1785121859880\", \"event_type\":\"price_change\"}","received_at":"2026-07-27T03:10:59.883879Z","schema_version":"clob-market-ws.price_change.v1","sequence":null,"server_hash":null,"server_timestamp":"1785121859880","session_id":"dd162b8dca5f43ff811d304e69a06123","source":"clob_market_ws"},"received_at":"2026-07-27T03:10:59.883879Z","record_id":"3e409ea059121c8fcab55f5448f095b6c133eea0e1f7e50780e3bd5ea536f413","schema_fingerprint":"4aa3821a28b0b7c2400bc59aba4bcc0a76e971dadd19610d3ad38c768e124dc7","schema_version":"edge-lab-recorder.raw.v1","sequence":null,"source":"clob_market_ws"}
{"event_at":"2026-07-27T03:10:59.881000Z","event_fingerprint":"03c63c7d44fe742ab82884a59101dc8e182a1ad238d2966cd731fc8b7eaddbea","payload":{"connection_id":"c7dc2e4762f849c6b6f9306b6518dcab","event_at":"2026-07-27T03:10:59.881000Z","event_type":"price_change","frame_hash":"7546a2fc90d7e24e4d2e6479e540f07376ff56220f074759d4666d5dcba7a342","frame_index":0,"kind":"data","monotonic_ns":223843217183458,"payload":{"event_type":"price_change","market":"0x717c0e8ccd4d5c7040185188fbae28be901ca589a11a94b1b38ca36a79eccfeb","price_changes":[{"asset_id":"41448400836309843603620980831210604935021861034693225347475867885462478926555","best_ask":"0.48","best_bid":"0.47","hash":"23f14b516e938263c386a780c5c53006d0ca275f","price":"0.42","side":"BUY","size":"313"},{"asset_id":"24254094493625419915756280046002869097156693848522361803041977572204227262166","best_ask":"0.53","best_bid":"0.52","hash":"c7bae205f53efe4d3457a6ef51c9d24a1e8de849","price":"0.58","side":"SELL","size":"313"}],"timestamp":"1785121859881"},"payload_hash":"94063e87880d64bc1db19599fbdacce647dee88c8081b246e931f1a6b155b0c8","raw_frame":"{\"market\":\"0x717c0e8ccd4d5c7040185188fbae28be901ca589a11a94b1b38ca36a79eccfeb\", \"price_changes\":[{\"asset_id\":\"41448400836309843603620980831210604935021861034693225347475867885462478926555\", \"price\":\"0.42\", \"size\":\"313\", \"side\":\"BUY\", \"hash\":\"23f14b516e938263c386a780c5c53006d0ca275f\", \"best_bid\":\"0.47\", \"best_ask\":\"0.48\"}, {\"asset_id\":\"24254094493625419915756280046002869097156693848522361803041977572204227262166\", \"price\":\"0.58\", \"size\":\"313\", \"side\":\"SELL\", \"hash\":\"c7bae205f53efe4d3457a6ef51c9d24a1e8de849\", \"best_bid\":\"0.52\", \"best_ask\":\"0.53\"}], \"timestamp\":\"1785121859881\", \"event_type\":\"price_change\"}","received_at":"2026-07-27T03:10:59.886885Z","schema_version":"clob-market-ws.price_change.v1","sequence":null,"server_hash":null,"server_timestamp":"1785121859881","session_id":"dd162b8dca5f43ff811d304e69a06123","source":"clob_market_ws"},"received_at":"2026-07-27T03:10:59.886885Z","record_id":"fe024fb1d212f4cb05dfeff811afc0d4fb066f8a937960aebaea604b8283aa0d","schema_fingerprint":"4aa3821a28b0b7c2400bc59aba4bcc0a76e971dadd19610d3ad38c768e124dc7","schema_version":"edge-lab-recorder.raw.v1","sequence":null,"source":"clob_market_ws"}
{"event_at":"2026-07-27T03:10:59.882000Z","event_fingerprint":"29166537fe0883c3a2d9973c1d395220eb389b180964a85e0e8f42fbff34bdf8","payload":{"connection_id":"c7dc2e4762f849c6b6f9306b6518dcab","event_at":"2026-07-27T03:10:59.882000Z","event_type":"price_change","frame_hash":"6bb0eb0dbbc3ca482ca35ce9a8bbb9165fa2feaea0b7f6a239adbcde63a21166","frame_index":0,"kind":"data","monotonic_ns":223843220953375,"payload":{"event_type":"price_change","market":"0x717c0e8ccd4d5c7040185188fbae28be901ca589a11a94b1b38ca36a79eccfeb","price_changes":[{"asset_id":"41448400836309843603620980831210604935021861034693225347475867885462478926555","best_ask":"0.48","best_bid":"0.47","hash":"e9d7d8309504801ff85d49f767d428d5d62a1e0c","price":"0.42","side":"BUY","size":"318"},{"asset_id":"24254094493625419915756280046002869097156693848522361803041977572204227262166","best_ask":"0.53","best_bid":"0.52","hash":"a11c7520d74b282089404c2f247bc12435ef17a5","price":"0.58","side":"SELL","size":"318"}],"timestamp":"1785121859882"},"payload_hash":"e277b567aa6a7e1b24b3f8df9c09fee5f3eb9fdc70c5748684ed555c1e247285","raw_frame":"{\"market\":\"0x717c0e8ccd4d5c7040185188fbae28be901ca589a11a94b1b38ca36a79eccfeb\", \"price_changes\":[{\"asset_id\":\"41448400836309843603620980831210604935021861034693225347475867885462478926555\", \"price\":\"0.42\", \"size\":\"318\", \"side\":\"BUY\", \"hash\":\"e9d7d8309504801ff85d49f767d428d5d62a1e0c\", \"best_bid\":\"0.47\", \"best_ask\":\"0.48\"}, {\"asset_id\":\"24254094493625419915756280046002869097156693848522361803041977572204227262166\", \"price\":\"0.58\", \"size\":\"318\", \"side\":\"SELL\", \"hash\":\"a11c7520d74b282089404c2f247bc12435ef17a5\", \"best_bid\":\"0.52\", \"best_ask\":\"0.53\"}], \"timestamp\":\"1785121859882\", \"event_type\":\"price_change\"}","received_at":"2026-07-27T03:10:59.890654Z","schema_version":"clob-market-ws.price_change.v1","sequence":null,"server_hash":null,"server_timestamp":"1785121859882","session_id":"dd162b8dca5f43ff811d304e69a06123","source":"clob_market_ws"},"received_at":"2026-07-27T03:10:59.890654Z","record_id":"966c364de0ec1d61a3c09846d1aaf0ec9eb57ed02494249022e8200d90979e6e","schema_fingerprint":"4aa3821a28b0b7c2400bc59aba4bcc0a76e971dadd19610d3ad38c768e124dc7","schema_version":"edge-lab-recorder.raw.v1","sequence":null,"source":"clob_market_ws"}
{"event_at":"2026-07-27T03:10:59.883000Z","event_fingerprint":"bd8999f956f1a15fe82eb0db6d305ad11545e1260fe3049ed0dc6c507ad8fddd","payload":{"connection_id":"c7dc2e4762f849c6b6f9306b6518dcab","event_at":"2026-07-27T03:10:59.883000Z","event_type":"price_change","frame_hash":"a3d7cdcfca1e30e3babfdb566107d689957196660fbfde2c2d31dcdc78c4b2d4","frame_index":0,"kind":"data","monotonic_ns":223843224066416,"payload":{"event_type":"price_change","market":"0x717c0e8ccd4d5c7040185188fbae28be901ca589a11a94b1b38ca36a79eccfeb","price_changes":[{"asset_id":"41448400836309843603620980831210604935021861034693225347475867885462478926555","best_ask":"0.48","best_bid":"0.47","hash":"94eba2fab739b48941f663bc5e1698c81cc06d9a","price":"0.42","side":"BUY","size":"323"},{"asset_id":"24254094493625419915756280046002869097156693848522361803041977572204227262166","best_ask":"0.53","best_bid":"0.52","hash":"8929fa3be08f96b573defcfd513208c228b87661","price":"0.58","side":"SELL","size":"323"}],"timestamp":"1785121859883"},"payload_hash":"fc5840e803f0fe5d9cd444c8cc7924e31b0478cc7574edbc30fe77faffff060f","raw_frame":"{\"market\":\"0x717c0e8ccd4d5c7040185188fbae28be901ca589a11a94b1b38ca36a79eccfeb\", \"price_changes\":[{\"asset_id\":\"41448400836309843603620980831210604935021861034693225347475867885462478926555\", \"price\":\"0.42\", \"size\":\"323\", \"side\":\"BUY\", \"hash\":\"94eba2fab739b48941f663bc5e1698c81cc06d9a\", \"best_bid\":\"0.47\", \"best_ask\":\"0.48\"}, {\"asset_id\":\"24254094493625419915756280046002869097156693848522361803041977572204227262166\", \"price\":\"0.58\", \"size\":\"323\", \"side\":\"SELL\", \"hash\":\"8929fa3be08f96b573defcfd513208c228b87661\", \"best_bid\":\"0.52\", \"best_ask\":\"0.53\"}], \"timestamp\":\"1785121859883\", \"event_type\":\"price_change\"}","received_at":"2026-07-27T03:10:59.893767Z","schema_version":"clob-market-ws.price_change.v1","sequence":null,"server_hash":null,"server_timestamp":"1785121859883","session_id":"dd162b8dca5f43ff811d304e69a06123","source":"clob_market_ws"},"received_at":"2026-07-27T03:10:59.893767Z","record_id":"4f2ab8a5340e4a27b75649c5c266e62873cee1c41fff68e89cd923833ca1d536","schema_fingerprint":"4aa3821a28b0b7c2400bc59aba4bcc0a76e971dadd19610d3ad38c768e124dc7","schema_version":"edge-lab-recorder.raw.v1","sequence":null,"source":"clob_market_ws"}
{"event_at":"2026-07-27T03:10:59.883000Z","event_fingerprint":"951ff52f73afa474b11ae57cb2ef8942a87aec0eee02b477a87670dc56cbb0df","payload":{"connection_id":"c7dc2e4762f849c6b6f9306b6518dcab","event_at":"2026-07-27T03:10:59.883000Z","event_type":"price_change","frame_hash":"b73643ec429c971740aa42cdc7b2fd62b69fdb9eef2c185e48f363fb9415d06a","frame_index":0,"kind":"data","monotonic_ns":223843226246875,"payload":{"event_type":"price_change","market":"0x717c0e8ccd4d5c7040185188fbae28be901ca589a11a94b1b38ca36a79eccfeb","price_changes":[{"asset_id":"41448400836309843603620980831210604935021861034693225347475867885462478926555","best_ask":"0.48","best_bid":"0.47","hash":"74e5aa0a41231ade23c862b2f83f445475611d7f","price":"0.42","side":"BUY","size":"328"},{"asset_id":"24254094493625419915756280046002869097156693848522361803041977572204227262166","best_ask":"0.53","best_bid":"0.52","hash":"660711b1c95ecff9ce8937aa0abe5e4fa3f64ede","price":"0.58","side":"SELL","size":"328"}],"timestamp":"1785121859883"},"payload_hash":"ecf2595a400617f304784bb93ad09dd2fcd8a7c70f14f483927180b35c6dda31","raw_frame":"{\"market\":\"0x717c0e8ccd4d5c7040185188fbae28be901ca589a11a94b1b38ca36a79eccfeb\", \"price_changes\":[{\"asset_id\":\"41448400836309843603620980831210604935021861034693225347475867885462478926555\", \"price\":\"0.42\", \"size\":\"328\", \"side\":\"BUY\", \"hash\":\"74e5aa0a41231ade23c862b2f83f445475611d7f\", \"best_bid\":\"0.47\", \"best_ask\":\"0.48\"}, {\"asset_id\":\"24254094493625419915756280046002869097156693848522361803041977572204227262166\", \"price\":\"0.58\", \"size\":\"328\", \"side\":\"SELL\", \"hash\":\"660711b1c95ecff9ce8937aa0abe5e4fa3f64ede\", \"best_bid\":\"0.52\", \"best_ask\":\"0.53\"}], \"timestamp\":\"1785121859883\", \"event_type\":\"price_change\"}","received_at":"2026-07-27T03:10:59.895954Z","schema_version":"clob-market-ws.price_change.v1","sequence":null,"server_hash":null,"server_timestamp":"1785121859883","session_id":"dd162b8dca5f43ff811d304e69a06123","source":"clob_market_ws"},"received_at":"2026-07-27T03:10:59.895954Z","record_id":"09b45c050b805efc7cdfc33f722fed3813036fcdfa64e635504e42e8d58f19fb","schema_fingerprint":"4aa3821a28b0b7c2400bc59aba4bcc0a76e971dadd19610d3ad38c768e124dc7","schema_version":"edge-lab-recorder.raw.v1","sequence":null,"source":"clob_market_ws"}
{"event_at":"2026-07-27T03:10:59.884000Z","event_fingerprint":"596ac47f97d58822db46b3eb6a0a554f616a3c486799b4003d264567a35defd7","payload":{"connection_id":"c7dc2e4762f849c6b6f9306b6518dcab","event_at":"2026-07-27T03:10:59.884000Z","event_type":"price_change","frame_hash":"793a59ea7cfb494da5ed11dd21329499e821fb7a1a6f74a63b8dadcbf1562fd7","frame_index":0,"kind":"data","monotonic_ns":223843227812166,"payload":{"event_type":"price_change","market":"0x717c0e8ccd4d5c7040185188fbae28be901ca589a11a94b1b38ca36a79eccfeb","price_changes":[{"asset_id":"41448400836309843603620980831210604935021861034693225347475867885462478926555","best_ask":"0.48","best_bid":"0.47","hash":"807e4b4495856611a0680a29b053cbca90fe9b80","price":"0.42","side":"BUY","size":"333"},{"asset_id":"24254094493625419915756280046002869097156693848522361803041977572204227262166","best_ask":"0.53","best_bid":"0.52","hash":"175129ebe63888c23b2a6257c0868403bb4a3745","price":"0.58","side":"SELL","size":"333"}],"timestamp":"1785121859884"},"payload_hash":"b61a6bb718e13df057aaca6c5781941985c2e94d2abf852a564fd0ba37c40945","raw_frame":"{\"market\":\"0x717c0e8ccd4d5c7040185188fbae28be901ca589a11a94b1b38ca36a79eccfeb\", \"price_changes\":[{\"asset_id\":\"41448400836309843603620980831210604935021861034693225347475867885462478926555\", \"price\":\"0.42\", \"size\":\"333\", \"side\":\"BUY\", \"hash\":\"807e4b4495856611a0680a29b053cbca90fe9b80\", \"best_bid\":\"0.47\", \"best_ask\":\"0.48\"}, {\"asset_id\":\"24254094493625419915756280046002869097156693848522361803041977572204227262166\", \"price\":\"0.58\", \"size\":\"333\", \"side\":\"SELL\", \"hash\":\"175129ebe63888c23b2a6257c0868403bb4a3745\", \"best_bid\":\"0.52\", \"best_ask\":\"0.53\"}], \"timestamp\":\"1785121859884\", \"event_type\":\"price_change\"}","received_at":"2026-07-27T03:10:59.897514Z","schema_version":"clob-market-ws.price_change.v1","sequence":null,"server_hash":null,"server_timestamp":"1785121859884","session_id":"dd162b8dca5f43ff811d304e69a06123","source":"clob_market_ws"},"received_at":"2026-07-27T03:10:59.897514Z","record_id":"079fc53ec39b518a95a9ebce12245b41111eeea0bd6fe1759e7e2104bde24cee","schema_fingerprint":"4aa3821a28b0b7c2400bc59aba4bcc0a76e971dadd19610d3ad38c768e124dc7","schema_version":"edge-lab-recorder.raw.v1","sequence":null,"source":"clob_market_ws"}
{"event_at":"2026-07-27T03:10:59.885000Z","event_fingerprint":"3836625c7a16f4b53249016e2c809a78b5cb0e0edfd9128dafaf378a9affe02d","payload":{"connection_id":"c7dc2e4762f849c6b6f9306b6518dcab","event_at":"2026-07-27T03:10:59.885000Z","event_type":"price_change","frame_hash":"4b548bf17dfdd69cf812158879f32ccb260c956de59f148dfcc88c0c4e844e29","frame_index":0,"kind":"data","monotonic_ns":223843228681750,"payload":{"event_type":"price_change","market":"0x717c0e8ccd4d5c7040185188fbae28be901ca589a11a94b1b38ca36a79eccfeb","price_changes":[{"asset_id":"41448400836309843603620980831210604935021861034693225347475867885462478926555","best_ask":"0.48","best_bid":"0.47","hash":"439dd4a92f9e012f2beeecbe253b0dd2d9edbacd","price":"0.42","side":"BUY","size":"338"},{"asset_id":"24254094493625419915756280046002869097156693848522361803041977572204227262166","best_ask":"0.53","best_bid":"0.52","hash":"3a251234a85d88490c7eb4f766f7d84f86f1c4eb","price":"0.58","side":"SELL","size":"338"}],"timestamp":"1785121859885"},"payload_hash":"3c274a52f9b8d4bba7c972395d0b2842a24bc43a2eccc03d49a8209f289bfa4c","raw_frame":"{\"market\":\"0x717c0e8ccd4d5c7040185188fbae28be901ca589a11a94b1b38ca36a79eccfeb\", \"price_changes\":[{\"asset_id\":\"41448400836309843603620980831210604935021861034693225347475867885462478926555\", \"price\":\"0.42\", \"size\":\"338\", \"side\":\"BUY\", \"hash\":\"439dd4a92f9e012f2beeecbe253b0dd2d9edbacd\", \"best_bid\":\"0.47\", \"best_ask\":\"0.48\"}, {\"asset_id\":\"24254094493625419915756280046002869097156693848522361803041977572204227262166\", \"price\":\"0.58\", \"size\":\"338\", \"side\":\"SELL\", \"hash\":\"3a251234a85d88490c7eb4f766f7d84f86f1c4eb\", \"best_bid\":\"0.52\", \"best_ask\":\"0.53\"}], \"timestamp\":\"1785121859885\", \"event_type\":\"price_change\"}","received_at":"2026-07-27T03:10:59.898389Z","schema_version":"clob-market-ws.price_change.v1","sequence":null,"server_hash":null,"server_timestamp":"1785121859885","session_id":"dd162b8dca5f43ff811d304e69a06123","source":"clob_market_ws"},"received_at":"2026-07-27T03:10:59.898389Z","record_id":"ed1d232268c961937466834f0de27bfab9070284d6c5e5d396366ab9e7547079","schema_fingerprint":"4aa3821a28b0b7c2400bc59aba4bcc0a76e971dadd19610d3ad38c768e124dc7","schema_version":"edge-lab-recorder.raw.v1","sequence":null,"source":"clob_market_ws"}
{"event_at":"2026-07-27T03:10:59.885000Z","event_fingerprint":"acee4aac3ea70157367745d4d1cbff0a6a32dbd87d5776baa8d14b479e19e5a6","payload":{"connection_id":"c7dc2e4762f849c6b6f9306b6518dcab","event_at":"2026-07-27T03:10:59.885000Z","event_type":"price_change","frame_hash":"f6e507c256a967a620ecc4c95edb0821ff1f894a398c1c7dcfbeb606d8ca1730","frame_index":0,"kind":"data","monotonic_ns":223843229212708,"payload":{"event_type":"price_change","market":"0x717c0e8ccd4d5c7040185188fbae28be901ca589a11a94b1b38ca36a79eccfeb","price_changes":[{"asset_id":"41448400836309843603620980831210604935021861034693225347475867885462478926555","best_ask":"0.48","best_bid":"0.47","hash":"6e9a1fcc106108b61e38757e34b6197f5a95c308","price":"0.42","side":"BUY","size":"343"},{"asset_id":"24254094493625419915756280046002869097156693848522361803041977572204227262166","best_ask":"0.53","best_bid":"0.52","hash":"1e18b7d3bcf582a0f7d85354bef7bbf476c3e747","price":"0.58","side":"SELL","size":"343"}],"timestamp":"1785121859885"},"payload_hash":"04ad173a8b8fa014807f4e9e62bd9fd47e5a3fe7ffd5e3036d5ee161d31272ae","raw_frame":"{\"market\":\"0x717c0e8ccd4d5c7040185188fbae28be901ca589a11a94b1b38ca36a79eccfeb\", \"price_changes\":[{\"asset_id\":\"41448400836309843603620980831210604935021861034693225347475867885462478926555\", \"price\":\"0.42\", \"size\":\"343\", \"side\":\"BUY\", \"hash\":\"6e9a1fcc106108b61e38757e34b6197f5a95c308\", \"best_bid\":\"0.47\", \"best_ask\":\"0.48\"}, {\"asset_id\":\"24254094493625419915756280046002869097156693848522361803041977572204227262166\", \"price\":\"0.58\", \"size\":\"343\", \"side\":\"SELL\", \"hash\":\"1e18b7d3bcf582a0f7d85354bef7bbf476c3e747\", \"best_bid\":\"0.52\", \"best_ask\":\"0.53\"}], \"timestamp\":\"1785121859885\", \"event_type\":\"price_change\"}","received_at":"2026-07-27T03:10:59.898921Z","schema_version":"clob-market-ws.price_change.v1","sequence":null,"server_hash":null,"server_timestamp":"1785121859885","session_id":"dd162b8dca5f43ff811d304e69a06123","source":"clob_market_ws"},"received_at":"2026-07-27T03:10:59.898921Z","record_id":"915f754dbec18315658f46f0184eab19d90e1ab47549e258c9d047ebad81a661","schema_fingerprint":"4aa3821a28b0b7c2400bc59aba4bcc0a76e971dadd19610d3ad38c768e124dc7","schema_version":"edge-lab-recorder.raw.v1","sequence":null,"source":"clob_market_ws"}
{"event_at":"2026-07-27T03:10:59.886000Z","event_fingerprint":"e8f43c33c6d1ed1d154a142a9b07358c58196832075daa0ffd14ae5570764228","payload":{"connection_id":"c7dc2e4762f849c6b6f9306b6518dcab","event_at":"2026-07-27T03:10:59.886000Z","event_type":"price_change","frame_hash":"3fb9328e84ae4df641c19958b10b9f9f287928bcdb39e4ceb3f361f1a2775000","frame_index":0,"kind":"data","monotonic_ns":223843230288000,"payload":{"event_type":"price_change","market":"0x717c0e8ccd4d5c7040185188fbae28be901ca589a11a94b1b38ca36a79eccfeb","price_changes":[{"asset_id":"41448400836309843603620980831210604935021861034693225347475867885462478926555","best_ask":"0.48","best_bid":"0.47","hash":"4386e009ec973e3bbefad46bc7b698fa3ae1ed91","price":"0.42","side":"BUY","size":"348"},{"asset_id":"24254094493625419915756280046002869097156693848522361803041977572204227262166","best_ask":"0.53","best_bid":"0.52","hash":"adbb20686471656dfd8aa02b6c8f5ace06800a9b","price":"0.58","side":"SELL","size":"348"}],"timestamp":"1785121859886"},"payload_hash":"b5cc28d8f67316d69669cdea95ff602c4ff37a8e9d9cf9b2cf5ea02f98fc7f17","raw_frame":"{\"market\":\"0x717c0e8ccd4d5c7040185188fbae28be901ca589a11a94b1b38ca36a79eccfeb\", \"price_changes\":[{\"asset_id\":\"41448400836309843603620980831210604935021861034693225347475867885462478926555\", \"price\":\"0.42\", \"size\":\"348\", \"side\":\"BUY\", \"hash\":\"4386e009ec973e3bbefad46bc7b698fa3ae1ed91\", \"best_bid\":\"0.47\", \"best_ask\":\"0.48\"}, {\"asset_id\":\"24254094493625419915756280046002869097156693848522361803041977572204227262166\", \"price\":\"0.58\", \"size\":\"348\", \"side\":\"SELL\", \"hash\":\"adbb20686471656dfd8aa02b6c8f5ace06800a9b\", \"best_bid\":\"0.52\", \"best_ask\":\"0.53\"}], \"timestamp\":\"1785121859886\", \"event_type\":\"price_change\"}","received_at":"2026-07-27T03:10:59.899995Z","schema_version":"clob-market-ws.price_change.v1","sequence":null,"server_hash":null,"server_timestamp":"1785121859886","session_id":"dd162b8dca5f43ff811d304e69a06123","source":"clob_market_ws"},"received_at":"2026-07-27T03:10:59.899995Z","record_id":"5f4b5b7c664c53afd80d1ee4b5e88a81841d1c0630349eecdb368777ee67d05d","schema_fingerprint":"4aa3821a28b0b7c2400bc59aba4bcc0a76e971dadd19610d3ad38c768e124dc7","schema_version":"edge-lab-recorder.raw.v1","sequence":null,"source":"clob_market_ws"}
{"event_at":"2026-07-27T03:10:59.887000Z","event_fingerprint":"6638b2e322b89357cb0c6a0f43d2af78b1c8da67236b5b3c1b52fe1658c0832c","payload":{"connection_id":"c7dc2e4762f849c6b6f9306b6518dcab","event_at":"2026-07-27T03:10:59.887000Z","event_type":"price_change","frame_hash":"fa7ab7971b37f0cb408de1093b5d73f6ee47c3dc7275c0747d81fc227de4f384","frame_index":0,"kind":"data","monotonic_ns":223843241054375,"payload":{"event_type":"price_change","market":"0x717c0e8ccd4d5c7040185188fbae28be901ca589a11a94b1b38ca36a79eccfeb","price_changes":[{"asset_id":"41448400836309843603620980831210604935021861034693225347475867885462478926555","best_ask":"0.48","best_bid":"0.47","hash":"cf6633bf6c835b4f0eca1d91c484fb50de9eabdf","price":"0.42","side":"BUY","size":"353"},{"asset_id":"24254094493625419915756280046002869097156693848522361803041977572204227262166","best_ask":"0.53","best_bid":"0.52","hash":"4ad391156945dfeab55de3360a0e28da2ef2cde3","price":"0.58","side":"SELL","size":"353"}],"timestamp":"1785121859887"},"payload_hash":"7e31b8e56cf6a688c3a119c11a80606819f81e355bb44ecec077af9fadee7699","raw_frame":"{\"market\":\"0x717c0e8ccd4d5c7040185188fbae28be901ca589a11a94b1b38ca36a79eccfeb\", \"price_changes\":[{\"asset_id\":\"41448400836309843603620980831210604935021861034693225347475867885462478926555\", \"price\":\"0.42\", \"size\":\"353\", \"side\":\"BUY\", \"hash\":\"cf6633bf6c835b4f0eca1d91c484fb50de9eabdf\", \"best_bid\":\"0.47\", \"best_ask\":\"0.48\"}, {\"asset_id\":\"24254094493625419915756280046002869097156693848522361803041977572204227262166\", \"price\":\"0.58\", \"size\":\"353\", \"side\":\"SELL\", \"hash\":\"4ad391156945dfeab55de3360a0e28da2ef2cde3\", \"best_bid\":\"0.52\", \"best_ask\":\"0.53\"}], \"timestamp\":\"1785121859887\", \"event_type\":\"price_change\"}","received_at":"2026-07-27T03:10:59.910755Z","schema_version":"clob-market-ws.price_change.v1","sequence":null,"server_hash":null,"server_timestamp":"1785121859887","session_id":"dd162b8dca5f43ff811d304e69a06123","source":"clob_market_ws"},"received_at":"2026-07-27T03:10:59.910755Z","record_id":"b5733479a972d724da49aa328d0b8aa649003fad8b82a810f2d72b54239038b5","schema_fingerprint":"4aa3821a28b0b7c2400bc59aba4bcc0a76e971dadd19610d3ad38c768e124dc7","schema_version":"edge-lab-recorder.raw.v1","sequence":null,"source":"clob_market_ws"}
{"event_at":"2026-07-27T03:10:59.888000Z","event_fingerprint":"f691162037907daa997e9e5652e78678e4d545ca46c11d1859360a2c9e3260f0","payload":{"connection_id":"c7dc2e4762f849c6b6f9306b6518dcab","event_at":"2026-07-27T03:10:59.888000Z","event_type":"price_change","frame_hash":"b336c3ebf5dc3da3705a2a6ec5631ca6f474d939376661e22beae54627b9b082","frame_index":0,"kind":"data","monotonic_ns":223843244256000,"payload":{"event_type":"price_change","market":"0x717c0e8ccd4d5c7040185188fbae28be901ca589a11a94b1b38ca36a79eccfeb","price_changes":[{"asset_id":"41448400836309843603620980831210604935021861034693225347475867885462478926555","best_ask":"0.48","best_bid":"0.47","hash":"3ba5b8b1ddc9c7fa3e9f599bcc63acafe5364f81","price":"0.42","side":"BUY","size":"358"},{"asset_id":"24254094493625419915756280046002869097156693848522361803041977572204227262166","best_ask":"0.53","best_bid":"0.52","hash":"cae56ff59a844a7bfbb4010043c7c04cf3c93148","price":"0.58","side":"SELL","size":"358"}],"timestamp":"1785121859888"},"payload_hash":"5bdca18cb65d4b75e0ab28bdc302ee4669d3fa6c0339017cd3a783c640a9609f","raw_frame":"{\"market\":\"0x717c0e8ccd4d5c7040185188fbae28be901ca589a11a94b1b38ca36a79eccfeb\", \"price_changes\":[{\"asset_id\":\"41448400836309843603620980831210604935021861034693225347475867885462478926555\", \"price\":\"0.42\", \"size\":\"358\", \"side\":\"BUY\", \"hash\":\"3ba5b8b1ddc9c7fa3e9f599bcc63acafe5364f81\", \"best_bid\":\"0.47\", \"best_ask\":\"0.48\"}, {\"asset_id\":\"24254094493625419915756280046002869097156693848522361803041977572204227262166\", \"price\":\"0.58\", \"size\":\"358\", \"side\":\"SELL\", \"hash\":\"cae56ff59a844a7bfbb4010043c7c04cf3c93148\", \"best_bid\":\"0.52\", \"best_ask\":\"0.53\"}], \"timestamp\":\"1785121859888\", \"event_type\":\"price_change\"}","received_at":"2026-07-27T03:10:59.913958Z","schema_version":"clob-market-ws.price_change.v1","sequence":null,"server_hash":null,"server_timestamp":"1785121859888","session_id":"dd162b8dca5f43ff811d304e69a06123","source":"clob_market_ws"},"received_at":"2026-07-27T03:10:59.913958Z","record_id":"55818847affeaee74c251ef44872cfa180949244cc141d27a4ea481ac47035c4","schema_fingerprint":"4aa3821a28b0b7c2400bc59aba4bcc0a76e971dadd19610d3ad38c768e124dc7","schema_version":"edge-lab-recorder.raw.v1","sequence":null,"source":"clob_market_ws"}
{"event_at":"2026-07-27T03:10:59.889000Z","event_fingerprint":"d7b5fca9a60c83dfd385257dfc181fd67406420768d6f0796682b6939757e5c3","payload":{"connection_id":"c7dc2e4762f849c6b6f9306b6518dcab","event_at":"2026-07-27T03:10:59.889000Z","event_type":"price_change","frame_hash":"ab844d797675e4cb656a076b1a3680814cfcf6f82c4303aced233a04b936419b","frame_index":0,"kind":"data","monotonic_ns":223843247964416,"payload":{"event_type":"price_change","market":"0x717c0e8ccd4d5c7040185188fbae28be901ca589a11a94b1b38ca36a79eccfeb","price_changes":[{"asset_id":"41448400836309843603620980831210604935021861034693225347475867885462478926555","best_ask":"0.48","best_bid":"0.47","hash":"1f12e77c74e639c94a283acfc2110ac716da94b2","price":"0.42","side":"BUY","size":"363"},{"asset_id":"24254094493625419915756280046002869097156693848522361803041977572204227262166","best_ask":"0.53","best_bid":"0.52","hash":"0239d42e2717131adec47e6c5504c3718f824f48","price":"0.58","side":"SELL","size":"363"}],"timestamp":"1785121859889"},"payload_hash":"894d8206b2fa0c4523a3341e18ecd7ff7fa5a1d0bcbf1075c7a4305b54f50139","raw_frame":"{\"market\":\"0x717c0e8ccd4d5c7040185188fbae28be901ca589a11a94b1b38ca36a79eccfeb\", \"price_changes\":[{\"asset_id\":\"41448400836309843603620980831210604935021861034693225347475867885462478926555\", \"price\":\"0.42\", \"size\":\"363\", \"side\":\"BUY\", \"hash\":\"1f12e77c74e639c94a283acfc2110ac716da94b2\", \"best_bid\":\"0.47\", \"best_ask\":\"0.48\"}, {\"asset_id\":\"24254094493625419915756280046002869097156693848522361803041977572204227262166\", \"price\":\"0.58\", \"size\":\"363\", \"side\":\"SELL\", \"hash\":\"0239d42e2717131adec47e6c5504c3718f824f48\", \"best_bid\":\"0.52\", \"best_ask\":\"0.53\"}], \"timestamp\":\"1785121859889\", \"event_type\":\"price_change\"}","received_at":"2026-07-27T03:10:59.917671Z","schema_version":"clob-market-ws.price_change.v1","sequence":null,"server_hash":null,"server_timestamp":"1785121859889","session_id":"dd162b8dca5f43ff811d304e69a06123","source":"clob_market_ws"},"received_at":"2026-07-27T03:10:59.917671Z","record_id":"52e685453f436640ec674a276ed95ab98f52eb07a2c5b8568ec253233aed7343","schema_fingerprint":"4aa3821a28b0b7c2400bc59aba4bcc0a76e971dadd19610d3ad38c768e124dc7","schema_version":"edge-lab-recorder.raw.v1","sequence":null,"source":"clob_market_ws"}
{"event_at":"2026-07-27T03:10:59.889000Z","event_fingerprint":"f243abf5e2b6182bde4cc5dc7d48a955772451a7a0c2b4d858ebd05708090f1f","payload":{"connection_id":"c7dc2e4762f849c6b6f9306b6518dcab","event_at":"2026-07-27T03:10:59.889000Z","event_type":"price_change","frame_hash":"29815be89f66f519dacf90e51b276612999edd2fdbc1e1e3ceabe8a1b9383285","frame_index":0,"kind":"data","monotonic_ns":223843249869208,"payload":{"event_type":"price_change","market":"0x717c0e8ccd4d5c7040185188fbae28be901ca589a11a94b1b38ca36a79eccfeb","price_changes":[{"asset_id":"41448400836309843603620980831210604935021861034693225347475867885462478926555","best_ask":"0.48","best_bid":"0.47","hash":"ca3597c9f4ee14ffc8a772497d31436e205e960b","price":"0.42","side":"BUY","size":"368"},{"asset_id":"24254094493625419915756280046002869097156693848522361803041977572204227262166","best_ask":"0.53","best_bid":"0.52","hash":"95ce7d72677e18e80808b41a4315d01866a1bc19","price":"0.58","side":"SELL","size":"368"}],"timestamp":"1785121859889"},"payload_hash":"fd0fbfeab287356f670deb896f44f6145a3157ed7c49295e9003dd0783629386","raw_frame":"{\"market\":\"0x717c0e8ccd4d5c7040185188fbae28be901ca589a11a94b1b38ca36a79eccfeb\", \"price_changes\":[{\"asset_id\":\"41448400836309843603620980831210604935021861034693225347475867885462478926555\", \"price\":\"0.42\", \"size\":\"368\", \"side\":\"BUY\", \"hash\":\"ca3597c9f4ee14ffc8a772497d31436e205e960b\", \"best_bid\":\"0.47\", \"best_ask\":\"0.48\"}, {\"asset_id\":\"24254094493625419915756280046002869097156693848522361803041977572204227262166\", \"price\":\"0.58\", \"size\":\"368\", \"side\":\"SELL\", \"hash\":\"95ce7d72677e18e80808b41a4315d01866a1bc19\", \"best_bid\":\"0.52\", \"best_ask\":\"0.53\"}], \"timestamp\":\"1785121859889\", \"event_type\":\"price_change\"}","received_at":"2026-07-27T03:10:59.919570Z","schema_version":"clob-market-ws.price_change.v1","sequence":null,"server_hash":null,"server_timestamp":"1785121859889","session_id":"dd162b8dca5f43ff811d304e69a06123","source":"clob_market_ws"},"received_at":"2026-07-27T03:10:59.919570Z","record_id":"5557ad102b96bc7e696a6be27e4161bc9668b58f06f8cd37663fd09b6739b3df","schema_fingerprint":"4aa3821a28b0b7c2400bc59aba4bcc0a76e971dadd19610d3ad38c768e124dc7","schema_version":"edge-lab-recorder.raw.v1","sequence":null,"source":"clob_market_ws"}
{"event_at":"2026-07-27T03:10:59.890000Z","event_fingerprint":"7ccf17a8c52799913f5cf8d629bf8d8781122d56e00a5dee1181134fe7599bbc","payload":{"connection_id":"c7dc2e4762f849c6b6f9306b6518dcab","event_at":"2026-07-27T03:10:59.890000Z","event_type":"price_change","frame_hash":"0c96617f5f9cedbd69e07db7e8fa5f560cbd46cc90624a8b557df545b9f13e9e","frame_index":0,"kind":"data","monotonic_ns":223843253102625,"payload":{"event_type":"price_change","market":"0x717c0e8ccd4d5c7040185188fbae28be901ca589a11a94b1b38ca36a79eccfeb","price_changes":[{"asset_id":"41448400836309843603620980831210604935021861034693225347475867885462478926555","best_ask":"0.48","best_bid":"0.47","hash":"1c73c5b97acf53a77716a2aba33881e7e213d951","price":"0.42","side":"BUY","size":"373"},{"asset_id":"24254094493625419915756280046002869097156693848522361803041977572204227262166","best_ask":"0.53","best_bid":"0.52","hash":"d0843e298abcdab80a75c9ac63ac13dc1bdd6571","price":"0.58","side":"SELL","size":"373"}],"timestamp":"1785121859890"},"payload_hash":"d4d9b99fae247278133a58a7c9278a100d551116f8173898eb6f9c21f4052075","raw_frame":"{\"market\":\"0x717c0e8ccd4d5c7040185188fbae28be901ca589a11a94b1b38ca36a79eccfeb\", \"price_changes\":[{\"asset_id\":\"41448400836309843603620980831210604935021861034693225347475867885462478926555\", \"price\":\"0.42\", \"size\":\"373\", \"side\":\"BUY\", \"hash\":\"1c73c5b97acf53a77716a2aba33881e7e213d951\", \"best_bid\":\"0.47\", \"best_ask\":\"0.48\"}, {\"asset_id\":\"24254094493625419915756280046002869097156693848522361803041977572204227262166\", \"price\":\"0.58\", \"size\":\"373\", \"side\":\"SELL\", \"hash\":\"d0843e298abcdab80a75c9ac63ac13dc1bdd6571\", \"best_bid\":\"0.52\", \"best_ask\":\"0.53\"}], \"timestamp\":\"1785121859890\", \"event_type\":\"price_change\"}","received_at":"2026-07-27T03:10:59.922803Z","schema_version":"clob-market-ws.price_change.v1","sequence":null,"server_hash":null,"server_timestamp":"1785121859890","session_id":"dd162b8dca5f43ff811d304e69a06123","source":"clob_market_ws"},"received_at":"2026-07-27T03:10:59.922803Z","record_id":"34bd5de64fcab7091e0593524cacc68713c071a48ab52f73fd4829c89e2f9421","schema_fingerprint":"4aa3821a28b0b7c2400bc59aba4bcc0a76e971dadd19610d3ad38c768e124dc7","schema_version":"edge-lab-recorder.raw.v1","sequence":null,"source":"clob_market_ws"}
{"event_at":"2026-07-27T03:10:59.891000Z","event_fingerprint":"b60840deadec49f205cd6b5a4adc331896f3c85c0b6dc703dbdfdc3772e3b9af","payload":{"connection_id":"c7dc2e4762f849c6b6f9306b6518dcab","event_at":"2026-07-27T03:10:59.891000Z","event_type":"price_change","frame_hash":"e2a3cc4cf8b649cf095f95ecf06238cb53c1b88cb109f2c90e4ea26dd0c15d92","frame_index":0,"kind":"data","monotonic_ns":223843258064750,"payload":{"event_type":"price_change","market":"0x717c0e8ccd4d5c7040185188fbae28be901ca589a11a94b1b38ca36a79eccfeb","price_changes":[{"asset_id":"41448400836309843603620980831210604935021861034693225347475867885462478926555","best_ask":"0.48","best_bid":"0.47","hash":"8c3aeb0a9447727649ae3f16317be77c00fc92e3","price":"0.42","side":"BUY","size":"378"},{"asset_id":"24254094493625419915756280046002869097156693848522361803041977572204227262166","best_ask":"0.53","best_bid":"0.52","hash":"2b0f16d073f384663601164a55a826b1e9fd11c7","price":"0.58","side":"SELL","size":"378"}],"timestamp":"1785121859891"},"payload_hash":"37781434daef3a42eee5a8eadc0361e8b94fee4a2cad716c60412258a52de616","raw_frame":"{\"market\":\"0x717c0e8ccd4d5c7040185188fbae28be901ca589a11a94b1b38ca36a79eccfeb\", \"price_changes\":[{\"asset_id\":\"41448400836309843603620980831210604935021861034693225347475867885462478926555\", \"price\":\"0.42\", \"size\":\"378\", \"side\":\"BUY\", \"hash\":\"8c3aeb0a9447727649ae3f16317be77c00fc92e3\", \"best_bid\":\"0.47\", \"best_ask\":\"0.48\"}, {\"asset_id\":\"24254094493625419915756280046002869097156693848522361803041977572204227262166\", \"price\":\"0.58\", \"size\":\"378\", \"side\":\"SELL\", \"hash\":\"2b0f16d073f384663601164a55a826b1e9fd11c7\", \"best_bid\":\"0.52\", \"best_ask\":\"0.53\"}], \"timestamp\":\"1785121859891\", \"event_type\":\"price_change\"}","received_at":"2026-07-27T03:10:59.927766Z","schema_version":"clob-market-ws.price_change.v1","sequence":null,"server_hash":null,"server_timestamp":"1785121859891","session_id":"dd162b8dca5f43ff811d304e69a06123","source":"clob_market_ws"},"received_at":"2026-07-27T03:10:59.927766Z","record_id":"b9820c9791071c779ea8facc66d72de09f394441fb8e7d16644b0ceb95e3f037","schema_fingerprint":"4aa3821a28b0b7c2400bc59aba4bcc0a76e971dadd19610d3ad38c768e124dc7","schema_version":"edge-lab-recorder.raw.v1","sequence":null,"source":"clob_market_ws"}
{"event_at":"2026-07-27T03:10:59.892000Z","event_fingerprint":"b2f02793c7ebf96e485a1c74e989f2390d6e2aac953b632c5976be9d1978c808","payload":{"connection_id":"c7dc2e4762f849c6b6f9306b6518dcab","event_at":"2026-07-27T03:10:59.892000Z","event_type":"price_change","frame_hash":"9b0766508ce6c2688ea259b5a6241736ca1a418d3a91aea57744e243c6fcd16b","frame_index":0,"kind":"data","monotonic_ns":223843262320125,"payload":{"event_type":"price_change","market":"0x717c0e8ccd4d5c7040185188fbae28be901ca589a11a94b1b38ca36a79eccfeb","price_changes":[{"asset_id":"41448400836309843603620980831210604935021861034693225347475867885462478926555","best_ask":"0.48","best_bid":"0.47","hash":"3cd8df22e9ff0fdcc587aa3f532e874a722b3bca","price":"0.42","side":"BUY","size":"383"},{"asset_id":"24254094493625419915756280046002869097156693848522361803041977572204227262166","best_ask":"0.53","best_bid":"0.52","hash":"f7766feec1775257c3045ae61612a787088cdee2","price":"0.58","side":"SELL","size":"383"}],"timestamp":"1785121859892"},"payload_hash":"2459232da4dcdf054c212380a3dd21ce205ce5aa3acb05d1d750ab0ad4bd2016","raw_frame":"{\"market\":\"0x717c0e8ccd4d5c7040185188fbae28be901ca589a11a94b1b38ca36a79eccfeb\", \"price_changes\":[{\"asset_id\":\"41448400836309843603620980831210604935021861034693225347475867885462478926555\", \"price\":\"0.42\", \"size\":\"383\", \"side\":\"BUY\", \"hash\":\"3cd8df22e9ff0fdcc587aa3f532e874a722b3bca\", \"best_bid\":\"0.47\", \"best_ask\":\"0.48\"}, {\"asset_id\":\"24254094493625419915756280046002869097156693848522361803041977572204227262166\", \"price\":\"0.58\", \"size\":\"383\", \"side\":\"SELL\", \"hash\":\"f7766feec1775257c3045ae61612a787088cdee2\", \"best_bid\":\"0.52\", \"best_ask\":\"0.53\"}], \"timestamp\":\"1785121859892\", \"event_type\":\"price_change\"}","received_at":"2026-07-27T03:10:59.932021Z","schema_version":"clob-market-ws.price_change.v1","sequence":null,"server_hash":null,"server_timestamp":"1785121859892","session_id":"dd162b8dca5f43ff811d304e69a06123","source":"clob_market_ws"},"received_at":"2026-07-27T03:10:59.932021Z","record_id":"cf58581fd44653ba1b7e870a33d162848f2362a239d7e2b29453445b7dc27868","schema_fingerprint":"4aa3821a28b0b7c2400bc59aba4bcc0a76e971dadd19610d3ad38c768e124dc7","schema_version":"edge-lab-recorder.raw.v1","sequence":null,"source":"clob_market_ws"}
{"event_at":"2026-07-27T03:10:59.893000Z","event_fingerprint":"32ee889af6cdbd540914f1f9b595ed08d3eb7e915d31d290b2307413237d74d8","payload":{"connection_id":"c7dc2e4762f849c6b6f9306b6518dcab","event_at":"2026-07-27T03:10:59.893000Z","event_type":"price_change","frame_hash":"2abb9be8f5f91bc6215a501464dbc8e64ad7a189f90c6a36f5baeb4dc21ff95a","frame_index":0,"kind":"data","monotonic_ns":223843268619125,"payload":{"event_type":"price_change","market":"0x717c0e8ccd4d5c7040185188fbae28be901ca589a11a94b1b38ca36a79eccfeb","price_changes":[{"asset_id":"41448400836309843603620980831210604935021861034693225347475867885462478926555","best_ask":"0.48","best_bid":"0.47","hash":"f219ec46b926c4c5b735e8cb59bd8e6896ef50bf","price":"0.42","side":"BUY","size":"388"},{"asset_id":"24254094493625419915756280046002869097156693848522361803041977572204227262166","best_ask":"0.53","best_bid":"0.52","hash":"81d8ab2297d137b0d904439d379e2395f22db41a","price":"0.58","side":"SELL","size":"388"}],"timestamp":"1785121859893"},"payload_hash":"6728713cab0e24a2a3e6d5f3145979e0d2e42c49d6e47d345ed8abda588b1993","raw_frame":"{\"market\":\"0x717c0e8ccd4d5c7040185188fbae28be901ca589a11a94b1b38ca36a79eccfeb\", \"price_changes\":[{\"asset_id\":\"41448400836309843603620980831210604935021861034693225347475867885462478926555\", \"price\":\"0.42\", \"size\":\"388\", \"side\":\"BUY\", \"hash\":\"f219ec46b926c4c5b735e8cb59bd8e6896ef50bf\", \"best_bid\":\"0.47\", \"best_ask\":\"0.48\"}, {\"asset_id\":\"24254094493625419915756280046002869097156693848522361803041977572204227262166\", \"price\":\"0.58\", \"size\":\"388\", \"side\":\"SELL\", \"hash\":\"81d8ab2297d137b0d904439d379e2395f22db41a\", \"best_bid\":\"0.52\", \"best_ask\":\"0.53\"}], \"timestamp\":\"1785121859893\", \"event_type\":\"price_change\"}","received_at":"2026-07-27T03:10:59.938319Z","schema_version":"clob-market-ws.price_change.v1","sequence":null,"server_hash":null,"server_timestamp":"1785121859893","session_id":"dd162b8dca5f43ff811d304e69a06123","source":"clob_market_ws"},"received_at":"2026-07-27T03:10:59.938319Z","record_id":"b0c4fd541cd60b2d175b73fca0609dd934cf7840fcecf2f7d8fb3024bd660d95","schema_fingerprint":"4aa3821a28b0b7c2400bc59aba4bcc0a76e971dadd19610d3ad38c768e124dc7","schema_version":"edge-lab-recorder.raw.v1","sequence":null,"source":"clob_market_ws"}
{"event_at":"2026-07-27T03:10:59.893000Z","event_fingerprint":"3a034007ef41354df406e2cbd04f551455f3448da9e99b6cd567a5c7a4ae09c5","payload":{"connection_id":"c7dc2e4762f849c6b6f9306b6518dcab","event_at":"2026-07-27T03:10:59.893000Z","event_type":"price_change","frame_hash":"33d503ddcb567924a7f6f755c1cc3c0e13515acdc8287765aeefb5ac972319a8","frame_index":0,"kind":"data","monotonic_ns":223843274349750,"payload":{"event_type":"price_change","market":"0x717c0e8ccd4d5c7040185188fbae28be901ca589a11a94b1b38ca36a79eccfeb","price_changes":[{"asset_id":"41448400836309843603620980831210604935021861034693225347475867885462478926555","best_ask":"0.48","best_bid":"0.47","hash":"aa3f0ed6e42fb71a6d6e79c1658e6ba149b8bbf5","price":"0.42","side":"BUY","size":"393"},{"asset_id":"24254094493625419915756280046002869097156693848522361803041977572204227262166","best_ask":"0.53","best_bid":"0.52","hash":"e5b6e34b48938e2c43d84149c6be2cfc4ac9fa7a","price":"0.58","side":"SELL","size":"393"}],"timestamp":"1785121859893"},"payload_hash":"ffce9a11f274f9369f238d0298b3c74eec4daa79bc3c16219c793c05ee3a5c5c","raw_frame":"{\"market\":\"0x717c0e8ccd4d5c7040185188fbae28be901ca589a11a94b1b38ca36a79eccfeb\", \"price_changes\":[{\"asset_id\":\"41448400836309843603620980831210604935021861034693225347475867885462478926555\", \"price\":\"0.42\", \"size\":\"393\", \"side\":\"BUY\", \"hash\":\"aa3f0ed6e42fb71a6d6e79c1658e6ba149b8bbf5\", \"best_bid\":\"0.47\", \"best_ask\":\"0.48\"}, {\"asset_id\":\"24254094493625419915756280046002869097156693848522361803041977572204227262166\", \"price\":\"0.58\", \"size\":\"393\", \"side\":\"SELL\", \"hash\":\"e5b6e34b48938e2c43d84149c6be2cfc4ac9fa7a\", \"best_bid\":\"0.52\", \"best_ask\":\"0.53\"}], \"timestamp\":\"1785121859893\", \"event_type\":\"price_change\"}","received_at":"2026-07-27T03:10:59.944051Z","schema_version":"clob-market-ws.price_change.v1","sequence":null,"server_hash":null,"server_timestamp":"1785121859893","session_id":"dd162b8dca5f43ff811d304e69a06123","source":"clob_market_ws"},"received_at":"2026-07-27T03:10:59.944051Z","record_id":"7fe31bb0eb717ff76dd4a157a46d519ea53ed3fc2f9ac9a2f908331fed673bf9","schema_fingerprint":"4aa3821a28b0b7c2400bc59aba4bcc0a76e971dadd19610d3ad38c768e124dc7","schema_version":"edge-lab-recorder.raw.v1","sequence":null,"source":"clob_market_ws"}
{"event_at":"2026-07-27T03:10:59.894000Z","event_fingerprint":"9b7ff0ae3a7038dd7923ae29461e41897212d7eae8d352d9bc4a14b08caefcca","payload":{"connection_id":"c7dc2e4762f849c6b6f9306b6518dcab","event_at":"2026-07-27T03:10:59.894000Z","event_type":"price_change","frame_hash":"2388092f1d85104d070c884ee680972e9cec88cb42dfd80afb7879bd42e65622","frame_index":0,"kind":"data","monotonic_ns":223843280080416,"payload":{"event_type":"price_change","market":"0x717c0e8ccd4d5c7040185188fbae28be901ca589a11a94b1b38ca36a79eccfeb","price_changes":[{"asset_id":"41448400836309843603620980831210604935021861034693225347475867885462478926555","best_ask":"0.48","best_bid":"0.47","hash":"058910c31570cae20120972dcb6f00edef1fd3af","price":"0.42","side":"BUY","size":"398"},{"asset_id":"24254094493625419915756280046002869097156693848522361803041977572204227262166","best_ask":"0.53","best_bid":"0.52","hash":"8bdeff788f5d0b66836f90bda67bbf1f828a9403","price":"0.58","side":"SELL","size":"398"}],"timestamp":"1785121859894"},"payload_hash":"dce69e1e1e6c57dafa22c27b85ada8acd8d587d613cf8b8f182c47380a854bd4","raw_frame":"{\"market\":\"0x717c0e8ccd4d5c7040185188fbae28be901ca589a11a94b1b38ca36a79eccfeb\", \"price_changes\":[{\"asset_id\":\"41448400836309843603620980831210604935021861034693225347475867885462478926555\", \"price\":\"0.42\", \"size\":\"398\", \"side\":\"BUY\", \"hash\":\"058910c31570cae20120972dcb6f00edef1fd3af\", \"best_bid\":\"0.47\", \"best_ask\":\"0.48\"}, {\"asset_id\":\"24254094493625419915756280046002869097156693848522361803041977572204227262166\", \"price\":\"0.58\", \"size\":\"398\", \"side\":\"SELL\", \"hash\":\"8bdeff788f5d0b66836f90bda67bbf1f828a9403\", \"best_bid\":\"0.52\", \"best_ask\":\"0.53\"}], \"timestamp\":\"1785121859894\", \"event_type\":\"price_change\"}","received_at":"2026-07-27T03:10:59.949778Z","schema_version":"clob-market-ws.price_change.v1","sequence":null,"server_hash":null,"server_timestamp":"1785121859894","session_id":"dd162b8dca5f43ff811d304e69a06123","source":"clob_market_ws"},"received_at":"2026-07-27T03:10:59.949778Z","record_id":"191fdd1b5de6148c2c5cad70c62671bdc8bb6a28a7452b8b304658f83fb86613","schema_fingerprint":"4aa3821a28b0b7c2400bc59aba4bcc0a76e971dadd19610d3ad38c768e124dc7","schema_version":"edge-lab-recorder.raw.v1","sequence":null,"source":"clob_market_ws"}
{"event_at":"2026-07-27T03:10:59.895000Z","event_fingerprint":"42f15801dbfefe825f87efd3aabfe89b82d00900169ba94ef282d618dc9486eb","payload":{"connection_id":"c7dc2e4762f849c6b6f9306b6518dcab","event_at":"2026-07-27T03:10:59.895000Z","event_type":"price_change","frame_hash":"035f23195e04f9e3277afb4f8dcd7dc04062b2afd732a7f8c116a226667f55ff","frame_index":0,"kind":"data","monotonic_ns":223843283393583,"payload":{"event_type":"price_change","market":"0x717c0e8ccd4d5c7040185188fbae28be901ca589a11a94b1b38ca36a79eccfeb","price_changes":[{"asset_id":"41448400836309843603620980831210604935021861034693225347475867885462478926555","best_ask":"0.48","best_bid":"0.47","hash":"046bc547a96f9f3fa6d99acd97bc7d844229f375","price":"0.42","side":"BUY","size":"403"},{"asset_id":"24254094493625419915756280046002869097156693848522361803041977572204227262166","best_ask":"0.53","best_bid":"0.52","hash":"47623c2e631c4fde5af0306d4991122db9bedb3d","price":"0.58","side":"SELL","size":"403"}],"timestamp":"1785121859895"},"payload_hash":"5f30cbc30fde7d55b4e91a29cc72a10ce931aa206eb85c68d51426ddf7bbbc65","raw_frame":"{\"market\":\"0x717c0e8ccd4d5c7040185188fbae28be901ca589a11a94b1b38ca36a79eccfeb\", \"price_changes\":[{\"asset_id\":\"41448400836309843603620980831210604935021861034693225347475867885462478926555\", \"price\":\"0.42\", \"size\":\"403\", \"side\":\"BUY\", \"hash\":\"046bc547a96f9f3fa6d99acd97bc7d844229f375\", \"best_bid\":\"0.47\", \"best_ask\":\"0.48\"}, {\"asset_id\":\"24254094493625419915756280046002869097156693848522361803041977572204227262166\", \"price\":\"0.58\", \"size\":\"403\", \"side\":\"SELL\", \"hash\":\"47623c2e631c4fde5af0306d4991122db9bedb3d\", \"best_bid\":\"0.52\", \"best_ask\":\"0.53\"}], \"timestamp\":\"1785121859895\", \"event_type\":\"price_change\"}","received_at":"2026-07-27T03:10:59.953091Z","schema_version":"clob-market-ws.price_change.v1","sequence":null,"server_hash":null,"server_timestamp":"1785121859895","session_id":"dd162b8dca5f43ff811d304e69a06123","source":"clob_market_ws"},"received_at":"2026-07-27T03:10:59.953091Z","record_id":"717ab18f7e966c9e815835e11a6d79a196dd5b823294ac5384fab67d85a8384e","schema_fingerprint":"4aa3821a28b0b7c2400bc59aba4bcc0a76e971dadd19610d3ad38c768e124dc7","schema_version":"edge-lab-recorder.raw.v1","sequence":null,"source":"clob_market_ws"}
{"event_at":"2026-07-27T03:10:59.895000Z","event_fingerprint":"14872ab1cb2223297e52af6b3e9e58ee63aaa5bb4a757b61984550a1f1da0570","payload":{"connection_id":"c7dc2e4762f849c6b6f9306b6518dcab","event_at":"2026-07-27T03:10:59.895000Z","event_type":"price_change","frame_hash":"2b4df6f04a2a2d84fde658f940c7a8107976d7041a866030c47752cbda59173d","frame_index":0,"kind":"data","monotonic_ns":223843287529500,"payload":{"event_type":"price_change","market":"0x717c0e8ccd4d5c7040185188fbae28be901ca589a11a94b1b38ca36a79eccfeb","price_changes":[{"asset_id":"41448400836309843603620980831210604935021861034693225347475867885462478926555","best_ask":"0.48","best_bid":"0.47","hash":"5724c167c58ff2b7f327942666936bb09897619d","price":"0.42","side":"BUY","size":"408"},{"asset_id":"24254094493625419915756280046002869097156693848522361803041977572204227262166","best_ask":"0.53","best_bid":"0.52","hash":"be0f98e8b5d234c289a4de870e4683de1a40ed48","price":"0.58","side":"SELL","size":"408"}],"timestamp":"1785121859895"},"payload_hash":"ab7dd4ee2670ee26342b279434be095e68dd0ed7c566c48f25cf4dd08eca0491","raw_frame":"{\"market\":\"0x717c0e8ccd4d5c7040185188fbae28be901ca589a11a94b1b38ca36a79eccfeb\", \"price_changes\":[{\"asset_id\":\"41448400836309843603620980831210604935021861034693225347475867885462478926555\", \"price\":\"0.42\", \"size\":\"408\", \"side\":\"BUY\", \"hash\":\"5724c167c58ff2b7f327942666936bb09897619d\", \"best_bid\":\"0.47\", \"best_ask\":\"0.48\"}, {\"asset_id\":\"24254094493625419915756280046002869097156693848522361803041977572204227262166\", \"price\":\"0.58\", \"size\":\"408\", \"side\":\"SELL\", \"hash\":\"be0f98e8b5d234c289a4de870e4683de1a40ed48\", \"best_bid\":\"0.52\", \"best_ask\":\"0.53\"}], \"timestamp\":\"1785121859895\", \"event_type\":\"price_change\"}","received_at":"2026-07-27T03:10:59.957231Z","schema_version":"clob-market-ws.price_change.v1","sequence":null,"server_hash":null,"server_timestamp":"1785121859895","session_id":"dd162b8dca5f43ff811d304e69a06123","source":"clob_market_ws"},"received_at":"2026-07-27T03:10:59.957231Z","record_id":"15bd9fe9514dcd374621d09fee7a5568d0d888c7d5c057e2b5d0ebd38a80f427","schema_fingerprint":"4aa3821a28b0b7c2400bc59aba4bcc0a76e971dadd19610d3ad38c768e124dc7","schema_version":"edge-lab-recorder.raw.v1","sequence":null,"source":"clob_market_ws"}
{"event_at":"2026-07-27T03:10:59.896000Z","event_fingerprint":"ffe72de873b38a9605078e70b38f26c7c732d8afd7bc943d1e2342a534788111","payload":{"connection_id":"c7dc2e4762f849c6b6f9306b6518dcab","event_at":"2026-07-27T03:10:59.896000Z","event_type":"price_change","frame_hash":"bf5cfe147b32df9e82f66ca43dd17a12dfaf2344a2d4be415d964843f1332f69","frame_index":0,"kind":"data","monotonic_ns":223843293332291,"payload":{"event_type":"price_change","market":"0x717c0e8ccd4d5c7040185188fbae28be901ca589a11a94b1b38ca36a79eccfeb","price_changes":[{"asset_id":"41448400836309843603620980831210604935021861034693225347475867885462478926555","best_ask":"0.48","best_bid":"0.47","hash":"76d01c87f96b728d23bd070dbc21bd23a8c4bfb2","price":"0.42","side":"BUY","size":"413"},{"asset_id":"24254094493625419915756280046002869097156693848522361803041977572204227262166","best_ask":"0.53","best_bid":"0.52","hash":"9dc9a6063b786ef2cfdfaf1289e0640a7d3cb8fe","price":"0.58","side":"SELL","size":"413"}],"timestamp":"1785121859896"},"payload_hash":"d3743283f9a6b4087010d0b26f22ab13564d0092045bf2c7f3f51ba06902d0d9","raw_frame":"{\"market\":\"0x717c0e8ccd4d5c7040185188fbae28be901ca589a11a94b1b38ca36a79eccfeb\", \"price_changes\":[{\"asset_id\":\"41448400836309843603620980831210604935021861034693225347475867885462478926555\", \"price\":\"0.42\", \"size\":\"413\", \"side\":\"BUY\", \"hash\":\"76d01c87f96b728d23bd070dbc21bd23a8c4bfb2\", \"best_bid\":\"0.47\", \"best_ask\":\"0.48\"}, {\"asset_id\":\"24254094493625419915756280046002869097156693848522361803041977572204227262166\", \"price\":\"0.58\", \"size\":\"413\", \"side\":\"SELL\", \"hash\":\"9dc9a6063b786ef2cfdfaf1289e0640a7d3cb8fe\", \"best_bid\":\"0.52\", \"best_ask\":\"0.53\"}], \"timestamp\":\"1785121859896\", \"event_type\":\"price_change\"}","received_at":"2026-07-27T03:10:59.963033Z","schema_version":"clob-market-ws.price_change.v1","sequence":null,"server_hash":null,"server_timestamp":"1785121859896","session_id":"dd162b8dca5f43ff811d304e69a06123","source":"clob_market_ws"},"received_at":"2026-07-27T03:10:59.963033Z","record_id":"789fcb1ab6eb45e0de2dac5cd0924c44c7b38453c1eea9e98f4893c2565e4aa8","schema_fingerprint":"4aa3821a28b0b7c2400bc59aba4bcc0a76e971dadd19610d3ad38c768e124dc7","schema_version":"edge-lab-recorder.raw.v1","sequence":null,"source":"clob_market_ws"}
{"event_at":"2026-07-27T03:10:59.897000Z","event_fingerprint":"ba58597037578aea4593e659f9cb0b99ee46f7b63ca7490398d67dbcc454b91e","payload":{"connection_id":"c7dc2e4762f849c6b6f9306b6518dcab","event_at":"2026-07-27T03:10:59.897000Z","event_type":"price_change","frame_hash":"b31d8bc6404c2b4f3d5312c29d0e5162895f19ca65b8f1e57d6356ae2be2aae9","frame_index":0,"kind":"data","monotonic_ns":223843296740250,"payload":{"event_type":"price_change","market":"0x717c0e8ccd4d5c7040185188fbae28be901ca589a11a94b1b38ca36a79eccfeb","price_changes":[{"asset_id":"41448400836309843603620980831210604935021861034693225347475867885462478926555","best_ask":"0.48","best_bid":"0.47","hash":"689c156fc5c3628804da7a77e0cbf2363ddc01cf","price":"0.42","side":"BUY","size":"418"},{"asset_id":"24254094493625419915756280046002869097156693848522361803041977572204227262166","best_ask":"0.53","best_bid":"0.52","hash":"cb7ce3a9a7ab38de0e44cffd671aa890b1399e4b","price":"0.58","side":"SELL","size":"418"}],"timestamp":"1785121859897"},"payload_hash":"f6c79a5acb8485d42a1686f44c45660aeec9ee9f0b1c29358a63a74fc4e037a2","raw_frame":"{\"market\":\"0x717c0e8ccd4d5c7040185188fbae28be901ca589a11a94b1b38ca36a79eccfeb\", \"price_changes\":[{\"asset_id\":\"41448400836309843603620980831210604935021861034693225347475867885462478926555\", \"price\":\"0.42\", \"size\":\"418\", \"side\":\"BUY\", \"hash\":\"689c156fc5c3628804da7a77e0cbf2363ddc01cf\", \"best_bid\":\"0.47\", \"best_ask\":\"0.48\"}, {\"asset_id\":\"24254094493625419915756280046002869097156693848522361803041977572204227262166\", \"price\":\"0.58\", \"size\":\"418\", \"side\":\"SELL\", \"hash\":\"cb7ce3a9a7ab38de0e44cffd671aa890b1399e4b\", \"best_bid\":\"0.52\", \"best_ask\":\"0.53\"}], \"timestamp\":\"1785121859897\", \"event_type\":\"price_change\"}","received_at":"2026-07-27T03:10:59.966440Z","schema_version":"clob-market-ws.price_change.v1","sequence":null,"server_hash":null,"server_timestamp":"1785121859897","session_id":"dd162b8dca5f43ff811d304e69a06123","source":"clob_market_ws"},"received_at":"2026-07-27T03:10:59.966440Z","record_id":"4583057c93db71b6dcb1f81cc4b8d1d8f391d392fe88f45d343146b7f4443bf3","schema_fingerprint":"4aa3821a28b0b7c2400bc59aba4bcc0a76e971dadd19610d3ad38c768e124dc7","schema_version":"edge-lab-recorder.raw.v1","sequence":null,"source":"clob_market_ws"}
