{"event_at":"2026-07-27T03:27:43.118000Z","event_fingerprint":"500a2f58bd85a7bf03f1361a86f6a939c6e08cc4abbd3357578d3611670dc472","payload":{"connection_id":"c7dc2e4762f849c6b6f9306b6518dcab","event_at":"2026-07-27T03:27:43.118000Z","event_type":"price_change","frame_hash":"f3eab9a31f6471f621d20a709665cacba45a239fea170bdfe5b5546544483b1a","frame_index":0,"kind":"data","monotonic_ns":224846383035375,"payload":{"event_type":"price_change","market":"0x717c0e8ccd4d5c7040185188fbae28be901ca589a11a94b1b38ca36a79eccfeb","price_changes":[{"asset_id":"24254094493625419915756280046002869097156693848522361803041977572204227262166","best_ask":"0.92","best_bid":"0.91","hash":"ceeddd88a6316058cf2f8bc64aa75558ae641585","price":"0.84","side":"BUY","size":"100"},{"asset_id":"41448400836309843603620980831210604935021861034693225347475867885462478926555","best_ask":"0.09","best_bid":"0.08","hash":"383a0588bb29c1349e63ca813de61359071c50c0","price":"0.16","side":"SELL","size":"100"}],"timestamp":"1785122863118"},"payload_hash":"55581528143c11d2b9519dcc4a9b855681a6a8901a9687b15f96afa15492766f","raw_frame":"{\"market\":\"0x717c0e8ccd4d5c7040185188fbae28be901ca589a11a94b1b38ca36a79eccfeb\", \"price_changes\":[{\"asset_id\":\"24254094493625419915756280046002869097156693848522361803041977572204227262166\", \"price\":\"0.84\", \"size\":\"100\", \"side\":\"BUY\", \"hash\":\"ceeddd88a6316058cf2f8bc64aa75558ae641585\", \"best_bid\":\"0.91\", \"best_ask\":\"0.92\"}, {\"asset_id\":\"41448400836309843603620980831210604935021861034693225347475867885462478926555\", \"price\":\"0.16\", \"size\":\"100\", \"side\":\"SELL\", \"hash\":\"383a0588bb29c1349e63ca813de61359071c50c0\", \"best_bid\":\"0.08\", \"best_ask\":\"0.09\"}], \"timestamp\":\"1785122863118\", \"event_type\":\"price_change\"}","received_at":"2026-07-27T03:27:43.021557Z","schema_version":"clob-market-ws.price_change.v1","sequence":null,"server_hash":null,"server_timestamp":"1785122863118","session_id":"dd162b8dca5f43ff811d304e69a06123","source":"clob_market_ws"},"received_at":"2026-07-27T03:27:43.021557Z","record_id":"c641170065aa0d40f613ea5679cd6c84b002ff1166f8b13d1ef6a38aa5f2db60","schema_fingerprint":"4aa3821a28b0b7c2400bc59aba4bcc0a76e971dadd19610d3ad38c768e124dc7","schema_version":"edge-lab-recorder.raw.v1","sequence":null,"source":"clob_market_ws"}
{"event_at":"2026-07-27T03:27:43.118000Z","event_fingerprint":"7399fd9d7a01682f3cd3f14e343204e65fd1484ed88f8e4f5a90589d13f6f161","payload":{"connection_id":"c7dc2e4762f849c6b6f9306b6518dcab","event_at":"2026-07-27T03:27:43.118000Z","event_type":"price_change","frame_hash":"b6d1b5ed06752fb9c3787cea75665e66bf035b0c52394f08ce3b7f0c91a1fc80","frame_index":0,"kind":"data","monotonic_ns":224846406140875,"payload":{"event_type":"price_change","market":"0x717c0e8ccd4d5c7040185188fbae28be901ca589a11a94b1b38ca36a79eccfeb","price_changes":[{"asset_id":"41448400836309843603620980831210604935021861034693225347475867885462478926555","best_ask":"0.09","best_bid":"0.08","hash":"383a0588bb29c1349e63ca813de61359071c50c0","price":"0.07","side":"BUY","size":"35.16"},{"asset_id":"24254094493625419915756280046002869097156693848522361803041977572204227262166","best_ask":"0.92","best_bid":"0.91","hash":"ceeddd88a6316058cf2f8bc64aa75558ae641585","price":"0.93","side":"SELL","size":"35.16"}],"timestamp":"1785122863118"},"payload_hash":"92517f17677f643b0dfa07607d27ff1eeb05270781e435e8b8e76f9746470b04","raw_frame":"{\"market\":\"0x717c0e8ccd4d5c7040185188fbae28be901ca589a11a94b1b38ca36a79eccfeb\", \"price_changes\":[{\"asset_id\":\"41448400836309843603620980831210604935021861034693225347475867885462478926555\", \"price\":\"0.07\", \"size\":\"35.16\", \"side\":\"BUY\", \"hash\":\"383a0588bb29c1349e63ca813de61359071c50c0\", \"best_bid\":\"0.08\", \"best_ask\":\"0.09\"}, {\"asset_id\":\"24254094493625419915756280046002869097156693848522361803041977572204227262166\", \"price\":\"0.93\", \"size\":\"35.16\", \"side\":\"SELL\", \"hash\":\"ceeddd88a6316058cf2f8bc64aa75558ae641585\", \"best_bid\":\"0.91\", \"best_ask\":\"0.92\"}], \"timestamp\":\"1785122863118\", \"event_type\":\"price_change\"}","received_at":"2026-07-27T03:27:43.044661Z","schema_version":"clob-market-ws.price_change.v1","sequence":null,"server_hash":null,"server_timestamp":"1785122863118","session_id":"dd162b8dca5f43ff811d304e69a06123","source":"clob_market_ws"},"received_at":"2026-07-27T03:27:43.044661Z","record_id":"d4de9cc3bf6ff8e84b01f3422e4dace639dd1a1aa433349916472548038e3e79","schema_fingerprint":"4aa3821a28b0b7c2400bc59aba4bcc0a76e971dadd19610d3ad38c768e124dc7","schema_version":"edge-lab-recorder.raw.v1","sequence":null,"source":"clob_market_ws"}
{"event_at":"2026-07-27T03:27:43.120000Z","event_fingerprint":"233519144753059215f0c533c3ccea741500aa06e3a58a385abcbd91e473a6f5","payload":{"connection_id":"c7dc2e4762f849c6b6f9306b6518dcab","event_at":"2026-07-27T03:27:43.120000Z","event_type":"price_change","frame_hash":"c34aec3e8e406be67631b9882ad207ccdfcb630e5fccd35702785b2a93476cc5","frame_index":0,"kind":"data","monotonic_ns":224846411220750,"payload":{"event_type":"price_change","market":"0x717c0e8ccd4d5c7040185188fbae28be901ca589a11a94b1b38ca36a79eccfeb","price_changes":[{"asset_id":"41448400836309843603620980831210604935021861034693225347475867885462478926555","best_ask":"0.09","best_bid":"0.08","hash":"136df11537effacee84fbe82dfbedbd4635e748c","price":"0.12","side":"SELL","size":"344.55"},{"asset_id":"24254094493625419915756280046002869097156693848522361803041977572204227262166","best_ask":"0.92","best_bid":"0.91","hash":"e2f9ccd8990932525a971ede95f79f3f951bf28b","price":"0.88","side":"BUY","size":"344.55"}],"timestamp":"1785122863120"},"payload_hash":"677b62230cbac70a9ac47580b2cecfa50f1016c821c28d31f929b5b051482051","raw_frame":"{\"market\":\"0x717c0e8ccd4d5c7040185188fbae28be901ca589a11a94b1b38ca36a79eccfeb\", \"price_changes\":[{\"asset_id\":\"41448400836309843603620980831210604935021861034693225347475867885462478926555\", \"price\":\"0.12\", \"size\":\"344.55\", \"side\":\"SELL\", \"hash\":\"136df11537effacee84fbe82dfbedbd4635e748c\", \"best_bid\":\"0.08\", \"best_ask\":\"0.09\"}, {\"asset_id\":\"24254094493625419915756280046002869097156693848522361803041977572204227262166\", \"price\":\"0.88\", \"size\":\"344.55\", \"side\":\"BUY\", \"hash\":\"e2f9ccd8990932525a971ede95f79f3f951bf28b\", \"best_bid\":\"0.91\", \"best_ask\":\"0.92\"}], \"timestamp\":\"1785122863120\", \"event_type\":\"price_change\"}","received_at":"2026-07-27T03:27:43.049740Z","schema_version":"clob-market-ws.price_change.v1","sequence":null,"server_hash":null,"server_timestamp":"1785122863120","session_id":"dd162b8dca5f43ff811d304e69a06123","source":"clob_market_ws"},"received_at":"2026-07-27T03:27:43.049740Z","record_id":"7dc5f6a8bbf1cfef90bfb3af4e7e21ba43bae1894ef6959d09fe3f75996be46f","schema_fingerprint":"4aa3821a28b0b7c2400bc59aba4bcc0a76e971dadd19610d3ad38c768e124dc7","schema_version":"edge-lab-recorder.raw.v1","sequence":null,"source":"clob_market_ws"}
{"event_at":"2026-07-27T03:27:43.146000Z","event_fingerprint":"9d6edf67a391e412d1e39cd1a9365f0bf11dee9e44f3a4392d7acccbb8b519ef","payload":{"connection_id":"c7dc2e4762f849c6b6f9306b6518dcab","event_at":"2026-07-27T03:27:43.146000Z","event_type":"price_change","frame_hash":"a87b2dd0711bd5aa0f2cd270354e9369f2e543ffe6ec10bad3d7ecc85102953f","frame_index":0,"kind":"data","monotonic_ns":224846414468208,"payload":{"event_type":"price_change","market":"0x717c0e8ccd4d5c7040185188fbae28be901ca589a11a94b1b38ca36a79eccfeb","price_changes":[{"asset_id":"41448400836309843603620980831210604935021861034693225347475867885462478926555","best_ask":"0.09","best_bid":"0.08","hash":"e7664589b05e60b233155f2dfac72e49659668e3","price":"0.01","side":"BUY","size":"5240.02"},{"asset_id":"24254094493625419915756280046002869097156693848522361803041977572204227262166","best_ask":"0.92","best_bid":"0.91","hash":"f19faf8ce51ddce0e55a912e714d04bd3ec246d3","price":"0.99","side":"SELL","size":"5240.02"}],"timestamp":"1785122863146"},"payload_hash":"a82e03d8a50da9034834b466f292452913d2b782aa6fe011b9c461852a3e9c82","raw_frame":"{\"market\":\"0x717c0e8ccd4d5c7040185188fbae28be901ca589a11a94b1b38ca36a79eccfeb\", \"price_changes\":[{\"asset_id\":\"41448400836309843603620980831210604935021861034693225347475867885462478926555\", \"price\":\"0.01\", \"size\":\"5240.02\", \"side\":\"BUY\", \"hash\":\"e7664589b05e60b233155f2dfac72e49659668e3\", \"best_bid\":\"0.08\", \"best_ask\":\"0.09\"}, {\"asset_id\":\"24254094493625419915756280046002869097156693848522361803041977572204227262166\", \"price\":\"0.99\", \"size\":\"5240.02\", \"side\":\"SELL\", \"hash\":\"f19faf8ce51ddce0e55a912e714d04bd3ec246d3\", \"best_bid\":\"0.91\", \"best_ask\":\"0.92\"}], \"timestamp\":\"1785122863146\", \"event_type\":\"price_change\"}","received_at":"2026-07-27T03:27:43.052987Z","schema_version":"clob-market-ws.price_change.v1","sequence":null,"server_hash":null,"server_timestamp":"1785122863146","session_id":"dd162b8dca5f43ff811d304e69a06123","source":"clob_market_ws"},"received_at":"2026-07-27T03:27:43.052987Z","record_id":"1a70eca4b2a9abe3dac4559ccb476fcddb2744e488e1c861d774f0336c4527af","schema_fingerprint":"4aa3821a28b0b7c2400bc59aba4bcc0a76e971dadd19610d3ad38c768e124dc7","schema_version":"edge-lab-recorder.raw.v1","sequence":null,"source":"clob_market_ws"}
{"event_at":"2026-07-27T03:27:43.172000Z","event_fingerprint":"2927c4d92614bf0558054caaba69c5d271ea319927458610ed95983f229da89d","payload":{"connection_id":"c7dc2e4762f849c6b6f9306b6518dcab","event_at":"2026-07-27T03:27:43.172000Z","event_type":"price_change","frame_hash":"7588fd8fc671169502df8010724f72a3847488455bc251d5af29c65e4cb1f730","frame_index":0,"kind":"data","monotonic_ns":224846418329583,"payload":{"event_type":"price_change","market":"0x717c0e8ccd4d5c7040185188fbae28be901ca589a11a94b1b38ca36a79eccfeb","price_changes":[{"asset_id":"24254094493625419915756280046002869097156693848522361803041977572204227262166","best_ask":"0.92","best_bid":"0.91","hash":"100036a2010fa4e0df99a232d62c78299bcc6a8a","price":"0.01","side":"BUY","size":"5155.02"},{"asset_id":"41448400836309843603620980831210604935021861034693225347475867885462478926555","best_ask":"0.09","best_bid":"0.08","hash":"fa6361baf793942412d8cbe21e429e959136ff05","price":"0.99","side":"SELL","size":"5155.02"}],"timestamp":"1785122863172"},"payload_hash":"1763c7b58405de3a9c23cebd8bc6fdbacf5f4ae3c775dcd323e44e5581897485","raw_frame":"{\"market\":\"0x717c0e8ccd4d5c7040185188fbae28be901ca589a11a94b1b38ca36a79eccfeb\", \"price_changes\":[{\"asset_id\":\"24254094493625419915756280046002869097156693848522361803041977572204227262166\", \"price\":\"0.01\", \"size\":\"5155.02\", \"side\":\"BUY\", \"hash\":\"100036a2010fa4e0df99a232d62c78299bcc6a8a\", \"best_bid\":\"0.91\", \"best_ask\":\"0.92\"}, {\"asset_id\":\"41448400836309843603620980831210604935021861034693225347475867885462478926555\", \"price\":\"0.99\", \"size\":\"5155.02\", \"side\":\"SELL\", \"hash\":\"fa6361baf793942412d8cbe21e429e959136ff05\", \"best_bid\":\"0.08\", \"best_ask\":\"0.09\"}], \"timestamp\":\"1785122863172\", \"event_type\":\"price_change\"}","received_at":"2026-07-27T03:27:43.056851Z","schema_version":"clob-market-ws.price_change.v1","sequence":null,"server_hash":null,"server_timestamp":"1785122863172","session_id":"dd162b8dca5f43ff811d304e69a06123","source":"clob_market_ws"},"received_at":"2026-07-27T03:27:43.056851Z","record_id":"e0fc39d9c0f6bf6d1498902c083c11275a4d2b848b724e28583094fba327c7ce","schema_fingerprint":"4aa3821a28b0b7c2400bc59aba4bcc0a76e971dadd19610d3ad38c768e124dc7","schema_version":"edge-lab-recorder.raw.v1","sequence":null,"source":"clob_market_ws"}
{"event_at":"2026-07-27T03:27:43.183000Z","event_fingerprint":"8b9a8abcc8b61cfe079d468bdae71de2878e2866854735d30c17b44e99937afd","payload":{"connection_id":"c7dc2e4762f849c6b6f9306b6518dcab","event_at":"2026-07-27T03:27:43.183000Z","event_type":"price_change","frame_hash":"05f2954987e6f7f363157294497f01b4cb025dc4e1440ae2aa3822c9dac53ec1","frame_index":0,"kind":"data","monotonic_ns":224846422064833,"payload":{"event_type":"price_change","market":"0x717c0e8ccd4d5c7040185188fbae28be901ca589a11a94b1b38ca36a79eccfeb","price_changes":[{"asset_id":"24254094493625419915756280046002869097156693848522361803041977572204227262166","best_ask":"0.92","best_bid":"0.91","hash":"942d716609118656af499af11a7ddc496dfe655a","price":"0.86","side":"BUY","size":"250"},{"asset_id":"41448400836309843603620980831210604935021861034693225347475867885462478926555","best_ask":"0.09","best_bid":"0.08","hash":"68da13179fdd418fe4bfbd4c024f9a7607722bc7","price":"0.14","side":"SELL","size":"250"}],"timestamp":"1785122863183"},"payload_hash":"af65e36c65920cd98d3887ef1fce3332fbeea48f86fb7ca0c2f5d6bb96597d1c","raw_frame":"{\"market\":\"0x717c0e8ccd4d5c7040185188fbae28be901ca589a11a94b1b38ca36a79eccfeb\", \"price_changes\":[{\"asset_id\":\"24254094493625419915756280046002869097156693848522361803041977572204227262166\", \"price\":\"0.86\", \"size\":\"250\", \"side\":\"BUY\", \"hash\":\"942d716609118656af499af11a7ddc496dfe655a\", \"best_bid\":\"0.91\", \"best_ask\":\"0.92\"}, {\"asset_id\":\"41448400836309843603620980831210604935021861034693225347475867885462478926555\", \"price\":\"0.14\", \"size\":\"250\", \"side\":\"SELL\", \"hash\":\"68da13179fdd418fe4bfbd4c024f9a7607722bc7\", \"best_bid\":\"0.08\", \"best_ask\":\"0.09\"}], \"timestamp\":\"1785122863183\", \"event_type\":\"price_change\"}","received_at":"2026-07-27T03:27:43.060589Z","schema_version":"clob-market-ws.price_change.v1","sequence":null,"server_hash":null,"server_timestamp":"1785122863183","session_id":"dd162b8dca5f43ff811d304e69a06123","source":"clob_market_ws"},"received_at":"2026-07-27T03:27:43.060589Z","record_id":"3651602a9b2e76f07c2cc363524db6c72957bc7afda2b468b7d989bb38077f26","schema_fingerprint":"4aa3821a28b0b7c2400bc59aba4bcc0a76e971dadd19610d3ad38c768e124dc7","schema_version":"edge-lab-recorder.raw.v1","sequence":null,"source":"clob_market_ws"}
{"event_at":"2026-07-27T03:27:43.241000Z","event_fingerprint":"2bd7461c9aa927333fa062ef1f5ca8c078217fc689d498d65e5177bb523b955a","payload":{"connection_id":"c7dc2e4762f849c6b6f9306b6518dcab","event_at":"2026-07-27T03:27:43.241000Z","event_type":"price_change","frame_hash":"f86a79e70da36c0a474c7682d09939e18022cd6c2db329feaa3642ec0dd273dd","frame_index":0,"kind":"data","monotonic_ns":224846492981416,"payload":{"event_type":"price_change","market":"0x717c0e8ccd4d5c7040185188fbae28be901ca589a11a94b1b38ca36a79eccfeb","price_changes":[{"asset_id":"41448400836309843603620980831210604935021861034693225347475867885462478926555","best_ask":"0.09","best_bid":"0.08","hash":"753baadb6b8fe5117ada3d18d6463476ed6b9e79","price":"0.12","side":"SELL","size":"338.5"},{"asset_id":"24254094493625419915756280046002869097156693848522361803041977572204227262166","best_ask":"0.92","best_bid":"0.91","hash":"d7f5ee91ad53da2b1fbd2b12db5c0a1a377a1510","price":"0.88","side":"BUY","size":"338.5"}],"timestamp":"1785122863241"},"payload_hash":"edaf34903e133c07e573d6e7ae2c9e1b85d3c14b0bb007199c64bb0df9558e78","raw_frame":"{\"market\":\"0x717c0e8ccd4d5c7040185188fbae28be901ca589a11a94b1b38ca36a79eccfeb\", \"price_changes\":[{\"asset_id\":\"41448400836309843603620980831210604935021861034693225347475867885462478926555\", \"price\":\"0.12\", \"size\":\"338.5\", \"side\":\"SELL\", \"hash\":\"753baadb6b8fe5117ada3d18d6463476ed6b9e79\", \"best_bid\":\"0.08\", \"best_ask\":\"0.09\"}, {\"asset_id\":\"24254094493625419915756280046002869097156693848522361803041977572204227262166\", \"price\":\"0.88\", \"size\":\"338.5\", \"side\":\"BUY\", \"hash\":\"d7f5ee91ad53da2b1fbd2b12db5c0a1a377a1510\", \"best_bid\":\"0.91\", \"best_ask\":\"0.92\"}], \"timestamp\":\"1785122863241\", \"event_type\":\"price_change\"}","received_at":"2026-07-27T03:27:43.131503Z","schema_version":"clob-market-ws.price_change.v1","sequence":null,"server_hash":null,"server_timestamp":"1785122863241","session_id":"dd162b8dca5f43ff811d304e69a06123","source":"clob_market_ws"},"received_at":"2026-07-27T03:27:43.131503Z","record_id":"09bbd0e7a4a2d7cfb8e76cf4d3c5b4e91ad477483d9bd6581f0d984d5dfe6f80","schema_fingerprint":"4aa3821a28b0b7c2400bc59aba4bcc0a76e971dadd19610d3ad38c768e124dc7","schema_version":"edge-lab-recorder.raw.v1","sequence":null,"source":"clob_market_ws"}
{"event_at":"2026-07-27T03:27:43.251000Z","event_fingerprint":"4cf02e23ce55cb9a8e9f052d45ddcd92ae596e96e1c8c59f0ac19deb288444a9","payload":{"connection_id":"c7dc2e4762f849c6b6f9306b6518dcab","event_at":"2026-07-27T03:27:43.251000Z","event_type":"price_change","frame_hash":"accaf461df354f17ea9cf51b026b243feb199986deb4c9dadd0b2b067a2e55ee","frame_index":0,"kind":"data","monotonic_ns":224846495762708,"payload":{"event_type":"price_change","market":"0x717c0e8ccd4d5c7040185188fbae28be901ca589a11a94b1b38ca36a79eccfeb","price_changes":[{"asset_id":"24254094493625419915756280046002869097156693848522361803041977572204227262166","best_ask":"0.92","best_bid":"0.91","hash":"6d0dae8c7557cb884e51e66bf6518b2b59ce45c1","price":"0.01","side":"BUY","size":"5160.02"},{"asset_id":"41448400836309843603620980831210604935021861034693225347475867885462478926555","best_ask":"0.09","best_bid":"0.08","hash":"bfb5974c729f6642a74009a7e9c6a9eac0c21ec3","price":"0.99","side":"SELL","size":"5160.02"}],"timestamp":"1785122863251"},"payload_hash":"1dc2cd7aee310142d36470680e6cb661e7b9445d714c6f9e6b30171756e03e99","raw_frame":"{\"market\":\"0x717c0e8ccd4d5c7040185188fbae28be901ca589a11a94b1b38ca36a79eccfeb\", \"price_changes\":[{\"asset_id\":\"24254094493625419915756280046002869097156693848522361803041977572204227262166\", \"price\":\"0.01\", \"size\":\"5160.02\", \"side\":\"BUY\", \"hash\":\"6d0dae8c7557cb884e51e66bf6518b2b59ce45c1\", \"best_bid\":\"0.91\", \"best_ask\":\"0.92\"}, {\"asset_id\":\"41448400836309843603620980831210604935021861034693225347475867885462478926555\", \"price\":\"0.99\", \"size\":\"5160.02\", \"side\":\"SELL\", \"hash\":\"bfb5974c729f6642a74009a7e9c6a9eac0c21ec3\", \"best_bid\":\"0.08\", \"best_ask\":\"0.09\"}], \"timestamp\":\"1785122863251\", \"event_type\":\"price_change\"}","received_at":"2026-07-27T03:27:43.134285Z","schema_version":"clob-market-ws.price_change.v1","sequence":null,"server_hash":null,"server_timestamp":"1785122863251","session_id":"dd162b8dca5f43ff811d304e69a06123","source":"clob_market_ws"},"received_at":"2026-07-27T03:27:43.134285Z","record_id":"d28964e09b77778c5cf91eb1c43ea439459631a15765ce9e2d13ab3b8bf17cae","schema_fingerprint":"4aa3821a28b0b7c2400bc59aba4bcc0a76e971dadd19610d3ad38c768e124dc7","schema_version":"edge-lab-recorder.raw.v1","sequence":null,"source":"clob_market_ws"}
{"event_at":"2026-07-27T03:27:43.262000Z","event_fingerprint":"dff42b8ece35ca4e388e339578b8290375eb3c460d034f7f360bc912fd9673e1","payload":{"connection_id":"c7dc2e4762f849c6b6f9306b6518dcab","event_at":"2026-07-27T03:27:43.262000Z","event_type":"price_change","frame_hash":"9f1b1e3ab510300ef197f10601df3893cd1572d8248529086c5682e89bdb1df7","frame_index":0,"kind":"data","monotonic_ns":224846501010958,"payload":{"event_type":"price_change","market":"0x717c0e8ccd4d5c7040185188fbae28be901ca589a11a94b1b38ca36a79eccfeb","price_changes":[{"asset_id":"41448400836309843603620980831210604935021861034693225347475867885462478926555","best_ask":"0.09","best_bid":"0.08","hash":"c8fdf8f8cf57446233aa842b22ab0d81771d5e9d","price":"0.03","side":"BUY","size":"1360"},{"asset_id":"24254094493625419915756280046002869097156693848522361803041977572204227262166","best_ask":"0.92","best_bid":"0.91","hash":"31991ded6fa89b4a66a1e303c7f66bdf817ea5a8","price":"0.97","side":"SELL","size":"1360"}],"timestamp":"1785122863262"},"payload_hash":"a9b4e02ac1da400db99a88f2fcf65fd32d3675410397a6175844b6db36e611b0","raw_frame":"{\"market\":\"0x717c0e8ccd4d5c7040185188fbae28be901ca589a11a94b1b38ca36a79eccfeb\", \"price_changes\":[{\"asset_id\":\"41448400836309843603620980831210604935021861034693225347475867885462478926555\", \"price\":\"0.03\", \"size\":\"1360\", \"side\":\"BUY\", \"hash\":\"c8fdf8f8cf57446233aa842b22ab0d81771d5e9d\", \"best_bid\":\"0.08\", \"best_ask\":\"0.09\"}, {\"asset_id\":\"24254094493625419915756280046002869097156693848522361803041977572204227262166\", \"price\":\"0.97\", \"size\":\"1360\", \"side\":\"SELL\", \"hash\":\"31991ded6fa89b4a66a1e303c7f66bdf817ea5a8\", \"best_bid\":\"0.91\", \"best_ask\":\"0.92\"}], \"timestamp\":\"1785122863262\", \"event_type\":\"price_change\"}","received_at":"2026-07-27T03:27:43.139533Z","schema_version":"clob-market-ws.price_change.v1","sequence":null,"server_hash":null,"server_timestamp":"1785122863262","session_id":"dd162b8dca5f43ff811d304e69a06123","source":"clob_market_ws"},"received_at":"2026-07-27T03:27:43.139533Z","record_id":"d69d7ac48fc6b4f45bd4926f624fba406a3e45b14a7436f191b306d5747abe63","schema_fingerprint":"4aa3821a28b0b7c2400bc59aba4bcc0a76e971dadd19610d3ad38c768e124dc7","schema_version":"edge-lab-recorder.raw.v1","sequence":null,"source":"clob_market_ws"}
{"event_at":"2026-07-27T03:27:43.262000Z","event_fingerprint":"ba857ad856aeefa018e2349220cef466cbce3228859964bf3bc46d304a78612d","payload":{"connection_id":"c7dc2e4762f849c6b6f9306b6518dcab","event_at":"2026-07-27T03:27:43.262000Z","event_type":"price_change","frame_hash":"14e1f1f21bc3bc69fec3b464ebd5505bf65d3348c676e24d10055a4b2d931c20","frame_index":0,"kind":"data","monotonic_ns":224846506383000,"payload":{"event_type":"price_change","market":"0x717c0e8ccd4d5c7040185188fbae28be901ca589a11a94b1b38ca36a79eccfeb","price_changes":[{"asset_id":"41448400836309843603620980831210604935021861034693225347475867885462478926555","best_ask":"0.09","best_bid":"0.08","hash":"dd6556f2f47ba96f52553b228892fffa84cee24a","price":"0.03","side":"BUY","size":"985"},{"asset_id":"24254094493625419915756280046002869097156693848522361803041977572204227262166","best_ask":"0.92","best_bid":"0.91","hash":"c644e898727f3e37b9f070ce2c9657b8e5a6db1c","price":"0.97","side":"SELL","size":"985"}],"timestamp":"1785122863262"},"payload_hash":"bac667abbec2bba1718c0754e9b806e39db98127b66e8a6d1002c97ce5dd4390","raw_frame":"{\"market\":\"0x717c0e8ccd4d5c7040185188fbae28be901ca589a11a94b1b38ca36a79eccfeb\", \"price_changes\":[{\"asset_id\":\"41448400836309843603620980831210604935021861034693225347475867885462478926555\", \"price\":\"0.03\", \"size\":\"985\", \"side\":\"BUY\", \"hash\":\"dd6556f2f47ba96f52553b228892fffa84cee24a\", \"best_bid\":\"0.08\", \"best_ask\":\"0.09\"}, {\"asset_id\":\"24254094493625419915756280046002869097156693848522361803041977572204227262166\", \"price\":\"0.97\", \"size\":\"985\", \"side\":\"SELL\", \"hash\":\"c644e898727f3e37b9f070ce2c9657b8e5a6db1c\", \"best_bid\":\"0.91\", \"best_ask\":\"0.92\"}], \"timestamp\":\"1785122863262\", \"event_type\":\"price_change\"}","received_at":"2026-07-27T03:27:43.144905Z","schema_version":"clob-market-ws.price_change.v1","sequence":null,"server_hash":null,"server_timestamp":"1785122863262","session_id":"dd162b8dca5f43ff811d304e69a06123","source":"clob_market_ws"},"received_at":"2026-07-27T03:27:43.144905Z","record_id":"a70ddd91c1a51c6d7fe0298306afe782b21682fc6c336322742a81ad076068d6","schema_fingerprint":"4aa3821a28b0b7c2400bc59aba4bcc0a76e971dadd19610d3ad38c768e124dc7","schema_version":"edge-lab-recorder.raw.v1","sequence":null,"source":"clob_market_ws"}
{"event_at":"2026-07-27T03:27:43.264000Z","event_fingerprint":"4e1cc46994564771582ac6758765951b9453b47463c4de48ea50618b4abd34d4","payload":{"connection_id":"c7dc2e4762f849c6b6f9306b6518dcab","event_at":"2026-07-27T03:27:43.264000Z","event_type":"price_change","frame_hash":"070300c6d08cfeea9bea82238f5f09cdc3e806f5accc7326bb99aa2b3a511165","frame_index":0,"kind":"data","monotonic_ns":224846512431250,"payload":{"event_type":"price_change","market":"0x717c0e8ccd4d5c7040185188fbae28be901ca589a11a94b1b38ca36a79eccfeb","price_changes":[{"asset_id":"24254094493625419915756280046002869097156693848522361803041977572204227262166","best_ask":"0.92","best_bid":"0.91","hash":"6aca2ba9e3109e4096881b1d6a984f84c343917c","price":"0.57","side":"BUY","size":"119.94"},{"asset_id":"41448400836309843603620980831210604935021861034693225347475867885462478926555","best_ask":"0.09","best_bid":"0.08","hash":"5476201fafcdb5de9fd9a1275745e4455911cd43","price":"0.43","side":"SELL","size":"119.94"}],"timestamp":"1785122863264"},"payload_hash":"7b1063abb2ad5517f60581f60b587e5d7b170ff082ede63bdc6a443c13b02660","raw_frame":"{\"market\":\"0x717c0e8ccd4d5c7040185188fbae28be901ca589a11a94b1b38ca36a79eccfeb\", \"price_changes\":[{\"asset_id\":\"24254094493625419915756280046002869097156693848522361803041977572204227262166\", \"price\":\"0.57\", \"size\":\"119.94\", \"side\":\"BUY\", \"hash\":\"6aca2ba9e3109e4096881b1d6a984f84c343917c\", \"best_bid\":\"0.91\", \"best_ask\":\"0.92\"}, {\"asset_id\":\"41448400836309843603620980831210604935021861034693225347475867885462478926555\", \"price\":\"0.43\", \"size\":\"119.94\", \"side\":\"SELL\", \"hash\":\"5476201fafcdb5de9fd9a1275745e4455911cd43\", \"best_bid\":\"0.08\", \"best_ask\":\"0.09\"}], \"timestamp\":\"1785122863264\", \"event_type\":\"price_change\"}","received_at":"2026-07-27T03:27:43.150955Z","schema_version":"clob-market-ws.price_change.v1","sequence":null,"server_hash":null,"server_timestamp":"1785122863264","session_id":"dd162b8dca5f43ff811d304e69a06123","source":"clob_market_ws"},"received_at":"2026-07-27T03:27:43.150955Z","record_id":"d59ae81c2e15117920157f1a528507d47d4e23dd86851d71fdad0d3878e83a6c","schema_fingerprint":"4aa3821a28b0b7c2400bc59aba4bcc0a76e971dadd19610d3ad38c768e124dc7","schema_version":"edge-lab-recorder.raw.v1","sequence":null,"source":"clob_market_ws"}
{"event_at":"2026-07-27T03:27:43.265000Z","event_fingerprint":"06e7222838b09f824b033e070e89575c7ea52066635efe19b20e1517fc9ab3cd","payload":{"connection_id":"c7dc2e4762f849c6b6f9306b6518dcab","event_at":"2026-07-27T03:27:43.265000Z","event_type":"price_change","frame_hash":"27069289e64e526211729ef58d1dd7bde38db82a48592b1871b9e2f22223e313","frame_index":0,"kind":"data","monotonic_ns":224846519538666,"payload":{"event_type":"price_change","market":"0x717c0e8ccd4d5c7040185188fbae28be901ca589a11a94b1b38ca36a79eccfeb","price_changes":[{"asset_id":"41448400836309843603620980831210604935021861034693225347475867885462478926555","best_ask":"0.09","best_bid":"0.08","hash":"65cac4ccf0af73abd380a6b265a833ba09bae1db","price":"0.03","side":"BUY","size":"610"},{"asset_id":"24254094493625419915756280046002869097156693848522361803041977572204227262166","best_ask":"0.92","best_bid":"0.91","hash":"b685c010c0fcbe703fdafb4defa74cba7f6f8794","price":"0.97","side":"SELL","size":"610"}],"timestamp":"1785122863265"},"payload_hash":"c30a0f881b5ae970ab355cc1993e444c6ad76c3d182fee8314e413f105641c3e","raw_frame":"{\"market\":\"0x717c0e8ccd4d5c7040185188fbae28be901ca589a11a94b1b38ca36a79eccfeb\", \"price_changes\":[{\"asset_id\":\"41448400836309843603620980831210604935021861034693225347475867885462478926555\", \"price\":\"0.03\", \"size\":\"610\", \"side\":\"BUY\", \"hash\":\"65cac4ccf0af73abd380a6b265a833ba09bae1db\", \"best_bid\":\"0.08\", \"best_ask\":\"0.09\"}, {\"asset_id\":\"24254094493625419915756280046002869097156693848522361803041977572204227262166\", \"price\":\"0.97\", \"size\":\"610\", \"side\":\"SELL\", \"hash\":\"b685c010c0fcbe703fdafb4defa74cba7f6f8794\", \"best_bid\":\"0.91\", \"best_ask\":\"0.92\"}], \"timestamp\":\"1785122863265\", \"event_type\":\"price_change\"}","received_at":"2026-07-27T03:27:43.158060Z","schema_version":"clob-market-ws.price_change.v1","sequence":null,"server_hash":null,"server_timestamp":"1785122863265","session_id":"dd162b8dca5f43ff811d304e69a06123","source":"clob_market_ws"},"received_at":"2026-07-27T03:27:43.158060Z","record_id":"d5a44436f4aa859eb1ddace01cd31a40ca2ce92e38e499670f7b575ddba98e7e","schema_fingerprint":"4aa3821a28b0b7c2400bc59aba4bcc0a76e971dadd19610d3ad38c768e124dc7","schema_version":"edge-lab-recorder.raw.v1","sequence":null,"source":"clob_market_ws"}
{"event_at":"2026-07-27T03:27:43.266000Z","event_fingerprint":"f676c924df0856074db7664e72c689fcdad21bd217640f9b52c7e521aa351cbf","payload":{"connection_id":"c7dc2e4762f849c6b6f9306b6518dcab","event_at":"2026-07-27T03:27:43.266000Z","event_type":"price_change","frame_hash":"2feec23a05255c1b612a97ee5e5c0523e41b65574220430a5c0eac7a4d6616da","frame_index":0,"kind":"data","monotonic_ns":224846523643041,"payload":{"event_type":"price_change","market":"0x717c0e8ccd4d5c7040185188fbae28be901ca589a11a94b1b38ca36a79eccfeb","price_changes":[{"asset_id":"24254094493625419915756280046002869097156693848522361803041977572204227262166","best_ask":"0.92","best_bid":"0.91","hash":"316bc47cadfece68ecfc3ebab71169503f02a8de","price":"0.57","side":"BUY","size":"62.47"},{"asset_id":"41448400836309843603620980831210604935021861034693225347475867885462478926555","best_ask":"0.09","best_bid":"0.08","hash":"21305ae5127082ed8bfa98f2e615ce450217198d","price":"0.43","side":"SELL","size":"62.47"}],"timestamp":"1785122863266"},"payload_hash":"7fc1d18c23c8609c14778b5326ce76b85e8c2acb480b0d81be20da5e6864bb9d","raw_frame":"{\"market\":\"0x717c0e8ccd4d5c7040185188fbae28be901ca589a11a94b1b38ca36a79eccfeb\", \"price_changes\":[{\"asset_id\":\"24254094493625419915756280046002869097156693848522361803041977572204227262166\", \"price\":\"0.57\", \"size\":\"62.47\", \"side\":\"BUY\", \"hash\":\"316bc47cadfece68ecfc3ebab71169503f02a8de\", \"best_bid\":\"0.91\", \"best_ask\":\"0.92\"}, {\"asset_id\":\"41448400836309843603620980831210604935021861034693225347475867885462478926555\", \"price\":\"0.43\", \"size\":\"62.47\", \"side\":\"SELL\", \"hash\":\"21305ae5127082ed8bfa98f2e615ce450217198d\", \"best_bid\":\"0.08\", \"best_ask\":\"0.09\"}], \"timestamp\":\"1785122863266\", \"event_type\":\"price_change\"}","received_at":"2026-07-27T03:27:43.162167Z","schema_version":"clob-market-ws.price_change.v1","sequence":null,"server_hash":null,"server_timestamp":"1785122863266","session_id":"dd162b8dca5f43ff811d304e69a06123","source":"clob_market_ws"},"received_at":"2026-07-27T03:27:43.162167Z","record_id":"aeb61cfcc968455322c234c80409a0b1c72448dff7d2bf01cbc9caba6b09e54d","schema_fingerprint":"4aa3821a28b0b7c2400bc59aba4bcc0a76e971dadd19610d3ad38c768e124dc7","schema_version":"edge-lab-recorder.raw.v1","sequence":null,"source":"clob_market_ws"}
{"event_at":"2026-07-27T03:27:43.266000Z","event_fingerprint":"2529824b441b5d4ab76e8c69686c28c17bf0fe9f3cb88fa4147e0528a7c2458c","payload":{"connection_id":"c7dc2e4762f849c6b6f9306b6518dcab","event_at":"2026-07-27T03:27:43.266000Z","event_type":"price_change","frame_hash":"8336e02e0ce64fe8164b303be51648b302f2233a609f5677c8ac93585b2ed5ad","frame_index":0,"kind":"data","monotonic_ns":224846529486333,"payload":{"event_type":"price_change","market":"0x717c0e8ccd4d5c7040185188fbae28be901ca589a11a94b1b38ca36a79eccfeb","price_changes":[{"asset_id":"24254094493625419915756280046002869097156693848522361803041977572204227262166","best_ask":"0.92","best_bid":"0.91","hash":"ed1b5a09b66e6e385950acdf8b9537f878499a80","price":"0.01","side":"BUY","size":"5155.02"},{"asset_id":"41448400836309843603620980831210604935021861034693225347475867885462478926555","best_ask":"0.09","best_bid":"0.08","hash":"55cec602fa70735eacb39aac75742d289715fbfa","price":"0.99","side":"SELL","size":"5155.02"}],"timestamp":"1785122863266"},"payload_hash":"354ef2427927bf1d6772c325cbb8493cfe9ac1f7f95eda7fdd084f7baf818bf7","raw_frame":"{\"market\":\"0x717c0e8ccd4d5c7040185188fbae28be901ca589a11a94b1b38ca36a79eccfeb\", \"price_changes\":[{\"asset_id\":\"24254094493625419915756280046002869097156693848522361803041977572204227262166\", \"price\":\"0.01\", \"size\":\"5155.02\", \"side\":\"BUY\", \"hash\":\"ed1b5a09b66e6e385950acdf8b9537f878499a80\", \"best_bid\":\"0.91\", \"best_ask\":\"0.92\"}, {\"asset_id\":\"41448400836309843603620980831210604935021861034693225347475867885462478926555\", \"price\":\"0.99\", \"size\":\"5155.02\", \"side\":\"SELL\", \"hash\":\"55cec602fa70735eacb39aac75742d289715fbfa\", \"best_bid\":\"0.08\", \"best_ask\":\"0.09\"}], \"timestamp\":\"1785122863266\", \"event_type\":\"price_change\"}","received_at":"2026-07-27T03:27:43.168007Z","schema_version":"clob-market-ws.price_change.v1","sequence":null,"server_hash":null,"server_timestamp":"1785122863266","session_id":"dd162b8dca5f43ff811d304e69a06123","source":"clob_market_ws"},"received_at":"2026-07-27T03:27:43.168007Z","record_id":"0889e283731576b4fa2972c9b09885aa5635b066bc289c02f00889401d3426a0","schema_fingerprint":"4aa3821a28b0b7c2400bc59aba4bcc0a76e971dadd19610d3ad38c768e124dc7","schema_version":"edge-lab-recorder.raw.v1","sequence":null,"source":"clob_market_ws"}
{"event_at":"2026-07-27T03:27:43.267000Z","event_fingerprint":"4f1106624d2a82d3db4aebf79711cd379dc7971954a0bdd8b0f009bc12e8a856","payload":{"connection_id":"c7dc2e4762f849c6b6f9306b6518dcab","event_at":"2026-07-27T03:27:43.267000Z","event_type":"price_change","frame_hash":"f7e3da4beeca0e67ffb162f8658d3fba4c22098f5016b8e9c3e4fea79d205647","frame_index":0,"kind":"data","monotonic_ns":224846534081583,"payload":{"event_type":"price_change","market":"0x717c0e8ccd4d5c7040185188fbae28be901ca589a11a94b1b38ca36a79eccfeb","price_changes":[{"asset_id":"24254094493625419915756280046002869097156693848522361803041977572204227262166","best_ask":"0.92","best_bid":"0.91","hash":"0abc30755756a6f8301977a28aef1e30551a9b3f","price":"0.57","side":"BUY","size":"5"},{"asset_id":"41448400836309843603620980831210604935021861034693225347475867885462478926555","best_ask":"0.09","best_bid":"0.08","hash":"98e9a4378d4cce18ed257fb124a5f8a7fcbff458","price":"0.43","side":"SELL","size":"5"}],"timestamp":"1785122863267"},"payload_hash":"77dd5baa470e4dc675728d87934b520e70d6327eec1d31214f9b71daeb3ab720","raw_frame":"{\"market\":\"0x717c0e8ccd4d5c7040185188fbae28be901ca589a11a94b1b38ca36a79eccfeb\", \"price_changes\":[{\"asset_id\":\"24254094493625419915756280046002869097156693848522361803041977572204227262166\", \"price\":\"0.57\", \"size\":\"5\", \"side\":\"BUY\", \"hash\":\"0abc30755756a6f8301977a28aef1e30551a9b3f\", \"best_bid\":\"0.91\", \"best_ask\":\"0.92\"}, {\"asset_id\":\"41448400836309843603620980831210604935021861034693225347475867885462478926555\", \"price\":\"0.43\", \"size\":\"5\", \"side\":\"SELL\", \"hash\":\"98e9a4378d4cce18ed257fb124a5f8a7fcbff458\", \"best_bid\":\"0.08\", \"best_ask\":\"0.09\"}], \"timestamp\":\"1785122863267\", \"event_type\":\"price_change\"}","received_at":"2026-07-27T03:27:43.172604Z","schema_version":"clob-market-ws.price_change.v1","sequence":null,"server_hash":null,"server_timestamp":"1785122863267","session_id":"dd162b8dca5f43ff811d304e69a06123","source":"clob_market_ws"},"received_at":"2026-07-27T03:27:43.172604Z","record_id":"1cdc71938dc358b0b48666636d6b870d66c692f326b277a0d18b30407be207fe","schema_fingerprint":"4aa3821a28b0b7c2400bc59aba4bcc0a76e971dadd19610d3ad38c768e124dc7","schema_version":"edge-lab-recorder.raw.v1","sequence":null,"source":"clob_market_ws"}
{"event_at":"2026-07-27T03:27:43.270000Z","event_fingerprint":"56aa21926a7ba1fb5e32e50240bf7ec0dc04e791b2794e3ea4d946204a5ac01b","payload":{"connection_id":"c7dc2e4762f849c6b6f9306b6518dcab","event_at":"2026-07-27T03:27:43.270000Z","event_type":"price_change","frame_hash":"da2d8288504c74f900b64fd64881c2edfc0eb3d887dd3e7c0ded08ffc35114e5","frame_index":0,"kind":"data","monotonic_ns":224846537802416,"payload":{"event_type":"price_change","market":"0x717c0e8ccd4d5c7040185188fbae28be901ca589a11a94b1b38ca36a79eccfeb","price_changes":[{"asset_id":"24254094493625419915756280046002869097156693848522361803041977572204227262166","best_ask":"0.92","best_bid":"0.91","hash":"1ad077d454c55412fe0c1dab748e7172df72800b","price":"0.01","side":"BUY","size":"5150.02"},{"asset_id":"41448400836309843603620980831210604935021861034693225347475867885462478926555","best_ask":"0.09","best_bid":"0.08","hash":"2af4a6d2f31819c98eabc26390132729565a0603","price":"0.99","side":"SELL","size":"5150.02"}],"timestamp":"1785122863270"},"payload_hash":"86ca92d7d1a7ffb2d79a13bace93a40b7200dbf4fd51cc245864f5c3fbd0d866","raw_frame":"{\"market\":\"0x717c0e8ccd4d5c7040185188fbae28be901ca589a11a94b1b38ca36a79eccfeb\", \"price_changes\":[{\"asset_id\":\"24254094493625419915756280046002869097156693848522361803041977572204227262166\", \"price\":\"0.01\", \"size\":\"5150.02\", \"side\":\"BUY\", \"hash\":\"1ad077d454c55412fe0c1dab748e7172df72800b\", \"best_bid\":\"0.91\", \"best_ask\":\"0.92\"}, {\"asset_id\":\"41448400836309843603620980831210604935021861034693225347475867885462478926555\", \"price\":\"0.99\", \"size\":\"5150.02\", \"side\":\"SELL\", \"hash\":\"2af4a6d2f31819c98eabc26390132729565a0603\", \"best_bid\":\"0.08\", \"best_ask\":\"0.09\"}], \"timestamp\":\"1785122863270\", \"event_type\":\"price_change\"}","received_at":"2026-07-27T03:27:43.176325Z","schema_version":"clob-market-ws.price_change.v1","sequence":null,"server_hash":null,"server_timestamp":"1785122863270","session_id":"dd162b8dca5f43ff811d304e69a06123","source":"clob_market_ws"},"received_at":"2026-07-27T03:27:43.176325Z","record_id":"e740e996a979d38db940d009789971c2e561f7f8254f6e87bab96dd70070db30","schema_fingerprint":"4aa3821a28b0b7c2400bc59aba4bcc0a76e971dadd19610d3ad38c768e124dc7","schema_version":"edge-lab-recorder.raw.v1","sequence":null,"source":"clob_market_ws"}
{"event_at":"2026-07-27T03:27:43.356000Z","event_fingerprint":"bfb4f0f1ab9f7195f10294213d22ff03ea3eedf9230ce27349c0ccbadddb3d2a","payload":{"connection_id":"c7dc2e4762f849c6b6f9306b6518dcab","event_at":"2026-07-27T03:27:43.356000Z","event_type":"price_change","frame_hash":"bea3553114de6c5935aa4ee130f652235a764209f4f176acf915761a2f45a7c7","frame_index":0,"kind":"data","monotonic_ns":224846600033833,"payload":{"event_type":"price_change","market":"0x717c0e8ccd4d5c7040185188fbae28be901ca589a11a94b1b38ca36a79eccfeb","price_changes":[{"asset_id":"41448400836309843603620980831210604935021861034693225347475867885462478926555","best_ask":"0.09","best_bid":"0.08","hash":"40ac9c1df614565a472e77eac5f63ba0c4b363e1","price":"0.12","side":"SELL","size":"344.55"},{"asset_id":"24254094493625419915756280046002869097156693848522361803041977572204227262166","best_ask":"0.92","best_bid":"0.91","hash":"ae6619af3bba2f21c1debcbefc9eed4d1641c6e4","price":"0.88","side":"BUY","size":"344.55"}],"timestamp":"1785122863356"},"payload_hash":"3da73a248a07a472c97760774c636df0f75b5dca459262e57466fd597f36ebe6","raw_frame":"{\"market\":\"0x717c0e8ccd4d5c7040185188fbae28be901ca589a11a94b1b38ca36a79eccfeb\", \"price_changes\":[{\"asset_id\":\"41448400836309843603620980831210604935021861034693225347475867885462478926555\", \"price\":\"0.12\", \"size\":\"344.55\", \"side\":\"SELL\", \"hash\":\"40ac9c1df614565a472e77eac5f63ba0c4b363e1\", \"best_bid\":\"0.08\", \"best_ask\":\"0.09\"}, {\"asset_id\":\"24254094493625419915756280046002869097156693848522361803041977572204227262166\", \"price\":\"0.88\", \"size\":\"344.55\", \"side\":\"BUY\", \"hash\":\"ae6619af3bba2f21c1debcbefc9eed4d1641c6e4\", \"best_bid\":\"0.91\", \"best_ask\":\"0.92\"}], \"timestamp\":\"1785122863356\", \"event_type\":\"price_change\"}","received_at":"2026-07-27T03:27:43.238552Z","schema_version":"clob-market-ws.price_change.v1","sequence":null,"server_hash":null,"server_timestamp":"1785122863356","session_id":"dd162b8dca5f43ff811d304e69a06123","source":"clob_market_ws"},"received_at":"2026-07-27T03:27:43.238552Z","record_id":"30d32ef253abc4d09ef7f5adca6e0a57c6c06a3af975b8481dfafd0a3e9600a4","schema_fingerprint":"4aa3821a28b0b7c2400bc59aba4bcc0a76e971dadd19610d3ad38c768e124dc7","schema_version":"edge-lab-recorder.raw.v1","sequence":null,"source":"clob_market_ws"}
{"event_at":"2026-07-27T03:27:43.384000Z","event_fingerprint":"dfc18f0b5577c6e1d708641787863f525075401def324003c72320f62dc36e80","payload":{"connection_id":"c7dc2e4762f849c6b6f9306b6518dcab","event_at":"2026-07-27T03:27:43.384000Z","event_type":"price_change","frame_hash":"883702afcd81ab0aefa23b768aff4a683311410114b5578ecb558bc5be359aa1","frame_index":0,"kind":"data","monotonic_ns":224846618533250,"payload":{"event_type":"price_change","market":"0x717c0e8ccd4d5c7040185188fbae28be901ca589a11a94b1b38ca36a79eccfeb","price_changes":[{"asset_id":"24254094493625419915756280046002869097156693848522361803041977572204227262166","best_ask":"0.92","best_bid":"0.91","hash":"9b445fa13eabb232b72fb24cb4eb71386fe5151a","price":"0.03","side":"BUY","size":"515"},{"asset_id":"41448400836309843603620980831210604935021861034693225347475867885462478926555","best_ask":"0.09","best_bid":"0.08","hash":"0a65d8cdce9e56fcc2b19ebeacf07467ff143a4c","price":"0.97","side":"SELL","size":"515"}],"timestamp":"1785122863384"},"payload_hash":"8563ad36b01019ba1da987446a9ec7ecc92c32bd5a5d1415ac6cf8836ffa8a1b","raw_frame":"{\"market\":\"0x717c0e8ccd4d5c7040185188fbae28be901ca589a11a94b1b38ca36a79eccfeb\", \"price_changes\":[{\"asset_id\":\"24254094493625419915756280046002869097156693848522361803041977572204227262166\", \"price\":\"0.03\", \"size\":\"515\", \"side\":\"BUY\", \"hash\":\"9b445fa13eabb232b72fb24cb4eb71386fe5151a\", \"best_bid\":\"0.91\", \"best_ask\":\"0.92\"}, {\"asset_id\":\"41448400836309843603620980831210604935021861034693225347475867885462478926555\", \"price\":\"0.97\", \"size\":\"515\", \"side\":\"SELL\", \"hash\":\"0a65d8cdce9e56fcc2b19ebeacf07467ff143a4c\", \"best_bid\":\"0.08\", \"best_ask\":\"0.09\"}], \"timestamp\":\"1785122863384\", \"event_type\":\"price_change\"}","received_at":"2026-07-27T03:27:43.257052Z","schema_version":"clob-market-ws.price_change.v1","sequence":null,"server_hash":null,"server_timestamp":"1785122863384","session_id":"dd162b8dca5f43ff811d304e69a06123","source":"clob_market_ws"},"received_at":"2026-07-27T03:27:43.257052Z","record_id":"bed99974444afa2bb444a9545a5a2b181bee176c7c3a84c036b34303be45a661","schema_fingerprint":"4aa3821a28b0b7c2400bc59aba4bcc0a76e971dadd19610d3ad38c768e124dc7","schema_version":"edge-lab-recorder.raw.v1","sequence":null,"source":"clob_market_ws"}
{"event_at":"2026-07-27T03:27:43.448000Z","event_fingerprint":"848586990cc00053ade133f3e94a9ecf5cb2f7062c71d4a6c959489f4464e39b","payload":{"connection_id":"c7dc2e4762f849c6b6f9306b6518dcab","event_at":"2026-07-27T03:27:43.448000Z","event_type":"price_change","frame_hash":"ed27d7ba24334adf7f4c02bd86b79d0f92fbc61c0523c225a9764436e4d3b659","frame_index":0,"kind":"data","monotonic_ns":224846684075000,"payload":{"event_type":"price_change","market":"0x717c0e8ccd4d5c7040185188fbae28be901ca589a11a94b1b38ca36a79eccfeb","price_changes":[{"asset_id":"41448400836309843603620980831210604935021861034693225347475867885462478926555","best_ask":"0.09","best_bid":"0.08","hash":"00803ac5da21da9736591daf326dcaa8ebdc5d58","price":"0.12","side":"SELL","size":"338.5"},{"asset_id":"24254094493625419915756280046002869097156693848522361803041977572204227262166","best_ask":"0.92","best_bid":"0.91","hash":"10243408da5b5703b1468a115ad631ce59485f34","price":"0.88","side":"BUY","size":"338.5"}],"timestamp":"1785122863448"},"payload_hash":"d964e987097c387d226669ec71493df49692338595da4795bbb4219d85ea3494","raw_frame":"{\"market\":\"0x717c0e8ccd4d5c7040185188fbae28be901ca589a11a94b1b38ca36a79eccfeb\", \"price_changes\":[{\"asset_id\":\"41448400836309843603620980831210604935021861034693225347475867885462478926555\", \"price\":\"0.12\", \"size\":\"338.5\", \"side\":\"SELL\", \"hash\":\"00803ac5da21da9736591daf326dcaa8ebdc5d58\", \"best_bid\":\"0.08\", \"best_ask\":\"0.09\"}, {\"asset_id\":\"24254094493625419915756280046002869097156693848522361803041977572204227262166\", \"price\":\"0.88\", \"size\":\"338.5\", \"side\":\"BUY\", \"hash\":\"10243408da5b5703b1468a115ad631ce59485f34\", \"best_bid\":\"0.91\", \"best_ask\":\"0.92\"}], \"timestamp\":\"1785122863448\", \"event_type\":\"price_change\"}","received_at":"2026-07-27T03:27:43.322586Z","schema_version":"clob-market-ws.price_change.v1","sequence":null,"server_hash":null,"server_timestamp":"1785122863448","session_id":"dd162b8dca5f43ff811d304e69a06123","source":"clob_market_ws"},"received_at":"2026-07-27T03:27:43.322586Z","record_id":"bf2cabd8e56de0861ba682a8f4e66f6dbf6c8962e802d6b9f8ecc5ebba40d5b0","schema_fingerprint":"4aa3821a28b0b7c2400bc59aba4bcc0a76e971dadd19610d3ad38c768e124dc7","schema_version":"edge-lab-recorder.raw.v1","sequence":null,"source":"clob_market_ws"}
{"event_at":"2026-07-27T03:27:43.474000Z","event_fingerprint":"81595981316648bb5992c0956c501dc8d026b4aaef6aa20f3f5fb3c6328e837c","payload":{"connection_id":"c7dc2e4762f849c6b6f9306b6518dcab","event_at":"2026-07-27T03:27:43.474000Z","event_type":"price_change","frame_hash":"29cf9021b1d8d4c281a9d74d679d610a1433685f4b99837ae0a7733924ec85b2","frame_index":0,"kind":"data","monotonic_ns":224846710997375,"payload":{"event_type":"price_change","market":"0x717c0e8ccd4d5c7040185188fbae28be901ca589a11a94b1b38ca36a79eccfeb","price_changes":[{"asset_id":"24254094493625419915756280046002869097156693848522361803041977572204227262166","best_ask":"0.92","best_bid":"0.91","hash":"f39e4b0c632fb3a15010eda3d35e6a2eb31b767b","price":"0.03","side":"BUY","size":"510"},{"asset_id":"41448400836309843603620980831210604935021861034693225347475867885462478926555","best_ask":"0.09","best_bid":"0.08","hash":"0e1c353244ac2317ddc6f3cc2f35879a7d76ad97","price":"0.97","side":"SELL","size":"510"}],"timestamp":"1785122863474"},"payload_hash":"37607af3c26959b5167902b27a566b48e7087f23cdc18f3d42bc73fc258d514f","raw_frame":"{\"market\":\"0x717c0e8ccd4d5c7040185188fbae28be901ca589a11a94b1b38ca36a79eccfeb\", \"price_changes\":[{\"asset_id\":\"24254094493625419915756280046002869097156693848522361803041977572204227262166\", \"price\":\"0.03\", \"size\":\"510\", \"side\":\"BUY\", \"hash\":\"f39e4b0c632fb3a15010eda3d35e6a2eb31b767b\", \"best_bid\":\"0.91\", \"best_ask\":\"0.92\"}, {\"asset_id\":\"41448400836309843603620980831210604935021861034693225347475867885462478926555\", \"price\":\"0.97\", \"size\":\"510\", \"side\":\"SELL\", \"hash\":\"0e1c353244ac2317ddc6f3cc2f35879a7d76ad97\", \"best_bid\":\"0.08\", \"best_ask\":\"0.09\"}], \"timestamp\":\"1785122863474\", \"event_type\":\"price_change\"}","received_at":"2026-07-27T03:27:43.349516Z","schema_version":"clob-market-ws.price_change.v1","sequence":null,"server_hash":null,"server_timestamp":"1785122863474","session_id":"dd162b8dca5f43ff811d304e69a06123","source":"clob_market_ws"},"received_at":"2026-07-27T03:27:43.349516Z","record_id":"90d015379653a56c66e77bc4c797de4c8c50fa2d6debd6327261111dcd2d457c","schema_fingerprint":"4aa3821a28b0b7c2400bc59aba4bcc0a76e971dadd19610d3ad38c768e124dc7","schema_version":"edge-lab-recorder.raw.v1","sequence":null,"source":"clob_market_ws"}
{"event_at":"2026-07-27T03:27:43.493000Z","event_fingerprint":"9432e17bbe994367a4c55ea0234e4ed8a166620114e053deb17f86763bed117c","payload":{"connection_id":"c7dc2e4762f849c6b6f9306b6518dcab","event_at":"2026-07-27T03:27:43.493000Z","event_type":"best_bid_ask","frame_hash":"880e75da36a4644f5c34e420ebe2bdfce43abb067981923757ac93706f9fd9b5","frame_index":0,"kind":"data","monotonic_ns":224846726703708,"payload":{"asset_id":"24254094493625419915756280046002869097156693848522361803041977572204227262166","best_ask":"0.92","best_bid":"0.91","event_type":"best_bid_ask","market":"0x717c0e8ccd4d5c7040185188fbae28be901ca589a11a94b1b38ca36a79eccfeb","spread":"0.01","timestamp":"1785122863493"},"payload_hash":"cd4056fcc1e88fc4fcb95fc9afd7a74802196f49c47a92b525f9341ecb39faae","raw_frame":"{\"market\":\"0x717c0e8ccd4d5c7040185188fbae28be901ca589a11a94b1b38ca36a79eccfeb\", \"asset_id\":\"24254094493625419915756280046002869097156693848522361803041977572204227262166\", \"best_bid\":\"0.91\", \"best_ask\":\"0.92\", \"spread\":\"0.01\", \"timestamp\":\"1785122863493\", \"event_type\":\"best_bid_ask\"}","received_at":"2026-07-27T03:27:43.365220Z","schema_version":"clob-market-ws.best_bid_ask.v1","sequence":null,"server_hash":null,"server_timestamp":"1785122863493","session_id":"dd162b8dca5f43ff811d304e69a06123","source":"clob_market_ws"},"received_at":"2026-07-27T03:27:43.365220Z","record_id":"84d63fb94a432ce40fd41edaf2f6e9d4b6e00b2a60f8f4cf5805e547d07e1ee0","schema_fingerprint":"8488399f31b0337811b13b266be932db7062827c2470b78bd8e9e99bab51d17d","schema_version":"edge-lab-recorder.raw.v1","sequence":null,"source":"clob_market_ws"}
{"event_at":"2026-07-27T03:27:43.493000Z","event_fingerprint":"942239317f31b1d5b946cca884e97563e7eff737cb912de8ff8da6ad2be1cc3f","payload":{"connection_id":"c7dc2e4762f849c6b6f9306b6518dcab","event_at":"2026-07-27T03:27:43.493000Z","event_type":"best_bid_ask","frame_hash":"ad03b51044d0580b975973ef4bba6a3a8da09c92e2aa221e26e75a5ad1b97bec","frame_index":0,"kind":"data","monotonic_ns":224846728127166,"payload":{"asset_id":"41448400836309843603620980831210604935021861034693225347475867885462478926555","best_ask":"0.09","best_bid":"0.08","event_type":"best_bid_ask","market":"0x717c0e8ccd4d5c7040185188fbae28be901ca589a11a94b1b38ca36a79eccfeb","spread":"0.01","timestamp":"1785122863493"},"payload_hash":"28e81d4fe66c8f4e76eff2fdacfec7a250723b80ed554662f624832a2774619c","raw_frame":"{\"market\":\"0x717c0e8ccd4d5c7040185188fbae28be901ca589a11a94b1b38ca36a79eccfeb\", \"asset_id\":\"41448400836309843603620980831210604935021861034693225347475867885462478926555\", \"best_bid\":\"0.08\", \"best_ask\":\"0.09\", \"spread\":\"0.01\", \"timestamp\":\"1785122863493\", \"event_type\":\"best_bid_ask\"}","received_at":"2026-07-27T03:27:43.366646Z","schema_version":"clob-market-ws.best_bid_ask.v1","sequence":null,"server_hash":null,"server_timestamp":"1785122863493","session_id":"dd162b8dca5f43ff811d304e69a06123","source":"clob_market_ws"},"received_at":"2026-07-27T03:27:43.366646Z","record_id":"99b50491a38caccd03aa8ae1e873211b0da2c11fd324a1b352a2916cb4d83023","schema_fingerprint":"8488399f31b0337811b13b266be932db7062827c2470b78bd8e9e99bab51d17d","schema_version":"edge-lab-recorder.raw.v1","sequence":null,"source":"clob_market_ws"}
{"event_at":"2026-07-27T03:27:43.493000Z","event_fingerprint":"f4866bb1515a00fa240b306dc77aa9d2d1c380c267ca2ccd0db78b7f6a6bb18b","payload":{"connection_id":"c7dc2e4762f849c6b6f9306b6518dcab","event_at":"2026-07-27T03:27:43.493000Z","event_type":"price_change","frame_hash":"542e1892a1c0a714e6aa10943e1daeedff0b7a2663a1791ef5aec1f09c820992","frame_index":0,"kind":"data","monotonic_ns":224846729438916,"payload":{"event_type":"price_change","market":"0x717c0e8ccd4d5c7040185188fbae28be901ca589a11a94b1b38ca36a79eccfeb","price_changes":[{"asset_id":"41448400836309843603620980831210604935021861034693225347475867885462478926555","best_ask":"0.09","best_bid":"0.08","hash":"99ac3ce43dd89719fa88002e32607b28784ab954","price":"0.08","side":"BUY","size":"373.72"},{"asset_id":"24254094493625419915756280046002869097156693848522361803041977572204227262166","best_ask":"0.92","best_bid":"0.91","hash":"f73770d41f2e3e5ca910bb0194a6bd30c0e205b2","price":"0.92","side":"SELL","size":"373.72"}],"timestamp":"1785122863493"},"payload_hash":"c19c93e484145f04675e7e6b6d8d9f0c606f0439d48d9d369cc5939fdc5e494a","raw_frame":"{\"market\":\"0x717c0e8ccd4d5c7040185188fbae28be901ca589a11a94b1b38ca36a79eccfeb\", \"price_changes\":[{\"asset_id\":\"41448400836309843603620980831210604935021861034693225347475867885462478926555\", \"price\":\"0.08\", \"size\":\"373.72\", \"side\":\"BUY\", \"hash\":\"99ac3ce43dd89719fa88002e32607b28784ab954\", \"best_bid\":\"0.08\", \"best_ask\":\"0.09\"}, {\"asset_id\":\"24254094493625419915756280046002869097156693848522361803041977572204227262166\", \"price\":\"0.92\", \"size\":\"373.72\", \"side\":\"SELL\", \"hash\":\"f73770d41f2e3e5ca910bb0194a6bd30c0e205b2\", \"best_bid\":\"0.91\", \"best_ask\":\"0.92\"}], \"timestamp\":\"1785122863493\", \"event_type\":\"price_change\"}","received_at":"2026-07-27T03:27:43.367955Z","schema_version":"clob-market-ws.price_change.v1","sequence":null,"server_hash":null,"server_timestamp":"1785122863493","session_id":"dd162b8dca5f43ff811d304e69a06123","source":"clob_market_ws"},"received_at":"2026-07-27T03:27:43.367955Z","record_id":"0039a5866617ab5f44d198f4f466261a0a7b267caa3f4afaad8c4020145029de","schema_fingerprint":"4aa3821a28b0b7c2400bc59aba4bcc0a76e971dadd19610d3ad38c768e124dc7","schema_version":"edge-lab-recorder.raw.v1","sequence":null,"source":"clob_market_ws"}
{"event_at":"2026-07-27T03:27:43.493000Z","event_fingerprint":"66a203288625aea4f0cc99173b1531a5cd50a9a5d146a8543cf2227ea42b7ef2","payload":{"connection_id":"c7dc2e4762f849c6b6f9306b6518dcab","event_at":"2026-07-27T03:27:43.493000Z","event_type":"book","frame_hash":"2dd9bc94a3ca9146e4a1eb76d4881293f87f8340e7b3281a47ace97854cdae24","frame_index":0,"kind":"data","monotonic_ns":224846731117125,"payload":{"asks":[{"price":"0.99","size":"5240.02"},{"price":"0.98","size":"620"},{"price":"0.97","size":"610"},{"price":"0.96","size":"560.77"},{"price":"0.95","size":"697.57"},{"price":"0.94","size":"44.22"},{"price":"0.93","size":"35.16"},{"price":"0.92","size":"373.72"}],"asset_id":"24254094493625419915756280046002869097156693848522361803041977572204227262166","bids":[{"price":"0.01","size":"5150.02"},{"price":"0.02","size":"530"},{"price":"0.03","size":"510"},{"price":"0.04","size":"500"},{"price":"0.05","size":"505"},{"price":"0.06","size":"500"},{"price":"0.07","size":"500"},{"price":"0.08","size":"500"},{"price":"0.09","size":"500"},{"price":"0.14","size":"7.14"},{"price":"0.15","size":"100"},{"price":"0.31","size":"10"},{"price":"0.33","size":"12"},{"price":"0.36","size":"5"},{"price":"0.37","size":"5"},{"price":"0.38","size":"5"},{"price":"0.39","size":"5"},{"price":"0.4","size":"5"},{"price":"0.41","size":"5"},{"price":"0.42","size":"5"},{"price":"0.43","size":"5"},{"price":"0.44","size":"5"},{"price":"0.45","size":"5"},{"price":"0.46","size":"5"},{"price":"0.47","size":"5"},{"price":"0.48","size":"5"},{"price":"0.49","size":"5"},{"price":"0.5","size":"5"},{"price":"0.51","size":"5"},{"price":"0.52","size":"5"},{"price":"0.53","size":"5"},{"price":"0.54","size":"45"},{"price":"0.55","size":"5"},{"price":"0.56","size":"5"},{"price":"0.57","size":"5"},{"price":"0.58","size":"5"},{"price":"0.59","size":"5"},{"price":"0.6","size":"5"},{"price":"0.61","size":"5"},{"price":"0.62","size":"5"},{"price":"0.63","size":"5"},{"price":"0.64","size":"5"},{"price":"0.65","size":"5"},{"price":"0.66","size":"6"},{"price":"0.67","size":"6"},{"price":"0.68","size":"6"},{"price":"0.69","size":"6"},{"price":"0.7","size":"6"},{"price":"0.71","size":"106"},{"price":"0.72","size":"106"},{"price":"0.73","size":"106"},{"price":"0.74","size":"106"},{"price":"0.75","size":"107"},{"price":"0.76","size":"107"},{"price":"0.77","size":"107"},{"price":"0.78","size":"107"},{"price":"0.79","size":"113"},{"price":"0.8","size":"115"},{"price":"0.81","size":"108"},{"price":"0.82","size":"198"},{"price":"0.83","size":"109"},{"price":"0.84","size":"100"},{"price":"0.85","size":"110"},{"price":"0.86","size":"250"},{"price":"0.88","size":"338.5"},{"price":"0.89","size":"123.22"},{"price":"0.9","size":"28.22"},{"price":"0.91","size":"40.08"}],"event_type":"book","hash":"f73770d41f2e3e5ca910bb0194a6bd30c0e205b2","market":"0x717c0e8ccd4d5c7040185188fbae28be901ca589a11a94b1b38ca36a79eccfeb","timestamp":"1785122863493"},"payload_hash":"8826794bf5da37f73b4fea169ad401fe3fd512b647e345e24dc79c316b69cc09","raw_frame":"{\"market\":\"0x717c0e8ccd4d5c7040185188fbae28be901ca589a11a94b1b38ca36a79eccfeb\", \"asset_id\":\"24254094493625419915756280046002869097156693848522361803041977572204227262166\", \"bids\":[{\"price\":\"0.01\", \"size\":\"5150.02\"}, {\"price\":\"0.02\", \"size\":\"530\"}, {\"price\":\"0.03\", \"size\":\"510\"}, {\"price\":\"0.04\", \"size\":\"500\"}, {\"price\":\"0.05\", \"size\":\"505\"}, {\"price\":\"0.06\", \"size\":\"500\"}, {\"price\":\"0.07\", \"size\":\"500\"}, {\"price\":\"0.08\", \"size\":\"500\"}, {\"price\":\"0.09\", \"size\":\"500\"}, {\"price\":\"0.14\", \"size\":\"7.14\"}, {\"price\":\"0.15\", \"size\":\"100\"}, {\"price\":\"0.31\", \"size\":\"10\"}, {\"price\":\"0.33\", \"size\":\"12\"}, {\"price\":\"0.36\", \"size\":\"5\"}, {\"price\":\"0.37\", \"size\":\"5\"}, {\"price\":\"0.38\", \"size\":\"5\"}, {\"price\":\"0.39\", \"size\":\"5\"}, {\"price\":\"0.4\", \"size\":\"5\"}, {\"price\":\"0.41\", \"size\":\"5\"}, {\"price\":\"0.42\", \"size\":\"5\"}, {\"price\":\"0.43\", \"size\":\"5\"}, {\"price\":\"0.44\", \"size\":\"5\"}, {\"price\":\"0.45\", \"size\":\"5\"}, {\"price\":\"0.46\", \"size\":\"5\"}, {\"price\":\"0.47\", \"size\":\"5\"}, {\"price\":\"0.48\", \"size\":\"5\"}, {\"price\":\"0.49\", \"size\":\"5\"}, {\"price\":\"0.5\", \"size\":\"5\"}, {\"price\":\"0.51\", \"size\":\"5\"}, {\"price\":\"0.52\", \"size\":\"5\"}, {\"price\":\"0.53\", \"size\":\"5\"}, {\"price\":\"0.54\", \"size\":\"45\"}, {\"price\":\"0.55\", \"size\":\"5\"}, {\"price\":\"0.56\", \"size\":\"5\"}, {\"price\":\"0.57\", \"size\":\"5\"}, {\"price\":\"0.58\", \"size\":\"5\"}, {\"price\":\"0.59\", \"size\":\"5\"}, {\"price\":\"0.6\", \"size\":\"5\"}, {\"price\":\"0.61\", \"size\":\"5\"}, {\"price\":\"0.62\", \"size\":\"5\"}, {\"price\":\"0.63\", \"size\":\"5\"}, {\"price\":\"0.64\", \"size\":\"5\"}, {\"price\":\"0.65\", \"size\":\"5\"}, {\"price\":\"0.66\", \"size\":\"6\"}, {\"price\":\"0.67\", \"size\":\"6\"}, {\"price\":\"0.68\", \"size\":\"6\"}, {\"price\":\"0.69\", \"size\":\"6\"}, {\"price\":\"0.7\", \"size\":\"6\"}, {\"price\":\"0.71\", \"size\":\"106\"}, {\"price\":\"0.72\", \"size\":\"106\"}, {\"price\":\"0.73\", \"size\":\"106\"}, {\"price\":\"0.74\", \"size\":\"106\"}, {\"price\":\"0.75\", \"size\":\"107\"}, {\"price\":\"0.76\", \"size\":\"107\"}, {\"price\":\"0.77\", \"size\":\"107\"}, {\"price\":\"0.78\", \"size\":\"107\"}, {\"price\":\"0.79\", \"size\":\"113\"}, {\"price\":\"0.8\", \"size\":\"115\"}, {\"price\":\"0.81\", \"size\":\"108\"}, {\"price\":\"0.82\", \"size\":\"198\"}, {\"price\":\"0.83\", \"size\":\"109\"}, {\"price\":\"0.84\", \"size\":\"100\"}, {\"price\":\"0.85\", \"size\":\"110\"}, {\"price\":\"0.86\", \"size\":\"250\"}, {\"price\":\"0.88\", \"size\":\"338.5\"}, {\"price\":\"0.89\", \"size\":\"123.22\"}, {\"price\":\"0.9\", \"size\":\"28.22\"}, {\"price\":\"0.91\", \"size\":\"40.08\"}], \"asks\":[{\"price\":\"0.99\", \"size\":\"5240.02\"}, {\"price\":\"0.98\", \"size\":\"620\"}, {\"price\":\"0.97\", \"size\":\"610\"}, {\"price\":\"0.96\", \"size\":\"560.77\"}, {\"price\":\"0.95\", \"size\":\"697.57\"}, {\"price\":\"0.94\", \"size\":\"44.22\"}, {\"price\":\"0.93\", \"size\":\"35.16\"}, {\"price\":\"0.92\", \"size\":\"373.72\"}], \"hash\":\"f73770d41f2e3e5ca910bb0194a6bd30c0e205b2\", \"timestamp\":\"1785122863493\", \"event_type\":\"book\"}","received_at":"2026-07-27T03:27:43.369639Z","schema_version":"clob-market-ws.book.v1","sequence":null,"server_hash":"f73770d41f2e3e5ca910bb0194a6bd30c0e205b2","server_timestamp":"1785122863493","session_id":"dd162b8dca5f43ff811d304e69a06123","source":"clob_market_ws"},"received_at":"2026-07-27T03:27:43.369639Z","record_id":"a8a1d05dcf12b024789a6f0f6dd25213f88622d33742b40206557f2bceaa12a5","schema_fingerprint":"dc2caa1c89c6a7426e2e07ff925910cd4d0a8a223a515d4092d91d6d127aacb6","schema_version":"edge-lab-recorder.raw.v1","sequence":null,"source":"clob_market_ws"}
{"event_at":"2026-07-27T03:27:43.493000Z","event_fingerprint":"2f370b7807a61416ff0e9888e42189fa22a574bd182dc9da77e5410a44a36ff5","payload":{"connection_id":"c7dc2e4762f849c6b6f9306b6518dcab","event_at":"2026-07-27T03:27:43.493000Z","event_type":"book","frame_hash":"e86b2287cb24f98477c3108877ae1d8e657179fa2d568fc64f6f1921719b4f0c","frame_index":0,"kind":"data","monotonic_ns":224846762195166,"payload":{"asks":[{"price":"0.99","size":"5150.02"},{"price":"0.98","size":"530"},{"price":"0.97","size":"510"},{"price":"0.96","size":"500"},{"price":"0.95","size":"505"},{"price":"0.94","size":"500"},{"price":"0.93","size":"500"},{"price":"0.92","size":"500"},{"price":"0.91","size":"500"},{"price":"0.86","size":"7.14"},{"price":"0.85","size":"100"},{"price":"0.69","size":"10"},{"price":"0.67","size":"12"},{"price":"0.64","size":"5"},{"price":"0.63","size":"5"},{"price":"0.62","size":"5"},{"price":"0.61","size":"5"},{"price":"0.6","size":"5"},{"price":"0.59","size":"5"},{"price":"0.58","size":"5"},{"price":"0.57","size":"5"},{"price":"0.56","size":"5"},{"price":"0.55","size":"5"},{"price":"0.54","size":"5"},{"price":"0.53","size":"5"},{"price":"0.52","size":"5"},{"price":"0.51","size":"5"},{"price":"0.5","size":"5"},{"price":"0.49","size":"5"},{"price":"0.48","size":"5"},{"price":"0.47","size":"5"},{"price":"0.46","size":"45"},{"price":"0.45","size":"5"},{"price":"0.44","size":"5"},{"price":"0.43","size":"5"},{"price":"0.42","size":"5"},{"price":"0.41","size":"5"},{"price":"0.4","size":"5"},{"price":"0.39","size":"5"},{"price":"0.38","size":"5"},{"price":"0.37","size":"5"},{"price":"0.36","size":"5"},{"price":"0.35","size":"5"},{"price":"0.34","size":"6"},{"price":"0.33","size":"6"},{"price":"0.32","size":"6"},{"price":"0.31","size":"6"},{"price":"0.3","size":"6"},{"price":"0.29","size":"106"},{"price":"0.28","size":"106"},{"price":"0.27","size":"106"},{"price":"0.26","size":"106"},{"price":"0.25","size":"107"},{"price":"0.24","size":"107"},{"price":"0.23","size":"107"},{"price":"0.22","size":"107"},{"price":"0.21","size":"113"},{"price":"0.2","size":"115"},{"price":"0.19","size":"108"},{"price":"0.18","size":"198"},{"price":"0.17","size":"109"},{"price":"0.16","size":"100"},{"price":"0.15","size":"110"},{"price":"0.14","size":"250"},{"price":"0.12","size":"338.5"},{"price":"0.11","size":"123.22"},{"price":"0.1","size":"28.22"},{"price":"0.09","size":"40.08"}],"asset_id":"41448400836309843603620980831210604935021861034693225347475867885462478926555","bids":[{"price":"0.01","size":"5240.02"},{"price":"0.02","size":"620"},{"price":"0.03","size":"610"},{"price":"0.04","size":"560.77"},{"price":"0.05","size":"697.57"},{"price":"0.06","size":"44.22"},{"price":"0.07","size":"35.16"},{"price":"0.08","size":"373.72"}],"event_type":"book","hash":"99ac3ce43dd89719fa88002e32607b28784ab954","market":"0x717c0e8ccd4d5c7040185188fbae28be901ca589a11a94b1b38ca36a79eccfeb","timestamp":"1785122863493"},"payload_hash":"807892965481fba3bd6d57b713217e147ce614af1f4e53da2ca121b6fc77e183","raw_frame":"{\"market\":\"0x717c0e8ccd4d5c7040185188fbae28be901ca589a11a94b1b38ca36a79eccfeb\", \"asset_id\":\"41448400836309843603620980831210604935021861034693225347475867885462478926555\", \"bids\":[{\"price\":\"0.01\", \"size\":\"5240.02\"}, {\"price\":\"0.02\", \"size\":\"620\"}, {\"price\":\"0.03\", \"size\":\"610\"}, {\"price\":\"0.04\", \"size\":\"560.77\"}, {\"price\":\"0.05\", \"size\":\"697.57\"}, {\"price\":\"0.06\", \"size\":\"44.22\"}, {\"price\":\"0.07\", \"size\":\"35.16\"}, {\"price\":\"0.08\", \"size\":\"373.72\"}], \"asks\":[{\"price\":\"0.99\", \"size\":\"5150.02\"}, {\"price\":\"0.98\", \"size\":\"530\"}, {\"price\":\"0.97\", \"size\":\"510\"}, {\"price\":\"0.96\", \"size\":\"500\"}, {\"price\":\"0.95\", \"size\":\"505\"}, {\"price\":\"0.94\", \"size\":\"500\"}, {\"price\":\"0.93\", \"size\":\"500\"}, {\"price\":\"0.92\", \"size\":\"500\"}, {\"price\":\"0.91\", \"size\":\"500\"}, {\"price\":\"0.86\", \"size\":\"7.14\"}, {\"price\":\"0.85\", \"size\":\"100\"}, {\"price\":\"0.69\", \"size\":\"10\"}, {\"price\":\"0.67\", \"size\":\"12\"}, {\"price\":\"0.64\", \"size\":\"5\"}, {\"price\":\"0.63\", \"size\":\"5\"}, {\"price\":\"0.62\", \"size\":\"5\"}, {\"price\":\"0.61\", \"size\":\"5\"}, {\"price\":\"0.6\", \"size\":\"5\"}, {\"price\":\"0.59\", \"size\":\"5\"}, {\"price\":\"0.58\", \"size\":\"5\"}, {\"price\":\"0.57\", \"size\":\"5\"}, {\"price\":\"0.56\", \"size\":\"5\"}, {\"price\":\"0.55\", \"size\":\"5\"}, {\"price\":\"0.54\", \"size\":\"5\"}, {\"price\":\"0.53\", \"size\":\"5\"}, {\"price\":\"0.52\", \"size\":\"5\"}, {\"price\":\"0.51\", \"size\":\"5\"}, {\"price\":\"0.5\", \"size\":\"5\"}, {\"price\":\"0.49\", \"size\":\"5\"}, {\"price\":\"0.48\", \"size\":\"5\"}, {\"price\":\"0.47\", \"size\":\"5\"}, {\"price\":\"0.46\", \"size\":\"45\"}, {\"price\":\"0.45\", \"size\":\"5\"}, {\"price\":\"0.44\", \"size\":\"5\"}, {\"price\":\"0.43\", \"size\":\"5\"}, {\"price\":\"0.42\", \"size\":\"5\"}, {\"price\":\"0.41\", \"size\":\"5\"}, {\"price\":\"0.4\", \"size\":\"5\"}, {\"price\":\"0.39\", \"size\":\"5\"}, {\"price\":\"0.38\", \"size\":\"5\"}, {\"price\":\"0.37\", \"size\":\"5\"}, {\"price\":\"0.36\", \"size\":\"5\"}, {\"price\":\"0.35\", \"size\":\"5\"}, {\"price\":\"0.34\", \"size\":\"6\"}, {\"price\":\"0.33\", \"size\":\"6\"}, {\"price\":\"0.32\", \"size\":\"6\"}, {\"price\":\"0.31\", \"size\":\"6\"}, {\"price\":\"0.3\", \"size\":\"6\"}, {\"price\":\"0.29\", \"size\":\"106\"}, {\"price\":\"0.28\", \"size\":\"106\"}, {\"price\":\"0.27\", \"size\":\"106\"}, {\"price\":\"0.26\", \"size\":\"106\"}, {\"price\":\"0.25\", \"size\":\"107\"}, {\"price\":\"0.24\", \"size\":\"107\"}, {\"price\":\"0.23\", \"size\":\"107\"}, {\"price\":\"0.22\", \"size\":\"107\"}, {\"price\":\"0.21\", \"size\":\"113\"}, {\"price\":\"0.2\", \"size\":\"115\"}, {\"price\":\"0.19\", \"size\":\"108\"}, {\"price\":\"0.18\", \"size\":\"198\"}, {\"price\":\"0.17\", \"size\":\"109\"}, {\"price\":\"0.16\", \"size\":\"100\"}, {\"price\":\"0.15\", \"size\":\"110\"}, {\"price\":\"0.14\", \"size\":\"250\"}, {\"price\":\"0.12\", \"size\":\"338.5\"}, {\"price\":\"0.11\", \"size\":\"123.22\"}, {\"price\":\"0.1\", \"size\":\"28.22\"}, {\"price\":\"0.09\", \"size\":\"40.08\"}], \"hash\":\"99ac3ce43dd89719fa88002e32607b28784ab954\", \"timestamp\":\"1785122863493\", \"event_type\":\"book\"}","received_at":"2026-07-27T03:27:43.400711Z","schema_version":"clob-market-ws.book.v1","sequence":null,"server_hash":"99ac3ce43dd89719fa88002e32607b28784ab954","server_timestamp":"1785122863493","session_id":"dd162b8dca5f43ff811d304e69a06123","source":"clob_market_ws"},"received_at":"2026-07-27T03:27:43.400711Z","record_id":"5db533d67c7b38346f5058e6e37cff8def495cf1e24f195406a6507ba1c2326d","schema_fingerprint":"dc2caa1c89c6a7426e2e07ff925910cd4d0a8a223a515d4092d91d6d127aacb6","schema_version":"edge-lab-recorder.raw.v1","sequence":null,"source":"clob_market_ws"}
{"event_at":"2026-07-27T03:27:43.517000Z","event_fingerprint":"6d0a94815ac460313042389f61c530c81fe285dcbdee4b6088152d0a9014a39b","payload":{"connection_id":"c7dc2e4762f849c6b6f9306b6518dcab","event_at":"2026-07-27T03:27:43.517000Z","event_type":"price_change","frame_hash":"f385ec23905d328612f6b6df831b8976c429b35559a1fcd1da2ed868aa0ba7c7","frame_index":0,"kind":"data","monotonic_ns":224846770180708,"payload":{"event_type":"price_change","market":"0x717c0e8ccd4d5c7040185188fbae28be901ca589a11a94b1b38ca36a79eccfeb","price_changes":[{"asset_id":"41448400836309843603620980831210604935021861034693225347475867885462478926555","best_ask":"0.09","best_bid":"0.08","hash":"b707f4f8026dcd6e9c8588d2ecde51df1eb5c723","price":"0.03","side":"BUY","size":"777"},{"asset_id":"24254094493625419915756280046002869097156693848522361803041977572204227262166","best_ask":"0.92","best_bid":"0.91","hash":"1be5e2747cb8985046cd96d67de9bded0a087d5e","price":"0.97","side":"SELL","size":"777"}],"timestamp":"1785122863517"},"payload_hash":"4943ffdfec6f991bb7e3b9ee84e8505cf27be6c850e1de1d0e8c042ef6aeb485","raw_frame":"{\"market\":\"0x717c0e8ccd4d5c7040185188fbae28be901ca589a11a94b1b38ca36a79eccfeb\", \"price_changes\":[{\"asset_id\":\"41448400836309843603620980831210604935021861034693225347475867885462478926555\", \"price\":\"0.03\", \"size\":\"777\", \"side\":\"BUY\", \"hash\":\"b707f4f8026dcd6e9c8588d2ecde51df1eb5c723\", \"best_bid\":\"0.08\", \"best_ask\":\"0.09\"}, {\"asset_id\":\"24254094493625419915756280046002869097156693848522361803041977572204227262166\", \"price\":\"0.97\", \"size\":\"777\", \"side\":\"SELL\", \"hash\":\"1be5e2747cb8985046cd96d67de9bded0a087d5e\", \"best_bid\":\"0.91\", \"best_ask\":\"0.92\"}], \"timestamp\":\"1785122863517\", \"event_type\":\"price_change\"}","received_at":"2026-07-27T03:27:43.408699Z","schema_version":"clob-market-ws.price_change.v1","sequence":null,"server_hash":null,"server_timestamp":"1785122863517","session_id":"dd162b8dca5f43ff811d304e69a06123","source":"clob_market_ws"},"received_at":"2026-07-27T03:27:43.408699Z","record_id":"31d79263e6455a66cafb9314377c4b658ab8310cc4e07d1e795f0fd42d3c0097","schema_fingerprint":"4aa3821a28b0b7c2400bc59aba4bcc0a76e971dadd19610d3ad38c768e124dc7","schema_version":"edge-lab-recorder.raw.v1","sequence":null,"source":"clob_market_ws"}
{"event_at":"2026-07-27T03:27:43.518000Z","event_fingerprint":"d942dfc07e4f3b60c84e4b5b45b55ef64c894d3d0734c2298959a78fdf274072","payload":{"connection_id":"c7dc2e4762f849c6b6f9306b6518dcab","event_at":"2026-07-27T03:27:43.518000Z","event_type":"price_change","frame_hash":"17980e1bafd9e6cebf83ce1cf44f03fa8a699c5e4ae2b5a7503fecc7dfb3032b","frame_index":0,"kind":"data","monotonic_ns":224846771865250,"payload":{"event_type":"price_change","market":"0x717c0e8ccd4d5c7040185188fbae28be901ca589a11a94b1b38ca36a79eccfeb","price_changes":[{"asset_id":"41448400836309843603620980831210604935021861034693225347475867885462478926555","best_ask":"0.09","best_bid":"0.08","hash":"b8fa1a5720bd180da6e6238ca70c836f52306630","price":"0.02","side":"BUY","size":"870"},{"asset_id":"24254094493625419915756280046002869097156693848522361803041977572204227262166","best_ask":"0.92","best_bid":"0.91","hash":"5404a9fa49c99d30803ec164b112b6d7065c2cba","price":"0.98","side":"SELL","size":"870"}],"timestamp":"1785122863518"},"payload_hash":"bed47ccaf3ad5969bb6c7557647c13768cb46f29a37f60c0cfaf0828c3f05431","raw_frame":"{\"market\":\"0x717c0e8ccd4d5c7040185188fbae28be901ca589a11a94b1b38ca36a79eccfeb\", \"price_changes\":[{\"asset_id\":\"41448400836309843603620980831210604935021861034693225347475867885462478926555\", \"price\":\"0.02\", \"size\":\"870\", \"side\":\"BUY\", \"hash\":\"b8fa1a5720bd180da6e6238ca70c836f52306630\", \"best_bid\":\"0.08\", \"best_ask\":\"0.09\"}, {\"asset_id\":\"24254094493625419915756280046002869097156693848522361803041977572204227262166\", \"price\":\"0.98\", \"size\":\"870\", \"side\":\"SELL\", \"hash\":\"5404a9fa49c99d30803ec164b112b6d7065c2cba\", \"best_bid\":\"0.91\", \"best_ask\":\"0.92\"}], \"timestamp\":\"1785122863518\", \"event_type\":\"price_change\"}","received_at":"2026-07-27T03:27:43.410384Z","schema_version":"clob-market-ws.price_change.v1","sequence":null,"server_hash":null,"server_timestamp":"1785122863518","session_id":"dd162b8dca5f43ff811d304e69a06123","source":"clob_market_ws"},"received_at":"2026-07-27T03:27:43.410384Z","record_id":"5bf2ecfd54f1ea50154620de12b6dd6fd5537cecf181d3a86ce30e6cccad7184","schema_fingerprint":"4aa3821a28b0b7c2400bc59aba4bcc0a76e971dadd19610d3ad38c768e124dc7","schema_version":"edge-lab-recorder.raw.v1","sequence":null,"source":"clob_market_ws"}
{"event_at":"2026-07-27T03:27:43.521000Z","event_fingerprint":"f4ff261a7f95489942d4652101fc3fc9350efa2a1c883838abe6d12ef83eb25a","payload":{"connection_id":"c7dc2e4762f849c6b6f9306b6518dcab","event_at":"2026-07-27T03:27:43.521000Z","event_type":"price_change","frame_hash":"8670cd6b490f94dcff3ee72d0420f17d48e54a05695c2671fca2030159363c5b","frame_index":0,"kind":"data","monotonic_ns":224846773470083,"payload":{"event_type":"price_change","market":"0x717c0e8ccd4d5c7040185188fbae28be901ca589a11a94b1b38ca36a79eccfeb","price_changes":[{"asset_id":"41448400836309843603620980831210604935021861034693225347475867885462478926555","best_ask":"0.09","best_bid":"0.08","hash":"23c3709bece79c1340c936a922bf3a6c28b1cd4b","price":"0.01","side":"BUY","size":"5740.02"},{"asset_id":"24254094493625419915756280046002869097156693848522361803041977572204227262166","best_ask":"0.92","best_bid":"0.91","hash":"978dcb7d50b39df673d66fb9e7556775607f8dc5","price":"0.99","side":"SELL","size":"5740.02"}],"timestamp":"1785122863521"},"payload_hash":"5866f826e09bdf122264c5676de3a81e9b458463e0cc181d52f9dd7d6b3f1dd1","raw_frame":"{\"market\":\"0x717c0e8ccd4d5c7040185188fbae28be901ca589a11a94b1b38ca36a79eccfeb\", \"price_changes\":[{\"asset_id\":\"41448400836309843603620980831210604935021861034693225347475867885462478926555\", \"price\":\"0.01\", \"size\":\"5740.02\", \"side\":\"BUY\", \"hash\":\"23c3709bece79c1340c936a922bf3a6c28b1cd4b\", \"best_bid\":\"0.08\", \"best_ask\":\"0.09\"}, {\"asset_id\":\"24254094493625419915756280046002869097156693848522361803041977572204227262166\", \"price\":\"0.99\", \"size\":\"5740.02\", \"side\":\"SELL\", \"hash\":\"978dcb7d50b39df673d66fb9e7556775607f8dc5\", \"best_bid\":\"0.91\", \"best_ask\":\"0.92\"}], \"timestamp\":\"1785122863521\", \"event_type\":\"price_change\"}","received_at":"2026-07-27T03:27:43.411985Z","schema_version":"clob-market-ws.price_change.v1","sequence":null,"server_hash":null,"server_timestamp":"1785122863521","session_id":"dd162b8dca5f43ff811d304e69a06123","source":"clob_market_ws"},"received_at":"2026-07-27T03:27:43.411985Z","record_id":"536e6ab5f393f9eed5196779a058dd86a493718e66f561c196ffa339921febfb","schema_fingerprint":"4aa3821a28b0b7c2400bc59aba4bcc0a76e971dadd19610d3ad38c768e124dc7","schema_version":"edge-lab-recorder.raw.v1","sequence":null,"source":"clob_market_ws"}
{"event_at":"2026-07-27T03:27:43.571000Z","event_fingerprint":"35255ace39de1739475691f2673f24ae1f46a4a719626b7020f5f7058ed73d30","payload":{"connection_id":"c7dc2e4762f849c6b6f9306b6518dcab","event_at":"2026-07-27T03:27:43.571000Z","event_type":"price_change","frame_hash":"60436c113c9b524c3fcd2a1f73723e2291d145f7be7b48f6f56084a79edcd176","frame_index":0,"kind":"data","monotonic_ns":224846810629625,"payload":{"event_type":"price_change","market":"0x717c0e8ccd4d5c7040185188fbae28be901ca589a11a94b1b38ca36a79eccfeb","price_changes":[{"asset_id":"41448400836309843603620980831210604935021861034693225347475867885462478926555","best_ask":"0.09","best_bid":"0.08","hash":"9800071f504a3912fe2d246cee096d6b4077fe40","price":"0.12","side":"SELL","size":"344.55"},{"asset_id":"24254094493625419915756280046002869097156693848522361803041977572204227262166","best_ask":"0.92","best_bid":"0.91","hash":"16fd5d429af8ad218ab18a9c19512689f158cd27","price":"0.88","side":"BUY","size":"344.55"}],"timestamp":"1785122863571"},"payload_hash":"187274055f4b5f06518ef8a6145100174170845b47f365725662e086952129f3","raw_frame":"{\"market\":\"0x717c0e8ccd4d5c7040185188fbae28be901ca589a11a94b1b38ca36a79eccfeb\", \"price_changes\":[{\"asset_id\":\"41448400836309843603620980831210604935021861034693225347475867885462478926555\", \"price\":\"0.12\", \"size\":\"344.55\", \"side\":\"SELL\", \"hash\":\"9800071f504a3912fe2d246cee096d6b4077fe40\", \"best_bid\":\"0.08\", \"best_ask\":\"0.09\"}, {\"asset_id\":\"24254094493625419915756280046002869097156693848522361803041977572204227262166\", \"price\":\"0.88\", \"size\":\"344.55\", \"side\":\"BUY\", \"hash\":\"16fd5d429af8ad218ab18a9c19512689f158cd27\", \"best_bid\":\"0.91\", \"best_ask\":\"0.92\"}], \"timestamp\":\"1785122863571\", \"event_type\":\"price_change\"}","received_at":"2026-07-27T03:27:43.449140Z","schema_version":"clob-market-ws.price_change.v1","sequence":null,"server_hash":null,"server_timestamp":"1785122863571","session_id":"dd162b8dca5f43ff811d304e69a06123","source":"clob_market_ws"},"received_at":"2026-07-27T03:27:43.449140Z","record_id":"4782f5e3ed3274ef92d95b2079cfaa59b948d3fac3445e024fe50a748e1c2399","schema_fingerprint":"4aa3821a28b0b7c2400bc59aba4bcc0a76e971dadd19610d3ad38c768e124dc7","schema_version":"edge-lab-recorder.raw.v1","sequence":null,"source":"clob_market_ws"}
{"event_at":"2026-07-27T03:27:43.577000Z","event_fingerprint":"b67f9e6d7894621b1be7a440e24f634953a8b423c4200bfc98808baead2299a8","payload":{"connection_id":"c7dc2e4762f849c6b6f9306b6518dcab","event_at":"2026-07-27T03:27:43.577000Z","event_type":"price_change","frame_hash":"573abd8581475e3ea7ebc5d45e4cf3fe4062186f26ebc0ecaad25abdaf5b0c38","frame_index":0,"kind":"data","monotonic_ns":224846815720083,"payload":{"event_type":"price_change","market":"0x717c0e8ccd4d5c7040185188fbae28be901ca589a11a94b1b38ca36a79eccfeb","price_changes":[{"asset_id":"24254094493625419915756280046002869097156693848522361803041977572204227262166","best_ask":"0.92","best_bid":"0.91","hash":"686ed50e21a312e605e6556e11cd15a29fb439be","price":"0.01","side":"BUY","size":"5155.02"},{"asset_id":"41448400836309843603620980831210604935021861034693225347475867885462478926555","best_ask":"0.09","best_bid":"0.08","hash":"3eec1eabf56a61ac73f6c75c93941b67c0231ce2","price":"0.99","side":"SELL","size":"5155.02"}],"timestamp":"1785122863577"},"payload_hash":"5dd835a8b0122021c074270cf7799244ebff0616040f63d16a5018641c0e136e","raw_frame":"{\"market\":\"0x717c0e8ccd4d5c7040185188fbae28be901ca589a11a94b1b38ca36a79eccfeb\", \"price_changes\":[{\"asset_id\":\"24254094493625419915756280046002869097156693848522361803041977572204227262166\", \"price\":\"0.01\", \"size\":\"5155.02\", \"side\":\"BUY\", \"hash\":\"686ed50e21a312e605e6556e11cd15a29fb439be\", \"best_bid\":\"0.91\", \"best_ask\":\"0.92\"}, {\"asset_id\":\"41448400836309843603620980831210604935021861034693225347475867885462478926555\", \"price\":\"0.99\", \"size\":\"5155.02\", \"side\":\"SELL\", \"hash\":\"3eec1eabf56a61ac73f6c75c93941b67c0231ce2\", \"best_bid\":\"0.08\", \"best_ask\":\"0.09\"}], \"timestamp\":\"1785122863577\", \"event_type\":\"price_change\"}","received_at":"2026-07-27T03:27:43.454237Z","schema_version":"clob-market-ws.price_change.v1","sequence":null,"server_hash":null,"server_timestamp":"1785122863577","session_id":"dd162b8dca5f43ff811d304e69a06123","source":"clob_market_ws"},"received_at":"2026-07-27T03:27:43.454237Z","record_id":"9165f37bbe36aca2f2b3323e0cef27506a75d382f4af01863e63ca8486d7b392","schema_fingerprint":"4aa3821a28b0b7c2400bc59aba4bcc0a76e971dadd19610d3ad38c768e124dc7","schema_version":"edge-lab-recorder.raw.v1","sequence":null,"source":"clob_market_ws"}
{"event_at":"2026-07-27T03:27:43.595000Z","event_fingerprint":"aeb4ac9cc73c5e97002b3027710f41be67b36b193f307e3b24f88cb3a293a033","payload":{"connection_id":"c7dc2e4762f849c6b6f9306b6518dcab","event_at":"2026-07-27T03:27:43.595000Z","event_type":"price_change","frame_hash":"68b50586fc51d18de3aa292603b777bb2616a49869d0f3549026dee8ea1ff5cd","frame_index":0,"kind":"data","monotonic_ns":224846830213083,"payload":{"event_type":"price_change","market":"0x717c0e8ccd4d5c7040185188fbae28be901ca589a11a94b1b38ca36a79eccfeb","price_changes":[{"asset_id":"24254094493625419915756280046002869097156693848522361803041977572204227262166","best_ask":"0.92","best_bid":"0.91","hash":"e3c62382050727b2d1cc76a6a62aea1976f3e005","price":"0.03","side":"BUY","size":"515"},{"asset_id":"41448400836309843603620980831210604935021861034693225347475867885462478926555","best_ask":"0.09","best_bid":"0.08","hash":"243385a7365044b2034cb40378cf228c5f83f1d2","price":"0.97","side":"SELL","size":"515"}],"timestamp":"1785122863595"},"payload_hash":"0f0ea04f834f81f6176958704f8ef5a28fce3fc5e425f832561ea1f56227a17a","raw_frame":"{\"market\":\"0x717c0e8ccd4d5c7040185188fbae28be901ca589a11a94b1b38ca36a79eccfeb\", \"price_changes\":[{\"asset_id\":\"24254094493625419915756280046002869097156693848522361803041977572204227262166\", \"price\":\"0.03\", \"size\":\"515\", \"side\":\"BUY\", \"hash\":\"e3c62382050727b2d1cc76a6a62aea1976f3e005\", \"best_bid\":\"0.91\", \"best_ask\":\"0.92\"}, {\"asset_id\":\"41448400836309843603620980831210604935021861034693225347475867885462478926555\", \"price\":\"0.97\", \"size\":\"515\", \"side\":\"SELL\", \"hash\":\"243385a7365044b2034cb40378cf228c5f83f1d2\", \"best_bid\":\"0.08\", \"best_ask\":\"0.09\"}], \"timestamp\":\"1785122863595\", \"event_type\":\"price_change\"}","received_at":"2026-07-27T03:27:43.468731Z","schema_version":"clob-market-ws.price_change.v1","sequence":null,"server_hash":null,"server_timestamp":"1785122863595","session_id":"dd162b8dca5f43ff811d304e69a06123","source":"clob_market_ws"},"received_at":"2026-07-27T03:27:43.468731Z","record_id":"e69eb78ace3498f17d1f8590353efdd768883ebd62fe35388aeebb5de4e6e61f","schema_fingerprint":"4aa3821a28b0b7c2400bc59aba4bcc0a76e971dadd19610d3ad38c768e124dc7","schema_version":"edge-lab-recorder.raw.v1","sequence":null,"source":"clob_market_ws"}
{"event_at":"2026-07-27T03:27:43.599000Z","event_fingerprint":"02fc9f2fc0ff98c724df5b35a3557b03e94928536a100c3a207949880d210df6","payload":{"connection_id":"c7dc2e4762f849c6b6f9306b6518dcab","event_at":"2026-07-27T03:27:43.599000Z","event_type":"price_change","frame_hash":"372d850b438847da85a8a162b1ceb7b9daf2c9dd30b8fd7f7a1d2f074665a770","frame_index":0,"kind":"data","monotonic_ns":224846834331541,"payload":{"event_type":"price_change","market":"0x717c0e8ccd4d5c7040185188fbae28be901ca589a11a94b1b38ca36a79eccfeb","price_changes":[{"asset_id":"24254094493625419915756280046002869097156693848522361803041977572204227262166","best_ask":"0.92","best_bid":"0.91","hash":"68caa3b45d231b36e447bd28fda9952156a94406","price":"0.01","side":"BUY","size":"5150.02"},{"asset_id":"41448400836309843603620980831210604935021861034693225347475867885462478926555","best_ask":"0.09","best_bid":"0.08","hash":"caea706e744342abd67ebe6b2dff5508619ef2fe","price":"0.99","side":"SELL","size":"5150.02"}],"timestamp":"1785122863599"},"payload_hash":"1da62db884dc07bbccea29c2084cc36a513f9678eccca027a6b18ebc1da5d0c0","raw_frame":"{\"market\":\"0x717c0e8ccd4d5c7040185188fbae28be901ca589a11a94b1b38ca36a79eccfeb\", \"price_changes\":[{\"asset_id\":\"24254094493625419915756280046002869097156693848522361803041977572204227262166\", \"price\":\"0.01\", \"size\":\"5150.02\", \"side\":\"BUY\", \"hash\":\"68caa3b45d231b36e447bd28fda9952156a94406\", \"best_bid\":\"0.91\", \"best_ask\":\"0.92\"}, {\"asset_id\":\"41448400836309843603620980831210604935021861034693225347475867885462478926555\", \"price\":\"0.99\", \"size\":\"5150.02\", \"side\":\"SELL\", \"hash\":\"caea706e744342abd67ebe6b2dff5508619ef2fe\", \"best_bid\":\"0.08\", \"best_ask\":\"0.09\"}], \"timestamp\":\"1785122863599\", \"event_type\":\"price_change\"}","received_at":"2026-07-27T03:27:43.472847Z","schema_version":"clob-market-ws.price_change.v1","sequence":null,"server_hash":null,"server_timestamp":"1785122863599","session_id":"dd162b8dca5f43ff811d304e69a06123","source":"clob_market_ws"},"received_at":"2026-07-27T03:27:43.472847Z","record_id":"1791ae1e0496f30e8e4379f5f6fc53186b7bfafa0bdb281429c052a2ea3fd3db","schema_fingerprint":"4aa3821a28b0b7c2400bc59aba4bcc0a76e971dadd19610d3ad38c768e124dc7","schema_version":"edge-lab-recorder.raw.v1","sequence":null,"source":"clob_market_ws"}
{"event_at":"2026-07-27T03:27:43.614000Z","event_fingerprint":"54da42bf16541e8f1d9eb2147567832c3aa59fab7bb88c0fdf65ce01e207749c","payload":{"connection_id":"c7dc2e4762f849c6b6f9306b6518dcab","event_at":"2026-07-27T03:27:43.614000Z","event_type":"last_trade_price","frame_hash":"5cdcd2516f23d8c7cd182b2abef0a33ac49312a1d1bf2332e6cc61e8b38400d0","frame_index":0,"kind":"data","monotonic_ns":224846869999083,"payload":{"asset_id":"24254094493625419915756280046002869097156693848522361803041977572204227262166","event_type":"last_trade_price","fee_rate_bps":"0","market":"0x717c0e8ccd4d5c7040185188fbae28be901ca589a11a94b1b38ca36a79eccfeb","price":"0.92","side":"BUY","size":"2","timestamp":"1785122863614","transaction_hash":"0xd99d268c85b6e0ffe9869cdc1c2cf6293cf4a9f56c3443303863b4c425235b5c"},"payload_hash":"66ff0bbfd1876f50bf48720aca1b78af4dff523b3a61bd13653790046e193645","raw_frame":"{\"market\":\"0x717c0e8ccd4d5c7040185188fbae28be901ca589a11a94b1b38ca36a79eccfeb\", \"asset_id\":\"24254094493625419915756280046002869097156693848522361803041977572204227262166\", \"price\":\"0.92\", \"size\":\"2\", \"fee_rate_bps\":\"0\", \"side\":\"BUY\", \"timestamp\":\"1785122863614\", \"event_type\":\"last_trade_price\", \"transaction_hash\":\"0xd99d268c85b6e0ffe9869cdc1c2cf6293cf4a9f56c3443303863b4c425235b5c\"}","received_at":"2026-07-27T03:27:43.508516Z","schema_version":"clob-market-ws.last_trade_price.v1","sequence":null,"server_hash":null,"server_timestamp":"1785122863614","session_id":"dd162b8dca5f43ff811d304e69a06123","source":"clob_market_ws"},"received_at":"2026-07-27T03:27:43.508516Z","record_id":"3bd89efa515f1efa11d06612d56f60eab84f9b8525650d403653f657c214db79","schema_fingerprint":"95ad9be75a4b695cd99991e12b2592bc7346f3f5388a82d0000ba65bc0d9fd0a","schema_version":"edge-lab-recorder.raw.v1","sequence":null,"source":"clob_market_ws"}
{"event_at":"2026-07-27T03:27:43.651000Z","event_fingerprint":"d93bacca0a304fd4de0e2e3525e6e27ee8c8cf4cba7af77929b8e58d8cf91c7b","payload":{"connection_id":"c7dc2e4762f849c6b6f9306b6518dcab","event_at":"2026-07-27T03:27:43.651000Z","event_type":"price_change","frame_hash":"0aff616e38fc9cb9fdf6cba287808e53d2df4c03f15f70441270b45bb6b6351d","frame_index":0,"kind":"data","monotonic_ns":224846885103333,"payload":{"event_type":"price_change","market":"0x717c0e8ccd4d5c7040185188fbae28be901ca589a11a94b1b38ca36a79eccfeb","price_changes":[{"asset_id":"24254094493625419915756280046002869097156693848522361803041977572204227262166","best_ask":"0.92","best_bid":"0.91","hash":"ebc15bbb89c07c60117bfe13fa27e498f858699e","price":"0.03","side":"BUY","size":"510"},{"asset_id":"41448400836309843603620980831210604935021861034693225347475867885462478926555","best_ask":"0.09","best_bid":"0.08","hash":"3dd1617c9b4ac0a0079a23eddde79a85a46ea5f6","price":"0.97","side":"SELL","size":"510"}],"timestamp":"1785122863651"},"payload_hash":"c5a4442de00269241b3498200073c0396504d212702fdcc1c3f315e157a4de31","raw_frame":"{\"market\":\"0x717c0e8ccd4d5c7040185188fbae28be901ca589a11a94b1b38ca36a79eccfeb\", \"price_changes\":[{\"asset_id\":\"24254094493625419915756280046002869097156693848522361803041977572204227262166\", \"price\":\"0.03\", \"size\":\"510\", \"side\":\"BUY\", \"hash\":\"ebc15bbb89c07c60117bfe13fa27e498f858699e\", \"best_bid\":\"0.91\", \"best_ask\":\"0.92\"}, {\"asset_id\":\"41448400836309843603620980831210604935021861034693225347475867885462478926555\", \"price\":\"0.97\", \"size\":\"510\", \"side\":\"SELL\", \"hash\":\"3dd1617c9b4ac0a0079a23eddde79a85a46ea5f6\", \"best_bid\":\"0.08\", \"best_ask\":\"0.09\"}], \"timestamp\":\"1785122863651\", \"event_type\":\"price_change\"}","received_at":"2026-07-27T03:27:43.523619Z","schema_version":"clob-market-ws.price_change.v1","sequence":null,"server_hash":null,"server_timestamp":"1785122863651","session_id":"dd162b8dca5f43ff811d304e69a06123","source":"clob_market_ws"},"received_at":"2026-07-27T03:27:43.523619Z","record_id":"bd021335d6f5b7ad807e2e38dd4cf761869c6add541d585537489d0ef4df10e6","schema_fingerprint":"4aa3821a28b0b7c2400bc59aba4bcc0a76e971dadd19610d3ad38c768e124dc7","schema_version":"edge-lab-recorder.raw.v1","sequence":null,"source":"clob_market_ws"}
{"event_at":"2026-07-27T03:27:43.651000Z","event_fingerprint":"adf06be1b2aae6745a448b588d3a1cea91d3cd3af664259869a84b31f3cb697c","payload":{"connection_id":"c7dc2e4762f849c6b6f9306b6518dcab","event_at":"2026-07-27T03:27:43.651000Z","event_type":"price_change","frame_hash":"5eb0c5a15b35f1f7cb9b508dd92f107431780d3b1c0c65c6cca7d554ef18935b","frame_index":0,"kind":"data","monotonic_ns":224846886805583,"payload":{"event_type":"price_change","market":"0x717c0e8ccd4d5c7040185188fbae28be901ca589a11a94b1b38ca36a79eccfeb","price_changes":[{"asset_id":"24254094493625419915756280046002869097156693848522361803041977572204227262166","best_ask":"0.92","best_bid":"0.91","hash":"2422e2f5515998c38b1685348aa489873b69ec1d","price":"0.01","side":"BUY","size":"5155.02"},{"asset_id":"41448400836309843603620980831210604935021861034693225347475867885462478926555","best_ask":"0.09","best_bid":"0.08","hash":"a3dc8ebcf7716ef8c87fb711987e60496d0857f4","price":"0.99","side":"SELL","size":"5155.02"}],"timestamp":"1785122863651"},"payload_hash":"fc32d848f57683393dc831cafda84407d229c5a3c5076addb8d4509896fe73e5","raw_frame":"{\"market\":\"0x717c0e8ccd4d5c7040185188fbae28be901ca589a11a94b1b38ca36a79eccfeb\", \"price_changes\":[{\"asset_id\":\"24254094493625419915756280046002869097156693848522361803041977572204227262166\", \"price\":\"0.01\", \"size\":\"5155.02\", \"side\":\"BUY\", \"hash\":\"2422e2f5515998c38b1685348aa489873b69ec1d\", \"best_bid\":\"0.91\", \"best_ask\":\"0.92\"}, {\"asset_id\":\"41448400836309843603620980831210604935021861034693225347475867885462478926555\", \"price\":\"0.99\", \"size\":\"5155.02\", \"side\":\"SELL\", \"hash\":\"a3dc8ebcf7716ef8c87fb711987e60496d0857f4\", \"best_bid\":\"0.08\", \"best_ask\":\"0.09\"}], \"timestamp\":\"1785122863651\", \"event_type\":\"price_change\"}","received_at":"2026-07-27T03:27:43.525321Z","schema_version":"clob-market-ws.price_change.v1","sequence":null,"server_hash":null,"server_timestamp":"1785122863651","session_id":"dd162b8dca5f43ff811d304e69a06123","source":"clob_market_ws"},"received_at":"2026-07-27T03:27:43.525321Z","record_id":"cace409cf81f72227caee5bdc7d1947b88e95c48ace11980d43a54c8a4555a50","schema_fingerprint":"4aa3821a28b0b7c2400bc59aba4bcc0a76e971dadd19610d3ad38c768e124dc7","schema_version":"edge-lab-recorder.raw.v1","sequence":null,"source":"clob_market_ws"}
{"event_at":"2026-07-27T03:27:43.667000Z","event_fingerprint":"5154fe02860eeb24594c50889599753313a7839a664a59ec15530ce36d59dec5","payload":{"connection_id":"c7dc2e4762f849c6b6f9306b6518dcab","event_at":"2026-07-27T03:27:43.667000Z","event_type":"price_change","frame_hash":"915a2190c355021afd4d209e31069d0aea12802c34260fe9ab1aa2b60012b6ea","frame_index":0,"kind":"data","monotonic_ns":224846910855125,"payload":{"event_type":"price_change","market":"0x717c0e8ccd4d5c7040185188fbae28be901ca589a11a94b1b38ca36a79eccfeb","price_changes":[{"asset_id":"41448400836309843603620980831210604935021861034693225347475867885462478926555","best_ask":"0.09","best_bid":"0.08","hash":"3babb3b38619f42c8c6509e476382ea0b54eb604","price":"0.12","side":"SELL","size":"338.5"},{"asset_id":"24254094493625419915756280046002869097156693848522361803041977572204227262166","best_ask":"0.92","best_bid":"0.91","hash":"4978d6e0a095d277dc18b78db319b2acf9f2c38b","price":"0.88","side":"BUY","size":"338.5"}],"timestamp":"1785122863667"},"payload_hash":"6f0df124bc5807adef61861852ae8e4f25f6685f3aed4edad810237c62e856e7","raw_frame":"{\"market\":\"0x717c0e8ccd4d5c7040185188fbae28be901ca589a11a94b1b38ca36a79eccfeb\", \"price_changes\":[{\"asset_id\":\"41448400836309843603620980831210604935021861034693225347475867885462478926555\", \"price\":\"0.12\", \"size\":\"338.5\", \"side\":\"SELL\", \"hash\":\"3babb3b38619f42c8c6509e476382ea0b54eb604\", \"best_bid\":\"0.08\", \"best_ask\":\"0.09\"}, {\"asset_id\":\"24254094493625419915756280046002869097156693848522361803041977572204227262166\", \"price\":\"0.88\", \"size\":\"338.5\", \"side\":\"BUY\", \"hash\":\"4978d6e0a095d277dc18b78db319b2acf9f2c38b\", \"best_bid\":\"0.91\", \"best_ask\":\"0.92\"}], \"timestamp\":\"1785122863667\", \"event_type\":\"price_change\"}","received_at":"2026-07-27T03:27:43.549369Z","schema_version":"clob-market-ws.price_change.v1","sequence":null,"server_hash":null,"server_timestamp":"1785122863667","session_id":"dd162b8dca5f43ff811d304e69a06123","source":"clob_market_ws"},"received_at":"2026-07-27T03:27:43.549369Z","record_id":"f8784291cd7f7b6c32929b72506c3a91e3679d7e3048d54e4458896159da6e6a","schema_fingerprint":"4aa3821a28b0b7c2400bc59aba4bcc0a76e971dadd19610d3ad38c768e124dc7","schema_version":"edge-lab-recorder.raw.v1","sequence":null,"source":"clob_market_ws"}
{"event_at":"2026-07-27T03:27:43.672000Z","event_fingerprint":"9fc85df425f7a5fb9c91b38bfb5a65b9c95ccdb7e2fa7a4c4b08c47018578a1f","payload":{"connection_id":"c7dc2e4762f849c6b6f9306b6518dcab","event_at":"2026-07-27T03:27:43.672000Z","event_type":"price_change","frame_hash":"d16313870d2036da23f0ebff638762f97d82572f9a9d2029257e0ae707a2473d","frame_index":0,"kind":"data","monotonic_ns":224846915818291,"payload":{"event_type":"price_change","market":"0x717c0e8ccd4d5c7040185188fbae28be901ca589a11a94b1b38ca36a79eccfeb","price_changes":[{"asset_id":"24254094493625419915756280046002869097156693848522361803041977572204227262166","best_ask":"0.92","best_bid":"0.91","hash":"af3787a75a1c4d1675e1300e4d76c4bf6c679d8d","price":"0.01","side":"BUY","size":"5150.02"},{"asset_id":"41448400836309843603620980831210604935021861034693225347475867885462478926555","best_ask":"0.09","best_bid":"0.08","hash":"772c19c6c6afeed72bfe0bdeb20e11e5bf1c1326","price":"0.99","side":"SELL","size":"5150.02"}],"timestamp":"1785122863672"},"payload_hash":"3544f06b1976e150219e7efcd8c5ff6f8b9eebe83329438dcd99918f150f95b6","raw_frame":"{\"market\":\"0x717c0e8ccd4d5c7040185188fbae28be901ca589a11a94b1b38ca36a79eccfeb\", \"price_changes\":[{\"asset_id\":\"24254094493625419915756280046002869097156693848522361803041977572204227262166\", \"price\":\"0.01\", \"size\":\"5150.02\", \"side\":\"BUY\", \"hash\":\"af3787a75a1c4d1675e1300e4d76c4bf6c679d8d\", \"best_bid\":\"0.91\", \"best_ask\":\"0.92\"}, {\"asset_id\":\"41448400836309843603620980831210604935021861034693225347475867885462478926555\", \"price\":\"0.99\", \"size\":\"5150.02\", \"side\":\"SELL\", \"hash\":\"772c19c6c6afeed72bfe0bdeb20e11e5bf1c1326\", \"best_bid\":\"0.08\", \"best_ask\":\"0.09\"}], \"timestamp\":\"1785122863672\", \"event_type\":\"price_change\"}","received_at":"2026-07-27T03:27:43.554333Z","schema_version":"clob-market-ws.price_change.v1","sequence":null,"server_hash":null,"server_timestamp":"1785122863672","session_id":"dd162b8dca5f43ff811d304e69a06123","source":"clob_market_ws"},"received_at":"2026-07-27T03:27:43.554333Z","record_id":"4b83a94d49eca85dc455f69f3a2732746770c8cd393dd679909860b2a308e47d","schema_fingerprint":"4aa3821a28b0b7c2400bc59aba4bcc0a76e971dadd19610d3ad38c768e124dc7","schema_version":"edge-lab-recorder.raw.v1","sequence":null,"source":"clob_market_ws"}
{"event_at":"2026-07-27T03:27:43.770000Z","event_fingerprint":"56916f3c9b80d87bf1f64f7a7d471bec611bad41646420a53ac4ae1ce92afde4","payload":{"connection_id":"c7dc2e4762f849c6b6f9306b6518dcab","event_at":"2026-07-27T03:27:43.770000Z","event_type":"price_change","frame_hash":"fc7953c3b6529f1d4f595dac9bb0743090dda3b0eb74ae884f314e2bd1a02210","frame_index":0,"kind":"data","monotonic_ns":224847021358708,"payload":{"event_type":"price_change","market":"0x717c0e8ccd4d5c7040185188fbae28be901ca589a11a94b1b38ca36a79eccfeb","price_changes":[{"asset_id":"41448400836309843603620980831210604935021861034693225347475867885462478926555","best_ask":"0.09","best_bid":"0.08","hash":"f750e02bf792057765bc1cfaaac4cbf600c3434d","price":"0.12","side":"SELL","size":"344.55"},{"asset_id":"24254094493625419915756280046002869097156693848522361803041977572204227262166","best_ask":"0.92","best_bid":"0.91","hash":"063feabfd41c465504b56ca0970d91762c8439e4","price":"0.88","side":"BUY","size":"344.55"}],"timestamp":"1785122863770"},"payload_hash":"d72337a5bd30628af9a4e3d63d01846d186c024fac2b3f4049853b4ba51bccb1","raw_frame":"{\"market\":\"0x717c0e8ccd4d5c7040185188fbae28be901ca589a11a94b1b38ca36a79eccfeb\", \"price_changes\":[{\"asset_id\":\"41448400836309843603620980831210604935021861034693225347475867885462478926555\", \"price\":\"0.12\", \"size\":\"344.55\", \"side\":\"SELL\", \"hash\":\"f750e02bf792057765bc1cfaaac4cbf600c3434d\", \"best_bid\":\"0.08\", \"best_ask\":\"0.09\"}, {\"asset_id\":\"24254094493625419915756280046002869097156693848522361803041977572204227262166\", \"price\":\"0.88\", \"size\":\"344.55\", \"side\":\"BUY\", \"hash\":\"063feabfd41c465504b56ca0970d91762c8439e4\", \"best_bid\":\"0.91\", \"best_ask\":\"0.92\"}], \"timestamp\":\"1785122863770\", \"event_type\":\"price_change\"}","received_at":"2026-07-27T03:27:43.659872Z","schema_version":"clob-market-ws.price_change.v1","sequence":null,"server_hash":null,"server_timestamp":"1785122863770","session_id":"dd162b8dca5f43ff811d304e69a06123","source":"clob_market_ws"},"received_at":"2026-07-27T03:27:43.659872Z","record_id":"40788ff4770285a3f4aa1398f48ceed9b71aa335903eb081f8a4bcc332ef1650","schema_fingerprint":"4aa3821a28b0b7c2400bc59aba4bcc0a76e971dadd19610d3ad38c768e124dc7","schema_version":"edge-lab-recorder.raw.v1","sequence":null,"source":"clob_market_ws"}
{"event_at":"2026-07-27T03:27:43.798000Z","event_fingerprint":"3368bc8ecbd4b410555ceb5e21d5005fa3176dd6b672f53e74ba16a54e6927eb","payload":{"connection_id":"c7dc2e4762f849c6b6f9306b6518dcab","event_at":"2026-07-27T03:27:43.798000Z","event_type":"price_change","frame_hash":"7f29997d58a647bb0f0a1d26bb413e762dc1cc78475a914d4090316426bdb8bf","frame_index":0,"kind":"data","monotonic_ns":224847032878666,"payload":{"event_type":"price_change","market":"0x717c0e8ccd4d5c7040185188fbae28be901ca589a11a94b1b38ca36a79eccfeb","price_changes":[{"asset_id":"24254094493625419915756280046002869097156693848522361803041977572204227262166","best_ask":"0.92","best_bid":"0.91","hash":"06ed605ad757835014780bd9e39b6cde37f06799","price":"0.02","side":"BUY","size":"535"},{"asset_id":"41448400836309843603620980831210604935021861034693225347475867885462478926555","best_ask":"0.09","best_bid":"0.08","hash":"b1d89e46b6706c085dce44b42a0e8b878d1192f6","price":"0.98","side":"SELL","size":"535"}],"timestamp":"1785122863798"},"payload_hash":"517e2e736c02c69b8a7458f6f9214e5f12b793f8ecfc12f8d4e8c7e583acd47b","raw_frame":"{\"market\":\"0x717c0e8ccd4d5c7040185188fbae28be901ca589a11a94b1b38ca36a79eccfeb\", \"price_changes\":[{\"asset_id\":\"24254094493625419915756280046002869097156693848522361803041977572204227262166\", \"price\":\"0.02\", \"size\":\"535\", \"side\":\"BUY\", \"hash\":\"06ed605ad757835014780bd9e39b6cde37f06799\", \"best_bid\":\"0.91\", \"best_ask\":\"0.92\"}, {\"asset_id\":\"41448400836309843603620980831210604935021861034693225347475867885462478926555\", \"price\":\"0.98\", \"size\":\"535\", \"side\":\"SELL\", \"hash\":\"b1d89e46b6706c085dce44b42a0e8b878d1192f6\", \"best_bid\":\"0.08\", \"best_ask\":\"0.09\"}], \"timestamp\":\"1785122863798\", \"event_type\":\"price_change\"}","received_at":"2026-07-27T03:27:43.671393Z","schema_version":"clob-market-ws.price_change.v1","sequence":null,"server_hash":null,"server_timestamp":"1785122863798","session_id":"dd162b8dca5f43ff811d304e69a06123","source":"clob_market_ws"},"received_at":"2026-07-27T03:27:43.671393Z","record_id":"0997b8e41f78953ea991a43715db73887b192ca731dea9e54b71a6bf8e59ff30","schema_fingerprint":"4aa3821a28b0b7c2400bc59aba4bcc0a76e971dadd19610d3ad38c768e124dc7","schema_version":"edge-lab-recorder.raw.v1","sequence":null,"source":"clob_market_ws"}
{"event_at":"2026-07-27T03:27:43.888000Z","event_fingerprint":"a0c2e3c934579776b835f75cebea0aea8a3a21f119d2dc67022c4e86e96e7a3a","payload":{"connection_id":"c7dc2e4762f849c6b6f9306b6518dcab","event_at":"2026-07-27T03:27:43.888000Z","event_type":"price_change","frame_hash":"a9a5ad37265d23672f4932815c44a49b2c53e39318bf5455e9a7b4b1e630f7a3","frame_index":0,"kind":"data","monotonic_ns":224847128415041,"payload":{"event_type":"price_change","market":"0x717c0e8ccd4d5c7040185188fbae28be901ca589a11a94b1b38ca36a79eccfeb","price_changes":[{"asset_id":"41448400836309843603620980831210604935021861034693225347475867885462478926555","best_ask":"0.09","best_bid":"0.08","hash":"4c376f3f737f82762a0d66359aed1bdd6144c69a","price":"0.12","side":"SELL","size":"338.5"},{"asset_id":"24254094493625419915756280046002869097156693848522361803041977572204227262166","best_ask":"0.92","best_bid":"0.91","hash":"df07b450b5580d01a0db923debd430499277b3dd","price":"0.88","side":"BUY","size":"338.5"}],"timestamp":"1785122863888"},"payload_hash":"c8a7131f5f9265fe8b14e03b6258c741b85574973c26da2433db791b0880e40f","raw_frame":"{\"market\":\"0x717c0e8ccd4d5c7040185188fbae28be901ca589a11a94b1b38ca36a79eccfeb\", \"price_changes\":[{\"asset_id\":\"41448400836309843603620980831210604935021861034693225347475867885462478926555\", \"price\":\"0.12\", \"size\":\"338.5\", \"side\":\"SELL\", \"hash\":\"4c376f3f737f82762a0d66359aed1bdd6144c69a\", \"best_bid\":\"0.08\", \"best_ask\":\"0.09\"}, {\"asset_id\":\"24254094493625419915756280046002869097156693848522361803041977572204227262166\", \"price\":\"0.88\", \"size\":\"338.5\", \"side\":\"BUY\", \"hash\":\"df07b450b5580d01a0db923debd430499277b3dd\", \"best_bid\":\"0.91\", \"best_ask\":\"0.92\"}], \"timestamp\":\"1785122863888\", \"event_type\":\"price_change\"}","received_at":"2026-07-27T03:27:43.766930Z","schema_version":"clob-market-ws.price_change.v1","sequence":null,"server_hash":null,"server_timestamp":"1785122863888","session_id":"dd162b8dca5f43ff811d304e69a06123","source":"clob_market_ws"},"received_at":"2026-07-27T03:27:43.766930Z","record_id":"b5477f4743c00c2b6f13c36d1e91d31491dff98eb4e288890dc830cb21db68d6","schema_fingerprint":"4aa3821a28b0b7c2400bc59aba4bcc0a76e971dadd19610d3ad38c768e124dc7","schema_version":"edge-lab-recorder.raw.v1","sequence":null,"source":"clob_market_ws"}
{"event_at":"2026-07-27T03:27:43.915000Z","event_fingerprint":"e18118e25ecb2d0d849a4d2034a6ab25958218714ccfa7f623f43ecfa0fcc154","payload":{"connection_id":"c7dc2e4762f849c6b6f9306b6518dcab","event_at":"2026-07-27T03:27:43.915000Z","event_type":"price_change","frame_hash":"416b221814a42da855e17d79f84c0d73625b5d4e497a8aaa5a132e48a7c52b76","frame_index":0,"kind":"data","monotonic_ns":224847151696708,"payload":{"event_type":"price_change","market":"0x717c0e8ccd4d5c7040185188fbae28be901ca589a11a94b1b38ca36a79eccfeb","price_changes":[{"asset_id":"24254094493625419915756280046002869097156693848522361803041977572204227262166","best_ask":"0.92","best_bid":"0.91","hash":"e5a327063de0683ec35287a05154a4e3ac2ee906","price":"0.02","side":"BUY","size":"530"},{"asset_id":"41448400836309843603620980831210604935021861034693225347475867885462478926555","best_ask":"0.09","best_bid":"0.08","hash":"c3e4afe00175195ec9d6a282e17d6f3a8b7261e8","price":"0.98","side":"SELL","size":"530"}],"timestamp":"1785122863915"},"payload_hash":"37160f77bf32972dd0767af8d659e5df2fc38ddd16c7cbdc1cdffb870530ede4","raw_frame":"{\"market\":\"0x717c0e8ccd4d5c7040185188fbae28be901ca589a11a94b1b38ca36a79eccfeb\", \"price_changes\":[{\"asset_id\":\"24254094493625419915756280046002869097156693848522361803041977572204227262166\", \"price\":\"0.02\", \"size\":\"530\", \"side\":\"BUY\", \"hash\":\"e5a327063de0683ec35287a05154a4e3ac2ee906\", \"best_bid\":\"0.91\", \"best_ask\":\"0.92\"}, {\"asset_id\":\"41448400836309843603620980831210604935021861034693225347475867885462478926555\", \"price\":\"0.98\", \"size\":\"530\", \"side\":\"SELL\", \"hash\":\"c3e4afe00175195ec9d6a282e17d6f3a8b7261e8\", \"best_bid\":\"0.08\", \"best_ask\":\"0.09\"}], \"timestamp\":\"1785122863915\", \"event_type\":\"price_change\"}","received_at":"2026-07-27T03:27:43.790214Z","schema_version":"clob-market-ws.price_change.v1","sequence":null,"server_hash":null,"server_timestamp":"1785122863915","session_id":"dd162b8dca5f43ff811d304e69a06123","source":"clob_market_ws"},"received_at":"2026-07-27T03:27:43.790214Z","record_id":"56df12ec898bd668e87698c1b7d633f9c3e019d2e9255ef19db4a6a725eb5b78","schema_fingerprint":"4aa3821a28b0b7c2400bc59aba4bcc0a76e971dadd19610d3ad38c768e124dc7","schema_version":"edge-lab-recorder.raw.v1","sequence":null,"source":"clob_market_ws"}
{"event_at":"2026-07-27T03:27:44.016000Z","event_fingerprint":"98555f047b7caef7fe6ec2c5345d64ae1b4dccffdb2ce1c08d43b30c5fdb3386","payload":{"connection_id":"c7dc2e4762f849c6b6f9306b6518dcab","event_at":"2026-07-27T03:27:44.016000Z","event_type":"price_change","frame_hash":"d5b5b9f3c013dd6cfd4995cabe3d39d23105bf8e04a2c4c477602ad34001d053","frame_index":0,"kind":"data","monotonic_ns":224847250345000,"payload":{"event_type":"price_change","market":"0x717c0e8ccd4d5c7040185188fbae28be901ca589a11a94b1b38ca36a79eccfeb","price_changes":[{"asset_id":"41448400836309843603620980831210604935021861034693225347475867885462478926555","best_ask":"0.09","best_bid":"0.08","hash":"4d1806c165414711f8eb287299f78f8a72011c26","price":"0.12","side":"SELL","size":"344.55"},{"asset_id":"24254094493625419915756280046002869097156693848522361803041977572204227262166","best_ask":"0.92","best_bid":"0.91","hash":"0ee99346284abaac037c8d3b4a766c95c74afe3e","price":"0.88","side":"BUY","size":"344.55"}],"timestamp":"1785122864016"},"payload_hash":"657cd0245b2c11d801b4d7e39cc0514b37d97476224c4763fc9513e6959a2515","raw_frame":"{\"market\":\"0x717c0e8ccd4d5c7040185188fbae28be901ca589a11a94b1b38ca36a79eccfeb\", \"price_changes\":[{\"asset_id\":\"41448400836309843603620980831210604935021861034693225347475867885462478926555\", \"price\":\"0.12\", \"size\":\"344.55\", \"side\":\"SELL\", \"hash\":\"4d1806c165414711f8eb287299f78f8a72011c26\", \"best_bid\":\"0.08\", \"best_ask\":\"0.09\"}, {\"asset_id\":\"24254094493625419915756280046002869097156693848522361803041977572204227262166\", \"price\":\"0.88\", \"size\":\"344.55\", \"side\":\"BUY\", \"hash\":\"0ee99346284abaac037c8d3b4a766c95c74afe3e\", \"best_bid\":\"0.91\", \"best_ask\":\"0.92\"}], \"timestamp\":\"1785122864016\", \"event_type\":\"price_change\"}","received_at":"2026-07-27T03:27:43.888855Z","schema_version":"clob-market-ws.price_change.v1","sequence":null,"server_hash":null,"server_timestamp":"1785122864016","session_id":"dd162b8dca5f43ff811d304e69a06123","source":"clob_market_ws"},"received_at":"2026-07-27T03:27:43.888855Z","record_id":"5790b5f29949cc1823fa7e8a007a8d12a58a78b8e290cf73b54637e2ed0fb238","schema_fingerprint":"4aa3821a28b0b7c2400bc59aba4bcc0a76e971dadd19610d3ad38c768e124dc7","schema_version":"edge-lab-recorder.raw.v1","sequence":null,"source":"clob_market_ws"}
{"event_at":"2026-07-27T03:27:44.017000Z","event_fingerprint":"33e38c52c633a0c6dbff1ba2d37ca1263caa59d46208fe5b38dfa9d557d4b50f","payload":{"connection_id":"c7dc2e4762f849c6b6f9306b6518dcab","event_at":"2026-07-27T03:27:44.017000Z","event_type":"price_change","frame_hash":"49d8c99991acd5e23c3703f2faa856b57a34df9573f9f5adae3087ba06d85d5a","frame_index":0,"kind":"data","monotonic_ns":224847254089125,"payload":{"event_type":"price_change","market":"0x717c0e8ccd4d5c7040185188fbae28be901ca589a11a94b1b38ca36a79eccfeb","price_changes":[{"asset_id":"24254094493625419915756280046002869097156693848522361803041977572204227262166","best_ask":"0.92","best_bid":"0.91","hash":"9a10ba0af8d061dca010fad11a60107abe720ae0","price":"0.02","side":"BUY","size":"535"},{"asset_id":"41448400836309843603620980831210604935021861034693225347475867885462478926555","best_ask":"0.09","best_bid":"0.08","hash":"814a4f12727c5ebe87754a43436c099275307dd0","price":"0.98","side":"SELL","size":"535"}],"timestamp":"1785122864017"},"payload_hash":"77e5254d4937c4a6dab61630a025f7fd032ff2040497d4255838e5c23b735d4e","raw_frame":"{\"market\":\"0x717c0e8ccd4d5c7040185188fbae28be901ca589a11a94b1b38ca36a79eccfeb\", \"price_changes\":[{\"asset_id\":\"24254094493625419915756280046002869097156693848522361803041977572204227262166\", \"price\":\"0.02\", \"size\":\"535\", \"side\":\"BUY\", \"hash\":\"9a10ba0af8d061dca010fad11a60107abe720ae0\", \"best_bid\":\"0.91\", \"best_ask\":\"0.92\"}, {\"asset_id\":\"41448400836309843603620980831210604935021861034693225347475867885462478926555\", \"price\":\"0.98\", \"size\":\"535\", \"side\":\"SELL\", \"hash\":\"814a4f12727c5ebe87754a43436c099275307dd0\", \"best_bid\":\"0.08\", \"best_ask\":\"0.09\"}], \"timestamp\":\"1785122864017\", \"event_type\":\"price_change\"}","received_at":"2026-07-27T03:27:43.892600Z","schema_version":"clob-market-ws.price_change.v1","sequence":null,"server_hash":null,"server_timestamp":"1785122864017","session_id":"dd162b8dca5f43ff811d304e69a06123","source":"clob_market_ws"},"received_at":"2026-07-27T03:27:43.892600Z","record_id":"50631bbfecc1345fa37867170695eafb26ea37bf52e69396cc74bd4eac68f971","schema_fingerprint":"4aa3821a28b0b7c2400bc59aba4bcc0a76e971dadd19610d3ad38c768e124dc7","schema_version":"edge-lab-recorder.raw.v1","sequence":null,"source":"clob_market_ws"}
{"event_at":"2026-07-27T03:27:44.022000Z","event_fingerprint":"d88fadc66487aa2bd6be6d2d34537e0b5d1918a6fcbcf148da1da8264f6bdf55","payload":{"connection_id":"c7dc2e4762f849c6b6f9306b6518dcab","event_at":"2026-07-27T03:27:44.022000Z","event_type":"price_change","frame_hash":"af293fd87c60b3bf5665612d8ec4f8aa14762102522398f96b0d3935bdfae6fe","frame_index":0,"kind":"data","monotonic_ns":224847259053375,"payload":{"event_type":"price_change","market":"0x717c0e8ccd4d5c7040185188fbae28be901ca589a11a94b1b38ca36a79eccfeb","price_changes":[{"asset_id":"41448400836309843603620980831210604935021861034693225347475867885462478926555","best_ask":"0.09","best_bid":"0.08","hash":"bdbaf83ba513cb75965823c4728d89bfeebe2230","price":"0.01","side":"BUY","size":"5745.02"},{"asset_id":"24254094493625419915756280046002869097156693848522361803041977572204227262166","best_ask":"0.92","best_bid":"0.91","hash":"ef5828fe7e5ea3291363486d9b80056b8206f489","price":"0.99","side":"SELL","size":"5745.02"}],"timestamp":"1785122864022"},"payload_hash":"6b428e2603475d1f56adf3230879e4bd6e6284502042a3b706ae2e3025838e53","raw_frame":"{\"market\":\"0x717c0e8ccd4d5c7040185188fbae28be901ca589a11a94b1b38ca36a79eccfeb\", \"price_changes\":[{\"asset_id\":\"41448400836309843603620980831210604935021861034693225347475867885462478926555\", \"price\":\"0.01\", \"size\":\"5745.02\", \"side\":\"BUY\", \"hash\":\"bdbaf83ba513cb75965823c4728d89bfeebe2230\", \"best_bid\":\"0.08\", \"best_ask\":\"0.09\"}, {\"asset_id\":\"24254094493625419915756280046002869097156693848522361803041977572204227262166\", \"price\":\"0.99\", \"size\":\"5745.02\", \"side\":\"SELL\", \"hash\":\"ef5828fe7e5ea3291363486d9b80056b8206f489\", \"best_bid\":\"0.91\", \"best_ask\":\"0.92\"}], \"timestamp\":\"1785122864022\", \"event_type\":\"price_change\"}","received_at":"2026-07-27T03:27:43.897562Z","schema_version":"clob-market-ws.price_change.v1","sequence":null,"server_hash":null,"server_timestamp":"1785122864022","session_id":"dd162b8dca5f43ff811d304e69a06123","source":"clob_market_ws"},"received_at":"2026-07-27T03:27:43.897562Z","record_id":"50b4c583b0bc1d71d6d8d84c27e04ca0f284440cdce5fc56a9bcc44ac3a364b4","schema_fingerprint":"4aa3821a28b0b7c2400bc59aba4bcc0a76e971dadd19610d3ad38c768e124dc7","schema_version":"edge-lab-recorder.raw.v1","sequence":null,"source":"clob_market_ws"}
{"event_at":"2026-07-27T03:27:44.026000Z","event_fingerprint":"919a05594117f59176cb9d998f011129daae6ae66ea8181be0419a3b8ca3eb4e","payload":{"connection_id":"c7dc2e4762f849c6b6f9306b6518dcab","event_at":"2026-07-27T03:27:44.026000Z","event_type":"price_change","frame_hash":"b07768fa252de7e59b84b68cb245d7f43569e90424d91f0bf36ae496cfec135f","frame_index":0,"kind":"data","monotonic_ns":224847262523625,"payload":{"event_type":"price_change","market":"0x717c0e8ccd4d5c7040185188fbae28be901ca589a11a94b1b38ca36a79eccfeb","price_changes":[{"asset_id":"41448400836309843603620980831210604935021861034693225347475867885462478926555","best_ask":"0.09","best_bid":"0.08","hash":"91f8ea5ba2c999bfe02154a650ffbbd615b2bdf9","price":"0.01","side":"BUY","size":"5750.02"},{"asset_id":"24254094493625419915756280046002869097156693848522361803041977572204227262166","best_ask":"0.92","best_bid":"0.91","hash":"e34ce87f8cecdace39024f1d4bda78e9c4a1649d","price":"0.99","side":"SELL","size":"5750.02"}],"timestamp":"1785122864026"},"payload_hash":"7d344ff4dfa68a87c429931fa328b3126e74facc68ddfa40bcd83482efd76083","raw_frame":"{\"market\":\"0x717c0e8ccd4d5c7040185188fbae28be901ca589a11a94b1b38ca36a79eccfeb\", \"price_changes\":[{\"asset_id\":\"41448400836309843603620980831210604935021861034693225347475867885462478926555\", \"price\":\"0.01\", \"size\":\"5750.02\", \"side\":\"BUY\", \"hash\":\"91f8ea5ba2c999bfe02154a650ffbbd615b2bdf9\", \"best_bid\":\"0.08\", \"best_ask\":\"0.09\"}, {\"asset_id\":\"24254094493625419915756280046002869097156693848522361803041977572204227262166\", \"price\":\"0.99\", \"size\":\"5750.02\", \"side\":\"SELL\", \"hash\":\"e34ce87f8cecdace39024f1d4bda78e9c4a1649d\", \"best_bid\":\"0.91\", \"best_ask\":\"0.92\"}], \"timestamp\":\"1785122864026\", \"event_type\":\"price_change\"}","received_at":"2026-07-27T03:27:43.901031Z","schema_version":"clob-market-ws.price_change.v1","sequence":null,"server_hash":null,"server_timestamp":"1785122864026","session_id":"dd162b8dca5f43ff811d304e69a06123","source":"clob_market_ws"},"received_at":"2026-07-27T03:27:43.901031Z","record_id":"9d3d7b70a10031bef78a49167fcbd10dd5d60808508d12fc95cadf61659ed885","schema_fingerprint":"4aa3821a28b0b7c2400bc59aba4bcc0a76e971dadd19610d3ad38c768e124dc7","schema_version":"edge-lab-recorder.raw.v1","sequence":null,"source":"clob_market_ws"}
{"event_at":"2026-07-27T03:27:44.050000Z","event_fingerprint":"306e662a2ec3cfa7aef6f45572c33e30774011859d57856a1e1c9141ec8776b7","payload":{"connection_id":"c7dc2e4762f849c6b6f9306b6518dcab","event_at":"2026-07-27T03:27:44.050000Z","event_type":"price_change","frame_hash":"7aef0273d16f5cf813cfa277806fa825c1d7438f3735eebc58f9b73f3c658749","frame_index":0,"kind":"data","monotonic_ns":224847292362458,"payload":{"event_type":"price_change","market":"0x717c0e8ccd4d5c7040185188fbae28be901ca589a11a94b1b38ca36a79eccfeb","price_changes":[{"asset_id":"24254094493625419915756280046002869097156693848522361803041977572204227262166","best_ask":"0.92","best_bid":"0.91","hash":"c486664843db5710daf5432095c329699dbbb466","price":"0.01","side":"BUY","size":"5155.02"},{"asset_id":"41448400836309843603620980831210604935021861034693225347475867885462478926555","best_ask":"0.09","best_bid":"0.08","hash":"456ee326c566f14e090639ea47a6512fd07f05d1","price":"0.99","side":"SELL","size":"5155.02"}],"timestamp":"1785122864050"},"payload_hash":"6fabd4123bf5ae2eae7a52fd849f3249c031fdae5c0e672209cca516e5ad4a70","raw_frame":"{\"market\":\"0x717c0e8ccd4d5c7040185188fbae28be901ca589a11a94b1b38ca36a79eccfeb\", \"price_changes\":[{\"asset_id\":\"24254094493625419915756280046002869097156693848522361803041977572204227262166\", \"price\":\"0.01\", \"size\":\"5155.02\", \"side\":\"BUY\", \"hash\":\"c486664843db5710daf5432095c329699dbbb466\", \"best_bid\":\"0.91\", \"best_ask\":\"0.92\"}, {\"asset_id\":\"41448400836309843603620980831210604935021861034693225347475867885462478926555\", \"price\":\"0.99\", \"size\":\"5155.02\", \"side\":\"SELL\", \"hash\":\"456ee326c566f14e090639ea47a6512fd07f05d1\", \"best_bid\":\"0.08\", \"best_ask\":\"0.09\"}], \"timestamp\":\"1785122864050\", \"event_type\":\"price_change\"}","received_at":"2026-07-27T03:27:43.930871Z","schema_version":"clob-market-ws.price_change.v1","sequence":null,"server_hash":null,"server_timestamp":"1785122864050","session_id":"dd162b8dca5f43ff811d304e69a06123","source":"clob_market_ws"},"received_at":"2026-07-27T03:27:43.930871Z","record_id":"d06b6d862fef649b26ee43664b8522384b386a5fe1cf6cc35063848d50277f3a","schema_fingerprint":"4aa3821a28b0b7c2400bc59aba4bcc0a76e971dadd19610d3ad38c768e124dc7","schema_version":"edge-lab-recorder.raw.v1","sequence":null,"source":"clob_market_ws"}
{"event_at":"2026-07-27T03:27:44.068000Z","event_fingerprint":"28a9bd3b4bc76b7a86ba344771a0772eb08346b488d1c2031c67dcc746cd593b","payload":{"connection_id":"c7dc2e4762f849c6b6f9306b6518dcab","event_at":"2026-07-27T03:27:44.068000Z","event_type":"price_change","frame_hash":"6ef1ef666c0fc7ca7d4a7098dab0d5b94a6b8e0730263339a0ca5d1071d84e4b","frame_index":0,"kind":"data","monotonic_ns":224847305358666,"payload":{"event_type":"price_change","market":"0x717c0e8ccd4d5c7040185188fbae28be901ca589a11a94b1b38ca36a79eccfeb","price_changes":[{"asset_id":"24254094493625419915756280046002869097156693848522361803041977572204227262166","best_ask":"0.92","best_bid":"0.91","hash":"6f01c86c429d23d4d02e57272fc2dfe3c7155d81","price":"0.01","side":"BUY","size":"5150.02"},{"asset_id":"41448400836309843603620980831210604935021861034693225347475867885462478926555","best_ask":"0.09","best_bid":"0.08","hash":"d3e77ba9d2a9ad939c6b5a9d8419b8dcd25b5069","price":"0.99","side":"SELL","size":"5150.02"}],"timestamp":"1785122864068"},"payload_hash":"26d7e273dcf982f994ae01747072a0e61e774ddf98fef02ddfcb530a4f1d7e65","raw_frame":"{\"market\":\"0x717c0e8ccd4d5c7040185188fbae28be901ca589a11a94b1b38ca36a79eccfeb\", \"price_changes\":[{\"asset_id\":\"24254094493625419915756280046002869097156693848522361803041977572204227262166\", \"price\":\"0.01\", \"size\":\"5150.02\", \"side\":\"BUY\", \"hash\":\"6f01c86c429d23d4d02e57272fc2dfe3c7155d81\", \"best_bid\":\"0.91\", \"best_ask\":\"0.92\"}, {\"asset_id\":\"41448400836309843603620980831210604935021861034693225347475867885462478926555\", \"price\":\"0.99\", \"size\":\"5150.02\", \"side\":\"SELL\", \"hash\":\"d3e77ba9d2a9ad939c6b5a9d8419b8dcd25b5069\", \"best_bid\":\"0.08\", \"best_ask\":\"0.09\"}], \"timestamp\":\"1785122864068\", \"event_type\":\"price_change\"}","received_at":"2026-07-27T03:27:43.943865Z","schema_version":"clob-market-ws.price_change.v1","sequence":null,"server_hash":null,"server_timestamp":"1785122864068","session_id":"dd162b8dca5f43ff811d304e69a06123","source":"clob_market_ws"},"received_at":"2026-07-27T03:27:43.943865Z","record_id":"d37b759e4065f2a0dd029f151cb2c84e9d33436dd599a194545400d8c6e4ecbc","schema_fingerprint":"4aa3821a28b0b7c2400bc59aba4bcc0a76e971dadd19610d3ad38c768e124dc7","schema_version":"edge-lab-recorder.raw.v1","sequence":null,"source":"clob_market_ws"}
{"event_at":"2026-07-27T03:27:44.069000Z","event_fingerprint":"a51a787692e24919c6f45dcd02c3a9494965aa228b84e6fdda7d84c39c622391","payload":{"connection_id":"c7dc2e4762f849c6b6f9306b6518dcab","event_at":"2026-07-27T03:27:44.069000Z","event_type":"price_change","frame_hash":"e05ab3ca3e83c93b8563e487c6e5f9236c280065c851b9fb0dea6e4c68014cbe","frame_index":0,"kind":"data","monotonic_ns":224847308817541,"payload":{"event_type":"price_change","market":"0x717c0e8ccd4d5c7040185188fbae28be901ca589a11a94b1b38ca36a79eccfeb","price_changes":[{"asset_id":"41448400836309843603620980831210604935021861034693225347475867885462478926555","best_ask":"0.09","best_bid":"0.08","hash":"4171ff4aa49c7abb78e24e079a915a4cadee0fed","price":"0.01","side":"BUY","size":"5745.02"},{"asset_id":"24254094493625419915756280046002869097156693848522361803041977572204227262166","best_ask":"0.92","best_bid":"0.91","hash":"ecae007f9e27f0b798adfcef867cfd55bba43e1b","price":"0.99","side":"SELL","size":"5745.02"}],"timestamp":"1785122864069"},"payload_hash":"0fe1578b050dd0d47e90d6cf5e70b8ec32e14f9d85be8be39a24a222deb3dcdc","raw_frame":"{\"market\":\"0x717c0e8ccd4d5c7040185188fbae28be901ca589a11a94b1b38ca36a79eccfeb\", \"price_changes\":[{\"asset_id\":\"41448400836309843603620980831210604935021861034693225347475867885462478926555\", \"price\":\"0.01\", \"size\":\"5745.02\", \"side\":\"BUY\", \"hash\":\"4171ff4aa49c7abb78e24e079a915a4cadee0fed\", \"best_bid\":\"0.08\", \"best_ask\":\"0.09\"}, {\"asset_id\":\"24254094493625419915756280046002869097156693848522361803041977572204227262166\", \"price\":\"0.99\", \"size\":\"5745.02\", \"side\":\"SELL\", \"hash\":\"ecae007f9e27f0b798adfcef867cfd55bba43e1b\", \"best_bid\":\"0.91\", \"best_ask\":\"0.92\"}], \"timestamp\":\"1785122864069\", \"event_type\":\"price_change\"}","received_at":"2026-07-27T03:27:43.947328Z","schema_version":"clob-market-ws.price_change.v1","sequence":null,"server_hash":null,"server_timestamp":"1785122864069","session_id":"dd162b8dca5f43ff811d304e69a06123","source":"clob_market_ws"},"received_at":"2026-07-27T03:27:43.947328Z","record_id":"3b9920fc7ad9ecabb9aaf14e07f67333602508889430bda6ee08c74d0b208087","schema_fingerprint":"4aa3821a28b0b7c2400bc59aba4bcc0a76e971dadd19610d3ad38c768e124dc7","schema_version":"edge-lab-recorder.raw.v1","sequence":null,"source":"clob_market_ws"}
{"event_at":"2026-07-27T03:27:44.075000Z","event_fingerprint":"9fe0acf75e207e64f0235eef7ab216205de2678323261a0366294d6a65cee03d","payload":{"connection_id":"c7dc2e4762f849c6b6f9306b6518dcab","event_at":"2026-07-27T03:27:44.075000Z","event_type":"price_change","frame_hash":"65ca4fc7c1e2484134d3a325dca0e8ebec45a7c50896c51a7d9e991400e08781","frame_index":0,"kind":"data","monotonic_ns":224847313042500,"payload":{"event_type":"price_change","market":"0x717c0e8ccd4d5c7040185188fbae28be901ca589a11a94b1b38ca36a79eccfeb","price_changes":[{"asset_id":"24254094493625419915756280046002869097156693848522361803041977572204227262166","best_ask":"0.92","best_bid":"0.91","hash":"7c488bc869208bb5e1820dccb9acbfb998e4675e","price":"0.02","side":"BUY","size":"530"},{"asset_id":"41448400836309843603620980831210604935021861034693225347475867885462478926555","best_ask":"0.09","best_bid":"0.08","hash":"aceda00a938d8e1a5a250686e59d563d745b88af","price":"0.98","side":"SELL","size":"530"}],"timestamp":"1785122864075"},"payload_hash":"936562587a918d8c399b03fb86f583fb4137b96dec487043032c0ed70d329290","raw_frame":"{\"market\":\"0x717c0e8ccd4d5c7040185188fbae28be901ca589a11a94b1b38ca36a79eccfeb\", \"price_changes\":[{\"asset_id\":\"24254094493625419915756280046002869097156693848522361803041977572204227262166\", \"price\":\"0.02\", \"size\":\"530\", \"side\":\"BUY\", \"hash\":\"7c488bc869208bb5e1820dccb9acbfb998e4675e\", \"best_bid\":\"0.91\", \"best_ask\":\"0.92\"}, {\"asset_id\":\"41448400836309843603620980831210604935021861034693225347475867885462478926555\", \"price\":\"0.98\", \"size\":\"530\", \"side\":\"SELL\", \"hash\":\"aceda00a938d8e1a5a250686e59d563d745b88af\", \"best_bid\":\"0.08\", \"best_ask\":\"0.09\"}], \"timestamp\":\"1785122864075\", \"event_type\":\"price_change\"}","received_at":"2026-07-27T03:27:43.951550Z","schema_version":"clob-market-ws.price_change.v1","sequence":null,"server_hash":null,"server_timestamp":"1785122864075","session_id":"dd162b8dca5f43ff811d304e69a06123","source":"clob_market_ws"},"received_at":"2026-07-27T03:27:43.951550Z","record_id":"7033dda72be9e55f7957005f33c7c7e19e6722904c3d7aaa8da8d670f557bb5f","schema_fingerprint":"4aa3821a28b0b7c2400bc59aba4bcc0a76e971dadd19610d3ad38c768e124dc7","schema_version":"edge-lab-recorder.raw.v1","sequence":null,"source":"clob_market_ws"}
{"event_at":"2026-07-27T03:27:44.077000Z","event_fingerprint":"61e5a789d482bb2c558ffbe3e5f9a2ba2e7795d292ee4b48f37da17464437528","payload":{"connection_id":"c7dc2e4762f849c6b6f9306b6518dcab","event_at":"2026-07-27T03:27:44.077000Z","event_type":"price_change","frame_hash":"199c222caf09b47a31dcdd8fd5d1673574258673a48af6aaa4da9050f4a43b80","frame_index":0,"kind":"data","monotonic_ns":224847314655375,"payload":{"event_type":"price_change","market":"0x717c0e8ccd4d5c7040185188fbae28be901ca589a11a94b1b38ca36a79eccfeb","price_changes":[{"asset_id":"24254094493625419915756280046002869097156693848522361803041977572204227262166","best_ask":"0.92","best_bid":"0.91","hash":"3cd55455c2e6f98a27f179fec777c766365e998d","price":"0.01","side":"BUY","size":"5155.02"},{"asset_id":"41448400836309843603620980831210604935021861034693225347475867885462478926555","best_ask":"0.09","best_bid":"0.08","hash":"426173e7392ef1bf53e8b9bdc16fa861e4d88f8b","price":"0.99","side":"SELL","size":"5155.02"}],"timestamp":"1785122864077"},"payload_hash":"4c535c0308bda8a56d476f2d95875204bdca4b2448a2c3625f25c4ea78cec9fe","raw_frame":"{\"market\":\"0x717c0e8ccd4d5c7040185188fbae28be901ca589a11a94b1b38ca36a79eccfeb\", \"price_changes\":[{\"asset_id\":\"24254094493625419915756280046002869097156693848522361803041977572204227262166\", \"price\":\"0.01\", \"size\":\"5155.02\", \"side\":\"BUY\", \"hash\":\"3cd55455c2e6f98a27f179fec777c766365e998d\", \"best_bid\":\"0.91\", \"best_ask\":\"0.92\"}, {\"asset_id\":\"41448400836309843603620980831210604935021861034693225347475867885462478926555\", \"price\":\"0.99\", \"size\":\"5155.02\", \"side\":\"SELL\", \"hash\":\"426173e7392ef1bf53e8b9bdc16fa861e4d88f8b\", \"best_bid\":\"0.08\", \"best_ask\":\"0.09\"}], \"timestamp\":\"1785122864077\", \"event_type\":\"price_change\"}","received_at":"2026-07-27T03:27:43.953163Z","schema_version":"clob-market-ws.price_change.v1","sequence":null,"server_hash":null,"server_timestamp":"1785122864077","session_id":"dd162b8dca5f43ff811d304e69a06123","source":"clob_market_ws"},"received_at":"2026-07-27T03:27:43.953163Z","record_id":"c20ae411f66eab45ffcae05ec672c8faec1046b7ee63eabb30528b1d3457fd5b","schema_fingerprint":"4aa3821a28b0b7c2400bc59aba4bcc0a76e971dadd19610d3ad38c768e124dc7","schema_version":"edge-lab-recorder.raw.v1","sequence":null,"source":"clob_market_ws"}
{"event_at":"2026-07-27T03:27:44.101000Z","event_fingerprint":"66711a4c2a02e14d7b69e67eaf715065b7a2b5b8133d388e7c56c6f57e3ed4b0","payload":{"connection_id":"c7dc2e4762f849c6b6f9306b6518dcab","event_at":"2026-07-27T03:27:44.101000Z","event_type":"price_change","frame_hash":"871465e6c9eaf2f7049196cc06f4b74d88e20172db39dd60c639bc0bdab82bdc","frame_index":0,"kind":"data","monotonic_ns":224847351235375,"payload":{"event_type":"price_change","market":"0x717c0e8ccd4d5c7040185188fbae28be901ca589a11a94b1b38ca36a79eccfeb","price_changes":[{"asset_id":"41448400836309843603620980831210604935021861034693225347475867885462478926555","best_ask":"0.09","best_bid":"0.08","hash":"b3a5c5ce3e4c585ddf4cf865bd7bf483f228ac3e","price":"0.01","side":"BUY","size":"5740.02"},{"asset_id":"24254094493625419915756280046002869097156693848522361803041977572204227262166","best_ask":"0.92","best_bid":"0.91","hash":"001fdd23ab99d3b56e462424fd95e969f832c0e9","price":"0.99","side":"SELL","size":"5740.02"}],"timestamp":"1785122864101"},"payload_hash":"311417e37a63f7a8b4e3934a3002ba216e5877cf88f99f2917ded19fab8771ce","raw_frame":"{\"market\":\"0x717c0e8ccd4d5c7040185188fbae28be901ca589a11a94b1b38ca36a79eccfeb\", \"price_changes\":[{\"asset_id\":\"41448400836309843603620980831210604935021861034693225347475867885462478926555\", \"price\":\"0.01\", \"size\":\"5740.02\", \"side\":\"BUY\", \"hash\":\"b3a5c5ce3e4c585ddf4cf865bd7bf483f228ac3e\", \"best_bid\":\"0.08\", \"best_ask\":\"0.09\"}, {\"asset_id\":\"24254094493625419915756280046002869097156693848522361803041977572204227262166\", \"price\":\"0.99\", \"size\":\"5740.02\", \"side\":\"SELL\", \"hash\":\"001fdd23ab99d3b56e462424fd95e969f832c0e9\", \"best_bid\":\"0.91\", \"best_ask\":\"0.92\"}], \"timestamp\":\"1785122864101\", \"event_type\":\"price_change\"}","received_at":"2026-07-27T03:27:43.989742Z","schema_version":"clob-market-ws.price_change.v1","sequence":null,"server_hash":null,"server_timestamp":"1785122864101","session_id":"dd162b8dca5f43ff811d304e69a06123","source":"clob_market_ws"},"received_at":"2026-07-27T03:27:43.989742Z","record_id":"de82838d4c80efe9b73f11f025adc6b9a5c151e01120dbaeb38841b251ef3077","schema_fingerprint":"4aa3821a28b0b7c2400bc59aba4bcc0a76e971dadd19610d3ad38c768e124dc7","schema_version":"edge-lab-recorder.raw.v1","sequence":null,"source":"clob_market_ws"}
{"event_at":"2026-07-27T03:27:44.111000Z","event_fingerprint":"8d9436963e0924b920d27aad2adc865922bb67783f14902d6a6e0aab6b8cd939","payload":{"connection_id":"c7dc2e4762f849c6b6f9306b6518dcab","event_at":"2026-07-27T03:27:44.111000Z","event_type":"price_change","frame_hash":"d51ae0e8484dab1cfdfa3b5c387e46f098d7511806c0f3276e73f5ef696a5266","frame_index":0,"kind":"data","monotonic_ns":224847354624375,"payload":{"event_type":"price_change","market":"0x717c0e8ccd4d5c7040185188fbae28be901ca589a11a94b1b38ca36a79eccfeb","price_changes":[{"asset_id":"24254094493625419915756280046002869097156693848522361803041977572204227262166","best_ask":"0.92","best_bid":"0.91","hash":"f42f5817cabd373ef2d109d8d792fd427f0d0136","price":"0.01","side":"BUY","size":"5150.02"},{"asset_id":"41448400836309843603620980831210604935021861034693225347475867885462478926555","best_ask":"0.09","best_bid":"0.08","hash":"9b71cadb0eb7e9478634de0a643a9bbee05b8f12","price":"0.99","side":"SELL","size":"5150.02"}],"timestamp":"1785122864111"},"payload_hash":"6929f8d86f728eedbeeffe2da3b3887687a1c94321e956ab315822d08ba7155a","raw_frame":"{\"market\":\"0x717c0e8ccd4d5c7040185188fbae28be901ca589a11a94b1b38ca36a79eccfeb\", \"price_changes\":[{\"asset_id\":\"24254094493625419915756280046002869097156693848522361803041977572204227262166\", \"price\":\"0.01\", \"size\":\"5150.02\", \"side\":\"BUY\", \"hash\":\"f42f5817cabd373ef2d109d8d792fd427f0d0136\", \"best_bid\":\"0.91\", \"best_ask\":\"0.92\"}, {\"asset_id\":\"41448400836309843603620980831210604935021861034693225347475867885462478926555\", \"price\":\"0.99\", \"size\":\"5150.02\", \"side\":\"SELL\", \"hash\":\"9b71cadb0eb7e9478634de0a643a9bbee05b8f12\", \"best_bid\":\"0.08\", \"best_ask\":\"0.09\"}], \"timestamp\":\"1785122864111\", \"event_type\":\"price_change\"}","received_at":"2026-07-27T03:27:43.993132Z","schema_version":"clob-market-ws.price_change.v1","sequence":null,"server_hash":null,"server_timestamp":"1785122864111","session_id":"dd162b8dca5f43ff811d304e69a06123","source":"clob_market_ws"},"received_at":"2026-07-27T03:27:43.993132Z","record_id":"c942e6d835a3983dbea49fe488a6a0bf5b427064fd747d55b92b724a72fa4ea1","schema_fingerprint":"4aa3821a28b0b7c2400bc59aba4bcc0a76e971dadd19610d3ad38c768e124dc7","schema_version":"edge-lab-recorder.raw.v1","sequence":null,"source":"clob_market_ws"}
{"event_at":"2026-07-27T03:27:44.126000Z","event_fingerprint":"a2c8d9a6dc7324b950bfa0134678b185b44a8476b41b96fec439b51407bec802","payload":{"connection_id":"c7dc2e4762f849c6b6f9306b6518dcab","event_at":"2026-07-27T03:27:44.126000Z","event_type":"price_change","frame_hash":"0f98450c78f2b6632c1ebc74d9c9aa42ccf5d59090e93e30806d06e7d78b5d83","frame_index":0,"kind":"data","monotonic_ns":224847360481750,"payload":{"event_type":"price_change","market":"0x717c0e8ccd4d5c7040185188fbae28be901ca589a11a94b1b38ca36a79eccfeb","price_changes":[{"asset_id":"24254094493625419915756280046002869097156693848522361803041977572204227262166","best_ask":"0.92","best_bid":"0.91","hash":"8516c112aa712aad48b2889d9431e1b08ed855f1","price":"0.57","side":"BUY","size":"62.47"},{"asset_id":"41448400836309843603620980831210604935021861034693225347475867885462478926555","best_ask":"0.09","best_bid":"0.08","hash":"a6038ba413ce1c708d12bb3ba1ec91b8b51e75c3","price":"0.43","side":"SELL","size":"62.47"}],"timestamp":"1785122864126"},"payload_hash":"1d3c40b8aace81897724e6f45920b70b6f7eebda75401a107888e70bed86e503","raw_frame":"{\"market\":\"0x717c0e8ccd4d5c7040185188fbae28be901ca589a11a94b1b38ca36a79eccfeb\", \"price_changes\":[{\"asset_id\":\"24254094493625419915756280046002869097156693848522361803041977572204227262166\", \"price\":\"0.57\", \"size\":\"62.47\", \"side\":\"BUY\", \"hash\":\"8516c112aa712aad48b2889d9431e1b08ed855f1\", \"best_bid\":\"0.91\", \"best_ask\":\"0.92\"}, {\"asset_id\":\"41448400836309843603620980831210604935021861034693225347475867885462478926555\", \"price\":\"0.43\", \"size\":\"62.47\", \"side\":\"SELL\", \"hash\":\"a6038ba413ce1c708d12bb3ba1ec91b8b51e75c3\", \"best_bid\":\"0.08\", \"best_ask\":\"0.09\"}], \"timestamp\":\"1785122864126\", \"event_type\":\"price_change\"}","received_at":"2026-07-27T03:27:43.998987Z","schema_version":"clob-market-ws.price_change.v1","sequence":null,"server_hash":null,"server_timestamp":"1785122864126","session_id":"dd162b8dca5f43ff811d304e69a06123","source":"clob_market_ws"},"received_at":"2026-07-27T03:27:43.998987Z","record_id":"5b2223af31613010f84ced08ef00e707ccde751cc0e88f4dfd1e87f42195b2a6","schema_fingerprint":"4aa3821a28b0b7c2400bc59aba4bcc0a76e971dadd19610d3ad38c768e124dc7","schema_version":"edge-lab-recorder.raw.v1","sequence":null,"source":"clob_market_ws"}
{"event_at":"2026-07-27T03:27:44.127000Z","event_fingerprint":"05526c1b0d2a3bf11ced22b59118f88c5c1f28281cae534c8ff1fa1442f89fe8","payload":{"connection_id":"c7dc2e4762f849c6b6f9306b6518dcab","event_at":"2026-07-27T03:27:44.127000Z","event_type":"price_change","frame_hash":"e4525591cd666bd6d81c6ff4dcc0d12d6cc1a926b7f5dd540b5c2a929689aab6","frame_index":0,"kind":"data","monotonic_ns":224847363711875,"payload":{"event_type":"price_change","market":"0x717c0e8ccd4d5c7040185188fbae28be901ca589a11a94b1b38ca36a79eccfeb","price_changes":[{"asset_id":"41448400836309843603620980831210604935021861034693225347475867885462478926555","best_ask":"0.09","best_bid":"0.08","hash":"4f0660d71b8a54a050cdb539fd8c3962014b937b","price":"0.03","side":"BUY","size":"1152"},{"asset_id":"24254094493625419915756280046002869097156693848522361803041977572204227262166","best_ask":"0.92","best_bid":"0.91","hash":"0d4a58d6e086a7aaeba0968c40737b1ebed9110b","price":"0.97","side":"SELL","size":"1152"}],"timestamp":"1785122864127"},"payload_hash":"c582f4f8affdc2cd191c86b650de8f7422b2028c5b94192ab4b6be08db06985b","raw_frame":"{\"market\":\"0x717c0e8ccd4d5c7040185188fbae28be901ca589a11a94b1b38ca36a79eccfeb\", \"price_changes\":[{\"asset_id\":\"41448400836309843603620980831210604935021861034693225347475867885462478926555\", \"price\":\"0.03\", \"size\":\"1152\", \"side\":\"BUY\", \"hash\":\"4f0660d71b8a54a050cdb539fd8c3962014b937b\", \"best_bid\":\"0.08\", \"best_ask\":\"0.09\"}, {\"asset_id\":\"24254094493625419915756280046002869097156693848522361803041977572204227262166\", \"price\":\"0.97\", \"size\":\"1152\", \"side\":\"SELL\", \"hash\":\"0d4a58d6e086a7aaeba0968c40737b1ebed9110b\", \"best_bid\":\"0.91\", \"best_ask\":\"0.92\"}], \"timestamp\":\"1785122864127\", \"event_type\":\"price_change\"}","received_at":"2026-07-27T03:27:44.002220Z","schema_version":"clob-market-ws.price_change.v1","sequence":null,"server_hash":null,"server_timestamp":"1785122864127","session_id":"dd162b8dca5f43ff811d304e69a06123","source":"clob_market_ws"},"received_at":"2026-07-27T03:27:44.002220Z","record_id":"e3aefee327185c9a49152fbb2cdf6e1a4ee1e1ecd536a80ed9df4b52d93dcbfd","schema_fingerprint":"4aa3821a28b0b7c2400bc59aba4bcc0a76e971dadd19610d3ad38c768e124dc7","schema_version":"edge-lab-recorder.raw.v1","sequence":null,"source":"clob_market_ws"}
{"event_at":"2026-07-27T03:27:44.149000Z","event_fingerprint":"d71e6f7d324b2e8731d9bbf1b9ddb49f88e3ddb9db216981a87f58ba83dd58bf","payload":{"connection_id":"c7dc2e4762f849c6b6f9306b6518dcab","event_at":"2026-07-27T03:27:44.149000Z","event_type":"price_change","frame_hash":"f88251e968a7d262a22923945352c1882d857895716e31b74814b4b96b38df8d","frame_index":0,"kind":"data","monotonic_ns":224847383964958,"payload":{"event_type":"price_change","market":"0x717c0e8ccd4d5c7040185188fbae28be901ca589a11a94b1b38ca36a79eccfeb","price_changes":[{"asset_id":"24254094493625419915756280046002869097156693848522361803041977572204227262166","best_ask":"0.92","best_bid":"0.91","hash":"9556dd5491e8eb45133e21d3d15a9f27b3d9ad38","price":"0.03","side":"BUY","size":"515"},{"asset_id":"41448400836309843603620980831210604935021861034693225347475867885462478926555","best_ask":"0.09","best_bid":"0.08","hash":"ca1b3beacf92c946cb3c0db89a4b5dd6bfa3a484","price":"0.97","side":"SELL","size":"515"}],"timestamp":"1785122864149"},"payload_hash":"4bc4b349939c89cc6de1d41a8994ecadfd2180dee906fe99f696d6839230f3ba","raw_frame":"{\"market\":\"0x717c0e8ccd4d5c7040185188fbae28be901ca589a11a94b1b38ca36a79eccfeb\", \"price_changes\":[{\"asset_id\":\"24254094493625419915756280046002869097156693848522361803041977572204227262166\", \"price\":\"0.03\", \"size\":\"515\", \"side\":\"BUY\", \"hash\":\"9556dd5491e8eb45133e21d3d15a9f27b3d9ad38\", \"best_bid\":\"0.91\", \"best_ask\":\"0.92\"}, {\"asset_id\":\"41448400836309843603620980831210604935021861034693225347475867885462478926555\", \"price\":\"0.97\", \"size\":\"515\", \"side\":\"SELL\", \"hash\":\"ca1b3beacf92c946cb3c0db89a4b5dd6bfa3a484\", \"best_bid\":\"0.08\", \"best_ask\":\"0.09\"}], \"timestamp\":\"1785122864149\", \"event_type\":\"price_change\"}","received_at":"2026-07-27T03:27:44.022471Z","schema_version":"clob-market-ws.price_change.v1","sequence":null,"server_hash":null,"server_timestamp":"1785122864149","session_id":"dd162b8dca5f43ff811d304e69a06123","source":"clob_market_ws"},"received_at":"2026-07-27T03:27:44.022471Z","record_id":"e192d1c3cd60eef93c081fc92e3372724b527836627c66b8f4fc1884fb6aee38","schema_fingerprint":"4aa3821a28b0b7c2400bc59aba4bcc0a76e971dadd19610d3ad38c768e124dc7","schema_version":"edge-lab-recorder.raw.v1","sequence":null,"source":"clob_market_ws"}
{"event_at":"2026-07-27T03:27:44.165000Z","event_fingerprint":"0ca7149250bbcef5dc9d216fa4b0b4aa12c83d9f85b98d287cb1b029a0b4713d","payload":{"connection_id":"c7dc2e4762f849c6b6f9306b6518dcab","event_at":"2026-07-27T03:27:44.165000Z","event_type":"price_change","frame_hash":"e6e2a1647e74bcc7ad1bfcc23bc498150c5589da3a7cff82eb96e20d0b3ad43f","frame_index":0,"kind":"data","monotonic_ns":224847406957708,"payload":{"event_type":"price_change","market":"0x717c0e8ccd4d5c7040185188fbae28be901ca589a11a94b1b38ca36a79eccfeb","price_changes":[{"asset_id":"41448400836309843603620980831210604935021861034693225347475867885462478926555","best_ask":"0.09","best_bid":"0.08","hash":"bdec59a86132a926e1c22a493f82bb8e19193072","price":"0.12","side":"SELL","size":"338.5"},{"asset_id":"24254094493625419915756280046002869097156693848522361803041977572204227262166","best_ask":"0.92","best_bid":"0.91","hash":"a7ac48ad0f66d4b606ed94bf88c13aa14d5661fe","price":"0.88","side":"BUY","size":"338.5"}],"timestamp":"1785122864165"},"payload_hash":"06d173d038e383bb1e635ad0a537cb440adcf3c94c723bb66433500f0e9048ec","raw_frame":"{\"market\":\"0x717c0e8ccd4d5c7040185188fbae28be901ca589a11a94b1b38ca36a79eccfeb\", \"price_changes\":[{\"asset_id\":\"41448400836309843603620980831210604935021861034693225347475867885462478926555\", \"price\":\"0.12\", \"size\":\"338.5\", \"side\":\"SELL\", \"hash\":\"bdec59a86132a926e1c22a493f82bb8e19193072\", \"best_bid\":\"0.08\", \"best_ask\":\"0.09\"}, {\"asset_id\":\"24254094493625419915756280046002869097156693848522361803041977572204227262166\", \"price\":\"0.88\", \"size\":\"338.5\", \"side\":\"BUY\", \"hash\":\"a7ac48ad0f66d4b606ed94bf88c13aa14d5661fe\", \"best_bid\":\"0.91\", \"best_ask\":\"0.92\"}], \"timestamp\":\"1785122864165\", \"event_type\":\"price_change\"}","received_at":"2026-07-27T03:27:44.045463Z","schema_version":"clob-market-ws.price_change.v1","sequence":null,"server_hash":null,"server_timestamp":"1785122864165","session_id":"dd162b8dca5f43ff811d304e69a06123","source":"clob_market_ws"},"received_at":"2026-07-27T03:27:44.045463Z","record_id":"dd47780af17981b8491eae6d1aa5dfd148363b1b0a875153ec655216f1d53c87","schema_fingerprint":"4aa3821a28b0b7c2400bc59aba4bcc0a76e971dadd19610d3ad38c768e124dc7","schema_version":"edge-lab-recorder.raw.v1","sequence":null,"source":"clob_market_ws"}
{"event_at":"2026-07-27T03:27:44.176000Z","event_fingerprint":"07c0b5fe08b8194b47616898d11fefe9c1ff14da5364ede4260a3a3b6980c96c","payload":{"connection_id":"c7dc2e4762f849c6b6f9306b6518dcab","event_at":"2026-07-27T03:27:44.176000Z","event_type":"price_change","frame_hash":"1b55894f087d9351aa1ad6bab5cc01ef7baf02ce8b6dbb55b93732938cf690a9","frame_index":0,"kind":"data","monotonic_ns":224847414591250,"payload":{"event_type":"price_change","market":"0x717c0e8ccd4d5c7040185188fbae28be901ca589a11a94b1b38ca36a79eccfeb","price_changes":[{"asset_id":"41448400836309843603620980831210604935021861034693225347475867885462478926555","best_ask":"0.09","best_bid":"0.08","hash":"ae58d4c4f7279a752888ea1fb158656f99dfa9af","price":"0.05","side":"BUY","size":"670.21"},{"asset_id":"24254094493625419915756280046002869097156693848522361803041977572204227262166","best_ask":"0.92","best_bid":"0.91","hash":"9668fba8e9afa3a7ced9bcdd5a691fb0dd7638a9","price":"0.95","side":"SELL","size":"670.21"}],"timestamp":"1785122864176"},"payload_hash":"f723bd0198b49514684144d78dc16f9c5c863181e7c959598d85f6f1bd9fa1f4","raw_frame":"{\"market\":\"0x717c0e8ccd4d5c7040185188fbae28be901ca589a11a94b1b38ca36a79eccfeb\", \"price_changes\":[{\"asset_id\":\"41448400836309843603620980831210604935021861034693225347475867885462478926555\", \"price\":\"0.05\", \"size\":\"670.21\", \"side\":\"BUY\", \"hash\":\"ae58d4c4f7279a752888ea1fb158656f99dfa9af\", \"best_bid\":\"0.08\", \"best_ask\":\"0.09\"}, {\"asset_id\":\"24254094493625419915756280046002869097156693848522361803041977572204227262166\", \"price\":\"0.95\", \"size\":\"670.21\", \"side\":\"SELL\", \"hash\":\"9668fba8e9afa3a7ced9bcdd5a691fb0dd7638a9\", \"best_bid\":\"0.91\", \"best_ask\":\"0.92\"}], \"timestamp\":\"1785122864176\", \"event_type\":\"price_change\"}","received_at":"2026-07-27T03:27:44.053099Z","schema_version":"clob-market-ws.price_change.v1","sequence":null,"server_hash":null,"server_timestamp":"1785122864176","session_id":"dd162b8dca5f43ff811d304e69a06123","source":"clob_market_ws"},"received_at":"2026-07-27T03:27:44.053099Z","record_id":"9e20c431a57fec293a52f6cf346b10e7c51b2645816d34aedfc0185df7151e54","schema_fingerprint":"4aa3821a28b0b7c2400bc59aba4bcc0a76e971dadd19610d3ad38c768e124dc7","schema_version":"edge-lab-recorder.raw.v1","sequence":null,"source":"clob_market_ws"}
{"event_at":"2026-07-27T03:27:44.178000Z","event_fingerprint":"f5616f15ef2d3b76d91b95e0d04a12cd9fd9b8fc1f21c8aaeb6dc423c5f8b117","payload":{"connection_id":"c7dc2e4762f849c6b6f9306b6518dcab","event_at":"2026-07-27T03:27:44.178000Z","event_type":"price_change","frame_hash":"966c530ed81921e87e2d6d98921ffdcae9c52ae1ae359efe796c02feee6317a6","frame_index":0,"kind":"data","monotonic_ns":224847418622333,"payload":{"event_type":"price_change","market":"0x717c0e8ccd4d5c7040185188fbae28be901ca589a11a94b1b38ca36a79eccfeb","price_changes":[{"asset_id":"24254094493625419915756280046002869097156693848522361803041977572204227262166","best_ask":"0.92","best_bid":"0.91","hash":"3d406da576ae96fa1dee35b6233131c00f43f227","price":"0.79","side":"BUY","size":"108"},{"asset_id":"41448400836309843603620980831210604935021861034693225347475867885462478926555","best_ask":"0.09","best_bid":"0.08","hash":"6009ef51819c2ddcebaa9056f969b1d4b6f68149","price":"0.21","side":"SELL","size":"108"}],"timestamp":"1785122864178"},"payload_hash":"712f7f7aeb2d5936c0e808bb4808cc8eb03a48be6abe540ecd39192ef24b07eb","raw_frame":"{\"market\":\"0x717c0e8ccd4d5c7040185188fbae28be901ca589a11a94b1b38ca36a79eccfeb\", \"price_changes\":[{\"asset_id\":\"24254094493625419915756280046002869097156693848522361803041977572204227262166\", \"price\":\"0.79\", \"size\":\"108\", \"side\":\"BUY\", \"hash\":\"3d406da576ae96fa1dee35b6233131c00f43f227\", \"best_bid\":\"0.91\", \"best_ask\":\"0.92\"}, {\"asset_id\":\"41448400836309843603620980831210604935021861034693225347475867885462478926555\", \"price\":\"0.21\", \"size\":\"108\", \"side\":\"SELL\", \"hash\":\"6009ef51819c2ddcebaa9056f969b1d4b6f68149\", \"best_bid\":\"0.08\", \"best_ask\":\"0.09\"}], \"timestamp\":\"1785122864178\", \"event_type\":\"price_change\"}","received_at":"2026-07-27T03:27:44.057131Z","schema_version":"clob-market-ws.price_change.v1","sequence":null,"server_hash":null,"server_timestamp":"1785122864178","session_id":"dd162b8dca5f43ff811d304e69a06123","source":"clob_market_ws"},"received_at":"2026-07-27T03:27:44.057131Z","record_id":"b65d5a9cff3687e7be08bd39c2bc7629616a3dba9bdc04a20987bbbbeb2db56e","schema_fingerprint":"4aa3821a28b0b7c2400bc59aba4bcc0a76e971dadd19610d3ad38c768e124dc7","schema_version":"edge-lab-recorder.raw.v1","sequence":null,"source":"clob_market_ws"}
{"event_at":"2026-07-27T03:27:44.185000Z","event_fingerprint":"acd9e5c1f4a8580c1bb885060ab64dd4852d9661773f38edd30d42d615534fa9","payload":{"connection_id":"c7dc2e4762f849c6b6f9306b6518dcab","event_at":"2026-07-27T03:27:44.185000Z","event_type":"price_change","frame_hash":"f1a03e47f4d575bfa81642607ec0c5424e200a06aba6616d65d476dbdb3c6ab2","frame_index":0,"kind":"data","monotonic_ns":224847423218666,"payload":{"event_type":"price_change","market":"0x717c0e8ccd4d5c7040185188fbae28be901ca589a11a94b1b38ca36a79eccfeb","price_changes":[{"asset_id":"24254094493625419915756280046002869097156693848522361803041977572204227262166","best_ask":"0.92","best_bid":"0.91","hash":"0e93f3c55d62756bfd7d1648203d3c8ac853ed6c","price":"0.85","side":"BUY","size":"130"},{"asset_id":"41448400836309843603620980831210604935021861034693225347475867885462478926555","best_ask":"0.09","best_bid":"0.08","hash":"85b20a715101ef0ee0434210cde2e98552d8c9e9","price":"0.15","side":"SELL","size":"130"}],"timestamp":"1785122864185"},"payload_hash":"21847ccfc1c186e1684b6896562153afd0d4df4f41cbe1a48cc07457da3128bc","raw_frame":"{\"market\":\"0x717c0e8ccd4d5c7040185188fbae28be901ca589a11a94b1b38ca36a79eccfeb\", \"price_changes\":[{\"asset_id\":\"24254094493625419915756280046002869097156693848522361803041977572204227262166\", \"price\":\"0.85\", \"size\":\"130\", \"side\":\"BUY\", \"hash\":\"0e93f3c55d62756bfd7d1648203d3c8ac853ed6c\", \"best_bid\":\"0.91\", \"best_ask\":\"0.92\"}, {\"asset_id\":\"41448400836309843603620980831210604935021861034693225347475867885462478926555\", \"price\":\"0.15\", \"size\":\"130\", \"side\":\"SELL\", \"hash\":\"85b20a715101ef0ee0434210cde2e98552d8c9e9\", \"best_bid\":\"0.08\", \"best_ask\":\"0.09\"}], \"timestamp\":\"1785122864185\", \"event_type\":\"price_change\"}","received_at":"2026-07-27T03:27:44.061726Z","schema_version":"clob-market-ws.price_change.v1","sequence":null,"server_hash":null,"server_timestamp":"1785122864185","session_id":"dd162b8dca5f43ff811d304e69a06123","source":"clob_market_ws"},"received_at":"2026-07-27T03:27:44.061726Z","record_id":"ed3956d1b1ae62989c16081562a89836e5c44852346c959e754132e3ade84231","schema_fingerprint":"4aa3821a28b0b7c2400bc59aba4bcc0a76e971dadd19610d3ad38c768e124dc7","schema_version":"edge-lab-recorder.raw.v1","sequence":null,"source":"clob_market_ws"}
{"event_at":"2026-07-27T03:27:44.186000Z","event_fingerprint":"c3ed2a48f3b9a9587f6646215fb95d5be94d683e08e6167f6e47bf3aa4284733","payload":{"connection_id":"c7dc2e4762f849c6b6f9306b6518dcab","event_at":"2026-07-27T03:27:44.186000Z","event_type":"price_change","frame_hash":"eee6ef30da785124e0a29c3fe670320446e6391ee00b11d69ae7494e56d3c897","frame_index":0,"kind":"data","monotonic_ns":224847426622833,"payload":{"event_type":"price_change","market":"0x717c0e8ccd4d5c7040185188fbae28be901ca589a11a94b1b38ca36a79eccfeb","price_changes":[{"asset_id":"41448400836309843603620980831210604935021861034693225347475867885462478926555","best_ask":"0.09","best_bid":"0.08","hash":"3a0d8664c8a45725506752ef43d52a6996510896","price":"0.06","side":"BUY","size":"64.22"},{"asset_id":"24254094493625419915756280046002869097156693848522361803041977572204227262166","best_ask":"0.92","best_bid":"0.91","hash":"1a5fbeed4c1f14c952989293cd5c8447651f5597","price":"0.94","side":"SELL","size":"64.22"}],"timestamp":"1785122864186"},"payload_hash":"c1e9c965a03247163da0bf4ac9efb1c1a1c12218d082be819c6ea3f86452d186","raw_frame":"{\"market\":\"0x717c0e8ccd4d5c7040185188fbae28be901ca589a11a94b1b38ca36a79eccfeb\", \"price_changes\":[{\"asset_id\":\"41448400836309843603620980831210604935021861034693225347475867885462478926555\", \"price\":\"0.06\", \"size\":\"64.22\", \"side\":\"BUY\", \"hash\":\"3a0d8664c8a45725506752ef43d52a6996510896\", \"best_bid\":\"0.08\", \"best_ask\":\"0.09\"}, {\"asset_id\":\"24254094493625419915756280046002869097156693848522361803041977572204227262166\", \"price\":\"0.94\", \"size\":\"64.22\", \"side\":\"SELL\", \"hash\":\"1a5fbeed4c1f14c952989293cd5c8447651f5597\", \"best_bid\":\"0.91\", \"best_ask\":\"0.92\"}], \"timestamp\":\"1785122864186\", \"event_type\":\"price_change\"}","received_at":"2026-07-27T03:27:44.065127Z","schema_version":"clob-market-ws.price_change.v1","sequence":null,"server_hash":null,"server_timestamp":"1785122864186","session_id":"dd162b8dca5f43ff811d304e69a06123","source":"clob_market_ws"},"received_at":"2026-07-27T03:27:44.065127Z","record_id":"c91c4348272dd0f0780ea32cf1d19c6b98233b064f93ad606d79604a0e0bf95b","schema_fingerprint":"4aa3821a28b0b7c2400bc59aba4bcc0a76e971dadd19610d3ad38c768e124dc7","schema_version":"edge-lab-recorder.raw.v1","sequence":null,"source":"clob_market_ws"}
{"event_at":"2026-07-27T03:27:44.203000Z","event_fingerprint":"fd11ad3ec63cbd2c6f281042335d34b19cc7419abb18be54aeca02fb0f46479d","payload":{"connection_id":"c7dc2e4762f849c6b6f9306b6518dcab","event_at":"2026-07-27T03:27:44.203000Z","event_type":"price_change","frame_hash":"a04a166dfe291d473e29545a4ab6c9f3cad79afafe752569339e01688c78dc00","frame_index":0,"kind":"data","monotonic_ns":224847443638958,"payload":{"event_type":"price_change","market":"0x717c0e8ccd4d5c7040185188fbae28be901ca589a11a94b1b38ca36a79eccfeb","price_changes":[{"asset_id":"24254094493625419915756280046002869097156693848522361803041977572204227262166","best_ask":"0.92","best_bid":"0.91","hash":"7c822c491c462b48a1d5a95e94a7d8268eec046d","price":"0.03","side":"BUY","size":"510"},{"asset_id":"41448400836309843603620980831210604935021861034693225347475867885462478926555","best_ask":"0.09","best_bid":"0.08","hash":"d5fce3b9dcc7c6e9bf9a7506db0403eb797c1639","price":"0.97","side":"SELL","size":"510"}],"timestamp":"1785122864203"},"payload_hash":"7af432738d706207c3c3a13e14f5875c18dcf801a8630387831eb1ae07829857","raw_frame":"{\"market\":\"0x717c0e8ccd4d5c7040185188fbae28be901ca589a11a94b1b38ca36a79eccfeb\", \"price_changes\":[{\"asset_id\":\"24254094493625419915756280046002869097156693848522361803041977572204227262166\", \"price\":\"0.03\", \"size\":\"510\", \"side\":\"BUY\", \"hash\":\"7c822c491c462b48a1d5a95e94a7d8268eec046d\", \"best_bid\":\"0.91\", \"best_ask\":\"0.92\"}, {\"asset_id\":\"41448400836309843603620980831210604935021861034693225347475867885462478926555\", \"price\":\"0.97\", \"size\":\"510\", \"side\":\"SELL\", \"hash\":\"d5fce3b9dcc7c6e9bf9a7506db0403eb797c1639\", \"best_bid\":\"0.08\", \"best_ask\":\"0.09\"}], \"timestamp\":\"1785122864203\", \"event_type\":\"price_change\"}","received_at":"2026-07-27T03:27:44.082145Z","schema_version":"clob-market-ws.price_change.v1","sequence":null,"server_hash":null,"server_timestamp":"1785122864203","session_id":"dd162b8dca5f43ff811d304e69a06123","source":"clob_market_ws"},"received_at":"2026-07-27T03:27:44.082145Z","record_id":"03aaecb9d17c6d8cbf28fffa82865886cf5dc15a4925d7d161a3f654f3af7ce6","schema_fingerprint":"4aa3821a28b0b7c2400bc59aba4bcc0a76e971dadd19610d3ad38c768e124dc7","schema_version":"edge-lab-recorder.raw.v1","sequence":null,"source":"clob_market_ws"}
{"event_at":"2026-07-27T03:27:44.207000Z","event_fingerprint":"734ae2af07fdeba4f65be3a4d95b325419c652477ea3faf11e5ec5018ca5d449","payload":{"connection_id":"c7dc2e4762f849c6b6f9306b6518dcab","event_at":"2026-07-27T03:27:44.207000Z","event_type":"price_change","frame_hash":"0ec75d1eea6e108bfced7b8740e98d6250ba8c624f0b3fd4a6f6b85abc4560e7","frame_index":0,"kind":"data","monotonic_ns":224847448069250,"payload":{"event_type":"price_change","market":"0x717c0e8ccd4d5c7040185188fbae28be901ca589a11a94b1b38ca36a79eccfeb","price_changes":[{"asset_id":"41448400836309843603620980831210604935021861034693225347475867885462478926555","best_ask":"0.09","best_bid":"0.08","hash":"ab40879fb2f2d1968c9f11412a73848ece51a735","price":"0.07","side":"BUY","size":"55.16"},{"asset_id":"24254094493625419915756280046002869097156693848522361803041977572204227262166","best_ask":"0.92","best_bid":"0.91","hash":"46f227d5161923ad75635aab3c3806e74d6c679f","price":"0.93","side":"SELL","size":"55.16"}],"timestamp":"1785122864207"},"payload_hash":"1f4033ad6947f19830f2d371b625cec35b7c60e0cce27dfa468e3322b87613ff","raw_frame":"{\"market\":\"0x717c0e8ccd4d5c7040185188fbae28be901ca589a11a94b1b38ca36a79eccfeb\", \"price_changes\":[{\"asset_id\":\"41448400836309843603620980831210604935021861034693225347475867885462478926555\", \"price\":\"0.07\", \"size\":\"55.16\", \"side\":\"BUY\", \"hash\":\"ab40879fb2f2d1968c9f11412a73848ece51a735\", \"best_bid\":\"0.08\", \"best_ask\":\"0.09\"}, {\"asset_id\":\"24254094493625419915756280046002869097156693848522361803041977572204227262166\", \"price\":\"0.93\", \"size\":\"55.16\", \"side\":\"SELL\", \"hash\":\"46f227d5161923ad75635aab3c3806e74d6c679f\", \"best_bid\":\"0.91\", \"best_ask\":\"0.92\"}], \"timestamp\":\"1785122864207\", \"event_type\":\"price_change\"}","received_at":"2026-07-27T03:27:44.086575Z","schema_version":"clob-market-ws.price_change.v1","sequence":null,"server_hash":null,"server_timestamp":"1785122864207","session_id":"dd162b8dca5f43ff811d304e69a06123","source":"clob_market_ws"},"received_at":"2026-07-27T03:27:44.086575Z","record_id":"939f46394a8ea51d41a1ecf94f985fd0df26de0e514406bc4470b1769f7ead10","schema_fingerprint":"4aa3821a28b0b7c2400bc59aba4bcc0a76e971dadd19610d3ad38c768e124dc7","schema_version":"edge-lab-recorder.raw.v1","sequence":null,"source":"clob_market_ws"}
{"event_at":"2026-07-27T03:27:44.207000Z","event_fingerprint":"7f0a7ed55cc96c48eb3cf578e4e37a6758021ee34d573dff459b8c4ce5328e0a","payload":{"connection_id":"c7dc2e4762f849c6b6f9306b6518dcab","event_at":"2026-07-27T03:27:44.207000Z","event_type":"price_change","frame_hash":"c2ceb7d14561fe4191db7c85cbe8c36c1d1c4f7ced5b25417f8b6408ff78d8ec","frame_index":0,"kind":"data","monotonic_ns":224847451420625,"payload":{"event_type":"price_change","market":"0x717c0e8ccd4d5c7040185188fbae28be901ca589a11a94b1b38ca36a79eccfeb","price_changes":[{"asset_id":"24254094493625419915756280046002869097156693848522361803041977572204227262166","best_ask":"0.92","best_bid":"0.91","hash":"82634d0c698df1d3506efeaeab1d4b99e8c463ed","price":"0.84","side":"BUY","size":"112.43"},{"asset_id":"41448400836309843603620980831210604935021861034693225347475867885462478926555","best_ask":"0.09","best_bid":"0.08","hash":"9e93352e7ad33b8eecb536a2a52f6d7f79a1fb07","price":"0.16","side":"SELL","size":"112.43"}],"timestamp":"1785122864207"},"payload_hash":"cdeeb3c8b919ca811c0a64615eae1e0190cad40fdd2bc9f4c2e0b030e0af537a","raw_frame":"{\"market\":\"0x717c0e8ccd4d5c7040185188fbae28be901ca589a11a94b1b38ca36a79eccfeb\", \"price_changes\":[{\"asset_id\":\"24254094493625419915756280046002869097156693848522361803041977572204227262166\", \"price\":\"0.84\", \"size\":\"112.43\", \"side\":\"BUY\", \"hash\":\"82634d0c698df1d3506efeaeab1d4b99e8c463ed\", \"best_bid\":\"0.91\", \"best_ask\":\"0.92\"}, {\"asset_id\":\"41448400836309843603620980831210604935021861034693225347475867885462478926555\", \"price\":\"0.16\", \"size\":\"112.43\", \"side\":\"SELL\", \"hash\":\"9e93352e7ad33b8eecb536a2a52f6d7f79a1fb07\", \"best_bid\":\"0.08\", \"best_ask\":\"0.09\"}], \"timestamp\":\"1785122864207\", \"event_type\":\"price_change\"}","received_at":"2026-07-27T03:27:44.089928Z","schema_version":"clob-market-ws.price_change.v1","sequence":null,"server_hash":null,"server_timestamp":"1785122864207","session_id":"dd162b8dca5f43ff811d304e69a06123","source":"clob_market_ws"},"received_at":"2026-07-27T03:27:44.089928Z","record_id":"127081d217a62b3f72a0cf7bdef708ff9e2a37298c257e71bf09c542d6b62c9c","schema_fingerprint":"4aa3821a28b0b7c2400bc59aba4bcc0a76e971dadd19610d3ad38c768e124dc7","schema_version":"edge-lab-recorder.raw.v1","sequence":null,"source":"clob_market_ws"}
{"event_at":"2026-07-27T03:27:44.251000Z","event_fingerprint":"48389a007cd53aa44f2e99c830e7d78bb54a9cdd7ce721f64f4f51eda30601b5","payload":{"connection_id":"c7dc2e4762f849c6b6f9306b6518dcab","event_at":"2026-07-27T03:27:44.251000Z","event_type":"price_change","frame_hash":"03561550fd2efac1244424785077155d60b16eb460df3e51c3338050baee4cb6","frame_index":0,"kind":"data","monotonic_ns":224847484340541,"payload":{"event_type":"price_change","market":"0x717c0e8ccd4d5c7040185188fbae28be901ca589a11a94b1b38ca36a79eccfeb","price_changes":[{"asset_id":"24254094493625419915756280046002869097156693848522361803041977572204227262166","best_ask":"0.92","best_bid":"0.91","hash":"369d12715116db0966611153c4339fcacf1d317a","price":"0.57","side":"BUY","size":"119.94"},{"asset_id":"41448400836309843603620980831210604935021861034693225347475867885462478926555","best_ask":"0.09","best_bid":"0.08","hash":"8d3b3f231b648fce0d56bcfdabd8a09e263af83f","price":"0.43","side":"SELL","size":"119.94"}],"timestamp":"1785122864251"},"payload_hash":"b79836e2a2b40c1f2fae0f3fc4453f0021db67c0edd3a35335c0da362624a7f4","raw_frame":"{\"market\":\"0x717c0e8ccd4d5c7040185188fbae28be901ca589a11a94b1b38ca36a79eccfeb\", \"price_changes\":[{\"asset_id\":\"24254094493625419915756280046002869097156693848522361803041977572204227262166\", \"price\":\"0.57\", \"size\":\"119.94\", \"side\":\"BUY\", \"hash\":\"369d12715116db0966611153c4339fcacf1d317a\", \"best_bid\":\"0.91\", \"best_ask\":\"0.92\"}, {\"asset_id\":\"41448400836309843603620980831210604935021861034693225347475867885462478926555\", \"price\":\"0.43\", \"size\":\"119.94\", \"side\":\"SELL\", \"hash\":\"8d3b3f231b648fce0d56bcfdabd8a09e263af83f\", \"best_bid\":\"0.08\", \"best_ask\":\"0.09\"}], \"timestamp\":\"1785122864251\", \"event_type\":\"price_change\"}","received_at":"2026-07-27T03:27:44.122847Z","schema_version":"clob-market-ws.price_change.v1","sequence":null,"server_hash":null,"server_timestamp":"1785122864251","session_id":"dd162b8dca5f43ff811d304e69a06123","source":"clob_market_ws"},"received_at":"2026-07-27T03:27:44.122847Z","record_id":"394585e000fdbc0e293b350a5e7de75b6deca4ac25fe7c9249845132e9244d8b","schema_fingerprint":"4aa3821a28b0b7c2400bc59aba4bcc0a76e971dadd19610d3ad38c768e124dc7","schema_version":"edge-lab-recorder.raw.v1","sequence":null,"source":"clob_market_ws"}
{"event_at":"2026-07-27T03:27:44.253000Z","event_fingerprint":"26cce5efaa719f585abb5f3fd34dec6e0cbba5376b167fb45daf49c2987c8b35","payload":{"connection_id":"c7dc2e4762f849c6b6f9306b6518dcab","event_at":"2026-07-27T03:27:44.253000Z","event_type":"price_change","frame_hash":"4558c93fa65b031b56efe5daadc271c35a976c5c3b082d8d457bcde07b292230","frame_index":0,"kind":"data","monotonic_ns":224847509454500,"payload":{"event_type":"price_change","market":"0x717c0e8ccd4d5c7040185188fbae28be901ca589a11a94b1b38ca36a79eccfeb","price_changes":[{"asset_id":"41448400836309843603620980831210604935021861034693225347475867885462478926555","best_ask":"0.09","best_bid":"0.08","hash":"aff12257e5b8b11117f1da58c824fe549af1d5dc","price":"0.03","side":"BUY","size":"1527"},{"asset_id":"24254094493625419915756280046002869097156693848522361803041977572204227262166","best_ask":"0.92","best_bid":"0.91","hash":"e3ae9eee53566d88ee5189bb2d1095f5d09da735","price":"0.97","side":"SELL","size":"1527"}],"timestamp":"1785122864253"},"payload_hash":"5ade37838b0cb64f936ebd169c8fbc760f73f38f9e1fa783c2b93e00045d4602","raw_frame":"{\"market\":\"0x717c0e8ccd4d5c7040185188fbae28be901ca589a11a94b1b38ca36a79eccfeb\", \"price_changes\":[{\"asset_id\":\"41448400836309843603620980831210604935021861034693225347475867885462478926555\", \"price\":\"0.03\", \"size\":\"1527\", \"side\":\"BUY\", \"hash\":\"aff12257e5b8b11117f1da58c824fe549af1d5dc\", \"best_bid\":\"0.08\", \"best_ask\":\"0.09\"}, {\"asset_id\":\"24254094493625419915756280046002869097156693848522361803041977572204227262166\", \"price\":\"0.97\", \"size\":\"1527\", \"side\":\"SELL\", \"hash\":\"e3ae9eee53566d88ee5189bb2d1095f5d09da735\", \"best_bid\":\"0.91\", \"best_ask\":\"0.92\"}], \"timestamp\":\"1785122864253\", \"event_type\":\"price_change\"}","received_at":"2026-07-27T03:27:44.147957Z","schema_version":"clob-market-ws.price_change.v1","sequence":null,"server_hash":null,"server_timestamp":"1785122864253","session_id":"dd162b8dca5f43ff811d304e69a06123","source":"clob_market_ws"},"received_at":"2026-07-27T03:27:44.147957Z","record_id":"aea1971e857cd3e0dc3ac044fdce5a53593c2917200c59078c7a77033348f26d","schema_fingerprint":"4aa3821a28b0b7c2400bc59aba4bcc0a76e971dadd19610d3ad38c768e124dc7","schema_version":"edge-lab-recorder.raw.v1","sequence":null,"source":"clob_market_ws"}
{"event_at":"2026-07-27T03:27:44.273000Z","event_fingerprint":"26ba926dc8722cf0804b10c3a15b05277bf9cd3a372ce304f9b02ec9a7c94f6f","payload":{"connection_id":"c7dc2e4762f849c6b6f9306b6518dcab","event_at":"2026-07-27T03:27:44.273000Z","event_type":"price_change","frame_hash":"86ce584d3c3b7031537db86dbc1e81e8ccc1f6ef5cd09d7ef2d0e9611263c415","frame_index":0,"kind":"data","monotonic_ns":224847512860125,"payload":{"event_type":"price_change","market":"0x717c0e8ccd4d5c7040185188fbae28be901ca589a11a94b1b38ca36a79eccfeb","price_changes":[{"asset_id":"24254094493625419915756280046002869097156693848522361803041977572204227262166","best_ask":"0.92","best_bid":"0.91","hash":"4e8ca78deef0e39161764ec1010850f1ac9c18b3","price":"0.86","side":"BUY","size":"150"},{"asset_id":"41448400836309843603620980831210604935021861034693225347475867885462478926555","best_ask":"0.09","best_bid":"0.08","hash":"e382bfd61476c50f79b5571c3f5cc5a55dc83715","price":"0.14","side":"SELL","size":"150"}],"timestamp":"1785122864273"},"payload_hash":"5f1984e1833e241dee590a00fef188674693de4434a175a1a8dfdb6d40f10b99","raw_frame":"{\"market\":\"0x717c0e8ccd4d5c7040185188fbae28be901ca589a11a94b1b38ca36a79eccfeb\", \"price_changes\":[{\"asset_id\":\"24254094493625419915756280046002869097156693848522361803041977572204227262166\", \"price\":\"0.86\", \"size\":\"150\", \"side\":\"BUY\", \"hash\":\"4e8ca78deef0e39161764ec1010850f1ac9c18b3\", \"best_bid\":\"0.91\", \"best_ask\":\"0.92\"}, {\"asset_id\":\"41448400836309843603620980831210604935021861034693225347475867885462478926555\", \"price\":\"0.14\", \"size\":\"150\", \"side\":\"SELL\", \"hash\":\"e382bfd61476c50f79b5571c3f5cc5a55dc83715\", \"best_bid\":\"0.08\", \"best_ask\":\"0.09\"}], \"timestamp\":\"1785122864273\", \"event_type\":\"price_change\"}","received_at":"2026-07-27T03:27:44.151366Z","schema_version":"clob-market-ws.price_change.v1","sequence":null,"server_hash":null,"server_timestamp":"1785122864273","session_id":"dd162b8dca5f43ff811d304e69a06123","source":"clob_market_ws"},"received_at":"2026-07-27T03:27:44.151366Z","record_id":"c21f3d9ff535c668e5718ecd229a9c86e7eef9559ddd8df0eafaecbd5b339ad7","schema_fingerprint":"4aa3821a28b0b7c2400bc59aba4bcc0a76e971dadd19610d3ad38c768e124dc7","schema_version":"edge-lab-recorder.raw.v1","sequence":null,"source":"clob_market_ws"}
{"event_at":"2026-07-27T03:27:44.278000Z","event_fingerprint":"2982a8ae1bda2ee10b2b789cb537778e4e8944a03f601a63b5b9f2eedc7f33e9","payload":{"connection_id":"c7dc2e4762f849c6b6f9306b6518dcab","event_at":"2026-07-27T03:27:44.278000Z","event_type":"price_change","frame_hash":"afe893ce3739561fb90990c085503a699b9ad311244aa60575c071fc283ba128","frame_index":0,"kind":"data","monotonic_ns":224847516410791,"payload":{"event_type":"price_change","market":"0x717c0e8ccd4d5c7040185188fbae28be901ca589a11a94b1b38ca36a79eccfeb","price_changes":[{"asset_id":"24254094493625419915756280046002869097156693848522361803041977572204227262166","best_ask":"0.92","best_bid":"0.91","hash":"267de7e851afd1bc9e3e9029645c2f567e9ec441","price":"0.02","side":"BUY","size":"535"},{"asset_id":"41448400836309843603620980831210604935021861034693225347475867885462478926555","best_ask":"0.09","best_bid":"0.08","hash":"8bc7f95b78f17cb48005888e5ea263f316bbc25a","price":"0.98","side":"SELL","size":"535"}],"timestamp":"1785122864278"},"payload_hash":"9da07f81f5f373fa7a4577f42d4ec049e52af921579d149b38c7b8a2c0df85d8","raw_frame":"{\"market\":\"0x717c0e8ccd4d5c7040185188fbae28be901ca589a11a94b1b38ca36a79eccfeb\", \"price_changes\":[{\"asset_id\":\"24254094493625419915756280046002869097156693848522361803041977572204227262166\", \"price\":\"0.02\", \"size\":\"535\", \"side\":\"BUY\", \"hash\":\"267de7e851afd1bc9e3e9029645c2f567e9ec441\", \"best_bid\":\"0.91\", \"best_ask\":\"0.92\"}, {\"asset_id\":\"41448400836309843603620980831210604935021861034693225347475867885462478926555\", \"price\":\"0.98\", \"size\":\"535\", \"side\":\"SELL\", \"hash\":\"8bc7f95b78f17cb48005888e5ea263f316bbc25a\", \"best_bid\":\"0.08\", \"best_ask\":\"0.09\"}], \"timestamp\":\"1785122864278\", \"event_type\":\"price_change\"}","received_at":"2026-07-27T03:27:44.154916Z","schema_version":"clob-market-ws.price_change.v1","sequence":null,"server_hash":null,"server_timestamp":"1785122864278","session_id":"dd162b8dca5f43ff811d304e69a06123","source":"clob_market_ws"},"received_at":"2026-07-27T03:27:44.154916Z","record_id":"34a52f8ad8d103159a4f872c24430e6830c9ad93a8d91b7c8af833c2900a7f24","schema_fingerprint":"4aa3821a28b0b7c2400bc59aba4bcc0a76e971dadd19610d3ad38c768e124dc7","schema_version":"edge-lab-recorder.raw.v1","sequence":null,"source":"clob_market_ws"}
{"event_at":"2026-07-27T03:27:44.291000Z","event_fingerprint":"bb7bb735c152127bd818f542c951803864a4fabb009000400a091b02890cf4d3","payload":{"connection_id":"c7dc2e4762f849c6b6f9306b6518dcab","event_at":"2026-07-27T03:27:44.291000Z","event_type":"price_change","frame_hash":"959ca1064490800b75e8f99e6c1df784d86226ab62a5ae1a9cb1165317a43ba6","frame_index":0,"kind":"data","monotonic_ns":224847527494083,"payload":{"event_type":"price_change","market":"0x717c0e8ccd4d5c7040185188fbae28be901ca589a11a94b1b38ca36a79eccfeb","price_changes":[{"asset_id":"24254094493625419915756280046002869097156693848522361803041977572204227262166","best_ask":"0.92","best_bid":"0.91","hash":"8c02b5a1a30631fadd558b68ccc8e16c573db4c2","price":"0.8","side":"BUY","size":"105"},{"asset_id":"41448400836309843603620980831210604935021861034693225347475867885462478926555","best_ask":"0.09","best_bid":"0.08","hash":"ddd607faffb88d8a8d89ee42a49a10b01da7dc69","price":"0.2","side":"SELL","size":"105"}],"timestamp":"1785122864291"},"payload_hash":"ca63d3890c527592bdbf6910850370d975830e784f4ce357e6e3cc333f01b137","raw_frame":"{\"market\":\"0x717c0e8ccd4d5c7040185188fbae28be901ca589a11a94b1b38ca36a79eccfeb\", \"price_changes\":[{\"asset_id\":\"24254094493625419915756280046002869097156693848522361803041977572204227262166\", \"price\":\"0.8\", \"size\":\"105\", \"side\":\"BUY\", \"hash\":\"8c02b5a1a30631fadd558b68ccc8e16c573db4c2\", \"best_bid\":\"0.91\", \"best_ask\":\"0.92\"}, {\"asset_id\":\"41448400836309843603620980831210604935021861034693225347475867885462478926555\", \"price\":\"0.2\", \"size\":\"105\", \"side\":\"SELL\", \"hash\":\"ddd607faffb88d8a8d89ee42a49a10b01da7dc69\", \"best_bid\":\"0.08\", \"best_ask\":\"0.09\"}], \"timestamp\":\"1785122864291\", \"event_type\":\"price_change\"}","received_at":"2026-07-27T03:27:44.165999Z","schema_version":"clob-market-ws.price_change.v1","sequence":null,"server_hash":null,"server_timestamp":"1785122864291","session_id":"dd162b8dca5f43ff811d304e69a06123","source":"clob_market_ws"},"received_at":"2026-07-27T03:27:44.165999Z","record_id":"a4f307e42b317e0efe37943794926d9305e654b388242352a91619a4662a115d","schema_fingerprint":"4aa3821a28b0b7c2400bc59aba4bcc0a76e971dadd19610d3ad38c768e124dc7","schema_version":"edge-lab-recorder.raw.v1","sequence":null,"source":"clob_market_ws"}
{"event_at":"2026-07-27T03:27:44.297000Z","event_fingerprint":"d76f73565886f19c11c83cbe10889d4a69374a3134080520cc1c24caf6b26980","payload":{"connection_id":"c7dc2e4762f849c6b6f9306b6518dcab","event_at":"2026-07-27T03:27:44.297000Z","event_type":"price_change","frame_hash":"115dc94f65da6e055078bd7bd9be893fc06267b571ffab96bf31a35a958e8ae5","frame_index":0,"kind":"data","monotonic_ns":224847532579583,"payload":{"event_type":"price_change","market":"0x717c0e8ccd4d5c7040185188fbae28be901ca589a11a94b1b38ca36a79eccfeb","price_changes":[{"asset_id":"41448400836309843603620980831210604935021861034693225347475867885462478926555","best_ask":"0.09","best_bid":"0.08","hash":"39b09a04ee39f612c8cb5d484cf41e56163ec088","price":"0.12","side":"SELL","size":"344.55"},{"asset_id":"24254094493625419915756280046002869097156693848522361803041977572204227262166","best_ask":"0.92","best_bid":"0.91","hash":"17b4b86ad4234fb05af1b51e4046f19a7e3cfc87","price":"0.88","side":"BUY","size":"344.55"}],"timestamp":"1785122864297"},"payload_hash":"c4909c0677f253f20d0aa1ab457fcaf501a883fc6ce1a033a3ddd0f1dceec5e2","raw_frame":"{\"market\":\"0x717c0e8ccd4d5c7040185188fbae28be901ca589a11a94b1b38ca36a79eccfeb\", \"price_changes\":[{\"asset_id\":\"41448400836309843603620980831210604935021861034693225347475867885462478926555\", \"price\":\"0.12\", \"size\":\"344.55\", \"side\":\"SELL\", \"hash\":\"39b09a04ee39f612c8cb5d484cf41e56163ec088\", \"best_bid\":\"0.08\", \"best_ask\":\"0.09\"}, {\"asset_id\":\"24254094493625419915756280046002869097156693848522361803041977572204227262166\", \"price\":\"0.88\", \"size\":\"344.55\", \"side\":\"BUY\", \"hash\":\"17b4b86ad4234fb05af1b51e4046f19a7e3cfc87\", \"best_bid\":\"0.91\", \"best_ask\":\"0.92\"}], \"timestamp\":\"1785122864297\", \"event_type\":\"price_change\"}","received_at":"2026-07-27T03:27:44.171077Z","schema_version":"clob-market-ws.price_change.v1","sequence":null,"server_hash":null,"server_timestamp":"1785122864297","session_id":"dd162b8dca5f43ff811d304e69a06123","source":"clob_market_ws"},"received_at":"2026-07-27T03:27:44.171077Z","record_id":"576a4a9eb2dce26602692d84a49add5a27e0295f64d5b852d49547919df1d7c1","schema_fingerprint":"4aa3821a28b0b7c2400bc59aba4bcc0a76e971dadd19610d3ad38c768e124dc7","schema_version":"edge-lab-recorder.raw.v1","sequence":null,"source":"clob_market_ws"}
{"event_at":"2026-07-27T03:27:44.318000Z","event_fingerprint":"53316655e0b556d73bd498c4742505c07fd57838af85684d93467bae6f2f2266","payload":{"connection_id":"c7dc2e4762f849c6b6f9306b6518dcab","event_at":"2026-07-27T03:27:44.318000Z","event_type":"price_change","frame_hash":"a6fd851e2274a8f6de8bc4c86b29c57e7555d4e356de1fa6c9e747ee46917289","frame_index":0,"kind":"data","monotonic_ns":224847559983958,"payload":{"event_type":"price_change","market":"0x717c0e8ccd4d5c7040185188fbae28be901ca589a11a94b1b38ca36a79eccfeb","price_changes":[{"asset_id":"24254094493625419915756280046002869097156693848522361803041977572204227262166","best_ask":"0.92","best_bid":"0.91","hash":"0e297b123b48f40d232b248056a67bbbe999efdb","price":"0.81","side":"BUY","size":"118"},{"asset_id":"41448400836309843603620980831210604935021861034693225347475867885462478926555","best_ask":"0.09","best_bid":"0.08","hash":"828939a6cfc1c5cabbdd4bace12c64de161225ab","price":"0.19","side":"SELL","size":"118"}],"timestamp":"1785122864318"},"payload_hash":"e30249db4848bd6edba612940daa150fa9d777936a940764b64876b4774d0c33","raw_frame":"{\"market\":\"0x717c0e8ccd4d5c7040185188fbae28be901ca589a11a94b1b38ca36a79eccfeb\", \"price_changes\":[{\"asset_id\":\"24254094493625419915756280046002869097156693848522361803041977572204227262166\", \"price\":\"0.81\", \"size\":\"118\", \"side\":\"BUY\", \"hash\":\"0e297b123b48f40d232b248056a67bbbe999efdb\", \"best_bid\":\"0.91\", \"best_ask\":\"0.92\"}, {\"asset_id\":\"41448400836309843603620980831210604935021861034693225347475867885462478926555\", \"price\":\"0.19\", \"size\":\"118\", \"side\":\"SELL\", \"hash\":\"828939a6cfc1c5cabbdd4bace12c64de161225ab\", \"best_bid\":\"0.08\", \"best_ask\":\"0.09\"}], \"timestamp\":\"1785122864318\", \"event_type\":\"price_change\"}","received_at":"2026-07-27T03:27:44.198483Z","schema_version":"clob-market-ws.price_change.v1","sequence":null,"server_hash":null,"server_timestamp":"1785122864318","session_id":"dd162b8dca5f43ff811d304e69a06123","source":"clob_market_ws"},"received_at":"2026-07-27T03:27:44.198483Z","record_id":"7a9a200a3d667d662ca945a4329fabe98d4c3b1b43a2cf93e652b4b8bee3675f","schema_fingerprint":"4aa3821a28b0b7c2400bc59aba4bcc0a76e971dadd19610d3ad38c768e124dc7","schema_version":"edge-lab-recorder.raw.v1","sequence":null,"source":"clob_market_ws"}
{"event_at":"2026-07-27T03:27:44.319000Z","event_fingerprint":"4103b1447cb7caa8db78e02bdc89ee17edc75279d8cca55741a0b55dd1e9749c","payload":{"connection_id":"c7dc2e4762f849c6b6f9306b6518dcab","event_at":"2026-07-27T03:27:44.319000Z","event_type":"price_change","frame_hash":"3ddf77efc4022b7f81adbd95e8b2a565b1b91da5b0545084b618fe01fdedc0db","frame_index":0,"kind":"data","monotonic_ns":224847563503666,"payload":{"event_type":"price_change","market":"0x717c0e8ccd4d5c7040185188fbae28be901ca589a11a94b1b38ca36a79eccfeb","price_changes":[{"asset_id":"24254094493625419915756280046002869097156693848522361803041977572204227262166","best_ask":"0.92","best_bid":"0.91","hash":"951be8e8564efa8a3f16eab8dc70857021082bdc","price":"0.68","side":"BUY","size":"11.97"},{"asset_id":"41448400836309843603620980831210604935021861034693225347475867885462478926555","best_ask":"0.09","best_bid":"0.08","hash":"59b5e82e662d90e149db656b868b2efe620aaca8","price":"0.32","side":"SELL","size":"11.97"}],"timestamp":"1785122864319"},"payload_hash":"f12fe222c59429c6aca0be42d5e4b6077ad7d5a27cd3ec56092aa03293b5cf33","raw_frame":"{\"market\":\"0x717c0e8ccd4d5c7040185188fbae28be901ca589a11a94b1b38ca36a79eccfeb\", \"price_changes\":[{\"asset_id\":\"24254094493625419915756280046002869097156693848522361803041977572204227262166\", \"price\":\"0.68\", \"size\":\"11.97\", \"side\":\"BUY\", \"hash\":\"951be8e8564efa8a3f16eab8dc70857021082bdc\", \"best_bid\":\"0.91\", \"best_ask\":\"0.92\"}, {\"asset_id\":\"41448400836309843603620980831210604935021861034693225347475867885462478926555\", \"price\":\"0.32\", \"size\":\"11.97\", \"side\":\"SELL\", \"hash\":\"59b5e82e662d90e149db656b868b2efe620aaca8\", \"best_bid\":\"0.08\", \"best_ask\":\"0.09\"}], \"timestamp\":\"1785122864319\", \"event_type\":\"price_change\"}","received_at":"2026-07-27T03:27:44.202009Z","schema_version":"clob-market-ws.price_change.v1","sequence":null,"server_hash":null,"server_timestamp":"1785122864319","session_id":"dd162b8dca5f43ff811d304e69a06123","source":"clob_market_ws"},"received_at":"2026-07-27T03:27:44.202009Z","record_id":"1861fdf64884574e5c56ab986cb28c719c672b75fc559585d22a9d4dd7167c98","schema_fingerprint":"4aa3821a28b0b7c2400bc59aba4bcc0a76e971dadd19610d3ad38c768e124dc7","schema_version":"edge-lab-recorder.raw.v1","sequence":null,"source":"clob_market_ws"}
{"event_at":"2026-07-27T03:27:44.348000Z","event_fingerprint":"dfb4d9c604505fb0a952a73e295ee9d1a74be67d0fffd48bef7b5dfc83f04b8e","payload":{"connection_id":"c7dc2e4762f849c6b6f9306b6518dcab","event_at":"2026-07-27T03:27:44.348000Z","event_type":"price_change","frame_hash":"5cf0b3f6639e857594f480c74e7db384f36cc75a638b2ba53494d722b7043cf2","frame_index":0,"kind":"data","monotonic_ns":224847593468625,"payload":{"event_type":"price_change","market":"0x717c0e8ccd4d5c7040185188fbae28be901ca589a11a94b1b38ca36a79eccfeb","price_changes":[{"asset_id":"24254094493625419915756280046002869097156693848522361803041977572204227262166","best_ask":"0.92","best_bid":"0.91","hash":"fba998475755d9535bd8bd11c9df48463d326fae","price":"0.02","side":"BUY","size":"530"},{"asset_id":"41448400836309843603620980831210604935021861034693225347475867885462478926555","best_ask":"0.09","best_bid":"0.08","hash":"b007124980d7e4934d29251a3319849cf14e0579","price":"0.98","side":"SELL","size":"530"}],"timestamp":"1785122864348"},"payload_hash":"e68b815637e8fa2097db9e38612f5ec819f28e0c9fd8245821aaad8c6288f576","raw_frame":"{\"market\":\"0x717c0e8ccd4d5c7040185188fbae28be901ca589a11a94b1b38ca36a79eccfeb\", \"price_changes\":[{\"asset_id\":\"24254094493625419915756280046002869097156693848522361803041977572204227262166\", \"price\":\"0.02\", \"size\":\"530\", \"side\":\"BUY\", \"hash\":\"fba998475755d9535bd8bd11c9df48463d326fae\", \"best_bid\":\"0.91\", \"best_ask\":\"0.92\"}, {\"asset_id\":\"41448400836309843603620980831210604935021861034693225347475867885462478926555\", \"price\":\"0.98\", \"size\":\"530\", \"side\":\"SELL\", \"hash\":\"b007124980d7e4934d29251a3319849cf14e0579\", \"best_bid\":\"0.08\", \"best_ask\":\"0.09\"}], \"timestamp\":\"1785122864348\", \"event_type\":\"price_change\"}","received_at":"2026-07-27T03:27:44.231970Z","schema_version":"clob-market-ws.price_change.v1","sequence":null,"server_hash":null,"server_timestamp":"1785122864348","session_id":"dd162b8dca5f43ff811d304e69a06123","source":"clob_market_ws"},"received_at":"2026-07-27T03:27:44.231970Z","record_id":"95aa590952718dd6ad9d2a57b7ba36ca53646619e2818e922ae4a68fbd7fc9a7","schema_fingerprint":"4aa3821a28b0b7c2400bc59aba4bcc0a76e971dadd19610d3ad38c768e124dc7","schema_version":"edge-lab-recorder.raw.v1","sequence":null,"source":"clob_market_ws"}
{"event_at":"2026-07-27T03:27:44.377000Z","event_fingerprint":"c299484491f70d811bacdb799f68cd8cb054293ace7ddcc0d0e493fb86ca2c81","payload":{"connection_id":"c7dc2e4762f849c6b6f9306b6518dcab","event_at":"2026-07-27T03:27:44.377000Z","event_type":"price_change","frame_hash":"6f94c162096810265c31bb1011ae4398365244861fffcf17ef17a74109ccfb8e","frame_index":0,"kind":"data","monotonic_ns":224847625965750,"payload":{"event_type":"price_change","market":"0x717c0e8ccd4d5c7040185188fbae28be901ca589a11a94b1b38ca36a79eccfeb","price_changes":[{"asset_id":"24254094493625419915756280046002869097156693848522361803041977572204227262166","best_ask":"0.92","best_bid":"0.91","hash":"de8fb7a117df09f1869eb3153fa9de6dbe0c2f3f","price":"0.57","side":"BUY","size":"177.41"},{"asset_id":"41448400836309843603620980831210604935021861034693225347475867885462478926555","best_ask":"0.09","best_bid":"0.08","hash":"b64f249a9471dde5d676948fd7bd59907bf66a23","price":"0.43","side":"SELL","size":"177.41"}],"timestamp":"1785122864377"},"payload_hash":"0ec31ba9dce0d0549db3fbc42daafb1796adade7b44aff533f7b226dfb04e4d2","raw_frame":"{\"market\":\"0x717c0e8ccd4d5c7040185188fbae28be901ca589a11a94b1b38ca36a79eccfeb\", \"price_changes\":[{\"asset_id\":\"24254094493625419915756280046002869097156693848522361803041977572204227262166\", \"price\":\"0.57\", \"size\":\"177.41\", \"side\":\"BUY\", \"hash\":\"de8fb7a117df09f1869eb3153fa9de6dbe0c2f3f\", \"best_bid\":\"0.91\", \"best_ask\":\"0.92\"}, {\"asset_id\":\"41448400836309843603620980831210604935021861034693225347475867885462478926555\", \"price\":\"0.43\", \"size\":\"177.41\", \"side\":\"SELL\", \"hash\":\"b64f249a9471dde5d676948fd7bd59907bf66a23\", \"best_bid\":\"0.08\", \"best_ask\":\"0.09\"}], \"timestamp\":\"1785122864377\", \"event_type\":\"price_change\"}","received_at":"2026-07-27T03:27:44.264470Z","schema_version":"clob-market-ws.price_change.v1","sequence":null,"server_hash":null,"server_timestamp":"1785122864377","session_id":"dd162b8dca5f43ff811d304e69a06123","source":"clob_market_ws"},"received_at":"2026-07-27T03:27:44.264470Z","record_id":"be41edf0044954f9fc0e800b57fc5cf7b0f51c9430809f1565526c10d65db6b7","schema_fingerprint":"4aa3821a28b0b7c2400bc59aba4bcc0a76e971dadd19610d3ad38c768e124dc7","schema_version":"edge-lab-recorder.raw.v1","sequence":null,"source":"clob_market_ws"}
{"event_at":"2026-07-27T03:27:44.378000Z","event_fingerprint":"e13221528c73ea855a64001a5f76baf5b275c8adeb9fa4d3908c55d26ee7918c","payload":{"connection_id":"c7dc2e4762f849c6b6f9306b6518dcab","event_at":"2026-07-27T03:27:44.378000Z","event_type":"price_change","frame_hash":"a54d0d7cb98ba36458a5ce6026e82a49913cae0f5823adb0a747862793543cde","frame_index":0,"kind":"data","monotonic_ns":224847629989166,"payload":{"event_type":"price_change","market":"0x717c0e8ccd4d5c7040185188fbae28be901ca589a11a94b1b38ca36a79eccfeb","price_changes":[{"asset_id":"41448400836309843603620980831210604935021861034693225347475867885462478926555","best_ask":"0.09","best_bid":"0.08","hash":"861aee152a768b71c6ac3b99036da764870e0a15","price":"0.03","side":"BUY","size":"1902"},{"asset_id":"24254094493625419915756280046002869097156693848522361803041977572204227262166","best_ask":"0.92","best_bid":"0.91","hash":"e31069d8f29e4eda40f72b56fc8ff87b1bfcc767","price":"0.97","side":"SELL","size":"1902"}],"timestamp":"1785122864378"},"payload_hash":"1912afc54ee1a4b2fcd18594a2c89ce1c4bc78bc33bb609b884c7665388438c4","raw_frame":"{\"market\":\"0x717c0e8ccd4d5c7040185188fbae28be901ca589a11a94b1b38ca36a79eccfeb\", \"price_changes\":[{\"asset_id\":\"41448400836309843603620980831210604935021861034693225347475867885462478926555\", \"price\":\"0.03\", \"size\":\"1902\", \"side\":\"BUY\", \"hash\":\"861aee152a768b71c6ac3b99036da764870e0a15\", \"best_bid\":\"0.08\", \"best_ask\":\"0.09\"}, {\"asset_id\":\"24254094493625419915756280046002869097156693848522361803041977572204227262166\", \"price\":\"0.97\", \"size\":\"1902\", \"side\":\"SELL\", \"hash\":\"e31069d8f29e4eda40f72b56fc8ff87b1bfcc767\", \"best_bid\":\"0.91\", \"best_ask\":\"0.92\"}], \"timestamp\":\"1785122864378\", \"event_type\":\"price_change\"}","received_at":"2026-07-27T03:27:44.268493Z","schema_version":"clob-market-ws.price_change.v1","sequence":null,"server_hash":null,"server_timestamp":"1785122864378","session_id":"dd162b8dca5f43ff811d304e69a06123","source":"clob_market_ws"},"received_at":"2026-07-27T03:27:44.268493Z","record_id":"a1b1d8c25c9333956ea2b9cb6b6ee1a837bddecc241a88fd29c017a1b9a2202a","schema_fingerprint":"4aa3821a28b0b7c2400bc59aba4bcc0a76e971dadd19610d3ad38c768e124dc7","schema_version":"edge-lab-recorder.raw.v1","sequence":null,"source":"clob_market_ws"}
{"event_at":"2026-07-27T03:27:44.384000Z","event_fingerprint":"cf7d493e3165335a2f27fccc4675201d3121c7e0e8f8df831c2c0e1592c08060","payload":{"connection_id":"c7dc2e4762f849c6b6f9306b6518dcab","event_at":"2026-07-27T03:27:44.384000Z","event_type":"best_bid_ask","frame_hash":"534c63cbb6a78bcf96dadc45b71f2001d28bd961486ddb4b32fffded98193563","frame_index":0,"kind":"data","monotonic_ns":224847632984875,"payload":{"asset_id":"24254094493625419915756280046002869097156693848522361803041977572204227262166","best_ask":"0.92","best_bid":"0.91","event_type":"best_bid_ask","market":"0x717c0e8ccd4d5c7040185188fbae28be901ca589a11a94b1b38ca36a79eccfeb","spread":"0.01","timestamp":"1785122864384"},"payload_hash":"6dc34d3253bacddd2dfc5c6ac9b5e12040862bea53e9579e6d3bcfaf2293d91d","raw_frame":"{\"market\":\"0x717c0e8ccd4d5c7040185188fbae28be901ca589a11a94b1b38ca36a79eccfeb\", \"asset_id\":\"24254094493625419915756280046002869097156693848522361803041977572204227262166\", \"best_bid\":\"0.91\", \"best_ask\":\"0.92\", \"spread\":\"0.01\", \"timestamp\":\"1785122864384\", \"event_type\":\"best_bid_ask\"}","received_at":"2026-07-27T03:27:44.271487Z","schema_version":"clob-market-ws.best_bid_ask.v1","sequence":null,"server_hash":null,"server_timestamp":"1785122864384","session_id":"dd162b8dca5f43ff811d304e69a06123","source":"clob_market_ws"},"received_at":"2026-07-27T03:27:44.271487Z","record_id":"64e3e3ba621308ce29001654dc388ae9660094d60ae8dc2ff4c9f722a70fbb4c","schema_fingerprint":"8488399f31b0337811b13b266be932db7062827c2470b78bd8e9e99bab51d17d","schema_version":"edge-lab-recorder.raw.v1","sequence":null,"source":"clob_market_ws"}
{"event_at":"2026-07-27T03:27:44.384000Z","event_fingerprint":"345a15ba8287bbeef050e86913ffb8e8d5a8137492d57d1b4b78d4d1aa7952b4","payload":{"connection_id":"c7dc2e4762f849c6b6f9306b6518dcab","event_at":"2026-07-27T03:27:44.384000Z","event_type":"best_bid_ask","frame_hash":"d1627b4376f7081f7a92f19376986d7e3dff0aed4a4bfdc93fdbc3b33e0a4905","frame_index":0,"kind":"data","monotonic_ns":224847634695958,"payload":{"asset_id":"41448400836309843603620980831210604935021861034693225347475867885462478926555","best_ask":"0.09","best_bid":"0.08","event_type":"best_bid_ask","market":"0x717c0e8ccd4d5c7040185188fbae28be901ca589a11a94b1b38ca36a79eccfeb","spread":"0.01","timestamp":"1785122864384"},"payload_hash":"97ef407e6e100f8cb87bc012a6aaa5e6dc71fba2df16f495b01a9fe54a4f7b4a","raw_frame":"{\"market\":\"0x717c0e8ccd4d5c7040185188fbae28be901ca589a11a94b1b38ca36a79eccfeb\", \"asset_id\":\"41448400836309843603620980831210604935021861034693225347475867885462478926555\", \"best_bid\":\"0.08\", \"best_ask\":\"0.09\", \"spread\":\"0.01\", \"timestamp\":\"1785122864384\", \"event_type\":\"best_bid_ask\"}","received_at":"2026-07-27T03:27:44.273197Z","schema_version":"clob-market-ws.best_bid_ask.v1","sequence":null,"server_hash":null,"server_timestamp":"1785122864384","session_id":"dd162b8dca5f43ff811d304e69a06123","source":"clob_market_ws"},"received_at":"2026-07-27T03:27:44.273197Z","record_id":"a934d3a478d8ab9b696c3aaa5f4d8a8ab318f572d67c1794e6b9341f3cd9a982","schema_fingerprint":"8488399f31b0337811b13b266be932db7062827c2470b78bd8e9e99bab51d17d","schema_version":"edge-lab-recorder.raw.v1","sequence":null,"source":"clob_market_ws"}
{"event_at":"2026-07-27T03:27:44.384000Z","event_fingerprint":"841fb634179cf747713ba226a3fa9858cee4736735795aae2fed4e36ea2ddf1e","payload":{"connection_id":"c7dc2e4762f849c6b6f9306b6518dcab","event_at":"2026-07-27T03:27:44.384000Z","event_type":"price_change","frame_hash":"cc70d6bac77bb34d78f2522fd238c32a98a43bfddd7e7ae535a7cc77ac1923d4","frame_index":0,"kind":"data","monotonic_ns":224847635850291,"payload":{"event_type":"price_change","market":"0x717c0e8ccd4d5c7040185188fbae28be901ca589a11a94b1b38ca36a79eccfeb","price_changes":[{"asset_id":"24254094493625419915756280046002869097156693848522361803041977572204227262166","best_ask":"0.92","best_bid":"0.91","hash":"2ea2cf10a56012411e96b467164d5d3a9ecfbdcd","price":"0.91","side":"BUY","size":"28.96"},{"asset_id":"41448400836309843603620980831210604935021861034693225347475867885462478926555","best_ask":"0.09","best_bid":"0.08","hash":"f6c566fe3ebbe22f8624194e8ffe4f5cf4389589","price":"0.09","side":"SELL","size":"28.96"}],"timestamp":"1785122864384"},"payload_hash":"8858f874e63b07df698dfe9dc38b19296a9da17b54df93f48bea52452209d451","raw_frame":"{\"market\":\"0x717c0e8ccd4d5c7040185188fbae28be901ca589a11a94b1b38ca36a79eccfeb\", \"price_changes\":[{\"asset_id\":\"24254094493625419915756280046002869097156693848522361803041977572204227262166\", \"price\":\"0.91\", \"size\":\"28.96\", \"side\":\"BUY\", \"hash\":\"2ea2cf10a56012411e96b467164d5d3a9ecfbdcd\", \"best_bid\":\"0.91\", \"best_ask\":\"0.92\"}, {\"asset_id\":\"41448400836309843603620980831210604935021861034693225347475867885462478926555\", \"price\":\"0.09\", \"size\":\"28.96\", \"side\":\"SELL\", \"hash\":\"f6c566fe3ebbe22f8624194e8ffe4f5cf4389589\", \"best_bid\":\"0.08\", \"best_ask\":\"0.09\"}], \"timestamp\":\"1785122864384\", \"event_type\":\"price_change\"}","received_at":"2026-07-27T03:27:44.274354Z","schema_version":"clob-market-ws.price_change.v1","sequence":null,"server_hash":null,"server_timestamp":"1785122864384","session_id":"dd162b8dca5f43ff811d304e69a06123","source":"clob_market_ws"},"received_at":"2026-07-27T03:27:44.274354Z","record_id":"57c22c25b93191ce4a158f5f5bbc14082a3a65cfac7a1ffac953a3f2450c8175","schema_fingerprint":"4aa3821a28b0b7c2400bc59aba4bcc0a76e971dadd19610d3ad38c768e124dc7","schema_version":"edge-lab-recorder.raw.v1","sequence":null,"source":"clob_market_ws"}
