{"event_at":"2026-07-27T03:17:34.245000Z","event_fingerprint":"303983a4822e37d02abc191feaaa9a0908908c9ab7828dfa75eaf35a93868698","payload":{"connection_id":"c7dc2e4762f849c6b6f9306b6518dcab","event_at":"2026-07-27T03:17:34.245000Z","event_type":"price_change","frame_hash":"0c028f57cd00d7c17bf771d01af52d1da59f4df579d7dfaf660f9f9efaad0045","frame_index":0,"kind":"data","monotonic_ns":224237505866541,"payload":{"event_type":"price_change","market":"0x717c0e8ccd4d5c7040185188fbae28be901ca589a11a94b1b38ca36a79eccfeb","price_changes":[{"asset_id":"24254094493625419915756280046002869097156693848522361803041977572204227262166","best_ask":"0.63","best_bid":"0.62","hash":"a2b6ba45a60306f6aa27f15de2f1e7ceff0c3ed0","price":"0.04","side":"BUY","size":"633.09"},{"asset_id":"41448400836309843603620980831210604935021861034693225347475867885462478926555","best_ask":"0.38","best_bid":"0.37","hash":"f87c8cb9bb459cd91b04a5d23f02997b0764b5f2","price":"0.96","side":"SELL","size":"633.09"}],"timestamp":"1785122254245"},"payload_hash":"b48d66b658348c5ac4c61bca605ca0d0d5b6a502b0c047856a423dbeff20ce70","raw_frame":"{\"market\":\"0x717c0e8ccd4d5c7040185188fbae28be901ca589a11a94b1b38ca36a79eccfeb\", \"price_changes\":[{\"asset_id\":\"24254094493625419915756280046002869097156693848522361803041977572204227262166\", \"price\":\"0.04\", \"size\":\"633.09\", \"side\":\"BUY\", \"hash\":\"a2b6ba45a60306f6aa27f15de2f1e7ceff0c3ed0\", \"best_bid\":\"0.62\", \"best_ask\":\"0.63\"}, {\"asset_id\":\"41448400836309843603620980831210604935021861034693225347475867885462478926555\", \"price\":\"0.96\", \"size\":\"633.09\", \"side\":\"SELL\", \"hash\":\"f87c8cb9bb459cd91b04a5d23f02997b0764b5f2\", \"best_bid\":\"0.37\", \"best_ask\":\"0.38\"}], \"timestamp\":\"1785122254245\", \"event_type\":\"price_change\"}","received_at":"2026-07-27T03:17:34.170039Z","schema_version":"clob-market-ws.price_change.v1","sequence":null,"server_hash":null,"server_timestamp":"1785122254245","session_id":"dd162b8dca5f43ff811d304e69a06123","source":"clob_market_ws"},"received_at":"2026-07-27T03:17:34.170039Z","record_id":"8f51348c81b435f3936277b0c8c371829b49200a06a0fec6a65cdd33a85095de","schema_fingerprint":"4aa3821a28b0b7c2400bc59aba4bcc0a76e971dadd19610d3ad38c768e124dc7","schema_version":"edge-lab-recorder.raw.v1","sequence":null,"source":"clob_market_ws"}
{"event_at":"2026-07-27T03:17:34.254000Z","event_fingerprint":"7205ab70432c0accfa642a1c16107d503f13d5c2b1c05375f6b364fde8d5e3e0","payload":{"connection_id":"c7dc2e4762f849c6b6f9306b6518dcab","event_at":"2026-07-27T03:17:34.254000Z","event_type":"price_change","frame_hash":"6349dc3bdd279890a7407ca41fd1de4f72f748ea35939e6af9f54749888b9fe4","frame_index":0,"kind":"data","monotonic_ns":224237508183500,"payload":{"event_type":"price_change","market":"0x717c0e8ccd4d5c7040185188fbae28be901ca589a11a94b1b38ca36a79eccfeb","price_changes":[{"asset_id":"41448400836309843603620980831210604935021861034693225347475867885462478926555","best_ask":"0.38","best_bid":"0.37","hash":"a312126dbe302ecc6d86d46f9d4e33ecf37676f2","price":"0.2","side":"BUY","size":"31.8"},{"asset_id":"24254094493625419915756280046002869097156693848522361803041977572204227262166","best_ask":"0.63","best_bid":"0.62","hash":"3e8bdb14afac01cd28fef74a234d4ab86efaeeda","price":"0.8","side":"SELL","size":"31.8"}],"timestamp":"1785122254254"},"payload_hash":"a20174e28fa72f9252d7671fd0cffd5e986c0e40bee7fcadcdb77951eb8c8aba","raw_frame":"{\"market\":\"0x717c0e8ccd4d5c7040185188fbae28be901ca589a11a94b1b38ca36a79eccfeb\", \"price_changes\":[{\"asset_id\":\"41448400836309843603620980831210604935021861034693225347475867885462478926555\", \"price\":\"0.2\", \"size\":\"31.8\", \"side\":\"BUY\", \"hash\":\"a312126dbe302ecc6d86d46f9d4e33ecf37676f2\", \"best_bid\":\"0.37\", \"best_ask\":\"0.38\"}, {\"asset_id\":\"24254094493625419915756280046002869097156693848522361803041977572204227262166\", \"price\":\"0.8\", \"size\":\"31.8\", \"side\":\"SELL\", \"hash\":\"3e8bdb14afac01cd28fef74a234d4ab86efaeeda\", \"best_bid\":\"0.62\", \"best_ask\":\"0.63\"}], \"timestamp\":\"1785122254254\", \"event_type\":\"price_change\"}","received_at":"2026-07-27T03:17:34.172356Z","schema_version":"clob-market-ws.price_change.v1","sequence":null,"server_hash":null,"server_timestamp":"1785122254254","session_id":"dd162b8dca5f43ff811d304e69a06123","source":"clob_market_ws"},"received_at":"2026-07-27T03:17:34.172356Z","record_id":"d161e1678a53450d661ec3d000abd8c5d45f78fad404ab8314ffb68c71d4fabf","schema_fingerprint":"4aa3821a28b0b7c2400bc59aba4bcc0a76e971dadd19610d3ad38c768e124dc7","schema_version":"edge-lab-recorder.raw.v1","sequence":null,"source":"clob_market_ws"}
{"event_at":"2026-07-27T03:17:34.313000Z","event_fingerprint":"1e329ada3cf093de3d7727538f39f0e6ac943c542fc276a4bfd6b24c50360869","payload":{"connection_id":"c7dc2e4762f849c6b6f9306b6518dcab","event_at":"2026-07-27T03:17:34.313000Z","event_type":"price_change","frame_hash":"818284841b2ecb0d6c2c07ba774abce4e50100b14afb47f2ced1dfb61c0604f6","frame_index":0,"kind":"data","monotonic_ns":224237555183208,"payload":{"event_type":"price_change","market":"0x717c0e8ccd4d5c7040185188fbae28be901ca589a11a94b1b38ca36a79eccfeb","price_changes":[{"asset_id":"24254094493625419915756280046002869097156693848522361803041977572204227262166","best_ask":"0.63","best_bid":"0.62","hash":"5df276b4a491b7ef16a97e7f5685a5c5c3a81b1d","price":"0.01","side":"BUY","size":"7713.02"},{"asset_id":"41448400836309843603620980831210604935021861034693225347475867885462478926555","best_ask":"0.38","best_bid":"0.37","hash":"3383bcd71a50f48fbcbf56a6a755f5f8f08af180","price":"0.99","side":"SELL","size":"7713.02"}],"timestamp":"1785122254313"},"payload_hash":"0ca1e2efb738a3a5c336ee18596affce7ba9addc9dddc8a09ba9957d340596dc","raw_frame":"{\"market\":\"0x717c0e8ccd4d5c7040185188fbae28be901ca589a11a94b1b38ca36a79eccfeb\", \"price_changes\":[{\"asset_id\":\"24254094493625419915756280046002869097156693848522361803041977572204227262166\", \"price\":\"0.01\", \"size\":\"7713.02\", \"side\":\"BUY\", \"hash\":\"5df276b4a491b7ef16a97e7f5685a5c5c3a81b1d\", \"best_bid\":\"0.62\", \"best_ask\":\"0.63\"}, {\"asset_id\":\"41448400836309843603620980831210604935021861034693225347475867885462478926555\", \"price\":\"0.99\", \"size\":\"7713.02\", \"side\":\"SELL\", \"hash\":\"3383bcd71a50f48fbcbf56a6a755f5f8f08af180\", \"best_bid\":\"0.37\", \"best_ask\":\"0.38\"}], \"timestamp\":\"1785122254313\", \"event_type\":\"price_change\"}","received_at":"2026-07-27T03:17:34.219356Z","schema_version":"clob-market-ws.price_change.v1","sequence":null,"server_hash":null,"server_timestamp":"1785122254313","session_id":"dd162b8dca5f43ff811d304e69a06123","source":"clob_market_ws"},"received_at":"2026-07-27T03:17:34.219356Z","record_id":"138a74ff504d311437d06e9b0976a877ad9ab0bb7d97457af048551d65c1b601","schema_fingerprint":"4aa3821a28b0b7c2400bc59aba4bcc0a76e971dadd19610d3ad38c768e124dc7","schema_version":"edge-lab-recorder.raw.v1","sequence":null,"source":"clob_market_ws"}
{"event_at":"2026-07-27T03:17:34.315000Z","event_fingerprint":"6ef6609343f4582a8fc81ed3f3bf59212d1f0a5abd1adfb50b3d140bb34a1ccc","payload":{"connection_id":"c7dc2e4762f849c6b6f9306b6518dcab","event_at":"2026-07-27T03:17:34.315000Z","event_type":"price_change","frame_hash":"9a3fffe1282723827d1eb210c6e52755a98a05cb583aa771ab5a3f9568969ab5","frame_index":0,"kind":"data","monotonic_ns":224237558115500,"payload":{"event_type":"price_change","market":"0x717c0e8ccd4d5c7040185188fbae28be901ca589a11a94b1b38ca36a79eccfeb","price_changes":[{"asset_id":"24254094493625419915756280046002869097156693848522361803041977572204227262166","best_ask":"0.63","best_bid":"0.62","hash":"c916a78cdfd7aa3072978dbc911468219946eb41","price":"0.04","side":"BUY","size":"628.09"},{"asset_id":"41448400836309843603620980831210604935021861034693225347475867885462478926555","best_ask":"0.38","best_bid":"0.37","hash":"38743339ac5101e6024e2943f9e9f387f036751d","price":"0.96","side":"SELL","size":"628.09"}],"timestamp":"1785122254315"},"payload_hash":"7ddd0b09ef840e167b0db2cda3fe6ed505dffceefbb152703004bdde45cde5c8","raw_frame":"{\"market\":\"0x717c0e8ccd4d5c7040185188fbae28be901ca589a11a94b1b38ca36a79eccfeb\", \"price_changes\":[{\"asset_id\":\"24254094493625419915756280046002869097156693848522361803041977572204227262166\", \"price\":\"0.04\", \"size\":\"628.09\", \"side\":\"BUY\", \"hash\":\"c916a78cdfd7aa3072978dbc911468219946eb41\", \"best_bid\":\"0.62\", \"best_ask\":\"0.63\"}, {\"asset_id\":\"41448400836309843603620980831210604935021861034693225347475867885462478926555\", \"price\":\"0.96\", \"size\":\"628.09\", \"side\":\"SELL\", \"hash\":\"38743339ac5101e6024e2943f9e9f387f036751d\", \"best_bid\":\"0.37\", \"best_ask\":\"0.38\"}], \"timestamp\":\"1785122254315\", \"event_type\":\"price_change\"}","received_at":"2026-07-27T03:17:34.222289Z","schema_version":"clob-market-ws.price_change.v1","sequence":null,"server_hash":null,"server_timestamp":"1785122254315","session_id":"dd162b8dca5f43ff811d304e69a06123","source":"clob_market_ws"},"received_at":"2026-07-27T03:17:34.222289Z","record_id":"49d67c1bb05a35957136e64740e0b439c8209a19af22654c43cb8823b3be003f","schema_fingerprint":"4aa3821a28b0b7c2400bc59aba4bcc0a76e971dadd19610d3ad38c768e124dc7","schema_version":"edge-lab-recorder.raw.v1","sequence":null,"source":"clob_market_ws"}
{"event_at":"2026-07-27T03:17:34.335000Z","event_fingerprint":"5e272bd57a39d219f24e234fe2c02f7a23d14cf344fc5c8eadf4d8ec3db4d413","payload":{"connection_id":"c7dc2e4762f849c6b6f9306b6518dcab","event_at":"2026-07-27T03:17:34.335000Z","event_type":"price_change","frame_hash":"695b9179a5db0c583ac8cf5ce1a973974d3a4bba0b1e0f73fcac67ed55ce6c41","frame_index":0,"kind":"data","monotonic_ns":224237573653958,"payload":{"event_type":"price_change","market":"0x717c0e8ccd4d5c7040185188fbae28be901ca589a11a94b1b38ca36a79eccfeb","price_changes":[{"asset_id":"24254094493625419915756280046002869097156693848522361803041977572204227262166","best_ask":"0.63","best_bid":"0.62","hash":"6f1a5a9a239bae2a23f068207274585b6396981c","price":"0.01","side":"BUY","size":"7708.02"},{"asset_id":"41448400836309843603620980831210604935021861034693225347475867885462478926555","best_ask":"0.38","best_bid":"0.37","hash":"a36eb7b9a0320759cd00bfba639996cf4151f0ae","price":"0.99","side":"SELL","size":"7708.02"}],"timestamp":"1785122254335"},"payload_hash":"50586087def3e59a1c5b80bba675876daab1c7f096033b5680a482913bf559b3","raw_frame":"{\"market\":\"0x717c0e8ccd4d5c7040185188fbae28be901ca589a11a94b1b38ca36a79eccfeb\", \"price_changes\":[{\"asset_id\":\"24254094493625419915756280046002869097156693848522361803041977572204227262166\", \"price\":\"0.01\", \"size\":\"7708.02\", \"side\":\"BUY\", \"hash\":\"6f1a5a9a239bae2a23f068207274585b6396981c\", \"best_bid\":\"0.62\", \"best_ask\":\"0.63\"}, {\"asset_id\":\"41448400836309843603620980831210604935021861034693225347475867885462478926555\", \"price\":\"0.99\", \"size\":\"7708.02\", \"side\":\"SELL\", \"hash\":\"a36eb7b9a0320759cd00bfba639996cf4151f0ae\", \"best_bid\":\"0.37\", \"best_ask\":\"0.38\"}], \"timestamp\":\"1785122254335\", \"event_type\":\"price_change\"}","received_at":"2026-07-27T03:17:34.237823Z","schema_version":"clob-market-ws.price_change.v1","sequence":null,"server_hash":null,"server_timestamp":"1785122254335","session_id":"dd162b8dca5f43ff811d304e69a06123","source":"clob_market_ws"},"received_at":"2026-07-27T03:17:34.237823Z","record_id":"a6630cd71d48eb1449d7269ef7068642f8daa868d0f109cfc28491e26c79b1bf","schema_fingerprint":"4aa3821a28b0b7c2400bc59aba4bcc0a76e971dadd19610d3ad38c768e124dc7","schema_version":"edge-lab-recorder.raw.v1","sequence":null,"source":"clob_market_ws"}
{"event_at":"2026-07-27T03:17:34.402000Z","event_fingerprint":"5c4a87d74467bdc8bc6924986d3e36911473ea61b774156f55827b07b8aa2677","payload":{"connection_id":"c7dc2e4762f849c6b6f9306b6518dcab","event_at":"2026-07-27T03:17:34.402000Z","event_type":"price_change","frame_hash":"b3117d8a78cd9e309f08103130b7de50c1d0cd29b7abfa8d14fb9191424e48c7","frame_index":0,"kind":"data","monotonic_ns":224237670474666,"payload":{"event_type":"price_change","market":"0x717c0e8ccd4d5c7040185188fbae28be901ca589a11a94b1b38ca36a79eccfeb","price_changes":[{"asset_id":"41448400836309843603620980831210604935021861034693225347475867885462478926555","best_ask":"0.38","best_bid":"0.37","hash":"d339fdc5ded365c18c9f8e2b8890f630bed278e3","price":"0.22","side":"BUY","size":"479.03"},{"asset_id":"24254094493625419915756280046002869097156693848522361803041977572204227262166","best_ask":"0.63","best_bid":"0.62","hash":"4018ff802ccddbdb542b5375cc72a125a7ecdd5c","price":"0.78","side":"SELL","size":"479.03"}],"timestamp":"1785122254402"},"payload_hash":"732607ec469735c65ab6cb6beae6291b6fe39215e3803c00d2545d1b67e12280","raw_frame":"{\"market\":\"0x717c0e8ccd4d5c7040185188fbae28be901ca589a11a94b1b38ca36a79eccfeb\", \"price_changes\":[{\"asset_id\":\"41448400836309843603620980831210604935021861034693225347475867885462478926555\", \"price\":\"0.22\", \"size\":\"479.03\", \"side\":\"BUY\", \"hash\":\"d339fdc5ded365c18c9f8e2b8890f630bed278e3\", \"best_bid\":\"0.37\", \"best_ask\":\"0.38\"}, {\"asset_id\":\"24254094493625419915756280046002869097156693848522361803041977572204227262166\", \"price\":\"0.78\", \"size\":\"479.03\", \"side\":\"SELL\", \"hash\":\"4018ff802ccddbdb542b5375cc72a125a7ecdd5c\", \"best_bid\":\"0.62\", \"best_ask\":\"0.63\"}], \"timestamp\":\"1785122254402\", \"event_type\":\"price_change\"}","received_at":"2026-07-27T03:17:34.334647Z","schema_version":"clob-market-ws.price_change.v1","sequence":null,"server_hash":null,"server_timestamp":"1785122254402","session_id":"dd162b8dca5f43ff811d304e69a06123","source":"clob_market_ws"},"received_at":"2026-07-27T03:17:34.334647Z","record_id":"bb1f96e13a5566965b676075242e706cf2868350eabc8c7aeaa2d2ab78cfb324","schema_fingerprint":"4aa3821a28b0b7c2400bc59aba4bcc0a76e971dadd19610d3ad38c768e124dc7","schema_version":"edge-lab-recorder.raw.v1","sequence":null,"source":"clob_market_ws"}
{"event_at":"2026-07-27T03:17:34.409000Z","event_fingerprint":"6751a298f84f80aa03e202d3862536c1b9b0af444af3525fbd12acbe156bbb64","payload":{"connection_id":"c7dc2e4762f849c6b6f9306b6518dcab","event_at":"2026-07-27T03:17:34.409000Z","event_type":"price_change","frame_hash":"db5f5070508c99efadc238c1a6b978a0a04bda18b6d24f0f0c30f390b642801c","frame_index":0,"kind":"data","monotonic_ns":224237673919458,"payload":{"event_type":"price_change","market":"0x717c0e8ccd4d5c7040185188fbae28be901ca589a11a94b1b38ca36a79eccfeb","price_changes":[{"asset_id":"24254094493625419915756280046002869097156693848522361803041977572204227262166","best_ask":"0.63","best_bid":"0.62","hash":"3b0479bf15012041d45879ad5b8607107a042729","price":"0.59","side":"BUY","size":"291.87"},{"asset_id":"41448400836309843603620980831210604935021861034693225347475867885462478926555","best_ask":"0.38","best_bid":"0.37","hash":"7549cb6e9366a38cc192f6f8e567944e8f610756","price":"0.41","side":"SELL","size":"291.87"}],"timestamp":"1785122254409"},"payload_hash":"c476ff706475181d0d1ad8aa30ad79a3ee6f7cf6632430b2f4e727d5b2a451de","raw_frame":"{\"market\":\"0x717c0e8ccd4d5c7040185188fbae28be901ca589a11a94b1b38ca36a79eccfeb\", \"price_changes\":[{\"asset_id\":\"24254094493625419915756280046002869097156693848522361803041977572204227262166\", \"price\":\"0.59\", \"size\":\"291.87\", \"side\":\"BUY\", \"hash\":\"3b0479bf15012041d45879ad5b8607107a042729\", \"best_bid\":\"0.62\", \"best_ask\":\"0.63\"}, {\"asset_id\":\"41448400836309843603620980831210604935021861034693225347475867885462478926555\", \"price\":\"0.41\", \"size\":\"291.87\", \"side\":\"SELL\", \"hash\":\"7549cb6e9366a38cc192f6f8e567944e8f610756\", \"best_bid\":\"0.37\", \"best_ask\":\"0.38\"}], \"timestamp\":\"1785122254409\", \"event_type\":\"price_change\"}","received_at":"2026-07-27T03:17:34.338091Z","schema_version":"clob-market-ws.price_change.v1","sequence":null,"server_hash":null,"server_timestamp":"1785122254409","session_id":"dd162b8dca5f43ff811d304e69a06123","source":"clob_market_ws"},"received_at":"2026-07-27T03:17:34.338091Z","record_id":"620d3d0491c34be0cb05899c48ca8960db331c8842237f0866e866d58084fa59","schema_fingerprint":"4aa3821a28b0b7c2400bc59aba4bcc0a76e971dadd19610d3ad38c768e124dc7","schema_version":"edge-lab-recorder.raw.v1","sequence":null,"source":"clob_market_ws"}
{"event_at":"2026-07-27T03:17:34.415000Z","event_fingerprint":"b023e06737aeda5bd0c825521df9c85db3b90bc77e01b8b39147696bf9a05432","payload":{"connection_id":"c7dc2e4762f849c6b6f9306b6518dcab","event_at":"2026-07-27T03:17:34.415000Z","event_type":"price_change","frame_hash":"3883568d6a239fb9000aa56a178221da0ab2757ed6bf05e6a168f495a5fb5b81","frame_index":0,"kind":"data","monotonic_ns":224237677615458,"payload":{"event_type":"price_change","market":"0x717c0e8ccd4d5c7040185188fbae28be901ca589a11a94b1b38ca36a79eccfeb","price_changes":[{"asset_id":"24254094493625419915756280046002869097156693848522361803041977572204227262166","best_ask":"0.63","best_bid":"0.62","hash":"f76de0d685695d93c829d9fe28847f7ebe27e33e","price":"0.04","side":"BUY","size":"633.09"},{"asset_id":"41448400836309843603620980831210604935021861034693225347475867885462478926555","best_ask":"0.38","best_bid":"0.37","hash":"88feb0d9e90a1d847a746355c4024c49b0855353","price":"0.96","side":"SELL","size":"633.09"}],"timestamp":"1785122254415"},"payload_hash":"b2d9c25abfcbe610382f08dbce92b3f06b27e4f8106f4a0b9e851f5fb3b9dc86","raw_frame":"{\"market\":\"0x717c0e8ccd4d5c7040185188fbae28be901ca589a11a94b1b38ca36a79eccfeb\", \"price_changes\":[{\"asset_id\":\"24254094493625419915756280046002869097156693848522361803041977572204227262166\", \"price\":\"0.04\", \"size\":\"633.09\", \"side\":\"BUY\", \"hash\":\"f76de0d685695d93c829d9fe28847f7ebe27e33e\", \"best_bid\":\"0.62\", \"best_ask\":\"0.63\"}, {\"asset_id\":\"41448400836309843603620980831210604935021861034693225347475867885462478926555\", \"price\":\"0.96\", \"size\":\"633.09\", \"side\":\"SELL\", \"hash\":\"88feb0d9e90a1d847a746355c4024c49b0855353\", \"best_bid\":\"0.37\", \"best_ask\":\"0.38\"}], \"timestamp\":\"1785122254415\", \"event_type\":\"price_change\"}","received_at":"2026-07-27T03:17:34.341783Z","schema_version":"clob-market-ws.price_change.v1","sequence":null,"server_hash":null,"server_timestamp":"1785122254415","session_id":"dd162b8dca5f43ff811d304e69a06123","source":"clob_market_ws"},"received_at":"2026-07-27T03:17:34.341783Z","record_id":"469021a500a86f045c359aad617c733955fa9640f88f38151da86f31111fa78a","schema_fingerprint":"4aa3821a28b0b7c2400bc59aba4bcc0a76e971dadd19610d3ad38c768e124dc7","schema_version":"edge-lab-recorder.raw.v1","sequence":null,"source":"clob_market_ws"}
{"event_at":"2026-07-27T03:17:34.435000Z","event_fingerprint":"38de03dcca1583c6b5e68c34912ebb750ed34ed78ceb6c2f68edcc8c55268d70","payload":{"connection_id":"c7dc2e4762f849c6b6f9306b6518dcab","event_at":"2026-07-27T03:17:34.435000Z","event_type":"price_change","frame_hash":"8c88abb77a803de9d9101591269f17fb1724b9f7b3bc5ec2ee6e8d7ed0ece769","frame_index":0,"kind":"data","monotonic_ns":224237679404458,"payload":{"event_type":"price_change","market":"0x717c0e8ccd4d5c7040185188fbae28be901ca589a11a94b1b38ca36a79eccfeb","price_changes":[{"asset_id":"24254094493625419915756280046002869097156693848522361803041977572204227262166","best_ask":"0.63","best_bid":"0.62","hash":"cdd090082589479ac45c661bf27251f28dfc1dfe","price":"0.58","side":"BUY","size":"105"},{"asset_id":"41448400836309843603620980831210604935021861034693225347475867885462478926555","best_ask":"0.38","best_bid":"0.37","hash":"ed852b3f96640e424569bc0a0f35d3e6cfd55eb9","price":"0.42","side":"SELL","size":"105"}],"timestamp":"1785122254435"},"payload_hash":"28f693d46e3002822ceb92dd239e362173bfe9e4126139934304b818e1430ed1","raw_frame":"{\"market\":\"0x717c0e8ccd4d5c7040185188fbae28be901ca589a11a94b1b38ca36a79eccfeb\", \"price_changes\":[{\"asset_id\":\"24254094493625419915756280046002869097156693848522361803041977572204227262166\", \"price\":\"0.58\", \"size\":\"105\", \"side\":\"BUY\", \"hash\":\"cdd090082589479ac45c661bf27251f28dfc1dfe\", \"best_bid\":\"0.62\", \"best_ask\":\"0.63\"}, {\"asset_id\":\"41448400836309843603620980831210604935021861034693225347475867885462478926555\", \"price\":\"0.42\", \"size\":\"105\", \"side\":\"SELL\", \"hash\":\"ed852b3f96640e424569bc0a0f35d3e6cfd55eb9\", \"best_bid\":\"0.37\", \"best_ask\":\"0.38\"}], \"timestamp\":\"1785122254435\", \"event_type\":\"price_change\"}","received_at":"2026-07-27T03:17:34.343576Z","schema_version":"clob-market-ws.price_change.v1","sequence":null,"server_hash":null,"server_timestamp":"1785122254435","session_id":"dd162b8dca5f43ff811d304e69a06123","source":"clob_market_ws"},"received_at":"2026-07-27T03:17:34.343576Z","record_id":"55a388a81e2b17dd55cd15e7ad49e5d812832867edf4dd41223cf1086c0b51ee","schema_fingerprint":"4aa3821a28b0b7c2400bc59aba4bcc0a76e971dadd19610d3ad38c768e124dc7","schema_version":"edge-lab-recorder.raw.v1","sequence":null,"source":"clob_market_ws"}
{"event_at":"2026-07-27T03:17:34.451000Z","event_fingerprint":"83cd397efbafd229aa86d7efe73c39e79571e50ab420acd18a59d519657f2332","payload":{"connection_id":"c7dc2e4762f849c6b6f9306b6518dcab","event_at":"2026-07-27T03:17:34.451000Z","event_type":"price_change","frame_hash":"8d276430342d394245bb812f980b0c51bb81dd238e989ce248d6144241ed59ef","frame_index":0,"kind":"data","monotonic_ns":224237698863916,"payload":{"event_type":"price_change","market":"0x717c0e8ccd4d5c7040185188fbae28be901ca589a11a94b1b38ca36a79eccfeb","price_changes":[{"asset_id":"24254094493625419915756280046002869097156693848522361803041977572204227262166","best_ask":"0.63","best_bid":"0.62","hash":"5fbac6cab6eaadae1ec95d81c6da2c816c3f05a6","price":"0.01","side":"BUY","size":"7713.02"},{"asset_id":"41448400836309843603620980831210604935021861034693225347475867885462478926555","best_ask":"0.38","best_bid":"0.37","hash":"9b951021d0ea0cdc0074345343432b5293f015ef","price":"0.99","side":"SELL","size":"7713.02"}],"timestamp":"1785122254451"},"payload_hash":"d4d284c6b36e55762915506f15985b02b3562777ebf8bbf6322a3df75b178f9a","raw_frame":"{\"market\":\"0x717c0e8ccd4d5c7040185188fbae28be901ca589a11a94b1b38ca36a79eccfeb\", \"price_changes\":[{\"asset_id\":\"24254094493625419915756280046002869097156693848522361803041977572204227262166\", \"price\":\"0.01\", \"size\":\"7713.02\", \"side\":\"BUY\", \"hash\":\"5fbac6cab6eaadae1ec95d81c6da2c816c3f05a6\", \"best_bid\":\"0.62\", \"best_ask\":\"0.63\"}, {\"asset_id\":\"41448400836309843603620980831210604935021861034693225347475867885462478926555\", \"price\":\"0.99\", \"size\":\"7713.02\", \"side\":\"SELL\", \"hash\":\"9b951021d0ea0cdc0074345343432b5293f015ef\", \"best_bid\":\"0.37\", \"best_ask\":\"0.38\"}], \"timestamp\":\"1785122254451\", \"event_type\":\"price_change\"}","received_at":"2026-07-27T03:17:34.363036Z","schema_version":"clob-market-ws.price_change.v1","sequence":null,"server_hash":null,"server_timestamp":"1785122254451","session_id":"dd162b8dca5f43ff811d304e69a06123","source":"clob_market_ws"},"received_at":"2026-07-27T03:17:34.363036Z","record_id":"12920e74bab9856ca71504c913cd36981fe336498b7acbf95422c299bb0211ff","schema_fingerprint":"4aa3821a28b0b7c2400bc59aba4bcc0a76e971dadd19610d3ad38c768e124dc7","schema_version":"edge-lab-recorder.raw.v1","sequence":null,"source":"clob_market_ws"}
{"event_at":"2026-07-27T03:17:34.466000Z","event_fingerprint":"77182d95547fda2ab46180be54874999a1324dabcbe84bcf1c5f8753afc3ed45","payload":{"connection_id":"c7dc2e4762f849c6b6f9306b6518dcab","event_at":"2026-07-27T03:17:34.466000Z","event_type":"price_change","frame_hash":"637deabfea2b1f7f983b8ed92a4a9667eeca0119a4cb4a10c3c30dcf59012b42","frame_index":0,"kind":"data","monotonic_ns":224237701420125,"payload":{"event_type":"price_change","market":"0x717c0e8ccd4d5c7040185188fbae28be901ca589a11a94b1b38ca36a79eccfeb","price_changes":[{"asset_id":"24254094493625419915756280046002869097156693848522361803041977572204227262166","best_ask":"0.63","best_bid":"0.62","hash":"facfcdb1534c2ab718aa5b9b92dcbbf2dd4156b7","price":"0.04","side":"BUY","size":"628.09"},{"asset_id":"41448400836309843603620980831210604935021861034693225347475867885462478926555","best_ask":"0.38","best_bid":"0.37","hash":"3d2de70559b006d5ef1fdc6b71f8c097dd6c9775","price":"0.96","side":"SELL","size":"628.09"}],"timestamp":"1785122254466"},"payload_hash":"f8c63fb90d5a23b507819d873b6b718a95acef8bde1373a908edeac04197145f","raw_frame":"{\"market\":\"0x717c0e8ccd4d5c7040185188fbae28be901ca589a11a94b1b38ca36a79eccfeb\", \"price_changes\":[{\"asset_id\":\"24254094493625419915756280046002869097156693848522361803041977572204227262166\", \"price\":\"0.04\", \"size\":\"628.09\", \"side\":\"BUY\", \"hash\":\"facfcdb1534c2ab718aa5b9b92dcbbf2dd4156b7\", \"best_bid\":\"0.62\", \"best_ask\":\"0.63\"}, {\"asset_id\":\"41448400836309843603620980831210604935021861034693225347475867885462478926555\", \"price\":\"0.96\", \"size\":\"628.09\", \"side\":\"SELL\", \"hash\":\"3d2de70559b006d5ef1fdc6b71f8c097dd6c9775\", \"best_bid\":\"0.37\", \"best_ask\":\"0.38\"}], \"timestamp\":\"1785122254466\", \"event_type\":\"price_change\"}","received_at":"2026-07-27T03:17:34.365589Z","schema_version":"clob-market-ws.price_change.v1","sequence":null,"server_hash":null,"server_timestamp":"1785122254466","session_id":"dd162b8dca5f43ff811d304e69a06123","source":"clob_market_ws"},"received_at":"2026-07-27T03:17:34.365589Z","record_id":"278340e4d328ec81c9d7aa55bd2002c9e542eb97a5c7abf629ee44f656735193","schema_fingerprint":"4aa3821a28b0b7c2400bc59aba4bcc0a76e971dadd19610d3ad38c768e124dc7","schema_version":"edge-lab-recorder.raw.v1","sequence":null,"source":"clob_market_ws"}
{"event_at":"2026-07-27T03:17:34.471000Z","event_fingerprint":"e24f1c1a37313da8b07eceb18c294fef0c92bd83de31891d84c075cb8997de65","payload":{"connection_id":"c7dc2e4762f849c6b6f9306b6518dcab","event_at":"2026-07-27T03:17:34.471000Z","event_type":"price_change","frame_hash":"db3402ef120a4632b3c867225feedf381d2d804f821cbfc7faac80f42ed9c782","frame_index":0,"kind":"data","monotonic_ns":224237704863958,"payload":{"event_type":"price_change","market":"0x717c0e8ccd4d5c7040185188fbae28be901ca589a11a94b1b38ca36a79eccfeb","price_changes":[{"asset_id":"24254094493625419915756280046002869097156693848522361803041977572204227262166","best_ask":"0.63","best_bid":"0.62","hash":"345629f4c902a73ee27ed1305a1f6216d8beffc4","price":"0.01","side":"BUY","size":"7708.02"},{"asset_id":"41448400836309843603620980831210604935021861034693225347475867885462478926555","best_ask":"0.38","best_bid":"0.37","hash":"2d38dca6457713116f32f20aa98a301e693c182a","price":"0.99","side":"SELL","size":"7708.02"}],"timestamp":"1785122254471"},"payload_hash":"85c5e0ee63d2524b236c86f47f34ec5b526ec074b2996da973335005aa43dea6","raw_frame":"{\"market\":\"0x717c0e8ccd4d5c7040185188fbae28be901ca589a11a94b1b38ca36a79eccfeb\", \"price_changes\":[{\"asset_id\":\"24254094493625419915756280046002869097156693848522361803041977572204227262166\", \"price\":\"0.01\", \"size\":\"7708.02\", \"side\":\"BUY\", \"hash\":\"345629f4c902a73ee27ed1305a1f6216d8beffc4\", \"best_bid\":\"0.62\", \"best_ask\":\"0.63\"}, {\"asset_id\":\"41448400836309843603620980831210604935021861034693225347475867885462478926555\", \"price\":\"0.99\", \"size\":\"7708.02\", \"side\":\"SELL\", \"hash\":\"2d38dca6457713116f32f20aa98a301e693c182a\", \"best_bid\":\"0.37\", \"best_ask\":\"0.38\"}], \"timestamp\":\"1785122254471\", \"event_type\":\"price_change\"}","received_at":"2026-07-27T03:17:34.369035Z","schema_version":"clob-market-ws.price_change.v1","sequence":null,"server_hash":null,"server_timestamp":"1785122254471","session_id":"dd162b8dca5f43ff811d304e69a06123","source":"clob_market_ws"},"received_at":"2026-07-27T03:17:34.369035Z","record_id":"3e11f5de88f4526fb0c1b45205689c0cd54cfec35dd351d8a8d14cf889fb8b9a","schema_fingerprint":"4aa3821a28b0b7c2400bc59aba4bcc0a76e971dadd19610d3ad38c768e124dc7","schema_version":"edge-lab-recorder.raw.v1","sequence":null,"source":"clob_market_ws"}
{"event_at":"2026-07-27T03:17:34.484000Z","event_fingerprint":"c0e52aaa600017b0a08180de5af4fc379e28a1336657dd16b517da0099deee3f","payload":{"connection_id":"c7dc2e4762f849c6b6f9306b6518dcab","event_at":"2026-07-27T03:17:34.484000Z","event_type":"price_change","frame_hash":"e360d899010055977f4cfa35f4597e1f43c4bc97045d0987cec2d63aef39f71d","frame_index":0,"kind":"data","monotonic_ns":224237735179833,"payload":{"event_type":"price_change","market":"0x717c0e8ccd4d5c7040185188fbae28be901ca589a11a94b1b38ca36a79eccfeb","price_changes":[{"asset_id":"24254094493625419915756280046002869097156693848522361803041977572204227262166","best_ask":"0.63","best_bid":"0.62","hash":"bd25ea37aa6a9e1c2d337911c945778c809f95dd","price":"0.61","side":"BUY","size":"73.42"},{"asset_id":"41448400836309843603620980831210604935021861034693225347475867885462478926555","best_ask":"0.38","best_bid":"0.37","hash":"6d2685afd8d4ded7ede1fc80499b27f0d2643630","price":"0.39","side":"SELL","size":"73.42"}],"timestamp":"1785122254484"},"payload_hash":"53d7752d1b18bd1d5d2570da1f6aeaeeafd4f95eca1c1fda58b0c894f02fafea","raw_frame":"{\"market\":\"0x717c0e8ccd4d5c7040185188fbae28be901ca589a11a94b1b38ca36a79eccfeb\", \"price_changes\":[{\"asset_id\":\"24254094493625419915756280046002869097156693848522361803041977572204227262166\", \"price\":\"0.61\", \"size\":\"73.42\", \"side\":\"BUY\", \"hash\":\"bd25ea37aa6a9e1c2d337911c945778c809f95dd\", \"best_bid\":\"0.62\", \"best_ask\":\"0.63\"}, {\"asset_id\":\"41448400836309843603620980831210604935021861034693225347475867885462478926555\", \"price\":\"0.39\", \"size\":\"73.42\", \"side\":\"SELL\", \"hash\":\"6d2685afd8d4ded7ede1fc80499b27f0d2643630\", \"best_bid\":\"0.37\", \"best_ask\":\"0.38\"}], \"timestamp\":\"1785122254484\", \"event_type\":\"price_change\"}","received_at":"2026-07-27T03:17:34.399351Z","schema_version":"clob-market-ws.price_change.v1","sequence":null,"server_hash":null,"server_timestamp":"1785122254484","session_id":"dd162b8dca5f43ff811d304e69a06123","source":"clob_market_ws"},"received_at":"2026-07-27T03:17:34.399351Z","record_id":"1c06020564044f928c860cb28baaa382a598f21b8324d3c299248f031f8d1ab2","schema_fingerprint":"4aa3821a28b0b7c2400bc59aba4bcc0a76e971dadd19610d3ad38c768e124dc7","schema_version":"edge-lab-recorder.raw.v1","sequence":null,"source":"clob_market_ws"}
{"event_at":"2026-07-27T03:17:34.485000Z","event_fingerprint":"25e2275c879682adc4d737ff1c35f0c0df6e212274966e32ff40b720b4a3ffe7","payload":{"connection_id":"c7dc2e4762f849c6b6f9306b6518dcab","event_at":"2026-07-27T03:17:34.485000Z","event_type":"price_change","frame_hash":"96f436e17c2dc5daadeb5c2fcf513a12927c87706ca2591072e35e8590b348e2","frame_index":0,"kind":"data","monotonic_ns":224237738720166,"payload":{"event_type":"price_change","market":"0x717c0e8ccd4d5c7040185188fbae28be901ca589a11a94b1b38ca36a79eccfeb","price_changes":[{"asset_id":"41448400836309843603620980831210604935021861034693225347475867885462478926555","best_ask":"0.38","best_bid":"0.37","hash":"98cd1c77d678ff90daee98a08866c994ceb39370","price":"0.3","side":"BUY","size":"144.94"},{"asset_id":"24254094493625419915756280046002869097156693848522361803041977572204227262166","best_ask":"0.63","best_bid":"0.62","hash":"1029e8f8e80e2c02c85ef0ab824f18c5ab954627","price":"0.7","side":"SELL","size":"144.94"}],"timestamp":"1785122254485"},"payload_hash":"675b8fc3f75cac6b07ed3b74c4ebbee6c80d4d093e53812e88e52527ae0caffd","raw_frame":"{\"market\":\"0x717c0e8ccd4d5c7040185188fbae28be901ca589a11a94b1b38ca36a79eccfeb\", \"price_changes\":[{\"asset_id\":\"41448400836309843603620980831210604935021861034693225347475867885462478926555\", \"price\":\"0.3\", \"size\":\"144.94\", \"side\":\"BUY\", \"hash\":\"98cd1c77d678ff90daee98a08866c994ceb39370\", \"best_bid\":\"0.37\", \"best_ask\":\"0.38\"}, {\"asset_id\":\"24254094493625419915756280046002869097156693848522361803041977572204227262166\", \"price\":\"0.7\", \"size\":\"144.94\", \"side\":\"SELL\", \"hash\":\"1029e8f8e80e2c02c85ef0ab824f18c5ab954627\", \"best_bid\":\"0.62\", \"best_ask\":\"0.63\"}], \"timestamp\":\"1785122254485\", \"event_type\":\"price_change\"}","received_at":"2026-07-27T03:17:34.402891Z","schema_version":"clob-market-ws.price_change.v1","sequence":null,"server_hash":null,"server_timestamp":"1785122254485","session_id":"dd162b8dca5f43ff811d304e69a06123","source":"clob_market_ws"},"received_at":"2026-07-27T03:17:34.402891Z","record_id":"c4fa486c0c08661235e8d69299d5d9cad99fc99009a69c7efddebe5e1d9e9831","schema_fingerprint":"4aa3821a28b0b7c2400bc59aba4bcc0a76e971dadd19610d3ad38c768e124dc7","schema_version":"edge-lab-recorder.raw.v1","sequence":null,"source":"clob_market_ws"}
{"event_at":"2026-07-27T03:17:34.496000Z","event_fingerprint":"9befaf11239721a254f1673ceb69064314f1d82bcdef5e07935eb41baa900fd9","payload":{"connection_id":"c7dc2e4762f849c6b6f9306b6518dcab","event_at":"2026-07-27T03:17:34.496000Z","event_type":"price_change","frame_hash":"50c0a948c6a5b24f41812fc18e6302e07137f7524ec2eef020bec17cbccbe39e","frame_index":0,"kind":"data","monotonic_ns":224237741654541,"payload":{"event_type":"price_change","market":"0x717c0e8ccd4d5c7040185188fbae28be901ca589a11a94b1b38ca36a79eccfeb","price_changes":[{"asset_id":"41448400836309843603620980831210604935021861034693225347475867885462478926555","best_ask":"0.38","best_bid":"0.37","hash":"004e2587c279e891ca0563de9a201775e0f37280","price":"0.3","side":"BUY","size":"164.94"},{"asset_id":"24254094493625419915756280046002869097156693848522361803041977572204227262166","best_ask":"0.63","best_bid":"0.62","hash":"2a4247f73a56c39238919650aca322b6beb95207","price":"0.7","side":"SELL","size":"164.94"}],"timestamp":"1785122254496"},"payload_hash":"e3036783ba0dc0b53f700b826eff3fb531cad6cb2a44c42d6193a26ffa7f56ca","raw_frame":"{\"market\":\"0x717c0e8ccd4d5c7040185188fbae28be901ca589a11a94b1b38ca36a79eccfeb\", \"price_changes\":[{\"asset_id\":\"41448400836309843603620980831210604935021861034693225347475867885462478926555\", \"price\":\"0.3\", \"size\":\"164.94\", \"side\":\"BUY\", \"hash\":\"004e2587c279e891ca0563de9a201775e0f37280\", \"best_bid\":\"0.37\", \"best_ask\":\"0.38\"}, {\"asset_id\":\"24254094493625419915756280046002869097156693848522361803041977572204227262166\", \"price\":\"0.7\", \"size\":\"164.94\", \"side\":\"SELL\", \"hash\":\"2a4247f73a56c39238919650aca322b6beb95207\", \"best_bid\":\"0.62\", \"best_ask\":\"0.63\"}], \"timestamp\":\"1785122254496\", \"event_type\":\"price_change\"}","received_at":"2026-07-27T03:17:34.405826Z","schema_version":"clob-market-ws.price_change.v1","sequence":null,"server_hash":null,"server_timestamp":"1785122254496","session_id":"dd162b8dca5f43ff811d304e69a06123","source":"clob_market_ws"},"received_at":"2026-07-27T03:17:34.405826Z","record_id":"b216937b9be9432b7c02633877865c7500dd00037befb1b62d0701311727bfed","schema_fingerprint":"4aa3821a28b0b7c2400bc59aba4bcc0a76e971dadd19610d3ad38c768e124dc7","schema_version":"edge-lab-recorder.raw.v1","sequence":null,"source":"clob_market_ws"}
