{"event_at":"2026-07-27T03:18:33.984000Z","event_fingerprint":"994fff8b3c1b0c79389e2f249542bb79c8cc75fb8f8a3bd2bee721b8cef183dc","payload":{"connection_id":"c7dc2e4762f849c6b6f9306b6518dcab","event_at":"2026-07-27T03:18:33.984000Z","event_type":"price_change","frame_hash":"e5f5e75727787bb44940fb61baf573fc7c04e0f8b7a4f04b0a2c6e7c535e4720","frame_index":0,"kind":"data","monotonic_ns":224297251320791,"payload":{"event_type":"price_change","market":"0x717c0e8ccd4d5c7040185188fbae28be901ca589a11a94b1b38ca36a79eccfeb","price_changes":[{"asset_id":"24254094493625419915756280046002869097156693848522361803041977572204227262166","best_ask":"0.52","best_bid":"0.51","hash":"21da94a78fc198cdbef91b828b4987ca896ce760","price":"0.51","side":"BUY","size":"56.34"},{"asset_id":"41448400836309843603620980831210604935021861034693225347475867885462478926555","best_ask":"0.49","best_bid":"0.48","hash":"96973ee1012d9bbac8cd35f1402b19083f9a9629","price":"0.49","side":"SELL","size":"56.34"}],"timestamp":"1785122313984"},"payload_hash":"dffd75d128217cb9f33773cd4fd365913386944c36cef1c05b7130869d80fdd9","raw_frame":"{\"market\":\"0x717c0e8ccd4d5c7040185188fbae28be901ca589a11a94b1b38ca36a79eccfeb\", \"price_changes\":[{\"asset_id\":\"24254094493625419915756280046002869097156693848522361803041977572204227262166\", \"price\":\"0.51\", \"size\":\"56.34\", \"side\":\"BUY\", \"hash\":\"21da94a78fc198cdbef91b828b4987ca896ce760\", \"best_bid\":\"0.51\", \"best_ask\":\"0.52\"}, {\"asset_id\":\"41448400836309843603620980831210604935021861034693225347475867885462478926555\", \"price\":\"0.49\", \"size\":\"56.34\", \"side\":\"SELL\", \"hash\":\"96973ee1012d9bbac8cd35f1402b19083f9a9629\", \"best_bid\":\"0.48\", \"best_ask\":\"0.49\"}], \"timestamp\":\"1785122313984\", \"event_type\":\"price_change\"}","received_at":"2026-07-27T03:18:33.914651Z","schema_version":"clob-market-ws.price_change.v1","sequence":null,"server_hash":null,"server_timestamp":"1785122313984","session_id":"dd162b8dca5f43ff811d304e69a06123","source":"clob_market_ws"},"received_at":"2026-07-27T03:18:33.914651Z","record_id":"2311e9fc98efdbeb32c04aef67bd629b706d2c1d7d4a2e11905eadd1c4123c98","schema_fingerprint":"4aa3821a28b0b7c2400bc59aba4bcc0a76e971dadd19610d3ad38c768e124dc7","schema_version":"edge-lab-recorder.raw.v1","sequence":null,"source":"clob_market_ws"}
{"event_at":"2026-07-27T03:18:34.011000Z","event_fingerprint":"a8f9e0797b97537bdea4e613bea530c66bb2a18c3df261da4dfcc686bea30188","payload":{"connection_id":"c7dc2e4762f849c6b6f9306b6518dcab","event_at":"2026-07-27T03:18:34.011000Z","event_type":"price_change","frame_hash":"0fb4b7bb5ffcf654e14f77e51a5fb5f299bb44a2cc484f9341900f25ef6f31dd","frame_index":0,"kind":"data","monotonic_ns":224297253924333,"payload":{"event_type":"price_change","market":"0x717c0e8ccd4d5c7040185188fbae28be901ca589a11a94b1b38ca36a79eccfeb","price_changes":[{"asset_id":"24254094493625419915756280046002869097156693848522361803041977572204227262166","best_ask":"0.52","best_bid":"0.51","hash":"647fb59e8ba45e3f9614338ca07a4bafd6b300a2","price":"0.5","side":"BUY","size":"73.22"},{"asset_id":"41448400836309843603620980831210604935021861034693225347475867885462478926555","best_ask":"0.49","best_bid":"0.48","hash":"de7a98959a574c4862fb4d024bdd75b5a683b62f","price":"0.5","side":"SELL","size":"73.22"}],"timestamp":"1785122314011"},"payload_hash":"ce46e412ab6e91def217bdc462826ff3f9ba61e0f9fd79cef275726f14f0a891","raw_frame":"{\"market\":\"0x717c0e8ccd4d5c7040185188fbae28be901ca589a11a94b1b38ca36a79eccfeb\", \"price_changes\":[{\"asset_id\":\"24254094493625419915756280046002869097156693848522361803041977572204227262166\", \"price\":\"0.5\", \"size\":\"73.22\", \"side\":\"BUY\", \"hash\":\"647fb59e8ba45e3f9614338ca07a4bafd6b300a2\", \"best_bid\":\"0.51\", \"best_ask\":\"0.52\"}, {\"asset_id\":\"41448400836309843603620980831210604935021861034693225347475867885462478926555\", \"price\":\"0.5\", \"size\":\"73.22\", \"side\":\"SELL\", \"hash\":\"de7a98959a574c4862fb4d024bdd75b5a683b62f\", \"best_bid\":\"0.48\", \"best_ask\":\"0.49\"}], \"timestamp\":\"1785122314011\", \"event_type\":\"price_change\"}","received_at":"2026-07-27T03:18:33.917258Z","schema_version":"clob-market-ws.price_change.v1","sequence":null,"server_hash":null,"server_timestamp":"1785122314011","session_id":"dd162b8dca5f43ff811d304e69a06123","source":"clob_market_ws"},"received_at":"2026-07-27T03:18:33.917258Z","record_id":"df3999934a100fa8f345113a33792981c560ee83e3f24b9dec12b38be13e5195","schema_fingerprint":"4aa3821a28b0b7c2400bc59aba4bcc0a76e971dadd19610d3ad38c768e124dc7","schema_version":"edge-lab-recorder.raw.v1","sequence":null,"source":"clob_market_ws"}
{"event_at":"2026-07-27T03:18:34.016000Z","event_fingerprint":"1b9a4145029df95bc63eff9abc9e62ec8cbbcbbdda30d9f3e7dad15507849ace","payload":{"connection_id":"c7dc2e4762f849c6b6f9306b6518dcab","event_at":"2026-07-27T03:18:34.016000Z","event_type":"price_change","frame_hash":"3ab3a2d805304463b14c4f46db71740682dad830c904d97051600705b0bd434c","frame_index":0,"kind":"data","monotonic_ns":224297257158333,"payload":{"event_type":"price_change","market":"0x717c0e8ccd4d5c7040185188fbae28be901ca589a11a94b1b38ca36a79eccfeb","price_changes":[{"asset_id":"41448400836309843603620980831210604935021861034693225347475867885462478926555","best_ask":"0.49","best_bid":"0.48","hash":"ea3824df7bde01ff5e1b80b2d0602439ebdbaa58","price":"0.44","side":"BUY","size":"24.6"},{"asset_id":"24254094493625419915756280046002869097156693848522361803041977572204227262166","best_ask":"0.52","best_bid":"0.51","hash":"c290cf33baa8f28dcc1e3d95426f4a9216d984a8","price":"0.56","side":"SELL","size":"24.6"}],"timestamp":"1785122314016"},"payload_hash":"7ca55bea29d5c0f8590bce1b142c6cebc490ce608ab67d58d45ddef1371feffa","raw_frame":"{\"market\":\"0x717c0e8ccd4d5c7040185188fbae28be901ca589a11a94b1b38ca36a79eccfeb\", \"price_changes\":[{\"asset_id\":\"41448400836309843603620980831210604935021861034693225347475867885462478926555\", \"price\":\"0.44\", \"size\":\"24.6\", \"side\":\"BUY\", \"hash\":\"ea3824df7bde01ff5e1b80b2d0602439ebdbaa58\", \"best_bid\":\"0.48\", \"best_ask\":\"0.49\"}, {\"asset_id\":\"24254094493625419915756280046002869097156693848522361803041977572204227262166\", \"price\":\"0.56\", \"size\":\"24.6\", \"side\":\"SELL\", \"hash\":\"c290cf33baa8f28dcc1e3d95426f4a9216d984a8\", \"best_bid\":\"0.51\", \"best_ask\":\"0.52\"}], \"timestamp\":\"1785122314016\", \"event_type\":\"price_change\"}","received_at":"2026-07-27T03:18:33.920493Z","schema_version":"clob-market-ws.price_change.v1","sequence":null,"server_hash":null,"server_timestamp":"1785122314016","session_id":"dd162b8dca5f43ff811d304e69a06123","source":"clob_market_ws"},"received_at":"2026-07-27T03:18:33.920493Z","record_id":"fad6b65417115eeb63c27f69c085d4afe3549492cf5ce95ab449268b2bd940d3","schema_fingerprint":"4aa3821a28b0b7c2400bc59aba4bcc0a76e971dadd19610d3ad38c768e124dc7","schema_version":"edge-lab-recorder.raw.v1","sequence":null,"source":"clob_market_ws"}
{"event_at":"2026-07-27T03:18:34.017000Z","event_fingerprint":"88c8e4e3bee3421491b1c714eb8384b0bb437fab31b3bc289dbe7c6727e0851d","payload":{"connection_id":"c7dc2e4762f849c6b6f9306b6518dcab","event_at":"2026-07-27T03:18:34.017000Z","event_type":"price_change","frame_hash":"48717cbc5d7788e18b62d27a06112ea5b36748336104276fa5ac93b9f79de12f","frame_index":0,"kind":"data","monotonic_ns":224297260534583,"payload":{"event_type":"price_change","market":"0x717c0e8ccd4d5c7040185188fbae28be901ca589a11a94b1b38ca36a79eccfeb","price_changes":[{"asset_id":"24254094493625419915756280046002869097156693848522361803041977572204227262166","best_ask":"0.52","best_bid":"0.51","hash":"cd7e4ce4bcd1331da7e7ab3b89b632ea3d46f72c","price":"0.04","side":"BUY","size":"633.09"},{"asset_id":"41448400836309843603620980831210604935021861034693225347475867885462478926555","best_ask":"0.49","best_bid":"0.48","hash":"97bd35e1b07f06a384e1a5d5583435d885aa407b","price":"0.96","side":"SELL","size":"633.09"}],"timestamp":"1785122314017"},"payload_hash":"cc2f1485e7f179848e6fcd098f4730f7eef6e48f572a19d0c454dcbf29f2f79a","raw_frame":"{\"market\":\"0x717c0e8ccd4d5c7040185188fbae28be901ca589a11a94b1b38ca36a79eccfeb\", \"price_changes\":[{\"asset_id\":\"24254094493625419915756280046002869097156693848522361803041977572204227262166\", \"price\":\"0.04\", \"size\":\"633.09\", \"side\":\"BUY\", \"hash\":\"cd7e4ce4bcd1331da7e7ab3b89b632ea3d46f72c\", \"best_bid\":\"0.51\", \"best_ask\":\"0.52\"}, {\"asset_id\":\"41448400836309843603620980831210604935021861034693225347475867885462478926555\", \"price\":\"0.96\", \"size\":\"633.09\", \"side\":\"SELL\", \"hash\":\"97bd35e1b07f06a384e1a5d5583435d885aa407b\", \"best_bid\":\"0.48\", \"best_ask\":\"0.49\"}], \"timestamp\":\"1785122314017\", \"event_type\":\"price_change\"}","received_at":"2026-07-27T03:18:33.923848Z","schema_version":"clob-market-ws.price_change.v1","sequence":null,"server_hash":null,"server_timestamp":"1785122314017","session_id":"dd162b8dca5f43ff811d304e69a06123","source":"clob_market_ws"},"received_at":"2026-07-27T03:18:33.923848Z","record_id":"953cf4bb3380934fc3e65e1162e6784410c97534c6f0422c1d7f2afcbce33ad3","schema_fingerprint":"4aa3821a28b0b7c2400bc59aba4bcc0a76e971dadd19610d3ad38c768e124dc7","schema_version":"edge-lab-recorder.raw.v1","sequence":null,"source":"clob_market_ws"}
{"event_at":"2026-07-27T03:18:34.020000Z","event_fingerprint":"a26549a1dab64802a26c68db5a6da0a875393cfad6a479462cf62f4b4824d2fa","payload":{"connection_id":"c7dc2e4762f849c6b6f9306b6518dcab","event_at":"2026-07-27T03:18:34.020000Z","event_type":"price_change","frame_hash":"baa6b323177de5cc7f3ff7358ceee15b7ef912024367daad689ea7c5acef3b33","frame_index":0,"kind":"data","monotonic_ns":224297263858041,"payload":{"event_type":"price_change","market":"0x717c0e8ccd4d5c7040185188fbae28be901ca589a11a94b1b38ca36a79eccfeb","price_changes":[{"asset_id":"41448400836309843603620980831210604935021861034693225347475867885462478926555","best_ask":"0.49","best_bid":"0.48","hash":"19c1a6b9c7e38d5aead219e60a134b3831e3c6e9","price":"0.01","side":"BUY","size":"7708.02"},{"asset_id":"24254094493625419915756280046002869097156693848522361803041977572204227262166","best_ask":"0.52","best_bid":"0.51","hash":"811d1796918a662ee24b8c1a4177c3a297358050","price":"0.99","side":"SELL","size":"7708.02"}],"timestamp":"1785122314020"},"payload_hash":"390413cda0cc4b5df4ab46a541782a8278ea45a1a78847482178dd5513a47773","raw_frame":"{\"market\":\"0x717c0e8ccd4d5c7040185188fbae28be901ca589a11a94b1b38ca36a79eccfeb\", \"price_changes\":[{\"asset_id\":\"41448400836309843603620980831210604935021861034693225347475867885462478926555\", \"price\":\"0.01\", \"size\":\"7708.02\", \"side\":\"BUY\", \"hash\":\"19c1a6b9c7e38d5aead219e60a134b3831e3c6e9\", \"best_bid\":\"0.48\", \"best_ask\":\"0.49\"}, {\"asset_id\":\"24254094493625419915756280046002869097156693848522361803041977572204227262166\", \"price\":\"0.99\", \"size\":\"7708.02\", \"side\":\"SELL\", \"hash\":\"811d1796918a662ee24b8c1a4177c3a297358050\", \"best_bid\":\"0.51\", \"best_ask\":\"0.52\"}], \"timestamp\":\"1785122314020\", \"event_type\":\"price_change\"}","received_at":"2026-07-27T03:18:33.927194Z","schema_version":"clob-market-ws.price_change.v1","sequence":null,"server_hash":null,"server_timestamp":"1785122314020","session_id":"dd162b8dca5f43ff811d304e69a06123","source":"clob_market_ws"},"received_at":"2026-07-27T03:18:33.927194Z","record_id":"5f8455fe9a60ea1ea273576e0877d6e77ac16c79e0883b1f01a5687fbafbe9b0","schema_fingerprint":"4aa3821a28b0b7c2400bc59aba4bcc0a76e971dadd19610d3ad38c768e124dc7","schema_version":"edge-lab-recorder.raw.v1","sequence":null,"source":"clob_market_ws"}
{"event_at":"2026-07-27T03:18:34.021000Z","event_fingerprint":"de064d4873fc8e23b91cd41cf62be6905816e4ac54015059f15162531a62d751","payload":{"connection_id":"c7dc2e4762f849c6b6f9306b6518dcab","event_at":"2026-07-27T03:18:34.021000Z","event_type":"price_change","frame_hash":"f10799d6fd501542ddd9b1ecc44c4e28ed41d518c0fb3b90518600b752f586cd","frame_index":0,"kind":"data","monotonic_ns":224297266350750,"payload":{"event_type":"price_change","market":"0x717c0e8ccd4d5c7040185188fbae28be901ca589a11a94b1b38ca36a79eccfeb","price_changes":[{"asset_id":"41448400836309843603620980831210604935021861034693225347475867885462478926555","best_ask":"0.49","best_bid":"0.48","hash":"90f5af70d8139dbe1ee26df8f07de6644dd73a68","price":"0.01","side":"BUY","size":"7713.02"},{"asset_id":"24254094493625419915756280046002869097156693848522361803041977572204227262166","best_ask":"0.52","best_bid":"0.51","hash":"fac568610d044e54460c0a0cffcd43d4aee804ef","price":"0.99","side":"SELL","size":"7713.02"}],"timestamp":"1785122314021"},"payload_hash":"9cf4295b45026db0a0d2e390e898e44967e2c2eb20d72416306134649041dc53","raw_frame":"{\"market\":\"0x717c0e8ccd4d5c7040185188fbae28be901ca589a11a94b1b38ca36a79eccfeb\", \"price_changes\":[{\"asset_id\":\"41448400836309843603620980831210604935021861034693225347475867885462478926555\", \"price\":\"0.01\", \"size\":\"7713.02\", \"side\":\"BUY\", \"hash\":\"90f5af70d8139dbe1ee26df8f07de6644dd73a68\", \"best_bid\":\"0.48\", \"best_ask\":\"0.49\"}, {\"asset_id\":\"24254094493625419915756280046002869097156693848522361803041977572204227262166\", \"price\":\"0.99\", \"size\":\"7713.02\", \"side\":\"SELL\", \"hash\":\"fac568610d044e54460c0a0cffcd43d4aee804ef\", \"best_bid\":\"0.51\", \"best_ask\":\"0.52\"}], \"timestamp\":\"1785122314021\", \"event_type\":\"price_change\"}","received_at":"2026-07-27T03:18:33.929688Z","schema_version":"clob-market-ws.price_change.v1","sequence":null,"server_hash":null,"server_timestamp":"1785122314021","session_id":"dd162b8dca5f43ff811d304e69a06123","source":"clob_market_ws"},"received_at":"2026-07-27T03:18:33.929688Z","record_id":"a084930c730f06ce171b326a66a66b220c52b4d8cdb1c77e08bfdd0f3e5b0add","schema_fingerprint":"4aa3821a28b0b7c2400bc59aba4bcc0a76e971dadd19610d3ad38c768e124dc7","schema_version":"edge-lab-recorder.raw.v1","sequence":null,"source":"clob_market_ws"}
{"event_at":"2026-07-27T03:18:34.041000Z","event_fingerprint":"15b8151ec237c3bd12bd8e0d588a5ebe056e213841cba552e36063227ee5cb66","payload":{"connection_id":"c7dc2e4762f849c6b6f9306b6518dcab","event_at":"2026-07-27T03:18:34.041000Z","event_type":"price_change","frame_hash":"f944b68a762c45cc1deb68ce9bb43b6f088dedd672d820461a46a761f6523176","frame_index":0,"kind":"data","monotonic_ns":224297277673125,"payload":{"event_type":"price_change","market":"0x717c0e8ccd4d5c7040185188fbae28be901ca589a11a94b1b38ca36a79eccfeb","price_changes":[{"asset_id":"41448400836309843603620980831210604935021861034693225347475867885462478926555","best_ask":"0.49","best_bid":"0.48","hash":"24ebd7db5d6a9672a2e85129e422e847087792a8","price":"0.01","side":"BUY","size":"7708.02"},{"asset_id":"24254094493625419915756280046002869097156693848522361803041977572204227262166","best_ask":"0.52","best_bid":"0.51","hash":"f140e1f669d893014696a8fc2fb09bb08f43c737","price":"0.99","side":"SELL","size":"7708.02"}],"timestamp":"1785122314041"},"payload_hash":"ac01c143d8d6216ad33ce53677ecad9028422111431ddf424b25fbd7c3bde17e","raw_frame":"{\"market\":\"0x717c0e8ccd4d5c7040185188fbae28be901ca589a11a94b1b38ca36a79eccfeb\", \"price_changes\":[{\"asset_id\":\"41448400836309843603620980831210604935021861034693225347475867885462478926555\", \"price\":\"0.01\", \"size\":\"7708.02\", \"side\":\"BUY\", \"hash\":\"24ebd7db5d6a9672a2e85129e422e847087792a8\", \"best_bid\":\"0.48\", \"best_ask\":\"0.49\"}, {\"asset_id\":\"24254094493625419915756280046002869097156693848522361803041977572204227262166\", \"price\":\"0.99\", \"size\":\"7708.02\", \"side\":\"SELL\", \"hash\":\"f140e1f669d893014696a8fc2fb09bb08f43c737\", \"best_bid\":\"0.51\", \"best_ask\":\"0.52\"}], \"timestamp\":\"1785122314041\", \"event_type\":\"price_change\"}","received_at":"2026-07-27T03:18:33.941007Z","schema_version":"clob-market-ws.price_change.v1","sequence":null,"server_hash":null,"server_timestamp":"1785122314041","session_id":"dd162b8dca5f43ff811d304e69a06123","source":"clob_market_ws"},"received_at":"2026-07-27T03:18:33.941007Z","record_id":"c0ec33dc3acef16a4db5e21140b96f1478a74970223dcc2ede287d5aa4403060","schema_fingerprint":"4aa3821a28b0b7c2400bc59aba4bcc0a76e971dadd19610d3ad38c768e124dc7","schema_version":"edge-lab-recorder.raw.v1","sequence":null,"source":"clob_market_ws"}
{"event_at":"2026-07-27T03:18:34.052000Z","event_fingerprint":"d07435c22795c463996a7581abd8fa1660a2fa9b1f3443362a4636a21c0ffbee","payload":{"connection_id":"c7dc2e4762f849c6b6f9306b6518dcab","event_at":"2026-07-27T03:18:34.052000Z","event_type":"price_change","frame_hash":"de03b77a6611c639627a4d4b9a91d3b081abb8a5fece53df07573de11bca360f","frame_index":0,"kind":"data","monotonic_ns":224297288873375,"payload":{"event_type":"price_change","market":"0x717c0e8ccd4d5c7040185188fbae28be901ca589a11a94b1b38ca36a79eccfeb","price_changes":[{"asset_id":"24254094493625419915756280046002869097156693848522361803041977572204227262166","best_ask":"0.52","best_bid":"0.51","hash":"01ffc97ed88c80a7acb5e27f714ffe8bbe292ee8","price":"0.01","side":"BUY","size":"7713.02"},{"asset_id":"41448400836309843603620980831210604935021861034693225347475867885462478926555","best_ask":"0.49","best_bid":"0.48","hash":"e3174b2798b790ecdba74149e2db01586c91dece","price":"0.99","side":"SELL","size":"7713.02"}],"timestamp":"1785122314052"},"payload_hash":"96d3eac00cfbc0c57448b59753423425c14b986ba96e3829598338861befb6b5","raw_frame":"{\"market\":\"0x717c0e8ccd4d5c7040185188fbae28be901ca589a11a94b1b38ca36a79eccfeb\", \"price_changes\":[{\"asset_id\":\"24254094493625419915756280046002869097156693848522361803041977572204227262166\", \"price\":\"0.01\", \"size\":\"7713.02\", \"side\":\"BUY\", \"hash\":\"01ffc97ed88c80a7acb5e27f714ffe8bbe292ee8\", \"best_bid\":\"0.51\", \"best_ask\":\"0.52\"}, {\"asset_id\":\"41448400836309843603620980831210604935021861034693225347475867885462478926555\", \"price\":\"0.99\", \"size\":\"7713.02\", \"side\":\"SELL\", \"hash\":\"e3174b2798b790ecdba74149e2db01586c91dece\", \"best_bid\":\"0.48\", \"best_ask\":\"0.49\"}], \"timestamp\":\"1785122314052\", \"event_type\":\"price_change\"}","received_at":"2026-07-27T03:18:33.952210Z","schema_version":"clob-market-ws.price_change.v1","sequence":null,"server_hash":null,"server_timestamp":"1785122314052","session_id":"dd162b8dca5f43ff811d304e69a06123","source":"clob_market_ws"},"received_at":"2026-07-27T03:18:33.952210Z","record_id":"8b37adf5275f607e27495da7e75425518edd4c1540569d713856a27b3b490304","schema_fingerprint":"4aa3821a28b0b7c2400bc59aba4bcc0a76e971dadd19610d3ad38c768e124dc7","schema_version":"edge-lab-recorder.raw.v1","sequence":null,"source":"clob_market_ws"}
{"event_at":"2026-07-27T03:18:34.065000Z","event_fingerprint":"69661833b8cf576fe5f9f14ce1b8faad2276e450a3064ae1deb584b8dfa1e1b9","payload":{"connection_id":"c7dc2e4762f849c6b6f9306b6518dcab","event_at":"2026-07-27T03:18:34.065000Z","event_type":"price_change","frame_hash":"52fccaebdae3049a15c5cfc152bb0e3cf36fedcf77a3a4c74b697c4fa4489f7a","frame_index":0,"kind":"data","monotonic_ns":224297300837041,"payload":{"event_type":"price_change","market":"0x717c0e8ccd4d5c7040185188fbae28be901ca589a11a94b1b38ca36a79eccfeb","price_changes":[{"asset_id":"24254094493625419915756280046002869097156693848522361803041977572204227262166","best_ask":"0.52","best_bid":"0.51","hash":"2e5840429ef15f01a095b787b6c807656ecee07e","price":"0.04","side":"BUY","size":"628.09"},{"asset_id":"41448400836309843603620980831210604935021861034693225347475867885462478926555","best_ask":"0.49","best_bid":"0.48","hash":"a26074f42f23898994455f53f316b0d75649c882","price":"0.96","side":"SELL","size":"628.09"}],"timestamp":"1785122314065"},"payload_hash":"c8585cca23bd9bd90f2516360f4a9b3faee084dd770ea50bba9d610a9c50a6b8","raw_frame":"{\"market\":\"0x717c0e8ccd4d5c7040185188fbae28be901ca589a11a94b1b38ca36a79eccfeb\", \"price_changes\":[{\"asset_id\":\"24254094493625419915756280046002869097156693848522361803041977572204227262166\", \"price\":\"0.04\", \"size\":\"628.09\", \"side\":\"BUY\", \"hash\":\"2e5840429ef15f01a095b787b6c807656ecee07e\", \"best_bid\":\"0.51\", \"best_ask\":\"0.52\"}, {\"asset_id\":\"41448400836309843603620980831210604935021861034693225347475867885462478926555\", \"price\":\"0.96\", \"size\":\"628.09\", \"side\":\"SELL\", \"hash\":\"a26074f42f23898994455f53f316b0d75649c882\", \"best_bid\":\"0.48\", \"best_ask\":\"0.49\"}], \"timestamp\":\"1785122314065\", \"event_type\":\"price_change\"}","received_at":"2026-07-27T03:18:33.964172Z","schema_version":"clob-market-ws.price_change.v1","sequence":null,"server_hash":null,"server_timestamp":"1785122314065","session_id":"dd162b8dca5f43ff811d304e69a06123","source":"clob_market_ws"},"received_at":"2026-07-27T03:18:33.964172Z","record_id":"ae5fa17561704ada37b4db34b797cd38fd2f7f6871f43edd4b77da69b4965440","schema_fingerprint":"4aa3821a28b0b7c2400bc59aba4bcc0a76e971dadd19610d3ad38c768e124dc7","schema_version":"edge-lab-recorder.raw.v1","sequence":null,"source":"clob_market_ws"}
{"event_at":"2026-07-27T03:18:34.071000Z","event_fingerprint":"0cd22f521ed48e43b8cadd1fea1366c8bf564aaec9e745202f274fd7a7fffe1a","payload":{"connection_id":"c7dc2e4762f849c6b6f9306b6518dcab","event_at":"2026-07-27T03:18:34.071000Z","event_type":"price_change","frame_hash":"2f2f0ab5813815e8c4dcf1687d841c68fc8e52c19a673cfd17f0fbf4f15cd0a0","frame_index":0,"kind":"data","monotonic_ns":224297306593500,"payload":{"event_type":"price_change","market":"0x717c0e8ccd4d5c7040185188fbae28be901ca589a11a94b1b38ca36a79eccfeb","price_changes":[{"asset_id":"24254094493625419915756280046002869097156693848522361803041977572204227262166","best_ask":"0.52","best_bid":"0.51","hash":"800c40631935b3b704a1ce7c76d50f2d9893815a","price":"0.01","side":"BUY","size":"7708.02"},{"asset_id":"41448400836309843603620980831210604935021861034693225347475867885462478926555","best_ask":"0.49","best_bid":"0.48","hash":"cea1fd3f4ad2ebdf88b7409d50c61269ed80b996","price":"0.99","side":"SELL","size":"7708.02"}],"timestamp":"1785122314071"},"payload_hash":"abd35ddee07f83df2cf88ba35df13986b4b70843a8ae281dff8ac96c928f892d","raw_frame":"{\"market\":\"0x717c0e8ccd4d5c7040185188fbae28be901ca589a11a94b1b38ca36a79eccfeb\", \"price_changes\":[{\"asset_id\":\"24254094493625419915756280046002869097156693848522361803041977572204227262166\", \"price\":\"0.01\", \"size\":\"7708.02\", \"side\":\"BUY\", \"hash\":\"800c40631935b3b704a1ce7c76d50f2d9893815a\", \"best_bid\":\"0.51\", \"best_ask\":\"0.52\"}, {\"asset_id\":\"41448400836309843603620980831210604935021861034693225347475867885462478926555\", \"price\":\"0.99\", \"size\":\"7708.02\", \"side\":\"SELL\", \"hash\":\"cea1fd3f4ad2ebdf88b7409d50c61269ed80b996\", \"best_bid\":\"0.48\", \"best_ask\":\"0.49\"}], \"timestamp\":\"1785122314071\", \"event_type\":\"price_change\"}","received_at":"2026-07-27T03:18:33.969928Z","schema_version":"clob-market-ws.price_change.v1","sequence":null,"server_hash":null,"server_timestamp":"1785122314071","session_id":"dd162b8dca5f43ff811d304e69a06123","source":"clob_market_ws"},"received_at":"2026-07-27T03:18:33.969928Z","record_id":"7f0d3803bc702b35eed5812eb27c6486953e10007a9bcd5d1525e9e88c45be70","schema_fingerprint":"4aa3821a28b0b7c2400bc59aba4bcc0a76e971dadd19610d3ad38c768e124dc7","schema_version":"edge-lab-recorder.raw.v1","sequence":null,"source":"clob_market_ws"}
{"event_at":"2026-07-27T03:18:34.086000Z","event_fingerprint":"519f041f9b36cbc696f5f2bbc40301c0f87407fcebc568df0e3ddb967bb378c8","payload":{"connection_id":"c7dc2e4762f849c6b6f9306b6518dcab","event_at":"2026-07-27T03:18:34.086000Z","event_type":"price_change","frame_hash":"039fab660b5aab1ae114ebc7afad5a5250df383e105a4e62c99ad288899b1843","frame_index":0,"kind":"data","monotonic_ns":224297320080916,"payload":{"event_type":"price_change","market":"0x717c0e8ccd4d5c7040185188fbae28be901ca589a11a94b1b38ca36a79eccfeb","price_changes":[{"asset_id":"24254094493625419915756280046002869097156693848522361803041977572204227262166","best_ask":"0.52","best_bid":"0.51","hash":"89cd7092c81ef7684cf2765fbf26975d77dc4f3c","price":"0.36","side":"BUY","size":"303.18"},{"asset_id":"41448400836309843603620980831210604935021861034693225347475867885462478926555","best_ask":"0.49","best_bid":"0.48","hash":"50cb00121aa6835338da29c84656cecb4fecb0b4","price":"0.64","side":"SELL","size":"303.18"}],"timestamp":"1785122314086"},"payload_hash":"84d0c84af827dbc2179fbedceb454ef6145feb03239c4978b788e001456ac712","raw_frame":"{\"market\":\"0x717c0e8ccd4d5c7040185188fbae28be901ca589a11a94b1b38ca36a79eccfeb\", \"price_changes\":[{\"asset_id\":\"24254094493625419915756280046002869097156693848522361803041977572204227262166\", \"price\":\"0.36\", \"size\":\"303.18\", \"side\":\"BUY\", \"hash\":\"89cd7092c81ef7684cf2765fbf26975d77dc4f3c\", \"best_bid\":\"0.51\", \"best_ask\":\"0.52\"}, {\"asset_id\":\"41448400836309843603620980831210604935021861034693225347475867885462478926555\", \"price\":\"0.64\", \"size\":\"303.18\", \"side\":\"SELL\", \"hash\":\"50cb00121aa6835338da29c84656cecb4fecb0b4\", \"best_bid\":\"0.48\", \"best_ask\":\"0.49\"}], \"timestamp\":\"1785122314086\", \"event_type\":\"price_change\"}","received_at":"2026-07-27T03:18:33.983415Z","schema_version":"clob-market-ws.price_change.v1","sequence":null,"server_hash":null,"server_timestamp":"1785122314086","session_id":"dd162b8dca5f43ff811d304e69a06123","source":"clob_market_ws"},"received_at":"2026-07-27T03:18:33.983415Z","record_id":"45ae74271e24069e5234d3ab886072039ae105205e0e72c3b428dacdeda87f70","schema_fingerprint":"4aa3821a28b0b7c2400bc59aba4bcc0a76e971dadd19610d3ad38c768e124dc7","schema_version":"edge-lab-recorder.raw.v1","sequence":null,"source":"clob_market_ws"}
{"event_at":"2026-07-27T03:18:34.086000Z","event_fingerprint":"7f5786273e024f9c147f69733bb2d382dfcf29d5950c6d5fa8f6c722987dc0ab","payload":{"connection_id":"c7dc2e4762f849c6b6f9306b6518dcab","event_at":"2026-07-27T03:18:34.086000Z","event_type":"price_change","frame_hash":"c25b128e6425e4a4b8b05333c74da9775e4a6cda06eb2791c72cc2d2c073e187","frame_index":0,"kind":"data","monotonic_ns":224297323175833,"payload":{"event_type":"price_change","market":"0x717c0e8ccd4d5c7040185188fbae28be901ca589a11a94b1b38ca36a79eccfeb","price_changes":[{"asset_id":"41448400836309843603620980831210604935021861034693225347475867885462478926555","best_ask":"0.49","best_bid":"0.48","hash":"0bc051beded20363149a96227283112b5be241af","price":"0.28","side":"BUY","size":"356.78"},{"asset_id":"24254094493625419915756280046002869097156693848522361803041977572204227262166","best_ask":"0.52","best_bid":"0.51","hash":"4ccd8ed6dc68ad53e049e8a60e589ba47612aced","price":"0.72","side":"SELL","size":"356.78"}],"timestamp":"1785122314086"},"payload_hash":"b86d5a6a831b84eadb3edc6a442ca09d543fc83bb691b91b2a2e059b997b89c9","raw_frame":"{\"market\":\"0x717c0e8ccd4d5c7040185188fbae28be901ca589a11a94b1b38ca36a79eccfeb\", \"price_changes\":[{\"asset_id\":\"41448400836309843603620980831210604935021861034693225347475867885462478926555\", \"price\":\"0.28\", \"size\":\"356.78\", \"side\":\"BUY\", \"hash\":\"0bc051beded20363149a96227283112b5be241af\", \"best_bid\":\"0.48\", \"best_ask\":\"0.49\"}, {\"asset_id\":\"24254094493625419915756280046002869097156693848522361803041977572204227262166\", \"price\":\"0.72\", \"size\":\"356.78\", \"side\":\"SELL\", \"hash\":\"4ccd8ed6dc68ad53e049e8a60e589ba47612aced\", \"best_bid\":\"0.51\", \"best_ask\":\"0.52\"}], \"timestamp\":\"1785122314086\", \"event_type\":\"price_change\"}","received_at":"2026-07-27T03:18:33.986512Z","schema_version":"clob-market-ws.price_change.v1","sequence":null,"server_hash":null,"server_timestamp":"1785122314086","session_id":"dd162b8dca5f43ff811d304e69a06123","source":"clob_market_ws"},"received_at":"2026-07-27T03:18:33.986512Z","record_id":"d09c214adce412c75da2975746f577b6a28eddd6101ae92cb34d0a1228390249","schema_fingerprint":"4aa3821a28b0b7c2400bc59aba4bcc0a76e971dadd19610d3ad38c768e124dc7","schema_version":"edge-lab-recorder.raw.v1","sequence":null,"source":"clob_market_ws"}
{"event_at":"2026-07-27T03:18:34.086000Z","event_fingerprint":"f938809e7002a7fdf9f090c9a8490cdaa2af11dd91a419d99a44eda0093918dd","payload":{"connection_id":"c7dc2e4762f849c6b6f9306b6518dcab","event_at":"2026-07-27T03:18:34.086000Z","event_type":"price_change","frame_hash":"99be4c58461ab5ade5a575b2092001f50dc193eafb13898c90a57976d304448d","frame_index":0,"kind":"data","monotonic_ns":224297324709875,"payload":{"event_type":"price_change","market":"0x717c0e8ccd4d5c7040185188fbae28be901ca589a11a94b1b38ca36a79eccfeb","price_changes":[{"asset_id":"24254094493625419915756280046002869097156693848522361803041977572204227262166","best_ask":"0.52","best_bid":"0.51","hash":"e6d92405e8afacdf0819a1baf50b7c68efdfe00d","price":"0.36","side":"BUY","size":"210.59"},{"asset_id":"41448400836309843603620980831210604935021861034693225347475867885462478926555","best_ask":"0.49","best_bid":"0.48","hash":"72e36b1be5b32ce7a76a77c695df0ad675f30636","price":"0.64","side":"SELL","size":"210.59"}],"timestamp":"1785122314086"},"payload_hash":"1224554e7b2582cbf683d40e73f29416fc1fedcab6e9a8dfd6c898e6a310962d","raw_frame":"{\"market\":\"0x717c0e8ccd4d5c7040185188fbae28be901ca589a11a94b1b38ca36a79eccfeb\", \"price_changes\":[{\"asset_id\":\"24254094493625419915756280046002869097156693848522361803041977572204227262166\", \"price\":\"0.36\", \"size\":\"210.59\", \"side\":\"BUY\", \"hash\":\"e6d92405e8afacdf0819a1baf50b7c68efdfe00d\", \"best_bid\":\"0.51\", \"best_ask\":\"0.52\"}, {\"asset_id\":\"41448400836309843603620980831210604935021861034693225347475867885462478926555\", \"price\":\"0.64\", \"size\":\"210.59\", \"side\":\"SELL\", \"hash\":\"72e36b1be5b32ce7a76a77c695df0ad675f30636\", \"best_bid\":\"0.48\", \"best_ask\":\"0.49\"}], \"timestamp\":\"1785122314086\", \"event_type\":\"price_change\"}","received_at":"2026-07-27T03:18:33.988047Z","schema_version":"clob-market-ws.price_change.v1","sequence":null,"server_hash":null,"server_timestamp":"1785122314086","session_id":"dd162b8dca5f43ff811d304e69a06123","source":"clob_market_ws"},"received_at":"2026-07-27T03:18:33.988047Z","record_id":"a590862235cff704a6aea5335e03eafb666347343c89240f3b75fa0d10c5ef80","schema_fingerprint":"4aa3821a28b0b7c2400bc59aba4bcc0a76e971dadd19610d3ad38c768e124dc7","schema_version":"edge-lab-recorder.raw.v1","sequence":null,"source":"clob_market_ws"}
