{"event_at":"2026-07-27T03:20:42.943000Z","event_fingerprint":"a176c6957d3d8ddd3a43b88372164cfe6818c58fa8a29cca5936a76db4e4a3e7","payload":{"connection_id":"c7dc2e4762f849c6b6f9306b6518dcab","event_at":"2026-07-27T03:20:42.943000Z","event_type":"price_change","frame_hash":"625ad831d62077194544e90f00751e4e60e88c10645bc36c41dbaf5cf5544c6f","frame_index":0,"kind":"data","monotonic_ns":224426179167083,"payload":{"event_type":"price_change","market":"0x717c0e8ccd4d5c7040185188fbae28be901ca589a11a94b1b38ca36a79eccfeb","price_changes":[{"asset_id":"24254094493625419915756280046002869097156693848522361803041977572204227262166","best_ask":"0.43","best_bid":"0.42","hash":"e386599b0375913051b4fec578af425303e21109","price":"0.25","side":"BUY","size":"150"},{"asset_id":"41448400836309843603620980831210604935021861034693225347475867885462478926555","best_ask":"0.58","best_bid":"0.57","hash":"28b590b42fdeeec5ab4fb57b73ccb37081e6a008","price":"0.75","side":"SELL","size":"150"}],"timestamp":"1785122442943"},"payload_hash":"8cf8df17b26b70d1f3080221b952d84d7eb3f2eed5408d8e52179894a3b3dde4","raw_frame":"{\"market\":\"0x717c0e8ccd4d5c7040185188fbae28be901ca589a11a94b1b38ca36a79eccfeb\", \"price_changes\":[{\"asset_id\":\"24254094493625419915756280046002869097156693848522361803041977572204227262166\", \"price\":\"0.25\", \"size\":\"150\", \"side\":\"BUY\", \"hash\":\"e386599b0375913051b4fec578af425303e21109\", \"best_bid\":\"0.42\", \"best_ask\":\"0.43\"}, {\"asset_id\":\"41448400836309843603620980831210604935021861034693225347475867885462478926555\", \"price\":\"0.75\", \"size\":\"150\", \"side\":\"SELL\", \"hash\":\"28b590b42fdeeec5ab4fb57b73ccb37081e6a008\", \"best_bid\":\"0.57\", \"best_ask\":\"0.58\"}], \"timestamp\":\"1785122442943\", \"event_type\":\"price_change\"}","received_at":"2026-07-27T03:20:42.824860Z","schema_version":"clob-market-ws.price_change.v1","sequence":null,"server_hash":null,"server_timestamp":"1785122442943","session_id":"dd162b8dca5f43ff811d304e69a06123","source":"clob_market_ws"},"received_at":"2026-07-27T03:20:42.824860Z","record_id":"67aafab44d796fadbca4741f3d72c0225cd604909e9b3c1dcad158a2223526e5","schema_fingerprint":"4aa3821a28b0b7c2400bc59aba4bcc0a76e971dadd19610d3ad38c768e124dc7","schema_version":"edge-lab-recorder.raw.v1","sequence":null,"source":"clob_market_ws"}
{"event_at":"2026-07-27T03:20:42.967000Z","event_fingerprint":"d09a81cbdc2c7a82c1cb8dfc0aecfde2ab78caa63f0a62d11c20b45f66b2d89e","payload":{"connection_id":"c7dc2e4762f849c6b6f9306b6518dcab","event_at":"2026-07-27T03:20:42.967000Z","event_type":"price_change","frame_hash":"a79d100503900b04747d98e1d39f1092ad080643e2477743bf9b0e41797947e1","frame_index":0,"kind":"data","monotonic_ns":224426204276750,"payload":{"event_type":"price_change","market":"0x717c0e8ccd4d5c7040185188fbae28be901ca589a11a94b1b38ca36a79eccfeb","price_changes":[{"asset_id":"41448400836309843603620980831210604935021861034693225347475867885462478926555","best_ask":"0.58","best_bid":"0.57","hash":"8a8a2467026b52665aceb36574cd288b903b5643","price":"0.5","side":"BUY","size":"127"},{"asset_id":"24254094493625419915756280046002869097156693848522361803041977572204227262166","best_ask":"0.43","best_bid":"0.42","hash":"f74e3381de4b8995ba1ebf8b09c434e1dd9310d2","price":"0.5","side":"SELL","size":"127"}],"timestamp":"1785122442967"},"payload_hash":"6573649dc281a646933d7a7250b0b0630cafc660f124160374bcef71beffa5a9","raw_frame":"{\"market\":\"0x717c0e8ccd4d5c7040185188fbae28be901ca589a11a94b1b38ca36a79eccfeb\", \"price_changes\":[{\"asset_id\":\"41448400836309843603620980831210604935021861034693225347475867885462478926555\", \"price\":\"0.5\", \"size\":\"127\", \"side\":\"BUY\", \"hash\":\"8a8a2467026b52665aceb36574cd288b903b5643\", \"best_bid\":\"0.57\", \"best_ask\":\"0.58\"}, {\"asset_id\":\"24254094493625419915756280046002869097156693848522361803041977572204227262166\", \"price\":\"0.5\", \"size\":\"127\", \"side\":\"SELL\", \"hash\":\"f74e3381de4b8995ba1ebf8b09c434e1dd9310d2\", \"best_bid\":\"0.42\", \"best_ask\":\"0.43\"}], \"timestamp\":\"1785122442967\", \"event_type\":\"price_change\"}","received_at":"2026-07-27T03:20:42.849970Z","schema_version":"clob-market-ws.price_change.v1","sequence":null,"server_hash":null,"server_timestamp":"1785122442967","session_id":"dd162b8dca5f43ff811d304e69a06123","source":"clob_market_ws"},"received_at":"2026-07-27T03:20:42.849970Z","record_id":"a8b488147a6f7a4410ef727e2812ca975ac9622fde736a61a35af76a233aab6e","schema_fingerprint":"4aa3821a28b0b7c2400bc59aba4bcc0a76e971dadd19610d3ad38c768e124dc7","schema_version":"edge-lab-recorder.raw.v1","sequence":null,"source":"clob_market_ws"}
{"event_at":"2026-07-27T03:20:42.967000Z","event_fingerprint":"92107b70e37afbfb32465049ef5c2f2b2652343abe839fe191b9d50451c8e15d","payload":{"connection_id":"c7dc2e4762f849c6b6f9306b6518dcab","event_at":"2026-07-27T03:20:42.967000Z","event_type":"price_change","frame_hash":"ac371f77311f3384c73bbd82953a5df1c5a2a0ecb7006c77bffdc1d2a0aea93b","frame_index":0,"kind":"data","monotonic_ns":224426207209208,"payload":{"event_type":"price_change","market":"0x717c0e8ccd4d5c7040185188fbae28be901ca589a11a94b1b38ca36a79eccfeb","price_changes":[{"asset_id":"41448400836309843603620980831210604935021861034693225347475867885462478926555","best_ask":"0.58","best_bid":"0.57","hash":"8a8a2467026b52665aceb36574cd288b903b5643","price":"0.55","side":"BUY","size":"279"},{"asset_id":"24254094493625419915756280046002869097156693848522361803041977572204227262166","best_ask":"0.43","best_bid":"0.42","hash":"f74e3381de4b8995ba1ebf8b09c434e1dd9310d2","price":"0.45","side":"SELL","size":"279"}],"timestamp":"1785122442967"},"payload_hash":"0f85bfb890d8ae020e881e309d077539414f5fafc4596b504b679cbd2e671c9f","raw_frame":"{\"market\":\"0x717c0e8ccd4d5c7040185188fbae28be901ca589a11a94b1b38ca36a79eccfeb\", \"price_changes\":[{\"asset_id\":\"41448400836309843603620980831210604935021861034693225347475867885462478926555\", \"price\":\"0.55\", \"size\":\"279\", \"side\":\"BUY\", \"hash\":\"8a8a2467026b52665aceb36574cd288b903b5643\", \"best_bid\":\"0.57\", \"best_ask\":\"0.58\"}, {\"asset_id\":\"24254094493625419915756280046002869097156693848522361803041977572204227262166\", \"price\":\"0.45\", \"size\":\"279\", \"side\":\"SELL\", \"hash\":\"f74e3381de4b8995ba1ebf8b09c434e1dd9310d2\", \"best_bid\":\"0.42\", \"best_ask\":\"0.43\"}], \"timestamp\":\"1785122442967\", \"event_type\":\"price_change\"}","received_at":"2026-07-27T03:20:42.852903Z","schema_version":"clob-market-ws.price_change.v1","sequence":null,"server_hash":null,"server_timestamp":"1785122442967","session_id":"dd162b8dca5f43ff811d304e69a06123","source":"clob_market_ws"},"received_at":"2026-07-27T03:20:42.852903Z","record_id":"2497879312cdf3162862d9acfd49eafc7bd53d11f35e3c1580313815aff09671","schema_fingerprint":"4aa3821a28b0b7c2400bc59aba4bcc0a76e971dadd19610d3ad38c768e124dc7","schema_version":"edge-lab-recorder.raw.v1","sequence":null,"source":"clob_market_ws"}
{"event_at":"2026-07-27T03:20:42.968000Z","event_fingerprint":"fcd8e2e409da8b41921414683d0608b62b3fe359a99869720b1a6d70ea38fb22","payload":{"connection_id":"c7dc2e4762f849c6b6f9306b6518dcab","event_at":"2026-07-27T03:20:42.968000Z","event_type":"price_change","frame_hash":"002053c8750d89d442818e97147bf6a7b9863e36333945c6e9a414b59490d7f2","frame_index":0,"kind":"data","monotonic_ns":224426209925166,"payload":{"event_type":"price_change","market":"0x717c0e8ccd4d5c7040185188fbae28be901ca589a11a94b1b38ca36a79eccfeb","price_changes":[{"asset_id":"41448400836309843603620980831210604935021861034693225347475867885462478926555","best_ask":"0.58","best_bid":"0.57","hash":"f3622358878d250bc446f8316be4baa184a86e7e","price":"0.01","side":"BUY","size":"5703.02"},{"asset_id":"24254094493625419915756280046002869097156693848522361803041977572204227262166","best_ask":"0.43","best_bid":"0.42","hash":"04f7ac959fae99b44723ef176aa350b0380e0fed","price":"0.99","side":"SELL","size":"5703.02"}],"timestamp":"1785122442968"},"payload_hash":"37df58e2114703e1963b16866295b2d15e11ad9b6a6220cb0d5cfa0efc6b1f62","raw_frame":"{\"market\":\"0x717c0e8ccd4d5c7040185188fbae28be901ca589a11a94b1b38ca36a79eccfeb\", \"price_changes\":[{\"asset_id\":\"41448400836309843603620980831210604935021861034693225347475867885462478926555\", \"price\":\"0.01\", \"size\":\"5703.02\", \"side\":\"BUY\", \"hash\":\"f3622358878d250bc446f8316be4baa184a86e7e\", \"best_bid\":\"0.57\", \"best_ask\":\"0.58\"}, {\"asset_id\":\"24254094493625419915756280046002869097156693848522361803041977572204227262166\", \"price\":\"0.99\", \"size\":\"5703.02\", \"side\":\"SELL\", \"hash\":\"04f7ac959fae99b44723ef176aa350b0380e0fed\", \"best_bid\":\"0.42\", \"best_ask\":\"0.43\"}], \"timestamp\":\"1785122442968\", \"event_type\":\"price_change\"}","received_at":"2026-07-27T03:20:42.855604Z","schema_version":"clob-market-ws.price_change.v1","sequence":null,"server_hash":null,"server_timestamp":"1785122442968","session_id":"dd162b8dca5f43ff811d304e69a06123","source":"clob_market_ws"},"received_at":"2026-07-27T03:20:42.855604Z","record_id":"f2819e429d4e236b96c8b8b932b0a16090fba2fd174c2e43426a6d04022a7d65","schema_fingerprint":"4aa3821a28b0b7c2400bc59aba4bcc0a76e971dadd19610d3ad38c768e124dc7","schema_version":"edge-lab-recorder.raw.v1","sequence":null,"source":"clob_market_ws"}
{"event_at":"2026-07-27T03:20:42.969000Z","event_fingerprint":"71ffe7348221eea62d6e29fb66a71760cf3e17339bb9d33ce61391eaacd73fef","payload":{"connection_id":"c7dc2e4762f849c6b6f9306b6518dcab","event_at":"2026-07-27T03:20:42.969000Z","event_type":"price_change","frame_hash":"6095c62cf9202264240ed3f46d5232f94229139ea812bb89b53843865a4799d1","frame_index":0,"kind":"data","monotonic_ns":224426213101291,"payload":{"event_type":"price_change","market":"0x717c0e8ccd4d5c7040185188fbae28be901ca589a11a94b1b38ca36a79eccfeb","price_changes":[{"asset_id":"24254094493625419915756280046002869097156693848522361803041977572204227262166","best_ask":"0.43","best_bid":"0.42","hash":"903c092bc8d2a155b99f3366de85371fa68ae6c2","price":"0.26","side":"BUY","size":"532.2"},{"asset_id":"41448400836309843603620980831210604935021861034693225347475867885462478926555","best_ask":"0.58","best_bid":"0.57","hash":"b2fe0b9d1709a587a423ed89c1922c58c38334e8","price":"0.74","side":"SELL","size":"532.2"}],"timestamp":"1785122442969"},"payload_hash":"f1592b519fe482fbaa77891cc667ab0f10112c166c17cbb9a736854befc9226e","raw_frame":"{\"market\":\"0x717c0e8ccd4d5c7040185188fbae28be901ca589a11a94b1b38ca36a79eccfeb\", \"price_changes\":[{\"asset_id\":\"24254094493625419915756280046002869097156693848522361803041977572204227262166\", \"price\":\"0.26\", \"size\":\"532.2\", \"side\":\"BUY\", \"hash\":\"903c092bc8d2a155b99f3366de85371fa68ae6c2\", \"best_bid\":\"0.42\", \"best_ask\":\"0.43\"}, {\"asset_id\":\"41448400836309843603620980831210604935021861034693225347475867885462478926555\", \"price\":\"0.74\", \"size\":\"532.2\", \"side\":\"SELL\", \"hash\":\"b2fe0b9d1709a587a423ed89c1922c58c38334e8\", \"best_bid\":\"0.57\", \"best_ask\":\"0.58\"}], \"timestamp\":\"1785122442969\", \"event_type\":\"price_change\"}","received_at":"2026-07-27T03:20:42.858796Z","schema_version":"clob-market-ws.price_change.v1","sequence":null,"server_hash":null,"server_timestamp":"1785122442969","session_id":"dd162b8dca5f43ff811d304e69a06123","source":"clob_market_ws"},"received_at":"2026-07-27T03:20:42.858796Z","record_id":"8fe9f19e1ea45f57064c666cc882a083dfbdcf1141a0325adb13df421a6f7e33","schema_fingerprint":"4aa3821a28b0b7c2400bc59aba4bcc0a76e971dadd19610d3ad38c768e124dc7","schema_version":"edge-lab-recorder.raw.v1","sequence":null,"source":"clob_market_ws"}
{"event_at":"2026-07-27T03:20:42.972000Z","event_fingerprint":"8dba7c63a2713d7ae2d157387a8a199e4d1231dee72b832dd06e83398b67b295","payload":{"connection_id":"c7dc2e4762f849c6b6f9306b6518dcab","event_at":"2026-07-27T03:20:42.972000Z","event_type":"price_change","frame_hash":"05166c12ba0314eb8b8d975650e659bbd2f70df561fc39af38743a467e891e35","frame_index":0,"kind":"data","monotonic_ns":224426217320500,"payload":{"event_type":"price_change","market":"0x717c0e8ccd4d5c7040185188fbae28be901ca589a11a94b1b38ca36a79eccfeb","price_changes":[{"asset_id":"41448400836309843603620980831210604935021861034693225347475867885462478926555","best_ask":"0.58","best_bid":"0.57","hash":"f6b21a669cf7ac596372447d1470e1fd6d69f96f","price":"0.54","side":"BUY","size":"115"},{"asset_id":"24254094493625419915756280046002869097156693848522361803041977572204227262166","best_ask":"0.43","best_bid":"0.42","hash":"e852e9d3123ef85fe685c0aae9d882b905714d1f","price":"0.46","side":"SELL","size":"115"}],"timestamp":"1785122442972"},"payload_hash":"c3e45edf42c56c1d5c3d20c6e501107822f069fb552a5caaa66db27e6f295102","raw_frame":"{\"market\":\"0x717c0e8ccd4d5c7040185188fbae28be901ca589a11a94b1b38ca36a79eccfeb\", \"price_changes\":[{\"asset_id\":\"41448400836309843603620980831210604935021861034693225347475867885462478926555\", \"price\":\"0.54\", \"size\":\"115\", \"side\":\"BUY\", \"hash\":\"f6b21a669cf7ac596372447d1470e1fd6d69f96f\", \"best_bid\":\"0.57\", \"best_ask\":\"0.58\"}, {\"asset_id\":\"24254094493625419915756280046002869097156693848522361803041977572204227262166\", \"price\":\"0.46\", \"size\":\"115\", \"side\":\"SELL\", \"hash\":\"e852e9d3123ef85fe685c0aae9d882b905714d1f\", \"best_bid\":\"0.42\", \"best_ask\":\"0.43\"}], \"timestamp\":\"1785122442972\", \"event_type\":\"price_change\"}","received_at":"2026-07-27T03:20:42.863014Z","schema_version":"clob-market-ws.price_change.v1","sequence":null,"server_hash":null,"server_timestamp":"1785122442972","session_id":"dd162b8dca5f43ff811d304e69a06123","source":"clob_market_ws"},"received_at":"2026-07-27T03:20:42.863014Z","record_id":"3fed8bb659ef4602efa8a93365220406307d312951551f6af318cdfd73cfe387","schema_fingerprint":"4aa3821a28b0b7c2400bc59aba4bcc0a76e971dadd19610d3ad38c768e124dc7","schema_version":"edge-lab-recorder.raw.v1","sequence":null,"source":"clob_market_ws"}
{"event_at":"2026-07-27T03:20:43.021000Z","event_fingerprint":"1cbf11835eaca5f7d6c9fb4c155cd7fda16d330476a335fd3896b4067cd34a9e","payload":{"connection_id":"c7dc2e4762f849c6b6f9306b6518dcab","event_at":"2026-07-27T03:20:43.021000Z","event_type":"price_change","frame_hash":"8b1043a66e5955e04aa3ce69044376d8c3769a4da63817ac5ac7b0144b7c563f","frame_index":0,"kind":"data","monotonic_ns":224426255573041,"payload":{"event_type":"price_change","market":"0x717c0e8ccd4d5c7040185188fbae28be901ca589a11a94b1b38ca36a79eccfeb","price_changes":[{"asset_id":"24254094493625419915756280046002869097156693848522361803041977572204227262166","best_ask":"0.43","best_bid":"0.42","hash":"82001926d8e70e9d30b213ad50b36cf8cecb5b46","price":"0.01","side":"BUY","size":"5708.02"},{"asset_id":"41448400836309843603620980831210604935021861034693225347475867885462478926555","best_ask":"0.58","best_bid":"0.57","hash":"f2e10fd7d8ee72d43a19916d49ee804dfae5be61","price":"0.99","side":"SELL","size":"5708.02"}],"timestamp":"1785122443021"},"payload_hash":"c03d2588e0c6b2082a11e475e216bc7dea663a010b37fab4d91d6e614cbbdd28","raw_frame":"{\"market\":\"0x717c0e8ccd4d5c7040185188fbae28be901ca589a11a94b1b38ca36a79eccfeb\", \"price_changes\":[{\"asset_id\":\"24254094493625419915756280046002869097156693848522361803041977572204227262166\", \"price\":\"0.01\", \"size\":\"5708.02\", \"side\":\"BUY\", \"hash\":\"82001926d8e70e9d30b213ad50b36cf8cecb5b46\", \"best_bid\":\"0.42\", \"best_ask\":\"0.43\"}, {\"asset_id\":\"41448400836309843603620980831210604935021861034693225347475867885462478926555\", \"price\":\"0.99\", \"size\":\"5708.02\", \"side\":\"SELL\", \"hash\":\"f2e10fd7d8ee72d43a19916d49ee804dfae5be61\", \"best_bid\":\"0.57\", \"best_ask\":\"0.58\"}], \"timestamp\":\"1785122443021\", \"event_type\":\"price_change\"}","received_at":"2026-07-27T03:20:42.901267Z","schema_version":"clob-market-ws.price_change.v1","sequence":null,"server_hash":null,"server_timestamp":"1785122443021","session_id":"dd162b8dca5f43ff811d304e69a06123","source":"clob_market_ws"},"received_at":"2026-07-27T03:20:42.901267Z","record_id":"2a9aed850fce158a5a3913dba594af16a1180fb70295acab419056b48ee5cd4a","schema_fingerprint":"4aa3821a28b0b7c2400bc59aba4bcc0a76e971dadd19610d3ad38c768e124dc7","schema_version":"edge-lab-recorder.raw.v1","sequence":null,"source":"clob_market_ws"}
{"event_at":"2026-07-27T03:20:43.024000Z","event_fingerprint":"fb2aa8d35dbedbdde5ad139e8834136d59870caca1625ae70113655777286a08","payload":{"connection_id":"c7dc2e4762f849c6b6f9306b6518dcab","event_at":"2026-07-27T03:20:43.024000Z","event_type":"price_change","frame_hash":"93ec8d7a0bb9a042cc07ed4924abc8b62a0dfbe631329cce00e6feb2ba88e5de","frame_index":0,"kind":"data","monotonic_ns":224426261902291,"payload":{"event_type":"price_change","market":"0x717c0e8ccd4d5c7040185188fbae28be901ca589a11a94b1b38ca36a79eccfeb","price_changes":[{"asset_id":"24254094493625419915756280046002869097156693848522361803041977572204227262166","best_ask":"0.43","best_bid":"0.42","hash":"6a01293cd6c4fdc14eb68b9f766a75e8cf0a37fe","price":"0.01","side":"BUY","size":"5713.02"},{"asset_id":"41448400836309843603620980831210604935021861034693225347475867885462478926555","best_ask":"0.58","best_bid":"0.57","hash":"3c78d874c9ee13f9225c7a3eeb4ba33e9546789c","price":"0.99","side":"SELL","size":"5713.02"}],"timestamp":"1785122443024"},"payload_hash":"2f66c6f779c4a33fe1ca3bde9622b59dd2657e5107c9645dc850dba78b51b905","raw_frame":"{\"market\":\"0x717c0e8ccd4d5c7040185188fbae28be901ca589a11a94b1b38ca36a79eccfeb\", \"price_changes\":[{\"asset_id\":\"24254094493625419915756280046002869097156693848522361803041977572204227262166\", \"price\":\"0.01\", \"size\":\"5713.02\", \"side\":\"BUY\", \"hash\":\"6a01293cd6c4fdc14eb68b9f766a75e8cf0a37fe\", \"best_bid\":\"0.42\", \"best_ask\":\"0.43\"}, {\"asset_id\":\"41448400836309843603620980831210604935021861034693225347475867885462478926555\", \"price\":\"0.99\", \"size\":\"5713.02\", \"side\":\"SELL\", \"hash\":\"3c78d874c9ee13f9225c7a3eeb4ba33e9546789c\", \"best_bid\":\"0.57\", \"best_ask\":\"0.58\"}], \"timestamp\":\"1785122443024\", \"event_type\":\"price_change\"}","received_at":"2026-07-27T03:20:42.907593Z","schema_version":"clob-market-ws.price_change.v1","sequence":null,"server_hash":null,"server_timestamp":"1785122443024","session_id":"dd162b8dca5f43ff811d304e69a06123","source":"clob_market_ws"},"received_at":"2026-07-27T03:20:42.907593Z","record_id":"651617f7d7e022f3e4744ee7a072e681979a697dd0ef082ae4447e247d1877af","schema_fingerprint":"4aa3821a28b0b7c2400bc59aba4bcc0a76e971dadd19610d3ad38c768e124dc7","schema_version":"edge-lab-recorder.raw.v1","sequence":null,"source":"clob_market_ws"}
{"event_at":"2026-07-27T03:20:43.042000Z","event_fingerprint":"1c359cb05a13fe0167da4dca2c28b674c317146a22639372c7206bad819b386b","payload":{"connection_id":"c7dc2e4762f849c6b6f9306b6518dcab","event_at":"2026-07-27T03:20:43.042000Z","event_type":"price_change","frame_hash":"e2ba1264dc34fb6a6f81239eade5c36472f31b0884f0338e8f8fd975df36e579","frame_index":0,"kind":"data","monotonic_ns":224426277888250,"payload":{"event_type":"price_change","market":"0x717c0e8ccd4d5c7040185188fbae28be901ca589a11a94b1b38ca36a79eccfeb","price_changes":[{"asset_id":"24254094493625419915756280046002869097156693848522361803041977572204227262166","best_ask":"0.43","best_bid":"0.42","hash":"10b6b73659768ec5089b188e7d633fb2c99f972c","price":"0.01","side":"BUY","size":"5708.02"},{"asset_id":"41448400836309843603620980831210604935021861034693225347475867885462478926555","best_ask":"0.58","best_bid":"0.57","hash":"a18de3d15625d63e686bd53291757542913ad2fe","price":"0.99","side":"SELL","size":"5708.02"}],"timestamp":"1785122443042"},"payload_hash":"28abc1af9f964c11f308fe33e6aa4d9bd43fb6422e7def262966ccd817786cd3","raw_frame":"{\"market\":\"0x717c0e8ccd4d5c7040185188fbae28be901ca589a11a94b1b38ca36a79eccfeb\", \"price_changes\":[{\"asset_id\":\"24254094493625419915756280046002869097156693848522361803041977572204227262166\", \"price\":\"0.01\", \"size\":\"5708.02\", \"side\":\"BUY\", \"hash\":\"10b6b73659768ec5089b188e7d633fb2c99f972c\", \"best_bid\":\"0.42\", \"best_ask\":\"0.43\"}, {\"asset_id\":\"41448400836309843603620980831210604935021861034693225347475867885462478926555\", \"price\":\"0.99\", \"size\":\"5708.02\", \"side\":\"SELL\", \"hash\":\"a18de3d15625d63e686bd53291757542913ad2fe\", \"best_bid\":\"0.57\", \"best_ask\":\"0.58\"}], \"timestamp\":\"1785122443042\", \"event_type\":\"price_change\"}","received_at":"2026-07-27T03:20:42.923581Z","schema_version":"clob-market-ws.price_change.v1","sequence":null,"server_hash":null,"server_timestamp":"1785122443042","session_id":"dd162b8dca5f43ff811d304e69a06123","source":"clob_market_ws"},"received_at":"2026-07-27T03:20:42.923581Z","record_id":"58857c3d95115b1aecce045576a302d232606a9517c551223df746787fd52140","schema_fingerprint":"4aa3821a28b0b7c2400bc59aba4bcc0a76e971dadd19610d3ad38c768e124dc7","schema_version":"edge-lab-recorder.raw.v1","sequence":null,"source":"clob_market_ws"}
{"event_at":"2026-07-27T03:20:43.047000Z","event_fingerprint":"e84da135c9232360d73da2e466cd0d6eec03491eb23df7980f86af50c79a6e56","payload":{"connection_id":"c7dc2e4762f849c6b6f9306b6518dcab","event_at":"2026-07-27T03:20:43.047000Z","event_type":"price_change","frame_hash":"2d70c85c4d8281e5dcf3bc3721458b8acf5e572bc141db7f1eac3e4d799f6608","frame_index":0,"kind":"data","monotonic_ns":224426285565375,"payload":{"event_type":"price_change","market":"0x717c0e8ccd4d5c7040185188fbae28be901ca589a11a94b1b38ca36a79eccfeb","price_changes":[{"asset_id":"41448400836309843603620980831210604935021861034693225347475867885462478926555","best_ask":"0.58","best_bid":"0.57","hash":"fcafab77f9f2d4135a1769e7bcd71649498aea76","price":"0.04","side":"BUY","size":"583.09"},{"asset_id":"24254094493625419915756280046002869097156693848522361803041977572204227262166","best_ask":"0.43","best_bid":"0.42","hash":"90d03fc6ec33d63c1308d72857dae30a7fb06d25","price":"0.96","side":"SELL","size":"583.09"}],"timestamp":"1785122443047"},"payload_hash":"43af8eb5afac84a805140d97b4d84d7476c5bd59534d83143466f63c96328aa7","raw_frame":"{\"market\":\"0x717c0e8ccd4d5c7040185188fbae28be901ca589a11a94b1b38ca36a79eccfeb\", \"price_changes\":[{\"asset_id\":\"41448400836309843603620980831210604935021861034693225347475867885462478926555\", \"price\":\"0.04\", \"size\":\"583.09\", \"side\":\"BUY\", \"hash\":\"fcafab77f9f2d4135a1769e7bcd71649498aea76\", \"best_bid\":\"0.57\", \"best_ask\":\"0.58\"}, {\"asset_id\":\"24254094493625419915756280046002869097156693848522361803041977572204227262166\", \"price\":\"0.96\", \"size\":\"583.09\", \"side\":\"SELL\", \"hash\":\"90d03fc6ec33d63c1308d72857dae30a7fb06d25\", \"best_bid\":\"0.42\", \"best_ask\":\"0.43\"}], \"timestamp\":\"1785122443047\", \"event_type\":\"price_change\"}","received_at":"2026-07-27T03:20:42.931255Z","schema_version":"clob-market-ws.price_change.v1","sequence":null,"server_hash":null,"server_timestamp":"1785122443047","session_id":"dd162b8dca5f43ff811d304e69a06123","source":"clob_market_ws"},"received_at":"2026-07-27T03:20:42.931255Z","record_id":"7b943eb4681d25debff7cbb1348be9544738dab180cd2163a1a5b02b6796b64c","schema_fingerprint":"4aa3821a28b0b7c2400bc59aba4bcc0a76e971dadd19610d3ad38c768e124dc7","schema_version":"edge-lab-recorder.raw.v1","sequence":null,"source":"clob_market_ws"}
{"event_at":"2026-07-27T03:20:43.060000Z","event_fingerprint":"343e767965f530696e2c81a058f46abb38d4adcb42fb0a4f23b4e8bc7f6d4a48","payload":{"connection_id":"c7dc2e4762f849c6b6f9306b6518dcab","event_at":"2026-07-27T03:20:43.060000Z","event_type":"price_change","frame_hash":"dbe29cf97693b56358e604019a606a1304c1aea1ce682550e73dce7b21ff29b6","frame_index":0,"kind":"data","monotonic_ns":224426295177125,"payload":{"event_type":"price_change","market":"0x717c0e8ccd4d5c7040185188fbae28be901ca589a11a94b1b38ca36a79eccfeb","price_changes":[{"asset_id":"24254094493625419915756280046002869097156693848522361803041977572204227262166","best_ask":"0.43","best_bid":"0.42","hash":"58b15c79ac114526736fa94eb0dbfa8fa3d36d5e","price":"0.4","side":"BUY","size":"9.6"},{"asset_id":"41448400836309843603620980831210604935021861034693225347475867885462478926555","best_ask":"0.58","best_bid":"0.57","hash":"e13ea06a7cd58689e2fa09d23f5f9a6e2abfe000","price":"0.6","side":"SELL","size":"9.6"}],"timestamp":"1785122443060"},"payload_hash":"2ce2073f15f6e4f309487286fa56adc436ff8cfff6221061f7e86dcadd85f9c3","raw_frame":"{\"market\":\"0x717c0e8ccd4d5c7040185188fbae28be901ca589a11a94b1b38ca36a79eccfeb\", \"price_changes\":[{\"asset_id\":\"24254094493625419915756280046002869097156693848522361803041977572204227262166\", \"price\":\"0.4\", \"size\":\"9.6\", \"side\":\"BUY\", \"hash\":\"58b15c79ac114526736fa94eb0dbfa8fa3d36d5e\", \"best_bid\":\"0.42\", \"best_ask\":\"0.43\"}, {\"asset_id\":\"41448400836309843603620980831210604935021861034693225347475867885462478926555\", \"price\":\"0.6\", \"size\":\"9.6\", \"side\":\"SELL\", \"hash\":\"e13ea06a7cd58689e2fa09d23f5f9a6e2abfe000\", \"best_bid\":\"0.57\", \"best_ask\":\"0.58\"}], \"timestamp\":\"1785122443060\", \"event_type\":\"price_change\"}","received_at":"2026-07-27T03:20:42.940868Z","schema_version":"clob-market-ws.price_change.v1","sequence":null,"server_hash":null,"server_timestamp":"1785122443060","session_id":"dd162b8dca5f43ff811d304e69a06123","source":"clob_market_ws"},"received_at":"2026-07-27T03:20:42.940868Z","record_id":"abbe05a74af01c165807ad1707ebd24684cd0598153a64edfc2fc038ba889651","schema_fingerprint":"4aa3821a28b0b7c2400bc59aba4bcc0a76e971dadd19610d3ad38c768e124dc7","schema_version":"edge-lab-recorder.raw.v1","sequence":null,"source":"clob_market_ws"}
{"event_at":"2026-07-27T03:20:43.075000Z","event_fingerprint":"c3753b2f5347e71ef55d40028370a47f750a1431a715d52f5bc36d8064021fb0","payload":{"connection_id":"c7dc2e4762f849c6b6f9306b6518dcab","event_at":"2026-07-27T03:20:43.075000Z","event_type":"price_change","frame_hash":"371a1cf9988423b617d4904163f3625f72dd21af45855e52ba350f5106d864d1","frame_index":0,"kind":"data","monotonic_ns":224426308638541,"payload":{"event_type":"price_change","market":"0x717c0e8ccd4d5c7040185188fbae28be901ca589a11a94b1b38ca36a79eccfeb","price_changes":[{"asset_id":"24254094493625419915756280046002869097156693848522361803041977572204227262166","best_ask":"0.43","best_bid":"0.42","hash":"27624dfb5dab4f807385d52496cdffb1ae3cfe15","price":"0.37","side":"BUY","size":"46.39"},{"asset_id":"41448400836309843603620980831210604935021861034693225347475867885462478926555","best_ask":"0.58","best_bid":"0.57","hash":"d6ac9a6261cfdb62b92d26b8efed57f73a1c0175","price":"0.63","side":"SELL","size":"46.39"}],"timestamp":"1785122443075"},"payload_hash":"69e9f7477a4a43e89d3763814931e51a9dbee85b66af3bc05af1795ce8fa388b","raw_frame":"{\"market\":\"0x717c0e8ccd4d5c7040185188fbae28be901ca589a11a94b1b38ca36a79eccfeb\", \"price_changes\":[{\"asset_id\":\"24254094493625419915756280046002869097156693848522361803041977572204227262166\", \"price\":\"0.37\", \"size\":\"46.39\", \"side\":\"BUY\", \"hash\":\"27624dfb5dab4f807385d52496cdffb1ae3cfe15\", \"best_bid\":\"0.42\", \"best_ask\":\"0.43\"}, {\"asset_id\":\"41448400836309843603620980831210604935021861034693225347475867885462478926555\", \"price\":\"0.63\", \"size\":\"46.39\", \"side\":\"SELL\", \"hash\":\"d6ac9a6261cfdb62b92d26b8efed57f73a1c0175\", \"best_bid\":\"0.57\", \"best_ask\":\"0.58\"}], \"timestamp\":\"1785122443075\", \"event_type\":\"price_change\"}","received_at":"2026-07-27T03:20:42.954330Z","schema_version":"clob-market-ws.price_change.v1","sequence":null,"server_hash":null,"server_timestamp":"1785122443075","session_id":"dd162b8dca5f43ff811d304e69a06123","source":"clob_market_ws"},"received_at":"2026-07-27T03:20:42.954330Z","record_id":"4182596054ab38e80567f0b9df501d96b08aae484d6b7b86802ec87751ea4e76","schema_fingerprint":"4aa3821a28b0b7c2400bc59aba4bcc0a76e971dadd19610d3ad38c768e124dc7","schema_version":"edge-lab-recorder.raw.v1","sequence":null,"source":"clob_market_ws"}
{"event_at":"2026-07-27T03:20:43.075000Z","event_fingerprint":"bb866301dc7c80e105a1f7805e46ea3eae1f9280ad4449590da872f285b3b956","payload":{"connection_id":"c7dc2e4762f849c6b6f9306b6518dcab","event_at":"2026-07-27T03:20:43.075000Z","event_type":"price_change","frame_hash":"315a1f36a73875ee6bbaeee1545e397fbe3bf60e9b3549320a43633b63795d41","frame_index":0,"kind":"data","monotonic_ns":224426312016000,"payload":{"event_type":"price_change","market":"0x717c0e8ccd4d5c7040185188fbae28be901ca589a11a94b1b38ca36a79eccfeb","price_changes":[{"asset_id":"24254094493625419915756280046002869097156693848522361803041977572204227262166","best_ask":"0.43","best_bid":"0.42","hash":"27624dfb5dab4f807385d52496cdffb1ae3cfe15","price":"0.35","side":"BUY","size":"110"},{"asset_id":"41448400836309843603620980831210604935021861034693225347475867885462478926555","best_ask":"0.58","best_bid":"0.57","hash":"d6ac9a6261cfdb62b92d26b8efed57f73a1c0175","price":"0.65","side":"SELL","size":"110"}],"timestamp":"1785122443075"},"payload_hash":"79d16b51f65b52d288b21f626f7af0199448f68f260a32f62837296054ec6a7c","raw_frame":"{\"market\":\"0x717c0e8ccd4d5c7040185188fbae28be901ca589a11a94b1b38ca36a79eccfeb\", \"price_changes\":[{\"asset_id\":\"24254094493625419915756280046002869097156693848522361803041977572204227262166\", \"price\":\"0.35\", \"size\":\"110\", \"side\":\"BUY\", \"hash\":\"27624dfb5dab4f807385d52496cdffb1ae3cfe15\", \"best_bid\":\"0.42\", \"best_ask\":\"0.43\"}, {\"asset_id\":\"41448400836309843603620980831210604935021861034693225347475867885462478926555\", \"price\":\"0.65\", \"size\":\"110\", \"side\":\"SELL\", \"hash\":\"d6ac9a6261cfdb62b92d26b8efed57f73a1c0175\", \"best_bid\":\"0.57\", \"best_ask\":\"0.58\"}], \"timestamp\":\"1785122443075\", \"event_type\":\"price_change\"}","received_at":"2026-07-27T03:20:42.957707Z","schema_version":"clob-market-ws.price_change.v1","sequence":null,"server_hash":null,"server_timestamp":"1785122443075","session_id":"dd162b8dca5f43ff811d304e69a06123","source":"clob_market_ws"},"received_at":"2026-07-27T03:20:42.957707Z","record_id":"b1c28b43a838897dcd7274f64eefa801e0a07a311b61585264b6129044252946","schema_fingerprint":"4aa3821a28b0b7c2400bc59aba4bcc0a76e971dadd19610d3ad38c768e124dc7","schema_version":"edge-lab-recorder.raw.v1","sequence":null,"source":"clob_market_ws"}
{"event_at":"2026-07-27T03:20:43.076000Z","event_fingerprint":"3849ff73b2d71ded04dd3e1e3d71567e51430532445163c9a1ef48c4052695e3","payload":{"connection_id":"c7dc2e4762f849c6b6f9306b6518dcab","event_at":"2026-07-27T03:20:43.076000Z","event_type":"price_change","frame_hash":"9b20692c5f499a7508d4fd87ec63ac3ad2e086d9f8dfec9c4c19935333112092","frame_index":0,"kind":"data","monotonic_ns":224426314909083,"payload":{"event_type":"price_change","market":"0x717c0e8ccd4d5c7040185188fbae28be901ca589a11a94b1b38ca36a79eccfeb","price_changes":[{"asset_id":"41448400836309843603620980831210604935021861034693225347475867885462478926555","best_ask":"0.58","best_bid":"0.57","hash":"27bb97b1f6ebf10f86f68b324e131263894d3d82","price":"0.51","side":"BUY","size":"157"},{"asset_id":"24254094493625419915756280046002869097156693848522361803041977572204227262166","best_ask":"0.43","best_bid":"0.42","hash":"8a0f4daeb1f462eca07ac977515cfca1267522b9","price":"0.49","side":"SELL","size":"157"}],"timestamp":"1785122443076"},"payload_hash":"7b3405b0f80e1c8278b27fa372a91caaa819b0cd67bf431d4e175c8e61ec9174","raw_frame":"{\"market\":\"0x717c0e8ccd4d5c7040185188fbae28be901ca589a11a94b1b38ca36a79eccfeb\", \"price_changes\":[{\"asset_id\":\"41448400836309843603620980831210604935021861034693225347475867885462478926555\", \"price\":\"0.51\", \"size\":\"157\", \"side\":\"BUY\", \"hash\":\"27bb97b1f6ebf10f86f68b324e131263894d3d82\", \"best_bid\":\"0.57\", \"best_ask\":\"0.58\"}, {\"asset_id\":\"24254094493625419915756280046002869097156693848522361803041977572204227262166\", \"price\":\"0.49\", \"size\":\"157\", \"side\":\"SELL\", \"hash\":\"8a0f4daeb1f462eca07ac977515cfca1267522b9\", \"best_bid\":\"0.42\", \"best_ask\":\"0.43\"}], \"timestamp\":\"1785122443076\", \"event_type\":\"price_change\"}","received_at":"2026-07-27T03:20:42.960600Z","schema_version":"clob-market-ws.price_change.v1","sequence":null,"server_hash":null,"server_timestamp":"1785122443076","session_id":"dd162b8dca5f43ff811d304e69a06123","source":"clob_market_ws"},"received_at":"2026-07-27T03:20:42.960600Z","record_id":"c119ff965e7d9b1651dcf96468d0ba9811ffbed542735411edcc89f699b24e93","schema_fingerprint":"4aa3821a28b0b7c2400bc59aba4bcc0a76e971dadd19610d3ad38c768e124dc7","schema_version":"edge-lab-recorder.raw.v1","sequence":null,"source":"clob_market_ws"}
{"event_at":"2026-07-27T03:20:43.078000Z","event_fingerprint":"e434a8c327db884bfd81aef186fca05bb4711e45db65773a5a13163275f46400","payload":{"connection_id":"c7dc2e4762f849c6b6f9306b6518dcab","event_at":"2026-07-27T03:20:43.078000Z","event_type":"price_change","frame_hash":"b1d7890b696ae0eb5d38a41f5ac611156c6f351ce279598c2db65089db8632d4","frame_index":0,"kind":"data","monotonic_ns":224426317288500,"payload":{"event_type":"price_change","market":"0x717c0e8ccd4d5c7040185188fbae28be901ca589a11a94b1b38ca36a79eccfeb","price_changes":[{"asset_id":"24254094493625419915756280046002869097156693848522361803041977572204227262166","best_ask":"0.43","best_bid":"0.42","hash":"f71d3b5ebe5f2fddfb91a7d5b934b36d8e31b06a","price":"0.39","side":"BUY","size":"76.99"},{"asset_id":"41448400836309843603620980831210604935021861034693225347475867885462478926555","best_ask":"0.58","best_bid":"0.57","hash":"ae69b0ea9014c5761c8c27b3033d3a54c9458ddf","price":"0.61","side":"SELL","size":"76.99"}],"timestamp":"1785122443078"},"payload_hash":"b9a7ce3c4a1558f56e54e034628189206c6aab3e5d45d56ce9a89670b7e733e6","raw_frame":"{\"market\":\"0x717c0e8ccd4d5c7040185188fbae28be901ca589a11a94b1b38ca36a79eccfeb\", \"price_changes\":[{\"asset_id\":\"24254094493625419915756280046002869097156693848522361803041977572204227262166\", \"price\":\"0.39\", \"size\":\"76.99\", \"side\":\"BUY\", \"hash\":\"f71d3b5ebe5f2fddfb91a7d5b934b36d8e31b06a\", \"best_bid\":\"0.42\", \"best_ask\":\"0.43\"}, {\"asset_id\":\"41448400836309843603620980831210604935021861034693225347475867885462478926555\", \"price\":\"0.61\", \"size\":\"76.99\", \"side\":\"SELL\", \"hash\":\"ae69b0ea9014c5761c8c27b3033d3a54c9458ddf\", \"best_bid\":\"0.57\", \"best_ask\":\"0.58\"}], \"timestamp\":\"1785122443078\", \"event_type\":\"price_change\"}","received_at":"2026-07-27T03:20:42.962980Z","schema_version":"clob-market-ws.price_change.v1","sequence":null,"server_hash":null,"server_timestamp":"1785122443078","session_id":"dd162b8dca5f43ff811d304e69a06123","source":"clob_market_ws"},"received_at":"2026-07-27T03:20:42.962980Z","record_id":"b3e6aaf1cf4ba654c161e82af8017e95250e4d74d97ab99795bfaa63c0efee51","schema_fingerprint":"4aa3821a28b0b7c2400bc59aba4bcc0a76e971dadd19610d3ad38c768e124dc7","schema_version":"edge-lab-recorder.raw.v1","sequence":null,"source":"clob_market_ws"}
{"event_at":"2026-07-27T03:20:43.080000Z","event_fingerprint":"ab3919849c85b235c827e9dfaace7f0333f9945af1c867cb30bb622bd6510e32","payload":{"connection_id":"c7dc2e4762f849c6b6f9306b6518dcab","event_at":"2026-07-27T03:20:43.080000Z","event_type":"price_change","frame_hash":"7a0be0f0c3ae479ca72645029ab0833a121d4ba49c4d648891c3e28415ea5ea5","frame_index":0,"kind":"data","monotonic_ns":224426319627291,"payload":{"event_type":"price_change","market":"0x717c0e8ccd4d5c7040185188fbae28be901ca589a11a94b1b38ca36a79eccfeb","price_changes":[{"asset_id":"41448400836309843603620980831210604935021861034693225347475867885462478926555","best_ask":"0.58","best_bid":"0.57","hash":"88e36ffc9a3f9e324066307bb244cdcd3d7ccc56","price":"0.5","side":"BUY","size":"133"},{"asset_id":"24254094493625419915756280046002869097156693848522361803041977572204227262166","best_ask":"0.43","best_bid":"0.42","hash":"0b3980e58d8d97ad02fc684b4b02d0d5bc7eba89","price":"0.5","side":"SELL","size":"133"}],"timestamp":"1785122443080"},"payload_hash":"2f49320caa7066ccf35c879f6963381ceea45cddbcc3f3399faa20fd48e733ab","raw_frame":"{\"market\":\"0x717c0e8ccd4d5c7040185188fbae28be901ca589a11a94b1b38ca36a79eccfeb\", \"price_changes\":[{\"asset_id\":\"41448400836309843603620980831210604935021861034693225347475867885462478926555\", \"price\":\"0.5\", \"size\":\"133\", \"side\":\"BUY\", \"hash\":\"88e36ffc9a3f9e324066307bb244cdcd3d7ccc56\", \"best_bid\":\"0.57\", \"best_ask\":\"0.58\"}, {\"asset_id\":\"24254094493625419915756280046002869097156693848522361803041977572204227262166\", \"price\":\"0.5\", \"size\":\"133\", \"side\":\"SELL\", \"hash\":\"0b3980e58d8d97ad02fc684b4b02d0d5bc7eba89\", \"best_bid\":\"0.42\", \"best_ask\":\"0.43\"}], \"timestamp\":\"1785122443080\", \"event_type\":\"price_change\"}","received_at":"2026-07-27T03:20:42.965319Z","schema_version":"clob-market-ws.price_change.v1","sequence":null,"server_hash":null,"server_timestamp":"1785122443080","session_id":"dd162b8dca5f43ff811d304e69a06123","source":"clob_market_ws"},"received_at":"2026-07-27T03:20:42.965319Z","record_id":"f9a25135b47b74da4b94d4dd279242b9dede48b22a39507a3e626ea086c63e83","schema_fingerprint":"4aa3821a28b0b7c2400bc59aba4bcc0a76e971dadd19610d3ad38c768e124dc7","schema_version":"edge-lab-recorder.raw.v1","sequence":null,"source":"clob_market_ws"}
{"event_at":"2026-07-27T03:20:43.081000Z","event_fingerprint":"2f5e53d8e2c5ae1fedf670bb777038662026cef51c00cd4800e557e48f2b2dc6","payload":{"connection_id":"c7dc2e4762f849c6b6f9306b6518dcab","event_at":"2026-07-27T03:20:43.081000Z","event_type":"price_change","frame_hash":"42b490ed944cba0ffcee487afdbb1b9c4ce61c3d262f453d74cfbf2b9bca3423","frame_index":0,"kind":"data","monotonic_ns":224426322336416,"payload":{"event_type":"price_change","market":"0x717c0e8ccd4d5c7040185188fbae28be901ca589a11a94b1b38ca36a79eccfeb","price_changes":[{"asset_id":"24254094493625419915756280046002869097156693848522361803041977572204227262166","best_ask":"0.43","best_bid":"0.42","hash":"74f46ebce950b1cada765a0458bef1600dce5a07","price":"0.38","side":"BUY","size":"64.07"},{"asset_id":"41448400836309843603620980831210604935021861034693225347475867885462478926555","best_ask":"0.58","best_bid":"0.57","hash":"f25a5719c3d0126966772bafbd155b9515542e4e","price":"0.62","side":"SELL","size":"64.07"}],"timestamp":"1785122443081"},"payload_hash":"637ea3473fed36ac26d3d20e6d87d7370459362c6893195a02abf9f5daeab1a1","raw_frame":"{\"market\":\"0x717c0e8ccd4d5c7040185188fbae28be901ca589a11a94b1b38ca36a79eccfeb\", \"price_changes\":[{\"asset_id\":\"24254094493625419915756280046002869097156693848522361803041977572204227262166\", \"price\":\"0.38\", \"size\":\"64.07\", \"side\":\"BUY\", \"hash\":\"74f46ebce950b1cada765a0458bef1600dce5a07\", \"best_bid\":\"0.42\", \"best_ask\":\"0.43\"}, {\"asset_id\":\"41448400836309843603620980831210604935021861034693225347475867885462478926555\", \"price\":\"0.62\", \"size\":\"64.07\", \"side\":\"SELL\", \"hash\":\"f25a5719c3d0126966772bafbd155b9515542e4e\", \"best_bid\":\"0.57\", \"best_ask\":\"0.58\"}], \"timestamp\":\"1785122443081\", \"event_type\":\"price_change\"}","received_at":"2026-07-27T03:20:42.968030Z","schema_version":"clob-market-ws.price_change.v1","sequence":null,"server_hash":null,"server_timestamp":"1785122443081","session_id":"dd162b8dca5f43ff811d304e69a06123","source":"clob_market_ws"},"received_at":"2026-07-27T03:20:42.968030Z","record_id":"5a0a5a60e1998520d41ef88f4272c1ebb8a7e1eba714bd047a4a2ebacd9f238a","schema_fingerprint":"4aa3821a28b0b7c2400bc59aba4bcc0a76e971dadd19610d3ad38c768e124dc7","schema_version":"edge-lab-recorder.raw.v1","sequence":null,"source":"clob_market_ws"}
{"event_at":"2026-07-27T03:20:43.083000Z","event_fingerprint":"2954e0f04df5e938b2b1baa3c627b3a8c9b1d56240891fbc2742870d322e3cd8","payload":{"connection_id":"c7dc2e4762f849c6b6f9306b6518dcab","event_at":"2026-07-27T03:20:43.083000Z","event_type":"price_change","frame_hash":"b59a710e6a40c49f2631637862a02e890667f0a6260d0a4b1cabb5c2f67608bd","frame_index":0,"kind":"data","monotonic_ns":224426324924791,"payload":{"event_type":"price_change","market":"0x717c0e8ccd4d5c7040185188fbae28be901ca589a11a94b1b38ca36a79eccfeb","price_changes":[{"asset_id":"24254094493625419915756280046002869097156693848522361803041977572204227262166","best_ask":"0.43","best_bid":"0.42","hash":"e739397ad121874b9e525e901acf0e4881fa112a","price":"0.36","side":"BUY","size":"32.88"},{"asset_id":"41448400836309843603620980831210604935021861034693225347475867885462478926555","best_ask":"0.58","best_bid":"0.57","hash":"67d9b0b85eeaf2ed12c7dfa8e376e3e2064a34d7","price":"0.64","side":"SELL","size":"32.88"}],"timestamp":"1785122443083"},"payload_hash":"ad1a9765d11dbf87f1c3b3fb37d5918c712bb0d1ba1e28cd10dd2c1c8c3b35c4","raw_frame":"{\"market\":\"0x717c0e8ccd4d5c7040185188fbae28be901ca589a11a94b1b38ca36a79eccfeb\", \"price_changes\":[{\"asset_id\":\"24254094493625419915756280046002869097156693848522361803041977572204227262166\", \"price\":\"0.36\", \"size\":\"32.88\", \"side\":\"BUY\", \"hash\":\"e739397ad121874b9e525e901acf0e4881fa112a\", \"best_bid\":\"0.42\", \"best_ask\":\"0.43\"}, {\"asset_id\":\"41448400836309843603620980831210604935021861034693225347475867885462478926555\", \"price\":\"0.64\", \"size\":\"32.88\", \"side\":\"SELL\", \"hash\":\"67d9b0b85eeaf2ed12c7dfa8e376e3e2064a34d7\", \"best_bid\":\"0.57\", \"best_ask\":\"0.58\"}], \"timestamp\":\"1785122443083\", \"event_type\":\"price_change\"}","received_at":"2026-07-27T03:20:42.970617Z","schema_version":"clob-market-ws.price_change.v1","sequence":null,"server_hash":null,"server_timestamp":"1785122443083","session_id":"dd162b8dca5f43ff811d304e69a06123","source":"clob_market_ws"},"received_at":"2026-07-27T03:20:42.970617Z","record_id":"52cac4efeab7dedc3d7af4a6406438f322b2b534c6edf94787e03029b8fef8f9","schema_fingerprint":"4aa3821a28b0b7c2400bc59aba4bcc0a76e971dadd19610d3ad38c768e124dc7","schema_version":"edge-lab-recorder.raw.v1","sequence":null,"source":"clob_market_ws"}
{"event_at":"2026-07-27T03:20:43.084000Z","event_fingerprint":"9c430f7cebf4ea5f9c9fab021ebb84794fb6c0c332c120eaea5c71faa60d5142","payload":{"connection_id":"c7dc2e4762f849c6b6f9306b6518dcab","event_at":"2026-07-27T03:20:43.084000Z","event_type":"price_change","frame_hash":"4774549aab151ca6df5f6337169dddf3ea4574b7fd220232626608962482b6b5","frame_index":0,"kind":"data","monotonic_ns":224426328005250,"payload":{"event_type":"price_change","market":"0x717c0e8ccd4d5c7040185188fbae28be901ca589a11a94b1b38ca36a79eccfeb","price_changes":[{"asset_id":"24254094493625419915756280046002869097156693848522361803041977572204227262166","best_ask":"0.43","best_bid":"0.42","hash":"e3a17c048938fa8407df5aae8822b5ee70e105cb","price":"0.34","side":"BUY","size":"21"},{"asset_id":"41448400836309843603620980831210604935021861034693225347475867885462478926555","best_ask":"0.58","best_bid":"0.57","hash":"da19c20d9e00dc5e6c06baab2715f90b63b566ea","price":"0.66","side":"SELL","size":"21"}],"timestamp":"1785122443084"},"payload_hash":"9a50fef20af4ccc331e28c4aa83683f3fc1c7f1f0acf71a82524937c3f15ac36","raw_frame":"{\"market\":\"0x717c0e8ccd4d5c7040185188fbae28be901ca589a11a94b1b38ca36a79eccfeb\", \"price_changes\":[{\"asset_id\":\"24254094493625419915756280046002869097156693848522361803041977572204227262166\", \"price\":\"0.34\", \"size\":\"21\", \"side\":\"BUY\", \"hash\":\"e3a17c048938fa8407df5aae8822b5ee70e105cb\", \"best_bid\":\"0.42\", \"best_ask\":\"0.43\"}, {\"asset_id\":\"41448400836309843603620980831210604935021861034693225347475867885462478926555\", \"price\":\"0.66\", \"size\":\"21\", \"side\":\"SELL\", \"hash\":\"da19c20d9e00dc5e6c06baab2715f90b63b566ea\", \"best_bid\":\"0.57\", \"best_ask\":\"0.58\"}], \"timestamp\":\"1785122443084\", \"event_type\":\"price_change\"}","received_at":"2026-07-27T03:20:42.973696Z","schema_version":"clob-market-ws.price_change.v1","sequence":null,"server_hash":null,"server_timestamp":"1785122443084","session_id":"dd162b8dca5f43ff811d304e69a06123","source":"clob_market_ws"},"received_at":"2026-07-27T03:20:42.973696Z","record_id":"72636aae5f3df63d4d04391430efeaa6631d68235d3f28bc40d6c7a91d98f3ef","schema_fingerprint":"4aa3821a28b0b7c2400bc59aba4bcc0a76e971dadd19610d3ad38c768e124dc7","schema_version":"edge-lab-recorder.raw.v1","sequence":null,"source":"clob_market_ws"}
{"event_at":"2026-07-27T03:20:43.098000Z","event_fingerprint":"d58050cb936b6c4e10e36f6f29e4d5087a79e6dd4d77454338596b950f942c3f","payload":{"connection_id":"c7dc2e4762f849c6b6f9306b6518dcab","event_at":"2026-07-27T03:20:43.098000Z","event_type":"price_change","frame_hash":"b6f9475425af0234c63f1440e83bf432fe99825f9969ffa3e6cda7c89bde5f47","frame_index":0,"kind":"data","monotonic_ns":224426333443791,"payload":{"event_type":"price_change","market":"0x717c0e8ccd4d5c7040185188fbae28be901ca589a11a94b1b38ca36a79eccfeb","price_changes":[{"asset_id":"24254094493625419915756280046002869097156693848522361803041977572204227262166","best_ask":"0.43","best_bid":"0.42","hash":"cbd5343c0685c9fb8f44a2e60513ebdb18ba4082","price":"0.01","side":"BUY","size":"5703.02"},{"asset_id":"41448400836309843603620980831210604935021861034693225347475867885462478926555","best_ask":"0.58","best_bid":"0.57","hash":"7f0800aeb09eea1a20266ba811e829ff8ce44d6c","price":"0.99","side":"SELL","size":"5703.02"}],"timestamp":"1785122443098"},"payload_hash":"41d86ae09341f7cb51e707dfe8f8bfaf99f419e20bed5f0926178737c0e9eb5f","raw_frame":"{\"market\":\"0x717c0e8ccd4d5c7040185188fbae28be901ca589a11a94b1b38ca36a79eccfeb\", \"price_changes\":[{\"asset_id\":\"24254094493625419915756280046002869097156693848522361803041977572204227262166\", \"price\":\"0.01\", \"size\":\"5703.02\", \"side\":\"BUY\", \"hash\":\"cbd5343c0685c9fb8f44a2e60513ebdb18ba4082\", \"best_bid\":\"0.42\", \"best_ask\":\"0.43\"}, {\"asset_id\":\"41448400836309843603620980831210604935021861034693225347475867885462478926555\", \"price\":\"0.99\", \"size\":\"5703.02\", \"side\":\"SELL\", \"hash\":\"7f0800aeb09eea1a20266ba811e829ff8ce44d6c\", \"best_bid\":\"0.57\", \"best_ask\":\"0.58\"}], \"timestamp\":\"1785122443098\", \"event_type\":\"price_change\"}","received_at":"2026-07-27T03:20:42.979135Z","schema_version":"clob-market-ws.price_change.v1","sequence":null,"server_hash":null,"server_timestamp":"1785122443098","session_id":"dd162b8dca5f43ff811d304e69a06123","source":"clob_market_ws"},"received_at":"2026-07-27T03:20:42.979135Z","record_id":"c1e20c93c976c8b37cb958452b11fc7e6d31d4e6e1bad46703f1a1c26fd1f5a1","schema_fingerprint":"4aa3821a28b0b7c2400bc59aba4bcc0a76e971dadd19610d3ad38c768e124dc7","schema_version":"edge-lab-recorder.raw.v1","sequence":null,"source":"clob_market_ws"}
{"event_at":"2026-07-27T03:20:43.099000Z","event_fingerprint":"1b42985def65880ebd4264a161e307438b8c8aa7948745909c70797b327fd1bc","payload":{"connection_id":"c7dc2e4762f849c6b6f9306b6518dcab","event_at":"2026-07-27T03:20:43.099000Z","event_type":"price_change","frame_hash":"3b5372b9151eeb1df814f117ff658a355dc55b556d8b07282226926a1628e59f","frame_index":0,"kind":"data","monotonic_ns":224426336787208,"payload":{"event_type":"price_change","market":"0x717c0e8ccd4d5c7040185188fbae28be901ca589a11a94b1b38ca36a79eccfeb","price_changes":[{"asset_id":"24254094493625419915756280046002869097156693848522361803041977572204227262166","best_ask":"0.43","best_bid":"0.42","hash":"342989e61de4f34efa66ea40b4410906804426de","price":"0.39","side":"BUY","size":"96.99"},{"asset_id":"41448400836309843603620980831210604935021861034693225347475867885462478926555","best_ask":"0.58","best_bid":"0.57","hash":"d1b42a27f4edde620e580c51c2dbf53b5209b24f","price":"0.61","side":"SELL","size":"96.99"}],"timestamp":"1785122443099"},"payload_hash":"e10773311462b8fe30be8f3b2f9a90504a12b672c270e9b10129f284b4963975","raw_frame":"{\"market\":\"0x717c0e8ccd4d5c7040185188fbae28be901ca589a11a94b1b38ca36a79eccfeb\", \"price_changes\":[{\"asset_id\":\"24254094493625419915756280046002869097156693848522361803041977572204227262166\", \"price\":\"0.39\", \"size\":\"96.99\", \"side\":\"BUY\", \"hash\":\"342989e61de4f34efa66ea40b4410906804426de\", \"best_bid\":\"0.42\", \"best_ask\":\"0.43\"}, {\"asset_id\":\"41448400836309843603620980831210604935021861034693225347475867885462478926555\", \"price\":\"0.61\", \"size\":\"96.99\", \"side\":\"SELL\", \"hash\":\"d1b42a27f4edde620e580c51c2dbf53b5209b24f\", \"best_bid\":\"0.57\", \"best_ask\":\"0.58\"}], \"timestamp\":\"1785122443099\", \"event_type\":\"price_change\"}","received_at":"2026-07-27T03:20:42.982478Z","schema_version":"clob-market-ws.price_change.v1","sequence":null,"server_hash":null,"server_timestamp":"1785122443099","session_id":"dd162b8dca5f43ff811d304e69a06123","source":"clob_market_ws"},"received_at":"2026-07-27T03:20:42.982478Z","record_id":"5e89db9aa1c151e2a17499d9c10f52056dd7e2ee9052c7239931f14c522aed92","schema_fingerprint":"4aa3821a28b0b7c2400bc59aba4bcc0a76e971dadd19610d3ad38c768e124dc7","schema_version":"edge-lab-recorder.raw.v1","sequence":null,"source":"clob_market_ws"}
{"event_at":"2026-07-27T03:20:43.100000Z","event_fingerprint":"1925acb70b80b9f3fadc1778c018bf73bd3fe826ff68b6c204ba5b77fb615f47","payload":{"connection_id":"c7dc2e4762f849c6b6f9306b6518dcab","event_at":"2026-07-27T03:20:43.100000Z","event_type":"price_change","frame_hash":"32fa5066e5f18e8892b5525b02664e7466f071a07708d9f48e72596911e7b8c4","frame_index":0,"kind":"data","monotonic_ns":224426340485750,"payload":{"event_type":"price_change","market":"0x717c0e8ccd4d5c7040185188fbae28be901ca589a11a94b1b38ca36a79eccfeb","price_changes":[{"asset_id":"41448400836309843603620980831210604935021861034693225347475867885462478926555","best_ask":"0.58","best_bid":"0.57","hash":"df3de7b9113249e147b768ec7f730476e21253ee","price":"0.04","side":"BUY","size":"578.09"},{"asset_id":"24254094493625419915756280046002869097156693848522361803041977572204227262166","best_ask":"0.43","best_bid":"0.42","hash":"b158d48ce174544b6b4f8b27b1f54a06e08f5deb","price":"0.96","side":"SELL","size":"578.09"}],"timestamp":"1785122443100"},"payload_hash":"9cf517944d3a4821334b302630da9a6835ae322752bea69952982ff996534415","raw_frame":"{\"market\":\"0x717c0e8ccd4d5c7040185188fbae28be901ca589a11a94b1b38ca36a79eccfeb\", \"price_changes\":[{\"asset_id\":\"41448400836309843603620980831210604935021861034693225347475867885462478926555\", \"price\":\"0.04\", \"size\":\"578.09\", \"side\":\"BUY\", \"hash\":\"df3de7b9113249e147b768ec7f730476e21253ee\", \"best_bid\":\"0.57\", \"best_ask\":\"0.58\"}, {\"asset_id\":\"24254094493625419915756280046002869097156693848522361803041977572204227262166\", \"price\":\"0.96\", \"size\":\"578.09\", \"side\":\"SELL\", \"hash\":\"b158d48ce174544b6b4f8b27b1f54a06e08f5deb\", \"best_bid\":\"0.42\", \"best_ask\":\"0.43\"}], \"timestamp\":\"1785122443100\", \"event_type\":\"price_change\"}","received_at":"2026-07-27T03:20:42.986174Z","schema_version":"clob-market-ws.price_change.v1","sequence":null,"server_hash":null,"server_timestamp":"1785122443100","session_id":"dd162b8dca5f43ff811d304e69a06123","source":"clob_market_ws"},"received_at":"2026-07-27T03:20:42.986174Z","record_id":"25f202196829510f2ed209d3363bfb62c88e107a9433f436c8a814bb995f518f","schema_fingerprint":"4aa3821a28b0b7c2400bc59aba4bcc0a76e971dadd19610d3ad38c768e124dc7","schema_version":"edge-lab-recorder.raw.v1","sequence":null,"source":"clob_market_ws"}
{"event_at":"2026-07-27T03:20:43.120000Z","event_fingerprint":"1c23a99dd9de491932b149e5f1ad2bb505777a5e82bd4d24c5011632c5f7270b","payload":{"connection_id":"c7dc2e4762f849c6b6f9306b6518dcab","event_at":"2026-07-27T03:20:43.120000Z","event_type":"price_change","frame_hash":"f19cb7eea0037830d1db1c46a27a9f02596ac9928ba3359416d0fb2635e5dc4b","frame_index":0,"kind":"data","monotonic_ns":224426354048833,"payload":{"event_type":"price_change","market":"0x717c0e8ccd4d5c7040185188fbae28be901ca589a11a94b1b38ca36a79eccfeb","price_changes":[{"asset_id":"41448400836309843603620980831210604935021861034693225347475867885462478926555","best_ask":"0.58","best_bid":"0.57","hash":"3a1dd1e590d5afc29d6c150a9da52a312348e034","price":"0.45","side":"BUY","size":"150"},{"asset_id":"24254094493625419915756280046002869097156693848522361803041977572204227262166","best_ask":"0.43","best_bid":"0.42","hash":"eea442f579675b33e2624b93098c24dcff6abcf5","price":"0.55","side":"SELL","size":"150"}],"timestamp":"1785122443120"},"payload_hash":"111b8ec453285bc16ee54c950d9c584715dead455a01077bdf1669bb9ec8dad8","raw_frame":"{\"market\":\"0x717c0e8ccd4d5c7040185188fbae28be901ca589a11a94b1b38ca36a79eccfeb\", \"price_changes\":[{\"asset_id\":\"41448400836309843603620980831210604935021861034693225347475867885462478926555\", \"price\":\"0.45\", \"size\":\"150\", \"side\":\"BUY\", \"hash\":\"3a1dd1e590d5afc29d6c150a9da52a312348e034\", \"best_bid\":\"0.57\", \"best_ask\":\"0.58\"}, {\"asset_id\":\"24254094493625419915756280046002869097156693848522361803041977572204227262166\", \"price\":\"0.55\", \"size\":\"150\", \"side\":\"SELL\", \"hash\":\"eea442f579675b33e2624b93098c24dcff6abcf5\", \"best_bid\":\"0.42\", \"best_ask\":\"0.43\"}], \"timestamp\":\"1785122443120\", \"event_type\":\"price_change\"}","received_at":"2026-07-27T03:20:42.999738Z","schema_version":"clob-market-ws.price_change.v1","sequence":null,"server_hash":null,"server_timestamp":"1785122443120","session_id":"dd162b8dca5f43ff811d304e69a06123","source":"clob_market_ws"},"received_at":"2026-07-27T03:20:42.999738Z","record_id":"351c577bd30a7c2a524904d63bbd6fa8bbc5075a64622c435aaba9db33f5ca11","schema_fingerprint":"4aa3821a28b0b7c2400bc59aba4bcc0a76e971dadd19610d3ad38c768e124dc7","schema_version":"edge-lab-recorder.raw.v1","sequence":null,"source":"clob_market_ws"}
{"event_at":"2026-07-27T03:20:43.146000Z","event_fingerprint":"4aa9d0a7b5948b719e157b6d2eb4046c1eac053849d8e91549be4fffe1d8046e","payload":{"connection_id":"c7dc2e4762f849c6b6f9306b6518dcab","event_at":"2026-07-27T03:20:43.146000Z","event_type":"price_change","frame_hash":"38fbd64f07e590c95135ce15617ab8d4b32ff5a0e4b34b335af6af6e9fef561b","frame_index":0,"kind":"data","monotonic_ns":224426382111458,"payload":{"event_type":"price_change","market":"0x717c0e8ccd4d5c7040185188fbae28be901ca589a11a94b1b38ca36a79eccfeb","price_changes":[{"asset_id":"24254094493625419915756280046002869097156693848522361803041977572204227262166","best_ask":"0.43","best_bid":"0.42","hash":"51d0af3b6fd73b7a85ab0080930f8950793053a2","price":"0.37","side":"BUY","size":"41.39"},{"asset_id":"41448400836309843603620980831210604935021861034693225347475867885462478926555","best_ask":"0.58","best_bid":"0.57","hash":"8597c43a1248a9daacf53d5bdb558d9690f5bad5","price":"0.63","side":"SELL","size":"41.39"}],"timestamp":"1785122443146"},"payload_hash":"c2a065b98e74303778467b8bedd64d216947801ed7b99aad925dcb1cb5a751cc","raw_frame":"{\"market\":\"0x717c0e8ccd4d5c7040185188fbae28be901ca589a11a94b1b38ca36a79eccfeb\", \"price_changes\":[{\"asset_id\":\"24254094493625419915756280046002869097156693848522361803041977572204227262166\", \"price\":\"0.37\", \"size\":\"41.39\", \"side\":\"BUY\", \"hash\":\"51d0af3b6fd73b7a85ab0080930f8950793053a2\", \"best_bid\":\"0.42\", \"best_ask\":\"0.43\"}, {\"asset_id\":\"41448400836309843603620980831210604935021861034693225347475867885462478926555\", \"price\":\"0.63\", \"size\":\"41.39\", \"side\":\"SELL\", \"hash\":\"8597c43a1248a9daacf53d5bdb558d9690f5bad5\", \"best_bid\":\"0.57\", \"best_ask\":\"0.58\"}], \"timestamp\":\"1785122443146\", \"event_type\":\"price_change\"}","received_at":"2026-07-27T03:20:43.027800Z","schema_version":"clob-market-ws.price_change.v1","sequence":null,"server_hash":null,"server_timestamp":"1785122443146","session_id":"dd162b8dca5f43ff811d304e69a06123","source":"clob_market_ws"},"received_at":"2026-07-27T03:20:43.027800Z","record_id":"6f06021b2597a94e53ea70907269cac93e63326f11b58a4c8a62f36cdeff10b6","schema_fingerprint":"4aa3821a28b0b7c2400bc59aba4bcc0a76e971dadd19610d3ad38c768e124dc7","schema_version":"edge-lab-recorder.raw.v1","sequence":null,"source":"clob_market_ws"}
{"event_at":"2026-07-27T03:20:43.148000Z","event_fingerprint":"4d2af74e86dd571ebd711e4bb14afefbdb2bc092401bf27aa5a46c13a2a907b4","payload":{"connection_id":"c7dc2e4762f849c6b6f9306b6518dcab","event_at":"2026-07-27T03:20:43.148000Z","event_type":"price_change","frame_hash":"eed6e5c9d9fe803c7f1f06b956e399d9d39d19c436ee201aa3d1c93ee0991c5d","frame_index":0,"kind":"data","monotonic_ns":224426385064125,"payload":{"event_type":"price_change","market":"0x717c0e8ccd4d5c7040185188fbae28be901ca589a11a94b1b38ca36a79eccfeb","price_changes":[{"asset_id":"24254094493625419915756280046002869097156693848522361803041977572204227262166","best_ask":"0.43","best_bid":"0.42","hash":"1295c915dce617d0a939bef15af6e1b57f12254d","price":"0.42","side":"BUY","size":"180"},{"asset_id":"41448400836309843603620980831210604935021861034693225347475867885462478926555","best_ask":"0.58","best_bid":"0.57","hash":"3696cb18064ff0598eb0fe636f582975e6cc3445","price":"0.58","side":"SELL","size":"180"}],"timestamp":"1785122443148"},"payload_hash":"ca9f7b5d43413962852b8cd6fef45c1da14c92f5e7f164c7d4d2895d6ec947f0","raw_frame":"{\"market\":\"0x717c0e8ccd4d5c7040185188fbae28be901ca589a11a94b1b38ca36a79eccfeb\", \"price_changes\":[{\"asset_id\":\"24254094493625419915756280046002869097156693848522361803041977572204227262166\", \"price\":\"0.42\", \"size\":\"180\", \"side\":\"BUY\", \"hash\":\"1295c915dce617d0a939bef15af6e1b57f12254d\", \"best_bid\":\"0.42\", \"best_ask\":\"0.43\"}, {\"asset_id\":\"41448400836309843603620980831210604935021861034693225347475867885462478926555\", \"price\":\"0.58\", \"size\":\"180\", \"side\":\"SELL\", \"hash\":\"3696cb18064ff0598eb0fe636f582975e6cc3445\", \"best_bid\":\"0.57\", \"best_ask\":\"0.58\"}], \"timestamp\":\"1785122443148\", \"event_type\":\"price_change\"}","received_at":"2026-07-27T03:20:43.030753Z","schema_version":"clob-market-ws.price_change.v1","sequence":null,"server_hash":null,"server_timestamp":"1785122443148","session_id":"dd162b8dca5f43ff811d304e69a06123","source":"clob_market_ws"},"received_at":"2026-07-27T03:20:43.030753Z","record_id":"47de9b1a9e98d8c4f12ccfd9e62ded9175a08d5829a32252fba93ab476c4c350","schema_fingerprint":"4aa3821a28b0b7c2400bc59aba4bcc0a76e971dadd19610d3ad38c768e124dc7","schema_version":"edge-lab-recorder.raw.v1","sequence":null,"source":"clob_market_ws"}
{"event_at":"2026-07-27T03:20:43.149000Z","event_fingerprint":"73c9d1992d58c3f5968074a2b643e74e784622d7e378a6a59024e5375942d575","payload":{"connection_id":"c7dc2e4762f849c6b6f9306b6518dcab","event_at":"2026-07-27T03:20:43.149000Z","event_type":"price_change","frame_hash":"272871385b550105d749ba06486873bd280ece05a40246a61cff3a99ae1b6f8c","frame_index":0,"kind":"data","monotonic_ns":224426387288458,"payload":{"event_type":"price_change","market":"0x717c0e8ccd4d5c7040185188fbae28be901ca589a11a94b1b38ca36a79eccfeb","price_changes":[{"asset_id":"41448400836309843603620980831210604935021861034693225347475867885462478926555","best_ask":"0.58","best_bid":"0.57","hash":"972f562f7f0dce9ebf6057ecbdebf393dee127d0","price":"0.55","side":"BUY","size":"304"},{"asset_id":"24254094493625419915756280046002869097156693848522361803041977572204227262166","best_ask":"0.43","best_bid":"0.42","hash":"fbb35fddbc6887309fa7481b2390d6c675672cfb","price":"0.45","side":"SELL","size":"304"}],"timestamp":"1785122443149"},"payload_hash":"a2204d23b4a5d097118921a35214e82497b255237f6b8652f8f1b411ae06dc5b","raw_frame":"{\"market\":\"0x717c0e8ccd4d5c7040185188fbae28be901ca589a11a94b1b38ca36a79eccfeb\", \"price_changes\":[{\"asset_id\":\"41448400836309843603620980831210604935021861034693225347475867885462478926555\", \"price\":\"0.55\", \"size\":\"304\", \"side\":\"BUY\", \"hash\":\"972f562f7f0dce9ebf6057ecbdebf393dee127d0\", \"best_bid\":\"0.57\", \"best_ask\":\"0.58\"}, {\"asset_id\":\"24254094493625419915756280046002869097156693848522361803041977572204227262166\", \"price\":\"0.45\", \"size\":\"304\", \"side\":\"SELL\", \"hash\":\"fbb35fddbc6887309fa7481b2390d6c675672cfb\", \"best_bid\":\"0.42\", \"best_ask\":\"0.43\"}], \"timestamp\":\"1785122443149\", \"event_type\":\"price_change\"}","received_at":"2026-07-27T03:20:43.032980Z","schema_version":"clob-market-ws.price_change.v1","sequence":null,"server_hash":null,"server_timestamp":"1785122443149","session_id":"dd162b8dca5f43ff811d304e69a06123","source":"clob_market_ws"},"received_at":"2026-07-27T03:20:43.032980Z","record_id":"65c522c904ef553c3a42bf850c3fe8925a9a2fd7ec9837e39ea7fcb49184d1f9","schema_fingerprint":"4aa3821a28b0b7c2400bc59aba4bcc0a76e971dadd19610d3ad38c768e124dc7","schema_version":"edge-lab-recorder.raw.v1","sequence":null,"source":"clob_market_ws"}
{"event_at":"2026-07-27T03:20:43.154000Z","event_fingerprint":"c6b8cf3dc0c477b28f34dada0602de45960393aa8ead4743f04f4300acd5996b","payload":{"connection_id":"c7dc2e4762f849c6b6f9306b6518dcab","event_at":"2026-07-27T03:20:43.154000Z","event_type":"price_change","frame_hash":"92f9b7d54426757c3b709e28e4674ee92511746a4221b1012ecbde7bcc786511","frame_index":0,"kind":"data","monotonic_ns":224426390579125,"payload":{"event_type":"price_change","market":"0x717c0e8ccd4d5c7040185188fbae28be901ca589a11a94b1b38ca36a79eccfeb","price_changes":[{"asset_id":"41448400836309843603620980831210604935021861034693225347475867885462478926555","best_ask":"0.58","best_bid":"0.57","hash":"18f6e2f94043ce5806418cd483c661564e266813","price":"0.58","side":"SELL","size":"196"},{"asset_id":"24254094493625419915756280046002869097156693848522361803041977572204227262166","best_ask":"0.43","best_bid":"0.42","hash":"8468f5ba17e4f7fcf6ff54cd4addf940107f4ee3","price":"0.42","side":"BUY","size":"196"}],"timestamp":"1785122443154"},"payload_hash":"d1ddf1d94e999554a0d50b3f8581e56fa1f1a2fc9054728d7141f660ecced9f2","raw_frame":"{\"market\":\"0x717c0e8ccd4d5c7040185188fbae28be901ca589a11a94b1b38ca36a79eccfeb\", \"price_changes\":[{\"asset_id\":\"41448400836309843603620980831210604935021861034693225347475867885462478926555\", \"price\":\"0.58\", \"size\":\"196\", \"side\":\"SELL\", \"hash\":\"18f6e2f94043ce5806418cd483c661564e266813\", \"best_bid\":\"0.57\", \"best_ask\":\"0.58\"}, {\"asset_id\":\"24254094493625419915756280046002869097156693848522361803041977572204227262166\", \"price\":\"0.42\", \"size\":\"196\", \"side\":\"BUY\", \"hash\":\"8468f5ba17e4f7fcf6ff54cd4addf940107f4ee3\", \"best_bid\":\"0.42\", \"best_ask\":\"0.43\"}], \"timestamp\":\"1785122443154\", \"event_type\":\"price_change\"}","received_at":"2026-07-27T03:20:43.036268Z","schema_version":"clob-market-ws.price_change.v1","sequence":null,"server_hash":null,"server_timestamp":"1785122443154","session_id":"dd162b8dca5f43ff811d304e69a06123","source":"clob_market_ws"},"received_at":"2026-07-27T03:20:43.036268Z","record_id":"6555f81804fe631fb335526a423e064e0c622bfb647c3ca7154f6570d1231dee","schema_fingerprint":"4aa3821a28b0b7c2400bc59aba4bcc0a76e971dadd19610d3ad38c768e124dc7","schema_version":"edge-lab-recorder.raw.v1","sequence":null,"source":"clob_market_ws"}
{"event_at":"2026-07-27T03:20:43.158000Z","event_fingerprint":"c17dbec4831baaa0ebed7206d61fed424f2172c163636fd4145cf9509987ccff","payload":{"connection_id":"c7dc2e4762f849c6b6f9306b6518dcab","event_at":"2026-07-27T03:20:43.158000Z","event_type":"price_change","frame_hash":"17ec1be2ff696fcdb8b69d23fef93073ca5828665aee9788746ff7a40c0f84f6","frame_index":0,"kind":"data","monotonic_ns":224426393672041,"payload":{"event_type":"price_change","market":"0x717c0e8ccd4d5c7040185188fbae28be901ca589a11a94b1b38ca36a79eccfeb","price_changes":[{"asset_id":"24254094493625419915756280046002869097156693848522361803041977572204227262166","best_ask":"0.43","best_bid":"0.42","hash":"3c6de1263c31cc07926fb1c0c40697dd2528e067","price":"0.37","side":"BUY","size":"46.39"},{"asset_id":"41448400836309843603620980831210604935021861034693225347475867885462478926555","best_ask":"0.58","best_bid":"0.57","hash":"1ebcdc5421ca546e930b680c5a3b008d4eb9a92d","price":"0.63","side":"SELL","size":"46.39"}],"timestamp":"1785122443158"},"payload_hash":"8f3d98bcc117cf3d841a21d6dfa57f831eb6983f96424cefbdbf1db496f349fc","raw_frame":"{\"market\":\"0x717c0e8ccd4d5c7040185188fbae28be901ca589a11a94b1b38ca36a79eccfeb\", \"price_changes\":[{\"asset_id\":\"24254094493625419915756280046002869097156693848522361803041977572204227262166\", \"price\":\"0.37\", \"size\":\"46.39\", \"side\":\"BUY\", \"hash\":\"3c6de1263c31cc07926fb1c0c40697dd2528e067\", \"best_bid\":\"0.42\", \"best_ask\":\"0.43\"}, {\"asset_id\":\"41448400836309843603620980831210604935021861034693225347475867885462478926555\", \"price\":\"0.63\", \"size\":\"46.39\", \"side\":\"SELL\", \"hash\":\"1ebcdc5421ca546e930b680c5a3b008d4eb9a92d\", \"best_bid\":\"0.57\", \"best_ask\":\"0.58\"}], \"timestamp\":\"1785122443158\", \"event_type\":\"price_change\"}","received_at":"2026-07-27T03:20:43.039361Z","schema_version":"clob-market-ws.price_change.v1","sequence":null,"server_hash":null,"server_timestamp":"1785122443158","session_id":"dd162b8dca5f43ff811d304e69a06123","source":"clob_market_ws"},"received_at":"2026-07-27T03:20:43.039361Z","record_id":"7c0e41c9b186644b03c9686f64222c1d824b38cd154b2160634fb354fc131e90","schema_fingerprint":"4aa3821a28b0b7c2400bc59aba4bcc0a76e971dadd19610d3ad38c768e124dc7","schema_version":"edge-lab-recorder.raw.v1","sequence":null,"source":"clob_market_ws"}
{"event_at":"2026-07-27T03:20:43.178000Z","event_fingerprint":"eab50e003b74700bc9e263640b982ec68c97356c04a0b9d1651cc45a12df3561","payload":{"connection_id":"c7dc2e4762f849c6b6f9306b6518dcab","event_at":"2026-07-27T03:20:43.178000Z","event_type":"price_change","frame_hash":"986811604492652f02f47118843f7a421fd808623a636ae6bf92ffbdc7de2438","frame_index":0,"kind":"data","monotonic_ns":224426415209125,"payload":{"event_type":"price_change","market":"0x717c0e8ccd4d5c7040185188fbae28be901ca589a11a94b1b38ca36a79eccfeb","price_changes":[{"asset_id":"24254094493625419915756280046002869097156693848522361803041977572204227262166","best_ask":"0.43","best_bid":"0.42","hash":"571758f7c912b41da34f30f8622e767dd074ee07","price":"0.38","side":"BUY","size":"69.07"},{"asset_id":"41448400836309843603620980831210604935021861034693225347475867885462478926555","best_ask":"0.58","best_bid":"0.57","hash":"e9709034eda84be1c4d60bd8b40e88b7befadb86","price":"0.62","side":"SELL","size":"69.07"}],"timestamp":"1785122443178"},"payload_hash":"661ceed27349e0d5bad2a69d2ffc069e552a028bc2608874a254c5571951bed4","raw_frame":"{\"market\":\"0x717c0e8ccd4d5c7040185188fbae28be901ca589a11a94b1b38ca36a79eccfeb\", \"price_changes\":[{\"asset_id\":\"24254094493625419915756280046002869097156693848522361803041977572204227262166\", \"price\":\"0.38\", \"size\":\"69.07\", \"side\":\"BUY\", \"hash\":\"571758f7c912b41da34f30f8622e767dd074ee07\", \"best_bid\":\"0.42\", \"best_ask\":\"0.43\"}, {\"asset_id\":\"41448400836309843603620980831210604935021861034693225347475867885462478926555\", \"price\":\"0.62\", \"size\":\"69.07\", \"side\":\"SELL\", \"hash\":\"e9709034eda84be1c4d60bd8b40e88b7befadb86\", \"best_bid\":\"0.57\", \"best_ask\":\"0.58\"}], \"timestamp\":\"1785122443178\", \"event_type\":\"price_change\"}","received_at":"2026-07-27T03:20:43.060897Z","schema_version":"clob-market-ws.price_change.v1","sequence":null,"server_hash":null,"server_timestamp":"1785122443178","session_id":"dd162b8dca5f43ff811d304e69a06123","source":"clob_market_ws"},"received_at":"2026-07-27T03:20:43.060897Z","record_id":"290d9238fa1d5a2b4d1c18ec79d318d99f2448b22426cdc50e5199c5ff92a0bd","schema_fingerprint":"4aa3821a28b0b7c2400bc59aba4bcc0a76e971dadd19610d3ad38c768e124dc7","schema_version":"edge-lab-recorder.raw.v1","sequence":null,"source":"clob_market_ws"}
{"event_at":"2026-07-27T03:20:43.181000Z","event_fingerprint":"87e9fca00797da1027459cb0b499e59d042a3f9a585a51a18833cbf3e03987ab","payload":{"connection_id":"c7dc2e4762f849c6b6f9306b6518dcab","event_at":"2026-07-27T03:20:43.181000Z","event_type":"price_change","frame_hash":"cdfacebb04dd7c7df11c44afd9248fba27007cf5e2f35a8c4738dbdf104e0797","frame_index":0,"kind":"data","monotonic_ns":224426418117583,"payload":{"event_type":"price_change","market":"0x717c0e8ccd4d5c7040185188fbae28be901ca589a11a94b1b38ca36a79eccfeb","price_changes":[{"asset_id":"41448400836309843603620980831210604935021861034693225347475867885462478926555","best_ask":"0.58","best_bid":"0.57","hash":"b2ba3793014ee84e9025b66ee95b896d8b459f91","price":"0.04","side":"BUY","size":"583.09"},{"asset_id":"24254094493625419915756280046002869097156693848522361803041977572204227262166","best_ask":"0.43","best_bid":"0.42","hash":"8288d9b1de747927c6f82229313117f3e6d594e1","price":"0.96","side":"SELL","size":"583.09"}],"timestamp":"1785122443181"},"payload_hash":"7f9e57933d318aca23e7cd3cbb1a3159b9b52fbb9520764f8e03a5599b84acaf","raw_frame":"{\"market\":\"0x717c0e8ccd4d5c7040185188fbae28be901ca589a11a94b1b38ca36a79eccfeb\", \"price_changes\":[{\"asset_id\":\"41448400836309843603620980831210604935021861034693225347475867885462478926555\", \"price\":\"0.04\", \"size\":\"583.09\", \"side\":\"BUY\", \"hash\":\"b2ba3793014ee84e9025b66ee95b896d8b459f91\", \"best_bid\":\"0.57\", \"best_ask\":\"0.58\"}, {\"asset_id\":\"24254094493625419915756280046002869097156693848522361803041977572204227262166\", \"price\":\"0.96\", \"size\":\"583.09\", \"side\":\"SELL\", \"hash\":\"8288d9b1de747927c6f82229313117f3e6d594e1\", \"best_bid\":\"0.42\", \"best_ask\":\"0.43\"}], \"timestamp\":\"1785122443181\", \"event_type\":\"price_change\"}","received_at":"2026-07-27T03:20:43.063806Z","schema_version":"clob-market-ws.price_change.v1","sequence":null,"server_hash":null,"server_timestamp":"1785122443181","session_id":"dd162b8dca5f43ff811d304e69a06123","source":"clob_market_ws"},"received_at":"2026-07-27T03:20:43.063806Z","record_id":"bc0984ec8363b961c49bc90cc314178718f2f49da67fcf051f5682b4bfe69183","schema_fingerprint":"4aa3821a28b0b7c2400bc59aba4bcc0a76e971dadd19610d3ad38c768e124dc7","schema_version":"edge-lab-recorder.raw.v1","sequence":null,"source":"clob_market_ws"}
{"event_at":"2026-07-27T03:20:43.234000Z","event_fingerprint":"87b6f71d80f0f616b03bb27abd9f0910f198cc475eb7f83a043923418e9e8235","payload":{"connection_id":"c7dc2e4762f849c6b6f9306b6518dcab","event_at":"2026-07-27T03:20:43.234000Z","event_type":"price_change","frame_hash":"1041e70c8098bbf0848708329a045755fba7e9e63d5e17f07e74c256731b59fb","frame_index":0,"kind":"data","monotonic_ns":224426472909375,"payload":{"event_type":"price_change","market":"0x717c0e8ccd4d5c7040185188fbae28be901ca589a11a94b1b38ca36a79eccfeb","price_changes":[{"asset_id":"24254094493625419915756280046002869097156693848522361803041977572204227262166","best_ask":"0.43","best_bid":"0.42","hash":"d0c3da75fa0f65614132912ad55f78520d88e62b","price":"0.34","side":"BUY","size":"15"},{"asset_id":"41448400836309843603620980831210604935021861034693225347475867885462478926555","best_ask":"0.58","best_bid":"0.57","hash":"031642f408fb0b1aa13434820afdb83a417b1db8","price":"0.66","side":"SELL","size":"15"}],"timestamp":"1785122443234"},"payload_hash":"aae28240323c657bb92678b0e6ba704720e992671f4860ff7111f54da4a83c25","raw_frame":"{\"market\":\"0x717c0e8ccd4d5c7040185188fbae28be901ca589a11a94b1b38ca36a79eccfeb\", \"price_changes\":[{\"asset_id\":\"24254094493625419915756280046002869097156693848522361803041977572204227262166\", \"price\":\"0.34\", \"size\":\"15\", \"side\":\"BUY\", \"hash\":\"d0c3da75fa0f65614132912ad55f78520d88e62b\", \"best_bid\":\"0.42\", \"best_ask\":\"0.43\"}, {\"asset_id\":\"41448400836309843603620980831210604935021861034693225347475867885462478926555\", \"price\":\"0.66\", \"size\":\"15\", \"side\":\"SELL\", \"hash\":\"031642f408fb0b1aa13434820afdb83a417b1db8\", \"best_bid\":\"0.57\", \"best_ask\":\"0.58\"}], \"timestamp\":\"1785122443234\", \"event_type\":\"price_change\"}","received_at":"2026-07-27T03:20:43.118595Z","schema_version":"clob-market-ws.price_change.v1","sequence":null,"server_hash":null,"server_timestamp":"1785122443234","session_id":"dd162b8dca5f43ff811d304e69a06123","source":"clob_market_ws"},"received_at":"2026-07-27T03:20:43.118595Z","record_id":"c4cb3910a8bef7aee5966e74acdbc862867a77728f592b68711aff49a13cf4ba","schema_fingerprint":"4aa3821a28b0b7c2400bc59aba4bcc0a76e971dadd19610d3ad38c768e124dc7","schema_version":"edge-lab-recorder.raw.v1","sequence":null,"source":"clob_market_ws"}
{"event_at":"2026-07-27T03:20:43.234000Z","event_fingerprint":"ba7fd1f1c6c2deaf703adc6683a90cc69c1767cf63f9a19698a5fc601128b846","payload":{"connection_id":"c7dc2e4762f849c6b6f9306b6518dcab","event_at":"2026-07-27T03:20:43.234000Z","event_type":"price_change","frame_hash":"569d829259f0327d39460370db364b466b45e535575e09cd16918eb79c6c3aa1","frame_index":0,"kind":"data","monotonic_ns":224426475909000,"payload":{"event_type":"price_change","market":"0x717c0e8ccd4d5c7040185188fbae28be901ca589a11a94b1b38ca36a79eccfeb","price_changes":[{"asset_id":"41448400836309843603620980831210604935021861034693225347475867885462478926555","best_ask":"0.58","best_bid":"0.57","hash":"031642f408fb0b1aa13434820afdb83a417b1db8","price":"0.54","side":"BUY","size":"105"},{"asset_id":"24254094493625419915756280046002869097156693848522361803041977572204227262166","best_ask":"0.43","best_bid":"0.42","hash":"d0c3da75fa0f65614132912ad55f78520d88e62b","price":"0.46","side":"SELL","size":"105"}],"timestamp":"1785122443234"},"payload_hash":"618ce264dccd0007cf00d42e1cff483694983c165298d6800a6a31f4a26ccb71","raw_frame":"{\"market\":\"0x717c0e8ccd4d5c7040185188fbae28be901ca589a11a94b1b38ca36a79eccfeb\", \"price_changes\":[{\"asset_id\":\"41448400836309843603620980831210604935021861034693225347475867885462478926555\", \"price\":\"0.54\", \"size\":\"105\", \"side\":\"BUY\", \"hash\":\"031642f408fb0b1aa13434820afdb83a417b1db8\", \"best_bid\":\"0.57\", \"best_ask\":\"0.58\"}, {\"asset_id\":\"24254094493625419915756280046002869097156693848522361803041977572204227262166\", \"price\":\"0.46\", \"size\":\"105\", \"side\":\"SELL\", \"hash\":\"d0c3da75fa0f65614132912ad55f78520d88e62b\", \"best_bid\":\"0.42\", \"best_ask\":\"0.43\"}], \"timestamp\":\"1785122443234\", \"event_type\":\"price_change\"}","received_at":"2026-07-27T03:20:43.121595Z","schema_version":"clob-market-ws.price_change.v1","sequence":null,"server_hash":null,"server_timestamp":"1785122443234","session_id":"dd162b8dca5f43ff811d304e69a06123","source":"clob_market_ws"},"received_at":"2026-07-27T03:20:43.121595Z","record_id":"d7d920a6d8f99c41a8ba76397690665a0f0be9cf7b73d456bfa88683f75d16e4","schema_fingerprint":"4aa3821a28b0b7c2400bc59aba4bcc0a76e971dadd19610d3ad38c768e124dc7","schema_version":"edge-lab-recorder.raw.v1","sequence":null,"source":"clob_market_ws"}
{"event_at":"2026-07-27T03:20:43.234000Z","event_fingerprint":"afec1d885cc6c7b22b80bdb3e6b32668463040f0ff2a388739a9cbd33c6bd705","payload":{"connection_id":"c7dc2e4762f849c6b6f9306b6518dcab","event_at":"2026-07-27T03:20:43.234000Z","event_type":"price_change","frame_hash":"43a22e221455d45a26d00af03a023528b005637e066b2f6b1e4e4c71f173f611","frame_index":0,"kind":"data","monotonic_ns":224426479268750,"payload":{"event_type":"price_change","market":"0x717c0e8ccd4d5c7040185188fbae28be901ca589a11a94b1b38ca36a79eccfeb","price_changes":[{"asset_id":"24254094493625419915756280046002869097156693848522361803041977572204227262166","best_ask":"0.43","best_bid":"0.42","hash":"d0c3da75fa0f65614132912ad55f78520d88e62b","price":"0.38","side":"BUY","size":"62.07"},{"asset_id":"41448400836309843603620980831210604935021861034693225347475867885462478926555","best_ask":"0.58","best_bid":"0.57","hash":"031642f408fb0b1aa13434820afdb83a417b1db8","price":"0.62","side":"SELL","size":"62.07"}],"timestamp":"1785122443234"},"payload_hash":"8a04e11de977e8696002843248e689bbe0a50a4c52a94721887484fb6f816105","raw_frame":"{\"market\":\"0x717c0e8ccd4d5c7040185188fbae28be901ca589a11a94b1b38ca36a79eccfeb\", \"price_changes\":[{\"asset_id\":\"24254094493625419915756280046002869097156693848522361803041977572204227262166\", \"price\":\"0.38\", \"size\":\"62.07\", \"side\":\"BUY\", \"hash\":\"d0c3da75fa0f65614132912ad55f78520d88e62b\", \"best_bid\":\"0.42\", \"best_ask\":\"0.43\"}, {\"asset_id\":\"41448400836309843603620980831210604935021861034693225347475867885462478926555\", \"price\":\"0.62\", \"size\":\"62.07\", \"side\":\"SELL\", \"hash\":\"031642f408fb0b1aa13434820afdb83a417b1db8\", \"best_bid\":\"0.57\", \"best_ask\":\"0.58\"}], \"timestamp\":\"1785122443234\", \"event_type\":\"price_change\"}","received_at":"2026-07-27T03:20:43.124955Z","schema_version":"clob-market-ws.price_change.v1","sequence":null,"server_hash":null,"server_timestamp":"1785122443234","session_id":"dd162b8dca5f43ff811d304e69a06123","source":"clob_market_ws"},"received_at":"2026-07-27T03:20:43.124955Z","record_id":"c7aefd55e2d870c2dc0a0c5ffd8e12141ee45c50822ec1d60ee1bf93adf6746b","schema_fingerprint":"4aa3821a28b0b7c2400bc59aba4bcc0a76e971dadd19610d3ad38c768e124dc7","schema_version":"edge-lab-recorder.raw.v1","sequence":null,"source":"clob_market_ws"}
{"event_at":"2026-07-27T03:20:43.234000Z","event_fingerprint":"91dda824aed88233ba754d8b410823798e13c11dc2c43c903ea74044f65a3874","payload":{"connection_id":"c7dc2e4762f849c6b6f9306b6518dcab","event_at":"2026-07-27T03:20:43.234000Z","event_type":"price_change","frame_hash":"3c22073605deef237528062446a7d8ae8015150411f73cd37d7108dca565f654","frame_index":0,"kind":"data","monotonic_ns":224426482074000,"payload":{"event_type":"price_change","market":"0x717c0e8ccd4d5c7040185188fbae28be901ca589a11a94b1b38ca36a79eccfeb","price_changes":[{"asset_id":"24254094493625419915756280046002869097156693848522361803041977572204227262166","best_ask":"0.43","best_bid":"0.42","hash":"d0c3da75fa0f65614132912ad55f78520d88e62b","price":"0.36","side":"BUY","size":"26.88"},{"asset_id":"41448400836309843603620980831210604935021861034693225347475867885462478926555","best_ask":"0.58","best_bid":"0.57","hash":"031642f408fb0b1aa13434820afdb83a417b1db8","price":"0.64","side":"SELL","size":"26.88"}],"timestamp":"1785122443234"},"payload_hash":"30faf63aaece27ef5352e6785b8b337e606d6b32384a9e22ae3c931f48926f5f","raw_frame":"{\"market\":\"0x717c0e8ccd4d5c7040185188fbae28be901ca589a11a94b1b38ca36a79eccfeb\", \"price_changes\":[{\"asset_id\":\"24254094493625419915756280046002869097156693848522361803041977572204227262166\", \"price\":\"0.36\", \"size\":\"26.88\", \"side\":\"BUY\", \"hash\":\"d0c3da75fa0f65614132912ad55f78520d88e62b\", \"best_bid\":\"0.42\", \"best_ask\":\"0.43\"}, {\"asset_id\":\"41448400836309843603620980831210604935021861034693225347475867885462478926555\", \"price\":\"0.64\", \"size\":\"26.88\", \"side\":\"SELL\", \"hash\":\"031642f408fb0b1aa13434820afdb83a417b1db8\", \"best_bid\":\"0.57\", \"best_ask\":\"0.58\"}], \"timestamp\":\"1785122443234\", \"event_type\":\"price_change\"}","received_at":"2026-07-27T03:20:43.127761Z","schema_version":"clob-market-ws.price_change.v1","sequence":null,"server_hash":null,"server_timestamp":"1785122443234","session_id":"dd162b8dca5f43ff811d304e69a06123","source":"clob_market_ws"},"received_at":"2026-07-27T03:20:43.127761Z","record_id":"6f835564c8663096101fe1fa70eeda648d1a9cf439def731bf5d57326d41b220","schema_fingerprint":"4aa3821a28b0b7c2400bc59aba4bcc0a76e971dadd19610d3ad38c768e124dc7","schema_version":"edge-lab-recorder.raw.v1","sequence":null,"source":"clob_market_ws"}
{"event_at":"2026-07-27T03:20:43.234000Z","event_fingerprint":"4fe77c26f3717b6a48ce2193f86fe4700c670328b4549e2f17d9da06c2895cee","payload":{"connection_id":"c7dc2e4762f849c6b6f9306b6518dcab","event_at":"2026-07-27T03:20:43.234000Z","event_type":"price_change","frame_hash":"773f415ce917e1f9874b21236196ffacc4b7582f4ef40ebd052af2c60cfa41ee","frame_index":0,"kind":"data","monotonic_ns":224426484977625,"payload":{"event_type":"price_change","market":"0x717c0e8ccd4d5c7040185188fbae28be901ca589a11a94b1b38ca36a79eccfeb","price_changes":[{"asset_id":"41448400836309843603620980831210604935021861034693225347475867885462478926555","best_ask":"0.58","best_bid":"0.57","hash":"031642f408fb0b1aa13434820afdb83a417b1db8","price":"0.52","side":"BUY","size":"15"},{"asset_id":"24254094493625419915756280046002869097156693848522361803041977572204227262166","best_ask":"0.43","best_bid":"0.42","hash":"d0c3da75fa0f65614132912ad55f78520d88e62b","price":"0.48","side":"SELL","size":"15"}],"timestamp":"1785122443234"},"payload_hash":"4d4b78b87ebbe1bfaef16eb39f7d41101f0a1d76230503c203ad093dd5564798","raw_frame":"{\"market\":\"0x717c0e8ccd4d5c7040185188fbae28be901ca589a11a94b1b38ca36a79eccfeb\", \"price_changes\":[{\"asset_id\":\"41448400836309843603620980831210604935021861034693225347475867885462478926555\", \"price\":\"0.52\", \"size\":\"15\", \"side\":\"BUY\", \"hash\":\"031642f408fb0b1aa13434820afdb83a417b1db8\", \"best_bid\":\"0.57\", \"best_ask\":\"0.58\"}, {\"asset_id\":\"24254094493625419915756280046002869097156693848522361803041977572204227262166\", \"price\":\"0.48\", \"size\":\"15\", \"side\":\"SELL\", \"hash\":\"d0c3da75fa0f65614132912ad55f78520d88e62b\", \"best_bid\":\"0.42\", \"best_ask\":\"0.43\"}], \"timestamp\":\"1785122443234\", \"event_type\":\"price_change\"}","received_at":"2026-07-27T03:20:43.130666Z","schema_version":"clob-market-ws.price_change.v1","sequence":null,"server_hash":null,"server_timestamp":"1785122443234","session_id":"dd162b8dca5f43ff811d304e69a06123","source":"clob_market_ws"},"received_at":"2026-07-27T03:20:43.130666Z","record_id":"9a4e62d49d9c08d945546558ec18e622f5645fda6b0c38a34e14f769fe0d73c4","schema_fingerprint":"4aa3821a28b0b7c2400bc59aba4bcc0a76e971dadd19610d3ad38c768e124dc7","schema_version":"edge-lab-recorder.raw.v1","sequence":null,"source":"clob_market_ws"}
{"event_at":"2026-07-27T03:20:43.253000Z","event_fingerprint":"cd6af26107a86ac6ecd61a3320e002033fc790fe7e6ad4d0c8ed884880d7efbe","payload":{"connection_id":"c7dc2e4762f849c6b6f9306b6518dcab","event_at":"2026-07-27T03:20:43.253000Z","event_type":"price_change","frame_hash":"fa723c9743c796881d58e2a8a3f1e6a8dd53d091f74edbddbb5567e0d819cdac","frame_index":0,"kind":"data","monotonic_ns":224426489030375,"payload":{"event_type":"price_change","market":"0x717c0e8ccd4d5c7040185188fbae28be901ca589a11a94b1b38ca36a79eccfeb","price_changes":[{"asset_id":"41448400836309843603620980831210604935021861034693225347475867885462478926555","best_ask":"0.58","best_bid":"0.57","hash":"28611c2bb3b3d727cf09ddf325f5b6e99758cbae","price":"0.01","side":"BUY","size":"5708.02"},{"asset_id":"24254094493625419915756280046002869097156693848522361803041977572204227262166","best_ask":"0.43","best_bid":"0.42","hash":"970e7fbd17e2b98c3864a5ff6d4496b42860e0f1","price":"0.99","side":"SELL","size":"5708.02"}],"timestamp":"1785122443253"},"payload_hash":"c5c233a619e21893a0bebe516f995a70a2a4c2be73f1ff40b180f9f6bfb7eabe","raw_frame":"{\"market\":\"0x717c0e8ccd4d5c7040185188fbae28be901ca589a11a94b1b38ca36a79eccfeb\", \"price_changes\":[{\"asset_id\":\"41448400836309843603620980831210604935021861034693225347475867885462478926555\", \"price\":\"0.01\", \"size\":\"5708.02\", \"side\":\"BUY\", \"hash\":\"28611c2bb3b3d727cf09ddf325f5b6e99758cbae\", \"best_bid\":\"0.57\", \"best_ask\":\"0.58\"}, {\"asset_id\":\"24254094493625419915756280046002869097156693848522361803041977572204227262166\", \"price\":\"0.99\", \"size\":\"5708.02\", \"side\":\"SELL\", \"hash\":\"970e7fbd17e2b98c3864a5ff6d4496b42860e0f1\", \"best_bid\":\"0.42\", \"best_ask\":\"0.43\"}], \"timestamp\":\"1785122443253\", \"event_type\":\"price_change\"}","received_at":"2026-07-27T03:20:43.134718Z","schema_version":"clob-market-ws.price_change.v1","sequence":null,"server_hash":null,"server_timestamp":"1785122443253","session_id":"dd162b8dca5f43ff811d304e69a06123","source":"clob_market_ws"},"received_at":"2026-07-27T03:20:43.134718Z","record_id":"3c60c8916b3e36a9e298b422627f8039375adcb2a868718409413d50b436beca","schema_fingerprint":"4aa3821a28b0b7c2400bc59aba4bcc0a76e971dadd19610d3ad38c768e124dc7","schema_version":"edge-lab-recorder.raw.v1","sequence":null,"source":"clob_market_ws"}
{"event_at":"2026-07-27T03:20:43.256000Z","event_fingerprint":"7da0c2e1b6b3ddaacba33c4f69243c7a4fa86835a64f96797081118768fdd5b1","payload":{"connection_id":"c7dc2e4762f849c6b6f9306b6518dcab","event_at":"2026-07-27T03:20:43.256000Z","event_type":"price_change","frame_hash":"0364d6141f87c32650d2257d9760bad482ab48987bd53e97eb17e6a8c916c1c0","frame_index":0,"kind":"data","monotonic_ns":224426493216333,"payload":{"event_type":"price_change","market":"0x717c0e8ccd4d5c7040185188fbae28be901ca589a11a94b1b38ca36a79eccfeb","price_changes":[{"asset_id":"41448400836309843603620980831210604935021861034693225347475867885462478926555","best_ask":"0.58","best_bid":"0.57","hash":"f5b25b7b169d784666d105c6c8376b9b5ea4253c","price":"0.53","side":"BUY","size":"14"},{"asset_id":"24254094493625419915756280046002869097156693848522361803041977572204227262166","best_ask":"0.43","best_bid":"0.42","hash":"323304ed525f8087682525f10c6774176c5761bb","price":"0.47","side":"SELL","size":"14"}],"timestamp":"1785122443256"},"payload_hash":"c51ba5b349c894d0469acd0d5d9b4495bd90ad610cc291a01ef937bdf2dc153b","raw_frame":"{\"market\":\"0x717c0e8ccd4d5c7040185188fbae28be901ca589a11a94b1b38ca36a79eccfeb\", \"price_changes\":[{\"asset_id\":\"41448400836309843603620980831210604935021861034693225347475867885462478926555\", \"price\":\"0.53\", \"size\":\"14\", \"side\":\"BUY\", \"hash\":\"f5b25b7b169d784666d105c6c8376b9b5ea4253c\", \"best_bid\":\"0.57\", \"best_ask\":\"0.58\"}, {\"asset_id\":\"24254094493625419915756280046002869097156693848522361803041977572204227262166\", \"price\":\"0.47\", \"size\":\"14\", \"side\":\"SELL\", \"hash\":\"323304ed525f8087682525f10c6774176c5761bb\", \"best_bid\":\"0.42\", \"best_ask\":\"0.43\"}], \"timestamp\":\"1785122443256\", \"event_type\":\"price_change\"}","received_at":"2026-07-27T03:20:43.138902Z","schema_version":"clob-market-ws.price_change.v1","sequence":null,"server_hash":null,"server_timestamp":"1785122443256","session_id":"dd162b8dca5f43ff811d304e69a06123","source":"clob_market_ws"},"received_at":"2026-07-27T03:20:43.138902Z","record_id":"0cd5c4cecbf8ddd4acba1383853c18afbf374bfc63ca19389edc9e6d179d62f7","schema_fingerprint":"4aa3821a28b0b7c2400bc59aba4bcc0a76e971dadd19610d3ad38c768e124dc7","schema_version":"edge-lab-recorder.raw.v1","sequence":null,"source":"clob_market_ws"}
{"event_at":"2026-07-27T03:20:43.257000Z","event_fingerprint":"aa4a15b1881dd75185041d22c6dda2eb8f6e32ccef5c4e87f6f2240d11696960","payload":{"connection_id":"c7dc2e4762f849c6b6f9306b6518dcab","event_at":"2026-07-27T03:20:43.257000Z","event_type":"price_change","frame_hash":"cbf4a9a97010adbddf1792ffda2b27b1d965e92c894b4f7641fd10e4622f4136","frame_index":0,"kind":"data","monotonic_ns":224426498088625,"payload":{"event_type":"price_change","market":"0x717c0e8ccd4d5c7040185188fbae28be901ca589a11a94b1b38ca36a79eccfeb","price_changes":[{"asset_id":"41448400836309843603620980831210604935021861034693225347475867885462478926555","best_ask":"0.58","best_bid":"0.57","hash":"24b61b29ff6825ff1fc713cfe73706acce5d6592","price":"0.55","side":"BUY","size":"312"},{"asset_id":"24254094493625419915756280046002869097156693848522361803041977572204227262166","best_ask":"0.43","best_bid":"0.42","hash":"640b0ecb18b7f5dfe993ac4e59f728805222ac8c","price":"0.45","side":"SELL","size":"312"}],"timestamp":"1785122443257"},"payload_hash":"77c6cb8ec934c832e1e6c0e9d6ebb59d2e87676aa2f6a2a54d157be1fa62448b","raw_frame":"{\"market\":\"0x717c0e8ccd4d5c7040185188fbae28be901ca589a11a94b1b38ca36a79eccfeb\", \"price_changes\":[{\"asset_id\":\"41448400836309843603620980831210604935021861034693225347475867885462478926555\", \"price\":\"0.55\", \"size\":\"312\", \"side\":\"BUY\", \"hash\":\"24b61b29ff6825ff1fc713cfe73706acce5d6592\", \"best_bid\":\"0.57\", \"best_ask\":\"0.58\"}, {\"asset_id\":\"24254094493625419915756280046002869097156693848522361803041977572204227262166\", \"price\":\"0.45\", \"size\":\"312\", \"side\":\"SELL\", \"hash\":\"640b0ecb18b7f5dfe993ac4e59f728805222ac8c\", \"best_bid\":\"0.42\", \"best_ask\":\"0.43\"}], \"timestamp\":\"1785122443257\", \"event_type\":\"price_change\"}","received_at":"2026-07-27T03:20:43.143775Z","schema_version":"clob-market-ws.price_change.v1","sequence":null,"server_hash":null,"server_timestamp":"1785122443257","session_id":"dd162b8dca5f43ff811d304e69a06123","source":"clob_market_ws"},"received_at":"2026-07-27T03:20:43.143775Z","record_id":"3f401f161efc4958e81f2f857272060ce7731c087781d8978219d24895fb05ac","schema_fingerprint":"4aa3821a28b0b7c2400bc59aba4bcc0a76e971dadd19610d3ad38c768e124dc7","schema_version":"edge-lab-recorder.raw.v1","sequence":null,"source":"clob_market_ws"}
{"event_at":"2026-07-27T03:20:43.258000Z","event_fingerprint":"c4573e1bcdc9f3557adf712acb7c76ce048de8b16072e7040ae07d53cee5480b","payload":{"connection_id":"c7dc2e4762f849c6b6f9306b6518dcab","event_at":"2026-07-27T03:20:43.258000Z","event_type":"price_change","frame_hash":"1ea8bc48a839609909315e620e5a5badc71cb6550239954e84e2976d90c8f424","frame_index":0,"kind":"data","monotonic_ns":224426500599041,"payload":{"event_type":"price_change","market":"0x717c0e8ccd4d5c7040185188fbae28be901ca589a11a94b1b38ca36a79eccfeb","price_changes":[{"asset_id":"24254094493625419915756280046002869097156693848522361803041977572204227262166","best_ask":"0.43","best_bid":"0.42","hash":"f23bc779385cd124ef4c59354ea6e72ed95f0d37","price":"0.35","side":"BUY","size":"116"},{"asset_id":"41448400836309843603620980831210604935021861034693225347475867885462478926555","best_ask":"0.58","best_bid":"0.57","hash":"422f54185c341e01c078368a842b4e6153eee069","price":"0.65","side":"SELL","size":"116"}],"timestamp":"1785122443258"},"payload_hash":"c84c7c5ac13dfa85482bc6ea7f37f0c583e56115443801a098d0d470598e8af6","raw_frame":"{\"market\":\"0x717c0e8ccd4d5c7040185188fbae28be901ca589a11a94b1b38ca36a79eccfeb\", \"price_changes\":[{\"asset_id\":\"24254094493625419915756280046002869097156693848522361803041977572204227262166\", \"price\":\"0.35\", \"size\":\"116\", \"side\":\"BUY\", \"hash\":\"f23bc779385cd124ef4c59354ea6e72ed95f0d37\", \"best_bid\":\"0.42\", \"best_ask\":\"0.43\"}, {\"asset_id\":\"41448400836309843603620980831210604935021861034693225347475867885462478926555\", \"price\":\"0.65\", \"size\":\"116\", \"side\":\"SELL\", \"hash\":\"422f54185c341e01c078368a842b4e6153eee069\", \"best_bid\":\"0.57\", \"best_ask\":\"0.58\"}], \"timestamp\":\"1785122443258\", \"event_type\":\"price_change\"}","received_at":"2026-07-27T03:20:43.146286Z","schema_version":"clob-market-ws.price_change.v1","sequence":null,"server_hash":null,"server_timestamp":"1785122443258","session_id":"dd162b8dca5f43ff811d304e69a06123","source":"clob_market_ws"},"received_at":"2026-07-27T03:20:43.146286Z","record_id":"52b69241752061e3a45d92799cd997681200d72ad3f1978044328cd5d5c9bcb3","schema_fingerprint":"4aa3821a28b0b7c2400bc59aba4bcc0a76e971dadd19610d3ad38c768e124dc7","schema_version":"edge-lab-recorder.raw.v1","sequence":null,"source":"clob_market_ws"}
{"event_at":"2026-07-27T03:20:43.258000Z","event_fingerprint":"9aea596f0a216da48614d21c4cb405f91b98a213369da536a64913789bc1fb5a","payload":{"connection_id":"c7dc2e4762f849c6b6f9306b6518dcab","event_at":"2026-07-27T03:20:43.258000Z","event_type":"price_change","frame_hash":"bc48864a17a5702c15d5a884dbc8f22703807e9052a34307c62aceb4867b10df","frame_index":0,"kind":"data","monotonic_ns":224426503023083,"payload":{"event_type":"price_change","market":"0x717c0e8ccd4d5c7040185188fbae28be901ca589a11a94b1b38ca36a79eccfeb","price_changes":[{"asset_id":"24254094493625419915756280046002869097156693848522361803041977572204227262166","best_ask":"0.43","best_bid":"0.42","hash":"6084cb3bf734dc2bc9bddcfee6f5a82e49b56f0a","price":"0.37","side":"BUY","size":"51.39"},{"asset_id":"41448400836309843603620980831210604935021861034693225347475867885462478926555","best_ask":"0.58","best_bid":"0.57","hash":"265073da5595cbb8273f62c916d6371f3cd83a03","price":"0.63","side":"SELL","size":"51.39"}],"timestamp":"1785122443258"},"payload_hash":"1b3ea3c52ed187cb5a72ad32b592b23575a654784888fca6939b1fcf918a0452","raw_frame":"{\"market\":\"0x717c0e8ccd4d5c7040185188fbae28be901ca589a11a94b1b38ca36a79eccfeb\", \"price_changes\":[{\"asset_id\":\"24254094493625419915756280046002869097156693848522361803041977572204227262166\", \"price\":\"0.37\", \"size\":\"51.39\", \"side\":\"BUY\", \"hash\":\"6084cb3bf734dc2bc9bddcfee6f5a82e49b56f0a\", \"best_bid\":\"0.42\", \"best_ask\":\"0.43\"}, {\"asset_id\":\"41448400836309843603620980831210604935021861034693225347475867885462478926555\", \"price\":\"0.63\", \"size\":\"51.39\", \"side\":\"SELL\", \"hash\":\"265073da5595cbb8273f62c916d6371f3cd83a03\", \"best_bid\":\"0.57\", \"best_ask\":\"0.58\"}], \"timestamp\":\"1785122443258\", \"event_type\":\"price_change\"}","received_at":"2026-07-27T03:20:43.148710Z","schema_version":"clob-market-ws.price_change.v1","sequence":null,"server_hash":null,"server_timestamp":"1785122443258","session_id":"dd162b8dca5f43ff811d304e69a06123","source":"clob_market_ws"},"received_at":"2026-07-27T03:20:43.148710Z","record_id":"f0af6f3079855d217e83a4eab4240ce9eba64bcf87863edf600923c98b9ab061","schema_fingerprint":"4aa3821a28b0b7c2400bc59aba4bcc0a76e971dadd19610d3ad38c768e124dc7","schema_version":"edge-lab-recorder.raw.v1","sequence":null,"source":"clob_market_ws"}
{"event_at":"2026-07-27T03:20:43.262000Z","event_fingerprint":"576b9c4ef65bec75489860f73f202bd6ebd6b0b2604634f86a134155ab51642d","payload":{"connection_id":"c7dc2e4762f849c6b6f9306b6518dcab","event_at":"2026-07-27T03:20:43.262000Z","event_type":"price_change","frame_hash":"425c6d986e310060a4b78e4a1523005e383671decb5c07a279db65f7c0ad69bb","frame_index":0,"kind":"data","monotonic_ns":224426506077750,"payload":{"event_type":"price_change","market":"0x717c0e8ccd4d5c7040185188fbae28be901ca589a11a94b1b38ca36a79eccfeb","price_changes":[{"asset_id":"41448400836309843603620980831210604935021861034693225347475867885462478926555","best_ask":"0.58","best_bid":"0.57","hash":"2d080a07629d71d1f688fecf2eb2ff4a8ed76794","price":"0.04","side":"BUY","size":"578.09"},{"asset_id":"24254094493625419915756280046002869097156693848522361803041977572204227262166","best_ask":"0.43","best_bid":"0.42","hash":"d5f6ad42ad9ca8d3bb9383fb0b25d00254d61d70","price":"0.96","side":"SELL","size":"578.09"}],"timestamp":"1785122443262"},"payload_hash":"72b827d6ec301d01a325c9cb6251bc97599df0173243943f32f644551e6ddaa3","raw_frame":"{\"market\":\"0x717c0e8ccd4d5c7040185188fbae28be901ca589a11a94b1b38ca36a79eccfeb\", \"price_changes\":[{\"asset_id\":\"41448400836309843603620980831210604935021861034693225347475867885462478926555\", \"price\":\"0.04\", \"size\":\"578.09\", \"side\":\"BUY\", \"hash\":\"2d080a07629d71d1f688fecf2eb2ff4a8ed76794\", \"best_bid\":\"0.57\", \"best_ask\":\"0.58\"}, {\"asset_id\":\"24254094493625419915756280046002869097156693848522361803041977572204227262166\", \"price\":\"0.96\", \"size\":\"578.09\", \"side\":\"SELL\", \"hash\":\"d5f6ad42ad9ca8d3bb9383fb0b25d00254d61d70\", \"best_bid\":\"0.42\", \"best_ask\":\"0.43\"}], \"timestamp\":\"1785122443262\", \"event_type\":\"price_change\"}","received_at":"2026-07-27T03:20:43.151764Z","schema_version":"clob-market-ws.price_change.v1","sequence":null,"server_hash":null,"server_timestamp":"1785122443262","session_id":"dd162b8dca5f43ff811d304e69a06123","source":"clob_market_ws"},"received_at":"2026-07-27T03:20:43.151764Z","record_id":"0ba3e63af59aec0f834d1898820152daaa962e3be429e1da4de21300534307cd","schema_fingerprint":"4aa3821a28b0b7c2400bc59aba4bcc0a76e971dadd19610d3ad38c768e124dc7","schema_version":"edge-lab-recorder.raw.v1","sequence":null,"source":"clob_market_ws"}
{"event_at":"2026-07-27T03:20:43.270000Z","event_fingerprint":"d38a22f325efb28615226d451df6b8114a432918926ea1b69621caa50b3d4993","payload":{"connection_id":"c7dc2e4762f849c6b6f9306b6518dcab","event_at":"2026-07-27T03:20:43.270000Z","event_type":"price_change","frame_hash":"15a4451ee34f6b9180cd62538c71ce53ea3c231e668ca4599ab3a934af3a4c70","frame_index":0,"kind":"data","monotonic_ns":224426508975541,"payload":{"event_type":"price_change","market":"0x717c0e8ccd4d5c7040185188fbae28be901ca589a11a94b1b38ca36a79eccfeb","price_changes":[{"asset_id":"41448400836309843603620980831210604935021861034693225347475867885462478926555","best_ask":"0.58","best_bid":"0.57","hash":"7bef5f530cc84d3469535111e04949dfe1a6913b","price":"0.01","side":"BUY","size":"5703.02"},{"asset_id":"24254094493625419915756280046002869097156693848522361803041977572204227262166","best_ask":"0.43","best_bid":"0.42","hash":"e26ee224f832d409a1483f23f15d2af5fb483866","price":"0.99","side":"SELL","size":"5703.02"}],"timestamp":"1785122443270"},"payload_hash":"4a0e5d617d2967c6356155e1a7df83f835bde8d95aa03584003d0df07f2fd256","raw_frame":"{\"market\":\"0x717c0e8ccd4d5c7040185188fbae28be901ca589a11a94b1b38ca36a79eccfeb\", \"price_changes\":[{\"asset_id\":\"41448400836309843603620980831210604935021861034693225347475867885462478926555\", \"price\":\"0.01\", \"size\":\"5703.02\", \"side\":\"BUY\", \"hash\":\"7bef5f530cc84d3469535111e04949dfe1a6913b\", \"best_bid\":\"0.57\", \"best_ask\":\"0.58\"}, {\"asset_id\":\"24254094493625419915756280046002869097156693848522361803041977572204227262166\", \"price\":\"0.99\", \"size\":\"5703.02\", \"side\":\"SELL\", \"hash\":\"e26ee224f832d409a1483f23f15d2af5fb483866\", \"best_bid\":\"0.42\", \"best_ask\":\"0.43\"}], \"timestamp\":\"1785122443270\", \"event_type\":\"price_change\"}","received_at":"2026-07-27T03:20:43.154662Z","schema_version":"clob-market-ws.price_change.v1","sequence":null,"server_hash":null,"server_timestamp":"1785122443270","session_id":"dd162b8dca5f43ff811d304e69a06123","source":"clob_market_ws"},"received_at":"2026-07-27T03:20:43.154662Z","record_id":"a813e4e4d7cd2e3b539c692c24f2a33c97f34aa9d7633396870dbda6e060e2c3","schema_fingerprint":"4aa3821a28b0b7c2400bc59aba4bcc0a76e971dadd19610d3ad38c768e124dc7","schema_version":"edge-lab-recorder.raw.v1","sequence":null,"source":"clob_market_ws"}
{"event_at":"2026-07-27T03:20:43.345000Z","event_fingerprint":"71c38e0a56b039301d70c9621dd12ea0633ca044c9beb93ebeb77dbb5c4d32a4","payload":{"connection_id":"c7dc2e4762f849c6b6f9306b6518dcab","event_at":"2026-07-27T03:20:43.345000Z","event_type":"price_change","frame_hash":"5a6df5a7d061576e1af05eaa10b884d19ea9c5c43905614d39fae6dbf4804cf6","frame_index":0,"kind":"data","monotonic_ns":224426580240166,"payload":{"event_type":"price_change","market":"0x717c0e8ccd4d5c7040185188fbae28be901ca589a11a94b1b38ca36a79eccfeb","price_changes":[{"asset_id":"24254094493625419915756280046002869097156693848522361803041977572204227262166","best_ask":"0.43","best_bid":"0.42","hash":"adc5dc851ec2ab36010f65ebf7a9fd51fbe7c2e6","price":"0.36","side":"BUY","size":"31.88"},{"asset_id":"41448400836309843603620980831210604935021861034693225347475867885462478926555","best_ask":"0.58","best_bid":"0.57","hash":"b45b67bc6bc3313590d751a82442180745a85c0c","price":"0.64","side":"SELL","size":"31.88"}],"timestamp":"1785122443345"},"payload_hash":"66199521f9dfa00b92da4a45a425909fc08edef614f40a27fabb6da024ed3be9","raw_frame":"{\"market\":\"0x717c0e8ccd4d5c7040185188fbae28be901ca589a11a94b1b38ca36a79eccfeb\", \"price_changes\":[{\"asset_id\":\"24254094493625419915756280046002869097156693848522361803041977572204227262166\", \"price\":\"0.36\", \"size\":\"31.88\", \"side\":\"BUY\", \"hash\":\"adc5dc851ec2ab36010f65ebf7a9fd51fbe7c2e6\", \"best_bid\":\"0.42\", \"best_ask\":\"0.43\"}, {\"asset_id\":\"41448400836309843603620980831210604935021861034693225347475867885462478926555\", \"price\":\"0.64\", \"size\":\"31.88\", \"side\":\"SELL\", \"hash\":\"b45b67bc6bc3313590d751a82442180745a85c0c\", \"best_bid\":\"0.57\", \"best_ask\":\"0.58\"}], \"timestamp\":\"1785122443345\", \"event_type\":\"price_change\"}","received_at":"2026-07-27T03:20:43.225923Z","schema_version":"clob-market-ws.price_change.v1","sequence":null,"server_hash":null,"server_timestamp":"1785122443345","session_id":"dd162b8dca5f43ff811d304e69a06123","source":"clob_market_ws"},"received_at":"2026-07-27T03:20:43.225923Z","record_id":"fc52721a61847edda0bd46bfdd91a0786e58c0f15348dc811aad396ae29a00e2","schema_fingerprint":"4aa3821a28b0b7c2400bc59aba4bcc0a76e971dadd19610d3ad38c768e124dc7","schema_version":"edge-lab-recorder.raw.v1","sequence":null,"source":"clob_market_ws"}
{"event_at":"2026-07-27T03:20:43.345000Z","event_fingerprint":"ae21b23becf1dbe0ab00610702d2e3b095d52f55f2ca96613df1b12db0bf99be","payload":{"connection_id":"c7dc2e4762f849c6b6f9306b6518dcab","event_at":"2026-07-27T03:20:43.345000Z","event_type":"price_change","frame_hash":"3158364db25c6b33bca1c151167280b485247a5603ad671e9039d5940c711b0c","frame_index":0,"kind":"data","monotonic_ns":224426583292166,"payload":{"event_type":"price_change","market":"0x717c0e8ccd4d5c7040185188fbae28be901ca589a11a94b1b38ca36a79eccfeb","price_changes":[{"asset_id":"24254094493625419915756280046002869097156693848522361803041977572204227262166","best_ask":"0.43","best_bid":"0.42","hash":"4115ef3ef3e1b3c8f2d2aade201a8d6ed9b77f95","price":"0.33","side":"BUY","size":"27"},{"asset_id":"41448400836309843603620980831210604935021861034693225347475867885462478926555","best_ask":"0.58","best_bid":"0.57","hash":"a6931b07390af840ca73dd8eab2a8e40a6706f06","price":"0.67","side":"SELL","size":"27"}],"timestamp":"1785122443345"},"payload_hash":"2893b5a6ac939ec7d26d27776a4b7f77b13f6a81556745791549729844ba306e","raw_frame":"{\"market\":\"0x717c0e8ccd4d5c7040185188fbae28be901ca589a11a94b1b38ca36a79eccfeb\", \"price_changes\":[{\"asset_id\":\"24254094493625419915756280046002869097156693848522361803041977572204227262166\", \"price\":\"0.33\", \"size\":\"27\", \"side\":\"BUY\", \"hash\":\"4115ef3ef3e1b3c8f2d2aade201a8d6ed9b77f95\", \"best_bid\":\"0.42\", \"best_ask\":\"0.43\"}, {\"asset_id\":\"41448400836309843603620980831210604935021861034693225347475867885462478926555\", \"price\":\"0.67\", \"size\":\"27\", \"side\":\"SELL\", \"hash\":\"a6931b07390af840ca73dd8eab2a8e40a6706f06\", \"best_bid\":\"0.57\", \"best_ask\":\"0.58\"}], \"timestamp\":\"1785122443345\", \"event_type\":\"price_change\"}","received_at":"2026-07-27T03:20:43.228976Z","schema_version":"clob-market-ws.price_change.v1","sequence":null,"server_hash":null,"server_timestamp":"1785122443345","session_id":"dd162b8dca5f43ff811d304e69a06123","source":"clob_market_ws"},"received_at":"2026-07-27T03:20:43.228976Z","record_id":"f04ecc7cddb4df47c49b221087a5a1a1610d7eb904d760a863c51a9aecac0bee","schema_fingerprint":"4aa3821a28b0b7c2400bc59aba4bcc0a76e971dadd19610d3ad38c768e124dc7","schema_version":"edge-lab-recorder.raw.v1","sequence":null,"source":"clob_market_ws"}
{"event_at":"2026-07-27T03:20:43.346000Z","event_fingerprint":"e52baa2f28e7a345cf4db67941ab8c4459b97fe73e4f765fa87b5df3a55b18e1","payload":{"connection_id":"c7dc2e4762f849c6b6f9306b6518dcab","event_at":"2026-07-27T03:20:43.346000Z","event_type":"price_change","frame_hash":"f690e940ab22c848e23cb9e92a7c09ff0e459dbd1ab4d7812b52a69ea13437a6","frame_index":0,"kind":"data","monotonic_ns":224426585679833,"payload":{"event_type":"price_change","market":"0x717c0e8ccd4d5c7040185188fbae28be901ca589a11a94b1b38ca36a79eccfeb","price_changes":[{"asset_id":"24254094493625419915756280046002869097156693848522361803041977572204227262166","best_ask":"0.43","best_bid":"0.42","hash":"4b385282a7507f148afab1b93bef5d4fb184c61d","price":"0.34","side":"BUY","size":"21"},{"asset_id":"41448400836309843603620980831210604935021861034693225347475867885462478926555","best_ask":"0.58","best_bid":"0.57","hash":"8e62c123cdcd1a84bf407f76c5267d090d6a15f4","price":"0.66","side":"SELL","size":"21"}],"timestamp":"1785122443346"},"payload_hash":"b1c418f97def807457f15026ff3f159cc5ce0634dab4dfecaf1c190b444574f7","raw_frame":"{\"market\":\"0x717c0e8ccd4d5c7040185188fbae28be901ca589a11a94b1b38ca36a79eccfeb\", \"price_changes\":[{\"asset_id\":\"24254094493625419915756280046002869097156693848522361803041977572204227262166\", \"price\":\"0.34\", \"size\":\"21\", \"side\":\"BUY\", \"hash\":\"4b385282a7507f148afab1b93bef5d4fb184c61d\", \"best_bid\":\"0.42\", \"best_ask\":\"0.43\"}, {\"asset_id\":\"41448400836309843603620980831210604935021861034693225347475867885462478926555\", \"price\":\"0.66\", \"size\":\"21\", \"side\":\"SELL\", \"hash\":\"8e62c123cdcd1a84bf407f76c5267d090d6a15f4\", \"best_bid\":\"0.57\", \"best_ask\":\"0.58\"}], \"timestamp\":\"1785122443346\", \"event_type\":\"price_change\"}","received_at":"2026-07-27T03:20:43.231364Z","schema_version":"clob-market-ws.price_change.v1","sequence":null,"server_hash":null,"server_timestamp":"1785122443346","session_id":"dd162b8dca5f43ff811d304e69a06123","source":"clob_market_ws"},"received_at":"2026-07-27T03:20:43.231364Z","record_id":"6504ac803627420b05245d061b9c0bab0f3e498f8844fe7aa916816a89ca953d","schema_fingerprint":"4aa3821a28b0b7c2400bc59aba4bcc0a76e971dadd19610d3ad38c768e124dc7","schema_version":"edge-lab-recorder.raw.v1","sequence":null,"source":"clob_market_ws"}
{"event_at":"2026-07-27T03:20:43.347000Z","event_fingerprint":"000f7cb94c27af88cbd677cffe7b47126afc3b7e785a045b09abdcd51c22d438","payload":{"connection_id":"c7dc2e4762f849c6b6f9306b6518dcab","event_at":"2026-07-27T03:20:43.347000Z","event_type":"price_change","frame_hash":"7c9b1e51e577a846ede7190fb8332535408608230ac3c7ae5e62649294442995","frame_index":0,"kind":"data","monotonic_ns":224426587936416,"payload":{"event_type":"price_change","market":"0x717c0e8ccd4d5c7040185188fbae28be901ca589a11a94b1b38ca36a79eccfeb","price_changes":[{"asset_id":"24254094493625419915756280046002869097156693848522361803041977572204227262166","best_ask":"0.43","best_bid":"0.42","hash":"ac85fb4c349c5868054c8e03cd514e46e62717f0","price":"0.37","side":"BUY","size":"56.39"},{"asset_id":"41448400836309843603620980831210604935021861034693225347475867885462478926555","best_ask":"0.58","best_bid":"0.57","hash":"7e2ad516afc2968936f2cb219a2a2663411889f7","price":"0.63","side":"SELL","size":"56.39"}],"timestamp":"1785122443347"},"payload_hash":"724a2bb242b181d38a25fcb1aecf7584a2f8863b9d4e9cefdb411e9020145d6e","raw_frame":"{\"market\":\"0x717c0e8ccd4d5c7040185188fbae28be901ca589a11a94b1b38ca36a79eccfeb\", \"price_changes\":[{\"asset_id\":\"24254094493625419915756280046002869097156693848522361803041977572204227262166\", \"price\":\"0.37\", \"size\":\"56.39\", \"side\":\"BUY\", \"hash\":\"ac85fb4c349c5868054c8e03cd514e46e62717f0\", \"best_bid\":\"0.42\", \"best_ask\":\"0.43\"}, {\"asset_id\":\"41448400836309843603620980831210604935021861034693225347475867885462478926555\", \"price\":\"0.63\", \"size\":\"56.39\", \"side\":\"SELL\", \"hash\":\"7e2ad516afc2968936f2cb219a2a2663411889f7\", \"best_bid\":\"0.57\", \"best_ask\":\"0.58\"}], \"timestamp\":\"1785122443347\", \"event_type\":\"price_change\"}","received_at":"2026-07-27T03:20:43.233622Z","schema_version":"clob-market-ws.price_change.v1","sequence":null,"server_hash":null,"server_timestamp":"1785122443347","session_id":"dd162b8dca5f43ff811d304e69a06123","source":"clob_market_ws"},"received_at":"2026-07-27T03:20:43.233622Z","record_id":"6ee8f6766b615ef7161f7c6b9af58b61ebdd6fc0c0ed0add8e8aff9a0ad1aef4","schema_fingerprint":"4aa3821a28b0b7c2400bc59aba4bcc0a76e971dadd19610d3ad38c768e124dc7","schema_version":"edge-lab-recorder.raw.v1","sequence":null,"source":"clob_market_ws"}
{"event_at":"2026-07-27T03:20:43.348000Z","event_fingerprint":"74d4ec4c6e57a83851551362edc08f07129f70b85c52bba1d1d14f94391eff0c","payload":{"connection_id":"c7dc2e4762f849c6b6f9306b6518dcab","event_at":"2026-07-27T03:20:43.348000Z","event_type":"price_change","frame_hash":"b3b2053bced91fd671370391e3677c6f0bea2483b42dab4e0342845a7800a738","frame_index":0,"kind":"data","monotonic_ns":224426590879625,"payload":{"event_type":"price_change","market":"0x717c0e8ccd4d5c7040185188fbae28be901ca589a11a94b1b38ca36a79eccfeb","price_changes":[{"asset_id":"24254094493625419915756280046002869097156693848522361803041977572204227262166","best_ask":"0.43","best_bid":"0.42","hash":"9dec41d5c3b08407f5d11d5b17bb614a6a9db3cb","price":"0.35","side":"BUY","size":"121"},{"asset_id":"41448400836309843603620980831210604935021861034693225347475867885462478926555","best_ask":"0.58","best_bid":"0.57","hash":"a657481976d811943ca7716b4b40c34a2c74ad16","price":"0.65","side":"SELL","size":"121"}],"timestamp":"1785122443348"},"payload_hash":"8b1a6759788005eabb8ae3d79ad9210a72c234ec9151df524bee116822c04fca","raw_frame":"{\"market\":\"0x717c0e8ccd4d5c7040185188fbae28be901ca589a11a94b1b38ca36a79eccfeb\", \"price_changes\":[{\"asset_id\":\"24254094493625419915756280046002869097156693848522361803041977572204227262166\", \"price\":\"0.35\", \"size\":\"121\", \"side\":\"BUY\", \"hash\":\"9dec41d5c3b08407f5d11d5b17bb614a6a9db3cb\", \"best_bid\":\"0.42\", \"best_ask\":\"0.43\"}, {\"asset_id\":\"41448400836309843603620980831210604935021861034693225347475867885462478926555\", \"price\":\"0.65\", \"size\":\"121\", \"side\":\"SELL\", \"hash\":\"a657481976d811943ca7716b4b40c34a2c74ad16\", \"best_bid\":\"0.57\", \"best_ask\":\"0.58\"}], \"timestamp\":\"1785122443348\", \"event_type\":\"price_change\"}","received_at":"2026-07-27T03:20:43.236564Z","schema_version":"clob-market-ws.price_change.v1","sequence":null,"server_hash":null,"server_timestamp":"1785122443348","session_id":"dd162b8dca5f43ff811d304e69a06123","source":"clob_market_ws"},"received_at":"2026-07-27T03:20:43.236564Z","record_id":"a768bab48be626613af439982b95980e7836468517424e9c22d2ca8278ad6383","schema_fingerprint":"4aa3821a28b0b7c2400bc59aba4bcc0a76e971dadd19610d3ad38c768e124dc7","schema_version":"edge-lab-recorder.raw.v1","sequence":null,"source":"clob_market_ws"}
{"event_at":"2026-07-27T03:20:43.371000Z","event_fingerprint":"89b5c47ed9c7730cb2d93e244a15697fcf7f8e67990ebdc182ff684c5df5f0bf","payload":{"connection_id":"c7dc2e4762f849c6b6f9306b6518dcab","event_at":"2026-07-27T03:20:43.371000Z","event_type":"price_change","frame_hash":"13db731257b4c28b3094bb54fb0ab0b258dcffeb1a0274626a6d1acecbe115fa","frame_index":0,"kind":"data","monotonic_ns":224426611518500,"payload":{"event_type":"price_change","market":"0x717c0e8ccd4d5c7040185188fbae28be901ca589a11a94b1b38ca36a79eccfeb","price_changes":[{"asset_id":"41448400836309843603620980831210604935021861034693225347475867885462478926555","best_ask":"0.58","best_bid":"0.57","hash":"15dc96329a8e6992465829704c20ce0e2e155e03","price":"0.02","side":"BUY","size":"688.1"},{"asset_id":"24254094493625419915756280046002869097156693848522361803041977572204227262166","best_ask":"0.43","best_bid":"0.42","hash":"49c417503c178661cea592ec4d92b694d7d4c829","price":"0.98","side":"SELL","size":"688.1"}],"timestamp":"1785122443371"},"payload_hash":"a1d091d134b3374356ad4aa4ea128c8a951bdf2dc44796998399b2f10e8bbd49","raw_frame":"{\"market\":\"0x717c0e8ccd4d5c7040185188fbae28be901ca589a11a94b1b38ca36a79eccfeb\", \"price_changes\":[{\"asset_id\":\"41448400836309843603620980831210604935021861034693225347475867885462478926555\", \"price\":\"0.02\", \"size\":\"688.1\", \"side\":\"BUY\", \"hash\":\"15dc96329a8e6992465829704c20ce0e2e155e03\", \"best_bid\":\"0.57\", \"best_ask\":\"0.58\"}, {\"asset_id\":\"24254094493625419915756280046002869097156693848522361803041977572204227262166\", \"price\":\"0.98\", \"size\":\"688.1\", \"side\":\"SELL\", \"hash\":\"49c417503c178661cea592ec4d92b694d7d4c829\", \"best_bid\":\"0.42\", \"best_ask\":\"0.43\"}], \"timestamp\":\"1785122443371\", \"event_type\":\"price_change\"}","received_at":"2026-07-27T03:20:43.257200Z","schema_version":"clob-market-ws.price_change.v1","sequence":null,"server_hash":null,"server_timestamp":"1785122443371","session_id":"dd162b8dca5f43ff811d304e69a06123","source":"clob_market_ws"},"received_at":"2026-07-27T03:20:43.257200Z","record_id":"3b9468c37dc2354fccb71361e2aa74df5ab6e1c790da2acb127e01db8f3ae760","schema_fingerprint":"4aa3821a28b0b7c2400bc59aba4bcc0a76e971dadd19610d3ad38c768e124dc7","schema_version":"edge-lab-recorder.raw.v1","sequence":null,"source":"clob_market_ws"}
{"event_at":"2026-07-27T03:20:43.379000Z","event_fingerprint":"70be95985e2a3e033c411bd52da135929242932da78f0966d6df07408101655a","payload":{"connection_id":"c7dc2e4762f849c6b6f9306b6518dcab","event_at":"2026-07-27T03:20:43.379000Z","event_type":"price_change","frame_hash":"f1a80886e3b15cfafa69f2f55a1550f159e83f7610fe36ff0f50eea71a4303b9","frame_index":0,"kind":"data","monotonic_ns":224426618771583,"payload":{"event_type":"price_change","market":"0x717c0e8ccd4d5c7040185188fbae28be901ca589a11a94b1b38ca36a79eccfeb","price_changes":[{"asset_id":"41448400836309843603620980831210604935021861034693225347475867885462478926555","best_ask":"0.58","best_bid":"0.57","hash":"8be5ffd90d4072bcde45793e79af77e18be8fc74","price":"0.01","side":"BUY","size":"5708.02"},{"asset_id":"24254094493625419915756280046002869097156693848522361803041977572204227262166","best_ask":"0.43","best_bid":"0.42","hash":"ba56cb47f01115dbc875d95d79cdf0151dbe8f8d","price":"0.99","side":"SELL","size":"5708.02"}],"timestamp":"1785122443379"},"payload_hash":"3cd2c81630547395116d2ffa28b7489abce40f15f3f30b7764a525182e67f808","raw_frame":"{\"market\":\"0x717c0e8ccd4d5c7040185188fbae28be901ca589a11a94b1b38ca36a79eccfeb\", \"price_changes\":[{\"asset_id\":\"41448400836309843603620980831210604935021861034693225347475867885462478926555\", \"price\":\"0.01\", \"size\":\"5708.02\", \"side\":\"BUY\", \"hash\":\"8be5ffd90d4072bcde45793e79af77e18be8fc74\", \"best_bid\":\"0.57\", \"best_ask\":\"0.58\"}, {\"asset_id\":\"24254094493625419915756280046002869097156693848522361803041977572204227262166\", \"price\":\"0.99\", \"size\":\"5708.02\", \"side\":\"SELL\", \"hash\":\"ba56cb47f01115dbc875d95d79cdf0151dbe8f8d\", \"best_bid\":\"0.42\", \"best_ask\":\"0.43\"}], \"timestamp\":\"1785122443379\", \"event_type\":\"price_change\"}","received_at":"2026-07-27T03:20:43.264454Z","schema_version":"clob-market-ws.price_change.v1","sequence":null,"server_hash":null,"server_timestamp":"1785122443379","session_id":"dd162b8dca5f43ff811d304e69a06123","source":"clob_market_ws"},"received_at":"2026-07-27T03:20:43.264454Z","record_id":"7a285efd7ef6c504e17bfe8e884bf7b5e76dccd73ef1a77d5d8ef521155142d1","schema_fingerprint":"4aa3821a28b0b7c2400bc59aba4bcc0a76e971dadd19610d3ad38c768e124dc7","schema_version":"edge-lab-recorder.raw.v1","sequence":null,"source":"clob_market_ws"}
{"event_at":"2026-07-27T03:20:43.401000Z","event_fingerprint":"5b3eb7306bd28116a16c3a3b746a603999e8f9f6cdc6290e2f0fdf33e2f56461","payload":{"connection_id":"c7dc2e4762f849c6b6f9306b6518dcab","event_at":"2026-07-27T03:20:43.401000Z","event_type":"price_change","frame_hash":"b318152e1744d61164c93a2a5d3c7c05d5e599a876c2c7fe97490a03f7349482","frame_index":0,"kind":"data","monotonic_ns":224426641009666,"payload":{"event_type":"price_change","market":"0x717c0e8ccd4d5c7040185188fbae28be901ca589a11a94b1b38ca36a79eccfeb","price_changes":[{"asset_id":"41448400836309843603620980831210604935021861034693225347475867885462478926555","best_ask":"0.58","best_bid":"0.57","hash":"c0c979d791a85149b41272383e3127b9f4b771be","price":"0.01","side":"BUY","size":"5703.02"},{"asset_id":"24254094493625419915756280046002869097156693848522361803041977572204227262166","best_ask":"0.43","best_bid":"0.42","hash":"cfb0fe1ea921fd4169d4578a551938405ece4fd7","price":"0.99","side":"SELL","size":"5703.02"}],"timestamp":"1785122443401"},"payload_hash":"430c8c7768e6167a00614bed3f8d0ec9b050dd3f3c121dabd13db3c7b09d6ac5","raw_frame":"{\"market\":\"0x717c0e8ccd4d5c7040185188fbae28be901ca589a11a94b1b38ca36a79eccfeb\", \"price_changes\":[{\"asset_id\":\"41448400836309843603620980831210604935021861034693225347475867885462478926555\", \"price\":\"0.01\", \"size\":\"5703.02\", \"side\":\"BUY\", \"hash\":\"c0c979d791a85149b41272383e3127b9f4b771be\", \"best_bid\":\"0.57\", \"best_ask\":\"0.58\"}, {\"asset_id\":\"24254094493625419915756280046002869097156693848522361803041977572204227262166\", \"price\":\"0.99\", \"size\":\"5703.02\", \"side\":\"SELL\", \"hash\":\"cfb0fe1ea921fd4169d4578a551938405ece4fd7\", \"best_bid\":\"0.42\", \"best_ask\":\"0.43\"}], \"timestamp\":\"1785122443401\", \"event_type\":\"price_change\"}","received_at":"2026-07-27T03:20:43.286692Z","schema_version":"clob-market-ws.price_change.v1","sequence":null,"server_hash":null,"server_timestamp":"1785122443401","session_id":"dd162b8dca5f43ff811d304e69a06123","source":"clob_market_ws"},"received_at":"2026-07-27T03:20:43.286692Z","record_id":"2934ae8798b116e21bba70d6d16aa6700523893d7bc49dc9a750b235273de1d9","schema_fingerprint":"4aa3821a28b0b7c2400bc59aba4bcc0a76e971dadd19610d3ad38c768e124dc7","schema_version":"edge-lab-recorder.raw.v1","sequence":null,"source":"clob_market_ws"}
{"event_at":"2026-07-27T03:20:43.403000Z","event_fingerprint":"6817e6ad260f48e754fbd200bd47215c869fe84a9e0e67277a319d2732c4336d","payload":{"connection_id":"c7dc2e4762f849c6b6f9306b6518dcab","event_at":"2026-07-27T03:20:43.403000Z","event_type":"price_change","frame_hash":"998382461cebdbde4ad61380acad362f2f051a659133673630795e0c6ec259f4","frame_index":0,"kind":"data","monotonic_ns":224426648361708,"payload":{"event_type":"price_change","market":"0x717c0e8ccd4d5c7040185188fbae28be901ca589a11a94b1b38ca36a79eccfeb","price_changes":[{"asset_id":"24254094493625419915756280046002869097156693848522361803041977572204227262166","best_ask":"0.43","best_bid":"0.42","hash":"4c4fda43935971e4e3ee97ff5bfe4a08c777bc61","price":"0.02","side":"BUY","size":"678.1"},{"asset_id":"41448400836309843603620980831210604935021861034693225347475867885462478926555","best_ask":"0.58","best_bid":"0.57","hash":"a67440e9a7184f006f4fd5718be89cb1d5682a25","price":"0.98","side":"SELL","size":"678.1"}],"timestamp":"1785122443403"},"payload_hash":"23878121eb63fed5a03a3455034998c376990e069155a4bf21e65dd7e008165a","raw_frame":"{\"market\":\"0x717c0e8ccd4d5c7040185188fbae28be901ca589a11a94b1b38ca36a79eccfeb\", \"price_changes\":[{\"asset_id\":\"24254094493625419915756280046002869097156693848522361803041977572204227262166\", \"price\":\"0.02\", \"size\":\"678.1\", \"side\":\"BUY\", \"hash\":\"4c4fda43935971e4e3ee97ff5bfe4a08c777bc61\", \"best_bid\":\"0.42\", \"best_ask\":\"0.43\"}, {\"asset_id\":\"41448400836309843603620980831210604935021861034693225347475867885462478926555\", \"price\":\"0.98\", \"size\":\"678.1\", \"side\":\"SELL\", \"hash\":\"a67440e9a7184f006f4fd5718be89cb1d5682a25\", \"best_bid\":\"0.57\", \"best_ask\":\"0.58\"}], \"timestamp\":\"1785122443403\", \"event_type\":\"price_change\"}","received_at":"2026-07-27T03:20:43.294047Z","schema_version":"clob-market-ws.price_change.v1","sequence":null,"server_hash":null,"server_timestamp":"1785122443403","session_id":"dd162b8dca5f43ff811d304e69a06123","source":"clob_market_ws"},"received_at":"2026-07-27T03:20:43.294047Z","record_id":"e9be2284f3d234a1c0213a8e6c93a87a49f678144677c70495a232789654258b","schema_fingerprint":"4aa3821a28b0b7c2400bc59aba4bcc0a76e971dadd19610d3ad38c768e124dc7","schema_version":"edge-lab-recorder.raw.v1","sequence":null,"source":"clob_market_ws"}
{"event_at":"2026-07-27T03:20:43.432000Z","event_fingerprint":"88abe003a8e64193319fb7df1685a7b3d555cacf4e23f97f24338b8d8acfa96b","payload":{"connection_id":"c7dc2e4762f849c6b6f9306b6518dcab","event_at":"2026-07-27T03:20:43.432000Z","event_type":"price_change","frame_hash":"f7032679f025ca737571c64bc31abc114dbc143f2459004cafe74a580c196421","frame_index":0,"kind":"data","monotonic_ns":224426670514291,"payload":{"event_type":"price_change","market":"0x717c0e8ccd4d5c7040185188fbae28be901ca589a11a94b1b38ca36a79eccfeb","price_changes":[{"asset_id":"41448400836309843603620980831210604935021861034693225347475867885462478926555","best_ask":"0.58","best_bid":"0.57","hash":"c6a24a9a194a749f91bd88ef1e7417731d786d25","price":"0.02","side":"BUY","size":"683.1"},{"asset_id":"24254094493625419915756280046002869097156693848522361803041977572204227262166","best_ask":"0.43","best_bid":"0.42","hash":"09822267c2d7c4e1472d46090f9738d5a906c009","price":"0.98","side":"SELL","size":"683.1"}],"timestamp":"1785122443432"},"payload_hash":"a41d74440f2c6c0fc79026bac680145c675a393a51b1da16c37abfb100a66f6e","raw_frame":"{\"market\":\"0x717c0e8ccd4d5c7040185188fbae28be901ca589a11a94b1b38ca36a79eccfeb\", \"price_changes\":[{\"asset_id\":\"41448400836309843603620980831210604935021861034693225347475867885462478926555\", \"price\":\"0.02\", \"size\":\"683.1\", \"side\":\"BUY\", \"hash\":\"c6a24a9a194a749f91bd88ef1e7417731d786d25\", \"best_bid\":\"0.57\", \"best_ask\":\"0.58\"}, {\"asset_id\":\"24254094493625419915756280046002869097156693848522361803041977572204227262166\", \"price\":\"0.98\", \"size\":\"683.1\", \"side\":\"SELL\", \"hash\":\"09822267c2d7c4e1472d46090f9738d5a906c009\", \"best_bid\":\"0.42\", \"best_ask\":\"0.43\"}], \"timestamp\":\"1785122443432\", \"event_type\":\"price_change\"}","received_at":"2026-07-27T03:20:43.316194Z","schema_version":"clob-market-ws.price_change.v1","sequence":null,"server_hash":null,"server_timestamp":"1785122443432","session_id":"dd162b8dca5f43ff811d304e69a06123","source":"clob_market_ws"},"received_at":"2026-07-27T03:20:43.316194Z","record_id":"8862788937a78bb950afc9e4e116f01bf1c437f64be4b93d8e557b1b941216ba","schema_fingerprint":"4aa3821a28b0b7c2400bc59aba4bcc0a76e971dadd19610d3ad38c768e124dc7","schema_version":"edge-lab-recorder.raw.v1","sequence":null,"source":"clob_market_ws"}
{"event_at":"2026-07-27T03:20:43.459000Z","event_fingerprint":"e4f3eb8144ca0953664f36631ee8bbfcd590d2fd8e62aaf2166b8811efac70f7","payload":{"connection_id":"c7dc2e4762f849c6b6f9306b6518dcab","event_at":"2026-07-27T03:20:43.459000Z","event_type":"price_change","frame_hash":"7e0db97991fd7ac885e7c34df31a19b47c2d80b0c7e73c4faf8cd00377062f86","frame_index":0,"kind":"data","monotonic_ns":224426694254166,"payload":{"event_type":"price_change","market":"0x717c0e8ccd4d5c7040185188fbae28be901ca589a11a94b1b38ca36a79eccfeb","price_changes":[{"asset_id":"41448400836309843603620980831210604935021861034693225347475867885462478926555","best_ask":"0.58","best_bid":"0.57","hash":"91262bcb9df24ff17eaf58f8ad71c8e0e633271a","price":"0.53","side":"BUY","size":"9"},{"asset_id":"24254094493625419915756280046002869097156693848522361803041977572204227262166","best_ask":"0.43","best_bid":"0.42","hash":"28e916ca67d210a8fb2ed35e1ffa03f52077ead5","price":"0.47","side":"SELL","size":"9"}],"timestamp":"1785122443459"},"payload_hash":"5176635d97ae09b8eb540e055651785cf75bd99f058fc7bae4ee57f3f075d7e8","raw_frame":"{\"market\":\"0x717c0e8ccd4d5c7040185188fbae28be901ca589a11a94b1b38ca36a79eccfeb\", \"price_changes\":[{\"asset_id\":\"41448400836309843603620980831210604935021861034693225347475867885462478926555\", \"price\":\"0.53\", \"size\":\"9\", \"side\":\"BUY\", \"hash\":\"91262bcb9df24ff17eaf58f8ad71c8e0e633271a\", \"best_bid\":\"0.57\", \"best_ask\":\"0.58\"}, {\"asset_id\":\"24254094493625419915756280046002869097156693848522361803041977572204227262166\", \"price\":\"0.47\", \"size\":\"9\", \"side\":\"SELL\", \"hash\":\"28e916ca67d210a8fb2ed35e1ffa03f52077ead5\", \"best_bid\":\"0.42\", \"best_ask\":\"0.43\"}], \"timestamp\":\"1785122443459\", \"event_type\":\"price_change\"}","received_at":"2026-07-27T03:20:43.339938Z","schema_version":"clob-market-ws.price_change.v1","sequence":null,"server_hash":null,"server_timestamp":"1785122443459","session_id":"dd162b8dca5f43ff811d304e69a06123","source":"clob_market_ws"},"received_at":"2026-07-27T03:20:43.339938Z","record_id":"7bb73de5c067732eb87a369f074550cc835e6e483f154a96c1bbfc1c5afda35b","schema_fingerprint":"4aa3821a28b0b7c2400bc59aba4bcc0a76e971dadd19610d3ad38c768e124dc7","schema_version":"edge-lab-recorder.raw.v1","sequence":null,"source":"clob_market_ws"}
{"event_at":"2026-07-27T03:20:43.463000Z","event_fingerprint":"e38d95b6840bdc0e3bcc38ec6c0ead3b3228bdfc9b34c52ee30e532e6570178a","payload":{"connection_id":"c7dc2e4762f849c6b6f9306b6518dcab","event_at":"2026-07-27T03:20:43.463000Z","event_type":"price_change","frame_hash":"916966b610a985e944cf8f1fbf03476cb34edd61a8941964e0d557459302639c","frame_index":0,"kind":"data","monotonic_ns":224426699110583,"payload":{"event_type":"price_change","market":"0x717c0e8ccd4d5c7040185188fbae28be901ca589a11a94b1b38ca36a79eccfeb","price_changes":[{"asset_id":"41448400836309843603620980831210604935021861034693225347475867885462478926555","best_ask":"0.58","best_bid":"0.57","hash":"1e1454783dc22a82dd216f7599dbc858da98fd32","price":"0.52","side":"BUY","size":"22"},{"asset_id":"24254094493625419915756280046002869097156693848522361803041977572204227262166","best_ask":"0.43","best_bid":"0.42","hash":"766e7f9beb51c23d8b3c5b2564a3b38d968e0aa6","price":"0.48","side":"SELL","size":"22"}],"timestamp":"1785122443463"},"payload_hash":"8d8c1f955f0795bdaf21a4be43353233379e41475d8c083142164c7c7dd1efed","raw_frame":"{\"market\":\"0x717c0e8ccd4d5c7040185188fbae28be901ca589a11a94b1b38ca36a79eccfeb\", \"price_changes\":[{\"asset_id\":\"41448400836309843603620980831210604935021861034693225347475867885462478926555\", \"price\":\"0.52\", \"size\":\"22\", \"side\":\"BUY\", \"hash\":\"1e1454783dc22a82dd216f7599dbc858da98fd32\", \"best_bid\":\"0.57\", \"best_ask\":\"0.58\"}, {\"asset_id\":\"24254094493625419915756280046002869097156693848522361803041977572204227262166\", \"price\":\"0.48\", \"size\":\"22\", \"side\":\"SELL\", \"hash\":\"766e7f9beb51c23d8b3c5b2564a3b38d968e0aa6\", \"best_bid\":\"0.42\", \"best_ask\":\"0.43\"}], \"timestamp\":\"1785122443463\", \"event_type\":\"price_change\"}","received_at":"2026-07-27T03:20:43.344790Z","schema_version":"clob-market-ws.price_change.v1","sequence":null,"server_hash":null,"server_timestamp":"1785122443463","session_id":"dd162b8dca5f43ff811d304e69a06123","source":"clob_market_ws"},"received_at":"2026-07-27T03:20:43.344790Z","record_id":"60e40029ddbd6f92abd206c19870558e45b0692376b913281cdf07d81321a349","schema_fingerprint":"4aa3821a28b0b7c2400bc59aba4bcc0a76e971dadd19610d3ad38c768e124dc7","schema_version":"edge-lab-recorder.raw.v1","sequence":null,"source":"clob_market_ws"}
{"event_at":"2026-07-27T03:20:43.519000Z","event_fingerprint":"ad48a4df9972931a0240b8d5b05420066c49e8831fb0599da375dd2b41a66372","payload":{"connection_id":"c7dc2e4762f849c6b6f9306b6518dcab","event_at":"2026-07-27T03:20:43.519000Z","event_type":"price_change","frame_hash":"09216e66bcfe241675b7c873df8df4452a5ccfc5548b7bf2f208094ee69ae3f3","frame_index":0,"kind":"data","monotonic_ns":224426758191041,"payload":{"event_type":"price_change","market":"0x717c0e8ccd4d5c7040185188fbae28be901ca589a11a94b1b38ca36a79eccfeb","price_changes":[{"asset_id":"41448400836309843603620980831210604935021861034693225347475867885462478926555","best_ask":"0.58","best_bid":"0.57","hash":"477c59ccd9afb47f634b8a94306c89e5b5b82d0c","price":"0.03","side":"BUY","size":"618.1"},{"asset_id":"24254094493625419915756280046002869097156693848522361803041977572204227262166","best_ask":"0.43","best_bid":"0.42","hash":"92586077b2c80af24d08f72ef10d36a2b0079fad","price":"0.97","side":"SELL","size":"618.1"}],"timestamp":"1785122443519"},"payload_hash":"d71b2c0be6780c4daef09c09eea528cd919d42c0df6bcee2f8535ebb5a03c799","raw_frame":"{\"market\":\"0x717c0e8ccd4d5c7040185188fbae28be901ca589a11a94b1b38ca36a79eccfeb\", \"price_changes\":[{\"asset_id\":\"41448400836309843603620980831210604935021861034693225347475867885462478926555\", \"price\":\"0.03\", \"size\":\"618.1\", \"side\":\"BUY\", \"hash\":\"477c59ccd9afb47f634b8a94306c89e5b5b82d0c\", \"best_bid\":\"0.57\", \"best_ask\":\"0.58\"}, {\"asset_id\":\"24254094493625419915756280046002869097156693848522361803041977572204227262166\", \"price\":\"0.97\", \"size\":\"618.1\", \"side\":\"SELL\", \"hash\":\"92586077b2c80af24d08f72ef10d36a2b0079fad\", \"best_bid\":\"0.42\", \"best_ask\":\"0.43\"}], \"timestamp\":\"1785122443519\", \"event_type\":\"price_change\"}","received_at":"2026-07-27T03:20:43.403869Z","schema_version":"clob-market-ws.price_change.v1","sequence":null,"server_hash":null,"server_timestamp":"1785122443519","session_id":"dd162b8dca5f43ff811d304e69a06123","source":"clob_market_ws"},"received_at":"2026-07-27T03:20:43.403869Z","record_id":"064a6fc542596cbe0e4cfeb33b57e3363c221d980424e7b96726f99bcc722fa4","schema_fingerprint":"4aa3821a28b0b7c2400bc59aba4bcc0a76e971dadd19610d3ad38c768e124dc7","schema_version":"edge-lab-recorder.raw.v1","sequence":null,"source":"clob_market_ws"}
{"event_at":"2026-07-27T03:20:43.570000Z","event_fingerprint":"4279bdeea6b3a35fa9cfd8b9cb463bbb13e409b0f5620554888e4358ebbb069a","payload":{"connection_id":"c7dc2e4762f849c6b6f9306b6518dcab","event_at":"2026-07-27T03:20:43.570000Z","event_type":"price_change","frame_hash":"900a096134026103c4c4a867dc9a05d2274c99a94e4f592a51ad7bacdc6a34da","frame_index":0,"kind":"data","monotonic_ns":224426808767125,"payload":{"event_type":"price_change","market":"0x717c0e8ccd4d5c7040185188fbae28be901ca589a11a94b1b38ca36a79eccfeb","price_changes":[{"asset_id":"41448400836309843603620980831210604935021861034693225347475867885462478926555","best_ask":"0.58","best_bid":"0.57","hash":"a4545e3182820cdf0541a311eed1183b10559aa8","price":"0.53","side":"BUY","size":"14"},{"asset_id":"24254094493625419915756280046002869097156693848522361803041977572204227262166","best_ask":"0.43","best_bid":"0.42","hash":"c11c3c55eb9acb37aee32df4988dd44cccf3591d","price":"0.47","side":"SELL","size":"14"}],"timestamp":"1785122443570"},"payload_hash":"68df3b4c888bd55dbb8f762912d257d15ef061d1d66459cc8dc7f1cc6c32288c","raw_frame":"{\"market\":\"0x717c0e8ccd4d5c7040185188fbae28be901ca589a11a94b1b38ca36a79eccfeb\", \"price_changes\":[{\"asset_id\":\"41448400836309843603620980831210604935021861034693225347475867885462478926555\", \"price\":\"0.53\", \"size\":\"14\", \"side\":\"BUY\", \"hash\":\"a4545e3182820cdf0541a311eed1183b10559aa8\", \"best_bid\":\"0.57\", \"best_ask\":\"0.58\"}, {\"asset_id\":\"24254094493625419915756280046002869097156693848522361803041977572204227262166\", \"price\":\"0.47\", \"size\":\"14\", \"side\":\"SELL\", \"hash\":\"c11c3c55eb9acb37aee32df4988dd44cccf3591d\", \"best_bid\":\"0.42\", \"best_ask\":\"0.43\"}], \"timestamp\":\"1785122443570\", \"event_type\":\"price_change\"}","received_at":"2026-07-27T03:20:43.454442Z","schema_version":"clob-market-ws.price_change.v1","sequence":null,"server_hash":null,"server_timestamp":"1785122443570","session_id":"dd162b8dca5f43ff811d304e69a06123","source":"clob_market_ws"},"received_at":"2026-07-27T03:20:43.454442Z","record_id":"d4a4a1e32b03f9449e55e271c5ddaa996c44cd4c8f6b42e73a38a79be5ad40cc","schema_fingerprint":"4aa3821a28b0b7c2400bc59aba4bcc0a76e971dadd19610d3ad38c768e124dc7","schema_version":"edge-lab-recorder.raw.v1","sequence":null,"source":"clob_market_ws"}
{"event_at":"2026-07-27T03:20:43.570000Z","event_fingerprint":"6e9e23628c319ed3891087a515b9b7738cb9ec3d0b3bdbb8f901928a26d07cc4","payload":{"connection_id":"c7dc2e4762f849c6b6f9306b6518dcab","event_at":"2026-07-27T03:20:43.570000Z","event_type":"price_change","frame_hash":"379a49a50f8aa9f376f0a0fd923de486272972042d2bebf4503ac99668494a88","frame_index":0,"kind":"data","monotonic_ns":224426813588708,"payload":{"event_type":"price_change","market":"0x717c0e8ccd4d5c7040185188fbae28be901ca589a11a94b1b38ca36a79eccfeb","price_changes":[{"asset_id":"41448400836309843603620980831210604935021861034693225347475867885462478926555","best_ask":"0.58","best_bid":"0.57","hash":"67b741ef155c79028952c93c1853dcdadd6a38ab","price":"0.52","side":"BUY","size":"15"},{"asset_id":"24254094493625419915756280046002869097156693848522361803041977572204227262166","best_ask":"0.43","best_bid":"0.42","hash":"7828d03f6cf6cee1517fc15253df8a629ecc098e","price":"0.48","side":"SELL","size":"15"}],"timestamp":"1785122443570"},"payload_hash":"5bd1c6ead64b661e9a4216faadf1ac41f699f9c42bcd499db45581ca7f0ca6b0","raw_frame":"{\"market\":\"0x717c0e8ccd4d5c7040185188fbae28be901ca589a11a94b1b38ca36a79eccfeb\", \"price_changes\":[{\"asset_id\":\"41448400836309843603620980831210604935021861034693225347475867885462478926555\", \"price\":\"0.52\", \"size\":\"15\", \"side\":\"BUY\", \"hash\":\"67b741ef155c79028952c93c1853dcdadd6a38ab\", \"best_bid\":\"0.57\", \"best_ask\":\"0.58\"}, {\"asset_id\":\"24254094493625419915756280046002869097156693848522361803041977572204227262166\", \"price\":\"0.48\", \"size\":\"15\", \"side\":\"SELL\", \"hash\":\"7828d03f6cf6cee1517fc15253df8a629ecc098e\", \"best_bid\":\"0.42\", \"best_ask\":\"0.43\"}], \"timestamp\":\"1785122443570\", \"event_type\":\"price_change\"}","received_at":"2026-07-27T03:20:43.459265Z","schema_version":"clob-market-ws.price_change.v1","sequence":null,"server_hash":null,"server_timestamp":"1785122443570","session_id":"dd162b8dca5f43ff811d304e69a06123","source":"clob_market_ws"},"received_at":"2026-07-27T03:20:43.459265Z","record_id":"4d273ab1c313d2a733b46e3fe609eed0099cdcbf5660d4d18f7a98e3247f5b9a","schema_fingerprint":"4aa3821a28b0b7c2400bc59aba4bcc0a76e971dadd19610d3ad38c768e124dc7","schema_version":"edge-lab-recorder.raw.v1","sequence":null,"source":"clob_market_ws"}
{"event_at":"2026-07-27T03:20:43.577000Z","event_fingerprint":"904556acb90bab8b2bd55517e25e893174cd100e11710f18d202e424ac3b32b6","payload":{"connection_id":"c7dc2e4762f849c6b6f9306b6518dcab","event_at":"2026-07-27T03:20:43.577000Z","event_type":"price_change","frame_hash":"b221d502d3a9158537a31e615896b56aea5f72b2b62641ccc98e7777f1f74805","frame_index":0,"kind":"data","monotonic_ns":224426821063000,"payload":{"event_type":"price_change","market":"0x717c0e8ccd4d5c7040185188fbae28be901ca589a11a94b1b38ca36a79eccfeb","price_changes":[{"asset_id":"24254094493625419915756280046002869097156693848522361803041977572204227262166","best_ask":"0.43","best_bid":"0.42","hash":"8ccb0b4c09f2f73e669d3bf69c3dd0c7be40d98c","price":"0.39","side":"BUY","size":"84.4"},{"asset_id":"41448400836309843603620980831210604935021861034693225347475867885462478926555","best_ask":"0.58","best_bid":"0.57","hash":"ffc308bb967658080cce9fe103fa61d2cda8c395","price":"0.61","side":"SELL","size":"84.4"}],"timestamp":"1785122443577"},"payload_hash":"f8fcf56d03e015a629a0d9a28863bf6629976dd45e621bd58949aa9d25c73bf7","raw_frame":"{\"market\":\"0x717c0e8ccd4d5c7040185188fbae28be901ca589a11a94b1b38ca36a79eccfeb\", \"price_changes\":[{\"asset_id\":\"24254094493625419915756280046002869097156693848522361803041977572204227262166\", \"price\":\"0.39\", \"size\":\"84.4\", \"side\":\"BUY\", \"hash\":\"8ccb0b4c09f2f73e669d3bf69c3dd0c7be40d98c\", \"best_bid\":\"0.42\", \"best_ask\":\"0.43\"}, {\"asset_id\":\"41448400836309843603620980831210604935021861034693225347475867885462478926555\", \"price\":\"0.61\", \"size\":\"84.4\", \"side\":\"SELL\", \"hash\":\"ffc308bb967658080cce9fe103fa61d2cda8c395\", \"best_bid\":\"0.57\", \"best_ask\":\"0.58\"}], \"timestamp\":\"1785122443577\", \"event_type\":\"price_change\"}","received_at":"2026-07-27T03:20:43.466742Z","schema_version":"clob-market-ws.price_change.v1","sequence":null,"server_hash":null,"server_timestamp":"1785122443577","session_id":"dd162b8dca5f43ff811d304e69a06123","source":"clob_market_ws"},"received_at":"2026-07-27T03:20:43.466742Z","record_id":"38b09f06e185b186319e635fdddcffbb0f722c528c09c4d414a78db34619b4aa","schema_fingerprint":"4aa3821a28b0b7c2400bc59aba4bcc0a76e971dadd19610d3ad38c768e124dc7","schema_version":"edge-lab-recorder.raw.v1","sequence":null,"source":"clob_market_ws"}
{"event_at":"2026-07-27T03:20:43.579000Z","event_fingerprint":"3a590e488e1c718344d84d26f3c307e7d243511e53b52faa12687fb09c5aa700","payload":{"connection_id":"c7dc2e4762f849c6b6f9306b6518dcab","event_at":"2026-07-27T03:20:43.579000Z","event_type":"price_change","frame_hash":"082149548b113f677fdef0e922102d9bc56220bceec99ff8c8036fb15af48261","frame_index":0,"kind":"data","monotonic_ns":224426826015166,"payload":{"event_type":"price_change","market":"0x717c0e8ccd4d5c7040185188fbae28be901ca589a11a94b1b38ca36a79eccfeb","price_changes":[{"asset_id":"24254094493625419915756280046002869097156693848522361803041977572204227262166","best_ask":"0.43","best_bid":"0.42","hash":"60849beca9c60ecdd8fa8fbe28f993be5e4c3fef","price":"0.35","side":"BUY","size":"134.02"},{"asset_id":"41448400836309843603620980831210604935021861034693225347475867885462478926555","best_ask":"0.58","best_bid":"0.57","hash":"ed77248b945925ba2a9fdcf1e8f2706ca487e9ba","price":"0.65","side":"SELL","size":"134.02"}],"timestamp":"1785122443579"},"payload_hash":"f35bacd9cc2ce905e7c883ffea1001708b9fd77d20b66ae83d19d4d85a366760","raw_frame":"{\"market\":\"0x717c0e8ccd4d5c7040185188fbae28be901ca589a11a94b1b38ca36a79eccfeb\", \"price_changes\":[{\"asset_id\":\"24254094493625419915756280046002869097156693848522361803041977572204227262166\", \"price\":\"0.35\", \"size\":\"134.02\", \"side\":\"BUY\", \"hash\":\"60849beca9c60ecdd8fa8fbe28f993be5e4c3fef\", \"best_bid\":\"0.42\", \"best_ask\":\"0.43\"}, {\"asset_id\":\"41448400836309843603620980831210604935021861034693225347475867885462478926555\", \"price\":\"0.65\", \"size\":\"134.02\", \"side\":\"SELL\", \"hash\":\"ed77248b945925ba2a9fdcf1e8f2706ca487e9ba\", \"best_bid\":\"0.57\", \"best_ask\":\"0.58\"}], \"timestamp\":\"1785122443579\", \"event_type\":\"price_change\"}","received_at":"2026-07-27T03:20:43.471698Z","schema_version":"clob-market-ws.price_change.v1","sequence":null,"server_hash":null,"server_timestamp":"1785122443579","session_id":"dd162b8dca5f43ff811d304e69a06123","source":"clob_market_ws"},"received_at":"2026-07-27T03:20:43.471698Z","record_id":"b6ec6d93e931cf9138f2ef665d9265bacd5f55fcb22f6d7dfd70fe436c432743","schema_fingerprint":"4aa3821a28b0b7c2400bc59aba4bcc0a76e971dadd19610d3ad38c768e124dc7","schema_version":"edge-lab-recorder.raw.v1","sequence":null,"source":"clob_market_ws"}
{"event_at":"2026-07-27T03:20:43.596000Z","event_fingerprint":"12a2cf0b66e4b1eff42683c715172e9ff75dad9f282c6c8457b5c3dab40ef15a","payload":{"connection_id":"c7dc2e4762f849c6b6f9306b6518dcab","event_at":"2026-07-27T03:20:43.596000Z","event_type":"price_change","frame_hash":"5198e8c23d704f5768125a983f8540e61d2c55849b67ba1ae2771b859ac9d8d6","frame_index":0,"kind":"data","monotonic_ns":224426832807041,"payload":{"event_type":"price_change","market":"0x717c0e8ccd4d5c7040185188fbae28be901ca589a11a94b1b38ca36a79eccfeb","price_changes":[{"asset_id":"41448400836309843603620980831210604935021861034693225347475867885462478926555","best_ask":"0.58","best_bid":"0.57","hash":"6895ebf2722332b6bdfb19613e1ec8c6616683f9","price":"0.03","side":"BUY","size":"613.1"},{"asset_id":"24254094493625419915756280046002869097156693848522361803041977572204227262166","best_ask":"0.43","best_bid":"0.42","hash":"5bbe297ba1864ee84c1df8f20bafaf1994aea4c8","price":"0.97","side":"SELL","size":"613.1"}],"timestamp":"1785122443596"},"payload_hash":"ecd59287426b5b40b022f451212b21285266c23dac35eb0247e21f8b818c247b","raw_frame":"{\"market\":\"0x717c0e8ccd4d5c7040185188fbae28be901ca589a11a94b1b38ca36a79eccfeb\", \"price_changes\":[{\"asset_id\":\"41448400836309843603620980831210604935021861034693225347475867885462478926555\", \"price\":\"0.03\", \"size\":\"613.1\", \"side\":\"BUY\", \"hash\":\"6895ebf2722332b6bdfb19613e1ec8c6616683f9\", \"best_bid\":\"0.57\", \"best_ask\":\"0.58\"}, {\"asset_id\":\"24254094493625419915756280046002869097156693848522361803041977572204227262166\", \"price\":\"0.97\", \"size\":\"613.1\", \"side\":\"SELL\", \"hash\":\"5bbe297ba1864ee84c1df8f20bafaf1994aea4c8\", \"best_bid\":\"0.42\", \"best_ask\":\"0.43\"}], \"timestamp\":\"1785122443596\", \"event_type\":\"price_change\"}","received_at":"2026-07-27T03:20:43.478483Z","schema_version":"clob-market-ws.price_change.v1","sequence":null,"server_hash":null,"server_timestamp":"1785122443596","session_id":"dd162b8dca5f43ff811d304e69a06123","source":"clob_market_ws"},"received_at":"2026-07-27T03:20:43.478483Z","record_id":"aeb7a3c67720873347c967465703b3e77d5d1fba04135b58ef5ba3c559613e1c","schema_fingerprint":"4aa3821a28b0b7c2400bc59aba4bcc0a76e971dadd19610d3ad38c768e124dc7","schema_version":"edge-lab-recorder.raw.v1","sequence":null,"source":"clob_market_ws"}
{"event_at":"2026-07-27T03:20:43.652000Z","event_fingerprint":"5b3e5e22b2c0140f0294bd8c732c60789efd695878bd53c6eb39ed6d85d8107a","payload":{"connection_id":"c7dc2e4762f849c6b6f9306b6518dcab","event_at":"2026-07-27T03:20:43.652000Z","event_type":"price_change","frame_hash":"09f8baa62bcc1d70b7d524b0ddc8debb82a9c67efd377e4d980a987b3d3b2c46","frame_index":0,"kind":"data","monotonic_ns":224426888556125,"payload":{"event_type":"price_change","market":"0x717c0e8ccd4d5c7040185188fbae28be901ca589a11a94b1b38ca36a79eccfeb","price_changes":[{"asset_id":"41448400836309843603620980831210604935021861034693225347475867885462478926555","best_ask":"0.58","best_bid":"0.57","hash":"76c3bdef17ccf2aba84dc786ef963ebca7b18c6c","price":"0.01","side":"BUY","size":"5708.02"},{"asset_id":"24254094493625419915756280046002869097156693848522361803041977572204227262166","best_ask":"0.43","best_bid":"0.42","hash":"0ac58f4f6659753aa1ba198bad43145154d5ca9c","price":"0.99","side":"SELL","size":"5708.02"}],"timestamp":"1785122443652"},"payload_hash":"9553d7d2fed4806c30bce1a880bc33516aed884650a5d4f285d576b9ce3e25c5","raw_frame":"{\"market\":\"0x717c0e8ccd4d5c7040185188fbae28be901ca589a11a94b1b38ca36a79eccfeb\", \"price_changes\":[{\"asset_id\":\"41448400836309843603620980831210604935021861034693225347475867885462478926555\", \"price\":\"0.01\", \"size\":\"5708.02\", \"side\":\"BUY\", \"hash\":\"76c3bdef17ccf2aba84dc786ef963ebca7b18c6c\", \"best_bid\":\"0.57\", \"best_ask\":\"0.58\"}, {\"asset_id\":\"24254094493625419915756280046002869097156693848522361803041977572204227262166\", \"price\":\"0.99\", \"size\":\"5708.02\", \"side\":\"SELL\", \"hash\":\"0ac58f4f6659753aa1ba198bad43145154d5ca9c\", \"best_bid\":\"0.42\", \"best_ask\":\"0.43\"}], \"timestamp\":\"1785122443652\", \"event_type\":\"price_change\"}","received_at":"2026-07-27T03:20:43.534233Z","schema_version":"clob-market-ws.price_change.v1","sequence":null,"server_hash":null,"server_timestamp":"1785122443652","session_id":"dd162b8dca5f43ff811d304e69a06123","source":"clob_market_ws"},"received_at":"2026-07-27T03:20:43.534233Z","record_id":"852baadd8a3d68971c0448ee7634a9103594cdd5d97800fe129fa723ce58d42f","schema_fingerprint":"4aa3821a28b0b7c2400bc59aba4bcc0a76e971dadd19610d3ad38c768e124dc7","schema_version":"edge-lab-recorder.raw.v1","sequence":null,"source":"clob_market_ws"}
{"event_at":"2026-07-27T03:20:43.672000Z","event_fingerprint":"cdc6f400862592a90fff356f5db2de0f43e6ebb0eb38a9628a92ed519507d147","payload":{"connection_id":"c7dc2e4762f849c6b6f9306b6518dcab","event_at":"2026-07-27T03:20:43.672000Z","event_type":"price_change","frame_hash":"52e0531d8d5d12fcbb38c56b743142eaeeab98d508b56edd210b749190cc38a2","frame_index":0,"kind":"data","monotonic_ns":224426909007041,"payload":{"event_type":"price_change","market":"0x717c0e8ccd4d5c7040185188fbae28be901ca589a11a94b1b38ca36a79eccfeb","price_changes":[{"asset_id":"41448400836309843603620980831210604935021861034693225347475867885462478926555","best_ask":"0.58","best_bid":"0.57","hash":"b2ea7aa4155ebd9fc372ad96d462b2cb488ecbff","price":"0.01","side":"BUY","size":"5703.02"},{"asset_id":"24254094493625419915756280046002869097156693848522361803041977572204227262166","best_ask":"0.43","best_bid":"0.42","hash":"c55e294d180ad65b9cdcf53fbcf5272fa3d59ca1","price":"0.99","side":"SELL","size":"5703.02"}],"timestamp":"1785122443672"},"payload_hash":"5c4c7894dd7c51d05f3d1b9c2f05cc5f42b291d2c6e7138ea694efe6c5b6573c","raw_frame":"{\"market\":\"0x717c0e8ccd4d5c7040185188fbae28be901ca589a11a94b1b38ca36a79eccfeb\", \"price_changes\":[{\"asset_id\":\"41448400836309843603620980831210604935021861034693225347475867885462478926555\", \"price\":\"0.01\", \"size\":\"5703.02\", \"side\":\"BUY\", \"hash\":\"b2ea7aa4155ebd9fc372ad96d462b2cb488ecbff\", \"best_bid\":\"0.57\", \"best_ask\":\"0.58\"}, {\"asset_id\":\"24254094493625419915756280046002869097156693848522361803041977572204227262166\", \"price\":\"0.99\", \"size\":\"5703.02\", \"side\":\"SELL\", \"hash\":\"c55e294d180ad65b9cdcf53fbcf5272fa3d59ca1\", \"best_bid\":\"0.42\", \"best_ask\":\"0.43\"}], \"timestamp\":\"1785122443672\", \"event_type\":\"price_change\"}","received_at":"2026-07-27T03:20:43.554682Z","schema_version":"clob-market-ws.price_change.v1","sequence":null,"server_hash":null,"server_timestamp":"1785122443672","session_id":"dd162b8dca5f43ff811d304e69a06123","source":"clob_market_ws"},"received_at":"2026-07-27T03:20:43.554682Z","record_id":"42b23205ee623f909ce632827d208c3a62ee60315aca9fb13979df0199fbd6fc","schema_fingerprint":"4aa3821a28b0b7c2400bc59aba4bcc0a76e971dadd19610d3ad38c768e124dc7","schema_version":"edge-lab-recorder.raw.v1","sequence":null,"source":"clob_market_ws"}
{"event_at":"2026-07-27T03:20:43.677000Z","event_fingerprint":"14c0f279a610fefdc39b9dfab1027d27853b87774e9d8f50ec09eee2e470caf3","payload":{"connection_id":"c7dc2e4762f849c6b6f9306b6518dcab","event_at":"2026-07-27T03:20:43.677000Z","event_type":"price_change","frame_hash":"d177d233ca4e25dfd69c8c50bd0d8a86e4b37a80ce95191728a0732c78736066","frame_index":0,"kind":"data","monotonic_ns":224426913277208,"payload":{"event_type":"price_change","market":"0x717c0e8ccd4d5c7040185188fbae28be901ca589a11a94b1b38ca36a79eccfeb","price_changes":[{"asset_id":"41448400836309843603620980831210604935021861034693225347475867885462478926555","best_ask":"0.58","best_bid":"0.57","hash":"bc8980c6fba84c25d116f95dff0604430a9ec27d","price":"0.03","side":"BUY","size":"618.1"},{"asset_id":"24254094493625419915756280046002869097156693848522361803041977572204227262166","best_ask":"0.43","best_bid":"0.42","hash":"9e328f212b7d389d703b2cd058506afcda34f0c0","price":"0.97","side":"SELL","size":"618.1"}],"timestamp":"1785122443677"},"payload_hash":"58b8b758bb9826ce8c57b7d3374c69d82404ec9e4eee9a724c511d50e4a899c8","raw_frame":"{\"market\":\"0x717c0e8ccd4d5c7040185188fbae28be901ca589a11a94b1b38ca36a79eccfeb\", \"price_changes\":[{\"asset_id\":\"41448400836309843603620980831210604935021861034693225347475867885462478926555\", \"price\":\"0.03\", \"size\":\"618.1\", \"side\":\"BUY\", \"hash\":\"bc8980c6fba84c25d116f95dff0604430a9ec27d\", \"best_bid\":\"0.57\", \"best_ask\":\"0.58\"}, {\"asset_id\":\"24254094493625419915756280046002869097156693848522361803041977572204227262166\", \"price\":\"0.97\", \"size\":\"618.1\", \"side\":\"SELL\", \"hash\":\"9e328f212b7d389d703b2cd058506afcda34f0c0\", \"best_bid\":\"0.42\", \"best_ask\":\"0.43\"}], \"timestamp\":\"1785122443677\", \"event_type\":\"price_change\"}","received_at":"2026-07-27T03:20:43.558952Z","schema_version":"clob-market-ws.price_change.v1","sequence":null,"server_hash":null,"server_timestamp":"1785122443677","session_id":"dd162b8dca5f43ff811d304e69a06123","source":"clob_market_ws"},"received_at":"2026-07-27T03:20:43.558952Z","record_id":"b00f13ad7f8b203c47fd19270f4b6e3c0eb43ec629ea5441de4bae29b62d4e2c","schema_fingerprint":"4aa3821a28b0b7c2400bc59aba4bcc0a76e971dadd19610d3ad38c768e124dc7","schema_version":"edge-lab-recorder.raw.v1","sequence":null,"source":"clob_market_ws"}
{"event_at":"2026-07-27T03:20:43.679000Z","event_fingerprint":"92e357afa96cc06f3638be7f4838036fdedc4a648cdcaadf5e8db2e431094c1e","payload":{"connection_id":"c7dc2e4762f849c6b6f9306b6518dcab","event_at":"2026-07-27T03:20:43.679000Z","event_type":"price_change","frame_hash":"7162d2c73f1201108b9484406e5fc42de3bb769c0b3ffa35b75c49e35f9ad8b6","frame_index":0,"kind":"data","monotonic_ns":224426918845833,"payload":{"event_type":"price_change","market":"0x717c0e8ccd4d5c7040185188fbae28be901ca589a11a94b1b38ca36a79eccfeb","price_changes":[{"asset_id":"41448400836309843603620980831210604935021861034693225347475867885462478926555","best_ask":"0.58","best_bid":"0.57","hash":"3df5b4827a6c198682f1e90dc9046ce3dfc4a7a4","price":"0.53","side":"BUY","size":"9"},{"asset_id":"24254094493625419915756280046002869097156693848522361803041977572204227262166","best_ask":"0.43","best_bid":"0.42","hash":"2d5b382d27169b0c772de203c100756e8fe93b81","price":"0.47","side":"SELL","size":"9"}],"timestamp":"1785122443679"},"payload_hash":"94b3c06c553ef5190f6c31ab4b10cb3d6af4504de17e2520efdde00a8e1455bb","raw_frame":"{\"market\":\"0x717c0e8ccd4d5c7040185188fbae28be901ca589a11a94b1b38ca36a79eccfeb\", \"price_changes\":[{\"asset_id\":\"41448400836309843603620980831210604935021861034693225347475867885462478926555\", \"price\":\"0.53\", \"size\":\"9\", \"side\":\"BUY\", \"hash\":\"3df5b4827a6c198682f1e90dc9046ce3dfc4a7a4\", \"best_bid\":\"0.57\", \"best_ask\":\"0.58\"}, {\"asset_id\":\"24254094493625419915756280046002869097156693848522361803041977572204227262166\", \"price\":\"0.47\", \"size\":\"9\", \"side\":\"SELL\", \"hash\":\"2d5b382d27169b0c772de203c100756e8fe93b81\", \"best_bid\":\"0.42\", \"best_ask\":\"0.43\"}], \"timestamp\":\"1785122443679\", \"event_type\":\"price_change\"}","received_at":"2026-07-27T03:20:43.564522Z","schema_version":"clob-market-ws.price_change.v1","sequence":null,"server_hash":null,"server_timestamp":"1785122443679","session_id":"dd162b8dca5f43ff811d304e69a06123","source":"clob_market_ws"},"received_at":"2026-07-27T03:20:43.564522Z","record_id":"a8713a583c5da698cc34c4fda8281ec1d1f62bf1378a687faa949461ceb049c4","schema_fingerprint":"4aa3821a28b0b7c2400bc59aba4bcc0a76e971dadd19610d3ad38c768e124dc7","schema_version":"edge-lab-recorder.raw.v1","sequence":null,"source":"clob_market_ws"}
{"event_at":"2026-07-27T03:20:43.683000Z","event_fingerprint":"98a03fc929a8e4a10344ea52506c0c1d2ae55ea15bb93279f8b128517d1210b6","payload":{"connection_id":"c7dc2e4762f849c6b6f9306b6518dcab","event_at":"2026-07-27T03:20:43.683000Z","event_type":"price_change","frame_hash":"49da221c790b953be0833c4e141c72289dadcf77348608bca1c4cbc4a1e2787c","frame_index":0,"kind":"data","monotonic_ns":224426926674958,"payload":{"event_type":"price_change","market":"0x717c0e8ccd4d5c7040185188fbae28be901ca589a11a94b1b38ca36a79eccfeb","price_changes":[{"asset_id":"41448400836309843603620980831210604935021861034693225347475867885462478926555","best_ask":"0.58","best_bid":"0.57","hash":"56c6a129fcc134f61052b4572d0b16d9f6c68d0f","price":"0.52","side":"BUY","size":"22"},{"asset_id":"24254094493625419915756280046002869097156693848522361803041977572204227262166","best_ask":"0.43","best_bid":"0.42","hash":"64fc76288bab3f4601d0d628639f814a988b7e27","price":"0.48","side":"SELL","size":"22"}],"timestamp":"1785122443683"},"payload_hash":"6f01f71d4c09b93151423891cf1a85432ba92e5a0c3ef5ccd927d847689da645","raw_frame":"{\"market\":\"0x717c0e8ccd4d5c7040185188fbae28be901ca589a11a94b1b38ca36a79eccfeb\", \"price_changes\":[{\"asset_id\":\"41448400836309843603620980831210604935021861034693225347475867885462478926555\", \"price\":\"0.52\", \"size\":\"22\", \"side\":\"BUY\", \"hash\":\"56c6a129fcc134f61052b4572d0b16d9f6c68d0f\", \"best_bid\":\"0.57\", \"best_ask\":\"0.58\"}, {\"asset_id\":\"24254094493625419915756280046002869097156693848522361803041977572204227262166\", \"price\":\"0.48\", \"size\":\"22\", \"side\":\"SELL\", \"hash\":\"64fc76288bab3f4601d0d628639f814a988b7e27\", \"best_bid\":\"0.42\", \"best_ask\":\"0.43\"}], \"timestamp\":\"1785122443683\", \"event_type\":\"price_change\"}","received_at":"2026-07-27T03:20:43.572351Z","schema_version":"clob-market-ws.price_change.v1","sequence":null,"server_hash":null,"server_timestamp":"1785122443683","session_id":"dd162b8dca5f43ff811d304e69a06123","source":"clob_market_ws"},"received_at":"2026-07-27T03:20:43.572351Z","record_id":"caea770d648c5aa06e871e746769377247c2c399087abdf8449491a8a8dfb897","schema_fingerprint":"4aa3821a28b0b7c2400bc59aba4bcc0a76e971dadd19610d3ad38c768e124dc7","schema_version":"edge-lab-recorder.raw.v1","sequence":null,"source":"clob_market_ws"}
{"event_at":"2026-07-27T03:20:43.819000Z","event_fingerprint":"fadd77a105e4efcc39c7cb1d146a7b54afd3e6176de48133a00ffe351c8798a5","payload":{"connection_id":"c7dc2e4762f849c6b6f9306b6518dcab","event_at":"2026-07-27T03:20:43.819000Z","event_type":"price_change","frame_hash":"dc45762d306b6186d5f36e10512ea46d98787bec6af1865b63db285d48d37964","frame_index":0,"kind":"data","monotonic_ns":224427053502750,"payload":{"event_type":"price_change","market":"0x717c0e8ccd4d5c7040185188fbae28be901ca589a11a94b1b38ca36a79eccfeb","price_changes":[{"asset_id":"41448400836309843603620980831210604935021861034693225347475867885462478926555","best_ask":"0.58","best_bid":"0.57","hash":"679865277f48b1ffd356480837126092507b8b8d","price":"0.03","side":"BUY","size":"613.1"},{"asset_id":"24254094493625419915756280046002869097156693848522361803041977572204227262166","best_ask":"0.43","best_bid":"0.42","hash":"ec15b3daf334b2c9a2721ed6bdbbf01221679d20","price":"0.97","side":"SELL","size":"613.1"}],"timestamp":"1785122443819"},"payload_hash":"5c01055e0157377e91a3ae42bd32458b15cb365a047d7615cbf07ec9ff94ebf7","raw_frame":"{\"market\":\"0x717c0e8ccd4d5c7040185188fbae28be901ca589a11a94b1b38ca36a79eccfeb\", \"price_changes\":[{\"asset_id\":\"41448400836309843603620980831210604935021861034693225347475867885462478926555\", \"price\":\"0.03\", \"size\":\"613.1\", \"side\":\"BUY\", \"hash\":\"679865277f48b1ffd356480837126092507b8b8d\", \"best_bid\":\"0.57\", \"best_ask\":\"0.58\"}, {\"asset_id\":\"24254094493625419915756280046002869097156693848522361803041977572204227262166\", \"price\":\"0.97\", \"size\":\"613.1\", \"side\":\"SELL\", \"hash\":\"ec15b3daf334b2c9a2721ed6bdbbf01221679d20\", \"best_bid\":\"0.42\", \"best_ask\":\"0.43\"}], \"timestamp\":\"1785122443819\", \"event_type\":\"price_change\"}","received_at":"2026-07-27T03:20:43.699174Z","schema_version":"clob-market-ws.price_change.v1","sequence":null,"server_hash":null,"server_timestamp":"1785122443819","session_id":"dd162b8dca5f43ff811d304e69a06123","source":"clob_market_ws"},"received_at":"2026-07-27T03:20:43.699174Z","record_id":"2d0f204f7fb90cec54bbc826b2a43a70af831b340bcb4a64d61a2b4f3bddd551","schema_fingerprint":"4aa3821a28b0b7c2400bc59aba4bcc0a76e971dadd19610d3ad38c768e124dc7","schema_version":"edge-lab-recorder.raw.v1","sequence":null,"source":"clob_market_ws"}
{"event_at":"2026-07-27T03:20:43.875000Z","event_fingerprint":"f7af9ad533ae6f1b09c29815511ae2ae2bc3c052446d01ae48af2fec9fa95627","payload":{"connection_id":"c7dc2e4762f849c6b6f9306b6518dcab","event_at":"2026-07-27T03:20:43.875000Z","event_type":"price_change","frame_hash":"f6e3909128614e4c180a4a2784b0a64d7df381e86dd9073480c6c3100754dd38","frame_index":0,"kind":"data","monotonic_ns":224427110476291,"payload":{"event_type":"price_change","market":"0x717c0e8ccd4d5c7040185188fbae28be901ca589a11a94b1b38ca36a79eccfeb","price_changes":[{"asset_id":"41448400836309843603620980831210604935021861034693225347475867885462478926555","best_ask":"0.58","best_bid":"0.57","hash":"14bd604d295c851a65cde3ba626fbdb822c9a85f","price":"0.01","side":"BUY","size":"5708.02"},{"asset_id":"24254094493625419915756280046002869097156693848522361803041977572204227262166","best_ask":"0.43","best_bid":"0.42","hash":"7e4e3686bb20d4b123f68766326e8bbd090816bd","price":"0.99","side":"SELL","size":"5708.02"}],"timestamp":"1785122443875"},"payload_hash":"413657ddeafdb2266c31c419ecacc796941d1ad7fd5943ca56848ce364b2ec8a","raw_frame":"{\"market\":\"0x717c0e8ccd4d5c7040185188fbae28be901ca589a11a94b1b38ca36a79eccfeb\", \"price_changes\":[{\"asset_id\":\"41448400836309843603620980831210604935021861034693225347475867885462478926555\", \"price\":\"0.01\", \"size\":\"5708.02\", \"side\":\"BUY\", \"hash\":\"14bd604d295c851a65cde3ba626fbdb822c9a85f\", \"best_bid\":\"0.57\", \"best_ask\":\"0.58\"}, {\"asset_id\":\"24254094493625419915756280046002869097156693848522361803041977572204227262166\", \"price\":\"0.99\", \"size\":\"5708.02\", \"side\":\"SELL\", \"hash\":\"7e4e3686bb20d4b123f68766326e8bbd090816bd\", \"best_bid\":\"0.42\", \"best_ask\":\"0.43\"}], \"timestamp\":\"1785122443875\", \"event_type\":\"price_change\"}","received_at":"2026-07-27T03:20:43.756144Z","schema_version":"clob-market-ws.price_change.v1","sequence":null,"server_hash":null,"server_timestamp":"1785122443875","session_id":"dd162b8dca5f43ff811d304e69a06123","source":"clob_market_ws"},"received_at":"2026-07-27T03:20:43.756144Z","record_id":"f9397ad3d2a13abf0c16db29d9d0d108b9250bbe803d72c041c32db483c16019","schema_fingerprint":"4aa3821a28b0b7c2400bc59aba4bcc0a76e971dadd19610d3ad38c768e124dc7","schema_version":"edge-lab-recorder.raw.v1","sequence":null,"source":"clob_market_ws"}
{"event_at":"2026-07-27T03:20:43.894000Z","event_fingerprint":"391d3799a394a6d6a43661ea56bd22bfac2a7ab47b9850e3154d216595692dcb","payload":{"connection_id":"c7dc2e4762f849c6b6f9306b6518dcab","event_at":"2026-07-27T03:20:43.894000Z","event_type":"price_change","frame_hash":"ff09b4048816fe560d1fada4a67ed045754343818a041be1c332b6561aa859d4","frame_index":0,"kind":"data","monotonic_ns":224427131542708,"payload":{"event_type":"price_change","market":"0x717c0e8ccd4d5c7040185188fbae28be901ca589a11a94b1b38ca36a79eccfeb","price_changes":[{"asset_id":"41448400836309843603620980831210604935021861034693225347475867885462478926555","best_ask":"0.58","best_bid":"0.57","hash":"df6680523600fe51912c44141d346a4f6b2e0c73","price":"0.01","side":"BUY","size":"5703.02"},{"asset_id":"24254094493625419915756280046002869097156693848522361803041977572204227262166","best_ask":"0.43","best_bid":"0.42","hash":"acae99aecedd4900d7982a9657362d506429cadd","price":"0.99","side":"SELL","size":"5703.02"}],"timestamp":"1785122443894"},"payload_hash":"d7a7e46da4e9a14889e3eacf38f6ede0bde3c9a19ad700442318cb75ee370827","raw_frame":"{\"market\":\"0x717c0e8ccd4d5c7040185188fbae28be901ca589a11a94b1b38ca36a79eccfeb\", \"price_changes\":[{\"asset_id\":\"41448400836309843603620980831210604935021861034693225347475867885462478926555\", \"price\":\"0.01\", \"size\":\"5703.02\", \"side\":\"BUY\", \"hash\":\"df6680523600fe51912c44141d346a4f6b2e0c73\", \"best_bid\":\"0.57\", \"best_ask\":\"0.58\"}, {\"asset_id\":\"24254094493625419915756280046002869097156693848522361803041977572204227262166\", \"price\":\"0.99\", \"size\":\"5703.02\", \"side\":\"SELL\", \"hash\":\"acae99aecedd4900d7982a9657362d506429cadd\", \"best_bid\":\"0.42\", \"best_ask\":\"0.43\"}], \"timestamp\":\"1785122443894\", \"event_type\":\"price_change\"}","received_at":"2026-07-27T03:20:43.777214Z","schema_version":"clob-market-ws.price_change.v1","sequence":null,"server_hash":null,"server_timestamp":"1785122443894","session_id":"dd162b8dca5f43ff811d304e69a06123","source":"clob_market_ws"},"received_at":"2026-07-27T03:20:43.777214Z","record_id":"c6611ef5cfae65eb00a4080fe82df6cd25c1fdc4f5c92389e8bdeb55bf7a49f8","schema_fingerprint":"4aa3821a28b0b7c2400bc59aba4bcc0a76e971dadd19610d3ad38c768e124dc7","schema_version":"edge-lab-recorder.raw.v1","sequence":null,"source":"clob_market_ws"}
{"event_at":"2026-07-27T03:20:43.897000Z","event_fingerprint":"18df0b23078fc49296592599e4ae737f1ea28dac000b24bfb2114f827b1829ed","payload":{"connection_id":"c7dc2e4762f849c6b6f9306b6518dcab","event_at":"2026-07-27T03:20:43.897000Z","event_type":"price_change","frame_hash":"9cab938f8e82633e396beee92db05771d3c3f8dfbca65c88b7beef42b8fbdcc9","frame_index":0,"kind":"data","monotonic_ns":224427137604833,"payload":{"event_type":"price_change","market":"0x717c0e8ccd4d5c7040185188fbae28be901ca589a11a94b1b38ca36a79eccfeb","price_changes":[{"asset_id":"41448400836309843603620980831210604935021861034693225347475867885462478926555","best_ask":"0.58","best_bid":"0.57","hash":"b79eb3a6872bfeab08c8b82290c8ddebedf8670c","price":"0.52","side":"BUY","size":"15"},{"asset_id":"24254094493625419915756280046002869097156693848522361803041977572204227262166","best_ask":"0.43","best_bid":"0.42","hash":"97392cf85e3e7be2fdafefc7ae8078a552f48532","price":"0.48","side":"SELL","size":"15"}],"timestamp":"1785122443897"},"payload_hash":"5e2d028a3d5781101b085fdad63c128fbf76def3b3be9b0cd20bdd18ba287ea7","raw_frame":"{\"market\":\"0x717c0e8ccd4d5c7040185188fbae28be901ca589a11a94b1b38ca36a79eccfeb\", \"price_changes\":[{\"asset_id\":\"41448400836309843603620980831210604935021861034693225347475867885462478926555\", \"price\":\"0.52\", \"size\":\"15\", \"side\":\"BUY\", \"hash\":\"b79eb3a6872bfeab08c8b82290c8ddebedf8670c\", \"best_bid\":\"0.57\", \"best_ask\":\"0.58\"}, {\"asset_id\":\"24254094493625419915756280046002869097156693848522361803041977572204227262166\", \"price\":\"0.48\", \"size\":\"15\", \"side\":\"SELL\", \"hash\":\"97392cf85e3e7be2fdafefc7ae8078a552f48532\", \"best_bid\":\"0.42\", \"best_ask\":\"0.43\"}], \"timestamp\":\"1785122443897\", \"event_type\":\"price_change\"}","received_at":"2026-07-27T03:20:43.783277Z","schema_version":"clob-market-ws.price_change.v1","sequence":null,"server_hash":null,"server_timestamp":"1785122443897","session_id":"dd162b8dca5f43ff811d304e69a06123","source":"clob_market_ws"},"received_at":"2026-07-27T03:20:43.783277Z","record_id":"3e264179d23da59c37beb8e2dbf5ae2e7f6f52ae1fc72e5bfa3fd667d7af568a","schema_fingerprint":"4aa3821a28b0b7c2400bc59aba4bcc0a76e971dadd19610d3ad38c768e124dc7","schema_version":"edge-lab-recorder.raw.v1","sequence":null,"source":"clob_market_ws"}
{"event_at":"2026-07-27T03:20:43.901000Z","event_fingerprint":"bf728f926ce4c8707f50f69a37158111fafe410178f91e5155313dc8348ba578","payload":{"connection_id":"c7dc2e4762f849c6b6f9306b6518dcab","event_at":"2026-07-27T03:20:43.901000Z","event_type":"price_change","frame_hash":"d7290ce49f4d0db7372c25595c24716c9fc3ebc98f4016e70ed735e9fc6ff47a","frame_index":0,"kind":"data","monotonic_ns":224427143741166,"payload":{"event_type":"price_change","market":"0x717c0e8ccd4d5c7040185188fbae28be901ca589a11a94b1b38ca36a79eccfeb","price_changes":[{"asset_id":"41448400836309843603620980831210604935021861034693225347475867885462478926555","best_ask":"0.58","best_bid":"0.57","hash":"460945be2cb3a287c1561017b989700ce67ae21f","price":"0.03","side":"BUY","size":"618.1"},{"asset_id":"24254094493625419915756280046002869097156693848522361803041977572204227262166","best_ask":"0.43","best_bid":"0.42","hash":"82c7bce252a57a77c17269371dbc487a98bfb09b","price":"0.97","side":"SELL","size":"618.1"}],"timestamp":"1785122443901"},"payload_hash":"38ac1ea5965b64d58efce5969767d30b8b4aa01286a57caf42a27af2ef29b267","raw_frame":"{\"market\":\"0x717c0e8ccd4d5c7040185188fbae28be901ca589a11a94b1b38ca36a79eccfeb\", \"price_changes\":[{\"asset_id\":\"41448400836309843603620980831210604935021861034693225347475867885462478926555\", \"price\":\"0.03\", \"size\":\"618.1\", \"side\":\"BUY\", \"hash\":\"460945be2cb3a287c1561017b989700ce67ae21f\", \"best_bid\":\"0.57\", \"best_ask\":\"0.58\"}, {\"asset_id\":\"24254094493625419915756280046002869097156693848522361803041977572204227262166\", \"price\":\"0.97\", \"size\":\"618.1\", \"side\":\"SELL\", \"hash\":\"82c7bce252a57a77c17269371dbc487a98bfb09b\", \"best_bid\":\"0.42\", \"best_ask\":\"0.43\"}], \"timestamp\":\"1785122443901\", \"event_type\":\"price_change\"}","received_at":"2026-07-27T03:20:43.789412Z","schema_version":"clob-market-ws.price_change.v1","sequence":null,"server_hash":null,"server_timestamp":"1785122443901","session_id":"dd162b8dca5f43ff811d304e69a06123","source":"clob_market_ws"},"received_at":"2026-07-27T03:20:43.789412Z","record_id":"78bd6833b87accdd4ca2f49235fbaca28eada581deb8122687ba094bbfb562e1","schema_fingerprint":"4aa3821a28b0b7c2400bc59aba4bcc0a76e971dadd19610d3ad38c768e124dc7","schema_version":"edge-lab-recorder.raw.v1","sequence":null,"source":"clob_market_ws"}
{"event_at":"2026-07-27T03:20:43.902000Z","event_fingerprint":"114deccc8b5e48edaf80fa9473185f250daa273c2d55be4b30d9b8b8cf1767fc","payload":{"connection_id":"c7dc2e4762f849c6b6f9306b6518dcab","event_at":"2026-07-27T03:20:43.902000Z","event_type":"price_change","frame_hash":"cff0b8304c3550b89837742397df4db7dfe4cbe2a79df7084856469691492133","frame_index":0,"kind":"data","monotonic_ns":224427147067958,"payload":{"event_type":"price_change","market":"0x717c0e8ccd4d5c7040185188fbae28be901ca589a11a94b1b38ca36a79eccfeb","price_changes":[{"asset_id":"41448400836309843603620980831210604935021861034693225347475867885462478926555","best_ask":"0.58","best_bid":"0.57","hash":"1aeda91fe080fcf1ecbf01cce697632ccc68f077","price":"0.53","side":"BUY","size":"14"},{"asset_id":"24254094493625419915756280046002869097156693848522361803041977572204227262166","best_ask":"0.43","best_bid":"0.42","hash":"6376869cdbdf1d689ead783a8c7d46d99a4b4489","price":"0.47","side":"SELL","size":"14"}],"timestamp":"1785122443902"},"payload_hash":"1d9fb6f08a9c352c8f04183fc487a91db654f7a1fb65969a27665a63f954e23d","raw_frame":"{\"market\":\"0x717c0e8ccd4d5c7040185188fbae28be901ca589a11a94b1b38ca36a79eccfeb\", \"price_changes\":[{\"asset_id\":\"41448400836309843603620980831210604935021861034693225347475867885462478926555\", \"price\":\"0.53\", \"size\":\"14\", \"side\":\"BUY\", \"hash\":\"1aeda91fe080fcf1ecbf01cce697632ccc68f077\", \"best_bid\":\"0.57\", \"best_ask\":\"0.58\"}, {\"asset_id\":\"24254094493625419915756280046002869097156693848522361803041977572204227262166\", \"price\":\"0.47\", \"size\":\"14\", \"side\":\"SELL\", \"hash\":\"6376869cdbdf1d689ead783a8c7d46d99a4b4489\", \"best_bid\":\"0.42\", \"best_ask\":\"0.43\"}], \"timestamp\":\"1785122443902\", \"event_type\":\"price_change\"}","received_at":"2026-07-27T03:20:43.792738Z","schema_version":"clob-market-ws.price_change.v1","sequence":null,"server_hash":null,"server_timestamp":"1785122443902","session_id":"dd162b8dca5f43ff811d304e69a06123","source":"clob_market_ws"},"received_at":"2026-07-27T03:20:43.792738Z","record_id":"86ecdbee0029a2b39b7bfb35528712183ba19b826a87bb4ec595a23255cba491","schema_fingerprint":"4aa3821a28b0b7c2400bc59aba4bcc0a76e971dadd19610d3ad38c768e124dc7","schema_version":"edge-lab-recorder.raw.v1","sequence":null,"source":"clob_market_ws"}
{"event_at":"2026-07-27T03:20:44.017000Z","event_fingerprint":"efd4d176221a40c43bdd33b01a93d5d376d7e79ed60f00b1523d24c5d6eca6fd","payload":{"connection_id":"c7dc2e4762f849c6b6f9306b6518dcab","event_at":"2026-07-27T03:20:44.017000Z","event_type":"price_change","frame_hash":"2575809dcf4aca50a953f9251085822a8bf2ca4f7fc8858b1abd3f18468283d0","frame_index":0,"kind":"data","monotonic_ns":224427256237875,"payload":{"event_type":"price_change","market":"0x717c0e8ccd4d5c7040185188fbae28be901ca589a11a94b1b38ca36a79eccfeb","price_changes":[{"asset_id":"41448400836309843603620980831210604935021861034693225347475867885462478926555","best_ask":"0.58","best_bid":"0.57","hash":"a8009836562b678da5418143f045cddde28e2854","price":"0.03","side":"BUY","size":"613.1"},{"asset_id":"24254094493625419915756280046002869097156693848522361803041977572204227262166","best_ask":"0.43","best_bid":"0.42","hash":"1e94f0d29c2181534b2bc290730e0baf77b8bcc8","price":"0.97","side":"SELL","size":"613.1"}],"timestamp":"1785122444017"},"payload_hash":"df3cf5e9b82479f697f783a6d3f9460060a14e5dc27f17cd21136416f57e8254","raw_frame":"{\"market\":\"0x717c0e8ccd4d5c7040185188fbae28be901ca589a11a94b1b38ca36a79eccfeb\", \"price_changes\":[{\"asset_id\":\"41448400836309843603620980831210604935021861034693225347475867885462478926555\", \"price\":\"0.03\", \"size\":\"613.1\", \"side\":\"BUY\", \"hash\":\"a8009836562b678da5418143f045cddde28e2854\", \"best_bid\":\"0.57\", \"best_ask\":\"0.58\"}, {\"asset_id\":\"24254094493625419915756280046002869097156693848522361803041977572204227262166\", \"price\":\"0.97\", \"size\":\"613.1\", \"side\":\"SELL\", \"hash\":\"1e94f0d29c2181534b2bc290730e0baf77b8bcc8\", \"best_bid\":\"0.42\", \"best_ask\":\"0.43\"}], \"timestamp\":\"1785122444017\", \"event_type\":\"price_change\"}","received_at":"2026-07-27T03:20:43.901904Z","schema_version":"clob-market-ws.price_change.v1","sequence":null,"server_hash":null,"server_timestamp":"1785122444017","session_id":"dd162b8dca5f43ff811d304e69a06123","source":"clob_market_ws"},"received_at":"2026-07-27T03:20:43.901904Z","record_id":"d01104fc8ce7b066b965ecb94a99d94e6b87c85fd7719d305e45c53c7e279d91","schema_fingerprint":"4aa3821a28b0b7c2400bc59aba4bcc0a76e971dadd19610d3ad38c768e124dc7","schema_version":"edge-lab-recorder.raw.v1","sequence":null,"source":"clob_market_ws"}
{"event_at":"2026-07-27T03:20:44.018000Z","event_fingerprint":"81d22d01acf9befc8d8005866e00e99af9eb597d2d22428185fb7edbd4f5af04","payload":{"connection_id":"c7dc2e4762f849c6b6f9306b6518dcab","event_at":"2026-07-27T03:20:44.018000Z","event_type":"price_change","frame_hash":"173409948ff4225645330fbba74159c8d747bb2074405305ad6d4a2b15a223fe","frame_index":0,"kind":"data","monotonic_ns":224427262101000,"payload":{"event_type":"price_change","market":"0x717c0e8ccd4d5c7040185188fbae28be901ca589a11a94b1b38ca36a79eccfeb","price_changes":[{"asset_id":"24254094493625419915756280046002869097156693848522361803041977572204227262166","best_ask":"0.43","best_bid":"0.42","hash":"fb754ff03729b94aaee9a5287a131da53eaef47f","price":"0.01","side":"BUY","size":"5708.02"},{"asset_id":"41448400836309843603620980831210604935021861034693225347475867885462478926555","best_ask":"0.58","best_bid":"0.57","hash":"5282fb2e35324a3d3338c2cec60f71de45e1a42a","price":"0.99","side":"SELL","size":"5708.02"}],"timestamp":"1785122444018"},"payload_hash":"a683256f674676c093d54229e71fa9bcd1d31c6cccd54dbb2374e39fcfea6e24","raw_frame":"{\"market\":\"0x717c0e8ccd4d5c7040185188fbae28be901ca589a11a94b1b38ca36a79eccfeb\", \"price_changes\":[{\"asset_id\":\"24254094493625419915756280046002869097156693848522361803041977572204227262166\", \"price\":\"0.01\", \"size\":\"5708.02\", \"side\":\"BUY\", \"hash\":\"fb754ff03729b94aaee9a5287a131da53eaef47f\", \"best_bid\":\"0.42\", \"best_ask\":\"0.43\"}, {\"asset_id\":\"41448400836309843603620980831210604935021861034693225347475867885462478926555\", \"price\":\"0.99\", \"size\":\"5708.02\", \"side\":\"SELL\", \"hash\":\"5282fb2e35324a3d3338c2cec60f71de45e1a42a\", \"best_bid\":\"0.57\", \"best_ask\":\"0.58\"}], \"timestamp\":\"1785122444018\", \"event_type\":\"price_change\"}","received_at":"2026-07-27T03:20:43.907769Z","schema_version":"clob-market-ws.price_change.v1","sequence":null,"server_hash":null,"server_timestamp":"1785122444018","session_id":"dd162b8dca5f43ff811d304e69a06123","source":"clob_market_ws"},"received_at":"2026-07-27T03:20:43.907769Z","record_id":"081f84421271f653c4e6e9b7f6d9352565802cadac3d05f64f514e3de7b61aaa","schema_fingerprint":"4aa3821a28b0b7c2400bc59aba4bcc0a76e971dadd19610d3ad38c768e124dc7","schema_version":"edge-lab-recorder.raw.v1","sequence":null,"source":"clob_market_ws"}
{"event_at":"2026-07-27T03:20:44.038000Z","event_fingerprint":"66488ddfedc46b4e3872dbdf7404e6545164d288c20198d5ad57da8e8676c539","payload":{"connection_id":"c7dc2e4762f849c6b6f9306b6518dcab","event_at":"2026-07-27T03:20:44.038000Z","event_type":"price_change","frame_hash":"34507f8edbd83f7b68f37baeca59c1d18a910530b03726077da4084ea714ac5c","frame_index":0,"kind":"data","monotonic_ns":224427282647125,"payload":{"event_type":"price_change","market":"0x717c0e8ccd4d5c7040185188fbae28be901ca589a11a94b1b38ca36a79eccfeb","price_changes":[{"asset_id":"24254094493625419915756280046002869097156693848522361803041977572204227262166","best_ask":"0.43","best_bid":"0.42","hash":"3174727c6f5e7060580f2e0f5fb7e5b92a7fa845","price":"0.01","side":"BUY","size":"5713.02"},{"asset_id":"41448400836309843603620980831210604935021861034693225347475867885462478926555","best_ask":"0.58","best_bid":"0.57","hash":"cf55a04a0539b38b4fd63098a3d95717bb1d4a75","price":"0.99","side":"SELL","size":"5713.02"}],"timestamp":"1785122444038"},"payload_hash":"cef2daadfa883fad31e87f1b5b8c97c1558ca9d9368049f23f9ffc81aad44a46","raw_frame":"{\"market\":\"0x717c0e8ccd4d5c7040185188fbae28be901ca589a11a94b1b38ca36a79eccfeb\", \"price_changes\":[{\"asset_id\":\"24254094493625419915756280046002869097156693848522361803041977572204227262166\", \"price\":\"0.01\", \"size\":\"5713.02\", \"side\":\"BUY\", \"hash\":\"3174727c6f5e7060580f2e0f5fb7e5b92a7fa845\", \"best_bid\":\"0.42\", \"best_ask\":\"0.43\"}, {\"asset_id\":\"41448400836309843603620980831210604935021861034693225347475867885462478926555\", \"price\":\"0.99\", \"size\":\"5713.02\", \"side\":\"SELL\", \"hash\":\"cf55a04a0539b38b4fd63098a3d95717bb1d4a75\", \"best_bid\":\"0.57\", \"best_ask\":\"0.58\"}], \"timestamp\":\"1785122444038\", \"event_type\":\"price_change\"}","received_at":"2026-07-27T03:20:43.928313Z","schema_version":"clob-market-ws.price_change.v1","sequence":null,"server_hash":null,"server_timestamp":"1785122444038","session_id":"dd162b8dca5f43ff811d304e69a06123","source":"clob_market_ws"},"received_at":"2026-07-27T03:20:43.928313Z","record_id":"862a824385027a5439cb4efdcbcc758bde6282e289eeb21e99c8912fd295254d","schema_fingerprint":"4aa3821a28b0b7c2400bc59aba4bcc0a76e971dadd19610d3ad38c768e124dc7","schema_version":"edge-lab-recorder.raw.v1","sequence":null,"source":"clob_market_ws"}
{"event_at":"2026-07-27T03:20:44.051000Z","event_fingerprint":"723a86b3a883da6a02375f93f63a9045cec48221aeb8b728fe221fccb8a71809","payload":{"connection_id":"c7dc2e4762f849c6b6f9306b6518dcab","event_at":"2026-07-27T03:20:44.051000Z","event_type":"price_change","frame_hash":"5bfcd80fe903ea86329ea345515b0a2f443329998946b3d28b61fc34b86f48be","frame_index":0,"kind":"data","monotonic_ns":224427289368208,"payload":{"event_type":"price_change","market":"0x717c0e8ccd4d5c7040185188fbae28be901ca589a11a94b1b38ca36a79eccfeb","price_changes":[{"asset_id":"41448400836309843603620980831210604935021861034693225347475867885462478926555","best_ask":"0.58","best_bid":"0.57","hash":"d0776ba2700d5a63723e1e9b845ff4f997124cb2","price":"0.51","side":"BUY","size":"167"},{"asset_id":"24254094493625419915756280046002869097156693848522361803041977572204227262166","best_ask":"0.43","best_bid":"0.42","hash":"ac846931678259c4f12936295f16a1b8ae590f0c","price":"0.49","side":"SELL","size":"167"}],"timestamp":"1785122444051"},"payload_hash":"56f95f0ead0c4867984b47232206342e7f461293addd70caf2bfb887b092e38d","raw_frame":"{\"market\":\"0x717c0e8ccd4d5c7040185188fbae28be901ca589a11a94b1b38ca36a79eccfeb\", \"price_changes\":[{\"asset_id\":\"41448400836309843603620980831210604935021861034693225347475867885462478926555\", \"price\":\"0.51\", \"size\":\"167\", \"side\":\"BUY\", \"hash\":\"d0776ba2700d5a63723e1e9b845ff4f997124cb2\", \"best_bid\":\"0.57\", \"best_ask\":\"0.58\"}, {\"asset_id\":\"24254094493625419915756280046002869097156693848522361803041977572204227262166\", \"price\":\"0.49\", \"size\":\"167\", \"side\":\"SELL\", \"hash\":\"ac846931678259c4f12936295f16a1b8ae590f0c\", \"best_bid\":\"0.42\", \"best_ask\":\"0.43\"}], \"timestamp\":\"1785122444051\", \"event_type\":\"price_change\"}","received_at":"2026-07-27T03:20:43.935034Z","schema_version":"clob-market-ws.price_change.v1","sequence":null,"server_hash":null,"server_timestamp":"1785122444051","session_id":"dd162b8dca5f43ff811d304e69a06123","source":"clob_market_ws"},"received_at":"2026-07-27T03:20:43.935034Z","record_id":"5e0d14581f46f02646874942b25209f1357b14a0c89750a3962db62f15f67bb0","schema_fingerprint":"4aa3821a28b0b7c2400bc59aba4bcc0a76e971dadd19610d3ad38c768e124dc7","schema_version":"edge-lab-recorder.raw.v1","sequence":null,"source":"clob_market_ws"}
{"event_at":"2026-07-27T03:20:44.055000Z","event_fingerprint":"d0f224b80f02561fd3dc54a7157cf17549793b4d6ef156765669d1dff2b29484","payload":{"connection_id":"c7dc2e4762f849c6b6f9306b6518dcab","event_at":"2026-07-27T03:20:44.055000Z","event_type":"price_change","frame_hash":"df117a17bcb7de13a2b12a7aa90096921ff48dffe4ec199cebccb7a8b4818d79","frame_index":0,"kind":"data","monotonic_ns":224427297315625,"payload":{"event_type":"price_change","market":"0x717c0e8ccd4d5c7040185188fbae28be901ca589a11a94b1b38ca36a79eccfeb","price_changes":[{"asset_id":"41448400836309843603620980831210604935021861034693225347475867885462478926555","best_ask":"0.58","best_bid":"0.57","hash":"db465e007f855e53cd34c73e49cadd6781b25ce1","price":"0.01","side":"BUY","size":"5708.02"},{"asset_id":"24254094493625419915756280046002869097156693848522361803041977572204227262166","best_ask":"0.43","best_bid":"0.42","hash":"5684338b00598db5538f69480544753e6a20a160","price":"0.99","side":"SELL","size":"5708.02"}],"timestamp":"1785122444055"},"payload_hash":"9a9ba4f12d183916cc19ed79a1a2a4cab3f43cf40aa4a596a93f686f8850676d","raw_frame":"{\"market\":\"0x717c0e8ccd4d5c7040185188fbae28be901ca589a11a94b1b38ca36a79eccfeb\", \"price_changes\":[{\"asset_id\":\"41448400836309843603620980831210604935021861034693225347475867885462478926555\", \"price\":\"0.01\", \"size\":\"5708.02\", \"side\":\"BUY\", \"hash\":\"db465e007f855e53cd34c73e49cadd6781b25ce1\", \"best_bid\":\"0.57\", \"best_ask\":\"0.58\"}, {\"asset_id\":\"24254094493625419915756280046002869097156693848522361803041977572204227262166\", \"price\":\"0.99\", \"size\":\"5708.02\", \"side\":\"SELL\", \"hash\":\"5684338b00598db5538f69480544753e6a20a160\", \"best_bid\":\"0.42\", \"best_ask\":\"0.43\"}], \"timestamp\":\"1785122444055\", \"event_type\":\"price_change\"}","received_at":"2026-07-27T03:20:43.942982Z","schema_version":"clob-market-ws.price_change.v1","sequence":null,"server_hash":null,"server_timestamp":"1785122444055","session_id":"dd162b8dca5f43ff811d304e69a06123","source":"clob_market_ws"},"received_at":"2026-07-27T03:20:43.942982Z","record_id":"c2b9b0713112a0ac8e7c7013616889afac969275536f602e89bcb5cd0230d0a4","schema_fingerprint":"4aa3821a28b0b7c2400bc59aba4bcc0a76e971dadd19610d3ad38c768e124dc7","schema_version":"edge-lab-recorder.raw.v1","sequence":null,"source":"clob_market_ws"}
{"event_at":"2026-07-27T03:20:44.069000Z","event_fingerprint":"2a687831a1a736c9a2450b9732ed5955390c6c8438e687f81abb43bfc661c66f","payload":{"connection_id":"c7dc2e4762f849c6b6f9306b6518dcab","event_at":"2026-07-27T03:20:44.069000Z","event_type":"price_change","frame_hash":"e562a7890cd8d123196c84f9c80691cc8962412731eef740e143818b980807b1","frame_index":0,"kind":"data","monotonic_ns":224427306012125,"payload":{"event_type":"price_change","market":"0x717c0e8ccd4d5c7040185188fbae28be901ca589a11a94b1b38ca36a79eccfeb","price_changes":[{"asset_id":"24254094493625419915756280046002869097156693848522361803041977572204227262166","best_ask":"0.43","best_bid":"0.42","hash":"3fce93fb569c0bdc2154d5c9c7e33872cf2b2771","price":"0.01","side":"BUY","size":"5708.02"},{"asset_id":"41448400836309843603620980831210604935021861034693225347475867885462478926555","best_ask":"0.58","best_bid":"0.57","hash":"e89375ee6ca9d536f0be9568e25e4d8d5cbf2937","price":"0.99","side":"SELL","size":"5708.02"}],"timestamp":"1785122444069"},"payload_hash":"dc44e3eada7272e07d06beb049e634252e1466eff02d49f6d4d72ced7e4c4ce6","raw_frame":"{\"market\":\"0x717c0e8ccd4d5c7040185188fbae28be901ca589a11a94b1b38ca36a79eccfeb\", \"price_changes\":[{\"asset_id\":\"24254094493625419915756280046002869097156693848522361803041977572204227262166\", \"price\":\"0.01\", \"size\":\"5708.02\", \"side\":\"BUY\", \"hash\":\"3fce93fb569c0bdc2154d5c9c7e33872cf2b2771\", \"best_bid\":\"0.42\", \"best_ask\":\"0.43\"}, {\"asset_id\":\"41448400836309843603620980831210604935021861034693225347475867885462478926555\", \"price\":\"0.99\", \"size\":\"5708.02\", \"side\":\"SELL\", \"hash\":\"e89375ee6ca9d536f0be9568e25e4d8d5cbf2937\", \"best_bid\":\"0.57\", \"best_ask\":\"0.58\"}], \"timestamp\":\"1785122444069\", \"event_type\":\"price_change\"}","received_at":"2026-07-27T03:20:43.951679Z","schema_version":"clob-market-ws.price_change.v1","sequence":null,"server_hash":null,"server_timestamp":"1785122444069","session_id":"dd162b8dca5f43ff811d304e69a06123","source":"clob_market_ws"},"received_at":"2026-07-27T03:20:43.951679Z","record_id":"560cb02864dbab8de1e2676dbc08cc9d95755f00f1e9ed52c303f26f85b729a5","schema_fingerprint":"4aa3821a28b0b7c2400bc59aba4bcc0a76e971dadd19610d3ad38c768e124dc7","schema_version":"edge-lab-recorder.raw.v1","sequence":null,"source":"clob_market_ws"}
{"event_at":"2026-07-27T03:20:44.077000Z","event_fingerprint":"17dde9dacb680ac3c6c167ba19569b11aa7a2acd4d0939ecddb3d55ce73763d0","payload":{"connection_id":"c7dc2e4762f849c6b6f9306b6518dcab","event_at":"2026-07-27T03:20:44.077000Z","event_type":"price_change","frame_hash":"ec42d54269589cc952f606a4c68c5590b5611efa5c268adf5eac70e7ecd0ec31","frame_index":0,"kind":"data","monotonic_ns":224427313016458,"payload":{"event_type":"price_change","market":"0x717c0e8ccd4d5c7040185188fbae28be901ca589a11a94b1b38ca36a79eccfeb","price_changes":[{"asset_id":"24254094493625419915756280046002869097156693848522361803041977572204227262166","best_ask":"0.43","best_bid":"0.42","hash":"983c8d5b1782625c3baddba308eb9c6b19bf4fbc","price":"0.01","side":"BUY","size":"5703.02"},{"asset_id":"41448400836309843603620980831210604935021861034693225347475867885462478926555","best_ask":"0.58","best_bid":"0.57","hash":"4d839689df884e018ef18e7cadb9441f54959ee7","price":"0.99","side":"SELL","size":"5703.02"}],"timestamp":"1785122444077"},"payload_hash":"50f177190f58e4395ccb43a714294816e0ab1089af736de94d8c23e4b0876225","raw_frame":"{\"market\":\"0x717c0e8ccd4d5c7040185188fbae28be901ca589a11a94b1b38ca36a79eccfeb\", \"price_changes\":[{\"asset_id\":\"24254094493625419915756280046002869097156693848522361803041977572204227262166\", \"price\":\"0.01\", \"size\":\"5703.02\", \"side\":\"BUY\", \"hash\":\"983c8d5b1782625c3baddba308eb9c6b19bf4fbc\", \"best_bid\":\"0.42\", \"best_ask\":\"0.43\"}, {\"asset_id\":\"41448400836309843603620980831210604935021861034693225347475867885462478926555\", \"price\":\"0.99\", \"size\":\"5703.02\", \"side\":\"SELL\", \"hash\":\"4d839689df884e018ef18e7cadb9441f54959ee7\", \"best_bid\":\"0.57\", \"best_ask\":\"0.58\"}], \"timestamp\":\"1785122444077\", \"event_type\":\"price_change\"}","received_at":"2026-07-27T03:20:43.958682Z","schema_version":"clob-market-ws.price_change.v1","sequence":null,"server_hash":null,"server_timestamp":"1785122444077","session_id":"dd162b8dca5f43ff811d304e69a06123","source":"clob_market_ws"},"received_at":"2026-07-27T03:20:43.958682Z","record_id":"f5fd3c1d8a616bf8a9025708f9605ac4b0cdcaab7af7591c51a3f991722df1a6","schema_fingerprint":"4aa3821a28b0b7c2400bc59aba4bcc0a76e971dadd19610d3ad38c768e124dc7","schema_version":"edge-lab-recorder.raw.v1","sequence":null,"source":"clob_market_ws"}
{"event_at":"2026-07-27T03:20:44.081000Z","event_fingerprint":"471df50e1cd0b37ce569c8a13185a5b3c8749a6e4323319419f3946dbd293fd2","payload":{"connection_id":"c7dc2e4762f849c6b6f9306b6518dcab","event_at":"2026-07-27T03:20:44.081000Z","event_type":"price_change","frame_hash":"75a65f1825a96efc8a3019530ba84d535b55aafe23aaddb6b55fa1a9b227c27f","frame_index":0,"kind":"data","monotonic_ns":224427320598750,"payload":{"event_type":"price_change","market":"0x717c0e8ccd4d5c7040185188fbae28be901ca589a11a94b1b38ca36a79eccfeb","price_changes":[{"asset_id":"41448400836309843603620980831210604935021861034693225347475867885462478926555","best_ask":"0.58","best_bid":"0.57","hash":"ecf8198de3dace8a876965459efe002e6bfa0f24","price":"0.01","side":"BUY","size":"5703.02"},{"asset_id":"24254094493625419915756280046002869097156693848522361803041977572204227262166","best_ask":"0.43","best_bid":"0.42","hash":"71504ea59c88529d6e23785eaf07059206d1235f","price":"0.99","side":"SELL","size":"5703.02"}],"timestamp":"1785122444081"},"payload_hash":"7cf0f8a5b3a18b3fbce57603e20a21d622a75d6bad4ffc93f0ef50a4cd667612","raw_frame":"{\"market\":\"0x717c0e8ccd4d5c7040185188fbae28be901ca589a11a94b1b38ca36a79eccfeb\", \"price_changes\":[{\"asset_id\":\"41448400836309843603620980831210604935021861034693225347475867885462478926555\", \"price\":\"0.01\", \"size\":\"5703.02\", \"side\":\"BUY\", \"hash\":\"ecf8198de3dace8a876965459efe002e6bfa0f24\", \"best_bid\":\"0.57\", \"best_ask\":\"0.58\"}, {\"asset_id\":\"24254094493625419915756280046002869097156693848522361803041977572204227262166\", \"price\":\"0.99\", \"size\":\"5703.02\", \"side\":\"SELL\", \"hash\":\"71504ea59c88529d6e23785eaf07059206d1235f\", \"best_bid\":\"0.42\", \"best_ask\":\"0.43\"}], \"timestamp\":\"1785122444081\", \"event_type\":\"price_change\"}","received_at":"2026-07-27T03:20:43.966263Z","schema_version":"clob-market-ws.price_change.v1","sequence":null,"server_hash":null,"server_timestamp":"1785122444081","session_id":"dd162b8dca5f43ff811d304e69a06123","source":"clob_market_ws"},"received_at":"2026-07-27T03:20:43.966263Z","record_id":"e5a636b283b4562accff3152575662e8431760bb0b0f615930fab48e0ecb098b","schema_fingerprint":"4aa3821a28b0b7c2400bc59aba4bcc0a76e971dadd19610d3ad38c768e124dc7","schema_version":"edge-lab-recorder.raw.v1","sequence":null,"source":"clob_market_ws"}
{"event_at":"2026-07-27T03:20:44.095000Z","event_fingerprint":"1d4f4daeeb1d67b06ee0e4fdd479e1e75e1daab567eaa92054aada7a7e432a39","payload":{"connection_id":"c7dc2e4762f849c6b6f9306b6518dcab","event_at":"2026-07-27T03:20:44.095000Z","event_type":"price_change","frame_hash":"171fb2ad6ffd96ccd79700abd30442f15ccd9cdc394065985f7a342d5f0c37fb","frame_index":0,"kind":"data","monotonic_ns":224427334070416,"payload":{"event_type":"price_change","market":"0x717c0e8ccd4d5c7040185188fbae28be901ca589a11a94b1b38ca36a79eccfeb","price_changes":[{"asset_id":"41448400836309843603620980831210604935021861034693225347475867885462478926555","best_ask":"0.58","best_bid":"0.57","hash":"d24c306f49a0270dab144456a9c0d2dbb770c5a5","price":"0.04","side":"BUY","size":"583.09"},{"asset_id":"24254094493625419915756280046002869097156693848522361803041977572204227262166","best_ask":"0.43","best_bid":"0.42","hash":"8acd14ff9e6d815e758f736a318da299d37e35c4","price":"0.96","side":"SELL","size":"583.09"}],"timestamp":"1785122444095"},"payload_hash":"b36991a3cd6ebd45f48a4b616bad2a207223bec045c18b8f11d0ad90a699d350","raw_frame":"{\"market\":\"0x717c0e8ccd4d5c7040185188fbae28be901ca589a11a94b1b38ca36a79eccfeb\", \"price_changes\":[{\"asset_id\":\"41448400836309843603620980831210604935021861034693225347475867885462478926555\", \"price\":\"0.04\", \"size\":\"583.09\", \"side\":\"BUY\", \"hash\":\"d24c306f49a0270dab144456a9c0d2dbb770c5a5\", \"best_bid\":\"0.57\", \"best_ask\":\"0.58\"}, {\"asset_id\":\"24254094493625419915756280046002869097156693848522361803041977572204227262166\", \"price\":\"0.96\", \"size\":\"583.09\", \"side\":\"SELL\", \"hash\":\"8acd14ff9e6d815e758f736a318da299d37e35c4\", \"best_bid\":\"0.42\", \"best_ask\":\"0.43\"}], \"timestamp\":\"1785122444095\", \"event_type\":\"price_change\"}","received_at":"2026-07-27T03:20:43.979739Z","schema_version":"clob-market-ws.price_change.v1","sequence":null,"server_hash":null,"server_timestamp":"1785122444095","session_id":"dd162b8dca5f43ff811d304e69a06123","source":"clob_market_ws"},"received_at":"2026-07-27T03:20:43.979739Z","record_id":"a5db078029f40ac9d7972d5389713ee5c1c45210ab5fb2b821e0acd1d1444bb0","schema_fingerprint":"4aa3821a28b0b7c2400bc59aba4bcc0a76e971dadd19610d3ad38c768e124dc7","schema_version":"edge-lab-recorder.raw.v1","sequence":null,"source":"clob_market_ws"}
{"event_at":"2026-07-27T03:20:44.152000Z","event_fingerprint":"284323f386fdad5cc7fa8fea91084a092e505a5ce8086d37fe218785f84707e6","payload":{"connection_id":"c7dc2e4762f849c6b6f9306b6518dcab","event_at":"2026-07-27T03:20:44.152000Z","event_type":"price_change","frame_hash":"845baa85515e02ef9e892c31e58b6b53af644fc62000ede6bbdf25a538d63139","frame_index":0,"kind":"data","monotonic_ns":224427387988916,"payload":{"event_type":"price_change","market":"0x717c0e8ccd4d5c7040185188fbae28be901ca589a11a94b1b38ca36a79eccfeb","price_changes":[{"asset_id":"24254094493625419915756280046002869097156693848522361803041977572204227262166","best_ask":"0.43","best_bid":"0.42","hash":"178675133a8ae9b178a74df2f4dcce647f68eec0","price":"0.45","side":"SELL","size":"318"},{"asset_id":"41448400836309843603620980831210604935021861034693225347475867885462478926555","best_ask":"0.58","best_bid":"0.57","hash":"4ffbb96be880c49607ca83c5ed7971db64ddb1b0","price":"0.55","side":"BUY","size":"318"}],"timestamp":"1785122444152"},"payload_hash":"388a35b94aea88c78435341706cd97e3b45fd590cfdd8471f2a9f4a40c98ef1a","raw_frame":"{\"market\":\"0x717c0e8ccd4d5c7040185188fbae28be901ca589a11a94b1b38ca36a79eccfeb\", \"price_changes\":[{\"asset_id\":\"24254094493625419915756280046002869097156693848522361803041977572204227262166\", \"price\":\"0.45\", \"size\":\"318\", \"side\":\"SELL\", \"hash\":\"178675133a8ae9b178a74df2f4dcce647f68eec0\", \"best_bid\":\"0.42\", \"best_ask\":\"0.43\"}, {\"asset_id\":\"41448400836309843603620980831210604935021861034693225347475867885462478926555\", \"price\":\"0.55\", \"size\":\"318\", \"side\":\"BUY\", \"hash\":\"4ffbb96be880c49607ca83c5ed7971db64ddb1b0\", \"best_bid\":\"0.57\", \"best_ask\":\"0.58\"}], \"timestamp\":\"1785122444152\", \"event_type\":\"price_change\"}","received_at":"2026-07-27T03:20:44.033653Z","schema_version":"clob-market-ws.price_change.v1","sequence":null,"server_hash":null,"server_timestamp":"1785122444152","session_id":"dd162b8dca5f43ff811d304e69a06123","source":"clob_market_ws"},"received_at":"2026-07-27T03:20:44.033653Z","record_id":"16181dc6620f3f5b6061275ed490bb1c853ecea7cc58c4329bd601777819d40a","schema_fingerprint":"4aa3821a28b0b7c2400bc59aba4bcc0a76e971dadd19610d3ad38c768e124dc7","schema_version":"edge-lab-recorder.raw.v1","sequence":null,"source":"clob_market_ws"}
{"event_at":"2026-07-27T03:20:44.177000Z","event_fingerprint":"730b96e2c928de803f216ef21e67d87092bc2ba41ee57a6a2f97aca756136f85","payload":{"connection_id":"c7dc2e4762f849c6b6f9306b6518dcab","event_at":"2026-07-27T03:20:44.177000Z","event_type":"price_change","frame_hash":"91a4410e571eaaab5170d303c01f769863b37e53aed04a0fd7eb19b9b85ef7ab","frame_index":0,"kind":"data","monotonic_ns":224427411882208,"payload":{"event_type":"price_change","market":"0x717c0e8ccd4d5c7040185188fbae28be901ca589a11a94b1b38ca36a79eccfeb","price_changes":[{"asset_id":"24254094493625419915756280046002869097156693848522361803041977572204227262166","best_ask":"0.43","best_bid":"0.42","hash":"b7e4dfe32cc75ff6590e164bd1d85aba9c996bfa","price":"0.39","side":"BUY","size":"64.4"},{"asset_id":"41448400836309843603620980831210604935021861034693225347475867885462478926555","best_ask":"0.58","best_bid":"0.57","hash":"aef26101b727b18fd2124a43e5741765c601e938","price":"0.61","side":"SELL","size":"64.4"}],"timestamp":"1785122444177"},"payload_hash":"409df88862b07dfec4db5a5235e9b95eb12f8f7b143e1f682fa56f05a35f0ce6","raw_frame":"{\"market\":\"0x717c0e8ccd4d5c7040185188fbae28be901ca589a11a94b1b38ca36a79eccfeb\", \"price_changes\":[{\"asset_id\":\"24254094493625419915756280046002869097156693848522361803041977572204227262166\", \"price\":\"0.39\", \"size\":\"64.4\", \"side\":\"BUY\", \"hash\":\"b7e4dfe32cc75ff6590e164bd1d85aba9c996bfa\", \"best_bid\":\"0.42\", \"best_ask\":\"0.43\"}, {\"asset_id\":\"41448400836309843603620980831210604935021861034693225347475867885462478926555\", \"price\":\"0.61\", \"size\":\"64.4\", \"side\":\"SELL\", \"hash\":\"aef26101b727b18fd2124a43e5741765c601e938\", \"best_bid\":\"0.57\", \"best_ask\":\"0.58\"}], \"timestamp\":\"1785122444177\", \"event_type\":\"price_change\"}","received_at":"2026-07-27T03:20:44.057551Z","schema_version":"clob-market-ws.price_change.v1","sequence":null,"server_hash":null,"server_timestamp":"1785122444177","session_id":"dd162b8dca5f43ff811d304e69a06123","source":"clob_market_ws"},"received_at":"2026-07-27T03:20:44.057551Z","record_id":"6750d9f1891a785d2f930b4b8f8a6d34c7b0d0610cf267e78be4f560796ca166","schema_fingerprint":"4aa3821a28b0b7c2400bc59aba4bcc0a76e971dadd19610d3ad38c768e124dc7","schema_version":"edge-lab-recorder.raw.v1","sequence":null,"source":"clob_market_ws"}
{"event_at":"2026-07-27T03:20:44.177000Z","event_fingerprint":"32bb76d73eb40d7fd4e2670c046ad1a5e3d04b70240299ad354cdcc225f4d358","payload":{"connection_id":"c7dc2e4762f849c6b6f9306b6518dcab","event_at":"2026-07-27T03:20:44.177000Z","event_type":"price_change","frame_hash":"9b798e8fe692c724e2b019d1738a2ceb7fba387cbead97061bd2320409725596","frame_index":0,"kind":"data","monotonic_ns":224427417618250,"payload":{"event_type":"price_change","market":"0x717c0e8ccd4d5c7040185188fbae28be901ca589a11a94b1b38ca36a79eccfeb","price_changes":[{"asset_id":"41448400836309843603620980831210604935021861034693225347475867885462478926555","best_ask":"0.58","best_bid":"0.57","hash":"aef26101b727b18fd2124a43e5741765c601e938","price":"0.51","side":"BUY","size":"147"},{"asset_id":"24254094493625419915756280046002869097156693848522361803041977572204227262166","best_ask":"0.43","best_bid":"0.42","hash":"b7e4dfe32cc75ff6590e164bd1d85aba9c996bfa","price":"0.49","side":"SELL","size":"147"}],"timestamp":"1785122444177"},"payload_hash":"b73a66beeb6039a2e1833c81cfa9b2e3263721822bf5117411632c77810ab6ba","raw_frame":"{\"market\":\"0x717c0e8ccd4d5c7040185188fbae28be901ca589a11a94b1b38ca36a79eccfeb\", \"price_changes\":[{\"asset_id\":\"41448400836309843603620980831210604935021861034693225347475867885462478926555\", \"price\":\"0.51\", \"size\":\"147\", \"side\":\"BUY\", \"hash\":\"aef26101b727b18fd2124a43e5741765c601e938\", \"best_bid\":\"0.57\", \"best_ask\":\"0.58\"}, {\"asset_id\":\"24254094493625419915756280046002869097156693848522361803041977572204227262166\", \"price\":\"0.49\", \"size\":\"147\", \"side\":\"SELL\", \"hash\":\"b7e4dfe32cc75ff6590e164bd1d85aba9c996bfa\", \"best_bid\":\"0.42\", \"best_ask\":\"0.43\"}], \"timestamp\":\"1785122444177\", \"event_type\":\"price_change\"}","received_at":"2026-07-27T03:20:44.063280Z","schema_version":"clob-market-ws.price_change.v1","sequence":null,"server_hash":null,"server_timestamp":"1785122444177","session_id":"dd162b8dca5f43ff811d304e69a06123","source":"clob_market_ws"},"received_at":"2026-07-27T03:20:44.063280Z","record_id":"5bd79428748b95e11365a08fffa2728dfbc3d52d720f808600d77962d06eab37","schema_fingerprint":"4aa3821a28b0b7c2400bc59aba4bcc0a76e971dadd19610d3ad38c768e124dc7","schema_version":"edge-lab-recorder.raw.v1","sequence":null,"source":"clob_market_ws"}
{"event_at":"2026-07-27T03:20:44.178000Z","event_fingerprint":"a9625e4ed72950633b498e5ab2fed21e055b4f1a9ea1152858bcb93a56243c70","payload":{"connection_id":"c7dc2e4762f849c6b6f9306b6518dcab","event_at":"2026-07-27T03:20:44.178000Z","event_type":"price_change","frame_hash":"56be265ef9b3a7381c495768d91d685a806a544ce33b7f285825c01713507452","frame_index":0,"kind":"data","monotonic_ns":224427424347458,"payload":{"event_type":"price_change","market":"0x717c0e8ccd4d5c7040185188fbae28be901ca589a11a94b1b38ca36a79eccfeb","price_changes":[{"asset_id":"41448400836309843603620980831210604935021861034693225347475867885462478926555","best_ask":"0.58","best_bid":"0.57","hash":"a981556a3f7af27e79ad9f4cbc588e8218700a1e","price":"0.04","side":"BUY","size":"578.09"},{"asset_id":"24254094493625419915756280046002869097156693848522361803041977572204227262166","best_ask":"0.43","best_bid":"0.42","hash":"27531946812da3d47c4aaf66c42354b98dc50674","price":"0.96","side":"SELL","size":"578.09"}],"timestamp":"1785122444178"},"payload_hash":"bda4c6dd46d3027f7fdc7eaa275dfbc6bb3edc79e21b1d418c334acf861dc9df","raw_frame":"{\"market\":\"0x717c0e8ccd4d5c7040185188fbae28be901ca589a11a94b1b38ca36a79eccfeb\", \"price_changes\":[{\"asset_id\":\"41448400836309843603620980831210604935021861034693225347475867885462478926555\", \"price\":\"0.04\", \"size\":\"578.09\", \"side\":\"BUY\", \"hash\":\"a981556a3f7af27e79ad9f4cbc588e8218700a1e\", \"best_bid\":\"0.57\", \"best_ask\":\"0.58\"}, {\"asset_id\":\"24254094493625419915756280046002869097156693848522361803041977572204227262166\", \"price\":\"0.96\", \"size\":\"578.09\", \"side\":\"SELL\", \"hash\":\"27531946812da3d47c4aaf66c42354b98dc50674\", \"best_bid\":\"0.42\", \"best_ask\":\"0.43\"}], \"timestamp\":\"1785122444178\", \"event_type\":\"price_change\"}","received_at":"2026-07-27T03:20:44.070008Z","schema_version":"clob-market-ws.price_change.v1","sequence":null,"server_hash":null,"server_timestamp":"1785122444178","session_id":"dd162b8dca5f43ff811d304e69a06123","source":"clob_market_ws"},"received_at":"2026-07-27T03:20:44.070008Z","record_id":"532900afbf30edef21044c1acc303d4bfb0345ddf782b595dcb84531ce730a27","schema_fingerprint":"4aa3821a28b0b7c2400bc59aba4bcc0a76e971dadd19610d3ad38c768e124dc7","schema_version":"edge-lab-recorder.raw.v1","sequence":null,"source":"clob_market_ws"}
{"event_at":"2026-07-27T03:20:44.215000Z","event_fingerprint":"be9bb2ce914c0cb0786fa36047eaefd5fe898960d25df20ed9ada6206ce9c21b","payload":{"connection_id":"c7dc2e4762f849c6b6f9306b6518dcab","event_at":"2026-07-27T03:20:44.215000Z","event_type":"price_change","frame_hash":"2ee055ea10d3f3c3f49ef7aad8df1315bd2e17d804601622903ff5f5189de949","frame_index":0,"kind":"data","monotonic_ns":224427454978750,"payload":{"event_type":"price_change","market":"0x717c0e8ccd4d5c7040185188fbae28be901ca589a11a94b1b38ca36a79eccfeb","price_changes":[{"asset_id":"24254094493625419915756280046002869097156693848522361803041977572204227262166","best_ask":"0.43","best_bid":"0.42","hash":"289c9d77d16c115d6601779c2f4b701d57be0d70","price":"0.39","side":"BUY","size":"44.4"},{"asset_id":"41448400836309843603620980831210604935021861034693225347475867885462478926555","best_ask":"0.58","best_bid":"0.57","hash":"c7d518cad10580d2368f183dfe97e2edddceb0a0","price":"0.61","side":"SELL","size":"44.4"}],"timestamp":"1785122444215"},"payload_hash":"ec909b1e008e580556992e4ae36f2c0a9c39ae477a5d5287907fbf57c8484b3f","raw_frame":"{\"market\":\"0x717c0e8ccd4d5c7040185188fbae28be901ca589a11a94b1b38ca36a79eccfeb\", \"price_changes\":[{\"asset_id\":\"24254094493625419915756280046002869097156693848522361803041977572204227262166\", \"price\":\"0.39\", \"size\":\"44.4\", \"side\":\"BUY\", \"hash\":\"289c9d77d16c115d6601779c2f4b701d57be0d70\", \"best_bid\":\"0.42\", \"best_ask\":\"0.43\"}, {\"asset_id\":\"41448400836309843603620980831210604935021861034693225347475867885462478926555\", \"price\":\"0.61\", \"size\":\"44.4\", \"side\":\"SELL\", \"hash\":\"c7d518cad10580d2368f183dfe97e2edddceb0a0\", \"best_bid\":\"0.57\", \"best_ask\":\"0.58\"}], \"timestamp\":\"1785122444215\", \"event_type\":\"price_change\"}","received_at":"2026-07-27T03:20:44.100641Z","schema_version":"clob-market-ws.price_change.v1","sequence":null,"server_hash":null,"server_timestamp":"1785122444215","session_id":"dd162b8dca5f43ff811d304e69a06123","source":"clob_market_ws"},"received_at":"2026-07-27T03:20:44.100641Z","record_id":"5b53aae0695cd08d20bff7f6775879ef8a90b8b8af64aca377bbf4c047123dde","schema_fingerprint":"4aa3821a28b0b7c2400bc59aba4bcc0a76e971dadd19610d3ad38c768e124dc7","schema_version":"edge-lab-recorder.raw.v1","sequence":null,"source":"clob_market_ws"}
