{"event_at":"2026-07-27T03:15:39.506000Z","event_fingerprint":"8232ba3594e99e979c7bbb9d22ae914cf606220481decf63c5a98a5503b6a709","payload":{"connection_id":"c7dc2e4762f849c6b6f9306b6518dcab","event_at":"2026-07-27T03:15:39.506000Z","event_type":"price_change","frame_hash":"96af09ccf937a6a2a3bd714547f7158e0e132f0452ebfc00c52f086d1804cf36","frame_index":0,"kind":"data","monotonic_ns":224122787262791,"payload":{"event_type":"price_change","market":"0x717c0e8ccd4d5c7040185188fbae28be901ca589a11a94b1b38ca36a79eccfeb","price_changes":[{"asset_id":"24254094493625419915756280046002869097156693848522361803041977572204227262166","best_ask":"0.55","best_bid":"0.54","hash":"ee8994ce5d2d514145fa77fbc6d91e27418b62ca","price":"0.03","side":"BUY","size":"1038.1"},{"asset_id":"41448400836309843603620980831210604935021861034693225347475867885462478926555","best_ask":"0.46","best_bid":"0.45","hash":"9309ebd1c986b9f3b77ed7ecf5f5287271b53ddb","price":"0.97","side":"SELL","size":"1038.1"}],"timestamp":"1785122139506"},"payload_hash":"12fd409a28df637c021e65dc0608645a311b1c7364f3e22668496b32b6561688","raw_frame":"{\"market\":\"0x717c0e8ccd4d5c7040185188fbae28be901ca589a11a94b1b38ca36a79eccfeb\", \"price_changes\":[{\"asset_id\":\"24254094493625419915756280046002869097156693848522361803041977572204227262166\", \"price\":\"0.03\", \"size\":\"1038.1\", \"side\":\"BUY\", \"hash\":\"ee8994ce5d2d514145fa77fbc6d91e27418b62ca\", \"best_bid\":\"0.54\", \"best_ask\":\"0.55\"}, {\"asset_id\":\"41448400836309843603620980831210604935021861034693225347475867885462478926555\", \"price\":\"0.97\", \"size\":\"1038.1\", \"side\":\"SELL\", \"hash\":\"9309ebd1c986b9f3b77ed7ecf5f5287271b53ddb\", \"best_bid\":\"0.45\", \"best_ask\":\"0.46\"}], \"timestamp\":\"1785122139506\", \"event_type\":\"price_change\"}","received_at":"2026-07-27T03:15:39.453045Z","schema_version":"clob-market-ws.price_change.v1","sequence":null,"server_hash":null,"server_timestamp":"1785122139506","session_id":"dd162b8dca5f43ff811d304e69a06123","source":"clob_market_ws"},"received_at":"2026-07-27T03:15:39.453045Z","record_id":"b4c949f9ffb18858502c71521fff1c7201c10b0d6dd8b832506716a5f979d530","schema_fingerprint":"4aa3821a28b0b7c2400bc59aba4bcc0a76e971dadd19610d3ad38c768e124dc7","schema_version":"edge-lab-recorder.raw.v1","sequence":null,"source":"clob_market_ws"}
{"event_at":"2026-07-27T03:15:39.546000Z","event_fingerprint":"a28a6a9739ef329731f0a2fe24c7140d19a8ec324b749a444f9813f946f4820d","payload":{"connection_id":"c7dc2e4762f849c6b6f9306b6518dcab","event_at":"2026-07-27T03:15:39.546000Z","event_type":"price_change","frame_hash":"cb136e170c38df48e267d43225597e1c032c18a1bf96aa35d4818b49a78ea15e","frame_index":0,"kind":"data","monotonic_ns":224122796109791,"payload":{"event_type":"price_change","market":"0x717c0e8ccd4d5c7040185188fbae28be901ca589a11a94b1b38ca36a79eccfeb","price_changes":[{"asset_id":"41448400836309843603620980831210604935021861034693225347475867885462478926555","best_ask":"0.46","best_bid":"0.45","hash":"93b18233a79abccd5718a1ece8752f839db93e4c","price":"0.39","side":"BUY","size":"165.53"},{"asset_id":"24254094493625419915756280046002869097156693848522361803041977572204227262166","best_ask":"0.55","best_bid":"0.54","hash":"fb78a650945981e25ec2dff4d0ecfee333be120a","price":"0.61","side":"SELL","size":"165.53"}],"timestamp":"1785122139546"},"payload_hash":"ec702cecdfcbd1206e5c6b91a049d6194e1836fcee038b8749e8ec96c8a5ccd9","raw_frame":"{\"market\":\"0x717c0e8ccd4d5c7040185188fbae28be901ca589a11a94b1b38ca36a79eccfeb\", \"price_changes\":[{\"asset_id\":\"41448400836309843603620980831210604935021861034693225347475867885462478926555\", \"price\":\"0.39\", \"size\":\"165.53\", \"side\":\"BUY\", \"hash\":\"93b18233a79abccd5718a1ece8752f839db93e4c\", \"best_bid\":\"0.45\", \"best_ask\":\"0.46\"}, {\"asset_id\":\"24254094493625419915756280046002869097156693848522361803041977572204227262166\", \"price\":\"0.61\", \"size\":\"165.53\", \"side\":\"SELL\", \"hash\":\"fb78a650945981e25ec2dff4d0ecfee333be120a\", \"best_bid\":\"0.54\", \"best_ask\":\"0.55\"}], \"timestamp\":\"1785122139546\", \"event_type\":\"price_change\"}","received_at":"2026-07-27T03:15:39.461898Z","schema_version":"clob-market-ws.price_change.v1","sequence":null,"server_hash":null,"server_timestamp":"1785122139546","session_id":"dd162b8dca5f43ff811d304e69a06123","source":"clob_market_ws"},"received_at":"2026-07-27T03:15:39.461898Z","record_id":"0d49beb6e2f560ed9280cc3b6cc511d8d174bb817bc9ce453412f8cd3376fabb","schema_fingerprint":"4aa3821a28b0b7c2400bc59aba4bcc0a76e971dadd19610d3ad38c768e124dc7","schema_version":"edge-lab-recorder.raw.v1","sequence":null,"source":"clob_market_ws"}
{"event_at":"2026-07-27T03:15:39.552000Z","event_fingerprint":"1d227e951eb80f0b417d078c81f1761bd8031973ee15615fdba7d753dab08c66","payload":{"connection_id":"c7dc2e4762f849c6b6f9306b6518dcab","event_at":"2026-07-27T03:15:39.552000Z","event_type":"price_change","frame_hash":"94036d6e3662315ff5c4111c9fcd766a1efc3c7629f070584cdf78619751bad9","frame_index":0,"kind":"data","monotonic_ns":224122798760375,"payload":{"event_type":"price_change","market":"0x717c0e8ccd4d5c7040185188fbae28be901ca589a11a94b1b38ca36a79eccfeb","price_changes":[{"asset_id":"41448400836309843603620980831210604935021861034693225347475867885462478926555","best_ask":"0.46","best_bid":"0.45","hash":"e3170ac8e3bdd97664ad0e2759e0dad1659dacdd","price":"0.4","side":"BUY","size":"133"},{"asset_id":"24254094493625419915756280046002869097156693848522361803041977572204227262166","best_ask":"0.55","best_bid":"0.54","hash":"3ef30329ec6e62361448c6eb98b5a6d4facdd2c2","price":"0.6","side":"SELL","size":"133"}],"timestamp":"1785122139552"},"payload_hash":"725f176aeb75d605c750b2bb0d3d3dfc39b4a318465aa0739d20d8b480a2cdef","raw_frame":"{\"market\":\"0x717c0e8ccd4d5c7040185188fbae28be901ca589a11a94b1b38ca36a79eccfeb\", \"price_changes\":[{\"asset_id\":\"41448400836309843603620980831210604935021861034693225347475867885462478926555\", \"price\":\"0.4\", \"size\":\"133\", \"side\":\"BUY\", \"hash\":\"e3170ac8e3bdd97664ad0e2759e0dad1659dacdd\", \"best_bid\":\"0.45\", \"best_ask\":\"0.46\"}, {\"asset_id\":\"24254094493625419915756280046002869097156693848522361803041977572204227262166\", \"price\":\"0.6\", \"size\":\"133\", \"side\":\"SELL\", \"hash\":\"3ef30329ec6e62361448c6eb98b5a6d4facdd2c2\", \"best_bid\":\"0.54\", \"best_ask\":\"0.55\"}], \"timestamp\":\"1785122139552\", \"event_type\":\"price_change\"}","received_at":"2026-07-27T03:15:39.464542Z","schema_version":"clob-market-ws.price_change.v1","sequence":null,"server_hash":null,"server_timestamp":"1785122139552","session_id":"dd162b8dca5f43ff811d304e69a06123","source":"clob_market_ws"},"received_at":"2026-07-27T03:15:39.464542Z","record_id":"2531f35406ccf7b6cba4b34d26520098785fd069b2a82fc3d683b56882b11ebe","schema_fingerprint":"4aa3821a28b0b7c2400bc59aba4bcc0a76e971dadd19610d3ad38c768e124dc7","schema_version":"edge-lab-recorder.raw.v1","sequence":null,"source":"clob_market_ws"}
{"event_at":"2026-07-27T03:15:39.553000Z","event_fingerprint":"cb8af009f410255382747090e7f6a19c24a150b4e3ac6b8592be1bfecf107bd2","payload":{"connection_id":"c7dc2e4762f849c6b6f9306b6518dcab","event_at":"2026-07-27T03:15:39.553000Z","event_type":"price_change","frame_hash":"7649adb0e7084eee2eaddd9db4463338a4f920d5035caeac30093d24a721b444","frame_index":0,"kind":"data","monotonic_ns":224122804072416,"payload":{"event_type":"price_change","market":"0x717c0e8ccd4d5c7040185188fbae28be901ca589a11a94b1b38ca36a79eccfeb","price_changes":[{"asset_id":"41448400836309843603620980831210604935021861034693225347475867885462478926555","best_ask":"0.46","best_bid":"0.45","hash":"21dd2a7cf8fc248250bdf8f7cede261343000c3c","price":"0.38","side":"BUY","size":"291.69"},{"asset_id":"24254094493625419915756280046002869097156693848522361803041977572204227262166","best_ask":"0.55","best_bid":"0.54","hash":"adf8454412e73e09fc200999014822b2a16b2eca","price":"0.62","side":"SELL","size":"291.69"}],"timestamp":"1785122139553"},"payload_hash":"56555c6dd250486629129c1956387e5e81c1ea97798129857d7ddbb1e75fee67","raw_frame":"{\"market\":\"0x717c0e8ccd4d5c7040185188fbae28be901ca589a11a94b1b38ca36a79eccfeb\", \"price_changes\":[{\"asset_id\":\"41448400836309843603620980831210604935021861034693225347475867885462478926555\", \"price\":\"0.38\", \"size\":\"291.69\", \"side\":\"BUY\", \"hash\":\"21dd2a7cf8fc248250bdf8f7cede261343000c3c\", \"best_bid\":\"0.45\", \"best_ask\":\"0.46\"}, {\"asset_id\":\"24254094493625419915756280046002869097156693848522361803041977572204227262166\", \"price\":\"0.62\", \"size\":\"291.69\", \"side\":\"SELL\", \"hash\":\"adf8454412e73e09fc200999014822b2a16b2eca\", \"best_bid\":\"0.54\", \"best_ask\":\"0.55\"}], \"timestamp\":\"1785122139553\", \"event_type\":\"price_change\"}","received_at":"2026-07-27T03:15:39.469856Z","schema_version":"clob-market-ws.price_change.v1","sequence":null,"server_hash":null,"server_timestamp":"1785122139553","session_id":"dd162b8dca5f43ff811d304e69a06123","source":"clob_market_ws"},"received_at":"2026-07-27T03:15:39.469856Z","record_id":"3edbfa30c26113ac954dd2251277dd5cc6596c3bf4f658c73557681219a18a71","schema_fingerprint":"4aa3821a28b0b7c2400bc59aba4bcc0a76e971dadd19610d3ad38c768e124dc7","schema_version":"edge-lab-recorder.raw.v1","sequence":null,"source":"clob_market_ws"}
{"event_at":"2026-07-27T03:15:39.571000Z","event_fingerprint":"f4d088d17d72890cd52927515a2e51b09de5149230831e3f11f6c6104f548ecb","payload":{"connection_id":"c7dc2e4762f849c6b6f9306b6518dcab","event_at":"2026-07-27T03:15:39.571000Z","event_type":"price_change","frame_hash":"ab9c94fd96183493c253d6e9777ae1532b89fa502fb93fba69a57b0f23235859","frame_index":0,"kind":"data","monotonic_ns":224122808649083,"payload":{"event_type":"price_change","market":"0x717c0e8ccd4d5c7040185188fbae28be901ca589a11a94b1b38ca36a79eccfeb","price_changes":[{"asset_id":"24254094493625419915756280046002869097156693848522361803041977572204227262166","best_ask":"0.55","best_bid":"0.54","hash":"e6d81e43b4df97c971d9e4915b1bde71c565af5d","price":"0.03","side":"BUY","size":"1033.1"},{"asset_id":"41448400836309843603620980831210604935021861034693225347475867885462478926555","best_ask":"0.46","best_bid":"0.45","hash":"10370b40b6ff79406494d812536086e5cf060981","price":"0.97","side":"SELL","size":"1033.1"}],"timestamp":"1785122139571"},"payload_hash":"44d9147f08902a86d01ca9c4ea27fb7a1c60aff35604302c97389ae45750e9c4","raw_frame":"{\"market\":\"0x717c0e8ccd4d5c7040185188fbae28be901ca589a11a94b1b38ca36a79eccfeb\", \"price_changes\":[{\"asset_id\":\"24254094493625419915756280046002869097156693848522361803041977572204227262166\", \"price\":\"0.03\", \"size\":\"1033.1\", \"side\":\"BUY\", \"hash\":\"e6d81e43b4df97c971d9e4915b1bde71c565af5d\", \"best_bid\":\"0.54\", \"best_ask\":\"0.55\"}, {\"asset_id\":\"41448400836309843603620980831210604935021861034693225347475867885462478926555\", \"price\":\"0.97\", \"size\":\"1033.1\", \"side\":\"SELL\", \"hash\":\"10370b40b6ff79406494d812536086e5cf060981\", \"best_bid\":\"0.45\", \"best_ask\":\"0.46\"}], \"timestamp\":\"1785122139571\", \"event_type\":\"price_change\"}","received_at":"2026-07-27T03:15:39.474432Z","schema_version":"clob-market-ws.price_change.v1","sequence":null,"server_hash":null,"server_timestamp":"1785122139571","session_id":"dd162b8dca5f43ff811d304e69a06123","source":"clob_market_ws"},"received_at":"2026-07-27T03:15:39.474432Z","record_id":"09b90059b5a74a4ee834e77b04023925f24678912e358a07daef805a1bf80ed6","schema_fingerprint":"4aa3821a28b0b7c2400bc59aba4bcc0a76e971dadd19610d3ad38c768e124dc7","schema_version":"edge-lab-recorder.raw.v1","sequence":null,"source":"clob_market_ws"}
{"event_at":"2026-07-27T03:15:39.651000Z","event_fingerprint":"7981f98e80d5b8562dee472d77de3fb7fe95972441d0076dcc65fea681cd7f94","payload":{"connection_id":"c7dc2e4762f849c6b6f9306b6518dcab","event_at":"2026-07-27T03:15:39.651000Z","event_type":"price_change","frame_hash":"d358486c5419d4fd3d6ad27deb3fd1802580f8c10103d6897455bf3d52e3bcc7","frame_index":0,"kind":"data","monotonic_ns":224122886971500,"payload":{"event_type":"price_change","market":"0x717c0e8ccd4d5c7040185188fbae28be901ca589a11a94b1b38ca36a79eccfeb","price_changes":[{"asset_id":"24254094493625419915756280046002869097156693848522361803041977572204227262166","best_ask":"0.55","best_bid":"0.54","hash":"18273a1c8680c553cc5d05d911d183cb27edc986","price":"0.01","side":"BUY","size":"7713.02"},{"asset_id":"41448400836309843603620980831210604935021861034693225347475867885462478926555","best_ask":"0.46","best_bid":"0.45","hash":"5db32ef061c1e5fafce568d622f025db7d322fe7","price":"0.99","side":"SELL","size":"7713.02"}],"timestamp":"1785122139651"},"payload_hash":"8ff51399e3341be2f380b8fc4e4630e1a673aa73f371073a8d6c7f66d844efa1","raw_frame":"{\"market\":\"0x717c0e8ccd4d5c7040185188fbae28be901ca589a11a94b1b38ca36a79eccfeb\", \"price_changes\":[{\"asset_id\":\"24254094493625419915756280046002869097156693848522361803041977572204227262166\", \"price\":\"0.01\", \"size\":\"7713.02\", \"side\":\"BUY\", \"hash\":\"18273a1c8680c553cc5d05d911d183cb27edc986\", \"best_bid\":\"0.54\", \"best_ask\":\"0.55\"}, {\"asset_id\":\"41448400836309843603620980831210604935021861034693225347475867885462478926555\", \"price\":\"0.99\", \"size\":\"7713.02\", \"side\":\"SELL\", \"hash\":\"5db32ef061c1e5fafce568d622f025db7d322fe7\", \"best_bid\":\"0.45\", \"best_ask\":\"0.46\"}], \"timestamp\":\"1785122139651\", \"event_type\":\"price_change\"}","received_at":"2026-07-27T03:15:39.552753Z","schema_version":"clob-market-ws.price_change.v1","sequence":null,"server_hash":null,"server_timestamp":"1785122139651","session_id":"dd162b8dca5f43ff811d304e69a06123","source":"clob_market_ws"},"received_at":"2026-07-27T03:15:39.552753Z","record_id":"69838f93c5b801ba29fbe1169e37f1fde6136ee339d0b473c43319c289afe970","schema_fingerprint":"4aa3821a28b0b7c2400bc59aba4bcc0a76e971dadd19610d3ad38c768e124dc7","schema_version":"edge-lab-recorder.raw.v1","sequence":null,"source":"clob_market_ws"}
{"event_at":"2026-07-27T03:15:39.668000Z","event_fingerprint":"7685883fa4a6dc789ec8d144179125b7a4dbd56c191c4f0e793fd54b2accc150","payload":{"connection_id":"c7dc2e4762f849c6b6f9306b6518dcab","event_at":"2026-07-27T03:15:39.668000Z","event_type":"price_change","frame_hash":"19052c22f55b08ea3589f93d6b0374bb0f20b3ffd2f1c53a3e66d67d33cfe5f2","frame_index":0,"kind":"data","monotonic_ns":224122906345916,"payload":{"event_type":"price_change","market":"0x717c0e8ccd4d5c7040185188fbae28be901ca589a11a94b1b38ca36a79eccfeb","price_changes":[{"asset_id":"24254094493625419915756280046002869097156693848522361803041977572204227262166","best_ask":"0.55","best_bid":"0.54","hash":"8dbf135e1db6bbbadf6710252a335adfba44a15d","price":"0.01","side":"BUY","size":"7708.02"},{"asset_id":"41448400836309843603620980831210604935021861034693225347475867885462478926555","best_ask":"0.46","best_bid":"0.45","hash":"0434322fdf72886c51b4825d606f979303c5fa13","price":"0.99","side":"SELL","size":"7708.02"}],"timestamp":"1785122139668"},"payload_hash":"c8f26c8660ae700bf2d38bf7c818b7d468161c3be302bcad3c1da806b866c4a0","raw_frame":"{\"market\":\"0x717c0e8ccd4d5c7040185188fbae28be901ca589a11a94b1b38ca36a79eccfeb\", \"price_changes\":[{\"asset_id\":\"24254094493625419915756280046002869097156693848522361803041977572204227262166\", \"price\":\"0.01\", \"size\":\"7708.02\", \"side\":\"BUY\", \"hash\":\"8dbf135e1db6bbbadf6710252a335adfba44a15d\", \"best_bid\":\"0.54\", \"best_ask\":\"0.55\"}, {\"asset_id\":\"41448400836309843603620980831210604935021861034693225347475867885462478926555\", \"price\":\"0.99\", \"size\":\"7708.02\", \"side\":\"SELL\", \"hash\":\"0434322fdf72886c51b4825d606f979303c5fa13\", \"best_bid\":\"0.45\", \"best_ask\":\"0.46\"}], \"timestamp\":\"1785122139668\", \"event_type\":\"price_change\"}","received_at":"2026-07-27T03:15:39.572128Z","schema_version":"clob-market-ws.price_change.v1","sequence":null,"server_hash":null,"server_timestamp":"1785122139668","session_id":"dd162b8dca5f43ff811d304e69a06123","source":"clob_market_ws"},"received_at":"2026-07-27T03:15:39.572128Z","record_id":"c75b8033212ba526816816b616760ccadaf66791c534587b77250eff3ddeafee","schema_fingerprint":"4aa3821a28b0b7c2400bc59aba4bcc0a76e971dadd19610d3ad38c768e124dc7","schema_version":"edge-lab-recorder.raw.v1","sequence":null,"source":"clob_market_ws"}
{"event_at":"2026-07-27T03:15:39.679000Z","event_fingerprint":"78d414ad36c3701b55057522edfa76054a4a8f76113d0583abcd7919afd457ec","payload":{"connection_id":"c7dc2e4762f849c6b6f9306b6518dcab","event_at":"2026-07-27T03:15:39.679000Z","event_type":"price_change","frame_hash":"75975b017d5183b75dadeae507d39e6f72713943c11b8910d2d92e621f6fd737","frame_index":0,"kind":"data","monotonic_ns":224122919645916,"payload":{"event_type":"price_change","market":"0x717c0e8ccd4d5c7040185188fbae28be901ca589a11a94b1b38ca36a79eccfeb","price_changes":[{"asset_id":"24254094493625419915756280046002869097156693848522361803041977572204227262166","best_ask":"0.55","best_bid":"0.54","hash":"08561d59b9f94b1d88c1bd3738d2fdb5fa5ec4dc","price":"0.01","side":"BUY","size":"7713.02"},{"asset_id":"41448400836309843603620980831210604935021861034693225347475867885462478926555","best_ask":"0.46","best_bid":"0.45","hash":"a165dde85192a24c48014974f1d8ea0d2d9aad77","price":"0.99","side":"SELL","size":"7713.02"}],"timestamp":"1785122139679"},"payload_hash":"ca3edccb74b33b858ba24ea92de2ccd54db2f95b7573971c038b917384909638","raw_frame":"{\"market\":\"0x717c0e8ccd4d5c7040185188fbae28be901ca589a11a94b1b38ca36a79eccfeb\", \"price_changes\":[{\"asset_id\":\"24254094493625419915756280046002869097156693848522361803041977572204227262166\", \"price\":\"0.01\", \"size\":\"7713.02\", \"side\":\"BUY\", \"hash\":\"08561d59b9f94b1d88c1bd3738d2fdb5fa5ec4dc\", \"best_bid\":\"0.54\", \"best_ask\":\"0.55\"}, {\"asset_id\":\"41448400836309843603620980831210604935021861034693225347475867885462478926555\", \"price\":\"0.99\", \"size\":\"7713.02\", \"side\":\"SELL\", \"hash\":\"a165dde85192a24c48014974f1d8ea0d2d9aad77\", \"best_bid\":\"0.45\", \"best_ask\":\"0.46\"}], \"timestamp\":\"1785122139679\", \"event_type\":\"price_change\"}","received_at":"2026-07-27T03:15:39.585427Z","schema_version":"clob-market-ws.price_change.v1","sequence":null,"server_hash":null,"server_timestamp":"1785122139679","session_id":"dd162b8dca5f43ff811d304e69a06123","source":"clob_market_ws"},"received_at":"2026-07-27T03:15:39.585427Z","record_id":"33ed85f56afb1cc56c7d12bbc2b455a9e2ae0b7177c4a512e764f30ad48e54dc","schema_fingerprint":"4aa3821a28b0b7c2400bc59aba4bcc0a76e971dadd19610d3ad38c768e124dc7","schema_version":"edge-lab-recorder.raw.v1","sequence":null,"source":"clob_market_ws"}
{"event_at":"2026-07-27T03:15:39.724000Z","event_fingerprint":"b3d14194593932148ca1c2d760c857e26d635f1e6f91b109dc07d204c8fcb050","payload":{"connection_id":"c7dc2e4762f849c6b6f9306b6518dcab","event_at":"2026-07-27T03:15:39.724000Z","event_type":"price_change","frame_hash":"1dfaade6744be03b7f431f7ec3fa9f8e7d8c04a83babdcbe14cb439abe88de07","frame_index":0,"kind":"data","monotonic_ns":224122961483583,"payload":{"event_type":"price_change","market":"0x717c0e8ccd4d5c7040185188fbae28be901ca589a11a94b1b38ca36a79eccfeb","price_changes":[{"asset_id":"41448400836309843603620980831210604935021861034693225347475867885462478926555","best_ask":"0.46","best_bid":"0.45","hash":"72ee390ca148790d8004136d81a8234df34a1dee","price":"0.4","side":"BUY","size":"128"},{"asset_id":"24254094493625419915756280046002869097156693848522361803041977572204227262166","best_ask":"0.55","best_bid":"0.54","hash":"c5a998e857bc54a3bbe727b7ee923b26ffaa2906","price":"0.6","side":"SELL","size":"128"}],"timestamp":"1785122139724"},"payload_hash":"bb56f6d161e03ba32e178dd2f18f72265d3b217d91d808908f697743d429836b","raw_frame":"{\"market\":\"0x717c0e8ccd4d5c7040185188fbae28be901ca589a11a94b1b38ca36a79eccfeb\", \"price_changes\":[{\"asset_id\":\"41448400836309843603620980831210604935021861034693225347475867885462478926555\", \"price\":\"0.4\", \"size\":\"128\", \"side\":\"BUY\", \"hash\":\"72ee390ca148790d8004136d81a8234df34a1dee\", \"best_bid\":\"0.45\", \"best_ask\":\"0.46\"}, {\"asset_id\":\"24254094493625419915756280046002869097156693848522361803041977572204227262166\", \"price\":\"0.6\", \"size\":\"128\", \"side\":\"SELL\", \"hash\":\"c5a998e857bc54a3bbe727b7ee923b26ffaa2906\", \"best_bid\":\"0.54\", \"best_ask\":\"0.55\"}], \"timestamp\":\"1785122139724\", \"event_type\":\"price_change\"}","received_at":"2026-07-27T03:15:39.627262Z","schema_version":"clob-market-ws.price_change.v1","sequence":null,"server_hash":null,"server_timestamp":"1785122139724","session_id":"dd162b8dca5f43ff811d304e69a06123","source":"clob_market_ws"},"received_at":"2026-07-27T03:15:39.627262Z","record_id":"c0a86ae42f3bab9f4012fa6ef5add308bebb91186087f987d07d88a1b4b516d3","schema_fingerprint":"4aa3821a28b0b7c2400bc59aba4bcc0a76e971dadd19610d3ad38c768e124dc7","schema_version":"edge-lab-recorder.raw.v1","sequence":null,"source":"clob_market_ws"}
{"event_at":"2026-07-27T03:15:39.727000Z","event_fingerprint":"9edae14d05cbce41804510330882a68fb48b66a9a12c198637d47da48f267f38","payload":{"connection_id":"c7dc2e4762f849c6b6f9306b6518dcab","event_at":"2026-07-27T03:15:39.727000Z","event_type":"price_change","frame_hash":"8dbeef3119f9e03229fb57624a60e8ba01e885bee9c343eecff69c12a1202f78","frame_index":0,"kind":"data","monotonic_ns":224122964637583,"payload":{"event_type":"price_change","market":"0x717c0e8ccd4d5c7040185188fbae28be901ca589a11a94b1b38ca36a79eccfeb","price_changes":[{"asset_id":"41448400836309843603620980831210604935021861034693225347475867885462478926555","best_ask":"0.46","best_bid":"0.45","hash":"3da35aa11494ca89a9ee3a267e3a7f7a8cb652f5","price":"0.38","side":"BUY","size":"286.69"},{"asset_id":"24254094493625419915756280046002869097156693848522361803041977572204227262166","best_ask":"0.55","best_bid":"0.54","hash":"7365b649d674b7bdd60b891b71e203e957bfd460","price":"0.62","side":"SELL","size":"286.69"}],"timestamp":"1785122139727"},"payload_hash":"4abfef1c8c50b02aeee1ab59878a2a909fac2052dddddcd80b41c6007e82a29e","raw_frame":"{\"market\":\"0x717c0e8ccd4d5c7040185188fbae28be901ca589a11a94b1b38ca36a79eccfeb\", \"price_changes\":[{\"asset_id\":\"41448400836309843603620980831210604935021861034693225347475867885462478926555\", \"price\":\"0.38\", \"size\":\"286.69\", \"side\":\"BUY\", \"hash\":\"3da35aa11494ca89a9ee3a267e3a7f7a8cb652f5\", \"best_bid\":\"0.45\", \"best_ask\":\"0.46\"}, {\"asset_id\":\"24254094493625419915756280046002869097156693848522361803041977572204227262166\", \"price\":\"0.62\", \"size\":\"286.69\", \"side\":\"SELL\", \"hash\":\"7365b649d674b7bdd60b891b71e203e957bfd460\", \"best_bid\":\"0.54\", \"best_ask\":\"0.55\"}], \"timestamp\":\"1785122139727\", \"event_type\":\"price_change\"}","received_at":"2026-07-27T03:15:39.630418Z","schema_version":"clob-market-ws.price_change.v1","sequence":null,"server_hash":null,"server_timestamp":"1785122139727","session_id":"dd162b8dca5f43ff811d304e69a06123","source":"clob_market_ws"},"received_at":"2026-07-27T03:15:39.630418Z","record_id":"51911bc0c21707ee0071b2d2a19aad595a371e81a2efbcf1d6fd1323261b67b0","schema_fingerprint":"4aa3821a28b0b7c2400bc59aba4bcc0a76e971dadd19610d3ad38c768e124dc7","schema_version":"edge-lab-recorder.raw.v1","sequence":null,"source":"clob_market_ws"}
{"event_at":"2026-07-27T03:15:39.730000Z","event_fingerprint":"c04e820c84c7654b041ce483cfc59366e343d41e7c3abfc99165bc936cb3f495","payload":{"connection_id":"c7dc2e4762f849c6b6f9306b6518dcab","event_at":"2026-07-27T03:15:39.730000Z","event_type":"price_change","frame_hash":"f250103c96c5165b18921f819c8d2ff8b7df0db3c8866b417397e9c4dec2fe8d","frame_index":0,"kind":"data","monotonic_ns":224122970112416,"payload":{"event_type":"price_change","market":"0x717c0e8ccd4d5c7040185188fbae28be901ca589a11a94b1b38ca36a79eccfeb","price_changes":[{"asset_id":"41448400836309843603620980831210604935021861034693225347475867885462478926555","best_ask":"0.46","best_bid":"0.45","hash":"a52aa78f6120c005b5e9981e888f10f9f7f1fc43","price":"0.39","side":"BUY","size":"171.53"},{"asset_id":"24254094493625419915756280046002869097156693848522361803041977572204227262166","best_ask":"0.55","best_bid":"0.54","hash":"ce25fa887c3cb357bae01fd6e5a53bbea40010a2","price":"0.61","side":"SELL","size":"171.53"}],"timestamp":"1785122139730"},"payload_hash":"1e1b2ccb0ebe2990579830df811c0c09b06261246347c1e770fb057f48cf13b9","raw_frame":"{\"market\":\"0x717c0e8ccd4d5c7040185188fbae28be901ca589a11a94b1b38ca36a79eccfeb\", \"price_changes\":[{\"asset_id\":\"41448400836309843603620980831210604935021861034693225347475867885462478926555\", \"price\":\"0.39\", \"size\":\"171.53\", \"side\":\"BUY\", \"hash\":\"a52aa78f6120c005b5e9981e888f10f9f7f1fc43\", \"best_bid\":\"0.45\", \"best_ask\":\"0.46\"}, {\"asset_id\":\"24254094493625419915756280046002869097156693848522361803041977572204227262166\", \"price\":\"0.61\", \"size\":\"171.53\", \"side\":\"SELL\", \"hash\":\"ce25fa887c3cb357bae01fd6e5a53bbea40010a2\", \"best_bid\":\"0.54\", \"best_ask\":\"0.55\"}], \"timestamp\":\"1785122139730\", \"event_type\":\"price_change\"}","received_at":"2026-07-27T03:15:39.635893Z","schema_version":"clob-market-ws.price_change.v1","sequence":null,"server_hash":null,"server_timestamp":"1785122139730","session_id":"dd162b8dca5f43ff811d304e69a06123","source":"clob_market_ws"},"received_at":"2026-07-27T03:15:39.635893Z","record_id":"a2e697a054dfbcc6d7226b31489fc69fd9cd11d11a3d5c35b9c459052141cc7b","schema_fingerprint":"4aa3821a28b0b7c2400bc59aba4bcc0a76e971dadd19610d3ad38c768e124dc7","schema_version":"edge-lab-recorder.raw.v1","sequence":null,"source":"clob_market_ws"}
{"event_at":"2026-07-27T03:15:39.731000Z","event_fingerprint":"49841657ed3f20065a853347d97493a650900fa2fd40527fd97674338e0e1610","payload":{"connection_id":"c7dc2e4762f849c6b6f9306b6518dcab","event_at":"2026-07-27T03:15:39.731000Z","event_type":"price_change","frame_hash":"e5874f30aec360e2b40d77aa9470deed6976b3c3f914e0ade2f153916bf1cba2","frame_index":0,"kind":"data","monotonic_ns":224122975340958,"payload":{"event_type":"price_change","market":"0x717c0e8ccd4d5c7040185188fbae28be901ca589a11a94b1b38ca36a79eccfeb","price_changes":[{"asset_id":"41448400836309843603620980831210604935021861034693225347475867885462478926555","best_ask":"0.46","best_bid":"0.45","hash":"af857e5036aae05d843022c6cfdba83748ca0af2","price":"0.28","side":"BUY","size":"20.9"},{"asset_id":"24254094493625419915756280046002869097156693848522361803041977572204227262166","best_ask":"0.55","best_bid":"0.54","hash":"242b7a6cce04ccd93364ec43f60c194e37a959e0","price":"0.72","side":"SELL","size":"20.9"}],"timestamp":"1785122139731"},"payload_hash":"83e15fc2f6de770898fe7ca5612c18c2a86f3ef74885d5889a70943a6354964e","raw_frame":"{\"market\":\"0x717c0e8ccd4d5c7040185188fbae28be901ca589a11a94b1b38ca36a79eccfeb\", \"price_changes\":[{\"asset_id\":\"41448400836309843603620980831210604935021861034693225347475867885462478926555\", \"price\":\"0.28\", \"size\":\"20.9\", \"side\":\"BUY\", \"hash\":\"af857e5036aae05d843022c6cfdba83748ca0af2\", \"best_bid\":\"0.45\", \"best_ask\":\"0.46\"}, {\"asset_id\":\"24254094493625419915756280046002869097156693848522361803041977572204227262166\", \"price\":\"0.72\", \"size\":\"20.9\", \"side\":\"SELL\", \"hash\":\"242b7a6cce04ccd93364ec43f60c194e37a959e0\", \"best_bid\":\"0.54\", \"best_ask\":\"0.55\"}], \"timestamp\":\"1785122139731\", \"event_type\":\"price_change\"}","received_at":"2026-07-27T03:15:39.641121Z","schema_version":"clob-market-ws.price_change.v1","sequence":null,"server_hash":null,"server_timestamp":"1785122139731","session_id":"dd162b8dca5f43ff811d304e69a06123","source":"clob_market_ws"},"received_at":"2026-07-27T03:15:39.641121Z","record_id":"bf8432940fddf4c5129a04f1fc24866cde6a2e85bbcf2f43b7beda69cb420d4e","schema_fingerprint":"4aa3821a28b0b7c2400bc59aba4bcc0a76e971dadd19610d3ad38c768e124dc7","schema_version":"edge-lab-recorder.raw.v1","sequence":null,"source":"clob_market_ws"}
{"event_at":"2026-07-27T03:15:39.752000Z","event_fingerprint":"f6ee6e315142e5881d7726160a74c738e538ea56e7ce60dd55fbe21e1af10b19","payload":{"connection_id":"c7dc2e4762f849c6b6f9306b6518dcab","event_at":"2026-07-27T03:15:39.752000Z","event_type":"price_change","frame_hash":"b19a246544d5d4501fc2e34a477e9fb7edb300305e69b3e1b88506fa18e80164","frame_index":0,"kind":"data","monotonic_ns":224122988734250,"payload":{"event_type":"price_change","market":"0x717c0e8ccd4d5c7040185188fbae28be901ca589a11a94b1b38ca36a79eccfeb","price_changes":[{"asset_id":"24254094493625419915756280046002869097156693848522361803041977572204227262166","best_ask":"0.55","best_bid":"0.54","hash":"997cb1b822253274e9b5002749ad184bbd675530","price":"0.01","side":"BUY","size":"7708.02"},{"asset_id":"41448400836309843603620980831210604935021861034693225347475867885462478926555","best_ask":"0.46","best_bid":"0.45","hash":"05723c6a05549d986ef58ac4939df97e01d674ff","price":"0.99","side":"SELL","size":"7708.02"}],"timestamp":"1785122139752"},"payload_hash":"6a27eb9383603b0fc25bf8d298e31e50412f75127591ffca3c039db3cdfb881f","raw_frame":"{\"market\":\"0x717c0e8ccd4d5c7040185188fbae28be901ca589a11a94b1b38ca36a79eccfeb\", \"price_changes\":[{\"asset_id\":\"24254094493625419915756280046002869097156693848522361803041977572204227262166\", \"price\":\"0.01\", \"size\":\"7708.02\", \"side\":\"BUY\", \"hash\":\"997cb1b822253274e9b5002749ad184bbd675530\", \"best_bid\":\"0.54\", \"best_ask\":\"0.55\"}, {\"asset_id\":\"41448400836309843603620980831210604935021861034693225347475867885462478926555\", \"price\":\"0.99\", \"size\":\"7708.02\", \"side\":\"SELL\", \"hash\":\"05723c6a05549d986ef58ac4939df97e01d674ff\", \"best_bid\":\"0.45\", \"best_ask\":\"0.46\"}], \"timestamp\":\"1785122139752\", \"event_type\":\"price_change\"}","received_at":"2026-07-27T03:15:39.654514Z","schema_version":"clob-market-ws.price_change.v1","sequence":null,"server_hash":null,"server_timestamp":"1785122139752","session_id":"dd162b8dca5f43ff811d304e69a06123","source":"clob_market_ws"},"received_at":"2026-07-27T03:15:39.654514Z","record_id":"afd7605be3c52143d8a3aa94e3e11694db40408c353345c93d07eb23b0fe8244","schema_fingerprint":"4aa3821a28b0b7c2400bc59aba4bcc0a76e971dadd19610d3ad38c768e124dc7","schema_version":"edge-lab-recorder.raw.v1","sequence":null,"source":"clob_market_ws"}
{"event_at":"2026-07-27T03:15:39.757000Z","event_fingerprint":"c49d0c2e984499bfc59b6e474599019c25b87b206fed95cf1f90cc41b5c248e9","payload":{"connection_id":"c7dc2e4762f849c6b6f9306b6518dcab","event_at":"2026-07-27T03:15:39.757000Z","event_type":"price_change","frame_hash":"06003ba7b1162b941698a41bf5c4e47d7f032502a648e3ca554a3c805c1b2176","frame_index":0,"kind":"data","monotonic_ns":224122992475583,"payload":{"event_type":"price_change","market":"0x717c0e8ccd4d5c7040185188fbae28be901ca589a11a94b1b38ca36a79eccfeb","price_changes":[{"asset_id":"24254094493625419915756280046002869097156693848522361803041977572204227262166","best_ask":"0.55","best_bid":"0.54","hash":"28054f22461fbd27e8baf3c630128b61b408cb3e","price":"0.01","side":"BUY","size":"7713.02"},{"asset_id":"41448400836309843603620980831210604935021861034693225347475867885462478926555","best_ask":"0.46","best_bid":"0.45","hash":"6654093875e95e2a8f125912c7c05f93002c4756","price":"0.99","side":"SELL","size":"7713.02"}],"timestamp":"1785122139757"},"payload_hash":"782a0aaac19e43b2ae7bfb2cb7dab7db7c021b41ed9af0944c86d38f5d4fdbc5","raw_frame":"{\"market\":\"0x717c0e8ccd4d5c7040185188fbae28be901ca589a11a94b1b38ca36a79eccfeb\", \"price_changes\":[{\"asset_id\":\"24254094493625419915756280046002869097156693848522361803041977572204227262166\", \"price\":\"0.01\", \"size\":\"7713.02\", \"side\":\"BUY\", \"hash\":\"28054f22461fbd27e8baf3c630128b61b408cb3e\", \"best_bid\":\"0.54\", \"best_ask\":\"0.55\"}, {\"asset_id\":\"41448400836309843603620980831210604935021861034693225347475867885462478926555\", \"price\":\"0.99\", \"size\":\"7713.02\", \"side\":\"SELL\", \"hash\":\"6654093875e95e2a8f125912c7c05f93002c4756\", \"best_bid\":\"0.45\", \"best_ask\":\"0.46\"}], \"timestamp\":\"1785122139757\", \"event_type\":\"price_change\"}","received_at":"2026-07-27T03:15:39.658256Z","schema_version":"clob-market-ws.price_change.v1","sequence":null,"server_hash":null,"server_timestamp":"1785122139757","session_id":"dd162b8dca5f43ff811d304e69a06123","source":"clob_market_ws"},"received_at":"2026-07-27T03:15:39.658256Z","record_id":"ee5eafb89dd8bde1082d04dd5ce5d9f8e6bea48695354bb689eb895ebc9dd26c","schema_fingerprint":"4aa3821a28b0b7c2400bc59aba4bcc0a76e971dadd19610d3ad38c768e124dc7","schema_version":"edge-lab-recorder.raw.v1","sequence":null,"source":"clob_market_ws"}
{"event_at":"2026-07-27T03:15:39.778000Z","event_fingerprint":"8eee76eaa3eff3f61e9d4b3eff1ad234a2abaaa62929b751a5bb2f836b09a7f8","payload":{"connection_id":"c7dc2e4762f849c6b6f9306b6518dcab","event_at":"2026-07-27T03:15:39.778000Z","event_type":"price_change","frame_hash":"6ff09f59211ee4cc385763d25271d02f7f44ac9a757f0ce7f8af918b8fb9e265","frame_index":0,"kind":"data","monotonic_ns":224123014474625,"payload":{"event_type":"price_change","market":"0x717c0e8ccd4d5c7040185188fbae28be901ca589a11a94b1b38ca36a79eccfeb","price_changes":[{"asset_id":"24254094493625419915756280046002869097156693848522361803041977572204227262166","best_ask":"0.55","best_bid":"0.54","hash":"974056a967af461d3e59a75842da296b8914440d","price":"0.01","side":"BUY","size":"7708.02"},{"asset_id":"41448400836309843603620980831210604935021861034693225347475867885462478926555","best_ask":"0.46","best_bid":"0.45","hash":"3f65f3f9ddeb0c9b5721c143f9035c6233a071fa","price":"0.99","side":"SELL","size":"7708.02"}],"timestamp":"1785122139778"},"payload_hash":"e14816f80e26f4fd337a55432e5645255755a2503a275e933e31482ee4fe6b7d","raw_frame":"{\"market\":\"0x717c0e8ccd4d5c7040185188fbae28be901ca589a11a94b1b38ca36a79eccfeb\", \"price_changes\":[{\"asset_id\":\"24254094493625419915756280046002869097156693848522361803041977572204227262166\", \"price\":\"0.01\", \"size\":\"7708.02\", \"side\":\"BUY\", \"hash\":\"974056a967af461d3e59a75842da296b8914440d\", \"best_bid\":\"0.54\", \"best_ask\":\"0.55\"}, {\"asset_id\":\"41448400836309843603620980831210604935021861034693225347475867885462478926555\", \"price\":\"0.99\", \"size\":\"7708.02\", \"side\":\"SELL\", \"hash\":\"3f65f3f9ddeb0c9b5721c143f9035c6233a071fa\", \"best_bid\":\"0.45\", \"best_ask\":\"0.46\"}], \"timestamp\":\"1785122139778\", \"event_type\":\"price_change\"}","received_at":"2026-07-27T03:15:39.680253Z","schema_version":"clob-market-ws.price_change.v1","sequence":null,"server_hash":null,"server_timestamp":"1785122139778","session_id":"dd162b8dca5f43ff811d304e69a06123","source":"clob_market_ws"},"received_at":"2026-07-27T03:15:39.680253Z","record_id":"7297535c4985daa21be39c2773e2239d7bed02571dab35fcd5e6c5a9acf9aee1","schema_fingerprint":"4aa3821a28b0b7c2400bc59aba4bcc0a76e971dadd19610d3ad38c768e124dc7","schema_version":"edge-lab-recorder.raw.v1","sequence":null,"source":"clob_market_ws"}
{"event_at":"2026-07-27T03:15:39.864000Z","event_fingerprint":"c5c8a794821cfe5ea7cd31e654bff74b4c8b3073f60899193d6252218c0c3a86","payload":{"connection_id":"c7dc2e4762f849c6b6f9306b6518dcab","event_at":"2026-07-27T03:15:39.864000Z","event_type":"price_change","frame_hash":"b2b8667b799c928e7ea1ddeafff05f3193c8d23a975d8438853a73ed9cd63a15","frame_index":0,"kind":"data","monotonic_ns":224123100272583,"payload":{"event_type":"price_change","market":"0x717c0e8ccd4d5c7040185188fbae28be901ca589a11a94b1b38ca36a79eccfeb","price_changes":[{"asset_id":"24254094493625419915756280046002869097156693848522361803041977572204227262166","best_ask":"0.55","best_bid":"0.54","hash":"ed4b3b79460cd81c5a3e6bbb5198c184f679b1e1","price":"0.49","side":"BUY","size":"100"},{"asset_id":"41448400836309843603620980831210604935021861034693225347475867885462478926555","best_ask":"0.46","best_bid":"0.45","hash":"8c20affa8de70babf2fe6bb869015b65cdf17b8e","price":"0.51","side":"SELL","size":"100"}],"timestamp":"1785122139864"},"payload_hash":"7a93054eecfc8a62abe8dcc26c9947528bd002c224f5c491bb6c6573762a0f3d","raw_frame":"{\"market\":\"0x717c0e8ccd4d5c7040185188fbae28be901ca589a11a94b1b38ca36a79eccfeb\", \"price_changes\":[{\"asset_id\":\"24254094493625419915756280046002869097156693848522361803041977572204227262166\", \"price\":\"0.49\", \"size\":\"100\", \"side\":\"BUY\", \"hash\":\"ed4b3b79460cd81c5a3e6bbb5198c184f679b1e1\", \"best_bid\":\"0.54\", \"best_ask\":\"0.55\"}, {\"asset_id\":\"41448400836309843603620980831210604935021861034693225347475867885462478926555\", \"price\":\"0.51\", \"size\":\"100\", \"side\":\"SELL\", \"hash\":\"8c20affa8de70babf2fe6bb869015b65cdf17b8e\", \"best_bid\":\"0.45\", \"best_ask\":\"0.46\"}], \"timestamp\":\"1785122139864\", \"event_type\":\"price_change\"}","received_at":"2026-07-27T03:15:39.766051Z","schema_version":"clob-market-ws.price_change.v1","sequence":null,"server_hash":null,"server_timestamp":"1785122139864","session_id":"dd162b8dca5f43ff811d304e69a06123","source":"clob_market_ws"},"received_at":"2026-07-27T03:15:39.766051Z","record_id":"a6acb7bef5b5196c5a2df7e154d646430766c586ae2e3eefda9d16430463b156","schema_fingerprint":"4aa3821a28b0b7c2400bc59aba4bcc0a76e971dadd19610d3ad38c768e124dc7","schema_version":"edge-lab-recorder.raw.v1","sequence":null,"source":"clob_market_ws"}
{"event_at":"2026-07-27T03:15:39.867000Z","event_fingerprint":"2e81e3097d28fb7b2c4f048440e72e2d993f2d4c71d37c5b6e3e124479a5e668","payload":{"connection_id":"c7dc2e4762f849c6b6f9306b6518dcab","event_at":"2026-07-27T03:15:39.867000Z","event_type":"price_change","frame_hash":"28b80950ebad6ed0f56f44951583216e6f9cd173fde163610f74e2372795e312","frame_index":0,"kind":"data","monotonic_ns":224123104176625,"payload":{"event_type":"price_change","market":"0x717c0e8ccd4d5c7040185188fbae28be901ca589a11a94b1b38ca36a79eccfeb","price_changes":[{"asset_id":"41448400836309843603620980831210604935021861034693225347475867885462478926555","best_ask":"0.46","best_bid":"0.45","hash":"7d7cfb5015e51f60d861350e299f350a8aa2b3ab","price":"0.37","side":"BUY","size":"131.74"},{"asset_id":"24254094493625419915756280046002869097156693848522361803041977572204227262166","best_ask":"0.55","best_bid":"0.54","hash":"040d321d79687d749b2b6cff2945c3a12f17eb6d","price":"0.63","side":"SELL","size":"131.74"}],"timestamp":"1785122139867"},"payload_hash":"78129e785eb2a5a4bd2c5e0234ed0373d3c2804b272bc6e60b1507d5e1cee704","raw_frame":"{\"market\":\"0x717c0e8ccd4d5c7040185188fbae28be901ca589a11a94b1b38ca36a79eccfeb\", \"price_changes\":[{\"asset_id\":\"41448400836309843603620980831210604935021861034693225347475867885462478926555\", \"price\":\"0.37\", \"size\":\"131.74\", \"side\":\"BUY\", \"hash\":\"7d7cfb5015e51f60d861350e299f350a8aa2b3ab\", \"best_bid\":\"0.45\", \"best_ask\":\"0.46\"}, {\"asset_id\":\"24254094493625419915756280046002869097156693848522361803041977572204227262166\", \"price\":\"0.63\", \"size\":\"131.74\", \"side\":\"SELL\", \"hash\":\"040d321d79687d749b2b6cff2945c3a12f17eb6d\", \"best_bid\":\"0.54\", \"best_ask\":\"0.55\"}], \"timestamp\":\"1785122139867\", \"event_type\":\"price_change\"}","received_at":"2026-07-27T03:15:39.769955Z","schema_version":"clob-market-ws.price_change.v1","sequence":null,"server_hash":null,"server_timestamp":"1785122139867","session_id":"dd162b8dca5f43ff811d304e69a06123","source":"clob_market_ws"},"received_at":"2026-07-27T03:15:39.769955Z","record_id":"7dd07a553917e86ef01826f82f024b5c1b597ff3b9ac34f659d4c293cfe3da17","schema_fingerprint":"4aa3821a28b0b7c2400bc59aba4bcc0a76e971dadd19610d3ad38c768e124dc7","schema_version":"edge-lab-recorder.raw.v1","sequence":null,"source":"clob_market_ws"}
{"event_at":"2026-07-27T03:15:39.868000Z","event_fingerprint":"86a1c3c3262e2a4fa9417e6b118980d1dd7f987e670b6443242319f6bf6d2d56","payload":{"connection_id":"c7dc2e4762f849c6b6f9306b6518dcab","event_at":"2026-07-27T03:15:39.868000Z","event_type":"price_change","frame_hash":"88c315eeeca318327542550e0df2fbe88d39e63c64482c8c592e7609b5d68465","frame_index":0,"kind":"data","monotonic_ns":224123107900750,"payload":{"event_type":"price_change","market":"0x717c0e8ccd4d5c7040185188fbae28be901ca589a11a94b1b38ca36a79eccfeb","price_changes":[{"asset_id":"24254094493625419915756280046002869097156693848522361803041977572204227262166","best_ask":"0.55","best_bid":"0.54","hash":"f410b4a8697f241c809afdca75549bbfd885882a","price":"0.5","side":"BUY","size":"20"},{"asset_id":"41448400836309843603620980831210604935021861034693225347475867885462478926555","best_ask":"0.46","best_bid":"0.45","hash":"b86091e921d82c8ccbc9153e14862cdbc3fb1a64","price":"0.5","side":"SELL","size":"20"}],"timestamp":"1785122139868"},"payload_hash":"c562059a3f55f62db3e56f03c35015ab210fcd56b529ead7d1ae92cdac83fa90","raw_frame":"{\"market\":\"0x717c0e8ccd4d5c7040185188fbae28be901ca589a11a94b1b38ca36a79eccfeb\", \"price_changes\":[{\"asset_id\":\"24254094493625419915756280046002869097156693848522361803041977572204227262166\", \"price\":\"0.5\", \"size\":\"20\", \"side\":\"BUY\", \"hash\":\"f410b4a8697f241c809afdca75549bbfd885882a\", \"best_bid\":\"0.54\", \"best_ask\":\"0.55\"}, {\"asset_id\":\"41448400836309843603620980831210604935021861034693225347475867885462478926555\", \"price\":\"0.5\", \"size\":\"20\", \"side\":\"SELL\", \"hash\":\"b86091e921d82c8ccbc9153e14862cdbc3fb1a64\", \"best_bid\":\"0.45\", \"best_ask\":\"0.46\"}], \"timestamp\":\"1785122139868\", \"event_type\":\"price_change\"}","received_at":"2026-07-27T03:15:39.773678Z","schema_version":"clob-market-ws.price_change.v1","sequence":null,"server_hash":null,"server_timestamp":"1785122139868","session_id":"dd162b8dca5f43ff811d304e69a06123","source":"clob_market_ws"},"received_at":"2026-07-27T03:15:39.773678Z","record_id":"5d4fe34e3e874ce5c0873aa39d09649f5976e0b4aef27ef726304b0a9b7c2a15","schema_fingerprint":"4aa3821a28b0b7c2400bc59aba4bcc0a76e971dadd19610d3ad38c768e124dc7","schema_version":"edge-lab-recorder.raw.v1","sequence":null,"source":"clob_market_ws"}
{"event_at":"2026-07-27T03:15:39.870000Z","event_fingerprint":"afb7259a26bea1c453a572c39eec555a953f029acbd450c054f4917474d51581","payload":{"connection_id":"c7dc2e4762f849c6b6f9306b6518dcab","event_at":"2026-07-27T03:15:39.870000Z","event_type":"price_change","frame_hash":"fa2d4faabcc7138d8ad55caa166717f01fb689255bde4d2a21cbc6cf18e2a614","frame_index":0,"kind":"data","monotonic_ns":224123112981875,"payload":{"event_type":"price_change","market":"0x717c0e8ccd4d5c7040185188fbae28be901ca589a11a94b1b38ca36a79eccfeb","price_changes":[{"asset_id":"24254094493625419915756280046002869097156693848522361803041977572204227262166","best_ask":"0.55","best_bid":"0.54","hash":"6060d64f5da4160d5d336700618a82ca310d1403","price":"0.47","side":"BUY","size":"127"},{"asset_id":"41448400836309843603620980831210604935021861034693225347475867885462478926555","best_ask":"0.46","best_bid":"0.45","hash":"bb8bf55939e4785b6d6bb6d09b766f5e85e032b4","price":"0.53","side":"SELL","size":"127"}],"timestamp":"1785122139870"},"payload_hash":"69a3e0bc09db9685a75371f6e9e648d34a3a58c4b559f7287fd332ef076d0e42","raw_frame":"{\"market\":\"0x717c0e8ccd4d5c7040185188fbae28be901ca589a11a94b1b38ca36a79eccfeb\", \"price_changes\":[{\"asset_id\":\"24254094493625419915756280046002869097156693848522361803041977572204227262166\", \"price\":\"0.47\", \"size\":\"127\", \"side\":\"BUY\", \"hash\":\"6060d64f5da4160d5d336700618a82ca310d1403\", \"best_bid\":\"0.54\", \"best_ask\":\"0.55\"}, {\"asset_id\":\"41448400836309843603620980831210604935021861034693225347475867885462478926555\", \"price\":\"0.53\", \"size\":\"127\", \"side\":\"SELL\", \"hash\":\"bb8bf55939e4785b6d6bb6d09b766f5e85e032b4\", \"best_bid\":\"0.45\", \"best_ask\":\"0.46\"}], \"timestamp\":\"1785122139870\", \"event_type\":\"price_change\"}","received_at":"2026-07-27T03:15:39.778759Z","schema_version":"clob-market-ws.price_change.v1","sequence":null,"server_hash":null,"server_timestamp":"1785122139870","session_id":"dd162b8dca5f43ff811d304e69a06123","source":"clob_market_ws"},"received_at":"2026-07-27T03:15:39.778759Z","record_id":"8a290af48768f2ee78e3b8e57d2192554c853499bb10ba53cd45f0f00134aa61","schema_fingerprint":"4aa3821a28b0b7c2400bc59aba4bcc0a76e971dadd19610d3ad38c768e124dc7","schema_version":"edge-lab-recorder.raw.v1","sequence":null,"source":"clob_market_ws"}
{"event_at":"2026-07-27T03:15:39.893000Z","event_fingerprint":"09414d3ff83de7c38a1b52c4861f7c15cb582f7e1e18c9c48c16b82b9b43a61c","payload":{"connection_id":"c7dc2e4762f849c6b6f9306b6518dcab","event_at":"2026-07-27T03:15:39.893000Z","event_type":"price_change","frame_hash":"b1596f343b4121dafdf0683cc6d5529652d67a712c7258252e30352446410953","frame_index":0,"kind":"data","monotonic_ns":224123132107791,"payload":{"event_type":"price_change","market":"0x717c0e8ccd4d5c7040185188fbae28be901ca589a11a94b1b38ca36a79eccfeb","price_changes":[{"asset_id":"24254094493625419915756280046002869097156693848522361803041977572204227262166","best_ask":"0.55","best_bid":"0.54","hash":"65d756c724ff22b29461e0925b459639bfd882d7","price":"0.02","side":"BUY","size":"1788.1"},{"asset_id":"41448400836309843603620980831210604935021861034693225347475867885462478926555","best_ask":"0.46","best_bid":"0.45","hash":"804457db931bacd8510d30e46f43659371647096","price":"0.98","side":"SELL","size":"1788.1"}],"timestamp":"1785122139893"},"payload_hash":"3c2f1902eb77100fd212584d75a59062cc3c95ad68a4d1e30b095f3d43def377","raw_frame":"{\"market\":\"0x717c0e8ccd4d5c7040185188fbae28be901ca589a11a94b1b38ca36a79eccfeb\", \"price_changes\":[{\"asset_id\":\"24254094493625419915756280046002869097156693848522361803041977572204227262166\", \"price\":\"0.02\", \"size\":\"1788.1\", \"side\":\"BUY\", \"hash\":\"65d756c724ff22b29461e0925b459639bfd882d7\", \"best_bid\":\"0.54\", \"best_ask\":\"0.55\"}, {\"asset_id\":\"41448400836309843603620980831210604935021861034693225347475867885462478926555\", \"price\":\"0.98\", \"size\":\"1788.1\", \"side\":\"SELL\", \"hash\":\"804457db931bacd8510d30e46f43659371647096\", \"best_bid\":\"0.45\", \"best_ask\":\"0.46\"}], \"timestamp\":\"1785122139893\", \"event_type\":\"price_change\"}","received_at":"2026-07-27T03:15:39.797886Z","schema_version":"clob-market-ws.price_change.v1","sequence":null,"server_hash":null,"server_timestamp":"1785122139893","session_id":"dd162b8dca5f43ff811d304e69a06123","source":"clob_market_ws"},"received_at":"2026-07-27T03:15:39.797886Z","record_id":"b07afd7e05bb4a79a35390bee2c0e99722ab1f41fc3912ac0179320255263f83","schema_fingerprint":"4aa3821a28b0b7c2400bc59aba4bcc0a76e971dadd19610d3ad38c768e124dc7","schema_version":"edge-lab-recorder.raw.v1","sequence":null,"source":"clob_market_ws"}
{"event_at":"2026-07-27T03:15:39.981000Z","event_fingerprint":"5885c0d50bd71daed19c2ff0d06ad778214dadb67bee0eb34bd52235091ff632","payload":{"connection_id":"c7dc2e4762f849c6b6f9306b6518dcab","event_at":"2026-07-27T03:15:39.981000Z","event_type":"price_change","frame_hash":"2dd5e97734aaabdf13231ac9795b5f8aa134b796490ab8e4c2ab29220c97a1a2","frame_index":0,"kind":"data","monotonic_ns":224123218672541,"payload":{"event_type":"price_change","market":"0x717c0e8ccd4d5c7040185188fbae28be901ca589a11a94b1b38ca36a79eccfeb","price_changes":[{"asset_id":"24254094493625419915756280046002869097156693848522361803041977572204227262166","best_ask":"0.55","best_bid":"0.54","hash":"9d92310dff1d30878ba833bd1b1b07d5baf6bef4","price":"0.54","side":"BUY","size":"51.38"},{"asset_id":"41448400836309843603620980831210604935021861034693225347475867885462478926555","best_ask":"0.46","best_bid":"0.45","hash":"d94cccaae41f9b2d7eb077e0173237270e5b6ba3","price":"0.46","side":"SELL","size":"51.38"}],"timestamp":"1785122139981"},"payload_hash":"823b2a4d5ae4265fc403ed88ceda1c8abf4782613562bda5014a9d20c82cf864","raw_frame":"{\"market\":\"0x717c0e8ccd4d5c7040185188fbae28be901ca589a11a94b1b38ca36a79eccfeb\", \"price_changes\":[{\"asset_id\":\"24254094493625419915756280046002869097156693848522361803041977572204227262166\", \"price\":\"0.54\", \"size\":\"51.38\", \"side\":\"BUY\", \"hash\":\"9d92310dff1d30878ba833bd1b1b07d5baf6bef4\", \"best_bid\":\"0.54\", \"best_ask\":\"0.55\"}, {\"asset_id\":\"41448400836309843603620980831210604935021861034693225347475867885462478926555\", \"price\":\"0.46\", \"size\":\"51.38\", \"side\":\"SELL\", \"hash\":\"d94cccaae41f9b2d7eb077e0173237270e5b6ba3\", \"best_bid\":\"0.45\", \"best_ask\":\"0.46\"}], \"timestamp\":\"1785122139981\", \"event_type\":\"price_change\"}","received_at":"2026-07-27T03:15:39.884447Z","schema_version":"clob-market-ws.price_change.v1","sequence":null,"server_hash":null,"server_timestamp":"1785122139981","session_id":"dd162b8dca5f43ff811d304e69a06123","source":"clob_market_ws"},"received_at":"2026-07-27T03:15:39.884447Z","record_id":"da906f9155e6e5e455ecca8178cbebd4a70d9edf71063cfe118c06ff07a00bf3","schema_fingerprint":"4aa3821a28b0b7c2400bc59aba4bcc0a76e971dadd19610d3ad38c768e124dc7","schema_version":"edge-lab-recorder.raw.v1","sequence":null,"source":"clob_market_ws"}
{"event_at":"2026-07-27T03:15:39.985000Z","event_fingerprint":"836e3ed7dcaea61fc8fc8e3b067d57f7634ae579d92c0861ab1116b034391581","payload":{"connection_id":"c7dc2e4762f849c6b6f9306b6518dcab","event_at":"2026-07-27T03:15:39.985000Z","event_type":"price_change","frame_hash":"5d05c7aa3533f0b9e5a5f16c77636d7dd5b6243eefc4ba24d58689e16459cd79","frame_index":0,"kind":"data","monotonic_ns":224123223144625,"payload":{"event_type":"price_change","market":"0x717c0e8ccd4d5c7040185188fbae28be901ca589a11a94b1b38ca36a79eccfeb","price_changes":[{"asset_id":"24254094493625419915756280046002869097156693848522361803041977572204227262166","best_ask":"0.55","best_bid":"0.54","hash":"1fcae5d457ec864c88be5906f82fdc1b676efa32","price":"0.44","side":"BUY","size":"116"},{"asset_id":"41448400836309843603620980831210604935021861034693225347475867885462478926555","best_ask":"0.46","best_bid":"0.45","hash":"a8fb27f885b20146a0316448a3f74cc75afc6537","price":"0.56","side":"SELL","size":"116"}],"timestamp":"1785122139985"},"payload_hash":"1cad9507cf076a4fdbb3a22d795bce82c462d3ee093c450788d44036276b913c","raw_frame":"{\"market\":\"0x717c0e8ccd4d5c7040185188fbae28be901ca589a11a94b1b38ca36a79eccfeb\", \"price_changes\":[{\"asset_id\":\"24254094493625419915756280046002869097156693848522361803041977572204227262166\", \"price\":\"0.44\", \"size\":\"116\", \"side\":\"BUY\", \"hash\":\"1fcae5d457ec864c88be5906f82fdc1b676efa32\", \"best_bid\":\"0.54\", \"best_ask\":\"0.55\"}, {\"asset_id\":\"41448400836309843603620980831210604935021861034693225347475867885462478926555\", \"price\":\"0.56\", \"size\":\"116\", \"side\":\"SELL\", \"hash\":\"a8fb27f885b20146a0316448a3f74cc75afc6537\", \"best_bid\":\"0.45\", \"best_ask\":\"0.46\"}], \"timestamp\":\"1785122139985\", \"event_type\":\"price_change\"}","received_at":"2026-07-27T03:15:39.888922Z","schema_version":"clob-market-ws.price_change.v1","sequence":null,"server_hash":null,"server_timestamp":"1785122139985","session_id":"dd162b8dca5f43ff811d304e69a06123","source":"clob_market_ws"},"received_at":"2026-07-27T03:15:39.888922Z","record_id":"0fbcf98f02cd378606ac25abc03dcf60c1586554826f63940c584171557ae66e","schema_fingerprint":"4aa3821a28b0b7c2400bc59aba4bcc0a76e971dadd19610d3ad38c768e124dc7","schema_version":"edge-lab-recorder.raw.v1","sequence":null,"source":"clob_market_ws"}
{"event_at":"2026-07-27T03:15:39.986000Z","event_fingerprint":"e58508e3801a142c5c6d663b3e94deddf6804ba223aed0bd3c591f6a3bffbfef","payload":{"connection_id":"c7dc2e4762f849c6b6f9306b6518dcab","event_at":"2026-07-27T03:15:39.986000Z","event_type":"price_change","frame_hash":"35e76206f75f6d6c9710e5b3f00c480e25705a76d006db913ba4c7f9215cd599","frame_index":0,"kind":"data","monotonic_ns":224123229498708,"payload":{"event_type":"price_change","market":"0x717c0e8ccd4d5c7040185188fbae28be901ca589a11a94b1b38ca36a79eccfeb","price_changes":[{"asset_id":"41448400836309843603620980831210604935021861034693225347475867885462478926555","best_ask":"0.46","best_bid":"0.45","hash":"fe77ee45fb11231d0182e0d3c0a779b406181df5","price":"0.41","side":"BUY","size":"17"},{"asset_id":"24254094493625419915756280046002869097156693848522361803041977572204227262166","best_ask":"0.55","best_bid":"0.54","hash":"0f46b46baecf21ca72744cce4c462e3433a48538","price":"0.59","side":"SELL","size":"17"}],"timestamp":"1785122139986"},"payload_hash":"61352a4c252d11b553f94a270a2a53b3d2818f3e1b45c34935b4fcd649c032ac","raw_frame":"{\"market\":\"0x717c0e8ccd4d5c7040185188fbae28be901ca589a11a94b1b38ca36a79eccfeb\", \"price_changes\":[{\"asset_id\":\"41448400836309843603620980831210604935021861034693225347475867885462478926555\", \"price\":\"0.41\", \"size\":\"17\", \"side\":\"BUY\", \"hash\":\"fe77ee45fb11231d0182e0d3c0a779b406181df5\", \"best_bid\":\"0.45\", \"best_ask\":\"0.46\"}, {\"asset_id\":\"24254094493625419915756280046002869097156693848522361803041977572204227262166\", \"price\":\"0.59\", \"size\":\"17\", \"side\":\"SELL\", \"hash\":\"0f46b46baecf21ca72744cce4c462e3433a48538\", \"best_bid\":\"0.54\", \"best_ask\":\"0.55\"}], \"timestamp\":\"1785122139986\", \"event_type\":\"price_change\"}","received_at":"2026-07-27T03:15:39.895274Z","schema_version":"clob-market-ws.price_change.v1","sequence":null,"server_hash":null,"server_timestamp":"1785122139986","session_id":"dd162b8dca5f43ff811d304e69a06123","source":"clob_market_ws"},"received_at":"2026-07-27T03:15:39.895274Z","record_id":"28f5e94e5177648e560b685b80eb9b9594fd36afa958d1b5f523b28d8e07c6f3","schema_fingerprint":"4aa3821a28b0b7c2400bc59aba4bcc0a76e971dadd19610d3ad38c768e124dc7","schema_version":"edge-lab-recorder.raw.v1","sequence":null,"source":"clob_market_ws"}
{"event_at":"2026-07-27T03:15:39.988000Z","event_fingerprint":"2a2fdc7ad1eaa57e9c67e71c7a924bb0a3fe9e9914bf70910de67a4e26734906","payload":{"connection_id":"c7dc2e4762f849c6b6f9306b6518dcab","event_at":"2026-07-27T03:15:39.988000Z","event_type":"price_change","frame_hash":"ff31c3b3e0080e4a4fbd2cf21d362bddc3aad6bdac730934c412810280f3aad4","frame_index":0,"kind":"data","monotonic_ns":224123233983000,"payload":{"event_type":"price_change","market":"0x717c0e8ccd4d5c7040185188fbae28be901ca589a11a94b1b38ca36a79eccfeb","price_changes":[{"asset_id":"41448400836309843603620980831210604935021861034693225347475867885462478926555","best_ask":"0.46","best_bid":"0.45","hash":"e82823b517e00c5ee42dbea1798892523ea8918d","price":"0.29","side":"BUY","size":"20.6"},{"asset_id":"24254094493625419915756280046002869097156693848522361803041977572204227262166","best_ask":"0.55","best_bid":"0.54","hash":"7dc3bec1e8e39fee9f2f0f638bbdeaf5d5b479df","price":"0.71","side":"SELL","size":"20.6"}],"timestamp":"1785122139988"},"payload_hash":"40f13cf89b681a3fccbd253eceb7d3f814d6bdfde777334baf30529739722cb8","raw_frame":"{\"market\":\"0x717c0e8ccd4d5c7040185188fbae28be901ca589a11a94b1b38ca36a79eccfeb\", \"price_changes\":[{\"asset_id\":\"41448400836309843603620980831210604935021861034693225347475867885462478926555\", \"price\":\"0.29\", \"size\":\"20.6\", \"side\":\"BUY\", \"hash\":\"e82823b517e00c5ee42dbea1798892523ea8918d\", \"best_bid\":\"0.45\", \"best_ask\":\"0.46\"}, {\"asset_id\":\"24254094493625419915756280046002869097156693848522361803041977572204227262166\", \"price\":\"0.71\", \"size\":\"20.6\", \"side\":\"SELL\", \"hash\":\"7dc3bec1e8e39fee9f2f0f638bbdeaf5d5b479df\", \"best_bid\":\"0.54\", \"best_ask\":\"0.55\"}], \"timestamp\":\"1785122139988\", \"event_type\":\"price_change\"}","received_at":"2026-07-27T03:15:39.899760Z","schema_version":"clob-market-ws.price_change.v1","sequence":null,"server_hash":null,"server_timestamp":"1785122139988","session_id":"dd162b8dca5f43ff811d304e69a06123","source":"clob_market_ws"},"received_at":"2026-07-27T03:15:39.899760Z","record_id":"468b94a502b453cdbd40dff4d44ba752611b7fa00f0c8627739a3f59fd05e452","schema_fingerprint":"4aa3821a28b0b7c2400bc59aba4bcc0a76e971dadd19610d3ad38c768e124dc7","schema_version":"edge-lab-recorder.raw.v1","sequence":null,"source":"clob_market_ws"}
{"event_at":"2026-07-27T03:15:39.988000Z","event_fingerprint":"5314299251d7eb72cf8cf81a30aa0bff4b19e8e030e24b681f934d0aa7b32db0","payload":{"connection_id":"c7dc2e4762f849c6b6f9306b6518dcab","event_at":"2026-07-27T03:15:39.988000Z","event_type":"price_change","frame_hash":"3808a5b45314e2789c60ae771cd526d71b801c8d7a328e1964d96ce781d58a26","frame_index":0,"kind":"data","monotonic_ns":224123237604916,"payload":{"event_type":"price_change","market":"0x717c0e8ccd4d5c7040185188fbae28be901ca589a11a94b1b38ca36a79eccfeb","price_changes":[{"asset_id":"24254094493625419915756280046002869097156693848522361803041977572204227262166","best_ask":"0.55","best_bid":"0.54","hash":"d23fbe52fddf1c7851e74c9d6ef05242eb46d3cc","price":"0.54","side":"BUY","size":"60.38"},{"asset_id":"41448400836309843603620980831210604935021861034693225347475867885462478926555","best_ask":"0.46","best_bid":"0.45","hash":"a790a009c398597573923e547298f1dd7eadd225","price":"0.46","side":"SELL","size":"60.38"}],"timestamp":"1785122139988"},"payload_hash":"8b0b57cd52544cbd3e80c0e5971dd90966d2b5f296fc2231f6ea71bc4605b3b5","raw_frame":"{\"market\":\"0x717c0e8ccd4d5c7040185188fbae28be901ca589a11a94b1b38ca36a79eccfeb\", \"price_changes\":[{\"asset_id\":\"24254094493625419915756280046002869097156693848522361803041977572204227262166\", \"price\":\"0.54\", \"size\":\"60.38\", \"side\":\"BUY\", \"hash\":\"d23fbe52fddf1c7851e74c9d6ef05242eb46d3cc\", \"best_bid\":\"0.54\", \"best_ask\":\"0.55\"}, {\"asset_id\":\"41448400836309843603620980831210604935021861034693225347475867885462478926555\", \"price\":\"0.46\", \"size\":\"60.38\", \"side\":\"SELL\", \"hash\":\"a790a009c398597573923e547298f1dd7eadd225\", \"best_bid\":\"0.45\", \"best_ask\":\"0.46\"}], \"timestamp\":\"1785122139988\", \"event_type\":\"price_change\"}","received_at":"2026-07-27T03:15:39.903382Z","schema_version":"clob-market-ws.price_change.v1","sequence":null,"server_hash":null,"server_timestamp":"1785122139988","session_id":"dd162b8dca5f43ff811d304e69a06123","source":"clob_market_ws"},"received_at":"2026-07-27T03:15:39.903382Z","record_id":"7b47e70ac768bd57ab1c3c425ae89132f6399212922905dfeb956fd6250071cf","schema_fingerprint":"4aa3821a28b0b7c2400bc59aba4bcc0a76e971dadd19610d3ad38c768e124dc7","schema_version":"edge-lab-recorder.raw.v1","sequence":null,"source":"clob_market_ws"}
{"event_at":"2026-07-27T03:15:39.989000Z","event_fingerprint":"25308b8298f648d85cac1351eace3ea5b542ca052f5ba057e7203cd4d68cf38e","payload":{"connection_id":"c7dc2e4762f849c6b6f9306b6518dcab","event_at":"2026-07-27T03:15:39.989000Z","event_type":"price_change","frame_hash":"bf916ee1ca39ba155f65c19b65cf2ea060840c2f81cd71c454f391c5fb153654","frame_index":0,"kind":"data","monotonic_ns":224123241388500,"payload":{"event_type":"price_change","market":"0x717c0e8ccd4d5c7040185188fbae28be901ca589a11a94b1b38ca36a79eccfeb","price_changes":[{"asset_id":"24254094493625419915756280046002869097156693848522361803041977572204227262166","best_ask":"0.55","best_bid":"0.54","hash":"7f2f3a773bd2fef3c9340e9e903b90ec3cb655a6","price":"0.5","side":"BUY","size":"15"},{"asset_id":"41448400836309843603620980831210604935021861034693225347475867885462478926555","best_ask":"0.46","best_bid":"0.45","hash":"4693e51cbe25b2ea8da75fe322ccab003f7cb15a","price":"0.5","side":"SELL","size":"15"}],"timestamp":"1785122139989"},"payload_hash":"2ba62fb1b9c0e943e37f4aa78336c9a3f9d6fd0b5bf9ae8df0d1d7f3967733d4","raw_frame":"{\"market\":\"0x717c0e8ccd4d5c7040185188fbae28be901ca589a11a94b1b38ca36a79eccfeb\", \"price_changes\":[{\"asset_id\":\"24254094493625419915756280046002869097156693848522361803041977572204227262166\", \"price\":\"0.5\", \"size\":\"15\", \"side\":\"BUY\", \"hash\":\"7f2f3a773bd2fef3c9340e9e903b90ec3cb655a6\", \"best_bid\":\"0.54\", \"best_ask\":\"0.55\"}, {\"asset_id\":\"41448400836309843603620980831210604935021861034693225347475867885462478926555\", \"price\":\"0.5\", \"size\":\"15\", \"side\":\"SELL\", \"hash\":\"4693e51cbe25b2ea8da75fe322ccab003f7cb15a\", \"best_bid\":\"0.45\", \"best_ask\":\"0.46\"}], \"timestamp\":\"1785122139989\", \"event_type\":\"price_change\"}","received_at":"2026-07-27T03:15:39.907165Z","schema_version":"clob-market-ws.price_change.v1","sequence":null,"server_hash":null,"server_timestamp":"1785122139989","session_id":"dd162b8dca5f43ff811d304e69a06123","source":"clob_market_ws"},"received_at":"2026-07-27T03:15:39.907165Z","record_id":"74fefee931859b134302b108cc5ba76dcc128ab67b94029cd353c7e1f18db3e1","schema_fingerprint":"4aa3821a28b0b7c2400bc59aba4bcc0a76e971dadd19610d3ad38c768e124dc7","schema_version":"edge-lab-recorder.raw.v1","sequence":null,"source":"clob_market_ws"}
{"event_at":"2026-07-27T03:15:39.990000Z","event_fingerprint":"63a439d6d5135c94aaedb4220ff27d184fda986f58a5723bad883ddf183f65e7","payload":{"connection_id":"c7dc2e4762f849c6b6f9306b6518dcab","event_at":"2026-07-27T03:15:39.990000Z","event_type":"price_change","frame_hash":"9e747846c7d835f29ec9ab512dc9251dd557c8f0b02ec1a6f846e06439429c52","frame_index":0,"kind":"data","monotonic_ns":224123247393041,"payload":{"event_type":"price_change","market":"0x717c0e8ccd4d5c7040185188fbae28be901ca589a11a94b1b38ca36a79eccfeb","price_changes":[{"asset_id":"41448400836309843603620980831210604935021861034693225347475867885462478926555","best_ask":"0.46","best_bid":"0.45","hash":"00b7a205456a4eba896ebd6c382c8b2c1073ecac","price":"0.42","side":"BUY","size":"18"},{"asset_id":"24254094493625419915756280046002869097156693848522361803041977572204227262166","best_ask":"0.55","best_bid":"0.54","hash":"5f1f79ce639842e7e8e59424f8100f83d7e44f53","price":"0.58","side":"SELL","size":"18"}],"timestamp":"1785122139990"},"payload_hash":"c8f157459c486a36866a00f33b545211ba3db36f861474e328b46683d68b48be","raw_frame":"{\"market\":\"0x717c0e8ccd4d5c7040185188fbae28be901ca589a11a94b1b38ca36a79eccfeb\", \"price_changes\":[{\"asset_id\":\"41448400836309843603620980831210604935021861034693225347475867885462478926555\", \"price\":\"0.42\", \"size\":\"18\", \"side\":\"BUY\", \"hash\":\"00b7a205456a4eba896ebd6c382c8b2c1073ecac\", \"best_bid\":\"0.45\", \"best_ask\":\"0.46\"}, {\"asset_id\":\"24254094493625419915756280046002869097156693848522361803041977572204227262166\", \"price\":\"0.58\", \"size\":\"18\", \"side\":\"SELL\", \"hash\":\"5f1f79ce639842e7e8e59424f8100f83d7e44f53\", \"best_bid\":\"0.54\", \"best_ask\":\"0.55\"}], \"timestamp\":\"1785122139990\", \"event_type\":\"price_change\"}","received_at":"2026-07-27T03:15:39.913170Z","schema_version":"clob-market-ws.price_change.v1","sequence":null,"server_hash":null,"server_timestamp":"1785122139990","session_id":"dd162b8dca5f43ff811d304e69a06123","source":"clob_market_ws"},"received_at":"2026-07-27T03:15:39.913170Z","record_id":"c742d643518576cf99c4004b2de632d5fe8ae14117cabc0f14945c591528fc48","schema_fingerprint":"4aa3821a28b0b7c2400bc59aba4bcc0a76e971dadd19610d3ad38c768e124dc7","schema_version":"edge-lab-recorder.raw.v1","sequence":null,"source":"clob_market_ws"}
{"event_at":"2026-07-27T03:15:39.991000Z","event_fingerprint":"ecb3692f7ca28f1b1908b1c718c7b5905ebe73749f3d276bda4e6afd04d49283","payload":{"connection_id":"c7dc2e4762f849c6b6f9306b6518dcab","event_at":"2026-07-27T03:15:39.991000Z","event_type":"price_change","frame_hash":"4bb294c2cec283509beda7d5d18e6d9feaaf3e21d1dca92edbbf69c3805820a5","frame_index":0,"kind":"data","monotonic_ns":224123252377458,"payload":{"event_type":"price_change","market":"0x717c0e8ccd4d5c7040185188fbae28be901ca589a11a94b1b38ca36a79eccfeb","price_changes":[{"asset_id":"24254094493625419915756280046002869097156693848522361803041977572204227262166","best_ask":"0.55","best_bid":"0.54","hash":"b454aa6b25b531bbeb7df7e515d626979820f8a0","price":"0.47","side":"BUY","size":"121"},{"asset_id":"41448400836309843603620980831210604935021861034693225347475867885462478926555","best_ask":"0.46","best_bid":"0.45","hash":"f8596e8f92b9947dc328be4303fd9efff1294850","price":"0.53","side":"SELL","size":"121"}],"timestamp":"1785122139991"},"payload_hash":"239da021c982ee35be0e0cbccbf8c6ca725926cfcb08685c0e24540eb7480800","raw_frame":"{\"market\":\"0x717c0e8ccd4d5c7040185188fbae28be901ca589a11a94b1b38ca36a79eccfeb\", \"price_changes\":[{\"asset_id\":\"24254094493625419915756280046002869097156693848522361803041977572204227262166\", \"price\":\"0.47\", \"size\":\"121\", \"side\":\"BUY\", \"hash\":\"b454aa6b25b531bbeb7df7e515d626979820f8a0\", \"best_bid\":\"0.54\", \"best_ask\":\"0.55\"}, {\"asset_id\":\"41448400836309843603620980831210604935021861034693225347475867885462478926555\", \"price\":\"0.53\", \"size\":\"121\", \"side\":\"SELL\", \"hash\":\"f8596e8f92b9947dc328be4303fd9efff1294850\", \"best_bid\":\"0.45\", \"best_ask\":\"0.46\"}], \"timestamp\":\"1785122139991\", \"event_type\":\"price_change\"}","received_at":"2026-07-27T03:15:39.918154Z","schema_version":"clob-market-ws.price_change.v1","sequence":null,"server_hash":null,"server_timestamp":"1785122139991","session_id":"dd162b8dca5f43ff811d304e69a06123","source":"clob_market_ws"},"received_at":"2026-07-27T03:15:39.918154Z","record_id":"71112aee07bc43ac3f5cfe23ac4e3cd4ddb04789f1f95843720988e7e9fba625","schema_fingerprint":"4aa3821a28b0b7c2400bc59aba4bcc0a76e971dadd19610d3ad38c768e124dc7","schema_version":"edge-lab-recorder.raw.v1","sequence":null,"source":"clob_market_ws"}
{"event_at":"2026-07-27T03:15:39.992000Z","event_fingerprint":"2871cf44b976325a2b33b5983898e54caaed415c5b165d9c34d338f5c744b7b9","payload":{"connection_id":"c7dc2e4762f849c6b6f9306b6518dcab","event_at":"2026-07-27T03:15:39.992000Z","event_type":"price_change","frame_hash":"97438e343707adc7ca1a546c168567c3ec0f0154b628df69f75f997dfc2f61e6","frame_index":0,"kind":"data","monotonic_ns":224123257503916,"payload":{"event_type":"price_change","market":"0x717c0e8ccd4d5c7040185188fbae28be901ca589a11a94b1b38ca36a79eccfeb","price_changes":[{"asset_id":"41448400836309843603620980831210604935021861034693225347475867885462478926555","best_ask":"0.46","best_bid":"0.45","hash":"60917ccc578264ca8c1e5c88399b573298c85b4d","price":"0.37","side":"BUY","size":"136.74"},{"asset_id":"24254094493625419915756280046002869097156693848522361803041977572204227262166","best_ask":"0.55","best_bid":"0.54","hash":"ac11200f45613e18fc543af31dffccaaa40f6da2","price":"0.63","side":"SELL","size":"136.74"}],"timestamp":"1785122139992"},"payload_hash":"2f34e7c81ee5668688ed868076c7841bda16b368f2a46686fa76160c62e581d2","raw_frame":"{\"market\":\"0x717c0e8ccd4d5c7040185188fbae28be901ca589a11a94b1b38ca36a79eccfeb\", \"price_changes\":[{\"asset_id\":\"41448400836309843603620980831210604935021861034693225347475867885462478926555\", \"price\":\"0.37\", \"size\":\"136.74\", \"side\":\"BUY\", \"hash\":\"60917ccc578264ca8c1e5c88399b573298c85b4d\", \"best_bid\":\"0.45\", \"best_ask\":\"0.46\"}, {\"asset_id\":\"24254094493625419915756280046002869097156693848522361803041977572204227262166\", \"price\":\"0.63\", \"size\":\"136.74\", \"side\":\"SELL\", \"hash\":\"ac11200f45613e18fc543af31dffccaaa40f6da2\", \"best_bid\":\"0.54\", \"best_ask\":\"0.55\"}], \"timestamp\":\"1785122139992\", \"event_type\":\"price_change\"}","received_at":"2026-07-27T03:15:39.923281Z","schema_version":"clob-market-ws.price_change.v1","sequence":null,"server_hash":null,"server_timestamp":"1785122139992","session_id":"dd162b8dca5f43ff811d304e69a06123","source":"clob_market_ws"},"received_at":"2026-07-27T03:15:39.923281Z","record_id":"e7bbb080fc3874f3d0db0b7d154e7c41e146c86569c4ae26915fc317a3c5c965","schema_fingerprint":"4aa3821a28b0b7c2400bc59aba4bcc0a76e971dadd19610d3ad38c768e124dc7","schema_version":"edge-lab-recorder.raw.v1","sequence":null,"source":"clob_market_ws"}
{"event_at":"2026-07-27T03:15:39.994000Z","event_fingerprint":"d7e99012d702a4c2418462e89be410abb1d20427863152dbbf1bfe95be435c84","payload":{"connection_id":"c7dc2e4762f849c6b6f9306b6518dcab","event_at":"2026-07-27T03:15:39.994000Z","event_type":"price_change","frame_hash":"f3db9765ab7f1c33ccb010dfb1ea53596501c697ce10ef93aedd254ff1661b9c","frame_index":0,"kind":"data","monotonic_ns":224123265966666,"payload":{"event_type":"price_change","market":"0x717c0e8ccd4d5c7040185188fbae28be901ca589a11a94b1b38ca36a79eccfeb","price_changes":[{"asset_id":"24254094493625419915756280046002869097156693848522361803041977572204227262166","best_ask":"0.55","best_bid":"0.54","hash":"e0e6a2aec5e3fc95200afad32dd95fbae102539f","price":"0.49","side":"BUY","size":"106"},{"asset_id":"41448400836309843603620980831210604935021861034693225347475867885462478926555","best_ask":"0.46","best_bid":"0.45","hash":"c3a4fc221aff344aec13c26572dcc65d1a0f5f46","price":"0.51","side":"SELL","size":"106"}],"timestamp":"1785122139994"},"payload_hash":"ba9f574a73b38ae8b861db19250dbefdeee7492f7b9d92893d9436d0b892c92a","raw_frame":"{\"market\":\"0x717c0e8ccd4d5c7040185188fbae28be901ca589a11a94b1b38ca36a79eccfeb\", \"price_changes\":[{\"asset_id\":\"24254094493625419915756280046002869097156693848522361803041977572204227262166\", \"price\":\"0.49\", \"size\":\"106\", \"side\":\"BUY\", \"hash\":\"e0e6a2aec5e3fc95200afad32dd95fbae102539f\", \"best_bid\":\"0.54\", \"best_ask\":\"0.55\"}, {\"asset_id\":\"41448400836309843603620980831210604935021861034693225347475867885462478926555\", \"price\":\"0.51\", \"size\":\"106\", \"side\":\"SELL\", \"hash\":\"c3a4fc221aff344aec13c26572dcc65d1a0f5f46\", \"best_bid\":\"0.45\", \"best_ask\":\"0.46\"}], \"timestamp\":\"1785122139994\", \"event_type\":\"price_change\"}","received_at":"2026-07-27T03:15:39.931742Z","schema_version":"clob-market-ws.price_change.v1","sequence":null,"server_hash":null,"server_timestamp":"1785122139994","session_id":"dd162b8dca5f43ff811d304e69a06123","source":"clob_market_ws"},"received_at":"2026-07-27T03:15:39.931742Z","record_id":"04f9b2a1cce87f5d5f1ebb62116c7a68a8b3fe9f42d59b5918b86ae0900278c0","schema_fingerprint":"4aa3821a28b0b7c2400bc59aba4bcc0a76e971dadd19610d3ad38c768e124dc7","schema_version":"edge-lab-recorder.raw.v1","sequence":null,"source":"clob_market_ws"}
{"event_at":"2026-07-27T03:15:40.007000Z","event_fingerprint":"1d0171be5ed5a19341dddcbbae9c0ac70e248b4b60551faf3e90e5b5f22ea7bc","payload":{"connection_id":"c7dc2e4762f849c6b6f9306b6518dcab","event_at":"2026-07-27T03:15:40.007000Z","event_type":"price_change","frame_hash":"70ac40ad1261a2ee31ac751f38268acc3b3d1a89291e959332e2d9f2fd9e411b","frame_index":0,"kind":"data","monotonic_ns":224123268582083,"payload":{"event_type":"price_change","market":"0x717c0e8ccd4d5c7040185188fbae28be901ca589a11a94b1b38ca36a79eccfeb","price_changes":[{"asset_id":"24254094493625419915756280046002869097156693848522361803041977572204227262166","best_ask":"0.55","best_bid":"0.54","hash":"3c9df60b0b8d793bf54a189e32cd7d3750799e24","price":"0.02","side":"BUY","size":"1783.1"},{"asset_id":"41448400836309843603620980831210604935021861034693225347475867885462478926555","best_ask":"0.46","best_bid":"0.45","hash":"c55f6fff7c4ca8d024e03cd8e70363f789139fd5","price":"0.98","side":"SELL","size":"1783.1"}],"timestamp":"1785122140007"},"payload_hash":"f4426a7529ac338722452615d12079a16eca85a6b6c55bc689d6f97e8efb7b7b","raw_frame":"{\"market\":\"0x717c0e8ccd4d5c7040185188fbae28be901ca589a11a94b1b38ca36a79eccfeb\", \"price_changes\":[{\"asset_id\":\"24254094493625419915756280046002869097156693848522361803041977572204227262166\", \"price\":\"0.02\", \"size\":\"1783.1\", \"side\":\"BUY\", \"hash\":\"3c9df60b0b8d793bf54a189e32cd7d3750799e24\", \"best_bid\":\"0.54\", \"best_ask\":\"0.55\"}, {\"asset_id\":\"41448400836309843603620980831210604935021861034693225347475867885462478926555\", \"price\":\"0.98\", \"size\":\"1783.1\", \"side\":\"SELL\", \"hash\":\"c55f6fff7c4ca8d024e03cd8e70363f789139fd5\", \"best_bid\":\"0.45\", \"best_ask\":\"0.46\"}], \"timestamp\":\"1785122140007\", \"event_type\":\"price_change\"}","received_at":"2026-07-27T03:15:39.934363Z","schema_version":"clob-market-ws.price_change.v1","sequence":null,"server_hash":null,"server_timestamp":"1785122140007","session_id":"dd162b8dca5f43ff811d304e69a06123","source":"clob_market_ws"},"received_at":"2026-07-27T03:15:39.934363Z","record_id":"7fc5d2e8b96edf7ffc21382d4dcd9553d4a1b638cd6b5f85576a5240bdd3256a","schema_fingerprint":"4aa3821a28b0b7c2400bc59aba4bcc0a76e971dadd19610d3ad38c768e124dc7","schema_version":"edge-lab-recorder.raw.v1","sequence":null,"source":"clob_market_ws"}
{"event_at":"2026-07-27T03:15:40.011000Z","event_fingerprint":"6747f1ef3866bcbce6501167f00f52fe6457c1a6df588801a5db1c2c684cc8cd","payload":{"connection_id":"c7dc2e4762f849c6b6f9306b6518dcab","event_at":"2026-07-27T03:15:40.011000Z","event_type":"price_change","frame_hash":"dadbd5fe714c3fbba5dadc4b9503544075edc6c9084438138c777b70aa4247d9","frame_index":0,"kind":"data","monotonic_ns":224123270799500,"payload":{"event_type":"price_change","market":"0x717c0e8ccd4d5c7040185188fbae28be901ca589a11a94b1b38ca36a79eccfeb","price_changes":[{"asset_id":"41448400836309843603620980831210604935021861034693225347475867885462478926555","best_ask":"0.46","best_bid":"0.45","hash":"1640a950b85cb6b6217d11929f34183322ed60d2","price":"0.41","side":"BUY","size":"5"},{"asset_id":"24254094493625419915756280046002869097156693848522361803041977572204227262166","best_ask":"0.55","best_bid":"0.54","hash":"7135dc3c05b5ebee6d01137bb7d15fbcc5008c75","price":"0.59","side":"SELL","size":"5"}],"timestamp":"1785122140011"},"payload_hash":"f8dbbc11b55e500fbfe96c9ef19b70b04b21ac7bbd7abaa13180f5094bbe5bb9","raw_frame":"{\"market\":\"0x717c0e8ccd4d5c7040185188fbae28be901ca589a11a94b1b38ca36a79eccfeb\", \"price_changes\":[{\"asset_id\":\"41448400836309843603620980831210604935021861034693225347475867885462478926555\", \"price\":\"0.41\", \"size\":\"5\", \"side\":\"BUY\", \"hash\":\"1640a950b85cb6b6217d11929f34183322ed60d2\", \"best_bid\":\"0.45\", \"best_ask\":\"0.46\"}, {\"asset_id\":\"24254094493625419915756280046002869097156693848522361803041977572204227262166\", \"price\":\"0.59\", \"size\":\"5\", \"side\":\"SELL\", \"hash\":\"7135dc3c05b5ebee6d01137bb7d15fbcc5008c75\", \"best_bid\":\"0.54\", \"best_ask\":\"0.55\"}], \"timestamp\":\"1785122140011\", \"event_type\":\"price_change\"}","received_at":"2026-07-27T03:15:39.936581Z","schema_version":"clob-market-ws.price_change.v1","sequence":null,"server_hash":null,"server_timestamp":"1785122140011","session_id":"dd162b8dca5f43ff811d304e69a06123","source":"clob_market_ws"},"received_at":"2026-07-27T03:15:39.936581Z","record_id":"dd3bc031d469534a8f018df463f948296ef967a2c2370ef005d2c49c2a742121","schema_fingerprint":"4aa3821a28b0b7c2400bc59aba4bcc0a76e971dadd19610d3ad38c768e124dc7","schema_version":"edge-lab-recorder.raw.v1","sequence":null,"source":"clob_market_ws"}
{"event_at":"2026-07-27T03:15:40.013000Z","event_fingerprint":"2862f140a0fd489d648ed078fd121c4377781b956c379322573a4a367c1d0407","payload":{"connection_id":"c7dc2e4762f849c6b6f9306b6518dcab","event_at":"2026-07-27T03:15:40.013000Z","event_type":"price_change","frame_hash":"59ff68c645d556216bc2c3c2212ce2a4316f1f3a7c774be38ff270637736fc9b","frame_index":0,"kind":"data","monotonic_ns":224123272650708,"payload":{"event_type":"price_change","market":"0x717c0e8ccd4d5c7040185188fbae28be901ca589a11a94b1b38ca36a79eccfeb","price_changes":[{"asset_id":"41448400836309843603620980831210604935021861034693225347475867885462478926555","best_ask":"0.46","best_bid":"0.45","hash":"8d059b37cfafe704c1542e98c01dd3462e2b5931","price":"0.42","side":"BUY","size":"6"},{"asset_id":"24254094493625419915756280046002869097156693848522361803041977572204227262166","best_ask":"0.55","best_bid":"0.54","hash":"f1d9c63b4b6743add5017294cb95cd021726f14c","price":"0.58","side":"SELL","size":"6"}],"timestamp":"1785122140013"},"payload_hash":"16f64b1bf284d5eb640021de68d024c0151334cf2c9e3b73b32ab0bdb2ad35fa","raw_frame":"{\"market\":\"0x717c0e8ccd4d5c7040185188fbae28be901ca589a11a94b1b38ca36a79eccfeb\", \"price_changes\":[{\"asset_id\":\"41448400836309843603620980831210604935021861034693225347475867885462478926555\", \"price\":\"0.42\", \"size\":\"6\", \"side\":\"BUY\", \"hash\":\"8d059b37cfafe704c1542e98c01dd3462e2b5931\", \"best_bid\":\"0.45\", \"best_ask\":\"0.46\"}, {\"asset_id\":\"24254094493625419915756280046002869097156693848522361803041977572204227262166\", \"price\":\"0.58\", \"size\":\"6\", \"side\":\"SELL\", \"hash\":\"f1d9c63b4b6743add5017294cb95cd021726f14c\", \"best_bid\":\"0.54\", \"best_ask\":\"0.55\"}], \"timestamp\":\"1785122140013\", \"event_type\":\"price_change\"}","received_at":"2026-07-27T03:15:39.938432Z","schema_version":"clob-market-ws.price_change.v1","sequence":null,"server_hash":null,"server_timestamp":"1785122140013","session_id":"dd162b8dca5f43ff811d304e69a06123","source":"clob_market_ws"},"received_at":"2026-07-27T03:15:39.938432Z","record_id":"c0d59da53f7146ab602729d7a5300ebc0c99947d50cc94b56dc693938355986a","schema_fingerprint":"4aa3821a28b0b7c2400bc59aba4bcc0a76e971dadd19610d3ad38c768e124dc7","schema_version":"edge-lab-recorder.raw.v1","sequence":null,"source":"clob_market_ws"}
{"event_at":"2026-07-27T03:15:40.024000Z","event_fingerprint":"8baf1d1f9cff60f5c94cf474952ac4dda4f293c44a49ac8a4b5ca3a78eb5a080","payload":{"connection_id":"c7dc2e4762f849c6b6f9306b6518dcab","event_at":"2026-07-27T03:15:40.024000Z","event_type":"price_change","frame_hash":"117e7ec9920f7d00bcb1b3161738391c369b17d792bdb7d6979996d8799c8e4d","frame_index":0,"kind":"data","monotonic_ns":224123274677708,"payload":{"event_type":"price_change","market":"0x717c0e8ccd4d5c7040185188fbae28be901ca589a11a94b1b38ca36a79eccfeb","price_changes":[{"asset_id":"41448400836309843603620980831210604935021861034693225347475867885462478926555","best_ask":"0.46","best_bid":"0.45","hash":"406be679ecf449bfecb3048738d46995601abd17","price":"0.39","side":"BUY","size":"159"},{"asset_id":"24254094493625419915756280046002869097156693848522361803041977572204227262166","best_ask":"0.55","best_bid":"0.54","hash":"f885e51a24895cc583eb244952bd0a59b11a66b1","price":"0.61","side":"SELL","size":"159"}],"timestamp":"1785122140024"},"payload_hash":"eba265281bfab1d12a0d00b0207480ff9e4c045889031335192a9e0ee96350c4","raw_frame":"{\"market\":\"0x717c0e8ccd4d5c7040185188fbae28be901ca589a11a94b1b38ca36a79eccfeb\", \"price_changes\":[{\"asset_id\":\"41448400836309843603620980831210604935021861034693225347475867885462478926555\", \"price\":\"0.39\", \"size\":\"159\", \"side\":\"BUY\", \"hash\":\"406be679ecf449bfecb3048738d46995601abd17\", \"best_bid\":\"0.45\", \"best_ask\":\"0.46\"}, {\"asset_id\":\"24254094493625419915756280046002869097156693848522361803041977572204227262166\", \"price\":\"0.61\", \"size\":\"159\", \"side\":\"SELL\", \"hash\":\"f885e51a24895cc583eb244952bd0a59b11a66b1\", \"best_bid\":\"0.54\", \"best_ask\":\"0.55\"}], \"timestamp\":\"1785122140024\", \"event_type\":\"price_change\"}","received_at":"2026-07-27T03:15:39.940459Z","schema_version":"clob-market-ws.price_change.v1","sequence":null,"server_hash":null,"server_timestamp":"1785122140024","session_id":"dd162b8dca5f43ff811d304e69a06123","source":"clob_market_ws"},"received_at":"2026-07-27T03:15:39.940459Z","record_id":"6e70fee2b48ef05d2bb784b35a6520363fcde73d479df12c4018068b66e56ac6","schema_fingerprint":"4aa3821a28b0b7c2400bc59aba4bcc0a76e971dadd19610d3ad38c768e124dc7","schema_version":"edge-lab-recorder.raw.v1","sequence":null,"source":"clob_market_ws"}
{"event_at":"2026-07-27T03:15:40.024000Z","event_fingerprint":"bbe5afdd24540b727231ec0f8cff2afe817cc728ae3242fd89f7161d3724b874","payload":{"connection_id":"c7dc2e4762f849c6b6f9306b6518dcab","event_at":"2026-07-27T03:15:40.024000Z","event_type":"price_change","frame_hash":"6d8090cd5bbcc352bedbfae2887928adc07b4d14abfe522d350aefb30df73684","frame_index":0,"kind":"data","monotonic_ns":224123276837041,"payload":{"event_type":"price_change","market":"0x717c0e8ccd4d5c7040185188fbae28be901ca589a11a94b1b38ca36a79eccfeb","price_changes":[{"asset_id":"41448400836309843603620980831210604935021861034693225347475867885462478926555","best_ask":"0.46","best_bid":"0.45","hash":"406be679ecf449bfecb3048738d46995601abd17","price":"0.38","side":"BUY","size":"274.07"},{"asset_id":"24254094493625419915756280046002869097156693848522361803041977572204227262166","best_ask":"0.55","best_bid":"0.54","hash":"f885e51a24895cc583eb244952bd0a59b11a66b1","price":"0.62","side":"SELL","size":"274.07"}],"timestamp":"1785122140024"},"payload_hash":"232f18c8b72dd63437f754798cb7266f570ee94e9c9f9a5c4bce523b9fbdb0d6","raw_frame":"{\"market\":\"0x717c0e8ccd4d5c7040185188fbae28be901ca589a11a94b1b38ca36a79eccfeb\", \"price_changes\":[{\"asset_id\":\"41448400836309843603620980831210604935021861034693225347475867885462478926555\", \"price\":\"0.38\", \"size\":\"274.07\", \"side\":\"BUY\", \"hash\":\"406be679ecf449bfecb3048738d46995601abd17\", \"best_bid\":\"0.45\", \"best_ask\":\"0.46\"}, {\"asset_id\":\"24254094493625419915756280046002869097156693848522361803041977572204227262166\", \"price\":\"0.62\", \"size\":\"274.07\", \"side\":\"SELL\", \"hash\":\"f885e51a24895cc583eb244952bd0a59b11a66b1\", \"best_bid\":\"0.54\", \"best_ask\":\"0.55\"}], \"timestamp\":\"1785122140024\", \"event_type\":\"price_change\"}","received_at":"2026-07-27T03:15:39.942613Z","schema_version":"clob-market-ws.price_change.v1","sequence":null,"server_hash":null,"server_timestamp":"1785122140024","session_id":"dd162b8dca5f43ff811d304e69a06123","source":"clob_market_ws"},"received_at":"2026-07-27T03:15:39.942613Z","record_id":"61602e794633ab2e98272d39a3e18384536ad5960bdb62d52d067cc5f8afdb10","schema_fingerprint":"4aa3821a28b0b7c2400bc59aba4bcc0a76e971dadd19610d3ad38c768e124dc7","schema_version":"edge-lab-recorder.raw.v1","sequence":null,"source":"clob_market_ws"}
{"event_at":"2026-07-27T03:15:40.032000Z","event_fingerprint":"e86b796eddb495037eef92081f256f2c4c18171dd84c2f551a16319e51135ea1","payload":{"connection_id":"c7dc2e4762f849c6b6f9306b6518dcab","event_at":"2026-07-27T03:15:40.032000Z","event_type":"price_change","frame_hash":"e13f367a61a04e82d1c731e9c161bf1bf8124f4d63b9eccba09970e3223c783a","frame_index":0,"kind":"data","monotonic_ns":224123279321458,"payload":{"event_type":"price_change","market":"0x717c0e8ccd4d5c7040185188fbae28be901ca589a11a94b1b38ca36a79eccfeb","price_changes":[{"asset_id":"41448400836309843603620980831210604935021861034693225347475867885462478926555","best_ask":"0.46","best_bid":"0.45","hash":"3d9b7f6ddbf1ee1fcc88818b71a75f601a2dd4be","price":"0.44","side":"BUY","size":"375.6"},{"asset_id":"24254094493625419915756280046002869097156693848522361803041977572204227262166","best_ask":"0.55","best_bid":"0.54","hash":"71f5b98f05056664fe11913b11862a72f9948058","price":"0.56","side":"SELL","size":"375.6"}],"timestamp":"1785122140032"},"payload_hash":"57a93896ac9e3546569b4d1401144b647b56145505e37ebe290d3bdd804b5d64","raw_frame":"{\"market\":\"0x717c0e8ccd4d5c7040185188fbae28be901ca589a11a94b1b38ca36a79eccfeb\", \"price_changes\":[{\"asset_id\":\"41448400836309843603620980831210604935021861034693225347475867885462478926555\", \"price\":\"0.44\", \"size\":\"375.6\", \"side\":\"BUY\", \"hash\":\"3d9b7f6ddbf1ee1fcc88818b71a75f601a2dd4be\", \"best_bid\":\"0.45\", \"best_ask\":\"0.46\"}, {\"asset_id\":\"24254094493625419915756280046002869097156693848522361803041977572204227262166\", \"price\":\"0.56\", \"size\":\"375.6\", \"side\":\"SELL\", \"hash\":\"71f5b98f05056664fe11913b11862a72f9948058\", \"best_bid\":\"0.54\", \"best_ask\":\"0.55\"}], \"timestamp\":\"1785122140032\", \"event_type\":\"price_change\"}","received_at":"2026-07-27T03:15:39.945095Z","schema_version":"clob-market-ws.price_change.v1","sequence":null,"server_hash":null,"server_timestamp":"1785122140032","session_id":"dd162b8dca5f43ff811d304e69a06123","source":"clob_market_ws"},"received_at":"2026-07-27T03:15:39.945095Z","record_id":"161367645d98d0e7f51d9d118cb585f65093b4c9023a4aac6dba990afcbfbc80","schema_fingerprint":"4aa3821a28b0b7c2400bc59aba4bcc0a76e971dadd19610d3ad38c768e124dc7","schema_version":"edge-lab-recorder.raw.v1","sequence":null,"source":"clob_market_ws"}
{"event_at":"2026-07-27T03:15:40.033000Z","event_fingerprint":"3d903a4ab95cd81b8bea3af7e89475bf534ac0b64f36b75d4c528f4afaef858a","payload":{"connection_id":"c7dc2e4762f849c6b6f9306b6518dcab","event_at":"2026-07-27T03:15:40.033000Z","event_type":"price_change","frame_hash":"cc0aa29e5c4d36cda8913f4bdc3ffb60bc734f516d8739483e253c400e3844c7","frame_index":0,"kind":"data","monotonic_ns":224123288886500,"payload":{"event_type":"price_change","market":"0x717c0e8ccd4d5c7040185188fbae28be901ca589a11a94b1b38ca36a79eccfeb","price_changes":[{"asset_id":"24254094493625419915756280046002869097156693848522361803041977572204227262166","best_ask":"0.55","best_bid":"0.54","hash":"9c04982b848c02da3b10a8fe75ae2ca38f5ea63d","price":"0.52","side":"BUY","size":"346.61"},{"asset_id":"41448400836309843603620980831210604935021861034693225347475867885462478926555","best_ask":"0.46","best_bid":"0.45","hash":"61e39df44f86d10cb51efedb6ac711b5c8cf4875","price":"0.48","side":"SELL","size":"346.61"}],"timestamp":"1785122140033"},"payload_hash":"fd6206cc2c3b6c0b02dcb983ca24305c3069d64bb12bf9b522feb2dc38d5f13f","raw_frame":"{\"market\":\"0x717c0e8ccd4d5c7040185188fbae28be901ca589a11a94b1b38ca36a79eccfeb\", \"price_changes\":[{\"asset_id\":\"24254094493625419915756280046002869097156693848522361803041977572204227262166\", \"price\":\"0.52\", \"size\":\"346.61\", \"side\":\"BUY\", \"hash\":\"9c04982b848c02da3b10a8fe75ae2ca38f5ea63d\", \"best_bid\":\"0.54\", \"best_ask\":\"0.55\"}, {\"asset_id\":\"41448400836309843603620980831210604935021861034693225347475867885462478926555\", \"price\":\"0.48\", \"size\":\"346.61\", \"side\":\"SELL\", \"hash\":\"61e39df44f86d10cb51efedb6ac711b5c8cf4875\", \"best_bid\":\"0.45\", \"best_ask\":\"0.46\"}], \"timestamp\":\"1785122140033\", \"event_type\":\"price_change\"}","received_at":"2026-07-27T03:15:39.954668Z","schema_version":"clob-market-ws.price_change.v1","sequence":null,"server_hash":null,"server_timestamp":"1785122140033","session_id":"dd162b8dca5f43ff811d304e69a06123","source":"clob_market_ws"},"received_at":"2026-07-27T03:15:39.954668Z","record_id":"a66ec56cb34bc4ae5fe4461e21a009767edd4c33e8b9ef82b05c59a4e7cda02f","schema_fingerprint":"4aa3821a28b0b7c2400bc59aba4bcc0a76e971dadd19610d3ad38c768e124dc7","schema_version":"edge-lab-recorder.raw.v1","sequence":null,"source":"clob_market_ws"}
{"event_at":"2026-07-27T03:15:40.035000Z","event_fingerprint":"3c2e25b939d0b2d16ea128463b819a392551f9de8915987b7b20e1b63311ebfd","payload":{"connection_id":"c7dc2e4762f849c6b6f9306b6518dcab","event_at":"2026-07-27T03:15:40.035000Z","event_type":"price_change","frame_hash":"e1c8971796a357e46ef1a601302724e70ea73276f1253b36410341c9047f4885","frame_index":0,"kind":"data","monotonic_ns":224123290509083,"payload":{"event_type":"price_change","market":"0x717c0e8ccd4d5c7040185188fbae28be901ca589a11a94b1b38ca36a79eccfeb","price_changes":[{"asset_id":"24254094493625419915756280046002869097156693848522361803041977572204227262166","best_ask":"0.55","best_bid":"0.54","hash":"86b75794df7b6061c97a660724673de473bc95c1","price":"0.53","side":"BUY","size":"124.43"},{"asset_id":"41448400836309843603620980831210604935021861034693225347475867885462478926555","best_ask":"0.46","best_bid":"0.45","hash":"75d7cef67fc78127c2d387e54015b0460a6f65c3","price":"0.47","side":"SELL","size":"124.43"}],"timestamp":"1785122140035"},"payload_hash":"aac32c4e7dec81e97dfaa07662cb8f6e6119b58d91cbd391bfcf21b858b139a0","raw_frame":"{\"market\":\"0x717c0e8ccd4d5c7040185188fbae28be901ca589a11a94b1b38ca36a79eccfeb\", \"price_changes\":[{\"asset_id\":\"24254094493625419915756280046002869097156693848522361803041977572204227262166\", \"price\":\"0.53\", \"size\":\"124.43\", \"side\":\"BUY\", \"hash\":\"86b75794df7b6061c97a660724673de473bc95c1\", \"best_bid\":\"0.54\", \"best_ask\":\"0.55\"}, {\"asset_id\":\"41448400836309843603620980831210604935021861034693225347475867885462478926555\", \"price\":\"0.47\", \"size\":\"124.43\", \"side\":\"SELL\", \"hash\":\"75d7cef67fc78127c2d387e54015b0460a6f65c3\", \"best_bid\":\"0.45\", \"best_ask\":\"0.46\"}], \"timestamp\":\"1785122140035\", \"event_type\":\"price_change\"}","received_at":"2026-07-27T03:15:39.956290Z","schema_version":"clob-market-ws.price_change.v1","sequence":null,"server_hash":null,"server_timestamp":"1785122140035","session_id":"dd162b8dca5f43ff811d304e69a06123","source":"clob_market_ws"},"received_at":"2026-07-27T03:15:39.956290Z","record_id":"725ff6b1190941e887ae61e5f701fcd88505c82ab74fc8f9ccae70c41376a270","schema_fingerprint":"4aa3821a28b0b7c2400bc59aba4bcc0a76e971dadd19610d3ad38c768e124dc7","schema_version":"edge-lab-recorder.raw.v1","sequence":null,"source":"clob_market_ws"}
{"event_at":"2026-07-27T03:15:40.036000Z","event_fingerprint":"8a9c6263a39ed315e90f1da6e1082b9ab48af76aaf56208e6a0e15d1da69677e","payload":{"connection_id":"c7dc2e4762f849c6b6f9306b6518dcab","event_at":"2026-07-27T03:15:40.036000Z","event_type":"best_bid_ask","frame_hash":"2cac9f512a47ff4c874d9a987d1cd1b5673009588f792f965420d92dafd8af7e","frame_index":0,"kind":"data","monotonic_ns":224123292197916,"payload":{"asset_id":"24254094493625419915756280046002869097156693848522361803041977572204227262166","best_ask":"0.56","best_bid":"0.54","event_type":"best_bid_ask","market":"0x717c0e8ccd4d5c7040185188fbae28be901ca589a11a94b1b38ca36a79eccfeb","spread":"0.02","timestamp":"1785122140036"},"payload_hash":"9ebfe6b3a520fac099a77eb4e574aab0924827b4426de41a0166d787f7fe4dea","raw_frame":"{\"market\":\"0x717c0e8ccd4d5c7040185188fbae28be901ca589a11a94b1b38ca36a79eccfeb\", \"asset_id\":\"24254094493625419915756280046002869097156693848522361803041977572204227262166\", \"best_bid\":\"0.54\", \"best_ask\":\"0.56\", \"spread\":\"0.02\", \"timestamp\":\"1785122140036\", \"event_type\":\"best_bid_ask\"}","received_at":"2026-07-27T03:15:39.957979Z","schema_version":"clob-market-ws.best_bid_ask.v1","sequence":null,"server_hash":null,"server_timestamp":"1785122140036","session_id":"dd162b8dca5f43ff811d304e69a06123","source":"clob_market_ws"},"received_at":"2026-07-27T03:15:39.957979Z","record_id":"4729f2b9c5176e34b2764a67bb44ab8bf5af9deba356fa030495aff7d4702d69","schema_fingerprint":"8488399f31b0337811b13b266be932db7062827c2470b78bd8e9e99bab51d17d","schema_version":"edge-lab-recorder.raw.v1","sequence":null,"source":"clob_market_ws"}
{"event_at":"2026-07-27T03:15:40.036000Z","event_fingerprint":"1354453ae8799ee352b1e7e2124caf25848563dc27c9e4c0e7b48e68ec49a7da","payload":{"connection_id":"c7dc2e4762f849c6b6f9306b6518dcab","event_at":"2026-07-27T03:15:40.036000Z","event_type":"best_bid_ask","frame_hash":"484b9eb52cbe265d53a1e380a4378fa592c405801bbafc761392d3cf9c883482","frame_index":0,"kind":"data","monotonic_ns":224123293651750,"payload":{"asset_id":"41448400836309843603620980831210604935021861034693225347475867885462478926555","best_ask":"0.46","best_bid":"0.44","event_type":"best_bid_ask","market":"0x717c0e8ccd4d5c7040185188fbae28be901ca589a11a94b1b38ca36a79eccfeb","spread":"0.02","timestamp":"1785122140036"},"payload_hash":"46358e7603a01746536f2e6ba5ddb6484396343d8be2d5f36dec82879a09b916","raw_frame":"{\"market\":\"0x717c0e8ccd4d5c7040185188fbae28be901ca589a11a94b1b38ca36a79eccfeb\", \"asset_id\":\"41448400836309843603620980831210604935021861034693225347475867885462478926555\", \"best_bid\":\"0.44\", \"best_ask\":\"0.46\", \"spread\":\"0.02\", \"timestamp\":\"1785122140036\", \"event_type\":\"best_bid_ask\"}","received_at":"2026-07-27T03:15:39.959433Z","schema_version":"clob-market-ws.best_bid_ask.v1","sequence":null,"server_hash":null,"server_timestamp":"1785122140036","session_id":"dd162b8dca5f43ff811d304e69a06123","source":"clob_market_ws"},"received_at":"2026-07-27T03:15:39.959433Z","record_id":"6357f4a474bffab894372b38935df01aefb4b0b3387d5ff58c2c672fff75b659","schema_fingerprint":"8488399f31b0337811b13b266be932db7062827c2470b78bd8e9e99bab51d17d","schema_version":"edge-lab-recorder.raw.v1","sequence":null,"source":"clob_market_ws"}
{"event_at":"2026-07-27T03:15:40.036000Z","event_fingerprint":"e990d28303d6fb1784ced63c10ffd35adcc696c2c0c9dfbb1d6c3dbaeae661aa","payload":{"connection_id":"c7dc2e4762f849c6b6f9306b6518dcab","event_at":"2026-07-27T03:15:40.036000Z","event_type":"price_change","frame_hash":"15d567e22d119e3483bb60c2d57609701f2b01372116023e9762280c1dcd5a46","frame_index":0,"kind":"data","monotonic_ns":224123295470458,"payload":{"event_type":"price_change","market":"0x717c0e8ccd4d5c7040185188fbae28be901ca589a11a94b1b38ca36a79eccfeb","price_changes":[{"asset_id":"41448400836309843603620980831210604935021861034693225347475867885462478926555","best_ask":"0.46","best_bid":"0.44","hash":"97f93b6b1f7b03c4c79f7a96331e583ebe5db227","price":"0.45","side":"BUY","size":"0"},{"asset_id":"24254094493625419915756280046002869097156693848522361803041977572204227262166","best_ask":"0.56","best_bid":"0.54","hash":"074c3140df9eb7d2c9b4a0402d2ede397263c4d0","price":"0.55","side":"SELL","size":"0"}],"timestamp":"1785122140036"},"payload_hash":"2b5b64194f1ea0408ad2585168696b14c91535fc908f8c4d8694ae008a69d90d","raw_frame":"{\"market\":\"0x717c0e8ccd4d5c7040185188fbae28be901ca589a11a94b1b38ca36a79eccfeb\", \"price_changes\":[{\"asset_id\":\"41448400836309843603620980831210604935021861034693225347475867885462478926555\", \"price\":\"0.45\", \"size\":\"0\", \"side\":\"BUY\", \"hash\":\"97f93b6b1f7b03c4c79f7a96331e583ebe5db227\", \"best_bid\":\"0.44\", \"best_ask\":\"0.46\"}, {\"asset_id\":\"24254094493625419915756280046002869097156693848522361803041977572204227262166\", \"price\":\"0.55\", \"size\":\"0\", \"side\":\"SELL\", \"hash\":\"074c3140df9eb7d2c9b4a0402d2ede397263c4d0\", \"best_bid\":\"0.54\", \"best_ask\":\"0.56\"}], \"timestamp\":\"1785122140036\", \"event_type\":\"price_change\"}","received_at":"2026-07-27T03:15:39.961252Z","schema_version":"clob-market-ws.price_change.v1","sequence":null,"server_hash":null,"server_timestamp":"1785122140036","session_id":"dd162b8dca5f43ff811d304e69a06123","source":"clob_market_ws"},"received_at":"2026-07-27T03:15:39.961252Z","record_id":"817f6cb978e8cff5e26ebd4125924280ab72db7d9c0b3d3e0a2d8b8e54ff34bd","schema_fingerprint":"4aa3821a28b0b7c2400bc59aba4bcc0a76e971dadd19610d3ad38c768e124dc7","schema_version":"edge-lab-recorder.raw.v1","sequence":null,"source":"clob_market_ws"}
{"event_at":"2026-07-27T03:15:40.039000Z","event_fingerprint":"0c3c46ae5b0439da97de322af9c766d4e5efc709a09c82492cc9868799c6ea9e","payload":{"connection_id":"c7dc2e4762f849c6b6f9306b6518dcab","event_at":"2026-07-27T03:15:40.039000Z","event_type":"price_change","frame_hash":"e31e84353e34fae62ad1f90b317cb90c2056e1806db6590fd4e2f1315ccb416a","frame_index":0,"kind":"data","monotonic_ns":224123298252208,"payload":{"event_type":"price_change","market":"0x717c0e8ccd4d5c7040185188fbae28be901ca589a11a94b1b38ca36a79eccfeb","price_changes":[{"asset_id":"41448400836309843603620980831210604935021861034693225347475867885462478926555","best_ask":"0.46","best_bid":"0.44","hash":"ef141b90a68de95f63111bf7992d987948192703","price":"0.01","side":"BUY","size":"7708.02"},{"asset_id":"24254094493625419915756280046002869097156693848522361803041977572204227262166","best_ask":"0.56","best_bid":"0.54","hash":"302bd383a3363e9121705e786e491528ec809d85","price":"0.99","side":"SELL","size":"7708.02"}],"timestamp":"1785122140039"},"payload_hash":"7af873b946bdf4ccf5f36a410db3c0ca8ee842a8ed66fc2ea74fd537839b6586","raw_frame":"{\"market\":\"0x717c0e8ccd4d5c7040185188fbae28be901ca589a11a94b1b38ca36a79eccfeb\", \"price_changes\":[{\"asset_id\":\"41448400836309843603620980831210604935021861034693225347475867885462478926555\", \"price\":\"0.01\", \"size\":\"7708.02\", \"side\":\"BUY\", \"hash\":\"ef141b90a68de95f63111bf7992d987948192703\", \"best_bid\":\"0.44\", \"best_ask\":\"0.46\"}, {\"asset_id\":\"24254094493625419915756280046002869097156693848522361803041977572204227262166\", \"price\":\"0.99\", \"size\":\"7708.02\", \"side\":\"SELL\", \"hash\":\"302bd383a3363e9121705e786e491528ec809d85\", \"best_bid\":\"0.54\", \"best_ask\":\"0.56\"}], \"timestamp\":\"1785122140039\", \"event_type\":\"price_change\"}","received_at":"2026-07-27T03:15:39.964034Z","schema_version":"clob-market-ws.price_change.v1","sequence":null,"server_hash":null,"server_timestamp":"1785122140039","session_id":"dd162b8dca5f43ff811d304e69a06123","source":"clob_market_ws"},"received_at":"2026-07-27T03:15:39.964034Z","record_id":"b69ddabe08d937a0916e28c1e398da95321b09b6793d189ea2f46f4f695de73e","schema_fingerprint":"4aa3821a28b0b7c2400bc59aba4bcc0a76e971dadd19610d3ad38c768e124dc7","schema_version":"edge-lab-recorder.raw.v1","sequence":null,"source":"clob_market_ws"}
{"event_at":"2026-07-27T03:15:40.040000Z","event_fingerprint":"be5389006b84c17df8fa950d350d3eb40559493613096d1af7ed705968076f0a","payload":{"connection_id":"c7dc2e4762f849c6b6f9306b6518dcab","event_at":"2026-07-27T03:15:40.040000Z","event_type":"price_change","frame_hash":"c640487faa5cb0d9b794223a9215627ef6666d83e728b291de1b2d1fedbbdd64","frame_index":0,"kind":"data","monotonic_ns":224123302131208,"payload":{"event_type":"price_change","market":"0x717c0e8ccd4d5c7040185188fbae28be901ca589a11a94b1b38ca36a79eccfeb","price_changes":[{"asset_id":"24254094493625419915756280046002869097156693848522361803041977572204227262166","best_ask":"0.56","best_bid":"0.54","hash":"6545bd3f5becad582d7f45823d20ba494b2cfeae","price":"0.54","side":"BUY","size":"77.18"},{"asset_id":"41448400836309843603620980831210604935021861034693225347475867885462478926555","best_ask":"0.46","best_bid":"0.44","hash":"5b1e4cb06509e7a5e3fb8d6607a1a4fcfc05c748","price":"0.46","side":"SELL","size":"77.18"}],"timestamp":"1785122140040"},"payload_hash":"63622a1272256a7d701d7b6b3b28bc848046b212c5ebe4cfa5764864d4c57f76","raw_frame":"{\"market\":\"0x717c0e8ccd4d5c7040185188fbae28be901ca589a11a94b1b38ca36a79eccfeb\", \"price_changes\":[{\"asset_id\":\"24254094493625419915756280046002869097156693848522361803041977572204227262166\", \"price\":\"0.54\", \"size\":\"77.18\", \"side\":\"BUY\", \"hash\":\"6545bd3f5becad582d7f45823d20ba494b2cfeae\", \"best_bid\":\"0.54\", \"best_ask\":\"0.56\"}, {\"asset_id\":\"41448400836309843603620980831210604935021861034693225347475867885462478926555\", \"price\":\"0.46\", \"size\":\"77.18\", \"side\":\"SELL\", \"hash\":\"5b1e4cb06509e7a5e3fb8d6607a1a4fcfc05c748\", \"best_bid\":\"0.44\", \"best_ask\":\"0.46\"}], \"timestamp\":\"1785122140040\", \"event_type\":\"price_change\"}","received_at":"2026-07-27T03:15:39.967905Z","schema_version":"clob-market-ws.price_change.v1","sequence":null,"server_hash":null,"server_timestamp":"1785122140040","session_id":"dd162b8dca5f43ff811d304e69a06123","source":"clob_market_ws"},"received_at":"2026-07-27T03:15:39.967905Z","record_id":"efe44944d8c8f71411ca9c594fe8aae8a4df69bc8c615f5899904bca3128b163","schema_fingerprint":"4aa3821a28b0b7c2400bc59aba4bcc0a76e971dadd19610d3ad38c768e124dc7","schema_version":"edge-lab-recorder.raw.v1","sequence":null,"source":"clob_market_ws"}
{"event_at":"2026-07-27T03:15:40.050000Z","event_fingerprint":"c0f56f41b7adf1d8e5336656230b533bab82b9cc11f277fe1bf40feb2bb26925","payload":{"connection_id":"c7dc2e4762f849c6b6f9306b6518dcab","event_at":"2026-07-27T03:15:40.050000Z","event_type":"price_change","frame_hash":"19dd1c3da23a3253941c96d60f848ecc218352ccc9f0dce83952ff60e49c1798","frame_index":0,"kind":"data","monotonic_ns":224123317106458,"payload":{"event_type":"price_change","market":"0x717c0e8ccd4d5c7040185188fbae28be901ca589a11a94b1b38ca36a79eccfeb","price_changes":[{"asset_id":"24254094493625419915756280046002869097156693848522361803041977572204227262166","best_ask":"0.56","best_bid":"0.54","hash":"9b0bcb952f44a1f850ee886b5e73748e86773b51","price":"0.01","side":"BUY","size":"7713.02"},{"asset_id":"41448400836309843603620980831210604935021861034693225347475867885462478926555","best_ask":"0.46","best_bid":"0.44","hash":"0d205f510166104769b52ff1a2841c00dc7386f9","price":"0.99","side":"SELL","size":"7713.02"}],"timestamp":"1785122140050"},"payload_hash":"2ac1aacc31c919295df42adfea5f7778dac9418384c366c3c10efe4ec0cc7301","raw_frame":"{\"market\":\"0x717c0e8ccd4d5c7040185188fbae28be901ca589a11a94b1b38ca36a79eccfeb\", \"price_changes\":[{\"asset_id\":\"24254094493625419915756280046002869097156693848522361803041977572204227262166\", \"price\":\"0.01\", \"size\":\"7713.02\", \"side\":\"BUY\", \"hash\":\"9b0bcb952f44a1f850ee886b5e73748e86773b51\", \"best_bid\":\"0.54\", \"best_ask\":\"0.56\"}, {\"asset_id\":\"41448400836309843603620980831210604935021861034693225347475867885462478926555\", \"price\":\"0.99\", \"size\":\"7713.02\", \"side\":\"SELL\", \"hash\":\"0d205f510166104769b52ff1a2841c00dc7386f9\", \"best_bid\":\"0.44\", \"best_ask\":\"0.46\"}], \"timestamp\":\"1785122140050\", \"event_type\":\"price_change\"}","received_at":"2026-07-27T03:15:39.982878Z","schema_version":"clob-market-ws.price_change.v1","sequence":null,"server_hash":null,"server_timestamp":"1785122140050","session_id":"dd162b8dca5f43ff811d304e69a06123","source":"clob_market_ws"},"received_at":"2026-07-27T03:15:39.982878Z","record_id":"d5a1d16ba2c23ab12800690558aec48cccd01cea48defba7c42ff930859e8a35","schema_fingerprint":"4aa3821a28b0b7c2400bc59aba4bcc0a76e971dadd19610d3ad38c768e124dc7","schema_version":"edge-lab-recorder.raw.v1","sequence":null,"source":"clob_market_ws"}
{"event_at":"2026-07-27T03:15:40.055000Z","event_fingerprint":"0d8440522c50352c407cc52640acf5af70c781d273b829b4d30db0501eb7fe25","payload":{"connection_id":"c7dc2e4762f849c6b6f9306b6518dcab","event_at":"2026-07-27T03:15:40.055000Z","event_type":"price_change","frame_hash":"292e0abaaab6c785297af0b366a3afff979d1617f3de84c9915dc1d77ee0ee68","frame_index":0,"kind":"data","monotonic_ns":224123320998875,"payload":{"event_type":"price_change","market":"0x717c0e8ccd4d5c7040185188fbae28be901ca589a11a94b1b38ca36a79eccfeb","price_changes":[{"asset_id":"24254094493625419915756280046002869097156693848522361803041977572204227262166","best_ask":"0.56","best_bid":"0.54","hash":"dd61897cbf3cc0dbdc039fe54b7ce6d561785927","price":"0.54","side":"BUY","size":"71.18"},{"asset_id":"41448400836309843603620980831210604935021861034693225347475867885462478926555","best_ask":"0.46","best_bid":"0.44","hash":"7d7e6a6a3035f80a2904e69b79af11b00d2f4b05","price":"0.46","side":"SELL","size":"71.18"}],"timestamp":"1785122140055"},"payload_hash":"673257ee3cdb866ec3c3961a1841d43ae6c63bc11747e759dc8ec1d429197b5b","raw_frame":"{\"market\":\"0x717c0e8ccd4d5c7040185188fbae28be901ca589a11a94b1b38ca36a79eccfeb\", \"price_changes\":[{\"asset_id\":\"24254094493625419915756280046002869097156693848522361803041977572204227262166\", \"price\":\"0.54\", \"size\":\"71.18\", \"side\":\"BUY\", \"hash\":\"dd61897cbf3cc0dbdc039fe54b7ce6d561785927\", \"best_bid\":\"0.54\", \"best_ask\":\"0.56\"}, {\"asset_id\":\"41448400836309843603620980831210604935021861034693225347475867885462478926555\", \"price\":\"0.46\", \"size\":\"71.18\", \"side\":\"SELL\", \"hash\":\"7d7e6a6a3035f80a2904e69b79af11b00d2f4b05\", \"best_bid\":\"0.44\", \"best_ask\":\"0.46\"}], \"timestamp\":\"1785122140055\", \"event_type\":\"price_change\"}","received_at":"2026-07-27T03:15:39.986780Z","schema_version":"clob-market-ws.price_change.v1","sequence":null,"server_hash":null,"server_timestamp":"1785122140055","session_id":"dd162b8dca5f43ff811d304e69a06123","source":"clob_market_ws"},"received_at":"2026-07-27T03:15:39.986780Z","record_id":"2590855becca0b119bfb2f3bc5adda5e9db2fcddd78abef7b3e72701f0763be8","schema_fingerprint":"4aa3821a28b0b7c2400bc59aba4bcc0a76e971dadd19610d3ad38c768e124dc7","schema_version":"edge-lab-recorder.raw.v1","sequence":null,"source":"clob_market_ws"}
{"event_at":"2026-07-27T03:15:40.056000Z","event_fingerprint":"43bb35f8a88613f19df287aed7300e355b1e35595d2c7288226266da3249e00f","payload":{"connection_id":"c7dc2e4762f849c6b6f9306b6518dcab","event_at":"2026-07-27T03:15:40.056000Z","event_type":"price_change","frame_hash":"2cbd8c805ec230cfb7be6ae63a64e95a20b2385db9ed3a5e064b56bb7df2feb2","frame_index":0,"kind":"data","monotonic_ns":224123322337375,"payload":{"event_type":"price_change","market":"0x717c0e8ccd4d5c7040185188fbae28be901ca589a11a94b1b38ca36a79eccfeb","price_changes":[{"asset_id":"41448400836309843603620980831210604935021861034693225347475867885462478926555","best_ask":"0.46","best_bid":"0.44","hash":"afab8e36b14226043a912936c7cafdf72826496d","price":"0.46","side":"SELL","size":"79.18"},{"asset_id":"24254094493625419915756280046002869097156693848522361803041977572204227262166","best_ask":"0.56","best_bid":"0.54","hash":"bc4a0f0f95be9c0c1c946e66a5c0f9080ff4dd09","price":"0.54","side":"BUY","size":"79.18"}],"timestamp":"1785122140056"},"payload_hash":"65686f9f87c864bba11d789fa7153d5f33d7a56a24f67189fc4eb718f15c83b2","raw_frame":"{\"market\":\"0x717c0e8ccd4d5c7040185188fbae28be901ca589a11a94b1b38ca36a79eccfeb\", \"price_changes\":[{\"asset_id\":\"41448400836309843603620980831210604935021861034693225347475867885462478926555\", \"price\":\"0.46\", \"size\":\"79.18\", \"side\":\"SELL\", \"hash\":\"afab8e36b14226043a912936c7cafdf72826496d\", \"best_bid\":\"0.44\", \"best_ask\":\"0.46\"}, {\"asset_id\":\"24254094493625419915756280046002869097156693848522361803041977572204227262166\", \"price\":\"0.54\", \"size\":\"79.18\", \"side\":\"BUY\", \"hash\":\"bc4a0f0f95be9c0c1c946e66a5c0f9080ff4dd09\", \"best_bid\":\"0.54\", \"best_ask\":\"0.56\"}], \"timestamp\":\"1785122140056\", \"event_type\":\"price_change\"}","received_at":"2026-07-27T03:15:39.988112Z","schema_version":"clob-market-ws.price_change.v1","sequence":null,"server_hash":null,"server_timestamp":"1785122140056","session_id":"dd162b8dca5f43ff811d304e69a06123","source":"clob_market_ws"},"received_at":"2026-07-27T03:15:39.988112Z","record_id":"2b478894484d4b6a542f3cc7b965e2c3a0c8ce4783b942f96fbc726d23e3c332","schema_fingerprint":"4aa3821a28b0b7c2400bc59aba4bcc0a76e971dadd19610d3ad38c768e124dc7","schema_version":"edge-lab-recorder.raw.v1","sequence":null,"source":"clob_market_ws"}
{"event_at":"2026-07-27T03:15:40.060000Z","event_fingerprint":"fedc5d149855d4e89053bef6edc57d1ab9636e29fe4c419bbb5b5a3663f8142c","payload":{"connection_id":"c7dc2e4762f849c6b6f9306b6518dcab","event_at":"2026-07-27T03:15:40.060000Z","event_type":"price_change","frame_hash":"18faae88c57777da12abaf4258be49b7914e8a293cd26bbc592f5dd196e3eff0","frame_index":0,"kind":"data","monotonic_ns":224123327367416,"payload":{"event_type":"price_change","market":"0x717c0e8ccd4d5c7040185188fbae28be901ca589a11a94b1b38ca36a79eccfeb","price_changes":[{"asset_id":"24254094493625419915756280046002869097156693848522361803041977572204227262166","best_ask":"0.56","best_bid":"0.54","hash":"b7ae7fad504204f07d35038ef4545c54a88ca832","price":"0.54","side":"BUY","size":"87.18"},{"asset_id":"41448400836309843603620980831210604935021861034693225347475867885462478926555","best_ask":"0.46","best_bid":"0.44","hash":"fa4df83c29b10abfa911c037ac10c63804d5dfde","price":"0.46","side":"SELL","size":"87.18"}],"timestamp":"1785122140060"},"payload_hash":"6f8911cd7895f41195ad8b56167a6191f9cab41581e4d725a84ee9680dc0e8c4","raw_frame":"{\"market\":\"0x717c0e8ccd4d5c7040185188fbae28be901ca589a11a94b1b38ca36a79eccfeb\", \"price_changes\":[{\"asset_id\":\"24254094493625419915756280046002869097156693848522361803041977572204227262166\", \"price\":\"0.54\", \"size\":\"87.18\", \"side\":\"BUY\", \"hash\":\"b7ae7fad504204f07d35038ef4545c54a88ca832\", \"best_bid\":\"0.54\", \"best_ask\":\"0.56\"}, {\"asset_id\":\"41448400836309843603620980831210604935021861034693225347475867885462478926555\", \"price\":\"0.46\", \"size\":\"87.18\", \"side\":\"SELL\", \"hash\":\"fa4df83c29b10abfa911c037ac10c63804d5dfde\", \"best_bid\":\"0.44\", \"best_ask\":\"0.46\"}], \"timestamp\":\"1785122140060\", \"event_type\":\"price_change\"}","received_at":"2026-07-27T03:15:39.993149Z","schema_version":"clob-market-ws.price_change.v1","sequence":null,"server_hash":null,"server_timestamp":"1785122140060","session_id":"dd162b8dca5f43ff811d304e69a06123","source":"clob_market_ws"},"received_at":"2026-07-27T03:15:39.993149Z","record_id":"4e6bbba666d4f5ab4109fa0d054a723648cfb70d295f2cd925a375bb92f56cd9","schema_fingerprint":"4aa3821a28b0b7c2400bc59aba4bcc0a76e971dadd19610d3ad38c768e124dc7","schema_version":"edge-lab-recorder.raw.v1","sequence":null,"source":"clob_market_ws"}
{"event_at":"2026-07-27T03:15:40.061000Z","event_fingerprint":"95a380accd43a259653fec5143778fea3efee9aad8e806b01280ed8eeb9007e7","payload":{"connection_id":"c7dc2e4762f849c6b6f9306b6518dcab","event_at":"2026-07-27T03:15:40.061000Z","event_type":"price_change","frame_hash":"8f3ee5e31ce62d72068450f7da6e3df4561ac09f22049993ee099151340254e7","frame_index":0,"kind":"data","monotonic_ns":224123334017166,"payload":{"event_type":"price_change","market":"0x717c0e8ccd4d5c7040185188fbae28be901ca589a11a94b1b38ca36a79eccfeb","price_changes":[{"asset_id":"24254094493625419915756280046002869097156693848522361803041977572204227262166","best_ask":"0.56","best_bid":"0.54","hash":"143fde1df9fe8fdb14d240592db1824ac134fd47","price":"0.54","side":"BUY","size":"79.18"},{"asset_id":"41448400836309843603620980831210604935021861034693225347475867885462478926555","best_ask":"0.46","best_bid":"0.44","hash":"8a5441505ef5749f113a52526c21a4f4b1b68394","price":"0.46","side":"SELL","size":"79.18"}],"timestamp":"1785122140061"},"payload_hash":"9dbbcf5b1649a40a693f2f478bacf2e5c809553a4d8d98601729442ba92a49d0","raw_frame":"{\"market\":\"0x717c0e8ccd4d5c7040185188fbae28be901ca589a11a94b1b38ca36a79eccfeb\", \"price_changes\":[{\"asset_id\":\"24254094493625419915756280046002869097156693848522361803041977572204227262166\", \"price\":\"0.54\", \"size\":\"79.18\", \"side\":\"BUY\", \"hash\":\"143fde1df9fe8fdb14d240592db1824ac134fd47\", \"best_bid\":\"0.54\", \"best_ask\":\"0.56\"}, {\"asset_id\":\"41448400836309843603620980831210604935021861034693225347475867885462478926555\", \"price\":\"0.46\", \"size\":\"79.18\", \"side\":\"SELL\", \"hash\":\"8a5441505ef5749f113a52526c21a4f4b1b68394\", \"best_bid\":\"0.44\", \"best_ask\":\"0.46\"}], \"timestamp\":\"1785122140061\", \"event_type\":\"price_change\"}","received_at":"2026-07-27T03:15:39.999793Z","schema_version":"clob-market-ws.price_change.v1","sequence":null,"server_hash":null,"server_timestamp":"1785122140061","session_id":"dd162b8dca5f43ff811d304e69a06123","source":"clob_market_ws"},"received_at":"2026-07-27T03:15:39.999793Z","record_id":"ef9624f2e947d386262cebff32903c4d4614d42e25fc1b864ee3962fdb2c4791","schema_fingerprint":"4aa3821a28b0b7c2400bc59aba4bcc0a76e971dadd19610d3ad38c768e124dc7","schema_version":"edge-lab-recorder.raw.v1","sequence":null,"source":"clob_market_ws"}
{"event_at":"2026-07-27T03:15:40.062000Z","event_fingerprint":"94b42bad3fa75a048ebbe464336810eef2e452e0673272a61fdc7cb8a3d8f7f2","payload":{"connection_id":"c7dc2e4762f849c6b6f9306b6518dcab","event_at":"2026-07-27T03:15:40.062000Z","event_type":"best_bid_ask","frame_hash":"a2af0f3accfdaab4f6e768b80bd1d54618faa815f062cf377b2f7ecf37a5c1f9","frame_index":0,"kind":"data","monotonic_ns":224123338536625,"payload":{"asset_id":"24254094493625419915756280046002869097156693848522361803041977572204227262166","best_ask":"0.56","best_bid":"0.55","event_type":"best_bid_ask","market":"0x717c0e8ccd4d5c7040185188fbae28be901ca589a11a94b1b38ca36a79eccfeb","spread":"0.01","timestamp":"1785122140062"},"payload_hash":"d4e90d1f076d8162b6373bc6e705baaf11d97369b9ea279eb6cd4284c3042a3b","raw_frame":"{\"market\":\"0x717c0e8ccd4d5c7040185188fbae28be901ca589a11a94b1b38ca36a79eccfeb\", \"asset_id\":\"24254094493625419915756280046002869097156693848522361803041977572204227262166\", \"best_bid\":\"0.55\", \"best_ask\":\"0.56\", \"spread\":\"0.01\", \"timestamp\":\"1785122140062\", \"event_type\":\"best_bid_ask\"}","received_at":"2026-07-27T03:15:40.004317Z","schema_version":"clob-market-ws.best_bid_ask.v1","sequence":null,"server_hash":null,"server_timestamp":"1785122140062","session_id":"dd162b8dca5f43ff811d304e69a06123","source":"clob_market_ws"},"received_at":"2026-07-27T03:15:40.004317Z","record_id":"2b28c7d77152070c9839321facfe82d795f4a942225e7ef70077c1d5a8796a08","schema_fingerprint":"8488399f31b0337811b13b266be932db7062827c2470b78bd8e9e99bab51d17d","schema_version":"edge-lab-recorder.raw.v1","sequence":null,"source":"clob_market_ws"}
{"event_at":"2026-07-27T03:15:40.062000Z","event_fingerprint":"614baf976f57d769b4743111dc3f8788a84a5ceedeb7f49b35e584290a1a2513","payload":{"connection_id":"c7dc2e4762f849c6b6f9306b6518dcab","event_at":"2026-07-27T03:15:40.062000Z","event_type":"best_bid_ask","frame_hash":"16465aa0b80cdd57a59f5142f6d9e00e6bfea282f24c28654302ad986235a17e","frame_index":0,"kind":"data","monotonic_ns":224123341607791,"payload":{"asset_id":"41448400836309843603620980831210604935021861034693225347475867885462478926555","best_ask":"0.45","best_bid":"0.44","event_type":"best_bid_ask","market":"0x717c0e8ccd4d5c7040185188fbae28be901ca589a11a94b1b38ca36a79eccfeb","spread":"0.01","timestamp":"1785122140062"},"payload_hash":"486f977c3d2cb57243daf476d3c1803ef4411341ae826e849bfe8a88aa8fa7de","raw_frame":"{\"market\":\"0x717c0e8ccd4d5c7040185188fbae28be901ca589a11a94b1b38ca36a79eccfeb\", \"asset_id\":\"41448400836309843603620980831210604935021861034693225347475867885462478926555\", \"best_bid\":\"0.44\", \"best_ask\":\"0.45\", \"spread\":\"0.01\", \"timestamp\":\"1785122140062\", \"event_type\":\"best_bid_ask\"}","received_at":"2026-07-27T03:15:40.007389Z","schema_version":"clob-market-ws.best_bid_ask.v1","sequence":null,"server_hash":null,"server_timestamp":"1785122140062","session_id":"dd162b8dca5f43ff811d304e69a06123","source":"clob_market_ws"},"received_at":"2026-07-27T03:15:40.007389Z","record_id":"4db828f25568b966f2a5aba551d6bbbed10623937e895b64d928b1f6b074dbb5","schema_fingerprint":"8488399f31b0337811b13b266be932db7062827c2470b78bd8e9e99bab51d17d","schema_version":"edge-lab-recorder.raw.v1","sequence":null,"source":"clob_market_ws"}
{"event_at":"2026-07-27T03:15:40.062000Z","event_fingerprint":"ab4965c212356b5b36297ac7f573cf4fa9116da14f8dbb3b0b7f36f126e5d6f9","payload":{"connection_id":"c7dc2e4762f849c6b6f9306b6518dcab","event_at":"2026-07-27T03:15:40.062000Z","event_type":"price_change","frame_hash":"7ae72a5814c95e2735cd566c39e5644275f425fe4058caba505197e75dc31e79","frame_index":0,"kind":"data","monotonic_ns":224123345023833,"payload":{"event_type":"price_change","market":"0x717c0e8ccd4d5c7040185188fbae28be901ca589a11a94b1b38ca36a79eccfeb","price_changes":[{"asset_id":"24254094493625419915756280046002869097156693848522361803041977572204227262166","best_ask":"0.56","best_bid":"0.55","hash":"0788e629d964486eaf2bcd43945d6d251898a912","price":"0.55","side":"BUY","size":"5"},{"asset_id":"41448400836309843603620980831210604935021861034693225347475867885462478926555","best_ask":"0.45","best_bid":"0.44","hash":"609a4afa6b813063fe029148fa5703f6947f9eb1","price":"0.45","side":"SELL","size":"5"}],"timestamp":"1785122140062"},"payload_hash":"934ab1b95bb5d139277f9145a7edc4df87b659bdd2df8b8dc46ce59552c4c409","raw_frame":"{\"market\":\"0x717c0e8ccd4d5c7040185188fbae28be901ca589a11a94b1b38ca36a79eccfeb\", \"price_changes\":[{\"asset_id\":\"24254094493625419915756280046002869097156693848522361803041977572204227262166\", \"price\":\"0.55\", \"size\":\"5\", \"side\":\"BUY\", \"hash\":\"0788e629d964486eaf2bcd43945d6d251898a912\", \"best_bid\":\"0.55\", \"best_ask\":\"0.56\"}, {\"asset_id\":\"41448400836309843603620980831210604935021861034693225347475867885462478926555\", \"price\":\"0.45\", \"size\":\"5\", \"side\":\"SELL\", \"hash\":\"609a4afa6b813063fe029148fa5703f6947f9eb1\", \"best_bid\":\"0.44\", \"best_ask\":\"0.45\"}], \"timestamp\":\"1785122140062\", \"event_type\":\"price_change\"}","received_at":"2026-07-27T03:15:40.010804Z","schema_version":"clob-market-ws.price_change.v1","sequence":null,"server_hash":null,"server_timestamp":"1785122140062","session_id":"dd162b8dca5f43ff811d304e69a06123","source":"clob_market_ws"},"received_at":"2026-07-27T03:15:40.010804Z","record_id":"d17ab665090ea78d802e66032dfdd78b65b93745000051b078f4b9e8fc4b8975","schema_fingerprint":"4aa3821a28b0b7c2400bc59aba4bcc0a76e971dadd19610d3ad38c768e124dc7","schema_version":"edge-lab-recorder.raw.v1","sequence":null,"source":"clob_market_ws"}
{"event_at":"2026-07-27T03:15:40.063000Z","event_fingerprint":"80bf7b18617e3949462293e8ad719d17584acc06093dcfdbebf8c380fb511a89","payload":{"connection_id":"c7dc2e4762f849c6b6f9306b6518dcab","event_at":"2026-07-27T03:15:40.063000Z","event_type":"price_change","frame_hash":"8d5983a323d41494e9e860b80a42ad90323774ff2310f403dfbd671fa7cd2b76","frame_index":0,"kind":"data","monotonic_ns":224123348404083,"payload":{"event_type":"price_change","market":"0x717c0e8ccd4d5c7040185188fbae28be901ca589a11a94b1b38ca36a79eccfeb","price_changes":[{"asset_id":"41448400836309843603620980831210604935021861034693225347475867885462478926555","best_ask":"0.45","best_bid":"0.44","hash":"02118dc08ab571be474d13421371b82f6c4c883c","price":"0.44","side":"BUY","size":"392.4"},{"asset_id":"24254094493625419915756280046002869097156693848522361803041977572204227262166","best_ask":"0.56","best_bid":"0.55","hash":"6e7c2b10f13e63396408517dd5e4dfcf084f81c6","price":"0.56","side":"SELL","size":"392.4"}],"timestamp":"1785122140063"},"payload_hash":"aa0f7909fbb4035815a571392cb8bd6f46e57e2ef72c12323ab8aec01abe87e4","raw_frame":"{\"market\":\"0x717c0e8ccd4d5c7040185188fbae28be901ca589a11a94b1b38ca36a79eccfeb\", \"price_changes\":[{\"asset_id\":\"41448400836309843603620980831210604935021861034693225347475867885462478926555\", \"price\":\"0.44\", \"size\":\"392.4\", \"side\":\"BUY\", \"hash\":\"02118dc08ab571be474d13421371b82f6c4c883c\", \"best_bid\":\"0.44\", \"best_ask\":\"0.45\"}, {\"asset_id\":\"24254094493625419915756280046002869097156693848522361803041977572204227262166\", \"price\":\"0.56\", \"size\":\"392.4\", \"side\":\"SELL\", \"hash\":\"6e7c2b10f13e63396408517dd5e4dfcf084f81c6\", \"best_bid\":\"0.55\", \"best_ask\":\"0.56\"}], \"timestamp\":\"1785122140063\", \"event_type\":\"price_change\"}","received_at":"2026-07-27T03:15:40.014178Z","schema_version":"clob-market-ws.price_change.v1","sequence":null,"server_hash":null,"server_timestamp":"1785122140063","session_id":"dd162b8dca5f43ff811d304e69a06123","source":"clob_market_ws"},"received_at":"2026-07-27T03:15:40.014178Z","record_id":"e8ba7d6ef88c165d8c0080fbb082af370b5b85b450a77ada01918aba40c57bbd","schema_fingerprint":"4aa3821a28b0b7c2400bc59aba4bcc0a76e971dadd19610d3ad38c768e124dc7","schema_version":"edge-lab-recorder.raw.v1","sequence":null,"source":"clob_market_ws"}
{"event_at":"2026-07-27T03:15:40.064000Z","event_fingerprint":"7b5f9ea38541f7c5757f48590605e86326a45611fb16815c179164c833277059","payload":{"connection_id":"c7dc2e4762f849c6b6f9306b6518dcab","event_at":"2026-07-27T03:15:40.064000Z","event_type":"price_change","frame_hash":"0a5c1442a0768b3224e0e99dd0e342892fd5128db497380b8e5b7dc4926380df","frame_index":0,"kind":"data","monotonic_ns":224123352212666,"payload":{"event_type":"price_change","market":"0x717c0e8ccd4d5c7040185188fbae28be901ca589a11a94b1b38ca36a79eccfeb","price_changes":[{"asset_id":"24254094493625419915756280046002869097156693848522361803041977572204227262166","best_ask":"0.56","best_bid":"0.55","hash":"f99656d475318509e30d9e8999f581a9ccee008f","price":"0.55","side":"BUY","size":"10"},{"asset_id":"41448400836309843603620980831210604935021861034693225347475867885462478926555","best_ask":"0.45","best_bid":"0.44","hash":"a88b786fdc132fe44fcab313cc9b94c9e0acde47","price":"0.45","side":"SELL","size":"10"}],"timestamp":"1785122140064"},"payload_hash":"84250fcb8ba43e884cb1a6817ae670762fdb52d3b40aede385bf722c06ea71e8","raw_frame":"{\"market\":\"0x717c0e8ccd4d5c7040185188fbae28be901ca589a11a94b1b38ca36a79eccfeb\", \"price_changes\":[{\"asset_id\":\"24254094493625419915756280046002869097156693848522361803041977572204227262166\", \"price\":\"0.55\", \"size\":\"10\", \"side\":\"BUY\", \"hash\":\"f99656d475318509e30d9e8999f581a9ccee008f\", \"best_bid\":\"0.55\", \"best_ask\":\"0.56\"}, {\"asset_id\":\"41448400836309843603620980831210604935021861034693225347475867885462478926555\", \"price\":\"0.45\", \"size\":\"10\", \"side\":\"SELL\", \"hash\":\"a88b786fdc132fe44fcab313cc9b94c9e0acde47\", \"best_bid\":\"0.44\", \"best_ask\":\"0.45\"}], \"timestamp\":\"1785122140064\", \"event_type\":\"price_change\"}","received_at":"2026-07-27T03:15:40.017987Z","schema_version":"clob-market-ws.price_change.v1","sequence":null,"server_hash":null,"server_timestamp":"1785122140064","session_id":"dd162b8dca5f43ff811d304e69a06123","source":"clob_market_ws"},"received_at":"2026-07-27T03:15:40.017987Z","record_id":"4d39a85705cdf67c618e1ac612d2a7b7d6277fbcb93128b7a53ba9c245e184fc","schema_fingerprint":"4aa3821a28b0b7c2400bc59aba4bcc0a76e971dadd19610d3ad38c768e124dc7","schema_version":"edge-lab-recorder.raw.v1","sequence":null,"source":"clob_market_ws"}
{"event_at":"2026-07-27T03:15:40.065000Z","event_fingerprint":"b2f37afee92209ba701b84263c39bd2079be18ae30343254d2dcc5306e21bcde","payload":{"connection_id":"c7dc2e4762f849c6b6f9306b6518dcab","event_at":"2026-07-27T03:15:40.065000Z","event_type":"price_change","frame_hash":"afc1d9ef08a174050a0aea58e6a793c42ddf1f742b880a4e8dcdce808b84c193","frame_index":0,"kind":"data","monotonic_ns":224123357573583,"payload":{"event_type":"price_change","market":"0x717c0e8ccd4d5c7040185188fbae28be901ca589a11a94b1b38ca36a79eccfeb","price_changes":[{"asset_id":"41448400836309843603620980831210604935021861034693225347475867885462478926555","best_ask":"0.45","best_bid":"0.44","hash":"fc0f96bf710f3664112d8f91b77fbd7f2eec2187","price":"0.42","side":"BUY","size":"0"},{"asset_id":"24254094493625419915756280046002869097156693848522361803041977572204227262166","best_ask":"0.56","best_bid":"0.55","hash":"60279b83b0905505cc71eecb9b2b2c5dfa352730","price":"0.58","side":"SELL","size":"0"}],"timestamp":"1785122140065"},"payload_hash":"2cc47d1c59af896afe9d1f1a14ee1a72bceeaa5e94a96fbf71bfc82156a683fa","raw_frame":"{\"market\":\"0x717c0e8ccd4d5c7040185188fbae28be901ca589a11a94b1b38ca36a79eccfeb\", \"price_changes\":[{\"asset_id\":\"41448400836309843603620980831210604935021861034693225347475867885462478926555\", \"price\":\"0.42\", \"size\":\"0\", \"side\":\"BUY\", \"hash\":\"fc0f96bf710f3664112d8f91b77fbd7f2eec2187\", \"best_bid\":\"0.44\", \"best_ask\":\"0.45\"}, {\"asset_id\":\"24254094493625419915756280046002869097156693848522361803041977572204227262166\", \"price\":\"0.58\", \"size\":\"0\", \"side\":\"SELL\", \"hash\":\"60279b83b0905505cc71eecb9b2b2c5dfa352730\", \"best_bid\":\"0.55\", \"best_ask\":\"0.56\"}], \"timestamp\":\"1785122140065\", \"event_type\":\"price_change\"}","received_at":"2026-07-27T03:15:40.023348Z","schema_version":"clob-market-ws.price_change.v1","sequence":null,"server_hash":null,"server_timestamp":"1785122140065","session_id":"dd162b8dca5f43ff811d304e69a06123","source":"clob_market_ws"},"received_at":"2026-07-27T03:15:40.023348Z","record_id":"e190490f2f135d1f5fa143b13b721f4429d373a0188649bb2cf84cc48c853a4c","schema_fingerprint":"4aa3821a28b0b7c2400bc59aba4bcc0a76e971dadd19610d3ad38c768e124dc7","schema_version":"edge-lab-recorder.raw.v1","sequence":null,"source":"clob_market_ws"}
{"event_at":"2026-07-27T03:15:40.065000Z","event_fingerprint":"92fc7b154c32974672e3078ff56c75e5431073de2ba7aba93b7890d4880393b0","payload":{"connection_id":"c7dc2e4762f849c6b6f9306b6518dcab","event_at":"2026-07-27T03:15:40.065000Z","event_type":"price_change","frame_hash":"82786cb26fbf84b927cef0b9b68583025f2481d3e54e5c74a9fab40b596ccc6e","frame_index":0,"kind":"data","monotonic_ns":224123360305541,"payload":{"event_type":"price_change","market":"0x717c0e8ccd4d5c7040185188fbae28be901ca589a11a94b1b38ca36a79eccfeb","price_changes":[{"asset_id":"24254094493625419915756280046002869097156693848522361803041977572204227262166","best_ask":"0.56","best_bid":"0.55","hash":"60279b83b0905505cc71eecb9b2b2c5dfa352730","price":"0.49","side":"BUY","size":"100"},{"asset_id":"41448400836309843603620980831210604935021861034693225347475867885462478926555","best_ask":"0.45","best_bid":"0.44","hash":"fc0f96bf710f3664112d8f91b77fbd7f2eec2187","price":"0.51","side":"SELL","size":"100"}],"timestamp":"1785122140065"},"payload_hash":"d9565c70b128687d7b0ee29fee00e240cf4db1348c03fce0f6731341cd7c8da0","raw_frame":"{\"market\":\"0x717c0e8ccd4d5c7040185188fbae28be901ca589a11a94b1b38ca36a79eccfeb\", \"price_changes\":[{\"asset_id\":\"24254094493625419915756280046002869097156693848522361803041977572204227262166\", \"price\":\"0.49\", \"size\":\"100\", \"side\":\"BUY\", \"hash\":\"60279b83b0905505cc71eecb9b2b2c5dfa352730\", \"best_bid\":\"0.55\", \"best_ask\":\"0.56\"}, {\"asset_id\":\"41448400836309843603620980831210604935021861034693225347475867885462478926555\", \"price\":\"0.51\", \"size\":\"100\", \"side\":\"SELL\", \"hash\":\"fc0f96bf710f3664112d8f91b77fbd7f2eec2187\", \"best_bid\":\"0.44\", \"best_ask\":\"0.45\"}], \"timestamp\":\"1785122140065\", \"event_type\":\"price_change\"}","received_at":"2026-07-27T03:15:40.026080Z","schema_version":"clob-market-ws.price_change.v1","sequence":null,"server_hash":null,"server_timestamp":"1785122140065","session_id":"dd162b8dca5f43ff811d304e69a06123","source":"clob_market_ws"},"received_at":"2026-07-27T03:15:40.026080Z","record_id":"0036dee499b29cca4d0a824d387bfa92a1ecd631b4f6207172840bdd459bce5f","schema_fingerprint":"4aa3821a28b0b7c2400bc59aba4bcc0a76e971dadd19610d3ad38c768e124dc7","schema_version":"edge-lab-recorder.raw.v1","sequence":null,"source":"clob_market_ws"}
{"event_at":"2026-07-27T03:15:40.065000Z","event_fingerprint":"bafb0d54fedd1445e116d0dc496d559762e4bb276a3f78221a261b1488403270","payload":{"connection_id":"c7dc2e4762f849c6b6f9306b6518dcab","event_at":"2026-07-27T03:15:40.065000Z","event_type":"price_change","frame_hash":"6d679ca387c1f729c23b5b36c0efaad6f0c0ffdac26414942a890f9d1b696259","frame_index":0,"kind":"data","monotonic_ns":224123368263500,"payload":{"event_type":"price_change","market":"0x717c0e8ccd4d5c7040185188fbae28be901ca589a11a94b1b38ca36a79eccfeb","price_changes":[{"asset_id":"41448400836309843603620980831210604935021861034693225347475867885462478926555","best_ask":"0.45","best_bid":"0.44","hash":"13b358bde7a98f37597e07a0733ee4ace2e1ca2e","price":"0.01","side":"BUY","size":"7703.02"},{"asset_id":"24254094493625419915756280046002869097156693848522361803041977572204227262166","best_ask":"0.56","best_bid":"0.55","hash":"41f0f8cb8d981e5da8f7ad6c085f2f54856da269","price":"0.99","side":"SELL","size":"7703.02"}],"timestamp":"1785122140065"},"payload_hash":"19d33e85fc78fd1372d2d9a01af11f11ea9b6d9b3f14dbe311b67c9e649f2c71","raw_frame":"{\"market\":\"0x717c0e8ccd4d5c7040185188fbae28be901ca589a11a94b1b38ca36a79eccfeb\", \"price_changes\":[{\"asset_id\":\"41448400836309843603620980831210604935021861034693225347475867885462478926555\", \"price\":\"0.01\", \"size\":\"7703.02\", \"side\":\"BUY\", \"hash\":\"13b358bde7a98f37597e07a0733ee4ace2e1ca2e\", \"best_bid\":\"0.44\", \"best_ask\":\"0.45\"}, {\"asset_id\":\"24254094493625419915756280046002869097156693848522361803041977572204227262166\", \"price\":\"0.99\", \"size\":\"7703.02\", \"side\":\"SELL\", \"hash\":\"41f0f8cb8d981e5da8f7ad6c085f2f54856da269\", \"best_bid\":\"0.55\", \"best_ask\":\"0.56\"}], \"timestamp\":\"1785122140065\", \"event_type\":\"price_change\"}","received_at":"2026-07-27T03:15:40.034038Z","schema_version":"clob-market-ws.price_change.v1","sequence":null,"server_hash":null,"server_timestamp":"1785122140065","session_id":"dd162b8dca5f43ff811d304e69a06123","source":"clob_market_ws"},"received_at":"2026-07-27T03:15:40.034038Z","record_id":"6d72a01be073d976ba7af097425747a62c37eea84cb26d6d2ee6302ce123373d","schema_fingerprint":"4aa3821a28b0b7c2400bc59aba4bcc0a76e971dadd19610d3ad38c768e124dc7","schema_version":"edge-lab-recorder.raw.v1","sequence":null,"source":"clob_market_ws"}
{"event_at":"2026-07-27T03:15:40.066000Z","event_fingerprint":"0ada837eeae9ded097b1c1c400a7928a1e64b4c8d5b5c90023a47fd889bb93c6","payload":{"connection_id":"c7dc2e4762f849c6b6f9306b6518dcab","event_at":"2026-07-27T03:15:40.066000Z","event_type":"price_change","frame_hash":"4ea4fed259069c83c08e3b7b63bf831ef6982de0d34f9dbad6fba3d6d6975995","frame_index":0,"kind":"data","monotonic_ns":224123373411250,"payload":{"event_type":"price_change","market":"0x717c0e8ccd4d5c7040185188fbae28be901ca589a11a94b1b38ca36a79eccfeb","price_changes":[{"asset_id":"41448400836309843603620980831210604935021861034693225347475867885462478926555","best_ask":"0.45","best_bid":"0.44","hash":"a116facbfd7a9f2fbf97f368790aeb3c25ed9d76","price":"0.4","side":"BUY","size":"115"},{"asset_id":"24254094493625419915756280046002869097156693848522361803041977572204227262166","best_ask":"0.56","best_bid":"0.55","hash":"a202a6f4a28f52481bceb989afe053631044d60b","price":"0.6","side":"SELL","size":"115"}],"timestamp":"1785122140066"},"payload_hash":"8672a58ee56a89488a43d6b5deb060d04d2844496ba2d43b887bab2f3e6267a4","raw_frame":"{\"market\":\"0x717c0e8ccd4d5c7040185188fbae28be901ca589a11a94b1b38ca36a79eccfeb\", \"price_changes\":[{\"asset_id\":\"41448400836309843603620980831210604935021861034693225347475867885462478926555\", \"price\":\"0.4\", \"size\":\"115\", \"side\":\"BUY\", \"hash\":\"a116facbfd7a9f2fbf97f368790aeb3c25ed9d76\", \"best_bid\":\"0.44\", \"best_ask\":\"0.45\"}, {\"asset_id\":\"24254094493625419915756280046002869097156693848522361803041977572204227262166\", \"price\":\"0.6\", \"size\":\"115\", \"side\":\"SELL\", \"hash\":\"a202a6f4a28f52481bceb989afe053631044d60b\", \"best_bid\":\"0.55\", \"best_ask\":\"0.56\"}], \"timestamp\":\"1785122140066\", \"event_type\":\"price_change\"}","received_at":"2026-07-27T03:15:40.039185Z","schema_version":"clob-market-ws.price_change.v1","sequence":null,"server_hash":null,"server_timestamp":"1785122140066","session_id":"dd162b8dca5f43ff811d304e69a06123","source":"clob_market_ws"},"received_at":"2026-07-27T03:15:40.039185Z","record_id":"52496e65094b461fbc871fd90259af9146de434a67e2a6f9330e448f027fb8ce","schema_fingerprint":"4aa3821a28b0b7c2400bc59aba4bcc0a76e971dadd19610d3ad38c768e124dc7","schema_version":"edge-lab-recorder.raw.v1","sequence":null,"source":"clob_market_ws"}
{"event_at":"2026-07-27T03:15:40.068000Z","event_fingerprint":"9b00298cb0c899af8ebc8800b4459078b3f526346ae56fdc0fd0c93947fca209","payload":{"connection_id":"c7dc2e4762f849c6b6f9306b6518dcab","event_at":"2026-07-27T03:15:40.068000Z","event_type":"price_change","frame_hash":"805b903e9b5d7b8779c0824f5ae3d60c0f53631f82253d0de2a116bc7bb837a0","frame_index":0,"kind":"data","monotonic_ns":224123380881083,"payload":{"event_type":"price_change","market":"0x717c0e8ccd4d5c7040185188fbae28be901ca589a11a94b1b38ca36a79eccfeb","price_changes":[{"asset_id":"41448400836309843603620980831210604935021861034693225347475867885462478926555","best_ask":"0.45","best_bid":"0.44","hash":"9f4e01fee3108a74848848a338138a6dffc136b6","price":"0.32","side":"BUY","size":"324.32"},{"asset_id":"24254094493625419915756280046002869097156693848522361803041977572204227262166","best_ask":"0.56","best_bid":"0.55","hash":"730156b4e0cab505af70e5f716b32db8fca8868b","price":"0.68","side":"SELL","size":"324.32"}],"timestamp":"1785122140068"},"payload_hash":"358b7db972c94fee97ccb287f898a196f6ea10b03243dba1d8b35a0b7655df48","raw_frame":"{\"market\":\"0x717c0e8ccd4d5c7040185188fbae28be901ca589a11a94b1b38ca36a79eccfeb\", \"price_changes\":[{\"asset_id\":\"41448400836309843603620980831210604935021861034693225347475867885462478926555\", \"price\":\"0.32\", \"size\":\"324.32\", \"side\":\"BUY\", \"hash\":\"9f4e01fee3108a74848848a338138a6dffc136b6\", \"best_bid\":\"0.44\", \"best_ask\":\"0.45\"}, {\"asset_id\":\"24254094493625419915756280046002869097156693848522361803041977572204227262166\", \"price\":\"0.68\", \"size\":\"324.32\", \"side\":\"SELL\", \"hash\":\"730156b4e0cab505af70e5f716b32db8fca8868b\", \"best_bid\":\"0.55\", \"best_ask\":\"0.56\"}], \"timestamp\":\"1785122140068\", \"event_type\":\"price_change\"}","received_at":"2026-07-27T03:15:40.046644Z","schema_version":"clob-market-ws.price_change.v1","sequence":null,"server_hash":null,"server_timestamp":"1785122140068","session_id":"dd162b8dca5f43ff811d304e69a06123","source":"clob_market_ws"},"received_at":"2026-07-27T03:15:40.046644Z","record_id":"f61a9eda3c8cb2ae31b86ac2e704c072ed75181ab64f5c3e3c28d75f83ddf62c","schema_fingerprint":"4aa3821a28b0b7c2400bc59aba4bcc0a76e971dadd19610d3ad38c768e124dc7","schema_version":"edge-lab-recorder.raw.v1","sequence":null,"source":"clob_market_ws"}
{"event_at":"2026-07-27T03:15:40.069000Z","event_fingerprint":"53eccb7fa817968a640039ceeaee315cc78ea0ec95423271c3ae405f0091af36","payload":{"connection_id":"c7dc2e4762f849c6b6f9306b6518dcab","event_at":"2026-07-27T03:15:40.069000Z","event_type":"price_change","frame_hash":"8781c18a667566763e631c86063d051f23b9f6e12e7a35ea073c490b70f2fabc","frame_index":0,"kind":"data","monotonic_ns":224123387651083,"payload":{"event_type":"price_change","market":"0x717c0e8ccd4d5c7040185188fbae28be901ca589a11a94b1b38ca36a79eccfeb","price_changes":[{"asset_id":"41448400836309843603620980831210604935021861034693225347475867885462478926555","best_ask":"0.45","best_bid":"0.44","hash":"68bbfcd1b76344dba0ca922d5b31c7e322a2a89e","price":"0.27","side":"BUY","size":"21.2"},{"asset_id":"24254094493625419915756280046002869097156693848522361803041977572204227262166","best_ask":"0.56","best_bid":"0.55","hash":"31349da457296b516e0a9c4c9dbd0859a82c32e1","price":"0.73","side":"SELL","size":"21.2"}],"timestamp":"1785122140069"},"payload_hash":"fa96fdb65b77c078f0664a97fe51c057c4d3cf874cd547e59ba478fe8ee2c032","raw_frame":"{\"market\":\"0x717c0e8ccd4d5c7040185188fbae28be901ca589a11a94b1b38ca36a79eccfeb\", \"price_changes\":[{\"asset_id\":\"41448400836309843603620980831210604935021861034693225347475867885462478926555\", \"price\":\"0.27\", \"size\":\"21.2\", \"side\":\"BUY\", \"hash\":\"68bbfcd1b76344dba0ca922d5b31c7e322a2a89e\", \"best_bid\":\"0.44\", \"best_ask\":\"0.45\"}, {\"asset_id\":\"24254094493625419915756280046002869097156693848522361803041977572204227262166\", \"price\":\"0.73\", \"size\":\"21.2\", \"side\":\"SELL\", \"hash\":\"31349da457296b516e0a9c4c9dbd0859a82c32e1\", \"best_bid\":\"0.55\", \"best_ask\":\"0.56\"}], \"timestamp\":\"1785122140069\", \"event_type\":\"price_change\"}","received_at":"2026-07-27T03:15:40.053425Z","schema_version":"clob-market-ws.price_change.v1","sequence":null,"server_hash":null,"server_timestamp":"1785122140069","session_id":"dd162b8dca5f43ff811d304e69a06123","source":"clob_market_ws"},"received_at":"2026-07-27T03:15:40.053425Z","record_id":"5d3d9431b7ac4deea54470a56cce25d948696239ccd218acb152b7a301c8b689","schema_fingerprint":"4aa3821a28b0b7c2400bc59aba4bcc0a76e971dadd19610d3ad38c768e124dc7","schema_version":"edge-lab-recorder.raw.v1","sequence":null,"source":"clob_market_ws"}
{"event_at":"2026-07-27T03:15:40.069000Z","event_fingerprint":"f6f7a19350d4b108e6663210be639ce0f202a06fec9561f4a79237977e5303b6","payload":{"connection_id":"c7dc2e4762f849c6b6f9306b6518dcab","event_at":"2026-07-27T03:15:40.069000Z","event_type":"price_change","frame_hash":"0f41a6fa44e73e617274e74515aec872f9643bc53f2c7d5746d6191047594419","frame_index":0,"kind":"data","monotonic_ns":224123393655500,"payload":{"event_type":"price_change","market":"0x717c0e8ccd4d5c7040185188fbae28be901ca589a11a94b1b38ca36a79eccfeb","price_changes":[{"asset_id":"24254094493625419915756280046002869097156693848522361803041977572204227262166","best_ask":"0.56","best_bid":"0.55","hash":"299222b819cbf96f3c2ae659833a2f6216b48027","price":"0.47","side":"BUY","size":"127"},{"asset_id":"41448400836309843603620980831210604935021861034693225347475867885462478926555","best_ask":"0.45","best_bid":"0.44","hash":"d9d3fb3234160bf4b1aa3ded395fc280986aa7ab","price":"0.53","side":"SELL","size":"127"}],"timestamp":"1785122140069"},"payload_hash":"f9763b374f186afe33c04941700cc74134b7aadf80cf9ebe9b47869c7c68ac2b","raw_frame":"{\"market\":\"0x717c0e8ccd4d5c7040185188fbae28be901ca589a11a94b1b38ca36a79eccfeb\", \"price_changes\":[{\"asset_id\":\"24254094493625419915756280046002869097156693848522361803041977572204227262166\", \"price\":\"0.47\", \"size\":\"127\", \"side\":\"BUY\", \"hash\":\"299222b819cbf96f3c2ae659833a2f6216b48027\", \"best_bid\":\"0.55\", \"best_ask\":\"0.56\"}, {\"asset_id\":\"41448400836309843603620980831210604935021861034693225347475867885462478926555\", \"price\":\"0.53\", \"size\":\"127\", \"side\":\"SELL\", \"hash\":\"d9d3fb3234160bf4b1aa3ded395fc280986aa7ab\", \"best_bid\":\"0.44\", \"best_ask\":\"0.45\"}], \"timestamp\":\"1785122140069\", \"event_type\":\"price_change\"}","received_at":"2026-07-27T03:15:40.059431Z","schema_version":"clob-market-ws.price_change.v1","sequence":null,"server_hash":null,"server_timestamp":"1785122140069","session_id":"dd162b8dca5f43ff811d304e69a06123","source":"clob_market_ws"},"received_at":"2026-07-27T03:15:40.059431Z","record_id":"45fb711eb214af3164f96ee2935035591f291cde6ae6c9c684625bf4be9441aa","schema_fingerprint":"4aa3821a28b0b7c2400bc59aba4bcc0a76e971dadd19610d3ad38c768e124dc7","schema_version":"edge-lab-recorder.raw.v1","sequence":null,"source":"clob_market_ws"}
{"event_at":"2026-07-27T03:15:40.071000Z","event_fingerprint":"e4f3571d07e03d14dc04ee24807238e7bd32277999413fd40d393e72635f7841","payload":{"connection_id":"c7dc2e4762f849c6b6f9306b6518dcab","event_at":"2026-07-27T03:15:40.071000Z","event_type":"price_change","frame_hash":"cd0dc73b965551dfb4cb2aaed9509242ac17b9b1a3e80625e71a9e53ae5620c6","frame_index":0,"kind":"data","monotonic_ns":224123399136875,"payload":{"event_type":"price_change","market":"0x717c0e8ccd4d5c7040185188fbae28be901ca589a11a94b1b38ca36a79eccfeb","price_changes":[{"asset_id":"24254094493625419915756280046002869097156693848522361803041977572204227262166","best_ask":"0.56","best_bid":"0.55","hash":"f6361e37c17d5859d5921266629c5a0d344ae930","price":"0.55","side":"BUY","size":"15"},{"asset_id":"41448400836309843603620980831210604935021861034693225347475867885462478926555","best_ask":"0.45","best_bid":"0.44","hash":"8697623737b1fee444374d55b9345a2317b0fccd","price":"0.45","side":"SELL","size":"15"}],"timestamp":"1785122140071"},"payload_hash":"dcbbcb013acc988fefd47c366b6ed64853a0ccf2f3fc05b9d97eb87591d5d177","raw_frame":"{\"market\":\"0x717c0e8ccd4d5c7040185188fbae28be901ca589a11a94b1b38ca36a79eccfeb\", \"price_changes\":[{\"asset_id\":\"24254094493625419915756280046002869097156693848522361803041977572204227262166\", \"price\":\"0.55\", \"size\":\"15\", \"side\":\"BUY\", \"hash\":\"f6361e37c17d5859d5921266629c5a0d344ae930\", \"best_bid\":\"0.55\", \"best_ask\":\"0.56\"}, {\"asset_id\":\"41448400836309843603620980831210604935021861034693225347475867885462478926555\", \"price\":\"0.45\", \"size\":\"15\", \"side\":\"SELL\", \"hash\":\"8697623737b1fee444374d55b9345a2317b0fccd\", \"best_bid\":\"0.44\", \"best_ask\":\"0.45\"}], \"timestamp\":\"1785122140071\", \"event_type\":\"price_change\"}","received_at":"2026-07-27T03:15:40.064911Z","schema_version":"clob-market-ws.price_change.v1","sequence":null,"server_hash":null,"server_timestamp":"1785122140071","session_id":"dd162b8dca5f43ff811d304e69a06123","source":"clob_market_ws"},"received_at":"2026-07-27T03:15:40.064911Z","record_id":"3c4ab357707d48703dd5a30278c80f9811163caea21782366562c05bca2aad9b","schema_fingerprint":"4aa3821a28b0b7c2400bc59aba4bcc0a76e971dadd19610d3ad38c768e124dc7","schema_version":"edge-lab-recorder.raw.v1","sequence":null,"source":"clob_market_ws"}
{"event_at":"2026-07-27T03:15:40.072000Z","event_fingerprint":"5ae7f5156667a55e85b147697c993908c38e597174d1125f240f4a301278e470","payload":{"connection_id":"c7dc2e4762f849c6b6f9306b6518dcab","event_at":"2026-07-27T03:15:40.072000Z","event_type":"price_change","frame_hash":"564d305a52726ecdf4d22d10a1e05676e6d9ce59beebf3076fdb9d575c117f56","frame_index":0,"kind":"data","monotonic_ns":224123405317833,"payload":{"event_type":"price_change","market":"0x717c0e8ccd4d5c7040185188fbae28be901ca589a11a94b1b38ca36a79eccfeb","price_changes":[{"asset_id":"41448400836309843603620980831210604935021861034693225347475867885462478926555","best_ask":"0.45","best_bid":"0.44","hash":"028d379126a4dc5f2df340773375f1bd4b00d86f","price":"0.41","side":"BUY","size":"11"},{"asset_id":"24254094493625419915756280046002869097156693848522361803041977572204227262166","best_ask":"0.56","best_bid":"0.55","hash":"646bd0467957a1692f35025dd87601bf19933339","price":"0.59","side":"SELL","size":"11"}],"timestamp":"1785122140072"},"payload_hash":"b393e73b327e52eb7dbb1a194f7c1b95fe8fd79ca9cc999d0e5f907a271c46ca","raw_frame":"{\"market\":\"0x717c0e8ccd4d5c7040185188fbae28be901ca589a11a94b1b38ca36a79eccfeb\", \"price_changes\":[{\"asset_id\":\"41448400836309843603620980831210604935021861034693225347475867885462478926555\", \"price\":\"0.41\", \"size\":\"11\", \"side\":\"BUY\", \"hash\":\"028d379126a4dc5f2df340773375f1bd4b00d86f\", \"best_bid\":\"0.44\", \"best_ask\":\"0.45\"}, {\"asset_id\":\"24254094493625419915756280046002869097156693848522361803041977572204227262166\", \"price\":\"0.59\", \"size\":\"11\", \"side\":\"SELL\", \"hash\":\"646bd0467957a1692f35025dd87601bf19933339\", \"best_bid\":\"0.55\", \"best_ask\":\"0.56\"}], \"timestamp\":\"1785122140072\", \"event_type\":\"price_change\"}","received_at":"2026-07-27T03:15:40.071093Z","schema_version":"clob-market-ws.price_change.v1","sequence":null,"server_hash":null,"server_timestamp":"1785122140072","session_id":"dd162b8dca5f43ff811d304e69a06123","source":"clob_market_ws"},"received_at":"2026-07-27T03:15:40.071093Z","record_id":"a763669c7a3490c5a07e3f8cda9965e1a8aff14b3cd05b1b7ca1b083f635d086","schema_fingerprint":"4aa3821a28b0b7c2400bc59aba4bcc0a76e971dadd19610d3ad38c768e124dc7","schema_version":"edge-lab-recorder.raw.v1","sequence":null,"source":"clob_market_ws"}
{"event_at":"2026-07-27T03:15:40.073000Z","event_fingerprint":"4ab5944bfb35634d6b55f8964712ea947dec315c253459a994f641c8335d7fb2","payload":{"connection_id":"c7dc2e4762f849c6b6f9306b6518dcab","event_at":"2026-07-27T03:15:40.073000Z","event_type":"price_change","frame_hash":"ddaef9901f226a5b2cde4416836f7d7dea3ad34ed0fe5fab3dca1c4cf87e7140","frame_index":0,"kind":"data","monotonic_ns":224123411712791,"payload":{"event_type":"price_change","market":"0x717c0e8ccd4d5c7040185188fbae28be901ca589a11a94b1b38ca36a79eccfeb","price_changes":[{"asset_id":"41448400836309843603620980831210604935021861034693225347475867885462478926555","best_ask":"0.45","best_bid":"0.44","hash":"402e96a376c9bc30d3acbf16eb91ae0a6f8aa8fe","price":"0.32","side":"BUY","size":"220.16"},{"asset_id":"24254094493625419915756280046002869097156693848522361803041977572204227262166","best_ask":"0.56","best_bid":"0.55","hash":"538de99bc26f93c01f9d5f2f4486fba3cb0f332e","price":"0.68","side":"SELL","size":"220.16"}],"timestamp":"1785122140073"},"payload_hash":"8502e1e8c6d954118d796700c58415f0d2e3fbf7382136784533968247083c3e","raw_frame":"{\"market\":\"0x717c0e8ccd4d5c7040185188fbae28be901ca589a11a94b1b38ca36a79eccfeb\", \"price_changes\":[{\"asset_id\":\"41448400836309843603620980831210604935021861034693225347475867885462478926555\", \"price\":\"0.32\", \"size\":\"220.16\", \"side\":\"BUY\", \"hash\":\"402e96a376c9bc30d3acbf16eb91ae0a6f8aa8fe\", \"best_bid\":\"0.44\", \"best_ask\":\"0.45\"}, {\"asset_id\":\"24254094493625419915756280046002869097156693848522361803041977572204227262166\", \"price\":\"0.68\", \"size\":\"220.16\", \"side\":\"SELL\", \"hash\":\"538de99bc26f93c01f9d5f2f4486fba3cb0f332e\", \"best_bid\":\"0.55\", \"best_ask\":\"0.56\"}], \"timestamp\":\"1785122140073\", \"event_type\":\"price_change\"}","received_at":"2026-07-27T03:15:40.077488Z","schema_version":"clob-market-ws.price_change.v1","sequence":null,"server_hash":null,"server_timestamp":"1785122140073","session_id":"dd162b8dca5f43ff811d304e69a06123","source":"clob_market_ws"},"received_at":"2026-07-27T03:15:40.077488Z","record_id":"a58d38054e35fda714220758bd322aab20e2b8457f4f0236188b9d22de3a91bc","schema_fingerprint":"4aa3821a28b0b7c2400bc59aba4bcc0a76e971dadd19610d3ad38c768e124dc7","schema_version":"edge-lab-recorder.raw.v1","sequence":null,"source":"clob_market_ws"}
{"event_at":"2026-07-27T03:15:40.073000Z","event_fingerprint":"3c582ba01d12a8f9eaebbeb707ba6ec0b74628e27c0ed90d785a84e8ca7a6920","payload":{"connection_id":"c7dc2e4762f849c6b6f9306b6518dcab","event_at":"2026-07-27T03:15:40.073000Z","event_type":"price_change","frame_hash":"e21623010430c399fe39f634eb94af539c27f8470c8f5a4f58cf7044b45f2099","frame_index":0,"kind":"data","monotonic_ns":224123418034291,"payload":{"event_type":"price_change","market":"0x717c0e8ccd4d5c7040185188fbae28be901ca589a11a94b1b38ca36a79eccfeb","price_changes":[{"asset_id":"41448400836309843603620980831210604935021861034693225347475867885462478926555","best_ask":"0.45","best_bid":"0.44","hash":"78f3f9c1e0d7e23944ba87e9fb81596e20bff66a","price":"0.24","side":"BUY","size":"23.39"},{"asset_id":"24254094493625419915756280046002869097156693848522361803041977572204227262166","best_ask":"0.56","best_bid":"0.55","hash":"72069c514b762f641cd7cb41544d94ce11a1362d","price":"0.76","side":"SELL","size":"23.39"}],"timestamp":"1785122140073"},"payload_hash":"917ad355745e526ad377e199fcd96c836af09c3f9322b6c5180a85296deb8c85","raw_frame":"{\"market\":\"0x717c0e8ccd4d5c7040185188fbae28be901ca589a11a94b1b38ca36a79eccfeb\", \"price_changes\":[{\"asset_id\":\"41448400836309843603620980831210604935021861034693225347475867885462478926555\", \"price\":\"0.24\", \"size\":\"23.39\", \"side\":\"BUY\", \"hash\":\"78f3f9c1e0d7e23944ba87e9fb81596e20bff66a\", \"best_bid\":\"0.44\", \"best_ask\":\"0.45\"}, {\"asset_id\":\"24254094493625419915756280046002869097156693848522361803041977572204227262166\", \"price\":\"0.76\", \"size\":\"23.39\", \"side\":\"SELL\", \"hash\":\"72069c514b762f641cd7cb41544d94ce11a1362d\", \"best_bid\":\"0.55\", \"best_ask\":\"0.56\"}], \"timestamp\":\"1785122140073\", \"event_type\":\"price_change\"}","received_at":"2026-07-27T03:15:40.083808Z","schema_version":"clob-market-ws.price_change.v1","sequence":null,"server_hash":null,"server_timestamp":"1785122140073","session_id":"dd162b8dca5f43ff811d304e69a06123","source":"clob_market_ws"},"received_at":"2026-07-27T03:15:40.083808Z","record_id":"b0afd65aca52a8440b36f992057d781fd923c51d41c6f21d134490bdfd729aab","schema_fingerprint":"4aa3821a28b0b7c2400bc59aba4bcc0a76e971dadd19610d3ad38c768e124dc7","schema_version":"edge-lab-recorder.raw.v1","sequence":null,"source":"clob_market_ws"}
{"event_at":"2026-07-27T03:15:40.074000Z","event_fingerprint":"d3ac4a5ed68ee531c51fccaaf4f2916a682a1c8000c943d2ae920115b49656f2","payload":{"connection_id":"c7dc2e4762f849c6b6f9306b6518dcab","event_at":"2026-07-27T03:15:40.074000Z","event_type":"price_change","frame_hash":"5012963842b5625220fd8c95cc032fb15148a1b96af04f76a8bf1b3f5b209f47","frame_index":0,"kind":"data","monotonic_ns":224123425721541,"payload":{"event_type":"price_change","market":"0x717c0e8ccd4d5c7040185188fbae28be901ca589a11a94b1b38ca36a79eccfeb","price_changes":[{"asset_id":"24254094493625419915756280046002869097156693848522361803041977572204227262166","best_ask":"0.56","best_bid":"0.55","hash":"14c80f93250d33e1b40c0e4bac955fc3d47bb4df","price":"0.5","side":"BUY","size":"20"},{"asset_id":"41448400836309843603620980831210604935021861034693225347475867885462478926555","best_ask":"0.45","best_bid":"0.44","hash":"28d6b41343745e79c4810c1a9328da2a5fc514f8","price":"0.5","side":"SELL","size":"20"}],"timestamp":"1785122140074"},"payload_hash":"3c33ac3c76f7221773aa3d74fcaa480fc4cb33dc3f0c56a68e1cf348e9c7dc18","raw_frame":"{\"market\":\"0x717c0e8ccd4d5c7040185188fbae28be901ca589a11a94b1b38ca36a79eccfeb\", \"price_changes\":[{\"asset_id\":\"24254094493625419915756280046002869097156693848522361803041977572204227262166\", \"price\":\"0.5\", \"size\":\"20\", \"side\":\"BUY\", \"hash\":\"14c80f93250d33e1b40c0e4bac955fc3d47bb4df\", \"best_bid\":\"0.55\", \"best_ask\":\"0.56\"}, {\"asset_id\":\"41448400836309843603620980831210604935021861034693225347475867885462478926555\", \"price\":\"0.5\", \"size\":\"20\", \"side\":\"SELL\", \"hash\":\"28d6b41343745e79c4810c1a9328da2a5fc514f8\", \"best_bid\":\"0.44\", \"best_ask\":\"0.45\"}], \"timestamp\":\"1785122140074\", \"event_type\":\"price_change\"}","received_at":"2026-07-27T03:15:40.091496Z","schema_version":"clob-market-ws.price_change.v1","sequence":null,"server_hash":null,"server_timestamp":"1785122140074","session_id":"dd162b8dca5f43ff811d304e69a06123","source":"clob_market_ws"},"received_at":"2026-07-27T03:15:40.091496Z","record_id":"910a089c72591f115e780ae1cdec890f231547e4de28705db73265a10c882cab","schema_fingerprint":"4aa3821a28b0b7c2400bc59aba4bcc0a76e971dadd19610d3ad38c768e124dc7","schema_version":"edge-lab-recorder.raw.v1","sequence":null,"source":"clob_market_ws"}
{"event_at":"2026-07-27T03:15:40.075000Z","event_fingerprint":"2c6ca90647150431e50c40ae4180f837eb3cdaccc475eb79dbc03d9f4c0e85f5","payload":{"connection_id":"c7dc2e4762f849c6b6f9306b6518dcab","event_at":"2026-07-27T03:15:40.075000Z","event_type":"price_change","frame_hash":"8698ba6c8042814000762eb8b11c89d808708c4decac96efe9eaa76b4e7429d1","frame_index":0,"kind":"data","monotonic_ns":224123433467500,"payload":{"event_type":"price_change","market":"0x717c0e8ccd4d5c7040185188fbae28be901ca589a11a94b1b38ca36a79eccfeb","price_changes":[{"asset_id":"24254094493625419915756280046002869097156693848522361803041977572204227262166","best_ask":"0.56","best_bid":"0.55","hash":"463223bbe6c159cd5b4bdbdbc525fc8af9c8532d","price":"0.55","side":"BUY","size":"20"},{"asset_id":"41448400836309843603620980831210604935021861034693225347475867885462478926555","best_ask":"0.45","best_bid":"0.44","hash":"7b06a2bd7801cab80502ac2e9fc6cea29bbdbd39","price":"0.45","side":"SELL","size":"20"}],"timestamp":"1785122140075"},"payload_hash":"75bff833526b35f16df57b51b09e0fe4c8bbd4a0a730a4518811bd99f2212902","raw_frame":"{\"market\":\"0x717c0e8ccd4d5c7040185188fbae28be901ca589a11a94b1b38ca36a79eccfeb\", \"price_changes\":[{\"asset_id\":\"24254094493625419915756280046002869097156693848522361803041977572204227262166\", \"price\":\"0.55\", \"size\":\"20\", \"side\":\"BUY\", \"hash\":\"463223bbe6c159cd5b4bdbdbc525fc8af9c8532d\", \"best_bid\":\"0.55\", \"best_ask\":\"0.56\"}, {\"asset_id\":\"41448400836309843603620980831210604935021861034693225347475867885462478926555\", \"price\":\"0.45\", \"size\":\"20\", \"side\":\"SELL\", \"hash\":\"7b06a2bd7801cab80502ac2e9fc6cea29bbdbd39\", \"best_bid\":\"0.44\", \"best_ask\":\"0.45\"}], \"timestamp\":\"1785122140075\", \"event_type\":\"price_change\"}","received_at":"2026-07-27T03:15:40.099241Z","schema_version":"clob-market-ws.price_change.v1","sequence":null,"server_hash":null,"server_timestamp":"1785122140075","session_id":"dd162b8dca5f43ff811d304e69a06123","source":"clob_market_ws"},"received_at":"2026-07-27T03:15:40.099241Z","record_id":"47617baa046143b67c40eceb7fec7d3264fb245f7fb1c79c02c80d97d91e9624","schema_fingerprint":"4aa3821a28b0b7c2400bc59aba4bcc0a76e971dadd19610d3ad38c768e124dc7","schema_version":"edge-lab-recorder.raw.v1","sequence":null,"source":"clob_market_ws"}
{"event_at":"2026-07-27T03:15:40.075000Z","event_fingerprint":"39046522641240f88d24a7d153abbb6061d754caf08befd7e8e3a583125daf19","payload":{"connection_id":"c7dc2e4762f849c6b6f9306b6518dcab","event_at":"2026-07-27T03:15:40.075000Z","event_type":"price_change","frame_hash":"a2209857176dc8ed4ffaef89501b7b32814e5637912856e89e91cbb160171e2f","frame_index":0,"kind":"data","monotonic_ns":224123439907583,"payload":{"event_type":"price_change","market":"0x717c0e8ccd4d5c7040185188fbae28be901ca589a11a94b1b38ca36a79eccfeb","price_changes":[{"asset_id":"41448400836309843603620980831210604935021861034693225347475867885462478926555","best_ask":"0.45","best_bid":"0.44","hash":"f11016fe48587a34080ec3f7c0147053308e3358","price":"0.3","side":"BUY","size":"123"},{"asset_id":"24254094493625419915756280046002869097156693848522361803041977572204227262166","best_ask":"0.56","best_bid":"0.55","hash":"2557dc894de56ed3a5d13d2c1b33e7018fb3b731","price":"0.7","side":"SELL","size":"123"}],"timestamp":"1785122140075"},"payload_hash":"e28b266845c0d79ddedae3fecb0d4f0e307e5233c2cb7068e1fddd96bbcb7997","raw_frame":"{\"market\":\"0x717c0e8ccd4d5c7040185188fbae28be901ca589a11a94b1b38ca36a79eccfeb\", \"price_changes\":[{\"asset_id\":\"41448400836309843603620980831210604935021861034693225347475867885462478926555\", \"price\":\"0.3\", \"size\":\"123\", \"side\":\"BUY\", \"hash\":\"f11016fe48587a34080ec3f7c0147053308e3358\", \"best_bid\":\"0.44\", \"best_ask\":\"0.45\"}, {\"asset_id\":\"24254094493625419915756280046002869097156693848522361803041977572204227262166\", \"price\":\"0.7\", \"size\":\"123\", \"side\":\"SELL\", \"hash\":\"2557dc894de56ed3a5d13d2c1b33e7018fb3b731\", \"best_bid\":\"0.55\", \"best_ask\":\"0.56\"}], \"timestamp\":\"1785122140075\", \"event_type\":\"price_change\"}","received_at":"2026-07-27T03:15:40.105682Z","schema_version":"clob-market-ws.price_change.v1","sequence":null,"server_hash":null,"server_timestamp":"1785122140075","session_id":"dd162b8dca5f43ff811d304e69a06123","source":"clob_market_ws"},"received_at":"2026-07-27T03:15:40.105682Z","record_id":"42e0c0eca4b1ac908186dd014689b22716115dd2c436d38fd24d7b110e37d396","schema_fingerprint":"4aa3821a28b0b7c2400bc59aba4bcc0a76e971dadd19610d3ad38c768e124dc7","schema_version":"edge-lab-recorder.raw.v1","sequence":null,"source":"clob_market_ws"}
{"event_at":"2026-07-27T03:15:40.086000Z","event_fingerprint":"fcea901b26cc674b24d663cb1d9ce9d6747af1db12bb2052077c564d305a9ca8","payload":{"connection_id":"c7dc2e4762f849c6b6f9306b6518dcab","event_at":"2026-07-27T03:15:40.086000Z","event_type":"price_change","frame_hash":"e55a88a6dc83ef8d1f535a6e0ac2ffa113559475a98b3bd7f25fa8eec3aac989","frame_index":0,"kind":"data","monotonic_ns":224123445531250,"payload":{"event_type":"price_change","market":"0x717c0e8ccd4d5c7040185188fbae28be901ca589a11a94b1b38ca36a79eccfeb","price_changes":[{"asset_id":"24254094493625419915756280046002869097156693848522361803041977572204227262166","best_ask":"0.56","best_bid":"0.55","hash":"49be8d8135095f08e1aa0cd42e3bd2eaaa1e6be1","price":"0.01","side":"BUY","size":"7708.02"},{"asset_id":"41448400836309843603620980831210604935021861034693225347475867885462478926555","best_ask":"0.45","best_bid":"0.44","hash":"aaef3059565febcb3a310f746d3e4e9446462931","price":"0.99","side":"SELL","size":"7708.02"}],"timestamp":"1785122140086"},"payload_hash":"3b7d5ed09453436d40b9057982bb05a4445899a87844bc4ed1babd5194c1d16b","raw_frame":"{\"market\":\"0x717c0e8ccd4d5c7040185188fbae28be901ca589a11a94b1b38ca36a79eccfeb\", \"price_changes\":[{\"asset_id\":\"24254094493625419915756280046002869097156693848522361803041977572204227262166\", \"price\":\"0.01\", \"size\":\"7708.02\", \"side\":\"BUY\", \"hash\":\"49be8d8135095f08e1aa0cd42e3bd2eaaa1e6be1\", \"best_bid\":\"0.55\", \"best_ask\":\"0.56\"}, {\"asset_id\":\"41448400836309843603620980831210604935021861034693225347475867885462478926555\", \"price\":\"0.99\", \"size\":\"7708.02\", \"side\":\"SELL\", \"hash\":\"aaef3059565febcb3a310f746d3e4e9446462931\", \"best_bid\":\"0.44\", \"best_ask\":\"0.45\"}], \"timestamp\":\"1785122140086\", \"event_type\":\"price_change\"}","received_at":"2026-07-27T03:15:40.111301Z","schema_version":"clob-market-ws.price_change.v1","sequence":null,"server_hash":null,"server_timestamp":"1785122140086","session_id":"dd162b8dca5f43ff811d304e69a06123","source":"clob_market_ws"},"received_at":"2026-07-27T03:15:40.111301Z","record_id":"8a9749883bcff9dcf6bf7637c1b8ec86297f7cab0fb0e4f2ff99bfc73198985b","schema_fingerprint":"4aa3821a28b0b7c2400bc59aba4bcc0a76e971dadd19610d3ad38c768e124dc7","schema_version":"edge-lab-recorder.raw.v1","sequence":null,"source":"clob_market_ws"}
{"event_at":"2026-07-27T03:15:40.087000Z","event_fingerprint":"f0c762547d3b39b4a70d77bd95c1489520f00135282a4f15e4c548b10f566f83","payload":{"connection_id":"c7dc2e4762f849c6b6f9306b6518dcab","event_at":"2026-07-27T03:15:40.087000Z","event_type":"price_change","frame_hash":"7b3471f2fb03682e575a756dcb002127cb3288d1a8b5eeb86e76cd413a28fc7e","frame_index":0,"kind":"data","monotonic_ns":224123451586333,"payload":{"event_type":"price_change","market":"0x717c0e8ccd4d5c7040185188fbae28be901ca589a11a94b1b38ca36a79eccfeb","price_changes":[{"asset_id":"24254094493625419915756280046002869097156693848522361803041977572204227262166","best_ask":"0.56","best_bid":"0.55","hash":"f10183e67858c61fa2ca5e8907dfbc958d2a8e1f","price":"0.55","side":"BUY","size":"32"},{"asset_id":"41448400836309843603620980831210604935021861034693225347475867885462478926555","best_ask":"0.45","best_bid":"0.44","hash":"53ebe1249d7a77b9604a25cf27ce539d89b0b78d","price":"0.45","side":"SELL","size":"32"}],"timestamp":"1785122140087"},"payload_hash":"20c489e0feb4ef1b536c808e0926fdf943752cfe99d5c32435d3025a262291be","raw_frame":"{\"market\":\"0x717c0e8ccd4d5c7040185188fbae28be901ca589a11a94b1b38ca36a79eccfeb\", \"price_changes\":[{\"asset_id\":\"24254094493625419915756280046002869097156693848522361803041977572204227262166\", \"price\":\"0.55\", \"size\":\"32\", \"side\":\"BUY\", \"hash\":\"f10183e67858c61fa2ca5e8907dfbc958d2a8e1f\", \"best_bid\":\"0.55\", \"best_ask\":\"0.56\"}, {\"asset_id\":\"41448400836309843603620980831210604935021861034693225347475867885462478926555\", \"price\":\"0.45\", \"size\":\"32\", \"side\":\"SELL\", \"hash\":\"53ebe1249d7a77b9604a25cf27ce539d89b0b78d\", \"best_bid\":\"0.44\", \"best_ask\":\"0.45\"}], \"timestamp\":\"1785122140087\", \"event_type\":\"price_change\"}","received_at":"2026-07-27T03:15:40.117360Z","schema_version":"clob-market-ws.price_change.v1","sequence":null,"server_hash":null,"server_timestamp":"1785122140087","session_id":"dd162b8dca5f43ff811d304e69a06123","source":"clob_market_ws"},"received_at":"2026-07-27T03:15:40.117360Z","record_id":"0c04a19f4dc7279d1fc913d4514a8e42265641edc23b2f0390efb21b7ef95d60","schema_fingerprint":"4aa3821a28b0b7c2400bc59aba4bcc0a76e971dadd19610d3ad38c768e124dc7","schema_version":"edge-lab-recorder.raw.v1","sequence":null,"source":"clob_market_ws"}
{"event_at":"2026-07-27T03:15:40.088000Z","event_fingerprint":"2bf1822a80fa3c5fc6875e7a738a8e741c546447d0432b7d156f81f0d99dfac6","payload":{"connection_id":"c7dc2e4762f849c6b6f9306b6518dcab","event_at":"2026-07-27T03:15:40.088000Z","event_type":"price_change","frame_hash":"8fe3971de7cd83e07959cceefd039b3dd5e0e3953972061a02a8c4cb0ad868f6","frame_index":0,"kind":"data","monotonic_ns":224123455392583,"payload":{"event_type":"price_change","market":"0x717c0e8ccd4d5c7040185188fbae28be901ca589a11a94b1b38ca36a79eccfeb","price_changes":[{"asset_id":"24254094493625419915756280046002869097156693848522361803041977572204227262166","best_ask":"0.56","best_bid":"0.55","hash":"d17143591964a1cddbb5e47a98f3745318f9a3c4","price":"0.04","side":"BUY","size":"843.09"},{"asset_id":"41448400836309843603620980831210604935021861034693225347475867885462478926555","best_ask":"0.45","best_bid":"0.44","hash":"a752f92029842f9209589c5e1636714087c79857","price":"0.96","side":"SELL","size":"843.09"}],"timestamp":"1785122140088"},"payload_hash":"9ca1fa7a7cdecaf5e45a0a76730d6f47bb1cdec7a675fe2f0ac23a02c932237c","raw_frame":"{\"market\":\"0x717c0e8ccd4d5c7040185188fbae28be901ca589a11a94b1b38ca36a79eccfeb\", \"price_changes\":[{\"asset_id\":\"24254094493625419915756280046002869097156693848522361803041977572204227262166\", \"price\":\"0.04\", \"size\":\"843.09\", \"side\":\"BUY\", \"hash\":\"d17143591964a1cddbb5e47a98f3745318f9a3c4\", \"best_bid\":\"0.55\", \"best_ask\":\"0.56\"}, {\"asset_id\":\"41448400836309843603620980831210604935021861034693225347475867885462478926555\", \"price\":\"0.96\", \"size\":\"843.09\", \"side\":\"SELL\", \"hash\":\"a752f92029842f9209589c5e1636714087c79857\", \"best_bid\":\"0.44\", \"best_ask\":\"0.45\"}], \"timestamp\":\"1785122140088\", \"event_type\":\"price_change\"}","received_at":"2026-07-27T03:15:40.121166Z","schema_version":"clob-market-ws.price_change.v1","sequence":null,"server_hash":null,"server_timestamp":"1785122140088","session_id":"dd162b8dca5f43ff811d304e69a06123","source":"clob_market_ws"},"received_at":"2026-07-27T03:15:40.121166Z","record_id":"4dc7e7c4244eb46e432f0eb75857bea98be73a270686975c670d0d9ba092d28e","schema_fingerprint":"4aa3821a28b0b7c2400bc59aba4bcc0a76e971dadd19610d3ad38c768e124dc7","schema_version":"edge-lab-recorder.raw.v1","sequence":null,"source":"clob_market_ws"}
{"event_at":"2026-07-27T03:15:40.088000Z","event_fingerprint":"c66ae20d16a70ad5ee64452aea44d26c4569acdca7e1596978166b9a353ae8d6","payload":{"connection_id":"c7dc2e4762f849c6b6f9306b6518dcab","event_at":"2026-07-27T03:15:40.088000Z","event_type":"price_change","frame_hash":"a5e43d3c07147d8fa24a4dcceb77a353d662fd898573ac34f2fefafb151cb849","frame_index":0,"kind":"data","monotonic_ns":224123461314000,"payload":{"event_type":"price_change","market":"0x717c0e8ccd4d5c7040185188fbae28be901ca589a11a94b1b38ca36a79eccfeb","price_changes":[{"asset_id":"41448400836309843603620980831210604935021861034693225347475867885462478926555","best_ask":"0.45","best_bid":"0.44","hash":"696871100f795e607131e805929ef956843893b3","price":"0.4","side":"BUY","size":"128"},{"asset_id":"24254094493625419915756280046002869097156693848522361803041977572204227262166","best_ask":"0.56","best_bid":"0.55","hash":"15f7c77db1447de18c89b5e3f600bff2fccdc8dc","price":"0.6","side":"SELL","size":"128"}],"timestamp":"1785122140088"},"payload_hash":"15bb3bcae73ecbd81e4e9dbd5c016810d09088d5dd3c842cb6c0f48d309863ca","raw_frame":"{\"market\":\"0x717c0e8ccd4d5c7040185188fbae28be901ca589a11a94b1b38ca36a79eccfeb\", \"price_changes\":[{\"asset_id\":\"41448400836309843603620980831210604935021861034693225347475867885462478926555\", \"price\":\"0.4\", \"size\":\"128\", \"side\":\"BUY\", \"hash\":\"696871100f795e607131e805929ef956843893b3\", \"best_bid\":\"0.44\", \"best_ask\":\"0.45\"}, {\"asset_id\":\"24254094493625419915756280046002869097156693848522361803041977572204227262166\", \"price\":\"0.6\", \"size\":\"128\", \"side\":\"SELL\", \"hash\":\"15f7c77db1447de18c89b5e3f600bff2fccdc8dc\", \"best_bid\":\"0.55\", \"best_ask\":\"0.56\"}], \"timestamp\":\"1785122140088\", \"event_type\":\"price_change\"}","received_at":"2026-07-27T03:15:40.127083Z","schema_version":"clob-market-ws.price_change.v1","sequence":null,"server_hash":null,"server_timestamp":"1785122140088","session_id":"dd162b8dca5f43ff811d304e69a06123","source":"clob_market_ws"},"received_at":"2026-07-27T03:15:40.127083Z","record_id":"0013daa3286c0bca71549266b209ca736c68af3fecd9d3428aa891bc16ec28bc","schema_fingerprint":"4aa3821a28b0b7c2400bc59aba4bcc0a76e971dadd19610d3ad38c768e124dc7","schema_version":"edge-lab-recorder.raw.v1","sequence":null,"source":"clob_market_ws"}
{"event_at":"2026-07-27T03:15:40.093000Z","event_fingerprint":"5455f1a9c861556e790282378d2267464e9c3f53eb241039b7ca3adb5d621679","payload":{"connection_id":"c7dc2e4762f849c6b6f9306b6518dcab","event_at":"2026-07-27T03:15:40.093000Z","event_type":"price_change","frame_hash":"489d2804d80cadee264fb09bd62f6a556122e96cce09179d348eb6d8c1a15743","frame_index":0,"kind":"data","monotonic_ns":224123466508833,"payload":{"event_type":"price_change","market":"0x717c0e8ccd4d5c7040185188fbae28be901ca589a11a94b1b38ca36a79eccfeb","price_changes":[{"asset_id":"41448400836309843603620980831210604935021861034693225347475867885462478926555","best_ask":"0.45","best_bid":"0.44","hash":"48b3a83a6f649f92080158d689e20b58bccbeef4","price":"0.46","side":"SELL","size":"74.18"},{"asset_id":"24254094493625419915756280046002869097156693848522361803041977572204227262166","best_ask":"0.56","best_bid":"0.55","hash":"205fb1d74a126d78f242afdff8c6d9f60976b6cc","price":"0.54","side":"BUY","size":"74.18"}],"timestamp":"1785122140093"},"payload_hash":"3643cb54ca184233cc9c05c40608ebcc92cc352186226decf15cd40847a9935c","raw_frame":"{\"market\":\"0x717c0e8ccd4d5c7040185188fbae28be901ca589a11a94b1b38ca36a79eccfeb\", \"price_changes\":[{\"asset_id\":\"41448400836309843603620980831210604935021861034693225347475867885462478926555\", \"price\":\"0.46\", \"size\":\"74.18\", \"side\":\"SELL\", \"hash\":\"48b3a83a6f649f92080158d689e20b58bccbeef4\", \"best_bid\":\"0.44\", \"best_ask\":\"0.45\"}, {\"asset_id\":\"24254094493625419915756280046002869097156693848522361803041977572204227262166\", \"price\":\"0.54\", \"size\":\"74.18\", \"side\":\"BUY\", \"hash\":\"205fb1d74a126d78f242afdff8c6d9f60976b6cc\", \"best_bid\":\"0.55\", \"best_ask\":\"0.56\"}], \"timestamp\":\"1785122140093\", \"event_type\":\"price_change\"}","received_at":"2026-07-27T03:15:40.132282Z","schema_version":"clob-market-ws.price_change.v1","sequence":null,"server_hash":null,"server_timestamp":"1785122140093","session_id":"dd162b8dca5f43ff811d304e69a06123","source":"clob_market_ws"},"received_at":"2026-07-27T03:15:40.132282Z","record_id":"25701cb92ef1c5ecb33daece58bc76c58bde09b8c4c44ed93152c2add953d100","schema_fingerprint":"4aa3821a28b0b7c2400bc59aba4bcc0a76e971dadd19610d3ad38c768e124dc7","schema_version":"edge-lab-recorder.raw.v1","sequence":null,"source":"clob_market_ws"}
{"event_at":"2026-07-27T03:15:40.095000Z","event_fingerprint":"ef603650bc6f5dd9e60ffa4702d0f2bccf6c6791974d505a54bd11a6fc68d61c","payload":{"connection_id":"c7dc2e4762f849c6b6f9306b6518dcab","event_at":"2026-07-27T03:15:40.095000Z","event_type":"price_change","frame_hash":"a7e5bb0a57886a5145046654ccddb3746e9864d07210f9421470b4311ba365d7","frame_index":0,"kind":"data","monotonic_ns":224123469559958,"payload":{"event_type":"price_change","market":"0x717c0e8ccd4d5c7040185188fbae28be901ca589a11a94b1b38ca36a79eccfeb","price_changes":[{"asset_id":"41448400836309843603620980831210604935021861034693225347475867885462478926555","best_ask":"0.45","best_bid":"0.44","hash":"1a2da2cc9c6048af701c7c05302228b998111746","price":"0.46","side":"SELL","size":"66.18"},{"asset_id":"24254094493625419915756280046002869097156693848522361803041977572204227262166","best_ask":"0.56","best_bid":"0.55","hash":"325fc06b9badc74dc3aecda7669516f102042fde","price":"0.54","side":"BUY","size":"66.18"}],"timestamp":"1785122140095"},"payload_hash":"66a08f73276c6f83f18d86e95356d0554dbbc8b90a6ba3979e920bf316e5c6f6","raw_frame":"{\"market\":\"0x717c0e8ccd4d5c7040185188fbae28be901ca589a11a94b1b38ca36a79eccfeb\", \"price_changes\":[{\"asset_id\":\"41448400836309843603620980831210604935021861034693225347475867885462478926555\", \"price\":\"0.46\", \"size\":\"66.18\", \"side\":\"SELL\", \"hash\":\"1a2da2cc9c6048af701c7c05302228b998111746\", \"best_bid\":\"0.44\", \"best_ask\":\"0.45\"}, {\"asset_id\":\"24254094493625419915756280046002869097156693848522361803041977572204227262166\", \"price\":\"0.54\", \"size\":\"66.18\", \"side\":\"BUY\", \"hash\":\"325fc06b9badc74dc3aecda7669516f102042fde\", \"best_bid\":\"0.55\", \"best_ask\":\"0.56\"}], \"timestamp\":\"1785122140095\", \"event_type\":\"price_change\"}","received_at":"2026-07-27T03:15:40.135334Z","schema_version":"clob-market-ws.price_change.v1","sequence":null,"server_hash":null,"server_timestamp":"1785122140095","session_id":"dd162b8dca5f43ff811d304e69a06123","source":"clob_market_ws"},"received_at":"2026-07-27T03:15:40.135334Z","record_id":"efe5505e7117f0b12a9e81b790c871fb36cdf23e1610a8292e5707a3fa87739f","schema_fingerprint":"4aa3821a28b0b7c2400bc59aba4bcc0a76e971dadd19610d3ad38c768e124dc7","schema_version":"edge-lab-recorder.raw.v1","sequence":null,"source":"clob_market_ws"}
{"event_at":"2026-07-27T03:15:40.095000Z","event_fingerprint":"d28b356f90a17f75170e78cd0ecf1ed34a2c313c5456fb555cd48dc556522e28","payload":{"connection_id":"c7dc2e4762f849c6b6f9306b6518dcab","event_at":"2026-07-27T03:15:40.095000Z","event_type":"price_change","frame_hash":"91b32c92adf8240238c4a8eb22fcfbd6be61eb7c3991f1e063b6f86912c1f4dc","frame_index":0,"kind":"data","monotonic_ns":224123475196208,"payload":{"event_type":"price_change","market":"0x717c0e8ccd4d5c7040185188fbae28be901ca589a11a94b1b38ca36a79eccfeb","price_changes":[{"asset_id":"24254094493625419915756280046002869097156693848522361803041977572204227262166","best_ask":"0.56","best_bid":"0.55","hash":"e9a199385b77bcedb13e344cc0b7532c17e2cce6","price":"0.55","side":"BUY","size":"37"},{"asset_id":"41448400836309843603620980831210604935021861034693225347475867885462478926555","best_ask":"0.45","best_bid":"0.44","hash":"448a2145528e267e28ddf3ffe97707e2c10334df","price":"0.45","side":"SELL","size":"37"}],"timestamp":"1785122140095"},"payload_hash":"aa9ebd23fc4e43f3c08b81e064f056a4b54cab6ec99b715116008d0552e8cd2e","raw_frame":"{\"market\":\"0x717c0e8ccd4d5c7040185188fbae28be901ca589a11a94b1b38ca36a79eccfeb\", \"price_changes\":[{\"asset_id\":\"24254094493625419915756280046002869097156693848522361803041977572204227262166\", \"price\":\"0.55\", \"size\":\"37\", \"side\":\"BUY\", \"hash\":\"e9a199385b77bcedb13e344cc0b7532c17e2cce6\", \"best_bid\":\"0.55\", \"best_ask\":\"0.56\"}, {\"asset_id\":\"41448400836309843603620980831210604935021861034693225347475867885462478926555\", \"price\":\"0.45\", \"size\":\"37\", \"side\":\"SELL\", \"hash\":\"448a2145528e267e28ddf3ffe97707e2c10334df\", \"best_bid\":\"0.44\", \"best_ask\":\"0.45\"}], \"timestamp\":\"1785122140095\", \"event_type\":\"price_change\"}","received_at":"2026-07-27T03:15:40.140969Z","schema_version":"clob-market-ws.price_change.v1","sequence":null,"server_hash":null,"server_timestamp":"1785122140095","session_id":"dd162b8dca5f43ff811d304e69a06123","source":"clob_market_ws"},"received_at":"2026-07-27T03:15:40.140969Z","record_id":"02909e413f8673a53b1b669219c0db07a92968e44d2af0f661e66a23f1074fc5","schema_fingerprint":"4aa3821a28b0b7c2400bc59aba4bcc0a76e971dadd19610d3ad38c768e124dc7","schema_version":"edge-lab-recorder.raw.v1","sequence":null,"source":"clob_market_ws"}
{"event_at":"2026-07-27T03:15:40.096000Z","event_fingerprint":"08dd3de1710e99bc06e8da085619a6975e9edb82a480ab4d367cd3f9afba8dea","payload":{"connection_id":"c7dc2e4762f849c6b6f9306b6518dcab","event_at":"2026-07-27T03:15:40.096000Z","event_type":"price_change","frame_hash":"c6ed421f44973017e083218c4a250ebc9cf44021cb54a79197b55dd25d6cf84c","frame_index":0,"kind":"data","monotonic_ns":224123482379208,"payload":{"event_type":"price_change","market":"0x717c0e8ccd4d5c7040185188fbae28be901ca589a11a94b1b38ca36a79eccfeb","price_changes":[{"asset_id":"41448400836309843603620980831210604935021861034693225347475867885462478926555","best_ask":"0.45","best_bid":"0.44","hash":"2d4fdec6de7ffa5d0490ef8e7afb866099ef01b0","price":"0.41","side":"BUY","size":"23"},{"asset_id":"24254094493625419915756280046002869097156693848522361803041977572204227262166","best_ask":"0.56","best_bid":"0.55","hash":"72d11e14656a1cf469858ee27d5b8c23e22301ea","price":"0.59","side":"SELL","size":"23"}],"timestamp":"1785122140096"},"payload_hash":"238ba6369ae9ba5874a6a4427430f5fcd0ea07841089f0c5048d9e4ab4e240f4","raw_frame":"{\"market\":\"0x717c0e8ccd4d5c7040185188fbae28be901ca589a11a94b1b38ca36a79eccfeb\", \"price_changes\":[{\"asset_id\":\"41448400836309843603620980831210604935021861034693225347475867885462478926555\", \"price\":\"0.41\", \"size\":\"23\", \"side\":\"BUY\", \"hash\":\"2d4fdec6de7ffa5d0490ef8e7afb866099ef01b0\", \"best_bid\":\"0.44\", \"best_ask\":\"0.45\"}, {\"asset_id\":\"24254094493625419915756280046002869097156693848522361803041977572204227262166\", \"price\":\"0.59\", \"size\":\"23\", \"side\":\"SELL\", \"hash\":\"72d11e14656a1cf469858ee27d5b8c23e22301ea\", \"best_bid\":\"0.55\", \"best_ask\":\"0.56\"}], \"timestamp\":\"1785122140096\", \"event_type\":\"price_change\"}","received_at":"2026-07-27T03:15:40.148153Z","schema_version":"clob-market-ws.price_change.v1","sequence":null,"server_hash":null,"server_timestamp":"1785122140096","session_id":"dd162b8dca5f43ff811d304e69a06123","source":"clob_market_ws"},"received_at":"2026-07-27T03:15:40.148153Z","record_id":"803ef713da1e1ccacc524b4d051c61f378a77f9d4a58fc619ae479af3e939cd1","schema_fingerprint":"4aa3821a28b0b7c2400bc59aba4bcc0a76e971dadd19610d3ad38c768e124dc7","schema_version":"edge-lab-recorder.raw.v1","sequence":null,"source":"clob_market_ws"}
{"event_at":"2026-07-27T03:15:40.104000Z","event_fingerprint":"a3e6a44c8434c7f44069c79d70dacfec146306b0a30c363200676deb8ff269c8","payload":{"connection_id":"c7dc2e4762f849c6b6f9306b6518dcab","event_at":"2026-07-27T03:15:40.104000Z","event_type":"price_change","frame_hash":"6a402d1422aa13584f1911fa1b524313ccb83bdd02edaae481fcc946fcb50ad4","frame_index":0,"kind":"data","monotonic_ns":224123488836750,"payload":{"event_type":"price_change","market":"0x717c0e8ccd4d5c7040185188fbae28be901ca589a11a94b1b38ca36a79eccfeb","price_changes":[{"asset_id":"41448400836309843603620980831210604935021861034693225347475867885462478926555","best_ask":"0.45","best_bid":"0.44","hash":"e87e771ba44b0470836221eabc29160b6cc55a95","price":"0.26","side":"BUY","size":"26.6"},{"asset_id":"24254094493625419915756280046002869097156693848522361803041977572204227262166","best_ask":"0.56","best_bid":"0.55","hash":"be079e5af125c552ceef09070af9f2b09cbb6eca","price":"0.74","side":"SELL","size":"26.6"}],"timestamp":"1785122140104"},"payload_hash":"fc60adad44f146b60d37b609d2348c1fadaa6584af8d37ba99056e484c064a07","raw_frame":"{\"market\":\"0x717c0e8ccd4d5c7040185188fbae28be901ca589a11a94b1b38ca36a79eccfeb\", \"price_changes\":[{\"asset_id\":\"41448400836309843603620980831210604935021861034693225347475867885462478926555\", \"price\":\"0.26\", \"size\":\"26.6\", \"side\":\"BUY\", \"hash\":\"e87e771ba44b0470836221eabc29160b6cc55a95\", \"best_bid\":\"0.44\", \"best_ask\":\"0.45\"}, {\"asset_id\":\"24254094493625419915756280046002869097156693848522361803041977572204227262166\", \"price\":\"0.74\", \"size\":\"26.6\", \"side\":\"SELL\", \"hash\":\"be079e5af125c552ceef09070af9f2b09cbb6eca\", \"best_bid\":\"0.55\", \"best_ask\":\"0.56\"}], \"timestamp\":\"1785122140104\", \"event_type\":\"price_change\"}","received_at":"2026-07-27T03:15:40.154607Z","schema_version":"clob-market-ws.price_change.v1","sequence":null,"server_hash":null,"server_timestamp":"1785122140104","session_id":"dd162b8dca5f43ff811d304e69a06123","source":"clob_market_ws"},"received_at":"2026-07-27T03:15:40.154607Z","record_id":"429a179b962d36c7990cee391d19f3f56b40bdb04cea5c23fca1c69fb2e9f756","schema_fingerprint":"4aa3821a28b0b7c2400bc59aba4bcc0a76e971dadd19610d3ad38c768e124dc7","schema_version":"edge-lab-recorder.raw.v1","sequence":null,"source":"clob_market_ws"}
{"event_at":"2026-07-27T03:15:40.119000Z","event_fingerprint":"b3afa82ea1105b27d746892e0f7e6616994e9cacd85067650d22e4f3a8ae7669","payload":{"connection_id":"c7dc2e4762f849c6b6f9306b6518dcab","event_at":"2026-07-27T03:15:40.119000Z","event_type":"price_change","frame_hash":"9746b8ebf15e136d4ee5706857ade3d2a8ad8f51b4ba5a5bf5a167731658ba01","frame_index":0,"kind":"data","monotonic_ns":224123493133583,"payload":{"event_type":"price_change","market":"0x717c0e8ccd4d5c7040185188fbae28be901ca589a11a94b1b38ca36a79eccfeb","price_changes":[{"asset_id":"41448400836309843603620980831210604935021861034693225347475867885462478926555","best_ask":"0.45","best_bid":"0.44","hash":"c7d7078ee405a8338d1ffebf4ddcba4a61027fe0","price":"0.28","side":"BUY","size":"135.84"},{"asset_id":"24254094493625419915756280046002869097156693848522361803041977572204227262166","best_ask":"0.56","best_bid":"0.55","hash":"4a63991c59c74088d15afa3ef0edbb2960025c32","price":"0.72","side":"SELL","size":"135.84"}],"timestamp":"1785122140119"},"payload_hash":"c8dd7b52681a42cbaa0da8aa89ce7b6c3e59f39005c13816638504d83b453ad7","raw_frame":"{\"market\":\"0x717c0e8ccd4d5c7040185188fbae28be901ca589a11a94b1b38ca36a79eccfeb\", \"price_changes\":[{\"asset_id\":\"41448400836309843603620980831210604935021861034693225347475867885462478926555\", \"price\":\"0.28\", \"size\":\"135.84\", \"side\":\"BUY\", \"hash\":\"c7d7078ee405a8338d1ffebf4ddcba4a61027fe0\", \"best_bid\":\"0.44\", \"best_ask\":\"0.45\"}, {\"asset_id\":\"24254094493625419915756280046002869097156693848522361803041977572204227262166\", \"price\":\"0.72\", \"size\":\"135.84\", \"side\":\"SELL\", \"hash\":\"4a63991c59c74088d15afa3ef0edbb2960025c32\", \"best_bid\":\"0.55\", \"best_ask\":\"0.56\"}], \"timestamp\":\"1785122140119\", \"event_type\":\"price_change\"}","received_at":"2026-07-27T03:15:40.158908Z","schema_version":"clob-market-ws.price_change.v1","sequence":null,"server_hash":null,"server_timestamp":"1785122140119","session_id":"dd162b8dca5f43ff811d304e69a06123","source":"clob_market_ws"},"received_at":"2026-07-27T03:15:40.158908Z","record_id":"11dc5903682f0fdda262fddf677253be9c7b1f6e61dfc95ca0903d42a975d089","schema_fingerprint":"4aa3821a28b0b7c2400bc59aba4bcc0a76e971dadd19610d3ad38c768e124dc7","schema_version":"edge-lab-recorder.raw.v1","sequence":null,"source":"clob_market_ws"}
{"event_at":"2026-07-27T03:15:40.122000Z","event_fingerprint":"dfe6a788290d9aec6deaf8434575e7a98a97724c6e463d809522cf355d1d259d","payload":{"connection_id":"c7dc2e4762f849c6b6f9306b6518dcab","event_at":"2026-07-27T03:15:40.122000Z","event_type":"price_change","frame_hash":"d74a04018c0c5e86dc6db86b56c56084d9b88575e530d535b31c91c2c98a9dfd","frame_index":0,"kind":"data","monotonic_ns":224123498445500,"payload":{"event_type":"price_change","market":"0x717c0e8ccd4d5c7040185188fbae28be901ca589a11a94b1b38ca36a79eccfeb","price_changes":[{"asset_id":"41448400836309843603620980831210604935021861034693225347475867885462478926555","best_ask":"0.45","best_bid":"0.44","hash":"c5eb65f559c263879add84690a506b48913eb73a","price":"0.41","side":"BUY","size":"11"},{"asset_id":"24254094493625419915756280046002869097156693848522361803041977572204227262166","best_ask":"0.56","best_bid":"0.55","hash":"57144f13f51db04f035f8b52c1766f3e391a4c96","price":"0.59","side":"SELL","size":"11"}],"timestamp":"1785122140122"},"payload_hash":"9a07a135fc3832e8180b91078f47219729d21fdbeb01061c952a0d3ee1b507e7","raw_frame":"{\"market\":\"0x717c0e8ccd4d5c7040185188fbae28be901ca589a11a94b1b38ca36a79eccfeb\", \"price_changes\":[{\"asset_id\":\"41448400836309843603620980831210604935021861034693225347475867885462478926555\", \"price\":\"0.41\", \"size\":\"11\", \"side\":\"BUY\", \"hash\":\"c5eb65f559c263879add84690a506b48913eb73a\", \"best_bid\":\"0.44\", \"best_ask\":\"0.45\"}, {\"asset_id\":\"24254094493625419915756280046002869097156693848522361803041977572204227262166\", \"price\":\"0.59\", \"size\":\"11\", \"side\":\"SELL\", \"hash\":\"57144f13f51db04f035f8b52c1766f3e391a4c96\", \"best_bid\":\"0.55\", \"best_ask\":\"0.56\"}], \"timestamp\":\"1785122140122\", \"event_type\":\"price_change\"}","received_at":"2026-07-27T03:15:40.164218Z","schema_version":"clob-market-ws.price_change.v1","sequence":null,"server_hash":null,"server_timestamp":"1785122140122","session_id":"dd162b8dca5f43ff811d304e69a06123","source":"clob_market_ws"},"received_at":"2026-07-27T03:15:40.164218Z","record_id":"fbbc7132964e638bcae1f15777310a9d85ba184cf2fabda6cfe0fd8ba3297a76","schema_fingerprint":"4aa3821a28b0b7c2400bc59aba4bcc0a76e971dadd19610d3ad38c768e124dc7","schema_version":"edge-lab-recorder.raw.v1","sequence":null,"source":"clob_market_ws"}
{"event_at":"2026-07-27T03:15:40.126000Z","event_fingerprint":"0db0c37c6ac3a55bdf0463d8b7d71f8c92faca7fb57eb9faced42dcb1e0b701f","payload":{"connection_id":"c7dc2e4762f849c6b6f9306b6518dcab","event_at":"2026-07-27T03:15:40.126000Z","event_type":"price_change","frame_hash":"e7ac62d26fcd25e80ac51b21aa711b71f83a314d78e25911561443b75cf952f2","frame_index":0,"kind":"data","monotonic_ns":224123503657916,"payload":{"event_type":"price_change","market":"0x717c0e8ccd4d5c7040185188fbae28be901ca589a11a94b1b38ca36a79eccfeb","price_changes":[{"asset_id":"41448400836309843603620980831210604935021861034693225347475867885462478926555","best_ask":"0.45","best_bid":"0.44","hash":"3322a3c3409ee3d9899c8b4f9a6640dccf296008","price":"0.45","side":"SELL","size":"43"},{"asset_id":"24254094493625419915756280046002869097156693848522361803041977572204227262166","best_ask":"0.56","best_bid":"0.55","hash":"007eaf8058579a6f4c8d6e9e4caf69bb8cbe5100","price":"0.55","side":"BUY","size":"43"}],"timestamp":"1785122140126"},"payload_hash":"034bc85e6c1a22be7a3fc746d7d00d93027804d8294000a4a24ebc3e62c0f254","raw_frame":"{\"market\":\"0x717c0e8ccd4d5c7040185188fbae28be901ca589a11a94b1b38ca36a79eccfeb\", \"price_changes\":[{\"asset_id\":\"41448400836309843603620980831210604935021861034693225347475867885462478926555\", \"price\":\"0.45\", \"size\":\"43\", \"side\":\"SELL\", \"hash\":\"3322a3c3409ee3d9899c8b4f9a6640dccf296008\", \"best_bid\":\"0.44\", \"best_ask\":\"0.45\"}, {\"asset_id\":\"24254094493625419915756280046002869097156693848522361803041977572204227262166\", \"price\":\"0.55\", \"size\":\"43\", \"side\":\"BUY\", \"hash\":\"007eaf8058579a6f4c8d6e9e4caf69bb8cbe5100\", \"best_bid\":\"0.55\", \"best_ask\":\"0.56\"}], \"timestamp\":\"1785122140126\", \"event_type\":\"price_change\"}","received_at":"2026-07-27T03:15:40.169429Z","schema_version":"clob-market-ws.price_change.v1","sequence":null,"server_hash":null,"server_timestamp":"1785122140126","session_id":"dd162b8dca5f43ff811d304e69a06123","source":"clob_market_ws"},"received_at":"2026-07-27T03:15:40.169429Z","record_id":"f8c24fc8de9e49a0215a75829b82c1bc0cb710025989f9a9fff0eea18a1e0152","schema_fingerprint":"4aa3821a28b0b7c2400bc59aba4bcc0a76e971dadd19610d3ad38c768e124dc7","schema_version":"edge-lab-recorder.raw.v1","sequence":null,"source":"clob_market_ws"}
{"event_at":"2026-07-27T03:15:40.134000Z","event_fingerprint":"c1276bdd6a4b0feed3669061b6c9031ba4d911a2e1c6701094bd04fbab163e9e","payload":{"connection_id":"c7dc2e4762f849c6b6f9306b6518dcab","event_at":"2026-07-27T03:15:40.134000Z","event_type":"price_change","frame_hash":"6345410505c815f2bfb53a356013653ce6fa516b389342fe18d3594b4c35712b","frame_index":0,"kind":"data","monotonic_ns":224123509690541,"payload":{"event_type":"price_change","market":"0x717c0e8ccd4d5c7040185188fbae28be901ca589a11a94b1b38ca36a79eccfeb","price_changes":[{"asset_id":"24254094493625419915756280046002869097156693848522361803041977572204227262166","best_ask":"0.56","best_bid":"0.55","hash":"228f4ac8f1ecc403eca3966fc6d5dac7ad6df5c1","price":"0.5","side":"BUY","size":"15"},{"asset_id":"41448400836309843603620980831210604935021861034693225347475867885462478926555","best_ask":"0.45","best_bid":"0.44","hash":"a5f8fa950fe99b69025f1187cd1f31ec390855a2","price":"0.5","side":"SELL","size":"15"}],"timestamp":"1785122140134"},"payload_hash":"7664d31193de5006b0fcc479a03321f13996b3e196283dd1ea3341e730015d70","raw_frame":"{\"market\":\"0x717c0e8ccd4d5c7040185188fbae28be901ca589a11a94b1b38ca36a79eccfeb\", \"price_changes\":[{\"asset_id\":\"24254094493625419915756280046002869097156693848522361803041977572204227262166\", \"price\":\"0.5\", \"size\":\"15\", \"side\":\"BUY\", \"hash\":\"228f4ac8f1ecc403eca3966fc6d5dac7ad6df5c1\", \"best_bid\":\"0.55\", \"best_ask\":\"0.56\"}, {\"asset_id\":\"41448400836309843603620980831210604935021861034693225347475867885462478926555\", \"price\":\"0.5\", \"size\":\"15\", \"side\":\"SELL\", \"hash\":\"a5f8fa950fe99b69025f1187cd1f31ec390855a2\", \"best_bid\":\"0.44\", \"best_ask\":\"0.45\"}], \"timestamp\":\"1785122140134\", \"event_type\":\"price_change\"}","received_at":"2026-07-27T03:15:40.175460Z","schema_version":"clob-market-ws.price_change.v1","sequence":null,"server_hash":null,"server_timestamp":"1785122140134","session_id":"dd162b8dca5f43ff811d304e69a06123","source":"clob_market_ws"},"received_at":"2026-07-27T03:15:40.175460Z","record_id":"d226d5e0ff52a12bff6c692856989adecc80b2d2d2496e17ff78df64e2521d6b","schema_fingerprint":"4aa3821a28b0b7c2400bc59aba4bcc0a76e971dadd19610d3ad38c768e124dc7","schema_version":"edge-lab-recorder.raw.v1","sequence":null,"source":"clob_market_ws"}
{"event_at":"2026-07-27T03:15:40.136000Z","event_fingerprint":"f16295f1051741ad64a204f488bc4810fe2fb79096f0bc41a95818c43c9a33ab","payload":{"connection_id":"c7dc2e4762f849c6b6f9306b6518dcab","event_at":"2026-07-27T03:15:40.136000Z","event_type":"price_change","frame_hash":"6b2c8397249ed849ca73bf9e1ad08cff70521d5343dbe23d9a3926768a217aa0","frame_index":0,"kind":"data","monotonic_ns":224123515701208,"payload":{"event_type":"price_change","market":"0x717c0e8ccd4d5c7040185188fbae28be901ca589a11a94b1b38ca36a79eccfeb","price_changes":[{"asset_id":"41448400836309843603620980831210604935021861034693225347475867885462478926555","best_ask":"0.45","best_bid":"0.44","hash":"d501e608576ad26b3711e0ea741972bd3c1dc54a","price":"0.45","side":"SELL","size":"48"},{"asset_id":"24254094493625419915756280046002869097156693848522361803041977572204227262166","best_ask":"0.56","best_bid":"0.55","hash":"fcc1596186273d3456c0d947777a7141d84d6451","price":"0.55","side":"BUY","size":"48"}],"timestamp":"1785122140136"},"payload_hash":"2a98e005dabcf167702b3f4d44ec71b2dd49bd2945faf989b5f64eb21a8bab82","raw_frame":"{\"market\":\"0x717c0e8ccd4d5c7040185188fbae28be901ca589a11a94b1b38ca36a79eccfeb\", \"price_changes\":[{\"asset_id\":\"41448400836309843603620980831210604935021861034693225347475867885462478926555\", \"price\":\"0.45\", \"size\":\"48\", \"side\":\"SELL\", \"hash\":\"d501e608576ad26b3711e0ea741972bd3c1dc54a\", \"best_bid\":\"0.44\", \"best_ask\":\"0.45\"}, {\"asset_id\":\"24254094493625419915756280046002869097156693848522361803041977572204227262166\", \"price\":\"0.55\", \"size\":\"48\", \"side\":\"BUY\", \"hash\":\"fcc1596186273d3456c0d947777a7141d84d6451\", \"best_bid\":\"0.55\", \"best_ask\":\"0.56\"}], \"timestamp\":\"1785122140136\", \"event_type\":\"price_change\"}","received_at":"2026-07-27T03:15:40.181473Z","schema_version":"clob-market-ws.price_change.v1","sequence":null,"server_hash":null,"server_timestamp":"1785122140136","session_id":"dd162b8dca5f43ff811d304e69a06123","source":"clob_market_ws"},"received_at":"2026-07-27T03:15:40.181473Z","record_id":"df6708dfcc3ab18d5889b088432ba16cb1ded57c6773075aebcaaf752ab4bda8","schema_fingerprint":"4aa3821a28b0b7c2400bc59aba4bcc0a76e971dadd19610d3ad38c768e124dc7","schema_version":"edge-lab-recorder.raw.v1","sequence":null,"source":"clob_market_ws"}
{"event_at":"2026-07-27T03:15:40.145000Z","event_fingerprint":"b6c3f48070e76f51bfcf7d5e89a186d527e6c879b9abb6337af73da0b4c29151","payload":{"connection_id":"c7dc2e4762f849c6b6f9306b6518dcab","event_at":"2026-07-27T03:15:40.145000Z","event_type":"price_change","frame_hash":"8bfb78fd56b39403e94129bd7909ab410df4ff8a15ca92875e99ad012e33c975","frame_index":0,"kind":"data","monotonic_ns":224123521453375,"payload":{"event_type":"price_change","market":"0x717c0e8ccd4d5c7040185188fbae28be901ca589a11a94b1b38ca36a79eccfeb","price_changes":[{"asset_id":"24254094493625419915756280046002869097156693848522361803041977572204227262166","best_ask":"0.56","best_bid":"0.55","hash":"4f1ced43af8c214d222bee0544949125fef03c8b","price":"0.04","side":"BUY","size":"838.09"},{"asset_id":"41448400836309843603620980831210604935021861034693225347475867885462478926555","best_ask":"0.45","best_bid":"0.44","hash":"1c6db72a2df1014a980d91a495acf181c376e5b8","price":"0.96","side":"SELL","size":"838.09"}],"timestamp":"1785122140145"},"payload_hash":"3eb7a2446e5aaddb9ef44716ac3f74d946b56ed457d0dbbd85d62b5628ae9773","raw_frame":"{\"market\":\"0x717c0e8ccd4d5c7040185188fbae28be901ca589a11a94b1b38ca36a79eccfeb\", \"price_changes\":[{\"asset_id\":\"24254094493625419915756280046002869097156693848522361803041977572204227262166\", \"price\":\"0.04\", \"size\":\"838.09\", \"side\":\"BUY\", \"hash\":\"4f1ced43af8c214d222bee0544949125fef03c8b\", \"best_bid\":\"0.55\", \"best_ask\":\"0.56\"}, {\"asset_id\":\"41448400836309843603620980831210604935021861034693225347475867885462478926555\", \"price\":\"0.96\", \"size\":\"838.09\", \"side\":\"SELL\", \"hash\":\"1c6db72a2df1014a980d91a495acf181c376e5b8\", \"best_bid\":\"0.44\", \"best_ask\":\"0.45\"}], \"timestamp\":\"1785122140145\", \"event_type\":\"price_change\"}","received_at":"2026-07-27T03:15:40.187227Z","schema_version":"clob-market-ws.price_change.v1","sequence":null,"server_hash":null,"server_timestamp":"1785122140145","session_id":"dd162b8dca5f43ff811d304e69a06123","source":"clob_market_ws"},"received_at":"2026-07-27T03:15:40.187227Z","record_id":"3b77988d1b8e040b8a7996bcb7bb63872f2dbef9b3ca2a973333a685c63f0d5c","schema_fingerprint":"4aa3821a28b0b7c2400bc59aba4bcc0a76e971dadd19610d3ad38c768e124dc7","schema_version":"edge-lab-recorder.raw.v1","sequence":null,"source":"clob_market_ws"}
{"event_at":"2026-07-27T03:15:40.151000Z","event_fingerprint":"05a504a8fd55a3df239a25ccf671a4541b2db3c77c50dbba6beacdc77f8bee59","payload":{"connection_id":"c7dc2e4762f849c6b6f9306b6518dcab","event_at":"2026-07-27T03:15:40.151000Z","event_type":"price_change","frame_hash":"c6125c5cafada64a5b2c59966a13ed50a1a87f380f6332d97b3bc7fb8debc680","frame_index":0,"kind":"data","monotonic_ns":224123529579250,"payload":{"event_type":"price_change","market":"0x717c0e8ccd4d5c7040185188fbae28be901ca589a11a94b1b38ca36a79eccfeb","price_changes":[{"asset_id":"41448400836309843603620980831210604935021861034693225347475867885462478926555","best_ask":"0.45","best_bid":"0.44","hash":"ce50cf77dc7eb302df79183a0727736715aad12a","price":"0.32","side":"BUY","size":"116"},{"asset_id":"24254094493625419915756280046002869097156693848522361803041977572204227262166","best_ask":"0.56","best_bid":"0.55","hash":"b164e4c56099049371da1a40a278d2cfe0998aa9","price":"0.68","side":"SELL","size":"116"}],"timestamp":"1785122140151"},"payload_hash":"23dc621abd064102f86b0d920f386c5c645ff58063a21f6892c5b824aad62963","raw_frame":"{\"market\":\"0x717c0e8ccd4d5c7040185188fbae28be901ca589a11a94b1b38ca36a79eccfeb\", \"price_changes\":[{\"asset_id\":\"41448400836309843603620980831210604935021861034693225347475867885462478926555\", \"price\":\"0.32\", \"size\":\"116\", \"side\":\"BUY\", \"hash\":\"ce50cf77dc7eb302df79183a0727736715aad12a\", \"best_bid\":\"0.44\", \"best_ask\":\"0.45\"}, {\"asset_id\":\"24254094493625419915756280046002869097156693848522361803041977572204227262166\", \"price\":\"0.68\", \"size\":\"116\", \"side\":\"SELL\", \"hash\":\"b164e4c56099049371da1a40a278d2cfe0998aa9\", \"best_bid\":\"0.55\", \"best_ask\":\"0.56\"}], \"timestamp\":\"1785122140151\", \"event_type\":\"price_change\"}","received_at":"2026-07-27T03:15:40.195352Z","schema_version":"clob-market-ws.price_change.v1","sequence":null,"server_hash":null,"server_timestamp":"1785122140151","session_id":"dd162b8dca5f43ff811d304e69a06123","source":"clob_market_ws"},"received_at":"2026-07-27T03:15:40.195352Z","record_id":"12639a98ddd15e01b3d7d57bf3c55ed71243d7f683388aa4653f7e3059c2ce32","schema_fingerprint":"4aa3821a28b0b7c2400bc59aba4bcc0a76e971dadd19610d3ad38c768e124dc7","schema_version":"edge-lab-recorder.raw.v1","sequence":null,"source":"clob_market_ws"}
