{"event_at":"2026-07-27T03:19:18.437000Z","event_fingerprint":"3a1f11320ad740f207fe8c33e742761cfcba182b84cf1a59145826fe3f6865b2","payload":{"connection_id":"c7dc2e4762f849c6b6f9306b6518dcab","event_at":"2026-07-27T03:19:18.437000Z","event_type":"price_change","frame_hash":"a22dace0df22d02a609282a455ca950d599d2dface0e44e134e6da568411f3f0","frame_index":0,"kind":"data","monotonic_ns":224341808546000,"payload":{"event_type":"price_change","market":"0x717c0e8ccd4d5c7040185188fbae28be901ca589a11a94b1b38ca36a79eccfeb","price_changes":[{"asset_id":"24254094493625419915756280046002869097156693848522361803041977572204227262166","best_ask":"0.58","best_bid":"0.56","hash":"d7637bf544db3ddc41b6b0e81973f42a8cd96327","price":"0.5","side":"BUY","size":"192.38"},{"asset_id":"41448400836309843603620980831210604935021861034693225347475867885462478926555","best_ask":"0.44","best_bid":"0.42","hash":"9291546e0ed9f6aee9e1d129d9d7b0f8c5de2e01","price":"0.5","side":"SELL","size":"192.38"}],"timestamp":"1785122358437"},"payload_hash":"3ca5a5ed73339dbfbbeab155ed5fe002977dc82918a093f261359e02e4133cfa","raw_frame":"{\"market\":\"0x717c0e8ccd4d5c7040185188fbae28be901ca589a11a94b1b38ca36a79eccfeb\", \"price_changes\":[{\"asset_id\":\"24254094493625419915756280046002869097156693848522361803041977572204227262166\", \"price\":\"0.5\", \"size\":\"192.38\", \"side\":\"BUY\", \"hash\":\"d7637bf544db3ddc41b6b0e81973f42a8cd96327\", \"best_bid\":\"0.56\", \"best_ask\":\"0.58\"}, {\"asset_id\":\"41448400836309843603620980831210604935021861034693225347475867885462478926555\", \"price\":\"0.5\", \"size\":\"192.38\", \"side\":\"SELL\", \"hash\":\"9291546e0ed9f6aee9e1d129d9d7b0f8c5de2e01\", \"best_bid\":\"0.42\", \"best_ask\":\"0.44\"}], \"timestamp\":\"1785122358437\", \"event_type\":\"price_change\"}","received_at":"2026-07-27T03:19:18.471258Z","schema_version":"clob-market-ws.price_change.v1","sequence":null,"server_hash":null,"server_timestamp":"1785122358437","session_id":"dd162b8dca5f43ff811d304e69a06123","source":"clob_market_ws"},"received_at":"2026-07-27T03:19:18.471258Z","record_id":"76846eab9418415966bd65588708491f6d28711c0690029bb87723abdf543c95","schema_fingerprint":"4aa3821a28b0b7c2400bc59aba4bcc0a76e971dadd19610d3ad38c768e124dc7","schema_version":"edge-lab-recorder.raw.v1","sequence":null,"source":"clob_market_ws"}
{"event_at":"2026-07-27T03:19:18.441000Z","event_fingerprint":"7c3f3b45b66f617ff9368c4e2b064e6f9bfaf450f966a46693761e89dbab83ef","payload":{"connection_id":"c7dc2e4762f849c6b6f9306b6518dcab","event_at":"2026-07-27T03:19:18.441000Z","event_type":"best_bid_ask","frame_hash":"0889a7ed89449650cbf7262201bbc1b647851ebc633faaf7c33bc0033bf6b507","frame_index":0,"kind":"data","monotonic_ns":224341815829625,"payload":{"asset_id":"24254094493625419915756280046002869097156693848522361803041977572204227262166","best_ask":"0.57","best_bid":"0.56","event_type":"best_bid_ask","market":"0x717c0e8ccd4d5c7040185188fbae28be901ca589a11a94b1b38ca36a79eccfeb","spread":"0.01","timestamp":"1785122358441"},"payload_hash":"92e5f10b6a4c7df6da49cd87600dd9ef5c86c9e1f111564d7118741c7c6a160c","raw_frame":"{\"market\":\"0x717c0e8ccd4d5c7040185188fbae28be901ca589a11a94b1b38ca36a79eccfeb\", \"asset_id\":\"24254094493625419915756280046002869097156693848522361803041977572204227262166\", \"best_bid\":\"0.56\", \"best_ask\":\"0.57\", \"spread\":\"0.01\", \"timestamp\":\"1785122358441\", \"event_type\":\"best_bid_ask\"}","received_at":"2026-07-27T03:19:18.478542Z","schema_version":"clob-market-ws.best_bid_ask.v1","sequence":null,"server_hash":null,"server_timestamp":"1785122358441","session_id":"dd162b8dca5f43ff811d304e69a06123","source":"clob_market_ws"},"received_at":"2026-07-27T03:19:18.478542Z","record_id":"07ebfde8561d5082f841d61b861253f5770e93bea9f22dca5eb7bfddad6f43d7","schema_fingerprint":"8488399f31b0337811b13b266be932db7062827c2470b78bd8e9e99bab51d17d","schema_version":"edge-lab-recorder.raw.v1","sequence":null,"source":"clob_market_ws"}
{"event_at":"2026-07-27T03:19:18.441000Z","event_fingerprint":"256b943be890b65bfa1d746db3107e946c71ea0bf56729a8c9b8df9705f8afa3","payload":{"connection_id":"c7dc2e4762f849c6b6f9306b6518dcab","event_at":"2026-07-27T03:19:18.441000Z","event_type":"best_bid_ask","frame_hash":"410191eb760f622a444efd9324aedc5fb798bae2ba3f70d080a34023c20b95e0","frame_index":0,"kind":"data","monotonic_ns":224341817709791,"payload":{"asset_id":"41448400836309843603620980831210604935021861034693225347475867885462478926555","best_ask":"0.44","best_bid":"0.43","event_type":"best_bid_ask","market":"0x717c0e8ccd4d5c7040185188fbae28be901ca589a11a94b1b38ca36a79eccfeb","spread":"0.01","timestamp":"1785122358441"},"payload_hash":"f72ccc5d749415b656d9696b4b05d4f2d4dd6c00b438bf7a22ce92f2ea514376","raw_frame":"{\"market\":\"0x717c0e8ccd4d5c7040185188fbae28be901ca589a11a94b1b38ca36a79eccfeb\", \"asset_id\":\"41448400836309843603620980831210604935021861034693225347475867885462478926555\", \"best_bid\":\"0.43\", \"best_ask\":\"0.44\", \"spread\":\"0.01\", \"timestamp\":\"1785122358441\", \"event_type\":\"best_bid_ask\"}","received_at":"2026-07-27T03:19:18.480422Z","schema_version":"clob-market-ws.best_bid_ask.v1","sequence":null,"server_hash":null,"server_timestamp":"1785122358441","session_id":"dd162b8dca5f43ff811d304e69a06123","source":"clob_market_ws"},"received_at":"2026-07-27T03:19:18.480422Z","record_id":"489819b537f7f4fafad36404b9f6302b5d9e913f545fa71ed5f3d502427535d6","schema_fingerprint":"8488399f31b0337811b13b266be932db7062827c2470b78bd8e9e99bab51d17d","schema_version":"edge-lab-recorder.raw.v1","sequence":null,"source":"clob_market_ws"}
{"event_at":"2026-07-27T03:19:18.440000Z","event_fingerprint":"4e908b272f034c9ceaa84945b5a0b45ba86318b0391da652bf44b5f42ce5524c","payload":{"connection_id":"c7dc2e4762f849c6b6f9306b6518dcab","event_at":"2026-07-27T03:19:18.440000Z","event_type":"price_change","frame_hash":"17dfbc3d1eb9cc46c62887a94cbc69964169b0eb3471d0b93c3d545ee20290c0","frame_index":0,"kind":"data","monotonic_ns":224341820940666,"payload":{"event_type":"price_change","market":"0x717c0e8ccd4d5c7040185188fbae28be901ca589a11a94b1b38ca36a79eccfeb","price_changes":[{"asset_id":"41448400836309843603620980831210604935021861034693225347475867885462478926555","best_ask":"0.44","best_bid":"0.43","hash":"1969eef6f0949706146d17a740735852c9eaaabb","price":"0.43","side":"BUY","size":"5"},{"asset_id":"24254094493625419915756280046002869097156693848522361803041977572204227262166","best_ask":"0.57","best_bid":"0.56","hash":"f1841745abeb53d33c0233e9c0467c7c1cc7d4c4","price":"0.57","side":"SELL","size":"5"}],"timestamp":"1785122358440"},"payload_hash":"516291fd375a1add98c10f9fcda42266667f5c6c585358c7e2342fad01415aa0","raw_frame":"{\"market\":\"0x717c0e8ccd4d5c7040185188fbae28be901ca589a11a94b1b38ca36a79eccfeb\", \"price_changes\":[{\"asset_id\":\"41448400836309843603620980831210604935021861034693225347475867885462478926555\", \"price\":\"0.43\", \"size\":\"5\", \"side\":\"BUY\", \"hash\":\"1969eef6f0949706146d17a740735852c9eaaabb\", \"best_bid\":\"0.43\", \"best_ask\":\"0.44\"}, {\"asset_id\":\"24254094493625419915756280046002869097156693848522361803041977572204227262166\", \"price\":\"0.57\", \"size\":\"5\", \"side\":\"SELL\", \"hash\":\"f1841745abeb53d33c0233e9c0467c7c1cc7d4c4\", \"best_bid\":\"0.56\", \"best_ask\":\"0.57\"}], \"timestamp\":\"1785122358440\", \"event_type\":\"price_change\"}","received_at":"2026-07-27T03:19:18.483652Z","schema_version":"clob-market-ws.price_change.v1","sequence":null,"server_hash":null,"server_timestamp":"1785122358440","session_id":"dd162b8dca5f43ff811d304e69a06123","source":"clob_market_ws"},"received_at":"2026-07-27T03:19:18.483652Z","record_id":"3ab0921777edf3f3cea9cbe21f6b980bd58353f25c0c4f713c80b0c78aa780b0","schema_fingerprint":"4aa3821a28b0b7c2400bc59aba4bcc0a76e971dadd19610d3ad38c768e124dc7","schema_version":"edge-lab-recorder.raw.v1","sequence":null,"source":"clob_market_ws"}
{"event_at":"2026-07-27T03:19:18.443000Z","event_fingerprint":"489d94daac55e8ca2d0b0dff96f9d329d6c00545726fb5f0cfdd2769b0a4c123","payload":{"connection_id":"c7dc2e4762f849c6b6f9306b6518dcab","event_at":"2026-07-27T03:19:18.443000Z","event_type":"price_change","frame_hash":"0ec3073027de5d49287e8f7064698388a5c118bdf99a596b4189f6ad085b721f","frame_index":0,"kind":"data","monotonic_ns":224341823361416,"payload":{"event_type":"price_change","market":"0x717c0e8ccd4d5c7040185188fbae28be901ca589a11a94b1b38ca36a79eccfeb","price_changes":[{"asset_id":"41448400836309843603620980831210604935021861034693225347475867885462478926555","best_ask":"0.44","best_bid":"0.43","hash":"c8f1a286a006be5f20910f86ce73710092d5ed26","price":"0.43","side":"BUY","size":"45"},{"asset_id":"24254094493625419915756280046002869097156693848522361803041977572204227262166","best_ask":"0.57","best_bid":"0.56","hash":"abf756cbe679d3bb026fa70c2d87aadfcfd4fbfa","price":"0.57","side":"SELL","size":"45"}],"timestamp":"1785122358443"},"payload_hash":"e7b96ad26df7e8f88624d913c9a36861ff634674e6130b15b07cc8b9ad389fb0","raw_frame":"{\"market\":\"0x717c0e8ccd4d5c7040185188fbae28be901ca589a11a94b1b38ca36a79eccfeb\", \"price_changes\":[{\"asset_id\":\"41448400836309843603620980831210604935021861034693225347475867885462478926555\", \"price\":\"0.43\", \"size\":\"45\", \"side\":\"BUY\", \"hash\":\"c8f1a286a006be5f20910f86ce73710092d5ed26\", \"best_bid\":\"0.43\", \"best_ask\":\"0.44\"}, {\"asset_id\":\"24254094493625419915756280046002869097156693848522361803041977572204227262166\", \"price\":\"0.57\", \"size\":\"45\", \"side\":\"SELL\", \"hash\":\"abf756cbe679d3bb026fa70c2d87aadfcfd4fbfa\", \"best_bid\":\"0.56\", \"best_ask\":\"0.57\"}], \"timestamp\":\"1785122358443\", \"event_type\":\"price_change\"}","received_at":"2026-07-27T03:19:18.486074Z","schema_version":"clob-market-ws.price_change.v1","sequence":null,"server_hash":null,"server_timestamp":"1785122358443","session_id":"dd162b8dca5f43ff811d304e69a06123","source":"clob_market_ws"},"received_at":"2026-07-27T03:19:18.486074Z","record_id":"c25bb1f81ed3fc0bf6b8d85432f6c1ee7b2fbe2259195114e225cc73405d1b57","schema_fingerprint":"4aa3821a28b0b7c2400bc59aba4bcc0a76e971dadd19610d3ad38c768e124dc7","schema_version":"edge-lab-recorder.raw.v1","sequence":null,"source":"clob_market_ws"}
{"event_at":"2026-07-27T03:19:18.444000Z","event_fingerprint":"b5dd77c97d7cb246d0eeb0f52ee5471e6f78287648c277cbb9eb8b195c8d0165","payload":{"connection_id":"c7dc2e4762f849c6b6f9306b6518dcab","event_at":"2026-07-27T03:19:18.444000Z","event_type":"price_change","frame_hash":"306a154b4cd25ca7219ba27961f82e5e62d66864cfa9ffe50c6b00e41755070d","frame_index":0,"kind":"data","monotonic_ns":224341826294208,"payload":{"event_type":"price_change","market":"0x717c0e8ccd4d5c7040185188fbae28be901ca589a11a94b1b38ca36a79eccfeb","price_changes":[{"asset_id":"24254094493625419915756280046002869097156693848522361803041977572204227262166","best_ask":"0.57","best_bid":"0.56","hash":"9fc99ff0a15bf64316337c5e2752608bffdb1eec","price":"0.5","side":"BUY","size":"222.38"},{"asset_id":"41448400836309843603620980831210604935021861034693225347475867885462478926555","best_ask":"0.44","best_bid":"0.43","hash":"4ebd04d9203f10cd56857215061ac0f86383c3d8","price":"0.5","side":"SELL","size":"222.38"}],"timestamp":"1785122358444"},"payload_hash":"568c0d3675884221afaac1dbd7468463586f3618bd1c332516a6d9f09a088fa5","raw_frame":"{\"market\":\"0x717c0e8ccd4d5c7040185188fbae28be901ca589a11a94b1b38ca36a79eccfeb\", \"price_changes\":[{\"asset_id\":\"24254094493625419915756280046002869097156693848522361803041977572204227262166\", \"price\":\"0.5\", \"size\":\"222.38\", \"side\":\"BUY\", \"hash\":\"9fc99ff0a15bf64316337c5e2752608bffdb1eec\", \"best_bid\":\"0.56\", \"best_ask\":\"0.57\"}, {\"asset_id\":\"41448400836309843603620980831210604935021861034693225347475867885462478926555\", \"price\":\"0.5\", \"size\":\"222.38\", \"side\":\"SELL\", \"hash\":\"4ebd04d9203f10cd56857215061ac0f86383c3d8\", \"best_bid\":\"0.43\", \"best_ask\":\"0.44\"}], \"timestamp\":\"1785122358444\", \"event_type\":\"price_change\"}","received_at":"2026-07-27T03:19:18.489007Z","schema_version":"clob-market-ws.price_change.v1","sequence":null,"server_hash":null,"server_timestamp":"1785122358444","session_id":"dd162b8dca5f43ff811d304e69a06123","source":"clob_market_ws"},"received_at":"2026-07-27T03:19:18.489007Z","record_id":"5ca70f11373a899c24b02cba30906e3e7b8caabd197fdfd0cd060736eefda85a","schema_fingerprint":"4aa3821a28b0b7c2400bc59aba4bcc0a76e971dadd19610d3ad38c768e124dc7","schema_version":"edge-lab-recorder.raw.v1","sequence":null,"source":"clob_market_ws"}
{"event_at":"2026-07-27T03:19:18.445000Z","event_fingerprint":"e5bb7c4cff210a0be22dcc9a560b2b3931426a84d648125ee1ebaed80695e1e1","payload":{"connection_id":"c7dc2e4762f849c6b6f9306b6518dcab","event_at":"2026-07-27T03:19:18.445000Z","event_type":"price_change","frame_hash":"eebe5206d30bb92d3fa9b97227805a4c33b00bdca15546889330ba73d73fe7ba","frame_index":0,"kind":"data","monotonic_ns":224341828912125,"payload":{"event_type":"price_change","market":"0x717c0e8ccd4d5c7040185188fbae28be901ca589a11a94b1b38ca36a79eccfeb","price_changes":[{"asset_id":"24254094493625419915756280046002869097156693848522361803041977572204227262166","best_ask":"0.57","best_bid":"0.56","hash":"a5a375356a65686bd723eb272521b61622eed34f","price":"0.58","side":"SELL","size":"443.4"},{"asset_id":"41448400836309843603620980831210604935021861034693225347475867885462478926555","best_ask":"0.44","best_bid":"0.43","hash":"782f1da46ee2abb78d1b01731dddae00ce8adc8e","price":"0.42","side":"BUY","size":"443.4"}],"timestamp":"1785122358445"},"payload_hash":"bf5890cd3bba78bf08b115790ad74f80de8c82456baa95c2876589e61228c4d8","raw_frame":"{\"market\":\"0x717c0e8ccd4d5c7040185188fbae28be901ca589a11a94b1b38ca36a79eccfeb\", \"price_changes\":[{\"asset_id\":\"24254094493625419915756280046002869097156693848522361803041977572204227262166\", \"price\":\"0.58\", \"size\":\"443.4\", \"side\":\"SELL\", \"hash\":\"a5a375356a65686bd723eb272521b61622eed34f\", \"best_bid\":\"0.56\", \"best_ask\":\"0.57\"}, {\"asset_id\":\"41448400836309843603620980831210604935021861034693225347475867885462478926555\", \"price\":\"0.42\", \"size\":\"443.4\", \"side\":\"BUY\", \"hash\":\"782f1da46ee2abb78d1b01731dddae00ce8adc8e\", \"best_bid\":\"0.43\", \"best_ask\":\"0.44\"}], \"timestamp\":\"1785122358445\", \"event_type\":\"price_change\"}","received_at":"2026-07-27T03:19:18.491622Z","schema_version":"clob-market-ws.price_change.v1","sequence":null,"server_hash":null,"server_timestamp":"1785122358445","session_id":"dd162b8dca5f43ff811d304e69a06123","source":"clob_market_ws"},"received_at":"2026-07-27T03:19:18.491622Z","record_id":"7ba7293785561ce5e6828a61cc56825c2957c43f9dd335f25ba03be42554c94b","schema_fingerprint":"4aa3821a28b0b7c2400bc59aba4bcc0a76e971dadd19610d3ad38c768e124dc7","schema_version":"edge-lab-recorder.raw.v1","sequence":null,"source":"clob_market_ws"}
{"event_at":"2026-07-27T03:19:18.447000Z","event_fingerprint":"a454e7098cb9a51c43cec068dda4968e3cc4b61a6ba0fe5992e0b87196995043","payload":{"connection_id":"c7dc2e4762f849c6b6f9306b6518dcab","event_at":"2026-07-27T03:19:18.447000Z","event_type":"price_change","frame_hash":"0d894bf4abc9198f8dafe564a3f247dd1a0dfd9ce37846519044c5bd2771ebb1","frame_index":0,"kind":"data","monotonic_ns":224341831962666,"payload":{"event_type":"price_change","market":"0x717c0e8ccd4d5c7040185188fbae28be901ca589a11a94b1b38ca36a79eccfeb","price_changes":[{"asset_id":"24254094493625419915756280046002869097156693848522361803041977572204227262166","best_ask":"0.57","best_bid":"0.56","hash":"87d6b9e40c922d04c8e80a8510d51b57b6145d64","price":"0.5","side":"BUY","size":"252.38"},{"asset_id":"41448400836309843603620980831210604935021861034693225347475867885462478926555","best_ask":"0.44","best_bid":"0.43","hash":"b59df832b23a8279628c07b15f8f2300d9d0ebe4","price":"0.5","side":"SELL","size":"252.38"}],"timestamp":"1785122358447"},"payload_hash":"65fb26b16865889c6ad2daae88778eb0b3143f5126bb0daef5db90376e1ceca1","raw_frame":"{\"market\":\"0x717c0e8ccd4d5c7040185188fbae28be901ca589a11a94b1b38ca36a79eccfeb\", \"price_changes\":[{\"asset_id\":\"24254094493625419915756280046002869097156693848522361803041977572204227262166\", \"price\":\"0.5\", \"size\":\"252.38\", \"side\":\"BUY\", \"hash\":\"87d6b9e40c922d04c8e80a8510d51b57b6145d64\", \"best_bid\":\"0.56\", \"best_ask\":\"0.57\"}, {\"asset_id\":\"41448400836309843603620980831210604935021861034693225347475867885462478926555\", \"price\":\"0.5\", \"size\":\"252.38\", \"side\":\"SELL\", \"hash\":\"b59df832b23a8279628c07b15f8f2300d9d0ebe4\", \"best_bid\":\"0.43\", \"best_ask\":\"0.44\"}], \"timestamp\":\"1785122358447\", \"event_type\":\"price_change\"}","received_at":"2026-07-27T03:19:18.494673Z","schema_version":"clob-market-ws.price_change.v1","sequence":null,"server_hash":null,"server_timestamp":"1785122358447","session_id":"dd162b8dca5f43ff811d304e69a06123","source":"clob_market_ws"},"received_at":"2026-07-27T03:19:18.494673Z","record_id":"c4e7a30d28894874f3f06e88946b51a9623f9de5005af6dccb5a39a85e261a7a","schema_fingerprint":"4aa3821a28b0b7c2400bc59aba4bcc0a76e971dadd19610d3ad38c768e124dc7","schema_version":"edge-lab-recorder.raw.v1","sequence":null,"source":"clob_market_ws"}
{"event_at":"2026-07-27T03:19:18.448000Z","event_fingerprint":"f14c1940219d320924c99e8ef20d34e5efa5197c6b3f0b1b2dccbe978afb7f92","payload":{"connection_id":"c7dc2e4762f849c6b6f9306b6518dcab","event_at":"2026-07-27T03:19:18.448000Z","event_type":"price_change","frame_hash":"f92913786d745ddd67e875968c500aaf4c33eb19a2ec78ca07d121c184b1e4e7","frame_index":0,"kind":"data","monotonic_ns":224341836676416,"payload":{"event_type":"price_change","market":"0x717c0e8ccd4d5c7040185188fbae28be901ca589a11a94b1b38ca36a79eccfeb","price_changes":[{"asset_id":"24254094493625419915756280046002869097156693848522361803041977572204227262166","best_ask":"0.57","best_bid":"0.56","hash":"15a73bdf0fe3fdeac8d11397d26354cd09776fbc","price":"0.58","side":"SELL","size":"438.4"},{"asset_id":"41448400836309843603620980831210604935021861034693225347475867885462478926555","best_ask":"0.44","best_bid":"0.43","hash":"1df307bcf5cace3c097ef28530dfcd69b6eb5a82","price":"0.42","side":"BUY","size":"438.4"}],"timestamp":"1785122358448"},"payload_hash":"a213214d0d3a33bfa9de1a23f0f5e91897ad9be9732228213d94129600dc8669","raw_frame":"{\"market\":\"0x717c0e8ccd4d5c7040185188fbae28be901ca589a11a94b1b38ca36a79eccfeb\", \"price_changes\":[{\"asset_id\":\"24254094493625419915756280046002869097156693848522361803041977572204227262166\", \"price\":\"0.58\", \"size\":\"438.4\", \"side\":\"SELL\", \"hash\":\"15a73bdf0fe3fdeac8d11397d26354cd09776fbc\", \"best_bid\":\"0.56\", \"best_ask\":\"0.57\"}, {\"asset_id\":\"41448400836309843603620980831210604935021861034693225347475867885462478926555\", \"price\":\"0.42\", \"size\":\"438.4\", \"side\":\"BUY\", \"hash\":\"1df307bcf5cace3c097ef28530dfcd69b6eb5a82\", \"best_bid\":\"0.43\", \"best_ask\":\"0.44\"}], \"timestamp\":\"1785122358448\", \"event_type\":\"price_change\"}","received_at":"2026-07-27T03:19:18.499389Z","schema_version":"clob-market-ws.price_change.v1","sequence":null,"server_hash":null,"server_timestamp":"1785122358448","session_id":"dd162b8dca5f43ff811d304e69a06123","source":"clob_market_ws"},"received_at":"2026-07-27T03:19:18.499389Z","record_id":"7f7f589582366ed62da370bb5f3fec155719d5cda2b9359db80d001f3c9d1dcc","schema_fingerprint":"4aa3821a28b0b7c2400bc59aba4bcc0a76e971dadd19610d3ad38c768e124dc7","schema_version":"edge-lab-recorder.raw.v1","sequence":null,"source":"clob_market_ws"}
{"event_at":"2026-07-27T03:19:18.449000Z","event_fingerprint":"f54c2f234ec755890292a1662f4b157809a9d3bfc927ee111da677681cf80cf2","payload":{"connection_id":"c7dc2e4762f849c6b6f9306b6518dcab","event_at":"2026-07-27T03:19:18.449000Z","event_type":"price_change","frame_hash":"798ba727f1d6a35d6348a3cddf2093f7d74a529ca6202ee8c3034970d66ed7e2","frame_index":0,"kind":"data","monotonic_ns":224341838960041,"payload":{"event_type":"price_change","market":"0x717c0e8ccd4d5c7040185188fbae28be901ca589a11a94b1b38ca36a79eccfeb","price_changes":[{"asset_id":"41448400836309843603620980831210604935021861034693225347475867885462478926555","best_ask":"0.44","best_bid":"0.43","hash":"1dfb696210ea38fcb4c49331ba69e040fe9c4562","price":"0.28","side":"BUY","size":"49.9"},{"asset_id":"24254094493625419915756280046002869097156693848522361803041977572204227262166","best_ask":"0.57","best_bid":"0.56","hash":"84a6940974b6e7f617b45a3a5a5adf138ee4900f","price":"0.72","side":"SELL","size":"49.9"}],"timestamp":"1785122358449"},"payload_hash":"f4ef0bd90fb388bd871c2cb9176cd37cd0a0cf588a2d9ef94d31cbf57e6465e6","raw_frame":"{\"market\":\"0x717c0e8ccd4d5c7040185188fbae28be901ca589a11a94b1b38ca36a79eccfeb\", \"price_changes\":[{\"asset_id\":\"41448400836309843603620980831210604935021861034693225347475867885462478926555\", \"price\":\"0.28\", \"size\":\"49.9\", \"side\":\"BUY\", \"hash\":\"1dfb696210ea38fcb4c49331ba69e040fe9c4562\", \"best_bid\":\"0.43\", \"best_ask\":\"0.44\"}, {\"asset_id\":\"24254094493625419915756280046002869097156693848522361803041977572204227262166\", \"price\":\"0.72\", \"size\":\"49.9\", \"side\":\"SELL\", \"hash\":\"84a6940974b6e7f617b45a3a5a5adf138ee4900f\", \"best_bid\":\"0.56\", \"best_ask\":\"0.57\"}], \"timestamp\":\"1785122358449\", \"event_type\":\"price_change\"}","received_at":"2026-07-27T03:19:18.501672Z","schema_version":"clob-market-ws.price_change.v1","sequence":null,"server_hash":null,"server_timestamp":"1785122358449","session_id":"dd162b8dca5f43ff811d304e69a06123","source":"clob_market_ws"},"received_at":"2026-07-27T03:19:18.501672Z","record_id":"c1567eaf737f61204205d30aabc90531584c5e29f99e6be84075c07e5dc13965","schema_fingerprint":"4aa3821a28b0b7c2400bc59aba4bcc0a76e971dadd19610d3ad38c768e124dc7","schema_version":"edge-lab-recorder.raw.v1","sequence":null,"source":"clob_market_ws"}
{"event_at":"2026-07-27T03:19:18.450000Z","event_fingerprint":"0fb985d21f1b8365187c3593f29152210aac53f08a1f1c55b55f19839c3de4d4","payload":{"connection_id":"c7dc2e4762f849c6b6f9306b6518dcab","event_at":"2026-07-27T03:19:18.450000Z","event_type":"price_change","frame_hash":"6722de65b841fcc9215e689a4d7f7ca4e3fa797b0f3615865ec1b4c6d48346ff","frame_index":0,"kind":"data","monotonic_ns":224341842015083,"payload":{"event_type":"price_change","market":"0x717c0e8ccd4d5c7040185188fbae28be901ca589a11a94b1b38ca36a79eccfeb","price_changes":[{"asset_id":"41448400836309843603620980831210604935021861034693225347475867885462478926555","best_ask":"0.44","best_bid":"0.43","hash":"f197aea130d11be90cb5b0d5d2522187864a5893","price":"0.42","side":"BUY","size":"432.4"},{"asset_id":"24254094493625419915756280046002869097156693848522361803041977572204227262166","best_ask":"0.57","best_bid":"0.56","hash":"c01cce57648ed1d7b832ccde2c9becba79ae4a1e","price":"0.58","side":"SELL","size":"432.4"}],"timestamp":"1785122358450"},"payload_hash":"0e0e45165382192bd7e0983425bea119b018f0d3cb481497bf3be467bb7c5e63","raw_frame":"{\"market\":\"0x717c0e8ccd4d5c7040185188fbae28be901ca589a11a94b1b38ca36a79eccfeb\", \"price_changes\":[{\"asset_id\":\"41448400836309843603620980831210604935021861034693225347475867885462478926555\", \"price\":\"0.42\", \"size\":\"432.4\", \"side\":\"BUY\", \"hash\":\"f197aea130d11be90cb5b0d5d2522187864a5893\", \"best_bid\":\"0.43\", \"best_ask\":\"0.44\"}, {\"asset_id\":\"24254094493625419915756280046002869097156693848522361803041977572204227262166\", \"price\":\"0.58\", \"size\":\"432.4\", \"side\":\"SELL\", \"hash\":\"c01cce57648ed1d7b832ccde2c9becba79ae4a1e\", \"best_bid\":\"0.56\", \"best_ask\":\"0.57\"}], \"timestamp\":\"1785122358450\", \"event_type\":\"price_change\"}","received_at":"2026-07-27T03:19:18.504727Z","schema_version":"clob-market-ws.price_change.v1","sequence":null,"server_hash":null,"server_timestamp":"1785122358450","session_id":"dd162b8dca5f43ff811d304e69a06123","source":"clob_market_ws"},"received_at":"2026-07-27T03:19:18.504727Z","record_id":"62ce2e5517d30c75c862bd74dc6875573acd10c3cd1c305554f515aad53a0be8","schema_fingerprint":"4aa3821a28b0b7c2400bc59aba4bcc0a76e971dadd19610d3ad38c768e124dc7","schema_version":"edge-lab-recorder.raw.v1","sequence":null,"source":"clob_market_ws"}
{"event_at":"2026-07-27T03:19:18.450000Z","event_fingerprint":"76219f1fd6affe43ebf398ebf49288e5ac8e5e26319bde35257e1927436e427f","payload":{"connection_id":"c7dc2e4762f849c6b6f9306b6518dcab","event_at":"2026-07-27T03:19:18.450000Z","event_type":"price_change","frame_hash":"cb7dc6e1ed493707edb7e34239044474e3174e88c49ca4b879f358dde216a9d3","frame_index":0,"kind":"data","monotonic_ns":224341846140958,"payload":{"event_type":"price_change","market":"0x717c0e8ccd4d5c7040185188fbae28be901ca589a11a94b1b38ca36a79eccfeb","price_changes":[{"asset_id":"41448400836309843603620980831210604935021861034693225347475867885462478926555","best_ask":"0.44","best_bid":"0.43","hash":"47685b647609de364aea75753c953881c312c879","price":"0.42","side":"BUY","size":"427.4"},{"asset_id":"24254094493625419915756280046002869097156693848522361803041977572204227262166","best_ask":"0.57","best_bid":"0.56","hash":"ab6b384c2b66d9065e9b644491b33fa36da14ff2","price":"0.58","side":"SELL","size":"427.4"}],"timestamp":"1785122358450"},"payload_hash":"2b6e1439e47d0248f0f89485ceb7cfdb755da39df09e73aa253a1d12fc9dc1ae","raw_frame":"{\"market\":\"0x717c0e8ccd4d5c7040185188fbae28be901ca589a11a94b1b38ca36a79eccfeb\", \"price_changes\":[{\"asset_id\":\"41448400836309843603620980831210604935021861034693225347475867885462478926555\", \"price\":\"0.42\", \"size\":\"427.4\", \"side\":\"BUY\", \"hash\":\"47685b647609de364aea75753c953881c312c879\", \"best_bid\":\"0.43\", \"best_ask\":\"0.44\"}, {\"asset_id\":\"24254094493625419915756280046002869097156693848522361803041977572204227262166\", \"price\":\"0.58\", \"size\":\"427.4\", \"side\":\"SELL\", \"hash\":\"ab6b384c2b66d9065e9b644491b33fa36da14ff2\", \"best_bid\":\"0.56\", \"best_ask\":\"0.57\"}], \"timestamp\":\"1785122358450\", \"event_type\":\"price_change\"}","received_at":"2026-07-27T03:19:18.508852Z","schema_version":"clob-market-ws.price_change.v1","sequence":null,"server_hash":null,"server_timestamp":"1785122358450","session_id":"dd162b8dca5f43ff811d304e69a06123","source":"clob_market_ws"},"received_at":"2026-07-27T03:19:18.508852Z","record_id":"69b44d9cc1f5d0df15f3d6a26bc3f699e1c9be354afca047d8c061d30421f183","schema_fingerprint":"4aa3821a28b0b7c2400bc59aba4bcc0a76e971dadd19610d3ad38c768e124dc7","schema_version":"edge-lab-recorder.raw.v1","sequence":null,"source":"clob_market_ws"}
{"event_at":"2026-07-27T03:19:18.451000Z","event_fingerprint":"1a9c92db8bf0411f40a97a28d95635a448353ff334804f3791bf7d1410a36239","payload":{"connection_id":"c7dc2e4762f849c6b6f9306b6518dcab","event_at":"2026-07-27T03:19:18.451000Z","event_type":"price_change","frame_hash":"4c165b1ee4f0c6a134781dd49c615cf98f2f7bd17db6de1dfadcd542a5c049fa","frame_index":0,"kind":"data","monotonic_ns":224341848534375,"payload":{"event_type":"price_change","market":"0x717c0e8ccd4d5c7040185188fbae28be901ca589a11a94b1b38ca36a79eccfeb","price_changes":[{"asset_id":"41448400836309843603620980831210604935021861034693225347475867885462478926555","best_ask":"0.44","best_bid":"0.43","hash":"309f28e110ce33798df435b14e4668e48fde74b4","price":"0.42","side":"BUY","size":"417.4"},{"asset_id":"24254094493625419915756280046002869097156693848522361803041977572204227262166","best_ask":"0.57","best_bid":"0.56","hash":"3dca86142600059bfce42a4c59ff020da19e1337","price":"0.58","side":"SELL","size":"417.4"}],"timestamp":"1785122358451"},"payload_hash":"e494d87779229d5b59a0828c1ef74f845d1e3bfb114c79822ac99940b86bf8d7","raw_frame":"{\"market\":\"0x717c0e8ccd4d5c7040185188fbae28be901ca589a11a94b1b38ca36a79eccfeb\", \"price_changes\":[{\"asset_id\":\"41448400836309843603620980831210604935021861034693225347475867885462478926555\", \"price\":\"0.42\", \"size\":\"417.4\", \"side\":\"BUY\", \"hash\":\"309f28e110ce33798df435b14e4668e48fde74b4\", \"best_bid\":\"0.43\", \"best_ask\":\"0.44\"}, {\"asset_id\":\"24254094493625419915756280046002869097156693848522361803041977572204227262166\", \"price\":\"0.58\", \"size\":\"417.4\", \"side\":\"SELL\", \"hash\":\"3dca86142600059bfce42a4c59ff020da19e1337\", \"best_bid\":\"0.56\", \"best_ask\":\"0.57\"}], \"timestamp\":\"1785122358451\", \"event_type\":\"price_change\"}","received_at":"2026-07-27T03:19:18.511245Z","schema_version":"clob-market-ws.price_change.v1","sequence":null,"server_hash":null,"server_timestamp":"1785122358451","session_id":"dd162b8dca5f43ff811d304e69a06123","source":"clob_market_ws"},"received_at":"2026-07-27T03:19:18.511245Z","record_id":"cd0b4c34198b48b63f80a5f920533abc75f636dd3914c6599b38069ad2d1d587","schema_fingerprint":"4aa3821a28b0b7c2400bc59aba4bcc0a76e971dadd19610d3ad38c768e124dc7","schema_version":"edge-lab-recorder.raw.v1","sequence":null,"source":"clob_market_ws"}
{"event_at":"2026-07-27T03:19:18.458000Z","event_fingerprint":"a528b73817b23f6674c49c9d937e50e503d184e6ae5b724b677498a742e22c02","payload":{"connection_id":"c7dc2e4762f849c6b6f9306b6518dcab","event_at":"2026-07-27T03:19:18.458000Z","event_type":"price_change","frame_hash":"31d83ef6c767ee6f8179793c977ded55d31db7ecf2613803bd34f40a4f6a4dda","frame_index":0,"kind":"data","monotonic_ns":224341851531958,"payload":{"event_type":"price_change","market":"0x717c0e8ccd4d5c7040185188fbae28be901ca589a11a94b1b38ca36a79eccfeb","price_changes":[{"asset_id":"41448400836309843603620980831210604935021861034693225347475867885462478926555","best_ask":"0.44","best_bid":"0.43","hash":"d7e39dcaac2fb3cc7b350f71015fd2473fa8eb1f","price":"0.43","side":"BUY","size":"50.54"},{"asset_id":"24254094493625419915756280046002869097156693848522361803041977572204227262166","best_ask":"0.57","best_bid":"0.56","hash":"20109b4ae9af66f21302e4b9b6f45740add1e923","price":"0.57","side":"SELL","size":"50.54"}],"timestamp":"1785122358458"},"payload_hash":"5936bd78d0fbc4f77ff370cecc83d2acd57ea7fcb1d4e75b61e016110963ead1","raw_frame":"{\"market\":\"0x717c0e8ccd4d5c7040185188fbae28be901ca589a11a94b1b38ca36a79eccfeb\", \"price_changes\":[{\"asset_id\":\"41448400836309843603620980831210604935021861034693225347475867885462478926555\", \"price\":\"0.43\", \"size\":\"50.54\", \"side\":\"BUY\", \"hash\":\"d7e39dcaac2fb3cc7b350f71015fd2473fa8eb1f\", \"best_bid\":\"0.43\", \"best_ask\":\"0.44\"}, {\"asset_id\":\"24254094493625419915756280046002869097156693848522361803041977572204227262166\", \"price\":\"0.57\", \"size\":\"50.54\", \"side\":\"SELL\", \"hash\":\"20109b4ae9af66f21302e4b9b6f45740add1e923\", \"best_bid\":\"0.56\", \"best_ask\":\"0.57\"}], \"timestamp\":\"1785122358458\", \"event_type\":\"price_change\"}","received_at":"2026-07-27T03:19:18.514245Z","schema_version":"clob-market-ws.price_change.v1","sequence":null,"server_hash":null,"server_timestamp":"1785122358458","session_id":"dd162b8dca5f43ff811d304e69a06123","source":"clob_market_ws"},"received_at":"2026-07-27T03:19:18.514245Z","record_id":"a06abf6e4dc3b38599a291462d07368016a7e84388487bdd753bec78d45fdc47","schema_fingerprint":"4aa3821a28b0b7c2400bc59aba4bcc0a76e971dadd19610d3ad38c768e124dc7","schema_version":"edge-lab-recorder.raw.v1","sequence":null,"source":"clob_market_ws"}
