{"event_at":"2026-07-27T03:16:43.149000Z","event_fingerprint":"14407f277bbb7bbe74e1388e48092f3747ea414d5100fcbbf6d7dfa3adab8144","payload":{"connection_id":"c7dc2e4762f849c6b6f9306b6518dcab","event_at":"2026-07-27T03:16:43.149000Z","event_type":"price_change","frame_hash":"3a5815628c9bdceb1267ae2652c4f0755cdca3c342772adf5d513ff673366c40","frame_index":0,"kind":"data","monotonic_ns":224186392367208,"payload":{"event_type":"price_change","market":"0x717c0e8ccd4d5c7040185188fbae28be901ca589a11a94b1b38ca36a79eccfeb","price_changes":[{"asset_id":"41448400836309843603620980831210604935021861034693225347475867885462478926555","best_ask":"0.46","best_bid":"0.45","hash":"0adf90ca6fe4998ecba842690a29a741119cb15c","price":"0.01","side":"BUY","size":"7703.02"},{"asset_id":"24254094493625419915756280046002869097156693848522361803041977572204227262166","best_ask":"0.55","best_bid":"0.54","hash":"f6078db598815fd90064a20cd3f8bd5c1ac38f85","price":"0.99","side":"SELL","size":"7703.02"}],"timestamp":"1785122203149"},"payload_hash":"b624ba6cd98bf703dc2e49b1aa53fbd7dd6ddb97614349981120b66af9598c65","raw_frame":"{\"market\":\"0x717c0e8ccd4d5c7040185188fbae28be901ca589a11a94b1b38ca36a79eccfeb\", \"price_changes\":[{\"asset_id\":\"41448400836309843603620980831210604935021861034693225347475867885462478926555\", \"price\":\"0.01\", \"size\":\"7703.02\", \"side\":\"BUY\", \"hash\":\"0adf90ca6fe4998ecba842690a29a741119cb15c\", \"best_bid\":\"0.45\", \"best_ask\":\"0.46\"}, {\"asset_id\":\"24254094493625419915756280046002869097156693848522361803041977572204227262166\", \"price\":\"0.99\", \"size\":\"7703.02\", \"side\":\"SELL\", \"hash\":\"f6078db598815fd90064a20cd3f8bd5c1ac38f85\", \"best_bid\":\"0.54\", \"best_ask\":\"0.55\"}], \"timestamp\":\"1785122203149\", \"event_type\":\"price_change\"}","received_at":"2026-07-27T03:16:43.057252Z","schema_version":"clob-market-ws.price_change.v1","sequence":null,"server_hash":null,"server_timestamp":"1785122203149","session_id":"dd162b8dca5f43ff811d304e69a06123","source":"clob_market_ws"},"received_at":"2026-07-27T03:16:43.057252Z","record_id":"488eb954be8c20be529d8c85d4a586915c80391c1952676429a0073ea8135751","schema_fingerprint":"4aa3821a28b0b7c2400bc59aba4bcc0a76e971dadd19610d3ad38c768e124dc7","schema_version":"edge-lab-recorder.raw.v1","sequence":null,"source":"clob_market_ws"}
{"event_at":"2026-07-27T03:16:43.150000Z","event_fingerprint":"ec3992329708fb67968e33e3b51b47b0560c884e8deb3d1689d302e08fb3b966","payload":{"connection_id":"c7dc2e4762f849c6b6f9306b6518dcab","event_at":"2026-07-27T03:16:43.150000Z","event_type":"price_change","frame_hash":"a8408ffd0f1bf9e8a33f724d2f417fc115a0fb2478084e57fef0be9f1288755d","frame_index":0,"kind":"data","monotonic_ns":224186397592666,"payload":{"event_type":"price_change","market":"0x717c0e8ccd4d5c7040185188fbae28be901ca589a11a94b1b38ca36a79eccfeb","price_changes":[{"asset_id":"24254094493625419915756280046002869097156693848522361803041977572204227262166","best_ask":"0.55","best_bid":"0.54","hash":"5054cebaf6ce7969f36be1a8327e717e44cacfef","price":"0.04","side":"BUY","size":"633.09"},{"asset_id":"41448400836309843603620980831210604935021861034693225347475867885462478926555","best_ask":"0.46","best_bid":"0.45","hash":"adf82be9816eb07220af95ac66e64599264dba81","price":"0.96","side":"SELL","size":"633.09"}],"timestamp":"1785122203150"},"payload_hash":"c86b4ee6083782b95051ae5a9a99c86266114a07591c2dc451fa54407a3ea16a","raw_frame":"{\"market\":\"0x717c0e8ccd4d5c7040185188fbae28be901ca589a11a94b1b38ca36a79eccfeb\", \"price_changes\":[{\"asset_id\":\"24254094493625419915756280046002869097156693848522361803041977572204227262166\", \"price\":\"0.04\", \"size\":\"633.09\", \"side\":\"BUY\", \"hash\":\"5054cebaf6ce7969f36be1a8327e717e44cacfef\", \"best_bid\":\"0.54\", \"best_ask\":\"0.55\"}, {\"asset_id\":\"41448400836309843603620980831210604935021861034693225347475867885462478926555\", \"price\":\"0.96\", \"size\":\"633.09\", \"side\":\"SELL\", \"hash\":\"adf82be9816eb07220af95ac66e64599264dba81\", \"best_bid\":\"0.45\", \"best_ask\":\"0.46\"}], \"timestamp\":\"1785122203150\", \"event_type\":\"price_change\"}","received_at":"2026-07-27T03:16:43.062477Z","schema_version":"clob-market-ws.price_change.v1","sequence":null,"server_hash":null,"server_timestamp":"1785122203150","session_id":"dd162b8dca5f43ff811d304e69a06123","source":"clob_market_ws"},"received_at":"2026-07-27T03:16:43.062477Z","record_id":"8cfb3972b98853fd9e188e23154b9539a819529271ef590c2af8253327342744","schema_fingerprint":"4aa3821a28b0b7c2400bc59aba4bcc0a76e971dadd19610d3ad38c768e124dc7","schema_version":"edge-lab-recorder.raw.v1","sequence":null,"source":"clob_market_ws"}
{"event_at":"2026-07-27T03:16:43.214000Z","event_fingerprint":"63eb366808c86450c59cafea696370e122a8637b2bb3be67ddbf95a492acf9db","payload":{"connection_id":"c7dc2e4762f849c6b6f9306b6518dcab","event_at":"2026-07-27T03:16:43.214000Z","event_type":"price_change","frame_hash":"6ecb378d34d6c4a0a87e7175c050f2b2681298d09dcb409b7a2b808f01ae2a29","frame_index":0,"kind":"data","monotonic_ns":224186449396291,"payload":{"event_type":"price_change","market":"0x717c0e8ccd4d5c7040185188fbae28be901ca589a11a94b1b38ca36a79eccfeb","price_changes":[{"asset_id":"24254094493625419915756280046002869097156693848522361803041977572204227262166","best_ask":"0.55","best_bid":"0.54","hash":"af8e296384d39758bdf3f63eb43575153a012276","price":"0.04","side":"BUY","size":"628.09"},{"asset_id":"41448400836309843603620980831210604935021861034693225347475867885462478926555","best_ask":"0.46","best_bid":"0.45","hash":"92b37c4ae05e499c9cb562db2935eccbb5452a32","price":"0.96","side":"SELL","size":"628.09"}],"timestamp":"1785122203214"},"payload_hash":"6b7b12ef2a4d8ebdbb97eea7fda555bd5a0a7c66209a068f4539fef7553ebcc5","raw_frame":"{\"market\":\"0x717c0e8ccd4d5c7040185188fbae28be901ca589a11a94b1b38ca36a79eccfeb\", \"price_changes\":[{\"asset_id\":\"24254094493625419915756280046002869097156693848522361803041977572204227262166\", \"price\":\"0.04\", \"size\":\"628.09\", \"side\":\"BUY\", \"hash\":\"af8e296384d39758bdf3f63eb43575153a012276\", \"best_bid\":\"0.54\", \"best_ask\":\"0.55\"}, {\"asset_id\":\"41448400836309843603620980831210604935021861034693225347475867885462478926555\", \"price\":\"0.96\", \"size\":\"628.09\", \"side\":\"SELL\", \"hash\":\"92b37c4ae05e499c9cb562db2935eccbb5452a32\", \"best_bid\":\"0.45\", \"best_ask\":\"0.46\"}], \"timestamp\":\"1785122203214\", \"event_type\":\"price_change\"}","received_at":"2026-07-27T03:16:43.114281Z","schema_version":"clob-market-ws.price_change.v1","sequence":null,"server_hash":null,"server_timestamp":"1785122203214","session_id":"dd162b8dca5f43ff811d304e69a06123","source":"clob_market_ws"},"received_at":"2026-07-27T03:16:43.114281Z","record_id":"bceb79e00b179dbe7222776c963e2d55cf800bb4761f24bad25950676d1e0b8f","schema_fingerprint":"4aa3821a28b0b7c2400bc59aba4bcc0a76e971dadd19610d3ad38c768e124dc7","schema_version":"edge-lab-recorder.raw.v1","sequence":null,"source":"clob_market_ws"}
{"event_at":"2026-07-27T03:16:43.250000Z","event_fingerprint":"537ae7ba49b9b6f606a4c483cde321ef0e2115e7fada1ef91a769f574d2b8a33","payload":{"connection_id":"c7dc2e4762f849c6b6f9306b6518dcab","event_at":"2026-07-27T03:16:43.250000Z","event_type":"price_change","frame_hash":"ba599303a159601446567c36ef8a0b3dc0232a68141bec322bf6a12ab5a1465e","frame_index":0,"kind":"data","monotonic_ns":224186485398833,"payload":{"event_type":"price_change","market":"0x717c0e8ccd4d5c7040185188fbae28be901ca589a11a94b1b38ca36a79eccfeb","price_changes":[{"asset_id":"24254094493625419915756280046002869097156693848522361803041977572204227262166","best_ask":"0.55","best_bid":"0.54","hash":"2196fe864be5fa8bf8dbd9fb229e12fc35166427","price":"0.01","side":"BUY","size":"7713.02"},{"asset_id":"41448400836309843603620980831210604935021861034693225347475867885462478926555","best_ask":"0.46","best_bid":"0.45","hash":"d4d75d1814f482d5f85a3b9a53055023544b8a4c","price":"0.99","side":"SELL","size":"7713.02"}],"timestamp":"1785122203250"},"payload_hash":"c5d84ee1816f5e698f7d119722acc3564ea4c2a8f28a0aeedc1c8d3b22c1fbd9","raw_frame":"{\"market\":\"0x717c0e8ccd4d5c7040185188fbae28be901ca589a11a94b1b38ca36a79eccfeb\", \"price_changes\":[{\"asset_id\":\"24254094493625419915756280046002869097156693848522361803041977572204227262166\", \"price\":\"0.01\", \"size\":\"7713.02\", \"side\":\"BUY\", \"hash\":\"2196fe864be5fa8bf8dbd9fb229e12fc35166427\", \"best_bid\":\"0.54\", \"best_ask\":\"0.55\"}, {\"asset_id\":\"41448400836309843603620980831210604935021861034693225347475867885462478926555\", \"price\":\"0.99\", \"size\":\"7713.02\", \"side\":\"SELL\", \"hash\":\"d4d75d1814f482d5f85a3b9a53055023544b8a4c\", \"best_bid\":\"0.45\", \"best_ask\":\"0.46\"}], \"timestamp\":\"1785122203250\", \"event_type\":\"price_change\"}","received_at":"2026-07-27T03:16:43.150282Z","schema_version":"clob-market-ws.price_change.v1","sequence":null,"server_hash":null,"server_timestamp":"1785122203250","session_id":"dd162b8dca5f43ff811d304e69a06123","source":"clob_market_ws"},"received_at":"2026-07-27T03:16:43.150282Z","record_id":"83151646d1a9d81c1f9f37da1168fe4bb8f39f567421032625295da49a735b83","schema_fingerprint":"4aa3821a28b0b7c2400bc59aba4bcc0a76e971dadd19610d3ad38c768e124dc7","schema_version":"edge-lab-recorder.raw.v1","sequence":null,"source":"clob_market_ws"}
{"event_at":"2026-07-27T03:16:43.270000Z","event_fingerprint":"d99b9c2546d9698f2a7519fc51d948ec13aa15ccff7faddf53298e80d7d5105b","payload":{"connection_id":"c7dc2e4762f849c6b6f9306b6518dcab","event_at":"2026-07-27T03:16:43.270000Z","event_type":"price_change","frame_hash":"fa7c36605696e6fc9792989c645490b9ba4a0e10c2a0d6bac088ded1ba1bacc3","frame_index":0,"kind":"data","monotonic_ns":224186507796416,"payload":{"event_type":"price_change","market":"0x717c0e8ccd4d5c7040185188fbae28be901ca589a11a94b1b38ca36a79eccfeb","price_changes":[{"asset_id":"24254094493625419915756280046002869097156693848522361803041977572204227262166","best_ask":"0.55","best_bid":"0.54","hash":"d49430aaea43ae02c219e2d76bfc0ee66519b3b2","price":"0.01","side":"BUY","size":"7708.02"},{"asset_id":"41448400836309843603620980831210604935021861034693225347475867885462478926555","best_ask":"0.46","best_bid":"0.45","hash":"bae838b7603b7263c0e0c46429e6b94ba243c997","price":"0.99","side":"SELL","size":"7708.02"}],"timestamp":"1785122203270"},"payload_hash":"4cd301bf65b52e4fe5cc9ab8234c1e2cde1e7e7a11b0c65b097056b429ea91a8","raw_frame":"{\"market\":\"0x717c0e8ccd4d5c7040185188fbae28be901ca589a11a94b1b38ca36a79eccfeb\", \"price_changes\":[{\"asset_id\":\"24254094493625419915756280046002869097156693848522361803041977572204227262166\", \"price\":\"0.01\", \"size\":\"7708.02\", \"side\":\"BUY\", \"hash\":\"d49430aaea43ae02c219e2d76bfc0ee66519b3b2\", \"best_bid\":\"0.54\", \"best_ask\":\"0.55\"}, {\"asset_id\":\"41448400836309843603620980831210604935021861034693225347475867885462478926555\", \"price\":\"0.99\", \"size\":\"7708.02\", \"side\":\"SELL\", \"hash\":\"bae838b7603b7263c0e0c46429e6b94ba243c997\", \"best_bid\":\"0.45\", \"best_ask\":\"0.46\"}], \"timestamp\":\"1785122203270\", \"event_type\":\"price_change\"}","received_at":"2026-07-27T03:16:43.172679Z","schema_version":"clob-market-ws.price_change.v1","sequence":null,"server_hash":null,"server_timestamp":"1785122203270","session_id":"dd162b8dca5f43ff811d304e69a06123","source":"clob_market_ws"},"received_at":"2026-07-27T03:16:43.172679Z","record_id":"c7914ab11989861e013c708a002b916e26cf2e85dcad548b511ec5c80a3ef680","schema_fingerprint":"4aa3821a28b0b7c2400bc59aba4bcc0a76e971dadd19610d3ad38c768e124dc7","schema_version":"edge-lab-recorder.raw.v1","sequence":null,"source":"clob_market_ws"}
{"event_at":"2026-07-27T03:16:43.296000Z","event_fingerprint":"c0cc6fb617415591bc169f6eb388253a0ec1e1c7f9f4d76b029e589e49f843ae","payload":{"connection_id":"c7dc2e4762f849c6b6f9306b6518dcab","event_at":"2026-07-27T03:16:43.296000Z","event_type":"price_change","frame_hash":"50ff7fba0f07cc52118af44d1c60f6b39a8ec2d6fd633594aa94913f993f50e0","frame_index":0,"kind":"data","monotonic_ns":224186531686708,"payload":{"event_type":"price_change","market":"0x717c0e8ccd4d5c7040185188fbae28be901ca589a11a94b1b38ca36a79eccfeb","price_changes":[{"asset_id":"24254094493625419915756280046002869097156693848522361803041977572204227262166","best_ask":"0.55","best_bid":"0.54","hash":"c3960cba32790f3b01bddea580db7308bbf10336","price":"0.01","side":"BUY","size":"7713.02"},{"asset_id":"41448400836309843603620980831210604935021861034693225347475867885462478926555","best_ask":"0.46","best_bid":"0.45","hash":"b11b2fbd45c15f07236d05db34b863ed887ac553","price":"0.99","side":"SELL","size":"7713.02"}],"timestamp":"1785122203296"},"payload_hash":"1bacd9d56c3a4cab13748b65478ad52346b294e3c4788e478061cb6e7ff329e0","raw_frame":"{\"market\":\"0x717c0e8ccd4d5c7040185188fbae28be901ca589a11a94b1b38ca36a79eccfeb\", \"price_changes\":[{\"asset_id\":\"24254094493625419915756280046002869097156693848522361803041977572204227262166\", \"price\":\"0.01\", \"size\":\"7713.02\", \"side\":\"BUY\", \"hash\":\"c3960cba32790f3b01bddea580db7308bbf10336\", \"best_bid\":\"0.54\", \"best_ask\":\"0.55\"}, {\"asset_id\":\"41448400836309843603620980831210604935021861034693225347475867885462478926555\", \"price\":\"0.99\", \"size\":\"7713.02\", \"side\":\"SELL\", \"hash\":\"b11b2fbd45c15f07236d05db34b863ed887ac553\", \"best_bid\":\"0.45\", \"best_ask\":\"0.46\"}], \"timestamp\":\"1785122203296\", \"event_type\":\"price_change\"}","received_at":"2026-07-27T03:16:43.196573Z","schema_version":"clob-market-ws.price_change.v1","sequence":null,"server_hash":null,"server_timestamp":"1785122203296","session_id":"dd162b8dca5f43ff811d304e69a06123","source":"clob_market_ws"},"received_at":"2026-07-27T03:16:43.196573Z","record_id":"29226e27e306ad3647d093272d174678684fc7fdda27bd1c27cf60436bb996e8","schema_fingerprint":"4aa3821a28b0b7c2400bc59aba4bcc0a76e971dadd19610d3ad38c768e124dc7","schema_version":"edge-lab-recorder.raw.v1","sequence":null,"source":"clob_market_ws"}
{"event_at":"2026-07-27T03:16:43.299000Z","event_fingerprint":"35b76cb7c516e4995f25fb4e5f878b5398ea0c55e9ac64b859f08da6b83660f5","payload":{"connection_id":"c7dc2e4762f849c6b6f9306b6518dcab","event_at":"2026-07-27T03:16:43.299000Z","event_type":"price_change","frame_hash":"d52ddeda5f0f86f58ed5ced848b9ac7dfef5b47647442a25d9cfd3eef0489bf1","frame_index":0,"kind":"data","monotonic_ns":224186534419833,"payload":{"event_type":"price_change","market":"0x717c0e8ccd4d5c7040185188fbae28be901ca589a11a94b1b38ca36a79eccfeb","price_changes":[{"asset_id":"24254094493625419915756280046002869097156693848522361803041977572204227262166","best_ask":"0.55","best_bid":"0.54","hash":"3ed945180cfdace2bc38248ab560a6a4916caa6b","price":"0.04","side":"BUY","size":"633.09"},{"asset_id":"41448400836309843603620980831210604935021861034693225347475867885462478926555","best_ask":"0.46","best_bid":"0.45","hash":"55e3dcbaaecb57e222a687d36305a3e990b77287","price":"0.96","side":"SELL","size":"633.09"}],"timestamp":"1785122203299"},"payload_hash":"a5f4fc8ee2d8235ad67de774d99042ce9cfbfd76c629dfddfc26a32c5e8a32d3","raw_frame":"{\"market\":\"0x717c0e8ccd4d5c7040185188fbae28be901ca589a11a94b1b38ca36a79eccfeb\", \"price_changes\":[{\"asset_id\":\"24254094493625419915756280046002869097156693848522361803041977572204227262166\", \"price\":\"0.04\", \"size\":\"633.09\", \"side\":\"BUY\", \"hash\":\"3ed945180cfdace2bc38248ab560a6a4916caa6b\", \"best_bid\":\"0.54\", \"best_ask\":\"0.55\"}, {\"asset_id\":\"41448400836309843603620980831210604935021861034693225347475867885462478926555\", \"price\":\"0.96\", \"size\":\"633.09\", \"side\":\"SELL\", \"hash\":\"55e3dcbaaecb57e222a687d36305a3e990b77287\", \"best_bid\":\"0.45\", \"best_ask\":\"0.46\"}], \"timestamp\":\"1785122203299\", \"event_type\":\"price_change\"}","received_at":"2026-07-27T03:16:43.199307Z","schema_version":"clob-market-ws.price_change.v1","sequence":null,"server_hash":null,"server_timestamp":"1785122203299","session_id":"dd162b8dca5f43ff811d304e69a06123","source":"clob_market_ws"},"received_at":"2026-07-27T03:16:43.199307Z","record_id":"9f2ec6404c155f861a5a08da7818c8c755a5f876a671bd35be0cf40ac1cea9e5","schema_fingerprint":"4aa3821a28b0b7c2400bc59aba4bcc0a76e971dadd19610d3ad38c768e124dc7","schema_version":"edge-lab-recorder.raw.v1","sequence":null,"source":"clob_market_ws"}
{"event_at":"2026-07-27T03:16:43.319000Z","event_fingerprint":"92648bd90dc5b70162e6d488e574bff1358edffbf0b9a28dba8098cbd0030155","payload":{"connection_id":"c7dc2e4762f849c6b6f9306b6518dcab","event_at":"2026-07-27T03:16:43.319000Z","event_type":"price_change","frame_hash":"81f244ae600c93ae59dd829d428ddbae32587d379d02baa0641b96a509305241","frame_index":0,"kind":"data","monotonic_ns":224186555983250,"payload":{"event_type":"price_change","market":"0x717c0e8ccd4d5c7040185188fbae28be901ca589a11a94b1b38ca36a79eccfeb","price_changes":[{"asset_id":"24254094493625419915756280046002869097156693848522361803041977572204227262166","best_ask":"0.55","best_bid":"0.54","hash":"5cb7f4c69def21fead6dfcbb964291dc17043aaa","price":"0.01","side":"BUY","size":"7708.02"},{"asset_id":"41448400836309843603620980831210604935021861034693225347475867885462478926555","best_ask":"0.46","best_bid":"0.45","hash":"1134a961d8dcf607a8854fdb83aed34dd85bd2ff","price":"0.99","side":"SELL","size":"7708.02"}],"timestamp":"1785122203319"},"payload_hash":"baa38a6dd20ac4eff9aecbe51b129bd2ec6148ed11eff9b9b4834b3782588e26","raw_frame":"{\"market\":\"0x717c0e8ccd4d5c7040185188fbae28be901ca589a11a94b1b38ca36a79eccfeb\", \"price_changes\":[{\"asset_id\":\"24254094493625419915756280046002869097156693848522361803041977572204227262166\", \"price\":\"0.01\", \"size\":\"7708.02\", \"side\":\"BUY\", \"hash\":\"5cb7f4c69def21fead6dfcbb964291dc17043aaa\", \"best_bid\":\"0.54\", \"best_ask\":\"0.55\"}, {\"asset_id\":\"41448400836309843603620980831210604935021861034693225347475867885462478926555\", \"price\":\"0.99\", \"size\":\"7708.02\", \"side\":\"SELL\", \"hash\":\"1134a961d8dcf607a8854fdb83aed34dd85bd2ff\", \"best_bid\":\"0.45\", \"best_ask\":\"0.46\"}], \"timestamp\":\"1785122203319\", \"event_type\":\"price_change\"}","received_at":"2026-07-27T03:16:43.220872Z","schema_version":"clob-market-ws.price_change.v1","sequence":null,"server_hash":null,"server_timestamp":"1785122203319","session_id":"dd162b8dca5f43ff811d304e69a06123","source":"clob_market_ws"},"received_at":"2026-07-27T03:16:43.220872Z","record_id":"5c24d696d4072e27d9a1d952463193d09af9568a5db2d90ab252e031431c097d","schema_fingerprint":"4aa3821a28b0b7c2400bc59aba4bcc0a76e971dadd19610d3ad38c768e124dc7","schema_version":"edge-lab-recorder.raw.v1","sequence":null,"source":"clob_market_ws"}
{"event_at":"2026-07-27T03:16:43.349000Z","event_fingerprint":"b517709c42227d940ec75562b5b3b090ff3c00bbbc597dd4babead245cddc4ff","payload":{"connection_id":"c7dc2e4762f849c6b6f9306b6518dcab","event_at":"2026-07-27T03:16:43.349000Z","event_type":"price_change","frame_hash":"377483cbcdbf887c4e4826e7f0d9910cb444bfd601d0eedcfdefdf075f6edaad","frame_index":0,"kind":"data","monotonic_ns":224186583343625,"payload":{"event_type":"price_change","market":"0x717c0e8ccd4d5c7040185188fbae28be901ca589a11a94b1b38ca36a79eccfeb","price_changes":[{"asset_id":"24254094493625419915756280046002869097156693848522361803041977572204227262166","best_ask":"0.55","best_bid":"0.54","hash":"a09bfb8b81a8acf511c9c78273ba5f895ff42953","price":"0.04","side":"BUY","size":"628.09"},{"asset_id":"41448400836309843603620980831210604935021861034693225347475867885462478926555","best_ask":"0.46","best_bid":"0.45","hash":"1a9253549be119c1f52cf21a7e7c1a025ec5f110","price":"0.96","side":"SELL","size":"628.09"}],"timestamp":"1785122203349"},"payload_hash":"99790a96114476aa52f2536274e700bf209e0195e29d436a8ddd55da54822e52","raw_frame":"{\"market\":\"0x717c0e8ccd4d5c7040185188fbae28be901ca589a11a94b1b38ca36a79eccfeb\", \"price_changes\":[{\"asset_id\":\"24254094493625419915756280046002869097156693848522361803041977572204227262166\", \"price\":\"0.04\", \"size\":\"628.09\", \"side\":\"BUY\", \"hash\":\"a09bfb8b81a8acf511c9c78273ba5f895ff42953\", \"best_bid\":\"0.54\", \"best_ask\":\"0.55\"}, {\"asset_id\":\"41448400836309843603620980831210604935021861034693225347475867885462478926555\", \"price\":\"0.96\", \"size\":\"628.09\", \"side\":\"SELL\", \"hash\":\"1a9253549be119c1f52cf21a7e7c1a025ec5f110\", \"best_bid\":\"0.45\", \"best_ask\":\"0.46\"}], \"timestamp\":\"1785122203349\", \"event_type\":\"price_change\"}","received_at":"2026-07-27T03:16:43.248230Z","schema_version":"clob-market-ws.price_change.v1","sequence":null,"server_hash":null,"server_timestamp":"1785122203349","session_id":"dd162b8dca5f43ff811d304e69a06123","source":"clob_market_ws"},"received_at":"2026-07-27T03:16:43.248230Z","record_id":"51800b739caec8be08cf26707473898905407cf9eea12f210a5f31de4db28f89","schema_fingerprint":"4aa3821a28b0b7c2400bc59aba4bcc0a76e971dadd19610d3ad38c768e124dc7","schema_version":"edge-lab-recorder.raw.v1","sequence":null,"source":"clob_market_ws"}
{"event_at":"2026-07-27T03:16:43.401000Z","event_fingerprint":"fda315e1538f76831cb627bf0d3d10975ec4218599ef8de868cae4c7e1d1af45","payload":{"connection_id":"c7dc2e4762f849c6b6f9306b6518dcab","event_at":"2026-07-27T03:16:43.401000Z","event_type":"price_change","frame_hash":"e30d495bfb5f12fb1acccbfd7b3f603386c9d6b4bb603b3e1d8b4044dc0d42e0","frame_index":0,"kind":"data","monotonic_ns":224186636669333,"payload":{"event_type":"price_change","market":"0x717c0e8ccd4d5c7040185188fbae28be901ca589a11a94b1b38ca36a79eccfeb","price_changes":[{"asset_id":"24254094493625419915756280046002869097156693848522361803041977572204227262166","best_ask":"0.55","best_bid":"0.54","hash":"6ea3e49c1f6036616d46e9ea08a77c5d70e3e011","price":"0.44","side":"BUY","size":"116"},{"asset_id":"41448400836309843603620980831210604935021861034693225347475867885462478926555","best_ask":"0.46","best_bid":"0.45","hash":"1ae97aff46de753e617b973d2f7c1187d6dc15a4","price":"0.56","side":"SELL","size":"116"}],"timestamp":"1785122203401"},"payload_hash":"41046d651d09c12735e236fd8b02a9e82102dd25079247f9d85bbc1559e3a9a5","raw_frame":"{\"market\":\"0x717c0e8ccd4d5c7040185188fbae28be901ca589a11a94b1b38ca36a79eccfeb\", \"price_changes\":[{\"asset_id\":\"24254094493625419915756280046002869097156693848522361803041977572204227262166\", \"price\":\"0.44\", \"size\":\"116\", \"side\":\"BUY\", \"hash\":\"6ea3e49c1f6036616d46e9ea08a77c5d70e3e011\", \"best_bid\":\"0.54\", \"best_ask\":\"0.55\"}, {\"asset_id\":\"41448400836309843603620980831210604935021861034693225347475867885462478926555\", \"price\":\"0.56\", \"size\":\"116\", \"side\":\"SELL\", \"hash\":\"1ae97aff46de753e617b973d2f7c1187d6dc15a4\", \"best_bid\":\"0.45\", \"best_ask\":\"0.46\"}], \"timestamp\":\"1785122203401\", \"event_type\":\"price_change\"}","received_at":"2026-07-27T03:16:43.301550Z","schema_version":"clob-market-ws.price_change.v1","sequence":null,"server_hash":null,"server_timestamp":"1785122203401","session_id":"dd162b8dca5f43ff811d304e69a06123","source":"clob_market_ws"},"received_at":"2026-07-27T03:16:43.301550Z","record_id":"e235107f69fee298f366b4ee4c9d7fcc7e1f12d5b324940063637d8a961905e9","schema_fingerprint":"4aa3821a28b0b7c2400bc59aba4bcc0a76e971dadd19610d3ad38c768e124dc7","schema_version":"edge-lab-recorder.raw.v1","sequence":null,"source":"clob_market_ws"}
{"event_at":"2026-07-27T03:16:43.406000Z","event_fingerprint":"97b84abdeb93233ee1b9cc1e0efe8456bf6d71e401f22b1a9b515a32c65a799d","payload":{"connection_id":"c7dc2e4762f849c6b6f9306b6518dcab","event_at":"2026-07-27T03:16:43.406000Z","event_type":"price_change","frame_hash":"1130191a1cd2ba1b70a502fff7c2250153e65b1e72cd1003a55d1aca906dfa4d","frame_index":0,"kind":"data","monotonic_ns":224186640918708,"payload":{"event_type":"price_change","market":"0x717c0e8ccd4d5c7040185188fbae28be901ca589a11a94b1b38ca36a79eccfeb","price_changes":[{"asset_id":"24254094493625419915756280046002869097156693848522361803041977572204227262166","best_ask":"0.55","best_bid":"0.54","hash":"dc7f8ca44e03f6393ade1b1c91ea537a6563486a","price":"0.47","side":"BUY","size":"132"},{"asset_id":"41448400836309843603620980831210604935021861034693225347475867885462478926555","best_ask":"0.46","best_bid":"0.45","hash":"ec1f3b3e3d9d0c96ad50cee37e855d297877fc62","price":"0.53","side":"SELL","size":"132"}],"timestamp":"1785122203406"},"payload_hash":"37ecf4fe51417d14aef4e88be898735d82fe576bf46ddbaf7d88c19defab4880","raw_frame":"{\"market\":\"0x717c0e8ccd4d5c7040185188fbae28be901ca589a11a94b1b38ca36a79eccfeb\", \"price_changes\":[{\"asset_id\":\"24254094493625419915756280046002869097156693848522361803041977572204227262166\", \"price\":\"0.47\", \"size\":\"132\", \"side\":\"BUY\", \"hash\":\"dc7f8ca44e03f6393ade1b1c91ea537a6563486a\", \"best_bid\":\"0.54\", \"best_ask\":\"0.55\"}, {\"asset_id\":\"41448400836309843603620980831210604935021861034693225347475867885462478926555\", \"price\":\"0.53\", \"size\":\"132\", \"side\":\"SELL\", \"hash\":\"ec1f3b3e3d9d0c96ad50cee37e855d297877fc62\", \"best_bid\":\"0.45\", \"best_ask\":\"0.46\"}], \"timestamp\":\"1785122203406\", \"event_type\":\"price_change\"}","received_at":"2026-07-27T03:16:43.305803Z","schema_version":"clob-market-ws.price_change.v1","sequence":null,"server_hash":null,"server_timestamp":"1785122203406","session_id":"dd162b8dca5f43ff811d304e69a06123","source":"clob_market_ws"},"received_at":"2026-07-27T03:16:43.305803Z","record_id":"61dcf54a70b1e7efa44ba00309f0a5125fed5507b70dbbb3db905bcc86964cd5","schema_fingerprint":"4aa3821a28b0b7c2400bc59aba4bcc0a76e971dadd19610d3ad38c768e124dc7","schema_version":"edge-lab-recorder.raw.v1","sequence":null,"source":"clob_market_ws"}
{"event_at":"2026-07-27T03:16:43.411000Z","event_fingerprint":"89a8d4800344314126e837ff9bf68e3c882ddd02de3b84517788e17a8a6c745b","payload":{"connection_id":"c7dc2e4762f849c6b6f9306b6518dcab","event_at":"2026-07-27T03:16:43.411000Z","event_type":"price_change","frame_hash":"1cd5ac508b5b1205ae7fe0c5a3f4597c18b57e52de7480b7f38058820b154750","frame_index":0,"kind":"data","monotonic_ns":224186647724666,"payload":{"event_type":"price_change","market":"0x717c0e8ccd4d5c7040185188fbae28be901ca589a11a94b1b38ca36a79eccfeb","price_changes":[{"asset_id":"41448400836309843603620980831210604935021861034693225347475867885462478926555","best_ask":"0.46","best_bid":"0.45","hash":"ea968411dc92588206bbf013bd51d5b9020cde3e","price":"0.24","side":"BUY","size":"23.39"},{"asset_id":"24254094493625419915756280046002869097156693848522361803041977572204227262166","best_ask":"0.55","best_bid":"0.54","hash":"1324d7654d1fdb0e972c7344b6be5083081bb5de","price":"0.76","side":"SELL","size":"23.39"}],"timestamp":"1785122203411"},"payload_hash":"ac4c9201445e04d2ca07f6598832c716584fed28bf36633984e8599b4eb79f9e","raw_frame":"{\"market\":\"0x717c0e8ccd4d5c7040185188fbae28be901ca589a11a94b1b38ca36a79eccfeb\", \"price_changes\":[{\"asset_id\":\"41448400836309843603620980831210604935021861034693225347475867885462478926555\", \"price\":\"0.24\", \"size\":\"23.39\", \"side\":\"BUY\", \"hash\":\"ea968411dc92588206bbf013bd51d5b9020cde3e\", \"best_bid\":\"0.45\", \"best_ask\":\"0.46\"}, {\"asset_id\":\"24254094493625419915756280046002869097156693848522361803041977572204227262166\", \"price\":\"0.76\", \"size\":\"23.39\", \"side\":\"SELL\", \"hash\":\"1324d7654d1fdb0e972c7344b6be5083081bb5de\", \"best_bid\":\"0.54\", \"best_ask\":\"0.55\"}], \"timestamp\":\"1785122203411\", \"event_type\":\"price_change\"}","received_at":"2026-07-27T03:16:43.312612Z","schema_version":"clob-market-ws.price_change.v1","sequence":null,"server_hash":null,"server_timestamp":"1785122203411","session_id":"dd162b8dca5f43ff811d304e69a06123","source":"clob_market_ws"},"received_at":"2026-07-27T03:16:43.312612Z","record_id":"0fa9a5777e2822cd600924b748d10a21001023d5b42a6e1eb532efedf09688f5","schema_fingerprint":"4aa3821a28b0b7c2400bc59aba4bcc0a76e971dadd19610d3ad38c768e124dc7","schema_version":"edge-lab-recorder.raw.v1","sequence":null,"source":"clob_market_ws"}
{"event_at":"2026-07-27T03:16:43.412000Z","event_fingerprint":"de945b883f444c10f8ed13da633a812b06674f7e8eb0f52c82db8eefddca970b","payload":{"connection_id":"c7dc2e4762f849c6b6f9306b6518dcab","event_at":"2026-07-27T03:16:43.412000Z","event_type":"price_change","frame_hash":"8ab293964b130eee2dc871038b786cff1425776cdaf74389de9a63a2a295f996","frame_index":0,"kind":"data","monotonic_ns":224186650282041,"payload":{"event_type":"price_change","market":"0x717c0e8ccd4d5c7040185188fbae28be901ca589a11a94b1b38ca36a79eccfeb","price_changes":[{"asset_id":"24254094493625419915756280046002869097156693848522361803041977572204227262166","best_ask":"0.55","best_bid":"0.54","hash":"9458246f8b774a937b764f31fce8728bc3201c4d","price":"0.29","side":"BUY","size":"20.6"},{"asset_id":"41448400836309843603620980831210604935021861034693225347475867885462478926555","best_ask":"0.46","best_bid":"0.45","hash":"c426e071c981707dc86f552f84a9bd03cebb6d32","price":"0.71","side":"SELL","size":"20.6"}],"timestamp":"1785122203412"},"payload_hash":"687d69f193c28d7957aad0afe27f5d4bfb241a938e488c0b6372de0b03f74a75","raw_frame":"{\"market\":\"0x717c0e8ccd4d5c7040185188fbae28be901ca589a11a94b1b38ca36a79eccfeb\", \"price_changes\":[{\"asset_id\":\"24254094493625419915756280046002869097156693848522361803041977572204227262166\", \"price\":\"0.29\", \"size\":\"20.6\", \"side\":\"BUY\", \"hash\":\"9458246f8b774a937b764f31fce8728bc3201c4d\", \"best_bid\":\"0.54\", \"best_ask\":\"0.55\"}, {\"asset_id\":\"41448400836309843603620980831210604935021861034693225347475867885462478926555\", \"price\":\"0.71\", \"size\":\"20.6\", \"side\":\"SELL\", \"hash\":\"c426e071c981707dc86f552f84a9bd03cebb6d32\", \"best_bid\":\"0.45\", \"best_ask\":\"0.46\"}], \"timestamp\":\"1785122203412\", \"event_type\":\"price_change\"}","received_at":"2026-07-27T03:16:43.315168Z","schema_version":"clob-market-ws.price_change.v1","sequence":null,"server_hash":null,"server_timestamp":"1785122203412","session_id":"dd162b8dca5f43ff811d304e69a06123","source":"clob_market_ws"},"received_at":"2026-07-27T03:16:43.315168Z","record_id":"79a88a74ab2df0f0d931cbdc96f612dd5f9fe8f6d1da98a5d04891ce0b291cf2","schema_fingerprint":"4aa3821a28b0b7c2400bc59aba4bcc0a76e971dadd19610d3ad38c768e124dc7","schema_version":"edge-lab-recorder.raw.v1","sequence":null,"source":"clob_market_ws"}
{"event_at":"2026-07-27T03:16:43.429000Z","event_fingerprint":"c406be80e2e6e55dadd2e0e6aec30e71997122a402b4a58a89a9bec4edb04b96","payload":{"connection_id":"c7dc2e4762f849c6b6f9306b6518dcab","event_at":"2026-07-27T03:16:43.429000Z","event_type":"price_change","frame_hash":"11902dc855d088953f7849a659d214b052b3d15941a9157df5addbcbaa972744","frame_index":0,"kind":"data","monotonic_ns":224186663675958,"payload":{"event_type":"price_change","market":"0x717c0e8ccd4d5c7040185188fbae28be901ca589a11a94b1b38ca36a79eccfeb","price_changes":[{"asset_id":"24254094493625419915756280046002869097156693848522361803041977572204227262166","best_ask":"0.55","best_bid":"0.54","hash":"cc9e5492a9ba5e606f84db3dce6aec5deae7aace","price":"0.04","side":"BUY","size":"633.09"},{"asset_id":"41448400836309843603620980831210604935021861034693225347475867885462478926555","best_ask":"0.46","best_bid":"0.45","hash":"af5879f03c4ce130f1cf12ab34e4fe8d11b89f74","price":"0.96","side":"SELL","size":"633.09"}],"timestamp":"1785122203429"},"payload_hash":"884ee40459b06263363c9581c42379c9f51996c090c82421d7082b57864605c6","raw_frame":"{\"market\":\"0x717c0e8ccd4d5c7040185188fbae28be901ca589a11a94b1b38ca36a79eccfeb\", \"price_changes\":[{\"asset_id\":\"24254094493625419915756280046002869097156693848522361803041977572204227262166\", \"price\":\"0.04\", \"size\":\"633.09\", \"side\":\"BUY\", \"hash\":\"cc9e5492a9ba5e606f84db3dce6aec5deae7aace\", \"best_bid\":\"0.54\", \"best_ask\":\"0.55\"}, {\"asset_id\":\"41448400836309843603620980831210604935021861034693225347475867885462478926555\", \"price\":\"0.96\", \"size\":\"633.09\", \"side\":\"SELL\", \"hash\":\"af5879f03c4ce130f1cf12ab34e4fe8d11b89f74\", \"best_bid\":\"0.45\", \"best_ask\":\"0.46\"}], \"timestamp\":\"1785122203429\", \"event_type\":\"price_change\"}","received_at":"2026-07-27T03:16:43.328560Z","schema_version":"clob-market-ws.price_change.v1","sequence":null,"server_hash":null,"server_timestamp":"1785122203429","session_id":"dd162b8dca5f43ff811d304e69a06123","source":"clob_market_ws"},"received_at":"2026-07-27T03:16:43.328560Z","record_id":"69c1835aabc53f843f0e81276cdc810df4a4e3dac5bf952edf220a8fffe658d4","schema_fingerprint":"4aa3821a28b0b7c2400bc59aba4bcc0a76e971dadd19610d3ad38c768e124dc7","schema_version":"edge-lab-recorder.raw.v1","sequence":null,"source":"clob_market_ws"}
