{"event_at":"2026-07-27T03:19:18.463000Z","event_fingerprint":"787ea57160c6b048a58330aac2556569c75ce8d90170be7a1f511a93bbc752db","payload":{"connection_id":"c7dc2e4762f849c6b6f9306b6518dcab","event_at":"2026-07-27T03:19:18.463000Z","event_type":"price_change","frame_hash":"65fd8b626bbbdebaf4194e66ab9213888aa2aad807cbe4e76ff03546dad37b03","frame_index":0,"kind":"data","monotonic_ns":224341874452541,"payload":{"event_type":"price_change","market":"0x717c0e8ccd4d5c7040185188fbae28be901ca589a11a94b1b38ca36a79eccfeb","price_changes":[{"asset_id":"24254094493625419915756280046002869097156693848522361803041977572204227262166","best_ask":"0.57","best_bid":"0.56","hash":"56968f71947238949fdca5bc2cd7126a1bc75e65","price":"0.01","side":"BUY","size":"5708.02"},{"asset_id":"41448400836309843603620980831210604935021861034693225347475867885462478926555","best_ask":"0.44","best_bid":"0.43","hash":"8856db86290394277e101a353e4a4f9f5e356f26","price":"0.99","side":"SELL","size":"5708.02"}],"timestamp":"1785122358463"},"payload_hash":"ba648144d5c1ec17856da33d906bce602cf24b2ca7fe42b0dc65e43e70a33f54","raw_frame":"{\"market\":\"0x717c0e8ccd4d5c7040185188fbae28be901ca589a11a94b1b38ca36a79eccfeb\", \"price_changes\":[{\"asset_id\":\"24254094493625419915756280046002869097156693848522361803041977572204227262166\", \"price\":\"0.01\", \"size\":\"5708.02\", \"side\":\"BUY\", \"hash\":\"56968f71947238949fdca5bc2cd7126a1bc75e65\", \"best_bid\":\"0.56\", \"best_ask\":\"0.57\"}, {\"asset_id\":\"41448400836309843603620980831210604935021861034693225347475867885462478926555\", \"price\":\"0.99\", \"size\":\"5708.02\", \"side\":\"SELL\", \"hash\":\"8856db86290394277e101a353e4a4f9f5e356f26\", \"best_bid\":\"0.43\", \"best_ask\":\"0.44\"}], \"timestamp\":\"1785122358463\", \"event_type\":\"price_change\"}","received_at":"2026-07-27T03:19:18.537165Z","schema_version":"clob-market-ws.price_change.v1","sequence":null,"server_hash":null,"server_timestamp":"1785122358463","session_id":"dd162b8dca5f43ff811d304e69a06123","source":"clob_market_ws"},"received_at":"2026-07-27T03:19:18.537165Z","record_id":"674417706a1e20b615c65681cf14ea5b615decf08ca4408fc6c7de690b8d8cb3","schema_fingerprint":"4aa3821a28b0b7c2400bc59aba4bcc0a76e971dadd19610d3ad38c768e124dc7","schema_version":"edge-lab-recorder.raw.v1","sequence":null,"source":"clob_market_ws"}
{"event_at":"2026-07-27T03:19:18.470000Z","event_fingerprint":"efdca973c96ea5c436b1248ebabea26de343622e4d2f33071af1b4463d501926","payload":{"connection_id":"c7dc2e4762f849c6b6f9306b6518dcab","event_at":"2026-07-27T03:19:18.470000Z","event_type":"price_change","frame_hash":"cbbe29ce9a846dd2c64523869fa3e1b5de756bb244de79f1b54e4278c4080604","frame_index":0,"kind":"data","monotonic_ns":224341881589083,"payload":{"event_type":"price_change","market":"0x717c0e8ccd4d5c7040185188fbae28be901ca589a11a94b1b38ca36a79eccfeb","price_changes":[{"asset_id":"41448400836309843603620980831210604935021861034693225347475867885462478926555","best_ask":"0.44","best_bid":"0.43","hash":"b8b863b09b11c561a18d7ce84cca6ad02eeef0e8","price":"0.43","side":"BUY","size":"45.54"},{"asset_id":"24254094493625419915756280046002869097156693848522361803041977572204227262166","best_ask":"0.57","best_bid":"0.56","hash":"ed31073dd56b416d723bfac2a7e99edbbc18a741","price":"0.57","side":"SELL","size":"45.54"}],"timestamp":"1785122358470"},"payload_hash":"7782c23e5b432b25539e27e85ca88f09942ddeeacdd90d14b8fe5ee358ce5f49","raw_frame":"{\"market\":\"0x717c0e8ccd4d5c7040185188fbae28be901ca589a11a94b1b38ca36a79eccfeb\", \"price_changes\":[{\"asset_id\":\"41448400836309843603620980831210604935021861034693225347475867885462478926555\", \"price\":\"0.43\", \"size\":\"45.54\", \"side\":\"BUY\", \"hash\":\"b8b863b09b11c561a18d7ce84cca6ad02eeef0e8\", \"best_bid\":\"0.43\", \"best_ask\":\"0.44\"}, {\"asset_id\":\"24254094493625419915756280046002869097156693848522361803041977572204227262166\", \"price\":\"0.57\", \"size\":\"45.54\", \"side\":\"SELL\", \"hash\":\"ed31073dd56b416d723bfac2a7e99edbbc18a741\", \"best_bid\":\"0.56\", \"best_ask\":\"0.57\"}], \"timestamp\":\"1785122358470\", \"event_type\":\"price_change\"}","received_at":"2026-07-27T03:19:18.544300Z","schema_version":"clob-market-ws.price_change.v1","sequence":null,"server_hash":null,"server_timestamp":"1785122358470","session_id":"dd162b8dca5f43ff811d304e69a06123","source":"clob_market_ws"},"received_at":"2026-07-27T03:19:18.544300Z","record_id":"b69d55da324c0140712720d00915991f9ede56ec7f1ceee537daa8c30d12c8c9","schema_fingerprint":"4aa3821a28b0b7c2400bc59aba4bcc0a76e971dadd19610d3ad38c768e124dc7","schema_version":"edge-lab-recorder.raw.v1","sequence":null,"source":"clob_market_ws"}
{"event_at":"2026-07-27T03:19:18.470000Z","event_fingerprint":"5ff150d86ab8cae8a003daabec964fa5600102d8c5f9500c40bac51a06d084e2","payload":{"connection_id":"c7dc2e4762f849c6b6f9306b6518dcab","event_at":"2026-07-27T03:19:18.470000Z","event_type":"price_change","frame_hash":"1a98c4caf471b6db30742d8ace2b4a411a054cdb5eae428bdaa4ed7a2edcb31e","frame_index":0,"kind":"data","monotonic_ns":224341885277416,"payload":{"event_type":"price_change","market":"0x717c0e8ccd4d5c7040185188fbae28be901ca589a11a94b1b38ca36a79eccfeb","price_changes":[{"asset_id":"24254094493625419915756280046002869097156693848522361803041977572204227262166","best_ask":"0.57","best_bid":"0.56","hash":"e7e26a4954004443f28de3660ef32484749540fa","price":"0.57","side":"SELL","size":"51.54"},{"asset_id":"41448400836309843603620980831210604935021861034693225347475867885462478926555","best_ask":"0.44","best_bid":"0.43","hash":"dca7a8ade2e810132680efc907cce2c9151480d7","price":"0.43","side":"BUY","size":"51.54"}],"timestamp":"1785122358470"},"payload_hash":"ea5eb024553e17b58420b1f5dc009955a8d6b512fac6fcb29f5b40a77e3a2f32","raw_frame":"{\"market\":\"0x717c0e8ccd4d5c7040185188fbae28be901ca589a11a94b1b38ca36a79eccfeb\", \"price_changes\":[{\"asset_id\":\"24254094493625419915756280046002869097156693848522361803041977572204227262166\", \"price\":\"0.57\", \"size\":\"51.54\", \"side\":\"SELL\", \"hash\":\"e7e26a4954004443f28de3660ef32484749540fa\", \"best_bid\":\"0.56\", \"best_ask\":\"0.57\"}, {\"asset_id\":\"41448400836309843603620980831210604935021861034693225347475867885462478926555\", \"price\":\"0.43\", \"size\":\"51.54\", \"side\":\"BUY\", \"hash\":\"dca7a8ade2e810132680efc907cce2c9151480d7\", \"best_bid\":\"0.43\", \"best_ask\":\"0.44\"}], \"timestamp\":\"1785122358470\", \"event_type\":\"price_change\"}","received_at":"2026-07-27T03:19:18.547989Z","schema_version":"clob-market-ws.price_change.v1","sequence":null,"server_hash":null,"server_timestamp":"1785122358470","session_id":"dd162b8dca5f43ff811d304e69a06123","source":"clob_market_ws"},"received_at":"2026-07-27T03:19:18.547989Z","record_id":"9132490625cb495e4736e45026607b18be537a8f8f7292418a464765e99295f9","schema_fingerprint":"4aa3821a28b0b7c2400bc59aba4bcc0a76e971dadd19610d3ad38c768e124dc7","schema_version":"edge-lab-recorder.raw.v1","sequence":null,"source":"clob_market_ws"}
{"event_at":"2026-07-27T03:19:18.471000Z","event_fingerprint":"625316ab0bd290e97b534cb3a8b48a948d426ef7f595f305c8e6048514c7f491","payload":{"connection_id":"c7dc2e4762f849c6b6f9306b6518dcab","event_at":"2026-07-27T03:19:18.471000Z","event_type":"price_change","frame_hash":"51691e5a9664438011720395f5a59d5ff68fcf30c2960c0cff8792361c28388e","frame_index":0,"kind":"data","monotonic_ns":224341888275958,"payload":{"event_type":"price_change","market":"0x717c0e8ccd4d5c7040185188fbae28be901ca589a11a94b1b38ca36a79eccfeb","price_changes":[{"asset_id":"24254094493625419915756280046002869097156693848522361803041977572204227262166","best_ask":"0.57","best_bid":"0.56","hash":"39755819af928e264177789f01c4c49823ec2942","price":"0.57","side":"SELL","size":"56.54"},{"asset_id":"41448400836309843603620980831210604935021861034693225347475867885462478926555","best_ask":"0.44","best_bid":"0.43","hash":"6ad08c21f08edb688abd9672f0cf7949f974e12f","price":"0.43","side":"BUY","size":"56.54"}],"timestamp":"1785122358471"},"payload_hash":"9f31eafe20645c30fdc5f7232b69c10d161b1b0bc733fd572c4c24bd334353c8","raw_frame":"{\"market\":\"0x717c0e8ccd4d5c7040185188fbae28be901ca589a11a94b1b38ca36a79eccfeb\", \"price_changes\":[{\"asset_id\":\"24254094493625419915756280046002869097156693848522361803041977572204227262166\", \"price\":\"0.57\", \"size\":\"56.54\", \"side\":\"SELL\", \"hash\":\"39755819af928e264177789f01c4c49823ec2942\", \"best_bid\":\"0.56\", \"best_ask\":\"0.57\"}, {\"asset_id\":\"41448400836309843603620980831210604935021861034693225347475867885462478926555\", \"price\":\"0.43\", \"size\":\"56.54\", \"side\":\"BUY\", \"hash\":\"6ad08c21f08edb688abd9672f0cf7949f974e12f\", \"best_bid\":\"0.43\", \"best_ask\":\"0.44\"}], \"timestamp\":\"1785122358471\", \"event_type\":\"price_change\"}","received_at":"2026-07-27T03:19:18.550988Z","schema_version":"clob-market-ws.price_change.v1","sequence":null,"server_hash":null,"server_timestamp":"1785122358471","session_id":"dd162b8dca5f43ff811d304e69a06123","source":"clob_market_ws"},"received_at":"2026-07-27T03:19:18.550988Z","record_id":"924abcfd39a7eeb8851e179ec3160d5b714242981e6adf6d0e382307760bd0be","schema_fingerprint":"4aa3821a28b0b7c2400bc59aba4bcc0a76e971dadd19610d3ad38c768e124dc7","schema_version":"edge-lab-recorder.raw.v1","sequence":null,"source":"clob_market_ws"}
{"event_at":"2026-07-27T03:19:18.472000Z","event_fingerprint":"d8fe4519fc03591f478cf39b3e905c11518bd008fd70c151cbea366a770609e4","payload":{"connection_id":"c7dc2e4762f849c6b6f9306b6518dcab","event_at":"2026-07-27T03:19:18.472000Z","event_type":"price_change","frame_hash":"d5f539b7a9c70b82d3368c75de4544f21f0f4b9e67c0d58b90b52004a0a07221","frame_index":0,"kind":"data","monotonic_ns":224341891295000,"payload":{"event_type":"price_change","market":"0x717c0e8ccd4d5c7040185188fbae28be901ca589a11a94b1b38ca36a79eccfeb","price_changes":[{"asset_id":"41448400836309843603620980831210604935021861034693225347475867885462478926555","best_ask":"0.44","best_bid":"0.43","hash":"898c193fec3c070a91ed30b01b3cd54f821c5e95","price":"0.42","side":"BUY","size":"392.4"},{"asset_id":"24254094493625419915756280046002869097156693848522361803041977572204227262166","best_ask":"0.57","best_bid":"0.56","hash":"a49ed78ca41510af8f6eff77f7f59945d543e2a9","price":"0.58","side":"SELL","size":"392.4"}],"timestamp":"1785122358472"},"payload_hash":"b80542af3d3564ff12e423fab18a596c8ac0f2a5895891999b5693f9d331717c","raw_frame":"{\"market\":\"0x717c0e8ccd4d5c7040185188fbae28be901ca589a11a94b1b38ca36a79eccfeb\", \"price_changes\":[{\"asset_id\":\"41448400836309843603620980831210604935021861034693225347475867885462478926555\", \"price\":\"0.42\", \"size\":\"392.4\", \"side\":\"BUY\", \"hash\":\"898c193fec3c070a91ed30b01b3cd54f821c5e95\", \"best_bid\":\"0.43\", \"best_ask\":\"0.44\"}, {\"asset_id\":\"24254094493625419915756280046002869097156693848522361803041977572204227262166\", \"price\":\"0.58\", \"size\":\"392.4\", \"side\":\"SELL\", \"hash\":\"a49ed78ca41510af8f6eff77f7f59945d543e2a9\", \"best_bid\":\"0.56\", \"best_ask\":\"0.57\"}], \"timestamp\":\"1785122358472\", \"event_type\":\"price_change\"}","received_at":"2026-07-27T03:19:18.554007Z","schema_version":"clob-market-ws.price_change.v1","sequence":null,"server_hash":null,"server_timestamp":"1785122358472","session_id":"dd162b8dca5f43ff811d304e69a06123","source":"clob_market_ws"},"received_at":"2026-07-27T03:19:18.554007Z","record_id":"b93a97f1ed9f1f8893e2d7b6fd9c97cf0fa7efa9a00971acf0f37a232d49036e","schema_fingerprint":"4aa3821a28b0b7c2400bc59aba4bcc0a76e971dadd19610d3ad38c768e124dc7","schema_version":"edge-lab-recorder.raw.v1","sequence":null,"source":"clob_market_ws"}
{"event_at":"2026-07-27T03:19:18.473000Z","event_fingerprint":"aaf78f93be1018b27ecae49b8d885aaa475aac426fa69b05169ac44f9db1c664","payload":{"connection_id":"c7dc2e4762f849c6b6f9306b6518dcab","event_at":"2026-07-27T03:19:18.473000Z","event_type":"price_change","frame_hash":"85f883dc5d50c898dde1b32b4bdc55602b4c7b9cc40b2642f2902f90130902a0","frame_index":0,"kind":"data","monotonic_ns":224341893566750,"payload":{"event_type":"price_change","market":"0x717c0e8ccd4d5c7040185188fbae28be901ca589a11a94b1b38ca36a79eccfeb","price_changes":[{"asset_id":"24254094493625419915756280046002869097156693848522361803041977572204227262166","best_ask":"0.57","best_bid":"0.56","hash":"686865e912e90e20c70563ff0cc9a682bad050b9","price":"0.5","side":"BUY","size":"227.38"},{"asset_id":"41448400836309843603620980831210604935021861034693225347475867885462478926555","best_ask":"0.44","best_bid":"0.43","hash":"4de3823dbcb645f47b3604041fcb87be3fc3ea38","price":"0.5","side":"SELL","size":"227.38"}],"timestamp":"1785122358473"},"payload_hash":"215d00ace06b115c01edfa34559e5e72b65bb49722c9353c27e044571edb1b46","raw_frame":"{\"market\":\"0x717c0e8ccd4d5c7040185188fbae28be901ca589a11a94b1b38ca36a79eccfeb\", \"price_changes\":[{\"asset_id\":\"24254094493625419915756280046002869097156693848522361803041977572204227262166\", \"price\":\"0.5\", \"size\":\"227.38\", \"side\":\"BUY\", \"hash\":\"686865e912e90e20c70563ff0cc9a682bad050b9\", \"best_bid\":\"0.56\", \"best_ask\":\"0.57\"}, {\"asset_id\":\"41448400836309843603620980831210604935021861034693225347475867885462478926555\", \"price\":\"0.5\", \"size\":\"227.38\", \"side\":\"SELL\", \"hash\":\"4de3823dbcb645f47b3604041fcb87be3fc3ea38\", \"best_bid\":\"0.43\", \"best_ask\":\"0.44\"}], \"timestamp\":\"1785122358473\", \"event_type\":\"price_change\"}","received_at":"2026-07-27T03:19:18.556277Z","schema_version":"clob-market-ws.price_change.v1","sequence":null,"server_hash":null,"server_timestamp":"1785122358473","session_id":"dd162b8dca5f43ff811d304e69a06123","source":"clob_market_ws"},"received_at":"2026-07-27T03:19:18.556277Z","record_id":"eed6f8c95a7e72a92e44b8b65f4b6577e4ed046ca992e2408d3967bf67bf4062","schema_fingerprint":"4aa3821a28b0b7c2400bc59aba4bcc0a76e971dadd19610d3ad38c768e124dc7","schema_version":"edge-lab-recorder.raw.v1","sequence":null,"source":"clob_market_ws"}
{"event_at":"2026-07-27T03:19:18.473000Z","event_fingerprint":"8aefeb294b81cbac1755a8978b8c9e284699f1c7604487a3e3c3533082d3bda2","payload":{"connection_id":"c7dc2e4762f849c6b6f9306b6518dcab","event_at":"2026-07-27T03:19:18.473000Z","event_type":"price_change","frame_hash":"1125a5b6ba3f812239458ec64220a656f63018e21b1a256a9cc78214a6cbf41e","frame_index":0,"kind":"data","monotonic_ns":224341896761625,"payload":{"event_type":"price_change","market":"0x717c0e8ccd4d5c7040185188fbae28be901ca589a11a94b1b38ca36a79eccfeb","price_changes":[{"asset_id":"41448400836309843603620980831210604935021861034693225347475867885462478926555","best_ask":"0.44","best_bid":"0.43","hash":"7aed3cd976afec5c33d65495fed43e265b29ea09","price":"0.5","side":"SELL","size":"211"},{"asset_id":"24254094493625419915756280046002869097156693848522361803041977572204227262166","best_ask":"0.57","best_bid":"0.56","hash":"f03a21b76ea0b4bd735ba69538c006f3e0233496","price":"0.5","side":"BUY","size":"211"}],"timestamp":"1785122358473"},"payload_hash":"d5560c1000d9a2dea7483727959a35b9752abe6abe1af7f912fe961d1380e6c6","raw_frame":"{\"market\":\"0x717c0e8ccd4d5c7040185188fbae28be901ca589a11a94b1b38ca36a79eccfeb\", \"price_changes\":[{\"asset_id\":\"41448400836309843603620980831210604935021861034693225347475867885462478926555\", \"price\":\"0.5\", \"size\":\"211\", \"side\":\"SELL\", \"hash\":\"7aed3cd976afec5c33d65495fed43e265b29ea09\", \"best_bid\":\"0.43\", \"best_ask\":\"0.44\"}, {\"asset_id\":\"24254094493625419915756280046002869097156693848522361803041977572204227262166\", \"price\":\"0.5\", \"size\":\"211\", \"side\":\"BUY\", \"hash\":\"f03a21b76ea0b4bd735ba69538c006f3e0233496\", \"best_bid\":\"0.56\", \"best_ask\":\"0.57\"}], \"timestamp\":\"1785122358473\", \"event_type\":\"price_change\"}","received_at":"2026-07-27T03:19:18.559472Z","schema_version":"clob-market-ws.price_change.v1","sequence":null,"server_hash":null,"server_timestamp":"1785122358473","session_id":"dd162b8dca5f43ff811d304e69a06123","source":"clob_market_ws"},"received_at":"2026-07-27T03:19:18.559472Z","record_id":"1e80a88cf6edb60f6cdec415574527d51c64c9f8ede49ffbf615db42b050ad84","schema_fingerprint":"4aa3821a28b0b7c2400bc59aba4bcc0a76e971dadd19610d3ad38c768e124dc7","schema_version":"edge-lab-recorder.raw.v1","sequence":null,"source":"clob_market_ws"}
{"event_at":"2026-07-27T03:19:18.474000Z","event_fingerprint":"86756ad5c460803c7e22fac5cd90e06ded9a24d3ba4a4aa0e0ee3ea48cc6c259","payload":{"connection_id":"c7dc2e4762f849c6b6f9306b6518dcab","event_at":"2026-07-27T03:19:18.474000Z","event_type":"price_change","frame_hash":"d6745977115d989cdb7e980ef6fe07eaf564e8f9712eab99d887b346ab2f9a17","frame_index":0,"kind":"data","monotonic_ns":224341899689416,"payload":{"event_type":"price_change","market":"0x717c0e8ccd4d5c7040185188fbae28be901ca589a11a94b1b38ca36a79eccfeb","price_changes":[{"asset_id":"41448400836309843603620980831210604935021861034693225347475867885462478926555","best_ask":"0.44","best_bid":"0.43","hash":"6e11d2c317452982d718a1fd4524ed34d1e58e55","price":"0.43","side":"BUY","size":"16.54"},{"asset_id":"24254094493625419915756280046002869097156693848522361803041977572204227262166","best_ask":"0.57","best_bid":"0.56","hash":"a650356b4193f9ccbc010522539e310fd5fd33e6","price":"0.57","side":"SELL","size":"16.54"}],"timestamp":"1785122358474"},"payload_hash":"c2c5074ec8d5c50a0faff79f3dc1f0846da9da2f466048171d9ddc5aca1446b0","raw_frame":"{\"market\":\"0x717c0e8ccd4d5c7040185188fbae28be901ca589a11a94b1b38ca36a79eccfeb\", \"price_changes\":[{\"asset_id\":\"41448400836309843603620980831210604935021861034693225347475867885462478926555\", \"price\":\"0.43\", \"size\":\"16.54\", \"side\":\"BUY\", \"hash\":\"6e11d2c317452982d718a1fd4524ed34d1e58e55\", \"best_bid\":\"0.43\", \"best_ask\":\"0.44\"}, {\"asset_id\":\"24254094493625419915756280046002869097156693848522361803041977572204227262166\", \"price\":\"0.57\", \"size\":\"16.54\", \"side\":\"SELL\", \"hash\":\"a650356b4193f9ccbc010522539e310fd5fd33e6\", \"best_bid\":\"0.56\", \"best_ask\":\"0.57\"}], \"timestamp\":\"1785122358474\", \"event_type\":\"price_change\"}","received_at":"2026-07-27T03:19:18.562402Z","schema_version":"clob-market-ws.price_change.v1","sequence":null,"server_hash":null,"server_timestamp":"1785122358474","session_id":"dd162b8dca5f43ff811d304e69a06123","source":"clob_market_ws"},"received_at":"2026-07-27T03:19:18.562402Z","record_id":"2fd67631058da92359c6d573a98cccf74395a830d125e232a02b1eb4ae8034e4","schema_fingerprint":"4aa3821a28b0b7c2400bc59aba4bcc0a76e971dadd19610d3ad38c768e124dc7","schema_version":"edge-lab-recorder.raw.v1","sequence":null,"source":"clob_market_ws"}
{"event_at":"2026-07-27T03:19:18.475000Z","event_fingerprint":"e7f0b66286cdfb193ea285ab7478c34dd8ac44b15c0c950db57a2bdf474c337c","payload":{"connection_id":"c7dc2e4762f849c6b6f9306b6518dcab","event_at":"2026-07-27T03:19:18.475000Z","event_type":"price_change","frame_hash":"6f381bf9f578198f5e42670b1cdc4f5fefb45df3cadb5f000f9c3ef3101857b3","frame_index":0,"kind":"data","monotonic_ns":224341902660291,"payload":{"event_type":"price_change","market":"0x717c0e8ccd4d5c7040185188fbae28be901ca589a11a94b1b38ca36a79eccfeb","price_changes":[{"asset_id":"41448400836309843603620980831210604935021861034693225347475867885462478926555","best_ask":"0.44","best_bid":"0.43","hash":"9ebf3ff826b4a358ae7fec9d110caa7a538a2e91","price":"0.43","side":"BUY","size":"26.54"},{"asset_id":"24254094493625419915756280046002869097156693848522361803041977572204227262166","best_ask":"0.57","best_bid":"0.56","hash":"8142988912f22b8157550793da437e42967c347c","price":"0.57","side":"SELL","size":"26.54"}],"timestamp":"1785122358475"},"payload_hash":"e189e9c2cf40686fdcef13dca4e3abf07952f392a9e065983729184e854dc4e1","raw_frame":"{\"market\":\"0x717c0e8ccd4d5c7040185188fbae28be901ca589a11a94b1b38ca36a79eccfeb\", \"price_changes\":[{\"asset_id\":\"41448400836309843603620980831210604935021861034693225347475867885462478926555\", \"price\":\"0.43\", \"size\":\"26.54\", \"side\":\"BUY\", \"hash\":\"9ebf3ff826b4a358ae7fec9d110caa7a538a2e91\", \"best_bid\":\"0.43\", \"best_ask\":\"0.44\"}, {\"asset_id\":\"24254094493625419915756280046002869097156693848522361803041977572204227262166\", \"price\":\"0.57\", \"size\":\"26.54\", \"side\":\"SELL\", \"hash\":\"8142988912f22b8157550793da437e42967c347c\", \"best_bid\":\"0.56\", \"best_ask\":\"0.57\"}], \"timestamp\":\"1785122358475\", \"event_type\":\"price_change\"}","received_at":"2026-07-27T03:19:18.565370Z","schema_version":"clob-market-ws.price_change.v1","sequence":null,"server_hash":null,"server_timestamp":"1785122358475","session_id":"dd162b8dca5f43ff811d304e69a06123","source":"clob_market_ws"},"received_at":"2026-07-27T03:19:18.565370Z","record_id":"cc1182c1b261f8e19b63d6c442b220e365cc5fc38618c4394b9918e0780841ad","schema_fingerprint":"4aa3821a28b0b7c2400bc59aba4bcc0a76e971dadd19610d3ad38c768e124dc7","schema_version":"edge-lab-recorder.raw.v1","sequence":null,"source":"clob_market_ws"}
{"event_at":"2026-07-27T03:19:18.476000Z","event_fingerprint":"75bd37cc621eb783855e7132ebab417c0899b20f7a46107c2ceaadc1aa8c10d4","payload":{"connection_id":"c7dc2e4762f849c6b6f9306b6518dcab","event_at":"2026-07-27T03:19:18.476000Z","event_type":"price_change","frame_hash":"48b092eca7431fdd49ad826a03a1cc4562f19f36da31f4037bcebb17dbc74605","frame_index":0,"kind":"data","monotonic_ns":224341905544291,"payload":{"event_type":"price_change","market":"0x717c0e8ccd4d5c7040185188fbae28be901ca589a11a94b1b38ca36a79eccfeb","price_changes":[{"asset_id":"41448400836309843603620980831210604935021861034693225347475867885462478926555","best_ask":"0.44","best_bid":"0.43","hash":"5854cfb622215353fb7c006fdd8e77479c4e7f9c","price":"0.43","side":"BUY","size":"34.54"},{"asset_id":"24254094493625419915756280046002869097156693848522361803041977572204227262166","best_ask":"0.57","best_bid":"0.56","hash":"e5a178ac776f25855e66f38e51b8ede550f3a836","price":"0.57","side":"SELL","size":"34.54"}],"timestamp":"1785122358476"},"payload_hash":"7432835666b399aacbb0ae182d241a08e1b29167aa7276c20a8a1ecdecba6fcf","raw_frame":"{\"market\":\"0x717c0e8ccd4d5c7040185188fbae28be901ca589a11a94b1b38ca36a79eccfeb\", \"price_changes\":[{\"asset_id\":\"41448400836309843603620980831210604935021861034693225347475867885462478926555\", \"price\":\"0.43\", \"size\":\"34.54\", \"side\":\"BUY\", \"hash\":\"5854cfb622215353fb7c006fdd8e77479c4e7f9c\", \"best_bid\":\"0.43\", \"best_ask\":\"0.44\"}, {\"asset_id\":\"24254094493625419915756280046002869097156693848522361803041977572204227262166\", \"price\":\"0.57\", \"size\":\"34.54\", \"side\":\"SELL\", \"hash\":\"e5a178ac776f25855e66f38e51b8ede550f3a836\", \"best_bid\":\"0.56\", \"best_ask\":\"0.57\"}], \"timestamp\":\"1785122358476\", \"event_type\":\"price_change\"}","received_at":"2026-07-27T03:19:18.568256Z","schema_version":"clob-market-ws.price_change.v1","sequence":null,"server_hash":null,"server_timestamp":"1785122358476","session_id":"dd162b8dca5f43ff811d304e69a06123","source":"clob_market_ws"},"received_at":"2026-07-27T03:19:18.568256Z","record_id":"ac7a137a550936178c849d5d4ad7a9b95ed2026b1a7dc5d009ececc6f4946b7a","schema_fingerprint":"4aa3821a28b0b7c2400bc59aba4bcc0a76e971dadd19610d3ad38c768e124dc7","schema_version":"edge-lab-recorder.raw.v1","sequence":null,"source":"clob_market_ws"}
{"event_at":"2026-07-27T03:19:18.478000Z","event_fingerprint":"e1c5874640da3fb3115889062166a7e8dfc668bca31caf6ee23e5905d008cc87","payload":{"connection_id":"c7dc2e4762f849c6b6f9306b6518dcab","event_at":"2026-07-27T03:19:18.478000Z","event_type":"price_change","frame_hash":"cbe2c50daebcf2475768b2d4a7956ccff2223b2cf909bf52ac8df36fb3c43485","frame_index":0,"kind":"data","monotonic_ns":224341908524000,"payload":{"event_type":"price_change","market":"0x717c0e8ccd4d5c7040185188fbae28be901ca589a11a94b1b38ca36a79eccfeb","price_changes":[{"asset_id":"41448400836309843603620980831210604935021861034693225347475867885462478926555","best_ask":"0.44","best_bid":"0.43","hash":"7442fc8b5a69ffeda0f2b50d3d99da25c3d5cdb8","price":"0.43","side":"BUY","size":"43.54"},{"asset_id":"24254094493625419915756280046002869097156693848522361803041977572204227262166","best_ask":"0.57","best_bid":"0.56","hash":"bfd261c3ed119a226a476efd85383a9e56d0aaad","price":"0.57","side":"SELL","size":"43.54"}],"timestamp":"1785122358478"},"payload_hash":"537ec304bd71ea8701dd33c9e0f28f37abfb59c07c64c3556067699ab800ba23","raw_frame":"{\"market\":\"0x717c0e8ccd4d5c7040185188fbae28be901ca589a11a94b1b38ca36a79eccfeb\", \"price_changes\":[{\"asset_id\":\"41448400836309843603620980831210604935021861034693225347475867885462478926555\", \"price\":\"0.43\", \"size\":\"43.54\", \"side\":\"BUY\", \"hash\":\"7442fc8b5a69ffeda0f2b50d3d99da25c3d5cdb8\", \"best_bid\":\"0.43\", \"best_ask\":\"0.44\"}, {\"asset_id\":\"24254094493625419915756280046002869097156693848522361803041977572204227262166\", \"price\":\"0.57\", \"size\":\"43.54\", \"side\":\"SELL\", \"hash\":\"bfd261c3ed119a226a476efd85383a9e56d0aaad\", \"best_bid\":\"0.56\", \"best_ask\":\"0.57\"}], \"timestamp\":\"1785122358478\", \"event_type\":\"price_change\"}","received_at":"2026-07-27T03:19:18.571236Z","schema_version":"clob-market-ws.price_change.v1","sequence":null,"server_hash":null,"server_timestamp":"1785122358478","session_id":"dd162b8dca5f43ff811d304e69a06123","source":"clob_market_ws"},"received_at":"2026-07-27T03:19:18.571236Z","record_id":"df6c2e446aaf8f1af89d46151026bf47c97e5eaa5f74193ca630dfc16fad24f6","schema_fingerprint":"4aa3821a28b0b7c2400bc59aba4bcc0a76e971dadd19610d3ad38c768e124dc7","schema_version":"edge-lab-recorder.raw.v1","sequence":null,"source":"clob_market_ws"}
{"event_at":"2026-07-27T03:19:18.482000Z","event_fingerprint":"40c78704cb1b19bc4f6f03b6d74937f4c62967a03cc89202d76a23ad86598d41","payload":{"connection_id":"c7dc2e4762f849c6b6f9306b6518dcab","event_at":"2026-07-27T03:19:18.482000Z","event_type":"price_change","frame_hash":"e11bbeea7794baeecb1b27b34127a11f3d54bb1122a86516cec8137cff1e071c","frame_index":0,"kind":"data","monotonic_ns":224341911491666,"payload":{"event_type":"price_change","market":"0x717c0e8ccd4d5c7040185188fbae28be901ca589a11a94b1b38ca36a79eccfeb","price_changes":[{"asset_id":"24254094493625419915756280046002869097156693848522361803041977572204227262166","best_ask":"0.57","best_bid":"0.56","hash":"c068a40be39c92e15133887a7c26c6e9c0fa5eb4","price":"0.04","side":"BUY","size":"633.09"},{"asset_id":"41448400836309843603620980831210604935021861034693225347475867885462478926555","best_ask":"0.44","best_bid":"0.43","hash":"b26dc1bcb09ab8adc7b12759e92285836adc39c3","price":"0.96","side":"SELL","size":"633.09"}],"timestamp":"1785122358482"},"payload_hash":"8972bdada1486e986668fbb2105729f2b7d0010979cc8ca113f251fdca13db83","raw_frame":"{\"market\":\"0x717c0e8ccd4d5c7040185188fbae28be901ca589a11a94b1b38ca36a79eccfeb\", \"price_changes\":[{\"asset_id\":\"24254094493625419915756280046002869097156693848522361803041977572204227262166\", \"price\":\"0.04\", \"size\":\"633.09\", \"side\":\"BUY\", \"hash\":\"c068a40be39c92e15133887a7c26c6e9c0fa5eb4\", \"best_bid\":\"0.56\", \"best_ask\":\"0.57\"}, {\"asset_id\":\"41448400836309843603620980831210604935021861034693225347475867885462478926555\", \"price\":\"0.96\", \"size\":\"633.09\", \"side\":\"SELL\", \"hash\":\"b26dc1bcb09ab8adc7b12759e92285836adc39c3\", \"best_bid\":\"0.43\", \"best_ask\":\"0.44\"}], \"timestamp\":\"1785122358482\", \"event_type\":\"price_change\"}","received_at":"2026-07-27T03:19:18.574202Z","schema_version":"clob-market-ws.price_change.v1","sequence":null,"server_hash":null,"server_timestamp":"1785122358482","session_id":"dd162b8dca5f43ff811d304e69a06123","source":"clob_market_ws"},"received_at":"2026-07-27T03:19:18.574202Z","record_id":"9fe8b541967186974e08cf6b9516436bedc0645a5910c76328d52954ee5a91fb","schema_fingerprint":"4aa3821a28b0b7c2400bc59aba4bcc0a76e971dadd19610d3ad38c768e124dc7","schema_version":"edge-lab-recorder.raw.v1","sequence":null,"source":"clob_market_ws"}
{"event_at":"2026-07-27T03:19:18.487000Z","event_fingerprint":"bf55847628874998b041e9ca4e9df37b6137d506b4414576c6abd405a91b084d","payload":{"connection_id":"c7dc2e4762f849c6b6f9306b6518dcab","event_at":"2026-07-27T03:19:18.487000Z","event_type":"price_change","frame_hash":"6d5de760ea8a127abec30ae8e8668f0539a4ca45438d4e4f0dc759b8dfe4c8fa","frame_index":0,"kind":"data","monotonic_ns":224341917073416,"payload":{"event_type":"price_change","market":"0x717c0e8ccd4d5c7040185188fbae28be901ca589a11a94b1b38ca36a79eccfeb","price_changes":[{"asset_id":"24254094493625419915756280046002869097156693848522361803041977572204227262166","best_ask":"0.57","best_bid":"0.56","hash":"2089abf49b64c74298855de8c9b3c4718239e032","price":"0.01","side":"BUY","size":"5703.02"},{"asset_id":"41448400836309843603620980831210604935021861034693225347475867885462478926555","best_ask":"0.44","best_bid":"0.43","hash":"c86f90b6aa00441f4838280d5960e8fb6db48cab","price":"0.99","side":"SELL","size":"5703.02"}],"timestamp":"1785122358487"},"payload_hash":"061f3f215c01e5da24b25af4e6de9e5cfceef30fe4d786ef944accf70d327a32","raw_frame":"{\"market\":\"0x717c0e8ccd4d5c7040185188fbae28be901ca589a11a94b1b38ca36a79eccfeb\", \"price_changes\":[{\"asset_id\":\"24254094493625419915756280046002869097156693848522361803041977572204227262166\", \"price\":\"0.01\", \"size\":\"5703.02\", \"side\":\"BUY\", \"hash\":\"2089abf49b64c74298855de8c9b3c4718239e032\", \"best_bid\":\"0.56\", \"best_ask\":\"0.57\"}, {\"asset_id\":\"41448400836309843603620980831210604935021861034693225347475867885462478926555\", \"price\":\"0.99\", \"size\":\"5703.02\", \"side\":\"SELL\", \"hash\":\"c86f90b6aa00441f4838280d5960e8fb6db48cab\", \"best_bid\":\"0.43\", \"best_ask\":\"0.44\"}], \"timestamp\":\"1785122358487\", \"event_type\":\"price_change\"}","received_at":"2026-07-27T03:19:18.579785Z","schema_version":"clob-market-ws.price_change.v1","sequence":null,"server_hash":null,"server_timestamp":"1785122358487","session_id":"dd162b8dca5f43ff811d304e69a06123","source":"clob_market_ws"},"received_at":"2026-07-27T03:19:18.579785Z","record_id":"6e425e53dff149936fdd8f4f70c4be93debda2c5b548c127ae0d9cbb5046246c","schema_fingerprint":"4aa3821a28b0b7c2400bc59aba4bcc0a76e971dadd19610d3ad38c768e124dc7","schema_version":"edge-lab-recorder.raw.v1","sequence":null,"source":"clob_market_ws"}
{"event_at":"2026-07-27T03:19:18.493000Z","event_fingerprint":"c133cb68e7eabb0da1d749ee73c7f477fde7d7f864cf99ed09e360d27559f510","payload":{"connection_id":"c7dc2e4762f849c6b6f9306b6518dcab","event_at":"2026-07-27T03:19:18.493000Z","event_type":"price_change","frame_hash":"0521ebd5bd71d195cfd0fc95ebcca60f497abaab46a055fac7b604c9d3e074e8","frame_index":0,"kind":"data","monotonic_ns":224341920586041,"payload":{"event_type":"price_change","market":"0x717c0e8ccd4d5c7040185188fbae28be901ca589a11a94b1b38ca36a79eccfeb","price_changes":[{"asset_id":"41448400836309843603620980831210604935021861034693225347475867885462478926555","best_ask":"0.44","best_bid":"0.43","hash":"bb17e2aa5e02c904060d9a5ed140c17dd9e2490a","price":"0.3","side":"BUY","size":"48.3"},{"asset_id":"24254094493625419915756280046002869097156693848522361803041977572204227262166","best_ask":"0.57","best_bid":"0.56","hash":"3384fead2a05c3a921ead593a9078429b01a2bd6","price":"0.7","side":"SELL","size":"48.3"}],"timestamp":"1785122358493"},"payload_hash":"7ca212f34f3a78569ef777fef13444aced7dd5bc295e1cbbb1b9092b6c23a7e9","raw_frame":"{\"market\":\"0x717c0e8ccd4d5c7040185188fbae28be901ca589a11a94b1b38ca36a79eccfeb\", \"price_changes\":[{\"asset_id\":\"41448400836309843603620980831210604935021861034693225347475867885462478926555\", \"price\":\"0.3\", \"size\":\"48.3\", \"side\":\"BUY\", \"hash\":\"bb17e2aa5e02c904060d9a5ed140c17dd9e2490a\", \"best_bid\":\"0.43\", \"best_ask\":\"0.44\"}, {\"asset_id\":\"24254094493625419915756280046002869097156693848522361803041977572204227262166\", \"price\":\"0.7\", \"size\":\"48.3\", \"side\":\"SELL\", \"hash\":\"3384fead2a05c3a921ead593a9078429b01a2bd6\", \"best_bid\":\"0.56\", \"best_ask\":\"0.57\"}], \"timestamp\":\"1785122358493\", \"event_type\":\"price_change\"}","received_at":"2026-07-27T03:19:18.583296Z","schema_version":"clob-market-ws.price_change.v1","sequence":null,"server_hash":null,"server_timestamp":"1785122358493","session_id":"dd162b8dca5f43ff811d304e69a06123","source":"clob_market_ws"},"received_at":"2026-07-27T03:19:18.583296Z","record_id":"21fc233967e8e4c9296b5de83bbbbbb26ef737b2a8350b88bec7364095896a2c","schema_fingerprint":"4aa3821a28b0b7c2400bc59aba4bcc0a76e971dadd19610d3ad38c768e124dc7","schema_version":"edge-lab-recorder.raw.v1","sequence":null,"source":"clob_market_ws"}
{"event_at":"2026-07-27T03:19:18.497000Z","event_fingerprint":"021204e3d7ba122c7ef134c19694448a64dedb08373ed167c66489abb9892d58","payload":{"connection_id":"c7dc2e4762f849c6b6f9306b6518dcab","event_at":"2026-07-27T03:19:18.497000Z","event_type":"price_change","frame_hash":"5e0edb6f61a3d0b94353cc191180695f164f0c049b3686596cf1b690eb52a8be","frame_index":0,"kind":"data","monotonic_ns":224341925821708,"payload":{"event_type":"price_change","market":"0x717c0e8ccd4d5c7040185188fbae28be901ca589a11a94b1b38ca36a79eccfeb","price_changes":[{"asset_id":"41448400836309843603620980831210604935021861034693225347475867885462478926555","best_ask":"0.44","best_bid":"0.43","hash":"00689e5337516135e9c6a755037a793cd3585e28","price":"0.31","side":"BUY","size":"218"},{"asset_id":"24254094493625419915756280046002869097156693848522361803041977572204227262166","best_ask":"0.57","best_bid":"0.56","hash":"0f4505ddd97eeae86b4e42cde99fbc40498c75f3","price":"0.69","side":"SELL","size":"218"}],"timestamp":"1785122358497"},"payload_hash":"19ac3ce7b2dd2c6ab8bd6834cf52b2e8f9e63941a22c3b9a3e9b0a9eddb6be8c","raw_frame":"{\"market\":\"0x717c0e8ccd4d5c7040185188fbae28be901ca589a11a94b1b38ca36a79eccfeb\", \"price_changes\":[{\"asset_id\":\"41448400836309843603620980831210604935021861034693225347475867885462478926555\", \"price\":\"0.31\", \"size\":\"218\", \"side\":\"BUY\", \"hash\":\"00689e5337516135e9c6a755037a793cd3585e28\", \"best_bid\":\"0.43\", \"best_ask\":\"0.44\"}, {\"asset_id\":\"24254094493625419915756280046002869097156693848522361803041977572204227262166\", \"price\":\"0.69\", \"size\":\"218\", \"side\":\"SELL\", \"hash\":\"0f4505ddd97eeae86b4e42cde99fbc40498c75f3\", \"best_bid\":\"0.56\", \"best_ask\":\"0.57\"}], \"timestamp\":\"1785122358497\", \"event_type\":\"price_change\"}","received_at":"2026-07-27T03:19:18.588531Z","schema_version":"clob-market-ws.price_change.v1","sequence":null,"server_hash":null,"server_timestamp":"1785122358497","session_id":"dd162b8dca5f43ff811d304e69a06123","source":"clob_market_ws"},"received_at":"2026-07-27T03:19:18.588531Z","record_id":"1a20efd989c441acbf2b3fc4f100ce1eb0f8c0e80a7a9cfb112ada944a2b8e80","schema_fingerprint":"4aa3821a28b0b7c2400bc59aba4bcc0a76e971dadd19610d3ad38c768e124dc7","schema_version":"edge-lab-recorder.raw.v1","sequence":null,"source":"clob_market_ws"}
{"event_at":"2026-07-27T03:19:18.500000Z","event_fingerprint":"54389241147922b1db3f675b91960c95bbd76c418bc8cc4154a2a512391f8952","payload":{"connection_id":"c7dc2e4762f849c6b6f9306b6518dcab","event_at":"2026-07-27T03:19:18.500000Z","event_type":"price_change","frame_hash":"1b2775a8acc6b0ee76da0ec4fcf1a12fcc817c62e78824e09db3229110e0ab31","frame_index":0,"kind":"data","monotonic_ns":224341930496250,"payload":{"event_type":"price_change","market":"0x717c0e8ccd4d5c7040185188fbae28be901ca589a11a94b1b38ca36a79eccfeb","price_changes":[{"asset_id":"41448400836309843603620980831210604935021861034693225347475867885462478926555","best_ask":"0.44","best_bid":"0.43","hash":"dcd2fe7949e8ae7aad010edd371b3ab9d984bc78","price":"0.43","side":"BUY","size":"68.54"},{"asset_id":"24254094493625419915756280046002869097156693848522361803041977572204227262166","best_ask":"0.57","best_bid":"0.56","hash":"ad223965f682c1176af7efe3e8a9418bd4d9b0cf","price":"0.57","side":"SELL","size":"68.54"}],"timestamp":"1785122358500"},"payload_hash":"7236df58727b626b0901b564e0c6392ee91f3d9b414dad2fcfc726797f1189d9","raw_frame":"{\"market\":\"0x717c0e8ccd4d5c7040185188fbae28be901ca589a11a94b1b38ca36a79eccfeb\", \"price_changes\":[{\"asset_id\":\"41448400836309843603620980831210604935021861034693225347475867885462478926555\", \"price\":\"0.43\", \"size\":\"68.54\", \"side\":\"BUY\", \"hash\":\"dcd2fe7949e8ae7aad010edd371b3ab9d984bc78\", \"best_bid\":\"0.43\", \"best_ask\":\"0.44\"}, {\"asset_id\":\"24254094493625419915756280046002869097156693848522361803041977572204227262166\", \"price\":\"0.57\", \"size\":\"68.54\", \"side\":\"SELL\", \"hash\":\"ad223965f682c1176af7efe3e8a9418bd4d9b0cf\", \"best_bid\":\"0.56\", \"best_ask\":\"0.57\"}], \"timestamp\":\"1785122358500\", \"event_type\":\"price_change\"}","received_at":"2026-07-27T03:19:18.593206Z","schema_version":"clob-market-ws.price_change.v1","sequence":null,"server_hash":null,"server_timestamp":"1785122358500","session_id":"dd162b8dca5f43ff811d304e69a06123","source":"clob_market_ws"},"received_at":"2026-07-27T03:19:18.593206Z","record_id":"34a952bb02f4e5337177b846393a8cc512a7a90e7d9792e7e33e4d9080279cae","schema_fingerprint":"4aa3821a28b0b7c2400bc59aba4bcc0a76e971dadd19610d3ad38c768e124dc7","schema_version":"edge-lab-recorder.raw.v1","sequence":null,"source":"clob_market_ws"}
{"event_at":"2026-07-27T03:19:18.511000Z","event_fingerprint":"8600656c80be2758c34e42fd1611124a3330c319d813b09916e57b7ba7922c02","payload":{"connection_id":"c7dc2e4762f849c6b6f9306b6518dcab","event_at":"2026-07-27T03:19:18.511000Z","event_type":"last_trade_price","frame_hash":"dfa9236b46ad38ef4b92db8fd598fe4370f7b64985be6e689875a1cacadb1395","frame_index":0,"kind":"data","monotonic_ns":224341934524875,"payload":{"asset_id":"41448400836309843603620980831210604935021861034693225347475867885462478926555","event_type":"last_trade_price","fee_rate_bps":"0","market":"0x717c0e8ccd4d5c7040185188fbae28be901ca589a11a94b1b38ca36a79eccfeb","price":"0.43","side":"BUY","size":"4.94","timestamp":"1785122358511","transaction_hash":"0xb7f2e3bb1c2d45caaf62ef5acc649c0e232cfe3fd214ba60e2628406333dc234"},"payload_hash":"8f14580153e396f2c9a39c8333a3ce4eb975fadcce8bc1f5442b464331353bdb","raw_frame":"{\"market\":\"0x717c0e8ccd4d5c7040185188fbae28be901ca589a11a94b1b38ca36a79eccfeb\", \"asset_id\":\"41448400836309843603620980831210604935021861034693225347475867885462478926555\", \"price\":\"0.43\", \"size\":\"4.94\", \"fee_rate_bps\":\"0\", \"side\":\"BUY\", \"timestamp\":\"1785122358511\", \"event_type\":\"last_trade_price\", \"transaction_hash\":\"0xb7f2e3bb1c2d45caaf62ef5acc649c0e232cfe3fd214ba60e2628406333dc234\"}","received_at":"2026-07-27T03:19:18.597235Z","schema_version":"clob-market-ws.last_trade_price.v1","sequence":null,"server_hash":null,"server_timestamp":"1785122358511","session_id":"dd162b8dca5f43ff811d304e69a06123","source":"clob_market_ws"},"received_at":"2026-07-27T03:19:18.597235Z","record_id":"8e80427129855d98ef95efbaa104b34926cd0da250cc36a6a1ed1c558f67c2be","schema_fingerprint":"95ad9be75a4b695cd99991e12b2592bc7346f3f5388a82d0000ba65bc0d9fd0a","schema_version":"edge-lab-recorder.raw.v1","sequence":null,"source":"clob_market_ws"}
{"event_at":"2026-07-27T03:19:18.521000Z","event_fingerprint":"b76f751ab6ce0971463aa928ab5028293eb260a574e975f2586bb8b046662fa7","payload":{"connection_id":"c7dc2e4762f849c6b6f9306b6518dcab","event_at":"2026-07-27T03:19:18.521000Z","event_type":"price_change","frame_hash":"6d5a2130cf4c839bcbf81166fe33a9c72c3563008a4783c361ac329253f8a0aa","frame_index":0,"kind":"data","monotonic_ns":224341937113625,"payload":{"event_type":"price_change","market":"0x717c0e8ccd4d5c7040185188fbae28be901ca589a11a94b1b38ca36a79eccfeb","price_changes":[{"asset_id":"24254094493625419915756280046002869097156693848522361803041977572204227262166","best_ask":"0.57","best_bid":"0.56","hash":"6ff9208669ac697395101478a3ce6a6998034a35","price":"0.37","side":"BUY","size":"198.08"},{"asset_id":"41448400836309843603620980831210604935021861034693225347475867885462478926555","best_ask":"0.44","best_bid":"0.43","hash":"acf57fdfdcc58a268c494e552e6fa650fe344a9c","price":"0.63","side":"SELL","size":"198.08"}],"timestamp":"1785122358521"},"payload_hash":"aee75678086346a14e713e2a5314bb9b325ce6e081401a81ae8977cf80ed5024","raw_frame":"{\"market\":\"0x717c0e8ccd4d5c7040185188fbae28be901ca589a11a94b1b38ca36a79eccfeb\", \"price_changes\":[{\"asset_id\":\"24254094493625419915756280046002869097156693848522361803041977572204227262166\", \"price\":\"0.37\", \"size\":\"198.08\", \"side\":\"BUY\", \"hash\":\"6ff9208669ac697395101478a3ce6a6998034a35\", \"best_bid\":\"0.56\", \"best_ask\":\"0.57\"}, {\"asset_id\":\"41448400836309843603620980831210604935021861034693225347475867885462478926555\", \"price\":\"0.63\", \"size\":\"198.08\", \"side\":\"SELL\", \"hash\":\"acf57fdfdcc58a268c494e552e6fa650fe344a9c\", \"best_bid\":\"0.43\", \"best_ask\":\"0.44\"}], \"timestamp\":\"1785122358521\", \"event_type\":\"price_change\"}","received_at":"2026-07-27T03:19:18.599826Z","schema_version":"clob-market-ws.price_change.v1","sequence":null,"server_hash":null,"server_timestamp":"1785122358521","session_id":"dd162b8dca5f43ff811d304e69a06123","source":"clob_market_ws"},"received_at":"2026-07-27T03:19:18.599826Z","record_id":"2864b707a43146a0c3da65a18e825047dec4b2a61536e53c6f85826e0fca43b5","schema_fingerprint":"4aa3821a28b0b7c2400bc59aba4bcc0a76e971dadd19610d3ad38c768e124dc7","schema_version":"edge-lab-recorder.raw.v1","sequence":null,"source":"clob_market_ws"}
{"event_at":"2026-07-27T03:19:18.522000Z","event_fingerprint":"1b8b6d501555cefe35bb21a772456c9af421463345aabe6c910846cd8427dd1f","payload":{"connection_id":"c7dc2e4762f849c6b6f9306b6518dcab","event_at":"2026-07-27T03:19:18.522000Z","event_type":"price_change","frame_hash":"c6086b6c8ecd2f8855b2946f03b32236826be0bae0e0ea845dde4a12ff26a5f0","frame_index":0,"kind":"data","monotonic_ns":224341940085583,"payload":{"event_type":"price_change","market":"0x717c0e8ccd4d5c7040185188fbae28be901ca589a11a94b1b38ca36a79eccfeb","price_changes":[{"asset_id":"41448400836309843603620980831210604935021861034693225347475867885462478926555","best_ask":"0.44","best_bid":"0.43","hash":"2ed5f0c7a2222a67a4db852c19f7eafedebb14bf","price":"0.31","side":"BUY","size":"188"},{"asset_id":"24254094493625419915756280046002869097156693848522361803041977572204227262166","best_ask":"0.57","best_bid":"0.56","hash":"9dd6791930a16d168006517f7892964ef1ea5f2b","price":"0.69","side":"SELL","size":"188"}],"timestamp":"1785122358522"},"payload_hash":"0018d9c2059d9fb1e41c396dd8b6272e7bfe958d9ff631f98465d8231eed8ec8","raw_frame":"{\"market\":\"0x717c0e8ccd4d5c7040185188fbae28be901ca589a11a94b1b38ca36a79eccfeb\", \"price_changes\":[{\"asset_id\":\"41448400836309843603620980831210604935021861034693225347475867885462478926555\", \"price\":\"0.31\", \"size\":\"188\", \"side\":\"BUY\", \"hash\":\"2ed5f0c7a2222a67a4db852c19f7eafedebb14bf\", \"best_bid\":\"0.43\", \"best_ask\":\"0.44\"}, {\"asset_id\":\"24254094493625419915756280046002869097156693848522361803041977572204227262166\", \"price\":\"0.69\", \"size\":\"188\", \"side\":\"SELL\", \"hash\":\"9dd6791930a16d168006517f7892964ef1ea5f2b\", \"best_bid\":\"0.56\", \"best_ask\":\"0.57\"}], \"timestamp\":\"1785122358522\", \"event_type\":\"price_change\"}","received_at":"2026-07-27T03:19:18.602795Z","schema_version":"clob-market-ws.price_change.v1","sequence":null,"server_hash":null,"server_timestamp":"1785122358522","session_id":"dd162b8dca5f43ff811d304e69a06123","source":"clob_market_ws"},"received_at":"2026-07-27T03:19:18.602795Z","record_id":"268a1ff925dd4b3166f2bc14f0613ad9dba9add58e22eb5fb9e088e82d8c9048","schema_fingerprint":"4aa3821a28b0b7c2400bc59aba4bcc0a76e971dadd19610d3ad38c768e124dc7","schema_version":"edge-lab-recorder.raw.v1","sequence":null,"source":"clob_market_ws"}
{"event_at":"2026-07-27T03:19:18.523000Z","event_fingerprint":"b4b3cc7396317fe24b950cd714696be8228617a1c9a911f005c51cd36946574b","payload":{"connection_id":"c7dc2e4762f849c6b6f9306b6518dcab","event_at":"2026-07-27T03:19:18.523000Z","event_type":"price_change","frame_hash":"01fdc67e777d063d4fd12c94ec16bd34a0bb2ab1fbd24a0bf8c7c8809c76e3f7","frame_index":0,"kind":"data","monotonic_ns":224341943183500,"payload":{"event_type":"price_change","market":"0x717c0e8ccd4d5c7040185188fbae28be901ca589a11a94b1b38ca36a79eccfeb","price_changes":[{"asset_id":"41448400836309843603620980831210604935021861034693225347475867885462478926555","best_ask":"0.44","best_bid":"0.43","hash":"646d977970ade00c4254da2f7cd2303a19012688","price":"0.31","side":"BUY","size":"158"},{"asset_id":"24254094493625419915756280046002869097156693848522361803041977572204227262166","best_ask":"0.57","best_bid":"0.56","hash":"a31171dc0b5917d599d412861c13578789ca8fd0","price":"0.69","side":"SELL","size":"158"}],"timestamp":"1785122358523"},"payload_hash":"5e38c0471e8f8156553d948a597f76ce7be16ac94df905111de412f2e7bbb1b1","raw_frame":"{\"market\":\"0x717c0e8ccd4d5c7040185188fbae28be901ca589a11a94b1b38ca36a79eccfeb\", \"price_changes\":[{\"asset_id\":\"41448400836309843603620980831210604935021861034693225347475867885462478926555\", \"price\":\"0.31\", \"size\":\"158\", \"side\":\"BUY\", \"hash\":\"646d977970ade00c4254da2f7cd2303a19012688\", \"best_bid\":\"0.43\", \"best_ask\":\"0.44\"}, {\"asset_id\":\"24254094493625419915756280046002869097156693848522361803041977572204227262166\", \"price\":\"0.69\", \"size\":\"158\", \"side\":\"SELL\", \"hash\":\"a31171dc0b5917d599d412861c13578789ca8fd0\", \"best_bid\":\"0.56\", \"best_ask\":\"0.57\"}], \"timestamp\":\"1785122358523\", \"event_type\":\"price_change\"}","received_at":"2026-07-27T03:19:18.605894Z","schema_version":"clob-market-ws.price_change.v1","sequence":null,"server_hash":null,"server_timestamp":"1785122358523","session_id":"dd162b8dca5f43ff811d304e69a06123","source":"clob_market_ws"},"received_at":"2026-07-27T03:19:18.605894Z","record_id":"ccac310b9cd010d802cf091be340d5ad5cba53738b536846cc2f688f8964ef0a","schema_fingerprint":"4aa3821a28b0b7c2400bc59aba4bcc0a76e971dadd19610d3ad38c768e124dc7","schema_version":"edge-lab-recorder.raw.v1","sequence":null,"source":"clob_market_ws"}
{"event_at":"2026-07-27T03:19:18.524000Z","event_fingerprint":"f1b89efb8b1973300a7d1ed6582dacb1e20438164ec4bbc9201feee6929a7e10","payload":{"connection_id":"c7dc2e4762f849c6b6f9306b6518dcab","event_at":"2026-07-27T03:19:18.524000Z","event_type":"price_change","frame_hash":"b6d2a7cfbcaba67a5abe5d80c55ff5baf2434224c187a8beecdcc536a50eeccb","frame_index":0,"kind":"data","monotonic_ns":224341946326083,"payload":{"event_type":"price_change","market":"0x717c0e8ccd4d5c7040185188fbae28be901ca589a11a94b1b38ca36a79eccfeb","price_changes":[{"asset_id":"24254094493625419915756280046002869097156693848522361803041977572204227262166","best_ask":"0.57","best_bid":"0.56","hash":"4165fcfee5546efcb6d9664538b9474a3a2f3916","price":"0.51","side":"BUY","size":"295"},{"asset_id":"41448400836309843603620980831210604935021861034693225347475867885462478926555","best_ask":"0.44","best_bid":"0.43","hash":"6dab9ab440b261f89135c416ff96ec2b43c3545b","price":"0.49","side":"SELL","size":"295"}],"timestamp":"1785122358524"},"payload_hash":"439fb33fbdd2bdc337b21aa4c3f0820f9d784bd37415ebc9e4eb5dbcde1303c9","raw_frame":"{\"market\":\"0x717c0e8ccd4d5c7040185188fbae28be901ca589a11a94b1b38ca36a79eccfeb\", \"price_changes\":[{\"asset_id\":\"24254094493625419915756280046002869097156693848522361803041977572204227262166\", \"price\":\"0.51\", \"size\":\"295\", \"side\":\"BUY\", \"hash\":\"4165fcfee5546efcb6d9664538b9474a3a2f3916\", \"best_bid\":\"0.56\", \"best_ask\":\"0.57\"}, {\"asset_id\":\"41448400836309843603620980831210604935021861034693225347475867885462478926555\", \"price\":\"0.49\", \"size\":\"295\", \"side\":\"SELL\", \"hash\":\"6dab9ab440b261f89135c416ff96ec2b43c3545b\", \"best_bid\":\"0.43\", \"best_ask\":\"0.44\"}], \"timestamp\":\"1785122358524\", \"event_type\":\"price_change\"}","received_at":"2026-07-27T03:19:18.609033Z","schema_version":"clob-market-ws.price_change.v1","sequence":null,"server_hash":null,"server_timestamp":"1785122358524","session_id":"dd162b8dca5f43ff811d304e69a06123","source":"clob_market_ws"},"received_at":"2026-07-27T03:19:18.609033Z","record_id":"f31cac67b564fb5a23a9ad3cd271bbc30dcfb639a11eaefe666fc80d67b0d23a","schema_fingerprint":"4aa3821a28b0b7c2400bc59aba4bcc0a76e971dadd19610d3ad38c768e124dc7","schema_version":"edge-lab-recorder.raw.v1","sequence":null,"source":"clob_market_ws"}
{"event_at":"2026-07-27T03:19:18.524000Z","event_fingerprint":"c87f2d48796da756ee7d27860d2072cdf5688a75fcdbf530d5013332e39a26c9","payload":{"connection_id":"c7dc2e4762f849c6b6f9306b6518dcab","event_at":"2026-07-27T03:19:18.524000Z","event_type":"price_change","frame_hash":"e492a04b02c23b0a9f18686e60c034277899918bad11f2c40d03293d5616d2b9","frame_index":0,"kind":"data","monotonic_ns":224341949503416,"payload":{"event_type":"price_change","market":"0x717c0e8ccd4d5c7040185188fbae28be901ca589a11a94b1b38ca36a79eccfeb","price_changes":[{"asset_id":"41448400836309843603620980831210604935021861034693225347475867885462478926555","best_ask":"0.44","best_bid":"0.43","hash":"c3ee9d5ed01f22c35533a43247626ce3814ea362","price":"0.31","side":"BUY","size":"128"},{"asset_id":"24254094493625419915756280046002869097156693848522361803041977572204227262166","best_ask":"0.57","best_bid":"0.56","hash":"f77967ea71a4a8f020dedb7f9596a7299116d1ad","price":"0.69","side":"SELL","size":"128"}],"timestamp":"1785122358524"},"payload_hash":"5135fa8e006568cf707fec35f520fee2804bbe615d2de0bc5ba6cbf56956000b","raw_frame":"{\"market\":\"0x717c0e8ccd4d5c7040185188fbae28be901ca589a11a94b1b38ca36a79eccfeb\", \"price_changes\":[{\"asset_id\":\"41448400836309843603620980831210604935021861034693225347475867885462478926555\", \"price\":\"0.31\", \"size\":\"128\", \"side\":\"BUY\", \"hash\":\"c3ee9d5ed01f22c35533a43247626ce3814ea362\", \"best_bid\":\"0.43\", \"best_ask\":\"0.44\"}, {\"asset_id\":\"24254094493625419915756280046002869097156693848522361803041977572204227262166\", \"price\":\"0.69\", \"size\":\"128\", \"side\":\"SELL\", \"hash\":\"f77967ea71a4a8f020dedb7f9596a7299116d1ad\", \"best_bid\":\"0.56\", \"best_ask\":\"0.57\"}], \"timestamp\":\"1785122358524\", \"event_type\":\"price_change\"}","received_at":"2026-07-27T03:19:18.612212Z","schema_version":"clob-market-ws.price_change.v1","sequence":null,"server_hash":null,"server_timestamp":"1785122358524","session_id":"dd162b8dca5f43ff811d304e69a06123","source":"clob_market_ws"},"received_at":"2026-07-27T03:19:18.612212Z","record_id":"e827dd995299efb1d36573248ae68ec77fa9cdddd6abc0a8ccaae9877ed7a316","schema_fingerprint":"4aa3821a28b0b7c2400bc59aba4bcc0a76e971dadd19610d3ad38c768e124dc7","schema_version":"edge-lab-recorder.raw.v1","sequence":null,"source":"clob_market_ws"}
{"event_at":"2026-07-27T03:19:18.527000Z","event_fingerprint":"a76752e647efcef866daf403615d71c5004c5cc8389a6910d0a786e1c16b6df0","payload":{"connection_id":"c7dc2e4762f849c6b6f9306b6518dcab","event_at":"2026-07-27T03:19:18.527000Z","event_type":"price_change","frame_hash":"61342f18eca23baecba38595aca57d8618c5414be5e029ced7bbb5cac27a6795","frame_index":0,"kind":"data","monotonic_ns":224341952481750,"payload":{"event_type":"price_change","market":"0x717c0e8ccd4d5c7040185188fbae28be901ca589a11a94b1b38ca36a79eccfeb","price_changes":[{"asset_id":"41448400836309843603620980831210604935021861034693225347475867885462478926555","best_ask":"0.44","best_bid":"0.43","hash":"e9b1e0df14292f7f5f6682a0cf5f61b5898f62d8","price":"0.42","side":"BUY","size":"122.4"},{"asset_id":"24254094493625419915756280046002869097156693848522361803041977572204227262166","best_ask":"0.57","best_bid":"0.56","hash":"0c0588c1a45e70ecbf82e9c59a9ea5bd4d57a4f0","price":"0.58","side":"SELL","size":"122.4"}],"timestamp":"1785122358527"},"payload_hash":"6b143e8fc9c833c941b243f9a88eaf0e91973736f3d3639282ce3f59715a9bbf","raw_frame":"{\"market\":\"0x717c0e8ccd4d5c7040185188fbae28be901ca589a11a94b1b38ca36a79eccfeb\", \"price_changes\":[{\"asset_id\":\"41448400836309843603620980831210604935021861034693225347475867885462478926555\", \"price\":\"0.42\", \"size\":\"122.4\", \"side\":\"BUY\", \"hash\":\"e9b1e0df14292f7f5f6682a0cf5f61b5898f62d8\", \"best_bid\":\"0.43\", \"best_ask\":\"0.44\"}, {\"asset_id\":\"24254094493625419915756280046002869097156693848522361803041977572204227262166\", \"price\":\"0.58\", \"size\":\"122.4\", \"side\":\"SELL\", \"hash\":\"0c0588c1a45e70ecbf82e9c59a9ea5bd4d57a4f0\", \"best_bid\":\"0.56\", \"best_ask\":\"0.57\"}], \"timestamp\":\"1785122358527\", \"event_type\":\"price_change\"}","received_at":"2026-07-27T03:19:18.615192Z","schema_version":"clob-market-ws.price_change.v1","sequence":null,"server_hash":null,"server_timestamp":"1785122358527","session_id":"dd162b8dca5f43ff811d304e69a06123","source":"clob_market_ws"},"received_at":"2026-07-27T03:19:18.615192Z","record_id":"4e19b4b69b8f5b0f2515ef81a6b400980aea6b543c2031993e547ee32e31aa8c","schema_fingerprint":"4aa3821a28b0b7c2400bc59aba4bcc0a76e971dadd19610d3ad38c768e124dc7","schema_version":"edge-lab-recorder.raw.v1","sequence":null,"source":"clob_market_ws"}
{"event_at":"2026-07-27T03:19:18.527000Z","event_fingerprint":"da468fd409b545c6e5fc41091cdd318d846468113668eef135c57b4e40eadcb7","payload":{"connection_id":"c7dc2e4762f849c6b6f9306b6518dcab","event_at":"2026-07-27T03:19:18.527000Z","event_type":"price_change","frame_hash":"2115e45e89dafde01f97760a36a804ce2079c541a9c4de2ef8b07c0c88f51f14","frame_index":0,"kind":"data","monotonic_ns":224341955379333,"payload":{"event_type":"price_change","market":"0x717c0e8ccd4d5c7040185188fbae28be901ca589a11a94b1b38ca36a79eccfeb","price_changes":[{"asset_id":"24254094493625419915756280046002869097156693848522361803041977572204227262166","best_ask":"0.57","best_bid":"0.56","hash":"0c0588c1a45e70ecbf82e9c59a9ea5bd4d57a4f0","price":"0.52","side":"BUY","size":"227"},{"asset_id":"41448400836309843603620980831210604935021861034693225347475867885462478926555","best_ask":"0.44","best_bid":"0.43","hash":"e9b1e0df14292f7f5f6682a0cf5f61b5898f62d8","price":"0.48","side":"SELL","size":"227"}],"timestamp":"1785122358527"},"payload_hash":"8160eb50e67bd00042349f52d4259e6caf320ee3bbe5ba7d0e219672b5ab4570","raw_frame":"{\"market\":\"0x717c0e8ccd4d5c7040185188fbae28be901ca589a11a94b1b38ca36a79eccfeb\", \"price_changes\":[{\"asset_id\":\"24254094493625419915756280046002869097156693848522361803041977572204227262166\", \"price\":\"0.52\", \"size\":\"227\", \"side\":\"BUY\", \"hash\":\"0c0588c1a45e70ecbf82e9c59a9ea5bd4d57a4f0\", \"best_bid\":\"0.56\", \"best_ask\":\"0.57\"}, {\"asset_id\":\"41448400836309843603620980831210604935021861034693225347475867885462478926555\", \"price\":\"0.48\", \"size\":\"227\", \"side\":\"SELL\", \"hash\":\"e9b1e0df14292f7f5f6682a0cf5f61b5898f62d8\", \"best_bid\":\"0.43\", \"best_ask\":\"0.44\"}], \"timestamp\":\"1785122358527\", \"event_type\":\"price_change\"}","received_at":"2026-07-27T03:19:18.618089Z","schema_version":"clob-market-ws.price_change.v1","sequence":null,"server_hash":null,"server_timestamp":"1785122358527","session_id":"dd162b8dca5f43ff811d304e69a06123","source":"clob_market_ws"},"received_at":"2026-07-27T03:19:18.618089Z","record_id":"ea21ade94c9bb322c8c92cc80d9c474eac8cd04a1d9527ee35a929d3f08e3c3c","schema_fingerprint":"4aa3821a28b0b7c2400bc59aba4bcc0a76e971dadd19610d3ad38c768e124dc7","schema_version":"edge-lab-recorder.raw.v1","sequence":null,"source":"clob_market_ws"}
{"event_at":"2026-07-27T03:19:18.529000Z","event_fingerprint":"4998f49bced0858c9cdc4ea45e59a67228536a5fecdf8cb6f16874ecda9ac7ba","payload":{"connection_id":"c7dc2e4762f849c6b6f9306b6518dcab","event_at":"2026-07-27T03:19:18.529000Z","event_type":"price_change","frame_hash":"a15530010a6c7949d91e0196a7c5fc126da19b9b6f769d81a48d0e56d11bd3eb","frame_index":0,"kind":"data","monotonic_ns":224341958286416,"payload":{"event_type":"price_change","market":"0x717c0e8ccd4d5c7040185188fbae28be901ca589a11a94b1b38ca36a79eccfeb","price_changes":[{"asset_id":"41448400836309843603620980831210604935021861034693225347475867885462478926555","best_ask":"0.44","best_bid":"0.43","hash":"da0988de8d370897d54ef3a8ed72181976aad2d0","price":"0.42","side":"BUY","size":"26.4"},{"asset_id":"24254094493625419915756280046002869097156693848522361803041977572204227262166","best_ask":"0.57","best_bid":"0.56","hash":"15d415f76f2c173fb4bcb6c3d86a391f319e5686","price":"0.58","side":"SELL","size":"26.4"}],"timestamp":"1785122358529"},"payload_hash":"2503fe743dd29cf0c0f0239903dfa98bed9f8903fd838c6ffaed7cda94a3fd21","raw_frame":"{\"market\":\"0x717c0e8ccd4d5c7040185188fbae28be901ca589a11a94b1b38ca36a79eccfeb\", \"price_changes\":[{\"asset_id\":\"41448400836309843603620980831210604935021861034693225347475867885462478926555\", \"price\":\"0.42\", \"size\":\"26.4\", \"side\":\"BUY\", \"hash\":\"da0988de8d370897d54ef3a8ed72181976aad2d0\", \"best_bid\":\"0.43\", \"best_ask\":\"0.44\"}, {\"asset_id\":\"24254094493625419915756280046002869097156693848522361803041977572204227262166\", \"price\":\"0.58\", \"size\":\"26.4\", \"side\":\"SELL\", \"hash\":\"15d415f76f2c173fb4bcb6c3d86a391f319e5686\", \"best_bid\":\"0.56\", \"best_ask\":\"0.57\"}], \"timestamp\":\"1785122358529\", \"event_type\":\"price_change\"}","received_at":"2026-07-27T03:19:18.620997Z","schema_version":"clob-market-ws.price_change.v1","sequence":null,"server_hash":null,"server_timestamp":"1785122358529","session_id":"dd162b8dca5f43ff811d304e69a06123","source":"clob_market_ws"},"received_at":"2026-07-27T03:19:18.620997Z","record_id":"08c9964050ca26ec499fa4db092e4a29c1739995a13443fc830a19c8507cd4db","schema_fingerprint":"4aa3821a28b0b7c2400bc59aba4bcc0a76e971dadd19610d3ad38c768e124dc7","schema_version":"edge-lab-recorder.raw.v1","sequence":null,"source":"clob_market_ws"}
{"event_at":"2026-07-27T03:19:18.529000Z","event_fingerprint":"09bfdaf3aad9fedcd79070aa5a91d7a5b79e3d63ae1966ed2917821d4b08e52c","payload":{"connection_id":"c7dc2e4762f849c6b6f9306b6518dcab","event_at":"2026-07-27T03:19:18.529000Z","event_type":"price_change","frame_hash":"15ba660d8a3843fca638a18b2ee810c9106a2efb3ff08685fe634066584a5c86","frame_index":0,"kind":"data","monotonic_ns":224341961445041,"payload":{"event_type":"price_change","market":"0x717c0e8ccd4d5c7040185188fbae28be901ca589a11a94b1b38ca36a79eccfeb","price_changes":[{"asset_id":"41448400836309843603620980831210604935021861034693225347475867885462478926555","best_ask":"0.44","best_bid":"0.43","hash":"42a3528a8007b713425df54631d1020a3e7b6921","price":"0.43","side":"BUY","size":"85.34"},{"asset_id":"24254094493625419915756280046002869097156693848522361803041977572204227262166","best_ask":"0.57","best_bid":"0.56","hash":"92f61302445689ea8d5a57ee2a5b14a8577a9a63","price":"0.57","side":"SELL","size":"85.34"}],"timestamp":"1785122358529"},"payload_hash":"1dceb554863f952427d7dfa0b63ffa88c67db92ccc1d9eccdc2680b12c98aeca","raw_frame":"{\"market\":\"0x717c0e8ccd4d5c7040185188fbae28be901ca589a11a94b1b38ca36a79eccfeb\", \"price_changes\":[{\"asset_id\":\"41448400836309843603620980831210604935021861034693225347475867885462478926555\", \"price\":\"0.43\", \"size\":\"85.34\", \"side\":\"BUY\", \"hash\":\"42a3528a8007b713425df54631d1020a3e7b6921\", \"best_bid\":\"0.43\", \"best_ask\":\"0.44\"}, {\"asset_id\":\"24254094493625419915756280046002869097156693848522361803041977572204227262166\", \"price\":\"0.57\", \"size\":\"85.34\", \"side\":\"SELL\", \"hash\":\"92f61302445689ea8d5a57ee2a5b14a8577a9a63\", \"best_bid\":\"0.56\", \"best_ask\":\"0.57\"}], \"timestamp\":\"1785122358529\", \"event_type\":\"price_change\"}","received_at":"2026-07-27T03:19:18.624139Z","schema_version":"clob-market-ws.price_change.v1","sequence":null,"server_hash":null,"server_timestamp":"1785122358529","session_id":"dd162b8dca5f43ff811d304e69a06123","source":"clob_market_ws"},"received_at":"2026-07-27T03:19:18.624139Z","record_id":"36ade01d668f8ecea41951b9529c2df0b8f209a0ba4be31b646e0deea2038645","schema_fingerprint":"4aa3821a28b0b7c2400bc59aba4bcc0a76e971dadd19610d3ad38c768e124dc7","schema_version":"edge-lab-recorder.raw.v1","sequence":null,"source":"clob_market_ws"}
{"event_at":"2026-07-27T03:19:18.530000Z","event_fingerprint":"9ea15b3cdc7119d4b11f54372b65f0c03ea2a29c8881c3b6c0838edae89ed1dc","payload":{"connection_id":"c7dc2e4762f849c6b6f9306b6518dcab","event_at":"2026-07-27T03:19:18.530000Z","event_type":"price_change","frame_hash":"7522c896308d36794fadd81ad3ad1523f044dec53ab842bee9b08202c9b837e1","frame_index":0,"kind":"data","monotonic_ns":224341964453750,"payload":{"event_type":"price_change","market":"0x717c0e8ccd4d5c7040185188fbae28be901ca589a11a94b1b38ca36a79eccfeb","price_changes":[{"asset_id":"24254094493625419915756280046002869097156693848522361803041977572204227262166","best_ask":"0.57","best_bid":"0.56","hash":"9197e4c882363ad93c028aad3030d578545a2ada","price":"0.56","side":"BUY","size":"12.14"},{"asset_id":"41448400836309843603620980831210604935021861034693225347475867885462478926555","best_ask":"0.44","best_bid":"0.43","hash":"73fd12e42a1096efb9bb1ce8a8808ac0e543d770","price":"0.44","side":"SELL","size":"12.14"}],"timestamp":"1785122358530"},"payload_hash":"fb22e8f958cd8f31e9d03996d9bccd2c4c0505cc1217c09b3bedff324e739fdd","raw_frame":"{\"market\":\"0x717c0e8ccd4d5c7040185188fbae28be901ca589a11a94b1b38ca36a79eccfeb\", \"price_changes\":[{\"asset_id\":\"24254094493625419915756280046002869097156693848522361803041977572204227262166\", \"price\":\"0.56\", \"size\":\"12.14\", \"side\":\"BUY\", \"hash\":\"9197e4c882363ad93c028aad3030d578545a2ada\", \"best_bid\":\"0.56\", \"best_ask\":\"0.57\"}, {\"asset_id\":\"41448400836309843603620980831210604935021861034693225347475867885462478926555\", \"price\":\"0.44\", \"size\":\"12.14\", \"side\":\"SELL\", \"hash\":\"73fd12e42a1096efb9bb1ce8a8808ac0e543d770\", \"best_bid\":\"0.43\", \"best_ask\":\"0.44\"}], \"timestamp\":\"1785122358530\", \"event_type\":\"price_change\"}","received_at":"2026-07-27T03:19:18.627164Z","schema_version":"clob-market-ws.price_change.v1","sequence":null,"server_hash":null,"server_timestamp":"1785122358530","session_id":"dd162b8dca5f43ff811d304e69a06123","source":"clob_market_ws"},"received_at":"2026-07-27T03:19:18.627164Z","record_id":"2a2a8ccd529ac0518b6f05d1c52b81ca0ccb5279f27af3e2a85842c0d9d20f71","schema_fingerprint":"4aa3821a28b0b7c2400bc59aba4bcc0a76e971dadd19610d3ad38c768e124dc7","schema_version":"edge-lab-recorder.raw.v1","sequence":null,"source":"clob_market_ws"}
{"event_at":"2026-07-27T03:19:18.530000Z","event_fingerprint":"4539d19cb633bab2c92ed3094cad05585421681b770282589e6d4c3cce04cdc0","payload":{"connection_id":"c7dc2e4762f849c6b6f9306b6518dcab","event_at":"2026-07-27T03:19:18.530000Z","event_type":"price_change","frame_hash":"2c7b06d13ba3aea40ff688a08738b9bc99956c78142fc4b2b4125a5c3840d40f","frame_index":0,"kind":"data","monotonic_ns":224341967481000,"payload":{"event_type":"price_change","market":"0x717c0e8ccd4d5c7040185188fbae28be901ca589a11a94b1b38ca36a79eccfeb","price_changes":[{"asset_id":"41448400836309843603620980831210604935021861034693225347475867885462478926555","best_ask":"0.44","best_bid":"0.43","hash":"33e31b0486be53160a035c853e125558f08ba61f","price":"0.43","side":"BUY","size":"94.94"},{"asset_id":"24254094493625419915756280046002869097156693848522361803041977572204227262166","best_ask":"0.57","best_bid":"0.56","hash":"3b1bf37a12c7b79232cb4fa26abe5aacf034a3b7","price":"0.57","side":"SELL","size":"94.94"}],"timestamp":"1785122358530"},"payload_hash":"7988d411d091360905d465fd9a705043e17d9c7c6648b454209bd755003efbcf","raw_frame":"{\"market\":\"0x717c0e8ccd4d5c7040185188fbae28be901ca589a11a94b1b38ca36a79eccfeb\", \"price_changes\":[{\"asset_id\":\"41448400836309843603620980831210604935021861034693225347475867885462478926555\", \"price\":\"0.43\", \"size\":\"94.94\", \"side\":\"BUY\", \"hash\":\"33e31b0486be53160a035c853e125558f08ba61f\", \"best_bid\":\"0.43\", \"best_ask\":\"0.44\"}, {\"asset_id\":\"24254094493625419915756280046002869097156693848522361803041977572204227262166\", \"price\":\"0.57\", \"size\":\"94.94\", \"side\":\"SELL\", \"hash\":\"3b1bf37a12c7b79232cb4fa26abe5aacf034a3b7\", \"best_bid\":\"0.56\", \"best_ask\":\"0.57\"}], \"timestamp\":\"1785122358530\", \"event_type\":\"price_change\"}","received_at":"2026-07-27T03:19:18.630192Z","schema_version":"clob-market-ws.price_change.v1","sequence":null,"server_hash":null,"server_timestamp":"1785122358530","session_id":"dd162b8dca5f43ff811d304e69a06123","source":"clob_market_ws"},"received_at":"2026-07-27T03:19:18.630192Z","record_id":"796c9fc974f56f745b3b6aad541dcc4dc3cc472f65d832f4a6ab36b04869d4bb","schema_fingerprint":"4aa3821a28b0b7c2400bc59aba4bcc0a76e971dadd19610d3ad38c768e124dc7","schema_version":"edge-lab-recorder.raw.v1","sequence":null,"source":"clob_market_ws"}
{"event_at":"2026-07-27T03:19:18.533000Z","event_fingerprint":"75d4dc84c8eb88671cb284fb1b50d5a9c16825d04186c795835b598d94ba7936","payload":{"connection_id":"c7dc2e4762f849c6b6f9306b6518dcab","event_at":"2026-07-27T03:19:18.533000Z","event_type":"price_change","frame_hash":"054c7afbd24123d779f6659d8c3bf3204e678fd26d354cf81936ce7d15b2f3ee","frame_index":0,"kind":"data","monotonic_ns":224341969688708,"payload":{"event_type":"price_change","market":"0x717c0e8ccd4d5c7040185188fbae28be901ca589a11a94b1b38ca36a79eccfeb","price_changes":[{"asset_id":"41448400836309843603620980831210604935021861034693225347475867885462478926555","best_ask":"0.44","best_bid":"0.43","hash":"da104dea13405e72152b483f5e62b4bb04e72ee5","price":"0.43","side":"BUY","size":"190.94"},{"asset_id":"24254094493625419915756280046002869097156693848522361803041977572204227262166","best_ask":"0.57","best_bid":"0.56","hash":"06430d904ac4b2a25193a5dae6337fdd1aa2bf75","price":"0.57","side":"SELL","size":"190.94"}],"timestamp":"1785122358533"},"payload_hash":"1cd0c91209a19dee299363c00d4a6139d55aa06c586958d74b0a01832a369ef4","raw_frame":"{\"market\":\"0x717c0e8ccd4d5c7040185188fbae28be901ca589a11a94b1b38ca36a79eccfeb\", \"price_changes\":[{\"asset_id\":\"41448400836309843603620980831210604935021861034693225347475867885462478926555\", \"price\":\"0.43\", \"size\":\"190.94\", \"side\":\"BUY\", \"hash\":\"da104dea13405e72152b483f5e62b4bb04e72ee5\", \"best_bid\":\"0.43\", \"best_ask\":\"0.44\"}, {\"asset_id\":\"24254094493625419915756280046002869097156693848522361803041977572204227262166\", \"price\":\"0.57\", \"size\":\"190.94\", \"side\":\"SELL\", \"hash\":\"06430d904ac4b2a25193a5dae6337fdd1aa2bf75\", \"best_bid\":\"0.56\", \"best_ask\":\"0.57\"}], \"timestamp\":\"1785122358533\", \"event_type\":\"price_change\"}","received_at":"2026-07-27T03:19:18.632400Z","schema_version":"clob-market-ws.price_change.v1","sequence":null,"server_hash":null,"server_timestamp":"1785122358533","session_id":"dd162b8dca5f43ff811d304e69a06123","source":"clob_market_ws"},"received_at":"2026-07-27T03:19:18.632400Z","record_id":"799b4be245301c27ee06ac6e0c39c75df11f4e8c854fc09dd4a52b1f563d40f4","schema_fingerprint":"4aa3821a28b0b7c2400bc59aba4bcc0a76e971dadd19610d3ad38c768e124dc7","schema_version":"edge-lab-recorder.raw.v1","sequence":null,"source":"clob_market_ws"}
{"event_at":"2026-07-27T03:19:18.534000Z","event_fingerprint":"074f87fe39a1117e86119f0363fa7f5418f928741aa35aff63384c2b85089bf8","payload":{"connection_id":"c7dc2e4762f849c6b6f9306b6518dcab","event_at":"2026-07-27T03:19:18.534000Z","event_type":"price_change","frame_hash":"069014302e345c00d8a2b9e75d07bbe91c057cae3b92308a2d77241aea0ccd2b","frame_index":0,"kind":"data","monotonic_ns":224341972516125,"payload":{"event_type":"price_change","market":"0x717c0e8ccd4d5c7040185188fbae28be901ca589a11a94b1b38ca36a79eccfeb","price_changes":[{"asset_id":"24254094493625419915756280046002869097156693848522361803041977572204227262166","best_ask":"0.57","best_bid":"0.56","hash":"50cba005d8ec82ada3b403e3b30e866ff556bd95","price":"0.55","side":"BUY","size":"30.67"},{"asset_id":"41448400836309843603620980831210604935021861034693225347475867885462478926555","best_ask":"0.44","best_bid":"0.43","hash":"be92094b30540b503f685d5994b990798d5569dd","price":"0.45","side":"SELL","size":"30.67"}],"timestamp":"1785122358534"},"payload_hash":"5dce0bcf01fe6d2176c688a1871574afd387d1ed0fd3a9eec4709652a65cfcf3","raw_frame":"{\"market\":\"0x717c0e8ccd4d5c7040185188fbae28be901ca589a11a94b1b38ca36a79eccfeb\", \"price_changes\":[{\"asset_id\":\"24254094493625419915756280046002869097156693848522361803041977572204227262166\", \"price\":\"0.55\", \"size\":\"30.67\", \"side\":\"BUY\", \"hash\":\"50cba005d8ec82ada3b403e3b30e866ff556bd95\", \"best_bid\":\"0.56\", \"best_ask\":\"0.57\"}, {\"asset_id\":\"41448400836309843603620980831210604935021861034693225347475867885462478926555\", \"price\":\"0.45\", \"size\":\"30.67\", \"side\":\"SELL\", \"hash\":\"be92094b30540b503f685d5994b990798d5569dd\", \"best_bid\":\"0.43\", \"best_ask\":\"0.44\"}], \"timestamp\":\"1785122358534\", \"event_type\":\"price_change\"}","received_at":"2026-07-27T03:19:18.635225Z","schema_version":"clob-market-ws.price_change.v1","sequence":null,"server_hash":null,"server_timestamp":"1785122358534","session_id":"dd162b8dca5f43ff811d304e69a06123","source":"clob_market_ws"},"received_at":"2026-07-27T03:19:18.635225Z","record_id":"66d6b7fc5c07d07186cbaea6aab7246e7c04acccf1531b7a67a5ca550e1b03e5","schema_fingerprint":"4aa3821a28b0b7c2400bc59aba4bcc0a76e971dadd19610d3ad38c768e124dc7","schema_version":"edge-lab-recorder.raw.v1","sequence":null,"source":"clob_market_ws"}
{"event_at":"2026-07-27T03:19:18.541000Z","event_fingerprint":"269153d387719387f0524451d509ca474cccdca38a0ba375eaf9ed8e5e824163","payload":{"connection_id":"c7dc2e4762f849c6b6f9306b6518dcab","event_at":"2026-07-27T03:19:18.541000Z","event_type":"price_change","frame_hash":"da7e228ead89347002c15d75d90efd929de64c25b8755ffd6633b0f39c2be0b2","frame_index":0,"kind":"data","monotonic_ns":224341976099125,"payload":{"event_type":"price_change","market":"0x717c0e8ccd4d5c7040185188fbae28be901ca589a11a94b1b38ca36a79eccfeb","price_changes":[{"asset_id":"24254094493625419915756280046002869097156693848522361803041977572204227262166","best_ask":"0.57","best_bid":"0.56","hash":"b699c0b9423bc36e63b3422f7c28513829481bd8","price":"0.04","side":"BUY","size":"628.09"},{"asset_id":"41448400836309843603620980831210604935021861034693225347475867885462478926555","best_ask":"0.44","best_bid":"0.43","hash":"05378afea4b0f2022081ccedb9842ca2d9ae6875","price":"0.96","side":"SELL","size":"628.09"}],"timestamp":"1785122358541"},"payload_hash":"861b3e8115e39916818906a467cea8928af3e3b8903afe0b83a3eefadb2f53a4","raw_frame":"{\"market\":\"0x717c0e8ccd4d5c7040185188fbae28be901ca589a11a94b1b38ca36a79eccfeb\", \"price_changes\":[{\"asset_id\":\"24254094493625419915756280046002869097156693848522361803041977572204227262166\", \"price\":\"0.04\", \"size\":\"628.09\", \"side\":\"BUY\", \"hash\":\"b699c0b9423bc36e63b3422f7c28513829481bd8\", \"best_bid\":\"0.56\", \"best_ask\":\"0.57\"}, {\"asset_id\":\"41448400836309843603620980831210604935021861034693225347475867885462478926555\", \"price\":\"0.96\", \"size\":\"628.09\", \"side\":\"SELL\", \"hash\":\"05378afea4b0f2022081ccedb9842ca2d9ae6875\", \"best_bid\":\"0.43\", \"best_ask\":\"0.44\"}], \"timestamp\":\"1785122358541\", \"event_type\":\"price_change\"}","received_at":"2026-07-27T03:19:18.638810Z","schema_version":"clob-market-ws.price_change.v1","sequence":null,"server_hash":null,"server_timestamp":"1785122358541","session_id":"dd162b8dca5f43ff811d304e69a06123","source":"clob_market_ws"},"received_at":"2026-07-27T03:19:18.638810Z","record_id":"c80d43fccdc241de205f61fd1700b76b7a45f7586ea05a49e92c06f0c45b64d8","schema_fingerprint":"4aa3821a28b0b7c2400bc59aba4bcc0a76e971dadd19610d3ad38c768e124dc7","schema_version":"edge-lab-recorder.raw.v1","sequence":null,"source":"clob_market_ws"}
{"event_at":"2026-07-27T03:19:18.546000Z","event_fingerprint":"9002bff7ee27e30680088d70630518345dd618708260f3bb66fe08ca30e0ea16","payload":{"connection_id":"c7dc2e4762f849c6b6f9306b6518dcab","event_at":"2026-07-27T03:19:18.546000Z","event_type":"price_change","frame_hash":"5a3bcd51f0dbafdd6bdff73ce57f4fd4b3eacbd14df95bf3e40b96ce88c1e0d1","frame_index":0,"kind":"data","monotonic_ns":224341979101541,"payload":{"event_type":"price_change","market":"0x717c0e8ccd4d5c7040185188fbae28be901ca589a11a94b1b38ca36a79eccfeb","price_changes":[{"asset_id":"41448400836309843603620980831210604935021861034693225347475867885462478926555","best_ask":"0.44","best_bid":"0.43","hash":"ffe0635bbfc5734c47e694c042ff4bfbc4634f45","price":"0.32","side":"BUY","size":"152"},{"asset_id":"24254094493625419915756280046002869097156693848522361803041977572204227262166","best_ask":"0.57","best_bid":"0.56","hash":"0f345bca9de2d6bbdf7aca12458d2a88ebf63942","price":"0.68","side":"SELL","size":"152"}],"timestamp":"1785122358546"},"payload_hash":"a5a92a1f90edf412e77cd23a48a369560a455f260980ceb706c0a221b2162306","raw_frame":"{\"market\":\"0x717c0e8ccd4d5c7040185188fbae28be901ca589a11a94b1b38ca36a79eccfeb\", \"price_changes\":[{\"asset_id\":\"41448400836309843603620980831210604935021861034693225347475867885462478926555\", \"price\":\"0.32\", \"size\":\"152\", \"side\":\"BUY\", \"hash\":\"ffe0635bbfc5734c47e694c042ff4bfbc4634f45\", \"best_bid\":\"0.43\", \"best_ask\":\"0.44\"}, {\"asset_id\":\"24254094493625419915756280046002869097156693848522361803041977572204227262166\", \"price\":\"0.68\", \"size\":\"152\", \"side\":\"SELL\", \"hash\":\"0f345bca9de2d6bbdf7aca12458d2a88ebf63942\", \"best_bid\":\"0.56\", \"best_ask\":\"0.57\"}], \"timestamp\":\"1785122358546\", \"event_type\":\"price_change\"}","received_at":"2026-07-27T03:19:18.641810Z","schema_version":"clob-market-ws.price_change.v1","sequence":null,"server_hash":null,"server_timestamp":"1785122358546","session_id":"dd162b8dca5f43ff811d304e69a06123","source":"clob_market_ws"},"received_at":"2026-07-27T03:19:18.641810Z","record_id":"497b783c0296aa41b024fa1a915321631af672f3e475ed327eee95d9c9f35881","schema_fingerprint":"4aa3821a28b0b7c2400bc59aba4bcc0a76e971dadd19610d3ad38c768e124dc7","schema_version":"edge-lab-recorder.raw.v1","sequence":null,"source":"clob_market_ws"}
{"event_at":"2026-07-27T03:19:18.550000Z","event_fingerprint":"098eca43b30df2c050ffbbbea5b1a913b3e1bb7e1ae7e85a17e468bfc53678ce","payload":{"connection_id":"c7dc2e4762f849c6b6f9306b6518dcab","event_at":"2026-07-27T03:19:18.550000Z","event_type":"price_change","frame_hash":"0c14db423a7c1b250e1045d12fd0d1ccc219e0f25bd82d99b3658a32c8e4a8fa","frame_index":0,"kind":"data","monotonic_ns":224341982236916,"payload":{"event_type":"price_change","market":"0x717c0e8ccd4d5c7040185188fbae28be901ca589a11a94b1b38ca36a79eccfeb","price_changes":[{"asset_id":"41448400836309843603620980831210604935021861034693225347475867885462478926555","best_ask":"0.44","best_bid":"0.43","hash":"3e8ca922c3a090bddf9b645d81eeccf2adb6e515","price":"0.32","side":"BUY","size":"182"},{"asset_id":"24254094493625419915756280046002869097156693848522361803041977572204227262166","best_ask":"0.57","best_bid":"0.56","hash":"d82125a9f673e66fa749adc43c7fff5212efb3cf","price":"0.68","side":"SELL","size":"182"}],"timestamp":"1785122358550"},"payload_hash":"d477b8a20449ecd7361041ec63cb0c16a3b77c32a10756026b5e988ef803e2db","raw_frame":"{\"market\":\"0x717c0e8ccd4d5c7040185188fbae28be901ca589a11a94b1b38ca36a79eccfeb\", \"price_changes\":[{\"asset_id\":\"41448400836309843603620980831210604935021861034693225347475867885462478926555\", \"price\":\"0.32\", \"size\":\"182\", \"side\":\"BUY\", \"hash\":\"3e8ca922c3a090bddf9b645d81eeccf2adb6e515\", \"best_bid\":\"0.43\", \"best_ask\":\"0.44\"}, {\"asset_id\":\"24254094493625419915756280046002869097156693848522361803041977572204227262166\", \"price\":\"0.68\", \"size\":\"182\", \"side\":\"SELL\", \"hash\":\"d82125a9f673e66fa749adc43c7fff5212efb3cf\", \"best_bid\":\"0.56\", \"best_ask\":\"0.57\"}], \"timestamp\":\"1785122358550\", \"event_type\":\"price_change\"}","received_at":"2026-07-27T03:19:18.644948Z","schema_version":"clob-market-ws.price_change.v1","sequence":null,"server_hash":null,"server_timestamp":"1785122358550","session_id":"dd162b8dca5f43ff811d304e69a06123","source":"clob_market_ws"},"received_at":"2026-07-27T03:19:18.644948Z","record_id":"27c83f78ea1d309f68eaf8216cf100cdce9e9eeef81f1b4f9bc63dbec9dc9b3f","schema_fingerprint":"4aa3821a28b0b7c2400bc59aba4bcc0a76e971dadd19610d3ad38c768e124dc7","schema_version":"edge-lab-recorder.raw.v1","sequence":null,"source":"clob_market_ws"}
{"event_at":"2026-07-27T03:19:18.555000Z","event_fingerprint":"25964fd3c819d34e7e1ee38f48e90fd6abaae2fda35ed9882dfd31439bdfd4ea","payload":{"connection_id":"c7dc2e4762f849c6b6f9306b6518dcab","event_at":"2026-07-27T03:19:18.555000Z","event_type":"price_change","frame_hash":"99af14514990e2303f0daa4dd6dc11b52fdbe64273cf867919811c197c5a17ff","frame_index":0,"kind":"data","monotonic_ns":224341985214708,"payload":{"event_type":"price_change","market":"0x717c0e8ccd4d5c7040185188fbae28be901ca589a11a94b1b38ca36a79eccfeb","price_changes":[{"asset_id":"41448400836309843603620980831210604935021861034693225347475867885462478926555","best_ask":"0.44","best_bid":"0.43","hash":"7c9365e9c7a9798151ad7f1de9b53a3ae5fc29ca","price":"0.32","side":"BUY","size":"212"},{"asset_id":"24254094493625419915756280046002869097156693848522361803041977572204227262166","best_ask":"0.57","best_bid":"0.56","hash":"887fcdff9be28cf46e84a5b0c4b5779b86c0e1f7","price":"0.68","side":"SELL","size":"212"}],"timestamp":"1785122358555"},"payload_hash":"bbd848aaa32eec01ef3e46c27c6c0019ed05fdf8ec121ed3fd3a84033066a69f","raw_frame":"{\"market\":\"0x717c0e8ccd4d5c7040185188fbae28be901ca589a11a94b1b38ca36a79eccfeb\", \"price_changes\":[{\"asset_id\":\"41448400836309843603620980831210604935021861034693225347475867885462478926555\", \"price\":\"0.32\", \"size\":\"212\", \"side\":\"BUY\", \"hash\":\"7c9365e9c7a9798151ad7f1de9b53a3ae5fc29ca\", \"best_bid\":\"0.43\", \"best_ask\":\"0.44\"}, {\"asset_id\":\"24254094493625419915756280046002869097156693848522361803041977572204227262166\", \"price\":\"0.68\", \"size\":\"212\", \"side\":\"SELL\", \"hash\":\"887fcdff9be28cf46e84a5b0c4b5779b86c0e1f7\", \"best_bid\":\"0.56\", \"best_ask\":\"0.57\"}], \"timestamp\":\"1785122358555\", \"event_type\":\"price_change\"}","received_at":"2026-07-27T03:19:18.647925Z","schema_version":"clob-market-ws.price_change.v1","sequence":null,"server_hash":null,"server_timestamp":"1785122358555","session_id":"dd162b8dca5f43ff811d304e69a06123","source":"clob_market_ws"},"received_at":"2026-07-27T03:19:18.647925Z","record_id":"5a6adbf6a0ee7e2a150d7dbc590640206c06be952c2bf5158c6b92a6f3686e7a","schema_fingerprint":"4aa3821a28b0b7c2400bc59aba4bcc0a76e971dadd19610d3ad38c768e124dc7","schema_version":"edge-lab-recorder.raw.v1","sequence":null,"source":"clob_market_ws"}
{"event_at":"2026-07-27T03:19:18.559000Z","event_fingerprint":"d6725c612e189d88ac3257e822cc6c36900ad7cec4c1bf21e28271ea63705e19","payload":{"connection_id":"c7dc2e4762f849c6b6f9306b6518dcab","event_at":"2026-07-27T03:19:18.559000Z","event_type":"price_change","frame_hash":"289661c4ab2fc78d684d19344a1cddc594d48a9acc28fbda4b3c0f5807fda546","frame_index":0,"kind":"data","monotonic_ns":224341988301500,"payload":{"event_type":"price_change","market":"0x717c0e8ccd4d5c7040185188fbae28be901ca589a11a94b1b38ca36a79eccfeb","price_changes":[{"asset_id":"41448400836309843603620980831210604935021861034693225347475867885462478926555","best_ask":"0.44","best_bid":"0.43","hash":"06615435bb38bd91bda587843f1c1849817a6397","price":"0.22","side":"BUY","size":"327.52"},{"asset_id":"24254094493625419915756280046002869097156693848522361803041977572204227262166","best_ask":"0.57","best_bid":"0.56","hash":"9333c9f35a3b1afdb61eabd14bbca4788fe0f212","price":"0.78","side":"SELL","size":"327.52"}],"timestamp":"1785122358559"},"payload_hash":"512c818afdf29ebd7d7e2b2c876d6b831ecf9b08d39ca5a4aee7d52ab15116ba","raw_frame":"{\"market\":\"0x717c0e8ccd4d5c7040185188fbae28be901ca589a11a94b1b38ca36a79eccfeb\", \"price_changes\":[{\"asset_id\":\"41448400836309843603620980831210604935021861034693225347475867885462478926555\", \"price\":\"0.22\", \"size\":\"327.52\", \"side\":\"BUY\", \"hash\":\"06615435bb38bd91bda587843f1c1849817a6397\", \"best_bid\":\"0.43\", \"best_ask\":\"0.44\"}, {\"asset_id\":\"24254094493625419915756280046002869097156693848522361803041977572204227262166\", \"price\":\"0.78\", \"size\":\"327.52\", \"side\":\"SELL\", \"hash\":\"9333c9f35a3b1afdb61eabd14bbca4788fe0f212\", \"best_bid\":\"0.56\", \"best_ask\":\"0.57\"}], \"timestamp\":\"1785122358559\", \"event_type\":\"price_change\"}","received_at":"2026-07-27T03:19:18.651012Z","schema_version":"clob-market-ws.price_change.v1","sequence":null,"server_hash":null,"server_timestamp":"1785122358559","session_id":"dd162b8dca5f43ff811d304e69a06123","source":"clob_market_ws"},"received_at":"2026-07-27T03:19:18.651012Z","record_id":"b639519c7dc774ba7cd4754b424d72567e9a9765e85f656da26dec772b1e447d","schema_fingerprint":"4aa3821a28b0b7c2400bc59aba4bcc0a76e971dadd19610d3ad38c768e124dc7","schema_version":"edge-lab-recorder.raw.v1","sequence":null,"source":"clob_market_ws"}
{"event_at":"2026-07-27T03:19:18.561000Z","event_fingerprint":"d5d96016400b213b00bf6e377831835c6c892cdde6fc3ab06577abb6cb59aeb9","payload":{"connection_id":"c7dc2e4762f849c6b6f9306b6518dcab","event_at":"2026-07-27T03:19:18.561000Z","event_type":"best_bid_ask","frame_hash":"17055be5efef848eb5b614d37425e948bdb2756640c0c6fa3cadb5565cbe7b2e","frame_index":0,"kind":"data","monotonic_ns":224341990963500,"payload":{"asset_id":"24254094493625419915756280046002869097156693848522361803041977572204227262166","best_ask":"0.57","best_bid":"0.55","event_type":"best_bid_ask","market":"0x717c0e8ccd4d5c7040185188fbae28be901ca589a11a94b1b38ca36a79eccfeb","spread":"0.02","timestamp":"1785122358561"},"payload_hash":"bf67ab603ff2de8019ccef5862f713b4506c0bbca6108930f579b7ffe025eb0f","raw_frame":"{\"market\":\"0x717c0e8ccd4d5c7040185188fbae28be901ca589a11a94b1b38ca36a79eccfeb\", \"asset_id\":\"24254094493625419915756280046002869097156693848522361803041977572204227262166\", \"best_bid\":\"0.55\", \"best_ask\":\"0.57\", \"spread\":\"0.02\", \"timestamp\":\"1785122358561\", \"event_type\":\"best_bid_ask\"}","received_at":"2026-07-27T03:19:18.653675Z","schema_version":"clob-market-ws.best_bid_ask.v1","sequence":null,"server_hash":null,"server_timestamp":"1785122358561","session_id":"dd162b8dca5f43ff811d304e69a06123","source":"clob_market_ws"},"received_at":"2026-07-27T03:19:18.653675Z","record_id":"13444429a35541347ea726ce7e1862e36cdb406557b2da73fc4eefce19158f3f","schema_fingerprint":"8488399f31b0337811b13b266be932db7062827c2470b78bd8e9e99bab51d17d","schema_version":"edge-lab-recorder.raw.v1","sequence":null,"source":"clob_market_ws"}
{"event_at":"2026-07-27T03:19:18.561000Z","event_fingerprint":"d696b1553385181279c82820539d4b8c002a4ad5d89b7f122549ec0767b4c632","payload":{"connection_id":"c7dc2e4762f849c6b6f9306b6518dcab","event_at":"2026-07-27T03:19:18.561000Z","event_type":"best_bid_ask","frame_hash":"aed427b17fa4fbc8a9106ee3396959f7c85f0a6a9417f44f3f1ca5bfc70fd3a0","frame_index":0,"kind":"data","monotonic_ns":224341992657458,"payload":{"asset_id":"41448400836309843603620980831210604935021861034693225347475867885462478926555","best_ask":"0.45","best_bid":"0.43","event_type":"best_bid_ask","market":"0x717c0e8ccd4d5c7040185188fbae28be901ca589a11a94b1b38ca36a79eccfeb","spread":"0.02","timestamp":"1785122358561"},"payload_hash":"85671947775775305249e4c0cc85af4d8655b1aa15dce496ef4c0fe92e10bef0","raw_frame":"{\"market\":\"0x717c0e8ccd4d5c7040185188fbae28be901ca589a11a94b1b38ca36a79eccfeb\", \"asset_id\":\"41448400836309843603620980831210604935021861034693225347475867885462478926555\", \"best_bid\":\"0.43\", \"best_ask\":\"0.45\", \"spread\":\"0.02\", \"timestamp\":\"1785122358561\", \"event_type\":\"best_bid_ask\"}","received_at":"2026-07-27T03:19:18.655370Z","schema_version":"clob-market-ws.best_bid_ask.v1","sequence":null,"server_hash":null,"server_timestamp":"1785122358561","session_id":"dd162b8dca5f43ff811d304e69a06123","source":"clob_market_ws"},"received_at":"2026-07-27T03:19:18.655370Z","record_id":"0536b89fd640a678a98ea424dc85e905b3d377c98c1877cfa20592997d74d98a","schema_fingerprint":"8488399f31b0337811b13b266be932db7062827c2470b78bd8e9e99bab51d17d","schema_version":"edge-lab-recorder.raw.v1","sequence":null,"source":"clob_market_ws"}
{"event_at":"2026-07-27T03:19:18.561000Z","event_fingerprint":"9d4526d888a35d822641403b7cef581b602e88f2d90c1703eb97d2a8ed09677b","payload":{"connection_id":"c7dc2e4762f849c6b6f9306b6518dcab","event_at":"2026-07-27T03:19:18.561000Z","event_type":"price_change","frame_hash":"e451674d427d0217097676c84134276bb8d39301b02a9239ad5cda609b52b957","frame_index":0,"kind":"data","monotonic_ns":224341995576958,"payload":{"event_type":"price_change","market":"0x717c0e8ccd4d5c7040185188fbae28be901ca589a11a94b1b38ca36a79eccfeb","price_changes":[{"asset_id":"24254094493625419915756280046002869097156693848522361803041977572204227262166","best_ask":"0.57","best_bid":"0.55","hash":"b0e8836ab5d240df22c283df159c2cdea23519d0","price":"0.56","side":"BUY","size":"0"},{"asset_id":"41448400836309843603620980831210604935021861034693225347475867885462478926555","best_ask":"0.45","best_bid":"0.43","hash":"fb9a97758ceb0645e18f21754d7e5e173ceabdee","price":"0.44","side":"SELL","size":"0"}],"timestamp":"1785122358561"},"payload_hash":"49e5ef27dbdab244c42c62bf449ef1cd44ae07e4735de06a7e8247cc3141d064","raw_frame":"{\"market\":\"0x717c0e8ccd4d5c7040185188fbae28be901ca589a11a94b1b38ca36a79eccfeb\", \"price_changes\":[{\"asset_id\":\"24254094493625419915756280046002869097156693848522361803041977572204227262166\", \"price\":\"0.56\", \"size\":\"0\", \"side\":\"BUY\", \"hash\":\"b0e8836ab5d240df22c283df159c2cdea23519d0\", \"best_bid\":\"0.55\", \"best_ask\":\"0.57\"}, {\"asset_id\":\"41448400836309843603620980831210604935021861034693225347475867885462478926555\", \"price\":\"0.44\", \"size\":\"0\", \"side\":\"SELL\", \"hash\":\"fb9a97758ceb0645e18f21754d7e5e173ceabdee\", \"best_bid\":\"0.43\", \"best_ask\":\"0.45\"}], \"timestamp\":\"1785122358561\", \"event_type\":\"price_change\"}","received_at":"2026-07-27T03:19:18.658286Z","schema_version":"clob-market-ws.price_change.v1","sequence":null,"server_hash":null,"server_timestamp":"1785122358561","session_id":"dd162b8dca5f43ff811d304e69a06123","source":"clob_market_ws"},"received_at":"2026-07-27T03:19:18.658286Z","record_id":"605c17b373d568c5c463f16d99f6403c2cd83af3df215fda674c6733cf282c9a","schema_fingerprint":"4aa3821a28b0b7c2400bc59aba4bcc0a76e971dadd19610d3ad38c768e124dc7","schema_version":"edge-lab-recorder.raw.v1","sequence":null,"source":"clob_market_ws"}
{"event_at":"2026-07-27T03:19:18.561000Z","event_fingerprint":"9babbe039706ad155733c965847df28582f6efa01ce4ebb19dac8587f75edeb6","payload":{"connection_id":"c7dc2e4762f849c6b6f9306b6518dcab","event_at":"2026-07-27T03:19:18.561000Z","event_type":"price_change","frame_hash":"73dbd4566b80546eeb009c4a9baeb3b09ab92e30e7bb27b9ecd64977ab3baf12","frame_index":0,"kind":"data","monotonic_ns":224341998733708,"payload":{"event_type":"price_change","market":"0x717c0e8ccd4d5c7040185188fbae28be901ca589a11a94b1b38ca36a79eccfeb","price_changes":[{"asset_id":"24254094493625419915756280046002869097156693848522361803041977572204227262166","best_ask":"0.57","best_bid":"0.55","hash":"b0e8836ab5d240df22c283df159c2cdea23519d0","price":"0.55","side":"BUY","size":"18.6"},{"asset_id":"41448400836309843603620980831210604935021861034693225347475867885462478926555","best_ask":"0.45","best_bid":"0.43","hash":"fb9a97758ceb0645e18f21754d7e5e173ceabdee","price":"0.45","side":"SELL","size":"18.6"}],"timestamp":"1785122358561"},"payload_hash":"d04deefc8634049d6a9d99dbd6557c9aceb93b375d82360af55ee1ed9a9b8ca4","raw_frame":"{\"market\":\"0x717c0e8ccd4d5c7040185188fbae28be901ca589a11a94b1b38ca36a79eccfeb\", \"price_changes\":[{\"asset_id\":\"24254094493625419915756280046002869097156693848522361803041977572204227262166\", \"price\":\"0.55\", \"size\":\"18.6\", \"side\":\"BUY\", \"hash\":\"b0e8836ab5d240df22c283df159c2cdea23519d0\", \"best_bid\":\"0.55\", \"best_ask\":\"0.57\"}, {\"asset_id\":\"41448400836309843603620980831210604935021861034693225347475867885462478926555\", \"price\":\"0.45\", \"size\":\"18.6\", \"side\":\"SELL\", \"hash\":\"fb9a97758ceb0645e18f21754d7e5e173ceabdee\", \"best_bid\":\"0.43\", \"best_ask\":\"0.45\"}], \"timestamp\":\"1785122358561\", \"event_type\":\"price_change\"}","received_at":"2026-07-27T03:19:18.661444Z","schema_version":"clob-market-ws.price_change.v1","sequence":null,"server_hash":null,"server_timestamp":"1785122358561","session_id":"dd162b8dca5f43ff811d304e69a06123","source":"clob_market_ws"},"received_at":"2026-07-27T03:19:18.661444Z","record_id":"af4602f265e73b7c975dd37fd18e28d6f21d996caf130215ddf780294e65b6fb","schema_fingerprint":"4aa3821a28b0b7c2400bc59aba4bcc0a76e971dadd19610d3ad38c768e124dc7","schema_version":"edge-lab-recorder.raw.v1","sequence":null,"source":"clob_market_ws"}
{"event_at":"2026-07-27T03:19:18.561000Z","event_fingerprint":"a7c0eb5f4681ac639b5d1b5713854c806fd228df735c160d5b73dbd7be3ceeb1","payload":{"connection_id":"c7dc2e4762f849c6b6f9306b6518dcab","event_at":"2026-07-27T03:19:18.561000Z","event_type":"price_change","frame_hash":"2fb5f8466e8dd42b21bfd2c8beceb04ee903cbffb94df074fb873fc21ae7a6ac","frame_index":0,"kind":"data","monotonic_ns":224342001672333,"payload":{"event_type":"price_change","market":"0x717c0e8ccd4d5c7040185188fbae28be901ca589a11a94b1b38ca36a79eccfeb","price_changes":[{"asset_id":"24254094493625419915756280046002869097156693848522361803041977572204227262166","best_ask":"0.57","best_bid":"0.55","hash":"515bce64cb7451a8750fff2117575ff2abbb981f","price":"0.49","side":"BUY","size":"27"},{"asset_id":"41448400836309843603620980831210604935021861034693225347475867885462478926555","best_ask":"0.45","best_bid":"0.43","hash":"e1332d7370a3927dff397ae2bfa3534a8887d1af","price":"0.51","side":"SELL","size":"27"}],"timestamp":"1785122358561"},"payload_hash":"129b3e31d84c9d7a0620d3b2245bf9bf7c6818f189ff492bf1ab33fd37bbffa2","raw_frame":"{\"market\":\"0x717c0e8ccd4d5c7040185188fbae28be901ca589a11a94b1b38ca36a79eccfeb\", \"price_changes\":[{\"asset_id\":\"24254094493625419915756280046002869097156693848522361803041977572204227262166\", \"price\":\"0.49\", \"size\":\"27\", \"side\":\"BUY\", \"hash\":\"515bce64cb7451a8750fff2117575ff2abbb981f\", \"best_bid\":\"0.55\", \"best_ask\":\"0.57\"}, {\"asset_id\":\"41448400836309843603620980831210604935021861034693225347475867885462478926555\", \"price\":\"0.51\", \"size\":\"27\", \"side\":\"SELL\", \"hash\":\"e1332d7370a3927dff397ae2bfa3534a8887d1af\", \"best_bid\":\"0.43\", \"best_ask\":\"0.45\"}], \"timestamp\":\"1785122358561\", \"event_type\":\"price_change\"}","received_at":"2026-07-27T03:19:18.664383Z","schema_version":"clob-market-ws.price_change.v1","sequence":null,"server_hash":null,"server_timestamp":"1785122358561","session_id":"dd162b8dca5f43ff811d304e69a06123","source":"clob_market_ws"},"received_at":"2026-07-27T03:19:18.664383Z","record_id":"c59f5106a68f7819b0dc6effc2429182c978c299b7cde13c412df84b639dd49e","schema_fingerprint":"4aa3821a28b0b7c2400bc59aba4bcc0a76e971dadd19610d3ad38c768e124dc7","schema_version":"edge-lab-recorder.raw.v1","sequence":null,"source":"clob_market_ws"}
{"event_at":"2026-07-27T03:19:18.562000Z","event_fingerprint":"51cf594d86d931d05e5f850936b00b82a5d409209db5a1066d65fa9750aab630","payload":{"connection_id":"c7dc2e4762f849c6b6f9306b6518dcab","event_at":"2026-07-27T03:19:18.562000Z","event_type":"price_change","frame_hash":"eea34ed399892faddd5a8c17442fed892a503fc32587836babd3202cf86b230c","frame_index":0,"kind":"data","monotonic_ns":224342004568541,"payload":{"event_type":"price_change","market":"0x717c0e8ccd4d5c7040185188fbae28be901ca589a11a94b1b38ca36a79eccfeb","price_changes":[{"asset_id":"41448400836309843603620980831210604935021861034693225347475867885462478926555","best_ask":"0.45","best_bid":"0.43","hash":"164798ef083aac63a33c118d12b2f79baedcba5f","price":"0.36","side":"BUY","size":"38.96"},{"asset_id":"24254094493625419915756280046002869097156693848522361803041977572204227262166","best_ask":"0.57","best_bid":"0.55","hash":"6be4b72b2360766975c92c46f495038543898dae","price":"0.64","side":"SELL","size":"38.96"}],"timestamp":"1785122358562"},"payload_hash":"3bfb4a9b1e8b23754dc2f74460b4a85078e6d4b2686ff9f1a1eaa420db6ba972","raw_frame":"{\"market\":\"0x717c0e8ccd4d5c7040185188fbae28be901ca589a11a94b1b38ca36a79eccfeb\", \"price_changes\":[{\"asset_id\":\"41448400836309843603620980831210604935021861034693225347475867885462478926555\", \"price\":\"0.36\", \"size\":\"38.96\", \"side\":\"BUY\", \"hash\":\"164798ef083aac63a33c118d12b2f79baedcba5f\", \"best_bid\":\"0.43\", \"best_ask\":\"0.45\"}, {\"asset_id\":\"24254094493625419915756280046002869097156693848522361803041977572204227262166\", \"price\":\"0.64\", \"size\":\"38.96\", \"side\":\"SELL\", \"hash\":\"6be4b72b2360766975c92c46f495038543898dae\", \"best_bid\":\"0.55\", \"best_ask\":\"0.57\"}], \"timestamp\":\"1785122358562\", \"event_type\":\"price_change\"}","received_at":"2026-07-27T03:19:18.667279Z","schema_version":"clob-market-ws.price_change.v1","sequence":null,"server_hash":null,"server_timestamp":"1785122358562","session_id":"dd162b8dca5f43ff811d304e69a06123","source":"clob_market_ws"},"received_at":"2026-07-27T03:19:18.667279Z","record_id":"0c2d1dfa9c0d8bb3a5d7947c0d612d2b9b9d41fd9b80493f81e7cf071628303f","schema_fingerprint":"4aa3821a28b0b7c2400bc59aba4bcc0a76e971dadd19610d3ad38c768e124dc7","schema_version":"edge-lab-recorder.raw.v1","sequence":null,"source":"clob_market_ws"}
{"event_at":"2026-07-27T03:19:18.563000Z","event_fingerprint":"f013567ea680e938e3de677ad4add36dc5e1f6bd079c6de8da505b3fdf3981e8","payload":{"connection_id":"c7dc2e4762f849c6b6f9306b6518dcab","event_at":"2026-07-27T03:19:18.563000Z","event_type":"price_change","frame_hash":"4cc018c9319a1975407946145f72bdd561fe3b0b279fa86b4292931fd4690fdc","frame_index":0,"kind":"data","monotonic_ns":224342006785375,"payload":{"event_type":"price_change","market":"0x717c0e8ccd4d5c7040185188fbae28be901ca589a11a94b1b38ca36a79eccfeb","price_changes":[{"asset_id":"41448400836309843603620980831210604935021861034693225347475867885462478926555","best_ask":"0.45","best_bid":"0.43","hash":"975e59cb088f6b8393da36cbd5c7d2ca70b7b13d","price":"0.37","side":"BUY","size":"19.79"},{"asset_id":"24254094493625419915756280046002869097156693848522361803041977572204227262166","best_ask":"0.57","best_bid":"0.55","hash":"9b60afd1c196f3391413026e917d8e4bd5a19b45","price":"0.63","side":"SELL","size":"19.79"}],"timestamp":"1785122358563"},"payload_hash":"b268cf192315ac3634423b18aff4ad6783efa05dd40c158a2c04b412e24a1f5f","raw_frame":"{\"market\":\"0x717c0e8ccd4d5c7040185188fbae28be901ca589a11a94b1b38ca36a79eccfeb\", \"price_changes\":[{\"asset_id\":\"41448400836309843603620980831210604935021861034693225347475867885462478926555\", \"price\":\"0.37\", \"size\":\"19.79\", \"side\":\"BUY\", \"hash\":\"975e59cb088f6b8393da36cbd5c7d2ca70b7b13d\", \"best_bid\":\"0.43\", \"best_ask\":\"0.45\"}, {\"asset_id\":\"24254094493625419915756280046002869097156693848522361803041977572204227262166\", \"price\":\"0.63\", \"size\":\"19.79\", \"side\":\"SELL\", \"hash\":\"9b60afd1c196f3391413026e917d8e4bd5a19b45\", \"best_bid\":\"0.55\", \"best_ask\":\"0.57\"}], \"timestamp\":\"1785122358563\", \"event_type\":\"price_change\"}","received_at":"2026-07-27T03:19:18.669496Z","schema_version":"clob-market-ws.price_change.v1","sequence":null,"server_hash":null,"server_timestamp":"1785122358563","session_id":"dd162b8dca5f43ff811d304e69a06123","source":"clob_market_ws"},"received_at":"2026-07-27T03:19:18.669496Z","record_id":"4980a085fc45419c57a52294e5450c4b76509977343835dd6b072f0ae1ae9102","schema_fingerprint":"4aa3821a28b0b7c2400bc59aba4bcc0a76e971dadd19610d3ad38c768e124dc7","schema_version":"edge-lab-recorder.raw.v1","sequence":null,"source":"clob_market_ws"}
{"event_at":"2026-07-27T03:19:18.565000Z","event_fingerprint":"6c4c5f72c0a69c8fcfbe07c9f993727c18e17f53cab9bf14a5bd779ce0651225","payload":{"connection_id":"c7dc2e4762f849c6b6f9306b6518dcab","event_at":"2026-07-27T03:19:18.565000Z","event_type":"price_change","frame_hash":"ab7623020ffaadb1752d954853a38e6476c7b9da5b453be579b5a0c3f7163346","frame_index":0,"kind":"data","monotonic_ns":224342009741291,"payload":{"event_type":"price_change","market":"0x717c0e8ccd4d5c7040185188fbae28be901ca589a11a94b1b38ca36a79eccfeb","price_changes":[{"asset_id":"24254094493625419915756280046002869097156693848522361803041977572204227262166","best_ask":"0.57","best_bid":"0.55","hash":"0885a91106b2e7fff2958db77a329176146f889a","price":"0.37","side":"BUY","size":"107.99"},{"asset_id":"41448400836309843603620980831210604935021861034693225347475867885462478926555","best_ask":"0.45","best_bid":"0.43","hash":"c4dde8bc5fcbeedc6b0e3721ba67a04e6539ba64","price":"0.63","side":"SELL","size":"107.99"}],"timestamp":"1785122358565"},"payload_hash":"689ad520547e994e6326c2057a8c03e97aaab5cf1d5f71732ae2b35ae1c31c8d","raw_frame":"{\"market\":\"0x717c0e8ccd4d5c7040185188fbae28be901ca589a11a94b1b38ca36a79eccfeb\", \"price_changes\":[{\"asset_id\":\"24254094493625419915756280046002869097156693848522361803041977572204227262166\", \"price\":\"0.37\", \"size\":\"107.99\", \"side\":\"BUY\", \"hash\":\"0885a91106b2e7fff2958db77a329176146f889a\", \"best_bid\":\"0.55\", \"best_ask\":\"0.57\"}, {\"asset_id\":\"41448400836309843603620980831210604935021861034693225347475867885462478926555\", \"price\":\"0.63\", \"size\":\"107.99\", \"side\":\"SELL\", \"hash\":\"c4dde8bc5fcbeedc6b0e3721ba67a04e6539ba64\", \"best_bid\":\"0.43\", \"best_ask\":\"0.45\"}], \"timestamp\":\"1785122358565\", \"event_type\":\"price_change\"}","received_at":"2026-07-27T03:19:18.672452Z","schema_version":"clob-market-ws.price_change.v1","sequence":null,"server_hash":null,"server_timestamp":"1785122358565","session_id":"dd162b8dca5f43ff811d304e69a06123","source":"clob_market_ws"},"received_at":"2026-07-27T03:19:18.672452Z","record_id":"1703972f2c56ca065734ddde784e8cff6d64212369b5eaf8339af593f71626f9","schema_fingerprint":"4aa3821a28b0b7c2400bc59aba4bcc0a76e971dadd19610d3ad38c768e124dc7","schema_version":"edge-lab-recorder.raw.v1","sequence":null,"source":"clob_market_ws"}
{"event_at":"2026-07-27T03:19:18.566000Z","event_fingerprint":"48779afa7b0496d2c51feb20cfc3d14e790cdb843c4bea880c83bd598c8d1c11","payload":{"connection_id":"c7dc2e4762f849c6b6f9306b6518dcab","event_at":"2026-07-27T03:19:18.566000Z","event_type":"price_change","frame_hash":"34761e84c71a1d74f9a76cadc6be05bb9baa1645df2fcf4696e2e1359b371b7c","frame_index":0,"kind":"data","monotonic_ns":224342012423041,"payload":{"event_type":"price_change","market":"0x717c0e8ccd4d5c7040185188fbae28be901ca589a11a94b1b38ca36a79eccfeb","price_changes":[{"asset_id":"41448400836309843603620980831210604935021861034693225347475867885462478926555","best_ask":"0.45","best_bid":"0.43","hash":"04152bdb2762cee41ada95d12409a0e07e03f27a","price":"0.22","side":"BUY","size":"176.01"},{"asset_id":"24254094493625419915756280046002869097156693848522361803041977572204227262166","best_ask":"0.57","best_bid":"0.55","hash":"3d1a8fd26cbe2bb69fe15b08804c2157d41aeb31","price":"0.78","side":"SELL","size":"176.01"}],"timestamp":"1785122358566"},"payload_hash":"e27545a6b75c628ea7c67ad93082a7a6d15e194c447498a6086e79eab74b91b5","raw_frame":"{\"market\":\"0x717c0e8ccd4d5c7040185188fbae28be901ca589a11a94b1b38ca36a79eccfeb\", \"price_changes\":[{\"asset_id\":\"41448400836309843603620980831210604935021861034693225347475867885462478926555\", \"price\":\"0.22\", \"size\":\"176.01\", \"side\":\"BUY\", \"hash\":\"04152bdb2762cee41ada95d12409a0e07e03f27a\", \"best_bid\":\"0.43\", \"best_ask\":\"0.45\"}, {\"asset_id\":\"24254094493625419915756280046002869097156693848522361803041977572204227262166\", \"price\":\"0.78\", \"size\":\"176.01\", \"side\":\"SELL\", \"hash\":\"3d1a8fd26cbe2bb69fe15b08804c2157d41aeb31\", \"best_bid\":\"0.55\", \"best_ask\":\"0.57\"}], \"timestamp\":\"1785122358566\", \"event_type\":\"price_change\"}","received_at":"2026-07-27T03:19:18.675129Z","schema_version":"clob-market-ws.price_change.v1","sequence":null,"server_hash":null,"server_timestamp":"1785122358566","session_id":"dd162b8dca5f43ff811d304e69a06123","source":"clob_market_ws"},"received_at":"2026-07-27T03:19:18.675129Z","record_id":"3e65f04ae78fa3d65ec125a70c179a95b6fd72dc4f20c994ea9709542bbc9caf","schema_fingerprint":"4aa3821a28b0b7c2400bc59aba4bcc0a76e971dadd19610d3ad38c768e124dc7","schema_version":"edge-lab-recorder.raw.v1","sequence":null,"source":"clob_market_ws"}
{"event_at":"2026-07-27T03:19:18.568000Z","event_fingerprint":"9d408e0f7a665971ad17e171a9d6d1e4b8d40e02c6ac55a5029b8351a7cf75ac","payload":{"connection_id":"c7dc2e4762f849c6b6f9306b6518dcab","event_at":"2026-07-27T03:19:18.568000Z","event_type":"price_change","frame_hash":"449ce8d65471a26c486b06a839c8540f0c82894f4f250e5cf77ff72591a44def","frame_index":0,"kind":"data","monotonic_ns":224342015448041,"payload":{"event_type":"price_change","market":"0x717c0e8ccd4d5c7040185188fbae28be901ca589a11a94b1b38ca36a79eccfeb","price_changes":[{"asset_id":"41448400836309843603620980831210604935021861034693225347475867885462478926555","best_ask":"0.45","best_bid":"0.43","hash":"f44b4c553c48c404460b0bd85ae9ee8abdf02e94","price":"0.22","side":"BUY","size":"24.5"},{"asset_id":"24254094493625419915756280046002869097156693848522361803041977572204227262166","best_ask":"0.57","best_bid":"0.55","hash":"b4847b225b85c78c9a7de57df0c1328467c05817","price":"0.78","side":"SELL","size":"24.5"}],"timestamp":"1785122358568"},"payload_hash":"1738e3278e37f0b9adbf45e4f44915bfa50d660640bb51927c96b2b5f712131c","raw_frame":"{\"market\":\"0x717c0e8ccd4d5c7040185188fbae28be901ca589a11a94b1b38ca36a79eccfeb\", \"price_changes\":[{\"asset_id\":\"41448400836309843603620980831210604935021861034693225347475867885462478926555\", \"price\":\"0.22\", \"size\":\"24.5\", \"side\":\"BUY\", \"hash\":\"f44b4c553c48c404460b0bd85ae9ee8abdf02e94\", \"best_bid\":\"0.43\", \"best_ask\":\"0.45\"}, {\"asset_id\":\"24254094493625419915756280046002869097156693848522361803041977572204227262166\", \"price\":\"0.78\", \"size\":\"24.5\", \"side\":\"SELL\", \"hash\":\"b4847b225b85c78c9a7de57df0c1328467c05817\", \"best_bid\":\"0.55\", \"best_ask\":\"0.57\"}], \"timestamp\":\"1785122358568\", \"event_type\":\"price_change\"}","received_at":"2026-07-27T03:19:18.678159Z","schema_version":"clob-market-ws.price_change.v1","sequence":null,"server_hash":null,"server_timestamp":"1785122358568","session_id":"dd162b8dca5f43ff811d304e69a06123","source":"clob_market_ws"},"received_at":"2026-07-27T03:19:18.678159Z","record_id":"b941a1cbc40d49349f86c795997e5709ecf6663f20d116743807d501a129b87e","schema_fingerprint":"4aa3821a28b0b7c2400bc59aba4bcc0a76e971dadd19610d3ad38c768e124dc7","schema_version":"edge-lab-recorder.raw.v1","sequence":null,"source":"clob_market_ws"}
{"event_at":"2026-07-27T03:19:18.571000Z","event_fingerprint":"489f2a35d0d2ccccf73fc85028b32c27e3cbb81545262d71e17bbfbb57f140a1","payload":{"connection_id":"c7dc2e4762f849c6b6f9306b6518dcab","event_at":"2026-07-27T03:19:18.571000Z","event_type":"price_change","frame_hash":"93db537bde2e14b179e988cdb802065f135e0963d6330dc1eeec70d555df671f","frame_index":0,"kind":"data","monotonic_ns":224342018330125,"payload":{"event_type":"price_change","market":"0x717c0e8ccd4d5c7040185188fbae28be901ca589a11a94b1b38ca36a79eccfeb","price_changes":[{"asset_id":"24254094493625419915756280046002869097156693848522361803041977572204227262166","best_ask":"0.57","best_bid":"0.55","hash":"c67f0fe8d99a708e08533355ef9622ebbe788336","price":"0.37","side":"BUY","size":"17.9"},{"asset_id":"41448400836309843603620980831210604935021861034693225347475867885462478926555","best_ask":"0.45","best_bid":"0.43","hash":"56d72799b5129fa8fa91303f9e023fa014b9585b","price":"0.63","side":"SELL","size":"17.9"}],"timestamp":"1785122358571"},"payload_hash":"f88113a7b6623a5d3e4de814fbf5ace5d12fc7cfc6a1ff20602599369969a571","raw_frame":"{\"market\":\"0x717c0e8ccd4d5c7040185188fbae28be901ca589a11a94b1b38ca36a79eccfeb\", \"price_changes\":[{\"asset_id\":\"24254094493625419915756280046002869097156693848522361803041977572204227262166\", \"price\":\"0.37\", \"size\":\"17.9\", \"side\":\"BUY\", \"hash\":\"c67f0fe8d99a708e08533355ef9622ebbe788336\", \"best_bid\":\"0.55\", \"best_ask\":\"0.57\"}, {\"asset_id\":\"41448400836309843603620980831210604935021861034693225347475867885462478926555\", \"price\":\"0.63\", \"size\":\"17.9\", \"side\":\"SELL\", \"hash\":\"56d72799b5129fa8fa91303f9e023fa014b9585b\", \"best_bid\":\"0.43\", \"best_ask\":\"0.45\"}], \"timestamp\":\"1785122358571\", \"event_type\":\"price_change\"}","received_at":"2026-07-27T03:19:18.681039Z","schema_version":"clob-market-ws.price_change.v1","sequence":null,"server_hash":null,"server_timestamp":"1785122358571","session_id":"dd162b8dca5f43ff811d304e69a06123","source":"clob_market_ws"},"received_at":"2026-07-27T03:19:18.681039Z","record_id":"f8e227581c8e54a60017e20ad45c97db630a7c0ac7743c59c523ba188d2c1f25","schema_fingerprint":"4aa3821a28b0b7c2400bc59aba4bcc0a76e971dadd19610d3ad38c768e124dc7","schema_version":"edge-lab-recorder.raw.v1","sequence":null,"source":"clob_market_ws"}
{"event_at":"2026-07-27T03:19:18.575000Z","event_fingerprint":"f4d162ed1ce224565ca188c444fdc041853eb1b821cdc8f93e0a499440d3736a","payload":{"connection_id":"c7dc2e4762f849c6b6f9306b6518dcab","event_at":"2026-07-27T03:19:18.575000Z","event_type":"price_change","frame_hash":"d48ce82b2538a2b18f720a8865b6f73dcc67706943ec0919b003fdade767a80c","frame_index":0,"kind":"data","monotonic_ns":224342021318708,"payload":{"event_type":"price_change","market":"0x717c0e8ccd4d5c7040185188fbae28be901ca589a11a94b1b38ca36a79eccfeb","price_changes":[{"asset_id":"24254094493625419915756280046002869097156693848522361803041977572204227262166","best_ask":"0.57","best_bid":"0.55","hash":"b15d28a0074799a9b8a1ae015bfa42fe597444b8","price":"0.5","side":"BUY","size":"181"},{"asset_id":"41448400836309843603620980831210604935021861034693225347475867885462478926555","best_ask":"0.45","best_bid":"0.43","hash":"8725e41b2c2caf112ed81effb5650ca5c88f6cd4","price":"0.5","side":"SELL","size":"181"}],"timestamp":"1785122358575"},"payload_hash":"5f984e1432f4e4a518858cc79f83af8bab89265c543ba4f07fb9c2320344c73c","raw_frame":"{\"market\":\"0x717c0e8ccd4d5c7040185188fbae28be901ca589a11a94b1b38ca36a79eccfeb\", \"price_changes\":[{\"asset_id\":\"24254094493625419915756280046002869097156693848522361803041977572204227262166\", \"price\":\"0.5\", \"size\":\"181\", \"side\":\"BUY\", \"hash\":\"b15d28a0074799a9b8a1ae015bfa42fe597444b8\", \"best_bid\":\"0.55\", \"best_ask\":\"0.57\"}, {\"asset_id\":\"41448400836309843603620980831210604935021861034693225347475867885462478926555\", \"price\":\"0.5\", \"size\":\"181\", \"side\":\"SELL\", \"hash\":\"8725e41b2c2caf112ed81effb5650ca5c88f6cd4\", \"best_bid\":\"0.43\", \"best_ask\":\"0.45\"}], \"timestamp\":\"1785122358575\", \"event_type\":\"price_change\"}","received_at":"2026-07-27T03:19:18.684029Z","schema_version":"clob-market-ws.price_change.v1","sequence":null,"server_hash":null,"server_timestamp":"1785122358575","session_id":"dd162b8dca5f43ff811d304e69a06123","source":"clob_market_ws"},"received_at":"2026-07-27T03:19:18.684029Z","record_id":"52ae8901852366bdbf98d4ba295b912ccc39304c6ebf1804303948b64a061cd8","schema_fingerprint":"4aa3821a28b0b7c2400bc59aba4bcc0a76e971dadd19610d3ad38c768e124dc7","schema_version":"edge-lab-recorder.raw.v1","sequence":null,"source":"clob_market_ws"}
{"event_at":"2026-07-27T03:19:18.575000Z","event_fingerprint":"cb36d1d9783f14d2f9f2825408b7ca6ffcfbbd20f271020e201b06f2a001e2b3","payload":{"connection_id":"c7dc2e4762f849c6b6f9306b6518dcab","event_at":"2026-07-27T03:19:18.575000Z","event_type":"best_bid_ask","frame_hash":"fdb521fbdda923689d00940d2e16f994d0a9bb388854d847b91fcc6adc0b7477","frame_index":0,"kind":"data","monotonic_ns":224342024118583,"payload":{"asset_id":"24254094493625419915756280046002869097156693848522361803041977572204227262166","best_ask":"0.56","best_bid":"0.55","event_type":"best_bid_ask","market":"0x717c0e8ccd4d5c7040185188fbae28be901ca589a11a94b1b38ca36a79eccfeb","spread":"0.01","timestamp":"1785122358575"},"payload_hash":"600e9abae965b7009590b72af9689b90a76ccaffd6219117547421bb79911306","raw_frame":"{\"market\":\"0x717c0e8ccd4d5c7040185188fbae28be901ca589a11a94b1b38ca36a79eccfeb\", \"asset_id\":\"24254094493625419915756280046002869097156693848522361803041977572204227262166\", \"best_bid\":\"0.55\", \"best_ask\":\"0.56\", \"spread\":\"0.01\", \"timestamp\":\"1785122358575\", \"event_type\":\"best_bid_ask\"}","received_at":"2026-07-27T03:19:18.686829Z","schema_version":"clob-market-ws.best_bid_ask.v1","sequence":null,"server_hash":null,"server_timestamp":"1785122358575","session_id":"dd162b8dca5f43ff811d304e69a06123","source":"clob_market_ws"},"received_at":"2026-07-27T03:19:18.686829Z","record_id":"0e928ad6e551510d1af21d535d5f7d84e78e55c6a55da273322557646b3da254","schema_fingerprint":"8488399f31b0337811b13b266be932db7062827c2470b78bd8e9e99bab51d17d","schema_version":"edge-lab-recorder.raw.v1","sequence":null,"source":"clob_market_ws"}
{"event_at":"2026-07-27T03:19:18.575000Z","event_fingerprint":"39d1dfd78edc89fb13acb0eea36315af50bbd98d4b10c7c6af3c006622e16cc9","payload":{"connection_id":"c7dc2e4762f849c6b6f9306b6518dcab","event_at":"2026-07-27T03:19:18.575000Z","event_type":"best_bid_ask","frame_hash":"23a629af545209e5061c3bd010fc0803af24d313bc96a28e286f79b696beb48b","frame_index":0,"kind":"data","monotonic_ns":224342026526208,"payload":{"asset_id":"41448400836309843603620980831210604935021861034693225347475867885462478926555","best_ask":"0.45","best_bid":"0.44","event_type":"best_bid_ask","market":"0x717c0e8ccd4d5c7040185188fbae28be901ca589a11a94b1b38ca36a79eccfeb","spread":"0.01","timestamp":"1785122358575"},"payload_hash":"a0658b6add5ec964d2d9c7c56ab4a6a68669d8141e0a37d310ac3f269f57ae25","raw_frame":"{\"market\":\"0x717c0e8ccd4d5c7040185188fbae28be901ca589a11a94b1b38ca36a79eccfeb\", \"asset_id\":\"41448400836309843603620980831210604935021861034693225347475867885462478926555\", \"best_bid\":\"0.44\", \"best_ask\":\"0.45\", \"spread\":\"0.01\", \"timestamp\":\"1785122358575\", \"event_type\":\"best_bid_ask\"}","received_at":"2026-07-27T03:19:18.689236Z","schema_version":"clob-market-ws.best_bid_ask.v1","sequence":null,"server_hash":null,"server_timestamp":"1785122358575","session_id":"dd162b8dca5f43ff811d304e69a06123","source":"clob_market_ws"},"received_at":"2026-07-27T03:19:18.689236Z","record_id":"730b0595da84c21ede120aff7198121aff7f650055ca50f6fd5a7e307b7690a4","schema_fingerprint":"8488399f31b0337811b13b266be932db7062827c2470b78bd8e9e99bab51d17d","schema_version":"edge-lab-recorder.raw.v1","sequence":null,"source":"clob_market_ws"}
{"event_at":"2026-07-27T03:19:18.575000Z","event_fingerprint":"a59ef7d97c58fd193ae586f682e1dae47098a8dfdeea12423dc952060302d0dc","payload":{"connection_id":"c7dc2e4762f849c6b6f9306b6518dcab","event_at":"2026-07-27T03:19:18.575000Z","event_type":"price_change","frame_hash":"7fd0ccc36162436bbf0b4b20d9b3534cc9a839b30c0470fdf5859ceca21e6860","frame_index":0,"kind":"data","monotonic_ns":224342029351000,"payload":{"event_type":"price_change","market":"0x717c0e8ccd4d5c7040185188fbae28be901ca589a11a94b1b38ca36a79eccfeb","price_changes":[{"asset_id":"41448400836309843603620980831210604935021861034693225347475867885462478926555","best_ask":"0.45","best_bid":"0.44","hash":"3352cc51d6790ddc81df3ff514f7a20cdf7d79e6","price":"0.44","side":"BUY","size":"40"},{"asset_id":"24254094493625419915756280046002869097156693848522361803041977572204227262166","best_ask":"0.56","best_bid":"0.55","hash":"06ec1b805b3010393681959c8833c7386f4e9eb1","price":"0.56","side":"SELL","size":"40"}],"timestamp":"1785122358575"},"payload_hash":"8705c28cb7cec3f6af815020bf69e396b670e8ebad9dc1b5fd0515d26461fe19","raw_frame":"{\"market\":\"0x717c0e8ccd4d5c7040185188fbae28be901ca589a11a94b1b38ca36a79eccfeb\", \"price_changes\":[{\"asset_id\":\"41448400836309843603620980831210604935021861034693225347475867885462478926555\", \"price\":\"0.44\", \"size\":\"40\", \"side\":\"BUY\", \"hash\":\"3352cc51d6790ddc81df3ff514f7a20cdf7d79e6\", \"best_bid\":\"0.44\", \"best_ask\":\"0.45\"}, {\"asset_id\":\"24254094493625419915756280046002869097156693848522361803041977572204227262166\", \"price\":\"0.56\", \"size\":\"40\", \"side\":\"SELL\", \"hash\":\"06ec1b805b3010393681959c8833c7386f4e9eb1\", \"best_bid\":\"0.55\", \"best_ask\":\"0.56\"}], \"timestamp\":\"1785122358575\", \"event_type\":\"price_change\"}","received_at":"2026-07-27T03:19:18.692059Z","schema_version":"clob-market-ws.price_change.v1","sequence":null,"server_hash":null,"server_timestamp":"1785122358575","session_id":"dd162b8dca5f43ff811d304e69a06123","source":"clob_market_ws"},"received_at":"2026-07-27T03:19:18.692059Z","record_id":"9522bd12e769c4026b91008aa57cb0d1383965d6cdfd0445917065b613d14a51","schema_fingerprint":"4aa3821a28b0b7c2400bc59aba4bcc0a76e971dadd19610d3ad38c768e124dc7","schema_version":"edge-lab-recorder.raw.v1","sequence":null,"source":"clob_market_ws"}
{"event_at":"2026-07-27T03:19:18.576000Z","event_fingerprint":"4d3623800dbf68194e8f8acd10567957bfb35408b33af23feac80be8d32de60e","payload":{"connection_id":"c7dc2e4762f849c6b6f9306b6518dcab","event_at":"2026-07-27T03:19:18.576000Z","event_type":"price_change","frame_hash":"fae36f2139a4a38a4f29f688d161029ef89f944e94b25cebadcdc37bd696a628","frame_index":0,"kind":"data","monotonic_ns":224342031663666,"payload":{"event_type":"price_change","market":"0x717c0e8ccd4d5c7040185188fbae28be901ca589a11a94b1b38ca36a79eccfeb","price_changes":[{"asset_id":"41448400836309843603620980831210604935021861034693225347475867885462478926555","best_ask":"0.45","best_bid":"0.44","hash":"95617a7870068a0fbaaa0bf7d8eaa787f14f85b6","price":"0.32","side":"BUY","size":"182"},{"asset_id":"24254094493625419915756280046002869097156693848522361803041977572204227262166","best_ask":"0.56","best_bid":"0.55","hash":"639ca12d658c46ba2c07d78e8713c3f2680ba4c1","price":"0.68","side":"SELL","size":"182"}],"timestamp":"1785122358576"},"payload_hash":"56d4b2147b4dea26ab42f3484505e7ddb94b7d3e57dabb33625281410eabbcaf","raw_frame":"{\"market\":\"0x717c0e8ccd4d5c7040185188fbae28be901ca589a11a94b1b38ca36a79eccfeb\", \"price_changes\":[{\"asset_id\":\"41448400836309843603620980831210604935021861034693225347475867885462478926555\", \"price\":\"0.32\", \"size\":\"182\", \"side\":\"BUY\", \"hash\":\"95617a7870068a0fbaaa0bf7d8eaa787f14f85b6\", \"best_bid\":\"0.44\", \"best_ask\":\"0.45\"}, {\"asset_id\":\"24254094493625419915756280046002869097156693848522361803041977572204227262166\", \"price\":\"0.68\", \"size\":\"182\", \"side\":\"SELL\", \"hash\":\"639ca12d658c46ba2c07d78e8713c3f2680ba4c1\", \"best_bid\":\"0.55\", \"best_ask\":\"0.56\"}], \"timestamp\":\"1785122358576\", \"event_type\":\"price_change\"}","received_at":"2026-07-27T03:19:18.694375Z","schema_version":"clob-market-ws.price_change.v1","sequence":null,"server_hash":null,"server_timestamp":"1785122358576","session_id":"dd162b8dca5f43ff811d304e69a06123","source":"clob_market_ws"},"received_at":"2026-07-27T03:19:18.694375Z","record_id":"e71fce49858ecd879bacf0e68f2c55ec57715b774a22002ae52560aad98a276b","schema_fingerprint":"4aa3821a28b0b7c2400bc59aba4bcc0a76e971dadd19610d3ad38c768e124dc7","schema_version":"edge-lab-recorder.raw.v1","sequence":null,"source":"clob_market_ws"}
{"event_at":"2026-07-27T03:19:18.576000Z","event_fingerprint":"a84c3b063d6fa4ab8b32a0c1100c5809fd76bf498c8365c025f35038f95238be","payload":{"connection_id":"c7dc2e4762f849c6b6f9306b6518dcab","event_at":"2026-07-27T03:19:18.576000Z","event_type":"price_change","frame_hash":"6bb3aba44e9256dcef95979a07f4280468949283aaf5a01cbd52028a5d043eab","frame_index":0,"kind":"data","monotonic_ns":224342033949791,"payload":{"event_type":"price_change","market":"0x717c0e8ccd4d5c7040185188fbae28be901ca589a11a94b1b38ca36a79eccfeb","price_changes":[{"asset_id":"41448400836309843603620980831210604935021861034693225347475867885462478926555","best_ask":"0.45","best_bid":"0.44","hash":"3295c152e72d115876d17ade3adfc483029ecb01","price":"0.5","side":"SELL","size":"197.38"},{"asset_id":"24254094493625419915756280046002869097156693848522361803041977572204227262166","best_ask":"0.56","best_bid":"0.55","hash":"e42f890c1e9b59c51733e39b42f7e16647593504","price":"0.5","side":"BUY","size":"197.38"}],"timestamp":"1785122358576"},"payload_hash":"8866caee4e7bc8f20d93ca17bc53c4073df03e891fb20bd15dbe5ee71f036bae","raw_frame":"{\"market\":\"0x717c0e8ccd4d5c7040185188fbae28be901ca589a11a94b1b38ca36a79eccfeb\", \"price_changes\":[{\"asset_id\":\"41448400836309843603620980831210604935021861034693225347475867885462478926555\", \"price\":\"0.5\", \"size\":\"197.38\", \"side\":\"SELL\", \"hash\":\"3295c152e72d115876d17ade3adfc483029ecb01\", \"best_bid\":\"0.44\", \"best_ask\":\"0.45\"}, {\"asset_id\":\"24254094493625419915756280046002869097156693848522361803041977572204227262166\", \"price\":\"0.5\", \"size\":\"197.38\", \"side\":\"BUY\", \"hash\":\"e42f890c1e9b59c51733e39b42f7e16647593504\", \"best_bid\":\"0.55\", \"best_ask\":\"0.56\"}], \"timestamp\":\"1785122358576\", \"event_type\":\"price_change\"}","received_at":"2026-07-27T03:19:18.696654Z","schema_version":"clob-market-ws.price_change.v1","sequence":null,"server_hash":null,"server_timestamp":"1785122358576","session_id":"dd162b8dca5f43ff811d304e69a06123","source":"clob_market_ws"},"received_at":"2026-07-27T03:19:18.696654Z","record_id":"be0d08345b3f79219936eb81de992d4a2716dbc53fdd684d7db396588037f461","schema_fingerprint":"4aa3821a28b0b7c2400bc59aba4bcc0a76e971dadd19610d3ad38c768e124dc7","schema_version":"edge-lab-recorder.raw.v1","sequence":null,"source":"clob_market_ws"}
{"event_at":"2026-07-27T03:19:18.577000Z","event_fingerprint":"9c546943329cb839fb4d5e13fcab4b0384b374e6a67cc08b0ed47730a642a589","payload":{"connection_id":"c7dc2e4762f849c6b6f9306b6518dcab","event_at":"2026-07-27T03:19:18.577000Z","event_type":"price_change","frame_hash":"e5efa4a9b015fd50fae88f7a5fae8f4a67bc4dec7150bf5e10af67fd19186b1c","frame_index":0,"kind":"data","monotonic_ns":224342036873333,"payload":{"event_type":"price_change","market":"0x717c0e8ccd4d5c7040185188fbae28be901ca589a11a94b1b38ca36a79eccfeb","price_changes":[{"asset_id":"24254094493625419915756280046002869097156693848522361803041977572204227262166","best_ask":"0.56","best_bid":"0.55","hash":"967452adc9710ddd446748f0c750d9936c5558ef","price":"0.5","side":"BUY","size":"167.38"},{"asset_id":"41448400836309843603620980831210604935021861034693225347475867885462478926555","best_ask":"0.45","best_bid":"0.44","hash":"c91e5e7af2c97646108da79b78784f1b4317e5b5","price":"0.5","side":"SELL","size":"167.38"}],"timestamp":"1785122358577"},"payload_hash":"c7db8ccbd125665924d7f6a6a90c061cf4179c281c342372ba3b3e31e8630fb8","raw_frame":"{\"market\":\"0x717c0e8ccd4d5c7040185188fbae28be901ca589a11a94b1b38ca36a79eccfeb\", \"price_changes\":[{\"asset_id\":\"24254094493625419915756280046002869097156693848522361803041977572204227262166\", \"price\":\"0.5\", \"size\":\"167.38\", \"side\":\"BUY\", \"hash\":\"967452adc9710ddd446748f0c750d9936c5558ef\", \"best_bid\":\"0.55\", \"best_ask\":\"0.56\"}, {\"asset_id\":\"41448400836309843603620980831210604935021861034693225347475867885462478926555\", \"price\":\"0.5\", \"size\":\"167.38\", \"side\":\"SELL\", \"hash\":\"c91e5e7af2c97646108da79b78784f1b4317e5b5\", \"best_bid\":\"0.44\", \"best_ask\":\"0.45\"}], \"timestamp\":\"1785122358577\", \"event_type\":\"price_change\"}","received_at":"2026-07-27T03:19:18.699584Z","schema_version":"clob-market-ws.price_change.v1","sequence":null,"server_hash":null,"server_timestamp":"1785122358577","session_id":"dd162b8dca5f43ff811d304e69a06123","source":"clob_market_ws"},"received_at":"2026-07-27T03:19:18.699584Z","record_id":"158c8c3072903835df519c2db4a4f075d1417d20b4b01514608795e28a188f19","schema_fingerprint":"4aa3821a28b0b7c2400bc59aba4bcc0a76e971dadd19610d3ad38c768e124dc7","schema_version":"edge-lab-recorder.raw.v1","sequence":null,"source":"clob_market_ws"}
{"event_at":"2026-07-27T03:19:18.577000Z","event_fingerprint":"b1c050d586803b1c8a548c59faeb16812fa4129463b2cb890778c960630de4f1","payload":{"connection_id":"c7dc2e4762f849c6b6f9306b6518dcab","event_at":"2026-07-27T03:19:18.577000Z","event_type":"price_change","frame_hash":"fbddb057adeb802ede1edcd767a80e34c765cfa88afd39db7591479b01544913","frame_index":0,"kind":"data","monotonic_ns":224342040660000,"payload":{"event_type":"price_change","market":"0x717c0e8ccd4d5c7040185188fbae28be901ca589a11a94b1b38ca36a79eccfeb","price_changes":[{"asset_id":"41448400836309843603620980831210604935021861034693225347475867885462478926555","best_ask":"0.45","best_bid":"0.44","hash":"bfc44fab1a6abc365038f32508552e2ec87893cb","price":"0.44","side":"BUY","size":"45"},{"asset_id":"24254094493625419915756280046002869097156693848522361803041977572204227262166","best_ask":"0.56","best_bid":"0.55","hash":"59ee3e2502d2a7599921dff6a86af7d70820f0ed","price":"0.56","side":"SELL","size":"45"}],"timestamp":"1785122358577"},"payload_hash":"a807d6e1f6ac76bf1517609678a3e3c6c55474b163e5e1975f416b2955e29eda","raw_frame":"{\"market\":\"0x717c0e8ccd4d5c7040185188fbae28be901ca589a11a94b1b38ca36a79eccfeb\", \"price_changes\":[{\"asset_id\":\"41448400836309843603620980831210604935021861034693225347475867885462478926555\", \"price\":\"0.44\", \"size\":\"45\", \"side\":\"BUY\", \"hash\":\"bfc44fab1a6abc365038f32508552e2ec87893cb\", \"best_bid\":\"0.44\", \"best_ask\":\"0.45\"}, {\"asset_id\":\"24254094493625419915756280046002869097156693848522361803041977572204227262166\", \"price\":\"0.56\", \"size\":\"45\", \"side\":\"SELL\", \"hash\":\"59ee3e2502d2a7599921dff6a86af7d70820f0ed\", \"best_bid\":\"0.55\", \"best_ask\":\"0.56\"}], \"timestamp\":\"1785122358577\", \"event_type\":\"price_change\"}","received_at":"2026-07-27T03:19:18.703345Z","schema_version":"clob-market-ws.price_change.v1","sequence":null,"server_hash":null,"server_timestamp":"1785122358577","session_id":"dd162b8dca5f43ff811d304e69a06123","source":"clob_market_ws"},"received_at":"2026-07-27T03:19:18.703345Z","record_id":"f53d7509f46a3d32c4eb20f58a1f0fd5fc9b0695f3b415676dec5f32f6d7e1fb","schema_fingerprint":"4aa3821a28b0b7c2400bc59aba4bcc0a76e971dadd19610d3ad38c768e124dc7","schema_version":"edge-lab-recorder.raw.v1","sequence":null,"source":"clob_market_ws"}
{"event_at":"2026-07-27T03:19:18.578000Z","event_fingerprint":"7f56a22210f795b54af10c0822f988d46d00e02cc535556a4ce8fb4879d00b5f","payload":{"connection_id":"c7dc2e4762f849c6b6f9306b6518dcab","event_at":"2026-07-27T03:19:18.578000Z","event_type":"price_change","frame_hash":"973b41fc12ad516cff5e666cb8061ba2db3e1ec24b5e04e001d9970763175ef4","frame_index":0,"kind":"data","monotonic_ns":224342044992875,"payload":{"event_type":"price_change","market":"0x717c0e8ccd4d5c7040185188fbae28be901ca589a11a94b1b38ca36a79eccfeb","price_changes":[{"asset_id":"24254094493625419915756280046002869097156693848522361803041977572204227262166","best_ask":"0.56","best_bid":"0.55","hash":"7c8f45f2ccd608cba7ed1544faba2e5b5b8ccdb4","price":"0.36","side":"BUY","size":"18"},{"asset_id":"41448400836309843603620980831210604935021861034693225347475867885462478926555","best_ask":"0.45","best_bid":"0.44","hash":"8272f309e38b4f498d8ce065f6e9d8e703cb8227","price":"0.64","side":"SELL","size":"18"}],"timestamp":"1785122358578"},"payload_hash":"19252afef63265d298ab6c71e3dff8d74e0b9aaa8e940abe0492f16acd9aae03","raw_frame":"{\"market\":\"0x717c0e8ccd4d5c7040185188fbae28be901ca589a11a94b1b38ca36a79eccfeb\", \"price_changes\":[{\"asset_id\":\"24254094493625419915756280046002869097156693848522361803041977572204227262166\", \"price\":\"0.36\", \"size\":\"18\", \"side\":\"BUY\", \"hash\":\"7c8f45f2ccd608cba7ed1544faba2e5b5b8ccdb4\", \"best_bid\":\"0.55\", \"best_ask\":\"0.56\"}, {\"asset_id\":\"41448400836309843603620980831210604935021861034693225347475867885462478926555\", \"price\":\"0.64\", \"size\":\"18\", \"side\":\"SELL\", \"hash\":\"8272f309e38b4f498d8ce065f6e9d8e703cb8227\", \"best_bid\":\"0.44\", \"best_ask\":\"0.45\"}], \"timestamp\":\"1785122358578\", \"event_type\":\"price_change\"}","received_at":"2026-07-27T03:19:18.707700Z","schema_version":"clob-market-ws.price_change.v1","sequence":null,"server_hash":null,"server_timestamp":"1785122358578","session_id":"dd162b8dca5f43ff811d304e69a06123","source":"clob_market_ws"},"received_at":"2026-07-27T03:19:18.707700Z","record_id":"e928cb05f6580864a2cdc91b76397c7e58c57dd2b6fce3ea7c13ebfc56499a94","schema_fingerprint":"4aa3821a28b0b7c2400bc59aba4bcc0a76e971dadd19610d3ad38c768e124dc7","schema_version":"edge-lab-recorder.raw.v1","sequence":null,"source":"clob_market_ws"}
{"event_at":"2026-07-27T03:19:18.579000Z","event_fingerprint":"bb89185cefa85d2bf4bd06c81319199fb699b070038956b9d993d8a940974e58","payload":{"connection_id":"c7dc2e4762f849c6b6f9306b6518dcab","event_at":"2026-07-27T03:19:18.579000Z","event_type":"price_change","frame_hash":"de0feb8c79db499e0dd0f7af0c5cdc1c3905175d9ce4efcbc175904ef9f75b1b","frame_index":0,"kind":"data","monotonic_ns":224342048327041,"payload":{"event_type":"price_change","market":"0x717c0e8ccd4d5c7040185188fbae28be901ca589a11a94b1b38ca36a79eccfeb","price_changes":[{"asset_id":"24254094493625419915756280046002869097156693848522361803041977572204227262166","best_ask":"0.56","best_bid":"0.55","hash":"c7592cbcf4d511cb552bd7f29d05ddb7b7c5221a","price":"0.5","side":"BUY","size":"137.38"},{"asset_id":"41448400836309843603620980831210604935021861034693225347475867885462478926555","best_ask":"0.45","best_bid":"0.44","hash":"dbae92e132379864a6dae327bbe3271dc1825236","price":"0.5","side":"SELL","size":"137.38"}],"timestamp":"1785122358579"},"payload_hash":"be2995772b1994ff190774ae5b122d570e5ad5129089ab4a7bfa57192e2247dd","raw_frame":"{\"market\":\"0x717c0e8ccd4d5c7040185188fbae28be901ca589a11a94b1b38ca36a79eccfeb\", \"price_changes\":[{\"asset_id\":\"24254094493625419915756280046002869097156693848522361803041977572204227262166\", \"price\":\"0.5\", \"size\":\"137.38\", \"side\":\"BUY\", \"hash\":\"c7592cbcf4d511cb552bd7f29d05ddb7b7c5221a\", \"best_bid\":\"0.55\", \"best_ask\":\"0.56\"}, {\"asset_id\":\"41448400836309843603620980831210604935021861034693225347475867885462478926555\", \"price\":\"0.5\", \"size\":\"137.38\", \"side\":\"SELL\", \"hash\":\"dbae92e132379864a6dae327bbe3271dc1825236\", \"best_bid\":\"0.44\", \"best_ask\":\"0.45\"}], \"timestamp\":\"1785122358579\", \"event_type\":\"price_change\"}","received_at":"2026-07-27T03:19:18.711035Z","schema_version":"clob-market-ws.price_change.v1","sequence":null,"server_hash":null,"server_timestamp":"1785122358579","session_id":"dd162b8dca5f43ff811d304e69a06123","source":"clob_market_ws"},"received_at":"2026-07-27T03:19:18.711035Z","record_id":"9a6a1a82e2deaa29a28fa9413b06a54d2c2e7325ff45a88b3db794361c7275cd","schema_fingerprint":"4aa3821a28b0b7c2400bc59aba4bcc0a76e971dadd19610d3ad38c768e124dc7","schema_version":"edge-lab-recorder.raw.v1","sequence":null,"source":"clob_market_ws"}
{"event_at":"2026-07-27T03:19:18.585000Z","event_fingerprint":"c875e55883fb2883210340dfb7b94279ee9f7bb4e057fe9c633da4013ad2bc43","payload":{"connection_id":"c7dc2e4762f849c6b6f9306b6518dcab","event_at":"2026-07-27T03:19:18.585000Z","event_type":"price_change","frame_hash":"0cb402dab0bf35a6981064315687bd22517d99a07dceda319e88f77eb1976586","frame_index":0,"kind":"data","monotonic_ns":224342051297625,"payload":{"event_type":"price_change","market":"0x717c0e8ccd4d5c7040185188fbae28be901ca589a11a94b1b38ca36a79eccfeb","price_changes":[{"asset_id":"24254094493625419915756280046002869097156693848522361803041977572204227262166","best_ask":"0.56","best_bid":"0.55","hash":"7f98126494cbe13d7d38e816528b718ef523beab","price":"0.55","side":"BUY","size":"9"},{"asset_id":"41448400836309843603620980831210604935021861034693225347475867885462478926555","best_ask":"0.45","best_bid":"0.44","hash":"5afb952c38f66eb030c95a5c6847ee950d936fd4","price":"0.45","side":"SELL","size":"9"}],"timestamp":"1785122358585"},"payload_hash":"9cc5bcf65123caf819a514cbfc8c716d55872f100b290fd344ea73c0075170f4","raw_frame":"{\"market\":\"0x717c0e8ccd4d5c7040185188fbae28be901ca589a11a94b1b38ca36a79eccfeb\", \"price_changes\":[{\"asset_id\":\"24254094493625419915756280046002869097156693848522361803041977572204227262166\", \"price\":\"0.55\", \"size\":\"9\", \"side\":\"BUY\", \"hash\":\"7f98126494cbe13d7d38e816528b718ef523beab\", \"best_bid\":\"0.55\", \"best_ask\":\"0.56\"}, {\"asset_id\":\"41448400836309843603620980831210604935021861034693225347475867885462478926555\", \"price\":\"0.45\", \"size\":\"9\", \"side\":\"SELL\", \"hash\":\"5afb952c38f66eb030c95a5c6847ee950d936fd4\", \"best_bid\":\"0.44\", \"best_ask\":\"0.45\"}], \"timestamp\":\"1785122358585\", \"event_type\":\"price_change\"}","received_at":"2026-07-27T03:19:18.714008Z","schema_version":"clob-market-ws.price_change.v1","sequence":null,"server_hash":null,"server_timestamp":"1785122358585","session_id":"dd162b8dca5f43ff811d304e69a06123","source":"clob_market_ws"},"received_at":"2026-07-27T03:19:18.714008Z","record_id":"a0b3bd218f25aec2534283497a87297e0dae13d8b756b6e7c23eca41d9a480c4","schema_fingerprint":"4aa3821a28b0b7c2400bc59aba4bcc0a76e971dadd19610d3ad38c768e124dc7","schema_version":"edge-lab-recorder.raw.v1","sequence":null,"source":"clob_market_ws"}
{"event_at":"2026-07-27T03:19:18.585000Z","event_fingerprint":"fed6be7ee7b0b3acab256cbf30a55133f87133db5ca7c17a2e8e015fe5a4d419","payload":{"connection_id":"c7dc2e4762f849c6b6f9306b6518dcab","event_at":"2026-07-27T03:19:18.585000Z","event_type":"price_change","frame_hash":"f292735f0595c82a96ab7c33e133c5bcbf10ba072ca6a23a5446ca0b84666590","frame_index":0,"kind":"data","monotonic_ns":224342054235833,"payload":{"event_type":"price_change","market":"0x717c0e8ccd4d5c7040185188fbae28be901ca589a11a94b1b38ca36a79eccfeb","price_changes":[{"asset_id":"24254094493625419915756280046002869097156693848522361803041977572204227262166","best_ask":"0.56","best_bid":"0.55","hash":"bed8848074d4a3a88dcfb50eacd698aab62aed4b","price":"0.57","side":"SELL","size":"184.94"},{"asset_id":"41448400836309843603620980831210604935021861034693225347475867885462478926555","best_ask":"0.45","best_bid":"0.44","hash":"e70b485833ae9fec7be17d435347d3160a734ef6","price":"0.43","side":"BUY","size":"184.94"}],"timestamp":"1785122358585"},"payload_hash":"d980c3e6fed7cb56ac90d56718ef87f79dae02469153fc43a999001d430e8bf8","raw_frame":"{\"market\":\"0x717c0e8ccd4d5c7040185188fbae28be901ca589a11a94b1b38ca36a79eccfeb\", \"price_changes\":[{\"asset_id\":\"24254094493625419915756280046002869097156693848522361803041977572204227262166\", \"price\":\"0.57\", \"size\":\"184.94\", \"side\":\"SELL\", \"hash\":\"bed8848074d4a3a88dcfb50eacd698aab62aed4b\", \"best_bid\":\"0.55\", \"best_ask\":\"0.56\"}, {\"asset_id\":\"41448400836309843603620980831210604935021861034693225347475867885462478926555\", \"price\":\"0.43\", \"size\":\"184.94\", \"side\":\"BUY\", \"hash\":\"e70b485833ae9fec7be17d435347d3160a734ef6\", \"best_bid\":\"0.44\", \"best_ask\":\"0.45\"}], \"timestamp\":\"1785122358585\", \"event_type\":\"price_change\"}","received_at":"2026-07-27T03:19:18.716946Z","schema_version":"clob-market-ws.price_change.v1","sequence":null,"server_hash":null,"server_timestamp":"1785122358585","session_id":"dd162b8dca5f43ff811d304e69a06123","source":"clob_market_ws"},"received_at":"2026-07-27T03:19:18.716946Z","record_id":"602b4e75684ca4ec5ec36c2aed91d4454f8c59bfd7ed6978b845aec4723366ee","schema_fingerprint":"4aa3821a28b0b7c2400bc59aba4bcc0a76e971dadd19610d3ad38c768e124dc7","schema_version":"edge-lab-recorder.raw.v1","sequence":null,"source":"clob_market_ws"}
{"event_at":"2026-07-27T03:19:18.586000Z","event_fingerprint":"2d7eaa7db174bdd73be046ac72aa98811460e956f908670d34cb8942bf86957f","payload":{"connection_id":"c7dc2e4762f849c6b6f9306b6518dcab","event_at":"2026-07-27T03:19:18.586000Z","event_type":"price_change","frame_hash":"3ae8e39f2fd269192b1bf39b75d5ac8277ed4ea1aa26a3589125952bcc8d8956","frame_index":0,"kind":"data","monotonic_ns":224342057156333,"payload":{"event_type":"price_change","market":"0x717c0e8ccd4d5c7040185188fbae28be901ca589a11a94b1b38ca36a79eccfeb","price_changes":[{"asset_id":"41448400836309843603620980831210604935021861034693225347475867885462478926555","best_ask":"0.45","best_bid":"0.44","hash":"0b8127752da0bc91b8183e5adf7fadbdaa07cb86","price":"0.43","side":"BUY","size":"175.94"},{"asset_id":"24254094493625419915756280046002869097156693848522361803041977572204227262166","best_ask":"0.56","best_bid":"0.55","hash":"e0688f34809d95bea6db1cfa05b6e2029ee4eb78","price":"0.57","side":"SELL","size":"175.94"}],"timestamp":"1785122358586"},"payload_hash":"9eb1eb8adeae8b2c4c546c41506fd8e7a9a8db642a406ba6053265b407b7cfc6","raw_frame":"{\"market\":\"0x717c0e8ccd4d5c7040185188fbae28be901ca589a11a94b1b38ca36a79eccfeb\", \"price_changes\":[{\"asset_id\":\"41448400836309843603620980831210604935021861034693225347475867885462478926555\", \"price\":\"0.43\", \"size\":\"175.94\", \"side\":\"BUY\", \"hash\":\"0b8127752da0bc91b8183e5adf7fadbdaa07cb86\", \"best_bid\":\"0.44\", \"best_ask\":\"0.45\"}, {\"asset_id\":\"24254094493625419915756280046002869097156693848522361803041977572204227262166\", \"price\":\"0.57\", \"size\":\"175.94\", \"side\":\"SELL\", \"hash\":\"e0688f34809d95bea6db1cfa05b6e2029ee4eb78\", \"best_bid\":\"0.55\", \"best_ask\":\"0.56\"}], \"timestamp\":\"1785122358586\", \"event_type\":\"price_change\"}","received_at":"2026-07-27T03:19:18.719866Z","schema_version":"clob-market-ws.price_change.v1","sequence":null,"server_hash":null,"server_timestamp":"1785122358586","session_id":"dd162b8dca5f43ff811d304e69a06123","source":"clob_market_ws"},"received_at":"2026-07-27T03:19:18.719866Z","record_id":"439a3a3cfe01f3a6606c346a3251e4c49e401aa8923e829dd7ecdf22177848f9","schema_fingerprint":"4aa3821a28b0b7c2400bc59aba4bcc0a76e971dadd19610d3ad38c768e124dc7","schema_version":"edge-lab-recorder.raw.v1","sequence":null,"source":"clob_market_ws"}
{"event_at":"2026-07-27T03:19:18.587000Z","event_fingerprint":"3b8924bbed11c83f40e855f02fa0e867effeaaedc4ae07b01b55644d26439fec","payload":{"connection_id":"c7dc2e4762f849c6b6f9306b6518dcab","event_at":"2026-07-27T03:19:18.587000Z","event_type":"price_change","frame_hash":"9feef0036001b8e7ad3c47c342d18983245c0dd30c67774f79e45cda1a550123","frame_index":0,"kind":"data","monotonic_ns":224342059744666,"payload":{"event_type":"price_change","market":"0x717c0e8ccd4d5c7040185188fbae28be901ca589a11a94b1b38ca36a79eccfeb","price_changes":[{"asset_id":"24254094493625419915756280046002869097156693848522361803041977572204227262166","best_ask":"0.56","best_bid":"0.55","hash":"9db58bb55f51614268a5b17ed1483d4d8e2d8981","price":"0.57","side":"SELL","size":"170.94"},{"asset_id":"41448400836309843603620980831210604935021861034693225347475867885462478926555","best_ask":"0.45","best_bid":"0.44","hash":"07f0118e97fd1e9d0c2fd4122edf6f6ff63e4ec5","price":"0.43","side":"BUY","size":"170.94"}],"timestamp":"1785122358587"},"payload_hash":"731edf17bfcb88da18c1793fae2cbbc997eb38b2f613bc9db008080811423d7c","raw_frame":"{\"market\":\"0x717c0e8ccd4d5c7040185188fbae28be901ca589a11a94b1b38ca36a79eccfeb\", \"price_changes\":[{\"asset_id\":\"24254094493625419915756280046002869097156693848522361803041977572204227262166\", \"price\":\"0.57\", \"size\":\"170.94\", \"side\":\"SELL\", \"hash\":\"9db58bb55f51614268a5b17ed1483d4d8e2d8981\", \"best_bid\":\"0.55\", \"best_ask\":\"0.56\"}, {\"asset_id\":\"41448400836309843603620980831210604935021861034693225347475867885462478926555\", \"price\":\"0.43\", \"size\":\"170.94\", \"side\":\"BUY\", \"hash\":\"07f0118e97fd1e9d0c2fd4122edf6f6ff63e4ec5\", \"best_bid\":\"0.44\", \"best_ask\":\"0.45\"}], \"timestamp\":\"1785122358587\", \"event_type\":\"price_change\"}","received_at":"2026-07-27T03:19:18.722454Z","schema_version":"clob-market-ws.price_change.v1","sequence":null,"server_hash":null,"server_timestamp":"1785122358587","session_id":"dd162b8dca5f43ff811d304e69a06123","source":"clob_market_ws"},"received_at":"2026-07-27T03:19:18.722454Z","record_id":"78545108afbcd14325f409b2b318a121deadb515592c001276c4a0e722e8cebe","schema_fingerprint":"4aa3821a28b0b7c2400bc59aba4bcc0a76e971dadd19610d3ad38c768e124dc7","schema_version":"edge-lab-recorder.raw.v1","sequence":null,"source":"clob_market_ws"}
{"event_at":"2026-07-27T03:19:18.588000Z","event_fingerprint":"548a1f4cfd0afa890a818a7df0b7242de48512e406ad1296f92c2a452d37a383","payload":{"connection_id":"c7dc2e4762f849c6b6f9306b6518dcab","event_at":"2026-07-27T03:19:18.588000Z","event_type":"price_change","frame_hash":"b746ee2e608ad23a8e46bd312b73428a81f4a97c23763be60bd346b6dcb7416d","frame_index":0,"kind":"data","monotonic_ns":224342061812000,"payload":{"event_type":"price_change","market":"0x717c0e8ccd4d5c7040185188fbae28be901ca589a11a94b1b38ca36a79eccfeb","price_changes":[{"asset_id":"41448400836309843603620980831210604935021861034693225347475867885462478926555","best_ask":"0.45","best_bid":"0.44","hash":"88c11be64f84750252eea9e0520ad271a9d78358","price":"0.44","side":"BUY","size":"67"},{"asset_id":"24254094493625419915756280046002869097156693848522361803041977572204227262166","best_ask":"0.56","best_bid":"0.55","hash":"1dc25e435db4008cf67801e7dd6fde6583a923a2","price":"0.56","side":"SELL","size":"67"}],"timestamp":"1785122358588"},"payload_hash":"c9c33220a8332c097c65d383459a8e7d0ad1c0c872404005da791b278fcb6151","raw_frame":"{\"market\":\"0x717c0e8ccd4d5c7040185188fbae28be901ca589a11a94b1b38ca36a79eccfeb\", \"price_changes\":[{\"asset_id\":\"41448400836309843603620980831210604935021861034693225347475867885462478926555\", \"price\":\"0.44\", \"size\":\"67\", \"side\":\"BUY\", \"hash\":\"88c11be64f84750252eea9e0520ad271a9d78358\", \"best_bid\":\"0.44\", \"best_ask\":\"0.45\"}, {\"asset_id\":\"24254094493625419915756280046002869097156693848522361803041977572204227262166\", \"price\":\"0.56\", \"size\":\"67\", \"side\":\"SELL\", \"hash\":\"1dc25e435db4008cf67801e7dd6fde6583a923a2\", \"best_bid\":\"0.55\", \"best_ask\":\"0.56\"}], \"timestamp\":\"1785122358588\", \"event_type\":\"price_change\"}","received_at":"2026-07-27T03:19:18.724521Z","schema_version":"clob-market-ws.price_change.v1","sequence":null,"server_hash":null,"server_timestamp":"1785122358588","session_id":"dd162b8dca5f43ff811d304e69a06123","source":"clob_market_ws"},"received_at":"2026-07-27T03:19:18.724521Z","record_id":"a6127539d939f3d2091e7095e0849b34e469b730599873b8e004363309f1c462","schema_fingerprint":"4aa3821a28b0b7c2400bc59aba4bcc0a76e971dadd19610d3ad38c768e124dc7","schema_version":"edge-lab-recorder.raw.v1","sequence":null,"source":"clob_market_ws"}
{"event_at":"2026-07-27T03:19:18.589000Z","event_fingerprint":"ab99404a85353f3928a5b3406baeb7115802f2dd9ec43cb7a1ff4f30cd08d880","payload":{"connection_id":"c7dc2e4762f849c6b6f9306b6518dcab","event_at":"2026-07-27T03:19:18.589000Z","event_type":"price_change","frame_hash":"1c114e2aae5e439d019a90ee978a3bd93ced9714c0d98e268306e14d8d8877e1","frame_index":0,"kind":"data","monotonic_ns":224342064113125,"payload":{"event_type":"price_change","market":"0x717c0e8ccd4d5c7040185188fbae28be901ca589a11a94b1b38ca36a79eccfeb","price_changes":[{"asset_id":"24254094493625419915756280046002869097156693848522361803041977572204227262166","best_ask":"0.56","best_bid":"0.55","hash":"7f4389bc7dc791b3c053e9f854e8ae7187d1f11a","price":"0.54","side":"BUY","size":"36.66"},{"asset_id":"41448400836309843603620980831210604935021861034693225347475867885462478926555","best_ask":"0.45","best_bid":"0.44","hash":"3658b98334e5bd6e7200c90c0de6355edaaea0db","price":"0.46","side":"SELL","size":"36.66"}],"timestamp":"1785122358589"},"payload_hash":"38fffb68eb4c3a76de7a689e8a646196b7b23a941d26b923562537d5180c5792","raw_frame":"{\"market\":\"0x717c0e8ccd4d5c7040185188fbae28be901ca589a11a94b1b38ca36a79eccfeb\", \"price_changes\":[{\"asset_id\":\"24254094493625419915756280046002869097156693848522361803041977572204227262166\", \"price\":\"0.54\", \"size\":\"36.66\", \"side\":\"BUY\", \"hash\":\"7f4389bc7dc791b3c053e9f854e8ae7187d1f11a\", \"best_bid\":\"0.55\", \"best_ask\":\"0.56\"}, {\"asset_id\":\"41448400836309843603620980831210604935021861034693225347475867885462478926555\", \"price\":\"0.46\", \"size\":\"36.66\", \"side\":\"SELL\", \"hash\":\"3658b98334e5bd6e7200c90c0de6355edaaea0db\", \"best_bid\":\"0.44\", \"best_ask\":\"0.45\"}], \"timestamp\":\"1785122358589\", \"event_type\":\"price_change\"}","received_at":"2026-07-27T03:19:18.726822Z","schema_version":"clob-market-ws.price_change.v1","sequence":null,"server_hash":null,"server_timestamp":"1785122358589","session_id":"dd162b8dca5f43ff811d304e69a06123","source":"clob_market_ws"},"received_at":"2026-07-27T03:19:18.726822Z","record_id":"8aa8f8231119793f1ab838581cf7bb7d444290bf3a51fc79abd872999ce2d1c8","schema_fingerprint":"4aa3821a28b0b7c2400bc59aba4bcc0a76e971dadd19610d3ad38c768e124dc7","schema_version":"edge-lab-recorder.raw.v1","sequence":null,"source":"clob_market_ws"}
{"event_at":"2026-07-27T03:19:18.590000Z","event_fingerprint":"355f188334559d23ba163d4c21a5211d876b2a446315547ce19c1722369409dc","payload":{"connection_id":"c7dc2e4762f849c6b6f9306b6518dcab","event_at":"2026-07-27T03:19:18.590000Z","event_type":"price_change","frame_hash":"43e348aab0f0f4074748ec422e64dd79899322a2205b4d4baa3cb25aaa2348c0","frame_index":0,"kind":"data","monotonic_ns":224342067103750,"payload":{"event_type":"price_change","market":"0x717c0e8ccd4d5c7040185188fbae28be901ca589a11a94b1b38ca36a79eccfeb","price_changes":[{"asset_id":"41448400836309843603620980831210604935021861034693225347475867885462478926555","best_ask":"0.45","best_bid":"0.44","hash":"727529e812aaa25d227222ef6f85c84d8372bcfb","price":"0.23","side":"BUY","size":"168.8"},{"asset_id":"24254094493625419915756280046002869097156693848522361803041977572204227262166","best_ask":"0.56","best_bid":"0.55","hash":"923139f3e63486e0c39dedb5431981302642080e","price":"0.77","side":"SELL","size":"168.8"}],"timestamp":"1785122358590"},"payload_hash":"92217f6e4cdc044f92785f6687438e85b434e07592c653f36272518a5c997664","raw_frame":"{\"market\":\"0x717c0e8ccd4d5c7040185188fbae28be901ca589a11a94b1b38ca36a79eccfeb\", \"price_changes\":[{\"asset_id\":\"41448400836309843603620980831210604935021861034693225347475867885462478926555\", \"price\":\"0.23\", \"size\":\"168.8\", \"side\":\"BUY\", \"hash\":\"727529e812aaa25d227222ef6f85c84d8372bcfb\", \"best_bid\":\"0.44\", \"best_ask\":\"0.45\"}, {\"asset_id\":\"24254094493625419915756280046002869097156693848522361803041977572204227262166\", \"price\":\"0.77\", \"size\":\"168.8\", \"side\":\"SELL\", \"hash\":\"923139f3e63486e0c39dedb5431981302642080e\", \"best_bid\":\"0.55\", \"best_ask\":\"0.56\"}], \"timestamp\":\"1785122358590\", \"event_type\":\"price_change\"}","received_at":"2026-07-27T03:19:18.729813Z","schema_version":"clob-market-ws.price_change.v1","sequence":null,"server_hash":null,"server_timestamp":"1785122358590","session_id":"dd162b8dca5f43ff811d304e69a06123","source":"clob_market_ws"},"received_at":"2026-07-27T03:19:18.729813Z","record_id":"0dd3fc04764ffccfb350800c872df3b53d873e46147c6689e99943c45977014f","schema_fingerprint":"4aa3821a28b0b7c2400bc59aba4bcc0a76e971dadd19610d3ad38c768e124dc7","schema_version":"edge-lab-recorder.raw.v1","sequence":null,"source":"clob_market_ws"}
{"event_at":"2026-07-27T03:19:18.590000Z","event_fingerprint":"80d1220870bfb5745a6945d3055568afb5f8e5480a8d39727dd4fecc3e4f96ff","payload":{"connection_id":"c7dc2e4762f849c6b6f9306b6518dcab","event_at":"2026-07-27T03:19:18.590000Z","event_type":"price_change","frame_hash":"8aa7e8e8d05ffcb1c490f442061b0a2d5f298c036c29d890705bae60b859a23d","frame_index":0,"kind":"data","monotonic_ns":224342074330625,"payload":{"event_type":"price_change","market":"0x717c0e8ccd4d5c7040185188fbae28be901ca589a11a94b1b38ca36a79eccfeb","price_changes":[{"asset_id":"24254094493625419915756280046002869097156693848522361803041977572204227262166","best_ask":"0.56","best_bid":"0.55","hash":"1ab7c57e9d1114c64724b38215c8843b188ee6e0","price":"0.51","side":"BUY","size":"285"},{"asset_id":"41448400836309843603620980831210604935021861034693225347475867885462478926555","best_ask":"0.45","best_bid":"0.44","hash":"ffcddf9322e97aa2016ba7a21cddc738145c298c","price":"0.49","side":"SELL","size":"285"}],"timestamp":"1785122358590"},"payload_hash":"a254b69dae74bbb403787f17a40cadf6bc87ff6c43a5ec308c3fd1edea5f18f0","raw_frame":"{\"market\":\"0x717c0e8ccd4d5c7040185188fbae28be901ca589a11a94b1b38ca36a79eccfeb\", \"price_changes\":[{\"asset_id\":\"24254094493625419915756280046002869097156693848522361803041977572204227262166\", \"price\":\"0.51\", \"size\":\"285\", \"side\":\"BUY\", \"hash\":\"1ab7c57e9d1114c64724b38215c8843b188ee6e0\", \"best_bid\":\"0.55\", \"best_ask\":\"0.56\"}, {\"asset_id\":\"41448400836309843603620980831210604935021861034693225347475867885462478926555\", \"price\":\"0.49\", \"size\":\"285\", \"side\":\"SELL\", \"hash\":\"ffcddf9322e97aa2016ba7a21cddc738145c298c\", \"best_bid\":\"0.44\", \"best_ask\":\"0.45\"}], \"timestamp\":\"1785122358590\", \"event_type\":\"price_change\"}","received_at":"2026-07-27T03:19:18.737040Z","schema_version":"clob-market-ws.price_change.v1","sequence":null,"server_hash":null,"server_timestamp":"1785122358590","session_id":"dd162b8dca5f43ff811d304e69a06123","source":"clob_market_ws"},"received_at":"2026-07-27T03:19:18.737040Z","record_id":"6a2872bbd9b00026e3b9bdfeab6e871d5401f51145cb48ed08a31bcde1872418","schema_fingerprint":"4aa3821a28b0b7c2400bc59aba4bcc0a76e971dadd19610d3ad38c768e124dc7","schema_version":"edge-lab-recorder.raw.v1","sequence":null,"source":"clob_market_ws"}
{"event_at":"2026-07-27T03:19:18.591000Z","event_fingerprint":"010a1a3ffe4b3f169cf9f032a3e4212f1acff91400401d20e5758f19e6ec4755","payload":{"connection_id":"c7dc2e4762f849c6b6f9306b6518dcab","event_at":"2026-07-27T03:19:18.591000Z","event_type":"price_change","frame_hash":"0bb4599eb285b3a5f7389c0978cf92858a0ad801cf778470d96f3e000d491d1d","frame_index":0,"kind":"data","monotonic_ns":224342078775833,"payload":{"event_type":"price_change","market":"0x717c0e8ccd4d5c7040185188fbae28be901ca589a11a94b1b38ca36a79eccfeb","price_changes":[{"asset_id":"41448400836309843603620980831210604935021861034693225347475867885462478926555","best_ask":"0.45","best_bid":"0.44","hash":"dd6bd9010a14d50e3688aa9265554e4342cb43ae","price":"0.44","side":"BUY","size":"76.6"},{"asset_id":"24254094493625419915756280046002869097156693848522361803041977572204227262166","best_ask":"0.56","best_bid":"0.55","hash":"8732eefdd773fbf53c84850559ba1ea6cfbe5061","price":"0.56","side":"SELL","size":"76.6"}],"timestamp":"1785122358591"},"payload_hash":"47fc949e4bba76472a09eddce4d526f3308f85faac883f707a78cfdb56215a13","raw_frame":"{\"market\":\"0x717c0e8ccd4d5c7040185188fbae28be901ca589a11a94b1b38ca36a79eccfeb\", \"price_changes\":[{\"asset_id\":\"41448400836309843603620980831210604935021861034693225347475867885462478926555\", \"price\":\"0.44\", \"size\":\"76.6\", \"side\":\"BUY\", \"hash\":\"dd6bd9010a14d50e3688aa9265554e4342cb43ae\", \"best_bid\":\"0.44\", \"best_ask\":\"0.45\"}, {\"asset_id\":\"24254094493625419915756280046002869097156693848522361803041977572204227262166\", \"price\":\"0.56\", \"size\":\"76.6\", \"side\":\"SELL\", \"hash\":\"8732eefdd773fbf53c84850559ba1ea6cfbe5061\", \"best_bid\":\"0.55\", \"best_ask\":\"0.56\"}], \"timestamp\":\"1785122358591\", \"event_type\":\"price_change\"}","received_at":"2026-07-27T03:19:18.741481Z","schema_version":"clob-market-ws.price_change.v1","sequence":null,"server_hash":null,"server_timestamp":"1785122358591","session_id":"dd162b8dca5f43ff811d304e69a06123","source":"clob_market_ws"},"received_at":"2026-07-27T03:19:18.741481Z","record_id":"32d30405d8218dc74bf02c31ee28dba4e149b14a1d01e1cad4d404cb524d91bf","schema_fingerprint":"4aa3821a28b0b7c2400bc59aba4bcc0a76e971dadd19610d3ad38c768e124dc7","schema_version":"edge-lab-recorder.raw.v1","sequence":null,"source":"clob_market_ws"}
{"event_at":"2026-07-27T03:19:18.591000Z","event_fingerprint":"eb17acbd9f1178f2da3177ea40722b168de658e44c60a1b40481530a3c150102","payload":{"connection_id":"c7dc2e4762f849c6b6f9306b6518dcab","event_at":"2026-07-27T03:19:18.591000Z","event_type":"price_change","frame_hash":"72f81cf7037ff6a67954752d99bba7f79b8fcdb8678c92c58103c7a75e01ff4e","frame_index":0,"kind":"data","monotonic_ns":224342085555125,"payload":{"event_type":"price_change","market":"0x717c0e8ccd4d5c7040185188fbae28be901ca589a11a94b1b38ca36a79eccfeb","price_changes":[{"asset_id":"41448400836309843603620980831210604935021861034693225347475867885462478926555","best_ask":"0.45","best_bid":"0.44","hash":"88340c1cd1bc53688dbccdace637854b795eba2c","price":"0.43","side":"BUY","size":"162.94"},{"asset_id":"24254094493625419915756280046002869097156693848522361803041977572204227262166","best_ask":"0.56","best_bid":"0.55","hash":"630b6e9beceffdc8d2005a4a6b176c10bc7958bf","price":"0.57","side":"SELL","size":"162.94"}],"timestamp":"1785122358591"},"payload_hash":"fe5c1ba2b1cea6e7d1967f781353a4ff7e39e79ee3777a5e848b2c69c2f60c73","raw_frame":"{\"market\":\"0x717c0e8ccd4d5c7040185188fbae28be901ca589a11a94b1b38ca36a79eccfeb\", \"price_changes\":[{\"asset_id\":\"41448400836309843603620980831210604935021861034693225347475867885462478926555\", \"price\":\"0.43\", \"size\":\"162.94\", \"side\":\"BUY\", \"hash\":\"88340c1cd1bc53688dbccdace637854b795eba2c\", \"best_bid\":\"0.44\", \"best_ask\":\"0.45\"}, {\"asset_id\":\"24254094493625419915756280046002869097156693848522361803041977572204227262166\", \"price\":\"0.57\", \"size\":\"162.94\", \"side\":\"SELL\", \"hash\":\"630b6e9beceffdc8d2005a4a6b176c10bc7958bf\", \"best_bid\":\"0.55\", \"best_ask\":\"0.56\"}], \"timestamp\":\"1785122358591\", \"event_type\":\"price_change\"}","received_at":"2026-07-27T03:19:18.748264Z","schema_version":"clob-market-ws.price_change.v1","sequence":null,"server_hash":null,"server_timestamp":"1785122358591","session_id":"dd162b8dca5f43ff811d304e69a06123","source":"clob_market_ws"},"received_at":"2026-07-27T03:19:18.748264Z","record_id":"e91ee73cb8707249b25d8d888532b4689906311f6039c24c51ea117b79924957","schema_fingerprint":"4aa3821a28b0b7c2400bc59aba4bcc0a76e971dadd19610d3ad38c768e124dc7","schema_version":"edge-lab-recorder.raw.v1","sequence":null,"source":"clob_market_ws"}
{"event_at":"2026-07-27T03:19:18.592000Z","event_fingerprint":"7cd2738ff73b2ea958f07879cba103388bbc7c914787c42b2e86622bdb001df4","payload":{"connection_id":"c7dc2e4762f849c6b6f9306b6518dcab","event_at":"2026-07-27T03:19:18.592000Z","event_type":"price_change","frame_hash":"5e9793af94b841a5ac7b92823e04a20436bf31b50d0ea058110eb2548f13f5cb","frame_index":0,"kind":"data","monotonic_ns":224342092363833,"payload":{"event_type":"price_change","market":"0x717c0e8ccd4d5c7040185188fbae28be901ca589a11a94b1b38ca36a79eccfeb","price_changes":[{"asset_id":"41448400836309843603620980831210604935021861034693225347475867885462478926555","best_ask":"0.45","best_bid":"0.44","hash":"0bcc2d3f082ae96084e39e2af617bf480f4ceb3a","price":"0.44","side":"BUY","size":"93.4"},{"asset_id":"24254094493625419915756280046002869097156693848522361803041977572204227262166","best_ask":"0.56","best_bid":"0.55","hash":"aa697584c9433cb507ed79cb69e6df76a1d075a2","price":"0.56","side":"SELL","size":"93.4"}],"timestamp":"1785122358592"},"payload_hash":"161093e408f2cc94ef7fb136361861036c718230da7fd87e5d32ec573aca90a6","raw_frame":"{\"market\":\"0x717c0e8ccd4d5c7040185188fbae28be901ca589a11a94b1b38ca36a79eccfeb\", \"price_changes\":[{\"asset_id\":\"41448400836309843603620980831210604935021861034693225347475867885462478926555\", \"price\":\"0.44\", \"size\":\"93.4\", \"side\":\"BUY\", \"hash\":\"0bcc2d3f082ae96084e39e2af617bf480f4ceb3a\", \"best_bid\":\"0.44\", \"best_ask\":\"0.45\"}, {\"asset_id\":\"24254094493625419915756280046002869097156693848522361803041977572204227262166\", \"price\":\"0.56\", \"size\":\"93.4\", \"side\":\"SELL\", \"hash\":\"aa697584c9433cb507ed79cb69e6df76a1d075a2\", \"best_bid\":\"0.55\", \"best_ask\":\"0.56\"}], \"timestamp\":\"1785122358592\", \"event_type\":\"price_change\"}","received_at":"2026-07-27T03:19:18.755071Z","schema_version":"clob-market-ws.price_change.v1","sequence":null,"server_hash":null,"server_timestamp":"1785122358592","session_id":"dd162b8dca5f43ff811d304e69a06123","source":"clob_market_ws"},"received_at":"2026-07-27T03:19:18.755071Z","record_id":"2b52e171c3e6e0ca6de4f4b1f889d082a2935b5fce12120b79f95384c138448c","schema_fingerprint":"4aa3821a28b0b7c2400bc59aba4bcc0a76e971dadd19610d3ad38c768e124dc7","schema_version":"edge-lab-recorder.raw.v1","sequence":null,"source":"clob_market_ws"}
{"event_at":"2026-07-27T03:19:18.592000Z","event_fingerprint":"ee7d6ca27b1f6ed92edd804cccad9b50cc633d52ba0866f089a3e78f8321803b","payload":{"connection_id":"c7dc2e4762f849c6b6f9306b6518dcab","event_at":"2026-07-27T03:19:18.592000Z","event_type":"price_change","frame_hash":"3763ae27d763194e07ba2309c81bc15d6937edf6b3fc434e94a34256d3f24d89","frame_index":0,"kind":"data","monotonic_ns":224342095760208,"payload":{"event_type":"price_change","market":"0x717c0e8ccd4d5c7040185188fbae28be901ca589a11a94b1b38ca36a79eccfeb","price_changes":[{"asset_id":"41448400836309843603620980831210604935021861034693225347475867885462478926555","best_ask":"0.45","best_bid":"0.44","hash":"fb86036ac86af28d8ee27362f32840ab9a19d95e","price":"0.44","side":"BUY","size":"98.94"},{"asset_id":"24254094493625419915756280046002869097156693848522361803041977572204227262166","best_ask":"0.56","best_bid":"0.55","hash":"368713ba41f646c273ab80c9a3eec7eb3e87a81c","price":"0.56","side":"SELL","size":"98.94"}],"timestamp":"1785122358592"},"payload_hash":"225daba50680e9c3a94f195e94bf43ced014a5d9e062c92cfe692ca3eda82c01","raw_frame":"{\"market\":\"0x717c0e8ccd4d5c7040185188fbae28be901ca589a11a94b1b38ca36a79eccfeb\", \"price_changes\":[{\"asset_id\":\"41448400836309843603620980831210604935021861034693225347475867885462478926555\", \"price\":\"0.44\", \"size\":\"98.94\", \"side\":\"BUY\", \"hash\":\"fb86036ac86af28d8ee27362f32840ab9a19d95e\", \"best_bid\":\"0.44\", \"best_ask\":\"0.45\"}, {\"asset_id\":\"24254094493625419915756280046002869097156693848522361803041977572204227262166\", \"price\":\"0.56\", \"size\":\"98.94\", \"side\":\"SELL\", \"hash\":\"368713ba41f646c273ab80c9a3eec7eb3e87a81c\", \"best_bid\":\"0.55\", \"best_ask\":\"0.56\"}], \"timestamp\":\"1785122358592\", \"event_type\":\"price_change\"}","received_at":"2026-07-27T03:19:18.758465Z","schema_version":"clob-market-ws.price_change.v1","sequence":null,"server_hash":null,"server_timestamp":"1785122358592","session_id":"dd162b8dca5f43ff811d304e69a06123","source":"clob_market_ws"},"received_at":"2026-07-27T03:19:18.758465Z","record_id":"53db198041de2ccb44e8f1b29587a0245fd08cbc172d041b0859bdaa738e3f58","schema_fingerprint":"4aa3821a28b0b7c2400bc59aba4bcc0a76e971dadd19610d3ad38c768e124dc7","schema_version":"edge-lab-recorder.raw.v1","sequence":null,"source":"clob_market_ws"}
{"event_at":"2026-07-27T03:19:18.593000Z","event_fingerprint":"b2aa352518154171a34b44a8f8d9a8942d3ae03cd0e524d2d65356a0b69eda04","payload":{"connection_id":"c7dc2e4762f849c6b6f9306b6518dcab","event_at":"2026-07-27T03:19:18.593000Z","event_type":"price_change","frame_hash":"4a73fcf80320c8f79d575e0840c992828085ee0ad931880496fccf5bf7796927","frame_index":0,"kind":"data","monotonic_ns":224342098795875,"payload":{"event_type":"price_change","market":"0x717c0e8ccd4d5c7040185188fbae28be901ca589a11a94b1b38ca36a79eccfeb","price_changes":[{"asset_id":"24254094493625419915756280046002869097156693848522361803041977572204227262166","best_ask":"0.56","best_bid":"0.55","hash":"6356e39a5ef3f188e58f2ccbff68772e6f607716","price":"0.49","side":"BUY","size":"32"},{"asset_id":"41448400836309843603620980831210604935021861034693225347475867885462478926555","best_ask":"0.45","best_bid":"0.44","hash":"a36ec09a46ffe7f04c171749ae0872f3f20fa47a","price":"0.51","side":"SELL","size":"32"}],"timestamp":"1785122358593"},"payload_hash":"5a82948ca6264acf6eeef0a46b8325c9b096c7cbc91a2ada6ccf350752bab122","raw_frame":"{\"market\":\"0x717c0e8ccd4d5c7040185188fbae28be901ca589a11a94b1b38ca36a79eccfeb\", \"price_changes\":[{\"asset_id\":\"24254094493625419915756280046002869097156693848522361803041977572204227262166\", \"price\":\"0.49\", \"size\":\"32\", \"side\":\"BUY\", \"hash\":\"6356e39a5ef3f188e58f2ccbff68772e6f607716\", \"best_bid\":\"0.55\", \"best_ask\":\"0.56\"}, {\"asset_id\":\"41448400836309843603620980831210604935021861034693225347475867885462478926555\", \"price\":\"0.51\", \"size\":\"32\", \"side\":\"SELL\", \"hash\":\"a36ec09a46ffe7f04c171749ae0872f3f20fa47a\", \"best_bid\":\"0.44\", \"best_ask\":\"0.45\"}], \"timestamp\":\"1785122358593\", \"event_type\":\"price_change\"}","received_at":"2026-07-27T03:19:18.761503Z","schema_version":"clob-market-ws.price_change.v1","sequence":null,"server_hash":null,"server_timestamp":"1785122358593","session_id":"dd162b8dca5f43ff811d304e69a06123","source":"clob_market_ws"},"received_at":"2026-07-27T03:19:18.761503Z","record_id":"982a9cc8f1483383c148018cca70da3eb04f5f2dc5516e3e4487eebcaad6341b","schema_fingerprint":"4aa3821a28b0b7c2400bc59aba4bcc0a76e971dadd19610d3ad38c768e124dc7","schema_version":"edge-lab-recorder.raw.v1","sequence":null,"source":"clob_market_ws"}
{"event_at":"2026-07-27T03:19:18.595000Z","event_fingerprint":"c9adc8e4b14cad0cf932764dad74d3bf01cbb963db5ee0e68d774df6a98370dc","payload":{"connection_id":"c7dc2e4762f849c6b6f9306b6518dcab","event_at":"2026-07-27T03:19:18.595000Z","event_type":"price_change","frame_hash":"07f53b1b33bead1d073a033d8f6c84fd8837ad642e43c0925cddfd5bc69cc870","frame_index":0,"kind":"data","monotonic_ns":224342101804916,"payload":{"event_type":"price_change","market":"0x717c0e8ccd4d5c7040185188fbae28be901ca589a11a94b1b38ca36a79eccfeb","price_changes":[{"asset_id":"41448400836309843603620980831210604935021861034693225347475867885462478926555","best_ask":"0.45","best_bid":"0.44","hash":"8efd61637c169a0af616f3f9342db3cfcfd3b2bb","price":"0.37","side":"BUY","size":"24.79"},{"asset_id":"24254094493625419915756280046002869097156693848522361803041977572204227262166","best_ask":"0.56","best_bid":"0.55","hash":"f1d6a09afedfb6824012b27b95f5a8aeb25620e0","price":"0.63","side":"SELL","size":"24.79"}],"timestamp":"1785122358595"},"payload_hash":"7bd5498ad2acab8006da663eacd86517ee09774ce0c888eb09f8e81cb359c4d1","raw_frame":"{\"market\":\"0x717c0e8ccd4d5c7040185188fbae28be901ca589a11a94b1b38ca36a79eccfeb\", \"price_changes\":[{\"asset_id\":\"41448400836309843603620980831210604935021861034693225347475867885462478926555\", \"price\":\"0.37\", \"size\":\"24.79\", \"side\":\"BUY\", \"hash\":\"8efd61637c169a0af616f3f9342db3cfcfd3b2bb\", \"best_bid\":\"0.44\", \"best_ask\":\"0.45\"}, {\"asset_id\":\"24254094493625419915756280046002869097156693848522361803041977572204227262166\", \"price\":\"0.63\", \"size\":\"24.79\", \"side\":\"SELL\", \"hash\":\"f1d6a09afedfb6824012b27b95f5a8aeb25620e0\", \"best_bid\":\"0.55\", \"best_ask\":\"0.56\"}], \"timestamp\":\"1785122358595\", \"event_type\":\"price_change\"}","received_at":"2026-07-27T03:19:18.764512Z","schema_version":"clob-market-ws.price_change.v1","sequence":null,"server_hash":null,"server_timestamp":"1785122358595","session_id":"dd162b8dca5f43ff811d304e69a06123","source":"clob_market_ws"},"received_at":"2026-07-27T03:19:18.764512Z","record_id":"efd525b13a070d4050c248cfa7ede35ffb2773f8cd4289787d62a01d3f5eb3a1","schema_fingerprint":"4aa3821a28b0b7c2400bc59aba4bcc0a76e971dadd19610d3ad38c768e124dc7","schema_version":"edge-lab-recorder.raw.v1","sequence":null,"source":"clob_market_ws"}
{"event_at":"2026-07-27T03:19:18.595000Z","event_fingerprint":"331e005a4d0c4b119bd332b6c81373ee25ac4be0b012f4c224f02760079ee0fd","payload":{"connection_id":"c7dc2e4762f849c6b6f9306b6518dcab","event_at":"2026-07-27T03:19:18.595000Z","event_type":"price_change","frame_hash":"6197c1993d5db102cc56c13fb7c3ce66068523654425213662f20a59ce75c3c5","frame_index":0,"kind":"data","monotonic_ns":224342106080250,"payload":{"event_type":"price_change","market":"0x717c0e8ccd4d5c7040185188fbae28be901ca589a11a94b1b38ca36a79eccfeb","price_changes":[{"asset_id":"24254094493625419915756280046002869097156693848522361803041977572204227262166","best_ask":"0.56","best_bid":"0.55","hash":"b9aa330bd5ca95603bf1fc9abf9d56ea9999f5ab","price":"0.5","side":"BUY","size":"162.38"},{"asset_id":"41448400836309843603620980831210604935021861034693225347475867885462478926555","best_ask":"0.45","best_bid":"0.44","hash":"565145e29e7c3211d5cc2bf48b19ab42fe166150","price":"0.5","side":"SELL","size":"162.38"}],"timestamp":"1785122358595"},"payload_hash":"3f0ef8274943af4280942634ca6349b492b5acd3b80126e1bd2abf4baefbd0bf","raw_frame":"{\"market\":\"0x717c0e8ccd4d5c7040185188fbae28be901ca589a11a94b1b38ca36a79eccfeb\", \"price_changes\":[{\"asset_id\":\"24254094493625419915756280046002869097156693848522361803041977572204227262166\", \"price\":\"0.5\", \"size\":\"162.38\", \"side\":\"BUY\", \"hash\":\"b9aa330bd5ca95603bf1fc9abf9d56ea9999f5ab\", \"best_bid\":\"0.55\", \"best_ask\":\"0.56\"}, {\"asset_id\":\"41448400836309843603620980831210604935021861034693225347475867885462478926555\", \"price\":\"0.5\", \"size\":\"162.38\", \"side\":\"SELL\", \"hash\":\"565145e29e7c3211d5cc2bf48b19ab42fe166150\", \"best_bid\":\"0.44\", \"best_ask\":\"0.45\"}], \"timestamp\":\"1785122358595\", \"event_type\":\"price_change\"}","received_at":"2026-07-27T03:19:18.768789Z","schema_version":"clob-market-ws.price_change.v1","sequence":null,"server_hash":null,"server_timestamp":"1785122358595","session_id":"dd162b8dca5f43ff811d304e69a06123","source":"clob_market_ws"},"received_at":"2026-07-27T03:19:18.768789Z","record_id":"def7c621af20f619d777cf4624e9d15d228274655d4552603196205074923455","schema_fingerprint":"4aa3821a28b0b7c2400bc59aba4bcc0a76e971dadd19610d3ad38c768e124dc7","schema_version":"edge-lab-recorder.raw.v1","sequence":null,"source":"clob_market_ws"}
{"event_at":"2026-07-27T03:19:18.605000Z","event_fingerprint":"0e9b0c8f5b8536182dc7ee79377f2500d26f183a65ca4bef95ee2de9642f813e","payload":{"connection_id":"c7dc2e4762f849c6b6f9306b6518dcab","event_at":"2026-07-27T03:19:18.605000Z","event_type":"price_change","frame_hash":"c9ca0521d9cd8e737abaa22767dc7dda0369ae404b247926742bc705b1c8734b","frame_index":0,"kind":"data","monotonic_ns":224342108349291,"payload":{"event_type":"price_change","market":"0x717c0e8ccd4d5c7040185188fbae28be901ca589a11a94b1b38ca36a79eccfeb","price_changes":[{"asset_id":"41448400836309843603620980831210604935021861034693225347475867885462478926555","best_ask":"0.45","best_bid":"0.44","hash":"b9e805e22e05162cd7400cb7405f4838e6d199f8","price":"0.44","side":"BUY","size":"58.94"},{"asset_id":"24254094493625419915756280046002869097156693848522361803041977572204227262166","best_ask":"0.56","best_bid":"0.55","hash":"bcd60ee0bc52b9e151323eaa9115f220184a0c96","price":"0.56","side":"SELL","size":"58.94"}],"timestamp":"1785122358605"},"payload_hash":"2b6844eb7a1d48d3f5eb9dc7665d440efeaf90f6a29509bddb78ee4fee94a14b","raw_frame":"{\"market\":\"0x717c0e8ccd4d5c7040185188fbae28be901ca589a11a94b1b38ca36a79eccfeb\", \"price_changes\":[{\"asset_id\":\"41448400836309843603620980831210604935021861034693225347475867885462478926555\", \"price\":\"0.44\", \"size\":\"58.94\", \"side\":\"BUY\", \"hash\":\"b9e805e22e05162cd7400cb7405f4838e6d199f8\", \"best_bid\":\"0.44\", \"best_ask\":\"0.45\"}, {\"asset_id\":\"24254094493625419915756280046002869097156693848522361803041977572204227262166\", \"price\":\"0.56\", \"size\":\"58.94\", \"side\":\"SELL\", \"hash\":\"bcd60ee0bc52b9e151323eaa9115f220184a0c96\", \"best_bid\":\"0.55\", \"best_ask\":\"0.56\"}], \"timestamp\":\"1785122358605\", \"event_type\":\"price_change\"}","received_at":"2026-07-27T03:19:18.771058Z","schema_version":"clob-market-ws.price_change.v1","sequence":null,"server_hash":null,"server_timestamp":"1785122358605","session_id":"dd162b8dca5f43ff811d304e69a06123","source":"clob_market_ws"},"received_at":"2026-07-27T03:19:18.771058Z","record_id":"70193029709ddc2f1c474ebff28ccd8ff05f5763580669f1fe98421cf94224d5","schema_fingerprint":"4aa3821a28b0b7c2400bc59aba4bcc0a76e971dadd19610d3ad38c768e124dc7","schema_version":"edge-lab-recorder.raw.v1","sequence":null,"source":"clob_market_ws"}
{"event_at":"2026-07-27T03:19:18.605000Z","event_fingerprint":"feddd93d61bb9a7f5f30c624e8f910cd5629b1b2c0eee2b163a71043ab33b5d4","payload":{"connection_id":"c7dc2e4762f849c6b6f9306b6518dcab","event_at":"2026-07-27T03:19:18.605000Z","event_type":"price_change","frame_hash":"c8cba176aa22a0d276dba81e67034a7c48d8fb600eb2609849e2da2e1ede29de","frame_index":0,"kind":"data","monotonic_ns":224342110716333,"payload":{"event_type":"price_change","market":"0x717c0e8ccd4d5c7040185188fbae28be901ca589a11a94b1b38ca36a79eccfeb","price_changes":[{"asset_id":"41448400836309843603620980831210604935021861034693225347475867885462478926555","best_ask":"0.45","best_bid":"0.44","hash":"11d6705c19c9bbea499fb8d8cff12bff7da00628","price":"0.44","side":"BUY","size":"53.94"},{"asset_id":"24254094493625419915756280046002869097156693848522361803041977572204227262166","best_ask":"0.56","best_bid":"0.55","hash":"f422fba5a699d47846bd57b28333ab8ed9a154e9","price":"0.56","side":"SELL","size":"53.94"}],"timestamp":"1785122358605"},"payload_hash":"2323632a8792ab2b22ee9d10ec71d173c0c25961f6d8d5987d47cbe358f9e3ee","raw_frame":"{\"market\":\"0x717c0e8ccd4d5c7040185188fbae28be901ca589a11a94b1b38ca36a79eccfeb\", \"price_changes\":[{\"asset_id\":\"41448400836309843603620980831210604935021861034693225347475867885462478926555\", \"price\":\"0.44\", \"size\":\"53.94\", \"side\":\"BUY\", \"hash\":\"11d6705c19c9bbea499fb8d8cff12bff7da00628\", \"best_bid\":\"0.44\", \"best_ask\":\"0.45\"}, {\"asset_id\":\"24254094493625419915756280046002869097156693848522361803041977572204227262166\", \"price\":\"0.56\", \"size\":\"53.94\", \"side\":\"SELL\", \"hash\":\"f422fba5a699d47846bd57b28333ab8ed9a154e9\", \"best_bid\":\"0.55\", \"best_ask\":\"0.56\"}], \"timestamp\":\"1785122358605\", \"event_type\":\"price_change\"}","received_at":"2026-07-27T03:19:18.773422Z","schema_version":"clob-market-ws.price_change.v1","sequence":null,"server_hash":null,"server_timestamp":"1785122358605","session_id":"dd162b8dca5f43ff811d304e69a06123","source":"clob_market_ws"},"received_at":"2026-07-27T03:19:18.773422Z","record_id":"a54518388354527f7d0f2365536274b5bb0045d27a6f18c1a9c673bb88c62e91","schema_fingerprint":"4aa3821a28b0b7c2400bc59aba4bcc0a76e971dadd19610d3ad38c768e124dc7","schema_version":"edge-lab-recorder.raw.v1","sequence":null,"source":"clob_market_ws"}
{"event_at":"2026-07-27T03:19:18.606000Z","event_fingerprint":"196618ddf02adbe3090a0d0e4ff7f8503d3b47e9b0361528002031e45acd0231","payload":{"connection_id":"c7dc2e4762f849c6b6f9306b6518dcab","event_at":"2026-07-27T03:19:18.606000Z","event_type":"price_change","frame_hash":"db06a8dc5779f4539f886694c4129103da4899116fa6348a544612e6c28d9d01","frame_index":0,"kind":"data","monotonic_ns":224342114029416,"payload":{"event_type":"price_change","market":"0x717c0e8ccd4d5c7040185188fbae28be901ca589a11a94b1b38ca36a79eccfeb","price_changes":[{"asset_id":"41448400836309843603620980831210604935021861034693225347475867885462478926555","best_ask":"0.45","best_bid":"0.44","hash":"9d6e35b4a9c2a27f485a89eea07a585e9275cef1","price":"0.34","side":"BUY","size":"180.29"},{"asset_id":"24254094493625419915756280046002869097156693848522361803041977572204227262166","best_ask":"0.56","best_bid":"0.55","hash":"6c8f2b5b3e9dc823ea1edd5dfb0f6cf07f603ef7","price":"0.66","side":"SELL","size":"180.29"}],"timestamp":"1785122358606"},"payload_hash":"9215dd6e027139ffd76ffd3d118ea3643d00719c366d10227b7767d84a2bf3d9","raw_frame":"{\"market\":\"0x717c0e8ccd4d5c7040185188fbae28be901ca589a11a94b1b38ca36a79eccfeb\", \"price_changes\":[{\"asset_id\":\"41448400836309843603620980831210604935021861034693225347475867885462478926555\", \"price\":\"0.34\", \"size\":\"180.29\", \"side\":\"BUY\", \"hash\":\"9d6e35b4a9c2a27f485a89eea07a585e9275cef1\", \"best_bid\":\"0.44\", \"best_ask\":\"0.45\"}, {\"asset_id\":\"24254094493625419915756280046002869097156693848522361803041977572204227262166\", \"price\":\"0.66\", \"size\":\"180.29\", \"side\":\"SELL\", \"hash\":\"6c8f2b5b3e9dc823ea1edd5dfb0f6cf07f603ef7\", \"best_bid\":\"0.55\", \"best_ask\":\"0.56\"}], \"timestamp\":\"1785122358606\", \"event_type\":\"price_change\"}","received_at":"2026-07-27T03:19:18.776738Z","schema_version":"clob-market-ws.price_change.v1","sequence":null,"server_hash":null,"server_timestamp":"1785122358606","session_id":"dd162b8dca5f43ff811d304e69a06123","source":"clob_market_ws"},"received_at":"2026-07-27T03:19:18.776738Z","record_id":"4e6e274eee76a203ab348d89584ec0b5bcd4ba7cc087356909675354e221b8df","schema_fingerprint":"4aa3821a28b0b7c2400bc59aba4bcc0a76e971dadd19610d3ad38c768e124dc7","schema_version":"edge-lab-recorder.raw.v1","sequence":null,"source":"clob_market_ws"}
{"event_at":"2026-07-27T03:19:18.608000Z","event_fingerprint":"53673cb292d019d0e5dab2068b5fee87505487f479989db37bb525090a1cb741","payload":{"connection_id":"c7dc2e4762f849c6b6f9306b6518dcab","event_at":"2026-07-27T03:19:18.608000Z","event_type":"price_change","frame_hash":"09fa56fce6fce6700a3ad8989c2c25a6a4e4eb05b24b60717a41655392ce2ffa","frame_index":0,"kind":"data","monotonic_ns":224342117090458,"payload":{"event_type":"price_change","market":"0x717c0e8ccd4d5c7040185188fbae28be901ca589a11a94b1b38ca36a79eccfeb","price_changes":[{"asset_id":"41448400836309843603620980831210604935021861034693225347475867885462478926555","best_ask":"0.45","best_bid":"0.44","hash":"99458901b2bf2c03b61cf261ff04ba3c653ba5f1","price":"0.38","side":"BUY","size":"14.6"},{"asset_id":"24254094493625419915756280046002869097156693848522361803041977572204227262166","best_ask":"0.56","best_bid":"0.55","hash":"8f708158a4b94d01063f1c651b920902f80fd56e","price":"0.62","side":"SELL","size":"14.6"}],"timestamp":"1785122358608"},"payload_hash":"4423a8c628ef26ddadcdb85678bae4ae83419bc60d69c3789ec62a29289078ad","raw_frame":"{\"market\":\"0x717c0e8ccd4d5c7040185188fbae28be901ca589a11a94b1b38ca36a79eccfeb\", \"price_changes\":[{\"asset_id\":\"41448400836309843603620980831210604935021861034693225347475867885462478926555\", \"price\":\"0.38\", \"size\":\"14.6\", \"side\":\"BUY\", \"hash\":\"99458901b2bf2c03b61cf261ff04ba3c653ba5f1\", \"best_bid\":\"0.44\", \"best_ask\":\"0.45\"}, {\"asset_id\":\"24254094493625419915756280046002869097156693848522361803041977572204227262166\", \"price\":\"0.62\", \"size\":\"14.6\", \"side\":\"SELL\", \"hash\":\"8f708158a4b94d01063f1c651b920902f80fd56e\", \"best_bid\":\"0.55\", \"best_ask\":\"0.56\"}], \"timestamp\":\"1785122358608\", \"event_type\":\"price_change\"}","received_at":"2026-07-27T03:19:18.779798Z","schema_version":"clob-market-ws.price_change.v1","sequence":null,"server_hash":null,"server_timestamp":"1785122358608","session_id":"dd162b8dca5f43ff811d304e69a06123","source":"clob_market_ws"},"received_at":"2026-07-27T03:19:18.779798Z","record_id":"81d6a3637f3354b9106e4c353bdd9fe0ef1c3195e06d46e75cafa1d69c95aff0","schema_fingerprint":"4aa3821a28b0b7c2400bc59aba4bcc0a76e971dadd19610d3ad38c768e124dc7","schema_version":"edge-lab-recorder.raw.v1","sequence":null,"source":"clob_market_ws"}
{"event_at":"2026-07-27T03:19:18.611000Z","event_fingerprint":"9bd15f673e4a7df82926fd9d6859eef990d9b6d8aec2359bcc3a4b64d9239c29","payload":{"connection_id":"c7dc2e4762f849c6b6f9306b6518dcab","event_at":"2026-07-27T03:19:18.611000Z","event_type":"price_change","frame_hash":"01d01030828f8876eb9499ffb3bba03887d1525c5310562805314343aacbc64b","frame_index":0,"kind":"data","monotonic_ns":224342120052500,"payload":{"event_type":"price_change","market":"0x717c0e8ccd4d5c7040185188fbae28be901ca589a11a94b1b38ca36a79eccfeb","price_changes":[{"asset_id":"24254094493625419915756280046002869097156693848522361803041977572204227262166","best_ask":"0.56","best_bid":"0.55","hash":"7b6f5693a6c24f66d93351a3e99d643596173cf0","price":"0.54","side":"BUY","size":"27.66"},{"asset_id":"41448400836309843603620980831210604935021861034693225347475867885462478926555","best_ask":"0.45","best_bid":"0.44","hash":"73d839b59768b188c174e16b5011ed9c3aafcc83","price":"0.46","side":"SELL","size":"27.66"}],"timestamp":"1785122358611"},"payload_hash":"5db92cc2703aad8b4adfa1fb2398ddd8de28f50555927774435cd2297fc045d4","raw_frame":"{\"market\":\"0x717c0e8ccd4d5c7040185188fbae28be901ca589a11a94b1b38ca36a79eccfeb\", \"price_changes\":[{\"asset_id\":\"24254094493625419915756280046002869097156693848522361803041977572204227262166\", \"price\":\"0.54\", \"size\":\"27.66\", \"side\":\"BUY\", \"hash\":\"7b6f5693a6c24f66d93351a3e99d643596173cf0\", \"best_bid\":\"0.55\", \"best_ask\":\"0.56\"}, {\"asset_id\":\"41448400836309843603620980831210604935021861034693225347475867885462478926555\", \"price\":\"0.46\", \"size\":\"27.66\", \"side\":\"SELL\", \"hash\":\"73d839b59768b188c174e16b5011ed9c3aafcc83\", \"best_bid\":\"0.44\", \"best_ask\":\"0.45\"}], \"timestamp\":\"1785122358611\", \"event_type\":\"price_change\"}","received_at":"2026-07-27T03:19:18.782761Z","schema_version":"clob-market-ws.price_change.v1","sequence":null,"server_hash":null,"server_timestamp":"1785122358611","session_id":"dd162b8dca5f43ff811d304e69a06123","source":"clob_market_ws"},"received_at":"2026-07-27T03:19:18.782761Z","record_id":"50125f2c59bdc5d62fb084683012dd3827f0e6e28495b31b00bb65a6d32f50f8","schema_fingerprint":"4aa3821a28b0b7c2400bc59aba4bcc0a76e971dadd19610d3ad38c768e124dc7","schema_version":"edge-lab-recorder.raw.v1","sequence":null,"source":"clob_market_ws"}
{"event_at":"2026-07-27T03:19:18.612000Z","event_fingerprint":"9530788d0a1b081abecfd81d1ea7a607d6cb9b52c0b6a69b1149504f86a8d697","payload":{"connection_id":"c7dc2e4762f849c6b6f9306b6518dcab","event_at":"2026-07-27T03:19:18.612000Z","event_type":"best_bid_ask","frame_hash":"ea4118fb79766b10300eefb959d885eb0fe75bfbcebf8834ff2211b4ef80032c","frame_index":0,"kind":"data","monotonic_ns":224342123162833,"payload":{"asset_id":"24254094493625419915756280046002869097156693848522361803041977572204227262166","best_ask":"0.56","best_bid":"0.54","event_type":"best_bid_ask","market":"0x717c0e8ccd4d5c7040185188fbae28be901ca589a11a94b1b38ca36a79eccfeb","spread":"0.02","timestamp":"1785122358612"},"payload_hash":"1a0bc7cde35ee31309e5bf7ba8c09192c054f64dc1c0c3972ccad39eb8d01787","raw_frame":"{\"market\":\"0x717c0e8ccd4d5c7040185188fbae28be901ca589a11a94b1b38ca36a79eccfeb\", \"asset_id\":\"24254094493625419915756280046002869097156693848522361803041977572204227262166\", \"best_bid\":\"0.54\", \"best_ask\":\"0.56\", \"spread\":\"0.02\", \"timestamp\":\"1785122358612\", \"event_type\":\"best_bid_ask\"}","received_at":"2026-07-27T03:19:18.785871Z","schema_version":"clob-market-ws.best_bid_ask.v1","sequence":null,"server_hash":null,"server_timestamp":"1785122358612","session_id":"dd162b8dca5f43ff811d304e69a06123","source":"clob_market_ws"},"received_at":"2026-07-27T03:19:18.785871Z","record_id":"95790bb1c8be86a7a53eeb9816ba5c30877abca6a2c2f46c63793c5351477a21","schema_fingerprint":"8488399f31b0337811b13b266be932db7062827c2470b78bd8e9e99bab51d17d","schema_version":"edge-lab-recorder.raw.v1","sequence":null,"source":"clob_market_ws"}
{"event_at":"2026-07-27T03:19:18.612000Z","event_fingerprint":"9288d05e676bd6a528d0075f6059b3c7129ef4a68c99a9b9599bbe170f7f24cd","payload":{"connection_id":"c7dc2e4762f849c6b6f9306b6518dcab","event_at":"2026-07-27T03:19:18.612000Z","event_type":"best_bid_ask","frame_hash":"dd698347b18a20fac4871c02fca4524e6a774761bf5c915828ad6f11d8139872","frame_index":0,"kind":"data","monotonic_ns":224342125752250,"payload":{"asset_id":"41448400836309843603620980831210604935021861034693225347475867885462478926555","best_ask":"0.46","best_bid":"0.44","event_type":"best_bid_ask","market":"0x717c0e8ccd4d5c7040185188fbae28be901ca589a11a94b1b38ca36a79eccfeb","spread":"0.02","timestamp":"1785122358612"},"payload_hash":"453dface1aa2199579e3c3d9a69630b9e4b7b971135438a82177d8ae2872a2d7","raw_frame":"{\"market\":\"0x717c0e8ccd4d5c7040185188fbae28be901ca589a11a94b1b38ca36a79eccfeb\", \"asset_id\":\"41448400836309843603620980831210604935021861034693225347475867885462478926555\", \"best_bid\":\"0.44\", \"best_ask\":\"0.46\", \"spread\":\"0.02\", \"timestamp\":\"1785122358612\", \"event_type\":\"best_bid_ask\"}","received_at":"2026-07-27T03:19:18.788460Z","schema_version":"clob-market-ws.best_bid_ask.v1","sequence":null,"server_hash":null,"server_timestamp":"1785122358612","session_id":"dd162b8dca5f43ff811d304e69a06123","source":"clob_market_ws"},"received_at":"2026-07-27T03:19:18.788460Z","record_id":"72dd5ee7251547632df0c6483fa8474ddcf30eb0fc2e5268aa6eaf8fb3ec024c","schema_fingerprint":"8488399f31b0337811b13b266be932db7062827c2470b78bd8e9e99bab51d17d","schema_version":"edge-lab-recorder.raw.v1","sequence":null,"source":"clob_market_ws"}
{"event_at":"2026-07-27T03:19:18.612000Z","event_fingerprint":"7fb34c74eb60e36ae82d549e2c283f37cc2a3e22d2327311d3816e99bcc76cc3","payload":{"connection_id":"c7dc2e4762f849c6b6f9306b6518dcab","event_at":"2026-07-27T03:19:18.612000Z","event_type":"price_change","frame_hash":"1bb4be88a5c993429017dc241858647855d661a4ed9f3bfd0b6df6057f1186d8","frame_index":0,"kind":"data","monotonic_ns":224342128488875,"payload":{"event_type":"price_change","market":"0x717c0e8ccd4d5c7040185188fbae28be901ca589a11a94b1b38ca36a79eccfeb","price_changes":[{"asset_id":"24254094493625419915756280046002869097156693848522361803041977572204227262166","best_ask":"0.56","best_bid":"0.54","hash":"5636bed0f93d8622e71ec70adf33f37acf1dd566","price":"0.55","side":"BUY","size":"0"},{"asset_id":"41448400836309843603620980831210604935021861034693225347475867885462478926555","best_ask":"0.46","best_bid":"0.44","hash":"c29733476c7eceac80adfd9c8f7f9f59348deac4","price":"0.45","side":"SELL","size":"0"}],"timestamp":"1785122358612"},"payload_hash":"eff3fb7cd4ac0985c3c8630208210564e996c7783a7cb18532c655b01214e64f","raw_frame":"{\"market\":\"0x717c0e8ccd4d5c7040185188fbae28be901ca589a11a94b1b38ca36a79eccfeb\", \"price_changes\":[{\"asset_id\":\"24254094493625419915756280046002869097156693848522361803041977572204227262166\", \"price\":\"0.55\", \"size\":\"0\", \"side\":\"BUY\", \"hash\":\"5636bed0f93d8622e71ec70adf33f37acf1dd566\", \"best_bid\":\"0.54\", \"best_ask\":\"0.56\"}, {\"asset_id\":\"41448400836309843603620980831210604935021861034693225347475867885462478926555\", \"price\":\"0.45\", \"size\":\"0\", \"side\":\"SELL\", \"hash\":\"c29733476c7eceac80adfd9c8f7f9f59348deac4\", \"best_bid\":\"0.44\", \"best_ask\":\"0.46\"}], \"timestamp\":\"1785122358612\", \"event_type\":\"price_change\"}","received_at":"2026-07-27T03:19:18.791196Z","schema_version":"clob-market-ws.price_change.v1","sequence":null,"server_hash":null,"server_timestamp":"1785122358612","session_id":"dd162b8dca5f43ff811d304e69a06123","source":"clob_market_ws"},"received_at":"2026-07-27T03:19:18.791196Z","record_id":"3aa0a4d24a97aec983b45da39d84e28d6cbb31ca820537ceea911923cc4b4476","schema_fingerprint":"4aa3821a28b0b7c2400bc59aba4bcc0a76e971dadd19610d3ad38c768e124dc7","schema_version":"edge-lab-recorder.raw.v1","sequence":null,"source":"clob_market_ws"}
{"event_at":"2026-07-27T03:19:18.612000Z","event_fingerprint":"c81649ac8f4796d4e2dec75f722771c430d13816f564f15403257368461461d6","payload":{"connection_id":"c7dc2e4762f849c6b6f9306b6518dcab","event_at":"2026-07-27T03:19:18.612000Z","event_type":"price_change","frame_hash":"dbe534d64f39f72e94572c34d5deea6e16d002cefa0cfcf94323ed397e361389","frame_index":0,"kind":"data","monotonic_ns":224342131060416,"payload":{"event_type":"price_change","market":"0x717c0e8ccd4d5c7040185188fbae28be901ca589a11a94b1b38ca36a79eccfeb","price_changes":[{"asset_id":"41448400836309843603620980831210604935021861034693225347475867885462478926555","best_ask":"0.46","best_bid":"0.44","hash":"01fdd7f6ffe0262b93a86389c9c7380b914d1664","price":"0.33","side":"BUY","size":"151"},{"asset_id":"24254094493625419915756280046002869097156693848522361803041977572204227262166","best_ask":"0.56","best_bid":"0.54","hash":"e3b7585f9f9026bd3fec167ffe08e1d1195e236d","price":"0.67","side":"SELL","size":"151"}],"timestamp":"1785122358612"},"payload_hash":"6eb93b0917f6dd05e6d2318074461a9e335f82880348b6fc84b71d7f688c591c","raw_frame":"{\"market\":\"0x717c0e8ccd4d5c7040185188fbae28be901ca589a11a94b1b38ca36a79eccfeb\", \"price_changes\":[{\"asset_id\":\"41448400836309843603620980831210604935021861034693225347475867885462478926555\", \"price\":\"0.33\", \"size\":\"151\", \"side\":\"BUY\", \"hash\":\"01fdd7f6ffe0262b93a86389c9c7380b914d1664\", \"best_bid\":\"0.44\", \"best_ask\":\"0.46\"}, {\"asset_id\":\"24254094493625419915756280046002869097156693848522361803041977572204227262166\", \"price\":\"0.67\", \"size\":\"151\", \"side\":\"SELL\", \"hash\":\"e3b7585f9f9026bd3fec167ffe08e1d1195e236d\", \"best_bid\":\"0.54\", \"best_ask\":\"0.56\"}], \"timestamp\":\"1785122358612\", \"event_type\":\"price_change\"}","received_at":"2026-07-27T03:19:18.793769Z","schema_version":"clob-market-ws.price_change.v1","sequence":null,"server_hash":null,"server_timestamp":"1785122358612","session_id":"dd162b8dca5f43ff811d304e69a06123","source":"clob_market_ws"},"received_at":"2026-07-27T03:19:18.793769Z","record_id":"5ddcf1fc9bf04413b9bebfd2d10482fd55ec67b9aec75ef142c36659fe0ac358","schema_fingerprint":"4aa3821a28b0b7c2400bc59aba4bcc0a76e971dadd19610d3ad38c768e124dc7","schema_version":"edge-lab-recorder.raw.v1","sequence":null,"source":"clob_market_ws"}
{"event_at":"2026-07-27T03:19:18.613000Z","event_fingerprint":"c3d23d0bee16ea410553c2a64507ba5cca34aa22c43cfbb0cbcef73ca705c99a","payload":{"connection_id":"c7dc2e4762f849c6b6f9306b6518dcab","event_at":"2026-07-27T03:19:18.613000Z","event_type":"price_change","frame_hash":"231f141a202447ee522a5404c77a4ef2afad6a1644a5d4024278ed2083ffda64","frame_index":0,"kind":"data","monotonic_ns":224342133469708,"payload":{"event_type":"price_change","market":"0x717c0e8ccd4d5c7040185188fbae28be901ca589a11a94b1b38ca36a79eccfeb","price_changes":[{"asset_id":"41448400836309843603620980831210604935021861034693225347475867885462478926555","best_ask":"0.46","best_bid":"0.44","hash":"d6af7b39b689a46e18217f9ae83467a80ea21ddf","price":"0.38","side":"BUY","size":"5"},{"asset_id":"24254094493625419915756280046002869097156693848522361803041977572204227262166","best_ask":"0.56","best_bid":"0.54","hash":"e2455e7a2727bfce22c0872d53cd5a9b73d5dff8","price":"0.62","side":"SELL","size":"5"}],"timestamp":"1785122358613"},"payload_hash":"9a73eb18a8123e417c4c180199feb08f1ac714f42716cfc24b030b1c5ef541e5","raw_frame":"{\"market\":\"0x717c0e8ccd4d5c7040185188fbae28be901ca589a11a94b1b38ca36a79eccfeb\", \"price_changes\":[{\"asset_id\":\"41448400836309843603620980831210604935021861034693225347475867885462478926555\", \"price\":\"0.38\", \"size\":\"5\", \"side\":\"BUY\", \"hash\":\"d6af7b39b689a46e18217f9ae83467a80ea21ddf\", \"best_bid\":\"0.44\", \"best_ask\":\"0.46\"}, {\"asset_id\":\"24254094493625419915756280046002869097156693848522361803041977572204227262166\", \"price\":\"0.62\", \"size\":\"5\", \"side\":\"SELL\", \"hash\":\"e2455e7a2727bfce22c0872d53cd5a9b73d5dff8\", \"best_bid\":\"0.54\", \"best_ask\":\"0.56\"}], \"timestamp\":\"1785122358613\", \"event_type\":\"price_change\"}","received_at":"2026-07-27T03:19:18.796177Z","schema_version":"clob-market-ws.price_change.v1","sequence":null,"server_hash":null,"server_timestamp":"1785122358613","session_id":"dd162b8dca5f43ff811d304e69a06123","source":"clob_market_ws"},"received_at":"2026-07-27T03:19:18.796177Z","record_id":"ba358e66e985342a9edea9c3096d2611b6d321b1a14afb021d452c57d146131f","schema_fingerprint":"4aa3821a28b0b7c2400bc59aba4bcc0a76e971dadd19610d3ad38c768e124dc7","schema_version":"edge-lab-recorder.raw.v1","sequence":null,"source":"clob_market_ws"}
{"event_at":"2026-07-27T03:19:18.613000Z","event_fingerprint":"d3cb6eff35364717ba2fd61a5bee9dda8ffd20621e2c2607e2183724f2d90e0b","payload":{"connection_id":"c7dc2e4762f849c6b6f9306b6518dcab","event_at":"2026-07-27T03:19:18.613000Z","event_type":"price_change","frame_hash":"c2524da555cc6541dd4f2ec291f9bd549b214406b516d32e6dd096adb4029de8","frame_index":0,"kind":"data","monotonic_ns":224342140040833,"payload":{"event_type":"price_change","market":"0x717c0e8ccd4d5c7040185188fbae28be901ca589a11a94b1b38ca36a79eccfeb","price_changes":[{"asset_id":"41448400836309843603620980831210604935021861034693225347475867885462478926555","best_ask":"0.46","best_bid":"0.44","hash":"426d617f646f362516519aa94cb213a7f4d3e58a","price":"0.23","side":"BUY","size":"23.89"},{"asset_id":"24254094493625419915756280046002869097156693848522361803041977572204227262166","best_ask":"0.56","best_bid":"0.54","hash":"86b74f128d7427e20ef2dbc426764ced4b2a05e8","price":"0.77","side":"SELL","size":"23.89"}],"timestamp":"1785122358613"},"payload_hash":"0d5897bbf1e282f7d7caa86c54d1c5846c625eb5cece08d340968cd015932f87","raw_frame":"{\"market\":\"0x717c0e8ccd4d5c7040185188fbae28be901ca589a11a94b1b38ca36a79eccfeb\", \"price_changes\":[{\"asset_id\":\"41448400836309843603620980831210604935021861034693225347475867885462478926555\", \"price\":\"0.23\", \"size\":\"23.89\", \"side\":\"BUY\", \"hash\":\"426d617f646f362516519aa94cb213a7f4d3e58a\", \"best_bid\":\"0.44\", \"best_ask\":\"0.46\"}, {\"asset_id\":\"24254094493625419915756280046002869097156693848522361803041977572204227262166\", \"price\":\"0.77\", \"size\":\"23.89\", \"side\":\"SELL\", \"hash\":\"86b74f128d7427e20ef2dbc426764ced4b2a05e8\", \"best_bid\":\"0.54\", \"best_ask\":\"0.56\"}], \"timestamp\":\"1785122358613\", \"event_type\":\"price_change\"}","received_at":"2026-07-27T03:19:18.802750Z","schema_version":"clob-market-ws.price_change.v1","sequence":null,"server_hash":null,"server_timestamp":"1785122358613","session_id":"dd162b8dca5f43ff811d304e69a06123","source":"clob_market_ws"},"received_at":"2026-07-27T03:19:18.802750Z","record_id":"9cf101d367e247b3dc5ecf7367ac4382f04c83162f1019c2186dd79ecf9b96ad","schema_fingerprint":"4aa3821a28b0b7c2400bc59aba4bcc0a76e971dadd19610d3ad38c768e124dc7","schema_version":"edge-lab-recorder.raw.v1","sequence":null,"source":"clob_market_ws"}
{"event_at":"2026-07-27T03:19:18.614000Z","event_fingerprint":"a06f4ca23f080b0d6164513fd08eb2d3570d381ea814a1831a5e1f35e2fc38c6","payload":{"connection_id":"c7dc2e4762f849c6b6f9306b6518dcab","event_at":"2026-07-27T03:19:18.614000Z","event_type":"price_change","frame_hash":"222d28ee0a9f9e13810cf6988a26baad86147d6aaa15b32b29485e738d9d02e4","frame_index":0,"kind":"data","monotonic_ns":224342146567750,"payload":{"event_type":"price_change","market":"0x717c0e8ccd4d5c7040185188fbae28be901ca589a11a94b1b38ca36a79eccfeb","price_changes":[{"asset_id":"41448400836309843603620980831210604935021861034693225347475867885462478926555","best_ask":"0.46","best_bid":"0.44","hash":"73ce2726609aa8620bdcddb3cceee86c55205374","price":"0.44","side":"BUY","size":"60.94"},{"asset_id":"24254094493625419915756280046002869097156693848522361803041977572204227262166","best_ask":"0.56","best_bid":"0.54","hash":"da1ab3abd08d7943383db4011494d025d193da1b","price":"0.56","side":"SELL","size":"60.94"}],"timestamp":"1785122358614"},"payload_hash":"b93b66f4ddde0c0714224713e7b2c43ab8e3dd525a6c47d27137996c45b5c426","raw_frame":"{\"market\":\"0x717c0e8ccd4d5c7040185188fbae28be901ca589a11a94b1b38ca36a79eccfeb\", \"price_changes\":[{\"asset_id\":\"41448400836309843603620980831210604935021861034693225347475867885462478926555\", \"price\":\"0.44\", \"size\":\"60.94\", \"side\":\"BUY\", \"hash\":\"73ce2726609aa8620bdcddb3cceee86c55205374\", \"best_bid\":\"0.44\", \"best_ask\":\"0.46\"}, {\"asset_id\":\"24254094493625419915756280046002869097156693848522361803041977572204227262166\", \"price\":\"0.56\", \"size\":\"60.94\", \"side\":\"SELL\", \"hash\":\"da1ab3abd08d7943383db4011494d025d193da1b\", \"best_bid\":\"0.54\", \"best_ask\":\"0.56\"}], \"timestamp\":\"1785122358614\", \"event_type\":\"price_change\"}","received_at":"2026-07-27T03:19:18.809270Z","schema_version":"clob-market-ws.price_change.v1","sequence":null,"server_hash":null,"server_timestamp":"1785122358614","session_id":"dd162b8dca5f43ff811d304e69a06123","source":"clob_market_ws"},"received_at":"2026-07-27T03:19:18.809270Z","record_id":"4a9687584dc99533d1986e44ad5dd105bfa36510c0f510aa013f84a4a7eef1e0","schema_fingerprint":"4aa3821a28b0b7c2400bc59aba4bcc0a76e971dadd19610d3ad38c768e124dc7","schema_version":"edge-lab-recorder.raw.v1","sequence":null,"source":"clob_market_ws"}
{"event_at":"2026-07-27T03:19:18.615000Z","event_fingerprint":"6896e977d9b4147cb6486af022272ca62f1c58db15818afe61dc1d77090982d4","payload":{"connection_id":"c7dc2e4762f849c6b6f9306b6518dcab","event_at":"2026-07-27T03:19:18.615000Z","event_type":"price_change","frame_hash":"87083f066e1e3210e1ae28bed5eba734f32f77b91eef3528a333e9be88098e68","frame_index":0,"kind":"data","monotonic_ns":224342148310500,"payload":{"event_type":"price_change","market":"0x717c0e8ccd4d5c7040185188fbae28be901ca589a11a94b1b38ca36a79eccfeb","price_changes":[{"asset_id":"24254094493625419915756280046002869097156693848522361803041977572204227262166","best_ask":"0.56","best_bid":"0.54","hash":"4628eb3902cc24befb8af12b5cd542df258e9a0e","price":"0.44","side":"BUY","size":"135.2"},{"asset_id":"41448400836309843603620980831210604935021861034693225347475867885462478926555","best_ask":"0.46","best_bid":"0.44","hash":"7a13cae9001a106bbf566dd6f2d89bcaefc5d797","price":"0.56","side":"SELL","size":"135.2"}],"timestamp":"1785122358615"},"payload_hash":"68ea85fb8844a9e066ccb96d92de5ef07ad872f6f1a8cd34c309eb5c32320fc5","raw_frame":"{\"market\":\"0x717c0e8ccd4d5c7040185188fbae28be901ca589a11a94b1b38ca36a79eccfeb\", \"price_changes\":[{\"asset_id\":\"24254094493625419915756280046002869097156693848522361803041977572204227262166\", \"price\":\"0.44\", \"size\":\"135.2\", \"side\":\"BUY\", \"hash\":\"4628eb3902cc24befb8af12b5cd542df258e9a0e\", \"best_bid\":\"0.54\", \"best_ask\":\"0.56\"}, {\"asset_id\":\"41448400836309843603620980831210604935021861034693225347475867885462478926555\", \"price\":\"0.56\", \"size\":\"135.2\", \"side\":\"SELL\", \"hash\":\"7a13cae9001a106bbf566dd6f2d89bcaefc5d797\", \"best_bid\":\"0.44\", \"best_ask\":\"0.46\"}], \"timestamp\":\"1785122358615\", \"event_type\":\"price_change\"}","received_at":"2026-07-27T03:19:18.811018Z","schema_version":"clob-market-ws.price_change.v1","sequence":null,"server_hash":null,"server_timestamp":"1785122358615","session_id":"dd162b8dca5f43ff811d304e69a06123","source":"clob_market_ws"},"received_at":"2026-07-27T03:19:18.811018Z","record_id":"6a6d3435927e7461322d2f4c2468288b34ad6d8c55f2284d82d1472a0b2d27dc","schema_fingerprint":"4aa3821a28b0b7c2400bc59aba4bcc0a76e971dadd19610d3ad38c768e124dc7","schema_version":"edge-lab-recorder.raw.v1","sequence":null,"source":"clob_market_ws"}
{"event_at":"2026-07-27T03:19:18.616000Z","event_fingerprint":"d2b482f75a9c3718263c34e80beef46e2c56895f4f0520439fb55380d000d079","payload":{"connection_id":"c7dc2e4762f849c6b6f9306b6518dcab","event_at":"2026-07-27T03:19:18.616000Z","event_type":"best_bid_ask","frame_hash":"9bdfc8b248dbcb48bee6215540703d75f13aff52f44aa10f6100568f14a128a0","frame_index":0,"kind":"data","monotonic_ns":224342158247125,"payload":{"asset_id":"24254094493625419915756280046002869097156693848522361803041977572204227262166","best_ask":"0.56","best_bid":"0.55","event_type":"best_bid_ask","market":"0x717c0e8ccd4d5c7040185188fbae28be901ca589a11a94b1b38ca36a79eccfeb","spread":"0.01","timestamp":"1785122358616"},"payload_hash":"52c20aa0aeea279b827a295f6cb88eccc87dfe84a67e19675ac93cf26bc22dff","raw_frame":"{\"market\":\"0x717c0e8ccd4d5c7040185188fbae28be901ca589a11a94b1b38ca36a79eccfeb\", \"asset_id\":\"24254094493625419915756280046002869097156693848522361803041977572204227262166\", \"best_bid\":\"0.55\", \"best_ask\":\"0.56\", \"spread\":\"0.01\", \"timestamp\":\"1785122358616\", \"event_type\":\"best_bid_ask\"}","received_at":"2026-07-27T03:19:18.820954Z","schema_version":"clob-market-ws.best_bid_ask.v1","sequence":null,"server_hash":null,"server_timestamp":"1785122358616","session_id":"dd162b8dca5f43ff811d304e69a06123","source":"clob_market_ws"},"received_at":"2026-07-27T03:19:18.820954Z","record_id":"b31d13ec523ec02e0fedc93b0e8799fa5ffed3d019e7f5924e9eb18019d4b050","schema_fingerprint":"8488399f31b0337811b13b266be932db7062827c2470b78bd8e9e99bab51d17d","schema_version":"edge-lab-recorder.raw.v1","sequence":null,"source":"clob_market_ws"}
{"event_at":"2026-07-27T03:19:18.616000Z","event_fingerprint":"c98364276244d8133c0774b3b7073403181bb84f0af1241c7b252af4615f612b","payload":{"connection_id":"c7dc2e4762f849c6b6f9306b6518dcab","event_at":"2026-07-27T03:19:18.616000Z","event_type":"best_bid_ask","frame_hash":"e19d53d0572112abcf6c27a122efc0d644e60ec85e01b6d6d62e689904dff4fe","frame_index":0,"kind":"data","monotonic_ns":224342159410041,"payload":{"asset_id":"41448400836309843603620980831210604935021861034693225347475867885462478926555","best_ask":"0.45","best_bid":"0.44","event_type":"best_bid_ask","market":"0x717c0e8ccd4d5c7040185188fbae28be901ca589a11a94b1b38ca36a79eccfeb","spread":"0.01","timestamp":"1785122358616"},"payload_hash":"5867d2450757293338ee7928023af874d0313ced49a5dc80b7e951f30749dea7","raw_frame":"{\"market\":\"0x717c0e8ccd4d5c7040185188fbae28be901ca589a11a94b1b38ca36a79eccfeb\", \"asset_id\":\"41448400836309843603620980831210604935021861034693225347475867885462478926555\", \"best_bid\":\"0.44\", \"best_ask\":\"0.45\", \"spread\":\"0.01\", \"timestamp\":\"1785122358616\", \"event_type\":\"best_bid_ask\"}","received_at":"2026-07-27T03:19:18.822119Z","schema_version":"clob-market-ws.best_bid_ask.v1","sequence":null,"server_hash":null,"server_timestamp":"1785122358616","session_id":"dd162b8dca5f43ff811d304e69a06123","source":"clob_market_ws"},"received_at":"2026-07-27T03:19:18.822119Z","record_id":"87bbda80875c6b7238e2f9bd1b650e4df5d105dd13449bce2493b408738c00c5","schema_fingerprint":"8488399f31b0337811b13b266be932db7062827c2470b78bd8e9e99bab51d17d","schema_version":"edge-lab-recorder.raw.v1","sequence":null,"source":"clob_market_ws"}
{"event_at":"2026-07-27T03:19:18.616000Z","event_fingerprint":"ae8daf4f2b3230ebbf85a4d299ee382e9209d5496d709afbc796880dd3dae5d5","payload":{"connection_id":"c7dc2e4762f849c6b6f9306b6518dcab","event_at":"2026-07-27T03:19:18.616000Z","event_type":"price_change","frame_hash":"4a0ae55b3798c4f0821ca75f0d06b88c12a4c07d3170ecc74b9e259481dff398","frame_index":0,"kind":"data","monotonic_ns":224342162150875,"payload":{"event_type":"price_change","market":"0x717c0e8ccd4d5c7040185188fbae28be901ca589a11a94b1b38ca36a79eccfeb","price_changes":[{"asset_id":"24254094493625419915756280046002869097156693848522361803041977572204227262166","best_ask":"0.56","best_bid":"0.55","hash":"85f4a8048b7cd8ba7f51f07c6792ecfb679079cf","price":"0.55","side":"BUY","size":"10"},{"asset_id":"41448400836309843603620980831210604935021861034693225347475867885462478926555","best_ask":"0.45","best_bid":"0.44","hash":"138dabe842846990657f6e43fae94dc5b3a25ee6","price":"0.45","side":"SELL","size":"10"}],"timestamp":"1785122358616"},"payload_hash":"fc79e7dae2ce8b50d3467fd0c6b23968ba80969bba3734781a4b638cbe3d0c38","raw_frame":"{\"market\":\"0x717c0e8ccd4d5c7040185188fbae28be901ca589a11a94b1b38ca36a79eccfeb\", \"price_changes\":[{\"asset_id\":\"24254094493625419915756280046002869097156693848522361803041977572204227262166\", \"price\":\"0.55\", \"size\":\"10\", \"side\":\"BUY\", \"hash\":\"85f4a8048b7cd8ba7f51f07c6792ecfb679079cf\", \"best_bid\":\"0.55\", \"best_ask\":\"0.56\"}, {\"asset_id\":\"41448400836309843603620980831210604935021861034693225347475867885462478926555\", \"price\":\"0.45\", \"size\":\"10\", \"side\":\"SELL\", \"hash\":\"138dabe842846990657f6e43fae94dc5b3a25ee6\", \"best_bid\":\"0.44\", \"best_ask\":\"0.45\"}], \"timestamp\":\"1785122358616\", \"event_type\":\"price_change\"}","received_at":"2026-07-27T03:19:18.824859Z","schema_version":"clob-market-ws.price_change.v1","sequence":null,"server_hash":null,"server_timestamp":"1785122358616","session_id":"dd162b8dca5f43ff811d304e69a06123","source":"clob_market_ws"},"received_at":"2026-07-27T03:19:18.824859Z","record_id":"e6426149beae7ea9bfd1b12e2841e4624595cf7fd5ba4904e48fc746df8baf88","schema_fingerprint":"4aa3821a28b0b7c2400bc59aba4bcc0a76e971dadd19610d3ad38c768e124dc7","schema_version":"edge-lab-recorder.raw.v1","sequence":null,"source":"clob_market_ws"}
{"event_at":"2026-07-27T03:19:18.617000Z","event_fingerprint":"1ee299f8de49a2f0686f342a7c88c815be9d3bf467641a6c9df07ea93c587b3d","payload":{"connection_id":"c7dc2e4762f849c6b6f9306b6518dcab","event_at":"2026-07-27T03:19:18.617000Z","event_type":"price_change","frame_hash":"cd10ca6c005599d9b8928f9df2db5b029166dc116db3b15851cc0a62ca24d215","frame_index":0,"kind":"data","monotonic_ns":224342165060958,"payload":{"event_type":"price_change","market":"0x717c0e8ccd4d5c7040185188fbae28be901ca589a11a94b1b38ca36a79eccfeb","price_changes":[{"asset_id":"24254094493625419915756280046002869097156693848522361803041977572204227262166","best_ask":"0.56","best_bid":"0.55","hash":"a4e443fd2e48b7e7ae80776c3affbc853ff8f5dc","price":"0.54","side":"BUY","size":"15.6"},{"asset_id":"41448400836309843603620980831210604935021861034693225347475867885462478926555","best_ask":"0.45","best_bid":"0.44","hash":"9e790ae925dc24a00972c16a5760f96d3b1c040e","price":"0.46","side":"SELL","size":"15.6"}],"timestamp":"1785122358617"},"payload_hash":"61121989e4202da8f59a9d668a84bf990dddd7b34da79dac8c90fd058c6dbc0f","raw_frame":"{\"market\":\"0x717c0e8ccd4d5c7040185188fbae28be901ca589a11a94b1b38ca36a79eccfeb\", \"price_changes\":[{\"asset_id\":\"24254094493625419915756280046002869097156693848522361803041977572204227262166\", \"price\":\"0.54\", \"size\":\"15.6\", \"side\":\"BUY\", \"hash\":\"a4e443fd2e48b7e7ae80776c3affbc853ff8f5dc\", \"best_bid\":\"0.55\", \"best_ask\":\"0.56\"}, {\"asset_id\":\"41448400836309843603620980831210604935021861034693225347475867885462478926555\", \"price\":\"0.46\", \"size\":\"15.6\", \"side\":\"SELL\", \"hash\":\"9e790ae925dc24a00972c16a5760f96d3b1c040e\", \"best_bid\":\"0.44\", \"best_ask\":\"0.45\"}], \"timestamp\":\"1785122358617\", \"event_type\":\"price_change\"}","received_at":"2026-07-27T03:19:18.827770Z","schema_version":"clob-market-ws.price_change.v1","sequence":null,"server_hash":null,"server_timestamp":"1785122358617","session_id":"dd162b8dca5f43ff811d304e69a06123","source":"clob_market_ws"},"received_at":"2026-07-27T03:19:18.827770Z","record_id":"54ac0353c660307329410530e43a0de9c4dbd33050395c10140f2063947ae397","schema_fingerprint":"4aa3821a28b0b7c2400bc59aba4bcc0a76e971dadd19610d3ad38c768e124dc7","schema_version":"edge-lab-recorder.raw.v1","sequence":null,"source":"clob_market_ws"}
