{"event_at":"2026-07-27T03:12:29.588000Z","event_fingerprint":"aa43fdaf2f8c04390ab841337efae3361136db833a89d7fb2a0bd0771b5c2462","payload":{"connection_id":"f95883f18d264834af91809e5f803e9f","event_at":"2026-07-27T03:12:29.588000Z","event_type":"price_change","frame_hash":"ce854663af57bb60f72d80d3d567658970a4e9f8a849341a9a58fa3d61f4490a","frame_index":0,"kind":"data","monotonic_ns":223932838828625,"payload":{"event_type":"price_change","market":"0xf9d60bb033695053c4d1d8592e52171c1042f64b41a4b72e09dcc6f4852b6670","price_changes":[{"asset_id":"96283536366176669581486355171583722558858323126916278856549586825357358273536","best_ask":"0.4","best_bid":"0.39","hash":"a7a930c1be6bfc57263b54a72f74f109b79276d4","price":"0.01","side":"BUY","size":"8294.52"},{"asset_id":"8698449539441374295770236407991735029336433231649246775082939325523552031992","best_ask":"0.61","best_bid":"0.6","hash":"4a8ee6a58edb4e18df9ffef17d3bbdc4546a3997","price":"0.99","side":"SELL","size":"8294.52"}],"timestamp":"1785121949588"},"payload_hash":"9fba6739723cbcca2288d76f983db70ee5b8f9fe7c6b7280d3fb3a78fd95f3a6","raw_frame":"{\"market\":\"0xf9d60bb033695053c4d1d8592e52171c1042f64b41a4b72e09dcc6f4852b6670\", \"price_changes\":[{\"asset_id\":\"96283536366176669581486355171583722558858323126916278856549586825357358273536\", \"price\":\"0.01\", \"size\":\"8294.52\", \"side\":\"BUY\", \"hash\":\"a7a930c1be6bfc57263b54a72f74f109b79276d4\", \"best_bid\":\"0.39\", \"best_ask\":\"0.4\"}, {\"asset_id\":\"8698449539441374295770236407991735029336433231649246775082939325523552031992\", \"price\":\"0.99\", \"size\":\"8294.52\", \"side\":\"SELL\", \"hash\":\"4a8ee6a58edb4e18df9ffef17d3bbdc4546a3997\", \"best_bid\":\"0.6\", \"best_ask\":\"0.61\"}], \"timestamp\":\"1785121949588\", \"event_type\":\"price_change\"}","received_at":"2026-07-27T03:12:29.507264Z","schema_version":"clob-market-ws.price_change.v1","sequence":null,"server_hash":null,"server_timestamp":"1785121949588","session_id":"ff6d21c8283948938400a32613abec2c","source":"clob_market_ws"},"received_at":"2026-07-27T03:12:29.507264Z","record_id":"266fe6ba787f643ed911d74350a9d760c6705d911348a32e1a48f0c3d52cb69a","schema_fingerprint":"4aa3821a28b0b7c2400bc59aba4bcc0a76e971dadd19610d3ad38c768e124dc7","schema_version":"edge-lab-recorder.raw.v1","sequence":null,"source":"clob_market_ws"}
{"event_at":"2026-07-27T03:12:29.598000Z","event_fingerprint":"7b6998a7dd327dd33d7f74ac3b79e98bc38bbb0136075b8a822144c80b3eccfe","payload":{"connection_id":"f95883f18d264834af91809e5f803e9f","event_at":"2026-07-27T03:12:29.598000Z","event_type":"price_change","frame_hash":"19297d67ca87cea51f6fc9ce88ca28de62dfb025e8fedeb22ca014c39f31a4ae","frame_index":0,"kind":"data","monotonic_ns":223932841447625,"payload":{"event_type":"price_change","market":"0xf9d60bb033695053c4d1d8592e52171c1042f64b41a4b72e09dcc6f4852b6670","price_changes":[{"asset_id":"8698449539441374295770236407991735029336433231649246775082939325523552031992","best_ask":"0.61","best_bid":"0.6","hash":"49c6d37a7b847bd7e3e2272ff70fd8dbbafb445e","price":"0.02","side":"BUY","size":"1350.79"},{"asset_id":"96283536366176669581486355171583722558858323126916278856549586825357358273536","best_ask":"0.4","best_bid":"0.39","hash":"ccfe96f300de99d87284c5a269de6350f333c01d","price":"0.98","side":"SELL","size":"1350.79"}],"timestamp":"1785121949598"},"payload_hash":"d7a9fe35a77b91ac0c42a8ccb6e49e4ad8096461fdc3aef035fbafd59d00699c","raw_frame":"{\"market\":\"0xf9d60bb033695053c4d1d8592e52171c1042f64b41a4b72e09dcc6f4852b6670\", \"price_changes\":[{\"asset_id\":\"8698449539441374295770236407991735029336433231649246775082939325523552031992\", \"price\":\"0.02\", \"size\":\"1350.79\", \"side\":\"BUY\", \"hash\":\"49c6d37a7b847bd7e3e2272ff70fd8dbbafb445e\", \"best_bid\":\"0.6\", \"best_ask\":\"0.61\"}, {\"asset_id\":\"96283536366176669581486355171583722558858323126916278856549586825357358273536\", \"price\":\"0.98\", \"size\":\"1350.79\", \"side\":\"SELL\", \"hash\":\"ccfe96f300de99d87284c5a269de6350f333c01d\", \"best_bid\":\"0.39\", \"best_ask\":\"0.4\"}], \"timestamp\":\"1785121949598\", \"event_type\":\"price_change\"}","received_at":"2026-07-27T03:12:29.509888Z","schema_version":"clob-market-ws.price_change.v1","sequence":null,"server_hash":null,"server_timestamp":"1785121949598","session_id":"ff6d21c8283948938400a32613abec2c","source":"clob_market_ws"},"received_at":"2026-07-27T03:12:29.509888Z","record_id":"33b9a997268c8d5b59333604f74b18092c4d8dbf20d2018158dbfe874c052bd8","schema_fingerprint":"4aa3821a28b0b7c2400bc59aba4bcc0a76e971dadd19610d3ad38c768e124dc7","schema_version":"edge-lab-recorder.raw.v1","sequence":null,"source":"clob_market_ws"}
{"event_at":"2026-07-27T03:12:29.599000Z","event_fingerprint":"842c369d3d577e351d540aa8b02a72bd5eb605d0fa5273763e433452034f7773","payload":{"connection_id":"f95883f18d264834af91809e5f803e9f","event_at":"2026-07-27T03:12:29.599000Z","event_type":"price_change","frame_hash":"5b9c4856862bf3b5192d34890fee34137efb682269ef2ca5fdcc869a5e3b5953","frame_index":0,"kind":"data","monotonic_ns":223932843340750,"payload":{"event_type":"price_change","market":"0xf9d60bb033695053c4d1d8592e52171c1042f64b41a4b72e09dcc6f4852b6670","price_changes":[{"asset_id":"8698449539441374295770236407991735029336433231649246775082939325523552031992","best_ask":"0.61","best_bid":"0.6","hash":"d5cd0babbd373c4484d5274a46d3e00e0990f77b","price":"0.56","side":"BUY","size":"0"},{"asset_id":"96283536366176669581486355171583722558858323126916278856549586825357358273536","best_ask":"0.4","best_bid":"0.39","hash":"715f262d9f23fc6e0c74f9a37528e32aaaabed98","price":"0.44","side":"SELL","size":"0"}],"timestamp":"1785121949599"},"payload_hash":"846d7e78ed81c1be8ce14bef1bf77438020dc27d6026b3fb5c3aef5e6459867b","raw_frame":"{\"market\":\"0xf9d60bb033695053c4d1d8592e52171c1042f64b41a4b72e09dcc6f4852b6670\", \"price_changes\":[{\"asset_id\":\"8698449539441374295770236407991735029336433231649246775082939325523552031992\", \"price\":\"0.56\", \"size\":\"0\", \"side\":\"BUY\", \"hash\":\"d5cd0babbd373c4484d5274a46d3e00e0990f77b\", \"best_bid\":\"0.6\", \"best_ask\":\"0.61\"}, {\"asset_id\":\"96283536366176669581486355171583722558858323126916278856549586825357358273536\", \"price\":\"0.44\", \"size\":\"0\", \"side\":\"SELL\", \"hash\":\"715f262d9f23fc6e0c74f9a37528e32aaaabed98\", \"best_bid\":\"0.39\", \"best_ask\":\"0.4\"}], \"timestamp\":\"1785121949599\", \"event_type\":\"price_change\"}","received_at":"2026-07-27T03:12:29.511782Z","schema_version":"clob-market-ws.price_change.v1","sequence":null,"server_hash":null,"server_timestamp":"1785121949599","session_id":"ff6d21c8283948938400a32613abec2c","source":"clob_market_ws"},"received_at":"2026-07-27T03:12:29.511782Z","record_id":"7901c9f19eea02c5441c0b8b7e0d1ce791b1c494d0562ea4eee330dd0d82d52e","schema_fingerprint":"4aa3821a28b0b7c2400bc59aba4bcc0a76e971dadd19610d3ad38c768e124dc7","schema_version":"edge-lab-recorder.raw.v1","sequence":null,"source":"clob_market_ws"}
{"event_at":"2026-07-27T03:12:29.634000Z","event_fingerprint":"3cd10a8aaa79494834f7a7befd8518b72b0c6444786cafa206885ff8577f797d","payload":{"connection_id":"f95883f18d264834af91809e5f803e9f","event_at":"2026-07-27T03:12:29.634000Z","event_type":"price_change","frame_hash":"7636f86721f29d6fd7b7277394363ed18cb1dfe15890ef5032e5cbcdd6d6cd2a","frame_index":0,"kind":"data","monotonic_ns":223932867582333,"payload":{"event_type":"price_change","market":"0xf9d60bb033695053c4d1d8592e52171c1042f64b41a4b72e09dcc6f4852b6670","price_changes":[{"asset_id":"8698449539441374295770236407991735029336433231649246775082939325523552031992","best_ask":"0.61","best_bid":"0.6","hash":"8898ac7b3999351719ba1aeb80632de930dba5db","price":"0.58","side":"BUY","size":"90"},{"asset_id":"96283536366176669581486355171583722558858323126916278856549586825357358273536","best_ask":"0.4","best_bid":"0.39","hash":"aaa71cc2219647e2b13330504adba67371882cc3","price":"0.42","side":"SELL","size":"90"}],"timestamp":"1785121949634"},"payload_hash":"720f9056c17ce1edc89025ea943d5d87856bb55d4801c5bfe2a42f456e33d0b8","raw_frame":"{\"market\":\"0xf9d60bb033695053c4d1d8592e52171c1042f64b41a4b72e09dcc6f4852b6670\", \"price_changes\":[{\"asset_id\":\"8698449539441374295770236407991735029336433231649246775082939325523552031992\", \"price\":\"0.58\", \"size\":\"90\", \"side\":\"BUY\", \"hash\":\"8898ac7b3999351719ba1aeb80632de930dba5db\", \"best_bid\":\"0.6\", \"best_ask\":\"0.61\"}, {\"asset_id\":\"96283536366176669581486355171583722558858323126916278856549586825357358273536\", \"price\":\"0.42\", \"size\":\"90\", \"side\":\"SELL\", \"hash\":\"aaa71cc2219647e2b13330504adba67371882cc3\", \"best_bid\":\"0.39\", \"best_ask\":\"0.4\"}], \"timestamp\":\"1785121949634\", \"event_type\":\"price_change\"}","received_at":"2026-07-27T03:12:29.536021Z","schema_version":"clob-market-ws.price_change.v1","sequence":null,"server_hash":null,"server_timestamp":"1785121949634","session_id":"ff6d21c8283948938400a32613abec2c","source":"clob_market_ws"},"received_at":"2026-07-27T03:12:29.536021Z","record_id":"0af3e1dad5bbb6bf663449ce3979750d495ea494c7f2398cf17e85623048fb88","schema_fingerprint":"4aa3821a28b0b7c2400bc59aba4bcc0a76e971dadd19610d3ad38c768e124dc7","schema_version":"edge-lab-recorder.raw.v1","sequence":null,"source":"clob_market_ws"}
{"event_at":"2026-07-27T03:12:29.634000Z","event_fingerprint":"5e2d9a0bbf1704d5c23010c98a5ff0aac6404a3bd9645db239fc7194e42ef2f8","payload":{"connection_id":"f95883f18d264834af91809e5f803e9f","event_at":"2026-07-27T03:12:29.634000Z","event_type":"price_change","frame_hash":"b5a5fd59a7564fc7c22e2ebf5f61e3bbcba78e30dc7b2ff06c616b8ea84dffbf","frame_index":0,"kind":"data","monotonic_ns":223932868649041,"payload":{"event_type":"price_change","market":"0xf9d60bb033695053c4d1d8592e52171c1042f64b41a4b72e09dcc6f4852b6670","price_changes":[{"asset_id":"8698449539441374295770236407991735029336433231649246775082939325523552031992","best_ask":"0.61","best_bid":"0.6","hash":"8898ac7b3999351719ba1aeb80632de930dba5db","price":"0.59","side":"BUY","size":"103.93"},{"asset_id":"96283536366176669581486355171583722558858323126916278856549586825357358273536","best_ask":"0.4","best_bid":"0.39","hash":"aaa71cc2219647e2b13330504adba67371882cc3","price":"0.41","side":"SELL","size":"103.93"}],"timestamp":"1785121949634"},"payload_hash":"2ddd20f3a09798892c7c437b41734e4a81ce76f008b0b092ab2bad7b1d561493","raw_frame":"{\"market\":\"0xf9d60bb033695053c4d1d8592e52171c1042f64b41a4b72e09dcc6f4852b6670\", \"price_changes\":[{\"asset_id\":\"8698449539441374295770236407991735029336433231649246775082939325523552031992\", \"price\":\"0.59\", \"size\":\"103.93\", \"side\":\"BUY\", \"hash\":\"8898ac7b3999351719ba1aeb80632de930dba5db\", \"best_bid\":\"0.6\", \"best_ask\":\"0.61\"}, {\"asset_id\":\"96283536366176669581486355171583722558858323126916278856549586825357358273536\", \"price\":\"0.41\", \"size\":\"103.93\", \"side\":\"SELL\", \"hash\":\"aaa71cc2219647e2b13330504adba67371882cc3\", \"best_bid\":\"0.39\", \"best_ask\":\"0.4\"}], \"timestamp\":\"1785121949634\", \"event_type\":\"price_change\"}","received_at":"2026-07-27T03:12:29.537100Z","schema_version":"clob-market-ws.price_change.v1","sequence":null,"server_hash":null,"server_timestamp":"1785121949634","session_id":"ff6d21c8283948938400a32613abec2c","source":"clob_market_ws"},"received_at":"2026-07-27T03:12:29.537100Z","record_id":"921f085a8d1f80df71889e1b740f35dff943e7665f7e58f07e4c71651b64f97a","schema_fingerprint":"4aa3821a28b0b7c2400bc59aba4bcc0a76e971dadd19610d3ad38c768e124dc7","schema_version":"edge-lab-recorder.raw.v1","sequence":null,"source":"clob_market_ws"}
{"event_at":"2026-07-27T03:12:29.645000Z","event_fingerprint":"2b6929f38876d2fbf3cc5f0d8f9ad24ec93ff22be722dfce440d20279b139b5f","payload":{"connection_id":"f95883f18d264834af91809e5f803e9f","event_at":"2026-07-27T03:12:29.645000Z","event_type":"last_trade_price","frame_hash":"ba72ece1202535bcdc2d00c0764df0f921fa19129b66a95046f9c2d232d21712","frame_index":0,"kind":"data","monotonic_ns":223932882307875,"payload":{"asset_id":"96283536366176669581486355171583722558858323126916278856549586825357358273536","event_type":"last_trade_price","fee_rate_bps":"0","market":"0xf9d60bb033695053c4d1d8592e52171c1042f64b41a4b72e09dcc6f4852b6670","price":"0.4","side":"BUY","size":"19.8","timestamp":"1785121949645","transaction_hash":"0xa462fea56bb33a32e2fd458d7f32116eef35a1d824e87cb550f1a0bdd5be094b"},"payload_hash":"30ba98dca0bd93f360b1fbbd44d87d07d9a0db7ed09ddb5a448aa19d572f8622","raw_frame":"{\"market\":\"0xf9d60bb033695053c4d1d8592e52171c1042f64b41a4b72e09dcc6f4852b6670\", \"asset_id\":\"96283536366176669581486355171583722558858323126916278856549586825357358273536\", \"price\":\"0.4\", \"size\":\"19.8\", \"fee_rate_bps\":\"0\", \"side\":\"BUY\", \"timestamp\":\"1785121949645\", \"event_type\":\"last_trade_price\", \"transaction_hash\":\"0xa462fea56bb33a32e2fd458d7f32116eef35a1d824e87cb550f1a0bdd5be094b\"}","received_at":"2026-07-27T03:12:29.550749Z","schema_version":"clob-market-ws.last_trade_price.v1","sequence":null,"server_hash":null,"server_timestamp":"1785121949645","session_id":"ff6d21c8283948938400a32613abec2c","source":"clob_market_ws"},"received_at":"2026-07-27T03:12:29.550749Z","record_id":"4fc05add325d5479983f31e3ed4acc2ffedbf1aa5670cee5347938997ad735a0","schema_fingerprint":"95ad9be75a4b695cd99991e12b2592bc7346f3f5388a82d0000ba65bc0d9fd0a","schema_version":"edge-lab-recorder.raw.v1","sequence":null,"source":"clob_market_ws"}
{"event_at":"2026-07-27T03:12:29.660000Z","event_fingerprint":"6888bf2c30c7b737afba6b15fb1887c6c5d22e66364329340ed477c3bd9f14dd","payload":{"connection_id":"f95883f18d264834af91809e5f803e9f","event_at":"2026-07-27T03:12:29.660000Z","event_type":"price_change","frame_hash":"ecb5e15cf19060f943b00f25495f8003d03356b62549b602a399313da3193ae4","frame_index":0,"kind":"data","monotonic_ns":223932894716333,"payload":{"event_type":"price_change","market":"0xf9d60bb033695053c4d1d8592e52171c1042f64b41a4b72e09dcc6f4852b6670","price_changes":[{"asset_id":"8698449539441374295770236407991735029336433231649246775082939325523552031992","best_ask":"0.61","best_bid":"0.6","hash":"68ccaee6c8b5d09553e85ef0a216669d583e16a0","price":"0.02","side":"BUY","size":"1345.79"},{"asset_id":"96283536366176669581486355171583722558858323126916278856549586825357358273536","best_ask":"0.4","best_bid":"0.39","hash":"f372ab6ecb119b5fd776c101ca7edcfa67a625be","price":"0.98","side":"SELL","size":"1345.79"}],"timestamp":"1785121949660"},"payload_hash":"98faffc4d458ce4478dd3defae2265edbaf189922ac85a8b26a2db90459238c7","raw_frame":"{\"market\":\"0xf9d60bb033695053c4d1d8592e52171c1042f64b41a4b72e09dcc6f4852b6670\", \"price_changes\":[{\"asset_id\":\"8698449539441374295770236407991735029336433231649246775082939325523552031992\", \"price\":\"0.02\", \"size\":\"1345.79\", \"side\":\"BUY\", \"hash\":\"68ccaee6c8b5d09553e85ef0a216669d583e16a0\", \"best_bid\":\"0.6\", \"best_ask\":\"0.61\"}, {\"asset_id\":\"96283536366176669581486355171583722558858323126916278856549586825357358273536\", \"price\":\"0.98\", \"size\":\"1345.79\", \"side\":\"SELL\", \"hash\":\"f372ab6ecb119b5fd776c101ca7edcfa67a625be\", \"best_bid\":\"0.39\", \"best_ask\":\"0.4\"}], \"timestamp\":\"1785121949660\", \"event_type\":\"price_change\"}","received_at":"2026-07-27T03:12:29.563154Z","schema_version":"clob-market-ws.price_change.v1","sequence":null,"server_hash":null,"server_timestamp":"1785121949660","session_id":"ff6d21c8283948938400a32613abec2c","source":"clob_market_ws"},"received_at":"2026-07-27T03:12:29.563154Z","record_id":"9608a412ed07973edaa274c9c63ac85f8b9dfe8c69f6b14309b8808834787654","schema_fingerprint":"4aa3821a28b0b7c2400bc59aba4bcc0a76e971dadd19610d3ad38c768e124dc7","schema_version":"edge-lab-recorder.raw.v1","sequence":null,"source":"clob_market_ws"}
{"event_at":"2026-07-27T03:12:29.662000Z","event_fingerprint":"8cc7a168852731aa35afb42b5ae3a47851a4b0b4daced6919754320337400a75","payload":{"connection_id":"f95883f18d264834af91809e5f803e9f","event_at":"2026-07-27T03:12:29.662000Z","event_type":"price_change","frame_hash":"2982dc1a7d78d666af5ec6224990b3511c605d9b64cb8238dd26b206fd5b23b8","frame_index":0,"kind":"data","monotonic_ns":223932896416750,"payload":{"event_type":"price_change","market":"0xf9d60bb033695053c4d1d8592e52171c1042f64b41a4b72e09dcc6f4852b6670","price_changes":[{"asset_id":"8698449539441374295770236407991735029336433231649246775082939325523552031992","best_ask":"0.61","best_bid":"0.6","hash":"805c6cdb1d0b8ff53c1d1fc460f34d13020e94d2","price":"0.53","side":"BUY","size":"54.15"},{"asset_id":"96283536366176669581486355171583722558858323126916278856549586825357358273536","best_ask":"0.4","best_bid":"0.39","hash":"ebaed97410b48fec994265d521e0ad93a387cdbd","price":"0.47","side":"SELL","size":"54.15"}],"timestamp":"1785121949662"},"payload_hash":"44a8eb00e40e12a4304a54e892ca2044f1737b220c74ab8fc549f3e13b714161","raw_frame":"{\"market\":\"0xf9d60bb033695053c4d1d8592e52171c1042f64b41a4b72e09dcc6f4852b6670\", \"price_changes\":[{\"asset_id\":\"8698449539441374295770236407991735029336433231649246775082939325523552031992\", \"price\":\"0.53\", \"size\":\"54.15\", \"side\":\"BUY\", \"hash\":\"805c6cdb1d0b8ff53c1d1fc460f34d13020e94d2\", \"best_bid\":\"0.6\", \"best_ask\":\"0.61\"}, {\"asset_id\":\"96283536366176669581486355171583722558858323126916278856549586825357358273536\", \"price\":\"0.47\", \"size\":\"54.15\", \"side\":\"SELL\", \"hash\":\"ebaed97410b48fec994265d521e0ad93a387cdbd\", \"best_bid\":\"0.39\", \"best_ask\":\"0.4\"}], \"timestamp\":\"1785121949662\", \"event_type\":\"price_change\"}","received_at":"2026-07-27T03:12:29.564852Z","schema_version":"clob-market-ws.price_change.v1","sequence":null,"server_hash":null,"server_timestamp":"1785121949662","session_id":"ff6d21c8283948938400a32613abec2c","source":"clob_market_ws"},"received_at":"2026-07-27T03:12:29.564852Z","record_id":"49842e0b2be39813170ad94a0c4c44568b4d77405ec74e123df2e098f1d7cde8","schema_fingerprint":"4aa3821a28b0b7c2400bc59aba4bcc0a76e971dadd19610d3ad38c768e124dc7","schema_version":"edge-lab-recorder.raw.v1","sequence":null,"source":"clob_market_ws"}
{"event_at":"2026-07-27T03:12:29.666000Z","event_fingerprint":"e572316c1ebc08facdc870c03e0ea7370ddea42be9e0a5f15165fff5f3735dae","payload":{"connection_id":"f95883f18d264834af91809e5f803e9f","event_at":"2026-07-27T03:12:29.666000Z","event_type":"price_change","frame_hash":"677871738e007d915e8e34b3256950a2c6abfae032bc1e429670af47439f0611","frame_index":0,"kind":"data","monotonic_ns":223932897437291,"payload":{"event_type":"price_change","market":"0xf9d60bb033695053c4d1d8592e52171c1042f64b41a4b72e09dcc6f4852b6670","price_changes":[{"asset_id":"8698449539441374295770236407991735029336433231649246775082939325523552031992","best_ask":"0.61","best_bid":"0.6","hash":"6fb368d819b38d858936ca96c14ecc9a4c2fa2b5","price":"0.51","side":"BUY","size":"46"},{"asset_id":"96283536366176669581486355171583722558858323126916278856549586825357358273536","best_ask":"0.4","best_bid":"0.39","hash":"a5b3bb545a8d8b1730d84c422f2bcd556a72a0c2","price":"0.49","side":"SELL","size":"46"}],"timestamp":"1785121949666"},"payload_hash":"4d6286f61ebaa91f72436f0c03938cac896082d1ad0091aab69194d2dcbda4dc","raw_frame":"{\"market\":\"0xf9d60bb033695053c4d1d8592e52171c1042f64b41a4b72e09dcc6f4852b6670\", \"price_changes\":[{\"asset_id\":\"8698449539441374295770236407991735029336433231649246775082939325523552031992\", \"price\":\"0.51\", \"size\":\"46\", \"side\":\"BUY\", \"hash\":\"6fb368d819b38d858936ca96c14ecc9a4c2fa2b5\", \"best_bid\":\"0.6\", \"best_ask\":\"0.61\"}, {\"asset_id\":\"96283536366176669581486355171583722558858323126916278856549586825357358273536\", \"price\":\"0.49\", \"size\":\"46\", \"side\":\"SELL\", \"hash\":\"a5b3bb545a8d8b1730d84c422f2bcd556a72a0c2\", \"best_bid\":\"0.39\", \"best_ask\":\"0.4\"}], \"timestamp\":\"1785121949666\", \"event_type\":\"price_change\"}","received_at":"2026-07-27T03:12:29.565888Z","schema_version":"clob-market-ws.price_change.v1","sequence":null,"server_hash":null,"server_timestamp":"1785121949666","session_id":"ff6d21c8283948938400a32613abec2c","source":"clob_market_ws"},"received_at":"2026-07-27T03:12:29.565888Z","record_id":"936eab9e782b3feb8a905efc982d020f12a1312a670b8e25c8ffabffcf2abfaa","schema_fingerprint":"4aa3821a28b0b7c2400bc59aba4bcc0a76e971dadd19610d3ad38c768e124dc7","schema_version":"edge-lab-recorder.raw.v1","sequence":null,"source":"clob_market_ws"}
{"event_at":"2026-07-27T03:12:29.684000Z","event_fingerprint":"28119213b9822abb95292249ba85f164b4e8d9ea3c6b117004f2606c65d0b0da","payload":{"connection_id":"f95883f18d264834af91809e5f803e9f","event_at":"2026-07-27T03:12:29.684000Z","event_type":"price_change","frame_hash":"5950ffb413810cd95872f000b5c271338efcc38d9f3ea5a3c6e6a0053d2e5f39","frame_index":0,"kind":"data","monotonic_ns":223932915915916,"payload":{"event_type":"price_change","market":"0xf9d60bb033695053c4d1d8592e52171c1042f64b41a4b72e09dcc6f4852b6670","price_changes":[{"asset_id":"8698449539441374295770236407991735029336433231649246775082939325523552031992","best_ask":"0.61","best_bid":"0.6","hash":"15a368877528883ee5e592ca341e3a88544fa75a","price":"0.54","side":"BUY","size":"85"},{"asset_id":"96283536366176669581486355171583722558858323126916278856549586825357358273536","best_ask":"0.4","best_bid":"0.39","hash":"2524b2dd32727311a2257afb08c7ac10fa56ebf0","price":"0.46","side":"SELL","size":"85"}],"timestamp":"1785121949684"},"payload_hash":"e5c8a01a94a4a5199a868a3b475aa2629f6f5fdaddd03c85dd3b99abed83ab0a","raw_frame":"{\"market\":\"0xf9d60bb033695053c4d1d8592e52171c1042f64b41a4b72e09dcc6f4852b6670\", \"price_changes\":[{\"asset_id\":\"8698449539441374295770236407991735029336433231649246775082939325523552031992\", \"price\":\"0.54\", \"size\":\"85\", \"side\":\"BUY\", \"hash\":\"15a368877528883ee5e592ca341e3a88544fa75a\", \"best_bid\":\"0.6\", \"best_ask\":\"0.61\"}, {\"asset_id\":\"96283536366176669581486355171583722558858323126916278856549586825357358273536\", \"price\":\"0.46\", \"size\":\"85\", \"side\":\"SELL\", \"hash\":\"2524b2dd32727311a2257afb08c7ac10fa56ebf0\", \"best_bid\":\"0.39\", \"best_ask\":\"0.4\"}], \"timestamp\":\"1785121949684\", \"event_type\":\"price_change\"}","received_at":"2026-07-27T03:12:29.584352Z","schema_version":"clob-market-ws.price_change.v1","sequence":null,"server_hash":null,"server_timestamp":"1785121949684","session_id":"ff6d21c8283948938400a32613abec2c","source":"clob_market_ws"},"received_at":"2026-07-27T03:12:29.584352Z","record_id":"ca16016b9803084e8db7f0547fb0cb6fd0e54c60d772e59bcd01b95177a4bc5e","schema_fingerprint":"4aa3821a28b0b7c2400bc59aba4bcc0a76e971dadd19610d3ad38c768e124dc7","schema_version":"edge-lab-recorder.raw.v1","sequence":null,"source":"clob_market_ws"}
{"event_at":"2026-07-27T03:12:29.690000Z","event_fingerprint":"e88b68228e98e15dccffc29492f1e1e2f3861df594d203bf3505e5dedc5be983","payload":{"connection_id":"f95883f18d264834af91809e5f803e9f","event_at":"2026-07-27T03:12:29.690000Z","event_type":"price_change","frame_hash":"776e646aa4d2e0b708ff427f9d99db52fde6683d7f8710512a2a5103c6f5ec52","frame_index":0,"kind":"data","monotonic_ns":223932920333916,"payload":{"event_type":"price_change","market":"0xf9d60bb033695053c4d1d8592e52171c1042f64b41a4b72e09dcc6f4852b6670","price_changes":[{"asset_id":"8698449539441374295770236407991735029336433231649246775082939325523552031992","best_ask":"0.61","best_bid":"0.6","hash":"e8889858b9dedc67e8a7a3d0bc6098988434c43d","price":"0.51","side":"BUY","size":"51"},{"asset_id":"96283536366176669581486355171583722558858323126916278856549586825357358273536","best_ask":"0.4","best_bid":"0.39","hash":"81ba0f74c56c37de6c3e75d728f405759f599cf1","price":"0.49","side":"SELL","size":"51"}],"timestamp":"1785121949690"},"payload_hash":"7a56398b8dc6001536d84e537960df5857d263d46bd459bcabbb15dfb7478b32","raw_frame":"{\"market\":\"0xf9d60bb033695053c4d1d8592e52171c1042f64b41a4b72e09dcc6f4852b6670\", \"price_changes\":[{\"asset_id\":\"8698449539441374295770236407991735029336433231649246775082939325523552031992\", \"price\":\"0.51\", \"size\":\"51\", \"side\":\"BUY\", \"hash\":\"e8889858b9dedc67e8a7a3d0bc6098988434c43d\", \"best_bid\":\"0.6\", \"best_ask\":\"0.61\"}, {\"asset_id\":\"96283536366176669581486355171583722558858323126916278856549586825357358273536\", \"price\":\"0.49\", \"size\":\"51\", \"side\":\"SELL\", \"hash\":\"81ba0f74c56c37de6c3e75d728f405759f599cf1\", \"best_bid\":\"0.39\", \"best_ask\":\"0.4\"}], \"timestamp\":\"1785121949690\", \"event_type\":\"price_change\"}","received_at":"2026-07-27T03:12:29.588775Z","schema_version":"clob-market-ws.price_change.v1","sequence":null,"server_hash":null,"server_timestamp":"1785121949690","session_id":"ff6d21c8283948938400a32613abec2c","source":"clob_market_ws"},"received_at":"2026-07-27T03:12:29.588775Z","record_id":"090fb38246fa938f101379eaf072a8057f4d669f8e584daa93fdc31495151b2b","schema_fingerprint":"4aa3821a28b0b7c2400bc59aba4bcc0a76e971dadd19610d3ad38c768e124dc7","schema_version":"edge-lab-recorder.raw.v1","sequence":null,"source":"clob_market_ws"}
{"event_at":"2026-07-27T03:12:29.692000Z","event_fingerprint":"a83e052cb4b5f406387a414f136c6cd462ae34c758c829826483ecb9ac2967cc","payload":{"connection_id":"f95883f18d264834af91809e5f803e9f","event_at":"2026-07-27T03:12:29.692000Z","event_type":"price_change","frame_hash":"b5551fa05aaf51e60f2c1c8771ed34ca38ddf669bb8385aa8b4c7138ad90ac6c","frame_index":0,"kind":"data","monotonic_ns":223932922601291,"payload":{"event_type":"price_change","market":"0xf9d60bb033695053c4d1d8592e52171c1042f64b41a4b72e09dcc6f4852b6670","price_changes":[{"asset_id":"8698449539441374295770236407991735029336433231649246775082939325523552031992","best_ask":"0.61","best_bid":"0.6","hash":"d18a7dd9e23d77c85c1e032cd0512d2faf620bea","price":"0.27","side":"BUY","size":"59.3"},{"asset_id":"96283536366176669581486355171583722558858323126916278856549586825357358273536","best_ask":"0.4","best_bid":"0.39","hash":"3f6d97d83bb195b3b1b3782a3d5ff045d21885e8","price":"0.73","side":"SELL","size":"59.3"}],"timestamp":"1785121949692"},"payload_hash":"489bb688b4abc6cf20f0d33d57fb8fdd39df5fa6f6052271a118327f2c52d9cc","raw_frame":"{\"market\":\"0xf9d60bb033695053c4d1d8592e52171c1042f64b41a4b72e09dcc6f4852b6670\", \"price_changes\":[{\"asset_id\":\"8698449539441374295770236407991735029336433231649246775082939325523552031992\", \"price\":\"0.27\", \"size\":\"59.3\", \"side\":\"BUY\", \"hash\":\"d18a7dd9e23d77c85c1e032cd0512d2faf620bea\", \"best_bid\":\"0.6\", \"best_ask\":\"0.61\"}, {\"asset_id\":\"96283536366176669581486355171583722558858323126916278856549586825357358273536\", \"price\":\"0.73\", \"size\":\"59.3\", \"side\":\"SELL\", \"hash\":\"3f6d97d83bb195b3b1b3782a3d5ff045d21885e8\", \"best_bid\":\"0.39\", \"best_ask\":\"0.4\"}], \"timestamp\":\"1785121949692\", \"event_type\":\"price_change\"}","received_at":"2026-07-27T03:12:29.591045Z","schema_version":"clob-market-ws.price_change.v1","sequence":null,"server_hash":null,"server_timestamp":"1785121949692","session_id":"ff6d21c8283948938400a32613abec2c","source":"clob_market_ws"},"received_at":"2026-07-27T03:12:29.591045Z","record_id":"1ea4531dc702727a0930a40367aaf00e29d2153a77f333d448479706f37618c8","schema_fingerprint":"4aa3821a28b0b7c2400bc59aba4bcc0a76e971dadd19610d3ad38c768e124dc7","schema_version":"edge-lab-recorder.raw.v1","sequence":null,"source":"clob_market_ws"}
{"event_at":"2026-07-27T03:12:29.695000Z","event_fingerprint":"94b75fde920f205ad13612d39184523c9bd12640ea8a7137bd4c18cd282fc641","payload":{"connection_id":"f95883f18d264834af91809e5f803e9f","event_at":"2026-07-27T03:12:29.695000Z","event_type":"price_change","frame_hash":"c73b32e4ce06195cca9987c2361aafbb63a3cefa9581d0b14e95891da4026238","frame_index":0,"kind":"data","monotonic_ns":223932926139125,"payload":{"event_type":"price_change","market":"0xf9d60bb033695053c4d1d8592e52171c1042f64b41a4b72e09dcc6f4852b6670","price_changes":[{"asset_id":"8698449539441374295770236407991735029336433231649246775082939325523552031992","best_ask":"0.61","best_bid":"0.6","hash":"570bee60bd94e7083490f7a3250dde78b7247986","price":"0.44","side":"BUY","size":"133.6"},{"asset_id":"96283536366176669581486355171583722558858323126916278856549586825357358273536","best_ask":"0.4","best_bid":"0.39","hash":"4a9942f0046877503733036957241ca2284aa8b6","price":"0.56","side":"SELL","size":"133.6"}],"timestamp":"1785121949695"},"payload_hash":"ba74d50f54b232cbd0d5e1faf31ec54e41a5931285c822d2cfac268d651f2c2c","raw_frame":"{\"market\":\"0xf9d60bb033695053c4d1d8592e52171c1042f64b41a4b72e09dcc6f4852b6670\", \"price_changes\":[{\"asset_id\":\"8698449539441374295770236407991735029336433231649246775082939325523552031992\", \"price\":\"0.44\", \"size\":\"133.6\", \"side\":\"BUY\", \"hash\":\"570bee60bd94e7083490f7a3250dde78b7247986\", \"best_bid\":\"0.6\", \"best_ask\":\"0.61\"}, {\"asset_id\":\"96283536366176669581486355171583722558858323126916278856549586825357358273536\", \"price\":\"0.56\", \"size\":\"133.6\", \"side\":\"SELL\", \"hash\":\"4a9942f0046877503733036957241ca2284aa8b6\", \"best_bid\":\"0.39\", \"best_ask\":\"0.4\"}], \"timestamp\":\"1785121949695\", \"event_type\":\"price_change\"}","received_at":"2026-07-27T03:12:29.594580Z","schema_version":"clob-market-ws.price_change.v1","sequence":null,"server_hash":null,"server_timestamp":"1785121949695","session_id":"ff6d21c8283948938400a32613abec2c","source":"clob_market_ws"},"received_at":"2026-07-27T03:12:29.594580Z","record_id":"815a2cd4badabe79e356e720a8ecfc56e65c367e11829396a2e7473487da34fd","schema_fingerprint":"4aa3821a28b0b7c2400bc59aba4bcc0a76e971dadd19610d3ad38c768e124dc7","schema_version":"edge-lab-recorder.raw.v1","sequence":null,"source":"clob_market_ws"}
{"event_at":"2026-07-27T03:12:29.695000Z","event_fingerprint":"eb49ec9503cb2c69bb3895a761b70aa3762e9fab63c98a705d4336482e804875","payload":{"connection_id":"f95883f18d264834af91809e5f803e9f","event_at":"2026-07-27T03:12:29.695000Z","event_type":"price_change","frame_hash":"2fe127b6b030674b1a1e10013723e032eefe4990aa4581b870d01cacef21d655","frame_index":0,"kind":"data","monotonic_ns":223932927786958,"payload":{"event_type":"price_change","market":"0xf9d60bb033695053c4d1d8592e52171c1042f64b41a4b72e09dcc6f4852b6670","price_changes":[{"asset_id":"8698449539441374295770236407991735029336433231649246775082939325523552031992","best_ask":"0.61","best_bid":"0.6","hash":"a516f633d49141c6c62d9c8086493ecaea01b663","price":"0.43","side":"BUY","size":"164.8"},{"asset_id":"96283536366176669581486355171583722558858323126916278856549586825357358273536","best_ask":"0.4","best_bid":"0.39","hash":"90f2a3104056d121c862adec105d7a22d34dd8ac","price":"0.57","side":"SELL","size":"164.8"}],"timestamp":"1785121949695"},"payload_hash":"be5626b24be24fcc442f28ef3ed066a0741771419a6d71782b764176f5e33814","raw_frame":"{\"market\":\"0xf9d60bb033695053c4d1d8592e52171c1042f64b41a4b72e09dcc6f4852b6670\", \"price_changes\":[{\"asset_id\":\"8698449539441374295770236407991735029336433231649246775082939325523552031992\", \"price\":\"0.43\", \"size\":\"164.8\", \"side\":\"BUY\", \"hash\":\"a516f633d49141c6c62d9c8086493ecaea01b663\", \"best_bid\":\"0.6\", \"best_ask\":\"0.61\"}, {\"asset_id\":\"96283536366176669581486355171583722558858323126916278856549586825357358273536\", \"price\":\"0.57\", \"size\":\"164.8\", \"side\":\"SELL\", \"hash\":\"90f2a3104056d121c862adec105d7a22d34dd8ac\", \"best_bid\":\"0.39\", \"best_ask\":\"0.4\"}], \"timestamp\":\"1785121949695\", \"event_type\":\"price_change\"}","received_at":"2026-07-27T03:12:29.596230Z","schema_version":"clob-market-ws.price_change.v1","sequence":null,"server_hash":null,"server_timestamp":"1785121949695","session_id":"ff6d21c8283948938400a32613abec2c","source":"clob_market_ws"},"received_at":"2026-07-27T03:12:29.596230Z","record_id":"fc58bf56649eef195efa4d033d309d7dbbc5c6d62749f2c53246d918ceb51acd","schema_fingerprint":"4aa3821a28b0b7c2400bc59aba4bcc0a76e971dadd19610d3ad38c768e124dc7","schema_version":"edge-lab-recorder.raw.v1","sequence":null,"source":"clob_market_ws"}
{"event_at":"2026-07-27T03:12:29.696000Z","event_fingerprint":"e194238d7e7b34f00813172c196eb66ac4b65416c0a81cde51517c40de5d91c2","payload":{"connection_id":"f95883f18d264834af91809e5f803e9f","event_at":"2026-07-27T03:12:29.696000Z","event_type":"price_change","frame_hash":"60d5edd9e27eb92fb5e18b9d5f249765f53ee6bd1a4c8f8b81920513c917d243","frame_index":0,"kind":"data","monotonic_ns":223932929350500,"payload":{"event_type":"price_change","market":"0xf9d60bb033695053c4d1d8592e52171c1042f64b41a4b72e09dcc6f4852b6670","price_changes":[{"asset_id":"8698449539441374295770236407991735029336433231649246775082939325523552031992","best_ask":"0.61","best_bid":"0.6","hash":"ef1475870dd78f9050c4f8e4115076ce0b510f8b","price":"0.42","side":"BUY","size":"147.09"},{"asset_id":"96283536366176669581486355171583722558858323126916278856549586825357358273536","best_ask":"0.4","best_bid":"0.39","hash":"1a11bcafd4ab1ca17914a5db275cd7266928a498","price":"0.58","side":"SELL","size":"147.09"}],"timestamp":"1785121949696"},"payload_hash":"fac7daa075253ad9ea37485acd574738ea4c95b3dc524b73b55ef1d6e12ca7b7","raw_frame":"{\"market\":\"0xf9d60bb033695053c4d1d8592e52171c1042f64b41a4b72e09dcc6f4852b6670\", \"price_changes\":[{\"asset_id\":\"8698449539441374295770236407991735029336433231649246775082939325523552031992\", \"price\":\"0.42\", \"size\":\"147.09\", \"side\":\"BUY\", \"hash\":\"ef1475870dd78f9050c4f8e4115076ce0b510f8b\", \"best_bid\":\"0.6\", \"best_ask\":\"0.61\"}, {\"asset_id\":\"96283536366176669581486355171583722558858323126916278856549586825357358273536\", \"price\":\"0.58\", \"size\":\"147.09\", \"side\":\"SELL\", \"hash\":\"1a11bcafd4ab1ca17914a5db275cd7266928a498\", \"best_bid\":\"0.39\", \"best_ask\":\"0.4\"}], \"timestamp\":\"1785121949696\", \"event_type\":\"price_change\"}","received_at":"2026-07-27T03:12:29.597799Z","schema_version":"clob-market-ws.price_change.v1","sequence":null,"server_hash":null,"server_timestamp":"1785121949696","session_id":"ff6d21c8283948938400a32613abec2c","source":"clob_market_ws"},"received_at":"2026-07-27T03:12:29.597799Z","record_id":"6e9b08f081d0acb33d991f165873c707c9d860f075589b1598c7dc577c0c72e1","schema_fingerprint":"4aa3821a28b0b7c2400bc59aba4bcc0a76e971dadd19610d3ad38c768e124dc7","schema_version":"edge-lab-recorder.raw.v1","sequence":null,"source":"clob_market_ws"}
{"event_at":"2026-07-27T03:12:29.696000Z","event_fingerprint":"4d4eaf31c52093cc5cb62c379e53b8e3587af236b4acae7061f08d4406f8c1df","payload":{"connection_id":"f95883f18d264834af91809e5f803e9f","event_at":"2026-07-27T03:12:29.696000Z","event_type":"price_change","frame_hash":"384754fac51227a202efcc526be71abf15dcb0f5351b1ec4a27f3d1a6273e940","frame_index":0,"kind":"data","monotonic_ns":223932930571833,"payload":{"event_type":"price_change","market":"0xf9d60bb033695053c4d1d8592e52171c1042f64b41a4b72e09dcc6f4852b6670","price_changes":[{"asset_id":"8698449539441374295770236407991735029336433231649246775082939325523552031992","best_ask":"0.61","best_bid":"0.6","hash":"a85997c09c027d420e5eb12e6bada518b313fa40","price":"0.41","side":"BUY","size":"150.3"},{"asset_id":"96283536366176669581486355171583722558858323126916278856549586825357358273536","best_ask":"0.4","best_bid":"0.39","hash":"e13043ad3674644691aff9a81a8883d63023f929","price":"0.59","side":"SELL","size":"150.3"}],"timestamp":"1785121949696"},"payload_hash":"929f9fe90047f3ddda66df4d461c427a66f5f173ee4eaf5f38ca2d5cf2388a64","raw_frame":"{\"market\":\"0xf9d60bb033695053c4d1d8592e52171c1042f64b41a4b72e09dcc6f4852b6670\", \"price_changes\":[{\"asset_id\":\"8698449539441374295770236407991735029336433231649246775082939325523552031992\", \"price\":\"0.41\", \"size\":\"150.3\", \"side\":\"BUY\", \"hash\":\"a85997c09c027d420e5eb12e6bada518b313fa40\", \"best_bid\":\"0.6\", \"best_ask\":\"0.61\"}, {\"asset_id\":\"96283536366176669581486355171583722558858323126916278856549586825357358273536\", \"price\":\"0.59\", \"size\":\"150.3\", \"side\":\"SELL\", \"hash\":\"e13043ad3674644691aff9a81a8883d63023f929\", \"best_bid\":\"0.39\", \"best_ask\":\"0.4\"}], \"timestamp\":\"1785121949696\", \"event_type\":\"price_change\"}","received_at":"2026-07-27T03:12:29.599015Z","schema_version":"clob-market-ws.price_change.v1","sequence":null,"server_hash":null,"server_timestamp":"1785121949696","session_id":"ff6d21c8283948938400a32613abec2c","source":"clob_market_ws"},"received_at":"2026-07-27T03:12:29.599015Z","record_id":"bf317817d6efd80dec7877cc432774f60a3f2033d0d6249ce8b87b778ca85431","schema_fingerprint":"4aa3821a28b0b7c2400bc59aba4bcc0a76e971dadd19610d3ad38c768e124dc7","schema_version":"edge-lab-recorder.raw.v1","sequence":null,"source":"clob_market_ws"}
{"event_at":"2026-07-27T03:12:29.697000Z","event_fingerprint":"0c81cab7c954fce076044be79edf9c1251a8f78efaaf8c5d85420843391e2368","payload":{"connection_id":"f95883f18d264834af91809e5f803e9f","event_at":"2026-07-27T03:12:29.697000Z","event_type":"price_change","frame_hash":"d1715d80805848b4db7df80f7199448994d0ce2ad5ca27847326f7f1823efe53","frame_index":0,"kind":"data","monotonic_ns":223932932274250,"payload":{"event_type":"price_change","market":"0xf9d60bb033695053c4d1d8592e52171c1042f64b41a4b72e09dcc6f4852b6670","price_changes":[{"asset_id":"96283536366176669581486355171583722558858323126916278856549586825357358273536","best_ask":"0.4","best_bid":"0.39","hash":"a1a4acaefee465025b312414445c4965a659b2d1","price":"0.26","side":"BUY","size":"170.6"},{"asset_id":"8698449539441374295770236407991735029336433231649246775082939325523552031992","best_ask":"0.61","best_bid":"0.6","hash":"d6cf51e53aedfb555ba50852e1af32030e55f3d3","price":"0.74","side":"SELL","size":"170.6"}],"timestamp":"1785121949697"},"payload_hash":"3e40a821e819d4e06f4354f6076ac8af97baaec2b5cebb9f29a601e87007be01","raw_frame":"{\"market\":\"0xf9d60bb033695053c4d1d8592e52171c1042f64b41a4b72e09dcc6f4852b6670\", \"price_changes\":[{\"asset_id\":\"96283536366176669581486355171583722558858323126916278856549586825357358273536\", \"price\":\"0.26\", \"size\":\"170.6\", \"side\":\"BUY\", \"hash\":\"a1a4acaefee465025b312414445c4965a659b2d1\", \"best_bid\":\"0.39\", \"best_ask\":\"0.4\"}, {\"asset_id\":\"8698449539441374295770236407991735029336433231649246775082939325523552031992\", \"price\":\"0.74\", \"size\":\"170.6\", \"side\":\"SELL\", \"hash\":\"d6cf51e53aedfb555ba50852e1af32030e55f3d3\", \"best_bid\":\"0.6\", \"best_ask\":\"0.61\"}], \"timestamp\":\"1785121949697\", \"event_type\":\"price_change\"}","received_at":"2026-07-27T03:12:29.600713Z","schema_version":"clob-market-ws.price_change.v1","sequence":null,"server_hash":null,"server_timestamp":"1785121949697","session_id":"ff6d21c8283948938400a32613abec2c","source":"clob_market_ws"},"received_at":"2026-07-27T03:12:29.600713Z","record_id":"ae8078f627b15ff6fbb4df18cd0f56e313432b3e825b93ba46e5da61fe8939d6","schema_fingerprint":"4aa3821a28b0b7c2400bc59aba4bcc0a76e971dadd19610d3ad38c768e124dc7","schema_version":"edge-lab-recorder.raw.v1","sequence":null,"source":"clob_market_ws"}
{"event_at":"2026-07-27T03:12:29.700000Z","event_fingerprint":"e172fba762be24fb209cb88afc547fa52c6856e344eb61df8d301dabc7cc55b7","payload":{"connection_id":"f95883f18d264834af91809e5f803e9f","event_at":"2026-07-27T03:12:29.700000Z","event_type":"price_change","frame_hash":"b64559ef7ac177cfb0886e4d381c755637b5d249ff52843d782271658c8ca039","frame_index":0,"kind":"data","monotonic_ns":223932933851791,"payload":{"event_type":"price_change","market":"0xf9d60bb033695053c4d1d8592e52171c1042f64b41a4b72e09dcc6f4852b6670","price_changes":[{"asset_id":"8698449539441374295770236407991735029336433231649246775082939325523552031992","best_ask":"0.61","best_bid":"0.6","hash":"f104d69f887d9bf803206b51e3c9631456fddb5b","price":"0.01","side":"BUY","size":"7942.52"},{"asset_id":"96283536366176669581486355171583722558858323126916278856549586825357358273536","best_ask":"0.4","best_bid":"0.39","hash":"87b8cac4c8f07ecedd94a3870abd1e55bf346688","price":"0.99","side":"SELL","size":"7942.52"}],"timestamp":"1785121949700"},"payload_hash":"b63a863f5a10e8b8378e95b3b980bcd013b43b04c8756a178177da747f64f4f3","raw_frame":"{\"market\":\"0xf9d60bb033695053c4d1d8592e52171c1042f64b41a4b72e09dcc6f4852b6670\", \"price_changes\":[{\"asset_id\":\"8698449539441374295770236407991735029336433231649246775082939325523552031992\", \"price\":\"0.01\", \"size\":\"7942.52\", \"side\":\"BUY\", \"hash\":\"f104d69f887d9bf803206b51e3c9631456fddb5b\", \"best_bid\":\"0.6\", \"best_ask\":\"0.61\"}, {\"asset_id\":\"96283536366176669581486355171583722558858323126916278856549586825357358273536\", \"price\":\"0.99\", \"size\":\"7942.52\", \"side\":\"SELL\", \"hash\":\"87b8cac4c8f07ecedd94a3870abd1e55bf346688\", \"best_bid\":\"0.39\", \"best_ask\":\"0.4\"}], \"timestamp\":\"1785121949700\", \"event_type\":\"price_change\"}","received_at":"2026-07-27T03:12:29.602294Z","schema_version":"clob-market-ws.price_change.v1","sequence":null,"server_hash":null,"server_timestamp":"1785121949700","session_id":"ff6d21c8283948938400a32613abec2c","source":"clob_market_ws"},"received_at":"2026-07-27T03:12:29.602294Z","record_id":"7f9c6cd91721f9a855a9aa1746e158f650a002b86a6e9612de28b3ae1459787f","schema_fingerprint":"4aa3821a28b0b7c2400bc59aba4bcc0a76e971dadd19610d3ad38c768e124dc7","schema_version":"edge-lab-recorder.raw.v1","sequence":null,"source":"clob_market_ws"}
