{"event_at":"2026-07-27T03:11:15.593000Z","event_fingerprint":"43cb00bda8663f3321e0ca80bda8ced5969f1da9aa83fabd6ddd09fa60560c11","payload":{"connection_id":"f95883f18d264834af91809e5f803e9f","event_at":"2026-07-27T03:11:15.593000Z","event_type":"book","frame_hash":"761bd43fc94ebb4598bd11f7101d1b494fe723d58bd9f04ebe0f4b477efbe08d","frame_index":0,"kind":"data","monotonic_ns":223867392605750,"payload":{"asks":[{"price":"0.99","size":"7914.52"},{"price":"0.98","size":"1568.79"},{"price":"0.97","size":"1207.8"},{"price":"0.96","size":"1051.5"},{"price":"0.95","size":"921"},{"price":"0.94","size":"969.09"},{"price":"0.93","size":"882.7"},{"price":"0.92","size":"664.19"},{"price":"0.91","size":"878.9"},{"price":"0.9","size":"368.99"},{"price":"0.89","size":"125.79"},{"price":"0.88","size":"150.9"},{"price":"0.87","size":"114.5"},{"price":"0.86","size":"108"},{"price":"0.85","size":"131.78"},{"price":"0.84","size":"96.6"},{"price":"0.83","size":"95.79"},{"price":"0.82","size":"122.7"},{"price":"0.81","size":"88.99"},{"price":"0.8","size":"89.99"},{"price":"0.79","size":"111.8"},{"price":"0.78","size":"61.2"},{"price":"0.77","size":"59.3"},{"price":"0.76","size":"87.6"},{"price":"0.75","size":"61"},{"price":"0.74","size":"54.6"},{"price":"0.73","size":"83.3"},{"price":"0.72","size":"52"},{"price":"0.71","size":"50.88"},{"price":"0.7","size":"80"},{"price":"0.69","size":"49.1"},{"price":"0.68","size":"48.18"},{"price":"0.67","size":"77.5"},{"price":"0.66","size":"46.79"},{"price":"0.65","size":"51.1"},{"price":"0.64","size":"80.58"},{"price":"0.63","size":"50.1"},{"price":"0.62","size":"49.6"},{"price":"0.61","size":"79.09"},{"price":"0.6","size":"48.7"},{"price":"0.59","size":"48.3"},{"price":"0.58","size":"78.09"},{"price":"0.57","size":"47.8"},{"price":"0.56","size":"47.6"},{"price":"0.55","size":"82.5"},{"price":"0.54","size":"47.3"},{"price":"0.53","size":"62.2"},{"price":"0.52","size":"77"},{"price":"0.51","size":"52"},{"price":"0.5","size":"47"},{"price":"0.49","size":"87"},{"price":"0.48","size":"47"},{"price":"0.47","size":"52.2"},{"price":"0.46","size":"92.3"},{"price":"0.45","size":"47.5"},{"price":"0.44","size":"47.6"},{"price":"0.43","size":"82.8"},{"price":"0.42","size":"123.09"},{"price":"0.41","size":"133.3"},{"price":"0.4","size":"182.31"},{"price":"0.39","size":"154.44"},{"price":"0.38","size":"134.03"},{"price":"0.37","size":"159.42"},{"price":"0.36","size":"134.28"},{"price":"0.35","size":"92.06"},{"price":"0.34","size":"155.67"},{"price":"0.33","size":"150.4"},{"price":"0.32","size":"28.22"},{"price":"0.31","size":"43.19"},{"price":"0.3","size":"28.35"},{"price":"0.29","size":"18.01"},{"price":"0.28","size":"50.54"},{"price":"0.27","size":"122.83"}],"asset_id":"8698449539441374295770236407991735029336433231649246775082939325523552031992","bids":[{"price":"0.01","size":"7844.52"},{"price":"0.02","size":"1065.79"},{"price":"0.03","size":"920.8"},{"price":"0.04","size":"803.5"},{"price":"0.05","size":"752"},{"price":"0.06","size":"833.79"},{"price":"0.07","size":"435.1"},{"price":"0.08","size":"257.04"},{"price":"0.09","size":"306.37"},{"price":"0.1","size":"333.6"},{"price":"0.11","size":"240.29"},{"price":"0.12","size":"233.4"},{"price":"0.13","size":"183.39"},{"price":"0.14","size":"143.2"},{"price":"0.15","size":"130.39"},{"price":"0.16","size":"131.6"},{"price":"0.17","size":"45.99"},{"price":"0.18","size":"66.19"},{"price":"0.19","size":"77.3"},{"price":"0.2","size":"63"},{"price":"0.21","size":"126.05"},{"price":"0.22","size":"143"},{"price":"0.23","size":"75"},{"price":"0.24","size":"10"},{"price":"0.25","size":"75"},{"price":"0.26","size":"18"}],"event_type":"book","hash":"8c02db2c75cde62f205ed4249cf5e0a80e997136","market":"0xf9d60bb033695053c4d1d8592e52171c1042f64b41a4b72e09dcc6f4852b6670","timestamp":"1785121875593"},"payload_hash":"76d716261e1448dbe8e58e10d658c3e7c32845d41056d2e78a06b2299db0de99","raw_frame":"{\"market\":\"0xf9d60bb033695053c4d1d8592e52171c1042f64b41a4b72e09dcc6f4852b6670\", \"asset_id\":\"8698449539441374295770236407991735029336433231649246775082939325523552031992\", \"bids\":[{\"price\":\"0.01\", \"size\":\"7844.52\"}, {\"price\":\"0.02\", \"size\":\"1065.79\"}, {\"price\":\"0.03\", \"size\":\"920.8\"}, {\"price\":\"0.04\", \"size\":\"803.5\"}, {\"price\":\"0.05\", \"size\":\"752\"}, {\"price\":\"0.06\", \"size\":\"833.79\"}, {\"price\":\"0.07\", \"size\":\"435.1\"}, {\"price\":\"0.08\", \"size\":\"257.04\"}, {\"price\":\"0.09\", \"size\":\"306.37\"}, {\"price\":\"0.1\", \"size\":\"333.6\"}, {\"price\":\"0.11\", \"size\":\"240.29\"}, {\"price\":\"0.12\", \"size\":\"233.4\"}, {\"price\":\"0.13\", \"size\":\"183.39\"}, {\"price\":\"0.14\", \"size\":\"143.2\"}, {\"price\":\"0.15\", \"size\":\"130.39\"}, {\"price\":\"0.16\", \"size\":\"131.6\"}, {\"price\":\"0.17\", \"size\":\"45.99\"}, {\"price\":\"0.18\", \"size\":\"66.19\"}, {\"price\":\"0.19\", \"size\":\"77.3\"}, {\"price\":\"0.2\", \"size\":\"63\"}, {\"price\":\"0.21\", \"size\":\"126.05\"}, {\"price\":\"0.22\", \"size\":\"143\"}, {\"price\":\"0.23\", \"size\":\"75\"}, {\"price\":\"0.24\", \"size\":\"10\"}, {\"price\":\"0.25\", \"size\":\"75\"}, {\"price\":\"0.26\", \"size\":\"18\"}], \"asks\":[{\"price\":\"0.99\", \"size\":\"7914.52\"}, {\"price\":\"0.98\", \"size\":\"1568.79\"}, {\"price\":\"0.97\", \"size\":\"1207.8\"}, {\"price\":\"0.96\", \"size\":\"1051.5\"}, {\"price\":\"0.95\", \"size\":\"921\"}, {\"price\":\"0.94\", \"size\":\"969.09\"}, {\"price\":\"0.93\", \"size\":\"882.7\"}, {\"price\":\"0.92\", \"size\":\"664.19\"}, {\"price\":\"0.91\", \"size\":\"878.9\"}, {\"price\":\"0.9\", \"size\":\"368.99\"}, {\"price\":\"0.89\", \"size\":\"125.79\"}, {\"price\":\"0.88\", \"size\":\"150.9\"}, {\"price\":\"0.87\", \"size\":\"114.5\"}, {\"price\":\"0.86\", \"size\":\"108\"}, {\"price\":\"0.85\", \"size\":\"131.78\"}, {\"price\":\"0.84\", \"size\":\"96.6\"}, {\"price\":\"0.83\", \"size\":\"95.79\"}, {\"price\":\"0.82\", \"size\":\"122.7\"}, {\"price\":\"0.81\", \"size\":\"88.99\"}, {\"price\":\"0.8\", \"size\":\"89.99\"}, {\"price\":\"0.79\", \"size\":\"111.8\"}, {\"price\":\"0.78\", \"size\":\"61.2\"}, {\"price\":\"0.77\", \"size\":\"59.3\"}, {\"price\":\"0.76\", \"size\":\"87.6\"}, {\"price\":\"0.75\", \"size\":\"61\"}, {\"price\":\"0.74\", \"size\":\"54.6\"}, {\"price\":\"0.73\", \"size\":\"83.3\"}, {\"price\":\"0.72\", \"size\":\"52\"}, {\"price\":\"0.71\", \"size\":\"50.88\"}, {\"price\":\"0.7\", \"size\":\"80\"}, {\"price\":\"0.69\", \"size\":\"49.1\"}, {\"price\":\"0.68\", \"size\":\"48.18\"}, {\"price\":\"0.67\", \"size\":\"77.5\"}, {\"price\":\"0.66\", \"size\":\"46.79\"}, {\"price\":\"0.65\", \"size\":\"51.1\"}, {\"price\":\"0.64\", \"size\":\"80.58\"}, {\"price\":\"0.63\", \"size\":\"50.1\"}, {\"price\":\"0.62\", \"size\":\"49.6\"}, {\"price\":\"0.61\", \"size\":\"79.09\"}, {\"price\":\"0.6\", \"size\":\"48.7\"}, {\"price\":\"0.59\", \"size\":\"48.3\"}, {\"price\":\"0.58\", \"size\":\"78.09\"}, {\"price\":\"0.57\", \"size\":\"47.8\"}, {\"price\":\"0.56\", \"size\":\"47.6\"}, {\"price\":\"0.55\", \"size\":\"82.5\"}, {\"price\":\"0.54\", \"size\":\"47.3\"}, {\"price\":\"0.53\", \"size\":\"62.2\"}, {\"price\":\"0.52\", \"size\":\"77\"}, {\"price\":\"0.51\", \"size\":\"52\"}, {\"price\":\"0.5\", \"size\":\"47\"}, {\"price\":\"0.49\", \"size\":\"87\"}, {\"price\":\"0.48\", \"size\":\"47\"}, {\"price\":\"0.47\", \"size\":\"52.2\"}, {\"price\":\"0.46\", \"size\":\"92.3\"}, {\"price\":\"0.45\", \"size\":\"47.5\"}, {\"price\":\"0.44\", \"size\":\"47.6\"}, {\"price\":\"0.43\", \"size\":\"82.8\"}, {\"price\":\"0.42\", \"size\":\"123.09\"}, {\"price\":\"0.41\", \"size\":\"133.3\"}, {\"price\":\"0.4\", \"size\":\"182.31\"}, {\"price\":\"0.39\", \"size\":\"154.44\"}, {\"price\":\"0.38\", \"size\":\"134.03\"}, {\"price\":\"0.37\", \"size\":\"159.42\"}, {\"price\":\"0.36\", \"size\":\"134.28\"}, {\"price\":\"0.35\", \"size\":\"92.06\"}, {\"price\":\"0.34\", \"size\":\"155.67\"}, {\"price\":\"0.33\", \"size\":\"150.4\"}, {\"price\":\"0.32\", \"size\":\"28.22\"}, {\"price\":\"0.31\", \"size\":\"43.19\"}, {\"price\":\"0.3\", \"size\":\"28.35\"}, {\"price\":\"0.29\", \"size\":\"18.01\"}, {\"price\":\"0.28\", \"size\":\"50.54\"}, {\"price\":\"0.27\", \"size\":\"122.83\"}], \"hash\":\"8c02db2c75cde62f205ed4249cf5e0a80e997136\", \"timestamp\":\"1785121875593\", \"event_type\":\"book\"}","received_at":"2026-07-27T03:11:24.061969Z","schema_version":"clob-market-ws.book.v1","sequence":null,"server_hash":"8c02db2c75cde62f205ed4249cf5e0a80e997136","server_timestamp":"1785121875593","session_id":"ff6d21c8283948938400a32613abec2c","source":"clob_market_ws"},"received_at":"2026-07-27T03:11:24.061969Z","record_id":"fb0d2383fb38606cb0f58924d04e447a08b73f06520faded55ecf044fa81a115","schema_fingerprint":"dc2caa1c89c6a7426e2e07ff925910cd4d0a8a223a515d4092d91d6d127aacb6","schema_version":"edge-lab-recorder.raw.v1","sequence":null,"source":"clob_market_ws"}
{"event_at":"2026-07-27T03:11:15.593000Z","event_fingerprint":"d2f9e0257cd037315e7343c7960ede2c91c99110c3fcabcf41c74a71a4b1c676","payload":{"connection_id":"f95883f18d264834af91809e5f803e9f","event_at":"2026-07-27T03:11:15.593000Z","event_type":"book","frame_hash":"d31e77bf0c76910a6e2706e988e12a7efe2b5e2010b86564242ef0f887e36c42","frame_index":0,"kind":"data","monotonic_ns":223867503422791,"payload":{"asks":[{"price":"0.99","size":"7844.52"},{"price":"0.98","size":"1065.79"},{"price":"0.97","size":"920.8"},{"price":"0.96","size":"803.5"},{"price":"0.95","size":"752"},{"price":"0.94","size":"833.79"},{"price":"0.93","size":"435.1"},{"price":"0.92","size":"257.04"},{"price":"0.91","size":"306.37"},{"price":"0.9","size":"333.6"},{"price":"0.89","size":"240.29"},{"price":"0.88","size":"233.4"},{"price":"0.87","size":"183.39"},{"price":"0.86","size":"143.2"},{"price":"0.85","size":"130.39"},{"price":"0.84","size":"131.6"},{"price":"0.83","size":"45.99"},{"price":"0.82","size":"66.19"},{"price":"0.81","size":"77.3"},{"price":"0.8","size":"63"},{"price":"0.79","size":"126.05"},{"price":"0.78","size":"143"},{"price":"0.77","size":"75"},{"price":"0.76","size":"10"},{"price":"0.75","size":"75"},{"price":"0.74","size":"18"}],"asset_id":"96283536366176669581486355171583722558858323126916278856549586825357358273536","bids":[{"price":"0.01","size":"7914.52"},{"price":"0.02","size":"1568.79"},{"price":"0.03","size":"1207.8"},{"price":"0.04","size":"1051.5"},{"price":"0.05","size":"921"},{"price":"0.06","size":"969.09"},{"price":"0.07","size":"882.7"},{"price":"0.08","size":"664.19"},{"price":"0.09","size":"878.9"},{"price":"0.1","size":"368.99"},{"price":"0.11","size":"125.79"},{"price":"0.12","size":"150.9"},{"price":"0.13","size":"114.5"},{"price":"0.14","size":"108"},{"price":"0.15","size":"131.78"},{"price":"0.16","size":"96.6"},{"price":"0.17","size":"95.79"},{"price":"0.18","size":"122.7"},{"price":"0.19","size":"88.99"},{"price":"0.2","size":"89.99"},{"price":"0.21","size":"111.8"},{"price":"0.22","size":"61.2"},{"price":"0.23","size":"59.3"},{"price":"0.24","size":"87.6"},{"price":"0.25","size":"61"},{"price":"0.26","size":"54.6"},{"price":"0.27","size":"83.3"},{"price":"0.28","size":"52"},{"price":"0.29","size":"50.88"},{"price":"0.3","size":"80"},{"price":"0.31","size":"49.1"},{"price":"0.32","size":"48.18"},{"price":"0.33","size":"77.5"},{"price":"0.34","size":"46.79"},{"price":"0.35","size":"51.1"},{"price":"0.36","size":"80.58"},{"price":"0.37","size":"50.1"},{"price":"0.38","size":"49.6"},{"price":"0.39","size":"79.09"},{"price":"0.4","size":"48.7"},{"price":"0.41","size":"48.3"},{"price":"0.42","size":"78.09"},{"price":"0.43","size":"47.8"},{"price":"0.44","size":"47.6"},{"price":"0.45","size":"82.5"},{"price":"0.46","size":"47.3"},{"price":"0.47","size":"62.2"},{"price":"0.48","size":"77"},{"price":"0.49","size":"52"},{"price":"0.5","size":"47"},{"price":"0.51","size":"87"},{"price":"0.52","size":"47"},{"price":"0.53","size":"52.2"},{"price":"0.54","size":"92.3"},{"price":"0.55","size":"47.5"},{"price":"0.56","size":"47.6"},{"price":"0.57","size":"82.8"},{"price":"0.58","size":"123.09"},{"price":"0.59","size":"133.3"},{"price":"0.6","size":"182.31"},{"price":"0.61","size":"154.44"},{"price":"0.62","size":"134.03"},{"price":"0.63","size":"159.42"},{"price":"0.64","size":"134.28"},{"price":"0.65","size":"92.06"},{"price":"0.66","size":"155.67"},{"price":"0.67","size":"150.4"},{"price":"0.68","size":"28.22"},{"price":"0.69","size":"43.19"},{"price":"0.7","size":"28.35"},{"price":"0.71","size":"18.01"},{"price":"0.72","size":"50.54"},{"price":"0.73","size":"122.83"}],"event_type":"book","hash":"1da46f67a7fea9da0442a7eea7acfe3eb88e1bcb","market":"0xf9d60bb033695053c4d1d8592e52171c1042f64b41a4b72e09dcc6f4852b6670","timestamp":"1785121875593"},"payload_hash":"2744a726f8d6214aecf99df835149fdaa177985d2b293380bc7ba43577195c9c","raw_frame":"{\"market\":\"0xf9d60bb033695053c4d1d8592e52171c1042f64b41a4b72e09dcc6f4852b6670\", \"asset_id\":\"96283536366176669581486355171583722558858323126916278856549586825357358273536\", \"bids\":[{\"price\":\"0.01\", \"size\":\"7914.52\"}, {\"price\":\"0.02\", \"size\":\"1568.79\"}, {\"price\":\"0.03\", \"size\":\"1207.8\"}, {\"price\":\"0.04\", \"size\":\"1051.5\"}, {\"price\":\"0.05\", \"size\":\"921\"}, {\"price\":\"0.06\", \"size\":\"969.09\"}, {\"price\":\"0.07\", \"size\":\"882.7\"}, {\"price\":\"0.08\", \"size\":\"664.19\"}, {\"price\":\"0.09\", \"size\":\"878.9\"}, {\"price\":\"0.1\", \"size\":\"368.99\"}, {\"price\":\"0.11\", \"size\":\"125.79\"}, {\"price\":\"0.12\", \"size\":\"150.9\"}, {\"price\":\"0.13\", \"size\":\"114.5\"}, {\"price\":\"0.14\", \"size\":\"108\"}, {\"price\":\"0.15\", \"size\":\"131.78\"}, {\"price\":\"0.16\", \"size\":\"96.6\"}, {\"price\":\"0.17\", \"size\":\"95.79\"}, {\"price\":\"0.18\", \"size\":\"122.7\"}, {\"price\":\"0.19\", \"size\":\"88.99\"}, {\"price\":\"0.2\", \"size\":\"89.99\"}, {\"price\":\"0.21\", \"size\":\"111.8\"}, {\"price\":\"0.22\", \"size\":\"61.2\"}, {\"price\":\"0.23\", \"size\":\"59.3\"}, {\"price\":\"0.24\", \"size\":\"87.6\"}, {\"price\":\"0.25\", \"size\":\"61\"}, {\"price\":\"0.26\", \"size\":\"54.6\"}, {\"price\":\"0.27\", \"size\":\"83.3\"}, {\"price\":\"0.28\", \"size\":\"52\"}, {\"price\":\"0.29\", \"size\":\"50.88\"}, {\"price\":\"0.3\", \"size\":\"80\"}, {\"price\":\"0.31\", \"size\":\"49.1\"}, {\"price\":\"0.32\", \"size\":\"48.18\"}, {\"price\":\"0.33\", \"size\":\"77.5\"}, {\"price\":\"0.34\", \"size\":\"46.79\"}, {\"price\":\"0.35\", \"size\":\"51.1\"}, {\"price\":\"0.36\", \"size\":\"80.58\"}, {\"price\":\"0.37\", \"size\":\"50.1\"}, {\"price\":\"0.38\", \"size\":\"49.6\"}, {\"price\":\"0.39\", \"size\":\"79.09\"}, {\"price\":\"0.4\", \"size\":\"48.7\"}, {\"price\":\"0.41\", \"size\":\"48.3\"}, {\"price\":\"0.42\", \"size\":\"78.09\"}, {\"price\":\"0.43\", \"size\":\"47.8\"}, {\"price\":\"0.44\", \"size\":\"47.6\"}, {\"price\":\"0.45\", \"size\":\"82.5\"}, {\"price\":\"0.46\", \"size\":\"47.3\"}, {\"price\":\"0.47\", \"size\":\"62.2\"}, {\"price\":\"0.48\", \"size\":\"77\"}, {\"price\":\"0.49\", \"size\":\"52\"}, {\"price\":\"0.5\", \"size\":\"47\"}, {\"price\":\"0.51\", \"size\":\"87\"}, {\"price\":\"0.52\", \"size\":\"47\"}, {\"price\":\"0.53\", \"size\":\"52.2\"}, {\"price\":\"0.54\", \"size\":\"92.3\"}, {\"price\":\"0.55\", \"size\":\"47.5\"}, {\"price\":\"0.56\", \"size\":\"47.6\"}, {\"price\":\"0.57\", \"size\":\"82.8\"}, {\"price\":\"0.58\", \"size\":\"123.09\"}, {\"price\":\"0.59\", \"size\":\"133.3\"}, {\"price\":\"0.6\", \"size\":\"182.31\"}, {\"price\":\"0.61\", \"size\":\"154.44\"}, {\"price\":\"0.62\", \"size\":\"134.03\"}, {\"price\":\"0.63\", \"size\":\"159.42\"}, {\"price\":\"0.64\", \"size\":\"134.28\"}, {\"price\":\"0.65\", \"size\":\"92.06\"}, {\"price\":\"0.66\", \"size\":\"155.67\"}, {\"price\":\"0.67\", \"size\":\"150.4\"}, {\"price\":\"0.68\", \"size\":\"28.22\"}, {\"price\":\"0.69\", \"size\":\"43.19\"}, {\"price\":\"0.7\", \"size\":\"28.35\"}, {\"price\":\"0.71\", \"size\":\"18.01\"}, {\"price\":\"0.72\", \"size\":\"50.54\"}, {\"price\":\"0.73\", \"size\":\"122.83\"}], \"asks\":[{\"price\":\"0.99\", \"size\":\"7844.52\"}, {\"price\":\"0.98\", \"size\":\"1065.79\"}, {\"price\":\"0.97\", \"size\":\"920.8\"}, {\"price\":\"0.96\", \"size\":\"803.5\"}, {\"price\":\"0.95\", \"size\":\"752\"}, {\"price\":\"0.94\", \"size\":\"833.79\"}, {\"price\":\"0.93\", \"size\":\"435.1\"}, {\"price\":\"0.92\", \"size\":\"257.04\"}, {\"price\":\"0.91\", \"size\":\"306.37\"}, {\"price\":\"0.9\", \"size\":\"333.6\"}, {\"price\":\"0.89\", \"size\":\"240.29\"}, {\"price\":\"0.88\", \"size\":\"233.4\"}, {\"price\":\"0.87\", \"size\":\"183.39\"}, {\"price\":\"0.86\", \"size\":\"143.2\"}, {\"price\":\"0.85\", \"size\":\"130.39\"}, {\"price\":\"0.84\", \"size\":\"131.6\"}, {\"price\":\"0.83\", \"size\":\"45.99\"}, {\"price\":\"0.82\", \"size\":\"66.19\"}, {\"price\":\"0.81\", \"size\":\"77.3\"}, {\"price\":\"0.8\", \"size\":\"63\"}, {\"price\":\"0.79\", \"size\":\"126.05\"}, {\"price\":\"0.78\", \"size\":\"143\"}, {\"price\":\"0.77\", \"size\":\"75\"}, {\"price\":\"0.76\", \"size\":\"10\"}, {\"price\":\"0.75\", \"size\":\"75\"}, {\"price\":\"0.74\", \"size\":\"18\"}], \"hash\":\"1da46f67a7fea9da0442a7eea7acfe3eb88e1bcb\", \"timestamp\":\"1785121875593\", \"event_type\":\"book\"}","received_at":"2026-07-27T03:11:24.172782Z","schema_version":"clob-market-ws.book.v1","sequence":null,"server_hash":"1da46f67a7fea9da0442a7eea7acfe3eb88e1bcb","server_timestamp":"1785121875593","session_id":"ff6d21c8283948938400a32613abec2c","source":"clob_market_ws"},"received_at":"2026-07-27T03:11:24.172782Z","record_id":"f73f321ca677362c33fc42d9a09e55206ad4c258689a5df76a7d44b4bb8b3fda","schema_fingerprint":"dc2caa1c89c6a7426e2e07ff925910cd4d0a8a223a515d4092d91d6d127aacb6","schema_version":"edge-lab-recorder.raw.v1","sequence":null,"source":"clob_market_ws"}
{"event_at":"2026-07-27T03:11:15.597000Z","event_fingerprint":"cbd12210dd1d07f54bbd1e49dfb2584cd5b70ec21b997c3b3a7a83c44d8817a3","payload":{"connection_id":"f95883f18d264834af91809e5f803e9f","event_at":"2026-07-27T03:11:15.597000Z","event_type":"price_change","frame_hash":"aee2af0161ec71da1af49fb1cbbd25ba0a40d3382a8ab66b8597bd71c4a6b3eb","frame_index":0,"kind":"data","monotonic_ns":223867514454041,"payload":{"event_type":"price_change","market":"0xf9d60bb033695053c4d1d8592e52171c1042f64b41a4b72e09dcc6f4852b6670","price_changes":[{"asset_id":"8698449539441374295770236407991735029336433231649246775082939325523552031992","best_ask":"0.27","best_bid":"0.26","hash":"2c2e0f96f5c72ca7faebbeaacf4904e08b4e3ce2","price":"0.08","side":"BUY","size":"252.04"},{"asset_id":"96283536366176669581486355171583722558858323126916278856549586825357358273536","best_ask":"0.74","best_bid":"0.73","hash":"8b5cc4ecee3e25ef6dd663cea8283cbb39cd0d57","price":"0.92","side":"SELL","size":"252.04"}],"timestamp":"1785121875597"},"payload_hash":"752d459134883f6caa5157f95f77f6d25adca44c59338cd1e66c84d0b9320d45","raw_frame":"{\"market\":\"0xf9d60bb033695053c4d1d8592e52171c1042f64b41a4b72e09dcc6f4852b6670\", \"price_changes\":[{\"asset_id\":\"8698449539441374295770236407991735029336433231649246775082939325523552031992\", \"price\":\"0.08\", \"size\":\"252.04\", \"side\":\"BUY\", \"hash\":\"2c2e0f96f5c72ca7faebbeaacf4904e08b4e3ce2\", \"best_bid\":\"0.26\", \"best_ask\":\"0.27\"}, {\"asset_id\":\"96283536366176669581486355171583722558858323126916278856549586825357358273536\", \"price\":\"0.92\", \"size\":\"252.04\", \"side\":\"SELL\", \"hash\":\"8b5cc4ecee3e25ef6dd663cea8283cbb39cd0d57\", \"best_bid\":\"0.73\", \"best_ask\":\"0.74\"}], \"timestamp\":\"1785121875597\", \"event_type\":\"price_change\"}","received_at":"2026-07-27T03:11:24.183821Z","schema_version":"clob-market-ws.price_change.v1","sequence":null,"server_hash":null,"server_timestamp":"1785121875597","session_id":"ff6d21c8283948938400a32613abec2c","source":"clob_market_ws"},"received_at":"2026-07-27T03:11:24.183821Z","record_id":"2a3458aba0be8cc1e4fe89f67a5b458c63b03601c8be773fa310f9b22c71bb19","schema_fingerprint":"4aa3821a28b0b7c2400bc59aba4bcc0a76e971dadd19610d3ad38c768e124dc7","schema_version":"edge-lab-recorder.raw.v1","sequence":null,"source":"clob_market_ws"}
{"event_at":"2026-07-27T03:11:15.597000Z","event_fingerprint":"ecd4712bca281e98c09991154ab6f88c7dcd89f2d73596745ba0f7c8ce36417e","payload":{"connection_id":"f95883f18d264834af91809e5f803e9f","event_at":"2026-07-27T03:11:15.597000Z","event_type":"price_change","frame_hash":"522296e6bbef2cf4ed354cc3baa91d8517b08798198c64732d29bf6ce4f85f92","frame_index":0,"kind":"data","monotonic_ns":223867518169166,"payload":{"event_type":"price_change","market":"0xf9d60bb033695053c4d1d8592e52171c1042f64b41a4b72e09dcc6f4852b6670","price_changes":[{"asset_id":"96283536366176669581486355171583722558858323126916278856549586825357358273536","best_ask":"0.74","best_bid":"0.73","hash":"0d42f61c23fd6e54c2ea0a27a9ceb6fe923dba21","price":"0.68","side":"BUY","size":"33.22"},{"asset_id":"8698449539441374295770236407991735029336433231649246775082939325523552031992","best_ask":"0.27","best_bid":"0.26","hash":"8bcd0779f681092e094010bc3e23f1ecdba85697","price":"0.32","side":"SELL","size":"33.22"}],"timestamp":"1785121875597"},"payload_hash":"ed6d1b70abe40b233814e75d18e272a540a965dbd30af0190ee2ec80254bfeb8","raw_frame":"{\"market\":\"0xf9d60bb033695053c4d1d8592e52171c1042f64b41a4b72e09dcc6f4852b6670\", \"price_changes\":[{\"asset_id\":\"96283536366176669581486355171583722558858323126916278856549586825357358273536\", \"price\":\"0.68\", \"size\":\"33.22\", \"side\":\"BUY\", \"hash\":\"0d42f61c23fd6e54c2ea0a27a9ceb6fe923dba21\", \"best_bid\":\"0.73\", \"best_ask\":\"0.74\"}, {\"asset_id\":\"8698449539441374295770236407991735029336433231649246775082939325523552031992\", \"price\":\"0.32\", \"size\":\"33.22\", \"side\":\"SELL\", \"hash\":\"8bcd0779f681092e094010bc3e23f1ecdba85697\", \"best_bid\":\"0.26\", \"best_ask\":\"0.27\"}], \"timestamp\":\"1785121875597\", \"event_type\":\"price_change\"}","received_at":"2026-07-27T03:11:24.187529Z","schema_version":"clob-market-ws.price_change.v1","sequence":null,"server_hash":null,"server_timestamp":"1785121875597","session_id":"ff6d21c8283948938400a32613abec2c","source":"clob_market_ws"},"received_at":"2026-07-27T03:11:24.187529Z","record_id":"b355323a240e5265c5439b5d3c9f875a0d86ab698dcb396210df064112cfed75","schema_fingerprint":"4aa3821a28b0b7c2400bc59aba4bcc0a76e971dadd19610d3ad38c768e124dc7","schema_version":"edge-lab-recorder.raw.v1","sequence":null,"source":"clob_market_ws"}
{"event_at":"2026-07-27T03:11:15.598000Z","event_fingerprint":"c9bb75b766e35f07e8bd3aa827ef56aea0d0864b4e7e5b0876c6761a5c5fc96c","payload":{"connection_id":"f95883f18d264834af91809e5f803e9f","event_at":"2026-07-27T03:11:15.598000Z","event_type":"price_change","frame_hash":"9b76de126e5a274ffdca2a2fc1d885b39fdeaa903ff31af82be099420fe58e12","frame_index":0,"kind":"data","monotonic_ns":223867521285000,"payload":{"event_type":"price_change","market":"0xf9d60bb033695053c4d1d8592e52171c1042f64b41a4b72e09dcc6f4852b6670","price_changes":[{"asset_id":"8698449539441374295770236407991735029336433231649246775082939325523552031992","best_ask":"0.27","best_bid":"0.26","hash":"1c6f531d85923873e2d6a73156769cb9b55db4a9","price":"0.16","side":"BUY","size":"161.4"},{"asset_id":"96283536366176669581486355171583722558858323126916278856549586825357358273536","best_ask":"0.74","best_bid":"0.73","hash":"9a1a6ef792faaf83b8f17d318fccb1d05aae7dff","price":"0.84","side":"SELL","size":"161.4"}],"timestamp":"1785121875598"},"payload_hash":"bc77eb422909145eb65085f7c569c6c98cb22a7f22c64ad82d09de4e8754f7a7","raw_frame":"{\"market\":\"0xf9d60bb033695053c4d1d8592e52171c1042f64b41a4b72e09dcc6f4852b6670\", \"price_changes\":[{\"asset_id\":\"8698449539441374295770236407991735029336433231649246775082939325523552031992\", \"price\":\"0.16\", \"size\":\"161.4\", \"side\":\"BUY\", \"hash\":\"1c6f531d85923873e2d6a73156769cb9b55db4a9\", \"best_bid\":\"0.26\", \"best_ask\":\"0.27\"}, {\"asset_id\":\"96283536366176669581486355171583722558858323126916278856549586825357358273536\", \"price\":\"0.84\", \"size\":\"161.4\", \"side\":\"SELL\", \"hash\":\"9a1a6ef792faaf83b8f17d318fccb1d05aae7dff\", \"best_bid\":\"0.73\", \"best_ask\":\"0.74\"}], \"timestamp\":\"1785121875598\", \"event_type\":\"price_change\"}","received_at":"2026-07-27T03:11:24.190645Z","schema_version":"clob-market-ws.price_change.v1","sequence":null,"server_hash":null,"server_timestamp":"1785121875598","session_id":"ff6d21c8283948938400a32613abec2c","source":"clob_market_ws"},"received_at":"2026-07-27T03:11:24.190645Z","record_id":"d796b1ef018d2afce8b8990da6ce8217bc2ce0e531b29be27754d38530df2f76","schema_fingerprint":"4aa3821a28b0b7c2400bc59aba4bcc0a76e971dadd19610d3ad38c768e124dc7","schema_version":"edge-lab-recorder.raw.v1","sequence":null,"source":"clob_market_ws"}
{"event_at":"2026-07-27T03:11:15.608000Z","event_fingerprint":"816c43da2eeb85f05fe66deff1b8fc9d7102967ab7c28076e4ac73e48872dc88","payload":{"connection_id":"f95883f18d264834af91809e5f803e9f","event_at":"2026-07-27T03:11:15.608000Z","event_type":"price_change","frame_hash":"4d7969198cc86b57b26734d9c56f04699eb7d8f13c157c3f3834abddcf70cef2","frame_index":0,"kind":"data","monotonic_ns":223867524477750,"payload":{"event_type":"price_change","market":"0xf9d60bb033695053c4d1d8592e52171c1042f64b41a4b72e09dcc6f4852b6670","price_changes":[{"asset_id":"96283536366176669581486355171583722558858323126916278856549586825357358273536","best_ask":"0.74","best_bid":"0.73","hash":"69de1a111236c07ef60b640fcce7e811b64da0f0","price":"0.01","side":"BUY","size":"7909.52"},{"asset_id":"8698449539441374295770236407991735029336433231649246775082939325523552031992","best_ask":"0.27","best_bid":"0.26","hash":"2305f65b59cf093438e00b017ffba38cea447e2d","price":"0.99","side":"SELL","size":"7909.52"}],"timestamp":"1785121875608"},"payload_hash":"b64274f7717da58970a2a9fcf5ffb9728d46ff1a556ea5f73374e4d7326e5f05","raw_frame":"{\"market\":\"0xf9d60bb033695053c4d1d8592e52171c1042f64b41a4b72e09dcc6f4852b6670\", \"price_changes\":[{\"asset_id\":\"96283536366176669581486355171583722558858323126916278856549586825357358273536\", \"price\":\"0.01\", \"size\":\"7909.52\", \"side\":\"BUY\", \"hash\":\"69de1a111236c07ef60b640fcce7e811b64da0f0\", \"best_bid\":\"0.73\", \"best_ask\":\"0.74\"}, {\"asset_id\":\"8698449539441374295770236407991735029336433231649246775082939325523552031992\", \"price\":\"0.99\", \"size\":\"7909.52\", \"side\":\"SELL\", \"hash\":\"2305f65b59cf093438e00b017ffba38cea447e2d\", \"best_bid\":\"0.26\", \"best_ask\":\"0.27\"}], \"timestamp\":\"1785121875608\", \"event_type\":\"price_change\"}","received_at":"2026-07-27T03:11:24.193838Z","schema_version":"clob-market-ws.price_change.v1","sequence":null,"server_hash":null,"server_timestamp":"1785121875608","session_id":"ff6d21c8283948938400a32613abec2c","source":"clob_market_ws"},"received_at":"2026-07-27T03:11:24.193838Z","record_id":"41171599b8dadaa2dcf76ab12578492c6bb42deeed8bc1687e121203119d99c6","schema_fingerprint":"4aa3821a28b0b7c2400bc59aba4bcc0a76e971dadd19610d3ad38c768e124dc7","schema_version":"edge-lab-recorder.raw.v1","sequence":null,"source":"clob_market_ws"}
{"event_at":"2026-07-27T03:11:15.610000Z","event_fingerprint":"98315e3ff5d08fd4fe27f762a6f2d61984ce1d6a4dee577686d60d3d79d1ab9c","payload":{"connection_id":"f95883f18d264834af91809e5f803e9f","event_at":"2026-07-27T03:11:15.610000Z","event_type":"price_change","frame_hash":"6cf1b0833dbbbf6a982cdbddc0bc6004d81ea87b491803b7498c5a52908e3a23","frame_index":0,"kind":"data","monotonic_ns":223867527452000,"payload":{"event_type":"price_change","market":"0xf9d60bb033695053c4d1d8592e52171c1042f64b41a4b72e09dcc6f4852b6670","price_changes":[{"asset_id":"96283536366176669581486355171583722558858323126916278856549586825357358273536","best_ask":"0.74","best_bid":"0.73","hash":"cf5e58e4d7df4625a815200d9daf3518a8fe7136","price":"0.65","side":"BUY","size":"82.06"},{"asset_id":"8698449539441374295770236407991735029336433231649246775082939325523552031992","best_ask":"0.27","best_bid":"0.26","hash":"49f2298675b0695b232f5b09101aac323a471976","price":"0.35","side":"SELL","size":"82.06"}],"timestamp":"1785121875610"},"payload_hash":"62cf7a5cd1cf8df6896d3421c433de7977271624223e53e7cf83d75ea63abadb","raw_frame":"{\"market\":\"0xf9d60bb033695053c4d1d8592e52171c1042f64b41a4b72e09dcc6f4852b6670\", \"price_changes\":[{\"asset_id\":\"96283536366176669581486355171583722558858323126916278856549586825357358273536\", \"price\":\"0.65\", \"size\":\"82.06\", \"side\":\"BUY\", \"hash\":\"cf5e58e4d7df4625a815200d9daf3518a8fe7136\", \"best_bid\":\"0.73\", \"best_ask\":\"0.74\"}, {\"asset_id\":\"8698449539441374295770236407991735029336433231649246775082939325523552031992\", \"price\":\"0.35\", \"size\":\"82.06\", \"side\":\"SELL\", \"hash\":\"49f2298675b0695b232f5b09101aac323a471976\", \"best_bid\":\"0.26\", \"best_ask\":\"0.27\"}], \"timestamp\":\"1785121875610\", \"event_type\":\"price_change\"}","received_at":"2026-07-27T03:11:24.196812Z","schema_version":"clob-market-ws.price_change.v1","sequence":null,"server_hash":null,"server_timestamp":"1785121875610","session_id":"ff6d21c8283948938400a32613abec2c","source":"clob_market_ws"},"received_at":"2026-07-27T03:11:24.196812Z","record_id":"5c0cf5cdf6e3d35d3919d9a89e6335f4c2089ac39c21eb5ff343ca93ccadfb2e","schema_fingerprint":"4aa3821a28b0b7c2400bc59aba4bcc0a76e971dadd19610d3ad38c768e124dc7","schema_version":"edge-lab-recorder.raw.v1","sequence":null,"source":"clob_market_ws"}
{"event_at":"2026-07-27T03:11:15.610000Z","event_fingerprint":"3235d045d5a87693b3e7b6aa802daed1b27c6cfe94c00208f4926ec7ab4dae7c","payload":{"connection_id":"f95883f18d264834af91809e5f803e9f","event_at":"2026-07-27T03:11:15.610000Z","event_type":"price_change","frame_hash":"60f7ffd4f8a27c244d2fe4e4dcd4be5a02a9f06fb671d6e4b77bda34df1399e5","frame_index":0,"kind":"data","monotonic_ns":223867544662000,"payload":{"event_type":"price_change","market":"0xf9d60bb033695053c4d1d8592e52171c1042f64b41a4b72e09dcc6f4852b6670","price_changes":[{"asset_id":"96283536366176669581486355171583722558858323126916278856549586825357358273536","best_ask":"0.74","best_bid":"0.73","hash":"cd15c562d239091b8992089e34f3c95538d17fc1","price":"0.64","side":"BUY","size":"124.28"},{"asset_id":"8698449539441374295770236407991735029336433231649246775082939325523552031992","best_ask":"0.27","best_bid":"0.26","hash":"5bf2da4add0fa41325bd98fd4b0d87d8a3927bdb","price":"0.36","side":"SELL","size":"124.28"}],"timestamp":"1785121875610"},"payload_hash":"9b060d4e4f7e7c4dab9e9bd786f39e875475d617da0a572c2b1f9cf5f9a406a3","raw_frame":"{\"market\":\"0xf9d60bb033695053c4d1d8592e52171c1042f64b41a4b72e09dcc6f4852b6670\", \"price_changes\":[{\"asset_id\":\"96283536366176669581486355171583722558858323126916278856549586825357358273536\", \"price\":\"0.64\", \"size\":\"124.28\", \"side\":\"BUY\", \"hash\":\"cd15c562d239091b8992089e34f3c95538d17fc1\", \"best_bid\":\"0.73\", \"best_ask\":\"0.74\"}, {\"asset_id\":\"8698449539441374295770236407991735029336433231649246775082939325523552031992\", \"price\":\"0.36\", \"size\":\"124.28\", \"side\":\"SELL\", \"hash\":\"5bf2da4add0fa41325bd98fd4b0d87d8a3927bdb\", \"best_bid\":\"0.26\", \"best_ask\":\"0.27\"}], \"timestamp\":\"1785121875610\", \"event_type\":\"price_change\"}","received_at":"2026-07-27T03:11:24.214018Z","schema_version":"clob-market-ws.price_change.v1","sequence":null,"server_hash":null,"server_timestamp":"1785121875610","session_id":"ff6d21c8283948938400a32613abec2c","source":"clob_market_ws"},"received_at":"2026-07-27T03:11:24.214018Z","record_id":"50e56c729ee1fa1f214d3c7da65c4dd1fe0bc649d663c58f7e7ac04d586dbe46","schema_fingerprint":"4aa3821a28b0b7c2400bc59aba4bcc0a76e971dadd19610d3ad38c768e124dc7","schema_version":"edge-lab-recorder.raw.v1","sequence":null,"source":"clob_market_ws"}
{"event_at":"2026-07-27T03:11:15.615000Z","event_fingerprint":"afcbc9516a52d58a8e70b3f8e74b1da6ce85d314634f8a34570bc883dd549dec","payload":{"connection_id":"f95883f18d264834af91809e5f803e9f","event_at":"2026-07-27T03:11:15.615000Z","event_type":"price_change","frame_hash":"08e9dcbf647daf7d279c5450c6f3e66fb043b64f5a434498c3027bea420d3308","frame_index":0,"kind":"data","monotonic_ns":223867547670291,"payload":{"event_type":"price_change","market":"0xf9d60bb033695053c4d1d8592e52171c1042f64b41a4b72e09dcc6f4852b6670","price_changes":[{"asset_id":"96283536366176669581486355171583722558858323126916278856549586825357358273536","best_ask":"0.74","best_bid":"0.73","hash":"ebbc296e79510a6d20a8714e353a77e1a7e83d10","price":"0.67","side":"BUY","size":"140.4"},{"asset_id":"8698449539441374295770236407991735029336433231649246775082939325523552031992","best_ask":"0.27","best_bid":"0.26","hash":"7a0f4483745c49c1418d99a4bbc79a80600891ba","price":"0.33","side":"SELL","size":"140.4"}],"timestamp":"1785121875615"},"payload_hash":"51917ec7ae983c1e792be612ef90e82c9351e0d0254bd1370651efc7e1f748cb","raw_frame":"{\"market\":\"0xf9d60bb033695053c4d1d8592e52171c1042f64b41a4b72e09dcc6f4852b6670\", \"price_changes\":[{\"asset_id\":\"96283536366176669581486355171583722558858323126916278856549586825357358273536\", \"price\":\"0.67\", \"size\":\"140.4\", \"side\":\"BUY\", \"hash\":\"ebbc296e79510a6d20a8714e353a77e1a7e83d10\", \"best_bid\":\"0.73\", \"best_ask\":\"0.74\"}, {\"asset_id\":\"8698449539441374295770236407991735029336433231649246775082939325523552031992\", \"price\":\"0.33\", \"size\":\"140.4\", \"side\":\"SELL\", \"hash\":\"7a0f4483745c49c1418d99a4bbc79a80600891ba\", \"best_bid\":\"0.26\", \"best_ask\":\"0.27\"}], \"timestamp\":\"1785121875615\", \"event_type\":\"price_change\"}","received_at":"2026-07-27T03:11:24.217036Z","schema_version":"clob-market-ws.price_change.v1","sequence":null,"server_hash":null,"server_timestamp":"1785121875615","session_id":"ff6d21c8283948938400a32613abec2c","source":"clob_market_ws"},"received_at":"2026-07-27T03:11:24.217036Z","record_id":"b880476acf6e35726eae31c71a1a251fd30f14b9321454e3e8ec322e007b3a75","schema_fingerprint":"4aa3821a28b0b7c2400bc59aba4bcc0a76e971dadd19610d3ad38c768e124dc7","schema_version":"edge-lab-recorder.raw.v1","sequence":null,"source":"clob_market_ws"}
{"event_at":"2026-07-27T03:11:15.616000Z","event_fingerprint":"c7fb8fcf4f4e408f4e3f02bc05fa6ad93ebf5260631e9defa8857c3108b4cf8f","payload":{"connection_id":"f95883f18d264834af91809e5f803e9f","event_at":"2026-07-27T03:11:15.616000Z","event_type":"price_change","frame_hash":"495216c243e12aa8c527e24d68df10a221790bfb4e83727288a5a34cee7c1a44","frame_index":0,"kind":"data","monotonic_ns":223867550050291,"payload":{"event_type":"price_change","market":"0xf9d60bb033695053c4d1d8592e52171c1042f64b41a4b72e09dcc6f4852b6670","price_changes":[{"asset_id":"96283536366176669581486355171583722558858323126916278856549586825357358273536","best_ask":"0.74","best_bid":"0.73","hash":"2b77731f534cbd916ae784344c6b600934933e95","price":"0.66","side":"BUY","size":"145.67"},{"asset_id":"8698449539441374295770236407991735029336433231649246775082939325523552031992","best_ask":"0.27","best_bid":"0.26","hash":"ddb5154d76125fcdb72403721b11715fd6eeddc2","price":"0.34","side":"SELL","size":"145.67"}],"timestamp":"1785121875616"},"payload_hash":"cfd02f9d66325427ac0ab48cbf4fb5ebb7c20865a560cf298e5ea6e8cdc3936c","raw_frame":"{\"market\":\"0xf9d60bb033695053c4d1d8592e52171c1042f64b41a4b72e09dcc6f4852b6670\", \"price_changes\":[{\"asset_id\":\"96283536366176669581486355171583722558858323126916278856549586825357358273536\", \"price\":\"0.66\", \"size\":\"145.67\", \"side\":\"BUY\", \"hash\":\"2b77731f534cbd916ae784344c6b600934933e95\", \"best_bid\":\"0.73\", \"best_ask\":\"0.74\"}, {\"asset_id\":\"8698449539441374295770236407991735029336433231649246775082939325523552031992\", \"price\":\"0.34\", \"size\":\"145.67\", \"side\":\"SELL\", \"hash\":\"ddb5154d76125fcdb72403721b11715fd6eeddc2\", \"best_bid\":\"0.26\", \"best_ask\":\"0.27\"}], \"timestamp\":\"1785121875616\", \"event_type\":\"price_change\"}","received_at":"2026-07-27T03:11:24.219408Z","schema_version":"clob-market-ws.price_change.v1","sequence":null,"server_hash":null,"server_timestamp":"1785121875616","session_id":"ff6d21c8283948938400a32613abec2c","source":"clob_market_ws"},"received_at":"2026-07-27T03:11:24.219408Z","record_id":"fa6da08a46aa3b3909236f19fb895efa0f0f6f54b28f6990ac56c53b4507ca1b","schema_fingerprint":"4aa3821a28b0b7c2400bc59aba4bcc0a76e971dadd19610d3ad38c768e124dc7","schema_version":"edge-lab-recorder.raw.v1","sequence":null,"source":"clob_market_ws"}
{"event_at":"2026-07-27T03:11:15.617000Z","event_fingerprint":"9443d78b6a917438d5a3beb8f55098f8b4dc5273efea1af6920b2d3e5be71a31","payload":{"connection_id":"f95883f18d264834af91809e5f803e9f","event_at":"2026-07-27T03:11:15.617000Z","event_type":"price_change","frame_hash":"49aa383633b2bddf6b91d415f4b26265a9a85c87a23b3f5a6d768d3bd4c4466b","frame_index":0,"kind":"data","monotonic_ns":223867557408666,"payload":{"event_type":"price_change","market":"0xf9d60bb033695053c4d1d8592e52171c1042f64b41a4b72e09dcc6f4852b6670","price_changes":[{"asset_id":"8698449539441374295770236407991735029336433231649246775082939325523552031992","best_ask":"0.27","best_bid":"0.26","hash":"995748f45799c94fc202ecf4834c78039031d941","price":"0.21","side":"BUY","size":"116.05"},{"asset_id":"96283536366176669581486355171583722558858323126916278856549586825357358273536","best_ask":"0.74","best_bid":"0.73","hash":"f4ba2d3a70b3e27a03805c10ac8a9211387baa01","price":"0.79","side":"SELL","size":"116.05"}],"timestamp":"1785121875617"},"payload_hash":"0e100eef7e1a5b20a8d58c237adc413268b7ef0eb698fdf0d0c413edeedffb23","raw_frame":"{\"market\":\"0xf9d60bb033695053c4d1d8592e52171c1042f64b41a4b72e09dcc6f4852b6670\", \"price_changes\":[{\"asset_id\":\"8698449539441374295770236407991735029336433231649246775082939325523552031992\", \"price\":\"0.21\", \"size\":\"116.05\", \"side\":\"BUY\", \"hash\":\"995748f45799c94fc202ecf4834c78039031d941\", \"best_bid\":\"0.26\", \"best_ask\":\"0.27\"}, {\"asset_id\":\"96283536366176669581486355171583722558858323126916278856549586825357358273536\", \"price\":\"0.79\", \"size\":\"116.05\", \"side\":\"SELL\", \"hash\":\"f4ba2d3a70b3e27a03805c10ac8a9211387baa01\", \"best_bid\":\"0.73\", \"best_ask\":\"0.74\"}], \"timestamp\":\"1785121875617\", \"event_type\":\"price_change\"}","received_at":"2026-07-27T03:11:24.226768Z","schema_version":"clob-market-ws.price_change.v1","sequence":null,"server_hash":null,"server_timestamp":"1785121875617","session_id":"ff6d21c8283948938400a32613abec2c","source":"clob_market_ws"},"received_at":"2026-07-27T03:11:24.226768Z","record_id":"0c011797669349a632e039e2a8091dad17f119c1698151ce1d974c2fb60b43a6","schema_fingerprint":"4aa3821a28b0b7c2400bc59aba4bcc0a76e971dadd19610d3ad38c768e124dc7","schema_version":"edge-lab-recorder.raw.v1","sequence":null,"source":"clob_market_ws"}
{"event_at":"2026-07-27T03:11:15.619000Z","event_fingerprint":"5dfe9e522a42c6c6f2be30fe97f42e1cc03ffbf542d5f9487efc17df916b7896","payload":{"connection_id":"f95883f18d264834af91809e5f803e9f","event_at":"2026-07-27T03:11:15.619000Z","event_type":"price_change","frame_hash":"9f1153ab8cb118ed33e0cb28975013c3ca1416ed6afd4d4ac6a191b55efd5449","frame_index":0,"kind":"data","monotonic_ns":223867561714250,"payload":{"event_type":"price_change","market":"0xf9d60bb033695053c4d1d8592e52171c1042f64b41a4b72e09dcc6f4852b6670","price_changes":[{"asset_id":"8698449539441374295770236407991735029336433231649246775082939325523552031992","best_ask":"0.27","best_bid":"0.26","hash":"07f83576f7212a8fb03872d142750dd9a2efd11e","price":"0.17","side":"BUY","size":"55.99"},{"asset_id":"96283536366176669581486355171583722558858323126916278856549586825357358273536","best_ask":"0.74","best_bid":"0.73","hash":"94383e3bcff976a2c585392e79029ba69d4ed71c","price":"0.83","side":"SELL","size":"55.99"}],"timestamp":"1785121875619"},"payload_hash":"83b7c05669f1d868c5ae06902f98158f63f965ef56c179a88b2987f90f8fdd4e","raw_frame":"{\"market\":\"0xf9d60bb033695053c4d1d8592e52171c1042f64b41a4b72e09dcc6f4852b6670\", \"price_changes\":[{\"asset_id\":\"8698449539441374295770236407991735029336433231649246775082939325523552031992\", \"price\":\"0.17\", \"size\":\"55.99\", \"side\":\"BUY\", \"hash\":\"07f83576f7212a8fb03872d142750dd9a2efd11e\", \"best_bid\":\"0.26\", \"best_ask\":\"0.27\"}, {\"asset_id\":\"96283536366176669581486355171583722558858323126916278856549586825357358273536\", \"price\":\"0.83\", \"size\":\"55.99\", \"side\":\"SELL\", \"hash\":\"94383e3bcff976a2c585392e79029ba69d4ed71c\", \"best_bid\":\"0.73\", \"best_ask\":\"0.74\"}], \"timestamp\":\"1785121875619\", \"event_type\":\"price_change\"}","received_at":"2026-07-27T03:11:24.231074Z","schema_version":"clob-market-ws.price_change.v1","sequence":null,"server_hash":null,"server_timestamp":"1785121875619","session_id":"ff6d21c8283948938400a32613abec2c","source":"clob_market_ws"},"received_at":"2026-07-27T03:11:24.231074Z","record_id":"0570d5dffd3894f91ae64a74d999b3763ce3ea52a10970e8e1a90e33d7f174cb","schema_fingerprint":"4aa3821a28b0b7c2400bc59aba4bcc0a76e971dadd19610d3ad38c768e124dc7","schema_version":"edge-lab-recorder.raw.v1","sequence":null,"source":"clob_market_ws"}
{"event_at":"2026-07-27T03:11:15.620000Z","event_fingerprint":"344adb516cf96ec5daa6f5ada632432bccf113607c05e0367aa366378d4fd16c","payload":{"connection_id":"f95883f18d264834af91809e5f803e9f","event_at":"2026-07-27T03:11:15.620000Z","event_type":"price_change","frame_hash":"103890c784105d962c4245663647b1529adb39c94d501fae8b3f51a672491b67","frame_index":0,"kind":"data","monotonic_ns":223867577803333,"payload":{"event_type":"price_change","market":"0xf9d60bb033695053c4d1d8592e52171c1042f64b41a4b72e09dcc6f4852b6670","price_changes":[{"asset_id":"96283536366176669581486355171583722558858323126916278856549586825357358273536","best_ask":"0.74","best_bid":"0.73","hash":"04644ac4bb79d776784b6b9201d79cf3a041e72f","price":"0.71","side":"BUY","size":"28.01"},{"asset_id":"8698449539441374295770236407991735029336433231649246775082939325523552031992","best_ask":"0.27","best_bid":"0.26","hash":"ed34747b51562bad6432c52b5db455812dd4001d","price":"0.29","side":"SELL","size":"28.01"}],"timestamp":"1785121875620"},"payload_hash":"ca7aa163c744c679e394199eaa46dc4aa21c6c4810eb318be295f43a5fad9269","raw_frame":"{\"market\":\"0xf9d60bb033695053c4d1d8592e52171c1042f64b41a4b72e09dcc6f4852b6670\", \"price_changes\":[{\"asset_id\":\"96283536366176669581486355171583722558858323126916278856549586825357358273536\", \"price\":\"0.71\", \"size\":\"28.01\", \"side\":\"BUY\", \"hash\":\"04644ac4bb79d776784b6b9201d79cf3a041e72f\", \"best_bid\":\"0.73\", \"best_ask\":\"0.74\"}, {\"asset_id\":\"8698449539441374295770236407991735029336433231649246775082939325523552031992\", \"price\":\"0.29\", \"size\":\"28.01\", \"side\":\"SELL\", \"hash\":\"ed34747b51562bad6432c52b5db455812dd4001d\", \"best_bid\":\"0.26\", \"best_ask\":\"0.27\"}], \"timestamp\":\"1785121875620\", \"event_type\":\"price_change\"}","received_at":"2026-07-27T03:11:24.247167Z","schema_version":"clob-market-ws.price_change.v1","sequence":null,"server_hash":null,"server_timestamp":"1785121875620","session_id":"ff6d21c8283948938400a32613abec2c","source":"clob_market_ws"},"received_at":"2026-07-27T03:11:24.247167Z","record_id":"4dd2c02c5d5229b3c65447b5dbf9481aa4dca2e9aec9218108691378921f8623","schema_fingerprint":"4aa3821a28b0b7c2400bc59aba4bcc0a76e971dadd19610d3ad38c768e124dc7","schema_version":"edge-lab-recorder.raw.v1","sequence":null,"source":"clob_market_ws"}
{"event_at":"2026-07-27T03:11:15.621000Z","event_fingerprint":"83549d92e69192200c6c4f14a0d616d935d24f74b8c5ab43fea544aa30463e93","payload":{"connection_id":"f95883f18d264834af91809e5f803e9f","event_at":"2026-07-27T03:11:15.621000Z","event_type":"price_change","frame_hash":"7c30b43f01a1bb8d4b31700c2491753adc1c20a76b2a164765cafd70e0529abd","frame_index":0,"kind":"data","monotonic_ns":223867593203791,"payload":{"event_type":"price_change","market":"0xf9d60bb033695053c4d1d8592e52171c1042f64b41a4b72e09dcc6f4852b6670","price_changes":[{"asset_id":"96283536366176669581486355171583722558858323126916278856549586825357358273536","best_ask":"0.74","best_bid":"0.73","hash":"441d72bb63e8b17f2c5e3576a3db6d26cb9d5c30","price":"0.68","side":"BUY","size":"43.22"},{"asset_id":"8698449539441374295770236407991735029336433231649246775082939325523552031992","best_ask":"0.27","best_bid":"0.26","hash":"c58cfaf5eb01afced7728f882fd2ec48f42024e0","price":"0.32","side":"SELL","size":"43.22"}],"timestamp":"1785121875621"},"payload_hash":"94924275cc24b4468a0892b6d0f60ab4c5fe1d4c39c9a08aca4c96be0f4e9380","raw_frame":"{\"market\":\"0xf9d60bb033695053c4d1d8592e52171c1042f64b41a4b72e09dcc6f4852b6670\", \"price_changes\":[{\"asset_id\":\"96283536366176669581486355171583722558858323126916278856549586825357358273536\", \"price\":\"0.68\", \"size\":\"43.22\", \"side\":\"BUY\", \"hash\":\"441d72bb63e8b17f2c5e3576a3db6d26cb9d5c30\", \"best_bid\":\"0.73\", \"best_ask\":\"0.74\"}, {\"asset_id\":\"8698449539441374295770236407991735029336433231649246775082939325523552031992\", \"price\":\"0.32\", \"size\":\"43.22\", \"side\":\"SELL\", \"hash\":\"c58cfaf5eb01afced7728f882fd2ec48f42024e0\", \"best_bid\":\"0.26\", \"best_ask\":\"0.27\"}], \"timestamp\":\"1785121875621\", \"event_type\":\"price_change\"}","received_at":"2026-07-27T03:11:24.262563Z","schema_version":"clob-market-ws.price_change.v1","sequence":null,"server_hash":null,"server_timestamp":"1785121875621","session_id":"ff6d21c8283948938400a32613abec2c","source":"clob_market_ws"},"received_at":"2026-07-27T03:11:24.262563Z","record_id":"b5327a4661eee44eca05be9671f66a09b3a83cf38f63d4287c0156153f6cf005","schema_fingerprint":"4aa3821a28b0b7c2400bc59aba4bcc0a76e971dadd19610d3ad38c768e124dc7","schema_version":"edge-lab-recorder.raw.v1","sequence":null,"source":"clob_market_ws"}
{"event_at":"2026-07-27T03:11:15.630000Z","event_fingerprint":"581cf0c87f8abc47946b9a2d5ed1430ce9b07bee0bdffa3b62a89318892c52ae","payload":{"connection_id":"f95883f18d264834af91809e5f803e9f","event_at":"2026-07-27T03:11:15.630000Z","event_type":"last_trade_price","frame_hash":"e13c5a1f330c6cb55000cb069132863258c1e03fc232dcb08a1f072f2dc19b4c","frame_index":0,"kind":"data","monotonic_ns":223867611887916,"payload":{"asset_id":"96283536366176669581486355171583722558858323126916278856549586825357358273536","event_type":"last_trade_price","fee_rate_bps":"0","market":"0xf9d60bb033695053c4d1d8592e52171c1042f64b41a4b72e09dcc6f4852b6670","price":"0.74","side":"BUY","size":"5","timestamp":"1785121875630","transaction_hash":"0xb4f5b21f6fc77bff9066f701dc773bfce84019fb3aa4effe2455823785ee2329"},"payload_hash":"52cab379368910048962dc8aeeb24b0bb6a3038e4477353a99d2d34426288da8","raw_frame":"{\"market\":\"0xf9d60bb033695053c4d1d8592e52171c1042f64b41a4b72e09dcc6f4852b6670\", \"asset_id\":\"96283536366176669581486355171583722558858323126916278856549586825357358273536\", \"price\":\"0.74\", \"size\":\"5\", \"fee_rate_bps\":\"0\", \"side\":\"BUY\", \"timestamp\":\"1785121875630\", \"event_type\":\"last_trade_price\", \"transaction_hash\":\"0xb4f5b21f6fc77bff9066f701dc773bfce84019fb3aa4effe2455823785ee2329\"}","received_at":"2026-07-27T03:11:24.281253Z","schema_version":"clob-market-ws.last_trade_price.v1","sequence":null,"server_hash":null,"server_timestamp":"1785121875630","session_id":"ff6d21c8283948938400a32613abec2c","source":"clob_market_ws"},"received_at":"2026-07-27T03:11:24.281253Z","record_id":"d537a13b7e0ad292613e7666f90962373d87488924a66e73d93d7dcb01561a83","schema_fingerprint":"95ad9be75a4b695cd99991e12b2592bc7346f3f5388a82d0000ba65bc0d9fd0a","schema_version":"edge-lab-recorder.raw.v1","sequence":null,"source":"clob_market_ws"}
{"event_at":"2026-07-27T03:11:15.624000Z","event_fingerprint":"95afb7a273b21215526ae554c0b35bd3609de92831730ea695980953507288c1","payload":{"connection_id":"f95883f18d264834af91809e5f803e9f","event_at":"2026-07-27T03:11:15.624000Z","event_type":"price_change","frame_hash":"017d896d0d59c9582414b8d9712167dd449c25759eca45c5a4fb1725dccc7260","frame_index":0,"kind":"data","monotonic_ns":223867613093208,"payload":{"event_type":"price_change","market":"0xf9d60bb033695053c4d1d8592e52171c1042f64b41a4b72e09dcc6f4852b6670","price_changes":[{"asset_id":"8698449539441374295770236407991735029336433231649246775082939325523552031992","best_ask":"0.27","best_bid":"0.26","hash":"91660526460c431634d5ea53aea6b8a583489abe","price":"0.22","side":"BUY","size":"138"},{"asset_id":"96283536366176669581486355171583722558858323126916278856549586825357358273536","best_ask":"0.74","best_bid":"0.73","hash":"ed08246ac706b3bf4f25785482f2fabe160feacf","price":"0.78","side":"SELL","size":"138"}],"timestamp":"1785121875624"},"payload_hash":"d2c2490bfe8c09f30ffc1461c8575f5b40916381d60aa76fc9ab5320df3b250a","raw_frame":"{\"market\":\"0xf9d60bb033695053c4d1d8592e52171c1042f64b41a4b72e09dcc6f4852b6670\", \"price_changes\":[{\"asset_id\":\"8698449539441374295770236407991735029336433231649246775082939325523552031992\", \"price\":\"0.22\", \"size\":\"138\", \"side\":\"BUY\", \"hash\":\"91660526460c431634d5ea53aea6b8a583489abe\", \"best_bid\":\"0.26\", \"best_ask\":\"0.27\"}, {\"asset_id\":\"96283536366176669581486355171583722558858323126916278856549586825357358273536\", \"price\":\"0.78\", \"size\":\"138\", \"side\":\"SELL\", \"hash\":\"ed08246ac706b3bf4f25785482f2fabe160feacf\", \"best_bid\":\"0.73\", \"best_ask\":\"0.74\"}], \"timestamp\":\"1785121875624\", \"event_type\":\"price_change\"}","received_at":"2026-07-27T03:11:24.282458Z","schema_version":"clob-market-ws.price_change.v1","sequence":null,"server_hash":null,"server_timestamp":"1785121875624","session_id":"ff6d21c8283948938400a32613abec2c","source":"clob_market_ws"},"received_at":"2026-07-27T03:11:24.282458Z","record_id":"de3eb20302a0a6fcee413f07921b51e0f916e4f3638b3d24a5059e8a48631b85","schema_fingerprint":"4aa3821a28b0b7c2400bc59aba4bcc0a76e971dadd19610d3ad38c768e124dc7","schema_version":"edge-lab-recorder.raw.v1","sequence":null,"source":"clob_market_ws"}
{"event_at":"2026-07-27T03:11:15.633000Z","event_fingerprint":"b095db6daef72650ae4c327c6935a8ec66e9cbf686e90e36c930209d3f1cfeed","payload":{"connection_id":"f95883f18d264834af91809e5f803e9f","event_at":"2026-07-27T03:11:15.633000Z","event_type":"price_change","frame_hash":"ebbd90acc1580407c88fd3570a37cbeafe2b10c81c1105dfdbeace73976e4cbd","frame_index":0,"kind":"data","monotonic_ns":223867614055666,"payload":{"event_type":"price_change","market":"0xf9d60bb033695053c4d1d8592e52171c1042f64b41a4b72e09dcc6f4852b6670","price_changes":[{"asset_id":"96283536366176669581486355171583722558858323126916278856549586825357358273536","best_ask":"0.74","best_bid":"0.73","hash":"1aa4f8611c72076833f389afc84a5fcc35de048b","price":"0.02","side":"BUY","size":"1573.79"},{"asset_id":"8698449539441374295770236407991735029336433231649246775082939325523552031992","best_ask":"0.27","best_bid":"0.26","hash":"8a9f84d35d6ce38240cc66614f7a76d0f8d3e818","price":"0.98","side":"SELL","size":"1573.79"}],"timestamp":"1785121875633"},"payload_hash":"0fe4f241d8515a8ba2bce7c6edaaa5ae295abd4954b96164716ff6ae73b522eb","raw_frame":"{\"market\":\"0xf9d60bb033695053c4d1d8592e52171c1042f64b41a4b72e09dcc6f4852b6670\", \"price_changes\":[{\"asset_id\":\"96283536366176669581486355171583722558858323126916278856549586825357358273536\", \"price\":\"0.02\", \"size\":\"1573.79\", \"side\":\"BUY\", \"hash\":\"1aa4f8611c72076833f389afc84a5fcc35de048b\", \"best_bid\":\"0.73\", \"best_ask\":\"0.74\"}, {\"asset_id\":\"8698449539441374295770236407991735029336433231649246775082939325523552031992\", \"price\":\"0.98\", \"size\":\"1573.79\", \"side\":\"SELL\", \"hash\":\"8a9f84d35d6ce38240cc66614f7a76d0f8d3e818\", \"best_bid\":\"0.26\", \"best_ask\":\"0.27\"}], \"timestamp\":\"1785121875633\", \"event_type\":\"price_change\"}","received_at":"2026-07-27T03:11:24.283422Z","schema_version":"clob-market-ws.price_change.v1","sequence":null,"server_hash":null,"server_timestamp":"1785121875633","session_id":"ff6d21c8283948938400a32613abec2c","source":"clob_market_ws"},"received_at":"2026-07-27T03:11:24.283422Z","record_id":"f53dd16ef3257b2a0c58927b0c6cfd831caca33dca958e4b60d8ffed3904ec32","schema_fingerprint":"4aa3821a28b0b7c2400bc59aba4bcc0a76e971dadd19610d3ad38c768e124dc7","schema_version":"edge-lab-recorder.raw.v1","sequence":null,"source":"clob_market_ws"}
{"event_at":"2026-07-27T03:11:15.634000Z","event_fingerprint":"a7d872d74184623b8b152e594632386f6264ea7fd0493311e506331e5c4397c9","payload":{"connection_id":"f95883f18d264834af91809e5f803e9f","event_at":"2026-07-27T03:11:15.634000Z","event_type":"price_change","frame_hash":"a0b3a49884a561eeb5832935f2b16f01adb5addf21d2365fc669d98c10d6aa5d","frame_index":0,"kind":"data","monotonic_ns":223867615744750,"payload":{"event_type":"price_change","market":"0xf9d60bb033695053c4d1d8592e52171c1042f64b41a4b72e09dcc6f4852b6670","price_changes":[{"asset_id":"96283536366176669581486355171583722558858323126916278856549586825357358273536","best_ask":"0.74","best_bid":"0.73","hash":"2bda6919594039be095dba17d9e1fdf5a19e344c","price":"0.7","side":"BUY","size":"38.35"},{"asset_id":"8698449539441374295770236407991735029336433231649246775082939325523552031992","best_ask":"0.27","best_bid":"0.26","hash":"6db8f06d22f2dbd024814e900ee6c7ac271c8ab2","price":"0.3","side":"SELL","size":"38.35"}],"timestamp":"1785121875634"},"payload_hash":"b031af06ea9b6b59a6102e4e333c2252c4d3a7015178b3896b763b0527f8e869","raw_frame":"{\"market\":\"0xf9d60bb033695053c4d1d8592e52171c1042f64b41a4b72e09dcc6f4852b6670\", \"price_changes\":[{\"asset_id\":\"96283536366176669581486355171583722558858323126916278856549586825357358273536\", \"price\":\"0.7\", \"size\":\"38.35\", \"side\":\"BUY\", \"hash\":\"2bda6919594039be095dba17d9e1fdf5a19e344c\", \"best_bid\":\"0.73\", \"best_ask\":\"0.74\"}, {\"asset_id\":\"8698449539441374295770236407991735029336433231649246775082939325523552031992\", \"price\":\"0.3\", \"size\":\"38.35\", \"side\":\"SELL\", \"hash\":\"6db8f06d22f2dbd024814e900ee6c7ac271c8ab2\", \"best_bid\":\"0.26\", \"best_ask\":\"0.27\"}], \"timestamp\":\"1785121875634\", \"event_type\":\"price_change\"}","received_at":"2026-07-27T03:11:24.285105Z","schema_version":"clob-market-ws.price_change.v1","sequence":null,"server_hash":null,"server_timestamp":"1785121875634","session_id":"ff6d21c8283948938400a32613abec2c","source":"clob_market_ws"},"received_at":"2026-07-27T03:11:24.285105Z","record_id":"9b7931f28da8dd8b3be1adf058a32cb23e4bbd79f529ccd159556cabb4dc0c74","schema_fingerprint":"4aa3821a28b0b7c2400bc59aba4bcc0a76e971dadd19610d3ad38c768e124dc7","schema_version":"edge-lab-recorder.raw.v1","sequence":null,"source":"clob_market_ws"}
{"event_at":"2026-07-27T03:11:15.636000Z","event_fingerprint":"ed0835a2451d92068685aeb7c91c1c943c214cc996e01acafd5b37551728537f","payload":{"connection_id":"f95883f18d264834af91809e5f803e9f","event_at":"2026-07-27T03:11:15.636000Z","event_type":"price_change","frame_hash":"469f87c128ee68091f3f564c8940172715d00a99806953c0b3413c811ba570d2","frame_index":0,"kind":"data","monotonic_ns":223867617384916,"payload":{"event_type":"price_change","market":"0xf9d60bb033695053c4d1d8592e52171c1042f64b41a4b72e09dcc6f4852b6670","price_changes":[{"asset_id":"96283536366176669581486355171583722558858323126916278856549586825357358273536","best_ask":"0.74","best_bid":"0.73","hash":"0b4e978eaddbf703033c7f26db566de8d539b940","price":"0.69","side":"BUY","size":"53.19"},{"asset_id":"8698449539441374295770236407991735029336433231649246775082939325523552031992","best_ask":"0.27","best_bid":"0.26","hash":"40481f45b657f97259c61b2fc41be8141ddaf4d3","price":"0.31","side":"SELL","size":"53.19"}],"timestamp":"1785121875636"},"payload_hash":"09b9eda3a0381664163c456624c65fd1a64b4733491bf560f3529d7752185090","raw_frame":"{\"market\":\"0xf9d60bb033695053c4d1d8592e52171c1042f64b41a4b72e09dcc6f4852b6670\", \"price_changes\":[{\"asset_id\":\"96283536366176669581486355171583722558858323126916278856549586825357358273536\", \"price\":\"0.69\", \"size\":\"53.19\", \"side\":\"BUY\", \"hash\":\"0b4e978eaddbf703033c7f26db566de8d539b940\", \"best_bid\":\"0.73\", \"best_ask\":\"0.74\"}, {\"asset_id\":\"8698449539441374295770236407991735029336433231649246775082939325523552031992\", \"price\":\"0.31\", \"size\":\"53.19\", \"side\":\"SELL\", \"hash\":\"40481f45b657f97259c61b2fc41be8141ddaf4d3\", \"best_bid\":\"0.26\", \"best_ask\":\"0.27\"}], \"timestamp\":\"1785121875636\", \"event_type\":\"price_change\"}","received_at":"2026-07-27T03:11:24.286745Z","schema_version":"clob-market-ws.price_change.v1","sequence":null,"server_hash":null,"server_timestamp":"1785121875636","session_id":"ff6d21c8283948938400a32613abec2c","source":"clob_market_ws"},"received_at":"2026-07-27T03:11:24.286745Z","record_id":"b28cf06e9645f976207605a765a32d617d04d35e1fceb9bb13d84c481f2a3199","schema_fingerprint":"4aa3821a28b0b7c2400bc59aba4bcc0a76e971dadd19610d3ad38c768e124dc7","schema_version":"edge-lab-recorder.raw.v1","sequence":null,"source":"clob_market_ws"}
{"event_at":"2026-07-27T03:11:15.639000Z","event_fingerprint":"e71b656eed1e4ee3e94622b9cb3a62561d7e4cfd850414d32e3872d410cc6570","payload":{"connection_id":"f95883f18d264834af91809e5f803e9f","event_at":"2026-07-27T03:11:15.639000Z","event_type":"price_change","frame_hash":"8540558a553914beb7da9686a0dd03a63853b912858cce0bb22151af56762ebc","frame_index":0,"kind":"data","monotonic_ns":223867620453000,"payload":{"event_type":"price_change","market":"0xf9d60bb033695053c4d1d8592e52171c1042f64b41a4b72e09dcc6f4852b6670","price_changes":[{"asset_id":"96283536366176669581486355171583722558858323126916278856549586825357358273536","best_ask":"0.74","best_bid":"0.73","hash":"4718d585098e7272f6787aa7f06e2f0fe3ecc9ba","price":"0.68","side":"BUY","size":"38.22"},{"asset_id":"8698449539441374295770236407991735029336433231649246775082939325523552031992","best_ask":"0.27","best_bid":"0.26","hash":"7074ba71ab77062bd66ba773dcc86835c2740e8f","price":"0.32","side":"SELL","size":"38.22"}],"timestamp":"1785121875639"},"payload_hash":"81bb2f82d8e56d501d37dfdcf6fcecc054ee437618b0a2fa3679e7c6d322b1ee","raw_frame":"{\"market\":\"0xf9d60bb033695053c4d1d8592e52171c1042f64b41a4b72e09dcc6f4852b6670\", \"price_changes\":[{\"asset_id\":\"96283536366176669581486355171583722558858323126916278856549586825357358273536\", \"price\":\"0.68\", \"size\":\"38.22\", \"side\":\"BUY\", \"hash\":\"4718d585098e7272f6787aa7f06e2f0fe3ecc9ba\", \"best_bid\":\"0.73\", \"best_ask\":\"0.74\"}, {\"asset_id\":\"8698449539441374295770236407991735029336433231649246775082939325523552031992\", \"price\":\"0.32\", \"size\":\"38.22\", \"side\":\"SELL\", \"hash\":\"7074ba71ab77062bd66ba773dcc86835c2740e8f\", \"best_bid\":\"0.26\", \"best_ask\":\"0.27\"}], \"timestamp\":\"1785121875639\", \"event_type\":\"price_change\"}","received_at":"2026-07-27T03:11:24.289813Z","schema_version":"clob-market-ws.price_change.v1","sequence":null,"server_hash":null,"server_timestamp":"1785121875639","session_id":"ff6d21c8283948938400a32613abec2c","source":"clob_market_ws"},"received_at":"2026-07-27T03:11:24.289813Z","record_id":"8c673ce88f8ef2f28c6feab1199b35ea32ddc7afa226a0ac1fafc0335b06bb23","schema_fingerprint":"4aa3821a28b0b7c2400bc59aba4bcc0a76e971dadd19610d3ad38c768e124dc7","schema_version":"edge-lab-recorder.raw.v1","sequence":null,"source":"clob_market_ws"}
{"event_at":"2026-07-27T03:11:15.640000Z","event_fingerprint":"188e72e22e10214cd32bdd510de1ad130814fa9d565b5092ccb7ba0ee1d52e9d","payload":{"connection_id":"f95883f18d264834af91809e5f803e9f","event_at":"2026-07-27T03:11:15.640000Z","event_type":"price_change","frame_hash":"edd2fbf4e611346a366b4dfc694bb3c39bd8764bc2432cd5747ffec0a8b74cb5","frame_index":0,"kind":"data","monotonic_ns":223867623293541,"payload":{"event_type":"price_change","market":"0xf9d60bb033695053c4d1d8592e52171c1042f64b41a4b72e09dcc6f4852b6670","price_changes":[{"asset_id":"8698449539441374295770236407991735029336433231649246775082939325523552031992","best_ask":"0.27","best_bid":"0.26","hash":"4be71e08bcaf6edb413bea266c4661698aa77bee","price":"0.05","side":"BUY","size":"852"},{"asset_id":"96283536366176669581486355171583722558858323126916278856549586825357358273536","best_ask":"0.74","best_bid":"0.73","hash":"9ad3635d98241d72242c698773e19fb23eea5b3a","price":"0.95","side":"SELL","size":"852"}],"timestamp":"1785121875640"},"payload_hash":"ea643c8a4a8f8693246afc77565f3e92e1f9c85434995aa588ddb01d19a25a68","raw_frame":"{\"market\":\"0xf9d60bb033695053c4d1d8592e52171c1042f64b41a4b72e09dcc6f4852b6670\", \"price_changes\":[{\"asset_id\":\"8698449539441374295770236407991735029336433231649246775082939325523552031992\", \"price\":\"0.05\", \"size\":\"852\", \"side\":\"BUY\", \"hash\":\"4be71e08bcaf6edb413bea266c4661698aa77bee\", \"best_bid\":\"0.26\", \"best_ask\":\"0.27\"}, {\"asset_id\":\"96283536366176669581486355171583722558858323126916278856549586825357358273536\", \"price\":\"0.95\", \"size\":\"852\", \"side\":\"SELL\", \"hash\":\"9ad3635d98241d72242c698773e19fb23eea5b3a\", \"best_bid\":\"0.73\", \"best_ask\":\"0.74\"}], \"timestamp\":\"1785121875640\", \"event_type\":\"price_change\"}","received_at":"2026-07-27T03:11:24.292650Z","schema_version":"clob-market-ws.price_change.v1","sequence":null,"server_hash":null,"server_timestamp":"1785121875640","session_id":"ff6d21c8283948938400a32613abec2c","source":"clob_market_ws"},"received_at":"2026-07-27T03:11:24.292650Z","record_id":"143b4726ee93f4564e5c0437aaea8d895d5a16a3c2b90b608c9da729493c3273","schema_fingerprint":"4aa3821a28b0b7c2400bc59aba4bcc0a76e971dadd19610d3ad38c768e124dc7","schema_version":"edge-lab-recorder.raw.v1","sequence":null,"source":"clob_market_ws"}
{"event_at":"2026-07-27T03:11:15.644000Z","event_fingerprint":"cbcf2e3070b4ccb0a76fc1d5d15eb2b7d074eca4b402d8ac41180381cfb33cdb","payload":{"connection_id":"f95883f18d264834af91809e5f803e9f","event_at":"2026-07-27T03:11:15.644000Z","event_type":"price_change","frame_hash":"2a0138e1dfc70452566b9e5316d4b7a2fd3f720790ac39b2fdcf4756c9a90b06","frame_index":0,"kind":"data","monotonic_ns":223867625071458,"payload":{"event_type":"price_change","market":"0xf9d60bb033695053c4d1d8592e52171c1042f64b41a4b72e09dcc6f4852b6670","price_changes":[{"asset_id":"96283536366176669581486355171583722558858323126916278856549586825357358273536","best_ask":"0.74","best_bid":"0.73","hash":"65d2d1f6e39245688ba58346389e1de41643d800","price":"0.68","side":"BUY","size":"56.11"},{"asset_id":"8698449539441374295770236407991735029336433231649246775082939325523552031992","best_ask":"0.27","best_bid":"0.26","hash":"c835ac3b54f801100f77a5226ece709f6547e292","price":"0.32","side":"SELL","size":"56.11"}],"timestamp":"1785121875644"},"payload_hash":"6e598539ac37e62055af86966aeeaf018568199e0176d135418b76b09a587050","raw_frame":"{\"market\":\"0xf9d60bb033695053c4d1d8592e52171c1042f64b41a4b72e09dcc6f4852b6670\", \"price_changes\":[{\"asset_id\":\"96283536366176669581486355171583722558858323126916278856549586825357358273536\", \"price\":\"0.68\", \"size\":\"56.11\", \"side\":\"BUY\", \"hash\":\"65d2d1f6e39245688ba58346389e1de41643d800\", \"best_bid\":\"0.73\", \"best_ask\":\"0.74\"}, {\"asset_id\":\"8698449539441374295770236407991735029336433231649246775082939325523552031992\", \"price\":\"0.32\", \"size\":\"56.11\", \"side\":\"SELL\", \"hash\":\"c835ac3b54f801100f77a5226ece709f6547e292\", \"best_bid\":\"0.26\", \"best_ask\":\"0.27\"}], \"timestamp\":\"1785121875644\", \"event_type\":\"price_change\"}","received_at":"2026-07-27T03:11:24.294430Z","schema_version":"clob-market-ws.price_change.v1","sequence":null,"server_hash":null,"server_timestamp":"1785121875644","session_id":"ff6d21c8283948938400a32613abec2c","source":"clob_market_ws"},"received_at":"2026-07-27T03:11:24.294430Z","record_id":"7510b8dd70d795b7c56127de8b3a3bfa8552a9a0aa631a976653fd44beab759c","schema_fingerprint":"4aa3821a28b0b7c2400bc59aba4bcc0a76e971dadd19610d3ad38c768e124dc7","schema_version":"edge-lab-recorder.raw.v1","sequence":null,"source":"clob_market_ws"}
{"event_at":"2026-07-27T03:11:15.652000Z","event_fingerprint":"a8b4e739848d2ec57a11fd61d9ab2209acff5c0b096c25063cffe7fba45e861e","payload":{"connection_id":"f95883f18d264834af91809e5f803e9f","event_at":"2026-07-27T03:11:15.652000Z","event_type":"price_change","frame_hash":"a48bbf96eebbb6f97c17e7d106d2dfdb004c8286f9918ec42dea6d9361d095a1","frame_index":0,"kind":"data","monotonic_ns":223867628067083,"payload":{"event_type":"price_change","market":"0xf9d60bb033695053c4d1d8592e52171c1042f64b41a4b72e09dcc6f4852b6670","price_changes":[{"asset_id":"96283536366176669581486355171583722558858323126916278856549586825357358273536","best_ask":"0.74","best_bid":"0.73","hash":"ec4e0eb2fa9c9dbef969c8cf180c94ca4092297d","price":"0.62","side":"BUY","size":"145.03"},{"asset_id":"8698449539441374295770236407991735029336433231649246775082939325523552031992","best_ask":"0.27","best_bid":"0.26","hash":"c978727dc3aef3e7dd0420e2d49cc5a8320e8bbc","price":"0.38","side":"SELL","size":"145.03"}],"timestamp":"1785121875652"},"payload_hash":"f925afb41804fc36c9ca3696a485b9ffd78fa5c84e32a11fd8afce087df41583","raw_frame":"{\"market\":\"0xf9d60bb033695053c4d1d8592e52171c1042f64b41a4b72e09dcc6f4852b6670\", \"price_changes\":[{\"asset_id\":\"96283536366176669581486355171583722558858323126916278856549586825357358273536\", \"price\":\"0.62\", \"size\":\"145.03\", \"side\":\"BUY\", \"hash\":\"ec4e0eb2fa9c9dbef969c8cf180c94ca4092297d\", \"best_bid\":\"0.73\", \"best_ask\":\"0.74\"}, {\"asset_id\":\"8698449539441374295770236407991735029336433231649246775082939325523552031992\", \"price\":\"0.38\", \"size\":\"145.03\", \"side\":\"SELL\", \"hash\":\"c978727dc3aef3e7dd0420e2d49cc5a8320e8bbc\", \"best_bid\":\"0.26\", \"best_ask\":\"0.27\"}], \"timestamp\":\"1785121875652\", \"event_type\":\"price_change\"}","received_at":"2026-07-27T03:11:24.297427Z","schema_version":"clob-market-ws.price_change.v1","sequence":null,"server_hash":null,"server_timestamp":"1785121875652","session_id":"ff6d21c8283948938400a32613abec2c","source":"clob_market_ws"},"received_at":"2026-07-27T03:11:24.297427Z","record_id":"3b3aaaa87c75894d64d7460f7724471b7eb9a0ba142bba91a2d07d0413905332","schema_fingerprint":"4aa3821a28b0b7c2400bc59aba4bcc0a76e971dadd19610d3ad38c768e124dc7","schema_version":"edge-lab-recorder.raw.v1","sequence":null,"source":"clob_market_ws"}
{"event_at":"2026-07-27T03:11:15.654000Z","event_fingerprint":"a02503080299a9fc9044e120b05fc1912e79dbdd0506a5f3e97b4e9a9ef81d00","payload":{"connection_id":"f95883f18d264834af91809e5f803e9f","event_at":"2026-07-27T03:11:15.654000Z","event_type":"price_change","frame_hash":"c11afa817ebaf005c51790642454d6a70a785b601c278eaec3ac7e6d0683e375","frame_index":0,"kind":"data","monotonic_ns":223867630752000,"payload":{"event_type":"price_change","market":"0xf9d60bb033695053c4d1d8592e52171c1042f64b41a4b72e09dcc6f4852b6670","price_changes":[{"asset_id":"8698449539441374295770236407991735029336433231649246775082939325523552031992","best_ask":"0.27","best_bid":"0.26","hash":"1f540bd651f109c8b9c708e6ec1de436416012a9","price":"0.17","side":"BUY","size":"64.89"},{"asset_id":"96283536366176669581486355171583722558858323126916278856549586825357358273536","best_ask":"0.74","best_bid":"0.73","hash":"bc34c825b68e8085f9cf003fb096fce58aa8783e","price":"0.83","side":"SELL","size":"64.89"}],"timestamp":"1785121875654"},"payload_hash":"a92da5c14e384e08e42f9b2b0da544633d6c88bd8c5ed2045188498cbb971d9f","raw_frame":"{\"market\":\"0xf9d60bb033695053c4d1d8592e52171c1042f64b41a4b72e09dcc6f4852b6670\", \"price_changes\":[{\"asset_id\":\"8698449539441374295770236407991735029336433231649246775082939325523552031992\", \"price\":\"0.17\", \"size\":\"64.89\", \"side\":\"BUY\", \"hash\":\"1f540bd651f109c8b9c708e6ec1de436416012a9\", \"best_bid\":\"0.26\", \"best_ask\":\"0.27\"}, {\"asset_id\":\"96283536366176669581486355171583722558858323126916278856549586825357358273536\", \"price\":\"0.83\", \"size\":\"64.89\", \"side\":\"SELL\", \"hash\":\"bc34c825b68e8085f9cf003fb096fce58aa8783e\", \"best_bid\":\"0.73\", \"best_ask\":\"0.74\"}], \"timestamp\":\"1785121875654\", \"event_type\":\"price_change\"}","received_at":"2026-07-27T03:11:24.300117Z","schema_version":"clob-market-ws.price_change.v1","sequence":null,"server_hash":null,"server_timestamp":"1785121875654","session_id":"ff6d21c8283948938400a32613abec2c","source":"clob_market_ws"},"received_at":"2026-07-27T03:11:24.300117Z","record_id":"487bea503cc06b63110b59e31c686f75eb8fea41266476e69d464964a1a8e897","schema_fingerprint":"4aa3821a28b0b7c2400bc59aba4bcc0a76e971dadd19610d3ad38c768e124dc7","schema_version":"edge-lab-recorder.raw.v1","sequence":null,"source":"clob_market_ws"}
{"event_at":"2026-07-27T03:11:15.660000Z","event_fingerprint":"7b1c2977fd803a5bfa36c3981c3939c21af4e5e0d541ec494990c5e182fb2a36","payload":{"connection_id":"f95883f18d264834af91809e5f803e9f","event_at":"2026-07-27T03:11:15.660000Z","event_type":"price_change","frame_hash":"75cb2e4d963122719c82dbf88d131da1cd646796dce19c488de9cfa750bbbad3","frame_index":0,"kind":"data","monotonic_ns":223867631989583,"payload":{"event_type":"price_change","market":"0xf9d60bb033695053c4d1d8592e52171c1042f64b41a4b72e09dcc6f4852b6670","price_changes":[{"asset_id":"96283536366176669581486355171583722558858323126916278856549586825357358273536","best_ask":"0.74","best_bid":"0.73","hash":"eb4be2b63235392a503acb0d2ec8068e689b5afc","price":"0.02","side":"BUY","size":"1568.79"},{"asset_id":"8698449539441374295770236407991735029336433231649246775082939325523552031992","best_ask":"0.27","best_bid":"0.26","hash":"15514067e317c43b81a57b3f40fbddf14b31ea22","price":"0.98","side":"SELL","size":"1568.79"}],"timestamp":"1785121875660"},"payload_hash":"d6c5797651e64b9647415eb5e5db15be6ed97c6aab24d07b75de903dab9dfe67","raw_frame":"{\"market\":\"0xf9d60bb033695053c4d1d8592e52171c1042f64b41a4b72e09dcc6f4852b6670\", \"price_changes\":[{\"asset_id\":\"96283536366176669581486355171583722558858323126916278856549586825357358273536\", \"price\":\"0.02\", \"size\":\"1568.79\", \"side\":\"BUY\", \"hash\":\"eb4be2b63235392a503acb0d2ec8068e689b5afc\", \"best_bid\":\"0.73\", \"best_ask\":\"0.74\"}, {\"asset_id\":\"8698449539441374295770236407991735029336433231649246775082939325523552031992\", \"price\":\"0.98\", \"size\":\"1568.79\", \"side\":\"SELL\", \"hash\":\"15514067e317c43b81a57b3f40fbddf14b31ea22\", \"best_bid\":\"0.26\", \"best_ask\":\"0.27\"}], \"timestamp\":\"1785121875660\", \"event_type\":\"price_change\"}","received_at":"2026-07-27T03:11:24.301354Z","schema_version":"clob-market-ws.price_change.v1","sequence":null,"server_hash":null,"server_timestamp":"1785121875660","session_id":"ff6d21c8283948938400a32613abec2c","source":"clob_market_ws"},"received_at":"2026-07-27T03:11:24.301354Z","record_id":"c37175726dad6958a3b0cbcd8a570fc25b174404b63bdd4c450cf993fe90e1dd","schema_fingerprint":"4aa3821a28b0b7c2400bc59aba4bcc0a76e971dadd19610d3ad38c768e124dc7","schema_version":"edge-lab-recorder.raw.v1","sequence":null,"source":"clob_market_ws"}
{"event_at":"2026-07-27T03:11:15.667000Z","event_fingerprint":"c9945867950af6b9be96090e974be02660a0fdab9fdd1db1bec88b5a26113edb","payload":{"connection_id":"f95883f18d264834af91809e5f803e9f","event_at":"2026-07-27T03:11:15.667000Z","event_type":"price_change","frame_hash":"bf580d592e21ab06fdeb9e68c65a0b4d8c861d64f5910b830d9c906b6e2a70ba","frame_index":0,"kind":"data","monotonic_ns":223867633376583,"payload":{"event_type":"price_change","market":"0xf9d60bb033695053c4d1d8592e52171c1042f64b41a4b72e09dcc6f4852b6670","price_changes":[{"asset_id":"8698449539441374295770236407991735029336433231649246775082939325523552031992","best_ask":"0.27","best_bid":"0.26","hash":"0ea622b10ac9e518610e60d5217ff9f77632e4d5","price":"0.32","side":"SELL","size":"61.11"},{"asset_id":"96283536366176669581486355171583722558858323126916278856549586825357358273536","best_ask":"0.74","best_bid":"0.73","hash":"b892922b2254840182b828979b6d9849c0a36d5a","price":"0.68","side":"BUY","size":"61.11"}],"timestamp":"1785121875667"},"payload_hash":"b65245f66b281ec927f4159e90dcdffc35687c8e11eb1a2ed481d55716adab93","raw_frame":"{\"market\":\"0xf9d60bb033695053c4d1d8592e52171c1042f64b41a4b72e09dcc6f4852b6670\", \"price_changes\":[{\"asset_id\":\"8698449539441374295770236407991735029336433231649246775082939325523552031992\", \"price\":\"0.32\", \"size\":\"61.11\", \"side\":\"SELL\", \"hash\":\"0ea622b10ac9e518610e60d5217ff9f77632e4d5\", \"best_bid\":\"0.26\", \"best_ask\":\"0.27\"}, {\"asset_id\":\"96283536366176669581486355171583722558858323126916278856549586825357358273536\", \"price\":\"0.68\", \"size\":\"61.11\", \"side\":\"BUY\", \"hash\":\"b892922b2254840182b828979b6d9849c0a36d5a\", \"best_bid\":\"0.73\", \"best_ask\":\"0.74\"}], \"timestamp\":\"1785121875667\", \"event_type\":\"price_change\"}","received_at":"2026-07-27T03:11:24.302741Z","schema_version":"clob-market-ws.price_change.v1","sequence":null,"server_hash":null,"server_timestamp":"1785121875667","session_id":"ff6d21c8283948938400a32613abec2c","source":"clob_market_ws"},"received_at":"2026-07-27T03:11:24.302741Z","record_id":"2c4bfcfd64c90ae62a89145d42ee76646bc509d9dbb859a3fd669276f573a58a","schema_fingerprint":"4aa3821a28b0b7c2400bc59aba4bcc0a76e971dadd19610d3ad38c768e124dc7","schema_version":"edge-lab-recorder.raw.v1","sequence":null,"source":"clob_market_ws"}
{"event_at":"2026-07-27T03:11:15.671000Z","event_fingerprint":"c1c0dafd522d5dec2bc29c2721594bb8d57ab828755d41ad798bb105af1880bf","payload":{"connection_id":"f95883f18d264834af91809e5f803e9f","event_at":"2026-07-27T03:11:15.671000Z","event_type":"price_change","frame_hash":"24b954051faddbd14c5adef7a47311529d2832fbb46a16481b3cdd54ce343093","frame_index":0,"kind":"data","monotonic_ns":223867636438000,"payload":{"event_type":"price_change","market":"0xf9d60bb033695053c4d1d8592e52171c1042f64b41a4b72e09dcc6f4852b6670","price_changes":[{"asset_id":"8698449539441374295770236407991735029336433231649246775082939325523552031992","best_ask":"0.27","best_bid":"0.26","hash":"cac0590883afe8e6b7fd42ccd770f8e82dd0f078","price":"0.21","side":"BUY","size":"111.05"},{"asset_id":"96283536366176669581486355171583722558858323126916278856549586825357358273536","best_ask":"0.74","best_bid":"0.73","hash":"b1dabafd44a8195c060718f8b2d8efd0c66e4231","price":"0.79","side":"SELL","size":"111.05"}],"timestamp":"1785121875671"},"payload_hash":"25627aaef7df93cf823009e58c57c20cf9d9b4e55fe7e59b298dc2ea8ae9931e","raw_frame":"{\"market\":\"0xf9d60bb033695053c4d1d8592e52171c1042f64b41a4b72e09dcc6f4852b6670\", \"price_changes\":[{\"asset_id\":\"8698449539441374295770236407991735029336433231649246775082939325523552031992\", \"price\":\"0.21\", \"size\":\"111.05\", \"side\":\"BUY\", \"hash\":\"cac0590883afe8e6b7fd42ccd770f8e82dd0f078\", \"best_bid\":\"0.26\", \"best_ask\":\"0.27\"}, {\"asset_id\":\"96283536366176669581486355171583722558858323126916278856549586825357358273536\", \"price\":\"0.79\", \"size\":\"111.05\", \"side\":\"SELL\", \"hash\":\"b1dabafd44a8195c060718f8b2d8efd0c66e4231\", \"best_bid\":\"0.73\", \"best_ask\":\"0.74\"}], \"timestamp\":\"1785121875671\", \"event_type\":\"price_change\"}","received_at":"2026-07-27T03:11:24.305802Z","schema_version":"clob-market-ws.price_change.v1","sequence":null,"server_hash":null,"server_timestamp":"1785121875671","session_id":"ff6d21c8283948938400a32613abec2c","source":"clob_market_ws"},"received_at":"2026-07-27T03:11:24.305802Z","record_id":"8a1504bad181c21675f312d0af42313ed9e52f459d813d1c072b1a57d470cc61","schema_fingerprint":"4aa3821a28b0b7c2400bc59aba4bcc0a76e971dadd19610d3ad38c768e124dc7","schema_version":"edge-lab-recorder.raw.v1","sequence":null,"source":"clob_market_ws"}
{"event_at":"2026-07-27T03:11:15.671000Z","event_fingerprint":"392bdd3c53644a411d75c12a6bf1bbb61185fcbcbec5f81bb8577ceeb097d3d5","payload":{"connection_id":"f95883f18d264834af91809e5f803e9f","event_at":"2026-07-27T03:11:15.671000Z","event_type":"price_change","frame_hash":"216dd4f8bb29f141ec8f2d3ffdeba8142b54634dd9c49a60ae693a7e0e30bf41","frame_index":0,"kind":"data","monotonic_ns":223867638299541,"payload":{"event_type":"price_change","market":"0xf9d60bb033695053c4d1d8592e52171c1042f64b41a4b72e09dcc6f4852b6670","price_changes":[{"asset_id":"8698449539441374295770236407991735029336433231649246775082939325523552031992","best_ask":"0.27","best_bid":"0.26","hash":"b2b63f1d05a4d0ebcc6598a55c4d12ed2e896c3c","price":"0.15","side":"BUY","size":"97.39"},{"asset_id":"96283536366176669581486355171583722558858323126916278856549586825357358273536","best_ask":"0.74","best_bid":"0.73","hash":"aa9dea692ab8eda8953c3e5174c1eaf8266f455b","price":"0.85","side":"SELL","size":"97.39"}],"timestamp":"1785121875671"},"payload_hash":"136199fc75e904bbf506c3690a6a2d85fd102efe127294b3f83029886a1513c8","raw_frame":"{\"market\":\"0xf9d60bb033695053c4d1d8592e52171c1042f64b41a4b72e09dcc6f4852b6670\", \"price_changes\":[{\"asset_id\":\"8698449539441374295770236407991735029336433231649246775082939325523552031992\", \"price\":\"0.15\", \"size\":\"97.39\", \"side\":\"BUY\", \"hash\":\"b2b63f1d05a4d0ebcc6598a55c4d12ed2e896c3c\", \"best_bid\":\"0.26\", \"best_ask\":\"0.27\"}, {\"asset_id\":\"96283536366176669581486355171583722558858323126916278856549586825357358273536\", \"price\":\"0.85\", \"size\":\"97.39\", \"side\":\"SELL\", \"hash\":\"aa9dea692ab8eda8953c3e5174c1eaf8266f455b\", \"best_bid\":\"0.73\", \"best_ask\":\"0.74\"}], \"timestamp\":\"1785121875671\", \"event_type\":\"price_change\"}","received_at":"2026-07-27T03:11:24.307663Z","schema_version":"clob-market-ws.price_change.v1","sequence":null,"server_hash":null,"server_timestamp":"1785121875671","session_id":"ff6d21c8283948938400a32613abec2c","source":"clob_market_ws"},"received_at":"2026-07-27T03:11:24.307663Z","record_id":"e7c1ee20bc51ea1b3c03fee5aa9c83356044ea4dc9a483fe96eb7c07edb8fe93","schema_fingerprint":"4aa3821a28b0b7c2400bc59aba4bcc0a76e971dadd19610d3ad38c768e124dc7","schema_version":"edge-lab-recorder.raw.v1","sequence":null,"source":"clob_market_ws"}
{"event_at":"2026-07-27T03:11:15.687000Z","event_fingerprint":"de6604ff3acf6749c7bf60584847151d97ade3290803169e33902a4fac5cc678","payload":{"connection_id":"f95883f18d264834af91809e5f803e9f","event_at":"2026-07-27T03:11:15.687000Z","event_type":"price_change","frame_hash":"004a7fdb7b9245b3143a3e7b23a8a05cbdfb6a00053be9af967a92a61af37f90","frame_index":0,"kind":"data","monotonic_ns":223867641156250,"payload":{"event_type":"price_change","market":"0xf9d60bb033695053c4d1d8592e52171c1042f64b41a4b72e09dcc6f4852b6670","price_changes":[{"asset_id":"96283536366176669581486355171583722558858323126916278856549586825357358273536","best_ask":"0.74","best_bid":"0.73","hash":"04ccc0a273a4c1bb97822db57bdee2736ab1c042","price":"0.01","side":"BUY","size":"7914.52"},{"asset_id":"8698449539441374295770236407991735029336433231649246775082939325523552031992","best_ask":"0.27","best_bid":"0.26","hash":"d1940b5325917ebb75190c90bf0adfe7e7f37bf1","price":"0.99","side":"SELL","size":"7914.52"}],"timestamp":"1785121875687"},"payload_hash":"bd303ee82336b843fc1f22306ac1685f487ebe8ab4995d5cdcbff08de645c633","raw_frame":"{\"market\":\"0xf9d60bb033695053c4d1d8592e52171c1042f64b41a4b72e09dcc6f4852b6670\", \"price_changes\":[{\"asset_id\":\"96283536366176669581486355171583722558858323126916278856549586825357358273536\", \"price\":\"0.01\", \"size\":\"7914.52\", \"side\":\"BUY\", \"hash\":\"04ccc0a273a4c1bb97822db57bdee2736ab1c042\", \"best_bid\":\"0.73\", \"best_ask\":\"0.74\"}, {\"asset_id\":\"8698449539441374295770236407991735029336433231649246775082939325523552031992\", \"price\":\"0.99\", \"size\":\"7914.52\", \"side\":\"SELL\", \"hash\":\"d1940b5325917ebb75190c90bf0adfe7e7f37bf1\", \"best_bid\":\"0.26\", \"best_ask\":\"0.27\"}], \"timestamp\":\"1785121875687\", \"event_type\":\"price_change\"}","received_at":"2026-07-27T03:11:24.310516Z","schema_version":"clob-market-ws.price_change.v1","sequence":null,"server_hash":null,"server_timestamp":"1785121875687","session_id":"ff6d21c8283948938400a32613abec2c","source":"clob_market_ws"},"received_at":"2026-07-27T03:11:24.310516Z","record_id":"9bb3111a8cfee0815936d4bc0859ad480056934ac5ba0ea798c7270a7f25a8e7","schema_fingerprint":"4aa3821a28b0b7c2400bc59aba4bcc0a76e971dadd19610d3ad38c768e124dc7","schema_version":"edge-lab-recorder.raw.v1","sequence":null,"source":"clob_market_ws"}
{"event_at":"2026-07-27T03:11:15.691000Z","event_fingerprint":"2f1b257fe5306ec8a4c60196ddd9d13c5b5c44851b05d51221e05d0a44f85aac","payload":{"connection_id":"f95883f18d264834af91809e5f803e9f","event_at":"2026-07-27T03:11:15.691000Z","event_type":"price_change","frame_hash":"eafafe55be4e3346d9d9e5b3061887f569a206252f022c7df8543e0cbde43bab","frame_index":0,"kind":"data","monotonic_ns":223867644140416,"payload":{"event_type":"price_change","market":"0xf9d60bb033695053c4d1d8592e52171c1042f64b41a4b72e09dcc6f4852b6670","price_changes":[{"asset_id":"8698449539441374295770236407991735029336433231649246775082939325523552031992","best_ask":"0.27","best_bid":"0.26","hash":"e3544854dd2c46411ebfb391af41384aa8034a34","price":"0.09","side":"BUY","size":"279.1"},{"asset_id":"96283536366176669581486355171583722558858323126916278856549586825357358273536","best_ask":"0.74","best_bid":"0.73","hash":"40b271dc0dc81db619b2f57310ade9400ffa486f","price":"0.91","side":"SELL","size":"279.1"}],"timestamp":"1785121875691"},"payload_hash":"242d5f8129cd715c7fc819c05a5cbc64cceebb34e1b33dfc3fd8616baef58c6d","raw_frame":"{\"market\":\"0xf9d60bb033695053c4d1d8592e52171c1042f64b41a4b72e09dcc6f4852b6670\", \"price_changes\":[{\"asset_id\":\"8698449539441374295770236407991735029336433231649246775082939325523552031992\", \"price\":\"0.09\", \"size\":\"279.1\", \"side\":\"BUY\", \"hash\":\"e3544854dd2c46411ebfb391af41384aa8034a34\", \"best_bid\":\"0.26\", \"best_ask\":\"0.27\"}, {\"asset_id\":\"96283536366176669581486355171583722558858323126916278856549586825357358273536\", \"price\":\"0.91\", \"size\":\"279.1\", \"side\":\"SELL\", \"hash\":\"40b271dc0dc81db619b2f57310ade9400ffa486f\", \"best_bid\":\"0.73\", \"best_ask\":\"0.74\"}], \"timestamp\":\"1785121875691\", \"event_type\":\"price_change\"}","received_at":"2026-07-27T03:11:24.313503Z","schema_version":"clob-market-ws.price_change.v1","sequence":null,"server_hash":null,"server_timestamp":"1785121875691","session_id":"ff6d21c8283948938400a32613abec2c","source":"clob_market_ws"},"received_at":"2026-07-27T03:11:24.313503Z","record_id":"33e7fc318219b7ac0498a3a3293d2baa51d6a3b696cf9b55447b705ea0916d2a","schema_fingerprint":"4aa3821a28b0b7c2400bc59aba4bcc0a76e971dadd19610d3ad38c768e124dc7","schema_version":"edge-lab-recorder.raw.v1","sequence":null,"source":"clob_market_ws"}
{"event_at":"2026-07-27T03:11:15.691000Z","event_fingerprint":"1b855df46a7ea45e0c980c8a08054b02dde2155fcef01f814734b36655561f66","payload":{"connection_id":"f95883f18d264834af91809e5f803e9f","event_at":"2026-07-27T03:11:15.691000Z","event_type":"price_change","frame_hash":"009660a205bb8335cc76851b9da23ece8e2b5a22a1b39a11ce2dae910f395ab5","frame_index":0,"kind":"data","monotonic_ns":223867646312041,"payload":{"event_type":"price_change","market":"0xf9d60bb033695053c4d1d8592e52171c1042f64b41a4b72e09dcc6f4852b6670","price_changes":[{"asset_id":"96283536366176669581486355171583722558858323126916278856549586825357358273536","best_ask":"0.74","best_bid":"0.73","hash":"40b271dc0dc81db619b2f57310ade9400ffa486f","price":"0.61","side":"BUY","size":"144.09"},{"asset_id":"8698449539441374295770236407991735029336433231649246775082939325523552031992","best_ask":"0.27","best_bid":"0.26","hash":"e3544854dd2c46411ebfb391af41384aa8034a34","price":"0.39","side":"SELL","size":"144.09"}],"timestamp":"1785121875691"},"payload_hash":"2b28a9519d241f3d9e9ff7f3b4beb23b9c50b7ce4a32febd711274ab82f0ef3d","raw_frame":"{\"market\":\"0xf9d60bb033695053c4d1d8592e52171c1042f64b41a4b72e09dcc6f4852b6670\", \"price_changes\":[{\"asset_id\":\"96283536366176669581486355171583722558858323126916278856549586825357358273536\", \"price\":\"0.61\", \"size\":\"144.09\", \"side\":\"BUY\", \"hash\":\"40b271dc0dc81db619b2f57310ade9400ffa486f\", \"best_bid\":\"0.73\", \"best_ask\":\"0.74\"}, {\"asset_id\":\"8698449539441374295770236407991735029336433231649246775082939325523552031992\", \"price\":\"0.39\", \"size\":\"144.09\", \"side\":\"SELL\", \"hash\":\"e3544854dd2c46411ebfb391af41384aa8034a34\", \"best_bid\":\"0.26\", \"best_ask\":\"0.27\"}], \"timestamp\":\"1785121875691\", \"event_type\":\"price_change\"}","received_at":"2026-07-27T03:11:24.315672Z","schema_version":"clob-market-ws.price_change.v1","sequence":null,"server_hash":null,"server_timestamp":"1785121875691","session_id":"ff6d21c8283948938400a32613abec2c","source":"clob_market_ws"},"received_at":"2026-07-27T03:11:24.315672Z","record_id":"30fdda77159b118e026dac504dcd744c606e8ba109881b46b8cd5e4449f4b976","schema_fingerprint":"4aa3821a28b0b7c2400bc59aba4bcc0a76e971dadd19610d3ad38c768e124dc7","schema_version":"edge-lab-recorder.raw.v1","sequence":null,"source":"clob_market_ws"}
{"event_at":"2026-07-27T03:11:15.691000Z","event_fingerprint":"59d6f4619a62fa245c2ffae05f13a31209383d567dc949faa9fdbb07811b9982","payload":{"connection_id":"f95883f18d264834af91809e5f803e9f","event_at":"2026-07-27T03:11:15.691000Z","event_type":"price_change","frame_hash":"3cfd2fac9e995d7d274eb5887c5f3dd98a748589ef3528f051f3a63cc70aa5ee","frame_index":0,"kind":"data","monotonic_ns":223867647981541,"payload":{"event_type":"price_change","market":"0xf9d60bb033695053c4d1d8592e52171c1042f64b41a4b72e09dcc6f4852b6670","price_changes":[{"asset_id":"96283536366176669581486355171583722558858323126916278856549586825357358273536","best_ask":"0.74","best_bid":"0.73","hash":"40b271dc0dc81db619b2f57310ade9400ffa486f","price":"0.6","side":"BUY","size":"172.03"},{"asset_id":"8698449539441374295770236407991735029336433231649246775082939325523552031992","best_ask":"0.27","best_bid":"0.26","hash":"e3544854dd2c46411ebfb391af41384aa8034a34","price":"0.4","side":"SELL","size":"172.03"}],"timestamp":"1785121875691"},"payload_hash":"6755159c59ea0e581c27b124e3931f15e6adec063ed3167d4e6acf9250906e60","raw_frame":"{\"market\":\"0xf9d60bb033695053c4d1d8592e52171c1042f64b41a4b72e09dcc6f4852b6670\", \"price_changes\":[{\"asset_id\":\"96283536366176669581486355171583722558858323126916278856549586825357358273536\", \"price\":\"0.6\", \"size\":\"172.03\", \"side\":\"BUY\", \"hash\":\"40b271dc0dc81db619b2f57310ade9400ffa486f\", \"best_bid\":\"0.73\", \"best_ask\":\"0.74\"}, {\"asset_id\":\"8698449539441374295770236407991735029336433231649246775082939325523552031992\", \"price\":\"0.4\", \"size\":\"172.03\", \"side\":\"SELL\", \"hash\":\"e3544854dd2c46411ebfb391af41384aa8034a34\", \"best_bid\":\"0.26\", \"best_ask\":\"0.27\"}], \"timestamp\":\"1785121875691\", \"event_type\":\"price_change\"}","received_at":"2026-07-27T03:11:24.317347Z","schema_version":"clob-market-ws.price_change.v1","sequence":null,"server_hash":null,"server_timestamp":"1785121875691","session_id":"ff6d21c8283948938400a32613abec2c","source":"clob_market_ws"},"received_at":"2026-07-27T03:11:24.317347Z","record_id":"9f05d10f28852ad0d8f486c7f78ad40aca6cc514a5285300a979db057fe98a56","schema_fingerprint":"4aa3821a28b0b7c2400bc59aba4bcc0a76e971dadd19610d3ad38c768e124dc7","schema_version":"edge-lab-recorder.raw.v1","sequence":null,"source":"clob_market_ws"}
{"event_at":"2026-07-27T03:11:15.692000Z","event_fingerprint":"e0cf424a0790659c6e09bb1090d77c41347df358e5978bffdf50d957592dd9b6","payload":{"connection_id":"f95883f18d264834af91809e5f803e9f","event_at":"2026-07-27T03:11:15.692000Z","event_type":"price_change","frame_hash":"a37c056e16f6c9fbd5f1e2920afeccf739cc61b52e5acb2d22101713a2024a01","frame_index":0,"kind":"data","monotonic_ns":223867650160375,"payload":{"event_type":"price_change","market":"0xf9d60bb033695053c4d1d8592e52171c1042f64b41a4b72e09dcc6f4852b6670","price_changes":[{"asset_id":"96283536366176669581486355171583722558858323126916278856549586825357358273536","best_ask":"0.74","best_bid":"0.73","hash":"4b8c6ea8407c705fa6e4758ac2f0b0edebc7e005","price":"0.64","side":"BUY","size":"129.68"},{"asset_id":"8698449539441374295770236407991735029336433231649246775082939325523552031992","best_ask":"0.27","best_bid":"0.26","hash":"30f556f3888fe71536ee4f9d072f6523ecea7883","price":"0.36","side":"SELL","size":"129.68"}],"timestamp":"1785121875692"},"payload_hash":"93f83c89501479f56c4c89f46811951fdf11edc9618436529e6b485a51425cc0","raw_frame":"{\"market\":\"0xf9d60bb033695053c4d1d8592e52171c1042f64b41a4b72e09dcc6f4852b6670\", \"price_changes\":[{\"asset_id\":\"96283536366176669581486355171583722558858323126916278856549586825357358273536\", \"price\":\"0.64\", \"size\":\"129.68\", \"side\":\"BUY\", \"hash\":\"4b8c6ea8407c705fa6e4758ac2f0b0edebc7e005\", \"best_bid\":\"0.73\", \"best_ask\":\"0.74\"}, {\"asset_id\":\"8698449539441374295770236407991735029336433231649246775082939325523552031992\", \"price\":\"0.36\", \"size\":\"129.68\", \"side\":\"SELL\", \"hash\":\"30f556f3888fe71536ee4f9d072f6523ecea7883\", \"best_bid\":\"0.26\", \"best_ask\":\"0.27\"}], \"timestamp\":\"1785121875692\", \"event_type\":\"price_change\"}","received_at":"2026-07-27T03:11:24.319520Z","schema_version":"clob-market-ws.price_change.v1","sequence":null,"server_hash":null,"server_timestamp":"1785121875692","session_id":"ff6d21c8283948938400a32613abec2c","source":"clob_market_ws"},"received_at":"2026-07-27T03:11:24.319520Z","record_id":"0708e5a5a0c3829f05f6e2b11e87c2466b74e9fe400ee555c12bed1c4b788b97","schema_fingerprint":"4aa3821a28b0b7c2400bc59aba4bcc0a76e971dadd19610d3ad38c768e124dc7","schema_version":"edge-lab-recorder.raw.v1","sequence":null,"source":"clob_market_ws"}
{"event_at":"2026-07-27T03:11:15.702000Z","event_fingerprint":"7b985cdbc5405f1cf4192d48812669476fdba0611db32f20beef26ec6b5f84de","payload":{"connection_id":"f95883f18d264834af91809e5f803e9f","event_at":"2026-07-27T03:11:15.702000Z","event_type":"price_change","frame_hash":"0029add21bcc80cd194e6920352b4bfb8776ed88287e10af4a5911970c62f8fa","frame_index":0,"kind":"data","monotonic_ns":223867653378625,"payload":{"event_type":"price_change","market":"0xf9d60bb033695053c4d1d8592e52171c1042f64b41a4b72e09dcc6f4852b6670","price_changes":[{"asset_id":"96283536366176669581486355171583722558858323126916278856549586825357358273536","best_ask":"0.74","best_bid":"0.73","hash":"80b4b8bab9c39223982b17b7c644b37d0b499de4","price":"0.64","side":"BUY","size":"140.31"},{"asset_id":"8698449539441374295770236407991735029336433231649246775082939325523552031992","best_ask":"0.27","best_bid":"0.26","hash":"0168369cc84ea7288ffc2dd9b43f32901190e956","price":"0.36","side":"SELL","size":"140.31"}],"timestamp":"1785121875702"},"payload_hash":"f761e11b684af9b2bc15ed682282b1122fd7f4875657b215f94c5c00aec15a2b","raw_frame":"{\"market\":\"0xf9d60bb033695053c4d1d8592e52171c1042f64b41a4b72e09dcc6f4852b6670\", \"price_changes\":[{\"asset_id\":\"96283536366176669581486355171583722558858323126916278856549586825357358273536\", \"price\":\"0.64\", \"size\":\"140.31\", \"side\":\"BUY\", \"hash\":\"80b4b8bab9c39223982b17b7c644b37d0b499de4\", \"best_bid\":\"0.73\", \"best_ask\":\"0.74\"}, {\"asset_id\":\"8698449539441374295770236407991735029336433231649246775082939325523552031992\", \"price\":\"0.36\", \"size\":\"140.31\", \"side\":\"SELL\", \"hash\":\"0168369cc84ea7288ffc2dd9b43f32901190e956\", \"best_bid\":\"0.26\", \"best_ask\":\"0.27\"}], \"timestamp\":\"1785121875702\", \"event_type\":\"price_change\"}","received_at":"2026-07-27T03:11:24.322736Z","schema_version":"clob-market-ws.price_change.v1","sequence":null,"server_hash":null,"server_timestamp":"1785121875702","session_id":"ff6d21c8283948938400a32613abec2c","source":"clob_market_ws"},"received_at":"2026-07-27T03:11:24.322736Z","record_id":"3bc34eec9e6bf110c13bc76d49dc765c96fa7d2a754e520db271860215c62010","schema_fingerprint":"4aa3821a28b0b7c2400bc59aba4bcc0a76e971dadd19610d3ad38c768e124dc7","schema_version":"edge-lab-recorder.raw.v1","sequence":null,"source":"clob_market_ws"}
{"event_at":"2026-07-27T03:11:15.702000Z","event_fingerprint":"8a4c7a3464b20771640de986c83a34e27f9cdd697f49a5c78f1718ef486f919c","payload":{"connection_id":"f95883f18d264834af91809e5f803e9f","event_at":"2026-07-27T03:11:15.702000Z","event_type":"price_change","frame_hash":"22a5c831b1ca3d955c85b4dd6e2f7a5707412a491719b67764c90eb1bd94a819","frame_index":0,"kind":"data","monotonic_ns":223867656656416,"payload":{"event_type":"price_change","market":"0xf9d60bb033695053c4d1d8592e52171c1042f64b41a4b72e09dcc6f4852b6670","price_changes":[{"asset_id":"8698449539441374295770236407991735029336433231649246775082939325523552031992","best_ask":"0.27","best_bid":"0.26","hash":"4c9aade4a8febb5834bd0967cf0f882db8bc6651","price":"0.2","side":"BUY","size":"58"},{"asset_id":"96283536366176669581486355171583722558858323126916278856549586825357358273536","best_ask":"0.74","best_bid":"0.73","hash":"ae17de8c486f3f7cef806280c90fa6562a44d13a","price":"0.8","side":"SELL","size":"58"}],"timestamp":"1785121875702"},"payload_hash":"347b8b0d7afc991cb53f514753bcfd62a8f6c4e4ad101214716094709209d986","raw_frame":"{\"market\":\"0xf9d60bb033695053c4d1d8592e52171c1042f64b41a4b72e09dcc6f4852b6670\", \"price_changes\":[{\"asset_id\":\"8698449539441374295770236407991735029336433231649246775082939325523552031992\", \"price\":\"0.2\", \"size\":\"58\", \"side\":\"BUY\", \"hash\":\"4c9aade4a8febb5834bd0967cf0f882db8bc6651\", \"best_bid\":\"0.26\", \"best_ask\":\"0.27\"}, {\"asset_id\":\"96283536366176669581486355171583722558858323126916278856549586825357358273536\", \"price\":\"0.8\", \"size\":\"58\", \"side\":\"SELL\", \"hash\":\"ae17de8c486f3f7cef806280c90fa6562a44d13a\", \"best_bid\":\"0.73\", \"best_ask\":\"0.74\"}], \"timestamp\":\"1785121875702\", \"event_type\":\"price_change\"}","received_at":"2026-07-27T03:11:24.326016Z","schema_version":"clob-market-ws.price_change.v1","sequence":null,"server_hash":null,"server_timestamp":"1785121875702","session_id":"ff6d21c8283948938400a32613abec2c","source":"clob_market_ws"},"received_at":"2026-07-27T03:11:24.326016Z","record_id":"52e6d0b859fb8260a9cc7c4d186712db89b727aea0cbb9a8cc22d6b333210e58","schema_fingerprint":"4aa3821a28b0b7c2400bc59aba4bcc0a76e971dadd19610d3ad38c768e124dc7","schema_version":"edge-lab-recorder.raw.v1","sequence":null,"source":"clob_market_ws"}
{"event_at":"2026-07-27T03:11:15.703000Z","event_fingerprint":"8a590a10b39fa98cab974e6ea9c28106fb48131ec5277695f84787a82def3642","payload":{"connection_id":"f95883f18d264834af91809e5f803e9f","event_at":"2026-07-27T03:11:15.703000Z","event_type":"price_change","frame_hash":"abf41821d8bac586ee5c447e805ddb234be1800bc95947fb6c1a76e326dd5e4d","frame_index":0,"kind":"data","monotonic_ns":223867659439791,"payload":{"event_type":"price_change","market":"0xf9d60bb033695053c4d1d8592e52171c1042f64b41a4b72e09dcc6f4852b6670","price_changes":[{"asset_id":"96283536366176669581486355171583722558858323126916278856549586825357358273536","best_ask":"0.74","best_bid":"0.73","hash":"5bc9fe35cf85e7d7e648270373a82f3b329d665a","price":"0.65","side":"BUY","size":"92.8"},{"asset_id":"8698449539441374295770236407991735029336433231649246775082939325523552031992","best_ask":"0.27","best_bid":"0.26","hash":"c72783a08efadcef7cfbbaceaa08650e22d6b8cb","price":"0.35","side":"SELL","size":"92.8"}],"timestamp":"1785121875703"},"payload_hash":"d13b18d854b96a2380103df90c3c73bcd6d6d5ac4e2f6078532c08234f9fe3d7","raw_frame":"{\"market\":\"0xf9d60bb033695053c4d1d8592e52171c1042f64b41a4b72e09dcc6f4852b6670\", \"price_changes\":[{\"asset_id\":\"96283536366176669581486355171583722558858323126916278856549586825357358273536\", \"price\":\"0.65\", \"size\":\"92.8\", \"side\":\"BUY\", \"hash\":\"5bc9fe35cf85e7d7e648270373a82f3b329d665a\", \"best_bid\":\"0.73\", \"best_ask\":\"0.74\"}, {\"asset_id\":\"8698449539441374295770236407991735029336433231649246775082939325523552031992\", \"price\":\"0.35\", \"size\":\"92.8\", \"side\":\"SELL\", \"hash\":\"c72783a08efadcef7cfbbaceaa08650e22d6b8cb\", \"best_bid\":\"0.26\", \"best_ask\":\"0.27\"}], \"timestamp\":\"1785121875703\", \"event_type\":\"price_change\"}","received_at":"2026-07-27T03:11:24.328798Z","schema_version":"clob-market-ws.price_change.v1","sequence":null,"server_hash":null,"server_timestamp":"1785121875703","session_id":"ff6d21c8283948938400a32613abec2c","source":"clob_market_ws"},"received_at":"2026-07-27T03:11:24.328798Z","record_id":"5772dd9d31934f0374c82c846c7cbf4687946b52349531a19a93f32f6c8eabd9","schema_fingerprint":"4aa3821a28b0b7c2400bc59aba4bcc0a76e971dadd19610d3ad38c768e124dc7","schema_version":"edge-lab-recorder.raw.v1","sequence":null,"source":"clob_market_ws"}
{"event_at":"2026-07-27T03:11:15.703000Z","event_fingerprint":"08b8abf3c8e8fb76e71b41a4468e5e1a85c32b5b2b72a565dfb241dde1c956de","payload":{"connection_id":"f95883f18d264834af91809e5f803e9f","event_at":"2026-07-27T03:11:15.703000Z","event_type":"price_change","frame_hash":"40ca673bfc997f9a1cf7867ecde3989266c31a6f1642ee81eaee114487729d71","frame_index":0,"kind":"data","monotonic_ns":223867662240250,"payload":{"event_type":"price_change","market":"0xf9d60bb033695053c4d1d8592e52171c1042f64b41a4b72e09dcc6f4852b6670","price_changes":[{"asset_id":"8698449539441374295770236407991735029336433231649246775082939325523552031992","best_ask":"0.27","best_bid":"0.26","hash":"23d40bfec09aa5e6ff8ba8e85bba95b74981c1a2","price":"0.05","side":"BUY","size":"896.19"},{"asset_id":"96283536366176669581486355171583722558858323126916278856549586825357358273536","best_ask":"0.74","best_bid":"0.73","hash":"e13ad7b92af6972b03a4f33002f5d0611a3720cb","price":"0.95","side":"SELL","size":"896.19"}],"timestamp":"1785121875703"},"payload_hash":"a804eaa334306ebb80f8d0696fd8eaef8fab1b98559c89daaa11f9cfda3573b1","raw_frame":"{\"market\":\"0xf9d60bb033695053c4d1d8592e52171c1042f64b41a4b72e09dcc6f4852b6670\", \"price_changes\":[{\"asset_id\":\"8698449539441374295770236407991735029336433231649246775082939325523552031992\", \"price\":\"0.05\", \"size\":\"896.19\", \"side\":\"BUY\", \"hash\":\"23d40bfec09aa5e6ff8ba8e85bba95b74981c1a2\", \"best_bid\":\"0.26\", \"best_ask\":\"0.27\"}, {\"asset_id\":\"96283536366176669581486355171583722558858323126916278856549586825357358273536\", \"price\":\"0.95\", \"size\":\"896.19\", \"side\":\"SELL\", \"hash\":\"e13ad7b92af6972b03a4f33002f5d0611a3720cb\", \"best_bid\":\"0.73\", \"best_ask\":\"0.74\"}], \"timestamp\":\"1785121875703\", \"event_type\":\"price_change\"}","received_at":"2026-07-27T03:11:24.331599Z","schema_version":"clob-market-ws.price_change.v1","sequence":null,"server_hash":null,"server_timestamp":"1785121875703","session_id":"ff6d21c8283948938400a32613abec2c","source":"clob_market_ws"},"received_at":"2026-07-27T03:11:24.331599Z","record_id":"63e670a605f997799e9f51a61dfd78c7784ae983060bd960371b42f2518d76d4","schema_fingerprint":"4aa3821a28b0b7c2400bc59aba4bcc0a76e971dadd19610d3ad38c768e124dc7","schema_version":"edge-lab-recorder.raw.v1","sequence":null,"source":"clob_market_ws"}
{"event_at":"2026-07-27T03:11:15.707000Z","event_fingerprint":"40182d6160a4ce2357d1b672ae4282b7b57184b9643d3726478f91a5c7b3414a","payload":{"connection_id":"f95883f18d264834af91809e5f803e9f","event_at":"2026-07-27T03:11:15.707000Z","event_type":"price_change","frame_hash":"83735a22e8e72f6bde51f043db8bf0e7d0bcb07c4345a754d6de4be6d5bc392e","frame_index":0,"kind":"data","monotonic_ns":223867664276250,"payload":{"event_type":"price_change","market":"0xf9d60bb033695053c4d1d8592e52171c1042f64b41a4b72e09dcc6f4852b6670","price_changes":[{"asset_id":"96283536366176669581486355171583722558858323126916278856549586825357358273536","best_ask":"0.74","best_bid":"0.73","hash":"4c1059de2d0fce41884acfe6b0e6a466e671ce8f","price":"0.65","side":"BUY","size":"87.8"},{"asset_id":"8698449539441374295770236407991735029336433231649246775082939325523552031992","best_ask":"0.27","best_bid":"0.26","hash":"5623b3bb66e4398e52a1a9ae2b3f01a9d5044e59","price":"0.35","side":"SELL","size":"87.8"}],"timestamp":"1785121875707"},"payload_hash":"4e2b32c961d21c63dbf989b1f8a801e5f5247b4bbf320c0f6a39528c59a8bfb4","raw_frame":"{\"market\":\"0xf9d60bb033695053c4d1d8592e52171c1042f64b41a4b72e09dcc6f4852b6670\", \"price_changes\":[{\"asset_id\":\"96283536366176669581486355171583722558858323126916278856549586825357358273536\", \"price\":\"0.65\", \"size\":\"87.8\", \"side\":\"BUY\", \"hash\":\"4c1059de2d0fce41884acfe6b0e6a466e671ce8f\", \"best_bid\":\"0.73\", \"best_ask\":\"0.74\"}, {\"asset_id\":\"8698449539441374295770236407991735029336433231649246775082939325523552031992\", \"price\":\"0.35\", \"size\":\"87.8\", \"side\":\"SELL\", \"hash\":\"5623b3bb66e4398e52a1a9ae2b3f01a9d5044e59\", \"best_bid\":\"0.26\", \"best_ask\":\"0.27\"}], \"timestamp\":\"1785121875707\", \"event_type\":\"price_change\"}","received_at":"2026-07-27T03:11:24.333641Z","schema_version":"clob-market-ws.price_change.v1","sequence":null,"server_hash":null,"server_timestamp":"1785121875707","session_id":"ff6d21c8283948938400a32613abec2c","source":"clob_market_ws"},"received_at":"2026-07-27T03:11:24.333641Z","record_id":"482ca8ff3eef299897f9349c974cb5f025caeb8fb11e517a43eee532c5c5a5b2","schema_fingerprint":"4aa3821a28b0b7c2400bc59aba4bcc0a76e971dadd19610d3ad38c768e124dc7","schema_version":"edge-lab-recorder.raw.v1","sequence":null,"source":"clob_market_ws"}
{"event_at":"2026-07-27T03:11:15.707000Z","event_fingerprint":"d9f9d492f29a5f232249382520dd08f7d065afe1f7f89973fc7aa1005c096608","payload":{"connection_id":"f95883f18d264834af91809e5f803e9f","event_at":"2026-07-27T03:11:15.707000Z","event_type":"price_change","frame_hash":"7efe830ecca9a06a1d2af1365f33a384f327f737b1616e4429e0a77e5233bd4d","frame_index":0,"kind":"data","monotonic_ns":223867684195958,"payload":{"event_type":"price_change","market":"0xf9d60bb033695053c4d1d8592e52171c1042f64b41a4b72e09dcc6f4852b6670","price_changes":[{"asset_id":"8698449539441374295770236407991735029336433231649246775082939325523552031992","best_ask":"0.27","best_bid":"0.26","hash":"5623b3bb66e4398e52a1a9ae2b3f01a9d5044e59","price":"0.16","side":"BUY","size":"146.4"},{"asset_id":"96283536366176669581486355171583722558858323126916278856549586825357358273536","best_ask":"0.74","best_bid":"0.73","hash":"4c1059de2d0fce41884acfe6b0e6a466e671ce8f","price":"0.84","side":"SELL","size":"146.4"}],"timestamp":"1785121875707"},"payload_hash":"16860cc4cf1f4117f0b5290a17823d25729eef14817de6332e1b5e21395f0b94","raw_frame":"{\"market\":\"0xf9d60bb033695053c4d1d8592e52171c1042f64b41a4b72e09dcc6f4852b6670\", \"price_changes\":[{\"asset_id\":\"8698449539441374295770236407991735029336433231649246775082939325523552031992\", \"price\":\"0.16\", \"size\":\"146.4\", \"side\":\"BUY\", \"hash\":\"5623b3bb66e4398e52a1a9ae2b3f01a9d5044e59\", \"best_bid\":\"0.26\", \"best_ask\":\"0.27\"}, {\"asset_id\":\"96283536366176669581486355171583722558858323126916278856549586825357358273536\", \"price\":\"0.84\", \"size\":\"146.4\", \"side\":\"SELL\", \"hash\":\"4c1059de2d0fce41884acfe6b0e6a466e671ce8f\", \"best_bid\":\"0.73\", \"best_ask\":\"0.74\"}], \"timestamp\":\"1785121875707\", \"event_type\":\"price_change\"}","received_at":"2026-07-27T03:11:24.353554Z","schema_version":"clob-market-ws.price_change.v1","sequence":null,"server_hash":null,"server_timestamp":"1785121875707","session_id":"ff6d21c8283948938400a32613abec2c","source":"clob_market_ws"},"received_at":"2026-07-27T03:11:24.353554Z","record_id":"3391281567b285182c8a38d2450c8e8f714f113cace8d946c2d0a5d2b67303fb","schema_fingerprint":"4aa3821a28b0b7c2400bc59aba4bcc0a76e971dadd19610d3ad38c768e124dc7","schema_version":"edge-lab-recorder.raw.v1","sequence":null,"source":"clob_market_ws"}
{"event_at":"2026-07-27T03:11:15.707000Z","event_fingerprint":"0c02f174e801884dcd3c4be3ad12f9fbaf1e17ea8c55fece2c0efe39d03b479e","payload":{"connection_id":"f95883f18d264834af91809e5f803e9f","event_at":"2026-07-27T03:11:15.707000Z","event_type":"price_change","frame_hash":"08f7072d4172a4aaed24936bcc51f81aeec1c1a640f1b064dfcc8481de7846b2","frame_index":0,"kind":"data","monotonic_ns":223867686852125,"payload":{"event_type":"price_change","market":"0xf9d60bb033695053c4d1d8592e52171c1042f64b41a4b72e09dcc6f4852b6670","price_changes":[{"asset_id":"8698449539441374295770236407991735029336433231649246775082939325523552031992","best_ask":"0.27","best_bid":"0.26","hash":"5623b3bb66e4398e52a1a9ae2b3f01a9d5044e59","price":"0.14","side":"BUY","size":"133.2"},{"asset_id":"96283536366176669581486355171583722558858323126916278856549586825357358273536","best_ask":"0.74","best_bid":"0.73","hash":"4c1059de2d0fce41884acfe6b0e6a466e671ce8f","price":"0.86","side":"SELL","size":"133.2"}],"timestamp":"1785121875707"},"payload_hash":"ab0ea8ef823bc96fa60012df19a30ce99f53fd0c6c51baf0dddc52e3863e9462","raw_frame":"{\"market\":\"0xf9d60bb033695053c4d1d8592e52171c1042f64b41a4b72e09dcc6f4852b6670\", \"price_changes\":[{\"asset_id\":\"8698449539441374295770236407991735029336433231649246775082939325523552031992\", \"price\":\"0.14\", \"size\":\"133.2\", \"side\":\"BUY\", \"hash\":\"5623b3bb66e4398e52a1a9ae2b3f01a9d5044e59\", \"best_bid\":\"0.26\", \"best_ask\":\"0.27\"}, {\"asset_id\":\"96283536366176669581486355171583722558858323126916278856549586825357358273536\", \"price\":\"0.86\", \"size\":\"133.2\", \"side\":\"SELL\", \"hash\":\"4c1059de2d0fce41884acfe6b0e6a466e671ce8f\", \"best_bid\":\"0.73\", \"best_ask\":\"0.74\"}], \"timestamp\":\"1785121875707\", \"event_type\":\"price_change\"}","received_at":"2026-07-27T03:11:24.356210Z","schema_version":"clob-market-ws.price_change.v1","sequence":null,"server_hash":null,"server_timestamp":"1785121875707","session_id":"ff6d21c8283948938400a32613abec2c","source":"clob_market_ws"},"received_at":"2026-07-27T03:11:24.356210Z","record_id":"99aa8673488b46db7d8ec6c555f12576cdd8130bffc148f1f03bb0798a1b8ab3","schema_fingerprint":"4aa3821a28b0b7c2400bc59aba4bcc0a76e971dadd19610d3ad38c768e124dc7","schema_version":"edge-lab-recorder.raw.v1","sequence":null,"source":"clob_market_ws"}
{"event_at":"2026-07-27T03:11:15.707000Z","event_fingerprint":"c0dfe371470e508c8e0bd86b0a9de5e383ec82486647f32794676290e2bbff6b","payload":{"connection_id":"f95883f18d264834af91809e5f803e9f","event_at":"2026-07-27T03:11:15.707000Z","event_type":"price_change","frame_hash":"3e3cd3b092f7e6444d691a33868149301f40d85057db4da9eb2437ce9147b039","frame_index":0,"kind":"data","monotonic_ns":223867690037833,"payload":{"event_type":"price_change","market":"0xf9d60bb033695053c4d1d8592e52171c1042f64b41a4b72e09dcc6f4852b6670","price_changes":[{"asset_id":"96283536366176669581486355171583722558858323126916278856549586825357358273536","best_ask":"0.74","best_bid":"0.73","hash":"4c1059de2d0fce41884acfe6b0e6a466e671ce8f","price":"0.73","side":"BUY","size":"117.83"},{"asset_id":"8698449539441374295770236407991735029336433231649246775082939325523552031992","best_ask":"0.27","best_bid":"0.26","hash":"5623b3bb66e4398e52a1a9ae2b3f01a9d5044e59","price":"0.27","side":"SELL","size":"117.83"}],"timestamp":"1785121875707"},"payload_hash":"b7953d191f3acc4e4dce1d403be2194d0ac5379680ad767259f2465a29b1f9ba","raw_frame":"{\"market\":\"0xf9d60bb033695053c4d1d8592e52171c1042f64b41a4b72e09dcc6f4852b6670\", \"price_changes\":[{\"asset_id\":\"96283536366176669581486355171583722558858323126916278856549586825357358273536\", \"price\":\"0.73\", \"size\":\"117.83\", \"side\":\"BUY\", \"hash\":\"4c1059de2d0fce41884acfe6b0e6a466e671ce8f\", \"best_bid\":\"0.73\", \"best_ask\":\"0.74\"}, {\"asset_id\":\"8698449539441374295770236407991735029336433231649246775082939325523552031992\", \"price\":\"0.27\", \"size\":\"117.83\", \"side\":\"SELL\", \"hash\":\"5623b3bb66e4398e52a1a9ae2b3f01a9d5044e59\", \"best_bid\":\"0.26\", \"best_ask\":\"0.27\"}], \"timestamp\":\"1785121875707\", \"event_type\":\"price_change\"}","received_at":"2026-07-27T03:11:24.359395Z","schema_version":"clob-market-ws.price_change.v1","sequence":null,"server_hash":null,"server_timestamp":"1785121875707","session_id":"ff6d21c8283948938400a32613abec2c","source":"clob_market_ws"},"received_at":"2026-07-27T03:11:24.359395Z","record_id":"3d48fe37c62b4f2d4f69b6cf42b967d1a83ae341db087258407c39a35a459b49","schema_fingerprint":"4aa3821a28b0b7c2400bc59aba4bcc0a76e971dadd19610d3ad38c768e124dc7","schema_version":"edge-lab-recorder.raw.v1","sequence":null,"source":"clob_market_ws"}
{"event_at":"2026-07-27T03:11:15.709000Z","event_fingerprint":"de4e3014a36302ccfeb0cf5f486d0187ceb0e6fb5d7e30c745f7e681f7f568bd","payload":{"connection_id":"f95883f18d264834af91809e5f803e9f","event_at":"2026-07-27T03:11:15.709000Z","event_type":"price_change","frame_hash":"84df416040cf3fb5d568214bccb5542cfb6d39d31531e90c7849562e754fe0e4","frame_index":0,"kind":"data","monotonic_ns":223867692933000,"payload":{"event_type":"price_change","market":"0xf9d60bb033695053c4d1d8592e52171c1042f64b41a4b72e09dcc6f4852b6670","price_changes":[{"asset_id":"8698449539441374295770236407991735029336433231649246775082939325523552031992","best_ask":"0.27","best_bid":"0.26","hash":"86fb2b95572930569179a2d2c84dd9c152a2275b","price":"0.32","side":"SELL","size":"56.11"},{"asset_id":"96283536366176669581486355171583722558858323126916278856549586825357358273536","best_ask":"0.74","best_bid":"0.73","hash":"abf365b09abfdcf4ae0836e2a14c387a0adcee5c","price":"0.68","side":"BUY","size":"56.11"}],"timestamp":"1785121875709"},"payload_hash":"29557ff6a8adcf32af9feed0d144a1d36eeea3e38f051f884850aed642a9e1bd","raw_frame":"{\"market\":\"0xf9d60bb033695053c4d1d8592e52171c1042f64b41a4b72e09dcc6f4852b6670\", \"price_changes\":[{\"asset_id\":\"8698449539441374295770236407991735029336433231649246775082939325523552031992\", \"price\":\"0.32\", \"size\":\"56.11\", \"side\":\"SELL\", \"hash\":\"86fb2b95572930569179a2d2c84dd9c152a2275b\", \"best_bid\":\"0.26\", \"best_ask\":\"0.27\"}, {\"asset_id\":\"96283536366176669581486355171583722558858323126916278856549586825357358273536\", \"price\":\"0.68\", \"size\":\"56.11\", \"side\":\"BUY\", \"hash\":\"abf365b09abfdcf4ae0836e2a14c387a0adcee5c\", \"best_bid\":\"0.73\", \"best_ask\":\"0.74\"}], \"timestamp\":\"1785121875709\", \"event_type\":\"price_change\"}","received_at":"2026-07-27T03:11:24.362292Z","schema_version":"clob-market-ws.price_change.v1","sequence":null,"server_hash":null,"server_timestamp":"1785121875709","session_id":"ff6d21c8283948938400a32613abec2c","source":"clob_market_ws"},"received_at":"2026-07-27T03:11:24.362292Z","record_id":"757c01b62232e29e1a6cd55189634fe8ad45256789ba0d7de33143ed281eccc3","schema_fingerprint":"4aa3821a28b0b7c2400bc59aba4bcc0a76e971dadd19610d3ad38c768e124dc7","schema_version":"edge-lab-recorder.raw.v1","sequence":null,"source":"clob_market_ws"}
{"event_at":"2026-07-27T03:11:15.711000Z","event_fingerprint":"2dc4f01b79ebff6466c25a6baed16620f3c41b6f8e2d811b16730afd3e4ae30c","payload":{"connection_id":"f95883f18d264834af91809e5f803e9f","event_at":"2026-07-27T03:11:15.711000Z","event_type":"price_change","frame_hash":"8bf570833073f7bb9b9cde93dbb8d3500bfe044308dd9e6b3c4eccb0b9f0da32","frame_index":0,"kind":"data","monotonic_ns":223867696208375,"payload":{"event_type":"price_change","market":"0xf9d60bb033695053c4d1d8592e52171c1042f64b41a4b72e09dcc6f4852b6670","price_changes":[{"asset_id":"8698449539441374295770236407991735029336433231649246775082939325523552031992","best_ask":"0.27","best_bid":"0.26","hash":"39f1bf43e8d2a2d589faf2de1ddb6737726ef964","price":"0.27","side":"SELL","size":"101.41"},{"asset_id":"96283536366176669581486355171583722558858323126916278856549586825357358273536","best_ask":"0.74","best_bid":"0.73","hash":"d23e1fb449e5b83371678fe5723a426a76a4e3a3","price":"0.73","side":"BUY","size":"101.41"}],"timestamp":"1785121875711"},"payload_hash":"f5de76f17066d31661085be49626e64a08d311b8237e2c525dc871b5c4459fcd","raw_frame":"{\"market\":\"0xf9d60bb033695053c4d1d8592e52171c1042f64b41a4b72e09dcc6f4852b6670\", \"price_changes\":[{\"asset_id\":\"8698449539441374295770236407991735029336433231649246775082939325523552031992\", \"price\":\"0.27\", \"size\":\"101.41\", \"side\":\"SELL\", \"hash\":\"39f1bf43e8d2a2d589faf2de1ddb6737726ef964\", \"best_bid\":\"0.26\", \"best_ask\":\"0.27\"}, {\"asset_id\":\"96283536366176669581486355171583722558858323126916278856549586825357358273536\", \"price\":\"0.73\", \"size\":\"101.41\", \"side\":\"BUY\", \"hash\":\"d23e1fb449e5b83371678fe5723a426a76a4e3a3\", \"best_bid\":\"0.73\", \"best_ask\":\"0.74\"}], \"timestamp\":\"1785121875711\", \"event_type\":\"price_change\"}","received_at":"2026-07-27T03:11:24.365566Z","schema_version":"clob-market-ws.price_change.v1","sequence":null,"server_hash":null,"server_timestamp":"1785121875711","session_id":"ff6d21c8283948938400a32613abec2c","source":"clob_market_ws"},"received_at":"2026-07-27T03:11:24.365566Z","record_id":"b7056fddfc6cf94cf160a95aacb40f21224145aeecdfd32ee1e37da6dc0445df","schema_fingerprint":"4aa3821a28b0b7c2400bc59aba4bcc0a76e971dadd19610d3ad38c768e124dc7","schema_version":"edge-lab-recorder.raw.v1","sequence":null,"source":"clob_market_ws"}
{"event_at":"2026-07-27T03:11:15.711000Z","event_fingerprint":"9bcb6f1fae0d3340fba6a22887baab128d2df1e9362bd91e39e578bb8791e5f3","payload":{"connection_id":"f95883f18d264834af91809e5f803e9f","event_at":"2026-07-27T03:11:15.711000Z","event_type":"price_change","frame_hash":"7db447fa40676e1c54fd3e3a3a5324ffff1c476a593d0d113b6a676cbbebae8a","frame_index":0,"kind":"data","monotonic_ns":223867698018333,"payload":{"event_type":"price_change","market":"0xf9d60bb033695053c4d1d8592e52171c1042f64b41a4b72e09dcc6f4852b6670","price_changes":[{"asset_id":"8698449539441374295770236407991735029336433231649246775082939325523552031992","best_ask":"0.27","best_bid":"0.26","hash":"71d72b2f44ebbcbb443c6abcfed2e6ed0aeec3cf","price":"0.24","side":"BUY","size":"5"},{"asset_id":"96283536366176669581486355171583722558858323126916278856549586825357358273536","best_ask":"0.74","best_bid":"0.73","hash":"218f998625f9264c02affb25d729920b13153dd9","price":"0.76","side":"SELL","size":"5"}],"timestamp":"1785121875711"},"payload_hash":"4ebac008f21486b656beebcb1621cfb83494b6b63fa3019c581b3d629c0ca9bb","raw_frame":"{\"market\":\"0xf9d60bb033695053c4d1d8592e52171c1042f64b41a4b72e09dcc6f4852b6670\", \"price_changes\":[{\"asset_id\":\"8698449539441374295770236407991735029336433231649246775082939325523552031992\", \"price\":\"0.24\", \"size\":\"5\", \"side\":\"BUY\", \"hash\":\"71d72b2f44ebbcbb443c6abcfed2e6ed0aeec3cf\", \"best_bid\":\"0.26\", \"best_ask\":\"0.27\"}, {\"asset_id\":\"96283536366176669581486355171583722558858323126916278856549586825357358273536\", \"price\":\"0.76\", \"size\":\"5\", \"side\":\"SELL\", \"hash\":\"218f998625f9264c02affb25d729920b13153dd9\", \"best_bid\":\"0.73\", \"best_ask\":\"0.74\"}], \"timestamp\":\"1785121875711\", \"event_type\":\"price_change\"}","received_at":"2026-07-27T03:11:24.367383Z","schema_version":"clob-market-ws.price_change.v1","sequence":null,"server_hash":null,"server_timestamp":"1785121875711","session_id":"ff6d21c8283948938400a32613abec2c","source":"clob_market_ws"},"received_at":"2026-07-27T03:11:24.367383Z","record_id":"298296162af4597f924f853392d5b28229e43add0235f59da92660aba4c983a4","schema_fingerprint":"4aa3821a28b0b7c2400bc59aba4bcc0a76e971dadd19610d3ad38c768e124dc7","schema_version":"edge-lab-recorder.raw.v1","sequence":null,"source":"clob_market_ws"}
{"event_at":"2026-07-27T03:11:15.711000Z","event_fingerprint":"788cab0a8a00dd01a4e878022962b451bcd35c2f6055b6a4a048fbe91c3e6ce0","payload":{"connection_id":"f95883f18d264834af91809e5f803e9f","event_at":"2026-07-27T03:11:15.711000Z","event_type":"price_change","frame_hash":"528efbee2ef89d5f48ea3e9246013f1e195fe61cee964a3073e1434a257ff9d5","frame_index":0,"kind":"data","monotonic_ns":223867700804375,"payload":{"event_type":"price_change","market":"0xf9d60bb033695053c4d1d8592e52171c1042f64b41a4b72e09dcc6f4852b6670","price_changes":[{"asset_id":"8698449539441374295770236407991735029336433231649246775082939325523552031992","best_ask":"0.27","best_bid":"0.26","hash":"71d72b2f44ebbcbb443c6abcfed2e6ed0aeec3cf","price":"0.26","side":"BUY","size":"13"},{"asset_id":"96283536366176669581486355171583722558858323126916278856549586825357358273536","best_ask":"0.74","best_bid":"0.73","hash":"218f998625f9264c02affb25d729920b13153dd9","price":"0.74","side":"SELL","size":"13"}],"timestamp":"1785121875711"},"payload_hash":"f04c76b3949279424948709183b3cee314a69c1c4a38a63fbb70f691155d2f8a","raw_frame":"{\"market\":\"0xf9d60bb033695053c4d1d8592e52171c1042f64b41a4b72e09dcc6f4852b6670\", \"price_changes\":[{\"asset_id\":\"8698449539441374295770236407991735029336433231649246775082939325523552031992\", \"price\":\"0.26\", \"size\":\"13\", \"side\":\"BUY\", \"hash\":\"71d72b2f44ebbcbb443c6abcfed2e6ed0aeec3cf\", \"best_bid\":\"0.26\", \"best_ask\":\"0.27\"}, {\"asset_id\":\"96283536366176669581486355171583722558858323126916278856549586825357358273536\", \"price\":\"0.74\", \"size\":\"13\", \"side\":\"SELL\", \"hash\":\"218f998625f9264c02affb25d729920b13153dd9\", \"best_bid\":\"0.73\", \"best_ask\":\"0.74\"}], \"timestamp\":\"1785121875711\", \"event_type\":\"price_change\"}","received_at":"2026-07-27T03:11:24.370164Z","schema_version":"clob-market-ws.price_change.v1","sequence":null,"server_hash":null,"server_timestamp":"1785121875711","session_id":"ff6d21c8283948938400a32613abec2c","source":"clob_market_ws"},"received_at":"2026-07-27T03:11:24.370164Z","record_id":"9614da687ddf0701cdab409efb766999bbf90f604db720b94837b2cac2ff9b3e","schema_fingerprint":"4aa3821a28b0b7c2400bc59aba4bcc0a76e971dadd19610d3ad38c768e124dc7","schema_version":"edge-lab-recorder.raw.v1","sequence":null,"source":"clob_market_ws"}
{"event_at":"2026-07-27T03:11:15.712000Z","event_fingerprint":"5a6111d2be3f7c18a83f88bb59a9f087554f2f550fc233500dd95532de4fbcb9","payload":{"connection_id":"f95883f18d264834af91809e5f803e9f","event_at":"2026-07-27T03:11:15.712000Z","event_type":"price_change","frame_hash":"007887d34e0623d164a25f82214218e81d5e59f0ed3f19446172612580ce3f78","frame_index":0,"kind":"data","monotonic_ns":223867703761208,"payload":{"event_type":"price_change","market":"0xf9d60bb033695053c4d1d8592e52171c1042f64b41a4b72e09dcc6f4852b6670","price_changes":[{"asset_id":"96283536366176669581486355171583722558858323126916278856549586825357358273536","best_ask":"0.74","best_bid":"0.73","hash":"da3ae4f446449093e97319e83899a1b51d7d8fe7","price":"0.01","side":"BUY","size":"7909.52"},{"asset_id":"8698449539441374295770236407991735029336433231649246775082939325523552031992","best_ask":"0.27","best_bid":"0.26","hash":"bb1b9e6ae5924e0d698fd1e9b0922b527e7abd38","price":"0.99","side":"SELL","size":"7909.52"}],"timestamp":"1785121875712"},"payload_hash":"acbcc3472ce9db401ee56dadfdc4c61f6f219afa23ccb8c9b90610f0d2917590","raw_frame":"{\"market\":\"0xf9d60bb033695053c4d1d8592e52171c1042f64b41a4b72e09dcc6f4852b6670\", \"price_changes\":[{\"asset_id\":\"96283536366176669581486355171583722558858323126916278856549586825357358273536\", \"price\":\"0.01\", \"size\":\"7909.52\", \"side\":\"BUY\", \"hash\":\"da3ae4f446449093e97319e83899a1b51d7d8fe7\", \"best_bid\":\"0.73\", \"best_ask\":\"0.74\"}, {\"asset_id\":\"8698449539441374295770236407991735029336433231649246775082939325523552031992\", \"price\":\"0.99\", \"size\":\"7909.52\", \"side\":\"SELL\", \"hash\":\"bb1b9e6ae5924e0d698fd1e9b0922b527e7abd38\", \"best_bid\":\"0.26\", \"best_ask\":\"0.27\"}], \"timestamp\":\"1785121875712\", \"event_type\":\"price_change\"}","received_at":"2026-07-27T03:11:24.373120Z","schema_version":"clob-market-ws.price_change.v1","sequence":null,"server_hash":null,"server_timestamp":"1785121875712","session_id":"ff6d21c8283948938400a32613abec2c","source":"clob_market_ws"},"received_at":"2026-07-27T03:11:24.373120Z","record_id":"e412d06af282228541c069291d3b16443f2d5f11aea31ded788420717e90110b","schema_fingerprint":"4aa3821a28b0b7c2400bc59aba4bcc0a76e971dadd19610d3ad38c768e124dc7","schema_version":"edge-lab-recorder.raw.v1","sequence":null,"source":"clob_market_ws"}
{"event_at":"2026-07-27T03:11:15.716000Z","event_fingerprint":"158a49283880b23094df144038be98be93199caad4b201b54164d795fbf41da5","payload":{"connection_id":"f95883f18d264834af91809e5f803e9f","event_at":"2026-07-27T03:11:15.716000Z","event_type":"last_trade_price","frame_hash":"5b7f654b1d7e4fcc07df3eab6af6d04c0fca22f61dc374a0aab8bf59d25fa12c","frame_index":0,"kind":"data","monotonic_ns":223867706669875,"payload":{"asset_id":"96283536366176669581486355171583722558858323126916278856549586825357358273536","event_type":"last_trade_price","fee_rate_bps":"0","market":"0xf9d60bb033695053c4d1d8592e52171c1042f64b41a4b72e09dcc6f4852b6670","price":"0.74","side":"BUY","size":"2","timestamp":"1785121875716","transaction_hash":"0xd4991ee3452d47a5a59dfb12003713ceeb6e36f0e0f63a633612cb61a28a151f"},"payload_hash":"27ec2f9434909e4a35e71882cc87f4a7a08537c398ad6795be3c5de9bc3869d4","raw_frame":"{\"market\":\"0xf9d60bb033695053c4d1d8592e52171c1042f64b41a4b72e09dcc6f4852b6670\", \"asset_id\":\"96283536366176669581486355171583722558858323126916278856549586825357358273536\", \"price\":\"0.74\", \"size\":\"2\", \"fee_rate_bps\":\"0\", \"side\":\"BUY\", \"timestamp\":\"1785121875716\", \"event_type\":\"last_trade_price\", \"transaction_hash\":\"0xd4991ee3452d47a5a59dfb12003713ceeb6e36f0e0f63a633612cb61a28a151f\"}","received_at":"2026-07-27T03:11:24.376029Z","schema_version":"clob-market-ws.last_trade_price.v1","sequence":null,"server_hash":null,"server_timestamp":"1785121875716","session_id":"ff6d21c8283948938400a32613abec2c","source":"clob_market_ws"},"received_at":"2026-07-27T03:11:24.376029Z","record_id":"3fdea27774efabe4add37a3f535179a8d98f06e16600dddd13ae279b4a8356ad","schema_fingerprint":"95ad9be75a4b695cd99991e12b2592bc7346f3f5388a82d0000ba65bc0d9fd0a","schema_version":"edge-lab-recorder.raw.v1","sequence":null,"source":"clob_market_ws"}
{"event_at":"2026-07-27T03:11:15.730000Z","event_fingerprint":"f9b3af597fe2c94fe5c9c1ed7d28c52d28509a0bbd426ba5a8eeaec8d46adadc","payload":{"connection_id":"f95883f18d264834af91809e5f803e9f","event_at":"2026-07-27T03:11:15.730000Z","event_type":"price_change","frame_hash":"5c093495b526f43d83d256fa8d2db39e11cf4f67b03ce200f3e02b8dae0a3836","frame_index":0,"kind":"data","monotonic_ns":223867709343416,"payload":{"event_type":"price_change","market":"0xf9d60bb033695053c4d1d8592e52171c1042f64b41a4b72e09dcc6f4852b6670","price_changes":[{"asset_id":"8698449539441374295770236407991735029336433231649246775082939325523552031992","best_ask":"0.27","best_bid":"0.26","hash":"c00cc67ec5017a2ac6c5e1f739fa5d57a2be316a","price":"0.21","side":"BUY","size":"106.05"},{"asset_id":"96283536366176669581486355171583722558858323126916278856549586825357358273536","best_ask":"0.74","best_bid":"0.73","hash":"3027fcb9a236bc31741ced7a3ac3c60d1e6e7da5","price":"0.79","side":"SELL","size":"106.05"}],"timestamp":"1785121875730"},"payload_hash":"a0e3e7249d671371da823f9f12f80494cc9524d397a1d95e2b269c63275c30ac","raw_frame":"{\"market\":\"0xf9d60bb033695053c4d1d8592e52171c1042f64b41a4b72e09dcc6f4852b6670\", \"price_changes\":[{\"asset_id\":\"8698449539441374295770236407991735029336433231649246775082939325523552031992\", \"price\":\"0.21\", \"size\":\"106.05\", \"side\":\"BUY\", \"hash\":\"c00cc67ec5017a2ac6c5e1f739fa5d57a2be316a\", \"best_bid\":\"0.26\", \"best_ask\":\"0.27\"}, {\"asset_id\":\"96283536366176669581486355171583722558858323126916278856549586825357358273536\", \"price\":\"0.79\", \"size\":\"106.05\", \"side\":\"SELL\", \"hash\":\"3027fcb9a236bc31741ced7a3ac3c60d1e6e7da5\", \"best_bid\":\"0.73\", \"best_ask\":\"0.74\"}], \"timestamp\":\"1785121875730\", \"event_type\":\"price_change\"}","received_at":"2026-07-27T03:11:24.378702Z","schema_version":"clob-market-ws.price_change.v1","sequence":null,"server_hash":null,"server_timestamp":"1785121875730","session_id":"ff6d21c8283948938400a32613abec2c","source":"clob_market_ws"},"received_at":"2026-07-27T03:11:24.378702Z","record_id":"91bec4bd2f4f19a9cf5ea20ac3d403c557513b4d67a5734c07866487c8a024b0","schema_fingerprint":"4aa3821a28b0b7c2400bc59aba4bcc0a76e971dadd19610d3ad38c768e124dc7","schema_version":"edge-lab-recorder.raw.v1","sequence":null,"source":"clob_market_ws"}
{"event_at":"2026-07-27T03:11:15.730000Z","event_fingerprint":"4b6ffe6b53ff294d9aa9924e8f5524ccc292c4fd84da6419f6f2147ac4f1fa56","payload":{"connection_id":"f95883f18d264834af91809e5f803e9f","event_at":"2026-07-27T03:11:15.730000Z","event_type":"price_change","frame_hash":"8e8030e7c143891ef6f817e530970b5513d05011d0e1696f04150b2a460f90cc","frame_index":0,"kind":"data","monotonic_ns":223867713188375,"payload":{"event_type":"price_change","market":"0xf9d60bb033695053c4d1d8592e52171c1042f64b41a4b72e09dcc6f4852b6670","price_changes":[{"asset_id":"8698449539441374295770236407991735029336433231649246775082939325523552031992","best_ask":"0.27","best_bid":"0.26","hash":"c00cc67ec5017a2ac6c5e1f739fa5d57a2be316a","price":"0.24","side":"BUY","size":"0"},{"asset_id":"96283536366176669581486355171583722558858323126916278856549586825357358273536","best_ask":"0.74","best_bid":"0.73","hash":"3027fcb9a236bc31741ced7a3ac3c60d1e6e7da5","price":"0.76","side":"SELL","size":"0"}],"timestamp":"1785121875730"},"payload_hash":"9d59856daf932617ab12dbd9942fdf8fccdeeb86635c53daf869a81a2758c952","raw_frame":"{\"market\":\"0xf9d60bb033695053c4d1d8592e52171c1042f64b41a4b72e09dcc6f4852b6670\", \"price_changes\":[{\"asset_id\":\"8698449539441374295770236407991735029336433231649246775082939325523552031992\", \"price\":\"0.24\", \"size\":\"0\", \"side\":\"BUY\", \"hash\":\"c00cc67ec5017a2ac6c5e1f739fa5d57a2be316a\", \"best_bid\":\"0.26\", \"best_ask\":\"0.27\"}, {\"asset_id\":\"96283536366176669581486355171583722558858323126916278856549586825357358273536\", \"price\":\"0.76\", \"size\":\"0\", \"side\":\"SELL\", \"hash\":\"3027fcb9a236bc31741ced7a3ac3c60d1e6e7da5\", \"best_bid\":\"0.73\", \"best_ask\":\"0.74\"}], \"timestamp\":\"1785121875730\", \"event_type\":\"price_change\"}","received_at":"2026-07-27T03:11:24.382553Z","schema_version":"clob-market-ws.price_change.v1","sequence":null,"server_hash":null,"server_timestamp":"1785121875730","session_id":"ff6d21c8283948938400a32613abec2c","source":"clob_market_ws"},"received_at":"2026-07-27T03:11:24.382553Z","record_id":"112147dafc327bda5b291f454831148f8538568a8bd3c7068236a514c90c081f","schema_fingerprint":"4aa3821a28b0b7c2400bc59aba4bcc0a76e971dadd19610d3ad38c768e124dc7","schema_version":"edge-lab-recorder.raw.v1","sequence":null,"source":"clob_market_ws"}
{"event_at":"2026-07-27T03:11:15.732000Z","event_fingerprint":"4f1eead8e3ca62216ec8e59c0b2711ca0a7c568e60a46ca158d73dde02ec96bd","payload":{"connection_id":"f95883f18d264834af91809e5f803e9f","event_at":"2026-07-27T03:11:15.732000Z","event_type":"price_change","frame_hash":"0d397ef4844fc7d94b84cc90bbef653a4f0316c091be6f2914f11d73897bd00a","frame_index":0,"kind":"data","monotonic_ns":223867715774583,"payload":{"event_type":"price_change","market":"0xf9d60bb033695053c4d1d8592e52171c1042f64b41a4b72e09dcc6f4852b6670","price_changes":[{"asset_id":"8698449539441374295770236407991735029336433231649246775082939325523552031992","best_ask":"0.27","best_bid":"0.26","hash":"47dcd68ed330809e5016fbd7af2c1a634d4e4fd2","price":"0.19","side":"BUY","size":"71.3"},{"asset_id":"96283536366176669581486355171583722558858323126916278856549586825357358273536","best_ask":"0.74","best_bid":"0.73","hash":"6336d0cc436930b410a4d2d56a94d05c146fa19b","price":"0.81","side":"SELL","size":"71.3"}],"timestamp":"1785121875732"},"payload_hash":"5d53ec50e10ec29763b4a5cf23f8958ff3fc3e7b6ad93681ca4eb54ec2388aff","raw_frame":"{\"market\":\"0xf9d60bb033695053c4d1d8592e52171c1042f64b41a4b72e09dcc6f4852b6670\", \"price_changes\":[{\"asset_id\":\"8698449539441374295770236407991735029336433231649246775082939325523552031992\", \"price\":\"0.19\", \"size\":\"71.3\", \"side\":\"BUY\", \"hash\":\"47dcd68ed330809e5016fbd7af2c1a634d4e4fd2\", \"best_bid\":\"0.26\", \"best_ask\":\"0.27\"}, {\"asset_id\":\"96283536366176669581486355171583722558858323126916278856549586825357358273536\", \"price\":\"0.81\", \"size\":\"71.3\", \"side\":\"SELL\", \"hash\":\"6336d0cc436930b410a4d2d56a94d05c146fa19b\", \"best_bid\":\"0.73\", \"best_ask\":\"0.74\"}], \"timestamp\":\"1785121875732\", \"event_type\":\"price_change\"}","received_at":"2026-07-27T03:11:24.385134Z","schema_version":"clob-market-ws.price_change.v1","sequence":null,"server_hash":null,"server_timestamp":"1785121875732","session_id":"ff6d21c8283948938400a32613abec2c","source":"clob_market_ws"},"received_at":"2026-07-27T03:11:24.385134Z","record_id":"7a2ee26dd10cafc4fb9f948d49ecad60de0982a85470099cdaa6e5acba8b9b31","schema_fingerprint":"4aa3821a28b0b7c2400bc59aba4bcc0a76e971dadd19610d3ad38c768e124dc7","schema_version":"edge-lab-recorder.raw.v1","sequence":null,"source":"clob_market_ws"}
{"event_at":"2026-07-27T03:11:15.736000Z","event_fingerprint":"71f8fd6afaba77b8cfa207ceafe16de24c862dbb89d52df9281e7581475eb724","payload":{"connection_id":"f95883f18d264834af91809e5f803e9f","event_at":"2026-07-27T03:11:15.736000Z","event_type":"price_change","frame_hash":"632a84d4c0b013898c75ab1aa71905074b5d33f604c7045af99715db7551a19f","frame_index":0,"kind":"data","monotonic_ns":223867718790000,"payload":{"event_type":"price_change","market":"0xf9d60bb033695053c4d1d8592e52171c1042f64b41a4b72e09dcc6f4852b6670","price_changes":[{"asset_id":"96283536366176669581486355171583722558858323126916278856549586825357358273536","best_ask":"0.74","best_bid":"0.73","hash":"5f5ff64182fe6485b98e67531d073ab6f20b9022","price":"0.68","side":"BUY","size":"61.11"},{"asset_id":"8698449539441374295770236407991735029336433231649246775082939325523552031992","best_ask":"0.27","best_bid":"0.26","hash":"9a5635f7be18bdd418adf81649524b15fd90c4af","price":"0.32","side":"SELL","size":"61.11"}],"timestamp":"1785121875736"},"payload_hash":"c1c0e310ee9d2eefcc8e42fdc69ead6fcf6b0746e0422d6f9f0b056baa6f03ed","raw_frame":"{\"market\":\"0xf9d60bb033695053c4d1d8592e52171c1042f64b41a4b72e09dcc6f4852b6670\", \"price_changes\":[{\"asset_id\":\"96283536366176669581486355171583722558858323126916278856549586825357358273536\", \"price\":\"0.68\", \"size\":\"61.11\", \"side\":\"BUY\", \"hash\":\"5f5ff64182fe6485b98e67531d073ab6f20b9022\", \"best_bid\":\"0.73\", \"best_ask\":\"0.74\"}, {\"asset_id\":\"8698449539441374295770236407991735029336433231649246775082939325523552031992\", \"price\":\"0.32\", \"size\":\"61.11\", \"side\":\"SELL\", \"hash\":\"9a5635f7be18bdd418adf81649524b15fd90c4af\", \"best_bid\":\"0.26\", \"best_ask\":\"0.27\"}], \"timestamp\":\"1785121875736\", \"event_type\":\"price_change\"}","received_at":"2026-07-27T03:11:24.388150Z","schema_version":"clob-market-ws.price_change.v1","sequence":null,"server_hash":null,"server_timestamp":"1785121875736","session_id":"ff6d21c8283948938400a32613abec2c","source":"clob_market_ws"},"received_at":"2026-07-27T03:11:24.388150Z","record_id":"c2a53922bc10438d98dad3519502bf11b11bb493cb02bff751cf11490c1ba305","schema_fingerprint":"4aa3821a28b0b7c2400bc59aba4bcc0a76e971dadd19610d3ad38c768e124dc7","schema_version":"edge-lab-recorder.raw.v1","sequence":null,"source":"clob_market_ws"}
{"event_at":"2026-07-27T03:11:15.738000Z","event_fingerprint":"c361aa30fb10094dca54db1c22f1d1807302284b02b4af7c2f8766d5e2f04ea7","payload":{"connection_id":"f95883f18d264834af91809e5f803e9f","event_at":"2026-07-27T03:11:15.738000Z","event_type":"price_change","frame_hash":"0c58264b21e26b6165e4283ea1fd727dd73a8115418fc44f686cff0464a96d1b","frame_index":0,"kind":"data","monotonic_ns":223867722655875,"payload":{"event_type":"price_change","market":"0xf9d60bb033695053c4d1d8592e52171c1042f64b41a4b72e09dcc6f4852b6670","price_changes":[{"asset_id":"8698449539441374295770236407991735029336433231649246775082939325523552031992","best_ask":"0.27","best_bid":"0.26","hash":"394680b3d827da0b52255e6cf16d047b94c2c6df","price":"0.26","side":"BUY","size":"8"},{"asset_id":"96283536366176669581486355171583722558858323126916278856549586825357358273536","best_ask":"0.74","best_bid":"0.73","hash":"e65d0f6f1aed086e3a28d36fb50584130a3ad1a4","price":"0.74","side":"SELL","size":"8"}],"timestamp":"1785121875738"},"payload_hash":"b759d16ce9b0cbf6402558d883b88cda6c2887f1098d858f66e15cd7e343bd19","raw_frame":"{\"market\":\"0xf9d60bb033695053c4d1d8592e52171c1042f64b41a4b72e09dcc6f4852b6670\", \"price_changes\":[{\"asset_id\":\"8698449539441374295770236407991735029336433231649246775082939325523552031992\", \"price\":\"0.26\", \"size\":\"8\", \"side\":\"BUY\", \"hash\":\"394680b3d827da0b52255e6cf16d047b94c2c6df\", \"best_bid\":\"0.26\", \"best_ask\":\"0.27\"}, {\"asset_id\":\"96283536366176669581486355171583722558858323126916278856549586825357358273536\", \"price\":\"0.74\", \"size\":\"8\", \"side\":\"SELL\", \"hash\":\"e65d0f6f1aed086e3a28d36fb50584130a3ad1a4\", \"best_bid\":\"0.73\", \"best_ask\":\"0.74\"}], \"timestamp\":\"1785121875738\", \"event_type\":\"price_change\"}","received_at":"2026-07-27T03:11:24.392014Z","schema_version":"clob-market-ws.price_change.v1","sequence":null,"server_hash":null,"server_timestamp":"1785121875738","session_id":"ff6d21c8283948938400a32613abec2c","source":"clob_market_ws"},"received_at":"2026-07-27T03:11:24.392014Z","record_id":"217d9dc0e736129a976f29f242045967b303fd96f0fe700fbaeec5f1f34af156","schema_fingerprint":"4aa3821a28b0b7c2400bc59aba4bcc0a76e971dadd19610d3ad38c768e124dc7","schema_version":"edge-lab-recorder.raw.v1","sequence":null,"source":"clob_market_ws"}
{"event_at":"2026-07-27T03:11:15.738000Z","event_fingerprint":"27caba6ed13852118a602d53b5b8c653c0fd8a1c1a155c748877eb470c075d7b","payload":{"connection_id":"f95883f18d264834af91809e5f803e9f","event_at":"2026-07-27T03:11:15.738000Z","event_type":"price_change","frame_hash":"dee259f83cacb67d82540062d43e2cf7be7d13cf20abebb83e6dd5c3920723aa","frame_index":0,"kind":"data","monotonic_ns":223867725674000,"payload":{"event_type":"price_change","market":"0xf9d60bb033695053c4d1d8592e52171c1042f64b41a4b72e09dcc6f4852b6670","price_changes":[{"asset_id":"8698449539441374295770236407991735029336433231649246775082939325523552031992","best_ask":"0.27","best_bid":"0.26","hash":"1d888fdc25c29a7a6263095640b73409a209e71a","price":"0.25","side":"BUY","size":"80"},{"asset_id":"96283536366176669581486355171583722558858323126916278856549586825357358273536","best_ask":"0.74","best_bid":"0.73","hash":"426ac1a27eeaa95ec1e440fa1c1c1b9a6ceef467","price":"0.75","side":"SELL","size":"80"}],"timestamp":"1785121875738"},"payload_hash":"8610dd38941da645c522da9441e4f2d45cb248d920f59f6d90279e9f5489d827","raw_frame":"{\"market\":\"0xf9d60bb033695053c4d1d8592e52171c1042f64b41a4b72e09dcc6f4852b6670\", \"price_changes\":[{\"asset_id\":\"8698449539441374295770236407991735029336433231649246775082939325523552031992\", \"price\":\"0.25\", \"size\":\"80\", \"side\":\"BUY\", \"hash\":\"1d888fdc25c29a7a6263095640b73409a209e71a\", \"best_bid\":\"0.26\", \"best_ask\":\"0.27\"}, {\"asset_id\":\"96283536366176669581486355171583722558858323126916278856549586825357358273536\", \"price\":\"0.75\", \"size\":\"80\", \"side\":\"SELL\", \"hash\":\"426ac1a27eeaa95ec1e440fa1c1c1b9a6ceef467\", \"best_bid\":\"0.73\", \"best_ask\":\"0.74\"}], \"timestamp\":\"1785121875738\", \"event_type\":\"price_change\"}","received_at":"2026-07-27T03:11:24.395033Z","schema_version":"clob-market-ws.price_change.v1","sequence":null,"server_hash":null,"server_timestamp":"1785121875738","session_id":"ff6d21c8283948938400a32613abec2c","source":"clob_market_ws"},"received_at":"2026-07-27T03:11:24.395033Z","record_id":"604bea2786433c8dced424c67839fee52cdfcdd8facbb7f5ec3ff8f64e64f536","schema_fingerprint":"4aa3821a28b0b7c2400bc59aba4bcc0a76e971dadd19610d3ad38c768e124dc7","schema_version":"edge-lab-recorder.raw.v1","sequence":null,"source":"clob_market_ws"}
{"event_at":"2026-07-27T03:11:15.739000Z","event_fingerprint":"9ff5f5a75aff58e9553550af12edab2e18eeae561ef8ba0f10e672ab0a23e08d","payload":{"connection_id":"f95883f18d264834af91809e5f803e9f","event_at":"2026-07-27T03:11:15.739000Z","event_type":"price_change","frame_hash":"3e82a03e554aecdb1042210ec472795807eb2c4d564d757f754c14952840a845","frame_index":0,"kind":"data","monotonic_ns":223867728851041,"payload":{"event_type":"price_change","market":"0xf9d60bb033695053c4d1d8592e52171c1042f64b41a4b72e09dcc6f4852b6670","price_changes":[{"asset_id":"8698449539441374295770236407991735029336433231649246775082939325523552031992","best_ask":"0.27","best_bid":"0.26","hash":"3e9df2614bdc239e89016c067979ee998c1e4b1a","price":"0.22","side":"BUY","size":"143"},{"asset_id":"96283536366176669581486355171583722558858323126916278856549586825357358273536","best_ask":"0.74","best_bid":"0.73","hash":"cc6830fd755053114103a5333da0a32d081f5d6e","price":"0.78","side":"SELL","size":"143"}],"timestamp":"1785121875739"},"payload_hash":"c28d9b983654a88b012daf58af9b97113ef5254a4ac4fa048e4a9c68ed635a66","raw_frame":"{\"market\":\"0xf9d60bb033695053c4d1d8592e52171c1042f64b41a4b72e09dcc6f4852b6670\", \"price_changes\":[{\"asset_id\":\"8698449539441374295770236407991735029336433231649246775082939325523552031992\", \"price\":\"0.22\", \"size\":\"143\", \"side\":\"BUY\", \"hash\":\"3e9df2614bdc239e89016c067979ee998c1e4b1a\", \"best_bid\":\"0.26\", \"best_ask\":\"0.27\"}, {\"asset_id\":\"96283536366176669581486355171583722558858323126916278856549586825357358273536\", \"price\":\"0.78\", \"size\":\"143\", \"side\":\"SELL\", \"hash\":\"cc6830fd755053114103a5333da0a32d081f5d6e\", \"best_bid\":\"0.73\", \"best_ask\":\"0.74\"}], \"timestamp\":\"1785121875739\", \"event_type\":\"price_change\"}","received_at":"2026-07-27T03:11:24.398210Z","schema_version":"clob-market-ws.price_change.v1","sequence":null,"server_hash":null,"server_timestamp":"1785121875739","session_id":"ff6d21c8283948938400a32613abec2c","source":"clob_market_ws"},"received_at":"2026-07-27T03:11:24.398210Z","record_id":"4abe9032e0ac55c267e176db9615a6cbaf7cd3e4a12cac0bc509501911d75aab","schema_fingerprint":"4aa3821a28b0b7c2400bc59aba4bcc0a76e971dadd19610d3ad38c768e124dc7","schema_version":"edge-lab-recorder.raw.v1","sequence":null,"source":"clob_market_ws"}
{"event_at":"2026-07-27T03:11:15.740000Z","event_fingerprint":"07a5b993932d4d802e35c8a801ec238b84ac2c89a4d8ad2807a62508b12c1611","payload":{"connection_id":"f95883f18d264834af91809e5f803e9f","event_at":"2026-07-27T03:11:15.740000Z","event_type":"price_change","frame_hash":"a3b27ebccf110149df79eb6a4c51912799ebf6725e1371098653d21b9b77fe53","frame_index":0,"kind":"data","monotonic_ns":223867731484791,"payload":{"event_type":"price_change","market":"0xf9d60bb033695053c4d1d8592e52171c1042f64b41a4b72e09dcc6f4852b6670","price_changes":[{"asset_id":"8698449539441374295770236407991735029336433231649246775082939325523552031992","best_ask":"0.27","best_bid":"0.26","hash":"d359b5f21c560f7c5445baf9effac554e0e57348","price":"0.2","side":"BUY","size":"53"},{"asset_id":"96283536366176669581486355171583722558858323126916278856549586825357358273536","best_ask":"0.74","best_bid":"0.73","hash":"984f9a095799f877cae2ed2b05d5ff0f225af4ce","price":"0.8","side":"SELL","size":"53"}],"timestamp":"1785121875740"},"payload_hash":"d1c57b7bdc6a68f14c483cc2745df8fd7ae5dfef83da9ba7d0e9d05ffbe46db0","raw_frame":"{\"market\":\"0xf9d60bb033695053c4d1d8592e52171c1042f64b41a4b72e09dcc6f4852b6670\", \"price_changes\":[{\"asset_id\":\"8698449539441374295770236407991735029336433231649246775082939325523552031992\", \"price\":\"0.2\", \"size\":\"53\", \"side\":\"BUY\", \"hash\":\"d359b5f21c560f7c5445baf9effac554e0e57348\", \"best_bid\":\"0.26\", \"best_ask\":\"0.27\"}, {\"asset_id\":\"96283536366176669581486355171583722558858323126916278856549586825357358273536\", \"price\":\"0.8\", \"size\":\"53\", \"side\":\"SELL\", \"hash\":\"984f9a095799f877cae2ed2b05d5ff0f225af4ce\", \"best_bid\":\"0.73\", \"best_ask\":\"0.74\"}], \"timestamp\":\"1785121875740\", \"event_type\":\"price_change\"}","received_at":"2026-07-27T03:11:24.400840Z","schema_version":"clob-market-ws.price_change.v1","sequence":null,"server_hash":null,"server_timestamp":"1785121875740","session_id":"ff6d21c8283948938400a32613abec2c","source":"clob_market_ws"},"received_at":"2026-07-27T03:11:24.400840Z","record_id":"c50a6687c8e7eac97d4db8e9a7c3e9539e4656c7e1c4efaf2990d8dfb81ebd1f","schema_fingerprint":"4aa3821a28b0b7c2400bc59aba4bcc0a76e971dadd19610d3ad38c768e124dc7","schema_version":"edge-lab-recorder.raw.v1","sequence":null,"source":"clob_market_ws"}
{"event_at":"2026-07-27T03:11:15.740000Z","event_fingerprint":"d72c4a0153c19548be9afeaa98d9457d5f8afee5c56ae98b8462450e1472ed72","payload":{"connection_id":"f95883f18d264834af91809e5f803e9f","event_at":"2026-07-27T03:11:15.740000Z","event_type":"price_change","frame_hash":"4a63df234d60f4b4e9bf36bcdfa7efc57c7c4fec62069a1274221e6567346861","frame_index":0,"kind":"data","monotonic_ns":223867734580708,"payload":{"event_type":"price_change","market":"0xf9d60bb033695053c4d1d8592e52171c1042f64b41a4b72e09dcc6f4852b6670","price_changes":[{"asset_id":"8698449539441374295770236407991735029336433231649246775082939325523552031992","best_ask":"0.27","best_bid":"0.26","hash":"d359b5f21c560f7c5445baf9effac554e0e57348","price":"0.19","side":"BUY","size":"65.3"},{"asset_id":"96283536366176669581486355171583722558858323126916278856549586825357358273536","best_ask":"0.74","best_bid":"0.73","hash":"984f9a095799f877cae2ed2b05d5ff0f225af4ce","price":"0.81","side":"SELL","size":"65.3"}],"timestamp":"1785121875740"},"payload_hash":"eef2b90627c35283ef2d9772ec04ae76f0ac9542631f46c308902631b8408aa3","raw_frame":"{\"market\":\"0xf9d60bb033695053c4d1d8592e52171c1042f64b41a4b72e09dcc6f4852b6670\", \"price_changes\":[{\"asset_id\":\"8698449539441374295770236407991735029336433231649246775082939325523552031992\", \"price\":\"0.19\", \"size\":\"65.3\", \"side\":\"BUY\", \"hash\":\"d359b5f21c560f7c5445baf9effac554e0e57348\", \"best_bid\":\"0.26\", \"best_ask\":\"0.27\"}, {\"asset_id\":\"96283536366176669581486355171583722558858323126916278856549586825357358273536\", \"price\":\"0.81\", \"size\":\"65.3\", \"side\":\"SELL\", \"hash\":\"984f9a095799f877cae2ed2b05d5ff0f225af4ce\", \"best_bid\":\"0.73\", \"best_ask\":\"0.74\"}], \"timestamp\":\"1785121875740\", \"event_type\":\"price_change\"}","received_at":"2026-07-27T03:11:24.403939Z","schema_version":"clob-market-ws.price_change.v1","sequence":null,"server_hash":null,"server_timestamp":"1785121875740","session_id":"ff6d21c8283948938400a32613abec2c","source":"clob_market_ws"},"received_at":"2026-07-27T03:11:24.403939Z","record_id":"ef9770651ddd8fa8fd6b489d808fa995dfb10557c31132ef90a68665a0c124dc","schema_fingerprint":"4aa3821a28b0b7c2400bc59aba4bcc0a76e971dadd19610d3ad38c768e124dc7","schema_version":"edge-lab-recorder.raw.v1","sequence":null,"source":"clob_market_ws"}
{"event_at":"2026-07-27T03:11:15.740000Z","event_fingerprint":"8099180eb1e2010981075084c0a8cbb63a0d4105ba2a60b13850f8bd3491e206","payload":{"connection_id":"f95883f18d264834af91809e5f803e9f","event_at":"2026-07-27T03:11:15.740000Z","event_type":"price_change","frame_hash":"7b677a98bb289d8d810861e56f3170db85367d1a0bf42a0aee174075d4dbedd1","frame_index":0,"kind":"data","monotonic_ns":223867737853083,"payload":{"event_type":"price_change","market":"0xf9d60bb033695053c4d1d8592e52171c1042f64b41a4b72e09dcc6f4852b6670","price_changes":[{"asset_id":"8698449539441374295770236407991735029336433231649246775082939325523552031992","best_ask":"0.27","best_bid":"0.26","hash":"d359b5f21c560f7c5445baf9effac554e0e57348","price":"0.22","side":"BUY","size":"138"},{"asset_id":"96283536366176669581486355171583722558858323126916278856549586825357358273536","best_ask":"0.74","best_bid":"0.73","hash":"984f9a095799f877cae2ed2b05d5ff0f225af4ce","price":"0.78","side":"SELL","size":"138"}],"timestamp":"1785121875740"},"payload_hash":"28f73a11bc5d61915db624b1e4c0d2d273149b9ffbcadc48ba65ba6b969d2aa8","raw_frame":"{\"market\":\"0xf9d60bb033695053c4d1d8592e52171c1042f64b41a4b72e09dcc6f4852b6670\", \"price_changes\":[{\"asset_id\":\"8698449539441374295770236407991735029336433231649246775082939325523552031992\", \"price\":\"0.22\", \"size\":\"138\", \"side\":\"BUY\", \"hash\":\"d359b5f21c560f7c5445baf9effac554e0e57348\", \"best_bid\":\"0.26\", \"best_ask\":\"0.27\"}, {\"asset_id\":\"96283536366176669581486355171583722558858323126916278856549586825357358273536\", \"price\":\"0.78\", \"size\":\"138\", \"side\":\"SELL\", \"hash\":\"984f9a095799f877cae2ed2b05d5ff0f225af4ce\", \"best_bid\":\"0.73\", \"best_ask\":\"0.74\"}], \"timestamp\":\"1785121875740\", \"event_type\":\"price_change\"}","received_at":"2026-07-27T03:11:24.407211Z","schema_version":"clob-market-ws.price_change.v1","sequence":null,"server_hash":null,"server_timestamp":"1785121875740","session_id":"ff6d21c8283948938400a32613abec2c","source":"clob_market_ws"},"received_at":"2026-07-27T03:11:24.407211Z","record_id":"342bf04bb732777a8726fdccb145d62429ff75cdd15a85a2522ff5cfdf55fecd","schema_fingerprint":"4aa3821a28b0b7c2400bc59aba4bcc0a76e971dadd19610d3ad38c768e124dc7","schema_version":"edge-lab-recorder.raw.v1","sequence":null,"source":"clob_market_ws"}
{"event_at":"2026-07-27T03:11:15.740000Z","event_fingerprint":"500e2cdfd75a91c1617dcbd1b5fca045ee81c98cf97a345abe06db30087031e8","payload":{"connection_id":"f95883f18d264834af91809e5f803e9f","event_at":"2026-07-27T03:11:15.740000Z","event_type":"price_change","frame_hash":"74fa5281d9e36ab251a7308d056d1e69ea92216479ba475fea34ef1b6f1cd26f","frame_index":0,"kind":"data","monotonic_ns":223867740851291,"payload":{"event_type":"price_change","market":"0xf9d60bb033695053c4d1d8592e52171c1042f64b41a4b72e09dcc6f4852b6670","price_changes":[{"asset_id":"8698449539441374295770236407991735029336433231649246775082939325523552031992","best_ask":"0.27","best_bid":"0.26","hash":"2da87243577bdd795726ffaf75cffac92e272d8c","price":"0.25","side":"BUY","size":"85"},{"asset_id":"96283536366176669581486355171583722558858323126916278856549586825357358273536","best_ask":"0.74","best_bid":"0.73","hash":"50e1be622d55c6414e1faf6130ef57e1abeb9520","price":"0.75","side":"SELL","size":"85"}],"timestamp":"1785121875740"},"payload_hash":"d490a987dac46889ffe62544bbfb24f7d45bb4d2b41e5696f465386d20689e20","raw_frame":"{\"market\":\"0xf9d60bb033695053c4d1d8592e52171c1042f64b41a4b72e09dcc6f4852b6670\", \"price_changes\":[{\"asset_id\":\"8698449539441374295770236407991735029336433231649246775082939325523552031992\", \"price\":\"0.25\", \"size\":\"85\", \"side\":\"BUY\", \"hash\":\"2da87243577bdd795726ffaf75cffac92e272d8c\", \"best_bid\":\"0.26\", \"best_ask\":\"0.27\"}, {\"asset_id\":\"96283536366176669581486355171583722558858323126916278856549586825357358273536\", \"price\":\"0.75\", \"size\":\"85\", \"side\":\"SELL\", \"hash\":\"50e1be622d55c6414e1faf6130ef57e1abeb9520\", \"best_bid\":\"0.73\", \"best_ask\":\"0.74\"}], \"timestamp\":\"1785121875740\", \"event_type\":\"price_change\"}","received_at":"2026-07-27T03:11:24.410209Z","schema_version":"clob-market-ws.price_change.v1","sequence":null,"server_hash":null,"server_timestamp":"1785121875740","session_id":"ff6d21c8283948938400a32613abec2c","source":"clob_market_ws"},"received_at":"2026-07-27T03:11:24.410209Z","record_id":"2bf897daa48393f8af81dbf696d62836f0b0a544ae219e2841786941e7895e3d","schema_fingerprint":"4aa3821a28b0b7c2400bc59aba4bcc0a76e971dadd19610d3ad38c768e124dc7","schema_version":"edge-lab-recorder.raw.v1","sequence":null,"source":"clob_market_ws"}
{"event_at":"2026-07-27T03:11:15.741000Z","event_fingerprint":"05d901778e7a7dc334f92112097e168a4c5c00d4d38ce3e45566070a893ec665","payload":{"connection_id":"f95883f18d264834af91809e5f803e9f","event_at":"2026-07-27T03:11:15.741000Z","event_type":"price_change","frame_hash":"16004cf4f408ad54711a20b7dd79a88a1942d775e1078b4933ca3aea36b85441","frame_index":0,"kind":"data","monotonic_ns":223867743835000,"payload":{"event_type":"price_change","market":"0xf9d60bb033695053c4d1d8592e52171c1042f64b41a4b72e09dcc6f4852b6670","price_changes":[{"asset_id":"8698449539441374295770236407991735029336433231649246775082939325523552031992","best_ask":"0.27","best_bid":"0.26","hash":"a88fa3f724cfa01b0269f5111bcfee0e7f770ad4","price":"0.25","side":"BUY","size":"90"},{"asset_id":"96283536366176669581486355171583722558858323126916278856549586825357358273536","best_ask":"0.74","best_bid":"0.73","hash":"359e698272a23121444543248accb68d620eeffe","price":"0.75","side":"SELL","size":"90"}],"timestamp":"1785121875741"},"payload_hash":"2ff3e6ab3b1d17fb0922a33f11f3aae66153b6cd8a14149d1f39932c9754254c","raw_frame":"{\"market\":\"0xf9d60bb033695053c4d1d8592e52171c1042f64b41a4b72e09dcc6f4852b6670\", \"price_changes\":[{\"asset_id\":\"8698449539441374295770236407991735029336433231649246775082939325523552031992\", \"price\":\"0.25\", \"size\":\"90\", \"side\":\"BUY\", \"hash\":\"a88fa3f724cfa01b0269f5111bcfee0e7f770ad4\", \"best_bid\":\"0.26\", \"best_ask\":\"0.27\"}, {\"asset_id\":\"96283536366176669581486355171583722558858323126916278856549586825357358273536\", \"price\":\"0.75\", \"size\":\"90\", \"side\":\"SELL\", \"hash\":\"359e698272a23121444543248accb68d620eeffe\", \"best_bid\":\"0.73\", \"best_ask\":\"0.74\"}], \"timestamp\":\"1785121875741\", \"event_type\":\"price_change\"}","received_at":"2026-07-27T03:11:24.413194Z","schema_version":"clob-market-ws.price_change.v1","sequence":null,"server_hash":null,"server_timestamp":"1785121875741","session_id":"ff6d21c8283948938400a32613abec2c","source":"clob_market_ws"},"received_at":"2026-07-27T03:11:24.413194Z","record_id":"3bfc57748add9f52638a2b1c11afcc4bcab10e2b6b940e32b065a0bb6a1dd8ce","schema_fingerprint":"4aa3821a28b0b7c2400bc59aba4bcc0a76e971dadd19610d3ad38c768e124dc7","schema_version":"edge-lab-recorder.raw.v1","sequence":null,"source":"clob_market_ws"}
{"event_at":"2026-07-27T03:11:15.747000Z","event_fingerprint":"affcb77987e6dec60786eae1bacd937fab727a0b82315aac994d9467eb96ee93","payload":{"connection_id":"f95883f18d264834af91809e5f803e9f","event_at":"2026-07-27T03:11:15.747000Z","event_type":"price_change","frame_hash":"4972167a1ba50b0b063e0f75c7657524be154d05fb4207e0818fa97664ade518","frame_index":0,"kind":"data","monotonic_ns":223867747132916,"payload":{"event_type":"price_change","market":"0xf9d60bb033695053c4d1d8592e52171c1042f64b41a4b72e09dcc6f4852b6670","price_changes":[{"asset_id":"8698449539441374295770236407991735029336433231649246775082939325523552031992","best_ask":"0.27","best_bid":"0.26","hash":"5e64b9450ca46e69e1dc530585ae178f9d6b7733","price":"0.22","side":"BUY","size":"143"},{"asset_id":"96283536366176669581486355171583722558858323126916278856549586825357358273536","best_ask":"0.74","best_bid":"0.73","hash":"944e784bdc038de738857d4c57c77f523555160c","price":"0.78","side":"SELL","size":"143"}],"timestamp":"1785121875747"},"payload_hash":"4f018ca137ae63ead97e54d72f91130a3296d1dbefa2f0eaed0a8e56def2ccaa","raw_frame":"{\"market\":\"0xf9d60bb033695053c4d1d8592e52171c1042f64b41a4b72e09dcc6f4852b6670\", \"price_changes\":[{\"asset_id\":\"8698449539441374295770236407991735029336433231649246775082939325523552031992\", \"price\":\"0.22\", \"size\":\"143\", \"side\":\"BUY\", \"hash\":\"5e64b9450ca46e69e1dc530585ae178f9d6b7733\", \"best_bid\":\"0.26\", \"best_ask\":\"0.27\"}, {\"asset_id\":\"96283536366176669581486355171583722558858323126916278856549586825357358273536\", \"price\":\"0.78\", \"size\":\"143\", \"side\":\"SELL\", \"hash\":\"944e784bdc038de738857d4c57c77f523555160c\", \"best_bid\":\"0.73\", \"best_ask\":\"0.74\"}], \"timestamp\":\"1785121875747\", \"event_type\":\"price_change\"}","received_at":"2026-07-27T03:11:24.416491Z","schema_version":"clob-market-ws.price_change.v1","sequence":null,"server_hash":null,"server_timestamp":"1785121875747","session_id":"ff6d21c8283948938400a32613abec2c","source":"clob_market_ws"},"received_at":"2026-07-27T03:11:24.416491Z","record_id":"c15e04eb73f3bc05b5fb43bead9e058046ecabd63ef8f76163aeaa698e233f7c","schema_fingerprint":"4aa3821a28b0b7c2400bc59aba4bcc0a76e971dadd19610d3ad38c768e124dc7","schema_version":"edge-lab-recorder.raw.v1","sequence":null,"source":"clob_market_ws"}
{"event_at":"2026-07-27T03:11:15.751000Z","event_fingerprint":"a124c352dff26663720105837846b7e19317dcc9d0cdee6feca80c69a1e81fa9","payload":{"connection_id":"f95883f18d264834af91809e5f803e9f","event_at":"2026-07-27T03:11:15.751000Z","event_type":"price_change","frame_hash":"850dbaa2cf53e969db6e7fee9e91063106937ca1d1f92330d69569837eadaf29","frame_index":0,"kind":"data","monotonic_ns":223867748537958,"payload":{"event_type":"price_change","market":"0xf9d60bb033695053c4d1d8592e52171c1042f64b41a4b72e09dcc6f4852b6670","price_changes":[{"asset_id":"96283536366176669581486355171583722558858323126916278856549586825357358273536","best_ask":"0.74","best_bid":"0.73","hash":"9fd73b489f5eb68cf6c35ac798ee18d75689402d","price":"0.02","side":"BUY","size":"1573.79"},{"asset_id":"8698449539441374295770236407991735029336433231649246775082939325523552031992","best_ask":"0.27","best_bid":"0.26","hash":"b7c0c60bfc1cccbf831b635ad7f8c2ba035695da","price":"0.98","side":"SELL","size":"1573.79"}],"timestamp":"1785121875751"},"payload_hash":"d441ebff557ea1e730295b6fb6253a21324f5dc22c6b505f5e39d91c40b59828","raw_frame":"{\"market\":\"0xf9d60bb033695053c4d1d8592e52171c1042f64b41a4b72e09dcc6f4852b6670\", \"price_changes\":[{\"asset_id\":\"96283536366176669581486355171583722558858323126916278856549586825357358273536\", \"price\":\"0.02\", \"size\":\"1573.79\", \"side\":\"BUY\", \"hash\":\"9fd73b489f5eb68cf6c35ac798ee18d75689402d\", \"best_bid\":\"0.73\", \"best_ask\":\"0.74\"}, {\"asset_id\":\"8698449539441374295770236407991735029336433231649246775082939325523552031992\", \"price\":\"0.98\", \"size\":\"1573.79\", \"side\":\"SELL\", \"hash\":\"b7c0c60bfc1cccbf831b635ad7f8c2ba035695da\", \"best_bid\":\"0.26\", \"best_ask\":\"0.27\"}], \"timestamp\":\"1785121875751\", \"event_type\":\"price_change\"}","received_at":"2026-07-27T03:11:24.417895Z","schema_version":"clob-market-ws.price_change.v1","sequence":null,"server_hash":null,"server_timestamp":"1785121875751","session_id":"ff6d21c8283948938400a32613abec2c","source":"clob_market_ws"},"received_at":"2026-07-27T03:11:24.417895Z","record_id":"1921dacfb8a1caacfd8ea995cb50b3219ccebb2fd3974c2c3cb88be16d78f47c","schema_fingerprint":"4aa3821a28b0b7c2400bc59aba4bcc0a76e971dadd19610d3ad38c768e124dc7","schema_version":"edge-lab-recorder.raw.v1","sequence":null,"source":"clob_market_ws"}
{"event_at":"2026-07-27T03:11:15.764000Z","event_fingerprint":"c3d56dd2007c8c09f0a5cd29e10310dea627c73569b0b2d1246acdd419471575","payload":{"connection_id":"f95883f18d264834af91809e5f803e9f","event_at":"2026-07-27T03:11:15.764000Z","event_type":"price_change","frame_hash":"7e9a636900f4dd4ab5871f6c7f3ce07c08e191b625a605731b404cb38307adf6","frame_index":0,"kind":"data","monotonic_ns":223867751603458,"payload":{"event_type":"price_change","market":"0xf9d60bb033695053c4d1d8592e52171c1042f64b41a4b72e09dcc6f4852b6670","price_changes":[{"asset_id":"96283536366176669581486355171583722558858323126916278856549586825357358273536","best_ask":"0.74","best_bid":"0.73","hash":"2514488e4ccdf4939b3ac0f426b8ab260523a449","price":"0.7","side":"BUY","size":"43.35"},{"asset_id":"8698449539441374295770236407991735029336433231649246775082939325523552031992","best_ask":"0.27","best_bid":"0.26","hash":"b94deb5287c36b3c8c3493931577abe95b5d7115","price":"0.3","side":"SELL","size":"43.35"}],"timestamp":"1785121875764"},"payload_hash":"b0d8870d415f57f1e47a39c65e83da1f4542c59d25fe74f179e588a6b86363a5","raw_frame":"{\"market\":\"0xf9d60bb033695053c4d1d8592e52171c1042f64b41a4b72e09dcc6f4852b6670\", \"price_changes\":[{\"asset_id\":\"96283536366176669581486355171583722558858323126916278856549586825357358273536\", \"price\":\"0.7\", \"size\":\"43.35\", \"side\":\"BUY\", \"hash\":\"2514488e4ccdf4939b3ac0f426b8ab260523a449\", \"best_bid\":\"0.73\", \"best_ask\":\"0.74\"}, {\"asset_id\":\"8698449539441374295770236407991735029336433231649246775082939325523552031992\", \"price\":\"0.3\", \"size\":\"43.35\", \"side\":\"SELL\", \"hash\":\"b94deb5287c36b3c8c3493931577abe95b5d7115\", \"best_bid\":\"0.26\", \"best_ask\":\"0.27\"}], \"timestamp\":\"1785121875764\", \"event_type\":\"price_change\"}","received_at":"2026-07-27T03:11:24.420961Z","schema_version":"clob-market-ws.price_change.v1","sequence":null,"server_hash":null,"server_timestamp":"1785121875764","session_id":"ff6d21c8283948938400a32613abec2c","source":"clob_market_ws"},"received_at":"2026-07-27T03:11:24.420961Z","record_id":"bc01c6c775aa26cf0fe9c37c8f044780eb732f2b7df29b7a787569d4d426f2cf","schema_fingerprint":"4aa3821a28b0b7c2400bc59aba4bcc0a76e971dadd19610d3ad38c768e124dc7","schema_version":"edge-lab-recorder.raw.v1","sequence":null,"source":"clob_market_ws"}
{"event_at":"2026-07-27T03:11:15.777000Z","event_fingerprint":"86ebe8ab5a9860c308ca1b65df6c8d0fe9ab814d98b5554f5360ed276f621e90","payload":{"connection_id":"f95883f18d264834af91809e5f803e9f","event_at":"2026-07-27T03:11:15.777000Z","event_type":"price_change","frame_hash":"3f47713cd17c59418ccd5c1a86fbb8684e8121d4188957f6fc5ecbb018e60f55","frame_index":0,"kind":"data","monotonic_ns":223867754882000,"payload":{"event_type":"price_change","market":"0xf9d60bb033695053c4d1d8592e52171c1042f64b41a4b72e09dcc6f4852b6670","price_changes":[{"asset_id":"96283536366176669581486355171583722558858323126916278856549586825357358273536","best_ask":"0.74","best_bid":"0.73","hash":"e8672d329c8d1f985d980c87ffd79025519371f8","price":"0.68","side":"BUY","size":"56.11"},{"asset_id":"8698449539441374295770236407991735029336433231649246775082939325523552031992","best_ask":"0.27","best_bid":"0.26","hash":"535dd2e715b24940e8d587a0b28aba205edab83e","price":"0.32","side":"SELL","size":"56.11"}],"timestamp":"1785121875777"},"payload_hash":"c1d5642863d4b95e1ea4e1e7b0368ff6228a2aa5867766dcecac5af6a8b357f1","raw_frame":"{\"market\":\"0xf9d60bb033695053c4d1d8592e52171c1042f64b41a4b72e09dcc6f4852b6670\", \"price_changes\":[{\"asset_id\":\"96283536366176669581486355171583722558858323126916278856549586825357358273536\", \"price\":\"0.68\", \"size\":\"56.11\", \"side\":\"BUY\", \"hash\":\"e8672d329c8d1f985d980c87ffd79025519371f8\", \"best_bid\":\"0.73\", \"best_ask\":\"0.74\"}, {\"asset_id\":\"8698449539441374295770236407991735029336433231649246775082939325523552031992\", \"price\":\"0.32\", \"size\":\"56.11\", \"side\":\"SELL\", \"hash\":\"535dd2e715b24940e8d587a0b28aba205edab83e\", \"best_bid\":\"0.26\", \"best_ask\":\"0.27\"}], \"timestamp\":\"1785121875777\", \"event_type\":\"price_change\"}","received_at":"2026-07-27T03:11:24.424234Z","schema_version":"clob-market-ws.price_change.v1","sequence":null,"server_hash":null,"server_timestamp":"1785121875777","session_id":"ff6d21c8283948938400a32613abec2c","source":"clob_market_ws"},"received_at":"2026-07-27T03:11:24.424234Z","record_id":"da7d51fb6683adb91bb1a8494fd80b27895ff3be3f2d17fde1c5e461337e5ee2","schema_fingerprint":"4aa3821a28b0b7c2400bc59aba4bcc0a76e971dadd19610d3ad38c768e124dc7","schema_version":"edge-lab-recorder.raw.v1","sequence":null,"source":"clob_market_ws"}
{"event_at":"2026-07-27T03:11:15.786000Z","event_fingerprint":"67b22b1b9e8fce696179b626be0a634aebfd220d3bd12d7b836f91a03df83fa8","payload":{"connection_id":"f95883f18d264834af91809e5f803e9f","event_at":"2026-07-27T03:11:15.786000Z","event_type":"price_change","frame_hash":"7d92b0624d3ec371f4217e9fa30083add8183965cf0cf70f4e536f77071880e8","frame_index":0,"kind":"data","monotonic_ns":223867776863375,"payload":{"event_type":"price_change","market":"0xf9d60bb033695053c4d1d8592e52171c1042f64b41a4b72e09dcc6f4852b6670","price_changes":[{"asset_id":"8698449539441374295770236407991735029336433231649246775082939325523552031992","best_ask":"0.27","best_bid":"0.26","hash":"77d98e0157f20846cc236f52ffc884b58cb92ca0","price":"0.18","side":"BUY","size":"71.19"},{"asset_id":"96283536366176669581486355171583722558858323126916278856549586825357358273536","best_ask":"0.74","best_bid":"0.73","hash":"86136e606f2a12c55d1cc2a094eafbb1144afc7c","price":"0.82","side":"SELL","size":"71.19"}],"timestamp":"1785121875786"},"payload_hash":"c8b4a84c31d633c43c885eca960391aba69cf428ad7aece70b01ced097f35018","raw_frame":"{\"market\":\"0xf9d60bb033695053c4d1d8592e52171c1042f64b41a4b72e09dcc6f4852b6670\", \"price_changes\":[{\"asset_id\":\"8698449539441374295770236407991735029336433231649246775082939325523552031992\", \"price\":\"0.18\", \"size\":\"71.19\", \"side\":\"BUY\", \"hash\":\"77d98e0157f20846cc236f52ffc884b58cb92ca0\", \"best_bid\":\"0.26\", \"best_ask\":\"0.27\"}, {\"asset_id\":\"96283536366176669581486355171583722558858323126916278856549586825357358273536\", \"price\":\"0.82\", \"size\":\"71.19\", \"side\":\"SELL\", \"hash\":\"86136e606f2a12c55d1cc2a094eafbb1144afc7c\", \"best_bid\":\"0.73\", \"best_ask\":\"0.74\"}], \"timestamp\":\"1785121875786\", \"event_type\":\"price_change\"}","received_at":"2026-07-27T03:11:24.446219Z","schema_version":"clob-market-ws.price_change.v1","sequence":null,"server_hash":null,"server_timestamp":"1785121875786","session_id":"ff6d21c8283948938400a32613abec2c","source":"clob_market_ws"},"received_at":"2026-07-27T03:11:24.446219Z","record_id":"01af2b3fc4e30c747f93be10cbb1acf3ea1ba741124cf23daef5fdc9dc2f16ee","schema_fingerprint":"4aa3821a28b0b7c2400bc59aba4bcc0a76e971dadd19610d3ad38c768e124dc7","schema_version":"edge-lab-recorder.raw.v1","sequence":null,"source":"clob_market_ws"}
{"event_at":"2026-07-27T03:11:15.791000Z","event_fingerprint":"e4ab10ae52e4a877fdebdfa2864c1b917930c5cf50f4b5f0119274393b107400","payload":{"connection_id":"f95883f18d264834af91809e5f803e9f","event_at":"2026-07-27T03:11:15.791000Z","event_type":"price_change","frame_hash":"a9984a01e5425964daf1facacd5bae5484307eec4ccc6d2ed119d7661e8b2782","frame_index":0,"kind":"data","monotonic_ns":223867780156666,"payload":{"event_type":"price_change","market":"0xf9d60bb033695053c4d1d8592e52171c1042f64b41a4b72e09dcc6f4852b6670","price_changes":[{"asset_id":"96283536366176669581486355171583722558858323126916278856549586825357358273536","best_ask":"0.74","best_bid":"0.73","hash":"5f672a8d30530d9dfb0b1865799d0bf933d24a02","price":"0.7","side":"BUY","size":"48.35"},{"asset_id":"8698449539441374295770236407991735029336433231649246775082939325523552031992","best_ask":"0.27","best_bid":"0.26","hash":"507342ca03ca7d8f9fa1b00a2cc1f07c2ba87b1a","price":"0.3","side":"SELL","size":"48.35"}],"timestamp":"1785121875791"},"payload_hash":"a0e909ad93be2b3478e2aa404a2f61750d9a1a858b65cf38addf76acdab294a0","raw_frame":"{\"market\":\"0xf9d60bb033695053c4d1d8592e52171c1042f64b41a4b72e09dcc6f4852b6670\", \"price_changes\":[{\"asset_id\":\"96283536366176669581486355171583722558858323126916278856549586825357358273536\", \"price\":\"0.7\", \"size\":\"48.35\", \"side\":\"BUY\", \"hash\":\"5f672a8d30530d9dfb0b1865799d0bf933d24a02\", \"best_bid\":\"0.73\", \"best_ask\":\"0.74\"}, {\"asset_id\":\"8698449539441374295770236407991735029336433231649246775082939325523552031992\", \"price\":\"0.3\", \"size\":\"48.35\", \"side\":\"SELL\", \"hash\":\"507342ca03ca7d8f9fa1b00a2cc1f07c2ba87b1a\", \"best_bid\":\"0.26\", \"best_ask\":\"0.27\"}], \"timestamp\":\"1785121875791\", \"event_type\":\"price_change\"}","received_at":"2026-07-27T03:11:24.449515Z","schema_version":"clob-market-ws.price_change.v1","sequence":null,"server_hash":null,"server_timestamp":"1785121875791","session_id":"ff6d21c8283948938400a32613abec2c","source":"clob_market_ws"},"received_at":"2026-07-27T03:11:24.449515Z","record_id":"fafbe557cc2b6af559b5be2859d219b40c49b87dbba0eeca44ed6b3809dc8b59","schema_fingerprint":"4aa3821a28b0b7c2400bc59aba4bcc0a76e971dadd19610d3ad38c768e124dc7","schema_version":"edge-lab-recorder.raw.v1","sequence":null,"source":"clob_market_ws"}
{"event_at":"2026-07-27T03:11:15.797000Z","event_fingerprint":"36d7cc01597eca47c3c262e3ff12602c1010f03cecb84838dd94fd14b614e027","payload":{"connection_id":"f95883f18d264834af91809e5f803e9f","event_at":"2026-07-27T03:11:15.797000Z","event_type":"price_change","frame_hash":"6cc837c660cb05bdaa5f2422f3574b9d34b00a80cfdede2fe1585151371470f6","frame_index":0,"kind":"data","monotonic_ns":223867782879833,"payload":{"event_type":"price_change","market":"0xf9d60bb033695053c4d1d8592e52171c1042f64b41a4b72e09dcc6f4852b6670","price_changes":[{"asset_id":"96283536366176669581486355171583722558858323126916278856549586825357358273536","best_ask":"0.74","best_bid":"0.73","hash":"9d3794333ddbbf6484d03f8396d5154a2b7d20ed","price":"0.66","side":"BUY","size":"163.47"},{"asset_id":"8698449539441374295770236407991735029336433231649246775082939325523552031992","best_ask":"0.27","best_bid":"0.26","hash":"1f52fba3816d4ab5862988c5899bb56872b2604f","price":"0.34","side":"SELL","size":"163.47"}],"timestamp":"1785121875797"},"payload_hash":"636d6461ee68575a23bc4d956fc539ddce65a3328b559c57d1bf9026b526030f","raw_frame":"{\"market\":\"0xf9d60bb033695053c4d1d8592e52171c1042f64b41a4b72e09dcc6f4852b6670\", \"price_changes\":[{\"asset_id\":\"96283536366176669581486355171583722558858323126916278856549586825357358273536\", \"price\":\"0.66\", \"size\":\"163.47\", \"side\":\"BUY\", \"hash\":\"9d3794333ddbbf6484d03f8396d5154a2b7d20ed\", \"best_bid\":\"0.73\", \"best_ask\":\"0.74\"}, {\"asset_id\":\"8698449539441374295770236407991735029336433231649246775082939325523552031992\", \"price\":\"0.34\", \"size\":\"163.47\", \"side\":\"SELL\", \"hash\":\"1f52fba3816d4ab5862988c5899bb56872b2604f\", \"best_bid\":\"0.26\", \"best_ask\":\"0.27\"}], \"timestamp\":\"1785121875797\", \"event_type\":\"price_change\"}","received_at":"2026-07-27T03:11:24.452236Z","schema_version":"clob-market-ws.price_change.v1","sequence":null,"server_hash":null,"server_timestamp":"1785121875797","session_id":"ff6d21c8283948938400a32613abec2c","source":"clob_market_ws"},"received_at":"2026-07-27T03:11:24.452236Z","record_id":"b3f22e95e4a964e5d59047c6cfe4fbdc3a556d54ae64e8c04eb68176c8a4e766","schema_fingerprint":"4aa3821a28b0b7c2400bc59aba4bcc0a76e971dadd19610d3ad38c768e124dc7","schema_version":"edge-lab-recorder.raw.v1","sequence":null,"source":"clob_market_ws"}
{"event_at":"2026-07-27T03:11:15.802000Z","event_fingerprint":"e1962f7a6f2b81b57a6d5d4eecbbb163f4863144b78266a9b1ad4c692fdb2f72","payload":{"connection_id":"f95883f18d264834af91809e5f803e9f","event_at":"2026-07-27T03:11:15.802000Z","event_type":"price_change","frame_hash":"aa271a9534ba2a0be8940e752bb946dfb66c74fdd03c593ad25a2d84196bb68b","frame_index":0,"kind":"data","monotonic_ns":223867786089500,"payload":{"event_type":"price_change","market":"0xf9d60bb033695053c4d1d8592e52171c1042f64b41a4b72e09dcc6f4852b6670","price_changes":[{"asset_id":"8698449539441374295770236407991735029336433231649246775082939325523552031992","best_ask":"0.27","best_bid":"0.26","hash":"de4f57bdeb0442c182c782cd58baf406c593d1f5","price":"0.32","side":"SELL","size":"61.11"},{"asset_id":"96283536366176669581486355171583722558858323126916278856549586825357358273536","best_ask":"0.74","best_bid":"0.73","hash":"c422a64ec1d79fcace2f09b381e0f2780ef4d685","price":"0.68","side":"BUY","size":"61.11"}],"timestamp":"1785121875802"},"payload_hash":"53348f89086274b8b4060b4679b11b0436ba48e501c0399f9e567cee777f585d","raw_frame":"{\"market\":\"0xf9d60bb033695053c4d1d8592e52171c1042f64b41a4b72e09dcc6f4852b6670\", \"price_changes\":[{\"asset_id\":\"8698449539441374295770236407991735029336433231649246775082939325523552031992\", \"price\":\"0.32\", \"size\":\"61.11\", \"side\":\"SELL\", \"hash\":\"de4f57bdeb0442c182c782cd58baf406c593d1f5\", \"best_bid\":\"0.26\", \"best_ask\":\"0.27\"}, {\"asset_id\":\"96283536366176669581486355171583722558858323126916278856549586825357358273536\", \"price\":\"0.68\", \"size\":\"61.11\", \"side\":\"BUY\", \"hash\":\"c422a64ec1d79fcace2f09b381e0f2780ef4d685\", \"best_bid\":\"0.73\", \"best_ask\":\"0.74\"}], \"timestamp\":\"1785121875802\", \"event_type\":\"price_change\"}","received_at":"2026-07-27T03:11:24.455446Z","schema_version":"clob-market-ws.price_change.v1","sequence":null,"server_hash":null,"server_timestamp":"1785121875802","session_id":"ff6d21c8283948938400a32613abec2c","source":"clob_market_ws"},"received_at":"2026-07-27T03:11:24.455446Z","record_id":"3d7d39c187c9dac46e309e7741f9dc102e9feeeb9349ac00342c11e813d85904","schema_fingerprint":"4aa3821a28b0b7c2400bc59aba4bcc0a76e971dadd19610d3ad38c768e124dc7","schema_version":"edge-lab-recorder.raw.v1","sequence":null,"source":"clob_market_ws"}
{"event_at":"2026-07-27T03:11:15.806000Z","event_fingerprint":"37342eaa7b32d09128438f8e3540d04cf9491bc55b9046b73f2bad459a51b349","payload":{"connection_id":"f95883f18d264834af91809e5f803e9f","event_at":"2026-07-27T03:11:15.806000Z","event_type":"price_change","frame_hash":"57289ac6ede0fd27b7b4d9655808ad29a2a3e3f0a572fda6719ee7e6244f7cce","frame_index":0,"kind":"data","monotonic_ns":223867789168625,"payload":{"event_type":"price_change","market":"0xf9d60bb033695053c4d1d8592e52171c1042f64b41a4b72e09dcc6f4852b6670","price_changes":[{"asset_id":"96283536366176669581486355171583722558858323126916278856549586825357358273536","best_ask":"0.74","best_bid":"0.73","hash":"87ce8296b0868440cf71325a690fdc48e4f67ff7","price":"0.02","side":"BUY","size":"1568.79"},{"asset_id":"8698449539441374295770236407991735029336433231649246775082939325523552031992","best_ask":"0.27","best_bid":"0.26","hash":"0cee02aab0e31bd7c82b8ba09aa468653908be90","price":"0.98","side":"SELL","size":"1568.79"}],"timestamp":"1785121875806"},"payload_hash":"4944fd644084dbd8c29e2f697adb7ca6868b49d08a23075f631c0bdd9a2b9e95","raw_frame":"{\"market\":\"0xf9d60bb033695053c4d1d8592e52171c1042f64b41a4b72e09dcc6f4852b6670\", \"price_changes\":[{\"asset_id\":\"96283536366176669581486355171583722558858323126916278856549586825357358273536\", \"price\":\"0.02\", \"size\":\"1568.79\", \"side\":\"BUY\", \"hash\":\"87ce8296b0868440cf71325a690fdc48e4f67ff7\", \"best_bid\":\"0.73\", \"best_ask\":\"0.74\"}, {\"asset_id\":\"8698449539441374295770236407991735029336433231649246775082939325523552031992\", \"price\":\"0.98\", \"size\":\"1568.79\", \"side\":\"SELL\", \"hash\":\"0cee02aab0e31bd7c82b8ba09aa468653908be90\", \"best_bid\":\"0.26\", \"best_ask\":\"0.27\"}], \"timestamp\":\"1785121875806\", \"event_type\":\"price_change\"}","received_at":"2026-07-27T03:11:24.458519Z","schema_version":"clob-market-ws.price_change.v1","sequence":null,"server_hash":null,"server_timestamp":"1785121875806","session_id":"ff6d21c8283948938400a32613abec2c","source":"clob_market_ws"},"received_at":"2026-07-27T03:11:24.458519Z","record_id":"7f7ea1841760044b2720f2afbff55ead49a092482ba8cfba2b6a294ed53a439b","schema_fingerprint":"4aa3821a28b0b7c2400bc59aba4bcc0a76e971dadd19610d3ad38c768e124dc7","schema_version":"edge-lab-recorder.raw.v1","sequence":null,"source":"clob_market_ws"}
{"event_at":"2026-07-27T03:11:15.812000Z","event_fingerprint":"2145c07d58fe61722eb024b9a2b99123cd9221ac0177fcfe4e1c40e3e3d8408d","payload":{"connection_id":"f95883f18d264834af91809e5f803e9f","event_at":"2026-07-27T03:11:15.812000Z","event_type":"price_change","frame_hash":"74967d27fabe898d1de9f1cae7ba279c25d78ef560be03cc925df8a8e6af2075","frame_index":0,"kind":"data","monotonic_ns":223867792581291,"payload":{"event_type":"price_change","market":"0xf9d60bb033695053c4d1d8592e52171c1042f64b41a4b72e09dcc6f4852b6670","price_changes":[{"asset_id":"8698449539441374295770236407991735029336433231649246775082939325523552031992","best_ask":"0.27","best_bid":"0.26","hash":"a8029625502208ed979bf49626fab95cc60e2260","price":"0.25","side":"BUY","size":"85"},{"asset_id":"96283536366176669581486355171583722558858323126916278856549586825357358273536","best_ask":"0.74","best_bid":"0.73","hash":"7adbdb7582f3c6bb8bda617a4b782f1bd5128b22","price":"0.75","side":"SELL","size":"85"}],"timestamp":"1785121875812"},"payload_hash":"72c4ba1e1db88149880e98494d2c45523d8a397e36e79ec23513c6ab90a7fe36","raw_frame":"{\"market\":\"0xf9d60bb033695053c4d1d8592e52171c1042f64b41a4b72e09dcc6f4852b6670\", \"price_changes\":[{\"asset_id\":\"8698449539441374295770236407991735029336433231649246775082939325523552031992\", \"price\":\"0.25\", \"size\":\"85\", \"side\":\"BUY\", \"hash\":\"a8029625502208ed979bf49626fab95cc60e2260\", \"best_bid\":\"0.26\", \"best_ask\":\"0.27\"}, {\"asset_id\":\"96283536366176669581486355171583722558858323126916278856549586825357358273536\", \"price\":\"0.75\", \"size\":\"85\", \"side\":\"SELL\", \"hash\":\"7adbdb7582f3c6bb8bda617a4b782f1bd5128b22\", \"best_bid\":\"0.73\", \"best_ask\":\"0.74\"}], \"timestamp\":\"1785121875812\", \"event_type\":\"price_change\"}","received_at":"2026-07-27T03:11:24.461939Z","schema_version":"clob-market-ws.price_change.v1","sequence":null,"server_hash":null,"server_timestamp":"1785121875812","session_id":"ff6d21c8283948938400a32613abec2c","source":"clob_market_ws"},"received_at":"2026-07-27T03:11:24.461939Z","record_id":"379ff5b4518bdf569f808bfd1afeed052731c20c209289b34311d80b4dba4be4","schema_fingerprint":"4aa3821a28b0b7c2400bc59aba4bcc0a76e971dadd19610d3ad38c768e124dc7","schema_version":"edge-lab-recorder.raw.v1","sequence":null,"source":"clob_market_ws"}
{"event_at":"2026-07-27T03:11:15.833000Z","event_fingerprint":"ea0755e9e9a14cb879d513da5fa62cb9565187f59aba3f83a4d7f0ef5f70a89f","payload":{"connection_id":"f95883f18d264834af91809e5f803e9f","event_at":"2026-07-27T03:11:15.833000Z","event_type":"price_change","frame_hash":"7fd057a95d2f4cd2dee3b395360e772b73bdfa77700f944c6f9f8ac837c48423","frame_index":0,"kind":"data","monotonic_ns":223867795761750,"payload":{"event_type":"price_change","market":"0xf9d60bb033695053c4d1d8592e52171c1042f64b41a4b72e09dcc6f4852b6670","price_changes":[{"asset_id":"96283536366176669581486355171583722558858323126916278856549586825357358273536","best_ask":"0.74","best_bid":"0.73","hash":"bcf27f1f4dcd6b207583bd36496738b71520d452","price":"0.73","side":"BUY","size":"96.34"},{"asset_id":"8698449539441374295770236407991735029336433231649246775082939325523552031992","best_ask":"0.27","best_bid":"0.26","hash":"8817055649b0a31ad5ca5d65d74c5dd3bc06dea8","price":"0.27","side":"SELL","size":"96.34"}],"timestamp":"1785121875833"},"payload_hash":"fa20309205d882a0add25586407e7c30a0db602133d1c34b2dc4da12857c7cf6","raw_frame":"{\"market\":\"0xf9d60bb033695053c4d1d8592e52171c1042f64b41a4b72e09dcc6f4852b6670\", \"price_changes\":[{\"asset_id\":\"96283536366176669581486355171583722558858323126916278856549586825357358273536\", \"price\":\"0.73\", \"size\":\"96.34\", \"side\":\"BUY\", \"hash\":\"bcf27f1f4dcd6b207583bd36496738b71520d452\", \"best_bid\":\"0.73\", \"best_ask\":\"0.74\"}, {\"asset_id\":\"8698449539441374295770236407991735029336433231649246775082939325523552031992\", \"price\":\"0.27\", \"size\":\"96.34\", \"side\":\"SELL\", \"hash\":\"8817055649b0a31ad5ca5d65d74c5dd3bc06dea8\", \"best_bid\":\"0.26\", \"best_ask\":\"0.27\"}], \"timestamp\":\"1785121875833\", \"event_type\":\"price_change\"}","received_at":"2026-07-27T03:11:24.465119Z","schema_version":"clob-market-ws.price_change.v1","sequence":null,"server_hash":null,"server_timestamp":"1785121875833","session_id":"ff6d21c8283948938400a32613abec2c","source":"clob_market_ws"},"received_at":"2026-07-27T03:11:24.465119Z","record_id":"db202e97c1e1c01b8652074887e074f6b08010c01bb664574f80670f3bc1de61","schema_fingerprint":"4aa3821a28b0b7c2400bc59aba4bcc0a76e971dadd19610d3ad38c768e124dc7","schema_version":"edge-lab-recorder.raw.v1","sequence":null,"source":"clob_market_ws"}
{"event_at":"2026-07-27T03:11:15.835000Z","event_fingerprint":"23d0a0eed8019cc4eaf45a207d8febad6b8a929976e5417d7258ffa07b461dcd","payload":{"connection_id":"f95883f18d264834af91809e5f803e9f","event_at":"2026-07-27T03:11:15.835000Z","event_type":"price_change","frame_hash":"ee765aec6bfd09556907b5870c08a3dcbc68664b3e62270089e528637b0bf84c","frame_index":0,"kind":"data","monotonic_ns":223867797878250,"payload":{"event_type":"price_change","market":"0xf9d60bb033695053c4d1d8592e52171c1042f64b41a4b72e09dcc6f4852b6670","price_changes":[{"asset_id":"8698449539441374295770236407991735029336433231649246775082939325523552031992","best_ask":"0.27","best_bid":"0.26","hash":"22e1e3664eb524845de117afe1500bc76e535f17","price":"0.27","side":"SELL","size":"112.76"},{"asset_id":"96283536366176669581486355171583722558858323126916278856549586825357358273536","best_ask":"0.74","best_bid":"0.73","hash":"08c90a4f8a09d23f45be33b6724636adfd3a9eca","price":"0.73","side":"BUY","size":"112.76"}],"timestamp":"1785121875835"},"payload_hash":"05060f69517ba0d515780114c42bf4c5df735105e08efa9368c14117d0edaa4e","raw_frame":"{\"market\":\"0xf9d60bb033695053c4d1d8592e52171c1042f64b41a4b72e09dcc6f4852b6670\", \"price_changes\":[{\"asset_id\":\"8698449539441374295770236407991735029336433231649246775082939325523552031992\", \"price\":\"0.27\", \"size\":\"112.76\", \"side\":\"SELL\", \"hash\":\"22e1e3664eb524845de117afe1500bc76e535f17\", \"best_bid\":\"0.26\", \"best_ask\":\"0.27\"}, {\"asset_id\":\"96283536366176669581486355171583722558858323126916278856549586825357358273536\", \"price\":\"0.73\", \"size\":\"112.76\", \"side\":\"BUY\", \"hash\":\"08c90a4f8a09d23f45be33b6724636adfd3a9eca\", \"best_bid\":\"0.73\", \"best_ask\":\"0.74\"}], \"timestamp\":\"1785121875835\", \"event_type\":\"price_change\"}","received_at":"2026-07-27T03:11:24.467242Z","schema_version":"clob-market-ws.price_change.v1","sequence":null,"server_hash":null,"server_timestamp":"1785121875835","session_id":"ff6d21c8283948938400a32613abec2c","source":"clob_market_ws"},"received_at":"2026-07-27T03:11:24.467242Z","record_id":"4b9d138ca23777029eeabe5025aa8df659b00faceddec92afbdc4fdd58e41d79","schema_fingerprint":"4aa3821a28b0b7c2400bc59aba4bcc0a76e971dadd19610d3ad38c768e124dc7","schema_version":"edge-lab-recorder.raw.v1","sequence":null,"source":"clob_market_ws"}
{"event_at":"2026-07-27T03:11:15.836000Z","event_fingerprint":"84329ec0a79f080afdb8edd9f610141c332a61d37e1e4ff4cf7935342e34fe8d","payload":{"connection_id":"f95883f18d264834af91809e5f803e9f","event_at":"2026-07-27T03:11:15.836000Z","event_type":"price_change","frame_hash":"2d6209657a7e2a95cffec532f6d2384f411ae66bbdd460c697eb22d8aac9e6e0","frame_index":0,"kind":"data","monotonic_ns":223867799934000,"payload":{"event_type":"price_change","market":"0xf9d60bb033695053c4d1d8592e52171c1042f64b41a4b72e09dcc6f4852b6670","price_changes":[{"asset_id":"8698449539441374295770236407991735029336433231649246775082939325523552031992","best_ask":"0.27","best_bid":"0.26","hash":"05dc86150848ff79bf3ed9384d4c151f619f01a7","price":"0.16","side":"BUY","size":"151.4"},{"asset_id":"96283536366176669581486355171583722558858323126916278856549586825357358273536","best_ask":"0.74","best_bid":"0.73","hash":"e64129e936f4089e413390d152ab8b6429b17054","price":"0.84","side":"SELL","size":"151.4"}],"timestamp":"1785121875836"},"payload_hash":"6348e84438be94f28c2d56758cc5983fdb37d41dd57b95b8dfa88717f531e2cf","raw_frame":"{\"market\":\"0xf9d60bb033695053c4d1d8592e52171c1042f64b41a4b72e09dcc6f4852b6670\", \"price_changes\":[{\"asset_id\":\"8698449539441374295770236407991735029336433231649246775082939325523552031992\", \"price\":\"0.16\", \"size\":\"151.4\", \"side\":\"BUY\", \"hash\":\"05dc86150848ff79bf3ed9384d4c151f619f01a7\", \"best_bid\":\"0.26\", \"best_ask\":\"0.27\"}, {\"asset_id\":\"96283536366176669581486355171583722558858323126916278856549586825357358273536\", \"price\":\"0.84\", \"size\":\"151.4\", \"side\":\"SELL\", \"hash\":\"e64129e936f4089e413390d152ab8b6429b17054\", \"best_bid\":\"0.73\", \"best_ask\":\"0.74\"}], \"timestamp\":\"1785121875836\", \"event_type\":\"price_change\"}","received_at":"2026-07-27T03:11:24.469292Z","schema_version":"clob-market-ws.price_change.v1","sequence":null,"server_hash":null,"server_timestamp":"1785121875836","session_id":"ff6d21c8283948938400a32613abec2c","source":"clob_market_ws"},"received_at":"2026-07-27T03:11:24.469292Z","record_id":"3bfb567702ea0dcc834f1f9383baab2a93c3e997939e6a02244a5f14a3b7de4d","schema_fingerprint":"4aa3821a28b0b7c2400bc59aba4bcc0a76e971dadd19610d3ad38c768e124dc7","schema_version":"edge-lab-recorder.raw.v1","sequence":null,"source":"clob_market_ws"}
{"event_at":"2026-07-27T03:11:15.838000Z","event_fingerprint":"34aadaa33f18d4ec0f4bc9752d742fe5f184986fba71666d6601bdb3cab27ed8","payload":{"connection_id":"f95883f18d264834af91809e5f803e9f","event_at":"2026-07-27T03:11:15.838000Z","event_type":"price_change","frame_hash":"45c8f8356f8d450f1bf453201010d0dc3f9e391b72c06fb2e8277bd85e62a3dd","frame_index":0,"kind":"data","monotonic_ns":223867803198125,"payload":{"event_type":"price_change","market":"0xf9d60bb033695053c4d1d8592e52171c1042f64b41a4b72e09dcc6f4852b6670","price_changes":[{"asset_id":"96283536366176669581486355171583722558858323126916278856549586825357358273536","best_ask":"0.74","best_bid":"0.73","hash":"d61d9d133f7ea04a05aa1635ffb9453d8cac8ab0","price":"0.72","side":"BUY","size":"55.68"},{"asset_id":"8698449539441374295770236407991735029336433231649246775082939325523552031992","best_ask":"0.27","best_bid":"0.26","hash":"acb2ed78ec69a7778426515791f020da44cbaa04","price":"0.28","side":"SELL","size":"55.68"}],"timestamp":"1785121875838"},"payload_hash":"a99805bb65558b74806a322a95704839e3221394615f6397059022f4018a2217","raw_frame":"{\"market\":\"0xf9d60bb033695053c4d1d8592e52171c1042f64b41a4b72e09dcc6f4852b6670\", \"price_changes\":[{\"asset_id\":\"96283536366176669581486355171583722558858323126916278856549586825357358273536\", \"price\":\"0.72\", \"size\":\"55.68\", \"side\":\"BUY\", \"hash\":\"d61d9d133f7ea04a05aa1635ffb9453d8cac8ab0\", \"best_bid\":\"0.73\", \"best_ask\":\"0.74\"}, {\"asset_id\":\"8698449539441374295770236407991735029336433231649246775082939325523552031992\", \"price\":\"0.28\", \"size\":\"55.68\", \"side\":\"SELL\", \"hash\":\"acb2ed78ec69a7778426515791f020da44cbaa04\", \"best_bid\":\"0.26\", \"best_ask\":\"0.27\"}], \"timestamp\":\"1785121875838\", \"event_type\":\"price_change\"}","received_at":"2026-07-27T03:11:24.472553Z","schema_version":"clob-market-ws.price_change.v1","sequence":null,"server_hash":null,"server_timestamp":"1785121875838","session_id":"ff6d21c8283948938400a32613abec2c","source":"clob_market_ws"},"received_at":"2026-07-27T03:11:24.472553Z","record_id":"b2c516f44ed618798052011d7cab85615d2d922011cfa5d7c23ed146bac27c71","schema_fingerprint":"4aa3821a28b0b7c2400bc59aba4bcc0a76e971dadd19610d3ad38c768e124dc7","schema_version":"edge-lab-recorder.raw.v1","sequence":null,"source":"clob_market_ws"}
{"event_at":"2026-07-27T03:11:15.846000Z","event_fingerprint":"25ef11d711ed1d02145b09622f8395275d8cec8df38784418582b40f4926410e","payload":{"connection_id":"f95883f18d264834af91809e5f803e9f","event_at":"2026-07-27T03:11:15.846000Z","event_type":"price_change","frame_hash":"0afa53238c69e71c64d7b18c156104cdf5f0a9c88c3056a248013f4d5084255e","frame_index":0,"kind":"data","monotonic_ns":223867806528000,"payload":{"event_type":"price_change","market":"0xf9d60bb033695053c4d1d8592e52171c1042f64b41a4b72e09dcc6f4852b6670","price_changes":[{"asset_id":"96283536366176669581486355171583722558858323126916278856549586825357358273536","best_ask":"0.74","best_bid":"0.73","hash":"5ed4f9ad274fb2956e02eca7a4276b208a1a83fe","price":"0.68","side":"BUY","size":"51.11"},{"asset_id":"8698449539441374295770236407991735029336433231649246775082939325523552031992","best_ask":"0.27","best_bid":"0.26","hash":"0079e320ec739cb761e68036bf46ad925be04a38","price":"0.32","side":"SELL","size":"51.11"}],"timestamp":"1785121875846"},"payload_hash":"cd29a8f860cf473393d0a5c77d87a9fa588db2e37b0e8a612a378731d60bb651","raw_frame":"{\"market\":\"0xf9d60bb033695053c4d1d8592e52171c1042f64b41a4b72e09dcc6f4852b6670\", \"price_changes\":[{\"asset_id\":\"96283536366176669581486355171583722558858323126916278856549586825357358273536\", \"price\":\"0.68\", \"size\":\"51.11\", \"side\":\"BUY\", \"hash\":\"5ed4f9ad274fb2956e02eca7a4276b208a1a83fe\", \"best_bid\":\"0.73\", \"best_ask\":\"0.74\"}, {\"asset_id\":\"8698449539441374295770236407991735029336433231649246775082939325523552031992\", \"price\":\"0.32\", \"size\":\"51.11\", \"side\":\"SELL\", \"hash\":\"0079e320ec739cb761e68036bf46ad925be04a38\", \"best_bid\":\"0.26\", \"best_ask\":\"0.27\"}], \"timestamp\":\"1785121875846\", \"event_type\":\"price_change\"}","received_at":"2026-07-27T03:11:24.475885Z","schema_version":"clob-market-ws.price_change.v1","sequence":null,"server_hash":null,"server_timestamp":"1785121875846","session_id":"ff6d21c8283948938400a32613abec2c","source":"clob_market_ws"},"received_at":"2026-07-27T03:11:24.475885Z","record_id":"7463e95b580ff580cdf90dd9b3828606964d7e35e716908535a52e8a59960173","schema_fingerprint":"4aa3821a28b0b7c2400bc59aba4bcc0a76e971dadd19610d3ad38c768e124dc7","schema_version":"edge-lab-recorder.raw.v1","sequence":null,"source":"clob_market_ws"}
{"event_at":"2026-07-27T03:11:15.848000Z","event_fingerprint":"84090637171c4963ef01e963db1d0e9df2375fc144a1740cdd981cca69ced4b1","payload":{"connection_id":"f95883f18d264834af91809e5f803e9f","event_at":"2026-07-27T03:11:15.848000Z","event_type":"price_change","frame_hash":"e589d7cf67220c389c43dc31e1a9a091e8183136226608fe7f2484f52bcdf31c","frame_index":0,"kind":"data","monotonic_ns":223867812838833,"payload":{"event_type":"price_change","market":"0xf9d60bb033695053c4d1d8592e52171c1042f64b41a4b72e09dcc6f4852b6670","price_changes":[{"asset_id":"8698449539441374295770236407991735029336433231649246775082939325523552031992","best_ask":"0.27","best_bid":"0.26","hash":"cc7e93eb7b206cd9f1f04a368b328ab7c93e6bfd","price":"0.32","side":"SELL","size":"46.11"},{"asset_id":"96283536366176669581486355171583722558858323126916278856549586825357358273536","best_ask":"0.74","best_bid":"0.73","hash":"70902e5638f8edaf8ae0e52e8e571bd781cf9289","price":"0.68","side":"BUY","size":"46.11"}],"timestamp":"1785121875848"},"payload_hash":"4a318b894c709d24561bbbd595f41d17ce40667aea85342ca5ce10ff44953778","raw_frame":"{\"market\":\"0xf9d60bb033695053c4d1d8592e52171c1042f64b41a4b72e09dcc6f4852b6670\", \"price_changes\":[{\"asset_id\":\"8698449539441374295770236407991735029336433231649246775082939325523552031992\", \"price\":\"0.32\", \"size\":\"46.11\", \"side\":\"SELL\", \"hash\":\"cc7e93eb7b206cd9f1f04a368b328ab7c93e6bfd\", \"best_bid\":\"0.26\", \"best_ask\":\"0.27\"}, {\"asset_id\":\"96283536366176669581486355171583722558858323126916278856549586825357358273536\", \"price\":\"0.68\", \"size\":\"46.11\", \"side\":\"BUY\", \"hash\":\"70902e5638f8edaf8ae0e52e8e571bd781cf9289\", \"best_bid\":\"0.73\", \"best_ask\":\"0.74\"}], \"timestamp\":\"1785121875848\", \"event_type\":\"price_change\"}","received_at":"2026-07-27T03:11:24.482195Z","schema_version":"clob-market-ws.price_change.v1","sequence":null,"server_hash":null,"server_timestamp":"1785121875848","session_id":"ff6d21c8283948938400a32613abec2c","source":"clob_market_ws"},"received_at":"2026-07-27T03:11:24.482195Z","record_id":"3953d5a757e435981f5b259108d9b2e8dfc965dd2750c6f17bc99ffa3abf9df8","schema_fingerprint":"4aa3821a28b0b7c2400bc59aba4bcc0a76e971dadd19610d3ad38c768e124dc7","schema_version":"edge-lab-recorder.raw.v1","sequence":null,"source":"clob_market_ws"}
{"event_at":"2026-07-27T03:11:15.848000Z","event_fingerprint":"f77ca53af5ac21ea57b68f9788096775579913146eea1be25e70f177f3b78ea2","payload":{"connection_id":"f95883f18d264834af91809e5f803e9f","event_at":"2026-07-27T03:11:15.848000Z","event_type":"price_change","frame_hash":"5124aaa4ea8a34d05391704686eb9b7dd96c5379d4a39f99af7e8d779aaca25f","frame_index":0,"kind":"data","monotonic_ns":223867814747500,"payload":{"event_type":"price_change","market":"0xf9d60bb033695053c4d1d8592e52171c1042f64b41a4b72e09dcc6f4852b6670","price_changes":[{"asset_id":"96283536366176669581486355171583722558858323126916278856549586825357358273536","best_ask":"0.74","best_bid":"0.73","hash":"22260d8752d648b917b7252fab98c6954572681d","price":"0.69","side":"BUY","size":"43.19"},{"asset_id":"8698449539441374295770236407991735029336433231649246775082939325523552031992","best_ask":"0.27","best_bid":"0.26","hash":"58064f18bdec78ceb1387f969f83a670b6b148fa","price":"0.31","side":"SELL","size":"43.19"}],"timestamp":"1785121875848"},"payload_hash":"003da159fccbc127df6e47d015bfe7b832d3b2ffed0b01124657944162acd6b9","raw_frame":"{\"market\":\"0xf9d60bb033695053c4d1d8592e52171c1042f64b41a4b72e09dcc6f4852b6670\", \"price_changes\":[{\"asset_id\":\"96283536366176669581486355171583722558858323126916278856549586825357358273536\", \"price\":\"0.69\", \"size\":\"43.19\", \"side\":\"BUY\", \"hash\":\"22260d8752d648b917b7252fab98c6954572681d\", \"best_bid\":\"0.73\", \"best_ask\":\"0.74\"}, {\"asset_id\":\"8698449539441374295770236407991735029336433231649246775082939325523552031992\", \"price\":\"0.31\", \"size\":\"43.19\", \"side\":\"SELL\", \"hash\":\"58064f18bdec78ceb1387f969f83a670b6b148fa\", \"best_bid\":\"0.26\", \"best_ask\":\"0.27\"}], \"timestamp\":\"1785121875848\", \"event_type\":\"price_change\"}","received_at":"2026-07-27T03:11:24.484110Z","schema_version":"clob-market-ws.price_change.v1","sequence":null,"server_hash":null,"server_timestamp":"1785121875848","session_id":"ff6d21c8283948938400a32613abec2c","source":"clob_market_ws"},"received_at":"2026-07-27T03:11:24.484110Z","record_id":"66c2ad205194c427fbaed60bdf44394b9c1be4068117471ae027b762083bd2cc","schema_fingerprint":"4aa3821a28b0b7c2400bc59aba4bcc0a76e971dadd19610d3ad38c768e124dc7","schema_version":"edge-lab-recorder.raw.v1","sequence":null,"source":"clob_market_ws"}
{"event_at":"2026-07-27T03:11:15.858000Z","event_fingerprint":"a11d062b867ed792cb3c00536705189edb1fa818a3f9747b31a204ff81507998","payload":{"connection_id":"f95883f18d264834af91809e5f803e9f","event_at":"2026-07-27T03:11:15.858000Z","event_type":"price_change","frame_hash":"fbd55efbeb7aea827df242111c913a409dcda65cb933da7f3b3ce9414a34a79d","frame_index":0,"kind":"data","monotonic_ns":223867819712833,"payload":{"event_type":"price_change","market":"0xf9d60bb033695053c4d1d8592e52171c1042f64b41a4b72e09dcc6f4852b6670","price_changes":[{"asset_id":"96283536366176669581486355171583722558858323126916278856549586825357358273536","best_ask":"0.74","best_bid":"0.73","hash":"745499a8fa2351b965540123a602fcaf13f4fb0b","price":"0.72","side":"BUY","size":"65.68"},{"asset_id":"8698449539441374295770236407991735029336433231649246775082939325523552031992","best_ask":"0.27","best_bid":"0.26","hash":"c6997619618899fc664e4837cc5c7f8308473184","price":"0.28","side":"SELL","size":"65.68"}],"timestamp":"1785121875858"},"payload_hash":"7799511d4020c23e4b5005d9c9e75c0fc575ac7dc78d917692e12f8c984f31a3","raw_frame":"{\"market\":\"0xf9d60bb033695053c4d1d8592e52171c1042f64b41a4b72e09dcc6f4852b6670\", \"price_changes\":[{\"asset_id\":\"96283536366176669581486355171583722558858323126916278856549586825357358273536\", \"price\":\"0.72\", \"size\":\"65.68\", \"side\":\"BUY\", \"hash\":\"745499a8fa2351b965540123a602fcaf13f4fb0b\", \"best_bid\":\"0.73\", \"best_ask\":\"0.74\"}, {\"asset_id\":\"8698449539441374295770236407991735029336433231649246775082939325523552031992\", \"price\":\"0.28\", \"size\":\"65.68\", \"side\":\"SELL\", \"hash\":\"c6997619618899fc664e4837cc5c7f8308473184\", \"best_bid\":\"0.26\", \"best_ask\":\"0.27\"}], \"timestamp\":\"1785121875858\", \"event_type\":\"price_change\"}","received_at":"2026-07-27T03:11:24.489070Z","schema_version":"clob-market-ws.price_change.v1","sequence":null,"server_hash":null,"server_timestamp":"1785121875858","session_id":"ff6d21c8283948938400a32613abec2c","source":"clob_market_ws"},"received_at":"2026-07-27T03:11:24.489070Z","record_id":"c2d79ca83b46f850f826cd94a5f07160d3784396a24e95664139b3950d287950","schema_fingerprint":"4aa3821a28b0b7c2400bc59aba4bcc0a76e971dadd19610d3ad38c768e124dc7","schema_version":"edge-lab-recorder.raw.v1","sequence":null,"source":"clob_market_ws"}
{"event_at":"2026-07-27T03:11:15.877000Z","event_fingerprint":"bde9c3164b20deb89fc7c97653bf4832be33af08e3c1258a7e56cd09473a4679","payload":{"connection_id":"f95883f18d264834af91809e5f803e9f","event_at":"2026-07-27T03:11:15.877000Z","event_type":"price_change","frame_hash":"89272526af899d177bd2a46e090d05141b904d9867e70a94b4693d3631e085cf","frame_index":0,"kind":"data","monotonic_ns":223867822872916,"payload":{"event_type":"price_change","market":"0xf9d60bb033695053c4d1d8592e52171c1042f64b41a4b72e09dcc6f4852b6670","price_changes":[{"asset_id":"96283536366176669581486355171583722558858323126916278856549586825357358273536","best_ask":"0.74","best_bid":"0.73","hash":"b15f3881437554da1b6f0ea253bdbb0105a7d8b2","price":"0.68","side":"BUY","size":"51.11"},{"asset_id":"8698449539441374295770236407991735029336433231649246775082939325523552031992","best_ask":"0.27","best_bid":"0.26","hash":"26541aad639423f4cdd63b48ac3891e7cb7e6961","price":"0.32","side":"SELL","size":"51.11"}],"timestamp":"1785121875877"},"payload_hash":"8945bd44dc75763f83962cafdcc4cfb0661d280207e851a746c483760cf36207","raw_frame":"{\"market\":\"0xf9d60bb033695053c4d1d8592e52171c1042f64b41a4b72e09dcc6f4852b6670\", \"price_changes\":[{\"asset_id\":\"96283536366176669581486355171583722558858323126916278856549586825357358273536\", \"price\":\"0.68\", \"size\":\"51.11\", \"side\":\"BUY\", \"hash\":\"b15f3881437554da1b6f0ea253bdbb0105a7d8b2\", \"best_bid\":\"0.73\", \"best_ask\":\"0.74\"}, {\"asset_id\":\"8698449539441374295770236407991735029336433231649246775082939325523552031992\", \"price\":\"0.32\", \"size\":\"51.11\", \"side\":\"SELL\", \"hash\":\"26541aad639423f4cdd63b48ac3891e7cb7e6961\", \"best_bid\":\"0.26\", \"best_ask\":\"0.27\"}], \"timestamp\":\"1785121875877\", \"event_type\":\"price_change\"}","received_at":"2026-07-27T03:11:24.492223Z","schema_version":"clob-market-ws.price_change.v1","sequence":null,"server_hash":null,"server_timestamp":"1785121875877","session_id":"ff6d21c8283948938400a32613abec2c","source":"clob_market_ws"},"received_at":"2026-07-27T03:11:24.492223Z","record_id":"c7c0df017012e39339245500b0810f04cb1ef124fec408e5ec4bd5190bf9f391","schema_fingerprint":"4aa3821a28b0b7c2400bc59aba4bcc0a76e971dadd19610d3ad38c768e124dc7","schema_version":"edge-lab-recorder.raw.v1","sequence":null,"source":"clob_market_ws"}
{"event_at":"2026-07-27T03:11:15.878000Z","event_fingerprint":"acc33e862d70f66a2356e685f6f562cdaa81afe12c8ac3300a5c96344df8386b","payload":{"connection_id":"f95883f18d264834af91809e5f803e9f","event_at":"2026-07-27T03:11:15.878000Z","event_type":"price_change","frame_hash":"bf9043eb2f37afdad74726580b0aedd851b915b575ebd775a29296c2c9b4fc1b","frame_index":0,"kind":"data","monotonic_ns":223867825983500,"payload":{"event_type":"price_change","market":"0xf9d60bb033695053c4d1d8592e52171c1042f64b41a4b72e09dcc6f4852b6670","price_changes":[{"asset_id":"96283536366176669581486355171583722558858323126916278856549586825357358273536","best_ask":"0.74","best_bid":"0.73","hash":"a37c2027d975706c129a639f155ac2c67ee65b46","price":"0.73","side":"BUY","size":"122.76"},{"asset_id":"8698449539441374295770236407991735029336433231649246775082939325523552031992","best_ask":"0.27","best_bid":"0.26","hash":"b442f29f60bd109e799a9b4e039700cc114cc10c","price":"0.27","side":"SELL","size":"122.76"}],"timestamp":"1785121875878"},"payload_hash":"41a70bd8166546d17954db8881434b4ea2c43ffcb7f49c8f65dbd8295bd33af9","raw_frame":"{\"market\":\"0xf9d60bb033695053c4d1d8592e52171c1042f64b41a4b72e09dcc6f4852b6670\", \"price_changes\":[{\"asset_id\":\"96283536366176669581486355171583722558858323126916278856549586825357358273536\", \"price\":\"0.73\", \"size\":\"122.76\", \"side\":\"BUY\", \"hash\":\"a37c2027d975706c129a639f155ac2c67ee65b46\", \"best_bid\":\"0.73\", \"best_ask\":\"0.74\"}, {\"asset_id\":\"8698449539441374295770236407991735029336433231649246775082939325523552031992\", \"price\":\"0.27\", \"size\":\"122.76\", \"side\":\"SELL\", \"hash\":\"b442f29f60bd109e799a9b4e039700cc114cc10c\", \"best_bid\":\"0.26\", \"best_ask\":\"0.27\"}], \"timestamp\":\"1785121875878\", \"event_type\":\"price_change\"}","received_at":"2026-07-27T03:11:24.495341Z","schema_version":"clob-market-ws.price_change.v1","sequence":null,"server_hash":null,"server_timestamp":"1785121875878","session_id":"ff6d21c8283948938400a32613abec2c","source":"clob_market_ws"},"received_at":"2026-07-27T03:11:24.495341Z","record_id":"6697cb7ad7df8c892278c8e8c8f1061d307550e363257e35a8c45082e66a3b0a","schema_fingerprint":"4aa3821a28b0b7c2400bc59aba4bcc0a76e971dadd19610d3ad38c768e124dc7","schema_version":"edge-lab-recorder.raw.v1","sequence":null,"source":"clob_market_ws"}
{"event_at":"2026-07-27T03:11:15.882000Z","event_fingerprint":"32442390480b59b685bd5f8c89969cb7ce2076e6e42541a103c6ef8fa743693f","payload":{"connection_id":"f95883f18d264834af91809e5f803e9f","event_at":"2026-07-27T03:11:15.882000Z","event_type":"price_change","frame_hash":"c2b7c138cba1e81044e69011c5a40b3187c5b009f3dd96e449b9ab26fe8d19f8","frame_index":0,"kind":"data","monotonic_ns":223867829232750,"payload":{"event_type":"price_change","market":"0xf9d60bb033695053c4d1d8592e52171c1042f64b41a4b72e09dcc6f4852b6670","price_changes":[{"asset_id":"96283536366176669581486355171583722558858323126916278856549586825357358273536","best_ask":"0.74","best_bid":"0.73","hash":"205f751afb04eb0c09e21472f8bf8cc5873ea441","price":"0.63","side":"BUY","size":"170.62"},{"asset_id":"8698449539441374295770236407991735029336433231649246775082939325523552031992","best_ask":"0.27","best_bid":"0.26","hash":"deb323413692f9207ed2437693050d4b0c0db2b2","price":"0.37","side":"SELL","size":"170.62"}],"timestamp":"1785121875882"},"payload_hash":"7eeba107b37c8a60b26cfba207c2b43126c594a219ca276e97b5414bfe9a1dc6","raw_frame":"{\"market\":\"0xf9d60bb033695053c4d1d8592e52171c1042f64b41a4b72e09dcc6f4852b6670\", \"price_changes\":[{\"asset_id\":\"96283536366176669581486355171583722558858323126916278856549586825357358273536\", \"price\":\"0.63\", \"size\":\"170.62\", \"side\":\"BUY\", \"hash\":\"205f751afb04eb0c09e21472f8bf8cc5873ea441\", \"best_bid\":\"0.73\", \"best_ask\":\"0.74\"}, {\"asset_id\":\"8698449539441374295770236407991735029336433231649246775082939325523552031992\", \"price\":\"0.37\", \"size\":\"170.62\", \"side\":\"SELL\", \"hash\":\"deb323413692f9207ed2437693050d4b0c0db2b2\", \"best_bid\":\"0.26\", \"best_ask\":\"0.27\"}], \"timestamp\":\"1785121875882\", \"event_type\":\"price_change\"}","received_at":"2026-07-27T03:11:24.498583Z","schema_version":"clob-market-ws.price_change.v1","sequence":null,"server_hash":null,"server_timestamp":"1785121875882","session_id":"ff6d21c8283948938400a32613abec2c","source":"clob_market_ws"},"received_at":"2026-07-27T03:11:24.498583Z","record_id":"7f43157f397324a533f4be0ce10ca9feecc819837b99f5f3615a4da427ce7bbb","schema_fingerprint":"4aa3821a28b0b7c2400bc59aba4bcc0a76e971dadd19610d3ad38c768e124dc7","schema_version":"edge-lab-recorder.raw.v1","sequence":null,"source":"clob_market_ws"}
