{"event_at":"2026-07-27T03:13:32.671000Z","event_fingerprint":"7371b0b711657a2d5df6c08adba1d4f80ed59524b67a0f2ccd406fec6da253ea","payload":{"connection_id":"f95883f18d264834af91809e5f803e9f","event_at":"2026-07-27T03:13:32.671000Z","event_type":"price_change","frame_hash":"2614830e549343d92f9b5814945349f72ffd0309edcc7da28498e9b38efaa677","frame_index":0,"kind":"data","monotonic_ns":223995910913000,"payload":{"event_type":"price_change","market":"0xf9d60bb033695053c4d1d8592e52171c1042f64b41a4b72e09dcc6f4852b6670","price_changes":[{"asset_id":"8698449539441374295770236407991735029336433231649246775082939325523552031992","best_ask":"0.82","best_bid":"0.81","hash":"0f325c1a06e952a8f7e0f4e7858763ef70a729d6","price":"0.8","side":"BUY","size":"99.76"},{"asset_id":"96283536366176669581486355171583722558858323126916278856549586825357358273536","best_ask":"0.19","best_bid":"0.18","hash":"25281ba71a58dbb8ed7b8340bb0dd84a2e66b8c2","price":"0.2","side":"SELL","size":"99.76"}],"timestamp":"1785122012671"},"payload_hash":"0d5c54d2404755076f86970013ab52bf1bbb02af37eeae1a1fae2ffdfad80948","raw_frame":"{\"market\":\"0xf9d60bb033695053c4d1d8592e52171c1042f64b41a4b72e09dcc6f4852b6670\", \"price_changes\":[{\"asset_id\":\"8698449539441374295770236407991735029336433231649246775082939325523552031992\", \"price\":\"0.8\", \"size\":\"99.76\", \"side\":\"BUY\", \"hash\":\"0f325c1a06e952a8f7e0f4e7858763ef70a729d6\", \"best_bid\":\"0.81\", \"best_ask\":\"0.82\"}, {\"asset_id\":\"96283536366176669581486355171583722558858323126916278856549586825357358273536\", \"price\":\"0.2\", \"size\":\"99.76\", \"side\":\"SELL\", \"hash\":\"25281ba71a58dbb8ed7b8340bb0dd84a2e66b8c2\", \"best_bid\":\"0.18\", \"best_ask\":\"0.19\"}], \"timestamp\":\"1785122012671\", \"event_type\":\"price_change\"}","received_at":"2026-07-27T03:13:32.578472Z","schema_version":"clob-market-ws.price_change.v1","sequence":null,"server_hash":null,"server_timestamp":"1785122012671","session_id":"ff6d21c8283948938400a32613abec2c","source":"clob_market_ws"},"received_at":"2026-07-27T03:13:32.578472Z","record_id":"b81dc64a3a1a19a38d117e6c990f4f3f8b76aa7d76210a9571a67975509f2fdc","schema_fingerprint":"4aa3821a28b0b7c2400bc59aba4bcc0a76e971dadd19610d3ad38c768e124dc7","schema_version":"edge-lab-recorder.raw.v1","sequence":null,"source":"clob_market_ws"}
{"event_at":"2026-07-27T03:13:32.675000Z","event_fingerprint":"74d84838a6ec2001887d0023e44bf34fe96cb136c4638aad1eeddd25cd5239f2","payload":{"connection_id":"f95883f18d264834af91809e5f803e9f","event_at":"2026-07-27T03:13:32.675000Z","event_type":"price_change","frame_hash":"1dc055030375ae52597b9b9693250cd9d70f4f128f3281ff066f018b2b6312f8","frame_index":0,"kind":"data","monotonic_ns":223995913107416,"payload":{"event_type":"price_change","market":"0xf9d60bb033695053c4d1d8592e52171c1042f64b41a4b72e09dcc6f4852b6670","price_changes":[{"asset_id":"8698449539441374295770236407991735029336433231649246775082939325523552031992","best_ask":"0.82","best_bid":"0.81","hash":"4c86877f98849323e45e491086ebe59efe2219e0","price":"0.01","side":"BUY","size":"8022.52"},{"asset_id":"96283536366176669581486355171583722558858323126916278856549586825357358273536","best_ask":"0.19","best_bid":"0.18","hash":"4aefa9ee98d7269e1b00c6152f9f99d999511ae2","price":"0.99","side":"SELL","size":"8022.52"}],"timestamp":"1785122012675"},"payload_hash":"231e458c5128d3b11f60969d3845b962124ed32897f52217f62a1b29ff5f2ac7","raw_frame":"{\"market\":\"0xf9d60bb033695053c4d1d8592e52171c1042f64b41a4b72e09dcc6f4852b6670\", \"price_changes\":[{\"asset_id\":\"8698449539441374295770236407991735029336433231649246775082939325523552031992\", \"price\":\"0.01\", \"size\":\"8022.52\", \"side\":\"BUY\", \"hash\":\"4c86877f98849323e45e491086ebe59efe2219e0\", \"best_bid\":\"0.81\", \"best_ask\":\"0.82\"}, {\"asset_id\":\"96283536366176669581486355171583722558858323126916278856549586825357358273536\", \"price\":\"0.99\", \"size\":\"8022.52\", \"side\":\"SELL\", \"hash\":\"4aefa9ee98d7269e1b00c6152f9f99d999511ae2\", \"best_bid\":\"0.18\", \"best_ask\":\"0.19\"}], \"timestamp\":\"1785122012675\", \"event_type\":\"price_change\"}","received_at":"2026-07-27T03:13:32.580667Z","schema_version":"clob-market-ws.price_change.v1","sequence":null,"server_hash":null,"server_timestamp":"1785122012675","session_id":"ff6d21c8283948938400a32613abec2c","source":"clob_market_ws"},"received_at":"2026-07-27T03:13:32.580667Z","record_id":"066fded2b4f2da6fc981caebac26088c86691faa7902bc50621ed06a153c1a04","schema_fingerprint":"4aa3821a28b0b7c2400bc59aba4bcc0a76e971dadd19610d3ad38c768e124dc7","schema_version":"edge-lab-recorder.raw.v1","sequence":null,"source":"clob_market_ws"}
{"event_at":"2026-07-27T03:13:32.679000Z","event_fingerprint":"088e95536e0fd306dbb9fb9622834104fad2fabda34df0c1c9db25a9f78ec2c6","payload":{"connection_id":"f95883f18d264834af91809e5f803e9f","event_at":"2026-07-27T03:13:32.679000Z","event_type":"price_change","frame_hash":"7a4ee7b3baef6427d9efc573ae8866d5e8218b82bf8b44ca929b92b0bae9485f","frame_index":0,"kind":"data","monotonic_ns":223995914767125,"payload":{"event_type":"price_change","market":"0xf9d60bb033695053c4d1d8592e52171c1042f64b41a4b72e09dcc6f4852b6670","price_changes":[{"asset_id":"8698449539441374295770236407991735029336433231649246775082939325523552031992","best_ask":"0.82","best_bid":"0.81","hash":"045cecb4fc97067f48496921b20db0ccf096e68d","price":"0.81","side":"BUY","size":"110.45"},{"asset_id":"96283536366176669581486355171583722558858323126916278856549586825357358273536","best_ask":"0.19","best_bid":"0.18","hash":"a1e56f3b5ee1f788ef065e880b5ba62b4b56559d","price":"0.19","side":"SELL","size":"110.45"}],"timestamp":"1785122012679"},"payload_hash":"aaf0867e9338a5206eeb09556a829758eb8c62c5c3d27a08898f0b111d2ff9ab","raw_frame":"{\"market\":\"0xf9d60bb033695053c4d1d8592e52171c1042f64b41a4b72e09dcc6f4852b6670\", \"price_changes\":[{\"asset_id\":\"8698449539441374295770236407991735029336433231649246775082939325523552031992\", \"price\":\"0.81\", \"size\":\"110.45\", \"side\":\"BUY\", \"hash\":\"045cecb4fc97067f48496921b20db0ccf096e68d\", \"best_bid\":\"0.81\", \"best_ask\":\"0.82\"}, {\"asset_id\":\"96283536366176669581486355171583722558858323126916278856549586825357358273536\", \"price\":\"0.19\", \"size\":\"110.45\", \"side\":\"SELL\", \"hash\":\"a1e56f3b5ee1f788ef065e880b5ba62b4b56559d\", \"best_bid\":\"0.18\", \"best_ask\":\"0.19\"}], \"timestamp\":\"1785122012679\", \"event_type\":\"price_change\"}","received_at":"2026-07-27T03:13:32.582328Z","schema_version":"clob-market-ws.price_change.v1","sequence":null,"server_hash":null,"server_timestamp":"1785122012679","session_id":"ff6d21c8283948938400a32613abec2c","source":"clob_market_ws"},"received_at":"2026-07-27T03:13:32.582328Z","record_id":"b7bdac6ed719da322a02b8c67ff5a90b4d2909c4e366a2fb5962d256dffc17bb","schema_fingerprint":"4aa3821a28b0b7c2400bc59aba4bcc0a76e971dadd19610d3ad38c768e124dc7","schema_version":"edge-lab-recorder.raw.v1","sequence":null,"source":"clob_market_ws"}
{"event_at":"2026-07-27T03:13:32.684000Z","event_fingerprint":"160eb4842be0ee25d0794693d921246ddc3da04aee36772128b512dd6574d336","payload":{"connection_id":"f95883f18d264834af91809e5f803e9f","event_at":"2026-07-27T03:13:32.684000Z","event_type":"price_change","frame_hash":"a07319e79c7ec1f4986885052026c17ab6e87cfdfe5633f04de2a1ff2ef025ae","frame_index":0,"kind":"data","monotonic_ns":223995916468416,"payload":{"event_type":"price_change","market":"0xf9d60bb033695053c4d1d8592e52171c1042f64b41a4b72e09dcc6f4852b6670","price_changes":[{"asset_id":"96283536366176669581486355171583722558858323126916278856549586825357358273536","best_ask":"0.19","best_bid":"0.18","hash":"990ca00e0c3d7aed43cadf86652584661b78e2be","price":"0.09","side":"BUY","size":"234.7"},{"asset_id":"8698449539441374295770236407991735029336433231649246775082939325523552031992","best_ask":"0.82","best_bid":"0.81","hash":"23c2e056bc75b6b03e03206d2c9a04d35e253121","price":"0.91","side":"SELL","size":"234.7"}],"timestamp":"1785122012684"},"payload_hash":"eb28dece86e0198cba891c6912df6303cd0f1bc9816c1918e0f7a2ed334144eb","raw_frame":"{\"market\":\"0xf9d60bb033695053c4d1d8592e52171c1042f64b41a4b72e09dcc6f4852b6670\", \"price_changes\":[{\"asset_id\":\"96283536366176669581486355171583722558858323126916278856549586825357358273536\", \"price\":\"0.09\", \"size\":\"234.7\", \"side\":\"BUY\", \"hash\":\"990ca00e0c3d7aed43cadf86652584661b78e2be\", \"best_bid\":\"0.18\", \"best_ask\":\"0.19\"}, {\"asset_id\":\"8698449539441374295770236407991735029336433231649246775082939325523552031992\", \"price\":\"0.91\", \"size\":\"234.7\", \"side\":\"SELL\", \"hash\":\"23c2e056bc75b6b03e03206d2c9a04d35e253121\", \"best_bid\":\"0.81\", \"best_ask\":\"0.82\"}], \"timestamp\":\"1785122012684\", \"event_type\":\"price_change\"}","received_at":"2026-07-27T03:13:32.584030Z","schema_version":"clob-market-ws.price_change.v1","sequence":null,"server_hash":null,"server_timestamp":"1785122012684","session_id":"ff6d21c8283948938400a32613abec2c","source":"clob_market_ws"},"received_at":"2026-07-27T03:13:32.584030Z","record_id":"b1e2160d1b8c771e35644d82a4f600757d16578c89c4e9e79c59c24020ccf791","schema_fingerprint":"4aa3821a28b0b7c2400bc59aba4bcc0a76e971dadd19610d3ad38c768e124dc7","schema_version":"edge-lab-recorder.raw.v1","sequence":null,"source":"clob_market_ws"}
{"event_at":"2026-07-27T03:13:32.685000Z","event_fingerprint":"74af6f3c1381ec18fe89899ac2de00777ce7b026a6e731b20fd20c56e50ad0fb","payload":{"connection_id":"f95883f18d264834af91809e5f803e9f","event_at":"2026-07-27T03:13:32.685000Z","event_type":"price_change","frame_hash":"6c24ec0d437587be398f343f327eeffbf679a9d149db2b74e5ac9eec3ae9407c","frame_index":0,"kind":"data","monotonic_ns":223995918124500,"payload":{"event_type":"price_change","market":"0xf9d60bb033695053c4d1d8592e52171c1042f64b41a4b72e09dcc6f4852b6670","price_changes":[{"asset_id":"96283536366176669581486355171583722558858323126916278856549586825357358273536","best_ask":"0.19","best_bid":"0.18","hash":"710feb1355b7765473dfe0698c250e29849f51c4","price":"0.09","side":"BUY","size":"229.1"},{"asset_id":"8698449539441374295770236407991735029336433231649246775082939325523552031992","best_ask":"0.82","best_bid":"0.81","hash":"3c5b65306997cd4f192fd9c691162c1d58b58806","price":"0.91","side":"SELL","size":"229.1"}],"timestamp":"1785122012685"},"payload_hash":"a7b13adb1be27a81274109c2690bcb82f4dfd9c8c1b7f854666d04b57488a609","raw_frame":"{\"market\":\"0xf9d60bb033695053c4d1d8592e52171c1042f64b41a4b72e09dcc6f4852b6670\", \"price_changes\":[{\"asset_id\":\"96283536366176669581486355171583722558858323126916278856549586825357358273536\", \"price\":\"0.09\", \"size\":\"229.1\", \"side\":\"BUY\", \"hash\":\"710feb1355b7765473dfe0698c250e29849f51c4\", \"best_bid\":\"0.18\", \"best_ask\":\"0.19\"}, {\"asset_id\":\"8698449539441374295770236407991735029336433231649246775082939325523552031992\", \"price\":\"0.91\", \"size\":\"229.1\", \"side\":\"SELL\", \"hash\":\"3c5b65306997cd4f192fd9c691162c1d58b58806\", \"best_bid\":\"0.81\", \"best_ask\":\"0.82\"}], \"timestamp\":\"1785122012685\", \"event_type\":\"price_change\"}","received_at":"2026-07-27T03:13:32.585686Z","schema_version":"clob-market-ws.price_change.v1","sequence":null,"server_hash":null,"server_timestamp":"1785122012685","session_id":"ff6d21c8283948938400a32613abec2c","source":"clob_market_ws"},"received_at":"2026-07-27T03:13:32.585686Z","record_id":"1834117120d67fa1318db44fdbee45bde52a6f679bb5e45121a2b6117aab5288","schema_fingerprint":"4aa3821a28b0b7c2400bc59aba4bcc0a76e971dadd19610d3ad38c768e124dc7","schema_version":"edge-lab-recorder.raw.v1","sequence":null,"source":"clob_market_ws"}
{"event_at":"2026-07-27T03:13:32.685000Z","event_fingerprint":"ddd15c00b3bae49eaaefeb62c177dd75e29b811a95d943441c69a9f95ad673a2","payload":{"connection_id":"f95883f18d264834af91809e5f803e9f","event_at":"2026-07-27T03:13:32.685000Z","event_type":"price_change","frame_hash":"06f8fa1fa9c318a3b0ce906e0011720391308697e0a9bd00050634aaedaf4809","frame_index":0,"kind":"data","monotonic_ns":223995919620375,"payload":{"event_type":"price_change","market":"0xf9d60bb033695053c4d1d8592e52171c1042f64b41a4b72e09dcc6f4852b6670","price_changes":[{"asset_id":"8698449539441374295770236407991735029336433231649246775082939325523552031992","best_ask":"0.82","best_bid":"0.81","hash":"04ad533c5ba94cc8c9e7adff539f8644463aaf98","price":"0.75","side":"BUY","size":"83"},{"asset_id":"96283536366176669581486355171583722558858323126916278856549586825357358273536","best_ask":"0.19","best_bid":"0.18","hash":"18bdb1e836caa1c76cf72d4fe1aa0424c82b52f0","price":"0.25","side":"SELL","size":"83"}],"timestamp":"1785122012685"},"payload_hash":"33ae7553cff3a04303bc15b57b74aaaf1f8d3b379cdcb277b7d70570d9787b4f","raw_frame":"{\"market\":\"0xf9d60bb033695053c4d1d8592e52171c1042f64b41a4b72e09dcc6f4852b6670\", \"price_changes\":[{\"asset_id\":\"8698449539441374295770236407991735029336433231649246775082939325523552031992\", \"price\":\"0.75\", \"size\":\"83\", \"side\":\"BUY\", \"hash\":\"04ad533c5ba94cc8c9e7adff539f8644463aaf98\", \"best_bid\":\"0.81\", \"best_ask\":\"0.82\"}, {\"asset_id\":\"96283536366176669581486355171583722558858323126916278856549586825357358273536\", \"price\":\"0.25\", \"size\":\"83\", \"side\":\"SELL\", \"hash\":\"18bdb1e836caa1c76cf72d4fe1aa0424c82b52f0\", \"best_bid\":\"0.18\", \"best_ask\":\"0.19\"}], \"timestamp\":\"1785122012685\", \"event_type\":\"price_change\"}","received_at":"2026-07-27T03:13:32.587182Z","schema_version":"clob-market-ws.price_change.v1","sequence":null,"server_hash":null,"server_timestamp":"1785122012685","session_id":"ff6d21c8283948938400a32613abec2c","source":"clob_market_ws"},"received_at":"2026-07-27T03:13:32.587182Z","record_id":"60772fe59efd694ed4a9e278fc3d5a5bb85c1ae5114e769d559471219a2a30e7","schema_fingerprint":"4aa3821a28b0b7c2400bc59aba4bcc0a76e971dadd19610d3ad38c768e124dc7","schema_version":"edge-lab-recorder.raw.v1","sequence":null,"source":"clob_market_ws"}
{"event_at":"2026-07-27T03:13:32.686000Z","event_fingerprint":"8152cf3b3158ccf15f17ea4c69d7500bee004e882c98539fcc5cea32523a8f91","payload":{"connection_id":"f95883f18d264834af91809e5f803e9f","event_at":"2026-07-27T03:13:32.686000Z","event_type":"price_change","frame_hash":"9951712555d51fccf56734fef859c1ba2bfa05757697985e9ba5a094159fdbcb","frame_index":0,"kind":"data","monotonic_ns":223995921116625,"payload":{"event_type":"price_change","market":"0xf9d60bb033695053c4d1d8592e52171c1042f64b41a4b72e09dcc6f4852b6670","price_changes":[{"asset_id":"8698449539441374295770236407991735029336433231649246775082939325523552031992","best_ask":"0.82","best_bid":"0.81","hash":"eba385bac3c23729957a0d15ea335466f3173320","price":"0.81","side":"BUY","size":"35.45"},{"asset_id":"96283536366176669581486355171583722558858323126916278856549586825357358273536","best_ask":"0.19","best_bid":"0.18","hash":"77abe89364f581b5861748d7710031fd13380031","price":"0.19","side":"SELL","size":"35.45"}],"timestamp":"1785122012686"},"payload_hash":"aab73f6a9669c4f2ebcb9b2d35b2c54ae2472fc42705eafd426121d49ea82517","raw_frame":"{\"market\":\"0xf9d60bb033695053c4d1d8592e52171c1042f64b41a4b72e09dcc6f4852b6670\", \"price_changes\":[{\"asset_id\":\"8698449539441374295770236407991735029336433231649246775082939325523552031992\", \"price\":\"0.81\", \"size\":\"35.45\", \"side\":\"BUY\", \"hash\":\"eba385bac3c23729957a0d15ea335466f3173320\", \"best_bid\":\"0.81\", \"best_ask\":\"0.82\"}, {\"asset_id\":\"96283536366176669581486355171583722558858323126916278856549586825357358273536\", \"price\":\"0.19\", \"size\":\"35.45\", \"side\":\"SELL\", \"hash\":\"77abe89364f581b5861748d7710031fd13380031\", \"best_bid\":\"0.18\", \"best_ask\":\"0.19\"}], \"timestamp\":\"1785122012686\", \"event_type\":\"price_change\"}","received_at":"2026-07-27T03:13:32.588676Z","schema_version":"clob-market-ws.price_change.v1","sequence":null,"server_hash":null,"server_timestamp":"1785122012686","session_id":"ff6d21c8283948938400a32613abec2c","source":"clob_market_ws"},"received_at":"2026-07-27T03:13:32.588676Z","record_id":"b83c911db35d74b05579957630be7a04415de60ec2c97f7d195d8d65702442b2","schema_fingerprint":"4aa3821a28b0b7c2400bc59aba4bcc0a76e971dadd19610d3ad38c768e124dc7","schema_version":"edge-lab-recorder.raw.v1","sequence":null,"source":"clob_market_ws"}
{"event_at":"2026-07-27T03:13:32.686000Z","event_fingerprint":"992be05147f462f6eeb74066c782d7f2ae06b3b44eaac2812b87574aa487be9e","payload":{"connection_id":"f95883f18d264834af91809e5f803e9f","event_at":"2026-07-27T03:13:32.686000Z","event_type":"price_change","frame_hash":"282ac2c4488f1b817cf34800f601e4f72dd6fe44379960fb975ac3ab6784ba7c","frame_index":0,"kind":"data","monotonic_ns":223995922636291,"payload":{"event_type":"price_change","market":"0xf9d60bb033695053c4d1d8592e52171c1042f64b41a4b72e09dcc6f4852b6670","price_changes":[{"asset_id":"8698449539441374295770236407991735029336433231649246775082939325523552031992","best_ask":"0.82","best_bid":"0.81","hash":"8b31c405ef97d8185a96c70dca62de341e37dc26","price":"0.81","side":"BUY","size":"28"},{"asset_id":"96283536366176669581486355171583722558858323126916278856549586825357358273536","best_ask":"0.19","best_bid":"0.18","hash":"5e5411cd8f151abc3179d088ca3f7d39340ba076","price":"0.19","side":"SELL","size":"28"}],"timestamp":"1785122012686"},"payload_hash":"f95347779f096674b1a88957709df231415668583a8a126f77f947589d5ac571","raw_frame":"{\"market\":\"0xf9d60bb033695053c4d1d8592e52171c1042f64b41a4b72e09dcc6f4852b6670\", \"price_changes\":[{\"asset_id\":\"8698449539441374295770236407991735029336433231649246775082939325523552031992\", \"price\":\"0.81\", \"size\":\"28\", \"side\":\"BUY\", \"hash\":\"8b31c405ef97d8185a96c70dca62de341e37dc26\", \"best_bid\":\"0.81\", \"best_ask\":\"0.82\"}, {\"asset_id\":\"96283536366176669581486355171583722558858323126916278856549586825357358273536\", \"price\":\"0.19\", \"size\":\"28\", \"side\":\"SELL\", \"hash\":\"5e5411cd8f151abc3179d088ca3f7d39340ba076\", \"best_bid\":\"0.18\", \"best_ask\":\"0.19\"}], \"timestamp\":\"1785122012686\", \"event_type\":\"price_change\"}","received_at":"2026-07-27T03:13:32.590196Z","schema_version":"clob-market-ws.price_change.v1","sequence":null,"server_hash":null,"server_timestamp":"1785122012686","session_id":"ff6d21c8283948938400a32613abec2c","source":"clob_market_ws"},"received_at":"2026-07-27T03:13:32.590196Z","record_id":"51cf905d57413447bcb910b7e46a58678c6462db2521ecd513faa9d6c69742f8","schema_fingerprint":"4aa3821a28b0b7c2400bc59aba4bcc0a76e971dadd19610d3ad38c768e124dc7","schema_version":"edge-lab-recorder.raw.v1","sequence":null,"source":"clob_market_ws"}
{"event_at":"2026-07-27T03:13:32.692000Z","event_fingerprint":"b02adbfa59c913a1be21a71321fe0eb5f6809d73c9288ed3051d433a9134c111","payload":{"connection_id":"f95883f18d264834af91809e5f803e9f","event_at":"2026-07-27T03:13:32.692000Z","event_type":"price_change","frame_hash":"cc66b0894e5283f02e6be8f0d4e64dad6080984a33ac8a8d6abcab28236ba59b","frame_index":0,"kind":"data","monotonic_ns":223995924228583,"payload":{"event_type":"price_change","market":"0xf9d60bb033695053c4d1d8592e52171c1042f64b41a4b72e09dcc6f4852b6670","price_changes":[{"asset_id":"96283536366176669581486355171583722558858323126916278856549586825357358273536","best_ask":"0.19","best_bid":"0.18","hash":"1ea99dd70eff1042a1b7dccf513d0aaf0132b30a","price":"0.24","side":"SELL","size":"176.92"},{"asset_id":"8698449539441374295770236407991735029336433231649246775082939325523552031992","best_ask":"0.82","best_bid":"0.81","hash":"cd6d1ac7495a4bb62ce6ec0865446cc29bdd46ec","price":"0.76","side":"BUY","size":"176.92"}],"timestamp":"1785122012692"},"payload_hash":"abb10e44fc64fad8534edae67c5c58d1163e85b8ed60719cca20265dd0bf80d2","raw_frame":"{\"market\":\"0xf9d60bb033695053c4d1d8592e52171c1042f64b41a4b72e09dcc6f4852b6670\", \"price_changes\":[{\"asset_id\":\"96283536366176669581486355171583722558858323126916278856549586825357358273536\", \"price\":\"0.24\", \"size\":\"176.92\", \"side\":\"SELL\", \"hash\":\"1ea99dd70eff1042a1b7dccf513d0aaf0132b30a\", \"best_bid\":\"0.18\", \"best_ask\":\"0.19\"}, {\"asset_id\":\"8698449539441374295770236407991735029336433231649246775082939325523552031992\", \"price\":\"0.76\", \"size\":\"176.92\", \"side\":\"BUY\", \"hash\":\"cd6d1ac7495a4bb62ce6ec0865446cc29bdd46ec\", \"best_bid\":\"0.81\", \"best_ask\":\"0.82\"}], \"timestamp\":\"1785122012692\", \"event_type\":\"price_change\"}","received_at":"2026-07-27T03:13:32.591790Z","schema_version":"clob-market-ws.price_change.v1","sequence":null,"server_hash":null,"server_timestamp":"1785122012692","session_id":"ff6d21c8283948938400a32613abec2c","source":"clob_market_ws"},"received_at":"2026-07-27T03:13:32.591790Z","record_id":"b47aea96f78b33b68ddc4356db5360cc9e7c72470c92413ee756747e626398e0","schema_fingerprint":"4aa3821a28b0b7c2400bc59aba4bcc0a76e971dadd19610d3ad38c768e124dc7","schema_version":"edge-lab-recorder.raw.v1","sequence":null,"source":"clob_market_ws"}
{"event_at":"2026-07-27T03:13:32.694000Z","event_fingerprint":"012bb4efce857926a1a0c87a46944f6418a0d2b7fcdd73e246564c86072f492e","payload":{"connection_id":"f95883f18d264834af91809e5f803e9f","event_at":"2026-07-27T03:13:32.694000Z","event_type":"price_change","frame_hash":"0a4b395230cd8f4f46f5326b9f83683d9924cc4161e231e2708dc29118c3b7ce","frame_index":0,"kind":"data","monotonic_ns":223995925984125,"payload":{"event_type":"price_change","market":"0xf9d60bb033695053c4d1d8592e52171c1042f64b41a4b72e09dcc6f4852b6670","price_changes":[{"asset_id":"96283536366176669581486355171583722558858323126916278856549586825357358273536","best_ask":"0.19","best_bid":"0.18","hash":"64da9e48cb52a0b17dfcfad481c0070421d06385","price":"0.18","side":"BUY","size":"30.87"},{"asset_id":"8698449539441374295770236407991735029336433231649246775082939325523552031992","best_ask":"0.82","best_bid":"0.81","hash":"5314be5a4abff5fab3c884dc939b6656a5a9d959","price":"0.82","side":"SELL","size":"30.87"}],"timestamp":"1785122012694"},"payload_hash":"14315962ca3a2f56d7f040cf2eff34c381c702c77fcb1903f25edaae6c842ce4","raw_frame":"{\"market\":\"0xf9d60bb033695053c4d1d8592e52171c1042f64b41a4b72e09dcc6f4852b6670\", \"price_changes\":[{\"asset_id\":\"96283536366176669581486355171583722558858323126916278856549586825357358273536\", \"price\":\"0.18\", \"size\":\"30.87\", \"side\":\"BUY\", \"hash\":\"64da9e48cb52a0b17dfcfad481c0070421d06385\", \"best_bid\":\"0.18\", \"best_ask\":\"0.19\"}, {\"asset_id\":\"8698449539441374295770236407991735029336433231649246775082939325523552031992\", \"price\":\"0.82\", \"size\":\"30.87\", \"side\":\"SELL\", \"hash\":\"5314be5a4abff5fab3c884dc939b6656a5a9d959\", \"best_bid\":\"0.81\", \"best_ask\":\"0.82\"}], \"timestamp\":\"1785122012694\", \"event_type\":\"price_change\"}","received_at":"2026-07-27T03:13:32.593544Z","schema_version":"clob-market-ws.price_change.v1","sequence":null,"server_hash":null,"server_timestamp":"1785122012694","session_id":"ff6d21c8283948938400a32613abec2c","source":"clob_market_ws"},"received_at":"2026-07-27T03:13:32.593544Z","record_id":"a45e9c824534fa5acec3a583e9af3564ec73591a0a5bea511f3e20537f3daf73","schema_fingerprint":"4aa3821a28b0b7c2400bc59aba4bcc0a76e971dadd19610d3ad38c768e124dc7","schema_version":"edge-lab-recorder.raw.v1","sequence":null,"source":"clob_market_ws"}
{"event_at":"2026-07-27T03:13:32.698000Z","event_fingerprint":"f8f60737c3c3009f7e85d901f7b8326afd2b7f222eb7747b101a6e9b530d8588","payload":{"connection_id":"f95883f18d264834af91809e5f803e9f","event_at":"2026-07-27T03:13:32.698000Z","event_type":"price_change","frame_hash":"05f55253b1084cece8492d9a79960343960d8aacd3c670ab0e1efece67107dd5","frame_index":0,"kind":"data","monotonic_ns":223995930150333,"payload":{"event_type":"price_change","market":"0xf9d60bb033695053c4d1d8592e52171c1042f64b41a4b72e09dcc6f4852b6670","price_changes":[{"asset_id":"96283536366176669581486355171583722558858323126916278856549586825357358273536","best_ask":"0.19","best_bid":"0.18","hash":"4c5a606b470444b0455cda1fdaea21cf253f821b","price":"0.12","side":"BUY","size":"151.8"},{"asset_id":"8698449539441374295770236407991735029336433231649246775082939325523552031992","best_ask":"0.82","best_bid":"0.81","hash":"30e428e56cff89778e2492002fb496e7c0ecfba1","price":"0.88","side":"SELL","size":"151.8"}],"timestamp":"1785122012698"},"payload_hash":"a63b77888cd781139453b09449ad1c3ff34e39cfb7537dba66af46dc300b0f0f","raw_frame":"{\"market\":\"0xf9d60bb033695053c4d1d8592e52171c1042f64b41a4b72e09dcc6f4852b6670\", \"price_changes\":[{\"asset_id\":\"96283536366176669581486355171583722558858323126916278856549586825357358273536\", \"price\":\"0.12\", \"size\":\"151.8\", \"side\":\"BUY\", \"hash\":\"4c5a606b470444b0455cda1fdaea21cf253f821b\", \"best_bid\":\"0.18\", \"best_ask\":\"0.19\"}, {\"asset_id\":\"8698449539441374295770236407991735029336433231649246775082939325523552031992\", \"price\":\"0.88\", \"size\":\"151.8\", \"side\":\"SELL\", \"hash\":\"30e428e56cff89778e2492002fb496e7c0ecfba1\", \"best_bid\":\"0.81\", \"best_ask\":\"0.82\"}], \"timestamp\":\"1785122012698\", \"event_type\":\"price_change\"}","received_at":"2026-07-27T03:13:32.597709Z","schema_version":"clob-market-ws.price_change.v1","sequence":null,"server_hash":null,"server_timestamp":"1785122012698","session_id":"ff6d21c8283948938400a32613abec2c","source":"clob_market_ws"},"received_at":"2026-07-27T03:13:32.597709Z","record_id":"b568b9b32f2c48783e46108d4c0321421c9c3b5d2e288e11ed2f343fb0358531","schema_fingerprint":"4aa3821a28b0b7c2400bc59aba4bcc0a76e971dadd19610d3ad38c768e124dc7","schema_version":"edge-lab-recorder.raw.v1","sequence":null,"source":"clob_market_ws"}
{"event_at":"2026-07-27T03:13:32.699000Z","event_fingerprint":"b109945b51fcf24f203e1aa60cf7bd57caf7f9f4a2d3a2df13cad214c72b930c","payload":{"connection_id":"f95883f18d264834af91809e5f803e9f","event_at":"2026-07-27T03:13:32.699000Z","event_type":"price_change","frame_hash":"cc87aac6d21e1df7a8a3261716563c748c1a1c6db11679b20839828ed997a4e5","frame_index":0,"kind":"data","monotonic_ns":223995931926833,"payload":{"event_type":"price_change","market":"0xf9d60bb033695053c4d1d8592e52171c1042f64b41a4b72e09dcc6f4852b6670","price_changes":[{"asset_id":"8698449539441374295770236407991735029336433231649246775082939325523552031992","best_ask":"0.82","best_bid":"0.81","hash":"8757b989e949b0206ee21685eb210d4384e8dee3","price":"0.76","side":"BUY","size":"189.92"},{"asset_id":"96283536366176669581486355171583722558858323126916278856549586825357358273536","best_ask":"0.19","best_bid":"0.18","hash":"62e586866cd189a0f21563e154eab81a3e9202a4","price":"0.24","side":"SELL","size":"189.92"}],"timestamp":"1785122012699"},"payload_hash":"b2b9218b910c5f8dc10a5f477d4ed97971a86153ffbce46ce133bab24765c4ac","raw_frame":"{\"market\":\"0xf9d60bb033695053c4d1d8592e52171c1042f64b41a4b72e09dcc6f4852b6670\", \"price_changes\":[{\"asset_id\":\"8698449539441374295770236407991735029336433231649246775082939325523552031992\", \"price\":\"0.76\", \"size\":\"189.92\", \"side\":\"BUY\", \"hash\":\"8757b989e949b0206ee21685eb210d4384e8dee3\", \"best_bid\":\"0.81\", \"best_ask\":\"0.82\"}, {\"asset_id\":\"96283536366176669581486355171583722558858323126916278856549586825357358273536\", \"price\":\"0.24\", \"size\":\"189.92\", \"side\":\"SELL\", \"hash\":\"62e586866cd189a0f21563e154eab81a3e9202a4\", \"best_bid\":\"0.18\", \"best_ask\":\"0.19\"}], \"timestamp\":\"1785122012699\", \"event_type\":\"price_change\"}","received_at":"2026-07-27T03:13:32.599487Z","schema_version":"clob-market-ws.price_change.v1","sequence":null,"server_hash":null,"server_timestamp":"1785122012699","session_id":"ff6d21c8283948938400a32613abec2c","source":"clob_market_ws"},"received_at":"2026-07-27T03:13:32.599487Z","record_id":"9206c91aa691ce5fea6d9dcbd41564fb9a7370290d5ae479dec8e61563b0c483","schema_fingerprint":"4aa3821a28b0b7c2400bc59aba4bcc0a76e971dadd19610d3ad38c768e124dc7","schema_version":"edge-lab-recorder.raw.v1","sequence":null,"source":"clob_market_ws"}
{"event_at":"2026-07-27T03:13:32.712000Z","event_fingerprint":"98678ceea33d46afb71bc82542e94a3f8769ea542d648a1acf6b5ced03b444dd","payload":{"connection_id":"f95883f18d264834af91809e5f803e9f","event_at":"2026-07-27T03:13:32.712000Z","event_type":"price_change","frame_hash":"e28c57038564a979b13be13395def21b2898a43e97ec4656c944b646d70abba0","frame_index":0,"kind":"data","monotonic_ns":223995944933875,"payload":{"event_type":"price_change","market":"0xf9d60bb033695053c4d1d8592e52171c1042f64b41a4b72e09dcc6f4852b6670","price_changes":[{"asset_id":"8698449539441374295770236407991735029336433231649246775082939325523552031992","best_ask":"0.82","best_bid":"0.81","hash":"3275992606b25fcada151a25ae60f4969e9747ef","price":"0.74","side":"BUY","size":"120.04"},{"asset_id":"96283536366176669581486355171583722558858323126916278856549586825357358273536","best_ask":"0.19","best_bid":"0.18","hash":"5413ec5dc2f87b7b0592ede40ffabf05c98ccd15","price":"0.26","side":"SELL","size":"120.04"}],"timestamp":"1785122012712"},"payload_hash":"d8b38b37c65581652741b2dcacacbbd4abfd7e689ac62430190f31f85c232ae2","raw_frame":"{\"market\":\"0xf9d60bb033695053c4d1d8592e52171c1042f64b41a4b72e09dcc6f4852b6670\", \"price_changes\":[{\"asset_id\":\"8698449539441374295770236407991735029336433231649246775082939325523552031992\", \"price\":\"0.74\", \"size\":\"120.04\", \"side\":\"BUY\", \"hash\":\"3275992606b25fcada151a25ae60f4969e9747ef\", \"best_bid\":\"0.81\", \"best_ask\":\"0.82\"}, {\"asset_id\":\"96283536366176669581486355171583722558858323126916278856549586825357358273536\", \"price\":\"0.26\", \"size\":\"120.04\", \"side\":\"SELL\", \"hash\":\"5413ec5dc2f87b7b0592ede40ffabf05c98ccd15\", \"best_bid\":\"0.18\", \"best_ask\":\"0.19\"}], \"timestamp\":\"1785122012712\", \"event_type\":\"price_change\"}","received_at":"2026-07-27T03:13:32.612491Z","schema_version":"clob-market-ws.price_change.v1","sequence":null,"server_hash":null,"server_timestamp":"1785122012712","session_id":"ff6d21c8283948938400a32613abec2c","source":"clob_market_ws"},"received_at":"2026-07-27T03:13:32.612491Z","record_id":"3f5f1ab50cffc763eae300223f8c845222d36d8d84865caf024d76d42f385670","schema_fingerprint":"4aa3821a28b0b7c2400bc59aba4bcc0a76e971dadd19610d3ad38c768e124dc7","schema_version":"edge-lab-recorder.raw.v1","sequence":null,"source":"clob_market_ws"}
{"event_at":"2026-07-27T03:13:32.714000Z","event_fingerprint":"202542ee5ea498340979c93d32d9ca78c43785f73a19b53878d84070af2fc79c","payload":{"connection_id":"f95883f18d264834af91809e5f803e9f","event_at":"2026-07-27T03:13:32.714000Z","event_type":"price_change","frame_hash":"64dc6046d8a35a36a96b6971309a36fff1097001f77fbb56f00b14893d6b7f52","frame_index":0,"kind":"data","monotonic_ns":223995947191750,"payload":{"event_type":"price_change","market":"0xf9d60bb033695053c4d1d8592e52171c1042f64b41a4b72e09dcc6f4852b6670","price_changes":[{"asset_id":"96283536366176669581486355171583722558858323126916278856549586825357358273536","best_ask":"0.19","best_bid":"0.18","hash":"5b4c484351a09c00ac9f751d3a5a7e4d8e3cf5bf","price":"0.09","side":"BUY","size":"236.16"},{"asset_id":"8698449539441374295770236407991735029336433231649246775082939325523552031992","best_ask":"0.82","best_bid":"0.81","hash":"d899bfef9c5428a6dee3780053da5cee8f95c081","price":"0.91","side":"SELL","size":"236.16"}],"timestamp":"1785122012714"},"payload_hash":"3e0d3eb09d8ef9828b202c8f32c029f4c3e62e3c99f4d53bf5244461921b74a3","raw_frame":"{\"market\":\"0xf9d60bb033695053c4d1d8592e52171c1042f64b41a4b72e09dcc6f4852b6670\", \"price_changes\":[{\"asset_id\":\"96283536366176669581486355171583722558858323126916278856549586825357358273536\", \"price\":\"0.09\", \"size\":\"236.16\", \"side\":\"BUY\", \"hash\":\"5b4c484351a09c00ac9f751d3a5a7e4d8e3cf5bf\", \"best_bid\":\"0.18\", \"best_ask\":\"0.19\"}, {\"asset_id\":\"8698449539441374295770236407991735029336433231649246775082939325523552031992\", \"price\":\"0.91\", \"size\":\"236.16\", \"side\":\"SELL\", \"hash\":\"d899bfef9c5428a6dee3780053da5cee8f95c081\", \"best_bid\":\"0.81\", \"best_ask\":\"0.82\"}], \"timestamp\":\"1785122012714\", \"event_type\":\"price_change\"}","received_at":"2026-07-27T03:13:32.614751Z","schema_version":"clob-market-ws.price_change.v1","sequence":null,"server_hash":null,"server_timestamp":"1785122012714","session_id":"ff6d21c8283948938400a32613abec2c","source":"clob_market_ws"},"received_at":"2026-07-27T03:13:32.614751Z","record_id":"809f3110c75df2f75bf65512e36398741c49cf2784e3f0789c65767391dbfcb3","schema_fingerprint":"4aa3821a28b0b7c2400bc59aba4bcc0a76e971dadd19610d3ad38c768e124dc7","schema_version":"edge-lab-recorder.raw.v1","sequence":null,"source":"clob_market_ws"}
{"event_at":"2026-07-27T03:13:32.716000Z","event_fingerprint":"edb1a3c63aaa3b4c5d6fb10339385a43c7500c9de28162439001d1e3cd6d9031","payload":{"connection_id":"f95883f18d264834af91809e5f803e9f","event_at":"2026-07-27T03:13:32.716000Z","event_type":"price_change","frame_hash":"9b57c42e02d606695eaa075539672d67a9d66d645761e3a34b5e0feeafb73c5a","frame_index":0,"kind":"data","monotonic_ns":223995949852541,"payload":{"event_type":"price_change","market":"0xf9d60bb033695053c4d1d8592e52171c1042f64b41a4b72e09dcc6f4852b6670","price_changes":[{"asset_id":"8698449539441374295770236407991735029336433231649246775082939325523552031992","best_ask":"0.82","best_bid":"0.81","hash":"2f36f565fb650078176911d1f35c214a3b6471fe","price":"0.01","side":"BUY","size":"8027.52"},{"asset_id":"96283536366176669581486355171583722558858323126916278856549586825357358273536","best_ask":"0.19","best_bid":"0.18","hash":"13fdf26aa996ab20fa100c823445e9827662e475","price":"0.99","side":"SELL","size":"8027.52"}],"timestamp":"1785122012716"},"payload_hash":"a3fcc782d07af3766829ce4738aae069ae7defd85069eb7547a6e6576de446e2","raw_frame":"{\"market\":\"0xf9d60bb033695053c4d1d8592e52171c1042f64b41a4b72e09dcc6f4852b6670\", \"price_changes\":[{\"asset_id\":\"8698449539441374295770236407991735029336433231649246775082939325523552031992\", \"price\":\"0.01\", \"size\":\"8027.52\", \"side\":\"BUY\", \"hash\":\"2f36f565fb650078176911d1f35c214a3b6471fe\", \"best_bid\":\"0.81\", \"best_ask\":\"0.82\"}, {\"asset_id\":\"96283536366176669581486355171583722558858323126916278856549586825357358273536\", \"price\":\"0.99\", \"size\":\"8027.52\", \"side\":\"SELL\", \"hash\":\"13fdf26aa996ab20fa100c823445e9827662e475\", \"best_bid\":\"0.18\", \"best_ask\":\"0.19\"}], \"timestamp\":\"1785122012716\", \"event_type\":\"price_change\"}","received_at":"2026-07-27T03:13:32.617410Z","schema_version":"clob-market-ws.price_change.v1","sequence":null,"server_hash":null,"server_timestamp":"1785122012716","session_id":"ff6d21c8283948938400a32613abec2c","source":"clob_market_ws"},"received_at":"2026-07-27T03:13:32.617410Z","record_id":"e4614f1794389111c7a0e305fe56c404578ffb6aef4cd4ca43b16c6695f3905c","schema_fingerprint":"4aa3821a28b0b7c2400bc59aba4bcc0a76e971dadd19610d3ad38c768e124dc7","schema_version":"edge-lab-recorder.raw.v1","sequence":null,"source":"clob_market_ws"}
{"event_at":"2026-07-27T03:13:32.717000Z","event_fingerprint":"2817582b3188ecf1a014ea2546200c6c89b3ce5d466ad592d55a1c44770bcfb0","payload":{"connection_id":"f95883f18d264834af91809e5f803e9f","event_at":"2026-07-27T03:13:32.717000Z","event_type":"price_change","frame_hash":"2e47780d290f6379d4073060826939737e00225315a4a14e4704988070f9aa53","frame_index":0,"kind":"data","monotonic_ns":223995951458083,"payload":{"event_type":"price_change","market":"0xf9d60bb033695053c4d1d8592e52171c1042f64b41a4b72e09dcc6f4852b6670","price_changes":[{"asset_id":"8698449539441374295770236407991735029336433231649246775082939325523552031992","best_ask":"0.82","best_bid":"0.81","hash":"1dad2afd158f84e28dad5b938b95210f2a6ee14d","price":"0.81","side":"BUY","size":"103"},{"asset_id":"96283536366176669581486355171583722558858323126916278856549586825357358273536","best_ask":"0.19","best_bid":"0.18","hash":"5e61b7dd2e2bdcc75d7b51ad5ee132c181ddb23b","price":"0.19","side":"SELL","size":"103"}],"timestamp":"1785122012717"},"payload_hash":"2a76b590a04aaceb0b825b267eef2f7c0ce2f07cd47521cabd0dcc629fcea84a","raw_frame":"{\"market\":\"0xf9d60bb033695053c4d1d8592e52171c1042f64b41a4b72e09dcc6f4852b6670\", \"price_changes\":[{\"asset_id\":\"8698449539441374295770236407991735029336433231649246775082939325523552031992\", \"price\":\"0.81\", \"size\":\"103\", \"side\":\"BUY\", \"hash\":\"1dad2afd158f84e28dad5b938b95210f2a6ee14d\", \"best_bid\":\"0.81\", \"best_ask\":\"0.82\"}, {\"asset_id\":\"96283536366176669581486355171583722558858323126916278856549586825357358273536\", \"price\":\"0.19\", \"size\":\"103\", \"side\":\"SELL\", \"hash\":\"5e61b7dd2e2bdcc75d7b51ad5ee132c181ddb23b\", \"best_bid\":\"0.18\", \"best_ask\":\"0.19\"}], \"timestamp\":\"1785122012717\", \"event_type\":\"price_change\"}","received_at":"2026-07-27T03:13:32.619017Z","schema_version":"clob-market-ws.price_change.v1","sequence":null,"server_hash":null,"server_timestamp":"1785122012717","session_id":"ff6d21c8283948938400a32613abec2c","source":"clob_market_ws"},"received_at":"2026-07-27T03:13:32.619017Z","record_id":"f1d4e2b23570bf4912c8809058a21f66bb5632e3427e7aaf78577bd98b4e29ba","schema_fingerprint":"4aa3821a28b0b7c2400bc59aba4bcc0a76e971dadd19610d3ad38c768e124dc7","schema_version":"edge-lab-recorder.raw.v1","sequence":null,"source":"clob_market_ws"}
{"event_at":"2026-07-27T03:13:32.726000Z","event_fingerprint":"45e84a58c52c7353a597117d3b315362e8c64d0517c8e552df756c3149a6acc8","payload":{"connection_id":"f95883f18d264834af91809e5f803e9f","event_at":"2026-07-27T03:13:32.726000Z","event_type":"price_change","frame_hash":"438cf55a9f0983f55cae550fc1938a3cf2c036ad3ee5416653d73cb7a6a2044c","frame_index":0,"kind":"data","monotonic_ns":223995958053541,"payload":{"event_type":"price_change","market":"0xf9d60bb033695053c4d1d8592e52171c1042f64b41a4b72e09dcc6f4852b6670","price_changes":[{"asset_id":"96283536366176669581486355171583722558858323126916278856549586825357358273536","best_ask":"0.19","best_bid":"0.18","hash":"c30a20f1fefd27d1771b958454dcdc627ed961b9","price":"0.14","side":"BUY","size":"30"},{"asset_id":"8698449539441374295770236407991735029336433231649246775082939325523552031992","best_ask":"0.82","best_bid":"0.81","hash":"1558e9583448ae3ae2d886280cd60459b1708120","price":"0.86","side":"SELL","size":"30"}],"timestamp":"1785122012726"},"payload_hash":"fb4d7c98fedd9e518871837ea2bc5305a8444fb7f7411c7d52f4a6fe44c513c3","raw_frame":"{\"market\":\"0xf9d60bb033695053c4d1d8592e52171c1042f64b41a4b72e09dcc6f4852b6670\", \"price_changes\":[{\"asset_id\":\"96283536366176669581486355171583722558858323126916278856549586825357358273536\", \"price\":\"0.14\", \"size\":\"30\", \"side\":\"BUY\", \"hash\":\"c30a20f1fefd27d1771b958454dcdc627ed961b9\", \"best_bid\":\"0.18\", \"best_ask\":\"0.19\"}, {\"asset_id\":\"8698449539441374295770236407991735029336433231649246775082939325523552031992\", \"price\":\"0.86\", \"size\":\"30\", \"side\":\"SELL\", \"hash\":\"1558e9583448ae3ae2d886280cd60459b1708120\", \"best_bid\":\"0.81\", \"best_ask\":\"0.82\"}], \"timestamp\":\"1785122012726\", \"event_type\":\"price_change\"}","received_at":"2026-07-27T03:13:32.625612Z","schema_version":"clob-market-ws.price_change.v1","sequence":null,"server_hash":null,"server_timestamp":"1785122012726","session_id":"ff6d21c8283948938400a32613abec2c","source":"clob_market_ws"},"received_at":"2026-07-27T03:13:32.625612Z","record_id":"a2922cdf306c93071da1e35bb885faeb018ca53f5185d659b7b200c13bceac4d","schema_fingerprint":"4aa3821a28b0b7c2400bc59aba4bcc0a76e971dadd19610d3ad38c768e124dc7","schema_version":"edge-lab-recorder.raw.v1","sequence":null,"source":"clob_market_ws"}
{"event_at":"2026-07-27T03:13:32.739000Z","event_fingerprint":"1493b1ade02ce901f15ad12e2ae4a528146bc365929ab13bcda701e31ed3a09c","payload":{"connection_id":"f95883f18d264834af91809e5f803e9f","event_at":"2026-07-27T03:13:32.739000Z","event_type":"price_change","frame_hash":"e86bcce9371513d8a0991f1bc0dd1341fbf16e9436190fb3f37ce4f9425c1808","frame_index":0,"kind":"data","monotonic_ns":223995972748791,"payload":{"event_type":"price_change","market":"0xf9d60bb033695053c4d1d8592e52171c1042f64b41a4b72e09dcc6f4852b6670","price_changes":[{"asset_id":"96283536366176669581486355171583722558858323126916278856549586825357358273536","best_ask":"0.19","best_bid":"0.18","hash":"6459d6b8e04c37dc368346eac2e26a080c9763c4","price":"0.12","side":"BUY","size":"126.8"},{"asset_id":"8698449539441374295770236407991735029336433231649246775082939325523552031992","best_ask":"0.82","best_bid":"0.81","hash":"85b2ab0ab817132f4715f3c06e8af6183c0e0607","price":"0.88","side":"SELL","size":"126.8"}],"timestamp":"1785122012739"},"payload_hash":"f599022dfb002498378b75a131db1016860b44e3bf749b83ef449a50c0d3e815","raw_frame":"{\"market\":\"0xf9d60bb033695053c4d1d8592e52171c1042f64b41a4b72e09dcc6f4852b6670\", \"price_changes\":[{\"asset_id\":\"96283536366176669581486355171583722558858323126916278856549586825357358273536\", \"price\":\"0.12\", \"size\":\"126.8\", \"side\":\"BUY\", \"hash\":\"6459d6b8e04c37dc368346eac2e26a080c9763c4\", \"best_bid\":\"0.18\", \"best_ask\":\"0.19\"}, {\"asset_id\":\"8698449539441374295770236407991735029336433231649246775082939325523552031992\", \"price\":\"0.88\", \"size\":\"126.8\", \"side\":\"SELL\", \"hash\":\"85b2ab0ab817132f4715f3c06e8af6183c0e0607\", \"best_bid\":\"0.81\", \"best_ask\":\"0.82\"}], \"timestamp\":\"1785122012739\", \"event_type\":\"price_change\"}","received_at":"2026-07-27T03:13:32.640304Z","schema_version":"clob-market-ws.price_change.v1","sequence":null,"server_hash":null,"server_timestamp":"1785122012739","session_id":"ff6d21c8283948938400a32613abec2c","source":"clob_market_ws"},"received_at":"2026-07-27T03:13:32.640304Z","record_id":"2ce3dac1f80eb1f5ab138910cedd206536c3893f7c5fe2ae7524ae39af2125bc","schema_fingerprint":"4aa3821a28b0b7c2400bc59aba4bcc0a76e971dadd19610d3ad38c768e124dc7","schema_version":"edge-lab-recorder.raw.v1","sequence":null,"source":"clob_market_ws"}
{"event_at":"2026-07-27T03:13:32.744000Z","event_fingerprint":"7d3c0c9115ebc377ba477d076e1b99e919a25d3d51b99b38eec84e5c9353478a","payload":{"connection_id":"f95883f18d264834af91809e5f803e9f","event_at":"2026-07-27T03:13:32.744000Z","event_type":"price_change","frame_hash":"82f3506826e854e2272da9b80f97c0f3126eac4c371f9c01e133266e0b6afd92","frame_index":0,"kind":"data","monotonic_ns":223995975767083,"payload":{"event_type":"price_change","market":"0xf9d60bb033695053c4d1d8592e52171c1042f64b41a4b72e09dcc6f4852b6670","price_changes":[{"asset_id":"8698449539441374295770236407991735029336433231649246775082939325523552031992","best_ask":"0.82","best_bid":"0.81","hash":"efacab35a7797cc8843d5a0f7e7c02a11b2c218a","price":"0.01","side":"BUY","size":"8022.52"},{"asset_id":"96283536366176669581486355171583722558858323126916278856549586825357358273536","best_ask":"0.19","best_bid":"0.18","hash":"1c7a6c55528477f3fbc0d6521c6a621d1229dee4","price":"0.99","side":"SELL","size":"8022.52"}],"timestamp":"1785122012744"},"payload_hash":"090531ee18ed23ccd4e4994abdc5168d6d18671f53b6d3c6d82735a1ffe6f5c8","raw_frame":"{\"market\":\"0xf9d60bb033695053c4d1d8592e52171c1042f64b41a4b72e09dcc6f4852b6670\", \"price_changes\":[{\"asset_id\":\"8698449539441374295770236407991735029336433231649246775082939325523552031992\", \"price\":\"0.01\", \"size\":\"8022.52\", \"side\":\"BUY\", \"hash\":\"efacab35a7797cc8843d5a0f7e7c02a11b2c218a\", \"best_bid\":\"0.81\", \"best_ask\":\"0.82\"}, {\"asset_id\":\"96283536366176669581486355171583722558858323126916278856549586825357358273536\", \"price\":\"0.99\", \"size\":\"8022.52\", \"side\":\"SELL\", \"hash\":\"1c7a6c55528477f3fbc0d6521c6a621d1229dee4\", \"best_bid\":\"0.18\", \"best_ask\":\"0.19\"}], \"timestamp\":\"1785122012744\", \"event_type\":\"price_change\"}","received_at":"2026-07-27T03:13:32.643324Z","schema_version":"clob-market-ws.price_change.v1","sequence":null,"server_hash":null,"server_timestamp":"1785122012744","session_id":"ff6d21c8283948938400a32613abec2c","source":"clob_market_ws"},"received_at":"2026-07-27T03:13:32.643324Z","record_id":"850252d00f53fd1a0a2a11cc34438fb85cbc2586dad18a27dadfb2545a37d004","schema_fingerprint":"4aa3821a28b0b7c2400bc59aba4bcc0a76e971dadd19610d3ad38c768e124dc7","schema_version":"edge-lab-recorder.raw.v1","sequence":null,"source":"clob_market_ws"}
{"event_at":"2026-07-27T03:13:32.747000Z","event_fingerprint":"5c0d245e3f3262fc1c93a8e1ef8dd290a5a9b4a9b7267e0a62077f98db4127ec","payload":{"connection_id":"f95883f18d264834af91809e5f803e9f","event_at":"2026-07-27T03:13:32.747000Z","event_type":"price_change","frame_hash":"08d28086f6cc84cf2f3c0a9c46f9023c9e4a56ae0b307343a534934cbe58703f","frame_index":0,"kind":"data","monotonic_ns":223995982461125,"payload":{"event_type":"price_change","market":"0xf9d60bb033695053c4d1d8592e52171c1042f64b41a4b72e09dcc6f4852b6670","price_changes":[{"asset_id":"96283536366176669581486355171583722558858323126916278856549586825357358273536","best_ask":"0.19","best_bid":"0.18","hash":"9190014f1b6f54b40d18d91a5aaee3e305fdc9ae","price":"0.14","side":"BUY","size":"25"},{"asset_id":"8698449539441374295770236407991735029336433231649246775082939325523552031992","best_ask":"0.82","best_bid":"0.81","hash":"70f0466a289c2b5eba8910b97fb10e74589edb4b","price":"0.86","side":"SELL","size":"25"}],"timestamp":"1785122012747"},"payload_hash":"d42cab9c73040f210beb05174c45cb6e3f6e79bb3b1c61d91bb10b9a93ac03e4","raw_frame":"{\"market\":\"0xf9d60bb033695053c4d1d8592e52171c1042f64b41a4b72e09dcc6f4852b6670\", \"price_changes\":[{\"asset_id\":\"96283536366176669581486355171583722558858323126916278856549586825357358273536\", \"price\":\"0.14\", \"size\":\"25\", \"side\":\"BUY\", \"hash\":\"9190014f1b6f54b40d18d91a5aaee3e305fdc9ae\", \"best_bid\":\"0.18\", \"best_ask\":\"0.19\"}, {\"asset_id\":\"8698449539441374295770236407991735029336433231649246775082939325523552031992\", \"price\":\"0.86\", \"size\":\"25\", \"side\":\"SELL\", \"hash\":\"70f0466a289c2b5eba8910b97fb10e74589edb4b\", \"best_bid\":\"0.81\", \"best_ask\":\"0.82\"}], \"timestamp\":\"1785122012747\", \"event_type\":\"price_change\"}","received_at":"2026-07-27T03:13:32.650017Z","schema_version":"clob-market-ws.price_change.v1","sequence":null,"server_hash":null,"server_timestamp":"1785122012747","session_id":"ff6d21c8283948938400a32613abec2c","source":"clob_market_ws"},"received_at":"2026-07-27T03:13:32.650017Z","record_id":"764ce2b16aa0db7be192eb7c54cb0ed5f176b8dc5000e984226d8bcc4a9b7b98","schema_fingerprint":"4aa3821a28b0b7c2400bc59aba4bcc0a76e971dadd19610d3ad38c768e124dc7","schema_version":"edge-lab-recorder.raw.v1","sequence":null,"source":"clob_market_ws"}
{"event_at":"2026-07-27T03:13:32.747000Z","event_fingerprint":"4e1439b47013f9fb42e557d2068dfb150bb9b9c394949cfbaa22225b07f495ca","payload":{"connection_id":"f95883f18d264834af91809e5f803e9f","event_at":"2026-07-27T03:13:32.747000Z","event_type":"price_change","frame_hash":"1c0b49402899af9d01a5a3d7e9246a3e06f956a999197268439eb778a48d2d8c","frame_index":0,"kind":"data","monotonic_ns":223995987038333,"payload":{"event_type":"price_change","market":"0xf9d60bb033695053c4d1d8592e52171c1042f64b41a4b72e09dcc6f4852b6670","price_changes":[{"asset_id":"8698449539441374295770236407991735029336433231649246775082939325523552031992","best_ask":"0.82","best_bid":"0.81","hash":"70f0466a289c2b5eba8910b97fb10e74589edb4b","price":"0.74","side":"BUY","size":"115.04"},{"asset_id":"96283536366176669581486355171583722558858323126916278856549586825357358273536","best_ask":"0.19","best_bid":"0.18","hash":"9190014f1b6f54b40d18d91a5aaee3e305fdc9ae","price":"0.26","side":"SELL","size":"115.04"}],"timestamp":"1785122012747"},"payload_hash":"cf34c8c353a630990b09b47193c0b37573b3cf03d3a8e6f305cdb295a6d8efa8","raw_frame":"{\"market\":\"0xf9d60bb033695053c4d1d8592e52171c1042f64b41a4b72e09dcc6f4852b6670\", \"price_changes\":[{\"asset_id\":\"8698449539441374295770236407991735029336433231649246775082939325523552031992\", \"price\":\"0.74\", \"size\":\"115.04\", \"side\":\"BUY\", \"hash\":\"70f0466a289c2b5eba8910b97fb10e74589edb4b\", \"best_bid\":\"0.81\", \"best_ask\":\"0.82\"}, {\"asset_id\":\"96283536366176669581486355171583722558858323126916278856549586825357358273536\", \"price\":\"0.26\", \"size\":\"115.04\", \"side\":\"SELL\", \"hash\":\"9190014f1b6f54b40d18d91a5aaee3e305fdc9ae\", \"best_bid\":\"0.18\", \"best_ask\":\"0.19\"}], \"timestamp\":\"1785122012747\", \"event_type\":\"price_change\"}","received_at":"2026-07-27T03:13:32.654598Z","schema_version":"clob-market-ws.price_change.v1","sequence":null,"server_hash":null,"server_timestamp":"1785122012747","session_id":"ff6d21c8283948938400a32613abec2c","source":"clob_market_ws"},"received_at":"2026-07-27T03:13:32.654598Z","record_id":"a1dac26b99267b4a5eb11454557345eadbd6ad9a14d14f444392434637dd88b4","schema_fingerprint":"4aa3821a28b0b7c2400bc59aba4bcc0a76e971dadd19610d3ad38c768e124dc7","schema_version":"edge-lab-recorder.raw.v1","sequence":null,"source":"clob_market_ws"}
{"event_at":"2026-07-27T03:13:32.764000Z","event_fingerprint":"b01569a8538477b9ef0a89f506d03c10faf2a7bd6a290d0db05bde97e860447a","payload":{"connection_id":"f95883f18d264834af91809e5f803e9f","event_at":"2026-07-27T03:13:32.764000Z","event_type":"price_change","frame_hash":"78f0cbc606b298a5fc94b69de3ef622981241a8545bdd53e01def6a0ec7ad7f8","frame_index":0,"kind":"data","monotonic_ns":223995996328625,"payload":{"event_type":"price_change","market":"0xf9d60bb033695053c4d1d8592e52171c1042f64b41a4b72e09dcc6f4852b6670","price_changes":[{"asset_id":"96283536366176669581486355171583722558858323126916278856549586825357358273536","best_ask":"0.19","best_bid":"0.18","hash":"9c8b992b9cc0f804f2679abe9897469942945d35","price":"0.18","side":"BUY","size":"55.87"},{"asset_id":"8698449539441374295770236407991735029336433231649246775082939325523552031992","best_ask":"0.82","best_bid":"0.81","hash":"d1e627cc7ab407ca0e4696f12d117e039801421b","price":"0.82","side":"SELL","size":"55.87"}],"timestamp":"1785122012764"},"payload_hash":"38876f2bff65384600d697798521437a47037978f2938d55ed347428e793d21c","raw_frame":"{\"market\":\"0xf9d60bb033695053c4d1d8592e52171c1042f64b41a4b72e09dcc6f4852b6670\", \"price_changes\":[{\"asset_id\":\"96283536366176669581486355171583722558858323126916278856549586825357358273536\", \"price\":\"0.18\", \"size\":\"55.87\", \"side\":\"BUY\", \"hash\":\"9c8b992b9cc0f804f2679abe9897469942945d35\", \"best_bid\":\"0.18\", \"best_ask\":\"0.19\"}, {\"asset_id\":\"8698449539441374295770236407991735029336433231649246775082939325523552031992\", \"price\":\"0.82\", \"size\":\"55.87\", \"side\":\"SELL\", \"hash\":\"d1e627cc7ab407ca0e4696f12d117e039801421b\", \"best_bid\":\"0.81\", \"best_ask\":\"0.82\"}], \"timestamp\":\"1785122012764\", \"event_type\":\"price_change\"}","received_at":"2026-07-27T03:13:32.663886Z","schema_version":"clob-market-ws.price_change.v1","sequence":null,"server_hash":null,"server_timestamp":"1785122012764","session_id":"ff6d21c8283948938400a32613abec2c","source":"clob_market_ws"},"received_at":"2026-07-27T03:13:32.663886Z","record_id":"2aff31dd369994e4fff0167182144150cd1f6ce0902d6107094c890ac47a13f7","schema_fingerprint":"4aa3821a28b0b7c2400bc59aba4bcc0a76e971dadd19610d3ad38c768e124dc7","schema_version":"edge-lab-recorder.raw.v1","sequence":null,"source":"clob_market_ws"}
{"event_at":"2026-07-27T03:13:32.765000Z","event_fingerprint":"b1369ec29f113f767152fd94b4b005af7d5057c0589f198f11d21c4bcdfe1594","payload":{"connection_id":"f95883f18d264834af91809e5f803e9f","event_at":"2026-07-27T03:13:32.765000Z","event_type":"price_change","frame_hash":"db62f26a8a937a132c54966172429f093e05e9f586f359f3aa97b308c9ba66c4","frame_index":0,"kind":"data","monotonic_ns":223995998222916,"payload":{"event_type":"price_change","market":"0xf9d60bb033695053c4d1d8592e52171c1042f64b41a4b72e09dcc6f4852b6670","price_changes":[{"asset_id":"8698449539441374295770236407991735029336433231649246775082939325523552031992","best_ask":"0.82","best_bid":"0.81","hash":"e74da488361aa0c0d93c71255411f2db4b3cfd98","price":"0.03","side":"BUY","size":"1075.8"},{"asset_id":"96283536366176669581486355171583722558858323126916278856549586825357358273536","best_ask":"0.19","best_bid":"0.18","hash":"b3325e0ec13ca491ef8993356d97216791c300cb","price":"0.97","side":"SELL","size":"1075.8"}],"timestamp":"1785122012765"},"payload_hash":"9115be79d12b02fe70cefed8c25e8a5cd9866dc524c4a0c1e89bce0ba338de75","raw_frame":"{\"market\":\"0xf9d60bb033695053c4d1d8592e52171c1042f64b41a4b72e09dcc6f4852b6670\", \"price_changes\":[{\"asset_id\":\"8698449539441374295770236407991735029336433231649246775082939325523552031992\", \"price\":\"0.03\", \"size\":\"1075.8\", \"side\":\"BUY\", \"hash\":\"e74da488361aa0c0d93c71255411f2db4b3cfd98\", \"best_bid\":\"0.81\", \"best_ask\":\"0.82\"}, {\"asset_id\":\"96283536366176669581486355171583722558858323126916278856549586825357358273536\", \"price\":\"0.97\", \"size\":\"1075.8\", \"side\":\"SELL\", \"hash\":\"b3325e0ec13ca491ef8993356d97216791c300cb\", \"best_bid\":\"0.18\", \"best_ask\":\"0.19\"}], \"timestamp\":\"1785122012765\", \"event_type\":\"price_change\"}","received_at":"2026-07-27T03:13:32.665781Z","schema_version":"clob-market-ws.price_change.v1","sequence":null,"server_hash":null,"server_timestamp":"1785122012765","session_id":"ff6d21c8283948938400a32613abec2c","source":"clob_market_ws"},"received_at":"2026-07-27T03:13:32.665781Z","record_id":"896f8f8c21944b5fd1ec28f7f6cec0ebd5a92858a2c0895f32754f61fdb1b43b","schema_fingerprint":"4aa3821a28b0b7c2400bc59aba4bcc0a76e971dadd19610d3ad38c768e124dc7","schema_version":"edge-lab-recorder.raw.v1","sequence":null,"source":"clob_market_ws"}
{"event_at":"2026-07-27T03:13:32.770000Z","event_fingerprint":"93ad66c096198703edd0bfaf23e3faea714465523f662f81d01018969b14527d","payload":{"connection_id":"f95883f18d264834af91809e5f803e9f","event_at":"2026-07-27T03:13:32.770000Z","event_type":"price_change","frame_hash":"d4a04610716afefb2d2911b4d11637d533f1c1be36b0ca1826f1b9a18965a64d","frame_index":0,"kind":"data","monotonic_ns":223996001399416,"payload":{"event_type":"price_change","market":"0xf9d60bb033695053c4d1d8592e52171c1042f64b41a4b72e09dcc6f4852b6670","price_changes":[{"asset_id":"96283536366176669581486355171583722558858323126916278856549586825357358273536","best_ask":"0.19","best_bid":"0.18","hash":"da7959bbc631c4254cf3cb9fd2026bdcbff6e2ad","price":"0.24","side":"SELL","size":"176.92"},{"asset_id":"8698449539441374295770236407991735029336433231649246775082939325523552031992","best_ask":"0.82","best_bid":"0.81","hash":"0e8e44c898396c42322045ba8c53791c2e1dad59","price":"0.76","side":"BUY","size":"176.92"}],"timestamp":"1785122012770"},"payload_hash":"9834043a378c11ca1a9119d5a69151498346281d4e3fa0f959fc3bf9459b1608","raw_frame":"{\"market\":\"0xf9d60bb033695053c4d1d8592e52171c1042f64b41a4b72e09dcc6f4852b6670\", \"price_changes\":[{\"asset_id\":\"96283536366176669581486355171583722558858323126916278856549586825357358273536\", \"price\":\"0.24\", \"size\":\"176.92\", \"side\":\"SELL\", \"hash\":\"da7959bbc631c4254cf3cb9fd2026bdcbff6e2ad\", \"best_bid\":\"0.18\", \"best_ask\":\"0.19\"}, {\"asset_id\":\"8698449539441374295770236407991735029336433231649246775082939325523552031992\", \"price\":\"0.76\", \"size\":\"176.92\", \"side\":\"BUY\", \"hash\":\"0e8e44c898396c42322045ba8c53791c2e1dad59\", \"best_bid\":\"0.81\", \"best_ask\":\"0.82\"}], \"timestamp\":\"1785122012770\", \"event_type\":\"price_change\"}","received_at":"2026-07-27T03:13:32.668958Z","schema_version":"clob-market-ws.price_change.v1","sequence":null,"server_hash":null,"server_timestamp":"1785122012770","session_id":"ff6d21c8283948938400a32613abec2c","source":"clob_market_ws"},"received_at":"2026-07-27T03:13:32.668958Z","record_id":"3b84168dfd2e0ae58623d6fdc1e3ddb3faf932ff0dd65affc335d076dcd5cd4d","schema_fingerprint":"4aa3821a28b0b7c2400bc59aba4bcc0a76e971dadd19610d3ad38c768e124dc7","schema_version":"edge-lab-recorder.raw.v1","sequence":null,"source":"clob_market_ws"}
{"event_at":"2026-07-27T03:13:32.772000Z","event_fingerprint":"f9e2496a9f0279999dc6018b815f42027b9a3d594d394f4a4f3f4d9c0f82e322","payload":{"connection_id":"f95883f18d264834af91809e5f803e9f","event_at":"2026-07-27T03:13:32.772000Z","event_type":"price_change","frame_hash":"73c01d2edff70c29aba2d7b990c1c433825836add19b4c5f97f410bf2a81dc2d","frame_index":0,"kind":"data","monotonic_ns":223996004804291,"payload":{"event_type":"price_change","market":"0xf9d60bb033695053c4d1d8592e52171c1042f64b41a4b72e09dcc6f4852b6670","price_changes":[{"asset_id":"8698449539441374295770236407991735029336433231649246775082939325523552031992","best_ask":"0.82","best_bid":"0.81","hash":"676162d8a2d8ac8b6bc7398eccaf0670d96b74a5","price":"0.75","side":"BUY","size":"88"},{"asset_id":"96283536366176669581486355171583722558858323126916278856549586825357358273536","best_ask":"0.19","best_bid":"0.18","hash":"97e699023269e00e0fb59d35af34b664c32d8832","price":"0.25","side":"SELL","size":"88"}],"timestamp":"1785122012772"},"payload_hash":"0235daf8e84acf17688761be485c63cf147f3158bfcf7784aa264e32e1acc989","raw_frame":"{\"market\":\"0xf9d60bb033695053c4d1d8592e52171c1042f64b41a4b72e09dcc6f4852b6670\", \"price_changes\":[{\"asset_id\":\"8698449539441374295770236407991735029336433231649246775082939325523552031992\", \"price\":\"0.75\", \"size\":\"88\", \"side\":\"BUY\", \"hash\":\"676162d8a2d8ac8b6bc7398eccaf0670d96b74a5\", \"best_bid\":\"0.81\", \"best_ask\":\"0.82\"}, {\"asset_id\":\"96283536366176669581486355171583722558858323126916278856549586825357358273536\", \"price\":\"0.25\", \"size\":\"88\", \"side\":\"SELL\", \"hash\":\"97e699023269e00e0fb59d35af34b664c32d8832\", \"best_bid\":\"0.18\", \"best_ask\":\"0.19\"}], \"timestamp\":\"1785122012772\", \"event_type\":\"price_change\"}","received_at":"2026-07-27T03:13:32.672361Z","schema_version":"clob-market-ws.price_change.v1","sequence":null,"server_hash":null,"server_timestamp":"1785122012772","session_id":"ff6d21c8283948938400a32613abec2c","source":"clob_market_ws"},"received_at":"2026-07-27T03:13:32.672361Z","record_id":"97aaca02d774b38f3bb66af7a9e26d35918927184c8b1c19d9f92ccddb33cd95","schema_fingerprint":"4aa3821a28b0b7c2400bc59aba4bcc0a76e971dadd19610d3ad38c768e124dc7","schema_version":"edge-lab-recorder.raw.v1","sequence":null,"source":"clob_market_ws"}
{"event_at":"2026-07-27T03:13:32.774000Z","event_fingerprint":"b25919e855d4d5f55b01377ae41754db5a60fc5d63be5e14317b56e9c5461519","payload":{"connection_id":"f95883f18d264834af91809e5f803e9f","event_at":"2026-07-27T03:13:32.774000Z","event_type":"price_change","frame_hash":"d0409468aafce10816847f39def5678e78f87926c1ca3ae2ff5c3befb045dd43","frame_index":0,"kind":"data","monotonic_ns":223996007291541,"payload":{"event_type":"price_change","market":"0xf9d60bb033695053c4d1d8592e52171c1042f64b41a4b72e09dcc6f4852b6670","price_changes":[{"asset_id":"96283536366176669581486355171583722558858323126916278856549586825357358273536","best_ask":"0.19","best_bid":"0.18","hash":"828bb41b242faf8c1d3bf6fab30adf0df7ad930a","price":"0.12","side":"BUY","size":"131.8"},{"asset_id":"8698449539441374295770236407991735029336433231649246775082939325523552031992","best_ask":"0.82","best_bid":"0.81","hash":"4b4f7a7f4cb832c1ce2b841fd19bac7d65fd8506","price":"0.88","side":"SELL","size":"131.8"}],"timestamp":"1785122012774"},"payload_hash":"f9fdb11f038345c1287a0dcd61c66704f09150010a8f4cfe8402bb49269da071","raw_frame":"{\"market\":\"0xf9d60bb033695053c4d1d8592e52171c1042f64b41a4b72e09dcc6f4852b6670\", \"price_changes\":[{\"asset_id\":\"96283536366176669581486355171583722558858323126916278856549586825357358273536\", \"price\":\"0.12\", \"size\":\"131.8\", \"side\":\"BUY\", \"hash\":\"828bb41b242faf8c1d3bf6fab30adf0df7ad930a\", \"best_bid\":\"0.18\", \"best_ask\":\"0.19\"}, {\"asset_id\":\"8698449539441374295770236407991735029336433231649246775082939325523552031992\", \"price\":\"0.88\", \"size\":\"131.8\", \"side\":\"SELL\", \"hash\":\"4b4f7a7f4cb832c1ce2b841fd19bac7d65fd8506\", \"best_bid\":\"0.81\", \"best_ask\":\"0.82\"}], \"timestamp\":\"1785122012774\", \"event_type\":\"price_change\"}","received_at":"2026-07-27T03:13:32.674851Z","schema_version":"clob-market-ws.price_change.v1","sequence":null,"server_hash":null,"server_timestamp":"1785122012774","session_id":"ff6d21c8283948938400a32613abec2c","source":"clob_market_ws"},"received_at":"2026-07-27T03:13:32.674851Z","record_id":"97a20d3a6b89ffdc5ddf3832a6828d387450064b764fdbfd9daa1d5b8f614036","schema_fingerprint":"4aa3821a28b0b7c2400bc59aba4bcc0a76e971dadd19610d3ad38c768e124dc7","schema_version":"edge-lab-recorder.raw.v1","sequence":null,"source":"clob_market_ws"}
{"event_at":"2026-07-27T03:13:32.775000Z","event_fingerprint":"da743d468dcc106ca2384e0fca53482c6b6e1b870efc8b8b56adbb56e80be5af","payload":{"connection_id":"f95883f18d264834af91809e5f803e9f","event_at":"2026-07-27T03:13:32.775000Z","event_type":"price_change","frame_hash":"fb1467967088762fc073dc45214e6f4a6ea59151ff4488dea760e60116d88213","frame_index":0,"kind":"data","monotonic_ns":223996008778166,"payload":{"event_type":"price_change","market":"0xf9d60bb033695053c4d1d8592e52171c1042f64b41a4b72e09dcc6f4852b6670","price_changes":[{"asset_id":"8698449539441374295770236407991735029336433231649246775082939325523552031992","best_ask":"0.82","best_bid":"0.81","hash":"9a68881199a12ed56145238ef2f0f73d664451db","price":"0.76","side":"BUY","size":"163.92"},{"asset_id":"96283536366176669581486355171583722558858323126916278856549586825357358273536","best_ask":"0.19","best_bid":"0.18","hash":"4db1f83ad4e051c40c5245d54568da067a076950","price":"0.24","side":"SELL","size":"163.92"}],"timestamp":"1785122012775"},"payload_hash":"d2fb7e5b94ef4c16282c0e3b9e77c3a6324b2fa6249c86e3ddc0ec6b87846802","raw_frame":"{\"market\":\"0xf9d60bb033695053c4d1d8592e52171c1042f64b41a4b72e09dcc6f4852b6670\", \"price_changes\":[{\"asset_id\":\"8698449539441374295770236407991735029336433231649246775082939325523552031992\", \"price\":\"0.76\", \"size\":\"163.92\", \"side\":\"BUY\", \"hash\":\"9a68881199a12ed56145238ef2f0f73d664451db\", \"best_bid\":\"0.81\", \"best_ask\":\"0.82\"}, {\"asset_id\":\"96283536366176669581486355171583722558858323126916278856549586825357358273536\", \"price\":\"0.24\", \"size\":\"163.92\", \"side\":\"SELL\", \"hash\":\"4db1f83ad4e051c40c5245d54568da067a076950\", \"best_bid\":\"0.18\", \"best_ask\":\"0.19\"}], \"timestamp\":\"1785122012775\", \"event_type\":\"price_change\"}","received_at":"2026-07-27T03:13:32.676338Z","schema_version":"clob-market-ws.price_change.v1","sequence":null,"server_hash":null,"server_timestamp":"1785122012775","session_id":"ff6d21c8283948938400a32613abec2c","source":"clob_market_ws"},"received_at":"2026-07-27T03:13:32.676338Z","record_id":"d4f7aa8f67699fb2e70d91ad5791b2729497da267adf04ffa29ca7a80b50c9ad","schema_fingerprint":"4aa3821a28b0b7c2400bc59aba4bcc0a76e971dadd19610d3ad38c768e124dc7","schema_version":"edge-lab-recorder.raw.v1","sequence":null,"source":"clob_market_ws"}
{"event_at":"2026-07-27T03:13:32.780000Z","event_fingerprint":"ad04c6bfb8cf724b8c7f736cd618acc2a17b250b022ed07cf1b5dedd99fd1059","payload":{"connection_id":"f95883f18d264834af91809e5f803e9f","event_at":"2026-07-27T03:13:32.780000Z","event_type":"price_change","frame_hash":"739db3a25d04dc17c4a19f261e1fc01abc4d45eda3224f96686c719b0d4aa123","frame_index":0,"kind":"data","monotonic_ns":223996012011083,"payload":{"event_type":"price_change","market":"0xf9d60bb033695053c4d1d8592e52171c1042f64b41a4b72e09dcc6f4852b6670","price_changes":[{"asset_id":"8698449539441374295770236407991735029336433231649246775082939325523552031992","best_ask":"0.82","best_bid":"0.81","hash":"4e10c892b1d1af595413f1e6d7ea776e6775e169","price":"0.01","side":"BUY","size":"8027.52"},{"asset_id":"96283536366176669581486355171583722558858323126916278856549586825357358273536","best_ask":"0.19","best_bid":"0.18","hash":"d0618941286911e892a1c74c39b98f2ea9d8d004","price":"0.99","side":"SELL","size":"8027.52"}],"timestamp":"1785122012780"},"payload_hash":"d14d7b52032ebaec8880df99eaf6c41922d46e42e8a4166ec275597f11cf00b9","raw_frame":"{\"market\":\"0xf9d60bb033695053c4d1d8592e52171c1042f64b41a4b72e09dcc6f4852b6670\", \"price_changes\":[{\"asset_id\":\"8698449539441374295770236407991735029336433231649246775082939325523552031992\", \"price\":\"0.01\", \"size\":\"8027.52\", \"side\":\"BUY\", \"hash\":\"4e10c892b1d1af595413f1e6d7ea776e6775e169\", \"best_bid\":\"0.81\", \"best_ask\":\"0.82\"}, {\"asset_id\":\"96283536366176669581486355171583722558858323126916278856549586825357358273536\", \"price\":\"0.99\", \"size\":\"8027.52\", \"side\":\"SELL\", \"hash\":\"d0618941286911e892a1c74c39b98f2ea9d8d004\", \"best_bid\":\"0.18\", \"best_ask\":\"0.19\"}], \"timestamp\":\"1785122012780\", \"event_type\":\"price_change\"}","received_at":"2026-07-27T03:13:32.679570Z","schema_version":"clob-market-ws.price_change.v1","sequence":null,"server_hash":null,"server_timestamp":"1785122012780","session_id":"ff6d21c8283948938400a32613abec2c","source":"clob_market_ws"},"received_at":"2026-07-27T03:13:32.679570Z","record_id":"b50613e3563ad749bedfcb7acf1ceb487fe4f66f8d139438fcb57e2eb3f4cc4a","schema_fingerprint":"4aa3821a28b0b7c2400bc59aba4bcc0a76e971dadd19610d3ad38c768e124dc7","schema_version":"edge-lab-recorder.raw.v1","sequence":null,"source":"clob_market_ws"}
{"event_at":"2026-07-27T03:13:32.799000Z","event_fingerprint":"ac36729c6a44216449fb6e3653484c267578a89f35750f6e908eac0809614880","payload":{"connection_id":"f95883f18d264834af91809e5f803e9f","event_at":"2026-07-27T03:13:32.799000Z","event_type":"price_change","frame_hash":"6f259311fdb1da0287ae56a8d915e0c6c9c73a3982dd1f49b5b0a2b9c0d08c4e","frame_index":0,"kind":"data","monotonic_ns":223996044773833,"payload":{"event_type":"price_change","market":"0xf9d60bb033695053c4d1d8592e52171c1042f64b41a4b72e09dcc6f4852b6670","price_changes":[{"asset_id":"8698449539441374295770236407991735029336433231649246775082939325523552031992","best_ask":"0.82","best_bid":"0.81","hash":"af5702df67ca35264bb638e05343c873bff691c8","price":"0.75","side":"BUY","size":"83"},{"asset_id":"96283536366176669581486355171583722558858323126916278856549586825357358273536","best_ask":"0.19","best_bid":"0.18","hash":"988a94fe1276dfc3b61cdbdb073a7f4c241b4828","price":"0.25","side":"SELL","size":"83"}],"timestamp":"1785122012799"},"payload_hash":"34fd84e85ae3619de44e104626a8dc9f66680179b37f6b72e44f9d33ca443d89","raw_frame":"{\"market\":\"0xf9d60bb033695053c4d1d8592e52171c1042f64b41a4b72e09dcc6f4852b6670\", \"price_changes\":[{\"asset_id\":\"8698449539441374295770236407991735029336433231649246775082939325523552031992\", \"price\":\"0.75\", \"size\":\"83\", \"side\":\"BUY\", \"hash\":\"af5702df67ca35264bb638e05343c873bff691c8\", \"best_bid\":\"0.81\", \"best_ask\":\"0.82\"}, {\"asset_id\":\"96283536366176669581486355171583722558858323126916278856549586825357358273536\", \"price\":\"0.25\", \"size\":\"83\", \"side\":\"SELL\", \"hash\":\"988a94fe1276dfc3b61cdbdb073a7f4c241b4828\", \"best_bid\":\"0.18\", \"best_ask\":\"0.19\"}], \"timestamp\":\"1785122012799\", \"event_type\":\"price_change\"}","received_at":"2026-07-27T03:13:32.712328Z","schema_version":"clob-market-ws.price_change.v1","sequence":null,"server_hash":null,"server_timestamp":"1785122012799","session_id":"ff6d21c8283948938400a32613abec2c","source":"clob_market_ws"},"received_at":"2026-07-27T03:13:32.712328Z","record_id":"5828f08ae91828de89c221bd14e05a147e34445cf74b971adf7fd1db0bf668cb","schema_fingerprint":"4aa3821a28b0b7c2400bc59aba4bcc0a76e971dadd19610d3ad38c768e124dc7","schema_version":"edge-lab-recorder.raw.v1","sequence":null,"source":"clob_market_ws"}
{"event_at":"2026-07-27T03:13:32.799000Z","event_fingerprint":"0f3c1056bf7570d3a3355f8d17006a34f7d6d5c69bd52ab2d0c071370d235269","payload":{"connection_id":"f95883f18d264834af91809e5f803e9f","event_at":"2026-07-27T03:13:32.799000Z","event_type":"price_change","frame_hash":"9f8885828d12fe2a3c20acbd820b3c148e2ddb16dc3d2adf1a30f65f8f722e89","frame_index":0,"kind":"data","monotonic_ns":223996051958250,"payload":{"event_type":"price_change","market":"0xf9d60bb033695053c4d1d8592e52171c1042f64b41a4b72e09dcc6f4852b6670","price_changes":[{"asset_id":"8698449539441374295770236407991735029336433231649246775082939325523552031992","best_ask":"0.82","best_bid":"0.81","hash":"2905ce6ea693164f42e67db517bd60230771e08e","price":"0.01","side":"BUY","size":"8022.52"},{"asset_id":"96283536366176669581486355171583722558858323126916278856549586825357358273536","best_ask":"0.19","best_bid":"0.18","hash":"8d2a48e8497692e372dabb088aabeac859b950bc","price":"0.99","side":"SELL","size":"8022.52"}],"timestamp":"1785122012799"},"payload_hash":"d0ecf1d155c4ab075ed558ced2a24c4ef490c35173ed9b1207825e4bf995615f","raw_frame":"{\"market\":\"0xf9d60bb033695053c4d1d8592e52171c1042f64b41a4b72e09dcc6f4852b6670\", \"price_changes\":[{\"asset_id\":\"8698449539441374295770236407991735029336433231649246775082939325523552031992\", \"price\":\"0.01\", \"size\":\"8022.52\", \"side\":\"BUY\", \"hash\":\"2905ce6ea693164f42e67db517bd60230771e08e\", \"best_bid\":\"0.81\", \"best_ask\":\"0.82\"}, {\"asset_id\":\"96283536366176669581486355171583722558858323126916278856549586825357358273536\", \"price\":\"0.99\", \"size\":\"8022.52\", \"side\":\"SELL\", \"hash\":\"8d2a48e8497692e372dabb088aabeac859b950bc\", \"best_bid\":\"0.18\", \"best_ask\":\"0.19\"}], \"timestamp\":\"1785122012799\", \"event_type\":\"price_change\"}","received_at":"2026-07-27T03:13:32.719515Z","schema_version":"clob-market-ws.price_change.v1","sequence":null,"server_hash":null,"server_timestamp":"1785122012799","session_id":"ff6d21c8283948938400a32613abec2c","source":"clob_market_ws"},"received_at":"2026-07-27T03:13:32.719515Z","record_id":"46f1988e0c7c32e0260add0a0dce090396994a83870f1993d80dd9724215affe","schema_fingerprint":"4aa3821a28b0b7c2400bc59aba4bcc0a76e971dadd19610d3ad38c768e124dc7","schema_version":"edge-lab-recorder.raw.v1","sequence":null,"source":"clob_market_ws"}
{"event_at":"2026-07-27T03:13:32.823000Z","event_fingerprint":"ea4d8649a8604da3cc1fd4a9edd8b422aff4f0f783f964488c819b9934083956","payload":{"connection_id":"f95883f18d264834af91809e5f803e9f","event_at":"2026-07-27T03:13:32.823000Z","event_type":"price_change","frame_hash":"be9a7b3bdfba6180cb5f8fed97271a6dfe7e7e5d41433e7a18819702c1d50744","frame_index":0,"kind":"data","monotonic_ns":223996060524083,"payload":{"event_type":"price_change","market":"0xf9d60bb033695053c4d1d8592e52171c1042f64b41a4b72e09dcc6f4852b6670","price_changes":[{"asset_id":"8698449539441374295770236407991735029336433231649246775082939325523552031992","best_ask":"0.82","best_bid":"0.81","hash":"5ba5e605232b50ee2c9094e90c1971fe3e23ee58","price":"0.74","side":"BUY","size":"120.04"},{"asset_id":"96283536366176669581486355171583722558858323126916278856549586825357358273536","best_ask":"0.19","best_bid":"0.18","hash":"7bef8604147cc00100fb1dc50448ac690225ff00","price":"0.26","side":"SELL","size":"120.04"}],"timestamp":"1785122012823"},"payload_hash":"94341673bfa90fad990324951170e883840e53af2e3f080158afb528f2371f58","raw_frame":"{\"market\":\"0xf9d60bb033695053c4d1d8592e52171c1042f64b41a4b72e09dcc6f4852b6670\", \"price_changes\":[{\"asset_id\":\"8698449539441374295770236407991735029336433231649246775082939325523552031992\", \"price\":\"0.74\", \"size\":\"120.04\", \"side\":\"BUY\", \"hash\":\"5ba5e605232b50ee2c9094e90c1971fe3e23ee58\", \"best_bid\":\"0.81\", \"best_ask\":\"0.82\"}, {\"asset_id\":\"96283536366176669581486355171583722558858323126916278856549586825357358273536\", \"price\":\"0.26\", \"size\":\"120.04\", \"side\":\"SELL\", \"hash\":\"7bef8604147cc00100fb1dc50448ac690225ff00\", \"best_bid\":\"0.18\", \"best_ask\":\"0.19\"}], \"timestamp\":\"1785122012823\", \"event_type\":\"price_change\"}","received_at":"2026-07-27T03:13:32.728082Z","schema_version":"clob-market-ws.price_change.v1","sequence":null,"server_hash":null,"server_timestamp":"1785122012823","session_id":"ff6d21c8283948938400a32613abec2c","source":"clob_market_ws"},"received_at":"2026-07-27T03:13:32.728082Z","record_id":"3ed1bf7c9eba133e0def2baa48daaae43dae978c56d99819ab4a4775da0ac2c5","schema_fingerprint":"4aa3821a28b0b7c2400bc59aba4bcc0a76e971dadd19610d3ad38c768e124dc7","schema_version":"edge-lab-recorder.raw.v1","sequence":null,"source":"clob_market_ws"}
{"event_at":"2026-07-27T03:13:32.830000Z","event_fingerprint":"41967b8ce8bbef37385eb09056d23a7a422e9337a3477b0835b7f25e2e905fcb","payload":{"connection_id":"f95883f18d264834af91809e5f803e9f","event_at":"2026-07-27T03:13:32.830000Z","event_type":"price_change","frame_hash":"c793c4200e9799cbc384e57b6b10d188207f29230d91a1411b53873cfb63ea84","frame_index":0,"kind":"data","monotonic_ns":223996062737333,"payload":{"event_type":"price_change","market":"0xf9d60bb033695053c4d1d8592e52171c1042f64b41a4b72e09dcc6f4852b6670","price_changes":[{"asset_id":"8698449539441374295770236407991735029336433231649246775082939325523552031992","best_ask":"0.82","best_bid":"0.81","hash":"a50a0e0e3f38ba0c22a053b363d6d4808b373573","price":"0.03","side":"BUY","size":"1070.8"},{"asset_id":"96283536366176669581486355171583722558858323126916278856549586825357358273536","best_ask":"0.19","best_bid":"0.18","hash":"7d5584b6488bfa3d8315a6dff74986ef18758661","price":"0.97","side":"SELL","size":"1070.8"}],"timestamp":"1785122012830"},"payload_hash":"b216e09aa65b5867a9e0353e1769dbec6208b97fa3de793bf24f346ae7f20077","raw_frame":"{\"market\":\"0xf9d60bb033695053c4d1d8592e52171c1042f64b41a4b72e09dcc6f4852b6670\", \"price_changes\":[{\"asset_id\":\"8698449539441374295770236407991735029336433231649246775082939325523552031992\", \"price\":\"0.03\", \"size\":\"1070.8\", \"side\":\"BUY\", \"hash\":\"a50a0e0e3f38ba0c22a053b363d6d4808b373573\", \"best_bid\":\"0.81\", \"best_ask\":\"0.82\"}, {\"asset_id\":\"96283536366176669581486355171583722558858323126916278856549586825357358273536\", \"price\":\"0.97\", \"size\":\"1070.8\", \"side\":\"SELL\", \"hash\":\"7d5584b6488bfa3d8315a6dff74986ef18758661\", \"best_bid\":\"0.18\", \"best_ask\":\"0.19\"}], \"timestamp\":\"1785122012830\", \"event_type\":\"price_change\"}","received_at":"2026-07-27T03:13:32.730292Z","schema_version":"clob-market-ws.price_change.v1","sequence":null,"server_hash":null,"server_timestamp":"1785122012830","session_id":"ff6d21c8283948938400a32613abec2c","source":"clob_market_ws"},"received_at":"2026-07-27T03:13:32.730292Z","record_id":"f6370369d905cead8a3a1f1a95364426c1b12e695b1722022a42c3ea5b2e04d6","schema_fingerprint":"4aa3821a28b0b7c2400bc59aba4bcc0a76e971dadd19610d3ad38c768e124dc7","schema_version":"edge-lab-recorder.raw.v1","sequence":null,"source":"clob_market_ws"}
{"event_at":"2026-07-27T03:13:32.896000Z","event_fingerprint":"ef3f16d6daedce5a96dc828b743836c92a3e519ed2b4aba6f1be0e74b668d7e5","payload":{"connection_id":"f95883f18d264834af91809e5f803e9f","event_at":"2026-07-27T03:13:32.896000Z","event_type":"price_change","frame_hash":"bbcda070d456e2a586d85f50bad44093fd53c1c589d7a69b7443e499b7889cf9","frame_index":0,"kind":"data","monotonic_ns":223996139625083,"payload":{"event_type":"price_change","market":"0xf9d60bb033695053c4d1d8592e52171c1042f64b41a4b72e09dcc6f4852b6670","price_changes":[{"asset_id":"8698449539441374295770236407991735029336433231649246775082939325523552031992","best_ask":"0.82","best_bid":"0.81","hash":"4637bc56e27ecd1143641c1d529916c974899630","price":"0.78","side":"BUY","size":"112.73"},{"asset_id":"96283536366176669581486355171583722558858323126916278856549586825357358273536","best_ask":"0.19","best_bid":"0.18","hash":"248dbd0bc098282efdd2cce491fe423f2b929c36","price":"0.22","side":"SELL","size":"112.73"}],"timestamp":"1785122012896"},"payload_hash":"c33264ae7b903ba87c19584772ab00c7d19895105db6103df2c450d9370a8de0","raw_frame":"{\"market\":\"0xf9d60bb033695053c4d1d8592e52171c1042f64b41a4b72e09dcc6f4852b6670\", \"price_changes\":[{\"asset_id\":\"8698449539441374295770236407991735029336433231649246775082939325523552031992\", \"price\":\"0.78\", \"size\":\"112.73\", \"side\":\"BUY\", \"hash\":\"4637bc56e27ecd1143641c1d529916c974899630\", \"best_bid\":\"0.81\", \"best_ask\":\"0.82\"}, {\"asset_id\":\"96283536366176669581486355171583722558858323126916278856549586825357358273536\", \"price\":\"0.22\", \"size\":\"112.73\", \"side\":\"SELL\", \"hash\":\"248dbd0bc098282efdd2cce491fe423f2b929c36\", \"best_bid\":\"0.18\", \"best_ask\":\"0.19\"}], \"timestamp\":\"1785122012896\", \"event_type\":\"price_change\"}","received_at":"2026-07-27T03:13:32.807178Z","schema_version":"clob-market-ws.price_change.v1","sequence":null,"server_hash":null,"server_timestamp":"1785122012896","session_id":"ff6d21c8283948938400a32613abec2c","source":"clob_market_ws"},"received_at":"2026-07-27T03:13:32.807178Z","record_id":"00d18838be3f173e5f684ed04b5c8253f6ee5e4ef98cb168d58add7cb7db832c","schema_fingerprint":"4aa3821a28b0b7c2400bc59aba4bcc0a76e971dadd19610d3ad38c768e124dc7","schema_version":"edge-lab-recorder.raw.v1","sequence":null,"source":"clob_market_ws"}
{"event_at":"2026-07-27T03:13:32.897000Z","event_fingerprint":"a32aeb2c1fbdae7e8c5ca8c099a833ff4107e7352108a0c61000c2c46299437d","payload":{"connection_id":"f95883f18d264834af91809e5f803e9f","event_at":"2026-07-27T03:13:32.897000Z","event_type":"price_change","frame_hash":"177fd9b6c20089c4a4528acfb3483b677029727db360379f3096420eaab82fc1","frame_index":0,"kind":"data","monotonic_ns":223996141384708,"payload":{"event_type":"price_change","market":"0xf9d60bb033695053c4d1d8592e52171c1042f64b41a4b72e09dcc6f4852b6670","price_changes":[{"asset_id":"8698449539441374295770236407991735029336433231649246775082939325523552031992","best_ask":"0.82","best_bid":"0.81","hash":"149e596b7809fd42491973fb5a7642c3f33ea99e","price":"0.79","side":"BUY","size":"121"},{"asset_id":"96283536366176669581486355171583722558858323126916278856549586825357358273536","best_ask":"0.19","best_bid":"0.18","hash":"6775d80ad162beacc3049fff858835593fc43e78","price":"0.21","side":"SELL","size":"121"}],"timestamp":"1785122012897"},"payload_hash":"db217f5e9d1e063e0d8f2d7f585ee94a05d3c84221650fcc31e3024a8b5940c4","raw_frame":"{\"market\":\"0xf9d60bb033695053c4d1d8592e52171c1042f64b41a4b72e09dcc6f4852b6670\", \"price_changes\":[{\"asset_id\":\"8698449539441374295770236407991735029336433231649246775082939325523552031992\", \"price\":\"0.79\", \"size\":\"121\", \"side\":\"BUY\", \"hash\":\"149e596b7809fd42491973fb5a7642c3f33ea99e\", \"best_bid\":\"0.81\", \"best_ask\":\"0.82\"}, {\"asset_id\":\"96283536366176669581486355171583722558858323126916278856549586825357358273536\", \"price\":\"0.21\", \"size\":\"121\", \"side\":\"SELL\", \"hash\":\"6775d80ad162beacc3049fff858835593fc43e78\", \"best_bid\":\"0.18\", \"best_ask\":\"0.19\"}], \"timestamp\":\"1785122012897\", \"event_type\":\"price_change\"}","received_at":"2026-07-27T03:13:32.808935Z","schema_version":"clob-market-ws.price_change.v1","sequence":null,"server_hash":null,"server_timestamp":"1785122012897","session_id":"ff6d21c8283948938400a32613abec2c","source":"clob_market_ws"},"received_at":"2026-07-27T03:13:32.808935Z","record_id":"35c8ffb43fdbad6e1eb1fad267a60b0b419b11d9290fef1b3a07b6fe28f253a9","schema_fingerprint":"4aa3821a28b0b7c2400bc59aba4bcc0a76e971dadd19610d3ad38c768e124dc7","schema_version":"edge-lab-recorder.raw.v1","sequence":null,"source":"clob_market_ws"}
{"event_at":"2026-07-27T03:13:32.898000Z","event_fingerprint":"8500fd6b5cd5dc4cd3e67dfc316c19cce1d3bcb805ffa04402d2ac078ecdd012","payload":{"connection_id":"f95883f18d264834af91809e5f803e9f","event_at":"2026-07-27T03:13:32.898000Z","event_type":"price_change","frame_hash":"d56d08a31aacc65662f6cf94cf9662c5350a12e75a44ad610c7532095063dc2b","frame_index":0,"kind":"data","monotonic_ns":223996143259750,"payload":{"event_type":"price_change","market":"0xf9d60bb033695053c4d1d8592e52171c1042f64b41a4b72e09dcc6f4852b6670","price_changes":[{"asset_id":"8698449539441374295770236407991735029336433231649246775082939325523552031992","best_ask":"0.82","best_bid":"0.81","hash":"dc3f67ed72a1c0500885a06c0b657a7b001df599","price":"0.81","side":"BUY","size":"93"},{"asset_id":"96283536366176669581486355171583722558858323126916278856549586825357358273536","best_ask":"0.19","best_bid":"0.18","hash":"3f61b2fccee146e016d06867555ea0b5f33b6e6a","price":"0.19","side":"SELL","size":"93"}],"timestamp":"1785122012898"},"payload_hash":"6d28845a21f0a0c025744650ed3d9fbbdeeb2ce74d0360d6060403c2bd35441d","raw_frame":"{\"market\":\"0xf9d60bb033695053c4d1d8592e52171c1042f64b41a4b72e09dcc6f4852b6670\", \"price_changes\":[{\"asset_id\":\"8698449539441374295770236407991735029336433231649246775082939325523552031992\", \"price\":\"0.81\", \"size\":\"93\", \"side\":\"BUY\", \"hash\":\"dc3f67ed72a1c0500885a06c0b657a7b001df599\", \"best_bid\":\"0.81\", \"best_ask\":\"0.82\"}, {\"asset_id\":\"96283536366176669581486355171583722558858323126916278856549586825357358273536\", \"price\":\"0.19\", \"size\":\"93\", \"side\":\"SELL\", \"hash\":\"3f61b2fccee146e016d06867555ea0b5f33b6e6a\", \"best_bid\":\"0.18\", \"best_ask\":\"0.19\"}], \"timestamp\":\"1785122012898\", \"event_type\":\"price_change\"}","received_at":"2026-07-27T03:13:32.810802Z","schema_version":"clob-market-ws.price_change.v1","sequence":null,"server_hash":null,"server_timestamp":"1785122012898","session_id":"ff6d21c8283948938400a32613abec2c","source":"clob_market_ws"},"received_at":"2026-07-27T03:13:32.810802Z","record_id":"49113da05ffede2dfa16b389e9cd8162a1098ec78b28a3918a28e8c8c054317d","schema_fingerprint":"4aa3821a28b0b7c2400bc59aba4bcc0a76e971dadd19610d3ad38c768e124dc7","schema_version":"edge-lab-recorder.raw.v1","sequence":null,"source":"clob_market_ws"}
{"event_at":"2026-07-27T03:13:32.899000Z","event_fingerprint":"1a3180f2d6804169b7bcf0ce0ea1b48634855441361ba09e9a4a3f14ee132ba9","payload":{"connection_id":"f95883f18d264834af91809e5f803e9f","event_at":"2026-07-27T03:13:32.899000Z","event_type":"price_change","frame_hash":"445d90c46fe3fc405ec3ec6375fb4cb362f0d192a43d5ab56487f8ff3ec1c9da","frame_index":0,"kind":"data","monotonic_ns":223996144961666,"payload":{"event_type":"price_change","market":"0xf9d60bb033695053c4d1d8592e52171c1042f64b41a4b72e09dcc6f4852b6670","price_changes":[{"asset_id":"96283536366176669581486355171583722558858323126916278856549586825357358273536","best_ask":"0.19","best_bid":"0.18","hash":"70c44f5cc304f0889e0995a1645c7f38b563a1a5","price":"0.12","side":"BUY","size":"121.8"},{"asset_id":"8698449539441374295770236407991735029336433231649246775082939325523552031992","best_ask":"0.82","best_bid":"0.81","hash":"92a86f37cd16592a2156f28758f7b5ecc4da59bc","price":"0.88","side":"SELL","size":"121.8"}],"timestamp":"1785122012899"},"payload_hash":"4512e0b857ea4c98a1e1fbf9c05c3212ff4798c861c08d5510dcf21375570e83","raw_frame":"{\"market\":\"0xf9d60bb033695053c4d1d8592e52171c1042f64b41a4b72e09dcc6f4852b6670\", \"price_changes\":[{\"asset_id\":\"96283536366176669581486355171583722558858323126916278856549586825357358273536\", \"price\":\"0.12\", \"size\":\"121.8\", \"side\":\"BUY\", \"hash\":\"70c44f5cc304f0889e0995a1645c7f38b563a1a5\", \"best_bid\":\"0.18\", \"best_ask\":\"0.19\"}, {\"asset_id\":\"8698449539441374295770236407991735029336433231649246775082939325523552031992\", \"price\":\"0.88\", \"size\":\"121.8\", \"side\":\"SELL\", \"hash\":\"92a86f37cd16592a2156f28758f7b5ecc4da59bc\", \"best_bid\":\"0.81\", \"best_ask\":\"0.82\"}], \"timestamp\":\"1785122012899\", \"event_type\":\"price_change\"}","received_at":"2026-07-27T03:13:32.812519Z","schema_version":"clob-market-ws.price_change.v1","sequence":null,"server_hash":null,"server_timestamp":"1785122012899","session_id":"ff6d21c8283948938400a32613abec2c","source":"clob_market_ws"},"received_at":"2026-07-27T03:13:32.812519Z","record_id":"1342c47415428c034a05fe4369fbbabdb2498f9ab6c20850600be997a86cc664","schema_fingerprint":"4aa3821a28b0b7c2400bc59aba4bcc0a76e971dadd19610d3ad38c768e124dc7","schema_version":"edge-lab-recorder.raw.v1","sequence":null,"source":"clob_market_ws"}
{"event_at":"2026-07-27T03:13:32.900000Z","event_fingerprint":"925254d7ff2c93779015894d70c93b3a49133cfeb2ccaa2075f08c6c075c4b64","payload":{"connection_id":"f95883f18d264834af91809e5f803e9f","event_at":"2026-07-27T03:13:32.900000Z","event_type":"price_change","frame_hash":"9d94de6d629cb1e9f1c6d751aa2b0310ee1d40d21efc5582b5eecf725126d7ab","frame_index":0,"kind":"data","monotonic_ns":223996146648625,"payload":{"event_type":"price_change","market":"0xf9d60bb033695053c4d1d8592e52171c1042f64b41a4b72e09dcc6f4852b6670","price_changes":[{"asset_id":"8698449539441374295770236407991735029336433231649246775082939325523552031992","best_ask":"0.82","best_bid":"0.81","hash":"769858c47ff6eca43c0386df1d8343ac20e99dca","price":"0.8","side":"BUY","size":"89.76"},{"asset_id":"96283536366176669581486355171583722558858323126916278856549586825357358273536","best_ask":"0.19","best_bid":"0.18","hash":"c112d50acf645f487ef5abf3ca8181c82f09fe42","price":"0.2","side":"SELL","size":"89.76"}],"timestamp":"1785122012900"},"payload_hash":"b716407903e2cec5f29ce0cc568fb8a7647f7a003938169a34685fdc6abe30c4","raw_frame":"{\"market\":\"0xf9d60bb033695053c4d1d8592e52171c1042f64b41a4b72e09dcc6f4852b6670\", \"price_changes\":[{\"asset_id\":\"8698449539441374295770236407991735029336433231649246775082939325523552031992\", \"price\":\"0.8\", \"size\":\"89.76\", \"side\":\"BUY\", \"hash\":\"769858c47ff6eca43c0386df1d8343ac20e99dca\", \"best_bid\":\"0.81\", \"best_ask\":\"0.82\"}, {\"asset_id\":\"96283536366176669581486355171583722558858323126916278856549586825357358273536\", \"price\":\"0.2\", \"size\":\"89.76\", \"side\":\"SELL\", \"hash\":\"c112d50acf645f487ef5abf3ca8181c82f09fe42\", \"best_bid\":\"0.18\", \"best_ask\":\"0.19\"}], \"timestamp\":\"1785122012900\", \"event_type\":\"price_change\"}","received_at":"2026-07-27T03:13:32.814206Z","schema_version":"clob-market-ws.price_change.v1","sequence":null,"server_hash":null,"server_timestamp":"1785122012900","session_id":"ff6d21c8283948938400a32613abec2c","source":"clob_market_ws"},"received_at":"2026-07-27T03:13:32.814206Z","record_id":"7bb022cc38f9bf0ef671e3d685c5f2f956db8766210012067e1dc504413fac30","schema_fingerprint":"4aa3821a28b0b7c2400bc59aba4bcc0a76e971dadd19610d3ad38c768e124dc7","schema_version":"edge-lab-recorder.raw.v1","sequence":null,"source":"clob_market_ws"}
{"event_at":"2026-07-27T03:13:32.905000Z","event_fingerprint":"66b49ac72afaa874312eb7289995b70571dcc03a4c3cdc171c919a332258a600","payload":{"connection_id":"f95883f18d264834af91809e5f803e9f","event_at":"2026-07-27T03:13:32.905000Z","event_type":"price_change","frame_hash":"832a9f7fed9733de900a40322edd6797c31bf5b6c57fd0283bdfd6f3bfec9299","frame_index":0,"kind":"data","monotonic_ns":223996148159583,"payload":{"event_type":"price_change","market":"0xf9d60bb033695053c4d1d8592e52171c1042f64b41a4b72e09dcc6f4852b6670","price_changes":[{"asset_id":"8698449539441374295770236407991735029336433231649246775082939325523552031992","best_ask":"0.82","best_bid":"0.81","hash":"1e6fb9d3d0bdcecd0a1f512a2e35e8637968abc3","price":"0.77","side":"BUY","size":"177.4"},{"asset_id":"96283536366176669581486355171583722558858323126916278856549586825357358273536","best_ask":"0.19","best_bid":"0.18","hash":"3d691be312b5ff2fc8030262f69fe5adba4eee73","price":"0.23","side":"SELL","size":"177.4"}],"timestamp":"1785122012905"},"payload_hash":"d1f8b21f58cd23f4fdf704fbefafb45789fd5cc8880a87cad0fede926a720172","raw_frame":"{\"market\":\"0xf9d60bb033695053c4d1d8592e52171c1042f64b41a4b72e09dcc6f4852b6670\", \"price_changes\":[{\"asset_id\":\"8698449539441374295770236407991735029336433231649246775082939325523552031992\", \"price\":\"0.77\", \"size\":\"177.4\", \"side\":\"BUY\", \"hash\":\"1e6fb9d3d0bdcecd0a1f512a2e35e8637968abc3\", \"best_bid\":\"0.81\", \"best_ask\":\"0.82\"}, {\"asset_id\":\"96283536366176669581486355171583722558858323126916278856549586825357358273536\", \"price\":\"0.23\", \"size\":\"177.4\", \"side\":\"SELL\", \"hash\":\"3d691be312b5ff2fc8030262f69fe5adba4eee73\", \"best_bid\":\"0.18\", \"best_ask\":\"0.19\"}], \"timestamp\":\"1785122012905\", \"event_type\":\"price_change\"}","received_at":"2026-07-27T03:13:32.815716Z","schema_version":"clob-market-ws.price_change.v1","sequence":null,"server_hash":null,"server_timestamp":"1785122012905","session_id":"ff6d21c8283948938400a32613abec2c","source":"clob_market_ws"},"received_at":"2026-07-27T03:13:32.815716Z","record_id":"c92d29b761b490fa27b171064ffab1c0ff85cec5d450b5cbdad80603f265d26d","schema_fingerprint":"4aa3821a28b0b7c2400bc59aba4bcc0a76e971dadd19610d3ad38c768e124dc7","schema_version":"edge-lab-recorder.raw.v1","sequence":null,"source":"clob_market_ws"}
{"event_at":"2026-07-27T03:13:32.907000Z","event_fingerprint":"2b201ead42a991e5f01423d0ca8bbf3c2e999de533f97060827dcc5626668cb8","payload":{"connection_id":"f95883f18d264834af91809e5f803e9f","event_at":"2026-07-27T03:13:32.907000Z","event_type":"price_change","frame_hash":"d5de6548467c9bf0974d6a22b2b3efb90ac658a2e4aa7af7331bab9d876d682b","frame_index":0,"kind":"data","monotonic_ns":223996155850875,"payload":{"event_type":"price_change","market":"0xf9d60bb033695053c4d1d8592e52171c1042f64b41a4b72e09dcc6f4852b6670","price_changes":[{"asset_id":"8698449539441374295770236407991735029336433231649246775082939325523552031992","best_ask":"0.82","best_bid":"0.81","hash":"0c8c5269127529e2de904a3c5b46eec0ceabc3bf","price":"0.77","side":"BUY","size":"162.7"},{"asset_id":"96283536366176669581486355171583722558858323126916278856549586825357358273536","best_ask":"0.19","best_bid":"0.18","hash":"1db2b3f68ce521980ea7a9ad93dfc6eb61aa21d4","price":"0.23","side":"SELL","size":"162.7"}],"timestamp":"1785122012907"},"payload_hash":"52da2eb09ed9a04b879bd1318a9c88b858cf7403156123e1dbbe8a72c4b37db0","raw_frame":"{\"market\":\"0xf9d60bb033695053c4d1d8592e52171c1042f64b41a4b72e09dcc6f4852b6670\", \"price_changes\":[{\"asset_id\":\"8698449539441374295770236407991735029336433231649246775082939325523552031992\", \"price\":\"0.77\", \"size\":\"162.7\", \"side\":\"BUY\", \"hash\":\"0c8c5269127529e2de904a3c5b46eec0ceabc3bf\", \"best_bid\":\"0.81\", \"best_ask\":\"0.82\"}, {\"asset_id\":\"96283536366176669581486355171583722558858323126916278856549586825357358273536\", \"price\":\"0.23\", \"size\":\"162.7\", \"side\":\"SELL\", \"hash\":\"1db2b3f68ce521980ea7a9ad93dfc6eb61aa21d4\", \"best_bid\":\"0.18\", \"best_ask\":\"0.19\"}], \"timestamp\":\"1785122012907\", \"event_type\":\"price_change\"}","received_at":"2026-07-27T03:13:32.823406Z","schema_version":"clob-market-ws.price_change.v1","sequence":null,"server_hash":null,"server_timestamp":"1785122012907","session_id":"ff6d21c8283948938400a32613abec2c","source":"clob_market_ws"},"received_at":"2026-07-27T03:13:32.823406Z","record_id":"b0f3d57c71a3b14a7b3e55bebdc4107fa61c3d4f1f6ed10292698bd1de02c487","schema_fingerprint":"4aa3821a28b0b7c2400bc59aba4bcc0a76e971dadd19610d3ad38c768e124dc7","schema_version":"edge-lab-recorder.raw.v1","sequence":null,"source":"clob_market_ws"}
{"event_at":"2026-07-27T03:13:32.911000Z","event_fingerprint":"84109cea309079efb2c7ce2f4610cb83f107eb18039703a05e93f056a6dd60a5","payload":{"connection_id":"f95883f18d264834af91809e5f803e9f","event_at":"2026-07-27T03:13:32.911000Z","event_type":"price_change","frame_hash":"d4b7e0a1903c6e92ad9188ce428f142191c24eb97ae5415d48530966dc9b1727","frame_index":0,"kind":"data","monotonic_ns":223996157381708,"payload":{"event_type":"price_change","market":"0xf9d60bb033695053c4d1d8592e52171c1042f64b41a4b72e09dcc6f4852b6670","price_changes":[{"asset_id":"8698449539441374295770236407991735029336433231649246775082939325523552031992","best_ask":"0.82","best_bid":"0.81","hash":"a9bc3c7f7ab0acc79af0290f63913dfee578f169","price":"0.75","side":"BUY","size":"93"},{"asset_id":"96283536366176669581486355171583722558858323126916278856549586825357358273536","best_ask":"0.19","best_bid":"0.18","hash":"96c3fb7f8cce09f179db89dee6aa122aa43778a6","price":"0.25","side":"SELL","size":"93"}],"timestamp":"1785122012911"},"payload_hash":"172c78c52d6990c235d3e4badbe3d388d054d1ba6dfb5405967dfe3af9e2ef49","raw_frame":"{\"market\":\"0xf9d60bb033695053c4d1d8592e52171c1042f64b41a4b72e09dcc6f4852b6670\", \"price_changes\":[{\"asset_id\":\"8698449539441374295770236407991735029336433231649246775082939325523552031992\", \"price\":\"0.75\", \"size\":\"93\", \"side\":\"BUY\", \"hash\":\"a9bc3c7f7ab0acc79af0290f63913dfee578f169\", \"best_bid\":\"0.81\", \"best_ask\":\"0.82\"}, {\"asset_id\":\"96283536366176669581486355171583722558858323126916278856549586825357358273536\", \"price\":\"0.25\", \"size\":\"93\", \"side\":\"SELL\", \"hash\":\"96c3fb7f8cce09f179db89dee6aa122aa43778a6\", \"best_bid\":\"0.18\", \"best_ask\":\"0.19\"}], \"timestamp\":\"1785122012911\", \"event_type\":\"price_change\"}","received_at":"2026-07-27T03:13:32.824939Z","schema_version":"clob-market-ws.price_change.v1","sequence":null,"server_hash":null,"server_timestamp":"1785122012911","session_id":"ff6d21c8283948938400a32613abec2c","source":"clob_market_ws"},"received_at":"2026-07-27T03:13:32.824939Z","record_id":"6fa6598eb868f7affe72688cae4309864b528a968d87e694316998033750ea85","schema_fingerprint":"4aa3821a28b0b7c2400bc59aba4bcc0a76e971dadd19610d3ad38c768e124dc7","schema_version":"edge-lab-recorder.raw.v1","sequence":null,"source":"clob_market_ws"}
{"event_at":"2026-07-27T03:13:32.912000Z","event_fingerprint":"2a60b233f1c58a7b44fa52dd68694d33fdd8167a67d877b5ccd6c4cad22adf5e","payload":{"connection_id":"f95883f18d264834af91809e5f803e9f","event_at":"2026-07-27T03:13:32.912000Z","event_type":"price_change","frame_hash":"bc34f23358e93a75446068a7a49664e8375bb6e34789415967370d24708409b6","frame_index":0,"kind":"data","monotonic_ns":223996159099458,"payload":{"event_type":"price_change","market":"0xf9d60bb033695053c4d1d8592e52171c1042f64b41a4b72e09dcc6f4852b6670","price_changes":[{"asset_id":"8698449539441374295770236407991735029336433231649246775082939325523552031992","best_ask":"0.82","best_bid":"0.81","hash":"9db55f9c157105c659f315fbf471cda53815ab32","price":"0.76","side":"BUY","size":"173.92"},{"asset_id":"96283536366176669581486355171583722558858323126916278856549586825357358273536","best_ask":"0.19","best_bid":"0.18","hash":"b74986c95b7471bcdbc0f622d60535c0cd2e477c","price":"0.24","side":"SELL","size":"173.92"}],"timestamp":"1785122012912"},"payload_hash":"8655b306b156c2b6db9ee5d0bc55b221a32010f9fa8a73db0fe630a59637ca3d","raw_frame":"{\"market\":\"0xf9d60bb033695053c4d1d8592e52171c1042f64b41a4b72e09dcc6f4852b6670\", \"price_changes\":[{\"asset_id\":\"8698449539441374295770236407991735029336433231649246775082939325523552031992\", \"price\":\"0.76\", \"size\":\"173.92\", \"side\":\"BUY\", \"hash\":\"9db55f9c157105c659f315fbf471cda53815ab32\", \"best_bid\":\"0.81\", \"best_ask\":\"0.82\"}, {\"asset_id\":\"96283536366176669581486355171583722558858323126916278856549586825357358273536\", \"price\":\"0.24\", \"size\":\"173.92\", \"side\":\"SELL\", \"hash\":\"b74986c95b7471bcdbc0f622d60535c0cd2e477c\", \"best_bid\":\"0.18\", \"best_ask\":\"0.19\"}], \"timestamp\":\"1785122012912\", \"event_type\":\"price_change\"}","received_at":"2026-07-27T03:13:32.826657Z","schema_version":"clob-market-ws.price_change.v1","sequence":null,"server_hash":null,"server_timestamp":"1785122012912","session_id":"ff6d21c8283948938400a32613abec2c","source":"clob_market_ws"},"received_at":"2026-07-27T03:13:32.826657Z","record_id":"de9da7eb2e38f171e8d978a284611d28c33d87da76a97a23757f59326b8a5466","schema_fingerprint":"4aa3821a28b0b7c2400bc59aba4bcc0a76e971dadd19610d3ad38c768e124dc7","schema_version":"edge-lab-recorder.raw.v1","sequence":null,"source":"clob_market_ws"}
{"event_at":"2026-07-27T03:13:32.913000Z","event_fingerprint":"c39143b50c65baee122f74e5c2ad850bdd36e9b7721f8f6c1213b79c37b3c994","payload":{"connection_id":"f95883f18d264834af91809e5f803e9f","event_at":"2026-07-27T03:13:32.913000Z","event_type":"price_change","frame_hash":"402ee4a3bd1c47fe33f08f183c0bb98806e4c696b8cbc080ee37c4fb3263022c","frame_index":0,"kind":"data","monotonic_ns":223996160618416,"payload":{"event_type":"price_change","market":"0xf9d60bb033695053c4d1d8592e52171c1042f64b41a4b72e09dcc6f4852b6670","price_changes":[{"asset_id":"96283536366176669581486355171583722558858323126916278856549586825357358273536","best_ask":"0.19","best_bid":"0.18","hash":"31146c7149b33fe5585f9be523f180372caff922","price":"0.12","side":"BUY","size":"116.8"},{"asset_id":"8698449539441374295770236407991735029336433231649246775082939325523552031992","best_ask":"0.82","best_bid":"0.81","hash":"34cacf387549e00ba42ec375bea346ff084991f3","price":"0.88","side":"SELL","size":"116.8"}],"timestamp":"1785122012913"},"payload_hash":"8a64d114736eb58939503f4dce87bf3f551573ff4fdf07f17bb6431159c9c9db","raw_frame":"{\"market\":\"0xf9d60bb033695053c4d1d8592e52171c1042f64b41a4b72e09dcc6f4852b6670\", \"price_changes\":[{\"asset_id\":\"96283536366176669581486355171583722558858323126916278856549586825357358273536\", \"price\":\"0.12\", \"size\":\"116.8\", \"side\":\"BUY\", \"hash\":\"31146c7149b33fe5585f9be523f180372caff922\", \"best_bid\":\"0.18\", \"best_ask\":\"0.19\"}, {\"asset_id\":\"8698449539441374295770236407991735029336433231649246775082939325523552031992\", \"price\":\"0.88\", \"size\":\"116.8\", \"side\":\"SELL\", \"hash\":\"34cacf387549e00ba42ec375bea346ff084991f3\", \"best_bid\":\"0.81\", \"best_ask\":\"0.82\"}], \"timestamp\":\"1785122012913\", \"event_type\":\"price_change\"}","received_at":"2026-07-27T03:13:32.828175Z","schema_version":"clob-market-ws.price_change.v1","sequence":null,"server_hash":null,"server_timestamp":"1785122012913","session_id":"ff6d21c8283948938400a32613abec2c","source":"clob_market_ws"},"received_at":"2026-07-27T03:13:32.828175Z","record_id":"3bac6863dc23b49273be3b520483679366483e5dcc4c1b48927d9c423351e703","schema_fingerprint":"4aa3821a28b0b7c2400bc59aba4bcc0a76e971dadd19610d3ad38c768e124dc7","schema_version":"edge-lab-recorder.raw.v1","sequence":null,"source":"clob_market_ws"}
{"event_at":"2026-07-27T03:13:32.914000Z","event_fingerprint":"ff5ba113cd384e89e7e878a5043cdf2a358d06d340cefe95ab7ffa710fd77757","payload":{"connection_id":"f95883f18d264834af91809e5f803e9f","event_at":"2026-07-27T03:13:32.914000Z","event_type":"price_change","frame_hash":"1159cf8d56bda0363fad4fe7ab59b4c412ff755ce3aeebf86a4a63cc54cea00d","frame_index":0,"kind":"data","monotonic_ns":223996162098875,"payload":{"event_type":"price_change","market":"0xf9d60bb033695053c4d1d8592e52171c1042f64b41a4b72e09dcc6f4852b6670","price_changes":[{"asset_id":"96283536366176669581486355171583722558858323126916278856549586825357358273536","best_ask":"0.19","best_bid":"0.18","hash":"f8e4a92675cbb9df3a7d0788f326c580e526b59c","price":"0.16","side":"BUY","size":"19"},{"asset_id":"8698449539441374295770236407991735029336433231649246775082939325523552031992","best_ask":"0.82","best_bid":"0.81","hash":"a9b57984019b062a1855806dd69e61ee6e5f4524","price":"0.84","side":"SELL","size":"19"}],"timestamp":"1785122012914"},"payload_hash":"1fd66e83badf13321a3cdad2b3363f34558af5135d861f5d0420ab39d92bd1e5","raw_frame":"{\"market\":\"0xf9d60bb033695053c4d1d8592e52171c1042f64b41a4b72e09dcc6f4852b6670\", \"price_changes\":[{\"asset_id\":\"96283536366176669581486355171583722558858323126916278856549586825357358273536\", \"price\":\"0.16\", \"size\":\"19\", \"side\":\"BUY\", \"hash\":\"f8e4a92675cbb9df3a7d0788f326c580e526b59c\", \"best_bid\":\"0.18\", \"best_ask\":\"0.19\"}, {\"asset_id\":\"8698449539441374295770236407991735029336433231649246775082939325523552031992\", \"price\":\"0.84\", \"size\":\"19\", \"side\":\"SELL\", \"hash\":\"a9b57984019b062a1855806dd69e61ee6e5f4524\", \"best_bid\":\"0.81\", \"best_ask\":\"0.82\"}], \"timestamp\":\"1785122012914\", \"event_type\":\"price_change\"}","received_at":"2026-07-27T03:13:32.829657Z","schema_version":"clob-market-ws.price_change.v1","sequence":null,"server_hash":null,"server_timestamp":"1785122012914","session_id":"ff6d21c8283948938400a32613abec2c","source":"clob_market_ws"},"received_at":"2026-07-27T03:13:32.829657Z","record_id":"1eaddec9dc73ea2eb0c439051d559779112dc6a9f151b9ea9b9c86e40225e95c","schema_fingerprint":"4aa3821a28b0b7c2400bc59aba4bcc0a76e971dadd19610d3ad38c768e124dc7","schema_version":"edge-lab-recorder.raw.v1","sequence":null,"source":"clob_market_ws"}
{"event_at":"2026-07-27T03:13:32.915000Z","event_fingerprint":"3f28a592d8c193112aeeae0fbf4cdded5b915a22cf1beb952def8cb6d2f1766f","payload":{"connection_id":"f95883f18d264834af91809e5f803e9f","event_at":"2026-07-27T03:13:32.915000Z","event_type":"price_change","frame_hash":"c08c7aec2c54fd2a98bf49d223b52a49729f2411e1086d64b0a629a052a13869","frame_index":0,"kind":"data","monotonic_ns":223996163646500,"payload":{"event_type":"price_change","market":"0xf9d60bb033695053c4d1d8592e52171c1042f64b41a4b72e09dcc6f4852b6670","price_changes":[{"asset_id":"8698449539441374295770236407991735029336433231649246775082939325523552031992","best_ask":"0.82","best_bid":"0.81","hash":"6ad854311b1c55c66745812a629a0b1a0bc9b156","price":"0.01","side":"BUY","size":"8017.52"},{"asset_id":"96283536366176669581486355171583722558858323126916278856549586825357358273536","best_ask":"0.19","best_bid":"0.18","hash":"940dd2427ff13445ee397417c29b174d0836e1db","price":"0.99","side":"SELL","size":"8017.52"}],"timestamp":"1785122012915"},"payload_hash":"815c62b0fb1059eb8d50fecf287bdcc1d0fb456981da5947861311e3558f4f9e","raw_frame":"{\"market\":\"0xf9d60bb033695053c4d1d8592e52171c1042f64b41a4b72e09dcc6f4852b6670\", \"price_changes\":[{\"asset_id\":\"8698449539441374295770236407991735029336433231649246775082939325523552031992\", \"price\":\"0.01\", \"size\":\"8017.52\", \"side\":\"BUY\", \"hash\":\"6ad854311b1c55c66745812a629a0b1a0bc9b156\", \"best_bid\":\"0.81\", \"best_ask\":\"0.82\"}, {\"asset_id\":\"96283536366176669581486355171583722558858323126916278856549586825357358273536\", \"price\":\"0.99\", \"size\":\"8017.52\", \"side\":\"SELL\", \"hash\":\"940dd2427ff13445ee397417c29b174d0836e1db\", \"best_bid\":\"0.18\", \"best_ask\":\"0.19\"}], \"timestamp\":\"1785122012915\", \"event_type\":\"price_change\"}","received_at":"2026-07-27T03:13:32.831201Z","schema_version":"clob-market-ws.price_change.v1","sequence":null,"server_hash":null,"server_timestamp":"1785122012915","session_id":"ff6d21c8283948938400a32613abec2c","source":"clob_market_ws"},"received_at":"2026-07-27T03:13:32.831201Z","record_id":"ce5af4b6c093096a220be660e3e470a1e4cb881aa8bec172fe47fee4aef26ad3","schema_fingerprint":"4aa3821a28b0b7c2400bc59aba4bcc0a76e971dadd19610d3ad38c768e124dc7","schema_version":"edge-lab-recorder.raw.v1","sequence":null,"source":"clob_market_ws"}
{"event_at":"2026-07-27T03:13:32.915000Z","event_fingerprint":"165e57ffabb3751088c8e151993bd56990f0c3826481c3b0c55bc5c85c37a79e","payload":{"connection_id":"f95883f18d264834af91809e5f803e9f","event_at":"2026-07-27T03:13:32.915000Z","event_type":"price_change","frame_hash":"5384472ac493c29a76c1a86c7695d8c8794b8e12564595d4caaca3332860fc6e","frame_index":0,"kind":"data","monotonic_ns":223996165334541,"payload":{"event_type":"price_change","market":"0xf9d60bb033695053c4d1d8592e52171c1042f64b41a4b72e09dcc6f4852b6670","price_changes":[{"asset_id":"96283536366176669581486355171583722558858323126916278856549586825357358273536","best_ask":"0.19","best_bid":"0.18","hash":"4c6a59cc5f6d38dbf6f11eea786513c8ba11356d","price":"0.01","side":"BUY","size":"7139.52"},{"asset_id":"8698449539441374295770236407991735029336433231649246775082939325523552031992","best_ask":"0.82","best_bid":"0.81","hash":"8fbf660a3a1b1b7f1a00de67a358528a55820ba8","price":"0.99","side":"SELL","size":"7139.52"}],"timestamp":"1785122012915"},"payload_hash":"3b64eb94c8053aa9a7608db985ac829107686b5dbb73cc30f3d25b069d06eef8","raw_frame":"{\"market\":\"0xf9d60bb033695053c4d1d8592e52171c1042f64b41a4b72e09dcc6f4852b6670\", \"price_changes\":[{\"asset_id\":\"96283536366176669581486355171583722558858323126916278856549586825357358273536\", \"price\":\"0.01\", \"size\":\"7139.52\", \"side\":\"BUY\", \"hash\":\"4c6a59cc5f6d38dbf6f11eea786513c8ba11356d\", \"best_bid\":\"0.18\", \"best_ask\":\"0.19\"}, {\"asset_id\":\"8698449539441374295770236407991735029336433231649246775082939325523552031992\", \"price\":\"0.99\", \"size\":\"7139.52\", \"side\":\"SELL\", \"hash\":\"8fbf660a3a1b1b7f1a00de67a358528a55820ba8\", \"best_bid\":\"0.81\", \"best_ask\":\"0.82\"}], \"timestamp\":\"1785122012915\", \"event_type\":\"price_change\"}","received_at":"2026-07-27T03:13:32.832892Z","schema_version":"clob-market-ws.price_change.v1","sequence":null,"server_hash":null,"server_timestamp":"1785122012915","session_id":"ff6d21c8283948938400a32613abec2c","source":"clob_market_ws"},"received_at":"2026-07-27T03:13:32.832892Z","record_id":"d0b218fbf25219b3845ff97a3f929e4e982880bd8fa168b10aa2d14b27d99952","schema_fingerprint":"4aa3821a28b0b7c2400bc59aba4bcc0a76e971dadd19610d3ad38c768e124dc7","schema_version":"edge-lab-recorder.raw.v1","sequence":null,"source":"clob_market_ws"}
{"event_at":"2026-07-27T03:13:32.918000Z","event_fingerprint":"5688df0f1b32e8b0f357843dba53ff60bc43030a98b37d6db7e0229a0e4bc4a6","payload":{"connection_id":"f95883f18d264834af91809e5f803e9f","event_at":"2026-07-27T03:13:32.918000Z","event_type":"price_change","frame_hash":"51d0405028f62da47ce2584b6ab3b2e4bc6a9e9fa3ea6e929e0074f4b52cebd9","frame_index":0,"kind":"data","monotonic_ns":223996166836833,"payload":{"event_type":"price_change","market":"0xf9d60bb033695053c4d1d8592e52171c1042f64b41a4b72e09dcc6f4852b6670","price_changes":[{"asset_id":"8698449539441374295770236407991735029336433231649246775082939325523552031992","best_ask":"0.82","best_bid":"0.81","hash":"1e75806260abd131bd9668209571e0cb7886d6e1","price":"0.01","side":"BUY","size":"8022.52"},{"asset_id":"96283536366176669581486355171583722558858323126916278856549586825357358273536","best_ask":"0.19","best_bid":"0.18","hash":"a3b313a294d4f33046590e23d969985a83bc0246","price":"0.99","side":"SELL","size":"8022.52"}],"timestamp":"1785122012918"},"payload_hash":"c7764edede1bb92dee6825deb619d0dd9e51e506760cafff41d3c63487178309","raw_frame":"{\"market\":\"0xf9d60bb033695053c4d1d8592e52171c1042f64b41a4b72e09dcc6f4852b6670\", \"price_changes\":[{\"asset_id\":\"8698449539441374295770236407991735029336433231649246775082939325523552031992\", \"price\":\"0.01\", \"size\":\"8022.52\", \"side\":\"BUY\", \"hash\":\"1e75806260abd131bd9668209571e0cb7886d6e1\", \"best_bid\":\"0.81\", \"best_ask\":\"0.82\"}, {\"asset_id\":\"96283536366176669581486355171583722558858323126916278856549586825357358273536\", \"price\":\"0.99\", \"size\":\"8022.52\", \"side\":\"SELL\", \"hash\":\"a3b313a294d4f33046590e23d969985a83bc0246\", \"best_bid\":\"0.18\", \"best_ask\":\"0.19\"}], \"timestamp\":\"1785122012918\", \"event_type\":\"price_change\"}","received_at":"2026-07-27T03:13:32.834394Z","schema_version":"clob-market-ws.price_change.v1","sequence":null,"server_hash":null,"server_timestamp":"1785122012918","session_id":"ff6d21c8283948938400a32613abec2c","source":"clob_market_ws"},"received_at":"2026-07-27T03:13:32.834394Z","record_id":"1dba262d3d9090976e977cd20521618cff22526340af33c6b68472744e5f8d6d","schema_fingerprint":"4aa3821a28b0b7c2400bc59aba4bcc0a76e971dadd19610d3ad38c768e124dc7","schema_version":"edge-lab-recorder.raw.v1","sequence":null,"source":"clob_market_ws"}
{"event_at":"2026-07-27T03:13:32.920000Z","event_fingerprint":"385d944b51d8dfe184f5b3fb90983aa601bbfba5800897f83051d576fdcfa9a1","payload":{"connection_id":"f95883f18d264834af91809e5f803e9f","event_at":"2026-07-27T03:13:32.920000Z","event_type":"price_change","frame_hash":"dbc22c51ace0cdf48b0d93fd21b2ef17ee14c61018e4d422b94d44918da7e8cc","frame_index":0,"kind":"data","monotonic_ns":223996168338875,"payload":{"event_type":"price_change","market":"0xf9d60bb033695053c4d1d8592e52171c1042f64b41a4b72e09dcc6f4852b6670","price_changes":[{"asset_id":"8698449539441374295770236407991735029336433231649246775082939325523552031992","best_ask":"0.82","best_bid":"0.81","hash":"dec62238d01cb7bc085d81301e69e67a1d2cf763","price":"0.01","side":"BUY","size":"8027.52"},{"asset_id":"96283536366176669581486355171583722558858323126916278856549586825357358273536","best_ask":"0.19","best_bid":"0.18","hash":"0ee3a7e1a393be9285d5c504dd3c32f4a2296226","price":"0.99","side":"SELL","size":"8027.52"}],"timestamp":"1785122012920"},"payload_hash":"4e9470849b1bada99edf0356353cfa7fc5286a55d61890ed847fe1f5c65cfecf","raw_frame":"{\"market\":\"0xf9d60bb033695053c4d1d8592e52171c1042f64b41a4b72e09dcc6f4852b6670\", \"price_changes\":[{\"asset_id\":\"8698449539441374295770236407991735029336433231649246775082939325523552031992\", \"price\":\"0.01\", \"size\":\"8027.52\", \"side\":\"BUY\", \"hash\":\"dec62238d01cb7bc085d81301e69e67a1d2cf763\", \"best_bid\":\"0.81\", \"best_ask\":\"0.82\"}, {\"asset_id\":\"96283536366176669581486355171583722558858323126916278856549586825357358273536\", \"price\":\"0.99\", \"size\":\"8027.52\", \"side\":\"SELL\", \"hash\":\"0ee3a7e1a393be9285d5c504dd3c32f4a2296226\", \"best_bid\":\"0.18\", \"best_ask\":\"0.19\"}], \"timestamp\":\"1785122012920\", \"event_type\":\"price_change\"}","received_at":"2026-07-27T03:13:32.835896Z","schema_version":"clob-market-ws.price_change.v1","sequence":null,"server_hash":null,"server_timestamp":"1785122012920","session_id":"ff6d21c8283948938400a32613abec2c","source":"clob_market_ws"},"received_at":"2026-07-27T03:13:32.835896Z","record_id":"f77a3b260076a766556bd9f7d46e12a7ed4cd9d46affa0b6649ecc8cca5908dc","schema_fingerprint":"4aa3821a28b0b7c2400bc59aba4bcc0a76e971dadd19610d3ad38c768e124dc7","schema_version":"edge-lab-recorder.raw.v1","sequence":null,"source":"clob_market_ws"}
{"event_at":"2026-07-27T03:13:32.921000Z","event_fingerprint":"cdaa1a92620f451e51987ad7efeb6c3a2b0568a78b1e5f885693061af0dc2c86","payload":{"connection_id":"f95883f18d264834af91809e5f803e9f","event_at":"2026-07-27T03:13:32.921000Z","event_type":"price_change","frame_hash":"2cf41d3d7df6a36b7640591ba923b7a3a988c32c0c16d70f262a2240888423f3","frame_index":0,"kind":"data","monotonic_ns":223996169806500,"payload":{"event_type":"price_change","market":"0xf9d60bb033695053c4d1d8592e52171c1042f64b41a4b72e09dcc6f4852b6670","price_changes":[{"asset_id":"96283536366176669581486355171583722558858323126916278856549586825357358273536","best_ask":"0.19","best_bid":"0.18","hash":"aede3d06eaf1dd6dad5b4dd52178767c26804f2b","price":"0.01","side":"BUY","size":"7134.52"},{"asset_id":"8698449539441374295770236407991735029336433231649246775082939325523552031992","best_ask":"0.82","best_bid":"0.81","hash":"590bcd2b99a06b53bac724bce7f56ccf0f230c3f","price":"0.99","side":"SELL","size":"7134.52"}],"timestamp":"1785122012921"},"payload_hash":"f1b9b65cb302cc12bd05abb8f16bb8274ed3ee67affdc7d95afd25972f37b27a","raw_frame":"{\"market\":\"0xf9d60bb033695053c4d1d8592e52171c1042f64b41a4b72e09dcc6f4852b6670\", \"price_changes\":[{\"asset_id\":\"96283536366176669581486355171583722558858323126916278856549586825357358273536\", \"price\":\"0.01\", \"size\":\"7134.52\", \"side\":\"BUY\", \"hash\":\"aede3d06eaf1dd6dad5b4dd52178767c26804f2b\", \"best_bid\":\"0.18\", \"best_ask\":\"0.19\"}, {\"asset_id\":\"8698449539441374295770236407991735029336433231649246775082939325523552031992\", \"price\":\"0.99\", \"size\":\"7134.52\", \"side\":\"SELL\", \"hash\":\"590bcd2b99a06b53bac724bce7f56ccf0f230c3f\", \"best_bid\":\"0.81\", \"best_ask\":\"0.82\"}], \"timestamp\":\"1785122012921\", \"event_type\":\"price_change\"}","received_at":"2026-07-27T03:13:32.837365Z","schema_version":"clob-market-ws.price_change.v1","sequence":null,"server_hash":null,"server_timestamp":"1785122012921","session_id":"ff6d21c8283948938400a32613abec2c","source":"clob_market_ws"},"received_at":"2026-07-27T03:13:32.837365Z","record_id":"cd4d3560417f4d2568bbbc82229524609c349ff49e12a3a4403c02655ebd11a5","schema_fingerprint":"4aa3821a28b0b7c2400bc59aba4bcc0a76e971dadd19610d3ad38c768e124dc7","schema_version":"edge-lab-recorder.raw.v1","sequence":null,"source":"clob_market_ws"}
{"event_at":"2026-07-27T03:13:32.921000Z","event_fingerprint":"e3c265da7d6fa5eb8cfd51007ae6a0ff6f4e055e7a941b71200bc10d3570e188","payload":{"connection_id":"f95883f18d264834af91809e5f803e9f","event_at":"2026-07-27T03:13:32.921000Z","event_type":"price_change","frame_hash":"2a31545fcd7aa7d7d1fe61a75a7f4554880daebc727c0be1523874846537ef26","frame_index":0,"kind":"data","monotonic_ns":223996171259000,"payload":{"event_type":"price_change","market":"0xf9d60bb033695053c4d1d8592e52171c1042f64b41a4b72e09dcc6f4852b6670","price_changes":[{"asset_id":"8698449539441374295770236407991735029336433231649246775082939325523552031992","best_ask":"0.82","best_bid":"0.81","hash":"b3d8c9cc55b02990e4f2a9e49cacc0e1bd73d1ce","price":"0.01","side":"BUY","size":"8032.52"},{"asset_id":"96283536366176669581486355171583722558858323126916278856549586825357358273536","best_ask":"0.19","best_bid":"0.18","hash":"3197aee506be53234d6c56afea43b3a82d20d584","price":"0.99","side":"SELL","size":"8032.52"}],"timestamp":"1785122012921"},"payload_hash":"ba9c720c135d4f70c093d4629f5234646886d944d0f5d16614ee01c70808a2cc","raw_frame":"{\"market\":\"0xf9d60bb033695053c4d1d8592e52171c1042f64b41a4b72e09dcc6f4852b6670\", \"price_changes\":[{\"asset_id\":\"8698449539441374295770236407991735029336433231649246775082939325523552031992\", \"price\":\"0.01\", \"size\":\"8032.52\", \"side\":\"BUY\", \"hash\":\"b3d8c9cc55b02990e4f2a9e49cacc0e1bd73d1ce\", \"best_bid\":\"0.81\", \"best_ask\":\"0.82\"}, {\"asset_id\":\"96283536366176669581486355171583722558858323126916278856549586825357358273536\", \"price\":\"0.99\", \"size\":\"8032.52\", \"side\":\"SELL\", \"hash\":\"3197aee506be53234d6c56afea43b3a82d20d584\", \"best_bid\":\"0.18\", \"best_ask\":\"0.19\"}], \"timestamp\":\"1785122012921\", \"event_type\":\"price_change\"}","received_at":"2026-07-27T03:13:32.838817Z","schema_version":"clob-market-ws.price_change.v1","sequence":null,"server_hash":null,"server_timestamp":"1785122012921","session_id":"ff6d21c8283948938400a32613abec2c","source":"clob_market_ws"},"received_at":"2026-07-27T03:13:32.838817Z","record_id":"d10a1c18635bf19f677318cfb26a7670190fdd228cc847fa471c6eb182c37c08","schema_fingerprint":"4aa3821a28b0b7c2400bc59aba4bcc0a76e971dadd19610d3ad38c768e124dc7","schema_version":"edge-lab-recorder.raw.v1","sequence":null,"source":"clob_market_ws"}
{"event_at":"2026-07-27T03:13:32.922000Z","event_fingerprint":"1c48a9bf7876115a29f73fadebfb9f81ac1ca17c53f7efa6a3eb30e8a00f8070","payload":{"connection_id":"f95883f18d264834af91809e5f803e9f","event_at":"2026-07-27T03:13:32.922000Z","event_type":"price_change","frame_hash":"01fcc64d184d219ae435af316490d8821476ea3faae3ec33e033dcc6ac7fa176","frame_index":0,"kind":"data","monotonic_ns":223996172848166,"payload":{"event_type":"price_change","market":"0xf9d60bb033695053c4d1d8592e52171c1042f64b41a4b72e09dcc6f4852b6670","price_changes":[{"asset_id":"96283536366176669581486355171583722558858323126916278856549586825357358273536","best_ask":"0.19","best_bid":"0.18","hash":"0a303666427445ab749ebd67bc68e1329122a01f","price":"0.01","side":"BUY","size":"7139.52"},{"asset_id":"8698449539441374295770236407991735029336433231649246775082939325523552031992","best_ask":"0.82","best_bid":"0.81","hash":"da0e72f3e4721f240d19e0f01b102df8bb320a7a","price":"0.99","side":"SELL","size":"7139.52"}],"timestamp":"1785122012922"},"payload_hash":"72afa5eedacecc62e90926bf4a7a8fada43f8e65c735bf76013eca6f64bdecec","raw_frame":"{\"market\":\"0xf9d60bb033695053c4d1d8592e52171c1042f64b41a4b72e09dcc6f4852b6670\", \"price_changes\":[{\"asset_id\":\"96283536366176669581486355171583722558858323126916278856549586825357358273536\", \"price\":\"0.01\", \"size\":\"7139.52\", \"side\":\"BUY\", \"hash\":\"0a303666427445ab749ebd67bc68e1329122a01f\", \"best_bid\":\"0.18\", \"best_ask\":\"0.19\"}, {\"asset_id\":\"8698449539441374295770236407991735029336433231649246775082939325523552031992\", \"price\":\"0.99\", \"size\":\"7139.52\", \"side\":\"SELL\", \"hash\":\"da0e72f3e4721f240d19e0f01b102df8bb320a7a\", \"best_bid\":\"0.81\", \"best_ask\":\"0.82\"}], \"timestamp\":\"1785122012922\", \"event_type\":\"price_change\"}","received_at":"2026-07-27T03:13:32.840405Z","schema_version":"clob-market-ws.price_change.v1","sequence":null,"server_hash":null,"server_timestamp":"1785122012922","session_id":"ff6d21c8283948938400a32613abec2c","source":"clob_market_ws"},"received_at":"2026-07-27T03:13:32.840405Z","record_id":"8d9014734ff3e0e0bd93bb4af210caaf1e5ec412787c2ea207f8bddc1fc47afa","schema_fingerprint":"4aa3821a28b0b7c2400bc59aba4bcc0a76e971dadd19610d3ad38c768e124dc7","schema_version":"edge-lab-recorder.raw.v1","sequence":null,"source":"clob_market_ws"}
{"event_at":"2026-07-27T03:13:32.939000Z","event_fingerprint":"cff980f9d20e111dd429fe9d91a4b4f3d4fdcddad1936e988da1022577b6431c","payload":{"connection_id":"f95883f18d264834af91809e5f803e9f","event_at":"2026-07-27T03:13:32.939000Z","event_type":"price_change","frame_hash":"968f0101103ee5e6ad0c980aa608bacdb02884b5385753350f5533c78ccde27d","frame_index":0,"kind":"data","monotonic_ns":223996174364458,"payload":{"event_type":"price_change","market":"0xf9d60bb033695053c4d1d8592e52171c1042f64b41a4b72e09dcc6f4852b6670","price_changes":[{"asset_id":"96283536366176669581486355171583722558858323126916278856549586825357358273536","best_ask":"0.19","best_bid":"0.18","hash":"0290d94b3780fc1c99357677bfec67e681a27978","price":"0.14","side":"BUY","size":"30"},{"asset_id":"8698449539441374295770236407991735029336433231649246775082939325523552031992","best_ask":"0.82","best_bid":"0.81","hash":"30b2ab050c55c6f7bd77815b6ffe7047d24f42e8","price":"0.86","side":"SELL","size":"30"}],"timestamp":"1785122012939"},"payload_hash":"d12a23e09d3aa8967dfadb97988c3cf29fb785ce721896f7459ad31ac7b35885","raw_frame":"{\"market\":\"0xf9d60bb033695053c4d1d8592e52171c1042f64b41a4b72e09dcc6f4852b6670\", \"price_changes\":[{\"asset_id\":\"96283536366176669581486355171583722558858323126916278856549586825357358273536\", \"price\":\"0.14\", \"size\":\"30\", \"side\":\"BUY\", \"hash\":\"0290d94b3780fc1c99357677bfec67e681a27978\", \"best_bid\":\"0.18\", \"best_ask\":\"0.19\"}, {\"asset_id\":\"8698449539441374295770236407991735029336433231649246775082939325523552031992\", \"price\":\"0.86\", \"size\":\"30\", \"side\":\"SELL\", \"hash\":\"30b2ab050c55c6f7bd77815b6ffe7047d24f42e8\", \"best_bid\":\"0.81\", \"best_ask\":\"0.82\"}], \"timestamp\":\"1785122012939\", \"event_type\":\"price_change\"}","received_at":"2026-07-27T03:13:32.841922Z","schema_version":"clob-market-ws.price_change.v1","sequence":null,"server_hash":null,"server_timestamp":"1785122012939","session_id":"ff6d21c8283948938400a32613abec2c","source":"clob_market_ws"},"received_at":"2026-07-27T03:13:32.841922Z","record_id":"47bf02b9c72e5ab1e9aa954c50b896450a205df402311fed4a937d3f2b4925bc","schema_fingerprint":"4aa3821a28b0b7c2400bc59aba4bcc0a76e971dadd19610d3ad38c768e124dc7","schema_version":"edge-lab-recorder.raw.v1","sequence":null,"source":"clob_market_ws"}
{"event_at":"2026-07-27T03:13:32.960000Z","event_fingerprint":"7085692f79c99063b8957f4dbb5e373ab22e369a75a04daea3b9a61688de0a58","payload":{"connection_id":"f95883f18d264834af91809e5f803e9f","event_at":"2026-07-27T03:13:32.960000Z","event_type":"price_change","frame_hash":"2714156052d0287ebeeb87e53b1f7eed699c0c1c22322b590694ccb5878bbb38","frame_index":0,"kind":"data","monotonic_ns":223996192861916,"payload":{"event_type":"price_change","market":"0xf9d60bb033695053c4d1d8592e52171c1042f64b41a4b72e09dcc6f4852b6670","price_changes":[{"asset_id":"8698449539441374295770236407991735029336433231649246775082939325523552031992","best_ask":"0.82","best_bid":"0.81","hash":"482feeedde42d0a3763247530bbd62eae11ed9e1","price":"0.74","side":"BUY","size":"115.04"},{"asset_id":"96283536366176669581486355171583722558858323126916278856549586825357358273536","best_ask":"0.19","best_bid":"0.18","hash":"b4ea009ca4610a2103e8f58782620229442cb18b","price":"0.26","side":"SELL","size":"115.04"}],"timestamp":"1785122012960"},"payload_hash":"5623b58f3d0e52a5f7f974fee31e548e9b0bba903b89dbe181745b14e61ec96e","raw_frame":"{\"market\":\"0xf9d60bb033695053c4d1d8592e52171c1042f64b41a4b72e09dcc6f4852b6670\", \"price_changes\":[{\"asset_id\":\"8698449539441374295770236407991735029336433231649246775082939325523552031992\", \"price\":\"0.74\", \"size\":\"115.04\", \"side\":\"BUY\", \"hash\":\"482feeedde42d0a3763247530bbd62eae11ed9e1\", \"best_bid\":\"0.81\", \"best_ask\":\"0.82\"}, {\"asset_id\":\"96283536366176669581486355171583722558858323126916278856549586825357358273536\", \"price\":\"0.26\", \"size\":\"115.04\", \"side\":\"SELL\", \"hash\":\"b4ea009ca4610a2103e8f58782620229442cb18b\", \"best_bid\":\"0.18\", \"best_ask\":\"0.19\"}], \"timestamp\":\"1785122012960\", \"event_type\":\"price_change\"}","received_at":"2026-07-27T03:13:32.860414Z","schema_version":"clob-market-ws.price_change.v1","sequence":null,"server_hash":null,"server_timestamp":"1785122012960","session_id":"ff6d21c8283948938400a32613abec2c","source":"clob_market_ws"},"received_at":"2026-07-27T03:13:32.860414Z","record_id":"92ad58a717e5e0e216ffd68ef66e11401393abde0358a35ab0d4f0b223615add","schema_fingerprint":"4aa3821a28b0b7c2400bc59aba4bcc0a76e971dadd19610d3ad38c768e124dc7","schema_version":"edge-lab-recorder.raw.v1","sequence":null,"source":"clob_market_ws"}
{"event_at":"2026-07-27T03:13:32.966000Z","event_fingerprint":"027b54d1971ef4ce8869470f9a88e8008e9e46b422db37e4f6707df8b370fb5a","payload":{"connection_id":"f95883f18d264834af91809e5f803e9f","event_at":"2026-07-27T03:13:32.966000Z","event_type":"price_change","frame_hash":"f8a1190e5647ea17439b7223a06c4ba9ce983b043108a908657b45cc1821a526","frame_index":0,"kind":"data","monotonic_ns":223996198673833,"payload":{"event_type":"price_change","market":"0xf9d60bb033695053c4d1d8592e52171c1042f64b41a4b72e09dcc6f4852b6670","price_changes":[{"asset_id":"96283536366176669581486355171583722558858323126916278856549586825357358273536","best_ask":"0.19","best_bid":"0.18","hash":"73879fc643f8178bcfb090052512e16d7b7a6199","price":"0.12","side":"BUY","size":"141.4"},{"asset_id":"8698449539441374295770236407991735029336433231649246775082939325523552031992","best_ask":"0.82","best_bid":"0.81","hash":"ef040b7766aed777c17ce9706bfec5fe8b222164","price":"0.88","side":"SELL","size":"141.4"}],"timestamp":"1785122012966"},"payload_hash":"119165c2daf1f850b1fee267bb0a8fe4a531679fb43f61272255af9578436836","raw_frame":"{\"market\":\"0xf9d60bb033695053c4d1d8592e52171c1042f64b41a4b72e09dcc6f4852b6670\", \"price_changes\":[{\"asset_id\":\"96283536366176669581486355171583722558858323126916278856549586825357358273536\", \"price\":\"0.12\", \"size\":\"141.4\", \"side\":\"BUY\", \"hash\":\"73879fc643f8178bcfb090052512e16d7b7a6199\", \"best_bid\":\"0.18\", \"best_ask\":\"0.19\"}, {\"asset_id\":\"8698449539441374295770236407991735029336433231649246775082939325523552031992\", \"price\":\"0.88\", \"size\":\"141.4\", \"side\":\"SELL\", \"hash\":\"ef040b7766aed777c17ce9706bfec5fe8b222164\", \"best_bid\":\"0.81\", \"best_ask\":\"0.82\"}], \"timestamp\":\"1785122012966\", \"event_type\":\"price_change\"}","received_at":"2026-07-27T03:13:32.866227Z","schema_version":"clob-market-ws.price_change.v1","sequence":null,"server_hash":null,"server_timestamp":"1785122012966","session_id":"ff6d21c8283948938400a32613abec2c","source":"clob_market_ws"},"received_at":"2026-07-27T03:13:32.866227Z","record_id":"aa782e200267acba4858ce1bd095d11ea25e32f8d572bd11c2089d66e9107fe4","schema_fingerprint":"4aa3821a28b0b7c2400bc59aba4bcc0a76e971dadd19610d3ad38c768e124dc7","schema_version":"edge-lab-recorder.raw.v1","sequence":null,"source":"clob_market_ws"}
{"event_at":"2026-07-27T03:13:32.982000Z","event_fingerprint":"3e375e18f16dd8e41c3ed26e26332dd8a7dae17d8b6f85692102aeb082ea5559","payload":{"connection_id":"f95883f18d264834af91809e5f803e9f","event_at":"2026-07-27T03:13:32.982000Z","event_type":"price_change","frame_hash":"4bc2a05cf26d8abb8583b42abc04bed716ce3a9d3fc7f9705e1a67f993596f55","frame_index":0,"kind":"data","monotonic_ns":223996215614750,"payload":{"event_type":"price_change","market":"0xf9d60bb033695053c4d1d8592e52171c1042f64b41a4b72e09dcc6f4852b6670","price_changes":[{"asset_id":"8698449539441374295770236407991735029336433231649246775082939325523552031992","best_ask":"0.82","best_bid":"0.81","hash":"9e87499e19c7be89ebedea119d48e8b7be11ae4d","price":"0.01","side":"BUY","size":"8027.52"},{"asset_id":"96283536366176669581486355171583722558858323126916278856549586825357358273536","best_ask":"0.19","best_bid":"0.18","hash":"f63fc0d7483245e2264bd9b4e772a7d48ea45484","price":"0.99","side":"SELL","size":"8027.52"}],"timestamp":"1785122012982"},"payload_hash":"66be5855260edca142545481428d638602fe5f6213254e41c7a1c8fb2a9637c2","raw_frame":"{\"market\":\"0xf9d60bb033695053c4d1d8592e52171c1042f64b41a4b72e09dcc6f4852b6670\", \"price_changes\":[{\"asset_id\":\"8698449539441374295770236407991735029336433231649246775082939325523552031992\", \"price\":\"0.01\", \"size\":\"8027.52\", \"side\":\"BUY\", \"hash\":\"9e87499e19c7be89ebedea119d48e8b7be11ae4d\", \"best_bid\":\"0.81\", \"best_ask\":\"0.82\"}, {\"asset_id\":\"96283536366176669581486355171583722558858323126916278856549586825357358273536\", \"price\":\"0.99\", \"size\":\"8027.52\", \"side\":\"SELL\", \"hash\":\"f63fc0d7483245e2264bd9b4e772a7d48ea45484\", \"best_bid\":\"0.18\", \"best_ask\":\"0.19\"}], \"timestamp\":\"1785122012982\", \"event_type\":\"price_change\"}","received_at":"2026-07-27T03:13:32.883172Z","schema_version":"clob-market-ws.price_change.v1","sequence":null,"server_hash":null,"server_timestamp":"1785122012982","session_id":"ff6d21c8283948938400a32613abec2c","source":"clob_market_ws"},"received_at":"2026-07-27T03:13:32.883172Z","record_id":"a2b23eb3fac3392164963b63376e661766e464753fe7524dc7aeb27a24ecd774","schema_fingerprint":"4aa3821a28b0b7c2400bc59aba4bcc0a76e971dadd19610d3ad38c768e124dc7","schema_version":"edge-lab-recorder.raw.v1","sequence":null,"source":"clob_market_ws"}
{"event_at":"2026-07-27T03:13:32.986000Z","event_fingerprint":"6dca011df65bd36dc01aa19757a6e53b672d058949e4470d562db66d19c8a648","payload":{"connection_id":"f95883f18d264834af91809e5f803e9f","event_at":"2026-07-27T03:13:32.986000Z","event_type":"price_change","frame_hash":"090940e5c0f7bb02f1ffbe5b1dc6794ae6c6150e0473a34be1c6d200253cd61e","frame_index":0,"kind":"data","monotonic_ns":223996217802625,"payload":{"event_type":"price_change","market":"0xf9d60bb033695053c4d1d8592e52171c1042f64b41a4b72e09dcc6f4852b6670","price_changes":[{"asset_id":"8698449539441374295770236407991735029336433231649246775082939325523552031992","best_ask":"0.82","best_bid":"0.81","hash":"6f3fa4570c2f6b113addc13e28e23b51198f0417","price":"0.72","side":"BUY","size":"145"},{"asset_id":"96283536366176669581486355171583722558858323126916278856549586825357358273536","best_ask":"0.19","best_bid":"0.18","hash":"24e6795d4f2cee03b8a1d560cdd15bb599a14060","price":"0.28","side":"SELL","size":"145"}],"timestamp":"1785122012986"},"payload_hash":"560691de582b3b565d689d211390228e25f79279a06e5033684b2532eb9808d3","raw_frame":"{\"market\":\"0xf9d60bb033695053c4d1d8592e52171c1042f64b41a4b72e09dcc6f4852b6670\", \"price_changes\":[{\"asset_id\":\"8698449539441374295770236407991735029336433231649246775082939325523552031992\", \"price\":\"0.72\", \"size\":\"145\", \"side\":\"BUY\", \"hash\":\"6f3fa4570c2f6b113addc13e28e23b51198f0417\", \"best_bid\":\"0.81\", \"best_ask\":\"0.82\"}, {\"asset_id\":\"96283536366176669581486355171583722558858323126916278856549586825357358273536\", \"price\":\"0.28\", \"size\":\"145\", \"side\":\"SELL\", \"hash\":\"24e6795d4f2cee03b8a1d560cdd15bb599a14060\", \"best_bid\":\"0.18\", \"best_ask\":\"0.19\"}], \"timestamp\":\"1785122012986\", \"event_type\":\"price_change\"}","received_at":"2026-07-27T03:13:32.885362Z","schema_version":"clob-market-ws.price_change.v1","sequence":null,"server_hash":null,"server_timestamp":"1785122012986","session_id":"ff6d21c8283948938400a32613abec2c","source":"clob_market_ws"},"received_at":"2026-07-27T03:13:32.885362Z","record_id":"57505b91459be372f9d888d9b09cd223257329874f506b579808230d315b5ebb","schema_fingerprint":"4aa3821a28b0b7c2400bc59aba4bcc0a76e971dadd19610d3ad38c768e124dc7","schema_version":"edge-lab-recorder.raw.v1","sequence":null,"source":"clob_market_ws"}
{"event_at":"2026-07-27T03:13:32.992000Z","event_fingerprint":"4aba8bc8309f16753a5d69e79f45b602990e20538b819a730c5a83ca3e467eb8","payload":{"connection_id":"f95883f18d264834af91809e5f803e9f","event_at":"2026-07-27T03:13:32.992000Z","event_type":"price_change","frame_hash":"9244fc1d35cb696e018183163a7c47b477917ca8a0499427579a699526fad7f6","frame_index":0,"kind":"data","monotonic_ns":223996223268833,"payload":{"event_type":"price_change","market":"0xf9d60bb033695053c4d1d8592e52171c1042f64b41a4b72e09dcc6f4852b6670","price_changes":[{"asset_id":"96283536366176669581486355171583722558858323126916278856549586825357358273536","best_ask":"0.19","best_bid":"0.18","hash":"339d018c795daaebf90ee8514dbc5e7b119a2cdd","price":"0.1","side":"BUY","size":"179.07"},{"asset_id":"8698449539441374295770236407991735029336433231649246775082939325523552031992","best_ask":"0.82","best_bid":"0.81","hash":"08ddf770d229306c14ff23a08904d1e6272a9387","price":"0.9","side":"SELL","size":"179.07"}],"timestamp":"1785122012992"},"payload_hash":"099bc667a8cf563e15637aabe7f05698a318ba5c8d796f026ad64fcfb0e00bf2","raw_frame":"{\"market\":\"0xf9d60bb033695053c4d1d8592e52171c1042f64b41a4b72e09dcc6f4852b6670\", \"price_changes\":[{\"asset_id\":\"96283536366176669581486355171583722558858323126916278856549586825357358273536\", \"price\":\"0.1\", \"size\":\"179.07\", \"side\":\"BUY\", \"hash\":\"339d018c795daaebf90ee8514dbc5e7b119a2cdd\", \"best_bid\":\"0.18\", \"best_ask\":\"0.19\"}, {\"asset_id\":\"8698449539441374295770236407991735029336433231649246775082939325523552031992\", \"price\":\"0.9\", \"size\":\"179.07\", \"side\":\"SELL\", \"hash\":\"08ddf770d229306c14ff23a08904d1e6272a9387\", \"best_bid\":\"0.81\", \"best_ask\":\"0.82\"}], \"timestamp\":\"1785122012992\", \"event_type\":\"price_change\"}","received_at":"2026-07-27T03:13:32.890828Z","schema_version":"clob-market-ws.price_change.v1","sequence":null,"server_hash":null,"server_timestamp":"1785122012992","session_id":"ff6d21c8283948938400a32613abec2c","source":"clob_market_ws"},"received_at":"2026-07-27T03:13:32.890828Z","record_id":"b2f992eb43f58f52d6f95cc1f9d8d5a4a7759f5e393d59992af2e8e5832c1374","schema_fingerprint":"4aa3821a28b0b7c2400bc59aba4bcc0a76e971dadd19610d3ad38c768e124dc7","schema_version":"edge-lab-recorder.raw.v1","sequence":null,"source":"clob_market_ws"}
{"event_at":"2026-07-27T03:13:33.022000Z","event_fingerprint":"95f0398573e70256f0c28f4348be45f4cee620efcf708e7f1c0e7ee8edd88ae8","payload":{"connection_id":"f95883f18d264834af91809e5f803e9f","event_at":"2026-07-27T03:13:33.022000Z","event_type":"price_change","frame_hash":"36985240e551e08ef80a204170c4b6e942683d61290e1c830c4bf46297d429d6","frame_index":0,"kind":"data","monotonic_ns":223996252901333,"payload":{"event_type":"price_change","market":"0xf9d60bb033695053c4d1d8592e52171c1042f64b41a4b72e09dcc6f4852b6670","price_changes":[{"asset_id":"96283536366176669581486355171583722558858323126916278856549586825357358273536","best_ask":"0.19","best_bid":"0.18","hash":"d0a790c475bf64a6e6f94f574a335807ac2c2d05","price":"0.12","side":"BUY","size":"153.2"},{"asset_id":"8698449539441374295770236407991735029336433231649246775082939325523552031992","best_ask":"0.82","best_bid":"0.81","hash":"9d7f7cb03444377c37805fd048b8fbb6167aab90","price":"0.88","side":"SELL","size":"153.2"}],"timestamp":"1785122013022"},"payload_hash":"b006a4ca71fdabaa137ce626edb4dcb029d08e3138584171a583139595a1cefd","raw_frame":"{\"market\":\"0xf9d60bb033695053c4d1d8592e52171c1042f64b41a4b72e09dcc6f4852b6670\", \"price_changes\":[{\"asset_id\":\"96283536366176669581486355171583722558858323126916278856549586825357358273536\", \"price\":\"0.12\", \"size\":\"153.2\", \"side\":\"BUY\", \"hash\":\"d0a790c475bf64a6e6f94f574a335807ac2c2d05\", \"best_bid\":\"0.18\", \"best_ask\":\"0.19\"}, {\"asset_id\":\"8698449539441374295770236407991735029336433231649246775082939325523552031992\", \"price\":\"0.88\", \"size\":\"153.2\", \"side\":\"SELL\", \"hash\":\"9d7f7cb03444377c37805fd048b8fbb6167aab90\", \"best_bid\":\"0.81\", \"best_ask\":\"0.82\"}], \"timestamp\":\"1785122013022\", \"event_type\":\"price_change\"}","received_at":"2026-07-27T03:13:32.920449Z","schema_version":"clob-market-ws.price_change.v1","sequence":null,"server_hash":null,"server_timestamp":"1785122013022","session_id":"ff6d21c8283948938400a32613abec2c","source":"clob_market_ws"},"received_at":"2026-07-27T03:13:32.920449Z","record_id":"b4443b29bada0d12bfb9199041730f943bb5bff5b013815f837f2d3eb9f9d07e","schema_fingerprint":"4aa3821a28b0b7c2400bc59aba4bcc0a76e971dadd19610d3ad38c768e124dc7","schema_version":"edge-lab-recorder.raw.v1","sequence":null,"source":"clob_market_ws"}
{"event_at":"2026-07-27T03:13:33.026000Z","event_fingerprint":"5353e30f98e89e783e71e15bc682bca7b7cfdca5f91671b8b7e79ca532f0352a","payload":{"connection_id":"f95883f18d264834af91809e5f803e9f","event_at":"2026-07-27T03:13:33.026000Z","event_type":"price_change","frame_hash":"7bd2e894ed8a7903814e1d1ba539bd28ae1aa3371f7cee166b4774163517ae3b","frame_index":0,"kind":"data","monotonic_ns":223996257569375,"payload":{"event_type":"price_change","market":"0xf9d60bb033695053c4d1d8592e52171c1042f64b41a4b72e09dcc6f4852b6670","price_changes":[{"asset_id":"96283536366176669581486355171583722558858323126916278856549586825357358273536","best_ask":"0.19","best_bid":"0.18","hash":"709cda2b7f4bf4953a378ba9b44161ecd7942c99","price":"0.01","side":"BUY","size":"7144.52"},{"asset_id":"8698449539441374295770236407991735029336433231649246775082939325523552031992","best_ask":"0.82","best_bid":"0.81","hash":"4c00f84828585824ec77ebfc0d81a9868a2e5098","price":"0.99","side":"SELL","size":"7144.52"}],"timestamp":"1785122013026"},"payload_hash":"af10c4632ab9f09b18748a64f62b00df90900f316f5ee43b1d84c88e977c3821","raw_frame":"{\"market\":\"0xf9d60bb033695053c4d1d8592e52171c1042f64b41a4b72e09dcc6f4852b6670\", \"price_changes\":[{\"asset_id\":\"96283536366176669581486355171583722558858323126916278856549586825357358273536\", \"price\":\"0.01\", \"size\":\"7144.52\", \"side\":\"BUY\", \"hash\":\"709cda2b7f4bf4953a378ba9b44161ecd7942c99\", \"best_bid\":\"0.18\", \"best_ask\":\"0.19\"}, {\"asset_id\":\"8698449539441374295770236407991735029336433231649246775082939325523552031992\", \"price\":\"0.99\", \"size\":\"7144.52\", \"side\":\"SELL\", \"hash\":\"4c00f84828585824ec77ebfc0d81a9868a2e5098\", \"best_bid\":\"0.81\", \"best_ask\":\"0.82\"}], \"timestamp\":\"1785122013026\", \"event_type\":\"price_change\"}","received_at":"2026-07-27T03:13:32.925122Z","schema_version":"clob-market-ws.price_change.v1","sequence":null,"server_hash":null,"server_timestamp":"1785122013026","session_id":"ff6d21c8283948938400a32613abec2c","source":"clob_market_ws"},"received_at":"2026-07-27T03:13:32.925122Z","record_id":"f2ec588a5cf7f3b1da9cb1c9e2da069d4bf8a3339eb330222de583a2c8d5a79a","schema_fingerprint":"4aa3821a28b0b7c2400bc59aba4bcc0a76e971dadd19610d3ad38c768e124dc7","schema_version":"edge-lab-recorder.raw.v1","sequence":null,"source":"clob_market_ws"}
{"event_at":"2026-07-27T03:13:33.028000Z","event_fingerprint":"2a3bde492859f449987a7399db0a756639a3c552bbeafcd7c8714c15c453b747","payload":{"connection_id":"f95883f18d264834af91809e5f803e9f","event_at":"2026-07-27T03:13:33.028000Z","event_type":"price_change","frame_hash":"8f6b77407b514bf8cb7b1c4122bd53254a0ea3853c5ed1dbfce457419d06ea6b","frame_index":0,"kind":"data","monotonic_ns":223996259746750,"payload":{"event_type":"price_change","market":"0xf9d60bb033695053c4d1d8592e52171c1042f64b41a4b72e09dcc6f4852b6670","price_changes":[{"asset_id":"96283536366176669581486355171583722558858323126916278856549586825357358273536","best_ask":"0.19","best_bid":"0.18","hash":"76e478249bec7fd633c499ee63a023b730706fd4","price":"0.01","side":"BUY","size":"7149.52"},{"asset_id":"8698449539441374295770236407991735029336433231649246775082939325523552031992","best_ask":"0.82","best_bid":"0.81","hash":"6cd03543ad68e61b64931de6d7f1412f0e73b74e","price":"0.99","side":"SELL","size":"7149.52"}],"timestamp":"1785122013028"},"payload_hash":"7301d7ee1d87351aa6da0024d7aadf3242e6d40c2deb942526966467c6299ea4","raw_frame":"{\"market\":\"0xf9d60bb033695053c4d1d8592e52171c1042f64b41a4b72e09dcc6f4852b6670\", \"price_changes\":[{\"asset_id\":\"96283536366176669581486355171583722558858323126916278856549586825357358273536\", \"price\":\"0.01\", \"size\":\"7149.52\", \"side\":\"BUY\", \"hash\":\"76e478249bec7fd633c499ee63a023b730706fd4\", \"best_bid\":\"0.18\", \"best_ask\":\"0.19\"}, {\"asset_id\":\"8698449539441374295770236407991735029336433231649246775082939325523552031992\", \"price\":\"0.99\", \"size\":\"7149.52\", \"side\":\"SELL\", \"hash\":\"6cd03543ad68e61b64931de6d7f1412f0e73b74e\", \"best_bid\":\"0.81\", \"best_ask\":\"0.82\"}], \"timestamp\":\"1785122013028\", \"event_type\":\"price_change\"}","received_at":"2026-07-27T03:13:32.927295Z","schema_version":"clob-market-ws.price_change.v1","sequence":null,"server_hash":null,"server_timestamp":"1785122013028","session_id":"ff6d21c8283948938400a32613abec2c","source":"clob_market_ws"},"received_at":"2026-07-27T03:13:32.927295Z","record_id":"75190e06583591fd5af27eefcff2675a87bda904591927cbbd6bc564ff8ee6ae","schema_fingerprint":"4aa3821a28b0b7c2400bc59aba4bcc0a76e971dadd19610d3ad38c768e124dc7","schema_version":"edge-lab-recorder.raw.v1","sequence":null,"source":"clob_market_ws"}
{"event_at":"2026-07-27T03:13:33.037000Z","event_fingerprint":"14f1a937b30b23324f34f0218463c703636541cff2a905e3e4cec3485e02071b","payload":{"connection_id":"f95883f18d264834af91809e5f803e9f","event_at":"2026-07-27T03:13:33.037000Z","event_type":"price_change","frame_hash":"9059ea775455ac85666b9460c6ee7c986d159c63ffb7a85c0732de197ff67e87","frame_index":0,"kind":"data","monotonic_ns":223996270891583,"payload":{"event_type":"price_change","market":"0xf9d60bb033695053c4d1d8592e52171c1042f64b41a4b72e09dcc6f4852b6670","price_changes":[{"asset_id":"96283536366176669581486355171583722558858323126916278856549586825357358273536","best_ask":"0.19","best_bid":"0.18","hash":"ede21be4fc4b18683a2cc96fb53def6d33ffbab7","price":"0.12","side":"BUY","size":"128.6"},{"asset_id":"8698449539441374295770236407991735029336433231649246775082939325523552031992","best_ask":"0.82","best_bid":"0.81","hash":"3688ac3fbc11777772cb808304fa3a2a801a40e4","price":"0.88","side":"SELL","size":"128.6"}],"timestamp":"1785122013037"},"payload_hash":"11326de2ad455421ddcb69e0027fd3c18c0df4524db8998b8636f40629390b24","raw_frame":"{\"market\":\"0xf9d60bb033695053c4d1d8592e52171c1042f64b41a4b72e09dcc6f4852b6670\", \"price_changes\":[{\"asset_id\":\"96283536366176669581486355171583722558858323126916278856549586825357358273536\", \"price\":\"0.12\", \"size\":\"128.6\", \"side\":\"BUY\", \"hash\":\"ede21be4fc4b18683a2cc96fb53def6d33ffbab7\", \"best_bid\":\"0.18\", \"best_ask\":\"0.19\"}, {\"asset_id\":\"8698449539441374295770236407991735029336433231649246775082939325523552031992\", \"price\":\"0.88\", \"size\":\"128.6\", \"side\":\"SELL\", \"hash\":\"3688ac3fbc11777772cb808304fa3a2a801a40e4\", \"best_bid\":\"0.81\", \"best_ask\":\"0.82\"}], \"timestamp\":\"1785122013037\", \"event_type\":\"price_change\"}","received_at":"2026-07-27T03:13:32.938445Z","schema_version":"clob-market-ws.price_change.v1","sequence":null,"server_hash":null,"server_timestamp":"1785122013037","session_id":"ff6d21c8283948938400a32613abec2c","source":"clob_market_ws"},"received_at":"2026-07-27T03:13:32.938445Z","record_id":"1bf20fb5fc378e4977cef6aff536e0fc8f071ca5e92c81ce7dc0f9491736a242","schema_fingerprint":"4aa3821a28b0b7c2400bc59aba4bcc0a76e971dadd19610d3ad38c768e124dc7","schema_version":"edge-lab-recorder.raw.v1","sequence":null,"source":"clob_market_ws"}
{"event_at":"2026-07-27T03:13:33.048000Z","event_fingerprint":"c26f859d53c68a0ed8efebc614f19646a8a6c293f329537bad692560ae546438","payload":{"connection_id":"f95883f18d264834af91809e5f803e9f","event_at":"2026-07-27T03:13:33.048000Z","event_type":"price_change","frame_hash":"8afc5b61b8818b10a7feab334c279474bb2e29ca07a3092e836f12590f34032c","frame_index":0,"kind":"data","monotonic_ns":223996279602250,"payload":{"event_type":"price_change","market":"0xf9d60bb033695053c4d1d8592e52171c1042f64b41a4b72e09dcc6f4852b6670","price_changes":[{"asset_id":"96283536366176669581486355171583722558858323126916278856549586825357358273536","best_ask":"0.19","best_bid":"0.18","hash":"3270ccb52f7711b824928642c7e991d245a4b1a1","price":"0.01","side":"BUY","size":"7144.52"},{"asset_id":"8698449539441374295770236407991735029336433231649246775082939325523552031992","best_ask":"0.82","best_bid":"0.81","hash":"334514ac14dca51c639238b12d58b9590d8f50e9","price":"0.99","side":"SELL","size":"7144.52"}],"timestamp":"1785122013048"},"payload_hash":"6d6c18277b8f3f315e9708d1f789a0e87710b5689beaf66c3e579aede25dda77","raw_frame":"{\"market\":\"0xf9d60bb033695053c4d1d8592e52171c1042f64b41a4b72e09dcc6f4852b6670\", \"price_changes\":[{\"asset_id\":\"96283536366176669581486355171583722558858323126916278856549586825357358273536\", \"price\":\"0.01\", \"size\":\"7144.52\", \"side\":\"BUY\", \"hash\":\"3270ccb52f7711b824928642c7e991d245a4b1a1\", \"best_bid\":\"0.18\", \"best_ask\":\"0.19\"}, {\"asset_id\":\"8698449539441374295770236407991735029336433231649246775082939325523552031992\", \"price\":\"0.99\", \"size\":\"7144.52\", \"side\":\"SELL\", \"hash\":\"334514ac14dca51c639238b12d58b9590d8f50e9\", \"best_bid\":\"0.81\", \"best_ask\":\"0.82\"}], \"timestamp\":\"1785122013048\", \"event_type\":\"price_change\"}","received_at":"2026-07-27T03:13:32.947160Z","schema_version":"clob-market-ws.price_change.v1","sequence":null,"server_hash":null,"server_timestamp":"1785122013048","session_id":"ff6d21c8283948938400a32613abec2c","source":"clob_market_ws"},"received_at":"2026-07-27T03:13:32.947160Z","record_id":"0f3fd5d8e991ea27bbd19481716299c183e66b00c60cd1c73b6dee31b7b03f09","schema_fingerprint":"4aa3821a28b0b7c2400bc59aba4bcc0a76e971dadd19610d3ad38c768e124dc7","schema_version":"edge-lab-recorder.raw.v1","sequence":null,"source":"clob_market_ws"}
{"event_at":"2026-07-27T03:13:33.062000Z","event_fingerprint":"a78abf7fe5cf36edd7f4b12506af7f4256794055a908efbf54862ccff7cf18e6","payload":{"connection_id":"f95883f18d264834af91809e5f803e9f","event_at":"2026-07-27T03:13:33.062000Z","event_type":"price_change","frame_hash":"d96ee44e91731272c57f2b515a237bda05d25be7e292895fece5265cd9c41d42","frame_index":0,"kind":"data","monotonic_ns":223996293545875,"payload":{"event_type":"price_change","market":"0xf9d60bb033695053c4d1d8592e52171c1042f64b41a4b72e09dcc6f4852b6670","price_changes":[{"asset_id":"8698449539441374295770236407991735029336433231649246775082939325523552031992","best_ask":"0.82","best_bid":"0.81","hash":"7bde1ef27430a2f9946210348cb36be049a935f7","price":"0.79","side":"BUY","size":"144.5"},{"asset_id":"96283536366176669581486355171583722558858323126916278856549586825357358273536","best_ask":"0.19","best_bid":"0.18","hash":"1c7372faae5f95583d8b39cfcf3d1bbb3059fec1","price":"0.21","side":"SELL","size":"144.5"}],"timestamp":"1785122013062"},"payload_hash":"36e7c14c387e03c2fcc76e1e0e903940fe3694e817382aee6a0bfdc14b206d2e","raw_frame":"{\"market\":\"0xf9d60bb033695053c4d1d8592e52171c1042f64b41a4b72e09dcc6f4852b6670\", \"price_changes\":[{\"asset_id\":\"8698449539441374295770236407991735029336433231649246775082939325523552031992\", \"price\":\"0.79\", \"size\":\"144.5\", \"side\":\"BUY\", \"hash\":\"7bde1ef27430a2f9946210348cb36be049a935f7\", \"best_bid\":\"0.81\", \"best_ask\":\"0.82\"}, {\"asset_id\":\"96283536366176669581486355171583722558858323126916278856549586825357358273536\", \"price\":\"0.21\", \"size\":\"144.5\", \"side\":\"SELL\", \"hash\":\"1c7372faae5f95583d8b39cfcf3d1bbb3059fec1\", \"best_bid\":\"0.18\", \"best_ask\":\"0.19\"}], \"timestamp\":\"1785122013062\", \"event_type\":\"price_change\"}","received_at":"2026-07-27T03:13:32.961095Z","schema_version":"clob-market-ws.price_change.v1","sequence":null,"server_hash":null,"server_timestamp":"1785122013062","session_id":"ff6d21c8283948938400a32613abec2c","source":"clob_market_ws"},"received_at":"2026-07-27T03:13:32.961095Z","record_id":"689f4de9047424fb69b907ad7ec051d72b43bc8cb5b3372a076d5b1d4ee5a255","schema_fingerprint":"4aa3821a28b0b7c2400bc59aba4bcc0a76e971dadd19610d3ad38c768e124dc7","schema_version":"edge-lab-recorder.raw.v1","sequence":null,"source":"clob_market_ws"}
{"event_at":"2026-07-27T03:13:33.063000Z","event_fingerprint":"75516ac3c1599b82f419ba67888bd5d9af1d0e4e4dd5822b2c93b7b04e4c4d35","payload":{"connection_id":"f95883f18d264834af91809e5f803e9f","event_at":"2026-07-27T03:13:33.063000Z","event_type":"price_change","frame_hash":"0e186c4a4772aa4d03498df78b114701f8cc584b3735592e9a43f7b2fd884f77","frame_index":0,"kind":"data","monotonic_ns":223996295687125,"payload":{"event_type":"price_change","market":"0xf9d60bb033695053c4d1d8592e52171c1042f64b41a4b72e09dcc6f4852b6670","price_changes":[{"asset_id":"8698449539441374295770236407991735029336433231649246775082939325523552031992","best_ask":"0.82","best_bid":"0.81","hash":"f026f0d01741d3ff73e1699563e1a8a2fcd0e489","price":"0.04","side":"BUY","size":"1336.5"},{"asset_id":"96283536366176669581486355171583722558858323126916278856549586825357358273536","best_ask":"0.19","best_bid":"0.18","hash":"ddb3a90bf4766fcf6edae59fa17228ba750ae93a","price":"0.96","side":"SELL","size":"1336.5"}],"timestamp":"1785122013063"},"payload_hash":"47e5eddf58efe915ee1ffc76d5234098a7caca45ad052914c930e4330b82d146","raw_frame":"{\"market\":\"0xf9d60bb033695053c4d1d8592e52171c1042f64b41a4b72e09dcc6f4852b6670\", \"price_changes\":[{\"asset_id\":\"8698449539441374295770236407991735029336433231649246775082939325523552031992\", \"price\":\"0.04\", \"size\":\"1336.5\", \"side\":\"BUY\", \"hash\":\"f026f0d01741d3ff73e1699563e1a8a2fcd0e489\", \"best_bid\":\"0.81\", \"best_ask\":\"0.82\"}, {\"asset_id\":\"96283536366176669581486355171583722558858323126916278856549586825357358273536\", \"price\":\"0.96\", \"size\":\"1336.5\", \"side\":\"SELL\", \"hash\":\"ddb3a90bf4766fcf6edae59fa17228ba750ae93a\", \"best_bid\":\"0.18\", \"best_ask\":\"0.19\"}], \"timestamp\":\"1785122013063\", \"event_type\":\"price_change\"}","received_at":"2026-07-27T03:13:32.963239Z","schema_version":"clob-market-ws.price_change.v1","sequence":null,"server_hash":null,"server_timestamp":"1785122013063","session_id":"ff6d21c8283948938400a32613abec2c","source":"clob_market_ws"},"received_at":"2026-07-27T03:13:32.963239Z","record_id":"504dfdf6516198636a81f4b47ccfaeb9550b364ba18a96f14758beebb0a13826","schema_fingerprint":"4aa3821a28b0b7c2400bc59aba4bcc0a76e971dadd19610d3ad38c768e124dc7","schema_version":"edge-lab-recorder.raw.v1","sequence":null,"source":"clob_market_ws"}
{"event_at":"2026-07-27T03:13:33.147000Z","event_fingerprint":"1e064ed7fc7b49c13914a05d8e5d9483a5ffd3464badca4941d5ffc02f6fc123","payload":{"connection_id":"f95883f18d264834af91809e5f803e9f","event_at":"2026-07-27T03:13:33.147000Z","event_type":"price_change","frame_hash":"8ac034df289b6d12364891442147218c8aa59543d4c8970ff04c7571f31ef873","frame_index":0,"kind":"data","monotonic_ns":223996378653750,"payload":{"event_type":"price_change","market":"0xf9d60bb033695053c4d1d8592e52171c1042f64b41a4b72e09dcc6f4852b6670","price_changes":[{"asset_id":"8698449539441374295770236407991735029336433231649246775082939325523552031992","best_ask":"0.82","best_bid":"0.81","hash":"e03938fd5b5af46df95498c14f1bfff1c47ad924","price":"0.75","side":"BUY","size":"83"},{"asset_id":"96283536366176669581486355171583722558858323126916278856549586825357358273536","best_ask":"0.19","best_bid":"0.18","hash":"6ae5b161d5ac9564bf87d8c252c8ab6dcfd50a32","price":"0.25","side":"SELL","size":"83"}],"timestamp":"1785122013147"},"payload_hash":"bc8003faaa8bbedffa4e7be343f26dcab0a0f08a66b69db379962b6216c7e5d3","raw_frame":"{\"market\":\"0xf9d60bb033695053c4d1d8592e52171c1042f64b41a4b72e09dcc6f4852b6670\", \"price_changes\":[{\"asset_id\":\"8698449539441374295770236407991735029336433231649246775082939325523552031992\", \"price\":\"0.75\", \"size\":\"83\", \"side\":\"BUY\", \"hash\":\"e03938fd5b5af46df95498c14f1bfff1c47ad924\", \"best_bid\":\"0.81\", \"best_ask\":\"0.82\"}, {\"asset_id\":\"96283536366176669581486355171583722558858323126916278856549586825357358273536\", \"price\":\"0.25\", \"size\":\"83\", \"side\":\"SELL\", \"hash\":\"6ae5b161d5ac9564bf87d8c252c8ab6dcfd50a32\", \"best_bid\":\"0.18\", \"best_ask\":\"0.19\"}], \"timestamp\":\"1785122013147\", \"event_type\":\"price_change\"}","received_at":"2026-07-27T03:13:33.046198Z","schema_version":"clob-market-ws.price_change.v1","sequence":null,"server_hash":null,"server_timestamp":"1785122013147","session_id":"ff6d21c8283948938400a32613abec2c","source":"clob_market_ws"},"received_at":"2026-07-27T03:13:33.046198Z","record_id":"abf5637b388ce960601325316db116e8b3e7b5cfc06e0c231fa79d372a0e2bf4","schema_fingerprint":"4aa3821a28b0b7c2400bc59aba4bcc0a76e971dadd19610d3ad38c768e124dc7","schema_version":"edge-lab-recorder.raw.v1","sequence":null,"source":"clob_market_ws"}
{"event_at":"2026-07-27T03:13:33.152000Z","event_fingerprint":"a6cd005e8d422d6efedddec827f90bb00c3dbf0eb0d32e86863fbf87453fb63c","payload":{"connection_id":"f95883f18d264834af91809e5f803e9f","event_at":"2026-07-27T03:13:33.152000Z","event_type":"price_change","frame_hash":"d0caa0473dc60f671cb9b75c916481b06995412338a852102978f75ce2f81b09","frame_index":0,"kind":"data","monotonic_ns":223996384557791,"payload":{"event_type":"price_change","market":"0xf9d60bb033695053c4d1d8592e52171c1042f64b41a4b72e09dcc6f4852b6670","price_changes":[{"asset_id":"8698449539441374295770236407991735029336433231649246775082939325523552031992","best_ask":"0.82","best_bid":"0.81","hash":"3ff3f4c9f88a7ea60b198fa3293ee879caa70754","price":"0.79","side":"BUY","size":"154.5"},{"asset_id":"96283536366176669581486355171583722558858323126916278856549586825357358273536","best_ask":"0.19","best_bid":"0.18","hash":"dd5445be5102fa35c6738bba94108347a954f57d","price":"0.21","side":"SELL","size":"154.5"}],"timestamp":"1785122013152"},"payload_hash":"599ef6a4ad27a858a6378c7fbbc56a81a35975ad92cdb101df8ff5cac2546c74","raw_frame":"{\"market\":\"0xf9d60bb033695053c4d1d8592e52171c1042f64b41a4b72e09dcc6f4852b6670\", \"price_changes\":[{\"asset_id\":\"8698449539441374295770236407991735029336433231649246775082939325523552031992\", \"price\":\"0.79\", \"size\":\"154.5\", \"side\":\"BUY\", \"hash\":\"3ff3f4c9f88a7ea60b198fa3293ee879caa70754\", \"best_bid\":\"0.81\", \"best_ask\":\"0.82\"}, {\"asset_id\":\"96283536366176669581486355171583722558858323126916278856549586825357358273536\", \"price\":\"0.21\", \"size\":\"154.5\", \"side\":\"SELL\", \"hash\":\"dd5445be5102fa35c6738bba94108347a954f57d\", \"best_bid\":\"0.18\", \"best_ask\":\"0.19\"}], \"timestamp\":\"1785122013152\", \"event_type\":\"price_change\"}","received_at":"2026-07-27T03:13:33.052109Z","schema_version":"clob-market-ws.price_change.v1","sequence":null,"server_hash":null,"server_timestamp":"1785122013152","session_id":"ff6d21c8283948938400a32613abec2c","source":"clob_market_ws"},"received_at":"2026-07-27T03:13:33.052109Z","record_id":"515bb0cdda2d046454610a68de716c7addac014bfa20d5c95948f190309a990f","schema_fingerprint":"4aa3821a28b0b7c2400bc59aba4bcc0a76e971dadd19610d3ad38c768e124dc7","schema_version":"edge-lab-recorder.raw.v1","sequence":null,"source":"clob_market_ws"}
{"event_at":"2026-07-27T03:13:33.170000Z","event_fingerprint":"1aa7d6e238e4880a375f9649f4f28aeed5658f48ec97c7bc4c4b4022415b6ced","payload":{"connection_id":"f95883f18d264834af91809e5f803e9f","event_at":"2026-07-27T03:13:33.170000Z","event_type":"price_change","frame_hash":"d8902ae1dcb7d53e79036733d272bea6494825627e20627288ae00ea573d2514","frame_index":0,"kind":"data","monotonic_ns":223996401434916,"payload":{"event_type":"price_change","market":"0xf9d60bb033695053c4d1d8592e52171c1042f64b41a4b72e09dcc6f4852b6670","price_changes":[{"asset_id":"8698449539441374295770236407991735029336433231649246775082939325523552031992","best_ask":"0.82","best_bid":"0.81","hash":"da0ca4e55bddef828040aeef064f06aa94d0ff77","price":"0.79","side":"BUY","size":"149.5"},{"asset_id":"96283536366176669581486355171583722558858323126916278856549586825357358273536","best_ask":"0.19","best_bid":"0.18","hash":"3faf74e2996d0f1d9261143d2794d54a43f3545c","price":"0.21","side":"SELL","size":"149.5"}],"timestamp":"1785122013170"},"payload_hash":"a39c96da4e75ea01c96d15f5208366233a2432d90f38f2f44130905ee65ccd44","raw_frame":"{\"market\":\"0xf9d60bb033695053c4d1d8592e52171c1042f64b41a4b72e09dcc6f4852b6670\", \"price_changes\":[{\"asset_id\":\"8698449539441374295770236407991735029336433231649246775082939325523552031992\", \"price\":\"0.79\", \"size\":\"149.5\", \"side\":\"BUY\", \"hash\":\"da0ca4e55bddef828040aeef064f06aa94d0ff77\", \"best_bid\":\"0.81\", \"best_ask\":\"0.82\"}, {\"asset_id\":\"96283536366176669581486355171583722558858323126916278856549586825357358273536\", \"price\":\"0.21\", \"size\":\"149.5\", \"side\":\"SELL\", \"hash\":\"3faf74e2996d0f1d9261143d2794d54a43f3545c\", \"best_bid\":\"0.18\", \"best_ask\":\"0.19\"}], \"timestamp\":\"1785122013170\", \"event_type\":\"price_change\"}","received_at":"2026-07-27T03:13:33.068978Z","schema_version":"clob-market-ws.price_change.v1","sequence":null,"server_hash":null,"server_timestamp":"1785122013170","session_id":"ff6d21c8283948938400a32613abec2c","source":"clob_market_ws"},"received_at":"2026-07-27T03:13:33.068978Z","record_id":"5c95c1e0e791debb3644cfb9f81dab726bc5939c1260978ae09f8ee73c560c43","schema_fingerprint":"4aa3821a28b0b7c2400bc59aba4bcc0a76e971dadd19610d3ad38c768e124dc7","schema_version":"edge-lab-recorder.raw.v1","sequence":null,"source":"clob_market_ws"}
{"event_at":"2026-07-27T03:13:33.174000Z","event_fingerprint":"8d82f82b6073a11e9df292e54081aa2989c654b3a0e68754896de580906ba6b7","payload":{"connection_id":"f95883f18d264834af91809e5f803e9f","event_at":"2026-07-27T03:13:33.174000Z","event_type":"price_change","frame_hash":"445e40078f71dcff6b2ccb1dbb57c39be3ac9ae3d5e4ec31a8d74898783a963f","frame_index":0,"kind":"data","monotonic_ns":223996404910666,"payload":{"event_type":"price_change","market":"0xf9d60bb033695053c4d1d8592e52171c1042f64b41a4b72e09dcc6f4852b6670","price_changes":[{"asset_id":"96283536366176669581486355171583722558858323126916278856549586825357358273536","best_ask":"0.19","best_bid":"0.18","hash":"3a5cad4f84c4eb194f0762c105b72f009c499ffd","price":"0.01","side":"BUY","size":"7139.52"},{"asset_id":"8698449539441374295770236407991735029336433231649246775082939325523552031992","best_ask":"0.82","best_bid":"0.81","hash":"36e935478d2d49d4fe120f69ec5425b6573277c0","price":"0.99","side":"SELL","size":"7139.52"}],"timestamp":"1785122013174"},"payload_hash":"4f4a26336931405f50a6179832a4de39b99245e9e75fea8e2cf3cc865fc28f96","raw_frame":"{\"market\":\"0xf9d60bb033695053c4d1d8592e52171c1042f64b41a4b72e09dcc6f4852b6670\", \"price_changes\":[{\"asset_id\":\"96283536366176669581486355171583722558858323126916278856549586825357358273536\", \"price\":\"0.01\", \"size\":\"7139.52\", \"side\":\"BUY\", \"hash\":\"3a5cad4f84c4eb194f0762c105b72f009c499ffd\", \"best_bid\":\"0.18\", \"best_ask\":\"0.19\"}, {\"asset_id\":\"8698449539441374295770236407991735029336433231649246775082939325523552031992\", \"price\":\"0.99\", \"size\":\"7139.52\", \"side\":\"SELL\", \"hash\":\"36e935478d2d49d4fe120f69ec5425b6573277c0\", \"best_bid\":\"0.81\", \"best_ask\":\"0.82\"}], \"timestamp\":\"1785122013174\", \"event_type\":\"price_change\"}","received_at":"2026-07-27T03:13:33.072462Z","schema_version":"clob-market-ws.price_change.v1","sequence":null,"server_hash":null,"server_timestamp":"1785122013174","session_id":"ff6d21c8283948938400a32613abec2c","source":"clob_market_ws"},"received_at":"2026-07-27T03:13:33.072462Z","record_id":"0feb8baa8170e216fc0654b050a029b7ffd9e15ef2695ea4179d76513c7c1345","schema_fingerprint":"4aa3821a28b0b7c2400bc59aba4bcc0a76e971dadd19610d3ad38c768e124dc7","schema_version":"edge-lab-recorder.raw.v1","sequence":null,"source":"clob_market_ws"}
{"event_at":"2026-07-27T03:13:33.174000Z","event_fingerprint":"dc28b2b08c80df79d3c6d0925d77fd6f2821b09417842ae9098bf6583ce0bfc6","payload":{"connection_id":"f95883f18d264834af91809e5f803e9f","event_at":"2026-07-27T03:13:33.174000Z","event_type":"price_change","frame_hash":"6f3ea023f3341110380f661e7dd6baf0d66036bfe69ad533fd171ceac3aeee5b","frame_index":0,"kind":"data","monotonic_ns":223996406485458,"payload":{"event_type":"price_change","market":"0xf9d60bb033695053c4d1d8592e52171c1042f64b41a4b72e09dcc6f4852b6670","price_changes":[{"asset_id":"8698449539441374295770236407991735029336433231649246775082939325523552031992","best_ask":"0.82","best_bid":"0.81","hash":"ed6d709f48ded7287f47f3c53a944898b3d2b50e","price":"0.01","side":"BUY","size":"8032.52"},{"asset_id":"96283536366176669581486355171583722558858323126916278856549586825357358273536","best_ask":"0.19","best_bid":"0.18","hash":"e27c69e19a4fecc522253e3b1744e1cef9149622","price":"0.99","side":"SELL","size":"8032.52"}],"timestamp":"1785122013174"},"payload_hash":"a081e882426e691416b4aa58cb215d05f3c8041b7dae9599f094ddcc50571fb6","raw_frame":"{\"market\":\"0xf9d60bb033695053c4d1d8592e52171c1042f64b41a4b72e09dcc6f4852b6670\", \"price_changes\":[{\"asset_id\":\"8698449539441374295770236407991735029336433231649246775082939325523552031992\", \"price\":\"0.01\", \"size\":\"8032.52\", \"side\":\"BUY\", \"hash\":\"ed6d709f48ded7287f47f3c53a944898b3d2b50e\", \"best_bid\":\"0.81\", \"best_ask\":\"0.82\"}, {\"asset_id\":\"96283536366176669581486355171583722558858323126916278856549586825357358273536\", \"price\":\"0.99\", \"size\":\"8032.52\", \"side\":\"SELL\", \"hash\":\"e27c69e19a4fecc522253e3b1744e1cef9149622\", \"best_bid\":\"0.18\", \"best_ask\":\"0.19\"}], \"timestamp\":\"1785122013174\", \"event_type\":\"price_change\"}","received_at":"2026-07-27T03:13:33.074033Z","schema_version":"clob-market-ws.price_change.v1","sequence":null,"server_hash":null,"server_timestamp":"1785122013174","session_id":"ff6d21c8283948938400a32613abec2c","source":"clob_market_ws"},"received_at":"2026-07-27T03:13:33.074033Z","record_id":"a66fa382016fcded59527f6872b04e22278c037eff6cc29a7c06ccb1890ee67c","schema_fingerprint":"4aa3821a28b0b7c2400bc59aba4bcc0a76e971dadd19610d3ad38c768e124dc7","schema_version":"edge-lab-recorder.raw.v1","sequence":null,"source":"clob_market_ws"}
{"event_at":"2026-07-27T03:13:33.175000Z","event_fingerprint":"36960350cc9e27fa1db49afabec551c0e423bb80bced189d34c40ed3b00c7e28","payload":{"connection_id":"f95883f18d264834af91809e5f803e9f","event_at":"2026-07-27T03:13:33.175000Z","event_type":"price_change","frame_hash":"56ba9865d60f69380f08a7a314690681d1e78eb27d40cf0d06c7dd191fda98df","frame_index":0,"kind":"data","monotonic_ns":223996408345916,"payload":{"event_type":"price_change","market":"0xf9d60bb033695053c4d1d8592e52171c1042f64b41a4b72e09dcc6f4852b6670","price_changes":[{"asset_id":"8698449539441374295770236407991735029336433231649246775082939325523552031992","best_ask":"0.82","best_bid":"0.81","hash":"c4c41aa9fe31f027ea24b481ddc252ddd1d7f61c","price":"0.04","side":"BUY","size":"1331.5"},{"asset_id":"96283536366176669581486355171583722558858323126916278856549586825357358273536","best_ask":"0.19","best_bid":"0.18","hash":"e6b48e5e530f998a8756d1ea9d7a7beb3cc0da1f","price":"0.96","side":"SELL","size":"1331.5"}],"timestamp":"1785122013175"},"payload_hash":"5bb280de2f76927ee7e1d1699de9cde14d6f8a4479369c332d51163847d19782","raw_frame":"{\"market\":\"0xf9d60bb033695053c4d1d8592e52171c1042f64b41a4b72e09dcc6f4852b6670\", \"price_changes\":[{\"asset_id\":\"8698449539441374295770236407991735029336433231649246775082939325523552031992\", \"price\":\"0.04\", \"size\":\"1331.5\", \"side\":\"BUY\", \"hash\":\"c4c41aa9fe31f027ea24b481ddc252ddd1d7f61c\", \"best_bid\":\"0.81\", \"best_ask\":\"0.82\"}, {\"asset_id\":\"96283536366176669581486355171583722558858323126916278856549586825357358273536\", \"price\":\"0.96\", \"size\":\"1331.5\", \"side\":\"SELL\", \"hash\":\"e6b48e5e530f998a8756d1ea9d7a7beb3cc0da1f\", \"best_bid\":\"0.18\", \"best_ask\":\"0.19\"}], \"timestamp\":\"1785122013175\", \"event_type\":\"price_change\"}","received_at":"2026-07-27T03:13:33.075899Z","schema_version":"clob-market-ws.price_change.v1","sequence":null,"server_hash":null,"server_timestamp":"1785122013175","session_id":"ff6d21c8283948938400a32613abec2c","source":"clob_market_ws"},"received_at":"2026-07-27T03:13:33.075899Z","record_id":"8ab4edec0b3be3e3fc74383a95eee2724693443c4668e121a6a9e7f3dcf6b14e","schema_fingerprint":"4aa3821a28b0b7c2400bc59aba4bcc0a76e971dadd19610d3ad38c768e124dc7","schema_version":"edge-lab-recorder.raw.v1","sequence":null,"source":"clob_market_ws"}
{"event_at":"2026-07-27T03:13:33.193000Z","event_fingerprint":"e53a4f67e628357698d75024583d65ae2925d9f19fd5316a88fa4250abe59b1f","payload":{"connection_id":"f95883f18d264834af91809e5f803e9f","event_at":"2026-07-27T03:13:33.193000Z","event_type":"price_change","frame_hash":"de739b61fc6e7ab674233e410e777fcdecde89c2843ee08fff9de3f01c8ba332","frame_index":0,"kind":"data","monotonic_ns":223996424759875,"payload":{"event_type":"price_change","market":"0xf9d60bb033695053c4d1d8592e52171c1042f64b41a4b72e09dcc6f4852b6670","price_changes":[{"asset_id":"8698449539441374295770236407991735029336433231649246775082939325523552031992","best_ask":"0.82","best_bid":"0.81","hash":"d89f18556e077e7ee82d86277630a654264a8541","price":"0.01","side":"BUY","size":"8027.52"},{"asset_id":"96283536366176669581486355171583722558858323126916278856549586825357358273536","best_ask":"0.19","best_bid":"0.18","hash":"4a0bab0b2da3b798b9c0588767569e5a28a31f4e","price":"0.99","side":"SELL","size":"8027.52"}],"timestamp":"1785122013193"},"payload_hash":"a3db4570437e515b0c3a1856969fd803edd70a57675121b940d12f436861887f","raw_frame":"{\"market\":\"0xf9d60bb033695053c4d1d8592e52171c1042f64b41a4b72e09dcc6f4852b6670\", \"price_changes\":[{\"asset_id\":\"8698449539441374295770236407991735029336433231649246775082939325523552031992\", \"price\":\"0.01\", \"size\":\"8027.52\", \"side\":\"BUY\", \"hash\":\"d89f18556e077e7ee82d86277630a654264a8541\", \"best_bid\":\"0.81\", \"best_ask\":\"0.82\"}, {\"asset_id\":\"96283536366176669581486355171583722558858323126916278856549586825357358273536\", \"price\":\"0.99\", \"size\":\"8027.52\", \"side\":\"SELL\", \"hash\":\"4a0bab0b2da3b798b9c0588767569e5a28a31f4e\", \"best_bid\":\"0.18\", \"best_ask\":\"0.19\"}], \"timestamp\":\"1785122013193\", \"event_type\":\"price_change\"}","received_at":"2026-07-27T03:13:33.092309Z","schema_version":"clob-market-ws.price_change.v1","sequence":null,"server_hash":null,"server_timestamp":"1785122013193","session_id":"ff6d21c8283948938400a32613abec2c","source":"clob_market_ws"},"received_at":"2026-07-27T03:13:33.092309Z","record_id":"a70ff082c157d59eb049ee71988dad22a4b9119c9c06c7197cd7fad5ef271f92","schema_fingerprint":"4aa3821a28b0b7c2400bc59aba4bcc0a76e971dadd19610d3ad38c768e124dc7","schema_version":"edge-lab-recorder.raw.v1","sequence":null,"source":"clob_market_ws"}
{"event_at":"2026-07-27T03:13:33.196000Z","event_fingerprint":"efa852be8ed7fd61c2dfc484447455b2a88924eec01ccf8a27b833706f73a081","payload":{"connection_id":"f95883f18d264834af91809e5f803e9f","event_at":"2026-07-27T03:13:33.196000Z","event_type":"price_change","frame_hash":"9f93df200d4d752f1df29f3c701a6ebf6f13c09e823617bcd1cfc77926ef1c2a","frame_index":0,"kind":"data","monotonic_ns":223996428506875,"payload":{"event_type":"price_change","market":"0xf9d60bb033695053c4d1d8592e52171c1042f64b41a4b72e09dcc6f4852b6670","price_changes":[{"asset_id":"8698449539441374295770236407991735029336433231649246775082939325523552031992","best_ask":"0.82","best_bid":"0.81","hash":"796dba6e6c95a31cc53fbef49a6d329817aad8a8","price":"0.77","side":"BUY","size":"167.7"},{"asset_id":"96283536366176669581486355171583722558858323126916278856549586825357358273536","best_ask":"0.19","best_bid":"0.18","hash":"8775c203b38965d60608cf7c3b200aad7bcb71c5","price":"0.23","side":"SELL","size":"167.7"}],"timestamp":"1785122013196"},"payload_hash":"ef2dc015707754c42bb578871ad08f2ce3227910b27cbd04c07129526ce0be40","raw_frame":"{\"market\":\"0xf9d60bb033695053c4d1d8592e52171c1042f64b41a4b72e09dcc6f4852b6670\", \"price_changes\":[{\"asset_id\":\"8698449539441374295770236407991735029336433231649246775082939325523552031992\", \"price\":\"0.77\", \"size\":\"167.7\", \"side\":\"BUY\", \"hash\":\"796dba6e6c95a31cc53fbef49a6d329817aad8a8\", \"best_bid\":\"0.81\", \"best_ask\":\"0.82\"}, {\"asset_id\":\"96283536366176669581486355171583722558858323126916278856549586825357358273536\", \"price\":\"0.23\", \"size\":\"167.7\", \"side\":\"SELL\", \"hash\":\"8775c203b38965d60608cf7c3b200aad7bcb71c5\", \"best_bid\":\"0.18\", \"best_ask\":\"0.19\"}], \"timestamp\":\"1785122013196\", \"event_type\":\"price_change\"}","received_at":"2026-07-27T03:13:33.096058Z","schema_version":"clob-market-ws.price_change.v1","sequence":null,"server_hash":null,"server_timestamp":"1785122013196","session_id":"ff6d21c8283948938400a32613abec2c","source":"clob_market_ws"},"received_at":"2026-07-27T03:13:33.096058Z","record_id":"59b4167a7fbbf18b4385db885fbc0a857d264295a9e4806a6914ea51f694584c","schema_fingerprint":"4aa3821a28b0b7c2400bc59aba4bcc0a76e971dadd19610d3ad38c768e124dc7","schema_version":"edge-lab-recorder.raw.v1","sequence":null,"source":"clob_market_ws"}
{"event_at":"2026-07-27T03:13:33.210000Z","event_fingerprint":"c3c0f49ebb5d0f9b3a15d160c3d003c59f17b7fb3daafb7009683598990cc210","payload":{"connection_id":"f95883f18d264834af91809e5f803e9f","event_at":"2026-07-27T03:13:33.210000Z","event_type":"price_change","frame_hash":"a151f3bf6dcd7006e6386a5b87c8ead13f693e4097126e42b5dc3afe1ffb3d7b","frame_index":0,"kind":"data","monotonic_ns":223996441183166,"payload":{"event_type":"price_change","market":"0xf9d60bb033695053c4d1d8592e52171c1042f64b41a4b72e09dcc6f4852b6670","price_changes":[{"asset_id":"8698449539441374295770236407991735029336433231649246775082939325523552031992","best_ask":"0.82","best_bid":"0.81","hash":"be25d14dbbda33e55824dd20258fb15fcc332ba5","price":"0.01","side":"BUY","size":"8032.52"},{"asset_id":"96283536366176669581486355171583722558858323126916278856549586825357358273536","best_ask":"0.19","best_bid":"0.18","hash":"137afabee98e770244a6c5739fdb25055c0f7de2","price":"0.99","side":"SELL","size":"8032.52"}],"timestamp":"1785122013210"},"payload_hash":"cf9a9963fb146f290d9f4669ca6b679f2ae3b31d44d1ed9b817dc5b0637dfbf4","raw_frame":"{\"market\":\"0xf9d60bb033695053c4d1d8592e52171c1042f64b41a4b72e09dcc6f4852b6670\", \"price_changes\":[{\"asset_id\":\"8698449539441374295770236407991735029336433231649246775082939325523552031992\", \"price\":\"0.01\", \"size\":\"8032.52\", \"side\":\"BUY\", \"hash\":\"be25d14dbbda33e55824dd20258fb15fcc332ba5\", \"best_bid\":\"0.81\", \"best_ask\":\"0.82\"}, {\"asset_id\":\"96283536366176669581486355171583722558858323126916278856549586825357358273536\", \"price\":\"0.99\", \"size\":\"8032.52\", \"side\":\"SELL\", \"hash\":\"137afabee98e770244a6c5739fdb25055c0f7de2\", \"best_bid\":\"0.18\", \"best_ask\":\"0.19\"}], \"timestamp\":\"1785122013210\", \"event_type\":\"price_change\"}","received_at":"2026-07-27T03:13:33.108732Z","schema_version":"clob-market-ws.price_change.v1","sequence":null,"server_hash":null,"server_timestamp":"1785122013210","session_id":"ff6d21c8283948938400a32613abec2c","source":"clob_market_ws"},"received_at":"2026-07-27T03:13:33.108732Z","record_id":"bdf82a191c823e0e58ac9e39bc511f2998a6dc06e88194859f0d17e4d396a634","schema_fingerprint":"4aa3821a28b0b7c2400bc59aba4bcc0a76e971dadd19610d3ad38c768e124dc7","schema_version":"edge-lab-recorder.raw.v1","sequence":null,"source":"clob_market_ws"}
{"event_at":"2026-07-27T03:13:33.211000Z","event_fingerprint":"a89f5841d1a4fbef9666f12a15251f97701ec037a80d81ea47b24777d70c4e9f","payload":{"connection_id":"f95883f18d264834af91809e5f803e9f","event_at":"2026-07-27T03:13:33.211000Z","event_type":"price_change","frame_hash":"7049570e89a2688615663d7d31b42fb2c286e571a4ef8d9e5294d9bd4fc57c31","frame_index":0,"kind":"data","monotonic_ns":223996443295875,"payload":{"event_type":"price_change","market":"0xf9d60bb033695053c4d1d8592e52171c1042f64b41a4b72e09dcc6f4852b6670","price_changes":[{"asset_id":"8698449539441374295770236407991735029336433231649246775082939325523552031992","best_ask":"0.82","best_bid":"0.81","hash":"e3d6e9b6a6f0d778815baee0c4f6162617578222","price":"0.81","side":"BUY","size":"18"},{"asset_id":"96283536366176669581486355171583722558858323126916278856549586825357358273536","best_ask":"0.19","best_bid":"0.18","hash":"47a0fdaa8ad97cfb7c548b7ef804b40ee00bff80","price":"0.19","side":"SELL","size":"18"}],"timestamp":"1785122013211"},"payload_hash":"f0d40d104c298c0a1c8c58b0684b7eb00ea1e0e03b71b45250953696dc7e7e0f","raw_frame":"{\"market\":\"0xf9d60bb033695053c4d1d8592e52171c1042f64b41a4b72e09dcc6f4852b6670\", \"price_changes\":[{\"asset_id\":\"8698449539441374295770236407991735029336433231649246775082939325523552031992\", \"price\":\"0.81\", \"size\":\"18\", \"side\":\"BUY\", \"hash\":\"e3d6e9b6a6f0d778815baee0c4f6162617578222\", \"best_bid\":\"0.81\", \"best_ask\":\"0.82\"}, {\"asset_id\":\"96283536366176669581486355171583722558858323126916278856549586825357358273536\", \"price\":\"0.19\", \"size\":\"18\", \"side\":\"SELL\", \"hash\":\"47a0fdaa8ad97cfb7c548b7ef804b40ee00bff80\", \"best_bid\":\"0.18\", \"best_ask\":\"0.19\"}], \"timestamp\":\"1785122013211\", \"event_type\":\"price_change\"}","received_at":"2026-07-27T03:13:33.110845Z","schema_version":"clob-market-ws.price_change.v1","sequence":null,"server_hash":null,"server_timestamp":"1785122013211","session_id":"ff6d21c8283948938400a32613abec2c","source":"clob_market_ws"},"received_at":"2026-07-27T03:13:33.110845Z","record_id":"013b4b058c82976feeddbe0df3945bb0407eafed0d48849f3086f142af63e04d","schema_fingerprint":"4aa3821a28b0b7c2400bc59aba4bcc0a76e971dadd19610d3ad38c768e124dc7","schema_version":"edge-lab-recorder.raw.v1","sequence":null,"source":"clob_market_ws"}
{"event_at":"2026-07-27T03:13:33.212000Z","event_fingerprint":"a04a38ecfc3613e416bd2615eced53ed4e310859a0b5dd9bde82208f3ec0e5ea","payload":{"connection_id":"f95883f18d264834af91809e5f803e9f","event_at":"2026-07-27T03:13:33.212000Z","event_type":"price_change","frame_hash":"e27dccd4b1cfec689883387e6e9d14dbd6c3643a8f02634e1132fa511099f356","frame_index":0,"kind":"data","monotonic_ns":223996445408125,"payload":{"event_type":"price_change","market":"0xf9d60bb033695053c4d1d8592e52171c1042f64b41a4b72e09dcc6f4852b6670","price_changes":[{"asset_id":"96283536366176669581486355171583722558858323126916278856549586825357358273536","best_ask":"0.19","best_bid":"0.18","hash":"850c99d4e8fd75add177b651ca9b699daaf24492","price":"0.09","side":"BUY","size":"229.1"},{"asset_id":"8698449539441374295770236407991735029336433231649246775082939325523552031992","best_ask":"0.82","best_bid":"0.81","hash":"74b5795205a18a5b7bf80754227070d96f2ee8d2","price":"0.91","side":"SELL","size":"229.1"}],"timestamp":"1785122013212"},"payload_hash":"237a60c58611e65f9eb828bddb02a1c8c7713ecad18306cba64847da4d3923c7","raw_frame":"{\"market\":\"0xf9d60bb033695053c4d1d8592e52171c1042f64b41a4b72e09dcc6f4852b6670\", \"price_changes\":[{\"asset_id\":\"96283536366176669581486355171583722558858323126916278856549586825357358273536\", \"price\":\"0.09\", \"size\":\"229.1\", \"side\":\"BUY\", \"hash\":\"850c99d4e8fd75add177b651ca9b699daaf24492\", \"best_bid\":\"0.18\", \"best_ask\":\"0.19\"}, {\"asset_id\":\"8698449539441374295770236407991735029336433231649246775082939325523552031992\", \"price\":\"0.91\", \"size\":\"229.1\", \"side\":\"SELL\", \"hash\":\"74b5795205a18a5b7bf80754227070d96f2ee8d2\", \"best_bid\":\"0.81\", \"best_ask\":\"0.82\"}], \"timestamp\":\"1785122013212\", \"event_type\":\"price_change\"}","received_at":"2026-07-27T03:13:33.112960Z","schema_version":"clob-market-ws.price_change.v1","sequence":null,"server_hash":null,"server_timestamp":"1785122013212","session_id":"ff6d21c8283948938400a32613abec2c","source":"clob_market_ws"},"received_at":"2026-07-27T03:13:33.112960Z","record_id":"65ca2ce7ff82b0ba3699b9fcdae6cb0c7458b47b8dc120f58341fe4cc988c0c2","schema_fingerprint":"4aa3821a28b0b7c2400bc59aba4bcc0a76e971dadd19610d3ad38c768e124dc7","schema_version":"edge-lab-recorder.raw.v1","sequence":null,"source":"clob_market_ws"}
{"event_at":"2026-07-27T03:13:33.225000Z","event_fingerprint":"361fa0a286284ffcc69276319a0c650c3a0b1cbc7213c7469d23bea9f4865d5a","payload":{"connection_id":"f95883f18d264834af91809e5f803e9f","event_at":"2026-07-27T03:13:33.225000Z","event_type":"price_change","frame_hash":"8c0240940366ec499648639907048e81d000d497c02067f05a09cb4c335a5218","frame_index":0,"kind":"data","monotonic_ns":223996457509166,"payload":{"event_type":"price_change","market":"0xf9d60bb033695053c4d1d8592e52171c1042f64b41a4b72e09dcc6f4852b6670","price_changes":[{"asset_id":"8698449539441374295770236407991735029336433231649246775082939325523552031992","best_ask":"0.82","best_bid":"0.81","hash":"338c8de52e9a8f7ec7fe1953415d93dfba96a63b","price":"0.77","side":"BUY","size":"162.7"},{"asset_id":"96283536366176669581486355171583722558858323126916278856549586825357358273536","best_ask":"0.19","best_bid":"0.18","hash":"69ffca00eaadbce796a0bd7b37082ac9d6652f8d","price":"0.23","side":"SELL","size":"162.7"}],"timestamp":"1785122013225"},"payload_hash":"e731e4062b90ded5884bbc6657bff5fdd609874aaef73e4a681f7c5a8e073165","raw_frame":"{\"market\":\"0xf9d60bb033695053c4d1d8592e52171c1042f64b41a4b72e09dcc6f4852b6670\", \"price_changes\":[{\"asset_id\":\"8698449539441374295770236407991735029336433231649246775082939325523552031992\", \"price\":\"0.77\", \"size\":\"162.7\", \"side\":\"BUY\", \"hash\":\"338c8de52e9a8f7ec7fe1953415d93dfba96a63b\", \"best_bid\":\"0.81\", \"best_ask\":\"0.82\"}, {\"asset_id\":\"96283536366176669581486355171583722558858323126916278856549586825357358273536\", \"price\":\"0.23\", \"size\":\"162.7\", \"side\":\"SELL\", \"hash\":\"69ffca00eaadbce796a0bd7b37082ac9d6652f8d\", \"best_bid\":\"0.18\", \"best_ask\":\"0.19\"}], \"timestamp\":\"1785122013225\", \"event_type\":\"price_change\"}","received_at":"2026-07-27T03:13:33.125059Z","schema_version":"clob-market-ws.price_change.v1","sequence":null,"server_hash":null,"server_timestamp":"1785122013225","session_id":"ff6d21c8283948938400a32613abec2c","source":"clob_market_ws"},"received_at":"2026-07-27T03:13:33.125059Z","record_id":"a937541bb72272de0fb3376b317075f379f265a89e22d6db6d10d2ab93beb2b9","schema_fingerprint":"4aa3821a28b0b7c2400bc59aba4bcc0a76e971dadd19610d3ad38c768e124dc7","schema_version":"edge-lab-recorder.raw.v1","sequence":null,"source":"clob_market_ws"}
{"event_at":"2026-07-27T03:13:33.229000Z","event_fingerprint":"1fd93a2cd8274db7112c21f960f868bc0785737db5a75e2d7bf989e344a2dd41","payload":{"connection_id":"f95883f18d264834af91809e5f803e9f","event_at":"2026-07-27T03:13:33.229000Z","event_type":"price_change","frame_hash":"9b31c271f7cec00a0b8b1e6fd629e04c710a74b81649aa94c789ebea45d38c5a","frame_index":0,"kind":"data","monotonic_ns":223996460354000,"payload":{"event_type":"price_change","market":"0xf9d60bb033695053c4d1d8592e52171c1042f64b41a4b72e09dcc6f4852b6670","price_changes":[{"asset_id":"96283536366176669581486355171583722558858323126916278856549586825357358273536","best_ask":"0.19","best_bid":"0.18","hash":"e38f74e66fc24b27ee8c5d3c25888740dd666627","price":"0.01","side":"BUY","size":"7134.52"},{"asset_id":"8698449539441374295770236407991735029336433231649246775082939325523552031992","best_ask":"0.82","best_bid":"0.81","hash":"d563d7a197e506e6e75cf4131191dc6cedd3dbb4","price":"0.99","side":"SELL","size":"7134.52"}],"timestamp":"1785122013229"},"payload_hash":"e8919fededfccad6c60901ef99ff7b5b56d740f301f9845d50b5a81dc79edd66","raw_frame":"{\"market\":\"0xf9d60bb033695053c4d1d8592e52171c1042f64b41a4b72e09dcc6f4852b6670\", \"price_changes\":[{\"asset_id\":\"96283536366176669581486355171583722558858323126916278856549586825357358273536\", \"price\":\"0.01\", \"size\":\"7134.52\", \"side\":\"BUY\", \"hash\":\"e38f74e66fc24b27ee8c5d3c25888740dd666627\", \"best_bid\":\"0.18\", \"best_ask\":\"0.19\"}, {\"asset_id\":\"8698449539441374295770236407991735029336433231649246775082939325523552031992\", \"price\":\"0.99\", \"size\":\"7134.52\", \"side\":\"SELL\", \"hash\":\"d563d7a197e506e6e75cf4131191dc6cedd3dbb4\", \"best_bid\":\"0.81\", \"best_ask\":\"0.82\"}], \"timestamp\":\"1785122013229\", \"event_type\":\"price_change\"}","received_at":"2026-07-27T03:13:33.127907Z","schema_version":"clob-market-ws.price_change.v1","sequence":null,"server_hash":null,"server_timestamp":"1785122013229","session_id":"ff6d21c8283948938400a32613abec2c","source":"clob_market_ws"},"received_at":"2026-07-27T03:13:33.127907Z","record_id":"d043f9282c12da32b5fabc09ce56809d80df09f7270c78377b86daded96d410a","schema_fingerprint":"4aa3821a28b0b7c2400bc59aba4bcc0a76e971dadd19610d3ad38c768e124dc7","schema_version":"edge-lab-recorder.raw.v1","sequence":null,"source":"clob_market_ws"}
{"event_at":"2026-07-27T03:13:33.230000Z","event_fingerprint":"9b274df8e100f53de53bc72ecec5216dcbb47edadad6948c42ff4258ffafc358","payload":{"connection_id":"f95883f18d264834af91809e5f803e9f","event_at":"2026-07-27T03:13:33.230000Z","event_type":"price_change","frame_hash":"9a69a9177aa604a1d05dfacd06a1f2d4241ff76ab206e60c4ad91867623c4cfb","frame_index":0,"kind":"data","monotonic_ns":223996461819750,"payload":{"event_type":"price_change","market":"0xf9d60bb033695053c4d1d8592e52171c1042f64b41a4b72e09dcc6f4852b6670","price_changes":[{"asset_id":"8698449539441374295770236407991735029336433231649246775082939325523552031992","best_ask":"0.82","best_bid":"0.81","hash":"c9e27743fa3c4674194dcb3c926ae07a9c553af5","price":"0.01","side":"BUY","size":"8027.52"},{"asset_id":"96283536366176669581486355171583722558858323126916278856549586825357358273536","best_ask":"0.19","best_bid":"0.18","hash":"6fa8091aecc1b32b234cadb5237208b92bca42ca","price":"0.99","side":"SELL","size":"8027.52"}],"timestamp":"1785122013230"},"payload_hash":"2d6a63fb098e794dfb0866f2f7f22948dde310d651ac32f6152b626d5c4ddfe5","raw_frame":"{\"market\":\"0xf9d60bb033695053c4d1d8592e52171c1042f64b41a4b72e09dcc6f4852b6670\", \"price_changes\":[{\"asset_id\":\"8698449539441374295770236407991735029336433231649246775082939325523552031992\", \"price\":\"0.01\", \"size\":\"8027.52\", \"side\":\"BUY\", \"hash\":\"c9e27743fa3c4674194dcb3c926ae07a9c553af5\", \"best_bid\":\"0.81\", \"best_ask\":\"0.82\"}, {\"asset_id\":\"96283536366176669581486355171583722558858323126916278856549586825357358273536\", \"price\":\"0.99\", \"size\":\"8027.52\", \"side\":\"SELL\", \"hash\":\"6fa8091aecc1b32b234cadb5237208b92bca42ca\", \"best_bid\":\"0.18\", \"best_ask\":\"0.19\"}], \"timestamp\":\"1785122013230\", \"event_type\":\"price_change\"}","received_at":"2026-07-27T03:13:33.129372Z","schema_version":"clob-market-ws.price_change.v1","sequence":null,"server_hash":null,"server_timestamp":"1785122013230","session_id":"ff6d21c8283948938400a32613abec2c","source":"clob_market_ws"},"received_at":"2026-07-27T03:13:33.129372Z","record_id":"2ae6c4d12c31bd3424500a8dfdbf236b02dbb06752c6153c2d217c785abc1f5a","schema_fingerprint":"4aa3821a28b0b7c2400bc59aba4bcc0a76e971dadd19610d3ad38c768e124dc7","schema_version":"edge-lab-recorder.raw.v1","sequence":null,"source":"clob_market_ws"}
{"event_at":"2026-07-27T03:13:33.231000Z","event_fingerprint":"3034f3d24f4f77ea4eb8eb6fe041b424dc22651cc31ddd33a63a4c1ad27e8641","payload":{"connection_id":"f95883f18d264834af91809e5f803e9f","event_at":"2026-07-27T03:13:33.231000Z","event_type":"price_change","frame_hash":"a09b4e8c34689ad99cbd042d8ed657d47c9ac2925677268130d2bad444485435","frame_index":0,"kind":"data","monotonic_ns":223996463350916,"payload":{"event_type":"price_change","market":"0xf9d60bb033695053c4d1d8592e52171c1042f64b41a4b72e09dcc6f4852b6670","price_changes":[{"asset_id":"8698449539441374295770236407991735029336433231649246775082939325523552031992","best_ask":"0.82","best_bid":"0.81","hash":"4c81d0f888b5777c9f17dd3285b59e1f0b14cd50","price":"0.01","side":"BUY","size":"8022.52"},{"asset_id":"96283536366176669581486355171583722558858323126916278856549586825357358273536","best_ask":"0.19","best_bid":"0.18","hash":"0bd29dd35e3f61ebcda9d7c100d9a6457ad7f709","price":"0.99","side":"SELL","size":"8022.52"}],"timestamp":"1785122013231"},"payload_hash":"17c9cfabef95193b3b1c77cbe12d95d42fd5dda0c764c49c27e6f350fefddc2c","raw_frame":"{\"market\":\"0xf9d60bb033695053c4d1d8592e52171c1042f64b41a4b72e09dcc6f4852b6670\", \"price_changes\":[{\"asset_id\":\"8698449539441374295770236407991735029336433231649246775082939325523552031992\", \"price\":\"0.01\", \"size\":\"8022.52\", \"side\":\"BUY\", \"hash\":\"4c81d0f888b5777c9f17dd3285b59e1f0b14cd50\", \"best_bid\":\"0.81\", \"best_ask\":\"0.82\"}, {\"asset_id\":\"96283536366176669581486355171583722558858323126916278856549586825357358273536\", \"price\":\"0.99\", \"size\":\"8022.52\", \"side\":\"SELL\", \"hash\":\"0bd29dd35e3f61ebcda9d7c100d9a6457ad7f709\", \"best_bid\":\"0.18\", \"best_ask\":\"0.19\"}], \"timestamp\":\"1785122013231\", \"event_type\":\"price_change\"}","received_at":"2026-07-27T03:13:33.130905Z","schema_version":"clob-market-ws.price_change.v1","sequence":null,"server_hash":null,"server_timestamp":"1785122013231","session_id":"ff6d21c8283948938400a32613abec2c","source":"clob_market_ws"},"received_at":"2026-07-27T03:13:33.130905Z","record_id":"4527d153dc6351ff360490aa334bc9fcd8ec23c1dfa6fa4ecc372d0eef76f2c8","schema_fingerprint":"4aa3821a28b0b7c2400bc59aba4bcc0a76e971dadd19610d3ad38c768e124dc7","schema_version":"edge-lab-recorder.raw.v1","sequence":null,"source":"clob_market_ws"}
{"event_at":"2026-07-27T03:13:33.232000Z","event_fingerprint":"94d625919ff183fa997631d80d66e8375bd546f00a27df33db2c9214ad085393","payload":{"connection_id":"f95883f18d264834af91809e5f803e9f","event_at":"2026-07-27T03:13:33.232000Z","event_type":"price_change","frame_hash":"fbde8d5d3bab023d1820e92d491a5ff98a8b5eb8b016ec6b2eb96eda56ade6d5","frame_index":0,"kind":"data","monotonic_ns":223996466071916,"payload":{"event_type":"price_change","market":"0xf9d60bb033695053c4d1d8592e52171c1042f64b41a4b72e09dcc6f4852b6670","price_changes":[{"asset_id":"96283536366176669581486355171583722558858323126916278856549586825357358273536","best_ask":"0.19","best_bid":"0.18","hash":"ecc1bf25d937c7e78e3ea1d83e66b0d344fa4918","price":"0.01","side":"BUY","size":"7139.52"},{"asset_id":"8698449539441374295770236407991735029336433231649246775082939325523552031992","best_ask":"0.82","best_bid":"0.81","hash":"66343804a76a3975a7e1daf46ce783ae60f949c1","price":"0.99","side":"SELL","size":"7139.52"}],"timestamp":"1785122013232"},"payload_hash":"b0f270d581deb1738d1f6f679ec3648810811b861689b8568d74725816dda8d3","raw_frame":"{\"market\":\"0xf9d60bb033695053c4d1d8592e52171c1042f64b41a4b72e09dcc6f4852b6670\", \"price_changes\":[{\"asset_id\":\"96283536366176669581486355171583722558858323126916278856549586825357358273536\", \"price\":\"0.01\", \"size\":\"7139.52\", \"side\":\"BUY\", \"hash\":\"ecc1bf25d937c7e78e3ea1d83e66b0d344fa4918\", \"best_bid\":\"0.18\", \"best_ask\":\"0.19\"}, {\"asset_id\":\"8698449539441374295770236407991735029336433231649246775082939325523552031992\", \"price\":\"0.99\", \"size\":\"7139.52\", \"side\":\"SELL\", \"hash\":\"66343804a76a3975a7e1daf46ce783ae60f949c1\", \"best_bid\":\"0.81\", \"best_ask\":\"0.82\"}], \"timestamp\":\"1785122013232\", \"event_type\":\"price_change\"}","received_at":"2026-07-27T03:13:33.133622Z","schema_version":"clob-market-ws.price_change.v1","sequence":null,"server_hash":null,"server_timestamp":"1785122013232","session_id":"ff6d21c8283948938400a32613abec2c","source":"clob_market_ws"},"received_at":"2026-07-27T03:13:33.133622Z","record_id":"226be614a89ad2951983f27caf40c905fd688b7f77423171021409170c3efc87","schema_fingerprint":"4aa3821a28b0b7c2400bc59aba4bcc0a76e971dadd19610d3ad38c768e124dc7","schema_version":"edge-lab-recorder.raw.v1","sequence":null,"source":"clob_market_ws"}
{"event_at":"2026-07-27T03:13:33.234000Z","event_fingerprint":"3f8ac7cb72d26dcfade864702ddae138d3bfb888b5be47f9543f3e764eb47977","payload":{"connection_id":"f95883f18d264834af91809e5f803e9f","event_at":"2026-07-27T03:13:33.234000Z","event_type":"price_change","frame_hash":"a05f2da6976fceac4f778bc2a091ef11cd60307c3a6d5d349f17a86af47cc52e","frame_index":0,"kind":"data","monotonic_ns":223996469324250,"payload":{"event_type":"price_change","market":"0xf9d60bb033695053c4d1d8592e52171c1042f64b41a4b72e09dcc6f4852b6670","price_changes":[{"asset_id":"96283536366176669581486355171583722558858323126916278856549586825357358273536","best_ask":"0.19","best_bid":"0.18","hash":"716c85b2200c7aa46c93a588daf648bcca15827d","price":"0.01","side":"BUY","size":"7144.52"},{"asset_id":"8698449539441374295770236407991735029336433231649246775082939325523552031992","best_ask":"0.82","best_bid":"0.81","hash":"0597ba8acf8eee9b4b58c6112ffd83882535c21d","price":"0.99","side":"SELL","size":"7144.52"}],"timestamp":"1785122013234"},"payload_hash":"89fcf43c858b71a4e6ee916781060709ebea514cbe914311495c97955945602f","raw_frame":"{\"market\":\"0xf9d60bb033695053c4d1d8592e52171c1042f64b41a4b72e09dcc6f4852b6670\", \"price_changes\":[{\"asset_id\":\"96283536366176669581486355171583722558858323126916278856549586825357358273536\", \"price\":\"0.01\", \"size\":\"7144.52\", \"side\":\"BUY\", \"hash\":\"716c85b2200c7aa46c93a588daf648bcca15827d\", \"best_bid\":\"0.18\", \"best_ask\":\"0.19\"}, {\"asset_id\":\"8698449539441374295770236407991735029336433231649246775082939325523552031992\", \"price\":\"0.99\", \"size\":\"7144.52\", \"side\":\"SELL\", \"hash\":\"0597ba8acf8eee9b4b58c6112ffd83882535c21d\", \"best_bid\":\"0.81\", \"best_ask\":\"0.82\"}], \"timestamp\":\"1785122013234\", \"event_type\":\"price_change\"}","received_at":"2026-07-27T03:13:33.136876Z","schema_version":"clob-market-ws.price_change.v1","sequence":null,"server_hash":null,"server_timestamp":"1785122013234","session_id":"ff6d21c8283948938400a32613abec2c","source":"clob_market_ws"},"received_at":"2026-07-27T03:13:33.136876Z","record_id":"09b73a52934681029adefa49d66f275ed9fdc178554ec0ba0a96055b7a7c1e19","schema_fingerprint":"4aa3821a28b0b7c2400bc59aba4bcc0a76e971dadd19610d3ad38c768e124dc7","schema_version":"edge-lab-recorder.raw.v1","sequence":null,"source":"clob_market_ws"}
{"event_at":"2026-07-27T03:13:33.234000Z","event_fingerprint":"0198bf01659b3c772b3ea7ffa04679a0ca31b4bbd7e5b6f1ab6dd844b40ed5c2","payload":{"connection_id":"f95883f18d264834af91809e5f803e9f","event_at":"2026-07-27T03:13:33.234000Z","event_type":"price_change","frame_hash":"0479e1f2317db189008b9f8fbfc9cb9fb25bb261258bf65f1321c6d7b08765b0","frame_index":0,"kind":"data","monotonic_ns":223996471075958,"payload":{"event_type":"price_change","market":"0xf9d60bb033695053c4d1d8592e52171c1042f64b41a4b72e09dcc6f4852b6670","price_changes":[{"asset_id":"8698449539441374295770236407991735029336433231649246775082939325523552031992","best_ask":"0.82","best_bid":"0.81","hash":"e63eb6e5ae3e9cd3d98babb17ff3805a3a6ec769","price":"0.01","side":"BUY","size":"8017.52"},{"asset_id":"96283536366176669581486355171583722558858323126916278856549586825357358273536","best_ask":"0.19","best_bid":"0.18","hash":"f0fa2b8cf9a2ab633faaf533786f80a1c7ffc5e0","price":"0.99","side":"SELL","size":"8017.52"}],"timestamp":"1785122013234"},"payload_hash":"f68baad8fd169bf227d0a986a14fe14cf0239c869c0502cb2e4ffc158b237827","raw_frame":"{\"market\":\"0xf9d60bb033695053c4d1d8592e52171c1042f64b41a4b72e09dcc6f4852b6670\", \"price_changes\":[{\"asset_id\":\"8698449539441374295770236407991735029336433231649246775082939325523552031992\", \"price\":\"0.01\", \"size\":\"8017.52\", \"side\":\"BUY\", \"hash\":\"e63eb6e5ae3e9cd3d98babb17ff3805a3a6ec769\", \"best_bid\":\"0.81\", \"best_ask\":\"0.82\"}, {\"asset_id\":\"96283536366176669581486355171583722558858323126916278856549586825357358273536\", \"price\":\"0.99\", \"size\":\"8017.52\", \"side\":\"SELL\", \"hash\":\"f0fa2b8cf9a2ab633faaf533786f80a1c7ffc5e0\", \"best_bid\":\"0.18\", \"best_ask\":\"0.19\"}], \"timestamp\":\"1785122013234\", \"event_type\":\"price_change\"}","received_at":"2026-07-27T03:13:33.138629Z","schema_version":"clob-market-ws.price_change.v1","sequence":null,"server_hash":null,"server_timestamp":"1785122013234","session_id":"ff6d21c8283948938400a32613abec2c","source":"clob_market_ws"},"received_at":"2026-07-27T03:13:33.138629Z","record_id":"98f4c9e73fe1b9a99ebf5197e88da93441d9fd40bad2a3d5cd5937415251a904","schema_fingerprint":"4aa3821a28b0b7c2400bc59aba4bcc0a76e971dadd19610d3ad38c768e124dc7","schema_version":"edge-lab-recorder.raw.v1","sequence":null,"source":"clob_market_ws"}
{"event_at":"2026-07-27T03:13:33.240000Z","event_fingerprint":"248b8b24d0cb0402fe52a3eba7dad53660d675b521f3b16a06aa70a66732428c","payload":{"connection_id":"f95883f18d264834af91809e5f803e9f","event_at":"2026-07-27T03:13:33.240000Z","event_type":"price_change","frame_hash":"bad87a87ab8489d01bfa9678d9a42bca05cdeed766d1d33dca8624f72c10804f","frame_index":0,"kind":"data","monotonic_ns":223996474826125,"payload":{"event_type":"price_change","market":"0xf9d60bb033695053c4d1d8592e52171c1042f64b41a4b72e09dcc6f4852b6670","price_changes":[{"asset_id":"8698449539441374295770236407991735029336433231649246775082939325523552031992","best_ask":"0.82","best_bid":"0.81","hash":"1378f7d1f51640ce2026b58a1c9e7502942e6df3","price":"0.01","side":"BUY","size":"8022.52"},{"asset_id":"96283536366176669581486355171583722558858323126916278856549586825357358273536","best_ask":"0.19","best_bid":"0.18","hash":"fa7a061ab5c6413ea6d854c87733d58c876868f1","price":"0.99","side":"SELL","size":"8022.52"}],"timestamp":"1785122013240"},"payload_hash":"a761721546b7d327263dde4e601158283dc3395e9e7374c34b66aeda6ba54f57","raw_frame":"{\"market\":\"0xf9d60bb033695053c4d1d8592e52171c1042f64b41a4b72e09dcc6f4852b6670\", \"price_changes\":[{\"asset_id\":\"8698449539441374295770236407991735029336433231649246775082939325523552031992\", \"price\":\"0.01\", \"size\":\"8022.52\", \"side\":\"BUY\", \"hash\":\"1378f7d1f51640ce2026b58a1c9e7502942e6df3\", \"best_bid\":\"0.81\", \"best_ask\":\"0.82\"}, {\"asset_id\":\"96283536366176669581486355171583722558858323126916278856549586825357358273536\", \"price\":\"0.99\", \"size\":\"8022.52\", \"side\":\"SELL\", \"hash\":\"fa7a061ab5c6413ea6d854c87733d58c876868f1\", \"best_bid\":\"0.18\", \"best_ask\":\"0.19\"}], \"timestamp\":\"1785122013240\", \"event_type\":\"price_change\"}","received_at":"2026-07-27T03:13:33.142378Z","schema_version":"clob-market-ws.price_change.v1","sequence":null,"server_hash":null,"server_timestamp":"1785122013240","session_id":"ff6d21c8283948938400a32613abec2c","source":"clob_market_ws"},"received_at":"2026-07-27T03:13:33.142378Z","record_id":"8f57d36d41c2b979715a27a4688fc90a4d7647d9595c19c3734517fbac604f38","schema_fingerprint":"4aa3821a28b0b7c2400bc59aba4bcc0a76e971dadd19610d3ad38c768e124dc7","schema_version":"edge-lab-recorder.raw.v1","sequence":null,"source":"clob_market_ws"}
{"event_at":"2026-07-27T03:13:33.249000Z","event_fingerprint":"2522773e9a34afa5a6dd5c32e6bf671819c0ebf8610748e44b3639fce23794b5","payload":{"connection_id":"f95883f18d264834af91809e5f803e9f","event_at":"2026-07-27T03:13:33.249000Z","event_type":"price_change","frame_hash":"d766d5d10118a92d75de6913ab9ad80b151819594ec79fd758ddbb5ca499533c","frame_index":0,"kind":"data","monotonic_ns":223996485366916,"payload":{"event_type":"price_change","market":"0xf9d60bb033695053c4d1d8592e52171c1042f64b41a4b72e09dcc6f4852b6670","price_changes":[{"asset_id":"8698449539441374295770236407991735029336433231649246775082939325523552031992","best_ask":"0.82","best_bid":"0.81","hash":"5af11c8a662be489d376e629b9b1d970c7b743c3","price":"0.81","side":"BUY","size":"93"},{"asset_id":"96283536366176669581486355171583722558858323126916278856549586825357358273536","best_ask":"0.19","best_bid":"0.18","hash":"a1ae410c8779a3c8f0100f7f162254d78fdb3822","price":"0.19","side":"SELL","size":"93"}],"timestamp":"1785122013249"},"payload_hash":"745bc45e48fac978ede6c20acca3ce7111f1c76f9ebe93e50acf8c69ae76bc07","raw_frame":"{\"market\":\"0xf9d60bb033695053c4d1d8592e52171c1042f64b41a4b72e09dcc6f4852b6670\", \"price_changes\":[{\"asset_id\":\"8698449539441374295770236407991735029336433231649246775082939325523552031992\", \"price\":\"0.81\", \"size\":\"93\", \"side\":\"BUY\", \"hash\":\"5af11c8a662be489d376e629b9b1d970c7b743c3\", \"best_bid\":\"0.81\", \"best_ask\":\"0.82\"}, {\"asset_id\":\"96283536366176669581486355171583722558858323126916278856549586825357358273536\", \"price\":\"0.19\", \"size\":\"93\", \"side\":\"SELL\", \"hash\":\"a1ae410c8779a3c8f0100f7f162254d78fdb3822\", \"best_bid\":\"0.18\", \"best_ask\":\"0.19\"}], \"timestamp\":\"1785122013249\", \"event_type\":\"price_change\"}","received_at":"2026-07-27T03:13:33.152912Z","schema_version":"clob-market-ws.price_change.v1","sequence":null,"server_hash":null,"server_timestamp":"1785122013249","session_id":"ff6d21c8283948938400a32613abec2c","source":"clob_market_ws"},"received_at":"2026-07-27T03:13:33.152912Z","record_id":"720da8e14f24d951138ecf919f6d73326c66cced5a98a601778b07f1519a3cf8","schema_fingerprint":"4aa3821a28b0b7c2400bc59aba4bcc0a76e971dadd19610d3ad38c768e124dc7","schema_version":"edge-lab-recorder.raw.v1","sequence":null,"source":"clob_market_ws"}
{"event_at":"2026-07-27T03:13:33.255000Z","event_fingerprint":"133cd3cab5e239cd4cefb8574bd65dfd4c1ebfaf59fe039c2b3198c6cfe1b12b","payload":{"connection_id":"f95883f18d264834af91809e5f803e9f","event_at":"2026-07-27T03:13:33.255000Z","event_type":"price_change","frame_hash":"66b68d18dafaa8c7b5abea89d3970188a29127fb7fd49dff10512d6e76a75f4d","frame_index":0,"kind":"data","monotonic_ns":223996494610375,"payload":{"event_type":"price_change","market":"0xf9d60bb033695053c4d1d8592e52171c1042f64b41a4b72e09dcc6f4852b6670","price_changes":[{"asset_id":"8698449539441374295770236407991735029336433231649246775082939325523552031992","best_ask":"0.82","best_bid":"0.81","hash":"b7e917cf3c8dbe44b29e663d36418b6fdb1590dd","price":"0.01","side":"BUY","size":"8027.52"},{"asset_id":"96283536366176669581486355171583722558858323126916278856549586825357358273536","best_ask":"0.19","best_bid":"0.18","hash":"7693aedd0384afeeb9d2545cb437304323cfaa1b","price":"0.99","side":"SELL","size":"8027.52"}],"timestamp":"1785122013255"},"payload_hash":"323dce3a7f5c189fdb9b434e0709737a1e0428e7e0fdf33948a52d9ee858b03c","raw_frame":"{\"market\":\"0xf9d60bb033695053c4d1d8592e52171c1042f64b41a4b72e09dcc6f4852b6670\", \"price_changes\":[{\"asset_id\":\"8698449539441374295770236407991735029336433231649246775082939325523552031992\", \"price\":\"0.01\", \"size\":\"8027.52\", \"side\":\"BUY\", \"hash\":\"b7e917cf3c8dbe44b29e663d36418b6fdb1590dd\", \"best_bid\":\"0.81\", \"best_ask\":\"0.82\"}, {\"asset_id\":\"96283536366176669581486355171583722558858323126916278856549586825357358273536\", \"price\":\"0.99\", \"size\":\"8027.52\", \"side\":\"SELL\", \"hash\":\"7693aedd0384afeeb9d2545cb437304323cfaa1b\", \"best_bid\":\"0.18\", \"best_ask\":\"0.19\"}], \"timestamp\":\"1785122013255\", \"event_type\":\"price_change\"}","received_at":"2026-07-27T03:13:33.162159Z","schema_version":"clob-market-ws.price_change.v1","sequence":null,"server_hash":null,"server_timestamp":"1785122013255","session_id":"ff6d21c8283948938400a32613abec2c","source":"clob_market_ws"},"received_at":"2026-07-27T03:13:33.162159Z","record_id":"799e44a1012f0e77326ebc4d1ee0592bec5830864d5db32fad6dac9253d40ef4","schema_fingerprint":"4aa3821a28b0b7c2400bc59aba4bcc0a76e971dadd19610d3ad38c768e124dc7","schema_version":"edge-lab-recorder.raw.v1","sequence":null,"source":"clob_market_ws"}
{"event_at":"2026-07-27T03:13:33.261000Z","event_fingerprint":"d8e832ce8909b140be3a6786f32acb23edb639b7c182aa055d7fb3ab73751211","payload":{"connection_id":"f95883f18d264834af91809e5f803e9f","event_at":"2026-07-27T03:13:33.261000Z","event_type":"price_change","frame_hash":"644a61de7dbddab310ec688384f7ce4676800cab964f3e663fd863fce8ad4f4c","frame_index":0,"kind":"data","monotonic_ns":223996496259583,"payload":{"event_type":"price_change","market":"0xf9d60bb033695053c4d1d8592e52171c1042f64b41a4b72e09dcc6f4852b6670","price_changes":[{"asset_id":"8698449539441374295770236407991735029336433231649246775082939325523552031992","best_ask":"0.82","best_bid":"0.81","hash":"77aaea15fdfe77ce18f89ba577eb81ddfc63c85f","price":"0.79","side":"BUY","size":"154.5"},{"asset_id":"96283536366176669581486355171583722558858323126916278856549586825357358273536","best_ask":"0.19","best_bid":"0.18","hash":"d872bdb0e14948c80bf39170e5ce0305b1def31a","price":"0.21","side":"SELL","size":"154.5"}],"timestamp":"1785122013261"},"payload_hash":"d16bb41edc0e8334dd630b221a7896b3458f18d82bb2cc3d49b1b9b44f24e0ec","raw_frame":"{\"market\":\"0xf9d60bb033695053c4d1d8592e52171c1042f64b41a4b72e09dcc6f4852b6670\", \"price_changes\":[{\"asset_id\":\"8698449539441374295770236407991735029336433231649246775082939325523552031992\", \"price\":\"0.79\", \"size\":\"154.5\", \"side\":\"BUY\", \"hash\":\"77aaea15fdfe77ce18f89ba577eb81ddfc63c85f\", \"best_bid\":\"0.81\", \"best_ask\":\"0.82\"}, {\"asset_id\":\"96283536366176669581486355171583722558858323126916278856549586825357358273536\", \"price\":\"0.21\", \"size\":\"154.5\", \"side\":\"SELL\", \"hash\":\"d872bdb0e14948c80bf39170e5ce0305b1def31a\", \"best_bid\":\"0.18\", \"best_ask\":\"0.19\"}], \"timestamp\":\"1785122013261\", \"event_type\":\"price_change\"}","received_at":"2026-07-27T03:13:33.163810Z","schema_version":"clob-market-ws.price_change.v1","sequence":null,"server_hash":null,"server_timestamp":"1785122013261","session_id":"ff6d21c8283948938400a32613abec2c","source":"clob_market_ws"},"received_at":"2026-07-27T03:13:33.163810Z","record_id":"3a49f4a785e8277a1cceb57dcac5d4330914dd7fadf3289bd1e6d353feebe0de","schema_fingerprint":"4aa3821a28b0b7c2400bc59aba4bcc0a76e971dadd19610d3ad38c768e124dc7","schema_version":"edge-lab-recorder.raw.v1","sequence":null,"source":"clob_market_ws"}
