{"event_at":"2026-07-27T03:10:45.957000Z","event_fingerprint":"27209eadc2a18e63f193573e723655908007d0dd6d5441ec4bdbdc67d60b5d84","payload":{"connection_id":"f95883f18d264834af91809e5f803e9f","event_at":"2026-07-27T03:10:45.957000Z","event_type":"price_change","frame_hash":"b8ec0e24bdeef1b892a647899aa0338ecd7dfeb1013271ae75853cf768bdb43f","frame_index":0,"kind":"data","monotonic_ns":223829243535625,"payload":{"event_type":"price_change","market":"0xf9d60bb033695053c4d1d8592e52171c1042f64b41a4b72e09dcc6f4852b6670","price_changes":[{"asset_id":"96283536366176669581486355171583722558858323126916278856549586825357358273536","best_ask":"0.79","best_bid":"0.78","hash":"8973cccc5fa2bc400735d0b89b1d4db9adddc45e","price":"0.78","side":"BUY","size":"127.1"},{"asset_id":"8698449539441374295770236407991735029336433231649246775082939325523552031992","best_ask":"0.22","best_bid":"0.21","hash":"4884aa6e9f7de2a859d144c89e98469e1c94eb8b","price":"0.22","side":"SELL","size":"127.1"}],"timestamp":"1785121845957"},"payload_hash":"33402a4795030edc6da8e91b47851440065d5ffabcedd619f2d77eb054696b73","raw_frame":"{\"market\":\"0xf9d60bb033695053c4d1d8592e52171c1042f64b41a4b72e09dcc6f4852b6670\", \"price_changes\":[{\"asset_id\":\"96283536366176669581486355171583722558858323126916278856549586825357358273536\", \"price\":\"0.78\", \"size\":\"127.1\", \"side\":\"BUY\", \"hash\":\"8973cccc5fa2bc400735d0b89b1d4db9adddc45e\", \"best_bid\":\"0.78\", \"best_ask\":\"0.79\"}, {\"asset_id\":\"8698449539441374295770236407991735029336433231649246775082939325523552031992\", \"price\":\"0.22\", \"size\":\"127.1\", \"side\":\"SELL\", \"hash\":\"4884aa6e9f7de2a859d144c89e98469e1c94eb8b\", \"best_bid\":\"0.21\", \"best_ask\":\"0.22\"}], \"timestamp\":\"1785121845957\", \"event_type\":\"price_change\"}","received_at":"2026-07-27T03:10:45.913432Z","schema_version":"clob-market-ws.price_change.v1","sequence":null,"server_hash":null,"server_timestamp":"1785121845957","session_id":"ff6d21c8283948938400a32613abec2c","source":"clob_market_ws"},"received_at":"2026-07-27T03:10:45.913432Z","record_id":"55dbc080caeff201ad488a0dd226f1006481e2e1c6b4c21e2b77498446ced5f9","schema_fingerprint":"4aa3821a28b0b7c2400bc59aba4bcc0a76e971dadd19610d3ad38c768e124dc7","schema_version":"edge-lab-recorder.raw.v1","sequence":null,"source":"clob_market_ws"}
{"event_at":"2026-07-27T03:10:45.962000Z","event_fingerprint":"cb7821f338004c18b5404a0b648e78ecc580d2a4fa6f03d91110d0570834abb9","payload":{"connection_id":"f95883f18d264834af91809e5f803e9f","event_at":"2026-07-27T03:10:45.962000Z","event_type":"price_change","frame_hash":"94692c79d79fcaf2f9a35ed00f5c04dc564b85c8a6179385c2be32f5dd9df211","frame_index":0,"kind":"data","monotonic_ns":223829250796333,"payload":{"event_type":"price_change","market":"0xf9d60bb033695053c4d1d8592e52171c1042f64b41a4b72e09dcc6f4852b6670","price_changes":[{"asset_id":"96283536366176669581486355171583722558858323126916278856549586825357358273536","best_ask":"0.79","best_bid":"0.78","hash":"ebf29283c17ec2281677ce337e488a4116409233","price":"0.66","side":"BUY","size":"156.29"},{"asset_id":"8698449539441374295770236407991735029336433231649246775082939325523552031992","best_ask":"0.22","best_bid":"0.21","hash":"8c3b93b44680b7931ca8ce9f2673ec629ff9a414","price":"0.34","side":"SELL","size":"156.29"}],"timestamp":"1785121845962"},"payload_hash":"b174f755fde67bad8e8131e74ee62cb5a532f0316670fe4a4a5581c3648cdb7c","raw_frame":"{\"market\":\"0xf9d60bb033695053c4d1d8592e52171c1042f64b41a4b72e09dcc6f4852b6670\", \"price_changes\":[{\"asset_id\":\"96283536366176669581486355171583722558858323126916278856549586825357358273536\", \"price\":\"0.66\", \"size\":\"156.29\", \"side\":\"BUY\", \"hash\":\"ebf29283c17ec2281677ce337e488a4116409233\", \"best_bid\":\"0.78\", \"best_ask\":\"0.79\"}, {\"asset_id\":\"8698449539441374295770236407991735029336433231649246775082939325523552031992\", \"price\":\"0.34\", \"size\":\"156.29\", \"side\":\"SELL\", \"hash\":\"8c3b93b44680b7931ca8ce9f2673ec629ff9a414\", \"best_bid\":\"0.21\", \"best_ask\":\"0.22\"}], \"timestamp\":\"1785121845962\", \"event_type\":\"price_change\"}","received_at":"2026-07-27T03:10:45.920693Z","schema_version":"clob-market-ws.price_change.v1","sequence":null,"server_hash":null,"server_timestamp":"1785121845962","session_id":"ff6d21c8283948938400a32613abec2c","source":"clob_market_ws"},"received_at":"2026-07-27T03:10:45.920693Z","record_id":"8a21b33b88f31563225a931eb0d9065e3f2a195c20e05b082d690bc8aeff9d6f","schema_fingerprint":"4aa3821a28b0b7c2400bc59aba4bcc0a76e971dadd19610d3ad38c768e124dc7","schema_version":"edge-lab-recorder.raw.v1","sequence":null,"source":"clob_market_ws"}
{"event_at":"2026-07-27T03:10:45.975000Z","event_fingerprint":"bfc7d773c65f1c51d47065c5d30042698ff3bd5abe228cf350acacdaba9327ae","payload":{"connection_id":"f95883f18d264834af91809e5f803e9f","event_at":"2026-07-27T03:10:45.975000Z","event_type":"price_change","frame_hash":"dce4313284e29cd74f400eeb94513474666a7761793c175b8affc394c64ca390","frame_index":0,"kind":"data","monotonic_ns":223829253785375,"payload":{"event_type":"price_change","market":"0xf9d60bb033695053c4d1d8592e52171c1042f64b41a4b72e09dcc6f4852b6670","price_changes":[{"asset_id":"96283536366176669581486355171583722558858323126916278856549586825357358273536","best_ask":"0.79","best_bid":"0.78","hash":"c1dcf4497be60b419360f075cd0b82c67511be1c","price":"0.78","side":"BUY","size":"132.1"},{"asset_id":"8698449539441374295770236407991735029336433231649246775082939325523552031992","best_ask":"0.22","best_bid":"0.21","hash":"99246c54da261f161cb9ce0ec53e968ed13ebd91","price":"0.22","side":"SELL","size":"132.1"}],"timestamp":"1785121845975"},"payload_hash":"6324d722b14d6e6005bafa70acd31573fb1035abcb26fb7c821cfb5a47502191","raw_frame":"{\"market\":\"0xf9d60bb033695053c4d1d8592e52171c1042f64b41a4b72e09dcc6f4852b6670\", \"price_changes\":[{\"asset_id\":\"96283536366176669581486355171583722558858323126916278856549586825357358273536\", \"price\":\"0.78\", \"size\":\"132.1\", \"side\":\"BUY\", \"hash\":\"c1dcf4497be60b419360f075cd0b82c67511be1c\", \"best_bid\":\"0.78\", \"best_ask\":\"0.79\"}, {\"asset_id\":\"8698449539441374295770236407991735029336433231649246775082939325523552031992\", \"price\":\"0.22\", \"size\":\"132.1\", \"side\":\"SELL\", \"hash\":\"99246c54da261f161cb9ce0ec53e968ed13ebd91\", \"best_bid\":\"0.21\", \"best_ask\":\"0.22\"}], \"timestamp\":\"1785121845975\", \"event_type\":\"price_change\"}","received_at":"2026-07-27T03:10:45.923682Z","schema_version":"clob-market-ws.price_change.v1","sequence":null,"server_hash":null,"server_timestamp":"1785121845975","session_id":"ff6d21c8283948938400a32613abec2c","source":"clob_market_ws"},"received_at":"2026-07-27T03:10:45.923682Z","record_id":"0ddbbd874de4ea652156df3059076e5024c132758db24def36a8d3fd6d1a63d7","schema_fingerprint":"4aa3821a28b0b7c2400bc59aba4bcc0a76e971dadd19610d3ad38c768e124dc7","schema_version":"edge-lab-recorder.raw.v1","sequence":null,"source":"clob_market_ws"}
{"event_at":"2026-07-27T03:10:45.983000Z","event_fingerprint":"f325c73184b2b232109eb25c976f74893879f7bbd0c2b79ce6b727a1f8999557","payload":{"connection_id":"f95883f18d264834af91809e5f803e9f","event_at":"2026-07-27T03:10:45.983000Z","event_type":"price_change","frame_hash":"53c5d30ed296e4b82548eb379598e37c7dbc52e86f21521546e7081275b065b7","frame_index":0,"kind":"data","monotonic_ns":223829256939208,"payload":{"event_type":"price_change","market":"0xf9d60bb033695053c4d1d8592e52171c1042f64b41a4b72e09dcc6f4852b6670","price_changes":[{"asset_id":"96283536366176669581486355171583722558858323126916278856549586825357358273536","best_ask":"0.79","best_bid":"0.78","hash":"60445ccc36c8bfecb351a701335ec47ec6b8e233","price":"0.77","side":"BUY","size":"100.1"},{"asset_id":"8698449539441374295770236407991735029336433231649246775082939325523552031992","best_ask":"0.22","best_bid":"0.21","hash":"6b49332b9673ea77695e20110645a535c5190ecb","price":"0.23","side":"SELL","size":"100.1"}],"timestamp":"1785121845983"},"payload_hash":"dbf7528997983e078b32248605085b7b5eba5be04b8e4c4f5dd7626fce6c3905","raw_frame":"{\"market\":\"0xf9d60bb033695053c4d1d8592e52171c1042f64b41a4b72e09dcc6f4852b6670\", \"price_changes\":[{\"asset_id\":\"96283536366176669581486355171583722558858323126916278856549586825357358273536\", \"price\":\"0.77\", \"size\":\"100.1\", \"side\":\"BUY\", \"hash\":\"60445ccc36c8bfecb351a701335ec47ec6b8e233\", \"best_bid\":\"0.78\", \"best_ask\":\"0.79\"}, {\"asset_id\":\"8698449539441374295770236407991735029336433231649246775082939325523552031992\", \"price\":\"0.23\", \"size\":\"100.1\", \"side\":\"SELL\", \"hash\":\"6b49332b9673ea77695e20110645a535c5190ecb\", \"best_bid\":\"0.21\", \"best_ask\":\"0.22\"}], \"timestamp\":\"1785121845983\", \"event_type\":\"price_change\"}","received_at":"2026-07-27T03:10:45.926835Z","schema_version":"clob-market-ws.price_change.v1","sequence":null,"server_hash":null,"server_timestamp":"1785121845983","session_id":"ff6d21c8283948938400a32613abec2c","source":"clob_market_ws"},"received_at":"2026-07-27T03:10:45.926835Z","record_id":"43a7972b8edfeaea11beb8baa49dbf84ca2b7e076b30d58b9a2fbf72224c54b9","schema_fingerprint":"4aa3821a28b0b7c2400bc59aba4bcc0a76e971dadd19610d3ad38c768e124dc7","schema_version":"edge-lab-recorder.raw.v1","sequence":null,"source":"clob_market_ws"}
{"event_at":"2026-07-27T03:10:45.985000Z","event_fingerprint":"78054e56d01db008fdaa555e3feb42c49492cf2fff9ff9496ef72254d3ed76d5","payload":{"connection_id":"f95883f18d264834af91809e5f803e9f","event_at":"2026-07-27T03:10:45.985000Z","event_type":"price_change","frame_hash":"616e5f73a8114d147c2fa09de5c8f9f309d5e9dccfeb07685a14bc15f75ebfad","frame_index":0,"kind":"data","monotonic_ns":223829260633708,"payload":{"event_type":"price_change","market":"0xf9d60bb033695053c4d1d8592e52171c1042f64b41a4b72e09dcc6f4852b6670","price_changes":[{"asset_id":"96283536366176669581486355171583722558858323126916278856549586825357358273536","best_ask":"0.79","best_bid":"0.78","hash":"3df5972783d3845538670dbcce5f40c3134bb8b0","price":"0.01","side":"BUY","size":"6919.52"},{"asset_id":"8698449539441374295770236407991735029336433231649246775082939325523552031992","best_ask":"0.22","best_bid":"0.21","hash":"50658fdf959371b3944f12b75435368fa06a0fa5","price":"0.99","side":"SELL","size":"6919.52"}],"timestamp":"1785121845985"},"payload_hash":"41451466b67484b44ff14934e531bf79912a17b712056264de864ae0ff704a39","raw_frame":"{\"market\":\"0xf9d60bb033695053c4d1d8592e52171c1042f64b41a4b72e09dcc6f4852b6670\", \"price_changes\":[{\"asset_id\":\"96283536366176669581486355171583722558858323126916278856549586825357358273536\", \"price\":\"0.01\", \"size\":\"6919.52\", \"side\":\"BUY\", \"hash\":\"3df5972783d3845538670dbcce5f40c3134bb8b0\", \"best_bid\":\"0.78\", \"best_ask\":\"0.79\"}, {\"asset_id\":\"8698449539441374295770236407991735029336433231649246775082939325523552031992\", \"price\":\"0.99\", \"size\":\"6919.52\", \"side\":\"SELL\", \"hash\":\"50658fdf959371b3944f12b75435368fa06a0fa5\", \"best_bid\":\"0.21\", \"best_ask\":\"0.22\"}], \"timestamp\":\"1785121845985\", \"event_type\":\"price_change\"}","received_at":"2026-07-27T03:10:45.930531Z","schema_version":"clob-market-ws.price_change.v1","sequence":null,"server_hash":null,"server_timestamp":"1785121845985","session_id":"ff6d21c8283948938400a32613abec2c","source":"clob_market_ws"},"received_at":"2026-07-27T03:10:45.930531Z","record_id":"d3e2d84f310197c14503383522671458982376d191dbcbcca415046da3d436c0","schema_fingerprint":"4aa3821a28b0b7c2400bc59aba4bcc0a76e971dadd19610d3ad38c768e124dc7","schema_version":"edge-lab-recorder.raw.v1","sequence":null,"source":"clob_market_ws"}
{"event_at":"2026-07-27T03:10:46.011000Z","event_fingerprint":"6077a5862875aa88930e0977ab1b8827da31c4014d7beee2069eb95afcca49e9","payload":{"connection_id":"f95883f18d264834af91809e5f803e9f","event_at":"2026-07-27T03:10:46.011000Z","event_type":"price_change","frame_hash":"cd61ce903d82533d71ef8178c6c9ffe769fe26c74c9c55800a4792a35212cfe1","frame_index":0,"kind":"data","monotonic_ns":223829264216916,"payload":{"event_type":"price_change","market":"0xf9d60bb033695053c4d1d8592e52171c1042f64b41a4b72e09dcc6f4852b6670","price_changes":[{"asset_id":"96283536366176669581486355171583722558858323126916278856549586825357358273536","best_ask":"0.79","best_bid":"0.78","hash":"574af150aae27ac3c034d11238318905c76988d3","price":"0.77","side":"BUY","size":"105.1"},{"asset_id":"8698449539441374295770236407991735029336433231649246775082939325523552031992","best_ask":"0.22","best_bid":"0.21","hash":"8064db40a3c47ffdf2d12515cbc2cea8a75bf46e","price":"0.23","side":"SELL","size":"105.1"}],"timestamp":"1785121846011"},"payload_hash":"b48e93c2dbbbc5e805f3e288992824066c789a6ae8b4a8cff28f81d83ccb60da","raw_frame":"{\"market\":\"0xf9d60bb033695053c4d1d8592e52171c1042f64b41a4b72e09dcc6f4852b6670\", \"price_changes\":[{\"asset_id\":\"96283536366176669581486355171583722558858323126916278856549586825357358273536\", \"price\":\"0.77\", \"size\":\"105.1\", \"side\":\"BUY\", \"hash\":\"574af150aae27ac3c034d11238318905c76988d3\", \"best_bid\":\"0.78\", \"best_ask\":\"0.79\"}, {\"asset_id\":\"8698449539441374295770236407991735029336433231649246775082939325523552031992\", \"price\":\"0.23\", \"size\":\"105.1\", \"side\":\"SELL\", \"hash\":\"8064db40a3c47ffdf2d12515cbc2cea8a75bf46e\", \"best_bid\":\"0.21\", \"best_ask\":\"0.22\"}], \"timestamp\":\"1785121846011\", \"event_type\":\"price_change\"}","received_at":"2026-07-27T03:10:45.934111Z","schema_version":"clob-market-ws.price_change.v1","sequence":null,"server_hash":null,"server_timestamp":"1785121846011","session_id":"ff6d21c8283948938400a32613abec2c","source":"clob_market_ws"},"received_at":"2026-07-27T03:10:45.934111Z","record_id":"eff93c9eb97bde254aa3c81cef5ec69018360d5ee39b465f6b8fb734a0a37bd0","schema_fingerprint":"4aa3821a28b0b7c2400bc59aba4bcc0a76e971dadd19610d3ad38c768e124dc7","schema_version":"edge-lab-recorder.raw.v1","sequence":null,"source":"clob_market_ws"}
{"event_at":"2026-07-27T03:10:46.012000Z","event_fingerprint":"81badbdff4b4449ae107a19854f9a9cc9478eab9e98cf6b7d607c1e4c4e456bd","payload":{"connection_id":"f95883f18d264834af91809e5f803e9f","event_at":"2026-07-27T03:10:46.012000Z","event_type":"price_change","frame_hash":"741ed20b53f521c7231f3eb2ab6906b263a11d718160724d36624b15a641f1ee","frame_index":0,"kind":"data","monotonic_ns":223829267402916,"payload":{"event_type":"price_change","market":"0xf9d60bb033695053c4d1d8592e52171c1042f64b41a4b72e09dcc6f4852b6670","price_changes":[{"asset_id":"96283536366176669581486355171583722558858323126916278856549586825357358273536","best_ask":"0.79","best_bid":"0.78","hash":"c480eceae9829a2b269b19c99286015555913da6","price":"0.77","side":"BUY","size":"110.1"},{"asset_id":"8698449539441374295770236407991735029336433231649246775082939325523552031992","best_ask":"0.22","best_bid":"0.21","hash":"69d93b16b575f068e0d171d95df868c8312b14b3","price":"0.23","side":"SELL","size":"110.1"}],"timestamp":"1785121846012"},"payload_hash":"52130f333542ea9727a7c0c3b469f7b6da89b478a40d70b6c0f17b813f90bc2d","raw_frame":"{\"market\":\"0xf9d60bb033695053c4d1d8592e52171c1042f64b41a4b72e09dcc6f4852b6670\", \"price_changes\":[{\"asset_id\":\"96283536366176669581486355171583722558858323126916278856549586825357358273536\", \"price\":\"0.77\", \"size\":\"110.1\", \"side\":\"BUY\", \"hash\":\"c480eceae9829a2b269b19c99286015555913da6\", \"best_bid\":\"0.78\", \"best_ask\":\"0.79\"}, {\"asset_id\":\"8698449539441374295770236407991735029336433231649246775082939325523552031992\", \"price\":\"0.23\", \"size\":\"110.1\", \"side\":\"SELL\", \"hash\":\"69d93b16b575f068e0d171d95df868c8312b14b3\", \"best_bid\":\"0.21\", \"best_ask\":\"0.22\"}], \"timestamp\":\"1785121846012\", \"event_type\":\"price_change\"}","received_at":"2026-07-27T03:10:45.937299Z","schema_version":"clob-market-ws.price_change.v1","sequence":null,"server_hash":null,"server_timestamp":"1785121846012","session_id":"ff6d21c8283948938400a32613abec2c","source":"clob_market_ws"},"received_at":"2026-07-27T03:10:45.937299Z","record_id":"9dd8b8315d3dd3565cbeb3a93b8149de34be89df5056c41e365c835eaf685ccb","schema_fingerprint":"4aa3821a28b0b7c2400bc59aba4bcc0a76e971dadd19610d3ad38c768e124dc7","schema_version":"edge-lab-recorder.raw.v1","sequence":null,"source":"clob_market_ws"}
{"event_at":"2026-07-27T03:10:46.013000Z","event_fingerprint":"1361bbb7aa4b806bf501a3f3a82449c59738d843ce9fb3cf191393754658c4fc","payload":{"connection_id":"f95883f18d264834af91809e5f803e9f","event_at":"2026-07-27T03:10:46.013000Z","event_type":"price_change","frame_hash":"19616c42c9041160253bcbda48126d2e92578ece0f22909d7a0ff4fd7975a8ee","frame_index":0,"kind":"data","monotonic_ns":223829270466375,"payload":{"event_type":"price_change","market":"0xf9d60bb033695053c4d1d8592e52171c1042f64b41a4b72e09dcc6f4852b6670","price_changes":[{"asset_id":"96283536366176669581486355171583722558858323126916278856549586825357358273536","best_ask":"0.79","best_bid":"0.78","hash":"eedc03bd972e6cee9107873b185af69fa0f7c4ea","price":"0.77","side":"BUY","size":"115.1"},{"asset_id":"8698449539441374295770236407991735029336433231649246775082939325523552031992","best_ask":"0.22","best_bid":"0.21","hash":"ac50f04b78aab5c11df2a3e68ba686c3ceac1e16","price":"0.23","side":"SELL","size":"115.1"}],"timestamp":"1785121846013"},"payload_hash":"447f4822090136390531cd1af100116f3f92339acd35576c861d42a4a0d5be3c","raw_frame":"{\"market\":\"0xf9d60bb033695053c4d1d8592e52171c1042f64b41a4b72e09dcc6f4852b6670\", \"price_changes\":[{\"asset_id\":\"96283536366176669581486355171583722558858323126916278856549586825357358273536\", \"price\":\"0.77\", \"size\":\"115.1\", \"side\":\"BUY\", \"hash\":\"eedc03bd972e6cee9107873b185af69fa0f7c4ea\", \"best_bid\":\"0.78\", \"best_ask\":\"0.79\"}, {\"asset_id\":\"8698449539441374295770236407991735029336433231649246775082939325523552031992\", \"price\":\"0.23\", \"size\":\"115.1\", \"side\":\"SELL\", \"hash\":\"ac50f04b78aab5c11df2a3e68ba686c3ceac1e16\", \"best_bid\":\"0.21\", \"best_ask\":\"0.22\"}], \"timestamp\":\"1785121846013\", \"event_type\":\"price_change\"}","received_at":"2026-07-27T03:10:45.940363Z","schema_version":"clob-market-ws.price_change.v1","sequence":null,"server_hash":null,"server_timestamp":"1785121846013","session_id":"ff6d21c8283948938400a32613abec2c","source":"clob_market_ws"},"received_at":"2026-07-27T03:10:45.940363Z","record_id":"ed15600b9ceb7eba4f57e1bbaf79095d3f122116ad6d706ad88f2e994044b1e8","schema_fingerprint":"4aa3821a28b0b7c2400bc59aba4bcc0a76e971dadd19610d3ad38c768e124dc7","schema_version":"edge-lab-recorder.raw.v1","sequence":null,"source":"clob_market_ws"}
{"event_at":"2026-07-27T03:10:46.014000Z","event_fingerprint":"4ecf6d92550e801dd8361b12e769e51bd122775e3c45e3c7b0e91e08e20b325d","payload":{"connection_id":"f95883f18d264834af91809e5f803e9f","event_at":"2026-07-27T03:10:46.014000Z","event_type":"price_change","frame_hash":"f6c98501a21db10d7c1c9410f5f6341337334c384650bb0bcfa65bd8eb9fb565","frame_index":0,"kind":"data","monotonic_ns":223829273438500,"payload":{"event_type":"price_change","market":"0xf9d60bb033695053c4d1d8592e52171c1042f64b41a4b72e09dcc6f4852b6670","price_changes":[{"asset_id":"96283536366176669581486355171583722558858323126916278856549586825357358273536","best_ask":"0.79","best_bid":"0.78","hash":"29baee6292519b747c9fce1b695041f171ba1283","price":"0.66","side":"BUY","size":"151.29"},{"asset_id":"8698449539441374295770236407991735029336433231649246775082939325523552031992","best_ask":"0.22","best_bid":"0.21","hash":"168e948715e596202e9dcf3c7575046defb8491f","price":"0.34","side":"SELL","size":"151.29"}],"timestamp":"1785121846014"},"payload_hash":"fef8dfe8edae332ff0e62daed32208090301b43f1bf64a800a6cc40881dfb529","raw_frame":"{\"market\":\"0xf9d60bb033695053c4d1d8592e52171c1042f64b41a4b72e09dcc6f4852b6670\", \"price_changes\":[{\"asset_id\":\"96283536366176669581486355171583722558858323126916278856549586825357358273536\", \"price\":\"0.66\", \"size\":\"151.29\", \"side\":\"BUY\", \"hash\":\"29baee6292519b747c9fce1b695041f171ba1283\", \"best_bid\":\"0.78\", \"best_ask\":\"0.79\"}, {\"asset_id\":\"8698449539441374295770236407991735029336433231649246775082939325523552031992\", \"price\":\"0.34\", \"size\":\"151.29\", \"side\":\"SELL\", \"hash\":\"168e948715e596202e9dcf3c7575046defb8491f\", \"best_bid\":\"0.21\", \"best_ask\":\"0.22\"}], \"timestamp\":\"1785121846014\", \"event_type\":\"price_change\"}","received_at":"2026-07-27T03:10:45.943334Z","schema_version":"clob-market-ws.price_change.v1","sequence":null,"server_hash":null,"server_timestamp":"1785121846014","session_id":"ff6d21c8283948938400a32613abec2c","source":"clob_market_ws"},"received_at":"2026-07-27T03:10:45.943334Z","record_id":"47acefa4de8e0472b3e16476e94836615346f70778add5083d65e062763a8e60","schema_fingerprint":"4aa3821a28b0b7c2400bc59aba4bcc0a76e971dadd19610d3ad38c768e124dc7","schema_version":"edge-lab-recorder.raw.v1","sequence":null,"source":"clob_market_ws"}
{"event_at":"2026-07-27T03:10:46.022000Z","event_fingerprint":"d8a1f13d851ab6c94fd2f3c8eb2391c00e9617adfae4d660f8c2a6bed1b4fc95","payload":{"connection_id":"f95883f18d264834af91809e5f803e9f","event_at":"2026-07-27T03:10:46.022000Z","event_type":"price_change","frame_hash":"dd340e9063e8e41d42ecf8c355f1fda26d1b978a409e11e2ba70fd363ee28eaf","frame_index":0,"kind":"data","monotonic_ns":223829276575416,"payload":{"event_type":"price_change","market":"0xf9d60bb033695053c4d1d8592e52171c1042f64b41a4b72e09dcc6f4852b6670","price_changes":[{"asset_id":"8698449539441374295770236407991735029336433231649246775082939325523552031992","best_ask":"0.22","best_bid":"0.21","hash":"634585b5ba734b0ab5a3041d109c98273873aedc","price":"0.25","side":"SELL","size":"110.57"},{"asset_id":"96283536366176669581486355171583722558858323126916278856549586825357358273536","best_ask":"0.79","best_bid":"0.78","hash":"513a585cb9f663a950381e93facd4d766599c3fe","price":"0.75","side":"BUY","size":"110.57"}],"timestamp":"1785121846022"},"payload_hash":"7ebfad79eedd4be7bbc950531962f72b025a5a85240f066f1e1b224fb53139b1","raw_frame":"{\"market\":\"0xf9d60bb033695053c4d1d8592e52171c1042f64b41a4b72e09dcc6f4852b6670\", \"price_changes\":[{\"asset_id\":\"8698449539441374295770236407991735029336433231649246775082939325523552031992\", \"price\":\"0.25\", \"size\":\"110.57\", \"side\":\"SELL\", \"hash\":\"634585b5ba734b0ab5a3041d109c98273873aedc\", \"best_bid\":\"0.21\", \"best_ask\":\"0.22\"}, {\"asset_id\":\"96283536366176669581486355171583722558858323126916278856549586825357358273536\", \"price\":\"0.75\", \"size\":\"110.57\", \"side\":\"BUY\", \"hash\":\"513a585cb9f663a950381e93facd4d766599c3fe\", \"best_bid\":\"0.78\", \"best_ask\":\"0.79\"}], \"timestamp\":\"1785121846022\", \"event_type\":\"price_change\"}","received_at":"2026-07-27T03:10:45.946471Z","schema_version":"clob-market-ws.price_change.v1","sequence":null,"server_hash":null,"server_timestamp":"1785121846022","session_id":"ff6d21c8283948938400a32613abec2c","source":"clob_market_ws"},"received_at":"2026-07-27T03:10:45.946471Z","record_id":"c35f22cb9c7d6b123ad1b150a145d53e1e709669389f73454b7cb7a69e43bef1","schema_fingerprint":"4aa3821a28b0b7c2400bc59aba4bcc0a76e971dadd19610d3ad38c768e124dc7","schema_version":"edge-lab-recorder.raw.v1","sequence":null,"source":"clob_market_ws"}
{"event_at":"2026-07-27T03:10:46.022000Z","event_fingerprint":"9b03e8e1849ed839018192c24f3c7e494d4d3a72846939d6451b16403712e989","payload":{"connection_id":"f95883f18d264834af91809e5f803e9f","event_at":"2026-07-27T03:10:46.022000Z","event_type":"price_change","frame_hash":"108bacdc7e9024226ec81e9bbfb190a4d5373c54f8826b228ccd02af97887435","frame_index":0,"kind":"data","monotonic_ns":223829279546375,"payload":{"event_type":"price_change","market":"0xf9d60bb033695053c4d1d8592e52171c1042f64b41a4b72e09dcc6f4852b6670","price_changes":[{"asset_id":"8698449539441374295770236407991735029336433231649246775082939325523552031992","best_ask":"0.22","best_bid":"0.21","hash":"286e147d4e9a76e844bee97951bad16cfa05102e","price":"0.01","side":"BUY","size":"6839.52"},{"asset_id":"96283536366176669581486355171583722558858323126916278856549586825357358273536","best_ask":"0.79","best_bid":"0.78","hash":"e204522f7722e12d67b4ac744f7cd2bb8437e9b3","price":"0.99","side":"SELL","size":"6839.52"}],"timestamp":"1785121846022"},"payload_hash":"6b1083f4e719b48e2615f79303488cb41fda8c21332d49d0b87789d65137a374","raw_frame":"{\"market\":\"0xf9d60bb033695053c4d1d8592e52171c1042f64b41a4b72e09dcc6f4852b6670\", \"price_changes\":[{\"asset_id\":\"8698449539441374295770236407991735029336433231649246775082939325523552031992\", \"price\":\"0.01\", \"size\":\"6839.52\", \"side\":\"BUY\", \"hash\":\"286e147d4e9a76e844bee97951bad16cfa05102e\", \"best_bid\":\"0.21\", \"best_ask\":\"0.22\"}, {\"asset_id\":\"96283536366176669581486355171583722558858323126916278856549586825357358273536\", \"price\":\"0.99\", \"size\":\"6839.52\", \"side\":\"SELL\", \"hash\":\"e204522f7722e12d67b4ac744f7cd2bb8437e9b3\", \"best_bid\":\"0.78\", \"best_ask\":\"0.79\"}], \"timestamp\":\"1785121846022\", \"event_type\":\"price_change\"}","received_at":"2026-07-27T03:10:45.949442Z","schema_version":"clob-market-ws.price_change.v1","sequence":null,"server_hash":null,"server_timestamp":"1785121846022","session_id":"ff6d21c8283948938400a32613abec2c","source":"clob_market_ws"},"received_at":"2026-07-27T03:10:45.949442Z","record_id":"6401b00028106511d535186cdd975859a8b2db4282543c195fad7930eba98336","schema_fingerprint":"4aa3821a28b0b7c2400bc59aba4bcc0a76e971dadd19610d3ad38c768e124dc7","schema_version":"edge-lab-recorder.raw.v1","sequence":null,"source":"clob_market_ws"}
{"event_at":"2026-07-27T03:10:46.023000Z","event_fingerprint":"08c448db25888652f4f6e52e626fe7f48d2b6a5ad344941756d4f1eb26c0868e","payload":{"connection_id":"f95883f18d264834af91809e5f803e9f","event_at":"2026-07-27T03:10:46.023000Z","event_type":"price_change","frame_hash":"0419a7702cc47af19c4dbc058dd6bba97970df18840313e2a9f98f572b6e67c6","frame_index":0,"kind":"data","monotonic_ns":223829282576583,"payload":{"event_type":"price_change","market":"0xf9d60bb033695053c4d1d8592e52171c1042f64b41a4b72e09dcc6f4852b6670","price_changes":[{"asset_id":"8698449539441374295770236407991735029336433231649246775082939325523552031992","best_ask":"0.22","best_bid":"0.21","hash":"04c22c6573423f1b7cededc4507cabc85407c453","price":"0.01","side":"BUY","size":"6844.52"},{"asset_id":"96283536366176669581486355171583722558858323126916278856549586825357358273536","best_ask":"0.79","best_bid":"0.78","hash":"650325eb3d06e90691433aeff1cb7732ea79c3ef","price":"0.99","side":"SELL","size":"6844.52"}],"timestamp":"1785121846023"},"payload_hash":"9b48fb24a88de3dbc800c9b5b8b8e10521c6be9c3906d086a7c5975f2eab86c2","raw_frame":"{\"market\":\"0xf9d60bb033695053c4d1d8592e52171c1042f64b41a4b72e09dcc6f4852b6670\", \"price_changes\":[{\"asset_id\":\"8698449539441374295770236407991735029336433231649246775082939325523552031992\", \"price\":\"0.01\", \"size\":\"6844.52\", \"side\":\"BUY\", \"hash\":\"04c22c6573423f1b7cededc4507cabc85407c453\", \"best_bid\":\"0.21\", \"best_ask\":\"0.22\"}, {\"asset_id\":\"96283536366176669581486355171583722558858323126916278856549586825357358273536\", \"price\":\"0.99\", \"size\":\"6844.52\", \"side\":\"SELL\", \"hash\":\"650325eb3d06e90691433aeff1cb7732ea79c3ef\", \"best_bid\":\"0.78\", \"best_ask\":\"0.79\"}], \"timestamp\":\"1785121846023\", \"event_type\":\"price_change\"}","received_at":"2026-07-27T03:10:45.952472Z","schema_version":"clob-market-ws.price_change.v1","sequence":null,"server_hash":null,"server_timestamp":"1785121846023","session_id":"ff6d21c8283948938400a32613abec2c","source":"clob_market_ws"},"received_at":"2026-07-27T03:10:45.952472Z","record_id":"678d3e24c2eed0344d8d2711648cd8f5d1aa7ba975ed66af68af2f4eb10d144d","schema_fingerprint":"4aa3821a28b0b7c2400bc59aba4bcc0a76e971dadd19610d3ad38c768e124dc7","schema_version":"edge-lab-recorder.raw.v1","sequence":null,"source":"clob_market_ws"}
{"event_at":"2026-07-27T03:10:46.024000Z","event_fingerprint":"c42c447db62d7de686747889adede5e2c3a8757c6de7e769e2fe339244a9a030","payload":{"connection_id":"f95883f18d264834af91809e5f803e9f","event_at":"2026-07-27T03:10:46.024000Z","event_type":"price_change","frame_hash":"43265f5ea2958ba7044e86522b7a24aa6f1a82ba75714447fa3b895f4ca909b0","frame_index":0,"kind":"data","monotonic_ns":223829285460833,"payload":{"event_type":"price_change","market":"0xf9d60bb033695053c4d1d8592e52171c1042f64b41a4b72e09dcc6f4852b6670","price_changes":[{"asset_id":"8698449539441374295770236407991735029336433231649246775082939325523552031992","best_ask":"0.22","best_bid":"0.21","hash":"6c409b32528c840d81348e2b5f381f3eda8513e2","price":"0.24","side":"SELL","size":"135"},{"asset_id":"96283536366176669581486355171583722558858323126916278856549586825357358273536","best_ask":"0.79","best_bid":"0.78","hash":"7ea83df38f53e86f06f402aec852b27ba95e7810","price":"0.76","side":"BUY","size":"135"}],"timestamp":"1785121846024"},"payload_hash":"f8ff82018a2cf1d201b63dca1ff1cb8c61bfc5bb55127aab03fda31c0d5f16f0","raw_frame":"{\"market\":\"0xf9d60bb033695053c4d1d8592e52171c1042f64b41a4b72e09dcc6f4852b6670\", \"price_changes\":[{\"asset_id\":\"8698449539441374295770236407991735029336433231649246775082939325523552031992\", \"price\":\"0.24\", \"size\":\"135\", \"side\":\"SELL\", \"hash\":\"6c409b32528c840d81348e2b5f381f3eda8513e2\", \"best_bid\":\"0.21\", \"best_ask\":\"0.22\"}, {\"asset_id\":\"96283536366176669581486355171583722558858323126916278856549586825357358273536\", \"price\":\"0.76\", \"size\":\"135\", \"side\":\"BUY\", \"hash\":\"7ea83df38f53e86f06f402aec852b27ba95e7810\", \"best_bid\":\"0.78\", \"best_ask\":\"0.79\"}], \"timestamp\":\"1785121846024\", \"event_type\":\"price_change\"}","received_at":"2026-07-27T03:10:45.955358Z","schema_version":"clob-market-ws.price_change.v1","sequence":null,"server_hash":null,"server_timestamp":"1785121846024","session_id":"ff6d21c8283948938400a32613abec2c","source":"clob_market_ws"},"received_at":"2026-07-27T03:10:45.955358Z","record_id":"d3edfffaead1ebcbd9f0080f72d2fdc59eb4caebee1464e7e36903cfbd8b7625","schema_fingerprint":"4aa3821a28b0b7c2400bc59aba4bcc0a76e971dadd19610d3ad38c768e124dc7","schema_version":"edge-lab-recorder.raw.v1","sequence":null,"source":"clob_market_ws"}
{"event_at":"2026-07-27T03:10:46.044000Z","event_fingerprint":"6f18cafcf6ceb859efec0726f82c1e166c0a2226e19939eaa1edb020d0c5e958","payload":{"connection_id":"f95883f18d264834af91809e5f803e9f","event_at":"2026-07-27T03:10:46.044000Z","event_type":"price_change","frame_hash":"b62d9a400c2de2541ba382074738ad82822f4f147b280fee1cbc3e8ef73022ea","frame_index":0,"kind":"data","monotonic_ns":223829288338583,"payload":{"event_type":"price_change","market":"0xf9d60bb033695053c4d1d8592e52171c1042f64b41a4b72e09dcc6f4852b6670","price_changes":[{"asset_id":"8698449539441374295770236407991735029336433231649246775082939325523552031992","best_ask":"0.22","best_bid":"0.21","hash":"de1865d6c35a628a33712600dd852aaeb91d0867","price":"0.34","side":"SELL","size":"156.29"},{"asset_id":"96283536366176669581486355171583722558858323126916278856549586825357358273536","best_ask":"0.79","best_bid":"0.78","hash":"85cc45fa55494186931ceda4e6916144518cfcd8","price":"0.66","side":"BUY","size":"156.29"}],"timestamp":"1785121846044"},"payload_hash":"7980e8640e5a79458dbd1ef1b1475873cd2d43fab003b4b1c55bb1723de8f74e","raw_frame":"{\"market\":\"0xf9d60bb033695053c4d1d8592e52171c1042f64b41a4b72e09dcc6f4852b6670\", \"price_changes\":[{\"asset_id\":\"8698449539441374295770236407991735029336433231649246775082939325523552031992\", \"price\":\"0.34\", \"size\":\"156.29\", \"side\":\"SELL\", \"hash\":\"de1865d6c35a628a33712600dd852aaeb91d0867\", \"best_bid\":\"0.21\", \"best_ask\":\"0.22\"}, {\"asset_id\":\"96283536366176669581486355171583722558858323126916278856549586825357358273536\", \"price\":\"0.66\", \"size\":\"156.29\", \"side\":\"BUY\", \"hash\":\"85cc45fa55494186931ceda4e6916144518cfcd8\", \"best_bid\":\"0.78\", \"best_ask\":\"0.79\"}], \"timestamp\":\"1785121846044\", \"event_type\":\"price_change\"}","received_at":"2026-07-27T03:10:45.958236Z","schema_version":"clob-market-ws.price_change.v1","sequence":null,"server_hash":null,"server_timestamp":"1785121846044","session_id":"ff6d21c8283948938400a32613abec2c","source":"clob_market_ws"},"received_at":"2026-07-27T03:10:45.958236Z","record_id":"33e09d4c2015f48e41bd69528f7012132b4089433b6d9bc7e76b4032a8a8a881","schema_fingerprint":"4aa3821a28b0b7c2400bc59aba4bcc0a76e971dadd19610d3ad38c768e124dc7","schema_version":"edge-lab-recorder.raw.v1","sequence":null,"source":"clob_market_ws"}
