{"event_at":"2026-07-27T03:14:00.194000Z","event_fingerprint":"fcada9bef2619a422e0576859cc0bdd457cc07c13036750c9a0e746ab1a0fbc6","payload":{"connection_id":"f95883f18d264834af91809e5f803e9f","event_at":"2026-07-27T03:14:00.194000Z","event_type":"price_change","frame_hash":"a326de460fff9842d47024e5c292056389e4c9f6ff93b232086478cbd1ccd3e1","frame_index":0,"kind":"data","monotonic_ns":224023490240416,"payload":{"event_type":"price_change","market":"0xf9d60bb033695053c4d1d8592e52171c1042f64b41a4b72e09dcc6f4852b6670","price_changes":[{"asset_id":"8698449539441374295770236407991735029336433231649246775082939325523552031992","best_ask":"0.87","best_bid":"0.86","hash":"0835cefeef23abbaa6a94acba3460d26362a00bc","price":"0.01","side":"BUY","size":"7617.5"},{"asset_id":"96283536366176669581486355171583722558858323126916278856549586825357358273536","best_ask":"0.14","best_bid":"0.13","hash":"259fb90beb79501c830ec5f799c261ac4b0712fd","price":"0.99","side":"SELL","size":"7617.5"}],"timestamp":"1785122040194"},"payload_hash":"5ac60c9cb9f96ab2cc49724a0c43a5fe296618fbbd6e1dbbf2e1bb1d00d08760","raw_frame":"{\"market\":\"0xf9d60bb033695053c4d1d8592e52171c1042f64b41a4b72e09dcc6f4852b6670\", \"price_changes\":[{\"asset_id\":\"8698449539441374295770236407991735029336433231649246775082939325523552031992\", \"price\":\"0.01\", \"size\":\"7617.5\", \"side\":\"BUY\", \"hash\":\"0835cefeef23abbaa6a94acba3460d26362a00bc\", \"best_bid\":\"0.86\", \"best_ask\":\"0.87\"}, {\"asset_id\":\"96283536366176669581486355171583722558858323126916278856549586825357358273536\", \"price\":\"0.99\", \"size\":\"7617.5\", \"side\":\"SELL\", \"hash\":\"259fb90beb79501c830ec5f799c261ac4b0712fd\", \"best_bid\":\"0.13\", \"best_ask\":\"0.14\"}], \"timestamp\":\"1785122040194\", \"event_type\":\"price_change\"}","received_at":"2026-07-27T03:14:00.157415Z","schema_version":"clob-market-ws.price_change.v1","sequence":null,"server_hash":null,"server_timestamp":"1785122040194","session_id":"ff6d21c8283948938400a32613abec2c","source":"clob_market_ws"},"received_at":"2026-07-27T03:14:00.157415Z","record_id":"dd54cffa444329fc1b444c97d3683a9d27b67c20dfe87d4fe201efa8cf253362","schema_fingerprint":"4aa3821a28b0b7c2400bc59aba4bcc0a76e971dadd19610d3ad38c768e124dc7","schema_version":"edge-lab-recorder.raw.v1","sequence":null,"source":"clob_market_ws"}
{"event_at":"2026-07-27T03:14:00.226000Z","event_fingerprint":"07cea60a8c662d493d16d6f9c1621286bf744eebb98df9d31316616f6516dd87","payload":{"connection_id":"f95883f18d264834af91809e5f803e9f","event_at":"2026-07-27T03:14:00.226000Z","event_type":"price_change","frame_hash":"7ae42814d781abfed53bccac1c284e013e7f98d290dfae2548439951315a46a8","frame_index":0,"kind":"data","monotonic_ns":224023502981583,"payload":{"event_type":"price_change","market":"0xf9d60bb033695053c4d1d8592e52171c1042f64b41a4b72e09dcc6f4852b6670","price_changes":[{"asset_id":"8698449539441374295770236407991735029336433231649246775082939325523552031992","best_ask":"0.87","best_bid":"0.86","hash":"37512b723123154537bea607bf6577bca68b5766","price":"0.01","side":"BUY","size":"7622.5"},{"asset_id":"96283536366176669581486355171583722558858323126916278856549586825357358273536","best_ask":"0.14","best_bid":"0.13","hash":"93606801deef97389665ed95da080ef26c23dd6c","price":"0.99","side":"SELL","size":"7622.5"}],"timestamp":"1785122040226"},"payload_hash":"8a886f61aab9aa3cbd2724ffa86000468e7a388ed21d5ba398c0a30c0fd8dbfd","raw_frame":"{\"market\":\"0xf9d60bb033695053c4d1d8592e52171c1042f64b41a4b72e09dcc6f4852b6670\", \"price_changes\":[{\"asset_id\":\"8698449539441374295770236407991735029336433231649246775082939325523552031992\", \"price\":\"0.01\", \"size\":\"7622.5\", \"side\":\"BUY\", \"hash\":\"37512b723123154537bea607bf6577bca68b5766\", \"best_bid\":\"0.86\", \"best_ask\":\"0.87\"}, {\"asset_id\":\"96283536366176669581486355171583722558858323126916278856549586825357358273536\", \"price\":\"0.99\", \"size\":\"7622.5\", \"side\":\"SELL\", \"hash\":\"93606801deef97389665ed95da080ef26c23dd6c\", \"best_bid\":\"0.13\", \"best_ask\":\"0.14\"}], \"timestamp\":\"1785122040226\", \"event_type\":\"price_change\"}","received_at":"2026-07-27T03:14:00.170157Z","schema_version":"clob-market-ws.price_change.v1","sequence":null,"server_hash":null,"server_timestamp":"1785122040226","session_id":"ff6d21c8283948938400a32613abec2c","source":"clob_market_ws"},"received_at":"2026-07-27T03:14:00.170157Z","record_id":"50f5427a496326dd8d32bf5451563e8691cded5d6971ecfe3a7d33df86b33c82","schema_fingerprint":"4aa3821a28b0b7c2400bc59aba4bcc0a76e971dadd19610d3ad38c768e124dc7","schema_version":"edge-lab-recorder.raw.v1","sequence":null,"source":"clob_market_ws"}
{"event_at":"2026-07-27T03:14:00.227000Z","event_fingerprint":"d9a4828e845b3cfdb95cf0082445d0cfce89846faf7a742ea0f0f1194b95de44","payload":{"connection_id":"f95883f18d264834af91809e5f803e9f","event_at":"2026-07-27T03:14:00.227000Z","event_type":"price_change","frame_hash":"74d94fc7f9a4c549c1f6e0fdf6b198e02e110427000f9a0dae129c106d16bce8","frame_index":0,"kind":"data","monotonic_ns":224023512533125,"payload":{"event_type":"price_change","market":"0xf9d60bb033695053c4d1d8592e52171c1042f64b41a4b72e09dcc6f4852b6670","price_changes":[{"asset_id":"8698449539441374295770236407991735029336433231649246775082939325523552031992","best_ask":"0.87","best_bid":"0.86","hash":"4d3d26b4f57664894c5ace1442b82838cf5f55b6","price":"0.7","side":"BUY","size":"90"},{"asset_id":"96283536366176669581486355171583722558858323126916278856549586825357358273536","best_ask":"0.14","best_bid":"0.13","hash":"61bb07391a399b49d09ada6086c7742d2f1ed759","price":"0.3","side":"SELL","size":"90"}],"timestamp":"1785122040227"},"payload_hash":"3c12b2aa52139142fd6d54122967196c50a24968facb5a1b8f8f705f13f0aa7b","raw_frame":"{\"market\":\"0xf9d60bb033695053c4d1d8592e52171c1042f64b41a4b72e09dcc6f4852b6670\", \"price_changes\":[{\"asset_id\":\"8698449539441374295770236407991735029336433231649246775082939325523552031992\", \"price\":\"0.7\", \"size\":\"90\", \"side\":\"BUY\", \"hash\":\"4d3d26b4f57664894c5ace1442b82838cf5f55b6\", \"best_bid\":\"0.86\", \"best_ask\":\"0.87\"}, {\"asset_id\":\"96283536366176669581486355171583722558858323126916278856549586825357358273536\", \"price\":\"0.3\", \"size\":\"90\", \"side\":\"SELL\", \"hash\":\"61bb07391a399b49d09ada6086c7742d2f1ed759\", \"best_bid\":\"0.13\", \"best_ask\":\"0.14\"}], \"timestamp\":\"1785122040227\", \"event_type\":\"price_change\"}","received_at":"2026-07-27T03:14:00.179708Z","schema_version":"clob-market-ws.price_change.v1","sequence":null,"server_hash":null,"server_timestamp":"1785122040227","session_id":"ff6d21c8283948938400a32613abec2c","source":"clob_market_ws"},"received_at":"2026-07-27T03:14:00.179708Z","record_id":"834c3b6113945be3899c40043097f2f3812e89a7844d010347df918c84e93b2c","schema_fingerprint":"4aa3821a28b0b7c2400bc59aba4bcc0a76e971dadd19610d3ad38c768e124dc7","schema_version":"edge-lab-recorder.raw.v1","sequence":null,"source":"clob_market_ws"}
{"event_at":"2026-07-27T03:14:00.227000Z","event_fingerprint":"92e3dddf9db5b1ce7e40dfc9e9ef31972f7b1502ae621942ddeb042884c6b663","payload":{"connection_id":"f95883f18d264834af91809e5f803e9f","event_at":"2026-07-27T03:14:00.227000Z","event_type":"price_change","frame_hash":"2d7f35bb1a8bd7d153da17f65885d1ee38f4f7ee50ebd4a9c54fc2b2b2ef828a","frame_index":0,"kind":"data","monotonic_ns":224023518596625,"payload":{"event_type":"price_change","market":"0xf9d60bb033695053c4d1d8592e52171c1042f64b41a4b72e09dcc6f4852b6670","price_changes":[{"asset_id":"8698449539441374295770236407991735029336433231649246775082939325523552031992","best_ask":"0.87","best_bid":"0.86","hash":"30467eb944bfb0bf9fa793c682e3ce4105abf830","price":"0.68","side":"BUY","size":"48.18"},{"asset_id":"96283536366176669581486355171583722558858323126916278856549586825357358273536","best_ask":"0.14","best_bid":"0.13","hash":"ef000a6f330f68f34ad49dd9824cefdef4fcd30a","price":"0.32","side":"SELL","size":"48.18"}],"timestamp":"1785122040227"},"payload_hash":"dde2a30d6f41276b820e43aa359674a22ce18bc4082f4e5d68cadc94c3d846ed","raw_frame":"{\"market\":\"0xf9d60bb033695053c4d1d8592e52171c1042f64b41a4b72e09dcc6f4852b6670\", \"price_changes\":[{\"asset_id\":\"8698449539441374295770236407991735029336433231649246775082939325523552031992\", \"price\":\"0.68\", \"size\":\"48.18\", \"side\":\"BUY\", \"hash\":\"30467eb944bfb0bf9fa793c682e3ce4105abf830\", \"best_bid\":\"0.86\", \"best_ask\":\"0.87\"}, {\"asset_id\":\"96283536366176669581486355171583722558858323126916278856549586825357358273536\", \"price\":\"0.32\", \"size\":\"48.18\", \"side\":\"SELL\", \"hash\":\"ef000a6f330f68f34ad49dd9824cefdef4fcd30a\", \"best_bid\":\"0.13\", \"best_ask\":\"0.14\"}], \"timestamp\":\"1785122040227\", \"event_type\":\"price_change\"}","received_at":"2026-07-27T03:14:00.185772Z","schema_version":"clob-market-ws.price_change.v1","sequence":null,"server_hash":null,"server_timestamp":"1785122040227","session_id":"ff6d21c8283948938400a32613abec2c","source":"clob_market_ws"},"received_at":"2026-07-27T03:14:00.185772Z","record_id":"d9a154ffe2cb88dec0eb8d97b0d06cd1738113b7ba32840f0314e9380c2b9398","schema_fingerprint":"4aa3821a28b0b7c2400bc59aba4bcc0a76e971dadd19610d3ad38c768e124dc7","schema_version":"edge-lab-recorder.raw.v1","sequence":null,"source":"clob_market_ws"}
{"event_at":"2026-07-27T03:14:00.228000Z","event_fingerprint":"ca9f15f6feaf6394049118ab78b5e9088729f6d2520f6782cdd2f395eadcbed2","payload":{"connection_id":"f95883f18d264834af91809e5f803e9f","event_at":"2026-07-27T03:14:00.228000Z","event_type":"price_change","frame_hash":"20f65db4f71088e6755828ef4a1c0b52f2c7b1dbfd79dbc798c839c19cba97f8","frame_index":0,"kind":"data","monotonic_ns":224023523874375,"payload":{"event_type":"price_change","market":"0xf9d60bb033695053c4d1d8592e52171c1042f64b41a4b72e09dcc6f4852b6670","price_changes":[{"asset_id":"8698449539441374295770236407991735029336433231649246775082939325523552031992","best_ask":"0.87","best_bid":"0.86","hash":"b51f54c5649b92ca1568dba22a7d9ce7fd5ef1a2","price":"0.57","side":"BUY","size":"42.8"},{"asset_id":"96283536366176669581486355171583722558858323126916278856549586825357358273536","best_ask":"0.14","best_bid":"0.13","hash":"3401228d7e5583c0d6f8c836550c2b20e931c29f","price":"0.43","side":"SELL","size":"42.8"}],"timestamp":"1785122040228"},"payload_hash":"d14bc07c2365429ab3c967ccd3f711f8bf75bdd8a4367438f9891938f68920ba","raw_frame":"{\"market\":\"0xf9d60bb033695053c4d1d8592e52171c1042f64b41a4b72e09dcc6f4852b6670\", \"price_changes\":[{\"asset_id\":\"8698449539441374295770236407991735029336433231649246775082939325523552031992\", \"price\":\"0.57\", \"size\":\"42.8\", \"side\":\"BUY\", \"hash\":\"b51f54c5649b92ca1568dba22a7d9ce7fd5ef1a2\", \"best_bid\":\"0.86\", \"best_ask\":\"0.87\"}, {\"asset_id\":\"96283536366176669581486355171583722558858323126916278856549586825357358273536\", \"price\":\"0.43\", \"size\":\"42.8\", \"side\":\"SELL\", \"hash\":\"3401228d7e5583c0d6f8c836550c2b20e931c29f\", \"best_bid\":\"0.13\", \"best_ask\":\"0.14\"}], \"timestamp\":\"1785122040228\", \"event_type\":\"price_change\"}","received_at":"2026-07-27T03:14:00.191055Z","schema_version":"clob-market-ws.price_change.v1","sequence":null,"server_hash":null,"server_timestamp":"1785122040228","session_id":"ff6d21c8283948938400a32613abec2c","source":"clob_market_ws"},"received_at":"2026-07-27T03:14:00.191055Z","record_id":"acc8b97af5933c3c3742a250a98c0bd752da1c46e42bdf7983fcf7ecfec03a40","schema_fingerprint":"4aa3821a28b0b7c2400bc59aba4bcc0a76e971dadd19610d3ad38c768e124dc7","schema_version":"edge-lab-recorder.raw.v1","sequence":null,"source":"clob_market_ws"}
{"event_at":"2026-07-27T03:14:00.228000Z","event_fingerprint":"cf5ac2e480c5b4aeb764da91bc19ba9aa7a00316a2f3c77e05dc0238c22f81f6","payload":{"connection_id":"f95883f18d264834af91809e5f803e9f","event_at":"2026-07-27T03:14:00.228000Z","event_type":"price_change","frame_hash":"ca884c3a08a20bf0a85231e53fe66053481394d7a41b5f3c9a7e4f228806e4dc","frame_index":0,"kind":"data","monotonic_ns":224023528272666,"payload":{"event_type":"price_change","market":"0xf9d60bb033695053c4d1d8592e52171c1042f64b41a4b72e09dcc6f4852b6670","price_changes":[{"asset_id":"8698449539441374295770236407991735029336433231649246775082939325523552031992","best_ask":"0.87","best_bid":"0.86","hash":"76811a8dbc6c0803db4dfc72e9f5a1ed48fafc7e","price":"0.54","side":"BUY","size":"42.3"},{"asset_id":"96283536366176669581486355171583722558858323126916278856549586825357358273536","best_ask":"0.14","best_bid":"0.13","hash":"a781f5b5940a11a19afd619a80447abf78b0dc22","price":"0.46","side":"SELL","size":"42.3"}],"timestamp":"1785122040228"},"payload_hash":"d024171abd63137b2cbcd9c1ecb6be4b60df5083e642cf13306cbffc64d7cad6","raw_frame":"{\"market\":\"0xf9d60bb033695053c4d1d8592e52171c1042f64b41a4b72e09dcc6f4852b6670\", \"price_changes\":[{\"asset_id\":\"8698449539441374295770236407991735029336433231649246775082939325523552031992\", \"price\":\"0.54\", \"size\":\"42.3\", \"side\":\"BUY\", \"hash\":\"76811a8dbc6c0803db4dfc72e9f5a1ed48fafc7e\", \"best_bid\":\"0.86\", \"best_ask\":\"0.87\"}, {\"asset_id\":\"96283536366176669581486355171583722558858323126916278856549586825357358273536\", \"price\":\"0.46\", \"size\":\"42.3\", \"side\":\"SELL\", \"hash\":\"a781f5b5940a11a19afd619a80447abf78b0dc22\", \"best_bid\":\"0.13\", \"best_ask\":\"0.14\"}], \"timestamp\":\"1785122040228\", \"event_type\":\"price_change\"}","received_at":"2026-07-27T03:14:00.195453Z","schema_version":"clob-market-ws.price_change.v1","sequence":null,"server_hash":null,"server_timestamp":"1785122040228","session_id":"ff6d21c8283948938400a32613abec2c","source":"clob_market_ws"},"received_at":"2026-07-27T03:14:00.195453Z","record_id":"2fec2bb3885d12f7db89856a63eed35d22019683c91423652df6bf4e8cceeb03","schema_fingerprint":"4aa3821a28b0b7c2400bc59aba4bcc0a76e971dadd19610d3ad38c768e124dc7","schema_version":"edge-lab-recorder.raw.v1","sequence":null,"source":"clob_market_ws"}
{"event_at":"2026-07-27T03:14:00.228000Z","event_fingerprint":"ef473419420fa7ef70c3c0929eb1a1d4886d18c60fe480e4c9b5d567d51c8af7","payload":{"connection_id":"f95883f18d264834af91809e5f803e9f","event_at":"2026-07-27T03:14:00.228000Z","event_type":"price_change","frame_hash":"ec8e9b3924d74de29b97b425a45b72a4171b8d7273cdf9504ba9e3c7fe40847e","frame_index":0,"kind":"data","monotonic_ns":224023532974416,"payload":{"event_type":"price_change","market":"0xf9d60bb033695053c4d1d8592e52171c1042f64b41a4b72e09dcc6f4852b6670","price_changes":[{"asset_id":"8698449539441374295770236407991735029336433231649246775082939325523552031992","best_ask":"0.87","best_bid":"0.86","hash":"e6a73927a316e27b08a90de781d0eac319fe34ff","price":"0.47","side":"BUY","size":"54.2"},{"asset_id":"96283536366176669581486355171583722558858323126916278856549586825357358273536","best_ask":"0.14","best_bid":"0.13","hash":"0d4692077c23a45e7f66e45bd9463b10db7d3b63","price":"0.53","side":"SELL","size":"54.2"}],"timestamp":"1785122040228"},"payload_hash":"a4bd67256cbc74f63f28687bf34476483e2073cad26eac5e42acea4a35fab2e1","raw_frame":"{\"market\":\"0xf9d60bb033695053c4d1d8592e52171c1042f64b41a4b72e09dcc6f4852b6670\", \"price_changes\":[{\"asset_id\":\"8698449539441374295770236407991735029336433231649246775082939325523552031992\", \"price\":\"0.47\", \"size\":\"54.2\", \"side\":\"BUY\", \"hash\":\"e6a73927a316e27b08a90de781d0eac319fe34ff\", \"best_bid\":\"0.86\", \"best_ask\":\"0.87\"}, {\"asset_id\":\"96283536366176669581486355171583722558858323126916278856549586825357358273536\", \"price\":\"0.53\", \"size\":\"54.2\", \"side\":\"SELL\", \"hash\":\"0d4692077c23a45e7f66e45bd9463b10db7d3b63\", \"best_bid\":\"0.13\", \"best_ask\":\"0.14\"}], \"timestamp\":\"1785122040228\", \"event_type\":\"price_change\"}","received_at":"2026-07-27T03:14:00.200148Z","schema_version":"clob-market-ws.price_change.v1","sequence":null,"server_hash":null,"server_timestamp":"1785122040228","session_id":"ff6d21c8283948938400a32613abec2c","source":"clob_market_ws"},"received_at":"2026-07-27T03:14:00.200148Z","record_id":"ac8f9497294ac98fa6cecf049b2b8989785b63517641137bbc69306d6dd9e13e","schema_fingerprint":"4aa3821a28b0b7c2400bc59aba4bcc0a76e971dadd19610d3ad38c768e124dc7","schema_version":"edge-lab-recorder.raw.v1","sequence":null,"source":"clob_market_ws"}
{"event_at":"2026-07-27T03:14:00.228000Z","event_fingerprint":"886105e8610936a9319f68879a278419688017d02ca4648de4ce588baafe0b27","payload":{"connection_id":"f95883f18d264834af91809e5f803e9f","event_at":"2026-07-27T03:14:00.228000Z","event_type":"price_change","frame_hash":"7184d86be00bad1970920fa530be5c8cbbd8f4c22d82c80f9c11d8949de5a8ea","frame_index":0,"kind":"data","monotonic_ns":224023536503083,"payload":{"event_type":"price_change","market":"0xf9d60bb033695053c4d1d8592e52171c1042f64b41a4b72e09dcc6f4852b6670","price_changes":[{"asset_id":"8698449539441374295770236407991735029336433231649246775082939325523552031992","best_ask":"0.87","best_bid":"0.86","hash":"edc724c35a8730018cc6ffeac900970fb679304f","price":"0.45","side":"BUY","size":"54.5"},{"asset_id":"96283536366176669581486355171583722558858323126916278856549586825357358273536","best_ask":"0.14","best_bid":"0.13","hash":"6d5f463ebf91f17e0107f0a1132248de8c176348","price":"0.55","side":"SELL","size":"54.5"}],"timestamp":"1785122040228"},"payload_hash":"2cbee03dd6f15c1d7147a9e689184523836e8e3f04df7e3de136d687a3289e13","raw_frame":"{\"market\":\"0xf9d60bb033695053c4d1d8592e52171c1042f64b41a4b72e09dcc6f4852b6670\", \"price_changes\":[{\"asset_id\":\"8698449539441374295770236407991735029336433231649246775082939325523552031992\", \"price\":\"0.45\", \"size\":\"54.5\", \"side\":\"BUY\", \"hash\":\"edc724c35a8730018cc6ffeac900970fb679304f\", \"best_bid\":\"0.86\", \"best_ask\":\"0.87\"}, {\"asset_id\":\"96283536366176669581486355171583722558858323126916278856549586825357358273536\", \"price\":\"0.55\", \"size\":\"54.5\", \"side\":\"SELL\", \"hash\":\"6d5f463ebf91f17e0107f0a1132248de8c176348\", \"best_bid\":\"0.13\", \"best_ask\":\"0.14\"}], \"timestamp\":\"1785122040228\", \"event_type\":\"price_change\"}","received_at":"2026-07-27T03:14:00.203675Z","schema_version":"clob-market-ws.price_change.v1","sequence":null,"server_hash":null,"server_timestamp":"1785122040228","session_id":"ff6d21c8283948938400a32613abec2c","source":"clob_market_ws"},"received_at":"2026-07-27T03:14:00.203675Z","record_id":"c9c456f4f375ef7465d5bcfb76a786b742e3e517959ac0b7a7976f1f70768883","schema_fingerprint":"4aa3821a28b0b7c2400bc59aba4bcc0a76e971dadd19610d3ad38c768e124dc7","schema_version":"edge-lab-recorder.raw.v1","sequence":null,"source":"clob_market_ws"}
{"event_at":"2026-07-27T03:14:00.228000Z","event_fingerprint":"519f873427c170261694a2a85e260a7e546f6e310982a856e5bb26341982f226","payload":{"connection_id":"f95883f18d264834af91809e5f803e9f","event_at":"2026-07-27T03:14:00.228000Z","event_type":"price_change","frame_hash":"d2c5303e39bd694849ab7c9da900dbf99fe50c00258c4aa664ab70c45631a77d","frame_index":0,"kind":"data","monotonic_ns":224023543535541,"payload":{"event_type":"price_change","market":"0xf9d60bb033695053c4d1d8592e52171c1042f64b41a4b72e09dcc6f4852b6670","price_changes":[{"asset_id":"8698449539441374295770236407991735029336433231649246775082939325523552031992","best_ask":"0.87","best_bid":"0.86","hash":"7be833c9d7e656483f8795fe00de043cbd912d95","price":"0.67","side":"BUY","size":"77.5"},{"asset_id":"96283536366176669581486355171583722558858323126916278856549586825357358273536","best_ask":"0.14","best_bid":"0.13","hash":"1208b7e225b12558a0de10923a0f0b6bf7d90198","price":"0.33","side":"SELL","size":"77.5"}],"timestamp":"1785122040228"},"payload_hash":"1cad8c8ac31bb677a48400d83fc9a9aaa3a53a2a0a0fdb1af199813f606f7045","raw_frame":"{\"market\":\"0xf9d60bb033695053c4d1d8592e52171c1042f64b41a4b72e09dcc6f4852b6670\", \"price_changes\":[{\"asset_id\":\"8698449539441374295770236407991735029336433231649246775082939325523552031992\", \"price\":\"0.67\", \"size\":\"77.5\", \"side\":\"BUY\", \"hash\":\"7be833c9d7e656483f8795fe00de043cbd912d95\", \"best_bid\":\"0.86\", \"best_ask\":\"0.87\"}, {\"asset_id\":\"96283536366176669581486355171583722558858323126916278856549586825357358273536\", \"price\":\"0.33\", \"size\":\"77.5\", \"side\":\"SELL\", \"hash\":\"1208b7e225b12558a0de10923a0f0b6bf7d90198\", \"best_bid\":\"0.13\", \"best_ask\":\"0.14\"}], \"timestamp\":\"1785122040228\", \"event_type\":\"price_change\"}","received_at":"2026-07-27T03:14:00.210710Z","schema_version":"clob-market-ws.price_change.v1","sequence":null,"server_hash":null,"server_timestamp":"1785122040228","session_id":"ff6d21c8283948938400a32613abec2c","source":"clob_market_ws"},"received_at":"2026-07-27T03:14:00.210710Z","record_id":"2da082af3713fee56977e23b7568c6ccd883f00c2281d0e1caddfe704dd9c5b1","schema_fingerprint":"4aa3821a28b0b7c2400bc59aba4bcc0a76e971dadd19610d3ad38c768e124dc7","schema_version":"edge-lab-recorder.raw.v1","sequence":null,"source":"clob_market_ws"}
{"event_at":"2026-07-27T03:14:00.228000Z","event_fingerprint":"aea4bf4f6701f9d6917adcd9be5902c8555f29a36e6a3ee1e99afcf3f454d3d9","payload":{"connection_id":"f95883f18d264834af91809e5f803e9f","event_at":"2026-07-27T03:14:00.228000Z","event_type":"price_change","frame_hash":"2a9542f4ca230620d21b16d8477c2f0b2ad42128861132a31000ca748c7fbec3","frame_index":0,"kind":"data","monotonic_ns":224023547381125,"payload":{"event_type":"price_change","market":"0xf9d60bb033695053c4d1d8592e52171c1042f64b41a4b72e09dcc6f4852b6670","price_changes":[{"asset_id":"8698449539441374295770236407991735029336433231649246775082939325523552031992","best_ask":"0.87","best_bid":"0.86","hash":"52bc8a687c9bcc2c5a01b7363826d9baeb42a3ad","price":"0.52","side":"BUY","size":"72"},{"asset_id":"96283536366176669581486355171583722558858323126916278856549586825357358273536","best_ask":"0.14","best_bid":"0.13","hash":"c404519ef1c7b275b0da1659c84c6692bac97252","price":"0.48","side":"SELL","size":"72"}],"timestamp":"1785122040228"},"payload_hash":"fa607adb1c87220731a7d273f76abf69807b7076a19ced7728acb4b692c7c971","raw_frame":"{\"market\":\"0xf9d60bb033695053c4d1d8592e52171c1042f64b41a4b72e09dcc6f4852b6670\", \"price_changes\":[{\"asset_id\":\"8698449539441374295770236407991735029336433231649246775082939325523552031992\", \"price\":\"0.52\", \"size\":\"72\", \"side\":\"BUY\", \"hash\":\"52bc8a687c9bcc2c5a01b7363826d9baeb42a3ad\", \"best_bid\":\"0.86\", \"best_ask\":\"0.87\"}, {\"asset_id\":\"96283536366176669581486355171583722558858323126916278856549586825357358273536\", \"price\":\"0.48\", \"size\":\"72\", \"side\":\"SELL\", \"hash\":\"c404519ef1c7b275b0da1659c84c6692bac97252\", \"best_bid\":\"0.13\", \"best_ask\":\"0.14\"}], \"timestamp\":\"1785122040228\", \"event_type\":\"price_change\"}","received_at":"2026-07-27T03:14:00.214561Z","schema_version":"clob-market-ws.price_change.v1","sequence":null,"server_hash":null,"server_timestamp":"1785122040228","session_id":"ff6d21c8283948938400a32613abec2c","source":"clob_market_ws"},"received_at":"2026-07-27T03:14:00.214561Z","record_id":"497f37a52ce924edd3000f9ab7933f449dd56feace002b4ea8a2352e07ca345a","schema_fingerprint":"4aa3821a28b0b7c2400bc59aba4bcc0a76e971dadd19610d3ad38c768e124dc7","schema_version":"edge-lab-recorder.raw.v1","sequence":null,"source":"clob_market_ws"}
{"event_at":"2026-07-27T03:14:00.228000Z","event_fingerprint":"1a0d7990f4b2f8f3fa1f9101a647ac2eda3cba78603830d547adb25a677e864f","payload":{"connection_id":"f95883f18d264834af91809e5f803e9f","event_at":"2026-07-27T03:14:00.228000Z","event_type":"price_change","frame_hash":"a43fb718994fa7d292ea1883bd4df9675be8ba4fbb7aae921128b7a75eecf4c1","frame_index":0,"kind":"data","monotonic_ns":224023551500625,"payload":{"event_type":"price_change","market":"0xf9d60bb033695053c4d1d8592e52171c1042f64b41a4b72e09dcc6f4852b6670","price_changes":[{"asset_id":"8698449539441374295770236407991735029336433231649246775082939325523552031992","best_ask":"0.87","best_bid":"0.86","hash":"1d5bbd002e6c223726c4bd0f4ebb2453645c0d45","price":"0.66","side":"BUY","size":"46.79"},{"asset_id":"96283536366176669581486355171583722558858323126916278856549586825357358273536","best_ask":"0.14","best_bid":"0.13","hash":"0f0218b9cec82be3e674031521cdd495adc75e31","price":"0.34","side":"SELL","size":"46.79"}],"timestamp":"1785122040228"},"payload_hash":"837aee72851329bf7c726cb9b8cf2a287aff56bc79e26a904fca2894ba12f2a3","raw_frame":"{\"market\":\"0xf9d60bb033695053c4d1d8592e52171c1042f64b41a4b72e09dcc6f4852b6670\", \"price_changes\":[{\"asset_id\":\"8698449539441374295770236407991735029336433231649246775082939325523552031992\", \"price\":\"0.66\", \"size\":\"46.79\", \"side\":\"BUY\", \"hash\":\"1d5bbd002e6c223726c4bd0f4ebb2453645c0d45\", \"best_bid\":\"0.86\", \"best_ask\":\"0.87\"}, {\"asset_id\":\"96283536366176669581486355171583722558858323126916278856549586825357358273536\", \"price\":\"0.34\", \"size\":\"46.79\", \"side\":\"SELL\", \"hash\":\"0f0218b9cec82be3e674031521cdd495adc75e31\", \"best_bid\":\"0.13\", \"best_ask\":\"0.14\"}], \"timestamp\":\"1785122040228\", \"event_type\":\"price_change\"}","received_at":"2026-07-27T03:14:00.218678Z","schema_version":"clob-market-ws.price_change.v1","sequence":null,"server_hash":null,"server_timestamp":"1785122040228","session_id":"ff6d21c8283948938400a32613abec2c","source":"clob_market_ws"},"received_at":"2026-07-27T03:14:00.218678Z","record_id":"f788dda15ba24b668ac779015ae3dc65dfb13bba7482b9340b42155f81d46546","schema_fingerprint":"4aa3821a28b0b7c2400bc59aba4bcc0a76e971dadd19610d3ad38c768e124dc7","schema_version":"edge-lab-recorder.raw.v1","sequence":null,"source":"clob_market_ws"}
{"event_at":"2026-07-27T03:14:00.229000Z","event_fingerprint":"a9fbe062c5a4527d012382116f372f18b58109c458b50f4a88996876a3a7c3cb","payload":{"connection_id":"f95883f18d264834af91809e5f803e9f","event_at":"2026-07-27T03:14:00.229000Z","event_type":"price_change","frame_hash":"c8937d23b62f7f8d2c185a289a273b5db115380dfa221489023b765df9d5526b","frame_index":0,"kind":"data","monotonic_ns":224023553874500,"payload":{"event_type":"price_change","market":"0xf9d60bb033695053c4d1d8592e52171c1042f64b41a4b72e09dcc6f4852b6670","price_changes":[{"asset_id":"8698449539441374295770236407991735029336433231649246775082939325523552031992","best_ask":"0.87","best_bid":"0.86","hash":"49c404debbe5d22b6ba9f94d885729c28b422210","price":"0.64","side":"BUY","size":"75.58"},{"asset_id":"96283536366176669581486355171583722558858323126916278856549586825357358273536","best_ask":"0.14","best_bid":"0.13","hash":"f7c2350ab1e1733ccaaffd8354770cb4cf1be6bd","price":"0.36","side":"SELL","size":"75.58"}],"timestamp":"1785122040229"},"payload_hash":"f86e25cd6d7e14445e2a9fc87bb5ef8c087582da153e46c46c1f4df36f26e323","raw_frame":"{\"market\":\"0xf9d60bb033695053c4d1d8592e52171c1042f64b41a4b72e09dcc6f4852b6670\", \"price_changes\":[{\"asset_id\":\"8698449539441374295770236407991735029336433231649246775082939325523552031992\", \"price\":\"0.64\", \"size\":\"75.58\", \"side\":\"BUY\", \"hash\":\"49c404debbe5d22b6ba9f94d885729c28b422210\", \"best_bid\":\"0.86\", \"best_ask\":\"0.87\"}, {\"asset_id\":\"96283536366176669581486355171583722558858323126916278856549586825357358273536\", \"price\":\"0.36\", \"size\":\"75.58\", \"side\":\"SELL\", \"hash\":\"f7c2350ab1e1733ccaaffd8354770cb4cf1be6bd\", \"best_bid\":\"0.13\", \"best_ask\":\"0.14\"}], \"timestamp\":\"1785122040229\", \"event_type\":\"price_change\"}","received_at":"2026-07-27T03:14:00.221052Z","schema_version":"clob-market-ws.price_change.v1","sequence":null,"server_hash":null,"server_timestamp":"1785122040229","session_id":"ff6d21c8283948938400a32613abec2c","source":"clob_market_ws"},"received_at":"2026-07-27T03:14:00.221052Z","record_id":"55c171ae15cf96d8da6e68cd568ed68f2a2412f726a050e600b08e88ccf711bf","schema_fingerprint":"4aa3821a28b0b7c2400bc59aba4bcc0a76e971dadd19610d3ad38c768e124dc7","schema_version":"edge-lab-recorder.raw.v1","sequence":null,"source":"clob_market_ws"}
{"event_at":"2026-07-27T03:14:00.229000Z","event_fingerprint":"6ccc8a8a74d57fbb2abf153680afdfdfb435ebbc3bf4dd2d8fcd44c05a3c425b","payload":{"connection_id":"f95883f18d264834af91809e5f803e9f","event_at":"2026-07-27T03:14:00.229000Z","event_type":"price_change","frame_hash":"7525200efc2909ed30e10f537433570d04011ead0fe3bf906742c9d702a987fc","frame_index":0,"kind":"data","monotonic_ns":224023557051166,"payload":{"event_type":"price_change","market":"0xf9d60bb033695053c4d1d8592e52171c1042f64b41a4b72e09dcc6f4852b6670","price_changes":[{"asset_id":"96283536366176669581486355171583722558858323126916278856549586825357358273536","best_ask":"0.14","best_bid":"0.13","hash":"37bbe1a52c7b2d95963f8dd0d0943e43affd055e","price":"0.07","side":"BUY","size":"167"},{"asset_id":"8698449539441374295770236407991735029336433231649246775082939325523552031992","best_ask":"0.87","best_bid":"0.86","hash":"a0f3f48a1817cc24fec631242cb08c90c6d8563d","price":"0.93","side":"SELL","size":"167"}],"timestamp":"1785122040229"},"payload_hash":"34716c5d59ec5c2fadfd8510de16dfe7e506507509d4436d4e23e3a766e796f6","raw_frame":"{\"market\":\"0xf9d60bb033695053c4d1d8592e52171c1042f64b41a4b72e09dcc6f4852b6670\", \"price_changes\":[{\"asset_id\":\"96283536366176669581486355171583722558858323126916278856549586825357358273536\", \"price\":\"0.07\", \"size\":\"167\", \"side\":\"BUY\", \"hash\":\"37bbe1a52c7b2d95963f8dd0d0943e43affd055e\", \"best_bid\":\"0.13\", \"best_ask\":\"0.14\"}, {\"asset_id\":\"8698449539441374295770236407991735029336433231649246775082939325523552031992\", \"price\":\"0.93\", \"size\":\"167\", \"side\":\"SELL\", \"hash\":\"a0f3f48a1817cc24fec631242cb08c90c6d8563d\", \"best_bid\":\"0.86\", \"best_ask\":\"0.87\"}], \"timestamp\":\"1785122040229\", \"event_type\":\"price_change\"}","received_at":"2026-07-27T03:14:00.224224Z","schema_version":"clob-market-ws.price_change.v1","sequence":null,"server_hash":null,"server_timestamp":"1785122040229","session_id":"ff6d21c8283948938400a32613abec2c","source":"clob_market_ws"},"received_at":"2026-07-27T03:14:00.224224Z","record_id":"be5f22777c89b380e2b1b05c35fc2a081fee524f53919f49b43f07791db051ca","schema_fingerprint":"4aa3821a28b0b7c2400bc59aba4bcc0a76e971dadd19610d3ad38c768e124dc7","schema_version":"edge-lab-recorder.raw.v1","sequence":null,"source":"clob_market_ws"}
{"event_at":"2026-07-27T03:14:00.229000Z","event_fingerprint":"d779e4a5a45343b13b46277b0dd496873b5149beb357e12b8fe281a3710d063c","payload":{"connection_id":"f95883f18d264834af91809e5f803e9f","event_at":"2026-07-27T03:14:00.229000Z","event_type":"price_change","frame_hash":"c21a63f6debd0760769d4aeb7d48f9bf2afe931f620f3736b16b084f18ef2cec","frame_index":0,"kind":"data","monotonic_ns":224023562019750,"payload":{"event_type":"price_change","market":"0xf9d60bb033695053c4d1d8592e52171c1042f64b41a4b72e09dcc6f4852b6670","price_changes":[{"asset_id":"8698449539441374295770236407991735029336433231649246775082939325523552031992","best_ask":"0.87","best_bid":"0.86","hash":"3662db85f43481b75db818bf3a8db9784716dd69","price":"0.65","side":"BUY","size":"46.1"},{"asset_id":"96283536366176669581486355171583722558858323126916278856549586825357358273536","best_ask":"0.14","best_bid":"0.13","hash":"2ff6f3b370fae7d70f2694f3e453f35422b061b0","price":"0.35","side":"SELL","size":"46.1"}],"timestamp":"1785122040229"},"payload_hash":"a7f078b42a41c7c693fce96abbdd29677201bfec15051ab9e5984ed920a78fab","raw_frame":"{\"market\":\"0xf9d60bb033695053c4d1d8592e52171c1042f64b41a4b72e09dcc6f4852b6670\", \"price_changes\":[{\"asset_id\":\"8698449539441374295770236407991735029336433231649246775082939325523552031992\", \"price\":\"0.65\", \"size\":\"46.1\", \"side\":\"BUY\", \"hash\":\"3662db85f43481b75db818bf3a8db9784716dd69\", \"best_bid\":\"0.86\", \"best_ask\":\"0.87\"}, {\"asset_id\":\"96283536366176669581486355171583722558858323126916278856549586825357358273536\", \"price\":\"0.35\", \"size\":\"46.1\", \"side\":\"SELL\", \"hash\":\"2ff6f3b370fae7d70f2694f3e453f35422b061b0\", \"best_bid\":\"0.13\", \"best_ask\":\"0.14\"}], \"timestamp\":\"1785122040229\", \"event_type\":\"price_change\"}","received_at":"2026-07-27T03:14:00.229194Z","schema_version":"clob-market-ws.price_change.v1","sequence":null,"server_hash":null,"server_timestamp":"1785122040229","session_id":"ff6d21c8283948938400a32613abec2c","source":"clob_market_ws"},"received_at":"2026-07-27T03:14:00.229194Z","record_id":"9cf5eb5eebbdea22cf6e26c178eb35ff282711f41d0cd74a4705312e72d310fe","schema_fingerprint":"4aa3821a28b0b7c2400bc59aba4bcc0a76e971dadd19610d3ad38c768e124dc7","schema_version":"edge-lab-recorder.raw.v1","sequence":null,"source":"clob_market_ws"}
{"event_at":"2026-07-27T03:14:00.229000Z","event_fingerprint":"488afc225d0b59c539728cdb0214e1029cceab3ccfd20c1458f1595dd0827fb2","payload":{"connection_id":"f95883f18d264834af91809e5f803e9f","event_at":"2026-07-27T03:14:00.229000Z","event_type":"price_change","frame_hash":"a9cbd151b7699063a8bbe7032229558d2df41c5abece87ab9d50545f40a8189e","frame_index":0,"kind":"data","monotonic_ns":224023568065125,"payload":{"event_type":"price_change","market":"0xf9d60bb033695053c4d1d8592e52171c1042f64b41a4b72e09dcc6f4852b6670","price_changes":[{"asset_id":"8698449539441374295770236407991735029336433231649246775082939325523552031992","best_ask":"0.87","best_bid":"0.86","hash":"d6a7ce06af6aec7046dc78c1e896dcb376a0f306","price":"0.63","side":"BUY","size":"57.1"},{"asset_id":"96283536366176669581486355171583722558858323126916278856549586825357358273536","best_ask":"0.14","best_bid":"0.13","hash":"55e2a2943f9a250ccaee159f8fadb24d665b7ae6","price":"0.37","side":"SELL","size":"57.1"}],"timestamp":"1785122040229"},"payload_hash":"f3664ba4a0d0e0cf82498c00b162af03c73cbfbec92a1efe63a44524f961be84","raw_frame":"{\"market\":\"0xf9d60bb033695053c4d1d8592e52171c1042f64b41a4b72e09dcc6f4852b6670\", \"price_changes\":[{\"asset_id\":\"8698449539441374295770236407991735029336433231649246775082939325523552031992\", \"price\":\"0.63\", \"size\":\"57.1\", \"side\":\"BUY\", \"hash\":\"d6a7ce06af6aec7046dc78c1e896dcb376a0f306\", \"best_bid\":\"0.86\", \"best_ask\":\"0.87\"}, {\"asset_id\":\"96283536366176669581486355171583722558858323126916278856549586825357358273536\", \"price\":\"0.37\", \"size\":\"57.1\", \"side\":\"SELL\", \"hash\":\"55e2a2943f9a250ccaee159f8fadb24d665b7ae6\", \"best_bid\":\"0.13\", \"best_ask\":\"0.14\"}], \"timestamp\":\"1785122040229\", \"event_type\":\"price_change\"}","received_at":"2026-07-27T03:14:00.235242Z","schema_version":"clob-market-ws.price_change.v1","sequence":null,"server_hash":null,"server_timestamp":"1785122040229","session_id":"ff6d21c8283948938400a32613abec2c","source":"clob_market_ws"},"received_at":"2026-07-27T03:14:00.235242Z","record_id":"72fde7481e0911218f68c3176e679e37cb1fc87912d56ab7d6027039251fc881","schema_fingerprint":"4aa3821a28b0b7c2400bc59aba4bcc0a76e971dadd19610d3ad38c768e124dc7","schema_version":"edge-lab-recorder.raw.v1","sequence":null,"source":"clob_market_ws"}
{"event_at":"2026-07-27T03:14:00.229000Z","event_fingerprint":"010d56d4a4845ac8467bff5a3fad02804eb0503f08dbd82bac678747ea43f5fd","payload":{"connection_id":"f95883f18d264834af91809e5f803e9f","event_at":"2026-07-27T03:14:00.229000Z","event_type":"price_change","frame_hash":"d1f83f1435b74547ca5965e5dabc925dc07006b9b476a1fbc1ef5f626fcabae5","frame_index":0,"kind":"data","monotonic_ns":224023571951083,"payload":{"event_type":"price_change","market":"0xf9d60bb033695053c4d1d8592e52171c1042f64b41a4b72e09dcc6f4852b6670","price_changes":[{"asset_id":"96283536366176669581486355171583722558858323126916278856549586825357358273536","best_ask":"0.14","best_bid":"0.13","hash":"bb304456c0b37340c466fa122820e6d5e383994c","price":"0.05","side":"BUY","size":"369.19"},{"asset_id":"8698449539441374295770236407991735029336433231649246775082939325523552031992","best_ask":"0.87","best_bid":"0.86","hash":"567f8fb991175ef4bfef7b2ab6b4eac07b54408e","price":"0.95","side":"SELL","size":"369.19"}],"timestamp":"1785122040229"},"payload_hash":"97e7ad34ced5c0ee576f9b7198a44ea582a2c537a4948596fc2ecf3df43c0c00","raw_frame":"{\"market\":\"0xf9d60bb033695053c4d1d8592e52171c1042f64b41a4b72e09dcc6f4852b6670\", \"price_changes\":[{\"asset_id\":\"96283536366176669581486355171583722558858323126916278856549586825357358273536\", \"price\":\"0.05\", \"size\":\"369.19\", \"side\":\"BUY\", \"hash\":\"bb304456c0b37340c466fa122820e6d5e383994c\", \"best_bid\":\"0.13\", \"best_ask\":\"0.14\"}, {\"asset_id\":\"8698449539441374295770236407991735029336433231649246775082939325523552031992\", \"price\":\"0.95\", \"size\":\"369.19\", \"side\":\"SELL\", \"hash\":\"567f8fb991175ef4bfef7b2ab6b4eac07b54408e\", \"best_bid\":\"0.86\", \"best_ask\":\"0.87\"}], \"timestamp\":\"1785122040229\", \"event_type\":\"price_change\"}","received_at":"2026-07-27T03:14:00.239124Z","schema_version":"clob-market-ws.price_change.v1","sequence":null,"server_hash":null,"server_timestamp":"1785122040229","session_id":"ff6d21c8283948938400a32613abec2c","source":"clob_market_ws"},"received_at":"2026-07-27T03:14:00.239124Z","record_id":"a4d80b9238844a58b6536f450d56b8a656c786789cd3dc2d06e5a66ab79d37ff","schema_fingerprint":"4aa3821a28b0b7c2400bc59aba4bcc0a76e971dadd19610d3ad38c768e124dc7","schema_version":"edge-lab-recorder.raw.v1","sequence":null,"source":"clob_market_ws"}
{"event_at":"2026-07-27T03:14:00.230000Z","event_fingerprint":"3c7f3020a5ca17a9065fbd5e90c46c58e0c4553f692ea66800d8a88e8845c193","payload":{"connection_id":"f95883f18d264834af91809e5f803e9f","event_at":"2026-07-27T03:14:00.230000Z","event_type":"price_change","frame_hash":"e287763724c32f3b047e6269abdb125c0a2cc8789a791c123db16d01ecf43afc","frame_index":0,"kind":"data","monotonic_ns":224023574384458,"payload":{"event_type":"price_change","market":"0xf9d60bb033695053c4d1d8592e52171c1042f64b41a4b72e09dcc6f4852b6670","price_changes":[{"asset_id":"8698449539441374295770236407991735029336433231649246775082939325523552031992","best_ask":"0.87","best_bid":"0.86","hash":"dac4cef145fadcd488675836a97796790e56075e","price":"0.39","side":"BUY","size":"44.09"},{"asset_id":"96283536366176669581486355171583722558858323126916278856549586825357358273536","best_ask":"0.14","best_bid":"0.13","hash":"13ea2655f9701705abc0970eb5ebb6a29cd009b1","price":"0.61","side":"SELL","size":"44.09"}],"timestamp":"1785122040230"},"payload_hash":"9a8478c2035ac5977109ec8bc8d33d08f3fdf2f2b4632c05561a1b8e3cc3fb35","raw_frame":"{\"market\":\"0xf9d60bb033695053c4d1d8592e52171c1042f64b41a4b72e09dcc6f4852b6670\", \"price_changes\":[{\"asset_id\":\"8698449539441374295770236407991735029336433231649246775082939325523552031992\", \"price\":\"0.39\", \"size\":\"44.09\", \"side\":\"BUY\", \"hash\":\"dac4cef145fadcd488675836a97796790e56075e\", \"best_bid\":\"0.86\", \"best_ask\":\"0.87\"}, {\"asset_id\":\"96283536366176669581486355171583722558858323126916278856549586825357358273536\", \"price\":\"0.61\", \"size\":\"44.09\", \"side\":\"SELL\", \"hash\":\"13ea2655f9701705abc0970eb5ebb6a29cd009b1\", \"best_bid\":\"0.13\", \"best_ask\":\"0.14\"}], \"timestamp\":\"1785122040230\", \"event_type\":\"price_change\"}","received_at":"2026-07-27T03:14:00.241558Z","schema_version":"clob-market-ws.price_change.v1","sequence":null,"server_hash":null,"server_timestamp":"1785122040230","session_id":"ff6d21c8283948938400a32613abec2c","source":"clob_market_ws"},"received_at":"2026-07-27T03:14:00.241558Z","record_id":"eddafe3db18484e8138c4fe5dbebd535ef5c711cfe8ddfe87ca1e8d56757888c","schema_fingerprint":"4aa3821a28b0b7c2400bc59aba4bcc0a76e971dadd19610d3ad38c768e124dc7","schema_version":"edge-lab-recorder.raw.v1","sequence":null,"source":"clob_market_ws"}
{"event_at":"2026-07-27T03:14:00.230000Z","event_fingerprint":"c64698d8da034a6043b24fa8e09f45490fa344498f9c9e9680ef2ce6011db3b1","payload":{"connection_id":"f95883f18d264834af91809e5f803e9f","event_at":"2026-07-27T03:14:00.230000Z","event_type":"price_change","frame_hash":"098dc5f84cd02f7b650fd26e2e30838f5fdf4a08ce217d0bb04d5ab627099d7b","frame_index":0,"kind":"data","monotonic_ns":224023578111791,"payload":{"event_type":"price_change","market":"0xf9d60bb033695053c4d1d8592e52171c1042f64b41a4b72e09dcc6f4852b6670","price_changes":[{"asset_id":"8698449539441374295770236407991735029336433231649246775082939325523552031992","best_ask":"0.87","best_bid":"0.86","hash":"f406e908fe6e921a29c086eb2889300ac45d349e","price":"0.48","side":"BUY","size":"42"},{"asset_id":"96283536366176669581486355171583722558858323126916278856549586825357358273536","best_ask":"0.14","best_bid":"0.13","hash":"5528fca8c5a9096db6b3eac6f68967119fdddf37","price":"0.52","side":"SELL","size":"42"}],"timestamp":"1785122040230"},"payload_hash":"2e88e571a3fe5475740b45d72bef689168ee928f2972b30274a21a43f9f19d3b","raw_frame":"{\"market\":\"0xf9d60bb033695053c4d1d8592e52171c1042f64b41a4b72e09dcc6f4852b6670\", \"price_changes\":[{\"asset_id\":\"8698449539441374295770236407991735029336433231649246775082939325523552031992\", \"price\":\"0.48\", \"size\":\"42\", \"side\":\"BUY\", \"hash\":\"f406e908fe6e921a29c086eb2889300ac45d349e\", \"best_bid\":\"0.86\", \"best_ask\":\"0.87\"}, {\"asset_id\":\"96283536366176669581486355171583722558858323126916278856549586825357358273536\", \"price\":\"0.52\", \"size\":\"42\", \"side\":\"SELL\", \"hash\":\"5528fca8c5a9096db6b3eac6f68967119fdddf37\", \"best_bid\":\"0.13\", \"best_ask\":\"0.14\"}], \"timestamp\":\"1785122040230\", \"event_type\":\"price_change\"}","received_at":"2026-07-27T03:14:00.245285Z","schema_version":"clob-market-ws.price_change.v1","sequence":null,"server_hash":null,"server_timestamp":"1785122040230","session_id":"ff6d21c8283948938400a32613abec2c","source":"clob_market_ws"},"received_at":"2026-07-27T03:14:00.245285Z","record_id":"bbc9e70d2e50f0adbcad4d02e16e419992fc19ed8831060d4d48a9f2264e1c79","schema_fingerprint":"4aa3821a28b0b7c2400bc59aba4bcc0a76e971dadd19610d3ad38c768e124dc7","schema_version":"edge-lab-recorder.raw.v1","sequence":null,"source":"clob_market_ws"}
{"event_at":"2026-07-27T03:14:00.230000Z","event_fingerprint":"49879f7a88300b473836b78887ff3d201b1ead79300b5b1079b07e49764a9798","payload":{"connection_id":"f95883f18d264834af91809e5f803e9f","event_at":"2026-07-27T03:14:00.230000Z","event_type":"price_change","frame_hash":"5b7744983644f337ff5f4d78971ad1716c6dedb8e2b0614b09b71691aa82a092","frame_index":0,"kind":"data","monotonic_ns":224023580047833,"payload":{"event_type":"price_change","market":"0xf9d60bb033695053c4d1d8592e52171c1042f64b41a4b72e09dcc6f4852b6670","price_changes":[{"asset_id":"8698449539441374295770236407991735029336433231649246775082939325523552031992","best_ask":"0.87","best_bid":"0.86","hash":"514f3ef6fcbbfbf4a2153f5eac4b1945d6b352f8","price":"0.72","side":"BUY","size":"52"},{"asset_id":"96283536366176669581486355171583722558858323126916278856549586825357358273536","best_ask":"0.14","best_bid":"0.13","hash":"08e9fe872ad2e25a15e4a13c631e983435996823","price":"0.28","side":"SELL","size":"52"}],"timestamp":"1785122040230"},"payload_hash":"d34a13c5da726a94258d49bc49258ec43ce1f430250a1bba3347cf112ea53ee6","raw_frame":"{\"market\":\"0xf9d60bb033695053c4d1d8592e52171c1042f64b41a4b72e09dcc6f4852b6670\", \"price_changes\":[{\"asset_id\":\"8698449539441374295770236407991735029336433231649246775082939325523552031992\", \"price\":\"0.72\", \"size\":\"52\", \"side\":\"BUY\", \"hash\":\"514f3ef6fcbbfbf4a2153f5eac4b1945d6b352f8\", \"best_bid\":\"0.86\", \"best_ask\":\"0.87\"}, {\"asset_id\":\"96283536366176669581486355171583722558858323126916278856549586825357358273536\", \"price\":\"0.28\", \"size\":\"52\", \"side\":\"SELL\", \"hash\":\"08e9fe872ad2e25a15e4a13c631e983435996823\", \"best_bid\":\"0.13\", \"best_ask\":\"0.14\"}], \"timestamp\":\"1785122040230\", \"event_type\":\"price_change\"}","received_at":"2026-07-27T03:14:00.247228Z","schema_version":"clob-market-ws.price_change.v1","sequence":null,"server_hash":null,"server_timestamp":"1785122040230","session_id":"ff6d21c8283948938400a32613abec2c","source":"clob_market_ws"},"received_at":"2026-07-27T03:14:00.247228Z","record_id":"97f2add5f3004711ce21274d311dccf7599f6d8871e8fa10da91ac86fe3af8a5","schema_fingerprint":"4aa3821a28b0b7c2400bc59aba4bcc0a76e971dadd19610d3ad38c768e124dc7","schema_version":"edge-lab-recorder.raw.v1","sequence":null,"source":"clob_market_ws"}
{"event_at":"2026-07-27T03:14:00.230000Z","event_fingerprint":"4f4a368b4fe648e62fe26d0c91de0ce2994012a2f228ba2258bf1b72cedc4e91","payload":{"connection_id":"f95883f18d264834af91809e5f803e9f","event_at":"2026-07-27T03:14:00.230000Z","event_type":"price_change","frame_hash":"4c62b4a763a3d47a0b2ac925fb2b1e71b31e34411bacf0587e724906cd51c63d","frame_index":0,"kind":"data","monotonic_ns":224023582142625,"payload":{"event_type":"price_change","market":"0xf9d60bb033695053c4d1d8592e52171c1042f64b41a4b72e09dcc6f4852b6670","price_changes":[{"asset_id":"8698449539441374295770236407991735029336433231649246775082939325523552031992","best_ask":"0.87","best_bid":"0.86","hash":"6e93db57b5eb4e85d0762fbcedca23bd02132b80","price":"0.6","side":"BUY","size":"43.7"},{"asset_id":"96283536366176669581486355171583722558858323126916278856549586825357358273536","best_ask":"0.14","best_bid":"0.13","hash":"f388ca92b29b2bf1cf1d1787d3a35e91b4fd8bcf","price":"0.4","side":"SELL","size":"43.7"}],"timestamp":"1785122040230"},"payload_hash":"ee0bfa18f187a50d71b1f25c967e3f4a9b7e255b92befdfefbde09232894ec17","raw_frame":"{\"market\":\"0xf9d60bb033695053c4d1d8592e52171c1042f64b41a4b72e09dcc6f4852b6670\", \"price_changes\":[{\"asset_id\":\"8698449539441374295770236407991735029336433231649246775082939325523552031992\", \"price\":\"0.6\", \"size\":\"43.7\", \"side\":\"BUY\", \"hash\":\"6e93db57b5eb4e85d0762fbcedca23bd02132b80\", \"best_bid\":\"0.86\", \"best_ask\":\"0.87\"}, {\"asset_id\":\"96283536366176669581486355171583722558858323126916278856549586825357358273536\", \"price\":\"0.4\", \"size\":\"43.7\", \"side\":\"SELL\", \"hash\":\"f388ca92b29b2bf1cf1d1787d3a35e91b4fd8bcf\", \"best_bid\":\"0.13\", \"best_ask\":\"0.14\"}], \"timestamp\":\"1785122040230\", \"event_type\":\"price_change\"}","received_at":"2026-07-27T03:14:00.249316Z","schema_version":"clob-market-ws.price_change.v1","sequence":null,"server_hash":null,"server_timestamp":"1785122040230","session_id":"ff6d21c8283948938400a32613abec2c","source":"clob_market_ws"},"received_at":"2026-07-27T03:14:00.249316Z","record_id":"d4b2b2351af8be7363b3d48235607869e9295522743176814e06876cbe49123a","schema_fingerprint":"4aa3821a28b0b7c2400bc59aba4bcc0a76e971dadd19610d3ad38c768e124dc7","schema_version":"edge-lab-recorder.raw.v1","sequence":null,"source":"clob_market_ws"}
{"event_at":"2026-07-27T03:14:00.230000Z","event_fingerprint":"4601947cc277d994fa759a347325828ebc29594a58beb2e93ea85e964f2e0d2d","payload":{"connection_id":"f95883f18d264834af91809e5f803e9f","event_at":"2026-07-27T03:14:00.230000Z","event_type":"price_change","frame_hash":"bd429121c54bac6a0dcf86a8045de0ba6e44e729d7d5bb03729d4bd859deed59","frame_index":0,"kind":"data","monotonic_ns":224023585759708,"payload":{"event_type":"price_change","market":"0xf9d60bb033695053c4d1d8592e52171c1042f64b41a4b72e09dcc6f4852b6670","price_changes":[{"asset_id":"8698449539441374295770236407991735029336433231649246775082939325523552031992","best_ask":"0.87","best_bid":"0.86","hash":"4c9869d2e28bb1f1c9d2b89bd970f923638586b3","price":"0.55","side":"BUY","size":"72.5"},{"asset_id":"96283536366176669581486355171583722558858323126916278856549586825357358273536","best_ask":"0.14","best_bid":"0.13","hash":"6885591d1bb5170184543777a2f4638244267ce6","price":"0.45","side":"SELL","size":"72.5"}],"timestamp":"1785122040230"},"payload_hash":"90c4611b5cac3c4236512884c8ebec8e1df3d31fa52fc605a12b24eb263fbacf","raw_frame":"{\"market\":\"0xf9d60bb033695053c4d1d8592e52171c1042f64b41a4b72e09dcc6f4852b6670\", \"price_changes\":[{\"asset_id\":\"8698449539441374295770236407991735029336433231649246775082939325523552031992\", \"price\":\"0.55\", \"size\":\"72.5\", \"side\":\"BUY\", \"hash\":\"4c9869d2e28bb1f1c9d2b89bd970f923638586b3\", \"best_bid\":\"0.86\", \"best_ask\":\"0.87\"}, {\"asset_id\":\"96283536366176669581486355171583722558858323126916278856549586825357358273536\", \"price\":\"0.45\", \"size\":\"72.5\", \"side\":\"SELL\", \"hash\":\"6885591d1bb5170184543777a2f4638244267ce6\", \"best_bid\":\"0.13\", \"best_ask\":\"0.14\"}], \"timestamp\":\"1785122040230\", \"event_type\":\"price_change\"}","received_at":"2026-07-27T03:14:00.252933Z","schema_version":"clob-market-ws.price_change.v1","sequence":null,"server_hash":null,"server_timestamp":"1785122040230","session_id":"ff6d21c8283948938400a32613abec2c","source":"clob_market_ws"},"received_at":"2026-07-27T03:14:00.252933Z","record_id":"73fa7c3765a02dbacfa42b5263b820eb48b298d3961ac4aa7a96ed79e66a62b0","schema_fingerprint":"4aa3821a28b0b7c2400bc59aba4bcc0a76e971dadd19610d3ad38c768e124dc7","schema_version":"edge-lab-recorder.raw.v1","sequence":null,"source":"clob_market_ws"}
{"event_at":"2026-07-27T03:14:00.230000Z","event_fingerprint":"9b9b6d2b4c76ab6d6f967e0a7e6e32a415287b2a782b8e7ddab2ce2925535a33","payload":{"connection_id":"f95883f18d264834af91809e5f803e9f","event_at":"2026-07-27T03:14:00.230000Z","event_type":"price_change","frame_hash":"cb4fd8fa3f3fcb82abf6483529aaf693993afcbfeb24b43e2d554da7936b9d05","frame_index":0,"kind":"data","monotonic_ns":224023588800750,"payload":{"event_type":"price_change","market":"0xf9d60bb033695053c4d1d8592e52171c1042f64b41a4b72e09dcc6f4852b6670","price_changes":[{"asset_id":"8698449539441374295770236407991735029336433231649246775082939325523552031992","best_ask":"0.87","best_bid":"0.86","hash":"161e825f183244900b7acdf5ef4b3907531e5ff4","price":"0.46","side":"BUY","size":"72.3"},{"asset_id":"96283536366176669581486355171583722558858323126916278856549586825357358273536","best_ask":"0.14","best_bid":"0.13","hash":"0042db569bffc3b7e2c69fd5dc2e23fe39872fe3","price":"0.54","side":"SELL","size":"72.3"}],"timestamp":"1785122040230"},"payload_hash":"8c14c549ca0bdcf522c70b5ad2dd40dbfda9598c4ba7c78424507e11c718c28e","raw_frame":"{\"market\":\"0xf9d60bb033695053c4d1d8592e52171c1042f64b41a4b72e09dcc6f4852b6670\", \"price_changes\":[{\"asset_id\":\"8698449539441374295770236407991735029336433231649246775082939325523552031992\", \"price\":\"0.46\", \"size\":\"72.3\", \"side\":\"BUY\", \"hash\":\"161e825f183244900b7acdf5ef4b3907531e5ff4\", \"best_bid\":\"0.86\", \"best_ask\":\"0.87\"}, {\"asset_id\":\"96283536366176669581486355171583722558858323126916278856549586825357358273536\", \"price\":\"0.54\", \"size\":\"72.3\", \"side\":\"SELL\", \"hash\":\"0042db569bffc3b7e2c69fd5dc2e23fe39872fe3\", \"best_bid\":\"0.13\", \"best_ask\":\"0.14\"}], \"timestamp\":\"1785122040230\", \"event_type\":\"price_change\"}","received_at":"2026-07-27T03:14:00.255974Z","schema_version":"clob-market-ws.price_change.v1","sequence":null,"server_hash":null,"server_timestamp":"1785122040230","session_id":"ff6d21c8283948938400a32613abec2c","source":"clob_market_ws"},"received_at":"2026-07-27T03:14:00.255974Z","record_id":"efb4acff762eced5e8ab5c798cb1ae3ff13b7dec4187c075a5d84855f160a011","schema_fingerprint":"4aa3821a28b0b7c2400bc59aba4bcc0a76e971dadd19610d3ad38c768e124dc7","schema_version":"edge-lab-recorder.raw.v1","sequence":null,"source":"clob_market_ws"}
{"event_at":"2026-07-27T03:14:00.230000Z","event_fingerprint":"cf26ec9083548a5cb77e0d90972f12e980ad3d51f251195cbf7d2258df0c60cf","payload":{"connection_id":"f95883f18d264834af91809e5f803e9f","event_at":"2026-07-27T03:14:00.230000Z","event_type":"price_change","frame_hash":"189f91bd15f94d4ec270e7477ef3c33d6d10f58cfd6262c669ebd10e49f2b0c1","frame_index":0,"kind":"data","monotonic_ns":224023591746916,"payload":{"event_type":"price_change","market":"0xf9d60bb033695053c4d1d8592e52171c1042f64b41a4b72e09dcc6f4852b6670","price_changes":[{"asset_id":"96283536366176669581486355171583722558858323126916278856549586825357358273536","best_ask":"0.14","best_bid":"0.13","hash":"08deda2ffc61489a7377562c0c421dc9d1bc2228","price":"0.08","side":"BUY","size":"164.5"},{"asset_id":"8698449539441374295770236407991735029336433231649246775082939325523552031992","best_ask":"0.87","best_bid":"0.86","hash":"ca2d19c44dbf7b7ec900bcd465f92d89887252e1","price":"0.92","side":"SELL","size":"164.5"}],"timestamp":"1785122040230"},"payload_hash":"f5e5a9ca5bc1335c4da5985eeb67f124b4d330e98df58d93f4f1bc7adb4eef9b","raw_frame":"{\"market\":\"0xf9d60bb033695053c4d1d8592e52171c1042f64b41a4b72e09dcc6f4852b6670\", \"price_changes\":[{\"asset_id\":\"96283536366176669581486355171583722558858323126916278856549586825357358273536\", \"price\":\"0.08\", \"size\":\"164.5\", \"side\":\"BUY\", \"hash\":\"08deda2ffc61489a7377562c0c421dc9d1bc2228\", \"best_bid\":\"0.13\", \"best_ask\":\"0.14\"}, {\"asset_id\":\"8698449539441374295770236407991735029336433231649246775082939325523552031992\", \"price\":\"0.92\", \"size\":\"164.5\", \"side\":\"SELL\", \"hash\":\"ca2d19c44dbf7b7ec900bcd465f92d89887252e1\", \"best_bid\":\"0.86\", \"best_ask\":\"0.87\"}], \"timestamp\":\"1785122040230\", \"event_type\":\"price_change\"}","received_at":"2026-07-27T03:14:00.258921Z","schema_version":"clob-market-ws.price_change.v1","sequence":null,"server_hash":null,"server_timestamp":"1785122040230","session_id":"ff6d21c8283948938400a32613abec2c","source":"clob_market_ws"},"received_at":"2026-07-27T03:14:00.258921Z","record_id":"12b0fb9bb25593dbfc3cc90ebdae9209806e5c22a8fa5e4cf2fabe43ff06daac","schema_fingerprint":"4aa3821a28b0b7c2400bc59aba4bcc0a76e971dadd19610d3ad38c768e124dc7","schema_version":"edge-lab-recorder.raw.v1","sequence":null,"source":"clob_market_ws"}
{"event_at":"2026-07-27T03:14:00.230000Z","event_fingerprint":"fab91d6c1c1dd6626aac212a517e35e8f36b6c0c600feecf76ebe935a3d9da18","payload":{"connection_id":"f95883f18d264834af91809e5f803e9f","event_at":"2026-07-27T03:14:00.230000Z","event_type":"price_change","frame_hash":"e82610e3c0796b11eaa0c5c49f177b64a8ab989200cc89516adc240e5345ddf1","frame_index":0,"kind":"data","monotonic_ns":224023594635041,"payload":{"event_type":"price_change","market":"0xf9d60bb033695053c4d1d8592e52171c1042f64b41a4b72e09dcc6f4852b6670","price_changes":[{"asset_id":"8698449539441374295770236407991735029336433231649246775082939325523552031992","best_ask":"0.87","best_bid":"0.86","hash":"acade5b930fe85a781d29b302882d6fe44928f38","price":"0.41","side":"BUY","size":"55.3"},{"asset_id":"96283536366176669581486355171583722558858323126916278856549586825357358273536","best_ask":"0.14","best_bid":"0.13","hash":"5b85836b15313d0d4487ec90fd6181a1f2a5a73b","price":"0.59","side":"SELL","size":"55.3"}],"timestamp":"1785122040230"},"payload_hash":"ba3d0e27f5c3f44ab1268b6b29f75677bed00dea9fbfbb1f29bed15355df9c61","raw_frame":"{\"market\":\"0xf9d60bb033695053c4d1d8592e52171c1042f64b41a4b72e09dcc6f4852b6670\", \"price_changes\":[{\"asset_id\":\"8698449539441374295770236407991735029336433231649246775082939325523552031992\", \"price\":\"0.41\", \"size\":\"55.3\", \"side\":\"BUY\", \"hash\":\"acade5b930fe85a781d29b302882d6fe44928f38\", \"best_bid\":\"0.86\", \"best_ask\":\"0.87\"}, {\"asset_id\":\"96283536366176669581486355171583722558858323126916278856549586825357358273536\", \"price\":\"0.59\", \"size\":\"55.3\", \"side\":\"SELL\", \"hash\":\"5b85836b15313d0d4487ec90fd6181a1f2a5a73b\", \"best_bid\":\"0.13\", \"best_ask\":\"0.14\"}], \"timestamp\":\"1785122040230\", \"event_type\":\"price_change\"}","received_at":"2026-07-27T03:14:00.261806Z","schema_version":"clob-market-ws.price_change.v1","sequence":null,"server_hash":null,"server_timestamp":"1785122040230","session_id":"ff6d21c8283948938400a32613abec2c","source":"clob_market_ws"},"received_at":"2026-07-27T03:14:00.261806Z","record_id":"6b120a5993c59914e1c3c1908cc3419c395b4662941526216c38cf5a1eb27e32","schema_fingerprint":"4aa3821a28b0b7c2400bc59aba4bcc0a76e971dadd19610d3ad38c768e124dc7","schema_version":"edge-lab-recorder.raw.v1","sequence":null,"source":"clob_market_ws"}
{"event_at":"2026-07-27T03:14:00.230000Z","event_fingerprint":"1061bdfc92363a258ec77d6e926394c549aed276d7bad236cee95ce9d710f20f","payload":{"connection_id":"f95883f18d264834af91809e5f803e9f","event_at":"2026-07-27T03:14:00.230000Z","event_type":"price_change","frame_hash":"66de73771aadb30331cd5774e1de64a8a3e35026a09742a8a470f0db2426f40b","frame_index":0,"kind":"data","monotonic_ns":224023596901125,"payload":{"event_type":"price_change","market":"0xf9d60bb033695053c4d1d8592e52171c1042f64b41a4b72e09dcc6f4852b6670","price_changes":[{"asset_id":"8698449539441374295770236407991735029336433231649246775082939325523552031992","best_ask":"0.87","best_bid":"0.86","hash":"a60155a433146b04a0975530f4cccf6f32666f25","price":"0.59","side":"BUY","size":"43.3"},{"asset_id":"96283536366176669581486355171583722558858323126916278856549586825357358273536","best_ask":"0.14","best_bid":"0.13","hash":"aaf63263523d2eeb5961d3206c3942b3efd467e7","price":"0.41","side":"SELL","size":"43.3"}],"timestamp":"1785122040230"},"payload_hash":"9a0bba950055be326ec1a0a2da06837025b63e4afca7986d766facb01d61d973","raw_frame":"{\"market\":\"0xf9d60bb033695053c4d1d8592e52171c1042f64b41a4b72e09dcc6f4852b6670\", \"price_changes\":[{\"asset_id\":\"8698449539441374295770236407991735029336433231649246775082939325523552031992\", \"price\":\"0.59\", \"size\":\"43.3\", \"side\":\"BUY\", \"hash\":\"a60155a433146b04a0975530f4cccf6f32666f25\", \"best_bid\":\"0.86\", \"best_ask\":\"0.87\"}, {\"asset_id\":\"96283536366176669581486355171583722558858323126916278856549586825357358273536\", \"price\":\"0.41\", \"size\":\"43.3\", \"side\":\"SELL\", \"hash\":\"aaf63263523d2eeb5961d3206c3942b3efd467e7\", \"best_bid\":\"0.13\", \"best_ask\":\"0.14\"}], \"timestamp\":\"1785122040230\", \"event_type\":\"price_change\"}","received_at":"2026-07-27T03:14:00.264080Z","schema_version":"clob-market-ws.price_change.v1","sequence":null,"server_hash":null,"server_timestamp":"1785122040230","session_id":"ff6d21c8283948938400a32613abec2c","source":"clob_market_ws"},"received_at":"2026-07-27T03:14:00.264080Z","record_id":"6426fbc27abe5f0c9d0631523c175fade99935f7958388edbf8b05baa041328a","schema_fingerprint":"4aa3821a28b0b7c2400bc59aba4bcc0a76e971dadd19610d3ad38c768e124dc7","schema_version":"edge-lab-recorder.raw.v1","sequence":null,"source":"clob_market_ws"}
{"event_at":"2026-07-27T03:14:00.230000Z","event_fingerprint":"9ecf2de01aa11e85472e1caee6cd5d14c8170fea2c3679d00a8550e142fba8d3","payload":{"connection_id":"f95883f18d264834af91809e5f803e9f","event_at":"2026-07-27T03:14:00.230000Z","event_type":"price_change","frame_hash":"ced5293360bdfea89b3c723a006f8547f45adadfcdb6a496832186ab6a0bc814","frame_index":0,"kind":"data","monotonic_ns":224023598947041,"payload":{"event_type":"price_change","market":"0xf9d60bb033695053c4d1d8592e52171c1042f64b41a4b72e09dcc6f4852b6670","price_changes":[{"asset_id":"8698449539441374295770236407991735029336433231649246775082939325523552031992","best_ask":"0.87","best_bid":"0.86","hash":"201418833472eb0c44b19f981cb30e2eb8e1275e","price":"0.62","side":"BUY","size":"44.6"},{"asset_id":"96283536366176669581486355171583722558858323126916278856549586825357358273536","best_ask":"0.14","best_bid":"0.13","hash":"813b058b42fc3bfadfe8a5a5b88ac39b74cf094d","price":"0.38","side":"SELL","size":"44.6"}],"timestamp":"1785122040230"},"payload_hash":"3cc5103d297c7399e45ba0cd384f22408d6ee9344f2a3fcd51b37c9a8728ccbe","raw_frame":"{\"market\":\"0xf9d60bb033695053c4d1d8592e52171c1042f64b41a4b72e09dcc6f4852b6670\", \"price_changes\":[{\"asset_id\":\"8698449539441374295770236407991735029336433231649246775082939325523552031992\", \"price\":\"0.62\", \"size\":\"44.6\", \"side\":\"BUY\", \"hash\":\"201418833472eb0c44b19f981cb30e2eb8e1275e\", \"best_bid\":\"0.86\", \"best_ask\":\"0.87\"}, {\"asset_id\":\"96283536366176669581486355171583722558858323126916278856549586825357358273536\", \"price\":\"0.38\", \"size\":\"44.6\", \"side\":\"SELL\", \"hash\":\"813b058b42fc3bfadfe8a5a5b88ac39b74cf094d\", \"best_bid\":\"0.13\", \"best_ask\":\"0.14\"}], \"timestamp\":\"1785122040230\", \"event_type\":\"price_change\"}","received_at":"2026-07-27T03:14:00.266119Z","schema_version":"clob-market-ws.price_change.v1","sequence":null,"server_hash":null,"server_timestamp":"1785122040230","session_id":"ff6d21c8283948938400a32613abec2c","source":"clob_market_ws"},"received_at":"2026-07-27T03:14:00.266119Z","record_id":"1eed7b594ff27196e4aacd49a41235a54f36e1ad18ca5546bfdabdaa9082b609","schema_fingerprint":"4aa3821a28b0b7c2400bc59aba4bcc0a76e971dadd19610d3ad38c768e124dc7","schema_version":"edge-lab-recorder.raw.v1","sequence":null,"source":"clob_market_ws"}
{"event_at":"2026-07-27T03:14:00.231000Z","event_fingerprint":"93d14819b54ca7a82d8458779c43b9091f0c751da541093f369b0d75470042e4","payload":{"connection_id":"f95883f18d264834af91809e5f803e9f","event_at":"2026-07-27T03:14:00.231000Z","event_type":"price_change","frame_hash":"f7d4d48796035b3694a6cb6f9970f7640b96fd501dde5c740cecedc782692911","frame_index":0,"kind":"data","monotonic_ns":224023601977333,"payload":{"event_type":"price_change","market":"0xf9d60bb033695053c4d1d8592e52171c1042f64b41a4b72e09dcc6f4852b6670","price_changes":[{"asset_id":"8698449539441374295770236407991735029336433231649246775082939325523552031992","best_ask":"0.87","best_bid":"0.86","hash":"80b77795781f085cfaed63c29de7cd9fd174d803","price":"0.38","side":"BUY","size":"57.6"},{"asset_id":"96283536366176669581486355171583722558858323126916278856549586825357358273536","best_ask":"0.14","best_bid":"0.13","hash":"52ef792706cf0f7ceda2789d40e47ca49afea21f","price":"0.62","side":"SELL","size":"57.6"}],"timestamp":"1785122040231"},"payload_hash":"ff2164173b0ea002f4ce4b478202f8e0ad099dd1d504cc969a847b5961ffbba2","raw_frame":"{\"market\":\"0xf9d60bb033695053c4d1d8592e52171c1042f64b41a4b72e09dcc6f4852b6670\", \"price_changes\":[{\"asset_id\":\"8698449539441374295770236407991735029336433231649246775082939325523552031992\", \"price\":\"0.38\", \"size\":\"57.6\", \"side\":\"BUY\", \"hash\":\"80b77795781f085cfaed63c29de7cd9fd174d803\", \"best_bid\":\"0.86\", \"best_ask\":\"0.87\"}, {\"asset_id\":\"96283536366176669581486355171583722558858323126916278856549586825357358273536\", \"price\":\"0.62\", \"size\":\"57.6\", \"side\":\"SELL\", \"hash\":\"52ef792706cf0f7ceda2789d40e47ca49afea21f\", \"best_bid\":\"0.13\", \"best_ask\":\"0.14\"}], \"timestamp\":\"1785122040231\", \"event_type\":\"price_change\"}","received_at":"2026-07-27T03:14:00.269145Z","schema_version":"clob-market-ws.price_change.v1","sequence":null,"server_hash":null,"server_timestamp":"1785122040231","session_id":"ff6d21c8283948938400a32613abec2c","source":"clob_market_ws"},"received_at":"2026-07-27T03:14:00.269145Z","record_id":"2c9e5f9dbb6dbcb262cb5869e997dbba6983199e27b53c64a91ae2d1cdc6f10c","schema_fingerprint":"4aa3821a28b0b7c2400bc59aba4bcc0a76e971dadd19610d3ad38c768e124dc7","schema_version":"edge-lab-recorder.raw.v1","sequence":null,"source":"clob_market_ws"}
{"event_at":"2026-07-27T03:14:00.231000Z","event_fingerprint":"c65d889ceb07cae72c7a8f9e2e386811bec38f5fedad0dcd6262b01505061aac","payload":{"connection_id":"f95883f18d264834af91809e5f803e9f","event_at":"2026-07-27T03:14:00.231000Z","event_type":"price_change","frame_hash":"31255339439a04f05ae10692ba8d99cc38577c1e19cb146bbd0203756ca3e8a2","frame_index":0,"kind":"data","monotonic_ns":224023604476541,"payload":{"event_type":"price_change","market":"0xf9d60bb033695053c4d1d8592e52171c1042f64b41a4b72e09dcc6f4852b6670","price_changes":[{"asset_id":"8698449539441374295770236407991735029336433231649246775082939325523552031992","best_ask":"0.87","best_bid":"0.86","hash":"1d7c9a3bf09cb3a7bbe7c1f3fa6a35f145c26123","price":"0.71","side":"BUY","size":"50.88"},{"asset_id":"96283536366176669581486355171583722558858323126916278856549586825357358273536","best_ask":"0.14","best_bid":"0.13","hash":"60f08e08d436baeabdd3342538a50a8ec8634b46","price":"0.29","side":"SELL","size":"50.88"}],"timestamp":"1785122040231"},"payload_hash":"13b00cc066deab9b7e1305ae255143ac8de157c0002f4af5956c3f7e57a98b7b","raw_frame":"{\"market\":\"0xf9d60bb033695053c4d1d8592e52171c1042f64b41a4b72e09dcc6f4852b6670\", \"price_changes\":[{\"asset_id\":\"8698449539441374295770236407991735029336433231649246775082939325523552031992\", \"price\":\"0.71\", \"size\":\"50.88\", \"side\":\"BUY\", \"hash\":\"1d7c9a3bf09cb3a7bbe7c1f3fa6a35f145c26123\", \"best_bid\":\"0.86\", \"best_ask\":\"0.87\"}, {\"asset_id\":\"96283536366176669581486355171583722558858323126916278856549586825357358273536\", \"price\":\"0.29\", \"size\":\"50.88\", \"side\":\"SELL\", \"hash\":\"60f08e08d436baeabdd3342538a50a8ec8634b46\", \"best_bid\":\"0.13\", \"best_ask\":\"0.14\"}], \"timestamp\":\"1785122040231\", \"event_type\":\"price_change\"}","received_at":"2026-07-27T03:14:00.271651Z","schema_version":"clob-market-ws.price_change.v1","sequence":null,"server_hash":null,"server_timestamp":"1785122040231","session_id":"ff6d21c8283948938400a32613abec2c","source":"clob_market_ws"},"received_at":"2026-07-27T03:14:00.271651Z","record_id":"b878fc3a4bdbf0c5b95231d5bcd4f54e8520cff515711c3a49ba591940ff6da3","schema_fingerprint":"4aa3821a28b0b7c2400bc59aba4bcc0a76e971dadd19610d3ad38c768e124dc7","schema_version":"edge-lab-recorder.raw.v1","sequence":null,"source":"clob_market_ws"}
{"event_at":"2026-07-27T03:14:00.231000Z","event_fingerprint":"e1729dafe2e0128d9ea995dad35a07c230a2c7d519834a021c06b8eebadc2372","payload":{"connection_id":"f95883f18d264834af91809e5f803e9f","event_at":"2026-07-27T03:14:00.231000Z","event_type":"price_change","frame_hash":"37fe5d0e1fd5acb2fa48b959f6014b7d6869419c8b21d98ee6b108ea021b2c2a","frame_index":0,"kind":"data","monotonic_ns":224023609063416,"payload":{"event_type":"price_change","market":"0xf9d60bb033695053c4d1d8592e52171c1042f64b41a4b72e09dcc6f4852b6670","price_changes":[{"asset_id":"8698449539441374295770236407991735029336433231649246775082939325523552031992","best_ask":"0.87","best_bid":"0.86","hash":"37438c1953359ff76af1aefaf592577f669a11c3","price":"0.77","side":"BUY","size":"59.3"},{"asset_id":"96283536366176669581486355171583722558858323126916278856549586825357358273536","best_ask":"0.14","best_bid":"0.13","hash":"d98b76cf32fe38f9c469137e6da2b92716ab9076","price":"0.23","side":"SELL","size":"59.3"}],"timestamp":"1785122040231"},"payload_hash":"562240abfdca7f8aa5c56bd741f58592250f55c9b83680e2d13bf45324b83993","raw_frame":"{\"market\":\"0xf9d60bb033695053c4d1d8592e52171c1042f64b41a4b72e09dcc6f4852b6670\", \"price_changes\":[{\"asset_id\":\"8698449539441374295770236407991735029336433231649246775082939325523552031992\", \"price\":\"0.77\", \"size\":\"59.3\", \"side\":\"BUY\", \"hash\":\"37438c1953359ff76af1aefaf592577f669a11c3\", \"best_bid\":\"0.86\", \"best_ask\":\"0.87\"}, {\"asset_id\":\"96283536366176669581486355171583722558858323126916278856549586825357358273536\", \"price\":\"0.23\", \"size\":\"59.3\", \"side\":\"SELL\", \"hash\":\"d98b76cf32fe38f9c469137e6da2b92716ab9076\", \"best_bid\":\"0.13\", \"best_ask\":\"0.14\"}], \"timestamp\":\"1785122040231\", \"event_type\":\"price_change\"}","received_at":"2026-07-27T03:14:00.276237Z","schema_version":"clob-market-ws.price_change.v1","sequence":null,"server_hash":null,"server_timestamp":"1785122040231","session_id":"ff6d21c8283948938400a32613abec2c","source":"clob_market_ws"},"received_at":"2026-07-27T03:14:00.276237Z","record_id":"4021ded5bd37d248a09c7130ac44697e3efbab1c25564ee34f26ffe72dfde951","schema_fingerprint":"4aa3821a28b0b7c2400bc59aba4bcc0a76e971dadd19610d3ad38c768e124dc7","schema_version":"edge-lab-recorder.raw.v1","sequence":null,"source":"clob_market_ws"}
{"event_at":"2026-07-27T03:14:00.231000Z","event_fingerprint":"d6e88f7d4dadedef677e62b17fe541a57dbb2dfb9e284b4c26a8458ce6122b20","payload":{"connection_id":"f95883f18d264834af91809e5f803e9f","event_at":"2026-07-27T03:14:00.231000Z","event_type":"price_change","frame_hash":"a9bc7bf4f59804ff3789b9d14c421992fd03d0ae10a3f6b0353c13b825ff46bd","frame_index":0,"kind":"data","monotonic_ns":224023613550166,"payload":{"event_type":"price_change","market":"0xf9d60bb033695053c4d1d8592e52171c1042f64b41a4b72e09dcc6f4852b6670","price_changes":[{"asset_id":"8698449539441374295770236407991735029336433231649246775082939325523552031992","best_ask":"0.87","best_bid":"0.86","hash":"1b40507bbc1586e9c8fa0a1067391749da465092","price":"0.56","side":"BUY","size":"54.6"},{"asset_id":"96283536366176669581486355171583722558858323126916278856549586825357358273536","best_ask":"0.14","best_bid":"0.13","hash":"319168916e9ebdc4db79dfb748a9ac2615f056d1","price":"0.44","side":"SELL","size":"54.6"}],"timestamp":"1785122040231"},"payload_hash":"5c17d7bf7c1054f7dc9f4ff724f5dbaac7927d0a851109711014e6a254d3eee0","raw_frame":"{\"market\":\"0xf9d60bb033695053c4d1d8592e52171c1042f64b41a4b72e09dcc6f4852b6670\", \"price_changes\":[{\"asset_id\":\"8698449539441374295770236407991735029336433231649246775082939325523552031992\", \"price\":\"0.56\", \"size\":\"54.6\", \"side\":\"BUY\", \"hash\":\"1b40507bbc1586e9c8fa0a1067391749da465092\", \"best_bid\":\"0.86\", \"best_ask\":\"0.87\"}, {\"asset_id\":\"96283536366176669581486355171583722558858323126916278856549586825357358273536\", \"price\":\"0.44\", \"size\":\"54.6\", \"side\":\"SELL\", \"hash\":\"319168916e9ebdc4db79dfb748a9ac2615f056d1\", \"best_bid\":\"0.13\", \"best_ask\":\"0.14\"}], \"timestamp\":\"1785122040231\", \"event_type\":\"price_change\"}","received_at":"2026-07-27T03:14:00.280729Z","schema_version":"clob-market-ws.price_change.v1","sequence":null,"server_hash":null,"server_timestamp":"1785122040231","session_id":"ff6d21c8283948938400a32613abec2c","source":"clob_market_ws"},"received_at":"2026-07-27T03:14:00.280729Z","record_id":"47e251cca2fcaa454b385baba4f7f10a836fdab458e6939a5a0c6dec786fc702","schema_fingerprint":"4aa3821a28b0b7c2400bc59aba4bcc0a76e971dadd19610d3ad38c768e124dc7","schema_version":"edge-lab-recorder.raw.v1","sequence":null,"source":"clob_market_ws"}
{"event_at":"2026-07-27T03:14:00.231000Z","event_fingerprint":"cbec31ba360fd1558f8a56f5f238807b533414746fb4a1772855da916dde9f3f","payload":{"connection_id":"f95883f18d264834af91809e5f803e9f","event_at":"2026-07-27T03:14:00.231000Z","event_type":"price_change","frame_hash":"9a582995a1aed93c533bfc7c577c79b2146ff5683b0cdb716a4b138e52b5f411","frame_index":0,"kind":"data","monotonic_ns":224023617279583,"payload":{"event_type":"price_change","market":"0xf9d60bb033695053c4d1d8592e52171c1042f64b41a4b72e09dcc6f4852b6670","price_changes":[{"asset_id":"8698449539441374295770236407991735029336433231649246775082939325523552031992","best_ask":"0.87","best_bid":"0.86","hash":"d6af7775cbd53250cffeaf27575ecaa96f270e7d","price":"0.76","side":"BUY","size":"87.6"},{"asset_id":"96283536366176669581486355171583722558858323126916278856549586825357358273536","best_ask":"0.14","best_bid":"0.13","hash":"88772e2514972fa98a26656b0194a25b4e4eadd7","price":"0.24","side":"SELL","size":"87.6"}],"timestamp":"1785122040231"},"payload_hash":"2f670bdccb0dc7db36fa5c5fa806d0ec67ada211af69f01d657462ddfde968f1","raw_frame":"{\"market\":\"0xf9d60bb033695053c4d1d8592e52171c1042f64b41a4b72e09dcc6f4852b6670\", \"price_changes\":[{\"asset_id\":\"8698449539441374295770236407991735029336433231649246775082939325523552031992\", \"price\":\"0.76\", \"size\":\"87.6\", \"side\":\"BUY\", \"hash\":\"d6af7775cbd53250cffeaf27575ecaa96f270e7d\", \"best_bid\":\"0.86\", \"best_ask\":\"0.87\"}, {\"asset_id\":\"96283536366176669581486355171583722558858323126916278856549586825357358273536\", \"price\":\"0.24\", \"size\":\"87.6\", \"side\":\"SELL\", \"hash\":\"88772e2514972fa98a26656b0194a25b4e4eadd7\", \"best_bid\":\"0.13\", \"best_ask\":\"0.14\"}], \"timestamp\":\"1785122040231\", \"event_type\":\"price_change\"}","received_at":"2026-07-27T03:14:00.284452Z","schema_version":"clob-market-ws.price_change.v1","sequence":null,"server_hash":null,"server_timestamp":"1785122040231","session_id":"ff6d21c8283948938400a32613abec2c","source":"clob_market_ws"},"received_at":"2026-07-27T03:14:00.284452Z","record_id":"a1dd70cde6634fffebc32562ef791b6dfa1c8f05b3ddec649c096adcee79304f","schema_fingerprint":"4aa3821a28b0b7c2400bc59aba4bcc0a76e971dadd19610d3ad38c768e124dc7","schema_version":"edge-lab-recorder.raw.v1","sequence":null,"source":"clob_market_ws"}
{"event_at":"2026-07-27T03:14:00.231000Z","event_fingerprint":"8bc18ce827e835081f894306c44839950a6b9aedf04f559c9660d99ce0999fe5","payload":{"connection_id":"f95883f18d264834af91809e5f803e9f","event_at":"2026-07-27T03:14:00.231000Z","event_type":"price_change","frame_hash":"97132017c204c8da1db802488350176dd21dfbc41cbe268f55167eb5a7cd174b","frame_index":0,"kind":"data","monotonic_ns":224023619986833,"payload":{"event_type":"price_change","market":"0xf9d60bb033695053c4d1d8592e52171c1042f64b41a4b72e09dcc6f4852b6670","price_changes":[{"asset_id":"96283536366176669581486355171583722558858323126916278856549586825357358273536","best_ask":"0.14","best_bid":"0.13","hash":"9452140cae15594ce953fd6f7a1bdb2ab7cc71cc","price":"0.11","side":"BUY","size":"75"},{"asset_id":"8698449539441374295770236407991735029336433231649246775082939325523552031992","best_ask":"0.87","best_bid":"0.86","hash":"56f73d2197c618bee698c59cfe35ea0ad224346f","price":"0.89","side":"SELL","size":"75"}],"timestamp":"1785122040231"},"payload_hash":"bc610278a9bade88291ab315df9eed5a415a227bec40538db481fe499ab82293","raw_frame":"{\"market\":\"0xf9d60bb033695053c4d1d8592e52171c1042f64b41a4b72e09dcc6f4852b6670\", \"price_changes\":[{\"asset_id\":\"96283536366176669581486355171583722558858323126916278856549586825357358273536\", \"price\":\"0.11\", \"size\":\"75\", \"side\":\"BUY\", \"hash\":\"9452140cae15594ce953fd6f7a1bdb2ab7cc71cc\", \"best_bid\":\"0.13\", \"best_ask\":\"0.14\"}, {\"asset_id\":\"8698449539441374295770236407991735029336433231649246775082939325523552031992\", \"price\":\"0.89\", \"size\":\"75\", \"side\":\"SELL\", \"hash\":\"56f73d2197c618bee698c59cfe35ea0ad224346f\", \"best_bid\":\"0.86\", \"best_ask\":\"0.87\"}], \"timestamp\":\"1785122040231\", \"event_type\":\"price_change\"}","received_at":"2026-07-27T03:14:00.287157Z","schema_version":"clob-market-ws.price_change.v1","sequence":null,"server_hash":null,"server_timestamp":"1785122040231","session_id":"ff6d21c8283948938400a32613abec2c","source":"clob_market_ws"},"received_at":"2026-07-27T03:14:00.287157Z","record_id":"e29a5b8ae33ae83affc85197f48f9627f93c4acb1154264371d3f24173c5fd45","schema_fingerprint":"4aa3821a28b0b7c2400bc59aba4bcc0a76e971dadd19610d3ad38c768e124dc7","schema_version":"edge-lab-recorder.raw.v1","sequence":null,"source":"clob_market_ws"}
{"event_at":"2026-07-27T03:14:00.231000Z","event_fingerprint":"5ce88abd3db7f5bc73c1d3d697fbc9289ba3ce90898981a4868feba01a595834","payload":{"connection_id":"f95883f18d264834af91809e5f803e9f","event_at":"2026-07-27T03:14:00.231000Z","event_type":"price_change","frame_hash":"2f357e232a63526f0d2258912ea86b82f0899a0ce034e9e65f354b9137f5f202","frame_index":0,"kind":"data","monotonic_ns":224023622486666,"payload":{"event_type":"price_change","market":"0xf9d60bb033695053c4d1d8592e52171c1042f64b41a4b72e09dcc6f4852b6670","price_changes":[{"asset_id":"8698449539441374295770236407991735029336433231649246775082939325523552031992","best_ask":"0.87","best_bid":"0.86","hash":"e423deb0daf64d360b3975efccb31d87805e84cb","price":"0.43","side":"BUY","size":"84.8"},{"asset_id":"96283536366176669581486355171583722558858323126916278856549586825357358273536","best_ask":"0.14","best_bid":"0.13","hash":"f3ec0a37e1244bba40fbe276795267b5fc3d2986","price":"0.57","side":"SELL","size":"84.8"}],"timestamp":"1785122040231"},"payload_hash":"000b775665de9663b96685d95a452f4237cdc0e1eaac18cb57acb783eacfe29f","raw_frame":"{\"market\":\"0xf9d60bb033695053c4d1d8592e52171c1042f64b41a4b72e09dcc6f4852b6670\", \"price_changes\":[{\"asset_id\":\"8698449539441374295770236407991735029336433231649246775082939325523552031992\", \"price\":\"0.43\", \"size\":\"84.8\", \"side\":\"BUY\", \"hash\":\"e423deb0daf64d360b3975efccb31d87805e84cb\", \"best_bid\":\"0.86\", \"best_ask\":\"0.87\"}, {\"asset_id\":\"96283536366176669581486355171583722558858323126916278856549586825357358273536\", \"price\":\"0.57\", \"size\":\"84.8\", \"side\":\"SELL\", \"hash\":\"f3ec0a37e1244bba40fbe276795267b5fc3d2986\", \"best_bid\":\"0.13\", \"best_ask\":\"0.14\"}], \"timestamp\":\"1785122040231\", \"event_type\":\"price_change\"}","received_at":"2026-07-27T03:14:00.289657Z","schema_version":"clob-market-ws.price_change.v1","sequence":null,"server_hash":null,"server_timestamp":"1785122040231","session_id":"ff6d21c8283948938400a32613abec2c","source":"clob_market_ws"},"received_at":"2026-07-27T03:14:00.289657Z","record_id":"a2e7f64acb983e20af21bf7e9a6c199d79c673451ae638264fc27a4999fd3ece","schema_fingerprint":"4aa3821a28b0b7c2400bc59aba4bcc0a76e971dadd19610d3ad38c768e124dc7","schema_version":"edge-lab-recorder.raw.v1","sequence":null,"source":"clob_market_ws"}
{"event_at":"2026-07-27T03:14:00.232000Z","event_fingerprint":"ce60df73c3afff858e1c60bac32e2a406bbf92fb139ab59d2adab2f478c92511","payload":{"connection_id":"f95883f18d264834af91809e5f803e9f","event_at":"2026-07-27T03:14:00.232000Z","event_type":"price_change","frame_hash":"6f0165d7f51c6adefb97d84c3a0353316be766d4918bfa51c61c01de476b0a64","frame_index":0,"kind":"data","monotonic_ns":224023628240833,"payload":{"event_type":"price_change","market":"0xf9d60bb033695053c4d1d8592e52171c1042f64b41a4b72e09dcc6f4852b6670","price_changes":[{"asset_id":"8698449539441374295770236407991735029336433231649246775082939325523552031992","best_ask":"0.87","best_bid":"0.86","hash":"3ea9c099a39c78bdf3a5c607e47b97bfe762bf3e","price":"0.69","side":"BUY","size":"49.1"},{"asset_id":"96283536366176669581486355171583722558858323126916278856549586825357358273536","best_ask":"0.14","best_bid":"0.13","hash":"e9f538ab3dcbb4819a528310f5cf63913e9d1f2a","price":"0.31","side":"SELL","size":"49.1"}],"timestamp":"1785122040232"},"payload_hash":"92708b195e0ffc309f170a3d856c2fbe4b592355d6a89cfa314b766ebbd03713","raw_frame":"{\"market\":\"0xf9d60bb033695053c4d1d8592e52171c1042f64b41a4b72e09dcc6f4852b6670\", \"price_changes\":[{\"asset_id\":\"8698449539441374295770236407991735029336433231649246775082939325523552031992\", \"price\":\"0.69\", \"size\":\"49.1\", \"side\":\"BUY\", \"hash\":\"3ea9c099a39c78bdf3a5c607e47b97bfe762bf3e\", \"best_bid\":\"0.86\", \"best_ask\":\"0.87\"}, {\"asset_id\":\"96283536366176669581486355171583722558858323126916278856549586825357358273536\", \"price\":\"0.31\", \"size\":\"49.1\", \"side\":\"SELL\", \"hash\":\"e9f538ab3dcbb4819a528310f5cf63913e9d1f2a\", \"best_bid\":\"0.13\", \"best_ask\":\"0.14\"}], \"timestamp\":\"1785122040232\", \"event_type\":\"price_change\"}","received_at":"2026-07-27T03:14:00.295414Z","schema_version":"clob-market-ws.price_change.v1","sequence":null,"server_hash":null,"server_timestamp":"1785122040232","session_id":"ff6d21c8283948938400a32613abec2c","source":"clob_market_ws"},"received_at":"2026-07-27T03:14:00.295414Z","record_id":"7e30a899ced274e58a0c6f746e8cb1a00966daf4d0e7639e964bb9fcb85989d1","schema_fingerprint":"4aa3821a28b0b7c2400bc59aba4bcc0a76e971dadd19610d3ad38c768e124dc7","schema_version":"edge-lab-recorder.raw.v1","sequence":null,"source":"clob_market_ws"}
{"event_at":"2026-07-27T03:14:00.232000Z","event_fingerprint":"d64dab2a16e05ddaa30c45bbfd3c06a5cc148b0c679007a030d247ecd0e32ac6","payload":{"connection_id":"f95883f18d264834af91809e5f803e9f","event_at":"2026-07-27T03:14:00.232000Z","event_type":"price_change","frame_hash":"ae0e3d91da5710404e6b7b817a0c63b88ce3a42b09ca9d36a52335d2d2471d02","frame_index":0,"kind":"data","monotonic_ns":224023631664916,"payload":{"event_type":"price_change","market":"0xf9d60bb033695053c4d1d8592e52171c1042f64b41a4b72e09dcc6f4852b6670","price_changes":[{"asset_id":"8698449539441374295770236407991735029336433231649246775082939325523552031992","best_ask":"0.87","best_bid":"0.86","hash":"82e84a9c2b92ad8e287b48e32005871a512ccd3b","price":"0.58","side":"BUY","size":"73.09"},{"asset_id":"96283536366176669581486355171583722558858323126916278856549586825357358273536","best_ask":"0.14","best_bid":"0.13","hash":"0651390a7ea6d0f7bd8d1b7d263be725b6cde795","price":"0.42","side":"SELL","size":"73.09"}],"timestamp":"1785122040232"},"payload_hash":"55553befd7ecbc4342ea7ccc518ca9b200229b975aed0b1818d1cfbb259ffd8a","raw_frame":"{\"market\":\"0xf9d60bb033695053c4d1d8592e52171c1042f64b41a4b72e09dcc6f4852b6670\", \"price_changes\":[{\"asset_id\":\"8698449539441374295770236407991735029336433231649246775082939325523552031992\", \"price\":\"0.58\", \"size\":\"73.09\", \"side\":\"BUY\", \"hash\":\"82e84a9c2b92ad8e287b48e32005871a512ccd3b\", \"best_bid\":\"0.86\", \"best_ask\":\"0.87\"}, {\"asset_id\":\"96283536366176669581486355171583722558858323126916278856549586825357358273536\", \"price\":\"0.42\", \"size\":\"73.09\", \"side\":\"SELL\", \"hash\":\"0651390a7ea6d0f7bd8d1b7d263be725b6cde795\", \"best_bid\":\"0.13\", \"best_ask\":\"0.14\"}], \"timestamp\":\"1785122040232\", \"event_type\":\"price_change\"}","received_at":"2026-07-27T03:14:00.298837Z","schema_version":"clob-market-ws.price_change.v1","sequence":null,"server_hash":null,"server_timestamp":"1785122040232","session_id":"ff6d21c8283948938400a32613abec2c","source":"clob_market_ws"},"received_at":"2026-07-27T03:14:00.298837Z","record_id":"49a67dfd66a26b64dbcfae857f51391645b8c5e4f3e5126511c4e291d6e3905e","schema_fingerprint":"4aa3821a28b0b7c2400bc59aba4bcc0a76e971dadd19610d3ad38c768e124dc7","schema_version":"edge-lab-recorder.raw.v1","sequence":null,"source":"clob_market_ws"}
{"event_at":"2026-07-27T03:14:00.232000Z","event_fingerprint":"5ea712223538e451b65899ea6209d18300c51bee8a90427b7dfeb50e045d6422","payload":{"connection_id":"f95883f18d264834af91809e5f803e9f","event_at":"2026-07-27T03:14:00.232000Z","event_type":"price_change","frame_hash":"677ea25fff12318e56b617272c99f69f686069cb398d0b86412e3dd2f81278fe","frame_index":0,"kind":"data","monotonic_ns":224023636152208,"payload":{"event_type":"price_change","market":"0xf9d60bb033695053c4d1d8592e52171c1042f64b41a4b72e09dcc6f4852b6670","price_changes":[{"asset_id":"8698449539441374295770236407991735029336433231649246775082939325523552031992","best_ask":"0.87","best_bid":"0.86","hash":"df482eba249bf68603c93ab11a6de5386b2b6901","price":"0.73","side":"BUY","size":"83.3"},{"asset_id":"96283536366176669581486355171583722558858323126916278856549586825357358273536","best_ask":"0.14","best_bid":"0.13","hash":"bcc657588feb34e62455124c18b8ba0ace0dfcc9","price":"0.27","side":"SELL","size":"83.3"}],"timestamp":"1785122040232"},"payload_hash":"0db8743eb8a548a2939e2c308ea92dfe655a96b4e260e9a122b1a3c74225fb99","raw_frame":"{\"market\":\"0xf9d60bb033695053c4d1d8592e52171c1042f64b41a4b72e09dcc6f4852b6670\", \"price_changes\":[{\"asset_id\":\"8698449539441374295770236407991735029336433231649246775082939325523552031992\", \"price\":\"0.73\", \"size\":\"83.3\", \"side\":\"BUY\", \"hash\":\"df482eba249bf68603c93ab11a6de5386b2b6901\", \"best_bid\":\"0.86\", \"best_ask\":\"0.87\"}, {\"asset_id\":\"96283536366176669581486355171583722558858323126916278856549586825357358273536\", \"price\":\"0.27\", \"size\":\"83.3\", \"side\":\"SELL\", \"hash\":\"bcc657588feb34e62455124c18b8ba0ace0dfcc9\", \"best_bid\":\"0.13\", \"best_ask\":\"0.14\"}], \"timestamp\":\"1785122040232\", \"event_type\":\"price_change\"}","received_at":"2026-07-27T03:14:00.303325Z","schema_version":"clob-market-ws.price_change.v1","sequence":null,"server_hash":null,"server_timestamp":"1785122040232","session_id":"ff6d21c8283948938400a32613abec2c","source":"clob_market_ws"},"received_at":"2026-07-27T03:14:00.303325Z","record_id":"ebf85df921baf3435a37bd8d0202994ff02b6d7affb5e1819f959099560a2d13","schema_fingerprint":"4aa3821a28b0b7c2400bc59aba4bcc0a76e971dadd19610d3ad38c768e124dc7","schema_version":"edge-lab-recorder.raw.v1","sequence":null,"source":"clob_market_ws"}
{"event_at":"2026-07-27T03:14:00.232000Z","event_fingerprint":"0e34625ffc93f3e4a086698c3b16edc69abc73630a8d4db24630f83bff8181cd","payload":{"connection_id":"f95883f18d264834af91809e5f803e9f","event_at":"2026-07-27T03:14:00.232000Z","event_type":"price_change","frame_hash":"79ba0b996363cf71b1caf5483b7f47499865f4a709bfd7400438524017fda016","frame_index":0,"kind":"data","monotonic_ns":224023640543625,"payload":{"event_type":"price_change","market":"0xf9d60bb033695053c4d1d8592e52171c1042f64b41a4b72e09dcc6f4852b6670","price_changes":[{"asset_id":"8698449539441374295770236407991735029336433231649246775082939325523552031992","best_ask":"0.87","best_bid":"0.86","hash":"82d5b9802f3fc00221155586b332cb2b7058893f","price":"0.61","side":"BUY","size":"74.09"},{"asset_id":"96283536366176669581486355171583722558858323126916278856549586825357358273536","best_ask":"0.14","best_bid":"0.13","hash":"b9b15b7291f3db432c9f423c967ac6487f2a7c73","price":"0.39","side":"SELL","size":"74.09"}],"timestamp":"1785122040232"},"payload_hash":"7d62bf4d97dd1d3f769675ae625568b87c5bd50ae4d90966d62b0ae9a6c4eb96","raw_frame":"{\"market\":\"0xf9d60bb033695053c4d1d8592e52171c1042f64b41a4b72e09dcc6f4852b6670\", \"price_changes\":[{\"asset_id\":\"8698449539441374295770236407991735029336433231649246775082939325523552031992\", \"price\":\"0.61\", \"size\":\"74.09\", \"side\":\"BUY\", \"hash\":\"82d5b9802f3fc00221155586b332cb2b7058893f\", \"best_bid\":\"0.86\", \"best_ask\":\"0.87\"}, {\"asset_id\":\"96283536366176669581486355171583722558858323126916278856549586825357358273536\", \"price\":\"0.39\", \"size\":\"74.09\", \"side\":\"SELL\", \"hash\":\"b9b15b7291f3db432c9f423c967ac6487f2a7c73\", \"best_bid\":\"0.13\", \"best_ask\":\"0.14\"}], \"timestamp\":\"1785122040232\", \"event_type\":\"price_change\"}","received_at":"2026-07-27T03:14:00.307717Z","schema_version":"clob-market-ws.price_change.v1","sequence":null,"server_hash":null,"server_timestamp":"1785122040232","session_id":"ff6d21c8283948938400a32613abec2c","source":"clob_market_ws"},"received_at":"2026-07-27T03:14:00.307717Z","record_id":"7bd0ac118ce47f3db3361bbf260bab8d6b072adac513a45ea37269c73715e287","schema_fingerprint":"4aa3821a28b0b7c2400bc59aba4bcc0a76e971dadd19610d3ad38c768e124dc7","schema_version":"edge-lab-recorder.raw.v1","sequence":null,"source":"clob_market_ws"}
{"event_at":"2026-07-27T03:14:00.232000Z","event_fingerprint":"791e7b26d6853f9fc4f86789b6a1c677867878bc0e9d722f977989dfd964c0c2","payload":{"connection_id":"f95883f18d264834af91809e5f803e9f","event_at":"2026-07-27T03:14:00.232000Z","event_type":"price_change","frame_hash":"e8ffc6db246be3246633cd69c9bb8865ca3ccaf5686e2dec587414e4ec3da292","frame_index":0,"kind":"data","monotonic_ns":224023644995916,"payload":{"event_type":"price_change","market":"0xf9d60bb033695053c4d1d8592e52171c1042f64b41a4b72e09dcc6f4852b6670","price_changes":[{"asset_id":"8698449539441374295770236407991735029336433231649246775082939325523552031992","best_ask":"0.87","best_bid":"0.86","hash":"38dbb7f958d1ee4055494f6691bfffb6de11a24b","price":"0.44","side":"BUY","size":"42.6"},{"asset_id":"96283536366176669581486355171583722558858323126916278856549586825357358273536","best_ask":"0.14","best_bid":"0.13","hash":"9a31f28c37a14e561936386099b6b0d11e377f2e","price":"0.56","side":"SELL","size":"42.6"}],"timestamp":"1785122040232"},"payload_hash":"70d43738bc041ab3c8a66898052f6ad0454fdb555aa4b7ca4359f156fd3fee9a","raw_frame":"{\"market\":\"0xf9d60bb033695053c4d1d8592e52171c1042f64b41a4b72e09dcc6f4852b6670\", \"price_changes\":[{\"asset_id\":\"8698449539441374295770236407991735029336433231649246775082939325523552031992\", \"price\":\"0.44\", \"size\":\"42.6\", \"side\":\"BUY\", \"hash\":\"38dbb7f958d1ee4055494f6691bfffb6de11a24b\", \"best_bid\":\"0.86\", \"best_ask\":\"0.87\"}, {\"asset_id\":\"96283536366176669581486355171583722558858323126916278856549586825357358273536\", \"price\":\"0.56\", \"size\":\"42.6\", \"side\":\"SELL\", \"hash\":\"9a31f28c37a14e561936386099b6b0d11e377f2e\", \"best_bid\":\"0.13\", \"best_ask\":\"0.14\"}], \"timestamp\":\"1785122040232\", \"event_type\":\"price_change\"}","received_at":"2026-07-27T03:14:00.312169Z","schema_version":"clob-market-ws.price_change.v1","sequence":null,"server_hash":null,"server_timestamp":"1785122040232","session_id":"ff6d21c8283948938400a32613abec2c","source":"clob_market_ws"},"received_at":"2026-07-27T03:14:00.312169Z","record_id":"c51a13a4eec09e113ab62e375ee3d3937a9828e5675df37074d1a709139529a5","schema_fingerprint":"4aa3821a28b0b7c2400bc59aba4bcc0a76e971dadd19610d3ad38c768e124dc7","schema_version":"edge-lab-recorder.raw.v1","sequence":null,"source":"clob_market_ws"}
