{"event_at":"2026-07-27T03:14:00.232000Z","event_fingerprint":"f8221438fb1bcaaad33416a9947d9cf95433a448015a6277cae456d9cfea07e8","payload":{"connection_id":"f95883f18d264834af91809e5f803e9f","event_at":"2026-07-27T03:14:00.232000Z","event_type":"price_change","frame_hash":"03000e9d1fc075c6b15f91978b9402362564756964e35d8e849fcdf0c475d244","frame_index":0,"kind":"data","monotonic_ns":224023679469041,"payload":{"event_type":"price_change","market":"0xf9d60bb033695053c4d1d8592e52171c1042f64b41a4b72e09dcc6f4852b6670","price_changes":[{"asset_id":"8698449539441374295770236407991735029336433231649246775082939325523552031992","best_ask":"0.87","best_bid":"0.86","hash":"d4ee2a7f95ca76fa29bcc45a86a98571eb2e42d7","price":"0.42","side":"BUY","size":"43.09"},{"asset_id":"96283536366176669581486355171583722558858323126916278856549586825357358273536","best_ask":"0.14","best_bid":"0.13","hash":"6c8839001c883698c13bcd8d9dbf5a410dc3c58e","price":"0.58","side":"SELL","size":"43.09"}],"timestamp":"1785122040232"},"payload_hash":"db8aa5d270d9851e9d220ef4a7529dbae7814d6776f329dc3a2072612d995ea2","raw_frame":"{\"market\":\"0xf9d60bb033695053c4d1d8592e52171c1042f64b41a4b72e09dcc6f4852b6670\", \"price_changes\":[{\"asset_id\":\"8698449539441374295770236407991735029336433231649246775082939325523552031992\", \"price\":\"0.42\", \"size\":\"43.09\", \"side\":\"BUY\", \"hash\":\"d4ee2a7f95ca76fa29bcc45a86a98571eb2e42d7\", \"best_bid\":\"0.86\", \"best_ask\":\"0.87\"}, {\"asset_id\":\"96283536366176669581486355171583722558858323126916278856549586825357358273536\", \"price\":\"0.58\", \"size\":\"43.09\", \"side\":\"SELL\", \"hash\":\"6c8839001c883698c13bcd8d9dbf5a410dc3c58e\", \"best_bid\":\"0.13\", \"best_ask\":\"0.14\"}], \"timestamp\":\"1785122040232\", \"event_type\":\"price_change\"}","received_at":"2026-07-27T03:14:00.346647Z","schema_version":"clob-market-ws.price_change.v1","sequence":null,"server_hash":null,"server_timestamp":"1785122040232","session_id":"ff6d21c8283948938400a32613abec2c","source":"clob_market_ws"},"received_at":"2026-07-27T03:14:00.346647Z","record_id":"c1bc00df8c5b2fc40fdc78f4006e38458fa5e87f254748848a7cd7fd2643fff5","schema_fingerprint":"4aa3821a28b0b7c2400bc59aba4bcc0a76e971dadd19610d3ad38c768e124dc7","schema_version":"edge-lab-recorder.raw.v1","sequence":null,"source":"clob_market_ws"}
{"event_at":"2026-07-27T03:14:00.232000Z","event_fingerprint":"0ed37e135aa26b0dc269a4f98618b7ebccbc3c7e80dc835f490965ce08b2ad2d","payload":{"connection_id":"f95883f18d264834af91809e5f803e9f","event_at":"2026-07-27T03:14:00.232000Z","event_type":"price_change","frame_hash":"616b4993b61f07680e2ad6caef93d13c9d6df9299c188db89e255de77b405883","frame_index":0,"kind":"data","monotonic_ns":224023690168416,"payload":{"event_type":"price_change","market":"0xf9d60bb033695053c4d1d8592e52171c1042f64b41a4b72e09dcc6f4852b6670","price_changes":[{"asset_id":"96283536366176669581486355171583722558858323126916278856549586825357358273536","best_ask":"0.14","best_bid":"0.13","hash":"16515ff0776f54bac4b0469afc4c82597b052eb9","price":"0.1","side":"BUY","size":"58.3"},{"asset_id":"8698449539441374295770236407991735029336433231649246775082939325523552031992","best_ask":"0.87","best_bid":"0.86","hash":"ba0d3f14060067bf17e2926c3cfda0c26afa8e36","price":"0.9","side":"SELL","size":"58.3"}],"timestamp":"1785122040232"},"payload_hash":"0ea5331d1bf97d8662d849d313b252073eb49ea41b4f566aaa2160ef0a077f53","raw_frame":"{\"market\":\"0xf9d60bb033695053c4d1d8592e52171c1042f64b41a4b72e09dcc6f4852b6670\", \"price_changes\":[{\"asset_id\":\"96283536366176669581486355171583722558858323126916278856549586825357358273536\", \"price\":\"0.1\", \"size\":\"58.3\", \"side\":\"BUY\", \"hash\":\"16515ff0776f54bac4b0469afc4c82597b052eb9\", \"best_bid\":\"0.13\", \"best_ask\":\"0.14\"}, {\"asset_id\":\"8698449539441374295770236407991735029336433231649246775082939325523552031992\", \"price\":\"0.9\", \"size\":\"58.3\", \"side\":\"SELL\", \"hash\":\"ba0d3f14060067bf17e2926c3cfda0c26afa8e36\", \"best_bid\":\"0.86\", \"best_ask\":\"0.87\"}], \"timestamp\":\"1785122040232\", \"event_type\":\"price_change\"}","received_at":"2026-07-27T03:14:00.357341Z","schema_version":"clob-market-ws.price_change.v1","sequence":null,"server_hash":null,"server_timestamp":"1785122040232","session_id":"ff6d21c8283948938400a32613abec2c","source":"clob_market_ws"},"received_at":"2026-07-27T03:14:00.357341Z","record_id":"59d6c8d719767f388c59d712f64225b79a0c62b4bcbb0fdcc6183d3bc0d4ded3","schema_fingerprint":"4aa3821a28b0b7c2400bc59aba4bcc0a76e971dadd19610d3ad38c768e124dc7","schema_version":"edge-lab-recorder.raw.v1","sequence":null,"source":"clob_market_ws"}
{"event_at":"2026-07-27T03:14:00.232000Z","event_fingerprint":"0a96f5689348dc43aad918cab717d2e6e887dc5c2b10b314e2998d316ef718b2","payload":{"connection_id":"f95883f18d264834af91809e5f803e9f","event_at":"2026-07-27T03:14:00.232000Z","event_type":"price_change","frame_hash":"0ec216212f228c1644ccfa6fc834f17488a2cfa0c740f2bb7a624bdb2686700c","frame_index":0,"kind":"data","monotonic_ns":224023694204416,"payload":{"event_type":"price_change","market":"0xf9d60bb033695053c4d1d8592e52171c1042f64b41a4b72e09dcc6f4852b6670","price_changes":[{"asset_id":"8698449539441374295770236407991735029336433231649246775082939325523552031992","best_ask":"0.87","best_bid":"0.86","hash":"c075809209dce005da48a1259b966c88abaf2508","price":"0.74","side":"BUY","size":"54.6"},{"asset_id":"96283536366176669581486355171583722558858323126916278856549586825357358273536","best_ask":"0.14","best_bid":"0.13","hash":"e67f7a0ffd8a863c7ba258e4e248450494158b13","price":"0.26","side":"SELL","size":"54.6"}],"timestamp":"1785122040232"},"payload_hash":"3545f05a84e2431072a8f5a62805e8171f9b8af4c3373e7ec73a7d221dbf7c8a","raw_frame":"{\"market\":\"0xf9d60bb033695053c4d1d8592e52171c1042f64b41a4b72e09dcc6f4852b6670\", \"price_changes\":[{\"asset_id\":\"8698449539441374295770236407991735029336433231649246775082939325523552031992\", \"price\":\"0.74\", \"size\":\"54.6\", \"side\":\"BUY\", \"hash\":\"c075809209dce005da48a1259b966c88abaf2508\", \"best_bid\":\"0.86\", \"best_ask\":\"0.87\"}, {\"asset_id\":\"96283536366176669581486355171583722558858323126916278856549586825357358273536\", \"price\":\"0.26\", \"size\":\"54.6\", \"side\":\"SELL\", \"hash\":\"e67f7a0ffd8a863c7ba258e4e248450494158b13\", \"best_bid\":\"0.13\", \"best_ask\":\"0.14\"}], \"timestamp\":\"1785122040232\", \"event_type\":\"price_change\"}","received_at":"2026-07-27T03:14:00.361382Z","schema_version":"clob-market-ws.price_change.v1","sequence":null,"server_hash":null,"server_timestamp":"1785122040232","session_id":"ff6d21c8283948938400a32613abec2c","source":"clob_market_ws"},"received_at":"2026-07-27T03:14:00.361382Z","record_id":"c278a240382d983a483d510a4063471d0ded6b17fbdb05e3ad0ea57e411cf655","schema_fingerprint":"4aa3821a28b0b7c2400bc59aba4bcc0a76e971dadd19610d3ad38c768e124dc7","schema_version":"edge-lab-recorder.raw.v1","sequence":null,"source":"clob_market_ws"}
{"event_at":"2026-07-27T03:14:00.233000Z","event_fingerprint":"87540b24b053795d14a602fb0e1227c7cf0dcfb94bad1c963c17dde555fd25fe","payload":{"connection_id":"f95883f18d264834af91809e5f803e9f","event_at":"2026-07-27T03:14:00.233000Z","event_type":"price_change","frame_hash":"5f49e949d4fbe881671a7d2e36a53bb02a6279afe9e8acabbcb01c16ee15c41a","frame_index":0,"kind":"data","monotonic_ns":224023698639875,"payload":{"event_type":"price_change","market":"0xf9d60bb033695053c4d1d8592e52171c1042f64b41a4b72e09dcc6f4852b6670","price_changes":[{"asset_id":"96283536366176669581486355171583722558858323126916278856549586825357358273536","best_ask":"0.14","best_bid":"0.13","hash":"20663b8f0a98dbdb6abacbd1c5833f3403bd382f","price":"0.09","side":"BUY","size":"70.6"},{"asset_id":"8698449539441374295770236407991735029336433231649246775082939325523552031992","best_ask":"0.87","best_bid":"0.86","hash":"38b50830e90cfdfcb9712dd49ce8317c272e1547","price":"0.91","side":"SELL","size":"70.6"}],"timestamp":"1785122040233"},"payload_hash":"99042555c37afed6a97b72811f75f386d7d4cd12be9fe8f2e4e174269eddcfe8","raw_frame":"{\"market\":\"0xf9d60bb033695053c4d1d8592e52171c1042f64b41a4b72e09dcc6f4852b6670\", \"price_changes\":[{\"asset_id\":\"96283536366176669581486355171583722558858323126916278856549586825357358273536\", \"price\":\"0.09\", \"size\":\"70.6\", \"side\":\"BUY\", \"hash\":\"20663b8f0a98dbdb6abacbd1c5833f3403bd382f\", \"best_bid\":\"0.13\", \"best_ask\":\"0.14\"}, {\"asset_id\":\"8698449539441374295770236407991735029336433231649246775082939325523552031992\", \"price\":\"0.91\", \"size\":\"70.6\", \"side\":\"SELL\", \"hash\":\"38b50830e90cfdfcb9712dd49ce8317c272e1547\", \"best_bid\":\"0.86\", \"best_ask\":\"0.87\"}], \"timestamp\":\"1785122040233\", \"event_type\":\"price_change\"}","received_at":"2026-07-27T03:14:00.365812Z","schema_version":"clob-market-ws.price_change.v1","sequence":null,"server_hash":null,"server_timestamp":"1785122040233","session_id":"ff6d21c8283948938400a32613abec2c","source":"clob_market_ws"},"received_at":"2026-07-27T03:14:00.365812Z","record_id":"528d221e5c6ac9fabcffc0301cc414e72000b849c9ed9f58a2d83dc30a42a8b7","schema_fingerprint":"4aa3821a28b0b7c2400bc59aba4bcc0a76e971dadd19610d3ad38c768e124dc7","schema_version":"edge-lab-recorder.raw.v1","sequence":null,"source":"clob_market_ws"}
{"event_at":"2026-07-27T03:14:00.233000Z","event_fingerprint":"824ae6d31329570f2e246cdf5f314768b99cc07143e2db7903292d8537ef6f70","payload":{"connection_id":"f95883f18d264834af91809e5f803e9f","event_at":"2026-07-27T03:14:00.233000Z","event_type":"price_change","frame_hash":"d5e012ef66944883ddbe67d68c9f6bb0060a7865c3f78b4986cf4920a5030374","frame_index":0,"kind":"data","monotonic_ns":224023704352208,"payload":{"event_type":"price_change","market":"0xf9d60bb033695053c4d1d8592e52171c1042f64b41a4b72e09dcc6f4852b6670","price_changes":[{"asset_id":"8698449539441374295770236407991735029336433231649246775082939325523552031992","best_ask":"0.87","best_bid":"0.86","hash":"641857c38c9d54f62e32b7b831ef4e49ec06d982","price":"0.49","side":"BUY","size":"72"},{"asset_id":"96283536366176669581486355171583722558858323126916278856549586825357358273536","best_ask":"0.14","best_bid":"0.13","hash":"e41005ddab4f75cbae346e07b2f93c4d1e5b5b90","price":"0.51","side":"SELL","size":"72"}],"timestamp":"1785122040233"},"payload_hash":"4dbfcf8bf5a7deb56e03063268483e0db42914c8feebdbfed55fdf8f1b20b5f2","raw_frame":"{\"market\":\"0xf9d60bb033695053c4d1d8592e52171c1042f64b41a4b72e09dcc6f4852b6670\", \"price_changes\":[{\"asset_id\":\"8698449539441374295770236407991735029336433231649246775082939325523552031992\", \"price\":\"0.49\", \"size\":\"72\", \"side\":\"BUY\", \"hash\":\"641857c38c9d54f62e32b7b831ef4e49ec06d982\", \"best_bid\":\"0.86\", \"best_ask\":\"0.87\"}, {\"asset_id\":\"96283536366176669581486355171583722558858323126916278856549586825357358273536\", \"price\":\"0.51\", \"size\":\"72\", \"side\":\"SELL\", \"hash\":\"e41005ddab4f75cbae346e07b2f93c4d1e5b5b90\", \"best_bid\":\"0.13\", \"best_ask\":\"0.14\"}], \"timestamp\":\"1785122040233\", \"event_type\":\"price_change\"}","received_at":"2026-07-27T03:14:00.371521Z","schema_version":"clob-market-ws.price_change.v1","sequence":null,"server_hash":null,"server_timestamp":"1785122040233","session_id":"ff6d21c8283948938400a32613abec2c","source":"clob_market_ws"},"received_at":"2026-07-27T03:14:00.371521Z","record_id":"186c5574367d5ee3ea2544399ad6c3b3ca57a2af89f0440f2118156fbb70c0d8","schema_fingerprint":"4aa3821a28b0b7c2400bc59aba4bcc0a76e971dadd19610d3ad38c768e124dc7","schema_version":"edge-lab-recorder.raw.v1","sequence":null,"source":"clob_market_ws"}
{"event_at":"2026-07-27T03:14:00.234000Z","event_fingerprint":"e8702168e2b6780076486c2aca7ae4e0cc9792e10672dbf6975c1959391b790c","payload":{"connection_id":"f95883f18d264834af91809e5f803e9f","event_at":"2026-07-27T03:14:00.234000Z","event_type":"price_change","frame_hash":"99306511aae65bc05376098cfab2f788c903ed8592d552f7017275a6b60d92a4","frame_index":0,"kind":"data","monotonic_ns":224023713490541,"payload":{"event_type":"price_change","market":"0xf9d60bb033695053c4d1d8592e52171c1042f64b41a4b72e09dcc6f4852b6670","price_changes":[{"asset_id":"8698449539441374295770236407991735029336433231649246775082939325523552031992","best_ask":"0.87","best_bid":"0.86","hash":"639ae94e59b18a53e54e6bb67905e6bcbf043ef0","price":"0.51","side":"BUY","size":"42"},{"asset_id":"96283536366176669581486355171583722558858323126916278856549586825357358273536","best_ask":"0.14","best_bid":"0.13","hash":"af6fc18627f9c0599cadf80a1532c360ccd309cb","price":"0.49","side":"SELL","size":"42"}],"timestamp":"1785122040234"},"payload_hash":"fcf37317700f8ab7417ecd504c8b4baa5b9cadee822f6fc160ec61feadcebb54","raw_frame":"{\"market\":\"0xf9d60bb033695053c4d1d8592e52171c1042f64b41a4b72e09dcc6f4852b6670\", \"price_changes\":[{\"asset_id\":\"8698449539441374295770236407991735029336433231649246775082939325523552031992\", \"price\":\"0.51\", \"size\":\"42\", \"side\":\"BUY\", \"hash\":\"639ae94e59b18a53e54e6bb67905e6bcbf043ef0\", \"best_bid\":\"0.86\", \"best_ask\":\"0.87\"}, {\"asset_id\":\"96283536366176669581486355171583722558858323126916278856549586825357358273536\", \"price\":\"0.49\", \"size\":\"42\", \"side\":\"SELL\", \"hash\":\"af6fc18627f9c0599cadf80a1532c360ccd309cb\", \"best_bid\":\"0.13\", \"best_ask\":\"0.14\"}], \"timestamp\":\"1785122040234\", \"event_type\":\"price_change\"}","received_at":"2026-07-27T03:14:00.380669Z","schema_version":"clob-market-ws.price_change.v1","sequence":null,"server_hash":null,"server_timestamp":"1785122040234","session_id":"ff6d21c8283948938400a32613abec2c","source":"clob_market_ws"},"received_at":"2026-07-27T03:14:00.380669Z","record_id":"16f4b1011195de86128355f7267c2cccf7d1c62f6709302885b50195f2a62f49","schema_fingerprint":"4aa3821a28b0b7c2400bc59aba4bcc0a76e971dadd19610d3ad38c768e124dc7","schema_version":"edge-lab-recorder.raw.v1","sequence":null,"source":"clob_market_ws"}
{"event_at":"2026-07-27T03:14:00.236000Z","event_fingerprint":"62d0af739eaf0db8a00111ae23ba16099ce7bce35707ec78588bf86f5d830803","payload":{"connection_id":"f95883f18d264834af91809e5f803e9f","event_at":"2026-07-27T03:14:00.236000Z","event_type":"price_change","frame_hash":"3493c6b2822b3a9624e448ba16f9ca45f6c38b994d49319f9660c5fbeed42d20","frame_index":0,"kind":"data","monotonic_ns":224023718295250,"payload":{"event_type":"price_change","market":"0xf9d60bb033695053c4d1d8592e52171c1042f64b41a4b72e09dcc6f4852b6670","price_changes":[{"asset_id":"8698449539441374295770236407991735029336433231649246775082939325523552031992","best_ask":"0.87","best_bid":"0.86","hash":"1077c8713314da7a784c06ac328dcf0a154f1146","price":"0.5","side":"BUY","size":"54"},{"asset_id":"96283536366176669581486355171583722558858323126916278856549586825357358273536","best_ask":"0.14","best_bid":"0.13","hash":"cca80b553aec6ea6ad1bd1776dd1d958764f586b","price":"0.5","side":"SELL","size":"54"}],"timestamp":"1785122040236"},"payload_hash":"4158f84c7c906d27b3b1274a4607288673d5969e269ecdcbf47ba6509c585327","raw_frame":"{\"market\":\"0xf9d60bb033695053c4d1d8592e52171c1042f64b41a4b72e09dcc6f4852b6670\", \"price_changes\":[{\"asset_id\":\"8698449539441374295770236407991735029336433231649246775082939325523552031992\", \"price\":\"0.5\", \"size\":\"54\", \"side\":\"BUY\", \"hash\":\"1077c8713314da7a784c06ac328dcf0a154f1146\", \"best_bid\":\"0.86\", \"best_ask\":\"0.87\"}, {\"asset_id\":\"96283536366176669581486355171583722558858323126916278856549586825357358273536\", \"price\":\"0.5\", \"size\":\"54\", \"side\":\"SELL\", \"hash\":\"cca80b553aec6ea6ad1bd1776dd1d958764f586b\", \"best_bid\":\"0.13\", \"best_ask\":\"0.14\"}], \"timestamp\":\"1785122040236\", \"event_type\":\"price_change\"}","received_at":"2026-07-27T03:14:00.385466Z","schema_version":"clob-market-ws.price_change.v1","sequence":null,"server_hash":null,"server_timestamp":"1785122040236","session_id":"ff6d21c8283948938400a32613abec2c","source":"clob_market_ws"},"received_at":"2026-07-27T03:14:00.385466Z","record_id":"77bd1214ac26fd239d9bd217c2fe515bfb5999b195675129a9bc82e3489b963d","schema_fingerprint":"4aa3821a28b0b7c2400bc59aba4bcc0a76e971dadd19610d3ad38c768e124dc7","schema_version":"edge-lab-recorder.raw.v1","sequence":null,"source":"clob_market_ws"}
{"event_at":"2026-07-27T03:14:00.245000Z","event_fingerprint":"63edfe6d4edda89c1ce94cd29c49f33313ea7e76b83d6ee67bac64e81ae553bf","payload":{"connection_id":"f95883f18d264834af91809e5f803e9f","event_at":"2026-07-27T03:14:00.245000Z","event_type":"price_change","frame_hash":"a7544210d665f554a00e38932761882cf302da7d0b90313d72c1a12d53d59383","frame_index":0,"kind":"data","monotonic_ns":224023724798541,"payload":{"event_type":"price_change","market":"0xf9d60bb033695053c4d1d8592e52171c1042f64b41a4b72e09dcc6f4852b6670","price_changes":[{"asset_id":"96283536366176669581486355171583722558858323126916278856549586825357358273536","best_ask":"0.14","best_bid":"0.13","hash":"4520bd223f579321a2a357c691e8a59d883e0172","price":"0.01","side":"BUY","size":"6734.5"},{"asset_id":"8698449539441374295770236407991735029336433231649246775082939325523552031992","best_ask":"0.87","best_bid":"0.86","hash":"44f245c1516183bb17e29dd8ceb6ab2f8e937b41","price":"0.99","side":"SELL","size":"6734.5"}],"timestamp":"1785122040245"},"payload_hash":"d16eaa96f5c3ca75fc98752e81865a325a2657c535a63dbfe7229dcd28e5a65e","raw_frame":"{\"market\":\"0xf9d60bb033695053c4d1d8592e52171c1042f64b41a4b72e09dcc6f4852b6670\", \"price_changes\":[{\"asset_id\":\"96283536366176669581486355171583722558858323126916278856549586825357358273536\", \"price\":\"0.01\", \"size\":\"6734.5\", \"side\":\"BUY\", \"hash\":\"4520bd223f579321a2a357c691e8a59d883e0172\", \"best_bid\":\"0.13\", \"best_ask\":\"0.14\"}, {\"asset_id\":\"8698449539441374295770236407991735029336433231649246775082939325523552031992\", \"price\":\"0.99\", \"size\":\"6734.5\", \"side\":\"SELL\", \"hash\":\"44f245c1516183bb17e29dd8ceb6ab2f8e937b41\", \"best_bid\":\"0.86\", \"best_ask\":\"0.87\"}], \"timestamp\":\"1785122040245\", \"event_type\":\"price_change\"}","received_at":"2026-07-27T03:14:00.391966Z","schema_version":"clob-market-ws.price_change.v1","sequence":null,"server_hash":null,"server_timestamp":"1785122040245","session_id":"ff6d21c8283948938400a32613abec2c","source":"clob_market_ws"},"received_at":"2026-07-27T03:14:00.391966Z","record_id":"c494abdffd4857283032828bb5a94e8437769883336fd0b29022cd95e01cbaa8","schema_fingerprint":"4aa3821a28b0b7c2400bc59aba4bcc0a76e971dadd19610d3ad38c768e124dc7","schema_version":"edge-lab-recorder.raw.v1","sequence":null,"source":"clob_market_ws"}
{"event_at":"2026-07-27T03:14:00.247000Z","event_fingerprint":"66e3845d76cf8b997cad0bd39d1525cc2d057a5b390a361f42afc20fd02cf2b5","payload":{"connection_id":"f95883f18d264834af91809e5f803e9f","event_at":"2026-07-27T03:14:00.247000Z","event_type":"price_change","frame_hash":"91727c6dd5dea109d71d4c17db346c826d21d873b8bd5f0cd8af0c3c8faab3b6","frame_index":0,"kind":"data","monotonic_ns":224023730143708,"payload":{"event_type":"price_change","market":"0xf9d60bb033695053c4d1d8592e52171c1042f64b41a4b72e09dcc6f4852b6670","price_changes":[{"asset_id":"8698449539441374295770236407991735029336433231649246775082939325523552031992","best_ask":"0.87","best_bid":"0.86","hash":"9ce578c90c5f1310b268885b776aab35842f5292","price":"0.01","side":"BUY","size":"7617.5"},{"asset_id":"96283536366176669581486355171583722558858323126916278856549586825357358273536","best_ask":"0.14","best_bid":"0.13","hash":"073c217bd400653925a5bd9c44c2e8d14e66c04c","price":"0.99","side":"SELL","size":"7617.5"}],"timestamp":"1785122040247"},"payload_hash":"1578ab749570e31fffa4e12fea3c4b88f81a45f9ff24edc579b3e6cd7ab526a0","raw_frame":"{\"market\":\"0xf9d60bb033695053c4d1d8592e52171c1042f64b41a4b72e09dcc6f4852b6670\", \"price_changes\":[{\"asset_id\":\"8698449539441374295770236407991735029336433231649246775082939325523552031992\", \"price\":\"0.01\", \"size\":\"7617.5\", \"side\":\"BUY\", \"hash\":\"9ce578c90c5f1310b268885b776aab35842f5292\", \"best_bid\":\"0.86\", \"best_ask\":\"0.87\"}, {\"asset_id\":\"96283536366176669581486355171583722558858323126916278856549586825357358273536\", \"price\":\"0.99\", \"size\":\"7617.5\", \"side\":\"SELL\", \"hash\":\"073c217bd400653925a5bd9c44c2e8d14e66c04c\", \"best_bid\":\"0.13\", \"best_ask\":\"0.14\"}], \"timestamp\":\"1785122040247\", \"event_type\":\"price_change\"}","received_at":"2026-07-27T03:14:00.397321Z","schema_version":"clob-market-ws.price_change.v1","sequence":null,"server_hash":null,"server_timestamp":"1785122040247","session_id":"ff6d21c8283948938400a32613abec2c","source":"clob_market_ws"},"received_at":"2026-07-27T03:14:00.397321Z","record_id":"aaeb647e0d5e868261784c69fd9a42e6c2c9d6e7abfab4f0b1d02cfa461f2bc9","schema_fingerprint":"4aa3821a28b0b7c2400bc59aba4bcc0a76e971dadd19610d3ad38c768e124dc7","schema_version":"edge-lab-recorder.raw.v1","sequence":null,"source":"clob_market_ws"}
{"event_at":"2026-07-27T03:14:00.249000Z","event_fingerprint":"2da8a78632db5708f22bc628848e49f51b9582236c4634a8a8e60ca754d3acab","payload":{"connection_id":"f95883f18d264834af91809e5f803e9f","event_at":"2026-07-27T03:14:00.249000Z","event_type":"price_change","frame_hash":"bc2017ae0b93ca678e26697a591c0db629c61d7500a6e807a30eb709d1c7640d","frame_index":0,"kind":"data","monotonic_ns":224023734514083,"payload":{"event_type":"price_change","market":"0xf9d60bb033695053c4d1d8592e52171c1042f64b41a4b72e09dcc6f4852b6670","price_changes":[{"asset_id":"8698449539441374295770236407991735029336433231649246775082939325523552031992","best_ask":"0.87","best_bid":"0.86","hash":"aecfb96fcbab441c0967e8e6f35468c106ef159d","price":"0.01","side":"BUY","size":"7622.5"},{"asset_id":"96283536366176669581486355171583722558858323126916278856549586825357358273536","best_ask":"0.14","best_bid":"0.13","hash":"ec69df74b79f5b17fd8d1bd7cee3465a6c7f73db","price":"0.99","side":"SELL","size":"7622.5"}],"timestamp":"1785122040249"},"payload_hash":"b016a6f518fd320f4c310baac3bf60d32e3ce2b4f4ff6aa61910e7c24f04897a","raw_frame":"{\"market\":\"0xf9d60bb033695053c4d1d8592e52171c1042f64b41a4b72e09dcc6f4852b6670\", \"price_changes\":[{\"asset_id\":\"8698449539441374295770236407991735029336433231649246775082939325523552031992\", \"price\":\"0.01\", \"size\":\"7622.5\", \"side\":\"BUY\", \"hash\":\"aecfb96fcbab441c0967e8e6f35468c106ef159d\", \"best_bid\":\"0.86\", \"best_ask\":\"0.87\"}, {\"asset_id\":\"96283536366176669581486355171583722558858323126916278856549586825357358273536\", \"price\":\"0.99\", \"size\":\"7622.5\", \"side\":\"SELL\", \"hash\":\"ec69df74b79f5b17fd8d1bd7cee3465a6c7f73db\", \"best_bid\":\"0.13\", \"best_ask\":\"0.14\"}], \"timestamp\":\"1785122040249\", \"event_type\":\"price_change\"}","received_at":"2026-07-27T03:14:00.401684Z","schema_version":"clob-market-ws.price_change.v1","sequence":null,"server_hash":null,"server_timestamp":"1785122040249","session_id":"ff6d21c8283948938400a32613abec2c","source":"clob_market_ws"},"received_at":"2026-07-27T03:14:00.401684Z","record_id":"bee31bd2188f65d365a6123ffa92f6eedb5e9d3ba53fd785cf57c60756675a98","schema_fingerprint":"4aa3821a28b0b7c2400bc59aba4bcc0a76e971dadd19610d3ad38c768e124dc7","schema_version":"edge-lab-recorder.raw.v1","sequence":null,"source":"clob_market_ws"}
{"event_at":"2026-07-27T03:14:00.251000Z","event_fingerprint":"727c86a599a7abab09c4076a904e8b2357f9a7b81173b86d70642b6b815d01d8","payload":{"connection_id":"f95883f18d264834af91809e5f803e9f","event_at":"2026-07-27T03:14:00.251000Z","event_type":"price_change","frame_hash":"8aa407c6b9033fe152db403d424aee04b0db599875f30d8c9dca748b6cc31f39","frame_index":0,"kind":"data","monotonic_ns":224023738767916,"payload":{"event_type":"price_change","market":"0xf9d60bb033695053c4d1d8592e52171c1042f64b41a4b72e09dcc6f4852b6670","price_changes":[{"asset_id":"96283536366176669581486355171583722558858323126916278856549586825357358273536","best_ask":"0.14","best_bid":"0.13","hash":"def2a91cf945fca5323e8ed417472352efc2fe04","price":"0.01","side":"BUY","size":"6729.5"},{"asset_id":"8698449539441374295770236407991735029336433231649246775082939325523552031992","best_ask":"0.87","best_bid":"0.86","hash":"c031656cf6d1b9bbbf201af6448322b6436b4dac","price":"0.99","side":"SELL","size":"6729.5"}],"timestamp":"1785122040251"},"payload_hash":"3bf8e3b76d53c830fb6811fb5d231b6c77030a21f15b69979d935e23b420e2b5","raw_frame":"{\"market\":\"0xf9d60bb033695053c4d1d8592e52171c1042f64b41a4b72e09dcc6f4852b6670\", \"price_changes\":[{\"asset_id\":\"96283536366176669581486355171583722558858323126916278856549586825357358273536\", \"price\":\"0.01\", \"size\":\"6729.5\", \"side\":\"BUY\", \"hash\":\"def2a91cf945fca5323e8ed417472352efc2fe04\", \"best_bid\":\"0.13\", \"best_ask\":\"0.14\"}, {\"asset_id\":\"8698449539441374295770236407991735029336433231649246775082939325523552031992\", \"price\":\"0.99\", \"size\":\"6729.5\", \"side\":\"SELL\", \"hash\":\"c031656cf6d1b9bbbf201af6448322b6436b4dac\", \"best_bid\":\"0.86\", \"best_ask\":\"0.87\"}], \"timestamp\":\"1785122040251\", \"event_type\":\"price_change\"}","received_at":"2026-07-27T03:14:00.405939Z","schema_version":"clob-market-ws.price_change.v1","sequence":null,"server_hash":null,"server_timestamp":"1785122040251","session_id":"ff6d21c8283948938400a32613abec2c","source":"clob_market_ws"},"received_at":"2026-07-27T03:14:00.405939Z","record_id":"9869cfba93f5374ba56d961e20eee3734f63fab04c09fb2bd7805f97d64a2959","schema_fingerprint":"4aa3821a28b0b7c2400bc59aba4bcc0a76e971dadd19610d3ad38c768e124dc7","schema_version":"edge-lab-recorder.raw.v1","sequence":null,"source":"clob_market_ws"}
{"event_at":"2026-07-27T03:14:00.252000Z","event_fingerprint":"89fd95ca9b91fafe383aa148d1a165598f089446408a30ff57f72169f9ad6242","payload":{"connection_id":"f95883f18d264834af91809e5f803e9f","event_at":"2026-07-27T03:14:00.252000Z","event_type":"price_change","frame_hash":"ce230bbe3ff74b1e00c10a0d1ac2ca97692da6037661588e38821236516e4df3","frame_index":0,"kind":"data","monotonic_ns":224023741733875,"payload":{"event_type":"price_change","market":"0xf9d60bb033695053c4d1d8592e52171c1042f64b41a4b72e09dcc6f4852b6670","price_changes":[{"asset_id":"8698449539441374295770236407991735029336433231649246775082939325523552031992","best_ask":"0.87","best_bid":"0.86","hash":"dd006aa1128c356e7985c2f5b730c5b6fcc5b093","price":"0.01","side":"BUY","size":"7627.5"},{"asset_id":"96283536366176669581486355171583722558858323126916278856549586825357358273536","best_ask":"0.14","best_bid":"0.13","hash":"09525ee32950e6f9fa65b06e03d211f09643b568","price":"0.99","side":"SELL","size":"7627.5"}],"timestamp":"1785122040252"},"payload_hash":"00d1dc4d7eec3289eaa31cf3696b893ffc4e48e09915dc9e23f64cb9e1a553b1","raw_frame":"{\"market\":\"0xf9d60bb033695053c4d1d8592e52171c1042f64b41a4b72e09dcc6f4852b6670\", \"price_changes\":[{\"asset_id\":\"8698449539441374295770236407991735029336433231649246775082939325523552031992\", \"price\":\"0.01\", \"size\":\"7627.5\", \"side\":\"BUY\", \"hash\":\"dd006aa1128c356e7985c2f5b730c5b6fcc5b093\", \"best_bid\":\"0.86\", \"best_ask\":\"0.87\"}, {\"asset_id\":\"96283536366176669581486355171583722558858323126916278856549586825357358273536\", \"price\":\"0.99\", \"size\":\"7627.5\", \"side\":\"SELL\", \"hash\":\"09525ee32950e6f9fa65b06e03d211f09643b568\", \"best_bid\":\"0.13\", \"best_ask\":\"0.14\"}], \"timestamp\":\"1785122040252\", \"event_type\":\"price_change\"}","received_at":"2026-07-27T03:14:00.408906Z","schema_version":"clob-market-ws.price_change.v1","sequence":null,"server_hash":null,"server_timestamp":"1785122040252","session_id":"ff6d21c8283948938400a32613abec2c","source":"clob_market_ws"},"received_at":"2026-07-27T03:14:00.408906Z","record_id":"84c9db825e99b5957d34957a88d443b79b5319a71d0fd6d440e77b6629a0abbb","schema_fingerprint":"4aa3821a28b0b7c2400bc59aba4bcc0a76e971dadd19610d3ad38c768e124dc7","schema_version":"edge-lab-recorder.raw.v1","sequence":null,"source":"clob_market_ws"}
{"event_at":"2026-07-27T03:14:00.255000Z","event_fingerprint":"1025859dbeeadebd0fbaaf6814ae8ef18af40f088ec5c4914d28c70affc75af4","payload":{"connection_id":"f95883f18d264834af91809e5f803e9f","event_at":"2026-07-27T03:14:00.255000Z","event_type":"price_change","frame_hash":"a61a4e6f516923a7021cbf59af2cae4e152b18aa3a31fa5946a802a5da713094","frame_index":0,"kind":"data","monotonic_ns":224023744699791,"payload":{"event_type":"price_change","market":"0xf9d60bb033695053c4d1d8592e52171c1042f64b41a4b72e09dcc6f4852b6670","price_changes":[{"asset_id":"8698449539441374295770236407991735029336433231649246775082939325523552031992","best_ask":"0.87","best_bid":"0.86","hash":"0bc02e9ff2ec34ba0865227731d40de149e95aee","price":"0.01","side":"BUY","size":"7622.5"},{"asset_id":"96283536366176669581486355171583722558858323126916278856549586825357358273536","best_ask":"0.14","best_bid":"0.13","hash":"977d1aa74e6d677d1a933cb51c5190df1496e0eb","price":"0.99","side":"SELL","size":"7622.5"}],"timestamp":"1785122040255"},"payload_hash":"2616aca252bdb885ca49f39af4f29b139f58f8c7fcdeec3ee8ab330842345c0d","raw_frame":"{\"market\":\"0xf9d60bb033695053c4d1d8592e52171c1042f64b41a4b72e09dcc6f4852b6670\", \"price_changes\":[{\"asset_id\":\"8698449539441374295770236407991735029336433231649246775082939325523552031992\", \"price\":\"0.01\", \"size\":\"7622.5\", \"side\":\"BUY\", \"hash\":\"0bc02e9ff2ec34ba0865227731d40de149e95aee\", \"best_bid\":\"0.86\", \"best_ask\":\"0.87\"}, {\"asset_id\":\"96283536366176669581486355171583722558858323126916278856549586825357358273536\", \"price\":\"0.99\", \"size\":\"7622.5\", \"side\":\"SELL\", \"hash\":\"977d1aa74e6d677d1a933cb51c5190df1496e0eb\", \"best_bid\":\"0.13\", \"best_ask\":\"0.14\"}], \"timestamp\":\"1785122040255\", \"event_type\":\"price_change\"}","received_at":"2026-07-27T03:14:00.411870Z","schema_version":"clob-market-ws.price_change.v1","sequence":null,"server_hash":null,"server_timestamp":"1785122040255","session_id":"ff6d21c8283948938400a32613abec2c","source":"clob_market_ws"},"received_at":"2026-07-27T03:14:00.411870Z","record_id":"4ccfab1ce1999e721a4bc704ddb10a19fd6167049cc6b6ec397a4ac4a9aeaa7b","schema_fingerprint":"4aa3821a28b0b7c2400bc59aba4bcc0a76e971dadd19610d3ad38c768e124dc7","schema_version":"edge-lab-recorder.raw.v1","sequence":null,"source":"clob_market_ws"}
{"event_at":"2026-07-27T03:14:00.256000Z","event_fingerprint":"db92e7780235016fe9c518d7ed09f3dca5c5273ebf1b6deec34ab9f23927d181","payload":{"connection_id":"f95883f18d264834af91809e5f803e9f","event_at":"2026-07-27T03:14:00.256000Z","event_type":"price_change","frame_hash":"e2829e96b0a59f29b09360a2b42bb320cdc2a5b9d1370251db692d7b3f324b4b","frame_index":0,"kind":"data","monotonic_ns":224023747144791,"payload":{"event_type":"price_change","market":"0xf9d60bb033695053c4d1d8592e52171c1042f64b41a4b72e09dcc6f4852b6670","price_changes":[{"asset_id":"96283536366176669581486355171583722558858323126916278856549586825357358273536","best_ask":"0.14","best_bid":"0.13","hash":"1ed4e0aeaa6ab9fd43f0143b1f4eaba7665c82ca","price":"0.01","side":"BUY","size":"6734.5"},{"asset_id":"8698449539441374295770236407991735029336433231649246775082939325523552031992","best_ask":"0.87","best_bid":"0.86","hash":"20e4e83806e7a0d48f5b773c35edcde0d6747dd2","price":"0.99","side":"SELL","size":"6734.5"}],"timestamp":"1785122040256"},"payload_hash":"6abfe6cdf7a9a0c502d168cba0382bb1dff54c5441c02d1bacca8bc43aad3cbb","raw_frame":"{\"market\":\"0xf9d60bb033695053c4d1d8592e52171c1042f64b41a4b72e09dcc6f4852b6670\", \"price_changes\":[{\"asset_id\":\"96283536366176669581486355171583722558858323126916278856549586825357358273536\", \"price\":\"0.01\", \"size\":\"6734.5\", \"side\":\"BUY\", \"hash\":\"1ed4e0aeaa6ab9fd43f0143b1f4eaba7665c82ca\", \"best_bid\":\"0.13\", \"best_ask\":\"0.14\"}, {\"asset_id\":\"8698449539441374295770236407991735029336433231649246775082939325523552031992\", \"price\":\"0.99\", \"size\":\"6734.5\", \"side\":\"SELL\", \"hash\":\"20e4e83806e7a0d48f5b773c35edcde0d6747dd2\", \"best_bid\":\"0.86\", \"best_ask\":\"0.87\"}], \"timestamp\":\"1785122040256\", \"event_type\":\"price_change\"}","received_at":"2026-07-27T03:14:00.414322Z","schema_version":"clob-market-ws.price_change.v1","sequence":null,"server_hash":null,"server_timestamp":"1785122040256","session_id":"ff6d21c8283948938400a32613abec2c","source":"clob_market_ws"},"received_at":"2026-07-27T03:14:00.414322Z","record_id":"45cc75a4608bf9f64e288747129f251cba194fca25ef4230769d1fb236716c5d","schema_fingerprint":"4aa3821a28b0b7c2400bc59aba4bcc0a76e971dadd19610d3ad38c768e124dc7","schema_version":"edge-lab-recorder.raw.v1","sequence":null,"source":"clob_market_ws"}
{"event_at":"2026-07-27T03:14:00.271000Z","event_fingerprint":"b77000d3ef1f3ca79905791686beeccd11c6ecf3cd4483e13c1c135277df8e55","payload":{"connection_id":"f95883f18d264834af91809e5f803e9f","event_at":"2026-07-27T03:14:00.271000Z","event_type":"price_change","frame_hash":"53d284c62bdcad99413ed1ff09ce2b4b9e150cfbf8785082c4af40f123c9194e","frame_index":0,"kind":"data","monotonic_ns":224023749742250,"payload":{"event_type":"price_change","market":"0xf9d60bb033695053c4d1d8592e52171c1042f64b41a4b72e09dcc6f4852b6670","price_changes":[{"asset_id":"96283536366176669581486355171583722558858323126916278856549586825357358273536","best_ask":"0.14","best_bid":"0.13","hash":"d00c4d7aa3c0967d0e6f5a69772f30407e672d72","price":"0.05","side":"BUY","size":"364.19"},{"asset_id":"8698449539441374295770236407991735029336433231649246775082939325523552031992","best_ask":"0.87","best_bid":"0.86","hash":"e23bf2b2160164dbd14866bb946995e138997c44","price":"0.95","side":"SELL","size":"364.19"}],"timestamp":"1785122040271"},"payload_hash":"1657b1e618c2423db71285ef13dd976305b50f84cf15222c08dcc468f17e0562","raw_frame":"{\"market\":\"0xf9d60bb033695053c4d1d8592e52171c1042f64b41a4b72e09dcc6f4852b6670\", \"price_changes\":[{\"asset_id\":\"96283536366176669581486355171583722558858323126916278856549586825357358273536\", \"price\":\"0.05\", \"size\":\"364.19\", \"side\":\"BUY\", \"hash\":\"d00c4d7aa3c0967d0e6f5a69772f30407e672d72\", \"best_bid\":\"0.13\", \"best_ask\":\"0.14\"}, {\"asset_id\":\"8698449539441374295770236407991735029336433231649246775082939325523552031992\", \"price\":\"0.95\", \"size\":\"364.19\", \"side\":\"SELL\", \"hash\":\"e23bf2b2160164dbd14866bb946995e138997c44\", \"best_bid\":\"0.86\", \"best_ask\":\"0.87\"}], \"timestamp\":\"1785122040271\", \"event_type\":\"price_change\"}","received_at":"2026-07-27T03:14:00.416913Z","schema_version":"clob-market-ws.price_change.v1","sequence":null,"server_hash":null,"server_timestamp":"1785122040271","session_id":"ff6d21c8283948938400a32613abec2c","source":"clob_market_ws"},"received_at":"2026-07-27T03:14:00.416913Z","record_id":"1dce830cf2d25b0fd3d29cec883197364e42d487bf2deb7b0595a4f1864abfcb","schema_fingerprint":"4aa3821a28b0b7c2400bc59aba4bcc0a76e971dadd19610d3ad38c768e124dc7","schema_version":"edge-lab-recorder.raw.v1","sequence":null,"source":"clob_market_ws"}
{"event_at":"2026-07-27T03:14:00.285000Z","event_fingerprint":"4f673157bdf044859f3cfddcde67fe50a77fd023540510bcaba6fb7880fd310e","payload":{"connection_id":"f95883f18d264834af91809e5f803e9f","event_at":"2026-07-27T03:14:00.285000Z","event_type":"price_change","frame_hash":"8df179cb865fc3d1b7b6a68cf67b29d1715850bfe2d2a8449771367376ba291e","frame_index":0,"kind":"data","monotonic_ns":224023752810708,"payload":{"event_type":"price_change","market":"0xf9d60bb033695053c4d1d8592e52171c1042f64b41a4b72e09dcc6f4852b6670","price_changes":[{"asset_id":"8698449539441374295770236407991735029336433231649246775082939325523552031992","best_ask":"0.87","best_bid":"0.86","hash":"91b26df178a2057103fcd4704e59eb0e429ecbf6","price":"0.02","side":"BUY","size":"1395.79"},{"asset_id":"96283536366176669581486355171583722558858323126916278856549586825357358273536","best_ask":"0.14","best_bid":"0.13","hash":"e42e8ba4ef786b5e4fb856ea5e7b777a5c32902d","price":"0.98","side":"SELL","size":"1395.79"}],"timestamp":"1785122040285"},"payload_hash":"2f15834f4ed1e004a217b295785898399126bb0d2fbb1349c42bbe998fd710a1","raw_frame":"{\"market\":\"0xf9d60bb033695053c4d1d8592e52171c1042f64b41a4b72e09dcc6f4852b6670\", \"price_changes\":[{\"asset_id\":\"8698449539441374295770236407991735029336433231649246775082939325523552031992\", \"price\":\"0.02\", \"size\":\"1395.79\", \"side\":\"BUY\", \"hash\":\"91b26df178a2057103fcd4704e59eb0e429ecbf6\", \"best_bid\":\"0.86\", \"best_ask\":\"0.87\"}, {\"asset_id\":\"96283536366176669581486355171583722558858323126916278856549586825357358273536\", \"price\":\"0.98\", \"size\":\"1395.79\", \"side\":\"SELL\", \"hash\":\"e42e8ba4ef786b5e4fb856ea5e7b777a5c32902d\", \"best_bid\":\"0.13\", \"best_ask\":\"0.14\"}], \"timestamp\":\"1785122040285\", \"event_type\":\"price_change\"}","received_at":"2026-07-27T03:14:00.419981Z","schema_version":"clob-market-ws.price_change.v1","sequence":null,"server_hash":null,"server_timestamp":"1785122040285","session_id":"ff6d21c8283948938400a32613abec2c","source":"clob_market_ws"},"received_at":"2026-07-27T03:14:00.419981Z","record_id":"f78a65c495a8dd42520bbfcde135b2e0ec5ef45571ac1837a93ebc17d229de3a","schema_fingerprint":"4aa3821a28b0b7c2400bc59aba4bcc0a76e971dadd19610d3ad38c768e124dc7","schema_version":"edge-lab-recorder.raw.v1","sequence":null,"source":"clob_market_ws"}
{"event_at":"2026-07-27T03:14:00.299000Z","event_fingerprint":"0fce9da367e067322186090532d90fa68658b2674ab62db6c8941b72a3e0e7ee","payload":{"connection_id":"f95883f18d264834af91809e5f803e9f","event_at":"2026-07-27T03:14:00.299000Z","event_type":"price_change","frame_hash":"d71a5832de6aed3f718dde4dbc70748c44764578f0b2205e3cb0c6f738c39e51","frame_index":0,"kind":"data","monotonic_ns":224023756113875,"payload":{"event_type":"price_change","market":"0xf9d60bb033695053c4d1d8592e52171c1042f64b41a4b72e09dcc6f4852b6670","price_changes":[{"asset_id":"96283536366176669581486355171583722558858323126916278856549586825357358273536","best_ask":"0.14","best_bid":"0.13","hash":"9e863f91e685e926feaadb834e1345c3bad415ac","price":"0.07","side":"BUY","size":"172"},{"asset_id":"8698449539441374295770236407991735029336433231649246775082939325523552031992","best_ask":"0.87","best_bid":"0.86","hash":"9ae57b6f8cd8899680a503dcee45bef2fbd5e7e9","price":"0.93","side":"SELL","size":"172"}],"timestamp":"1785122040299"},"payload_hash":"d2b80c7907355ab717a82ab50588ecae79e9277903feb1ea7359ac10ce6115fc","raw_frame":"{\"market\":\"0xf9d60bb033695053c4d1d8592e52171c1042f64b41a4b72e09dcc6f4852b6670\", \"price_changes\":[{\"asset_id\":\"96283536366176669581486355171583722558858323126916278856549586825357358273536\", \"price\":\"0.07\", \"size\":\"172\", \"side\":\"BUY\", \"hash\":\"9e863f91e685e926feaadb834e1345c3bad415ac\", \"best_bid\":\"0.13\", \"best_ask\":\"0.14\"}, {\"asset_id\":\"8698449539441374295770236407991735029336433231649246775082939325523552031992\", \"price\":\"0.93\", \"size\":\"172\", \"side\":\"SELL\", \"hash\":\"9ae57b6f8cd8899680a503dcee45bef2fbd5e7e9\", \"best_bid\":\"0.86\", \"best_ask\":\"0.87\"}], \"timestamp\":\"1785122040299\", \"event_type\":\"price_change\"}","received_at":"2026-07-27T03:14:00.423283Z","schema_version":"clob-market-ws.price_change.v1","sequence":null,"server_hash":null,"server_timestamp":"1785122040299","session_id":"ff6d21c8283948938400a32613abec2c","source":"clob_market_ws"},"received_at":"2026-07-27T03:14:00.423283Z","record_id":"df705ff2cdf7210fd3fd853d3c805353ebc986bce85fec2616833f01e860c0e3","schema_fingerprint":"4aa3821a28b0b7c2400bc59aba4bcc0a76e971dadd19610d3ad38c768e124dc7","schema_version":"edge-lab-recorder.raw.v1","sequence":null,"source":"clob_market_ws"}
{"event_at":"2026-07-27T03:14:00.364000Z","event_fingerprint":"9f3341c80ee2dcdb6bdbe0988606bfbbaaae87a052d5756d0e0aa25f1545ae76","payload":{"connection_id":"f95883f18d264834af91809e5f803e9f","event_at":"2026-07-27T03:14:00.364000Z","event_type":"price_change","frame_hash":"d0540ea5c100c63fd4b16d2f8b7f0a0200ce5ce5169510abd828220868b57e6a","frame_index":0,"kind":"data","monotonic_ns":224023757861708,"payload":{"event_type":"price_change","market":"0xf9d60bb033695053c4d1d8592e52171c1042f64b41a4b72e09dcc6f4852b6670","price_changes":[{"asset_id":"8698449539441374295770236407991735029336433231649246775082939325523552031992","best_ask":"0.87","best_bid":"0.86","hash":"12229f694ca1cff29a968a9794a055864fa4282c","price":"0.01","side":"BUY","size":"7627.5"},{"asset_id":"96283536366176669581486355171583722558858323126916278856549586825357358273536","best_ask":"0.14","best_bid":"0.13","hash":"f583933554120502fc172650ea8792a3f22371c3","price":"0.99","side":"SELL","size":"7627.5"}],"timestamp":"1785122040364"},"payload_hash":"2b5d26df17b9f524605e2d6abf3feb5be2b50a1f5aaa9766cf43f593aa6447c2","raw_frame":"{\"market\":\"0xf9d60bb033695053c4d1d8592e52171c1042f64b41a4b72e09dcc6f4852b6670\", \"price_changes\":[{\"asset_id\":\"8698449539441374295770236407991735029336433231649246775082939325523552031992\", \"price\":\"0.01\", \"size\":\"7627.5\", \"side\":\"BUY\", \"hash\":\"12229f694ca1cff29a968a9794a055864fa4282c\", \"best_bid\":\"0.86\", \"best_ask\":\"0.87\"}, {\"asset_id\":\"96283536366176669581486355171583722558858323126916278856549586825357358273536\", \"price\":\"0.99\", \"size\":\"7627.5\", \"side\":\"SELL\", \"hash\":\"f583933554120502fc172650ea8792a3f22371c3\", \"best_bid\":\"0.13\", \"best_ask\":\"0.14\"}], \"timestamp\":\"1785122040364\", \"event_type\":\"price_change\"}","received_at":"2026-07-27T03:14:00.425031Z","schema_version":"clob-market-ws.price_change.v1","sequence":null,"server_hash":null,"server_timestamp":"1785122040364","session_id":"ff6d21c8283948938400a32613abec2c","source":"clob_market_ws"},"received_at":"2026-07-27T03:14:00.425031Z","record_id":"a6245bdd738fed7ab9836f20f89c714b5f4c0fdc94473804699a8171035e8ff2","schema_fingerprint":"4aa3821a28b0b7c2400bc59aba4bcc0a76e971dadd19610d3ad38c768e124dc7","schema_version":"edge-lab-recorder.raw.v1","sequence":null,"source":"clob_market_ws"}
{"event_at":"2026-07-27T03:14:00.371000Z","event_fingerprint":"ebce79782a4a797edc0ffd2411b3620dc410aea1b827d01142672246bafebda3","payload":{"connection_id":"f95883f18d264834af91809e5f803e9f","event_at":"2026-07-27T03:14:00.371000Z","event_type":"best_bid_ask","frame_hash":"e0d16f6cb7956c6ebfafe27f93502bbff9bb3da376f869ad85b7a8e6e84ba83f","frame_index":0,"kind":"data","monotonic_ns":224023758817958,"payload":{"asset_id":"8698449539441374295770236407991735029336433231649246775082939325523552031992","best_ask":"0.87","best_bid":"0.85","event_type":"best_bid_ask","market":"0xf9d60bb033695053c4d1d8592e52171c1042f64b41a4b72e09dcc6f4852b6670","spread":"0.02","timestamp":"1785122040371"},"payload_hash":"dacb9034b95b11035738d208c76404e5412bc23db5f62ed9be129f5ceb020a54","raw_frame":"{\"market\":\"0xf9d60bb033695053c4d1d8592e52171c1042f64b41a4b72e09dcc6f4852b6670\", \"asset_id\":\"8698449539441374295770236407991735029336433231649246775082939325523552031992\", \"best_bid\":\"0.85\", \"best_ask\":\"0.87\", \"spread\":\"0.02\", \"timestamp\":\"1785122040371\", \"event_type\":\"best_bid_ask\"}","received_at":"2026-07-27T03:14:00.425991Z","schema_version":"clob-market-ws.best_bid_ask.v1","sequence":null,"server_hash":null,"server_timestamp":"1785122040371","session_id":"ff6d21c8283948938400a32613abec2c","source":"clob_market_ws"},"received_at":"2026-07-27T03:14:00.425991Z","record_id":"97c7dcd649c2d41f4247d96d729a6f57727e68ed4a7cca5b612209de68cf464f","schema_fingerprint":"8488399f31b0337811b13b266be932db7062827c2470b78bd8e9e99bab51d17d","schema_version":"edge-lab-recorder.raw.v1","sequence":null,"source":"clob_market_ws"}
{"event_at":"2026-07-27T03:14:00.371000Z","event_fingerprint":"b4a69f724e4caee2487eb5a86966cab1efadd6a83a7df5f6d536915ffddd2c46","payload":{"connection_id":"f95883f18d264834af91809e5f803e9f","event_at":"2026-07-27T03:14:00.371000Z","event_type":"best_bid_ask","frame_hash":"9bd92b939513d71a6e4c7027f29cfc479d8262b9809df08743060bb04e31fd19","frame_index":0,"kind":"data","monotonic_ns":224023759384291,"payload":{"asset_id":"96283536366176669581486355171583722558858323126916278856549586825357358273536","best_ask":"0.15","best_bid":"0.13","event_type":"best_bid_ask","market":"0xf9d60bb033695053c4d1d8592e52171c1042f64b41a4b72e09dcc6f4852b6670","spread":"0.02","timestamp":"1785122040371"},"payload_hash":"957b16fa48532af03d61e674f7d514df1970404a79b3b48b5bd777750a9d1e6f","raw_frame":"{\"market\":\"0xf9d60bb033695053c4d1d8592e52171c1042f64b41a4b72e09dcc6f4852b6670\", \"asset_id\":\"96283536366176669581486355171583722558858323126916278856549586825357358273536\", \"best_bid\":\"0.13\", \"best_ask\":\"0.15\", \"spread\":\"0.02\", \"timestamp\":\"1785122040371\", \"event_type\":\"best_bid_ask\"}","received_at":"2026-07-27T03:14:00.426560Z","schema_version":"clob-market-ws.best_bid_ask.v1","sequence":null,"server_hash":null,"server_timestamp":"1785122040371","session_id":"ff6d21c8283948938400a32613abec2c","source":"clob_market_ws"},"received_at":"2026-07-27T03:14:00.426560Z","record_id":"56b6689f26a419214ecf6556a026050b755f6bbf2c4d8bca80da42c1539fb756","schema_fingerprint":"8488399f31b0337811b13b266be932db7062827c2470b78bd8e9e99bab51d17d","schema_version":"edge-lab-recorder.raw.v1","sequence":null,"source":"clob_market_ws"}
{"event_at":"2026-07-27T03:14:00.371000Z","event_fingerprint":"4297d1c34522dba32490cd46d0a3866f3463ea77dee673ddb8e59c4ac5610851","payload":{"connection_id":"f95883f18d264834af91809e5f803e9f","event_at":"2026-07-27T03:14:00.371000Z","event_type":"price_change","frame_hash":"af876327671684ca59df0822151e0d5125486bbef8c49623901ee5d87ba894a2","frame_index":0,"kind":"data","monotonic_ns":224023759908708,"payload":{"event_type":"price_change","market":"0xf9d60bb033695053c4d1d8592e52171c1042f64b41a4b72e09dcc6f4852b6670","price_changes":[{"asset_id":"96283536366176669581486355171583722558858323126916278856549586825357358273536","best_ask":"0.15","best_bid":"0.13","hash":"fb3d30b3dc5b70014b5bd5260d6a96f28517e188","price":"0.14","side":"SELL","size":"0"},{"asset_id":"8698449539441374295770236407991735029336433231649246775082939325523552031992","best_ask":"0.87","best_bid":"0.85","hash":"eab76fe4576decf3d49112b3c05226a32e5e6524","price":"0.86","side":"BUY","size":"0"}],"timestamp":"1785122040371"},"payload_hash":"ca561ad8ff9fecd377a5820f24a12190db0581064737db2931060b28ac685ef8","raw_frame":"{\"market\":\"0xf9d60bb033695053c4d1d8592e52171c1042f64b41a4b72e09dcc6f4852b6670\", \"price_changes\":[{\"asset_id\":\"96283536366176669581486355171583722558858323126916278856549586825357358273536\", \"price\":\"0.14\", \"size\":\"0\", \"side\":\"SELL\", \"hash\":\"fb3d30b3dc5b70014b5bd5260d6a96f28517e188\", \"best_bid\":\"0.13\", \"best_ask\":\"0.15\"}, {\"asset_id\":\"8698449539441374295770236407991735029336433231649246775082939325523552031992\", \"price\":\"0.86\", \"size\":\"0\", \"side\":\"BUY\", \"hash\":\"eab76fe4576decf3d49112b3c05226a32e5e6524\", \"best_bid\":\"0.85\", \"best_ask\":\"0.87\"}], \"timestamp\":\"1785122040371\", \"event_type\":\"price_change\"}","received_at":"2026-07-27T03:14:00.427085Z","schema_version":"clob-market-ws.price_change.v1","sequence":null,"server_hash":null,"server_timestamp":"1785122040371","session_id":"ff6d21c8283948938400a32613abec2c","source":"clob_market_ws"},"received_at":"2026-07-27T03:14:00.427085Z","record_id":"b270be4ef3583708f4e3d079aab3568ea9d17a0c4438f5ae998c42b895cf247a","schema_fingerprint":"4aa3821a28b0b7c2400bc59aba4bcc0a76e971dadd19610d3ad38c768e124dc7","schema_version":"edge-lab-recorder.raw.v1","sequence":null,"source":"clob_market_ws"}
{"event_at":"2026-07-27T03:14:00.371000Z","event_fingerprint":"7978e114341104c6569b8c759e9d4c6bc9fb4d32b2fea1571a5444a5a7c20377","payload":{"connection_id":"f95883f18d264834af91809e5f803e9f","event_at":"2026-07-27T03:14:00.371000Z","event_type":"price_change","frame_hash":"6dffdf84b01f9cfa18b1d3e8469b32c5464031cb1826ac8f6a6536cd83c144de","frame_index":0,"kind":"data","monotonic_ns":224023760622541,"payload":{"event_type":"price_change","market":"0xf9d60bb033695053c4d1d8592e52171c1042f64b41a4b72e09dcc6f4852b6670","price_changes":[{"asset_id":"96283536366176669581486355171583722558858323126916278856549586825357358273536","best_ask":"0.15","best_bid":"0.13","hash":"fb3d30b3dc5b70014b5bd5260d6a96f28517e188","price":"0.09","side":"BUY","size":"57.6"},{"asset_id":"8698449539441374295770236407991735029336433231649246775082939325523552031992","best_ask":"0.87","best_bid":"0.85","hash":"eab76fe4576decf3d49112b3c05226a32e5e6524","price":"0.91","side":"SELL","size":"57.6"}],"timestamp":"1785122040371"},"payload_hash":"5434f4de623122f93729a9d8e8985512bb95c01d375499a5899adcb48832d1eb","raw_frame":"{\"market\":\"0xf9d60bb033695053c4d1d8592e52171c1042f64b41a4b72e09dcc6f4852b6670\", \"price_changes\":[{\"asset_id\":\"96283536366176669581486355171583722558858323126916278856549586825357358273536\", \"price\":\"0.09\", \"size\":\"57.6\", \"side\":\"BUY\", \"hash\":\"fb3d30b3dc5b70014b5bd5260d6a96f28517e188\", \"best_bid\":\"0.13\", \"best_ask\":\"0.15\"}, {\"asset_id\":\"8698449539441374295770236407991735029336433231649246775082939325523552031992\", \"price\":\"0.91\", \"size\":\"57.6\", \"side\":\"SELL\", \"hash\":\"eab76fe4576decf3d49112b3c05226a32e5e6524\", \"best_bid\":\"0.85\", \"best_ask\":\"0.87\"}], \"timestamp\":\"1785122040371\", \"event_type\":\"price_change\"}","received_at":"2026-07-27T03:14:00.427799Z","schema_version":"clob-market-ws.price_change.v1","sequence":null,"server_hash":null,"server_timestamp":"1785122040371","session_id":"ff6d21c8283948938400a32613abec2c","source":"clob_market_ws"},"received_at":"2026-07-27T03:14:00.427799Z","record_id":"9cb259083e32c4e18ca4db794575df87723c2b3a7761111f975fd2e227cafda2","schema_fingerprint":"4aa3821a28b0b7c2400bc59aba4bcc0a76e971dadd19610d3ad38c768e124dc7","schema_version":"edge-lab-recorder.raw.v1","sequence":null,"source":"clob_market_ws"}
{"event_at":"2026-07-27T03:14:00.395000Z","event_fingerprint":"558933cc473b7bf3f748496f5adfc2b5b80e5d4547bdbed61cec87c28000cbf6","payload":{"connection_id":"f95883f18d264834af91809e5f803e9f","event_at":"2026-07-27T03:14:00.395000Z","event_type":"price_change","frame_hash":"0cfbbfe812021f1a4c25beae0e1c35eb63c4576d0c231d1900bdffcb738fa219","frame_index":0,"kind":"data","monotonic_ns":224023761324000,"payload":{"event_type":"price_change","market":"0xf9d60bb033695053c4d1d8592e52171c1042f64b41a4b72e09dcc6f4852b6670","price_changes":[{"asset_id":"8698449539441374295770236407991735029336433231649246775082939325523552031992","best_ask":"0.87","best_bid":"0.85","hash":"3c3c9f6df34e9fd73d25ce7c5568500871511ebb","price":"0.63","side":"BUY","size":"45.1"},{"asset_id":"96283536366176669581486355171583722558858323126916278856549586825357358273536","best_ask":"0.15","best_bid":"0.13","hash":"9770dba4d82aaf925280f91d1b73f10ecb146e97","price":"0.37","side":"SELL","size":"45.1"}],"timestamp":"1785122040395"},"payload_hash":"f548769221d03bdcb51760cd5b406617f95096e06a37d4625ec9229f44be5aa0","raw_frame":"{\"market\":\"0xf9d60bb033695053c4d1d8592e52171c1042f64b41a4b72e09dcc6f4852b6670\", \"price_changes\":[{\"asset_id\":\"8698449539441374295770236407991735029336433231649246775082939325523552031992\", \"price\":\"0.63\", \"size\":\"45.1\", \"side\":\"BUY\", \"hash\":\"3c3c9f6df34e9fd73d25ce7c5568500871511ebb\", \"best_bid\":\"0.85\", \"best_ask\":\"0.87\"}, {\"asset_id\":\"96283536366176669581486355171583722558858323126916278856549586825357358273536\", \"price\":\"0.37\", \"size\":\"45.1\", \"side\":\"SELL\", \"hash\":\"9770dba4d82aaf925280f91d1b73f10ecb146e97\", \"best_bid\":\"0.13\", \"best_ask\":\"0.15\"}], \"timestamp\":\"1785122040395\", \"event_type\":\"price_change\"}","received_at":"2026-07-27T03:14:00.428500Z","schema_version":"clob-market-ws.price_change.v1","sequence":null,"server_hash":null,"server_timestamp":"1785122040395","session_id":"ff6d21c8283948938400a32613abec2c","source":"clob_market_ws"},"received_at":"2026-07-27T03:14:00.428500Z","record_id":"8fc12181f5ea70646965a87c899ba28b671842094e838acbac7fff59065fcc44","schema_fingerprint":"4aa3821a28b0b7c2400bc59aba4bcc0a76e971dadd19610d3ad38c768e124dc7","schema_version":"edge-lab-recorder.raw.v1","sequence":null,"source":"clob_market_ws"}
{"event_at":"2026-07-27T03:14:00.395000Z","event_fingerprint":"3e3229ea713fbe8fc956aa864680f6d4d58d97c254f68d935ce2fde8066266dc","payload":{"connection_id":"f95883f18d264834af91809e5f803e9f","event_at":"2026-07-27T03:14:00.395000Z","event_type":"price_change","frame_hash":"ed92f1937a4e8cbe505c63be1d312f4e2b1d52621ca9d97469dcf655f9f2a5aa","frame_index":0,"kind":"data","monotonic_ns":224023761986208,"payload":{"event_type":"price_change","market":"0xf9d60bb033695053c4d1d8592e52171c1042f64b41a4b72e09dcc6f4852b6670","price_changes":[{"asset_id":"8698449539441374295770236407991735029336433231649246775082939325523552031992","best_ask":"0.87","best_bid":"0.85","hash":"9daf6b95a7a2438f66808e91e24f90c53144a1a8","price":"0.59","side":"BUY","size":"55.3"},{"asset_id":"96283536366176669581486355171583722558858323126916278856549586825357358273536","best_ask":"0.15","best_bid":"0.13","hash":"a9792c5355c954f060fdfb5c270ffdc663a5b054","price":"0.41","side":"SELL","size":"55.3"}],"timestamp":"1785122040395"},"payload_hash":"49a57368ad67ac22a55e4711c2ce72758d3698a773b081c1b8351421555d7008","raw_frame":"{\"market\":\"0xf9d60bb033695053c4d1d8592e52171c1042f64b41a4b72e09dcc6f4852b6670\", \"price_changes\":[{\"asset_id\":\"8698449539441374295770236407991735029336433231649246775082939325523552031992\", \"price\":\"0.59\", \"size\":\"55.3\", \"side\":\"BUY\", \"hash\":\"9daf6b95a7a2438f66808e91e24f90c53144a1a8\", \"best_bid\":\"0.85\", \"best_ask\":\"0.87\"}, {\"asset_id\":\"96283536366176669581486355171583722558858323126916278856549586825357358273536\", \"price\":\"0.41\", \"size\":\"55.3\", \"side\":\"SELL\", \"hash\":\"a9792c5355c954f060fdfb5c270ffdc663a5b054\", \"best_bid\":\"0.13\", \"best_ask\":\"0.15\"}], \"timestamp\":\"1785122040395\", \"event_type\":\"price_change\"}","received_at":"2026-07-27T03:14:00.429162Z","schema_version":"clob-market-ws.price_change.v1","sequence":null,"server_hash":null,"server_timestamp":"1785122040395","session_id":"ff6d21c8283948938400a32613abec2c","source":"clob_market_ws"},"received_at":"2026-07-27T03:14:00.429162Z","record_id":"dbc7cf32228e9be7c055719eb22f7d53792f7f634f055249fe8ec1f2c16ad82d","schema_fingerprint":"4aa3821a28b0b7c2400bc59aba4bcc0a76e971dadd19610d3ad38c768e124dc7","schema_version":"edge-lab-recorder.raw.v1","sequence":null,"source":"clob_market_ws"}
{"event_at":"2026-07-27T03:14:00.399000Z","event_fingerprint":"b84b1dc70aae53fef357d6142ea90f727765af91ad45930b365a362ba1e2345e","payload":{"connection_id":"f95883f18d264834af91809e5f803e9f","event_at":"2026-07-27T03:14:00.399000Z","event_type":"price_change","frame_hash":"d86af7c2cdd78a8711a1e583142dcedf6e7ee027a9795416e126b2450fb0c0e1","frame_index":0,"kind":"data","monotonic_ns":224023762679625,"payload":{"event_type":"price_change","market":"0xf9d60bb033695053c4d1d8592e52171c1042f64b41a4b72e09dcc6f4852b6670","price_changes":[{"asset_id":"8698449539441374295770236407991735029336433231649246775082939325523552031992","best_ask":"0.87","best_bid":"0.85","hash":"3082ab3d33c17c1b6cafa990564f19b9b121eeab","price":"0.83","side":"BUY","size":"43.3"},{"asset_id":"96283536366176669581486355171583722558858323126916278856549586825357358273536","best_ask":"0.15","best_bid":"0.13","hash":"fe7890bd6c07667535f03a6c40b9cadb1c4b5276","price":"0.17","side":"SELL","size":"43.3"}],"timestamp":"1785122040399"},"payload_hash":"dce9004342c4240e7892fd1852593df69749331eec894cafd216694d440171fa","raw_frame":"{\"market\":\"0xf9d60bb033695053c4d1d8592e52171c1042f64b41a4b72e09dcc6f4852b6670\", \"price_changes\":[{\"asset_id\":\"8698449539441374295770236407991735029336433231649246775082939325523552031992\", \"price\":\"0.83\", \"size\":\"43.3\", \"side\":\"BUY\", \"hash\":\"3082ab3d33c17c1b6cafa990564f19b9b121eeab\", \"best_bid\":\"0.85\", \"best_ask\":\"0.87\"}, {\"asset_id\":\"96283536366176669581486355171583722558858323126916278856549586825357358273536\", \"price\":\"0.17\", \"size\":\"43.3\", \"side\":\"SELL\", \"hash\":\"fe7890bd6c07667535f03a6c40b9cadb1c4b5276\", \"best_bid\":\"0.13\", \"best_ask\":\"0.15\"}], \"timestamp\":\"1785122040399\", \"event_type\":\"price_change\"}","received_at":"2026-07-27T03:14:00.429856Z","schema_version":"clob-market-ws.price_change.v1","sequence":null,"server_hash":null,"server_timestamp":"1785122040399","session_id":"ff6d21c8283948938400a32613abec2c","source":"clob_market_ws"},"received_at":"2026-07-27T03:14:00.429856Z","record_id":"14bba3bea25ffc5feb22a4309819842bbde7f833fafc588333471296e501d885","schema_fingerprint":"4aa3821a28b0b7c2400bc59aba4bcc0a76e971dadd19610d3ad38c768e124dc7","schema_version":"edge-lab-recorder.raw.v1","sequence":null,"source":"clob_market_ws"}
{"event_at":"2026-07-27T03:14:00.399000Z","event_fingerprint":"79013f789ffab5b9871f04712c2105a41b2e7013d18ab9cc1a5eb23ad432f264","payload":{"connection_id":"f95883f18d264834af91809e5f803e9f","event_at":"2026-07-27T03:14:00.399000Z","event_type":"price_change","frame_hash":"6ed54525e9a72981c6b2110c000360edf787b0f4295169828a09c142db1280a6","frame_index":0,"kind":"data","monotonic_ns":224023763298708,"payload":{"event_type":"price_change","market":"0xf9d60bb033695053c4d1d8592e52171c1042f64b41a4b72e09dcc6f4852b6670","price_changes":[{"asset_id":"96283536366176669581486355171583722558858323126916278856549586825357358273536","best_ask":"0.15","best_bid":"0.13","hash":"fe7890bd6c07667535f03a6c40b9cadb1c4b5276","price":"0.07","side":"BUY","size":"167"},{"asset_id":"8698449539441374295770236407991735029336433231649246775082939325523552031992","best_ask":"0.87","best_bid":"0.85","hash":"3082ab3d33c17c1b6cafa990564f19b9b121eeab","price":"0.93","side":"SELL","size":"167"}],"timestamp":"1785122040399"},"payload_hash":"819095b805ba11c502d6bbe0358ef4d959a832cd81667b91a88e0b56f545cdc9","raw_frame":"{\"market\":\"0xf9d60bb033695053c4d1d8592e52171c1042f64b41a4b72e09dcc6f4852b6670\", \"price_changes\":[{\"asset_id\":\"96283536366176669581486355171583722558858323126916278856549586825357358273536\", \"price\":\"0.07\", \"size\":\"167\", \"side\":\"BUY\", \"hash\":\"fe7890bd6c07667535f03a6c40b9cadb1c4b5276\", \"best_bid\":\"0.13\", \"best_ask\":\"0.15\"}, {\"asset_id\":\"8698449539441374295770236407991735029336433231649246775082939325523552031992\", \"price\":\"0.93\", \"size\":\"167\", \"side\":\"SELL\", \"hash\":\"3082ab3d33c17c1b6cafa990564f19b9b121eeab\", \"best_bid\":\"0.85\", \"best_ask\":\"0.87\"}], \"timestamp\":\"1785122040399\", \"event_type\":\"price_change\"}","received_at":"2026-07-27T03:14:00.430475Z","schema_version":"clob-market-ws.price_change.v1","sequence":null,"server_hash":null,"server_timestamp":"1785122040399","session_id":"ff6d21c8283948938400a32613abec2c","source":"clob_market_ws"},"received_at":"2026-07-27T03:14:00.430475Z","record_id":"638ec3f3468a2b78d35b8115d90e5f2bc3acc1d65f0695e3cd4e34e9c18a7ffd","schema_fingerprint":"4aa3821a28b0b7c2400bc59aba4bcc0a76e971dadd19610d3ad38c768e124dc7","schema_version":"edge-lab-recorder.raw.v1","sequence":null,"source":"clob_market_ws"}
{"event_at":"2026-07-27T03:14:00.420000Z","event_fingerprint":"f698f373fde92d9816de3a22adc794b17bfda5d9b319a14386912c099c412177","payload":{"connection_id":"f95883f18d264834af91809e5f803e9f","event_at":"2026-07-27T03:14:00.420000Z","event_type":"price_change","frame_hash":"996af9a9e8edbe70e443b3d01e42ffe03aef1af428cd3445e55f1dd705c59e36","frame_index":0,"kind":"data","monotonic_ns":224023764027708,"payload":{"event_type":"price_change","market":"0xf9d60bb033695053c4d1d8592e52171c1042f64b41a4b72e09dcc6f4852b6670","price_changes":[{"asset_id":"8698449539441374295770236407991735029336433231649246775082939325523552031992","best_ask":"0.87","best_bid":"0.85","hash":"630c7b1b870ea489fea094a433b0eb45d925e0f8","price":"0.01","side":"BUY","size":"7622.5"},{"asset_id":"96283536366176669581486355171583722558858323126916278856549586825357358273536","best_ask":"0.15","best_bid":"0.13","hash":"584fedbcc3fc0b840924193b5f5fb90e3b1096b1","price":"0.99","side":"SELL","size":"7622.5"}],"timestamp":"1785122040420"},"payload_hash":"6b4b790327000c3d41cfcb9b91ad644021e6a39ad0c1c2e31b0e0741162b861a","raw_frame":"{\"market\":\"0xf9d60bb033695053c4d1d8592e52171c1042f64b41a4b72e09dcc6f4852b6670\", \"price_changes\":[{\"asset_id\":\"8698449539441374295770236407991735029336433231649246775082939325523552031992\", \"price\":\"0.01\", \"size\":\"7622.5\", \"side\":\"BUY\", \"hash\":\"630c7b1b870ea489fea094a433b0eb45d925e0f8\", \"best_bid\":\"0.85\", \"best_ask\":\"0.87\"}, {\"asset_id\":\"96283536366176669581486355171583722558858323126916278856549586825357358273536\", \"price\":\"0.99\", \"size\":\"7622.5\", \"side\":\"SELL\", \"hash\":\"584fedbcc3fc0b840924193b5f5fb90e3b1096b1\", \"best_bid\":\"0.13\", \"best_ask\":\"0.15\"}], \"timestamp\":\"1785122040420\", \"event_type\":\"price_change\"}","received_at":"2026-07-27T03:14:00.431200Z","schema_version":"clob-market-ws.price_change.v1","sequence":null,"server_hash":null,"server_timestamp":"1785122040420","session_id":"ff6d21c8283948938400a32613abec2c","source":"clob_market_ws"},"received_at":"2026-07-27T03:14:00.431200Z","record_id":"f560b4255f298b04baa7653c30529e6745b8c02e423eeaec2d52583cfea24430","schema_fingerprint":"4aa3821a28b0b7c2400bc59aba4bcc0a76e971dadd19610d3ad38c768e124dc7","schema_version":"edge-lab-recorder.raw.v1","sequence":null,"source":"clob_market_ws"}
{"event_at":"2026-07-27T03:14:00.428000Z","event_fingerprint":"b35318ca9b4a2e44cea32d500fda48cfc55fb633beb9bd261aa65f85f1b15f17","payload":{"connection_id":"f95883f18d264834af91809e5f803e9f","event_at":"2026-07-27T03:14:00.428000Z","event_type":"price_change","frame_hash":"7077b3b91df9e2da2ebbf4969ca16a53fae80b57bcb6bb41af58f4647dd58c1a","frame_index":0,"kind":"data","monotonic_ns":224023764766166,"payload":{"event_type":"price_change","market":"0xf9d60bb033695053c4d1d8592e52171c1042f64b41a4b72e09dcc6f4852b6670","price_changes":[{"asset_id":"96283536366176669581486355171583722558858323126916278856549586825357358273536","best_ask":"0.15","best_bid":"0.13","hash":"d2c9d9e198d7da460a3c400e31d9838c38f10155","price":"0.1","side":"BUY","size":"63.3"},{"asset_id":"8698449539441374295770236407991735029336433231649246775082939325523552031992","best_ask":"0.87","best_bid":"0.85","hash":"e16101b63a0301410a6d56e633c4f5d2ccd3f577","price":"0.9","side":"SELL","size":"63.3"}],"timestamp":"1785122040428"},"payload_hash":"074bf9ec1c35f3bbb5b13d936a4c15c597623f96f986077872916ebad7031556","raw_frame":"{\"market\":\"0xf9d60bb033695053c4d1d8592e52171c1042f64b41a4b72e09dcc6f4852b6670\", \"price_changes\":[{\"asset_id\":\"96283536366176669581486355171583722558858323126916278856549586825357358273536\", \"price\":\"0.1\", \"size\":\"63.3\", \"side\":\"BUY\", \"hash\":\"d2c9d9e198d7da460a3c400e31d9838c38f10155\", \"best_bid\":\"0.13\", \"best_ask\":\"0.15\"}, {\"asset_id\":\"8698449539441374295770236407991735029336433231649246775082939325523552031992\", \"price\":\"0.9\", \"size\":\"63.3\", \"side\":\"SELL\", \"hash\":\"e16101b63a0301410a6d56e633c4f5d2ccd3f577\", \"best_bid\":\"0.85\", \"best_ask\":\"0.87\"}], \"timestamp\":\"1785122040428\", \"event_type\":\"price_change\"}","received_at":"2026-07-27T03:14:00.431940Z","schema_version":"clob-market-ws.price_change.v1","sequence":null,"server_hash":null,"server_timestamp":"1785122040428","session_id":"ff6d21c8283948938400a32613abec2c","source":"clob_market_ws"},"received_at":"2026-07-27T03:14:00.431940Z","record_id":"2757204158ddf210511438cc27d46b101f74395a152e7fb46b944ccfbac0bbc6","schema_fingerprint":"4aa3821a28b0b7c2400bc59aba4bcc0a76e971dadd19610d3ad38c768e124dc7","schema_version":"edge-lab-recorder.raw.v1","sequence":null,"source":"clob_market_ws"}
{"event_at":"2026-07-27T03:14:00.433000Z","event_fingerprint":"f2f2554d1234e2873e886eba6ffdea9caba2d717e08ffc705e61b94726fe26f6","payload":{"connection_id":"f95883f18d264834af91809e5f803e9f","event_at":"2026-07-27T03:14:00.433000Z","event_type":"price_change","frame_hash":"3f5ff87e43ee11c0dcf2c61222fabbbe57458acb3fc596d71431b71c32cc0298","frame_index":0,"kind":"data","monotonic_ns":224023765433500,"payload":{"event_type":"price_change","market":"0xf9d60bb033695053c4d1d8592e52171c1042f64b41a4b72e09dcc6f4852b6670","price_changes":[{"asset_id":"8698449539441374295770236407991735029336433231649246775082939325523552031992","best_ask":"0.87","best_bid":"0.85","hash":"0aed6782f1045a4f55ecc40ae1c4c19e2b7c328c","price":"0.8","side":"BUY","size":"85.7"},{"asset_id":"96283536366176669581486355171583722558858323126916278856549586825357358273536","best_ask":"0.15","best_bid":"0.13","hash":"6620e0275049ca2b34f63728646bfc96b4844f28","price":"0.2","side":"SELL","size":"85.7"}],"timestamp":"1785122040433"},"payload_hash":"ffc1f6189a92ef31761c86e94af2e6e6db0dc3ee4c3cbd9b327e685279dda918","raw_frame":"{\"market\":\"0xf9d60bb033695053c4d1d8592e52171c1042f64b41a4b72e09dcc6f4852b6670\", \"price_changes\":[{\"asset_id\":\"8698449539441374295770236407991735029336433231649246775082939325523552031992\", \"price\":\"0.8\", \"size\":\"85.7\", \"side\":\"BUY\", \"hash\":\"0aed6782f1045a4f55ecc40ae1c4c19e2b7c328c\", \"best_bid\":\"0.85\", \"best_ask\":\"0.87\"}, {\"asset_id\":\"96283536366176669581486355171583722558858323126916278856549586825357358273536\", \"price\":\"0.2\", \"size\":\"85.7\", \"side\":\"SELL\", \"hash\":\"6620e0275049ca2b34f63728646bfc96b4844f28\", \"best_bid\":\"0.13\", \"best_ask\":\"0.15\"}], \"timestamp\":\"1785122040433\", \"event_type\":\"price_change\"}","received_at":"2026-07-27T03:14:00.432609Z","schema_version":"clob-market-ws.price_change.v1","sequence":null,"server_hash":null,"server_timestamp":"1785122040433","session_id":"ff6d21c8283948938400a32613abec2c","source":"clob_market_ws"},"received_at":"2026-07-27T03:14:00.432609Z","record_id":"9feed4477432628c375a8d9cc6a184ee10cc80595de243bb29d9948a069ba10b","schema_fingerprint":"4aa3821a28b0b7c2400bc59aba4bcc0a76e971dadd19610d3ad38c768e124dc7","schema_version":"edge-lab-recorder.raw.v1","sequence":null,"source":"clob_market_ws"}
{"event_at":"2026-07-27T03:14:00.442000Z","event_fingerprint":"02d75567b6cd8f2c39bc005df08abed0b94e26d4386ac7179d6518b5cba8af4b","payload":{"connection_id":"f95883f18d264834af91809e5f803e9f","event_at":"2026-07-27T03:14:00.442000Z","event_type":"price_change","frame_hash":"984597a62a6630beb771aeb240b0013ec385f59aed2b36df6ee9cee292d752c6","frame_index":0,"kind":"data","monotonic_ns":224023766082791,"payload":{"event_type":"price_change","market":"0xf9d60bb033695053c4d1d8592e52171c1042f64b41a4b72e09dcc6f4852b6670","price_changes":[{"asset_id":"96283536366176669581486355171583722558858323126916278856549586825357358273536","best_ask":"0.15","best_bid":"0.13","hash":"125afe5e01a8adac2788ea0ada86a2a885675672","price":"0.05","side":"BUY","size":"359.19"},{"asset_id":"8698449539441374295770236407991735029336433231649246775082939325523552031992","best_ask":"0.87","best_bid":"0.85","hash":"771a7a96a5f596827c271f2c53e543e2f83c1c01","price":"0.95","side":"SELL","size":"359.19"}],"timestamp":"1785122040442"},"payload_hash":"dac1f3c075f3db19377cb5d19f7f9f7e42dd9a6c5b99c3967a713a53be7c70e8","raw_frame":"{\"market\":\"0xf9d60bb033695053c4d1d8592e52171c1042f64b41a4b72e09dcc6f4852b6670\", \"price_changes\":[{\"asset_id\":\"96283536366176669581486355171583722558858323126916278856549586825357358273536\", \"price\":\"0.05\", \"size\":\"359.19\", \"side\":\"BUY\", \"hash\":\"125afe5e01a8adac2788ea0ada86a2a885675672\", \"best_bid\":\"0.13\", \"best_ask\":\"0.15\"}, {\"asset_id\":\"8698449539441374295770236407991735029336433231649246775082939325523552031992\", \"price\":\"0.95\", \"size\":\"359.19\", \"side\":\"SELL\", \"hash\":\"771a7a96a5f596827c271f2c53e543e2f83c1c01\", \"best_bid\":\"0.85\", \"best_ask\":\"0.87\"}], \"timestamp\":\"1785122040442\", \"event_type\":\"price_change\"}","received_at":"2026-07-27T03:14:00.433259Z","schema_version":"clob-market-ws.price_change.v1","sequence":null,"server_hash":null,"server_timestamp":"1785122040442","session_id":"ff6d21c8283948938400a32613abec2c","source":"clob_market_ws"},"received_at":"2026-07-27T03:14:00.433259Z","record_id":"0ee1b0c63546ee686f4e1928a0b11891c2fbd7a256ceb28c6aadccbbedda156a","schema_fingerprint":"4aa3821a28b0b7c2400bc59aba4bcc0a76e971dadd19610d3ad38c768e124dc7","schema_version":"edge-lab-recorder.raw.v1","sequence":null,"source":"clob_market_ws"}
{"event_at":"2026-07-27T03:14:00.448000Z","event_fingerprint":"a83325e9fbfe78d1905942dafc525f83b5d9556d2899d8a0f6eac94338038a3a","payload":{"connection_id":"f95883f18d264834af91809e5f803e9f","event_at":"2026-07-27T03:14:00.448000Z","event_type":"best_bid_ask","frame_hash":"29c4f59c4c00438737675c1c430cff36f0712941a10fede4f61997bbc15be0b1","frame_index":0,"kind":"data","monotonic_ns":224023766680000,"payload":{"asset_id":"8698449539441374295770236407991735029336433231649246775082939325523552031992","best_ask":"0.86","best_bid":"0.85","event_type":"best_bid_ask","market":"0xf9d60bb033695053c4d1d8592e52171c1042f64b41a4b72e09dcc6f4852b6670","spread":"0.01","timestamp":"1785122040448"},"payload_hash":"7cb47d2247d0be205603d343399c735e8df8b137e27ee09aad72f06e0999b122","raw_frame":"{\"market\":\"0xf9d60bb033695053c4d1d8592e52171c1042f64b41a4b72e09dcc6f4852b6670\", \"asset_id\":\"8698449539441374295770236407991735029336433231649246775082939325523552031992\", \"best_bid\":\"0.85\", \"best_ask\":\"0.86\", \"spread\":\"0.01\", \"timestamp\":\"1785122040448\", \"event_type\":\"best_bid_ask\"}","received_at":"2026-07-27T03:14:00.433856Z","schema_version":"clob-market-ws.best_bid_ask.v1","sequence":null,"server_hash":null,"server_timestamp":"1785122040448","session_id":"ff6d21c8283948938400a32613abec2c","source":"clob_market_ws"},"received_at":"2026-07-27T03:14:00.433856Z","record_id":"73479ace7020fb36cc87b896621fe088e85978de8b1386a7272ba54daaf3090e","schema_fingerprint":"8488399f31b0337811b13b266be932db7062827c2470b78bd8e9e99bab51d17d","schema_version":"edge-lab-recorder.raw.v1","sequence":null,"source":"clob_market_ws"}
{"event_at":"2026-07-27T03:14:00.448000Z","event_fingerprint":"e9c611da45847a6b5491d76a15aa059c8d71e2e44bfcba1520b84a89f960e263","payload":{"connection_id":"f95883f18d264834af91809e5f803e9f","event_at":"2026-07-27T03:14:00.448000Z","event_type":"best_bid_ask","frame_hash":"916c6ea63797cb071eec8755252c4c0c520b38ac1be17115406bed6c226dd800","frame_index":0,"kind":"data","monotonic_ns":224023767121625,"payload":{"asset_id":"96283536366176669581486355171583722558858323126916278856549586825357358273536","best_ask":"0.15","best_bid":"0.14","event_type":"best_bid_ask","market":"0xf9d60bb033695053c4d1d8592e52171c1042f64b41a4b72e09dcc6f4852b6670","spread":"0.01","timestamp":"1785122040448"},"payload_hash":"3ba6a357cfca2066b8bf5179532f276f2117d4d231be601a8e3ad781c38188b7","raw_frame":"{\"market\":\"0xf9d60bb033695053c4d1d8592e52171c1042f64b41a4b72e09dcc6f4852b6670\", \"asset_id\":\"96283536366176669581486355171583722558858323126916278856549586825357358273536\", \"best_bid\":\"0.14\", \"best_ask\":\"0.15\", \"spread\":\"0.01\", \"timestamp\":\"1785122040448\", \"event_type\":\"best_bid_ask\"}","received_at":"2026-07-27T03:14:00.434298Z","schema_version":"clob-market-ws.best_bid_ask.v1","sequence":null,"server_hash":null,"server_timestamp":"1785122040448","session_id":"ff6d21c8283948938400a32613abec2c","source":"clob_market_ws"},"received_at":"2026-07-27T03:14:00.434298Z","record_id":"05f99e6b9ea7bd51580145cd41e19ec48da9f3731508ec25351af4fd3cbfb807","schema_fingerprint":"8488399f31b0337811b13b266be932db7062827c2470b78bd8e9e99bab51d17d","schema_version":"edge-lab-recorder.raw.v1","sequence":null,"source":"clob_market_ws"}
{"event_at":"2026-07-27T03:14:00.448000Z","event_fingerprint":"bec446de156a811c256e2bd877554e3477431f9ed25c5994acafb7c0cf87c548","payload":{"connection_id":"f95883f18d264834af91809e5f803e9f","event_at":"2026-07-27T03:14:00.448000Z","event_type":"price_change","frame_hash":"7b5786a0549e255cb338021f29a7bae03705104ad9d9096dbf437c12ccbd57b9","frame_index":0,"kind":"data","monotonic_ns":224023767574750,"payload":{"event_type":"price_change","market":"0xf9d60bb033695053c4d1d8592e52171c1042f64b41a4b72e09dcc6f4852b6670","price_changes":[{"asset_id":"96283536366176669581486355171583722558858323126916278856549586825357358273536","best_ask":"0.15","best_bid":"0.14","hash":"2ef3573ab58a681a39197a2d2176f1bba937d90a","price":"0.14","side":"BUY","size":"75"},{"asset_id":"8698449539441374295770236407991735029336433231649246775082939325523552031992","best_ask":"0.86","best_bid":"0.85","hash":"4e1ccbfbe6a9a23b14a9d4bc71edbbef52dbda94","price":"0.86","side":"SELL","size":"75"}],"timestamp":"1785122040448"},"payload_hash":"c2e0aa3e56d7910cff6ad6965066d90ef6cc99e49a10b9f12f41429812e57324","raw_frame":"{\"market\":\"0xf9d60bb033695053c4d1d8592e52171c1042f64b41a4b72e09dcc6f4852b6670\", \"price_changes\":[{\"asset_id\":\"96283536366176669581486355171583722558858323126916278856549586825357358273536\", \"price\":\"0.14\", \"size\":\"75\", \"side\":\"BUY\", \"hash\":\"2ef3573ab58a681a39197a2d2176f1bba937d90a\", \"best_bid\":\"0.14\", \"best_ask\":\"0.15\"}, {\"asset_id\":\"8698449539441374295770236407991735029336433231649246775082939325523552031992\", \"price\":\"0.86\", \"size\":\"75\", \"side\":\"SELL\", \"hash\":\"4e1ccbfbe6a9a23b14a9d4bc71edbbef52dbda94\", \"best_bid\":\"0.85\", \"best_ask\":\"0.86\"}], \"timestamp\":\"1785122040448\", \"event_type\":\"price_change\"}","received_at":"2026-07-27T03:14:00.434751Z","schema_version":"clob-market-ws.price_change.v1","sequence":null,"server_hash":null,"server_timestamp":"1785122040448","session_id":"ff6d21c8283948938400a32613abec2c","source":"clob_market_ws"},"received_at":"2026-07-27T03:14:00.434751Z","record_id":"e2123ce18c34d8b5e5c813f1625af33bfcd46b8e5d2c580aa17679378fa92019","schema_fingerprint":"4aa3821a28b0b7c2400bc59aba4bcc0a76e971dadd19610d3ad38c768e124dc7","schema_version":"edge-lab-recorder.raw.v1","sequence":null,"source":"clob_market_ws"}
{"event_at":"2026-07-27T03:14:00.452000Z","event_fingerprint":"e131ebfb950ee9c2d4931641cd7b4edd71735a567011e4aca9b2fae0d3494abb","payload":{"connection_id":"f95883f18d264834af91809e5f803e9f","event_at":"2026-07-27T03:14:00.452000Z","event_type":"price_change","frame_hash":"3bf69f9df2d8cf99a4057e8810709c14fd430fad1c7ae7b1bbc0eb37459efee2","frame_index":0,"kind":"data","monotonic_ns":224023768230833,"payload":{"event_type":"price_change","market":"0xf9d60bb033695053c4d1d8592e52171c1042f64b41a4b72e09dcc6f4852b6670","price_changes":[{"asset_id":"96283536366176669581486355171583722558858323126916278856549586825357358273536","best_ask":"0.15","best_bid":"0.14","hash":"7afdbd7b6ed16f79cc80d4be746130c7ad23acdf","price":"0.05","side":"BUY","size":"259.19"},{"asset_id":"8698449539441374295770236407991735029336433231649246775082939325523552031992","best_ask":"0.86","best_bid":"0.85","hash":"c25ccdd8b74a2f20525f887f6be6d9a16a2398ae","price":"0.95","side":"SELL","size":"259.19"}],"timestamp":"1785122040452"},"payload_hash":"39436dd9d5c4b01849553556db5ac5519f60e3419f880ba9589232eb9283aa93","raw_frame":"{\"market\":\"0xf9d60bb033695053c4d1d8592e52171c1042f64b41a4b72e09dcc6f4852b6670\", \"price_changes\":[{\"asset_id\":\"96283536366176669581486355171583722558858323126916278856549586825357358273536\", \"price\":\"0.05\", \"size\":\"259.19\", \"side\":\"BUY\", \"hash\":\"7afdbd7b6ed16f79cc80d4be746130c7ad23acdf\", \"best_bid\":\"0.14\", \"best_ask\":\"0.15\"}, {\"asset_id\":\"8698449539441374295770236407991735029336433231649246775082939325523552031992\", \"price\":\"0.95\", \"size\":\"259.19\", \"side\":\"SELL\", \"hash\":\"c25ccdd8b74a2f20525f887f6be6d9a16a2398ae\", \"best_bid\":\"0.85\", \"best_ask\":\"0.86\"}], \"timestamp\":\"1785122040452\", \"event_type\":\"price_change\"}","received_at":"2026-07-27T03:14:00.435406Z","schema_version":"clob-market-ws.price_change.v1","sequence":null,"server_hash":null,"server_timestamp":"1785122040452","session_id":"ff6d21c8283948938400a32613abec2c","source":"clob_market_ws"},"received_at":"2026-07-27T03:14:00.435406Z","record_id":"aaf737796988a599c7f3cfb7e9e9f704b6d922c330e475fe5fb846ea97551013","schema_fingerprint":"4aa3821a28b0b7c2400bc59aba4bcc0a76e971dadd19610d3ad38c768e124dc7","schema_version":"edge-lab-recorder.raw.v1","sequence":null,"source":"clob_market_ws"}
{"event_at":"2026-07-27T03:14:00.454000Z","event_fingerprint":"bfbb9c829f49fbc9db98fd1a5b5da6aa283a3dbe5c8fbb0d17ffdfbe04274118","payload":{"connection_id":"f95883f18d264834af91809e5f803e9f","event_at":"2026-07-27T03:14:00.454000Z","event_type":"price_change","frame_hash":"dc7fdf6ac3904bda4354b76a27a5ef439a53adda1b6142447f7caad9727b9ed8","frame_index":0,"kind":"data","monotonic_ns":224023768860208,"payload":{"event_type":"price_change","market":"0xf9d60bb033695053c4d1d8592e52171c1042f64b41a4b72e09dcc6f4852b6670","price_changes":[{"asset_id":"96283536366176669581486355171583722558858323126916278856549586825357358273536","best_ask":"0.15","best_bid":"0.14","hash":"43cfec79e686ecd033cf9a64040f2e92baf71f58","price":"0.01","side":"BUY","size":"6234.5"},{"asset_id":"8698449539441374295770236407991735029336433231649246775082939325523552031992","best_ask":"0.86","best_bid":"0.85","hash":"c3aa703ff16027bb1154e5667734a95172fcf4fd","price":"0.99","side":"SELL","size":"6234.5"}],"timestamp":"1785122040454"},"payload_hash":"e411cb4b00afa4f56c56a07122d2a5b8c11e2d544b9bb12c4690929132331282","raw_frame":"{\"market\":\"0xf9d60bb033695053c4d1d8592e52171c1042f64b41a4b72e09dcc6f4852b6670\", \"price_changes\":[{\"asset_id\":\"96283536366176669581486355171583722558858323126916278856549586825357358273536\", \"price\":\"0.01\", \"size\":\"6234.5\", \"side\":\"BUY\", \"hash\":\"43cfec79e686ecd033cf9a64040f2e92baf71f58\", \"best_bid\":\"0.14\", \"best_ask\":\"0.15\"}, {\"asset_id\":\"8698449539441374295770236407991735029336433231649246775082939325523552031992\", \"price\":\"0.99\", \"size\":\"6234.5\", \"side\":\"SELL\", \"hash\":\"c3aa703ff16027bb1154e5667734a95172fcf4fd\", \"best_bid\":\"0.85\", \"best_ask\":\"0.86\"}], \"timestamp\":\"1785122040454\", \"event_type\":\"price_change\"}","received_at":"2026-07-27T03:14:00.436037Z","schema_version":"clob-market-ws.price_change.v1","sequence":null,"server_hash":null,"server_timestamp":"1785122040454","session_id":"ff6d21c8283948938400a32613abec2c","source":"clob_market_ws"},"received_at":"2026-07-27T03:14:00.436037Z","record_id":"13a45f482195d45a7296b8924c517ee64c57b4c273b8e3b974dafc835f061dcf","schema_fingerprint":"4aa3821a28b0b7c2400bc59aba4bcc0a76e971dadd19610d3ad38c768e124dc7","schema_version":"edge-lab-recorder.raw.v1","sequence":null,"source":"clob_market_ws"}
{"event_at":"2026-07-27T03:14:00.458000Z","event_fingerprint":"899fc0ede7587353814f044ba708989977dff5958eca2101bb33e90947dfeaff","payload":{"connection_id":"f95883f18d264834af91809e5f803e9f","event_at":"2026-07-27T03:14:00.458000Z","event_type":"price_change","frame_hash":"170d2a245933a1229c3ef922f73d34901d97a9ba8e97331855eeff157b98b6b6","frame_index":0,"kind":"data","monotonic_ns":224023769504166,"payload":{"event_type":"price_change","market":"0xf9d60bb033695053c4d1d8592e52171c1042f64b41a4b72e09dcc6f4852b6670","price_changes":[{"asset_id":"96283536366176669581486355171583722558858323126916278856549586825357358273536","best_ask":"0.15","best_bid":"0.14","hash":"fe02148b8244f9a1aab763f406a968fb19d3091d","price":"0.02","side":"BUY","size":"535.79"},{"asset_id":"8698449539441374295770236407991735029336433231649246775082939325523552031992","best_ask":"0.86","best_bid":"0.85","hash":"964cd06e387361d2a6944fccf14d3916329cf519","price":"0.98","side":"SELL","size":"535.79"}],"timestamp":"1785122040458"},"payload_hash":"c961d1eca11f7589949c6bc036b12a0f2c860bbf09405f6b04d5dc8de204d532","raw_frame":"{\"market\":\"0xf9d60bb033695053c4d1d8592e52171c1042f64b41a4b72e09dcc6f4852b6670\", \"price_changes\":[{\"asset_id\":\"96283536366176669581486355171583722558858323126916278856549586825357358273536\", \"price\":\"0.02\", \"size\":\"535.79\", \"side\":\"BUY\", \"hash\":\"fe02148b8244f9a1aab763f406a968fb19d3091d\", \"best_bid\":\"0.14\", \"best_ask\":\"0.15\"}, {\"asset_id\":\"8698449539441374295770236407991735029336433231649246775082939325523552031992\", \"price\":\"0.98\", \"size\":\"535.79\", \"side\":\"SELL\", \"hash\":\"964cd06e387361d2a6944fccf14d3916329cf519\", \"best_bid\":\"0.85\", \"best_ask\":\"0.86\"}], \"timestamp\":\"1785122040458\", \"event_type\":\"price_change\"}","received_at":"2026-07-27T03:14:00.436675Z","schema_version":"clob-market-ws.price_change.v1","sequence":null,"server_hash":null,"server_timestamp":"1785122040458","session_id":"ff6d21c8283948938400a32613abec2c","source":"clob_market_ws"},"received_at":"2026-07-27T03:14:00.436675Z","record_id":"2cc580c570100b21d3932e80d7c7a51930483ae8fd2e842d9634b9bfbae6e1da","schema_fingerprint":"4aa3821a28b0b7c2400bc59aba4bcc0a76e971dadd19610d3ad38c768e124dc7","schema_version":"edge-lab-recorder.raw.v1","sequence":null,"source":"clob_market_ws"}
{"event_at":"2026-07-27T03:14:00.459000Z","event_fingerprint":"4144aea0599e879d6c8e3e07eb9c602875881862ca649947a6e20dd3baade9c4","payload":{"connection_id":"f95883f18d264834af91809e5f803e9f","event_at":"2026-07-27T03:14:00.459000Z","event_type":"price_change","frame_hash":"8e5697cdf6bbe9889a5446fff0616cfa5f9abb42be58de6cb66612fe288936cd","frame_index":0,"kind":"data","monotonic_ns":224023770995958,"payload":{"event_type":"price_change","market":"0xf9d60bb033695053c4d1d8592e52171c1042f64b41a4b72e09dcc6f4852b6670","price_changes":[{"asset_id":"8698449539441374295770236407991735029336433231649246775082939325523552031992","best_ask":"0.86","best_bid":"0.85","hash":"010cc18e886fd17b6ffc87a95c73a88cfba5cdeb","price":"0.7","side":"BUY","size":"85"},{"asset_id":"96283536366176669581486355171583722558858323126916278856549586825357358273536","best_ask":"0.15","best_bid":"0.14","hash":"a405af17ba2ae6fec5df312e02b7314260e52dab","price":"0.3","side":"SELL","size":"85"}],"timestamp":"1785122040459"},"payload_hash":"59cac5598c224e8467f5495927b54164f40fe2260f45df6d5411732d7ce7348f","raw_frame":"{\"market\":\"0xf9d60bb033695053c4d1d8592e52171c1042f64b41a4b72e09dcc6f4852b6670\", \"price_changes\":[{\"asset_id\":\"8698449539441374295770236407991735029336433231649246775082939325523552031992\", \"price\":\"0.7\", \"size\":\"85\", \"side\":\"BUY\", \"hash\":\"010cc18e886fd17b6ffc87a95c73a88cfba5cdeb\", \"best_bid\":\"0.85\", \"best_ask\":\"0.86\"}, {\"asset_id\":\"96283536366176669581486355171583722558858323126916278856549586825357358273536\", \"price\":\"0.3\", \"size\":\"85\", \"side\":\"SELL\", \"hash\":\"a405af17ba2ae6fec5df312e02b7314260e52dab\", \"best_bid\":\"0.14\", \"best_ask\":\"0.15\"}], \"timestamp\":\"1785122040459\", \"event_type\":\"price_change\"}","received_at":"2026-07-27T03:14:00.438166Z","schema_version":"clob-market-ws.price_change.v1","sequence":null,"server_hash":null,"server_timestamp":"1785122040459","session_id":"ff6d21c8283948938400a32613abec2c","source":"clob_market_ws"},"received_at":"2026-07-27T03:14:00.438166Z","record_id":"f886b0ba9305855674846ae0cf12e6c0e537ded5925506e6ee0b64c316040035","schema_fingerprint":"4aa3821a28b0b7c2400bc59aba4bcc0a76e971dadd19610d3ad38c768e124dc7","schema_version":"edge-lab-recorder.raw.v1","sequence":null,"source":"clob_market_ws"}
{"event_at":"2026-07-27T03:14:00.460000Z","event_fingerprint":"3178315ace7140cde2b164ba00358dce3779a4d7f517c947abb7d6935efe1925","payload":{"connection_id":"f95883f18d264834af91809e5f803e9f","event_at":"2026-07-27T03:14:00.460000Z","event_type":"price_change","frame_hash":"0dc79d80649379434a722cb4d7313c29e7fca2c361487d81985928695d8ae70b","frame_index":0,"kind":"data","monotonic_ns":224023772501041,"payload":{"event_type":"price_change","market":"0xf9d60bb033695053c4d1d8592e52171c1042f64b41a4b72e09dcc6f4852b6670","price_changes":[{"asset_id":"96283536366176669581486355171583722558858323126916278856549586825357358273536","best_ask":"0.15","best_bid":"0.14","hash":"ae5d52a1c41f540bb00d051d7d1924259e1f7008","price":"0.04","side":"BUY","size":"273.5"},{"asset_id":"8698449539441374295770236407991735029336433231649246775082939325523552031992","best_ask":"0.86","best_bid":"0.85","hash":"3ee97c44f99b9262873902e86d830b26d18dec3d","price":"0.96","side":"SELL","size":"273.5"}],"timestamp":"1785122040460"},"payload_hash":"78c57bb58499b0dc75c8304eb7cbf38cc11f0671506ed4d1d16e3ccd9108b8b9","raw_frame":"{\"market\":\"0xf9d60bb033695053c4d1d8592e52171c1042f64b41a4b72e09dcc6f4852b6670\", \"price_changes\":[{\"asset_id\":\"96283536366176669581486355171583722558858323126916278856549586825357358273536\", \"price\":\"0.04\", \"size\":\"273.5\", \"side\":\"BUY\", \"hash\":\"ae5d52a1c41f540bb00d051d7d1924259e1f7008\", \"best_bid\":\"0.14\", \"best_ask\":\"0.15\"}, {\"asset_id\":\"8698449539441374295770236407991735029336433231649246775082939325523552031992\", \"price\":\"0.96\", \"size\":\"273.5\", \"side\":\"SELL\", \"hash\":\"3ee97c44f99b9262873902e86d830b26d18dec3d\", \"best_bid\":\"0.85\", \"best_ask\":\"0.86\"}], \"timestamp\":\"1785122040460\", \"event_type\":\"price_change\"}","received_at":"2026-07-27T03:14:00.439672Z","schema_version":"clob-market-ws.price_change.v1","sequence":null,"server_hash":null,"server_timestamp":"1785122040460","session_id":"ff6d21c8283948938400a32613abec2c","source":"clob_market_ws"},"received_at":"2026-07-27T03:14:00.439672Z","record_id":"cd18af0cd4971e15aa69d00684502f8399c5628f22345e7a89cdd43fcf65cc7f","schema_fingerprint":"4aa3821a28b0b7c2400bc59aba4bcc0a76e971dadd19610d3ad38c768e124dc7","schema_version":"edge-lab-recorder.raw.v1","sequence":null,"source":"clob_market_ws"}
{"event_at":"2026-07-27T03:14:00.463000Z","event_fingerprint":"673e7ee06ba513b6179f9e2969eb917f23fadc012c891ac4b7c0c95d14e6abbf","payload":{"connection_id":"f95883f18d264834af91809e5f803e9f","event_at":"2026-07-27T03:14:00.463000Z","event_type":"price_change","frame_hash":"4c41432c90de127cff462d8301689cd2678bf3fc081001bab384c97ff5f906c9","frame_index":0,"kind":"data","monotonic_ns":224023773991250,"payload":{"event_type":"price_change","market":"0xf9d60bb033695053c4d1d8592e52171c1042f64b41a4b72e09dcc6f4852b6670","price_changes":[{"asset_id":"96283536366176669581486355171583722558858323126916278856549586825357358273536","best_ask":"0.15","best_bid":"0.14","hash":"8caf093bdf187642a1f00186a4c83c71e3a187c6","price":"0.3","side":"SELL","size":"80"},{"asset_id":"8698449539441374295770236407991735029336433231649246775082939325523552031992","best_ask":"0.86","best_bid":"0.85","hash":"786f3039043e7d08a83bf4d1c007d2264457eca1","price":"0.7","side":"BUY","size":"80"}],"timestamp":"1785122040463"},"payload_hash":"593676ac0d0706d003a62b179f2ff42fba5fa540e726e85cfe037317db16723b","raw_frame":"{\"market\":\"0xf9d60bb033695053c4d1d8592e52171c1042f64b41a4b72e09dcc6f4852b6670\", \"price_changes\":[{\"asset_id\":\"96283536366176669581486355171583722558858323126916278856549586825357358273536\", \"price\":\"0.3\", \"size\":\"80\", \"side\":\"SELL\", \"hash\":\"8caf093bdf187642a1f00186a4c83c71e3a187c6\", \"best_bid\":\"0.14\", \"best_ask\":\"0.15\"}, {\"asset_id\":\"8698449539441374295770236407991735029336433231649246775082939325523552031992\", \"price\":\"0.7\", \"size\":\"80\", \"side\":\"BUY\", \"hash\":\"786f3039043e7d08a83bf4d1c007d2264457eca1\", \"best_bid\":\"0.85\", \"best_ask\":\"0.86\"}], \"timestamp\":\"1785122040463\", \"event_type\":\"price_change\"}","received_at":"2026-07-27T03:14:00.441162Z","schema_version":"clob-market-ws.price_change.v1","sequence":null,"server_hash":null,"server_timestamp":"1785122040463","session_id":"ff6d21c8283948938400a32613abec2c","source":"clob_market_ws"},"received_at":"2026-07-27T03:14:00.441162Z","record_id":"56efecc1590fceb3d6816d9eb359b2673efcf2a834f8cc2b7837d13770056301","schema_fingerprint":"4aa3821a28b0b7c2400bc59aba4bcc0a76e971dadd19610d3ad38c768e124dc7","schema_version":"edge-lab-recorder.raw.v1","sequence":null,"source":"clob_market_ws"}
{"event_at":"2026-07-27T03:14:00.464000Z","event_fingerprint":"2a6daa03ac3ef0c29a96b8fce1f776d42984ab0e9cf312d78419a9aafa0f1567","payload":{"connection_id":"f95883f18d264834af91809e5f803e9f","event_at":"2026-07-27T03:14:00.464000Z","event_type":"best_bid_ask","frame_hash":"e5ed2e67ac63743932cdd0e93ce8979b4e434750f1377b54233500163498ec71","frame_index":0,"kind":"data","monotonic_ns":224023775503416,"payload":{"asset_id":"8698449539441374295770236407991735029336433231649246775082939325523552031992","best_ask":"0.87","best_bid":"0.85","event_type":"best_bid_ask","market":"0xf9d60bb033695053c4d1d8592e52171c1042f64b41a4b72e09dcc6f4852b6670","spread":"0.02","timestamp":"1785122040464"},"payload_hash":"8a0dbe4199c796a375226d3eef819f3955edeaed09ec2ffd2dbe8a2d42c739e7","raw_frame":"{\"market\":\"0xf9d60bb033695053c4d1d8592e52171c1042f64b41a4b72e09dcc6f4852b6670\", \"asset_id\":\"8698449539441374295770236407991735029336433231649246775082939325523552031992\", \"best_bid\":\"0.85\", \"best_ask\":\"0.87\", \"spread\":\"0.02\", \"timestamp\":\"1785122040464\", \"event_type\":\"best_bid_ask\"}","received_at":"2026-07-27T03:14:00.442678Z","schema_version":"clob-market-ws.best_bid_ask.v1","sequence":null,"server_hash":null,"server_timestamp":"1785122040464","session_id":"ff6d21c8283948938400a32613abec2c","source":"clob_market_ws"},"received_at":"2026-07-27T03:14:00.442678Z","record_id":"acd5358036fe609fb02efbb526a77abcea5f3521521e4215abb8ce824bf4069d","schema_fingerprint":"8488399f31b0337811b13b266be932db7062827c2470b78bd8e9e99bab51d17d","schema_version":"edge-lab-recorder.raw.v1","sequence":null,"source":"clob_market_ws"}
{"event_at":"2026-07-27T03:14:00.464000Z","event_fingerprint":"53581df78d73d0e46413b2308b2017fc0872f65129ff5a37d5ce0075f476c3af","payload":{"connection_id":"f95883f18d264834af91809e5f803e9f","event_at":"2026-07-27T03:14:00.464000Z","event_type":"best_bid_ask","frame_hash":"c38e1c102e9f75eb2b3fb378baadec32955a42384ba6201eb3270698e32beb1c","frame_index":0,"kind":"data","monotonic_ns":224023775980958,"payload":{"asset_id":"96283536366176669581486355171583722558858323126916278856549586825357358273536","best_ask":"0.15","best_bid":"0.13","event_type":"best_bid_ask","market":"0xf9d60bb033695053c4d1d8592e52171c1042f64b41a4b72e09dcc6f4852b6670","spread":"0.02","timestamp":"1785122040464"},"payload_hash":"481419c91d54e5ef57961fe61f2d4c7b1700c738d8223501fdff3d077656574f","raw_frame":"{\"market\":\"0xf9d60bb033695053c4d1d8592e52171c1042f64b41a4b72e09dcc6f4852b6670\", \"asset_id\":\"96283536366176669581486355171583722558858323126916278856549586825357358273536\", \"best_bid\":\"0.13\", \"best_ask\":\"0.15\", \"spread\":\"0.02\", \"timestamp\":\"1785122040464\", \"event_type\":\"best_bid_ask\"}","received_at":"2026-07-27T03:14:00.443156Z","schema_version":"clob-market-ws.best_bid_ask.v1","sequence":null,"server_hash":null,"server_timestamp":"1785122040464","session_id":"ff6d21c8283948938400a32613abec2c","source":"clob_market_ws"},"received_at":"2026-07-27T03:14:00.443156Z","record_id":"78c0882d6e2964a017f1be23a2ed6c83587c76a006f3649a4057efdbd4a55071","schema_fingerprint":"8488399f31b0337811b13b266be932db7062827c2470b78bd8e9e99bab51d17d","schema_version":"edge-lab-recorder.raw.v1","sequence":null,"source":"clob_market_ws"}
{"event_at":"2026-07-27T03:14:00.464000Z","event_fingerprint":"3429f7afd46797ca821f584577ae0e9881dd8b591aaf74f80af40c29ba5cf13f","payload":{"connection_id":"f95883f18d264834af91809e5f803e9f","event_at":"2026-07-27T03:14:00.464000Z","event_type":"price_change","frame_hash":"12a95f9e6d17fe4cdec4e5cb301acf59317b2da0327c05eb4a6602a9d87694dd","frame_index":0,"kind":"data","monotonic_ns":224023776592875,"payload":{"event_type":"price_change","market":"0xf9d60bb033695053c4d1d8592e52171c1042f64b41a4b72e09dcc6f4852b6670","price_changes":[{"asset_id":"96283536366176669581486355171583722558858323126916278856549586825357358273536","best_ask":"0.15","best_bid":"0.13","hash":"1d61d621e40c9b6827874322811c6272636be9a7","price":"0.14","side":"BUY","size":"0"},{"asset_id":"8698449539441374295770236407991735029336433231649246775082939325523552031992","best_ask":"0.87","best_bid":"0.85","hash":"33a2691b0076c705ed4a1727ad9ca84784d10ed6","price":"0.86","side":"SELL","size":"0"}],"timestamp":"1785122040464"},"payload_hash":"59c7def613a9b5f9c8018c0ceaec9a0f1eff17e92c68c3d447e0abc7de372ef4","raw_frame":"{\"market\":\"0xf9d60bb033695053c4d1d8592e52171c1042f64b41a4b72e09dcc6f4852b6670\", \"price_changes\":[{\"asset_id\":\"96283536366176669581486355171583722558858323126916278856549586825357358273536\", \"price\":\"0.14\", \"size\":\"0\", \"side\":\"BUY\", \"hash\":\"1d61d621e40c9b6827874322811c6272636be9a7\", \"best_bid\":\"0.13\", \"best_ask\":\"0.15\"}, {\"asset_id\":\"8698449539441374295770236407991735029336433231649246775082939325523552031992\", \"price\":\"0.86\", \"size\":\"0\", \"side\":\"SELL\", \"hash\":\"33a2691b0076c705ed4a1727ad9ca84784d10ed6\", \"best_bid\":\"0.85\", \"best_ask\":\"0.87\"}], \"timestamp\":\"1785122040464\", \"event_type\":\"price_change\"}","received_at":"2026-07-27T03:14:00.443763Z","schema_version":"clob-market-ws.price_change.v1","sequence":null,"server_hash":null,"server_timestamp":"1785122040464","session_id":"ff6d21c8283948938400a32613abec2c","source":"clob_market_ws"},"received_at":"2026-07-27T03:14:00.443763Z","record_id":"fad7b249fa0d2674b81f41ff13780ffe5b9b8a6d0702c952d7fbb70bd43c666d","schema_fingerprint":"4aa3821a28b0b7c2400bc59aba4bcc0a76e971dadd19610d3ad38c768e124dc7","schema_version":"edge-lab-recorder.raw.v1","sequence":null,"source":"clob_market_ws"}
{"event_at":"2026-07-27T03:14:00.467000Z","event_fingerprint":"f14460381a9c5de385cdb65651078f1c1035b554d701d5019e9450d34081dc9c","payload":{"connection_id":"f95883f18d264834af91809e5f803e9f","event_at":"2026-07-27T03:14:00.467000Z","event_type":"price_change","frame_hash":"726f5a5f32b7358678fa32be7656f544c74757a09b0e19fefd55e52b13bc69bb","frame_index":0,"kind":"data","monotonic_ns":224023777816291,"payload":{"event_type":"price_change","market":"0xf9d60bb033695053c4d1d8592e52171c1042f64b41a4b72e09dcc6f4852b6670","price_changes":[{"asset_id":"96283536366176669581486355171583722558858323126916278856549586825357358273536","best_ask":"0.15","best_bid":"0.13","hash":"f3a1d58751707069bdc8dea56796b193c2836bee","price":"0.03","side":"BUY","size":"301.5"},{"asset_id":"8698449539441374295770236407991735029336433231649246775082939325523552031992","best_ask":"0.87","best_bid":"0.85","hash":"925e642f8880dc7024c6697cb2f438018a3ca012","price":"0.97","side":"SELL","size":"301.5"}],"timestamp":"1785122040467"},"payload_hash":"f8fbbe4344c551e13e52de091c8061ad45921ada76694eebadd22d5bc7e3391a","raw_frame":"{\"market\":\"0xf9d60bb033695053c4d1d8592e52171c1042f64b41a4b72e09dcc6f4852b6670\", \"price_changes\":[{\"asset_id\":\"96283536366176669581486355171583722558858323126916278856549586825357358273536\", \"price\":\"0.03\", \"size\":\"301.5\", \"side\":\"BUY\", \"hash\":\"f3a1d58751707069bdc8dea56796b193c2836bee\", \"best_bid\":\"0.13\", \"best_ask\":\"0.15\"}, {\"asset_id\":\"8698449539441374295770236407991735029336433231649246775082939325523552031992\", \"price\":\"0.97\", \"size\":\"301.5\", \"side\":\"SELL\", \"hash\":\"925e642f8880dc7024c6697cb2f438018a3ca012\", \"best_bid\":\"0.85\", \"best_ask\":\"0.87\"}], \"timestamp\":\"1785122040467\", \"event_type\":\"price_change\"}","received_at":"2026-07-27T03:14:00.444992Z","schema_version":"clob-market-ws.price_change.v1","sequence":null,"server_hash":null,"server_timestamp":"1785122040467","session_id":"ff6d21c8283948938400a32613abec2c","source":"clob_market_ws"},"received_at":"2026-07-27T03:14:00.444992Z","record_id":"f38e6d27bc98df4729b8cd0acd68e36dcf0055bceaa90df1894b52700f553080","schema_fingerprint":"4aa3821a28b0b7c2400bc59aba4bcc0a76e971dadd19610d3ad38c768e124dc7","schema_version":"edge-lab-recorder.raw.v1","sequence":null,"source":"clob_market_ws"}
{"event_at":"2026-07-27T03:14:00.471000Z","event_fingerprint":"92fbfcf20c40414678470beceed796338f8ec6e78d7d51b45e5df9c4f58f82d7","payload":{"connection_id":"f95883f18d264834af91809e5f803e9f","event_at":"2026-07-27T03:14:00.471000Z","event_type":"price_change","frame_hash":"51cead18b33de0b6046f8498a57a6d1568d963af0641884f280c2ad0c54e0d46","frame_index":0,"kind":"data","monotonic_ns":224023778406083,"payload":{"event_type":"price_change","market":"0xf9d60bb033695053c4d1d8592e52171c1042f64b41a4b72e09dcc6f4852b6670","price_changes":[{"asset_id":"96283536366176669581486355171583722558858323126916278856549586825357358273536","best_ask":"0.15","best_bid":"0.13","hash":"111e8e15aa1923fe40465283dd91782f49f5de4e","price":"0.07","side":"BUY","size":"172"},{"asset_id":"8698449539441374295770236407991735029336433231649246775082939325523552031992","best_ask":"0.87","best_bid":"0.85","hash":"c59ced39c632841b40a35d935f2253d2da602027","price":"0.93","side":"SELL","size":"172"}],"timestamp":"1785122040471"},"payload_hash":"cd70a6a9acf8e26ea362c30d93b8213516b9f758674cec06a722c6b86be77229","raw_frame":"{\"market\":\"0xf9d60bb033695053c4d1d8592e52171c1042f64b41a4b72e09dcc6f4852b6670\", \"price_changes\":[{\"asset_id\":\"96283536366176669581486355171583722558858323126916278856549586825357358273536\", \"price\":\"0.07\", \"size\":\"172\", \"side\":\"BUY\", \"hash\":\"111e8e15aa1923fe40465283dd91782f49f5de4e\", \"best_bid\":\"0.13\", \"best_ask\":\"0.15\"}, {\"asset_id\":\"8698449539441374295770236407991735029336433231649246775082939325523552031992\", \"price\":\"0.93\", \"size\":\"172\", \"side\":\"SELL\", \"hash\":\"c59ced39c632841b40a35d935f2253d2da602027\", \"best_bid\":\"0.85\", \"best_ask\":\"0.87\"}], \"timestamp\":\"1785122040471\", \"event_type\":\"price_change\"}","received_at":"2026-07-27T03:14:00.445583Z","schema_version":"clob-market-ws.price_change.v1","sequence":null,"server_hash":null,"server_timestamp":"1785122040471","session_id":"ff6d21c8283948938400a32613abec2c","source":"clob_market_ws"},"received_at":"2026-07-27T03:14:00.445583Z","record_id":"1b94547e7dd03f10fce9bac8ca778c536238b62598fb9f4bf2a2bc7f5378a9ce","schema_fingerprint":"4aa3821a28b0b7c2400bc59aba4bcc0a76e971dadd19610d3ad38c768e124dc7","schema_version":"edge-lab-recorder.raw.v1","sequence":null,"source":"clob_market_ws"}
{"event_at":"2026-07-27T03:14:00.473000Z","event_fingerprint":"225de5813ce32a4f8095aa2eb1979ded6eb20a200c2d58295ee20fb0c9ab7909","payload":{"connection_id":"f95883f18d264834af91809e5f803e9f","event_at":"2026-07-27T03:14:00.473000Z","event_type":"price_change","frame_hash":"75b7f53d7b34cf475d05875df2dc79553d53e58bba228b01566d0371a898d163","frame_index":0,"kind":"data","monotonic_ns":224023779492916,"payload":{"event_type":"price_change","market":"0xf9d60bb033695053c4d1d8592e52171c1042f64b41a4b72e09dcc6f4852b6670","price_changes":[{"asset_id":"8698449539441374295770236407991735029336433231649246775082939325523552031992","best_ask":"0.87","best_bid":"0.85","hash":"782661b5ca09be2a5afa1d4e5113b9122ddc8057","price":"0.85","side":"BUY","size":"12.88"},{"asset_id":"96283536366176669581486355171583722558858323126916278856549586825357358273536","best_ask":"0.15","best_bid":"0.13","hash":"0889b1d41a32c1bcd0e79b1f4713ac58201bee2d","price":"0.15","side":"SELL","size":"12.88"}],"timestamp":"1785122040473"},"payload_hash":"994f0d95ed9ae33cb3f3e672286ed84c94f691fa5e78ff129122d257f9d82ba2","raw_frame":"{\"market\":\"0xf9d60bb033695053c4d1d8592e52171c1042f64b41a4b72e09dcc6f4852b6670\", \"price_changes\":[{\"asset_id\":\"8698449539441374295770236407991735029336433231649246775082939325523552031992\", \"price\":\"0.85\", \"size\":\"12.88\", \"side\":\"BUY\", \"hash\":\"782661b5ca09be2a5afa1d4e5113b9122ddc8057\", \"best_bid\":\"0.85\", \"best_ask\":\"0.87\"}, {\"asset_id\":\"96283536366176669581486355171583722558858323126916278856549586825357358273536\", \"price\":\"0.15\", \"size\":\"12.88\", \"side\":\"SELL\", \"hash\":\"0889b1d41a32c1bcd0e79b1f4713ac58201bee2d\", \"best_bid\":\"0.13\", \"best_ask\":\"0.15\"}], \"timestamp\":\"1785122040473\", \"event_type\":\"price_change\"}","received_at":"2026-07-27T03:14:00.446663Z","schema_version":"clob-market-ws.price_change.v1","sequence":null,"server_hash":null,"server_timestamp":"1785122040473","session_id":"ff6d21c8283948938400a32613abec2c","source":"clob_market_ws"},"received_at":"2026-07-27T03:14:00.446663Z","record_id":"e0015191b8974401739086b3fc0473e33ce26a4f716acbc19542fad98e76ffd7","schema_fingerprint":"4aa3821a28b0b7c2400bc59aba4bcc0a76e971dadd19610d3ad38c768e124dc7","schema_version":"edge-lab-recorder.raw.v1","sequence":null,"source":"clob_market_ws"}
{"event_at":"2026-07-27T03:14:00.474000Z","event_fingerprint":"c1a8a7d0d2b477f358a0e0731cb270fda1dafa025aa7e94da105e9f3c4eeedf8","payload":{"connection_id":"f95883f18d264834af91809e5f803e9f","event_at":"2026-07-27T03:14:00.474000Z","event_type":"price_change","frame_hash":"35a8c9bf8fd37ebca01e3939fd2e2807883a5bd096b786f30be3cada60a19e75","frame_index":0,"kind":"data","monotonic_ns":224023780163583,"payload":{"event_type":"price_change","market":"0xf9d60bb033695053c4d1d8592e52171c1042f64b41a4b72e09dcc6f4852b6670","price_changes":[{"asset_id":"96283536366176669581486355171583722558858323126916278856549586825357358273536","best_ask":"0.15","best_bid":"0.13","hash":"04f1ef0c93f6ac35592599b6b07dc308a5ce4ca2","price":"0.15","side":"SELL","size":"19.88"},{"asset_id":"8698449539441374295770236407991735029336433231649246775082939325523552031992","best_ask":"0.87","best_bid":"0.85","hash":"281fdaff7ac6da2cbd840931b80dbc0983f9e42d","price":"0.85","side":"BUY","size":"19.88"}],"timestamp":"1785122040474"},"payload_hash":"345b3b71221c3a969db9e74739f05d90485473f4c276e82cc28afd8b9473d610","raw_frame":"{\"market\":\"0xf9d60bb033695053c4d1d8592e52171c1042f64b41a4b72e09dcc6f4852b6670\", \"price_changes\":[{\"asset_id\":\"96283536366176669581486355171583722558858323126916278856549586825357358273536\", \"price\":\"0.15\", \"size\":\"19.88\", \"side\":\"SELL\", \"hash\":\"04f1ef0c93f6ac35592599b6b07dc308a5ce4ca2\", \"best_bid\":\"0.13\", \"best_ask\":\"0.15\"}, {\"asset_id\":\"8698449539441374295770236407991735029336433231649246775082939325523552031992\", \"price\":\"0.85\", \"size\":\"19.88\", \"side\":\"BUY\", \"hash\":\"281fdaff7ac6da2cbd840931b80dbc0983f9e42d\", \"best_bid\":\"0.85\", \"best_ask\":\"0.87\"}], \"timestamp\":\"1785122040474\", \"event_type\":\"price_change\"}","received_at":"2026-07-27T03:14:00.447338Z","schema_version":"clob-market-ws.price_change.v1","sequence":null,"server_hash":null,"server_timestamp":"1785122040474","session_id":"ff6d21c8283948938400a32613abec2c","source":"clob_market_ws"},"received_at":"2026-07-27T03:14:00.447338Z","record_id":"e8b6a2169931540de1b6c019beae124c179b289d4d89fb302a8d923e1338a8ba","schema_fingerprint":"4aa3821a28b0b7c2400bc59aba4bcc0a76e971dadd19610d3ad38c768e124dc7","schema_version":"edge-lab-recorder.raw.v1","sequence":null,"source":"clob_market_ws"}
{"event_at":"2026-07-27T03:14:00.475000Z","event_fingerprint":"63652965285b64189de44ada2b2916157b4401183f4545e59ecf3bead52310d8","payload":{"connection_id":"f95883f18d264834af91809e5f803e9f","event_at":"2026-07-27T03:14:00.475000Z","event_type":"price_change","frame_hash":"cbfb00ef043fb627993659fd220edecaa05d26ab2e81c8109b51290a9cc397a7","frame_index":0,"kind":"data","monotonic_ns":224023780781541,"payload":{"event_type":"price_change","market":"0xf9d60bb033695053c4d1d8592e52171c1042f64b41a4b72e09dcc6f4852b6670","price_changes":[{"asset_id":"8698449539441374295770236407991735029336433231649246775082939325523552031992","best_ask":"0.87","best_bid":"0.85","hash":"6342aaf3ad3eba3c0fcff1e1724800c59ec477b8","price":"0.85","side":"BUY","size":"24.88"},{"asset_id":"96283536366176669581486355171583722558858323126916278856549586825357358273536","best_ask":"0.15","best_bid":"0.13","hash":"c7ff713422e435baf45a14bedc946cde1bdc579c","price":"0.15","side":"SELL","size":"24.88"}],"timestamp":"1785122040475"},"payload_hash":"cb79c787f87d513459baac039920a39d46baec94a998c5e388fb15b536429b4d","raw_frame":"{\"market\":\"0xf9d60bb033695053c4d1d8592e52171c1042f64b41a4b72e09dcc6f4852b6670\", \"price_changes\":[{\"asset_id\":\"8698449539441374295770236407991735029336433231649246775082939325523552031992\", \"price\":\"0.85\", \"size\":\"24.88\", \"side\":\"BUY\", \"hash\":\"6342aaf3ad3eba3c0fcff1e1724800c59ec477b8\", \"best_bid\":\"0.85\", \"best_ask\":\"0.87\"}, {\"asset_id\":\"96283536366176669581486355171583722558858323126916278856549586825357358273536\", \"price\":\"0.15\", \"size\":\"24.88\", \"side\":\"SELL\", \"hash\":\"c7ff713422e435baf45a14bedc946cde1bdc579c\", \"best_bid\":\"0.13\", \"best_ask\":\"0.15\"}], \"timestamp\":\"1785122040475\", \"event_type\":\"price_change\"}","received_at":"2026-07-27T03:14:00.447958Z","schema_version":"clob-market-ws.price_change.v1","sequence":null,"server_hash":null,"server_timestamp":"1785122040475","session_id":"ff6d21c8283948938400a32613abec2c","source":"clob_market_ws"},"received_at":"2026-07-27T03:14:00.447958Z","record_id":"8c34fdfc80e2adb74e197c119232ffdaf23a12c066aa779bb7b45e9423e477c0","schema_fingerprint":"4aa3821a28b0b7c2400bc59aba4bcc0a76e971dadd19610d3ad38c768e124dc7","schema_version":"edge-lab-recorder.raw.v1","sequence":null,"source":"clob_market_ws"}
{"event_at":"2026-07-27T03:14:00.481000Z","event_fingerprint":"405d6b5573beca4d0c4fb46f48488a809c8f035dd1348ea371034356c8e1dd2d","payload":{"connection_id":"f95883f18d264834af91809e5f803e9f","event_at":"2026-07-27T03:14:00.481000Z","event_type":"price_change","frame_hash":"b026dca3f94ebe075620f99c58e7e9c5874774d8dd82a8a51ec6e325d0af3dcc","frame_index":0,"kind":"data","monotonic_ns":224023781722166,"payload":{"event_type":"price_change","market":"0xf9d60bb033695053c4d1d8592e52171c1042f64b41a4b72e09dcc6f4852b6670","price_changes":[{"asset_id":"8698449539441374295770236407991735029336433231649246775082939325523552031992","best_ask":"0.87","best_bid":"0.85","hash":"680114122415b8015c1b1691e0f547984d395c8f","price":"0.85","side":"BUY","size":"19.88"},{"asset_id":"96283536366176669581486355171583722558858323126916278856549586825357358273536","best_ask":"0.15","best_bid":"0.13","hash":"3df8c07c151eb5e33c5437a5b22723481d08eda0","price":"0.15","side":"SELL","size":"19.88"}],"timestamp":"1785122040481"},"payload_hash":"ec57b5577740202e7b4dd44db04e4394ea656121f47f7909679851c010bdd66f","raw_frame":"{\"market\":\"0xf9d60bb033695053c4d1d8592e52171c1042f64b41a4b72e09dcc6f4852b6670\", \"price_changes\":[{\"asset_id\":\"8698449539441374295770236407991735029336433231649246775082939325523552031992\", \"price\":\"0.85\", \"size\":\"19.88\", \"side\":\"BUY\", \"hash\":\"680114122415b8015c1b1691e0f547984d395c8f\", \"best_bid\":\"0.85\", \"best_ask\":\"0.87\"}, {\"asset_id\":\"96283536366176669581486355171583722558858323126916278856549586825357358273536\", \"price\":\"0.15\", \"size\":\"19.88\", \"side\":\"SELL\", \"hash\":\"3df8c07c151eb5e33c5437a5b22723481d08eda0\", \"best_bid\":\"0.13\", \"best_ask\":\"0.15\"}], \"timestamp\":\"1785122040481\", \"event_type\":\"price_change\"}","received_at":"2026-07-27T03:14:00.448898Z","schema_version":"clob-market-ws.price_change.v1","sequence":null,"server_hash":null,"server_timestamp":"1785122040481","session_id":"ff6d21c8283948938400a32613abec2c","source":"clob_market_ws"},"received_at":"2026-07-27T03:14:00.448898Z","record_id":"83bd86aae4de02e7b45596b5407cab05c8d96850c0e51c023ae905af0dee93ee","schema_fingerprint":"4aa3821a28b0b7c2400bc59aba4bcc0a76e971dadd19610d3ad38c768e124dc7","schema_version":"edge-lab-recorder.raw.v1","sequence":null,"source":"clob_market_ws"}
{"event_at":"2026-07-27T03:14:00.483000Z","event_fingerprint":"54475ae81b4939aef591319ab4faacd8e6f339f4e147bc9eaf3475d95e8c4acf","payload":{"connection_id":"f95883f18d264834af91809e5f803e9f","event_at":"2026-07-27T03:14:00.483000Z","event_type":"price_change","frame_hash":"73b2fe9c523982d09c94d1becfa0b548c1381327dc52febef083983a099064bb","frame_index":0,"kind":"data","monotonic_ns":224023782434958,"payload":{"event_type":"price_change","market":"0xf9d60bb033695053c4d1d8592e52171c1042f64b41a4b72e09dcc6f4852b6670","price_changes":[{"asset_id":"96283536366176669581486355171583722558858323126916278856549586825357358273536","best_ask":"0.15","best_bid":"0.13","hash":"eade6a751893c4b9b0fd79e65b61e7d8643c7601","price":"0.15","side":"SELL","size":"12.88"},{"asset_id":"8698449539441374295770236407991735029336433231649246775082939325523552031992","best_ask":"0.87","best_bid":"0.85","hash":"34088013b4e9042babdeb083a504b233177c39b5","price":"0.85","side":"BUY","size":"12.88"}],"timestamp":"1785122040483"},"payload_hash":"124c5b2b2c153789d522ac1c5ec994572dbea21aeac1c07a442c210eedd86ece","raw_frame":"{\"market\":\"0xf9d60bb033695053c4d1d8592e52171c1042f64b41a4b72e09dcc6f4852b6670\", \"price_changes\":[{\"asset_id\":\"96283536366176669581486355171583722558858323126916278856549586825357358273536\", \"price\":\"0.15\", \"size\":\"12.88\", \"side\":\"SELL\", \"hash\":\"eade6a751893c4b9b0fd79e65b61e7d8643c7601\", \"best_bid\":\"0.13\", \"best_ask\":\"0.15\"}, {\"asset_id\":\"8698449539441374295770236407991735029336433231649246775082939325523552031992\", \"price\":\"0.85\", \"size\":\"12.88\", \"side\":\"BUY\", \"hash\":\"34088013b4e9042babdeb083a504b233177c39b5\", \"best_bid\":\"0.85\", \"best_ask\":\"0.87\"}], \"timestamp\":\"1785122040483\", \"event_type\":\"price_change\"}","received_at":"2026-07-27T03:14:00.449606Z","schema_version":"clob-market-ws.price_change.v1","sequence":null,"server_hash":null,"server_timestamp":"1785122040483","session_id":"ff6d21c8283948938400a32613abec2c","source":"clob_market_ws"},"received_at":"2026-07-27T03:14:00.449606Z","record_id":"a061711abbdb5142ca653220b380708a4a821c7bfd492cbe70f2f2fc1e0c9a94","schema_fingerprint":"4aa3821a28b0b7c2400bc59aba4bcc0a76e971dadd19610d3ad38c768e124dc7","schema_version":"edge-lab-recorder.raw.v1","sequence":null,"source":"clob_market_ws"}
{"event_at":"2026-07-27T03:14:00.483000Z","event_fingerprint":"2790738a1c3383c8fdfb9d0061bc85e93d061cd09cdb86ea3984bf5968eccd46","payload":{"connection_id":"f95883f18d264834af91809e5f803e9f","event_at":"2026-07-27T03:14:00.483000Z","event_type":"price_change","frame_hash":"6da48a3692ebaacca48922dce35f59b2949466eebc45941c0a5ce8e68804633d","frame_index":0,"kind":"data","monotonic_ns":224023783942958,"payload":{"event_type":"price_change","market":"0xf9d60bb033695053c4d1d8592e52171c1042f64b41a4b72e09dcc6f4852b6670","price_changes":[{"asset_id":"8698449539441374295770236407991735029336433231649246775082939325523552031992","best_ask":"0.87","best_bid":"0.85","hash":"b5eed98835dc67661ebfc2cd94db3cb122949414","price":"0.85","side":"BUY","size":"7.88"},{"asset_id":"96283536366176669581486355171583722558858323126916278856549586825357358273536","best_ask":"0.15","best_bid":"0.13","hash":"88aa140a630bbe0677695019152a8b62082df8f3","price":"0.15","side":"SELL","size":"7.88"}],"timestamp":"1785122040483"},"payload_hash":"d05a5738acd0a72b51b0df2f82f0898e66c3b5ecd80687777fb06201863f4789","raw_frame":"{\"market\":\"0xf9d60bb033695053c4d1d8592e52171c1042f64b41a4b72e09dcc6f4852b6670\", \"price_changes\":[{\"asset_id\":\"8698449539441374295770236407991735029336433231649246775082939325523552031992\", \"price\":\"0.85\", \"size\":\"7.88\", \"side\":\"BUY\", \"hash\":\"b5eed98835dc67661ebfc2cd94db3cb122949414\", \"best_bid\":\"0.85\", \"best_ask\":\"0.87\"}, {\"asset_id\":\"96283536366176669581486355171583722558858323126916278856549586825357358273536\", \"price\":\"0.15\", \"size\":\"7.88\", \"side\":\"SELL\", \"hash\":\"88aa140a630bbe0677695019152a8b62082df8f3\", \"best_bid\":\"0.13\", \"best_ask\":\"0.15\"}], \"timestamp\":\"1785122040483\", \"event_type\":\"price_change\"}","received_at":"2026-07-27T03:14:00.451113Z","schema_version":"clob-market-ws.price_change.v1","sequence":null,"server_hash":null,"server_timestamp":"1785122040483","session_id":"ff6d21c8283948938400a32613abec2c","source":"clob_market_ws"},"received_at":"2026-07-27T03:14:00.451113Z","record_id":"93186d21617641d9081a9a034df818d9c6b6f65e7b68d6a06b0d8fd261c866f1","schema_fingerprint":"4aa3821a28b0b7c2400bc59aba4bcc0a76e971dadd19610d3ad38c768e124dc7","schema_version":"edge-lab-recorder.raw.v1","sequence":null,"source":"clob_market_ws"}
{"event_at":"2026-07-27T03:14:00.492000Z","event_fingerprint":"b1cfb1724793865f33dc074fa893d47f6c3eac47afbf0b537cf97ef61097fe5f","payload":{"connection_id":"f95883f18d264834af91809e5f803e9f","event_at":"2026-07-27T03:14:00.492000Z","event_type":"price_change","frame_hash":"ec4b0efc549d82d312e2f9c838296915180b5ea467150e2a096c9c3bbc09cd76","frame_index":0,"kind":"data","monotonic_ns":224023785587458,"payload":{"event_type":"price_change","market":"0xf9d60bb033695053c4d1d8592e52171c1042f64b41a4b72e09dcc6f4852b6670","price_changes":[{"asset_id":"96283536366176669581486355171583722558858323126916278856549586825357358273536","best_ask":"0.15","best_bid":"0.13","hash":"b9636baa8229a715017b9dbf7971f124929af0de","price":"0.07","side":"BUY","size":"167"},{"asset_id":"8698449539441374295770236407991735029336433231649246775082939325523552031992","best_ask":"0.87","best_bid":"0.85","hash":"af708c9ed30f171d40b62270173303e912645545","price":"0.93","side":"SELL","size":"167"}],"timestamp":"1785122040492"},"payload_hash":"c152be4a92393fbd83779c4360c36ddda3d5ddc5e6710bed73fcea2568d295d3","raw_frame":"{\"market\":\"0xf9d60bb033695053c4d1d8592e52171c1042f64b41a4b72e09dcc6f4852b6670\", \"price_changes\":[{\"asset_id\":\"96283536366176669581486355171583722558858323126916278856549586825357358273536\", \"price\":\"0.07\", \"size\":\"167\", \"side\":\"BUY\", \"hash\":\"b9636baa8229a715017b9dbf7971f124929af0de\", \"best_bid\":\"0.13\", \"best_ask\":\"0.15\"}, {\"asset_id\":\"8698449539441374295770236407991735029336433231649246775082939325523552031992\", \"price\":\"0.93\", \"size\":\"167\", \"side\":\"SELL\", \"hash\":\"af708c9ed30f171d40b62270173303e912645545\", \"best_bid\":\"0.85\", \"best_ask\":\"0.87\"}], \"timestamp\":\"1785122040492\", \"event_type\":\"price_change\"}","received_at":"2026-07-27T03:14:00.452754Z","schema_version":"clob-market-ws.price_change.v1","sequence":null,"server_hash":null,"server_timestamp":"1785122040492","session_id":"ff6d21c8283948938400a32613abec2c","source":"clob_market_ws"},"received_at":"2026-07-27T03:14:00.452754Z","record_id":"d0fddd206ce0a2bc7537de5fc99041d60d646ea7bdfe5ae50c4332b5cf2b9ee6","schema_fingerprint":"4aa3821a28b0b7c2400bc59aba4bcc0a76e971dadd19610d3ad38c768e124dc7","schema_version":"edge-lab-recorder.raw.v1","sequence":null,"source":"clob_market_ws"}
{"event_at":"2026-07-27T03:14:00.493000Z","event_fingerprint":"6649f7f32eb5e8713bbde17eddd2b09b56a902fa7d2a24af06aefdcf0ebe91be","payload":{"connection_id":"f95883f18d264834af91809e5f803e9f","event_at":"2026-07-27T03:14:00.493000Z","event_type":"best_bid_ask","frame_hash":"9b145bce9657ae14ad235cd6322c1e3da0de04a60d2c9b1a13a95dfc51cd1611","frame_index":0,"kind":"data","monotonic_ns":224023786716541,"payload":{"asset_id":"8698449539441374295770236407991735029336433231649246775082939325523552031992","best_ask":"0.86","best_bid":"0.85","event_type":"best_bid_ask","market":"0xf9d60bb033695053c4d1d8592e52171c1042f64b41a4b72e09dcc6f4852b6670","spread":"0.01","timestamp":"1785122040493"},"payload_hash":"ff4dc98525d8febfdf5177be50f5f6f22dd3527754442b3f3c4a17ac19f346e2","raw_frame":"{\"market\":\"0xf9d60bb033695053c4d1d8592e52171c1042f64b41a4b72e09dcc6f4852b6670\", \"asset_id\":\"8698449539441374295770236407991735029336433231649246775082939325523552031992\", \"best_bid\":\"0.85\", \"best_ask\":\"0.86\", \"spread\":\"0.01\", \"timestamp\":\"1785122040493\", \"event_type\":\"best_bid_ask\"}","received_at":"2026-07-27T03:14:00.453889Z","schema_version":"clob-market-ws.best_bid_ask.v1","sequence":null,"server_hash":null,"server_timestamp":"1785122040493","session_id":"ff6d21c8283948938400a32613abec2c","source":"clob_market_ws"},"received_at":"2026-07-27T03:14:00.453889Z","record_id":"90827e453024544a3b9732381df0d7135b2f5b73fee6a7f66dc9cc018191d6fe","schema_fingerprint":"8488399f31b0337811b13b266be932db7062827c2470b78bd8e9e99bab51d17d","schema_version":"edge-lab-recorder.raw.v1","sequence":null,"source":"clob_market_ws"}
{"event_at":"2026-07-27T03:14:00.493000Z","event_fingerprint":"6d72efa42d2a0517a7ca0bbc51b4e0976be631758eaa6ab9cddae261ae0e95b5","payload":{"connection_id":"f95883f18d264834af91809e5f803e9f","event_at":"2026-07-27T03:14:00.493000Z","event_type":"best_bid_ask","frame_hash":"8389711d4e4289e69a2f14541abecba10bc69856d1723cd00f75a5037fe7f247","frame_index":0,"kind":"data","monotonic_ns":224023787278291,"payload":{"asset_id":"96283536366176669581486355171583722558858323126916278856549586825357358273536","best_ask":"0.15","best_bid":"0.14","event_type":"best_bid_ask","market":"0xf9d60bb033695053c4d1d8592e52171c1042f64b41a4b72e09dcc6f4852b6670","spread":"0.01","timestamp":"1785122040493"},"payload_hash":"1017088acc9d51c3d23df868d76a58789313955c614bebf937bda605db307ef4","raw_frame":"{\"market\":\"0xf9d60bb033695053c4d1d8592e52171c1042f64b41a4b72e09dcc6f4852b6670\", \"asset_id\":\"96283536366176669581486355171583722558858323126916278856549586825357358273536\", \"best_bid\":\"0.14\", \"best_ask\":\"0.15\", \"spread\":\"0.01\", \"timestamp\":\"1785122040493\", \"event_type\":\"best_bid_ask\"}","received_at":"2026-07-27T03:14:00.454453Z","schema_version":"clob-market-ws.best_bid_ask.v1","sequence":null,"server_hash":null,"server_timestamp":"1785122040493","session_id":"ff6d21c8283948938400a32613abec2c","source":"clob_market_ws"},"received_at":"2026-07-27T03:14:00.454453Z","record_id":"c4965a2d55812631c4b4c4fe5cea10128dc9df3fb4fd0daf24c70b8ac412f94d","schema_fingerprint":"8488399f31b0337811b13b266be932db7062827c2470b78bd8e9e99bab51d17d","schema_version":"edge-lab-recorder.raw.v1","sequence":null,"source":"clob_market_ws"}
{"event_at":"2026-07-27T03:14:00.492000Z","event_fingerprint":"f4dbbcef94bd99db80c609ab323568756f35cfdecec3d318ad72dc8ccea22521","payload":{"connection_id":"f95883f18d264834af91809e5f803e9f","event_at":"2026-07-27T03:14:00.492000Z","event_type":"price_change","frame_hash":"183f19e9b01d109193fc4b2d36cb4dfd23e7ff9c88fa6245ef5adba5994463b5","frame_index":0,"kind":"data","monotonic_ns":224023792713541,"payload":{"event_type":"price_change","market":"0xf9d60bb033695053c4d1d8592e52171c1042f64b41a4b72e09dcc6f4852b6670","price_changes":[{"asset_id":"96283536366176669581486355171583722558858323126916278856549586825357358273536","best_ask":"0.15","best_bid":"0.14","hash":"5d377d491a9dba9ec0c3eaad5e82383c4aea3088","price":"0.14","side":"BUY","size":"75"},{"asset_id":"8698449539441374295770236407991735029336433231649246775082939325523552031992","best_ask":"0.86","best_bid":"0.85","hash":"a8602b369d8df6490aaa8ea66b8a3330a15e585d","price":"0.86","side":"SELL","size":"75"}],"timestamp":"1785122040492"},"payload_hash":"96163c20989ce63f2e21dfa68aa24fcd23f7d31c299828ab088d2363b3bda23d","raw_frame":"{\"market\":\"0xf9d60bb033695053c4d1d8592e52171c1042f64b41a4b72e09dcc6f4852b6670\", \"price_changes\":[{\"asset_id\":\"96283536366176669581486355171583722558858323126916278856549586825357358273536\", \"price\":\"0.14\", \"size\":\"75\", \"side\":\"BUY\", \"hash\":\"5d377d491a9dba9ec0c3eaad5e82383c4aea3088\", \"best_bid\":\"0.14\", \"best_ask\":\"0.15\"}, {\"asset_id\":\"8698449539441374295770236407991735029336433231649246775082939325523552031992\", \"price\":\"0.86\", \"size\":\"75\", \"side\":\"SELL\", \"hash\":\"a8602b369d8df6490aaa8ea66b8a3330a15e585d\", \"best_bid\":\"0.85\", \"best_ask\":\"0.86\"}], \"timestamp\":\"1785122040492\", \"event_type\":\"price_change\"}","received_at":"2026-07-27T03:14:00.459883Z","schema_version":"clob-market-ws.price_change.v1","sequence":null,"server_hash":null,"server_timestamp":"1785122040492","session_id":"ff6d21c8283948938400a32613abec2c","source":"clob_market_ws"},"received_at":"2026-07-27T03:14:00.459883Z","record_id":"7a83000369e6f1e81d4c4a2a940c026c2f43cda75a0294c9ea3d671c13cb4909","schema_fingerprint":"4aa3821a28b0b7c2400bc59aba4bcc0a76e971dadd19610d3ad38c768e124dc7","schema_version":"edge-lab-recorder.raw.v1","sequence":null,"source":"clob_market_ws"}
{"event_at":"2026-07-27T03:14:00.498000Z","event_fingerprint":"97f00056e9ac039b50d5b252f4a1757d51b2a1282aa7997511d45a53676a79ab","payload":{"connection_id":"f95883f18d264834af91809e5f803e9f","event_at":"2026-07-27T03:14:00.498000Z","event_type":"best_bid_ask","frame_hash":"f03d38c56391a32b5a1866cfc162bdcde8fec4187fa85de76debf26d540eb06f","frame_index":0,"kind":"data","monotonic_ns":224023797497041,"payload":{"asset_id":"8698449539441374295770236407991735029336433231649246775082939325523552031992","best_ask":"0.87","best_bid":"0.85","event_type":"best_bid_ask","market":"0xf9d60bb033695053c4d1d8592e52171c1042f64b41a4b72e09dcc6f4852b6670","spread":"0.02","timestamp":"1785122040498"},"payload_hash":"dc8f763f14f0e36af5e7fa7c5e4895e9943cd512dbb360308e05c97c55c7a19b","raw_frame":"{\"market\":\"0xf9d60bb033695053c4d1d8592e52171c1042f64b41a4b72e09dcc6f4852b6670\", \"asset_id\":\"8698449539441374295770236407991735029336433231649246775082939325523552031992\", \"best_bid\":\"0.85\", \"best_ask\":\"0.87\", \"spread\":\"0.02\", \"timestamp\":\"1785122040498\", \"event_type\":\"best_bid_ask\"}","received_at":"2026-07-27T03:14:00.464657Z","schema_version":"clob-market-ws.best_bid_ask.v1","sequence":null,"server_hash":null,"server_timestamp":"1785122040498","session_id":"ff6d21c8283948938400a32613abec2c","source":"clob_market_ws"},"received_at":"2026-07-27T03:14:00.464657Z","record_id":"01e1a42e438e43ccb69e6f6b29384a428c1eb16ba93f8524ab23d20bc5438d47","schema_fingerprint":"8488399f31b0337811b13b266be932db7062827c2470b78bd8e9e99bab51d17d","schema_version":"edge-lab-recorder.raw.v1","sequence":null,"source":"clob_market_ws"}
{"event_at":"2026-07-27T03:14:00.498000Z","event_fingerprint":"bd3d909c222a8933451876d7532a9bd109007e4a0dca9f94e2867e487af1ed94","payload":{"connection_id":"f95883f18d264834af91809e5f803e9f","event_at":"2026-07-27T03:14:00.498000Z","event_type":"best_bid_ask","frame_hash":"e556062c016d586976ed6d302043fea2ad74c5dead7b3a98de92817c909daa85","frame_index":0,"kind":"data","monotonic_ns":224023799655208,"payload":{"asset_id":"96283536366176669581486355171583722558858323126916278856549586825357358273536","best_ask":"0.15","best_bid":"0.13","event_type":"best_bid_ask","market":"0xf9d60bb033695053c4d1d8592e52171c1042f64b41a4b72e09dcc6f4852b6670","spread":"0.02","timestamp":"1785122040498"},"payload_hash":"e73d8de6e1e124133cd654f21d9784102b1e6afcdc83fd833a7f3f5df411af6d","raw_frame":"{\"market\":\"0xf9d60bb033695053c4d1d8592e52171c1042f64b41a4b72e09dcc6f4852b6670\", \"asset_id\":\"96283536366176669581486355171583722558858323126916278856549586825357358273536\", \"best_bid\":\"0.13\", \"best_ask\":\"0.15\", \"spread\":\"0.02\", \"timestamp\":\"1785122040498\", \"event_type\":\"best_bid_ask\"}","received_at":"2026-07-27T03:14:00.466827Z","schema_version":"clob-market-ws.best_bid_ask.v1","sequence":null,"server_hash":null,"server_timestamp":"1785122040498","session_id":"ff6d21c8283948938400a32613abec2c","source":"clob_market_ws"},"received_at":"2026-07-27T03:14:00.466827Z","record_id":"e5bd777135870e526fc330c5a359caeb7521d49a44bd228759633b588316a06d","schema_fingerprint":"8488399f31b0337811b13b266be932db7062827c2470b78bd8e9e99bab51d17d","schema_version":"edge-lab-recorder.raw.v1","sequence":null,"source":"clob_market_ws"}
{"event_at":"2026-07-27T03:14:00.498000Z","event_fingerprint":"01f02bddacf1526dc438886fa85188b9ff6295ffa82be63108cf1a0cb1bae771","payload":{"connection_id":"f95883f18d264834af91809e5f803e9f","event_at":"2026-07-27T03:14:00.498000Z","event_type":"price_change","frame_hash":"4ec1b94f3247aefe3f952bd0dfb3cd0cac01e31401397f66f02db8a764901609","frame_index":0,"kind":"data","monotonic_ns":224023801406750,"payload":{"event_type":"price_change","market":"0xf9d60bb033695053c4d1d8592e52171c1042f64b41a4b72e09dcc6f4852b6670","price_changes":[{"asset_id":"96283536366176669581486355171583722558858323126916278856549586825357358273536","best_ask":"0.15","best_bid":"0.13","hash":"32da660fa8c7595ae36504a0d45ba593f632a367","price":"0.14","side":"BUY","size":"0"},{"asset_id":"8698449539441374295770236407991735029336433231649246775082939325523552031992","best_ask":"0.87","best_bid":"0.85","hash":"e6d99ef50272722d3807690e1d42886866c63c15","price":"0.86","side":"SELL","size":"0"}],"timestamp":"1785122040498"},"payload_hash":"78f24dae23fa688ba4f9372d56cfcf4d26a9e517e41e9fc6d4f49fa5898073dd","raw_frame":"{\"market\":\"0xf9d60bb033695053c4d1d8592e52171c1042f64b41a4b72e09dcc6f4852b6670\", \"price_changes\":[{\"asset_id\":\"96283536366176669581486355171583722558858323126916278856549586825357358273536\", \"price\":\"0.14\", \"size\":\"0\", \"side\":\"BUY\", \"hash\":\"32da660fa8c7595ae36504a0d45ba593f632a367\", \"best_bid\":\"0.13\", \"best_ask\":\"0.15\"}, {\"asset_id\":\"8698449539441374295770236407991735029336433231649246775082939325523552031992\", \"price\":\"0.86\", \"size\":\"0\", \"side\":\"SELL\", \"hash\":\"e6d99ef50272722d3807690e1d42886866c63c15\", \"best_bid\":\"0.85\", \"best_ask\":\"0.87\"}], \"timestamp\":\"1785122040498\", \"event_type\":\"price_change\"}","received_at":"2026-07-27T03:14:00.468580Z","schema_version":"clob-market-ws.price_change.v1","sequence":null,"server_hash":null,"server_timestamp":"1785122040498","session_id":"ff6d21c8283948938400a32613abec2c","source":"clob_market_ws"},"received_at":"2026-07-27T03:14:00.468580Z","record_id":"f4aaee7c59a884241f1639871bc149f5da0142d241204e1aab44c68a013a1229","schema_fingerprint":"4aa3821a28b0b7c2400bc59aba4bcc0a76e971dadd19610d3ad38c768e124dc7","schema_version":"edge-lab-recorder.raw.v1","sequence":null,"source":"clob_market_ws"}
{"event_at":"2026-07-27T03:14:00.506000Z","event_fingerprint":"b9dff7474e2afbc6d5a8a8dacdcac612c190701e60574d0218382cecb066279b","payload":{"connection_id":"f95883f18d264834af91809e5f803e9f","event_at":"2026-07-27T03:14:00.506000Z","event_type":"price_change","frame_hash":"aeb0163fab387fcc3c8d91d4cd4d97898ef9c94a5ff73e0a9a8d4c4783b518e9","frame_index":0,"kind":"data","monotonic_ns":224023804112500,"payload":{"event_type":"price_change","market":"0xf9d60bb033695053c4d1d8592e52171c1042f64b41a4b72e09dcc6f4852b6670","price_changes":[{"asset_id":"8698449539441374295770236407991735029336433231649246775082939325523552031992","best_ask":"0.87","best_bid":"0.85","hash":"55bee1d97f14b73927b4032009c3cd6e59ff1426","price":"0.03","side":"BUY","size":"1178.8"},{"asset_id":"96283536366176669581486355171583722558858323126916278856549586825357358273536","best_ask":"0.15","best_bid":"0.13","hash":"1cd3977ff30e78a00e28e12b408100ad0d72ecac","price":"0.97","side":"SELL","size":"1178.8"}],"timestamp":"1785122040506"},"payload_hash":"8e1634efb8bf93f6b7970f4ee278f5f4c64f9c036275d8273ed9d8486fdcc385","raw_frame":"{\"market\":\"0xf9d60bb033695053c4d1d8592e52171c1042f64b41a4b72e09dcc6f4852b6670\", \"price_changes\":[{\"asset_id\":\"8698449539441374295770236407991735029336433231649246775082939325523552031992\", \"price\":\"0.03\", \"size\":\"1178.8\", \"side\":\"BUY\", \"hash\":\"55bee1d97f14b73927b4032009c3cd6e59ff1426\", \"best_bid\":\"0.85\", \"best_ask\":\"0.87\"}, {\"asset_id\":\"96283536366176669581486355171583722558858323126916278856549586825357358273536\", \"price\":\"0.97\", \"size\":\"1178.8\", \"side\":\"SELL\", \"hash\":\"1cd3977ff30e78a00e28e12b408100ad0d72ecac\", \"best_bid\":\"0.13\", \"best_ask\":\"0.15\"}], \"timestamp\":\"1785122040506\", \"event_type\":\"price_change\"}","received_at":"2026-07-27T03:14:00.471285Z","schema_version":"clob-market-ws.price_change.v1","sequence":null,"server_hash":null,"server_timestamp":"1785122040506","session_id":"ff6d21c8283948938400a32613abec2c","source":"clob_market_ws"},"received_at":"2026-07-27T03:14:00.471285Z","record_id":"ee71071bc54d256de0b3e6f6fe7f8b56a9d2673ca14d63f7ea44bf5de61ca8af","schema_fingerprint":"4aa3821a28b0b7c2400bc59aba4bcc0a76e971dadd19610d3ad38c768e124dc7","schema_version":"edge-lab-recorder.raw.v1","sequence":null,"source":"clob_market_ws"}
{"event_at":"2026-07-27T03:14:00.517000Z","event_fingerprint":"4480299c90398bc06d045970e49c607920765224bf917cf10cd137b7f1bbcc12","payload":{"connection_id":"f95883f18d264834af91809e5f803e9f","event_at":"2026-07-27T03:14:00.517000Z","event_type":"price_change","frame_hash":"549105ff2f6f80d02da59257fbb4c0574e4c7a180c738a7ac5b7eb14f50118ee","frame_index":0,"kind":"data","monotonic_ns":224023806281791,"payload":{"event_type":"price_change","market":"0xf9d60bb033695053c4d1d8592e52171c1042f64b41a4b72e09dcc6f4852b6670","price_changes":[{"asset_id":"8698449539441374295770236407991735029336433231649246775082939325523552031992","best_ask":"0.87","best_bid":"0.85","hash":"43abaa48c05ae271812e777f2bd42649c0f75c41","price":"0.82","side":"BUY","size":"103.2"},{"asset_id":"96283536366176669581486355171583722558858323126916278856549586825357358273536","best_ask":"0.15","best_bid":"0.13","hash":"6b8900649633dce81070c301d4534510833a9f5c","price":"0.18","side":"SELL","size":"103.2"}],"timestamp":"1785122040517"},"payload_hash":"35aff6b851de6bdb8d48edf0b2e807836e7431d678cb2cda62ffe67b3955ad89","raw_frame":"{\"market\":\"0xf9d60bb033695053c4d1d8592e52171c1042f64b41a4b72e09dcc6f4852b6670\", \"price_changes\":[{\"asset_id\":\"8698449539441374295770236407991735029336433231649246775082939325523552031992\", \"price\":\"0.82\", \"size\":\"103.2\", \"side\":\"BUY\", \"hash\":\"43abaa48c05ae271812e777f2bd42649c0f75c41\", \"best_bid\":\"0.85\", \"best_ask\":\"0.87\"}, {\"asset_id\":\"96283536366176669581486355171583722558858323126916278856549586825357358273536\", \"price\":\"0.18\", \"size\":\"103.2\", \"side\":\"SELL\", \"hash\":\"6b8900649633dce81070c301d4534510833a9f5c\", \"best_bid\":\"0.13\", \"best_ask\":\"0.15\"}], \"timestamp\":\"1785122040517\", \"event_type\":\"price_change\"}","received_at":"2026-07-27T03:14:00.473457Z","schema_version":"clob-market-ws.price_change.v1","sequence":null,"server_hash":null,"server_timestamp":"1785122040517","session_id":"ff6d21c8283948938400a32613abec2c","source":"clob_market_ws"},"received_at":"2026-07-27T03:14:00.473457Z","record_id":"0ad90a210327191d3c6ca641697870f14bdb119033cbc494623589d15e5d55a0","schema_fingerprint":"4aa3821a28b0b7c2400bc59aba4bcc0a76e971dadd19610d3ad38c768e124dc7","schema_version":"edge-lab-recorder.raw.v1","sequence":null,"source":"clob_market_ws"}
{"event_at":"2026-07-27T03:14:00.517000Z","event_fingerprint":"13d426b89ac7be464bd53af5901ab30da02dd362bdb57fef101231c0f4cb00cd","payload":{"connection_id":"f95883f18d264834af91809e5f803e9f","event_at":"2026-07-27T03:14:00.517000Z","event_type":"price_change","frame_hash":"4c7e5d76625e0444c3f73dd430440245e4a9b6ba0dbd619391f4c043a013a528","frame_index":0,"kind":"data","monotonic_ns":224023808933958,"payload":{"event_type":"price_change","market":"0xf9d60bb033695053c4d1d8592e52171c1042f64b41a4b72e09dcc6f4852b6670","price_changes":[{"asset_id":"96283536366176669581486355171583722558858323126916278856549586825357358273536","best_ask":"0.15","best_bid":"0.13","hash":"6b8900649633dce81070c301d4534510833a9f5c","price":"0.1","side":"BUY","size":"53.3"},{"asset_id":"8698449539441374295770236407991735029336433231649246775082939325523552031992","best_ask":"0.87","best_bid":"0.85","hash":"43abaa48c05ae271812e777f2bd42649c0f75c41","price":"0.9","side":"SELL","size":"53.3"}],"timestamp":"1785122040517"},"payload_hash":"8470bac8eec77a41352a6077654712ee08241230abdcf65c76a4202926249c44","raw_frame":"{\"market\":\"0xf9d60bb033695053c4d1d8592e52171c1042f64b41a4b72e09dcc6f4852b6670\", \"price_changes\":[{\"asset_id\":\"96283536366176669581486355171583722558858323126916278856549586825357358273536\", \"price\":\"0.1\", \"size\":\"53.3\", \"side\":\"BUY\", \"hash\":\"6b8900649633dce81070c301d4534510833a9f5c\", \"best_bid\":\"0.13\", \"best_ask\":\"0.15\"}, {\"asset_id\":\"8698449539441374295770236407991735029336433231649246775082939325523552031992\", \"price\":\"0.9\", \"size\":\"53.3\", \"side\":\"SELL\", \"hash\":\"43abaa48c05ae271812e777f2bd42649c0f75c41\", \"best_bid\":\"0.85\", \"best_ask\":\"0.87\"}], \"timestamp\":\"1785122040517\", \"event_type\":\"price_change\"}","received_at":"2026-07-27T03:14:00.476106Z","schema_version":"clob-market-ws.price_change.v1","sequence":null,"server_hash":null,"server_timestamp":"1785122040517","session_id":"ff6d21c8283948938400a32613abec2c","source":"clob_market_ws"},"received_at":"2026-07-27T03:14:00.476106Z","record_id":"654eaacb1e454cabebb68b1e381c5ed6b9c4409b72b7e1cec52b033cffbc54b0","schema_fingerprint":"4aa3821a28b0b7c2400bc59aba4bcc0a76e971dadd19610d3ad38c768e124dc7","schema_version":"edge-lab-recorder.raw.v1","sequence":null,"source":"clob_market_ws"}
{"event_at":"2026-07-27T03:14:00.517000Z","event_fingerprint":"a916adfd4efd6d2867bbf1b30be3f7c655c8569d369fc3a77ff198361f52b842","payload":{"connection_id":"f95883f18d264834af91809e5f803e9f","event_at":"2026-07-27T03:14:00.517000Z","event_type":"price_change","frame_hash":"48d45677342cef8cd12a81299597bccd8049b84e0a7128f443d2acc2ee1e1cf8","frame_index":0,"kind":"data","monotonic_ns":224023811796750,"payload":{"event_type":"price_change","market":"0xf9d60bb033695053c4d1d8592e52171c1042f64b41a4b72e09dcc6f4852b6670","price_changes":[{"asset_id":"8698449539441374295770236407991735029336433231649246775082939325523552031992","best_ask":"0.87","best_bid":"0.85","hash":"43abaa48c05ae271812e777f2bd42649c0f75c41","price":"0.83","side":"BUY","size":"38.3"},{"asset_id":"96283536366176669581486355171583722558858323126916278856549586825357358273536","best_ask":"0.15","best_bid":"0.13","hash":"6b8900649633dce81070c301d4534510833a9f5c","price":"0.17","side":"SELL","size":"38.3"}],"timestamp":"1785122040517"},"payload_hash":"6b3ff6690c519c208109cce2a7df94dce1e4bb0c9d67ccf336c1f0306ea81e35","raw_frame":"{\"market\":\"0xf9d60bb033695053c4d1d8592e52171c1042f64b41a4b72e09dcc6f4852b6670\", \"price_changes\":[{\"asset_id\":\"8698449539441374295770236407991735029336433231649246775082939325523552031992\", \"price\":\"0.83\", \"size\":\"38.3\", \"side\":\"BUY\", \"hash\":\"43abaa48c05ae271812e777f2bd42649c0f75c41\", \"best_bid\":\"0.85\", \"best_ask\":\"0.87\"}, {\"asset_id\":\"96283536366176669581486355171583722558858323126916278856549586825357358273536\", \"price\":\"0.17\", \"size\":\"38.3\", \"side\":\"SELL\", \"hash\":\"6b8900649633dce81070c301d4534510833a9f5c\", \"best_bid\":\"0.13\", \"best_ask\":\"0.15\"}], \"timestamp\":\"1785122040517\", \"event_type\":\"price_change\"}","received_at":"2026-07-27T03:14:00.478965Z","schema_version":"clob-market-ws.price_change.v1","sequence":null,"server_hash":null,"server_timestamp":"1785122040517","session_id":"ff6d21c8283948938400a32613abec2c","source":"clob_market_ws"},"received_at":"2026-07-27T03:14:00.478965Z","record_id":"2e6d2b5045ec3937d5a5ee997064f8d08baa87c0b5e7c0b0e61af019aa42e2f9","schema_fingerprint":"4aa3821a28b0b7c2400bc59aba4bcc0a76e971dadd19610d3ad38c768e124dc7","schema_version":"edge-lab-recorder.raw.v1","sequence":null,"source":"clob_market_ws"}
{"event_at":"2026-07-27T03:14:00.518000Z","event_fingerprint":"af25520eba6a8be8e913d890d2def893ac96592cfccd229dfe520c551937d8e0","payload":{"connection_id":"f95883f18d264834af91809e5f803e9f","event_at":"2026-07-27T03:14:00.518000Z","event_type":"price_change","frame_hash":"c34445abd0823d1f0c6b89c7b1a9b1762e3ac551e02b456c610a610c72349592","frame_index":0,"kind":"data","monotonic_ns":224023813919166,"payload":{"event_type":"price_change","market":"0xf9d60bb033695053c4d1d8592e52171c1042f64b41a4b72e09dcc6f4852b6670","price_changes":[{"asset_id":"96283536366176669581486355171583722558858323126916278856549586825357358273536","best_ask":"0.15","best_bid":"0.13","hash":"062dbe579ccdda5efa97365897ed4e150fcc8cbe","price":"0.15","side":"SELL","size":"14.88"},{"asset_id":"8698449539441374295770236407991735029336433231649246775082939325523552031992","best_ask":"0.87","best_bid":"0.85","hash":"d3e2e50267b6cdf33688d1877a6e4dd6c9a0dc60","price":"0.85","side":"BUY","size":"14.88"}],"timestamp":"1785122040518"},"payload_hash":"9bd36b5d7e1e2aa7dbdbdba61b44f14479bd58ed4b3b8e5d01b2a41fc37da8ab","raw_frame":"{\"market\":\"0xf9d60bb033695053c4d1d8592e52171c1042f64b41a4b72e09dcc6f4852b6670\", \"price_changes\":[{\"asset_id\":\"96283536366176669581486355171583722558858323126916278856549586825357358273536\", \"price\":\"0.15\", \"size\":\"14.88\", \"side\":\"SELL\", \"hash\":\"062dbe579ccdda5efa97365897ed4e150fcc8cbe\", \"best_bid\":\"0.13\", \"best_ask\":\"0.15\"}, {\"asset_id\":\"8698449539441374295770236407991735029336433231649246775082939325523552031992\", \"price\":\"0.85\", \"size\":\"14.88\", \"side\":\"BUY\", \"hash\":\"d3e2e50267b6cdf33688d1877a6e4dd6c9a0dc60\", \"best_bid\":\"0.85\", \"best_ask\":\"0.87\"}], \"timestamp\":\"1785122040518\", \"event_type\":\"price_change\"}","received_at":"2026-07-27T03:14:00.481093Z","schema_version":"clob-market-ws.price_change.v1","sequence":null,"server_hash":null,"server_timestamp":"1785122040518","session_id":"ff6d21c8283948938400a32613abec2c","source":"clob_market_ws"},"received_at":"2026-07-27T03:14:00.481093Z","record_id":"c818140ead7659b5f15244d8281ae22322cafa95431419b8d9f623e5e9ecd860","schema_fingerprint":"4aa3821a28b0b7c2400bc59aba4bcc0a76e971dadd19610d3ad38c768e124dc7","schema_version":"edge-lab-recorder.raw.v1","sequence":null,"source":"clob_market_ws"}
{"event_at":"2026-07-27T03:14:00.519000Z","event_fingerprint":"97f4fbd67a3a5e6a47b20b99f6fce08ba0fbcbb1349243d1048663a8eee9c986","payload":{"connection_id":"f95883f18d264834af91809e5f803e9f","event_at":"2026-07-27T03:14:00.519000Z","event_type":"price_change","frame_hash":"d7db0b7c59c0d5436147146ad3550f49f647364f4d2a3562d1943af230032dfd","frame_index":0,"kind":"data","monotonic_ns":224023814612041,"payload":{"event_type":"price_change","market":"0xf9d60bb033695053c4d1d8592e52171c1042f64b41a4b72e09dcc6f4852b6670","price_changes":[{"asset_id":"96283536366176669581486355171583722558858323126916278856549586825357358273536","best_ask":"0.15","best_bid":"0.13","hash":"cd173185c2a7092e319e53f21001f6c1b3791632","price":"0.15","side":"SELL","size":"7.88"},{"asset_id":"8698449539441374295770236407991735029336433231649246775082939325523552031992","best_ask":"0.87","best_bid":"0.85","hash":"2ba196df5762d8598d607242cd7fe25528eda776","price":"0.85","side":"BUY","size":"7.88"}],"timestamp":"1785122040519"},"payload_hash":"746283e67bc3c0172d2875133fc36678b459596cf5fa2b3e72c3b521da430556","raw_frame":"{\"market\":\"0xf9d60bb033695053c4d1d8592e52171c1042f64b41a4b72e09dcc6f4852b6670\", \"price_changes\":[{\"asset_id\":\"96283536366176669581486355171583722558858323126916278856549586825357358273536\", \"price\":\"0.15\", \"size\":\"7.88\", \"side\":\"SELL\", \"hash\":\"cd173185c2a7092e319e53f21001f6c1b3791632\", \"best_bid\":\"0.13\", \"best_ask\":\"0.15\"}, {\"asset_id\":\"8698449539441374295770236407991735029336433231649246775082939325523552031992\", \"price\":\"0.85\", \"size\":\"7.88\", \"side\":\"BUY\", \"hash\":\"2ba196df5762d8598d607242cd7fe25528eda776\", \"best_bid\":\"0.85\", \"best_ask\":\"0.87\"}], \"timestamp\":\"1785122040519\", \"event_type\":\"price_change\"}","received_at":"2026-07-27T03:14:00.481787Z","schema_version":"clob-market-ws.price_change.v1","sequence":null,"server_hash":null,"server_timestamp":"1785122040519","session_id":"ff6d21c8283948938400a32613abec2c","source":"clob_market_ws"},"received_at":"2026-07-27T03:14:00.481787Z","record_id":"8e13a428e68b64f8745f8ac6e3904f243fae2f615e2f7eefc037d528251e86fe","schema_fingerprint":"4aa3821a28b0b7c2400bc59aba4bcc0a76e971dadd19610d3ad38c768e124dc7","schema_version":"edge-lab-recorder.raw.v1","sequence":null,"source":"clob_market_ws"}
{"event_at":"2026-07-27T03:14:00.520000Z","event_fingerprint":"0d699b9403fb9ff697f267100958e82d99a0620d1a7c9561932474611915bf9d","payload":{"connection_id":"f95883f18d264834af91809e5f803e9f","event_at":"2026-07-27T03:14:00.520000Z","event_type":"price_change","frame_hash":"219c3a2117e414d35882cdd1f918f474a550f93129bfbbcf3cd379f3019bddc6","frame_index":0,"kind":"data","monotonic_ns":224023815801083,"payload":{"event_type":"price_change","market":"0xf9d60bb033695053c4d1d8592e52171c1042f64b41a4b72e09dcc6f4852b6670","price_changes":[{"asset_id":"96283536366176669581486355171583722558858323126916278856549586825357358273536","best_ask":"0.15","best_bid":"0.13","hash":"dcf34a2e15df26bd343b34f5a7fed3b6d82a576a","price":"0.11","side":"BUY","size":"80"},{"asset_id":"8698449539441374295770236407991735029336433231649246775082939325523552031992","best_ask":"0.87","best_bid":"0.85","hash":"76b8d2608531fb8b7596d76c13429950cfa79dfb","price":"0.89","side":"SELL","size":"80"}],"timestamp":"1785122040520"},"payload_hash":"695fddceeae6c3cc9d7de06380bd39431d136685cb58ce5b9b4ae05fa853fec1","raw_frame":"{\"market\":\"0xf9d60bb033695053c4d1d8592e52171c1042f64b41a4b72e09dcc6f4852b6670\", \"price_changes\":[{\"asset_id\":\"96283536366176669581486355171583722558858323126916278856549586825357358273536\", \"price\":\"0.11\", \"size\":\"80\", \"side\":\"BUY\", \"hash\":\"dcf34a2e15df26bd343b34f5a7fed3b6d82a576a\", \"best_bid\":\"0.13\", \"best_ask\":\"0.15\"}, {\"asset_id\":\"8698449539441374295770236407991735029336433231649246775082939325523552031992\", \"price\":\"0.89\", \"size\":\"80\", \"side\":\"SELL\", \"hash\":\"76b8d2608531fb8b7596d76c13429950cfa79dfb\", \"best_bid\":\"0.85\", \"best_ask\":\"0.87\"}], \"timestamp\":\"1785122040520\", \"event_type\":\"price_change\"}","received_at":"2026-07-27T03:14:00.482971Z","schema_version":"clob-market-ws.price_change.v1","sequence":null,"server_hash":null,"server_timestamp":"1785122040520","session_id":"ff6d21c8283948938400a32613abec2c","source":"clob_market_ws"},"received_at":"2026-07-27T03:14:00.482971Z","record_id":"64e5fbe757e3e0cbb032e4276f35d35c69a4aaa37c981f24333e7ff08fa7b0e5","schema_fingerprint":"4aa3821a28b0b7c2400bc59aba4bcc0a76e971dadd19610d3ad38c768e124dc7","schema_version":"edge-lab-recorder.raw.v1","sequence":null,"source":"clob_market_ws"}
{"event_at":"2026-07-27T03:14:00.522000Z","event_fingerprint":"2146590bc54798f310d42003a165de640f23f8ec9b3c6f4d1d11327585799367","payload":{"connection_id":"f95883f18d264834af91809e5f803e9f","event_at":"2026-07-27T03:14:00.522000Z","event_type":"price_change","frame_hash":"5362680f6514b0ac64bd24e1951c231b0b860b7c5b2b287cd66b4e85c86174ea","frame_index":0,"kind":"data","monotonic_ns":224023817414416,"payload":{"event_type":"price_change","market":"0xf9d60bb033695053c4d1d8592e52171c1042f64b41a4b72e09dcc6f4852b6670","price_changes":[{"asset_id":"96283536366176669581486355171583722558858323126916278856549586825357358273536","best_ask":"0.15","best_bid":"0.13","hash":"afc3457ceeafb7563ed1458b8573aae5e12c2993","price":"0.07","side":"BUY","size":"157"},{"asset_id":"8698449539441374295770236407991735029336433231649246775082939325523552031992","best_ask":"0.87","best_bid":"0.85","hash":"dc985450710aca811594cbb080d91e2642aec985","price":"0.93","side":"SELL","size":"157"}],"timestamp":"1785122040522"},"payload_hash":"090e76529fd2f7f05a78e74db2485ed17ede41bdfd71fdca1f2c58681a1d1d81","raw_frame":"{\"market\":\"0xf9d60bb033695053c4d1d8592e52171c1042f64b41a4b72e09dcc6f4852b6670\", \"price_changes\":[{\"asset_id\":\"96283536366176669581486355171583722558858323126916278856549586825357358273536\", \"price\":\"0.07\", \"size\":\"157\", \"side\":\"BUY\", \"hash\":\"afc3457ceeafb7563ed1458b8573aae5e12c2993\", \"best_bid\":\"0.13\", \"best_ask\":\"0.15\"}, {\"asset_id\":\"8698449539441374295770236407991735029336433231649246775082939325523552031992\", \"price\":\"0.93\", \"size\":\"157\", \"side\":\"SELL\", \"hash\":\"dc985450710aca811594cbb080d91e2642aec985\", \"best_bid\":\"0.85\", \"best_ask\":\"0.87\"}], \"timestamp\":\"1785122040522\", \"event_type\":\"price_change\"}","received_at":"2026-07-27T03:14:00.484584Z","schema_version":"clob-market-ws.price_change.v1","sequence":null,"server_hash":null,"server_timestamp":"1785122040522","session_id":"ff6d21c8283948938400a32613abec2c","source":"clob_market_ws"},"received_at":"2026-07-27T03:14:00.484584Z","record_id":"c5a2286f7a24085003bcd05f3a598f891c88da07ba9171b319145ccacea3fb88","schema_fingerprint":"4aa3821a28b0b7c2400bc59aba4bcc0a76e971dadd19610d3ad38c768e124dc7","schema_version":"edge-lab-recorder.raw.v1","sequence":null,"source":"clob_market_ws"}
{"event_at":"2026-07-27T03:14:00.546000Z","event_fingerprint":"62f72087a0995f0626e3e0d3f6b460886d8667ce49d114045d02b675f25f7cd2","payload":{"connection_id":"f95883f18d264834af91809e5f803e9f","event_at":"2026-07-27T03:14:00.546000Z","event_type":"price_change","frame_hash":"65b9bb01f55884de873eefa37cb1e1bdb38f0218cb301ac45f5493e4a6199f4e","frame_index":0,"kind":"data","monotonic_ns":224023818965500,"payload":{"event_type":"price_change","market":"0xf9d60bb033695053c4d1d8592e52171c1042f64b41a4b72e09dcc6f4852b6670","price_changes":[{"asset_id":"96283536366176669581486355171583722558858323126916278856549586825357358273536","best_ask":"0.15","best_bid":"0.13","hash":"bd79de7d7526abf6ebba06b6f9b7adc601dc3694","price":"0.1","side":"BUY","size":"58.3"},{"asset_id":"8698449539441374295770236407991735029336433231649246775082939325523552031992","best_ask":"0.87","best_bid":"0.85","hash":"fa7215002c37753a5ea49e836732eb5b6d707ee6","price":"0.9","side":"SELL","size":"58.3"}],"timestamp":"1785122040546"},"payload_hash":"737969de8dd79b29c6b28543d154e20409fbd85650cbd223cdf7e1498b881cfb","raw_frame":"{\"market\":\"0xf9d60bb033695053c4d1d8592e52171c1042f64b41a4b72e09dcc6f4852b6670\", \"price_changes\":[{\"asset_id\":\"96283536366176669581486355171583722558858323126916278856549586825357358273536\", \"price\":\"0.1\", \"size\":\"58.3\", \"side\":\"BUY\", \"hash\":\"bd79de7d7526abf6ebba06b6f9b7adc601dc3694\", \"best_bid\":\"0.13\", \"best_ask\":\"0.15\"}, {\"asset_id\":\"8698449539441374295770236407991735029336433231649246775082939325523552031992\", \"price\":\"0.9\", \"size\":\"58.3\", \"side\":\"SELL\", \"hash\":\"fa7215002c37753a5ea49e836732eb5b6d707ee6\", \"best_bid\":\"0.85\", \"best_ask\":\"0.87\"}], \"timestamp\":\"1785122040546\", \"event_type\":\"price_change\"}","received_at":"2026-07-27T03:14:00.486133Z","schema_version":"clob-market-ws.price_change.v1","sequence":null,"server_hash":null,"server_timestamp":"1785122040546","session_id":"ff6d21c8283948938400a32613abec2c","source":"clob_market_ws"},"received_at":"2026-07-27T03:14:00.486133Z","record_id":"0e3b4bb51db0114116a8aeead00b43215015534e87ee06f513044e98e845639a","schema_fingerprint":"4aa3821a28b0b7c2400bc59aba4bcc0a76e971dadd19610d3ad38c768e124dc7","schema_version":"edge-lab-recorder.raw.v1","sequence":null,"source":"clob_market_ws"}
{"event_at":"2026-07-27T03:14:00.547000Z","event_fingerprint":"c1f2e2bb1f533ed5af07d7087f2e658bc54f8969ec376fa4d278155c1ada58ee","payload":{"connection_id":"f95883f18d264834af91809e5f803e9f","event_at":"2026-07-27T03:14:00.547000Z","event_type":"price_change","frame_hash":"3013d942020999a7fc7669d93b275331109b58a29378932d0c8eabf13d9ccaa1","frame_index":0,"kind":"data","monotonic_ns":224023820596750,"payload":{"event_type":"price_change","market":"0xf9d60bb033695053c4d1d8592e52171c1042f64b41a4b72e09dcc6f4852b6670","price_changes":[{"asset_id":"8698449539441374295770236407991735029336433231649246775082939325523552031992","best_ask":"0.87","best_bid":"0.85","hash":"ef3c7c83fa7eb679c064a611adcf0cf3d2b8d399","price":"0.78","side":"BUY","size":"66.2"},{"asset_id":"96283536366176669581486355171583722558858323126916278856549586825357358273536","best_ask":"0.15","best_bid":"0.13","hash":"223ed3e2b687f17e1350db4fc84943f0f33cca1f","price":"0.22","side":"SELL","size":"66.2"}],"timestamp":"1785122040547"},"payload_hash":"51f4fee8556580c9af762684d70a81d12bdaa24ca296e43a11c6c51f5f837618","raw_frame":"{\"market\":\"0xf9d60bb033695053c4d1d8592e52171c1042f64b41a4b72e09dcc6f4852b6670\", \"price_changes\":[{\"asset_id\":\"8698449539441374295770236407991735029336433231649246775082939325523552031992\", \"price\":\"0.78\", \"size\":\"66.2\", \"side\":\"BUY\", \"hash\":\"ef3c7c83fa7eb679c064a611adcf0cf3d2b8d399\", \"best_bid\":\"0.85\", \"best_ask\":\"0.87\"}, {\"asset_id\":\"96283536366176669581486355171583722558858323126916278856549586825357358273536\", \"price\":\"0.22\", \"size\":\"66.2\", \"side\":\"SELL\", \"hash\":\"223ed3e2b687f17e1350db4fc84943f0f33cca1f\", \"best_bid\":\"0.13\", \"best_ask\":\"0.15\"}], \"timestamp\":\"1785122040547\", \"event_type\":\"price_change\"}","received_at":"2026-07-27T03:14:00.487765Z","schema_version":"clob-market-ws.price_change.v1","sequence":null,"server_hash":null,"server_timestamp":"1785122040547","session_id":"ff6d21c8283948938400a32613abec2c","source":"clob_market_ws"},"received_at":"2026-07-27T03:14:00.487765Z","record_id":"4059a0cca9bc8e315b32733bae0003cfeeb80e12975764695975baffda3ca5bb","schema_fingerprint":"4aa3821a28b0b7c2400bc59aba4bcc0a76e971dadd19610d3ad38c768e124dc7","schema_version":"edge-lab-recorder.raw.v1","sequence":null,"source":"clob_market_ws"}
{"event_at":"2026-07-27T03:14:00.549000Z","event_fingerprint":"67e1401d1fe4b7bd3e698ec358dfc6250f76bbb778d9d19268a415ae1e0ab459","payload":{"connection_id":"f95883f18d264834af91809e5f803e9f","event_at":"2026-07-27T03:14:00.549000Z","event_type":"price_change","frame_hash":"98848262e2b15fbf8cb6d1a7ece79f5314bef3e25885cdbcca8f4fec20e3f9af","frame_index":0,"kind":"data","monotonic_ns":224023822408125,"payload":{"event_type":"price_change","market":"0xf9d60bb033695053c4d1d8592e52171c1042f64b41a4b72e09dcc6f4852b6670","price_changes":[{"asset_id":"96283536366176669581486355171583722558858323126916278856549586825357358273536","best_ask":"0.15","best_bid":"0.13","hash":"e85dc93cfd60c1fe1665fb9b9ce8cbca9d340dd5","price":"0.1","side":"BUY","size":"63.3"},{"asset_id":"8698449539441374295770236407991735029336433231649246775082939325523552031992","best_ask":"0.87","best_bid":"0.85","hash":"67cf257af15c4c4e30e34b7f36398f041f99cb16","price":"0.9","side":"SELL","size":"63.3"}],"timestamp":"1785122040549"},"payload_hash":"7b0800795213184078b0421e212fcf0183bbf968f1ff29f2c3cb22338dc466de","raw_frame":"{\"market\":\"0xf9d60bb033695053c4d1d8592e52171c1042f64b41a4b72e09dcc6f4852b6670\", \"price_changes\":[{\"asset_id\":\"96283536366176669581486355171583722558858323126916278856549586825357358273536\", \"price\":\"0.1\", \"size\":\"63.3\", \"side\":\"BUY\", \"hash\":\"e85dc93cfd60c1fe1665fb9b9ce8cbca9d340dd5\", \"best_bid\":\"0.13\", \"best_ask\":\"0.15\"}, {\"asset_id\":\"8698449539441374295770236407991735029336433231649246775082939325523552031992\", \"price\":\"0.9\", \"size\":\"63.3\", \"side\":\"SELL\", \"hash\":\"67cf257af15c4c4e30e34b7f36398f041f99cb16\", \"best_bid\":\"0.85\", \"best_ask\":\"0.87\"}], \"timestamp\":\"1785122040549\", \"event_type\":\"price_change\"}","received_at":"2026-07-27T03:14:00.489577Z","schema_version":"clob-market-ws.price_change.v1","sequence":null,"server_hash":null,"server_timestamp":"1785122040549","session_id":"ff6d21c8283948938400a32613abec2c","source":"clob_market_ws"},"received_at":"2026-07-27T03:14:00.489577Z","record_id":"1f3b253848ef65498c0802d22d63cf310619f493aae38e64708d1f48ffe33573","schema_fingerprint":"4aa3821a28b0b7c2400bc59aba4bcc0a76e971dadd19610d3ad38c768e124dc7","schema_version":"edge-lab-recorder.raw.v1","sequence":null,"source":"clob_market_ws"}
{"event_at":"2026-07-27T03:14:00.555000Z","event_fingerprint":"e7143f1c4cf0247ce680d7f57bd192492f040e09850ec108c8ced4764ec55c63","payload":{"connection_id":"f95883f18d264834af91809e5f803e9f","event_at":"2026-07-27T03:14:00.555000Z","event_type":"price_change","frame_hash":"2546ff53e3d8634bac827617227234492be7418a11eebcadcdf3236dc522e03b","frame_index":0,"kind":"data","monotonic_ns":224023823953041,"payload":{"event_type":"price_change","market":"0xf9d60bb033695053c4d1d8592e52171c1042f64b41a4b72e09dcc6f4852b6670","price_changes":[{"asset_id":"8698449539441374295770236407991735029336433231649246775082939325523552031992","best_ask":"0.87","best_bid":"0.85","hash":"0f8cb01ac12c6c18d31b2086e691f9760a9fce5d","price":"0.78","side":"BUY","size":"71.2"},{"asset_id":"96283536366176669581486355171583722558858323126916278856549586825357358273536","best_ask":"0.15","best_bid":"0.13","hash":"63591be944aad6554e927654219b345e092955f0","price":"0.22","side":"SELL","size":"71.2"}],"timestamp":"1785122040555"},"payload_hash":"ffb23daa3915f28cbe5ad2d3a452551a8f460b76264f1debab86bc650b021a12","raw_frame":"{\"market\":\"0xf9d60bb033695053c4d1d8592e52171c1042f64b41a4b72e09dcc6f4852b6670\", \"price_changes\":[{\"asset_id\":\"8698449539441374295770236407991735029336433231649246775082939325523552031992\", \"price\":\"0.78\", \"size\":\"71.2\", \"side\":\"BUY\", \"hash\":\"0f8cb01ac12c6c18d31b2086e691f9760a9fce5d\", \"best_bid\":\"0.85\", \"best_ask\":\"0.87\"}, {\"asset_id\":\"96283536366176669581486355171583722558858323126916278856549586825357358273536\", \"price\":\"0.22\", \"size\":\"71.2\", \"side\":\"SELL\", \"hash\":\"63591be944aad6554e927654219b345e092955f0\", \"best_bid\":\"0.13\", \"best_ask\":\"0.15\"}], \"timestamp\":\"1785122040555\", \"event_type\":\"price_change\"}","received_at":"2026-07-27T03:14:00.491122Z","schema_version":"clob-market-ws.price_change.v1","sequence":null,"server_hash":null,"server_timestamp":"1785122040555","session_id":"ff6d21c8283948938400a32613abec2c","source":"clob_market_ws"},"received_at":"2026-07-27T03:14:00.491122Z","record_id":"07b0f98b2f2487ac68b936bc10b6c56d571fa806770c15412aafa2b079ad05b1","schema_fingerprint":"4aa3821a28b0b7c2400bc59aba4bcc0a76e971dadd19610d3ad38c768e124dc7","schema_version":"edge-lab-recorder.raw.v1","sequence":null,"source":"clob_market_ws"}
{"event_at":"2026-07-27T03:14:00.556000Z","event_fingerprint":"7a24c2ac31ac3632abe0ebe85a757bd04895b3a15f6c58588b47bee7234f0eb8","payload":{"connection_id":"f95883f18d264834af91809e5f803e9f","event_at":"2026-07-27T03:14:00.556000Z","event_type":"price_change","frame_hash":"63acd786d4376fb3d15d656a32ca364156f56a76b31ec6eb8e91e92de5659f57","frame_index":0,"kind":"data","monotonic_ns":224023825379125,"payload":{"event_type":"price_change","market":"0xf9d60bb033695053c4d1d8592e52171c1042f64b41a4b72e09dcc6f4852b6670","price_changes":[{"asset_id":"96283536366176669581486355171583722558858323126916278856549586825357358273536","best_ask":"0.15","best_bid":"0.13","hash":"a31c9e8052b619506203922737bf015c1b98e465","price":"0.1","side":"BUY","size":"68.3"},{"asset_id":"8698449539441374295770236407991735029336433231649246775082939325523552031992","best_ask":"0.87","best_bid":"0.85","hash":"5ba613f21cd3449390e8ce45b2d7c47b3b931438","price":"0.9","side":"SELL","size":"68.3"}],"timestamp":"1785122040556"},"payload_hash":"1d462bb9b5f547a6a77d81ad81862cf0229f0b5410dc06877df1eeab86a63b6b","raw_frame":"{\"market\":\"0xf9d60bb033695053c4d1d8592e52171c1042f64b41a4b72e09dcc6f4852b6670\", \"price_changes\":[{\"asset_id\":\"96283536366176669581486355171583722558858323126916278856549586825357358273536\", \"price\":\"0.1\", \"size\":\"68.3\", \"side\":\"BUY\", \"hash\":\"a31c9e8052b619506203922737bf015c1b98e465\", \"best_bid\":\"0.13\", \"best_ask\":\"0.15\"}, {\"asset_id\":\"8698449539441374295770236407991735029336433231649246775082939325523552031992\", \"price\":\"0.9\", \"size\":\"68.3\", \"side\":\"SELL\", \"hash\":\"5ba613f21cd3449390e8ce45b2d7c47b3b931438\", \"best_bid\":\"0.85\", \"best_ask\":\"0.87\"}], \"timestamp\":\"1785122040556\", \"event_type\":\"price_change\"}","received_at":"2026-07-27T03:14:00.492555Z","schema_version":"clob-market-ws.price_change.v1","sequence":null,"server_hash":null,"server_timestamp":"1785122040556","session_id":"ff6d21c8283948938400a32613abec2c","source":"clob_market_ws"},"received_at":"2026-07-27T03:14:00.492555Z","record_id":"740b36d15895a903cb99059a32f4fb1e71b62f394a8afef01da89d9de1608681","schema_fingerprint":"4aa3821a28b0b7c2400bc59aba4bcc0a76e971dadd19610d3ad38c768e124dc7","schema_version":"edge-lab-recorder.raw.v1","sequence":null,"source":"clob_market_ws"}
{"event_at":"2026-07-27T03:14:00.557000Z","event_fingerprint":"1533987cbe53800c423da297226b00652250b83b6a3ff5666820c72387691f07","payload":{"connection_id":"f95883f18d264834af91809e5f803e9f","event_at":"2026-07-27T03:14:00.557000Z","event_type":"price_change","frame_hash":"2973eb74ed164ed0538860bffecc751ff7ab393dd11b51a9994eac9bb4d0f8b4","frame_index":0,"kind":"data","monotonic_ns":224023825945125,"payload":{"event_type":"price_change","market":"0xf9d60bb033695053c4d1d8592e52171c1042f64b41a4b72e09dcc6f4852b6670","price_changes":[{"asset_id":"8698449539441374295770236407991735029336433231649246775082939325523552031992","best_ask":"0.87","best_bid":"0.85","hash":"3afaf56a6bc3b46ef9eb55bc0023c865ff606562","price":"0.78","side":"BUY","size":"76.2"},{"asset_id":"96283536366176669581486355171583722558858323126916278856549586825357358273536","best_ask":"0.15","best_bid":"0.13","hash":"eca0b2ca506a9a0186615aa6a669b21864777897","price":"0.22","side":"SELL","size":"76.2"}],"timestamp":"1785122040557"},"payload_hash":"665fe530238e4934c029c0bebdb86dd36f18644cddbe9fdceeb4d438e30cab00","raw_frame":"{\"market\":\"0xf9d60bb033695053c4d1d8592e52171c1042f64b41a4b72e09dcc6f4852b6670\", \"price_changes\":[{\"asset_id\":\"8698449539441374295770236407991735029336433231649246775082939325523552031992\", \"price\":\"0.78\", \"size\":\"76.2\", \"side\":\"BUY\", \"hash\":\"3afaf56a6bc3b46ef9eb55bc0023c865ff606562\", \"best_bid\":\"0.85\", \"best_ask\":\"0.87\"}, {\"asset_id\":\"96283536366176669581486355171583722558858323126916278856549586825357358273536\", \"price\":\"0.22\", \"size\":\"76.2\", \"side\":\"SELL\", \"hash\":\"eca0b2ca506a9a0186615aa6a669b21864777897\", \"best_bid\":\"0.13\", \"best_ask\":\"0.15\"}], \"timestamp\":\"1785122040557\", \"event_type\":\"price_change\"}","received_at":"2026-07-27T03:14:00.493121Z","schema_version":"clob-market-ws.price_change.v1","sequence":null,"server_hash":null,"server_timestamp":"1785122040557","session_id":"ff6d21c8283948938400a32613abec2c","source":"clob_market_ws"},"received_at":"2026-07-27T03:14:00.493121Z","record_id":"9bd2bcc7ef7c4d0093ca1a2574e27f3281ef923302ae629941ecfd7813aa8afd","schema_fingerprint":"4aa3821a28b0b7c2400bc59aba4bcc0a76e971dadd19610d3ad38c768e124dc7","schema_version":"edge-lab-recorder.raw.v1","sequence":null,"source":"clob_market_ws"}
{"event_at":"2026-07-27T03:14:00.562000Z","event_fingerprint":"91135f723cee9118d9ec2727d239304c00eab14cad602856917233a8beb54f6a","payload":{"connection_id":"f95883f18d264834af91809e5f803e9f","event_at":"2026-07-27T03:14:00.562000Z","event_type":"price_change","frame_hash":"d0f27a4250008cd1940489b9979c0a27e59dd12a715c8a4253b29dacea6fedbf","frame_index":0,"kind":"data","monotonic_ns":224023827029375,"payload":{"event_type":"price_change","market":"0xf9d60bb033695053c4d1d8592e52171c1042f64b41a4b72e09dcc6f4852b6670","price_changes":[{"asset_id":"8698449539441374295770236407991735029336433231649246775082939325523552031992","best_ask":"0.87","best_bid":"0.85","hash":"b0a2b60e985eb7e9fb96eb2f66388b3037ff231e","price":"0.01","side":"BUY","size":"7617.5"},{"asset_id":"96283536366176669581486355171583722558858323126916278856549586825357358273536","best_ask":"0.15","best_bid":"0.13","hash":"1a84830178c61d6e61ab3e5de0037f1db00a4b60","price":"0.99","side":"SELL","size":"7617.5"}],"timestamp":"1785122040562"},"payload_hash":"3da1d33cc32f9586099aea4dfe54d95e40f58d5c4ef0e00e14db882788dc44fd","raw_frame":"{\"market\":\"0xf9d60bb033695053c4d1d8592e52171c1042f64b41a4b72e09dcc6f4852b6670\", \"price_changes\":[{\"asset_id\":\"8698449539441374295770236407991735029336433231649246775082939325523552031992\", \"price\":\"0.01\", \"size\":\"7617.5\", \"side\":\"BUY\", \"hash\":\"b0a2b60e985eb7e9fb96eb2f66388b3037ff231e\", \"best_bid\":\"0.85\", \"best_ask\":\"0.87\"}, {\"asset_id\":\"96283536366176669581486355171583722558858323126916278856549586825357358273536\", \"price\":\"0.99\", \"size\":\"7617.5\", \"side\":\"SELL\", \"hash\":\"1a84830178c61d6e61ab3e5de0037f1db00a4b60\", \"best_bid\":\"0.13\", \"best_ask\":\"0.15\"}], \"timestamp\":\"1785122040562\", \"event_type\":\"price_change\"}","received_at":"2026-07-27T03:14:00.494198Z","schema_version":"clob-market-ws.price_change.v1","sequence":null,"server_hash":null,"server_timestamp":"1785122040562","session_id":"ff6d21c8283948938400a32613abec2c","source":"clob_market_ws"},"received_at":"2026-07-27T03:14:00.494198Z","record_id":"061613a9aa5f081942c3ec544e8b44c1cc7c40cec183e1b4e086b8770acde37c","schema_fingerprint":"4aa3821a28b0b7c2400bc59aba4bcc0a76e971dadd19610d3ad38c768e124dc7","schema_version":"edge-lab-recorder.raw.v1","sequence":null,"source":"clob_market_ws"}
{"event_at":"2026-07-27T03:14:00.563000Z","event_fingerprint":"0fa1ce0cf7a410972346a016fe675be904fd8f3b08963a3a44db7fd4ef2baaa0","payload":{"connection_id":"f95883f18d264834af91809e5f803e9f","event_at":"2026-07-27T03:14:00.563000Z","event_type":"price_change","frame_hash":"4b014e9314642b73688f642d0cd6a78511bfad3074ede6b881688958197aad24","frame_index":0,"kind":"data","monotonic_ns":224023828533041,"payload":{"event_type":"price_change","market":"0xf9d60bb033695053c4d1d8592e52171c1042f64b41a4b72e09dcc6f4852b6670","price_changes":[{"asset_id":"96283536366176669581486355171583722558858323126916278856549586825357358273536","best_ask":"0.15","best_bid":"0.13","hash":"8f02498cf9229f43c283440913be839596e878be","price":"0.01","side":"BUY","size":"6229.5"},{"asset_id":"8698449539441374295770236407991735029336433231649246775082939325523552031992","best_ask":"0.87","best_bid":"0.85","hash":"56ca377c22f9ef87505c920460e4c3de013dc825","price":"0.99","side":"SELL","size":"6229.5"}],"timestamp":"1785122040563"},"payload_hash":"af4fae7531e9731378715dfd2cad73efff92d55adca4549d9599b4044e00045b","raw_frame":"{\"market\":\"0xf9d60bb033695053c4d1d8592e52171c1042f64b41a4b72e09dcc6f4852b6670\", \"price_changes\":[{\"asset_id\":\"96283536366176669581486355171583722558858323126916278856549586825357358273536\", \"price\":\"0.01\", \"size\":\"6229.5\", \"side\":\"BUY\", \"hash\":\"8f02498cf9229f43c283440913be839596e878be\", \"best_bid\":\"0.13\", \"best_ask\":\"0.15\"}, {\"asset_id\":\"8698449539441374295770236407991735029336433231649246775082939325523552031992\", \"price\":\"0.99\", \"size\":\"6229.5\", \"side\":\"SELL\", \"hash\":\"56ca377c22f9ef87505c920460e4c3de013dc825\", \"best_bid\":\"0.85\", \"best_ask\":\"0.87\"}], \"timestamp\":\"1785122040563\", \"event_type\":\"price_change\"}","received_at":"2026-07-27T03:14:00.495709Z","schema_version":"clob-market-ws.price_change.v1","sequence":null,"server_hash":null,"server_timestamp":"1785122040563","session_id":"ff6d21c8283948938400a32613abec2c","source":"clob_market_ws"},"received_at":"2026-07-27T03:14:00.495709Z","record_id":"4557504d3f72e813188b22cfe37893b9871ec704a4b9b901710c153aa18a924f","schema_fingerprint":"4aa3821a28b0b7c2400bc59aba4bcc0a76e971dadd19610d3ad38c768e124dc7","schema_version":"edge-lab-recorder.raw.v1","sequence":null,"source":"clob_market_ws"}
{"event_at":"2026-07-27T03:14:00.572000Z","event_fingerprint":"f6b9ff0b1f9005e9e86e8645681fb7e88e88e93ee23dfd5e11f74d698983c7cc","payload":{"connection_id":"f95883f18d264834af91809e5f803e9f","event_at":"2026-07-27T03:14:00.572000Z","event_type":"price_change","frame_hash":"70bb1275f54d18b34df4c50f83be7879d2a7d027b287793833d0d2dcf728c43b","frame_index":0,"kind":"data","monotonic_ns":224023829186833,"payload":{"event_type":"price_change","market":"0xf9d60bb033695053c4d1d8592e52171c1042f64b41a4b72e09dcc6f4852b6670","price_changes":[{"asset_id":"96283536366176669581486355171583722558858323126916278856549586825357358273536","best_ask":"0.15","best_bid":"0.13","hash":"c1a63aa5496797cddffbaee64736c9a476a95f83","price":"0.01","side":"BUY","size":"6234.5"},{"asset_id":"8698449539441374295770236407991735029336433231649246775082939325523552031992","best_ask":"0.87","best_bid":"0.85","hash":"34ae99e1a5956cb1775ccb63ffd779bf4bec7df7","price":"0.99","side":"SELL","size":"6234.5"}],"timestamp":"1785122040572"},"payload_hash":"8a254abb19f7b8003da86fb59ecfec38539d4f5cafaa2e280ba110143efc04ba","raw_frame":"{\"market\":\"0xf9d60bb033695053c4d1d8592e52171c1042f64b41a4b72e09dcc6f4852b6670\", \"price_changes\":[{\"asset_id\":\"96283536366176669581486355171583722558858323126916278856549586825357358273536\", \"price\":\"0.01\", \"size\":\"6234.5\", \"side\":\"BUY\", \"hash\":\"c1a63aa5496797cddffbaee64736c9a476a95f83\", \"best_bid\":\"0.13\", \"best_ask\":\"0.15\"}, {\"asset_id\":\"8698449539441374295770236407991735029336433231649246775082939325523552031992\", \"price\":\"0.99\", \"size\":\"6234.5\", \"side\":\"SELL\", \"hash\":\"34ae99e1a5956cb1775ccb63ffd779bf4bec7df7\", \"best_bid\":\"0.85\", \"best_ask\":\"0.87\"}], \"timestamp\":\"1785122040572\", \"event_type\":\"price_change\"}","received_at":"2026-07-27T03:14:00.496362Z","schema_version":"clob-market-ws.price_change.v1","sequence":null,"server_hash":null,"server_timestamp":"1785122040572","session_id":"ff6d21c8283948938400a32613abec2c","source":"clob_market_ws"},"received_at":"2026-07-27T03:14:00.496362Z","record_id":"4addc67b6d5b191894fab5d76cbab08ac8b20aba1da2ca9e29017a1b4059ef4a","schema_fingerprint":"4aa3821a28b0b7c2400bc59aba4bcc0a76e971dadd19610d3ad38c768e124dc7","schema_version":"edge-lab-recorder.raw.v1","sequence":null,"source":"clob_market_ws"}
{"event_at":"2026-07-27T03:14:00.573000Z","event_fingerprint":"1b382bf535f6c1faf765c3f372ea6b89170ac3e5d05d113d80cc1df6474528b9","payload":{"connection_id":"f95883f18d264834af91809e5f803e9f","event_at":"2026-07-27T03:14:00.573000Z","event_type":"price_change","frame_hash":"c03d82e3eca5fcb70bf7b41b46319ed8a9db0dfa680be0a645088f7b42336195","frame_index":0,"kind":"data","monotonic_ns":224023829796333,"payload":{"event_type":"price_change","market":"0xf9d60bb033695053c4d1d8592e52171c1042f64b41a4b72e09dcc6f4852b6670","price_changes":[{"asset_id":"8698449539441374295770236407991735029336433231649246775082939325523552031992","best_ask":"0.87","best_bid":"0.85","hash":"2977b52b46bced7ca905b94c39a976e5cc7f00e6","price":"0.78","side":"BUY","size":"71.2"},{"asset_id":"96283536366176669581486355171583722558858323126916278856549586825357358273536","best_ask":"0.15","best_bid":"0.13","hash":"13c1172a5a3d543ee8cbbb527c0945d96f76c0ed","price":"0.22","side":"SELL","size":"71.2"}],"timestamp":"1785122040573"},"payload_hash":"e357d07f9d38fb4fb2018a2d2f4a5192044006f785796516b0fd26d8f015510f","raw_frame":"{\"market\":\"0xf9d60bb033695053c4d1d8592e52171c1042f64b41a4b72e09dcc6f4852b6670\", \"price_changes\":[{\"asset_id\":\"8698449539441374295770236407991735029336433231649246775082939325523552031992\", \"price\":\"0.78\", \"size\":\"71.2\", \"side\":\"BUY\", \"hash\":\"2977b52b46bced7ca905b94c39a976e5cc7f00e6\", \"best_bid\":\"0.85\", \"best_ask\":\"0.87\"}, {\"asset_id\":\"96283536366176669581486355171583722558858323126916278856549586825357358273536\", \"price\":\"0.22\", \"size\":\"71.2\", \"side\":\"SELL\", \"hash\":\"13c1172a5a3d543ee8cbbb527c0945d96f76c0ed\", \"best_bid\":\"0.13\", \"best_ask\":\"0.15\"}], \"timestamp\":\"1785122040573\", \"event_type\":\"price_change\"}","received_at":"2026-07-27T03:14:00.496972Z","schema_version":"clob-market-ws.price_change.v1","sequence":null,"server_hash":null,"server_timestamp":"1785122040573","session_id":"ff6d21c8283948938400a32613abec2c","source":"clob_market_ws"},"received_at":"2026-07-27T03:14:00.496972Z","record_id":"c75410f03f49f6dca8357cd03a3c58e10f4b5e40f4f1a4dfa187c7c8f32ac8cf","schema_fingerprint":"4aa3821a28b0b7c2400bc59aba4bcc0a76e971dadd19610d3ad38c768e124dc7","schema_version":"edge-lab-recorder.raw.v1","sequence":null,"source":"clob_market_ws"}
{"event_at":"2026-07-27T03:14:00.573000Z","event_fingerprint":"ca52c7bf9dbef4547b80ff49f124aca584d018662309760830392cd30a52b4bd","payload":{"connection_id":"f95883f18d264834af91809e5f803e9f","event_at":"2026-07-27T03:14:00.573000Z","event_type":"price_change","frame_hash":"4f679013e3ca58affeee519331df2c5532a08fe21398c62d26872b4bb9a275ff","frame_index":0,"kind":"data","monotonic_ns":224023830412041,"payload":{"event_type":"price_change","market":"0xf9d60bb033695053c4d1d8592e52171c1042f64b41a4b72e09dcc6f4852b6670","price_changes":[{"asset_id":"96283536366176669581486355171583722558858323126916278856549586825357358273536","best_ask":"0.15","best_bid":"0.13","hash":"7aa15812c5277e255c1496056ff6e3a45bbb11fc","price":"0.1","side":"BUY","size":"73.3"},{"asset_id":"8698449539441374295770236407991735029336433231649246775082939325523552031992","best_ask":"0.87","best_bid":"0.85","hash":"a476d3d5d3b0feb89d9a8c42c62ac90c18297ae5","price":"0.9","side":"SELL","size":"73.3"}],"timestamp":"1785122040573"},"payload_hash":"c3d9973ddf8a2b8ee4409647f40a7f44d3c74fccbff715b6c5864d145cf75a89","raw_frame":"{\"market\":\"0xf9d60bb033695053c4d1d8592e52171c1042f64b41a4b72e09dcc6f4852b6670\", \"price_changes\":[{\"asset_id\":\"96283536366176669581486355171583722558858323126916278856549586825357358273536\", \"price\":\"0.1\", \"size\":\"73.3\", \"side\":\"BUY\", \"hash\":\"7aa15812c5277e255c1496056ff6e3a45bbb11fc\", \"best_bid\":\"0.13\", \"best_ask\":\"0.15\"}, {\"asset_id\":\"8698449539441374295770236407991735029336433231649246775082939325523552031992\", \"price\":\"0.9\", \"size\":\"73.3\", \"side\":\"SELL\", \"hash\":\"a476d3d5d3b0feb89d9a8c42c62ac90c18297ae5\", \"best_bid\":\"0.85\", \"best_ask\":\"0.87\"}], \"timestamp\":\"1785122040573\", \"event_type\":\"price_change\"}","received_at":"2026-07-27T03:14:00.497588Z","schema_version":"clob-market-ws.price_change.v1","sequence":null,"server_hash":null,"server_timestamp":"1785122040573","session_id":"ff6d21c8283948938400a32613abec2c","source":"clob_market_ws"},"received_at":"2026-07-27T03:14:00.497588Z","record_id":"9b4a180b6bc8a5ce146be82d1b12f34b7cc58aab75f6913dd1c58b39cd03b913","schema_fingerprint":"4aa3821a28b0b7c2400bc59aba4bcc0a76e971dadd19610d3ad38c768e124dc7","schema_version":"edge-lab-recorder.raw.v1","sequence":null,"source":"clob_market_ws"}
{"event_at":"2026-07-27T03:14:00.574000Z","event_fingerprint":"f51d79560982b1a84dbddef664c09cf510ae303ba18a7c004346b6e8359d7a67","payload":{"connection_id":"f95883f18d264834af91809e5f803e9f","event_at":"2026-07-27T03:14:00.574000Z","event_type":"price_change","frame_hash":"19e1bcc0bac0ecb54a1a40292f866325fb42b97f0d30d13662e90c9e1c0716fb","frame_index":0,"kind":"data","monotonic_ns":224023830995125,"payload":{"event_type":"price_change","market":"0xf9d60bb033695053c4d1d8592e52171c1042f64b41a4b72e09dcc6f4852b6670","price_changes":[{"asset_id":"8698449539441374295770236407991735029336433231649246775082939325523552031992","best_ask":"0.87","best_bid":"0.85","hash":"d8399236af7cc91db4792856343d4783873c7c1b","price":"0.01","side":"BUY","size":"7622.5"},{"asset_id":"96283536366176669581486355171583722558858323126916278856549586825357358273536","best_ask":"0.15","best_bid":"0.13","hash":"84408f8c6335668b9949e48f6a12a12106fbaba9","price":"0.99","side":"SELL","size":"7622.5"}],"timestamp":"1785122040574"},"payload_hash":"9628eb1e89fdadd90b74fde8139734480e1d1f5585ec1070ed29f24300b58707","raw_frame":"{\"market\":\"0xf9d60bb033695053c4d1d8592e52171c1042f64b41a4b72e09dcc6f4852b6670\", \"price_changes\":[{\"asset_id\":\"8698449539441374295770236407991735029336433231649246775082939325523552031992\", \"price\":\"0.01\", \"size\":\"7622.5\", \"side\":\"BUY\", \"hash\":\"d8399236af7cc91db4792856343d4783873c7c1b\", \"best_bid\":\"0.85\", \"best_ask\":\"0.87\"}, {\"asset_id\":\"96283536366176669581486355171583722558858323126916278856549586825357358273536\", \"price\":\"0.99\", \"size\":\"7622.5\", \"side\":\"SELL\", \"hash\":\"84408f8c6335668b9949e48f6a12a12106fbaba9\", \"best_bid\":\"0.13\", \"best_ask\":\"0.15\"}], \"timestamp\":\"1785122040574\", \"event_type\":\"price_change\"}","received_at":"2026-07-27T03:14:00.498170Z","schema_version":"clob-market-ws.price_change.v1","sequence":null,"server_hash":null,"server_timestamp":"1785122040574","session_id":"ff6d21c8283948938400a32613abec2c","source":"clob_market_ws"},"received_at":"2026-07-27T03:14:00.498170Z","record_id":"6a1c1a48a0c63f6992af437032144cbafb72881862398f981d5a0e03b6f403f0","schema_fingerprint":"4aa3821a28b0b7c2400bc59aba4bcc0a76e971dadd19610d3ad38c768e124dc7","schema_version":"edge-lab-recorder.raw.v1","sequence":null,"source":"clob_market_ws"}
{"event_at":"2026-07-27T03:14:00.574000Z","event_fingerprint":"578d4fbd9a4279f168e9c6300977175e56178688211254b0b867d477a4286ec1","payload":{"connection_id":"f95883f18d264834af91809e5f803e9f","event_at":"2026-07-27T03:14:00.574000Z","event_type":"price_change","frame_hash":"b3da7c3dc9316f7ae80c1881804ac504d75a5362ba707add1b42dc8cc7b357de","frame_index":0,"kind":"data","monotonic_ns":224023831762916,"payload":{"event_type":"price_change","market":"0xf9d60bb033695053c4d1d8592e52171c1042f64b41a4b72e09dcc6f4852b6670","price_changes":[{"asset_id":"96283536366176669581486355171583722558858323126916278856549586825357358273536","best_ask":"0.15","best_bid":"0.13","hash":"0466e0c136424fe493130361f98d9c8922cf4270","price":"0.01","side":"BUY","size":"6239.5"},{"asset_id":"8698449539441374295770236407991735029336433231649246775082939325523552031992","best_ask":"0.87","best_bid":"0.85","hash":"8069db4f83b0fad2f19bc324398be16df9344d81","price":"0.99","side":"SELL","size":"6239.5"}],"timestamp":"1785122040574"},"payload_hash":"cd320e2b8525dffa93a87d72f6f3a6f0cf19f4a7d5dbc71ae47b010d20d8c91b","raw_frame":"{\"market\":\"0xf9d60bb033695053c4d1d8592e52171c1042f64b41a4b72e09dcc6f4852b6670\", \"price_changes\":[{\"asset_id\":\"96283536366176669581486355171583722558858323126916278856549586825357358273536\", \"price\":\"0.01\", \"size\":\"6239.5\", \"side\":\"BUY\", \"hash\":\"0466e0c136424fe493130361f98d9c8922cf4270\", \"best_bid\":\"0.13\", \"best_ask\":\"0.15\"}, {\"asset_id\":\"8698449539441374295770236407991735029336433231649246775082939325523552031992\", \"price\":\"0.99\", \"size\":\"6239.5\", \"side\":\"SELL\", \"hash\":\"8069db4f83b0fad2f19bc324398be16df9344d81\", \"best_bid\":\"0.85\", \"best_ask\":\"0.87\"}], \"timestamp\":\"1785122040574\", \"event_type\":\"price_change\"}","received_at":"2026-07-27T03:14:00.498938Z","schema_version":"clob-market-ws.price_change.v1","sequence":null,"server_hash":null,"server_timestamp":"1785122040574","session_id":"ff6d21c8283948938400a32613abec2c","source":"clob_market_ws"},"received_at":"2026-07-27T03:14:00.498938Z","record_id":"fb77531094a8ac2fbc593c2f2276e7a706c5d5c3b042d6768bfd622976faa7b7","schema_fingerprint":"4aa3821a28b0b7c2400bc59aba4bcc0a76e971dadd19610d3ad38c768e124dc7","schema_version":"edge-lab-recorder.raw.v1","sequence":null,"source":"clob_market_ws"}
{"event_at":"2026-07-27T03:14:00.575000Z","event_fingerprint":"d333639abdfdec3fb05223cbf24bc3c6d8651a086d98baddd8933cf428474555","payload":{"connection_id":"f95883f18d264834af91809e5f803e9f","event_at":"2026-07-27T03:14:00.575000Z","event_type":"price_change","frame_hash":"dfbf63fcc89fc28e1f308afefdc06fd636027e16ee99246eda7dbc006b8185ae","frame_index":0,"kind":"data","monotonic_ns":224023832351166,"payload":{"event_type":"price_change","market":"0xf9d60bb033695053c4d1d8592e52171c1042f64b41a4b72e09dcc6f4852b6670","price_changes":[{"asset_id":"8698449539441374295770236407991735029336433231649246775082939325523552031992","best_ask":"0.87","best_bid":"0.85","hash":"3b3877b7a728aa9473c4429d82cb0a0bab036178","price":"0.01","side":"BUY","size":"7627.5"},{"asset_id":"96283536366176669581486355171583722558858323126916278856549586825357358273536","best_ask":"0.15","best_bid":"0.13","hash":"6d6114fac33fd7f71c0e69457926460233471ccd","price":"0.99","side":"SELL","size":"7627.5"}],"timestamp":"1785122040575"},"payload_hash":"01ca71b68be3f474cfc9ac49de5d548acca6fd4c6fd88e00804f4e819617737d","raw_frame":"{\"market\":\"0xf9d60bb033695053c4d1d8592e52171c1042f64b41a4b72e09dcc6f4852b6670\", \"price_changes\":[{\"asset_id\":\"8698449539441374295770236407991735029336433231649246775082939325523552031992\", \"price\":\"0.01\", \"size\":\"7627.5\", \"side\":\"BUY\", \"hash\":\"3b3877b7a728aa9473c4429d82cb0a0bab036178\", \"best_bid\":\"0.85\", \"best_ask\":\"0.87\"}, {\"asset_id\":\"96283536366176669581486355171583722558858323126916278856549586825357358273536\", \"price\":\"0.99\", \"size\":\"7627.5\", \"side\":\"SELL\", \"hash\":\"6d6114fac33fd7f71c0e69457926460233471ccd\", \"best_bid\":\"0.13\", \"best_ask\":\"0.15\"}], \"timestamp\":\"1785122040575\", \"event_type\":\"price_change\"}","received_at":"2026-07-27T03:14:00.499527Z","schema_version":"clob-market-ws.price_change.v1","sequence":null,"server_hash":null,"server_timestamp":"1785122040575","session_id":"ff6d21c8283948938400a32613abec2c","source":"clob_market_ws"},"received_at":"2026-07-27T03:14:00.499527Z","record_id":"38b36ec75dba9aad6b56f137908f38741dc6ed0e62451599cc5662c59b41446b","schema_fingerprint":"4aa3821a28b0b7c2400bc59aba4bcc0a76e971dadd19610d3ad38c768e124dc7","schema_version":"edge-lab-recorder.raw.v1","sequence":null,"source":"clob_market_ws"}
{"event_at":"2026-07-27T03:14:00.576000Z","event_fingerprint":"3388a4ff702adaa9c4ec0ea876426bc42d3ddeb4cda84191632afa4b0ae71b20","payload":{"connection_id":"f95883f18d264834af91809e5f803e9f","event_at":"2026-07-27T03:14:00.576000Z","event_type":"price_change","frame_hash":"dd53814113c4f75c13ad7153b4f43df0c51a279e8e5d61f62a0279c508c160b6","frame_index":0,"kind":"data","monotonic_ns":224023832924666,"payload":{"event_type":"price_change","market":"0xf9d60bb033695053c4d1d8592e52171c1042f64b41a4b72e09dcc6f4852b6670","price_changes":[{"asset_id":"8698449539441374295770236407991735029336433231649246775082939325523552031992","best_ask":"0.87","best_bid":"0.85","hash":"27e0f09cfa72b9ae75014cd7657f22181814330a","price":"0.03","side":"BUY","size":"1173.8"},{"asset_id":"96283536366176669581486355171583722558858323126916278856549586825357358273536","best_ask":"0.15","best_bid":"0.13","hash":"058921ce81e83fee9b17d774b9d5f70d99017f57","price":"0.97","side":"SELL","size":"1173.8"}],"timestamp":"1785122040576"},"payload_hash":"8a30387979bee4c8c3f55a8534cc2bd31e91995541a744ec23115b3c7d3c8322","raw_frame":"{\"market\":\"0xf9d60bb033695053c4d1d8592e52171c1042f64b41a4b72e09dcc6f4852b6670\", \"price_changes\":[{\"asset_id\":\"8698449539441374295770236407991735029336433231649246775082939325523552031992\", \"price\":\"0.03\", \"size\":\"1173.8\", \"side\":\"BUY\", \"hash\":\"27e0f09cfa72b9ae75014cd7657f22181814330a\", \"best_bid\":\"0.85\", \"best_ask\":\"0.87\"}, {\"asset_id\":\"96283536366176669581486355171583722558858323126916278856549586825357358273536\", \"price\":\"0.97\", \"size\":\"1173.8\", \"side\":\"SELL\", \"hash\":\"058921ce81e83fee9b17d774b9d5f70d99017f57\", \"best_bid\":\"0.13\", \"best_ask\":\"0.15\"}], \"timestamp\":\"1785122040576\", \"event_type\":\"price_change\"}","received_at":"2026-07-27T03:14:00.500100Z","schema_version":"clob-market-ws.price_change.v1","sequence":null,"server_hash":null,"server_timestamp":"1785122040576","session_id":"ff6d21c8283948938400a32613abec2c","source":"clob_market_ws"},"received_at":"2026-07-27T03:14:00.500100Z","record_id":"20b688bb2457780fd388be8dfdf1d1bf7a1b08c74eb0ce4730c43badff5c6f69","schema_fingerprint":"4aa3821a28b0b7c2400bc59aba4bcc0a76e971dadd19610d3ad38c768e124dc7","schema_version":"edge-lab-recorder.raw.v1","sequence":null,"source":"clob_market_ws"}
{"event_at":"2026-07-27T03:14:00.576000Z","event_fingerprint":"e946840daff1580c9f190a2871875587236587ae6480c7ee436a7c824ffcd22c","payload":{"connection_id":"f95883f18d264834af91809e5f803e9f","event_at":"2026-07-27T03:14:00.576000Z","event_type":"price_change","frame_hash":"3fa4e62528c7bf8c8b6ade910e956f361be28c2735daccc1c493a201e678e488","frame_index":0,"kind":"data","monotonic_ns":224023833494166,"payload":{"event_type":"price_change","market":"0xf9d60bb033695053c4d1d8592e52171c1042f64b41a4b72e09dcc6f4852b6670","price_changes":[{"asset_id":"8698449539441374295770236407991735029336433231649246775082939325523552031992","best_ask":"0.87","best_bid":"0.85","hash":"cb99e3e90e07d42ea21dcd6b15ae198b5f61996d","price":"0.01","side":"BUY","size":"7622.5"},{"asset_id":"96283536366176669581486355171583722558858323126916278856549586825357358273536","best_ask":"0.15","best_bid":"0.13","hash":"22d5da1ee52d8a13676e5c520948454daeddf7ea","price":"0.99","side":"SELL","size":"7622.5"}],"timestamp":"1785122040576"},"payload_hash":"07dd4fa5f1cf581c8033c327550ac852b8a50e3cabe65ab2c212855a4d9f26b9","raw_frame":"{\"market\":\"0xf9d60bb033695053c4d1d8592e52171c1042f64b41a4b72e09dcc6f4852b6670\", \"price_changes\":[{\"asset_id\":\"8698449539441374295770236407991735029336433231649246775082939325523552031992\", \"price\":\"0.01\", \"size\":\"7622.5\", \"side\":\"BUY\", \"hash\":\"cb99e3e90e07d42ea21dcd6b15ae198b5f61996d\", \"best_bid\":\"0.85\", \"best_ask\":\"0.87\"}, {\"asset_id\":\"96283536366176669581486355171583722558858323126916278856549586825357358273536\", \"price\":\"0.99\", \"size\":\"7622.5\", \"side\":\"SELL\", \"hash\":\"22d5da1ee52d8a13676e5c520948454daeddf7ea\", \"best_bid\":\"0.13\", \"best_ask\":\"0.15\"}], \"timestamp\":\"1785122040576\", \"event_type\":\"price_change\"}","received_at":"2026-07-27T03:14:00.500670Z","schema_version":"clob-market-ws.price_change.v1","sequence":null,"server_hash":null,"server_timestamp":"1785122040576","session_id":"ff6d21c8283948938400a32613abec2c","source":"clob_market_ws"},"received_at":"2026-07-27T03:14:00.500670Z","record_id":"d7cbfadb5ec3b986f239600848ea25130528d1513378c661613eadc53288586e","schema_fingerprint":"4aa3821a28b0b7c2400bc59aba4bcc0a76e971dadd19610d3ad38c768e124dc7","schema_version":"edge-lab-recorder.raw.v1","sequence":null,"source":"clob_market_ws"}
{"event_at":"2026-07-27T03:14:00.599000Z","event_fingerprint":"e6a7e9fc98f748e07d6e32faec520da93bf5cad0e1059f1e56b869571831653c","payload":{"connection_id":"f95883f18d264834af91809e5f803e9f","event_at":"2026-07-27T03:14:00.599000Z","event_type":"price_change","frame_hash":"d76a36da44e9e0780b7e6976ee2423d6ba3711457094eecbf4d7210bb28af5eb","frame_index":0,"kind":"data","monotonic_ns":224023834142833,"payload":{"event_type":"price_change","market":"0xf9d60bb033695053c4d1d8592e52171c1042f64b41a4b72e09dcc6f4852b6670","price_changes":[{"asset_id":"8698449539441374295770236407991735029336433231649246775082939325523552031992","best_ask":"0.87","best_bid":"0.85","hash":"8038c68fdfd4ed903d990fc0a5c15b8a99b729a4","price":"0.01","side":"BUY","size":"7617.5"},{"asset_id":"96283536366176669581486355171583722558858323126916278856549586825357358273536","best_ask":"0.15","best_bid":"0.13","hash":"0b9862f0b5e7e458d64df533d2e63f5eec99ebf7","price":"0.99","side":"SELL","size":"7617.5"}],"timestamp":"1785122040599"},"payload_hash":"7568c006a849ef0b5c51b7d75d763b3c14497d12e95d0d3eca55305c44cdc81d","raw_frame":"{\"market\":\"0xf9d60bb033695053c4d1d8592e52171c1042f64b41a4b72e09dcc6f4852b6670\", \"price_changes\":[{\"asset_id\":\"8698449539441374295770236407991735029336433231649246775082939325523552031992\", \"price\":\"0.01\", \"size\":\"7617.5\", \"side\":\"BUY\", \"hash\":\"8038c68fdfd4ed903d990fc0a5c15b8a99b729a4\", \"best_bid\":\"0.85\", \"best_ask\":\"0.87\"}, {\"asset_id\":\"96283536366176669581486355171583722558858323126916278856549586825357358273536\", \"price\":\"0.99\", \"size\":\"7617.5\", \"side\":\"SELL\", \"hash\":\"0b9862f0b5e7e458d64df533d2e63f5eec99ebf7\", \"best_bid\":\"0.13\", \"best_ask\":\"0.15\"}], \"timestamp\":\"1785122040599\", \"event_type\":\"price_change\"}","received_at":"2026-07-27T03:14:00.501317Z","schema_version":"clob-market-ws.price_change.v1","sequence":null,"server_hash":null,"server_timestamp":"1785122040599","session_id":"ff6d21c8283948938400a32613abec2c","source":"clob_market_ws"},"received_at":"2026-07-27T03:14:00.501317Z","record_id":"3da1e804b250c753e70d300acf7aae69f55b7f58f7e50309343c9d678c3bd80d","schema_fingerprint":"4aa3821a28b0b7c2400bc59aba4bcc0a76e971dadd19610d3ad38c768e124dc7","schema_version":"edge-lab-recorder.raw.v1","sequence":null,"source":"clob_market_ws"}
{"event_at":"2026-07-27T03:14:00.600000Z","event_fingerprint":"a4c9de400c0d4b122b75b4822c31a918a33021f58bf1c92198a474b6e2f57a67","payload":{"connection_id":"f95883f18d264834af91809e5f803e9f","event_at":"2026-07-27T03:14:00.600000Z","event_type":"price_change","frame_hash":"9cb0905de439834251ff0cabd174f504b1416646676fbc43a6828de25f17a482","frame_index":0,"kind":"data","monotonic_ns":224023834851875,"payload":{"event_type":"price_change","market":"0xf9d60bb033695053c4d1d8592e52171c1042f64b41a4b72e09dcc6f4852b6670","price_changes":[{"asset_id":"8698449539441374295770236407991735029336433231649246775082939325523552031992","best_ask":"0.87","best_bid":"0.85","hash":"e8db0ca857b9a6f57d3067d000117bedd1516de2","price":"0.8","side":"BUY","size":"90.7"},{"asset_id":"96283536366176669581486355171583722558858323126916278856549586825357358273536","best_ask":"0.15","best_bid":"0.13","hash":"afb7795b057f84110926581d6d44e077eeab269c","price":"0.2","side":"SELL","size":"90.7"}],"timestamp":"1785122040600"},"payload_hash":"9978caeeb72538b84d318b9c3a897ebf7aa4cbf96d5dad0e6503b3d5d85555a7","raw_frame":"{\"market\":\"0xf9d60bb033695053c4d1d8592e52171c1042f64b41a4b72e09dcc6f4852b6670\", \"price_changes\":[{\"asset_id\":\"8698449539441374295770236407991735029336433231649246775082939325523552031992\", \"price\":\"0.8\", \"size\":\"90.7\", \"side\":\"BUY\", \"hash\":\"e8db0ca857b9a6f57d3067d000117bedd1516de2\", \"best_bid\":\"0.85\", \"best_ask\":\"0.87\"}, {\"asset_id\":\"96283536366176669581486355171583722558858323126916278856549586825357358273536\", \"price\":\"0.2\", \"size\":\"90.7\", \"side\":\"SELL\", \"hash\":\"afb7795b057f84110926581d6d44e077eeab269c\", \"best_bid\":\"0.13\", \"best_ask\":\"0.15\"}], \"timestamp\":\"1785122040600\", \"event_type\":\"price_change\"}","received_at":"2026-07-27T03:14:00.502020Z","schema_version":"clob-market-ws.price_change.v1","sequence":null,"server_hash":null,"server_timestamp":"1785122040600","session_id":"ff6d21c8283948938400a32613abec2c","source":"clob_market_ws"},"received_at":"2026-07-27T03:14:00.502020Z","record_id":"a9c7ee87c5629c2877d1bd71c27cf5c55aa8387b4dddf134b88b0218daf03503","schema_fingerprint":"4aa3821a28b0b7c2400bc59aba4bcc0a76e971dadd19610d3ad38c768e124dc7","schema_version":"edge-lab-recorder.raw.v1","sequence":null,"source":"clob_market_ws"}
{"event_at":"2026-07-27T03:14:00.679000Z","event_fingerprint":"b5e87bdd8f1da1c2e5fb14eacd2e14e5f8b7a671aa8f5cfbd524f8d057976670","payload":{"connection_id":"f95883f18d264834af91809e5f803e9f","event_at":"2026-07-27T03:14:00.679000Z","event_type":"best_bid_ask","frame_hash":"c2f060e19cad69e615be138ffe96fc7a286f45173051a1a0e05b33c81699b469","frame_index":0,"kind":"data","monotonic_ns":224023909244916,"payload":{"asset_id":"8698449539441374295770236407991735029336433231649246775082939325523552031992","best_ask":"0.86","best_bid":"0.85","event_type":"best_bid_ask","market":"0xf9d60bb033695053c4d1d8592e52171c1042f64b41a4b72e09dcc6f4852b6670","spread":"0.01","timestamp":"1785122040679"},"payload_hash":"b52d71430116b3aa29d23e7f7de59dc36f8fe9d460ac8b4dcf3d17380d822f02","raw_frame":"{\"market\":\"0xf9d60bb033695053c4d1d8592e52171c1042f64b41a4b72e09dcc6f4852b6670\", \"asset_id\":\"8698449539441374295770236407991735029336433231649246775082939325523552031992\", \"best_bid\":\"0.85\", \"best_ask\":\"0.86\", \"spread\":\"0.01\", \"timestamp\":\"1785122040679\", \"event_type\":\"best_bid_ask\"}","received_at":"2026-07-27T03:14:00.576409Z","schema_version":"clob-market-ws.best_bid_ask.v1","sequence":null,"server_hash":null,"server_timestamp":"1785122040679","session_id":"ff6d21c8283948938400a32613abec2c","source":"clob_market_ws"},"received_at":"2026-07-27T03:14:00.576409Z","record_id":"d6a789e328f820eff1431eb0779a9ad53e9d1ff8a5a6522dd2c076261b382334","schema_fingerprint":"8488399f31b0337811b13b266be932db7062827c2470b78bd8e9e99bab51d17d","schema_version":"edge-lab-recorder.raw.v1","sequence":null,"source":"clob_market_ws"}
{"event_at":"2026-07-27T03:14:00.679000Z","event_fingerprint":"9d14aff7b9a9243cbb712a82bba90c9b5ebf8b7deb67e13e138f1a39bed54551","payload":{"connection_id":"f95883f18d264834af91809e5f803e9f","event_at":"2026-07-27T03:14:00.679000Z","event_type":"best_bid_ask","frame_hash":"6ad278844735203e9de8a80fe26307ba365487e601b38d08ef00b49827a6daa7","frame_index":0,"kind":"data","monotonic_ns":224023910616250,"payload":{"asset_id":"96283536366176669581486355171583722558858323126916278856549586825357358273536","best_ask":"0.15","best_bid":"0.14","event_type":"best_bid_ask","market":"0xf9d60bb033695053c4d1d8592e52171c1042f64b41a4b72e09dcc6f4852b6670","spread":"0.01","timestamp":"1785122040679"},"payload_hash":"453d53efc6bf6beecbea578bea32156518e06ec65cdc1f54f6c15bcba6c88873","raw_frame":"{\"market\":\"0xf9d60bb033695053c4d1d8592e52171c1042f64b41a4b72e09dcc6f4852b6670\", \"asset_id\":\"96283536366176669581486355171583722558858323126916278856549586825357358273536\", \"best_bid\":\"0.14\", \"best_ask\":\"0.15\", \"spread\":\"0.01\", \"timestamp\":\"1785122040679\", \"event_type\":\"best_bid_ask\"}","received_at":"2026-07-27T03:14:00.577782Z","schema_version":"clob-market-ws.best_bid_ask.v1","sequence":null,"server_hash":null,"server_timestamp":"1785122040679","session_id":"ff6d21c8283948938400a32613abec2c","source":"clob_market_ws"},"received_at":"2026-07-27T03:14:00.577782Z","record_id":"501904c4e0150018ca67d5316adf08901fee20f5945b4e19c75477eb58901dbc","schema_fingerprint":"8488399f31b0337811b13b266be932db7062827c2470b78bd8e9e99bab51d17d","schema_version":"edge-lab-recorder.raw.v1","sequence":null,"source":"clob_market_ws"}
{"event_at":"2026-07-27T03:14:00.679000Z","event_fingerprint":"797f4bcea32bda6f01f35a9c65e6b4a5529d3656adaf4e11c0a3e4f9bf9b58d5","payload":{"connection_id":"f95883f18d264834af91809e5f803e9f","event_at":"2026-07-27T03:14:00.679000Z","event_type":"price_change","frame_hash":"d957451dbd6d6c3504ccb9cbb3ff4b32606eda82e26bc0ac937d685cc1f65dc9","frame_index":0,"kind":"data","monotonic_ns":224023911784125,"payload":{"event_type":"price_change","market":"0xf9d60bb033695053c4d1d8592e52171c1042f64b41a4b72e09dcc6f4852b6670","price_changes":[{"asset_id":"96283536366176669581486355171583722558858323126916278856549586825357358273536","best_ask":"0.15","best_bid":"0.14","hash":"ebda7844d84a4da7c3de9394c5aeb23276ba68b0","price":"0.14","side":"BUY","size":"75"},{"asset_id":"8698449539441374295770236407991735029336433231649246775082939325523552031992","best_ask":"0.86","best_bid":"0.85","hash":"b230dbaa5f6dac36f05855c3b7da98c8193a0f21","price":"0.86","side":"SELL","size":"75"}],"timestamp":"1785122040679"},"payload_hash":"93b84e162581fdca903adc6acb9a229a2b8ca30e770d90385eefcab86c06808c","raw_frame":"{\"market\":\"0xf9d60bb033695053c4d1d8592e52171c1042f64b41a4b72e09dcc6f4852b6670\", \"price_changes\":[{\"asset_id\":\"96283536366176669581486355171583722558858323126916278856549586825357358273536\", \"price\":\"0.14\", \"size\":\"75\", \"side\":\"BUY\", \"hash\":\"ebda7844d84a4da7c3de9394c5aeb23276ba68b0\", \"best_bid\":\"0.14\", \"best_ask\":\"0.15\"}, {\"asset_id\":\"8698449539441374295770236407991735029336433231649246775082939325523552031992\", \"price\":\"0.86\", \"size\":\"75\", \"side\":\"SELL\", \"hash\":\"b230dbaa5f6dac36f05855c3b7da98c8193a0f21\", \"best_bid\":\"0.85\", \"best_ask\":\"0.86\"}], \"timestamp\":\"1785122040679\", \"event_type\":\"price_change\"}","received_at":"2026-07-27T03:14:00.578951Z","schema_version":"clob-market-ws.price_change.v1","sequence":null,"server_hash":null,"server_timestamp":"1785122040679","session_id":"ff6d21c8283948938400a32613abec2c","source":"clob_market_ws"},"received_at":"2026-07-27T03:14:00.578951Z","record_id":"42dead7ecba9882096020585cb4988a1fb6f43c87c4362174c44a47dfeeac8fd","schema_fingerprint":"4aa3821a28b0b7c2400bc59aba4bcc0a76e971dadd19610d3ad38c768e124dc7","schema_version":"edge-lab-recorder.raw.v1","sequence":null,"source":"clob_market_ws"}
{"event_at":"2026-07-27T03:14:00.681000Z","event_fingerprint":"4fc7a2c719a3112f51479239e88dc052b7f77eec0ea9980395918866fabd4a10","payload":{"connection_id":"f95883f18d264834af91809e5f803e9f","event_at":"2026-07-27T03:14:00.681000Z","event_type":"best_bid_ask","frame_hash":"d72989d64702ad38073c9092cd963a2aba44a990dbec7c85350a97f4c481dff0","frame_index":0,"kind":"data","monotonic_ns":224023913774291,"payload":{"asset_id":"8698449539441374295770236407991735029336433231649246775082939325523552031992","best_ask":"0.87","best_bid":"0.85","event_type":"best_bid_ask","market":"0xf9d60bb033695053c4d1d8592e52171c1042f64b41a4b72e09dcc6f4852b6670","spread":"0.02","timestamp":"1785122040681"},"payload_hash":"21d81cfa708069cb9823584aff7cf1be41cca13498f14160853ef7cbd0bb626b","raw_frame":"{\"market\":\"0xf9d60bb033695053c4d1d8592e52171c1042f64b41a4b72e09dcc6f4852b6670\", \"asset_id\":\"8698449539441374295770236407991735029336433231649246775082939325523552031992\", \"best_bid\":\"0.85\", \"best_ask\":\"0.87\", \"spread\":\"0.02\", \"timestamp\":\"1785122040681\", \"event_type\":\"best_bid_ask\"}","received_at":"2026-07-27T03:14:00.580940Z","schema_version":"clob-market-ws.best_bid_ask.v1","sequence":null,"server_hash":null,"server_timestamp":"1785122040681","session_id":"ff6d21c8283948938400a32613abec2c","source":"clob_market_ws"},"received_at":"2026-07-27T03:14:00.580940Z","record_id":"e0de2c8709b225d56eb394abaca495c9eaa447b72a320410834a8577e9e26a6f","schema_fingerprint":"8488399f31b0337811b13b266be932db7062827c2470b78bd8e9e99bab51d17d","schema_version":"edge-lab-recorder.raw.v1","sequence":null,"source":"clob_market_ws"}
{"event_at":"2026-07-27T03:14:00.681000Z","event_fingerprint":"a97eb2096a857bac1f5f9f9fc888a4ccf9d244ebe6a34325a90a3a643246afae","payload":{"connection_id":"f95883f18d264834af91809e5f803e9f","event_at":"2026-07-27T03:14:00.681000Z","event_type":"best_bid_ask","frame_hash":"f3b6a14448dd2b8a191825ceed624777d1fc7900fa5a970781a66b5bd1b10537","frame_index":0,"kind":"data","monotonic_ns":224023914928375,"payload":{"asset_id":"96283536366176669581486355171583722558858323126916278856549586825357358273536","best_ask":"0.15","best_bid":"0.13","event_type":"best_bid_ask","market":"0xf9d60bb033695053c4d1d8592e52171c1042f64b41a4b72e09dcc6f4852b6670","spread":"0.02","timestamp":"1785122040681"},"payload_hash":"d964ff7986bc80dfdc1464d3a25253a52fef681b48f07270251c9e642a286791","raw_frame":"{\"market\":\"0xf9d60bb033695053c4d1d8592e52171c1042f64b41a4b72e09dcc6f4852b6670\", \"asset_id\":\"96283536366176669581486355171583722558858323126916278856549586825357358273536\", \"best_bid\":\"0.13\", \"best_ask\":\"0.15\", \"spread\":\"0.02\", \"timestamp\":\"1785122040681\", \"event_type\":\"best_bid_ask\"}","received_at":"2026-07-27T03:14:00.582097Z","schema_version":"clob-market-ws.best_bid_ask.v1","sequence":null,"server_hash":null,"server_timestamp":"1785122040681","session_id":"ff6d21c8283948938400a32613abec2c","source":"clob_market_ws"},"received_at":"2026-07-27T03:14:00.582097Z","record_id":"b6da3a75f9ee0a291ce0e75ca93879088df7117b56b07690b255cdd2cb98b0fa","schema_fingerprint":"8488399f31b0337811b13b266be932db7062827c2470b78bd8e9e99bab51d17d","schema_version":"edge-lab-recorder.raw.v1","sequence":null,"source":"clob_market_ws"}
{"event_at":"2026-07-27T03:14:00.681000Z","event_fingerprint":"628ba8b98be39038a17bf24f387e40a45ac047d29b5253619ecc080b67308085","payload":{"connection_id":"f95883f18d264834af91809e5f803e9f","event_at":"2026-07-27T03:14:00.681000Z","event_type":"price_change","frame_hash":"6891675c8688aea553293b5c2a98ed931b8082dd6bcc2e94271ae7fef1a54127","frame_index":0,"kind":"data","monotonic_ns":224023916020083,"payload":{"event_type":"price_change","market":"0xf9d60bb033695053c4d1d8592e52171c1042f64b41a4b72e09dcc6f4852b6670","price_changes":[{"asset_id":"96283536366176669581486355171583722558858323126916278856549586825357358273536","best_ask":"0.15","best_bid":"0.13","hash":"f0fa78c1044a49fe9b5295b39ec15452a2679bbe","price":"0.14","side":"BUY","size":"0"},{"asset_id":"8698449539441374295770236407991735029336433231649246775082939325523552031992","best_ask":"0.87","best_bid":"0.85","hash":"1a54ddc6b864cb4d0a86cd658bc9c2c84e41a0e0","price":"0.86","side":"SELL","size":"0"}],"timestamp":"1785122040681"},"payload_hash":"cf6bbe113533f4c5625dbfe507228d65106a1567abf8460d3fabe5155e269f72","raw_frame":"{\"market\":\"0xf9d60bb033695053c4d1d8592e52171c1042f64b41a4b72e09dcc6f4852b6670\", \"price_changes\":[{\"asset_id\":\"96283536366176669581486355171583722558858323126916278856549586825357358273536\", \"price\":\"0.14\", \"size\":\"0\", \"side\":\"BUY\", \"hash\":\"f0fa78c1044a49fe9b5295b39ec15452a2679bbe\", \"best_bid\":\"0.13\", \"best_ask\":\"0.15\"}, {\"asset_id\":\"8698449539441374295770236407991735029336433231649246775082939325523552031992\", \"price\":\"0.86\", \"size\":\"0\", \"side\":\"SELL\", \"hash\":\"1a54ddc6b864cb4d0a86cd658bc9c2c84e41a0e0\", \"best_bid\":\"0.85\", \"best_ask\":\"0.87\"}], \"timestamp\":\"1785122040681\", \"event_type\":\"price_change\"}","received_at":"2026-07-27T03:14:00.583189Z","schema_version":"clob-market-ws.price_change.v1","sequence":null,"server_hash":null,"server_timestamp":"1785122040681","session_id":"ff6d21c8283948938400a32613abec2c","source":"clob_market_ws"},"received_at":"2026-07-27T03:14:00.583189Z","record_id":"e86362a775bfbddf02ef2b2126421f81bcfda7e4d8643e5750d1f210881fffe3","schema_fingerprint":"4aa3821a28b0b7c2400bc59aba4bcc0a76e971dadd19610d3ad38c768e124dc7","schema_version":"edge-lab-recorder.raw.v1","sequence":null,"source":"clob_market_ws"}
{"event_at":"2026-07-27T03:14:00.682000Z","event_fingerprint":"6901971225759c9fef22f80b3ee73d13f631f841b21a7828abd1ee1835ea224c","payload":{"connection_id":"f95883f18d264834af91809e5f803e9f","event_at":"2026-07-27T03:14:00.682000Z","event_type":"price_change","frame_hash":"2ba973d8e1ddbf9405f3fb930bdb6ffc7d143dd384eeba8cf06edc0d98d3dd79","frame_index":0,"kind":"data","monotonic_ns":224023917585208,"payload":{"event_type":"price_change","market":"0xf9d60bb033695053c4d1d8592e52171c1042f64b41a4b72e09dcc6f4852b6670","price_changes":[{"asset_id":"8698449539441374295770236407991735029336433231649246775082939325523552031992","best_ask":"0.87","best_bid":"0.85","hash":"e855e70f1b742348b667f1212bfe8d43ef63e15d","price":"0.01","side":"BUY","size":"7622.5"},{"asset_id":"96283536366176669581486355171583722558858323126916278856549586825357358273536","best_ask":"0.15","best_bid":"0.13","hash":"fca3888a9d74c8872600de15f6ea6c7baa424c78","price":"0.99","side":"SELL","size":"7622.5"}],"timestamp":"1785122040682"},"payload_hash":"71d3d277d3531a81ccc312688711e4752b27b6abacaceccabc67c3a3896915d5","raw_frame":"{\"market\":\"0xf9d60bb033695053c4d1d8592e52171c1042f64b41a4b72e09dcc6f4852b6670\", \"price_changes\":[{\"asset_id\":\"8698449539441374295770236407991735029336433231649246775082939325523552031992\", \"price\":\"0.01\", \"size\":\"7622.5\", \"side\":\"BUY\", \"hash\":\"e855e70f1b742348b667f1212bfe8d43ef63e15d\", \"best_bid\":\"0.85\", \"best_ask\":\"0.87\"}, {\"asset_id\":\"96283536366176669581486355171583722558858323126916278856549586825357358273536\", \"price\":\"0.99\", \"size\":\"7622.5\", \"side\":\"SELL\", \"hash\":\"fca3888a9d74c8872600de15f6ea6c7baa424c78\", \"best_bid\":\"0.13\", \"best_ask\":\"0.15\"}], \"timestamp\":\"1785122040682\", \"event_type\":\"price_change\"}","received_at":"2026-07-27T03:14:00.584751Z","schema_version":"clob-market-ws.price_change.v1","sequence":null,"server_hash":null,"server_timestamp":"1785122040682","session_id":"ff6d21c8283948938400a32613abec2c","source":"clob_market_ws"},"received_at":"2026-07-27T03:14:00.584751Z","record_id":"bf193f23a245132fcb4de1bde3812f12cddb37d6ecf4825c31b0cd970834f2a2","schema_fingerprint":"4aa3821a28b0b7c2400bc59aba4bcc0a76e971dadd19610d3ad38c768e124dc7","schema_version":"edge-lab-recorder.raw.v1","sequence":null,"source":"clob_market_ws"}
