{"event_at":"2026-07-27T03:11:57.635000Z","event_fingerprint":"a8f596a114eee64ff0fd5d40cccc75e927efe3a2312d602545eec2fb9e5e02d2","payload":{"connection_id":"f95883f18d264834af91809e5f803e9f","event_at":"2026-07-27T03:11:57.635000Z","event_type":"price_change","frame_hash":"0b04b5fbdeedbfc619088d33e99f1703d7cbaad640e5f509d30a2a41b04ccf9c","frame_index":0,"kind":"data","monotonic_ns":223907238404333,"payload":{"event_type":"price_change","market":"0xf9d60bb033695053c4d1d8592e52171c1042f64b41a4b72e09dcc6f4852b6670","price_changes":[{"asset_id":"96283536366176669581486355171583722558858323126916278856549586825357358273536","best_ask":"0.42","best_bid":"0.41","hash":"a8d0b67be3fc3c3d42046e9c742006d3ccffcc7d","price":"0.41","side":"BUY","size":"1.65"},{"asset_id":"8698449539441374295770236407991735029336433231649246775082939325523552031992","best_ask":"0.59","best_bid":"0.58","hash":"9c7980a0fbfb8f7d7a3e9959f9ff0a539b3070d0","price":"0.59","side":"SELL","size":"1.65"}],"timestamp":"1785121917635"},"payload_hash":"879bec35b61fc00ac40458901248b97e0b286793a2e98c39ba509218839b9b53","raw_frame":"{\"market\":\"0xf9d60bb033695053c4d1d8592e52171c1042f64b41a4b72e09dcc6f4852b6670\", \"price_changes\":[{\"asset_id\":\"96283536366176669581486355171583722558858323126916278856549586825357358273536\", \"price\":\"0.41\", \"size\":\"1.65\", \"side\":\"BUY\", \"hash\":\"a8d0b67be3fc3c3d42046e9c742006d3ccffcc7d\", \"best_bid\":\"0.41\", \"best_ask\":\"0.42\"}, {\"asset_id\":\"8698449539441374295770236407991735029336433231649246775082939325523552031992\", \"price\":\"0.59\", \"size\":\"1.65\", \"side\":\"SELL\", \"hash\":\"9c7980a0fbfb8f7d7a3e9959f9ff0a539b3070d0\", \"best_bid\":\"0.58\", \"best_ask\":\"0.59\"}], \"timestamp\":\"1785121917635\", \"event_type\":\"price_change\"}","received_at":"2026-07-27T03:12:03.907215Z","schema_version":"clob-market-ws.price_change.v1","sequence":null,"server_hash":null,"server_timestamp":"1785121917635","session_id":"ff6d21c8283948938400a32613abec2c","source":"clob_market_ws"},"received_at":"2026-07-27T03:12:03.907215Z","record_id":"175d64ee5d6b6e8416b0c2e1475b961c37c14fe56b566cf64e2c7848a22d6bf8","schema_fingerprint":"4aa3821a28b0b7c2400bc59aba4bcc0a76e971dadd19610d3ad38c768e124dc7","schema_version":"edge-lab-recorder.raw.v1","sequence":null,"source":"clob_market_ws"}
{"event_at":null,"event_fingerprint":"353923781898a2d29d61ad49fc67976c83d6b504312181109d29c845fd8b27e1","payload":{"connection_id":"f95883f18d264834af91809e5f803e9f","detail":{"current_server_timestamp":"1785121917635","entity":"clob_market_ws:8698449539441374295770236407991735029336433231649246775082939325523552031992","previous_server_timestamp":"1785121917636"},"event_type":"anomaly.time_regression","kind":"diagnostic","monotonic_ns":223907240594916,"received_at":"2026-07-27T03:12:03.909405Z","schema_version":"edge-lab-recorder.anomaly.v1","session_id":"ff6d21c8283948938400a32613abec2c","source":"clob_market_ws","trigger_frame_hash":"2f15bf61aeea925c438d4f887d5b694d4920c9885ac09a674250657a3c886abe","trigger_server_hash":"9c7980a0fbfb8f7d7a3e9959f9ff0a539b3070d0"},"received_at":"2026-07-27T03:12:03.909405Z","record_id":"59ad1cdc733b306a3b4ef9278dc25f6d57b0d79efa18d9c32f3b923bd5ab1935","schema_fingerprint":"cb1780324c96914017c24d4692a681315845f9745a5a4a3a289c5a43388b35c3","schema_version":"edge-lab-recorder.raw.v1","sequence":null,"source":"clob_market_ws"}
{"event_at":"2026-07-27T03:11:57.635000Z","event_fingerprint":"141d567e88792936359bb581cf2876ffb3bdaf1f91ecabad4d7e8d3b50917c7e","payload":{"connection_id":"f95883f18d264834af91809e5f803e9f","event_at":"2026-07-27T03:11:57.635000Z","event_type":"book","frame_hash":"2f15bf61aeea925c438d4f887d5b694d4920c9885ac09a674250657a3c886abe","frame_index":0,"kind":"data","monotonic_ns":223907240448208,"payload":{"asks":[{"price":"0.99","size":"7871.52"},{"price":"0.98","size":"1065.79"},{"price":"0.97","size":"900.8"},{"price":"0.96","size":"773.5"},{"price":"0.95","size":"761"},{"price":"0.94","size":"716.09"},{"price":"0.93","size":"661.2"},{"price":"0.92","size":"642.59"},{"price":"0.91","size":"658.1"},{"price":"0.9","size":"116.6"},{"price":"0.89","size":"107.29"},{"price":"0.88","size":"129.4"},{"price":"0.87","size":"92.9"},{"price":"0.86","size":"87.2"},{"price":"0.85","size":"112.39"},{"price":"0.84","size":"87.1"},{"price":"0.83","size":"83.29"},{"price":"0.82","size":"117.9"},{"price":"0.81","size":"76.19"},{"price":"0.8","size":"73.6"},{"price":"0.79","size":"101.3"},{"price":"0.78","size":"68.2"},{"price":"0.77","size":"66.3"},{"price":"0.76","size":"115.6"},{"price":"0.75","size":"83"},{"price":"0.74","size":"79.6"},{"price":"0.73","size":"118.3"},{"price":"0.72","size":"86"},{"price":"0.71","size":"83.88"},{"price":"0.7","size":"123"},{"price":"0.69","size":"71.1"},{"price":"0.68","size":"106.53"},{"price":"0.67","size":"52.16"},{"price":"0.66","size":"62.35"},{"price":"0.65","size":"22.21"},{"price":"0.64","size":"30.69"},{"price":"0.63","size":"43.56"},{"price":"0.62","size":"36.63"},{"price":"0.61","size":"10"},{"price":"0.6","size":"5"},{"price":"0.59","size":"1.65"}],"asset_id":"8698449539441374295770236407991735029336433231649246775082939325523552031992","bids":[{"price":"0.01","size":"8142.52"},{"price":"0.02","size":"1365.79"},{"price":"0.03","size":"1124.13"},{"price":"0.04","size":"1081.5"},{"price":"0.05","size":"947"},{"price":"0.06","size":"908.09"},{"price":"0.07","size":"456.2"},{"price":"0.08","size":"168.65"},{"price":"0.09","size":"343.1"},{"price":"0.1","size":"403.6"},{"price":"0.11","size":"120.29"},{"price":"0.12","size":"144.4"},{"price":"0.13","size":"133.9"},{"price":"0.14","size":"97.2"},{"price":"0.15","size":"116.39"},{"price":"0.16","size":"122.1"},{"price":"0.17","size":"133.29"},{"price":"0.18","size":"111.89"},{"price":"0.19","size":"132.19"},{"price":"0.2","size":"145.6"},{"price":"0.21","size":"95.3"},{"price":"0.22","size":"138.2"},{"price":"0.23","size":"93.3"},{"price":"0.24","size":"101.6"},{"price":"0.25","size":"113"},{"price":"0.26","size":"115.6"},{"price":"0.27","size":"83.3"},{"price":"0.28","size":"121"},{"price":"0.29","size":"73.88"},{"price":"0.3","size":"87"},{"price":"0.31","size":"101.1"},{"price":"0.32","size":"84.18"},{"price":"0.33","size":"68.5"},{"price":"0.34","size":"110.79"},{"price":"0.35","size":"65.1"},{"price":"0.36","size":"66.33"},{"price":"0.37","size":"77.4"},{"price":"0.38","size":"41"},{"price":"0.39","size":"190.7"},{"price":"0.4","size":"101.7"},{"price":"0.41","size":"44.4"},{"price":"0.42","size":"71.09"},{"price":"0.43","size":"148.48"},{"price":"0.44","size":"117.36"},{"price":"0.45","size":"37.31"},{"price":"0.46","size":"67.17"},{"price":"0.47","size":"11"},{"price":"0.48","size":"10"},{"price":"0.49","size":"40"},{"price":"0.5","size":"33.64"},{"price":"0.51","size":"20"},{"price":"0.52","size":"130"},{"price":"0.53","size":"5.62"},{"price":"0.54","size":"105"},{"price":"0.55","size":"119.05"},{"price":"0.56","size":"110"},{"price":"0.57","size":"105"},{"price":"0.58","size":"40.54"}],"event_type":"book","hash":"9c7980a0fbfb8f7d7a3e9959f9ff0a539b3070d0","market":"0xf9d60bb033695053c4d1d8592e52171c1042f64b41a4b72e09dcc6f4852b6670","timestamp":"1785121917635"},"payload_hash":"bb294682ebe749aed00b1927e9b4d9b74bbd9957671725672be4fdcea3d96f19","raw_frame":"{\"market\":\"0xf9d60bb033695053c4d1d8592e52171c1042f64b41a4b72e09dcc6f4852b6670\", \"asset_id\":\"8698449539441374295770236407991735029336433231649246775082939325523552031992\", \"bids\":[{\"price\":\"0.01\", \"size\":\"8142.52\"}, {\"price\":\"0.02\", \"size\":\"1365.79\"}, {\"price\":\"0.03\", \"size\":\"1124.13\"}, {\"price\":\"0.04\", \"size\":\"1081.5\"}, {\"price\":\"0.05\", \"size\":\"947\"}, {\"price\":\"0.06\", \"size\":\"908.09\"}, {\"price\":\"0.07\", \"size\":\"456.2\"}, {\"price\":\"0.08\", \"size\":\"168.65\"}, {\"price\":\"0.09\", \"size\":\"343.1\"}, {\"price\":\"0.1\", \"size\":\"403.6\"}, {\"price\":\"0.11\", \"size\":\"120.29\"}, {\"price\":\"0.12\", \"size\":\"144.4\"}, {\"price\":\"0.13\", \"size\":\"133.9\"}, {\"price\":\"0.14\", \"size\":\"97.2\"}, {\"price\":\"0.15\", \"size\":\"116.39\"}, {\"price\":\"0.16\", \"size\":\"122.1\"}, {\"price\":\"0.17\", \"size\":\"133.29\"}, {\"price\":\"0.18\", \"size\":\"111.89\"}, {\"price\":\"0.19\", \"size\":\"132.19\"}, {\"price\":\"0.2\", \"size\":\"145.6\"}, {\"price\":\"0.21\", \"size\":\"95.3\"}, {\"price\":\"0.22\", \"size\":\"138.2\"}, {\"price\":\"0.23\", \"size\":\"93.3\"}, {\"price\":\"0.24\", \"size\":\"101.6\"}, {\"price\":\"0.25\", \"size\":\"113\"}, {\"price\":\"0.26\", \"size\":\"115.6\"}, {\"price\":\"0.27\", \"size\":\"83.3\"}, {\"price\":\"0.28\", \"size\":\"121\"}, {\"price\":\"0.29\", \"size\":\"73.88\"}, {\"price\":\"0.3\", \"size\":\"87\"}, {\"price\":\"0.31\", \"size\":\"101.1\"}, {\"price\":\"0.32\", \"size\":\"84.18\"}, {\"price\":\"0.33\", \"size\":\"68.5\"}, {\"price\":\"0.34\", \"size\":\"110.79\"}, {\"price\":\"0.35\", \"size\":\"65.1\"}, {\"price\":\"0.36\", \"size\":\"66.33\"}, {\"price\":\"0.37\", \"size\":\"77.4\"}, {\"price\":\"0.38\", \"size\":\"41\"}, {\"price\":\"0.39\", \"size\":\"190.7\"}, {\"price\":\"0.4\", \"size\":\"101.7\"}, {\"price\":\"0.41\", \"size\":\"44.4\"}, {\"price\":\"0.42\", \"size\":\"71.09\"}, {\"price\":\"0.43\", \"size\":\"148.48\"}, {\"price\":\"0.44\", \"size\":\"117.36\"}, {\"price\":\"0.45\", \"size\":\"37.31\"}, {\"price\":\"0.46\", \"size\":\"67.17\"}, {\"price\":\"0.47\", \"size\":\"11\"}, {\"price\":\"0.48\", \"size\":\"10\"}, {\"price\":\"0.49\", \"size\":\"40\"}, {\"price\":\"0.5\", \"size\":\"33.64\"}, {\"price\":\"0.51\", \"size\":\"20\"}, {\"price\":\"0.52\", \"size\":\"130\"}, {\"price\":\"0.53\", \"size\":\"5.62\"}, {\"price\":\"0.54\", \"size\":\"105\"}, {\"price\":\"0.55\", \"size\":\"119.05\"}, {\"price\":\"0.56\", \"size\":\"110\"}, {\"price\":\"0.57\", \"size\":\"105\"}, {\"price\":\"0.58\", \"size\":\"40.54\"}], \"asks\":[{\"price\":\"0.99\", \"size\":\"7871.52\"}, {\"price\":\"0.98\", \"size\":\"1065.79\"}, {\"price\":\"0.97\", \"size\":\"900.8\"}, {\"price\":\"0.96\", \"size\":\"773.5\"}, {\"price\":\"0.95\", \"size\":\"761\"}, {\"price\":\"0.94\", \"size\":\"716.09\"}, {\"price\":\"0.93\", \"size\":\"661.2\"}, {\"price\":\"0.92\", \"size\":\"642.59\"}, {\"price\":\"0.91\", \"size\":\"658.1\"}, {\"price\":\"0.9\", \"size\":\"116.6\"}, {\"price\":\"0.89\", \"size\":\"107.29\"}, {\"price\":\"0.88\", \"size\":\"129.4\"}, {\"price\":\"0.87\", \"size\":\"92.9\"}, {\"price\":\"0.86\", \"size\":\"87.2\"}, {\"price\":\"0.85\", \"size\":\"112.39\"}, {\"price\":\"0.84\", \"size\":\"87.1\"}, {\"price\":\"0.83\", \"size\":\"83.29\"}, {\"price\":\"0.82\", \"size\":\"117.9\"}, {\"price\":\"0.81\", \"size\":\"76.19\"}, {\"price\":\"0.8\", \"size\":\"73.6\"}, {\"price\":\"0.79\", \"size\":\"101.3\"}, {\"price\":\"0.78\", \"size\":\"68.2\"}, {\"price\":\"0.77\", \"size\":\"66.3\"}, {\"price\":\"0.76\", \"size\":\"115.6\"}, {\"price\":\"0.75\", \"size\":\"83\"}, {\"price\":\"0.74\", \"size\":\"79.6\"}, {\"price\":\"0.73\", \"size\":\"118.3\"}, {\"price\":\"0.72\", \"size\":\"86\"}, {\"price\":\"0.71\", \"size\":\"83.88\"}, {\"price\":\"0.7\", \"size\":\"123\"}, {\"price\":\"0.69\", \"size\":\"71.1\"}, {\"price\":\"0.68\", \"size\":\"106.53\"}, {\"price\":\"0.67\", \"size\":\"52.16\"}, {\"price\":\"0.66\", \"size\":\"62.35\"}, {\"price\":\"0.65\", \"size\":\"22.21\"}, {\"price\":\"0.64\", \"size\":\"30.69\"}, {\"price\":\"0.63\", \"size\":\"43.56\"}, {\"price\":\"0.62\", \"size\":\"36.63\"}, {\"price\":\"0.61\", \"size\":\"10\"}, {\"price\":\"0.6\", \"size\":\"5\"}, {\"price\":\"0.59\", \"size\":\"1.65\"}], \"hash\":\"9c7980a0fbfb8f7d7a3e9959f9ff0a539b3070d0\", \"timestamp\":\"1785121917635\", \"event_type\":\"book\"}","received_at":"2026-07-27T03:12:03.909258Z","schema_version":"clob-market-ws.book.v1","sequence":null,"server_hash":"9c7980a0fbfb8f7d7a3e9959f9ff0a539b3070d0","server_timestamp":"1785121917635","session_id":"ff6d21c8283948938400a32613abec2c","source":"clob_market_ws"},"received_at":"2026-07-27T03:12:03.909258Z","record_id":"3da23fa9f30226603172047b9d0867d8a22e3c7fd3ee16730f5e76ba003e993e","schema_fingerprint":"dc2caa1c89c6a7426e2e07ff925910cd4d0a8a223a515d4092d91d6d127aacb6","schema_version":"edge-lab-recorder.raw.v1","sequence":null,"source":"clob_market_ws"}
{"event_at":null,"event_fingerprint":"93f450c3af783e107ac14c842cfdc0aa30a9558d9b066f1ae9982b9196b21da5","payload":{"connection_id":"f95883f18d264834af91809e5f803e9f","detail":{"current_server_timestamp":"1785121917635","entity":"clob_market_ws:96283536366176669581486355171583722558858323126916278856549586825357358273536","previous_server_timestamp":"1785121917636"},"event_type":"anomaly.time_regression","kind":"diagnostic","monotonic_ns":223907245475208,"received_at":"2026-07-27T03:12:03.914285Z","schema_version":"edge-lab-recorder.anomaly.v1","session_id":"ff6d21c8283948938400a32613abec2c","source":"clob_market_ws","trigger_frame_hash":"4ba197daa146c0b3dc242fd2883464a7f1939bba7262927ec141d9d1a508b702","trigger_server_hash":"a8d0b67be3fc3c3d42046e9c742006d3ccffcc7d"},"received_at":"2026-07-27T03:12:03.914285Z","record_id":"e83ec11a720749d3c56b58392561c380309cb033a3b18cbe2d1a864a38e75b1e","schema_fingerprint":"cb1780324c96914017c24d4692a681315845f9745a5a4a3a289c5a43388b35c3","schema_version":"edge-lab-recorder.raw.v1","sequence":null,"source":"clob_market_ws"}
{"event_at":"2026-07-27T03:11:57.635000Z","event_fingerprint":"0c3f18e0cd46930ce3774ceb93b99c1d89ee1e00a6f0d1ac3c99ccd6f957a5a2","payload":{"connection_id":"f95883f18d264834af91809e5f803e9f","event_at":"2026-07-27T03:11:57.635000Z","event_type":"book","frame_hash":"4ba197daa146c0b3dc242fd2883464a7f1939bba7262927ec141d9d1a508b702","frame_index":0,"kind":"data","monotonic_ns":223907245339541,"payload":{"asks":[{"price":"0.99","size":"8142.52"},{"price":"0.98","size":"1365.79"},{"price":"0.97","size":"1124.13"},{"price":"0.96","size":"1081.5"},{"price":"0.95","size":"947"},{"price":"0.94","size":"908.09"},{"price":"0.93","size":"456.2"},{"price":"0.92","size":"168.65"},{"price":"0.91","size":"343.1"},{"price":"0.9","size":"403.6"},{"price":"0.89","size":"120.29"},{"price":"0.88","size":"144.4"},{"price":"0.87","size":"133.9"},{"price":"0.86","size":"97.2"},{"price":"0.85","size":"116.39"},{"price":"0.84","size":"122.1"},{"price":"0.83","size":"133.29"},{"price":"0.82","size":"111.89"},{"price":"0.81","size":"132.19"},{"price":"0.8","size":"145.6"},{"price":"0.79","size":"95.3"},{"price":"0.78","size":"138.2"},{"price":"0.77","size":"93.3"},{"price":"0.76","size":"101.6"},{"price":"0.75","size":"113"},{"price":"0.74","size":"115.6"},{"price":"0.73","size":"83.3"},{"price":"0.72","size":"121"},{"price":"0.71","size":"73.88"},{"price":"0.7","size":"87"},{"price":"0.69","size":"101.1"},{"price":"0.68","size":"84.18"},{"price":"0.67","size":"68.5"},{"price":"0.66","size":"110.79"},{"price":"0.65","size":"65.1"},{"price":"0.64","size":"66.33"},{"price":"0.63","size":"77.4"},{"price":"0.62","size":"41"},{"price":"0.61","size":"190.7"},{"price":"0.6","size":"101.7"},{"price":"0.59","size":"44.4"},{"price":"0.58","size":"71.09"},{"price":"0.57","size":"148.48"},{"price":"0.56","size":"117.36"},{"price":"0.55","size":"37.31"},{"price":"0.54","size":"67.17"},{"price":"0.53","size":"11"},{"price":"0.52","size":"10"},{"price":"0.51","size":"40"},{"price":"0.5","size":"33.64"},{"price":"0.49","size":"20"},{"price":"0.48","size":"130"},{"price":"0.47","size":"5.62"},{"price":"0.46","size":"105"},{"price":"0.45","size":"119.05"},{"price":"0.44","size":"110"},{"price":"0.43","size":"105"},{"price":"0.42","size":"40.54"}],"asset_id":"96283536366176669581486355171583722558858323126916278856549586825357358273536","bids":[{"price":"0.01","size":"7871.52"},{"price":"0.02","size":"1065.79"},{"price":"0.03","size":"900.8"},{"price":"0.04","size":"773.5"},{"price":"0.05","size":"761"},{"price":"0.06","size":"716.09"},{"price":"0.07","size":"661.2"},{"price":"0.08","size":"642.59"},{"price":"0.09","size":"658.1"},{"price":"0.1","size":"116.6"},{"price":"0.11","size":"107.29"},{"price":"0.12","size":"129.4"},{"price":"0.13","size":"92.9"},{"price":"0.14","size":"87.2"},{"price":"0.15","size":"112.39"},{"price":"0.16","size":"87.1"},{"price":"0.17","size":"83.29"},{"price":"0.18","size":"117.9"},{"price":"0.19","size":"76.19"},{"price":"0.2","size":"73.6"},{"price":"0.21","size":"101.3"},{"price":"0.22","size":"68.2"},{"price":"0.23","size":"66.3"},{"price":"0.24","size":"115.6"},{"price":"0.25","size":"83"},{"price":"0.26","size":"79.6"},{"price":"0.27","size":"118.3"},{"price":"0.28","size":"86"},{"price":"0.29","size":"83.88"},{"price":"0.3","size":"123"},{"price":"0.31","size":"71.1"},{"price":"0.32","size":"106.53"},{"price":"0.33","size":"52.16"},{"price":"0.34","size":"62.35"},{"price":"0.35","size":"22.21"},{"price":"0.36","size":"30.69"},{"price":"0.37","size":"43.56"},{"price":"0.38","size":"36.63"},{"price":"0.39","size":"10"},{"price":"0.4","size":"5"},{"price":"0.41","size":"1.65"}],"event_type":"book","hash":"a8d0b67be3fc3c3d42046e9c742006d3ccffcc7d","market":"0xf9d60bb033695053c4d1d8592e52171c1042f64b41a4b72e09dcc6f4852b6670","timestamp":"1785121917635"},"payload_hash":"f0d83833c6c4ae183a05dfc769abcc04091d36a588d2ab2e42c2a742c8d9eb3c","raw_frame":"{\"market\":\"0xf9d60bb033695053c4d1d8592e52171c1042f64b41a4b72e09dcc6f4852b6670\", \"asset_id\":\"96283536366176669581486355171583722558858323126916278856549586825357358273536\", \"bids\":[{\"price\":\"0.01\", \"size\":\"7871.52\"}, {\"price\":\"0.02\", \"size\":\"1065.79\"}, {\"price\":\"0.03\", \"size\":\"900.8\"}, {\"price\":\"0.04\", \"size\":\"773.5\"}, {\"price\":\"0.05\", \"size\":\"761\"}, {\"price\":\"0.06\", \"size\":\"716.09\"}, {\"price\":\"0.07\", \"size\":\"661.2\"}, {\"price\":\"0.08\", \"size\":\"642.59\"}, {\"price\":\"0.09\", \"size\":\"658.1\"}, {\"price\":\"0.1\", \"size\":\"116.6\"}, {\"price\":\"0.11\", \"size\":\"107.29\"}, {\"price\":\"0.12\", \"size\":\"129.4\"}, {\"price\":\"0.13\", \"size\":\"92.9\"}, {\"price\":\"0.14\", \"size\":\"87.2\"}, {\"price\":\"0.15\", \"size\":\"112.39\"}, {\"price\":\"0.16\", \"size\":\"87.1\"}, {\"price\":\"0.17\", \"size\":\"83.29\"}, {\"price\":\"0.18\", \"size\":\"117.9\"}, {\"price\":\"0.19\", \"size\":\"76.19\"}, {\"price\":\"0.2\", \"size\":\"73.6\"}, {\"price\":\"0.21\", \"size\":\"101.3\"}, {\"price\":\"0.22\", \"size\":\"68.2\"}, {\"price\":\"0.23\", \"size\":\"66.3\"}, {\"price\":\"0.24\", \"size\":\"115.6\"}, {\"price\":\"0.25\", \"size\":\"83\"}, {\"price\":\"0.26\", \"size\":\"79.6\"}, {\"price\":\"0.27\", \"size\":\"118.3\"}, {\"price\":\"0.28\", \"size\":\"86\"}, {\"price\":\"0.29\", \"size\":\"83.88\"}, {\"price\":\"0.3\", \"size\":\"123\"}, {\"price\":\"0.31\", \"size\":\"71.1\"}, {\"price\":\"0.32\", \"size\":\"106.53\"}, {\"price\":\"0.33\", \"size\":\"52.16\"}, {\"price\":\"0.34\", \"size\":\"62.35\"}, {\"price\":\"0.35\", \"size\":\"22.21\"}, {\"price\":\"0.36\", \"size\":\"30.69\"}, {\"price\":\"0.37\", \"size\":\"43.56\"}, {\"price\":\"0.38\", \"size\":\"36.63\"}, {\"price\":\"0.39\", \"size\":\"10\"}, {\"price\":\"0.4\", \"size\":\"5\"}, {\"price\":\"0.41\", \"size\":\"1.65\"}], \"asks\":[{\"price\":\"0.99\", \"size\":\"8142.52\"}, {\"price\":\"0.98\", \"size\":\"1365.79\"}, {\"price\":\"0.97\", \"size\":\"1124.13\"}, {\"price\":\"0.96\", \"size\":\"1081.5\"}, {\"price\":\"0.95\", \"size\":\"947\"}, {\"price\":\"0.94\", \"size\":\"908.09\"}, {\"price\":\"0.93\", \"size\":\"456.2\"}, {\"price\":\"0.92\", \"size\":\"168.65\"}, {\"price\":\"0.91\", \"size\":\"343.1\"}, {\"price\":\"0.9\", \"size\":\"403.6\"}, {\"price\":\"0.89\", \"size\":\"120.29\"}, {\"price\":\"0.88\", \"size\":\"144.4\"}, {\"price\":\"0.87\", \"size\":\"133.9\"}, {\"price\":\"0.86\", \"size\":\"97.2\"}, {\"price\":\"0.85\", \"size\":\"116.39\"}, {\"price\":\"0.84\", \"size\":\"122.1\"}, {\"price\":\"0.83\", \"size\":\"133.29\"}, {\"price\":\"0.82\", \"size\":\"111.89\"}, {\"price\":\"0.81\", \"size\":\"132.19\"}, {\"price\":\"0.8\", \"size\":\"145.6\"}, {\"price\":\"0.79\", \"size\":\"95.3\"}, {\"price\":\"0.78\", \"size\":\"138.2\"}, {\"price\":\"0.77\", \"size\":\"93.3\"}, {\"price\":\"0.76\", \"size\":\"101.6\"}, {\"price\":\"0.75\", \"size\":\"113\"}, {\"price\":\"0.74\", \"size\":\"115.6\"}, {\"price\":\"0.73\", \"size\":\"83.3\"}, {\"price\":\"0.72\", \"size\":\"121\"}, {\"price\":\"0.71\", \"size\":\"73.88\"}, {\"price\":\"0.7\", \"size\":\"87\"}, {\"price\":\"0.69\", \"size\":\"101.1\"}, {\"price\":\"0.68\", \"size\":\"84.18\"}, {\"price\":\"0.67\", \"size\":\"68.5\"}, {\"price\":\"0.66\", \"size\":\"110.79\"}, {\"price\":\"0.65\", \"size\":\"65.1\"}, {\"price\":\"0.64\", \"size\":\"66.33\"}, {\"price\":\"0.63\", \"size\":\"77.4\"}, {\"price\":\"0.62\", \"size\":\"41\"}, {\"price\":\"0.61\", \"size\":\"190.7\"}, {\"price\":\"0.6\", \"size\":\"101.7\"}, {\"price\":\"0.59\", \"size\":\"44.4\"}, {\"price\":\"0.58\", \"size\":\"71.09\"}, {\"price\":\"0.57\", \"size\":\"148.48\"}, {\"price\":\"0.56\", \"size\":\"117.36\"}, {\"price\":\"0.55\", \"size\":\"37.31\"}, {\"price\":\"0.54\", \"size\":\"67.17\"}, {\"price\":\"0.53\", \"size\":\"11\"}, {\"price\":\"0.52\", \"size\":\"10\"}, {\"price\":\"0.51\", \"size\":\"40\"}, {\"price\":\"0.5\", \"size\":\"33.64\"}, {\"price\":\"0.49\", \"size\":\"20\"}, {\"price\":\"0.48\", \"size\":\"130\"}, {\"price\":\"0.47\", \"size\":\"5.62\"}, {\"price\":\"0.46\", \"size\":\"105\"}, {\"price\":\"0.45\", \"size\":\"119.05\"}, {\"price\":\"0.44\", \"size\":\"110\"}, {\"price\":\"0.43\", \"size\":\"105\"}, {\"price\":\"0.42\", \"size\":\"40.54\"}], \"hash\":\"a8d0b67be3fc3c3d42046e9c742006d3ccffcc7d\", \"timestamp\":\"1785121917635\", \"event_type\":\"book\"}","received_at":"2026-07-27T03:12:03.914149Z","schema_version":"clob-market-ws.book.v1","sequence":null,"server_hash":"a8d0b67be3fc3c3d42046e9c742006d3ccffcc7d","server_timestamp":"1785121917635","session_id":"ff6d21c8283948938400a32613abec2c","source":"clob_market_ws"},"received_at":"2026-07-27T03:12:03.914149Z","record_id":"0eb3624444c5c1b3e9563edfdab012f15af8a85613e03a529409ce9c7f38c4e5","schema_fingerprint":"dc2caa1c89c6a7426e2e07ff925910cd4d0a8a223a515d4092d91d6d127aacb6","schema_version":"edge-lab-recorder.raw.v1","sequence":null,"source":"clob_market_ws"}
{"event_at":"2026-07-27T03:11:57.638000Z","event_fingerprint":"53e6d2c50b8d448d56d81f02c207e074d59e319dc62fcced193822eae115a1d5","payload":{"connection_id":"f95883f18d264834af91809e5f803e9f","event_at":"2026-07-27T03:11:57.638000Z","event_type":"price_change","frame_hash":"7dd8a7c9743063adb9c602676c677e33a54a6c5302853741273c4537dbc31da5","frame_index":0,"kind":"data","monotonic_ns":223907250678166,"payload":{"event_type":"price_change","market":"0xf9d60bb033695053c4d1d8592e52171c1042f64b41a4b72e09dcc6f4852b6670","price_changes":[{"asset_id":"96283536366176669581486355171583722558858323126916278856549586825357358273536","best_ask":"0.42","best_bid":"0.41","hash":"a12e205cfbc6da232d5c5854a8db407bc1783ad0","price":"0.37","side":"BUY","size":"48.56"},{"asset_id":"8698449539441374295770236407991735029336433231649246775082939325523552031992","best_ask":"0.59","best_bid":"0.58","hash":"9c45f1fd8ef325a23b6ad6578fcc7d897f04c0ef","price":"0.63","side":"SELL","size":"48.56"}],"timestamp":"1785121917638"},"payload_hash":"3239ca44469dea44ddd537e522bfa1c1bd0d6a4c51b0c84b88672974e30f16ca","raw_frame":"{\"market\":\"0xf9d60bb033695053c4d1d8592e52171c1042f64b41a4b72e09dcc6f4852b6670\", \"price_changes\":[{\"asset_id\":\"96283536366176669581486355171583722558858323126916278856549586825357358273536\", \"price\":\"0.37\", \"size\":\"48.56\", \"side\":\"BUY\", \"hash\":\"a12e205cfbc6da232d5c5854a8db407bc1783ad0\", \"best_bid\":\"0.41\", \"best_ask\":\"0.42\"}, {\"asset_id\":\"8698449539441374295770236407991735029336433231649246775082939325523552031992\", \"price\":\"0.63\", \"size\":\"48.56\", \"side\":\"SELL\", \"hash\":\"9c45f1fd8ef325a23b6ad6578fcc7d897f04c0ef\", \"best_bid\":\"0.58\", \"best_ask\":\"0.59\"}], \"timestamp\":\"1785121917638\", \"event_type\":\"price_change\"}","received_at":"2026-07-27T03:12:03.919488Z","schema_version":"clob-market-ws.price_change.v1","sequence":null,"server_hash":null,"server_timestamp":"1785121917638","session_id":"ff6d21c8283948938400a32613abec2c","source":"clob_market_ws"},"received_at":"2026-07-27T03:12:03.919488Z","record_id":"f6ef5708acd161b8214fa15a4d8b191d49e686157a47e594a4e4a2335f6b1e6b","schema_fingerprint":"4aa3821a28b0b7c2400bc59aba4bcc0a76e971dadd19610d3ad38c768e124dc7","schema_version":"edge-lab-recorder.raw.v1","sequence":null,"source":"clob_market_ws"}
{"event_at":"2026-07-27T03:11:57.639000Z","event_fingerprint":"d41be3e1f957d0ba956e3abed0f7cb6f19269dc3357adff6f04ee01b015e0b4f","payload":{"connection_id":"f95883f18d264834af91809e5f803e9f","event_at":"2026-07-27T03:11:57.639000Z","event_type":"price_change","frame_hash":"c798d3ca6563b73c842154866d6ef120fc14618b5dcacbaf280ca08d98febe1a","frame_index":0,"kind":"data","monotonic_ns":223907251839000,"payload":{"event_type":"price_change","market":"0xf9d60bb033695053c4d1d8592e52171c1042f64b41a4b72e09dcc6f4852b6670","price_changes":[{"asset_id":"96283536366176669581486355171583722558858323126916278856549586825357358273536","best_ask":"0.42","best_bid":"0.41","hash":"2e52f4978f769c2e82685b74614574d498dcbe17","price":"0.39","side":"BUY","size":"5"},{"asset_id":"8698449539441374295770236407991735029336433231649246775082939325523552031992","best_ask":"0.59","best_bid":"0.58","hash":"8a805d4b67f4ec8e2efd2ce3c9a118331e1d92c9","price":"0.61","side":"SELL","size":"5"}],"timestamp":"1785121917639"},"payload_hash":"7accee8d3151166af074f9511798eb3563679eaccf21a734b0e718534044552d","raw_frame":"{\"market\":\"0xf9d60bb033695053c4d1d8592e52171c1042f64b41a4b72e09dcc6f4852b6670\", \"price_changes\":[{\"asset_id\":\"96283536366176669581486355171583722558858323126916278856549586825357358273536\", \"price\":\"0.39\", \"size\":\"5\", \"side\":\"BUY\", \"hash\":\"2e52f4978f769c2e82685b74614574d498dcbe17\", \"best_bid\":\"0.41\", \"best_ask\":\"0.42\"}, {\"asset_id\":\"8698449539441374295770236407991735029336433231649246775082939325523552031992\", \"price\":\"0.61\", \"size\":\"5\", \"side\":\"SELL\", \"hash\":\"8a805d4b67f4ec8e2efd2ce3c9a118331e1d92c9\", \"best_bid\":\"0.58\", \"best_ask\":\"0.59\"}], \"timestamp\":\"1785121917639\", \"event_type\":\"price_change\"}","received_at":"2026-07-27T03:12:03.920649Z","schema_version":"clob-market-ws.price_change.v1","sequence":null,"server_hash":null,"server_timestamp":"1785121917639","session_id":"ff6d21c8283948938400a32613abec2c","source":"clob_market_ws"},"received_at":"2026-07-27T03:12:03.920649Z","record_id":"cc2855a0e2aa0163049f8021135e3488810ccce73c73b69b51f8c3529c780a28","schema_fingerprint":"4aa3821a28b0b7c2400bc59aba4bcc0a76e971dadd19610d3ad38c768e124dc7","schema_version":"edge-lab-recorder.raw.v1","sequence":null,"source":"clob_market_ws"}
{"event_at":"2026-07-27T03:11:57.640000Z","event_fingerprint":"9ec6d4995ae821c7566a8dba329972ccb07a725ff8e7ac1f67c0fb30477119bc","payload":{"connection_id":"f95883f18d264834af91809e5f803e9f","event_at":"2026-07-27T03:11:57.640000Z","event_type":"best_bid_ask","frame_hash":"b247f8d498ab5633551519b1ec322e0ccdd129fbe7747595e85c50e6640eb46f","frame_index":0,"kind":"data","monotonic_ns":223907253192041,"payload":{"asset_id":"8698449539441374295770236407991735029336433231649246775082939325523552031992","best_ask":"0.6","best_bid":"0.58","event_type":"best_bid_ask","market":"0xf9d60bb033695053c4d1d8592e52171c1042f64b41a4b72e09dcc6f4852b6670","spread":"0.02","timestamp":"1785121917640"},"payload_hash":"793c0049b8f1af2e73a5492e14208de5d6cfb1aece682a44c6fe93759b2bbd3f","raw_frame":"{\"market\":\"0xf9d60bb033695053c4d1d8592e52171c1042f64b41a4b72e09dcc6f4852b6670\", \"asset_id\":\"8698449539441374295770236407991735029336433231649246775082939325523552031992\", \"best_bid\":\"0.58\", \"best_ask\":\"0.6\", \"spread\":\"0.02\", \"timestamp\":\"1785121917640\", \"event_type\":\"best_bid_ask\"}","received_at":"2026-07-27T03:12:03.922001Z","schema_version":"clob-market-ws.best_bid_ask.v1","sequence":null,"server_hash":null,"server_timestamp":"1785121917640","session_id":"ff6d21c8283948938400a32613abec2c","source":"clob_market_ws"},"received_at":"2026-07-27T03:12:03.922001Z","record_id":"9e3875e712dfdfbebfacb73a8a4c6d38939e3221545073a88601d9c77a518b32","schema_fingerprint":"8488399f31b0337811b13b266be932db7062827c2470b78bd8e9e99bab51d17d","schema_version":"edge-lab-recorder.raw.v1","sequence":null,"source":"clob_market_ws"}
{"event_at":"2026-07-27T03:11:57.640000Z","event_fingerprint":"c9307aa290cf0f4842d301ba75e45891ad3a48b5da0f9334ad1448ff539c1753","payload":{"connection_id":"f95883f18d264834af91809e5f803e9f","event_at":"2026-07-27T03:11:57.640000Z","event_type":"best_bid_ask","frame_hash":"450589075b59cf7e77ed3d726aa4e4403fc1a81dd4acb6ac93e4b2dbc109a472","frame_index":0,"kind":"data","monotonic_ns":223907254123250,"payload":{"asset_id":"96283536366176669581486355171583722558858323126916278856549586825357358273536","best_ask":"0.42","best_bid":"0.4","event_type":"best_bid_ask","market":"0xf9d60bb033695053c4d1d8592e52171c1042f64b41a4b72e09dcc6f4852b6670","spread":"0.02","timestamp":"1785121917640"},"payload_hash":"38876e7fbaf60c73741d640bc0126cdf081230667c9845ada0fa5ab5f3710409","raw_frame":"{\"market\":\"0xf9d60bb033695053c4d1d8592e52171c1042f64b41a4b72e09dcc6f4852b6670\", \"asset_id\":\"96283536366176669581486355171583722558858323126916278856549586825357358273536\", \"best_bid\":\"0.4\", \"best_ask\":\"0.42\", \"spread\":\"0.02\", \"timestamp\":\"1785121917640\", \"event_type\":\"best_bid_ask\"}","received_at":"2026-07-27T03:12:03.922933Z","schema_version":"clob-market-ws.best_bid_ask.v1","sequence":null,"server_hash":null,"server_timestamp":"1785121917640","session_id":"ff6d21c8283948938400a32613abec2c","source":"clob_market_ws"},"received_at":"2026-07-27T03:12:03.922933Z","record_id":"a2fe94f8c714737fcb93bf2a2633a2d5c5a6010533a5c035bb09cf5ddd9a6f71","schema_fingerprint":"8488399f31b0337811b13b266be932db7062827c2470b78bd8e9e99bab51d17d","schema_version":"edge-lab-recorder.raw.v1","sequence":null,"source":"clob_market_ws"}
{"event_at":"2026-07-27T03:11:57.640000Z","event_fingerprint":"14d0592457f2d98a5e6dd9590e24e96841bb5dd637b2d38a229d26962662f5d2","payload":{"connection_id":"f95883f18d264834af91809e5f803e9f","event_at":"2026-07-27T03:11:57.640000Z","event_type":"price_change","frame_hash":"e0186d66a3fc42f81db9d562e50f8a282cc382956646c93390be7be4f92eac3a","frame_index":0,"kind":"data","monotonic_ns":223907257665083,"payload":{"event_type":"price_change","market":"0xf9d60bb033695053c4d1d8592e52171c1042f64b41a4b72e09dcc6f4852b6670","price_changes":[{"asset_id":"96283536366176669581486355171583722558858323126916278856549586825357358273536","best_ask":"0.42","best_bid":"0.4","hash":"713365500a04be2db76d56dae913838bec830762","price":"0.4","side":"BUY","size":"4.58"},{"asset_id":"8698449539441374295770236407991735029336433231649246775082939325523552031992","best_ask":"0.6","best_bid":"0.58","hash":"0c3c1f018d80a6be489ee2a8ef9ef0df61143961","price":"0.6","side":"SELL","size":"4.58"}],"timestamp":"1785121917640"},"payload_hash":"a64672a612472ed05a5d9daba8dcd81cc24f679462998e907612f4c4f30e40f3","raw_frame":"{\"market\":\"0xf9d60bb033695053c4d1d8592e52171c1042f64b41a4b72e09dcc6f4852b6670\", \"price_changes\":[{\"asset_id\":\"96283536366176669581486355171583722558858323126916278856549586825357358273536\", \"price\":\"0.4\", \"size\":\"4.58\", \"side\":\"BUY\", \"hash\":\"713365500a04be2db76d56dae913838bec830762\", \"best_bid\":\"0.4\", \"best_ask\":\"0.42\"}, {\"asset_id\":\"8698449539441374295770236407991735029336433231649246775082939325523552031992\", \"price\":\"0.6\", \"size\":\"4.58\", \"side\":\"SELL\", \"hash\":\"0c3c1f018d80a6be489ee2a8ef9ef0df61143961\", \"best_bid\":\"0.58\", \"best_ask\":\"0.6\"}], \"timestamp\":\"1785121917640\", \"event_type\":\"price_change\"}","received_at":"2026-07-27T03:12:03.926474Z","schema_version":"clob-market-ws.price_change.v1","sequence":null,"server_hash":null,"server_timestamp":"1785121917640","session_id":"ff6d21c8283948938400a32613abec2c","source":"clob_market_ws"},"received_at":"2026-07-27T03:12:03.926474Z","record_id":"d1e824e5e418bb902db6e8a777643ea51b1761723db872a33a586ac1e29a6713","schema_fingerprint":"4aa3821a28b0b7c2400bc59aba4bcc0a76e971dadd19610d3ad38c768e124dc7","schema_version":"edge-lab-recorder.raw.v1","sequence":null,"source":"clob_market_ws"}
{"event_at":"2026-07-27T03:11:57.640000Z","event_fingerprint":"6ea69dd21aa6dcf7b7d9b0be34e31908e63d1b8654b561a04f9e9ac344bf35eb","payload":{"connection_id":"f95883f18d264834af91809e5f803e9f","event_at":"2026-07-27T03:11:57.640000Z","event_type":"price_change","frame_hash":"744350bc75f503c963ec2abca7dbff812fa62338d5c261d0aa41ad7f7d55b74c","frame_index":0,"kind":"data","monotonic_ns":223907258872083,"payload":{"event_type":"price_change","market":"0xf9d60bb033695053c4d1d8592e52171c1042f64b41a4b72e09dcc6f4852b6670","price_changes":[{"asset_id":"96283536366176669581486355171583722558858323126916278856549586825357358273536","best_ask":"0.42","best_bid":"0.4","hash":"713365500a04be2db76d56dae913838bec830762","price":"0.41","side":"BUY","size":"0"},{"asset_id":"8698449539441374295770236407991735029336433231649246775082939325523552031992","best_ask":"0.6","best_bid":"0.58","hash":"0c3c1f018d80a6be489ee2a8ef9ef0df61143961","price":"0.59","side":"SELL","size":"0"}],"timestamp":"1785121917640"},"payload_hash":"ddec0bb8f56fa97435b9180755b68bbabc217cf18c3f9e612e338d532ac7ceec","raw_frame":"{\"market\":\"0xf9d60bb033695053c4d1d8592e52171c1042f64b41a4b72e09dcc6f4852b6670\", \"price_changes\":[{\"asset_id\":\"96283536366176669581486355171583722558858323126916278856549586825357358273536\", \"price\":\"0.41\", \"size\":\"0\", \"side\":\"BUY\", \"hash\":\"713365500a04be2db76d56dae913838bec830762\", \"best_bid\":\"0.4\", \"best_ask\":\"0.42\"}, {\"asset_id\":\"8698449539441374295770236407991735029336433231649246775082939325523552031992\", \"price\":\"0.59\", \"size\":\"0\", \"side\":\"SELL\", \"hash\":\"0c3c1f018d80a6be489ee2a8ef9ef0df61143961\", \"best_bid\":\"0.58\", \"best_ask\":\"0.6\"}], \"timestamp\":\"1785121917640\", \"event_type\":\"price_change\"}","received_at":"2026-07-27T03:12:03.927682Z","schema_version":"clob-market-ws.price_change.v1","sequence":null,"server_hash":null,"server_timestamp":"1785121917640","session_id":"ff6d21c8283948938400a32613abec2c","source":"clob_market_ws"},"received_at":"2026-07-27T03:12:03.927682Z","record_id":"82e1fdbf1f3a62ad97518214abe61b0fabe9da0d16b2d75526ad394ed46f906d","schema_fingerprint":"4aa3821a28b0b7c2400bc59aba4bcc0a76e971dadd19610d3ad38c768e124dc7","schema_version":"edge-lab-recorder.raw.v1","sequence":null,"source":"clob_market_ws"}
{"event_at":"2026-07-27T03:11:57.640000Z","event_fingerprint":"84f0ba53e7779cf43b0f9ef3b92e3d2ebbfea1eed3a8565638b8c878cc601bd3","payload":{"connection_id":"f95883f18d264834af91809e5f803e9f","event_at":"2026-07-27T03:11:57.640000Z","event_type":"book","frame_hash":"e4f174abe1cc46e351962f85268688231b52db85a9b333a92b18340ff900732a","frame_index":0,"kind":"data","monotonic_ns":223907259948333,"payload":{"asks":[{"price":"0.99","size":"7871.52"},{"price":"0.98","size":"1065.79"},{"price":"0.97","size":"900.8"},{"price":"0.96","size":"773.5"},{"price":"0.95","size":"761"},{"price":"0.94","size":"716.09"},{"price":"0.93","size":"661.2"},{"price":"0.92","size":"642.59"},{"price":"0.91","size":"658.1"},{"price":"0.9","size":"116.6"},{"price":"0.89","size":"107.29"},{"price":"0.88","size":"129.4"},{"price":"0.87","size":"92.9"},{"price":"0.86","size":"87.2"},{"price":"0.85","size":"112.39"},{"price":"0.84","size":"87.1"},{"price":"0.83","size":"83.29"},{"price":"0.82","size":"117.9"},{"price":"0.81","size":"76.19"},{"price":"0.8","size":"73.6"},{"price":"0.79","size":"101.3"},{"price":"0.78","size":"68.2"},{"price":"0.77","size":"66.3"},{"price":"0.76","size":"115.6"},{"price":"0.75","size":"83"},{"price":"0.74","size":"79.6"},{"price":"0.73","size":"118.3"},{"price":"0.72","size":"86"},{"price":"0.71","size":"83.88"},{"price":"0.7","size":"123"},{"price":"0.69","size":"71.1"},{"price":"0.68","size":"106.53"},{"price":"0.67","size":"52.16"},{"price":"0.66","size":"62.35"},{"price":"0.65","size":"22.21"},{"price":"0.64","size":"30.69"},{"price":"0.63","size":"48.56"},{"price":"0.62","size":"36.63"},{"price":"0.61","size":"5"},{"price":"0.6","size":"4.58"}],"asset_id":"8698449539441374295770236407991735029336433231649246775082939325523552031992","bids":[{"price":"0.01","size":"8142.52"},{"price":"0.02","size":"1365.79"},{"price":"0.03","size":"1124.13"},{"price":"0.04","size":"1081.5"},{"price":"0.05","size":"947"},{"price":"0.06","size":"908.09"},{"price":"0.07","size":"456.2"},{"price":"0.08","size":"168.65"},{"price":"0.09","size":"343.1"},{"price":"0.1","size":"403.6"},{"price":"0.11","size":"120.29"},{"price":"0.12","size":"144.4"},{"price":"0.13","size":"133.9"},{"price":"0.14","size":"97.2"},{"price":"0.15","size":"116.39"},{"price":"0.16","size":"122.1"},{"price":"0.17","size":"133.29"},{"price":"0.18","size":"111.89"},{"price":"0.19","size":"132.19"},{"price":"0.2","size":"145.6"},{"price":"0.21","size":"95.3"},{"price":"0.22","size":"138.2"},{"price":"0.23","size":"93.3"},{"price":"0.24","size":"101.6"},{"price":"0.25","size":"113"},{"price":"0.26","size":"115.6"},{"price":"0.27","size":"83.3"},{"price":"0.28","size":"121"},{"price":"0.29","size":"73.88"},{"price":"0.3","size":"87"},{"price":"0.31","size":"101.1"},{"price":"0.32","size":"84.18"},{"price":"0.33","size":"68.5"},{"price":"0.34","size":"110.79"},{"price":"0.35","size":"65.1"},{"price":"0.36","size":"66.33"},{"price":"0.37","size":"77.4"},{"price":"0.38","size":"41"},{"price":"0.39","size":"190.7"},{"price":"0.4","size":"101.7"},{"price":"0.41","size":"44.4"},{"price":"0.42","size":"71.09"},{"price":"0.43","size":"148.48"},{"price":"0.44","size":"117.36"},{"price":"0.45","size":"37.31"},{"price":"0.46","size":"67.17"},{"price":"0.47","size":"11"},{"price":"0.48","size":"10"},{"price":"0.49","size":"40"},{"price":"0.5","size":"33.64"},{"price":"0.51","size":"20"},{"price":"0.52","size":"130"},{"price":"0.53","size":"5.62"},{"price":"0.54","size":"105"},{"price":"0.55","size":"119.05"},{"price":"0.56","size":"110"},{"price":"0.57","size":"105"},{"price":"0.58","size":"40.54"}],"event_type":"book","hash":"0c3c1f018d80a6be489ee2a8ef9ef0df61143961","market":"0xf9d60bb033695053c4d1d8592e52171c1042f64b41a4b72e09dcc6f4852b6670","timestamp":"1785121917640"},"payload_hash":"ace9e4e8eaa180bd71fd183f9609a53bb1cf444044b97ff459d6c0b237efc913","raw_frame":"{\"market\":\"0xf9d60bb033695053c4d1d8592e52171c1042f64b41a4b72e09dcc6f4852b6670\", \"asset_id\":\"8698449539441374295770236407991735029336433231649246775082939325523552031992\", \"bids\":[{\"price\":\"0.01\", \"size\":\"8142.52\"}, {\"price\":\"0.02\", \"size\":\"1365.79\"}, {\"price\":\"0.03\", \"size\":\"1124.13\"}, {\"price\":\"0.04\", \"size\":\"1081.5\"}, {\"price\":\"0.05\", \"size\":\"947\"}, {\"price\":\"0.06\", \"size\":\"908.09\"}, {\"price\":\"0.07\", \"size\":\"456.2\"}, {\"price\":\"0.08\", \"size\":\"168.65\"}, {\"price\":\"0.09\", \"size\":\"343.1\"}, {\"price\":\"0.1\", \"size\":\"403.6\"}, {\"price\":\"0.11\", \"size\":\"120.29\"}, {\"price\":\"0.12\", \"size\":\"144.4\"}, {\"price\":\"0.13\", \"size\":\"133.9\"}, {\"price\":\"0.14\", \"size\":\"97.2\"}, {\"price\":\"0.15\", \"size\":\"116.39\"}, {\"price\":\"0.16\", \"size\":\"122.1\"}, {\"price\":\"0.17\", \"size\":\"133.29\"}, {\"price\":\"0.18\", \"size\":\"111.89\"}, {\"price\":\"0.19\", \"size\":\"132.19\"}, {\"price\":\"0.2\", \"size\":\"145.6\"}, {\"price\":\"0.21\", \"size\":\"95.3\"}, {\"price\":\"0.22\", \"size\":\"138.2\"}, {\"price\":\"0.23\", \"size\":\"93.3\"}, {\"price\":\"0.24\", \"size\":\"101.6\"}, {\"price\":\"0.25\", \"size\":\"113\"}, {\"price\":\"0.26\", \"size\":\"115.6\"}, {\"price\":\"0.27\", \"size\":\"83.3\"}, {\"price\":\"0.28\", \"size\":\"121\"}, {\"price\":\"0.29\", \"size\":\"73.88\"}, {\"price\":\"0.3\", \"size\":\"87\"}, {\"price\":\"0.31\", \"size\":\"101.1\"}, {\"price\":\"0.32\", \"size\":\"84.18\"}, {\"price\":\"0.33\", \"size\":\"68.5\"}, {\"price\":\"0.34\", \"size\":\"110.79\"}, {\"price\":\"0.35\", \"size\":\"65.1\"}, {\"price\":\"0.36\", \"size\":\"66.33\"}, {\"price\":\"0.37\", \"size\":\"77.4\"}, {\"price\":\"0.38\", \"size\":\"41\"}, {\"price\":\"0.39\", \"size\":\"190.7\"}, {\"price\":\"0.4\", \"size\":\"101.7\"}, {\"price\":\"0.41\", \"size\":\"44.4\"}, {\"price\":\"0.42\", \"size\":\"71.09\"}, {\"price\":\"0.43\", \"size\":\"148.48\"}, {\"price\":\"0.44\", \"size\":\"117.36\"}, {\"price\":\"0.45\", \"size\":\"37.31\"}, {\"price\":\"0.46\", \"size\":\"67.17\"}, {\"price\":\"0.47\", \"size\":\"11\"}, {\"price\":\"0.48\", \"size\":\"10\"}, {\"price\":\"0.49\", \"size\":\"40\"}, {\"price\":\"0.5\", \"size\":\"33.64\"}, {\"price\":\"0.51\", \"size\":\"20\"}, {\"price\":\"0.52\", \"size\":\"130\"}, {\"price\":\"0.53\", \"size\":\"5.62\"}, {\"price\":\"0.54\", \"size\":\"105\"}, {\"price\":\"0.55\", \"size\":\"119.05\"}, {\"price\":\"0.56\", \"size\":\"110\"}, {\"price\":\"0.57\", \"size\":\"105\"}, {\"price\":\"0.58\", \"size\":\"40.54\"}], \"asks\":[{\"price\":\"0.99\", \"size\":\"7871.52\"}, {\"price\":\"0.98\", \"size\":\"1065.79\"}, {\"price\":\"0.97\", \"size\":\"900.8\"}, {\"price\":\"0.96\", \"size\":\"773.5\"}, {\"price\":\"0.95\", \"size\":\"761\"}, {\"price\":\"0.94\", \"size\":\"716.09\"}, {\"price\":\"0.93\", \"size\":\"661.2\"}, {\"price\":\"0.92\", \"size\":\"642.59\"}, {\"price\":\"0.91\", \"size\":\"658.1\"}, {\"price\":\"0.9\", \"size\":\"116.6\"}, {\"price\":\"0.89\", \"size\":\"107.29\"}, {\"price\":\"0.88\", \"size\":\"129.4\"}, {\"price\":\"0.87\", \"size\":\"92.9\"}, {\"price\":\"0.86\", \"size\":\"87.2\"}, {\"price\":\"0.85\", \"size\":\"112.39\"}, {\"price\":\"0.84\", \"size\":\"87.1\"}, {\"price\":\"0.83\", \"size\":\"83.29\"}, {\"price\":\"0.82\", \"size\":\"117.9\"}, {\"price\":\"0.81\", \"size\":\"76.19\"}, {\"price\":\"0.8\", \"size\":\"73.6\"}, {\"price\":\"0.79\", \"size\":\"101.3\"}, {\"price\":\"0.78\", \"size\":\"68.2\"}, {\"price\":\"0.77\", \"size\":\"66.3\"}, {\"price\":\"0.76\", \"size\":\"115.6\"}, {\"price\":\"0.75\", \"size\":\"83\"}, {\"price\":\"0.74\", \"size\":\"79.6\"}, {\"price\":\"0.73\", \"size\":\"118.3\"}, {\"price\":\"0.72\", \"size\":\"86\"}, {\"price\":\"0.71\", \"size\":\"83.88\"}, {\"price\":\"0.7\", \"size\":\"123\"}, {\"price\":\"0.69\", \"size\":\"71.1\"}, {\"price\":\"0.68\", \"size\":\"106.53\"}, {\"price\":\"0.67\", \"size\":\"52.16\"}, {\"price\":\"0.66\", \"size\":\"62.35\"}, {\"price\":\"0.65\", \"size\":\"22.21\"}, {\"price\":\"0.64\", \"size\":\"30.69\"}, {\"price\":\"0.63\", \"size\":\"48.56\"}, {\"price\":\"0.62\", \"size\":\"36.63\"}, {\"price\":\"0.61\", \"size\":\"5\"}, {\"price\":\"0.6\", \"size\":\"4.58\"}], \"hash\":\"0c3c1f018d80a6be489ee2a8ef9ef0df61143961\", \"timestamp\":\"1785121917640\", \"event_type\":\"book\"}","received_at":"2026-07-27T03:12:03.928758Z","schema_version":"clob-market-ws.book.v1","sequence":null,"server_hash":"0c3c1f018d80a6be489ee2a8ef9ef0df61143961","server_timestamp":"1785121917640","session_id":"ff6d21c8283948938400a32613abec2c","source":"clob_market_ws"},"received_at":"2026-07-27T03:12:03.928758Z","record_id":"15c1a358912e27cca3369ab0de3a62cf4a7d94269ce9dda914d100c277255a0d","schema_fingerprint":"dc2caa1c89c6a7426e2e07ff925910cd4d0a8a223a515d4092d91d6d127aacb6","schema_version":"edge-lab-recorder.raw.v1","sequence":null,"source":"clob_market_ws"}
{"event_at":"2026-07-27T03:11:57.640000Z","event_fingerprint":"9cc13f64502d816f8143abfb0ff97149a7c9d8fb564eda7f16eea5ed1cbddcdf","payload":{"connection_id":"f95883f18d264834af91809e5f803e9f","event_at":"2026-07-27T03:11:57.640000Z","event_type":"book","frame_hash":"2cbe8e7ea1b30303d66047be42875e1e55afbba8293ec6b5c11b670f39893aa2","frame_index":0,"kind":"data","monotonic_ns":223907265297208,"payload":{"asks":[{"price":"0.99","size":"8142.52"},{"price":"0.98","size":"1365.79"},{"price":"0.97","size":"1124.13"},{"price":"0.96","size":"1081.5"},{"price":"0.95","size":"947"},{"price":"0.94","size":"908.09"},{"price":"0.93","size":"456.2"},{"price":"0.92","size":"168.65"},{"price":"0.91","size":"343.1"},{"price":"0.9","size":"403.6"},{"price":"0.89","size":"120.29"},{"price":"0.88","size":"144.4"},{"price":"0.87","size":"133.9"},{"price":"0.86","size":"97.2"},{"price":"0.85","size":"116.39"},{"price":"0.84","size":"122.1"},{"price":"0.83","size":"133.29"},{"price":"0.82","size":"111.89"},{"price":"0.81","size":"132.19"},{"price":"0.8","size":"145.6"},{"price":"0.79","size":"95.3"},{"price":"0.78","size":"138.2"},{"price":"0.77","size":"93.3"},{"price":"0.76","size":"101.6"},{"price":"0.75","size":"113"},{"price":"0.74","size":"115.6"},{"price":"0.73","size":"83.3"},{"price":"0.72","size":"121"},{"price":"0.71","size":"73.88"},{"price":"0.7","size":"87"},{"price":"0.69","size":"101.1"},{"price":"0.68","size":"84.18"},{"price":"0.67","size":"68.5"},{"price":"0.66","size":"110.79"},{"price":"0.65","size":"65.1"},{"price":"0.64","size":"66.33"},{"price":"0.63","size":"77.4"},{"price":"0.62","size":"41"},{"price":"0.61","size":"190.7"},{"price":"0.6","size":"101.7"},{"price":"0.59","size":"44.4"},{"price":"0.58","size":"71.09"},{"price":"0.57","size":"148.48"},{"price":"0.56","size":"117.36"},{"price":"0.55","size":"37.31"},{"price":"0.54","size":"67.17"},{"price":"0.53","size":"11"},{"price":"0.52","size":"10"},{"price":"0.51","size":"40"},{"price":"0.5","size":"33.64"},{"price":"0.49","size":"20"},{"price":"0.48","size":"130"},{"price":"0.47","size":"5.62"},{"price":"0.46","size":"105"},{"price":"0.45","size":"119.05"},{"price":"0.44","size":"110"},{"price":"0.43","size":"105"},{"price":"0.42","size":"40.54"}],"asset_id":"96283536366176669581486355171583722558858323126916278856549586825357358273536","bids":[{"price":"0.01","size":"7871.52"},{"price":"0.02","size":"1065.79"},{"price":"0.03","size":"900.8"},{"price":"0.04","size":"773.5"},{"price":"0.05","size":"761"},{"price":"0.06","size":"716.09"},{"price":"0.07","size":"661.2"},{"price":"0.08","size":"642.59"},{"price":"0.09","size":"658.1"},{"price":"0.1","size":"116.6"},{"price":"0.11","size":"107.29"},{"price":"0.12","size":"129.4"},{"price":"0.13","size":"92.9"},{"price":"0.14","size":"87.2"},{"price":"0.15","size":"112.39"},{"price":"0.16","size":"87.1"},{"price":"0.17","size":"83.29"},{"price":"0.18","size":"117.9"},{"price":"0.19","size":"76.19"},{"price":"0.2","size":"73.6"},{"price":"0.21","size":"101.3"},{"price":"0.22","size":"68.2"},{"price":"0.23","size":"66.3"},{"price":"0.24","size":"115.6"},{"price":"0.25","size":"83"},{"price":"0.26","size":"79.6"},{"price":"0.27","size":"118.3"},{"price":"0.28","size":"86"},{"price":"0.29","size":"83.88"},{"price":"0.3","size":"123"},{"price":"0.31","size":"71.1"},{"price":"0.32","size":"106.53"},{"price":"0.33","size":"52.16"},{"price":"0.34","size":"62.35"},{"price":"0.35","size":"22.21"},{"price":"0.36","size":"30.69"},{"price":"0.37","size":"48.56"},{"price":"0.38","size":"36.63"},{"price":"0.39","size":"5"},{"price":"0.4","size":"4.58"}],"event_type":"book","hash":"713365500a04be2db76d56dae913838bec830762","market":"0xf9d60bb033695053c4d1d8592e52171c1042f64b41a4b72e09dcc6f4852b6670","timestamp":"1785121917640"},"payload_hash":"c524577f951d6c3a131dacbb3ab0262b4ae2e3ea4e0e56983f21c58382e6dd01","raw_frame":"{\"market\":\"0xf9d60bb033695053c4d1d8592e52171c1042f64b41a4b72e09dcc6f4852b6670\", \"asset_id\":\"96283536366176669581486355171583722558858323126916278856549586825357358273536\", \"bids\":[{\"price\":\"0.01\", \"size\":\"7871.52\"}, {\"price\":\"0.02\", \"size\":\"1065.79\"}, {\"price\":\"0.03\", \"size\":\"900.8\"}, {\"price\":\"0.04\", \"size\":\"773.5\"}, {\"price\":\"0.05\", \"size\":\"761\"}, {\"price\":\"0.06\", \"size\":\"716.09\"}, {\"price\":\"0.07\", \"size\":\"661.2\"}, {\"price\":\"0.08\", \"size\":\"642.59\"}, {\"price\":\"0.09\", \"size\":\"658.1\"}, {\"price\":\"0.1\", \"size\":\"116.6\"}, {\"price\":\"0.11\", \"size\":\"107.29\"}, {\"price\":\"0.12\", \"size\":\"129.4\"}, {\"price\":\"0.13\", \"size\":\"92.9\"}, {\"price\":\"0.14\", \"size\":\"87.2\"}, {\"price\":\"0.15\", \"size\":\"112.39\"}, {\"price\":\"0.16\", \"size\":\"87.1\"}, {\"price\":\"0.17\", \"size\":\"83.29\"}, {\"price\":\"0.18\", \"size\":\"117.9\"}, {\"price\":\"0.19\", \"size\":\"76.19\"}, {\"price\":\"0.2\", \"size\":\"73.6\"}, {\"price\":\"0.21\", \"size\":\"101.3\"}, {\"price\":\"0.22\", \"size\":\"68.2\"}, {\"price\":\"0.23\", \"size\":\"66.3\"}, {\"price\":\"0.24\", \"size\":\"115.6\"}, {\"price\":\"0.25\", \"size\":\"83\"}, {\"price\":\"0.26\", \"size\":\"79.6\"}, {\"price\":\"0.27\", \"size\":\"118.3\"}, {\"price\":\"0.28\", \"size\":\"86\"}, {\"price\":\"0.29\", \"size\":\"83.88\"}, {\"price\":\"0.3\", \"size\":\"123\"}, {\"price\":\"0.31\", \"size\":\"71.1\"}, {\"price\":\"0.32\", \"size\":\"106.53\"}, {\"price\":\"0.33\", \"size\":\"52.16\"}, {\"price\":\"0.34\", \"size\":\"62.35\"}, {\"price\":\"0.35\", \"size\":\"22.21\"}, {\"price\":\"0.36\", \"size\":\"30.69\"}, {\"price\":\"0.37\", \"size\":\"48.56\"}, {\"price\":\"0.38\", \"size\":\"36.63\"}, {\"price\":\"0.39\", \"size\":\"5\"}, {\"price\":\"0.4\", \"size\":\"4.58\"}], \"asks\":[{\"price\":\"0.99\", \"size\":\"8142.52\"}, {\"price\":\"0.98\", \"size\":\"1365.79\"}, {\"price\":\"0.97\", \"size\":\"1124.13\"}, {\"price\":\"0.96\", \"size\":\"1081.5\"}, {\"price\":\"0.95\", \"size\":\"947\"}, {\"price\":\"0.94\", \"size\":\"908.09\"}, {\"price\":\"0.93\", \"size\":\"456.2\"}, {\"price\":\"0.92\", \"size\":\"168.65\"}, {\"price\":\"0.91\", \"size\":\"343.1\"}, {\"price\":\"0.9\", \"size\":\"403.6\"}, {\"price\":\"0.89\", \"size\":\"120.29\"}, {\"price\":\"0.88\", \"size\":\"144.4\"}, {\"price\":\"0.87\", \"size\":\"133.9\"}, {\"price\":\"0.86\", \"size\":\"97.2\"}, {\"price\":\"0.85\", \"size\":\"116.39\"}, {\"price\":\"0.84\", \"size\":\"122.1\"}, {\"price\":\"0.83\", \"size\":\"133.29\"}, {\"price\":\"0.82\", \"size\":\"111.89\"}, {\"price\":\"0.81\", \"size\":\"132.19\"}, {\"price\":\"0.8\", \"size\":\"145.6\"}, {\"price\":\"0.79\", \"size\":\"95.3\"}, {\"price\":\"0.78\", \"size\":\"138.2\"}, {\"price\":\"0.77\", \"size\":\"93.3\"}, {\"price\":\"0.76\", \"size\":\"101.6\"}, {\"price\":\"0.75\", \"size\":\"113\"}, {\"price\":\"0.74\", \"size\":\"115.6\"}, {\"price\":\"0.73\", \"size\":\"83.3\"}, {\"price\":\"0.72\", \"size\":\"121\"}, {\"price\":\"0.71\", \"size\":\"73.88\"}, {\"price\":\"0.7\", \"size\":\"87\"}, {\"price\":\"0.69\", \"size\":\"101.1\"}, {\"price\":\"0.68\", \"size\":\"84.18\"}, {\"price\":\"0.67\", \"size\":\"68.5\"}, {\"price\":\"0.66\", \"size\":\"110.79\"}, {\"price\":\"0.65\", \"size\":\"65.1\"}, {\"price\":\"0.64\", \"size\":\"66.33\"}, {\"price\":\"0.63\", \"size\":\"77.4\"}, {\"price\":\"0.62\", \"size\":\"41\"}, {\"price\":\"0.61\", \"size\":\"190.7\"}, {\"price\":\"0.6\", \"size\":\"101.7\"}, {\"price\":\"0.59\", \"size\":\"44.4\"}, {\"price\":\"0.58\", \"size\":\"71.09\"}, {\"price\":\"0.57\", \"size\":\"148.48\"}, {\"price\":\"0.56\", \"size\":\"117.36\"}, {\"price\":\"0.55\", \"size\":\"37.31\"}, {\"price\":\"0.54\", \"size\":\"67.17\"}, {\"price\":\"0.53\", \"size\":\"11\"}, {\"price\":\"0.52\", \"size\":\"10\"}, {\"price\":\"0.51\", \"size\":\"40\"}, {\"price\":\"0.5\", \"size\":\"33.64\"}, {\"price\":\"0.49\", \"size\":\"20\"}, {\"price\":\"0.48\", \"size\":\"130\"}, {\"price\":\"0.47\", \"size\":\"5.62\"}, {\"price\":\"0.46\", \"size\":\"105\"}, {\"price\":\"0.45\", \"size\":\"119.05\"}, {\"price\":\"0.44\", \"size\":\"110\"}, {\"price\":\"0.43\", \"size\":\"105\"}, {\"price\":\"0.42\", \"size\":\"40.54\"}], \"hash\":\"713365500a04be2db76d56dae913838bec830762\", \"timestamp\":\"1785121917640\", \"event_type\":\"book\"}","received_at":"2026-07-27T03:12:03.934106Z","schema_version":"clob-market-ws.book.v1","sequence":null,"server_hash":"713365500a04be2db76d56dae913838bec830762","server_timestamp":"1785121917640","session_id":"ff6d21c8283948938400a32613abec2c","source":"clob_market_ws"},"received_at":"2026-07-27T03:12:03.934106Z","record_id":"af54271d51f6fa918716d867cf4bff52e4e5943d67879a89329028141400783e","schema_fingerprint":"dc2caa1c89c6a7426e2e07ff925910cd4d0a8a223a515d4092d91d6d127aacb6","schema_version":"edge-lab-recorder.raw.v1","sequence":null,"source":"clob_market_ws"}
{"event_at":"2026-07-27T03:11:57.644000Z","event_fingerprint":"6018683b067a7c4ae320621389db2019430b0cbce23f5b5ddde7b3d3d431758a","payload":{"connection_id":"f95883f18d264834af91809e5f803e9f","event_at":"2026-07-27T03:11:57.644000Z","event_type":"price_change","frame_hash":"b0909b9c5a929957c3eca8553ad33d1899647c2a2f3db5c7052ed7a0e0d8db47","frame_index":0,"kind":"data","monotonic_ns":223907271499458,"payload":{"event_type":"price_change","market":"0xf9d60bb033695053c4d1d8592e52171c1042f64b41a4b72e09dcc6f4852b6670","price_changes":[{"asset_id":"96283536366176669581486355171583722558858323126916278856549586825357358273536","best_ask":"0.42","best_bid":"0.4","hash":"ebd36b12bdbc688905a3a008881b50bbe79d9829","price":"0.37","side":"BUY","size":"53.56"},{"asset_id":"8698449539441374295770236407991735029336433231649246775082939325523552031992","best_ask":"0.6","best_bid":"0.58","hash":"b89853cfd2bf0802497a1c654dddcc4239e5b7e0","price":"0.63","side":"SELL","size":"53.56"}],"timestamp":"1785121917644"},"payload_hash":"c17478884dbc016e544d7761cec0f82b2d1b4a9ffcd99f5e4fafdbcd9cbabde5","raw_frame":"{\"market\":\"0xf9d60bb033695053c4d1d8592e52171c1042f64b41a4b72e09dcc6f4852b6670\", \"price_changes\":[{\"asset_id\":\"96283536366176669581486355171583722558858323126916278856549586825357358273536\", \"price\":\"0.37\", \"size\":\"53.56\", \"side\":\"BUY\", \"hash\":\"ebd36b12bdbc688905a3a008881b50bbe79d9829\", \"best_bid\":\"0.4\", \"best_ask\":\"0.42\"}, {\"asset_id\":\"8698449539441374295770236407991735029336433231649246775082939325523552031992\", \"price\":\"0.63\", \"size\":\"53.56\", \"side\":\"SELL\", \"hash\":\"b89853cfd2bf0802497a1c654dddcc4239e5b7e0\", \"best_bid\":\"0.58\", \"best_ask\":\"0.6\"}], \"timestamp\":\"1785121917644\", \"event_type\":\"price_change\"}","received_at":"2026-07-27T03:12:03.940309Z","schema_version":"clob-market-ws.price_change.v1","sequence":null,"server_hash":null,"server_timestamp":"1785121917644","session_id":"ff6d21c8283948938400a32613abec2c","source":"clob_market_ws"},"received_at":"2026-07-27T03:12:03.940309Z","record_id":"cdbfa56ffa40d7f8d93b0b6209caba8c6aed70bd2b45e3e9906652589e4c227f","schema_fingerprint":"4aa3821a28b0b7c2400bc59aba4bcc0a76e971dadd19610d3ad38c768e124dc7","schema_version":"edge-lab-recorder.raw.v1","sequence":null,"source":"clob_market_ws"}
{"event_at":"2026-07-27T03:11:57.649000Z","event_fingerprint":"6f8d5a251a1adc18502bf3c67b00eac550f10b0fab459942487b971118809e97","payload":{"connection_id":"f95883f18d264834af91809e5f803e9f","event_at":"2026-07-27T03:11:57.649000Z","event_type":"price_change","frame_hash":"52348e4476a056708e1dc8ff1ef1128e3fab1037d5001fb012289a1c791daec4","frame_index":0,"kind":"data","monotonic_ns":223907273102791,"payload":{"event_type":"price_change","market":"0xf9d60bb033695053c4d1d8592e52171c1042f64b41a4b72e09dcc6f4852b6670","price_changes":[{"asset_id":"8698449539441374295770236407991735029336433231649246775082939325523552031992","best_ask":"0.6","best_bid":"0.58","hash":"dd84b13997a7953bc7c2872064b670b34dc12863","price":"0.82","side":"SELL","size":"122.9"},{"asset_id":"96283536366176669581486355171583722558858323126916278856549586825357358273536","best_ask":"0.42","best_bid":"0.4","hash":"fe3c48be974266224eb14b125fd3e21648137439","price":"0.18","side":"BUY","size":"122.9"}],"timestamp":"1785121917649"},"payload_hash":"08ecb428c334df9c712e10d70a37a8eb029e812a2d3a6dc973455d3a1a07c83f","raw_frame":"{\"market\":\"0xf9d60bb033695053c4d1d8592e52171c1042f64b41a4b72e09dcc6f4852b6670\", \"price_changes\":[{\"asset_id\":\"8698449539441374295770236407991735029336433231649246775082939325523552031992\", \"price\":\"0.82\", \"size\":\"122.9\", \"side\":\"SELL\", \"hash\":\"dd84b13997a7953bc7c2872064b670b34dc12863\", \"best_bid\":\"0.58\", \"best_ask\":\"0.6\"}, {\"asset_id\":\"96283536366176669581486355171583722558858323126916278856549586825357358273536\", \"price\":\"0.18\", \"size\":\"122.9\", \"side\":\"BUY\", \"hash\":\"fe3c48be974266224eb14b125fd3e21648137439\", \"best_bid\":\"0.4\", \"best_ask\":\"0.42\"}], \"timestamp\":\"1785121917649\", \"event_type\":\"price_change\"}","received_at":"2026-07-27T03:12:03.941913Z","schema_version":"clob-market-ws.price_change.v1","sequence":null,"server_hash":null,"server_timestamp":"1785121917649","session_id":"ff6d21c8283948938400a32613abec2c","source":"clob_market_ws"},"received_at":"2026-07-27T03:12:03.941913Z","record_id":"53ca76aedcfdea4ca151238d254e27a0097c5e7465a719bc608e422aebf90451","schema_fingerprint":"4aa3821a28b0b7c2400bc59aba4bcc0a76e971dadd19610d3ad38c768e124dc7","schema_version":"edge-lab-recorder.raw.v1","sequence":null,"source":"clob_market_ws"}
{"event_at":"2026-07-27T03:11:57.650000Z","event_fingerprint":"f591d2f824de23b4a93e01d15a3ea63b0c97065969a911de3e5d093e5f0c8fc4","payload":{"connection_id":"f95883f18d264834af91809e5f803e9f","event_at":"2026-07-27T03:11:57.650000Z","event_type":"price_change","frame_hash":"0256fc8aa6455b3b6cbc2344aad7d7f02798ddc5a29c5b957216b6e7165e74d1","frame_index":0,"kind":"data","monotonic_ns":223907274921625,"payload":{"event_type":"price_change","market":"0xf9d60bb033695053c4d1d8592e52171c1042f64b41a4b72e09dcc6f4852b6670","price_changes":[{"asset_id":"8698449539441374295770236407991735029336433231649246775082939325523552031992","best_ask":"0.6","best_bid":"0.58","hash":"12b9c90c882349a74bc289a621d900d07ba40a6d","price":"0.01","side":"BUY","size":"8147.52"},{"asset_id":"96283536366176669581486355171583722558858323126916278856549586825357358273536","best_ask":"0.42","best_bid":"0.4","hash":"6e781c6a55630fb9a685fadd0831c4546278348b","price":"0.99","side":"SELL","size":"8147.52"}],"timestamp":"1785121917650"},"payload_hash":"bee58cbe72098ce2ffa55c30c974cc73fe97f8be1a460eb04584ce8a6b5d3628","raw_frame":"{\"market\":\"0xf9d60bb033695053c4d1d8592e52171c1042f64b41a4b72e09dcc6f4852b6670\", \"price_changes\":[{\"asset_id\":\"8698449539441374295770236407991735029336433231649246775082939325523552031992\", \"price\":\"0.01\", \"size\":\"8147.52\", \"side\":\"BUY\", \"hash\":\"12b9c90c882349a74bc289a621d900d07ba40a6d\", \"best_bid\":\"0.58\", \"best_ask\":\"0.6\"}, {\"asset_id\":\"96283536366176669581486355171583722558858323126916278856549586825357358273536\", \"price\":\"0.99\", \"size\":\"8147.52\", \"side\":\"SELL\", \"hash\":\"6e781c6a55630fb9a685fadd0831c4546278348b\", \"best_bid\":\"0.4\", \"best_ask\":\"0.42\"}], \"timestamp\":\"1785121917650\", \"event_type\":\"price_change\"}","received_at":"2026-07-27T03:12:03.943731Z","schema_version":"clob-market-ws.price_change.v1","sequence":null,"server_hash":null,"server_timestamp":"1785121917650","session_id":"ff6d21c8283948938400a32613abec2c","source":"clob_market_ws"},"received_at":"2026-07-27T03:12:03.943731Z","record_id":"c6ab49e9fd7c61b25a689e04b898476bf08d14852e3d2527854b008ccf2c2c3e","schema_fingerprint":"4aa3821a28b0b7c2400bc59aba4bcc0a76e971dadd19610d3ad38c768e124dc7","schema_version":"edge-lab-recorder.raw.v1","sequence":null,"source":"clob_market_ws"}
{"event_at":"2026-07-27T03:11:57.651000Z","event_fingerprint":"55c951133afb9018cb7304af135910daae38c0a7a3bcd933eb4057af45e63092","payload":{"connection_id":"f95883f18d264834af91809e5f803e9f","event_at":"2026-07-27T03:11:57.651000Z","event_type":"price_change","frame_hash":"d46c4fb09a21f73367be40667dda3344f0e7b73f654a323083893970c1dd8fea","frame_index":0,"kind":"data","monotonic_ns":223907277606000,"payload":{"event_type":"price_change","market":"0xf9d60bb033695053c4d1d8592e52171c1042f64b41a4b72e09dcc6f4852b6670","price_changes":[{"asset_id":"8698449539441374295770236407991735029336433231649246775082939325523552031992","best_ask":"0.6","best_bid":"0.58","hash":"1b06d9048596ae31559af66795809d5e3c897da0","price":"0.4","side":"BUY","size":"96.5"},{"asset_id":"96283536366176669581486355171583722558858323126916278856549586825357358273536","best_ask":"0.42","best_bid":"0.4","hash":"5e41750b5aed2e6e6fa05f476fd331f17f2da37c","price":"0.6","side":"SELL","size":"96.5"}],"timestamp":"1785121917651"},"payload_hash":"b6c22102ffc780112661aa287575f1eead66df4e3ec5d4b5ee8a2bbd8b1c9359","raw_frame":"{\"market\":\"0xf9d60bb033695053c4d1d8592e52171c1042f64b41a4b72e09dcc6f4852b6670\", \"price_changes\":[{\"asset_id\":\"8698449539441374295770236407991735029336433231649246775082939325523552031992\", \"price\":\"0.4\", \"size\":\"96.5\", \"side\":\"BUY\", \"hash\":\"1b06d9048596ae31559af66795809d5e3c897da0\", \"best_bid\":\"0.58\", \"best_ask\":\"0.6\"}, {\"asset_id\":\"96283536366176669581486355171583722558858323126916278856549586825357358273536\", \"price\":\"0.6\", \"size\":\"96.5\", \"side\":\"SELL\", \"hash\":\"5e41750b5aed2e6e6fa05f476fd331f17f2da37c\", \"best_bid\":\"0.4\", \"best_ask\":\"0.42\"}], \"timestamp\":\"1785121917651\", \"event_type\":\"price_change\"}","received_at":"2026-07-27T03:12:03.946416Z","schema_version":"clob-market-ws.price_change.v1","sequence":null,"server_hash":null,"server_timestamp":"1785121917651","session_id":"ff6d21c8283948938400a32613abec2c","source":"clob_market_ws"},"received_at":"2026-07-27T03:12:03.946416Z","record_id":"e39c2f884f2bbc1e36350e1a33dfa09a7472c87dc94cab8322d217ef86d47d26","schema_fingerprint":"4aa3821a28b0b7c2400bc59aba4bcc0a76e971dadd19610d3ad38c768e124dc7","schema_version":"edge-lab-recorder.raw.v1","sequence":null,"source":"clob_market_ws"}
{"event_at":"2026-07-27T03:11:57.652000Z","event_fingerprint":"6604b226cf4336d11353bf5748737ced8bc92691326da05dc514286fdd47b37b","payload":{"connection_id":"f95883f18d264834af91809e5f803e9f","event_at":"2026-07-27T03:11:57.652000Z","event_type":"price_change","frame_hash":"dea6b052275d8b6d214442b8c08f517efb79c6e306c4548adf65f1b615360592","frame_index":0,"kind":"data","monotonic_ns":223907280762750,"payload":{"event_type":"price_change","market":"0xf9d60bb033695053c4d1d8592e52171c1042f64b41a4b72e09dcc6f4852b6670","price_changes":[{"asset_id":"96283536366176669581486355171583722558858323126916278856549586825357358273536","best_ask":"0.42","best_bid":"0.4","hash":"6cefaf3f218f2ded3c3ae4c3d05bf401772473e1","price":"0.37","side":"BUY","size":"38.56"},{"asset_id":"8698449539441374295770236407991735029336433231649246775082939325523552031992","best_ask":"0.6","best_bid":"0.58","hash":"80d5f7266c922e0c05d522da538bc750a66c4b3f","price":"0.63","side":"SELL","size":"38.56"}],"timestamp":"1785121917652"},"payload_hash":"7067a13b1f9fb15cafa6a51012fe25da119bd97486e6365e1c512740126f967d","raw_frame":"{\"market\":\"0xf9d60bb033695053c4d1d8592e52171c1042f64b41a4b72e09dcc6f4852b6670\", \"price_changes\":[{\"asset_id\":\"96283536366176669581486355171583722558858323126916278856549586825357358273536\", \"price\":\"0.37\", \"size\":\"38.56\", \"side\":\"BUY\", \"hash\":\"6cefaf3f218f2ded3c3ae4c3d05bf401772473e1\", \"best_bid\":\"0.4\", \"best_ask\":\"0.42\"}, {\"asset_id\":\"8698449539441374295770236407991735029336433231649246775082939325523552031992\", \"price\":\"0.63\", \"size\":\"38.56\", \"side\":\"SELL\", \"hash\":\"80d5f7266c922e0c05d522da538bc750a66c4b3f\", \"best_bid\":\"0.58\", \"best_ask\":\"0.6\"}], \"timestamp\":\"1785121917652\", \"event_type\":\"price_change\"}","received_at":"2026-07-27T03:12:03.949572Z","schema_version":"clob-market-ws.price_change.v1","sequence":null,"server_hash":null,"server_timestamp":"1785121917652","session_id":"ff6d21c8283948938400a32613abec2c","source":"clob_market_ws"},"received_at":"2026-07-27T03:12:03.949572Z","record_id":"96acb62a743532821578a6f42890f06d3884ab99ab370e8971d6d61d3d6ae1e8","schema_fingerprint":"4aa3821a28b0b7c2400bc59aba4bcc0a76e971dadd19610d3ad38c768e124dc7","schema_version":"edge-lab-recorder.raw.v1","sequence":null,"source":"clob_market_ws"}
{"event_at":"2026-07-27T03:11:57.652000Z","event_fingerprint":"14e9d8a9fa77ade24af0145b20433d02980a9c74de10e0d8aa1956c9ab83b706","payload":{"connection_id":"f95883f18d264834af91809e5f803e9f","event_at":"2026-07-27T03:11:57.652000Z","event_type":"price_change","frame_hash":"0b754d1dfb63b09e80b9f872fa9d786ea7784af459606dba6b51cbac7387e204","frame_index":0,"kind":"data","monotonic_ns":223907283685625,"payload":{"event_type":"price_change","market":"0xf9d60bb033695053c4d1d8592e52171c1042f64b41a4b72e09dcc6f4852b6670","price_changes":[{"asset_id":"8698449539441374295770236407991735029336433231649246775082939325523552031992","best_ask":"0.6","best_bid":"0.58","hash":"80d5f7266c922e0c05d522da538bc750a66c4b3f","price":"0.57","side":"BUY","size":"90"},{"asset_id":"96283536366176669581486355171583722558858323126916278856549586825357358273536","best_ask":"0.42","best_bid":"0.4","hash":"6cefaf3f218f2ded3c3ae4c3d05bf401772473e1","price":"0.43","side":"SELL","size":"90"}],"timestamp":"1785121917652"},"payload_hash":"b8b99f7a92438e7dda9d90bab57884753d4da7e409ffbe85e47bc34ed224036d","raw_frame":"{\"market\":\"0xf9d60bb033695053c4d1d8592e52171c1042f64b41a4b72e09dcc6f4852b6670\", \"price_changes\":[{\"asset_id\":\"8698449539441374295770236407991735029336433231649246775082939325523552031992\", \"price\":\"0.57\", \"size\":\"90\", \"side\":\"BUY\", \"hash\":\"80d5f7266c922e0c05d522da538bc750a66c4b3f\", \"best_bid\":\"0.58\", \"best_ask\":\"0.6\"}, {\"asset_id\":\"96283536366176669581486355171583722558858323126916278856549586825357358273536\", \"price\":\"0.43\", \"size\":\"90\", \"side\":\"SELL\", \"hash\":\"6cefaf3f218f2ded3c3ae4c3d05bf401772473e1\", \"best_bid\":\"0.4\", \"best_ask\":\"0.42\"}], \"timestamp\":\"1785121917652\", \"event_type\":\"price_change\"}","received_at":"2026-07-27T03:12:03.952495Z","schema_version":"clob-market-ws.price_change.v1","sequence":null,"server_hash":null,"server_timestamp":"1785121917652","session_id":"ff6d21c8283948938400a32613abec2c","source":"clob_market_ws"},"received_at":"2026-07-27T03:12:03.952495Z","record_id":"15bc9c0c1e4d568f8cba694e9bafc50a3afe71da9ad76c5a21f704af31fc4cc9","schema_fingerprint":"4aa3821a28b0b7c2400bc59aba4bcc0a76e971dadd19610d3ad38c768e124dc7","schema_version":"edge-lab-recorder.raw.v1","sequence":null,"source":"clob_market_ws"}
{"event_at":"2026-07-27T03:11:57.652000Z","event_fingerprint":"b1e2863e22e72f3b24158b51b7bd5e9cb27928e9ed051202f1114da43ff3bd71","payload":{"connection_id":"f95883f18d264834af91809e5f803e9f","event_at":"2026-07-27T03:11:57.652000Z","event_type":"price_change","frame_hash":"4831427024e572b1900d4cc69841ebe4bad8bf9bda304c81b5955fa0b2a52623","frame_index":0,"kind":"data","monotonic_ns":223907285250416,"payload":{"event_type":"price_change","market":"0xf9d60bb033695053c4d1d8592e52171c1042f64b41a4b72e09dcc6f4852b6670","price_changes":[{"asset_id":"96283536366176669581486355171583722558858323126916278856549586825357358273536","best_ask":"0.42","best_bid":"0.4","hash":"6cefaf3f218f2ded3c3ae4c3d05bf401772473e1","price":"0.38","side":"BUY","size":"31.63"},{"asset_id":"8698449539441374295770236407991735029336433231649246775082939325523552031992","best_ask":"0.6","best_bid":"0.58","hash":"80d5f7266c922e0c05d522da538bc750a66c4b3f","price":"0.62","side":"SELL","size":"31.63"}],"timestamp":"1785121917652"},"payload_hash":"619742e8e88c8574a6fb17fd3989fa83fb62c5e602e76c6a69b071cef470633a","raw_frame":"{\"market\":\"0xf9d60bb033695053c4d1d8592e52171c1042f64b41a4b72e09dcc6f4852b6670\", \"price_changes\":[{\"asset_id\":\"96283536366176669581486355171583722558858323126916278856549586825357358273536\", \"price\":\"0.38\", \"size\":\"31.63\", \"side\":\"BUY\", \"hash\":\"6cefaf3f218f2ded3c3ae4c3d05bf401772473e1\", \"best_bid\":\"0.4\", \"best_ask\":\"0.42\"}, {\"asset_id\":\"8698449539441374295770236407991735029336433231649246775082939325523552031992\", \"price\":\"0.62\", \"size\":\"31.63\", \"side\":\"SELL\", \"hash\":\"80d5f7266c922e0c05d522da538bc750a66c4b3f\", \"best_bid\":\"0.58\", \"best_ask\":\"0.6\"}], \"timestamp\":\"1785121917652\", \"event_type\":\"price_change\"}","received_at":"2026-07-27T03:12:03.954058Z","schema_version":"clob-market-ws.price_change.v1","sequence":null,"server_hash":null,"server_timestamp":"1785121917652","session_id":"ff6d21c8283948938400a32613abec2c","source":"clob_market_ws"},"received_at":"2026-07-27T03:12:03.954058Z","record_id":"bc0003718fea9189700eb77f4c870eb286cfd81e2fb74c2e5577f7749f413eb2","schema_fingerprint":"4aa3821a28b0b7c2400bc59aba4bcc0a76e971dadd19610d3ad38c768e124dc7","schema_version":"edge-lab-recorder.raw.v1","sequence":null,"source":"clob_market_ws"}
{"event_at":"2026-07-27T03:11:57.658000Z","event_fingerprint":"05d7c4a20f07c7d824cdb47ef38609e1f815ff3975770e646ae133b2f14508a3","payload":{"connection_id":"f95883f18d264834af91809e5f803e9f","event_at":"2026-07-27T03:11:57.658000Z","event_type":"price_change","frame_hash":"944d2aa749595efd860868fc175eaa8b7a8390b0bb0f5c6e4548694cf5e07fba","frame_index":0,"kind":"data","monotonic_ns":223907287227708,"payload":{"event_type":"price_change","market":"0xf9d60bb033695053c4d1d8592e52171c1042f64b41a4b72e09dcc6f4852b6670","price_changes":[{"asset_id":"8698449539441374295770236407991735029336433231649246775082939325523552031992","best_ask":"0.6","best_bid":"0.58","hash":"791b258e3efef520ae960923e7c712b9b8ec1a2d","price":"0.57","side":"BUY","size":"85"},{"asset_id":"96283536366176669581486355171583722558858323126916278856549586825357358273536","best_ask":"0.42","best_bid":"0.4","hash":"9a720e8bfd66fef2deb7bedd887d2e81ee5f6dab","price":"0.43","side":"SELL","size":"85"}],"timestamp":"1785121917658"},"payload_hash":"f82c8a283293f5a8cbd8d9a19903e0a0d3372bd306b4e628efdf89b8598c0bfe","raw_frame":"{\"market\":\"0xf9d60bb033695053c4d1d8592e52171c1042f64b41a4b72e09dcc6f4852b6670\", \"price_changes\":[{\"asset_id\":\"8698449539441374295770236407991735029336433231649246775082939325523552031992\", \"price\":\"0.57\", \"size\":\"85\", \"side\":\"BUY\", \"hash\":\"791b258e3efef520ae960923e7c712b9b8ec1a2d\", \"best_bid\":\"0.58\", \"best_ask\":\"0.6\"}, {\"asset_id\":\"96283536366176669581486355171583722558858323126916278856549586825357358273536\", \"price\":\"0.43\", \"size\":\"85\", \"side\":\"SELL\", \"hash\":\"9a720e8bfd66fef2deb7bedd887d2e81ee5f6dab\", \"best_bid\":\"0.4\", \"best_ask\":\"0.42\"}], \"timestamp\":\"1785121917658\", \"event_type\":\"price_change\"}","received_at":"2026-07-27T03:12:03.956037Z","schema_version":"clob-market-ws.price_change.v1","sequence":null,"server_hash":null,"server_timestamp":"1785121917658","session_id":"ff6d21c8283948938400a32613abec2c","source":"clob_market_ws"},"received_at":"2026-07-27T03:12:03.956037Z","record_id":"6755c4145ffd77563a89346fda21d0b892c9159746120f73d4d979ee2d9a46da","schema_fingerprint":"4aa3821a28b0b7c2400bc59aba4bcc0a76e971dadd19610d3ad38c768e124dc7","schema_version":"edge-lab-recorder.raw.v1","sequence":null,"source":"clob_market_ws"}
{"event_at":"2026-07-27T03:11:57.663000Z","event_fingerprint":"753b47afe37142c9dc566826e18ebb2ce2f5396f754015d5ed07b16f023b5a18","payload":{"connection_id":"f95883f18d264834af91809e5f803e9f","event_at":"2026-07-27T03:11:57.663000Z","event_type":"best_bid_ask","frame_hash":"65b1b11f2a670dce054efc92240eefd2a0a683809b4be3ae824c5195431fa0ed","frame_index":0,"kind":"data","monotonic_ns":223907288744541,"payload":{"asset_id":"8698449539441374295770236407991735029336433231649246775082939325523552031992","best_ask":"0.6","best_bid":"0.59","event_type":"best_bid_ask","market":"0xf9d60bb033695053c4d1d8592e52171c1042f64b41a4b72e09dcc6f4852b6670","spread":"0.01","timestamp":"1785121917663"},"payload_hash":"3c891b93a1a85185ffaa0c0aca42399d13a0d3d78925a9487d6dfc19f0bc5810","raw_frame":"{\"market\":\"0xf9d60bb033695053c4d1d8592e52171c1042f64b41a4b72e09dcc6f4852b6670\", \"asset_id\":\"8698449539441374295770236407991735029336433231649246775082939325523552031992\", \"best_bid\":\"0.59\", \"best_ask\":\"0.6\", \"spread\":\"0.01\", \"timestamp\":\"1785121917663\", \"event_type\":\"best_bid_ask\"}","received_at":"2026-07-27T03:12:03.957554Z","schema_version":"clob-market-ws.best_bid_ask.v1","sequence":null,"server_hash":null,"server_timestamp":"1785121917663","session_id":"ff6d21c8283948938400a32613abec2c","source":"clob_market_ws"},"received_at":"2026-07-27T03:12:03.957554Z","record_id":"3b5aa89e439c931d5f39c090f11b2ad88689c186b87552b3d77a3518df301d7e","schema_fingerprint":"8488399f31b0337811b13b266be932db7062827c2470b78bd8e9e99bab51d17d","schema_version":"edge-lab-recorder.raw.v1","sequence":null,"source":"clob_market_ws"}
{"event_at":"2026-07-27T03:11:57.663000Z","event_fingerprint":"f4b21dfee06453764606bde4cfe5ac05a8e972496f5b37ff01c79443d591d275","payload":{"connection_id":"f95883f18d264834af91809e5f803e9f","event_at":"2026-07-27T03:11:57.663000Z","event_type":"best_bid_ask","frame_hash":"0c20d3044757592345a3d7b69318ea55af7e9d992f1ad4fad2bcc0bbf1a644d3","frame_index":0,"kind":"data","monotonic_ns":223907289835791,"payload":{"asset_id":"96283536366176669581486355171583722558858323126916278856549586825357358273536","best_ask":"0.41","best_bid":"0.4","event_type":"best_bid_ask","market":"0xf9d60bb033695053c4d1d8592e52171c1042f64b41a4b72e09dcc6f4852b6670","spread":"0.01","timestamp":"1785121917663"},"payload_hash":"6e8e860dc634eaada7bb383f6dbb96376bfb84865f04f7aada081de23e909e8d","raw_frame":"{\"market\":\"0xf9d60bb033695053c4d1d8592e52171c1042f64b41a4b72e09dcc6f4852b6670\", \"asset_id\":\"96283536366176669581486355171583722558858323126916278856549586825357358273536\", \"best_bid\":\"0.4\", \"best_ask\":\"0.41\", \"spread\":\"0.01\", \"timestamp\":\"1785121917663\", \"event_type\":\"best_bid_ask\"}","received_at":"2026-07-27T03:12:03.958646Z","schema_version":"clob-market-ws.best_bid_ask.v1","sequence":null,"server_hash":null,"server_timestamp":"1785121917663","session_id":"ff6d21c8283948938400a32613abec2c","source":"clob_market_ws"},"received_at":"2026-07-27T03:12:03.958646Z","record_id":"e6823814fbed43d98700e346113c33e54417f1440db8a54d4b13ec4b106933da","schema_fingerprint":"8488399f31b0337811b13b266be932db7062827c2470b78bd8e9e99bab51d17d","schema_version":"edge-lab-recorder.raw.v1","sequence":null,"source":"clob_market_ws"}
{"event_at":"2026-07-27T03:11:57.663000Z","event_fingerprint":"f28c58c62baae667e34f480c63fb967a9d74992524ac7ccb2798b13409519461","payload":{"connection_id":"f95883f18d264834af91809e5f803e9f","event_at":"2026-07-27T03:11:57.663000Z","event_type":"price_change","frame_hash":"6ebcabd81c9e67b61c2ed82249dc5e13e9d84c8e6c1f976e9b6f54cccc23d55e","frame_index":0,"kind":"data","monotonic_ns":223907290668541,"payload":{"event_type":"price_change","market":"0xf9d60bb033695053c4d1d8592e52171c1042f64b41a4b72e09dcc6f4852b6670","price_changes":[{"asset_id":"8698449539441374295770236407991735029336433231649246775082939325523552031992","best_ask":"0.6","best_bid":"0.59","hash":"e9d1c8725d3de71e8f0dc5b22d4e8751041ed44f","price":"0.59","side":"BUY","size":"75"},{"asset_id":"96283536366176669581486355171583722558858323126916278856549586825357358273536","best_ask":"0.41","best_bid":"0.4","hash":"41ffe6308a2676cc61f7bfd17d62de63e4eccd58","price":"0.41","side":"SELL","size":"75"}],"timestamp":"1785121917663"},"payload_hash":"f46742d1004367df385906f24178dfb83315a6ae9e5fc54147d13db2af5715c0","raw_frame":"{\"market\":\"0xf9d60bb033695053c4d1d8592e52171c1042f64b41a4b72e09dcc6f4852b6670\", \"price_changes\":[{\"asset_id\":\"8698449539441374295770236407991735029336433231649246775082939325523552031992\", \"price\":\"0.59\", \"size\":\"75\", \"side\":\"BUY\", \"hash\":\"e9d1c8725d3de71e8f0dc5b22d4e8751041ed44f\", \"best_bid\":\"0.59\", \"best_ask\":\"0.6\"}, {\"asset_id\":\"96283536366176669581486355171583722558858323126916278856549586825357358273536\", \"price\":\"0.41\", \"size\":\"75\", \"side\":\"SELL\", \"hash\":\"41ffe6308a2676cc61f7bfd17d62de63e4eccd58\", \"best_bid\":\"0.4\", \"best_ask\":\"0.41\"}], \"timestamp\":\"1785121917663\", \"event_type\":\"price_change\"}","received_at":"2026-07-27T03:12:03.959478Z","schema_version":"clob-market-ws.price_change.v1","sequence":null,"server_hash":null,"server_timestamp":"1785121917663","session_id":"ff6d21c8283948938400a32613abec2c","source":"clob_market_ws"},"received_at":"2026-07-27T03:12:03.959478Z","record_id":"7e7118844abcaaae2e93eb09392a596a3e8ec6704fd0d00c233044af257e70fa","schema_fingerprint":"4aa3821a28b0b7c2400bc59aba4bcc0a76e971dadd19610d3ad38c768e124dc7","schema_version":"edge-lab-recorder.raw.v1","sequence":null,"source":"clob_market_ws"}
{"event_at":"2026-07-27T03:11:57.663000Z","event_fingerprint":"5bcd92632e7e146f707ec4f2be0efd0422a24b860199849d7d58e68ef1268f9f","payload":{"connection_id":"f95883f18d264834af91809e5f803e9f","event_at":"2026-07-27T03:11:57.663000Z","event_type":"price_change","frame_hash":"d23eec31bce763129d6784d3b038b784a06f42f8a8224790674ad821abb221ac","frame_index":0,"kind":"data","monotonic_ns":223907291884500,"payload":{"event_type":"price_change","market":"0xf9d60bb033695053c4d1d8592e52171c1042f64b41a4b72e09dcc6f4852b6670","price_changes":[{"asset_id":"8698449539441374295770236407991735029336433231649246775082939325523552031992","best_ask":"0.6","best_bid":"0.59","hash":"0af5aede78621eff12fe8d105baa9b8225920dba","price":"0.59","side":"BUY","size":"80"},{"asset_id":"96283536366176669581486355171583722558858323126916278856549586825357358273536","best_ask":"0.41","best_bid":"0.4","hash":"569894ee8eaccd55b3f627c869636e9d5ffdd7d5","price":"0.41","side":"SELL","size":"80"}],"timestamp":"1785121917663"},"payload_hash":"46b8f03c3bf4e4da43888e58727e5eeb0f8397d07295d74af2d10c35957e9414","raw_frame":"{\"market\":\"0xf9d60bb033695053c4d1d8592e52171c1042f64b41a4b72e09dcc6f4852b6670\", \"price_changes\":[{\"asset_id\":\"8698449539441374295770236407991735029336433231649246775082939325523552031992\", \"price\":\"0.59\", \"size\":\"80\", \"side\":\"BUY\", \"hash\":\"0af5aede78621eff12fe8d105baa9b8225920dba\", \"best_bid\":\"0.59\", \"best_ask\":\"0.6\"}, {\"asset_id\":\"96283536366176669581486355171583722558858323126916278856549586825357358273536\", \"price\":\"0.41\", \"size\":\"80\", \"side\":\"SELL\", \"hash\":\"569894ee8eaccd55b3f627c869636e9d5ffdd7d5\", \"best_bid\":\"0.4\", \"best_ask\":\"0.41\"}], \"timestamp\":\"1785121917663\", \"event_type\":\"price_change\"}","received_at":"2026-07-27T03:12:03.960694Z","schema_version":"clob-market-ws.price_change.v1","sequence":null,"server_hash":null,"server_timestamp":"1785121917663","session_id":"ff6d21c8283948938400a32613abec2c","source":"clob_market_ws"},"received_at":"2026-07-27T03:12:03.960694Z","record_id":"3898559c09ba00c6d3b6b18b7b599932b23efe3a429091f230c72145a0417af4","schema_fingerprint":"4aa3821a28b0b7c2400bc59aba4bcc0a76e971dadd19610d3ad38c768e124dc7","schema_version":"edge-lab-recorder.raw.v1","sequence":null,"source":"clob_market_ws"}
{"event_at":"2026-07-27T03:11:57.665000Z","event_fingerprint":"ddb04c116cd2b1d22db2bb3f676cbd44442be9e129c1982e268daba40a486822","payload":{"connection_id":"f95883f18d264834af91809e5f803e9f","event_at":"2026-07-27T03:11:57.665000Z","event_type":"price_change","frame_hash":"864762361f46fa407eb1293b084d43539e4f0929de25a66b6b590c9a5a67e592","frame_index":0,"kind":"data","monotonic_ns":223907293858416,"payload":{"event_type":"price_change","market":"0xf9d60bb033695053c4d1d8592e52171c1042f64b41a4b72e09dcc6f4852b6670","price_changes":[{"asset_id":"8698449539441374295770236407991735029336433231649246775082939325523552031992","best_ask":"0.6","best_bid":"0.59","hash":"98b190f6fb20a65e5534c42f00a18db66d249bb7","price":"0.58","side":"BUY","size":"45.54"},{"asset_id":"96283536366176669581486355171583722558858323126916278856549586825357358273536","best_ask":"0.41","best_bid":"0.4","hash":"aa9b9f8832162612914108c81fb5dd3c5011e225","price":"0.42","side":"SELL","size":"45.54"}],"timestamp":"1785121917665"},"payload_hash":"e076db12862a0677ce29da18807ed49ad0d012a55ed11a9db2d7fb83778441b8","raw_frame":"{\"market\":\"0xf9d60bb033695053c4d1d8592e52171c1042f64b41a4b72e09dcc6f4852b6670\", \"price_changes\":[{\"asset_id\":\"8698449539441374295770236407991735029336433231649246775082939325523552031992\", \"price\":\"0.58\", \"size\":\"45.54\", \"side\":\"BUY\", \"hash\":\"98b190f6fb20a65e5534c42f00a18db66d249bb7\", \"best_bid\":\"0.59\", \"best_ask\":\"0.6\"}, {\"asset_id\":\"96283536366176669581486355171583722558858323126916278856549586825357358273536\", \"price\":\"0.42\", \"size\":\"45.54\", \"side\":\"SELL\", \"hash\":\"aa9b9f8832162612914108c81fb5dd3c5011e225\", \"best_bid\":\"0.4\", \"best_ask\":\"0.41\"}], \"timestamp\":\"1785121917665\", \"event_type\":\"price_change\"}","received_at":"2026-07-27T03:12:03.962662Z","schema_version":"clob-market-ws.price_change.v1","sequence":null,"server_hash":null,"server_timestamp":"1785121917665","session_id":"ff6d21c8283948938400a32613abec2c","source":"clob_market_ws"},"received_at":"2026-07-27T03:12:03.962662Z","record_id":"9b127bcc9e4c25b9940b3bd284af09ac421e6a45938cbc417bf000af710c7fd3","schema_fingerprint":"4aa3821a28b0b7c2400bc59aba4bcc0a76e971dadd19610d3ad38c768e124dc7","schema_version":"edge-lab-recorder.raw.v1","sequence":null,"source":"clob_market_ws"}
{"event_at":"2026-07-27T03:11:57.666000Z","event_fingerprint":"b6744b26ad4251557eaeba712ebf9c870a19061e92969a3d7f0912447a4432c3","payload":{"connection_id":"f95883f18d264834af91809e5f803e9f","event_at":"2026-07-27T03:11:57.666000Z","event_type":"price_change","frame_hash":"e16cca1f3a2997495d671b393d1326826bf888c759b2629346ab5c68123a12f5","frame_index":0,"kind":"data","monotonic_ns":223907296608833,"payload":{"event_type":"price_change","market":"0xf9d60bb033695053c4d1d8592e52171c1042f64b41a4b72e09dcc6f4852b6670","price_changes":[{"asset_id":"96283536366176669581486355171583722558858323126916278856549586825357358273536","best_ask":"0.41","best_bid":"0.4","hash":"de096868f7fce9ddd6ef04e7d38a2c7cfb439767","price":"0.35","side":"BUY","size":"36.21"},{"asset_id":"8698449539441374295770236407991735029336433231649246775082939325523552031992","best_ask":"0.6","best_bid":"0.59","hash":"a1a7b116738f5a2eede5a7a870c619f3f7c6ba5e","price":"0.65","side":"SELL","size":"36.21"}],"timestamp":"1785121917666"},"payload_hash":"299ae0adc47d2d36060f38c004383481db38ffc394545480bc2f4ed678195c11","raw_frame":"{\"market\":\"0xf9d60bb033695053c4d1d8592e52171c1042f64b41a4b72e09dcc6f4852b6670\", \"price_changes\":[{\"asset_id\":\"96283536366176669581486355171583722558858323126916278856549586825357358273536\", \"price\":\"0.35\", \"size\":\"36.21\", \"side\":\"BUY\", \"hash\":\"de096868f7fce9ddd6ef04e7d38a2c7cfb439767\", \"best_bid\":\"0.4\", \"best_ask\":\"0.41\"}, {\"asset_id\":\"8698449539441374295770236407991735029336433231649246775082939325523552031992\", \"price\":\"0.65\", \"size\":\"36.21\", \"side\":\"SELL\", \"hash\":\"a1a7b116738f5a2eede5a7a870c619f3f7c6ba5e\", \"best_bid\":\"0.59\", \"best_ask\":\"0.6\"}], \"timestamp\":\"1785121917666\", \"event_type\":\"price_change\"}","received_at":"2026-07-27T03:12:03.965419Z","schema_version":"clob-market-ws.price_change.v1","sequence":null,"server_hash":null,"server_timestamp":"1785121917666","session_id":"ff6d21c8283948938400a32613abec2c","source":"clob_market_ws"},"received_at":"2026-07-27T03:12:03.965419Z","record_id":"159f5573295901de4c2ea43079bc711d92505f61d89e1546c3d4fad86a998d18","schema_fingerprint":"4aa3821a28b0b7c2400bc59aba4bcc0a76e971dadd19610d3ad38c768e124dc7","schema_version":"edge-lab-recorder.raw.v1","sequence":null,"source":"clob_market_ws"}
{"event_at":"2026-07-27T03:11:57.667000Z","event_fingerprint":"5b932e3f96d3887010f28c7b38bab4c87b9c5e8ee5d987beea07afd69576e32c","payload":{"connection_id":"f95883f18d264834af91809e5f803e9f","event_at":"2026-07-27T03:11:57.667000Z","event_type":"price_change","frame_hash":"a51baf27f7a1f74edeb83a4eb197c0a38d5ceee130e051dc235f5be981141048","frame_index":0,"kind":"data","monotonic_ns":223907298112000,"payload":{"event_type":"price_change","market":"0xf9d60bb033695053c4d1d8592e52171c1042f64b41a4b72e09dcc6f4852b6670","price_changes":[{"asset_id":"8698449539441374295770236407991735029336433231649246775082939325523552031992","best_ask":"0.6","best_bid":"0.59","hash":"f04a9a43fb8237351929994ea198570739d07d75","price":"0.61","side":"SELL","size":"10"},{"asset_id":"96283536366176669581486355171583722558858323126916278856549586825357358273536","best_ask":"0.41","best_bid":"0.4","hash":"bb934afffab4505d3992d9cfe166ace94fbd7347","price":"0.39","side":"BUY","size":"10"}],"timestamp":"1785121917667"},"payload_hash":"c21dd0adbe2fdc070f5295fd1aa28a12aa959831f9057a5435c3c60407398f78","raw_frame":"{\"market\":\"0xf9d60bb033695053c4d1d8592e52171c1042f64b41a4b72e09dcc6f4852b6670\", \"price_changes\":[{\"asset_id\":\"8698449539441374295770236407991735029336433231649246775082939325523552031992\", \"price\":\"0.61\", \"size\":\"10\", \"side\":\"SELL\", \"hash\":\"f04a9a43fb8237351929994ea198570739d07d75\", \"best_bid\":\"0.59\", \"best_ask\":\"0.6\"}, {\"asset_id\":\"96283536366176669581486355171583722558858323126916278856549586825357358273536\", \"price\":\"0.39\", \"size\":\"10\", \"side\":\"BUY\", \"hash\":\"bb934afffab4505d3992d9cfe166ace94fbd7347\", \"best_bid\":\"0.4\", \"best_ask\":\"0.41\"}], \"timestamp\":\"1785121917667\", \"event_type\":\"price_change\"}","received_at":"2026-07-27T03:12:03.966916Z","schema_version":"clob-market-ws.price_change.v1","sequence":null,"server_hash":null,"server_timestamp":"1785121917667","session_id":"ff6d21c8283948938400a32613abec2c","source":"clob_market_ws"},"received_at":"2026-07-27T03:12:03.966916Z","record_id":"3e9774a392f110703e4ea10a030914c9e25ddefb8ff4df4480dd8f734f820c66","schema_fingerprint":"4aa3821a28b0b7c2400bc59aba4bcc0a76e971dadd19610d3ad38c768e124dc7","schema_version":"edge-lab-recorder.raw.v1","sequence":null,"source":"clob_market_ws"}
{"event_at":"2026-07-27T03:11:57.673000Z","event_fingerprint":"826efb9ca1b663794061cd6068ca807ae3e04410b2916bb55c76464564bd6ca5","payload":{"connection_id":"f95883f18d264834af91809e5f803e9f","event_at":"2026-07-27T03:11:57.673000Z","event_type":"price_change","frame_hash":"9d1a3ad7df548a99e1074bb0f1b5fb98d770bc6369577619b626a12f3d820bff","frame_index":0,"kind":"data","monotonic_ns":223907301126166,"payload":{"event_type":"price_change","market":"0xf9d60bb033695053c4d1d8592e52171c1042f64b41a4b72e09dcc6f4852b6670","price_changes":[{"asset_id":"8698449539441374295770236407991735029336433231649246775082939325523552031992","best_ask":"0.6","best_bid":"0.59","hash":"0a5578430d57018f3470ac564fd820d2b0630725","price":"0.59","side":"BUY","size":"85"},{"asset_id":"96283536366176669581486355171583722558858323126916278856549586825357358273536","best_ask":"0.41","best_bid":"0.4","hash":"063233e37365c0bef204714da4867b980f13f33a","price":"0.41","side":"SELL","size":"85"}],"timestamp":"1785121917673"},"payload_hash":"fd37c862f25982fe377f1b9e26ebd76e6a8b54f387652854e717f79175ea09b4","raw_frame":"{\"market\":\"0xf9d60bb033695053c4d1d8592e52171c1042f64b41a4b72e09dcc6f4852b6670\", \"price_changes\":[{\"asset_id\":\"8698449539441374295770236407991735029336433231649246775082939325523552031992\", \"price\":\"0.59\", \"size\":\"85\", \"side\":\"BUY\", \"hash\":\"0a5578430d57018f3470ac564fd820d2b0630725\", \"best_bid\":\"0.59\", \"best_ask\":\"0.6\"}, {\"asset_id\":\"96283536366176669581486355171583722558858323126916278856549586825357358273536\", \"price\":\"0.41\", \"size\":\"85\", \"side\":\"SELL\", \"hash\":\"063233e37365c0bef204714da4867b980f13f33a\", \"best_bid\":\"0.4\", \"best_ask\":\"0.41\"}], \"timestamp\":\"1785121917673\", \"event_type\":\"price_change\"}","received_at":"2026-07-27T03:12:03.969930Z","schema_version":"clob-market-ws.price_change.v1","sequence":null,"server_hash":null,"server_timestamp":"1785121917673","session_id":"ff6d21c8283948938400a32613abec2c","source":"clob_market_ws"},"received_at":"2026-07-27T03:12:03.969930Z","record_id":"3a897a4c196f136e80072ee55cf57730b31a9cefd4eba22d6ec225a89b182381","schema_fingerprint":"4aa3821a28b0b7c2400bc59aba4bcc0a76e971dadd19610d3ad38c768e124dc7","schema_version":"edge-lab-recorder.raw.v1","sequence":null,"source":"clob_market_ws"}
{"event_at":"2026-07-27T03:11:57.677000Z","event_fingerprint":"e8367bc60831a983d09f7ccbcb8b521b1c07ae71b95c399fa4a193a3d22fd432","payload":{"connection_id":"f95883f18d264834af91809e5f803e9f","event_at":"2026-07-27T03:11:57.677000Z","event_type":"price_change","frame_hash":"3adc6464d9341070fe31cff317f036d3ef6dc8787cb7863ca6d85c2487521e2c","frame_index":0,"kind":"data","monotonic_ns":223907304247750,"payload":{"event_type":"price_change","market":"0xf9d60bb033695053c4d1d8592e52171c1042f64b41a4b72e09dcc6f4852b6670","price_changes":[{"asset_id":"8698449539441374295770236407991735029336433231649246775082939325523552031992","best_ask":"0.6","best_bid":"0.59","hash":"5d7161cc26570c7a49947da31cf0e0ed16e63c74","price":"0.42","side":"BUY","size":"76.19"},{"asset_id":"96283536366176669581486355171583722558858323126916278856549586825357358273536","best_ask":"0.41","best_bid":"0.4","hash":"86b1ae5feb9c94cab86225f51214b2ab87d9db2a","price":"0.58","side":"SELL","size":"76.19"}],"timestamp":"1785121917677"},"payload_hash":"86a9912bbd995009a99b0d1bc85a8dde18d884a3571c1e29d4cccd7ae949d5d7","raw_frame":"{\"market\":\"0xf9d60bb033695053c4d1d8592e52171c1042f64b41a4b72e09dcc6f4852b6670\", \"price_changes\":[{\"asset_id\":\"8698449539441374295770236407991735029336433231649246775082939325523552031992\", \"price\":\"0.42\", \"size\":\"76.19\", \"side\":\"BUY\", \"hash\":\"5d7161cc26570c7a49947da31cf0e0ed16e63c74\", \"best_bid\":\"0.59\", \"best_ask\":\"0.6\"}, {\"asset_id\":\"96283536366176669581486355171583722558858323126916278856549586825357358273536\", \"price\":\"0.58\", \"size\":\"76.19\", \"side\":\"SELL\", \"hash\":\"86b1ae5feb9c94cab86225f51214b2ab87d9db2a\", \"best_bid\":\"0.4\", \"best_ask\":\"0.41\"}], \"timestamp\":\"1785121917677\", \"event_type\":\"price_change\"}","received_at":"2026-07-27T03:12:03.973052Z","schema_version":"clob-market-ws.price_change.v1","sequence":null,"server_hash":null,"server_timestamp":"1785121917677","session_id":"ff6d21c8283948938400a32613abec2c","source":"clob_market_ws"},"received_at":"2026-07-27T03:12:03.973052Z","record_id":"16cce06e12ae05d000a6c00b2c8b8a7f575f827d9199a238814afbb275536f05","schema_fingerprint":"4aa3821a28b0b7c2400bc59aba4bcc0a76e971dadd19610d3ad38c768e124dc7","schema_version":"edge-lab-recorder.raw.v1","sequence":null,"source":"clob_market_ws"}
{"event_at":"2026-07-27T03:11:57.679000Z","event_fingerprint":"05ace1313344d94ec6f971c197587648dfa09f931ef00efb2ed576c940db4bd1","payload":{"connection_id":"f95883f18d264834af91809e5f803e9f","event_at":"2026-07-27T03:11:57.679000Z","event_type":"price_change","frame_hash":"f78074cf7a132409db3327ed0842a7f1deee17100e4975c9d117fbb0efac3dae","frame_index":0,"kind":"data","monotonic_ns":223907307284791,"payload":{"event_type":"price_change","market":"0xf9d60bb033695053c4d1d8592e52171c1042f64b41a4b72e09dcc6f4852b6670","price_changes":[{"asset_id":"96283536366176669581486355171583722558858323126916278856549586825357358273536","best_ask":"0.41","best_bid":"0.4","hash":"8f15946c475c6d691532c0c4e9709dc7a25efe28","price":"0.17","side":"BUY","size":"88.29"},{"asset_id":"8698449539441374295770236407991735029336433231649246775082939325523552031992","best_ask":"0.6","best_bid":"0.59","hash":"75f989f3474e2b7f8b1c94728853259c1814c8fb","price":"0.83","side":"SELL","size":"88.29"}],"timestamp":"1785121917679"},"payload_hash":"ce832fe2ddd25c87adff787dabe2ba13fab725d602b7db4d81498c54ac69b77d","raw_frame":"{\"market\":\"0xf9d60bb033695053c4d1d8592e52171c1042f64b41a4b72e09dcc6f4852b6670\", \"price_changes\":[{\"asset_id\":\"96283536366176669581486355171583722558858323126916278856549586825357358273536\", \"price\":\"0.17\", \"size\":\"88.29\", \"side\":\"BUY\", \"hash\":\"8f15946c475c6d691532c0c4e9709dc7a25efe28\", \"best_bid\":\"0.4\", \"best_ask\":\"0.41\"}, {\"asset_id\":\"8698449539441374295770236407991735029336433231649246775082939325523552031992\", \"price\":\"0.83\", \"size\":\"88.29\", \"side\":\"SELL\", \"hash\":\"75f989f3474e2b7f8b1c94728853259c1814c8fb\", \"best_bid\":\"0.59\", \"best_ask\":\"0.6\"}], \"timestamp\":\"1785121917679\", \"event_type\":\"price_change\"}","received_at":"2026-07-27T03:12:03.976089Z","schema_version":"clob-market-ws.price_change.v1","sequence":null,"server_hash":null,"server_timestamp":"1785121917679","session_id":"ff6d21c8283948938400a32613abec2c","source":"clob_market_ws"},"received_at":"2026-07-27T03:12:03.976089Z","record_id":"8ebb164a15247f4b0cf15b9234a8bc2406bd9021f92f72397b9182cc3c7fa751","schema_fingerprint":"4aa3821a28b0b7c2400bc59aba4bcc0a76e971dadd19610d3ad38c768e124dc7","schema_version":"edge-lab-recorder.raw.v1","sequence":null,"source":"clob_market_ws"}
{"event_at":"2026-07-27T03:11:57.681000Z","event_fingerprint":"59596643676a9d3268daa35f826403d0d37a6e4fda4567b98252ee119a0e095c","payload":{"connection_id":"f95883f18d264834af91809e5f803e9f","event_at":"2026-07-27T03:11:57.681000Z","event_type":"price_change","frame_hash":"787447d02b9f462f4880b3524552c2734980ddd5a766c7134e7e16bb2465b421","frame_index":0,"kind":"data","monotonic_ns":223907310322541,"payload":{"event_type":"price_change","market":"0xf9d60bb033695053c4d1d8592e52171c1042f64b41a4b72e09dcc6f4852b6670","price_changes":[{"asset_id":"96283536366176669581486355171583722558858323126916278856549586825357358273536","best_ask":"0.41","best_bid":"0.4","hash":"2e291b6e2b3c60c5149a347f61b8fe8f7cdd73fa","price":"0.28","side":"BUY","size":"91"},{"asset_id":"8698449539441374295770236407991735029336433231649246775082939325523552031992","best_ask":"0.6","best_bid":"0.59","hash":"b39748d6291858d757aac72c79c4c0fdb623a165","price":"0.72","side":"SELL","size":"91"}],"timestamp":"1785121917681"},"payload_hash":"54894999186552f83c578b1c88bcb044ec7a1085966b759b88fb415459e52bc1","raw_frame":"{\"market\":\"0xf9d60bb033695053c4d1d8592e52171c1042f64b41a4b72e09dcc6f4852b6670\", \"price_changes\":[{\"asset_id\":\"96283536366176669581486355171583722558858323126916278856549586825357358273536\", \"price\":\"0.28\", \"size\":\"91\", \"side\":\"BUY\", \"hash\":\"2e291b6e2b3c60c5149a347f61b8fe8f7cdd73fa\", \"best_bid\":\"0.4\", \"best_ask\":\"0.41\"}, {\"asset_id\":\"8698449539441374295770236407991735029336433231649246775082939325523552031992\", \"price\":\"0.72\", \"size\":\"91\", \"side\":\"SELL\", \"hash\":\"b39748d6291858d757aac72c79c4c0fdb623a165\", \"best_bid\":\"0.59\", \"best_ask\":\"0.6\"}], \"timestamp\":\"1785121917681\", \"event_type\":\"price_change\"}","received_at":"2026-07-27T03:12:03.979124Z","schema_version":"clob-market-ws.price_change.v1","sequence":null,"server_hash":null,"server_timestamp":"1785121917681","session_id":"ff6d21c8283948938400a32613abec2c","source":"clob_market_ws"},"received_at":"2026-07-27T03:12:03.979124Z","record_id":"8154e955e5037a264a03244b84285cd3e3fd0d304169d9f6cc83f1b0f9615bae","schema_fingerprint":"4aa3821a28b0b7c2400bc59aba4bcc0a76e971dadd19610d3ad38c768e124dc7","schema_version":"edge-lab-recorder.raw.v1","sequence":null,"source":"clob_market_ws"}
{"event_at":"2026-07-27T03:11:57.681000Z","event_fingerprint":"49a9c2ef456559947c8f03ecf7ae58d7aa45ca1a3b0b75e2b83ddfc19f3a7bb0","payload":{"connection_id":"f95883f18d264834af91809e5f803e9f","event_at":"2026-07-27T03:11:57.681000Z","event_type":"price_change","frame_hash":"0028df5d5ea00ec3dcaeb1f9dd6198e7d16fae9ac413eb780aef65f748b1e4ab","frame_index":0,"kind":"data","monotonic_ns":223907313402083,"payload":{"event_type":"price_change","market":"0xf9d60bb033695053c4d1d8592e52171c1042f64b41a4b72e09dcc6f4852b6670","price_changes":[{"asset_id":"8698449539441374295770236407991735029336433231649246775082939325523552031992","best_ask":"0.6","best_bid":"0.59","hash":"0ac866bb4c15f387add124cfa955608a8668f925","price":"0.02","side":"BUY","size":"1370.79"},{"asset_id":"96283536366176669581486355171583722558858323126916278856549586825357358273536","best_ask":"0.41","best_bid":"0.4","hash":"b20cd9d381d32699b6178f109f0e438758a10df2","price":"0.98","side":"SELL","size":"1370.79"}],"timestamp":"1785121917681"},"payload_hash":"4e937c003f56ebbc9a874c8769a6defa568f8d37955d64550cec8e9f85a9d76a","raw_frame":"{\"market\":\"0xf9d60bb033695053c4d1d8592e52171c1042f64b41a4b72e09dcc6f4852b6670\", \"price_changes\":[{\"asset_id\":\"8698449539441374295770236407991735029336433231649246775082939325523552031992\", \"price\":\"0.02\", \"size\":\"1370.79\", \"side\":\"BUY\", \"hash\":\"0ac866bb4c15f387add124cfa955608a8668f925\", \"best_bid\":\"0.59\", \"best_ask\":\"0.6\"}, {\"asset_id\":\"96283536366176669581486355171583722558858323126916278856549586825357358273536\", \"price\":\"0.98\", \"size\":\"1370.79\", \"side\":\"SELL\", \"hash\":\"b20cd9d381d32699b6178f109f0e438758a10df2\", \"best_bid\":\"0.4\", \"best_ask\":\"0.41\"}], \"timestamp\":\"1785121917681\", \"event_type\":\"price_change\"}","received_at":"2026-07-27T03:12:03.982203Z","schema_version":"clob-market-ws.price_change.v1","sequence":null,"server_hash":null,"server_timestamp":"1785121917681","session_id":"ff6d21c8283948938400a32613abec2c","source":"clob_market_ws"},"received_at":"2026-07-27T03:12:03.982203Z","record_id":"d29cad7f3bdf587ed6f3a34edaf3b1025362c90363857cbaebc70d7e29982214","schema_fingerprint":"4aa3821a28b0b7c2400bc59aba4bcc0a76e971dadd19610d3ad38c768e124dc7","schema_version":"edge-lab-recorder.raw.v1","sequence":null,"source":"clob_market_ws"}
{"event_at":"2026-07-27T03:11:57.683000Z","event_fingerprint":"5692a3efd96fbac75ef33cd6de0e298274ede2e0e87d7699e46c90a3599cddc1","payload":{"connection_id":"f95883f18d264834af91809e5f803e9f","event_at":"2026-07-27T03:11:57.683000Z","event_type":"price_change","frame_hash":"5075f506ada3b7288474e1ac4ed7b9c93d5d5672f837bb5f13c50cd9b5af4959","frame_index":0,"kind":"data","monotonic_ns":223907315773333,"payload":{"event_type":"price_change","market":"0xf9d60bb033695053c4d1d8592e52171c1042f64b41a4b72e09dcc6f4852b6670","price_changes":[{"asset_id":"8698449539441374295770236407991735029336433231649246775082939325523552031992","best_ask":"0.6","best_bid":"0.59","hash":"4a38605bfae19b1238434ae6d060c2807af5501f","price":"0.58","side":"BUY","size":"40.54"},{"asset_id":"96283536366176669581486355171583722558858323126916278856549586825357358273536","best_ask":"0.41","best_bid":"0.4","hash":"163a3ffa7a88cf1a668567b10d7d0cbcd0a9ddd3","price":"0.42","side":"SELL","size":"40.54"}],"timestamp":"1785121917683"},"payload_hash":"cfcdea353f67a5cd3467775d90240fc320ce1af1343d87ee593e346dcbb0cdcd","raw_frame":"{\"market\":\"0xf9d60bb033695053c4d1d8592e52171c1042f64b41a4b72e09dcc6f4852b6670\", \"price_changes\":[{\"asset_id\":\"8698449539441374295770236407991735029336433231649246775082939325523552031992\", \"price\":\"0.58\", \"size\":\"40.54\", \"side\":\"BUY\", \"hash\":\"4a38605bfae19b1238434ae6d060c2807af5501f\", \"best_bid\":\"0.59\", \"best_ask\":\"0.6\"}, {\"asset_id\":\"96283536366176669581486355171583722558858323126916278856549586825357358273536\", \"price\":\"0.42\", \"size\":\"40.54\", \"side\":\"SELL\", \"hash\":\"163a3ffa7a88cf1a668567b10d7d0cbcd0a9ddd3\", \"best_bid\":\"0.4\", \"best_ask\":\"0.41\"}], \"timestamp\":\"1785121917683\", \"event_type\":\"price_change\"}","received_at":"2026-07-27T03:12:03.984576Z","schema_version":"clob-market-ws.price_change.v1","sequence":null,"server_hash":null,"server_timestamp":"1785121917683","session_id":"ff6d21c8283948938400a32613abec2c","source":"clob_market_ws"},"received_at":"2026-07-27T03:12:03.984576Z","record_id":"8c05b0daf7f2410e5f7dcd6c3fb33f8ea469ce1454c8d6c4725b05879c0b8d25","schema_fingerprint":"4aa3821a28b0b7c2400bc59aba4bcc0a76e971dadd19610d3ad38c768e124dc7","schema_version":"edge-lab-recorder.raw.v1","sequence":null,"source":"clob_market_ws"}
{"event_at":"2026-07-27T03:11:57.685000Z","event_fingerprint":"9e0721c0624bf3b290a7e8d3a5e6135efe8445c75c30f6ccf7567046a18af650","payload":{"connection_id":"f95883f18d264834af91809e5f803e9f","event_at":"2026-07-27T03:11:57.685000Z","event_type":"price_change","frame_hash":"4ec7567d1e6ed486fb9d1ff6f6ad52da3b524a2838ae5abdb4ac1150dfaf7583","frame_index":0,"kind":"data","monotonic_ns":223907318714625,"payload":{"event_type":"price_change","market":"0xf9d60bb033695053c4d1d8592e52171c1042f64b41a4b72e09dcc6f4852b6670","price_changes":[{"asset_id":"8698449539441374295770236407991735029336433231649246775082939325523552031992","best_ask":"0.6","best_bid":"0.59","hash":"c99db5aad0e0b933549a0dea5cef5cd54b718185","price":"0.01","side":"BUY","size":"8152.52"},{"asset_id":"96283536366176669581486355171583722558858323126916278856549586825357358273536","best_ask":"0.41","best_bid":"0.4","hash":"1596d1ba4133d702e6cebf3d4ecf42de7fe40599","price":"0.99","side":"SELL","size":"8152.52"}],"timestamp":"1785121917685"},"payload_hash":"57a4c329210ed64b8f323b98f25746b7cb085e67dc7742ce91ac8e99524019d4","raw_frame":"{\"market\":\"0xf9d60bb033695053c4d1d8592e52171c1042f64b41a4b72e09dcc6f4852b6670\", \"price_changes\":[{\"asset_id\":\"8698449539441374295770236407991735029336433231649246775082939325523552031992\", \"price\":\"0.01\", \"size\":\"8152.52\", \"side\":\"BUY\", \"hash\":\"c99db5aad0e0b933549a0dea5cef5cd54b718185\", \"best_bid\":\"0.59\", \"best_ask\":\"0.6\"}, {\"asset_id\":\"96283536366176669581486355171583722558858323126916278856549586825357358273536\", \"price\":\"0.99\", \"size\":\"8152.52\", \"side\":\"SELL\", \"hash\":\"1596d1ba4133d702e6cebf3d4ecf42de7fe40599\", \"best_bid\":\"0.4\", \"best_ask\":\"0.41\"}], \"timestamp\":\"1785121917685\", \"event_type\":\"price_change\"}","received_at":"2026-07-27T03:12:03.987518Z","schema_version":"clob-market-ws.price_change.v1","sequence":null,"server_hash":null,"server_timestamp":"1785121917685","session_id":"ff6d21c8283948938400a32613abec2c","source":"clob_market_ws"},"received_at":"2026-07-27T03:12:03.987518Z","record_id":"4329f60be6cf83008832d03fc23a228254ee1c34121f01dea7f235737f41aac8","schema_fingerprint":"4aa3821a28b0b7c2400bc59aba4bcc0a76e971dadd19610d3ad38c768e124dc7","schema_version":"edge-lab-recorder.raw.v1","sequence":null,"source":"clob_market_ws"}
{"event_at":"2026-07-27T03:11:57.687000Z","event_fingerprint":"b554592e09bdb0df1051ad6fbe1b8ad5473d1d2a360d376a7c0e341431aac66f","payload":{"connection_id":"f95883f18d264834af91809e5f803e9f","event_at":"2026-07-27T03:11:57.687000Z","event_type":"price_change","frame_hash":"6b32179e68d453baea18ca36e6a82fba7312a034becd75fc2e89ea2fa032b826","frame_index":0,"kind":"data","monotonic_ns":223907321665041,"payload":{"event_type":"price_change","market":"0xf9d60bb033695053c4d1d8592e52171c1042f64b41a4b72e09dcc6f4852b6670","price_changes":[{"asset_id":"8698449539441374295770236407991735029336433231649246775082939325523552031992","best_ask":"0.6","best_bid":"0.59","hash":"729126f49f3377a29b50b21133f08a259fef1122","price":"0.43","side":"BUY","size":"160.48"},{"asset_id":"96283536366176669581486355171583722558858323126916278856549586825357358273536","best_ask":"0.41","best_bid":"0.4","hash":"c861e094652601b45906bdbab1b497d5c7baf0aa","price":"0.57","side":"SELL","size":"160.48"}],"timestamp":"1785121917687"},"payload_hash":"e3efd542222d2d2c54781ad70e6a58ef9155f996b9253d478f02ca2495689c20","raw_frame":"{\"market\":\"0xf9d60bb033695053c4d1d8592e52171c1042f64b41a4b72e09dcc6f4852b6670\", \"price_changes\":[{\"asset_id\":\"8698449539441374295770236407991735029336433231649246775082939325523552031992\", \"price\":\"0.43\", \"size\":\"160.48\", \"side\":\"BUY\", \"hash\":\"729126f49f3377a29b50b21133f08a259fef1122\", \"best_bid\":\"0.59\", \"best_ask\":\"0.6\"}, {\"asset_id\":\"96283536366176669581486355171583722558858323126916278856549586825357358273536\", \"price\":\"0.57\", \"size\":\"160.48\", \"side\":\"SELL\", \"hash\":\"c861e094652601b45906bdbab1b497d5c7baf0aa\", \"best_bid\":\"0.4\", \"best_ask\":\"0.41\"}], \"timestamp\":\"1785121917687\", \"event_type\":\"price_change\"}","received_at":"2026-07-27T03:12:03.990468Z","schema_version":"clob-market-ws.price_change.v1","sequence":null,"server_hash":null,"server_timestamp":"1785121917687","session_id":"ff6d21c8283948938400a32613abec2c","source":"clob_market_ws"},"received_at":"2026-07-27T03:12:03.990468Z","record_id":"7494cec47b98e1d0fdda5565a0b2fc202f33cd889b04304dbe60b3c66e965f26","schema_fingerprint":"4aa3821a28b0b7c2400bc59aba4bcc0a76e971dadd19610d3ad38c768e124dc7","schema_version":"edge-lab-recorder.raw.v1","sequence":null,"source":"clob_market_ws"}
{"event_at":"2026-07-27T03:11:57.691000Z","event_fingerprint":"a4f4e753b33c99e79e41cc5d3d3f2c419f339da73a03435793033a8f50e8c3b6","payload":{"connection_id":"f95883f18d264834af91809e5f803e9f","event_at":"2026-07-27T03:11:57.691000Z","event_type":"price_change","frame_hash":"25f7f955fadba5f0a4df10607e977c19ddf8d130e27468acfea0461fa10729b4","frame_index":0,"kind":"data","monotonic_ns":223907324552666,"payload":{"event_type":"price_change","market":"0xf9d60bb033695053c4d1d8592e52171c1042f64b41a4b72e09dcc6f4852b6670","price_changes":[{"asset_id":"8698449539441374295770236407991735029336433231649246775082939325523552031992","best_ask":"0.6","best_bid":"0.59","hash":"a5f8acd9ecc32efd3c33bc8986b33b59cb8fab2d","price":"0.58","side":"BUY","size":"45.54"},{"asset_id":"96283536366176669581486355171583722558858323126916278856549586825357358273536","best_ask":"0.41","best_bid":"0.4","hash":"1fa97510d2f8206897568c7c12bc8038178647a1","price":"0.42","side":"SELL","size":"45.54"}],"timestamp":"1785121917691"},"payload_hash":"99d8f197fc0eaaade9ba151bfaa581244b81a7861e461b7a8e505ba7a989b8a8","raw_frame":"{\"market\":\"0xf9d60bb033695053c4d1d8592e52171c1042f64b41a4b72e09dcc6f4852b6670\", \"price_changes\":[{\"asset_id\":\"8698449539441374295770236407991735029336433231649246775082939325523552031992\", \"price\":\"0.58\", \"size\":\"45.54\", \"side\":\"BUY\", \"hash\":\"a5f8acd9ecc32efd3c33bc8986b33b59cb8fab2d\", \"best_bid\":\"0.59\", \"best_ask\":\"0.6\"}, {\"asset_id\":\"96283536366176669581486355171583722558858323126916278856549586825357358273536\", \"price\":\"0.42\", \"size\":\"45.54\", \"side\":\"SELL\", \"hash\":\"1fa97510d2f8206897568c7c12bc8038178647a1\", \"best_bid\":\"0.4\", \"best_ask\":\"0.41\"}], \"timestamp\":\"1785121917691\", \"event_type\":\"price_change\"}","received_at":"2026-07-27T03:12:03.993355Z","schema_version":"clob-market-ws.price_change.v1","sequence":null,"server_hash":null,"server_timestamp":"1785121917691","session_id":"ff6d21c8283948938400a32613abec2c","source":"clob_market_ws"},"received_at":"2026-07-27T03:12:03.993355Z","record_id":"a9f3b64f3bd8e9328758cc976f7c04883fafbeb162a414593560f692b84a754c","schema_fingerprint":"4aa3821a28b0b7c2400bc59aba4bcc0a76e971dadd19610d3ad38c768e124dc7","schema_version":"edge-lab-recorder.raw.v1","sequence":null,"source":"clob_market_ws"}
{"event_at":"2026-07-27T03:11:57.691000Z","event_fingerprint":"7998209b05f868f3bb3d7a1f80154ddc7fa313a530d07e3f943b0a0a17befdcb","payload":{"connection_id":"f95883f18d264834af91809e5f803e9f","event_at":"2026-07-27T03:11:57.691000Z","event_type":"price_change","frame_hash":"a64c1b7334e890c92b0fe9251cdba972ae7d33db287ea7d1d8066e269c56c4db","frame_index":0,"kind":"data","monotonic_ns":223907327470666,"payload":{"event_type":"price_change","market":"0xf9d60bb033695053c4d1d8592e52171c1042f64b41a4b72e09dcc6f4852b6670","price_changes":[{"asset_id":"8698449539441374295770236407991735029336433231649246775082939325523552031992","best_ask":"0.6","best_bid":"0.59","hash":"c72788df1c96dba63e185c3c484419fabae5fb71","price":"0.51","side":"BUY","size":"25"},{"asset_id":"96283536366176669581486355171583722558858323126916278856549586825357358273536","best_ask":"0.41","best_bid":"0.4","hash":"6340fa8330bc48c17a3447ad83240e42b9746d61","price":"0.49","side":"SELL","size":"25"}],"timestamp":"1785121917691"},"payload_hash":"45db6d6eba0a30489e38d2041f416f57a7a4ac26b670e145ae0382f2235f9e38","raw_frame":"{\"market\":\"0xf9d60bb033695053c4d1d8592e52171c1042f64b41a4b72e09dcc6f4852b6670\", \"price_changes\":[{\"asset_id\":\"8698449539441374295770236407991735029336433231649246775082939325523552031992\", \"price\":\"0.51\", \"size\":\"25\", \"side\":\"BUY\", \"hash\":\"c72788df1c96dba63e185c3c484419fabae5fb71\", \"best_bid\":\"0.59\", \"best_ask\":\"0.6\"}, {\"asset_id\":\"96283536366176669581486355171583722558858323126916278856549586825357358273536\", \"price\":\"0.49\", \"size\":\"25\", \"side\":\"SELL\", \"hash\":\"6340fa8330bc48c17a3447ad83240e42b9746d61\", \"best_bid\":\"0.4\", \"best_ask\":\"0.41\"}], \"timestamp\":\"1785121917691\", \"event_type\":\"price_change\"}","received_at":"2026-07-27T03:12:03.996274Z","schema_version":"clob-market-ws.price_change.v1","sequence":null,"server_hash":null,"server_timestamp":"1785121917691","session_id":"ff6d21c8283948938400a32613abec2c","source":"clob_market_ws"},"received_at":"2026-07-27T03:12:03.996274Z","record_id":"5c2a58a671f81e01ac6c4d78207c6aef52cd12783bcd14e75506c9de13aa0e7f","schema_fingerprint":"4aa3821a28b0b7c2400bc59aba4bcc0a76e971dadd19610d3ad38c768e124dc7","schema_version":"edge-lab-recorder.raw.v1","sequence":null,"source":"clob_market_ws"}
{"event_at":"2026-07-27T03:11:57.692000Z","event_fingerprint":"3bccb9a92a52b5484530576059b16da84ce5cba8ebbdd6254f2a21c552400db3","payload":{"connection_id":"f95883f18d264834af91809e5f803e9f","event_at":"2026-07-27T03:11:57.692000Z","event_type":"price_change","frame_hash":"5760dcfd3e3d493b41d9edf766c39a62776c2be6aa640b3d3b79325ab379c871","frame_index":0,"kind":"data","monotonic_ns":223907330291125,"payload":{"event_type":"price_change","market":"0xf9d60bb033695053c4d1d8592e52171c1042f64b41a4b72e09dcc6f4852b6670","price_changes":[{"asset_id":"96283536366176669581486355171583722558858323126916278856549586825357358273536","best_ask":"0.41","best_bid":"0.4","hash":"308b4db0800f0a5cee7ea58c68b608ffa7f9b64c","price":"0.3","side":"BUY","size":"128"},{"asset_id":"8698449539441374295770236407991735029336433231649246775082939325523552031992","best_ask":"0.6","best_bid":"0.59","hash":"e93d2fade9cc3f47ae20906e881db7ca7e5716f6","price":"0.7","side":"SELL","size":"128"}],"timestamp":"1785121917692"},"payload_hash":"ce4107163fe7c9ef908226045e25876adc624ba847877c6ec5db6eb3b340e87e","raw_frame":"{\"market\":\"0xf9d60bb033695053c4d1d8592e52171c1042f64b41a4b72e09dcc6f4852b6670\", \"price_changes\":[{\"asset_id\":\"96283536366176669581486355171583722558858323126916278856549586825357358273536\", \"price\":\"0.3\", \"size\":\"128\", \"side\":\"BUY\", \"hash\":\"308b4db0800f0a5cee7ea58c68b608ffa7f9b64c\", \"best_bid\":\"0.4\", \"best_ask\":\"0.41\"}, {\"asset_id\":\"8698449539441374295770236407991735029336433231649246775082939325523552031992\", \"price\":\"0.7\", \"size\":\"128\", \"side\":\"SELL\", \"hash\":\"e93d2fade9cc3f47ae20906e881db7ca7e5716f6\", \"best_bid\":\"0.59\", \"best_ask\":\"0.6\"}], \"timestamp\":\"1785121917692\", \"event_type\":\"price_change\"}","received_at":"2026-07-27T03:12:03.999095Z","schema_version":"clob-market-ws.price_change.v1","sequence":null,"server_hash":null,"server_timestamp":"1785121917692","session_id":"ff6d21c8283948938400a32613abec2c","source":"clob_market_ws"},"received_at":"2026-07-27T03:12:03.999095Z","record_id":"93bea74435610688cfb55a7303e99f2803fc7c0fa244ac1937991d12d4e55080","schema_fingerprint":"4aa3821a28b0b7c2400bc59aba4bcc0a76e971dadd19610d3ad38c768e124dc7","schema_version":"edge-lab-recorder.raw.v1","sequence":null,"source":"clob_market_ws"}
{"event_at":"2026-07-27T03:11:57.693000Z","event_fingerprint":"dd1afd53b8fffd012dc2772906b19a689c140b8000e24cf14715df062966f8e5","payload":{"connection_id":"f95883f18d264834af91809e5f803e9f","event_at":"2026-07-27T03:11:57.693000Z","event_type":"price_change","frame_hash":"812097f68210584bf899a1fb7f4df864d6192ecfcafc89269aeea86f04f2fe15","frame_index":0,"kind":"data","monotonic_ns":223907331694041,"payload":{"event_type":"price_change","market":"0xf9d60bb033695053c4d1d8592e52171c1042f64b41a4b72e09dcc6f4852b6670","price_changes":[{"asset_id":"96283536366176669581486355171583722558858323126916278856549586825357358273536","best_ask":"0.41","best_bid":"0.4","hash":"1d3b9c6f7e07757b8b06df710cd47596e1d8d54b","price":"0.3","side":"BUY","size":"133"},{"asset_id":"8698449539441374295770236407991735029336433231649246775082939325523552031992","best_ask":"0.6","best_bid":"0.59","hash":"4387b25f8337b303cef34cc80cda082285a6b5d0","price":"0.7","side":"SELL","size":"133"}],"timestamp":"1785121917693"},"payload_hash":"49e55e5455a6d421e9be0e9f44b7c2684d4e144db9cc06460073260d27e16eef","raw_frame":"{\"market\":\"0xf9d60bb033695053c4d1d8592e52171c1042f64b41a4b72e09dcc6f4852b6670\", \"price_changes\":[{\"asset_id\":\"96283536366176669581486355171583722558858323126916278856549586825357358273536\", \"price\":\"0.3\", \"size\":\"133\", \"side\":\"BUY\", \"hash\":\"1d3b9c6f7e07757b8b06df710cd47596e1d8d54b\", \"best_bid\":\"0.4\", \"best_ask\":\"0.41\"}, {\"asset_id\":\"8698449539441374295770236407991735029336433231649246775082939325523552031992\", \"price\":\"0.7\", \"size\":\"133\", \"side\":\"SELL\", \"hash\":\"4387b25f8337b303cef34cc80cda082285a6b5d0\", \"best_bid\":\"0.59\", \"best_ask\":\"0.6\"}], \"timestamp\":\"1785121917693\", \"event_type\":\"price_change\"}","received_at":"2026-07-27T03:12:04.000495Z","schema_version":"clob-market-ws.price_change.v1","sequence":null,"server_hash":null,"server_timestamp":"1785121917693","session_id":"ff6d21c8283948938400a32613abec2c","source":"clob_market_ws"},"received_at":"2026-07-27T03:12:04.000495Z","record_id":"3b59a09436db3212f32a5d432d5c83bed4a3e48727a9274bd0c9461b44736d37","schema_fingerprint":"4aa3821a28b0b7c2400bc59aba4bcc0a76e971dadd19610d3ad38c768e124dc7","schema_version":"edge-lab-recorder.raw.v1","sequence":null,"source":"clob_market_ws"}
{"event_at":"2026-07-27T03:11:57.694000Z","event_fingerprint":"489ef1ec04d4322012e0e15e9eabee5d5bc52115ebcde7a523bfec0464cfbe94","payload":{"connection_id":"f95883f18d264834af91809e5f803e9f","event_at":"2026-07-27T03:11:57.694000Z","event_type":"price_change","frame_hash":"d14760e8af9bde1a36e88d661b53b1b8120d8a1dffba4e80aee3a7dd9adaae65","frame_index":0,"kind":"data","monotonic_ns":223907335276958,"payload":{"event_type":"price_change","market":"0xf9d60bb033695053c4d1d8592e52171c1042f64b41a4b72e09dcc6f4852b6670","price_changes":[{"asset_id":"8698449539441374295770236407991735029336433231649246775082939325523552031992","best_ask":"0.6","best_bid":"0.59","hash":"d250e9643a63eb4ee62dfb16b928b3ee8901b1a8","price":"0.46","side":"BUY","size":"57.1"},{"asset_id":"96283536366176669581486355171583722558858323126916278856549586825357358273536","best_ask":"0.41","best_bid":"0.4","hash":"c3ecee543c13eca80e9b8ef4ed16ffcf05ae219e","price":"0.54","side":"SELL","size":"57.1"}],"timestamp":"1785121917694"},"payload_hash":"112d2e93a333a695cdd15b4781d3a4a8477c5e2b42763ff51c70510e183d3fcc","raw_frame":"{\"market\":\"0xf9d60bb033695053c4d1d8592e52171c1042f64b41a4b72e09dcc6f4852b6670\", \"price_changes\":[{\"asset_id\":\"8698449539441374295770236407991735029336433231649246775082939325523552031992\", \"price\":\"0.46\", \"size\":\"57.1\", \"side\":\"BUY\", \"hash\":\"d250e9643a63eb4ee62dfb16b928b3ee8901b1a8\", \"best_bid\":\"0.59\", \"best_ask\":\"0.6\"}, {\"asset_id\":\"96283536366176669581486355171583722558858323126916278856549586825357358273536\", \"price\":\"0.54\", \"size\":\"57.1\", \"side\":\"SELL\", \"hash\":\"c3ecee543c13eca80e9b8ef4ed16ffcf05ae219e\", \"best_bid\":\"0.4\", \"best_ask\":\"0.41\"}], \"timestamp\":\"1785121917694\", \"event_type\":\"price_change\"}","received_at":"2026-07-27T03:12:04.004080Z","schema_version":"clob-market-ws.price_change.v1","sequence":null,"server_hash":null,"server_timestamp":"1785121917694","session_id":"ff6d21c8283948938400a32613abec2c","source":"clob_market_ws"},"received_at":"2026-07-27T03:12:04.004080Z","record_id":"115a33cdb612cc75a146bf7af46c3523fab68f7c36db050ce55172c8b2a2e4db","schema_fingerprint":"4aa3821a28b0b7c2400bc59aba4bcc0a76e971dadd19610d3ad38c768e124dc7","schema_version":"edge-lab-recorder.raw.v1","sequence":null,"source":"clob_market_ws"}
{"event_at":"2026-07-27T03:11:57.695000Z","event_fingerprint":"a22137dc3720275057a64374c8b526cb1635f702bcc2ed82fbe9483d6ded5d94","payload":{"connection_id":"f95883f18d264834af91809e5f803e9f","event_at":"2026-07-27T03:11:57.695000Z","event_type":"price_change","frame_hash":"68eb15b8dc794ad5f7d169786d08be0822f2174898a457be6891806e976167f8","frame_index":0,"kind":"data","monotonic_ns":223907338408833,"payload":{"event_type":"price_change","market":"0xf9d60bb033695053c4d1d8592e52171c1042f64b41a4b72e09dcc6f4852b6670","price_changes":[{"asset_id":"96283536366176669581486355171583722558858323126916278856549586825357358273536","best_ask":"0.41","best_bid":"0.4","hash":"f34935427931df3431ed3ffcdb37fb41fe40061a","price":"0.3","side":"BUY","size":"138"},{"asset_id":"8698449539441374295770236407991735029336433231649246775082939325523552031992","best_ask":"0.6","best_bid":"0.59","hash":"16b0d07ad61e149345dcab5f58d2f0bd84610c3b","price":"0.7","side":"SELL","size":"138"}],"timestamp":"1785121917695"},"payload_hash":"02b7bd0f605bea429934f63a4d3d6abb28b33a2aec049af745b36722f3e083a1","raw_frame":"{\"market\":\"0xf9d60bb033695053c4d1d8592e52171c1042f64b41a4b72e09dcc6f4852b6670\", \"price_changes\":[{\"asset_id\":\"96283536366176669581486355171583722558858323126916278856549586825357358273536\", \"price\":\"0.3\", \"size\":\"138\", \"side\":\"BUY\", \"hash\":\"f34935427931df3431ed3ffcdb37fb41fe40061a\", \"best_bid\":\"0.4\", \"best_ask\":\"0.41\"}, {\"asset_id\":\"8698449539441374295770236407991735029336433231649246775082939325523552031992\", \"price\":\"0.7\", \"size\":\"138\", \"side\":\"SELL\", \"hash\":\"16b0d07ad61e149345dcab5f58d2f0bd84610c3b\", \"best_bid\":\"0.59\", \"best_ask\":\"0.6\"}], \"timestamp\":\"1785121917695\", \"event_type\":\"price_change\"}","received_at":"2026-07-27T03:12:04.007212Z","schema_version":"clob-market-ws.price_change.v1","sequence":null,"server_hash":null,"server_timestamp":"1785121917695","session_id":"ff6d21c8283948938400a32613abec2c","source":"clob_market_ws"},"received_at":"2026-07-27T03:12:04.007212Z","record_id":"c78aa92eeb24f950c30ed0ed23a71124353986fb25d7581a61404fc013df406c","schema_fingerprint":"4aa3821a28b0b7c2400bc59aba4bcc0a76e971dadd19610d3ad38c768e124dc7","schema_version":"edge-lab-recorder.raw.v1","sequence":null,"source":"clob_market_ws"}
{"event_at":"2026-07-27T03:11:57.695000Z","event_fingerprint":"e96653398a96501f81296154f7f64dd3b78936ec8c332a249409343ba9ffd3dc","payload":{"connection_id":"f95883f18d264834af91809e5f803e9f","event_at":"2026-07-27T03:11:57.695000Z","event_type":"price_change","frame_hash":"9e1125707a959de06324d52301a2b0f996d7eab35ffff05409bb3fcdda32f095","frame_index":0,"kind":"data","monotonic_ns":223907341220000,"payload":{"event_type":"price_change","market":"0xf9d60bb033695053c4d1d8592e52171c1042f64b41a4b72e09dcc6f4852b6670","price_changes":[{"asset_id":"8698449539441374295770236407991735029336433231649246775082939325523552031992","best_ask":"0.6","best_bid":"0.59","hash":"60cfd3455dc4516773c3f9b4e93e657eb92dd602","price":"0.58","side":"BUY","size":"50.54"},{"asset_id":"96283536366176669581486355171583722558858323126916278856549586825357358273536","best_ask":"0.41","best_bid":"0.4","hash":"b0306d1519dac82d2ad147a4aa64a469ad1559fe","price":"0.42","side":"SELL","size":"50.54"}],"timestamp":"1785121917695"},"payload_hash":"67618cf3ab71c9d9a70c08709a779233671f94d2a9d1f257491f7f1b9b54f673","raw_frame":"{\"market\":\"0xf9d60bb033695053c4d1d8592e52171c1042f64b41a4b72e09dcc6f4852b6670\", \"price_changes\":[{\"asset_id\":\"8698449539441374295770236407991735029336433231649246775082939325523552031992\", \"price\":\"0.58\", \"size\":\"50.54\", \"side\":\"BUY\", \"hash\":\"60cfd3455dc4516773c3f9b4e93e657eb92dd602\", \"best_bid\":\"0.59\", \"best_ask\":\"0.6\"}, {\"asset_id\":\"96283536366176669581486355171583722558858323126916278856549586825357358273536\", \"price\":\"0.42\", \"size\":\"50.54\", \"side\":\"SELL\", \"hash\":\"b0306d1519dac82d2ad147a4aa64a469ad1559fe\", \"best_bid\":\"0.4\", \"best_ask\":\"0.41\"}], \"timestamp\":\"1785121917695\", \"event_type\":\"price_change\"}","received_at":"2026-07-27T03:12:04.010023Z","schema_version":"clob-market-ws.price_change.v1","sequence":null,"server_hash":null,"server_timestamp":"1785121917695","session_id":"ff6d21c8283948938400a32613abec2c","source":"clob_market_ws"},"received_at":"2026-07-27T03:12:04.010023Z","record_id":"5fe9894666af710799896d6375e65ab20e7a7cda3f2e4941e552c29e8af44ece","schema_fingerprint":"4aa3821a28b0b7c2400bc59aba4bcc0a76e971dadd19610d3ad38c768e124dc7","schema_version":"edge-lab-recorder.raw.v1","sequence":null,"source":"clob_market_ws"}
{"event_at":"2026-07-27T03:11:57.700000Z","event_fingerprint":"04956f77eaa3c8f9c764864dfd88fec5862fbe7b56ade616cd007260c4383d33","payload":{"connection_id":"f95883f18d264834af91809e5f803e9f","event_at":"2026-07-27T03:11:57.700000Z","event_type":"price_change","frame_hash":"fe1209d114b37d5764bbb9ed70737e1d0cdbc26893f117977284eaa4e35fe9c9","frame_index":0,"kind":"data","monotonic_ns":223907344208083,"payload":{"event_type":"price_change","market":"0xf9d60bb033695053c4d1d8592e52171c1042f64b41a4b72e09dcc6f4852b6670","price_changes":[{"asset_id":"8698449539441374295770236407991735029336433231649246775082939325523552031992","best_ask":"0.6","best_bid":"0.59","hash":"83617203175e9c2c1970327a0e262ea1f85fca3d","price":"0.51","side":"BUY","size":"20"},{"asset_id":"96283536366176669581486355171583722558858323126916278856549586825357358273536","best_ask":"0.41","best_bid":"0.4","hash":"63bac1458a50ad7b235ec2cdd34e9d3a7add8eca","price":"0.49","side":"SELL","size":"20"}],"timestamp":"1785121917700"},"payload_hash":"0f0e82240ac3d5760c409085c6bddc4074e8517fe3fc8f63835af0dcabb23012","raw_frame":"{\"market\":\"0xf9d60bb033695053c4d1d8592e52171c1042f64b41a4b72e09dcc6f4852b6670\", \"price_changes\":[{\"asset_id\":\"8698449539441374295770236407991735029336433231649246775082939325523552031992\", \"price\":\"0.51\", \"size\":\"20\", \"side\":\"BUY\", \"hash\":\"83617203175e9c2c1970327a0e262ea1f85fca3d\", \"best_bid\":\"0.59\", \"best_ask\":\"0.6\"}, {\"asset_id\":\"96283536366176669581486355171583722558858323126916278856549586825357358273536\", \"price\":\"0.49\", \"size\":\"20\", \"side\":\"SELL\", \"hash\":\"63bac1458a50ad7b235ec2cdd34e9d3a7add8eca\", \"best_bid\":\"0.4\", \"best_ask\":\"0.41\"}], \"timestamp\":\"1785121917700\", \"event_type\":\"price_change\"}","received_at":"2026-07-27T03:12:04.013011Z","schema_version":"clob-market-ws.price_change.v1","sequence":null,"server_hash":null,"server_timestamp":"1785121917700","session_id":"ff6d21c8283948938400a32613abec2c","source":"clob_market_ws"},"received_at":"2026-07-27T03:12:04.013011Z","record_id":"59e07fbcd1f0a41cd78696137bd33b0a1c6f593b8962f86b9f1164c217a3bbc9","schema_fingerprint":"4aa3821a28b0b7c2400bc59aba4bcc0a76e971dadd19610d3ad38c768e124dc7","schema_version":"edge-lab-recorder.raw.v1","sequence":null,"source":"clob_market_ws"}
{"event_at":"2026-07-27T03:11:57.705000Z","event_fingerprint":"05123e7925227735d610c09468ed1c9130474f6606548cc01d5d0f30ff6f7760","payload":{"connection_id":"f95883f18d264834af91809e5f803e9f","event_at":"2026-07-27T03:11:57.705000Z","event_type":"price_change","frame_hash":"4a5467db86d2e892e83a117eb89933001d23fe2ce7f489f0c17af3e25829e8ff","frame_index":0,"kind":"data","monotonic_ns":223907347140750,"payload":{"event_type":"price_change","market":"0xf9d60bb033695053c4d1d8592e52171c1042f64b41a4b72e09dcc6f4852b6670","price_changes":[{"asset_id":"8698449539441374295770236407991735029336433231649246775082939325523552031992","best_ask":"0.6","best_bid":"0.59","hash":"560496190505f24968134e96d6eb5a316f15a1fa","price":"0.01","side":"BUY","size":"8147.52"},{"asset_id":"96283536366176669581486355171583722558858323126916278856549586825357358273536","best_ask":"0.41","best_bid":"0.4","hash":"3b5bb5bf77c7e27f116ed7797b20b089d7c9d4ff","price":"0.99","side":"SELL","size":"8147.52"}],"timestamp":"1785121917705"},"payload_hash":"8be3d2ca34fe9029a92bea91b757135bd1d41410bbed1a7dae3ce8c5d14b3c4f","raw_frame":"{\"market\":\"0xf9d60bb033695053c4d1d8592e52171c1042f64b41a4b72e09dcc6f4852b6670\", \"price_changes\":[{\"asset_id\":\"8698449539441374295770236407991735029336433231649246775082939325523552031992\", \"price\":\"0.01\", \"size\":\"8147.52\", \"side\":\"BUY\", \"hash\":\"560496190505f24968134e96d6eb5a316f15a1fa\", \"best_bid\":\"0.59\", \"best_ask\":\"0.6\"}, {\"asset_id\":\"96283536366176669581486355171583722558858323126916278856549586825357358273536\", \"price\":\"0.99\", \"size\":\"8147.52\", \"side\":\"SELL\", \"hash\":\"3b5bb5bf77c7e27f116ed7797b20b089d7c9d4ff\", \"best_bid\":\"0.4\", \"best_ask\":\"0.41\"}], \"timestamp\":\"1785121917705\", \"event_type\":\"price_change\"}","received_at":"2026-07-27T03:12:04.015943Z","schema_version":"clob-market-ws.price_change.v1","sequence":null,"server_hash":null,"server_timestamp":"1785121917705","session_id":"ff6d21c8283948938400a32613abec2c","source":"clob_market_ws"},"received_at":"2026-07-27T03:12:04.015943Z","record_id":"7133ffb67186e560ec6b6f6304cdf6663ccd5318e61419446da0cfaa9e4fcd18","schema_fingerprint":"4aa3821a28b0b7c2400bc59aba4bcc0a76e971dadd19610d3ad38c768e124dc7","schema_version":"edge-lab-recorder.raw.v1","sequence":null,"source":"clob_market_ws"}
{"event_at":"2026-07-27T03:11:57.707000Z","event_fingerprint":"6782a815c569ded31a2c01bb2ff09364a7a0c84607b853bb8333e815558cc46f","payload":{"connection_id":"f95883f18d264834af91809e5f803e9f","event_at":"2026-07-27T03:11:57.707000Z","event_type":"price_change","frame_hash":"addf9d9f916087699b0d646c34bb367db17ed3fd1190b38bd9d5661e23bf40b7","frame_index":0,"kind":"data","monotonic_ns":223907348571666,"payload":{"event_type":"price_change","market":"0xf9d60bb033695053c4d1d8592e52171c1042f64b41a4b72e09dcc6f4852b6670","price_changes":[{"asset_id":"8698449539441374295770236407991735029336433231649246775082939325523552031992","best_ask":"0.6","best_bid":"0.59","hash":"7d742c8bc499fb446f9ac1f0c91a043ff3c093d4","price":"0.61","side":"SELL","size":"5"},{"asset_id":"96283536366176669581486355171583722558858323126916278856549586825357358273536","best_ask":"0.41","best_bid":"0.4","hash":"322287a257997278eaf993e9b29354e5a083fe4a","price":"0.39","side":"BUY","size":"5"}],"timestamp":"1785121917707"},"payload_hash":"ac61cea18cd183d854e9cdce2c2f727e5be4a1c77e6ee44a65635c0c8d8160dc","raw_frame":"{\"market\":\"0xf9d60bb033695053c4d1d8592e52171c1042f64b41a4b72e09dcc6f4852b6670\", \"price_changes\":[{\"asset_id\":\"8698449539441374295770236407991735029336433231649246775082939325523552031992\", \"price\":\"0.61\", \"size\":\"5\", \"side\":\"SELL\", \"hash\":\"7d742c8bc499fb446f9ac1f0c91a043ff3c093d4\", \"best_bid\":\"0.59\", \"best_ask\":\"0.6\"}, {\"asset_id\":\"96283536366176669581486355171583722558858323126916278856549586825357358273536\", \"price\":\"0.39\", \"size\":\"5\", \"side\":\"BUY\", \"hash\":\"322287a257997278eaf993e9b29354e5a083fe4a\", \"best_bid\":\"0.4\", \"best_ask\":\"0.41\"}], \"timestamp\":\"1785121917707\", \"event_type\":\"price_change\"}","received_at":"2026-07-27T03:12:04.017375Z","schema_version":"clob-market-ws.price_change.v1","sequence":null,"server_hash":null,"server_timestamp":"1785121917707","session_id":"ff6d21c8283948938400a32613abec2c","source":"clob_market_ws"},"received_at":"2026-07-27T03:12:04.017375Z","record_id":"76d96a29d47c96fa5bb844e65b2565375cb8b4b68c47c76e42817facab2bf5b6","schema_fingerprint":"4aa3821a28b0b7c2400bc59aba4bcc0a76e971dadd19610d3ad38c768e124dc7","schema_version":"edge-lab-recorder.raw.v1","sequence":null,"source":"clob_market_ws"}
{"event_at":"2026-07-27T03:11:57.708000Z","event_fingerprint":"9a6e43bd388a20d33d9ff5f1b56e91f125efd064388d2a4aec70816ada53304d","payload":{"connection_id":"f95883f18d264834af91809e5f803e9f","event_at":"2026-07-27T03:11:57.708000Z","event_type":"price_change","frame_hash":"5b54d1a3bcdf96ddd0b016d587074c76831a5151f1236b40204bf811f4169c7a","frame_index":0,"kind":"data","monotonic_ns":223907351519916,"payload":{"event_type":"price_change","market":"0xf9d60bb033695053c4d1d8592e52171c1042f64b41a4b72e09dcc6f4852b6670","price_changes":[{"asset_id":"96283536366176669581486355171583722558858323126916278856549586825357358273536","best_ask":"0.41","best_bid":"0.4","hash":"64237c6af77adc6a79491c38a58cbcab3212d6d6","price":"0.27","side":"BUY","size":"130.68"},{"asset_id":"8698449539441374295770236407991735029336433231649246775082939325523552031992","best_ask":"0.6","best_bid":"0.59","hash":"02fedfffae73130b81a2a12cc503065ec4932069","price":"0.73","side":"SELL","size":"130.68"}],"timestamp":"1785121917708"},"payload_hash":"f76912aa8cb2e29ff5b462f254f251fd700eaf9ca195b6ee298ff2f9db234aeb","raw_frame":"{\"market\":\"0xf9d60bb033695053c4d1d8592e52171c1042f64b41a4b72e09dcc6f4852b6670\", \"price_changes\":[{\"asset_id\":\"96283536366176669581486355171583722558858323126916278856549586825357358273536\", \"price\":\"0.27\", \"size\":\"130.68\", \"side\":\"BUY\", \"hash\":\"64237c6af77adc6a79491c38a58cbcab3212d6d6\", \"best_bid\":\"0.4\", \"best_ask\":\"0.41\"}, {\"asset_id\":\"8698449539441374295770236407991735029336433231649246775082939325523552031992\", \"price\":\"0.73\", \"size\":\"130.68\", \"side\":\"SELL\", \"hash\":\"02fedfffae73130b81a2a12cc503065ec4932069\", \"best_bid\":\"0.59\", \"best_ask\":\"0.6\"}], \"timestamp\":\"1785121917708\", \"event_type\":\"price_change\"}","received_at":"2026-07-27T03:12:04.020323Z","schema_version":"clob-market-ws.price_change.v1","sequence":null,"server_hash":null,"server_timestamp":"1785121917708","session_id":"ff6d21c8283948938400a32613abec2c","source":"clob_market_ws"},"received_at":"2026-07-27T03:12:04.020323Z","record_id":"6c1ea56a0824a60281140ab64698d9df3ba750d4c032357b05d4eef188e83448","schema_fingerprint":"4aa3821a28b0b7c2400bc59aba4bcc0a76e971dadd19610d3ad38c768e124dc7","schema_version":"edge-lab-recorder.raw.v1","sequence":null,"source":"clob_market_ws"}
{"event_at":"2026-07-27T03:11:57.709000Z","event_fingerprint":"6216701b987b46ab19f058c0115f4f9e40fb06ac72e291647365b8963db987ad","payload":{"connection_id":"f95883f18d264834af91809e5f803e9f","event_at":"2026-07-27T03:11:57.709000Z","event_type":"price_change","frame_hash":"640fc50500dfd75333c34406dcc5d5aaa09c3f768bc6f31922481517027195a0","frame_index":0,"kind":"data","monotonic_ns":223907354532500,"payload":{"event_type":"price_change","market":"0xf9d60bb033695053c4d1d8592e52171c1042f64b41a4b72e09dcc6f4852b6670","price_changes":[{"asset_id":"96283536366176669581486355171583722558858323126916278856549586825357358273536","best_ask":"0.41","best_bid":"0.4","hash":"f3571bd9a58e3179adaaf6912358334223d3584c","price":"0.29","side":"BUY","size":"95.79"},{"asset_id":"8698449539441374295770236407991735029336433231649246775082939325523552031992","best_ask":"0.6","best_bid":"0.59","hash":"2c86d102c6cf9acca0863bb4b5e3dd9e3bf26371","price":"0.71","side":"SELL","size":"95.79"}],"timestamp":"1785121917709"},"payload_hash":"d121aa838f4c1c528138c7351ca9411a4836de368f0323212974e6ad5a0eac74","raw_frame":"{\"market\":\"0xf9d60bb033695053c4d1d8592e52171c1042f64b41a4b72e09dcc6f4852b6670\", \"price_changes\":[{\"asset_id\":\"96283536366176669581486355171583722558858323126916278856549586825357358273536\", \"price\":\"0.29\", \"size\":\"95.79\", \"side\":\"BUY\", \"hash\":\"f3571bd9a58e3179adaaf6912358334223d3584c\", \"best_bid\":\"0.4\", \"best_ask\":\"0.41\"}, {\"asset_id\":\"8698449539441374295770236407991735029336433231649246775082939325523552031992\", \"price\":\"0.71\", \"size\":\"95.79\", \"side\":\"SELL\", \"hash\":\"2c86d102c6cf9acca0863bb4b5e3dd9e3bf26371\", \"best_bid\":\"0.59\", \"best_ask\":\"0.6\"}], \"timestamp\":\"1785121917709\", \"event_type\":\"price_change\"}","received_at":"2026-07-27T03:12:04.023336Z","schema_version":"clob-market-ws.price_change.v1","sequence":null,"server_hash":null,"server_timestamp":"1785121917709","session_id":"ff6d21c8283948938400a32613abec2c","source":"clob_market_ws"},"received_at":"2026-07-27T03:12:04.023336Z","record_id":"11247cb4cee6261dc1bd4d01193548ea7dd209c7eee2e45666e272d1ffb5c83b","schema_fingerprint":"4aa3821a28b0b7c2400bc59aba4bcc0a76e971dadd19610d3ad38c768e124dc7","schema_version":"edge-lab-recorder.raw.v1","sequence":null,"source":"clob_market_ws"}
{"event_at":"2026-07-27T03:11:57.709000Z","event_fingerprint":"2862770c5415828ebb76320133e10b8dc1fa20ab720aaeb13896d48d0b7b524d","payload":{"connection_id":"f95883f18d264834af91809e5f803e9f","event_at":"2026-07-27T03:11:57.709000Z","event_type":"price_change","frame_hash":"4be838c90981d9ba6a5f9e6fbbfde295a0ec5be258225152ac5aa40b0138c0ba","frame_index":0,"kind":"data","monotonic_ns":223907357441875,"payload":{"event_type":"price_change","market":"0xf9d60bb033695053c4d1d8592e52171c1042f64b41a4b72e09dcc6f4852b6670","price_changes":[{"asset_id":"96283536366176669581486355171583722558858323126916278856549586825357358273536","best_ask":"0.41","best_bid":"0.4","hash":"c75c00cdc3359b486b8d5e859a29c1718160511b","price":"0.28","side":"BUY","size":"103.14"},{"asset_id":"8698449539441374295770236407991735029336433231649246775082939325523552031992","best_ask":"0.6","best_bid":"0.59","hash":"43820ac4f8461cf5101199c94306b2213e84b071","price":"0.72","side":"SELL","size":"103.14"}],"timestamp":"1785121917709"},"payload_hash":"14da4ecaab465510676a961762b2cfc8d733f1620282ca39aeb8071c11400171","raw_frame":"{\"market\":\"0xf9d60bb033695053c4d1d8592e52171c1042f64b41a4b72e09dcc6f4852b6670\", \"price_changes\":[{\"asset_id\":\"96283536366176669581486355171583722558858323126916278856549586825357358273536\", \"price\":\"0.28\", \"size\":\"103.14\", \"side\":\"BUY\", \"hash\":\"c75c00cdc3359b486b8d5e859a29c1718160511b\", \"best_bid\":\"0.4\", \"best_ask\":\"0.41\"}, {\"asset_id\":\"8698449539441374295770236407991735029336433231649246775082939325523552031992\", \"price\":\"0.72\", \"size\":\"103.14\", \"side\":\"SELL\", \"hash\":\"43820ac4f8461cf5101199c94306b2213e84b071\", \"best_bid\":\"0.59\", \"best_ask\":\"0.6\"}], \"timestamp\":\"1785121917709\", \"event_type\":\"price_change\"}","received_at":"2026-07-27T03:12:04.026245Z","schema_version":"clob-market-ws.price_change.v1","sequence":null,"server_hash":null,"server_timestamp":"1785121917709","session_id":"ff6d21c8283948938400a32613abec2c","source":"clob_market_ws"},"received_at":"2026-07-27T03:12:04.026245Z","record_id":"eb72d08e22b4b003feafb13b3606f4c78119a10f9c0fba1530b64266132e37b8","schema_fingerprint":"4aa3821a28b0b7c2400bc59aba4bcc0a76e971dadd19610d3ad38c768e124dc7","schema_version":"edge-lab-recorder.raw.v1","sequence":null,"source":"clob_market_ws"}
{"event_at":"2026-07-27T03:11:57.710000Z","event_fingerprint":"7f58736984f28f69ddc3277da77537b3fc6a33c02d71d220589922439e0505c5","payload":{"connection_id":"f95883f18d264834af91809e5f803e9f","event_at":"2026-07-27T03:11:57.710000Z","event_type":"price_change","frame_hash":"1b866eb96e242abfd2149f135275441312a14bfbb631233a4c1dedc4a0f04855","frame_index":0,"kind":"data","monotonic_ns":223907360364875,"payload":{"event_type":"price_change","market":"0xf9d60bb033695053c4d1d8592e52171c1042f64b41a4b72e09dcc6f4852b6670","price_changes":[{"asset_id":"8698449539441374295770236407991735029336433231649246775082939325523552031992","best_ask":"0.6","best_bid":"0.59","hash":"4019077f1f7dfa69499358fd995b6e0daaf2d468","price":"0.42","side":"BUY","size":"86.42"},{"asset_id":"96283536366176669581486355171583722558858323126916278856549586825357358273536","best_ask":"0.41","best_bid":"0.4","hash":"c7214864eac78bcf4e82d1b2b44f8940ef475773","price":"0.58","side":"SELL","size":"86.42"}],"timestamp":"1785121917710"},"payload_hash":"ac832ad44950c1b5a73ff176ad7124b3b96566caa338ac2150043ee591f16cde","raw_frame":"{\"market\":\"0xf9d60bb033695053c4d1d8592e52171c1042f64b41a4b72e09dcc6f4852b6670\", \"price_changes\":[{\"asset_id\":\"8698449539441374295770236407991735029336433231649246775082939325523552031992\", \"price\":\"0.42\", \"size\":\"86.42\", \"side\":\"BUY\", \"hash\":\"4019077f1f7dfa69499358fd995b6e0daaf2d468\", \"best_bid\":\"0.59\", \"best_ask\":\"0.6\"}, {\"asset_id\":\"96283536366176669581486355171583722558858323126916278856549586825357358273536\", \"price\":\"0.58\", \"size\":\"86.42\", \"side\":\"SELL\", \"hash\":\"c7214864eac78bcf4e82d1b2b44f8940ef475773\", \"best_bid\":\"0.4\", \"best_ask\":\"0.41\"}], \"timestamp\":\"1785121917710\", \"event_type\":\"price_change\"}","received_at":"2026-07-27T03:12:04.029164Z","schema_version":"clob-market-ws.price_change.v1","sequence":null,"server_hash":null,"server_timestamp":"1785121917710","session_id":"ff6d21c8283948938400a32613abec2c","source":"clob_market_ws"},"received_at":"2026-07-27T03:12:04.029164Z","record_id":"f805501c6788492f17fa231f28419dd3df9b4b6dafc1c61bf8c38fef3053d3a3","schema_fingerprint":"4aa3821a28b0b7c2400bc59aba4bcc0a76e971dadd19610d3ad38c768e124dc7","schema_version":"edge-lab-recorder.raw.v1","sequence":null,"source":"clob_market_ws"}
{"event_at":"2026-07-27T03:11:57.712000Z","event_fingerprint":"b0a91a6419b4b9c8bd9aca75da38cca45b736074b2b23e81f95c8381597479b8","payload":{"connection_id":"f95883f18d264834af91809e5f803e9f","event_at":"2026-07-27T03:11:57.712000Z","event_type":"price_change","frame_hash":"21bfb8e8b36c34fba4a7bbab649abb3a6bea6f8fedf56ce084eefa20525ba5c0","frame_index":0,"kind":"data","monotonic_ns":223907363481666,"payload":{"event_type":"price_change","market":"0xf9d60bb033695053c4d1d8592e52171c1042f64b41a4b72e09dcc6f4852b6670","price_changes":[{"asset_id":"96283536366176669581486355171583722558858323126916278856549586825357358273536","best_ask":"0.41","best_bid":"0.4","hash":"ff8a234e185729f095146b00cb43d8717c2ff169","price":"0.3","side":"BUY","size":"149.71"},{"asset_id":"8698449539441374295770236407991735029336433231649246775082939325523552031992","best_ask":"0.6","best_bid":"0.59","hash":"7905522272dc6e581625097bbade51c009a1b3ad","price":"0.7","side":"SELL","size":"149.71"}],"timestamp":"1785121917712"},"payload_hash":"f0676a31f58b68803718da842824135f34ab0f05ec715cb1a48b0c819b9f3eb3","raw_frame":"{\"market\":\"0xf9d60bb033695053c4d1d8592e52171c1042f64b41a4b72e09dcc6f4852b6670\", \"price_changes\":[{\"asset_id\":\"96283536366176669581486355171583722558858323126916278856549586825357358273536\", \"price\":\"0.3\", \"size\":\"149.71\", \"side\":\"BUY\", \"hash\":\"ff8a234e185729f095146b00cb43d8717c2ff169\", \"best_bid\":\"0.4\", \"best_ask\":\"0.41\"}, {\"asset_id\":\"8698449539441374295770236407991735029336433231649246775082939325523552031992\", \"price\":\"0.7\", \"size\":\"149.71\", \"side\":\"SELL\", \"hash\":\"7905522272dc6e581625097bbade51c009a1b3ad\", \"best_bid\":\"0.59\", \"best_ask\":\"0.6\"}], \"timestamp\":\"1785121917712\", \"event_type\":\"price_change\"}","received_at":"2026-07-27T03:12:04.032285Z","schema_version":"clob-market-ws.price_change.v1","sequence":null,"server_hash":null,"server_timestamp":"1785121917712","session_id":"ff6d21c8283948938400a32613abec2c","source":"clob_market_ws"},"received_at":"2026-07-27T03:12:04.032285Z","record_id":"9c5b5a19e5e8b4721cc5cc8295f6f50f11c4df03010c194a57211e6413cf9f65","schema_fingerprint":"4aa3821a28b0b7c2400bc59aba4bcc0a76e971dadd19610d3ad38c768e124dc7","schema_version":"edge-lab-recorder.raw.v1","sequence":null,"source":"clob_market_ws"}
{"event_at":"2026-07-27T03:11:57.713000Z","event_fingerprint":"472d52c0df1dab759b606a218b79af21f520535642ad34c2af5392dfcc448362","payload":{"connection_id":"f95883f18d264834af91809e5f803e9f","event_at":"2026-07-27T03:11:57.713000Z","event_type":"price_change","frame_hash":"c89a7d6d37f80941c31c3e531c5076d3cd0bae16f27533afc2247b3599afe9c1","frame_index":0,"kind":"data","monotonic_ns":223907365530250,"payload":{"event_type":"price_change","market":"0xf9d60bb033695053c4d1d8592e52171c1042f64b41a4b72e09dcc6f4852b6670","price_changes":[{"asset_id":"8698449539441374295770236407991735029336433231649246775082939325523552031992","best_ask":"0.6","best_bid":"0.59","hash":"1f7bd109aec6227f9e7266a0f470dba6a189ab1a","price":"0.42","side":"BUY","size":"74.42"},{"asset_id":"96283536366176669581486355171583722558858323126916278856549586825357358273536","best_ask":"0.41","best_bid":"0.4","hash":"98c06fafa2c26c8c78cf8af9be018b431bb66406","price":"0.58","side":"SELL","size":"74.42"}],"timestamp":"1785121917713"},"payload_hash":"d4a5216d7b81064ca356adc78d82539acd730f874e21877145d964b4ca716c6a","raw_frame":"{\"market\":\"0xf9d60bb033695053c4d1d8592e52171c1042f64b41a4b72e09dcc6f4852b6670\", \"price_changes\":[{\"asset_id\":\"8698449539441374295770236407991735029336433231649246775082939325523552031992\", \"price\":\"0.42\", \"size\":\"74.42\", \"side\":\"BUY\", \"hash\":\"1f7bd109aec6227f9e7266a0f470dba6a189ab1a\", \"best_bid\":\"0.59\", \"best_ask\":\"0.6\"}, {\"asset_id\":\"96283536366176669581486355171583722558858323126916278856549586825357358273536\", \"price\":\"0.58\", \"size\":\"74.42\", \"side\":\"SELL\", \"hash\":\"98c06fafa2c26c8c78cf8af9be018b431bb66406\", \"best_bid\":\"0.4\", \"best_ask\":\"0.41\"}], \"timestamp\":\"1785121917713\", \"event_type\":\"price_change\"}","received_at":"2026-07-27T03:12:04.034333Z","schema_version":"clob-market-ws.price_change.v1","sequence":null,"server_hash":null,"server_timestamp":"1785121917713","session_id":"ff6d21c8283948938400a32613abec2c","source":"clob_market_ws"},"received_at":"2026-07-27T03:12:04.034333Z","record_id":"3d2219d683701ea96a8ee96e2b66db35c3f0a931694d22a0894cfcd4f29de15e","schema_fingerprint":"4aa3821a28b0b7c2400bc59aba4bcc0a76e971dadd19610d3ad38c768e124dc7","schema_version":"edge-lab-recorder.raw.v1","sequence":null,"source":"clob_market_ws"}
{"event_at":"2026-07-27T03:11:57.717000Z","event_fingerprint":"cca455e1a026627d7544fbd25a994b9c44f8fb3182fedc3bc982c389d28693c7","payload":{"connection_id":"f95883f18d264834af91809e5f803e9f","event_at":"2026-07-27T03:11:57.717000Z","event_type":"price_change","frame_hash":"82aed5c34bbc8be287ba68bd77fbd7c5f114e2892974a7e691f3458e1bae0453","frame_index":0,"kind":"data","monotonic_ns":223907369077416,"payload":{"event_type":"price_change","market":"0xf9d60bb033695053c4d1d8592e52171c1042f64b41a4b72e09dcc6f4852b6670","price_changes":[{"asset_id":"96283536366176669581486355171583722558858323126916278856549586825357358273536","best_ask":"0.41","best_bid":"0.4","hash":"65af5c188fc947cede72442d3e443b432c82bb4b","price":"0.4","side":"BUY","size":"9.58"},{"asset_id":"8698449539441374295770236407991735029336433231649246775082939325523552031992","best_ask":"0.6","best_bid":"0.59","hash":"a70f8184e944b7f4e4d757dcec157166d8bbb532","price":"0.6","side":"SELL","size":"9.58"}],"timestamp":"1785121917717"},"payload_hash":"8627e8a6b104499b590bb7311732d991cc5d1ec5090113a6f2006e33e6ffdb9b","raw_frame":"{\"market\":\"0xf9d60bb033695053c4d1d8592e52171c1042f64b41a4b72e09dcc6f4852b6670\", \"price_changes\":[{\"asset_id\":\"96283536366176669581486355171583722558858323126916278856549586825357358273536\", \"price\":\"0.4\", \"size\":\"9.58\", \"side\":\"BUY\", \"hash\":\"65af5c188fc947cede72442d3e443b432c82bb4b\", \"best_bid\":\"0.4\", \"best_ask\":\"0.41\"}, {\"asset_id\":\"8698449539441374295770236407991735029336433231649246775082939325523552031992\", \"price\":\"0.6\", \"size\":\"9.58\", \"side\":\"SELL\", \"hash\":\"a70f8184e944b7f4e4d757dcec157166d8bbb532\", \"best_bid\":\"0.59\", \"best_ask\":\"0.6\"}], \"timestamp\":\"1785121917717\", \"event_type\":\"price_change\"}","received_at":"2026-07-27T03:12:04.037879Z","schema_version":"clob-market-ws.price_change.v1","sequence":null,"server_hash":null,"server_timestamp":"1785121917717","session_id":"ff6d21c8283948938400a32613abec2c","source":"clob_market_ws"},"received_at":"2026-07-27T03:12:04.037879Z","record_id":"aa021fb8c25513135467b18d4a59841041eef3ce43076ad38a51a49bafa9b5c9","schema_fingerprint":"4aa3821a28b0b7c2400bc59aba4bcc0a76e971dadd19610d3ad38c768e124dc7","schema_version":"edge-lab-recorder.raw.v1","sequence":null,"source":"clob_market_ws"}
{"event_at":"2026-07-27T03:11:57.713000Z","event_fingerprint":"b3be5f71b003ee75542d5422cd00ec8394070c9c64c24d26bfa79ad2eed5d95b","payload":{"connection_id":"f95883f18d264834af91809e5f803e9f","event_at":"2026-07-27T03:11:57.713000Z","event_type":"last_trade_price","frame_hash":"7f3cb6cb385f68826fffa43d5df0fa72f8d71a10209684ce82968387ea9378a2","frame_index":0,"kind":"data","monotonic_ns":223907372008500,"payload":{"asset_id":"96283536366176669581486355171583722558858323126916278856549586825357358273536","event_type":"last_trade_price","fee_rate_bps":"0","market":"0xf9d60bb033695053c4d1d8592e52171c1042f64b41a4b72e09dcc6f4852b6670","price":"0.41","side":"SELL","size":"0.02","timestamp":"1785121917713","transaction_hash":"0x063e7dcd07ba68cc875663a30e65c816db4672c17a9202bba355a59a740f7dac"},"payload_hash":"72db7f8411073a47e4ca92950088def855cf1a8f4d563225fa1a776ef24e7ce9","raw_frame":"{\"market\":\"0xf9d60bb033695053c4d1d8592e52171c1042f64b41a4b72e09dcc6f4852b6670\", \"asset_id\":\"96283536366176669581486355171583722558858323126916278856549586825357358273536\", \"price\":\"0.41\", \"size\":\"0.02\", \"fee_rate_bps\":\"0\", \"side\":\"SELL\", \"timestamp\":\"1785121917713\", \"event_type\":\"last_trade_price\", \"transaction_hash\":\"0x063e7dcd07ba68cc875663a30e65c816db4672c17a9202bba355a59a740f7dac\"}","received_at":"2026-07-27T03:12:04.040812Z","schema_version":"clob-market-ws.last_trade_price.v1","sequence":null,"server_hash":null,"server_timestamp":"1785121917713","session_id":"ff6d21c8283948938400a32613abec2c","source":"clob_market_ws"},"received_at":"2026-07-27T03:12:04.040812Z","record_id":"278833d3e08e0e830088716097f7d5ac693eaecf156f1229be70eb3ed3ac2085","schema_fingerprint":"95ad9be75a4b695cd99991e12b2592bc7346f3f5388a82d0000ba65bc0d9fd0a","schema_version":"edge-lab-recorder.raw.v1","sequence":null,"source":"clob_market_ws"}
{"event_at":"2026-07-27T03:11:57.729000Z","event_fingerprint":"f12f301c0a379c2128b388c9b9ff72e8d9c67916863260335837036a81597ecb","payload":{"connection_id":"f95883f18d264834af91809e5f803e9f","event_at":"2026-07-27T03:11:57.729000Z","event_type":"price_change","frame_hash":"fe59b9f465a5b4fe95cea6ccd1370240256ef9cef8803c3f997885ab10489c36","frame_index":0,"kind":"data","monotonic_ns":223907374265791,"payload":{"event_type":"price_change","market":"0xf9d60bb033695053c4d1d8592e52171c1042f64b41a4b72e09dcc6f4852b6670","price_changes":[{"asset_id":"8698449539441374295770236407991735029336433231649246775082939325523552031992","best_ask":"0.6","best_bid":"0.59","hash":"5ab82ec4a5a3ba574d1d20c53b87233441733333","price":"0.58","side":"BUY","size":"55.54"},{"asset_id":"96283536366176669581486355171583722558858323126916278856549586825357358273536","best_ask":"0.41","best_bid":"0.4","hash":"05d53373aa4bfd7f457676d1b245bb430dafce9c","price":"0.42","side":"SELL","size":"55.54"}],"timestamp":"1785121917729"},"payload_hash":"21c7a95d0b4f917ff62c8a4e618960dd6332a58f339c9e995dfe3877937bae40","raw_frame":"{\"market\":\"0xf9d60bb033695053c4d1d8592e52171c1042f64b41a4b72e09dcc6f4852b6670\", \"price_changes\":[{\"asset_id\":\"8698449539441374295770236407991735029336433231649246775082939325523552031992\", \"price\":\"0.58\", \"size\":\"55.54\", \"side\":\"BUY\", \"hash\":\"5ab82ec4a5a3ba574d1d20c53b87233441733333\", \"best_bid\":\"0.59\", \"best_ask\":\"0.6\"}, {\"asset_id\":\"96283536366176669581486355171583722558858323126916278856549586825357358273536\", \"price\":\"0.42\", \"size\":\"55.54\", \"side\":\"SELL\", \"hash\":\"05d53373aa4bfd7f457676d1b245bb430dafce9c\", \"best_bid\":\"0.4\", \"best_ask\":\"0.41\"}], \"timestamp\":\"1785121917729\", \"event_type\":\"price_change\"}","received_at":"2026-07-27T03:12:04.043068Z","schema_version":"clob-market-ws.price_change.v1","sequence":null,"server_hash":null,"server_timestamp":"1785121917729","session_id":"ff6d21c8283948938400a32613abec2c","source":"clob_market_ws"},"received_at":"2026-07-27T03:12:04.043068Z","record_id":"54c1f8ae6d7e3b0a44a596d3f5eff955745481f7d1f65510d70b1a58c3d04750","schema_fingerprint":"4aa3821a28b0b7c2400bc59aba4bcc0a76e971dadd19610d3ad38c768e124dc7","schema_version":"edge-lab-recorder.raw.v1","sequence":null,"source":"clob_market_ws"}
{"event_at":"2026-07-27T03:11:57.732000Z","event_fingerprint":"9aafbd6f3e9d7d36d40b8c83960b1d764d392c95903b75826d356a4721027df1","payload":{"connection_id":"f95883f18d264834af91809e5f803e9f","event_at":"2026-07-27T03:11:57.732000Z","event_type":"price_change","frame_hash":"01ce5134f9f5069de97858c9141aca8df12c3e03ff89cab6a12f7cddd463f6aa","frame_index":0,"kind":"data","monotonic_ns":223907376764500,"payload":{"event_type":"price_change","market":"0xf9d60bb033695053c4d1d8592e52171c1042f64b41a4b72e09dcc6f4852b6670","price_changes":[{"asset_id":"8698449539441374295770236407991735029336433231649246775082939325523552031992","best_ask":"0.6","best_bid":"0.59","hash":"c43df37b65ab7471ce6daf4334d5d2bcc348c3a8","price":"0.02","side":"BUY","size":"1365.79"},{"asset_id":"96283536366176669581486355171583722558858323126916278856549586825357358273536","best_ask":"0.41","best_bid":"0.4","hash":"029e6261942d70e007cc7f38d1e1d45fb0bb5a41","price":"0.98","side":"SELL","size":"1365.79"}],"timestamp":"1785121917732"},"payload_hash":"15f46ead294ef20b5f5341ee582fe7a024e795dd30d5f68f3be31826da964305","raw_frame":"{\"market\":\"0xf9d60bb033695053c4d1d8592e52171c1042f64b41a4b72e09dcc6f4852b6670\", \"price_changes\":[{\"asset_id\":\"8698449539441374295770236407991735029336433231649246775082939325523552031992\", \"price\":\"0.02\", \"size\":\"1365.79\", \"side\":\"BUY\", \"hash\":\"c43df37b65ab7471ce6daf4334d5d2bcc348c3a8\", \"best_bid\":\"0.59\", \"best_ask\":\"0.6\"}, {\"asset_id\":\"96283536366176669581486355171583722558858323126916278856549586825357358273536\", \"price\":\"0.98\", \"size\":\"1365.79\", \"side\":\"SELL\", \"hash\":\"029e6261942d70e007cc7f38d1e1d45fb0bb5a41\", \"best_bid\":\"0.4\", \"best_ask\":\"0.41\"}], \"timestamp\":\"1785121917732\", \"event_type\":\"price_change\"}","received_at":"2026-07-27T03:12:04.045566Z","schema_version":"clob-market-ws.price_change.v1","sequence":null,"server_hash":null,"server_timestamp":"1785121917732","session_id":"ff6d21c8283948938400a32613abec2c","source":"clob_market_ws"},"received_at":"2026-07-27T03:12:04.045566Z","record_id":"87cdb2e4a7f9ed08599bc68d485c23f54b62ade556090e4bbccc0a8554f93ba1","schema_fingerprint":"4aa3821a28b0b7c2400bc59aba4bcc0a76e971dadd19610d3ad38c768e124dc7","schema_version":"edge-lab-recorder.raw.v1","sequence":null,"source":"clob_market_ws"}
{"event_at":"2026-07-27T03:11:57.736000Z","event_fingerprint":"40454d69487ebe7f995c2362cb41432e4865339a74a26a02bc39f640b9384235","payload":{"connection_id":"f95883f18d264834af91809e5f803e9f","event_at":"2026-07-27T03:11:57.736000Z","event_type":"price_change","frame_hash":"796a4084864096aaa1a6837fd2e6f4b48ac574cd14a8bb3f95e9c1de81094d7e","frame_index":0,"kind":"data","monotonic_ns":223907379726708,"payload":{"event_type":"price_change","market":"0xf9d60bb033695053c4d1d8592e52171c1042f64b41a4b72e09dcc6f4852b6670","price_changes":[{"asset_id":"96283536366176669581486355171583722558858323126916278856549586825357358273536","best_ask":"0.41","best_bid":"0.4","hash":"286c9829b9ecec3a9cc6f44467d68db52bbd2935","price":"0.39","side":"BUY","size":"10"},{"asset_id":"8698449539441374295770236407991735029336433231649246775082939325523552031992","best_ask":"0.6","best_bid":"0.59","hash":"221cf10837bab1f21b416181f2f7bb5fe5178a95","price":"0.61","side":"SELL","size":"10"}],"timestamp":"1785121917736"},"payload_hash":"69b4def30206dfbb89dcef669924ed47251cd739a81671c9c7ff180913969a65","raw_frame":"{\"market\":\"0xf9d60bb033695053c4d1d8592e52171c1042f64b41a4b72e09dcc6f4852b6670\", \"price_changes\":[{\"asset_id\":\"96283536366176669581486355171583722558858323126916278856549586825357358273536\", \"price\":\"0.39\", \"size\":\"10\", \"side\":\"BUY\", \"hash\":\"286c9829b9ecec3a9cc6f44467d68db52bbd2935\", \"best_bid\":\"0.4\", \"best_ask\":\"0.41\"}, {\"asset_id\":\"8698449539441374295770236407991735029336433231649246775082939325523552031992\", \"price\":\"0.61\", \"size\":\"10\", \"side\":\"SELL\", \"hash\":\"221cf10837bab1f21b416181f2f7bb5fe5178a95\", \"best_bid\":\"0.59\", \"best_ask\":\"0.6\"}], \"timestamp\":\"1785121917736\", \"event_type\":\"price_change\"}","received_at":"2026-07-27T03:12:04.048529Z","schema_version":"clob-market-ws.price_change.v1","sequence":null,"server_hash":null,"server_timestamp":"1785121917736","session_id":"ff6d21c8283948938400a32613abec2c","source":"clob_market_ws"},"received_at":"2026-07-27T03:12:04.048529Z","record_id":"31b63d0ae83bee83f934857a61465540801b8d5f80b1846361926cb5ed04a570","schema_fingerprint":"4aa3821a28b0b7c2400bc59aba4bcc0a76e971dadd19610d3ad38c768e124dc7","schema_version":"edge-lab-recorder.raw.v1","sequence":null,"source":"clob_market_ws"}
{"event_at":"2026-07-27T03:11:57.746000Z","event_fingerprint":"d7104a437ec13c95e416b949293eb92d02dff33b78ae387fc9f6bae07d94f627","payload":{"connection_id":"f95883f18d264834af91809e5f803e9f","event_at":"2026-07-27T03:11:57.746000Z","event_type":"price_change","frame_hash":"cd76110c965477765518b0f2daf74e68e98358528c3790c76f8e48289251d5b0","frame_index":0,"kind":"data","monotonic_ns":223907389255500,"payload":{"event_type":"price_change","market":"0xf9d60bb033695053c4d1d8592e52171c1042f64b41a4b72e09dcc6f4852b6670","price_changes":[{"asset_id":"96283536366176669581486355171583722558858323126916278856549586825357358273536","best_ask":"0.41","best_bid":"0.4","hash":"f1e72819e7c1c2fd89488ef41074ebe39c7ce117","price":"0.39","side":"BUY","size":"58.95"},{"asset_id":"8698449539441374295770236407991735029336433231649246775082939325523552031992","best_ask":"0.6","best_bid":"0.59","hash":"a0caede4522779790f7faa386d8e19cb9404581d","price":"0.61","side":"SELL","size":"58.95"}],"timestamp":"1785121917746"},"payload_hash":"8f368c6746ed79b59cf84dc02c2a8b971b83060a4fb1ab1f8246bca2d2855535","raw_frame":"{\"market\":\"0xf9d60bb033695053c4d1d8592e52171c1042f64b41a4b72e09dcc6f4852b6670\", \"price_changes\":[{\"asset_id\":\"96283536366176669581486355171583722558858323126916278856549586825357358273536\", \"price\":\"0.39\", \"size\":\"58.95\", \"side\":\"BUY\", \"hash\":\"f1e72819e7c1c2fd89488ef41074ebe39c7ce117\", \"best_bid\":\"0.4\", \"best_ask\":\"0.41\"}, {\"asset_id\":\"8698449539441374295770236407991735029336433231649246775082939325523552031992\", \"price\":\"0.61\", \"size\":\"58.95\", \"side\":\"SELL\", \"hash\":\"a0caede4522779790f7faa386d8e19cb9404581d\", \"best_bid\":\"0.59\", \"best_ask\":\"0.6\"}], \"timestamp\":\"1785121917746\", \"event_type\":\"price_change\"}","received_at":"2026-07-27T03:12:04.058055Z","schema_version":"clob-market-ws.price_change.v1","sequence":null,"server_hash":null,"server_timestamp":"1785121917746","session_id":"ff6d21c8283948938400a32613abec2c","source":"clob_market_ws"},"received_at":"2026-07-27T03:12:04.058055Z","record_id":"2bc1ace5014e55b10c665ad70aa97ec9dfdeaebe8f0b77ff6be5796f1c63804f","schema_fingerprint":"4aa3821a28b0b7c2400bc59aba4bcc0a76e971dadd19610d3ad38c768e124dc7","schema_version":"edge-lab-recorder.raw.v1","sequence":null,"source":"clob_market_ws"}
{"event_at":"2026-07-27T03:11:57.748000Z","event_fingerprint":"cd5e8dd5b835de3a39af197c8bffee473b533a59e42e4e7de485d7f4c126d012","payload":{"connection_id":"f95883f18d264834af91809e5f803e9f","event_at":"2026-07-27T03:11:57.748000Z","event_type":"price_change","frame_hash":"eb774305b5c04131f5729dd7b3b140d0e54360e1c47393ab45068a7c0bfd734a","frame_index":0,"kind":"data","monotonic_ns":223907395186125,"payload":{"event_type":"price_change","market":"0xf9d60bb033695053c4d1d8592e52171c1042f64b41a4b72e09dcc6f4852b6670","price_changes":[{"asset_id":"96283536366176669581486355171583722558858323126916278856549586825357358273536","best_ask":"0.41","best_bid":"0.4","hash":"78180171eb9f9a47c121850162e21a0efba5cf17","price":"0.4","side":"BUY","size":"57.34"},{"asset_id":"8698449539441374295770236407991735029336433231649246775082939325523552031992","best_ask":"0.6","best_bid":"0.59","hash":"3d86206de458a0662f63cbbd80606b4a5f4eaacd","price":"0.6","side":"SELL","size":"57.34"}],"timestamp":"1785121917748"},"payload_hash":"143b2be67073a0bc45e6b4e8200cf5f74f74ca02d802c1b4c2eee1a94260cd73","raw_frame":"{\"market\":\"0xf9d60bb033695053c4d1d8592e52171c1042f64b41a4b72e09dcc6f4852b6670\", \"price_changes\":[{\"asset_id\":\"96283536366176669581486355171583722558858323126916278856549586825357358273536\", \"price\":\"0.4\", \"size\":\"57.34\", \"side\":\"BUY\", \"hash\":\"78180171eb9f9a47c121850162e21a0efba5cf17\", \"best_bid\":\"0.4\", \"best_ask\":\"0.41\"}, {\"asset_id\":\"8698449539441374295770236407991735029336433231649246775082939325523552031992\", \"price\":\"0.6\", \"size\":\"57.34\", \"side\":\"SELL\", \"hash\":\"3d86206de458a0662f63cbbd80606b4a5f4eaacd\", \"best_bid\":\"0.59\", \"best_ask\":\"0.6\"}], \"timestamp\":\"1785121917748\", \"event_type\":\"price_change\"}","received_at":"2026-07-27T03:12:04.063985Z","schema_version":"clob-market-ws.price_change.v1","sequence":null,"server_hash":null,"server_timestamp":"1785121917748","session_id":"ff6d21c8283948938400a32613abec2c","source":"clob_market_ws"},"received_at":"2026-07-27T03:12:04.063985Z","record_id":"3303e8672a5b7c3fe639294d5983b40b4a69f9bf172e69d6c690531fa6d029a1","schema_fingerprint":"4aa3821a28b0b7c2400bc59aba4bcc0a76e971dadd19610d3ad38c768e124dc7","schema_version":"edge-lab-recorder.raw.v1","sequence":null,"source":"clob_market_ws"}
{"event_at":"2026-07-27T03:11:57.749000Z","event_fingerprint":"c32f0626b89a6a6d18dc8f95236685b80c692b5c44d9de9cd19aa277b2c70d0e","payload":{"connection_id":"f95883f18d264834af91809e5f803e9f","event_at":"2026-07-27T03:11:57.749000Z","event_type":"price_change","frame_hash":"7a92028794e86e4231e49ef2c66a2e907c60cfc0421ffad566b3cbedacc16f88","frame_index":0,"kind":"data","monotonic_ns":223907398228666,"payload":{"event_type":"price_change","market":"0xf9d60bb033695053c4d1d8592e52171c1042f64b41a4b72e09dcc6f4852b6670","price_changes":[{"asset_id":"96283536366176669581486355171583722558858323126916278856549586825357358273536","best_ask":"0.41","best_bid":"0.4","hash":"110aec8251793be895736a31fd8dd8eea3f5b3b4","price":"0.4","side":"BUY","size":"64.34"},{"asset_id":"8698449539441374295770236407991735029336433231649246775082939325523552031992","best_ask":"0.6","best_bid":"0.59","hash":"73940d6be4274dc369fe29ea857a38c1434128ce","price":"0.6","side":"SELL","size":"64.34"}],"timestamp":"1785121917749"},"payload_hash":"e3311b3ddc3cea97aed7a4607df0f724f4387889a34a256442254444437cc38a","raw_frame":"{\"market\":\"0xf9d60bb033695053c4d1d8592e52171c1042f64b41a4b72e09dcc6f4852b6670\", \"price_changes\":[{\"asset_id\":\"96283536366176669581486355171583722558858323126916278856549586825357358273536\", \"price\":\"0.4\", \"size\":\"64.34\", \"side\":\"BUY\", \"hash\":\"110aec8251793be895736a31fd8dd8eea3f5b3b4\", \"best_bid\":\"0.4\", \"best_ask\":\"0.41\"}, {\"asset_id\":\"8698449539441374295770236407991735029336433231649246775082939325523552031992\", \"price\":\"0.6\", \"size\":\"64.34\", \"side\":\"SELL\", \"hash\":\"73940d6be4274dc369fe29ea857a38c1434128ce\", \"best_bid\":\"0.59\", \"best_ask\":\"0.6\"}], \"timestamp\":\"1785121917749\", \"event_type\":\"price_change\"}","received_at":"2026-07-27T03:12:04.067032Z","schema_version":"clob-market-ws.price_change.v1","sequence":null,"server_hash":null,"server_timestamp":"1785121917749","session_id":"ff6d21c8283948938400a32613abec2c","source":"clob_market_ws"},"received_at":"2026-07-27T03:12:04.067032Z","record_id":"9cd8a051387dae8dd4e16b55cc0f4eaa480a454017fefbc65c0c61f84e39d178","schema_fingerprint":"4aa3821a28b0b7c2400bc59aba4bcc0a76e971dadd19610d3ad38c768e124dc7","schema_version":"edge-lab-recorder.raw.v1","sequence":null,"source":"clob_market_ws"}
{"event_at":"2026-07-27T03:11:57.750000Z","event_fingerprint":"e9e789c5d131c7867fc274b2ac1430729e17ba89038cde8156b712cc05703730","payload":{"connection_id":"f95883f18d264834af91809e5f803e9f","event_at":"2026-07-27T03:11:57.750000Z","event_type":"price_change","frame_hash":"c2b607bbeb9e5ec065e4a2c6b52a2f7098cec2bccc6c51ceba2381e48dd46d80","frame_index":0,"kind":"data","monotonic_ns":223907399556958,"payload":{"event_type":"price_change","market":"0xf9d60bb033695053c4d1d8592e52171c1042f64b41a4b72e09dcc6f4852b6670","price_changes":[{"asset_id":"96283536366176669581486355171583722558858323126916278856549586825357358273536","best_ask":"0.41","best_bid":"0.4","hash":"3c3d85c989c238b2d19b0eb289a53e3db5d9102b","price":"0.37","side":"BUY","size":"28.56"},{"asset_id":"8698449539441374295770236407991735029336433231649246775082939325523552031992","best_ask":"0.6","best_bid":"0.59","hash":"b01c7e2a72b26bbf0ae2bef87f67cbf70698440b","price":"0.63","side":"SELL","size":"28.56"}],"timestamp":"1785121917750"},"payload_hash":"ff99f0fc070e64a81ae2073ec358ddf4ff8d6dc47a83513f3794af6ffc230f1d","raw_frame":"{\"market\":\"0xf9d60bb033695053c4d1d8592e52171c1042f64b41a4b72e09dcc6f4852b6670\", \"price_changes\":[{\"asset_id\":\"96283536366176669581486355171583722558858323126916278856549586825357358273536\", \"price\":\"0.37\", \"size\":\"28.56\", \"side\":\"BUY\", \"hash\":\"3c3d85c989c238b2d19b0eb289a53e3db5d9102b\", \"best_bid\":\"0.4\", \"best_ask\":\"0.41\"}, {\"asset_id\":\"8698449539441374295770236407991735029336433231649246775082939325523552031992\", \"price\":\"0.63\", \"size\":\"28.56\", \"side\":\"SELL\", \"hash\":\"b01c7e2a72b26bbf0ae2bef87f67cbf70698440b\", \"best_bid\":\"0.59\", \"best_ask\":\"0.6\"}], \"timestamp\":\"1785121917750\", \"event_type\":\"price_change\"}","received_at":"2026-07-27T03:12:04.068364Z","schema_version":"clob-market-ws.price_change.v1","sequence":null,"server_hash":null,"server_timestamp":"1785121917750","session_id":"ff6d21c8283948938400a32613abec2c","source":"clob_market_ws"},"received_at":"2026-07-27T03:12:04.068364Z","record_id":"a6976dcefaf3c187e6c218eee49ba19767040ef9ee4ff4e5a22bb88495558a19","schema_fingerprint":"4aa3821a28b0b7c2400bc59aba4bcc0a76e971dadd19610d3ad38c768e124dc7","schema_version":"edge-lab-recorder.raw.v1","sequence":null,"source":"clob_market_ws"}
{"event_at":"2026-07-27T03:11:57.750000Z","event_fingerprint":"447cdeacaf5ddef57468521d51eeba59c643df19fb641af190647224bb3fc7d8","payload":{"connection_id":"f95883f18d264834af91809e5f803e9f","event_at":"2026-07-27T03:11:57.750000Z","event_type":"price_change","frame_hash":"f7059c0a5a613222d998788e157b7a22f6b1971bdac2760ba00da09720f4ce60","frame_index":0,"kind":"data","monotonic_ns":223907400959791,"payload":{"event_type":"price_change","market":"0xf9d60bb033695053c4d1d8592e52171c1042f64b41a4b72e09dcc6f4852b6670","price_changes":[{"asset_id":"8698449539441374295770236407991735029336433231649246775082939325523552031992","best_ask":"0.6","best_bid":"0.59","hash":"b01c7e2a72b26bbf0ae2bef87f67cbf70698440b","price":"0.58","side":"BUY","size":"40.54"},{"asset_id":"96283536366176669581486355171583722558858323126916278856549586825357358273536","best_ask":"0.41","best_bid":"0.4","hash":"3c3d85c989c238b2d19b0eb289a53e3db5d9102b","price":"0.42","side":"SELL","size":"40.54"}],"timestamp":"1785121917750"},"payload_hash":"0b669425724019420e40b273895b3b1ffb2735610bcd5ac2cd05174ee666c7cd","raw_frame":"{\"market\":\"0xf9d60bb033695053c4d1d8592e52171c1042f64b41a4b72e09dcc6f4852b6670\", \"price_changes\":[{\"asset_id\":\"8698449539441374295770236407991735029336433231649246775082939325523552031992\", \"price\":\"0.58\", \"size\":\"40.54\", \"side\":\"BUY\", \"hash\":\"b01c7e2a72b26bbf0ae2bef87f67cbf70698440b\", \"best_bid\":\"0.59\", \"best_ask\":\"0.6\"}, {\"asset_id\":\"96283536366176669581486355171583722558858323126916278856549586825357358273536\", \"price\":\"0.42\", \"size\":\"40.54\", \"side\":\"SELL\", \"hash\":\"3c3d85c989c238b2d19b0eb289a53e3db5d9102b\", \"best_bid\":\"0.4\", \"best_ask\":\"0.41\"}], \"timestamp\":\"1785121917750\", \"event_type\":\"price_change\"}","received_at":"2026-07-27T03:12:04.069767Z","schema_version":"clob-market-ws.price_change.v1","sequence":null,"server_hash":null,"server_timestamp":"1785121917750","session_id":"ff6d21c8283948938400a32613abec2c","source":"clob_market_ws"},"received_at":"2026-07-27T03:12:04.069767Z","record_id":"fe29d81ae42427daf7fc68311f2fd747fac38b46e170d7b37dcbffa95aa5c6ba","schema_fingerprint":"4aa3821a28b0b7c2400bc59aba4bcc0a76e971dadd19610d3ad38c768e124dc7","schema_version":"edge-lab-recorder.raw.v1","sequence":null,"source":"clob_market_ws"}
{"event_at":"2026-07-27T03:11:57.750000Z","event_fingerprint":"205762f148fd036f266b4d2d06bb015072aef9c150ad25621d4c9765814799f9","payload":{"connection_id":"f95883f18d264834af91809e5f803e9f","event_at":"2026-07-27T03:11:57.750000Z","event_type":"price_change","frame_hash":"5b2fc9920b64978c6e04fff73dd02aeb74e744453094319761890ad62b4fb71d","frame_index":0,"kind":"data","monotonic_ns":223907402177666,"payload":{"event_type":"price_change","market":"0xf9d60bb033695053c4d1d8592e52171c1042f64b41a4b72e09dcc6f4852b6670","price_changes":[{"asset_id":"96283536366176669581486355171583722558858323126916278856549586825357358273536","best_ask":"0.41","best_bid":"0.4","hash":"3c3d85c989c238b2d19b0eb289a53e3db5d9102b","price":"0.28","side":"BUY","size":"98.14"},{"asset_id":"8698449539441374295770236407991735029336433231649246775082939325523552031992","best_ask":"0.6","best_bid":"0.59","hash":"b01c7e2a72b26bbf0ae2bef87f67cbf70698440b","price":"0.72","side":"SELL","size":"98.14"}],"timestamp":"1785121917750"},"payload_hash":"2fb5b456da73ea74a8dd24d9cfe4c2709a9e4ab9f32dfd78d3a93a27198b8b66","raw_frame":"{\"market\":\"0xf9d60bb033695053c4d1d8592e52171c1042f64b41a4b72e09dcc6f4852b6670\", \"price_changes\":[{\"asset_id\":\"96283536366176669581486355171583722558858323126916278856549586825357358273536\", \"price\":\"0.28\", \"size\":\"98.14\", \"side\":\"BUY\", \"hash\":\"3c3d85c989c238b2d19b0eb289a53e3db5d9102b\", \"best_bid\":\"0.4\", \"best_ask\":\"0.41\"}, {\"asset_id\":\"8698449539441374295770236407991735029336433231649246775082939325523552031992\", \"price\":\"0.72\", \"size\":\"98.14\", \"side\":\"SELL\", \"hash\":\"b01c7e2a72b26bbf0ae2bef87f67cbf70698440b\", \"best_bid\":\"0.59\", \"best_ask\":\"0.6\"}], \"timestamp\":\"1785121917750\", \"event_type\":\"price_change\"}","received_at":"2026-07-27T03:12:04.070986Z","schema_version":"clob-market-ws.price_change.v1","sequence":null,"server_hash":null,"server_timestamp":"1785121917750","session_id":"ff6d21c8283948938400a32613abec2c","source":"clob_market_ws"},"received_at":"2026-07-27T03:12:04.070986Z","record_id":"a08a7f4e3ed7407eb743218558a70ee8a7500f0bffba620e2ae0c32e567ba6e8","schema_fingerprint":"4aa3821a28b0b7c2400bc59aba4bcc0a76e971dadd19610d3ad38c768e124dc7","schema_version":"edge-lab-recorder.raw.v1","sequence":null,"source":"clob_market_ws"}
{"event_at":"2026-07-27T03:11:57.756000Z","event_fingerprint":"34c6aff58e1d3c22862d575bcd2bc10261b4727b47bb1a10f97e9af2383073c1","payload":{"connection_id":"f95883f18d264834af91809e5f803e9f","event_at":"2026-07-27T03:11:57.756000Z","event_type":"price_change","frame_hash":"2987f2d8496ef0a575991c0ab778a9b601e4cd4accfd3d2806c9dcfb193e5d7a","frame_index":0,"kind":"data","monotonic_ns":223907403454125,"payload":{"event_type":"price_change","market":"0xf9d60bb033695053c4d1d8592e52171c1042f64b41a4b72e09dcc6f4852b6670","price_changes":[{"asset_id":"8698449539441374295770236407991735029336433231649246775082939325523552031992","best_ask":"0.6","best_bid":"0.59","hash":"e849678801c5b3a89c82b9a9b37e4594823a2b3c","price":"0.58","side":"BUY","size":"30.54"},{"asset_id":"96283536366176669581486355171583722558858323126916278856549586825357358273536","best_ask":"0.41","best_bid":"0.4","hash":"8710f3927571e925c9a8fca7dd474bb22657d1cf","price":"0.42","side":"SELL","size":"30.54"}],"timestamp":"1785121917756"},"payload_hash":"cdcb4b65ea55bb2e3365c6a8dd048f27400a24c50f536b9f6c869f688cdbe94c","raw_frame":"{\"market\":\"0xf9d60bb033695053c4d1d8592e52171c1042f64b41a4b72e09dcc6f4852b6670\", \"price_changes\":[{\"asset_id\":\"8698449539441374295770236407991735029336433231649246775082939325523552031992\", \"price\":\"0.58\", \"size\":\"30.54\", \"side\":\"BUY\", \"hash\":\"e849678801c5b3a89c82b9a9b37e4594823a2b3c\", \"best_bid\":\"0.59\", \"best_ask\":\"0.6\"}, {\"asset_id\":\"96283536366176669581486355171583722558858323126916278856549586825357358273536\", \"price\":\"0.42\", \"size\":\"30.54\", \"side\":\"SELL\", \"hash\":\"8710f3927571e925c9a8fca7dd474bb22657d1cf\", \"best_bid\":\"0.4\", \"best_ask\":\"0.41\"}], \"timestamp\":\"1785121917756\", \"event_type\":\"price_change\"}","received_at":"2026-07-27T03:12:04.072262Z","schema_version":"clob-market-ws.price_change.v1","sequence":null,"server_hash":null,"server_timestamp":"1785121917756","session_id":"ff6d21c8283948938400a32613abec2c","source":"clob_market_ws"},"received_at":"2026-07-27T03:12:04.072262Z","record_id":"5891798f010d700f2273c358b380f8aef8e387dc53a8797216b3e195c5384dd1","schema_fingerprint":"4aa3821a28b0b7c2400bc59aba4bcc0a76e971dadd19610d3ad38c768e124dc7","schema_version":"edge-lab-recorder.raw.v1","sequence":null,"source":"clob_market_ws"}
{"event_at":"2026-07-27T03:11:57.756000Z","event_fingerprint":"41907384fd5b7e505e95c8b9d8ce902d049e0fa05e350e2b3ef2c6a7d04ec1e1","payload":{"connection_id":"f95883f18d264834af91809e5f803e9f","event_at":"2026-07-27T03:11:57.756000Z","event_type":"price_change","frame_hash":"92c2797d46d6f5786cd78aac88023a98048389909e6d1a5350cdab9ca75abc23","frame_index":0,"kind":"data","monotonic_ns":223907405030541,"payload":{"event_type":"price_change","market":"0xf9d60bb033695053c4d1d8592e52171c1042f64b41a4b72e09dcc6f4852b6670","price_changes":[{"asset_id":"96283536366176669581486355171583722558858323126916278856549586825357358273536","best_ask":"0.41","best_bid":"0.4","hash":"d7e1df3c0bddd3f1a9df331b0dc62f66cc75cba6","price":"0.29","side":"BUY","size":"85.79"},{"asset_id":"8698449539441374295770236407991735029336433231649246775082939325523552031992","best_ask":"0.6","best_bid":"0.59","hash":"44a84c579c156250d122129ad6523da00db1a00b","price":"0.71","side":"SELL","size":"85.79"}],"timestamp":"1785121917756"},"payload_hash":"5064ca468d93811032e5cab4df3ac8fb623eec9c51da7d1d2edbf18369c56013","raw_frame":"{\"market\":\"0xf9d60bb033695053c4d1d8592e52171c1042f64b41a4b72e09dcc6f4852b6670\", \"price_changes\":[{\"asset_id\":\"96283536366176669581486355171583722558858323126916278856549586825357358273536\", \"price\":\"0.29\", \"size\":\"85.79\", \"side\":\"BUY\", \"hash\":\"d7e1df3c0bddd3f1a9df331b0dc62f66cc75cba6\", \"best_bid\":\"0.4\", \"best_ask\":\"0.41\"}, {\"asset_id\":\"8698449539441374295770236407991735029336433231649246775082939325523552031992\", \"price\":\"0.71\", \"size\":\"85.79\", \"side\":\"SELL\", \"hash\":\"44a84c579c156250d122129ad6523da00db1a00b\", \"best_bid\":\"0.59\", \"best_ask\":\"0.6\"}], \"timestamp\":\"1785121917756\", \"event_type\":\"price_change\"}","received_at":"2026-07-27T03:12:04.073838Z","schema_version":"clob-market-ws.price_change.v1","sequence":null,"server_hash":null,"server_timestamp":"1785121917756","session_id":"ff6d21c8283948938400a32613abec2c","source":"clob_market_ws"},"received_at":"2026-07-27T03:12:04.073838Z","record_id":"1d65cf0c043ae21f1958bd7d041a7edd655ea62906eba1dee51304ac16dfd31f","schema_fingerprint":"4aa3821a28b0b7c2400bc59aba4bcc0a76e971dadd19610d3ad38c768e124dc7","schema_version":"edge-lab-recorder.raw.v1","sequence":null,"source":"clob_market_ws"}
{"event_at":"2026-07-27T03:11:57.756000Z","event_fingerprint":"e4b39e6561accc5ea899d0854e42def362aa6233a5abed529c7b434a64f47bce","payload":{"connection_id":"f95883f18d264834af91809e5f803e9f","event_at":"2026-07-27T03:11:57.756000Z","event_type":"price_change","frame_hash":"22bb5f8031252c432700126031452a1b46b04771d43491b81388a65c2ffc4509","frame_index":0,"kind":"data","monotonic_ns":223907406922333,"payload":{"event_type":"price_change","market":"0xf9d60bb033695053c4d1d8592e52171c1042f64b41a4b72e09dcc6f4852b6670","price_changes":[{"asset_id":"96283536366176669581486355171583722558858323126916278856549586825357358273536","best_ask":"0.41","best_bid":"0.4","hash":"2f4edcc59598ab580e09994c0f90eb913390b5e3","price":"0.27","side":"BUY","size":"120.68"},{"asset_id":"8698449539441374295770236407991735029336433231649246775082939325523552031992","best_ask":"0.6","best_bid":"0.59","hash":"cbeb36dff7f89d9c6fb682f20910fea441d66818","price":"0.73","side":"SELL","size":"120.68"}],"timestamp":"1785121917756"},"payload_hash":"ad179b49127b7662c9a8ef4ffdcebba3f855ba00d8bca36699025d74135022c2","raw_frame":"{\"market\":\"0xf9d60bb033695053c4d1d8592e52171c1042f64b41a4b72e09dcc6f4852b6670\", \"price_changes\":[{\"asset_id\":\"96283536366176669581486355171583722558858323126916278856549586825357358273536\", \"price\":\"0.27\", \"size\":\"120.68\", \"side\":\"BUY\", \"hash\":\"2f4edcc59598ab580e09994c0f90eb913390b5e3\", \"best_bid\":\"0.4\", \"best_ask\":\"0.41\"}, {\"asset_id\":\"8698449539441374295770236407991735029336433231649246775082939325523552031992\", \"price\":\"0.73\", \"size\":\"120.68\", \"side\":\"SELL\", \"hash\":\"cbeb36dff7f89d9c6fb682f20910fea441d66818\", \"best_bid\":\"0.59\", \"best_ask\":\"0.6\"}], \"timestamp\":\"1785121917756\", \"event_type\":\"price_change\"}","received_at":"2026-07-27T03:12:04.075725Z","schema_version":"clob-market-ws.price_change.v1","sequence":null,"server_hash":null,"server_timestamp":"1785121917756","session_id":"ff6d21c8283948938400a32613abec2c","source":"clob_market_ws"},"received_at":"2026-07-27T03:12:04.075725Z","record_id":"f0b9551bf43e19b309fb6318c64faf268f7c40667aeddc4d0fe415d13da2a69b","schema_fingerprint":"4aa3821a28b0b7c2400bc59aba4bcc0a76e971dadd19610d3ad38c768e124dc7","schema_version":"edge-lab-recorder.raw.v1","sequence":null,"source":"clob_market_ws"}
{"event_at":"2026-07-27T03:11:57.757000Z","event_fingerprint":"ee9ef761b867c0c870f38545a809883300fe83020779191c5daf49114e1f7725","payload":{"connection_id":"f95883f18d264834af91809e5f803e9f","event_at":"2026-07-27T03:11:57.757000Z","event_type":"price_change","frame_hash":"1be2450b6c058b194f540e1c7d91d51d08a5342885958c187a9c863568dc6a8c","frame_index":0,"kind":"data","monotonic_ns":223907408571208,"payload":{"event_type":"price_change","market":"0xf9d60bb033695053c4d1d8592e52171c1042f64b41a4b72e09dcc6f4852b6670","price_changes":[{"asset_id":"96283536366176669581486355171583722558858323126916278856549586825357358273536","best_ask":"0.41","best_bid":"0.4","hash":"5ae26186ee38baf2176c6b3b00d847725ced564e","price":"0.28","side":"BUY","size":"88.14"},{"asset_id":"8698449539441374295770236407991735029336433231649246775082939325523552031992","best_ask":"0.6","best_bid":"0.59","hash":"e507c3d96a2a37a3d109629b532e156b958225c5","price":"0.72","side":"SELL","size":"88.14"}],"timestamp":"1785121917757"},"payload_hash":"db0f96b1a845387b4ca0925298d52fa36d9826e6a957ab0b4f3c2e6007fbd05c","raw_frame":"{\"market\":\"0xf9d60bb033695053c4d1d8592e52171c1042f64b41a4b72e09dcc6f4852b6670\", \"price_changes\":[{\"asset_id\":\"96283536366176669581486355171583722558858323126916278856549586825357358273536\", \"price\":\"0.28\", \"size\":\"88.14\", \"side\":\"BUY\", \"hash\":\"5ae26186ee38baf2176c6b3b00d847725ced564e\", \"best_bid\":\"0.4\", \"best_ask\":\"0.41\"}, {\"asset_id\":\"8698449539441374295770236407991735029336433231649246775082939325523552031992\", \"price\":\"0.72\", \"size\":\"88.14\", \"side\":\"SELL\", \"hash\":\"e507c3d96a2a37a3d109629b532e156b958225c5\", \"best_bid\":\"0.59\", \"best_ask\":\"0.6\"}], \"timestamp\":\"1785121917757\", \"event_type\":\"price_change\"}","received_at":"2026-07-27T03:12:04.077375Z","schema_version":"clob-market-ws.price_change.v1","sequence":null,"server_hash":null,"server_timestamp":"1785121917757","session_id":"ff6d21c8283948938400a32613abec2c","source":"clob_market_ws"},"received_at":"2026-07-27T03:12:04.077375Z","record_id":"53d94d6944e2f0c25b85660e435ff18e7e3e10d97579e585b4ce6515337dee9b","schema_fingerprint":"4aa3821a28b0b7c2400bc59aba4bcc0a76e971dadd19610d3ad38c768e124dc7","schema_version":"edge-lab-recorder.raw.v1","sequence":null,"source":"clob_market_ws"}
{"event_at":"2026-07-27T03:11:57.757000Z","event_fingerprint":"fc6747fcef3e3207a263dee9c45ec9f06a9e186c71d5dabbd5f8eb8f0d34891d","payload":{"connection_id":"f95883f18d264834af91809e5f803e9f","event_at":"2026-07-27T03:11:57.757000Z","event_type":"price_change","frame_hash":"b10b3c4b9a6f2847ce0e48034ff15aaad093bd5e5917c0a0fa6e1efaf5e5b87a","frame_index":0,"kind":"data","monotonic_ns":223907410584375,"payload":{"event_type":"price_change","market":"0xf9d60bb033695053c4d1d8592e52171c1042f64b41a4b72e09dcc6f4852b6670","price_changes":[{"asset_id":"96283536366176669581486355171583722558858323126916278856549586825357358273536","best_ask":"0.41","best_bid":"0.4","hash":"29a6120719a277ec30c5ec105b1e5b88aaddc0cd","price":"0.3","side":"BUY","size":"139.71"},{"asset_id":"8698449539441374295770236407991735029336433231649246775082939325523552031992","best_ask":"0.6","best_bid":"0.59","hash":"afcd44bde9f73dd64be6526deb260e19b0ce14d5","price":"0.7","side":"SELL","size":"139.71"}],"timestamp":"1785121917757"},"payload_hash":"1c4fd1cf1859a4acd668b4b8861d46b9c814ebb7196ab839357e5ac5dada94d0","raw_frame":"{\"market\":\"0xf9d60bb033695053c4d1d8592e52171c1042f64b41a4b72e09dcc6f4852b6670\", \"price_changes\":[{\"asset_id\":\"96283536366176669581486355171583722558858323126916278856549586825357358273536\", \"price\":\"0.3\", \"size\":\"139.71\", \"side\":\"BUY\", \"hash\":\"29a6120719a277ec30c5ec105b1e5b88aaddc0cd\", \"best_bid\":\"0.4\", \"best_ask\":\"0.41\"}, {\"asset_id\":\"8698449539441374295770236407991735029336433231649246775082939325523552031992\", \"price\":\"0.7\", \"size\":\"139.71\", \"side\":\"SELL\", \"hash\":\"afcd44bde9f73dd64be6526deb260e19b0ce14d5\", \"best_bid\":\"0.59\", \"best_ask\":\"0.6\"}], \"timestamp\":\"1785121917757\", \"event_type\":\"price_change\"}","received_at":"2026-07-27T03:12:04.079391Z","schema_version":"clob-market-ws.price_change.v1","sequence":null,"server_hash":null,"server_timestamp":"1785121917757","session_id":"ff6d21c8283948938400a32613abec2c","source":"clob_market_ws"},"received_at":"2026-07-27T03:12:04.079391Z","record_id":"1f4b042dce4abf866cded4fc7698caf30c637587e7fe250e15afd9f24def2f55","schema_fingerprint":"4aa3821a28b0b7c2400bc59aba4bcc0a76e971dadd19610d3ad38c768e124dc7","schema_version":"edge-lab-recorder.raw.v1","sequence":null,"source":"clob_market_ws"}
{"event_at":"2026-07-27T03:11:57.754000Z","event_fingerprint":"2614ea904f47499e02b56189a6e5f57644a880650a175c9900db50b472a3b7de","payload":{"connection_id":"f95883f18d264834af91809e5f803e9f","event_at":"2026-07-27T03:11:57.754000Z","event_type":"last_trade_price","frame_hash":"91aa10acc3940cfb17c463b5561fffa72d5d67c9d11c2037d440b33386c5fa1d","frame_index":0,"kind":"data","monotonic_ns":223907411899625,"payload":{"asset_id":"8698449539441374295770236407991735029336433231649246775082939325523552031992","event_type":"last_trade_price","fee_rate_bps":"0","market":"0xf9d60bb033695053c4d1d8592e52171c1042f64b41a4b72e09dcc6f4852b6670","price":"0.59","side":"BUY","size":"2.060832","timestamp":"1785121917754","transaction_hash":"0x72a31ff093beb2d00950539903c4b49aec0748eb235118bf8f19d9a89d9ad89a"},"payload_hash":"6d38a178a4725de8a0aa0546b54c5f42c31a2ecb0e331de9a4201e34669da304","raw_frame":"{\"market\":\"0xf9d60bb033695053c4d1d8592e52171c1042f64b41a4b72e09dcc6f4852b6670\", \"asset_id\":\"8698449539441374295770236407991735029336433231649246775082939325523552031992\", \"price\":\"0.59\", \"size\":\"2.060832\", \"fee_rate_bps\":\"0\", \"side\":\"BUY\", \"timestamp\":\"1785121917754\", \"event_type\":\"last_trade_price\", \"transaction_hash\":\"0x72a31ff093beb2d00950539903c4b49aec0748eb235118bf8f19d9a89d9ad89a\"}","received_at":"2026-07-27T03:12:04.080707Z","schema_version":"clob-market-ws.last_trade_price.v1","sequence":null,"server_hash":null,"server_timestamp":"1785121917754","session_id":"ff6d21c8283948938400a32613abec2c","source":"clob_market_ws"},"received_at":"2026-07-27T03:12:04.080707Z","record_id":"2158c9a0c3f6e2a4531aa7613e597d9691b2f09cc9cfb0516a4092e2f63d8f0d","schema_fingerprint":"95ad9be75a4b695cd99991e12b2592bc7346f3f5388a82d0000ba65bc0d9fd0a","schema_version":"edge-lab-recorder.raw.v1","sequence":null,"source":"clob_market_ws"}
{"event_at":"2026-07-27T03:11:57.762000Z","event_fingerprint":"278b2f5cdfb3a4db1748f31dd4df4ded2b0bc31d5d2373f12b038112624e8343","payload":{"connection_id":"f95883f18d264834af91809e5f803e9f","event_at":"2026-07-27T03:11:57.762000Z","event_type":"price_change","frame_hash":"a6e0e8810ad6fffd994119c503480937ce11476cfaad23f71a1d90afae64ddf8","frame_index":0,"kind":"data","monotonic_ns":223907412945500,"payload":{"event_type":"price_change","market":"0xf9d60bb033695053c4d1d8592e52171c1042f64b41a4b72e09dcc6f4852b6670","price_changes":[{"asset_id":"8698449539441374295770236407991735029336433231649246775082939325523552031992","best_ask":"0.6","best_bid":"0.59","hash":"5ad74704df634f14bd852e96b38c24aec9dabc24","price":"0.54","side":"BUY","size":"115"},{"asset_id":"96283536366176669581486355171583722558858323126916278856549586825357358273536","best_ask":"0.41","best_bid":"0.4","hash":"0407c89df6ab221f916c2693f5572d6a1d227381","price":"0.46","side":"SELL","size":"115"}],"timestamp":"1785121917762"},"payload_hash":"276d5ee3df1b69d0d97aa2d938523df6e59e83c2fc5f9130d2846ea062e51002","raw_frame":"{\"market\":\"0xf9d60bb033695053c4d1d8592e52171c1042f64b41a4b72e09dcc6f4852b6670\", \"price_changes\":[{\"asset_id\":\"8698449539441374295770236407991735029336433231649246775082939325523552031992\", \"price\":\"0.54\", \"size\":\"115\", \"side\":\"BUY\", \"hash\":\"5ad74704df634f14bd852e96b38c24aec9dabc24\", \"best_bid\":\"0.59\", \"best_ask\":\"0.6\"}, {\"asset_id\":\"96283536366176669581486355171583722558858323126916278856549586825357358273536\", \"price\":\"0.46\", \"size\":\"115\", \"side\":\"SELL\", \"hash\":\"0407c89df6ab221f916c2693f5572d6a1d227381\", \"best_bid\":\"0.4\", \"best_ask\":\"0.41\"}], \"timestamp\":\"1785121917762\", \"event_type\":\"price_change\"}","received_at":"2026-07-27T03:12:04.081753Z","schema_version":"clob-market-ws.price_change.v1","sequence":null,"server_hash":null,"server_timestamp":"1785121917762","session_id":"ff6d21c8283948938400a32613abec2c","source":"clob_market_ws"},"received_at":"2026-07-27T03:12:04.081753Z","record_id":"248a8c61316ff713fd30148f47c36a54212fda5a5714e032bc4eaebf0f281796","schema_fingerprint":"4aa3821a28b0b7c2400bc59aba4bcc0a76e971dadd19610d3ad38c768e124dc7","schema_version":"edge-lab-recorder.raw.v1","sequence":null,"source":"clob_market_ws"}
{"event_at":"2026-07-27T03:11:57.768000Z","event_fingerprint":"030c36f89bf8230241eb811de03a8035bd9f6d69e2f778978b36d9f70c83f208","payload":{"connection_id":"f95883f18d264834af91809e5f803e9f","event_at":"2026-07-27T03:11:57.768000Z","event_type":"price_change","frame_hash":"2681777b227390da596cfc648b6dc9011cbd1401fa453d74911d20e44920e3e0","frame_index":0,"kind":"data","monotonic_ns":223907414029500,"payload":{"event_type":"price_change","market":"0xf9d60bb033695053c4d1d8592e52171c1042f64b41a4b72e09dcc6f4852b6670","price_changes":[{"asset_id":"96283536366176669581486355171583722558858323126916278856549586825357358273536","best_ask":"0.41","best_bid":"0.4","hash":"6d9a976ab5f7233ad16d8dd06eb7131f90c1aad9","price":"0.34","side":"BUY","size":"72.35"},{"asset_id":"8698449539441374295770236407991735029336433231649246775082939325523552031992","best_ask":"0.6","best_bid":"0.59","hash":"7491ae375d86a168a02f5e8e3b1e3824919901ab","price":"0.66","side":"SELL","size":"72.35"}],"timestamp":"1785121917768"},"payload_hash":"90b1afcca73a57cdb5e6c12f2a3e7bd996966c1e28c9eade1fa08c8db639ffcf","raw_frame":"{\"market\":\"0xf9d60bb033695053c4d1d8592e52171c1042f64b41a4b72e09dcc6f4852b6670\", \"price_changes\":[{\"asset_id\":\"96283536366176669581486355171583722558858323126916278856549586825357358273536\", \"price\":\"0.34\", \"size\":\"72.35\", \"side\":\"BUY\", \"hash\":\"6d9a976ab5f7233ad16d8dd06eb7131f90c1aad9\", \"best_bid\":\"0.4\", \"best_ask\":\"0.41\"}, {\"asset_id\":\"8698449539441374295770236407991735029336433231649246775082939325523552031992\", \"price\":\"0.66\", \"size\":\"72.35\", \"side\":\"SELL\", \"hash\":\"7491ae375d86a168a02f5e8e3b1e3824919901ab\", \"best_bid\":\"0.59\", \"best_ask\":\"0.6\"}], \"timestamp\":\"1785121917768\", \"event_type\":\"price_change\"}","received_at":"2026-07-27T03:12:04.082837Z","schema_version":"clob-market-ws.price_change.v1","sequence":null,"server_hash":null,"server_timestamp":"1785121917768","session_id":"ff6d21c8283948938400a32613abec2c","source":"clob_market_ws"},"received_at":"2026-07-27T03:12:04.082837Z","record_id":"9283f4778b4150ba58f41f278be74a04ee006bd9db733ecac4e689a4c9cbc9dd","schema_fingerprint":"4aa3821a28b0b7c2400bc59aba4bcc0a76e971dadd19610d3ad38c768e124dc7","schema_version":"edge-lab-recorder.raw.v1","sequence":null,"source":"clob_market_ws"}
{"event_at":"2026-07-27T03:11:57.769000Z","event_fingerprint":"7899b17767856c204f28345074b5bbab35eb78e7c5cd36c309b363eb97611574","payload":{"connection_id":"f95883f18d264834af91809e5f803e9f","event_at":"2026-07-27T03:11:57.769000Z","event_type":"price_change","frame_hash":"8167cc47a2c78078d04e9c58424ceca0e3a7b7b47d4baccb6527cddd69539f08","frame_index":0,"kind":"data","monotonic_ns":223907415095416,"payload":{"event_type":"price_change","market":"0xf9d60bb033695053c4d1d8592e52171c1042f64b41a4b72e09dcc6f4852b6670","price_changes":[{"asset_id":"8698449539441374295770236407991735029336433231649246775082939325523552031992","best_ask":"0.6","best_bid":"0.59","hash":"df1ac17fa5ec9eac3eb58808a4e0b94fa8d47533","price":"0.59","side":"BUY","size":"10"},{"asset_id":"96283536366176669581486355171583722558858323126916278856549586825357358273536","best_ask":"0.41","best_bid":"0.4","hash":"dda2dfee22abf3a400d7709a6f480f068b4b00aa","price":"0.41","side":"SELL","size":"10"}],"timestamp":"1785121917769"},"payload_hash":"f3a0fc02337718900bcb12e2062d32888a0114deb31b8a1e953defbfb84da21c","raw_frame":"{\"market\":\"0xf9d60bb033695053c4d1d8592e52171c1042f64b41a4b72e09dcc6f4852b6670\", \"price_changes\":[{\"asset_id\":\"8698449539441374295770236407991735029336433231649246775082939325523552031992\", \"price\":\"0.59\", \"size\":\"10\", \"side\":\"BUY\", \"hash\":\"df1ac17fa5ec9eac3eb58808a4e0b94fa8d47533\", \"best_bid\":\"0.59\", \"best_ask\":\"0.6\"}, {\"asset_id\":\"96283536366176669581486355171583722558858323126916278856549586825357358273536\", \"price\":\"0.41\", \"size\":\"10\", \"side\":\"SELL\", \"hash\":\"dda2dfee22abf3a400d7709a6f480f068b4b00aa\", \"best_bid\":\"0.4\", \"best_ask\":\"0.41\"}], \"timestamp\":\"1785121917769\", \"event_type\":\"price_change\"}","received_at":"2026-07-27T03:12:04.083902Z","schema_version":"clob-market-ws.price_change.v1","sequence":null,"server_hash":null,"server_timestamp":"1785121917769","session_id":"ff6d21c8283948938400a32613abec2c","source":"clob_market_ws"},"received_at":"2026-07-27T03:12:04.083902Z","record_id":"f5237f6a921ab790dc8dfdfa9463d79069f92d5b958f29576c721476fb815d55","schema_fingerprint":"4aa3821a28b0b7c2400bc59aba4bcc0a76e971dadd19610d3ad38c768e124dc7","schema_version":"edge-lab-recorder.raw.v1","sequence":null,"source":"clob_market_ws"}
{"event_at":"2026-07-27T03:11:57.769000Z","event_fingerprint":"2f10092d28b3563f3505f159057e6bc045c328c6a674a4dc3035a6ab078b09fd","payload":{"connection_id":"f95883f18d264834af91809e5f803e9f","event_at":"2026-07-27T03:11:57.769000Z","event_type":"price_change","frame_hash":"81b5069677cdaaa743e0ad0763383676ecea1911e4ae53cb2a7bade5f5ec8b0a","frame_index":0,"kind":"data","monotonic_ns":223907416201250,"payload":{"event_type":"price_change","market":"0xf9d60bb033695053c4d1d8592e52171c1042f64b41a4b72e09dcc6f4852b6670","price_changes":[{"asset_id":"96283536366176669581486355171583722558858323126916278856549586825357358273536","best_ask":"0.41","best_bid":"0.4","hash":"5681fb460f827caccc6271da2ed304ecd8cdfaa7","price":"0.32","side":"BUY","size":"116.53"},{"asset_id":"8698449539441374295770236407991735029336433231649246775082939325523552031992","best_ask":"0.6","best_bid":"0.59","hash":"d9e285abd3fc9277e9dee38ecf6b86e739def423","price":"0.68","side":"SELL","size":"116.53"}],"timestamp":"1785121917769"},"payload_hash":"2666659cebb990bc2164cb187be73370a06e0cce5234de639e027bfee42be5ed","raw_frame":"{\"market\":\"0xf9d60bb033695053c4d1d8592e52171c1042f64b41a4b72e09dcc6f4852b6670\", \"price_changes\":[{\"asset_id\":\"96283536366176669581486355171583722558858323126916278856549586825357358273536\", \"price\":\"0.32\", \"size\":\"116.53\", \"side\":\"BUY\", \"hash\":\"5681fb460f827caccc6271da2ed304ecd8cdfaa7\", \"best_bid\":\"0.4\", \"best_ask\":\"0.41\"}, {\"asset_id\":\"8698449539441374295770236407991735029336433231649246775082939325523552031992\", \"price\":\"0.68\", \"size\":\"116.53\", \"side\":\"SELL\", \"hash\":\"d9e285abd3fc9277e9dee38ecf6b86e739def423\", \"best_bid\":\"0.59\", \"best_ask\":\"0.6\"}], \"timestamp\":\"1785121917769\", \"event_type\":\"price_change\"}","received_at":"2026-07-27T03:12:04.085008Z","schema_version":"clob-market-ws.price_change.v1","sequence":null,"server_hash":null,"server_timestamp":"1785121917769","session_id":"ff6d21c8283948938400a32613abec2c","source":"clob_market_ws"},"received_at":"2026-07-27T03:12:04.085008Z","record_id":"a8ba4e319cd395a75a7ce5cc2adf19554ee7f157156b4a8fb8549176fd1552b7","schema_fingerprint":"4aa3821a28b0b7c2400bc59aba4bcc0a76e971dadd19610d3ad38c768e124dc7","schema_version":"edge-lab-recorder.raw.v1","sequence":null,"source":"clob_market_ws"}
{"event_at":"2026-07-27T03:11:57.771000Z","event_fingerprint":"3fbefb99f10c60c0313d3cca10eeac8bc71ecc2ff38f3b83343c0b31411ed9d5","payload":{"connection_id":"f95883f18d264834af91809e5f803e9f","event_at":"2026-07-27T03:11:57.771000Z","event_type":"price_change","frame_hash":"293f81c7c725ea17abf3c7d15118bb39618d09dd6deda425c9465888b080ebb7","frame_index":0,"kind":"data","monotonic_ns":223907417359666,"payload":{"event_type":"price_change","market":"0xf9d60bb033695053c4d1d8592e52171c1042f64b41a4b72e09dcc6f4852b6670","price_changes":[{"asset_id":"96283536366176669581486355171583722558858323126916278856549586825357358273536","best_ask":"0.41","best_bid":"0.4","hash":"35ae39d0b21a576575dd7e5d9a7d8743c5ca3a0b","price":"0.35","side":"BUY","size":"46.21"},{"asset_id":"8698449539441374295770236407991735029336433231649246775082939325523552031992","best_ask":"0.6","best_bid":"0.59","hash":"e749b8042acacd666106686ff9d24b5a9079ebcd","price":"0.65","side":"SELL","size":"46.21"}],"timestamp":"1785121917771"},"payload_hash":"b929ed82dab5773186f6dd83cdfdb2aefac264c37f5c56f7db5aef4aaf798dcf","raw_frame":"{\"market\":\"0xf9d60bb033695053c4d1d8592e52171c1042f64b41a4b72e09dcc6f4852b6670\", \"price_changes\":[{\"asset_id\":\"96283536366176669581486355171583722558858323126916278856549586825357358273536\", \"price\":\"0.35\", \"size\":\"46.21\", \"side\":\"BUY\", \"hash\":\"35ae39d0b21a576575dd7e5d9a7d8743c5ca3a0b\", \"best_bid\":\"0.4\", \"best_ask\":\"0.41\"}, {\"asset_id\":\"8698449539441374295770236407991735029336433231649246775082939325523552031992\", \"price\":\"0.65\", \"size\":\"46.21\", \"side\":\"SELL\", \"hash\":\"e749b8042acacd666106686ff9d24b5a9079ebcd\", \"best_bid\":\"0.59\", \"best_ask\":\"0.6\"}], \"timestamp\":\"1785121917771\", \"event_type\":\"price_change\"}","received_at":"2026-07-27T03:12:04.086167Z","schema_version":"clob-market-ws.price_change.v1","sequence":null,"server_hash":null,"server_timestamp":"1785121917771","session_id":"ff6d21c8283948938400a32613abec2c","source":"clob_market_ws"},"received_at":"2026-07-27T03:12:04.086167Z","record_id":"0b825209285ebabb221aafcb97f0974682de3f09a002542e4045bbb4080c1a0f","schema_fingerprint":"4aa3821a28b0b7c2400bc59aba4bcc0a76e971dadd19610d3ad38c768e124dc7","schema_version":"edge-lab-recorder.raw.v1","sequence":null,"source":"clob_market_ws"}
{"event_at":"2026-07-27T03:11:57.772000Z","event_fingerprint":"80ef18d212194795f1430d0076be294dfc30196dcf974e0675f32dbcd1fac7cd","payload":{"connection_id":"f95883f18d264834af91809e5f803e9f","event_at":"2026-07-27T03:11:57.772000Z","event_type":"price_change","frame_hash":"2a73c56698a32f18a4e1d12f6cae6f4d9bdc18868ec37c2c9befe39b3b3eed0e","frame_index":0,"kind":"data","monotonic_ns":223907418521000,"payload":{"event_type":"price_change","market":"0xf9d60bb033695053c4d1d8592e52171c1042f64b41a4b72e09dcc6f4852b6670","price_changes":[{"asset_id":"8698449539441374295770236407991735029336433231649246775082939325523552031992","best_ask":"0.6","best_bid":"0.59","hash":"93002f2dd4f4250ca11683badbd28883ba9d338f","price":"0.58","side":"BUY","size":"21.1"},{"asset_id":"96283536366176669581486355171583722558858323126916278856549586825357358273536","best_ask":"0.41","best_bid":"0.4","hash":"61bc29d3c52dd8fd1325af88a7271f47c4b5b179","price":"0.42","side":"SELL","size":"21.1"}],"timestamp":"1785121917772"},"payload_hash":"bd5f053c2dfd50b2047f681a7545f346da1cfd545f2c331684f6a8c8ae2255ae","raw_frame":"{\"market\":\"0xf9d60bb033695053c4d1d8592e52171c1042f64b41a4b72e09dcc6f4852b6670\", \"price_changes\":[{\"asset_id\":\"8698449539441374295770236407991735029336433231649246775082939325523552031992\", \"price\":\"0.58\", \"size\":\"21.1\", \"side\":\"BUY\", \"hash\":\"93002f2dd4f4250ca11683badbd28883ba9d338f\", \"best_bid\":\"0.59\", \"best_ask\":\"0.6\"}, {\"asset_id\":\"96283536366176669581486355171583722558858323126916278856549586825357358273536\", \"price\":\"0.42\", \"size\":\"21.1\", \"side\":\"SELL\", \"hash\":\"61bc29d3c52dd8fd1325af88a7271f47c4b5b179\", \"best_bid\":\"0.4\", \"best_ask\":\"0.41\"}], \"timestamp\":\"1785121917772\", \"event_type\":\"price_change\"}","received_at":"2026-07-27T03:12:04.087328Z","schema_version":"clob-market-ws.price_change.v1","sequence":null,"server_hash":null,"server_timestamp":"1785121917772","session_id":"ff6d21c8283948938400a32613abec2c","source":"clob_market_ws"},"received_at":"2026-07-27T03:12:04.087328Z","record_id":"08a61c81d908e82dd6e62b78ba33c3845680298a2d16a954454e6e98227ee38a","schema_fingerprint":"4aa3821a28b0b7c2400bc59aba4bcc0a76e971dadd19610d3ad38c768e124dc7","schema_version":"edge-lab-recorder.raw.v1","sequence":null,"source":"clob_market_ws"}
{"event_at":"2026-07-27T03:11:57.777000Z","event_fingerprint":"8353cf8ef4c1440e4d07c344c91f443adda39c66b993da21c25df569c4e06590","payload":{"connection_id":"f95883f18d264834af91809e5f803e9f","event_at":"2026-07-27T03:11:57.777000Z","event_type":"price_change","frame_hash":"3d8e07c341a97dc2a0d1e94550b24751895ab17e6e7e29c35f8eb5149c2f2e40","frame_index":0,"kind":"data","monotonic_ns":223907419732250,"payload":{"event_type":"price_change","market":"0xf9d60bb033695053c4d1d8592e52171c1042f64b41a4b72e09dcc6f4852b6670","price_changes":[{"asset_id":"96283536366176669581486355171583722558858323126916278856549586825357358273536","best_ask":"0.41","best_bid":"0.4","hash":"3161421e1ef7928ac0b57935abfe4d76221d0862","price":"0.33","side":"BUY","size":"62.16"},{"asset_id":"8698449539441374295770236407991735029336433231649246775082939325523552031992","best_ask":"0.6","best_bid":"0.59","hash":"bce872c2341878d312ba28925b740326299b37ec","price":"0.67","side":"SELL","size":"62.16"}],"timestamp":"1785121917777"},"payload_hash":"96c80e57cfa9d18118bbfab991954ede52e6f9344e289a3e795582abe67a9599","raw_frame":"{\"market\":\"0xf9d60bb033695053c4d1d8592e52171c1042f64b41a4b72e09dcc6f4852b6670\", \"price_changes\":[{\"asset_id\":\"96283536366176669581486355171583722558858323126916278856549586825357358273536\", \"price\":\"0.33\", \"size\":\"62.16\", \"side\":\"BUY\", \"hash\":\"3161421e1ef7928ac0b57935abfe4d76221d0862\", \"best_bid\":\"0.4\", \"best_ask\":\"0.41\"}, {\"asset_id\":\"8698449539441374295770236407991735029336433231649246775082939325523552031992\", \"price\":\"0.67\", \"size\":\"62.16\", \"side\":\"SELL\", \"hash\":\"bce872c2341878d312ba28925b740326299b37ec\", \"best_bid\":\"0.59\", \"best_ask\":\"0.6\"}], \"timestamp\":\"1785121917777\", \"event_type\":\"price_change\"}","received_at":"2026-07-27T03:12:04.088538Z","schema_version":"clob-market-ws.price_change.v1","sequence":null,"server_hash":null,"server_timestamp":"1785121917777","session_id":"ff6d21c8283948938400a32613abec2c","source":"clob_market_ws"},"received_at":"2026-07-27T03:12:04.088538Z","record_id":"4bbf476f8451bb7c00b47ae893b0e1190c733858ea967efc8fddb7d0713ff193","schema_fingerprint":"4aa3821a28b0b7c2400bc59aba4bcc0a76e971dadd19610d3ad38c768e124dc7","schema_version":"edge-lab-recorder.raw.v1","sequence":null,"source":"clob_market_ws"}
{"event_at":"2026-07-27T03:11:57.778000Z","event_fingerprint":"3fbc26a7f43c5d74715f03fed8e76ae6bbf45880c054acaa7da97ae6abcf256c","payload":{"connection_id":"f95883f18d264834af91809e5f803e9f","event_at":"2026-07-27T03:11:57.778000Z","event_type":"price_change","frame_hash":"17fa21f6d18ef07de6f1ec94cea3f3ddfe1919c5b087637c7b406d5eb9b74833","frame_index":0,"kind":"data","monotonic_ns":223907421454375,"payload":{"event_type":"price_change","market":"0xf9d60bb033695053c4d1d8592e52171c1042f64b41a4b72e09dcc6f4852b6670","price_changes":[{"asset_id":"8698449539441374295770236407991735029336433231649246775082939325523552031992","best_ask":"0.6","best_bid":"0.59","hash":"00165ee3bba2deea4d8b60779b231ccde40ff861","price":"0.59","side":"BUY","size":"15"},{"asset_id":"96283536366176669581486355171583722558858323126916278856549586825357358273536","best_ask":"0.41","best_bid":"0.4","hash":"5e831dd8a23235e8f2cb4bf6f1db7107f6cb570a","price":"0.41","side":"SELL","size":"15"}],"timestamp":"1785121917778"},"payload_hash":"857da1954da1da286e0c7af5080f8723ebb8aad0a852301c9f6125dc39136306","raw_frame":"{\"market\":\"0xf9d60bb033695053c4d1d8592e52171c1042f64b41a4b72e09dcc6f4852b6670\", \"price_changes\":[{\"asset_id\":\"8698449539441374295770236407991735029336433231649246775082939325523552031992\", \"price\":\"0.59\", \"size\":\"15\", \"side\":\"BUY\", \"hash\":\"00165ee3bba2deea4d8b60779b231ccde40ff861\", \"best_bid\":\"0.59\", \"best_ask\":\"0.6\"}, {\"asset_id\":\"96283536366176669581486355171583722558858323126916278856549586825357358273536\", \"price\":\"0.41\", \"size\":\"15\", \"side\":\"SELL\", \"hash\":\"5e831dd8a23235e8f2cb4bf6f1db7107f6cb570a\", \"best_bid\":\"0.4\", \"best_ask\":\"0.41\"}], \"timestamp\":\"1785121917778\", \"event_type\":\"price_change\"}","received_at":"2026-07-27T03:12:04.090259Z","schema_version":"clob-market-ws.price_change.v1","sequence":null,"server_hash":null,"server_timestamp":"1785121917778","session_id":"ff6d21c8283948938400a32613abec2c","source":"clob_market_ws"},"received_at":"2026-07-27T03:12:04.090259Z","record_id":"5fc271a146867331b81cc5ce604b79a34238ef53ee5f1885f17731844c36bf67","schema_fingerprint":"4aa3821a28b0b7c2400bc59aba4bcc0a76e971dadd19610d3ad38c768e124dc7","schema_version":"edge-lab-recorder.raw.v1","sequence":null,"source":"clob_market_ws"}
