{"event_at":"2026-07-27T03:06:50.070000Z","event_fingerprint":"7210a4eb70a9db86d4279bf90e1f0a81445ed9eed8456e51870835cbe7253de8","payload":{"connection_id":"f95883f18d264834af91809e5f803e9f","event_at":"2026-07-27T03:06:50.070000Z","event_type":"price_change","frame_hash":"588ca0927e972136ae3ef6c9322fd2a4c6294bbdf167ae484087838af767dfe1","frame_index":0,"kind":"data","monotonic_ns":223593316233458,"payload":{"event_type":"price_change","market":"0xf9d60bb033695053c4d1d8592e52171c1042f64b41a4b72e09dcc6f4852b6670","price_changes":[{"asset_id":"8698449539441374295770236407991735029336433231649246775082939325523552031992","best_ask":"0.51","best_bid":"0.5","hash":"714bdbfff7f99bf163185154536975d7780a02a4","price":"0.24","side":"BUY","size":"291.68"},{"asset_id":"96283536366176669581486355171583722558858323126916278856549586825357358273536","best_ask":"0.5","best_bid":"0.49","hash":"50a664b9cf134a3edb62dfe99736b87d616f40cc","price":"0.76","side":"SELL","size":"291.68"}],"timestamp":"1785121610070"},"payload_hash":"b52a080d153b7be451374d5d57c647d7ab642a9b7ae0642fe99dab59616be294","raw_frame":"{\"market\":\"0xf9d60bb033695053c4d1d8592e52171c1042f64b41a4b72e09dcc6f4852b6670\", \"price_changes\":[{\"asset_id\":\"8698449539441374295770236407991735029336433231649246775082939325523552031992\", \"price\":\"0.24\", \"size\":\"291.68\", \"side\":\"BUY\", \"hash\":\"714bdbfff7f99bf163185154536975d7780a02a4\", \"best_bid\":\"0.5\", \"best_ask\":\"0.51\"}, {\"asset_id\":\"96283536366176669581486355171583722558858323126916278856549586825357358273536\", \"price\":\"0.76\", \"size\":\"291.68\", \"side\":\"SELL\", \"hash\":\"50a664b9cf134a3edb62dfe99736b87d616f40cc\", \"best_bid\":\"0.49\", \"best_ask\":\"0.5\"}], \"timestamp\":\"1785121610070\", \"event_type\":\"price_change\"}","received_at":"2026-07-27T03:06:49.989439Z","schema_version":"clob-market-ws.price_change.v1","sequence":null,"server_hash":null,"server_timestamp":"1785121610070","session_id":"ff6d21c8283948938400a32613abec2c","source":"clob_market_ws"},"received_at":"2026-07-27T03:06:49.989439Z","record_id":"f52ee42d1b210322ba06e054061c2a9a77af37407dc95cc8175cca62daff20b3","schema_fingerprint":"4aa3821a28b0b7c2400bc59aba4bcc0a76e971dadd19610d3ad38c768e124dc7","schema_version":"edge-lab-recorder.raw.v1","sequence":null,"source":"clob_market_ws"}
{"event_at":"2026-07-27T03:06:50.109000Z","event_fingerprint":"4027f367581bebab93144e0331e7ce0d25ba650ef3aabeb0d32ecd69b550dec0","payload":{"connection_id":"f95883f18d264834af91809e5f803e9f","event_at":"2026-07-27T03:06:50.109000Z","event_type":"price_change","frame_hash":"c462d2235402c9cd9f5523d2d488205facb1cbcd55f5eb0c1c3c27b316b2c237","frame_index":0,"kind":"data","monotonic_ns":223593343018708,"payload":{"event_type":"price_change","market":"0xf9d60bb033695053c4d1d8592e52171c1042f64b41a4b72e09dcc6f4852b6670","price_changes":[{"asset_id":"96283536366176669581486355171583722558858323126916278856549586825357358273536","best_ask":"0.5","best_bid":"0.49","hash":"b93b4b67754037d21e3cd71287be758b55354a2a","price":"0.24","side":"BUY","size":"291.68"},{"asset_id":"8698449539441374295770236407991735029336433231649246775082939325523552031992","best_ask":"0.51","best_bid":"0.5","hash":"97947ebf9f9747d3b31ea0eee5f03e86596fe69f","price":"0.76","side":"SELL","size":"291.68"}],"timestamp":"1785121610109"},"payload_hash":"34413ba8d189e87790c2cc9504d200b8474c4780e165f4ec72d4f26b151d69b3","raw_frame":"{\"market\":\"0xf9d60bb033695053c4d1d8592e52171c1042f64b41a4b72e09dcc6f4852b6670\", \"price_changes\":[{\"asset_id\":\"96283536366176669581486355171583722558858323126916278856549586825357358273536\", \"price\":\"0.24\", \"size\":\"291.68\", \"side\":\"BUY\", \"hash\":\"b93b4b67754037d21e3cd71287be758b55354a2a\", \"best_bid\":\"0.49\", \"best_ask\":\"0.5\"}, {\"asset_id\":\"8698449539441374295770236407991735029336433231649246775082939325523552031992\", \"price\":\"0.76\", \"size\":\"291.68\", \"side\":\"SELL\", \"hash\":\"97947ebf9f9747d3b31ea0eee5f03e86596fe69f\", \"best_bid\":\"0.5\", \"best_ask\":\"0.51\"}], \"timestamp\":\"1785121610109\", \"event_type\":\"price_change\"}","received_at":"2026-07-27T03:06:50.016221Z","schema_version":"clob-market-ws.price_change.v1","sequence":null,"server_hash":null,"server_timestamp":"1785121610109","session_id":"ff6d21c8283948938400a32613abec2c","source":"clob_market_ws"},"received_at":"2026-07-27T03:06:50.016221Z","record_id":"1a82b65ae1c91ec49705ef802620e70c45fa04383af6503dad01444354a59b8a","schema_fingerprint":"4aa3821a28b0b7c2400bc59aba4bcc0a76e971dadd19610d3ad38c768e124dc7","schema_version":"edge-lab-recorder.raw.v1","sequence":null,"source":"clob_market_ws"}
{"event_at":"2026-07-27T03:06:50.138000Z","event_fingerprint":"ac90ef87859c50786fa5bc298ff9c72404d5e32e3e30c8788f1d14b84b13d171","payload":{"connection_id":"f95883f18d264834af91809e5f803e9f","event_at":"2026-07-27T03:06:50.138000Z","event_type":"price_change","frame_hash":"c08dc9d33b2402f123b001a9c042252ceeb5ccea33005cf803dac263102c427f","frame_index":0,"kind":"data","monotonic_ns":223593373317208,"payload":{"event_type":"price_change","market":"0xf9d60bb033695053c4d1d8592e52171c1042f64b41a4b72e09dcc6f4852b6670","price_changes":[{"asset_id":"8698449539441374295770236407991735029336433231649246775082939325523552031992","best_ask":"0.51","best_bid":"0.5","hash":"61d39f1afd728454a71ade633be521bd801aa333","price":"0.23","side":"BUY","size":"150"},{"asset_id":"96283536366176669581486355171583722558858323126916278856549586825357358273536","best_ask":"0.5","best_bid":"0.49","hash":"cd257ad063a8693c29f993a3e4ac23cc7fadd32b","price":"0.77","side":"SELL","size":"150"}],"timestamp":"1785121610138"},"payload_hash":"54fdd7d23c7564c1c94a413246a6dbc352de75753055b91066a4bcd83f855999","raw_frame":"{\"market\":\"0xf9d60bb033695053c4d1d8592e52171c1042f64b41a4b72e09dcc6f4852b6670\", \"price_changes\":[{\"asset_id\":\"8698449539441374295770236407991735029336433231649246775082939325523552031992\", \"price\":\"0.23\", \"size\":\"150\", \"side\":\"BUY\", \"hash\":\"61d39f1afd728454a71ade633be521bd801aa333\", \"best_bid\":\"0.5\", \"best_ask\":\"0.51\"}, {\"asset_id\":\"96283536366176669581486355171583722558858323126916278856549586825357358273536\", \"price\":\"0.77\", \"size\":\"150\", \"side\":\"SELL\", \"hash\":\"cd257ad063a8693c29f993a3e4ac23cc7fadd32b\", \"best_bid\":\"0.49\", \"best_ask\":\"0.5\"}], \"timestamp\":\"1785121610138\", \"event_type\":\"price_change\"}","received_at":"2026-07-27T03:06:50.046516Z","schema_version":"clob-market-ws.price_change.v1","sequence":null,"server_hash":null,"server_timestamp":"1785121610138","session_id":"ff6d21c8283948938400a32613abec2c","source":"clob_market_ws"},"received_at":"2026-07-27T03:06:50.046516Z","record_id":"2f2e264a7ed933e19d0d9cce3c800081fada347e998d0eb03139f9434485af58","schema_fingerprint":"4aa3821a28b0b7c2400bc59aba4bcc0a76e971dadd19610d3ad38c768e124dc7","schema_version":"edge-lab-recorder.raw.v1","sequence":null,"source":"clob_market_ws"}
{"event_at":"2026-07-27T03:06:50.175000Z","event_fingerprint":"0939194b753b63243d58f9f8e8fb93625912951013a4a3340b860ab94552f6fd","payload":{"connection_id":"f95883f18d264834af91809e5f803e9f","event_at":"2026-07-27T03:06:50.175000Z","event_type":"price_change","frame_hash":"88bf68ed690b5783c834a8aa128a9679da051eddff76aab67f279b3e703f1741","frame_index":0,"kind":"data","monotonic_ns":223593409488666,"payload":{"event_type":"price_change","market":"0xf9d60bb033695053c4d1d8592e52171c1042f64b41a4b72e09dcc6f4852b6670","price_changes":[{"asset_id":"96283536366176669581486355171583722558858323126916278856549586825357358273536","best_ask":"0.5","best_bid":"0.49","hash":"e0ef959c1bd11a3494cad25b79fc32afc8dd9bcd","price":"0.23","side":"BUY","size":"150"},{"asset_id":"8698449539441374295770236407991735029336433231649246775082939325523552031992","best_ask":"0.51","best_bid":"0.5","hash":"903ec927b8b5dcf0052b733e088bcb50a1e6a9fa","price":"0.77","side":"SELL","size":"150"}],"timestamp":"1785121610175"},"payload_hash":"c4e23f5dc1ee07b0c68085d5b78b87eae9804769dcdf2339d3a6ff35c0a02f01","raw_frame":"{\"market\":\"0xf9d60bb033695053c4d1d8592e52171c1042f64b41a4b72e09dcc6f4852b6670\", \"price_changes\":[{\"asset_id\":\"96283536366176669581486355171583722558858323126916278856549586825357358273536\", \"price\":\"0.23\", \"size\":\"150\", \"side\":\"BUY\", \"hash\":\"e0ef959c1bd11a3494cad25b79fc32afc8dd9bcd\", \"best_bid\":\"0.49\", \"best_ask\":\"0.5\"}, {\"asset_id\":\"8698449539441374295770236407991735029336433231649246775082939325523552031992\", \"price\":\"0.77\", \"size\":\"150\", \"side\":\"SELL\", \"hash\":\"903ec927b8b5dcf0052b733e088bcb50a1e6a9fa\", \"best_bid\":\"0.5\", \"best_ask\":\"0.51\"}], \"timestamp\":\"1785121610175\", \"event_type\":\"price_change\"}","received_at":"2026-07-27T03:06:50.082691Z","schema_version":"clob-market-ws.price_change.v1","sequence":null,"server_hash":null,"server_timestamp":"1785121610175","session_id":"ff6d21c8283948938400a32613abec2c","source":"clob_market_ws"},"received_at":"2026-07-27T03:06:50.082691Z","record_id":"a722898c5e45e85e587c86cb3cad10f997e65d87181e93e04405f96eeb8e4b63","schema_fingerprint":"4aa3821a28b0b7c2400bc59aba4bcc0a76e971dadd19610d3ad38c768e124dc7","schema_version":"edge-lab-recorder.raw.v1","sequence":null,"source":"clob_market_ws"}
{"event_at":"2026-07-27T03:06:51.184000Z","event_fingerprint":"43c8a30d3d7ab98d0e527c3926391860c82a1a3518b6560fe362c6d36f6b44a8","payload":{"connection_id":"f95883f18d264834af91809e5f803e9f","event_at":"2026-07-27T03:06:51.184000Z","event_type":"price_change","frame_hash":"c8628d77723d8e9c0a64ba153bc79ef9dcbe67b985cff9fd611b22dce403449a","frame_index":0,"kind":"data","monotonic_ns":223594418283333,"payload":{"event_type":"price_change","market":"0xf9d60bb033695053c4d1d8592e52171c1042f64b41a4b72e09dcc6f4852b6670","price_changes":[{"asset_id":"96283536366176669581486355171583722558858323126916278856549586825357358273536","best_ask":"0.5","best_bid":"0.49","hash":"6cf37335e95601f8945baaab3403deafa31ab115","price":"0.41","side":"BUY","size":"272.6"},{"asset_id":"8698449539441374295770236407991735029336433231649246775082939325523552031992","best_ask":"0.51","best_bid":"0.5","hash":"e7e7f54cecc5af2298edee964def2f059ad023d0","price":"0.59","side":"SELL","size":"272.6"}],"timestamp":"1785121611184"},"payload_hash":"537a0177dfc13e08baf02a18e02569b1e1406edae39b7c124cd307b38a940725","raw_frame":"{\"market\":\"0xf9d60bb033695053c4d1d8592e52171c1042f64b41a4b72e09dcc6f4852b6670\", \"price_changes\":[{\"asset_id\":\"96283536366176669581486355171583722558858323126916278856549586825357358273536\", \"price\":\"0.41\", \"size\":\"272.6\", \"side\":\"BUY\", \"hash\":\"6cf37335e95601f8945baaab3403deafa31ab115\", \"best_bid\":\"0.49\", \"best_ask\":\"0.5\"}, {\"asset_id\":\"8698449539441374295770236407991735029336433231649246775082939325523552031992\", \"price\":\"0.59\", \"size\":\"272.6\", \"side\":\"SELL\", \"hash\":\"e7e7f54cecc5af2298edee964def2f059ad023d0\", \"best_bid\":\"0.5\", \"best_ask\":\"0.51\"}], \"timestamp\":\"1785121611184\", \"event_type\":\"price_change\"}","received_at":"2026-07-27T03:06:51.091471Z","schema_version":"clob-market-ws.price_change.v1","sequence":null,"server_hash":null,"server_timestamp":"1785121611184","session_id":"ff6d21c8283948938400a32613abec2c","source":"clob_market_ws"},"received_at":"2026-07-27T03:06:51.091471Z","record_id":"f3a6e70515a6ceb7dd0a60ee33c6e5bfcbd722a1f0a1b66be9df149b0f7dcb80","schema_fingerprint":"4aa3821a28b0b7c2400bc59aba4bcc0a76e971dadd19610d3ad38c768e124dc7","schema_version":"edge-lab-recorder.raw.v1","sequence":null,"source":"clob_market_ws"}
{"event_at":"2026-07-27T03:06:51.257000Z","event_fingerprint":"fcbb4f9f0a68a8eea84cb5003ebe18a6efdeca6b23df3d16ab2cd4af5b9e0c12","payload":{"connection_id":"f95883f18d264834af91809e5f803e9f","event_at":"2026-07-27T03:06:51.257000Z","event_type":"price_change","frame_hash":"1195c307ce390dd4830606646301720c66f5aac81eb40b2b60decb79a792d932","frame_index":0,"kind":"data","monotonic_ns":223594489265666,"payload":{"event_type":"price_change","market":"0xf9d60bb033695053c4d1d8592e52171c1042f64b41a4b72e09dcc6f4852b6670","price_changes":[{"asset_id":"96283536366176669581486355171583722558858323126916278856549586825357358273536","best_ask":"0.5","best_bid":"0.49","hash":"30d622f28c14082c14db8429561151cfa6f5cadf","price":"0.42","side":"BUY","size":"234.03"},{"asset_id":"8698449539441374295770236407991735029336433231649246775082939325523552031992","best_ask":"0.51","best_bid":"0.5","hash":"7607d90c997b4ac4c446cf9e606d5d0cfa5a2468","price":"0.58","side":"SELL","size":"234.03"}],"timestamp":"1785121611257"},"payload_hash":"5d80b4dbc355ccc659afaad85b56fccd512d661d06fce30cea9fe994596114b5","raw_frame":"{\"market\":\"0xf9d60bb033695053c4d1d8592e52171c1042f64b41a4b72e09dcc6f4852b6670\", \"price_changes\":[{\"asset_id\":\"96283536366176669581486355171583722558858323126916278856549586825357358273536\", \"price\":\"0.42\", \"size\":\"234.03\", \"side\":\"BUY\", \"hash\":\"30d622f28c14082c14db8429561151cfa6f5cadf\", \"best_bid\":\"0.49\", \"best_ask\":\"0.5\"}, {\"asset_id\":\"8698449539441374295770236407991735029336433231649246775082939325523552031992\", \"price\":\"0.58\", \"size\":\"234.03\", \"side\":\"SELL\", \"hash\":\"7607d90c997b4ac4c446cf9e606d5d0cfa5a2468\", \"best_bid\":\"0.5\", \"best_ask\":\"0.51\"}], \"timestamp\":\"1785121611257\", \"event_type\":\"price_change\"}","received_at":"2026-07-27T03:06:51.162459Z","schema_version":"clob-market-ws.price_change.v1","sequence":null,"server_hash":null,"server_timestamp":"1785121611257","session_id":"ff6d21c8283948938400a32613abec2c","source":"clob_market_ws"},"received_at":"2026-07-27T03:06:51.162459Z","record_id":"f76ff7bd9b1f2f8aeea9fb2944a72cfb05c79e69f726aaac252254bcddea8c31","schema_fingerprint":"4aa3821a28b0b7c2400bc59aba4bcc0a76e971dadd19610d3ad38c768e124dc7","schema_version":"edge-lab-recorder.raw.v1","sequence":null,"source":"clob_market_ws"}
{"event_at":"2026-07-27T03:06:52.161000Z","event_fingerprint":"75566b2665f2b7714d0cd869f14bc9c23befabd2ca5a6c675a2f50d6d596ac43","payload":{"connection_id":"f95883f18d264834af91809e5f803e9f","event_at":"2026-07-27T03:06:52.161000Z","event_type":"price_change","frame_hash":"92004d05058005b01b1bdc48ef2d8eabdedf5a792ce8dc23f8729c6bab2c4636","frame_index":0,"kind":"data","monotonic_ns":223595397088500,"payload":{"event_type":"price_change","market":"0xf9d60bb033695053c4d1d8592e52171c1042f64b41a4b72e09dcc6f4852b6670","price_changes":[{"asset_id":"96283536366176669581486355171583722558858323126916278856549586825357358273536","best_ask":"0.5","best_bid":"0.49","hash":"da8a5a1ef02b0b4b27759d5949aee2250d94477c","price":"0.42","side":"BUY","size":"229.03"},{"asset_id":"8698449539441374295770236407991735029336433231649246775082939325523552031992","best_ask":"0.51","best_bid":"0.5","hash":"49f62cf90b501e1a55b216b48ee006e0a6f5747d","price":"0.58","side":"SELL","size":"229.03"}],"timestamp":"1785121612161"},"payload_hash":"e8c2e765a4a41564d7ecbc4a0da86a62a5217556669ede680c50fd7f549e4e4f","raw_frame":"{\"market\":\"0xf9d60bb033695053c4d1d8592e52171c1042f64b41a4b72e09dcc6f4852b6670\", \"price_changes\":[{\"asset_id\":\"96283536366176669581486355171583722558858323126916278856549586825357358273536\", \"price\":\"0.42\", \"size\":\"229.03\", \"side\":\"BUY\", \"hash\":\"da8a5a1ef02b0b4b27759d5949aee2250d94477c\", \"best_bid\":\"0.49\", \"best_ask\":\"0.5\"}, {\"asset_id\":\"8698449539441374295770236407991735029336433231649246775082939325523552031992\", \"price\":\"0.58\", \"size\":\"229.03\", \"side\":\"SELL\", \"hash\":\"49f62cf90b501e1a55b216b48ee006e0a6f5747d\", \"best_bid\":\"0.5\", \"best_ask\":\"0.51\"}], \"timestamp\":\"1785121612161\", \"event_type\":\"price_change\"}","received_at":"2026-07-27T03:06:52.070263Z","schema_version":"clob-market-ws.price_change.v1","sequence":null,"server_hash":null,"server_timestamp":"1785121612161","session_id":"ff6d21c8283948938400a32613abec2c","source":"clob_market_ws"},"received_at":"2026-07-27T03:06:52.070263Z","record_id":"31def743e9c22304692317b051068a54278aa70be1c533b1f5d460ef2489e4e7","schema_fingerprint":"4aa3821a28b0b7c2400bc59aba4bcc0a76e971dadd19610d3ad38c768e124dc7","schema_version":"edge-lab-recorder.raw.v1","sequence":null,"source":"clob_market_ws"}
{"event_at":"2026-07-27T03:06:52.263000Z","event_fingerprint":"408d582bf937cd6eaeefc9997f51da3480855a606746ce8f2049df7f03ee661f","payload":{"connection_id":"f95883f18d264834af91809e5f803e9f","event_at":"2026-07-27T03:06:52.263000Z","event_type":"price_change","frame_hash":"c694c6b84a7a9831073ad75bc059c2eba484e56157dbbf3ef7bcd935db06965d","frame_index":0,"kind":"data","monotonic_ns":223595498955208,"payload":{"event_type":"price_change","market":"0xf9d60bb033695053c4d1d8592e52171c1042f64b41a4b72e09dcc6f4852b6670","price_changes":[{"asset_id":"96283536366176669581486355171583722558858323126916278856549586825357358273536","best_ask":"0.5","best_bid":"0.49","hash":"e4cbeb14b91ae6559fd799a080e4fc1b3af956de","price":"0.43","side":"BUY","size":"238.9"},{"asset_id":"8698449539441374295770236407991735029336433231649246775082939325523552031992","best_ask":"0.51","best_bid":"0.5","hash":"502d320638293fd947b1ad510fbb55ecea5ca373","price":"0.57","side":"SELL","size":"238.9"}],"timestamp":"1785121612263"},"payload_hash":"6a6cffe5187cbf84ce4bef24b21b3eb11b5649b3ed6634463a5a26cff30c465d","raw_frame":"{\"market\":\"0xf9d60bb033695053c4d1d8592e52171c1042f64b41a4b72e09dcc6f4852b6670\", \"price_changes\":[{\"asset_id\":\"96283536366176669581486355171583722558858323126916278856549586825357358273536\", \"price\":\"0.43\", \"size\":\"238.9\", \"side\":\"BUY\", \"hash\":\"e4cbeb14b91ae6559fd799a080e4fc1b3af956de\", \"best_bid\":\"0.49\", \"best_ask\":\"0.5\"}, {\"asset_id\":\"8698449539441374295770236407991735029336433231649246775082939325523552031992\", \"price\":\"0.57\", \"size\":\"238.9\", \"side\":\"SELL\", \"hash\":\"502d320638293fd947b1ad510fbb55ecea5ca373\", \"best_bid\":\"0.5\", \"best_ask\":\"0.51\"}], \"timestamp\":\"1785121612263\", \"event_type\":\"price_change\"}","received_at":"2026-07-27T03:06:52.172134Z","schema_version":"clob-market-ws.price_change.v1","sequence":null,"server_hash":null,"server_timestamp":"1785121612263","session_id":"ff6d21c8283948938400a32613abec2c","source":"clob_market_ws"},"received_at":"2026-07-27T03:06:52.172134Z","record_id":"44b91f040ccfdf9d93baf50d1a4be2abaf8df368307403155e1a784af520a871","schema_fingerprint":"4aa3821a28b0b7c2400bc59aba4bcc0a76e971dadd19610d3ad38c768e124dc7","schema_version":"edge-lab-recorder.raw.v1","sequence":null,"source":"clob_market_ws"}
{"event_at":"2026-07-27T03:06:53.427000Z","event_fingerprint":"dd7fe01d0470f3fb85e671f1f429ff7a9e52b83f5b2ccc4a3e42bc164319482f","payload":{"connection_id":"f95883f18d264834af91809e5f803e9f","event_at":"2026-07-27T03:06:53.427000Z","event_type":"price_change","frame_hash":"8d45641fabdd66852c17271846390c7ad381e2c9d25f1f260bfa41cdb9613b71","frame_index":0,"kind":"data","monotonic_ns":223596661559583,"payload":{"event_type":"price_change","market":"0xf9d60bb033695053c4d1d8592e52171c1042f64b41a4b72e09dcc6f4852b6670","price_changes":[{"asset_id":"96283536366176669581486355171583722558858323126916278856549586825357358273536","best_ask":"0.5","best_bid":"0.49","hash":"d87c2cacb168e43e0981f1f98e5971161368a431","price":"0.46","side":"BUY","size":"169.57"},{"asset_id":"8698449539441374295770236407991735029336433231649246775082939325523552031992","best_ask":"0.51","best_bid":"0.5","hash":"3f8d010eaec6d4d88554c6277d5ae72d8702e148","price":"0.54","side":"SELL","size":"169.57"}],"timestamp":"1785121613427"},"payload_hash":"d11a9df291833920fea7ff02552fc55c3ba70521d9b49505af69ca1c68a864cd","raw_frame":"{\"market\":\"0xf9d60bb033695053c4d1d8592e52171c1042f64b41a4b72e09dcc6f4852b6670\", \"price_changes\":[{\"asset_id\":\"96283536366176669581486355171583722558858323126916278856549586825357358273536\", \"price\":\"0.46\", \"size\":\"169.57\", \"side\":\"BUY\", \"hash\":\"d87c2cacb168e43e0981f1f98e5971161368a431\", \"best_bid\":\"0.49\", \"best_ask\":\"0.5\"}, {\"asset_id\":\"8698449539441374295770236407991735029336433231649246775082939325523552031992\", \"price\":\"0.54\", \"size\":\"169.57\", \"side\":\"SELL\", \"hash\":\"3f8d010eaec6d4d88554c6277d5ae72d8702e148\", \"best_bid\":\"0.5\", \"best_ask\":\"0.51\"}], \"timestamp\":\"1785121613427\", \"event_type\":\"price_change\"}","received_at":"2026-07-27T03:06:53.334717Z","schema_version":"clob-market-ws.price_change.v1","sequence":null,"server_hash":null,"server_timestamp":"1785121613427","session_id":"ff6d21c8283948938400a32613abec2c","source":"clob_market_ws"},"received_at":"2026-07-27T03:06:53.334717Z","record_id":"ae0d25e21bc129bbf668e8e4a270f2cb1f89c30323412f0bc9a9268698cc1cf2","schema_fingerprint":"4aa3821a28b0b7c2400bc59aba4bcc0a76e971dadd19610d3ad38c768e124dc7","schema_version":"edge-lab-recorder.raw.v1","sequence":null,"source":"clob_market_ws"}
{"event_at":"2026-07-27T03:06:53.427000Z","event_fingerprint":"06ff10044b232499bcc549005608d388edc7bce3885c0c55c8c8edbba58a1c43","payload":{"connection_id":"f95883f18d264834af91809e5f803e9f","event_at":"2026-07-27T03:06:53.427000Z","event_type":"price_change","frame_hash":"b430b3d5ddcd7100b7553e4181b7585c5dbe6166714fe36fbcbab1ee29bd0bad","frame_index":0,"kind":"data","monotonic_ns":223596663004458,"payload":{"event_type":"price_change","market":"0xf9d60bb033695053c4d1d8592e52171c1042f64b41a4b72e09dcc6f4852b6670","price_changes":[{"asset_id":"8698449539441374295770236407991735029336433231649246775082939325523552031992","best_ask":"0.51","best_bid":"0.5","hash":"3f8d010eaec6d4d88554c6277d5ae72d8702e148","price":"0.5","side":"BUY","size":"100"},{"asset_id":"96283536366176669581486355171583722558858323126916278856549586825357358273536","best_ask":"0.5","best_bid":"0.49","hash":"d87c2cacb168e43e0981f1f98e5971161368a431","price":"0.5","side":"SELL","size":"100"}],"timestamp":"1785121613427"},"payload_hash":"cb1b7553376816c0d89abb9fafbf928c90515cc4559bd25eaa991dad96f6cc4f","raw_frame":"{\"market\":\"0xf9d60bb033695053c4d1d8592e52171c1042f64b41a4b72e09dcc6f4852b6670\", \"price_changes\":[{\"asset_id\":\"8698449539441374295770236407991735029336433231649246775082939325523552031992\", \"price\":\"0.5\", \"size\":\"100\", \"side\":\"BUY\", \"hash\":\"3f8d010eaec6d4d88554c6277d5ae72d8702e148\", \"best_bid\":\"0.5\", \"best_ask\":\"0.51\"}, {\"asset_id\":\"96283536366176669581486355171583722558858323126916278856549586825357358273536\", \"price\":\"0.5\", \"size\":\"100\", \"side\":\"SELL\", \"hash\":\"d87c2cacb168e43e0981f1f98e5971161368a431\", \"best_bid\":\"0.49\", \"best_ask\":\"0.5\"}], \"timestamp\":\"1785121613427\", \"event_type\":\"price_change\"}","received_at":"2026-07-27T03:06:53.336164Z","schema_version":"clob-market-ws.price_change.v1","sequence":null,"server_hash":null,"server_timestamp":"1785121613427","session_id":"ff6d21c8283948938400a32613abec2c","source":"clob_market_ws"},"received_at":"2026-07-27T03:06:53.336164Z","record_id":"7fcc079679e85665664c7867e8111c2dd6d4a8f8bdd9b325c99ac1d7904418ba","schema_fingerprint":"4aa3821a28b0b7c2400bc59aba4bcc0a76e971dadd19610d3ad38c768e124dc7","schema_version":"edge-lab-recorder.raw.v1","sequence":null,"source":"clob_market_ws"}
{"event_at":"2026-07-27T03:06:53.429000Z","event_fingerprint":"9f0d450aa95819d5b01ddeb1f7109f69fdd85cb4ebda51c308c1dcbb869eb723","payload":{"connection_id":"f95883f18d264834af91809e5f803e9f","event_at":"2026-07-27T03:06:53.429000Z","event_type":"best_bid_ask","frame_hash":"ad9bd40e1a038782af0c7a3f838888cfb43e6a34da77027d16af68bdc3cf07fc","frame_index":0,"kind":"data","monotonic_ns":223596664550625,"payload":{"asset_id":"8698449539441374295770236407991735029336433231649246775082939325523552031992","best_ask":"0.51","best_bid":"0.49","event_type":"best_bid_ask","market":"0xf9d60bb033695053c4d1d8592e52171c1042f64b41a4b72e09dcc6f4852b6670","spread":"0.02","timestamp":"1785121613429"},"payload_hash":"e1c1de744fdb9f3e8ac8f34ba8320423b6da29b542418e4273edc423f154e7f5","raw_frame":"{\"market\":\"0xf9d60bb033695053c4d1d8592e52171c1042f64b41a4b72e09dcc6f4852b6670\", \"asset_id\":\"8698449539441374295770236407991735029336433231649246775082939325523552031992\", \"best_bid\":\"0.49\", \"best_ask\":\"0.51\", \"spread\":\"0.02\", \"timestamp\":\"1785121613429\", \"event_type\":\"best_bid_ask\"}","received_at":"2026-07-27T03:06:53.337708Z","schema_version":"clob-market-ws.best_bid_ask.v1","sequence":null,"server_hash":null,"server_timestamp":"1785121613429","session_id":"ff6d21c8283948938400a32613abec2c","source":"clob_market_ws"},"received_at":"2026-07-27T03:06:53.337708Z","record_id":"953c462712818275959498e8d15ea4ab7fbcf356841fe5574e424859a9699208","schema_fingerprint":"8488399f31b0337811b13b266be932db7062827c2470b78bd8e9e99bab51d17d","schema_version":"edge-lab-recorder.raw.v1","sequence":null,"source":"clob_market_ws"}
{"event_at":"2026-07-27T03:06:53.429000Z","event_fingerprint":"240a4f2eb83977293eb98cb6b984cd99a4fd2c567d97fbbb094861a451d8f906","payload":{"connection_id":"f95883f18d264834af91809e5f803e9f","event_at":"2026-07-27T03:06:53.429000Z","event_type":"best_bid_ask","frame_hash":"6555fe90f15ed08b9600070e1978e4ecd22b1842526db46e8863a506774d735a","frame_index":0,"kind":"data","monotonic_ns":223596665489875,"payload":{"asset_id":"96283536366176669581486355171583722558858323126916278856549586825357358273536","best_ask":"0.51","best_bid":"0.49","event_type":"best_bid_ask","market":"0xf9d60bb033695053c4d1d8592e52171c1042f64b41a4b72e09dcc6f4852b6670","spread":"0.02","timestamp":"1785121613429"},"payload_hash":"a8ce619a09f860bdb98cc2eb596d6b3b4deb17c087b37eb85bb16f546fc2de4b","raw_frame":"{\"market\":\"0xf9d60bb033695053c4d1d8592e52171c1042f64b41a4b72e09dcc6f4852b6670\", \"asset_id\":\"96283536366176669581486355171583722558858323126916278856549586825357358273536\", \"best_bid\":\"0.49\", \"best_ask\":\"0.51\", \"spread\":\"0.02\", \"timestamp\":\"1785121613429\", \"event_type\":\"best_bid_ask\"}","received_at":"2026-07-27T03:06:53.338654Z","schema_version":"clob-market-ws.best_bid_ask.v1","sequence":null,"server_hash":null,"server_timestamp":"1785121613429","session_id":"ff6d21c8283948938400a32613abec2c","source":"clob_market_ws"},"received_at":"2026-07-27T03:06:53.338654Z","record_id":"d803bff5ab57f83d8e490366a4214da0c42ccd23131bebd7223fe522cdf778da","schema_fingerprint":"8488399f31b0337811b13b266be932db7062827c2470b78bd8e9e99bab51d17d","schema_version":"edge-lab-recorder.raw.v1","sequence":null,"source":"clob_market_ws"}
{"event_at":"2026-07-27T03:06:53.429000Z","event_fingerprint":"f2e1443a67ab637521869457a1bec25fd1dde6fd7a1653ae636a15d0c6143a3e","payload":{"connection_id":"f95883f18d264834af91809e5f803e9f","event_at":"2026-07-27T03:06:53.429000Z","event_type":"price_change","frame_hash":"3cfef42387ae93d2deb20e23564dfa7adf09fe12df3445efbbb52742c7354c8b","frame_index":0,"kind":"data","monotonic_ns":223596665849791,"payload":{"event_type":"price_change","market":"0xf9d60bb033695053c4d1d8592e52171c1042f64b41a4b72e09dcc6f4852b6670","price_changes":[{"asset_id":"96283536366176669581486355171583722558858323126916278856549586825357358273536","best_ask":"0.51","best_bid":"0.49","hash":"1ac8c39e2ac70eb85cfcdbcd6100bf99f982a227","price":"0.46","side":"BUY","size":"69.57"},{"asset_id":"8698449539441374295770236407991735029336433231649246775082939325523552031992","best_ask":"0.51","best_bid":"0.49","hash":"e013a50aec301f4cb33ecf7cfd139e6cb5e76eca","price":"0.54","side":"SELL","size":"69.57"}],"timestamp":"1785121613429"},"payload_hash":"2feba1468976457735628887596b2be6969cec1013038a4f21f539597df75078","raw_frame":"{\"market\":\"0xf9d60bb033695053c4d1d8592e52171c1042f64b41a4b72e09dcc6f4852b6670\", \"price_changes\":[{\"asset_id\":\"96283536366176669581486355171583722558858323126916278856549586825357358273536\", \"price\":\"0.46\", \"size\":\"69.57\", \"side\":\"BUY\", \"hash\":\"1ac8c39e2ac70eb85cfcdbcd6100bf99f982a227\", \"best_bid\":\"0.49\", \"best_ask\":\"0.51\"}, {\"asset_id\":\"8698449539441374295770236407991735029336433231649246775082939325523552031992\", \"price\":\"0.54\", \"size\":\"69.57\", \"side\":\"SELL\", \"hash\":\"e013a50aec301f4cb33ecf7cfd139e6cb5e76eca\", \"best_bid\":\"0.49\", \"best_ask\":\"0.51\"}], \"timestamp\":\"1785121613429\", \"event_type\":\"price_change\"}","received_at":"2026-07-27T03:06:53.339013Z","schema_version":"clob-market-ws.price_change.v1","sequence":null,"server_hash":null,"server_timestamp":"1785121613429","session_id":"ff6d21c8283948938400a32613abec2c","source":"clob_market_ws"},"received_at":"2026-07-27T03:06:53.339013Z","record_id":"11ca61d5521efae6cd9abbe9d699ad70aa6c24ffe8306f2c304f83469a394e03","schema_fingerprint":"4aa3821a28b0b7c2400bc59aba4bcc0a76e971dadd19610d3ad38c768e124dc7","schema_version":"edge-lab-recorder.raw.v1","sequence":null,"source":"clob_market_ws"}
{"event_at":"2026-07-27T03:06:53.429000Z","event_fingerprint":"3d159e54bc955d912b9d54a16e94bf1ae27c9935cef02c9b0bd58ce4dc35d5fd","payload":{"connection_id":"f95883f18d264834af91809e5f803e9f","event_at":"2026-07-27T03:06:53.429000Z","event_type":"price_change","frame_hash":"33e133d65041704d51344dcac797bc301c8882ec23f7212dbfbb21bc79bf9f4a","frame_index":0,"kind":"data","monotonic_ns":223596666667291,"payload":{"event_type":"price_change","market":"0xf9d60bb033695053c4d1d8592e52171c1042f64b41a4b72e09dcc6f4852b6670","price_changes":[{"asset_id":"8698449539441374295770236407991735029336433231649246775082939325523552031992","best_ask":"0.51","best_bid":"0.49","hash":"e013a50aec301f4cb33ecf7cfd139e6cb5e76eca","price":"0.5","side":"BUY","size":"0"},{"asset_id":"96283536366176669581486355171583722558858323126916278856549586825357358273536","best_ask":"0.51","best_bid":"0.49","hash":"1ac8c39e2ac70eb85cfcdbcd6100bf99f982a227","price":"0.5","side":"SELL","size":"0"}],"timestamp":"1785121613429"},"payload_hash":"ca30adcc06bb8a504d695f74f404116211e8cebeeec959befeffdc881a0a764e","raw_frame":"{\"market\":\"0xf9d60bb033695053c4d1d8592e52171c1042f64b41a4b72e09dcc6f4852b6670\", \"price_changes\":[{\"asset_id\":\"8698449539441374295770236407991735029336433231649246775082939325523552031992\", \"price\":\"0.5\", \"size\":\"0\", \"side\":\"BUY\", \"hash\":\"e013a50aec301f4cb33ecf7cfd139e6cb5e76eca\", \"best_bid\":\"0.49\", \"best_ask\":\"0.51\"}, {\"asset_id\":\"96283536366176669581486355171583722558858323126916278856549586825357358273536\", \"price\":\"0.5\", \"size\":\"0\", \"side\":\"SELL\", \"hash\":\"1ac8c39e2ac70eb85cfcdbcd6100bf99f982a227\", \"best_bid\":\"0.49\", \"best_ask\":\"0.51\"}], \"timestamp\":\"1785121613429\", \"event_type\":\"price_change\"}","received_at":"2026-07-27T03:06:53.339825Z","schema_version":"clob-market-ws.price_change.v1","sequence":null,"server_hash":null,"server_timestamp":"1785121613429","session_id":"ff6d21c8283948938400a32613abec2c","source":"clob_market_ws"},"received_at":"2026-07-27T03:06:53.339825Z","record_id":"d0f9148dca2ee0403671292ccd8a5a22f2ea29871f0b37cb2d40df9873939d7d","schema_fingerprint":"4aa3821a28b0b7c2400bc59aba4bcc0a76e971dadd19610d3ad38c768e124dc7","schema_version":"edge-lab-recorder.raw.v1","sequence":null,"source":"clob_market_ws"}
{"event_at":"2026-07-27T03:06:53.463000Z","event_fingerprint":"851e80e079354944d6adf92392a4bfbbfd519fc1f20dbce834e13194c0d5b773","payload":{"connection_id":"f95883f18d264834af91809e5f803e9f","event_at":"2026-07-27T03:06:53.463000Z","event_type":"price_change","frame_hash":"fb76e00b9edd37a1f7222e7537e74a852aa053283e057adb54e8a5a25e2c7c5a","frame_index":0,"kind":"data","monotonic_ns":223596695999166,"payload":{"event_type":"price_change","market":"0xf9d60bb033695053c4d1d8592e52171c1042f64b41a4b72e09dcc6f4852b6670","price_changes":[{"asset_id":"8698449539441374295770236407991735029336433231649246775082939325523552031992","best_ask":"0.51","best_bid":"0.49","hash":"b39708aa9aa6c07a515bcac2dbedbc11d59bc8af","price":"0.41","side":"BUY","size":"185.1"},{"asset_id":"96283536366176669581486355171583722558858323126916278856549586825357358273536","best_ask":"0.51","best_bid":"0.49","hash":"16a5e393487c0d7af039d92653c2ee8032f36342","price":"0.59","side":"SELL","size":"185.1"}],"timestamp":"1785121613463"},"payload_hash":"9bb9703033a2f409911e7b9fb4bd2c467f4931e31d8322532782b120bcc65bbe","raw_frame":"{\"market\":\"0xf9d60bb033695053c4d1d8592e52171c1042f64b41a4b72e09dcc6f4852b6670\", \"price_changes\":[{\"asset_id\":\"8698449539441374295770236407991735029336433231649246775082939325523552031992\", \"price\":\"0.41\", \"size\":\"185.1\", \"side\":\"BUY\", \"hash\":\"b39708aa9aa6c07a515bcac2dbedbc11d59bc8af\", \"best_bid\":\"0.49\", \"best_ask\":\"0.51\"}, {\"asset_id\":\"96283536366176669581486355171583722558858323126916278856549586825357358273536\", \"price\":\"0.59\", \"size\":\"185.1\", \"side\":\"SELL\", \"hash\":\"16a5e393487c0d7af039d92653c2ee8032f36342\", \"best_bid\":\"0.49\", \"best_ask\":\"0.51\"}], \"timestamp\":\"1785121613463\", \"event_type\":\"price_change\"}","received_at":"2026-07-27T03:06:53.369159Z","schema_version":"clob-market-ws.price_change.v1","sequence":null,"server_hash":null,"server_timestamp":"1785121613463","session_id":"ff6d21c8283948938400a32613abec2c","source":"clob_market_ws"},"received_at":"2026-07-27T03:06:53.369159Z","record_id":"f12fdea6e85d1f2bfb4d73793fc82284f37384bd6d4a73590ebf0babcf997317","schema_fingerprint":"4aa3821a28b0b7c2400bc59aba4bcc0a76e971dadd19610d3ad38c768e124dc7","schema_version":"edge-lab-recorder.raw.v1","sequence":null,"source":"clob_market_ws"}
{"event_at":"2026-07-27T03:06:53.463000Z","event_fingerprint":"f218a1cc33cdba8d379ed9382e7bb85f053c5f6e5bb4cb63c180d2742ed03a93","payload":{"connection_id":"f95883f18d264834af91809e5f803e9f","event_at":"2026-07-27T03:06:53.463000Z","event_type":"price_change","frame_hash":"162d8bf8dd5680b8309761a53949a7656b710c6e9a1c7fb6ce3ea59a93101ba2","frame_index":0,"kind":"data","monotonic_ns":223596696798333,"payload":{"event_type":"price_change","market":"0xf9d60bb033695053c4d1d8592e52171c1042f64b41a4b72e09dcc6f4852b6670","price_changes":[{"asset_id":"96283536366176669581486355171583722558858323126916278856549586825357358273536","best_ask":"0.51","best_bid":"0.49","hash":"16a5e393487c0d7af039d92653c2ee8032f36342","price":"0.45","side":"BUY","size":"79.78"},{"asset_id":"8698449539441374295770236407991735029336433231649246775082939325523552031992","best_ask":"0.51","best_bid":"0.49","hash":"b39708aa9aa6c07a515bcac2dbedbc11d59bc8af","price":"0.55","side":"SELL","size":"79.78"}],"timestamp":"1785121613463"},"payload_hash":"d342e525d7693b8a4d77d876cb17dfa7105d938ddff17feddb2373ab84d5f689","raw_frame":"{\"market\":\"0xf9d60bb033695053c4d1d8592e52171c1042f64b41a4b72e09dcc6f4852b6670\", \"price_changes\":[{\"asset_id\":\"96283536366176669581486355171583722558858323126916278856549586825357358273536\", \"price\":\"0.45\", \"size\":\"79.78\", \"side\":\"BUY\", \"hash\":\"16a5e393487c0d7af039d92653c2ee8032f36342\", \"best_bid\":\"0.49\", \"best_ask\":\"0.51\"}, {\"asset_id\":\"8698449539441374295770236407991735029336433231649246775082939325523552031992\", \"price\":\"0.55\", \"size\":\"79.78\", \"side\":\"SELL\", \"hash\":\"b39708aa9aa6c07a515bcac2dbedbc11d59bc8af\", \"best_bid\":\"0.49\", \"best_ask\":\"0.51\"}], \"timestamp\":\"1785121613463\", \"event_type\":\"price_change\"}","received_at":"2026-07-27T03:06:53.369961Z","schema_version":"clob-market-ws.price_change.v1","sequence":null,"server_hash":null,"server_timestamp":"1785121613463","session_id":"ff6d21c8283948938400a32613abec2c","source":"clob_market_ws"},"received_at":"2026-07-27T03:06:53.369961Z","record_id":"06682003fc3df3df486d07deabdc9d8de3ecc7eaa43ceca27b6702fc874a4c6a","schema_fingerprint":"4aa3821a28b0b7c2400bc59aba4bcc0a76e971dadd19610d3ad38c768e124dc7","schema_version":"edge-lab-recorder.raw.v1","sequence":null,"source":"clob_market_ws"}
{"event_at":"2026-07-27T03:06:53.463000Z","event_fingerprint":"908722c095d6b71ce29fa82ea08df613b4a2528d1f6b5cd600418cefb1c83dd6","payload":{"connection_id":"f95883f18d264834af91809e5f803e9f","event_at":"2026-07-27T03:06:53.463000Z","event_type":"price_change","frame_hash":"7d088cc1862ec873375af79a9247bcbdf097292e34649e8a6645f0ab44c81d05","frame_index":0,"kind":"data","monotonic_ns":223596697463666,"payload":{"event_type":"price_change","market":"0xf9d60bb033695053c4d1d8592e52171c1042f64b41a4b72e09dcc6f4852b6670","price_changes":[{"asset_id":"96283536366176669581486355171583722558858323126916278856549586825357358273536","best_ask":"0.51","best_bid":"0.49","hash":"16a5e393487c0d7af039d92653c2ee8032f36342","price":"0.47","side":"BUY","size":"234.36"},{"asset_id":"8698449539441374295770236407991735029336433231649246775082939325523552031992","best_ask":"0.51","best_bid":"0.49","hash":"b39708aa9aa6c07a515bcac2dbedbc11d59bc8af","price":"0.53","side":"SELL","size":"234.36"}],"timestamp":"1785121613463"},"payload_hash":"1fc61fb70b178b41701364ec601fef1561d520a51264b52507741ed170cb8f99","raw_frame":"{\"market\":\"0xf9d60bb033695053c4d1d8592e52171c1042f64b41a4b72e09dcc6f4852b6670\", \"price_changes\":[{\"asset_id\":\"96283536366176669581486355171583722558858323126916278856549586825357358273536\", \"price\":\"0.47\", \"size\":\"234.36\", \"side\":\"BUY\", \"hash\":\"16a5e393487c0d7af039d92653c2ee8032f36342\", \"best_bid\":\"0.49\", \"best_ask\":\"0.51\"}, {\"asset_id\":\"8698449539441374295770236407991735029336433231649246775082939325523552031992\", \"price\":\"0.53\", \"size\":\"234.36\", \"side\":\"SELL\", \"hash\":\"b39708aa9aa6c07a515bcac2dbedbc11d59bc8af\", \"best_bid\":\"0.49\", \"best_ask\":\"0.51\"}], \"timestamp\":\"1785121613463\", \"event_type\":\"price_change\"}","received_at":"2026-07-27T03:06:53.370625Z","schema_version":"clob-market-ws.price_change.v1","sequence":null,"server_hash":null,"server_timestamp":"1785121613463","session_id":"ff6d21c8283948938400a32613abec2c","source":"clob_market_ws"},"received_at":"2026-07-27T03:06:53.370625Z","record_id":"77fdb82d3e8c5b9ba065c6fa2d9c1777c62126356f3e3970f82cb32341dee478","schema_fingerprint":"4aa3821a28b0b7c2400bc59aba4bcc0a76e971dadd19610d3ad38c768e124dc7","schema_version":"edge-lab-recorder.raw.v1","sequence":null,"source":"clob_market_ws"}
{"event_at":"2026-07-27T03:06:53.488000Z","event_fingerprint":"810fa139731e26e765cfe4deeb5e6e925c8c80e4582c02177117f6b3f23c2635","payload":{"connection_id":"f95883f18d264834af91809e5f803e9f","event_at":"2026-07-27T03:06:53.488000Z","event_type":"price_change","frame_hash":"837b77569ac403081365d8036725620a54b1f06c4f1a4c5ea77adf423aabf11f","frame_index":0,"kind":"data","monotonic_ns":223596722072041,"payload":{"event_type":"price_change","market":"0xf9d60bb033695053c4d1d8592e52171c1042f64b41a4b72e09dcc6f4852b6670","price_changes":[{"asset_id":"96283536366176669581486355171583722558858323126916278856549586825357358273536","best_ask":"0.51","best_bid":"0.49","hash":"f23abe422a385803aa52e491e3853ecd3e2bc881","price":"0.49","side":"BUY","size":"30"},{"asset_id":"8698449539441374295770236407991735029336433231649246775082939325523552031992","best_ask":"0.51","best_bid":"0.49","hash":"d98d43d317e8b79d800aa8f82c8e0404c6004073","price":"0.51","side":"SELL","size":"30"}],"timestamp":"1785121613488"},"payload_hash":"7b9a4ef4b51bbfb9812cc8cc2b6965c28f89996a58b5fb85275a563d08645b9c","raw_frame":"{\"market\":\"0xf9d60bb033695053c4d1d8592e52171c1042f64b41a4b72e09dcc6f4852b6670\", \"price_changes\":[{\"asset_id\":\"96283536366176669581486355171583722558858323126916278856549586825357358273536\", \"price\":\"0.49\", \"size\":\"30\", \"side\":\"BUY\", \"hash\":\"f23abe422a385803aa52e491e3853ecd3e2bc881\", \"best_bid\":\"0.49\", \"best_ask\":\"0.51\"}, {\"asset_id\":\"8698449539441374295770236407991735029336433231649246775082939325523552031992\", \"price\":\"0.51\", \"size\":\"30\", \"side\":\"SELL\", \"hash\":\"d98d43d317e8b79d800aa8f82c8e0404c6004073\", \"best_bid\":\"0.49\", \"best_ask\":\"0.51\"}], \"timestamp\":\"1785121613488\", \"event_type\":\"price_change\"}","received_at":"2026-07-27T03:06:53.395234Z","schema_version":"clob-market-ws.price_change.v1","sequence":null,"server_hash":null,"server_timestamp":"1785121613488","session_id":"ff6d21c8283948938400a32613abec2c","source":"clob_market_ws"},"received_at":"2026-07-27T03:06:53.395234Z","record_id":"460a9ec73004ff3a3a98f59e952281d1dcbf314f81f555dcdb77becdd1faf9f6","schema_fingerprint":"4aa3821a28b0b7c2400bc59aba4bcc0a76e971dadd19610d3ad38c768e124dc7","schema_version":"edge-lab-recorder.raw.v1","sequence":null,"source":"clob_market_ws"}
{"event_at":"2026-07-27T03:06:53.490000Z","event_fingerprint":"d560121324404377c3ca36bfdcd1d38e62d568065ad1e39d4350532aa7a69b17","payload":{"connection_id":"f95883f18d264834af91809e5f803e9f","event_at":"2026-07-27T03:06:53.490000Z","event_type":"price_change","frame_hash":"db7b0c7f122c22b19b13b07f13c7c57597776f9c3f50172a507cfa944fff739f","frame_index":0,"kind":"data","monotonic_ns":223596724042041,"payload":{"event_type":"price_change","market":"0xf9d60bb033695053c4d1d8592e52171c1042f64b41a4b72e09dcc6f4852b6670","price_changes":[{"asset_id":"8698449539441374295770236407991735029336433231649246775082939325523552031992","best_ask":"0.51","best_bid":"0.49","hash":"ab5d3cfef3e7c4e1b99a127031eac2f62e07b1e0","price":"0.47","side":"BUY","size":"69.45"},{"asset_id":"96283536366176669581486355171583722558858323126916278856549586825357358273536","best_ask":"0.51","best_bid":"0.49","hash":"5b44effb0b51e3be5c29b5abd03986d0210f2d8f","price":"0.53","side":"SELL","size":"69.45"}],"timestamp":"1785121613490"},"payload_hash":"39c32ecadd5120fb5914545dd9c7532262663c8e96255f31a9e7636efff28f42","raw_frame":"{\"market\":\"0xf9d60bb033695053c4d1d8592e52171c1042f64b41a4b72e09dcc6f4852b6670\", \"price_changes\":[{\"asset_id\":\"8698449539441374295770236407991735029336433231649246775082939325523552031992\", \"price\":\"0.47\", \"size\":\"69.45\", \"side\":\"BUY\", \"hash\":\"ab5d3cfef3e7c4e1b99a127031eac2f62e07b1e0\", \"best_bid\":\"0.49\", \"best_ask\":\"0.51\"}, {\"asset_id\":\"96283536366176669581486355171583722558858323126916278856549586825357358273536\", \"price\":\"0.53\", \"size\":\"69.45\", \"side\":\"SELL\", \"hash\":\"5b44effb0b51e3be5c29b5abd03986d0210f2d8f\", \"best_bid\":\"0.49\", \"best_ask\":\"0.51\"}], \"timestamp\":\"1785121613490\", \"event_type\":\"price_change\"}","received_at":"2026-07-27T03:06:53.397203Z","schema_version":"clob-market-ws.price_change.v1","sequence":null,"server_hash":null,"server_timestamp":"1785121613490","session_id":"ff6d21c8283948938400a32613abec2c","source":"clob_market_ws"},"received_at":"2026-07-27T03:06:53.397203Z","record_id":"3b633e7f319990774f87584248d5cba60415ba7d8ad6c17aaa6fcefa20c7f098","schema_fingerprint":"4aa3821a28b0b7c2400bc59aba4bcc0a76e971dadd19610d3ad38c768e124dc7","schema_version":"edge-lab-recorder.raw.v1","sequence":null,"source":"clob_market_ws"}
{"event_at":"2026-07-27T03:06:53.491000Z","event_fingerprint":"0cadef117a62c6d3fe5204a6c32680d3ed622841811faf05d1e2a7b590bac012","payload":{"connection_id":"f95883f18d264834af91809e5f803e9f","event_at":"2026-07-27T03:06:53.491000Z","event_type":"price_change","frame_hash":"6a9f9c54ff399ced0850baa964644821407c4a29104446c2b00554bcde0c5add","frame_index":0,"kind":"data","monotonic_ns":223596724588333,"payload":{"event_type":"price_change","market":"0xf9d60bb033695053c4d1d8592e52171c1042f64b41a4b72e09dcc6f4852b6670","price_changes":[{"asset_id":"8698449539441374295770236407991735029336433231649246775082939325523552031992","best_ask":"0.51","best_bid":"0.49","hash":"08e4cbe28cacba877abc8579de4a9f6287288255","price":"0.47","side":"BUY","size":"74.45"},{"asset_id":"96283536366176669581486355171583722558858323126916278856549586825357358273536","best_ask":"0.51","best_bid":"0.49","hash":"4a64dd1bd4e517f5c43f0f76760a3e8486a2b521","price":"0.53","side":"SELL","size":"74.45"}],"timestamp":"1785121613491"},"payload_hash":"f1a25ceb072c50b19daebd4157941c4c002517024710f082da609fce8b01125b","raw_frame":"{\"market\":\"0xf9d60bb033695053c4d1d8592e52171c1042f64b41a4b72e09dcc6f4852b6670\", \"price_changes\":[{\"asset_id\":\"8698449539441374295770236407991735029336433231649246775082939325523552031992\", \"price\":\"0.47\", \"size\":\"74.45\", \"side\":\"BUY\", \"hash\":\"08e4cbe28cacba877abc8579de4a9f6287288255\", \"best_bid\":\"0.49\", \"best_ask\":\"0.51\"}, {\"asset_id\":\"96283536366176669581486355171583722558858323126916278856549586825357358273536\", \"price\":\"0.53\", \"size\":\"74.45\", \"side\":\"SELL\", \"hash\":\"4a64dd1bd4e517f5c43f0f76760a3e8486a2b521\", \"best_bid\":\"0.49\", \"best_ask\":\"0.51\"}], \"timestamp\":\"1785121613491\", \"event_type\":\"price_change\"}","received_at":"2026-07-27T03:06:53.397750Z","schema_version":"clob-market-ws.price_change.v1","sequence":null,"server_hash":null,"server_timestamp":"1785121613491","session_id":"ff6d21c8283948938400a32613abec2c","source":"clob_market_ws"},"received_at":"2026-07-27T03:06:53.397750Z","record_id":"dad7c5bd24742d25b962b66b194c1601bb39f7268a111db70f68bd0a93c4b75c","schema_fingerprint":"4aa3821a28b0b7c2400bc59aba4bcc0a76e971dadd19610d3ad38c768e124dc7","schema_version":"edge-lab-recorder.raw.v1","sequence":null,"source":"clob_market_ws"}
{"event_at":"2026-07-27T03:06:53.492000Z","event_fingerprint":"4aa0dc3497f4b60c5687d105a9ddb6a98d5a7a3e63634ab21387a2b259b2ec80","payload":{"connection_id":"f95883f18d264834af91809e5f803e9f","event_at":"2026-07-27T03:06:53.492000Z","event_type":"price_change","frame_hash":"1e7bf95707f2f8a47573a51a76b08ddf9f52af5574d6b427ae9f3244fa4a30b8","frame_index":0,"kind":"data","monotonic_ns":223596725123791,"payload":{"event_type":"price_change","market":"0xf9d60bb033695053c4d1d8592e52171c1042f64b41a4b72e09dcc6f4852b6670","price_changes":[{"asset_id":"96283536366176669581486355171583722558858323126916278856549586825357358273536","best_ask":"0.51","best_bid":"0.49","hash":"6ffe968df2cdfa3d147453c42675ce0d77d76908","price":"0.49","side":"BUY","size":"35"},{"asset_id":"8698449539441374295770236407991735029336433231649246775082939325523552031992","best_ask":"0.51","best_bid":"0.49","hash":"77e7748831b3302f986e93c0005cd2116850079c","price":"0.51","side":"SELL","size":"35"}],"timestamp":"1785121613492"},"payload_hash":"95f873eed49770571a8ded939d3e5e688ea2229820d3d93d51d3d05ce80a9aaf","raw_frame":"{\"market\":\"0xf9d60bb033695053c4d1d8592e52171c1042f64b41a4b72e09dcc6f4852b6670\", \"price_changes\":[{\"asset_id\":\"96283536366176669581486355171583722558858323126916278856549586825357358273536\", \"price\":\"0.49\", \"size\":\"35\", \"side\":\"BUY\", \"hash\":\"6ffe968df2cdfa3d147453c42675ce0d77d76908\", \"best_bid\":\"0.49\", \"best_ask\":\"0.51\"}, {\"asset_id\":\"8698449539441374295770236407991735029336433231649246775082939325523552031992\", \"price\":\"0.51\", \"size\":\"35\", \"side\":\"SELL\", \"hash\":\"77e7748831b3302f986e93c0005cd2116850079c\", \"best_bid\":\"0.49\", \"best_ask\":\"0.51\"}], \"timestamp\":\"1785121613492\", \"event_type\":\"price_change\"}","received_at":"2026-07-27T03:06:53.398286Z","schema_version":"clob-market-ws.price_change.v1","sequence":null,"server_hash":null,"server_timestamp":"1785121613492","session_id":"ff6d21c8283948938400a32613abec2c","source":"clob_market_ws"},"received_at":"2026-07-27T03:06:53.398286Z","record_id":"0526770eff220ccc9bab1df35bd30c8c4bf29dc58312c3d87807617910337714","schema_fingerprint":"4aa3821a28b0b7c2400bc59aba4bcc0a76e971dadd19610d3ad38c768e124dc7","schema_version":"edge-lab-recorder.raw.v1","sequence":null,"source":"clob_market_ws"}
{"event_at":"2026-07-27T03:06:53.493000Z","event_fingerprint":"44b72d57baeaca0c30382e019c857389cb7965f1e44ca2ee9860f4ae348c0161","payload":{"connection_id":"f95883f18d264834af91809e5f803e9f","event_at":"2026-07-27T03:06:53.493000Z","event_type":"price_change","frame_hash":"2ea226e560b366e16f794466442982969ba015649f68e5e036558fe464bf3f92","frame_index":0,"kind":"data","monotonic_ns":223596730272291,"payload":{"event_type":"price_change","market":"0xf9d60bb033695053c4d1d8592e52171c1042f64b41a4b72e09dcc6f4852b6670","price_changes":[{"asset_id":"8698449539441374295770236407991735029336433231649246775082939325523552031992","best_ask":"0.51","best_bid":"0.49","hash":"ca8463e280cba1d718903346129fd186629669a8","price":"0.47","side":"BUY","size":"79.45"},{"asset_id":"96283536366176669581486355171583722558858323126916278856549586825357358273536","best_ask":"0.51","best_bid":"0.49","hash":"ad01137eb13fe1b1052f8a06cc5b5b7079f10d73","price":"0.53","side":"SELL","size":"79.45"}],"timestamp":"1785121613493"},"payload_hash":"4a67a40ad787198c9a97bc93f3e3dd845670ae12f7648bf4c65ab256839b2802","raw_frame":"{\"market\":\"0xf9d60bb033695053c4d1d8592e52171c1042f64b41a4b72e09dcc6f4852b6670\", \"price_changes\":[{\"asset_id\":\"8698449539441374295770236407991735029336433231649246775082939325523552031992\", \"price\":\"0.47\", \"size\":\"79.45\", \"side\":\"BUY\", \"hash\":\"ca8463e280cba1d718903346129fd186629669a8\", \"best_bid\":\"0.49\", \"best_ask\":\"0.51\"}, {\"asset_id\":\"96283536366176669581486355171583722558858323126916278856549586825357358273536\", \"price\":\"0.53\", \"size\":\"79.45\", \"side\":\"SELL\", \"hash\":\"ad01137eb13fe1b1052f8a06cc5b5b7079f10d73\", \"best_bid\":\"0.49\", \"best_ask\":\"0.51\"}], \"timestamp\":\"1785121613493\", \"event_type\":\"price_change\"}","received_at":"2026-07-27T03:06:53.403432Z","schema_version":"clob-market-ws.price_change.v1","sequence":null,"server_hash":null,"server_timestamp":"1785121613493","session_id":"ff6d21c8283948938400a32613abec2c","source":"clob_market_ws"},"received_at":"2026-07-27T03:06:53.403432Z","record_id":"c8f90c6890b0ca12eb9651af8d43b66bc3d24ec31ab5036e631a0d27c5ca85b3","schema_fingerprint":"4aa3821a28b0b7c2400bc59aba4bcc0a76e971dadd19610d3ad38c768e124dc7","schema_version":"edge-lab-recorder.raw.v1","sequence":null,"source":"clob_market_ws"}
{"event_at":"2026-07-27T03:06:53.494000Z","event_fingerprint":"a721012350445a666820a9f3535e6a89b381c1273290db3a5c7749cea2d75fc6","payload":{"connection_id":"f95883f18d264834af91809e5f803e9f","event_at":"2026-07-27T03:06:53.494000Z","event_type":"price_change","frame_hash":"b73d7ecf71eed9ae1f895e845b20d8d3994dbd7114f002e719f6a26dc3adac27","frame_index":0,"kind":"data","monotonic_ns":223596853925458,"payload":{"event_type":"price_change","market":"0xf9d60bb033695053c4d1d8592e52171c1042f64b41a4b72e09dcc6f4852b6670","price_changes":[{"asset_id":"8698449539441374295770236407991735029336433231649246775082939325523552031992","best_ask":"0.51","best_bid":"0.49","hash":"f5f16aed94beacb59aa1b6df8707899496d1f917","price":"0.47","side":"BUY","size":"84.45"},{"asset_id":"96283536366176669581486355171583722558858323126916278856549586825357358273536","best_ask":"0.51","best_bid":"0.49","hash":"f06ca00969d0bbec3ca882546d524112625c86a8","price":"0.53","side":"SELL","size":"84.45"}],"timestamp":"1785121613494"},"payload_hash":"0e24e9d3306b7b83d6eb573973413daa82a3bb2e3e51c9717be378d2838915cc","raw_frame":"{\"market\":\"0xf9d60bb033695053c4d1d8592e52171c1042f64b41a4b72e09dcc6f4852b6670\", \"price_changes\":[{\"asset_id\":\"8698449539441374295770236407991735029336433231649246775082939325523552031992\", \"price\":\"0.47\", \"size\":\"84.45\", \"side\":\"BUY\", \"hash\":\"f5f16aed94beacb59aa1b6df8707899496d1f917\", \"best_bid\":\"0.49\", \"best_ask\":\"0.51\"}, {\"asset_id\":\"96283536366176669581486355171583722558858323126916278856549586825357358273536\", \"price\":\"0.53\", \"size\":\"84.45\", \"side\":\"SELL\", \"hash\":\"f06ca00969d0bbec3ca882546d524112625c86a8\", \"best_bid\":\"0.49\", \"best_ask\":\"0.51\"}], \"timestamp\":\"1785121613494\", \"event_type\":\"price_change\"}","received_at":"2026-07-27T03:06:53.527081Z","schema_version":"clob-market-ws.price_change.v1","sequence":null,"server_hash":null,"server_timestamp":"1785121613494","session_id":"ff6d21c8283948938400a32613abec2c","source":"clob_market_ws"},"received_at":"2026-07-27T03:06:53.527081Z","record_id":"8c1ad72f87c916e54247a2928a6ba8a9fcebedbbfea1f8cdf856ef5f758b3566","schema_fingerprint":"4aa3821a28b0b7c2400bc59aba4bcc0a76e971dadd19610d3ad38c768e124dc7","schema_version":"edge-lab-recorder.raw.v1","sequence":null,"source":"clob_market_ws"}
{"event_at":"2026-07-27T03:06:53.494000Z","event_fingerprint":"74dde23f87ee93b9ceadff8c44fc265b6c2cac3f062cded203eb414c792a1632","payload":{"connection_id":"f95883f18d264834af91809e5f803e9f","event_at":"2026-07-27T03:06:53.494000Z","event_type":"price_change","frame_hash":"0894a9a33195474c762827d00acfb6c33341830cff7dd979d4d834a4f6fa10dd","frame_index":0,"kind":"data","monotonic_ns":223596866279708,"payload":{"event_type":"price_change","market":"0xf9d60bb033695053c4d1d8592e52171c1042f64b41a4b72e09dcc6f4852b6670","price_changes":[{"asset_id":"8698449539441374295770236407991735029336433231649246775082939325523552031992","best_ask":"0.51","best_bid":"0.49","hash":"b6ccc03b158e8d54c2b8b5ea7c4b38da74151f9c","price":"0.47","side":"BUY","size":"89.45"},{"asset_id":"96283536366176669581486355171583722558858323126916278856549586825357358273536","best_ask":"0.51","best_bid":"0.49","hash":"7f4ef071895f8ea3fa1515fe136a87fb07d75e3b","price":"0.53","side":"SELL","size":"89.45"}],"timestamp":"1785121613494"},"payload_hash":"a35211a190d46db0fceda15c49c9c020b52ffaa9070174363298099bf58f902f","raw_frame":"{\"market\":\"0xf9d60bb033695053c4d1d8592e52171c1042f64b41a4b72e09dcc6f4852b6670\", \"price_changes\":[{\"asset_id\":\"8698449539441374295770236407991735029336433231649246775082939325523552031992\", \"price\":\"0.47\", \"size\":\"89.45\", \"side\":\"BUY\", \"hash\":\"b6ccc03b158e8d54c2b8b5ea7c4b38da74151f9c\", \"best_bid\":\"0.49\", \"best_ask\":\"0.51\"}, {\"asset_id\":\"96283536366176669581486355171583722558858323126916278856549586825357358273536\", \"price\":\"0.53\", \"size\":\"89.45\", \"side\":\"SELL\", \"hash\":\"7f4ef071895f8ea3fa1515fe136a87fb07d75e3b\", \"best_bid\":\"0.49\", \"best_ask\":\"0.51\"}], \"timestamp\":\"1785121613494\", \"event_type\":\"price_change\"}","received_at":"2026-07-27T03:06:53.539439Z","schema_version":"clob-market-ws.price_change.v1","sequence":null,"server_hash":null,"server_timestamp":"1785121613494","session_id":"ff6d21c8283948938400a32613abec2c","source":"clob_market_ws"},"received_at":"2026-07-27T03:06:53.539439Z","record_id":"70ec94d38073a88bda61c322bf5199b454f61ddbac3df36982f4bd905ee94686","schema_fingerprint":"4aa3821a28b0b7c2400bc59aba4bcc0a76e971dadd19610d3ad38c768e124dc7","schema_version":"edge-lab-recorder.raw.v1","sequence":null,"source":"clob_market_ws"}
{"event_at":"2026-07-27T03:06:53.496000Z","event_fingerprint":"27760ffd01e8ee10257f77ddc4bf667ce14b18f98ce2222c1da13112e8b38c0f","payload":{"connection_id":"f95883f18d264834af91809e5f803e9f","event_at":"2026-07-27T03:06:53.496000Z","event_type":"price_change","frame_hash":"2ec4ce43cb5702d05993b8e33cdeab0c8866b8b350c20463847b6686d6b226c8","frame_index":0,"kind":"data","monotonic_ns":223596867661000,"payload":{"event_type":"price_change","market":"0xf9d60bb033695053c4d1d8592e52171c1042f64b41a4b72e09dcc6f4852b6670","price_changes":[{"asset_id":"96283536366176669581486355171583722558858323126916278856549586825357358273536","best_ask":"0.51","best_bid":"0.49","hash":"be3d67963bc66117a731317892d3ce906382d4e1","price":"0.49","side":"BUY","size":"40"},{"asset_id":"8698449539441374295770236407991735029336433231649246775082939325523552031992","best_ask":"0.51","best_bid":"0.49","hash":"7e9c90aa151cb5e35403a94db875acf89d8e9b1a","price":"0.51","side":"SELL","size":"40"}],"timestamp":"1785121613496"},"payload_hash":"164abf816de819ea5a3e6bbb3f8ec7ff04eb781d452523e368592867c6b956eb","raw_frame":"{\"market\":\"0xf9d60bb033695053c4d1d8592e52171c1042f64b41a4b72e09dcc6f4852b6670\", \"price_changes\":[{\"asset_id\":\"96283536366176669581486355171583722558858323126916278856549586825357358273536\", \"price\":\"0.49\", \"size\":\"40\", \"side\":\"BUY\", \"hash\":\"be3d67963bc66117a731317892d3ce906382d4e1\", \"best_bid\":\"0.49\", \"best_ask\":\"0.51\"}, {\"asset_id\":\"8698449539441374295770236407991735029336433231649246775082939325523552031992\", \"price\":\"0.51\", \"size\":\"40\", \"side\":\"SELL\", \"hash\":\"7e9c90aa151cb5e35403a94db875acf89d8e9b1a\", \"best_bid\":\"0.49\", \"best_ask\":\"0.51\"}], \"timestamp\":\"1785121613496\", \"event_type\":\"price_change\"}","received_at":"2026-07-27T03:06:53.540820Z","schema_version":"clob-market-ws.price_change.v1","sequence":null,"server_hash":null,"server_timestamp":"1785121613496","session_id":"ff6d21c8283948938400a32613abec2c","source":"clob_market_ws"},"received_at":"2026-07-27T03:06:53.540820Z","record_id":"e2ae7bb3b782390445b3dd2a4fd1166ad8222e3ca77af598cf2b8ae5df45c6e8","schema_fingerprint":"4aa3821a28b0b7c2400bc59aba4bcc0a76e971dadd19610d3ad38c768e124dc7","schema_version":"edge-lab-recorder.raw.v1","sequence":null,"source":"clob_market_ws"}
{"event_at":"2026-07-27T03:06:53.497000Z","event_fingerprint":"c99e88a4790c499d8fc0fd2a7426276aa4e74bb3401c22a7feeb9f0f87d68267","payload":{"connection_id":"f95883f18d264834af91809e5f803e9f","event_at":"2026-07-27T03:06:53.497000Z","event_type":"price_change","frame_hash":"cd87a67698dcb6557c09a47ecfd022bc0fdf9c2728572f0cb71c6f2a05e97630","frame_index":0,"kind":"data","monotonic_ns":223596868910916,"payload":{"event_type":"price_change","market":"0xf9d60bb033695053c4d1d8592e52171c1042f64b41a4b72e09dcc6f4852b6670","price_changes":[{"asset_id":"96283536366176669581486355171583722558858323126916278856549586825357358273536","best_ask":"0.51","best_bid":"0.49","hash":"b6dae19722d33e68145266ad85af195b687b0234","price":"0.49","side":"BUY","size":"45"},{"asset_id":"8698449539441374295770236407991735029336433231649246775082939325523552031992","best_ask":"0.51","best_bid":"0.49","hash":"fcee0e3bf1e40ae4e1bb78fa30be4af648ca4040","price":"0.51","side":"SELL","size":"45"}],"timestamp":"1785121613497"},"payload_hash":"f3548b0b0d2b25e16799d35bd3f26448a1bfb1cc14e723bf08c46b8b4383f810","raw_frame":"{\"market\":\"0xf9d60bb033695053c4d1d8592e52171c1042f64b41a4b72e09dcc6f4852b6670\", \"price_changes\":[{\"asset_id\":\"96283536366176669581486355171583722558858323126916278856549586825357358273536\", \"price\":\"0.49\", \"size\":\"45\", \"side\":\"BUY\", \"hash\":\"b6dae19722d33e68145266ad85af195b687b0234\", \"best_bid\":\"0.49\", \"best_ask\":\"0.51\"}, {\"asset_id\":\"8698449539441374295770236407991735029336433231649246775082939325523552031992\", \"price\":\"0.51\", \"size\":\"45\", \"side\":\"SELL\", \"hash\":\"fcee0e3bf1e40ae4e1bb78fa30be4af648ca4040\", \"best_bid\":\"0.49\", \"best_ask\":\"0.51\"}], \"timestamp\":\"1785121613497\", \"event_type\":\"price_change\"}","received_at":"2026-07-27T03:06:53.542071Z","schema_version":"clob-market-ws.price_change.v1","sequence":null,"server_hash":null,"server_timestamp":"1785121613497","session_id":"ff6d21c8283948938400a32613abec2c","source":"clob_market_ws"},"received_at":"2026-07-27T03:06:53.542071Z","record_id":"8f03e47d0dd170e74fdef08ca877fd0260f1d23397db5f11412a16cff0d91749","schema_fingerprint":"4aa3821a28b0b7c2400bc59aba4bcc0a76e971dadd19610d3ad38c768e124dc7","schema_version":"edge-lab-recorder.raw.v1","sequence":null,"source":"clob_market_ws"}
{"event_at":"2026-07-27T03:06:53.498000Z","event_fingerprint":"7fde4bed46efa096154bae2aca030dcd4925bb4666281a25595c9fc19798cf30","payload":{"connection_id":"f95883f18d264834af91809e5f803e9f","event_at":"2026-07-27T03:06:53.498000Z","event_type":"price_change","frame_hash":"a399d0d597793a942e4d5a825a2a27319ceef3834605d779c922c1547f17155c","frame_index":0,"kind":"data","monotonic_ns":223596873736166,"payload":{"event_type":"price_change","market":"0xf9d60bb033695053c4d1d8592e52171c1042f64b41a4b72e09dcc6f4852b6670","price_changes":[{"asset_id":"96283536366176669581486355171583722558858323126916278856549586825357358273536","best_ask":"0.51","best_bid":"0.49","hash":"b5d58d83832b163623063a1249d53cea4527d87b","price":"0.49","side":"BUY","size":"50"},{"asset_id":"8698449539441374295770236407991735029336433231649246775082939325523552031992","best_ask":"0.51","best_bid":"0.49","hash":"a62bfb4bf8cc814a6d64a2ea87dcc087ebeabcbd","price":"0.51","side":"SELL","size":"50"}],"timestamp":"1785121613498"},"payload_hash":"0b3949bbfd6ee45e4ff16bc52a1c76ff6afd8fb813318110054980dce577ae11","raw_frame":"{\"market\":\"0xf9d60bb033695053c4d1d8592e52171c1042f64b41a4b72e09dcc6f4852b6670\", \"price_changes\":[{\"asset_id\":\"96283536366176669581486355171583722558858323126916278856549586825357358273536\", \"price\":\"0.49\", \"size\":\"50\", \"side\":\"BUY\", \"hash\":\"b5d58d83832b163623063a1249d53cea4527d87b\", \"best_bid\":\"0.49\", \"best_ask\":\"0.51\"}, {\"asset_id\":\"8698449539441374295770236407991735029336433231649246775082939325523552031992\", \"price\":\"0.51\", \"size\":\"50\", \"side\":\"SELL\", \"hash\":\"a62bfb4bf8cc814a6d64a2ea87dcc087ebeabcbd\", \"best_bid\":\"0.49\", \"best_ask\":\"0.51\"}], \"timestamp\":\"1785121613498\", \"event_type\":\"price_change\"}","received_at":"2026-07-27T03:06:53.546896Z","schema_version":"clob-market-ws.price_change.v1","sequence":null,"server_hash":null,"server_timestamp":"1785121613498","session_id":"ff6d21c8283948938400a32613abec2c","source":"clob_market_ws"},"received_at":"2026-07-27T03:06:53.546896Z","record_id":"779734f59c8a0edc0bcb17af3240e074eff4b08e9ed15a6b195a189c8ce10a76","schema_fingerprint":"4aa3821a28b0b7c2400bc59aba4bcc0a76e971dadd19610d3ad38c768e124dc7","schema_version":"edge-lab-recorder.raw.v1","sequence":null,"source":"clob_market_ws"}
{"event_at":"2026-07-27T03:06:53.499000Z","event_fingerprint":"3fc8bb73d7b5c72cc57c6ea36bfb081f9d082b2a39d8f20fd71403422e784a74","payload":{"connection_id":"f95883f18d264834af91809e5f803e9f","event_at":"2026-07-27T03:06:53.499000Z","event_type":"price_change","frame_hash":"e50f47d727ad37db41aa54c31e79fe6b24fa40469a98483a2e680d7a8ff9bc4b","frame_index":0,"kind":"data","monotonic_ns":223596874340666,"payload":{"event_type":"price_change","market":"0xf9d60bb033695053c4d1d8592e52171c1042f64b41a4b72e09dcc6f4852b6670","price_changes":[{"asset_id":"96283536366176669581486355171583722558858323126916278856549586825357358273536","best_ask":"0.51","best_bid":"0.49","hash":"7d795eddc8af8773bc3d0597c66d72511ade1104","price":"0.49","side":"BUY","size":"55"},{"asset_id":"8698449539441374295770236407991735029336433231649246775082939325523552031992","best_ask":"0.51","best_bid":"0.49","hash":"77ade9545e7452f0138531c967bfbad6711e77fd","price":"0.51","side":"SELL","size":"55"}],"timestamp":"1785121613499"},"payload_hash":"57cc0349ebb8dd75dfecfae103b9dc09391ab808ac284dc4e4785efc9aeee1c4","raw_frame":"{\"market\":\"0xf9d60bb033695053c4d1d8592e52171c1042f64b41a4b72e09dcc6f4852b6670\", \"price_changes\":[{\"asset_id\":\"96283536366176669581486355171583722558858323126916278856549586825357358273536\", \"price\":\"0.49\", \"size\":\"55\", \"side\":\"BUY\", \"hash\":\"7d795eddc8af8773bc3d0597c66d72511ade1104\", \"best_bid\":\"0.49\", \"best_ask\":\"0.51\"}, {\"asset_id\":\"8698449539441374295770236407991735029336433231649246775082939325523552031992\", \"price\":\"0.51\", \"size\":\"55\", \"side\":\"SELL\", \"hash\":\"77ade9545e7452f0138531c967bfbad6711e77fd\", \"best_bid\":\"0.49\", \"best_ask\":\"0.51\"}], \"timestamp\":\"1785121613499\", \"event_type\":\"price_change\"}","received_at":"2026-07-27T03:06:53.547501Z","schema_version":"clob-market-ws.price_change.v1","sequence":null,"server_hash":null,"server_timestamp":"1785121613499","session_id":"ff6d21c8283948938400a32613abec2c","source":"clob_market_ws"},"received_at":"2026-07-27T03:06:53.547501Z","record_id":"5b346ebcdb574a0f25a87875fa74799e37e73531b0f67f493ecf42a97a68acaf","schema_fingerprint":"4aa3821a28b0b7c2400bc59aba4bcc0a76e971dadd19610d3ad38c768e124dc7","schema_version":"edge-lab-recorder.raw.v1","sequence":null,"source":"clob_market_ws"}
{"event_at":"2026-07-27T03:06:53.500000Z","event_fingerprint":"0be61738cc70189f7d784445b305361c9167b06ffbf22d55b4db480d317104c2","payload":{"connection_id":"f95883f18d264834af91809e5f803e9f","event_at":"2026-07-27T03:06:53.500000Z","event_type":"price_change","frame_hash":"e1c3ba2238c9329f30ec9796e2126c67a310f6132b5648e314167218f3118e88","frame_index":0,"kind":"data","monotonic_ns":223596874988750,"payload":{"event_type":"price_change","market":"0xf9d60bb033695053c4d1d8592e52171c1042f64b41a4b72e09dcc6f4852b6670","price_changes":[{"asset_id":"96283536366176669581486355171583722558858323126916278856549586825357358273536","best_ask":"0.51","best_bid":"0.49","hash":"beedd8605a94ebc5bec3463a73757a83aa01c935","price":"0.49","side":"BUY","size":"60"},{"asset_id":"8698449539441374295770236407991735029336433231649246775082939325523552031992","best_ask":"0.51","best_bid":"0.49","hash":"9ef32884018ad68c6fae09f7805cb5655bfa1c8c","price":"0.51","side":"SELL","size":"60"}],"timestamp":"1785121613500"},"payload_hash":"06cba31707e255d382e0e0d1f4dba0f536b042a3c6e3218e0e3eaffa8b57a1bb","raw_frame":"{\"market\":\"0xf9d60bb033695053c4d1d8592e52171c1042f64b41a4b72e09dcc6f4852b6670\", \"price_changes\":[{\"asset_id\":\"96283536366176669581486355171583722558858323126916278856549586825357358273536\", \"price\":\"0.49\", \"size\":\"60\", \"side\":\"BUY\", \"hash\":\"beedd8605a94ebc5bec3463a73757a83aa01c935\", \"best_bid\":\"0.49\", \"best_ask\":\"0.51\"}, {\"asset_id\":\"8698449539441374295770236407991735029336433231649246775082939325523552031992\", \"price\":\"0.51\", \"size\":\"60\", \"side\":\"SELL\", \"hash\":\"9ef32884018ad68c6fae09f7805cb5655bfa1c8c\", \"best_bid\":\"0.49\", \"best_ask\":\"0.51\"}], \"timestamp\":\"1785121613500\", \"event_type\":\"price_change\"}","received_at":"2026-07-27T03:06:53.548149Z","schema_version":"clob-market-ws.price_change.v1","sequence":null,"server_hash":null,"server_timestamp":"1785121613500","session_id":"ff6d21c8283948938400a32613abec2c","source":"clob_market_ws"},"received_at":"2026-07-27T03:06:53.548149Z","record_id":"c4b93372093ca3c3728b6dc573b10ed3490e89af6c6717e6b114c8c4548be224","schema_fingerprint":"4aa3821a28b0b7c2400bc59aba4bcc0a76e971dadd19610d3ad38c768e124dc7","schema_version":"edge-lab-recorder.raw.v1","sequence":null,"source":"clob_market_ws"}
{"event_at":"2026-07-27T03:06:53.501000Z","event_fingerprint":"4941f8f454daea14d76aa8ecfdc4a564926ee026e238a529a24abd209e091015","payload":{"connection_id":"f95883f18d264834af91809e5f803e9f","event_at":"2026-07-27T03:06:53.501000Z","event_type":"price_change","frame_hash":"e68daf7f38bc3ca68d30e84586932cb6f9d433a3ea6dc3ceae9e79ce5ec4117b","frame_index":0,"kind":"data","monotonic_ns":223596876087500,"payload":{"event_type":"price_change","market":"0xf9d60bb033695053c4d1d8592e52171c1042f64b41a4b72e09dcc6f4852b6670","price_changes":[{"asset_id":"96283536366176669581486355171583722558858323126916278856549586825357358273536","best_ask":"0.51","best_bid":"0.49","hash":"ff78bf88db1a12c228f4f99ba4340602ac609bd6","price":"0.49","side":"BUY","size":"65"},{"asset_id":"8698449539441374295770236407991735029336433231649246775082939325523552031992","best_ask":"0.51","best_bid":"0.49","hash":"1eea583981b3b7f820a6b6bcefaa42e9b5118bf2","price":"0.51","side":"SELL","size":"65"}],"timestamp":"1785121613501"},"payload_hash":"f74359e02694f465c1dfcce1fcf3d6acb19b755680dc4ee1d81dffc6cf818423","raw_frame":"{\"market\":\"0xf9d60bb033695053c4d1d8592e52171c1042f64b41a4b72e09dcc6f4852b6670\", \"price_changes\":[{\"asset_id\":\"96283536366176669581486355171583722558858323126916278856549586825357358273536\", \"price\":\"0.49\", \"size\":\"65\", \"side\":\"BUY\", \"hash\":\"ff78bf88db1a12c228f4f99ba4340602ac609bd6\", \"best_bid\":\"0.49\", \"best_ask\":\"0.51\"}, {\"asset_id\":\"8698449539441374295770236407991735029336433231649246775082939325523552031992\", \"price\":\"0.51\", \"size\":\"65\", \"side\":\"SELL\", \"hash\":\"1eea583981b3b7f820a6b6bcefaa42e9b5118bf2\", \"best_bid\":\"0.49\", \"best_ask\":\"0.51\"}], \"timestamp\":\"1785121613501\", \"event_type\":\"price_change\"}","received_at":"2026-07-27T03:06:53.549248Z","schema_version":"clob-market-ws.price_change.v1","sequence":null,"server_hash":null,"server_timestamp":"1785121613501","session_id":"ff6d21c8283948938400a32613abec2c","source":"clob_market_ws"},"received_at":"2026-07-27T03:06:53.549248Z","record_id":"ef0317ccee0786183d4604ecb8c04e22f20c64edfe69218cc43af9d9e44ab173","schema_fingerprint":"4aa3821a28b0b7c2400bc59aba4bcc0a76e971dadd19610d3ad38c768e124dc7","schema_version":"edge-lab-recorder.raw.v1","sequence":null,"source":"clob_market_ws"}
{"event_at":"2026-07-27T03:06:53.502000Z","event_fingerprint":"0c7caa025ccfa6b40226f9be9a5f1f70266d7553c4f92e88201eeaa5504a4372","payload":{"connection_id":"f95883f18d264834af91809e5f803e9f","event_at":"2026-07-27T03:06:53.502000Z","event_type":"price_change","frame_hash":"f9e53d33d32f9cb44740d8b9dfb45e3185678da1a77858097f66ddd7bcda94ff","frame_index":0,"kind":"data","monotonic_ns":223596876588375,"payload":{"event_type":"price_change","market":"0xf9d60bb033695053c4d1d8592e52171c1042f64b41a4b72e09dcc6f4852b6670","price_changes":[{"asset_id":"96283536366176669581486355171583722558858323126916278856549586825357358273536","best_ask":"0.51","best_bid":"0.49","hash":"b349eb55a87918cc02e37a57f94cea5dd843076a","price":"0.49","side":"BUY","size":"70"},{"asset_id":"8698449539441374295770236407991735029336433231649246775082939325523552031992","best_ask":"0.51","best_bid":"0.49","hash":"f5ed6969b78bd6de00e6e841b9796321dcfed025","price":"0.51","side":"SELL","size":"70"}],"timestamp":"1785121613502"},"payload_hash":"115c2a60e72dd67bd9e30888ea45e57c953b18972bf84c97d7579d4ff57f1ff2","raw_frame":"{\"market\":\"0xf9d60bb033695053c4d1d8592e52171c1042f64b41a4b72e09dcc6f4852b6670\", \"price_changes\":[{\"asset_id\":\"96283536366176669581486355171583722558858323126916278856549586825357358273536\", \"price\":\"0.49\", \"size\":\"70\", \"side\":\"BUY\", \"hash\":\"b349eb55a87918cc02e37a57f94cea5dd843076a\", \"best_bid\":\"0.49\", \"best_ask\":\"0.51\"}, {\"asset_id\":\"8698449539441374295770236407991735029336433231649246775082939325523552031992\", \"price\":\"0.51\", \"size\":\"70\", \"side\":\"SELL\", \"hash\":\"f5ed6969b78bd6de00e6e841b9796321dcfed025\", \"best_bid\":\"0.49\", \"best_ask\":\"0.51\"}], \"timestamp\":\"1785121613502\", \"event_type\":\"price_change\"}","received_at":"2026-07-27T03:06:53.549749Z","schema_version":"clob-market-ws.price_change.v1","sequence":null,"server_hash":null,"server_timestamp":"1785121613502","session_id":"ff6d21c8283948938400a32613abec2c","source":"clob_market_ws"},"received_at":"2026-07-27T03:06:53.549749Z","record_id":"6d3d52d48c72cd42f58be8c51bda45937f881d4f3eb5b823accdf1f6e3f03342","schema_fingerprint":"4aa3821a28b0b7c2400bc59aba4bcc0a76e971dadd19610d3ad38c768e124dc7","schema_version":"edge-lab-recorder.raw.v1","sequence":null,"source":"clob_market_ws"}
{"event_at":"2026-07-27T03:06:53.503000Z","event_fingerprint":"9e1b872ed9b2cd6b2af6ffeedce7ca9fd7f56ae38b6749b695efb0264b09edf4","payload":{"connection_id":"f95883f18d264834af91809e5f803e9f","event_at":"2026-07-27T03:06:53.503000Z","event_type":"price_change","frame_hash":"6e2101835f231cc9e9cb814b746be7374fb2d9fd1823106fecc60dff3d7180fb","frame_index":0,"kind":"data","monotonic_ns":223596877972375,"payload":{"event_type":"price_change","market":"0xf9d60bb033695053c4d1d8592e52171c1042f64b41a4b72e09dcc6f4852b6670","price_changes":[{"asset_id":"96283536366176669581486355171583722558858323126916278856549586825357358273536","best_ask":"0.51","best_bid":"0.49","hash":"266c1d0c8623ce6766e70646145d424ce7374c37","price":"0.49","side":"BUY","size":"75"},{"asset_id":"8698449539441374295770236407991735029336433231649246775082939325523552031992","best_ask":"0.51","best_bid":"0.49","hash":"f926e89d32b9e5c8e6582a52340ae52ea54edf83","price":"0.51","side":"SELL","size":"75"}],"timestamp":"1785121613503"},"payload_hash":"483e6276a4e0121c851889d64c0fc59c77f7eecf4d204ad9d9b4311dd1658388","raw_frame":"{\"market\":\"0xf9d60bb033695053c4d1d8592e52171c1042f64b41a4b72e09dcc6f4852b6670\", \"price_changes\":[{\"asset_id\":\"96283536366176669581486355171583722558858323126916278856549586825357358273536\", \"price\":\"0.49\", \"size\":\"75\", \"side\":\"BUY\", \"hash\":\"266c1d0c8623ce6766e70646145d424ce7374c37\", \"best_bid\":\"0.49\", \"best_ask\":\"0.51\"}, {\"asset_id\":\"8698449539441374295770236407991735029336433231649246775082939325523552031992\", \"price\":\"0.51\", \"size\":\"75\", \"side\":\"SELL\", \"hash\":\"f926e89d32b9e5c8e6582a52340ae52ea54edf83\", \"best_bid\":\"0.49\", \"best_ask\":\"0.51\"}], \"timestamp\":\"1785121613503\", \"event_type\":\"price_change\"}","received_at":"2026-07-27T03:06:53.551127Z","schema_version":"clob-market-ws.price_change.v1","sequence":null,"server_hash":null,"server_timestamp":"1785121613503","session_id":"ff6d21c8283948938400a32613abec2c","source":"clob_market_ws"},"received_at":"2026-07-27T03:06:53.551127Z","record_id":"e6e35643e8866c2bb5cebff8b9f804500f9cba26ea51629df4814fbf4dee9db6","schema_fingerprint":"4aa3821a28b0b7c2400bc59aba4bcc0a76e971dadd19610d3ad38c768e124dc7","schema_version":"edge-lab-recorder.raw.v1","sequence":null,"source":"clob_market_ws"}
{"event_at":"2026-07-27T03:06:53.504000Z","event_fingerprint":"9d347554a57cefd90bb81994bcfb158a760aeacdf2f87305d0441d9918336827","payload":{"connection_id":"f95883f18d264834af91809e5f803e9f","event_at":"2026-07-27T03:06:53.504000Z","event_type":"price_change","frame_hash":"1e3f52a825fb00cfed590a4df3d492aa07ac5fb5280bd636ac8aa738fedf3e7a","frame_index":0,"kind":"data","monotonic_ns":223596879403458,"payload":{"event_type":"price_change","market":"0xf9d60bb033695053c4d1d8592e52171c1042f64b41a4b72e09dcc6f4852b6670","price_changes":[{"asset_id":"96283536366176669581486355171583722558858323126916278856549586825357358273536","best_ask":"0.51","best_bid":"0.49","hash":"9460e4b9a4e22eaf9c2499ff613e11df8519ab70","price":"0.49","side":"BUY","size":"80"},{"asset_id":"8698449539441374295770236407991735029336433231649246775082939325523552031992","best_ask":"0.51","best_bid":"0.49","hash":"460d30b9b2967238e0b8ca6147d6d9d827fced82","price":"0.51","side":"SELL","size":"80"}],"timestamp":"1785121613504"},"payload_hash":"6f53be56ec567ccaf13dfa16ffa9614e2c3c685455d99a769ad37a2248f9d3a6","raw_frame":"{\"market\":\"0xf9d60bb033695053c4d1d8592e52171c1042f64b41a4b72e09dcc6f4852b6670\", \"price_changes\":[{\"asset_id\":\"96283536366176669581486355171583722558858323126916278856549586825357358273536\", \"price\":\"0.49\", \"size\":\"80\", \"side\":\"BUY\", \"hash\":\"9460e4b9a4e22eaf9c2499ff613e11df8519ab70\", \"best_bid\":\"0.49\", \"best_ask\":\"0.51\"}, {\"asset_id\":\"8698449539441374295770236407991735029336433231649246775082939325523552031992\", \"price\":\"0.51\", \"size\":\"80\", \"side\":\"SELL\", \"hash\":\"460d30b9b2967238e0b8ca6147d6d9d827fced82\", \"best_bid\":\"0.49\", \"best_ask\":\"0.51\"}], \"timestamp\":\"1785121613504\", \"event_type\":\"price_change\"}","received_at":"2026-07-27T03:06:53.552557Z","schema_version":"clob-market-ws.price_change.v1","sequence":null,"server_hash":null,"server_timestamp":"1785121613504","session_id":"ff6d21c8283948938400a32613abec2c","source":"clob_market_ws"},"received_at":"2026-07-27T03:06:53.552557Z","record_id":"a16e0eed8104536a443c28b3ca9227c4947f5316e564bbcce0fb168723d61a41","schema_fingerprint":"4aa3821a28b0b7c2400bc59aba4bcc0a76e971dadd19610d3ad38c768e124dc7","schema_version":"edge-lab-recorder.raw.v1","sequence":null,"source":"clob_market_ws"}
{"event_at":"2026-07-27T03:06:53.505000Z","event_fingerprint":"6d3a48695dae13e2e31dc82ddcb2150a34ff5ade5000c90270108b36edce7422","payload":{"connection_id":"f95883f18d264834af91809e5f803e9f","event_at":"2026-07-27T03:06:53.505000Z","event_type":"price_change","frame_hash":"5d7a9f7ed8266151a5fed0c01d2c8ef3c9e807b116960ac0105b523ae8968858","frame_index":0,"kind":"data","monotonic_ns":223596880828875,"payload":{"event_type":"price_change","market":"0xf9d60bb033695053c4d1d8592e52171c1042f64b41a4b72e09dcc6f4852b6670","price_changes":[{"asset_id":"96283536366176669581486355171583722558858323126916278856549586825357358273536","best_ask":"0.51","best_bid":"0.49","hash":"86cb85ab5738c37d372ef7be8679144d01201646","price":"0.49","side":"BUY","size":"85"},{"asset_id":"8698449539441374295770236407991735029336433231649246775082939325523552031992","best_ask":"0.51","best_bid":"0.49","hash":"bd6f35994d99ce61bc9e84ac8b09265bedd1c75d","price":"0.51","side":"SELL","size":"85"}],"timestamp":"1785121613505"},"payload_hash":"2ed80616f6f8bc8dd8e4a10bf5b37b7c17c0132a4352665ecbd7482f294784f5","raw_frame":"{\"market\":\"0xf9d60bb033695053c4d1d8592e52171c1042f64b41a4b72e09dcc6f4852b6670\", \"price_changes\":[{\"asset_id\":\"96283536366176669581486355171583722558858323126916278856549586825357358273536\", \"price\":\"0.49\", \"size\":\"85\", \"side\":\"BUY\", \"hash\":\"86cb85ab5738c37d372ef7be8679144d01201646\", \"best_bid\":\"0.49\", \"best_ask\":\"0.51\"}, {\"asset_id\":\"8698449539441374295770236407991735029336433231649246775082939325523552031992\", \"price\":\"0.51\", \"size\":\"85\", \"side\":\"SELL\", \"hash\":\"bd6f35994d99ce61bc9e84ac8b09265bedd1c75d\", \"best_bid\":\"0.49\", \"best_ask\":\"0.51\"}], \"timestamp\":\"1785121613505\", \"event_type\":\"price_change\"}","received_at":"2026-07-27T03:06:53.553983Z","schema_version":"clob-market-ws.price_change.v1","sequence":null,"server_hash":null,"server_timestamp":"1785121613505","session_id":"ff6d21c8283948938400a32613abec2c","source":"clob_market_ws"},"received_at":"2026-07-27T03:06:53.553983Z","record_id":"3b2820b742bfbe95dd621499e5c4a36c466c12563a54b6cf8eaab669376ef388","schema_fingerprint":"4aa3821a28b0b7c2400bc59aba4bcc0a76e971dadd19610d3ad38c768e124dc7","schema_version":"edge-lab-recorder.raw.v1","sequence":null,"source":"clob_market_ws"}
{"event_at":"2026-07-27T03:06:53.506000Z","event_fingerprint":"ee96a829da4b89c75206f4b93831c1bed7ff2b4f2084f6758abe67f43e8910d6","payload":{"connection_id":"f95883f18d264834af91809e5f803e9f","event_at":"2026-07-27T03:06:53.506000Z","event_type":"price_change","frame_hash":"5db747722f5175824d6cff6a0524e62a65af6b915124bf019963e3189fbc9bfb","frame_index":0,"kind":"data","monotonic_ns":223596882221875,"payload":{"event_type":"price_change","market":"0xf9d60bb033695053c4d1d8592e52171c1042f64b41a4b72e09dcc6f4852b6670","price_changes":[{"asset_id":"96283536366176669581486355171583722558858323126916278856549586825357358273536","best_ask":"0.51","best_bid":"0.49","hash":"6ada175b925732139ff0008ea1fa9aa9e8c4dbd8","price":"0.49","side":"BUY","size":"90"},{"asset_id":"8698449539441374295770236407991735029336433231649246775082939325523552031992","best_ask":"0.51","best_bid":"0.49","hash":"51060aa30d338088337cb754e5c0dfebdbf4bfa8","price":"0.51","side":"SELL","size":"90"}],"timestamp":"1785121613506"},"payload_hash":"9214dd41e93a85c576dfeef4f97eda6aadcfcd7483d0c7354123ee2921c69a0a","raw_frame":"{\"market\":\"0xf9d60bb033695053c4d1d8592e52171c1042f64b41a4b72e09dcc6f4852b6670\", \"price_changes\":[{\"asset_id\":\"96283536366176669581486355171583722558858323126916278856549586825357358273536\", \"price\":\"0.49\", \"size\":\"90\", \"side\":\"BUY\", \"hash\":\"6ada175b925732139ff0008ea1fa9aa9e8c4dbd8\", \"best_bid\":\"0.49\", \"best_ask\":\"0.51\"}, {\"asset_id\":\"8698449539441374295770236407991735029336433231649246775082939325523552031992\", \"price\":\"0.51\", \"size\":\"90\", \"side\":\"SELL\", \"hash\":\"51060aa30d338088337cb754e5c0dfebdbf4bfa8\", \"best_bid\":\"0.49\", \"best_ask\":\"0.51\"}], \"timestamp\":\"1785121613506\", \"event_type\":\"price_change\"}","received_at":"2026-07-27T03:06:53.555382Z","schema_version":"clob-market-ws.price_change.v1","sequence":null,"server_hash":null,"server_timestamp":"1785121613506","session_id":"ff6d21c8283948938400a32613abec2c","source":"clob_market_ws"},"received_at":"2026-07-27T03:06:53.555382Z","record_id":"e6bae9c028fbcd451d1d8fb390f119a5f350cd4a729ae6238ff196d5804aaeac","schema_fingerprint":"4aa3821a28b0b7c2400bc59aba4bcc0a76e971dadd19610d3ad38c768e124dc7","schema_version":"edge-lab-recorder.raw.v1","sequence":null,"source":"clob_market_ws"}
{"event_at":"2026-07-27T03:06:53.507000Z","event_fingerprint":"a1cbaf3c4cadeb234b33d7243d0f047e81dad42fa91d36812b0a386df712b9b6","payload":{"connection_id":"f95883f18d264834af91809e5f803e9f","event_at":"2026-07-27T03:06:53.507000Z","event_type":"price_change","frame_hash":"c6e905f2abfcdbe81e96200d8803f87213ee0d7da52a93e55a5051ca95ebb9da","frame_index":0,"kind":"data","monotonic_ns":223596882729416,"payload":{"event_type":"price_change","market":"0xf9d60bb033695053c4d1d8592e52171c1042f64b41a4b72e09dcc6f4852b6670","price_changes":[{"asset_id":"96283536366176669581486355171583722558858323126916278856549586825357358273536","best_ask":"0.51","best_bid":"0.49","hash":"70de2595c4a06e3a80e902521087b1635d7e71d6","price":"0.49","side":"BUY","size":"95"},{"asset_id":"8698449539441374295770236407991735029336433231649246775082939325523552031992","best_ask":"0.51","best_bid":"0.49","hash":"4fdf8d779ed43b7f205eed8d477a0b1d70960572","price":"0.51","side":"SELL","size":"95"}],"timestamp":"1785121613507"},"payload_hash":"00497e60521a72c59a25eb22171e01bc9699ede3771e127b85aee9e402dd39cd","raw_frame":"{\"market\":\"0xf9d60bb033695053c4d1d8592e52171c1042f64b41a4b72e09dcc6f4852b6670\", \"price_changes\":[{\"asset_id\":\"96283536366176669581486355171583722558858323126916278856549586825357358273536\", \"price\":\"0.49\", \"size\":\"95\", \"side\":\"BUY\", \"hash\":\"70de2595c4a06e3a80e902521087b1635d7e71d6\", \"best_bid\":\"0.49\", \"best_ask\":\"0.51\"}, {\"asset_id\":\"8698449539441374295770236407991735029336433231649246775082939325523552031992\", \"price\":\"0.51\", \"size\":\"95\", \"side\":\"SELL\", \"hash\":\"4fdf8d779ed43b7f205eed8d477a0b1d70960572\", \"best_bid\":\"0.49\", \"best_ask\":\"0.51\"}], \"timestamp\":\"1785121613507\", \"event_type\":\"price_change\"}","received_at":"2026-07-27T03:06:53.555890Z","schema_version":"clob-market-ws.price_change.v1","sequence":null,"server_hash":null,"server_timestamp":"1785121613507","session_id":"ff6d21c8283948938400a32613abec2c","source":"clob_market_ws"},"received_at":"2026-07-27T03:06:53.555890Z","record_id":"18d5d9b7575fbd538a9e2c0ea5ad33663a108f575dbaf450f882db6200152966","schema_fingerprint":"4aa3821a28b0b7c2400bc59aba4bcc0a76e971dadd19610d3ad38c768e124dc7","schema_version":"edge-lab-recorder.raw.v1","sequence":null,"source":"clob_market_ws"}
{"event_at":"2026-07-27T03:06:53.508000Z","event_fingerprint":"471d5ef169a25013e8f7f8eac82e8eaf03b45e023c46236d71e64468e14e8ce7","payload":{"connection_id":"f95883f18d264834af91809e5f803e9f","event_at":"2026-07-27T03:06:53.508000Z","event_type":"price_change","frame_hash":"d0392ee8dc3b6844eae29228aea63bac4e9642e4906f66453f82dfff3b2211b9","frame_index":0,"kind":"data","monotonic_ns":223596889352833,"payload":{"event_type":"price_change","market":"0xf9d60bb033695053c4d1d8592e52171c1042f64b41a4b72e09dcc6f4852b6670","price_changes":[{"asset_id":"96283536366176669581486355171583722558858323126916278856549586825357358273536","best_ask":"0.51","best_bid":"0.49","hash":"60178fb0a0f819fac5f5cb5c213e507144bff21c","price":"0.49","side":"BUY","size":"100"},{"asset_id":"8698449539441374295770236407991735029336433231649246775082939325523552031992","best_ask":"0.51","best_bid":"0.49","hash":"8650e655d54b47168f9da0dd7a7ab6b436956f24","price":"0.51","side":"SELL","size":"100"}],"timestamp":"1785121613508"},"payload_hash":"3394a840bd7e261f9abeefc59e135096d687d07397b1f782d264da819f50685c","raw_frame":"{\"market\":\"0xf9d60bb033695053c4d1d8592e52171c1042f64b41a4b72e09dcc6f4852b6670\", \"price_changes\":[{\"asset_id\":\"96283536366176669581486355171583722558858323126916278856549586825357358273536\", \"price\":\"0.49\", \"size\":\"100\", \"side\":\"BUY\", \"hash\":\"60178fb0a0f819fac5f5cb5c213e507144bff21c\", \"best_bid\":\"0.49\", \"best_ask\":\"0.51\"}, {\"asset_id\":\"8698449539441374295770236407991735029336433231649246775082939325523552031992\", \"price\":\"0.51\", \"size\":\"100\", \"side\":\"SELL\", \"hash\":\"8650e655d54b47168f9da0dd7a7ab6b436956f24\", \"best_bid\":\"0.49\", \"best_ask\":\"0.51\"}], \"timestamp\":\"1785121613508\", \"event_type\":\"price_change\"}","received_at":"2026-07-27T03:06:53.562513Z","schema_version":"clob-market-ws.price_change.v1","sequence":null,"server_hash":null,"server_timestamp":"1785121613508","session_id":"ff6d21c8283948938400a32613abec2c","source":"clob_market_ws"},"received_at":"2026-07-27T03:06:53.562513Z","record_id":"efd4cedc3e42654b7da0d2660cd3c592a98fe5f493fe03d5eb2321a0947b0812","schema_fingerprint":"4aa3821a28b0b7c2400bc59aba4bcc0a76e971dadd19610d3ad38c768e124dc7","schema_version":"edge-lab-recorder.raw.v1","sequence":null,"source":"clob_market_ws"}
{"event_at":"2026-07-27T03:06:53.509000Z","event_fingerprint":"33aac54e4b55b7c83f8fb30491e4c9ab2df3227f4e7a1fbfa0c58b888ad27ef8","payload":{"connection_id":"f95883f18d264834af91809e5f803e9f","event_at":"2026-07-27T03:06:53.509000Z","event_type":"price_change","frame_hash":"6be266fca5e4a26619b3b1e89c4af0668f2a0f828a172e54c23eeca83ecb50e1","frame_index":0,"kind":"data","monotonic_ns":223596889928500,"payload":{"event_type":"price_change","market":"0xf9d60bb033695053c4d1d8592e52171c1042f64b41a4b72e09dcc6f4852b6670","price_changes":[{"asset_id":"96283536366176669581486355171583722558858323126916278856549586825357358273536","best_ask":"0.51","best_bid":"0.49","hash":"10740975fe456bee2f47f2a7c1f087b6b696b4e3","price":"0.49","side":"BUY","size":"105"},{"asset_id":"8698449539441374295770236407991735029336433231649246775082939325523552031992","best_ask":"0.51","best_bid":"0.49","hash":"c137ed41ac5f41b96ebf08fea4b543fc999fc958","price":"0.51","side":"SELL","size":"105"}],"timestamp":"1785121613509"},"payload_hash":"d1bb48c8a0b313cd9d4c9e1a1af81cb763da9abd9d7dc6d9c6150413829697b7","raw_frame":"{\"market\":\"0xf9d60bb033695053c4d1d8592e52171c1042f64b41a4b72e09dcc6f4852b6670\", \"price_changes\":[{\"asset_id\":\"96283536366176669581486355171583722558858323126916278856549586825357358273536\", \"price\":\"0.49\", \"size\":\"105\", \"side\":\"BUY\", \"hash\":\"10740975fe456bee2f47f2a7c1f087b6b696b4e3\", \"best_bid\":\"0.49\", \"best_ask\":\"0.51\"}, {\"asset_id\":\"8698449539441374295770236407991735029336433231649246775082939325523552031992\", \"price\":\"0.51\", \"size\":\"105\", \"side\":\"SELL\", \"hash\":\"c137ed41ac5f41b96ebf08fea4b543fc999fc958\", \"best_bid\":\"0.49\", \"best_ask\":\"0.51\"}], \"timestamp\":\"1785121613509\", \"event_type\":\"price_change\"}","received_at":"2026-07-27T03:06:53.563088Z","schema_version":"clob-market-ws.price_change.v1","sequence":null,"server_hash":null,"server_timestamp":"1785121613509","session_id":"ff6d21c8283948938400a32613abec2c","source":"clob_market_ws"},"received_at":"2026-07-27T03:06:53.563088Z","record_id":"d54edff61e8f7a7af66e398423667d21901c22a283e31943b97e96de58e5acfa","schema_fingerprint":"4aa3821a28b0b7c2400bc59aba4bcc0a76e971dadd19610d3ad38c768e124dc7","schema_version":"edge-lab-recorder.raw.v1","sequence":null,"source":"clob_market_ws"}
{"event_at":"2026-07-27T03:06:53.510000Z","event_fingerprint":"2f5309892d10238d8b3bc6e20e108711da2387d0cdf268ddd3575b8b4bb93c8f","payload":{"connection_id":"f95883f18d264834af91809e5f803e9f","event_at":"2026-07-27T03:06:53.510000Z","event_type":"price_change","frame_hash":"8f75d2384977a59a491beb41f14018d98563bcd2a4730827018047b51be55f5d","frame_index":0,"kind":"data","monotonic_ns":223596890497625,"payload":{"event_type":"price_change","market":"0xf9d60bb033695053c4d1d8592e52171c1042f64b41a4b72e09dcc6f4852b6670","price_changes":[{"asset_id":"96283536366176669581486355171583722558858323126916278856549586825357358273536","best_ask":"0.51","best_bid":"0.49","hash":"05ba06bd8acfb210c4ca3cc011ebc37a2305ecb9","price":"0.49","side":"BUY","size":"110"},{"asset_id":"8698449539441374295770236407991735029336433231649246775082939325523552031992","best_ask":"0.51","best_bid":"0.49","hash":"76e53f6d5cfb9cf54cff12388c4781ee3735757f","price":"0.51","side":"SELL","size":"110"}],"timestamp":"1785121613510"},"payload_hash":"65405a4d770e27515781fcc82f8ef910b769c8b3fac66a8220349b2a83cbe912","raw_frame":"{\"market\":\"0xf9d60bb033695053c4d1d8592e52171c1042f64b41a4b72e09dcc6f4852b6670\", \"price_changes\":[{\"asset_id\":\"96283536366176669581486355171583722558858323126916278856549586825357358273536\", \"price\":\"0.49\", \"size\":\"110\", \"side\":\"BUY\", \"hash\":\"05ba06bd8acfb210c4ca3cc011ebc37a2305ecb9\", \"best_bid\":\"0.49\", \"best_ask\":\"0.51\"}, {\"asset_id\":\"8698449539441374295770236407991735029336433231649246775082939325523552031992\", \"price\":\"0.51\", \"size\":\"110\", \"side\":\"SELL\", \"hash\":\"76e53f6d5cfb9cf54cff12388c4781ee3735757f\", \"best_bid\":\"0.49\", \"best_ask\":\"0.51\"}], \"timestamp\":\"1785121613510\", \"event_type\":\"price_change\"}","received_at":"2026-07-27T03:06:53.563657Z","schema_version":"clob-market-ws.price_change.v1","sequence":null,"server_hash":null,"server_timestamp":"1785121613510","session_id":"ff6d21c8283948938400a32613abec2c","source":"clob_market_ws"},"received_at":"2026-07-27T03:06:53.563657Z","record_id":"6abdb9aebbb4b386fa4483f93684b0a1ce636824975c4ce264b5bea424b36057","schema_fingerprint":"4aa3821a28b0b7c2400bc59aba4bcc0a76e971dadd19610d3ad38c768e124dc7","schema_version":"edge-lab-recorder.raw.v1","sequence":null,"source":"clob_market_ws"}
{"event_at":"2026-07-27T03:06:53.511000Z","event_fingerprint":"31a9bb68b06544870a9b795789d68efb634247e4c31ae53f7da0ef4af45e189b","payload":{"connection_id":"f95883f18d264834af91809e5f803e9f","event_at":"2026-07-27T03:06:53.511000Z","event_type":"price_change","frame_hash":"27ede9e5bef0a9c8a1a811bad7a811ae1785032a0eefddc4adbd4def0788a8cd","frame_index":0,"kind":"data","monotonic_ns":223596891098833,"payload":{"event_type":"price_change","market":"0xf9d60bb033695053c4d1d8592e52171c1042f64b41a4b72e09dcc6f4852b6670","price_changes":[{"asset_id":"96283536366176669581486355171583722558858323126916278856549586825357358273536","best_ask":"0.51","best_bid":"0.49","hash":"2271175cbc1797faed6e6a28647bfcfcce745545","price":"0.49","side":"BUY","size":"115"},{"asset_id":"8698449539441374295770236407991735029336433231649246775082939325523552031992","best_ask":"0.51","best_bid":"0.49","hash":"be49dd3203af4e89dfba34ff9599f5cc6db56cd9","price":"0.51","side":"SELL","size":"115"}],"timestamp":"1785121613511"},"payload_hash":"10666f5bac2d8c36c3cd0ca4e02914d86ce9a11754204d9bd2d36440618db4b6","raw_frame":"{\"market\":\"0xf9d60bb033695053c4d1d8592e52171c1042f64b41a4b72e09dcc6f4852b6670\", \"price_changes\":[{\"asset_id\":\"96283536366176669581486355171583722558858323126916278856549586825357358273536\", \"price\":\"0.49\", \"size\":\"115\", \"side\":\"BUY\", \"hash\":\"2271175cbc1797faed6e6a28647bfcfcce745545\", \"best_bid\":\"0.49\", \"best_ask\":\"0.51\"}, {\"asset_id\":\"8698449539441374295770236407991735029336433231649246775082939325523552031992\", \"price\":\"0.51\", \"size\":\"115\", \"side\":\"SELL\", \"hash\":\"be49dd3203af4e89dfba34ff9599f5cc6db56cd9\", \"best_bid\":\"0.49\", \"best_ask\":\"0.51\"}], \"timestamp\":\"1785121613511\", \"event_type\":\"price_change\"}","received_at":"2026-07-27T03:06:53.564258Z","schema_version":"clob-market-ws.price_change.v1","sequence":null,"server_hash":null,"server_timestamp":"1785121613511","session_id":"ff6d21c8283948938400a32613abec2c","source":"clob_market_ws"},"received_at":"2026-07-27T03:06:53.564258Z","record_id":"f298fc233a22a704ad04ef02ed5bda0e8de9423b26eebf138a66b72ae4b7e464","schema_fingerprint":"4aa3821a28b0b7c2400bc59aba4bcc0a76e971dadd19610d3ad38c768e124dc7","schema_version":"edge-lab-recorder.raw.v1","sequence":null,"source":"clob_market_ws"}
{"event_at":"2026-07-27T03:06:53.511000Z","event_fingerprint":"bf3bf0c491632f55da79e907ccc79abb93e1746bc215307ec990fd6a82e58bb0","payload":{"connection_id":"f95883f18d264834af91809e5f803e9f","event_at":"2026-07-27T03:06:53.511000Z","event_type":"price_change","frame_hash":"922361a4610f000065f9bc56ab3c66337ffc834736f8d0073904b8be8836b380","frame_index":0,"kind":"data","monotonic_ns":223596891662833,"payload":{"event_type":"price_change","market":"0xf9d60bb033695053c4d1d8592e52171c1042f64b41a4b72e09dcc6f4852b6670","price_changes":[{"asset_id":"96283536366176669581486355171583722558858323126916278856549586825357358273536","best_ask":"0.51","best_bid":"0.49","hash":"83ebe57ba9d8c6aca68819ce86e6f431e1fb0cb3","price":"0.49","side":"BUY","size":"120"},{"asset_id":"8698449539441374295770236407991735029336433231649246775082939325523552031992","best_ask":"0.51","best_bid":"0.49","hash":"f4562cdc1f571047c8f25c8cb77f031b8ffbc94a","price":"0.51","side":"SELL","size":"120"}],"timestamp":"1785121613511"},"payload_hash":"95c64ebd0af32cf8720e60c73ec9170284bbb463aff292d6747fb19f30782a60","raw_frame":"{\"market\":\"0xf9d60bb033695053c4d1d8592e52171c1042f64b41a4b72e09dcc6f4852b6670\", \"price_changes\":[{\"asset_id\":\"96283536366176669581486355171583722558858323126916278856549586825357358273536\", \"price\":\"0.49\", \"size\":\"120\", \"side\":\"BUY\", \"hash\":\"83ebe57ba9d8c6aca68819ce86e6f431e1fb0cb3\", \"best_bid\":\"0.49\", \"best_ask\":\"0.51\"}, {\"asset_id\":\"8698449539441374295770236407991735029336433231649246775082939325523552031992\", \"price\":\"0.51\", \"size\":\"120\", \"side\":\"SELL\", \"hash\":\"f4562cdc1f571047c8f25c8cb77f031b8ffbc94a\", \"best_bid\":\"0.49\", \"best_ask\":\"0.51\"}], \"timestamp\":\"1785121613511\", \"event_type\":\"price_change\"}","received_at":"2026-07-27T03:06:53.564823Z","schema_version":"clob-market-ws.price_change.v1","sequence":null,"server_hash":null,"server_timestamp":"1785121613511","session_id":"ff6d21c8283948938400a32613abec2c","source":"clob_market_ws"},"received_at":"2026-07-27T03:06:53.564823Z","record_id":"354c77bcd3b21f24930cbe92458ffd633e48849da36f3ec4f4ccb901ddd3f3b3","schema_fingerprint":"4aa3821a28b0b7c2400bc59aba4bcc0a76e971dadd19610d3ad38c768e124dc7","schema_version":"edge-lab-recorder.raw.v1","sequence":null,"source":"clob_market_ws"}
{"event_at":"2026-07-27T03:06:53.512000Z","event_fingerprint":"7f6edb05bb6975a8aad2b7b93131ea8684b1e3019e0d3d1679b5c156f5ea0295","payload":{"connection_id":"f95883f18d264834af91809e5f803e9f","event_at":"2026-07-27T03:06:53.512000Z","event_type":"price_change","frame_hash":"7431fab96976aa3d13007870e813a2933f3f2eb343bf6922483a3064ffeaa92e","frame_index":0,"kind":"data","monotonic_ns":223596892209125,"payload":{"event_type":"price_change","market":"0xf9d60bb033695053c4d1d8592e52171c1042f64b41a4b72e09dcc6f4852b6670","price_changes":[{"asset_id":"96283536366176669581486355171583722558858323126916278856549586825357358273536","best_ask":"0.51","best_bid":"0.49","hash":"597803528ee25a737aee0012d415c7c383bdfa81","price":"0.49","side":"BUY","size":"125"},{"asset_id":"8698449539441374295770236407991735029336433231649246775082939325523552031992","best_ask":"0.51","best_bid":"0.49","hash":"12414a9f280aefdeb1cff1887853e98ea6393a49","price":"0.51","side":"SELL","size":"125"}],"timestamp":"1785121613512"},"payload_hash":"9826ac6dae5f8acf97a62ac1b0a9adce464e59655bfac649853239e202d35770","raw_frame":"{\"market\":\"0xf9d60bb033695053c4d1d8592e52171c1042f64b41a4b72e09dcc6f4852b6670\", \"price_changes\":[{\"asset_id\":\"96283536366176669581486355171583722558858323126916278856549586825357358273536\", \"price\":\"0.49\", \"size\":\"125\", \"side\":\"BUY\", \"hash\":\"597803528ee25a737aee0012d415c7c383bdfa81\", \"best_bid\":\"0.49\", \"best_ask\":\"0.51\"}, {\"asset_id\":\"8698449539441374295770236407991735029336433231649246775082939325523552031992\", \"price\":\"0.51\", \"size\":\"125\", \"side\":\"SELL\", \"hash\":\"12414a9f280aefdeb1cff1887853e98ea6393a49\", \"best_bid\":\"0.49\", \"best_ask\":\"0.51\"}], \"timestamp\":\"1785121613512\", \"event_type\":\"price_change\"}","received_at":"2026-07-27T03:06:53.565369Z","schema_version":"clob-market-ws.price_change.v1","sequence":null,"server_hash":null,"server_timestamp":"1785121613512","session_id":"ff6d21c8283948938400a32613abec2c","source":"clob_market_ws"},"received_at":"2026-07-27T03:06:53.565369Z","record_id":"dd3ca01708e21586824b74275a58e8c6577576b6d867b9a42e5b80230d82d60f","schema_fingerprint":"4aa3821a28b0b7c2400bc59aba4bcc0a76e971dadd19610d3ad38c768e124dc7","schema_version":"edge-lab-recorder.raw.v1","sequence":null,"source":"clob_market_ws"}
{"event_at":"2026-07-27T03:06:53.513000Z","event_fingerprint":"72005afe028ab8e56d6603b951e55a42ddcc78aa94cdec38c31fa4e0d6d8974c","payload":{"connection_id":"f95883f18d264834af91809e5f803e9f","event_at":"2026-07-27T03:06:53.513000Z","event_type":"price_change","frame_hash":"2765938a0bfc10544d03aede5f5fe7085aad1e1b4671d2196f281937f859ca0b","frame_index":0,"kind":"data","monotonic_ns":223596892762208,"payload":{"event_type":"price_change","market":"0xf9d60bb033695053c4d1d8592e52171c1042f64b41a4b72e09dcc6f4852b6670","price_changes":[{"asset_id":"96283536366176669581486355171583722558858323126916278856549586825357358273536","best_ask":"0.51","best_bid":"0.49","hash":"d310191bdd6afeaf2ae2244cd8d4c2f2b98e38db","price":"0.49","side":"BUY","size":"130"},{"asset_id":"8698449539441374295770236407991735029336433231649246775082939325523552031992","best_ask":"0.51","best_bid":"0.49","hash":"34fd6e055871747c0ff5aa214e31043f48f0a7a1","price":"0.51","side":"SELL","size":"130"}],"timestamp":"1785121613513"},"payload_hash":"b20dff277336cff83fff276ee3aea706c573757403ba81bfceff8350f935e8d1","raw_frame":"{\"market\":\"0xf9d60bb033695053c4d1d8592e52171c1042f64b41a4b72e09dcc6f4852b6670\", \"price_changes\":[{\"asset_id\":\"96283536366176669581486355171583722558858323126916278856549586825357358273536\", \"price\":\"0.49\", \"size\":\"130\", \"side\":\"BUY\", \"hash\":\"d310191bdd6afeaf2ae2244cd8d4c2f2b98e38db\", \"best_bid\":\"0.49\", \"best_ask\":\"0.51\"}, {\"asset_id\":\"8698449539441374295770236407991735029336433231649246775082939325523552031992\", \"price\":\"0.51\", \"size\":\"130\", \"side\":\"SELL\", \"hash\":\"34fd6e055871747c0ff5aa214e31043f48f0a7a1\", \"best_bid\":\"0.49\", \"best_ask\":\"0.51\"}], \"timestamp\":\"1785121613513\", \"event_type\":\"price_change\"}","received_at":"2026-07-27T03:06:53.565923Z","schema_version":"clob-market-ws.price_change.v1","sequence":null,"server_hash":null,"server_timestamp":"1785121613513","session_id":"ff6d21c8283948938400a32613abec2c","source":"clob_market_ws"},"received_at":"2026-07-27T03:06:53.565923Z","record_id":"409283e0d30678978cfcbc488f0cd458d438176db8fcc05ed00e972cdeef3251","schema_fingerprint":"4aa3821a28b0b7c2400bc59aba4bcc0a76e971dadd19610d3ad38c768e124dc7","schema_version":"edge-lab-recorder.raw.v1","sequence":null,"source":"clob_market_ws"}
{"event_at":"2026-07-27T03:06:53.514000Z","event_fingerprint":"815bef002390aa9505b97ffddbea88be77f78b54f15f89f6661a12505ca0746d","payload":{"connection_id":"f95883f18d264834af91809e5f803e9f","event_at":"2026-07-27T03:06:53.514000Z","event_type":"price_change","frame_hash":"c89ce4906bdf2dad610ee8a2b10cfc19d5ec6a6e3bdc0d376672a8584af2336c","frame_index":0,"kind":"data","monotonic_ns":223596893437333,"payload":{"event_type":"price_change","market":"0xf9d60bb033695053c4d1d8592e52171c1042f64b41a4b72e09dcc6f4852b6670","price_changes":[{"asset_id":"96283536366176669581486355171583722558858323126916278856549586825357358273536","best_ask":"0.51","best_bid":"0.49","hash":"f0a168eaf15b8e92169d223677e3e96bc8a2ebbb","price":"0.49","side":"BUY","size":"135"},{"asset_id":"8698449539441374295770236407991735029336433231649246775082939325523552031992","best_ask":"0.51","best_bid":"0.49","hash":"592e3054df26f53862d62b7f820945c21e1e0ef2","price":"0.51","side":"SELL","size":"135"}],"timestamp":"1785121613514"},"payload_hash":"f715014502f804492e17eb14ba5a4e4eb3d5e75a2ffd25e76407c4f25d4f64e1","raw_frame":"{\"market\":\"0xf9d60bb033695053c4d1d8592e52171c1042f64b41a4b72e09dcc6f4852b6670\", \"price_changes\":[{\"asset_id\":\"96283536366176669581486355171583722558858323126916278856549586825357358273536\", \"price\":\"0.49\", \"size\":\"135\", \"side\":\"BUY\", \"hash\":\"f0a168eaf15b8e92169d223677e3e96bc8a2ebbb\", \"best_bid\":\"0.49\", \"best_ask\":\"0.51\"}, {\"asset_id\":\"8698449539441374295770236407991735029336433231649246775082939325523552031992\", \"price\":\"0.51\", \"size\":\"135\", \"side\":\"SELL\", \"hash\":\"592e3054df26f53862d62b7f820945c21e1e0ef2\", \"best_bid\":\"0.49\", \"best_ask\":\"0.51\"}], \"timestamp\":\"1785121613514\", \"event_type\":\"price_change\"}","received_at":"2026-07-27T03:06:53.566592Z","schema_version":"clob-market-ws.price_change.v1","sequence":null,"server_hash":null,"server_timestamp":"1785121613514","session_id":"ff6d21c8283948938400a32613abec2c","source":"clob_market_ws"},"received_at":"2026-07-27T03:06:53.566592Z","record_id":"41cd6ee21a118f4d6a7f3b0e7cadcb5fecd5d5cfe14a00cfdec6b23e5e2b6c25","schema_fingerprint":"4aa3821a28b0b7c2400bc59aba4bcc0a76e971dadd19610d3ad38c768e124dc7","schema_version":"edge-lab-recorder.raw.v1","sequence":null,"source":"clob_market_ws"}
{"event_at":"2026-07-27T03:06:53.515000Z","event_fingerprint":"c231c0abba03b1d295e9b245c40e81269b5179a31c2939af5673bc3450d378d3","payload":{"connection_id":"f95883f18d264834af91809e5f803e9f","event_at":"2026-07-27T03:06:53.515000Z","event_type":"price_change","frame_hash":"40b16d4b003d7dbba420cdac46dadbbfc6a3ed9704dd95ea58389cf95ac41a2a","frame_index":0,"kind":"data","monotonic_ns":223596894879291,"payload":{"event_type":"price_change","market":"0xf9d60bb033695053c4d1d8592e52171c1042f64b41a4b72e09dcc6f4852b6670","price_changes":[{"asset_id":"96283536366176669581486355171583722558858323126916278856549586825357358273536","best_ask":"0.51","best_bid":"0.49","hash":"6e2904e0dda1fc9a99a84fc565a44c1700e1b74a","price":"0.49","side":"BUY","size":"140"},{"asset_id":"8698449539441374295770236407991735029336433231649246775082939325523552031992","best_ask":"0.51","best_bid":"0.49","hash":"91194675574dd7d6497560c45a69408b1c714221","price":"0.51","side":"SELL","size":"140"}],"timestamp":"1785121613515"},"payload_hash":"6848bc6be6a998a73188fdca4521fc7dc4ca7cdb0ccac1374cd8f42a2fdbe86c","raw_frame":"{\"market\":\"0xf9d60bb033695053c4d1d8592e52171c1042f64b41a4b72e09dcc6f4852b6670\", \"price_changes\":[{\"asset_id\":\"96283536366176669581486355171583722558858323126916278856549586825357358273536\", \"price\":\"0.49\", \"size\":\"140\", \"side\":\"BUY\", \"hash\":\"6e2904e0dda1fc9a99a84fc565a44c1700e1b74a\", \"best_bid\":\"0.49\", \"best_ask\":\"0.51\"}, {\"asset_id\":\"8698449539441374295770236407991735029336433231649246775082939325523552031992\", \"price\":\"0.51\", \"size\":\"140\", \"side\":\"SELL\", \"hash\":\"91194675574dd7d6497560c45a69408b1c714221\", \"best_bid\":\"0.49\", \"best_ask\":\"0.51\"}], \"timestamp\":\"1785121613515\", \"event_type\":\"price_change\"}","received_at":"2026-07-27T03:06:53.568034Z","schema_version":"clob-market-ws.price_change.v1","sequence":null,"server_hash":null,"server_timestamp":"1785121613515","session_id":"ff6d21c8283948938400a32613abec2c","source":"clob_market_ws"},"received_at":"2026-07-27T03:06:53.568034Z","record_id":"a8e1ddc0c72e0617156260e446008d5e363e8f1494e0bc9755ef4d8f65d675a3","schema_fingerprint":"4aa3821a28b0b7c2400bc59aba4bcc0a76e971dadd19610d3ad38c768e124dc7","schema_version":"edge-lab-recorder.raw.v1","sequence":null,"source":"clob_market_ws"}
{"event_at":"2026-07-27T03:06:53.515000Z","event_fingerprint":"8d55098c2f876e2608784581ad61811ec1ff3ef23d1403709444d8adcc80b446","payload":{"connection_id":"f95883f18d264834af91809e5f803e9f","event_at":"2026-07-27T03:06:53.515000Z","event_type":"price_change","frame_hash":"daff4a7a72fba47195c8b913fbcc6402d82b9a54f07edc83e524ccf3c3125c55","frame_index":0,"kind":"data","monotonic_ns":223596914950750,"payload":{"event_type":"price_change","market":"0xf9d60bb033695053c4d1d8592e52171c1042f64b41a4b72e09dcc6f4852b6670","price_changes":[{"asset_id":"8698449539441374295770236407991735029336433231649246775082939325523552031992","best_ask":"0.51","best_bid":"0.49","hash":"b16260299f64b41924700f7ffc6062011acb7e8d","price":"0.47","side":"BUY","size":"94.45"},{"asset_id":"96283536366176669581486355171583722558858323126916278856549586825357358273536","best_ask":"0.51","best_bid":"0.49","hash":"1a8879bef2045359aadb3ba960ed093600ed08de","price":"0.53","side":"SELL","size":"94.45"}],"timestamp":"1785121613515"},"payload_hash":"142503b3508d58fe8b460a51fc96ccf7f3e39987c633b0dbf3cc74bdf9d395a8","raw_frame":"{\"market\":\"0xf9d60bb033695053c4d1d8592e52171c1042f64b41a4b72e09dcc6f4852b6670\", \"price_changes\":[{\"asset_id\":\"8698449539441374295770236407991735029336433231649246775082939325523552031992\", \"price\":\"0.47\", \"size\":\"94.45\", \"side\":\"BUY\", \"hash\":\"b16260299f64b41924700f7ffc6062011acb7e8d\", \"best_bid\":\"0.49\", \"best_ask\":\"0.51\"}, {\"asset_id\":\"96283536366176669581486355171583722558858323126916278856549586825357358273536\", \"price\":\"0.53\", \"size\":\"94.45\", \"side\":\"SELL\", \"hash\":\"1a8879bef2045359aadb3ba960ed093600ed08de\", \"best_bid\":\"0.49\", \"best_ask\":\"0.51\"}], \"timestamp\":\"1785121613515\", \"event_type\":\"price_change\"}","received_at":"2026-07-27T03:06:53.588109Z","schema_version":"clob-market-ws.price_change.v1","sequence":null,"server_hash":null,"server_timestamp":"1785121613515","session_id":"ff6d21c8283948938400a32613abec2c","source":"clob_market_ws"},"received_at":"2026-07-27T03:06:53.588109Z","record_id":"f8bbf4cfd28dd7b6ac0a3ce865ac140d2a0631bb36418a4fa9cca496dbc84233","schema_fingerprint":"4aa3821a28b0b7c2400bc59aba4bcc0a76e971dadd19610d3ad38c768e124dc7","schema_version":"edge-lab-recorder.raw.v1","sequence":null,"source":"clob_market_ws"}
{"event_at":"2026-07-27T03:06:53.516000Z","event_fingerprint":"a6b102df8eda2ed44bd5369e717d43866d1da4221116d5c24a651407fd08c2a2","payload":{"connection_id":"f95883f18d264834af91809e5f803e9f","event_at":"2026-07-27T03:06:53.516000Z","event_type":"price_change","frame_hash":"875bfb9125c820bb5bbc338eca5d39d0ef73d76e5fd8106c5abb114c87c9719d","frame_index":0,"kind":"data","monotonic_ns":223596915603708,"payload":{"event_type":"price_change","market":"0xf9d60bb033695053c4d1d8592e52171c1042f64b41a4b72e09dcc6f4852b6670","price_changes":[{"asset_id":"96283536366176669581486355171583722558858323126916278856549586825357358273536","best_ask":"0.51","best_bid":"0.49","hash":"dd9461e7b2c6afcc6b6d50c30410c0868c08c89f","price":"0.49","side":"BUY","size":"145"},{"asset_id":"8698449539441374295770236407991735029336433231649246775082939325523552031992","best_ask":"0.51","best_bid":"0.49","hash":"b85872165aa6f1c11f7c8b1f465748038fee651b","price":"0.51","side":"SELL","size":"145"}],"timestamp":"1785121613516"},"payload_hash":"7e49eeb21081ffb79384a1a735883e61b4acf3634050e0280f8333fbc3ae8d4d","raw_frame":"{\"market\":\"0xf9d60bb033695053c4d1d8592e52171c1042f64b41a4b72e09dcc6f4852b6670\", \"price_changes\":[{\"asset_id\":\"96283536366176669581486355171583722558858323126916278856549586825357358273536\", \"price\":\"0.49\", \"size\":\"145\", \"side\":\"BUY\", \"hash\":\"dd9461e7b2c6afcc6b6d50c30410c0868c08c89f\", \"best_bid\":\"0.49\", \"best_ask\":\"0.51\"}, {\"asset_id\":\"8698449539441374295770236407991735029336433231649246775082939325523552031992\", \"price\":\"0.51\", \"size\":\"145\", \"side\":\"SELL\", \"hash\":\"b85872165aa6f1c11f7c8b1f465748038fee651b\", \"best_bid\":\"0.49\", \"best_ask\":\"0.51\"}], \"timestamp\":\"1785121613516\", \"event_type\":\"price_change\"}","received_at":"2026-07-27T03:06:53.588764Z","schema_version":"clob-market-ws.price_change.v1","sequence":null,"server_hash":null,"server_timestamp":"1785121613516","session_id":"ff6d21c8283948938400a32613abec2c","source":"clob_market_ws"},"received_at":"2026-07-27T03:06:53.588764Z","record_id":"57e44d0a7ddbaafe19ec703163c8a0804fafac2ddda825ba15006e530dbc0498","schema_fingerprint":"4aa3821a28b0b7c2400bc59aba4bcc0a76e971dadd19610d3ad38c768e124dc7","schema_version":"edge-lab-recorder.raw.v1","sequence":null,"source":"clob_market_ws"}
{"event_at":"2026-07-27T03:06:53.517000Z","event_fingerprint":"205a21b50afbd1402094e188dc6d611eb3a72e6ff3d0bf2193ba304708088376","payload":{"connection_id":"f95883f18d264834af91809e5f803e9f","event_at":"2026-07-27T03:06:53.517000Z","event_type":"price_change","frame_hash":"fa2875191827571a5833cecbcef522fed270397f6fe597f7197ae53e46d79dfd","frame_index":0,"kind":"data","monotonic_ns":223596916114208,"payload":{"event_type":"price_change","market":"0xf9d60bb033695053c4d1d8592e52171c1042f64b41a4b72e09dcc6f4852b6670","price_changes":[{"asset_id":"8698449539441374295770236407991735029336433231649246775082939325523552031992","best_ask":"0.51","best_bid":"0.49","hash":"8c73842186366f3d61ffc396c76fd386c88a1387","price":"0.47","side":"BUY","size":"99.45"},{"asset_id":"96283536366176669581486355171583722558858323126916278856549586825357358273536","best_ask":"0.51","best_bid":"0.49","hash":"1b07bcc506ec1963741e641c56a3a6b69b0e8a05","price":"0.53","side":"SELL","size":"99.45"}],"timestamp":"1785121613517"},"payload_hash":"647e9d88322839dfb87721ca03f142439a8feb65ad348e585b4e2f21b83e05ba","raw_frame":"{\"market\":\"0xf9d60bb033695053c4d1d8592e52171c1042f64b41a4b72e09dcc6f4852b6670\", \"price_changes\":[{\"asset_id\":\"8698449539441374295770236407991735029336433231649246775082939325523552031992\", \"price\":\"0.47\", \"size\":\"99.45\", \"side\":\"BUY\", \"hash\":\"8c73842186366f3d61ffc396c76fd386c88a1387\", \"best_bid\":\"0.49\", \"best_ask\":\"0.51\"}, {\"asset_id\":\"96283536366176669581486355171583722558858323126916278856549586825357358273536\", \"price\":\"0.53\", \"size\":\"99.45\", \"side\":\"SELL\", \"hash\":\"1b07bcc506ec1963741e641c56a3a6b69b0e8a05\", \"best_bid\":\"0.49\", \"best_ask\":\"0.51\"}], \"timestamp\":\"1785121613517\", \"event_type\":\"price_change\"}","received_at":"2026-07-27T03:06:53.589274Z","schema_version":"clob-market-ws.price_change.v1","sequence":null,"server_hash":null,"server_timestamp":"1785121613517","session_id":"ff6d21c8283948938400a32613abec2c","source":"clob_market_ws"},"received_at":"2026-07-27T03:06:53.589274Z","record_id":"4ea67920338fbc58967b069c8b5eb0c3c38563a75a2ea22610c36569599bd0d1","schema_fingerprint":"4aa3821a28b0b7c2400bc59aba4bcc0a76e971dadd19610d3ad38c768e124dc7","schema_version":"edge-lab-recorder.raw.v1","sequence":null,"source":"clob_market_ws"}
{"event_at":"2026-07-27T03:06:53.517000Z","event_fingerprint":"f90b65b03ca76fe622ffa30e0c9ad975ac648afb8298c661113a50e20fadbe12","payload":{"connection_id":"f95883f18d264834af91809e5f803e9f","event_at":"2026-07-27T03:06:53.517000Z","event_type":"price_change","frame_hash":"ba836a47f0cf4005e2b78ebc72cd5309b3bbdb1270a7c27e3655e4c8cf7da789","frame_index":0,"kind":"data","monotonic_ns":223596916772875,"payload":{"event_type":"price_change","market":"0xf9d60bb033695053c4d1d8592e52171c1042f64b41a4b72e09dcc6f4852b6670","price_changes":[{"asset_id":"96283536366176669581486355171583722558858323126916278856549586825357358273536","best_ask":"0.51","best_bid":"0.49","hash":"5012377752e2c3e42201de43e4d3675591ff413e","price":"0.49","side":"BUY","size":"150"},{"asset_id":"8698449539441374295770236407991735029336433231649246775082939325523552031992","best_ask":"0.51","best_bid":"0.49","hash":"e159392fd4742750a8573f9c0a960a37aae95f8e","price":"0.51","side":"SELL","size":"150"}],"timestamp":"1785121613517"},"payload_hash":"e269435f6c277156cb57a05b9cf728a3c5f46e225a7c1dd2e2b75f8773e0dc70","raw_frame":"{\"market\":\"0xf9d60bb033695053c4d1d8592e52171c1042f64b41a4b72e09dcc6f4852b6670\", \"price_changes\":[{\"asset_id\":\"96283536366176669581486355171583722558858323126916278856549586825357358273536\", \"price\":\"0.49\", \"size\":\"150\", \"side\":\"BUY\", \"hash\":\"5012377752e2c3e42201de43e4d3675591ff413e\", \"best_bid\":\"0.49\", \"best_ask\":\"0.51\"}, {\"asset_id\":\"8698449539441374295770236407991735029336433231649246775082939325523552031992\", \"price\":\"0.51\", \"size\":\"150\", \"side\":\"SELL\", \"hash\":\"e159392fd4742750a8573f9c0a960a37aae95f8e\", \"best_bid\":\"0.49\", \"best_ask\":\"0.51\"}], \"timestamp\":\"1785121613517\", \"event_type\":\"price_change\"}","received_at":"2026-07-27T03:06:53.589931Z","schema_version":"clob-market-ws.price_change.v1","sequence":null,"server_hash":null,"server_timestamp":"1785121613517","session_id":"ff6d21c8283948938400a32613abec2c","source":"clob_market_ws"},"received_at":"2026-07-27T03:06:53.589931Z","record_id":"6dbd1266ba97e00151edccafe1bb6f88798733e6d1feaa9d74b29780285ec97a","schema_fingerprint":"4aa3821a28b0b7c2400bc59aba4bcc0a76e971dadd19610d3ad38c768e124dc7","schema_version":"edge-lab-recorder.raw.v1","sequence":null,"source":"clob_market_ws"}
{"event_at":"2026-07-27T03:06:53.518000Z","event_fingerprint":"480dbb2af17944e23252ed38a3f893bd00930102a19f35e967d937b5ac6e3fa8","payload":{"connection_id":"f95883f18d264834af91809e5f803e9f","event_at":"2026-07-27T03:06:53.518000Z","event_type":"price_change","frame_hash":"c01bfa6c0845cb24a584040e7cc10b4ef6bd9f176998a7d677139da33542df60","frame_index":0,"kind":"data","monotonic_ns":223596917631500,"payload":{"event_type":"price_change","market":"0xf9d60bb033695053c4d1d8592e52171c1042f64b41a4b72e09dcc6f4852b6670","price_changes":[{"asset_id":"8698449539441374295770236407991735029336433231649246775082939325523552031992","best_ask":"0.51","best_bid":"0.49","hash":"74b72fcede87d0135821acc067b9a5ec79925fe7","price":"0.47","side":"BUY","size":"104.45"},{"asset_id":"96283536366176669581486355171583722558858323126916278856549586825357358273536","best_ask":"0.51","best_bid":"0.49","hash":"feabb115a96a96bbe95e45827c3d5d3d5bb4b5a0","price":"0.53","side":"SELL","size":"104.45"}],"timestamp":"1785121613518"},"payload_hash":"018f21b08b4e9f3cadf063d41a47b9cffe1fcb9c3fc9277cab1d9be4de64d0ca","raw_frame":"{\"market\":\"0xf9d60bb033695053c4d1d8592e52171c1042f64b41a4b72e09dcc6f4852b6670\", \"price_changes\":[{\"asset_id\":\"8698449539441374295770236407991735029336433231649246775082939325523552031992\", \"price\":\"0.47\", \"size\":\"104.45\", \"side\":\"BUY\", \"hash\":\"74b72fcede87d0135821acc067b9a5ec79925fe7\", \"best_bid\":\"0.49\", \"best_ask\":\"0.51\"}, {\"asset_id\":\"96283536366176669581486355171583722558858323126916278856549586825357358273536\", \"price\":\"0.53\", \"size\":\"104.45\", \"side\":\"SELL\", \"hash\":\"feabb115a96a96bbe95e45827c3d5d3d5bb4b5a0\", \"best_bid\":\"0.49\", \"best_ask\":\"0.51\"}], \"timestamp\":\"1785121613518\", \"event_type\":\"price_change\"}","received_at":"2026-07-27T03:06:53.590790Z","schema_version":"clob-market-ws.price_change.v1","sequence":null,"server_hash":null,"server_timestamp":"1785121613518","session_id":"ff6d21c8283948938400a32613abec2c","source":"clob_market_ws"},"received_at":"2026-07-27T03:06:53.590790Z","record_id":"a488a2c784bf6dde35649dd5e1d7f78991b324fd354a68da0d3eaed1278a8561","schema_fingerprint":"4aa3821a28b0b7c2400bc59aba4bcc0a76e971dadd19610d3ad38c768e124dc7","schema_version":"edge-lab-recorder.raw.v1","sequence":null,"source":"clob_market_ws"}
{"event_at":"2026-07-27T03:06:53.519000Z","event_fingerprint":"e7bea1a93c57885edf52b3a2a8e8f9220c0a0bd6b0af6c0c2aeea435c5f9f2ac","payload":{"connection_id":"f95883f18d264834af91809e5f803e9f","event_at":"2026-07-27T03:06:53.519000Z","event_type":"price_change","frame_hash":"274c3fcad04fcb7fa389f6527f94daff51ad308e6ed855465a2b151d5a183ea3","frame_index":0,"kind":"data","monotonic_ns":223596918438333,"payload":{"event_type":"price_change","market":"0xf9d60bb033695053c4d1d8592e52171c1042f64b41a4b72e09dcc6f4852b6670","price_changes":[{"asset_id":"8698449539441374295770236407991735029336433231649246775082939325523552031992","best_ask":"0.51","best_bid":"0.49","hash":"a337230dacdd8fb0b35cd2dbb7acf0248fac2dbc","price":"0.47","side":"BUY","size":"109.45"},{"asset_id":"96283536366176669581486355171583722558858323126916278856549586825357358273536","best_ask":"0.51","best_bid":"0.49","hash":"4323c87ff11823c9ec56157e22cc3ec59b25ac7e","price":"0.53","side":"SELL","size":"109.45"}],"timestamp":"1785121613519"},"payload_hash":"82303aa675b77b95ea0496986239df0f877de2943badf52dfacdb6aa5c398c3e","raw_frame":"{\"market\":\"0xf9d60bb033695053c4d1d8592e52171c1042f64b41a4b72e09dcc6f4852b6670\", \"price_changes\":[{\"asset_id\":\"8698449539441374295770236407991735029336433231649246775082939325523552031992\", \"price\":\"0.47\", \"size\":\"109.45\", \"side\":\"BUY\", \"hash\":\"a337230dacdd8fb0b35cd2dbb7acf0248fac2dbc\", \"best_bid\":\"0.49\", \"best_ask\":\"0.51\"}, {\"asset_id\":\"96283536366176669581486355171583722558858323126916278856549586825357358273536\", \"price\":\"0.53\", \"size\":\"109.45\", \"side\":\"SELL\", \"hash\":\"4323c87ff11823c9ec56157e22cc3ec59b25ac7e\", \"best_bid\":\"0.49\", \"best_ask\":\"0.51\"}], \"timestamp\":\"1785121613519\", \"event_type\":\"price_change\"}","received_at":"2026-07-27T03:06:53.591597Z","schema_version":"clob-market-ws.price_change.v1","sequence":null,"server_hash":null,"server_timestamp":"1785121613519","session_id":"ff6d21c8283948938400a32613abec2c","source":"clob_market_ws"},"received_at":"2026-07-27T03:06:53.591597Z","record_id":"18dfbf7cb6e21b50294dc6fb751a7a6bfd90e0da9b191dc7aa92fc19002ee645","schema_fingerprint":"4aa3821a28b0b7c2400bc59aba4bcc0a76e971dadd19610d3ad38c768e124dc7","schema_version":"edge-lab-recorder.raw.v1","sequence":null,"source":"clob_market_ws"}
{"event_at":"2026-07-27T03:06:53.520000Z","event_fingerprint":"667497f761a6c8838d51cec6ac16875788f0f540dfd33db8f83320baab07f9a6","payload":{"connection_id":"f95883f18d264834af91809e5f803e9f","event_at":"2026-07-27T03:06:53.520000Z","event_type":"price_change","frame_hash":"23dd9177540df741995b50c7463a1cc0fe570970ce5ab6dc2e0bd7514a2c38cd","frame_index":0,"kind":"data","monotonic_ns":223596919159416,"payload":{"event_type":"price_change","market":"0xf9d60bb033695053c4d1d8592e52171c1042f64b41a4b72e09dcc6f4852b6670","price_changes":[{"asset_id":"8698449539441374295770236407991735029336433231649246775082939325523552031992","best_ask":"0.51","best_bid":"0.49","hash":"08b67269d61f4c4504d32c2716389e3a2b555e70","price":"0.47","side":"BUY","size":"114.45"},{"asset_id":"96283536366176669581486355171583722558858323126916278856549586825357358273536","best_ask":"0.51","best_bid":"0.49","hash":"ea05d0f3dd198a77abeabcacc1aa1861ce2b7398","price":"0.53","side":"SELL","size":"114.45"}],"timestamp":"1785121613520"},"payload_hash":"9a8b12faa1ec8837aa80afeab66b14f1f54342f5f3d226eadc89614d8af69e89","raw_frame":"{\"market\":\"0xf9d60bb033695053c4d1d8592e52171c1042f64b41a4b72e09dcc6f4852b6670\", \"price_changes\":[{\"asset_id\":\"8698449539441374295770236407991735029336433231649246775082939325523552031992\", \"price\":\"0.47\", \"size\":\"114.45\", \"side\":\"BUY\", \"hash\":\"08b67269d61f4c4504d32c2716389e3a2b555e70\", \"best_bid\":\"0.49\", \"best_ask\":\"0.51\"}, {\"asset_id\":\"96283536366176669581486355171583722558858323126916278856549586825357358273536\", \"price\":\"0.53\", \"size\":\"114.45\", \"side\":\"SELL\", \"hash\":\"ea05d0f3dd198a77abeabcacc1aa1861ce2b7398\", \"best_bid\":\"0.49\", \"best_ask\":\"0.51\"}], \"timestamp\":\"1785121613520\", \"event_type\":\"price_change\"}","received_at":"2026-07-27T03:06:53.592318Z","schema_version":"clob-market-ws.price_change.v1","sequence":null,"server_hash":null,"server_timestamp":"1785121613520","session_id":"ff6d21c8283948938400a32613abec2c","source":"clob_market_ws"},"received_at":"2026-07-27T03:06:53.592318Z","record_id":"2009265b6140676baf662e861d1cea7e3508d0567f81cfe73a8e3c02016b8c87","schema_fingerprint":"4aa3821a28b0b7c2400bc59aba4bcc0a76e971dadd19610d3ad38c768e124dc7","schema_version":"edge-lab-recorder.raw.v1","sequence":null,"source":"clob_market_ws"}
{"event_at":"2026-07-27T03:06:53.521000Z","event_fingerprint":"896fc2c30be05d650126f75c6acfbb0c490de7d5c02ff0a160632dd61d1a774e","payload":{"connection_id":"f95883f18d264834af91809e5f803e9f","event_at":"2026-07-27T03:06:53.521000Z","event_type":"price_change","frame_hash":"716f031564c1ee656c79076573efea56be66e5035fd2843753b98b5f66f4d736","frame_index":0,"kind":"data","monotonic_ns":223596920097416,"payload":{"event_type":"price_change","market":"0xf9d60bb033695053c4d1d8592e52171c1042f64b41a4b72e09dcc6f4852b6670","price_changes":[{"asset_id":"96283536366176669581486355171583722558858323126916278856549586825357358273536","best_ask":"0.51","best_bid":"0.49","hash":"411a5036ea75f24424e55e2e6202ab33a1eb15f6","price":"0.49","side":"BUY","size":"155"},{"asset_id":"8698449539441374295770236407991735029336433231649246775082939325523552031992","best_ask":"0.51","best_bid":"0.49","hash":"674796417d0ac02f58d488e3faaa7e0d9951cb19","price":"0.51","side":"SELL","size":"155"}],"timestamp":"1785121613521"},"payload_hash":"388386497658e6a902103dad9c889445fd7243398db6cdf7bbe8bdda5b399cfb","raw_frame":"{\"market\":\"0xf9d60bb033695053c4d1d8592e52171c1042f64b41a4b72e09dcc6f4852b6670\", \"price_changes\":[{\"asset_id\":\"96283536366176669581486355171583722558858323126916278856549586825357358273536\", \"price\":\"0.49\", \"size\":\"155\", \"side\":\"BUY\", \"hash\":\"411a5036ea75f24424e55e2e6202ab33a1eb15f6\", \"best_bid\":\"0.49\", \"best_ask\":\"0.51\"}, {\"asset_id\":\"8698449539441374295770236407991735029336433231649246775082939325523552031992\", \"price\":\"0.51\", \"size\":\"155\", \"side\":\"SELL\", \"hash\":\"674796417d0ac02f58d488e3faaa7e0d9951cb19\", \"best_bid\":\"0.49\", \"best_ask\":\"0.51\"}], \"timestamp\":\"1785121613521\", \"event_type\":\"price_change\"}","received_at":"2026-07-27T03:06:53.593256Z","schema_version":"clob-market-ws.price_change.v1","sequence":null,"server_hash":null,"server_timestamp":"1785121613521","session_id":"ff6d21c8283948938400a32613abec2c","source":"clob_market_ws"},"received_at":"2026-07-27T03:06:53.593256Z","record_id":"262f84f8aa9c18619bbbbe0493e91f7cab7468c6add9e1fc0cf67972740b5f0c","schema_fingerprint":"4aa3821a28b0b7c2400bc59aba4bcc0a76e971dadd19610d3ad38c768e124dc7","schema_version":"edge-lab-recorder.raw.v1","sequence":null,"source":"clob_market_ws"}
{"event_at":"2026-07-27T03:06:53.521000Z","event_fingerprint":"7e450e70540df95979138b74847f57c06bb7aad08ca7a88ff49cad7ad1c586eb","payload":{"connection_id":"f95883f18d264834af91809e5f803e9f","event_at":"2026-07-27T03:06:53.521000Z","event_type":"price_change","frame_hash":"d7d098b7c37a30a16793e084582b015600066bb1f82428741b30cd7a9635f4e7","frame_index":0,"kind":"data","monotonic_ns":223596920840333,"payload":{"event_type":"price_change","market":"0xf9d60bb033695053c4d1d8592e52171c1042f64b41a4b72e09dcc6f4852b6670","price_changes":[{"asset_id":"96283536366176669581486355171583722558858323126916278856549586825357358273536","best_ask":"0.51","best_bid":"0.49","hash":"bed8c66b9775e4a2278b9948bef5953670e9b154","price":"0.49","side":"BUY","size":"160"},{"asset_id":"8698449539441374295770236407991735029336433231649246775082939325523552031992","best_ask":"0.51","best_bid":"0.49","hash":"7aef563b0d7c2fa6639db29c98c0de56a884543f","price":"0.51","side":"SELL","size":"160"}],"timestamp":"1785121613521"},"payload_hash":"62aaaecff345a08763b0bc3a5dd3aa09cbc39f907549e1b8f6cf6ccfb3cabb66","raw_frame":"{\"market\":\"0xf9d60bb033695053c4d1d8592e52171c1042f64b41a4b72e09dcc6f4852b6670\", \"price_changes\":[{\"asset_id\":\"96283536366176669581486355171583722558858323126916278856549586825357358273536\", \"price\":\"0.49\", \"size\":\"160\", \"side\":\"BUY\", \"hash\":\"bed8c66b9775e4a2278b9948bef5953670e9b154\", \"best_bid\":\"0.49\", \"best_ask\":\"0.51\"}, {\"asset_id\":\"8698449539441374295770236407991735029336433231649246775082939325523552031992\", \"price\":\"0.51\", \"size\":\"160\", \"side\":\"SELL\", \"hash\":\"7aef563b0d7c2fa6639db29c98c0de56a884543f\", \"best_bid\":\"0.49\", \"best_ask\":\"0.51\"}], \"timestamp\":\"1785121613521\", \"event_type\":\"price_change\"}","received_at":"2026-07-27T03:06:53.593999Z","schema_version":"clob-market-ws.price_change.v1","sequence":null,"server_hash":null,"server_timestamp":"1785121613521","session_id":"ff6d21c8283948938400a32613abec2c","source":"clob_market_ws"},"received_at":"2026-07-27T03:06:53.593999Z","record_id":"b5ab909c76153984bdb2b32d23b9f44efff9e0288f9f2426cc3690a8161567fa","schema_fingerprint":"4aa3821a28b0b7c2400bc59aba4bcc0a76e971dadd19610d3ad38c768e124dc7","schema_version":"edge-lab-recorder.raw.v1","sequence":null,"source":"clob_market_ws"}
{"event_at":"2026-07-27T03:06:53.522000Z","event_fingerprint":"81bbeea2aa63c5b7d1fb1adf6bcf766dbab2edc2b975cbbfaefbb7e40b397fa5","payload":{"connection_id":"f95883f18d264834af91809e5f803e9f","event_at":"2026-07-27T03:06:53.522000Z","event_type":"price_change","frame_hash":"ed6f85964ba21579c3ae403589125707770abfaa2365aea751fa90e7ae80050e","frame_index":0,"kind":"data","monotonic_ns":223596921568500,"payload":{"event_type":"price_change","market":"0xf9d60bb033695053c4d1d8592e52171c1042f64b41a4b72e09dcc6f4852b6670","price_changes":[{"asset_id":"96283536366176669581486355171583722558858323126916278856549586825357358273536","best_ask":"0.51","best_bid":"0.49","hash":"2b39a3bfa6d199c03cc228fa178bbb691699895e","price":"0.49","side":"BUY","size":"165"},{"asset_id":"8698449539441374295770236407991735029336433231649246775082939325523552031992","best_ask":"0.51","best_bid":"0.49","hash":"45b73a8c48835bdaf8c13934f3ba201cd80a126e","price":"0.51","side":"SELL","size":"165"}],"timestamp":"1785121613522"},"payload_hash":"fe30b33879e99bf8b803e6a9635a78783a4dba0c85cc0c9aae5ebd1326babba7","raw_frame":"{\"market\":\"0xf9d60bb033695053c4d1d8592e52171c1042f64b41a4b72e09dcc6f4852b6670\", \"price_changes\":[{\"asset_id\":\"96283536366176669581486355171583722558858323126916278856549586825357358273536\", \"price\":\"0.49\", \"size\":\"165\", \"side\":\"BUY\", \"hash\":\"2b39a3bfa6d199c03cc228fa178bbb691699895e\", \"best_bid\":\"0.49\", \"best_ask\":\"0.51\"}, {\"asset_id\":\"8698449539441374295770236407991735029336433231649246775082939325523552031992\", \"price\":\"0.51\", \"size\":\"165\", \"side\":\"SELL\", \"hash\":\"45b73a8c48835bdaf8c13934f3ba201cd80a126e\", \"best_bid\":\"0.49\", \"best_ask\":\"0.51\"}], \"timestamp\":\"1785121613522\", \"event_type\":\"price_change\"}","received_at":"2026-07-27T03:06:53.594727Z","schema_version":"clob-market-ws.price_change.v1","sequence":null,"server_hash":null,"server_timestamp":"1785121613522","session_id":"ff6d21c8283948938400a32613abec2c","source":"clob_market_ws"},"received_at":"2026-07-27T03:06:53.594727Z","record_id":"4db4cee3e5d2c387098ff853e9a9db50ec72cae388e9a26282fb013a2e3b16f8","schema_fingerprint":"4aa3821a28b0b7c2400bc59aba4bcc0a76e971dadd19610d3ad38c768e124dc7","schema_version":"edge-lab-recorder.raw.v1","sequence":null,"source":"clob_market_ws"}
{"event_at":"2026-07-27T03:06:53.523000Z","event_fingerprint":"9a8791b1e24ad1c611b33fa700662d1d1544eef2dee0da5f19184591dcf8503f","payload":{"connection_id":"f95883f18d264834af91809e5f803e9f","event_at":"2026-07-27T03:06:53.523000Z","event_type":"price_change","frame_hash":"50123a045efe93cdf2862765b9c627fa0a3497c087b7127926ecfc5a7a5a8609","frame_index":0,"kind":"data","monotonic_ns":223596922293958,"payload":{"event_type":"price_change","market":"0xf9d60bb033695053c4d1d8592e52171c1042f64b41a4b72e09dcc6f4852b6670","price_changes":[{"asset_id":"96283536366176669581486355171583722558858323126916278856549586825357358273536","best_ask":"0.51","best_bid":"0.49","hash":"1fc533455fdfd082c7a4088418e808b8c3194292","price":"0.49","side":"BUY","size":"170"},{"asset_id":"8698449539441374295770236407991735029336433231649246775082939325523552031992","best_ask":"0.51","best_bid":"0.49","hash":"edaf4c57394d67156f9e3a475fd9934cb316f25b","price":"0.51","side":"SELL","size":"170"}],"timestamp":"1785121613523"},"payload_hash":"5ae70e1272eda0350aad66715eadf723d9bfad93f216041c51d1b89cc6e6e3f1","raw_frame":"{\"market\":\"0xf9d60bb033695053c4d1d8592e52171c1042f64b41a4b72e09dcc6f4852b6670\", \"price_changes\":[{\"asset_id\":\"96283536366176669581486355171583722558858323126916278856549586825357358273536\", \"price\":\"0.49\", \"size\":\"170\", \"side\":\"BUY\", \"hash\":\"1fc533455fdfd082c7a4088418e808b8c3194292\", \"best_bid\":\"0.49\", \"best_ask\":\"0.51\"}, {\"asset_id\":\"8698449539441374295770236407991735029336433231649246775082939325523552031992\", \"price\":\"0.51\", \"size\":\"170\", \"side\":\"SELL\", \"hash\":\"edaf4c57394d67156f9e3a475fd9934cb316f25b\", \"best_bid\":\"0.49\", \"best_ask\":\"0.51\"}], \"timestamp\":\"1785121613523\", \"event_type\":\"price_change\"}","received_at":"2026-07-27T03:06:53.595452Z","schema_version":"clob-market-ws.price_change.v1","sequence":null,"server_hash":null,"server_timestamp":"1785121613523","session_id":"ff6d21c8283948938400a32613abec2c","source":"clob_market_ws"},"received_at":"2026-07-27T03:06:53.595452Z","record_id":"a76375e8c38e632ff66d49a3eb6bf0df30c6824d23853495e4c26b85d8cd35a6","schema_fingerprint":"4aa3821a28b0b7c2400bc59aba4bcc0a76e971dadd19610d3ad38c768e124dc7","schema_version":"edge-lab-recorder.raw.v1","sequence":null,"source":"clob_market_ws"}
{"event_at":"2026-07-27T03:06:53.524000Z","event_fingerprint":"6352fd32d1c4f7f3752d94f1080a78566bed83369b32a034a2d20597408cc277","payload":{"connection_id":"f95883f18d264834af91809e5f803e9f","event_at":"2026-07-27T03:06:53.524000Z","event_type":"price_change","frame_hash":"33d8f4ff7a46648c139257dcf7ba401762d83a383db2b5ffc79903ab44790f8a","frame_index":0,"kind":"data","monotonic_ns":223596923647458,"payload":{"event_type":"price_change","market":"0xf9d60bb033695053c4d1d8592e52171c1042f64b41a4b72e09dcc6f4852b6670","price_changes":[{"asset_id":"96283536366176669581486355171583722558858323126916278856549586825357358273536","best_ask":"0.51","best_bid":"0.49","hash":"dca11027e55f1403f5c32162a7368adce7b0c050","price":"0.49","side":"BUY","size":"175"},{"asset_id":"8698449539441374295770236407991735029336433231649246775082939325523552031992","best_ask":"0.51","best_bid":"0.49","hash":"01480d2dd05360e2e834ee17313dc486fbdbe15d","price":"0.51","side":"SELL","size":"175"}],"timestamp":"1785121613524"},"payload_hash":"4c509b1b5ea6cc5a4720b61c392f5dda84b0f20ca13bc203145e9663764b8113","raw_frame":"{\"market\":\"0xf9d60bb033695053c4d1d8592e52171c1042f64b41a4b72e09dcc6f4852b6670\", \"price_changes\":[{\"asset_id\":\"96283536366176669581486355171583722558858323126916278856549586825357358273536\", \"price\":\"0.49\", \"size\":\"175\", \"side\":\"BUY\", \"hash\":\"dca11027e55f1403f5c32162a7368adce7b0c050\", \"best_bid\":\"0.49\", \"best_ask\":\"0.51\"}, {\"asset_id\":\"8698449539441374295770236407991735029336433231649246775082939325523552031992\", \"price\":\"0.51\", \"size\":\"175\", \"side\":\"SELL\", \"hash\":\"01480d2dd05360e2e834ee17313dc486fbdbe15d\", \"best_bid\":\"0.49\", \"best_ask\":\"0.51\"}], \"timestamp\":\"1785121613524\", \"event_type\":\"price_change\"}","received_at":"2026-07-27T03:06:53.596802Z","schema_version":"clob-market-ws.price_change.v1","sequence":null,"server_hash":null,"server_timestamp":"1785121613524","session_id":"ff6d21c8283948938400a32613abec2c","source":"clob_market_ws"},"received_at":"2026-07-27T03:06:53.596802Z","record_id":"caefecb0e7846477c4b5de1d2f8d35173ad2eede646ab047a58e3c365dc5f930","schema_fingerprint":"4aa3821a28b0b7c2400bc59aba4bcc0a76e971dadd19610d3ad38c768e124dc7","schema_version":"edge-lab-recorder.raw.v1","sequence":null,"source":"clob_market_ws"}
{"event_at":"2026-07-27T03:06:53.525000Z","event_fingerprint":"1154446e0adeb380b50eee8179d895ccdfb4807140901377d953a56fd6eb3236","payload":{"connection_id":"f95883f18d264834af91809e5f803e9f","event_at":"2026-07-27T03:06:53.525000Z","event_type":"price_change","frame_hash":"225f13568ed4b01efe3719de7f741f7a0a3c6e241d5f3e5ba9ccb1e3826fd77d","frame_index":0,"kind":"data","monotonic_ns":223596925087958,"payload":{"event_type":"price_change","market":"0xf9d60bb033695053c4d1d8592e52171c1042f64b41a4b72e09dcc6f4852b6670","price_changes":[{"asset_id":"96283536366176669581486355171583722558858323126916278856549586825357358273536","best_ask":"0.51","best_bid":"0.49","hash":"5e444a2e665d5df7cfc932637d82cf175e59345b","price":"0.49","side":"BUY","size":"180"},{"asset_id":"8698449539441374295770236407991735029336433231649246775082939325523552031992","best_ask":"0.51","best_bid":"0.49","hash":"0ca723c22bc70a96b6d2c4d722b40a363a218391","price":"0.51","side":"SELL","size":"180"}],"timestamp":"1785121613525"},"payload_hash":"244cb4055ff3ce0efed3cbe1f30102dbe837efbd87455d3b3a15c32c68d947ee","raw_frame":"{\"market\":\"0xf9d60bb033695053c4d1d8592e52171c1042f64b41a4b72e09dcc6f4852b6670\", \"price_changes\":[{\"asset_id\":\"96283536366176669581486355171583722558858323126916278856549586825357358273536\", \"price\":\"0.49\", \"size\":\"180\", \"side\":\"BUY\", \"hash\":\"5e444a2e665d5df7cfc932637d82cf175e59345b\", \"best_bid\":\"0.49\", \"best_ask\":\"0.51\"}, {\"asset_id\":\"8698449539441374295770236407991735029336433231649246775082939325523552031992\", \"price\":\"0.51\", \"size\":\"180\", \"side\":\"SELL\", \"hash\":\"0ca723c22bc70a96b6d2c4d722b40a363a218391\", \"best_bid\":\"0.49\", \"best_ask\":\"0.51\"}], \"timestamp\":\"1785121613525\", \"event_type\":\"price_change\"}","received_at":"2026-07-27T03:06:53.598242Z","schema_version":"clob-market-ws.price_change.v1","sequence":null,"server_hash":null,"server_timestamp":"1785121613525","session_id":"ff6d21c8283948938400a32613abec2c","source":"clob_market_ws"},"received_at":"2026-07-27T03:06:53.598242Z","record_id":"71a56051670f47fb410c6b3faaef05bf93849d1223f72e55f0b25290ae3ae653","schema_fingerprint":"4aa3821a28b0b7c2400bc59aba4bcc0a76e971dadd19610d3ad38c768e124dc7","schema_version":"edge-lab-recorder.raw.v1","sequence":null,"source":"clob_market_ws"}
{"event_at":"2026-07-27T03:06:53.526000Z","event_fingerprint":"c686fb1418afeff1393734e2e8499bf8e219d327dad0e9ebd492a21f614666f7","payload":{"connection_id":"f95883f18d264834af91809e5f803e9f","event_at":"2026-07-27T03:06:53.526000Z","event_type":"price_change","frame_hash":"a8901341a952e19aafc491bc5c6a30fd3ea3c8c64ea11caaa64139ad3d138753","frame_index":0,"kind":"data","monotonic_ns":223596926559541,"payload":{"event_type":"price_change","market":"0xf9d60bb033695053c4d1d8592e52171c1042f64b41a4b72e09dcc6f4852b6670","price_changes":[{"asset_id":"96283536366176669581486355171583722558858323126916278856549586825357358273536","best_ask":"0.51","best_bid":"0.49","hash":"2c15391222c88a443325cc4a7d5a2eb7037de231","price":"0.49","side":"BUY","size":"185"},{"asset_id":"8698449539441374295770236407991735029336433231649246775082939325523552031992","best_ask":"0.51","best_bid":"0.49","hash":"6c46446a20e6e318936e4808e865cc48734c6f13","price":"0.51","side":"SELL","size":"185"}],"timestamp":"1785121613526"},"payload_hash":"4054b04df5fa9e4565526007e9eca46cab3305ea291cef60eed431ac0fafa86d","raw_frame":"{\"market\":\"0xf9d60bb033695053c4d1d8592e52171c1042f64b41a4b72e09dcc6f4852b6670\", \"price_changes\":[{\"asset_id\":\"96283536366176669581486355171583722558858323126916278856549586825357358273536\", \"price\":\"0.49\", \"size\":\"185\", \"side\":\"BUY\", \"hash\":\"2c15391222c88a443325cc4a7d5a2eb7037de231\", \"best_bid\":\"0.49\", \"best_ask\":\"0.51\"}, {\"asset_id\":\"8698449539441374295770236407991735029336433231649246775082939325523552031992\", \"price\":\"0.51\", \"size\":\"185\", \"side\":\"SELL\", \"hash\":\"6c46446a20e6e318936e4808e865cc48734c6f13\", \"best_bid\":\"0.49\", \"best_ask\":\"0.51\"}], \"timestamp\":\"1785121613526\", \"event_type\":\"price_change\"}","received_at":"2026-07-27T03:06:53.599713Z","schema_version":"clob-market-ws.price_change.v1","sequence":null,"server_hash":null,"server_timestamp":"1785121613526","session_id":"ff6d21c8283948938400a32613abec2c","source":"clob_market_ws"},"received_at":"2026-07-27T03:06:53.599713Z","record_id":"9de7154aa06e810a692f142948869cca56b78ba7a5c6eced438015eb4b84cead","schema_fingerprint":"4aa3821a28b0b7c2400bc59aba4bcc0a76e971dadd19610d3ad38c768e124dc7","schema_version":"edge-lab-recorder.raw.v1","sequence":null,"source":"clob_market_ws"}
{"event_at":"2026-07-27T03:06:53.527000Z","event_fingerprint":"662b3934191e7dfe527d64e43e75e5ba4d19c235ed25586b75e47f573a186971","payload":{"connection_id":"f95883f18d264834af91809e5f803e9f","event_at":"2026-07-27T03:06:53.527000Z","event_type":"price_change","frame_hash":"7a957378eafd474dab7370733fad1ad53343f55e0da7b1eddcf51a315efe2140","frame_index":0,"kind":"data","monotonic_ns":223596928017833,"payload":{"event_type":"price_change","market":"0xf9d60bb033695053c4d1d8592e52171c1042f64b41a4b72e09dcc6f4852b6670","price_changes":[{"asset_id":"96283536366176669581486355171583722558858323126916278856549586825357358273536","best_ask":"0.51","best_bid":"0.49","hash":"a26421047e4c2d09c0d45eacfb3ac8ae6ea398f0","price":"0.49","side":"BUY","size":"190"},{"asset_id":"8698449539441374295770236407991735029336433231649246775082939325523552031992","best_ask":"0.51","best_bid":"0.49","hash":"cf01dc99560736a7b6e54115b7ef44c8d1ff4987","price":"0.51","side":"SELL","size":"190"}],"timestamp":"1785121613527"},"payload_hash":"840d19aef387031ef299566b22101800b9ae6cc588aa4ea98f674f7c4d265981","raw_frame":"{\"market\":\"0xf9d60bb033695053c4d1d8592e52171c1042f64b41a4b72e09dcc6f4852b6670\", \"price_changes\":[{\"asset_id\":\"96283536366176669581486355171583722558858323126916278856549586825357358273536\", \"price\":\"0.49\", \"size\":\"190\", \"side\":\"BUY\", \"hash\":\"a26421047e4c2d09c0d45eacfb3ac8ae6ea398f0\", \"best_bid\":\"0.49\", \"best_ask\":\"0.51\"}, {\"asset_id\":\"8698449539441374295770236407991735029336433231649246775082939325523552031992\", \"price\":\"0.51\", \"size\":\"190\", \"side\":\"SELL\", \"hash\":\"cf01dc99560736a7b6e54115b7ef44c8d1ff4987\", \"best_bid\":\"0.49\", \"best_ask\":\"0.51\"}], \"timestamp\":\"1785121613527\", \"event_type\":\"price_change\"}","received_at":"2026-07-27T03:06:53.601176Z","schema_version":"clob-market-ws.price_change.v1","sequence":null,"server_hash":null,"server_timestamp":"1785121613527","session_id":"ff6d21c8283948938400a32613abec2c","source":"clob_market_ws"},"received_at":"2026-07-27T03:06:53.601176Z","record_id":"b82a3e219c0828e697b639f43fd05f30e1264a6ff521bd2297ae27755358b864","schema_fingerprint":"4aa3821a28b0b7c2400bc59aba4bcc0a76e971dadd19610d3ad38c768e124dc7","schema_version":"edge-lab-recorder.raw.v1","sequence":null,"source":"clob_market_ws"}
{"event_at":"2026-07-27T03:06:53.528000Z","event_fingerprint":"a9f251677d77c8ad4609ff8d3e7a7ef62ef5ebded6f01bc1497c56a5917c3c76","payload":{"connection_id":"f95883f18d264834af91809e5f803e9f","event_at":"2026-07-27T03:06:53.528000Z","event_type":"price_change","frame_hash":"682df8a047b2e9f7b3af5e717e7d458772b25c52e3a59cbb1ea094b53d0a3e9b","frame_index":0,"kind":"data","monotonic_ns":223596929053458,"payload":{"event_type":"price_change","market":"0xf9d60bb033695053c4d1d8592e52171c1042f64b41a4b72e09dcc6f4852b6670","price_changes":[{"asset_id":"8698449539441374295770236407991735029336433231649246775082939325523552031992","best_ask":"0.51","best_bid":"0.49","hash":"7c1f4684efbc4afdfb61e9e3510bf4a85aef60da","price":"0.47","side":"BUY","size":"119.45"},{"asset_id":"96283536366176669581486355171583722558858323126916278856549586825357358273536","best_ask":"0.51","best_bid":"0.49","hash":"c05e73d8749156a49040d38e25b021dd71a4a684","price":"0.53","side":"SELL","size":"119.45"}],"timestamp":"1785121613528"},"payload_hash":"8d0b51d3967069a5c59ffdd422fcd7a1c944ac6246a6aeb4d9a9d767c3bf9819","raw_frame":"{\"market\":\"0xf9d60bb033695053c4d1d8592e52171c1042f64b41a4b72e09dcc6f4852b6670\", \"price_changes\":[{\"asset_id\":\"8698449539441374295770236407991735029336433231649246775082939325523552031992\", \"price\":\"0.47\", \"size\":\"119.45\", \"side\":\"BUY\", \"hash\":\"7c1f4684efbc4afdfb61e9e3510bf4a85aef60da\", \"best_bid\":\"0.49\", \"best_ask\":\"0.51\"}, {\"asset_id\":\"96283536366176669581486355171583722558858323126916278856549586825357358273536\", \"price\":\"0.53\", \"size\":\"119.45\", \"side\":\"SELL\", \"hash\":\"c05e73d8749156a49040d38e25b021dd71a4a684\", \"best_bid\":\"0.49\", \"best_ask\":\"0.51\"}], \"timestamp\":\"1785121613528\", \"event_type\":\"price_change\"}","received_at":"2026-07-27T03:06:53.602207Z","schema_version":"clob-market-ws.price_change.v1","sequence":null,"server_hash":null,"server_timestamp":"1785121613528","session_id":"ff6d21c8283948938400a32613abec2c","source":"clob_market_ws"},"received_at":"2026-07-27T03:06:53.602207Z","record_id":"a761a7a9c9240e8a2e33d694571e4ea786773f8fcb823adf0605fbb28a833db4","schema_fingerprint":"4aa3821a28b0b7c2400bc59aba4bcc0a76e971dadd19610d3ad38c768e124dc7","schema_version":"edge-lab-recorder.raw.v1","sequence":null,"source":"clob_market_ws"}
{"event_at":"2026-07-27T03:06:53.528000Z","event_fingerprint":"406e3bc285aadfdd66d3fb42f71d392022daa23fe26e350d79433e6c219f71cf","payload":{"connection_id":"f95883f18d264834af91809e5f803e9f","event_at":"2026-07-27T03:06:53.528000Z","event_type":"price_change","frame_hash":"2feec15d44512dc151f6ccdd33b7e2d846d93aed841f029f85661c0349491b9b","frame_index":0,"kind":"data","monotonic_ns":223596930483583,"payload":{"event_type":"price_change","market":"0xf9d60bb033695053c4d1d8592e52171c1042f64b41a4b72e09dcc6f4852b6670","price_changes":[{"asset_id":"96283536366176669581486355171583722558858323126916278856549586825357358273536","best_ask":"0.51","best_bid":"0.49","hash":"5b4d2a2a67215f7140db75cb32844e225d2c4267","price":"0.49","side":"BUY","size":"195"},{"asset_id":"8698449539441374295770236407991735029336433231649246775082939325523552031992","best_ask":"0.51","best_bid":"0.49","hash":"dbd42b94f1e60faf666e6da275ed087aa45d1dc1","price":"0.51","side":"SELL","size":"195"}],"timestamp":"1785121613528"},"payload_hash":"d9c85ccfbaf247c91f7618c8f7cff52c8b544abf5d0b0e914c750398c9e3007b","raw_frame":"{\"market\":\"0xf9d60bb033695053c4d1d8592e52171c1042f64b41a4b72e09dcc6f4852b6670\", \"price_changes\":[{\"asset_id\":\"96283536366176669581486355171583722558858323126916278856549586825357358273536\", \"price\":\"0.49\", \"size\":\"195\", \"side\":\"BUY\", \"hash\":\"5b4d2a2a67215f7140db75cb32844e225d2c4267\", \"best_bid\":\"0.49\", \"best_ask\":\"0.51\"}, {\"asset_id\":\"8698449539441374295770236407991735029336433231649246775082939325523552031992\", \"price\":\"0.51\", \"size\":\"195\", \"side\":\"SELL\", \"hash\":\"dbd42b94f1e60faf666e6da275ed087aa45d1dc1\", \"best_bid\":\"0.49\", \"best_ask\":\"0.51\"}], \"timestamp\":\"1785121613528\", \"event_type\":\"price_change\"}","received_at":"2026-07-27T03:06:53.603641Z","schema_version":"clob-market-ws.price_change.v1","sequence":null,"server_hash":null,"server_timestamp":"1785121613528","session_id":"ff6d21c8283948938400a32613abec2c","source":"clob_market_ws"},"received_at":"2026-07-27T03:06:53.603641Z","record_id":"b315aef58fdbde7aa8342f57821669b486a16f2cd25e1a807fbba7d9e3789503","schema_fingerprint":"4aa3821a28b0b7c2400bc59aba4bcc0a76e971dadd19610d3ad38c768e124dc7","schema_version":"edge-lab-recorder.raw.v1","sequence":null,"source":"clob_market_ws"}
{"event_at":"2026-07-27T03:06:53.529000Z","event_fingerprint":"ea969bce07341dd966113868152edfab6a40121be75dc1d347696bc8ec6517e0","payload":{"connection_id":"f95883f18d264834af91809e5f803e9f","event_at":"2026-07-27T03:06:53.529000Z","event_type":"price_change","frame_hash":"fd18f0b908149877faae83f393fb8c4a73e733389549d7d50743cb263a68e9c3","frame_index":0,"kind":"data","monotonic_ns":223596931053500,"payload":{"event_type":"price_change","market":"0xf9d60bb033695053c4d1d8592e52171c1042f64b41a4b72e09dcc6f4852b6670","price_changes":[{"asset_id":"8698449539441374295770236407991735029336433231649246775082939325523552031992","best_ask":"0.51","best_bid":"0.49","hash":"64e54cf70e3ff5d594c139dbf40ccfef2b1d8298","price":"0.47","side":"BUY","size":"124.45"},{"asset_id":"96283536366176669581486355171583722558858323126916278856549586825357358273536","best_ask":"0.51","best_bid":"0.49","hash":"2051b0306bd08573f47b79e5c97ac05ea622d300","price":"0.53","side":"SELL","size":"124.45"}],"timestamp":"1785121613529"},"payload_hash":"6d540988579577183c0b0a4294b2031bd1e27991489a29c69b590a163411112c","raw_frame":"{\"market\":\"0xf9d60bb033695053c4d1d8592e52171c1042f64b41a4b72e09dcc6f4852b6670\", \"price_changes\":[{\"asset_id\":\"8698449539441374295770236407991735029336433231649246775082939325523552031992\", \"price\":\"0.47\", \"size\":\"124.45\", \"side\":\"BUY\", \"hash\":\"64e54cf70e3ff5d594c139dbf40ccfef2b1d8298\", \"best_bid\":\"0.49\", \"best_ask\":\"0.51\"}, {\"asset_id\":\"96283536366176669581486355171583722558858323126916278856549586825357358273536\", \"price\":\"0.53\", \"size\":\"124.45\", \"side\":\"SELL\", \"hash\":\"2051b0306bd08573f47b79e5c97ac05ea622d300\", \"best_bid\":\"0.49\", \"best_ask\":\"0.51\"}], \"timestamp\":\"1785121613529\", \"event_type\":\"price_change\"}","received_at":"2026-07-27T03:06:53.604214Z","schema_version":"clob-market-ws.price_change.v1","sequence":null,"server_hash":null,"server_timestamp":"1785121613529","session_id":"ff6d21c8283948938400a32613abec2c","source":"clob_market_ws"},"received_at":"2026-07-27T03:06:53.604214Z","record_id":"893e4256336e440b8220b7fd4d8ad8075669a559422c8e20bac90a6d9f61554e","schema_fingerprint":"4aa3821a28b0b7c2400bc59aba4bcc0a76e971dadd19610d3ad38c768e124dc7","schema_version":"edge-lab-recorder.raw.v1","sequence":null,"source":"clob_market_ws"}
{"event_at":"2026-07-27T03:06:53.530000Z","event_fingerprint":"3895b7605ec41f8504846e2593728615e24ed0e1ae7bd86783b914a25cfab5c6","payload":{"connection_id":"f95883f18d264834af91809e5f803e9f","event_at":"2026-07-27T03:06:53.530000Z","event_type":"price_change","frame_hash":"163e4cd85324db8bf5f26689f65c3983be7f024dbaa96cb4d6f64771a861d353","frame_index":0,"kind":"data","monotonic_ns":223596931710625,"payload":{"event_type":"price_change","market":"0xf9d60bb033695053c4d1d8592e52171c1042f64b41a4b72e09dcc6f4852b6670","price_changes":[{"asset_id":"96283536366176669581486355171583722558858323126916278856549586825357358273536","best_ask":"0.51","best_bid":"0.49","hash":"8a5a122fd77f4c304a7fdaa1aa540d8658222efd","price":"0.49","side":"BUY","size":"200"},{"asset_id":"8698449539441374295770236407991735029336433231649246775082939325523552031992","best_ask":"0.51","best_bid":"0.49","hash":"9fb076b1815c9fe7490fb92904482918ecbef868","price":"0.51","side":"SELL","size":"200"}],"timestamp":"1785121613530"},"payload_hash":"e72c83e74c058a59145307f114c566cd9e0070218a7f23499bd760e458b1170f","raw_frame":"{\"market\":\"0xf9d60bb033695053c4d1d8592e52171c1042f64b41a4b72e09dcc6f4852b6670\", \"price_changes\":[{\"asset_id\":\"96283536366176669581486355171583722558858323126916278856549586825357358273536\", \"price\":\"0.49\", \"size\":\"200\", \"side\":\"BUY\", \"hash\":\"8a5a122fd77f4c304a7fdaa1aa540d8658222efd\", \"best_bid\":\"0.49\", \"best_ask\":\"0.51\"}, {\"asset_id\":\"8698449539441374295770236407991735029336433231649246775082939325523552031992\", \"price\":\"0.51\", \"size\":\"200\", \"side\":\"SELL\", \"hash\":\"9fb076b1815c9fe7490fb92904482918ecbef868\", \"best_bid\":\"0.49\", \"best_ask\":\"0.51\"}], \"timestamp\":\"1785121613530\", \"event_type\":\"price_change\"}","received_at":"2026-07-27T03:06:53.604857Z","schema_version":"clob-market-ws.price_change.v1","sequence":null,"server_hash":null,"server_timestamp":"1785121613530","session_id":"ff6d21c8283948938400a32613abec2c","source":"clob_market_ws"},"received_at":"2026-07-27T03:06:53.604857Z","record_id":"80ebfc018098e32cfca2383bdf22324801da5ed261e1863d568a4fd21ae50fc9","schema_fingerprint":"4aa3821a28b0b7c2400bc59aba4bcc0a76e971dadd19610d3ad38c768e124dc7","schema_version":"edge-lab-recorder.raw.v1","sequence":null,"source":"clob_market_ws"}
{"event_at":"2026-07-27T03:06:53.530000Z","event_fingerprint":"95cb4f16a5d1d550dae852973065513d265a929d571abe104777d9409a535be1","payload":{"connection_id":"f95883f18d264834af91809e5f803e9f","event_at":"2026-07-27T03:06:53.530000Z","event_type":"price_change","frame_hash":"3e1ec007e277edceec118991c90b873c13ce91c7705438053e90ea85de3499a1","frame_index":0,"kind":"data","monotonic_ns":223596932626541,"payload":{"event_type":"price_change","market":"0xf9d60bb033695053c4d1d8592e52171c1042f64b41a4b72e09dcc6f4852b6670","price_changes":[{"asset_id":"8698449539441374295770236407991735029336433231649246775082939325523552031992","best_ask":"0.51","best_bid":"0.49","hash":"987bb7ee7cb20ea9333de7120d12520926f89e05","price":"0.47","side":"BUY","size":"129.45"},{"asset_id":"96283536366176669581486355171583722558858323126916278856549586825357358273536","best_ask":"0.51","best_bid":"0.49","hash":"04ff410697e2114b6be86348da629be3edd77a4e","price":"0.53","side":"SELL","size":"129.45"}],"timestamp":"1785121613530"},"payload_hash":"e3ec33b34ea534cc875a628ac49c3c61c8b2acf94413f3ad523202ac65b67310","raw_frame":"{\"market\":\"0xf9d60bb033695053c4d1d8592e52171c1042f64b41a4b72e09dcc6f4852b6670\", \"price_changes\":[{\"asset_id\":\"8698449539441374295770236407991735029336433231649246775082939325523552031992\", \"price\":\"0.47\", \"size\":\"129.45\", \"side\":\"BUY\", \"hash\":\"987bb7ee7cb20ea9333de7120d12520926f89e05\", \"best_bid\":\"0.49\", \"best_ask\":\"0.51\"}, {\"asset_id\":\"96283536366176669581486355171583722558858323126916278856549586825357358273536\", \"price\":\"0.53\", \"size\":\"129.45\", \"side\":\"SELL\", \"hash\":\"04ff410697e2114b6be86348da629be3edd77a4e\", \"best_bid\":\"0.49\", \"best_ask\":\"0.51\"}], \"timestamp\":\"1785121613530\", \"event_type\":\"price_change\"}","received_at":"2026-07-27T03:06:53.605784Z","schema_version":"clob-market-ws.price_change.v1","sequence":null,"server_hash":null,"server_timestamp":"1785121613530","session_id":"ff6d21c8283948938400a32613abec2c","source":"clob_market_ws"},"received_at":"2026-07-27T03:06:53.605784Z","record_id":"35efe53f6fb1764476610929fb2e37ec918b1a01338a795ab221eac2dce666ee","schema_fingerprint":"4aa3821a28b0b7c2400bc59aba4bcc0a76e971dadd19610d3ad38c768e124dc7","schema_version":"edge-lab-recorder.raw.v1","sequence":null,"source":"clob_market_ws"}
{"event_at":"2026-07-27T03:06:53.531000Z","event_fingerprint":"ab89cfca46c03deaebe681baddc61884e16076dfacba440cabdc2a047d78c22a","payload":{"connection_id":"f95883f18d264834af91809e5f803e9f","event_at":"2026-07-27T03:06:53.531000Z","event_type":"price_change","frame_hash":"9381bb9631957d738be51e8043937d059bf880875486a0a9c1c1daac53593cc5","frame_index":0,"kind":"data","monotonic_ns":223596933850375,"payload":{"event_type":"price_change","market":"0xf9d60bb033695053c4d1d8592e52171c1042f64b41a4b72e09dcc6f4852b6670","price_changes":[{"asset_id":"96283536366176669581486355171583722558858323126916278856549586825357358273536","best_ask":"0.51","best_bid":"0.49","hash":"ae99f0bd3a130e157d9bd8c1c9de5e633facba38","price":"0.49","side":"BUY","size":"205"},{"asset_id":"8698449539441374295770236407991735029336433231649246775082939325523552031992","best_ask":"0.51","best_bid":"0.49","hash":"38e0e4a150680e5382726ab8e3ea3f708a42b187","price":"0.51","side":"SELL","size":"205"}],"timestamp":"1785121613531"},"payload_hash":"3749303bb928e008898d1f1b81fa16885096c8958660d568de52d472542faee0","raw_frame":"{\"market\":\"0xf9d60bb033695053c4d1d8592e52171c1042f64b41a4b72e09dcc6f4852b6670\", \"price_changes\":[{\"asset_id\":\"96283536366176669581486355171583722558858323126916278856549586825357358273536\", \"price\":\"0.49\", \"size\":\"205\", \"side\":\"BUY\", \"hash\":\"ae99f0bd3a130e157d9bd8c1c9de5e633facba38\", \"best_bid\":\"0.49\", \"best_ask\":\"0.51\"}, {\"asset_id\":\"8698449539441374295770236407991735029336433231649246775082939325523552031992\", \"price\":\"0.51\", \"size\":\"205\", \"side\":\"SELL\", \"hash\":\"38e0e4a150680e5382726ab8e3ea3f708a42b187\", \"best_bid\":\"0.49\", \"best_ask\":\"0.51\"}], \"timestamp\":\"1785121613531\", \"event_type\":\"price_change\"}","received_at":"2026-07-27T03:06:53.606997Z","schema_version":"clob-market-ws.price_change.v1","sequence":null,"server_hash":null,"server_timestamp":"1785121613531","session_id":"ff6d21c8283948938400a32613abec2c","source":"clob_market_ws"},"received_at":"2026-07-27T03:06:53.606997Z","record_id":"abb671bfd5372b8927d320a0b51aa418a1a350afa3e83fe28c1d04649f302051","schema_fingerprint":"4aa3821a28b0b7c2400bc59aba4bcc0a76e971dadd19610d3ad38c768e124dc7","schema_version":"edge-lab-recorder.raw.v1","sequence":null,"source":"clob_market_ws"}
{"event_at":"2026-07-27T03:06:53.532000Z","event_fingerprint":"33d71831e750550fa7b8fbef412d18ed3d3d5a554d98ce206b35b515d7718674","payload":{"connection_id":"f95883f18d264834af91809e5f803e9f","event_at":"2026-07-27T03:06:53.532000Z","event_type":"price_change","frame_hash":"6356750d2a9493aeeba8d8a6dc6d48703299c22ca6c496d2e83e302e9b7cbb35","frame_index":0,"kind":"data","monotonic_ns":223596935074166,"payload":{"event_type":"price_change","market":"0xf9d60bb033695053c4d1d8592e52171c1042f64b41a4b72e09dcc6f4852b6670","price_changes":[{"asset_id":"8698449539441374295770236407991735029336433231649246775082939325523552031992","best_ask":"0.51","best_bid":"0.49","hash":"60c38a03eeb53d316ffd53d80aef0a89ef9fb86d","price":"0.47","side":"BUY","size":"134.45"},{"asset_id":"96283536366176669581486355171583722558858323126916278856549586825357358273536","best_ask":"0.51","best_bid":"0.49","hash":"84e8c56cf182ebbaa5dc16fd5fe86071cde6bd5a","price":"0.53","side":"SELL","size":"134.45"}],"timestamp":"1785121613532"},"payload_hash":"38fcda896e8373c23f6c9be3d7adbdbd2f1be6550a9eed9b89198b707951d0b1","raw_frame":"{\"market\":\"0xf9d60bb033695053c4d1d8592e52171c1042f64b41a4b72e09dcc6f4852b6670\", \"price_changes\":[{\"asset_id\":\"8698449539441374295770236407991735029336433231649246775082939325523552031992\", \"price\":\"0.47\", \"size\":\"134.45\", \"side\":\"BUY\", \"hash\":\"60c38a03eeb53d316ffd53d80aef0a89ef9fb86d\", \"best_bid\":\"0.49\", \"best_ask\":\"0.51\"}, {\"asset_id\":\"96283536366176669581486355171583722558858323126916278856549586825357358273536\", \"price\":\"0.53\", \"size\":\"134.45\", \"side\":\"SELL\", \"hash\":\"84e8c56cf182ebbaa5dc16fd5fe86071cde6bd5a\", \"best_bid\":\"0.49\", \"best_ask\":\"0.51\"}], \"timestamp\":\"1785121613532\", \"event_type\":\"price_change\"}","received_at":"2026-07-27T03:06:53.608232Z","schema_version":"clob-market-ws.price_change.v1","sequence":null,"server_hash":null,"server_timestamp":"1785121613532","session_id":"ff6d21c8283948938400a32613abec2c","source":"clob_market_ws"},"received_at":"2026-07-27T03:06:53.608232Z","record_id":"5531e1b06bf52341bba46a52f026a955145fda77337f51f929922c371cc57a64","schema_fingerprint":"4aa3821a28b0b7c2400bc59aba4bcc0a76e971dadd19610d3ad38c768e124dc7","schema_version":"edge-lab-recorder.raw.v1","sequence":null,"source":"clob_market_ws"}
{"event_at":"2026-07-27T03:06:53.533000Z","event_fingerprint":"261a179901e6449af7e8bb91ff364a358b29351b732673c4b1efab145df5cc7a","payload":{"connection_id":"f95883f18d264834af91809e5f803e9f","event_at":"2026-07-27T03:06:53.533000Z","event_type":"price_change","frame_hash":"cde0211d31770a05504ad0680a3c40ea53b76e6ef870e68cfdad4eaa8742b020","frame_index":0,"kind":"data","monotonic_ns":223596936245083,"payload":{"event_type":"price_change","market":"0xf9d60bb033695053c4d1d8592e52171c1042f64b41a4b72e09dcc6f4852b6670","price_changes":[{"asset_id":"96283536366176669581486355171583722558858323126916278856549586825357358273536","best_ask":"0.51","best_bid":"0.49","hash":"92f41203741a197d2fbe8e8d40d90f03042bd3d5","price":"0.49","side":"BUY","size":"210"},{"asset_id":"8698449539441374295770236407991735029336433231649246775082939325523552031992","best_ask":"0.51","best_bid":"0.49","hash":"7251977c7d37a2762c3df7647633622313e1b62f","price":"0.51","side":"SELL","size":"210"}],"timestamp":"1785121613533"},"payload_hash":"d219e04d78aaaa3d39ad7f4beb7733a61e8a8b14c9cd140dd604a45a4ee1a56f","raw_frame":"{\"market\":\"0xf9d60bb033695053c4d1d8592e52171c1042f64b41a4b72e09dcc6f4852b6670\", \"price_changes\":[{\"asset_id\":\"96283536366176669581486355171583722558858323126916278856549586825357358273536\", \"price\":\"0.49\", \"size\":\"210\", \"side\":\"BUY\", \"hash\":\"92f41203741a197d2fbe8e8d40d90f03042bd3d5\", \"best_bid\":\"0.49\", \"best_ask\":\"0.51\"}, {\"asset_id\":\"8698449539441374295770236407991735029336433231649246775082939325523552031992\", \"price\":\"0.51\", \"size\":\"210\", \"side\":\"SELL\", \"hash\":\"7251977c7d37a2762c3df7647633622313e1b62f\", \"best_bid\":\"0.49\", \"best_ask\":\"0.51\"}], \"timestamp\":\"1785121613533\", \"event_type\":\"price_change\"}","received_at":"2026-07-27T03:06:53.609400Z","schema_version":"clob-market-ws.price_change.v1","sequence":null,"server_hash":null,"server_timestamp":"1785121613533","session_id":"ff6d21c8283948938400a32613abec2c","source":"clob_market_ws"},"received_at":"2026-07-27T03:06:53.609400Z","record_id":"dfa03b227eff4cc6bb76f7cfb1a4fa3922cc4526cc6afb2d8489a1f245a07009","schema_fingerprint":"4aa3821a28b0b7c2400bc59aba4bcc0a76e971dadd19610d3ad38c768e124dc7","schema_version":"edge-lab-recorder.raw.v1","sequence":null,"source":"clob_market_ws"}
{"event_at":"2026-07-27T03:06:53.534000Z","event_fingerprint":"6edf51f2f64fc482121698bbb71d17da5038588582b0b7ef676daefe33ddffbf","payload":{"connection_id":"f95883f18d264834af91809e5f803e9f","event_at":"2026-07-27T03:06:53.534000Z","event_type":"price_change","frame_hash":"ad5944bbba70de8217d8447821e74ed0f7cfb12acef6f318ec3a80cb48de613e","frame_index":0,"kind":"data","monotonic_ns":223596937654541,"payload":{"event_type":"price_change","market":"0xf9d60bb033695053c4d1d8592e52171c1042f64b41a4b72e09dcc6f4852b6670","price_changes":[{"asset_id":"8698449539441374295770236407991735029336433231649246775082939325523552031992","best_ask":"0.51","best_bid":"0.49","hash":"8554cd312527043b1c5b12c05bae043f4dda18ea","price":"0.47","side":"BUY","size":"139.45"},{"asset_id":"96283536366176669581486355171583722558858323126916278856549586825357358273536","best_ask":"0.51","best_bid":"0.49","hash":"8bdfaeaecaa7493540a66678c87da853c49f4b8f","price":"0.53","side":"SELL","size":"139.45"}],"timestamp":"1785121613534"},"payload_hash":"22609edf45036e4f7ca73351f738a0d4995a5be2b0445c9f0f6bcf4af2f9429e","raw_frame":"{\"market\":\"0xf9d60bb033695053c4d1d8592e52171c1042f64b41a4b72e09dcc6f4852b6670\", \"price_changes\":[{\"asset_id\":\"8698449539441374295770236407991735029336433231649246775082939325523552031992\", \"price\":\"0.47\", \"size\":\"139.45\", \"side\":\"BUY\", \"hash\":\"8554cd312527043b1c5b12c05bae043f4dda18ea\", \"best_bid\":\"0.49\", \"best_ask\":\"0.51\"}, {\"asset_id\":\"96283536366176669581486355171583722558858323126916278856549586825357358273536\", \"price\":\"0.53\", \"size\":\"139.45\", \"side\":\"SELL\", \"hash\":\"8bdfaeaecaa7493540a66678c87da853c49f4b8f\", \"best_bid\":\"0.49\", \"best_ask\":\"0.51\"}], \"timestamp\":\"1785121613534\", \"event_type\":\"price_change\"}","received_at":"2026-07-27T03:06:53.610812Z","schema_version":"clob-market-ws.price_change.v1","sequence":null,"server_hash":null,"server_timestamp":"1785121613534","session_id":"ff6d21c8283948938400a32613abec2c","source":"clob_market_ws"},"received_at":"2026-07-27T03:06:53.610812Z","record_id":"c03c967a1ddce8226a5897e82eef7be7878a0b51e0382881bb4a973be679439d","schema_fingerprint":"4aa3821a28b0b7c2400bc59aba4bcc0a76e971dadd19610d3ad38c768e124dc7","schema_version":"edge-lab-recorder.raw.v1","sequence":null,"source":"clob_market_ws"}
{"event_at":"2026-07-27T03:06:53.535000Z","event_fingerprint":"b65919ad03aec4a93752086864d540ec4e0a1d153c61eccd4e4bb1b5f9e50d49","payload":{"connection_id":"f95883f18d264834af91809e5f803e9f","event_at":"2026-07-27T03:06:53.535000Z","event_type":"price_change","frame_hash":"ff6317d2516540ec7948dba09e036700972331383fd69aee57e2c41f9ffba56c","frame_index":0,"kind":"data","monotonic_ns":223597045813000,"payload":{"event_type":"price_change","market":"0xf9d60bb033695053c4d1d8592e52171c1042f64b41a4b72e09dcc6f4852b6670","price_changes":[{"asset_id":"96283536366176669581486355171583722558858323126916278856549586825357358273536","best_ask":"0.51","best_bid":"0.49","hash":"548942e0188aec2f7c2269df9be0b4b9e7ec4914","price":"0.49","side":"BUY","size":"215"},{"asset_id":"8698449539441374295770236407991735029336433231649246775082939325523552031992","best_ask":"0.51","best_bid":"0.49","hash":"977cc58f09fbe12e8c8a6246be3c35999257b9da","price":"0.51","side":"SELL","size":"215"}],"timestamp":"1785121613535"},"payload_hash":"4d63736b911228bcbbf3281ad68fa7daa797e39350b9b5d1389d3c77d081780e","raw_frame":"{\"market\":\"0xf9d60bb033695053c4d1d8592e52171c1042f64b41a4b72e09dcc6f4852b6670\", \"price_changes\":[{\"asset_id\":\"96283536366176669581486355171583722558858323126916278856549586825357358273536\", \"price\":\"0.49\", \"size\":\"215\", \"side\":\"BUY\", \"hash\":\"548942e0188aec2f7c2269df9be0b4b9e7ec4914\", \"best_bid\":\"0.49\", \"best_ask\":\"0.51\"}, {\"asset_id\":\"8698449539441374295770236407991735029336433231649246775082939325523552031992\", \"price\":\"0.51\", \"size\":\"215\", \"side\":\"SELL\", \"hash\":\"977cc58f09fbe12e8c8a6246be3c35999257b9da\", \"best_bid\":\"0.49\", \"best_ask\":\"0.51\"}], \"timestamp\":\"1785121613535\", \"event_type\":\"price_change\"}","received_at":"2026-07-27T03:06:53.718964Z","schema_version":"clob-market-ws.price_change.v1","sequence":null,"server_hash":null,"server_timestamp":"1785121613535","session_id":"ff6d21c8283948938400a32613abec2c","source":"clob_market_ws"},"received_at":"2026-07-27T03:06:53.718964Z","record_id":"98f3960aaab9f4d5d343adf1c947f1b8ffad89703adc426d4a42a627a027806e","schema_fingerprint":"4aa3821a28b0b7c2400bc59aba4bcc0a76e971dadd19610d3ad38c768e124dc7","schema_version":"edge-lab-recorder.raw.v1","sequence":null,"source":"clob_market_ws"}
{"event_at":"2026-07-27T03:06:53.536000Z","event_fingerprint":"baa82f1a1f39dec8ad7378eff02fb0cd611d26c1145b74fb41ae15dcd9ffb210","payload":{"connection_id":"f95883f18d264834af91809e5f803e9f","event_at":"2026-07-27T03:06:53.536000Z","event_type":"price_change","frame_hash":"9613cc5ce398addedf64874f9b88446f01eba5c68c3bcc287ff94f945275f581","frame_index":0,"kind":"data","monotonic_ns":223597047342291,"payload":{"event_type":"price_change","market":"0xf9d60bb033695053c4d1d8592e52171c1042f64b41a4b72e09dcc6f4852b6670","price_changes":[{"asset_id":"8698449539441374295770236407991735029336433231649246775082939325523552031992","best_ask":"0.51","best_bid":"0.49","hash":"162c12a7e0fbacb7970372b1d39d6c26a5865e86","price":"0.47","side":"BUY","size":"144.45"},{"asset_id":"96283536366176669581486355171583722558858323126916278856549586825357358273536","best_ask":"0.51","best_bid":"0.49","hash":"7c274ac06751c65e21efdbcd8a8a2648bac74b2b","price":"0.53","side":"SELL","size":"144.45"}],"timestamp":"1785121613536"},"payload_hash":"09d5e42cd3eee4482b04c3597411f17f4ed4ab5850ad966b0ecd1eb2a1919e70","raw_frame":"{\"market\":\"0xf9d60bb033695053c4d1d8592e52171c1042f64b41a4b72e09dcc6f4852b6670\", \"price_changes\":[{\"asset_id\":\"8698449539441374295770236407991735029336433231649246775082939325523552031992\", \"price\":\"0.47\", \"size\":\"144.45\", \"side\":\"BUY\", \"hash\":\"162c12a7e0fbacb7970372b1d39d6c26a5865e86\", \"best_bid\":\"0.49\", \"best_ask\":\"0.51\"}, {\"asset_id\":\"96283536366176669581486355171583722558858323126916278856549586825357358273536\", \"price\":\"0.53\", \"size\":\"144.45\", \"side\":\"SELL\", \"hash\":\"7c274ac06751c65e21efdbcd8a8a2648bac74b2b\", \"best_bid\":\"0.49\", \"best_ask\":\"0.51\"}], \"timestamp\":\"1785121613536\", \"event_type\":\"price_change\"}","received_at":"2026-07-27T03:06:53.720493Z","schema_version":"clob-market-ws.price_change.v1","sequence":null,"server_hash":null,"server_timestamp":"1785121613536","session_id":"ff6d21c8283948938400a32613abec2c","source":"clob_market_ws"},"received_at":"2026-07-27T03:06:53.720493Z","record_id":"2a1608db5b4390384e16de713c2306fbfecc6b88a85e5cdce962f1fb8a16ee3e","schema_fingerprint":"4aa3821a28b0b7c2400bc59aba4bcc0a76e971dadd19610d3ad38c768e124dc7","schema_version":"edge-lab-recorder.raw.v1","sequence":null,"source":"clob_market_ws"}
{"event_at":"2026-07-27T03:06:53.537000Z","event_fingerprint":"c2d29b0f24a69cdc58977dbde2e963fa76eab87913dcd456c7ed6627e12506a4","payload":{"connection_id":"f95883f18d264834af91809e5f803e9f","event_at":"2026-07-27T03:06:53.537000Z","event_type":"price_change","frame_hash":"2bf01f8aac0297c9e610c0998e2776ed6cdff37871671e503fa0c9f21404cb07","frame_index":0,"kind":"data","monotonic_ns":223597048854125,"payload":{"event_type":"price_change","market":"0xf9d60bb033695053c4d1d8592e52171c1042f64b41a4b72e09dcc6f4852b6670","price_changes":[{"asset_id":"96283536366176669581486355171583722558858323126916278856549586825357358273536","best_ask":"0.51","best_bid":"0.49","hash":"ec5ad8f8be31b16c39279f93835e9db0468fd5ac","price":"0.49","side":"BUY","size":"220"},{"asset_id":"8698449539441374295770236407991735029336433231649246775082939325523552031992","best_ask":"0.51","best_bid":"0.49","hash":"0bb3f529ed78f179cc7744423ea73c9f3a2a93fd","price":"0.51","side":"SELL","size":"220"}],"timestamp":"1785121613537"},"payload_hash":"c964ba4b1cd392a45ff10d762648e9869586e09dcf78e045106ff24dc46c3c22","raw_frame":"{\"market\":\"0xf9d60bb033695053c4d1d8592e52171c1042f64b41a4b72e09dcc6f4852b6670\", \"price_changes\":[{\"asset_id\":\"96283536366176669581486355171583722558858323126916278856549586825357358273536\", \"price\":\"0.49\", \"size\":\"220\", \"side\":\"BUY\", \"hash\":\"ec5ad8f8be31b16c39279f93835e9db0468fd5ac\", \"best_bid\":\"0.49\", \"best_ask\":\"0.51\"}, {\"asset_id\":\"8698449539441374295770236407991735029336433231649246775082939325523552031992\", \"price\":\"0.51\", \"size\":\"220\", \"side\":\"SELL\", \"hash\":\"0bb3f529ed78f179cc7744423ea73c9f3a2a93fd\", \"best_bid\":\"0.49\", \"best_ask\":\"0.51\"}], \"timestamp\":\"1785121613537\", \"event_type\":\"price_change\"}","received_at":"2026-07-27T03:06:53.722011Z","schema_version":"clob-market-ws.price_change.v1","sequence":null,"server_hash":null,"server_timestamp":"1785121613537","session_id":"ff6d21c8283948938400a32613abec2c","source":"clob_market_ws"},"received_at":"2026-07-27T03:06:53.722011Z","record_id":"2eb2632bc48c56a1d18db6827e7c4ec02109b0bce688cec195db536980d52a06","schema_fingerprint":"4aa3821a28b0b7c2400bc59aba4bcc0a76e971dadd19610d3ad38c768e124dc7","schema_version":"edge-lab-recorder.raw.v1","sequence":null,"source":"clob_market_ws"}
{"event_at":"2026-07-27T03:06:53.537000Z","event_fingerprint":"8acb07912591b699709f578aaf44aa84d7aeb3890dfec4e518c5f1be077df439","payload":{"connection_id":"f95883f18d264834af91809e5f803e9f","event_at":"2026-07-27T03:06:53.537000Z","event_type":"price_change","frame_hash":"4746ff762b88956d7b0b02c78abcd24df5f54394a77e6db97ad6f3ef0cb78f7a","frame_index":0,"kind":"data","monotonic_ns":223597049511625,"payload":{"event_type":"price_change","market":"0xf9d60bb033695053c4d1d8592e52171c1042f64b41a4b72e09dcc6f4852b6670","price_changes":[{"asset_id":"8698449539441374295770236407991735029336433231649246775082939325523552031992","best_ask":"0.51","best_bid":"0.49","hash":"26249d0e30814a42065ace57f1f00fef25f03dbc","price":"0.47","side":"BUY","size":"149.45"},{"asset_id":"96283536366176669581486355171583722558858323126916278856549586825357358273536","best_ask":"0.51","best_bid":"0.49","hash":"1b934a60dc945200752c6f0b8907d0fe321ac38e","price":"0.53","side":"SELL","size":"149.45"}],"timestamp":"1785121613537"},"payload_hash":"83820df1c4c9c145600dfd91b9a3f78ea2488e0054d55330428945261e8c53ef","raw_frame":"{\"market\":\"0xf9d60bb033695053c4d1d8592e52171c1042f64b41a4b72e09dcc6f4852b6670\", \"price_changes\":[{\"asset_id\":\"8698449539441374295770236407991735029336433231649246775082939325523552031992\", \"price\":\"0.47\", \"size\":\"149.45\", \"side\":\"BUY\", \"hash\":\"26249d0e30814a42065ace57f1f00fef25f03dbc\", \"best_bid\":\"0.49\", \"best_ask\":\"0.51\"}, {\"asset_id\":\"96283536366176669581486355171583722558858323126916278856549586825357358273536\", \"price\":\"0.53\", \"size\":\"149.45\", \"side\":\"SELL\", \"hash\":\"1b934a60dc945200752c6f0b8907d0fe321ac38e\", \"best_bid\":\"0.49\", \"best_ask\":\"0.51\"}], \"timestamp\":\"1785121613537\", \"event_type\":\"price_change\"}","received_at":"2026-07-27T03:06:53.722669Z","schema_version":"clob-market-ws.price_change.v1","sequence":null,"server_hash":null,"server_timestamp":"1785121613537","session_id":"ff6d21c8283948938400a32613abec2c","source":"clob_market_ws"},"received_at":"2026-07-27T03:06:53.722669Z","record_id":"fb63d702284407350cbf7235e948ee6e170ca9a9b2f684fef201e395485d0e22","schema_fingerprint":"4aa3821a28b0b7c2400bc59aba4bcc0a76e971dadd19610d3ad38c768e124dc7","schema_version":"edge-lab-recorder.raw.v1","sequence":null,"source":"clob_market_ws"}
{"event_at":"2026-07-27T03:06:53.538000Z","event_fingerprint":"ce8b1be1a9e4df4981f8da555909e619c3c36cef87f2075bc3e2db2de7fe1f10","payload":{"connection_id":"f95883f18d264834af91809e5f803e9f","event_at":"2026-07-27T03:06:53.538000Z","event_type":"price_change","frame_hash":"ebecc482de59b0e7d747f1c3673efc59f503461e8a720da4b8b9c63fbe806a59","frame_index":0,"kind":"data","monotonic_ns":223597050420750,"payload":{"event_type":"price_change","market":"0xf9d60bb033695053c4d1d8592e52171c1042f64b41a4b72e09dcc6f4852b6670","price_changes":[{"asset_id":"96283536366176669581486355171583722558858323126916278856549586825357358273536","best_ask":"0.51","best_bid":"0.49","hash":"3a9de9957f8420ccda56e25059450126f2a99fed","price":"0.49","side":"BUY","size":"225"},{"asset_id":"8698449539441374295770236407991735029336433231649246775082939325523552031992","best_ask":"0.51","best_bid":"0.49","hash":"08eca7481733065c127b3e47a4b5b250bca98a5f","price":"0.51","side":"SELL","size":"225"}],"timestamp":"1785121613538"},"payload_hash":"854950f55b73ca9278d359082efa31805622dd015262bf5723a342f2e8e1f7c7","raw_frame":"{\"market\":\"0xf9d60bb033695053c4d1d8592e52171c1042f64b41a4b72e09dcc6f4852b6670\", \"price_changes\":[{\"asset_id\":\"96283536366176669581486355171583722558858323126916278856549586825357358273536\", \"price\":\"0.49\", \"size\":\"225\", \"side\":\"BUY\", \"hash\":\"3a9de9957f8420ccda56e25059450126f2a99fed\", \"best_bid\":\"0.49\", \"best_ask\":\"0.51\"}, {\"asset_id\":\"8698449539441374295770236407991735029336433231649246775082939325523552031992\", \"price\":\"0.51\", \"size\":\"225\", \"side\":\"SELL\", \"hash\":\"08eca7481733065c127b3e47a4b5b250bca98a5f\", \"best_bid\":\"0.49\", \"best_ask\":\"0.51\"}], \"timestamp\":\"1785121613538\", \"event_type\":\"price_change\"}","received_at":"2026-07-27T03:06:53.723573Z","schema_version":"clob-market-ws.price_change.v1","sequence":null,"server_hash":null,"server_timestamp":"1785121613538","session_id":"ff6d21c8283948938400a32613abec2c","source":"clob_market_ws"},"received_at":"2026-07-27T03:06:53.723573Z","record_id":"8e49bae5ad22a169d688f11f77a67957ed0e1a9c19c83a0253df65f67ab314fd","schema_fingerprint":"4aa3821a28b0b7c2400bc59aba4bcc0a76e971dadd19610d3ad38c768e124dc7","schema_version":"edge-lab-recorder.raw.v1","sequence":null,"source":"clob_market_ws"}
{"event_at":"2026-07-27T03:06:53.539000Z","event_fingerprint":"5b6e0bb27293f7287918f02773ecbee5cf0174b07c3cd56ce939b4165c41fa47","payload":{"connection_id":"f95883f18d264834af91809e5f803e9f","event_at":"2026-07-27T03:06:53.539000Z","event_type":"price_change","frame_hash":"ccd41a49ab97a2b19b86b70638c3ebd4314dd9238df14a37f00d7cdc5f2c03b5","frame_index":0,"kind":"data","monotonic_ns":223597051889500,"payload":{"event_type":"price_change","market":"0xf9d60bb033695053c4d1d8592e52171c1042f64b41a4b72e09dcc6f4852b6670","price_changes":[{"asset_id":"8698449539441374295770236407991735029336433231649246775082939325523552031992","best_ask":"0.51","best_bid":"0.49","hash":"7999940fda2d1ce80706583f06044240e1a2d86f","price":"0.47","side":"BUY","size":"154.45"},{"asset_id":"96283536366176669581486355171583722558858323126916278856549586825357358273536","best_ask":"0.51","best_bid":"0.49","hash":"1c06731447f472ad4462240c8653b3b8acfffa91","price":"0.53","side":"SELL","size":"154.45"}],"timestamp":"1785121613539"},"payload_hash":"da54452e6f83c7deb98c3da023abe3ce525405f7b80dcf4f540d23c994652d39","raw_frame":"{\"market\":\"0xf9d60bb033695053c4d1d8592e52171c1042f64b41a4b72e09dcc6f4852b6670\", \"price_changes\":[{\"asset_id\":\"8698449539441374295770236407991735029336433231649246775082939325523552031992\", \"price\":\"0.47\", \"size\":\"154.45\", \"side\":\"BUY\", \"hash\":\"7999940fda2d1ce80706583f06044240e1a2d86f\", \"best_bid\":\"0.49\", \"best_ask\":\"0.51\"}, {\"asset_id\":\"96283536366176669581486355171583722558858323126916278856549586825357358273536\", \"price\":\"0.53\", \"size\":\"154.45\", \"side\":\"SELL\", \"hash\":\"1c06731447f472ad4462240c8653b3b8acfffa91\", \"best_bid\":\"0.49\", \"best_ask\":\"0.51\"}], \"timestamp\":\"1785121613539\", \"event_type\":\"price_change\"}","received_at":"2026-07-27T03:06:53.725041Z","schema_version":"clob-market-ws.price_change.v1","sequence":null,"server_hash":null,"server_timestamp":"1785121613539","session_id":"ff6d21c8283948938400a32613abec2c","source":"clob_market_ws"},"received_at":"2026-07-27T03:06:53.725041Z","record_id":"4ac99735e970ece08bc1b112e2d5070df1b97e36183ac7ba9e69b403334fedbc","schema_fingerprint":"4aa3821a28b0b7c2400bc59aba4bcc0a76e971dadd19610d3ad38c768e124dc7","schema_version":"edge-lab-recorder.raw.v1","sequence":null,"source":"clob_market_ws"}
{"event_at":"2026-07-27T03:06:53.540000Z","event_fingerprint":"532ffe381eb1b0057c81c1adfecea758b5d1e5bcae89acd49ffe8993573e8f25","payload":{"connection_id":"f95883f18d264834af91809e5f803e9f","event_at":"2026-07-27T03:06:53.540000Z","event_type":"price_change","frame_hash":"442d707b63ee7c6373d44a309ad91252640262bf9c21f2b46fb38f559db35260","frame_index":0,"kind":"data","monotonic_ns":223597053474958,"payload":{"event_type":"price_change","market":"0xf9d60bb033695053c4d1d8592e52171c1042f64b41a4b72e09dcc6f4852b6670","price_changes":[{"asset_id":"8698449539441374295770236407991735029336433231649246775082939325523552031992","best_ask":"0.51","best_bid":"0.49","hash":"f2b3aa402cbec9312a99b3fa0e3411f1d858499c","price":"0.47","side":"BUY","size":"159.45"},{"asset_id":"96283536366176669581486355171583722558858323126916278856549586825357358273536","best_ask":"0.51","best_bid":"0.49","hash":"d7c91cd19b1b1af8992d6944c9e30ff422337e1a","price":"0.53","side":"SELL","size":"159.45"}],"timestamp":"1785121613540"},"payload_hash":"f7ecc3628a20cd52ccaf29fa457353b8bb9738220c9e55e665c36723ab734be5","raw_frame":"{\"market\":\"0xf9d60bb033695053c4d1d8592e52171c1042f64b41a4b72e09dcc6f4852b6670\", \"price_changes\":[{\"asset_id\":\"8698449539441374295770236407991735029336433231649246775082939325523552031992\", \"price\":\"0.47\", \"size\":\"159.45\", \"side\":\"BUY\", \"hash\":\"f2b3aa402cbec9312a99b3fa0e3411f1d858499c\", \"best_bid\":\"0.49\", \"best_ask\":\"0.51\"}, {\"asset_id\":\"96283536366176669581486355171583722558858323126916278856549586825357358273536\", \"price\":\"0.53\", \"size\":\"159.45\", \"side\":\"SELL\", \"hash\":\"d7c91cd19b1b1af8992d6944c9e30ff422337e1a\", \"best_bid\":\"0.49\", \"best_ask\":\"0.51\"}], \"timestamp\":\"1785121613540\", \"event_type\":\"price_change\"}","received_at":"2026-07-27T03:06:53.726623Z","schema_version":"clob-market-ws.price_change.v1","sequence":null,"server_hash":null,"server_timestamp":"1785121613540","session_id":"ff6d21c8283948938400a32613abec2c","source":"clob_market_ws"},"received_at":"2026-07-27T03:06:53.726623Z","record_id":"5dc7766fb680c31924733849aee5270e998dc00711d8579f0732d4a1076bb3c5","schema_fingerprint":"4aa3821a28b0b7c2400bc59aba4bcc0a76e971dadd19610d3ad38c768e124dc7","schema_version":"edge-lab-recorder.raw.v1","sequence":null,"source":"clob_market_ws"}
{"event_at":"2026-07-27T03:06:53.541000Z","event_fingerprint":"415c020f47a8b4da7e38cd8621ba8812db405de8c943f0d66752e7f3e1744ade","payload":{"connection_id":"f95883f18d264834af91809e5f803e9f","event_at":"2026-07-27T03:06:53.541000Z","event_type":"price_change","frame_hash":"bb6e48421fcb499d84b5a06645eee85f7c4d7cfc97ff2a6397168c66d19e542b","frame_index":0,"kind":"data","monotonic_ns":223597055098666,"payload":{"event_type":"price_change","market":"0xf9d60bb033695053c4d1d8592e52171c1042f64b41a4b72e09dcc6f4852b6670","price_changes":[{"asset_id":"8698449539441374295770236407991735029336433231649246775082939325523552031992","best_ask":"0.51","best_bid":"0.49","hash":"aa8b94ff7825d79cfdd820b71259ffa9e45fc902","price":"0.47","side":"BUY","size":"164.45"},{"asset_id":"96283536366176669581486355171583722558858323126916278856549586825357358273536","best_ask":"0.51","best_bid":"0.49","hash":"2c866f682d3934641677e891374d1b5cac01179e","price":"0.53","side":"SELL","size":"164.45"}],"timestamp":"1785121613541"},"payload_hash":"a280b431cd89d4f70dc507f9e01e6301b8abffe0abc1b3ed8657c6c24964c9d5","raw_frame":"{\"market\":\"0xf9d60bb033695053c4d1d8592e52171c1042f64b41a4b72e09dcc6f4852b6670\", \"price_changes\":[{\"asset_id\":\"8698449539441374295770236407991735029336433231649246775082939325523552031992\", \"price\":\"0.47\", \"size\":\"164.45\", \"side\":\"BUY\", \"hash\":\"aa8b94ff7825d79cfdd820b71259ffa9e45fc902\", \"best_bid\":\"0.49\", \"best_ask\":\"0.51\"}, {\"asset_id\":\"96283536366176669581486355171583722558858323126916278856549586825357358273536\", \"price\":\"0.53\", \"size\":\"164.45\", \"side\":\"SELL\", \"hash\":\"2c866f682d3934641677e891374d1b5cac01179e\", \"best_bid\":\"0.49\", \"best_ask\":\"0.51\"}], \"timestamp\":\"1785121613541\", \"event_type\":\"price_change\"}","received_at":"2026-07-27T03:06:53.728250Z","schema_version":"clob-market-ws.price_change.v1","sequence":null,"server_hash":null,"server_timestamp":"1785121613541","session_id":"ff6d21c8283948938400a32613abec2c","source":"clob_market_ws"},"received_at":"2026-07-27T03:06:53.728250Z","record_id":"af149eb71107dfae903bc589ffa60b2754ae1798505d72cde8c8fb8bac41c80d","schema_fingerprint":"4aa3821a28b0b7c2400bc59aba4bcc0a76e971dadd19610d3ad38c768e124dc7","schema_version":"edge-lab-recorder.raw.v1","sequence":null,"source":"clob_market_ws"}
{"event_at":"2026-07-27T03:06:53.541000Z","event_fingerprint":"cee49e67c9c5bcbd5c5f2eb68f0d9e9aa763d7e0ef280d5937649966f85c3624","payload":{"connection_id":"f95883f18d264834af91809e5f803e9f","event_at":"2026-07-27T03:06:53.541000Z","event_type":"price_change","frame_hash":"64f0ae42b465a943f8d0bb1f91aa1e6e70fa7cf085630c132c990ff1f350c0f5","frame_index":0,"kind":"data","monotonic_ns":223597056563583,"payload":{"event_type":"price_change","market":"0xf9d60bb033695053c4d1d8592e52171c1042f64b41a4b72e09dcc6f4852b6670","price_changes":[{"asset_id":"8698449539441374295770236407991735029336433231649246775082939325523552031992","best_ask":"0.51","best_bid":"0.49","hash":"f384bc5022ad9685d86895bbebd4db4e8f99b5f1","price":"0.47","side":"BUY","size":"169.45"},{"asset_id":"96283536366176669581486355171583722558858323126916278856549586825357358273536","best_ask":"0.51","best_bid":"0.49","hash":"1daa7b503909ded8c2a765ec1676f1dc1be670c8","price":"0.53","side":"SELL","size":"169.45"}],"timestamp":"1785121613541"},"payload_hash":"66050fc112be5dce2a33f24e162f806566729f8a6441a5e4adcd394fa7ca132a","raw_frame":"{\"market\":\"0xf9d60bb033695053c4d1d8592e52171c1042f64b41a4b72e09dcc6f4852b6670\", \"price_changes\":[{\"asset_id\":\"8698449539441374295770236407991735029336433231649246775082939325523552031992\", \"price\":\"0.47\", \"size\":\"169.45\", \"side\":\"BUY\", \"hash\":\"f384bc5022ad9685d86895bbebd4db4e8f99b5f1\", \"best_bid\":\"0.49\", \"best_ask\":\"0.51\"}, {\"asset_id\":\"96283536366176669581486355171583722558858323126916278856549586825357358273536\", \"price\":\"0.53\", \"size\":\"169.45\", \"side\":\"SELL\", \"hash\":\"1daa7b503909ded8c2a765ec1676f1dc1be670c8\", \"best_bid\":\"0.49\", \"best_ask\":\"0.51\"}], \"timestamp\":\"1785121613541\", \"event_type\":\"price_change\"}","received_at":"2026-07-27T03:06:53.729716Z","schema_version":"clob-market-ws.price_change.v1","sequence":null,"server_hash":null,"server_timestamp":"1785121613541","session_id":"ff6d21c8283948938400a32613abec2c","source":"clob_market_ws"},"received_at":"2026-07-27T03:06:53.729716Z","record_id":"35441e9b71093b7be6f8b988b59b9414f4bd250c69197804f4893969270164a2","schema_fingerprint":"4aa3821a28b0b7c2400bc59aba4bcc0a76e971dadd19610d3ad38c768e124dc7","schema_version":"edge-lab-recorder.raw.v1","sequence":null,"source":"clob_market_ws"}
{"event_at":"2026-07-27T03:06:53.542000Z","event_fingerprint":"392d68395f857f71cb4931affcf2b504b7bebc5319c1a92ecf86290b8d6e5be1","payload":{"connection_id":"f95883f18d264834af91809e5f803e9f","event_at":"2026-07-27T03:06:53.542000Z","event_type":"price_change","frame_hash":"dbc3075e78abe6437e40f7b2a5c28ebe16cdd102659bd53ffd238bfc8b51e097","frame_index":0,"kind":"data","monotonic_ns":223597057996416,"payload":{"event_type":"price_change","market":"0xf9d60bb033695053c4d1d8592e52171c1042f64b41a4b72e09dcc6f4852b6670","price_changes":[{"asset_id":"8698449539441374295770236407991735029336433231649246775082939325523552031992","best_ask":"0.51","best_bid":"0.49","hash":"c3c5b78f10b430011845a8894432450bf8eea14c","price":"0.47","side":"BUY","size":"174.45"},{"asset_id":"96283536366176669581486355171583722558858323126916278856549586825357358273536","best_ask":"0.51","best_bid":"0.49","hash":"7659f67615a681444e2a44a3975b66d17e39163c","price":"0.53","side":"SELL","size":"174.45"}],"timestamp":"1785121613542"},"payload_hash":"1e472c1f0e2e1e24b6b6510c0a34b37f35b94c52d88537b9362db64a50fdcbbe","raw_frame":"{\"market\":\"0xf9d60bb033695053c4d1d8592e52171c1042f64b41a4b72e09dcc6f4852b6670\", \"price_changes\":[{\"asset_id\":\"8698449539441374295770236407991735029336433231649246775082939325523552031992\", \"price\":\"0.47\", \"size\":\"174.45\", \"side\":\"BUY\", \"hash\":\"c3c5b78f10b430011845a8894432450bf8eea14c\", \"best_bid\":\"0.49\", \"best_ask\":\"0.51\"}, {\"asset_id\":\"96283536366176669581486355171583722558858323126916278856549586825357358273536\", \"price\":\"0.53\", \"size\":\"174.45\", \"side\":\"SELL\", \"hash\":\"7659f67615a681444e2a44a3975b66d17e39163c\", \"best_bid\":\"0.49\", \"best_ask\":\"0.51\"}], \"timestamp\":\"1785121613542\", \"event_type\":\"price_change\"}","received_at":"2026-07-27T03:06:53.731149Z","schema_version":"clob-market-ws.price_change.v1","sequence":null,"server_hash":null,"server_timestamp":"1785121613542","session_id":"ff6d21c8283948938400a32613abec2c","source":"clob_market_ws"},"received_at":"2026-07-27T03:06:53.731149Z","record_id":"e46f740d374ff3fcf751a14aaf888197128163741c52f823755b43784c836de4","schema_fingerprint":"4aa3821a28b0b7c2400bc59aba4bcc0a76e971dadd19610d3ad38c768e124dc7","schema_version":"edge-lab-recorder.raw.v1","sequence":null,"source":"clob_market_ws"}
{"event_at":"2026-07-27T03:06:53.543000Z","event_fingerprint":"a5cc0c6252a56dde6ba23fc0411a31b847cbbe2bad2672587a4d3c435f61a2c8","payload":{"connection_id":"f95883f18d264834af91809e5f803e9f","event_at":"2026-07-27T03:06:53.543000Z","event_type":"price_change","frame_hash":"5af7db161c7daadc57e7fc99d43c19cb605ea3026338224576bf507f5d0f3209","frame_index":0,"kind":"data","monotonic_ns":223597058931083,"payload":{"event_type":"price_change","market":"0xf9d60bb033695053c4d1d8592e52171c1042f64b41a4b72e09dcc6f4852b6670","price_changes":[{"asset_id":"8698449539441374295770236407991735029336433231649246775082939325523552031992","best_ask":"0.51","best_bid":"0.49","hash":"70621e6332e27c32ccafe201d26617a536cebddc","price":"0.47","side":"BUY","size":"179.45"},{"asset_id":"96283536366176669581486355171583722558858323126916278856549586825357358273536","best_ask":"0.51","best_bid":"0.49","hash":"7768599ca954265adacecf58df88b62e4381d01d","price":"0.53","side":"SELL","size":"179.45"}],"timestamp":"1785121613543"},"payload_hash":"40789859b79136ee47965aeb3b70b6add99b2aa015ac787c7cbaf021f2f0b49a","raw_frame":"{\"market\":\"0xf9d60bb033695053c4d1d8592e52171c1042f64b41a4b72e09dcc6f4852b6670\", \"price_changes\":[{\"asset_id\":\"8698449539441374295770236407991735029336433231649246775082939325523552031992\", \"price\":\"0.47\", \"size\":\"179.45\", \"side\":\"BUY\", \"hash\":\"70621e6332e27c32ccafe201d26617a536cebddc\", \"best_bid\":\"0.49\", \"best_ask\":\"0.51\"}, {\"asset_id\":\"96283536366176669581486355171583722558858323126916278856549586825357358273536\", \"price\":\"0.53\", \"size\":\"179.45\", \"side\":\"SELL\", \"hash\":\"7768599ca954265adacecf58df88b62e4381d01d\", \"best_bid\":\"0.49\", \"best_ask\":\"0.51\"}], \"timestamp\":\"1785121613543\", \"event_type\":\"price_change\"}","received_at":"2026-07-27T03:06:53.732090Z","schema_version":"clob-market-ws.price_change.v1","sequence":null,"server_hash":null,"server_timestamp":"1785121613543","session_id":"ff6d21c8283948938400a32613abec2c","source":"clob_market_ws"},"received_at":"2026-07-27T03:06:53.732090Z","record_id":"d8eed570916b1b749ad05968c66f71d522c1ee16218f5f82659fc7762e5f4353","schema_fingerprint":"4aa3821a28b0b7c2400bc59aba4bcc0a76e971dadd19610d3ad38c768e124dc7","schema_version":"edge-lab-recorder.raw.v1","sequence":null,"source":"clob_market_ws"}
{"event_at":"2026-07-27T03:06:53.544000Z","event_fingerprint":"6ea58878ce1e761059d3b630aaac49e54e875d5942ff01b2451c979c3562b95d","payload":{"connection_id":"f95883f18d264834af91809e5f803e9f","event_at":"2026-07-27T03:06:53.544000Z","event_type":"price_change","frame_hash":"97f9ee24a36ebe291d42e812db22655f0ce6ea822f8c8f2cb998bf3023069041","frame_index":0,"kind":"data","monotonic_ns":223597059929708,"payload":{"event_type":"price_change","market":"0xf9d60bb033695053c4d1d8592e52171c1042f64b41a4b72e09dcc6f4852b6670","price_changes":[{"asset_id":"8698449539441374295770236407991735029336433231649246775082939325523552031992","best_ask":"0.51","best_bid":"0.49","hash":"148bb4843103b990914b8dcde3bb826e6227edfa","price":"0.47","side":"BUY","size":"184.45"},{"asset_id":"96283536366176669581486355171583722558858323126916278856549586825357358273536","best_ask":"0.51","best_bid":"0.49","hash":"b384024989166cf2d03170c2037784aba5a569b6","price":"0.53","side":"SELL","size":"184.45"}],"timestamp":"1785121613544"},"payload_hash":"addeb2eea787a805342ea3c7a48f49c352bffe020a817fa4745cb82198ec2d43","raw_frame":"{\"market\":\"0xf9d60bb033695053c4d1d8592e52171c1042f64b41a4b72e09dcc6f4852b6670\", \"price_changes\":[{\"asset_id\":\"8698449539441374295770236407991735029336433231649246775082939325523552031992\", \"price\":\"0.47\", \"size\":\"184.45\", \"side\":\"BUY\", \"hash\":\"148bb4843103b990914b8dcde3bb826e6227edfa\", \"best_bid\":\"0.49\", \"best_ask\":\"0.51\"}, {\"asset_id\":\"96283536366176669581486355171583722558858323126916278856549586825357358273536\", \"price\":\"0.53\", \"size\":\"184.45\", \"side\":\"SELL\", \"hash\":\"b384024989166cf2d03170c2037784aba5a569b6\", \"best_bid\":\"0.49\", \"best_ask\":\"0.51\"}], \"timestamp\":\"1785121613544\", \"event_type\":\"price_change\"}","received_at":"2026-07-27T03:06:53.733088Z","schema_version":"clob-market-ws.price_change.v1","sequence":null,"server_hash":null,"server_timestamp":"1785121613544","session_id":"ff6d21c8283948938400a32613abec2c","source":"clob_market_ws"},"received_at":"2026-07-27T03:06:53.733088Z","record_id":"86e5692f40a604d3c023f088460fdfc6d7de2aae6a049b4e0ca72cc3d33726c2","schema_fingerprint":"4aa3821a28b0b7c2400bc59aba4bcc0a76e971dadd19610d3ad38c768e124dc7","schema_version":"edge-lab-recorder.raw.v1","sequence":null,"source":"clob_market_ws"}
{"event_at":"2026-07-27T03:06:53.544000Z","event_fingerprint":"21feffa517d56a13c3f97a879d4c9a93ecfa0a64669bc60f49cd72bfc9ab135b","payload":{"connection_id":"f95883f18d264834af91809e5f803e9f","event_at":"2026-07-27T03:06:53.544000Z","event_type":"price_change","frame_hash":"041bc285ca9a06ed04b8cb412fd50428d127df3c7f22efa4bb822b25039ad471","frame_index":0,"kind":"data","monotonic_ns":223597060443166,"payload":{"event_type":"price_change","market":"0xf9d60bb033695053c4d1d8592e52171c1042f64b41a4b72e09dcc6f4852b6670","price_changes":[{"asset_id":"8698449539441374295770236407991735029336433231649246775082939325523552031992","best_ask":"0.51","best_bid":"0.49","hash":"ac6483de96c0d33da34dd9e205ddecf0fc585c1a","price":"0.47","side":"BUY","size":"189.45"},{"asset_id":"96283536366176669581486355171583722558858323126916278856549586825357358273536","best_ask":"0.51","best_bid":"0.49","hash":"e045a40068c4232d16f6d26d1fb2e16d527d93b9","price":"0.53","side":"SELL","size":"189.45"}],"timestamp":"1785121613544"},"payload_hash":"d8a856d7c40daa49e316c21a338aeec702585987742011ae879de830dde131ba","raw_frame":"{\"market\":\"0xf9d60bb033695053c4d1d8592e52171c1042f64b41a4b72e09dcc6f4852b6670\", \"price_changes\":[{\"asset_id\":\"8698449539441374295770236407991735029336433231649246775082939325523552031992\", \"price\":\"0.47\", \"size\":\"189.45\", \"side\":\"BUY\", \"hash\":\"ac6483de96c0d33da34dd9e205ddecf0fc585c1a\", \"best_bid\":\"0.49\", \"best_ask\":\"0.51\"}, {\"asset_id\":\"96283536366176669581486355171583722558858323126916278856549586825357358273536\", \"price\":\"0.53\", \"size\":\"189.45\", \"side\":\"SELL\", \"hash\":\"e045a40068c4232d16f6d26d1fb2e16d527d93b9\", \"best_bid\":\"0.49\", \"best_ask\":\"0.51\"}], \"timestamp\":\"1785121613544\", \"event_type\":\"price_change\"}","received_at":"2026-07-27T03:06:53.733602Z","schema_version":"clob-market-ws.price_change.v1","sequence":null,"server_hash":null,"server_timestamp":"1785121613544","session_id":"ff6d21c8283948938400a32613abec2c","source":"clob_market_ws"},"received_at":"2026-07-27T03:06:53.733602Z","record_id":"30b8d1fe7239c0b57201fca85f45588525d9902f60afde0cbfde01df09abaedc","schema_fingerprint":"4aa3821a28b0b7c2400bc59aba4bcc0a76e971dadd19610d3ad38c768e124dc7","schema_version":"edge-lab-recorder.raw.v1","sequence":null,"source":"clob_market_ws"}
{"event_at":"2026-07-27T03:06:53.545000Z","event_fingerprint":"070e920d538a2a1ea73fd211618ea3e47fa6a72a492a2504b930e07eaef498be","payload":{"connection_id":"f95883f18d264834af91809e5f803e9f","event_at":"2026-07-27T03:06:53.545000Z","event_type":"price_change","frame_hash":"d570f70749e94bcdb32ebcf43be0214819264d6e9f9fa2cd6dd7b2d0e40a512c","frame_index":0,"kind":"data","monotonic_ns":223597061561208,"payload":{"event_type":"price_change","market":"0xf9d60bb033695053c4d1d8592e52171c1042f64b41a4b72e09dcc6f4852b6670","price_changes":[{"asset_id":"8698449539441374295770236407991735029336433231649246775082939325523552031992","best_ask":"0.51","best_bid":"0.49","hash":"9147ed5e3aafc814ced7cf4834c4e9a120dd60b3","price":"0.47","side":"BUY","size":"194.45"},{"asset_id":"96283536366176669581486355171583722558858323126916278856549586825357358273536","best_ask":"0.51","best_bid":"0.49","hash":"592618f17c41892595b8708ff6f90d281f20de16","price":"0.53","side":"SELL","size":"194.45"}],"timestamp":"1785121613545"},"payload_hash":"a31dcba7aab7f0d6e0f56ad489a16a871e1f2ef6642621036426cac24e1af553","raw_frame":"{\"market\":\"0xf9d60bb033695053c4d1d8592e52171c1042f64b41a4b72e09dcc6f4852b6670\", \"price_changes\":[{\"asset_id\":\"8698449539441374295770236407991735029336433231649246775082939325523552031992\", \"price\":\"0.47\", \"size\":\"194.45\", \"side\":\"BUY\", \"hash\":\"9147ed5e3aafc814ced7cf4834c4e9a120dd60b3\", \"best_bid\":\"0.49\", \"best_ask\":\"0.51\"}, {\"asset_id\":\"96283536366176669581486355171583722558858323126916278856549586825357358273536\", \"price\":\"0.53\", \"size\":\"194.45\", \"side\":\"SELL\", \"hash\":\"592618f17c41892595b8708ff6f90d281f20de16\", \"best_bid\":\"0.49\", \"best_ask\":\"0.51\"}], \"timestamp\":\"1785121613545\", \"event_type\":\"price_change\"}","received_at":"2026-07-27T03:06:53.734719Z","schema_version":"clob-market-ws.price_change.v1","sequence":null,"server_hash":null,"server_timestamp":"1785121613545","session_id":"ff6d21c8283948938400a32613abec2c","source":"clob_market_ws"},"received_at":"2026-07-27T03:06:53.734719Z","record_id":"2f3f12221c3cde27c4541549343d17b45b6adff72a9eabd96c6dde4cdfe20d52","schema_fingerprint":"4aa3821a28b0b7c2400bc59aba4bcc0a76e971dadd19610d3ad38c768e124dc7","schema_version":"edge-lab-recorder.raw.v1","sequence":null,"source":"clob_market_ws"}
{"event_at":"2026-07-27T03:06:53.546000Z","event_fingerprint":"6c86bbe54ce2bbbf355bba06aa3ec1cd7a437c437445f799f519123d19ce1e25","payload":{"connection_id":"f95883f18d264834af91809e5f803e9f","event_at":"2026-07-27T03:06:53.546000Z","event_type":"price_change","frame_hash":"76aa7a8c597c20219f129df9c019a19415a1619f86e05294f8008f4a20b1e18b","frame_index":0,"kind":"data","monotonic_ns":223597062052250,"payload":{"event_type":"price_change","market":"0xf9d60bb033695053c4d1d8592e52171c1042f64b41a4b72e09dcc6f4852b6670","price_changes":[{"asset_id":"8698449539441374295770236407991735029336433231649246775082939325523552031992","best_ask":"0.51","best_bid":"0.49","hash":"416745c29f21e157c3c8299bc9e0590a98e63e52","price":"0.47","side":"BUY","size":"199.45"},{"asset_id":"96283536366176669581486355171583722558858323126916278856549586825357358273536","best_ask":"0.51","best_bid":"0.49","hash":"7d9a07e579dbdf9e00ce6488cbd57c266318aefc","price":"0.53","side":"SELL","size":"199.45"}],"timestamp":"1785121613546"},"payload_hash":"b218ac7e742ca40927469b3f178fb08823d0cfe7b58448ad7df189591dec1d5c","raw_frame":"{\"market\":\"0xf9d60bb033695053c4d1d8592e52171c1042f64b41a4b72e09dcc6f4852b6670\", \"price_changes\":[{\"asset_id\":\"8698449539441374295770236407991735029336433231649246775082939325523552031992\", \"price\":\"0.47\", \"size\":\"199.45\", \"side\":\"BUY\", \"hash\":\"416745c29f21e157c3c8299bc9e0590a98e63e52\", \"best_bid\":\"0.49\", \"best_ask\":\"0.51\"}, {\"asset_id\":\"96283536366176669581486355171583722558858323126916278856549586825357358273536\", \"price\":\"0.53\", \"size\":\"199.45\", \"side\":\"SELL\", \"hash\":\"7d9a07e579dbdf9e00ce6488cbd57c266318aefc\", \"best_bid\":\"0.49\", \"best_ask\":\"0.51\"}], \"timestamp\":\"1785121613546\", \"event_type\":\"price_change\"}","received_at":"2026-07-27T03:06:53.735211Z","schema_version":"clob-market-ws.price_change.v1","sequence":null,"server_hash":null,"server_timestamp":"1785121613546","session_id":"ff6d21c8283948938400a32613abec2c","source":"clob_market_ws"},"received_at":"2026-07-27T03:06:53.735211Z","record_id":"d46061b85e5065a80d431f541bc5111686fbde341942f7c4b60d2cbc60a447ed","schema_fingerprint":"4aa3821a28b0b7c2400bc59aba4bcc0a76e971dadd19610d3ad38c768e124dc7","schema_version":"edge-lab-recorder.raw.v1","sequence":null,"source":"clob_market_ws"}
{"event_at":"2026-07-27T03:06:53.546000Z","event_fingerprint":"e436f8575b315fb7d2f840a0445e1ee44488a78a15b50abad5cdab3b8d32934d","payload":{"connection_id":"f95883f18d264834af91809e5f803e9f","event_at":"2026-07-27T03:06:53.546000Z","event_type":"price_change","frame_hash":"8d1addf82fce9fbac07726aaeec8d9fc6fdb8ef026216f5b205dd0ff82155797","frame_index":0,"kind":"data","monotonic_ns":223597062879208,"payload":{"event_type":"price_change","market":"0xf9d60bb033695053c4d1d8592e52171c1042f64b41a4b72e09dcc6f4852b6670","price_changes":[{"asset_id":"8698449539441374295770236407991735029336433231649246775082939325523552031992","best_ask":"0.51","best_bid":"0.49","hash":"47ed5bdc563a3a4af41e493e7507dd8497839153","price":"0.47","side":"BUY","size":"204.45"},{"asset_id":"96283536366176669581486355171583722558858323126916278856549586825357358273536","best_ask":"0.51","best_bid":"0.49","hash":"81540c2de1d68123cfb9649e4ebc83ec00838448","price":"0.53","side":"SELL","size":"204.45"}],"timestamp":"1785121613546"},"payload_hash":"6a307ab76ed25c885e09da4a96e093fc0d360dca3606d47b51d8bfce391c6ece","raw_frame":"{\"market\":\"0xf9d60bb033695053c4d1d8592e52171c1042f64b41a4b72e09dcc6f4852b6670\", \"price_changes\":[{\"asset_id\":\"8698449539441374295770236407991735029336433231649246775082939325523552031992\", \"price\":\"0.47\", \"size\":\"204.45\", \"side\":\"BUY\", \"hash\":\"47ed5bdc563a3a4af41e493e7507dd8497839153\", \"best_bid\":\"0.49\", \"best_ask\":\"0.51\"}, {\"asset_id\":\"96283536366176669581486355171583722558858323126916278856549586825357358273536\", \"price\":\"0.53\", \"size\":\"204.45\", \"side\":\"SELL\", \"hash\":\"81540c2de1d68123cfb9649e4ebc83ec00838448\", \"best_bid\":\"0.49\", \"best_ask\":\"0.51\"}], \"timestamp\":\"1785121613546\", \"event_type\":\"price_change\"}","received_at":"2026-07-27T03:06:53.736031Z","schema_version":"clob-market-ws.price_change.v1","sequence":null,"server_hash":null,"server_timestamp":"1785121613546","session_id":"ff6d21c8283948938400a32613abec2c","source":"clob_market_ws"},"received_at":"2026-07-27T03:06:53.736031Z","record_id":"3fba94adf97a13acb6d3366dfaf0651fa98751322857f0abd16e6b0d061fecf0","schema_fingerprint":"4aa3821a28b0b7c2400bc59aba4bcc0a76e971dadd19610d3ad38c768e124dc7","schema_version":"edge-lab-recorder.raw.v1","sequence":null,"source":"clob_market_ws"}
{"event_at":"2026-07-27T03:06:53.547000Z","event_fingerprint":"5f3b1652df72273575adb933e3f4cd133ce062ff692a440093d493ce62e6d8d7","payload":{"connection_id":"f95883f18d264834af91809e5f803e9f","event_at":"2026-07-27T03:06:53.547000Z","event_type":"price_change","frame_hash":"aa968398a63446c59575066c28dc28b84de51ae5d063419d0ea24762dd85a8f8","frame_index":0,"kind":"data","monotonic_ns":223597064337458,"payload":{"event_type":"price_change","market":"0xf9d60bb033695053c4d1d8592e52171c1042f64b41a4b72e09dcc6f4852b6670","price_changes":[{"asset_id":"8698449539441374295770236407991735029336433231649246775082939325523552031992","best_ask":"0.51","best_bid":"0.49","hash":"44f736cdb1f9772cb2e1d0e8dcc90398d8d6f85b","price":"0.47","side":"BUY","size":"209.45"},{"asset_id":"96283536366176669581486355171583722558858323126916278856549586825357358273536","best_ask":"0.51","best_bid":"0.49","hash":"028d9a62f3da204ea9e0dd7d60b79069022a24a2","price":"0.53","side":"SELL","size":"209.45"}],"timestamp":"1785121613547"},"payload_hash":"084e662b71d3dd2c7be0f98ee93531f158105dbb18fcf6b6cc7bb68a5d476945","raw_frame":"{\"market\":\"0xf9d60bb033695053c4d1d8592e52171c1042f64b41a4b72e09dcc6f4852b6670\", \"price_changes\":[{\"asset_id\":\"8698449539441374295770236407991735029336433231649246775082939325523552031992\", \"price\":\"0.47\", \"size\":\"209.45\", \"side\":\"BUY\", \"hash\":\"44f736cdb1f9772cb2e1d0e8dcc90398d8d6f85b\", \"best_bid\":\"0.49\", \"best_ask\":\"0.51\"}, {\"asset_id\":\"96283536366176669581486355171583722558858323126916278856549586825357358273536\", \"price\":\"0.53\", \"size\":\"209.45\", \"side\":\"SELL\", \"hash\":\"028d9a62f3da204ea9e0dd7d60b79069022a24a2\", \"best_bid\":\"0.49\", \"best_ask\":\"0.51\"}], \"timestamp\":\"1785121613547\", \"event_type\":\"price_change\"}","received_at":"2026-07-27T03:06:53.737483Z","schema_version":"clob-market-ws.price_change.v1","sequence":null,"server_hash":null,"server_timestamp":"1785121613547","session_id":"ff6d21c8283948938400a32613abec2c","source":"clob_market_ws"},"received_at":"2026-07-27T03:06:53.737483Z","record_id":"42f22eb4bbe5e75f626b7aa5decb3f9c333ddfee00f372c5931e59641d76f366","schema_fingerprint":"4aa3821a28b0b7c2400bc59aba4bcc0a76e971dadd19610d3ad38c768e124dc7","schema_version":"edge-lab-recorder.raw.v1","sequence":null,"source":"clob_market_ws"}
