{"event_at":"2026-07-27T03:10:46.047000Z","event_fingerprint":"77ec3f9e452638282a714fbc21f3fd866bf60974ba15e521689f687b9e3793af","payload":{"connection_id":"f95883f18d264834af91809e5f803e9f","event_at":"2026-07-27T03:10:46.047000Z","event_type":"price_change","frame_hash":"31111885dfdec944c33af61c25b7d1cd6a04d86159eaf5c8fd66e93165da57b2","frame_index":0,"kind":"data","monotonic_ns":223829302971791,"payload":{"event_type":"price_change","market":"0xf9d60bb033695053c4d1d8592e52171c1042f64b41a4b72e09dcc6f4852b6670","price_changes":[{"asset_id":"8698449539441374295770236407991735029336433231649246775082939325523552031992","best_ask":"0.22","best_bid":"0.21","hash":"0ec0e7d680f805a9ba2d800684394b9bff24ff19","price":"0.01","side":"BUY","size":"6839.52"},{"asset_id":"96283536366176669581486355171583722558858323126916278856549586825357358273536","best_ask":"0.79","best_bid":"0.78","hash":"d4e5984d9443859b435948396e02b0acdb2d6b98","price":"0.99","side":"SELL","size":"6839.52"}],"timestamp":"1785121846047"},"payload_hash":"aeee3aaa2a116b2a5930947a4ba2b31737d8022c516c95eb389edbe127ec01aa","raw_frame":"{\"market\":\"0xf9d60bb033695053c4d1d8592e52171c1042f64b41a4b72e09dcc6f4852b6670\", \"price_changes\":[{\"asset_id\":\"8698449539441374295770236407991735029336433231649246775082939325523552031992\", \"price\":\"0.01\", \"size\":\"6839.52\", \"side\":\"BUY\", \"hash\":\"0ec0e7d680f805a9ba2d800684394b9bff24ff19\", \"best_bid\":\"0.21\", \"best_ask\":\"0.22\"}, {\"asset_id\":\"96283536366176669581486355171583722558858323126916278856549586825357358273536\", \"price\":\"0.99\", \"size\":\"6839.52\", \"side\":\"SELL\", \"hash\":\"d4e5984d9443859b435948396e02b0acdb2d6b98\", \"best_bid\":\"0.78\", \"best_ask\":\"0.79\"}], \"timestamp\":\"1785121846047\", \"event_type\":\"price_change\"}","received_at":"2026-07-27T03:10:45.972874Z","schema_version":"clob-market-ws.price_change.v1","sequence":null,"server_hash":null,"server_timestamp":"1785121846047","session_id":"ff6d21c8283948938400a32613abec2c","source":"clob_market_ws"},"received_at":"2026-07-27T03:10:45.972874Z","record_id":"6dbaf75eaa6ca21faac5ac7ce22d9be6aa00acf1744312616cbb184b10420ed9","schema_fingerprint":"4aa3821a28b0b7c2400bc59aba4bcc0a76e971dadd19610d3ad38c768e124dc7","schema_version":"edge-lab-recorder.raw.v1","sequence":null,"source":"clob_market_ws"}
{"event_at":"2026-07-27T03:10:46.069000Z","event_fingerprint":"1af1d28d2acad60f20cc9095bcee3852acebba647fb7f2a16bb2302c26981a25","payload":{"connection_id":"f95883f18d264834af91809e5f803e9f","event_at":"2026-07-27T03:10:46.069000Z","event_type":"price_change","frame_hash":"4a420b870434300c82777503c20126bc842584e43f037363a8f5ec336b92fe07","frame_index":0,"kind":"data","monotonic_ns":223829305329125,"payload":{"event_type":"price_change","market":"0xf9d60bb033695053c4d1d8592e52171c1042f64b41a4b72e09dcc6f4852b6670","price_changes":[{"asset_id":"96283536366176669581486355171583722558858323126916278856549586825357358273536","best_ask":"0.79","best_bid":"0.78","hash":"08a11fd3c50f886fe4b7bfe61125cf869d922374","price":"0.02","side":"BUY","size":"2328.79"},{"asset_id":"8698449539441374295770236407991735029336433231649246775082939325523552031992","best_ask":"0.22","best_bid":"0.21","hash":"c8a08a7a9b3cb06b522c5837b1b6d15ecb7ee64a","price":"0.98","side":"SELL","size":"2328.79"}],"timestamp":"1785121846069"},"payload_hash":"649b06649acc330e4a915cf4d50ef0ac42a2ab9fad010cdd25e93d801a889990","raw_frame":"{\"market\":\"0xf9d60bb033695053c4d1d8592e52171c1042f64b41a4b72e09dcc6f4852b6670\", \"price_changes\":[{\"asset_id\":\"96283536366176669581486355171583722558858323126916278856549586825357358273536\", \"price\":\"0.02\", \"size\":\"2328.79\", \"side\":\"BUY\", \"hash\":\"08a11fd3c50f886fe4b7bfe61125cf869d922374\", \"best_bid\":\"0.78\", \"best_ask\":\"0.79\"}, {\"asset_id\":\"8698449539441374295770236407991735029336433231649246775082939325523552031992\", \"price\":\"0.98\", \"size\":\"2328.79\", \"side\":\"SELL\", \"hash\":\"c8a08a7a9b3cb06b522c5837b1b6d15ecb7ee64a\", \"best_bid\":\"0.21\", \"best_ask\":\"0.22\"}], \"timestamp\":\"1785121846069\", \"event_type\":\"price_change\"}","received_at":"2026-07-27T03:10:45.975228Z","schema_version":"clob-market-ws.price_change.v1","sequence":null,"server_hash":null,"server_timestamp":"1785121846069","session_id":"ff6d21c8283948938400a32613abec2c","source":"clob_market_ws"},"received_at":"2026-07-27T03:10:45.975228Z","record_id":"9a60ff7bbd4489c065d16a92bd93182d35b41a958955c9d2dd03571aad606c62","schema_fingerprint":"4aa3821a28b0b7c2400bc59aba4bcc0a76e971dadd19610d3ad38c768e124dc7","schema_version":"edge-lab-recorder.raw.v1","sequence":null,"source":"clob_market_ws"}
{"event_at":"2026-07-27T03:10:46.077000Z","event_fingerprint":"dd06b584221bc34eeefeafe15750d032b436f6940a667b65319f466f91a22365","payload":{"connection_id":"f95883f18d264834af91809e5f803e9f","event_at":"2026-07-27T03:10:46.077000Z","event_type":"price_change","frame_hash":"3fd23357f268938e2b9e8319a72aa6ffadb9aab2b1c572dc6097d1e54c30e3d8","frame_index":0,"kind":"data","monotonic_ns":223829309131083,"payload":{"event_type":"price_change","market":"0xf9d60bb033695053c4d1d8592e52171c1042f64b41a4b72e09dcc6f4852b6670","price_changes":[{"asset_id":"8698449539441374295770236407991735029336433231649246775082939325523552031992","best_ask":"0.22","best_bid":"0.21","hash":"5e1fa58dbe5027c90388580da4bfc05b7f8a6e05","price":"0.34","side":"SELL","size":"151.29"},{"asset_id":"96283536366176669581486355171583722558858323126916278856549586825357358273536","best_ask":"0.79","best_bid":"0.78","hash":"a31756d04bbbecd1a447f21c936ef362025777aa","price":"0.66","side":"BUY","size":"151.29"}],"timestamp":"1785121846077"},"payload_hash":"7790fda2e11f3bd4c3e03b13407d739a024040bc2e683a66b15c148531d12d62","raw_frame":"{\"market\":\"0xf9d60bb033695053c4d1d8592e52171c1042f64b41a4b72e09dcc6f4852b6670\", \"price_changes\":[{\"asset_id\":\"8698449539441374295770236407991735029336433231649246775082939325523552031992\", \"price\":\"0.34\", \"size\":\"151.29\", \"side\":\"SELL\", \"hash\":\"5e1fa58dbe5027c90388580da4bfc05b7f8a6e05\", \"best_bid\":\"0.21\", \"best_ask\":\"0.22\"}, {\"asset_id\":\"96283536366176669581486355171583722558858323126916278856549586825357358273536\", \"price\":\"0.66\", \"size\":\"151.29\", \"side\":\"BUY\", \"hash\":\"a31756d04bbbecd1a447f21c936ef362025777aa\", \"best_bid\":\"0.78\", \"best_ask\":\"0.79\"}], \"timestamp\":\"1785121846077\", \"event_type\":\"price_change\"}","received_at":"2026-07-27T03:10:45.979029Z","schema_version":"clob-market-ws.price_change.v1","sequence":null,"server_hash":null,"server_timestamp":"1785121846077","session_id":"ff6d21c8283948938400a32613abec2c","source":"clob_market_ws"},"received_at":"2026-07-27T03:10:45.979029Z","record_id":"d6021cfce599ceb3a3237e4e24b756ae5fa23b6725688e448073770ebdf87ba6","schema_fingerprint":"4aa3821a28b0b7c2400bc59aba4bcc0a76e971dadd19610d3ad38c768e124dc7","schema_version":"edge-lab-recorder.raw.v1","sequence":null,"source":"clob_market_ws"}
{"event_at":"2026-07-27T03:10:46.098000Z","event_fingerprint":"7118b116bbaff00139fc28c73f1c52d7ee34fb44ca7b62bd8b28e924c991210a","payload":{"connection_id":"f95883f18d264834af91809e5f803e9f","event_at":"2026-07-27T03:10:46.098000Z","event_type":"price_change","frame_hash":"d192c33778ee3fe677d252472ff72b501ef9b56e4fcb9ff4484c198de723c15e","frame_index":0,"kind":"data","monotonic_ns":223829334087791,"payload":{"event_type":"price_change","market":"0xf9d60bb033695053c4d1d8592e52171c1042f64b41a4b72e09dcc6f4852b6670","price_changes":[{"asset_id":"8698449539441374295770236407991735029336433231649246775082939325523552031992","best_ask":"0.22","best_bid":"0.21","hash":"8982c3d1648413009496ff48196def3bda781210","price":"0.15","side":"BUY","size":"217.48"},{"asset_id":"96283536366176669581486355171583722558858323126916278856549586825357358273536","best_ask":"0.79","best_bid":"0.78","hash":"30268fe31fe7b447499bb091ac785415268a3964","price":"0.85","side":"SELL","size":"217.48"}],"timestamp":"1785121846098"},"payload_hash":"553b3f3f18673c0d88c5d48a43c701f8aff45955a3feb10ad55cbb3f8732d0d2","raw_frame":"{\"market\":\"0xf9d60bb033695053c4d1d8592e52171c1042f64b41a4b72e09dcc6f4852b6670\", \"price_changes\":[{\"asset_id\":\"8698449539441374295770236407991735029336433231649246775082939325523552031992\", \"price\":\"0.15\", \"size\":\"217.48\", \"side\":\"BUY\", \"hash\":\"8982c3d1648413009496ff48196def3bda781210\", \"best_bid\":\"0.21\", \"best_ask\":\"0.22\"}, {\"asset_id\":\"96283536366176669581486355171583722558858323126916278856549586825357358273536\", \"price\":\"0.85\", \"size\":\"217.48\", \"side\":\"SELL\", \"hash\":\"30268fe31fe7b447499bb091ac785415268a3964\", \"best_bid\":\"0.78\", \"best_ask\":\"0.79\"}], \"timestamp\":\"1785121846098\", \"event_type\":\"price_change\"}","received_at":"2026-07-27T03:10:46.003982Z","schema_version":"clob-market-ws.price_change.v1","sequence":null,"server_hash":null,"server_timestamp":"1785121846098","session_id":"ff6d21c8283948938400a32613abec2c","source":"clob_market_ws"},"received_at":"2026-07-27T03:10:46.003982Z","record_id":"b804a4385ca9fe958cf1b4c826fcdc1c825f61ad005f6a89cc7a1aa7ed4f02f7","schema_fingerprint":"4aa3821a28b0b7c2400bc59aba4bcc0a76e971dadd19610d3ad38c768e124dc7","schema_version":"edge-lab-recorder.raw.v1","sequence":null,"source":"clob_market_ws"}
{"event_at":"2026-07-27T03:10:46.104000Z","event_fingerprint":"d19cc62aee0296d9770dff5b68fd078d7f5cb1b6a62ad9e0b7dec55098b20290","payload":{"connection_id":"f95883f18d264834af91809e5f803e9f","event_at":"2026-07-27T03:10:46.104000Z","event_type":"price_change","frame_hash":"98440c05135fa72993a2ac7768bdb4b4ddd53b9325520e9ce9b81683024f1fee","frame_index":0,"kind":"data","monotonic_ns":223829338604375,"payload":{"event_type":"price_change","market":"0xf9d60bb033695053c4d1d8592e52171c1042f64b41a4b72e09dcc6f4852b6670","price_changes":[{"asset_id":"96283536366176669581486355171583722558858323126916278856549586825357358273536","best_ask":"0.79","best_bid":"0.78","hash":"a63637b223b934411219adb9b64c65ece10882ff","price":"0.66","side":"BUY","size":"156.29"},{"asset_id":"8698449539441374295770236407991735029336433231649246775082939325523552031992","best_ask":"0.22","best_bid":"0.21","hash":"6f1d0d697b90b2061e277498410a98ec9d389517","price":"0.34","side":"SELL","size":"156.29"}],"timestamp":"1785121846104"},"payload_hash":"748c745cdfe90132f21f636bd0d1ebe186326efcaf71c5717a34119db1dc7d86","raw_frame":"{\"market\":\"0xf9d60bb033695053c4d1d8592e52171c1042f64b41a4b72e09dcc6f4852b6670\", \"price_changes\":[{\"asset_id\":\"96283536366176669581486355171583722558858323126916278856549586825357358273536\", \"price\":\"0.66\", \"size\":\"156.29\", \"side\":\"BUY\", \"hash\":\"a63637b223b934411219adb9b64c65ece10882ff\", \"best_bid\":\"0.78\", \"best_ask\":\"0.79\"}, {\"asset_id\":\"8698449539441374295770236407991735029336433231649246775082939325523552031992\", \"price\":\"0.34\", \"size\":\"156.29\", \"side\":\"SELL\", \"hash\":\"6f1d0d697b90b2061e277498410a98ec9d389517\", \"best_bid\":\"0.21\", \"best_ask\":\"0.22\"}], \"timestamp\":\"1785121846104\", \"event_type\":\"price_change\"}","received_at":"2026-07-27T03:10:46.008499Z","schema_version":"clob-market-ws.price_change.v1","sequence":null,"server_hash":null,"server_timestamp":"1785121846104","session_id":"ff6d21c8283948938400a32613abec2c","source":"clob_market_ws"},"received_at":"2026-07-27T03:10:46.008499Z","record_id":"689553f6e6e904ca5a172e9aedfe1c1206e0cca21cfcd9f561b29b0e9efda526","schema_fingerprint":"4aa3821a28b0b7c2400bc59aba4bcc0a76e971dadd19610d3ad38c768e124dc7","schema_version":"edge-lab-recorder.raw.v1","sequence":null,"source":"clob_market_ws"}
{"event_at":"2026-07-27T03:10:46.121000Z","event_fingerprint":"456fb3e906d79261c3e1ba2dae0bc6eab32568eaade27eb2e7118cdfc9056563","payload":{"connection_id":"f95883f18d264834af91809e5f803e9f","event_at":"2026-07-27T03:10:46.121000Z","event_type":"price_change","frame_hash":"1ea90e63ec42bd8ec09640dad9202a623512ffc434773131d72e6f93a5f4d073","frame_index":0,"kind":"data","monotonic_ns":223829355523125,"payload":{"event_type":"price_change","market":"0xf9d60bb033695053c4d1d8592e52171c1042f64b41a4b72e09dcc6f4852b6670","price_changes":[{"asset_id":"96283536366176669581486355171583722558858323126916278856549586825357358273536","best_ask":"0.79","best_bid":"0.78","hash":"68e1a72e2f1eaceb409c337d68840ce66aa6368c","price":"0.77","side":"BUY","size":"95.1"},{"asset_id":"8698449539441374295770236407991735029336433231649246775082939325523552031992","best_ask":"0.22","best_bid":"0.21","hash":"b60a12d9f30fdc57d3e6913f670ddf8f5ab5c84d","price":"0.23","side":"SELL","size":"95.1"}],"timestamp":"1785121846121"},"payload_hash":"d892ce605e66ebfbf5213411b90e01054fd848f2f65269488f950a1a766f2231","raw_frame":"{\"market\":\"0xf9d60bb033695053c4d1d8592e52171c1042f64b41a4b72e09dcc6f4852b6670\", \"price_changes\":[{\"asset_id\":\"96283536366176669581486355171583722558858323126916278856549586825357358273536\", \"price\":\"0.77\", \"size\":\"95.1\", \"side\":\"BUY\", \"hash\":\"68e1a72e2f1eaceb409c337d68840ce66aa6368c\", \"best_bid\":\"0.78\", \"best_ask\":\"0.79\"}, {\"asset_id\":\"8698449539441374295770236407991735029336433231649246775082939325523552031992\", \"price\":\"0.23\", \"size\":\"95.1\", \"side\":\"SELL\", \"hash\":\"b60a12d9f30fdc57d3e6913f670ddf8f5ab5c84d\", \"best_bid\":\"0.21\", \"best_ask\":\"0.22\"}], \"timestamp\":\"1785121846121\", \"event_type\":\"price_change\"}","received_at":"2026-07-27T03:10:46.025409Z","schema_version":"clob-market-ws.price_change.v1","sequence":null,"server_hash":null,"server_timestamp":"1785121846121","session_id":"ff6d21c8283948938400a32613abec2c","source":"clob_market_ws"},"received_at":"2026-07-27T03:10:46.025409Z","record_id":"63a3a2cbf3a9bf1bd9b247d64eb69a6e8c5ee902730308aaf92d0a2f1e340de2","schema_fingerprint":"4aa3821a28b0b7c2400bc59aba4bcc0a76e971dadd19610d3ad38c768e124dc7","schema_version":"edge-lab-recorder.raw.v1","sequence":null,"source":"clob_market_ws"}
{"event_at":"2026-07-27T03:10:46.122000Z","event_fingerprint":"0c7989ee5e4c8b77f3c959ee32ef8bbccb83387190201bfedec122a99fb87192","payload":{"connection_id":"f95883f18d264834af91809e5f803e9f","event_at":"2026-07-27T03:10:46.122000Z","event_type":"price_change","frame_hash":"60b9e54714275a37a76b8be078d4c03171a1cdc1d218504e73ba529f70fe4562","frame_index":0,"kind":"data","monotonic_ns":223829359085416,"payload":{"event_type":"price_change","market":"0xf9d60bb033695053c4d1d8592e52171c1042f64b41a4b72e09dcc6f4852b6670","price_changes":[{"asset_id":"8698449539441374295770236407991735029336433231649246775082939325523552031992","best_ask":"0.22","best_bid":"0.21","hash":"be5fc4c748ead382d3a5e9039d7f8e841fc4e7e0","price":"0.25","side":"SELL","size":"100"},{"asset_id":"96283536366176669581486355171583722558858323126916278856549586825357358273536","best_ask":"0.79","best_bid":"0.78","hash":"ae21e6ba96c33ce8119c874182950a9382446049","price":"0.75","side":"BUY","size":"100"}],"timestamp":"1785121846122"},"payload_hash":"5b452835aaf74bf6178f30b94a21446736905dda21bb8d670869ccd4d6453ed6","raw_frame":"{\"market\":\"0xf9d60bb033695053c4d1d8592e52171c1042f64b41a4b72e09dcc6f4852b6670\", \"price_changes\":[{\"asset_id\":\"8698449539441374295770236407991735029336433231649246775082939325523552031992\", \"price\":\"0.25\", \"size\":\"100\", \"side\":\"SELL\", \"hash\":\"be5fc4c748ead382d3a5e9039d7f8e841fc4e7e0\", \"best_bid\":\"0.21\", \"best_ask\":\"0.22\"}, {\"asset_id\":\"96283536366176669581486355171583722558858323126916278856549586825357358273536\", \"price\":\"0.75\", \"size\":\"100\", \"side\":\"BUY\", \"hash\":\"ae21e6ba96c33ce8119c874182950a9382446049\", \"best_bid\":\"0.78\", \"best_ask\":\"0.79\"}], \"timestamp\":\"1785121846122\", \"event_type\":\"price_change\"}","received_at":"2026-07-27T03:10:46.028980Z","schema_version":"clob-market-ws.price_change.v1","sequence":null,"server_hash":null,"server_timestamp":"1785121846122","session_id":"ff6d21c8283948938400a32613abec2c","source":"clob_market_ws"},"received_at":"2026-07-27T03:10:46.028980Z","record_id":"114361301bd2a217909922951507d8a9294f8245eaeca5d357decfbea3951098","schema_fingerprint":"4aa3821a28b0b7c2400bc59aba4bcc0a76e971dadd19610d3ad38c768e124dc7","schema_version":"edge-lab-recorder.raw.v1","sequence":null,"source":"clob_market_ws"}
{"event_at":"2026-07-27T03:10:46.122000Z","event_fingerprint":"9802528b6c2463d71e73ad65c1918ac672028f5fa4c26e894b772a3c2e293c1c","payload":{"connection_id":"f95883f18d264834af91809e5f803e9f","event_at":"2026-07-27T03:10:46.122000Z","event_type":"price_change","frame_hash":"99933af9a20925e1110004f667a420790fb68e1b8bcfb581329aabb1357d8382","frame_index":0,"kind":"data","monotonic_ns":223829362389791,"payload":{"event_type":"price_change","market":"0xf9d60bb033695053c4d1d8592e52171c1042f64b41a4b72e09dcc6f4852b6670","price_changes":[{"asset_id":"8698449539441374295770236407991735029336433231649246775082939325523552031992","best_ask":"0.22","best_bid":"0.21","hash":"be5fc4c748ead382d3a5e9039d7f8e841fc4e7e0","price":"0.24","side":"SELL","size":"110"},{"asset_id":"96283536366176669581486355171583722558858323126916278856549586825357358273536","best_ask":"0.79","best_bid":"0.78","hash":"ae21e6ba96c33ce8119c874182950a9382446049","price":"0.76","side":"BUY","size":"110"}],"timestamp":"1785121846122"},"payload_hash":"f989901a975c6537e3735dade3a03bf81cd686682ba7bc854b7288be88bfa36e","raw_frame":"{\"market\":\"0xf9d60bb033695053c4d1d8592e52171c1042f64b41a4b72e09dcc6f4852b6670\", \"price_changes\":[{\"asset_id\":\"8698449539441374295770236407991735029336433231649246775082939325523552031992\", \"price\":\"0.24\", \"size\":\"110\", \"side\":\"SELL\", \"hash\":\"be5fc4c748ead382d3a5e9039d7f8e841fc4e7e0\", \"best_bid\":\"0.21\", \"best_ask\":\"0.22\"}, {\"asset_id\":\"96283536366176669581486355171583722558858323126916278856549586825357358273536\", \"price\":\"0.76\", \"size\":\"110\", \"side\":\"BUY\", \"hash\":\"ae21e6ba96c33ce8119c874182950a9382446049\", \"best_bid\":\"0.78\", \"best_ask\":\"0.79\"}], \"timestamp\":\"1785121846122\", \"event_type\":\"price_change\"}","received_at":"2026-07-27T03:10:46.032285Z","schema_version":"clob-market-ws.price_change.v1","sequence":null,"server_hash":null,"server_timestamp":"1785121846122","session_id":"ff6d21c8283948938400a32613abec2c","source":"clob_market_ws"},"received_at":"2026-07-27T03:10:46.032285Z","record_id":"ad68bff0f88ea7e98ac2e29bec6e2e165e0c1a0397627ef4aa18d32003316339","schema_fingerprint":"4aa3821a28b0b7c2400bc59aba4bcc0a76e971dadd19610d3ad38c768e124dc7","schema_version":"edge-lab-recorder.raw.v1","sequence":null,"source":"clob_market_ws"}
{"event_at":"2026-07-27T03:10:46.126000Z","event_fingerprint":"50e3bee837230fc7417f89c3d9bd77c91437e96f54d2b4be0dfd64ce7315ab11","payload":{"connection_id":"f95883f18d264834af91809e5f803e9f","event_at":"2026-07-27T03:10:46.126000Z","event_type":"price_change","frame_hash":"5def7206780dfe10d5319879c3e93ac83763296ebe41e8dc9fe924783922fac6","frame_index":0,"kind":"data","monotonic_ns":223829364790625,"payload":{"event_type":"price_change","market":"0xf9d60bb033695053c4d1d8592e52171c1042f64b41a4b72e09dcc6f4852b6670","price_changes":[{"asset_id":"96283536366176669581486355171583722558858323126916278856549586825357358273536","best_ask":"0.79","best_bid":"0.78","hash":"0c46d0573b88e4c32f746557d609c5c8d2c33368","price":"0.02","side":"BUY","size":"2323.79"},{"asset_id":"8698449539441374295770236407991735029336433231649246775082939325523552031992","best_ask":"0.22","best_bid":"0.21","hash":"eb5b26c65746a20935db899f4934c7ffbb66c481","price":"0.98","side":"SELL","size":"2323.79"}],"timestamp":"1785121846126"},"payload_hash":"24041973540a4a7a5db61dc7fdc27e5ea64dacb6054d1ff8aae52f7118594d47","raw_frame":"{\"market\":\"0xf9d60bb033695053c4d1d8592e52171c1042f64b41a4b72e09dcc6f4852b6670\", \"price_changes\":[{\"asset_id\":\"96283536366176669581486355171583722558858323126916278856549586825357358273536\", \"price\":\"0.02\", \"size\":\"2323.79\", \"side\":\"BUY\", \"hash\":\"0c46d0573b88e4c32f746557d609c5c8d2c33368\", \"best_bid\":\"0.78\", \"best_ask\":\"0.79\"}, {\"asset_id\":\"8698449539441374295770236407991735029336433231649246775082939325523552031992\", \"price\":\"0.98\", \"size\":\"2323.79\", \"side\":\"SELL\", \"hash\":\"eb5b26c65746a20935db899f4934c7ffbb66c481\", \"best_bid\":\"0.21\", \"best_ask\":\"0.22\"}], \"timestamp\":\"1785121846126\", \"event_type\":\"price_change\"}","received_at":"2026-07-27T03:10:46.034692Z","schema_version":"clob-market-ws.price_change.v1","sequence":null,"server_hash":null,"server_timestamp":"1785121846126","session_id":"ff6d21c8283948938400a32613abec2c","source":"clob_market_ws"},"received_at":"2026-07-27T03:10:46.034692Z","record_id":"2703f9f68be3eae12ba6150b1676984830637a50ee2d91d7bef64ff0ab561ee8","schema_fingerprint":"4aa3821a28b0b7c2400bc59aba4bcc0a76e971dadd19610d3ad38c768e124dc7","schema_version":"edge-lab-recorder.raw.v1","sequence":null,"source":"clob_market_ws"}
{"event_at":"2026-07-27T03:10:46.135000Z","event_fingerprint":"2a7a7e06b13eccb46512fb0ec707a22decbb4f4eab36b099b530917a036a6380","payload":{"connection_id":"f95883f18d264834af91809e5f803e9f","event_at":"2026-07-27T03:10:46.135000Z","event_type":"price_change","frame_hash":"f44ad275e17c85080588e77c576291f9be9ff3dac6860101a9ece55fa09d3513","frame_index":0,"kind":"data","monotonic_ns":223829368717041,"payload":{"event_type":"price_change","market":"0xf9d60bb033695053c4d1d8592e52171c1042f64b41a4b72e09dcc6f4852b6670","price_changes":[{"asset_id":"8698449539441374295770236407991735029336433231649246775082939325523552031992","best_ask":"0.22","best_bid":"0.21","hash":"f5cf7b2a4bff3dbd47658a07cd1be6dc96c651a0","price":"0.01","side":"BUY","size":"6834.52"},{"asset_id":"96283536366176669581486355171583722558858323126916278856549586825357358273536","best_ask":"0.79","best_bid":"0.78","hash":"ac9e3c8701b9f42b11a47dda0e37c7a972313f93","price":"0.99","side":"SELL","size":"6834.52"}],"timestamp":"1785121846135"},"payload_hash":"b9c0dbd2f98cea7a76cd7e3016230cc7c6eb007a4a87006593408d1f353507ae","raw_frame":"{\"market\":\"0xf9d60bb033695053c4d1d8592e52171c1042f64b41a4b72e09dcc6f4852b6670\", \"price_changes\":[{\"asset_id\":\"8698449539441374295770236407991735029336433231649246775082939325523552031992\", \"price\":\"0.01\", \"size\":\"6834.52\", \"side\":\"BUY\", \"hash\":\"f5cf7b2a4bff3dbd47658a07cd1be6dc96c651a0\", \"best_bid\":\"0.21\", \"best_ask\":\"0.22\"}, {\"asset_id\":\"96283536366176669581486355171583722558858323126916278856549586825357358273536\", \"price\":\"0.99\", \"size\":\"6834.52\", \"side\":\"SELL\", \"hash\":\"ac9e3c8701b9f42b11a47dda0e37c7a972313f93\", \"best_bid\":\"0.78\", \"best_ask\":\"0.79\"}], \"timestamp\":\"1785121846135\", \"event_type\":\"price_change\"}","received_at":"2026-07-27T03:10:46.038612Z","schema_version":"clob-market-ws.price_change.v1","sequence":null,"server_hash":null,"server_timestamp":"1785121846135","session_id":"ff6d21c8283948938400a32613abec2c","source":"clob_market_ws"},"received_at":"2026-07-27T03:10:46.038612Z","record_id":"b57bbcead66b19bbd66aefd018de6a8e284188727fe6ddb6e43bcc7232ffeafb","schema_fingerprint":"4aa3821a28b0b7c2400bc59aba4bcc0a76e971dadd19610d3ad38c768e124dc7","schema_version":"edge-lab-recorder.raw.v1","sequence":null,"source":"clob_market_ws"}
{"event_at":"2026-07-27T03:10:46.139000Z","event_fingerprint":"ac59a90b85c1a21047a621500edf51bfa57b3fff102417fe61b9a7020f5d8768","payload":{"connection_id":"f95883f18d264834af91809e5f803e9f","event_at":"2026-07-27T03:10:46.139000Z","event_type":"price_change","frame_hash":"77ba069f40bba2b1c2f53bb4a9dd1d1c654a19ff53b15f9ebd2b8171546f9258","frame_index":0,"kind":"data","monotonic_ns":223829372213708,"payload":{"event_type":"price_change","market":"0xf9d60bb033695053c4d1d8592e52171c1042f64b41a4b72e09dcc6f4852b6670","price_changes":[{"asset_id":"96283536366176669581486355171583722558858323126916278856549586825357358273536","best_ask":"0.79","best_bid":"0.78","hash":"e1fa7f65904fcb1e4f4e51242f6c51c33a69e393","price":"0.66","side":"BUY","size":"151.29"},{"asset_id":"8698449539441374295770236407991735029336433231649246775082939325523552031992","best_ask":"0.22","best_bid":"0.21","hash":"8299c6db9d28baf6645ebbb685838eadcc58f59b","price":"0.34","side":"SELL","size":"151.29"}],"timestamp":"1785121846139"},"payload_hash":"0cbf87c9c685d6b7243a6d36bbd788f0bdd2ae450d22db15cc0bc3086957cfc1","raw_frame":"{\"market\":\"0xf9d60bb033695053c4d1d8592e52171c1042f64b41a4b72e09dcc6f4852b6670\", \"price_changes\":[{\"asset_id\":\"96283536366176669581486355171583722558858323126916278856549586825357358273536\", \"price\":\"0.66\", \"size\":\"151.29\", \"side\":\"BUY\", \"hash\":\"e1fa7f65904fcb1e4f4e51242f6c51c33a69e393\", \"best_bid\":\"0.78\", \"best_ask\":\"0.79\"}, {\"asset_id\":\"8698449539441374295770236407991735029336433231649246775082939325523552031992\", \"price\":\"0.34\", \"size\":\"151.29\", \"side\":\"SELL\", \"hash\":\"8299c6db9d28baf6645ebbb685838eadcc58f59b\", \"best_bid\":\"0.21\", \"best_ask\":\"0.22\"}], \"timestamp\":\"1785121846139\", \"event_type\":\"price_change\"}","received_at":"2026-07-27T03:10:46.042109Z","schema_version":"clob-market-ws.price_change.v1","sequence":null,"server_hash":null,"server_timestamp":"1785121846139","session_id":"ff6d21c8283948938400a32613abec2c","source":"clob_market_ws"},"received_at":"2026-07-27T03:10:46.042109Z","record_id":"993607158064622f761d8f81c63819e3c99382709bbb4a1232d4e34bc5b89e4e","schema_fingerprint":"4aa3821a28b0b7c2400bc59aba4bcc0a76e971dadd19610d3ad38c768e124dc7","schema_version":"edge-lab-recorder.raw.v1","sequence":null,"source":"clob_market_ws"}
{"event_at":"2026-07-27T03:10:46.148000Z","event_fingerprint":"f2e51b45cd9a6934f4188c37742cdb3a323328e02ae69609e6abe0e5960c33b6","payload":{"connection_id":"f95883f18d264834af91809e5f803e9f","event_at":"2026-07-27T03:10:46.148000Z","event_type":"price_change","frame_hash":"7433aa5e459773b4a25844b7fe12b450f67c0ff6798321d31e1ccd6694603a34","frame_index":0,"kind":"data","monotonic_ns":223829380497375,"payload":{"event_type":"price_change","market":"0xf9d60bb033695053c4d1d8592e52171c1042f64b41a4b72e09dcc6f4852b6670","price_changes":[{"asset_id":"96283536366176669581486355171583722558858323126916278856549586825357358273536","best_ask":"0.79","best_bid":"0.78","hash":"204f09c4e3575827eb4c8a34d73f59c53d7bf6d6","price":"0.78","side":"BUY","size":"127.1"},{"asset_id":"8698449539441374295770236407991735029336433231649246775082939325523552031992","best_ask":"0.22","best_bid":"0.21","hash":"ea8240ce2035d34cdbec0352e1e6f6fd71f127cb","price":"0.22","side":"SELL","size":"127.1"}],"timestamp":"1785121846148"},"payload_hash":"34530110c74b4612228e2384312086f153df7b5488e4efffb3fefb6f9979b948","raw_frame":"{\"market\":\"0xf9d60bb033695053c4d1d8592e52171c1042f64b41a4b72e09dcc6f4852b6670\", \"price_changes\":[{\"asset_id\":\"96283536366176669581486355171583722558858323126916278856549586825357358273536\", \"price\":\"0.78\", \"size\":\"127.1\", \"side\":\"BUY\", \"hash\":\"204f09c4e3575827eb4c8a34d73f59c53d7bf6d6\", \"best_bid\":\"0.78\", \"best_ask\":\"0.79\"}, {\"asset_id\":\"8698449539441374295770236407991735029336433231649246775082939325523552031992\", \"price\":\"0.22\", \"size\":\"127.1\", \"side\":\"SELL\", \"hash\":\"ea8240ce2035d34cdbec0352e1e6f6fd71f127cb\", \"best_bid\":\"0.21\", \"best_ask\":\"0.22\"}], \"timestamp\":\"1785121846148\", \"event_type\":\"price_change\"}","received_at":"2026-07-27T03:10:46.050399Z","schema_version":"clob-market-ws.price_change.v1","sequence":null,"server_hash":null,"server_timestamp":"1785121846148","session_id":"ff6d21c8283948938400a32613abec2c","source":"clob_market_ws"},"received_at":"2026-07-27T03:10:46.050399Z","record_id":"e1de8608d80c6e851cda1c7de24a38930345eb844e3431cfbbd9aac4cd41d8d4","schema_fingerprint":"4aa3821a28b0b7c2400bc59aba4bcc0a76e971dadd19610d3ad38c768e124dc7","schema_version":"edge-lab-recorder.raw.v1","sequence":null,"source":"clob_market_ws"}
{"event_at":"2026-07-27T03:10:46.165000Z","event_fingerprint":"b77bf83a5c1cf08e4f38f81afc9d0a2f2962011ffddfbf90f7e66bdd8c353a7e","payload":{"connection_id":"f95883f18d264834af91809e5f803e9f","event_at":"2026-07-27T03:10:46.165000Z","event_type":"price_change","frame_hash":"f7210525d743e97f4a236c4e543273958ab5499797f8b08910206cab74637862","frame_index":0,"kind":"data","monotonic_ns":223829398248083,"payload":{"event_type":"price_change","market":"0xf9d60bb033695053c4d1d8592e52171c1042f64b41a4b72e09dcc6f4852b6670","price_changes":[{"asset_id":"96283536366176669581486355171583722558858323126916278856549586825357358273536","best_ask":"0.79","best_bid":"0.78","hash":"532cc1e34dd07184f2866beba4af1e6cc243b761","price":"0.78","side":"BUY","size":"132.1"},{"asset_id":"8698449539441374295770236407991735029336433231649246775082939325523552031992","best_ask":"0.22","best_bid":"0.21","hash":"e8c1b8194e189dba7b506c966cf274ae408100a3","price":"0.22","side":"SELL","size":"132.1"}],"timestamp":"1785121846165"},"payload_hash":"d21c50bdc078d89ba226eb93dd0ff4b9f40b979d42e791cdff7855319cf85e6b","raw_frame":"{\"market\":\"0xf9d60bb033695053c4d1d8592e52171c1042f64b41a4b72e09dcc6f4852b6670\", \"price_changes\":[{\"asset_id\":\"96283536366176669581486355171583722558858323126916278856549586825357358273536\", \"price\":\"0.78\", \"size\":\"132.1\", \"side\":\"BUY\", \"hash\":\"532cc1e34dd07184f2866beba4af1e6cc243b761\", \"best_bid\":\"0.78\", \"best_ask\":\"0.79\"}, {\"asset_id\":\"8698449539441374295770236407991735029336433231649246775082939325523552031992\", \"price\":\"0.22\", \"size\":\"132.1\", \"side\":\"SELL\", \"hash\":\"e8c1b8194e189dba7b506c966cf274ae408100a3\", \"best_bid\":\"0.21\", \"best_ask\":\"0.22\"}], \"timestamp\":\"1785121846165\", \"event_type\":\"price_change\"}","received_at":"2026-07-27T03:10:46.068149Z","schema_version":"clob-market-ws.price_change.v1","sequence":null,"server_hash":null,"server_timestamp":"1785121846165","session_id":"ff6d21c8283948938400a32613abec2c","source":"clob_market_ws"},"received_at":"2026-07-27T03:10:46.068149Z","record_id":"e02c338bc8808e2e12086d271428718f53e4029e1450187332e1b54ea99930a2","schema_fingerprint":"4aa3821a28b0b7c2400bc59aba4bcc0a76e971dadd19610d3ad38c768e124dc7","schema_version":"edge-lab-recorder.raw.v1","sequence":null,"source":"clob_market_ws"}
{"event_at":"2026-07-27T03:10:46.166000Z","event_fingerprint":"53cefe11f03336fd7864c266f8e2f284393f78c7386bad1040b3d32700d894d2","payload":{"connection_id":"f95883f18d264834af91809e5f803e9f","event_at":"2026-07-27T03:10:46.166000Z","event_type":"price_change","frame_hash":"91bbc401f65873d811e089f67d00e66017dca6f3fdfb20f7cd4abc5971b037ef","frame_index":0,"kind":"data","monotonic_ns":223829400921083,"payload":{"event_type":"price_change","market":"0xf9d60bb033695053c4d1d8592e52171c1042f64b41a4b72e09dcc6f4852b6670","price_changes":[{"asset_id":"8698449539441374295770236407991735029336433231649246775082939325523552031992","best_ask":"0.22","best_bid":"0.21","hash":"41c5cd215fe8e82ba7753662f088ee8a7a0bd7fc","price":"0.34","side":"SELL","size":"156.29"},{"asset_id":"96283536366176669581486355171583722558858323126916278856549586825357358273536","best_ask":"0.79","best_bid":"0.78","hash":"54405c18f3e43c425e0176425093b6f6bbd1eb31","price":"0.66","side":"BUY","size":"156.29"}],"timestamp":"1785121846166"},"payload_hash":"f4b911736ee6afac2bb3d9dfa390354058481eafa7ded4a914dc7313c47ccbed","raw_frame":"{\"market\":\"0xf9d60bb033695053c4d1d8592e52171c1042f64b41a4b72e09dcc6f4852b6670\", \"price_changes\":[{\"asset_id\":\"8698449539441374295770236407991735029336433231649246775082939325523552031992\", \"price\":\"0.34\", \"size\":\"156.29\", \"side\":\"SELL\", \"hash\":\"41c5cd215fe8e82ba7753662f088ee8a7a0bd7fc\", \"best_bid\":\"0.21\", \"best_ask\":\"0.22\"}, {\"asset_id\":\"96283536366176669581486355171583722558858323126916278856549586825357358273536\", \"price\":\"0.66\", \"size\":\"156.29\", \"side\":\"BUY\", \"hash\":\"54405c18f3e43c425e0176425093b6f6bbd1eb31\", \"best_bid\":\"0.78\", \"best_ask\":\"0.79\"}], \"timestamp\":\"1785121846166\", \"event_type\":\"price_change\"}","received_at":"2026-07-27T03:10:46.070813Z","schema_version":"clob-market-ws.price_change.v1","sequence":null,"server_hash":null,"server_timestamp":"1785121846166","session_id":"ff6d21c8283948938400a32613abec2c","source":"clob_market_ws"},"received_at":"2026-07-27T03:10:46.070813Z","record_id":"8b719241b557f6de8ea66c1e5f52ba64500a41d62bba89beb1d66f2090213c3a","schema_fingerprint":"4aa3821a28b0b7c2400bc59aba4bcc0a76e971dadd19610d3ad38c768e124dc7","schema_version":"edge-lab-recorder.raw.v1","sequence":null,"source":"clob_market_ws"}
{"event_at":"2026-07-27T03:10:46.167000Z","event_fingerprint":"1856027a926b0e529aaf0bac25bd6cc47b5b3b69f8f000ff5f8ba99df00813fd","payload":{"connection_id":"f95883f18d264834af91809e5f803e9f","event_at":"2026-07-27T03:10:46.167000Z","event_type":"price_change","frame_hash":"5c7a6764666a883c5d89c0ed3bec15daf9a42d809eb8dcf8fcd912a031555cd6","frame_index":0,"kind":"data","monotonic_ns":223829404046458,"payload":{"event_type":"price_change","market":"0xf9d60bb033695053c4d1d8592e52171c1042f64b41a4b72e09dcc6f4852b6670","price_changes":[{"asset_id":"96283536366176669581486355171583722558858323126916278856549586825357358273536","best_ask":"0.79","best_bid":"0.78","hash":"b08882e13d71afd6753f1870d828e5d390071d7a","price":"0.72","side":"BUY","size":"114.8"},{"asset_id":"8698449539441374295770236407991735029336433231649246775082939325523552031992","best_ask":"0.22","best_bid":"0.21","hash":"876b76110a4fe6dd54b6e0a8239c4c0c3913cfa8","price":"0.28","side":"SELL","size":"114.8"}],"timestamp":"1785121846167"},"payload_hash":"3a6a4d6287d349531f5c68b36f56c6862487c9453b6c46607a2e374b71bad1ea","raw_frame":"{\"market\":\"0xf9d60bb033695053c4d1d8592e52171c1042f64b41a4b72e09dcc6f4852b6670\", \"price_changes\":[{\"asset_id\":\"96283536366176669581486355171583722558858323126916278856549586825357358273536\", \"price\":\"0.72\", \"size\":\"114.8\", \"side\":\"BUY\", \"hash\":\"b08882e13d71afd6753f1870d828e5d390071d7a\", \"best_bid\":\"0.78\", \"best_ask\":\"0.79\"}, {\"asset_id\":\"8698449539441374295770236407991735029336433231649246775082939325523552031992\", \"price\":\"0.28\", \"size\":\"114.8\", \"side\":\"SELL\", \"hash\":\"876b76110a4fe6dd54b6e0a8239c4c0c3913cfa8\", \"best_bid\":\"0.21\", \"best_ask\":\"0.22\"}], \"timestamp\":\"1785121846167\", \"event_type\":\"price_change\"}","received_at":"2026-07-27T03:10:46.073941Z","schema_version":"clob-market-ws.price_change.v1","sequence":null,"server_hash":null,"server_timestamp":"1785121846167","session_id":"ff6d21c8283948938400a32613abec2c","source":"clob_market_ws"},"received_at":"2026-07-27T03:10:46.073941Z","record_id":"e2c70e77e8c234ddfaa4325c80714c361863bff730843c73306f2fe1ef8cd158","schema_fingerprint":"4aa3821a28b0b7c2400bc59aba4bcc0a76e971dadd19610d3ad38c768e124dc7","schema_version":"edge-lab-recorder.raw.v1","sequence":null,"source":"clob_market_ws"}
{"event_at":"2026-07-27T03:10:46.168000Z","event_fingerprint":"57d9b598a5c1dc14c55838f641bfd8a9547909c12157213e4c579cfbaf00a796","payload":{"connection_id":"f95883f18d264834af91809e5f803e9f","event_at":"2026-07-27T03:10:46.168000Z","event_type":"price_change","frame_hash":"d7843ff9d31dfa80711acb0600c110115978126c9fa6bf3061c0f875a7490436","frame_index":0,"kind":"data","monotonic_ns":223829415969500,"payload":{"event_type":"price_change","market":"0xf9d60bb033695053c4d1d8592e52171c1042f64b41a4b72e09dcc6f4852b6670","price_changes":[{"asset_id":"96283536366176669581486355171583722558858323126916278856549586825357358273536","best_ask":"0.79","best_bid":"0.78","hash":"cbde8f3dfbc0e4e1d7c5e7993eb3eac789c0562c","price":"0.77","side":"BUY","size":"100.1"},{"asset_id":"8698449539441374295770236407991735029336433231649246775082939325523552031992","best_ask":"0.22","best_bid":"0.21","hash":"b5672ee49a9197715ef63c88b8515a46ac3e5787","price":"0.23","side":"SELL","size":"100.1"}],"timestamp":"1785121846168"},"payload_hash":"22e795804040d75f00a1d413c4412c95d335ede3ebbb9953b2f514309403c0d0","raw_frame":"{\"market\":\"0xf9d60bb033695053c4d1d8592e52171c1042f64b41a4b72e09dcc6f4852b6670\", \"price_changes\":[{\"asset_id\":\"96283536366176669581486355171583722558858323126916278856549586825357358273536\", \"price\":\"0.77\", \"size\":\"100.1\", \"side\":\"BUY\", \"hash\":\"cbde8f3dfbc0e4e1d7c5e7993eb3eac789c0562c\", \"best_bid\":\"0.78\", \"best_ask\":\"0.79\"}, {\"asset_id\":\"8698449539441374295770236407991735029336433231649246775082939325523552031992\", \"price\":\"0.23\", \"size\":\"100.1\", \"side\":\"SELL\", \"hash\":\"b5672ee49a9197715ef63c88b8515a46ac3e5787\", \"best_bid\":\"0.21\", \"best_ask\":\"0.22\"}], \"timestamp\":\"1785121846168\", \"event_type\":\"price_change\"}","received_at":"2026-07-27T03:10:46.085863Z","schema_version":"clob-market-ws.price_change.v1","sequence":null,"server_hash":null,"server_timestamp":"1785121846168","session_id":"ff6d21c8283948938400a32613abec2c","source":"clob_market_ws"},"received_at":"2026-07-27T03:10:46.085863Z","record_id":"28b23349574b9efb3e761ebd17033e1b603ea8be69d5f93fe9f1a316e2bbb85d","schema_fingerprint":"4aa3821a28b0b7c2400bc59aba4bcc0a76e971dadd19610d3ad38c768e124dc7","schema_version":"edge-lab-recorder.raw.v1","sequence":null,"source":"clob_market_ws"}
{"event_at":"2026-07-27T03:10:46.184000Z","event_fingerprint":"a6a81a9c582ef90fc21232a85d618073091385e52953bd382dbba7cd1e4f54aa","payload":{"connection_id":"f95883f18d264834af91809e5f803e9f","event_at":"2026-07-27T03:10:46.184000Z","event_type":"price_change","frame_hash":"8e5968bfbcd4bfbcc19687c9448f069bd5afd1695436dd94bf855e01adbb8136","frame_index":0,"kind":"data","monotonic_ns":223829419082250,"payload":{"event_type":"price_change","market":"0xf9d60bb033695053c4d1d8592e52171c1042f64b41a4b72e09dcc6f4852b6670","price_changes":[{"asset_id":"96283536366176669581486355171583722558858323126916278856549586825357358273536","best_ask":"0.79","best_bid":"0.78","hash":"ac019bd9fcb274d5de208d41f0c0d4fcf5addf45","price":"0.01","side":"BUY","size":"6924.52"},{"asset_id":"8698449539441374295770236407991735029336433231649246775082939325523552031992","best_ask":"0.22","best_bid":"0.21","hash":"f4085fa2294f16a0e2f383bc1d29f4eb59d49aa8","price":"0.99","side":"SELL","size":"6924.52"}],"timestamp":"1785121846184"},"payload_hash":"32193233b7243f818b46dd3d2dffe4479f1ca670041e83da12b318d02879f06a","raw_frame":"{\"market\":\"0xf9d60bb033695053c4d1d8592e52171c1042f64b41a4b72e09dcc6f4852b6670\", \"price_changes\":[{\"asset_id\":\"96283536366176669581486355171583722558858323126916278856549586825357358273536\", \"price\":\"0.01\", \"size\":\"6924.52\", \"side\":\"BUY\", \"hash\":\"ac019bd9fcb274d5de208d41f0c0d4fcf5addf45\", \"best_bid\":\"0.78\", \"best_ask\":\"0.79\"}, {\"asset_id\":\"8698449539441374295770236407991735029336433231649246775082939325523552031992\", \"price\":\"0.99\", \"size\":\"6924.52\", \"side\":\"SELL\", \"hash\":\"f4085fa2294f16a0e2f383bc1d29f4eb59d49aa8\", \"best_bid\":\"0.21\", \"best_ask\":\"0.22\"}], \"timestamp\":\"1785121846184\", \"event_type\":\"price_change\"}","received_at":"2026-07-27T03:10:46.088976Z","schema_version":"clob-market-ws.price_change.v1","sequence":null,"server_hash":null,"server_timestamp":"1785121846184","session_id":"ff6d21c8283948938400a32613abec2c","source":"clob_market_ws"},"received_at":"2026-07-27T03:10:46.088976Z","record_id":"8e37381bf1cb891669b8e4ed98e9dbed1b58e5c230d385d8415468f9c7aded17","schema_fingerprint":"4aa3821a28b0b7c2400bc59aba4bcc0a76e971dadd19610d3ad38c768e124dc7","schema_version":"edge-lab-recorder.raw.v1","sequence":null,"source":"clob_market_ws"}
{"event_at":"2026-07-27T03:10:46.184000Z","event_fingerprint":"056c3b0b0e1873d14e961ac7119357f8fb3d72228b7fdfe68b1fd05293b9b318","payload":{"connection_id":"f95883f18d264834af91809e5f803e9f","event_at":"2026-07-27T03:10:46.184000Z","event_type":"price_change","frame_hash":"a16db88f65b7c89b701743c5b2cda853db47be603557acc8481089762cbc4763","frame_index":0,"kind":"data","monotonic_ns":223829422165083,"payload":{"event_type":"price_change","market":"0xf9d60bb033695053c4d1d8592e52171c1042f64b41a4b72e09dcc6f4852b6670","price_changes":[{"asset_id":"96283536366176669581486355171583722558858323126916278856549586825357358273536","best_ask":"0.79","best_bid":"0.78","hash":"cbdc27bb381dc7a298809cb222539d219f19a486","price":"0.72","side":"BUY","size":"109.8"},{"asset_id":"8698449539441374295770236407991735029336433231649246775082939325523552031992","best_ask":"0.22","best_bid":"0.21","hash":"39c7d5bfec47515e097a1632a88f5d74b9ea0d0d","price":"0.28","side":"SELL","size":"109.8"}],"timestamp":"1785121846184"},"payload_hash":"4865e107c2215c490b823612e65cb73d7e2dc31d715af7745c4031f4dc2dcb9b","raw_frame":"{\"market\":\"0xf9d60bb033695053c4d1d8592e52171c1042f64b41a4b72e09dcc6f4852b6670\", \"price_changes\":[{\"asset_id\":\"96283536366176669581486355171583722558858323126916278856549586825357358273536\", \"price\":\"0.72\", \"size\":\"109.8\", \"side\":\"BUY\", \"hash\":\"cbdc27bb381dc7a298809cb222539d219f19a486\", \"best_bid\":\"0.78\", \"best_ask\":\"0.79\"}, {\"asset_id\":\"8698449539441374295770236407991735029336433231649246775082939325523552031992\", \"price\":\"0.28\", \"size\":\"109.8\", \"side\":\"SELL\", \"hash\":\"39c7d5bfec47515e097a1632a88f5d74b9ea0d0d\", \"best_bid\":\"0.21\", \"best_ask\":\"0.22\"}], \"timestamp\":\"1785121846184\", \"event_type\":\"price_change\"}","received_at":"2026-07-27T03:10:46.092061Z","schema_version":"clob-market-ws.price_change.v1","sequence":null,"server_hash":null,"server_timestamp":"1785121846184","session_id":"ff6d21c8283948938400a32613abec2c","source":"clob_market_ws"},"received_at":"2026-07-27T03:10:46.092061Z","record_id":"e25af3758fdbd990ea6312581e70e448e06711258ac1bd28908433ca44c007ff","schema_fingerprint":"4aa3821a28b0b7c2400bc59aba4bcc0a76e971dadd19610d3ad38c768e124dc7","schema_version":"edge-lab-recorder.raw.v1","sequence":null,"source":"clob_market_ws"}
{"event_at":"2026-07-27T03:10:46.184000Z","event_fingerprint":"fc7c50171a0fa8b0508bb2badd31d1b36e981656a5d27df5810a7f85d4d30ba3","payload":{"connection_id":"f95883f18d264834af91809e5f803e9f","event_at":"2026-07-27T03:10:46.184000Z","event_type":"price_change","frame_hash":"b49af798e37562f3058b6098e5a8b64c55a5ba266c504d98cc595f8715350e1d","frame_index":0,"kind":"data","monotonic_ns":223829425147416,"payload":{"event_type":"price_change","market":"0xf9d60bb033695053c4d1d8592e52171c1042f64b41a4b72e09dcc6f4852b6670","price_changes":[{"asset_id":"96283536366176669581486355171583722558858323126916278856549586825357358273536","best_ask":"0.79","best_bid":"0.78","hash":"cbdc27bb381dc7a298809cb222539d219f19a486","price":"0.78","side":"BUY","size":"127.1"},{"asset_id":"8698449539441374295770236407991735029336433231649246775082939325523552031992","best_ask":"0.22","best_bid":"0.21","hash":"39c7d5bfec47515e097a1632a88f5d74b9ea0d0d","price":"0.22","side":"SELL","size":"127.1"}],"timestamp":"1785121846184"},"payload_hash":"22a8e3f148c1265160a1c852011d2d49e2624a60285490147226c86a07497163","raw_frame":"{\"market\":\"0xf9d60bb033695053c4d1d8592e52171c1042f64b41a4b72e09dcc6f4852b6670\", \"price_changes\":[{\"asset_id\":\"96283536366176669581486355171583722558858323126916278856549586825357358273536\", \"price\":\"0.78\", \"size\":\"127.1\", \"side\":\"BUY\", \"hash\":\"cbdc27bb381dc7a298809cb222539d219f19a486\", \"best_bid\":\"0.78\", \"best_ask\":\"0.79\"}, {\"asset_id\":\"8698449539441374295770236407991735029336433231649246775082939325523552031992\", \"price\":\"0.22\", \"size\":\"127.1\", \"side\":\"SELL\", \"hash\":\"39c7d5bfec47515e097a1632a88f5d74b9ea0d0d\", \"best_bid\":\"0.21\", \"best_ask\":\"0.22\"}], \"timestamp\":\"1785121846184\", \"event_type\":\"price_change\"}","received_at":"2026-07-27T03:10:46.095041Z","schema_version":"clob-market-ws.price_change.v1","sequence":null,"server_hash":null,"server_timestamp":"1785121846184","session_id":"ff6d21c8283948938400a32613abec2c","source":"clob_market_ws"},"received_at":"2026-07-27T03:10:46.095041Z","record_id":"90dfd7ede1108328d000f50e5cd5ef67676487f032a184f298c3b1b806fc86ae","schema_fingerprint":"4aa3821a28b0b7c2400bc59aba4bcc0a76e971dadd19610d3ad38c768e124dc7","schema_version":"edge-lab-recorder.raw.v1","sequence":null,"source":"clob_market_ws"}
{"event_at":"2026-07-27T03:10:46.185000Z","event_fingerprint":"cc48c43fc914a0a634fc23260574cf6de8bf11877563fb8ea79668934922c915","payload":{"connection_id":"f95883f18d264834af91809e5f803e9f","event_at":"2026-07-27T03:10:46.185000Z","event_type":"price_change","frame_hash":"6f6c76c7505283e2ec370399f4baa9344b596c4a53c0fca561828e5fd71e8cfc","frame_index":0,"kind":"data","monotonic_ns":223829427460375,"payload":{"event_type":"price_change","market":"0xf9d60bb033695053c4d1d8592e52171c1042f64b41a4b72e09dcc6f4852b6670","price_changes":[{"asset_id":"96283536366176669581486355171583722558858323126916278856549586825357358273536","best_ask":"0.79","best_bid":"0.78","hash":"afab972744eeec69ddd51c8520ed48054bbfb1ee","price":"0.77","side":"BUY","size":"105.1"},{"asset_id":"8698449539441374295770236407991735029336433231649246775082939325523552031992","best_ask":"0.22","best_bid":"0.21","hash":"828ebc874d339637ffdc3a80bb0aa96316460352","price":"0.23","side":"SELL","size":"105.1"}],"timestamp":"1785121846185"},"payload_hash":"3e45d6f4b455e0df84704817f67978658757a3e51c09f42415b8f52f86c51383","raw_frame":"{\"market\":\"0xf9d60bb033695053c4d1d8592e52171c1042f64b41a4b72e09dcc6f4852b6670\", \"price_changes\":[{\"asset_id\":\"96283536366176669581486355171583722558858323126916278856549586825357358273536\", \"price\":\"0.77\", \"size\":\"105.1\", \"side\":\"BUY\", \"hash\":\"afab972744eeec69ddd51c8520ed48054bbfb1ee\", \"best_bid\":\"0.78\", \"best_ask\":\"0.79\"}, {\"asset_id\":\"8698449539441374295770236407991735029336433231649246775082939325523552031992\", \"price\":\"0.23\", \"size\":\"105.1\", \"side\":\"SELL\", \"hash\":\"828ebc874d339637ffdc3a80bb0aa96316460352\", \"best_bid\":\"0.21\", \"best_ask\":\"0.22\"}], \"timestamp\":\"1785121846185\", \"event_type\":\"price_change\"}","received_at":"2026-07-27T03:10:46.097355Z","schema_version":"clob-market-ws.price_change.v1","sequence":null,"server_hash":null,"server_timestamp":"1785121846185","session_id":"ff6d21c8283948938400a32613abec2c","source":"clob_market_ws"},"received_at":"2026-07-27T03:10:46.097355Z","record_id":"b286c6fc7ed43a5a46237c00de00885ebc8ac173f6ed25ccadedfef11c51b836","schema_fingerprint":"4aa3821a28b0b7c2400bc59aba4bcc0a76e971dadd19610d3ad38c768e124dc7","schema_version":"edge-lab-recorder.raw.v1","sequence":null,"source":"clob_market_ws"}
{"event_at":"2026-07-27T03:10:46.193000Z","event_fingerprint":"fc85282c2b47f25edb07813c017884769c2005b8d881d26876e51289a057f489","payload":{"connection_id":"f95883f18d264834af91809e5f803e9f","event_at":"2026-07-27T03:10:46.193000Z","event_type":"price_change","frame_hash":"8d07f7d6d967f89d63d91738191400b5db47002f0ba5ea22f3675a1ae0ce2918","frame_index":0,"kind":"data","monotonic_ns":223829430048333,"payload":{"event_type":"price_change","market":"0xf9d60bb033695053c4d1d8592e52171c1042f64b41a4b72e09dcc6f4852b6670","price_changes":[{"asset_id":"96283536366176669581486355171583722558858323126916278856549586825357358273536","best_ask":"0.79","best_bid":"0.78","hash":"31977709fc1519601972171fec51fdecae9d5cba","price":"0.69","side":"BUY","size":"152.7"},{"asset_id":"8698449539441374295770236407991735029336433231649246775082939325523552031992","best_ask":"0.22","best_bid":"0.21","hash":"a43d063b3195edc28586abc304ef66886ff60108","price":"0.31","side":"SELL","size":"152.7"}],"timestamp":"1785121846193"},"payload_hash":"c85dec4c8374c2e7e00347a627025c43e269d9a49b25e6c754002a6fd470de1e","raw_frame":"{\"market\":\"0xf9d60bb033695053c4d1d8592e52171c1042f64b41a4b72e09dcc6f4852b6670\", \"price_changes\":[{\"asset_id\":\"96283536366176669581486355171583722558858323126916278856549586825357358273536\", \"price\":\"0.69\", \"size\":\"152.7\", \"side\":\"BUY\", \"hash\":\"31977709fc1519601972171fec51fdecae9d5cba\", \"best_bid\":\"0.78\", \"best_ask\":\"0.79\"}, {\"asset_id\":\"8698449539441374295770236407991735029336433231649246775082939325523552031992\", \"price\":\"0.31\", \"size\":\"152.7\", \"side\":\"SELL\", \"hash\":\"a43d063b3195edc28586abc304ef66886ff60108\", \"best_bid\":\"0.21\", \"best_ask\":\"0.22\"}], \"timestamp\":\"1785121846193\", \"event_type\":\"price_change\"}","received_at":"2026-07-27T03:10:46.099949Z","schema_version":"clob-market-ws.price_change.v1","sequence":null,"server_hash":null,"server_timestamp":"1785121846193","session_id":"ff6d21c8283948938400a32613abec2c","source":"clob_market_ws"},"received_at":"2026-07-27T03:10:46.099949Z","record_id":"bae51035d7c92da09086e953923d084182b568d17e878b35d7c574e1193d7e04","schema_fingerprint":"4aa3821a28b0b7c2400bc59aba4bcc0a76e971dadd19610d3ad38c768e124dc7","schema_version":"edge-lab-recorder.raw.v1","sequence":null,"source":"clob_market_ws"}
{"event_at":"2026-07-27T03:10:46.201000Z","event_fingerprint":"e8f63c3edea350e2a2fe0493f4ad549ffbf4bb0c51b2dc702dc9ca9916fdfa5a","payload":{"connection_id":"f95883f18d264834af91809e5f803e9f","event_at":"2026-07-27T03:10:46.201000Z","event_type":"price_change","frame_hash":"4df2f120016b9e829955cf9b261b3b1465724f130a0a18f93394b58fcc632b38","frame_index":0,"kind":"data","monotonic_ns":223829437187500,"payload":{"event_type":"price_change","market":"0xf9d60bb033695053c4d1d8592e52171c1042f64b41a4b72e09dcc6f4852b6670","price_changes":[{"asset_id":"8698449539441374295770236407991735029336433231649246775082939325523552031992","best_ask":"0.22","best_bid":"0.21","hash":"98137f852c5f5662302281bb456ee25850654087","price":"0.34","side":"SELL","size":"151.29"},{"asset_id":"96283536366176669581486355171583722558858323126916278856549586825357358273536","best_ask":"0.79","best_bid":"0.78","hash":"6f38ed15d3974c49f2a6b7bfecf76f3d74a6714d","price":"0.66","side":"BUY","size":"151.29"}],"timestamp":"1785121846201"},"payload_hash":"3d60da89e0dd481c962a308a2f6d8f6259daaefd757c49c0a245b179fd985ed1","raw_frame":"{\"market\":\"0xf9d60bb033695053c4d1d8592e52171c1042f64b41a4b72e09dcc6f4852b6670\", \"price_changes\":[{\"asset_id\":\"8698449539441374295770236407991735029336433231649246775082939325523552031992\", \"price\":\"0.34\", \"size\":\"151.29\", \"side\":\"SELL\", \"hash\":\"98137f852c5f5662302281bb456ee25850654087\", \"best_bid\":\"0.21\", \"best_ask\":\"0.22\"}, {\"asset_id\":\"96283536366176669581486355171583722558858323126916278856549586825357358273536\", \"price\":\"0.66\", \"size\":\"151.29\", \"side\":\"BUY\", \"hash\":\"6f38ed15d3974c49f2a6b7bfecf76f3d74a6714d\", \"best_bid\":\"0.78\", \"best_ask\":\"0.79\"}], \"timestamp\":\"1785121846201\", \"event_type\":\"price_change\"}","received_at":"2026-07-27T03:10:46.107081Z","schema_version":"clob-market-ws.price_change.v1","sequence":null,"server_hash":null,"server_timestamp":"1785121846201","session_id":"ff6d21c8283948938400a32613abec2c","source":"clob_market_ws"},"received_at":"2026-07-27T03:10:46.107081Z","record_id":"8d6ec135f8a7abe91cf8209d3ad389e9fceddf75cc8d9b95feb624c03bf59487","schema_fingerprint":"4aa3821a28b0b7c2400bc59aba4bcc0a76e971dadd19610d3ad38c768e124dc7","schema_version":"edge-lab-recorder.raw.v1","sequence":null,"source":"clob_market_ws"}
{"event_at":"2026-07-27T03:10:46.210000Z","event_fingerprint":"cf30c37960a05c720782bd3eb5f2edde6390f4ec9f7eb5db68723ff212f5c03e","payload":{"connection_id":"f95883f18d264834af91809e5f803e9f","event_at":"2026-07-27T03:10:46.210000Z","event_type":"price_change","frame_hash":"c0b2cb1c6f4d2eeaaad7e13995a08b093c97a2a40af8de57fabaf0316842276d","frame_index":0,"kind":"data","monotonic_ns":223829456364791,"payload":{"event_type":"price_change","market":"0xf9d60bb033695053c4d1d8592e52171c1042f64b41a4b72e09dcc6f4852b6670","price_changes":[{"asset_id":"96283536366176669581486355171583722558858323126916278856549586825357358273536","best_ask":"0.79","best_bid":"0.78","hash":"bbc6ef7d37d15efca66e7842db818e071fce9833","price":"0.01","side":"BUY","size":"6919.52"},{"asset_id":"8698449539441374295770236407991735029336433231649246775082939325523552031992","best_ask":"0.22","best_bid":"0.21","hash":"e1477673a1333d7f9ca5628876ec9b47c96b8f2b","price":"0.99","side":"SELL","size":"6919.52"}],"timestamp":"1785121846210"},"payload_hash":"915afca1b9c42f1b042ab958fdf4677137c4138d410a9a7db9f546f6e9866ee7","raw_frame":"{\"market\":\"0xf9d60bb033695053c4d1d8592e52171c1042f64b41a4b72e09dcc6f4852b6670\", \"price_changes\":[{\"asset_id\":\"96283536366176669581486355171583722558858323126916278856549586825357358273536\", \"price\":\"0.01\", \"size\":\"6919.52\", \"side\":\"BUY\", \"hash\":\"bbc6ef7d37d15efca66e7842db818e071fce9833\", \"best_bid\":\"0.78\", \"best_ask\":\"0.79\"}, {\"asset_id\":\"8698449539441374295770236407991735029336433231649246775082939325523552031992\", \"price\":\"0.99\", \"size\":\"6919.52\", \"side\":\"SELL\", \"hash\":\"e1477673a1333d7f9ca5628876ec9b47c96b8f2b\", \"best_bid\":\"0.21\", \"best_ask\":\"0.22\"}], \"timestamp\":\"1785121846210\", \"event_type\":\"price_change\"}","received_at":"2026-07-27T03:10:46.126255Z","schema_version":"clob-market-ws.price_change.v1","sequence":null,"server_hash":null,"server_timestamp":"1785121846210","session_id":"ff6d21c8283948938400a32613abec2c","source":"clob_market_ws"},"received_at":"2026-07-27T03:10:46.126255Z","record_id":"0052d2b7260e8a7657d864de92f1ceb340a9b120e419b8c660a5a4b34bf8b0f9","schema_fingerprint":"4aa3821a28b0b7c2400bc59aba4bcc0a76e971dadd19610d3ad38c768e124dc7","schema_version":"edge-lab-recorder.raw.v1","sequence":null,"source":"clob_market_ws"}
{"event_at":"2026-07-27T03:10:46.219000Z","event_fingerprint":"76e8f8104646d230e1347373eaa0504857bf2d2d0709524df17e22b29608f80c","payload":{"connection_id":"f95883f18d264834af91809e5f803e9f","event_at":"2026-07-27T03:10:46.219000Z","event_type":"price_change","frame_hash":"9ae7b9a8ad81a0d5b2e0f4985f35114de272c634dcffe99917b81ad661d874b7","frame_index":0,"kind":"data","monotonic_ns":223829459566333,"payload":{"event_type":"price_change","market":"0xf9d60bb033695053c4d1d8592e52171c1042f64b41a4b72e09dcc6f4852b6670","price_changes":[{"asset_id":"96283536366176669581486355171583722558858323126916278856549586825357358273536","best_ask":"0.79","best_bid":"0.78","hash":"ad33b454395519cefa782aeb615a03d9af010b0c","price":"0.01","side":"BUY","size":"6924.52"},{"asset_id":"8698449539441374295770236407991735029336433231649246775082939325523552031992","best_ask":"0.22","best_bid":"0.21","hash":"624e34647bd734b19a9817d3167fe2ab45e464a7","price":"0.99","side":"SELL","size":"6924.52"}],"timestamp":"1785121846219"},"payload_hash":"3efcdcc383e928b6544fde2e722bc5f914f43d73b81c275b6975e41e5d14fc6f","raw_frame":"{\"market\":\"0xf9d60bb033695053c4d1d8592e52171c1042f64b41a4b72e09dcc6f4852b6670\", \"price_changes\":[{\"asset_id\":\"96283536366176669581486355171583722558858323126916278856549586825357358273536\", \"price\":\"0.01\", \"size\":\"6924.52\", \"side\":\"BUY\", \"hash\":\"ad33b454395519cefa782aeb615a03d9af010b0c\", \"best_bid\":\"0.78\", \"best_ask\":\"0.79\"}, {\"asset_id\":\"8698449539441374295770236407991735029336433231649246775082939325523552031992\", \"price\":\"0.99\", \"size\":\"6924.52\", \"side\":\"SELL\", \"hash\":\"624e34647bd734b19a9817d3167fe2ab45e464a7\", \"best_bid\":\"0.21\", \"best_ask\":\"0.22\"}], \"timestamp\":\"1785121846219\", \"event_type\":\"price_change\"}","received_at":"2026-07-27T03:10:46.129461Z","schema_version":"clob-market-ws.price_change.v1","sequence":null,"server_hash":null,"server_timestamp":"1785121846219","session_id":"ff6d21c8283948938400a32613abec2c","source":"clob_market_ws"},"received_at":"2026-07-27T03:10:46.129461Z","record_id":"ecb9c6379450732eff597e6358b937d9cad37bc8ba5a316738244739c4ec0fc1","schema_fingerprint":"4aa3821a28b0b7c2400bc59aba4bcc0a76e971dadd19610d3ad38c768e124dc7","schema_version":"edge-lab-recorder.raw.v1","sequence":null,"source":"clob_market_ws"}
{"event_at":"2026-07-27T03:10:46.220000Z","event_fingerprint":"1aed8047c7fcd2ebe7d7af111438793b82d23b7d6f6f9d35afd6f4f6d7041b09","payload":{"connection_id":"f95883f18d264834af91809e5f803e9f","event_at":"2026-07-27T03:10:46.220000Z","event_type":"price_change","frame_hash":"297b1775665818fc99063f0bde94f25838d34487efc7566e13129eef9b0d84c9","frame_index":0,"kind":"data","monotonic_ns":223829462087416,"payload":{"event_type":"price_change","market":"0xf9d60bb033695053c4d1d8592e52171c1042f64b41a4b72e09dcc6f4852b6670","price_changes":[{"asset_id":"96283536366176669581486355171583722558858323126916278856549586825357358273536","best_ask":"0.79","best_bid":"0.78","hash":"255e7336dbc661b645969bbe40825930dd84f72d","price":"0.77","side":"BUY","size":"110.1"},{"asset_id":"8698449539441374295770236407991735029336433231649246775082939325523552031992","best_ask":"0.22","best_bid":"0.21","hash":"e10b9007e947b8f4f48db87bec0eefe86c2606d4","price":"0.23","side":"SELL","size":"110.1"}],"timestamp":"1785121846220"},"payload_hash":"6b698a91cde233a5e836ee021b4487b04505cb50d902c8cf99232ddcbbea1c9f","raw_frame":"{\"market\":\"0xf9d60bb033695053c4d1d8592e52171c1042f64b41a4b72e09dcc6f4852b6670\", \"price_changes\":[{\"asset_id\":\"96283536366176669581486355171583722558858323126916278856549586825357358273536\", \"price\":\"0.77\", \"size\":\"110.1\", \"side\":\"BUY\", \"hash\":\"255e7336dbc661b645969bbe40825930dd84f72d\", \"best_bid\":\"0.78\", \"best_ask\":\"0.79\"}, {\"asset_id\":\"8698449539441374295770236407991735029336433231649246775082939325523552031992\", \"price\":\"0.23\", \"size\":\"110.1\", \"side\":\"SELL\", \"hash\":\"e10b9007e947b8f4f48db87bec0eefe86c2606d4\", \"best_bid\":\"0.21\", \"best_ask\":\"0.22\"}], \"timestamp\":\"1785121846220\", \"event_type\":\"price_change\"}","received_at":"2026-07-27T03:10:46.131983Z","schema_version":"clob-market-ws.price_change.v1","sequence":null,"server_hash":null,"server_timestamp":"1785121846220","session_id":"ff6d21c8283948938400a32613abec2c","source":"clob_market_ws"},"received_at":"2026-07-27T03:10:46.131983Z","record_id":"499e8e6d68302c3bdb4b081f0357250c7365f219b42e378f47cd5a884b8b41f0","schema_fingerprint":"4aa3821a28b0b7c2400bc59aba4bcc0a76e971dadd19610d3ad38c768e124dc7","schema_version":"edge-lab-recorder.raw.v1","sequence":null,"source":"clob_market_ws"}
{"event_at":"2026-07-27T03:10:46.221000Z","event_fingerprint":"5d7061df03c05e312fe4a42f3a9d2e828f18b75097bd8fa2c75e5b1cad6c23da","payload":{"connection_id":"f95883f18d264834af91809e5f803e9f","event_at":"2026-07-27T03:10:46.221000Z","event_type":"price_change","frame_hash":"7f82e90ee9284f2f8beb07791e05360c80d2c1905b203807025653aaabed30e7","frame_index":0,"kind":"data","monotonic_ns":223829464462583,"payload":{"event_type":"price_change","market":"0xf9d60bb033695053c4d1d8592e52171c1042f64b41a4b72e09dcc6f4852b6670","price_changes":[{"asset_id":"96283536366176669581486355171583722558858323126916278856549586825357358273536","best_ask":"0.79","best_bid":"0.78","hash":"8f6d40c829980e71772157f73dc3638aa582dc8d","price":"0.77","side":"BUY","size":"115.1"},{"asset_id":"8698449539441374295770236407991735029336433231649246775082939325523552031992","best_ask":"0.22","best_bid":"0.21","hash":"1d226d3566319ce71ad231f5f3efad195b71f481","price":"0.23","side":"SELL","size":"115.1"}],"timestamp":"1785121846221"},"payload_hash":"cd4fd3f788a10afa88d1b9bba998edfddc27e93d30a15c7a1f2c7ac0989b998a","raw_frame":"{\"market\":\"0xf9d60bb033695053c4d1d8592e52171c1042f64b41a4b72e09dcc6f4852b6670\", \"price_changes\":[{\"asset_id\":\"96283536366176669581486355171583722558858323126916278856549586825357358273536\", \"price\":\"0.77\", \"size\":\"115.1\", \"side\":\"BUY\", \"hash\":\"8f6d40c829980e71772157f73dc3638aa582dc8d\", \"best_bid\":\"0.78\", \"best_ask\":\"0.79\"}, {\"asset_id\":\"8698449539441374295770236407991735029336433231649246775082939325523552031992\", \"price\":\"0.23\", \"size\":\"115.1\", \"side\":\"SELL\", \"hash\":\"1d226d3566319ce71ad231f5f3efad195b71f481\", \"best_bid\":\"0.21\", \"best_ask\":\"0.22\"}], \"timestamp\":\"1785121846221\", \"event_type\":\"price_change\"}","received_at":"2026-07-27T03:10:46.134361Z","schema_version":"clob-market-ws.price_change.v1","sequence":null,"server_hash":null,"server_timestamp":"1785121846221","session_id":"ff6d21c8283948938400a32613abec2c","source":"clob_market_ws"},"received_at":"2026-07-27T03:10:46.134361Z","record_id":"433f8dea906a6e1c657d39e979006a39f955f9cf267235987e853f6a7f2f93bd","schema_fingerprint":"4aa3821a28b0b7c2400bc59aba4bcc0a76e971dadd19610d3ad38c768e124dc7","schema_version":"edge-lab-recorder.raw.v1","sequence":null,"source":"clob_market_ws"}
{"event_at":"2026-07-27T03:10:46.226000Z","event_fingerprint":"9a10b9cdf31027118aaf0282a148c37c4e1a70aae494c11f70e70f51c2b205aa","payload":{"connection_id":"f95883f18d264834af91809e5f803e9f","event_at":"2026-07-27T03:10:46.226000Z","event_type":"price_change","frame_hash":"60c71c0d3ce2886eb793e4de7181d1691ff63322fba3dada5512b91d7a209608","frame_index":0,"kind":"data","monotonic_ns":223829466225583,"payload":{"event_type":"price_change","market":"0xf9d60bb033695053c4d1d8592e52171c1042f64b41a4b72e09dcc6f4852b6670","price_changes":[{"asset_id":"96283536366176669581486355171583722558858323126916278856549586825357358273536","best_ask":"0.79","best_bid":"0.78","hash":"907215c52ba735a74b3f12e9271593b3b1330e0a","price":"0.01","side":"BUY","size":"6929.52"},{"asset_id":"8698449539441374295770236407991735029336433231649246775082939325523552031992","best_ask":"0.22","best_bid":"0.21","hash":"264f0a5274c9286e3c253098fd103813f29a0331","price":"0.99","side":"SELL","size":"6929.52"}],"timestamp":"1785121846226"},"payload_hash":"6e9255a5b68e14861ae397976fbd74d83e36ba81234569446f3c23bb8cc976ad","raw_frame":"{\"market\":\"0xf9d60bb033695053c4d1d8592e52171c1042f64b41a4b72e09dcc6f4852b6670\", \"price_changes\":[{\"asset_id\":\"96283536366176669581486355171583722558858323126916278856549586825357358273536\", \"price\":\"0.01\", \"size\":\"6929.52\", \"side\":\"BUY\", \"hash\":\"907215c52ba735a74b3f12e9271593b3b1330e0a\", \"best_bid\":\"0.78\", \"best_ask\":\"0.79\"}, {\"asset_id\":\"8698449539441374295770236407991735029336433231649246775082939325523552031992\", \"price\":\"0.99\", \"size\":\"6929.52\", \"side\":\"SELL\", \"hash\":\"264f0a5274c9286e3c253098fd103813f29a0331\", \"best_bid\":\"0.21\", \"best_ask\":\"0.22\"}], \"timestamp\":\"1785121846226\", \"event_type\":\"price_change\"}","received_at":"2026-07-27T03:10:46.136120Z","schema_version":"clob-market-ws.price_change.v1","sequence":null,"server_hash":null,"server_timestamp":"1785121846226","session_id":"ff6d21c8283948938400a32613abec2c","source":"clob_market_ws"},"received_at":"2026-07-27T03:10:46.136120Z","record_id":"77b270f5fe435629a87bd04cebfa5c1bc78ac5cbcc9aa29805fe38703fe66664","schema_fingerprint":"4aa3821a28b0b7c2400bc59aba4bcc0a76e971dadd19610d3ad38c768e124dc7","schema_version":"edge-lab-recorder.raw.v1","sequence":null,"source":"clob_market_ws"}
{"event_at":"2026-07-27T03:10:46.227000Z","event_fingerprint":"3054136c010f8f9e3037891caf50f6d392ac366c4730bdeed24f985fc0414608","payload":{"connection_id":"f95883f18d264834af91809e5f803e9f","event_at":"2026-07-27T03:10:46.227000Z","event_type":"price_change","frame_hash":"378f86330623322985b9ef309845e018272f9b2fe98cd9fcd065323f057f69f4","frame_index":0,"kind":"data","monotonic_ns":223829469111750,"payload":{"event_type":"price_change","market":"0xf9d60bb033695053c4d1d8592e52171c1042f64b41a4b72e09dcc6f4852b6670","price_changes":[{"asset_id":"96283536366176669581486355171583722558858323126916278856549586825357358273536","best_ask":"0.79","best_bid":"0.78","hash":"b57820ce89c31a6dde335b6532f4b5696eb4652f","price":"0.67","side":"BUY","size":"131.87"},{"asset_id":"8698449539441374295770236407991735029336433231649246775082939325523552031992","best_ask":"0.22","best_bid":"0.21","hash":"bf409c69a5e6b87d12aafc2eda98b998f41fc815","price":"0.33","side":"SELL","size":"131.87"}],"timestamp":"1785121846227"},"payload_hash":"c80dcc3212d7062c0003574b8a977e30dde62412fe6af582f60cd3bbd376ca6a","raw_frame":"{\"market\":\"0xf9d60bb033695053c4d1d8592e52171c1042f64b41a4b72e09dcc6f4852b6670\", \"price_changes\":[{\"asset_id\":\"96283536366176669581486355171583722558858323126916278856549586825357358273536\", \"price\":\"0.67\", \"size\":\"131.87\", \"side\":\"BUY\", \"hash\":\"b57820ce89c31a6dde335b6532f4b5696eb4652f\", \"best_bid\":\"0.78\", \"best_ask\":\"0.79\"}, {\"asset_id\":\"8698449539441374295770236407991735029336433231649246775082939325523552031992\", \"price\":\"0.33\", \"size\":\"131.87\", \"side\":\"SELL\", \"hash\":\"bf409c69a5e6b87d12aafc2eda98b998f41fc815\", \"best_bid\":\"0.21\", \"best_ask\":\"0.22\"}], \"timestamp\":\"1785121846227\", \"event_type\":\"price_change\"}","received_at":"2026-07-27T03:10:46.139006Z","schema_version":"clob-market-ws.price_change.v1","sequence":null,"server_hash":null,"server_timestamp":"1785121846227","session_id":"ff6d21c8283948938400a32613abec2c","source":"clob_market_ws"},"received_at":"2026-07-27T03:10:46.139006Z","record_id":"ff23d6d8e223b29532f1acd2198666210fb46b17798de03ae3d0ce3ad9129c05","schema_fingerprint":"4aa3821a28b0b7c2400bc59aba4bcc0a76e971dadd19610d3ad38c768e124dc7","schema_version":"edge-lab-recorder.raw.v1","sequence":null,"source":"clob_market_ws"}
{"event_at":"2026-07-27T03:10:46.238000Z","event_fingerprint":"b9f57a5bda77796dacdc59273d386880206fbeb3b1dd0dbb4d1349520998b64b","payload":{"connection_id":"f95883f18d264834af91809e5f803e9f","event_at":"2026-07-27T03:10:46.238000Z","event_type":"price_change","frame_hash":"7aa17263898889d9b1546bae0c7e196d3154c6dfb1b9a4801eeadb5f63543e0e","frame_index":0,"kind":"data","monotonic_ns":223829472130416,"payload":{"event_type":"price_change","market":"0xf9d60bb033695053c4d1d8592e52171c1042f64b41a4b72e09dcc6f4852b6670","price_changes":[{"asset_id":"8698449539441374295770236407991735029336433231649246775082939325523552031992","best_ask":"0.22","best_bid":"0.21","hash":"3fa58ae93cb72e6eb1e97d59ee651d468bab0940","price":"0.24","side":"SELL","size":"135"},{"asset_id":"96283536366176669581486355171583722558858323126916278856549586825357358273536","best_ask":"0.79","best_bid":"0.78","hash":"6443f8c7677a600df52f3484f0a32502699f21bc","price":"0.76","side":"BUY","size":"135"}],"timestamp":"1785121846238"},"payload_hash":"3958dd9edbe14dc71a861755848e19a50609b07703c678c1f61c4c09929eb46a","raw_frame":"{\"market\":\"0xf9d60bb033695053c4d1d8592e52171c1042f64b41a4b72e09dcc6f4852b6670\", \"price_changes\":[{\"asset_id\":\"8698449539441374295770236407991735029336433231649246775082939325523552031992\", \"price\":\"0.24\", \"size\":\"135\", \"side\":\"SELL\", \"hash\":\"3fa58ae93cb72e6eb1e97d59ee651d468bab0940\", \"best_bid\":\"0.21\", \"best_ask\":\"0.22\"}, {\"asset_id\":\"96283536366176669581486355171583722558858323126916278856549586825357358273536\", \"price\":\"0.76\", \"size\":\"135\", \"side\":\"BUY\", \"hash\":\"6443f8c7677a600df52f3484f0a32502699f21bc\", \"best_bid\":\"0.78\", \"best_ask\":\"0.79\"}], \"timestamp\":\"1785121846238\", \"event_type\":\"price_change\"}","received_at":"2026-07-27T03:10:46.142025Z","schema_version":"clob-market-ws.price_change.v1","sequence":null,"server_hash":null,"server_timestamp":"1785121846238","session_id":"ff6d21c8283948938400a32613abec2c","source":"clob_market_ws"},"received_at":"2026-07-27T03:10:46.142025Z","record_id":"1ec703d602a0456e914df25e7614cf3febc2275f9c98987ed115248b2ebb4617","schema_fingerprint":"4aa3821a28b0b7c2400bc59aba4bcc0a76e971dadd19610d3ad38c768e124dc7","schema_version":"edge-lab-recorder.raw.v1","sequence":null,"source":"clob_market_ws"}
{"event_at":"2026-07-27T03:10:46.239000Z","event_fingerprint":"710aac6453635ac015a99e7bfb04f3189ece83a2f95614dd469187834913f20d","payload":{"connection_id":"f95883f18d264834af91809e5f803e9f","event_at":"2026-07-27T03:10:46.239000Z","event_type":"price_change","frame_hash":"45141bb3654264bcd790535eac3fa7913326f2e4db4abb059667fe46491d75a2","frame_index":0,"kind":"data","monotonic_ns":223829475727250,"payload":{"event_type":"price_change","market":"0xf9d60bb033695053c4d1d8592e52171c1042f64b41a4b72e09dcc6f4852b6670","price_changes":[{"asset_id":"8698449539441374295770236407991735029336433231649246775082939325523552031992","best_ask":"0.22","best_bid":"0.21","hash":"856cd6189464370b985064bfaba89d87c1b09c62","price":"0.25","side":"SELL","size":"110.57"},{"asset_id":"96283536366176669581486355171583722558858323126916278856549586825357358273536","best_ask":"0.79","best_bid":"0.78","hash":"f12a347be4cd6344100f2fa75480d13117d68c28","price":"0.75","side":"BUY","size":"110.57"}],"timestamp":"1785121846239"},"payload_hash":"1f120a4f3affe56567a3b72405456f21232f6e7649c53040e5fd39033f7ae7e8","raw_frame":"{\"market\":\"0xf9d60bb033695053c4d1d8592e52171c1042f64b41a4b72e09dcc6f4852b6670\", \"price_changes\":[{\"asset_id\":\"8698449539441374295770236407991735029336433231649246775082939325523552031992\", \"price\":\"0.25\", \"size\":\"110.57\", \"side\":\"SELL\", \"hash\":\"856cd6189464370b985064bfaba89d87c1b09c62\", \"best_bid\":\"0.21\", \"best_ask\":\"0.22\"}, {\"asset_id\":\"96283536366176669581486355171583722558858323126916278856549586825357358273536\", \"price\":\"0.75\", \"size\":\"110.57\", \"side\":\"BUY\", \"hash\":\"f12a347be4cd6344100f2fa75480d13117d68c28\", \"best_bid\":\"0.78\", \"best_ask\":\"0.79\"}], \"timestamp\":\"1785121846239\", \"event_type\":\"price_change\"}","received_at":"2026-07-27T03:10:46.145621Z","schema_version":"clob-market-ws.price_change.v1","sequence":null,"server_hash":null,"server_timestamp":"1785121846239","session_id":"ff6d21c8283948938400a32613abec2c","source":"clob_market_ws"},"received_at":"2026-07-27T03:10:46.145621Z","record_id":"7be0db5b0efb9eb758d9d993870b70efa312ccad3bcfd3102515d302dd70e1a9","schema_fingerprint":"4aa3821a28b0b7c2400bc59aba4bcc0a76e971dadd19610d3ad38c768e124dc7","schema_version":"edge-lab-recorder.raw.v1","sequence":null,"source":"clob_market_ws"}
{"event_at":"2026-07-27T03:10:46.243000Z","event_fingerprint":"01ee888d7e4b93a9d08566c7660ae1e28a5cc8ff4471c40957f3c893f090ab1b","payload":{"connection_id":"f95883f18d264834af91809e5f803e9f","event_at":"2026-07-27T03:10:46.243000Z","event_type":"price_change","frame_hash":"99e10b344718bd5b0fecfbac8b6b3faea919f4ad6bfe79e7841099b72bed008f","frame_index":0,"kind":"data","monotonic_ns":223829479000333,"payload":{"event_type":"price_change","market":"0xf9d60bb033695053c4d1d8592e52171c1042f64b41a4b72e09dcc6f4852b6670","price_changes":[{"asset_id":"96283536366176669581486355171583722558858323126916278856549586825357358273536","best_ask":"0.79","best_bid":"0.78","hash":"91f06ed0f0dd886df6a913dc36e2c434415e8b12","price":"0.01","side":"BUY","size":"6924.52"},{"asset_id":"8698449539441374295770236407991735029336433231649246775082939325523552031992","best_ask":"0.22","best_bid":"0.21","hash":"37ba14badbbe83f2ecfd046ba7bae522aeca854c","price":"0.99","side":"SELL","size":"6924.52"}],"timestamp":"1785121846243"},"payload_hash":"5d1bd435a63f35b1201b891a8289c0ba1c8391d17aad3b8f337ea8cbd05f9f88","raw_frame":"{\"market\":\"0xf9d60bb033695053c4d1d8592e52171c1042f64b41a4b72e09dcc6f4852b6670\", \"price_changes\":[{\"asset_id\":\"96283536366176669581486355171583722558858323126916278856549586825357358273536\", \"price\":\"0.01\", \"size\":\"6924.52\", \"side\":\"BUY\", \"hash\":\"91f06ed0f0dd886df6a913dc36e2c434415e8b12\", \"best_bid\":\"0.78\", \"best_ask\":\"0.79\"}, {\"asset_id\":\"8698449539441374295770236407991735029336433231649246775082939325523552031992\", \"price\":\"0.99\", \"size\":\"6924.52\", \"side\":\"SELL\", \"hash\":\"37ba14badbbe83f2ecfd046ba7bae522aeca854c\", \"best_bid\":\"0.21\", \"best_ask\":\"0.22\"}], \"timestamp\":\"1785121846243\", \"event_type\":\"price_change\"}","received_at":"2026-07-27T03:10:46.148894Z","schema_version":"clob-market-ws.price_change.v1","sequence":null,"server_hash":null,"server_timestamp":"1785121846243","session_id":"ff6d21c8283948938400a32613abec2c","source":"clob_market_ws"},"received_at":"2026-07-27T03:10:46.148894Z","record_id":"6ebd7cf9072480da04f498e1ccbe2f7b83933a5c006294a1380891dde0fca0be","schema_fingerprint":"4aa3821a28b0b7c2400bc59aba4bcc0a76e971dadd19610d3ad38c768e124dc7","schema_version":"edge-lab-recorder.raw.v1","sequence":null,"source":"clob_market_ws"}
{"event_at":"2026-07-27T03:10:46.243000Z","event_fingerprint":"e5bd4e9ba0b6e9ded0f539214ea0cf0fec66b8d1c241ebc55589d731ceae529e","payload":{"connection_id":"f95883f18d264834af91809e5f803e9f","event_at":"2026-07-27T03:10:46.243000Z","event_type":"price_change","frame_hash":"e8e4c5e4c9d2a2be23ee4b45ed9b8d556d9be4600812357680ed2bd26aa4e90e","frame_index":0,"kind":"data","monotonic_ns":223829488437125,"payload":{"event_type":"price_change","market":"0xf9d60bb033695053c4d1d8592e52171c1042f64b41a4b72e09dcc6f4852b6670","price_changes":[{"asset_id":"8698449539441374295770236407991735029336433231649246775082939325523552031992","best_ask":"0.22","best_bid":"0.21","hash":"cded89a9e2c89057c4bc97bad77c901d858cbb0a","price":"0.01","side":"BUY","size":"6829.52"},{"asset_id":"96283536366176669581486355171583722558858323126916278856549586825357358273536","best_ask":"0.79","best_bid":"0.78","hash":"21fc49211b81e1533e3df6b09fdb4f14e45df725","price":"0.99","side":"SELL","size":"6829.52"}],"timestamp":"1785121846243"},"payload_hash":"ec5e38a4c066638aea517140f6155591f02f18382ac45e476681cbd9d6d7efe7","raw_frame":"{\"market\":\"0xf9d60bb033695053c4d1d8592e52171c1042f64b41a4b72e09dcc6f4852b6670\", \"price_changes\":[{\"asset_id\":\"8698449539441374295770236407991735029336433231649246775082939325523552031992\", \"price\":\"0.01\", \"size\":\"6829.52\", \"side\":\"BUY\", \"hash\":\"cded89a9e2c89057c4bc97bad77c901d858cbb0a\", \"best_bid\":\"0.21\", \"best_ask\":\"0.22\"}, {\"asset_id\":\"96283536366176669581486355171583722558858323126916278856549586825357358273536\", \"price\":\"0.99\", \"size\":\"6829.52\", \"side\":\"SELL\", \"hash\":\"21fc49211b81e1533e3df6b09fdb4f14e45df725\", \"best_bid\":\"0.78\", \"best_ask\":\"0.79\"}], \"timestamp\":\"1785121846243\", \"event_type\":\"price_change\"}","received_at":"2026-07-27T03:10:46.158329Z","schema_version":"clob-market-ws.price_change.v1","sequence":null,"server_hash":null,"server_timestamp":"1785121846243","session_id":"ff6d21c8283948938400a32613abec2c","source":"clob_market_ws"},"received_at":"2026-07-27T03:10:46.158329Z","record_id":"f7c4af6838dbb03f8b868e41ae9da27d17015ed9fd52cede7cf89739b11b98ea","schema_fingerprint":"4aa3821a28b0b7c2400bc59aba4bcc0a76e971dadd19610d3ad38c768e124dc7","schema_version":"edge-lab-recorder.raw.v1","sequence":null,"source":"clob_market_ws"}
{"event_at":"2026-07-27T03:10:46.246000Z","event_fingerprint":"23c7486a91adc4a5dfec314036a935d9b47b79337c6cdca5b62dca24586aa02d","payload":{"connection_id":"f95883f18d264834af91809e5f803e9f","event_at":"2026-07-27T03:10:46.246000Z","event_type":"price_change","frame_hash":"adf25cc657ef704c89b29d25e6040ddd58d32a864219e3203b8f2a9501ba99c9","frame_index":0,"kind":"data","monotonic_ns":223829494677291,"payload":{"event_type":"price_change","market":"0xf9d60bb033695053c4d1d8592e52171c1042f64b41a4b72e09dcc6f4852b6670","price_changes":[{"asset_id":"96283536366176669581486355171583722558858323126916278856549586825357358273536","best_ask":"0.79","best_bid":"0.78","hash":"13984e2a33116d51ac62820c69ee5f410dcd0ccd","price":"0.01","side":"BUY","size":"6929.52"},{"asset_id":"8698449539441374295770236407991735029336433231649246775082939325523552031992","best_ask":"0.22","best_bid":"0.21","hash":"d574dde7a6fe34aa975ab837a6a92c97b29b43ba","price":"0.99","side":"SELL","size":"6929.52"}],"timestamp":"1785121846246"},"payload_hash":"f42b7e0a383ee416e0d43e1a880af7edc24f51f855274a7c4e2f5f66558c4967","raw_frame":"{\"market\":\"0xf9d60bb033695053c4d1d8592e52171c1042f64b41a4b72e09dcc6f4852b6670\", \"price_changes\":[{\"asset_id\":\"96283536366176669581486355171583722558858323126916278856549586825357358273536\", \"price\":\"0.01\", \"size\":\"6929.52\", \"side\":\"BUY\", \"hash\":\"13984e2a33116d51ac62820c69ee5f410dcd0ccd\", \"best_bid\":\"0.78\", \"best_ask\":\"0.79\"}, {\"asset_id\":\"8698449539441374295770236407991735029336433231649246775082939325523552031992\", \"price\":\"0.99\", \"size\":\"6929.52\", \"side\":\"SELL\", \"hash\":\"d574dde7a6fe34aa975ab837a6a92c97b29b43ba\", \"best_bid\":\"0.21\", \"best_ask\":\"0.22\"}], \"timestamp\":\"1785121846246\", \"event_type\":\"price_change\"}","received_at":"2026-07-27T03:10:46.164571Z","schema_version":"clob-market-ws.price_change.v1","sequence":null,"server_hash":null,"server_timestamp":"1785121846246","session_id":"ff6d21c8283948938400a32613abec2c","source":"clob_market_ws"},"received_at":"2026-07-27T03:10:46.164571Z","record_id":"4f38e91cd50792248f7fc354f99fbae4100c4b58e5683d393cc98148a362961b","schema_fingerprint":"4aa3821a28b0b7c2400bc59aba4bcc0a76e971dadd19610d3ad38c768e124dc7","schema_version":"edge-lab-recorder.raw.v1","sequence":null,"source":"clob_market_ws"}
{"event_at":"2026-07-27T03:10:46.249000Z","event_fingerprint":"5390fcc692aba5e782f607f7617e6e3e7344b40ff86acad54069926f20583ad6","payload":{"connection_id":"f95883f18d264834af91809e5f803e9f","event_at":"2026-07-27T03:10:46.249000Z","event_type":"price_change","frame_hash":"f71c9553837de5c8972faabb4daa14d359cc52246b415e12419c5010d2a9f316","frame_index":0,"kind":"data","monotonic_ns":223829500197875,"payload":{"event_type":"price_change","market":"0xf9d60bb033695053c4d1d8592e52171c1042f64b41a4b72e09dcc6f4852b6670","price_changes":[{"asset_id":"8698449539441374295770236407991735029336433231649246775082939325523552031992","best_ask":"0.22","best_bid":"0.21","hash":"7a8e0cce10cf1f8ca5c72b6d5688866f3e01d902","price":"0.01","side":"BUY","size":"6834.52"},{"asset_id":"96283536366176669581486355171583722558858323126916278856549586825357358273536","best_ask":"0.79","best_bid":"0.78","hash":"564654e05ef46e900de9d63e6a7a9a10c8dfe9da","price":"0.99","side":"SELL","size":"6834.52"}],"timestamp":"1785121846249"},"payload_hash":"50c74ebabdfabfff47810e3d134c8e99720e6bc914c4a698dc6fabe7cf920395","raw_frame":"{\"market\":\"0xf9d60bb033695053c4d1d8592e52171c1042f64b41a4b72e09dcc6f4852b6670\", \"price_changes\":[{\"asset_id\":\"8698449539441374295770236407991735029336433231649246775082939325523552031992\", \"price\":\"0.01\", \"size\":\"6834.52\", \"side\":\"BUY\", \"hash\":\"7a8e0cce10cf1f8ca5c72b6d5688866f3e01d902\", \"best_bid\":\"0.21\", \"best_ask\":\"0.22\"}, {\"asset_id\":\"96283536366176669581486355171583722558858323126916278856549586825357358273536\", \"price\":\"0.99\", \"size\":\"6834.52\", \"side\":\"SELL\", \"hash\":\"564654e05ef46e900de9d63e6a7a9a10c8dfe9da\", \"best_bid\":\"0.78\", \"best_ask\":\"0.79\"}], \"timestamp\":\"1785121846249\", \"event_type\":\"price_change\"}","received_at":"2026-07-27T03:10:46.170089Z","schema_version":"clob-market-ws.price_change.v1","sequence":null,"server_hash":null,"server_timestamp":"1785121846249","session_id":"ff6d21c8283948938400a32613abec2c","source":"clob_market_ws"},"received_at":"2026-07-27T03:10:46.170089Z","record_id":"755caef28724c1beb9d98cf48726a62a60e32d500382bacca19c838e9cc7aee8","schema_fingerprint":"4aa3821a28b0b7c2400bc59aba4bcc0a76e971dadd19610d3ad38c768e124dc7","schema_version":"edge-lab-recorder.raw.v1","sequence":null,"source":"clob_market_ws"}
{"event_at":"2026-07-27T03:10:46.251000Z","event_fingerprint":"5f4f3df678c9dea1ba9dbfe21bf594819b3a1d2c1018757b0bc4da3cdd57abca","payload":{"connection_id":"f95883f18d264834af91809e5f803e9f","event_at":"2026-07-27T03:10:46.251000Z","event_type":"price_change","frame_hash":"a49ed91593ea0a12b5976b7deda4585ae2a4ae55b2152d5f964c25edc8041b9c","frame_index":0,"kind":"data","monotonic_ns":223829503676750,"payload":{"event_type":"price_change","market":"0xf9d60bb033695053c4d1d8592e52171c1042f64b41a4b72e09dcc6f4852b6670","price_changes":[{"asset_id":"96283536366176669581486355171583722558858323126916278856549586825357358273536","best_ask":"0.79","best_bid":"0.78","hash":"95114dc4b8f6df977f419182683d1720ea0b5e99","price":"0.01","side":"BUY","size":"6924.52"},{"asset_id":"8698449539441374295770236407991735029336433231649246775082939325523552031992","best_ask":"0.22","best_bid":"0.21","hash":"fc741e9688911d52b1a6e5e25962c7082c5a4c36","price":"0.99","side":"SELL","size":"6924.52"}],"timestamp":"1785121846251"},"payload_hash":"03e5406cdfcebf848433b606037b2848780ea7349023da08f5bebb5e31e6ad4f","raw_frame":"{\"market\":\"0xf9d60bb033695053c4d1d8592e52171c1042f64b41a4b72e09dcc6f4852b6670\", \"price_changes\":[{\"asset_id\":\"96283536366176669581486355171583722558858323126916278856549586825357358273536\", \"price\":\"0.01\", \"size\":\"6924.52\", \"side\":\"BUY\", \"hash\":\"95114dc4b8f6df977f419182683d1720ea0b5e99\", \"best_bid\":\"0.78\", \"best_ask\":\"0.79\"}, {\"asset_id\":\"8698449539441374295770236407991735029336433231649246775082939325523552031992\", \"price\":\"0.99\", \"size\":\"6924.52\", \"side\":\"SELL\", \"hash\":\"fc741e9688911d52b1a6e5e25962c7082c5a4c36\", \"best_bid\":\"0.21\", \"best_ask\":\"0.22\"}], \"timestamp\":\"1785121846251\", \"event_type\":\"price_change\"}","received_at":"2026-07-27T03:10:46.173570Z","schema_version":"clob-market-ws.price_change.v1","sequence":null,"server_hash":null,"server_timestamp":"1785121846251","session_id":"ff6d21c8283948938400a32613abec2c","source":"clob_market_ws"},"received_at":"2026-07-27T03:10:46.173570Z","record_id":"079c2a24f0272a9f88fcfa5d470a666e90943ed5dcb793bc2d7e0799d98b3ee1","schema_fingerprint":"4aa3821a28b0b7c2400bc59aba4bcc0a76e971dadd19610d3ad38c768e124dc7","schema_version":"edge-lab-recorder.raw.v1","sequence":null,"source":"clob_market_ws"}
{"event_at":"2026-07-27T03:10:46.253000Z","event_fingerprint":"99c6006dd2bfd3db05bd41c94c706805e541a4e0d7131f5ab03219a57d4268ff","payload":{"connection_id":"f95883f18d264834af91809e5f803e9f","event_at":"2026-07-27T03:10:46.253000Z","event_type":"price_change","frame_hash":"7ee52d7aff5b2d0fe8907e2dbfbead7e6df9e5e64cd7e1542e078c231b732a59","frame_index":0,"kind":"data","monotonic_ns":223829505903000,"payload":{"event_type":"price_change","market":"0xf9d60bb033695053c4d1d8592e52171c1042f64b41a4b72e09dcc6f4852b6670","price_changes":[{"asset_id":"8698449539441374295770236407991735029336433231649246775082939325523552031992","best_ask":"0.22","best_bid":"0.21","hash":"e6fb5b3ef3789508d632670f563bca8255623c90","price":"0.01","side":"BUY","size":"6839.52"},{"asset_id":"96283536366176669581486355171583722558858323126916278856549586825357358273536","best_ask":"0.79","best_bid":"0.78","hash":"49f6e8ad2a5d945d69a9f77c33cc78de7bbf2be5","price":"0.99","side":"SELL","size":"6839.52"}],"timestamp":"1785121846253"},"payload_hash":"343bda10d4296bcbb0767534b173f458abf6884cc07c577be8f7baf12f4dadc3","raw_frame":"{\"market\":\"0xf9d60bb033695053c4d1d8592e52171c1042f64b41a4b72e09dcc6f4852b6670\", \"price_changes\":[{\"asset_id\":\"8698449539441374295770236407991735029336433231649246775082939325523552031992\", \"price\":\"0.01\", \"size\":\"6839.52\", \"side\":\"BUY\", \"hash\":\"e6fb5b3ef3789508d632670f563bca8255623c90\", \"best_bid\":\"0.21\", \"best_ask\":\"0.22\"}, {\"asset_id\":\"96283536366176669581486355171583722558858323126916278856549586825357358273536\", \"price\":\"0.99\", \"size\":\"6839.52\", \"side\":\"SELL\", \"hash\":\"49f6e8ad2a5d945d69a9f77c33cc78de7bbf2be5\", \"best_bid\":\"0.78\", \"best_ask\":\"0.79\"}], \"timestamp\":\"1785121846253\", \"event_type\":\"price_change\"}","received_at":"2026-07-27T03:10:46.175803Z","schema_version":"clob-market-ws.price_change.v1","sequence":null,"server_hash":null,"server_timestamp":"1785121846253","session_id":"ff6d21c8283948938400a32613abec2c","source":"clob_market_ws"},"received_at":"2026-07-27T03:10:46.175803Z","record_id":"752024b685e496b13ca8387b2957958ddbadf98b7f731a47b332715317ef7b27","schema_fingerprint":"4aa3821a28b0b7c2400bc59aba4bcc0a76e971dadd19610d3ad38c768e124dc7","schema_version":"edge-lab-recorder.raw.v1","sequence":null,"source":"clob_market_ws"}
{"event_at":"2026-07-27T03:10:46.255000Z","event_fingerprint":"503a4681b7c0049fbf5c05a622446e66ccd7a493fc996a9470a9c2b704db9df4","payload":{"connection_id":"f95883f18d264834af91809e5f803e9f","event_at":"2026-07-27T03:10:46.255000Z","event_type":"price_change","frame_hash":"71b2a80fae724cd50d3d67744427a9d5f1c19d5dc21ef0b09a8851556ef4f638","frame_index":0,"kind":"data","monotonic_ns":223829507758291,"payload":{"event_type":"price_change","market":"0xf9d60bb033695053c4d1d8592e52171c1042f64b41a4b72e09dcc6f4852b6670","price_changes":[{"asset_id":"96283536366176669581486355171583722558858323126916278856549586825357358273536","best_ask":"0.79","best_bid":"0.78","hash":"c490f2e76907baa46690460c05379b2b50923ee3","price":"0.01","side":"BUY","size":"6919.52"},{"asset_id":"8698449539441374295770236407991735029336433231649246775082939325523552031992","best_ask":"0.22","best_bid":"0.21","hash":"6b7e6ee1c78af021c30b86d1cfc37ed29a611f9d","price":"0.99","side":"SELL","size":"6919.52"}],"timestamp":"1785121846255"},"payload_hash":"ef83fdbd842f48f96ae33ebf2c2fe2c12acc80bf32e4f7a3c7579cc45d93f000","raw_frame":"{\"market\":\"0xf9d60bb033695053c4d1d8592e52171c1042f64b41a4b72e09dcc6f4852b6670\", \"price_changes\":[{\"asset_id\":\"96283536366176669581486355171583722558858323126916278856549586825357358273536\", \"price\":\"0.01\", \"size\":\"6919.52\", \"side\":\"BUY\", \"hash\":\"c490f2e76907baa46690460c05379b2b50923ee3\", \"best_bid\":\"0.78\", \"best_ask\":\"0.79\"}, {\"asset_id\":\"8698449539441374295770236407991735029336433231649246775082939325523552031992\", \"price\":\"0.99\", \"size\":\"6919.52\", \"side\":\"SELL\", \"hash\":\"6b7e6ee1c78af021c30b86d1cfc37ed29a611f9d\", \"best_bid\":\"0.21\", \"best_ask\":\"0.22\"}], \"timestamp\":\"1785121846255\", \"event_type\":\"price_change\"}","received_at":"2026-07-27T03:10:46.177658Z","schema_version":"clob-market-ws.price_change.v1","sequence":null,"server_hash":null,"server_timestamp":"1785121846255","session_id":"ff6d21c8283948938400a32613abec2c","source":"clob_market_ws"},"received_at":"2026-07-27T03:10:46.177658Z","record_id":"316490a91f4d00a0d66fb552be8207800e1340db32cb250cec8cdfec16095c17","schema_fingerprint":"4aa3821a28b0b7c2400bc59aba4bcc0a76e971dadd19610d3ad38c768e124dc7","schema_version":"edge-lab-recorder.raw.v1","sequence":null,"source":"clob_market_ws"}
{"event_at":"2026-07-27T03:10:46.263000Z","event_fingerprint":"bcb180d4e737b3df3786e0cc0b66e988abf8b1c5fa2e761f49d2a66bcf21ceba","payload":{"connection_id":"f95883f18d264834af91809e5f803e9f","event_at":"2026-07-27T03:10:46.263000Z","event_type":"price_change","frame_hash":"3d6ca502f8e8aeb53d2c747e4ea6d36c93653decbde5fa10ff519025d2ef5465","frame_index":0,"kind":"data","monotonic_ns":223829509350000,"payload":{"event_type":"price_change","market":"0xf9d60bb033695053c4d1d8592e52171c1042f64b41a4b72e09dcc6f4852b6670","price_changes":[{"asset_id":"96283536366176669581486355171583722558858323126916278856549586825357358273536","best_ask":"0.79","best_bid":"0.78","hash":"fcfda70b7d0c7303d15e57a36319874dd640c6cf","price":"0.77","side":"BUY","size":"95.1"},{"asset_id":"8698449539441374295770236407991735029336433231649246775082939325523552031992","best_ask":"0.22","best_bid":"0.21","hash":"50ef01c765517e7c8b47ba787ed3a039d6c6af6f","price":"0.23","side":"SELL","size":"95.1"}],"timestamp":"1785121846263"},"payload_hash":"eed818d9ac6a5306ff65ceb50a1141dbfc69323f128571b5147a8c5ab760612d","raw_frame":"{\"market\":\"0xf9d60bb033695053c4d1d8592e52171c1042f64b41a4b72e09dcc6f4852b6670\", \"price_changes\":[{\"asset_id\":\"96283536366176669581486355171583722558858323126916278856549586825357358273536\", \"price\":\"0.77\", \"size\":\"95.1\", \"side\":\"BUY\", \"hash\":\"fcfda70b7d0c7303d15e57a36319874dd640c6cf\", \"best_bid\":\"0.78\", \"best_ask\":\"0.79\"}, {\"asset_id\":\"8698449539441374295770236407991735029336433231649246775082939325523552031992\", \"price\":\"0.23\", \"size\":\"95.1\", \"side\":\"SELL\", \"hash\":\"50ef01c765517e7c8b47ba787ed3a039d6c6af6f\", \"best_bid\":\"0.21\", \"best_ask\":\"0.22\"}], \"timestamp\":\"1785121846263\", \"event_type\":\"price_change\"}","received_at":"2026-07-27T03:10:46.179244Z","schema_version":"clob-market-ws.price_change.v1","sequence":null,"server_hash":null,"server_timestamp":"1785121846263","session_id":"ff6d21c8283948938400a32613abec2c","source":"clob_market_ws"},"received_at":"2026-07-27T03:10:46.179244Z","record_id":"a605a7fccc23331718c6fe00d984c9fb0366ce95be24e8f27e2a5ad15a165a12","schema_fingerprint":"4aa3821a28b0b7c2400bc59aba4bcc0a76e971dadd19610d3ad38c768e124dc7","schema_version":"edge-lab-recorder.raw.v1","sequence":null,"source":"clob_market_ws"}
{"event_at":"2026-07-27T03:10:46.266000Z","event_fingerprint":"b0c145dd14bfe720c0e822a2b9a7da57abe9d4f6cd5d5c123d59539b76080699","payload":{"connection_id":"f95883f18d264834af91809e5f803e9f","event_at":"2026-07-27T03:10:46.266000Z","event_type":"price_change","frame_hash":"a9a559882b709ddf1c4b5962a204399a7b52e72d66414861208d33c0571e3acf","frame_index":0,"kind":"data","monotonic_ns":223829512377000,"payload":{"event_type":"price_change","market":"0xf9d60bb033695053c4d1d8592e52171c1042f64b41a4b72e09dcc6f4852b6670","price_changes":[{"asset_id":"96283536366176669581486355171583722558858323126916278856549586825357358273536","best_ask":"0.79","best_bid":"0.78","hash":"60dc600c8bea55ee62361e88ab32f12befd08d7a","price":"0.01","side":"BUY","size":"6914.52"},{"asset_id":"8698449539441374295770236407991735029336433231649246775082939325523552031992","best_ask":"0.22","best_bid":"0.21","hash":"0f6cf2a7f918c34f52ce2dec4033270c7a1d1500","price":"0.99","side":"SELL","size":"6914.52"}],"timestamp":"1785121846266"},"payload_hash":"1d47b9523da82fbf1709fcdca94cba6531ec590e3ec5ccd6404b3c2b97cb32ca","raw_frame":"{\"market\":\"0xf9d60bb033695053c4d1d8592e52171c1042f64b41a4b72e09dcc6f4852b6670\", \"price_changes\":[{\"asset_id\":\"96283536366176669581486355171583722558858323126916278856549586825357358273536\", \"price\":\"0.01\", \"size\":\"6914.52\", \"side\":\"BUY\", \"hash\":\"60dc600c8bea55ee62361e88ab32f12befd08d7a\", \"best_bid\":\"0.78\", \"best_ask\":\"0.79\"}, {\"asset_id\":\"8698449539441374295770236407991735029336433231649246775082939325523552031992\", \"price\":\"0.99\", \"size\":\"6914.52\", \"side\":\"SELL\", \"hash\":\"0f6cf2a7f918c34f52ce2dec4033270c7a1d1500\", \"best_bid\":\"0.21\", \"best_ask\":\"0.22\"}], \"timestamp\":\"1785121846266\", \"event_type\":\"price_change\"}","received_at":"2026-07-27T03:10:46.182269Z","schema_version":"clob-market-ws.price_change.v1","sequence":null,"server_hash":null,"server_timestamp":"1785121846266","session_id":"ff6d21c8283948938400a32613abec2c","source":"clob_market_ws"},"received_at":"2026-07-27T03:10:46.182269Z","record_id":"ac970fdf50a977d89132166f69a374494d94435e7895eb95842d4ac5ce41303f","schema_fingerprint":"4aa3821a28b0b7c2400bc59aba4bcc0a76e971dadd19610d3ad38c768e124dc7","schema_version":"edge-lab-recorder.raw.v1","sequence":null,"source":"clob_market_ws"}
{"event_at":"2026-07-27T03:10:46.287000Z","event_fingerprint":"d73d6f6a8041e080068522432d356f9b8ffffa89541c1a5663e150756dfdf3ef","payload":{"connection_id":"f95883f18d264834af91809e5f803e9f","event_at":"2026-07-27T03:10:46.287000Z","event_type":"price_change","frame_hash":"b6311998003b3f00574daf20ce0a4268670d11394e12d787313333b5bbd5c6c2","frame_index":0,"kind":"data","monotonic_ns":223829521212125,"payload":{"event_type":"price_change","market":"0xf9d60bb033695053c4d1d8592e52171c1042f64b41a4b72e09dcc6f4852b6670","price_changes":[{"asset_id":"96283536366176669581486355171583722558858323126916278856549586825357358273536","best_ask":"0.79","best_bid":"0.78","hash":"bb6a51f5418c8c6bc0ff9126b8aca986bca5ad7e","price":"0.67","side":"BUY","size":"126.87"},{"asset_id":"8698449539441374295770236407991735029336433231649246775082939325523552031992","best_ask":"0.22","best_bid":"0.21","hash":"f5d5776cd40a0ecef03ec0a68330f537f987ea30","price":"0.33","side":"SELL","size":"126.87"}],"timestamp":"1785121846287"},"payload_hash":"afff9d5183318c9f5421559475aef94028d9914e19b18e65736a45966f6e46aa","raw_frame":"{\"market\":\"0xf9d60bb033695053c4d1d8592e52171c1042f64b41a4b72e09dcc6f4852b6670\", \"price_changes\":[{\"asset_id\":\"96283536366176669581486355171583722558858323126916278856549586825357358273536\", \"price\":\"0.67\", \"size\":\"126.87\", \"side\":\"BUY\", \"hash\":\"bb6a51f5418c8c6bc0ff9126b8aca986bca5ad7e\", \"best_bid\":\"0.78\", \"best_ask\":\"0.79\"}, {\"asset_id\":\"8698449539441374295770236407991735029336433231649246775082939325523552031992\", \"price\":\"0.33\", \"size\":\"126.87\", \"side\":\"SELL\", \"hash\":\"f5d5776cd40a0ecef03ec0a68330f537f987ea30\", \"best_bid\":\"0.21\", \"best_ask\":\"0.22\"}], \"timestamp\":\"1785121846287\", \"event_type\":\"price_change\"}","received_at":"2026-07-27T03:10:46.191111Z","schema_version":"clob-market-ws.price_change.v1","sequence":null,"server_hash":null,"server_timestamp":"1785121846287","session_id":"ff6d21c8283948938400a32613abec2c","source":"clob_market_ws"},"received_at":"2026-07-27T03:10:46.191111Z","record_id":"54ad42646f51a321f701ec40980b0a37339438dbae80267bb343fb36e8af31b1","schema_fingerprint":"4aa3821a28b0b7c2400bc59aba4bcc0a76e971dadd19610d3ad38c768e124dc7","schema_version":"edge-lab-recorder.raw.v1","sequence":null,"source":"clob_market_ws"}
{"event_at":"2026-07-27T03:10:46.293000Z","event_fingerprint":"a2dc49d730b3bc81243f6e5791bace3518632d650983afe9a01d028dea2aa279","payload":{"connection_id":"f95883f18d264834af91809e5f803e9f","event_at":"2026-07-27T03:10:46.293000Z","event_type":"price_change","frame_hash":"8624954f013a00daa0869c95b4d597d7935fc25e0b95d53570b07aebffb84717","frame_index":0,"kind":"data","monotonic_ns":223829526589125,"payload":{"event_type":"price_change","market":"0xf9d60bb033695053c4d1d8592e52171c1042f64b41a4b72e09dcc6f4852b6670","price_changes":[{"asset_id":"96283536366176669581486355171583722558858323126916278856549586825357358273536","best_ask":"0.79","best_bid":"0.78","hash":"ff210d976944599a497ccac1f1ee577de575f239","price":"0.72","side":"BUY","size":"114.8"},{"asset_id":"8698449539441374295770236407991735029336433231649246775082939325523552031992","best_ask":"0.22","best_bid":"0.21","hash":"c0a3f8f72024d6e5930d8e74a40b767a7ef5cd04","price":"0.28","side":"SELL","size":"114.8"}],"timestamp":"1785121846293"},"payload_hash":"cd2233d580fe19037ecdf14ec2d325a877c378bc67bde74b4c7525d8ea418914","raw_frame":"{\"market\":\"0xf9d60bb033695053c4d1d8592e52171c1042f64b41a4b72e09dcc6f4852b6670\", \"price_changes\":[{\"asset_id\":\"96283536366176669581486355171583722558858323126916278856549586825357358273536\", \"price\":\"0.72\", \"size\":\"114.8\", \"side\":\"BUY\", \"hash\":\"ff210d976944599a497ccac1f1ee577de575f239\", \"best_bid\":\"0.78\", \"best_ask\":\"0.79\"}, {\"asset_id\":\"8698449539441374295770236407991735029336433231649246775082939325523552031992\", \"price\":\"0.28\", \"size\":\"114.8\", \"side\":\"SELL\", \"hash\":\"c0a3f8f72024d6e5930d8e74a40b767a7ef5cd04\", \"best_bid\":\"0.21\", \"best_ask\":\"0.22\"}], \"timestamp\":\"1785121846293\", \"event_type\":\"price_change\"}","received_at":"2026-07-27T03:10:46.196474Z","schema_version":"clob-market-ws.price_change.v1","sequence":null,"server_hash":null,"server_timestamp":"1785121846293","session_id":"ff6d21c8283948938400a32613abec2c","source":"clob_market_ws"},"received_at":"2026-07-27T03:10:46.196474Z","record_id":"e4b022c97a7478d232fb60f75b22635c4345a415195e571956c0b451a6e83ec9","schema_fingerprint":"4aa3821a28b0b7c2400bc59aba4bcc0a76e971dadd19610d3ad38c768e124dc7","schema_version":"edge-lab-recorder.raw.v1","sequence":null,"source":"clob_market_ws"}
{"event_at":"2026-07-27T03:10:46.294000Z","event_fingerprint":"cc9f4fe040d5a69d805513450f8aad25f65e712109bb1ebdaa5c4686957c7156","payload":{"connection_id":"f95883f18d264834af91809e5f803e9f","event_at":"2026-07-27T03:10:46.294000Z","event_type":"price_change","frame_hash":"6f66849fdfc6f5647369c960350d36e6820d130c6dfd36d7aba27868c025537c","frame_index":0,"kind":"data","monotonic_ns":223829529595666,"payload":{"event_type":"price_change","market":"0xf9d60bb033695053c4d1d8592e52171c1042f64b41a4b72e09dcc6f4852b6670","price_changes":[{"asset_id":"96283536366176669581486355171583722558858323126916278856549586825357358273536","best_ask":"0.79","best_bid":"0.78","hash":"3a92752fdf49c14dde081fad4196990668bf2700","price":"0.72","side":"BUY","size":"119.8"},{"asset_id":"8698449539441374295770236407991735029336433231649246775082939325523552031992","best_ask":"0.22","best_bid":"0.21","hash":"a83a3f69e65cd3c4e33becfa4356e15b7e5e6c44","price":"0.28","side":"SELL","size":"119.8"}],"timestamp":"1785121846294"},"payload_hash":"dd060887160a7d6f136dab625f94e53d90f697788c6fe2fd829cad4eaa2066c3","raw_frame":"{\"market\":\"0xf9d60bb033695053c4d1d8592e52171c1042f64b41a4b72e09dcc6f4852b6670\", \"price_changes\":[{\"asset_id\":\"96283536366176669581486355171583722558858323126916278856549586825357358273536\", \"price\":\"0.72\", \"size\":\"119.8\", \"side\":\"BUY\", \"hash\":\"3a92752fdf49c14dde081fad4196990668bf2700\", \"best_bid\":\"0.78\", \"best_ask\":\"0.79\"}, {\"asset_id\":\"8698449539441374295770236407991735029336433231649246775082939325523552031992\", \"price\":\"0.28\", \"size\":\"119.8\", \"side\":\"SELL\", \"hash\":\"a83a3f69e65cd3c4e33becfa4356e15b7e5e6c44\", \"best_bid\":\"0.21\", \"best_ask\":\"0.22\"}], \"timestamp\":\"1785121846294\", \"event_type\":\"price_change\"}","received_at":"2026-07-27T03:10:46.199488Z","schema_version":"clob-market-ws.price_change.v1","sequence":null,"server_hash":null,"server_timestamp":"1785121846294","session_id":"ff6d21c8283948938400a32613abec2c","source":"clob_market_ws"},"received_at":"2026-07-27T03:10:46.199488Z","record_id":"8efef7829c9fbbb8098d14bd113dacb715a41782925ee3b35fe4b3f7ac3acf93","schema_fingerprint":"4aa3821a28b0b7c2400bc59aba4bcc0a76e971dadd19610d3ad38c768e124dc7","schema_version":"edge-lab-recorder.raw.v1","sequence":null,"source":"clob_market_ws"}
{"event_at":"2026-07-27T03:10:46.306000Z","event_fingerprint":"a3f755be504d0b33e5665d69d01c10e21d8e0b234d52cde5aa97f94636b04f7f","payload":{"connection_id":"f95883f18d264834af91809e5f803e9f","event_at":"2026-07-27T03:10:46.306000Z","event_type":"price_change","frame_hash":"5fe85c245d24a5bcb20fbc2540d23c600f8d06d5160be4c4dd48763acd1adeee","frame_index":0,"kind":"data","monotonic_ns":223829543469333,"payload":{"event_type":"price_change","market":"0xf9d60bb033695053c4d1d8592e52171c1042f64b41a4b72e09dcc6f4852b6670","price_changes":[{"asset_id":"96283536366176669581486355171583722558858323126916278856549586825357358273536","best_ask":"0.79","best_bid":"0.78","hash":"8d0358cfe02fd03bbd4fd37968e647ee87637b9d","price":"0.78","side":"BUY","size":"132.1"},{"asset_id":"8698449539441374295770236407991735029336433231649246775082939325523552031992","best_ask":"0.22","best_bid":"0.21","hash":"fb5e32cc13ceca9bcc995c2771ff83629f7e89a1","price":"0.22","side":"SELL","size":"132.1"}],"timestamp":"1785121846306"},"payload_hash":"dd2f30d98193a651b26aba083ba3e2f1df08906ed10ef433ed7bf87698f6a449","raw_frame":"{\"market\":\"0xf9d60bb033695053c4d1d8592e52171c1042f64b41a4b72e09dcc6f4852b6670\", \"price_changes\":[{\"asset_id\":\"96283536366176669581486355171583722558858323126916278856549586825357358273536\", \"price\":\"0.78\", \"size\":\"132.1\", \"side\":\"BUY\", \"hash\":\"8d0358cfe02fd03bbd4fd37968e647ee87637b9d\", \"best_bid\":\"0.78\", \"best_ask\":\"0.79\"}, {\"asset_id\":\"8698449539441374295770236407991735029336433231649246775082939325523552031992\", \"price\":\"0.22\", \"size\":\"132.1\", \"side\":\"SELL\", \"hash\":\"fb5e32cc13ceca9bcc995c2771ff83629f7e89a1\", \"best_bid\":\"0.21\", \"best_ask\":\"0.22\"}], \"timestamp\":\"1785121846306\", \"event_type\":\"price_change\"}","received_at":"2026-07-27T03:10:46.213363Z","schema_version":"clob-market-ws.price_change.v1","sequence":null,"server_hash":null,"server_timestamp":"1785121846306","session_id":"ff6d21c8283948938400a32613abec2c","source":"clob_market_ws"},"received_at":"2026-07-27T03:10:46.213363Z","record_id":"6df2bd72d8ed47f122246d57b9aac2f0c4295a38bf6392349c613c26a0ded406","schema_fingerprint":"4aa3821a28b0b7c2400bc59aba4bcc0a76e971dadd19610d3ad38c768e124dc7","schema_version":"edge-lab-recorder.raw.v1","sequence":null,"source":"clob_market_ws"}
{"event_at":"2026-07-27T03:10:46.320000Z","event_fingerprint":"9ec47b26e868542edd0d8909dc40e19ee033c24f66d2de44e1eae30c5a09aa7e","payload":{"connection_id":"f95883f18d264834af91809e5f803e9f","event_at":"2026-07-27T03:10:46.320000Z","event_type":"price_change","frame_hash":"5b3f7468d76841420fd5f331712f9455b00f7d297bdfa9823e42f39cc1839988","frame_index":0,"kind":"data","monotonic_ns":223829555311333,"payload":{"event_type":"price_change","market":"0xf9d60bb033695053c4d1d8592e52171c1042f64b41a4b72e09dcc6f4852b6670","price_changes":[{"asset_id":"8698449539441374295770236407991735029336433231649246775082939325523552031992","best_ask":"0.22","best_bid":"0.21","hash":"1f9662325cf6230fdad85700177448fb16800fe5","price":"0.33","side":"SELL","size":"131.87"},{"asset_id":"96283536366176669581486355171583722558858323126916278856549586825357358273536","best_ask":"0.79","best_bid":"0.78","hash":"2c2c65d2808bb46c0a23e4a046e45feeb17aaba0","price":"0.67","side":"BUY","size":"131.87"}],"timestamp":"1785121846320"},"payload_hash":"26273dfebbd322f6dda5979db2356fd1e382728c6dbd5db8e610eb1ffdc99ff4","raw_frame":"{\"market\":\"0xf9d60bb033695053c4d1d8592e52171c1042f64b41a4b72e09dcc6f4852b6670\", \"price_changes\":[{\"asset_id\":\"8698449539441374295770236407991735029336433231649246775082939325523552031992\", \"price\":\"0.33\", \"size\":\"131.87\", \"side\":\"SELL\", \"hash\":\"1f9662325cf6230fdad85700177448fb16800fe5\", \"best_bid\":\"0.21\", \"best_ask\":\"0.22\"}, {\"asset_id\":\"96283536366176669581486355171583722558858323126916278856549586825357358273536\", \"price\":\"0.67\", \"size\":\"131.87\", \"side\":\"BUY\", \"hash\":\"2c2c65d2808bb46c0a23e4a046e45feeb17aaba0\", \"best_bid\":\"0.78\", \"best_ask\":\"0.79\"}], \"timestamp\":\"1785121846320\", \"event_type\":\"price_change\"}","received_at":"2026-07-27T03:10:46.225201Z","schema_version":"clob-market-ws.price_change.v1","sequence":null,"server_hash":null,"server_timestamp":"1785121846320","session_id":"ff6d21c8283948938400a32613abec2c","source":"clob_market_ws"},"received_at":"2026-07-27T03:10:46.225201Z","record_id":"9ccca223fbe978baf1c9990b08cde4b13054433dd0fd3d4c00adb16a024ec774","schema_fingerprint":"4aa3821a28b0b7c2400bc59aba4bcc0a76e971dadd19610d3ad38c768e124dc7","schema_version":"edge-lab-recorder.raw.v1","sequence":null,"source":"clob_market_ws"}
{"event_at":"2026-07-27T03:10:46.321000Z","event_fingerprint":"63b731ed879060f3fdf524a9389adc5ca91065d655372f79615f3d3886b178d5","payload":{"connection_id":"f95883f18d264834af91809e5f803e9f","event_at":"2026-07-27T03:10:46.321000Z","event_type":"price_change","frame_hash":"8cc42516837a7284a4911c81c1382878eb0c44d2a546734df7fa48ee1a9bba49","frame_index":0,"kind":"data","monotonic_ns":223829561541000,"payload":{"event_type":"price_change","market":"0xf9d60bb033695053c4d1d8592e52171c1042f64b41a4b72e09dcc6f4852b6670","price_changes":[{"asset_id":"96283536366176669581486355171583722558858323126916278856549586825357358273536","best_ask":"0.79","best_bid":"0.78","hash":"49dd8f2e5f4c6eb11d6b0826c9019665eb7f578f","price":"0.72","side":"BUY","size":"124.8"},{"asset_id":"8698449539441374295770236407991735029336433231649246775082939325523552031992","best_ask":"0.22","best_bid":"0.21","hash":"d5b452a898762fa20f89008d4b1ba54f93063d3a","price":"0.28","side":"SELL","size":"124.8"}],"timestamp":"1785121846321"},"payload_hash":"effb4e891762e98a1f3dc95309be0826a4841efb8dcf41b6750697a4dc8e8903","raw_frame":"{\"market\":\"0xf9d60bb033695053c4d1d8592e52171c1042f64b41a4b72e09dcc6f4852b6670\", \"price_changes\":[{\"asset_id\":\"96283536366176669581486355171583722558858323126916278856549586825357358273536\", \"price\":\"0.72\", \"size\":\"124.8\", \"side\":\"BUY\", \"hash\":\"49dd8f2e5f4c6eb11d6b0826c9019665eb7f578f\", \"best_bid\":\"0.78\", \"best_ask\":\"0.79\"}, {\"asset_id\":\"8698449539441374295770236407991735029336433231649246775082939325523552031992\", \"price\":\"0.28\", \"size\":\"124.8\", \"side\":\"SELL\", \"hash\":\"d5b452a898762fa20f89008d4b1ba54f93063d3a\", \"best_bid\":\"0.21\", \"best_ask\":\"0.22\"}], \"timestamp\":\"1785121846321\", \"event_type\":\"price_change\"}","received_at":"2026-07-27T03:10:46.231427Z","schema_version":"clob-market-ws.price_change.v1","sequence":null,"server_hash":null,"server_timestamp":"1785121846321","session_id":"ff6d21c8283948938400a32613abec2c","source":"clob_market_ws"},"received_at":"2026-07-27T03:10:46.231427Z","record_id":"f2d2c959573359141cab34300c14e3dc80b81d6838a4804c5728b50ef0ddf633","schema_fingerprint":"4aa3821a28b0b7c2400bc59aba4bcc0a76e971dadd19610d3ad38c768e124dc7","schema_version":"edge-lab-recorder.raw.v1","sequence":null,"source":"clob_market_ws"}
{"event_at":"2026-07-27T03:10:46.324000Z","event_fingerprint":"dfbf4b0f04870a9796117b143dcf7b95e7265c718d9a6906fff429ac8163e25b","payload":{"connection_id":"f95883f18d264834af91809e5f803e9f","event_at":"2026-07-27T03:10:46.324000Z","event_type":"price_change","frame_hash":"7a9b0063b8268f175b96ddb7dc23a9de136f9f0a55da786991ca2604c4aa2208","frame_index":0,"kind":"data","monotonic_ns":223829566274500,"payload":{"event_type":"price_change","market":"0xf9d60bb033695053c4d1d8592e52171c1042f64b41a4b72e09dcc6f4852b6670","price_changes":[{"asset_id":"8698449539441374295770236407991735029336433231649246775082939325523552031992","best_ask":"0.22","best_bid":"0.21","hash":"210b3efb01d9ce87971778aca1ec0bd7e4aa85b6","price":"0.21","side":"BUY","size":"27.23"},{"asset_id":"96283536366176669581486355171583722558858323126916278856549586825357358273536","best_ask":"0.79","best_bid":"0.78","hash":"b08f690fa59b44766df23ba9a36994c6b3f6fcd5","price":"0.79","side":"SELL","size":"27.23"}],"timestamp":"1785121846324"},"payload_hash":"59be01c9f62d04fa605b8a5f4f62ff6ce09b74f9ef937e3c2f83c3314d166e9f","raw_frame":"{\"market\":\"0xf9d60bb033695053c4d1d8592e52171c1042f64b41a4b72e09dcc6f4852b6670\", \"price_changes\":[{\"asset_id\":\"8698449539441374295770236407991735029336433231649246775082939325523552031992\", \"price\":\"0.21\", \"size\":\"27.23\", \"side\":\"BUY\", \"hash\":\"210b3efb01d9ce87971778aca1ec0bd7e4aa85b6\", \"best_bid\":\"0.21\", \"best_ask\":\"0.22\"}, {\"asset_id\":\"96283536366176669581486355171583722558858323126916278856549586825357358273536\", \"price\":\"0.79\", \"size\":\"27.23\", \"side\":\"SELL\", \"hash\":\"b08f690fa59b44766df23ba9a36994c6b3f6fcd5\", \"best_bid\":\"0.78\", \"best_ask\":\"0.79\"}], \"timestamp\":\"1785121846324\", \"event_type\":\"price_change\"}","received_at":"2026-07-27T03:10:46.236165Z","schema_version":"clob-market-ws.price_change.v1","sequence":null,"server_hash":null,"server_timestamp":"1785121846324","session_id":"ff6d21c8283948938400a32613abec2c","source":"clob_market_ws"},"received_at":"2026-07-27T03:10:46.236165Z","record_id":"84105e640620a1104ea0663a15a618f45992ceba41a35a9da7863e9451872a9f","schema_fingerprint":"4aa3821a28b0b7c2400bc59aba4bcc0a76e971dadd19610d3ad38c768e124dc7","schema_version":"edge-lab-recorder.raw.v1","sequence":null,"source":"clob_market_ws"}
{"event_at":"2026-07-27T03:10:46.327000Z","event_fingerprint":"6e58a217eb79bc429c95173c8fce8303426691783995c00e617547fa66b89556","payload":{"connection_id":"f95883f18d264834af91809e5f803e9f","event_at":"2026-07-27T03:10:46.327000Z","event_type":"price_change","frame_hash":"be8262d73e706799865abad882fc476cf16b8f2d4c930d92971e27dd2b29319a","frame_index":0,"kind":"data","monotonic_ns":223829569467583,"payload":{"event_type":"price_change","market":"0xf9d60bb033695053c4d1d8592e52171c1042f64b41a4b72e09dcc6f4852b6670","price_changes":[{"asset_id":"8698449539441374295770236407991735029336433231649246775082939325523552031992","best_ask":"0.22","best_bid":"0.21","hash":"6c28c4694fc36f649eadea3524547ba9014e6a47","price":"0.24","side":"SELL","size":"110"},{"asset_id":"96283536366176669581486355171583722558858323126916278856549586825357358273536","best_ask":"0.79","best_bid":"0.78","hash":"2a10e1c915cb7e18a89cda62c419b22625a81cb7","price":"0.76","side":"BUY","size":"110"}],"timestamp":"1785121846327"},"payload_hash":"95cbfb6c90944973ea5fe90d6b61c189b4fa77861b766f5fbecf2b8cabde2a98","raw_frame":"{\"market\":\"0xf9d60bb033695053c4d1d8592e52171c1042f64b41a4b72e09dcc6f4852b6670\", \"price_changes\":[{\"asset_id\":\"8698449539441374295770236407991735029336433231649246775082939325523552031992\", \"price\":\"0.24\", \"size\":\"110\", \"side\":\"SELL\", \"hash\":\"6c28c4694fc36f649eadea3524547ba9014e6a47\", \"best_bid\":\"0.21\", \"best_ask\":\"0.22\"}, {\"asset_id\":\"96283536366176669581486355171583722558858323126916278856549586825357358273536\", \"price\":\"0.76\", \"size\":\"110\", \"side\":\"BUY\", \"hash\":\"2a10e1c915cb7e18a89cda62c419b22625a81cb7\", \"best_bid\":\"0.78\", \"best_ask\":\"0.79\"}], \"timestamp\":\"1785121846327\", \"event_type\":\"price_change\"}","received_at":"2026-07-27T03:10:46.239359Z","schema_version":"clob-market-ws.price_change.v1","sequence":null,"server_hash":null,"server_timestamp":"1785121846327","session_id":"ff6d21c8283948938400a32613abec2c","source":"clob_market_ws"},"received_at":"2026-07-27T03:10:46.239359Z","record_id":"c459fa9432bb847a24c72c4ee7e846f67d5e4b8d24a40f98c00276c852f85dbe","schema_fingerprint":"4aa3821a28b0b7c2400bc59aba4bcc0a76e971dadd19610d3ad38c768e124dc7","schema_version":"edge-lab-recorder.raw.v1","sequence":null,"source":"clob_market_ws"}
{"event_at":"2026-07-27T03:10:46.327000Z","event_fingerprint":"b6deaaabc4acae58f1fca0c5edea2e51959a3a2fc0638e9f77b517be94c3a73b","payload":{"connection_id":"f95883f18d264834af91809e5f803e9f","event_at":"2026-07-27T03:10:46.327000Z","event_type":"price_change","frame_hash":"372ac2058f5cecf74979086c8b6f795cb13f696cff918725d99a3ecdf506cf69","frame_index":0,"kind":"data","monotonic_ns":223829572679750,"payload":{"event_type":"price_change","market":"0xf9d60bb033695053c4d1d8592e52171c1042f64b41a4b72e09dcc6f4852b6670","price_changes":[{"asset_id":"8698449539441374295770236407991735029336433231649246775082939325523552031992","best_ask":"0.22","best_bid":"0.21","hash":"6c28c4694fc36f649eadea3524547ba9014e6a47","price":"0.25","side":"SELL","size":"100"},{"asset_id":"96283536366176669581486355171583722558858323126916278856549586825357358273536","best_ask":"0.79","best_bid":"0.78","hash":"2a10e1c915cb7e18a89cda62c419b22625a81cb7","price":"0.75","side":"BUY","size":"100"}],"timestamp":"1785121846327"},"payload_hash":"305a601773a0d37c60e0b28c7b2bd91670be1a693211b79e82b833c432a3e16e","raw_frame":"{\"market\":\"0xf9d60bb033695053c4d1d8592e52171c1042f64b41a4b72e09dcc6f4852b6670\", \"price_changes\":[{\"asset_id\":\"8698449539441374295770236407991735029336433231649246775082939325523552031992\", \"price\":\"0.25\", \"size\":\"100\", \"side\":\"SELL\", \"hash\":\"6c28c4694fc36f649eadea3524547ba9014e6a47\", \"best_bid\":\"0.21\", \"best_ask\":\"0.22\"}, {\"asset_id\":\"96283536366176669581486355171583722558858323126916278856549586825357358273536\", \"price\":\"0.75\", \"size\":\"100\", \"side\":\"BUY\", \"hash\":\"2a10e1c915cb7e18a89cda62c419b22625a81cb7\", \"best_bid\":\"0.78\", \"best_ask\":\"0.79\"}], \"timestamp\":\"1785121846327\", \"event_type\":\"price_change\"}","received_at":"2026-07-27T03:10:46.242573Z","schema_version":"clob-market-ws.price_change.v1","sequence":null,"server_hash":null,"server_timestamp":"1785121846327","session_id":"ff6d21c8283948938400a32613abec2c","source":"clob_market_ws"},"received_at":"2026-07-27T03:10:46.242573Z","record_id":"459f6f604f353ade49f17eb99d7dcbb8a5cc329eed9e5537c727038e0402a1d0","schema_fingerprint":"4aa3821a28b0b7c2400bc59aba4bcc0a76e971dadd19610d3ad38c768e124dc7","schema_version":"edge-lab-recorder.raw.v1","sequence":null,"source":"clob_market_ws"}
{"event_at":"2026-07-27T03:10:46.345000Z","event_fingerprint":"75a2621785b08bd4f8e936c2ac62b258f917e35be2d6a3803a93a63457854fb2","payload":{"connection_id":"f95883f18d264834af91809e5f803e9f","event_at":"2026-07-27T03:10:46.345000Z","event_type":"price_change","frame_hash":"8096157f0bd8b67532f0f8dac16432443ca34a7958b79ee87daf9132fc905ed5","frame_index":0,"kind":"data","monotonic_ns":223829577501583,"payload":{"event_type":"price_change","market":"0xf9d60bb033695053c4d1d8592e52171c1042f64b41a4b72e09dcc6f4852b6670","price_changes":[{"asset_id":"96283536366176669581486355171583722558858323126916278856549586825357358273536","best_ask":"0.79","best_bid":"0.78","hash":"00e4d9f071e56646c053cd00fbb8cc91e336070c","price":"0.01","side":"BUY","size":"6919.52"},{"asset_id":"8698449539441374295770236407991735029336433231649246775082939325523552031992","best_ask":"0.22","best_bid":"0.21","hash":"a39e7d38bc8c528ce7a521ac7f3aa2168090cfd2","price":"0.99","side":"SELL","size":"6919.52"}],"timestamp":"1785121846345"},"payload_hash":"d378635d7375f98c2229c8bf2ca82eac27a156856fb1c8e06f24346c4b68630c","raw_frame":"{\"market\":\"0xf9d60bb033695053c4d1d8592e52171c1042f64b41a4b72e09dcc6f4852b6670\", \"price_changes\":[{\"asset_id\":\"96283536366176669581486355171583722558858323126916278856549586825357358273536\", \"price\":\"0.01\", \"size\":\"6919.52\", \"side\":\"BUY\", \"hash\":\"00e4d9f071e56646c053cd00fbb8cc91e336070c\", \"best_bid\":\"0.78\", \"best_ask\":\"0.79\"}, {\"asset_id\":\"8698449539441374295770236407991735029336433231649246775082939325523552031992\", \"price\":\"0.99\", \"size\":\"6919.52\", \"side\":\"SELL\", \"hash\":\"a39e7d38bc8c528ce7a521ac7f3aa2168090cfd2\", \"best_bid\":\"0.21\", \"best_ask\":\"0.22\"}], \"timestamp\":\"1785121846345\", \"event_type\":\"price_change\"}","received_at":"2026-07-27T03:10:46.247394Z","schema_version":"clob-market-ws.price_change.v1","sequence":null,"server_hash":null,"server_timestamp":"1785121846345","session_id":"ff6d21c8283948938400a32613abec2c","source":"clob_market_ws"},"received_at":"2026-07-27T03:10:46.247394Z","record_id":"56d5147b83e7667fb81f768862e443fb51d3273a9fd6c84edd679d28531293be","schema_fingerprint":"4aa3821a28b0b7c2400bc59aba4bcc0a76e971dadd19610d3ad38c768e124dc7","schema_version":"edge-lab-recorder.raw.v1","sequence":null,"source":"clob_market_ws"}
{"event_at":"2026-07-27T03:10:46.362000Z","event_fingerprint":"c2aebc361757f55cfa03847c43bbc8101b583e5a1bfa2dafc8bfb1953f86cea3","payload":{"connection_id":"f95883f18d264834af91809e5f803e9f","event_at":"2026-07-27T03:10:46.362000Z","event_type":"price_change","frame_hash":"43a98b3213bc6495d8869604e1568653e25b9307a91c470e4a89a4e6a6ebb24c","frame_index":0,"kind":"data","monotonic_ns":223829593512166,"payload":{"event_type":"price_change","market":"0xf9d60bb033695053c4d1d8592e52171c1042f64b41a4b72e09dcc6f4852b6670","price_changes":[{"asset_id":"96283536366176669581486355171583722558858323126916278856549586825357358273536","best_ask":"0.79","best_bid":"0.78","hash":"8f1e5904dc81b358221d0503cb594a7b9aa9e831","price":"0.72","side":"BUY","size":"114.8"},{"asset_id":"8698449539441374295770236407991735029336433231649246775082939325523552031992","best_ask":"0.22","best_bid":"0.21","hash":"bd0481eaa8c697ff21e57574273fcbaa8a316471","price":"0.28","side":"SELL","size":"114.8"}],"timestamp":"1785121846362"},"payload_hash":"2bc618304035faa3da6a433b01a37d26cb318ae7bbbc9952cb40d7ec24b06135","raw_frame":"{\"market\":\"0xf9d60bb033695053c4d1d8592e52171c1042f64b41a4b72e09dcc6f4852b6670\", \"price_changes\":[{\"asset_id\":\"96283536366176669581486355171583722558858323126916278856549586825357358273536\", \"price\":\"0.72\", \"size\":\"114.8\", \"side\":\"BUY\", \"hash\":\"8f1e5904dc81b358221d0503cb594a7b9aa9e831\", \"best_bid\":\"0.78\", \"best_ask\":\"0.79\"}, {\"asset_id\":\"8698449539441374295770236407991735029336433231649246775082939325523552031992\", \"price\":\"0.28\", \"size\":\"114.8\", \"side\":\"SELL\", \"hash\":\"bd0481eaa8c697ff21e57574273fcbaa8a316471\", \"best_bid\":\"0.21\", \"best_ask\":\"0.22\"}], \"timestamp\":\"1785121846362\", \"event_type\":\"price_change\"}","received_at":"2026-07-27T03:10:46.263404Z","schema_version":"clob-market-ws.price_change.v1","sequence":null,"server_hash":null,"server_timestamp":"1785121846362","session_id":"ff6d21c8283948938400a32613abec2c","source":"clob_market_ws"},"received_at":"2026-07-27T03:10:46.263404Z","record_id":"4db23f76365ca9ff46817a8f9835d0ee12e815d3665b170b71c18a11a1b788a9","schema_fingerprint":"4aa3821a28b0b7c2400bc59aba4bcc0a76e971dadd19610d3ad38c768e124dc7","schema_version":"edge-lab-recorder.raw.v1","sequence":null,"source":"clob_market_ws"}
{"event_at":"2026-07-27T03:10:46.362000Z","event_fingerprint":"97a6113c119d74b3568f3fa718ac69fbd247f9be4380645902201410bc18dbce","payload":{"connection_id":"f95883f18d264834af91809e5f803e9f","event_at":"2026-07-27T03:10:46.362000Z","event_type":"price_change","frame_hash":"3238098a1c8c959b3cf444a59aa67f306c96b817c36541804adb2d30885631ae","frame_index":0,"kind":"data","monotonic_ns":223829596341416,"payload":{"event_type":"price_change","market":"0xf9d60bb033695053c4d1d8592e52171c1042f64b41a4b72e09dcc6f4852b6670","price_changes":[{"asset_id":"96283536366176669581486355171583722558858323126916278856549586825357358273536","best_ask":"0.79","best_bid":"0.78","hash":"8f1e5904dc81b358221d0503cb594a7b9aa9e831","price":"0.78","side":"BUY","size":"127.1"},{"asset_id":"8698449539441374295770236407991735029336433231649246775082939325523552031992","best_ask":"0.22","best_bid":"0.21","hash":"bd0481eaa8c697ff21e57574273fcbaa8a316471","price":"0.22","side":"SELL","size":"127.1"}],"timestamp":"1785121846362"},"payload_hash":"69a4569326d8a5a81b6919d59ef016cddf14c8899944dba2a81d88c97aede9e0","raw_frame":"{\"market\":\"0xf9d60bb033695053c4d1d8592e52171c1042f64b41a4b72e09dcc6f4852b6670\", \"price_changes\":[{\"asset_id\":\"96283536366176669581486355171583722558858323126916278856549586825357358273536\", \"price\":\"0.78\", \"size\":\"127.1\", \"side\":\"BUY\", \"hash\":\"8f1e5904dc81b358221d0503cb594a7b9aa9e831\", \"best_bid\":\"0.78\", \"best_ask\":\"0.79\"}, {\"asset_id\":\"8698449539441374295770236407991735029336433231649246775082939325523552031992\", \"price\":\"0.22\", \"size\":\"127.1\", \"side\":\"SELL\", \"hash\":\"bd0481eaa8c697ff21e57574273fcbaa8a316471\", \"best_bid\":\"0.21\", \"best_ask\":\"0.22\"}], \"timestamp\":\"1785121846362\", \"event_type\":\"price_change\"}","received_at":"2026-07-27T03:10:46.266234Z","schema_version":"clob-market-ws.price_change.v1","sequence":null,"server_hash":null,"server_timestamp":"1785121846362","session_id":"ff6d21c8283948938400a32613abec2c","source":"clob_market_ws"},"received_at":"2026-07-27T03:10:46.266234Z","record_id":"f80c4b090c33418c3954ba859bce9f51d19d49f25851b814572aa703184a9718","schema_fingerprint":"4aa3821a28b0b7c2400bc59aba4bcc0a76e971dadd19610d3ad38c768e124dc7","schema_version":"edge-lab-recorder.raw.v1","sequence":null,"source":"clob_market_ws"}
{"event_at":"2026-07-27T03:10:46.381000Z","event_fingerprint":"4bf61a6e2410da985ac7374c9ccb561262d9fb99390bd924b5fa3fa184cf8e9e","payload":{"connection_id":"f95883f18d264834af91809e5f803e9f","event_at":"2026-07-27T03:10:46.381000Z","event_type":"price_change","frame_hash":"0fbb551a191a2fb2626c2139911e8c0049ab4f7ddb3489ec5c563408c473b6d9","frame_index":0,"kind":"data","monotonic_ns":223829616267916,"payload":{"event_type":"price_change","market":"0xf9d60bb033695053c4d1d8592e52171c1042f64b41a4b72e09dcc6f4852b6670","price_changes":[{"asset_id":"8698449539441374295770236407991735029336433231649246775082939325523552031992","best_ask":"0.22","best_bid":"0.21","hash":"94b6ed40c9e879c2c49be0865e6885c224cab109","price":"0.33","side":"SELL","size":"126.87"},{"asset_id":"96283536366176669581486355171583722558858323126916278856549586825357358273536","best_ask":"0.79","best_bid":"0.78","hash":"2dd373a54726793e97e7914ab7e9938168cbd1bf","price":"0.67","side":"BUY","size":"126.87"}],"timestamp":"1785121846381"},"payload_hash":"aece14fc92121b1d395df3b2c52cce9d4ab3a062ef1d71b8c9e80126b11d0a69","raw_frame":"{\"market\":\"0xf9d60bb033695053c4d1d8592e52171c1042f64b41a4b72e09dcc6f4852b6670\", \"price_changes\":[{\"asset_id\":\"8698449539441374295770236407991735029336433231649246775082939325523552031992\", \"price\":\"0.33\", \"size\":\"126.87\", \"side\":\"SELL\", \"hash\":\"94b6ed40c9e879c2c49be0865e6885c224cab109\", \"best_bid\":\"0.21\", \"best_ask\":\"0.22\"}, {\"asset_id\":\"96283536366176669581486355171583722558858323126916278856549586825357358273536\", \"price\":\"0.67\", \"size\":\"126.87\", \"side\":\"BUY\", \"hash\":\"2dd373a54726793e97e7914ab7e9938168cbd1bf\", \"best_bid\":\"0.78\", \"best_ask\":\"0.79\"}], \"timestamp\":\"1785121846381\", \"event_type\":\"price_change\"}","received_at":"2026-07-27T03:10:46.286158Z","schema_version":"clob-market-ws.price_change.v1","sequence":null,"server_hash":null,"server_timestamp":"1785121846381","session_id":"ff6d21c8283948938400a32613abec2c","source":"clob_market_ws"},"received_at":"2026-07-27T03:10:46.286158Z","record_id":"f9d88fd20050d805f6020698ab61c9db8cb5e0dc667a4099823371a0b7e6db61","schema_fingerprint":"4aa3821a28b0b7c2400bc59aba4bcc0a76e971dadd19610d3ad38c768e124dc7","schema_version":"edge-lab-recorder.raw.v1","sequence":null,"source":"clob_market_ws"}
{"event_at":"2026-07-27T03:10:46.388000Z","event_fingerprint":"14b62002ea8d1e13eced2581800f9758b5871105293d4f101bdcdf707b21a431","payload":{"connection_id":"f95883f18d264834af91809e5f803e9f","event_at":"2026-07-27T03:10:46.388000Z","event_type":"price_change","frame_hash":"1eed63bbeb2dfed25c1e76c16024fd7b65c0f477befb011af96fc52605f9a709","frame_index":0,"kind":"data","monotonic_ns":223829620350666,"payload":{"event_type":"price_change","market":"0xf9d60bb033695053c4d1d8592e52171c1042f64b41a4b72e09dcc6f4852b6670","price_changes":[{"asset_id":"96283536366176669581486355171583722558858323126916278856549586825357358273536","best_ask":"0.79","best_bid":"0.78","hash":"d8109afaf9b58ba35778038019a4ac774e9d1819","price":"0.77","side":"BUY","size":"100.1"},{"asset_id":"8698449539441374295770236407991735029336433231649246775082939325523552031992","best_ask":"0.22","best_bid":"0.21","hash":"dcb2b0720aba8cbe699793e5224f601bfc955795","price":"0.23","side":"SELL","size":"100.1"}],"timestamp":"1785121846388"},"payload_hash":"bdb2003593c8bf3ea5b61d340b91a739a692a15cab61c9b8fd3e873a6b315f93","raw_frame":"{\"market\":\"0xf9d60bb033695053c4d1d8592e52171c1042f64b41a4b72e09dcc6f4852b6670\", \"price_changes\":[{\"asset_id\":\"96283536366176669581486355171583722558858323126916278856549586825357358273536\", \"price\":\"0.77\", \"size\":\"100.1\", \"side\":\"BUY\", \"hash\":\"d8109afaf9b58ba35778038019a4ac774e9d1819\", \"best_bid\":\"0.78\", \"best_ask\":\"0.79\"}, {\"asset_id\":\"8698449539441374295770236407991735029336433231649246775082939325523552031992\", \"price\":\"0.23\", \"size\":\"100.1\", \"side\":\"SELL\", \"hash\":\"dcb2b0720aba8cbe699793e5224f601bfc955795\", \"best_bid\":\"0.21\", \"best_ask\":\"0.22\"}], \"timestamp\":\"1785121846388\", \"event_type\":\"price_change\"}","received_at":"2026-07-27T03:10:46.290240Z","schema_version":"clob-market-ws.price_change.v1","sequence":null,"server_hash":null,"server_timestamp":"1785121846388","session_id":"ff6d21c8283948938400a32613abec2c","source":"clob_market_ws"},"received_at":"2026-07-27T03:10:46.290240Z","record_id":"5281af9ae3b58a46ca06281cdb5e6a87668a949d31894946e3ed91e45c3c9c2c","schema_fingerprint":"4aa3821a28b0b7c2400bc59aba4bcc0a76e971dadd19610d3ad38c768e124dc7","schema_version":"edge-lab-recorder.raw.v1","sequence":null,"source":"clob_market_ws"}
{"event_at":"2026-07-27T03:10:46.408000Z","event_fingerprint":"023e748bb62e347b7521af26895d260a26f4b987dbc77b1f9d506326e8919c87","payload":{"connection_id":"f95883f18d264834af91809e5f803e9f","event_at":"2026-07-27T03:10:46.408000Z","event_type":"price_change","frame_hash":"18203836986dc09c467a8527dcedcfb13209b091add053cdbc6b38ea7a61f07a","frame_index":0,"kind":"data","monotonic_ns":223829639546000,"payload":{"event_type":"price_change","market":"0xf9d60bb033695053c4d1d8592e52171c1042f64b41a4b72e09dcc6f4852b6670","price_changes":[{"asset_id":"96283536366176669581486355171583722558858323126916278856549586825357358273536","best_ask":"0.79","best_bid":"0.78","hash":"53ff63557e477ced9f68dfd363cd7bf68a794dd7","price":"0.67","side":"BUY","size":"131.87"},{"asset_id":"8698449539441374295770236407991735029336433231649246775082939325523552031992","best_ask":"0.22","best_bid":"0.21","hash":"b6dfef6ee495604d360e3ef1d13c92ad87273010","price":"0.33","side":"SELL","size":"131.87"}],"timestamp":"1785121846408"},"payload_hash":"581663852061e881f8399978c6331dda50ba9be6ad48069e6fcdc33131d36a59","raw_frame":"{\"market\":\"0xf9d60bb033695053c4d1d8592e52171c1042f64b41a4b72e09dcc6f4852b6670\", \"price_changes\":[{\"asset_id\":\"96283536366176669581486355171583722558858323126916278856549586825357358273536\", \"price\":\"0.67\", \"size\":\"131.87\", \"side\":\"BUY\", \"hash\":\"53ff63557e477ced9f68dfd363cd7bf68a794dd7\", \"best_bid\":\"0.78\", \"best_ask\":\"0.79\"}, {\"asset_id\":\"8698449539441374295770236407991735029336433231649246775082939325523552031992\", \"price\":\"0.33\", \"size\":\"131.87\", \"side\":\"SELL\", \"hash\":\"b6dfef6ee495604d360e3ef1d13c92ad87273010\", \"best_bid\":\"0.21\", \"best_ask\":\"0.22\"}], \"timestamp\":\"1785121846408\", \"event_type\":\"price_change\"}","received_at":"2026-07-27T03:10:46.309439Z","schema_version":"clob-market-ws.price_change.v1","sequence":null,"server_hash":null,"server_timestamp":"1785121846408","session_id":"ff6d21c8283948938400a32613abec2c","source":"clob_market_ws"},"received_at":"2026-07-27T03:10:46.309439Z","record_id":"8e43336f9e510ef85a104187a6cc0f44652183b976ff5bd65a17a619c1647c23","schema_fingerprint":"4aa3821a28b0b7c2400bc59aba4bcc0a76e971dadd19610d3ad38c768e124dc7","schema_version":"edge-lab-recorder.raw.v1","sequence":null,"source":"clob_market_ws"}
{"event_at":"2026-07-27T03:10:46.415000Z","event_fingerprint":"8aa65692cf72fbc368064ab4363f404d38d9b65f4123a5d48e631aa39f9edf70","payload":{"connection_id":"f95883f18d264834af91809e5f803e9f","event_at":"2026-07-27T03:10:46.415000Z","event_type":"price_change","frame_hash":"1ff316dc10dbd3f825b6cb029cab668bef1e7efbdc598251da8701bafc2f4bc0","frame_index":0,"kind":"data","monotonic_ns":223829648564333,"payload":{"event_type":"price_change","market":"0xf9d60bb033695053c4d1d8592e52171c1042f64b41a4b72e09dcc6f4852b6670","price_changes":[{"asset_id":"96283536366176669581486355171583722558858323126916278856549586825357358273536","best_ask":"0.79","best_bid":"0.78","hash":"9c0bc25c7fb34ef15b616d5657e8312f63b1a487","price":"0.01","side":"BUY","size":"6914.52"},{"asset_id":"8698449539441374295770236407991735029336433231649246775082939325523552031992","best_ask":"0.22","best_bid":"0.21","hash":"b93d9eda56571285c02d05f4773072f66ed7c39e","price":"0.99","side":"SELL","size":"6914.52"}],"timestamp":"1785121846415"},"payload_hash":"55340aa38c04e8f84da466aa9b41d77fc3d55170543c0796861834f88c420681","raw_frame":"{\"market\":\"0xf9d60bb033695053c4d1d8592e52171c1042f64b41a4b72e09dcc6f4852b6670\", \"price_changes\":[{\"asset_id\":\"96283536366176669581486355171583722558858323126916278856549586825357358273536\", \"price\":\"0.01\", \"size\":\"6914.52\", \"side\":\"BUY\", \"hash\":\"9c0bc25c7fb34ef15b616d5657e8312f63b1a487\", \"best_bid\":\"0.78\", \"best_ask\":\"0.79\"}, {\"asset_id\":\"8698449539441374295770236407991735029336433231649246775082939325523552031992\", \"price\":\"0.99\", \"size\":\"6914.52\", \"side\":\"SELL\", \"hash\":\"b93d9eda56571285c02d05f4773072f66ed7c39e\", \"best_bid\":\"0.21\", \"best_ask\":\"0.22\"}], \"timestamp\":\"1785121846415\", \"event_type\":\"price_change\"}","received_at":"2026-07-27T03:10:46.318461Z","schema_version":"clob-market-ws.price_change.v1","sequence":null,"server_hash":null,"server_timestamp":"1785121846415","session_id":"ff6d21c8283948938400a32613abec2c","source":"clob_market_ws"},"received_at":"2026-07-27T03:10:46.318461Z","record_id":"c9533f5d2997251400a4749123b1b76fe0c7fae8d4718e8626350dc300e9e933","schema_fingerprint":"4aa3821a28b0b7c2400bc59aba4bcc0a76e971dadd19610d3ad38c768e124dc7","schema_version":"edge-lab-recorder.raw.v1","sequence":null,"source":"clob_market_ws"}
{"event_at":"2026-07-27T03:10:46.416000Z","event_fingerprint":"950ef5b0afa6bf7ce6347bd0c2886c8998a9a0fdba66a651b070ec55b84026f8","payload":{"connection_id":"f95883f18d264834af91809e5f803e9f","event_at":"2026-07-27T03:10:46.416000Z","event_type":"price_change","frame_hash":"cd114ba38ade938687774cf4a25fd4178ed101356f66b4e2b3c7bea500235bb5","frame_index":0,"kind":"data","monotonic_ns":223829658422708,"payload":{"event_type":"price_change","market":"0xf9d60bb033695053c4d1d8592e52171c1042f64b41a4b72e09dcc6f4852b6670","price_changes":[{"asset_id":"96283536366176669581486355171583722558858323126916278856549586825357358273536","best_ask":"0.79","best_bid":"0.78","hash":"973110b82fbaab253faab0f36deb64b66d319390","price":"0.77","side":"BUY","size":"105.1"},{"asset_id":"8698449539441374295770236407991735029336433231649246775082939325523552031992","best_ask":"0.22","best_bid":"0.21","hash":"5c47493f7dd16232a98105da8a11e567508ac35c","price":"0.23","side":"SELL","size":"105.1"}],"timestamp":"1785121846416"},"payload_hash":"3e40e622a3f649e21366564d0d60083136d9f2ce3f22abfcf931751946e7698e","raw_frame":"{\"market\":\"0xf9d60bb033695053c4d1d8592e52171c1042f64b41a4b72e09dcc6f4852b6670\", \"price_changes\":[{\"asset_id\":\"96283536366176669581486355171583722558858323126916278856549586825357358273536\", \"price\":\"0.77\", \"size\":\"105.1\", \"side\":\"BUY\", \"hash\":\"973110b82fbaab253faab0f36deb64b66d319390\", \"best_bid\":\"0.78\", \"best_ask\":\"0.79\"}, {\"asset_id\":\"8698449539441374295770236407991735029336433231649246775082939325523552031992\", \"price\":\"0.23\", \"size\":\"105.1\", \"side\":\"SELL\", \"hash\":\"5c47493f7dd16232a98105da8a11e567508ac35c\", \"best_bid\":\"0.21\", \"best_ask\":\"0.22\"}], \"timestamp\":\"1785121846416\", \"event_type\":\"price_change\"}","received_at":"2026-07-27T03:10:46.328312Z","schema_version":"clob-market-ws.price_change.v1","sequence":null,"server_hash":null,"server_timestamp":"1785121846416","session_id":"ff6d21c8283948938400a32613abec2c","source":"clob_market_ws"},"received_at":"2026-07-27T03:10:46.328312Z","record_id":"a52e4009a3e5e5d8edb7ed113fbf254d54457de82a8e3a7200c0d108f0b5fe31","schema_fingerprint":"4aa3821a28b0b7c2400bc59aba4bcc0a76e971dadd19610d3ad38c768e124dc7","schema_version":"edge-lab-recorder.raw.v1","sequence":null,"source":"clob_market_ws"}
{"event_at":"2026-07-27T03:10:46.416000Z","event_fingerprint":"3027795f471da454abcfabc989a70807d8caccef3e0443d8526327c6d627aa2c","payload":{"connection_id":"f95883f18d264834af91809e5f803e9f","event_at":"2026-07-27T03:10:46.416000Z","event_type":"price_change","frame_hash":"87b0ab28cf3eaa459b94bbf1fbd504d6952c120bd157ba1a9a65ae71d93a64d5","frame_index":0,"kind":"data","monotonic_ns":223829659865291,"payload":{"event_type":"price_change","market":"0xf9d60bb033695053c4d1d8592e52171c1042f64b41a4b72e09dcc6f4852b6670","price_changes":[{"asset_id":"8698449539441374295770236407991735029336433231649246775082939325523552031992","best_ask":"0.22","best_bid":"0.21","hash":"a8dfa3b05c576438b1560f6bbc71a91c06e4a162","price":"0.09","side":"BUY","size":"743.9"},{"asset_id":"96283536366176669581486355171583722558858323126916278856549586825357358273536","best_ask":"0.79","best_bid":"0.78","hash":"c530e388770b0fb99c82f76571a7b405c5229445","price":"0.91","side":"SELL","size":"743.9"}],"timestamp":"1785121846416"},"payload_hash":"b755f37f81c4609438feba3ba0bb5b0fd703c391178bba657d52cee5f5a5dcdb","raw_frame":"{\"market\":\"0xf9d60bb033695053c4d1d8592e52171c1042f64b41a4b72e09dcc6f4852b6670\", \"price_changes\":[{\"asset_id\":\"8698449539441374295770236407991735029336433231649246775082939325523552031992\", \"price\":\"0.09\", \"size\":\"743.9\", \"side\":\"BUY\", \"hash\":\"a8dfa3b05c576438b1560f6bbc71a91c06e4a162\", \"best_bid\":\"0.21\", \"best_ask\":\"0.22\"}, {\"asset_id\":\"96283536366176669581486355171583722558858323126916278856549586825357358273536\", \"price\":\"0.91\", \"size\":\"743.9\", \"side\":\"SELL\", \"hash\":\"c530e388770b0fb99c82f76571a7b405c5229445\", \"best_bid\":\"0.78\", \"best_ask\":\"0.79\"}], \"timestamp\":\"1785121846416\", \"event_type\":\"price_change\"}","received_at":"2026-07-27T03:10:46.329763Z","schema_version":"clob-market-ws.price_change.v1","sequence":null,"server_hash":null,"server_timestamp":"1785121846416","session_id":"ff6d21c8283948938400a32613abec2c","source":"clob_market_ws"},"received_at":"2026-07-27T03:10:46.329763Z","record_id":"8010f5bbfee5338399e4d48780fc3e2d9069d5e093e1fdbfec9a64e14a30d01a","schema_fingerprint":"4aa3821a28b0b7c2400bc59aba4bcc0a76e971dadd19610d3ad38c768e124dc7","schema_version":"edge-lab-recorder.raw.v1","sequence":null,"source":"clob_market_ws"}
{"event_at":"2026-07-27T03:10:46.417000Z","event_fingerprint":"47df212c90f7fec23690123a9532e4920b8c9fb52f3fd85da65865583236da68","payload":{"connection_id":"f95883f18d264834af91809e5f803e9f","event_at":"2026-07-27T03:10:46.417000Z","event_type":"price_change","frame_hash":"dcf4c63a851b60c84ac25fb7ca3ef9784f73bf07efb7015a2c73737db53795d8","frame_index":0,"kind":"data","monotonic_ns":223829662219916,"payload":{"event_type":"price_change","market":"0xf9d60bb033695053c4d1d8592e52171c1042f64b41a4b72e09dcc6f4852b6670","price_changes":[{"asset_id":"96283536366176669581486355171583722558858323126916278856549586825357358273536","best_ask":"0.79","best_bid":"0.78","hash":"97875dde5d604c14ed6268bcce20a32de69c1a23","price":"0.77","side":"BUY","size":"110.1"},{"asset_id":"8698449539441374295770236407991735029336433231649246775082939325523552031992","best_ask":"0.22","best_bid":"0.21","hash":"1bed03582b4dcaf99c1609279483872fc2f9e8ef","price":"0.23","side":"SELL","size":"110.1"}],"timestamp":"1785121846417"},"payload_hash":"de941be7b87c1afbb96a8390538255cd620d28b21038fa3e64be801a4c6c4505","raw_frame":"{\"market\":\"0xf9d60bb033695053c4d1d8592e52171c1042f64b41a4b72e09dcc6f4852b6670\", \"price_changes\":[{\"asset_id\":\"96283536366176669581486355171583722558858323126916278856549586825357358273536\", \"price\":\"0.77\", \"size\":\"110.1\", \"side\":\"BUY\", \"hash\":\"97875dde5d604c14ed6268bcce20a32de69c1a23\", \"best_bid\":\"0.78\", \"best_ask\":\"0.79\"}, {\"asset_id\":\"8698449539441374295770236407991735029336433231649246775082939325523552031992\", \"price\":\"0.23\", \"size\":\"110.1\", \"side\":\"SELL\", \"hash\":\"1bed03582b4dcaf99c1609279483872fc2f9e8ef\", \"best_bid\":\"0.21\", \"best_ask\":\"0.22\"}], \"timestamp\":\"1785121846417\", \"event_type\":\"price_change\"}","received_at":"2026-07-27T03:10:46.332113Z","schema_version":"clob-market-ws.price_change.v1","sequence":null,"server_hash":null,"server_timestamp":"1785121846417","session_id":"ff6d21c8283948938400a32613abec2c","source":"clob_market_ws"},"received_at":"2026-07-27T03:10:46.332113Z","record_id":"65bcbb844ee1d950a79caf8475b315681be3cdbe999d7cccd8bff38b996157aa","schema_fingerprint":"4aa3821a28b0b7c2400bc59aba4bcc0a76e971dadd19610d3ad38c768e124dc7","schema_version":"edge-lab-recorder.raw.v1","sequence":null,"source":"clob_market_ws"}
{"event_at":"2026-07-27T03:10:46.436000Z","event_fingerprint":"7faf9ec31fd83cb07dd6c93839f6367bfa18f6ea1c25a5d855a5822242f8bc95","payload":{"connection_id":"f95883f18d264834af91809e5f803e9f","event_at":"2026-07-27T03:10:46.436000Z","event_type":"price_change","frame_hash":"650663f6e6300e393af470333331ccb81572160782313fdeb9abf3ca10141e93","frame_index":0,"kind":"data","monotonic_ns":223829670595375,"payload":{"event_type":"price_change","market":"0xf9d60bb033695053c4d1d8592e52171c1042f64b41a4b72e09dcc6f4852b6670","price_changes":[{"asset_id":"8698449539441374295770236407991735029336433231649246775082939325523552031992","best_ask":"0.22","best_bid":"0.21","hash":"2904ca8d09a78cd291c619d154dc7ad9aac2abd0","price":"0.17","side":"BUY","size":"105.19"},{"asset_id":"96283536366176669581486355171583722558858323126916278856549586825357358273536","best_ask":"0.79","best_bid":"0.78","hash":"4b9537cbc14eaebf8555ab0d80d76420fdf5aad2","price":"0.83","side":"SELL","size":"105.19"}],"timestamp":"1785121846436"},"payload_hash":"64b4027decbc5f5441338f47fcabb0d44a2b509264f1a276c9433296ef8f8e63","raw_frame":"{\"market\":\"0xf9d60bb033695053c4d1d8592e52171c1042f64b41a4b72e09dcc6f4852b6670\", \"price_changes\":[{\"asset_id\":\"8698449539441374295770236407991735029336433231649246775082939325523552031992\", \"price\":\"0.17\", \"size\":\"105.19\", \"side\":\"BUY\", \"hash\":\"2904ca8d09a78cd291c619d154dc7ad9aac2abd0\", \"best_bid\":\"0.21\", \"best_ask\":\"0.22\"}, {\"asset_id\":\"96283536366176669581486355171583722558858323126916278856549586825357358273536\", \"price\":\"0.83\", \"size\":\"105.19\", \"side\":\"SELL\", \"hash\":\"4b9537cbc14eaebf8555ab0d80d76420fdf5aad2\", \"best_bid\":\"0.78\", \"best_ask\":\"0.79\"}], \"timestamp\":\"1785121846436\", \"event_type\":\"price_change\"}","received_at":"2026-07-27T03:10:46.340484Z","schema_version":"clob-market-ws.price_change.v1","sequence":null,"server_hash":null,"server_timestamp":"1785121846436","session_id":"ff6d21c8283948938400a32613abec2c","source":"clob_market_ws"},"received_at":"2026-07-27T03:10:46.340484Z","record_id":"736b7d78551b5c2a8bfc839a2d25e6727ec3cafd7da835625c6c27bdeb481268","schema_fingerprint":"4aa3821a28b0b7c2400bc59aba4bcc0a76e971dadd19610d3ad38c768e124dc7","schema_version":"edge-lab-recorder.raw.v1","sequence":null,"source":"clob_market_ws"}
{"event_at":"2026-07-27T03:10:46.439000Z","event_fingerprint":"2ef50345853a2b9334949500089dd16bd5a7fa206b6e2bc5429d485534ce77b0","payload":{"connection_id":"f95883f18d264834af91809e5f803e9f","event_at":"2026-07-27T03:10:46.439000Z","event_type":"price_change","frame_hash":"be1f7731a2ba268dc3a8fb6f345a99b689fd3ba0d73af1ba31cce838fcecc677","frame_index":0,"kind":"data","monotonic_ns":223829673511833,"payload":{"event_type":"price_change","market":"0xf9d60bb033695053c4d1d8592e52171c1042f64b41a4b72e09dcc6f4852b6670","price_changes":[{"asset_id":"96283536366176669581486355171583722558858323126916278856549586825357358273536","best_ask":"0.79","best_bid":"0.78","hash":"c3bc9d0045d36346e99791e1bd9a5d954e9fb351","price":"0.67","side":"BUY","size":"126.87"},{"asset_id":"8698449539441374295770236407991735029336433231649246775082939325523552031992","best_ask":"0.22","best_bid":"0.21","hash":"ba083835ddf86845f4aba6bb3697a74f7e1bcc4a","price":"0.33","side":"SELL","size":"126.87"}],"timestamp":"1785121846439"},"payload_hash":"6a402d0e61f53e701acb6957aa8a146643d9e133693d76cbf19da1c90440a09c","raw_frame":"{\"market\":\"0xf9d60bb033695053c4d1d8592e52171c1042f64b41a4b72e09dcc6f4852b6670\", \"price_changes\":[{\"asset_id\":\"96283536366176669581486355171583722558858323126916278856549586825357358273536\", \"price\":\"0.67\", \"size\":\"126.87\", \"side\":\"BUY\", \"hash\":\"c3bc9d0045d36346e99791e1bd9a5d954e9fb351\", \"best_bid\":\"0.78\", \"best_ask\":\"0.79\"}, {\"asset_id\":\"8698449539441374295770236407991735029336433231649246775082939325523552031992\", \"price\":\"0.33\", \"size\":\"126.87\", \"side\":\"SELL\", \"hash\":\"ba083835ddf86845f4aba6bb3697a74f7e1bcc4a\", \"best_bid\":\"0.21\", \"best_ask\":\"0.22\"}], \"timestamp\":\"1785121846439\", \"event_type\":\"price_change\"}","received_at":"2026-07-27T03:10:46.343405Z","schema_version":"clob-market-ws.price_change.v1","sequence":null,"server_hash":null,"server_timestamp":"1785121846439","session_id":"ff6d21c8283948938400a32613abec2c","source":"clob_market_ws"},"received_at":"2026-07-27T03:10:46.343405Z","record_id":"5aa27803ac2ff340b20b3ea7c6c0ff297121b81530b18a9b009565081ea41f15","schema_fingerprint":"4aa3821a28b0b7c2400bc59aba4bcc0a76e971dadd19610d3ad38c768e124dc7","schema_version":"edge-lab-recorder.raw.v1","sequence":null,"source":"clob_market_ws"}
{"event_at":"2026-07-27T03:10:46.444000Z","event_fingerprint":"d05232932d242103138f3f2bfd27f27575660615a1ddec0f9b2256e710a8ec38","payload":{"connection_id":"f95883f18d264834af91809e5f803e9f","event_at":"2026-07-27T03:10:46.444000Z","event_type":"price_change","frame_hash":"ee1c676f981fa94b1e9bf432e85c8f114cf2ed6ad9d93b7a6b116e2a81f11e65","frame_index":0,"kind":"data","monotonic_ns":223829677690791,"payload":{"event_type":"price_change","market":"0xf9d60bb033695053c4d1d8592e52171c1042f64b41a4b72e09dcc6f4852b6670","price_changes":[{"asset_id":"8698449539441374295770236407991735029336433231649246775082939325523552031992","best_ask":"0.22","best_bid":"0.21","hash":"47f759ff34b77b398614f5ab76f0c1c60b336380","price":"0.18","side":"BUY","size":"73.6"},{"asset_id":"96283536366176669581486355171583722558858323126916278856549586825357358273536","best_ask":"0.79","best_bid":"0.78","hash":"2019444b926351cf92ac5eda4aa53da26222c89f","price":"0.82","side":"SELL","size":"73.6"}],"timestamp":"1785121846444"},"payload_hash":"b585da4f28fb0816d8a5472cf561af77a7b67b9f15fc34d3015dcf2243e7c6c7","raw_frame":"{\"market\":\"0xf9d60bb033695053c4d1d8592e52171c1042f64b41a4b72e09dcc6f4852b6670\", \"price_changes\":[{\"asset_id\":\"8698449539441374295770236407991735029336433231649246775082939325523552031992\", \"price\":\"0.18\", \"size\":\"73.6\", \"side\":\"BUY\", \"hash\":\"47f759ff34b77b398614f5ab76f0c1c60b336380\", \"best_bid\":\"0.21\", \"best_ask\":\"0.22\"}, {\"asset_id\":\"96283536366176669581486355171583722558858323126916278856549586825357358273536\", \"price\":\"0.82\", \"size\":\"73.6\", \"side\":\"SELL\", \"hash\":\"2019444b926351cf92ac5eda4aa53da26222c89f\", \"best_bid\":\"0.78\", \"best_ask\":\"0.79\"}], \"timestamp\":\"1785121846444\", \"event_type\":\"price_change\"}","received_at":"2026-07-27T03:10:46.347575Z","schema_version":"clob-market-ws.price_change.v1","sequence":null,"server_hash":null,"server_timestamp":"1785121846444","session_id":"ff6d21c8283948938400a32613abec2c","source":"clob_market_ws"},"received_at":"2026-07-27T03:10:46.347575Z","record_id":"100f3608a235c9827ada0da5dcb20e648a55da408099dffa672b744b9717f629","schema_fingerprint":"4aa3821a28b0b7c2400bc59aba4bcc0a76e971dadd19610d3ad38c768e124dc7","schema_version":"edge-lab-recorder.raw.v1","sequence":null,"source":"clob_market_ws"}
{"event_at":"2026-07-27T03:10:46.445000Z","event_fingerprint":"a89f8cc060d742e31dc07e2f9c9ae825ec7c74ec589d2e70affe44385684ee28","payload":{"connection_id":"f95883f18d264834af91809e5f803e9f","event_at":"2026-07-27T03:10:46.445000Z","event_type":"price_change","frame_hash":"fa8079cc537a99d62fbd11d0b22fd37421682b553c64f4222efe672e7ca481a1","frame_index":0,"kind":"data","monotonic_ns":223829680707125,"payload":{"event_type":"price_change","market":"0xf9d60bb033695053c4d1d8592e52171c1042f64b41a4b72e09dcc6f4852b6670","price_changes":[{"asset_id":"8698449539441374295770236407991735029336433231649246775082939325523552031992","best_ask":"0.22","best_bid":"0.21","hash":"33d28c957711fee0ca0ecd7cba242616ddfa2223","price":"0.25","side":"SELL","size":"110.57"},{"asset_id":"96283536366176669581486355171583722558858323126916278856549586825357358273536","best_ask":"0.79","best_bid":"0.78","hash":"29683649be9d1ecefb9c7949abe6e5fc1ed0af42","price":"0.75","side":"BUY","size":"110.57"}],"timestamp":"1785121846445"},"payload_hash":"9f05430d374421a17abfed4bb4d1470e0703aaf749d4ef2718f3b6c680ec381c","raw_frame":"{\"market\":\"0xf9d60bb033695053c4d1d8592e52171c1042f64b41a4b72e09dcc6f4852b6670\", \"price_changes\":[{\"asset_id\":\"8698449539441374295770236407991735029336433231649246775082939325523552031992\", \"price\":\"0.25\", \"size\":\"110.57\", \"side\":\"SELL\", \"hash\":\"33d28c957711fee0ca0ecd7cba242616ddfa2223\", \"best_bid\":\"0.21\", \"best_ask\":\"0.22\"}, {\"asset_id\":\"96283536366176669581486355171583722558858323126916278856549586825357358273536\", \"price\":\"0.75\", \"size\":\"110.57\", \"side\":\"BUY\", \"hash\":\"29683649be9d1ecefb9c7949abe6e5fc1ed0af42\", \"best_bid\":\"0.78\", \"best_ask\":\"0.79\"}], \"timestamp\":\"1785121846445\", \"event_type\":\"price_change\"}","received_at":"2026-07-27T03:10:46.350599Z","schema_version":"clob-market-ws.price_change.v1","sequence":null,"server_hash":null,"server_timestamp":"1785121846445","session_id":"ff6d21c8283948938400a32613abec2c","source":"clob_market_ws"},"received_at":"2026-07-27T03:10:46.350599Z","record_id":"c1d31a1890c41075182a7cbdb973dcb7e34b1af997813946aa77cc2d3c4a379f","schema_fingerprint":"4aa3821a28b0b7c2400bc59aba4bcc0a76e971dadd19610d3ad38c768e124dc7","schema_version":"edge-lab-recorder.raw.v1","sequence":null,"source":"clob_market_ws"}
{"event_at":"2026-07-27T03:10:46.445000Z","event_fingerprint":"2f7038b00eb2998033b69f1c0fbfd3b06d79c063b77df93f0886aea8eb5be624","payload":{"connection_id":"f95883f18d264834af91809e5f803e9f","event_at":"2026-07-27T03:10:46.445000Z","event_type":"price_change","frame_hash":"3efc90eda93385849b7392fbd9d1a7db46a026fd41c9b7726601e529d8a969a2","frame_index":0,"kind":"data","monotonic_ns":223829681893250,"payload":{"event_type":"price_change","market":"0xf9d60bb033695053c4d1d8592e52171c1042f64b41a4b72e09dcc6f4852b6670","price_changes":[{"asset_id":"8698449539441374295770236407991735029336433231649246775082939325523552031992","best_ask":"0.22","best_bid":"0.21","hash":"3bdca633eb2559fc7591dceb68eda6e23a5a66e0","price":"0.24","side":"SELL","size":"135"},{"asset_id":"96283536366176669581486355171583722558858323126916278856549586825357358273536","best_ask":"0.79","best_bid":"0.78","hash":"99c7d69a1f5eeda0bf994ad176caee3478ce23fd","price":"0.76","side":"BUY","size":"135"}],"timestamp":"1785121846445"},"payload_hash":"7d30901c1397450e80aa80342931b3335b41c7228155593648090d2029aba7e9","raw_frame":"{\"market\":\"0xf9d60bb033695053c4d1d8592e52171c1042f64b41a4b72e09dcc6f4852b6670\", \"price_changes\":[{\"asset_id\":\"8698449539441374295770236407991735029336433231649246775082939325523552031992\", \"price\":\"0.24\", \"size\":\"135\", \"side\":\"SELL\", \"hash\":\"3bdca633eb2559fc7591dceb68eda6e23a5a66e0\", \"best_bid\":\"0.21\", \"best_ask\":\"0.22\"}, {\"asset_id\":\"96283536366176669581486355171583722558858323126916278856549586825357358273536\", \"price\":\"0.76\", \"size\":\"135\", \"side\":\"BUY\", \"hash\":\"99c7d69a1f5eeda0bf994ad176caee3478ce23fd\", \"best_bid\":\"0.78\", \"best_ask\":\"0.79\"}], \"timestamp\":\"1785121846445\", \"event_type\":\"price_change\"}","received_at":"2026-07-27T03:10:46.351791Z","schema_version":"clob-market-ws.price_change.v1","sequence":null,"server_hash":null,"server_timestamp":"1785121846445","session_id":"ff6d21c8283948938400a32613abec2c","source":"clob_market_ws"},"received_at":"2026-07-27T03:10:46.351791Z","record_id":"2ca5f3e6fe16ffd6e9be172f477ee56647bf099f2a004694dd2a4051c00d0b55","schema_fingerprint":"4aa3821a28b0b7c2400bc59aba4bcc0a76e971dadd19610d3ad38c768e124dc7","schema_version":"edge-lab-recorder.raw.v1","sequence":null,"source":"clob_market_ws"}
{"event_at":"2026-07-27T03:10:46.468000Z","event_fingerprint":"84749b330ff80f65d460d874a65776e3eb1118a8e8374cce42860e1fe8e13670","payload":{"connection_id":"f95883f18d264834af91809e5f803e9f","event_at":"2026-07-27T03:10:46.468000Z","event_type":"price_change","frame_hash":"45cef30535f1eb2b27f88a1335a3fe57f1c89c8da90764eeb0cb605aea1b9a0c","frame_index":0,"kind":"data","monotonic_ns":223829701351625,"payload":{"event_type":"price_change","market":"0xf9d60bb033695053c4d1d8592e52171c1042f64b41a4b72e09dcc6f4852b6670","price_changes":[{"asset_id":"8698449539441374295770236407991735029336433231649246775082939325523552031992","best_ask":"0.22","best_bid":"0.21","hash":"0781f23baf2107a07c32003068c7263328ef1ba8","price":"0.33","side":"SELL","size":"131.87"},{"asset_id":"96283536366176669581486355171583722558858323126916278856549586825357358273536","best_ask":"0.79","best_bid":"0.78","hash":"2781e74ac18e7113670246390c2926c421c29058","price":"0.67","side":"BUY","size":"131.87"}],"timestamp":"1785121846468"},"payload_hash":"0b4e765178c9405d1f9d9bccb91d5d98923157bdc234a38b0afea635805b64c9","raw_frame":"{\"market\":\"0xf9d60bb033695053c4d1d8592e52171c1042f64b41a4b72e09dcc6f4852b6670\", \"price_changes\":[{\"asset_id\":\"8698449539441374295770236407991735029336433231649246775082939325523552031992\", \"price\":\"0.33\", \"size\":\"131.87\", \"side\":\"SELL\", \"hash\":\"0781f23baf2107a07c32003068c7263328ef1ba8\", \"best_bid\":\"0.21\", \"best_ask\":\"0.22\"}, {\"asset_id\":\"96283536366176669581486355171583722558858323126916278856549586825357358273536\", \"price\":\"0.67\", \"size\":\"131.87\", \"side\":\"BUY\", \"hash\":\"2781e74ac18e7113670246390c2926c421c29058\", \"best_bid\":\"0.78\", \"best_ask\":\"0.79\"}], \"timestamp\":\"1785121846468\", \"event_type\":\"price_change\"}","received_at":"2026-07-27T03:10:46.371243Z","schema_version":"clob-market-ws.price_change.v1","sequence":null,"server_hash":null,"server_timestamp":"1785121846468","session_id":"ff6d21c8283948938400a32613abec2c","source":"clob_market_ws"},"received_at":"2026-07-27T03:10:46.371243Z","record_id":"98895a26d4ad4cdfdde3b8faca13c0565f1a1e4935dff66612c37c941abe3784","schema_fingerprint":"4aa3821a28b0b7c2400bc59aba4bcc0a76e971dadd19610d3ad38c768e124dc7","schema_version":"edge-lab-recorder.raw.v1","sequence":null,"source":"clob_market_ws"}
{"event_at":"2026-07-27T03:10:46.471000Z","event_fingerprint":"db654ce1563640bd2411334cf660735705384b86099b5c99903c0e8971f53d78","payload":{"connection_id":"f95883f18d264834af91809e5f803e9f","event_at":"2026-07-27T03:10:46.471000Z","event_type":"price_change","frame_hash":"fde68efdb60bbc33702003e78c86390ee95a115804e86400492cdfb9fc084fa0","frame_index":0,"kind":"data","monotonic_ns":223829704196875,"payload":{"event_type":"price_change","market":"0xf9d60bb033695053c4d1d8592e52171c1042f64b41a4b72e09dcc6f4852b6670","price_changes":[{"asset_id":"96283536366176669581486355171583722558858323126916278856549586825357358273536","best_ask":"0.79","best_bid":"0.78","hash":"5acd7b927bcc6ca94b4039a2a973f4cfb39c53d7","price":"0.77","side":"BUY","size":"105.1"},{"asset_id":"8698449539441374295770236407991735029336433231649246775082939325523552031992","best_ask":"0.22","best_bid":"0.21","hash":"214fc9cb945eb44aca3b26fb05c250d64194c471","price":"0.23","side":"SELL","size":"105.1"}],"timestamp":"1785121846471"},"payload_hash":"6d5dff6dd482b13f3e12df2bafce6346cfb231493eced4864fe286fb122b3cb2","raw_frame":"{\"market\":\"0xf9d60bb033695053c4d1d8592e52171c1042f64b41a4b72e09dcc6f4852b6670\", \"price_changes\":[{\"asset_id\":\"96283536366176669581486355171583722558858323126916278856549586825357358273536\", \"price\":\"0.77\", \"size\":\"105.1\", \"side\":\"BUY\", \"hash\":\"5acd7b927bcc6ca94b4039a2a973f4cfb39c53d7\", \"best_bid\":\"0.78\", \"best_ask\":\"0.79\"}, {\"asset_id\":\"8698449539441374295770236407991735029336433231649246775082939325523552031992\", \"price\":\"0.23\", \"size\":\"105.1\", \"side\":\"SELL\", \"hash\":\"214fc9cb945eb44aca3b26fb05c250d64194c471\", \"best_bid\":\"0.21\", \"best_ask\":\"0.22\"}], \"timestamp\":\"1785121846471\", \"event_type\":\"price_change\"}","received_at":"2026-07-27T03:10:46.374087Z","schema_version":"clob-market-ws.price_change.v1","sequence":null,"server_hash":null,"server_timestamp":"1785121846471","session_id":"ff6d21c8283948938400a32613abec2c","source":"clob_market_ws"},"received_at":"2026-07-27T03:10:46.374087Z","record_id":"444d5264ced561eaf24bbe69b59b155aadd2f0de91dce14d9e0e1f041b15092f","schema_fingerprint":"4aa3821a28b0b7c2400bc59aba4bcc0a76e971dadd19610d3ad38c768e124dc7","schema_version":"edge-lab-recorder.raw.v1","sequence":null,"source":"clob_market_ws"}
{"event_at":"2026-07-27T03:10:46.494000Z","event_fingerprint":"ab50bee6244b7c45bd148ad9307f627eeebdffba27c4445a0b11fe0a137bad63","payload":{"connection_id":"f95883f18d264834af91809e5f803e9f","event_at":"2026-07-27T03:10:46.494000Z","event_type":"price_change","frame_hash":"24f189f5c5e93ca18362e9f64b5fff331c1af663cb3c8f8a0183766df51613cc","frame_index":0,"kind":"data","monotonic_ns":223829726108458,"payload":{"event_type":"price_change","market":"0xf9d60bb033695053c4d1d8592e52171c1042f64b41a4b72e09dcc6f4852b6670","price_changes":[{"asset_id":"8698449539441374295770236407991735029336433231649246775082939325523552031992","best_ask":"0.22","best_bid":"0.21","hash":"f197c5f5ab9817c1761d6d84cf7a1cc81a4a130b","price":"0.21","side":"BUY","size":"102.23"},{"asset_id":"96283536366176669581486355171583722558858323126916278856549586825357358273536","best_ask":"0.79","best_bid":"0.78","hash":"957d8e0a68a1b42b04f2e62148d351b01e6b1b05","price":"0.79","side":"SELL","size":"102.23"}],"timestamp":"1785121846494"},"payload_hash":"3e573ba6b9e31869b5e3e2c6d3fb9e4e26962ac130ac7ad556ad5ddf923ff2ef","raw_frame":"{\"market\":\"0xf9d60bb033695053c4d1d8592e52171c1042f64b41a4b72e09dcc6f4852b6670\", \"price_changes\":[{\"asset_id\":\"8698449539441374295770236407991735029336433231649246775082939325523552031992\", \"price\":\"0.21\", \"size\":\"102.23\", \"side\":\"BUY\", \"hash\":\"f197c5f5ab9817c1761d6d84cf7a1cc81a4a130b\", \"best_bid\":\"0.21\", \"best_ask\":\"0.22\"}, {\"asset_id\":\"96283536366176669581486355171583722558858323126916278856549586825357358273536\", \"price\":\"0.79\", \"size\":\"102.23\", \"side\":\"SELL\", \"hash\":\"957d8e0a68a1b42b04f2e62148d351b01e6b1b05\", \"best_bid\":\"0.78\", \"best_ask\":\"0.79\"}], \"timestamp\":\"1785121846494\", \"event_type\":\"price_change\"}","received_at":"2026-07-27T03:10:46.395996Z","schema_version":"clob-market-ws.price_change.v1","sequence":null,"server_hash":null,"server_timestamp":"1785121846494","session_id":"ff6d21c8283948938400a32613abec2c","source":"clob_market_ws"},"received_at":"2026-07-27T03:10:46.395996Z","record_id":"62a317613e7ea2edd75300336e89017a6c157317789a1af9b1bed813547d4165","schema_fingerprint":"4aa3821a28b0b7c2400bc59aba4bcc0a76e971dadd19610d3ad38c768e124dc7","schema_version":"edge-lab-recorder.raw.v1","sequence":null,"source":"clob_market_ws"}
{"event_at":"2026-07-27T03:10:46.496000Z","event_fingerprint":"4d9c8973de809190dfa4180dfc45ba05b932fb042ec9932d2d78c2add6554eb2","payload":{"connection_id":"f95883f18d264834af91809e5f803e9f","event_at":"2026-07-27T03:10:46.496000Z","event_type":"price_change","frame_hash":"7ea779c613ba15f72df8971d35a39efefa39c43eaf4207aab5aa62b3242ad9ac","frame_index":0,"kind":"data","monotonic_ns":223829728712750,"payload":{"event_type":"price_change","market":"0xf9d60bb033695053c4d1d8592e52171c1042f64b41a4b72e09dcc6f4852b6670","price_changes":[{"asset_id":"96283536366176669581486355171583722558858323126916278856549586825357358273536","best_ask":"0.79","best_bid":"0.78","hash":"fd011651ce1481611d09d8c5cbeb7768f8926597","price":"0.04","side":"BUY","size":"1066.5"},{"asset_id":"8698449539441374295770236407991735029336433231649246775082939325523552031992","best_ask":"0.22","best_bid":"0.21","hash":"68c534e70e27f963e68cffa9683f2535685ba0fd","price":"0.96","side":"SELL","size":"1066.5"}],"timestamp":"1785121846496"},"payload_hash":"c443c82e82a75b750f2c0c18a02090ef4c01c16e54237b93c94a166022ca624e","raw_frame":"{\"market\":\"0xf9d60bb033695053c4d1d8592e52171c1042f64b41a4b72e09dcc6f4852b6670\", \"price_changes\":[{\"asset_id\":\"96283536366176669581486355171583722558858323126916278856549586825357358273536\", \"price\":\"0.04\", \"size\":\"1066.5\", \"side\":\"BUY\", \"hash\":\"fd011651ce1481611d09d8c5cbeb7768f8926597\", \"best_bid\":\"0.78\", \"best_ask\":\"0.79\"}, {\"asset_id\":\"8698449539441374295770236407991735029336433231649246775082939325523552031992\", \"price\":\"0.96\", \"size\":\"1066.5\", \"side\":\"SELL\", \"hash\":\"68c534e70e27f963e68cffa9683f2535685ba0fd\", \"best_bid\":\"0.21\", \"best_ask\":\"0.22\"}], \"timestamp\":\"1785121846496\", \"event_type\":\"price_change\"}","received_at":"2026-07-27T03:10:46.398606Z","schema_version":"clob-market-ws.price_change.v1","sequence":null,"server_hash":null,"server_timestamp":"1785121846496","session_id":"ff6d21c8283948938400a32613abec2c","source":"clob_market_ws"},"received_at":"2026-07-27T03:10:46.398606Z","record_id":"af12ec9678f6a6865bc71675359f8cd3c55a9c9d26f7084b010ccecc884b39df","schema_fingerprint":"4aa3821a28b0b7c2400bc59aba4bcc0a76e971dadd19610d3ad38c768e124dc7","schema_version":"edge-lab-recorder.raw.v1","sequence":null,"source":"clob_market_ws"}
{"event_at":"2026-07-27T03:10:46.496000Z","event_fingerprint":"88f724fd70f86cbad25581992e51b71fa30b025c13423ddef9acb0c1d12c2992","payload":{"connection_id":"f95883f18d264834af91809e5f803e9f","event_at":"2026-07-27T03:10:46.496000Z","event_type":"price_change","frame_hash":"11c41fc673fc9aff6f19ec788fe7ba49c2e7f8b5037a8e64b83a4560b5bf2f76","frame_index":0,"kind":"data","monotonic_ns":223829731138708,"payload":{"event_type":"price_change","market":"0xf9d60bb033695053c4d1d8592e52171c1042f64b41a4b72e09dcc6f4852b6670","price_changes":[{"asset_id":"8698449539441374295770236407991735029336433231649246775082939325523552031992","best_ask":"0.22","best_bid":"0.21","hash":"549242d9f26887cbe586fd340e5f672b3f2241b7","price":"0.33","side":"SELL","size":"126.87"},{"asset_id":"96283536366176669581486355171583722558858323126916278856549586825357358273536","best_ask":"0.79","best_bid":"0.78","hash":"dff4b00588771cdd832da2a901f150f54c28c5aa","price":"0.67","side":"BUY","size":"126.87"}],"timestamp":"1785121846496"},"payload_hash":"231a31f77c35a8eef641f776bdf965c90f5a0cd094c97fef862864e8caf73457","raw_frame":"{\"market\":\"0xf9d60bb033695053c4d1d8592e52171c1042f64b41a4b72e09dcc6f4852b6670\", \"price_changes\":[{\"asset_id\":\"8698449539441374295770236407991735029336433231649246775082939325523552031992\", \"price\":\"0.33\", \"size\":\"126.87\", \"side\":\"SELL\", \"hash\":\"549242d9f26887cbe586fd340e5f672b3f2241b7\", \"best_bid\":\"0.21\", \"best_ask\":\"0.22\"}, {\"asset_id\":\"96283536366176669581486355171583722558858323126916278856549586825357358273536\", \"price\":\"0.67\", \"size\":\"126.87\", \"side\":\"BUY\", \"hash\":\"dff4b00588771cdd832da2a901f150f54c28c5aa\", \"best_bid\":\"0.78\", \"best_ask\":\"0.79\"}], \"timestamp\":\"1785121846496\", \"event_type\":\"price_change\"}","received_at":"2026-07-27T03:10:46.401035Z","schema_version":"clob-market-ws.price_change.v1","sequence":null,"server_hash":null,"server_timestamp":"1785121846496","session_id":"ff6d21c8283948938400a32613abec2c","source":"clob_market_ws"},"received_at":"2026-07-27T03:10:46.401035Z","record_id":"c628ca4a8741ac49fc7b5233db363c5e95d2aad654b0a8aef9567d22584e91c5","schema_fingerprint":"4aa3821a28b0b7c2400bc59aba4bcc0a76e971dadd19610d3ad38c768e124dc7","schema_version":"edge-lab-recorder.raw.v1","sequence":null,"source":"clob_market_ws"}
{"event_at":"2026-07-27T03:10:46.497000Z","event_fingerprint":"2d821de670a5a863947b65598827edfc42bede9c6841073b271e410bd17ab035","payload":{"connection_id":"f95883f18d264834af91809e5f803e9f","event_at":"2026-07-27T03:10:46.497000Z","event_type":"price_change","frame_hash":"217e726ddc330f6756d4ed27575cc695904a29298cdc20dcdbd3fdaa19f8f0cb","frame_index":0,"kind":"data","monotonic_ns":223829732255750,"payload":{"event_type":"price_change","market":"0xf9d60bb033695053c4d1d8592e52171c1042f64b41a4b72e09dcc6f4852b6670","price_changes":[{"asset_id":"8698449539441374295770236407991735029336433231649246775082939325523552031992","best_ask":"0.22","best_bid":"0.21","hash":"0ec8f160e2fc6bf0dedb00750c09922983d2c9a2","price":"0.21","side":"BUY","size":"27.23"},{"asset_id":"96283536366176669581486355171583722558858323126916278856549586825357358273536","best_ask":"0.79","best_bid":"0.78","hash":"258b55d5d7a1b9f8358368084fda55b55345a6ad","price":"0.79","side":"SELL","size":"27.23"}],"timestamp":"1785121846497"},"payload_hash":"57bfe40bdf626b8036198ef0daae27a1336dbfa7767d75bb189efc4f2a09f280","raw_frame":"{\"market\":\"0xf9d60bb033695053c4d1d8592e52171c1042f64b41a4b72e09dcc6f4852b6670\", \"price_changes\":[{\"asset_id\":\"8698449539441374295770236407991735029336433231649246775082939325523552031992\", \"price\":\"0.21\", \"size\":\"27.23\", \"side\":\"BUY\", \"hash\":\"0ec8f160e2fc6bf0dedb00750c09922983d2c9a2\", \"best_bid\":\"0.21\", \"best_ask\":\"0.22\"}, {\"asset_id\":\"96283536366176669581486355171583722558858323126916278856549586825357358273536\", \"price\":\"0.79\", \"size\":\"27.23\", \"side\":\"SELL\", \"hash\":\"258b55d5d7a1b9f8358368084fda55b55345a6ad\", \"best_bid\":\"0.78\", \"best_ask\":\"0.79\"}], \"timestamp\":\"1785121846497\", \"event_type\":\"price_change\"}","received_at":"2026-07-27T03:10:46.402145Z","schema_version":"clob-market-ws.price_change.v1","sequence":null,"server_hash":null,"server_timestamp":"1785121846497","session_id":"ff6d21c8283948938400a32613abec2c","source":"clob_market_ws"},"received_at":"2026-07-27T03:10:46.402145Z","record_id":"7acef51a63730ffe531beb21552f8e3cb0dca624f8cf140fbb5c6f3d4e7f443e","schema_fingerprint":"4aa3821a28b0b7c2400bc59aba4bcc0a76e971dadd19610d3ad38c768e124dc7","schema_version":"edge-lab-recorder.raw.v1","sequence":null,"source":"clob_market_ws"}
{"event_at":"2026-07-27T03:10:46.510000Z","event_fingerprint":"3a7ccb03a8ebb37e6db6f20fb795e5d01c2cba41256896650787399e05847b4b","payload":{"connection_id":"f95883f18d264834af91809e5f803e9f","event_at":"2026-07-27T03:10:46.510000Z","event_type":"price_change","frame_hash":"068e4df81877f6f1355d7ccdc63a66e342b33fd8df3ee304922e98d85a3bb8d1","frame_index":0,"kind":"data","monotonic_ns":223829742945958,"payload":{"event_type":"price_change","market":"0xf9d60bb033695053c4d1d8592e52171c1042f64b41a4b72e09dcc6f4852b6670","price_changes":[{"asset_id":"96283536366176669581486355171583722558858323126916278856549586825357358273536","best_ask":"0.79","best_bid":"0.78","hash":"bcfe73674afee629073de3929bc9a2ffbb9aaede","price":"0.72","side":"BUY","size":"119.8"},{"asset_id":"8698449539441374295770236407991735029336433231649246775082939325523552031992","best_ask":"0.22","best_bid":"0.21","hash":"40ba1b1801d42d6432473085c4fc130a808758d5","price":"0.28","side":"SELL","size":"119.8"}],"timestamp":"1785121846510"},"payload_hash":"1187804549ef3b9152723215fcaeab5213cee30059dc09dac677d821fa3d2a5c","raw_frame":"{\"market\":\"0xf9d60bb033695053c4d1d8592e52171c1042f64b41a4b72e09dcc6f4852b6670\", \"price_changes\":[{\"asset_id\":\"96283536366176669581486355171583722558858323126916278856549586825357358273536\", \"price\":\"0.72\", \"size\":\"119.8\", \"side\":\"BUY\", \"hash\":\"bcfe73674afee629073de3929bc9a2ffbb9aaede\", \"best_bid\":\"0.78\", \"best_ask\":\"0.79\"}, {\"asset_id\":\"8698449539441374295770236407991735029336433231649246775082939325523552031992\", \"price\":\"0.28\", \"size\":\"119.8\", \"side\":\"SELL\", \"hash\":\"40ba1b1801d42d6432473085c4fc130a808758d5\", \"best_bid\":\"0.21\", \"best_ask\":\"0.22\"}], \"timestamp\":\"1785121846510\", \"event_type\":\"price_change\"}","received_at":"2026-07-27T03:10:46.412839Z","schema_version":"clob-market-ws.price_change.v1","sequence":null,"server_hash":null,"server_timestamp":"1785121846510","session_id":"ff6d21c8283948938400a32613abec2c","source":"clob_market_ws"},"received_at":"2026-07-27T03:10:46.412839Z","record_id":"68062351b352cae9d0d04d40affa1d7375591cc22a7918a000e02c7c73dca054","schema_fingerprint":"4aa3821a28b0b7c2400bc59aba4bcc0a76e971dadd19610d3ad38c768e124dc7","schema_version":"edge-lab-recorder.raw.v1","sequence":null,"source":"clob_market_ws"}
{"event_at":"2026-07-27T03:10:46.511000Z","event_fingerprint":"cd9e6b258ba5b1be922fa3203a4a6478d8e81b5cecba50ac0064f7650caa3bb4","payload":{"connection_id":"f95883f18d264834af91809e5f803e9f","event_at":"2026-07-27T03:10:46.511000Z","event_type":"price_change","frame_hash":"8a394af1bd3ed0308e367131051ae68101baee8d4809bb8631aacd8c75bdef4f","frame_index":0,"kind":"data","monotonic_ns":223829744856833,"payload":{"event_type":"price_change","market":"0xf9d60bb033695053c4d1d8592e52171c1042f64b41a4b72e09dcc6f4852b6670","price_changes":[{"asset_id":"8698449539441374295770236407991735029336433231649246775082939325523552031992","best_ask":"0.22","best_bid":"0.21","hash":"de80d83c17ed2fb06256fbcfb5af12ac6c493b36","price":"0.16","side":"BUY","size":"199.72"},{"asset_id":"96283536366176669581486355171583722558858323126916278856549586825357358273536","best_ask":"0.79","best_bid":"0.78","hash":"8f216c4965a9ae38ff3db0648785215870ca585d","price":"0.84","side":"SELL","size":"199.72"}],"timestamp":"1785121846511"},"payload_hash":"367ab375106c2f580809a9e03966835108841bad1a1359ce2033b4c1bbe66322","raw_frame":"{\"market\":\"0xf9d60bb033695053c4d1d8592e52171c1042f64b41a4b72e09dcc6f4852b6670\", \"price_changes\":[{\"asset_id\":\"8698449539441374295770236407991735029336433231649246775082939325523552031992\", \"price\":\"0.16\", \"size\":\"199.72\", \"side\":\"BUY\", \"hash\":\"de80d83c17ed2fb06256fbcfb5af12ac6c493b36\", \"best_bid\":\"0.21\", \"best_ask\":\"0.22\"}, {\"asset_id\":\"96283536366176669581486355171583722558858323126916278856549586825357358273536\", \"price\":\"0.84\", \"size\":\"199.72\", \"side\":\"SELL\", \"hash\":\"8f216c4965a9ae38ff3db0648785215870ca585d\", \"best_bid\":\"0.78\", \"best_ask\":\"0.79\"}], \"timestamp\":\"1785121846511\", \"event_type\":\"price_change\"}","received_at":"2026-07-27T03:10:46.414748Z","schema_version":"clob-market-ws.price_change.v1","sequence":null,"server_hash":null,"server_timestamp":"1785121846511","session_id":"ff6d21c8283948938400a32613abec2c","source":"clob_market_ws"},"received_at":"2026-07-27T03:10:46.414748Z","record_id":"6313f8a5074a3cb438e6b2b855f0d63a31c0de8569c7c33469c5fc1f32fd5153","schema_fingerprint":"4aa3821a28b0b7c2400bc59aba4bcc0a76e971dadd19610d3ad38c768e124dc7","schema_version":"edge-lab-recorder.raw.v1","sequence":null,"source":"clob_market_ws"}
{"event_at":"2026-07-27T03:10:46.522000Z","event_fingerprint":"b75f0a51bc143d824ea37e9ed38c0fe3615bb449995c08971e4adca7fef6ab04","payload":{"connection_id":"f95883f18d264834af91809e5f803e9f","event_at":"2026-07-27T03:10:46.522000Z","event_type":"price_change","frame_hash":"ec2d846c53c09211d848105e71bd909ffc6c5f9fc6bba1863cb9d1564deb48ec","frame_index":0,"kind":"data","monotonic_ns":223829754605875,"payload":{"event_type":"price_change","market":"0xf9d60bb033695053c4d1d8592e52171c1042f64b41a4b72e09dcc6f4852b6670","price_changes":[{"asset_id":"96283536366176669581486355171583722558858323126916278856549586825357358273536","best_ask":"0.79","best_bid":"0.78","hash":"efd50ee13bc24244085eeeeb2787ef4b5dc8a778","price":"0.67","side":"BUY","size":"131.87"},{"asset_id":"8698449539441374295770236407991735029336433231649246775082939325523552031992","best_ask":"0.22","best_bid":"0.21","hash":"30388c725badfbb119faefe87f88af49d2576918","price":"0.33","side":"SELL","size":"131.87"}],"timestamp":"1785121846522"},"payload_hash":"5f57be25bbc80912c115997bfd2ee311f16e0d2460bd5a7080ae9590712af5eb","raw_frame":"{\"market\":\"0xf9d60bb033695053c4d1d8592e52171c1042f64b41a4b72e09dcc6f4852b6670\", \"price_changes\":[{\"asset_id\":\"96283536366176669581486355171583722558858323126916278856549586825357358273536\", \"price\":\"0.67\", \"size\":\"131.87\", \"side\":\"BUY\", \"hash\":\"efd50ee13bc24244085eeeeb2787ef4b5dc8a778\", \"best_bid\":\"0.78\", \"best_ask\":\"0.79\"}, {\"asset_id\":\"8698449539441374295770236407991735029336433231649246775082939325523552031992\", \"price\":\"0.33\", \"size\":\"131.87\", \"side\":\"SELL\", \"hash\":\"30388c725badfbb119faefe87f88af49d2576918\", \"best_bid\":\"0.21\", \"best_ask\":\"0.22\"}], \"timestamp\":\"1785121846522\", \"event_type\":\"price_change\"}","received_at":"2026-07-27T03:10:46.424493Z","schema_version":"clob-market-ws.price_change.v1","sequence":null,"server_hash":null,"server_timestamp":"1785121846522","session_id":"ff6d21c8283948938400a32613abec2c","source":"clob_market_ws"},"received_at":"2026-07-27T03:10:46.424493Z","record_id":"a363f2daa94ae795c2bc8c43fff4c96421e8016d170739c88a08e0a57627f0cb","schema_fingerprint":"4aa3821a28b0b7c2400bc59aba4bcc0a76e971dadd19610d3ad38c768e124dc7","schema_version":"edge-lab-recorder.raw.v1","sequence":null,"source":"clob_market_ws"}
{"event_at":"2026-07-27T03:10:46.523000Z","event_fingerprint":"c6973978a61a9300be2a977e200ce622309124144048f965977f658903dab1a5","payload":{"connection_id":"f95883f18d264834af91809e5f803e9f","event_at":"2026-07-27T03:10:46.523000Z","event_type":"price_change","frame_hash":"01ea414dd80fdee09b111e462847f9e91574c146f7865674870c9918cc8e3827","frame_index":0,"kind":"data","monotonic_ns":223829762498083,"payload":{"event_type":"price_change","market":"0xf9d60bb033695053c4d1d8592e52171c1042f64b41a4b72e09dcc6f4852b6670","price_changes":[{"asset_id":"96283536366176669581486355171583722558858323126916278856549586825357358273536","best_ask":"0.79","best_bid":"0.78","hash":"982417c11e62dee7846101c7dd8445ba6d10e344","price":"0.72","side":"BUY","size":"100"},{"asset_id":"8698449539441374295770236407991735029336433231649246775082939325523552031992","best_ask":"0.22","best_bid":"0.21","hash":"ce04a5a46547157ee92898f4d9e7160e7d054a6a","price":"0.28","side":"SELL","size":"100"}],"timestamp":"1785121846523"},"payload_hash":"044e023c37f582f2b0cae1961e8df8cc3edbc4b1b8a8e59818a80cca24ad93a7","raw_frame":"{\"market\":\"0xf9d60bb033695053c4d1d8592e52171c1042f64b41a4b72e09dcc6f4852b6670\", \"price_changes\":[{\"asset_id\":\"96283536366176669581486355171583722558858323126916278856549586825357358273536\", \"price\":\"0.72\", \"size\":\"100\", \"side\":\"BUY\", \"hash\":\"982417c11e62dee7846101c7dd8445ba6d10e344\", \"best_bid\":\"0.78\", \"best_ask\":\"0.79\"}, {\"asset_id\":\"8698449539441374295770236407991735029336433231649246775082939325523552031992\", \"price\":\"0.28\", \"size\":\"100\", \"side\":\"SELL\", \"hash\":\"ce04a5a46547157ee92898f4d9e7160e7d054a6a\", \"best_bid\":\"0.21\", \"best_ask\":\"0.22\"}], \"timestamp\":\"1785121846523\", \"event_type\":\"price_change\"}","received_at":"2026-07-27T03:10:46.432387Z","schema_version":"clob-market-ws.price_change.v1","sequence":null,"server_hash":null,"server_timestamp":"1785121846523","session_id":"ff6d21c8283948938400a32613abec2c","source":"clob_market_ws"},"received_at":"2026-07-27T03:10:46.432387Z","record_id":"a18dba1248d57130fa6cb6849cfc05f5562b89352875d78d01b30d585ef69b78","schema_fingerprint":"4aa3821a28b0b7c2400bc59aba4bcc0a76e971dadd19610d3ad38c768e124dc7","schema_version":"edge-lab-recorder.raw.v1","sequence":null,"source":"clob_market_ws"}
{"event_at":"2026-07-27T03:10:46.546000Z","event_fingerprint":"26fcc65fa5b96e431f6f8a917f1aaef1a53b8a8e2b32af5e62f246a62d0fd6a5","payload":{"connection_id":"f95883f18d264834af91809e5f803e9f","event_at":"2026-07-27T03:10:46.546000Z","event_type":"price_change","frame_hash":"2577886e3b9bda199394f93790064062a930c66705fa57d5bd6709dae1e9bb1a","frame_index":0,"kind":"data","monotonic_ns":223829780427250,"payload":{"event_type":"price_change","market":"0xf9d60bb033695053c4d1d8592e52171c1042f64b41a4b72e09dcc6f4852b6670","price_changes":[{"asset_id":"8698449539441374295770236407991735029336433231649246775082939325523552031992","best_ask":"0.22","best_bid":"0.21","hash":"838f7860703839a0c0684e4415b5b97f0480b372","price":"0.25","side":"SELL","size":"100"},{"asset_id":"96283536366176669581486355171583722558858323126916278856549586825357358273536","best_ask":"0.79","best_bid":"0.78","hash":"1dd2d995dfbf7d05485900c88787e79e6c8e11ea","price":"0.75","side":"BUY","size":"100"}],"timestamp":"1785121846546"},"payload_hash":"f0104e86e5d4c4ef4172ede1c102dee8dda99c83596d65446bb3089a2392ad99","raw_frame":"{\"market\":\"0xf9d60bb033695053c4d1d8592e52171c1042f64b41a4b72e09dcc6f4852b6670\", \"price_changes\":[{\"asset_id\":\"8698449539441374295770236407991735029336433231649246775082939325523552031992\", \"price\":\"0.25\", \"size\":\"100\", \"side\":\"SELL\", \"hash\":\"838f7860703839a0c0684e4415b5b97f0480b372\", \"best_bid\":\"0.21\", \"best_ask\":\"0.22\"}, {\"asset_id\":\"96283536366176669581486355171583722558858323126916278856549586825357358273536\", \"price\":\"0.75\", \"size\":\"100\", \"side\":\"BUY\", \"hash\":\"1dd2d995dfbf7d05485900c88787e79e6c8e11ea\", \"best_bid\":\"0.78\", \"best_ask\":\"0.79\"}], \"timestamp\":\"1785121846546\", \"event_type\":\"price_change\"}","received_at":"2026-07-27T03:10:46.450316Z","schema_version":"clob-market-ws.price_change.v1","sequence":null,"server_hash":null,"server_timestamp":"1785121846546","session_id":"ff6d21c8283948938400a32613abec2c","source":"clob_market_ws"},"received_at":"2026-07-27T03:10:46.450316Z","record_id":"3372ad3d40089b268cfd0262b96d2cd6c9866a30a185730d7113f1fd2c3a33cf","schema_fingerprint":"4aa3821a28b0b7c2400bc59aba4bcc0a76e971dadd19610d3ad38c768e124dc7","schema_version":"edge-lab-recorder.raw.v1","sequence":null,"source":"clob_market_ws"}
{"event_at":"2026-07-27T03:10:46.546000Z","event_fingerprint":"e805e8063e3f5ddf2c15ff8eab053e12958df291f8274d3a3ea749a55845a727","payload":{"connection_id":"f95883f18d264834af91809e5f803e9f","event_at":"2026-07-27T03:10:46.546000Z","event_type":"price_change","frame_hash":"06e3d8a4af8ff53cc094ccd8f23b3d06f069e2cd3859d0650171b0edbbe897de","frame_index":0,"kind":"data","monotonic_ns":223829782745291,"payload":{"event_type":"price_change","market":"0xf9d60bb033695053c4d1d8592e52171c1042f64b41a4b72e09dcc6f4852b6670","price_changes":[{"asset_id":"8698449539441374295770236407991735029336433231649246775082939325523552031992","best_ask":"0.22","best_bid":"0.21","hash":"838f7860703839a0c0684e4415b5b97f0480b372","price":"0.24","side":"SELL","size":"110"},{"asset_id":"96283536366176669581486355171583722558858323126916278856549586825357358273536","best_ask":"0.79","best_bid":"0.78","hash":"1dd2d995dfbf7d05485900c88787e79e6c8e11ea","price":"0.76","side":"BUY","size":"110"}],"timestamp":"1785121846546"},"payload_hash":"3d60a6119166262124a35b4d0e4c6630a43ef883b9f6bdbdda53043fe1cc6184","raw_frame":"{\"market\":\"0xf9d60bb033695053c4d1d8592e52171c1042f64b41a4b72e09dcc6f4852b6670\", \"price_changes\":[{\"asset_id\":\"8698449539441374295770236407991735029336433231649246775082939325523552031992\", \"price\":\"0.24\", \"size\":\"110\", \"side\":\"SELL\", \"hash\":\"838f7860703839a0c0684e4415b5b97f0480b372\", \"best_bid\":\"0.21\", \"best_ask\":\"0.22\"}, {\"asset_id\":\"96283536366176669581486355171583722558858323126916278856549586825357358273536\", \"price\":\"0.76\", \"size\":\"110\", \"side\":\"BUY\", \"hash\":\"1dd2d995dfbf7d05485900c88787e79e6c8e11ea\", \"best_bid\":\"0.78\", \"best_ask\":\"0.79\"}], \"timestamp\":\"1785121846546\", \"event_type\":\"price_change\"}","received_at":"2026-07-27T03:10:46.452633Z","schema_version":"clob-market-ws.price_change.v1","sequence":null,"server_hash":null,"server_timestamp":"1785121846546","session_id":"ff6d21c8283948938400a32613abec2c","source":"clob_market_ws"},"received_at":"2026-07-27T03:10:46.452633Z","record_id":"e3f077d094508f1fcdbc27942d898bf76c948cc12fa02be9b179e5ea5c1c1e8f","schema_fingerprint":"4aa3821a28b0b7c2400bc59aba4bcc0a76e971dadd19610d3ad38c768e124dc7","schema_version":"edge-lab-recorder.raw.v1","sequence":null,"source":"clob_market_ws"}
{"event_at":"2026-07-27T03:10:46.550000Z","event_fingerprint":"253405c60c99aa9b946fcb0c01c28b05070c024bcc6218d17a68c096e971b283","payload":{"connection_id":"f95883f18d264834af91809e5f803e9f","event_at":"2026-07-27T03:10:46.550000Z","event_type":"price_change","frame_hash":"3f415de9a5e838c157cdf559ac4309dd82043517809eacc7ad493b14622dce6f","frame_index":0,"kind":"data","monotonic_ns":223829785256416,"payload":{"event_type":"price_change","market":"0xf9d60bb033695053c4d1d8592e52171c1042f64b41a4b72e09dcc6f4852b6670","price_changes":[{"asset_id":"96283536366176669581486355171583722558858323126916278856549586825357358273536","best_ask":"0.79","best_bid":"0.78","hash":"963a535fe24c68ec108de7f2274249a59d670f20","price":"0.04","side":"BUY","size":"1061.5"},{"asset_id":"8698449539441374295770236407991735029336433231649246775082939325523552031992","best_ask":"0.22","best_bid":"0.21","hash":"ba82ba303b535ca0df58681c75e9bc0b1eb2c4bb","price":"0.96","side":"SELL","size":"1061.5"}],"timestamp":"1785121846550"},"payload_hash":"2e06c3ac76cd44e91949475bc2e3efb756e154b4527449c2a4a62a01e3d0153a","raw_frame":"{\"market\":\"0xf9d60bb033695053c4d1d8592e52171c1042f64b41a4b72e09dcc6f4852b6670\", \"price_changes\":[{\"asset_id\":\"96283536366176669581486355171583722558858323126916278856549586825357358273536\", \"price\":\"0.04\", \"size\":\"1061.5\", \"side\":\"BUY\", \"hash\":\"963a535fe24c68ec108de7f2274249a59d670f20\", \"best_bid\":\"0.78\", \"best_ask\":\"0.79\"}, {\"asset_id\":\"8698449539441374295770236407991735029336433231649246775082939325523552031992\", \"price\":\"0.96\", \"size\":\"1061.5\", \"side\":\"SELL\", \"hash\":\"ba82ba303b535ca0df58681c75e9bc0b1eb2c4bb\", \"best_bid\":\"0.21\", \"best_ask\":\"0.22\"}], \"timestamp\":\"1785121846550\", \"event_type\":\"price_change\"}","received_at":"2026-07-27T03:10:46.455146Z","schema_version":"clob-market-ws.price_change.v1","sequence":null,"server_hash":null,"server_timestamp":"1785121846550","session_id":"ff6d21c8283948938400a32613abec2c","source":"clob_market_ws"},"received_at":"2026-07-27T03:10:46.455146Z","record_id":"0c69cdad3e530ebb59ac365d729e991aa0d4efbe19eaadebee4e2ccd1041da09","schema_fingerprint":"4aa3821a28b0b7c2400bc59aba4bcc0a76e971dadd19610d3ad38c768e124dc7","schema_version":"edge-lab-recorder.raw.v1","sequence":null,"source":"clob_market_ws"}
{"event_at":"2026-07-27T03:10:46.563000Z","event_fingerprint":"1077d8805823b77156f89ffeb27f6afbec6b0b8073ea1c5cbaccce470517e99c","payload":{"connection_id":"f95883f18d264834af91809e5f803e9f","event_at":"2026-07-27T03:10:46.563000Z","event_type":"price_change","frame_hash":"ca6187b658a317055255d78f863d26143196f057ca2bd3a208812cc2d4654423","frame_index":0,"kind":"data","monotonic_ns":223829798640791,"payload":{"event_type":"price_change","market":"0xf9d60bb033695053c4d1d8592e52171c1042f64b41a4b72e09dcc6f4852b6670","price_changes":[{"asset_id":"96283536366176669581486355171583722558858323126916278856549586825357358273536","best_ask":"0.79","best_bid":"0.78","hash":"fe9bdc7c10e1c5204fd05ebd17ceb5e21975f56f","price":"0.01","side":"BUY","size":"6909.52"},{"asset_id":"8698449539441374295770236407991735029336433231649246775082939325523552031992","best_ask":"0.22","best_bid":"0.21","hash":"188c02a1afb4a207ca3f6f4ba632216676f3516b","price":"0.99","side":"SELL","size":"6909.52"}],"timestamp":"1785121846563"},"payload_hash":"2d49042fbe949a47f821ad2e5f72a405b05edffc9838cd9cff8efe4812042245","raw_frame":"{\"market\":\"0xf9d60bb033695053c4d1d8592e52171c1042f64b41a4b72e09dcc6f4852b6670\", \"price_changes\":[{\"asset_id\":\"96283536366176669581486355171583722558858323126916278856549586825357358273536\", \"price\":\"0.01\", \"size\":\"6909.52\", \"side\":\"BUY\", \"hash\":\"fe9bdc7c10e1c5204fd05ebd17ceb5e21975f56f\", \"best_bid\":\"0.78\", \"best_ask\":\"0.79\"}, {\"asset_id\":\"8698449539441374295770236407991735029336433231649246775082939325523552031992\", \"price\":\"0.99\", \"size\":\"6909.52\", \"side\":\"SELL\", \"hash\":\"188c02a1afb4a207ca3f6f4ba632216676f3516b\", \"best_bid\":\"0.21\", \"best_ask\":\"0.22\"}], \"timestamp\":\"1785121846563\", \"event_type\":\"price_change\"}","received_at":"2026-07-27T03:10:46.468527Z","schema_version":"clob-market-ws.price_change.v1","sequence":null,"server_hash":null,"server_timestamp":"1785121846563","session_id":"ff6d21c8283948938400a32613abec2c","source":"clob_market_ws"},"received_at":"2026-07-27T03:10:46.468527Z","record_id":"a34188bce8d0250ef657f9d2be12f385374a4a6cdff7e8bcd8b922060f7d4496","schema_fingerprint":"4aa3821a28b0b7c2400bc59aba4bcc0a76e971dadd19610d3ad38c768e124dc7","schema_version":"edge-lab-recorder.raw.v1","sequence":null,"source":"clob_market_ws"}
{"event_at":"2026-07-27T03:10:46.567000Z","event_fingerprint":"00de2778a058c5b1ec2392c817ef12e183a921e83c82953f8991eab7beccd370","payload":{"connection_id":"f95883f18d264834af91809e5f803e9f","event_at":"2026-07-27T03:10:46.567000Z","event_type":"price_change","frame_hash":"e10fc0cf97ce826c1ef62b696d5ed36d6aaf9b957550a89c4621fedea17c10b4","frame_index":0,"kind":"data","monotonic_ns":223829803989208,"payload":{"event_type":"price_change","market":"0xf9d60bb033695053c4d1d8592e52171c1042f64b41a4b72e09dcc6f4852b6670","price_changes":[{"asset_id":"96283536366176669581486355171583722558858323126916278856549586825357358273536","best_ask":"0.79","best_bid":"0.78","hash":"bcdce55adea75366850e1410a1b5f32586373353","price":"0.67","side":"BUY","size":"126.87"},{"asset_id":"8698449539441374295770236407991735029336433231649246775082939325523552031992","best_ask":"0.22","best_bid":"0.21","hash":"ef82d93bfcdbb0e3d9b1560110216cad2c12360d","price":"0.33","side":"SELL","size":"126.87"}],"timestamp":"1785121846567"},"payload_hash":"666c97f4a4baca3bd4c4a1920ddcb503d6cc4e9a51c773e3f19c99a617933243","raw_frame":"{\"market\":\"0xf9d60bb033695053c4d1d8592e52171c1042f64b41a4b72e09dcc6f4852b6670\", \"price_changes\":[{\"asset_id\":\"96283536366176669581486355171583722558858323126916278856549586825357358273536\", \"price\":\"0.67\", \"size\":\"126.87\", \"side\":\"BUY\", \"hash\":\"bcdce55adea75366850e1410a1b5f32586373353\", \"best_bid\":\"0.78\", \"best_ask\":\"0.79\"}, {\"asset_id\":\"8698449539441374295770236407991735029336433231649246775082939325523552031992\", \"price\":\"0.33\", \"size\":\"126.87\", \"side\":\"SELL\", \"hash\":\"ef82d93bfcdbb0e3d9b1560110216cad2c12360d\", \"best_bid\":\"0.21\", \"best_ask\":\"0.22\"}], \"timestamp\":\"1785121846567\", \"event_type\":\"price_change\"}","received_at":"2026-07-27T03:10:46.473871Z","schema_version":"clob-market-ws.price_change.v1","sequence":null,"server_hash":null,"server_timestamp":"1785121846567","session_id":"ff6d21c8283948938400a32613abec2c","source":"clob_market_ws"},"received_at":"2026-07-27T03:10:46.473871Z","record_id":"11e455d17009d96e7ebf42130d93294abdc8bc1e197a4a3e4922f59b6a7bfe23","schema_fingerprint":"4aa3821a28b0b7c2400bc59aba4bcc0a76e971dadd19610d3ad38c768e124dc7","schema_version":"edge-lab-recorder.raw.v1","sequence":null,"source":"clob_market_ws"}
{"event_at":"2026-07-27T03:10:46.567000Z","event_fingerprint":"7802ee0de778cef8880fc4b82df2480d06944966f4e0d2671ec582d8ecf48cb5","payload":{"connection_id":"f95883f18d264834af91809e5f803e9f","event_at":"2026-07-27T03:10:46.567000Z","event_type":"price_change","frame_hash":"19b7afd50db313ed2c721e43780b9e156dc2d6a682545a6551f8d9dd7473e88d","frame_index":0,"kind":"data","monotonic_ns":223829806509000,"payload":{"event_type":"price_change","market":"0xf9d60bb033695053c4d1d8592e52171c1042f64b41a4b72e09dcc6f4852b6670","price_changes":[{"asset_id":"8698449539441374295770236407991735029336433231649246775082939325523552031992","best_ask":"0.22","best_bid":"0.21","hash":"9a149e03c8de7f877a4393b5dcb4cfdad8c0721c","price":"0.01","side":"BUY","size":"6834.52"},{"asset_id":"96283536366176669581486355171583722558858323126916278856549586825357358273536","best_ask":"0.79","best_bid":"0.78","hash":"17da6dd5141dcc59e0e47b3ecc7e6b0275b65cfa","price":"0.99","side":"SELL","size":"6834.52"}],"timestamp":"1785121846567"},"payload_hash":"f13f971e3b215ffa480cbd92898101e5f9063cf19d08ca7a8e99fe54b3f6f3c9","raw_frame":"{\"market\":\"0xf9d60bb033695053c4d1d8592e52171c1042f64b41a4b72e09dcc6f4852b6670\", \"price_changes\":[{\"asset_id\":\"8698449539441374295770236407991735029336433231649246775082939325523552031992\", \"price\":\"0.01\", \"size\":\"6834.52\", \"side\":\"BUY\", \"hash\":\"9a149e03c8de7f877a4393b5dcb4cfdad8c0721c\", \"best_bid\":\"0.21\", \"best_ask\":\"0.22\"}, {\"asset_id\":\"96283536366176669581486355171583722558858323126916278856549586825357358273536\", \"price\":\"0.99\", \"size\":\"6834.52\", \"side\":\"SELL\", \"hash\":\"17da6dd5141dcc59e0e47b3ecc7e6b0275b65cfa\", \"best_bid\":\"0.78\", \"best_ask\":\"0.79\"}], \"timestamp\":\"1785121846567\", \"event_type\":\"price_change\"}","received_at":"2026-07-27T03:10:46.476399Z","schema_version":"clob-market-ws.price_change.v1","sequence":null,"server_hash":null,"server_timestamp":"1785121846567","session_id":"ff6d21c8283948938400a32613abec2c","source":"clob_market_ws"},"received_at":"2026-07-27T03:10:46.476399Z","record_id":"ec9b0c241887c4157ce58ca7d94cae7a9f6914ce003898eec7a15ad36fe5d20d","schema_fingerprint":"4aa3821a28b0b7c2400bc59aba4bcc0a76e971dadd19610d3ad38c768e124dc7","schema_version":"edge-lab-recorder.raw.v1","sequence":null,"source":"clob_market_ws"}
{"event_at":"2026-07-27T03:10:46.568000Z","event_fingerprint":"f9b0da154f276230bb5be10f0f87be4ffb38b6eece8114c65c55cc67344dcf72","payload":{"connection_id":"f95883f18d264834af91809e5f803e9f","event_at":"2026-07-27T03:10:46.568000Z","event_type":"price_change","frame_hash":"bd4d35dfe03c97712bc46e63653b693a8fbfb2121f9d8b9ab7add9f6a4b9daf1","frame_index":0,"kind":"data","monotonic_ns":223829809811000,"payload":{"event_type":"price_change","market":"0xf9d60bb033695053c4d1d8592e52171c1042f64b41a4b72e09dcc6f4852b6670","price_changes":[{"asset_id":"8698449539441374295770236407991735029336433231649246775082939325523552031992","best_ask":"0.22","best_bid":"0.21","hash":"83cd6ca9896dcdef9c99ef9852b98c929a6bf12a","price":"0.01","side":"BUY","size":"6829.52"},{"asset_id":"96283536366176669581486355171583722558858323126916278856549586825357358273536","best_ask":"0.79","best_bid":"0.78","hash":"65a85b5bd1bf11033b6cbc26e2cb5623f8839edb","price":"0.99","side":"SELL","size":"6829.52"}],"timestamp":"1785121846568"},"payload_hash":"385b6c5b60d80beba29abbc31832d72bb2f119d922ab158e2334d4b25e273d16","raw_frame":"{\"market\":\"0xf9d60bb033695053c4d1d8592e52171c1042f64b41a4b72e09dcc6f4852b6670\", \"price_changes\":[{\"asset_id\":\"8698449539441374295770236407991735029336433231649246775082939325523552031992\", \"price\":\"0.01\", \"size\":\"6829.52\", \"side\":\"BUY\", \"hash\":\"83cd6ca9896dcdef9c99ef9852b98c929a6bf12a\", \"best_bid\":\"0.21\", \"best_ask\":\"0.22\"}, {\"asset_id\":\"96283536366176669581486355171583722558858323126916278856549586825357358273536\", \"price\":\"0.99\", \"size\":\"6829.52\", \"side\":\"SELL\", \"hash\":\"65a85b5bd1bf11033b6cbc26e2cb5623f8839edb\", \"best_bid\":\"0.78\", \"best_ask\":\"0.79\"}], \"timestamp\":\"1785121846568\", \"event_type\":\"price_change\"}","received_at":"2026-07-27T03:10:46.479700Z","schema_version":"clob-market-ws.price_change.v1","sequence":null,"server_hash":null,"server_timestamp":"1785121846568","session_id":"ff6d21c8283948938400a32613abec2c","source":"clob_market_ws"},"received_at":"2026-07-27T03:10:46.479700Z","record_id":"f25a81e941d96e3023cb69bffd6d50db097b816f059855d9905eedf1701d6981","schema_fingerprint":"4aa3821a28b0b7c2400bc59aba4bcc0a76e971dadd19610d3ad38c768e124dc7","schema_version":"edge-lab-recorder.raw.v1","sequence":null,"source":"clob_market_ws"}
{"event_at":"2026-07-27T03:10:46.569000Z","event_fingerprint":"4f4fbb9dac438057ceb9aa671d5e5b15e8eec822622ba620e29301584879f1bb","payload":{"connection_id":"f95883f18d264834af91809e5f803e9f","event_at":"2026-07-27T03:10:46.569000Z","event_type":"price_change","frame_hash":"0d04f2d55ada3649db43c42c3d953e8f81419f27eb3185206a621029634a9fe7","frame_index":0,"kind":"data","monotonic_ns":223829812784625,"payload":{"event_type":"price_change","market":"0xf9d60bb033695053c4d1d8592e52171c1042f64b41a4b72e09dcc6f4852b6670","price_changes":[{"asset_id":"96283536366176669581486355171583722558858323126916278856549586825357358273536","best_ask":"0.79","best_bid":"0.78","hash":"a56d681b672657dfa236a5cc8e8673d0407a5e3b","price":"0.01","side":"BUY","size":"6914.52"},{"asset_id":"8698449539441374295770236407991735029336433231649246775082939325523552031992","best_ask":"0.22","best_bid":"0.21","hash":"78342520f66798267042be68aafc6a8fea56518c","price":"0.99","side":"SELL","size":"6914.52"}],"timestamp":"1785121846569"},"payload_hash":"0147b575eacb1629602860b8b3d39f465145a5366fd2e208f7e783ed36c62484","raw_frame":"{\"market\":\"0xf9d60bb033695053c4d1d8592e52171c1042f64b41a4b72e09dcc6f4852b6670\", \"price_changes\":[{\"asset_id\":\"96283536366176669581486355171583722558858323126916278856549586825357358273536\", \"price\":\"0.01\", \"size\":\"6914.52\", \"side\":\"BUY\", \"hash\":\"a56d681b672657dfa236a5cc8e8673d0407a5e3b\", \"best_bid\":\"0.78\", \"best_ask\":\"0.79\"}, {\"asset_id\":\"8698449539441374295770236407991735029336433231649246775082939325523552031992\", \"price\":\"0.99\", \"size\":\"6914.52\", \"side\":\"SELL\", \"hash\":\"78342520f66798267042be68aafc6a8fea56518c\", \"best_bid\":\"0.21\", \"best_ask\":\"0.22\"}], \"timestamp\":\"1785121846569\", \"event_type\":\"price_change\"}","received_at":"2026-07-27T03:10:46.482673Z","schema_version":"clob-market-ws.price_change.v1","sequence":null,"server_hash":null,"server_timestamp":"1785121846569","session_id":"ff6d21c8283948938400a32613abec2c","source":"clob_market_ws"},"received_at":"2026-07-27T03:10:46.482673Z","record_id":"daa5a8a9b3c3859d3ac68e8fa9a42e2b2d6f1a4b9db038e853c430c4f00f3e6a","schema_fingerprint":"4aa3821a28b0b7c2400bc59aba4bcc0a76e971dadd19610d3ad38c768e124dc7","schema_version":"edge-lab-recorder.raw.v1","sequence":null,"source":"clob_market_ws"}
{"event_at":"2026-07-27T03:10:46.570000Z","event_fingerprint":"2c206c98f59bf86da285322b1af5454e522ad9c96e8cdf06c9634281b677b8af","payload":{"connection_id":"f95883f18d264834af91809e5f803e9f","event_at":"2026-07-27T03:10:46.570000Z","event_type":"price_change","frame_hash":"0f2db610707a4caaf5002c542c022ff87cb6ea1ae6cfb45da19d355f062e3f39","frame_index":0,"kind":"data","monotonic_ns":223829814880083,"payload":{"event_type":"price_change","market":"0xf9d60bb033695053c4d1d8592e52171c1042f64b41a4b72e09dcc6f4852b6670","price_changes":[{"asset_id":"8698449539441374295770236407991735029336433231649246775082939325523552031992","best_ask":"0.22","best_bid":"0.21","hash":"426d1c07e6295e622c84facc8936fab642665f3c","price":"0.09","side":"BUY","size":"738.9"},{"asset_id":"96283536366176669581486355171583722558858323126916278856549586825357358273536","best_ask":"0.79","best_bid":"0.78","hash":"a7b428dad083a659f5ff53b22006f3705caf47ed","price":"0.91","side":"SELL","size":"738.9"}],"timestamp":"1785121846570"},"payload_hash":"c115d3ebb5d02b0f700975cda5bc1a4e423bc2fa577a8ecb1daf1edb932e869a","raw_frame":"{\"market\":\"0xf9d60bb033695053c4d1d8592e52171c1042f64b41a4b72e09dcc6f4852b6670\", \"price_changes\":[{\"asset_id\":\"8698449539441374295770236407991735029336433231649246775082939325523552031992\", \"price\":\"0.09\", \"size\":\"738.9\", \"side\":\"BUY\", \"hash\":\"426d1c07e6295e622c84facc8936fab642665f3c\", \"best_bid\":\"0.21\", \"best_ask\":\"0.22\"}, {\"asset_id\":\"96283536366176669581486355171583722558858323126916278856549586825357358273536\", \"price\":\"0.91\", \"size\":\"738.9\", \"side\":\"SELL\", \"hash\":\"a7b428dad083a659f5ff53b22006f3705caf47ed\", \"best_bid\":\"0.78\", \"best_ask\":\"0.79\"}], \"timestamp\":\"1785121846570\", \"event_type\":\"price_change\"}","received_at":"2026-07-27T03:10:46.484775Z","schema_version":"clob-market-ws.price_change.v1","sequence":null,"server_hash":null,"server_timestamp":"1785121846570","session_id":"ff6d21c8283948938400a32613abec2c","source":"clob_market_ws"},"received_at":"2026-07-27T03:10:46.484775Z","record_id":"52727c487330a8a300f0b39102f073c9e47d70de74add0f74fec215fc2c416ae","schema_fingerprint":"4aa3821a28b0b7c2400bc59aba4bcc0a76e971dadd19610d3ad38c768e124dc7","schema_version":"edge-lab-recorder.raw.v1","sequence":null,"source":"clob_market_ws"}
{"event_at":"2026-07-27T03:10:46.571000Z","event_fingerprint":"cbe6b7976ee6b0fcac1d5e276f0f4ec81e5f45538b813b06f30060e1c2990ce0","payload":{"connection_id":"f95883f18d264834af91809e5f803e9f","event_at":"2026-07-27T03:10:46.571000Z","event_type":"price_change","frame_hash":"95cc90d7ccd966f3d371c9d4412f81eb0ce98dc3d9706bfb10a9a1d6d26879f7","frame_index":0,"kind":"data","monotonic_ns":223829818226625,"payload":{"event_type":"price_change","market":"0xf9d60bb033695053c4d1d8592e52171c1042f64b41a4b72e09dcc6f4852b6670","price_changes":[{"asset_id":"8698449539441374295770236407991735029336433231649246775082939325523552031992","best_ask":"0.22","best_bid":"0.21","hash":"d05082829dad8a87ba47f5eec5c676b733515251","price":"0.01","side":"BUY","size":"6834.52"},{"asset_id":"96283536366176669581486355171583722558858323126916278856549586825357358273536","best_ask":"0.79","best_bid":"0.78","hash":"2286c2834398917aefa9e592e9732e00b952943e","price":"0.99","side":"SELL","size":"6834.52"}],"timestamp":"1785121846571"},"payload_hash":"c4dbd15acd7abab42adea30a50b071b4e07a2914030ae900d977ed84be9eef78","raw_frame":"{\"market\":\"0xf9d60bb033695053c4d1d8592e52171c1042f64b41a4b72e09dcc6f4852b6670\", \"price_changes\":[{\"asset_id\":\"8698449539441374295770236407991735029336433231649246775082939325523552031992\", \"price\":\"0.01\", \"size\":\"6834.52\", \"side\":\"BUY\", \"hash\":\"d05082829dad8a87ba47f5eec5c676b733515251\", \"best_bid\":\"0.21\", \"best_ask\":\"0.22\"}, {\"asset_id\":\"96283536366176669581486355171583722558858323126916278856549586825357358273536\", \"price\":\"0.99\", \"size\":\"6834.52\", \"side\":\"SELL\", \"hash\":\"2286c2834398917aefa9e592e9732e00b952943e\", \"best_bid\":\"0.78\", \"best_ask\":\"0.79\"}], \"timestamp\":\"1785121846571\", \"event_type\":\"price_change\"}","received_at":"2026-07-27T03:10:46.488114Z","schema_version":"clob-market-ws.price_change.v1","sequence":null,"server_hash":null,"server_timestamp":"1785121846571","session_id":"ff6d21c8283948938400a32613abec2c","source":"clob_market_ws"},"received_at":"2026-07-27T03:10:46.488114Z","record_id":"0bf93eb969f9a7b01a49efcc23da339b20fdc423d6a97084a817431862c8294d","schema_fingerprint":"4aa3821a28b0b7c2400bc59aba4bcc0a76e971dadd19610d3ad38c768e124dc7","schema_version":"edge-lab-recorder.raw.v1","sequence":null,"source":"clob_market_ws"}
{"event_at":"2026-07-27T03:10:46.574000Z","event_fingerprint":"1acb66a25730a6e933e31a7a0b9b5938616d333f99496393c4a17a8a3d832df2","payload":{"connection_id":"f95883f18d264834af91809e5f803e9f","event_at":"2026-07-27T03:10:46.574000Z","event_type":"price_change","frame_hash":"65885457834e5044523cf4e8c908c0dfd77d46a92b65db986816ccf96bfc3ba1","frame_index":0,"kind":"data","monotonic_ns":223829821058708,"payload":{"event_type":"price_change","market":"0xf9d60bb033695053c4d1d8592e52171c1042f64b41a4b72e09dcc6f4852b6670","price_changes":[{"asset_id":"8698449539441374295770236407991735029336433231649246775082939325523552031992","best_ask":"0.22","best_bid":"0.21","hash":"b12589f68454057d8843d12c9e98f7a8fe94dc2d","price":"0.21","side":"BUY","size":"102.23"},{"asset_id":"96283536366176669581486355171583722558858323126916278856549586825357358273536","best_ask":"0.79","best_bid":"0.78","hash":"506f19fb82ea07b96cdfdbb99af1ae9b1730e82c","price":"0.79","side":"SELL","size":"102.23"}],"timestamp":"1785121846574"},"payload_hash":"d44f059df550ca0a4408546969428e88ab75f0da1fecd6a19c4189a16b0708dd","raw_frame":"{\"market\":\"0xf9d60bb033695053c4d1d8592e52171c1042f64b41a4b72e09dcc6f4852b6670\", \"price_changes\":[{\"asset_id\":\"8698449539441374295770236407991735029336433231649246775082939325523552031992\", \"price\":\"0.21\", \"size\":\"102.23\", \"side\":\"BUY\", \"hash\":\"b12589f68454057d8843d12c9e98f7a8fe94dc2d\", \"best_bid\":\"0.21\", \"best_ask\":\"0.22\"}, {\"asset_id\":\"96283536366176669581486355171583722558858323126916278856549586825357358273536\", \"price\":\"0.79\", \"size\":\"102.23\", \"side\":\"SELL\", \"hash\":\"506f19fb82ea07b96cdfdbb99af1ae9b1730e82c\", \"best_bid\":\"0.78\", \"best_ask\":\"0.79\"}], \"timestamp\":\"1785121846574\", \"event_type\":\"price_change\"}","received_at":"2026-07-27T03:10:46.490946Z","schema_version":"clob-market-ws.price_change.v1","sequence":null,"server_hash":null,"server_timestamp":"1785121846574","session_id":"ff6d21c8283948938400a32613abec2c","source":"clob_market_ws"},"received_at":"2026-07-27T03:10:46.490946Z","record_id":"e4811f4f72c35dd38795e219712617684b77e1eedff8c8e70e75a4229a7ead8b","schema_fingerprint":"4aa3821a28b0b7c2400bc59aba4bcc0a76e971dadd19610d3ad38c768e124dc7","schema_version":"edge-lab-recorder.raw.v1","sequence":null,"source":"clob_market_ws"}
{"event_at":"2026-07-27T03:10:46.576000Z","event_fingerprint":"f636ea5f6a59b1b0a705ab5b05d904652e3831218558ad24caef47d4cd4ef03e","payload":{"connection_id":"f95883f18d264834af91809e5f803e9f","event_at":"2026-07-27T03:10:46.576000Z","event_type":"price_change","frame_hash":"49d0c59cf06c3df292c8473275db6cbb77f07120913f23fb4639968de34e96a3","frame_index":0,"kind":"data","monotonic_ns":223829823544750,"payload":{"event_type":"price_change","market":"0xf9d60bb033695053c4d1d8592e52171c1042f64b41a4b72e09dcc6f4852b6670","price_changes":[{"asset_id":"96283536366176669581486355171583722558858323126916278856549586825357358273536","best_ask":"0.79","best_bid":"0.78","hash":"f2a5801b9d2b4f707519009b19eb234672fd32d8","price":"0.01","side":"BUY","size":"6919.52"},{"asset_id":"8698449539441374295770236407991735029336433231649246775082939325523552031992","best_ask":"0.22","best_bid":"0.21","hash":"b2ed0327689727e9884e98b8ab736fbffcc86967","price":"0.99","side":"SELL","size":"6919.52"}],"timestamp":"1785121846576"},"payload_hash":"081f1ac0d3458f99e888c09392905e3e908a7dc4012893710b7100845363e977","raw_frame":"{\"market\":\"0xf9d60bb033695053c4d1d8592e52171c1042f64b41a4b72e09dcc6f4852b6670\", \"price_changes\":[{\"asset_id\":\"96283536366176669581486355171583722558858323126916278856549586825357358273536\", \"price\":\"0.01\", \"size\":\"6919.52\", \"side\":\"BUY\", \"hash\":\"f2a5801b9d2b4f707519009b19eb234672fd32d8\", \"best_bid\":\"0.78\", \"best_ask\":\"0.79\"}, {\"asset_id\":\"8698449539441374295770236407991735029336433231649246775082939325523552031992\", \"price\":\"0.99\", \"size\":\"6919.52\", \"side\":\"SELL\", \"hash\":\"b2ed0327689727e9884e98b8ab736fbffcc86967\", \"best_bid\":\"0.21\", \"best_ask\":\"0.22\"}], \"timestamp\":\"1785121846576\", \"event_type\":\"price_change\"}","received_at":"2026-07-27T03:10:46.493434Z","schema_version":"clob-market-ws.price_change.v1","sequence":null,"server_hash":null,"server_timestamp":"1785121846576","session_id":"ff6d21c8283948938400a32613abec2c","source":"clob_market_ws"},"received_at":"2026-07-27T03:10:46.493434Z","record_id":"cdcdd9c68e82867bb5815945cabeea830e16e14239e980c5e847ea1ed8fab79d","schema_fingerprint":"4aa3821a28b0b7c2400bc59aba4bcc0a76e971dadd19610d3ad38c768e124dc7","schema_version":"edge-lab-recorder.raw.v1","sequence":null,"source":"clob_market_ws"}
